{
  "version": 8,
  "blockIdVersion": 8,
  "anchorX": 1,
  "anchorY": 6,
  "anchorZ": 0,
  "blocks": [
    {
      "x": -1,
      "y": 5,
      "z": -2,
      "name": "Rock_Basalt"
    },
    {
      "x": -1,
      "y": 5,
      "z": -1,
      "name": "Rock_Basalt"
    },
    {
      "x": -1,
      "y": 6,
      "z": -1,
      "name": "Plant_Crop_Mushroom_Block_Red"
    },
    {
      "x": -1,
      "y": 7,
      "z": -1,
      "name": "Plant_Crop_Mushroom_Block_Red"
    },
    {
      "x": -1,
      "y": 8,
      "z": -1,
      "name": "Plant_Crop_Mushroom_Block_Red"
    },
    {
      "x": -1,
      "y": 5,
      "z": 0,
      "name": "Rock_Basalt"
    },
    {
      "x": -1,
      "y": 6,
      "z": 0,
      "name": "Plant_Crop_Mushroom_Block_Red"
    },
    {
      "x": -1,
      "y": 7,
      "z": 0,
      "name": "Plant_Crop_Mushroom_Block_Red"
    },
    {
      "x": 0,
      "y": 5,
      "z": -2,
      "name": "Rock_Basalt"
    },
    {
      "x": 0,
      "y": 6,
      "z": -2,
      "name": "Plant_Crop_Mushroom_Block_Red"
    },
    {
      "x": 0,
      "y": 7,
      "z": -2,
      "name": "Plant_Crop_Mushroom_Block_Red"
    },
    {
      "x": 0,
      "y": 8,
      "z": -2,
      "name": "Plant_Crop_Mushroom_Glowing_Orange"
    },
    {
      "x": 0,
      "y": 4,
      "z": -1,
      "name": "Rock_Basalt"
    },
    {
      "x": 0,
      "y": 5,
      "z": -1,
      "name": "Rock_Basalt"
    },
    {
      "x": 0,
      "y": 6,
      "z": -1,
      "name": "Plant_Crop_Mushroom_Block_Red"
    },
    {
      "x": 0,
      "y": 7,
      "z": -1,
      "name": "Plant_Crop_Mushroom_Block_Red"
    },
    {
      "x": 0,
      "y": 8,
      "z": -1,
      "name": "Plant_Crop_Mushroom_Block_Red"
    },
    {
      "x": 0,
      "y": 9,
      "z": -1,
      "name": "Plant_Crop_Mushroom_Cap_Red",
      "components": {
        "Components": {
          "FarmingBlock": {}
        }
      }
    },
    {
      "x": 0,
      "y": 4,
      "z": 0,
      "name": "Rock_Basalt"
    },
    {
      "x": 0,
      "y": 5,
      "z": 0,
      "name": "Rock_Basalt"
    },
    {
      "x": 0,
      "y": 6,
      "z": 0,
      "name": "Rock_Basalt"
    },
    {
      "x": 0,
      "y": 7,
      "z": 0,
      "name": "Plant_Crop_Mushroom_Block_Red"
    },
    {
      "x": 0,
      "y": 8,
      "z": 0,
      "name": "Plant_Crop_Mushroom_Block_Red"
    },
    {
      "x": 0,
      "y": 9,
      "z": 0,
      "name": "Plant_Crop_Mushroom_Glowing_Orange"
    },
    {
      "x": 0,
      "y": 4,
      "z": 1,
      "name": "Rock_Basalt"
    },
    {
      "x": 0,
      "y": 5,
      "z": 1,
      "name": "Rock_Basalt"
    },
    {
      "x": 0,
      "y": 6,
      "z": 1,
      "name": "Rock_Basalt"
    },
    {
      "x": 0,
      "y": 7,
      "z": 1,
      "name": "Plant_Crop_Mushroom_Block_Red"
    },
    {
      "x": 0,
      "y": 8,
      "z": 1,
      "name": "Plant_Crop_Mushroom_Block_Red"
    },
    {
      "x": 0,
      "y": 9,
      "z": 1,
      "name": "Plant_Crop_Mushroom_Glowing_Orange"
    },
    {
      "x": 1,
      "y": 5,
      "z": -2,
      "name": "Rock_Basalt"
    },
    {
      "x": 1,
      "y": 6,
      "z": -2,
      "name": "Plant_Crop_Mushroom_Block_Red"
    },
    {
      "x": 1,
      "y": 7,
      "z": -2,
      "name": "Plant_Crop_Mushroom_Block_Red"
    },
    {
      "x": 1,
      "y": 8,
      "z": -2,
      "name": "Plant_Crop_Mushroom_Glowing_Orange"
    },
    {
      "x": 1,
      "y": 4,
      "z": -1,
      "name": "Rock_Basalt"
    },
    {
      "x": 1,
      "y": 5,
      "z": -1,
      "name": "Rock_Basalt"
    },
    {
      "x": 1,
      "y": 6,
      "z": -1,
      "name": "Rock_Basalt"
    },
    {
      "x": 1,
      "y": 7,
      "z": -1,
      "name": "Plant_Crop_Mushroom_Block_Red"
    },
    {
      "x": 1,
      "y": 8,
      "z": -1,
      "name": "Plant_Crop_Mushroom_Block_Red"
    },
    {
      "x": 1,
      "y": 9,
      "z": -1,
      "name": "Plant_Crop_Mushroom_Cap_Red",
      "components": {
        "Components": {
          "FarmingBlock": {}
        }
      }
    },
    {
      "x": 1,
      "y": 4,
      "z": 0,
      "name": "Rock_Basalt"
    },
    {
      "x": 1,
      "y": 5,
      "z": 0,
      "name": "Rock_Basalt"
    },
    {
      "x": 1,
      "y": 6,
      "z": 0,
      "name": "Rock_Basalt"
    },
    {
      "x": 1,
      "y": 7,
      "z": 0,
      "name": "Plant_Crop_Mushroom_Block_Red"
    },
    {
      "x": 1,
      "y": 8,
      "z": 0,
      "name": "Plant_Crop_Mushroom_Block_Red"
    },
    {
      "x": 1,
      "y": 9,
      "z": 0,
      "name": "Plant_Crop_Mushroom_Glowing_Orange"
    },
    {
      "x": 1,
      "y": 4,
      "z": 1,
      "name": "Rock_Basalt"
    },
    {
      "x": 1,
      "y": 5,
      "z": 1,
      "name": "Rock_Basalt"
    },
    {
      "x": 1,
      "y": 6,
      "z": 1,
      "name": "Rock_Basalt"
    },
    {
      "x": 1,
      "y": 7,
      "z": 1,
      "name": "Plant_Crop_Mushroom_Block_Red"
    },
    {
      "x": 1,
      "y": 8,
      "z": 1,
      "name": "Plant_Crop_Mushroom_Block_Red"
    },
    {
      "x": 2,
      "y": 4,
      "z": -1,
      "name": "Rock_Basalt"
    },
    {
      "x": 2,
      "y": 5,
      "z": -1,
      "name": "Rock_Basalt"
    },
    {
      "x": 2,
      "y": 6,
      "z": -1,
      "name": "Rock_Basalt"
    },
    {
      "x": 2,
      "y": 7,
      "z": -1,
      "name": "Plant_Crop_Mushroom_Block_Red"
    },
    {
      "x": 2,
      "y": 8,
      "z": -1,
      "name": "Plant_Crop_Mushroom_Block_Red"
    },
    {
      "x": 2,
      "y": 9,
      "z": -1,
      "name": "Plant_Crop_Mushroom_Glowing_Orange"
    },
    {
      "x": 2,
      "y": 4,
      "z": 0,
      "name": "Rock_Basalt"
    },
    {
      "x": 2,
      "y": 5,
      "z": 0,
      "name": "Rock_Basalt"
    },
    {
      "x": 2,
      "y": 6,
      "z": 0,
      "name": "Rock_Basalt"
    },
    {
      "x": 2,
      "y": 7,
      "z": 0,
      "name": "Plant_Crop_Mushroom_Block_Red"
    },
    {
      "x": 2,
      "y": 8,
      "z": 0,
      "name": "Plant_Crop_Mushroom_Block_Red"
    },
    {
      "x": 2,
      "y": 5,
      "z": 1,
      "name": "Rock_Basalt"
    },
    {
      "x": 2,
      "y": 6,
      "z": 1,
      "name": "Rock_Basalt"
    },
    {
      "x": 2,
      "y": 7,
      "z": 1,
      "name": "Plant_Crop_Mushroom_Block_Red"
    }
  ]
}