{
  "version": 8,
  "blockIdVersion": 8,
  "anchorX": 1,
  "anchorY": 7,
  "anchorZ": 1,
  "blocks": [
    {
      "x": -4,
      "y": 5,
      "z": -4,
      "name": "Rock_Slate"
    },
    {
      "x": -4,
      "y": 6,
      "z": -4,
      "name": "Rock_Slate"
    },
    {
      "x": -4,
      "y": 7,
      "z": -4,
      "name": "Rock_Slate"
    },
    {
      "x": -4,
      "y": 3,
      "z": -3,
      "name": "Rock_Slate"
    },
    {
      "x": -4,
      "y": 4,
      "z": -3,
      "name": "Rock_Slate"
    },
    {
      "x": -4,
      "y": 5,
      "z": -3,
      "name": "Rock_Slate"
    },
    {
      "x": -4,
      "y": 6,
      "z": -3,
      "name": "Rock_Slate"
    },
    {
      "x": -4,
      "y": 7,
      "z": -3,
      "name": "Rock_Slate"
    },
    {
      "x": -4,
      "y": 3,
      "z": -2,
      "name": "Rock_Slate"
    },
    {
      "x": -4,
      "y": 4,
      "z": -2,
      "name": "Rock_Slate"
    },
    {
      "x": -4,
      "y": 5,
      "z": -2,
      "name": "Rock_Slate"
    },
    {
      "x": -4,
      "y": 6,
      "z": -2,
      "name": "Rock_Slate"
    },
    {
      "x": -4,
      "y": 8,
      "z": 1,
      "name": "Wood_Burnt_Branch_Long"
    },
    {
      "x": -4,
      "y": 9,
      "z": 1,
      "name": "Wood_Burnt_Branch_Long"
    },
    {
      "x": -4,
      "y": 10,
      "z": 1,
      "name": "Wood_Burnt_Branch_Long"
    },
    {
      "x": -4,
      "y": 11,
      "z": 1,
      "name": "Wood_Deadwood_Roof_Flat",
      "rotation": 1
    },
    {
      "x": -4,
      "y": 5,
      "z": 2,
      "name": "Rock_Volcanic"
    },
    {
      "x": -4,
      "y": 6,
      "z": 2,
      "name": "Rock_Volcanic_Cobble"
    },
    {
      "x": -4,
      "y": 7,
      "z": 2,
      "name": "Rock_Basalt_Brick"
    },
    {
      "x": -4,
      "y": 8,
      "z": 2,
      "name": "Empty"
    },
    {
      "x": -4,
      "y": 9,
      "z": 2,
      "name": "Empty"
    },
    {
      "x": -4,
      "y": 10,
      "z": 2,
      "name": "Empty"
    },
    {
      "x": -4,
      "y": 11,
      "z": 2,
      "name": "Wood_Deadwood_Roof_Flat",
      "rotation": 1
    },
    {
      "x": -4,
      "y": 5,
      "z": 3,
      "name": "Rock_Volcanic"
    },
    {
      "x": -4,
      "y": 6,
      "z": 3,
      "name": "Rock_Volcanic"
    },
    {
      "x": -4,
      "y": 7,
      "z": 3,
      "name": "Rock_Basalt_Brick"
    },
    {
      "x": -4,
      "y": 8,
      "z": 3,
      "name": "Empty"
    },
    {
      "x": -4,
      "y": 9,
      "z": 3,
      "name": "Empty"
    },
    {
      "x": -4,
      "y": 10,
      "z": 3,
      "name": "Empty"
    },
    {
      "x": -4,
      "y": 11,
      "z": 3,
      "name": "Wood_Deadwood_Roof_Flat",
      "rotation": 1
    },
    {
      "x": -4,
      "y": 5,
      "z": 4,
      "name": "Rock_Volcanic"
    },
    {
      "x": -4,
      "y": 6,
      "z": 4,
      "name": "Rock_Volcanic"
    },
    {
      "x": -4,
      "y": 7,
      "z": 4,
      "name": "Rock_Basalt_Brick"
    },
    {
      "x": -4,
      "y": 8,
      "z": 4,
      "name": "Empty"
    },
    {
      "x": -4,
      "y": 9,
      "z": 4,
      "name": "Empty"
    },
    {
      "x": -4,
      "y": 10,
      "z": 4,
      "name": "Empty"
    },
    {
      "x": -4,
      "y": 11,
      "z": 4,
      "name": "Wood_Deadwood_Roof_Flat",
      "rotation": 1
    },
    {
      "x": -4,
      "y": 4,
      "z": 5,
      "name": "Rock_Volcanic"
    },
    {
      "x": -4,
      "y": 5,
      "z": 5,
      "name": "Rock_Volcanic"
    },
    {
      "x": -4,
      "y": 6,
      "z": 5,
      "name": "Rock_Volcanic_Cobble"
    },
    {
      "x": -4,
      "y": 7,
      "z": 5,
      "name": "Rock_Basalt_Brick"
    },
    {
      "x": -4,
      "y": 8,
      "z": 5,
      "name": "Rock_Basalt_Brick"
    },
    {
      "x": -4,
      "y": 9,
      "z": 5,
      "name": "Wood_Burnt_Branch_Long"
    },
    {
      "x": -4,
      "y": 10,
      "z": 5,
      "name": "Wood_Burnt_Branch_Long"
    },
    {
      "x": -4,
      "y": 11,
      "z": 5,
      "name": "Wood_Deadwood_Roof_Flat",
      "rotation": 1
    },
    {
      "x": -3,
      "y": 6,
      "z": -5,
      "name": "Rock_Slate"
    },
    {
      "x": -3,
      "y": 7,
      "z": -5,
      "name": "Rock_Slate"
    },
    {
      "x": -3,
      "y": 3,
      "z": -4,
      "name": "Rock_Slate"
    },
    {
      "x": -3,
      "y": 4,
      "z": -4,
      "name": "Rock_Slate"
    },
    {
      "x": -3,
      "y": 5,
      "z": -4,
      "name": "Rock_Slate"
    },
    {
      "x": -3,
      "y": 6,
      "z": -4,
      "name": "Rock_Slate"
    },
    {
      "x": -3,
      "y": 7,
      "z": -4,
      "name": "Rock_Slate"
    },
    {
      "x": -3,
      "y": 8,
      "z": -4,
      "name": "Plant_Bush_Dead_Twisted"
    },
    {
      "x": -3,
      "y": 1,
      "z": -3,
      "name": "Rock_Slate"
    },
    {
      "x": -3,
      "y": 2,
      "z": -3,
      "name": "Rock_Slate"
    },
    {
      "x": -3,
      "y": 3,
      "z": -3,
      "name": "Rock_Slate"
    },
    {
      "x": -3,
      "y": 4,
      "z": -3,
      "name": "Rock_Slate"
    },
    {
      "x": -3,
      "y": 5,
      "z": -3,
      "name": "Rock_Slate"
    },
    {
      "x": -3,
      "y": 6,
      "z": -3,
      "name": "Rock_Slate"
    },
    {
      "x": -3,
      "y": 7,
      "z": -3,
      "name": "Rock_Slate"
    },
    {
      "x": -3,
      "y": 8,
      "z": -3,
      "name": "Furniture_Ancient_Barrel"
    },
    {
      "x": -3,
      "y": 1,
      "z": -2,
      "name": "Rock_Slate"
    },
    {
      "x": -3,
      "y": 2,
      "z": -2,
      "name": "Rock_Slate"
    },
    {
      "x": -3,
      "y": 3,
      "z": -2,
      "name": "Rock_Slate"
    },
    {
      "x": -3,
      "y": 4,
      "z": -2,
      "name": "Rock_Slate"
    },
    {
      "x": -3,
      "y": 5,
      "z": -2,
      "name": "Rock_Slate"
    },
    {
      "x": -3,
      "y": 6,
      "z": -2,
      "name": "Rock_Slate"
    },
    {
      "x": -3,
      "y": 7,
      "z": -2,
      "name": "Rock_Slate"
    },
    {
      "x": -3,
      "y": 8,
      "z": -2,
      "name": "Plant_Bush_Dead_Twisted"
    },
    {
      "x": -3,
      "y": 3,
      "z": -1,
      "name": "Rock_Slate"
    },
    {
      "x": -3,
      "y": 4,
      "z": -1,
      "name": "Rock_Slate"
    },
    {
      "x": -3,
      "y": 5,
      "z": -1,
      "name": "Rock_Slate"
    },
    {
      "x": -3,
      "y": 4,
      "z": 1,
      "name": "Rock_Volcanic"
    },
    {
      "x": -3,
      "y": 5,
      "z": 1,
      "name": "Rock_Volcanic_Cobble"
    },
    {
      "x": -3,
      "y": 6,
      "z": 1,
      "name": "Rock_Volcanic_Cobble"
    },
    {
      "x": -3,
      "y": 7,
      "z": 1,
      "name": "Rock_Basalt_Brick"
    },
    {
      "x": -3,
      "y": 8,
      "z": 1,
      "name": "Rock_Basalt_Brick"
    },
    {
      "x": -3,
      "y": 9,
      "z": 1,
      "name": "Furniture_Human_Ruins_Torch",
      "rotation": 2
    },
    {
      "x": -3,
      "y": 10,
      "z": 1,
      "name": "Empty"
    },
    {
      "x": -3,
      "y": 11,
      "z": 1,
      "name": "Wood_Deadwood_Roof_Flat",
      "rotation": 1
    },
    {
      "x": -3,
      "y": 7,
      "z": 2,
      "name": "Rock_Basalt_Cobble"
    },
    {
      "x": -3,
      "y": 8,
      "z": 2,
      "name": "Furniture_Ancient_Barrel"
    },
    {
      "x": -3,
      "y": 9,
      "z": 2,
      "name": "Empty"
    },
    {
      "x": -3,
      "y": 10,
      "z": 2,
      "name": "Empty"
    },
    {
      "x": -3,
      "y": 11,
      "z": 2,
      "name": "Wood_Deadwood_Roof_Flat",
      "rotation": 1
    },
    {
      "x": -3,
      "y": 7,
      "z": 3,
      "name": "Rock_Basalt_Cobble"
    },
    {
      "x": -3,
      "y": 8,
      "z": 3,
      "name": "Block_Spawner_Block",
      "components": {
        "Components": {
          "PlacedByInteraction": {
            "WhoPlacedUuid": {
              "$binary": "5OYreBmdMS+xlzjMlwn5JQ==",
              "$type": "04"
            }
          },
          "BlockSpawner": {
            "BlockSpawnerId": "Zone4_Encounters_Tier1"
          }
        }
      },
      "rotation": 3
    },
    {
      "x": -3,
      "y": 9,
      "z": 3,
      "name": "Empty"
    },
    {
      "x": -3,
      "y": 10,
      "z": 3,
      "name": "Empty"
    },
    {
      "x": -3,
      "y": 11,
      "z": 3,
      "name": "Wood_Deadwood_Roof_Flat",
      "rotation": 1
    },
    {
      "x": -3,
      "y": 7,
      "z": 4,
      "name": "Rock_Basalt_Cobble"
    },
    {
      "x": -3,
      "y": 8,
      "z": 4,
      "name": "Empty"
    },
    {
      "x": -3,
      "y": 9,
      "z": 4,
      "name": "Empty"
    },
    {
      "x": -3,
      "y": 10,
      "z": 4,
      "name": "Empty"
    },
    {
      "x": -3,
      "y": 11,
      "z": 4,
      "name": "Wood_Deadwood_Roof_Flat",
      "rotation": 1
    },
    {
      "x": -3,
      "y": 3,
      "z": 5,
      "name": "Rock_Volcanic"
    },
    {
      "x": -3,
      "y": 4,
      "z": 5,
      "name": "Rock_Volcanic"
    },
    {
      "x": -3,
      "y": 5,
      "z": 5,
      "name": "Rock_Volcanic_Cobble"
    },
    {
      "x": -3,
      "y": 6,
      "z": 5,
      "name": "Rock_Volcanic_Cobble"
    },
    {
      "x": -3,
      "y": 7,
      "z": 5,
      "name": "Rock_Basalt_Brick"
    },
    {
      "x": -3,
      "y": 8,
      "z": 5,
      "name": "Plant_Bush_Dead_Tall"
    },
    {
      "x": -3,
      "y": 9,
      "z": 5,
      "name": "Empty"
    },
    {
      "x": -3,
      "y": 10,
      "z": 5,
      "name": "Empty"
    },
    {
      "x": -3,
      "y": 11,
      "z": 5,
      "name": "Wood_Deadwood_Roof_Flat",
      "rotation": 1
    },
    {
      "x": -2,
      "y": 6,
      "z": -5,
      "name": "Rock_Slate"
    },
    {
      "x": -2,
      "y": 7,
      "z": -5,
      "name": "Rock_Slate"
    },
    {
      "x": -2,
      "y": 2,
      "z": -4,
      "name": "Rock_Slate"
    },
    {
      "x": -2,
      "y": 3,
      "z": -4,
      "name": "Rock_Slate"
    },
    {
      "x": -2,
      "y": 4,
      "z": -4,
      "name": "Rock_Slate"
    },
    {
      "x": -2,
      "y": 5,
      "z": -4,
      "name": "Rock_Slate"
    },
    {
      "x": -2,
      "y": 6,
      "z": -4,
      "name": "Rock_Slate"
    },
    {
      "x": -2,
      "y": 7,
      "z": -4,
      "name": "Rock_Slate"
    },
    {
      "x": -2,
      "y": 8,
      "z": -4,
      "name": "Furniture_Human_Ruins_Pot_Small"
    },
    {
      "x": -2,
      "y": 0,
      "z": -3,
      "name": "Rock_Slate"
    },
    {
      "x": -2,
      "y": 1,
      "z": -3,
      "name": "Rock_Slate"
    },
    {
      "x": -2,
      "y": 2,
      "z": -3,
      "name": "Rock_Slate"
    },
    {
      "x": -2,
      "y": 3,
      "z": -3,
      "name": "Rock_Slate"
    },
    {
      "x": -2,
      "y": 4,
      "z": -3,
      "name": "Rock_Volcanic"
    },
    {
      "x": -2,
      "y": 5,
      "z": -3,
      "name": "Rock_Volcanic"
    },
    {
      "x": -2,
      "y": 6,
      "z": -3,
      "name": "Rock_Volcanic_Cobble"
    },
    {
      "x": -2,
      "y": 7,
      "z": -3,
      "name": "Rock_Basalt_Brick"
    },
    {
      "x": -2,
      "y": 8,
      "z": -3,
      "name": "Rock_Basalt_Brick"
    },
    {
      "x": -2,
      "y": 9,
      "z": -3,
      "name": "Rock_Basalt_Brick"
    },
    {
      "x": -2,
      "y": 10,
      "z": -3,
      "name": "Rock_Basalt_Brick"
    },
    {
      "x": -2,
      "y": 11,
      "z": -3,
      "name": "Rock_Basalt_Brick"
    },
    {
      "x": -2,
      "y": 12,
      "z": -3,
      "name": "Wood_Deadwood_Roof_Flat",
      "rotation": 1
    },
    {
      "x": -2,
      "y": 0,
      "z": -2,
      "name": "Rock_Slate"
    },
    {
      "x": -2,
      "y": 1,
      "z": -2,
      "name": "Rock_Slate"
    },
    {
      "x": -2,
      "y": 2,
      "z": -2,
      "name": "Rock_Slate"
    },
    {
      "x": -2,
      "y": 3,
      "z": -2,
      "name": "Rock_Volcanic"
    },
    {
      "x": -2,
      "y": 4,
      "z": -2,
      "name": "Rock_Volcanic"
    },
    {
      "x": -2,
      "y": 5,
      "z": -2,
      "name": "Rock_Volcanic_Cobble"
    },
    {
      "x": -2,
      "y": 6,
      "z": -2,
      "name": "Rock_Volcanic_Cobble"
    },
    {
      "x": -2,
      "y": 7,
      "z": -2,
      "name": "Rock_Basalt_Brick"
    },
    {
      "x": -2,
      "y": 8,
      "z": -2,
      "name": "Rock_Basalt_Brick"
    },
    {
      "x": -2,
      "y": 9,
      "z": -2,
      "name": "Rock_Basalt_Brick"
    },
    {
      "x": -2,
      "y": 10,
      "z": -2,
      "name": "Rock_Basalt_Cobble"
    },
    {
      "x": -2,
      "y": 11,
      "z": -2,
      "name": "Rock_Basalt_Cobble"
    },
    {
      "x": -2,
      "y": 2,
      "z": -1,
      "name": "Rock_Slate"
    },
    {
      "x": -2,
      "y": 3,
      "z": -1,
      "name": "Rock_Volcanic"
    },
    {
      "x": -2,
      "y": 4,
      "z": -1,
      "name": "Rock_Volcanic"
    },
    {
      "x": -2,
      "y": 5,
      "z": -1,
      "name": "Rock_Volcanic_Cobble"
    },
    {
      "x": -2,
      "y": 6,
      "z": -1,
      "name": "Rock_Volcanic_Cobble"
    },
    {
      "x": -2,
      "y": 7,
      "z": -1,
      "name": "Rock_Volcanic_Cobble"
    },
    {
      "x": -2,
      "y": 8,
      "z": -1,
      "name": "Rock_Basalt_Brick"
    },
    {
      "x": -2,
      "y": 9,
      "z": -1,
      "name": "Furniture_Ancient_Window",
      "rotation": 1
    },
    {
      "x": -2,
      "y": 10,
      "z": -1,
      "name": "Furniture_Ancient_Window",
      "rotation": 1
    },
    {
      "x": -2,
      "y": 11,
      "z": -1,
      "name": "Empty"
    },
    {
      "x": -2,
      "y": 3,
      "z": 0,
      "name": "Rock_Volcanic"
    },
    {
      "x": -2,
      "y": 4,
      "z": 0,
      "name": "Rock_Volcanic"
    },
    {
      "x": -2,
      "y": 5,
      "z": 0,
      "name": "Rock_Volcanic"
    },
    {
      "x": -2,
      "y": 6,
      "z": 0,
      "name": "Rock_Volcanic_Cobble"
    },
    {
      "x": -2,
      "y": 7,
      "z": 0,
      "name": "Rock_Volcanic_Cobble"
    },
    {
      "x": -2,
      "y": 8,
      "z": 0,
      "name": "Rock_Basalt_Brick"
    },
    {
      "x": -2,
      "y": 9,
      "z": 0,
      "name": "Rock_Basalt_Cobble"
    },
    {
      "x": -2,
      "y": 10,
      "z": 0,
      "name": "Empty"
    },
    {
      "x": -2,
      "y": 11,
      "z": 0,
      "name": "Empty"
    },
    {
      "x": -2,
      "y": 3,
      "z": 1,
      "name": "Rock_Volcanic"
    },
    {
      "x": -2,
      "y": 4,
      "z": 1,
      "name": "Rock_Volcanic"
    },
    {
      "x": -2,
      "y": 5,
      "z": 1,
      "name": "Rock_Volcanic"
    },
    {
      "x": -2,
      "y": 6,
      "z": 1,
      "name": "Rock_Volcanic_Cobble"
    },
    {
      "x": -2,
      "y": 7,
      "z": 1,
      "name": "Rock_Basalt_Brick"
    },
    {
      "x": -2,
      "y": 8,
      "z": 1,
      "name": "Rock_Basalt_Brick"
    },
    {
      "x": -2,
      "y": 9,
      "z": 1,
      "name": "Rock_Basalt_Cobble"
    },
    {
      "x": -2,
      "y": 10,
      "z": 1,
      "name": "Rock_Basalt_Cobble"
    },
    {
      "x": -2,
      "y": 11,
      "z": 1,
      "name": "Empty"
    },
    {
      "x": -2,
      "y": 2,
      "z": 2,
      "name": "Rock_Volcanic"
    },
    {
      "x": -2,
      "y": 3,
      "z": 2,
      "name": "Rock_Volcanic"
    },
    {
      "x": -2,
      "y": 4,
      "z": 2,
      "name": "Rock_Volcanic"
    },
    {
      "x": -2,
      "y": 5,
      "z": 2,
      "name": "Rock_Volcanic_Cobble"
    },
    {
      "x": -2,
      "y": 6,
      "z": 2,
      "name": "Rock_Volcanic_Cobble"
    },
    {
      "x": -2,
      "y": 7,
      "z": 2,
      "name": "Rock_Basalt_Brick"
    },
    {
      "x": -2,
      "y": 8,
      "z": 2,
      "name": "Rock_Basalt_Cobble"
    },
    {
      "x": -2,
      "y": 9,
      "z": 2,
      "name": "Rock_Basalt_Cobble"
    },
    {
      "x": -2,
      "y": 10,
      "z": 2,
      "name": "Rock_Basalt_Cobble"
    },
    {
      "x": -2,
      "y": 11,
      "z": 2,
      "name": "Rock_Basalt_Cobble"
    },
    {
      "x": -2,
      "y": 2,
      "z": 3,
      "name": "Rock_Volcanic"
    },
    {
      "x": -2,
      "y": 3,
      "z": 3,
      "name": "Rock_Volcanic"
    },
    {
      "x": -2,
      "y": 4,
      "z": 3,
      "name": "Rock_Volcanic"
    },
    {
      "x": -2,
      "y": 5,
      "z": 3,
      "name": "Rock_Volcanic_Cobble"
    },
    {
      "x": -2,
      "y": 6,
      "z": 3,
      "name": "Rock_Volcanic_Cobble"
    },
    {
      "x": -2,
      "y": 7,
      "z": 3,
      "name": "Rock_Basalt_Brick"
    },
    {
      "x": -2,
      "y": 8,
      "z": 3,
      "name": "Rock_Basalt_Cobble"
    },
    {
      "x": -2,
      "y": 9,
      "z": 3,
      "name": "Rock_Basalt_Cobble"
    },
    {
      "x": -2,
      "y": 10,
      "z": 3,
      "name": "Rock_Basalt_Cobble"
    },
    {
      "x": -2,
      "y": 11,
      "z": 3,
      "name": "Rock_Basalt_Cobble"
    },
    {
      "x": -2,
      "y": 12,
      "z": 3,
      "name": "Wood_Deadwood_Roof_Flat",
      "rotation": 1
    },
    {
      "x": -2,
      "y": 2,
      "z": 4,
      "name": "Rock_Volcanic"
    },
    {
      "x": -2,
      "y": 3,
      "z": 4,
      "name": "Rock_Volcanic"
    },
    {
      "x": -2,
      "y": 4,
      "z": 4,
      "name": "Rock_Volcanic"
    },
    {
      "x": -2,
      "y": 5,
      "z": 4,
      "name": "Rock_Volcanic_Cobble"
    },
    {
      "x": -2,
      "y": 6,
      "z": 4,
      "name": "Rock_Volcanic_Cobble"
    },
    {
      "x": -2,
      "y": 7,
      "z": 4,
      "name": "Rock_Basalt_Brick"
    },
    {
      "x": -2,
      "y": 8,
      "z": 4,
      "name": "Rock_Basalt_Cobble"
    },
    {
      "x": -2,
      "y": 9,
      "z": 4,
      "name": "Rock_Basalt_Cobble"
    },
    {
      "x": -2,
      "y": 10,
      "z": 4,
      "name": "Rock_Basalt_Cobble"
    },
    {
      "x": -2,
      "y": 11,
      "z": 4,
      "name": "Rock_Basalt_Brick"
    },
    {
      "x": -2,
      "y": 12,
      "z": 4,
      "name": "Wood_Deadwood_Roof_Flat",
      "rotation": 1
    },
    {
      "x": -2,
      "y": 3,
      "z": 5,
      "name": "Rock_Volcanic"
    },
    {
      "x": -2,
      "y": 4,
      "z": 5,
      "name": "Rock_Volcanic"
    },
    {
      "x": -2,
      "y": 5,
      "z": 5,
      "name": "Rock_Volcanic"
    },
    {
      "x": -2,
      "y": 6,
      "z": 5,
      "name": "Rock_Volcanic_Cobble"
    },
    {
      "x": -2,
      "y": 7,
      "z": 5,
      "name": "Rock_Volcanic_Cobble"
    },
    {
      "x": -2,
      "y": 8,
      "z": 5,
      "name": "Rock_Basalt_Brick"
    },
    {
      "x": -2,
      "y": 9,
      "z": 5,
      "name": "Rock_Basalt_Brick"
    },
    {
      "x": -2,
      "y": 10,
      "z": 5,
      "name": "Rock_Basalt_Brick"
    },
    {
      "x": -2,
      "y": 11,
      "z": 5,
      "name": "Rock_Basalt_Brick"
    },
    {
      "x": -2,
      "y": 12,
      "z": 5,
      "name": "Wood_Deadwood_Roof_Flat",
      "rotation": 1
    },
    {
      "x": -1,
      "y": 3,
      "z": -4,
      "name": "Rock_Slate"
    },
    {
      "x": -1,
      "y": 4,
      "z": -4,
      "name": "Rock_Slate"
    },
    {
      "x": -1,
      "y": 0,
      "z": -3,
      "name": "Rock_Slate"
    },
    {
      "x": -1,
      "y": 1,
      "z": -3,
      "name": "Rock_Slate"
    },
    {
      "x": -1,
      "y": 2,
      "z": -3,
      "name": "Rock_Slate"
    },
    {
      "x": -1,
      "y": 3,
      "z": -3,
      "name": "Rock_Volcanic"
    },
    {
      "x": -1,
      "y": 4,
      "z": -3,
      "name": "Rock_Volcanic"
    },
    {
      "x": -1,
      "y": 5,
      "z": -3,
      "name": "Rock_Volcanic_Cobble"
    },
    {
      "x": -1,
      "y": 6,
      "z": -3,
      "name": "Rock_Volcanic_Cobble"
    },
    {
      "x": -1,
      "y": 7,
      "z": -3,
      "name": "Rock_Basalt_Brick"
    },
    {
      "x": -1,
      "y": 8,
      "z": -3,
      "name": "Rock_Basalt_Brick"
    },
    {
      "x": -1,
      "y": 9,
      "z": -3,
      "name": "Rock_Basalt_Brick"
    },
    {
      "x": -1,
      "y": 10,
      "z": -3,
      "name": "Rock_Basalt_Cobble"
    },
    {
      "x": -1,
      "y": 11,
      "z": -3,
      "name": "Rock_Basalt_Cobble"
    },
    {
      "x": -1,
      "y": 12,
      "z": -3,
      "name": "Wood_Deadwood_Roof_Flat",
      "rotation": 1
    },
    {
      "x": -1,
      "y": 0,
      "z": -2,
      "name": "Rock_Slate"
    },
    {
      "x": -1,
      "y": 1,
      "z": -2,
      "name": "Rock_Slate"
    },
    {
      "x": -1,
      "y": 2,
      "z": -2,
      "name": "Rock_Slate"
    },
    {
      "x": -1,
      "y": 3,
      "z": -2,
      "name": "Rock_Slate"
    },
    {
      "x": -1,
      "y": 4,
      "z": -2,
      "name": "Rock_Slate"
    },
    {
      "x": -1,
      "y": 5,
      "z": -2,
      "name": "Rock_Slate"
    },
    {
      "x": -1,
      "y": 6,
      "z": -2,
      "name": "Rock_Slate"
    },
    {
      "x": -1,
      "y": 7,
      "z": -2,
      "name": "Wood_Deadwood_Planks"
    },
    {
      "x": -1,
      "y": 8,
      "z": -2,
      "name": "Empty"
    },
    {
      "x": -1,
      "y": 9,
      "z": -2,
      "name": "Empty"
    },
    {
      "x": -1,
      "y": 10,
      "z": -2,
      "name": "Empty"
    },
    {
      "x": -1,
      "y": 11,
      "z": -2,
      "name": "Wood_Burnt_Branch_Long",
      "rotation": 4
    },
    {
      "x": -1,
      "y": 12,
      "z": -2,
      "name": "Wood_Deadwood_Roof_Flat",
      "rotation": 1
    },
    {
      "x": -1,
      "y": 2,
      "z": -1,
      "name": "Rock_Slate"
    },
    {
      "x": -1,
      "y": 3,
      "z": -1,
      "name": "Rock_Slate"
    },
    {
      "x": -1,
      "y": 4,
      "z": -1,
      "name": "Rock_Slate"
    },
    {
      "x": -1,
      "y": 5,
      "z": -1,
      "name": "Rock_Slate"
    },
    {
      "x": -1,
      "y": 6,
      "z": -1,
      "name": "Rock_Slate"
    },
    {
      "x": -1,
      "y": 7,
      "z": -1,
      "name": "Wood_Deadwood_Planks"
    },
    {
      "x": -1,
      "y": 8,
      "z": -1,
      "name": "Furniture_Human_Ruins_Pot_Small"
    },
    {
      "x": -1,
      "y": 9,
      "z": -1,
      "name": "Empty"
    },
    {
      "x": -1,
      "y": 10,
      "z": -1,
      "name": "Empty"
    },
    {
      "x": -1,
      "y": 11,
      "z": -1,
      "name": "Wood_Burnt_Branch_Long",
      "rotation": 4
    },
    {
      "x": -1,
      "y": 12,
      "z": -1,
      "name": "Wood_Deadwood_Roof_Flat",
      "rotation": 1
    },
    {
      "x": -1,
      "y": 7,
      "z": 0,
      "name": "Wood_Deadwood_Planks"
    },
    {
      "x": -1,
      "y": 8,
      "z": 0,
      "name": "Empty"
    },
    {
      "x": -1,
      "y": 9,
      "z": 0,
      "name": "Empty"
    },
    {
      "x": -1,
      "y": 10,
      "z": 0,
      "name": "Empty"
    },
    {
      "x": -1,
      "y": 11,
      "z": 0,
      "name": "Empty"
    },
    {
      "x": -1,
      "y": 7,
      "z": 1,
      "name": "Wood_Deadwood_Planks"
    },
    {
      "x": -1,
      "y": 8,
      "z": 1,
      "name": "Empty"
    },
    {
      "x": -1,
      "y": 9,
      "z": 1,
      "name": "Empty"
    },
    {
      "x": -1,
      "y": 10,
      "z": 1,
      "name": "Empty"
    },
    {
      "x": -1,
      "y": 11,
      "z": 1,
      "name": "Empty"
    },
    {
      "x": -1,
      "y": 7,
      "z": 2,
      "name": "Wood_Deadwood_Planks"
    },
    {
      "x": -1,
      "y": 8,
      "z": 2,
      "name": "Empty"
    },
    {
      "x": -1,
      "y": 9,
      "z": 2,
      "name": "Empty"
    },
    {
      "x": -1,
      "y": 10,
      "z": 2,
      "name": "Empty"
    },
    {
      "x": -1,
      "y": 11,
      "z": 2,
      "name": "Empty"
    },
    {
      "x": -1,
      "y": 7,
      "z": 3,
      "name": "Wood_Deadwood_Planks"
    },
    {
      "x": -1,
      "y": 8,
      "z": 3,
      "name": "Empty"
    },
    {
      "x": -1,
      "y": 9,
      "z": 3,
      "name": "Empty"
    },
    {
      "x": -1,
      "y": 10,
      "z": 3,
      "name": "Empty"
    },
    {
      "x": -1,
      "y": 11,
      "z": 3,
      "name": "Wood_Burnt_Branch_Long",
      "rotation": 4
    },
    {
      "x": -1,
      "y": 12,
      "z": 3,
      "name": "Wood_Deadwood_Roof_Flat",
      "rotation": 1
    },
    {
      "x": -1,
      "y": 7,
      "z": 4,
      "name": "Wood_Deadwood_Planks"
    },
    {
      "x": -1,
      "y": 8,
      "z": 4,
      "name": "Furniture_Ancient_Barrel"
    },
    {
      "x": -1,
      "y": 9,
      "z": 4,
      "name": "Empty"
    },
    {
      "x": -1,
      "y": 10,
      "z": 4,
      "name": "Empty"
    },
    {
      "x": -1,
      "y": 11,
      "z": 4,
      "name": "Wood_Burnt_Branch_Long",
      "rotation": 4
    },
    {
      "x": -1,
      "y": 12,
      "z": 4,
      "name": "Wood_Deadwood_Roof_Flat",
      "rotation": 1
    },
    {
      "x": -1,
      "y": 2,
      "z": 5,
      "name": "Rock_Volcanic"
    },
    {
      "x": -1,
      "y": 3,
      "z": 5,
      "name": "Rock_Volcanic"
    },
    {
      "x": -1,
      "y": 4,
      "z": 5,
      "name": "Rock_Volcanic"
    },
    {
      "x": -1,
      "y": 5,
      "z": 5,
      "name": "Rock_Volcanic_Cobble"
    },
    {
      "x": -1,
      "y": 6,
      "z": 5,
      "name": "Rock_Volcanic_Cobble"
    },
    {
      "x": -1,
      "y": 7,
      "z": 5,
      "name": "Rock_Basalt_Brick"
    },
    {
      "x": -1,
      "y": 8,
      "z": 5,
      "name": "Rock_Basalt_Brick"
    },
    {
      "x": -1,
      "y": 9,
      "z": 5,
      "name": "Rock_Basalt_Cobble"
    },
    {
      "x": -1,
      "y": 10,
      "z": 5,
      "name": "Rock_Basalt_Cobble"
    },
    {
      "x": -1,
      "y": 11,
      "z": 5,
      "name": "Rock_Basalt_Cobble"
    },
    {
      "x": -1,
      "y": 12,
      "z": 5,
      "name": "Wood_Deadwood_Roof_Flat",
      "rotation": 1
    },
    {
      "x": 0,
      "y": 2,
      "z": -3,
      "name": "Rock_Volcanic"
    },
    {
      "x": 0,
      "y": 3,
      "z": -3,
      "name": "Rock_Volcanic"
    },
    {
      "x": 0,
      "y": 4,
      "z": -3,
      "name": "Rock_Volcanic"
    },
    {
      "x": 0,
      "y": 5,
      "z": -3,
      "name": "Rock_Volcanic_Cobble"
    },
    {
      "x": 0,
      "y": 6,
      "z": -3,
      "name": "Rock_Volcanic_Cobble"
    },
    {
      "x": 0,
      "y": 7,
      "z": -3,
      "name": "Rock_Basalt_Brick"
    },
    {
      "x": 0,
      "y": 8,
      "z": -3,
      "name": "*Furniture_Human_Ruins_Door_State_Definitions_CloseDoorIn",
      "rotation": 2
    },
    {
      "x": 0,
      "y": 9,
      "z": -3,
      "name": "*Furniture_Human_Ruins_Door_State_Definitions_CloseDoorIn",
      "filler": 1024,
      "rotation": 2
    },
    {
      "x": 0,
      "y": 10,
      "z": -3,
      "name": "Rock_Basalt_Cobble"
    },
    {
      "x": 0,
      "y": 11,
      "z": -3,
      "name": "Rock_Basalt_Cobble"
    },
    {
      "x": 0,
      "y": 12,
      "z": -3,
      "name": "Wood_Deadwood_Roof_Flat",
      "rotation": 1
    },
    {
      "x": 0,
      "y": 3,
      "z": -2,
      "name": "Rock_Slate"
    },
    {
      "x": 0,
      "y": 5,
      "z": -2,
      "name": "Rock_Slate"
    },
    {
      "x": 0,
      "y": 6,
      "z": -2,
      "name": "Rock_Slate"
    },
    {
      "x": 0,
      "y": 7,
      "z": -2,
      "name": "Wood_Deadwood_Planks"
    },
    {
      "x": 0,
      "y": 8,
      "z": -2,
      "name": "Empty"
    },
    {
      "x": 0,
      "y": 9,
      "z": -2,
      "name": "Empty"
    },
    {
      "x": 0,
      "y": 10,
      "z": -2,
      "name": "Empty"
    },
    {
      "x": 0,
      "y": 11,
      "z": -2,
      "name": "Empty"
    },
    {
      "x": 0,
      "y": 12,
      "z": -2,
      "name": "Wood_Deadwood_Roof_Flat",
      "rotation": 1
    },
    {
      "x": 0,
      "y": 7,
      "z": -1,
      "name": "Wood_Deadwood_Planks"
    },
    {
      "x": 0,
      "y": 8,
      "z": -1,
      "name": "Empty"
    },
    {
      "x": 0,
      "y": 9,
      "z": -1,
      "name": "Empty"
    },
    {
      "x": 0,
      "y": 10,
      "z": -1,
      "name": "Empty"
    },
    {
      "x": 0,
      "y": 11,
      "z": -1,
      "name": "Empty"
    },
    {
      "x": 0,
      "y": 12,
      "z": -1,
      "name": "Wood_Deadwood_Roof_Flat",
      "rotation": 1
    },
    {
      "x": 0,
      "y": 7,
      "z": 0,
      "name": "Wood_Deadwood_Planks"
    },
    {
      "x": 0,
      "y": 8,
      "z": 0,
      "name": "Empty"
    },
    {
      "x": 0,
      "y": 9,
      "z": 0,
      "name": "Empty"
    },
    {
      "x": 0,
      "y": 10,
      "z": 0,
      "name": "Empty"
    },
    {
      "x": 0,
      "y": 11,
      "z": 0,
      "name": "Empty"
    },
    {
      "x": 0,
      "y": 7,
      "z": 1,
      "name": "Furniture_Ancient_Platform"
    },
    {
      "x": 0,
      "y": 8,
      "z": 1,
      "name": "Empty"
    },
    {
      "x": 0,
      "y": 9,
      "z": 1,
      "name": "Empty"
    },
    {
      "x": 0,
      "y": 10,
      "z": 1,
      "name": "Empty"
    },
    {
      "x": 0,
      "y": 11,
      "z": 1,
      "name": "Empty"
    },
    {
      "x": 0,
      "y": 7,
      "z": 2,
      "name": "Furniture_Ancient_Platform"
    },
    {
      "x": 0,
      "y": 8,
      "z": 2,
      "name": "Empty"
    },
    {
      "x": 0,
      "y": 9,
      "z": 2,
      "name": "Empty"
    },
    {
      "x": 0,
      "y": 10,
      "z": 2,
      "name": "Empty"
    },
    {
      "x": 0,
      "y": 11,
      "z": 2,
      "name": "Empty"
    },
    {
      "x": 0,
      "y": 7,
      "z": 3,
      "name": "Wood_Deadwood_Planks"
    },
    {
      "x": 0,
      "y": 8,
      "z": 3,
      "name": "Empty"
    },
    {
      "x": 0,
      "y": 9,
      "z": 3,
      "name": "Empty"
    },
    {
      "x": 0,
      "y": 10,
      "z": 3,
      "name": "Empty"
    },
    {
      "x": 0,
      "y": 11,
      "z": 3,
      "name": "Empty"
    },
    {
      "x": 0,
      "y": 7,
      "z": 4,
      "name": "Wood_Deadwood_Planks"
    },
    {
      "x": 0,
      "y": 8,
      "z": 4,
      "name": "Empty"
    },
    {
      "x": 0,
      "y": 9,
      "z": 4,
      "name": "Empty"
    },
    {
      "x": 0,
      "y": 10,
      "z": 4,
      "name": "Empty"
    },
    {
      "x": 0,
      "y": 11,
      "z": 4,
      "name": "Empty"
    },
    {
      "x": 0,
      "y": 12,
      "z": 4,
      "name": "Wood_Deadwood_Roof_Flat",
      "rotation": 1
    },
    {
      "x": 0,
      "y": 2,
      "z": 5,
      "name": "Rock_Volcanic"
    },
    {
      "x": 0,
      "y": 3,
      "z": 5,
      "name": "Rock_Volcanic"
    },
    {
      "x": 0,
      "y": 4,
      "z": 5,
      "name": "Rock_Volcanic"
    },
    {
      "x": 0,
      "y": 5,
      "z": 5,
      "name": "Rock_Volcanic_Cobble"
    },
    {
      "x": 0,
      "y": 6,
      "z": 5,
      "name": "Rock_Volcanic_Cobble"
    },
    {
      "x": 0,
      "y": 7,
      "z": 5,
      "name": "Rock_Basalt_Brick"
    },
    {
      "x": 0,
      "y": 8,
      "z": 5,
      "name": "*Furniture_Human_Ruins_Door_State_Definitions_CloseDoorOut"
    },
    {
      "x": 0,
      "y": 9,
      "z": 5,
      "name": "*Furniture_Human_Ruins_Door_State_Definitions_CloseDoorOut",
      "filler": 1024
    },
    {
      "x": 0,
      "y": 10,
      "z": 5,
      "name": "Rock_Basalt_Cobble"
    },
    {
      "x": 0,
      "y": 11,
      "z": 5,
      "name": "Rock_Basalt_Cobble"
    },
    {
      "x": 0,
      "y": 12,
      "z": 5,
      "name": "Wood_Deadwood_Roof_Flat",
      "rotation": 1
    },
    {
      "x": 1,
      "y": 4,
      "z": -3,
      "name": "Rock_Volcanic"
    },
    {
      "x": 1,
      "y": 5,
      "z": -3,
      "name": "Rock_Volcanic_Cobble"
    },
    {
      "x": 1,
      "y": 6,
      "z": -3,
      "name": "Rock_Volcanic_Cobble"
    },
    {
      "x": 1,
      "y": 7,
      "z": -3,
      "name": "Rock_Basalt_Brick"
    },
    {
      "x": 1,
      "y": 8,
      "z": -3,
      "name": "Rock_Basalt_Brick"
    },
    {
      "x": 1,
      "y": 9,
      "z": -3,
      "name": "Rock_Basalt_Cobble"
    },
    {
      "x": 1,
      "y": 10,
      "z": -3,
      "name": "Rock_Basalt_Brick"
    },
    {
      "x": 1,
      "y": 11,
      "z": -3,
      "name": "Rock_Basalt_Brick"
    },
    {
      "x": 1,
      "y": 7,
      "z": -2,
      "name": "Wood_Deadwood_Planks"
    },
    {
      "x": 1,
      "y": 8,
      "z": -2,
      "name": "*Wood_Deadwood_Fence_State_Definitions_Corner",
      "rotation": 1
    },
    {
      "x": 1,
      "y": 9,
      "z": -2,
      "name": "Wood_Deadwood_Beam"
    },
    {
      "x": 1,
      "y": 10,
      "z": -2,
      "name": "Wood_Deadwood_Beam"
    },
    {
      "x": 1,
      "y": 11,
      "z": -2,
      "name": "Wood_Deadwood_Beam"
    },
    {
      "x": 1,
      "y": 12,
      "z": -2,
      "name": "Wood_Deadwood_Roof_Flat",
      "rotation": 1
    },
    {
      "x": 1,
      "y": 7,
      "z": -1,
      "name": "Wood_Deadwood_Planks"
    },
    {
      "x": 1,
      "y": 8,
      "z": -1,
      "name": "Wood_Deadwood_Fence",
      "rotation": 1
    },
    {
      "x": 1,
      "y": 9,
      "z": -1,
      "name": "Empty"
    },
    {
      "x": 1,
      "y": 10,
      "z": -1,
      "name": "Empty"
    },
    {
      "x": 1,
      "y": 11,
      "z": -1,
      "name": "Empty"
    },
    {
      "x": 1,
      "y": 12,
      "z": -1,
      "name": "Wood_Deadwood_Roof_Flat",
      "rotation": 1
    },
    {
      "x": 1,
      "y": 7,
      "z": 0,
      "name": "Wood_Deadwood_Planks"
    },
    {
      "x": 1,
      "y": 8,
      "z": 0,
      "name": "Empty"
    },
    {
      "x": 1,
      "y": 9,
      "z": 0,
      "name": "Empty"
    },
    {
      "x": 1,
      "y": 10,
      "z": 0,
      "name": "Empty"
    },
    {
      "x": 1,
      "y": 11,
      "z": 0,
      "name": "Empty"
    },
    {
      "x": 1,
      "y": 12,
      "z": 0,
      "name": "Wood_Deadwood_Roof_Flat",
      "rotation": 1
    },
    {
      "x": 1,
      "y": 7,
      "z": 1,
      "name": "Furniture_Ancient_Platform"
    },
    {
      "x": 1,
      "y": 8,
      "z": 1,
      "name": "*Wood_Deadwood_Fence_State_Definitions_Corner",
      "rotation": 2
    },
    {
      "x": 1,
      "y": 9,
      "z": 1,
      "name": "Empty"
    },
    {
      "x": 1,
      "y": 10,
      "z": 1,
      "name": "Empty"
    },
    {
      "x": 1,
      "y": 11,
      "z": 1,
      "name": "Empty"
    },
    {
      "x": 1,
      "y": 7,
      "z": 2,
      "name": "Furniture_Ancient_Platform"
    },
    {
      "x": 1,
      "y": 8,
      "z": 2,
      "name": "Empty"
    },
    {
      "x": 1,
      "y": 9,
      "z": 2,
      "name": "Empty"
    },
    {
      "x": 1,
      "y": 10,
      "z": 2,
      "name": "Empty"
    },
    {
      "x": 1,
      "y": 11,
      "z": 2,
      "name": "Empty"
    },
    {
      "x": 1,
      "y": 7,
      "z": 3,
      "name": "Wood_Deadwood_Planks"
    },
    {
      "x": 1,
      "y": 8,
      "z": 3,
      "name": "Wood_Deadwood_Fence",
      "rotation": 3
    },
    {
      "x": 1,
      "y": 9,
      "z": 3,
      "name": "Empty"
    },
    {
      "x": 1,
      "y": 10,
      "z": 3,
      "name": "Empty"
    },
    {
      "x": 1,
      "y": 11,
      "z": 3,
      "name": "Empty"
    },
    {
      "x": 1,
      "y": 7,
      "z": 4,
      "name": "Wood_Deadwood_Planks"
    },
    {
      "x": 1,
      "y": 8,
      "z": 4,
      "name": "*Wood_Deadwood_Fence_State_Definitions_Corner",
      "rotation": 2
    },
    {
      "x": 1,
      "y": 9,
      "z": 4,
      "name": "Wood_Deadwood_Beam"
    },
    {
      "x": 1,
      "y": 10,
      "z": 4,
      "name": "Empty"
    },
    {
      "x": 1,
      "y": 11,
      "z": 4,
      "name": "Empty"
    },
    {
      "x": 1,
      "y": 1,
      "z": 5,
      "name": "Rock_Volcanic"
    },
    {
      "x": 1,
      "y": 2,
      "z": 5,
      "name": "Rock_Volcanic"
    },
    {
      "x": 1,
      "y": 3,
      "z": 5,
      "name": "Rock_Volcanic"
    },
    {
      "x": 1,
      "y": 4,
      "z": 5,
      "name": "Rock_Volcanic"
    },
    {
      "x": 1,
      "y": 5,
      "z": 5,
      "name": "Rock_Volcanic_Cobble"
    },
    {
      "x": 1,
      "y": 6,
      "z": 5,
      "name": "Rock_Volcanic_Cobble"
    },
    {
      "x": 1,
      "y": 7,
      "z": 5,
      "name": "Rock_Basalt_Brick"
    },
    {
      "x": 1,
      "y": 8,
      "z": 5,
      "name": "Rock_Basalt_Brick"
    },
    {
      "x": 1,
      "y": 9,
      "z": 5,
      "name": "Empty"
    },
    {
      "x": 1,
      "y": 10,
      "z": 5,
      "name": "Empty"
    },
    {
      "x": 1,
      "y": 11,
      "z": 5,
      "name": "Empty"
    },
    {
      "x": 2,
      "y": 8,
      "z": -3,
      "name": "Rock_Basalt_Brick"
    },
    {
      "x": 2,
      "y": 9,
      "z": -3,
      "name": "Rock_Basalt_Brick"
    },
    {
      "x": 2,
      "y": 10,
      "z": -3,
      "name": "Rock_Basalt_Brick"
    },
    {
      "x": 2,
      "y": 11,
      "z": -3,
      "name": "Empty"
    },
    {
      "x": 2,
      "y": 7,
      "z": -2,
      "name": "Wood_Deadwood_Planks"
    },
    {
      "x": 2,
      "y": 8,
      "z": -2,
      "name": "Wood_Deadwood_Fence"
    },
    {
      "x": 2,
      "y": 9,
      "z": -2,
      "name": "Empty"
    },
    {
      "x": 2,
      "y": 10,
      "z": -2,
      "name": "Empty"
    },
    {
      "x": 2,
      "y": 11,
      "z": -2,
      "name": "Empty"
    },
    {
      "x": 2,
      "y": 12,
      "z": -2,
      "name": "Wood_Deadwood_Roof_Flat",
      "rotation": 1
    },
    {
      "x": 2,
      "y": 7,
      "z": -1,
      "name": "Wood_Deadwood_Planks"
    },
    {
      "x": 2,
      "y": 8,
      "z": -1,
      "name": "Empty"
    },
    {
      "x": 2,
      "y": 9,
      "z": -1,
      "name": "Empty"
    },
    {
      "x": 2,
      "y": 10,
      "z": -1,
      "name": "Empty"
    },
    {
      "x": 2,
      "y": 11,
      "z": -1,
      "name": "Empty"
    },
    {
      "x": 2,
      "y": 12,
      "z": -1,
      "name": "Wood_Deadwood_Roof_Flat",
      "rotation": 1
    },
    {
      "x": 2,
      "y": 7,
      "z": 0,
      "name": "Wood_Deadwood_Planks"
    },
    {
      "x": 2,
      "y": 8,
      "z": 0,
      "name": "Empty"
    },
    {
      "x": 2,
      "y": 9,
      "z": 0,
      "name": "Empty"
    },
    {
      "x": 2,
      "y": 10,
      "z": 0,
      "name": "Empty"
    },
    {
      "x": 2,
      "y": 11,
      "z": 0,
      "name": "Empty"
    },
    {
      "x": 2,
      "y": 12,
      "z": 0,
      "name": "Wood_Deadwood_Roof_Flat",
      "rotation": 1
    },
    {
      "x": 2,
      "y": 7,
      "z": 1,
      "name": "Wood_Deadwood_Planks"
    },
    {
      "x": 2,
      "y": 8,
      "z": 1,
      "name": "Wood_Deadwood_Fence",
      "rotation": 2
    },
    {
      "x": 2,
      "y": 9,
      "z": 1,
      "name": "Empty"
    },
    {
      "x": 2,
      "y": 10,
      "z": 1,
      "name": "Empty"
    },
    {
      "x": 2,
      "y": 11,
      "z": 1,
      "name": "Empty"
    },
    {
      "x": 2,
      "y": 12,
      "z": 1,
      "name": "Wood_Deadwood_Roof_Flat",
      "rotation": 1
    },
    {
      "x": 2,
      "y": 7,
      "z": 2,
      "name": "Wood_Deadwood_Planks"
    },
    {
      "x": 2,
      "y": 8,
      "z": 2,
      "name": "Empty"
    },
    {
      "x": 2,
      "y": 9,
      "z": 2,
      "name": "Empty"
    },
    {
      "x": 2,
      "y": 10,
      "z": 2,
      "name": "Empty"
    },
    {
      "x": 2,
      "y": 11,
      "z": 2,
      "name": "Empty"
    },
    {
      "x": 2,
      "y": 7,
      "z": 3,
      "name": "Furniture_Ancient_Platform"
    },
    {
      "x": 2,
      "y": 8,
      "z": 3,
      "name": "Empty"
    },
    {
      "x": 2,
      "y": 9,
      "z": 3,
      "name": "Empty"
    },
    {
      "x": 2,
      "y": 10,
      "z": 3,
      "name": "Empty"
    },
    {
      "x": 2,
      "y": 11,
      "z": 3,
      "name": "Empty"
    },
    {
      "x": 2,
      "y": 7,
      "z": 4,
      "name": "Wood_Deadwood_Planks"
    },
    {
      "x": 2,
      "y": 8,
      "z": 4,
      "name": "Plant_Hay_Bundle"
    },
    {
      "x": 2,
      "y": 9,
      "z": 4,
      "name": "Empty"
    },
    {
      "x": 2,
      "y": 10,
      "z": 4,
      "name": "Empty"
    },
    {
      "x": 2,
      "y": 11,
      "z": 4,
      "name": "Empty"
    },
    {
      "x": 2,
      "y": 1,
      "z": 5,
      "name": "Rock_Volcanic"
    },
    {
      "x": 2,
      "y": 2,
      "z": 5,
      "name": "Rock_Volcanic"
    },
    {
      "x": 2,
      "y": 3,
      "z": 5,
      "name": "Rock_Volcanic"
    },
    {
      "x": 2,
      "y": 4,
      "z": 5,
      "name": "Rock_Volcanic"
    },
    {
      "x": 2,
      "y": 5,
      "z": 5,
      "name": "Rock_Volcanic_Cobble"
    },
    {
      "x": 2,
      "y": 6,
      "z": 5,
      "name": "Rock_Volcanic_Cobble"
    },
    {
      "x": 2,
      "y": 7,
      "z": 5,
      "name": "Rock_Basalt_Brick"
    },
    {
      "x": 2,
      "y": 8,
      "z": 5,
      "name": "Rock_Basalt_Brick"
    },
    {
      "x": 2,
      "y": 9,
      "z": 5,
      "name": "Rock_Basalt_Brick"
    },
    {
      "x": 2,
      "y": 10,
      "z": 5,
      "name": "Empty"
    },
    {
      "x": 2,
      "y": 11,
      "z": 5,
      "name": "Empty"
    },
    {
      "x": 3,
      "y": 6,
      "z": -3,
      "name": "Rock_Volcanic_Cobble"
    },
    {
      "x": 3,
      "y": 7,
      "z": -3,
      "name": "Rock_Volcanic_Cobble"
    },
    {
      "x": 3,
      "y": 8,
      "z": -3,
      "name": "Rock_Basalt_Brick"
    },
    {
      "x": 3,
      "y": 9,
      "z": -3,
      "name": "Wood_Deadwood_Planks"
    },
    {
      "x": 3,
      "y": 10,
      "z": -3,
      "name": "Wood_Deadwood_Planks"
    },
    {
      "x": 3,
      "y": 11,
      "z": -3,
      "name": "Wood_Deadwood_Roof",
      "rotation": 1
    },
    {
      "x": 3,
      "y": 7,
      "z": -2,
      "name": "Wood_Deadwood_Planks"
    },
    {
      "x": 3,
      "y": 8,
      "z": -2,
      "name": "Wood_Deadwood_Fence"
    },
    {
      "x": 3,
      "y": 9,
      "z": -2,
      "name": "Furniture_Human_Ruins_Torch",
      "rotation": 3
    },
    {
      "x": 3,
      "y": 10,
      "z": -2,
      "name": "Empty"
    },
    {
      "x": 3,
      "y": 11,
      "z": -2,
      "name": "Wood_Deadwood_Roof_Hollow",
      "rotation": 1
    },
    {
      "x": 3,
      "y": 7,
      "z": -1,
      "name": "Wood_Deadwood_Planks"
    },
    {
      "x": 3,
      "y": 8,
      "z": -1,
      "name": "Plant_Hay_Bundle"
    },
    {
      "x": 3,
      "y": 9,
      "z": -1,
      "name": "Empty"
    },
    {
      "x": 3,
      "y": 10,
      "z": -1,
      "name": "Empty"
    },
    {
      "x": 3,
      "y": 11,
      "z": -1,
      "name": "Wood_Deadwood_Roof_Hollow",
      "rotation": 1
    },
    {
      "x": 3,
      "y": 7,
      "z": 0,
      "name": "Wood_Deadwood_Planks"
    },
    {
      "x": 3,
      "y": 8,
      "z": 0,
      "name": "Block_Spawner_Block",
      "components": {
        "Components": {
          "PlacedByInteraction": {
            "WhoPlacedUuid": {
              "$binary": "5OYreBmdMS+xlzjMlwn5JQ==",
              "$type": "04"
            }
          },
          "BlockSpawner": {
            "BlockSpawnerId": "Zone4_Encounters_Tier1"
          }
        }
      },
      "rotation": 3
    },
    {
      "x": 3,
      "y": 9,
      "z": 0,
      "name": "Empty"
    },
    {
      "x": 3,
      "y": 10,
      "z": 0,
      "name": "Empty"
    },
    {
      "x": 3,
      "y": 11,
      "z": 0,
      "name": "Wood_Deadwood_Roof_Hollow",
      "rotation": 1
    },
    {
      "x": 3,
      "y": 7,
      "z": 1,
      "name": "Wood_Deadwood_Planks"
    },
    {
      "x": 3,
      "y": 8,
      "z": 1,
      "name": "Wood_Deadwood_Fence",
      "rotation": 2
    },
    {
      "x": 3,
      "y": 9,
      "z": 1,
      "name": "Empty"
    },
    {
      "x": 3,
      "y": 10,
      "z": 1,
      "name": "Empty"
    },
    {
      "x": 3,
      "y": 11,
      "z": 1,
      "name": "Wood_Deadwood_Beam",
      "rotation": 4
    },
    {
      "x": 3,
      "y": 7,
      "z": 2,
      "name": "Wood_Deadwood_Planks"
    },
    {
      "x": 3,
      "y": 8,
      "z": 2,
      "name": "Empty"
    },
    {
      "x": 3,
      "y": 9,
      "z": 2,
      "name": "Empty"
    },
    {
      "x": 3,
      "y": 10,
      "z": 2,
      "name": "Empty"
    },
    {
      "x": 3,
      "y": 11,
      "z": 2,
      "name": "Wood_Deadwood_Beam",
      "rotation": 4
    },
    {
      "x": 3,
      "y": 7,
      "z": 3,
      "name": "Wood_Deadwood_Planks"
    },
    {
      "x": 3,
      "y": 8,
      "z": 3,
      "name": "Empty"
    },
    {
      "x": 3,
      "y": 9,
      "z": 3,
      "name": "Empty"
    },
    {
      "x": 3,
      "y": 10,
      "z": 3,
      "name": "Empty"
    },
    {
      "x": 3,
      "y": 7,
      "z": 4,
      "name": "Wood_Deadwood_Planks"
    },
    {
      "x": 3,
      "y": 8,
      "z": 4,
      "name": "Wood_Deadwood_Fence",
      "rotation": 2
    },
    {
      "x": 3,
      "y": 9,
      "z": 4,
      "name": "Empty"
    },
    {
      "x": 3,
      "y": 10,
      "z": 4,
      "name": "Empty"
    },
    {
      "x": 3,
      "y": 11,
      "z": 4,
      "name": "Wood_Deadwood_Beam",
      "rotation": 4
    },
    {
      "x": 3,
      "y": 2,
      "z": 5,
      "name": "Rock_Volcanic"
    },
    {
      "x": 3,
      "y": 3,
      "z": 5,
      "name": "Rock_Volcanic"
    },
    {
      "x": 3,
      "y": 4,
      "z": 5,
      "name": "Rock_Volcanic"
    },
    {
      "x": 3,
      "y": 5,
      "z": 5,
      "name": "Rock_Volcanic"
    },
    {
      "x": 3,
      "y": 6,
      "z": 5,
      "name": "Rock_Volcanic_Cobble"
    },
    {
      "x": 3,
      "y": 7,
      "z": 5,
      "name": "Rock_Basalt_Brick"
    },
    {
      "x": 3,
      "y": 8,
      "z": 5,
      "name": "Rock_Basalt_Brick"
    },
    {
      "x": 3,
      "y": 9,
      "z": 5,
      "name": "Wood_Deadwood_Planks"
    },
    {
      "x": 3,
      "y": 10,
      "z": 5,
      "name": "Wood_Deadwood_Planks"
    },
    {
      "x": 3,
      "y": 11,
      "z": 5,
      "name": "Wood_Deadwood_Roof",
      "rotation": 1
    },
    {
      "x": 4,
      "y": 5,
      "z": -3,
      "name": "Rock_Volcanic_Cobble"
    },
    {
      "x": 4,
      "y": 6,
      "z": -3,
      "name": "Rock_Volcanic_Cobble"
    },
    {
      "x": 4,
      "y": 7,
      "z": -3,
      "name": "Rock_Basalt_Brick"
    },
    {
      "x": 4,
      "y": 8,
      "z": -3,
      "name": "Rock_Basalt_Brick"
    },
    {
      "x": 4,
      "y": 9,
      "z": -3,
      "name": "Wood_Deadwood_Planks"
    },
    {
      "x": 4,
      "y": 10,
      "z": -3,
      "name": "Wood_Deadwood_Roof",
      "rotation": 1
    },
    {
      "x": 4,
      "y": 3,
      "z": -2,
      "name": "Rock_Volcanic"
    },
    {
      "x": 4,
      "y": 4,
      "z": -2,
      "name": "Rock_Volcanic"
    },
    {
      "x": 4,
      "y": 5,
      "z": -2,
      "name": "Rock_Volcanic_Cobble"
    },
    {
      "x": 4,
      "y": 6,
      "z": -2,
      "name": "Rock_Volcanic_Cobble"
    },
    {
      "x": 4,
      "y": 7,
      "z": -2,
      "name": "Rock_Basalt_Brick"
    },
    {
      "x": 4,
      "y": 8,
      "z": -2,
      "name": "Rock_Basalt_Brick"
    },
    {
      "x": 4,
      "y": 9,
      "z": -2,
      "name": "Wood_Deadwood_Planks"
    },
    {
      "x": 4,
      "y": 10,
      "z": -2,
      "name": "Wood_Deadwood_Roof",
      "rotation": 1
    },
    {
      "x": 4,
      "y": 3,
      "z": -1,
      "name": "Rock_Volcanic"
    },
    {
      "x": 4,
      "y": 4,
      "z": -1,
      "name": "Rock_Volcanic"
    },
    {
      "x": 4,
      "y": 5,
      "z": -1,
      "name": "Rock_Volcanic_Cobble"
    },
    {
      "x": 4,
      "y": 6,
      "z": -1,
      "name": "Rock_Volcanic_Cobble"
    },
    {
      "x": 4,
      "y": 7,
      "z": -1,
      "name": "Rock_Basalt_Brick"
    },
    {
      "x": 4,
      "y": 8,
      "z": -1,
      "name": "Rock_Basalt_Brick"
    },
    {
      "x": 4,
      "y": 9,
      "z": -1,
      "name": "Wood_Deadwood_Planks"
    },
    {
      "x": 4,
      "y": 10,
      "z": -1,
      "name": "Wood_Deadwood_Roof",
      "rotation": 1
    },
    {
      "x": 4,
      "y": 3,
      "z": 0,
      "name": "Rock_Volcanic"
    },
    {
      "x": 4,
      "y": 4,
      "z": 0,
      "name": "Rock_Volcanic"
    },
    {
      "x": 4,
      "y": 5,
      "z": 0,
      "name": "Rock_Volcanic"
    },
    {
      "x": 4,
      "y": 6,
      "z": 0,
      "name": "Rock_Volcanic_Cobble"
    },
    {
      "x": 4,
      "y": 7,
      "z": 0,
      "name": "Rock_Volcanic_Cobble"
    },
    {
      "x": 4,
      "y": 8,
      "z": 0,
      "name": "Rock_Basalt_Brick"
    },
    {
      "x": 4,
      "y": 9,
      "z": 0,
      "name": "Wood_Deadwood_Planks"
    },
    {
      "x": 4,
      "y": 10,
      "z": 0,
      "name": "Wood_Deadwood_Roof",
      "rotation": 1
    },
    {
      "x": 4,
      "y": 6,
      "z": 1,
      "name": "Rock_Volcanic_Cobble"
    },
    {
      "x": 4,
      "y": 7,
      "z": 1,
      "name": "Rock_Volcanic_Cobble"
    },
    {
      "x": 4,
      "y": 8,
      "z": 1,
      "name": "Rock_Basalt_Brick"
    },
    {
      "x": 4,
      "y": 10,
      "z": 1,
      "name": "Wood_Deadwood_Roof",
      "rotation": 1
    },
    {
      "x": 4,
      "y": 5,
      "z": 3,
      "name": "Rock_Volcanic_Cobble"
    },
    {
      "x": 4,
      "y": 6,
      "z": 3,
      "name": "Rock_Volcanic_Cobble"
    },
    {
      "x": 4,
      "y": 3,
      "z": 4,
      "name": "Rock_Volcanic"
    },
    {
      "x": 4,
      "y": 4,
      "z": 4,
      "name": "Rock_Volcanic"
    },
    {
      "x": 4,
      "y": 5,
      "z": 4,
      "name": "Rock_Volcanic_Cobble"
    },
    {
      "x": 4,
      "y": 6,
      "z": 4,
      "name": "Rock_Volcanic_Cobble"
    },
    {
      "x": 4,
      "y": 7,
      "z": 4,
      "name": "Rock_Basalt_Brick"
    },
    {
      "x": 4,
      "y": 8,
      "z": 4,
      "name": "Rock_Basalt_Brick"
    },
    {
      "x": 4,
      "y": 9,
      "z": 4,
      "name": "Wood_Deadwood_Planks"
    },
    {
      "x": 4,
      "y": 10,
      "z": 4,
      "name": "Wood_Deadwood_Roof",
      "rotation": 1
    },
    {
      "x": 4,
      "y": 3,
      "z": 5,
      "name": "Rock_Volcanic"
    },
    {
      "x": 4,
      "y": 4,
      "z": 5,
      "name": "Rock_Volcanic"
    },
    {
      "x": 4,
      "y": 5,
      "z": 5,
      "name": "Rock_Volcanic"
    },
    {
      "x": 4,
      "y": 6,
      "z": 5,
      "name": "Rock_Volcanic"
    },
    {
      "x": 4,
      "y": 7,
      "z": 5,
      "name": "Rock_Basalt_Brick"
    },
    {
      "x": 4,
      "y": 8,
      "z": 5,
      "name": "Rock_Basalt_Brick"
    },
    {
      "x": 4,
      "y": 9,
      "z": 5,
      "name": "Wood_Deadwood_Planks"
    },
    {
      "x": 4,
      "y": 10,
      "z": 5,
      "name": "Wood_Deadwood_Roof",
      "rotation": 1
    }
  ]
}