{
  "version": 8,
  "blockIdVersion": 8,
  "anchorX": 0,
  "anchorY": 4,
  "anchorZ": 1,
  "blocks": [
    {
      "x": -6,
      "y": 5,
      "z": 0,
      "name": "Rock_Volcanic"
    },
    {
      "x": -6,
      "y": 6,
      "z": 0,
      "name": "Rock_Volcanic"
    },
    {
      "x": -6,
      "y": 7,
      "z": 0,
      "name": "Rock_Volcanic"
    },
    {
      "x": -6,
      "y": 5,
      "z": 1,
      "name": "Rock_Volcanic"
    },
    {
      "x": -6,
      "y": 6,
      "z": 1,
      "name": "Rock_Volcanic"
    },
    {
      "x": -6,
      "y": 7,
      "z": 1,
      "name": "Rock_Volcanic"
    },
    {
      "x": -6,
      "y": 6,
      "z": 2,
      "name": "Rock_Volcanic"
    },
    {
      "x": -6,
      "y": 7,
      "z": 2,
      "name": "Rock_Volcanic"
    },
    {
      "x": -5,
      "y": 3,
      "z": -4,
      "name": "Rock_Slate"
    },
    {
      "x": -5,
      "y": 4,
      "z": -4,
      "name": "Rock_Slate"
    },
    {
      "x": -5,
      "y": 5,
      "z": -4,
      "name": "Rock_Slate"
    },
    {
      "x": -5,
      "y": 6,
      "z": -4,
      "name": "Rock_Slate"
    },
    {
      "x": -5,
      "y": 3,
      "z": -3,
      "name": "Rock_Slate"
    },
    {
      "x": -5,
      "y": 4,
      "z": -3,
      "name": "Rock_Slate"
    },
    {
      "x": -5,
      "y": 5,
      "z": -3,
      "name": "Rock_Slate"
    },
    {
      "x": -5,
      "y": 6,
      "z": -3,
      "name": "Rock_Slate"
    },
    {
      "x": -5,
      "y": 3,
      "z": -2,
      "name": "Rock_Volcanic"
    },
    {
      "x": -5,
      "y": 4,
      "z": -2,
      "name": "Rock_Volcanic"
    },
    {
      "x": -5,
      "y": 5,
      "z": -2,
      "name": "Rock_Slate"
    },
    {
      "x": -5,
      "y": 3,
      "z": -1,
      "name": "Rock_Volcanic"
    },
    {
      "x": -5,
      "y": 4,
      "z": -1,
      "name": "Rock_Volcanic"
    },
    {
      "x": -5,
      "y": 5,
      "z": -1,
      "name": "Rock_Volcanic"
    },
    {
      "x": -5,
      "y": 6,
      "z": -1,
      "name": "Rock_Volcanic_Cobble"
    },
    {
      "x": -5,
      "y": 7,
      "z": -1,
      "name": "Rock_Volcanic_Cobble"
    },
    {
      "x": -5,
      "y": 8,
      "z": -1,
      "name": "Rock_Basalt_Brick"
    },
    {
      "x": -5,
      "y": 9,
      "z": -1,
      "name": "Rock_Basalt_Cobble"
    },
    {
      "x": -5,
      "y": 10,
      "z": -1,
      "name": "Wood_Burnt_Branch_Long"
    },
    {
      "x": -5,
      "y": 11,
      "z": -1,
      "name": "Wood_Burnt_Branch_Long"
    },
    {
      "x": -5,
      "y": 12,
      "z": -1,
      "name": "Wood_Deadwood_Roof_Flat",
      "rotation": 1
    },
    {
      "x": -5,
      "y": 3,
      "z": 0,
      "name": "Rock_Volcanic"
    },
    {
      "x": -5,
      "y": 4,
      "z": 0,
      "name": "Rock_Volcanic"
    },
    {
      "x": -5,
      "y": 5,
      "z": 0,
      "name": "Rock_Volcanic"
    },
    {
      "x": -5,
      "y": 6,
      "z": 0,
      "name": "Rock_Volcanic"
    },
    {
      "x": -5,
      "y": 7,
      "z": 0,
      "name": "Rock_Volcanic"
    },
    {
      "x": -5,
      "y": 8,
      "z": 0,
      "name": "Wood_Deadwood_Planks"
    },
    {
      "x": -5,
      "y": 9,
      "z": 0,
      "name": "Furniture_Human_Ruins_Pot_Small"
    },
    {
      "x": -5,
      "y": 10,
      "z": 0,
      "name": "Empty"
    },
    {
      "x": -5,
      "y": 12,
      "z": 0,
      "name": "Wood_Deadwood_Roof_Flat",
      "rotation": 1
    },
    {
      "x": -5,
      "y": 3,
      "z": 1,
      "name": "Rock_Volcanic"
    },
    {
      "x": -5,
      "y": 4,
      "z": 1,
      "name": "Rock_Volcanic"
    },
    {
      "x": -5,
      "y": 5,
      "z": 1,
      "name": "Rock_Volcanic"
    },
    {
      "x": -5,
      "y": 6,
      "z": 1,
      "name": "Rock_Volcanic"
    },
    {
      "x": -5,
      "y": 7,
      "z": 1,
      "name": "Rock_Volcanic"
    },
    {
      "x": -5,
      "y": 8,
      "z": 1,
      "name": "Wood_Deadwood_Planks"
    },
    {
      "x": -5,
      "y": 9,
      "z": 1,
      "name": "Empty"
    },
    {
      "x": -5,
      "y": 10,
      "z": 1,
      "name": "Empty"
    },
    {
      "x": -5,
      "y": 11,
      "z": 1,
      "name": "Empty"
    },
    {
      "x": -5,
      "y": 12,
      "z": 1,
      "name": "Wood_Deadwood_Roof_Flat",
      "rotation": 1
    },
    {
      "x": -5,
      "y": 4,
      "z": 2,
      "name": "Rock_Volcanic"
    },
    {
      "x": -5,
      "y": 5,
      "z": 2,
      "name": "Rock_Volcanic"
    },
    {
      "x": -5,
      "y": 6,
      "z": 2,
      "name": "Rock_Volcanic"
    },
    {
      "x": -5,
      "y": 7,
      "z": 2,
      "name": "Rock_Volcanic"
    },
    {
      "x": -5,
      "y": 8,
      "z": 2,
      "name": "Empty"
    },
    {
      "x": -5,
      "y": 9,
      "z": 2,
      "name": "Empty"
    },
    {
      "x": -5,
      "y": 10,
      "z": 2,
      "name": "Empty"
    },
    {
      "x": -5,
      "y": 12,
      "z": 2,
      "name": "Wood_Deadwood_Roof_Flat",
      "rotation": 1
    },
    {
      "x": -5,
      "y": 3,
      "z": 3,
      "name": "Rock_Slate"
    },
    {
      "x": -5,
      "y": 4,
      "z": 3,
      "name": "Rock_Volcanic"
    },
    {
      "x": -5,
      "y": 5,
      "z": 3,
      "name": "Rock_Slate"
    },
    {
      "x": -5,
      "y": 6,
      "z": 3,
      "name": "Rock_Volcanic_Cobble"
    },
    {
      "x": -5,
      "y": 7,
      "z": 3,
      "name": "Rock_Basalt_Brick"
    },
    {
      "x": -5,
      "y": 8,
      "z": 3,
      "name": "Rock_Basalt_Cobble"
    },
    {
      "x": -5,
      "y": 9,
      "z": 3,
      "name": "Rock_Basalt_Cobble"
    },
    {
      "x": -5,
      "y": 10,
      "z": 3,
      "name": "Wood_Burnt_Branch_Long"
    },
    {
      "x": -5,
      "y": 11,
      "z": 3,
      "name": "Wood_Burnt_Branch_Long"
    },
    {
      "x": -5,
      "y": 12,
      "z": 3,
      "name": "Wood_Deadwood_Roof_Flat",
      "rotation": 1
    },
    {
      "x": -5,
      "y": 3,
      "z": 4,
      "name": "Rock_Slate"
    },
    {
      "x": -5,
      "y": 4,
      "z": 4,
      "name": "Rock_Slate"
    },
    {
      "x": -5,
      "y": 5,
      "z": 4,
      "name": "Rock_Slate"
    },
    {
      "x": -5,
      "y": 6,
      "z": 4,
      "name": "Rock_Slate"
    },
    {
      "x": -5,
      "y": 7,
      "z": 4,
      "name": "Rock_Slate"
    },
    {
      "x": -5,
      "y": 5,
      "z": 5,
      "name": "Rock_Slate"
    },
    {
      "x": -5,
      "y": 6,
      "z": 5,
      "name": "Rock_Slate"
    },
    {
      "x": -5,
      "y": 7,
      "z": 5,
      "name": "Rock_Slate"
    },
    {
      "x": -4,
      "y": 2,
      "z": -5,
      "name": "Rock_Slate"
    },
    {
      "x": -4,
      "y": 3,
      "z": -5,
      "name": "Rock_Slate"
    },
    {
      "x": -4,
      "y": 4,
      "z": -5,
      "name": "Rock_Slate"
    },
    {
      "x": -4,
      "y": 5,
      "z": -5,
      "name": "Rock_Slate"
    },
    {
      "x": -4,
      "y": 6,
      "z": -5,
      "name": "Rock_Slate"
    },
    {
      "x": -4,
      "y": 0,
      "z": -4,
      "name": "Rock_Slate"
    },
    {
      "x": -4,
      "y": 1,
      "z": -4,
      "name": "Rock_Slate"
    },
    {
      "x": -4,
      "y": 2,
      "z": -4,
      "name": "Rock_Slate"
    },
    {
      "x": -4,
      "y": 3,
      "z": -4,
      "name": "Rock_Volcanic"
    },
    {
      "x": -4,
      "y": 4,
      "z": -4,
      "name": "Rock_Slate"
    },
    {
      "x": -4,
      "y": 5,
      "z": -4,
      "name": "Rock_Slate"
    },
    {
      "x": -4,
      "y": 6,
      "z": -4,
      "name": "Rock_Slate"
    },
    {
      "x": -4,
      "y": 0,
      "z": -3,
      "name": "Rock_Slate"
    },
    {
      "x": -4,
      "y": 1,
      "z": -3,
      "name": "Rock_Slate"
    },
    {
      "x": -4,
      "y": 2,
      "z": -3,
      "name": "Rock_Volcanic"
    },
    {
      "x": -4,
      "y": 3,
      "z": -3,
      "name": "Rock_Volcanic"
    },
    {
      "x": -4,
      "y": 4,
      "z": -3,
      "name": "Rock_Volcanic"
    },
    {
      "x": -4,
      "y": 5,
      "z": -3,
      "name": "Rock_Slate"
    },
    {
      "x": -4,
      "y": 6,
      "z": -3,
      "name": "Rock_Volcanic"
    },
    {
      "x": -4,
      "y": 7,
      "z": -3,
      "name": "Rock_Volcanic"
    },
    {
      "x": -4,
      "y": 1,
      "z": -2,
      "name": "Rock_Slate"
    },
    {
      "x": -4,
      "y": 2,
      "z": -2,
      "name": "Rock_Volcanic"
    },
    {
      "x": -4,
      "y": 3,
      "z": -2,
      "name": "Rock_Volcanic"
    },
    {
      "x": -4,
      "y": 4,
      "z": -2,
      "name": "Rock_Volcanic"
    },
    {
      "x": -4,
      "y": 5,
      "z": -2,
      "name": "Rock_Slate"
    },
    {
      "x": -4,
      "y": 6,
      "z": -2,
      "name": "Rock_Volcanic"
    },
    {
      "x": -4,
      "y": 7,
      "z": -2,
      "name": "Rock_Volcanic"
    },
    {
      "x": -4,
      "y": 2,
      "z": -1,
      "name": "Rock_Volcanic"
    },
    {
      "x": -4,
      "y": 3,
      "z": -1,
      "name": "Rock_Volcanic"
    },
    {
      "x": -4,
      "y": 4,
      "z": -1,
      "name": "Rock_Volcanic"
    },
    {
      "x": -4,
      "y": 5,
      "z": -1,
      "name": "Rock_Volcanic"
    },
    {
      "x": -4,
      "y": 6,
      "z": -1,
      "name": "Rock_Volcanic_Cobble"
    },
    {
      "x": -4,
      "y": 7,
      "z": -1,
      "name": "Rock_Basalt_Brick"
    },
    {
      "x": -4,
      "y": 8,
      "z": -1,
      "name": "Rock_Basalt_Cobble"
    },
    {
      "x": -4,
      "y": 9,
      "z": -1,
      "name": "Rock_Basalt_Cobble"
    },
    {
      "x": -4,
      "y": 10,
      "z": -1,
      "name": "Empty"
    },
    {
      "x": -4,
      "y": 12,
      "z": -1,
      "name": "Wood_Deadwood_Roof_Flat",
      "rotation": 1
    },
    {
      "x": -4,
      "y": 2,
      "z": 0,
      "name": "Rock_Volcanic"
    },
    {
      "x": -4,
      "y": 3,
      "z": 0,
      "name": "Rock_Volcanic"
    },
    {
      "x": -4,
      "y": 4,
      "z": 0,
      "name": "Rock_Volcanic"
    },
    {
      "x": -4,
      "y": 5,
      "z": 0,
      "name": "Rock_Volcanic"
    },
    {
      "x": -4,
      "y": 6,
      "z": 0,
      "name": "Rock_Volcanic"
    },
    {
      "x": -4,
      "y": 7,
      "z": 0,
      "name": "Rock_Volcanic"
    },
    {
      "x": -4,
      "y": 8,
      "z": 0,
      "name": "Wood_Deadwood_Planks"
    },
    {
      "x": -4,
      "y": 9,
      "z": 0,
      "name": "Furniture_Ancient_Crate",
      "rotation": 3
    },
    {
      "x": -4,
      "y": 10,
      "z": 0,
      "name": "Empty"
    },
    {
      "x": -4,
      "y": 11,
      "z": 0,
      "name": "Empty"
    },
    {
      "x": -4,
      "y": 12,
      "z": 0,
      "name": "Wood_Deadwood_Roof_Flat",
      "rotation": 1
    },
    {
      "x": -4,
      "y": 2,
      "z": 1,
      "name": "Rock_Volcanic"
    },
    {
      "x": -4,
      "y": 3,
      "z": 1,
      "name": "Rock_Volcanic"
    },
    {
      "x": -4,
      "y": 4,
      "z": 1,
      "name": "Rock_Volcanic"
    },
    {
      "x": -4,
      "y": 5,
      "z": 1,
      "name": "Rock_Volcanic"
    },
    {
      "x": -4,
      "y": 6,
      "z": 1,
      "name": "Rock_Volcanic"
    },
    {
      "x": -4,
      "y": 7,
      "z": 1,
      "name": "Rock_Volcanic"
    },
    {
      "x": -4,
      "y": 8,
      "z": 1,
      "name": "Wood_Deadwood_Planks"
    },
    {
      "x": -4,
      "y": 9,
      "z": 1,
      "name": "Furniture_Ancient_Crate",
      "rotation": 2
    },
    {
      "x": -4,
      "y": 10,
      "z": 1,
      "name": "Furniture_Human_Ruins_Pot_Small"
    },
    {
      "x": -4,
      "y": 11,
      "z": 1,
      "name": "Empty"
    },
    {
      "x": -4,
      "y": 12,
      "z": 1,
      "name": "Wood_Deadwood_Roof_Flat",
      "rotation": 1
    },
    {
      "x": -4,
      "y": 2,
      "z": 2,
      "name": "Rock_Volcanic"
    },
    {
      "x": -4,
      "y": 3,
      "z": 2,
      "name": "Rock_Volcanic"
    },
    {
      "x": -4,
      "y": 4,
      "z": 2,
      "name": "Rock_Volcanic"
    },
    {
      "x": -4,
      "y": 5,
      "z": 2,
      "name": "Rock_Volcanic"
    },
    {
      "x": -4,
      "y": 6,
      "z": 2,
      "name": "Rock_Volcanic"
    },
    {
      "x": -4,
      "y": 7,
      "z": 2,
      "name": "Rock_Volcanic"
    },
    {
      "x": -4,
      "y": 8,
      "z": 2,
      "name": "Wood_Deadwood_Planks"
    },
    {
      "x": -4,
      "y": 9,
      "z": 2,
      "name": "Furniture_Ancient_Barrel"
    },
    {
      "x": -4,
      "y": 10,
      "z": 2,
      "name": "Empty"
    },
    {
      "x": -4,
      "y": 11,
      "z": 2,
      "name": "Empty"
    },
    {
      "x": -4,
      "y": 12,
      "z": 2,
      "name": "Wood_Deadwood_Roof_Flat",
      "rotation": 1
    },
    {
      "x": -4,
      "y": 1,
      "z": 3,
      "name": "Rock_Slate"
    },
    {
      "x": -4,
      "y": 2,
      "z": 3,
      "name": "Rock_Slate"
    },
    {
      "x": -4,
      "y": 3,
      "z": 3,
      "name": "Rock_Volcanic"
    },
    {
      "x": -4,
      "y": 4,
      "z": 3,
      "name": "Rock_Volcanic"
    },
    {
      "x": -4,
      "y": 5,
      "z": 3,
      "name": "Rock_Volcanic"
    },
    {
      "x": -4,
      "y": 6,
      "z": 3,
      "name": "Rock_Volcanic"
    },
    {
      "x": -4,
      "y": 7,
      "z": 3,
      "name": "Rock_Volcanic_Cobble"
    },
    {
      "x": -4,
      "y": 8,
      "z": 3,
      "name": "Rock_Basalt_Brick"
    },
    {
      "x": -4,
      "y": 9,
      "z": 3,
      "name": "Rock_Basalt_Cobble"
    },
    {
      "x": -4,
      "y": 10,
      "z": 3,
      "name": "Plant_Crop_Mushroom_Glowing_Purple"
    },
    {
      "x": -4,
      "y": 11,
      "z": 3,
      "name": "Empty"
    },
    {
      "x": -4,
      "y": 12,
      "z": 3,
      "name": "Wood_Deadwood_Roof_Flat",
      "rotation": 1
    },
    {
      "x": -4,
      "y": 1,
      "z": 4,
      "name": "Rock_Slate"
    },
    {
      "x": -4,
      "y": 2,
      "z": 4,
      "name": "Rock_Slate"
    },
    {
      "x": -4,
      "y": 3,
      "z": 4,
      "name": "Rock_Slate"
    },
    {
      "x": -4,
      "y": 4,
      "z": 4,
      "name": "Rock_Slate"
    },
    {
      "x": -4,
      "y": 5,
      "z": 4,
      "name": "Rock_Slate"
    },
    {
      "x": -4,
      "y": 6,
      "z": 4,
      "name": "Rock_Slate"
    },
    {
      "x": -4,
      "y": 7,
      "z": 4,
      "name": "Rock_Slate"
    },
    {
      "x": -4,
      "y": 3,
      "z": 5,
      "name": "Rock_Slate"
    },
    {
      "x": -4,
      "y": 4,
      "z": 5,
      "name": "Rock_Slate"
    },
    {
      "x": -4,
      "y": 5,
      "z": 5,
      "name": "Rock_Slate"
    },
    {
      "x": -4,
      "y": 6,
      "z": 5,
      "name": "Rock_Slate"
    },
    {
      "x": -4,
      "y": 7,
      "z": 5,
      "name": "Rock_Slate"
    },
    {
      "x": -4,
      "y": 5,
      "z": 6,
      "name": "Rock_Slate"
    },
    {
      "x": -4,
      "y": 6,
      "z": 6,
      "name": "Rock_Slate"
    },
    {
      "x": -4,
      "y": 7,
      "z": 6,
      "name": "Rock_Slate"
    },
    {
      "x": -3,
      "y": 2,
      "z": -5,
      "name": "Rock_Slate"
    },
    {
      "x": -3,
      "y": 3,
      "z": -5,
      "name": "Rock_Slate"
    },
    {
      "x": -3,
      "y": 4,
      "z": -5,
      "name": "Rock_Slate"
    },
    {
      "x": -3,
      "y": 5,
      "z": -5,
      "name": "Rock_Slate"
    },
    {
      "x": -3,
      "y": 6,
      "z": -5,
      "name": "Rock_Slate"
    },
    {
      "x": -3,
      "y": 0,
      "z": -4,
      "name": "Rock_Slate"
    },
    {
      "x": -3,
      "y": 1,
      "z": -4,
      "name": "Rock_Slate"
    },
    {
      "x": -3,
      "y": 2,
      "z": -4,
      "name": "Rock_Slate"
    },
    {
      "x": -3,
      "y": 3,
      "z": -4,
      "name": "Rock_Volcanic"
    },
    {
      "x": -3,
      "y": 4,
      "z": -4,
      "name": "Rock_Volcanic"
    },
    {
      "x": -3,
      "y": 5,
      "z": -4,
      "name": "Rock_Slate"
    },
    {
      "x": -3,
      "y": 6,
      "z": -4,
      "name": "Rock_Volcanic"
    },
    {
      "x": -3,
      "y": 7,
      "z": -4,
      "name": "Plant_Bramble_Dead_Twisted"
    },
    {
      "x": -3,
      "y": 16,
      "z": -4,
      "name": "Cloth_Roof_Hide_Flap",
      "rotation": 2
    },
    {
      "x": -3,
      "y": 0,
      "z": -3,
      "name": "Rock_Slate"
    },
    {
      "x": -3,
      "y": 1,
      "z": -3,
      "name": "Rock_Slate"
    },
    {
      "x": -3,
      "y": 2,
      "z": -3,
      "name": "Rock_Volcanic"
    },
    {
      "x": -3,
      "y": 3,
      "z": -3,
      "name": "Rock_Volcanic"
    },
    {
      "x": -3,
      "y": 4,
      "z": -3,
      "name": "Rock_Volcanic"
    },
    {
      "x": -3,
      "y": 5,
      "z": -3,
      "name": "Rock_Volcanic"
    },
    {
      "x": -3,
      "y": 6,
      "z": -3,
      "name": "Rock_Volcanic"
    },
    {
      "x": -3,
      "y": 7,
      "z": -3,
      "name": "Rock_Volcanic"
    },
    {
      "x": -3,
      "y": 16,
      "z": -3,
      "name": "Wood_Blackwood_Beam",
      "rotation": 5
    },
    {
      "x": -3,
      "y": 17,
      "z": -3,
      "name": "Cloth_Roof_Hide_Flat"
    },
    {
      "x": -3,
      "y": 1,
      "z": -2,
      "name": "Rock_Volcanic"
    },
    {
      "x": -3,
      "y": 2,
      "z": -2,
      "name": "Rock_Volcanic"
    },
    {
      "x": -3,
      "y": 3,
      "z": -2,
      "name": "Rock_Volcanic"
    },
    {
      "x": -3,
      "y": 4,
      "z": -2,
      "name": "Rock_Volcanic"
    },
    {
      "x": -3,
      "y": 5,
      "z": -2,
      "name": "Rock_Volcanic"
    },
    {
      "x": -3,
      "y": 6,
      "z": -2,
      "name": "Rock_Volcanic"
    },
    {
      "x": -3,
      "y": 7,
      "z": -2,
      "name": "Rock_Volcanic"
    },
    {
      "x": -3,
      "y": 8,
      "z": -2,
      "name": "Rock_Basalt_Brick"
    },
    {
      "x": -3,
      "y": 9,
      "z": -2,
      "name": "Wood_Burnt_Trunk"
    },
    {
      "x": -3,
      "y": 10,
      "z": -2,
      "name": "Wood_Burnt_Trunk"
    },
    {
      "x": -3,
      "y": 11,
      "z": -2,
      "name": "Wood_Burnt_Trunk"
    },
    {
      "x": -3,
      "y": 12,
      "z": -2,
      "name": "Wood_Burnt_Trunk"
    },
    {
      "x": -3,
      "y": 13,
      "z": -2,
      "name": "*Wood_Blackwood_Roof_Steep_State_Definitions_Corner_Right",
      "rotation": 3
    },
    {
      "x": -3,
      "y": 14,
      "z": -2,
      "name": "*Wood_Blackwood_Roof_Steep_State_Definitions_Corner_Right",
      "filler": 1024,
      "rotation": 3
    },
    {
      "x": -3,
      "y": 1,
      "z": -1,
      "name": "Rock_Volcanic"
    },
    {
      "x": -3,
      "y": 2,
      "z": -1,
      "name": "Rock_Volcanic"
    },
    {
      "x": -3,
      "y": 3,
      "z": -1,
      "name": "Rock_Volcanic"
    },
    {
      "x": -3,
      "y": 4,
      "z": -1,
      "name": "Rock_Volcanic"
    },
    {
      "x": -3,
      "y": 5,
      "z": -1,
      "name": "Rock_Volcanic"
    },
    {
      "x": -3,
      "y": 6,
      "z": -1,
      "name": "Rock_Volcanic"
    },
    {
      "x": -3,
      "y": 7,
      "z": -1,
      "name": "Rock_Volcanic_Cobble"
    },
    {
      "x": -3,
      "y": 8,
      "z": -1,
      "name": "Rock_Basalt_Brick"
    },
    {
      "x": -3,
      "y": 9,
      "z": -1,
      "name": "Wood_Deadwood_Planks"
    },
    {
      "x": -3,
      "y": 10,
      "z": -1,
      "name": "Wood_Deadwood_Planks"
    },
    {
      "x": -3,
      "y": 11,
      "z": -1,
      "name": "Wood_Blackwood_Planks"
    },
    {
      "x": -3,
      "y": 12,
      "z": -1,
      "name": "Wood_Blackwood_Planks"
    },
    {
      "x": -3,
      "y": 13,
      "z": -1,
      "name": "Wood_Blackwood_Roof_Steep",
      "rotation": 3
    },
    {
      "x": -3,
      "y": 14,
      "z": -1,
      "name": "Wood_Blackwood_Roof_Steep",
      "filler": 1024,
      "rotation": 3
    },
    {
      "x": -3,
      "y": 1,
      "z": 0,
      "name": "Rock_Volcanic"
    },
    {
      "x": -3,
      "y": 2,
      "z": 0,
      "name": "Rock_Volcanic"
    },
    {
      "x": -3,
      "y": 3,
      "z": 0,
      "name": "Rock_Volcanic"
    },
    {
      "x": -3,
      "y": 4,
      "z": 0,
      "name": "Rock_Volcanic"
    },
    {
      "x": -3,
      "y": 5,
      "z": 0,
      "name": "Rock_Volcanic"
    },
    {
      "x": -3,
      "y": 6,
      "z": 0,
      "name": "Rock_Volcanic_Cobble"
    },
    {
      "x": -3,
      "y": 7,
      "z": 0,
      "name": "Rock_Volcanic_Cobble"
    },
    {
      "x": -3,
      "y": 8,
      "z": 0,
      "name": "Rock_Basalt_Brick"
    },
    {
      "x": -3,
      "y": 9,
      "z": 0,
      "name": "Wood_Deadwood_Planks"
    },
    {
      "x": -3,
      "y": 10,
      "z": 0,
      "name": "Wood_Deadwood_Planks"
    },
    {
      "x": -3,
      "y": 11,
      "z": 0,
      "name": "Wood_Blackwood_Planks"
    },
    {
      "x": -3,
      "y": 12,
      "z": 0,
      "name": "Wood_Blackwood_Planks"
    },
    {
      "x": -3,
      "y": 13,
      "z": 0,
      "name": "Wood_Blackwood_Roof_Steep",
      "rotation": 3
    },
    {
      "x": -3,
      "y": 14,
      "z": 0,
      "name": "Wood_Blackwood_Roof_Steep",
      "filler": 1024,
      "rotation": 3
    },
    {
      "x": -3,
      "y": 1,
      "z": 1,
      "name": "Rock_Volcanic"
    },
    {
      "x": -3,
      "y": 2,
      "z": 1,
      "name": "Rock_Volcanic"
    },
    {
      "x": -3,
      "y": 3,
      "z": 1,
      "name": "Rock_Volcanic"
    },
    {
      "x": -3,
      "y": 4,
      "z": 1,
      "name": "Rock_Volcanic"
    },
    {
      "x": -3,
      "y": 5,
      "z": 1,
      "name": "Rock_Volcanic"
    },
    {
      "x": -3,
      "y": 6,
      "z": 1,
      "name": "Rock_Volcanic_Cobble"
    },
    {
      "x": -3,
      "y": 7,
      "z": 1,
      "name": "Rock_Volcanic_Cobble"
    },
    {
      "x": -3,
      "y": 8,
      "z": 1,
      "name": "Rock_Volcanic_Cobble"
    },
    {
      "x": -3,
      "y": 9,
      "z": 1,
      "name": "Wood_Deadwood_Planks"
    },
    {
      "x": -3,
      "y": 10,
      "z": 1,
      "name": "Wood_Blackwood_Planks"
    },
    {
      "x": -3,
      "y": 11,
      "z": 1,
      "name": "Wood_Blackwood_Planks"
    },
    {
      "x": -3,
      "y": 12,
      "z": 1,
      "name": "Wood_Blackwood_Planks"
    },
    {
      "x": -3,
      "y": 13,
      "z": 1,
      "name": "Wood_Blackwood_Roof_Steep",
      "rotation": 3
    },
    {
      "x": -3,
      "y": 14,
      "z": 1,
      "name": "Wood_Blackwood_Roof_Steep",
      "filler": 1024,
      "rotation": 3
    },
    {
      "x": -3,
      "y": 1,
      "z": 2,
      "name": "Rock_Volcanic"
    },
    {
      "x": -3,
      "y": 2,
      "z": 2,
      "name": "Rock_Volcanic"
    },
    {
      "x": -3,
      "y": 3,
      "z": 2,
      "name": "Rock_Volcanic"
    },
    {
      "x": -3,
      "y": 4,
      "z": 2,
      "name": "Rock_Volcanic"
    },
    {
      "x": -3,
      "y": 5,
      "z": 2,
      "name": "Rock_Volcanic"
    },
    {
      "x": -3,
      "y": 6,
      "z": 2,
      "name": "Rock_Volcanic_Cobble"
    },
    {
      "x": -3,
      "y": 7,
      "z": 2,
      "name": "Rock_Volcanic_Cobble"
    },
    {
      "x": -3,
      "y": 8,
      "z": 2,
      "name": "Rock_Volcanic_Cobble"
    },
    {
      "x": -3,
      "y": 9,
      "z": 2,
      "name": "Wood_Deadwood_Planks"
    },
    {
      "x": -3,
      "y": 10,
      "z": 2,
      "name": "Wood_Blackwood_Planks"
    },
    {
      "x": -3,
      "y": 11,
      "z": 2,
      "name": "Wood_Blackwood_Planks"
    },
    {
      "x": -3,
      "y": 12,
      "z": 2,
      "name": "Wood_Blackwood_Planks"
    },
    {
      "x": -3,
      "y": 13,
      "z": 2,
      "name": "Wood_Blackwood_Roof_Steep",
      "rotation": 3
    },
    {
      "x": -3,
      "y": 14,
      "z": 2,
      "name": "Wood_Blackwood_Roof_Steep",
      "filler": 1024,
      "rotation": 3
    },
    {
      "x": -3,
      "y": 1,
      "z": 3,
      "name": "Rock_Slate"
    },
    {
      "x": -3,
      "y": 2,
      "z": 3,
      "name": "Rock_Volcanic"
    },
    {
      "x": -3,
      "y": 3,
      "z": 3,
      "name": "Rock_Volcanic"
    },
    {
      "x": -3,
      "y": 4,
      "z": 3,
      "name": "Rock_Volcanic"
    },
    {
      "x": -3,
      "y": 5,
      "z": 3,
      "name": "Rock_Volcanic"
    },
    {
      "x": -3,
      "y": 6,
      "z": 3,
      "name": "Rock_Volcanic"
    },
    {
      "x": -3,
      "y": 7,
      "z": 3,
      "name": "Rock_Volcanic_Cobble"
    },
    {
      "x": -3,
      "y": 8,
      "z": 3,
      "name": "Rock_Basalt_Brick"
    },
    {
      "x": -3,
      "y": 9,
      "z": 3,
      "name": "Wood_Blackwood_Planks"
    },
    {
      "x": -3,
      "y": 10,
      "z": 3,
      "name": "Wood_Blackwood_Planks"
    },
    {
      "x": -3,
      "y": 11,
      "z": 3,
      "name": "Wood_Blackwood_Planks"
    },
    {
      "x": -3,
      "y": 12,
      "z": 3,
      "name": "Wood_Blackwood_Planks"
    },
    {
      "x": -3,
      "y": 13,
      "z": 3,
      "name": "Wood_Blackwood_Roof_Steep",
      "rotation": 3
    },
    {
      "x": -3,
      "y": 14,
      "z": 3,
      "name": "Wood_Blackwood_Roof_Steep",
      "filler": 1024,
      "rotation": 3
    },
    {
      "x": -3,
      "y": 1,
      "z": 4,
      "name": "Rock_Slate"
    },
    {
      "x": -3,
      "y": 2,
      "z": 4,
      "name": "Rock_Slate"
    },
    {
      "x": -3,
      "y": 3,
      "z": 4,
      "name": "Rock_Slate"
    },
    {
      "x": -3,
      "y": 4,
      "z": 4,
      "name": "Rock_Slate"
    },
    {
      "x": -3,
      "y": 5,
      "z": 4,
      "name": "Rock_Volcanic"
    },
    {
      "x": -3,
      "y": 6,
      "z": 4,
      "name": "Rock_Volcanic"
    },
    {
      "x": -3,
      "y": 7,
      "z": 4,
      "name": "Rock_Basalt_Brick"
    },
    {
      "x": -3,
      "y": 8,
      "z": 4,
      "name": "Rock_Basalt_Brick"
    },
    {
      "x": -3,
      "y": 9,
      "z": 4,
      "name": "Wood_Burnt_Trunk"
    },
    {
      "x": -3,
      "y": 10,
      "z": 4,
      "name": "Wood_Burnt_Trunk"
    },
    {
      "x": -3,
      "y": 11,
      "z": 4,
      "name": "Wood_Burnt_Trunk"
    },
    {
      "x": -3,
      "y": 12,
      "z": 4,
      "name": "Wood_Burnt_Trunk"
    },
    {
      "x": -3,
      "y": 13,
      "z": 4,
      "name": "*Wood_Blackwood_Roof_Steep_State_Definitions_Corner_Right"
    },
    {
      "x": -3,
      "y": 14,
      "z": 4,
      "name": "*Wood_Blackwood_Roof_Steep_State_Definitions_Corner_Right",
      "filler": 1024
    },
    {
      "x": -3,
      "y": 3,
      "z": 5,
      "name": "Rock_Slate"
    },
    {
      "x": -3,
      "y": 4,
      "z": 5,
      "name": "Rock_Slate"
    },
    {
      "x": -3,
      "y": 5,
      "z": 5,
      "name": "Rock_Slate"
    },
    {
      "x": -3,
      "y": 6,
      "z": 5,
      "name": "Rock_Slate"
    },
    {
      "x": -3,
      "y": 7,
      "z": 5,
      "name": "Rock_Slate"
    },
    {
      "x": -3,
      "y": 8,
      "z": 5,
      "name": "Plant_Bush_Dead_Twisted"
    },
    {
      "x": -3,
      "y": 6,
      "z": 6,
      "name": "Rock_Slate"
    },
    {
      "x": -3,
      "y": 7,
      "z": 6,
      "name": "Rock_Slate"
    },
    {
      "x": -2,
      "y": 2,
      "z": -5,
      "name": "Rock_Slate"
    },
    {
      "x": -2,
      "y": 3,
      "z": -5,
      "name": "Rock_Slate"
    },
    {
      "x": -2,
      "y": 4,
      "z": -5,
      "name": "Rock_Slate"
    },
    {
      "x": -2,
      "y": 5,
      "z": -5,
      "name": "Rock_Slate"
    },
    {
      "x": -2,
      "y": 1,
      "z": -4,
      "name": "Rock_Slate"
    },
    {
      "x": -2,
      "y": 2,
      "z": -4,
      "name": "Rock_Volcanic"
    },
    {
      "x": -2,
      "y": 3,
      "z": -4,
      "name": "Rock_Volcanic"
    },
    {
      "x": -2,
      "y": 4,
      "z": -4,
      "name": "Rock_Volcanic"
    },
    {
      "x": -2,
      "y": 5,
      "z": -4,
      "name": "Rock_Volcanic"
    },
    {
      "x": -2,
      "y": 6,
      "z": -4,
      "name": "Rock_Volcanic"
    },
    {
      "x": -2,
      "y": 7,
      "z": -4,
      "name": "Rock_Volcanic"
    },
    {
      "x": -2,
      "y": 16,
      "z": -4,
      "name": "Cloth_Roof_Hide_Vertical",
      "rotation": 2
    },
    {
      "x": -2,
      "y": 2,
      "z": -3,
      "name": "Rock_Volcanic"
    },
    {
      "x": -2,
      "y": 3,
      "z": -3,
      "name": "Rock_Volcanic"
    },
    {
      "x": -2,
      "y": 4,
      "z": -3,
      "name": "Rock_Volcanic"
    },
    {
      "x": -2,
      "y": 5,
      "z": -3,
      "name": "Rock_Volcanic"
    },
    {
      "x": -2,
      "y": 6,
      "z": -3,
      "name": "Rock_Volcanic"
    },
    {
      "x": -2,
      "y": 7,
      "z": -3,
      "name": "Rock_Volcanic"
    },
    {
      "x": -2,
      "y": 8,
      "z": -3,
      "name": "Plant_Crop_Mushroom_Glowing_Purple"
    },
    {
      "x": -2,
      "y": 16,
      "z": -3,
      "name": "Wood_Blackwood_Beam",
      "rotation": 5
    },
    {
      "x": -2,
      "y": 17,
      "z": -3,
      "name": "Cloth_Roof_Hide_Flat"
    },
    {
      "x": -2,
      "y": 1,
      "z": -2,
      "name": "Rock_Volcanic"
    },
    {
      "x": -2,
      "y": 2,
      "z": -2,
      "name": "Rock_Volcanic"
    },
    {
      "x": -2,
      "y": 3,
      "z": -2,
      "name": "Rock_Volcanic"
    },
    {
      "x": -2,
      "y": 4,
      "z": -2,
      "name": "Rock_Volcanic"
    },
    {
      "x": -2,
      "y": 5,
      "z": -2,
      "name": "Rock_Volcanic"
    },
    {
      "x": -2,
      "y": 6,
      "z": -2,
      "name": "Rock_Volcanic"
    },
    {
      "x": -2,
      "y": 7,
      "z": -2,
      "name": "Rock_Volcanic_Cobble"
    },
    {
      "x": -2,
      "y": 8,
      "z": -2,
      "name": "Rock_Basalt_Brick"
    },
    {
      "x": -2,
      "y": 9,
      "z": -2,
      "name": "Wood_Deadwood_Planks"
    },
    {
      "x": -2,
      "y": 10,
      "z": -2,
      "name": "Wood_Blackwood_Planks"
    },
    {
      "x": -2,
      "y": 11,
      "z": -2,
      "name": "Wood_Blackwood_Planks"
    },
    {
      "x": -2,
      "y": 12,
      "z": -2,
      "name": "Wood_Blackwood_Planks"
    },
    {
      "x": -2,
      "y": 13,
      "z": -2,
      "name": "Wood_Blackwood_Roof_Steep",
      "rotation": 2
    },
    {
      "x": -2,
      "y": 14,
      "z": -2,
      "name": "Wood_Blackwood_Roof_Steep",
      "filler": 1024,
      "rotation": 2
    },
    {
      "x": -2,
      "y": 1,
      "z": -1,
      "name": "Rock_Volcanic"
    },
    {
      "x": -2,
      "y": 2,
      "z": -1,
      "name": "Rock_Volcanic"
    },
    {
      "x": -2,
      "y": 3,
      "z": -1,
      "name": "Rock_Volcanic"
    },
    {
      "x": -2,
      "y": 4,
      "z": -1,
      "name": "Wood_Deadwood_Planks"
    },
    {
      "x": -2,
      "y": 5,
      "z": -1,
      "name": "Furniture_Human_Ruins_Ladder",
      "rotation": 1
    },
    {
      "x": -2,
      "y": 6,
      "z": -1,
      "name": "Furniture_Human_Ruins_Ladder",
      "rotation": 1
    },
    {
      "x": -2,
      "y": 7,
      "z": -1,
      "name": "Furniture_Human_Ruins_Ladder",
      "rotation": 1
    },
    {
      "x": -2,
      "y": 8,
      "z": -1,
      "name": "Furniture_Human_Ruins_Ladder",
      "rotation": 1
    },
    {
      "x": -2,
      "y": 9,
      "z": -1,
      "name": "Furniture_Human_Ruins_Ladder",
      "rotation": 1
    },
    {
      "x": -2,
      "y": 10,
      "z": -1,
      "name": "Empty"
    },
    {
      "x": -2,
      "y": 11,
      "z": -1,
      "name": "Empty"
    },
    {
      "x": -2,
      "y": 12,
      "z": -1,
      "name": "Empty"
    },
    {
      "x": -2,
      "y": 13,
      "z": -1,
      "name": "Wood_Blackwood_Planks"
    },
    {
      "x": -2,
      "y": 14,
      "z": -1,
      "name": "Wood_Blackwood_Planks"
    },
    {
      "x": -2,
      "y": 15,
      "z": -1,
      "name": "Wood_Burnt_Trunk"
    },
    {
      "x": -2,
      "y": 16,
      "z": -1,
      "name": "Wood_Burnt_Trunk"
    },
    {
      "x": -2,
      "y": 17,
      "z": -1,
      "name": "Wood_Burnt_Trunk"
    },
    {
      "x": -2,
      "y": 18,
      "z": -1,
      "name": "*Wood_Blackwood_Roof_Steep_State_Definitions_Corner_Right",
      "rotation": 3
    },
    {
      "x": -2,
      "y": 19,
      "z": -1,
      "name": "*Wood_Blackwood_Roof_Steep_State_Definitions_Corner_Right",
      "filler": 1024,
      "rotation": 3
    },
    {
      "x": -2,
      "y": 1,
      "z": 0,
      "name": "Rock_Volcanic"
    },
    {
      "x": -2,
      "y": 2,
      "z": 0,
      "name": "Rock_Volcanic"
    },
    {
      "x": -2,
      "y": 3,
      "z": 0,
      "name": "Rock_Volcanic"
    },
    {
      "x": -2,
      "y": 4,
      "z": 0,
      "name": "Wood_Deadwood_Planks"
    },
    {
      "x": -2,
      "y": 5,
      "z": 0,
      "name": "Empty"
    },
    {
      "x": -2,
      "y": 6,
      "z": 0,
      "name": "Empty"
    },
    {
      "x": -2,
      "y": 7,
      "z": 0,
      "name": "Empty"
    },
    {
      "x": -2,
      "y": 8,
      "z": 0,
      "name": "Furniture_Ancient_Platform"
    },
    {
      "x": -2,
      "y": 9,
      "z": 0,
      "name": "Empty"
    },
    {
      "x": -2,
      "y": 10,
      "z": 0,
      "name": "Empty"
    },
    {
      "x": -2,
      "y": 11,
      "z": 0,
      "name": "Empty"
    },
    {
      "x": -2,
      "y": 12,
      "z": 0,
      "name": "Empty"
    },
    {
      "x": -2,
      "y": 13,
      "z": 0,
      "name": "Wood_Blackwood_Planks_Half",
      "rotation": 5
    },
    {
      "x": -2,
      "y": 14,
      "z": 0,
      "name": "Wood_Blackwood_Planks"
    },
    {
      "x": -2,
      "y": 15,
      "z": 0,
      "name": "Wood_Blackwood_Planks"
    },
    {
      "x": -2,
      "y": 16,
      "z": 0,
      "name": "Wood_Blackwood_Planks"
    },
    {
      "x": -2,
      "y": 17,
      "z": 0,
      "name": "Wood_Blackwood_Planks"
    },
    {
      "x": -2,
      "y": 18,
      "z": 0,
      "name": "Wood_Blackwood_Roof_Steep",
      "rotation": 3
    },
    {
      "x": -2,
      "y": 19,
      "z": 0,
      "name": "Wood_Blackwood_Roof_Steep",
      "filler": 1024,
      "rotation": 3
    },
    {
      "x": -2,
      "y": 1,
      "z": 1,
      "name": "Rock_Volcanic"
    },
    {
      "x": -2,
      "y": 2,
      "z": 1,
      "name": "Rock_Volcanic"
    },
    {
      "x": -2,
      "y": 3,
      "z": 1,
      "name": "Rock_Volcanic"
    },
    {
      "x": -2,
      "y": 4,
      "z": 1,
      "name": "Wood_Deadwood_Planks"
    },
    {
      "x": -2,
      "y": 5,
      "z": 1,
      "name": "Empty"
    },
    {
      "x": -2,
      "y": 6,
      "z": 1,
      "name": "Empty"
    },
    {
      "x": -2,
      "y": 7,
      "z": 1,
      "name": "Empty"
    },
    {
      "x": -2,
      "y": 8,
      "z": 1,
      "name": "Furniture_Ancient_Platform"
    },
    {
      "x": -2,
      "y": 9,
      "z": 1,
      "name": "Empty"
    },
    {
      "x": -2,
      "y": 10,
      "z": 1,
      "name": "Empty"
    },
    {
      "x": -2,
      "y": 11,
      "z": 1,
      "name": "Empty"
    },
    {
      "x": -2,
      "y": 12,
      "z": 1,
      "name": "Empty"
    },
    {
      "x": -2,
      "y": 13,
      "z": 1,
      "name": "Wood_Blackwood_Planks_Half",
      "rotation": 5
    },
    {
      "x": -2,
      "y": 14,
      "z": 1,
      "name": "Wood_Blackwood_Planks"
    },
    {
      "x": -2,
      "y": 15,
      "z": 1,
      "name": "Wood_Blackwood_Planks"
    },
    {
      "x": -2,
      "y": 16,
      "z": 1,
      "name": "Wood_Blackwood_Planks"
    },
    {
      "x": -2,
      "y": 17,
      "z": 1,
      "name": "Wood_Blackwood_Planks"
    },
    {
      "x": -2,
      "y": 18,
      "z": 1,
      "name": "Wood_Blackwood_Roof_Steep",
      "rotation": 3
    },
    {
      "x": -2,
      "y": 19,
      "z": 1,
      "name": "Wood_Blackwood_Roof_Steep",
      "filler": 1024,
      "rotation": 3
    },
    {
      "x": -2,
      "y": 1,
      "z": 2,
      "name": "Rock_Volcanic"
    },
    {
      "x": -2,
      "y": 2,
      "z": 2,
      "name": "Rock_Volcanic"
    },
    {
      "x": -2,
      "y": 3,
      "z": 2,
      "name": "Rock_Volcanic"
    },
    {
      "x": -2,
      "y": 4,
      "z": 2,
      "name": "Wood_Deadwood_Planks"
    },
    {
      "x": -2,
      "y": 5,
      "z": 2,
      "name": "Empty"
    },
    {
      "x": -2,
      "y": 6,
      "z": 2,
      "name": "Empty"
    },
    {
      "x": -2,
      "y": 7,
      "z": 2,
      "name": "Empty"
    },
    {
      "x": -2,
      "y": 8,
      "z": 2,
      "name": "Furniture_Ancient_Platform"
    },
    {
      "x": -2,
      "y": 9,
      "z": 2,
      "name": "Furniture_Ancient_Barrel"
    },
    {
      "x": -2,
      "y": 10,
      "z": 2,
      "name": "Empty"
    },
    {
      "x": -2,
      "y": 11,
      "z": 2,
      "name": "Empty"
    },
    {
      "x": -2,
      "y": 12,
      "z": 2,
      "name": "Empty"
    },
    {
      "x": -2,
      "y": 13,
      "z": 2,
      "name": "Wood_Blackwood_Planks_Half",
      "rotation": 5
    },
    {
      "x": -2,
      "y": 14,
      "z": 2,
      "name": "Wood_Blackwood_Planks"
    },
    {
      "x": -2,
      "y": 15,
      "z": 2,
      "name": "Wood_Blackwood_Planks"
    },
    {
      "x": -2,
      "y": 16,
      "z": 2,
      "name": "Wood_Blackwood_Planks"
    },
    {
      "x": -2,
      "y": 17,
      "z": 2,
      "name": "Wood_Blackwood_Planks"
    },
    {
      "x": -2,
      "y": 18,
      "z": 2,
      "name": "Wood_Blackwood_Roof_Steep",
      "rotation": 3
    },
    {
      "x": -2,
      "y": 19,
      "z": 2,
      "name": "Wood_Blackwood_Roof_Steep",
      "filler": 1024,
      "rotation": 3
    },
    {
      "x": -2,
      "y": 1,
      "z": 3,
      "name": "Rock_Volcanic"
    },
    {
      "x": -2,
      "y": 2,
      "z": 3,
      "name": "Rock_Volcanic"
    },
    {
      "x": -2,
      "y": 3,
      "z": 3,
      "name": "Rock_Volcanic"
    },
    {
      "x": -2,
      "y": 4,
      "z": 3,
      "name": "Wood_Deadwood_Planks"
    },
    {
      "x": -2,
      "y": 5,
      "z": 3,
      "name": "Empty"
    },
    {
      "x": -2,
      "y": 6,
      "z": 3,
      "name": "Empty"
    },
    {
      "x": -2,
      "y": 7,
      "z": 3,
      "name": "Empty"
    },
    {
      "x": -2,
      "y": 8,
      "z": 3,
      "name": "Furniture_Ancient_Platform"
    },
    {
      "x": -2,
      "y": 9,
      "z": 3,
      "name": "Furniture_Ancient_Crate",
      "rotation": 2
    },
    {
      "x": -2,
      "y": 10,
      "z": 3,
      "name": "Furniture_Human_Ruins_Torch",
      "rotation": 1
    },
    {
      "x": -2,
      "y": 11,
      "z": 3,
      "name": "Empty"
    },
    {
      "x": -2,
      "y": 12,
      "z": 3,
      "name": "Empty"
    },
    {
      "x": -2,
      "y": 13,
      "z": 3,
      "name": "Wood_Blackwood_Planks"
    },
    {
      "x": -2,
      "y": 14,
      "z": 3,
      "name": "Wood_Blackwood_Planks"
    },
    {
      "x": -2,
      "y": 15,
      "z": 3,
      "name": "Wood_Burnt_Trunk"
    },
    {
      "x": -2,
      "y": 16,
      "z": 3,
      "name": "Wood_Burnt_Trunk"
    },
    {
      "x": -2,
      "y": 17,
      "z": 3,
      "name": "Wood_Burnt_Trunk"
    },
    {
      "x": -2,
      "y": 18,
      "z": 3,
      "name": "*Wood_Blackwood_Roof_Steep_State_Definitions_Corner_Right"
    },
    {
      "x": -2,
      "y": 19,
      "z": 3,
      "name": "*Wood_Blackwood_Roof_Steep_State_Definitions_Corner_Right",
      "filler": 1024
    },
    {
      "x": -2,
      "y": 3,
      "z": 4,
      "name": "Rock_Volcanic"
    },
    {
      "x": -2,
      "y": 4,
      "z": 4,
      "name": "Rock_Volcanic"
    },
    {
      "x": -2,
      "y": 5,
      "z": 4,
      "name": "Rock_Volcanic"
    },
    {
      "x": -2,
      "y": 6,
      "z": 4,
      "name": "Rock_Volcanic_Cobble"
    },
    {
      "x": -2,
      "y": 7,
      "z": 4,
      "name": "Rock_Basalt_Brick"
    },
    {
      "x": -2,
      "y": 8,
      "z": 4,
      "name": "Rock_Basalt_Brick"
    },
    {
      "x": -2,
      "y": 9,
      "z": 4,
      "name": "Wood_Deadwood_Planks"
    },
    {
      "x": -2,
      "y": 10,
      "z": 4,
      "name": "Wood_Blackwood_Planks"
    },
    {
      "x": -2,
      "y": 11,
      "z": 4,
      "name": "Wood_Blackwood_Planks"
    },
    {
      "x": -2,
      "y": 12,
      "z": 4,
      "name": "Wood_Blackwood_Planks"
    },
    {
      "x": -2,
      "y": 13,
      "z": 4,
      "name": "Wood_Blackwood_Roof_Steep"
    },
    {
      "x": -2,
      "y": 14,
      "z": 4,
      "name": "Wood_Blackwood_Roof_Steep",
      "filler": 1024
    },
    {
      "x": -2,
      "y": 5,
      "z": 5,
      "name": "Rock_Slate"
    },
    {
      "x": -2,
      "y": 6,
      "z": 5,
      "name": "Rock_Slate"
    },
    {
      "x": -2,
      "y": 7,
      "z": 5,
      "name": "Rock_Slate"
    },
    {
      "x": -1,
      "y": 3,
      "z": -5,
      "name": "Rock_Volcanic"
    },
    {
      "x": -1,
      "y": 4,
      "z": -5,
      "name": "Rock_Volcanic"
    },
    {
      "x": -1,
      "y": 2,
      "z": -4,
      "name": "Rock_Volcanic"
    },
    {
      "x": -1,
      "y": 3,
      "z": -4,
      "name": "Rock_Volcanic"
    },
    {
      "x": -1,
      "y": 4,
      "z": -4,
      "name": "Rock_Volcanic"
    },
    {
      "x": -1,
      "y": 5,
      "z": -4,
      "name": "Rock_Volcanic"
    },
    {
      "x": -1,
      "y": 6,
      "z": -4,
      "name": "Rock_Volcanic"
    },
    {
      "x": -1,
      "y": 7,
      "z": -4,
      "name": "Rock_Volcanic"
    },
    {
      "x": -1,
      "y": 15,
      "z": -4,
      "name": "Cloth_Roof_Hide_Flap",
      "rotation": 2
    },
    {
      "x": -1,
      "y": 16,
      "z": -4,
      "name": "Cloth_Roof_Hide_Vertical",
      "rotation": 2
    },
    {
      "x": -1,
      "y": 1,
      "z": -3,
      "name": "Rock_Volcanic"
    },
    {
      "x": -1,
      "y": 2,
      "z": -3,
      "name": "Rock_Volcanic"
    },
    {
      "x": -1,
      "y": 3,
      "z": -3,
      "name": "Rock_Volcanic"
    },
    {
      "x": -1,
      "y": 4,
      "z": -3,
      "name": "Rock_Volcanic"
    },
    {
      "x": -1,
      "y": 5,
      "z": -3,
      "name": "Rock_Volcanic"
    },
    {
      "x": -1,
      "y": 6,
      "z": -3,
      "name": "Rock_Volcanic"
    },
    {
      "x": -1,
      "y": 7,
      "z": -3,
      "name": "Rock_Volcanic"
    },
    {
      "x": -1,
      "y": 8,
      "z": -3,
      "name": "Rock_Volcanic_Cobble_Half"
    },
    {
      "x": -1,
      "y": 16,
      "z": -3,
      "name": "Wood_Blackwood_Beam",
      "rotation": 5
    },
    {
      "x": -1,
      "y": 17,
      "z": -3,
      "name": "Cloth_Roof_Hide_Flat"
    },
    {
      "x": -1,
      "y": 19,
      "z": -3,
      "name": "Cloth_Roof_Hide_Flap",
      "rotation": 3
    },
    {
      "x": -1,
      "y": 20,
      "z": -3,
      "name": "Cloth_Roof_Hide_Vertical",
      "rotation": 3
    },
    {
      "x": -1,
      "y": 1,
      "z": -2,
      "name": "Rock_Volcanic"
    },
    {
      "x": -1,
      "y": 2,
      "z": -2,
      "name": "Rock_Volcanic"
    },
    {
      "x": -1,
      "y": 3,
      "z": -2,
      "name": "Rock_Volcanic"
    },
    {
      "x": -1,
      "y": 4,
      "z": -2,
      "name": "Rock_Volcanic"
    },
    {
      "x": -1,
      "y": 5,
      "z": -2,
      "name": "Rock_Volcanic"
    },
    {
      "x": -1,
      "y": 6,
      "z": -2,
      "name": "Rock_Volcanic"
    },
    {
      "x": -1,
      "y": 7,
      "z": -2,
      "name": "Rock_Volcanic_Cobble"
    },
    {
      "x": -1,
      "y": 8,
      "z": -2,
      "name": "Rock_Volcanic_Cobble"
    },
    {
      "x": -1,
      "y": 9,
      "z": -2,
      "name": "Wood_Deadwood_Planks_Half",
      "rotation": 5
    },
    {
      "x": -1,
      "y": 10,
      "z": -2,
      "name": "Wood_Deadwood_Planks_Half",
      "rotation": 5
    },
    {
      "x": -1,
      "y": 11,
      "z": -2,
      "name": "Wood_Blackwood_Planks"
    },
    {
      "x": -1,
      "y": 12,
      "z": -2,
      "name": "Wood_Blackwood_Planks"
    },
    {
      "x": -1,
      "y": 13,
      "z": -2,
      "name": "Wood_Blackwood_Roof_Steep",
      "rotation": 2
    },
    {
      "x": -1,
      "y": 14,
      "z": -2,
      "name": "Wood_Blackwood_Roof_Steep",
      "filler": 1024,
      "rotation": 2
    },
    {
      "x": -1,
      "y": 1,
      "z": -1,
      "name": "Rock_Volcanic"
    },
    {
      "x": -1,
      "y": 2,
      "z": -1,
      "name": "Rock_Volcanic"
    },
    {
      "x": -1,
      "y": 3,
      "z": -1,
      "name": "Rock_Volcanic"
    },
    {
      "x": -1,
      "y": 4,
      "z": -1,
      "name": "Wood_Deadwood_Planks"
    },
    {
      "x": -1,
      "y": 5,
      "z": -1,
      "name": "Empty"
    },
    {
      "x": -1,
      "y": 6,
      "z": -1,
      "name": "Empty"
    },
    {
      "x": -1,
      "y": 7,
      "z": -1,
      "name": "Empty"
    },
    {
      "x": -1,
      "y": 8,
      "z": -1,
      "name": "Furniture_Ancient_Platform"
    },
    {
      "x": -1,
      "y": 9,
      "z": -1,
      "name": "Empty"
    },
    {
      "x": -1,
      "y": 10,
      "z": -1,
      "name": "Empty"
    },
    {
      "x": -1,
      "y": 11,
      "z": -1,
      "name": "Empty"
    },
    {
      "x": -1,
      "y": 12,
      "z": -1,
      "name": "Empty"
    },
    {
      "x": -1,
      "y": 13,
      "z": -1,
      "name": "Wood_Blackwood_Planks_Half",
      "rotation": 4
    },
    {
      "x": -1,
      "y": 14,
      "z": -1,
      "name": "Wood_Blackwood_Planks"
    },
    {
      "x": -1,
      "y": 15,
      "z": -1,
      "name": "Wood_Blackwood_Planks"
    },
    {
      "x": -1,
      "y": 16,
      "z": -1,
      "name": "Wood_Blackwood_Planks"
    },
    {
      "x": -1,
      "y": 17,
      "z": -1,
      "name": "Wood_Blackwood_Planks"
    },
    {
      "x": -1,
      "y": 18,
      "z": -1,
      "name": "Wood_Blackwood_Roof_Steep",
      "rotation": 2
    },
    {
      "x": -1,
      "y": 19,
      "z": -1,
      "name": "Wood_Blackwood_Roof_Steep",
      "filler": 1024,
      "rotation": 2
    },
    {
      "x": -1,
      "y": 1,
      "z": 0,
      "name": "Rock_Volcanic"
    },
    {
      "x": -1,
      "y": 2,
      "z": 0,
      "name": "Rock_Volcanic"
    },
    {
      "x": -1,
      "y": 3,
      "z": 0,
      "name": "Rock_Volcanic"
    },
    {
      "x": -1,
      "y": 4,
      "z": 0,
      "name": "Wood_Deadwood_Planks"
    },
    {
      "x": -1,
      "y": 5,
      "z": 0,
      "name": "Empty"
    },
    {
      "x": -1,
      "y": 6,
      "z": 0,
      "name": "Empty"
    },
    {
      "x": -1,
      "y": 7,
      "z": 0,
      "name": "Empty"
    },
    {
      "x": -1,
      "y": 8,
      "z": 0,
      "name": "Furniture_Ancient_Platform"
    },
    {
      "x": -1,
      "y": 9,
      "z": 0,
      "name": "Empty"
    },
    {
      "x": -1,
      "y": 10,
      "z": 0,
      "name": "Empty"
    },
    {
      "x": -1,
      "y": 11,
      "z": 0,
      "name": "Empty"
    },
    {
      "x": -1,
      "y": 12,
      "z": 0,
      "name": "Empty"
    },
    {
      "x": -1,
      "y": 13,
      "z": 0,
      "name": "Empty"
    },
    {
      "x": -1,
      "y": 14,
      "z": 0,
      "name": "Empty"
    },
    {
      "x": -1,
      "y": 15,
      "z": 0,
      "name": "Empty"
    },
    {
      "x": -1,
      "y": 16,
      "z": 0,
      "name": "Empty"
    },
    {
      "x": -1,
      "y": 17,
      "z": 0,
      "name": "Empty"
    },
    {
      "x": -1,
      "y": 18,
      "z": 0,
      "name": "Empty"
    },
    {
      "x": -1,
      "y": 19,
      "z": 0,
      "name": "Empty"
    },
    {
      "x": -1,
      "y": 20,
      "z": 0,
      "name": "Wood_Deadwood_Roof_Flat"
    },
    {
      "x": -1,
      "y": 1,
      "z": 1,
      "name": "Rock_Volcanic"
    },
    {
      "x": -1,
      "y": 2,
      "z": 1,
      "name": "Rock_Volcanic"
    },
    {
      "x": -1,
      "y": 3,
      "z": 1,
      "name": "Rock_Volcanic"
    },
    {
      "x": -1,
      "y": 4,
      "z": 1,
      "name": "Rock_Volcanic"
    },
    {
      "x": -1,
      "y": 5,
      "z": 1,
      "name": "Rock_Basalt_Cobble_Stairs",
      "rotation": 3
    },
    {
      "x": -1,
      "y": 6,
      "z": 1,
      "name": "Empty"
    },
    {
      "x": -1,
      "y": 7,
      "z": 1,
      "name": "Rock_Basalt_Cobble_Half",
      "rotation": 7
    },
    {
      "x": -1,
      "y": 8,
      "z": 1,
      "name": "Furniture_Ancient_Platform"
    },
    {
      "x": -1,
      "y": 9,
      "z": 1,
      "name": "Empty"
    },
    {
      "x": -1,
      "y": 10,
      "z": 1,
      "name": "Rock_Basalt_Brick_Half",
      "rotation": 7
    },
    {
      "x": -1,
      "y": 11,
      "z": 1,
      "name": "Empty"
    },
    {
      "x": -1,
      "y": 12,
      "z": 1,
      "name": "Empty"
    },
    {
      "x": -1,
      "y": 13,
      "z": 1,
      "name": "Empty"
    },
    {
      "x": -1,
      "y": 14,
      "z": 1,
      "name": "Rock_Basalt_Brick_Half",
      "rotation": 7
    },
    {
      "x": -1,
      "y": 15,
      "z": 1,
      "name": "Rock_Basalt_Cobble_Stairs",
      "rotation": 9
    },
    {
      "x": -1,
      "y": 16,
      "z": 1,
      "name": "Rock_Basalt_Cobble"
    },
    {
      "x": -1,
      "y": 17,
      "z": 1,
      "name": "Rock_Basalt_Cobble_Stairs",
      "rotation": 3
    },
    {
      "x": -1,
      "y": 18,
      "z": 1,
      "name": "Empty"
    },
    {
      "x": -1,
      "y": 19,
      "z": 1,
      "name": "Empty"
    },
    {
      "x": -1,
      "y": 20,
      "z": 1,
      "name": "Wood_Deadwood_Roof_Flat"
    },
    {
      "x": -1,
      "y": 1,
      "z": 2,
      "name": "Rock_Volcanic"
    },
    {
      "x": -1,
      "y": 2,
      "z": 2,
      "name": "Rock_Volcanic"
    },
    {
      "x": -1,
      "y": 3,
      "z": 2,
      "name": "Rock_Volcanic"
    },
    {
      "x": -1,
      "y": 4,
      "z": 2,
      "name": "Wood_Deadwood_Planks"
    },
    {
      "x": -1,
      "y": 5,
      "z": 2,
      "name": "Empty"
    },
    {
      "x": -1,
      "y": 6,
      "z": 2,
      "name": "Empty"
    },
    {
      "x": -1,
      "y": 7,
      "z": 2,
      "name": "Empty"
    },
    {
      "x": -1,
      "y": 8,
      "z": 2,
      "name": "Furniture_Ancient_Platform"
    },
    {
      "x": -1,
      "y": 9,
      "z": 2,
      "name": "Empty"
    },
    {
      "x": -1,
      "y": 10,
      "z": 2,
      "name": "Empty"
    },
    {
      "x": -1,
      "y": 11,
      "z": 2,
      "name": "Empty"
    },
    {
      "x": -1,
      "y": 12,
      "z": 2,
      "name": "Empty"
    },
    {
      "x": -1,
      "y": 13,
      "z": 2,
      "name": "Empty"
    },
    {
      "x": -1,
      "y": 14,
      "z": 2,
      "name": "Empty"
    },
    {
      "x": -1,
      "y": 15,
      "z": 2,
      "name": "Empty"
    },
    {
      "x": -1,
      "y": 16,
      "z": 2,
      "name": "Empty"
    },
    {
      "x": -1,
      "y": 17,
      "z": 2,
      "name": "Empty"
    },
    {
      "x": -1,
      "y": 18,
      "z": 2,
      "name": "Empty"
    },
    {
      "x": -1,
      "y": 19,
      "z": 2,
      "name": "Empty"
    },
    {
      "x": -1,
      "y": 20,
      "z": 2,
      "name": "Wood_Blackwood_Roof_Flat"
    },
    {
      "x": -1,
      "y": 2,
      "z": 3,
      "name": "Rock_Volcanic"
    },
    {
      "x": -1,
      "y": 3,
      "z": 3,
      "name": "Rock_Volcanic"
    },
    {
      "x": -1,
      "y": 4,
      "z": 3,
      "name": "Wood_Deadwood_Planks"
    },
    {
      "x": -1,
      "y": 5,
      "z": 3,
      "name": "Empty"
    },
    {
      "x": -1,
      "y": 6,
      "z": 3,
      "name": "Empty"
    },
    {
      "x": -1,
      "y": 7,
      "z": 3,
      "name": "Empty"
    },
    {
      "x": -1,
      "y": 8,
      "z": 3,
      "name": "Furniture_Ancient_Platform"
    },
    {
      "x": -1,
      "y": 9,
      "z": 3,
      "name": "Block_Spawner_Block",
      "components": {
        "Components": {
          "PlacedByInteraction": {
            "WhoPlacedUuid": {
              "$binary": "5OYreBmdMS+xlzjMlwn5JQ==",
              "$type": "04"
            }
          },
          "BlockSpawner": {
            "BlockSpawnerId": "Zone4_Encounters_Tier1"
          }
        }
      },
      "rotation": 2
    },
    {
      "x": -1,
      "y": 10,
      "z": 3,
      "name": "Empty"
    },
    {
      "x": -1,
      "y": 11,
      "z": 3,
      "name": "Empty"
    },
    {
      "x": -1,
      "y": 12,
      "z": 3,
      "name": "Empty"
    },
    {
      "x": -1,
      "y": 13,
      "z": 3,
      "name": "Wood_Blackwood_Planks_Half",
      "rotation": 6
    },
    {
      "x": -1,
      "y": 14,
      "z": 3,
      "name": "Wood_Blackwood_Planks"
    },
    {
      "x": -1,
      "y": 15,
      "z": 3,
      "name": "Wood_Blackwood_Planks"
    },
    {
      "x": -1,
      "y": 16,
      "z": 3,
      "name": "Wood_Blackwood_Planks"
    },
    {
      "x": -1,
      "y": 17,
      "z": 3,
      "name": "Wood_Blackwood_Planks"
    },
    {
      "x": -1,
      "y": 18,
      "z": 3,
      "name": "Wood_Blackwood_Roof_Steep"
    },
    {
      "x": -1,
      "y": 19,
      "z": 3,
      "name": "Wood_Blackwood_Roof_Steep",
      "filler": 1024
    },
    {
      "x": -1,
      "y": 2,
      "z": 4,
      "name": "Rock_Volcanic"
    },
    {
      "x": -1,
      "y": 3,
      "z": 4,
      "name": "Rock_Volcanic"
    },
    {
      "x": -1,
      "y": 4,
      "z": 4,
      "name": "Rock_Volcanic"
    },
    {
      "x": -1,
      "y": 5,
      "z": 4,
      "name": "Rock_Volcanic"
    },
    {
      "x": -1,
      "y": 6,
      "z": 4,
      "name": "Rock_Volcanic_Cobble"
    },
    {
      "x": -1,
      "y": 7,
      "z": 4,
      "name": "Rock_Volcanic_Cobble"
    },
    {
      "x": -1,
      "y": 8,
      "z": 4,
      "name": "Rock_Basalt_Brick"
    },
    {
      "x": -1,
      "y": 9,
      "z": 4,
      "name": "Wood_Deadwood_Planks"
    },
    {
      "x": -1,
      "y": 10,
      "z": 4,
      "name": "Wood_Blackwood_Planks"
    },
    {
      "x": -1,
      "y": 11,
      "z": 4,
      "name": "Wood_Blackwood_Planks"
    },
    {
      "x": -1,
      "y": 12,
      "z": 4,
      "name": "Wood_Blackwood_Planks"
    },
    {
      "x": -1,
      "y": 13,
      "z": 4,
      "name": "Wood_Blackwood_Roof_Steep"
    },
    {
      "x": -1,
      "y": 14,
      "z": 4,
      "name": "Wood_Blackwood_Roof_Steep",
      "filler": 1024
    },
    {
      "x": -1,
      "y": 4,
      "z": 5,
      "name": "Rock_Volcanic"
    },
    {
      "x": -1,
      "y": 5,
      "z": 5,
      "name": "Rock_Volcanic"
    },
    {
      "x": -1,
      "y": 6,
      "z": 5,
      "name": "Plant_Bush_Dead_Twisted"
    },
    {
      "x": 0,
      "y": 3,
      "z": -5,
      "name": "Rock_Volcanic"
    },
    {
      "x": 0,
      "y": 4,
      "z": -5,
      "name": "Rock_Volcanic"
    },
    {
      "x": 0,
      "y": 2,
      "z": -4,
      "name": "Rock_Volcanic"
    },
    {
      "x": 0,
      "y": 3,
      "z": -4,
      "name": "Rock_Volcanic"
    },
    {
      "x": 0,
      "y": 4,
      "z": -4,
      "name": "Rock_Volcanic"
    },
    {
      "x": 0,
      "y": 5,
      "z": -4,
      "name": "Rock_Volcanic"
    },
    {
      "x": 0,
      "y": 6,
      "z": -4,
      "name": "Rock_Volcanic"
    },
    {
      "x": 0,
      "y": 7,
      "z": -4,
      "name": "Rock_Volcanic"
    },
    {
      "x": 0,
      "y": 8,
      "z": -4,
      "name": "Rock_Volcanic_Cobble_Half"
    },
    {
      "x": 0,
      "y": 20,
      "z": -4,
      "name": "Cloth_Roof_Hide_Flap",
      "rotation": 2
    },
    {
      "x": 0,
      "y": 1,
      "z": -3,
      "name": "Rock_Volcanic"
    },
    {
      "x": 0,
      "y": 2,
      "z": -3,
      "name": "Rock_Volcanic"
    },
    {
      "x": 0,
      "y": 3,
      "z": -3,
      "name": "Rock_Volcanic"
    },
    {
      "x": 0,
      "y": 4,
      "z": -3,
      "name": "Rock_Volcanic"
    },
    {
      "x": 0,
      "y": 5,
      "z": -3,
      "name": "Rock_Volcanic"
    },
    {
      "x": 0,
      "y": 6,
      "z": -3,
      "name": "Rock_Volcanic"
    },
    {
      "x": 0,
      "y": 7,
      "z": -3,
      "name": "Rock_Volcanic"
    },
    {
      "x": 0,
      "y": 8,
      "z": -3,
      "name": "Rock_Volcanic_Cobble_Half"
    },
    {
      "x": 0,
      "y": 12,
      "z": -3,
      "name": "Wood_Blackwood_Beam"
    },
    {
      "x": 0,
      "y": 13,
      "z": -3,
      "name": "Wood_Blackwood_Beam"
    },
    {
      "x": 0,
      "y": 14,
      "z": -3,
      "name": "Wood_Blackwood_Beam"
    },
    {
      "x": 0,
      "y": 15,
      "z": -3,
      "name": "Wood_Blackwood_Beam"
    },
    {
      "x": 0,
      "y": 16,
      "z": -3,
      "name": "Wood_Burnt_Trunk",
      "rotation": 4
    },
    {
      "x": 0,
      "y": 17,
      "z": -3,
      "name": "Wood_Blackwood_Beam"
    },
    {
      "x": 0,
      "y": 18,
      "z": -3,
      "name": "Wood_Blackwood_Beam"
    },
    {
      "x": 0,
      "y": 19,
      "z": -3,
      "name": "Wood_Blackwood_Beam"
    },
    {
      "x": 0,
      "y": 20,
      "z": -3,
      "name": "Wood_Blackwood_Beam"
    },
    {
      "x": 0,
      "y": 21,
      "z": -3,
      "name": "Cloth_Roof_Hide_Flat"
    },
    {
      "x": 0,
      "y": 1,
      "z": -2,
      "name": "Rock_Volcanic"
    },
    {
      "x": 0,
      "y": 2,
      "z": -2,
      "name": "Rock_Volcanic"
    },
    {
      "x": 0,
      "y": 3,
      "z": -2,
      "name": "Rock_Volcanic"
    },
    {
      "x": 0,
      "y": 4,
      "z": -2,
      "name": "Rock_Volcanic"
    },
    {
      "x": 0,
      "y": 5,
      "z": -2,
      "name": "Rock_Volcanic"
    },
    {
      "x": 0,
      "y": 6,
      "z": -2,
      "name": "Rock_Volcanic"
    },
    {
      "x": 0,
      "y": 7,
      "z": -2,
      "name": "Rock_Volcanic_Cobble"
    },
    {
      "x": 0,
      "y": 8,
      "z": -2,
      "name": "Rock_Basalt_Brick"
    },
    {
      "x": 0,
      "y": 11,
      "z": -2,
      "name": "Wood_Blackwood_Planks"
    },
    {
      "x": 0,
      "y": 12,
      "z": -2,
      "name": "Wood_Blackwood_Planks"
    },
    {
      "x": 0,
      "y": 13,
      "z": -2,
      "name": "Wood_Blackwood_Roof_Steep",
      "rotation": 2
    },
    {
      "x": 0,
      "y": 14,
      "z": -2,
      "name": "Wood_Blackwood_Roof_Steep",
      "filler": 1024,
      "rotation": 2
    },
    {
      "x": 0,
      "y": 16,
      "z": -2,
      "name": "Wood_Burnt_Trunk",
      "rotation": 4
    },
    {
      "x": 0,
      "y": 1,
      "z": -1,
      "name": "Rock_Volcanic"
    },
    {
      "x": 0,
      "y": 2,
      "z": -1,
      "name": "Rock_Volcanic"
    },
    {
      "x": 0,
      "y": 3,
      "z": -1,
      "name": "Rock_Volcanic"
    },
    {
      "x": 0,
      "y": 4,
      "z": -1,
      "name": "Wood_Deadwood_Planks"
    },
    {
      "x": 0,
      "y": 5,
      "z": -1,
      "name": "Empty"
    },
    {
      "x": 0,
      "y": 6,
      "z": -1,
      "name": "Empty"
    },
    {
      "x": 0,
      "y": 7,
      "z": -1,
      "name": "Empty"
    },
    {
      "x": 0,
      "y": 8,
      "z": -1,
      "name": "Furniture_Ancient_Platform"
    },
    {
      "x": 0,
      "y": 9,
      "z": -1,
      "name": "Empty"
    },
    {
      "x": 0,
      "y": 10,
      "z": -1,
      "name": "Empty"
    },
    {
      "x": 0,
      "y": 11,
      "z": -1,
      "name": "Empty"
    },
    {
      "x": 0,
      "y": 12,
      "z": -1,
      "name": "Empty"
    },
    {
      "x": 0,
      "y": 13,
      "z": -1,
      "name": "Wood_Blackwood_Planks_Half",
      "rotation": 4
    },
    {
      "x": 0,
      "y": 14,
      "z": -1,
      "name": "Wood_Blackwood_Planks"
    },
    {
      "x": 0,
      "y": 15,
      "z": -1,
      "name": "Wood_Blackwood_Planks"
    },
    {
      "x": 0,
      "y": 16,
      "z": -1,
      "name": "Wood_Burnt_Trunk",
      "rotation": 4
    },
    {
      "x": 0,
      "y": 17,
      "z": -1,
      "name": "Wood_Blackwood_Planks"
    },
    {
      "x": 0,
      "y": 18,
      "z": -1,
      "name": "Wood_Blackwood_Roof_Steep",
      "rotation": 2
    },
    {
      "x": 0,
      "y": 19,
      "z": -1,
      "name": "Wood_Blackwood_Roof_Steep",
      "filler": 1024,
      "rotation": 2
    },
    {
      "x": 0,
      "y": 2,
      "z": 0,
      "name": "Rock_Volcanic"
    },
    {
      "x": 0,
      "y": 3,
      "z": 0,
      "name": "Rock_Volcanic"
    },
    {
      "x": 0,
      "y": 4,
      "z": 0,
      "name": "Rock_Volcanic"
    },
    {
      "x": 0,
      "y": 5,
      "z": 0,
      "name": "Rock_Basalt_Cobble_Stairs",
      "rotation": 2
    },
    {
      "x": 0,
      "y": 6,
      "z": 0,
      "name": "Empty"
    },
    {
      "x": 0,
      "y": 7,
      "z": 0,
      "name": "Rock_Basalt_Cobble_Half",
      "rotation": 6
    },
    {
      "x": 0,
      "y": 8,
      "z": 0,
      "name": "Furniture_Ancient_Platform"
    },
    {
      "x": 0,
      "y": 9,
      "z": 0,
      "name": "Empty"
    },
    {
      "x": 0,
      "y": 10,
      "z": 0,
      "name": "Rock_Basalt_Brick_Half",
      "rotation": 6
    },
    {
      "x": 0,
      "y": 11,
      "z": 0,
      "name": "Empty"
    },
    {
      "x": 0,
      "y": 12,
      "z": 0,
      "name": "Empty"
    },
    {
      "x": 0,
      "y": 13,
      "z": 0,
      "name": "Empty"
    },
    {
      "x": 0,
      "y": 14,
      "z": 0,
      "name": "Rock_Basalt_Brick_Half",
      "rotation": 6
    },
    {
      "x": 0,
      "y": 15,
      "z": 0,
      "name": "Empty"
    },
    {
      "x": 0,
      "y": 16,
      "z": 0,
      "name": "Wood_Burnt_Branch_Long",
      "rotation": 4
    },
    {
      "x": 0,
      "y": 17,
      "z": 0,
      "name": "Empty"
    },
    {
      "x": 0,
      "y": 18,
      "z": 0,
      "name": "Empty"
    },
    {
      "x": 0,
      "y": 19,
      "z": 0,
      "name": "Empty"
    },
    {
      "x": 0,
      "y": 1,
      "z": 1,
      "name": "Rock_Volcanic"
    },
    {
      "x": 0,
      "y": 2,
      "z": 1,
      "name": "Rock_Volcanic"
    },
    {
      "x": 0,
      "y": 3,
      "z": 1,
      "name": "Rock_Volcanic"
    },
    {
      "x": 0,
      "y": 4,
      "z": 1,
      "name": "Wood_Deadwood_Planks"
    },
    {
      "x": 0,
      "y": 5,
      "z": 1,
      "name": "Rock_Basalt_Cobble_Half"
    },
    {
      "x": 0,
      "y": 6,
      "z": 1,
      "name": "Wood_Burnt_Branch_Long"
    },
    {
      "x": 0,
      "y": 7,
      "z": 1,
      "name": "Rock_Basalt_Cobble"
    },
    {
      "x": 0,
      "y": 8,
      "z": 1,
      "name": "Wood_Burnt_Trunk"
    },
    {
      "x": 0,
      "y": 9,
      "z": 1,
      "name": "Wood_Burnt_Trunk"
    },
    {
      "x": 0,
      "y": 10,
      "z": 1,
      "name": "Wood_Burnt_Trunk"
    },
    {
      "x": 0,
      "y": 11,
      "z": 1,
      "name": "Wood_Burnt_Trunk"
    },
    {
      "x": 0,
      "y": 12,
      "z": 1,
      "name": "Wood_Burnt_Trunk"
    },
    {
      "x": 0,
      "y": 13,
      "z": 1,
      "name": "Wood_Burnt_Trunk"
    },
    {
      "x": 0,
      "y": 14,
      "z": 1,
      "name": "Wood_Burnt_Trunk"
    },
    {
      "x": 0,
      "y": 15,
      "z": 1,
      "name": "Rock_Basalt_Cobble"
    },
    {
      "x": 0,
      "y": 16,
      "z": 1,
      "name": "Rock_Basalt_Cobble"
    },
    {
      "x": 0,
      "y": 17,
      "z": 1,
      "name": "Rock_Basalt_Cobble"
    },
    {
      "x": 0,
      "y": 18,
      "z": 1,
      "name": "Empty"
    },
    {
      "x": 0,
      "y": 19,
      "z": 1,
      "name": "Empty"
    },
    {
      "x": 0,
      "y": 20,
      "z": 1,
      "name": "Wood_Blackwood_Roof_Flat"
    },
    {
      "x": 0,
      "y": 1,
      "z": 2,
      "name": "Rock_Volcanic"
    },
    {
      "x": 0,
      "y": 2,
      "z": 2,
      "name": "Rock_Volcanic"
    },
    {
      "x": 0,
      "y": 3,
      "z": 2,
      "name": "Rock_Volcanic"
    },
    {
      "x": 0,
      "y": 4,
      "z": 2,
      "name": "Wood_Deadwood_Planks"
    },
    {
      "x": 0,
      "y": 5,
      "z": 2,
      "name": "Rock_Basalt_Cobble_Stairs"
    },
    {
      "x": 0,
      "y": 6,
      "z": 2,
      "name": "Empty"
    },
    {
      "x": 0,
      "y": 7,
      "z": 2,
      "name": "Rock_Basalt_Cobble_Half",
      "rotation": 4
    },
    {
      "x": 0,
      "y": 8,
      "z": 2,
      "name": "Furniture_Ancient_Platform"
    },
    {
      "x": 0,
      "y": 9,
      "z": 2,
      "name": "Empty"
    },
    {
      "x": 0,
      "y": 10,
      "z": 2,
      "name": "Rock_Basalt_Brick_Half",
      "rotation": 4
    },
    {
      "x": 0,
      "y": 11,
      "z": 2,
      "name": "Empty"
    },
    {
      "x": 0,
      "y": 12,
      "z": 2,
      "name": "Empty"
    },
    {
      "x": 0,
      "y": 13,
      "z": 2,
      "name": "Empty"
    },
    {
      "x": 0,
      "y": 14,
      "z": 2,
      "name": "Rock_Basalt_Brick_Half",
      "rotation": 4
    },
    {
      "x": 0,
      "y": 15,
      "z": 2,
      "name": "Empty"
    },
    {
      "x": 0,
      "y": 16,
      "z": 2,
      "name": "Wood_Burnt_Branch_Long",
      "rotation": 4
    },
    {
      "x": 0,
      "y": 17,
      "z": 2,
      "name": "Empty"
    },
    {
      "x": 0,
      "y": 18,
      "z": 2,
      "name": "Empty"
    },
    {
      "x": 0,
      "y": 19,
      "z": 2,
      "name": "Empty"
    },
    {
      "x": 0,
      "y": 20,
      "z": 2,
      "name": "Wood_Blackwood_Roof_Flat"
    },
    {
      "x": 0,
      "y": 2,
      "z": 3,
      "name": "Rock_Volcanic"
    },
    {
      "x": 0,
      "y": 3,
      "z": 3,
      "name": "Rock_Volcanic"
    },
    {
      "x": 0,
      "y": 4,
      "z": 3,
      "name": "Wood_Deadwood_Planks"
    },
    {
      "x": 0,
      "y": 5,
      "z": 3,
      "name": "Empty"
    },
    {
      "x": 0,
      "y": 6,
      "z": 3,
      "name": "Empty"
    },
    {
      "x": 0,
      "y": 7,
      "z": 3,
      "name": "Empty"
    },
    {
      "x": 0,
      "y": 8,
      "z": 3,
      "name": "Furniture_Ancient_Platform"
    },
    {
      "x": 0,
      "y": 9,
      "z": 3,
      "name": "Empty"
    },
    {
      "x": 0,
      "y": 10,
      "z": 3,
      "name": "Empty"
    },
    {
      "x": 0,
      "y": 11,
      "z": 3,
      "name": "Empty"
    },
    {
      "x": 0,
      "y": 12,
      "z": 3,
      "name": "Empty"
    },
    {
      "x": 0,
      "y": 13,
      "z": 3,
      "name": "Wood_Blackwood_Planks_Half",
      "rotation": 6
    },
    {
      "x": 0,
      "y": 14,
      "z": 3,
      "name": "Wood_Blackwood_Planks"
    },
    {
      "x": 0,
      "y": 15,
      "z": 3,
      "name": "Wood_Blackwood_Planks"
    },
    {
      "x": 0,
      "y": 16,
      "z": 3,
      "name": "Wood_Blackwood_Planks"
    },
    {
      "x": 0,
      "y": 17,
      "z": 3,
      "name": "Wood_Blackwood_Planks"
    },
    {
      "x": 0,
      "y": 18,
      "z": 3,
      "name": "Wood_Blackwood_Roof_Steep"
    },
    {
      "x": 0,
      "y": 19,
      "z": 3,
      "name": "Wood_Blackwood_Roof_Steep",
      "filler": 1024
    },
    {
      "x": 0,
      "y": 3,
      "z": 4,
      "name": "Rock_Volcanic"
    },
    {
      "x": 0,
      "y": 4,
      "z": 4,
      "name": "Rock_Volcanic"
    },
    {
      "x": 0,
      "y": 5,
      "z": 4,
      "name": "Rock_Volcanic"
    },
    {
      "x": 0,
      "y": 6,
      "z": 4,
      "name": "Rock_Volcanic_Cobble"
    },
    {
      "x": 0,
      "y": 7,
      "z": 4,
      "name": "Rock_Volcanic_Cobble"
    },
    {
      "x": 0,
      "y": 8,
      "z": 4,
      "name": "Rock_Basalt_Brick"
    },
    {
      "x": 0,
      "y": 9,
      "z": 4,
      "name": "Empty"
    },
    {
      "x": 0,
      "y": 10,
      "z": 4,
      "name": "Empty"
    },
    {
      "x": 0,
      "y": 11,
      "z": 4,
      "name": "Empty"
    },
    {
      "x": 0,
      "y": 12,
      "z": 4,
      "name": "Wood_Blackwood_Planks"
    },
    {
      "x": 0,
      "y": 13,
      "z": 4,
      "name": "Wood_Blackwood_Roof_Steep"
    },
    {
      "x": 0,
      "y": 14,
      "z": 4,
      "name": "Wood_Blackwood_Roof_Steep",
      "filler": 1024
    },
    {
      "x": 0,
      "y": 3,
      "z": 5,
      "name": "Rock_Volcanic"
    },
    {
      "x": 0,
      "y": 4,
      "z": 5,
      "name": "Rock_Volcanic"
    },
    {
      "x": 0,
      "y": 5,
      "z": 5,
      "name": "Rock_Volcanic"
    },
    {
      "x": 1,
      "y": 3,
      "z": -5,
      "name": "Rock_Volcanic"
    },
    {
      "x": 1,
      "y": 4,
      "z": -5,
      "name": "Rock_Volcanic"
    },
    {
      "x": 1,
      "y": 2,
      "z": -4,
      "name": "Rock_Volcanic"
    },
    {
      "x": 1,
      "y": 3,
      "z": -4,
      "name": "Rock_Volcanic"
    },
    {
      "x": 1,
      "y": 4,
      "z": -4,
      "name": "Rock_Volcanic"
    },
    {
      "x": 1,
      "y": 5,
      "z": -4,
      "name": "Rock_Volcanic"
    },
    {
      "x": 1,
      "y": 6,
      "z": -4,
      "name": "Rock_Volcanic"
    },
    {
      "x": 1,
      "y": 7,
      "z": -4,
      "name": "Rock_Volcanic_Cobble_Stairs",
      "rotation": 1
    },
    {
      "x": 1,
      "y": 16,
      "z": -4,
      "name": "Cloth_Roof_Hide_Flap",
      "rotation": 2
    },
    {
      "x": 1,
      "y": 1,
      "z": -3,
      "name": "Rock_Volcanic"
    },
    {
      "x": 1,
      "y": 2,
      "z": -3,
      "name": "Rock_Volcanic"
    },
    {
      "x": 1,
      "y": 3,
      "z": -3,
      "name": "Rock_Volcanic"
    },
    {
      "x": 1,
      "y": 4,
      "z": -3,
      "name": "Rock_Volcanic"
    },
    {
      "x": 1,
      "y": 5,
      "z": -3,
      "name": "Rock_Volcanic"
    },
    {
      "x": 1,
      "y": 6,
      "z": -3,
      "name": "Rock_Volcanic"
    },
    {
      "x": 1,
      "y": 7,
      "z": -3,
      "name": "Rock_Volcanic_Cobble_Stairs",
      "rotation": 1
    },
    {
      "x": 1,
      "y": 16,
      "z": -3,
      "name": "Wood_Blackwood_Beam",
      "rotation": 5
    },
    {
      "x": 1,
      "y": 17,
      "z": -3,
      "name": "Cloth_Roof_Hide_Flat"
    },
    {
      "x": 1,
      "y": 1,
      "z": -2,
      "name": "Rock_Volcanic"
    },
    {
      "x": 1,
      "y": 2,
      "z": -2,
      "name": "Rock_Volcanic"
    },
    {
      "x": 1,
      "y": 3,
      "z": -2,
      "name": "Rock_Volcanic"
    },
    {
      "x": 1,
      "y": 4,
      "z": -2,
      "name": "Rock_Volcanic"
    },
    {
      "x": 1,
      "y": 5,
      "z": -2,
      "name": "Rock_Volcanic"
    },
    {
      "x": 1,
      "y": 6,
      "z": -2,
      "name": "Rock_Volcanic"
    },
    {
      "x": 1,
      "y": 7,
      "z": -2,
      "name": "Rock_Volcanic_Cobble"
    },
    {
      "x": 1,
      "y": 8,
      "z": -2,
      "name": "Rock_Basalt_Brick"
    },
    {
      "x": 1,
      "y": 9,
      "z": -2,
      "name": "Wood_Deadwood_Planks_Half",
      "rotation": 7
    },
    {
      "x": 1,
      "y": 10,
      "z": -2,
      "name": "Wood_Deadwood_Planks_Half",
      "rotation": 7
    },
    {
      "x": 1,
      "y": 11,
      "z": -2,
      "name": "Wood_Blackwood_Planks"
    },
    {
      "x": 1,
      "y": 12,
      "z": -2,
      "name": "Wood_Blackwood_Planks"
    },
    {
      "x": 1,
      "y": 13,
      "z": -2,
      "name": "Wood_Blackwood_Roof_Steep",
      "rotation": 2
    },
    {
      "x": 1,
      "y": 14,
      "z": -2,
      "name": "Wood_Blackwood_Roof_Steep",
      "filler": 1024,
      "rotation": 2
    },
    {
      "x": 1,
      "y": 1,
      "z": -1,
      "name": "Rock_Volcanic"
    },
    {
      "x": 1,
      "y": 2,
      "z": -1,
      "name": "Rock_Volcanic"
    },
    {
      "x": 1,
      "y": 3,
      "z": -1,
      "name": "Rock_Volcanic"
    },
    {
      "x": 1,
      "y": 4,
      "z": -1,
      "name": "Wood_Deadwood_Planks"
    },
    {
      "x": 1,
      "y": 5,
      "z": -1,
      "name": "Block_Spawner_Block",
      "components": {
        "Components": {
          "PlacedByInteraction": {
            "WhoPlacedUuid": {
              "$binary": "5OYreBmdMS+xlzjMlwn5JQ==",
              "$type": "04"
            }
          },
          "BlockSpawner": {
            "BlockSpawnerId": "Zone4_Encounters_Tier2"
          }
        }
      }
    },
    {
      "x": 1,
      "y": 6,
      "z": -1,
      "name": "Empty"
    },
    {
      "x": 1,
      "y": 7,
      "z": -1,
      "name": "Empty"
    },
    {
      "x": 1,
      "y": 8,
      "z": -1,
      "name": "Furniture_Ancient_Platform"
    },
    {
      "x": 1,
      "y": 9,
      "z": -1,
      "name": "Empty"
    },
    {
      "x": 1,
      "y": 10,
      "z": -1,
      "name": "Empty"
    },
    {
      "x": 1,
      "y": 11,
      "z": -1,
      "name": "Empty"
    },
    {
      "x": 1,
      "y": 12,
      "z": -1,
      "name": "Empty"
    },
    {
      "x": 1,
      "y": 13,
      "z": -1,
      "name": "Wood_Blackwood_Planks_Half",
      "rotation": 4
    },
    {
      "x": 1,
      "y": 14,
      "z": -1,
      "name": "Wood_Blackwood_Planks"
    },
    {
      "x": 1,
      "y": 15,
      "z": -1,
      "name": "Wood_Blackwood_Planks"
    },
    {
      "x": 1,
      "y": 16,
      "z": -1,
      "name": "Wood_Blackwood_Planks"
    },
    {
      "x": 1,
      "y": 17,
      "z": -1,
      "name": "Wood_Blackwood_Planks"
    },
    {
      "x": 1,
      "y": 18,
      "z": -1,
      "name": "Wood_Blackwood_Roof_Steep",
      "rotation": 2
    },
    {
      "x": 1,
      "y": 19,
      "z": -1,
      "name": "Wood_Blackwood_Roof_Steep",
      "filler": 1024,
      "rotation": 2
    },
    {
      "x": 1,
      "y": 1,
      "z": 0,
      "name": "Rock_Volcanic"
    },
    {
      "x": 1,
      "y": 2,
      "z": 0,
      "name": "Rock_Volcanic"
    },
    {
      "x": 1,
      "y": 3,
      "z": 0,
      "name": "Rock_Volcanic"
    },
    {
      "x": 1,
      "y": 4,
      "z": 0,
      "name": "Wood_Deadwood_Planks"
    },
    {
      "x": 1,
      "y": 5,
      "z": 0,
      "name": "Empty"
    },
    {
      "x": 1,
      "y": 6,
      "z": 0,
      "name": "Empty"
    },
    {
      "x": 1,
      "y": 7,
      "z": 0,
      "name": "Empty"
    },
    {
      "x": 1,
      "y": 8,
      "z": 0,
      "name": "Furniture_Ancient_Platform"
    },
    {
      "x": 1,
      "y": 9,
      "z": 0,
      "name": "Empty"
    },
    {
      "x": 1,
      "y": 10,
      "z": 0,
      "name": "Empty"
    },
    {
      "x": 1,
      "y": 11,
      "z": 0,
      "name": "Empty"
    },
    {
      "x": 1,
      "y": 12,
      "z": 0,
      "name": "Empty"
    },
    {
      "x": 1,
      "y": 13,
      "z": 0,
      "name": "Empty"
    },
    {
      "x": 1,
      "y": 14,
      "z": 0,
      "name": "Empty"
    },
    {
      "x": 1,
      "y": 15,
      "z": 0,
      "name": "Empty"
    },
    {
      "x": 1,
      "y": 16,
      "z": 0,
      "name": "Empty"
    },
    {
      "x": 1,
      "y": 17,
      "z": 0,
      "name": "Empty"
    },
    {
      "x": 1,
      "y": 18,
      "z": 0,
      "name": "Empty"
    },
    {
      "x": 1,
      "y": 19,
      "z": 0,
      "name": "Empty"
    },
    {
      "x": 1,
      "y": 20,
      "z": 0,
      "name": "Wood_Blackwood_Roof_Flat"
    },
    {
      "x": 1,
      "y": 1,
      "z": 1,
      "name": "Rock_Volcanic"
    },
    {
      "x": 1,
      "y": 2,
      "z": 1,
      "name": "Rock_Volcanic"
    },
    {
      "x": 1,
      "y": 3,
      "z": 1,
      "name": "Rock_Volcanic"
    },
    {
      "x": 1,
      "y": 4,
      "z": 1,
      "name": "Rock_Volcanic"
    },
    {
      "x": 1,
      "y": 5,
      "z": 1,
      "name": "Rock_Basalt_Cobble_Stairs",
      "rotation": 1
    },
    {
      "x": 1,
      "y": 6,
      "z": 1,
      "name": "Empty"
    },
    {
      "x": 1,
      "y": 7,
      "z": 1,
      "name": "Rock_Basalt_Cobble_Half",
      "rotation": 5
    },
    {
      "x": 1,
      "y": 8,
      "z": 1,
      "name": "Furniture_Ancient_Platform"
    },
    {
      "x": 1,
      "y": 9,
      "z": 1,
      "name": "Empty"
    },
    {
      "x": 1,
      "y": 10,
      "z": 1,
      "name": "Rock_Basalt_Brick_Half",
      "rotation": 5
    },
    {
      "x": 1,
      "y": 11,
      "z": 1,
      "name": "Empty"
    },
    {
      "x": 1,
      "y": 12,
      "z": 1,
      "name": "Empty"
    },
    {
      "x": 1,
      "y": 13,
      "z": 1,
      "name": "Empty"
    },
    {
      "x": 1,
      "y": 14,
      "z": 1,
      "name": "Rock_Basalt_Brick_Half",
      "rotation": 5
    },
    {
      "x": 1,
      "y": 15,
      "z": 1,
      "name": "Rock_Basalt_Cobble_Stairs",
      "rotation": 11
    },
    {
      "x": 1,
      "y": 16,
      "z": 1,
      "name": "Rock_Basalt_Cobble"
    },
    {
      "x": 1,
      "y": 17,
      "z": 1,
      "name": "Rock_Basalt_Cobble_Stairs",
      "rotation": 1
    },
    {
      "x": 1,
      "y": 18,
      "z": 1,
      "name": "Empty"
    },
    {
      "x": 1,
      "y": 19,
      "z": 1,
      "name": "Empty"
    },
    {
      "x": 1,
      "y": 20,
      "z": 1,
      "name": "Wood_Blackwood_Roof_Flat"
    },
    {
      "x": 1,
      "y": 1,
      "z": 2,
      "name": "Rock_Volcanic"
    },
    {
      "x": 1,
      "y": 2,
      "z": 2,
      "name": "Rock_Volcanic"
    },
    {
      "x": 1,
      "y": 3,
      "z": 2,
      "name": "Rock_Volcanic"
    },
    {
      "x": 1,
      "y": 4,
      "z": 2,
      "name": "Wood_Deadwood_Planks"
    },
    {
      "x": 1,
      "y": 5,
      "z": 2,
      "name": "Empty"
    },
    {
      "x": 1,
      "y": 6,
      "z": 2,
      "name": "Empty"
    },
    {
      "x": 1,
      "y": 7,
      "z": 2,
      "name": "Empty"
    },
    {
      "x": 1,
      "y": 8,
      "z": 2,
      "name": "Furniture_Ancient_Platform"
    },
    {
      "x": 1,
      "y": 9,
      "z": 2,
      "name": "Empty"
    },
    {
      "x": 1,
      "y": 10,
      "z": 2,
      "name": "Empty"
    },
    {
      "x": 1,
      "y": 11,
      "z": 2,
      "name": "Empty"
    },
    {
      "x": 1,
      "y": 12,
      "z": 2,
      "name": "Empty"
    },
    {
      "x": 1,
      "y": 13,
      "z": 2,
      "name": "Empty"
    },
    {
      "x": 1,
      "y": 14,
      "z": 2,
      "name": "Empty"
    },
    {
      "x": 1,
      "y": 15,
      "z": 2,
      "name": "Empty"
    },
    {
      "x": 1,
      "y": 16,
      "z": 2,
      "name": "Empty"
    },
    {
      "x": 1,
      "y": 17,
      "z": 2,
      "name": "Empty"
    },
    {
      "x": 1,
      "y": 18,
      "z": 2,
      "name": "Empty"
    },
    {
      "x": 1,
      "y": 19,
      "z": 2,
      "name": "Empty"
    },
    {
      "x": 1,
      "y": 20,
      "z": 2,
      "name": "Wood_Blackwood_Roof_Flat"
    },
    {
      "x": 1,
      "y": 2,
      "z": 3,
      "name": "Rock_Volcanic"
    },
    {
      "x": 1,
      "y": 3,
      "z": 3,
      "name": "Rock_Volcanic"
    },
    {
      "x": 1,
      "y": 4,
      "z": 3,
      "name": "Wood_Deadwood_Planks"
    },
    {
      "x": 1,
      "y": 5,
      "z": 3,
      "name": "Empty"
    },
    {
      "x": 1,
      "y": 6,
      "z": 3,
      "name": "Empty"
    },
    {
      "x": 1,
      "y": 7,
      "z": 3,
      "name": "Empty"
    },
    {
      "x": 1,
      "y": 8,
      "z": 3,
      "name": "Furniture_Ancient_Platform"
    },
    {
      "x": 1,
      "y": 9,
      "z": 3,
      "name": "Empty"
    },
    {
      "x": 1,
      "y": 10,
      "z": 3,
      "name": "Empty"
    },
    {
      "x": 1,
      "y": 11,
      "z": 3,
      "name": "Empty"
    },
    {
      "x": 1,
      "y": 12,
      "z": 3,
      "name": "Empty"
    },
    {
      "x": 1,
      "y": 13,
      "z": 3,
      "name": "Wood_Blackwood_Planks_Half",
      "rotation": 6
    },
    {
      "x": 1,
      "y": 14,
      "z": 3,
      "name": "Wood_Blackwood_Planks"
    },
    {
      "x": 1,
      "y": 15,
      "z": 3,
      "name": "Wood_Blackwood_Planks"
    },
    {
      "x": 1,
      "y": 16,
      "z": 3,
      "name": "Wood_Blackwood_Planks"
    },
    {
      "x": 1,
      "y": 17,
      "z": 3,
      "name": "Wood_Blackwood_Planks"
    },
    {
      "x": 1,
      "y": 18,
      "z": 3,
      "name": "Wood_Blackwood_Roof_Steep"
    },
    {
      "x": 1,
      "y": 19,
      "z": 3,
      "name": "Wood_Blackwood_Roof_Steep",
      "filler": 1024
    },
    {
      "x": 1,
      "y": 3,
      "z": 4,
      "name": "Rock_Volcanic"
    },
    {
      "x": 1,
      "y": 4,
      "z": 4,
      "name": "Rock_Volcanic"
    },
    {
      "x": 1,
      "y": 5,
      "z": 4,
      "name": "Rock_Volcanic"
    },
    {
      "x": 1,
      "y": 6,
      "z": 4,
      "name": "Rock_Volcanic"
    },
    {
      "x": 1,
      "y": 7,
      "z": 4,
      "name": "Rock_Volcanic_Cobble"
    },
    {
      "x": 1,
      "y": 8,
      "z": 4,
      "name": "Rock_Basalt_Cobble"
    },
    {
      "x": 1,
      "y": 9,
      "z": 4,
      "name": "Empty"
    },
    {
      "x": 1,
      "y": 10,
      "z": 4,
      "name": "Empty"
    },
    {
      "x": 1,
      "y": 11,
      "z": 4,
      "name": "Empty"
    },
    {
      "x": 1,
      "y": 12,
      "z": 4,
      "name": "Empty"
    },
    {
      "x": 1,
      "y": 13,
      "z": 4,
      "name": "Wood_Blackwood_Roof"
    },
    {
      "x": 1,
      "y": 3,
      "z": 5,
      "name": "Rock_Volcanic"
    },
    {
      "x": 1,
      "y": 4,
      "z": 5,
      "name": "Rock_Volcanic"
    },
    {
      "x": 1,
      "y": 5,
      "z": 5,
      "name": "Rock_Volcanic"
    },
    {
      "x": 2,
      "y": 3,
      "z": -5,
      "name": "Rock_Volcanic"
    },
    {
      "x": 2,
      "y": 4,
      "z": -5,
      "name": "Rock_Volcanic"
    },
    {
      "x": 2,
      "y": 2,
      "z": -4,
      "name": "Rock_Volcanic"
    },
    {
      "x": 2,
      "y": 3,
      "z": -4,
      "name": "Rock_Volcanic"
    },
    {
      "x": 2,
      "y": 4,
      "z": -4,
      "name": "Rock_Volcanic"
    },
    {
      "x": 2,
      "y": 5,
      "z": -4,
      "name": "Rock_Volcanic_Cobble"
    },
    {
      "x": 2,
      "y": 6,
      "z": -4,
      "name": "Rock_Volcanic_Cobble_Stairs",
      "rotation": 1
    },
    {
      "x": 2,
      "y": 1,
      "z": -3,
      "name": "Rock_Volcanic"
    },
    {
      "x": 2,
      "y": 2,
      "z": -3,
      "name": "Rock_Volcanic"
    },
    {
      "x": 2,
      "y": 3,
      "z": -3,
      "name": "Rock_Volcanic"
    },
    {
      "x": 2,
      "y": 4,
      "z": -3,
      "name": "Rock_Volcanic"
    },
    {
      "x": 2,
      "y": 5,
      "z": -3,
      "name": "Rock_Volcanic"
    },
    {
      "x": 2,
      "y": 6,
      "z": -3,
      "name": "Rock_Volcanic"
    },
    {
      "x": 2,
      "y": 16,
      "z": -3,
      "name": "Wood_Blackwood_Beam",
      "rotation": 5
    },
    {
      "x": 2,
      "y": 1,
      "z": -2,
      "name": "Rock_Volcanic"
    },
    {
      "x": 2,
      "y": 2,
      "z": -2,
      "name": "Rock_Volcanic"
    },
    {
      "x": 2,
      "y": 3,
      "z": -2,
      "name": "Rock_Volcanic"
    },
    {
      "x": 2,
      "y": 4,
      "z": -2,
      "name": "Rock_Volcanic"
    },
    {
      "x": 2,
      "y": 5,
      "z": -2,
      "name": "Rock_Volcanic"
    },
    {
      "x": 2,
      "y": 6,
      "z": -2,
      "name": "Rock_Volcanic_Cobble"
    },
    {
      "x": 2,
      "y": 7,
      "z": -2,
      "name": "Rock_Volcanic_Cobble"
    },
    {
      "x": 2,
      "y": 8,
      "z": -2,
      "name": "Rock_Basalt_Cobble"
    },
    {
      "x": 2,
      "y": 9,
      "z": -2,
      "name": "Wood_Deadwood_Planks"
    },
    {
      "x": 2,
      "y": 10,
      "z": -2,
      "name": "Wood_Deadwood_Planks"
    },
    {
      "x": 2,
      "y": 11,
      "z": -2,
      "name": "Wood_Blackwood_Planks"
    },
    {
      "x": 2,
      "y": 12,
      "z": -2,
      "name": "Wood_Blackwood_Planks"
    },
    {
      "x": 2,
      "y": 13,
      "z": -2,
      "name": "Wood_Blackwood_Roof_Steep",
      "rotation": 2
    },
    {
      "x": 2,
      "y": 14,
      "z": -2,
      "name": "Wood_Blackwood_Roof_Steep",
      "filler": 1024,
      "rotation": 2
    },
    {
      "x": 2,
      "y": 1,
      "z": -1,
      "name": "Rock_Volcanic"
    },
    {
      "x": 2,
      "y": 2,
      "z": -1,
      "name": "Rock_Volcanic"
    },
    {
      "x": 2,
      "y": 3,
      "z": -1,
      "name": "Rock_Volcanic"
    },
    {
      "x": 2,
      "y": 4,
      "z": -1,
      "name": "Wood_Deadwood_Planks"
    },
    {
      "x": 2,
      "y": 5,
      "z": -1,
      "name": "Furniture_Ancient_Crate",
      "rotation": 3
    },
    {
      "x": 2,
      "y": 6,
      "z": -1,
      "name": "Furniture_Human_Ruins_Torch",
      "rotation": 3
    },
    {
      "x": 2,
      "y": 7,
      "z": -1,
      "name": "Empty"
    },
    {
      "x": 2,
      "y": 8,
      "z": -1,
      "name": "Furniture_Ancient_Platform"
    },
    {
      "x": 2,
      "y": 9,
      "z": -1,
      "name": "Furniture_Ancient_Barrel"
    },
    {
      "x": 2,
      "y": 10,
      "z": -1,
      "name": "Empty"
    },
    {
      "x": 2,
      "y": 11,
      "z": -1,
      "name": "Empty"
    },
    {
      "x": 2,
      "y": 12,
      "z": -1,
      "name": "Empty"
    },
    {
      "x": 2,
      "y": 13,
      "z": -1,
      "name": "Wood_Blackwood_Planks"
    },
    {
      "x": 2,
      "y": 14,
      "z": -1,
      "name": "Wood_Blackwood_Planks"
    },
    {
      "x": 2,
      "y": 15,
      "z": -1,
      "name": "Wood_Burnt_Trunk"
    },
    {
      "x": 2,
      "y": 16,
      "z": -1,
      "name": "Wood_Burnt_Trunk"
    },
    {
      "x": 2,
      "y": 17,
      "z": -1,
      "name": "Wood_Burnt_Trunk"
    },
    {
      "x": 2,
      "y": 18,
      "z": -1,
      "name": "*Wood_Blackwood_Roof_Steep_State_Definitions_Corner_Right",
      "rotation": 2
    },
    {
      "x": 2,
      "y": 19,
      "z": -1,
      "name": "*Wood_Blackwood_Roof_Steep_State_Definitions_Corner_Right",
      "filler": 1024,
      "rotation": 2
    },
    {
      "x": 2,
      "y": 1,
      "z": 0,
      "name": "Rock_Volcanic"
    },
    {
      "x": 2,
      "y": 2,
      "z": 0,
      "name": "Rock_Volcanic"
    },
    {
      "x": 2,
      "y": 3,
      "z": 0,
      "name": "Rock_Volcanic"
    },
    {
      "x": 2,
      "y": 4,
      "z": 0,
      "name": "Wood_Deadwood_Planks"
    },
    {
      "x": 2,
      "y": 5,
      "z": 0,
      "name": "Furniture_Ancient_Barrel"
    },
    {
      "x": 2,
      "y": 6,
      "z": 0,
      "name": "Empty"
    },
    {
      "x": 2,
      "y": 7,
      "z": 0,
      "name": "Empty"
    },
    {
      "x": 2,
      "y": 8,
      "z": 0,
      "name": "Furniture_Ancient_Platform"
    },
    {
      "x": 2,
      "y": 9,
      "z": 0,
      "name": "Empty"
    },
    {
      "x": 2,
      "y": 10,
      "z": 0,
      "name": "Empty"
    },
    {
      "x": 2,
      "y": 11,
      "z": 0,
      "name": "Empty"
    },
    {
      "x": 2,
      "y": 12,
      "z": 0,
      "name": "Empty"
    },
    {
      "x": 2,
      "y": 13,
      "z": 0,
      "name": "Wood_Blackwood_Planks_Half",
      "rotation": 7
    },
    {
      "x": 2,
      "y": 14,
      "z": 0,
      "name": "Wood_Blackwood_Planks"
    },
    {
      "x": 2,
      "y": 15,
      "z": 0,
      "name": "Wood_Blackwood_Planks"
    },
    {
      "x": 2,
      "y": 16,
      "z": 0,
      "name": "Wood_Blackwood_Planks"
    },
    {
      "x": 2,
      "y": 17,
      "z": 0,
      "name": "Wood_Blackwood_Planks"
    },
    {
      "x": 2,
      "y": 18,
      "z": 0,
      "name": "Wood_Blackwood_Roof_Steep",
      "rotation": 1
    },
    {
      "x": 2,
      "y": 19,
      "z": 0,
      "name": "Wood_Blackwood_Roof_Steep",
      "filler": 1024,
      "rotation": 1
    },
    {
      "x": 2,
      "y": 1,
      "z": 1,
      "name": "Rock_Volcanic"
    },
    {
      "x": 2,
      "y": 2,
      "z": 1,
      "name": "Rock_Volcanic"
    },
    {
      "x": 2,
      "y": 3,
      "z": 1,
      "name": "Rock_Volcanic"
    },
    {
      "x": 2,
      "y": 4,
      "z": 1,
      "name": "Wood_Deadwood_Planks"
    },
    {
      "x": 2,
      "y": 5,
      "z": 1,
      "name": "Empty"
    },
    {
      "x": 2,
      "y": 6,
      "z": 1,
      "name": "Empty"
    },
    {
      "x": 2,
      "y": 7,
      "z": 1,
      "name": "Empty"
    },
    {
      "x": 2,
      "y": 8,
      "z": 1,
      "name": "Furniture_Ancient_Platform"
    },
    {
      "x": 2,
      "y": 9,
      "z": 1,
      "name": "Empty"
    },
    {
      "x": 2,
      "y": 10,
      "z": 1,
      "name": "Empty"
    },
    {
      "x": 2,
      "y": 11,
      "z": 1,
      "name": "Empty"
    },
    {
      "x": 2,
      "y": 12,
      "z": 1,
      "name": "Empty"
    },
    {
      "x": 2,
      "y": 13,
      "z": 1,
      "name": "Wood_Blackwood_Planks_Half",
      "rotation": 7
    },
    {
      "x": 2,
      "y": 14,
      "z": 1,
      "name": "Wood_Blackwood_Planks"
    },
    {
      "x": 2,
      "y": 15,
      "z": 1,
      "name": "Wood_Blackwood_Planks"
    },
    {
      "x": 2,
      "y": 16,
      "z": 1,
      "name": "Wood_Blackwood_Planks"
    },
    {
      "x": 2,
      "y": 17,
      "z": 1,
      "name": "Wood_Blackwood_Planks"
    },
    {
      "x": 2,
      "y": 18,
      "z": 1,
      "name": "Wood_Blackwood_Roof_Steep",
      "rotation": 1
    },
    {
      "x": 2,
      "y": 19,
      "z": 1,
      "name": "Wood_Blackwood_Roof_Steep",
      "filler": 1024,
      "rotation": 1
    },
    {
      "x": 2,
      "y": 1,
      "z": 2,
      "name": "Rock_Volcanic"
    },
    {
      "x": 2,
      "y": 2,
      "z": 2,
      "name": "Rock_Volcanic"
    },
    {
      "x": 2,
      "y": 3,
      "z": 2,
      "name": "Rock_Volcanic"
    },
    {
      "x": 2,
      "y": 4,
      "z": 2,
      "name": "Wood_Deadwood_Planks"
    },
    {
      "x": 2,
      "y": 5,
      "z": 2,
      "name": "Empty"
    },
    {
      "x": 2,
      "y": 6,
      "z": 2,
      "name": "Empty"
    },
    {
      "x": 2,
      "y": 7,
      "z": 2,
      "name": "Empty"
    },
    {
      "x": 2,
      "y": 8,
      "z": 2,
      "name": "Furniture_Ancient_Platform"
    },
    {
      "x": 2,
      "y": 9,
      "z": 2,
      "name": "Empty"
    },
    {
      "x": 2,
      "y": 10,
      "z": 2,
      "name": "Empty"
    },
    {
      "x": 2,
      "y": 11,
      "z": 2,
      "name": "Empty"
    },
    {
      "x": 2,
      "y": 12,
      "z": 2,
      "name": "Empty"
    },
    {
      "x": 2,
      "y": 13,
      "z": 2,
      "name": "Wood_Blackwood_Planks_Half",
      "rotation": 7
    },
    {
      "x": 2,
      "y": 14,
      "z": 2,
      "name": "Wood_Blackwood_Planks"
    },
    {
      "x": 2,
      "y": 15,
      "z": 2,
      "name": "Wood_Blackwood_Planks"
    },
    {
      "x": 2,
      "y": 16,
      "z": 2,
      "name": "Wood_Blackwood_Planks"
    },
    {
      "x": 2,
      "y": 17,
      "z": 2,
      "name": "Wood_Blackwood_Planks"
    },
    {
      "x": 2,
      "y": 18,
      "z": 2,
      "name": "Wood_Blackwood_Roof_Steep",
      "rotation": 1
    },
    {
      "x": 2,
      "y": 19,
      "z": 2,
      "name": "Wood_Blackwood_Roof_Steep",
      "filler": 1024,
      "rotation": 1
    },
    {
      "x": 2,
      "y": 1,
      "z": 3,
      "name": "Rock_Volcanic"
    },
    {
      "x": 2,
      "y": 2,
      "z": 3,
      "name": "Rock_Volcanic"
    },
    {
      "x": 2,
      "y": 3,
      "z": 3,
      "name": "Rock_Volcanic"
    },
    {
      "x": 2,
      "y": 4,
      "z": 3,
      "name": "Wood_Deadwood_Planks"
    },
    {
      "x": 2,
      "y": 5,
      "z": 3,
      "name": "Furniture_Ancient_Barrel"
    },
    {
      "x": 2,
      "y": 6,
      "z": 3,
      "name": "Empty"
    },
    {
      "x": 2,
      "y": 7,
      "z": 3,
      "name": "Empty"
    },
    {
      "x": 2,
      "y": 8,
      "z": 3,
      "name": "Furniture_Ancient_Platform"
    },
    {
      "x": 2,
      "y": 9,
      "z": 3,
      "name": "Empty"
    },
    {
      "x": 2,
      "y": 10,
      "z": 3,
      "name": "Empty"
    },
    {
      "x": 2,
      "y": 11,
      "z": 3,
      "name": "Empty"
    },
    {
      "x": 2,
      "y": 12,
      "z": 3,
      "name": "Empty"
    },
    {
      "x": 2,
      "y": 13,
      "z": 3,
      "name": "Wood_Blackwood_Planks"
    },
    {
      "x": 2,
      "y": 14,
      "z": 3,
      "name": "Wood_Blackwood_Planks"
    },
    {
      "x": 2,
      "y": 15,
      "z": 3,
      "name": "Wood_Burnt_Trunk"
    },
    {
      "x": 2,
      "y": 16,
      "z": 3,
      "name": "Wood_Burnt_Trunk"
    },
    {
      "x": 2,
      "y": 17,
      "z": 3,
      "name": "Wood_Burnt_Trunk"
    },
    {
      "x": 2,
      "y": 18,
      "z": 3,
      "name": "*Wood_Blackwood_Roof_Steep_State_Definitions_Corner_Right",
      "rotation": 1
    },
    {
      "x": 2,
      "y": 19,
      "z": 3,
      "name": "*Wood_Blackwood_Roof_Steep_State_Definitions_Corner_Right",
      "filler": 1024,
      "rotation": 1
    },
    {
      "x": 2,
      "y": 3,
      "z": 4,
      "name": "Rock_Volcanic"
    },
    {
      "x": 2,
      "y": 4,
      "z": 4,
      "name": "Rock_Volcanic"
    },
    {
      "x": 2,
      "y": 5,
      "z": 4,
      "name": "Rock_Volcanic"
    },
    {
      "x": 2,
      "y": 6,
      "z": 4,
      "name": "Rock_Volcanic_Cobble"
    },
    {
      "x": 2,
      "y": 7,
      "z": 4,
      "name": "Rock_Volcanic_Cobble"
    },
    {
      "x": 2,
      "y": 8,
      "z": 4,
      "name": "Rock_Volcanic_Cobble"
    },
    {
      "x": 2,
      "y": 9,
      "z": 4,
      "name": "Wood_Deadwood_Planks"
    },
    {
      "x": 2,
      "y": 10,
      "z": 4,
      "name": "Wood_Blackwood_Planks"
    },
    {
      "x": 2,
      "y": 11,
      "z": 4,
      "name": "Empty"
    },
    {
      "x": 2,
      "y": 12,
      "z": 4,
      "name": "Empty"
    },
    {
      "x": 2,
      "y": 13,
      "z": 4,
      "name": "Wood_Blackwood_Roof_Steep"
    },
    {
      "x": 2,
      "y": 14,
      "z": 4,
      "name": "Wood_Blackwood_Roof_Steep",
      "filler": 1024
    },
    {
      "x": 2,
      "y": 4,
      "z": 5,
      "name": "Rock_Volcanic"
    },
    {
      "x": 2,
      "y": 5,
      "z": 5,
      "name": "Rock_Volcanic"
    },
    {
      "x": 2,
      "y": 6,
      "z": 5,
      "name": "Rock_Volcanic"
    },
    {
      "x": 3,
      "y": 3,
      "z": -5,
      "name": "Rock_Volcanic"
    },
    {
      "x": 3,
      "y": 4,
      "z": -5,
      "name": "Rock_Volcanic"
    },
    {
      "x": 3,
      "y": 2,
      "z": -4,
      "name": "Rock_Volcanic"
    },
    {
      "x": 3,
      "y": 3,
      "z": -4,
      "name": "Rock_Volcanic"
    },
    {
      "x": 3,
      "y": 4,
      "z": -4,
      "name": "Rock_Volcanic"
    },
    {
      "x": 3,
      "y": 5,
      "z": -4,
      "name": "Rock_Volcanic_Cobble_Stairs",
      "rotation": 1
    },
    {
      "x": 3,
      "y": 1,
      "z": -3,
      "name": "Rock_Volcanic"
    },
    {
      "x": 3,
      "y": 2,
      "z": -3,
      "name": "Rock_Volcanic"
    },
    {
      "x": 3,
      "y": 3,
      "z": -3,
      "name": "Rock_Volcanic"
    },
    {
      "x": 3,
      "y": 4,
      "z": -3,
      "name": "Rock_Volcanic"
    },
    {
      "x": 3,
      "y": 5,
      "z": -3,
      "name": "Rock_Volcanic_Cobble_Stairs",
      "rotation": 1
    },
    {
      "x": 3,
      "y": 16,
      "z": -3,
      "name": "Wood_Blackwood_Beam",
      "rotation": 5
    },
    {
      "x": 3,
      "y": 1,
      "z": -2,
      "name": "Rock_Volcanic"
    },
    {
      "x": 3,
      "y": 2,
      "z": -2,
      "name": "Rock_Volcanic"
    },
    {
      "x": 3,
      "y": 3,
      "z": -2,
      "name": "Rock_Volcanic"
    },
    {
      "x": 3,
      "y": 4,
      "z": -2,
      "name": "Rock_Volcanic"
    },
    {
      "x": 3,
      "y": 5,
      "z": -2,
      "name": "Rock_Volcanic"
    },
    {
      "x": 3,
      "y": 6,
      "z": -2,
      "name": "Rock_Volcanic"
    },
    {
      "x": 3,
      "y": 7,
      "z": -2,
      "name": "Rock_Volcanic_Cobble"
    },
    {
      "x": 3,
      "y": 8,
      "z": -2,
      "name": "Rock_Basalt_Cobble"
    },
    {
      "x": 3,
      "y": 9,
      "z": -2,
      "name": "Wood_Burnt_Trunk"
    },
    {
      "x": 3,
      "y": 10,
      "z": -2,
      "name": "Wood_Burnt_Trunk"
    },
    {
      "x": 3,
      "y": 11,
      "z": -2,
      "name": "Wood_Burnt_Trunk"
    },
    {
      "x": 3,
      "y": 12,
      "z": -2,
      "name": "Wood_Burnt_Trunk"
    },
    {
      "x": 3,
      "y": 13,
      "z": -2,
      "name": "*Wood_Blackwood_Roof_Steep_State_Definitions_Corner_Right",
      "rotation": 2
    },
    {
      "x": 3,
      "y": 14,
      "z": -2,
      "name": "*Wood_Blackwood_Roof_Steep_State_Definitions_Corner_Right",
      "filler": 1024,
      "rotation": 2
    },
    {
      "x": 3,
      "y": 1,
      "z": -1,
      "name": "Rock_Volcanic"
    },
    {
      "x": 3,
      "y": 3,
      "z": -1,
      "name": "Rock_Volcanic"
    },
    {
      "x": 3,
      "y": 4,
      "z": -1,
      "name": "Rock_Volcanic"
    },
    {
      "x": 3,
      "y": 5,
      "z": -1,
      "name": "Rock_Volcanic"
    },
    {
      "x": 3,
      "y": 6,
      "z": -1,
      "name": "Rock_Volcanic_Cobble"
    },
    {
      "x": 3,
      "y": 7,
      "z": -1,
      "name": "Rock_Volcanic_Cobble"
    },
    {
      "x": 3,
      "y": 8,
      "z": -1,
      "name": "Rock_Basalt_Brick"
    },
    {
      "x": 3,
      "y": 9,
      "z": -1,
      "name": "Wood_Deadwood_Planks"
    },
    {
      "x": 3,
      "y": 10,
      "z": -1,
      "name": "Wood_Deadwood_Planks"
    },
    {
      "x": 3,
      "y": 11,
      "z": -1,
      "name": "Wood_Blackwood_Planks"
    },
    {
      "x": 3,
      "y": 12,
      "z": -1,
      "name": "Wood_Blackwood_Planks"
    },
    {
      "x": 3,
      "y": 13,
      "z": -1,
      "name": "Wood_Blackwood_Roof_Steep",
      "rotation": 1
    },
    {
      "x": 3,
      "y": 14,
      "z": -1,
      "name": "Wood_Blackwood_Roof_Steep",
      "filler": 1024,
      "rotation": 1
    },
    {
      "x": 3,
      "y": 2,
      "z": 0,
      "name": "Rock_Volcanic"
    },
    {
      "x": 3,
      "y": 3,
      "z": 0,
      "name": "Rock_Volcanic"
    },
    {
      "x": 3,
      "y": 4,
      "z": 0,
      "name": "Rock_Volcanic"
    },
    {
      "x": 3,
      "y": 5,
      "z": 0,
      "name": "Rock_Volcanic"
    },
    {
      "x": 3,
      "y": 6,
      "z": 0,
      "name": "Rock_Volcanic_Cobble"
    },
    {
      "x": 3,
      "y": 7,
      "z": 0,
      "name": "Rock_Basalt_Brick"
    },
    {
      "x": 3,
      "y": 8,
      "z": 0,
      "name": "Rock_Basalt_Brick"
    },
    {
      "x": 3,
      "y": 9,
      "z": 0,
      "name": "Wood_Deadwood_Planks"
    },
    {
      "x": 3,
      "y": 10,
      "z": 0,
      "name": "Furniture_Ancient_Window",
      "rotation": 1
    },
    {
      "x": 3,
      "y": 11,
      "z": 0,
      "name": "Furniture_Ancient_Window",
      "rotation": 1
    },
    {
      "x": 3,
      "y": 12,
      "z": 0,
      "name": "Wood_Blackwood_Planks"
    },
    {
      "x": 3,
      "y": 13,
      "z": 0,
      "name": "Wood_Blackwood_Roof",
      "rotation": 1
    },
    {
      "x": 3,
      "y": 2,
      "z": 1,
      "name": "Rock_Volcanic"
    },
    {
      "x": 3,
      "y": 3,
      "z": 1,
