{
  "version": 8,
  "blockIdVersion": 10,
  "anchorX": 0,
  "anchorY": 6,
  "anchorZ": 1,
  "blocks": [
    {
      "x": -11,
      "y": 16,
      "z": -5,
      "name": "Plant_Leaves_Autumn"
    },
    {
      "x": -11,
      "y": 17,
      "z": -5,
      "name": "Plant_Leaves_Autumn"
    },
    {
      "x": -11,
      "y": 18,
      "z": -5,
      "name": "Plant_Leaves_Autumn"
    },
    {
      "x": -11,
      "y": 17,
      "z": -4,
      "name": "Plant_Leaves_Autumn"
    },
    {
      "x": -11,
      "y": 18,
      "z": -4,
      "name": "Plant_Leaves_Autumn"
    },
    {
      "x": -11,
      "y": 17,
      "z": -3,
      "name": "Plant_Leaves_Autumn"
    },
    {
      "x": -11,
      "y": 18,
      "z": -3,
      "name": "Plant_Leaves_Autumn"
    },
    {
      "x": -11,
      "y": 19,
      "z": -3,
      "name": "Plant_Leaves_Autumn"
    },
    {
      "x": -11,
      "y": 18,
      "z": -2,
      "name": "Plant_Leaves_Autumn"
    },
    {
      "x": -11,
      "y": 19,
      "z": -2,
      "name": "Plant_Leaves_Autumn"
    },
    {
      "x": -11,
      "y": 18,
      "z": -1,
      "name": "Plant_Leaves_Autumn"
    },
    {
      "x": -10,
      "y": 17,
      "z": -6,
      "name": "Plant_Leaves_Autumn"
    },
    {
      "x": -10,
      "y": 18,
      "z": -6,
      "name": "Plant_Leaves_Autumn"
    },
    {
      "x": -10,
      "y": 17,
      "z": -5,
      "name": "Plant_Leaves_Autumn"
    },
    {
      "x": -10,
      "y": 18,
      "z": -5,
      "name": "Plant_Leaves_Autumn"
    },
    {
      "x": -10,
      "y": 17,
      "z": -4,
      "name": "Plant_Leaves_Autumn"
    },
    {
      "x": -10,
      "y": 18,
      "z": -4,
      "name": "Plant_Leaves_Autumn"
    },
    {
      "x": -10,
      "y": 19,
      "z": -4,
      "name": "Plant_Leaves_Autumn"
    },
    {
      "x": -10,
      "y": 20,
      "z": -4,
      "name": "Plant_Leaves_Autumn"
    },
    {
      "x": -10,
      "y": 17,
      "z": -3,
      "name": "Plant_Leaves_Autumn"
    },
    {
      "x": -10,
      "y": 18,
      "z": -3,
      "name": "Plant_Leaves_Autumn"
    },
    {
      "x": -10,
      "y": 20,
      "z": -3,
      "name": "Plant_Leaves_Autumn"
    },
    {
      "x": -10,
      "y": 21,
      "z": -3,
      "name": "Plant_Leaves_Autumn"
    },
    {
      "x": -10,
      "y": 18,
      "z": -2,
      "name": "Plant_Leaves_Autumn"
    },
    {
      "x": -10,
      "y": 20,
      "z": -2,
      "name": "Plant_Leaves_Autumn"
    },
    {
      "x": -10,
      "y": 18,
      "z": -1,
      "name": "Plant_Leaves_Autumn"
    },
    {
      "x": -10,
      "y": 19,
      "z": -1,
      "name": "Plant_Leaves_Autumn"
    },
    {
      "x": -10,
      "y": 20,
      "z": -1,
      "name": "Plant_Leaves_Autumn"
    },
    {
      "x": -10,
      "y": 18,
      "z": 0,
      "name": "Plant_Leaves_Autumn"
    },
    {
      "x": -10,
      "y": 18,
      "z": 1,
      "name": "Plant_Leaves_Autumn"
    },
    {
      "x": -9,
      "y": 16,
      "z": -6,
      "name": "Plant_Leaves_Autumn"
    },
    {
      "x": -9,
      "y": 17,
      "z": -6,
      "name": "Plant_Leaves_Autumn"
    },
    {
      "x": -9,
      "y": 18,
      "z": -6,
      "name": "Plant_Leaves_Autumn"
    },
    {
      "x": -9,
      "y": 19,
      "z": -6,
      "name": "Plant_Leaves_Autumn"
    },
    {
      "x": -9,
      "y": 18,
      "z": -5,
      "name": "Plant_Leaves_Autumn"
    },
    {
      "x": -9,
      "y": 19,
      "z": -5,
      "name": "Plant_Leaves_Autumn"
    },
    {
      "x": -9,
      "y": 20,
      "z": -5,
      "name": "Plant_Leaves_Autumn"
    },
    {
      "x": -9,
      "y": 18,
      "z": -4,
      "name": "Plant_Leaves_Autumn"
    },
    {
      "x": -9,
      "y": 19,
      "z": -4,
      "name": "Plant_Leaves_Autumn"
    },
    {
      "x": -9,
      "y": 18,
      "z": -3,
      "name": "Plant_Leaves_Autumn"
    },
    {
      "x": -9,
      "y": 19,
      "z": -3,
      "name": "Plant_Leaves_Autumn"
    },
    {
      "x": -9,
      "y": 20,
      "z": -3,
      "name": "Plant_Leaves_Autumn"
    },
    {
      "x": -9,
      "y": 16,
      "z": -2,
      "name": "Plant_Leaves_Autumn"
    },
    {
      "x": -9,
      "y": 17,
      "z": -2,
      "name": "Plant_Leaves_Autumn"
    },
    {
      "x": -9,
      "y": 18,
      "z": -2,
      "name": "Plant_Leaves_Autumn"
    },
    {
      "x": -9,
      "y": 19,
      "z": -2,
      "name": "Plant_Leaves_Autumn"
    },
    {
      "x": -9,
      "y": 17,
      "z": -1,
      "name": "Plant_Leaves_Autumn"
    },
    {
      "x": -9,
      "y": 18,
      "z": -1,
      "name": "Plant_Leaves_Autumn"
    },
    {
      "x": -9,
      "y": 19,
      "z": -1,
      "name": "Plant_Leaves_Autumn"
    },
    {
      "x": -9,
      "y": 16,
      "z": 0,
      "name": "Plant_Leaves_Autumn"
    },
    {
      "x": -9,
      "y": 17,
      "z": 0,
      "name": "Plant_Leaves_Autumn"
    },
    {
      "x": -9,
      "y": 18,
      "z": 0,
      "name": "Plant_Leaves_Autumn"
    },
    {
      "x": -9,
      "y": 19,
      "z": 0,
      "name": "Plant_Leaves_Autumn"
    },
    {
      "x": -9,
      "y": 17,
      "z": 1,
      "name": "Plant_Leaves_Autumn"
    },
    {
      "x": -9,
      "y": 18,
      "z": 1,
      "name": "Plant_Leaves_Autumn"
    },
    {
      "x": -9,
      "y": 18,
      "z": 2,
      "name": "Plant_Leaves_Autumn"
    },
    {
      "x": -9,
      "y": 23,
      "z": 3,
      "name": "Plant_Leaves_Autumn"
    },
    {
      "x": -8,
      "y": 18,
      "z": -7,
      "name": "Plant_Leaves_Autumn"
    },
    {
      "x": -8,
      "y": 19,
      "z": -7,
      "name": "Plant_Leaves_Autumn"
    },
    {
      "x": -8,
      "y": 18,
      "z": -6,
      "name": "Plant_Leaves_Autumn"
    },
    {
      "x": -8,
      "y": 25,
      "z": -6,
      "name": "Plant_Leaves_Autumn"
    },
    {
      "x": -8,
      "y": 18,
      "z": -5,
      "name": "Plant_Leaves_Autumn"
    },
    {
      "x": -8,
      "y": 26,
      "z": -3,
      "name": "Plant_Leaves_Autumn"
    },
    {
      "x": -8,
      "y": 17,
      "z": -2,
      "name": "Plant_Leaves_Autumn"
    },
    {
      "x": -8,
      "y": 18,
      "z": -2,
      "name": "Wood_Oak_Branch_Long",
      "rotation": 5
    },
    {
      "x": -8,
      "y": 19,
      "z": -2,
      "name": "Plant_Leaves_Autumn"
    },
    {
      "x": -8,
      "y": 26,
      "z": -2,
      "name": "Plant_Leaves_Autumn"
    },
    {
      "x": -8,
      "y": 27,
      "z": -2,
      "name": "Plant_Leaves_Autumn"
    },
    {
      "x": -8,
      "y": 18,
      "z": -1,
      "name": "Plant_Leaves_Autumn"
    },
    {
      "x": -8,
      "y": 19,
      "z": -1,
      "name": "Plant_Leaves_Autumn"
    },
    {
      "x": -8,
      "y": 26,
      "z": -1,
      "name": "Plant_Leaves_Autumn"
    },
    {
      "x": -8,
      "y": 27,
      "z": -1,
      "name": "Plant_Leaves_Autumn"
    },
    {
      "x": -8,
      "y": 28,
      "z": -1,
      "name": "Plant_Leaves_Autumn"
    },
    {
      "x": -8,
      "y": 26,
      "z": 0,
      "name": "Plant_Leaves_Autumn"
    },
    {
      "x": -8,
      "y": 27,
      "z": 0,
      "name": "Plant_Leaves_Autumn"
    },
    {
      "x": -8,
      "y": 26,
      "z": 1,
      "name": "Plant_Leaves_Autumn"
    },
    {
      "x": -8,
      "y": 27,
      "z": 1,
      "name": "Plant_Leaves_Autumn"
    },
    {
      "x": -8,
      "y": 23,
      "z": 2,
      "name": "Plant_Leaves_Autumn"
    },
    {
      "x": -8,
      "y": 26,
      "z": 2,
      "name": "Plant_Leaves_Autumn"
    },
    {
      "x": -8,
      "y": 23,
      "z": 3,
      "name": "Plant_Leaves_Autumn"
    },
    {
      "x": -8,
      "y": 22,
      "z": 4,
      "name": "Plant_Leaves_Autumn"
    },
    {
      "x": -8,
      "y": 23,
      "z": 4,
      "name": "Plant_Leaves_Autumn"
    },
    {
      "x": -8,
      "y": 22,
      "z": 5,
      "name": "Plant_Leaves_Autumn"
    },
    {
      "x": -8,
      "y": 23,
      "z": 5,
      "name": "Plant_Leaves_Autumn"
    },
    {
      "x": -8,
      "y": 24,
      "z": 5,
      "name": "Plant_Leaves_Autumn"
    },
    {
      "x": -8,
      "y": 22,
      "z": 6,
      "name": "Plant_Leaves_Autumn"
    },
    {
      "x": -8,
      "y": 23,
      "z": 6,
      "name": "Plant_Leaves_Autumn"
    },
    {
      "x": -8,
      "y": 24,
      "z": 6,
      "name": "Plant_Leaves_Autumn"
    },
    {
      "x": -8,
      "y": 23,
      "z": 7,
      "name": "Plant_Leaves_Autumn"
    },
    {
      "x": -7,
      "y": 25,
      "z": -8,
      "name": "Plant_Leaves_Autumn"
    },
    {
      "x": -7,
      "y": 18,
      "z": -7,
      "name": "Plant_Leaves_Autumn"
    },
    {
      "x": -7,
      "y": 25,
      "z": -7,
      "name": "Plant_Leaves_Autumn"
    },
    {
      "x": -7,
      "y": 26,
      "z": -7,
      "name": "Plant_Leaves_Autumn"
    },
    {
      "x": -7,
      "y": 18,
      "z": -6,
      "name": "Plant_Leaves_Autumn"
    },
    {
      "x": -7,
      "y": 25,
      "z": -6,
      "name": "Plant_Leaves_Autumn"
    },
    {
      "x": -7,
      "y": 18,
      "z": -5,
      "name": "Plant_Leaves_Autumn"
    },
    {
      "x": -7,
      "y": 25,
      "z": -5,
      "name": "Plant_Leaves_Autumn"
    },
    {
      "x": -7,
      "y": 18,
      "z": -2,
      "name": "Wood_Oak_Branch_Long",
      "rotation": 5
    },
    {
      "x": -7,
      "y": 26,
      "z": -2,
      "name": "Wood_Oak_Branch_Long",
      "rotation": 5
    },
    {
      "x": -7,
      "y": 27,
      "z": -2,
      "name": "Plant_Leaves_Autumn"
    },
    {
      "x": -7,
      "y": 28,
      "z": -2,
      "name": "Plant_Leaves_Autumn"
    },
    {
      "x": -7,
      "y": 27,
      "z": -1,
      "name": "Plant_Leaves_Autumn"
    },
    {
      "x": -7,
      "y": 28,
      "z": -1,
      "name": "Plant_Leaves_Autumn"
    },
    {
      "x": -7,
      "y": 27,
      "z": 0,
      "name": "Plant_Leaves_Autumn"
    },
    {
      "x": -7,
      "y": 27,
      "z": 1,
      "name": "Plant_Leaves_Autumn"
    },
    {
      "x": -7,
      "y": 18,
      "z": 2,
      "name": "Plant_Leaves_Autumn"
    },
    {
      "x": -7,
      "y": 19,
      "z": 2,
      "name": "Plant_Leaves_Autumn"
    },
    {
      "x": -7,
      "y": 18,
      "z": 3,
      "name": "Plant_Leaves_Autumn"
    },
    {
      "x": -7,
      "y": 22,
      "z": 3,
      "name": "Plant_Leaves_Autumn"
    },
    {
      "x": -7,
      "y": 23,
      "z": 3,
      "name": "Plant_Leaves_Autumn"
    },
    {
      "x": -7,
      "y": 18,
      "z": 4,
      "name": "Plant_Leaves_Autumn"
    },
    {
      "x": -7,
      "y": 22,
      "z": 4,
      "name": "Plant_Leaves_Autumn"
    },
    {
      "x": -7,
      "y": 23,
      "z": 4,
      "name": "Plant_Leaves_Autumn"
    },
    {
      "x": -7,
      "y": 24,
      "z": 5,
      "name": "Plant_Leaves_Autumn"
    },
    {
      "x": -7,
      "y": 23,
      "z": 6,
      "name": "Plant_Leaves_Autumn"
    },
    {
      "x": -7,
      "y": 24,
      "z": 6,
      "name": "Plant_Leaves_Autumn"
    },
    {
      "x": -7,
      "y": 25,
      "z": 6,
      "name": "Plant_Leaves_Autumn"
    },
    {
      "x": -7,
      "y": 23,
      "z": 7,
      "name": "Plant_Leaves_Autumn"
    },
    {
      "x": -7,
      "y": 24,
      "z": 7,
      "name": "Plant_Leaves_Autumn"
    },
    {
      "x": -7,
      "y": 23,
      "z": 8,
      "name": "Plant_Leaves_Autumn"
    },
    {
      "x": -6,
      "y": 19,
      "z": -8,
      "name": "Plant_Leaves_Autumn"
    },
    {
      "x": -6,
      "y": 25,
      "z": -8,
      "name": "Plant_Leaves_Autumn"
    },
    {
      "x": -6,
      "y": 19,
      "z": -7,
      "name": "Plant_Leaves_Autumn"
    },
    {
      "x": -6,
      "y": 25,
      "z": -7,
      "name": "Plant_Leaves_Autumn"
    },
    {
      "x": -6,
      "y": 26,
      "z": -7,
      "name": "Plant_Leaves_Autumn"
    },
    {
      "x": -6,
      "y": 19,
      "z": -6,
      "name": "Plant_Leaves_Autumn"
    },
    {
      "x": -6,
      "y": 20,
      "z": -6,
      "name": "Plant_Leaves_Autumn"
    },
    {
      "x": -6,
      "y": 25,
      "z": -6,
      "name": "Plant_Leaves_Autumn"
    },
    {
      "x": -6,
      "y": 26,
      "z": -6,
      "name": "Plant_Leaves_Autumn"
    },
    {
      "x": -6,
      "y": 19,
      "z": -5,
      "name": "Plant_Leaves_Autumn"
    },
    {
      "x": -6,
      "y": 20,
      "z": -5,
      "name": "Plant_Leaves_Autumn"
    },
    {
      "x": -6,
      "y": 25,
      "z": -5,
      "name": "Plant_Leaves_Autumn"
    },
    {
      "x": -6,
      "y": 17,
      "z": -4,
      "name": "Plant_Leaves_Autumn"
    },
    {
      "x": -6,
      "y": 18,
      "z": -4,
      "name": "Plant_Leaves_Autumn"
    },
    {
      "x": -6,
      "y": 19,
      "z": -4,
      "name": "Plant_Leaves_Autumn"
    },
    {
      "x": -6,
      "y": 25,
      "z": -4,
      "name": "Plant_Leaves_Autumn"
    },
    {
      "x": -6,
      "y": 17,
      "z": -3,
      "name": "Plant_Leaves_Autumn"
    },
    {
      "x": -6,
      "y": 18,
      "z": -3,
      "name": "Wood_Oak_Branch_Corner",
      "rotation": 2
    },
    {
      "x": -6,
      "y": 19,
      "z": -3,
      "name": "Plant_Leaves_Autumn"
    },
    {
      "x": -6,
      "y": 29,
      "z": -3,
      "name": "Plant_Leaves_Autumn"
    },
    {
      "x": -6,
      "y": 17,
      "z": -2,
      "name": "Wood_Oak_Roots"
    },
    {
      "x": -6,
      "y": 18,
      "z": -2,
      "name": "Wood_Oak_Trunk_Full"
    },
    {
      "x": -6,
      "y": 25,
      "z": -2,
      "name": "Wood_Oak_Roots"
    },
    {
      "x": -6,
      "y": 26,
      "z": -2,
      "name": "Wood_Oak_Trunk_Full"
    },
    {
      "x": -6,
      "y": 29,
      "z": -2,
      "name": "Plant_Leaves_Autumn"
    },
    {
      "x": -6,
      "y": 28,
      "z": -1,
      "name": "Plant_Leaves_Autumn"
    },
    {
      "x": -6,
      "y": 29,
      "z": -1,
      "name": "Plant_Leaves_Autumn"
    },
    {
      "x": -6,
      "y": 27,
      "z": 0,
      "name": "Plant_Leaves_Autumn"
    },
    {
      "x": -6,
      "y": 28,
      "z": 0,
      "name": "Plant_Leaves_Autumn"
    },
    {
      "x": -6,
      "y": 18,
      "z": 1,
      "name": "Plant_Leaves_Autumn"
    },
    {
      "x": -6,
      "y": 26,
      "z": 1,
      "name": "Plant_Leaves_Autumn"
    },
    {
      "x": -6,
      "y": 17,
      "z": 2,
      "name": "Plant_Leaves_Autumn"
    },
    {
      "x": -6,
      "y": 18,
      "z": 2,
      "name": "Plant_Leaves_Autumn"
    },
    {
      "x": -6,
      "y": 19,
      "z": 2,
      "name": "Plant_Leaves_Autumn"
    },
    {
      "x": -6,
      "y": 26,
      "z": 2,
      "name": "Plant_Leaves_Autumn"
    },
    {
      "x": -6,
      "y": 27,
      "z": 2,
      "name": "Plant_Leaves_Autumn"
    },
    {
      "x": -6,
      "y": 17,
      "z": 3,
      "name": "Plant_Leaves_Autumn"
    },
    {
      "x": -6,
      "y": 18,
      "z": 3,
      "name": "Plant_Leaves_Autumn"
    },
    {
      "x": -6,
      "y": 26,
      "z": 3,
      "name": "Plant_Leaves_Autumn"
    },
    {
      "x": -6,
      "y": 18,
      "z": 4,
      "name": "Plant_Leaves_Autumn"
    },
    {
      "x": -6,
      "y": 23,
      "z": 4,
      "name": "Plant_Leaves_Autumn"
    },
    {
      "x": -6,
      "y": 22,
      "z": 5,
      "name": "Plant_Leaves_Autumn"
    },
    {
      "x": -6,
      "y": 23,
      "z": 5,
      "name": "Plant_Leaves_Autumn"
    },
    {
      "x": -6,
      "y": 22,
      "z": 6,
      "name": "Plant_Leaves_Autumn"
    },
    {
      "x": -6,
      "y": 23,
      "z": 6,
      "name": "Plant_Leaves_Autumn"
    },
    {
      "x": -6,
      "y": 24,
      "z": 6,
      "name": "Plant_Leaves_Autumn"
    },
    {
      "x": -6,
      "y": 22,
      "z": 7,
      "name": "Plant_Leaves_Autumn"
    },
    {
      "x": -6,
      "y": 23,
      "z": 7,
      "name": "Plant_Leaves_Autumn"
    },
    {
      "x": -6,
      "y": 24,
      "z": 7,
      "name": "Plant_Leaves_Autumn"
    },
    {
      "x": -6,
      "y": 25,
      "z": 7,
      "name": "Plant_Leaves_Autumn"
    },
    {
      "x": -6,
      "y": 22,
      "z": 8,
      "name": "Plant_Leaves_Autumn"
    },
    {
      "x": -6,
      "y": 23,
      "z": 8,
      "name": "Plant_Leaves_Autumn"
    },
    {
      "x": -6,
      "y": 24,
      "z": 8,
      "name": "Plant_Leaves_Autumn"
    },
    {
      "x": -5,
      "y": 20,
      "z": -11,
      "name": "Plant_Leaves_Autumn"
    },
    {
      "x": -5,
      "y": 21,
      "z": -10,
      "name": "Plant_Leaves_Autumn"
    },
    {
      "x": -5,
      "y": 20,
      "z": -9,
      "name": "Plant_Leaves_Autumn"
    },
    {
      "x": -5,
      "y": 21,
      "z": -9,
      "name": "Plant_Leaves_Autumn"
    },
    {
      "x": -5,
      "y": 22,
      "z": -9,
      "name": "Plant_Leaves_Autumn"
    },
    {
      "x": -5,
      "y": 25,
      "z": -9,
      "name": "Plant_Leaves_Autumn"
    },
    {
      "x": -5,
      "y": 26,
      "z": -9,
      "name": "Plant_Leaves_Autumn"
    },
    {
      "x": -5,
      "y": 27,
      "z": -9,
      "name": "Plant_Leaves_Autumn"
    },
    {
      "x": -5,
      "y": 25,
      "z": -8,
      "name": "Plant_Leaves_Autumn"
    },
    {
      "x": -5,
      "y": 26,
      "z": -8,
      "name": "Plant_Leaves_Autumn"
    },
    {
      "x": -5,
      "y": 20,
      "z": -7,
      "name": "Plant_Leaves_Autumn"
    },
    {
      "x": -5,
      "y": 25,
      "z": -7,
      "name": "Plant_Leaves_Autumn"
    },
    {
      "x": -5,
      "y": 20,
      "z": -6,
      "name": "Plant_Leaves_Autumn"
    },
    {
      "x": -5,
      "y": 25,
      "z": -6,
      "name": "Plant_Leaves_Autumn"
    },
    {
      "x": -5,
      "y": 26,
      "z": -6,
      "name": "Plant_Leaves_Autumn"
    },
    {
      "x": -5,
      "y": 19,
      "z": -5,
      "name": "Plant_Leaves_Autumn"
    },
    {
      "x": -5,
      "y": 20,
      "z": -5,
      "name": "Plant_Leaves_Autumn"
    },
    {
      "x": -5,
      "y": 24,
      "z": -5,
      "name": "Plant_Leaves_Autumn"
    },
    {
      "x": -5,
      "y": 25,
      "z": -5,
      "name": "Plant_Leaves_Autumn"
    },
    {
      "x": -5,
      "y": 26,
      "z": -5,
      "name": "Plant_Leaves_Autumn"
    },
    {
      "x": -5,
      "y": 18,
      "z": -4,
      "name": "Plant_Leaves_Autumn"
    },
    {
      "x": -5,
      "y": 19,
      "z": -4,
      "name": "Plant_Leaves_Autumn"
    },
    {
      "x": -5,
      "y": 25,
      "z": -4,
      "name": "Plant_Leaves_Autumn"
    },
    {
      "x": -5,
      "y": 19,
      "z": -3,
      "name": "Plant_Leaves_Autumn"
    },
    {
      "x": -5,
      "y": 28,
      "z": -3,
      "name": "Plant_Leaves_Autumn"
    },
    {
      "x": -5,
      "y": 29,
      "z": -3,
      "name": "Plant_Leaves_Autumn"
    },
    {
      "x": -5,
      "y": 18,
      "z": -2,
      "name": "Wood_Oak_Trunk_Full"
    },
    {
      "x": -5,
      "y": 25,
      "z": -2,
      "name": "Wood_Oak_Roots"
    },
    {
      "x": -5,
      "y": 26,
      "z": -2,
      "name": "Wood_Oak_Trunk_Full"
    },
    {
      "x": -5,
      "y": 29,
      "z": -2,
      "name": "Plant_Leaves_Autumn"
    },
    {
      "x": -5,
      "y": 17,
      "z": -1,
      "name": "Wood_Oak_Roots"
    },
    {
      "x": -5,
      "y": 18,
      "z": -1,
      "name": "Wood_Oak_Trunk_Full"
    },
    {
      "x": -5,
      "y": 21,
      "z": -1,
      "name": "Plant_Leaves_Autumn"
    },
    {
      "x": -5,
      "y": 29,
      "z": -1,
      "name": "Plant_Leaves_Autumn"
    },
    {
      "x": -5,
      "y": 18,
      "z": 0,
      "name": "Wood_Oak_Trunk_Full"
    },
    {
      "x": -5,
      "y": 28,
      "z": 0,
      "name": "Plant_Leaves_Autumn"
    },
    {
      "x": -5,
      "y": 29,
      "z": 0,
      "name": "Plant_Leaves_Autumn"
    },
    {
      "x": -5,
      "y": 18,
      "z": 1,
      "name": "Wood_Oak_Branch_Long",
      "rotation": 4
    },
    {
      "x": -5,
      "y": 19,
      "z": 1,
      "name": "Plant_Leaves_Autumn"
    },
    {
      "x": -5,
      "y": 26,
      "z": 1,
      "name": "Plant_Leaves_Autumn"
    },
    {
      "x": -5,
      "y": 27,
      "z": 1,
      "name": "Plant_Leaves_Autumn"
    },
    {
      "x": -5,
      "y": 28,
      "z": 1,
      "name": "Plant_Leaves_Autumn"
    },
    {
      "x": -5,
      "y": 17,
      "z": 2,
      "name": "Plant_Leaves_Autumn"
    },
    {
      "x": -5,
      "y": 18,
      "z": 2,
      "name": "Plant_Leaves_Autumn"
    },
    {
      "x": -5,
      "y": 19,
      "z": 2,
      "name": "Plant_Leaves_Autumn"
    },
    {
      "x": -5,
      "y": 25,
      "z": 2,
      "name": "Plant_Leaves_Autumn"
    },
    {
      "x": -5,
      "y": 26,
      "z": 2,
      "name": "Plant_Leaves_Autumn"
    },
    {
      "x": -5,
      "y": 18,
      "z": 3,
      "name": "Plant_Leaves_Autumn"
    },
    {
      "x": -5,
      "y": 26,
      "z": 3,
      "name": "Plant_Leaves_Autumn"
    },
    {
      "x": -5,
      "y": 23,
      "z": 4,
      "name": "Plant_Leaves_Autumn"
    },
    {
      "x": -5,
      "y": 23,
      "z": 5,
      "name": "Wood_Oak_Branch_Long",
      "rotation": 5
    },
    {
      "x": -5,
      "y": 21,
      "z": 6,
      "name": "Plant_Leaves_Autumn"
    },
    {
      "x": -5,
      "y": 22,
      "z": 6,
      "name": "Plant_Leaves_Autumn"
    },
    {
      "x": -5,
      "y": 23,
      "z": 6,
      "name": "Plant_Leaves_Autumn"
    },
    {
      "x": -5,
      "y": 23,
      "z": 7,
      "name": "Plant_Leaves_Autumn"
    },
    {
      "x": -5,
      "y": 24,
      "z": 7,
      "name": "Plant_Leaves_Autumn"
    },
    {
      "x": -5,
      "y": 25,
      "z": 7,
      "name": "Plant_Leaves_Autumn"
    },
    {
      "x": -5,
      "y": 23,
      "z": 8,
      "name": "Plant_Leaves_Autumn"
    },
    {
      "x": -4,
      "y": 20,
      "z": -12,
      "name": "Plant_Leaves_Autumn"
    },
    {
      "x": -4,
      "y": 20,
      "z": -11,
      "name": "Plant_Leaves_Autumn"
    },
    {
      "x": -4,
      "y": 21,
      "z": -11,
      "name": "Plant_Leaves_Autumn"
    },
    {
      "x": -4,
      "y": 19,
      "z": -10,
      "name": "Plant_Leaves_Autumn"
    },
    {
      "x": -4,
      "y": 20,
      "z": -10,
      "name": "Plant_Leaves_Autumn"
    },
    {
      "x": -4,
      "y": 21,
      "z": -10,
      "name": "Plant_Leaves_Autumn"
    },
    {
      "x": -4,
      "y": 22,
      "z": -10,
      "name": "Plant_Leaves_Autumn"
    },
    {
      "x": -4,
      "y": 25,
      "z": -10,
      "name": "Plant_Leaves_Autumn"
    },
    {
      "x": -4,
      "y": 20,
      "z": -9,
      "name": "Plant_Leaves_Autumn"
    },
    {
      "x": -4,
      "y": 21,
      "z": -9,
      "name": "Plant_Leaves_Autumn"
    },
    {
      "x": -4,
      "y": 25,
      "z": -9,
      "name": "Plant_Leaves_Autumn"
    },
    {
      "x": -4,
      "y": 26,
      "z": -9,
      "name": "Plant_Leaves_Autumn"
    },
    {
      "x": -4,
      "y": 25,
      "z": -8,
      "name": "Plant_Leaves_Autumn"
    },
    {
      "x": -4,
      "y": 26,
      "z": -8,
      "name": "Plant_Leaves_Autumn"
    },
    {
      "x": -4,
      "y": 25,
      "z": -7,
      "name": "Plant_Leaves_Autumn"
    },
    {
      "x": -4,
      "y": 26,
      "z": -7,
      "name": "Plant_Leaves_Autumn"
    },
    {
      "x": -4,
      "y": 20,
      "z": -6,
      "name": "Plant_Leaves_Autumn"
    },
    {
      "x": -4,
      "y": 24,
      "z": -6,
      "name": "Plant_Leaves_Autumn"
    },
    {
      "x": -4,
      "y": 25,
      "z": -6,
      "name": "Wood_Oak_Branch_Long",
      "rotation": 5
    },
    {
      "x": -4,
      "y": 26,
      "z": -6,
      "name": "Plant_Leaves_Autumn"
    },
    {
      "x": -4,
      "y": 25,
      "z": -5,
      "name": "Plant_Leaves_Autumn"
    },
    {
      "x": -4,
      "y": 26,
      "z": -5,
      "name": "Plant_Leaves_Autumn"
    },
    {
      "x": -4,
      "y": 25,
      "z": -4,
      "name": "Plant_Leaves_Autumn"
    },
    {
      "x": -4,
      "y": 28,
      "z": -3,
      "name": "Plant_Leaves_Autumn"
    },
    {
      "x": -4,
      "y": 29,
      "z": -3,
      "name": "Plant_Leaves_Autumn"
    },
    {
      "x": -4,
      "y": 21,
      "z": -2,
      "name": "Plant_Leaves_Autumn"
    },
    {
      "x": -4,
      "y": 26,
      "z": -2,
      "name": "Wood_Oak_Trunk_Full"
    },
    {
      "x": -4,
      "y": 29,
      "z": -2,
      "name": "Plant_Leaves_Autumn"
    },
    {
      "x": -4,
      "y": 16,
      "z": -1,
      "name": "Wood_Oak_Roots"
    },
    {
      "x": -4,
      "y": 17,
      "z": -1,
      "name": "Wood_Oak_Trunk_Full"
    },
    {
      "x": -4,
      "y": 18,
      "z": -1,
      "name": "Wood_Oak_Trunk_Full"
    },
    {
      "x": -4,
      "y": 21,
      "z": -1,
      "name": "Plant_Leaves_Autumn"
    },
    {
      "x": -4,
      "y": 22,
      "z": -1,
      "name": "Plant_Leaves_Autumn"
    },
    {
      "x": -4,
      "y": 26,
      "z": -1,
      "name": "Wood_Oak_Trunk_Full"
    },
    {
      "x": -4,
      "y": 27,
      "z": -1,
      "name": "Wood_Oak_Trunk_Full"
    },
    {
      "x": -4,
      "y": 28,
      "z": -1,
      "name": "Wood_Oak_Branch_Long"
    },
    {
      "x": -4,
      "y": 29,
      "z": -1,
      "name": "Plant_Leaves_Autumn"
    },
    {
      "x": -4,
      "y": 18,
      "z": 0,
      "name": "Plant_Leaves_Autumn"
    },
    {
      "x": -4,
      "y": 21,
      "z": 0,
      "name": "Plant_Leaves_Autumn"
    },
    {
      "x": -4,
      "y": 26,
      "z": 0,
      "name": "Wood_Oak_Branch_Long",
      "rotation": 4
    },
    {
      "x": -4,
      "y": 28,
      "z": 0,
      "name": "Plant_Leaves_Autumn"
    },
    {
      "x": -4,
      "y": 29,
      "z": 0,
      "name": "Plant_Leaves_Autumn"
    },
    {
      "x": -4,
      "y": 18,
      "z": 1,
      "name": "Plant_Leaves_Autumn"
    },
    {
      "x": -4,
      "y": 26,
      "z": 1,
      "name": "Wood_Oak_Branch_Long",
      "rotation": 4
    },
    {
      "x": -4,
      "y": 27,
      "z": 1,
      "name": "Plant_Leaves_Autumn"
    },
    {
      "x": -4,
      "y": 28,
      "z": 1,
      "name": "Plant_Leaves_Autumn"
    },
    {
      "x": -4,
      "y": 18,
      "z": 2,
      "name": "Plant_Leaves_Autumn"
    },
    {
      "x": -4,
      "y": 25,
      "z": 2,
      "name": "Plant_Leaves_Autumn"
    },
    {
      "x": -4,
      "y": 26,
      "z": 2,
      "name": "Plant_Leaves_Autumn"
    },
    {
      "x": -4,
      "y": 27,
      "z": 2,
      "name": "Plant_Leaves_Autumn"
    },
    {
      "x": -4,
      "y": 28,
      "z": 2,
      "name": "Plant_Leaves_Autumn"
    },
    {
      "x": -4,
      "y": 18,
      "z": 3,
      "name": "Plant_Leaves_Autumn"
    },
    {
      "x": -4,
      "y": 26,
      "z": 3,
      "name": "Plant_Leaves_Autumn"
    },
    {
      "x": -4,
      "y": 27,
      "z": 3,
      "name": "Plant_Leaves_Autumn"
    },
    {
      "x": -4,
      "y": 23,
      "z": 5,
      "name": "Wood_Oak_Trunk_Full"
    },
    {
      "x": -4,
      "y": 22,
      "z": 6,
      "name": "Plant_Leaves_Autumn"
    },
    {
      "x": -4,
      "y": 23,
      "z": 6,
      "name": "Plant_Leaves_Autumn"
    },
    {
      "x": -4,
      "y": 24,
      "z": 6,
      "name": "Plant_Leaves_Autumn"
    },
    {
      "x": -4,
      "y": 22,
      "z": 7,
      "name": "Plant_Leaves_Autumn"
    },
    {
      "x": -4,
      "y": 23,
      "z": 7,
      "name": "Plant_Leaves_Autumn"
    },
    {
      "x": -4,
      "y": 24,
      "z": 7,
      "name": "Plant_Leaves_Autumn"
    },
    {
      "x": -4,
      "y": 21,
      "z": 8,
      "name": "Plant_Leaves_Autumn"
    },
    {
      "x": -4,
      "y": 23,
      "z": 8,
      "name": "Plant_Leaves_Autumn"
    },
    {
      "x": -4,
      "y": 25,
      "z": 8,
      "name": "Plant_Leaves_Autumn"
    },
    {
      "x": -3,
      "y": 20,
      "z": -13,
      "name": "Plant_Leaves_Autumn"
    },
    {
      "x": -3,
      "y": 20,
      "z": -12,
      "name": "Plant_Leaves_Autumn"
    },
    {
      "x": -3,
      "y": 21,
      "z": -12,
      "name": "Plant_Leaves_Autumn"
    },
    {
      "x": -3,
      "y": 20,
      "z": -11,
      "name": "Plant_Leaves_Autumn"
    },
    {
      "x": -3,
      "y": 21,
      "z": -11,
      "name": "Plant_Leaves_Autumn"
    },
    {
      "x": -3,
      "y": 22,
      "z": -11,
      "name": "Plant_Leaves_Autumn"
    },
    {
      "x": -3,
      "y": 19,
      "z": -10,
      "name": "Plant_Leaves_Autumn"
    },
    {
      "x": -3,
      "y": 20,
      "z": -10,
      "name": "Plant_Leaves_Autumn"
    },
    {
      "x": -3,
      "y": 21,
      "z": -10,
      "name": "Plant_Leaves_Autumn"
    },
    {
      "x": -3,
      "y": 22,
      "z": -10,
      "name": "Plant_Leaves_Autumn"
    },
    {
      "x": -3,
      "y": 25,
      "z": -10,
      "name": "Plant_Leaves_Autumn"
    },
    {
      "x": -3,
      "y": 26,
      "z": -10,
      "name": "Plant_Leaves_Autumn"
    },
    {
      "x": -3,
      "y": 27,
      "z": -10,
      "name": "Plant_Leaves_Autumn"
    },
    {
      "x": -3,
      "y": 20,
      "z": -9,
      "name": "Plant_Leaves_Autumn"
    },
    {
      "x": -3,
      "y": 21,
      "z": -9,
      "name": "Plant_Leaves_Autumn"
    },
    {
      "x": -3,
      "y": 25,
      "z": -9,
      "name": "Plant_Leaves_Autumn"
    },
    {
      "x": -3,
      "y": 25,
      "z": -8,
      "name": "Plant_Leaves_Autumn"
    },
    {
      "x": -3,
      "y": 25,
      "z": -7,
      "name": "Plant_Leaves_Autumn"
    },
    {
      "x": -3,
      "y": 20,
      "z": -6,
      "name": "Wood_Oak_Branch_Long",
      "rotation": 5
    },
    {
      "x": -3,
      "y": 25,
      "z": -6,
      "name": "Wood_Oak_Branch_Long",
      "rotation": 5
    },
    {
      "x": -3,
      "y": 28,
      "z": -5,
      "name": "Plant_Leaves_Autumn"
    },
    {
      "x": -3,
      "y": 29,
      "z": -5,
      "name": "Plant_Leaves_Autumn"
    },
    {
      "x": -3,
      "y": 16,
      "z": -1,
      "name": "Wood_Oak_Roots"
    },
    {
      "x": -3,
      "y": 17,
      "z": -1,
      "name": "Wood_Oak_Trunk_Full"
    },
    {
      "x": -3,
      "y": 21,
      "z": -1,
      "name": "Wood_Oak_Branch_Long",
      "rotation": 5
    },
    {
      "x": -3,
      "y": 22,
      "z": -1,
      "name": "Plant_Leaves_Autumn"
    },
    {
      "x": -3,
      "y": 25,
      "z": -1,
      "name": "Wood_Oak_Roots"
    },
    {
      "x": -3,
      "y": 26,
      "z": -1,
      "name": "Wood_Oak_Trunk_Full"
    },
    {
      "x": -3,
      "y": 29,
      "z": 0,
      "name": "Plant_Leaves_Autumn"
    },
    {
      "x": -3,
      "y": 26,
      "z": 1,
      "name": "Plant_Leaves_Autumn"
    },
    {
      "x": -3,
      "y": 28,
      "z": 1,
      "name": "Plant_Leaves_Autumn"
    },
    {
      "x": -3,
      "y": 18,
      "z": 2,
      "name": "Plant_Leaves_Autumn"
    },
    {
      "x": -3,
      "y": 22,
      "z": 2,
      "name": "Wood_Oak_Trunk_Full"
    },
    {
      "x": -3,
      "y": 26,
      "z": 2,
      "name": "Plant_Leaves_Autumn"
    },
    {
      "x": -3,
      "y": 18,
      "z": 3,
      "name": "Plant_Leaves_Autumn"
    },
    {
      "x": -3,
      "y": 22,
      "z": 3,
      "name": "Wood_Oak_Trunk_Full"
    },
    {
      "x": -3,
      "y": 26,
      "z": 3,
      "name": "Plant_Leaves_Autumn"
    },
    {
      "x": -3,
      "y": 27,
      "z": 3,
      "name": "Plant_Leaves_Autumn"
    },
    {
      "x": -3,
      "y": 22,
      "z": 4,
      "name": "Wood_Oak_Trunk_Full"
    },
    {
      "x": -3,
      "y": 23,
      "z": 4,
      "name": "Wood_Oak_Trunk_Full"
    },
    {
      "x": -3,
      "y": 23,
      "z": 5,
      "name": "Wood_Oak_Trunk_Full"
    },
    {
      "x": -3,
      "y": 23,
      "z": 6,
      "name": "Wood_Oak_Branch_Corner"
    },
    {
      "x": -3,
      "y": 24,
      "z": 6,
      "name": "Plant_Leaves_Autumn"
    },
    {
      "x": -3,
      "y": 20,
      "z": 7,
      "name": "Plant_Leaves_Autumn"
    },
    {
      "x": -3,
      "y": 23,
      "z": 7,
      "name": "Plant_Leaves_Autumn"
    },
    {
      "x": -3,
      "y": 21,
      "z": 8,
      "name": "Plant_Leaves_Autumn"
    },
    {
      "x": -3,
      "y": 23,
      "z": 8,
      "name": "Plant_Leaves_Autumn"
    },
    {
      "x": -3,
      "y": 25,
      "z": 8,
      "name": "Plant_Leaves_Autumn"
    },
    {
      "x": -3,
      "y": 26,
      "z": 8,
      "name": "Plant_Leaves_Autumn"
    },
    {
      "x": -3,
      "y": 23,
      "z": 9,
      "name": "Plant_Leaves_Autumn"
    },
    {
      "x": -2,
      "y": 20,
      "z": -12,
      "name": "Plant_Leaves_Autumn"
    },
    {
      "x": -2,
      "y": 21,
      "z": -12,
      "name": "Plant_Leaves_Autumn"
    },
    {
      "x": -2,
      "y": 25,
      "z": -12,
      "name": "Plant_Leaves_Autumn"
    },
    {
      "x": -2,
      "y": 19,
      "z": -11,
      "name": "Plant_Leaves_Autumn"
    },
    {
      "x": -2,
      "y": 20,
      "z": -11,
      "name": "Plant_Leaves_Autumn"
    },
    {
      "x": -2,
      "y": 21,
      "z": -11,
      "name": "Plant_Leaves_Autumn"
    },
    {
      "x": -2,
      "y": 22,
      "z": -11,
      "name": "Plant_Leaves_Autumn"
    },
    {
      "x": -2,
      "y": 25,
      "z": -11,
      "name": "Plant_Leaves_Autumn"
    },
    {
      "x": -2,
      "y": 26,
      "z": -11,
      "name": "Plant_Leaves_Autumn"
    },
    {
      "x": -2,
      "y": 21,
      "z": -10,
      "name": "Wood_Oak_Branch_Long",
      "rotation": 4
    },
    {
      "x": -2,
      "y": 25,
      "z": -10,
      "name": "Plant_Leaves_Autumn"
    },
    {
      "x": -2,
      "y": 27,
      "z": -10,
      "name": "Plant_Leaves_Autumn"
    },
    {
      "x": -2,
      "y": 21,
      "z": -9,
      "name": "Wood_Oak_Trunk_Full"
    },
    {
      "x": -2,
      "y": 25,
      "z": -9,
      "name": "Plant_Leaves_Autumn"
    },
    {
      "x": -2,
      "y": 19,
      "z": -8,
      "name": "Wood_Oak_Roots"
    },
    {
      "x": -2,
      "y": 21,
      "z": -8,
      "name": "Wood_Oak_Trunk_Full"
    },
    {
      "x": -2,
      "y": 25,
      "z": -8,
      "name": "Plant_Leaves_Autumn"
    },
    {
      "x": -2,
      "y": 26,
      "z": -8,
      "name": "Plant_Leaves_Autumn"
    },
    {
      "x": -2,
      "y": 20,
      "z": -6,
      "name": "Wood_Oak_Branch_Long",
      "rotation": 5
    },
    {
      "x": -2,
      "y": 25,
      "z": -6,
      "name": "Wood_Oak_Branch_Long",
      "rotation": 5
    },
    {
      "x": -2,
      "y": 29,
      "z": -6,
      "name": "Plant_Leaves_Autumn"
    },
    {
      "x": -2,
      "y": 29,
      "z": -5,
      "name": "Plant_Leaves_Autumn"
    },
    {
      "x": -2,
      "y": 29,
      "z": -4,
      "name": "Plant_Leaves_Autumn"
    },
    {
      "x": -2,
      "y": 30,
      "z": -4,
      "name": "Plant_Leaves_Autumn"
    },
    {
      "x": -2,
      "y": 22,
      "z": -2,
      "name": "Wood_Oak_Branch_Short",
      "rotation": 3
    },
    {
      "x": -2,
      "y": 23,
      "z": -2,
      "name": "Wood_Oak_Branch_Short",
      "rotation": 3
    },
    {
      "x": -2,
      "y": 16,
      "z": -1,
      "name": "Wood_Oak_Trunk_Full"
    },
    {
      "x": -2,
      "y": 17,
      "z": -1,
      "name": "Wood_Oak_Trunk_Full"
    },
    {
      "x": -2,
      "y": 20,
      "z": -1,
      "name": "Wood_Oak_Trunk_Full"
    },
    {
      "x": -2,
      "y": 21,
      "z": -1,
      "name": "Wood_Oak_Trunk"
    },
    {
      "x": -2,
      "y": 22,
      "z": -1,
      "name": "Wood_Oak_Trunk"
    },
    {
      "x": -2,
      "y": 23,
      "z": -1,
      "name": "Wood_Oak_Trunk_Full"
    },
    {
      "x": -2,
      "y": 25,
      "z": -1,
      "name": "Wood_Oak_Trunk_Full"
    },
    {
      "x": -2,
      "y": 26,
      "z": -1,
      "name": "Wood_Oak_Trunk_Full"
    },
    {
      "x": -2,
      "y": 21,
      "z": 0,
      "name": "Wood_Oak_Trunk_Full"
    },
    {
      "x": -2,
      "y": 22,
      "z": 0,
      "name": "Wood_Oak_Trunk_Full"
    },
    {
      "x": -2,
      "y": 29,
      "z": 0,
      "name": "Plant_Leaves_Autumn"
    },
    {
      "x": -2,
      "y": 21,
      "z": 1,
      "name": "Wood_Oak_Trunk_Full"
    },
    {
      "x": -2,
      "y": 22,
      "z": 1,
      "name": "Wood_Oak_Trunk_Full"
    },
    {
      "x": -2,
      "y": 22,
      "z": 2,
      "name": "Wood_Oak_Trunk_Full"
    },
    {
      "x": -2,
      "y": 23,
      "z": 4,
      "name": "Wood_Oak_Branch_Long",
      "rotation": 5
    },
    {
      "x": -2,
      "y": 24,
      "z": 5,
      "name": "Plant_Leaves_Autumn"
    },
    {
      "x": -2,
      "y": 20,
      "z": 6,
      "name": "Plant_Leaves_Autumn"
    },
    {
      "x": -2,
      "y": 23,
      "z": 6,
      "name": "Plant_Leaves_Autumn"
    },
    {
      "x": -2,
      "y": 24,
      "z": 6,
      "name": "Plant_Leaves_Autumn"
    },
    {
      "x": -2,
      "y": 20,
      "z": 7,
      "name": "Plant_Leaves_Autumn"
    },
    {
      "x": -2,
      "y": 21,
      "z": 7,
      "name": "Plant_Leaves_Autumn"
    },
    {
      "x": -2,
      "y": 23,
      "z": 7,
      "name": "Plant_Leaves_Autumn"
    },
    {
      "x": -2,
      "y": 20,
      "z": 8,
      "name": "Plant_Leaves_Autumn"
    },
    {
      "x": -2,
      "y": 21,
      "z": 8,
      "name": "Plant_Leaves_Autumn"
    },
    {
      "x": -2,
      "y": 23,
      "z": 8,
      "name": "Plant_Leaves_Autumn"
    },
    {
      "x": -2,
      "y": 24,
      "z": 8,
      "name": "Plant_Leaves_Autumn"
    },
    {
      "x": -2,
      "y": 25,
      "z": 8,
      "name": "Plant_Leaves_Autumn"
    },
    {
      "x": -2,
      "y": 25,
      "z": 9,
      "name": "Plant_Leaves_Autumn"
    },
    {
      "x": -1,
      "y": 20,
      "z": -13,
      "name": "Plant_Leaves_Autumn"
    },
    {
      "x": -1,
      "y": 25,
      "z": -13,
      "name": "Plant_Leaves_Autumn"
    },
    {
      "x": -1,
      "y": 20,
      "z": -12,
      "name": "Plant_Leaves_Autumn"
    },
    {
      "x": -1,
      "y": 21,
      "z": -12,
      "name": "Plant_Leaves_Autumn"
    },
    {
      "x": -1,
      "y": 25,
      "z": -12,
      "name": "Plant_Leaves_Autumn"
    },
    {
      "x": -1,
      "y": 19,
      "z": -11,
      "name": "Plant_Leaves_Autumn"
    },
    {
      "x": -1,
      "y": 20,
      "z": -11,
      "name": "Plant_Leaves_Autumn"
    },
    {
      "x": -1,
      "y": 22,
      "z": -11,
      "name": "Plant_Leaves_Autumn"
    },
    {
      "x": -1,
      "y": 25,
      "z": -11,
      "name": "Plant_Leaves_Autumn"
    },
    {
      "x": -1,
      "y": 26,
      "z": -11,
      "name": "Plant_Leaves_Autumn"
    },
    {
      "x": -1,
      "y": 20,
      "z": -10,
      "name": "Plant_Leaves_Autumn"
    },
    {
      "x": -1,
      "y": 25,
      "z": -10,
      "name": "Plant_Leaves_Autumn"
    },
    {
      "x": -1,
      "y": 26,
      "z": -10,
      "name": "Plant_Leaves_Autumn"
    },
    {
      "x": -1,
      "y": 25,
      "z": -9,
      "name": "Plant_Leaves_Autumn"
    },
    {
      "x": -1,
      "y": 26,
      "z": -9,
      "name": "Plant_Leaves_Autumn"
    },
    {
      "x": -1,
      "y": 19,
      "z": -8,
      "name": "Wood_Oak_Roots"
    },
    {
      "x": -1,
      "y": 20,
      "z": -8,
      "name": "Wood_Oak_Trunk_Full"
    },
    {
      "x": -1,
      "y": 21,
      "z": -8,
      "name": "Wood_Oak_Trunk_Full"
    },
    {
      "x": -1,
      "y": 25,
      "z": -8,
      "name": "Plant_Leaves_Autumn"
    },
    {
      "x": -1,
      "y": 19,
      "z": -7,
      "name": "Wood_Oak_Roots"
    },
    {
      "x": -1,
      "y": 20,
      "z": -7,
      "name": "Wood_Oak_Trunk_Full"
    },
    {
      "x": -1,
      "y": 25,
      "z": -7,
      "name": "Wood_Oak_Branch_Long",
      "rotation": 4
    },
    {
      "x": -1,
      "y": 19,
      "z": -6,
      "name": "Wood_Oak_Trunk_Full"
    },
    {
      "x": -1,
      "y": 20,
      "z": -6,
      "name": "Wood_Oak_Trunk_Full"
    },
    {
      "x": -1,
      "y": 23,
      "z": -6,
      "name": "Wood_Oak_Trunk_Full"
    },
    {
      "x": -1,
      "y": 24,
      "z": -6,
      "name": "Wood_Oak_Trunk"
    },
    {
      "x": -1,
      "y": 25,
      "z": -6,
      "name": "Wood_Oak_Trunk"
    },
    {
      "x": -1,
      "y": 26,
      "z": -6,
      "name": "Wood_Oak_Trunk"
    },
    {
      "x": -1,
      "y": 27,
      "z": -6,
      "name": "Wood_Oak_Trunk_Full"
    },
    {
      "x": -1,
      "y": 29,
      "z": -6,
      "name": "Plant_Leaves_Autumn"
    },
    {
      "x": -1,
      "y": 30,
      "z": -6,
      "name": "Plant_Leaves_Autumn"
    },
    {
      "x": -1,
      "y": 29,
      "z": -5,
      "name": "Plant_Leaves_Autumn"
    },
    {
      "x": -1,
      "y": 29,
      "z": -4,
      "name": "Plant_Leaves_Autumn"
    },
    {
      "x": -1,
      "y": 30,
      "z": -4,
      "name": "Plant_Leaves_Autumn"
    },
    {
      "x": -1,
      "y": 30,
      "z": -3,
      "name": "Plant_Leaves_Autumn"
    },
    {
      "x": -1,
      "y": 31,
      "z": -3,
      "name": "Plant_Leaves_Autumn"
    },
    {
      "x": -1,
      "y": 15,
      "z": -2,
      "name": "Wood_Oak_Trunk_Full"
    },
    {
      "x": -1,
      "y": 16,
      "z": -2,
      "name": "Wood_Oak_Trunk"
    },
    {
      "x": -1,
      "y": 17,
      "z": -2,
      "name": "Wood_Oak_Trunk"
    },
    {
      "x": -1,
      "y": 18,
      "z": -2,
      "name": "Wood_Oak_Trunk"
    },
    {
      "x": -1,
      "y": 19,
      "z": -2,
      "name": "Wood_Oak_Trunk"
    },
    {
      "x": -1,
      "y": 20,
      "z": -2,
      "name": "Wood_Oak_Trunk"
    },
    {
      "x": -1,
      "y": 21,
      "z": -2,
      "name": "Wood_Oak_Trunk"
    },
    {
      "x": -1,
      "y": 22,
      "z": -2,
      "name": "Wood_Oak_Trunk"
    },
    {
      "x": -1,
      "y": 23,
      "z": -2,
      "name": "Wood_Oak_Trunk"
    },
    {
      "x": -1,
      "y": 24,
      "z": -2,
      "name": "Wood_Oak_Trunk"
    },
    {
      "x": -1,
      "y": 25,
      "z": -2,
      "name": "Wood_Oak_Trunk_Full"
    },
    {
      "x": -1,
      "y": 30,
      "z": -2,
      "name": "Plant_Leaves_Autumn"
    },
    {
      "x": -1,
      "y": 11,
      "z": -1,
      "name": "Wood_Oak_Trunk_Full"
    },
    {
      "x": -1,
      "y": 12,
      "z": -1,
      "name": "Wood_Oak_Trunk"
    },
    {
      "x": -1,
      "y": 13,
      "z": -1,
      "name": "Wood_Oak_Trunk"
    },
    {
      "x": -1,
      "y": 14,
      "z": -1,
      "name": "Wood_Oak_Trunk"
    },
    {
      "x": -1,
      "y": 15,
      "z": -1,
      "name": "Wood_Oak_Trunk"
    },
    {
      "x": -1,
      "y": 16,
      "z": -1,
      "name": "Wood_Oak_Trunk"
    },
    {
      "x": -1,
      "y": 17,
      "z": -1,
      "name": "Wood_Oak_Trunk"
    },
    {
      "x": -1,
      "y": 18,
      "z": -1,
      "name": "Wood_Oak_Trunk"
    },
    {
      "x": -1,
      "y": 19,
      "z": -1,
      "name": "Wood_Oak_Trunk"
    },
    {
      "x": -1,
      "y": 20,
      "z": -1,
      "name": "Wood_Oak_Trunk"
    },
    {
      "x": -1,
      "y": 21,
      "z": -1,
      "name": "Wood_Oak_Trunk"
    },
    {
      "x": -1,
      "y": 22,
      "z": -1,
      "name": "Wood_Oak_Trunk"
    },
    {
      "x": -1,
      "y": 23,
      "z": -1,
      "name": "Wood_Oak_Trunk"
    },
    {
      "x": -1,
      "y": 24,
      "z": -1,
      "name": "Wood_Oak_Trunk"
    },
    {
      "x": -1,
      "y": 25,
      "z": -1,
      "name": "Wood_Oak_Trunk"
    },
    {
      "x": -1,
      "y": 26,
      "z": -1,
      "name": "Wood_Oak_Trunk"
    },
    {
      "x": -1,
      "y": 27,
      "z": -1,
      "name": "Wood_Oak_Trunk"
    },
    {
      "x": -1,
      "y": 28,
      "z": -1,
      "name": "Wood_Oak_Trunk_Full"
    },
    {
      "x": -1,
      "y": 29,
      "z": -1,
      "name": "Wood_Oak_Branch_Long"
    },
    {
      "x": -1,
      "y": 30,
      "z": -1,
      "name": "Plant_Leaves_Autumn"
    },
    {
      "x": -1,
      "y": 4,
      "z": 0,
      "name": "Wood_Oak_Trunk_Full"
    },
    {
      "x": -1,
      "y": 5,
      "z": 0,
      "name": "Wood_Oak_Trunk"
    },
    {
      "x": -1,
      "y": 6,
      "z": 0,
      "name": "Wood_Oak_Trunk"
    },
    {
      "x": -1,
      "y": 7,
      "z": 0,
      "name": "Wood_Oak_Trunk"
    },
    {
      "x": -1,
      "y": 8,
      "z": 0,
      "name": "Wood_Oak_Trunk"
    },
    {
      "x": -1,
      "y": 9,
      "z": 0,
      "name": "Wood_Oak_Trunk"
    },
    {
      "x": -1,
      "y": 10,
      "z": 0,
      "name": "Wood_Oak_Trunk"
    },
    {
      "x": -1,
      "y": 11,
      "z": 0,
      "name": "Wood_Oak_Trunk"
    },
    {
      "x": -1,
      "y": 12,
      "z": 0,
      "name": "Wood_Oak_Trunk"
    },
    {
      "x": -1,
      "y": 13,
      "z": 0,
      "name": "Wood_Oak_Trunk"
    },
    {
      "x": -1,
      "y": 14,
      "z": 0,
      "name": "Wood_Oak_Trunk"
    },
    {
      "x": -1,
      "y": 15,
      "z": 0,
      "name": "Wood_Oak_Trunk_Full"
    },
    {
      "x": -1,
      "y": 17,
      "z": 0,
      "name": "Wood_Oak_Trunk_Full"
    },
    {
      "x": -1,
      "y": 18,
      "z": 0,
      "name": "Wood_Oak_Trunk"
    },
    {
      "x": -1,
      "y": 19,
      "z": 0,
      "name": "Wood_Oak_Trunk"
    },
    {
      "x": -1,
      "y": 20,
      "z": 0,
      "name": "Wood_Oak_Trunk_Full"
    },
    {
      "x": -1,
      "y": 30,
      "z": 0,
      "name": "Plant_Leaves_Autumn"
    },
    {
      "x": -1,
      "y": 4,
      "z": 1,
      "name": "Wood_Oak_Roots"
    },
    {
      "x": -1,
      "y": 5,
      "z": 1,
      "name": "Wood_Oak_Trunk_Full"
    },
    {
      "x": -1,
      "y": 6,
      "z": 1,
      "name": "Wood_Oak_Trunk"
    },
    {
      "x": -1,
      "y": 7,
      "z": 1,
      "name": "Wood_Oak_Trunk"
    },
    {
      "x": -1,
      "y": 8,
      "z": 1,
      "name": "Wood_Oak_Trunk"
    },
    {
      "x": -1,
      "y": 9,
      "z": 1,
      "name": "Wood_Oak_Trunk"
    },
    {
      "x": -1,
      "y": 10,
      "z": 1,
      "name": "Wood_Oak_Trunk"
    },
    {
      "x": -1,
      "y": 11,
      "z": 1,
      "name": "Wood_Oak_Trunk"
    },
    {
      "x": -1,
      "y": 12,
      "z": 1,
      "name": "Wood_Oak_Trunk_Full"
    },
    {
      "x": -1,
      "y": 19,
      "z": 1,
      "name": "Wood_Oak_Branch_Short"
    },
    {
      "x": -1,
      "y": 30,
      "z": 1,
      "name": "Plant_Leaves_Autumn"
    },
    {
      "x": -1,
      "y": 30,
      "z": 2,
      "name": "Plant_Leaves_Autumn"
    },
    {
      "x": -1,
      "y": 22,
      "z": 4,
      "name": "Plant_Leaves_Autumn"
    },
    {
      "x": -1,
      "y": 23,
      "z": 4,
      "name": "Wood_Oak_Branch_Long",
      "rotation": 5
    },
    {
      "x": -1,
      "y": 24,
      "z": 4,
      "name": "Plant_Leaves_Autumn"
    },
    {
      "x": -1,
      "y": 23,
      "z": 5,
      "name": "Plant_Leaves_Autumn"
    },
    {
      "x": -1,
      "y": 24,
      "z": 5,
      "name": "Plant_Leaves_Autumn"
    },
    {
      "x": -1,
      "y": 20,
      "z": 6,
      "name": "Plant_Leaves_Autumn"
    },
    {
      "x": -1,
      "y": 23,
      "z": 6,
      "name": "Plant_Leaves_Autumn"
    },
    {
      "x": -1,
      "y": 24,
      "z": 6,
      "name": "Plant_Leaves_Autumn"
    },
    {
      "x": -1,
      "y": 25,
      "z": 6,
      "name": "Plant_Leaves_Autumn"
    },
    {
      "x": -1,
      "y": 20,
      "z": 7,
      "name": "Plant_Leaves_Autumn"
    },
    {
      "x": -1,
      "y": 21,
      "z": 7,
      "name": "Plant_Leaves_Autumn"
    },
    {
      "x": -1,
      "y": 23,
      "z": 7,
      "name": "Plant_Leaves_Autumn"
    },
    {
      "x": -1,
      "y": 24,
      "z": 7,
      "name": "Plant_Leaves_Autumn"
    },
    {
      "x": -1,
      "y": 25,
      "z": 7,
      "name": "Plant_Leaves_Autumn"
    },
    {
      "x": -1,
      "y": 26,
      "z": 7,
      "name": "Plant_Leaves_Autumn"
    },
    {
      "x": -1,
      "y": 19,
      "z": 8,
      "name": "Plant_Leaves_Autumn"
    },
    {
      "x": -1,
      "y": 20,
      "z": 8,
      "name": "Plant_Leaves_Autumn"
    },
    {
      "x": -1,
      "y": 23,
      "z": 8,
      "name": "Plant_Leaves_Autumn"
    },
    {
      "x": -1,
      "y": 24,
      "z": 8,
      "name": "Plant_Leaves_Autumn"
    },
    {
      "x": -1,
      "y": 20,
      "z": 9,
      "name": "Plant_Leaves_Autumn"
    },
    {
      "x": -1,
      "y": 20,
      "z": 10,
      "name": "Plant_Leaves_Autumn"
    },
    {
      "x": 0,
      "y": 20,
      "z": -13,
      "name": "Plant_Leaves_Autumn"
    },
    {
      "x": 0,
      "y": 21,
      "z": -13,
      "name": "Plant_Leaves_Autumn"
    },
    {
      "x": 0,
      "y": 22,
      "z": -13,
      "name": "Plant_Leaves_Autumn"
    },
    {
      "x": 0,
      "y": 20,
      "z": -12,
      "name": "Plant_Leaves_Autumn"
    },
    {
      "x": 0,
      "y": 21,
      "z": -12,
      "name": "Plant_Leaves_Autumn"
    },
    {
      "x": 0,
      "y": 22,
      "z": -12,
      "name": "Plant_Leaves_Autumn"
    },
    {
      "x": 0,
      "y": 19,
      "z": -11,
      "name": "Plant_Leaves_Autumn"
    },
    {
      "x": 0,
      "y": 20,
      "z": -11,
      "name": "Plant_Leaves_Autumn"
    },
    {
      "x": 0,
      "y": 21,
      "z": -11,
      "name": "Plant_Leaves_Autumn"
    },
    {
      "x": 0,
      "y": 19,
      "z": -10,
      "name": "Plant_Leaves_Autumn"
    },
    {
      "x": 0,
      "y": 20,
      "z": -10,
      "name": "Plant_Leaves_Autumn"
    },
    {
      "x": 0,
      "y": 21,
      "z": -10,
      "name": "Plant_Leaves_Autumn"
    },
    {
      "x": 0,
      "y": 22,
      "z": -10,
      "name": "Plant_Leaves_Autumn"
    },
    {
      "x": 0,
      "y": 25,
      "z": -10,
      "name": "Plant_Leaves_Autumn"
    },
    {
      "x": 0,
      "y": 20,
      "z": -9,
      "name": "Plant_Leaves_Autumn"
    },
    {
      "x": 0,
      "y": 26,
      "z": -9,
      "name": "Plant_Leaves_Autumn"
    },
    {
      "x": 0,
      "y": 20,
      "z": -8,
      "name": "Wood_Oak_Branch_Long",
      "rotation": 5
    },
    {
      "x": 0,
      "y": 25,
      "z": -8,
      "name": "Plant_Leaves_Autumn"
    },
    {
      "x": 0,
      "y": 29,
      "z": -8,
      "name": "Plant_Leaves_Autumn"
    },
    {
      "x": 0,
      "y": 28,
      "z": -7,
      "name": "Plant_Leaves_Autumn"
    },
    {
      "x": 0,
      "y": 29,
      "z": -7,
      "name": "Plant_Leaves_Autumn"
    },
    {
      "x": 0,
      "y": 19,
      "z": -6,
      "name": "Wood_Oak_Trunk_Full"
    },
    {
      "x": 0,
      "y": 20,
      "z": -6,
      "name": "Wood_Oak_Trunk_Full"
    },
    {
      "x": 0,
      "y": 22,
      "z": -6,
      "name": "Wood_Oak_Trunk_Full"
    },
    {
      "x": 0,
      "y": 23,
      "z": -6,
      "name": "Wood_Oak_Trunk_Full"
    },
    {
      "x": 0,
      "y": 25,
      "z": -6,
      "name": "Wood_Oak_Branch_Long",
      "rotation": 5
    },
    {
      "x": 0,
      "y": 27,
      "z": -6,
      "name": "Wood_Oak_Branch_Corner",
      "rotation": 1
    },
    {
      "x": 0,
      "y": 28,
      "z": -6,
      "name": "Wood_Oak_Branch_Long"
    },
    {
      "x": 0,
      "y": 29,
      "z": -6,
      "name": "Plant_Leaves_Autumn"
    },
    {
      "x": 0,
      "y": 30,
      "z": -6,
      "name": "Plant_Leaves_Autumn"
    },
    {
      "x": 0,
      "y": 19,
      "z": -5,
      "name": "Wood_Oak_Trunk_Full"
    },
    {
      "x": 0,
      "y": 20,
      "z": -5,
      "name": "Wood_Oak_Trunk_Full"
    },
    {
      "x": 0,
      "y": 21,
      "z": -5,
      "name": "Wood_Oak_Trunk"
    },
    {
      "x": 0,
      "y": 22,
      "z": -5,
      "name": "Wood_Oak_Trunk_Full"
    },
    {
      "x": 0,
      "y": 29,
      "z": -5,
      "name": "Plant_Leaves_Autumn"
    },
    {
      "x": 0,
      "y": 30,
      "z": -5,
      "name": "Plant_Leaves_Autumn"
    },
    {
      "x": 0,
      "y": 19,
      "z": -4,
      "name": "Wood_Oak_Trunk_Full"
    },
    {
      "x": 0,
      "y": 20,
      "z": -4,
      "name": "Wood_Oak_Trunk_Full"
    },
    {
      "x": 0,
      "y": 30,
      "z": -4,
      "name": "Plant_Leaves_Autumn"
    },
    {
      "x": 0,
      "y": 18,
      "z": -3,
      "name": "Wood_Oak_Trunk_Full"
    },
    {
      "x": 0,
      "y": 19,
      "z": -3,
      "name": "Wood_Oak_Trunk_Full"
    },
    {
      "x": 0,
      "y": 30,
      "z": -3,
      "name": "Plant_Leaves_Autumn"
    },
    {
      "x": 0,
      "y": 12,
      "z": -2,
      "name": "Wood_Oak_Trunk_Full"
    },
    {
      "x": 0,
      "y": 13,
      "z": -2,
      "name": "Wood_Oak_Trunk"
    },
    {
      "x": 0,
      "y": 14,
      "z": -2,
      "name": "Wood_Oak_Trunk"
    },
    {
      "x": 0,
      "y": 15,
      "z": -2,
      "name": "Wood_Oak_Trunk"
    },
    {
      "x": 0,
      "y": 16,
      "z": -2,
      "name": "Wood_Oak_Trunk"
    },
    {
      "x": 0,
      "y": 17,
      "z": -2,
      "name": "Wood_Oak_Trunk"
    },
    {
      "x": 0,
      "y": 18,
      "z": -2,
      "name": "Wood_Oak_Trunk"
    },
    {
      "x": 0,
      "y": 19,
      "z": -2,
      "name": "Wood_Oak_Trunk"
    },
    {
      "x": 0,
      "y": 20,
      "z": -2,
      "name": "Wood_Oak_Trunk"
    },
    {
      "x": 0,
      "y": 21,
      "z": -2,
      "name": "Wood_Oak_Trunk"
    },
    {
      "x": 0,
      "y": 22,
      "z": -2,
      "name": "Wood_Oak_Trunk_Full"
    },
    {
      "x": 0,
      "y": 30,
      "z": -2,
      "name": "Plant_Leaves_Autumn"
    },
    {
      "x": 0,
      "y": 4,
      "z": -1,
      "name": "Wood_Oak_Trunk_Full"
    },
    {
      "x": 0,
      "y": 5,
      "z": -1,
      "name": "Wood_Oak_Trunk"
    },
    {
      "x": 0,
      "y": 6,
      "z": -1,
      "name": "Wood_Oak_Trunk_Full"
    },
    {
      "x": 0,
      "y": 9,
      "z": -1,
      "name": "Wood_Oak_Trunk_Full"
    },
    {
      "x": 0,
      "y": 10,
      "z": -1,
      "name": "Wood_Oak_Trunk"
    },
    {
      "x": 0,
      "y": 11,
      "z": -1,
      "name": "Wood_Oak_Trunk"
    },
    {
      "x": 0,
      "y": 12,
      "z": -1,
      "name": "Wood_Oak_Trunk"
    },
    {
      "x": 0,
      "y": 13,
      "z": -1,
      "name": "Wood_Oak_Trunk"
    },
    {
      "x": 0,
      "y": 14,
      "z": -1,
      "name": "Wood_Oak_Trunk"
    },
    {
      "x": 0,
      "y": 15,
      "z": -1,
      "name": "Wood_Oak_Trunk"
    },
    {
      "x": 0,
      "y": 16,
      "z": -1,
      "name": "Wood_Oak_Trunk"
    },
    {
      "x": 0,
      "y": 17,
      "z": -1,
      "name": "Wood_Oak_Trunk"
    },
    {
      "x": 0,
      "y": 18,
      "z": -1,
      "name": "Wood_Oak_Trunk"
    },
    {
      "x": 0,
      "y": 19,
      "z": -1,
      "name": "Wood_Oak_Trunk"
    },
    {
      "x": 0,
      "y": 20,
      "z": -1,
      "name": "Wood_Oak_Trunk"
    },
    {
      "x": 0,
      "y": 21,
      "z": -1,
      "name": "Wood_Oak_Trunk"
    },
    {
      "x": 0,
      "y": 22,
      "z": -1,
      "name": "Wood_Oak_Trunk"
    },
    {
      "x": 0,
      "y": 23,
      "z": -1,
      "name": "Wood_Oak_Trunk"
    },
    {
      "x": 0,
      "y": 24,
      "z": -1,
      "name": "Wood_Oak_Trunk_Full"
    },
    {
      "x": 0,
      "y": 29,
      "z": -1,
      "name": "Plant_Leaves_Autumn"
    },
    {
      "x": 0,
      "y": 30,
      "z": -1,
      "name": "Plant_Leaves_Autumn"
    },
    {
      "x": 0,
      "y": 2,
      "z": 0,
      "name": "Wood_Oak_Roots"
    },
    {
      "x": 0,
      "y": 3,
      "z": 0,
      "name": "Wood_Oak_Trunk_Full"
    },
    {
      "x": 0,
      "y": 4,
      "z": 0,
      "name": "Wood_Oak_Trunk"
    },
    {
      "x": 0,
      "y": 5,
      "z": 0,
      "name": "Wood_Oak_Trunk"
    },
    {
      "x": 0,
      "y": 6,
      "z": 0,
      "name": "Wood_Oak_Trunk"
    },
    {
      "x": 0,
      "y": 7,
      "z": 0,
      "name": "Wood_Oak_Trunk"
    },
    {
      "x": 0,
      "y": 8,
      "z": 0,
      "name": "Wood_Oak_Trunk"
    },
    {
      "x": 0,
      "y": 9,
      "z": 0,
      "name": "Wood_Oak_Trunk"
    },
    {
      "x": 0,
      "y": 10,
      "z": 0,
      "name": "Wood_Oak_Trunk"
    },
    {
      "x": 0,
      "y": 11,
      "z": 0,
      "name": "Wood_Oak_Trunk"
    },
    {
      "x": 0,
      "y": 12,
      "z": 0,
      "name": "Wood_Oak_Trunk"
    },
    {
      "x": 0,
      "y": 13,
      "z": 0,
      "name": "Wood_Oak_Trunk"
    },
    {
      "x": 0,
      "y": 14,
      "z": 0,
      "name": "Wood_Oak_Trunk"
    },
    {
      "x": 0,
      "y": 15,
      "z": 0,
      "name": "Wood_Oak_Trunk"
    },
    {
      "x": 0,
      "y": 16,
      "z": 0,
      "name": "Wood_Oak_Trunk"
    },
    {
      "x": 0,
      "y": 17,
      "z": 0,
      "name": "Wood_Oak_Trunk"
    },
    {
      "x": 0,
      "y": 18,
      "z": 0,
      "name": "Wood_Oak_Trunk"
    },
    {
      "x": 0,
      "y": 19,
      "z": 0,
      "name": "Wood_Oak_Trunk"
    },
    {
      "x": 0,
      "y": 20,
      "z": 0,
      "name": "Wood_Oak_Trunk"
    },
    {
      "x": 0,
      "y": 21,
      "z": 0,
      "name": "Wood_Oak_Trunk"
    },
    {
      "x": 0,
      "y": 22,
      "z": 0,
      "name": "Wood_Oak_Trunk"
    },
    {
      "x": 0,
      "y": 23,
      "z": 0,
      "name": "Wood_Oak_Trunk_Full"
    },
    {
      "x": 0,
      "y": 29,
      "z": 0,
      "name": "Plant_Leaves_Autumn"
    },
    {
      "x": 0,
      "y": 30,
      "z": 0,
      "name": "Plant_Leaves_Autumn"
    },
    {
      "x": 0,
      "y": 2,
      "z": 1,
      "name": "Wood_Oak_Roots"
    },
    {
      "x": 0,
      "y": 3,
      "z": 1,
      "name": "Wood_Oak_Trunk_Full"
    },
    {
      "x": 0,
      "y": 4,
      "z": 1,
      "name": "Wood_Oak_Trunk"
    },
    {
      "x": 0,
      "y": 5,
      "z": 1,
      "name": "Wood_Oak_Trunk"
    },
    {
      "x": 0,
      "y": 6,
      "z": 1,
      "name": "Wood_Oak_Trunk"
    },
    {
      "x": 0,
      "y": 7,
      "z": 1,
      "name": "Wood_Oak_Trunk"
    },
    {
      "x": 0,
      "y": 8,
      "z": 1,
      "name": "Wood_Oak_Trunk"
    },
    {
      "x": 0,
      "y": 9,
      "z": 1,
      "name": "Wood_Oak_Trunk"
    },
    {
      "x": 0,
      "y": 10,
      "z": 1,
      "name": "Wood_Oak_Trunk"
    },
    {
      "x": 0,
      "y": 11,
      "z": 1,
      "name": "Wood_Oak_Trunk"
    },
    {
      "x": 0,
      "y": 12,
      "z": 1,
      "name": "Wood_Oak_Trunk"
    },
    {
      "x": 0,
      "y": 13,
      "z": 1,
      "name": "Wood_Oak_Trunk"
    },
    {
      "x": 0,
      "y": 14,
      "z": 1,
      "name": "Wood_Oak_Trunk_Full"
    },
    {
      "x": 0,
      "y": 19,
      "z": 1,
      "name": "Wood_Oak_Trunk_Full"
    },
    {
      "x": 0,
      "y": 29,
      "z": 1,
      "name": "Plant_Leaves_Autumn"
    },
    {
      "x": 0,
      "y": 30,
      "z": 1,
      "name": "Plant_Leaves_Autumn"
    },
    {
      "x": 0,
      "y": 31,
      "z": 1,
      "name": "Plant_Leaves_Autumn"
    },
    {
      "x": 0,
      "y": 4,
      "z": 2,
      "name": "Wood_Oak_Roots"
    },
    {
      "x": 0,
      "y": 5,
      "z": 2,
      "name": "Wood_Oak_Trunk_Full"
    },
    {
      "x": 0,
      "y": 6,
      "z": 2,
      "name": "Wood_Oak_Trunk"
    },
    {
      "x": 0,
      "y": 7,
      "z": 2,
      "name": "Wood_Oak_Trunk"
    },
    {
      "x": 0,
      "y": 8,
      "z": 2,
      "name": "Wood_Oak_Trunk"
    },
    {
      "x": 0,
      "y": 9,
      "z": 2,
      "name": "Wood_Oak_Trunk"
    },
    {
      "x": 0,
      "y": 10,
      "z": 2,
      "name": "Wood_Oak_Trunk"
    },
    {
      "x": 0,
      "y": 11,
      "z": 2,
      "name": "Wood_Oak_Trunk_Full"
    },
    {
      "x": 0,
      "y": 19,
      "z": 2,
      "name": "Wood_Oak_Trunk_Full"
    },
    {
      "x": 0,
      "y": 29,
      "z": 2,
      "name": "Plant_Leaves_Autumn"
    },
    {
      "x": 0,
      "y": 30,
      "z": 2,
      "name": "Plant_Leaves_Autumn"
    },
    {
      "x": 0,
      "y": 23,
      "z": 3,
      "name": "Plant_Leaves_Autumn"
    },
    {
      "x": 0,
      "y": 24,
      "z": 3,
      "name": "Plant_Leaves_Autumn"
    },
    {
      "x": 0,
      "y": 22,
      "z": 4,
      "name": "Plant_Leaves_Autumn"
    },
    {
      "x": 0,
      "y": 23,
      "z": 4,
      "name": "Plant_Leaves_Autumn"
    },
    {
      "x": 0,
      "y": 24,
      "z": 4,
      "name": "Plant_Leaves_Autumn"
    },
    {
      "x": 0,
      "y": 23,
      "z": 5,
      "name": "Plant_Leaves_Autumn"
    },
    {
      "x": 0,
      "y": 23,
      "z": 6,
      "name": "Plant_Leaves_Autumn"
    },
    {
      "x": 0,
      "y": 24,
      "z": 6,
      "name": "Plant_Leaves_Autumn"
    },
    {
      "x": 0,
      "y": 19,
      "z": 7,
      "name": "Plant_Leaves_Autumn"
    },
    {
      "x": 0,
      "y": 20,
      "z": 7,
      "name": "Plant_Leaves_Autumn"
    },
    {
      "x": 0,
      "y": 21,
      "z": 7,
      "name": "Plant_Leaves_Autumn"
    },
    {
      "x": 0,
      "y": 23,
      "z": 7,
      "name": "Plant_Leaves_Autumn"
    },
    {
      "x": 0,
      "y": 25,
      "z": 7,
      "name": "Plant_Leaves_Autumn"
    },
    {
      "x": 0,
      "y": 26,
      "z": 7,
      "name": "Plant_Leaves_Autumn"
    },
    {
      "x": 0,
      "y": 18,
      "z": 8,
      "name": "Plant_Leaves_Autumn"
    },
    {
      "x": 0,
      "y": 19,
      "z": 8,
      "name": "Plant_Leaves_Autumn"
    },
    {
      "x": 0,
      "y": 20,
      "z": 8,
      "name": "Plant_Leaves_Autumn"
    },
    {
      "x": 0,
      "y": 23,
      "z": 8,
      "name": "Plant_Leaves_Autumn"
    },
    {
      "x": 0,
      "y": 20,
      "z": 9,
      "name": "Plant_Leaves_Autumn"
    },
    {
      "x": 0,
      "y": 21,
      "z": 9,
      "name": "Plant_Leaves_Autumn"
    },
    {
      "x": 0,
      "y": 20,
      "z": 10,
      "name": "Plant_Leaves_Autumn"
    },
    {
      "x": 0,
      "y": 20,
      "z": 11,
      "name": "Plant_Leaves_Autumn"
    },
    {
      "x": 1,
      "y": 20,
      "z": -13,
      "name": "Plant_Leaves_Autumn"
    },
    {
      "x": 1,
      "y": 21,
      "z": -13,
      "name": "Plant_Leaves_Autumn"
    },
    {
      "x": 1,
      "y": 19,
      "z": -12,
      "name": "Plant_Leaves_Autumn"
    },
    {
      "x": 1,
      "y": 20,
      "z": -12,
      "name": "Plant_Leaves_Autumn"
    },
    {
      "x": 1,
      "y": 19,
      "z": -11,
      "name": "Plant_Leaves_Autumn"
    },
    {
      "x": 1,
      "y": 20,
      "z": -11,
      "name": "Plant_Leaves_Autumn"
    },
    {
      "x": 1,
      "y": 21,
      "z": -11,
      "name": "Plant_Leaves_Autumn"
    },
    {
      "x": 1,
      "y": 22,
      "z": -11,
      "name": "Plant_Leaves_Autumn"
    },
    {
      "x": 1,
      "y": 25,
      "z": -11,
      "name": "Plant_Leaves_Autumn"
    },
    {
      "x": 1,
      "y": 20,
      "z": -10,
      "name": "Plant_Leaves_Autumn"
    },
    {
      "x": 1,
      "y": 21,
      "z": -10,
      "name": "Plant_Leaves_Autumn"
    },
    {
      "x": 1,
      "y": 25,
      "z": -10,
      "name": "Plant_Leaves_Autumn"
    },
    {
      "x": 1,
      "y": 26,
      "z": -10,
      "name": "Plant_Leaves_Autumn"
    },
    {
      "x": 1,
      "y": 25,
      "z": -9,
      "name": "Plant_Leaves_Autumn"
    },
    {
      "x": 1,
      "y": 26,
      "z": -9,
      "name": "Plant_Leaves_Autumn"
    },
    {
      "x": 1,
      "y": 15,
      "z": -8,
      "name": "Plant_Leaves_Autumn"
    },
    {
      "x": 1,
      "y": 19,
      "z": -8,
      "name": "Plant_Leaves_Autumn"
    },
    {
      "x": 1,
      "y": 20,
      "z": -8,
      "name": "Wood_Oak_Branch_Long",
      "rotation": 5
    },
    {
      "x": 1,
      "y": 25,
      "z": -8,
      "name": "Plant_Leaves_Autumn"
    },
    {
      "x": 1,
      "y": 15,
      "z": -7,
      "name": "Plant_Leaves_Autumn"
    },
    {
      "x": 1,
      "y": 25,
      "z": -7,
      "name": "Plant_Leaves_Autumn"
    },
    {
      "x": 1,
      "y": 15,
      "z": -6,
      "name": "Plant_Leaves_Autumn"
    },
    {
      "x": 1,
      "y": 25,
      "z": -6,
      "name": "Plant_Leaves_Autumn"
    },
    {
      "x": 1,
      "y": 28,
      "z": -6,
      "name": "Plant_Leaves_Autumn"
    },
    {
      "x": 1,
      "y": 29,
      "z": -6,
      "name": "Plant_Leaves_Autumn"
    },
    {
      "x": 1,
      "y": 29,
      "z": -5,
      "name": "Plant_Leaves_Autumn"
    },
    {
      "x": 1,
      "y": 30,
      "z": -5,
      "name": "Plant_Leaves_Autumn"
    },
    {
      "x": 1,
      "y": 28,
      "z": -4,
      "name": "Plant_Leaves_Autumn"
    },
    {
      "x": 1,
      "y": 29,
      "z": -4,
      "name": "Plant_Leaves_Autumn"
    },
    {
      "x": 1,
      "y": 30,
      "z": -4,
      "name": "Plant_Leaves_Autumn"
    },
    {
      "x": 1,
      "y": 30,
      "z": -3,
      "name": "Plant_Leaves_Autumn"
    },
    {
      "x": 1,
      "y": 12,
      "z": -2,
      "name": "Wood_Oak_Branch_Corner",
      "rotation": 2
    },
    {
      "x": 1,
      "y": 16,
      "z": -2,
      "name": "Wood_Oak_Trunk_Full"
    },
    {
      "x": 1,
      "y": 17,
      "z": -2,
      "name": "Wood_Oak_Trunk"
    },
    {
      "x": 1,
      "y": 18,
      "z": -2,
      "name": "Wood_Oak_Trunk"
    },
    {
      "x": 1,
      "y": 19,
      "z": -2,
      "name": "Wood_Oak_Trunk"
    },
    {
      "x": 1,
      "y": 20,
      "z": -2,
      "name": "Wood_Oak_Trunk_Full"
    },
    {
      "x": 1,
      "y": 30,
      "z": -2,
      "name": "Plant_Leaves_Autumn"
    },
    {
      "x": 1,
      "y": 10,
      "z": -1,
      "name": "Wood_Oak_Trunk_Full"
    },
    {
      "x": 1,
      "y": 11,
      "z": -1,
      "name": "Wood_Oak_Trunk"
    },
    {
      "x": 1,
      "y": 12,
      "z": -1,
      "name": "Wood_Oak_Trunk"
    },
    {
      "x": 1,
      "y": 13,
      "z": -1,
      "name": "Wood_Oak_Trunk"
    },
    {
      "x": 1,
      "y": 14,
      "z": -1,
      "name": "Wood_Oak_Trunk"
    },
    {
      "x": 1,
      "y": 15,
      "z": -1,
      "name": "Wood_Oak_Trunk"
    },
    {
      "x": 1,
      "y": 16,
      "z": -1,
      "name": "Wood_Oak_Trunk"
    },
    {
      "x": 1,
      "y": 17,
      "z": -1,
      "name": "Wood_Oak_Trunk"
    },
    {
      "x": 1,
      "y": 18,
      "z": -1,
      "name": "Wood_Oak_Trunk"
    },
    {
      "x": 1,
      "y": 19,
      "z": -1,
      "name": "Wood_Oak_Trunk"
    },
    {
      "x": 1,
      "y": 20,
      "z": -1,
      "name": "Wood_Oak_Trunk"
    },
    {
      "x": 1,
      "y": 21,
      "z": -1,
      "name": "Wood_Oak_Trunk"
    },
    {
      "x": 1,
      "y": 22,
      "z": -1,
      "name": "Wood_Oak_Trunk_Full"
    },
    {
      "x": 1,
      "y": 24,
      "z": -1,
      "name": "Wood_Oak_Trunk_Full"
    },
    {
      "x": 1,
      "y": 25,
      "z": -1,
      "name": "Wood_Oak_Trunk_Full"
    },
    {
      "x": 1,
      "y": 30,
      "z": -1,
      "name": "Plant_Leaves_Autumn"
    },
    {
      "x": 1,
      "y": 3,
      "z": 0,
      "name": "Wood_Oak_Roots"
    },
    {
      "x": 1,
      "y": 4,
      "z": 0,
      "name": "Wood_Oak_Trunk_Full"
    },
    {
      "x": 1,
      "y": 5,
      "z": 0,
      "name": "Wood_Oak_Trunk"
    },
    {
      "x": 1,
      "y": 6,
      "z": 0,
      "name": "Wood_Oak_Trunk"
    },
    {
      "x": 1,
      "y": 7,
      "z": 0,
      "name": "Wood_Oak_Trunk"
    },
    {
      "x": 1,
      "y": 8,
      "z": 0,
      "name": "Wood_Oak_Trunk"
    },
    {
      "x": 1,
      "y": 9,
      "z": 0,
      "name": "Wood_Oak_Trunk"
    },
    {
      "x": 1,
      "y": 10,
      "z": 0,
      "name": "Wood_Oak_Trunk"
    },
    {
      "x": 1,
      "y": 11,
      "z": 0,
      "name": "Wood_Oak_Trunk"
    },
    {
      "x": 1,
      "y": 12,
      "z": 0,
      "name": "Wood_Oak_Trunk_Full"
    },
    {
      "x": 1,
      "y": 17,
      "z": 0,
      "name": "Wood_Oak_Trunk_Full"
    },
    {
      "x": 1,
      "y": 18,
      "z": 0,
      "name": "Wood_Oak_Trunk"
    },
    {
      "x": 1,
      "y": 19,
      "z": 0,
      "name": "Wood_Oak_Trunk_Full"
    },
    {
      "x": 1,
      "y": 22,
      "z": 0,
      "name": "Wood_Oak_Trunk_Full"
    },
    {
      "x": 1,
      "y": 29,
      "z": 0,
      "name": "Plant_Leaves_Autumn"
    },
    {
      "x": 1,
      "y": 30,
      "z": 0,
      "name": "Plant_Leaves_Autumn"
    },
    {
      "x": 1,
      "y": 3,
      "z": 1,
      "name": "Wood_Oak_Roots"
    },
    {
      "x": 1,
      "y": 4,
      "z": 1,
      "name": "Wood_Oak_Trunk_Full"
    },
    {
      "x": 1,
      "y": 5,
      "z": 1,
      "name": "Wood_Oak_Trunk"
    },
    {
      "x": 1,
      "y": 6,
      "z": 1,
      "name": "Wood_Oak_Trunk"
    },
    {
      "x": 1,
      "y": 7,
      "z": 1,
      "name": "Wood_Oak_Trunk"
    },
    {
      "x": 1,
      "y": 8,
      "z": 1,
      "name": "Wood_Oak_Trunk"
    },
    {
      "x": 1,
      "y": 9,
      "z": 1,
      "name": "Wood_Oak_Trunk"
    },
    {
      "x": 1,
      "y": 10,
      "z": 1,
      "name": "Wood_Oak_Trunk"
    },
    {
      "x": 1,
      "y": 11,
      "z": 1,
      "name": "Wood_Oak_Trunk"
    },
    {
      "x": 1,
      "y": 12,
      "z": 1,
      "name": "Wood_Oak_Trunk_Full"
    },
    {
      "x": 1,
      "y": 29,
      "z": 1,
      "name": "Plant_Leaves_Autumn"
    },
    {
      "x": 1,
      "y": 30,
      "z": 1,
      "name": "Plant_Leaves_Autumn"
    },
    {
      "x": 1,
      "y": 7,
      "z": 2,
      "name": "Wood_Oak_Trunk_Full"
    },
    {
      "x": 1,
      "y": 8,
      "z": 2,
      "name": "Wood_Oak_Trunk"
    },
    {
      "x": 1,
      "y": 9,
      "z": 2,
      "name": "Wood_Oak_Trunk"
    },
    {
      "x": 1,
      "y": 10,
      "z": 2,
      "name": "Wood_Oak_Trunk_Full"
    },
    {
      "x": 1,
      "y": 19,
      "z": 2,
      "name": "Wood_Oak_Trunk_Full"
    },
    {
      "x": 1,
      "y": 29,
      "z": 2,
      "name": "Plant_Leaves_Autumn"
    },
    {
      "x": 1,
      "y": 18,
      "z": 3,
      "name": "Wood_Oak_Roots"
    },
    {
      "x": 1,
      "y": 19,
      "z": 3,
      "name": "Wood_Oak_Trunk_Full"
    },
    {
      "x": 1,
      "y": 20,
      "z": 3,
      "name": "Wood_Oak_Trunk_Full"
    },
    {
      "x": 1,
      "y": 20,
      "z": 4,
      "name": "Wood_Oak_Trunk_Full"
    },
    {
      "x": 1,
      "y": 23,
      "z": 4,
      "name": "Plant_Leaves_Autumn"
    },
    {
      "x": 1,
      "y": 23,
      "z": 6,
      "name": "Plant_Leaves_Autumn"
    },
    {
      "x": 1,
      "y": 24,
      "z": 6,
      "name": "Plant_Leaves_Autumn"
    },
    {
      "x": 1,
      "y": 19,
      "z": 7,
      "name": "Plant_Leaves_Autumn"
    },
    {
      "x": 1,
      "y": 20,
      "z": 7,
      "name": "Plant_Leaves_Autumn"
    },
    {
      "x": 1,
      "y": 21,
      "z": 7,
      "name": "Plant_Leaves_Autumn"
    },
    {
      "x": 1,
      "y": 19,
      "z": 8,
      "name": "Plant_Leaves_Autumn"
    },
    {
      "x": 1,
      "y": 20,
      "z": 8,
      "name": "Plant_Leaves_Autumn"
    },
    {
      "x": 1,
      "y": 20,
      "z": 9,
      "name": "Plant_Leaves_Autumn"
    },
    {
      "x": 1,
      "y": 21,
      "z": 9,
      "name": "Plant_Leaves_Autumn"
    },
    {
      "x": 1,
      "y": 20,
      "z": 10,
      "name": "Plant_Leaves_Autumn"
    },
    {
      "x": 1,
      "y": 21,
      "z": 10,
      "name": "Plant_Leaves_Autumn"
    },
    {
      "x": 1,
      "y": 20,
      "z": 11,
      "name": "Plant_Leaves_Autumn"
    },
    {
      "x": 2,
      "y": 20,
      "z": -13,
      "name": "Plant_Leaves_Autumn"
    },
    {
      "x": 2,
      "y": 20,
      "z": -12,
      "name": "Plant_Leaves_Autumn"
    },
    {
      "x": 2,
      "y": 21,
      "z": -12,
      "name": "Plant_Leaves_Autumn"
    },
    {
      "x": 2,
      "y": 19,
      "z": -11,
      "name": "Plant_Leaves_Autumn"
    },
    {
      "x": 2,
      "y": 20,
      "z": -11,
      "name": "Plant_Leaves_Autumn"
    },
    {
      "x": 2,
      "y": 21,
      "z": -11,
      "name": "Plant_Leaves_Autumn"
    },
    {
      "x": 2,
      "y": 19,
      "z": -10,
      "name": "Plant_Leaves_Autumn"
    },
    {
      "x": 2,
      "y": 20,
      "z": -10,
      "name": "Plant_Leaves_Autumn"
    },
    {
      "x": 2,
      "y": 21,
      "z": -10,
      "name": "Plant_Leaves_Autumn"
    },
    {
      "x": 2,
      "y": 22,
      "z": -10,
      "name": "Plant_Leaves_Autumn"
    },
    {
      "x": 2,
      "y": 20,
      "z": -9,
      "name": "Plant_Leaves_Autumn"
    },
    {
      "x": 2,
      "y": 21,
      "z": -9,
      "name": "Plant_Leaves_Autumn"
    },
    {
      "x": 2,
      "y": 15,
      "z": -8,
      "name": "Plant_Leaves_Autumn"
    },
    {
      "x": 2,
      "y": 20,
      "z": -8,
      "name": "Plant_Leaves_Autumn"
    },
    {
      "x": 2,
      "y": 21,
      "z": -8,
      "name": "Plant_Leaves_Autumn"
    },
    {
      "x": 2,
      "y": 22,
      "z": -8,
      "name": "Plant_Leaves_Autumn"
    },
    {
      "x": 2,
      "y": 25,
      "z": -8,
      "name": "Plant_Leaves_Autumn"
    },
    {
      "x": 2,
      "y": 15,
      "z": -7,
      "name": "Plant_Leaves_Autumn"
    },
    {
      "x": 2,
      "y": 19,
      "z": -7,
      "name": "Plant_Leaves_Autumn"
    },
    {
      "x": 2,
      "y": 20,
      "z": -7,
      "name": "Plant_Leaves_Autumn"
    },
    {
      "x": 2,
      "y": 25,
      "z": -7,
      "name": "Plant_Leaves_Autumn"
    },
    {
      "x": 2,
      "y": 25,
      "z": -6,
      "name": "Plant_Leaves_Autumn"
    },
    {
      "x": 2,
      "y": 28,
      "z": -6,
      "name": "Plant_Leaves_Autumn"
    },
    {
      "x": 2,
      "y": 29,
      "z": -6,
      "name": "Plant_Leaves_Autumn"
    },
    {
      "x": 2,
      "y": 29,
      "z": -5,
      "name": "Plant_Leaves_Autumn"
    },
    {
      "x": 2,
      "y": 30,
      "z": -5,
      "name": "Plant_Leaves_Autumn"
    },
    {
      "x": 2,
      "y": 29,
      "z": -4,
      "name": "Plant_Leaves_Autumn"
    },
    {
      "x": 2,
      "y": 14,
      "z": -2,
      "name": "Wood_Oak_Roots"
    },
    {
      "x": 2,
      "y": 15,
      "z": -2,
      "name": "Wood_Oak_Trunk_Full"
    },
    {
      "x": 2,
      "y": 22,
      "z": -2,
      "name": "Plant_Leaves_Autumn"
    },
    {
      "x": 2,
      "y": 25,
      "z": -2,
      "name": "Wood_Oak_Trunk_Full"
    },
    {
      "x": 2,
      "y": 14,
      "z": -1,
      "name": "Wood_Oak_Trunk_Full"
    },
    {
      "x": 2,
      "y": 15,
      "z": -1,
      "name": "Wood_Oak_Trunk"
    },
    {
      "x": 2,
      "y": 16,
      "z": -1,
      "name": "Wood_Oak_Trunk_Full"
    },
    {
      "x": 2,
      "y": 21,
      "z": -1,
      "name": "Wood_Oak_Branch_Corner",
      "rotation": 1
    },
    {
      "x": 2,
      "y": 22,
      "z": -1,
      "name": "Plant_Leaves_Autumn"
    },
    {
      "x": 2,
      "y": 25,
      "z": -1,
      "name": "Wood_Oak_Trunk_Full"
    },
    {
      "x": 2,
      "y": 18,
      "z": 0,
      "name": "Wood_Oak_Branch_Short",
      "rotation": 1
    },
    {
      "x": 2,
      "y": 29,
      "z": 0,
      "name": "Plant_Leaves_Autumn"
    },
    {
      "x": 2,
      "y": 30,
      "z": 0,
      "name": "Plant_Leaves_Autumn"
    },
    {
      "x": 2,
      "y": 29,
      "z": 1,
      "name": "Plant_Leaves_Autumn"
    },
    {
      "x": 2,
      "y": 30,
      "z": 1,
      "name": "Plant_Leaves_Autumn"
    },
    {
      "x": 2,
      "y": 19,
      "z": 4,
      "name": "Wood_Oak_Roots"
    },
    {
      "x": 2,
      "y": 20,
      "z": 4,
      "name": "Wood_Oak_Trunk_Full"
    },
    {
      "x": 2,
      "y": 19,
      "z": 5,
      "name": "Wood_Oak_Roots"
    },
    {
      "x": 2,
      "y": 20,
      "z": 5,
      "name": "Wood_Oak_Trunk_Full"
    },
    {
      "x": 2,
      "y": 20,
      "z": 6,
      "name": "Wood_Oak_Trunk_Full"
    },
    {
      "x": 2,
      "y": 23,
      "z": 6,
      "name": "Plant_Leaves_Autumn"
    },
    {
      "x": 2,
      "y": 20,
      "z": 7,
      "name": "Wood_Oak_Branch_Long",
      "rotation": 4
    },
    {
      "x": 2,
      "y": 20,
      "z": 8,
      "name": "Plant_Leaves_Autumn"
    },
    {
      "x": 2,
      "y": 21,
      "z": 8,
      "name": "Plant_Leaves_Autumn"
    },
    {
      "x": 2,
      "y": 20,
      "z": 9,
      "name": "Plant_Leaves_Autumn"
    },
    {
      "x": 2,
      "y": 21,
      "z": 9,
      "name": "Plant_Leaves_Autumn"
    },
    {
      "x": 2,
      "y": 21,
      "z": 10,
      "name": "Plant_Leaves_Autumn"
    },
    {
      "x": 3,
      "y": 20,
      "z": -13,
      "name": "Plant_Leaves_Autumn"
    },
    {
      "x": 3,
      "y": 21,
      "z": -13,
      "name": "Plant_Leaves_Autumn"
    },
    {
      "x": 3,
      "y": 19,
      "z": -11,
      "name": "Plant_Leaves_Autumn"
    },
    {
      "x": 3,
      "y": 20,
      "z": -11,
      "name": "Plant_Leaves_Autumn"
    },
    {
      "x": 3,
      "y": 21,
      "z": -11,
      "name": "Plant_Leaves_Autumn"
    },
    {
      "x": 3,
      "y": 22,
      "z": -11,
      "name": "Plant_Leaves_Autumn"
    },
    {
      "x": 3,
      "y": 19,
      "z": -10,
      "name": "Plant_Leaves_Autumn"
    },
    {
      "x": 3,
      "y": 20,
      "z": -10,
      "name": "Plant_Leaves_Autumn"
    },
    {
      "x": 3,
      "y": 21,
      "z": -10,
      "name": "Plant_Leaves_Autumn"
    },
    {
      "x": 3,
      "y": 20,
      "z": -9,
      "name": "Plant_Leaves_Autumn"
    },
    {
      "x": 3,
      "y": 15,
      "z": -8,
      "name": "Plant_Leaves_Autumn"
    },
    {
      "x": 3,
      "y": 20,
      "z": -8,
      "name": "Plant_Leaves_Autumn"
    },
    {
      "x": 3,
      "y": 14,
      "z": -7,
      "name": "Plant_Leaves_Autumn"
    },
    {
      "x": 3,
      "y": 15,
      "z": -7,
      "name": "Plant_Leaves_Autumn"
    },
    {
      "x": 3,
      "y": 16,
      "z": -7,
      "name": "Plant_Leaves_Autumn"
    },
    {
      "x": 3,
      "y": 20,
      "z": -7,
      "name": "Plant_Leaves_Autumn"
    },
    {
      "x": 3,
      "y": 25,
      "z": -7,
      "name": "Plant_Leaves_Autumn"
    },
    {
      "x": 3,
      "y": 15,
      "z": -6,
      "name": "Plant_Leaves_Autumn"
    },
    {
      "x": 3,
      "y": 16,
      "z": -6,
      "name": "Plant_Leaves_Autumn"
    },
    {
      "x": 3,
      "y": 14,
      "z": -5,
      "name": "Wood_Oak_Roots"
    },
    {
      "x": 3,
      "y": 15,
      "z": -5,
      "name": "Wood_Oak_Trunk_Full"
    },
    {
      "x": 3,
      "y": 26,
      "z": -5,
      "name": "Plant_Leaves_Autumn"
    },
    {
      "x": 3,
      "y": 29,
      "z": -5,
      "name": "Plant_Leaves_Autumn"
    },
    {
      "x": 3,
      "y": 30,
      "z": -5,
      "name": "Plant_Leaves_Autumn"
    },
    {
      "x": 3,
      "y": 14,
      "z": -4,
      "name": "Wood_Oak_Roots"
    },
    {
      "x": 3,
      "y": 15,
      "z": -4,
      "name": "Wood_Oak_Trunk_Full"
    },
    {
      "x": 3,
      "y": 27,
      "z": -4,
      "name": "Plant_Leaves_Autumn"
    },
    {
      "x": 3,
      "y": 15,
      "z": -3,
      "name": "Wood_Oak_Trunk_Full"
    },
    {
      "x": 3,
      "y": 27,
      "z": -3,
      "name": "Plant_Leaves_Autumn"
    },
    {
      "x": 3,
      "y": 28,
      "z": -3,
      "name": "Plant_Leaves_Autumn"
    },
    {
      "x": 3,
      "y": 15,
      "z": -2,
      "name": "Wood_Oak_Trunk_Full"
    },
    {
      "x": 3,
      "y": 22,
      "z": -2,
      "name": "Plant_Leaves_Autumn"
    },
    {
      "x": 3,
      "y": 24,
      "z": -2,
      "name": "Wood_Oak_Roots"
    },
    {
      "x": 3,
      "y": 25,
      "z": -2,
      "name": "Wood_Oak_Trunk_Full"
    },
    {
      "x": 3,
      "y": 26,
      "z": -2,
      "name": "Wood_Oak_Trunk_Full"
    },
    {
      "x": 3,
      "y": 27,
      "z": -2,
      "name": "Plant_Leaves_Autumn"
    },
    {
      "x": 3,
      "y": 30,
      "z": -2,
      "name": "Plant_Leaves_Autumn"
    },
    {
      "x": 3,
      "y": 16,
      "z": -1,
      "name": "Wood_Oak_Trunk_Full"
    },
    {
      "x": 3,
      "y": 17,
      "z": -1,
      "name": "Wood_Oak_Trunk_Full"
    },
    {
      "x": 3,
      "y": 22,
      "z": -1,
      "name": "Plant_Leaves_Autumn"
    },
    {
      "x": 3,
      "y": 27,
      "z": -1,
      "name": "Plant_Leaves_Autumn"
    },
    {
      "x": 3,
      "y": 30,
      "z": -1,
      "name": "Plant_Leaves_Autumn"
    },
    {
      "x": 3,
      "y": 30,
      "z": 0,
      "name": "Plant_Leaves_Autumn"
    },
    {
      "x": 3,
      "y": 27,
      "z": 1,
      "name": "Plant_Leaves_Autumn"
    },
    {
      "x": 3,
      "y": 29,
      "z": 1,
      "name": "Plant_Leaves_Autumn"
    },
    {
      "x": 3,
      "y": 26,
      "z": 2,
      "name": "Plant_Leaves_Autumn"
    },
    {
      "x": 3,
      "y": 20,
      "z": 3,
      "name": "Plant_Leaves_Autumn"
    },
    {
      "x": 3,
      "y": 25,
      "z": 3,
      "name": "Plant_Leaves_Autumn"
    },
    {
      "x": 3,
      "y": 25,
      "z": 4,
      "name": "Plant_Leaves_Autumn"
    },
    {
      "x": 3,
      "y": 20,
      "z": 5,
      "name": "Wood_Oak_Branch_Long",
      "rotation": 5
    },
    {
      "x": 3,
      "y": 19,
      "z": 7,
      "name": "Plant_Leaves_Autumn"
    },
    {
      "x": 3,
      "y": 20,
      "z": 7,
      "name": "Plant_Leaves_Autumn"
    },
    {
      "x": 3,
      "y": 19,
      "z": 8,
      "name": "Plant_Leaves_Autumn"
    },
    {
      "x": 3,
      "y": 20,
      "z": 8,
      "name": "Plant_Leaves_Autumn"
    },
    {
      "x": 3,
      "y": 21,
      "z": 8,
      "name": "Plant_Leaves_Autumn"
    },
    {
      "x": 3,
      "y": 20,
      "z": 9,
      "name": "Plant_Leaves_Autumn"
    },
    {
      "x": 3,
      "y": 21,
      "z": 9,
      "name": "Plant_Leaves_Autumn"
    },
    {
      "x": 3,
      "y": 20,
      "z": 10,
      "name": "Plant_Leaves_Autumn"
    },
    {
      "x": 4,
      "y": 20,
      "z": -11,
      "name": "Plant_Leaves_Autumn"
    },
    {
      "x": 4,
      "y": 20,
      "z": -10,
      "name": "Plant_Leaves_Autumn"
    },
    {
      "x": 4,
      "y": 21,
      "z": -10,
      "name": "Plant_Leaves_Autumn"
    },
    {
      "x": 4,
      "y": 15,
      "z": -9,
      "name": "Plant_Leaves_Autumn"
    },
    {
      "x": 4,
      "y": 15,
      "z": -8,
      "name": "Plant_Leaves_Autumn"
    },
    {
      "x": 4,
      "y": 15,
      "z": -7,
      "name": "Plant_Leaves_Autumn"
    },
    {
      "x": 4,
      "y": 16,
      "z": -7,
      "name": "Plant_Leaves_Autumn"
    },
    {
      "x": 4,
      "y": 14,
      "z": -6,
      "name": "Plant_Leaves_Autumn"
    },
    {
      "x": 4,
      "y": 15,
      "z": -6,
      "name": "Wood_Oak_Branch_Long",
      "rotation": 4
    },
    {
      "x": 4,
      "y": 15,
      "z": -5,
      "name": "Wood_Oak_Trunk_Full"
    },
    {
      "x": 4,
      "y": 26,
      "z": -5,
      "name": "Plant_Leaves_Autumn"
    },
    {
      "x": 4,
      "y": 26,
      "z": -4,
      "name": "Plant_Leaves_Autumn"
    },
    {
      "x": 4,
      "y": 27,
      "z": -4,
      "name": "Plant_Leaves_Autumn"
    },
    {
      "x": 4,
      "y": 27,
      "z": -3,
      "name": "Plant_Leaves_Autumn"
    },
    {
      "x": 4,
      "y": 17,
      "z": -2,
      "name": "Wood_Oak_Trunk_Full"
    },
    {
      "x": 4,
      "y": 18,
      "z": -2,
      "name": "Wood_Oak_Trunk_Full"
    },
    {
      "x": 4,
      "y": 25,
      "z": -2,
      "name": "Wood_Oak_Roots"
    },
    {
      "x": 4,
      "y": 26,
      "z": -2,
      "name": "Wood_Oak_Trunk_Full"
    },
    {
      "x": 4,
      "y": 27,
      "z": -2,
      "name": "Plant_Leaves_Autumn"
    },
    {
      "x": 4,
      "y": 17,
      "z": -1,
      "name": "Wood_Oak_Trunk_Full"
    },
    {
      "x": 4,
      "y": 26,
      "z": -1,
      "name": "Wood_Oak_Branch_Long",
      "rotation": 4
    },
    {
      "x": 4,
      "y": 27,
      "z": -1,
      "name": "Plant_Leaves_Autumn"
    },
    {
      "x": 4,
      "y": 26,
      "z": 0,
      "name": "Wood_Oak_Branch_Long",
      "rotation": 4
    },
    {
      "x": 4,
      "y": 27,
      "z": 0,
      "name": "Plant_Leaves_Autumn"
    },
    {
      "x": 4,
      "y": 25,
      "z": 1,
      "name": "Plant_Leaves_Autumn"
    },
    {
      "x": 4,
      "y": 26,
      "z": 1,
      "name": "Plant_Leaves_Autumn"
    },
    {
      "x": 4,
      "y": 27,
      "z": 1,
      "name": "Plant_Leaves_Autumn"
    },
    {
      "x": 4,
      "y": 26,
      "z": 2,
      "name": "Plant_Leaves_Autumn"
    },
    {
      "x": 4,
      "y": 27,
      "z": 2,
      "name": "Plant_Leaves_Autumn"
    },
    {
      "x": 4,
      "y": 20,
      "z": 3,
      "name": "Plant_Leaves_Autumn"
    },
    {
      "x": 4,
      "y": 25,
      "z": 3,
      "name": "Plant_Leaves_Autumn"
    },
    {
      "x": 4,
      "y": 26,
      "z": 3,
      "name": "Plant_Leaves_Autumn"
    },
    {
      "x": 4,
      "y": 19,
      "z": 4,
      "name": "Plant_Leaves_Autumn"
    },
    {
      "x": 4,
      "y": 20,
      "z": 4,
      "name": "Plant_Leaves_Autumn"
    },
    {
      "x": 4,
      "y": 21,
      "z": 4,
      "name": "Plant_Leaves_Autumn"
    },
    {
      "x": 4,
      "y": 25,
      "z": 4,
      "name": "Plant_Leaves_Autumn"
    },
    {
      "x": 4,
      "y": 19,
      "z": 5,
      "name": "Plant_Leaves_Autumn"
    },
    {
      "x": 4,
      "y": 20,
      "z": 5,
      "name": "Wood_Oak_Branch_Long",
      "rotation": 5
    },
    {
      "x": 4,
      "y": 25,
      "z": 5,
      "name": "Plant_Leaves_Autumn"
    },
    {
      "x": 4,
      "y": 20,
      "z": 6,
      "name": "Plant_Leaves_Autumn"
    },
    {
      "x": 4,
      "y": 21,
      "z": 6,
      "name": "Plant_Leaves_Autumn"
    },
    {
      "x": 4,
      "y": 19,
      "z": 7,
      "name": "Plant_Leaves_Autumn"
    },
    {
      "x": 4,
      "y": 20,
      "z": 8,
      "name": "Plant_Leaves_Autumn"
    },
    {
      "x": 4,
      "y": 21,
      "z": 8,
      "name": "Plant_Leaves_Autumn"
    },
    {
      "x": 4,
      "y": 20,
      "z": 9,
      "name": "Plant_Leaves_Autumn"
    },
    {
      "x": 4,
      "y": 20,
      "z": 10,
      "name": "Plant_Leaves_Autumn"
    },
    {
      "x": 5,
      "y": 15,
      "z": -7,
      "name": "Plant_Leaves_Autumn"
    },
    {
      "x": 5,
      "y": 16,
      "z": -7,
      "name": "Plant_Leaves_Autumn"
    },
    {
      "x": 5,
      "y": 15,
      "z": -6,
      "name": "Plant_Leaves_Autumn"
    },
    {
      "x": 5,
      "y": 16,
      "z": -6,
      "name": "Plant_Leaves_Autumn"
    },
    {
      "x": 5,
      "y": 18,
      "z": -6,
      "name": "Plant_Leaves_Autumn"
    },
    {
      "x": 5,
      "y": 15,
      "z": -5,
      "name": "Plant_Leaves_Autumn"
    },
    {
      "x": 5,
      "y": 16,
      "z": -5,
      "name": "Plant_Leaves_Autumn"
    },
    {
      "x": 5,
      "y": 18,
      "z": -5,
      "name": "Plant_Leaves_Autumn"
    },
    {
      "x": 5,
      "y": 19,
      "z": -5,
      "name": "Plant_Leaves_Autumn"
    },
    {
      "x": 5,
      "y": 26,
      "z": -5,
      "name": "Plant_Leaves_Autumn"
    },
    {
      "x": 5,
      "y": 18,
      "z": -4,
      "name": "Wood_Oak_Branch_Long",
      "rotation": 4
    },
    {
      "x": 5,
      "y": 26,
      "z": -4,
      "name": "Plant_Leaves_Autumn"
    },
    {
      "x": 5,
      "y": 18,
      "z": -3,
      "name": "Wood_Oak_Branch_Long",
      "rotation": 4
    },
    {
      "x": 5,
      "y": 27,
      "z": -3,
      "name": "Plant_Leaves_Autumn"
    },
    {
      "x": 5,
      "y": 18,
      "z": -2,
      "name": "Wood_Oak_Trunk_Full"
    },
    {
      "x": 5,
      "y": 26,
      "z": -2,
      "name": "Wood_Oak_Branch_Corner",
      "rotation": 1
    },
    {
      "x": 5,
      "y": 26,
      "z": -1,
      "name": "Plant_Leaves_Autumn"
    },
    {
      "x": 5,
      "y": 27,
      "z": -1,
      "name": "Plant_Leaves_Autumn"
    },
    {
      "x": 5,
      "y": 26,
      "z": 0,
      "name": "Plant_Leaves_Autumn"
    },
    {
      "x": 5,
      "y": 25,
      "z": 1,
      "name": "Plant_Leaves_Autumn"
    },
    {
      "x": 5,
      "y": 26,
      "z": 1,
      "name": "Plant_Leaves_Autumn"
    },
    {
      "x": 5,
      "y": 25,
      "z": 2,
      "name": "Plant_Leaves_Autumn"
    },
    {
      "x": 5,
      "y": 26,
      "z": 2,
      "name": "Plant_Leaves_Autumn"
    },
    {
      "x": 5,
      "y": 20,
      "z": 3,
      "name": "Plant_Leaves_Autumn"
    },
    {
      "x": 5,
      "y": 21,
      "z": 3,
      "name": "Plant_Leaves_Autumn"
    },
    {
      "x": 5,
      "y": 22,
      "z": 3,
      "name": "Plant_Leaves_Autumn"
    },
    {
      "x": 5,
      "y": 25,
      "z": 3,
      "name": "Plant_Leaves_Autumn"
    },
    {
      "x": 5,
      "y": 20,
      "z": 4,
      "name": "Plant_Leaves_Autumn"
    },
    {
      "x": 5,
      "y": 21,
      "z": 4,
      "name": "Plant_Leaves_Autumn"
    },
    {
      "x": 5,
      "y": 25,
      "z": 4,
      "name": "Plant_Leaves_Autumn"
    },
    {
      "x": 5,
      "y": 19,
      "z": 5,
      "name": "Plant_Leaves_Autumn"
    },
    {
      "x": 5,
      "y": 20,
      "z": 5,
      "name": "Plant_Leaves_Autumn"
    },
    {
      "x": 5,
      "y": 21,
      "z": 5,
      "name": "Plant_Leaves_Autumn"
    },
    {
      "x": 5,
      "y": 20,
      "z": 6,
      "name": "Plant_Leaves_Autumn"
    },
    {
      "x": 5,
      "y": 20,
      "z": 7,
      "name": "Plant_Leaves_Autumn"
    },
    {
      "x": 5,
      "y": 21,
      "z": 7,
      "name": "Plant_Leaves_Autumn"
    },
    {
      "x": 5,
      "y": 21,
      "z": 8,
      "name": "Plant_Leaves_Autumn"
    },
    {
      "x": 6,
      "y": 18,
      "z": -6,
      "name": "Plant_Leaves_Autumn"
    },
    {
      "x": 6,
      "y": 16,
      "z": -5,
      "name": "Plant_Leaves_Autumn"
    },
    {
      "x": 6,
      "y": 18,
      "z": -5,
      "name": "Plant_Leaves_Autumn"
    },
    {
      "x": 6,
      "y": 19,
      "z": -5,
      "name": "Plant_Leaves_Autumn"
    },
    {
      "x": 6,
      "y": 26,
      "z": -4,
      "name": "Plant_Leaves_Autumn"
    },
    {
      "x": 6,
      "y": 27,
      "z": -4,
      "name": "Plant_Leaves_Autumn"
    },
    {
      "x": 6,
      "y": 19,
      "z": -3,
      "name": "Plant_Leaves_Autumn"
    },
    {
      "x": 6,
      "y": 26,
      "z": -3,
      "name": "Plant_Leaves_Autumn"
    },
    {
      "x": 6,
      "y": 27,
      "z": -3,
      "name": "Plant_Leaves_Autumn"
    },
    {
      "x": 6,
      "y": 18,
      "z": -2,
      "name": "Wood_Oak_Trunk_Full"
    },
    {
      "x": 6,
      "y": 19,
      "z": -2,
      "name": "Wood_Oak_Trunk_Full"
    },
    {
      "x": 6,
      "y": 20,
      "z": -2,
      "name": "Plant_Leaves_Autumn"
    },
    {
      "x": 6,
      "y": 26,
      "z": -2,
      "name": "Plant_Leaves_Autumn"
    },
    {
      "x": 6,
      "y": 27,
      "z": -2,
      "name": "Plant_Leaves_Autumn"
    },
    {
      "x": 6,
      "y": 19,
      "z": -1,
      "name": "Plant_Leaves_Autumn"
    },
    {
      "x": 6,
      "y": 23,
      "z": -1,
      "name": "Plant_Leaves_Autumn"
    },
    {
      "x": 6,
      "y": 24,
      "z": -1,
      "name": "Plant_Leaves_Autumn"
    },
    {
      "x": 6,
      "y": 26,
      "z": -1,
      "name": "Plant_Leaves_Autumn"
    },
    {
      "x": 6,
      "y": 27,
      "z": -1,
      "name": "Plant_Leaves_Autumn"
    },
    {
      "x": 6,
      "y": 25,
      "z": 0,
      "name": "Plant_Leaves_Autumn"
    },
    {
      "x": 6,
      "y": 26,
      "z": 0,
      "name": "Plant_Leaves_Autumn"
    },
    {
      "x": 6,
      "y": 24,
      "z": 1,
      "name": "Plant_Leaves_Autumn"
    },
    {
      "x": 6,
      "y": 25,
      "z": 1,
      "name": "Plant_Leaves_Autumn"
    },
    {
      "x": 6,
      "y": 26,
      "z": 1,
      "name": "Plant_Leaves_Autumn"
    },
    {
      "x": 6,
      "y": 25,
      "z": 2,
      "name": "Plant_Leaves_Autumn"
    },
    {
      "x": 6,
      "y": 26,
      "z": 2,
      "name": "Plant_Leaves_Autumn"
    },
    {
      "x": 6,
      "y": 20,
      "z": 3,
      "name": "Plant_Leaves_Autumn"
    },
    {
      "x": 6,
      "y": 22,
      "z": 3,
      "name": "Plant_Leaves_Autumn"
    },
    {
      "x": 6,
      "y": 25,
      "z": 3,
      "name": "Plant_Leaves_Autumn"
    },
    {
      "x": 6,
      "y": 20,
      "z": 4,
      "name": "Plant_Leaves_Autumn"
    },
    {
      "x": 6,
      "y": 21,
      "z": 4,
      "name": "Plant_Leaves_Autumn"
    },
    {
      "x": 6,
      "y": 22,
      "z": 4,
      "name": "Plant_Leaves_Autumn"
    },
    {
      "x": 6,
      "y": 20,
      "z": 5,
      "name": "Plant_Leaves_Autumn"
    },
    {
      "x": 6,
      "y": 21,
      "z": 5,
      "name": "Plant_Leaves_Autumn"
    },
    {
      "x": 6,
      "y": 20,
      "z": 6,
      "name": "Plant_Leaves_Autumn"
    },
    {
      "x": 6,
      "y": 21,
      "z": 6,
      "name": "Plant_Leaves_Autumn"
    },
    {
      "x": 6,
      "y": 22,
      "z": 6,
      "name": "Plant_Leaves_Autumn"
    },
    {
      "x": 6,
      "y": 22,
      "z": 7,
      "name": "Plant_Leaves_Autumn"
    },
    {
      "x": 7,
      "y": 18,
      "z": -6,
      "name": "Plant_Leaves_Autumn"
    },
    {
      "x": 7,
      "y": 18,
      "z": -5,
      "name": "Plant_Leaves_Autumn"
    },
    {
      "x": 7,
      "y": 18,
      "z": -4,
      "name": "Plant_Leaves_Autumn"
    },
    {
      "x": 7,
      "y": 19,
      "z": -4,
      "name": "Plant_Leaves_Autumn"
    },
    {
      "x": 7,
      "y": 24,
      "z": -4,
      "name": "Plant_Leaves_Autumn"
    },
    {
      "x": 7,
      "y": 25,
      "z": -4,
      "name": "Plant_Leaves_Autumn"
    },
    {
      "x": 7,
      "y": 19,
      "z": -3,
      "name": "Plant_Leaves_Autumn"
    },
    {
      "x": 7,
      "y": 20,
      "z": -3,
      "name": "Plant_Leaves_Autumn"
    },
    {
      "x": 7,
      "y": 24,
      "z": -3,
      "name": "Plant_Leaves_Autumn"
    },
    {
      "x": 7,
      "y": 25,
      "z": -3,
      "name": "Plant_Leaves_Autumn"
    },
    {
      "x": 7,
      "y": 26,
      "z": -3,
      "name": "Plant_Leaves_Autumn"
    },
    {
      "x": 7,
      "y": 18,
      "z": -2,
      "name": "Plant_Leaves_Autumn"
    },
    {
      "x": 7,
      "y": 19,
      "z": -2,
      "name": "Wood_Oak_Branch_Long",
      "rotation": 5
    },
    {
      "x": 7,
      "y": 20,
      "z": -2,
      "name": "Plant_Leaves_Autumn"
    },
    {
      "x": 7,
      "y": 24,
      "z": -2,
      "name": "Plant_Leaves_Autumn"
    },
    {
      "x": 7,
      "y": 25,
      "z": -2,
      "name": "Plant_Leaves_Autumn"
    },
    {
      "x": 7,
      "y": 26,
      "z": -2,
      "name": "Plant_Leaves_Autumn"
    },
    {
      "x": 7,
      "y": 19,
      "z": -1,
      "name": "Plant_Leaves_Autumn"
    },
    {
      "x": 7,
      "y": 23,
      "z": -1,
      "name": "Plant_Leaves_Autumn"
    },
    {
      "x": 7,
      "y": 24,
      "z": -1,
      "name": "Plant_Leaves_Autumn"
    },
    {
      "x": 7,
      "y": 25,
      "z": -1,
      "name": "Plant_Leaves_Autumn"
    },
    {
      "x": 7,
      "y": 26,
      "z": -1,
      "name": "Plant_Leaves_Autumn"
    },
    {
      "x": 7,
      "y": 25,
      "z": 0,
      "name": "Plant_Leaves_Autumn"
    },
    {
      "x": 7,
      "y": 26,
      "z": 0,
      "name": "Plant_Leaves_Autumn"
    },
    {
      "x": 7,
      "y": 19,
      "z": 1,
      "name": "Plant_Leaves_Autumn"
    },
    {
      "x": 7,
      "y": 20,
      "z": 4,
      "name": "Plant_Leaves_Autumn"
    },
    {
      "x": 7,
      "y": 21,
      "z": 4,
      "name": "Plant_Leaves_Autumn"
    },
    {
      "x": 7,
      "y": 22,
      "z": 4,
      "name": "Plant_Leaves_Autumn"
    },
    {
      "x": 8,
      "y": 18,
      "z": -6,
      "name": "Plant_Leaves_Autumn"
    },
    {
      "x": 8,
      "y": 18,
      "z": -5,
      "name": "Plant_Leaves_Autumn"
    },
    {
      "x": 8,
      "y": 19,
      "z": -4,
      "name": "Plant_Leaves_Autumn"
    },
    {
      "x": 8,
      "y": 20,
      "z": -4,
      "name": "Plant_Leaves_Autumn"
    },
    {
      "x": 8,
      "y": 19,
      "z": -3,
      "name": "Plant_Leaves_Autumn"
    },
    {
      "x": 8,
      "y": 25,
      "z": -3,
      "name": "Plant_Leaves_Autumn"
    },
    {
      "x": 8,
      "y": 18,
      "z": -2,
      "name": "Plant_Leaves_Autumn"
    },
    {
      "x": 8,
      "y": 19,
      "z": -2,
      "name": "Plant_Leaves_Autumn"
    },
    {
      "x": 8,
      "y": 20,
      "z": -2,
      "name": "Plant_Leaves_Autumn"
    },
    {
      "x": 8,
      "y": 25,
      "z": -2,
      "name": "Plant_Leaves_Autumn"
    },
    {
      "x": 8,
      "y": 18,
      "z": -1,
      "name": "Plant_Leaves_Autumn"
    },
    {
      "x": 8,
      "y": 19,
      "z": -1,
      "name": "Plant_Leaves_Autumn"
    },
    {
      "x": 8,
      "y": 20,
      "z": -1,
      "name": "Plant_Leaves_Autumn"
    },
    {
      "x": 8,
      "y": 24,
      "z": -1,
      "name": "Plant_Leaves_Autumn"
    },
    {
      "x": 8,
      "y": 25,
      "z": -1,
      "name": "Plant_Leaves_Autumn"
    },
    {
      "x": 8,
      "y": 26,
      "z": -1,
      "name": "Plant_Leaves_Autumn"
    },
    {
      "x": 8,
      "y": 19,
      "z": 0,
      "name": "Plant_Leaves_Autumn"
    },
    {
      "x": 8,
      "y": 19,
      "z": 1,
      "name": "Plant_Leaves_Autumn"
    },
    {
      "x": 8,
      "y": 19,
      "z": 2,
      "name": "Plant_Leaves_Autumn"
    },
    {
      "x": 9,
      "y": 18,
      "z": -6,
      "name": "Plant_Leaves_Autumn"
    },
    {
      "x": 9,
      "y": 18,
      "z": -5,
      "name": "Plant_Leaves_Autumn"
    },
    {
      "x": 9,
      "y": 18,
      "z": -4,
      "name": "Plant_Leaves_Autumn"
    },
    {
      "x": 9,
      "y": 19,
      "z": -4,
      "name": "Plant_Leaves_Autumn"
    },
    {
      "x": 9,
      "y": 20,
      "z": -4,
      "name": "Plant_Leaves_Autumn"
    },
    {
      "x": 9,
      "y": 18,
      "z": -3,
      "name": "Plant_Leaves_Autumn"
    },
    {
      "x": 9,
      "y": 18,
      "z": -2,
      "name": "Plant_Leaves_Autumn"
    },
    {
      "x": 9,
      "y": 19,
      "z": -2,
      "name": "Plant_Leaves_Autumn"
    },
    {
      "x": 9,
      "y": 18,
      "z": -1,
      "name": "Plant_Leaves_Autumn"
    },
    {
      "x": 9,
      "y": 18,
      "z": 0,
      "name": "Plant_Leaves_Autumn"
    },
    {
      "x": 10,
      "y": 18,
      "z": -5,
      "name": "Plant_Leaves_Autumn"
    },
    {
      "x": 10,
      "y": 18,
      "z": -4,
      "name": "Plant_Leaves_Autumn"
    },
    {
      "x": 10,
      "y": 18,
      "z": -3,
      "name": "Plant_Leaves_Autumn"
    },
    {
      "x": 10,
      "y": 18,
      "z": -2,
      "name": "Plant_Leaves_Autumn"
    },
    {
      "x": 10,
      "y": 19,
      "z": -2,
      "name": "Plant_Leaves_Autumn"
    },
    {
      "x": 10,
      "y": 18,
      "z": 0,
      "name": "Plant_Leaves_Autumn"
    },
    {
      "x": 11,
      "y": 18,
      "z": -2,
      "name": "Plant_Leaves_Autumn"
    }
  ]
}