{
  "version": 8,
  "blockIdVersion": 8,
  "anchorX": 0,
  "anchorY": 9,
  "anchorZ": -1,
  "blocks": [
    {
      "x": -3,
      "y": 14,
      "z": -1,
      "name": "Plant_Vine_Wall",
      "rotation": 3
    },
    {
      "x": -3,
      "y": 13,
      "z": 0,
      "name": "Plant_Vine_Wall",
      "rotation": 3
    },
    {
      "x": -3,
      "y": 14,
      "z": 0,
      "name": "Plant_Vine",
      "rotation": 3
    },
    {
      "x": -2,
      "y": 4,
      "z": -3,
      "name": "Rock_Quartzite"
    },
    {
      "x": -2,
      "y": 5,
      "z": -3,
      "name": "Rock_Quartzite"
    },
    {
      "x": -2,
      "y": 6,
      "z": -3,
      "name": "Rock_Quartzite"
    },
    {
      "x": -2,
      "y": 7,
      "z": -3,
      "name": "Rock_Quartzite"
    },
    {
      "x": -2,
      "y": 8,
      "z": -3,
      "name": "Rock_Quartzite"
    },
    {
      "x": -2,
      "y": 9,
      "z": -3,
      "name": "Rock_Quartzite_Brick"
    },
    {
      "x": -2,
      "y": 10,
      "z": -3,
      "name": "Rock_Quartzite_Brick"
    },
    {
      "x": -2,
      "y": 11,
      "z": -3,
      "name": "Rock_Quartzite_Brick"
    },
    {
      "x": -2,
      "y": 12,
      "z": -3,
      "name": "Rock_Quartzite_Brick"
    },
    {
      "x": -2,
      "y": 4,
      "z": -2,
      "name": "Rock_Quartzite"
    },
    {
      "x": -2,
      "y": 5,
      "z": -2,
      "name": "Rock_Quartzite"
    },
    {
      "x": -2,
      "y": 6,
      "z": -2,
      "name": "Rock_Quartzite"
    },
    {
      "x": -2,
      "y": 7,
      "z": -2,
      "name": "Rock_Quartzite"
    },
    {
      "x": -2,
      "y": 8,
      "z": -2,
      "name": "Rock_Quartzite"
    },
    {
      "x": -2,
      "y": 9,
      "z": -2,
      "name": "Rock_Quartzite"
    },
    {
      "x": -2,
      "y": 10,
      "z": -2,
      "name": "Rock_Quartzite"
    },
    {
      "x": -2,
      "y": 11,
      "z": -2,
      "name": "Rock_Quartzite_Brick"
    },
    {
      "x": -2,
      "y": 12,
      "z": -2,
      "name": "Rock_Quartzite_Brick"
    },
    {
      "x": -2,
      "y": 13,
      "z": -2,
      "name": "Rock_Quartzite_Brick"
    },
    {
      "x": -2,
      "y": 14,
      "z": -2,
      "name": "Rock_Quartzite_Brick"
    },
    {
      "x": -2,
      "y": 15,
      "z": -2,
      "name": "Rock_Quartzite"
    },
    {
      "x": -2,
      "y": 16,
      "z": -2,
      "name": "Plant_Vine",
      "rotation": 3
    },
    {
      "x": -2,
      "y": 4,
      "z": -1,
      "name": "Rock_Quartzite"
    },
    {
      "x": -2,
      "y": 5,
      "z": -1,
      "name": "Rock_Quartzite"
    },
    {
      "x": -2,
      "y": 6,
      "z": -1,
      "name": "Rock_Quartzite"
    },
    {
      "x": -2,
      "y": 7,
      "z": -1,
      "name": "Rock_Quartzite"
    },
    {
      "x": -2,
      "y": 8,
      "z": -1,
      "name": "Rock_Quartzite"
    },
    {
      "x": -2,
      "y": 9,
      "z": -1,
      "name": "Rock_Quartzite"
    },
    {
      "x": -2,
      "y": 10,
      "z": -1,
      "name": "Rock_Quartzite"
    },
    {
      "x": -2,
      "y": 11,
      "z": -1,
      "name": "Rock_Quartzite_Brick"
    },
    {
      "x": -2,
      "y": 14,
      "z": -1,
      "name": "Rock_Quartzite_Brick"
    },
    {
      "x": -2,
      "y": 15,
      "z": -1,
      "name": "Plant_Moss_Rug_Green"
    },
    {
      "x": -2,
      "y": 16,
      "z": -1,
      "name": "Plant_Vine_Wall",
      "rotation": 3
    },
    {
      "x": -2,
      "y": 17,
      "z": -1,
      "name": "Plant_Vine",
      "rotation": 3
    },
    {
      "x": -2,
      "y": 4,
      "z": 0,
      "name": "Rock_Quartzite"
    },
    {
      "x": -2,
      "y": 5,
      "z": 0,
      "name": "Rock_Quartzite"
    },
    {
      "x": -2,
      "y": 6,
      "z": 0,
      "name": "Rock_Quartzite"
    },
    {
      "x": -2,
      "y": 7,
      "z": 0,
      "name": "Rock_Quartzite"
    },
    {
      "x": -2,
      "y": 8,
      "z": 0,
      "name": "Rock_Quartzite"
    },
    {
      "x": -2,
      "y": 9,
      "z": 0,
      "name": "Rock_Quartzite"
    },
    {
      "x": -2,
      "y": 10,
      "z": 0,
      "name": "Rock_Quartzite_Brick"
    },
    {
      "x": -2,
      "y": 11,
      "z": 0,
      "name": "Rock_Quartzite_Brick"
    },
    {
      "x": -2,
      "y": 12,
      "z": 0,
      "name": "Rock_Quartzite_Brick"
    },
    {
      "x": -2,
      "y": 13,
      "z": 0,
      "name": "Rock_Quartzite_Brick"
    },
    {
      "x": -2,
      "y": 14,
      "z": 0,
      "name": "Rock_Quartzite_Brick"
    },
    {
      "x": -2,
      "y": 15,
      "z": 0,
      "name": "Plant_Moss_Rug_Green"
    },
    {
      "x": -2,
      "y": 16,
      "z": 0,
      "name": "Plant_Vine",
      "rotation": 3
    },
    {
      "x": -2,
      "y": 17,
      "z": 0,
      "name": "Plant_Vine",
      "rotation": 3
    },
    {
      "x": -2,
      "y": 4,
      "z": 1,
      "name": "Rock_Quartzite"
    },
    {
      "x": -2,
      "y": 5,
      "z": 1,
      "name": "Rock_Quartzite"
    },
    {
      "x": -2,
      "y": 6,
      "z": 1,
      "name": "Rock_Quartzite"
    },
    {
      "x": -2,
      "y": 7,
      "z": 1,
      "name": "Rock_Quartzite"
    },
    {
      "x": -2,
      "y": 8,
      "z": 1,
      "name": "Rock_Quartzite"
    },
    {
      "x": -2,
      "y": 9,
      "z": 1,
      "name": "Rock_Quartzite"
    },
    {
      "x": -2,
      "y": 10,
      "z": 1,
      "name": "Rock_Quartzite_Brick"
    },
    {
      "x": -1,
      "y": 4,
      "z": -3,
      "name": "Rock_Quartzite_Brick"
    },
    {
      "x": -1,
      "y": 5,
      "z": -3,
      "name": "Rock_Quartzite"
    },
    {
      "x": -1,
      "y": 6,
      "z": -3,
      "name": "Rock_Quartzite"
    },
    {
      "x": -1,
      "y": 7,
      "z": -3,
      "name": "Rock_Quartzite_Brick"
    },
    {
      "x": -1,
      "y": 8,
      "z": -3,
      "name": "Rock_Quartzite_Brick"
    },
    {
      "x": -1,
      "y": 9,
      "z": -3,
      "name": "Rock_Quartzite_Brick"
    },
    {
      "x": -1,
      "y": 10,
      "z": -3,
      "name": "Rock_Quartzite_Brick"
    },
    {
      "x": -1,
      "y": 11,
      "z": -3,
      "name": "Rock_Quartzite_Brick"
    },
    {
      "x": -1,
      "y": 12,
      "z": -3,
      "name": "Rock_Quartzite_Brick"
    },
    {
      "x": -1,
      "y": 13,
      "z": -3,
      "name": "Rock_Quartzite"
    },
    {
      "x": -1,
      "y": 14,
      "z": -3,
      "name": "Rock_Quartzite_Brick"
    },
    {
      "x": -1,
      "y": 15,
      "z": -3,
      "name": "Rock_Quartzite_Brick"
    },
    {
      "x": -1,
      "y": 16,
      "z": -3,
      "name": "Rock_Quartzite_Brick"
    },
    {
      "x": -1,
      "y": 4,
      "z": -2,
      "name": "Rock_Quartzite"
    },
    {
      "x": -1,
      "y": 5,
      "z": -2,
      "name": "Rock_Quartzite"
    },
    {
      "x": -1,
      "y": 6,
      "z": -2,
      "name": "Rock_Quartzite"
    },
    {
      "x": -1,
      "y": 7,
      "z": -2,
      "name": "Rock_Quartzite"
    },
    {
      "x": -1,
      "y": 8,
      "z": -2,
      "name": "Rock_Quartzite"
    },
    {
      "x": -1,
      "y": 9,
      "z": -2,
      "name": "Rock_Quartzite_Brick"
    },
    {
      "x": -1,
      "y": 10,
      "z": -2,
      "name": "Rock_Quartzite"
    },
    {
      "x": -1,
      "y": 11,
      "z": -2,
      "name": "Rock_Quartzite"
    },
    {
      "x": -1,
      "y": 12,
      "z": -2,
      "name": "Rock_Quartzite"
    },
    {
      "x": -1,
      "y": 13,
      "z": -2,
      "name": "Rock_Quartzite_Brick"
    },
    {
      "x": -1,
      "y": 14,
      "z": -2,
      "name": "Rock_Quartzite"
    },
    {
      "x": -1,
      "y": 15,
      "z": -2,
      "name": "Rock_Quartzite_Brick"
    },
    {
      "x": -1,
      "y": 16,
      "z": -2,
      "name": "Rock_Quartzite"
    },
    {
      "x": -1,
      "y": 17,
      "z": -2,
      "name": "Plant_Moss_Rug_Green"
    },
    {
      "x": -1,
      "y": 4,
      "z": -1,
      "name": "Rock_Quartzite"
    },
    {
      "x": -1,
      "y": 5,
      "z": -1,
      "name": "Rock_Quartzite"
    },
    {
      "x": -1,
      "y": 6,
      "z": -1,
      "name": "Rock_Quartzite"
    },
    {
      "x": -1,
      "y": 7,
      "z": -1,
      "name": "Rock_Quartzite"
    },
    {
      "x": -1,
      "y": 8,
      "z": -1,
      "name": "Rock_Quartzite"
    },
    {
      "x": -1,
      "y": 9,
      "z": -1,
      "name": "Rock_Quartzite"
    },
    {
      "x": -1,
      "y": 10,
      "z": -1,
      "name": "Rock_Quartzite"
    },
    {
      "x": -1,
      "y": 11,
      "z": -1,
      "name": "Rock_Quartzite"
    },
    {
      "x": -1,
      "y": 12,
      "z": -1,
      "name": "Rock_Crystal_Green_Block"
    },
    {
      "x": -1,
      "y": 13,
      "z": -1,
      "name": "Rock_Crystal_Green_Block"
    },
    {
      "x": -1,
      "y": 14,
      "z": -1,
      "name": "Rock_Quartzite"
    },
    {
      "x": -1,
      "y": 15,
      "z": -1,
      "name": "Rock_Quartzite"
    },
    {
      "x": -1,
      "y": 16,
      "z": -1,
      "name": "Rock_Quartzite_Cobble"
    },
    {
      "x": -1,
      "y": 17,
      "z": -1,
      "name": "Rock_Quartzite_Cobble"
    },
    {
      "x": -1,
      "y": 18,
      "z": -1,
      "name": "Plant_Moss_Rug_Green"
    },
    {
      "x": -1,
      "y": 4,
      "z": 0,
      "name": "Rock_Quartzite"
    },
    {
      "x": -1,
      "y": 5,
      "z": 0,
      "name": "Rock_Quartzite"
    },
    {
      "x": -1,
      "y": 6,
      "z": 0,
      "name": "Rock_Quartzite"
    },
    {
      "x": -1,
      "y": 7,
      "z": 0,
      "name": "Rock_Quartzite"
    },
    {
      "x": -1,
      "y": 8,
      "z": 0,
      "name": "Rock_Quartzite"
    },
    {
      "x": -1,
      "y": 9,
      "z": 0,
      "name": "Rock_Quartzite"
    },
    {
      "x": -1,
      "y": 10,
      "z": 0,
      "name": "Rock_Quartzite_Brick"
    },
    {
      "x": -1,
      "y": 11,
      "z": 0,
      "name": "Rock_Quartzite_Brick"
    },
    {
      "x": -1,
      "y": 12,
      "z": 0,
      "name": "Rock_Quartzite_Brick"
    },
    {
      "x": -1,
      "y": 13,
      "z": 0,
      "name": "Rock_Quartzite"
    },
    {
      "x": -1,
      "y": 14,
      "z": 0,
      "name": "Rock_Quartzite_Brick"
    },
    {
      "x": -1,
      "y": 15,
      "z": 0,
      "name": "Rock_Quartzite_Brick"
    },
    {
      "x": -1,
      "y": 16,
      "z": 0,
      "name": "Rock_Quartzite"
    },
    {
      "x": -1,
      "y": 17,
      "z": 0,
      "name": "Rock_Quartzite_Cobble"
    },
    {
      "x": -1,
      "y": 18,
      "z": 0,
      "name": "Plant_Moss_Rug_Green"
    },
    {
      "x": -1,
      "y": 4,
      "z": 1,
      "name": "Rock_Quartzite"
    },
    {
      "x": -1,
      "y": 5,
      "z": 1,
      "name": "Rock_Quartzite"
    },
    {
      "x": -1,
      "y": 6,
      "z": 1,
      "name": "Rock_Quartzite"
    },
    {
      "x": -1,
      "y": 7,
      "z": 1,
      "name": "Rock_Quartzite"
    },
    {
      "x": -1,
      "y": 8,
      "z": 1,
      "name": "Rock_Quartzite"
    },
    {
      "x": -1,
      "y": 9,
      "z": 1,
      "name": "Rock_Quartzite_Brick"
    },
    {
      "x": -1,
      "y": 10,
      "z": 1,
      "name": "Rock_Quartzite_Brick"
    },
    {
      "x": -1,
      "y": 11,
      "z": 1,
      "name": "Rock_Quartzite_Brick"
    },
    {
      "x": -1,
      "y": 12,
      "z": 1,
      "name": "Rock_Quartzite_Brick"
    },
    {
      "x": -1,
      "y": 13,
      "z": 1,
      "name": "Rock_Quartzite_Brick"
    },
    {
      "x": -1,
      "y": 14,
      "z": 1,
      "name": "Rock_Quartzite_Brick"
    },
    {
      "x": -1,
      "y": 15,
      "z": 1,
      "name": "Rock_Quartzite_Brick"
    },
    {
      "x": 0,
      "y": 4,
      "z": -3,
      "name": "Rock_Quartzite_Brick"
    },
    {
      "x": 0,
      "y": 5,
      "z": -3,
      "name": "Rock_Quartzite_Brick"
    },
    {
      "x": 0,
      "y": 6,
      "z": -3,
      "name": "Rock_Quartzite_Brick"
    },
    {
      "x": 0,
      "y": 7,
      "z": -3,
      "name": "Rock_Quartzite_Brick"
    },
    {
      "x": 0,
      "y": 8,
      "z": -3,
      "name": "Rock_Quartzite_Brick"
    },
    {
      "x": 0,
      "y": 9,
      "z": -3,
      "name": "Rock_Quartzite_Brick"
    },
    {
      "x": 0,
      "y": 10,
      "z": -3,
      "name": "Rock_Quartzite"
    },
    {
      "x": 0,
      "y": 11,
      "z": -3,
      "name": "Rock_Quartzite"
    },
    {
      "x": 0,
      "y": 14,
      "z": -3,
      "name": "Rock_Quartzite"
    },
    {
      "x": 0,
      "y": 15,
      "z": -3,
      "name": "Rock_Quartzite_Brick"
    },
    {
      "x": 0,
      "y": 16,
      "z": -3,
      "name": "Rock_Quartzite_Brick"
    },
    {
      "x": 0,
      "y": 4,
      "z": -2,
      "name": "Rock_Quartzite_Brick"
    },
    {
      "x": 0,
      "y": 5,
      "z": -2,
      "name": "Rock_Quartzite"
    },
    {
      "x": 0,
      "y": 6,
      "z": -2,
      "name": "Rock_Quartzite"
    },
    {
      "x": 0,
      "y": 7,
      "z": -2,
      "name": "Rock_Quartzite_Brick"
    },
    {
      "x": 0,
      "y": 8,
      "z": -2,
      "name": "Rock_Quartzite"
    },
    {
      "x": 0,
      "y": 9,
      "z": -2,
      "name": "Rock_Quartzite"
    },
    {
      "x": 0,
      "y": 10,
      "z": -2,
      "name": "Rock_Quartzite"
    },
    {
      "x": 0,
      "y": 11,
      "z": -2,
      "name": "Rock_Quartzite"
    },
    {
      "x": 0,
      "y": 12,
      "z": -2,
      "name": "Rock_Crystal_Green_Block"
    },
    {
      "x": 0,
      "y": 13,
      "z": -2,
      "name": "Rock_Crystal_Green_Block"
    },
    {
      "x": 0,
      "y": 14,
      "z": -2,
      "name": "Rock_Quartzite"
    },
    {
      "x": 0,
      "y": 15,
      "z": -2,
      "name": "Rock_Quartzite"
    },
    {
      "x": 0,
      "y": 16,
      "z": -2,
      "name": "Rock_Quartzite_Brick"
    },
    {
      "x": 0,
      "y": 17,
      "z": -2,
      "name": "Rock_Quartzite_Cobble"
    },
    {
      "x": 0,
      "y": 18,
      "z": -2,
      "name": "Rock_Quartzite_Cobble"
    },
    {
      "x": 0,
      "y": 4,
      "z": -1,
      "name": "Rock_Quartzite"
    },
    {
      "x": 0,
      "y": 5,
      "z": -1,
      "name": "Rock_Quartzite"
    },
    {
      "x": 0,
      "y": 6,
      "z": -1,
      "name": "Rock_Quartzite"
    },
    {
      "x": 0,
      "y": 7,
      "z": -1,
      "name": "Rock_Quartzite"
    },
    {
      "x": 0,
      "y": 8,
      "z": -1,
      "name": "Rock_Quartzite"
    },
    {
      "x": 0,
      "y": 9,
      "z": -1,
      "name": "Rock_Quartzite_Brick"
    },
    {
      "x": 0,
      "y": 10,
      "z": -1,
      "name": "Rock_Quartzite"
    },
    {
      "x": 0,
      "y": 11,
      "z": -1,
      "name": "Rock_Quartzite"
    },
    {
      "x": 0,
      "y": 12,
      "z": -1,
      "name": "Rock_Crystal_Green_Block"
    },
    {
      "x": 0,
      "y": 13,
      "z": -1,
      "name": "Rock_Crystal_Green_Block"
    },
    {
      "x": 0,
      "y": 14,
      "z": -1,
      "name": "Rock_Quartzite"
    },
    {
      "x": 0,
      "y": 15,
      "z": -1,
      "name": "Rock_Quartzite"
    },
    {
      "x": 0,
      "y": 16,
      "z": -1,
      "name": "Rock_Quartzite"
    },
    {
      "x": 0,
      "y": 17,
      "z": -1,
      "name": "Rock_Quartzite_Cobble"
    },
    {
      "x": 0,
      "y": 18,
      "z": -1,
      "name": "Rock_Quartzite_Cobble"
    },
    {
      "x": 0,
      "y": 4,
      "z": 0,
      "name": "Rock_Quartzite"
    },
    {
      "x": 0,
      "y": 5,
      "z": 0,
      "name": "Rock_Quartzite"
    },
    {
      "x": 0,
      "y": 6,
      "z": 0,
      "name": "Rock_Quartzite"
    },
    {
      "x": 0,
      "y": 7,
      "z": 0,
      "name": "Rock_Quartzite"
    },
    {
      "x": 0,
      "y": 8,
      "z": 0,
      "name": "Rock_Quartzite"
    },
    {
      "x": 0,
      "y": 9,
      "z": 0,
      "name": "Rock_Quartzite_Brick"
    },
    {
      "x": 0,
      "y": 10,
      "z": 0,
      "name": "Rock_Quartzite"
    },
    {
      "x": 0,
      "y": 11,
      "z": 0,
      "name": "Rock_Quartzite"
    },
    {
      "x": 0,
      "y": 12,
      "z": 0,
      "name": "Rock_Crystal_Green_Block"
    },
    {
      "x": 0,
      "y": 13,
      "z": 0,
      "name": "Rock_Crystal_Green_Block"
    },
    {
      "x": 0,
      "y": 14,
      "z": 0,
      "name": "Rock_Quartzite"
    },
    {
      "x": 0,
      "y": 15,
      "z": 0,
      "name": "Rock_Quartzite"
    },
    {
      "x": 0,
      "y": 16,
      "z": 0,
      "name": "Rock_Crystal_Green_Block"
    },
    {
      "x": 0,
      "y": 17,
      "z": 0,
      "name": "Rock_Quartzite"
    },
    {
      "x": 0,
      "y": 4,
      "z": 1,
      "name": "Rock_Quartzite"
    },
    {
      "x": 0,
      "y": 5,
      "z": 1,
      "name": "Rock_Quartzite_Brick"
    },
    {
      "x": 0,
      "y": 6,
      "z": 1,
      "name": "Rock_Quartzite_Brick"
    },
    {
      "x": 0,
      "y": 7,
      "z": 1,
      "name": "Rock_Quartzite"
    },
    {
      "x": 0,
      "y": 8,
      "z": 1,
      "name": "Rock_Quartzite_Brick"
    },
    {
      "x": 0,
      "y": 9,
      "z": 1,
      "name": "Rock_Quartzite_Brick"
    },
    {
      "x": 0,
      "y": 10,
      "z": 1,
      "name": "Rock_Quartzite_Brick"
    },
    {
      "x": 0,
      "y": 11,
      "z": 1,
      "name": "Rock_Quartzite"
    },
    {
      "x": 0,
      "y": 14,
      "z": 1,
      "name": "Rock_Quartzite_Brick"
    },
    {
      "x": 0,
      "y": 15,
      "z": 1,
      "name": "Rock_Quartzite_Brick"
    },
    {
      "x": 0,
      "y": 17,
      "z": 1,
      "name": "Rock_Quartzite"
    },
    {
      "x": 1,
      "y": 4,
      "z": -3,
      "name": "Rock_Quartzite_Brick"
    },
    {
      "x": 1,
      "y": 5,
      "z": -3,
      "name": "Rock_Quartzite"
    },
    {
      "x": 1,
      "y": 6,
      "z": -3,
      "name": "Rock_Quartzite"
    },
    {
      "x": 1,
      "y": 7,
      "z": -3,
      "name": "Rock_Quartzite_Brick"
    },
    {
      "x": 1,
      "y": 8,
      "z": -3,
      "name": "Rock_Quartzite"
    },
    {
      "x": 1,
      "y": 9,
      "z": -3,
      "name": "Rock_Quartzite"
    },
    {
      "x": 1,
      "y": 10,
      "z": -3,
      "name": "Rock_Quartzite"
    },
    {
      "x": 1,
      "y": 11,
      "z": -3,
      "name": "Rock_Quartzite"
    },
    {
      "x": 1,
      "y": 12,
      "z": -3,
      "name": "Rock_Quartzite"
    },
    {
      "x": 1,
      "y": 13,
      "z": -3,
      "name": "Rock_Quartzite"
    },
    {
      "x": 1,
      "y": 14,
      "z": -3,
      "name": "Rock_Quartzite"
    },
    {
      "x": 1,
      "y": 4,
      "z": -2,
      "name": "Rock_Quartzite"
    },
    {
      "x": 1,
      "y": 5,
      "z": -2,
      "name": "Rock_Quartzite"
    },
    {
      "x": 1,
      "y": 6,
      "z": -2,
      "name": "Rock_Quartzite"
    },
    {
      "x": 1,
      "y": 7,
      "z": -2,
      "name": "Rock_Quartzite"
    },
    {
      "x": 1,
      "y": 8,
      "z": -2,
      "name": "Rock_Quartzite"
    },
    {
      "x": 1,
      "y": 9,
      "z": -2,
      "name": "Rock_Quartzite"
    },
    {
      "x": 1,
      "y": 10,
      "z": -2,
      "name": "Rock_Quartzite"
    },
    {
      "x": 1,
      "y": 11,
      "z": -2,
      "name": "Rock_Quartzite"
    },
    {
      "x": 1,
      "y": 12,
      "z": -2,
      "name": "Rock_Quartzite"
    },
    {
      "x": 1,
      "y": 13,
      "z": -2,
      "name": "Rock_Quartzite"
    },
    {
      "x": 1,
      "y": 14,
      "z": -2,
      "name": "Rock_Quartzite"
    },
    {
      "x": 1,
      "y": 15,
      "z": -2,
      "name": "Rock_Quartzite_Brick"
    },
    {
      "x": 1,
      "y": 16,
      "z": -2,
      "name": "Rock_Quartzite_Brick"
    },
    {
      "x": 1,
      "y": 17,
      "z": -2,
      "name": "Rock_Quartzite_Brick"
    },
    {
      "x": 1,
      "y": 18,
      "z": -2,
      "name": "Rock_Quartzite_Cobble"
    },
    {
      "x": 1,
      "y": 4,
      "z": -1,
      "name": "Rock_Quartzite"
    },
    {
      "x": 1,
      "y": 5,
      "z": -1,
      "name": "Rock_Quartzite"
    },
    {
      "x": 1,
      "y": 6,
      "z": -1,
      "name": "Rock_Quartzite"
    },
    {
      "x": 1,
      "y": 7,
      "z": -1,
      "name": "Rock_Quartzite"
    },
    {
      "x": 1,
      "y": 8,
      "z": -1,
      "name": "Rock_Quartzite"
    },
    {
      "x": 1,
      "y": 9,
      "z": -1,
      "name": "Rock_Quartzite"
    },
    {
      "x": 1,
      "y": 10,
      "z": -1,
      "name": "Rock_Quartzite"
    },
    {
      "x": 1,
      "y": 11,
      "z": -1,
      "name": "Rock_Quartzite"
    },
    {
      "x": 1,
      "y": 12,
      "z": -1,
      "name": "Rock_Crystal_Green_Block"
    },
    {
      "x": 1,
      "y": 13,
      "z": -1,
      "name": "Rock_Crystal_Green_Block"
    },
    {
      "x": 1,
      "y": 14,
      "z": -1,
      "name": "Rock_Quartzite"
    },
    {
      "x": 1,
      "y": 15,
      "z": -1,
      "name": "Rock_Quartzite"
    },
    {
      "x": 1,
      "y": 16,
      "z": -1,
      "name": "Rock_Quartzite_Brick"
    },
    {
      "x": 1,
      "y": 17,
      "z": -1,
      "name": "Rock_Quartzite_Brick"
    },
    {
      "x": 1,
      "y": 18,
      "z": -1,
      "name": "Rock_Quartzite_Cobble"
    },
    {
      "x": 1,
      "y": 4,
      "z": 0,
      "name": "Rock_Quartzite"
    },
    {
      "x": 1,
      "y": 5,
      "z": 0,
      "name": "Rock_Quartzite_Brick"
    },
    {
      "x": 1,
      "y": 6,
      "z": 0,
      "name": "Rock_Quartzite_Brick"
    },
    {
      "x": 1,
      "y": 7,
      "z": 0,
      "name": "Rock_Quartzite"
    },
    {
      "x": 1,
      "y": 8,
      "z": 0,
      "name": "Rock_Quartzite_Brick"
    },
    {
      "x": 1,
      "y": 9,
      "z": 0,
      "name": "Rock_Quartzite"
    },
    {
      "x": 1,
      "y": 10,
      "z": 0,
      "name": "Rock_Quartzite"
    },
    {
      "x": 1,
      "y": 11,
      "z": 0,
      "name": "Rock_Quartzite"
    },
    {
      "x": 1,
      "y": 12,
      "z": 0,
      "name": "Rock_Quartzite"
    },
    {
      "x": 1,
      "y": 13,
      "z": 0,
      "name": "Rock_Quartzite"
    },
    {
      "x": 1,
      "y": 14,
      "z": 0,
      "name": "Rock_Quartzite"
    },
    {
      "x": 1,
      "y": 15,
      "z": 0,
      "name": "Rock_Quartzite"
    },
    {
      "x": 1,
      "y": 16,
      "z": 0,
      "name": "Rock_Quartzite"
    },
    {
      "x": 1,
      "y": 17,
      "z": 0,
      "name": "Rock_Quartzite"
    },
    {
      "x": 1,
      "y": 4,
      "z": 1,
      "name": "Rock_Quartzite_Brick"
    },
    {
      "x": 1,
      "y": 5,
      "z": 1,
      "name": "Rock_Quartzite_Brick"
    },
    {
      "x": 1,
      "y": 6,
      "z": 1,
      "name": "Rock_Quartzite_Brick"
    },
    {
      "x": 1,
      "y": 7,
      "z": 1,
      "name": "Rock_Quartzite_Brick"
    },
    {
      "x": 1,
      "y": 8,
      "z": 1,
      "name": "Rock_Quartzite_Brick"
    },
    {
      "x": 1,
      "y": 9,
      "z": 1,
      "name": "Rock_Quartzite_Brick"
    },
    {
      "x": 1,
      "y": 10,
      "z": 1,
      "name": "Rock_Quartzite"
    },
    {
      "x": 1,
      "y": 11,
      "z": 1,
      "name": "Rock_Quartzite"
    },
    {
      "x": 1,
      "y": 12,
      "z": 1,
      "name": "Rock_Quartzite"
    },
    {
      "x": 1,
      "y": 13,
      "z": 1,
      "name": "Rock_Quartzite"
    },
    {
      "x": 1,
      "y": 14,
      "z": 1,
      "name": "Rock_Quartzite"
    },
    {
      "x": 1,
      "y": 15,
      "z": 1,
      "name": "Rock_Quartzite"
    },
    {
      "x": 1,
      "y": 16,
      "z": 1,
      "name": "Rock_Quartzite"
    },
    {
      "x": 1,
      "y": 17,
      "z": 1,
      "name": "Rock_Quartzite"
    },
    {
      "x": 2,
      "y": 4,
      "z": -3,
      "name": "Rock_Quartzite"
    },
    {
      "x": 2,
      "y": 5,
      "z": -3,
      "name": "Rock_Quartzite"
    },
    {
      "x": 2,
      "y": 6,
      "z": -3,
      "name": "Rock_Quartzite"
    },
    {
      "x": 2,
      "y": 7,
      "z": -3,
      "name": "Rock_Quartzite"
    },
    {
      "x": 2,
      "y": 8,
      "z": -3,
      "name": "Rock_Quartzite"
    },
    {
      "x": 2,
      "y": 9,
      "z": -3,
      "name": "Rock_Quartzite"
    },
    {
      "x": 2,
      "y": 4,
      "z": -2,
      "name": "Rock_Quartzite"
    },
    {
      "x": 2,
      "y": 5,
      "z": -2,
      "name": "Rock_Quartzite"
    },
    {
      "x": 2,
      "y": 6,
      "z": -2,
      "name": "Rock_Quartzite"
    },
    {
      "x": 2,
      "y": 7,
      "z": -2,
      "name": "Rock_Quartzite"
    },
    {
      "x": 2,
      "y": 8,
      "z": -2,
      "name": "Rock_Quartzite"
    },
    {
      "x": 2,
      "y": 9,
      "z": -2,
      "name": "Rock_Quartzite"
    },
    {
      "x": 2,
      "y": 10,
      "z": -2,
      "name": "Rock_Quartzite"
    },
    {
      "x": 2,
      "y": 11,
      "z": -2,
      "name": "Rock_Quartzite"
    },
    {
      "x": 2,
      "y": 12,
      "z": -2,
      "name": "Rock_Quartzite"
    },
    {
      "x": 2,
      "y": 13,
      "z": -2,
      "name": "Rock_Quartzite"
    },
    {
      "x": 2,
      "y": 14,
      "z": -2,
      "name": "Rock_Quartzite"
    },
    {
      "x": 2,
      "y": 15,
      "z": -2,
      "name": "Rock_Quartzite"
    },
    {
      "x": 2,
      "y": 16,
      "z": -2,
      "name": "Rock_Quartzite_Brick"
    },
    {
      "x": 2,
      "y": 17,
      "z": -2,
      "name": "Rock_Quartzite_Brick"
    },
    {
      "x": 2,
      "y": 4,
      "z": -1,
      "name": "Rock_Quartzite"
    },
    {
      "x": 2,
      "y": 5,
      "z": -1,
      "name": "Rock_Quartzite"
    },
    {
      "x": 2,
      "y": 6,
      "z": -1,
      "name": "Rock_Quartzite"
    },
    {
      "x": 2,
      "y": 7,
      "z": -1,
      "name": "Rock_Quartzite"
    },
    {
      "x": 2,
      "y": 8,
      "z": -1,
      "name": "Rock_Quartzite"
    },
    {
      "x": 2,
      "y": 9,
      "z": -1,
      "name": "Rock_Quartzite"
    },
    {
      "x": 2,
      "y": 10,
      "z": -1,
      "name": "Rock_Quartzite"
    },
    {
      "x": 2,
      "y": 11,
      "z": -1,
      "name": "Rock_Quartzite"
    },
    {
      "x": 2,
      "y": 14,
      "z": -1,
      "name": "Rock_Quartzite"
    },
    {
      "x": 2,
      "y": 15,
      "z": -1,
      "name": "Rock_Quartzite"
    },
    {
      "x": 2,
      "y": 17,
      "z": -1,
      "name": "Rock_Quartzite"
    },
    {
      "x": 2,
      "y": 4,
      "z": 0,
      "name": "Rock_Quartzite"
    },
    {
      "x": 2,
      "y": 5,
      "z": 0,
      "name": "Rock_Quartzite"
    },
    {
      "x": 2,
      "y": 6,
      "z": 0,
      "name": "Rock_Quartzite"
    },
    {
      "x": 2,
      "y": 7,
      "z": 0,
      "name": "Rock_Quartzite"
    },
    {
      "x": 2,
      "y": 8,
      "z": 0,
      "name": "Rock_Quartzite"
    },
    {
      "x": 2,
      "y": 9,
      "z": 0,
      "name": "Rock_Quartzite"
    },
    {
      "x": 2,
      "y": 10,
      "z": 0,
      "name": "Rock_Quartzite"
    },
    {
      "x": 2,
      "y": 11,
      "z": 0,
      "name": "Rock_Quartzite"
    },
    {
      "x": 2,
      "y": 12,
      "z": 0,
      "name": "Rock_Quartzite"
    },
    {
      "x": 2,
      "y": 13,
      "z": 0,
      "name": "Rock_Quartzite"
    },
    {
      "x": 2,
      "y": 14,
      "z": 0,
      "name": "Rock_Quartzite"
    },
    {
      "x": 2,
      "y": 15,
      "z": 0,
      "name": "Rock_Quartzite"
    },
    {
      "x": 2,
      "y": 16,
      "z": 0,
      "name": "Rock_Quartzite"
    },
    {
      "x": 2,
      "y": 17,
      "z": 0,
      "name": "Rock_Quartzite"
    },
    {
      "x": 2,
      "y": 11,
      "z": 1,
      "name": "Rock_Quartzite"
    },
    {
      "x": 2,
      "y": 12,
      "z": 1,
      "name": "Rock_Quartzite"
    },
    {
      "x": 2,
      "y": 13,
      "z": 1,
      "name": "Rock_Quartzite"
    },
    {
      "x": 2,
      "y": 14,
      "z": 1,
      "name": "Rock_Quartzite"
    },
    {
      "x": 2,
      "y": 15,
      "z": 1,
      "name": "Rock_Quartzite"
    },
    {
      "x": 2,
      "y": 16,
      "z": 1,
      "name": "Rock_Quartzite"
    }
  ]
}