{
  "version": 8,
  "blockIdVersion": 8,
  "anchorX": 7,
  "anchorY": 9,
  "anchorZ": 4,
  "blocks": [
    {
      "x": 5,
      "y": 25,
      "z": 4,
      "name": "Plant_Leaves_Burnt"
    },
    {
      "x": 5,
      "y": 28,
      "z": 4,
      "name": "Plant_Leaves_Burnt"
    },
    {
      "x": 6,
      "y": 31,
      "z": 2,
      "name": "Plant_Leaves_Burnt"
    },
    {
      "x": 6,
      "y": 5,
      "z": 3,
      "name": "Wood_Burnt_Roots"
    },
    {
      "x": 6,
      "y": 6,
      "z": 3,
      "name": "Wood_Burnt_Trunk_Full"
    },
    {
      "x": 6,
      "y": 24,
      "z": 3,
      "name": "Plant_Leaves_Burnt"
    },
    {
      "x": 6,
      "y": 25,
      "z": 3,
      "name": "Plant_Leaves_Burnt"
    },
    {
      "x": 6,
      "y": 28,
      "z": 3,
      "name": "Plant_Leaves_Burnt"
    },
    {
      "x": 6,
      "y": 30,
      "z": 3,
      "name": "Plant_Leaves_Burnt"
    },
    {
      "x": 6,
      "y": 31,
      "z": 3,
      "name": "Plant_Leaves_Burnt"
    },
    {
      "x": 6,
      "y": 5,
      "z": 4,
      "name": "Wood_Burnt_Roots"
    },
    {
      "x": 6,
      "y": 6,
      "z": 4,
      "name": "Wood_Burnt_Trunk"
    },
    {
      "x": 6,
      "y": 7,
      "z": 4,
      "name": "Wood_Burnt_Trunk_Full"
    },
    {
      "x": 6,
      "y": 15,
      "z": 4,
      "name": "Wood_Burnt_Branch_Long",
      "rotation": 5
    },
    {
      "x": 6,
      "y": 25,
      "z": 4,
      "name": "Wood_Burnt_Branch_Long",
      "rotation": 5
    },
    {
      "x": 6,
      "y": 26,
      "z": 4,
      "name": "Plant_Leaves_Burnt"
    },
    {
      "x": 6,
      "y": 27,
      "z": 4,
      "name": "Plant_Leaves_Burnt"
    },
    {
      "x": 6,
      "y": 28,
      "z": 4,
      "name": "Wood_Burnt_Branch_Long",
      "rotation": 5
    },
    {
      "x": 6,
      "y": 33,
      "z": 4,
      "name": "Plant_Leaves_Burnt"
    },
    {
      "x": 6,
      "y": 25,
      "z": 5,
      "name": "Plant_Leaves_Burnt"
    },
    {
      "x": 6,
      "y": 28,
      "z": 5,
      "name": "Plant_Leaves_Burnt"
    },
    {
      "x": 6,
      "y": 29,
      "z": 5,
      "name": "Plant_Leaves_Burnt"
    },
    {
      "x": 7,
      "y": 25,
      "z": 2,
      "name": "Plant_Leaves_Burnt"
    },
    {
      "x": 7,
      "y": 31,
      "z": 2,
      "name": "Plant_Leaves_Burnt"
    },
    {
      "x": 7,
      "y": 4,
      "z": 3,
      "name": "Wood_Burnt_Roots"
    },
    {
      "x": 7,
      "y": 5,
      "z": 3,
      "name": "Wood_Burnt_Trunk"
    },
    {
      "x": 7,
      "y": 6,
      "z": 3,
      "name": "Wood_Burnt_Trunk_Full"
    },
    {
      "x": 7,
      "y": 19,
      "z": 3,
      "name": "Wood_Burnt_Branch_Long",
      "rotation": 4
    },
    {
      "x": 7,
      "y": 24,
      "z": 3,
      "name": "Wood_Burnt_Branch_Long",
      "rotation": 4
    },
    {
      "x": 7,
      "y": 25,
      "z": 3,
      "name": "Plant_Leaves_Burnt"
    },
    {
      "x": 7,
      "y": 30,
      "z": 3,
      "name": "Plant_Leaves_Burnt"
    },
    {
      "x": 7,
      "y": 31,
      "z": 3,
      "name": "Wood_Burnt_Branch_Long",
      "rotation": 4
    },
    {
      "x": 7,
      "y": 33,
      "z": 3,
      "name": "Plant_Leaves_Burnt"
    },
    {
      "x": 7,
      "y": 35,
      "z": 3,
      "name": "Plant_Leaves_Burnt"
    },
    {
      "x": 7,
      "y": 3,
      "z": 4,
      "name": "Wood_Burnt_Roots"
    },
    {
      "x": 7,
      "y": 4,
      "z": 4,
      "name": "Wood_Burnt_Trunk"
    },
    {
      "x": 7,
      "y": 5,
      "z": 4,
      "name": "Wood_Burnt_Trunk"
    },
    {
      "x": 7,
      "y": 6,
      "z": 4,
      "name": "Wood_Burnt_Trunk"
    },
    {
      "x": 7,
      "y": 7,
      "z": 4,
      "name": "Wood_Burnt_Trunk"
    },
    {
      "x": 7,
      "y": 8,
      "z": 4,
      "name": "Wood_Burnt_Trunk"
    },
    {
      "x": 7,
      "y": 9,
      "z": 4,
      "name": "Wood_Burnt_Trunk"
    },
    {
      "x": 7,
      "y": 10,
      "z": 4,
      "name": "Wood_Burnt_Trunk"
    },
    {
      "x": 7,
      "y": 11,
      "z": 4,
      "name": "Wood_Burnt_Trunk"
    },
    {
      "x": 7,
      "y": 12,
      "z": 4,
      "name": "Wood_Burnt_Trunk"
    },
    {
      "x": 7,
      "y": 13,
      "z": 4,
      "name": "Wood_Burnt_Trunk"
    },
    {
      "x": 7,
      "y": 14,
      "z": 4,
      "name": "Wood_Burnt_Trunk"
    },
    {
      "x": 7,
      "y": 15,
      "z": 4,
      "name": "Wood_Burnt_Trunk"
    },
    {
      "x": 7,
      "y": 16,
      "z": 4,
      "name": "Wood_Burnt_Trunk"
    },
    {
      "x": 7,
      "y": 17,
      "z": 4,
      "name": "Wood_Burnt_Trunk"
    },
    {
      "x": 7,
      "y": 18,
      "z": 4,
      "name": "Wood_Burnt_Trunk"
    },
    {
      "x": 7,
      "y": 19,
      "z": 4,
      "name": "Wood_Burnt_Trunk"
    },
    {
      "x": 7,
      "y": 20,
      "z": 4,
      "name": "Wood_Burnt_Trunk"
    },
    {
      "x": 7,
      "y": 21,
      "z": 4,
      "name": "Wood_Burnt_Trunk"
    },
    {
      "x": 7,
      "y": 22,
      "z": 4,
      "name": "Wood_Burnt_Trunk"
    },
    {
      "x": 7,
      "y": 23,
      "z": 4,
      "name": "Wood_Burnt_Trunk"
    },
    {
      "x": 7,
      "y": 24,
      "z": 4,
      "name": "Wood_Burnt_Trunk"
    },
    {
      "x": 7,
      "y": 25,
      "z": 4,
      "name": "Wood_Burnt_Trunk"
    },
    {
      "x": 7,
      "y": 26,
      "z": 4,
      "name": "Wood_Burnt_Trunk"
    },
    {
      "x": 7,
      "y": 27,
      "z": 4,
      "name": "Wood_Burnt_Trunk"
    },
    {
      "x": 7,
      "y": 28,
      "z": 4,
      "name": "Wood_Burnt_Trunk"
    },
    {
      "x": 7,
      "y": 29,
      "z": 4,
      "name": "Wood_Burnt_Trunk"
    },
    {
      "x": 7,
      "y": 30,
      "z": 4,
      "name": "Wood_Burnt_Trunk"
    },
    {
      "x": 7,
      "y": 31,
      "z": 4,
      "name": "Wood_Burnt_Trunk"
    },
    {
      "x": 7,
      "y": 32,
      "z": 4,
      "name": "Wood_Burnt_Trunk"
    },
    {
      "x": 7,
      "y": 33,
      "z": 4,
      "name": "Wood_Burnt_Trunk"
    },
    {
      "x": 7,
      "y": 34,
      "z": 4,
      "name": "Plant_Leaves_Burnt"
    },
    {
      "x": 7,
      "y": 35,
      "z": 4,
      "name": "Plant_Leaves_Burnt"
    },
    {
      "x": 7,
      "y": 36,
      "z": 4,
      "name": "Plant_Leaves_Burnt"
    },
    {
      "x": 7,
      "y": 37,
      "z": 4,
      "name": "Plant_Leaves_Burnt"
    },
    {
      "x": 7,
      "y": 38,
      "z": 4,
      "name": "Plant_Leaves_Burnt"
    },
    {
      "x": 7,
      "y": 4,
      "z": 5,
      "name": "Wood_Burnt_Roots"
    },
    {
      "x": 7,
      "y": 5,
      "z": 5,
      "name": "Wood_Burnt_Trunk"
    },
    {
      "x": 7,
      "y": 6,
      "z": 5,
      "name": "Wood_Burnt_Trunk_Full"
    },
    {
      "x": 7,
      "y": 20,
      "z": 5,
      "name": "Wood_Burnt_Branch_Long",
      "rotation": 4
    },
    {
      "x": 7,
      "y": 22,
      "z": 5,
      "name": "Plant_Leaves_Burnt"
    },
    {
      "x": 7,
      "y": 23,
      "z": 5,
      "name": "Wood_Burnt_Branch_Long",
      "rotation": 4
    },
    {
      "x": 7,
      "y": 24,
      "z": 5,
      "name": "Plant_Leaves_Burnt"
    },
    {
      "x": 7,
      "y": 29,
      "z": 5,
      "name": "Wood_Burnt_Branch_Long",
      "rotation": 4
    },
    {
      "x": 7,
      "y": 30,
      "z": 5,
      "name": "Plant_Leaves_Burnt"
    },
    {
      "x": 7,
      "y": 33,
      "z": 5,
      "name": "Plant_Leaves_Burnt"
    },
    {
      "x": 7,
      "y": 23,
      "z": 6,
      "name": "Plant_Leaves_Burnt"
    },
    {
      "x": 7,
      "y": 30,
      "z": 6,
      "name": "Plant_Leaves_Burnt"
    },
    {
      "x": 8,
      "y": 24,
      "z": 3,
      "name": "Plant_Leaves_Burnt"
    },
    {
      "x": 8,
      "y": 26,
      "z": 3,
      "name": "Plant_Leaves_Burnt"
    },
    {
      "x": 8,
      "y": 27,
      "z": 3,
      "name": "Plant_Leaves_Burnt"
    },
    {
      "x": 8,
      "y": 30,
      "z": 3,
      "name": "Plant_Leaves_Burnt"
    },
    {
      "x": 8,
      "y": 5,
      "z": 4,
      "name": "Wood_Burnt_Roots"
    },
    {
      "x": 8,
      "y": 6,
      "z": 4,
      "name": "Wood_Burnt_Trunk"
    },
    {
      "x": 8,
      "y": 7,
      "z": 4,
      "name": "Wood_Burnt_Trunk_Full"
    },
    {
      "x": 8,
      "y": 15,
      "z": 4,
      "name": "Wood_Burnt_Branch_Short",
      "rotation": 1
    },
    {
      "x": 8,
      "y": 26,
      "z": 4,
      "name": "Plant_Leaves_Burnt"
    },
    {
      "x": 8,
      "y": 27,
      "z": 4,
      "name": "Wood_Burnt_Branch_Long",
      "rotation": 5
    },
    {
      "x": 8,
      "y": 30,
      "z": 4,
      "name": "Wood_Burnt_Branch_Long",
      "rotation": 5
    },
    {
      "x": 8,
      "y": 31,
      "z": 4,
      "name": "Plant_Leaves_Burnt"
    },
    {
      "x": 8,
      "y": 32,
      "z": 4,
      "name": "Plant_Leaves_Burnt"
    },
    {
      "x": 8,
      "y": 33,
      "z": 4,
      "name": "Plant_Leaves_Burnt"
    },
    {
      "x": 8,
      "y": 34,
      "z": 4,
      "name": "Plant_Leaves_Burnt"
    },
    {
      "x": 8,
      "y": 35,
      "z": 4,
      "name": "Plant_Leaves_Burnt"
    },
    {
      "x": 8,
      "y": 23,
      "z": 5,
      "name": "Plant_Leaves_Burnt"
    },
    {
      "x": 8,
      "y": 29,
      "z": 5,
      "name": "Plant_Leaves_Burnt"
    },
    {
      "x": 8,
      "y": 30,
      "z": 5,
      "name": "Plant_Leaves_Burnt"
    },
    {
      "x": 9,
      "y": 27,
      "z": 3,
      "name": "Plant_Leaves_Burnt"
    },
    {
      "x": 9,
      "y": 27,
      "z": 4,
      "name": "Plant_Leaves_Burnt"
    },
    {
      "x": 9,
      "y": 30,
      "z": 4,
      "name": "Plant_Leaves_Burnt"
    }
  ]
}