{
  "version": 8,
  "blockIdVersion": 8,
  "anchorX": 0,
  "anchorY": 0,
  "anchorZ": 0,
  "blocks": [
    {
      "x": -5,
      "y": 0,
      "z": -3,
      "name": "Wood_Petrified_Trunk"
    },
    {
      "x": -5,
      "y": 0,
      "z": -2,
      "name": "Wood_Petrified_Trunk"
    },
    {
      "x": -5,
      "y": 1,
      "z": -2,
      "name": "Wood_Petrified_Trunk"
    },
    {
      "x": -5,
      "y": 0,
      "z": -1,
      "name": "Wood_Petrified_Trunk"
    },
    {
      "x": -5,
      "y": 0,
      "z": 1,
      "name": "Wood_Petrified_Trunk"
    },
    {
      "x": -5,
      "y": 1,
      "z": 1,
      "name": "Wood_Petrified_Trunk"
    },
    {
      "x": -5,
      "y": 2,
      "z": 1,
      "name": "Wood_Petrified_Trunk"
    },
    {
      "x": -5,
      "y": 0,
      "z": 2,
      "name": "Wood_Petrified_Trunk"
    },
    {
      "x": -5,
      "y": 1,
      "z": 2,
      "name": "Wood_Petrified_Trunk"
    },
    {
      "x": -5,
      "y": 0,
      "z": 3,
      "name": "Wood_Petrified_Trunk"
    },
    {
      "x": -5,
      "y": 0,
      "z": 4,
      "name": "Wood_Petrified_Trunk"
    },
    {
      "x": -4,
      "y": 0,
      "z": -3,
      "name": "Wood_Petrified_Trunk"
    },
    {
      "x": -4,
      "y": 1,
      "z": -3,
      "name": "Wood_Petrified_Trunk"
    },
    {
      "x": -4,
      "y": 0,
      "z": -2,
      "name": "Wood_Petrified_Trunk"
    },
    {
      "x": -4,
      "y": 1,
      "z": -2,
      "name": "Wood_Petrified_Trunk"
    },
    {
      "x": -4,
      "y": 2,
      "z": -2,
      "name": "Wood_Petrified_Trunk"
    },
    {
      "x": -4,
      "y": 3,
      "z": -2,
      "name": "Wood_Petrified_Trunk"
    },
    {
      "x": -4,
      "y": 4,
      "z": -2,
      "name": "Wood_Petrified_Trunk"
    },
    {
      "x": -4,
      "y": 5,
      "z": -2,
      "name": "Wood_Burnt_Trunk"
    },
    {
      "x": -4,
      "y": 6,
      "z": -2,
      "name": "Wood_Burnt_Trunk"
    },
    {
      "x": -4,
      "y": 7,
      "z": -2,
      "name": "Wood_Burnt_Trunk"
    },
    {
      "x": -4,
      "y": 0,
      "z": -1,
      "name": "Wood_Petrified_Trunk"
    },
    {
      "x": -4,
      "y": 1,
      "z": -1,
      "name": "Wood_Petrified_Trunk"
    },
    {
      "x": -4,
      "y": 2,
      "z": -1,
      "name": "Wood_Petrified_Trunk"
    },
    {
      "x": -4,
      "y": 3,
      "z": -1,
      "name": "Wood_Petrified_Trunk"
    },
    {
      "x": -4,
      "y": 4,
      "z": -1,
      "name": "Wood_Petrified_Trunk"
    },
    {
      "x": -4,
      "y": 5,
      "z": -1,
      "name": "Wood_Petrified_Trunk"
    },
    {
      "x": -4,
      "y": 6,
      "z": -1,
      "name": "Wood_Burnt_Trunk"
    },
    {
      "x": -4,
      "y": 7,
      "z": -1,
      "name": "Wood_Burnt_Trunk"
    },
    {
      "x": -4,
      "y": 0,
      "z": 0,
      "name": "Wood_Petrified_Trunk"
    },
    {
      "x": -4,
      "y": 1,
      "z": 0,
      "name": "Wood_Petrified_Trunk"
    },
    {
      "x": -4,
      "y": 2,
      "z": 0,
      "name": "Wood_Petrified_Trunk"
    },
    {
      "x": -4,
      "y": 3,
      "z": 0,
      "name": "Wood_Petrified_Trunk"
    },
    {
      "x": -4,
      "y": 4,
      "z": 0,
      "name": "Wood_Petrified_Trunk"
    },
    {
      "x": -4,
      "y": 5,
      "z": 0,
      "name": "Wood_Petrified_Trunk"
    },
    {
      "x": -4,
      "y": 6,
      "z": 0,
      "name": "Wood_Burnt_Trunk"
    },
    {
      "x": -4,
      "y": 7,
      "z": 0,
      "name": "Wood_Burnt_Trunk"
    },
    {
      "x": -4,
      "y": 0,
      "z": 1,
      "name": "Wood_Petrified_Trunk"
    },
    {
      "x": -4,
      "y": 1,
      "z": 1,
      "name": "Wood_Petrified_Trunk"
    },
    {
      "x": -4,
      "y": 2,
      "z": 1,
      "name": "Wood_Petrified_Trunk"
    },
    {
      "x": -4,
      "y": 3,
      "z": 1,
      "name": "Wood_Petrified_Trunk"
    },
    {
      "x": -4,
      "y": 4,
      "z": 1,
      "name": "Wood_Petrified_Trunk"
    },
    {
      "x": -4,
      "y": 5,
      "z": 1,
      "name": "Wood_Petrified_Trunk"
    },
    {
      "x": -4,
      "y": 6,
      "z": 1,
      "name": "Wood_Burnt_Trunk"
    },
    {
      "x": -4,
      "y": 7,
      "z": 1,
      "name": "Wood_Burnt_Trunk"
    },
    {
      "x": -4,
      "y": 0,
      "z": 2,
      "name": "Wood_Petrified_Trunk"
    },
    {
      "x": -4,
      "y": 1,
      "z": 2,
      "name": "Wood_Petrified_Trunk"
    },
    {
      "x": -4,
      "y": 2,
      "z": 2,
      "name": "Wood_Petrified_Trunk"
    },
    {
      "x": -4,
      "y": 3,
      "z": 2,
      "name": "Wood_Petrified_Trunk"
    },
    {
      "x": -4,
      "y": 0,
      "z": 3,
      "name": "Wood_Petrified_Trunk"
    },
    {
      "x": -4,
      "y": 1,
      "z": 3,
      "name": "Wood_Petrified_Trunk"
    },
    {
      "x": -4,
      "y": 2,
      "z": 3,
      "name": "Wood_Petrified_Trunk"
    },
    {
      "x": -4,
      "y": 0,
      "z": 4,
      "name": "Wood_Petrified_Trunk"
    },
    {
      "x": -3,
      "y": -1,
      "z": -6,
      "name": "Wood_Petrified_Trunk"
    },
    {
      "x": -3,
      "y": -1,
      "z": -5,
      "name": "Wood_Petrified_Trunk"
    },
    {
      "x": -3,
      "y": 0,
      "z": -4,
      "name": "Wood_Petrified_Trunk"
    },
    {
      "x": -3,
      "y": 1,
      "z": -4,
      "name": "Wood_Petrified_Trunk"
    },
    {
      "x": -3,
      "y": 0,
      "z": -3,
      "name": "Wood_Petrified_Trunk"
    },
    {
      "x": -3,
      "y": 1,
      "z": -3,
      "name": "Wood_Petrified_Trunk"
    },
    {
      "x": -3,
      "y": 2,
      "z": -3,
      "name": "Wood_Petrified_Trunk"
    },
    {
      "x": -3,
      "y": 3,
      "z": -3,
      "name": "Wood_Petrified_Trunk"
    },
    {
      "x": -3,
      "y": 4,
      "z": -3,
      "name": "Wood_Petrified_Trunk"
    },
    {
      "x": -3,
      "y": 5,
      "z": -3,
      "name": "Wood_Burnt_Trunk"
    },
    {
      "x": -3,
      "y": 6,
      "z": -3,
      "name": "Wood_Burnt_Trunk"
    },
    {
      "x": -3,
      "y": 0,
      "z": -2,
      "name": "Wood_Petrified_Trunk"
    },
    {
      "x": -3,
      "y": 1,
      "z": -2,
      "name": "Wood_Petrified_Trunk"
    },
    {
      "x": -3,
      "y": 2,
      "z": -2,
      "name": "Wood_Petrified_Trunk"
    },
    {
      "x": -3,
      "y": 3,
      "z": -2,
      "name": "Wood_Petrified_Trunk"
    },
    {
      "x": -3,
      "y": 4,
      "z": -2,
      "name": "Wood_Petrified_Trunk"
    },
    {
      "x": -3,
      "y": 5,
      "z": -2,
      "name": "Wood_Burnt_Trunk"
    },
    {
      "x": -3,
      "y": 0,
      "z": -1,
      "name": "Wood_Petrified_Trunk"
    },
    {
      "x": -3,
      "y": 1,
      "z": -1,
      "name": "Wood_Petrified_Trunk"
    },
    {
      "x": -3,
      "y": 2,
      "z": -1,
      "name": "Wood_Petrified_Trunk"
    },
    {
      "x": -3,
      "y": 0,
      "z": 0,
      "name": "Wood_Petrified_Trunk"
    },
    {
      "x": -3,
      "y": 1,
      "z": 0,
      "name": "Wood_Petrified_Trunk"
    },
    {
      "x": -3,
      "y": 2,
      "z": 0,
      "name": "Wood_Petrified_Trunk"
    },
    {
      "x": -3,
      "y": 0,
      "z": 1,
      "name": "Wood_Petrified_Trunk"
    },
    {
      "x": -3,
      "y": 1,
      "z": 1,
      "name": "Wood_Petrified_Trunk"
    },
    {
      "x": -3,
      "y": 2,
      "z": 1,
      "name": "Wood_Petrified_Trunk"
    },
    {
      "x": -3,
      "y": 0,
      "z": 2,
      "name": "Wood_Petrified_Trunk"
    },
    {
      "x": -3,
      "y": 1,
      "z": 2,
      "name": "Wood_Petrified_Trunk"
    },
    {
      "x": -3,
      "y": 2,
      "z": 2,
      "name": "Wood_Petrified_Trunk"
    },
    {
      "x": -3,
      "y": 3,
      "z": 2,
      "name": "Wood_Petrified_Trunk"
    },
    {
      "x": -3,
      "y": 4,
      "z": 2,
      "name": "Wood_Petrified_Trunk"
    },
    {
      "x": -3,
      "y": 5,
      "z": 2,
      "name": "Wood_Petrified_Trunk"
    },
    {
      "x": -3,
      "y": 6,
      "z": 2,
      "name": "Wood_Burnt_Trunk"
    },
    {
      "x": -3,
      "y": 7,
      "z": 2,
      "name": "Wood_Burnt_Trunk"
    },
    {
      "x": -3,
      "y": 0,
      "z": 3,
      "name": "Wood_Petrified_Trunk"
    },
    {
      "x": -3,
      "y": 1,
      "z": 3,
      "name": "Wood_Petrified_Trunk"
    },
    {
      "x": -3,
      "y": 2,
      "z": 3,
      "name": "Wood_Petrified_Trunk"
    },
    {
      "x": -3,
      "y": 0,
      "z": 4,
      "name": "Wood_Petrified_Trunk"
    },
    {
      "x": -3,
      "y": 1,
      "z": 4,
      "name": "Wood_Petrified_Trunk"
    },
    {
      "x": -2,
      "y": -1,
      "z": -6,
      "name": "Wood_Petrified_Trunk"
    },
    {
      "x": -2,
      "y": 0,
      "z": -5,
      "name": "Wood_Petrified_Trunk"
    },
    {
      "x": -2,
      "y": 1,
      "z": -5,
      "name": "Wood_Petrified_Trunk"
    },
    {
      "x": -2,
      "y": 0,
      "z": -4,
      "name": "Wood_Petrified_Trunk"
    },
    {
      "x": -2,
      "y": 1,
      "z": -4,
      "name": "Wood_Petrified_Trunk"
    },
    {
      "x": -2,
      "y": 2,
      "z": -4,
      "name": "Wood_Petrified_Trunk"
    },
    {
      "x": -2,
      "y": 3,
      "z": -4,
      "name": "Wood_Petrified_Trunk"
    },
    {
      "x": -2,
      "y": 4,
      "z": -4,
      "name": "Wood_Petrified_Trunk"
    },
    {
      "x": -2,
      "y": 5,
      "z": -4,
      "name": "Wood_Burnt_Trunk"
    },
    {
      "x": -2,
      "y": 6,
      "z": -4,
      "name": "Wood_Burnt_Trunk"
    },
    {
      "x": -2,
      "y": 7,
      "z": -4,
      "name": "Wood_Burnt_Trunk"
    },
    {
      "x": -2,
      "y": 0,
      "z": -3,
      "name": "Wood_Petrified_Trunk"
    },
    {
      "x": -2,
      "y": 1,
      "z": -3,
      "name": "Wood_Petrified_Trunk"
    },
    {
      "x": -2,
      "y": 2,
      "z": -3,
      "name": "Wood_Petrified_Trunk"
    },
    {
      "x": -2,
      "y": 3,
      "z": -3,
      "name": "Wood_Petrified_Trunk"
    },
    {
      "x": -2,
      "y": 4,
      "z": -3,
      "name": "Wood_Petrified_Trunk"
    },
    {
      "x": -2,
      "y": 5,
      "z": -3,
      "name": "Wood_Burnt_Trunk"
    },
    {
      "x": -2,
      "y": 0,
      "z": -2,
      "name": "Wood_Petrified_Trunk"
    },
    {
      "x": -2,
      "y": 1,
      "z": -2,
      "name": "Wood_Petrified_Trunk"
    },
    {
      "x": -2,
      "y": 0,
      "z": -1,
      "name": "Wood_Petrified_Trunk"
    },
    {
      "x": -2,
      "y": 0,
      "z": 0,
      "name": "Wood_Petrified_Trunk"
    },
    {
      "x": -2,
      "y": 0,
      "z": 1,
      "name": "Wood_Petrified_Trunk"
    },
    {
      "x": -2,
      "y": 0,
      "z": 2,
      "name": "Wood_Petrified_Trunk"
    },
    {
      "x": -2,
      "y": 1,
      "z": 2,
      "name": "Wood_Petrified_Trunk"
    },
    {
      "x": -2,
      "y": 0,
      "z": 3,
      "name": "Wood_Petrified_Trunk"
    },
    {
      "x": -2,
      "y": 1,
      "z": 3,
      "name": "Wood_Petrified_Trunk"
    },
    {
      "x": -2,
      "y": 2,
      "z": 3,
      "name": "Wood_Petrified_Trunk"
    },
    {
      "x": -2,
      "y": 3,
      "z": 3,
      "name": "Wood_Petrified_Trunk"
    },
    {
      "x": -2,
      "y": 4,
      "z": 3,
      "name": "Wood_Petrified_Trunk"
    },
    {
      "x": -2,
      "y": 5,
      "z": 3,
      "name": "Wood_Petrified_Trunk"
    },
    {
      "x": -2,
      "y": 6,
      "z": 3,
      "name": "Wood_Burnt_Trunk"
    },
    {
      "x": -2,
      "y": 7,
      "z": 3,
      "name": "Wood_Burnt_Trunk"
    },
    {
      "x": -2,
      "y": 0,
      "z": 4,
      "name": "Wood_Petrified_Trunk"
    },
    {
      "x": -2,
      "y": 1,
      "z": 4,
      "name": "Wood_Petrified_Trunk"
    },
    {
      "x": -2,
      "y": 2,
      "z": 4,
      "name": "Wood_Petrified_Trunk"
    },
    {
      "x": -1,
      "y": -1,
      "z": -6,
      "name": "Wood_Petrified_Trunk"
    },
    {
      "x": -1,
      "y": 0,
      "z": -6,
      "name": "Wood_Petrified_Trunk"
    },
    {
      "x": -1,
      "y": 0,
      "z": -5,
      "name": "Wood_Petrified_Trunk"
    },
    {
      "x": -1,
      "y": 1,
      "z": -5,
      "name": "Wood_Petrified_Trunk"
    },
    {
      "x": -1,
      "y": 2,
      "z": -5,
      "name": "Wood_Petrified_Trunk"
    },
    {
      "x": -1,
      "y": 0,
      "z": -4,
      "name": "Wood_Petrified_Trunk"
    },
    {
      "x": -1,
      "y": 1,
      "z": -4,
      "name": "Wood_Petrified_Trunk"
    },
    {
      "x": -1,
      "y": 2,
      "z": -4,
      "name": "Wood_Petrified_Trunk"
    },
    {
      "x": -1,
      "y": 3,
      "z": -4,
      "name": "Wood_Petrified_Trunk"
    },
    {
      "x": -1,
      "y": 4,
      "z": -4,
      "name": "Wood_Petrified_Trunk"
    },
    {
      "x": -1,
      "y": 5,
      "z": -4,
      "name": "Wood_Petrified_Trunk"
    },
    {
      "x": -1,
      "y": 6,
      "z": -4,
      "name": "Wood_Burnt_Trunk"
    },
    {
      "x": -1,
      "y": 7,
      "z": -4,
      "name": "Wood_Burnt_Trunk"
    },
    {
      "x": -1,
      "y": 0,
      "z": -3,
      "name": "Wood_Petrified_Trunk"
    },
    {
      "x": -1,
      "y": 1,
      "z": -3,
      "name": "Wood_Petrified_Trunk"
    },
    {
      "x": -1,
      "y": 2,
      "z": -3,
      "name": "Wood_Petrified_Trunk"
    },
    {
      "x": -1,
      "y": 0,
      "z": -2,
      "name": "Wood_Petrified_Trunk"
    },
    {
      "x": -1,
      "y": 0,
      "z": -1,
      "name": "Wood_Petrified_Trunk"
    },
    {
      "x": -1,
      "y": 0,
      "z": 1,
      "name": "Wood_Petrified_Trunk"
    },
    {
      "x": -1,
      "y": 0,
      "z": 2,
      "name": "Wood_Petrified_Trunk"
    },
    {
      "x": -1,
      "y": 0,
      "z": 3,
      "name": "Wood_Petrified_Trunk"
    },
    {
      "x": -1,
      "y": 1,
      "z": 3,
      "name": "Wood_Petrified_Trunk"
    },
    {
      "x": -1,
      "y": 2,
      "z": 3,
      "name": "Wood_Petrified_Trunk"
    },
    {
      "x": -1,
      "y": 5,
      "z": 3,
      "name": "Wood_Petrified_Trunk"
    },
    {
      "x": -1,
      "y": 6,
      "z": 3,
      "name": "Wood_Burnt_Trunk"
    },
    {
      "x": -1,
      "y": 7,
      "z": 3,
      "name": "Wood_Burnt_Trunk"
    },
    {
      "x": -1,
      "y": 8,
      "z": 3,
      "name": "Wood_Burnt_Trunk"
    },
    {
      "x": -1,
      "y": 0,
      "z": 4,
      "name": "Wood_Petrified_Trunk"
    },
    {
      "x": -1,
      "y": 1,
      "z": 4,
      "name": "Wood_Petrified_Trunk"
    },
    {
      "x": -1,
      "y": 2,
      "z": 4,
      "name": "Wood_Petrified_Trunk"
    },
    {
      "x": -1,
      "y": 3,
      "z": 4,
      "name": "Wood_Petrified_Trunk"
    },
    {
      "x": -1,
      "y": 4,
      "z": 4,
      "name": "Wood_Petrified_Trunk"
    },
    {
      "x": -1,
      "y": 8,
      "z": 4,
      "name": "Wood_Burnt_Trunk"
    },
    {
      "x": 0,
      "y": 0,
      "z": -6,
      "name": "Wood_Petrified_Trunk"
    },
    {
      "x": 0,
      "y": 0,
      "z": -5,
      "name": "Wood_Petrified_Trunk"
    },
    {
      "x": 0,
      "y": 1,
      "z": -5,
      "name": "Wood_Petrified_Trunk"
    },
    {
      "x": 0,
      "y": 2,
      "z": -5,
      "name": "Wood_Petrified_Trunk"
    },
    {
      "x": 0,
      "y": 3,
      "z": -5,
      "name": "Wood_Petrified_Trunk"
    },
    {
      "x": 0,
      "y": 5,
      "z": -5,
      "name": "Wood_Petrified_Trunk"
    },
    {
      "x": 0,
      "y": 6,
      "z": -5,
      "name": "Wood_Burnt_Trunk"
    },
    {
      "x": 0,
      "y": 0,
      "z": -4,
      "name": "Wood_Petrified_Trunk"
    },
    {
      "x": 0,
      "y": 1,
      "z": -4,
      "name": "Wood_Petrified_Trunk"
    },
    {
      "x": 0,
      "y": 2,
      "z": -4,
      "name": "Wood_Petrified_Trunk"
    },
    {
      "x": 0,
      "y": 3,
      "z": -4,
      "name": "Wood_Petrified_Trunk"
    },
    {
      "x": 0,
      "y": 4,
      "z": -4,
      "name": "Wood_Petrified_Trunk"
    },
    {
      "x": 0,
      "y": 5,
      "z": -4,
      "name": "Wood_Petrified_Trunk"
    },
    {
      "x": 0,
      "y": 6,
      "z": -4,
      "name": "Wood_Burnt_Trunk"
    },
    {
      "x": 0,
      "y": 7,
      "z": -4,
      "name": "Wood_Burnt_Trunk"
    },
    {
      "x": 0,
      "y": 0,
      "z": -3,
      "name": "Wood_Petrified_Trunk"
    },
    {
      "x": 0,
      "y": 2,
      "z": -3,
      "name": "Wood_Petrified_Trunk"
    },
    {
      "x": 0,
      "y": 0,
      "z": -2,
      "name": "Wood_Petrified_Trunk"
    },
    {
      "x": 0,
      "y": 0,
      "z": 2,
      "name": "Wood_Petrified_Trunk"
    },
    {
      "x": 0,
      "y": 0,
      "z": 3,
      "name": "Wood_Petrified_Trunk"
    },
    {
      "x": 0,
      "y": 2,
      "z": 3,
      "name": "Wood_Petrified_Trunk"
    },
    {
      "x": 0,
      "y": 8,
      "z": 3,
      "name": "Wood_Burnt_Trunk"
    },
    {
      "x": 0,
      "y": 0,
      "z": 4,
      "name": "Wood_Petrified_Trunk"
    },
    {
      "x": 0,
      "y": 1,
      "z": 4,
      "name": "Wood_Petrified_Trunk"
    },
    {
      "x": 0,
      "y": 2,
      "z": 4,
      "name": "Wood_Petrified_Trunk"
    },
    {
      "x": 0,
      "y": 3,
      "z": 4,
      "name": "Wood_Petrified_Trunk"
    },
    {
      "x": 0,
      "y": 4,
      "z": 4,
      "name": "Wood_Petrified_Trunk"
    },
    {
      "x": 0,
      "y": 5,
      "z": 4,
      "name": "Wood_Burnt_Trunk"
    },
    {
      "x": 0,
      "y": 6,
      "z": 4,
      "name": "Wood_Burnt_Trunk"
    },
    {
      "x": 0,
      "y": 7,
      "z": 4,
      "name": "Wood_Burnt_Trunk"
    },
    {
      "x": 0,
      "y": 8,
      "z": 4,
      "name": "Wood_Burnt_Trunk"
    },
    {
      "x": 0,
      "y": 0,
      "z": 5,
      "name": "Wood_Petrified_Trunk"
    },
    {
      "x": 0,
      "y": 1,
      "z": 5,
      "name": "Wood_Petrified_Trunk"
    },
    {
      "x": 0,
      "y": 2,
      "z": 5,
      "name": "Wood_Petrified_Trunk"
    },
    {
      "x": 0,
      "y": 3,
      "z": 5,
      "name": "Wood_Petrified_Trunk"
    },
    {
      "x": 0,
      "y": 4,
      "z": 5,
      "name": "Wood_Petrified_Trunk"
    },
    {
      "x": 0,
      "y": 5,
      "z": 5,
      "name": "Wood_Burnt_Trunk"
    },
    {
      "x": 0,
      "y": 6,
      "z": 5,
      "name": "Wood_Burnt_Trunk"
    },
    {
      "x": 1,
      "y": 0,
      "z": -5,
      "name": "Wood_Petrified_Trunk"
    },
    {
      "x": 1,
      "y": 1,
      "z": -5,
      "name": "Wood_Petrified_Trunk"
    },
    {
      "x": 1,
      "y": 2,
      "z": -5,
      "name": "Wood_Petrified_Trunk"
    },
    {
      "x": 1,
      "y": 3,
      "z": -5,
      "name": "Wood_Petrified_Trunk"
    },
    {
      "x": 1,
      "y": 4,
      "z": -5,
      "name": "Wood_Petrified_Trunk"
    },
    {
      "x": 1,
      "y": 5,
      "z": -5,
      "name": "Wood_Petrified_Trunk"
    },
    {
      "x": 1,
      "y": 6,
      "z": -5,
      "name": "Wood_Burnt_Trunk"
    },
    {
      "x": 1,
      "y": 0,
      "z": -4,
      "name": "Wood_Petrified_Trunk"
    },
    {
      "x": 1,
      "y": 1,
      "z": -4,
      "name": "Wood_Petrified_Trunk"
    },
    {
      "x": 1,
      "y": 2,
      "z": -4,
      "name": "Wood_Petrified_Trunk"
    },
    {
      "x": 1,
      "y": 3,
      "z": -4,
      "name": "Wood_Petrified_Trunk"
    },
    {
      "x": 1,
      "y": 4,
      "z": -4,
      "name": "Wood_Petrified_Trunk"
    },
    {
      "x": 1,
      "y": 5,
      "z": -4,
      "name": "Wood_Petrified_Trunk"
    },
    {
      "x": 1,
      "y": 6,
      "z": -4,
      "name": "Wood_Burnt_Trunk"
    },
    {
      "x": 1,
      "y": 7,
      "z": -4,
      "name": "Wood_Burnt_Trunk"
    },
    {
      "x": 1,
      "y": 0,
      "z": -3,
      "name": "Wood_Petrified_Trunk"
    },
    {
      "x": 1,
      "y": 2,
      "z": -3,
      "name": "Wood_Petrified_Trunk"
    },
    {
      "x": 1,
      "y": 0,
      "z": -2,
      "name": "Wood_Petrified_Trunk"
    },
    {
      "x": 1,
      "y": 0,
      "z": -1,
      "name": "Wood_Petrified_Trunk"
    },
    {
      "x": 1,
      "y": 0,
      "z": 1,
      "name": "Wood_Petrified_Trunk"
    },
    {
      "x": 1,
      "y": 0,
      "z": 2,
      "name": "Wood_Petrified_Trunk"
    },
    {
      "x": 1,
      "y": 0,
      "z": 3,
      "name": "Wood_Petrified_Trunk"
    },
    {
      "x": 1,
      "y": 2,
      "z": 3,
      "name": "Wood_Petrified_Trunk"
    },
    {
      "x": 1,
      "y": 8,
      "z": 3,
      "name": "Wood_Burnt_Trunk"
    },
    {
      "x": 1,
      "y": 9,
      "z": 3,
      "name": "Wood_Burnt_Trunk"
    },
    {
      "x": 1,
      "y": 0,
      "z": 4,
      "name": "Wood_Petrified_Trunk"
    },
    {
      "x": 1,
      "y": 2,
      "z": 4,
      "name": "Wood_Petrified_Trunk"
    },
    {
      "x": 1,
      "y": 3,
      "z": 4,
      "name": "Wood_Petrified_Trunk"
    },
    {
      "x": 1,
      "y": 4,
      "z": 4,
      "name": "Wood_Petrified_Trunk"
    },
    {
      "x": 1,
      "y": 5,
      "z": 4,
      "name": "Wood_Burnt_Trunk"
    },
    {
      "x": 1,
      "y": 6,
      "z": 4,
      "name": "Wood_Burnt_Trunk"
    },
    {
      "x": 1,
      "y": 7,
      "z": 4,
      "name": "Wood_Burnt_Trunk"
    },
    {
      "x": 1,
      "y": 8,
      "z": 4,
      "name": "Wood_Burnt_Trunk"
    },
    {
      "x": 1,
      "y": 9,
      "z": 4,
      "name": "Wood_Burnt_Trunk"
    },
    {
      "x": 1,
      "y": 1,
      "z": 5,
      "name": "Wood_Petrified_Trunk"
    },
    {
      "x": 1,
      "y": 2,
      "z": 5,
      "name": "Wood_Petrified_Trunk"
    },
    {
      "x": 1,
      "y": 3,
      "z": 5,
      "name": "Wood_Petrified_Trunk"
    },
    {
      "x": 1,
      "y": 4,
      "z": 5,
      "name": "Wood_Petrified_Trunk"
    },
    {
      "x": 1,
      "y": 5,
      "z": 5,
      "name": "Wood_Burnt_Trunk"
    },
    {
      "x": 1,
      "y": 6,
      "z": 5,
      "name": "Wood_Burnt_Trunk"
    },
    {
      "x": 1,
      "y": 7,
      "z": 5,
      "name": "Wood_Burnt_Trunk"
    },
    {
      "x": 1,
      "y": 8,
      "z": 5,
      "name": "Wood_Burnt_Trunk"
    },
    {
      "x": 2,
      "y": 0,
      "z": -5,
      "name": "Wood_Petrified_Trunk"
    },
    {
      "x": 2,
      "y": 0,
      "z": -4,
      "name": "Wood_Petrified_Trunk"
    },
    {
      "x": 2,
      "y": 1,
      "z": -4,
      "name": "Wood_Petrified_Trunk"
    },
    {
      "x": 2,
      "y": 2,
      "z": -4,
      "name": "Wood_Petrified_Trunk"
    },
    {
      "x": 2,
      "y": 3,
      "z": -4,
      "name": "Wood_Petrified_Trunk"
    },
    {
      "x": 2,
      "y": 4,
      "z": -4,
      "name": "Wood_Petrified_Trunk"
    },
    {
      "x": 2,
      "y": 5,
      "z": -4,
      "name": "Wood_Petrified_Trunk"
    },
    {
      "x": 2,
      "y": 6,
      "z": -4,
      "name": "Wood_Burnt_Trunk"
    },
    {
      "x": 2,
      "y": 7,
      "z": -4,
      "name": "Wood_Burnt_Trunk"
    },
    {
      "x": 2,
      "y": 0,
      "z": -3,
      "name": "Wood_Petrified_Trunk"
    },
    {
      "x": 2,
      "y": 1,
      "z": -3,
      "name": "Wood_Petrified_Trunk"
    },
    {
      "x": 2,
      "y": 2,
      "z": -3,
      "name": "Wood_Petrified_Trunk"
    },
    {
      "x": 2,
      "y": 3,
      "z": -3,
      "name": "Wood_Petrified_Trunk"
    },
    {
      "x": 2,
      "y": 4,
      "z": -3,
      "name": "Wood_Petrified_Trunk"
    },
    {
      "x": 2,
      "y": 5,
      "z": -3,
      "name": "Wood_Petrified_Trunk"
    },
    {
      "x": 2,
      "y": 6,
      "z": -3,
      "name": "Wood_Burnt_Trunk"
    },
    {
      "x": 2,
      "y": 7,
      "z": -3,
      "name": "Wood_Burnt_Trunk"
    },
    {
      "x": 2,
      "y": 0,
      "z": -2,
      "name": "Wood_Petrified_Trunk"
    },
    {
      "x": 2,
      "y": 1,
      "z": -2,
      "name": "Wood_Petrified_Trunk"
    },
    {
      "x": 2,
      "y": 0,
      "z": -1,
      "name": "Wood_Petrified_Trunk"
    },
    {
      "x": 2,
      "y": 0,
      "z": 0,
      "name": "Wood_Petrified_Trunk"
    },
    {
      "x": 2,
      "y": 0,
      "z": 1,
      "name": "Wood_Petrified_Trunk"
    },
    {
      "x": 2,
      "y": 0,
      "z": 2,
      "name": "Wood_Petrified_Trunk"
    },
    {
      "x": 2,
      "y": 1,
      "z": 3,
      "name": "Wood_Petrified_Trunk"
    },
    {
      "x": 2,
      "y": 2,
      "z": 3,
      "name": "Wood_Petrified_Trunk"
    },
    {
      "x": 2,
      "y": 3,
      "z": 3,
      "name": "Wood_Petrified_Trunk"
    },
    {
      "x": 2,
      "y": 4,
      "z": 3,
      "name": "Wood_Petrified_Trunk"
    },
    {
      "x": 2,
      "y": 5,
      "z": 3,
      "name": "Wood_Petrified_Trunk"
    },
    {
      "x": 2,
      "y": 6,
      "z": 3,
      "name": "Wood_Petrified_Trunk"
    },
    {
      "x": 2,
      "y": 7,
      "z": 3,
      "name": "Wood_Petrified_Trunk"
    },
    {
      "x": 2,
      "y": 8,
      "z": 3,
      "name": "Wood_Burnt_Trunk"
    },
    {
      "x": 2,
      "y": 9,
      "z": 3,
      "name": "Wood_Burnt_Trunk"
    },
    {
      "x": 2,
      "y": 1,
      "z": 4,
      "name": "Wood_Petrified_Trunk"
    },
    {
      "x": 2,
      "y": 2,
      "z": 4,
      "name": "Wood_Petrified_Trunk"
    },
    {
      "x": 2,
      "y": 3,
      "z": 4,
      "name": "Wood_Petrified_Trunk"
    },
    {
      "x": 2,
      "y": 4,
      "z": 4,
      "name": "Wood_Petrified_Trunk"
    },
    {
      "x": 2,
      "y": 5,
      "z": 4,
      "name": "Wood_Petrified_Trunk"
    },
    {
      "x": 2,
      "y": 6,
      "z": 4,
      "name": "Wood_Petrified_Trunk"
    },
    {
      "x": 2,
      "y": 7,
      "z": 4,
      "name": "Wood_Petrified_Trunk"
    },
    {
      "x": 2,
      "y": 8,
      "z": 4,
      "name": "Wood_Burnt_Trunk"
    },
    {
      "x": 2,
      "y": 9,
      "z": 4,
      "name": "Wood_Burnt_Trunk"
    },
    {
      "x": 2,
      "y": 10,
      "z": 4,
      "name": "Wood_Burnt_Trunk"
    },
    {
      "x": 2,
      "y": 1,
      "z": 5,
      "name": "Wood_Petrified_Trunk"
    },
    {
      "x": 2,
      "y": 2,
      "z": 5,
      "name": "Wood_Petrified_Trunk"
    },
    {
      "x": 2,
      "y": 3,
      "z": 5,
      "name": "Wood_Petrified_Trunk"
    },
    {
      "x": 2,
      "y": 4,
      "z": 5,
      "name": "Wood_Petrified_Trunk"
    },
    {
      "x": 2,
      "y": 5,
      "z": 5,
      "name": "Wood_Petrified_Trunk"
    },
    {
      "x": 2,
      "y": 6,
      "z": 5,
      "name": "Wood_Petrified_Trunk"
    },
    {
      "x": 2,
      "y": 7,
      "z": 5,
      "name": "Wood_Petrified_Trunk"
    },
    {
      "x": 2,
      "y": 8,
      "z": 5,
      "name": "Wood_Burnt_Trunk"
    },
    {
      "x": 3,
      "y": 0,
      "z": -4,
      "name": "Wood_Petrified_Trunk"
    },
    {
      "x": 3,
      "y": 1,
      "z": -4,
      "name": "Wood_Petrified_Trunk"
    },
    {
      "x": 3,
      "y": 2,
      "z": -4,
      "name": "Wood_Petrified_Trunk"
    },
    {
      "x": 3,
      "y": 3,
      "z": -4,
      "name": "Wood_Petrified_Trunk"
    },
    {
      "x": 3,
      "y": 4,
      "z": -4,
      "name": "Wood_Petrified_Trunk"
    },
    {
      "x": 3,
      "y": 5,
      "z": -4,
      "name": "Wood_Petrified_Trunk"
    },
    {
      "x": 3,
      "y": 6,
      "z": -4,
      "name": "Wood_Burnt_Trunk"
    },
    {
      "x": 3,
      "y": 0,
      "z": -3,
      "name": "Wood_Petrified_Trunk"
    },
    {
      "x": 3,
      "y": 2,
      "z": -3,
      "name": "Wood_Petrified_Trunk"
    },
    {
      "x": 3,
      "y": 3,
      "z": -3,
      "name": "Wood_Petrified_Trunk"
    },
    {
      "x": 3,
      "y": 4,
      "z": -3,
      "name": "Wood_Petrified_Trunk"
    },
    {
      "x": 3,
      "y": 5,
      "z": -3,
      "name": "Wood_Petrified_Trunk"
    },
    {
      "x": 3,
      "y": 6,
      "z": -3,
      "name": "Wood_Burnt_Trunk"
    },
    {
      "x": 3,
      "y": 7,
      "z": -3,
      "name": "Wood_Burnt_Trunk"
    },
    {
      "x": 3,
      "y": 8,
      "z": -3,
      "name": "Wood_Burnt_Trunk"
    },
    {
      "x": 3,
      "y": 0,
      "z": -2,
      "name": "Wood_Petrified_Trunk"
    },
    {
      "x": 3,
      "y": 2,
      "z": -2,
      "name": "Wood_Petrified_Trunk"
    },
    {
      "x": 3,
      "y": 3,
      "z": -2,
      "name": "Wood_Petrified_Trunk"
    },
    {
      "x": 3,
      "y": 4,
      "z": -2,
      "name": "Wood_Petrified_Trunk"
    },
    {
      "x": 3,
      "y": 5,
      "z": -2,
      "name": "Wood_Petrified_Trunk"
    },
    {
      "x": 3,
      "y": 6,
      "z": -2,
      "name": "Wood_Petrified_Trunk"
    },
    {
      "x": 3,
      "y": 7,
      "z": -2,
      "name": "Wood_Burnt_Trunk"
    },
    {
      "x": 3,
      "y": 8,
      "z": -2,
      "name": "Wood_Burnt_Trunk"
    },
    {
      "x": 3,
      "y": 9,
      "z": -2,
      "name": "Wood_Burnt_Trunk"
    },
    {
      "x": 3,
      "y": 0,
      "z": -1,
      "name": "Wood_Petrified_Trunk"
    },
    {
      "x": 3,
      "y": 1,
      "z": -1,
      "name": "Wood_Petrified_Trunk"
    },
    {
      "x": 3,
      "y": 2,
      "z": -1,
      "name": "Wood_Petrified_Trunk"
    },
    {
      "x": 3,
      "y": 0,
      "z": 0,
      "name": "Wood_Petrified_Trunk"
    },
    {
      "x": 3,
      "y": 2,
      "z": 0,
      "name": "Wood_Petrified_Trunk"
    },
    {
      "x": 3,
      "y": 0,
      "z": 1,
      "name": "Wood_Petrified_Trunk"
    },
    {
      "x": 3,
      "y": 2,
      "z": 1,
      "name": "Wood_Petrified_Trunk"
    },
    {
      "x": 3,
      "y": 1,
      "z": 2,
      "name": "Wood_Petrified_Trunk"
    },
    {
      "x": 3,
      "y": 2,
      "z": 2,
      "name": "Wood_Petrified_Trunk"
    },
    {
      "x": 3,
      "y": 3,
      "z": 2,
      "name": "Wood_Petrified_Trunk"
    },
    {
      "x": 3,
      "y": 4,
      "z": 2,
      "name": "Wood_Petrified_Trunk"
    },
    {
      "x": 3,
      "y": 5,
      "z": 2,
      "name": "Wood_Petrified_Trunk"
    },
    {
      "x": 3,
      "y": 6,
      "z": 2,
      "name": "Wood_Petrified_Trunk"
    },
    {
      "x": 3,
      "y": 7,
      "z": 2,
      "name": "Wood_Petrified_Trunk"
    },
    {
      "x": 3,
      "y": 8,
      "z": 2,
      "name": "Wood_Petrified_Trunk"
    },
    {
      "x": 3,
      "y": 9,
      "z": 2,
      "name": "Wood_Burnt_Trunk"
    },
    {
      "x": 3,
      "y": 10,
      "z": 2,
      "name": "Wood_Burnt_Trunk"
    },
    {
      "x": 3,
      "y": 1,
      "z": 3,
      "name": "Wood_Petrified_Trunk"
    },
    {
      "x": 3,
      "y": 2,
      "z": 3,
      "name": "Wood_Petrified_Trunk"
    },
    {
      "x": 3,
      "y": 3,
      "z": 3,
      "name": "Wood_Petrified_Trunk"
    },
    {
      "x": 3,
      "y": 4,
      "z": 3,
      "name": "Wood_Petrified_Trunk"
    },
    {
      "x": 3,
      "y": 5,
      "z": 3,
      "name": "Wood_Petrified_Trunk"
    },
    {
      "x": 3,
      "y": 6,
      "z": 3,
      "name": "Wood_Petrified_Trunk"
    },
    {
      "x": 3,
      "y": 7,
      "z": 3,
      "name": "Wood_Petrified_Trunk"
    },
    {
      "x": 3,
      "y": 8,
      "z": 3,
      "name": "Wood_Petrified_Trunk"
    },
    {
      "x": 3,
      "y": 9,
      "z": 3,
      "name": "Wood_Burnt_Trunk"
    },
    {
      "x": 3,
      "y": 10,
      "z": 3,
      "name": "Wood_Burnt_Trunk"
    },
    {
      "x": 3,
      "y": 1,
      "z": 4,
      "name": "Wood_Petrified_Trunk"
    },
    {
      "x": 3,
      "y": 2,
      "z": 4,
      "name": "Wood_Petrified_Trunk"
    },
    {
      "x": 3,
      "y": 3,
      "z": 4,
      "name": "Wood_Petrified_Trunk"
    },
    {
      "x": 3,
      "y": 4,
      "z": 4,
      "name": "Wood_Petrified_Trunk"
    },
    {
      "x": 3,
      "y": 5,
      "z": 4,
      "name": "Wood_Petrified_Trunk"
    },
    {
      "x": 3,
      "y": 6,
      "z": 4,
      "name": "Wood_Petrified_Trunk"
    },
    {
      "x": 3,
      "y": 7,
      "z": 4,
      "name": "Wood_Petrified_Trunk"
    },
    {
      "x": 3,
      "y": 8,
      "z": 4,
      "name": "Wood_Petrified_Trunk"
    },
    {
      "x": 3,
      "y": 9,
      "z": 4,
      "name": "Wood_Burnt_Trunk"
    },
    {
      "x": 3,
      "y": 10,
      "z": 4,
      "name": "Wood_Burnt_Trunk"
    },
    {
      "x": 3,
      "y": 1,
      "z": 5,
      "name": "Wood_Petrified_Trunk"
    },
    {
      "x": 3,
      "y": 2,
      "z": 5,
      "name": "Wood_Petrified_Trunk"
    },
    {
      "x": 3,
      "y": 3,
      "z": 5,
      "name": "Wood_Petrified_Trunk"
    },
    {
      "x": 3,
      "y": 4,
      "z": 5,
      "name": "Wood_Petrified_Trunk"
    },
    {
      "x": 3,
      "y": 5,
      "z": 5,
      "name": "Wood_Petrified_Trunk"
    },
    {
      "x": 3,
      "y": 6,
      "z": 5,
      "name": "Wood_Petrified_Trunk"
    },
    {
      "x": 3,
      "y": 7,
      "z": 5,
      "name": "Wood_Petrified_Trunk"
    },
    {
      "x": 3,
      "y": 8,
      "z": 5,
      "name": "Wood_Petrified_Trunk"
    },
    {
      "x": 4,
      "y": 0,
      "z": -3,
      "name": "Wood_Petrified_Trunk"
    },
    {
      "x": 4,
      "y": 1,
      "z": -3,
      "name": "Wood_Petrified_Trunk"
    },
    {
      "x": 4,
      "y": 2,
      "z": -3,
      "name": "Wood_Petrified_Trunk"
    },
    {
      "x": 4,
      "y": 3,
      "z": -3,
      "name": "Wood_Petrified_Trunk"
    },
    {
      "x": 4,
      "y": 4,
      "z": -3,
      "name": "Wood_Petrified_Trunk"
    },
    {
      "x": 4,
      "y": 5,
      "z": -3,
      "name": "Wood_Petrified_Trunk"
    },
    {
      "x": 4,
      "y": 6,
      "z": -3,
      "name": "Wood_Petrified_Trunk"
    },
    {
      "x": 4,
      "y": 7,
      "z": -3,
      "name": "Wood_Burnt_Trunk"
    },
    {
      "x": 4,
      "y": 8,
      "z": -3,
      "name": "Wood_Burnt_Trunk"
    },
    {
      "x": 4,
      "y": 0,
      "z": -2,
      "name": "Wood_Petrified_Trunk"
    },
    {
      "x": 4,
      "y": 2,
      "z": -2,
      "name": "Wood_Petrified_Trunk"
    },
    {
      "x": 4,
      "y": 3,
      "z": -2,
      "name": "Wood_Petrified_Trunk"
    },
    {
      "x": 4,
      "y": 4,
      "z": -2,
      "name": "Wood_Petrified_Trunk"
    },
    {
      "x": 4,
      "y": 5,
      "z": -2,
      "name": "Wood_Petrified_Trunk"
    },
    {
      "x": 4,
      "y": 6,
      "z": -2,
      "name": "Wood_Petrified_Trunk"
    },
    {
      "x": 4,
      "y": 7,
      "z": -2,
      "name": "Wood_Burnt_Trunk"
    },
    {
      "x": 4,
      "y": 8,
      "z": -2,
      "name": "Wood_Burnt_Trunk"
    },
    {
      "x": 4,
      "y": 9,
      "z": -2,
      "name": "Wood_Burnt_Trunk"
    },
    {
      "x": 4,
      "y": 10,
      "z": -2,
      "name": "Wood_Burnt_Trunk"
    },
    {
      "x": 4,
      "y": 11,
      "z": -2,
      "name": "Wood_Burnt_Trunk"
    },
    {
      "x": 4,
      "y": 0,
      "z": -1,
      "name": "Wood_Petrified_Trunk"
    },
    {
      "x": 4,
      "y": 2,
      "z": -1,
      "name": "Wood_Petrified_Trunk"
    },
    {
      "x": 4,
      "y": 3,
      "z": -1,
      "name": "Wood_Petrified_Trunk"
    },
    {
      "x": 4,
      "y": 4,
      "z": -1,
      "name": "Wood_Petrified_Trunk"
    },
    {
      "x": 4,
      "y": 5,
      "z": -1,
      "name": "Wood_Petrified_Trunk"
    },
    {
      "x": 4,
      "y": 6,
      "z": -1,
      "name": "Wood_Petrified_Trunk"
    },
    {
      "x": 4,
      "y": 7,
      "z": -1,
      "name": "Wood_Petrified_Trunk"
    },
    {
      "x": 4,
      "y": 8,
      "z": -1,
      "name": "Wood_Burnt_Trunk"
    },
    {
      "x": 4,
      "y": 9,
      "z": -1,
      "name": "Wood_Burnt_Trunk"
    },
    {
      "x": 4,
      "y": 10,
      "z": -1,
      "name": "Wood_Burnt_Trunk"
    },
    {
      "x": 4,
      "y": 11,
      "z": -1,
      "name": "Wood_Burnt_Trunk"
    },
    {
      "x": 4,
      "y": 0,
      "z": 0,
      "name": "Wood_Petrified_Trunk"
    },
    {
      "x": 4,
      "y": 1,
      "z": 0,
      "name": "Wood_Petrified_Trunk"
    },
    {
      "x": 4,
      "y": 2,
      "z": 0,
      "name": "Wood_Petrified_Trunk"
    },
    {
      "x": 4,
      "y": 3,
      "z": 0,
      "name": "Wood_Petrified_Trunk"
    },
    {
      "x": 4,
      "y": 4,
      "z": 0,
      "name": "Wood_Petrified_Trunk"
    },
    {
      "x": 4,
      "y": 5,
      "z": 0,
      "name": "Wood_Petrified_Trunk"
    },
    {
      "x": 4,
      "y": 6,
      "z": 0,
      "name": "Wood_Petrified_Trunk"
    },
    {
      "x": 4,
      "y": 7,
      "z": 0,
      "name": "Wood_Petrified_Trunk"
    },
    {
      "x": 4,
      "y": 8,
      "z": 0,
      "name": "Wood_Petrified_Trunk"
    },
    {
      "x": 4,
      "y": 9,
      "z": 0,
      "name": "Wood_Petrified_Trunk"
    },
    {
      "x": 4,
      "y": 10,
      "z": 0,
      "name": "Wood_Burnt_Trunk"
    },
    {
      "x": 4,
      "y": 11,
      "z": 0,
      "name": "Wood_Burnt_Trunk"
    },
    {
      "x": 4,
      "y": 1,
      "z": 1,
      "name": "Wood_Petrified_Trunk"
    },
    {
      "x": 4,
      "y": 2,
      "z": 1,
      "name": "Wood_Petrified_Trunk"
    },
    {
      "x": 4,
      "y": 3,
      "z": 1,
      "name": "Wood_Petrified_Trunk"
    },
    {
      "x": 4,
      "y": 4,
      "z": 1,
      "name": "Wood_Petrified_Trunk"
    },
    {
      "x": 4,
      "y": 5,
      "z": 1,
      "name": "Wood_Petrified_Trunk"
    },
    {
      "x": 4,
      "y": 6,
      "z": 1,
      "name": "Wood_Petrified_Trunk"
    },
    {
      "x": 4,
      "y": 7,
      "z": 1,
      "name": "Wood_Petrified_Trunk"
    },
    {
      "x": 4,
      "y": 8,
      "z": 1,
      "name": "Wood_Petrified_Trunk"
    },
    {
      "x": 4,
      "y": 9,
      "z": 1,
      "name": "Wood_Burnt_Trunk"
    },
    {
      "x": 4,
      "y": 10,
      "z": 1,
      "name": "Wood_Burnt_Trunk"
    },
    {
      "x": 4,
      "y": 11,
      "z": 1,
      "name": "Wood_Burnt_Trunk"
    },
    {
      "x": 4,
      "y": 1,
      "z": 2,
      "name": "Wood_Petrified_Trunk"
    },
    {
      "x": 4,
      "y": 2,
      "z": 2,
      "name": "Wood_Petrified_Trunk"
    },
    {
      "x": 4,
      "y": 3,
      "z": 2,
      "name": "Wood_Petrified_Trunk"
    },
    {
      "x": 4,
      "y": 4,
      "z": 2,
      "name": "Wood_Petrified_Trunk"
    },
    {
      "x": 4,
      "y": 5,
      "z": 2,
      "name": "Wood_Petrified_Trunk"
    },
    {
      "x": 4,
      "y": 6,
      "z": 2,
      "name": "Wood_Petrified_Trunk"
    },
    {
      "x": 4,
      "y": 7,
      "z": 2,
      "name": "Wood_Petrified_Trunk"
    },
    {
      "x": 4,
      "y": 8,
      "z": 2,
      "name": "Wood_Petrified_Trunk"
    },
    {
      "x": 4,
      "y": 9,
      "z": 2,
      "name": "Wood_Burnt_Trunk"
    },
    {
      "x": 4,
      "y": 10,
      "z": 2,
      "name": "Wood_Burnt_Trunk"
    },
    {
      "x": 4,
      "y": 2,
      "z": 3,
      "name": "Wood_Petrified_Trunk"
    },
    {
      "x": 4,
      "y": 3,
      "z": 3,
      "name": "Wood_Petrified_Trunk"
    },
    {
      "x": 4,
      "y": 4,
      "z": 3,
      "name": "Wood_Petrified_Trunk"
    },
    {
      "x": 4,
      "y": 5,
      "z": 3,
      "name": "Wood_Petrified_Trunk"
    },
    {
      "x": 4,
      "y": 6,
      "z": 3,
      "name": "Wood_Petrified_Trunk"
    },
    {
      "x": 4,
      "y": 7,
      "z": 3,
      "name": "Wood_Petrified_Trunk"
    },
    {
      "x": 4,
      "y": 8,
      "z": 3,
      "name": "Wood_Petrified_Trunk"
    },
    {
      "x": 4,
      "y": 9,
      "z": 3,
      "name": "Wood_Burnt_Trunk"
    },
    {
      "x": 4,
      "y": 10,
      "z": 3,
      "name": "Wood_Burnt_Trunk"
    },
    {
      "x": 4,
      "y": 1,
      "z": 4,
      "name": "Wood_Petrified_Trunk"
    },
    {
      "x": 4,
      "y": 2,
      "z": 4,
      "name": "Wood_Petrified_Trunk"
    },
    {
      "x": 4,
      "y": 3,
      "z": 4,
      "name": "Wood_Petrified_Trunk"
    },
    {
      "x": 4,
      "y": 4,
      "z": 4,
      "name": "Wood_Petrified_Trunk"
    },
    {
      "x": 4,
      "y": 5,
      "z": 4,
      "name": "Wood_Petrified_Trunk"
    },
    {
      "x": 4,
      "y": 6,
      "z": 4,
      "name": "Wood_Petrified_Trunk"
    },
    {
      "x": 4,
      "y": 7,
      "z": 4,
      "name": "Wood_Petrified_Trunk"
    },
    {
      "x": 4,
      "y": 8,
      "z": 4,
      "name": "Wood_Petrified_Trunk"
    },
    {
      "x": 4,
      "y": 9,
      "z": 4,
      "name": "Wood_Burnt_Trunk"
    },
    {
      "x": 4,
      "y": 10,
      "z": 4,
      "name": "Wood_Burnt_Trunk"
    },
    {
      "x": 4,
      "y": 1,
      "z": 5,
      "name": "Wood_Petrified_Trunk"
    },
    {
      "x": 4,
      "y": 2,
      "z": 5,
      "name": "Wood_Petrified_Trunk"
    },
    {
      "x": 5,
      "y": 0,
      "z": -3,
      "name": "Wood_Petrified_Trunk"
    },
    {
      "x": 5,
      "y": 2,
      "z": -3,
      "name": "Wood_Petrified_Trunk"
    },
    {
      "x": 5,
      "y": 0,
      "z": -2,
      "name": "Wood_Petrified_Trunk"
    },
    {
      "x": 5,
      "y": 1,
      "z": -2,
      "name": "Wood_Petrified_Trunk"
    },
    {
      "x": 5,
      "y": 2,
      "z": -2,
      "name": "Wood_Petrified_Trunk"
    },
    {
      "x": 5,
      "y": 3,
      "z": -2,
      "name": "Wood_Petrified_Trunk"
    },
    {
      "x": 5,
      "y": 4,
      "z": -2,
      "name": "Wood_Petrified_Trunk"
    },
    {
      "x": 5,
      "y": 5,
      "z": -2,
      "name": "Wood_Petrified_Trunk"
    },
    {
      "x": 5,
      "y": 6,
      "z": -2,
      "name": "Wood_Petrified_Trunk"
    },
    {
      "x": 5,
      "y": 7,
      "z": -2,
      "name": "Wood_Burnt_Trunk"
    },
    {
      "x": 5,
      "y": 8,
      "z": -2,
      "name": "Wood_Burnt_Trunk"
    },
    {
      "x": 5,
      "y": 9,
      "z": -2,
      "name": "Wood_Burnt_Trunk"
    },
    {
      "x": 5,
      "y": 10,
      "z": -2,
      "name": "Wood_Burnt_Trunk"
    },
    {
      "x": 5,
      "y": 11,
      "z": -2,
      "name": "Wood_Burnt_Trunk"
    },
    {
      "x": 5,
      "y": 0,
      "z": -1,
      "name": "Wood_Petrified_Trunk"
    },
    {
      "x": 5,
      "y": 1,
      "z": -1,
      "name": "Wood_Petrified_Trunk"
    },
    {
      "x": 5,
      "y": 2,
      "z": -1,
      "name": "Wood_Petrified_Trunk"
    },
    {
      "x": 5,
      "y": 3,
      "z": -1,
      "name": "Wood_Petrified_Trunk"
    },
    {
      "x": 5,
      "y": 4,
      "z": -1,
      "name": "Wood_Petrified_Trunk"
    },
    {
      "x": 5,
      "y": 5,
      "z": -1,
      "name": "Wood_Petrified_Trunk"
    },
    {
      "x": 5,
      "y": 6,
      "z": -1,
      "name": "Wood_Petrified_Trunk"
    },
    {
      "x": 5,
      "y": 7,
      "z": -1,
      "name": "Wood_Petrified_Trunk"
    },
    {
      "x": 5,
      "y": 8,
      "z": -1,
      "name": "Wood_Burnt_Trunk"
    },
    {
      "x": 5,
      "y": 9,
      "z": -1,
      "name": "Wood_Burnt_Trunk"
    },
    {
      "x": 5,
      "y": 10,
      "z": -1,
      "name": "Wood_Burnt_Trunk"
    },
    {
      "x": 5,
      "y": 11,
      "z": -1,
      "name": "Wood_Burnt_Trunk"
    },
    {
      "x": 5,
      "y": 12,
      "z": -1,
      "name": "Wood_Burnt_Trunk"
    },
    {
      "x": 5,
      "y": 1,
      "z": 0,
      "name": "Wood_Petrified_Trunk"
    },
    {
      "x": 5,
      "y": 2,
      "z": 0,
      "name": "Wood_Petrified_Trunk"
    },
    {
      "x": 5,
      "y": 3,
      "z": 0,
      "name": "Wood_Petrified_Trunk"
    },
    {
      "x": 5,
      "y": 4,
      "z": 0,
      "name": "Wood_Petrified_Trunk"
    },
    {
      "x": 5,
      "y": 5,
      "z": 0,
      "name": "Wood_Petrified_Trunk"
    },
    {
      "x": 5,
      "y": 6,
      "z": 0,
      "name": "Wood_Petrified_Trunk"
    },
    {
      "x": 5,
      "y": 7,
      "z": 0,
      "name": "Wood_Petrified_Trunk"
    },
    {
      "x": 5,
      "y": 8,
      "z": 0,
      "name": "Wood_Petrified_Trunk"
    },
    {
      "x": 5,
      "y": 9,
      "z": 0,
      "name": "Wood_Burnt_Trunk"
    },
    {
      "x": 5,
      "y": 10,
      "z": 0,
      "name": "Wood_Burnt_Trunk"
    },
    {
      "x": 5,
      "y": 11,
      "z": 0,
      "name": "Wood_Burnt_Trunk"
    },
    {
      "x": 5,
      "y": 12,
      "z": 0,
      "name": "Wood_Burnt_Trunk"
    },
    {
      "x": 5,
      "y": 1,
      "z": 1,
      "name": "Wood_Petrified_Trunk"
    },
    {
      "x": 5,
      "y": 2,
      "z": 1,
      "name": "Wood_Petrified_Trunk"
    },
    {
      "x": 5,
      "y": 3,
      "z": 1,
      "name": "Wood_Petrified_Trunk"
    },
    {
      "x": 5,
      "y": 4,
      "z": 1,
      "name": "Wood_Petrified_Trunk"
    },
    {
      "x": 5,
      "y": 5,
      "z": 1,
      "name": "Wood_Petrified_Trunk"
    },
    {
      "x": 5,
      "y": 6,
      "z": 1,
      "name": "Wood_Petrified_Trunk"
    },
    {
      "x": 5,
      "y": 7,
      "z": 1,
      "name": "Wood_Petrified_Trunk"
    },
    {
      "x": 5,
      "y": 8,
      "z": 1,
      "name": "Wood_Petrified_Trunk"
    },
    {
      "x": 5,
      "y": 9,
      "z": 1,
      "name": "Wood_Burnt_Trunk"
    },
    {
      "x": 5,
      "y": 10,
      "z": 1,
      "name": "Wood_Burnt_Trunk"
    },
    {
      "x": 5,
      "y": 11,
      "z": 1,
      "name": "Wood_Burnt_Trunk"
    },
    {
      "x": 5,
      "y": 1,
      "z": 2,
      "name": "Wood_Petrified_Trunk"
    },
    {
      "x": 5,
      "y": 2,
      "z": 2,
      "name": "Wood_Petrified_Trunk"
    },
    {
      "x": 5,
      "y": 3,
      "z": 2,
      "name": "Wood_Petrified_Trunk"
    },
    {
      "x": 5,
      "y": 4,
      "z": 2,
      "name": "Wood_Petrified_Trunk"
    },
    {
      "x": 5,
      "y": 5,
      "z": 2,
      "name": "Wood_Petrified_Trunk"
    },
    {
      "x": 5,
      "y": 6,
      "z": 2,
      "name": "Wood_Petrified_Trunk"
    },
    {
      "x": 5,
      "y": 7,
      "z": 2,
      "name": "Wood_Petrified_Trunk"
    },
    {
      "x": 5,
      "y": 8,
      "z": 2,
      "name": "Wood_Petrified_Trunk"
    },
    {
      "x": 5,
      "y": 9,
      "z": 2,
      "name": "Wood_Burnt_Trunk"
    },
    {
      "x": 5,
      "y": 10,
      "z": 2,
      "name": "Wood_Burnt_Trunk"
    },
    {
      "x": 5,
      "y": 11,
      "z": 2,
      "name": "Wood_Burnt_Trunk"
    },
    {
      "x": 5,
      "y": 1,
      "z": 3,
      "name": "Wood_Petrified_Trunk"
    },
    {
      "x": 5,
      "y": 2,
      "z": 3,
      "name": "Wood_Petrified_Trunk"
    },
    {
      "x": 5,
      "y": 3,
      "z": 3,
      "name": "Wood_Petrified_Trunk"
    },
    {
      "x": 5,
      "y": 4,
      "z": 3,
      "name": "Wood_Petrified_Trunk"
    },
    {
      "x": 5,
      "y": 5,
      "z": 3,
      "name": "Wood_Petrified_Trunk"
    },
    {
      "x": 5,
      "y": 6,
      "z": 3,
      "name": "Wood_Petrified_Trunk"
    },
    {
      "x": 5,
      "y": 7,
      "z": 3,
      "name": "Wood_Petrified_Trunk"
    },
    {
      "x": 5,
      "y": 8,
      "z": 3,
      "name": "Wood_Petrified_Trunk"
    },
    {
      "x": 5,
      "y": 9,
      "z": 3,
      "name": "Wood_Burnt_Trunk"
    },
    {
      "x": 5,
      "y": 10,
      "z": 3,
      "name": "Wood_Burnt_Trunk"
    },
    {
      "x": 5,
      "y": 11,
      "z": 3,
      "name": "Wood_Burnt_Trunk"
    },
    {
      "x": 5,
      "y": 1,
      "z": 4,
      "name": "Wood_Petrified_Trunk"
    },
    {
      "x": 5,
      "y": 2,
      "z": 4,
      "name": "Wood_Petrified_Trunk"
    },
    {
      "x": 5,
      "y": 1,
      "z": 5,
      "name": "Wood_Petrified_Trunk"
    },
    {
      "x": 6,
      "y": 0,
      "z": -3,
      "name": "Wood_Petrified_Trunk"
    },
    {
      "x": 6,
      "y": 1,
      "z": -3,
      "name": "Wood_Petrified_Trunk"
    },
    {
      "x": 6,
      "y": 0,
      "z": -2,
      "name": "Wood_Petrified_Trunk"
    },
    {
      "x": 6,
      "y": 1,
      "z": -2,
      "name": "Wood_Petrified_Trunk"
    },
    {
      "x": 6,
      "y": 2,
      "z": -2,
      "name": "Wood_Petrified_Trunk"
    },
    {
      "x": 6,
      "y": 3,
      "z": -2,
      "name": "Wood_Petrified_Trunk"
    },
    {
      "x": 6,
      "y": 7,
      "z": -2,
      "name": "Wood_Petrified_Trunk"
    },
    {
      "x": 6,
      "y": 8,
      "z": -2,
      "name": "Wood_Burnt_Trunk"
    },
    {
      "x": 6,
      "y": 9,
      "z": -2,
      "name": "Wood_Burnt_Trunk"
    },
    {
      "x": 6,
      "y": 0,
      "z": -1,
      "name": "Wood_Petrified_Trunk"
    },
    {
      "x": 6,
      "y": 1,
      "z": -1,
      "name": "Wood_Petrified_Trunk"
    },
    {
      "x": 6,
      "y": 2,
      "z": -1,
      "name": "Wood_Petrified_Trunk"
    },
    {
      "x": 6,
      "y": 3,
      "z": -1,
      "name": "Wood_Petrified_Trunk"
    },
    {
      "x": 6,
      "y": 5,
      "z": -1,
      "name": "Wood_Petrified_Trunk"
    },
    {
      "x": 6,
      "y": 6,
      "z": -1,
      "name": "Wood_Petrified_Trunk"
    },
    {
      "x": 6,
      "y": 7,
      "z": -1,
      "name": "Wood_Petrified_Trunk"
    },
    {
      "x": 6,
      "y": 8,
      "z": -1,
      "name": "Wood_Burnt_Trunk"
    },
    {
      "x": 6,
      "y": 9,
      "z": -1,
      "name": "Wood_Burnt_Trunk"
    },
    {
      "x": 6,
      "y": 10,
      "z": -1,
      "name": "Wood_Burnt_Trunk"
    },
    {
      "x": 6,
      "y": 2,
      "z": 0,
      "name": "Wood_Petrified_Trunk"
    },
    {
      "x": 6,
      "y": 3,
      "z": 0,
      "name": "Wood_Petrified_Trunk"
    },
    {
      "x": 6,
      "y": 4,
      "z": 0,
      "name": "Wood_Petrified_Trunk"
    },
    {
      "x": 6,
      "y": 5,
      "z": 0,
      "name": "Wood_Petrified_Trunk"
    },
    {
      "x": 6,
      "y": 6,
      "z": 0,
      "name": "Wood_Petrified_Trunk"
    },
    {
      "x": 6,
      "y": 7,
      "z": 0,
      "name": "Wood_Petrified_Trunk"
    },
    {
      "x": 6,
      "y": 8,
      "z": 0,
      "name": "Wood_Petrified_Trunk"
    },
    {
      "x": 6,
      "y": 9,
      "z": 0,
      "name": "Wood_Burnt_Trunk"
    },
    {
      "x": 6,
      "y": 10,
      "z": 0,
      "name": "Wood_Burnt_Trunk"
    },
    {
      "x": 6,
      "y": 11,
      "z": 0,
      "name": "Wood_Burnt_Trunk"
    },
    {
      "x": 6,
      "y": 12,
      "z": 0,
      "name": "Wood_Burnt_Trunk"
    },
    {
      "x": 6,
      "y": 2,
      "z": 1,
      "name": "Wood_Petrified_Trunk"
    },
    {
      "x": 6,
      "y": 3,
      "z": 1,
      "name": "Wood_Petrified_Trunk"
    },
    {
      "x": 6,
      "y": 4,
      "z": 1,
      "name": "Wood_Petrified_Trunk"
    },
    {
      "x": 6,
      "y": 5,
      "z": 1,
      "name": "Wood_Petrified_Trunk"
    },
    {
      "x": 6,
      "y": 6,
      "z": 1,
      "name": "Wood_Petrified_Trunk"
    },
    {
      "x": 6,
      "y": 7,
      "z": 1,
      "name": "Wood_Petrified_Trunk"
    },
    {
      "x": 6,
      "y": 8,
      "z": 1,
      "name": "Wood_Petrified_Trunk"
    },
    {
      "x": 6,
      "y": 9,
      "z": 1,
      "name": "Wood_Petrified_Trunk"
    },
    {
      "x": 6,
      "y": 10,
      "z": 1,
      "name": "Wood_Burnt_Trunk"
    },
    {
      "x": 6,
      "y": 11,
      "z": 1,
      "name": "Wood_Burnt_Trunk"
    },
    {
      "x": 6,
      "y": 12,
      "z": 1,
      "name": "Wood_Burnt_Trunk"
    },
    {
      "x": 6,
      "y": 4,
      "z": 2,
      "name": "Wood_Petrified_Trunk"
    },
    {
      "x": 6,
      "y": 5,
      "z": 2,
      "name": "Wood_Petrified_Trunk"
    },
    {
      "x": 6,
      "y": 6,
      "z": 2,
      "name": "Wood_Petrified_Trunk"
    },
    {
      "x": 6,
      "y": 7,
      "z": 2,
      "name": "Wood_Petrified_Trunk"
    },
    {
      "x": 6,
      "y": 8,
      "z": 2,
      "name": "Wood_Petrified_Trunk"
    },
    {
      "x": 6,
      "y": 9,
      "z": 2,
      "name": "Wood_Petrified_Trunk"
    },
    {
      "x": 6,
      "y": 10,
      "z": 2,
      "name": "Wood_Burnt_Trunk"
    },
    {
      "x": 6,
      "y": 1,
      "z": 4,
      "name": "Wood_Petrified_Trunk"
    },
    {
      "x": 7,
      "y": 0,
      "z": -3,
      "name": "Wood_Petrified_Trunk"
    },
    {
      "x": 7,
      "y": 0,
      "z": -2,
      "name": "Wood_Petrified_Trunk"
    },
    {
      "x": 7,
      "y": 1,
      "z": -1,
      "name": "Wood_Petrified_Trunk"
    },
    {
      "x": 7,
      "y": 2,
      "z": -1,
      "name": "Wood_Petrified_Trunk"
    },
    {
      "x": 7,
      "y": 6,
      "z": 0,
      "name": "Wood_Petrified_Trunk"
    },
    {
      "x": 7,
      "y": 7,
      "z": 0,
      "name": "Wood_Petrified_Trunk"
    },
    {
      "x": 7,
      "y": 6,
      "z": 1,
      "name": "Wood_Petrified_Trunk"
    },
    {
      "x": 7,
      "y": 7,
      "z": 1,
      "name": "Wood_Petrified_Trunk"
    },
    {
      "x": 8,
      "y": 1,
      "z": -1,
      "name": "Wood_Petrified_Trunk"
    }
  ]
}