{
  "version": 8,
  "blockIdVersion": 8,
  "anchorX": 0,
  "anchorY": 17,
  "anchorZ": 9,
  "blocks": [
    {
      "x": -5,
      "y": 6,
      "z": -9,
      "name": "Rock_Stone"
    },
    {
      "x": -5,
      "y": 7,
      "z": -9,
      "name": "Rock_Stone"
    },
    {
      "x": -5,
      "y": 8,
      "z": -9,
      "name": "Rock_Quartzite_Brick"
    },
    {
      "x": -5,
      "y": 9,
      "z": -9,
      "name": "Rock_Quartzite_Brick"
    },
    {
      "x": -5,
      "y": 10,
      "z": -9,
      "name": "Rock_Quartzite"
    },
    {
      "x": -5,
      "y": 11,
      "z": -9,
      "name": "Rock_Quartzite"
    },
    {
      "x": -5,
      "y": 12,
      "z": -9,
      "name": "Rock_Quartzite"
    },
    {
      "x": -5,
      "y": 13,
      "z": -9,
      "name": "Rock_Quartzite"
    },
    {
      "x": -5,
      "y": 14,
      "z": -9,
      "name": "Rock_Quartzite"
    },
    {
      "x": -5,
      "y": 15,
      "z": -9,
      "name": "Rock_Quartzite"
    },
    {
      "x": -5,
      "y": 6,
      "z": -8,
      "name": "Rock_Stone"
    },
    {
      "x": -5,
      "y": 7,
      "z": -8,
      "name": "Rock_Stone"
    },
    {
      "x": -5,
      "y": 8,
      "z": -8,
      "name": "Rock_Quartzite_Brick"
    },
    {
      "x": -5,
      "y": 9,
      "z": -8,
      "name": "Rock_Quartzite_Brick"
    },
    {
      "x": -5,
      "y": 10,
      "z": -8,
      "name": "Rock_Quartzite_Cobble"
    },
    {
      "x": -5,
      "y": 11,
      "z": -8,
      "name": "Rock_Quartzite_Cobble"
    },
    {
      "x": -5,
      "y": 12,
      "z": -8,
      "name": "Rock_Quartzite"
    },
    {
      "x": -5,
      "y": 13,
      "z": -8,
      "name": "Rock_Quartzite"
    },
    {
      "x": -5,
      "y": 14,
      "z": -8,
      "name": "Rock_Quartzite"
    },
    {
      "x": -5,
      "y": 15,
      "z": -8,
      "name": "Rock_Quartzite"
    },
    {
      "x": -5,
      "y": 6,
      "z": -7,
      "name": "Rock_Stone"
    },
    {
      "x": -5,
      "y": 7,
      "z": -7,
      "name": "Rock_Stone"
    },
    {
      "x": -5,
      "y": 8,
      "z": -7,
      "name": "Rock_Quartzite_Brick"
    },
    {
      "x": -5,
      "y": 9,
      "z": -7,
      "name": "Rock_Quartzite_Brick"
    },
    {
      "x": -5,
      "y": 10,
      "z": -7,
      "name": "Rock_Quartzite_Cobble"
    },
    {
      "x": -5,
      "y": 11,
      "z": -7,
      "name": "Rock_Quartzite_Cobble"
    },
    {
      "x": -5,
      "y": 12,
      "z": -7,
      "name": "Rock_Quartzite"
    },
    {
      "x": -5,
      "y": 13,
      "z": -7,
      "name": "Rock_Quartzite"
    },
    {
      "x": -5,
      "y": 14,
      "z": -7,
      "name": "Rock_Quartzite"
    },
    {
      "x": -5,
      "y": 15,
      "z": -7,
      "name": "Rock_Quartzite"
    },
    {
      "x": -5,
      "y": 6,
      "z": -6,
      "name": "Rock_Stone"
    },
    {
      "x": -5,
      "y": 7,
      "z": -6,
      "name": "Rock_Stone"
    },
    {
      "x": -5,
      "y": 8,
      "z": -6,
      "name": "Rock_Quartzite_Brick"
    },
    {
      "x": -5,
      "y": 9,
      "z": -6,
      "name": "Rock_Quartzite_Brick"
    },
    {
      "x": -5,
      "y": 10,
      "z": -6,
      "name": "Rock_Quartzite_Cobble"
    },
    {
      "x": -5,
      "y": 11,
      "z": -6,
      "name": "Rock_Quartzite"
    },
    {
      "x": -5,
      "y": 12,
      "z": -6,
      "name": "Rock_Quartzite"
    },
    {
      "x": -5,
      "y": 13,
      "z": -6,
      "name": "Rock_Stone"
    },
    {
      "x": -5,
      "y": 14,
      "z": -6,
      "name": "Rock_Quartzite"
    },
    {
      "x": -5,
      "y": 15,
      "z": -6,
      "name": "Rock_Quartzite"
    },
    {
      "x": -5,
      "y": 6,
      "z": -5,
      "name": "Rock_Stone"
    },
    {
      "x": -5,
      "y": 7,
      "z": -5,
      "name": "Rock_Stone"
    },
    {
      "x": -5,
      "y": 8,
      "z": -5,
      "name": "Rock_Quartzite_Brick"
    },
    {
      "x": -5,
      "y": 9,
      "z": -5,
      "name": "Rock_Quartzite_Brick"
    },
    {
      "x": -5,
      "y": 10,
      "z": -5,
      "name": "Rock_Quartzite"
    },
    {
      "x": -5,
      "y": 11,
      "z": -5,
      "name": "Rock_Quartzite"
    },
    {
      "x": -5,
      "y": 12,
      "z": -5,
      "name": "Rock_Stone"
    },
    {
      "x": -5,
      "y": 13,
      "z": -5,
      "name": "Rock_Stone"
    },
    {
      "x": -5,
      "y": 14,
      "z": -5,
      "name": "Rock_Quartzite"
    },
    {
      "x": -5,
      "y": 15,
      "z": -5,
      "name": "Rock_Quartzite"
    },
    {
      "x": -5,
      "y": 6,
      "z": -4,
      "name": "Rock_Stone"
    },
    {
      "x": -5,
      "y": 7,
      "z": -4,
      "name": "Rock_Stone"
    },
    {
      "x": -5,
      "y": 8,
      "z": -4,
      "name": "Rock_Quartzite_Brick"
    },
    {
      "x": -5,
      "y": 9,
      "z": -4,
      "name": "Rock_Quartzite_Brick"
    },
    {
      "x": -5,
      "y": 10,
      "z": -4,
      "name": "Rock_Quartzite"
    },
    {
      "x": -5,
      "y": 11,
      "z": -4,
      "name": "Rock_Quartzite"
    },
    {
      "x": -5,
      "y": 12,
      "z": -4,
      "name": "Rock_Stone"
    },
    {
      "x": -5,
      "y": 13,
      "z": -4,
      "name": "Rock_Stone"
    },
    {
      "x": -5,
      "y": 14,
      "z": -4,
      "name": "Rock_Quartzite"
    },
    {
      "x": -5,
      "y": 15,
      "z": -4,
      "name": "Rock_Quartzite"
    },
    {
      "x": -5,
      "y": 6,
      "z": -3,
      "name": "Rock_Stone"
    },
    {
      "x": -5,
      "y": 7,
      "z": -3,
      "name": "Rock_Stone"
    },
    {
      "x": -5,
      "y": 8,
      "z": -3,
      "name": "Rock_Quartzite_Brick"
    },
    {
      "x": -5,
      "y": 9,
      "z": -3,
      "name": "Rock_Quartzite_Brick"
    },
    {
      "x": -5,
      "y": 10,
      "z": -3,
      "name": "Rock_Quartzite_Brick"
    },
    {
      "x": -5,
      "y": 11,
      "z": -3,
      "name": "Rock_Quartzite"
    },
    {
      "x": -5,
      "y": 12,
      "z": -3,
      "name": "Rock_Quartzite"
    },
    {
      "x": -5,
      "y": 13,
      "z": -3,
      "name": "Rock_Quartzite"
    },
    {
      "x": -5,
      "y": 14,
      "z": -3,
      "name": "Rock_Quartzite"
    },
    {
      "x": -5,
      "y": 15,
      "z": -3,
      "name": "Rock_Quartzite"
    },
    {
      "x": -5,
      "y": 8,
      "z": -2,
      "name": "Rock_Stone"
    },
    {
      "x": -5,
      "y": 9,
      "z": -2,
      "name": "Rock_Quartzite_Brick"
    },
    {
      "x": -5,
      "y": 10,
      "z": -2,
      "name": "Rock_Quartzite_Brick"
    },
    {
      "x": -5,
      "y": 11,
      "z": -2,
      "name": "Rock_Quartzite_Brick"
    },
    {
      "x": -5,
      "y": 12,
      "z": -2,
      "name": "Rock_Quartzite_Brick"
    },
    {
      "x": -5,
      "y": 13,
      "z": -2,
      "name": "Rock_Quartzite_Brick"
    },
    {
      "x": -5,
      "y": 14,
      "z": -2,
      "name": "Rock_Quartzite_Brick"
    },
    {
      "x": -5,
      "y": 15,
      "z": -2,
      "name": "Rock_Quartzite_Brick"
    },
    {
      "x": -5,
      "y": 9,
      "z": -1,
      "name": "Rock_Stone"
    },
    {
      "x": -5,
      "y": 10,
      "z": -1,
      "name": "Rock_Quartzite_Brick"
    },
    {
      "x": -5,
      "y": 11,
      "z": -1,
      "name": "Rock_Quartzite_Brick"
    },
    {
      "x": -5,
      "y": 12,
      "z": -1,
      "name": "Rock_Quartzite_Brick"
    },
    {
      "x": -5,
      "y": 13,
      "z": -1,
      "name": "Rock_Quartzite_Brick"
    },
    {
      "x": -5,
      "y": 14,
      "z": -1,
      "name": "Rock_Quartzite_Brick"
    },
    {
      "x": -5,
      "y": 15,
      "z": -1,
      "name": "Rock_Quartzite_Brick"
    },
    {
      "x": -5,
      "y": 16,
      "z": -1,
      "name": "Rock_Quartzite_Brick"
    },
    {
      "x": -5,
      "y": 10,
      "z": 0,
      "name": "Rock_Stone"
    },
    {
      "x": -5,
      "y": 11,
      "z": 0,
      "name": "Rock_Quartzite_Brick"
    },
    {
      "x": -5,
      "y": 12,
      "z": 0,
      "name": "Rock_Quartzite_Brick"
    },
    {
      "x": -5,
      "y": 13,
      "z": 0,
      "name": "Rock_Quartzite_Brick"
    },
    {
      "x": -5,
      "y": 14,
      "z": 0,
      "name": "Rock_Quartzite_Brick"
    },
    {
      "x": -5,
      "y": 15,
      "z": 0,
      "name": "Rock_Quartzite_Brick"
    },
    {
      "x": -5,
      "y": 16,
      "z": 0,
      "name": "Rock_Quartzite_Brick"
    },
    {
      "x": -5,
      "y": 17,
      "z": 0,
      "name": "Rock_Quartzite_Brick"
    },
    {
      "x": -5,
      "y": 11,
      "z": 1,
      "name": "Rock_Quartzite"
    },
    {
      "x": -5,
      "y": 12,
      "z": 1,
      "name": "Rock_Quartzite_Brick"
    },
    {
      "x": -5,
      "y": 13,
      "z": 1,
      "name": "Rock_Quartzite_Brick"
    },
    {
      "x": -5,
      "y": 14,
      "z": 1,
      "name": "Rock_Quartzite_Cobble"
    },
    {
      "x": -5,
      "y": 15,
      "z": 1,
      "name": "Rock_Quartzite_Cobble"
    },
    {
      "x": -5,
      "y": 16,
      "z": 1,
      "name": "Rock_Quartzite"
    },
    {
      "x": -5,
      "y": 17,
      "z": 1,
      "name": "Rock_Quartzite"
    },
    {
      "x": -5,
      "y": 18,
      "z": 1,
      "name": "Rock_Quartzite"
    },
    {
      "x": -5,
      "y": 12,
      "z": 2,
      "name": "Rock_Quartzite"
    },
    {
      "x": -5,
      "y": 13,
      "z": 2,
      "name": "Rock_Quartzite_Brick"
    },
    {
      "x": -5,
      "y": 14,
      "z": 2,
      "name": "Rock_Quartzite_Brick"
    },
    {
      "x": -5,
      "y": 15,
      "z": 2,
      "name": "Rock_Quartzite_Brick"
    },
    {
      "x": -5,
      "y": 16,
      "z": 2,
      "name": "Rock_Quartzite_Cobble"
    },
    {
      "x": -5,
      "y": 17,
      "z": 2,
      "name": "Rock_Quartzite"
    },
    {
      "x": -5,
      "y": 18,
      "z": 2,
      "name": "Rock_Quartzite"
    },
    {
      "x": -5,
      "y": 19,
      "z": 2,
      "name": "Rock_Quartzite"
    },
    {
      "x": -5,
      "y": 0,
      "z": 3,
      "name": "Rock_Stone"
    },
    {
      "x": -5,
      "y": 1,
      "z": 3,
      "name": "Rock_Stone"
    },
    {
      "x": -5,
      "y": 2,
      "z": 3,
      "name": "Rock_Stone_Brick"
    },
    {
      "x": -5,
      "y": 3,
      "z": 3,
      "name": "Rock_Stone_Brick"
    },
    {
      "x": -5,
      "y": 4,
      "z": 3,
      "name": "Rock_Stone"
    },
    {
      "x": -5,
      "y": 5,
      "z": 3,
      "name": "Rock_Stone"
    },
    {
      "x": -5,
      "y": 6,
      "z": 3,
      "name": "Rock_Stone"
    },
    {
      "x": -5,
      "y": 7,
      "z": 3,
      "name": "Rock_Stone"
    },
    {
      "x": -5,
      "y": 13,
      "z": 3,
      "name": "Rock_Quartzite_Brick"
    },
    {
      "x": -5,
      "y": 14,
      "z": 3,
      "name": "Rock_Quartzite_Brick"
    },
    {
      "x": -5,
      "y": 15,
      "z": 3,
      "name": "Rock_Quartzite_Brick"
    },
    {
      "x": -5,
      "y": 16,
      "z": 3,
      "name": "Rock_Quartzite_Brick"
    },
    {
      "x": -5,
      "y": 17,
      "z": 3,
      "name": "Rock_Quartzite"
    },
    {
      "x": -5,
      "y": 18,
      "z": 3,
      "name": "Rock_Quartzite"
    },
    {
      "x": -5,
      "y": 19,
      "z": 3,
      "name": "Rock_Quartzite"
    },
    {
      "x": -5,
      "y": 20,
      "z": 3,
      "name": "Rock_Quartzite"
    },
    {
      "x": -5,
      "y": 0,
      "z": 4,
      "name": "Rock_Stone"
    },
    {
      "x": -5,
      "y": 1,
      "z": 4,
      "name": "Rock_Stone"
    },
    {
      "x": -5,
      "y": 2,
      "z": 4,
      "name": "Rock_Stone_Brick"
    },
    {
      "x": -5,
      "y": 3,
      "z": 4,
      "name": "Rock_Stone_Brick"
    },
    {
      "x": -5,
      "y": 4,
      "z": 4,
      "name": "Rock_Stone"
    },
    {
      "x": -5,
      "y": 5,
      "z": 4,
      "name": "Rock_Stone"
    },
    {
      "x": -5,
      "y": 6,
      "z": 4,
      "name": "Rock_Stone"
    },
    {
      "x": -5,
      "y": 7,
      "z": 4,
      "name": "Rock_Stone"
    },
    {
      "x": -5,
      "y": 14,
      "z": 4,
      "name": "Rock_Quartzite_Brick"
    },
    {
      "x": -5,
      "y": 15,
      "z": 4,
      "name": "Rock_Quartzite_Brick"
    },
    {
      "x": -5,
      "y": 16,
      "z": 4,
      "name": "Rock_Quartzite_Brick"
    },
    {
      "x": -5,
      "y": 17,
      "z": 4,
      "name": "Rock_Quartzite_Brick"
    },
    {
      "x": -5,
      "y": 18,
      "z": 4,
      "name": "Rock_Quartzite"
    },
    {
      "x": -5,
      "y": 19,
      "z": 4,
      "name": "Rock_Quartzite"
    },
    {
      "x": -5,
      "y": 20,
      "z": 4,
      "name": "Rock_Quartzite"
    },
    {
      "x": -5,
      "y": 21,
      "z": 4,
      "name": "Rock_Quartzite"
    },
    {
      "x": -5,
      "y": 22,
      "z": 4,
      "name": "Rock_Quartzite"
    },
    {
      "x": -5,
      "y": 23,
      "z": 4,
      "name": "Rock_Quartzite_Brick"
    },
    {
      "x": -5,
      "y": 0,
      "z": 5,
      "name": "Rock_Stone"
    },
    {
      "x": -5,
      "y": 1,
      "z": 5,
      "name": "Rock_Stone"
    },
    {
      "x": -5,
      "y": 2,
      "z": 5,
      "name": "Rock_Stone_Brick"
    },
    {
      "x": -5,
      "y": 3,
      "z": 5,
      "name": "Rock_Stone_Brick"
    },
    {
      "x": -5,
      "y": 4,
      "z": 5,
      "name": "Rock_Stone_Cobble"
    },
    {
      "x": -5,
      "y": 5,
      "z": 5,
      "name": "Rock_Stone"
    },
    {
      "x": -5,
      "y": 6,
      "z": 5,
      "name": "Rock_Stone"
    },
    {
      "x": -5,
      "y": 7,
      "z": 5,
      "name": "Rock_Stone"
    },
    {
      "x": -5,
      "y": 15,
      "z": 5,
      "name": "Rock_Quartzite_Brick"
    },
    {
      "x": -5,
      "y": 16,
      "z": 5,
      "name": "Rock_Quartzite_Brick"
    },
    {
      "x": -5,
      "y": 17,
      "z": 5,
      "name": "Rock_Quartzite_Brick"
    },
    {
      "x": -5,
      "y": 18,
      "z": 5,
      "name": "Rock_Quartzite_Brick"
    },
    {
      "x": -5,
      "y": 19,
      "z": 5,
      "name": "Rock_Quartzite"
    },
    {
      "x": -5,
      "y": 20,
      "z": 5,
      "name": "Rock_Quartzite"
    },
    {
      "x": -5,
      "y": 21,
      "z": 5,
      "name": "Rock_Quartzite"
    },
    {
      "x": -5,
      "y": 22,
      "z": 5,
      "name": "Rock_Quartzite"
    },
    {
      "x": -5,
      "y": 23,
      "z": 5,
      "name": "Rock_Stone"
    },
    {
      "x": -5,
      "y": 0,
      "z": 6,
      "name": "Rock_Stone"
    },
    {
      "x": -5,
      "y": 1,
      "z": 6,
      "name": "Rock_Stone"
    },
    {
      "x": -5,
      "y": 2,
      "z": 6,
      "name": "Rock_Stone_Brick"
    },
    {
      "x": -5,
      "y": 3,
      "z": 6,
      "name": "Rock_Stone_Brick"
    },
    {
      "x": -5,
      "y": 4,
      "z": 6,
      "name": "Rock_Stone_Cobble"
    },
    {
      "x": -5,
      "y": 5,
      "z": 6,
      "name": "Rock_Stone"
    },
    {
      "x": -5,
      "y": 6,
      "z": 6,
      "name": "Rock_Stone"
    },
    {
      "x": -5,
      "y": 7,
      "z": 6,
      "name": "Rock_Stone"
    },
    {
      "x": -5,
      "y": 16,
      "z": 6,
      "name": "Rock_Stone"
    },
    {
      "x": -5,
      "y": 17,
      "z": 6,
      "name": "Rock_Quartzite_Brick"
    },
    {
      "x": -5,
      "y": 18,
      "z": 6,
      "name": "Rock_Quartzite_Brick"
    },
    {
      "x": -5,
      "y": 19,
      "z": 6,
      "name": "Rock_Quartzite_Brick"
    },
    {
      "x": -5,
      "y": 20,
      "z": 6,
      "name": "Rock_Quartzite"
    },
    {
      "x": -5,
      "y": 21,
      "z": 6,
      "name": "Rock_Quartzite"
    },
    {
      "x": -5,
      "y": 22,
      "z": 6,
      "name": "Rock_Quartzite_Cobble"
    },
    {
      "x": -5,
      "y": 23,
      "z": 6,
      "name": "Rock_Stone"
    },
    {
      "x": -5,
      "y": 0,
      "z": 7,
      "name": "Rock_Stone"
    },
    {
      "x": -5,
      "y": 1,
      "z": 7,
      "name": "Rock_Stone"
    },
    {
      "x": -5,
      "y": 2,
      "z": 7,
      "name": "Rock_Stone_Brick"
    },
    {
      "x": -5,
      "y": 3,
      "z": 7,
      "name": "Rock_Stone"
    },
    {
      "x": -5,
      "y": 4,
      "z": 7,
      "name": "Rock_Stone"
    },
    {
      "x": -5,
      "y": 5,
      "z": 7,
      "name": "Rock_Stone"
    },
    {
      "x": -5,
      "y": 6,
      "z": 7,
      "name": "Rock_Stone"
    },
    {
      "x": -5,
      "y": 7,
      "z": 7,
      "name": "Rock_Stone"
    },
    {
      "x": -5,
      "y": 16,
      "z": 7,
      "name": "Rock_Stone"
    },
    {
      "x": -5,
      "y": 17,
      "z": 7,
      "name": "Rock_Quartzite"
    },
    {
      "x": -5,
      "y": 18,
      "z": 7,
      "name": "Rock_Quartzite_Brick"
    },
    {
      "x": -5,
      "y": 19,
      "z": 7,
      "name": "Rock_Quartzite_Brick"
    },
    {
      "x": -5,
      "y": 20,
      "z": 7,
      "name": "Rock_Quartzite"
    },
    {
      "x": -5,
      "y": 21,
      "z": 7,
      "name": "Rock_Quartzite"
    },
    {
      "x": -5,
      "y": 22,
      "z": 7,
      "name": "Rock_Quartzite_Cobble"
    },
    {
      "x": -5,
      "y": 23,
      "z": 7,
      "name": "Rock_Stone"
    },
    {
      "x": -5,
      "y": 0,
      "z": 8,
      "name": "Rock_Stone"
    },
    {
      "x": -5,
      "y": 1,
      "z": 8,
      "name": "Rock_Stone"
    },
    {
      "x": -5,
      "y": 2,
      "z": 8,
      "name": "Rock_Stone_Brick"
    },
    {
      "x": -5,
      "y": 3,
      "z": 8,
      "name": "Rock_Stone_Brick"
    },
    {
      "x": -5,
      "y": 4,
      "z": 8,
      "name": "Rock_Stone"
    },
    {
      "x": -5,
      "y": 5,
      "z": 8,
      "name": "Rock_Stone"
    },
    {
      "x": -5,
      "y": 6,
      "z": 8,
      "name": "Rock_Stone"
    },
    {
      "x": -5,
      "y": 7,
      "z": 8,
      "name": "Rock_Stone"
    },
    {
      "x": -5,
      "y": 16,
      "z": 8,
      "name": "Rock_Stone"
    },
    {
      "x": -5,
      "y": 17,
      "z": 8,
      "name": "Rock_Quartzite"
    },
    {
      "x": -5,
      "y": 18,
      "z": 8,
      "name": "Rock_Quartzite_Brick"
    },
    {
      "x": -5,
      "y": 19,
      "z": 8,
      "name": "Rock_Quartzite_Brick"
    },
    {
      "x": -5,
      "y": 20,
      "z": 8,
      "name": "Rock_Quartzite_Cobble"
    },
    {
      "x": -5,
      "y": 21,
      "z": 8,
      "name": "Rock_Quartzite"
    },
    {
      "x": -5,
      "y": 22,
      "z": 8,
      "name": "Rock_Quartzite"
    },
    {
      "x": -5,
      "y": 23,
      "z": 8,
      "name": "Rock_Stone"
    },
    {
      "x": -5,
      "y": 0,
      "z": 9,
      "name": "Rock_Stone"
    },
    {
      "x": -5,
      "y": 1,
      "z": 9,
      "name": "Rock_Stone"
    },
    {
      "x": -5,
      "y": 2,
      "z": 9,
      "name": "Rock_Stone_Brick"
    },
    {
      "x": -5,
      "y": 3,
      "z": 9,
      "name": "Rock_Stone_Brick"
    },
    {
      "x": -5,
      "y": 4,
      "z": 9,
      "name": "Rock_Stone"
    },
    {
      "x": -5,
      "y": 5,
      "z": 9,
      "name": "Rock_Stone"
    },
    {
      "x": -5,
      "y": 6,
      "z": 9,
      "name": "Rock_Stone"
    },
    {
      "x": -5,
      "y": 7,
      "z": 9,
      "name": "Rock_Stone"
    },
    {
      "x": -5,
      "y": 16,
      "z": 9,
      "name": "Rock_Stone"
    },
    {
      "x": -5,
      "y": 17,
      "z": 9,
      "name": "Rock_Quartzite"
    },
    {
      "x": -5,
      "y": 18,
      "z": 9,
      "name": "Rock_Quartzite_Brick"
    },
    {
      "x": -5,
      "y": 19,
      "z": 9,
      "name": "Rock_Quartzite_Cobble"
    },
    {
      "x": -5,
      "y": 20,
      "z": 9,
      "name": "Rock_Quartzite_Cobble"
    },
    {
      "x": -5,
      "y": 21,
      "z": 9,
      "name": "Rock_Quartzite"
    },
    {
      "x": -5,
      "y": 22,
      "z": 9,
      "name": "Rock_Quartzite"
    },
    {
      "x": -5,
      "y": 23,
      "z": 9,
      "name": "Rock_Stone"
    },
    {
      "x": -4,
      "y": 6,
      "z": -9,
      "name": "Rock_Stone"
    },
    {
      "x": -4,
      "y": 7,
      "z": -9,
      "name": "Rock_Stone"
    },
    {
      "x": -4,
      "y": 8,
      "z": -9,
      "name": "Rock_Quartzite_Brick"
    },
    {
      "x": -4,
      "y": 9,
      "z": -9,
      "name": "Rock_Quartzite_Brick"
    },
    {
      "x": -4,
      "y": 10,
      "z": -9,
      "name": "Rock_Quartzite"
    },
    {
      "x": -4,
      "y": 11,
      "z": -9,
      "name": "Rock_Quartzite"
    },
    {
      "x": -4,
      "y": 12,
      "z": -9,
      "name": "Rock_Quartzite"
    },
    {
      "x": -4,
      "y": 13,
      "z": -9,
      "name": "Rock_Quartzite"
    },
    {
      "x": -4,
      "y": 14,
      "z": -9,
      "name": "Rock_Quartzite"
    },
    {
      "x": -4,
      "y": 15,
      "z": -9,
      "name": "Rock_Quartzite"
    },
    {
      "x": -4,
      "y": 6,
      "z": -8,
      "name": "Rock_Stone"
    },
    {
      "x": -4,
      "y": 7,
      "z": -8,
      "name": "Rock_Stone_Cobble"
    },
    {
      "x": -4,
      "y": 8,
      "z": -8,
      "name": "Rock_Quartzite"
    },
    {
      "x": -4,
      "y": 9,
      "z": -8,
      "name": "Rock_Quartzite"
    },
    {
      "x": -4,
      "y": 10,
      "z": -8,
      "name": "Rock_Stone_Brick"
    },
    {
      "x": -4,
      "y": 11,
      "z": -8,
      "name": "Rock_Stone_Brick"
    },
    {
      "x": -4,
      "y": 12,
      "z": -8,
      "name": "Rock_Stone_Brick"
    },
    {
      "x": -4,
      "y": 13,
      "z": -8,
      "name": "Rock_Quartzite"
    },
    {
      "x": -4,
      "y": 14,
      "z": -8,
      "name": "Rock_Quartzite"
    },
    {
      "x": -4,
      "y": 15,
      "z": -8,
      "name": "Rock_Quartzite"
    },
    {
      "x": -4,
      "y": 6,
      "z": -7,
      "name": "Rock_Stone"
    },
    {
      "x": -4,
      "y": 7,
      "z": -7,
      "name": "Rock_Stone_Cobble"
    },
    {
      "x": -4,
      "y": 8,
      "z": -7,
      "name": "Rock_Quartzite"
    },
    {
      "x": -4,
      "y": 9,
      "z": -7,
      "name": "Empty"
    },
    {
      "x": -4,
      "y": 10,
      "z": -7,
      "name": "Empty"
    },
    {
      "x": -4,
      "y": 11,
      "z": -7,
      "name": "Empty"
    },
    {
      "x": -4,
      "y": 12,
      "z": -7,
      "name": "Empty"
    },
    {
      "x": -4,
      "y": 13,
      "z": -7,
      "name": "Rock_Quartzite"
    },
    {
      "x": -4,
      "y": 14,
      "z": -7,
      "name": "Rock_Quartzite"
    },
    {
      "x": -4,
      "y": 15,
      "z": -7,
      "name": "Rock_Quartzite"
    },
    {
      "x": -4,
      "y": 6,
      "z": -6,
      "name": "Rock_Stone"
    },
    {
      "x": -4,
      "y": 7,
      "z": -6,
      "name": "Rock_Stone_Cobble"
    },
    {
      "x": -4,
      "y": 8,
      "z": -6,
      "name": "Empty"
    },
    {
      "x": -4,
      "y": 9,
      "z": -6,
      "name": "Empty"
    },
    {
      "x": -4,
      "y": 10,
      "z": -6,
      "name": "Empty"
    },
    {
      "x": -4,
      "y": 11,
      "z": -6,
      "name": "Empty"
    },
    {
      "x": -4,
      "y": 12,
      "z": -6,
      "name": "Empty"
    },
    {
      "x": -4,
      "y": 13,
      "z": -6,
      "name": "Rock_Stone"
    },
    {
      "x": -4,
      "y": 14,
      "z": -6,
      "name": "Rock_Stone"
    },
    {
      "x": -4,
      "y": 15,
      "z": -6,
      "name": "Rock_Quartzite"
    },
    {
      "x": -4,
      "y": 6,
      "z": -5,
      "name": "Rock_Stone"
    },
    {
      "x": -4,
      "y": 7,
      "z": -5,
      "name": "Soil_Pathway"
    },
    {
      "x": -4,
      "y": 8,
      "z": -5,
      "name": "Empty"
    },
    {
      "x": -4,
      "y": 9,
      "z": -5,
      "name": "Empty"
    },
    {
      "x": -4,
      "y": 10,
      "z": -5,
      "name": "Empty"
    },
    {
      "x": -4,
      "y": 11,
      "z": -5,
      "name": "Empty"
    },
    {
      "x": -4,
      "y": 12,
      "z": -5,
      "name": "Empty"
    },
    {
      "x": -4,
      "y": 13,
      "z": -5,
      "name": "Rock_Stone"
    },
    {
      "x": -4,
      "y": 14,
      "z": -5,
      "name": "Rock_Stone"
    },
    {
      "x": -4,
      "y": 15,
      "z": -5,
      "name": "Rock_Quartzite"
    },
    {
      "x": -4,
      "y": 6,
      "z": -4,
      "name": "Rock_Stone"
    },
    {
      "x": -4,
      "y": 7,
      "z": -4,
      "name": "Soil_Pathway"
    },
    {
      "x": -4,
      "y": 8,
      "z": -4,
      "name": "Soil_Pathway_Half"
    },
    {
      "x": -4,
      "y": 9,
      "z": -4,
      "name": "Empty"
    },
    {
      "x": -4,
      "y": 10,
      "z": -4,
      "name": "Empty"
    },
    {
      "x": -4,
      "y": 11,
      "z": -4,
      "name": "Empty"
    },
    {
      "x": -4,
      "y": 12,
      "z": -4,
      "name": "Rock_Stone_Stalactite_Large",
      "filler": 31744,
      "rotation": 8
    },
    {
      "x": -4,
      "y": 13,
      "z": -4,
      "name": "Rock_Stone_Stalactite_Large",
      "rotation": 8
    },
    {
      "x": -4,
      "y": 14,
      "z": -4,
      "name": "Rock_Stone"
    },
    {
      "x": -4,
      "y": 15,
      "z": -4,
      "name": "Rock_Quartzite"
    },
    {
      "x": -4,
      "y": 6,
      "z": -3,
      "name": "Rock_Stone"
    },
    {
      "x": -4,
      "y": 7,
      "z": -3,
      "name": "Rock_Stone"
    },
    {
      "x": -4,
      "y": 8,
      "z": -3,
      "name": "Rock_Quartzite_Brick"
    },
    {
      "x": -4,
      "y": 9,
      "z": -3,
      "name": "Rock_Quartzite_Brick_Half",
      "rotation": 5
    },
    {
      "x": -4,
      "y": 10,
      "z": -3,
      "name": "Rock_Quartzite_Brick_Half",
      "rotation": 5
    },
    {
      "x": -4,
      "y": 11,
      "z": -3,
      "name": "Rock_Quartzite_Brick_Half",
      "rotation": 5
    },
    {
      "x": -4,
      "y": 12,
      "z": -3,
      "name": "Rock_Quartzite_Brick_Half",
      "rotation": 5
    },
    {
      "x": -4,
      "y": 13,
      "z": -3,
      "name": "Rock_Quartzite_Brick_Half",
      "rotation": 5
    },
    {
      "x": -4,
      "y": 14,
      "z": -3,
      "name": "Rock_Quartzite_Brick"
    },
    {
      "x": -4,
      "y": 15,
      "z": -3,
      "name": "Rock_Quartzite"
    },
    {
      "x": -4,
      "y": 8,
      "z": -2,
      "name": "Rock_Stone"
    },
    {
      "x": -4,
      "y": 9,
      "z": -2,
      "name": "Rock_Stone_Cobble_Stairs",
      "rotation": 2
    },
    {
      "x": -4,
      "y": 10,
      "z": -2,
      "name": "Empty"
    },
    {
      "x": -4,
      "y": 11,
      "z": -2,
      "name": "Empty"
    },
    {
      "x": -4,
      "y": 12,
      "z": -2,
      "name": "Empty"
    },
    {
      "x": -4,
      "y": 13,
      "z": -2,
      "name": "Empty"
    },
    {
      "x": -4,
      "y": 14,
      "z": -2,
      "name": "Empty"
    },
    {
      "x": -4,
      "y": 15,
      "z": -2,
      "name": "Rock_Quartzite_Brick"
    },
    {
      "x": -4,
      "y": 9,
      "z": -1,
      "name": "Rock_Stone"
    },
    {
      "x": -4,
      "y": 10,
      "z": -1,
      "name": "Rock_Stone_Cobble_Stairs",
      "rotation": 2
    },
    {
      "x": -4,
      "y": 11,
      "z": -1,
      "name": "Empty"
    },
    {
      "x": -4,
      "y": 12,
      "z": -1,
      "name": "Empty"
    },
    {
      "x": -4,
      "y": 13,
      "z": -1,
      "name": "Empty"
    },
    {
      "x": -4,
      "y": 14,
      "z": -1,
      "name": "Empty"
    },
    {
      "x": -4,
      "y": 15,
      "z": -1,
      "name": "Empty"
    },
    {
      "x": -4,
      "y": 16,
      "z": -1,
      "name": "Rock_Quartzite_Brick"
    },
    {
      "x": -4,
      "y": 10,
      "z": 0,
      "name": "Rock_Stone"
    },
    {
      "x": -4,
      "y": 11,
      "z": 0,
      "name": "Rock_Stone_Cobble_Stairs",
      "rotation": 2
    },
    {
      "x": -4,
      "y": 12,
      "z": 0,
      "name": "Empty"
    },
    {
      "x": -4,
      "y": 13,
      "z": 0,
      "name": "Empty"
    },
    {
      "x": -4,
      "y": 14,
      "z": 0,
      "name": "Empty"
    },
    {
      "x": -4,
      "y": 15,
      "z": 0,
      "name": "Empty"
    },
    {
      "x": -4,
      "y": 16,
      "z": 0,
      "name": "Empty"
    },
    {
      "x": -4,
      "y": 17,
      "z": 0,
      "name": "Rock_Quartzite_Brick"
    },
    {
      "x": -4,
      "y": 11,
      "z": 1,
      "name": "Rock_Stone"
    },
    {
      "x": -4,
      "y": 12,
      "z": 1,
      "name": "Rock_Stone_Cobble_Stairs",
      "rotation": 2
    },
    {
      "x": -4,
      "y": 13,
      "z": 1,
      "name": "Empty"
    },
    {
      "x": -4,
      "y": 14,
      "z": 1,
      "name": "Empty"
    },
    {
      "x": -4,
      "y": 15,
      "z": 1,
      "name": "Empty"
    },
    {
      "x": -4,
      "y": 16,
      "z": 1,
      "name": "Empty"
    },
    {
      "x": -4,
      "y": 17,
      "z": 1,
      "name": "Empty"
    },
    {
      "x": -4,
      "y": 18,
      "z": 1,
      "name": "Rock_Quartzite_Brick"
    },
    {
      "x": -4,
      "y": 12,
      "z": 2,
      "name": "Rock_Stone"
    },
    {
      "x": -4,
      "y": 13,
      "z": 2,
      "name": "Rock_Stone_Cobble_Stairs",
      "rotation": 2
    },
    {
      "x": -4,
      "y": 14,
      "z": 2,
      "name": "Empty"
    },
    {
      "x": -4,
      "y": 15,
      "z": 2,
      "name": "Empty"
    },
    {
      "x": -4,
      "y": 16,
      "z": 2,
      "name": "Empty"
    },
    {
      "x": -4,
      "y": 17,
      "z": 2,
      "name": "Empty"
    },
    {
      "x": -4,
      "y": 18,
      "z": 2,
      "name": "Empty"
    },
    {
      "x": -4,
      "y": 19,
      "z": 2,
      "name": "Rock_Quartzite_Brick"
    },
    {
      "x": -4,
      "y": 0,
      "z": 3,
      "name": "Rock_Stone"
    },
    {
      "x": -4,
      "y": 1,
      "z": 3,
      "name": "Rock_Stone"
    },
    {
      "x": -4,
      "y": 2,
      "z": 3,
      "name": "Rock_Stone_Brick"
    },
    {
      "x": -4,
      "y": 3,
      "z": 3,
      "name": "Rock_Stone_Brick"
    },
    {
      "x": -4,
      "y": 4,
      "z": 3,
      "name": "Rock_Stone"
    },
    {
      "x": -4,
      "y": 5,
      "z": 3,
      "name": "Rock_Stone"
    },
    {
      "x": -4,
      "y": 6,
      "z": 3,
      "name": "Rock_Stone"
    },
    {
      "x": -4,
      "y": 7,
      "z": 3,
      "name": "Rock_Stone"
    },
    {
      "x": -4,
      "y": 13,
      "z": 3,
      "name": "Rock_Stone"
    },
    {
      "x": -4,
      "y": 14,
      "z": 3,
      "name": "Soil_Pathway"
    },
    {
      "x": -4,
      "y": 15,
      "z": 3,
      "name": "Plant_Crop_Mushroom_Flatcap_Green",
      "components": {
        "Components": {
          "FarmingBlock": {}
        }
      }
    },
    {
      "x": -4,
      "y": 16,
      "z": 3,
      "name": "Empty"
    },
    {
      "x": -4,
      "y": 17,
      "z": 3,
      "name": "Empty"
    },
    {
      "x": -4,
      "y": 18,
      "z": 3,
      "name": "Empty"
    },
    {
      "x": -4,
      "y": 19,
      "z": 3,
      "name": "Empty"
    },
    {
      "x": -4,
      "y": 20,
      "z": 3,
      "name": "Rock_Quartzite_Brick"
    },
    {
      "x": -4,
      "y": 0,
      "z": 4,
      "name": "Rock_Stone"
    },
    {
      "x": -4,
      "y": 1,
      "z": 4,
      "name": "Rock_Stone"
    },
    {
      "x": -4,
      "y": 2,
      "z": 4,
      "name": "Rock_Stone_Brick"
    },
    {
      "x": -4,
      "y": 3,
      "z": 4,
      "name": "Rock_Stone_Brick"
    },
    {
      "x": -4,
      "y": 4,
      "z": 4,
      "name": "Rock_Stone_Cobble"
    },
    {
      "x": -4,
      "y": 5,
      "z": 4,
      "name": "Rock_Stone_Cobble"
    },
    {
      "x": -4,
      "y": 6,
      "z": 4,
      "name": "Rock_Stone"
    },
    {
      "x": -4,
      "y": 7,
      "z": 4,
      "name": "Rock_Stone"
    },
    {
      "x": -4,
      "y": 14,
      "z": 4,
      "name": "Rock_Stone"
    },
    {
      "x": -4,
      "y": 15,
      "z": 4,
      "name": "Soil_Pathway"
    },
    {
      "x": -4,
      "y": 16,
      "z": 4,
      "name": "Empty"
    },
    {
      "x": -4,
      "y": 17,
      "z": 4,
      "name": "Empty"
    },
    {
      "x": -4,
      "y": 18,
      "z": 4,
      "name": "Empty"
    },
    {
      "x": -4,
      "y": 19,
      "z": 4,
      "name": "Plant_Vine_Wall"
    },
    {
      "x": -4,
      "y": 20,
      "z": 4,
      "name": "Plant_Vine"
    },
    {
      "x": -4,
      "y": 21,
      "z": 4,
      "name": "Rock_Quartzite_Brick"
    },
    {
      "x": -4,
      "y": 22,
      "z": 4,
      "name": "Rock_Quartzite_Brick"
    },
    {
      "x": -4,
      "y": 23,
      "z": 4,
      "name": "Rock_Quartzite_Brick"
    },
    {
      "x": -4,
      "y": 0,
      "z": 5,
      "name": "Rock_Stone"
    },
    {
      "x": -4,
      "y": 1,
      "z": 5,
      "name": "Rock_Stone_Cobble"
    },
    {
      "x": -4,
      "y": 2,
      "z": 5,
      "name": "Rock_Stone_Brick"
    },
    {
      "x": -4,
      "y": 3,
      "z": 5,
      "name": "Rock_Stone_Brick"
    },
    {
      "x": -4,
      "y": 4,
      "z": 5,
      "name": "Rock_Stone_Brick"
    },
    {
      "x": -4,
      "y": 5,
      "z": 5,
      "name": "Rock_Stone_Brick"
    },
    {
      "x": -4,
      "y": 6,
      "z": 5,
      "name": "Rock_Stone_Brick"
    },
    {
      "x": -4,
      "y": 7,
      "z": 5,
      "name": "Rock_Stone"
    },
    {
      "x": -4,
      "y": 15,
      "z": 5,
      "name": "Rock_Stone"
    },
    {
      "x": -4,
      "y": 16,
      "z": 5,
      "name": "Rock_Stone_Cobble_Half"
    },
    {
      "x": -4,
      "y": 17,
      "z": 5,
      "name": "Empty"
    },
    {
      "x": -4,
      "y": 18,
      "z": 5,
      "name": "Empty"
    },
    {
      "x": -4,
      "y": 19,
      "z": 5,
      "name": "Empty"
    },
    {
      "x": -4,
      "y": 20,
      "z": 5,
      "name": "Empty"
    },
    {
      "x": -4,
      "y": 21,
      "z": 5,
      "name": "Rock_Quartzite"
    },
    {
      "x": -4,
      "y": 22,
      "z": 5,
      "name": "Rock_Quartzite_Brick"
    },
    {
      "x": -4,
      "y": 23,
      "z": 5,
      "name": "Rock_Stone"
    },
    {
      "x": -4,
      "y": 0,
      "z": 6,
      "name": "Rock_Stone"
    },
    {
      "x": -4,
      "y": 1,
      "z": 6,
      "name": "Rock_Stone_Cobble"
    },
    {
      "x": -4,
      "y": 2,
      "z": 6,
      "name": "Rubble_Stone"
    },
    {
      "x": -4,
      "y": 3,
      "z": 6,
      "name": "Empty"
    },
    {
      "x": -4,
      "y": 4,
      "z": 6,
      "name": "Empty"
    },
    {
      "x": -4,
      "y": 5,
      "z": 6,
      "name": "Empty"
    },
    {
      "x": -4,
      "y": 6,
      "z": 6,
      "name": "Empty"
    },
    {
      "x": -4,
      "y": 7,
      "z": 6,
      "name": "Rock_Stone"
    },
    {
      "x": -4,
      "y": 16,
      "z": 6,
      "name": "Rock_Stone_Cobble_Mossy"
    },
    {
      "x": -4,
      "y": 17,
      "z": 6,
      "name": "Rock_Stone_Cobble_Half"
    },
    {
      "x": -4,
      "y": 18,
      "z": 6,
      "name": "Empty"
    },
    {
      "x": -4,
      "y": 19,
      "z": 6,
      "name": "Empty"
    },
    {
      "x": -4,
      "y": 20,
      "z": 6,
      "name": "Empty"
    },
    {
      "x": -4,
      "y": 21,
      "z": 6,
      "name": "Rock_Quartzite"
    },
    {
      "x": -4,
      "y": 22,
      "z": 6,
      "name": "Rock_Quartzite"
    },
    {
      "x": -4,
      "y": 23,
      "z": 6,
      "name": "Rock_Stone"
    },
    {
      "x": -4,
      "y": 0,
      "z": 7,
      "name": "Rock_Stone"
    },
    {
      "x": -4,
      "y": 1,
      "z": 7,
      "name": "Rock_Stone"
    },
    {
      "x": -4,
      "y": 2,
      "z": 7,
      "name": "Empty"
    },
    {
      "x": -4,
      "y": 3,
      "z": 7,
      "name": "Rock_Stone_Stalactite_Large",
      "filler": 31744,
      "rotation": 8
    },
    {
      "x": -4,
      "y": 4,
      "z": 7,
      "name": "Rock_Stone_Stalactite_Large",
      "rotation": 8
    },
    {
      "x": -4,
      "y": 5,
      "z": 7,
      "name": "Rock_Stone"
    },
    {
      "x": -4,
      "y": 6,
      "z": 7,
      "name": "Rock_Stone"
    },
    {
      "x": -4,
      "y": 7,
      "z": 7,
      "name": "Rock_Stone"
    },
    {
      "x": -4,
      "y": 16,
      "z": 7,
      "name": "Rock_Stone"
    },
    {
      "x": -4,
      "y": 17,
      "z": 7,
      "name": "Rock_Stone_Cobble"
    },
    {
      "x": -4,
      "y": 18,
      "z": 7,
      "name": "Plant_Moss_Rug_Green"
    },
    {
      "x": -4,
      "y": 19,
      "z": 7,
      "name": "Empty"
    },
    {
      "x": -4,
      "y": 20,
      "z": 7,
      "name": "Plant_Vine_Wall",
      "rotation": 1
    },
    {
      "x": -4,
      "y": 21,
      "z": 7,
      "name": "Plant_Vine",
      "rotation": 1
    },
    {
      "x": -4,
      "y": 22,
      "z": 7,
      "name": "Rock_Quartzite"
    },
    {
      "x": -4,
      "y": 23,
      "z": 7,
      "name": "Rock_Stone"
    },
    {
      "x": -4,
      "y": 0,
      "z": 8,
      "name": "Rock_Stone"
    },
    {
      "x": -4,
      "y": 1,
      "z": 8,
      "name": "Rock_Stone"
    },
    {
      "x": -4,
      "y": 2,
      "z": 8,
      "name": "Furniture_Ancient_Pot"
    },
    {
      "x": -4,
      "y": 3,
      "z": 8,
      "name": "Empty"
    },
    {
      "x": -4,
      "y": 4,
      "z": 8,
      "name": "Empty"
    },
    {
      "x": -4,
      "y": 5,
      "z": 8,
      "name": "Rock_Stone"
    },
    {
      "x": -4,
      "y": 6,
      "z": 8,
      "name": "Rock_Stone"
    },
    {
      "x": -4,
      "y": 7,
      "z": 8,
      "name": "Rock_Stone"
    },
    {
      "x": -4,
      "y": 16,
      "z": 8,
      "name": "Rock_Stone"
    },
    {
      "x": -4,
      "y": 17,
      "z": 8,
      "name": "Rock_Stone_Cobble"
    },
    {
      "x": -4,
      "y": 18,
      "z": 8,
      "name": "Rubble_Stone_Medium"
    },
    {
      "x": -4,
      "y": 19,
      "z": 8,
      "name": "Empty"
    },
    {
      "x": -4,
      "y": 20,
      "z": 8,
      "name": "Empty"
    },
    {
      "x": -4,
      "y": 21,
      "z": 8,
      "name": "Plant_Vine_Wall",
      "rotation": 1
    },
    {
      "x": -4,
      "y": 22,
      "z": 8,
      "name": "Plant_Vine",
      "rotation": 1
    },
    {
      "x": -4,
      "y": 23,
      "z": 8,
      "name": "Rock_Stone"
    },
    {
      "x": -4,
      "y": 0,
      "z": 9,
      "name": "Rock_Stone"
    },
    {
      "x": -4,
      "y": 1,
      "z": 9,
      "name": "Rock_Stone"
    },
    {
      "x": -4,
      "y": 2,
      "z": 9,
      "name": "Rock_Stone_Brick_Decorative"
    },
    {
      "x": -4,
      "y": 3,
      "z": 9,
      "name": "Rock_Stone_Brick"
    },
    {
      "x": -4,
      "y": 4,
      "z": 9,
      "name": "Rock_Stone_Brick"
    },
    {
      "x": -4,
      "y": 5,
      "z": 9,
      "name": "Rock_Stone_Brick"
    },
    {
      "x": -4,
      "y": 6,
      "z": 9,
      "name": "Rock_Stone_Brick"
    },
    {
      "x": -4,
      "y": 7,
      "z": 9,
      "name": "Rock_Stone"
    },
    {
      "x": -4,
      "y": 16,
      "z": 9,
      "name": "Rock_Stone"
    },
    {
      "x": -4,
      "y": 17,
      "z": 9,
      "name": "Rock_Stone_Cobble"
    },
    {
      "x": -4,
      "y": 18,
      "z": 9,
      "name": "Rubble_Stone"
    },
    {
      "x": -4,
      "y": 19,
      "z": 9,
      "name": "Empty"
    },
    {
      "x": -4,
      "y": 20,
      "z": 9,
      "name": "Empty"
    },
    {
      "x": -4,
      "y": 21,
      "z": 9,
      "name": "Empty"
    },
    {
      "x": -4,
      "y": 22,
      "z": 9,
      "name": "Plant_Vine",
      "rotation": 1
    },
    {
      "x": -4,
      "y": 23,
      "z": 9,
      "name": "Rock_Stone"
    },
    {
      "x": -3,
      "y": 6,
      "z": -9,
      "name": "Rock_Stone"
    },
    {
      "x": -3,
      "y": 7,
      "z": -9,
      "name": "Rock_Stone"
    },
    {
      "x": -3,
      "y": 8,
      "z": -9,
      "name": "Rock_Quartzite_Brick"
    },
    {
      "x": -3,
      "y": 9,
      "z": -9,
      "name": "Rock_Quartzite_Brick"
    },
    {
      "x": -3,
      "y": 10,
      "z": -9,
      "name": "Rock_Quartzite"
    },
    {
      "x": -3,
      "y": 11,
      "z": -9,
      "name": "Rock_Quartzite"
    },
    {
      "x": -3,
      "y": 12,
      "z": -9,
      "name": "Rock_Quartzite"
    },
    {
      "x": -3,
      "y": 13,
      "z": -9,
      "name": "Rock_Quartzite"
    },
    {
      "x": -3,
      "y": 14,
      "z": -9,
      "name": "Rock_Quartzite_Cobble"
    },
    {
      "x": -3,
      "y": 15,
      "z": -9,
      "name": "Rock_Quartzite"
    },
    {
      "x": -3,
      "y": 6,
      "z": -8,
      "name": "Rock_Stone"
    },
    {
      "x": -3,
      "y": 7,
      "z": -8,
      "name": "Rock_Stone_Cobble"
    },
    {
      "x": -3,
      "y": 8,
      "z": -8,
      "name": "Rock_Quartzite"
    },
    {
      "x": -3,
      "y": 9,
      "z": -8,
      "name": "Rock_Quartzite"
    },
    {
      "x": -3,
      "y": 10,
      "z": -8,
      "name": "Empty"
    },
    {
      "x": -3,
      "y": 11,
      "z": -8,
      "name": "Empty"
    },
    {
      "x": -3,
      "y": 12,
      "z": -8,
      "name": "Empty"
    },
    {
      "x": -3,
      "y": 13,
      "z": -8,
      "name": "Rock_Quartzite"
    },
    {
      "x": -3,
      "y": 14,
      "z": -8,
      "name": "Rock_Quartzite"
    },
    {
      "x": -3,
      "y": 15,
      "z": -8,
      "name": "Rock_Quartzite"
    },
    {
      "x": -3,
      "y": 6,
      "z": -7,
      "name": "Rock_Stone"
    },
    {
      "x": -3,
      "y": 7,
      "z": -7,
      "name": "Rock_Stone_Cobble"
    },
    {
      "x": -3,
      "y": 8,
      "z": -7,
      "name": "Empty"
    },
    {
      "x": -3,
      "y": 9,
      "z": -7,
      "name": "Empty"
    },
    {
      "x": -3,
      "y": 10,
      "z": -7,
      "name": "Empty"
    },
    {
      "x": -3,
      "y": 11,
      "z": -7,
      "name": "Empty"
    },
    {
      "x": -3,
      "y": 12,
      "z": -7,
      "name": "Empty"
    },
    {
      "x": -3,
      "y": 13,
      "z": -7,
      "name": "Rock_Quartzite"
    },
    {
      "x": -3,
      "y": 14,
      "z": -7,
      "name": "Rock_Quartzite"
    },
    {
      "x": -3,
      "y": 15,
      "z": -7,
      "name": "Rock_Quartzite"
    },
    {
      "x": -3,
      "y": 6,
      "z": -6,
      "name": "Rock_Stone"
    },
    {
      "x": -3,
      "y": 7,
      "z": -6,
      "name": "Soil_Pathway"
    },
    {
      "x": -3,
      "y": 8,
      "z": -6,
      "name": "Empty"
    },
    {
      "x": -3,
      "y": 9,
      "z": -6,
      "name": "Empty"
    },
    {
      "x": -3,
      "y": 10,
      "z": -6,
      "name": "Empty"
    },
    {
      "x": -3,
      "y": 11,
      "z": -6,
      "name": "Empty"
    },
    {
      "x": -3,
      "y": 12,
      "z": -6,
      "name": "Empty"
    },
    {
      "x": -3,
      "y": 13,
      "z": -6,
      "name": "Empty"
    },
    {
      "x": -3,
      "y": 14,
      "z": -6,
      "name": "Empty"
    },
    {
      "x": -3,
      "y": 15,
      "z": -6,
      "name": "Rock_Stone"
    },
    {
      "x": -3,
      "y": 6,
      "z": -5,
      "name": "Rock_Stone"
    },
    {
      "x": -3,
      "y": 7,
      "z": -5,
      "name": "Soil_Pathway"
    },
    {
      "x": -3,
      "y": 8,
      "z": -5,
      "name": "Empty"
    },
    {
      "x": -3,
      "y": 9,
      "z": -5,
      "name": "Empty"
    },
    {
      "x": -3,
      "y": 10,
      "z": -5,
      "name": "Empty"
    },
    {
      "x": -3,
      "y": 11,
      "z": -5,
      "name": "Empty"
    },
    {
      "x": -3,
      "y": 12,
      "z": -5,
      "name": "Empty"
    },
    {
      "x": -3,
      "y": 13,
      "z": -5,
      "name": "Empty"
    },
    {
      "x": -3,
      "y": 14,
      "z": -5,
      "name": "Empty"
    },
    {
      "x": -3,
      "y": 15,
      "z": -5,
      "name": "Rock_Stone"
    },
    {
      "x": -3,
      "y": 6,
      "z": -4,
      "name": "Rock_Stone"
    },
    {
      "x": -3,
      "y": 7,
      "z": -4,
      "name": "Soil_Pathway"
    },
    {
      "x": -3,
      "y": 8,
      "z": -4,
      "name": "Empty"
    },
    {
      "x": -3,
      "y": 9,
      "z": -4,
      "name": "Empty"
    },
    {
      "x": -3,
      "y": 10,
      "z": -4,
      "name": "Empty"
    },
    {
      "x": -3,
      "y": 11,
      "z": -4,
      "name": "Empty"
    },
    {
      "x": -3,
      "y": 12,
      "z": -4,
      "name": "Empty"
    },
    {
      "x": -3,
      "y": 13,
      "z": -4,
      "name": "Empty"
    },
    {
      "x": -3,
      "y": 14,
      "z": -4,
      "name": "Empty"
    },
    {
      "x": -3,
      "y": 15,
      "z": -4,
      "name": "Rock_Stone"
    },
    {
      "x": -3,
      "y": 6,
      "z": -3,
      "name": "Rock_Stone"
    },
    {
      "x": -3,
      "y": 7,
      "z": -3,
      "name": "Rock_Stone"
    },
    {
      "x": -3,
      "y": 8,
      "z": -3,
      "name": "Rock_Stone_Cobble_Stairs",
      "rotation": 2
    },
    {
      "x": -3,
      "y": 9,
      "z": -3,
      "name": "Empty"
    },
    {
      "x": -3,
      "y": 10,
      "z": -3,
      "name": "Empty"
    },
    {
      "x": -3,
      "y": 11,
      "z": -3,
      "name": "Empty"
    },
    {
      "x": -3,
      "y": 12,
      "z": -3,
      "name": "Empty"
    },
    {
      "x": -3,
      "y": 13,
      "z": -3,
      "name": "Empty"
    },
    {
      "x": -3,
      "y": 14,
      "z": -3,
      "name": "Rock_Quartzite_Brick_Half",
      "rotation": 8
    },
    {
      "x": -3,
      "y": 15,
      "z": -3,
      "name": "Rock_Quartzite"
    },
    {
      "x": -3,
      "y": 8,
      "z": -2,
      "name": "Rock_Stone"
    },
    {
      "x": -3,
      "y": 9,
      "z": -2,
      "name": "Rock_Stone_Cobble_Stairs",
      "rotation": 2
    },
    {
      "x": -3,
      "y": 10,
      "z": -2,
      "name": "Empty"
    },
    {
      "x": -3,
      "y": 11,
      "z": -2,
      "name": "Empty"
    },
    {
      "x": -3,
      "y": 12,
      "z": -2,
      "name": "Empty"
    },
    {
      "x": -3,
      "y": 13,
      "z": -2,
      "name": "Empty"
    },
    {
      "x": -3,
      "y": 14,
      "z": -2,
      "name": "Empty"
    },
    {
      "x": -3,
      "y": 15,
      "z": -2,
      "name": "Rock_Quartzite_Brick"
    },
    {
      "x": -3,
      "y": 9,
      "z": -1,
      "name": "Rock_Stone"
    },
    {
      "x": -3,
      "y": 10,
      "z": -1,
      "name": "Rock_Stone_Cobble_Stairs",
      "rotation": 2
    },
    {
      "x": -3,
      "y": 11,
      "z": -1,
      "name": "Empty"
    },
    {
      "x": -3,
      "y": 12,
      "z": -1,
      "name": "Empty"
    },
    {
      "x": -3,
      "y": 13,
      "z": -1,
      "name": "Empty"
    },
    {
      "x": -3,
      "y": 14,
      "z": -1,
      "name": "Empty"
    },
    {
      "x": -3,
      "y": 15,
      "z": -1,
      "name": "Empty"
    },
    {
      "x": -3,
      "y": 16,
      "z": -1,
      "name": "Rock_Quartzite_Brick"
    },
    {
      "x": -3,
      "y": 10,
      "z": 0,
      "name": "Rock_Stone"
    },
    {
      "x": -3,
      "y": 11,
      "z": 0,
      "name": "Rock_Stone_Cobble_Stairs",
      "rotation": 2
    },
    {
      "x": -3,
      "y": 12,
      "z": 0,
      "name": "Empty"
    },
    {
      "x": -3,
      "y": 13,
      "z": 0,
      "name": "Empty"
    },
    {
      "x": -3,
      "y": 14,
      "z": 0,
      "name": "Empty"
    },
    {
      "x": -3,
      "y": 15,
      "z": 0,
      "name": "Empty"
    },
    {
      "x": -3,
      "y": 16,
      "z": 0,
      "name": "Empty"
    },
    {
      "x": -3,
      "y": 17,
      "z": 0,
      "name": "Rock_Quartzite_Brick"
    },
    {
      "x": -3,
      "y": 11,
      "z": 1,
      "name": "Rock_Stone"
    },
    {
      "x": -3,
      "y": 12,
      "z": 1,
      "name": "Rock_Stone_Cobble_Stairs",
      "rotation": 2
    },
    {
      "x": -3,
      "y": 13,
      "z": 1,
      "name": "Empty"
    },
    {
      "x": -3,
      "y": 14,
      "z": 1,
      "name": "Empty"
    },
    {
      "x": -3,
      "y": 15,
      "z": 1,
      "name": "Empty"
    },
    {
      "x": -3,
      "y": 16,
      "z": 1,
      "name": "Empty"
    },
    {
      "x": -3,
      "y": 17,
      "z": 1,
      "name": "Empty"
    },
    {
      "x": -3,
      "y": 18,
      "z": 1,
      "name": "Rock_Quartzite_Brick"
    },
    {
      "x": -3,
      "y": 12,
      "z": 2,
      "name": "Rock_Stone"
    },
    {
      "x": -3,
      "y": 13,
      "z": 2,
      "name": "Rock_Stone_Cobble_Stairs",
      "rotation": 2
    },
    {
      "x": -3,
      "y": 14,
      "z": 2,
      "name": "Empty"
    },
    {
      "x": -3,
      "y": 15,
      "z": 2,
      "name": "Empty"
    },
    {
      "x": -3,
      "y": 16,
      "z": 2,
      "name": "Empty"
    },
    {
      "x": -3,
      "y": 17,
      "z": 2,
      "name": "Empty"
    },
    {
      "x": -3,
      "y": 18,
      "z": 2,
      "name": "Empty"
    },
    {
      "x": -3,
      "y": 19,
      "z": 2,
      "name": "Rock_Quartzite_Brick"
    },
    {
      "x": -3,
      "y": 0,
      "z": 3,
      "name": "Rock_Stone"
    },
    {
      "x": -3,
      "y": 1,
      "z": 3,
      "name": "Rock_Stone"
    },
    {
      "x": -3,
      "y": 2,
      "z": 3,
      "name": "Rock_Stone_Brick"
    },
    {
      "x": -3,
      "y": 3,
      "z": 3,
      "name": "Rock_Stone_Brick"
    },
    {
      "x": -3,
      "y": 4,
      "z": 3,
      "name": "Rock_Stone"
    },
    {
      "x": -3,
      "y": 5,
      "z": 3,
      "name": "Rock_Stone"
    },
    {
      "x": -3,
      "y": 6,
      "z": 3,
      "name": "Rock_Stone"
    },
    {
      "x": -3,
      "y": 7,
      "z": 3,
      "name": "Rock_Stone"
    },
    {
      "x": -3,
      "y": 13,
      "z": 3,
      "name": "Soil_Pathway"
    },
    {
      "x": -3,
      "y": 14,
      "z": 3,
      "name": "Soil_Pathway_Half"
    },
    {
      "x": -3,
      "y": 15,
      "z": 3,
      "name": "Empty"
    },
    {
      "x": -3,
      "y": 16,
      "z": 3,
      "name": "Empty"
    },
    {
      "x": -3,
      "y": 17,
      "z": 3,
      "name": "Empty"
    },
    {
      "x": -3,
      "y": 18,
      "z": 3,
      "name": "Empty"
    },
    {
      "x": -3,
      "y": 19,
      "z": 3,
      "name": "Empty"
    },
    {
      "x": -3,
      "y": 20,
      "z": 3,
      "name": "Rock_Quartzite_Brick"
    },
    {
      "x": -3,
      "y": 0,
      "z": 4,
      "name": "Rock_Stone"
    },
    {
      "x": -3,
      "y": 1,
      "z": 4,
      "name": "Rock_Stone"
    },
    {
      "x": -3,
      "y": 2,
      "z": 4,
      "name": "Rock_Stone_Brick"
    },
    {
      "x": -3,
      "y": 3,
      "z": 4,
      "name": "Rock_Stone_Brick_Half",
      "rotation": 4
    },
    {
      "x": -3,
      "y": 4,
      "z": 4,
      "name": "Rock_Stone_Cobble"
    },
    {
      "x": -3,
      "y": 5,
      "z": 4,
      "name": "Rock_Stone_Cobble"
    },
    {
      "x": -3,
      "y": 6,
      "z": 4,
      "name": "Rock_Stone"
    },
    {
      "x": -3,
      "y": 7,
      "z": 4,
      "name": "Rock_Stone"
    },
    {
      "x": -3,
      "y": 14,
      "z": 4,
      "name": "Soil_Pathway"
    },
    {
      "x": -3,
      "y": 15,
      "z": 4,
      "name": "Rock_Stone_Cobble_Stairs",
      "rotation": 2
    },
    {
      "x": -3,
      "y": 16,
      "z": 4,
      "name": "Empty"
    },
    {
      "x": -3,
      "y": 17,
      "z": 4,
      "name": "Empty"
    },
    {
      "x": -3,
      "y": 18,
      "z": 4,
      "name": "Empty"
    },
    {
      "x": -3,
      "y": 19,
      "z": 4,
      "name": "Empty"
    },
    {
      "x": -3,
      "y": 20,
      "z": 4,
      "name": "Empty"
    },
    {
      "x": -3,
      "y": 21,
      "z": 4,
      "name": "Rock_Quartzite_Brick"
    },
    {
      "x": -3,
      "y": 22,
      "z": 4,
      "name": "Rock_Quartzite_Brick"
    },
    {
      "x": -3,
      "y": 23,
      "z": 4,
      "name": "Rock_Quartzite_Brick"
    },
    {
      "x": -3,
      "y": 0,
      "z": 5,
      "name": "Rock_Stone"
    },
    {
      "x": -3,
      "y": 1,
      "z": 5,
      "name": "Rock_Stone_Cobble"
    },
    {
      "x": -3,
      "y": 2,
      "z": 5,
      "name": "Empty"
    },
    {
      "x": -3,
      "y": 3,
      "z": 5,
      "name": "Empty"
    },
    {
      "x": -3,
      "y": 4,
      "z": 5,
      "name": "Empty"
    },
    {
      "x": -3,
      "y": 5,
      "z": 5,
      "name": "Deco_SpiderWeb",
      "rotation": 10
    },
    {
      "x": -3,
      "y": 6,
      "z": 5,
      "name": "Rock_Stone_Brick"
    },
    {
      "x": -3,
      "y": 7,
      "z": 5,
      "name": "Rock_Stone"
    },
    {
      "x": -3,
      "y": 15,
      "z": 5,
      "name": "Rock_Stone"
    },
    {
      "x": -3,
      "y": 16,
      "z": 5,
      "name": "Rock_Stone_Cobble_Stairs",
      "rotation": 2
    },
    {
      "x": -3,
      "y": 17,
      "z": 5,
      "name": "Empty"
    },
    {
      "x": -3,
      "y": 18,
      "z": 5,
      "name": "Empty"
    },
    {
      "x": -3,
      "y": 19,
      "z": 5,
      "name": "Empty"
    },
    {
      "x": -3,
      "y": 20,
      "z": 5,
      "name": "Wood_Gnarled_Roots"
    },
    {
      "x": -3,
      "y": 21,
      "z": 5,
      "name": "Rock_Quartzite"
    },
    {
      "x": -3,
      "y": 22,
      "z": 5,
      "name": "Rock_Quartzite_Brick"
    },
    {
      "x": -3,
      "y": 23,
      "z": 5,
      "name": "Rock_Stone"
    },
    {
      "x": -3,
      "y": 0,
      "z": 6,
      "name": "Rock_Stone"
    },
    {
      "x": -3,
      "y": 1,
      "z": 6,
      "name": "Rock_Stone"
    },
    {
      "x": -3,
      "y": 2,
      "z": 6,
      "name": "Empty"
    },
    {
      "x": -3,
      "y": 3,
      "z": 6,
      "name": "Empty"
    },
    {
      "x": -3,
      "y": 4,
      "z": 6,
      "name": "Empty"
    },
    {
      "x": -3,
      "y": 5,
      "z": 6,
      "name": "Empty"
    },
    {
      "x": -3,
      "y": 6,
      "z": 6,
      "name": "Empty"
    },
    {
      "x": -3,
      "y": 7,
      "z": 6,
      "name": "Rock_Stone"
    },
    {
      "x": -3,
      "y": 16,
      "z": 6,
      "name": "Rock_Stone"
    },
    {
      "x": -3,
      "y": 17,
      "z": 6,
      "name": "Rock_Stone_Cobble_Half"
    },
    {
      "x": -3,
      "y": 18,
      "z": 6,
      "name": "Empty"
    },
    {
      "x": -3,
      "y": 19,
      "z": 6,
      "name": "Empty"
    },
    {
      "x": -3,
      "y": 20,
      "z": 6,
      "name": "Empty"
    },
    {
      "x": -3,
      "y": 21,
      "z": 6,
      "name": "Empty"
    },
    {
      "x": -3,
      "y": 22,
      "z": 6,
      "name": "Rock_Quartzite"
    },
    {
      "x": -3,
      "y": 23,
      "z": 6,
      "name": "Rock_Stone"
    },
    {
      "x": -3,
      "y": 0,
      "z": 7,
      "name": "Rock_Stone"
    },
    {
      "x": -3,
      "y": 1,
      "z": 7,
      "name": "Rock_Stone"
    },
    {
      "x": -3,
      "y": 3,
      "z": 7,
      "name": "Empty"
    },
    {
      "x": -3,
      "y": 4,
      "z": 7,
      "name": "Empty"
    },
    {
      "x": -3,
      "y": 5,
      "z": 7,
      "name": "Empty"
    },
    {
      "x": -3,
      "y": 6,
      "z": 7,
      "name": "Rock_Stone"
    },
    {
      "x": -3,
      "y": 7,
      "z": 7,
      "name": "Rock_Stone"
    },
    {
      "x": -3,
      "y": 16,
      "z": 7,
      "name": "Rock_Stone"
    },
    {
      "x": -3,
      "y": 17,
      "z": 7,
      "name": "Rock_Stone_Cobble"
    },
    {
      "x": -3,
      "y": 18,
      "z": 7,
      "name": "Plant_Moss_Rug_Green"
    },
    {
      "x": -3,
      "y": 19,
      "z": 7,
      "name": "Empty"
    },
    {
      "x": -3,
      "y": 20,
      "z": 7,
      "name": "Empty"
    },
    {
      "x": -3,
      "y": 21,
      "z": 7,
      "name": "Empty"
    },
    {
      "x": -3,
      "y": 22,
      "z": 7,
      "name": "Empty"
    },
    {
      "x": -3,
      "y": 23,
      "z": 7,
      "name": "Rock_Stone"
    },
    {
      "x": -3,
      "y": 0,
      "z": 8,
      "name": "Rock_Stone"
    },
    {
      "x": -3,
      "y": 1,
      "z": 8,
      "name": "Rock_Stone"
    },
    {
      "x": -3,
      "y": 2,
      "z": 8,
      "name": "Furniture_Ancient_Bench",
      "rotation": 1
    },
    {
      "x": -3,
      "y": 3,
      "z": 8,
      "name": "Empty"
    },
    {
      "x": -3,
      "y": 4,
      "z": 8,
      "name": "Empty"
    },
    {
      "x": -3,
      "y": 5,
      "z": 8,
      "name": "Rock_Stone_Stalactite_Small",
      "rotation": 8
    },
    {
      "x": -3,
      "y": 6,
      "z": 8,
      "name": "Rock_Stone"
    },
    {
      "x": -3,
      "y": 7,
      "z": 8,
      "name": "Rock_Stone"
    },
    {
      "x": -3,
      "y": 16,
      "z": 8,
      "name": "Rock_Stone"
    },
    {
      "x": -3,
      "y": 17,
      "z": 8,
      "name": "Soil_Gravel_Mossy"
    },
    {
      "x": -3,
      "y": 18,
      "z": 8,
      "name": "Empty"
    },
    {
      "x": -3,
      "y": 19,
      "z": 8,
      "name": "Empty"
    },
    {
      "x": -3,
      "y": 20,
      "z": 8,
      "name": "Empty"
    },
    {
      "x": -3,
      "y": 21,
      "z": 8,
      "name": "Empty"
    },
    {
      "x": -3,
      "y": 22,
      "z": 8,
      "name": "Empty"
    },
    {
      "x": -3,
      "y": 23,
      "z": 8,
      "name": "Rock_Stone"
    },
    {
      "x": -3,
      "y": 0,
      "z": 9,
      "name": "Rock_Stone"
    },
    {
      "x": -3,
      "y": 1,
      "z": 9,
      "name": "Rock_Stone"
    },
    {
      "x": -3,
      "y": 2,
      "z": 9,
      "name": "Furniture_Ancient_Bench",
      "filler": 32,
      "rotation": 1
    },
    {
      "x": -3,
      "y": 3,
      "z": 9,
      "name": "Empty"
    },
    {
      "x": -3,
      "y": 4,
      "z": 9,
      "name": "Empty"
    },
    {
      "x": -3,
      "y": 5,
      "z": 9,
      "name": "Empty"
    },
    {
      "x": -3,
      "y": 6,
      "z": 9,
      "name": "Rock_Stone_Brick"
    },
    {
      "x": -3,
      "y": 7,
      "z": 9,
      "name": "Rock_Stone"
    },
    {
      "x": -3,
      "y": 16,
      "z": 9,
      "name": "Rock_Stone"
    },
    {
      "x": -3,
      "y": 17,
      "z": 9,
      "name": "Soil_Gravel"
    },
    {
      "x": -3,
      "y": 18,
      "z": 9,
      "name": "Empty"
    },
    {
      "x": -3,
      "y": 19,
      "z": 9,
      "name": "Empty"
    },
    {
      "x": -3,
      "y": 20,
      "z": 9,
      "name": "Empty"
    },
    {
      "x": -3,
      "y": 21,
      "z": 9,
      "name": "Empty"
    },
    {
      "x": -3,
      "y": 22,
      "z": 9,
      "name": "Empty"
    },
    {
      "x": -3,
      "y": 23,
      "z": 9,
      "name": "Rock_Stone"
    },
    {
      "x": -2,
      "y": 6,
      "z": -9,
      "name": "Rock_Stone"
    },
    {
      "x": -2,
      "y": 7,
      "z": -9,
      "name": "Rock_Stone"
    },
    {
      "x": -2,
      "y": 8,
      "z": -9,
      "name": "Rock_Quartzite_Brick"
    },
    {
      "x": -2,
      "y": 9,
      "z": -9,
      "name": "Rock_Quartzite_Brick"
    },
    {
      "x": -2,
      "y": 10,
      "z": -9,
      "name": "Rock_Quartzite"
    },
    {
      "x": -2,
      "y": 11,
      "z": -9,
      "name": "Rock_Quartzite"
    },
    {
      "x": -2,
      "y": 12,
      "z": -9,
      "name": "Rock_Quartzite_Cobble"
    },
    {
      "x": -2,
      "y": 13,
      "z": -9,
      "name": "Rock_Quartzite_Cobble"
    },
    {
      "x": -2,
      "y": 14,
      "z": -9,
      "name": "Rock_Quartzite_Cobble"
    },
    {
      "x": -2,
      "y": 15,
      "z": -9,
      "name": "Rock_Quartzite"
    },
    {
      "x": -2,
      "y": 6,
      "z": -8,
      "name": "Rock_Stone"
    },
    {
      "x": -2,
      "y": 7,
      "z": -8,
      "name": "Rock_Stone"
    },
    {
      "x": -2,
      "y": 8,
      "z": -8,
      "name": "Empty"
    },
    {
      "x": -2,
      "y": 9,
      "z": -8,
      "name": "Empty"
    },
    {
      "x": -2,
      "y": 10,
      "z": -8,
      "name": "Empty"
    },
    {
      "x": -2,
      "y": 11,
      "z": -8,
      "name": "Empty"
    },
    {
      "x": -2,
      "y": 12,
      "z": -8,
      "name": "Empty"
    },
    {
      "x": -2,
      "y": 13,
      "z": -8,
      "name": "Rock_Quartzite"
    },
    {
      "x": -2,
      "y": 14,
      "z": -8,
      "name": "Rock_Quartzite"
    },
    {
      "x": -2,
      "y": 15,
      "z": -8,
      "name": "Rock_Quartzite"
    },
    {
      "x": -2,
      "y": 6,
      "z": -7,
      "name": "Rock_Stone"
    },
    {
      "x": -2,
      "y": 7,
      "z": -7,
      "name": "Rock_Stone"
    },
    {
      "x": -2,
      "y": 8,
      "z": -7,
      "name": "Empty"
    },
    {
      "x": -2,
      "y": 9,
      "z": -7,
      "name": "Empty"
    },
    {
      "x": -2,
      "y": 10,
      "z": -7,
      "name": "Empty"
    },
    {
      "x": -2,
      "y": 11,
      "z": -7,
      "name": "Empty"
    },
    {
      "x": -2,
      "y": 12,
      "z": -7,
      "name": "Empty"
    },
    {
      "x": -2,
      "y": 13,
      "z": -7,
      "name": "Empty"
    },
    {
      "x": -2,
      "y": 14,
      "z": -7,
      "name": "Empty"
    },
    {
      "x": -2,
      "y": 15,
      "z": -7,
      "name": "Rock_Quartzite"
    },
    {
      "x": -2,
      "y": 6,
      "z": -6,
      "name": "Rock_Stone"
    },
    {
      "x": -2,
      "y": 7,
      "z": -6,
      "name": "Soil_Gravel"
    },
    {
      "x": -2,
      "y": 8,
      "z": -6,
      "name": "Empty"
    },
    {
      "x": -2,
      "y": 9,
      "z": -6,
      "name": "Empty"
    },
    {
      "x": -2,
      "y": 10,
      "z": -6,
      "name": "Empty"
    },
    {
      "x": -2,
      "y": 11,
      "z": -6,
      "name": "Empty"
    },
    {
      "x": -2,
      "y": 12,
      "z": -6,
      "name": "Empty"
    },
    {
      "x": -2,
      "y": 13,
      "z": -6,
      "name": "Empty"
    },
    {
      "x": -2,
      "y": 14,
      "z": -6,
      "name": "Empty"
    },
    {
      "x": -2,
      "y": 15,
      "z": -6,
      "name": "Rock_Stone"
    },
    {
      "x": -2,
      "y": 6,
      "z": -5,
      "name": "Rock_Stone"
    },
    {
      "x": -2,
      "y": 7,
      "z": -5,
      "name": "Soil_Gravel"
    },
    {
      "x": -2,
      "y": 8,
      "z": -5,
      "name": "Empty"
    },
    {
      "x": -2,
      "y": 9,
      "z": -5,
      "name": "Empty"
    },
    {
      "x": -2,
      "y": 10,
      "z": -5,
      "name": "Empty"
    },
    {
      "x": -2,
      "y": 11,
      "z": -5,
      "name": "Empty"
    },
    {
      "x": -2,
      "y": 12,
      "z": -5,
      "name": "Empty"
    },
    {
      "x": -2,
      "y": 13,
      "z": -5,
      "name": "Empty"
    },
    {
      "x": -2,
      "y": 14,
      "z": -5,
      "name": "Empty"
    },
    {
      "x": -2,
      "y": 15,
      "z": -5,
      "name": "Rock_Stone"
    },
    {
      "x": -2,
      "y": 6,
      "z": -4,
      "name": "Rock_Stone"
    },
    {
      "x": -2,
      "y": 7,
      "z": -4,
      "name": "Rock_Stone_Cobble"
    },
    {
      "x": -2,
      "y": 8,
      "z": -4,
      "name": "Empty"
    },
    {
      "x": -2,
      "y": 9,
      "z": -4,
      "name": "Empty"
    },
    {
      "x": -2,
      "y": 10,
      "z": -4,
      "name": "Empty"
    },
    {
      "x": -2,
      "y": 11,
      "z": -4,
      "name": "Empty"
    },
    {
      "x": -2,
      "y": 12,
      "z": -4,
      "name": "Empty"
    },
    {
      "x": -2,
      "y": 13,
      "z": -4,
      "name": "Empty"
    },
    {
      "x": -2,
      "y": 14,
      "z": -4,
      "name": "Empty"
    },
    {
      "x": -2,
      "y": 15,
      "z": -4,
      "name": "Rock_Quartzite"
    },
    {
      "x": -2,
      "y": 6,
      "z": -3,
      "name": "Rock_Stone"
    },
    {
      "x": -2,
      "y": 7,
      "z": -3,
      "name": "Rock_Stone_Cobble"
    },
    {
      "x": -2,
      "y": 8,
      "z": -3,
      "name": "Rock_Stone_Cobble_Stairs",
      "rotation": 2
    },
    {
      "x": -2,
      "y": 9,
      "z": -3,
      "name": "Empty"
    },
    {
      "x": -2,
      "y": 10,
      "z": -3,
      "name": "Empty"
    },
    {
      "x": -2,
      "y": 11,
      "z": -3,
      "name": "Empty"
    },
    {
      "x": -2,
      "y": 12,
      "z": -3,
      "name": "Empty"
    },
    {
      "x": -2,
      "y": 13,
      "z": -3,
      "name": "Empty"
    },
    {
      "x": -2,
      "y": 14,
      "z": -3,
      "name": "Rock_Quartzite_Brick_Half",
      "rotation": 8
    },
    {
      "x": -2,
      "y": 15,
      "z": -3,
      "name": "Rock_Quartzite"
    },
    {
      "x": -2,
      "y": 8,
      "z": -2,
      "name": "Rock_Stone"
    },
    {
      "x": -2,
      "y": 9,
      "z": -2,
      "name": "Rock_Stone_Cobble_Stairs",
      "rotation": 2
    },
    {
      "x": -2,
      "y": 10,
      "z": -2,
      "name": "Empty"
    },
    {
      "x": -2,
      "y": 11,
      "z": -2,
      "name": "Empty"
    },
    {
      "x": -2,
      "y": 12,
      "z": -2,
      "name": "Empty"
    },
    {
      "x": -2,
      "y": 13,
      "z": -2,
      "name": "Empty"
    },
    {
      "x": -2,
      "y": 14,
      "z": -2,
      "name": "Empty"
    },
    {
      "x": -2,
      "y": 15,
      "z": -2,
      "name": "Rock_Quartzite_Brick"
    },
    {
      "x": -2,
      "y": 9,
      "z": -1,
      "name": "Rock_Stone"
    },
    {
      "x": -2,
      "y": 10,
      "z": -1,
      "name": "Rock_Stone_Cobble_Stairs",
      "rotation": 2
    },
    {
      "x": -2,
      "y": 11,
      "z": -1,
      "name": "Empty"
    },
    {
      "x": -2,
      "y": 12,
      "z": -1,
      "name": "Empty"
    },
    {
      "x": -2,
      "y": 13,
      "z": -1,
      "name": "Empty"
    },
    {
      "x": -2,
      "y": 14,
      "z": -1,
      "name": "Empty"
    },
    {
      "x": -2,
      "y": 15,
      "z": -1,
      "name": "Empty"
    },
    {
      "x": -2,
      "y": 16,
      "z": -1,
      "name": "Rock_Quartzite_Brick"
    },
    {
      "x": -2,
      "y": 10,
      "z": 0,
      "name": "Rock_Stone"
    },
    {
      "x": -2,
      "y": 11,
      "z": 0,
      "name": "Rock_Stone_Cobble_Stairs",
      "rotation": 2
    },
    {
      "x": -2,
      "y": 12,
      "z": 0,
      "name": "Empty"
    },
    {
      "x": -2,
      "y": 13,
      "z": 0,
      "name": "Empty"
    },
    {
      "x": -2,
      "y": 14,
      "z": 0,
      "name": "Empty"
    },
    {
      "x": -2,
      "y": 15,
      "z": 0,
      "name": "Empty"
    },
    {
      "x": -2,
      "y": 16,
      "z": 0,
      "name": "Empty"
    },
    {
      "x": -2,
      "y": 17,
      "z": 0,
      "name": "Rock_Quartzite_Brick"
    },
    {
      "x": -2,
      "y": 11,
      "z": 1,
      "name": "Rock_Stone_Cobble"
    },
    {
      "x": -2,
      "y": 12,
      "z": 1,
      "name": "Rubble_Stone"
    },
    {
      "x": -2,
      "y": 13,
      "z": 1,
      "name": "Empty"
    },
    {
      "x": -2,
      "y": 14,
      "z": 1,
      "name": "Empty"
    },
    {
      "x": -2,
      "y": 15,
      "z": 1,
      "name": "Empty"
    },
    {
      "x": -2,
      "y": 16,
      "z": 1,
      "name": "Empty"
    },
    {
      "x": -2,
      "y": 17,
      "z": 1,
      "name": "Empty"
    },
    {
      "x": -2,
      "y": 18,
      "z": 1,
      "name": "Rock_Quartzite_Brick"
    },
    {
      "x": -2,
      "y": 12,
      "z": 2,
      "name": "Rock_Stone_Brick"
    },
    {
      "x": -2,
      "y": 13,
      "z": 2,
      "name": "Rock_Stone_Cobble_Stairs",
      "rotation": 2
    },
    {
      "x": -2,
      "y": 14,
      "z": 2,
      "name": "Empty"
    },
    {
      "x": -2,
      "y": 15,
      "z": 2,
      "name": "Empty"
    },
    {
      "x": -2,
      "y": 16,
      "z": 2,
      "name": "Empty"
    },
    {
      "x": -2,
      "y": 17,
      "z": 2,
      "name": "Empty"
    },
    {
      "x": -2,
      "y": 18,
      "z": 2,
      "name": "Wood_Dry_Roots"
    },
    {
      "x": -2,
      "y": 19,
      "z": 2,
      "name": "Rock_Quartzite_Brick"
    },
    {
      "x": -2,
      "y": 0,
      "z": 3,
      "name": "Rock_Stone"
    },
    {
      "x": -2,
      "y": 1,
      "z": 3,
      "name": "Rock_Stone"
    },
    {
      "x": -2,
      "y": 2,
      "z": 3,
      "name": "Rock_Stone_Brick"
    },
    {
      "x": -2,
      "y": 3,
      "z": 3,
      "name": "Rock_Stone_Brick"
    },
    {
      "x": -2,
      "y": 4,
      "z": 3,
      "name": "Rock_Stone"
    },
    {
      "x": -2,
      "y": 5,
      "z": 3,
      "name": "Rock_Stone"
    },
    {
      "x": -2,
      "y": 6,
      "z": 3,
      "name": "Rock_Stone"
    },
    {
      "x": -2,
      "y": 7,
      "z": 3,
      "name": "Rock_Stone"
    },
    {
      "x": -2,
      "y": 13,
      "z": 3,
      "name": "Rock_Stone"
    },
    {
      "x": -2,
      "y": 14,
      "z": 3,
      "name": "Rock_Stone_Cobble_Stairs",
      "rotation": 2
    },
    {
      "x": -2,
      "y": 15,
      "z": 3,
      "name": "Empty"
    },
    {
      "x": -2,
      "y": 16,
      "z": 3,
      "name": "Empty"
    },
    {
      "x": -2,
      "y": 17,
      "z": 3,
      "name": "Empty"
    },
    {
      "x": -2,
      "y": 18,
      "z": 3,
      "name": "Empty"
    },
    {
      "x": -2,
      "y": 19,
      "z": 3,
      "name": "Rock_Quartzite"
    },
    {
      "x": -2,
      "y": 20,
      "z": 3,
      "name": "Rock_Quartzite_Brick"
    },
    {
      "x": -2,
      "y": 0,
      "z": 4,
      "name": "Rock_Stone_Cobble"
    },
    {
      "x": -2,
      "y": 1,
      "z": 4,
      "name": "Rock_Stone_Cobble"
    },
    {
      "x": -2,
      "y": 2,
      "z": 4,
      "name": "Rock_Stone_Brick_Half",
      "rotation": 4
    },
    {
      "x": -2,
      "y": 3,
      "z": 4,
      "name": "Rock_Stone_Brick_Half",
      "rotation": 4
    },
    {
      "x": -2,
      "y": 4,
      "z": 4,
      "name": "Rock_Stone_Brick"
    },
    {
      "x": -2,
      "y": 5,
      "z": 4,
      "name": "Rock_Stone_Brick"
    },
    {
      "x": -2,
      "y": 6,
      "z": 4,
      "name": "Rock_Stone_Brick"
    },
    {
      "x": -2,
      "y": 7,
      "z": 4,
      "name": "Rock_Stone_Brick"
    },
    {
      "x": -2,
      "y": 14,
      "z": 4,
      "name": "Rock_Stone"
    },
    {
      "x": -2,
      "y": 15,
      "z": 4,
      "name": "Rock_Stone_Cobble_Stairs",
      "rotation": 2
    },
    {
      "x": -2,
      "y": 16,
      "z": 4,
      "name": "Empty"
    },
    {
      "x": -2,
      "y": 17,
      "z": 4,
      "name": "Empty"
    },
    {
      "x": -2,
      "y": 18,
      "z": 4,
      "name": "Empty"
    },
    {
      "x": -2,
      "y": 19,
      "z": 4,
      "name": "Empty"
    },
    {
      "x": -2,
      "y": 20,
      "z": 4,
      "name": "Plant_Vine"
    },
    {
      "x": -2,
      "y": 21,
      "z": 4,
      "name": "Rock_Quartzite_Brick"
    },
    {
      "x": -2,
      "y": 22,
      "z": 4,
      "name": "Rock_Quartzite_Brick"
    },
    {
      "x": -2,
      "y": 23,
      "z": 4,
      "name": "Rock_Quartzite_Brick"
    },
    {
      "x": -2,
      "y": 0,
      "z": 5,
      "name": "Rock_Stone"
    },
    {
      "x": -2,
      "y": 1,
      "z": 5,
      "name": "Rock_Stone"
    },
    {
      "x": -2,
      "y": 2,
      "z": 5,
      "name": "Rubble_Stone_Medium"
    },
    {
      "x": -2,
      "y": 3,
      "z": 5,
      "name": "Empty"
    },
    {
      "x": -2,
      "y": 4,
      "z": 5,
      "name": "Empty"
    },
    {
      "x": -2,
      "y": 5,
      "z": 5,
      "name": "Empty"
    },
    {
      "x": -2,
      "y": 6,
      "z": 5,
      "name": "Rock_Stone_Brick_Half",
      "rotation": 8
    },
    {
      "x": -2,
      "y": 7,
      "z": 5,
      "name": "Rock_Stone"
    },
    {
      "x": -2,
      "y": 15,
      "z": 5,
      "name": "Rock_Stone"
    },
    {
      "x": -2,
      "y": 16,
      "z": 5,
      "name": "Rock_Stone_Cobble_Stairs",
      "rotation": 2
    },
    {
      "x": -2,
      "y": 17,
      "z": 5,
      "name": "Empty"
    },
    {
      "x": -2,
      "y": 18,
      "z": 5,
      "name": "Empty"
    },
    {
      "x": -2,
      "y": 19,
      "z": 5,
      "name": "Empty"
    },
    {
      "x": -2,
      "y": 20,
      "z": 5,
      "name": "Empty"
    },
    {
      "x": -2,
      "y": 21,
      "z": 5,
      "name": "Rock_Quartzite"
    },
    {
      "x": -2,
      "y": 22,
      "z": 5,
      "name": "Rock_Quartzite_Brick"
    },
    {
      "x": -2,
      "y": 23,
      "z": 5,
      "name": "Rock_Stone"
    },
    {
      "x": -2,
      "y": 0,
      "z": 6,
      "name": "Rock_Stone"
    },
    {
      "x": -2,
      "y": 1,
      "z": 6,
      "name": "Soil_Gravel"
    },
    {
      "x": -2,
      "y": 2,
      "z": 6,
      "name": "Empty"
    },
    {
      "x": -2,
      "y": 3,
      "z": 6,
      "name": "Empty"
    },
    {
      "x": -2,
      "y": 4,
      "z": 6,
      "name": "Empty"
    },
    {
      "x": -2,
      "y": 5,
      "z": 6,
      "name": "Empty"
    },
    {
      "x": -2,
      "y": 6,
      "z": 6,
      "name": "Empty"
    },
    {
      "x": -2,
      "y": 7,
      "z": 6,
      "name": "Rock_Stone"
    },
    {
      "x": -2,
      "y": 16,
      "z": 6,
      "name": "Rock_Stone"
    },
    {
      "x": -2,
      "y": 17,
      "z": 6,
      "name": "Rock_Stone_Cobble_Stairs",
      "rotation": 2
    },
    {
      "x": -2,
      "y": 18,
      "z": 6,
      "name": "Empty"
    },
    {
      "x": -2,
      "y": 19,
      "z": 6,
      "name": "Empty"
    },
    {
      "x": -2,
      "y": 20,
      "z": 6,
      "name": "Empty"
    },
    {
      "x": -2,
      "y": 21,
      "z": 6,
      "name": "Empty"
    },
    {
      "x": -2,
      "y": 22,
      "z": 6,
      "name": "Empty"
    },
    {
      "x": -2,
      "y": 23,
      "z": 6,
      "name": "Rock_Stone"
    },
    {
      "x": -2,
      "y": 0,
      "z": 7,
      "name": "Rock_Stone"
    },
    {
      "x": -2,
      "y": 1,
      "z": 7,
      "name": "Soil_Gravel"
    },
    {
      "x": -2,
      "y": 2,
      "z": 7,
      "name": "Empty"
    },
    {
      "x": -2,
      "y": 3,
      "z": 7,
      "name": "Empty"
    },
    {
      "x": -2,
      "y": 4,
      "z": 7,
      "name": "Empty"
    },
    {
      "x": -2,
      "y": 5,
      "z": 7,
      "name": "Empty"
    },
    {
      "x": -2,
      "y": 6,
      "z": 7,
      "name": "Empty"
    },
    {
      "x": -2,
      "y": 7,
      "z": 7,
      "name": "Rock_Stone"
    },
    {
      "x": -2,
      "y": 16,
      "z": 7,
      "name": "Rock_Stone"
    },
    {
      "x": -2,
      "y": 17,
      "z": 7,
      "name": "Soil_Gravel_Mossy"
    },
    {
      "x": -2,
      "y": 18,
      "z": 7,
      "name": "Empty"
    },
    {
      "x": -2,
      "y": 19,
      "z": 7,
      "name": "Empty"
    },
    {
      "x": -2,
      "y": 20,
      "z": 7,
      "name": "Empty"
    },
    {
      "x": -2,
      "y": 21,
      "z": 7,
      "name": "Empty"
    },
    {
      "x": -2,
      "y": 22,
      "z": 7,
      "name": "Empty"
    },
    {
      "x": -2,
      "y": 23,
      "z": 7,
      "name": "Rock_Stone"
    },
    {
      "x": -2,
      "y": 0,
      "z": 8,
      "name": "Rock_Stone"
    },
    {
      "x": -2,
      "y": 1,
      "z": 8,
      "name": "Rock_Stone"
    },
    {
      "x": -2,
      "y": 2,
      "z": 8,
      "name": "Empty"
    },
    {
      "x": -2,
      "y": 3,
      "z": 8,
      "name": "Empty"
    },
    {
      "x": -2,
      "y": 4,
      "z": 8,
      "name": "Empty"
    },
    {
      "x": -2,
      "y": 5,
      "z": 8,
      "name": "Empty"
    },
    {
      "x": -2,
      "y": 6,
      "z": 8,
      "name": "Rock_Stone"
    },
    {
      "x": -2,
      "y": 7,
      "z": 8,
      "name": "Rock_Stone"
    },
    {
      "x": -2,
      "y": 16,
      "z": 8,
      "name": "Rock_Stone"
    },
    {
      "x": -2,
      "y": 17,
      "z": 8,
      "name": "Soil_Pathway"
    },
    {
      "x": -2,
      "y": 18,
      "z": 8,
      "name": "Empty"
    },
    {
      "x": -2,
      "y": 19,
      "z": 8,
      "name": "Empty"
    },
    {
      "x": -2,
      "y": 20,
      "z": 8,
      "name": "Empty"
    },
    {
      "x": -2,
      "y": 21,
      "z": 8,
      "name": "Empty"
    },
    {
      "x": -2,
      "y": 22,
      "z": 8,
      "name": "Empty"
    },
    {
      "x": -2,
      "y": 23,
      "z": 8,
      "name": "Rock_Stone"
    },
    {
      "x": -2,
      "y": 0,
      "z": 9,
      "name": "Rock_Stone"
    },
    {
      "x": -2,
      "y": 1,
      "z": 9,
      "name": "Rock_Stone"
    },
    {
      "x": -2,
      "y": 2,
      "z": 9,
      "name": "Empty"
    },
    {
      "x": -2,
      "y": 3,
      "z": 9,
      "name": "Empty"
    },
    {
      "x": -2,
      "y": 4,
      "z": 9,
      "name": "Empty"
    },
    {
      "x": -2,
      "y": 5,
      "z": 9,
      "name": "Empty"
    },
    {
      "x": -2,
      "y": 6,
      "z": 9,
      "name": "Rock_Stone_Brick_Half",
      "rotation": 8
    },
    {
      "x": -2,
      "y": 7,
      "z": 9,
      "name": "Rock_Stone"
    },
    {
      "x": -2,
      "y": 16,
      "z": 9,
      "name": "Rock_Stone"
    },
    {
      "x": -2,
      "y": 17,
      "z": 9,
      "name": "Soil_Pathway"
    },
    {
      "x": -2,
      "y": 18,
      "z": 9,
      "name": "Plant_Grass_Rocky_Short"
    },
    {
      "x": -2,
      "y": 19,
      "z": 9,
      "name": "Empty"
    },
    {
      "x": -2,
      "y": 20,
      "z": 9,
      "name": "Empty"
    },
    {
      "x": -2,
      "y": 21,
      "z": 9,
      "name": "Empty"
    },
    {
      "x": -2,
      "y": 22,
      "z": 9,
      "name": "Empty"
    },
    {
      "x": -2,
      "y": 23,
      "z": 9,
      "name": "Rock_Stone"
    },
    {
      "x": -1,
      "y": 6,
      "z": -9,
      "name": "Rock_Stone"
    },
    {
      "x": -1,
      "y": 7,
      "z": -9,
      "name": "Rock_Stone"
    },
    {
      "x": -1,
      "y": 8,
      "z": -9,
      "name": "Rock_Quartzite_Brick"
    },
    {
      "x": -1,
      "y": 9,
      "z": -9,
      "name": "Rock_Quartzite_Brick"
    },
    {
      "x": -1,
      "y": 10,
      "z": -9,
      "name": "Rock_Quartzite"
    },
    {
      "x": -1,
      "y": 11,
      "z": -9,
      "name": "Rock_Quartzite"
    },
    {
      "x": -1,
      "y": 12,
      "z": -9,
      "name": "Rock_Quartzite"
    },
    {
      "x": -1,
      "y": 13,
      "z": -9,
      "name": "Rock_Quartzite_Cobble"
    },
    {
      "x": -1,
      "y": 14,
      "z": -9,
      "name": "Rock_Quartzite_Cobble"
    },
    {
      "x": -1,
      "y": 15,
      "z": -9,
      "name": "Rock_Quartzite"
    },
    {
      "x": -1,
      "y": 6,
      "z": -8,
      "name": "Rock_Stone"
    },
    {
      "x": -1,
      "y": 7,
      "z": -8,
      "name": "Rock_Stone"
    },
    {
      "x": -1,
      "y": 8,
      "z": -8,
      "name": "Empty"
    },
    {
      "x": -1,
      "y": 9,
      "z": -8,
      "name": "Empty"
    },
    {
      "x": -1,
      "y": 10,
      "z": -8,
      "name": "Empty"
    },
    {
      "x": -1,
      "y": 11,
      "z": -8,
      "name": "Empty"
    },
    {
      "x": -1,
      "y": 12,
      "z": -8,
      "name": "Empty"
    },
    {
      "x": -1,
      "y": 13,
      "z": -8,
      "name": "Empty"
    },
    {
      "x": -1,
      "y": 14,
      "z": -8,
      "name": "Rock_Quartzite"
    },
    {
      "x": -1,
      "y": 15,
      "z": -8,
      "name": "Rock_Quartzite"
    },
    {
      "x": -1,
      "y": 6,
      "z": -7,
      "name": "Rock_Stone"
    },
    {
      "x": -1,
      "y": 7,
      "z": -7,
      "name": "Rock_Stone"
    },
    {
      "x": -1,
      "y": 8,
      "z": -7,
      "name": "Empty"
    },
    {
      "x": -1,
      "y": 9,
      "z": -7,
      "name": "Empty"
    },
    {
      "x": -1,
      "y": 10,
      "z": -7,
      "name": "Empty"
    },
    {
      "x": -1,
      "y": 11,
      "z": -7,
      "name": "Empty"
    },
    {
      "x": -1,
      "y": 12,
      "z": -7,
      "name": "Empty"
    },
    {
      "x": -1,
      "y": 13,
      "z": -7,
      "name": "Empty"
    },
    {
      "x": -1,
      "y": 14,
      "z": -7,
      "name": "Empty"
    },
    {
      "x": -1,
      "y": 15,
      "z": -7,
      "name": "Rock_Quartzite"
    },
    {
      "x": -1,
      "y": 6,
      "z": -6,
      "name": "Rock_Stone"
    },
    {
      "x": -1,
      "y": 7,
      "z": -6,
      "name": "Soil_Gravel"
    },
    {
      "x": -1,
      "y": 8,
      "z": -6,
      "name": "Empty"
    },
    {
      "x": -1,
      "y": 9,
      "z": -6,
      "name": "Empty"
    },
    {
      "x": -1,
      "y": 10,
      "z": -6,
      "name": "Empty"
    },
    {
      "x": -1,
      "y": 11,
      "z": -6,
      "name": "Empty"
    },
    {
      "x": -1,
      "y": 12,
      "z": -6,
      "name": "Empty"
    },
    {
      "x": -1,
      "y": 13,
      "z": -6,
      "name": "Empty"
    },
    {
      "x": -1,
      "y": 14,
      "z": -6,
      "name": "Empty"
    },
    {
      "x": -1,
      "y": 15,
      "z": -6,
      "name": "Rock_Quartzite"
    },
    {
      "x": -1,
      "y": 6,
      "z": -5,
      "name": "Rock_Stone"
    },
    {
      "x": -1,
      "y": 7,
      "z": -5,
      "name": "Rock_Stone_Cobble"
    },
    {
      "x": -1,
      "y": 8,
      "z": -5,
      "name": "Empty"
    },
    {
      "x": -1,
      "y": 9,
      "z": -5,
      "name": "Empty"
    },
    {
      "x": -1,
      "y": 10,
      "z": -5,
      "name": "Empty"
    },
    {
      "x": -1,
      "y": 11,
      "z": -5,
      "name": "Empty"
    },
    {
      "x": -1,
      "y": 12,
      "z": -5,
      "name": "Empty"
    },
    {
      "x": -1,
      "y": 13,
      "z": -5,
      "name": "Empty"
    },
    {
      "x": -1,
      "y": 14,
      "z": -5,
      "name": "Empty"
    },
    {
      "x": -1,
      "y": 15,
      "z": -5,
      "name": "Rock_Quartzite_Cobble"
    },
    {
      "x": -1,
      "y": 6,
      "z": -4,
      "name": "Rock_Stone"
    },
    {
      "x": -1,
      "y": 7,
      "z": -4,
      "name": "Rock_Stone_Cobble"
    },
    {
      "x": -1,
      "y": 8,
      "z": -4,
      "name": "Deco_Bone_Skulls"
    },
    {
      "x": -1,
      "y": 9,
      "z": -4,
      "name": "Empty"
    },
    {
      "x": -1,
      "y": 10,
      "z": -4,
      "name": "Empty"
    },
    {
      "x": -1,
      "y": 11,
      "z": -4,
      "name": "Empty"
    },
    {
      "x": -1,
      "y": 12,
      "z": -4,
      "name": "Empty"
    },
    {
      "x": -1,
      "y": 13,
      "z": -4,
      "name": "Empty"
    },
    {
      "x": -1,
      "y": 14,
      "z": -4,
      "name": "Empty"
    },
    {
      "x": -1,
      "y": 15,
      "z": -4,
      "name": "Rock_Quartzite_Cobble"
    },
    {
      "x": -1,
      "y": 6,
      "z": -3,
      "name": "Rock_Stone"
    },
    {
      "x": -1,
      "y": 7,
      "z": -3,
      "name": "Rock_Stone"
    },
    {
      "x": -1,
      "y": 8,
      "z": -3,
      "name": "Rock_Quartzite_Brick"
    },
    {
      "x": -1,
      "y": 9,
      "z": -3,
      "name": "Rock_Quartzite_Brick_Half",
      "rotation": 7
    },
    {
      "x": -1,
      "y": 10,
      "z": -3,
      "name": "Rock_Quartzite_Brick_Half",
      "rotation": 7
    },
    {
      "x": -1,
      "y": 11,
      "z": -3,
      "name": "Rock_Quartzite_Brick_Half",
      "rotation": 7
    },
    {
      "x": -1,
      "y": 12,
      "z": -3,
      "name": "Rock_Quartzite_Brick_Half",
      "rotation": 7
    },
    {
      "x": -1,
      "y": 13,
      "z": -3,
      "name": "Rock_Quartzite_Brick_Half",
      "rotation": 7
    },
    {
      "x": -1,
      "y": 14,
      "z": -3,
      "name": "Rock_Quartzite_Brick"
    },
    {
      "x": -1,
      "y": 15,
      "z": -3,
      "name": "Rock_Quartzite"
    },
    {
      "x": -1,
      "y": 8,
      "z": -2,
      "name": "Rock_Stone"
    },
    {
      "x": -1,
      "y": 9,
      "z": -2,
      "name": "Rock_Stone_Cobble_Stairs",
      "rotation": 2
    },
    {
      "x": -1,
      "y": 10,
      "z": -2,
      "name": "Empty"
    },
    {
      "x": -1,
      "y": 11,
      "z": -2,
      "name": "Empty"
    },
    {
      "x": -1,
      "y": 12,
      "z": -2,
      "name": "Empty"
    },
    {
      "x": -1,
      "y": 13,
      "z": -2,
      "name": "Empty"
    },
    {
      "x": -1,
      "y": 14,
      "z": -2,
      "name": "Empty"
    },
    {
      "x": -1,
      "y": 15,
      "z": -2,
      "name": "Rock_Quartzite_Brick"
    },
    {
      "x": -1,
      "y": 9,
      "z": -1,
      "name": "Rock_Stone"
    },
    {
      "x": -1,
      "y": 10,
      "z": -1,
      "name": "Rock_Stone_Cobble_Stairs",
      "rotation": 2
    },
    {
      "x": -1,
      "y": 11,
      "z": -1,
      "name": "Empty"
    },
    {
      "x": -1,
      "y": 12,
      "z": -1,
      "name": "Empty"
    },
    {
      "x": -1,
      "y": 13,
      "z": -1,
      "name": "Empty"
    },
    {
      "x": -1,
      "y": 14,
      "z": -1,
      "name": "Empty"
    },
    {
      "x": -1,
      "y": 15,
      "z": -1,
      "name": "Empty"
    },
    {
      "x": -1,
      "y": 16,
      "z": -1,
      "name": "Rock_Quartzite_Brick"
    },
    {
      "x": -1,
      "y": 10,
      "z": 0,
      "name": "Rock_Stone"
    },
    {
      "x": -1,
      "y": 11,
      "z": 0,
      "name": "Rock_Stone_Cobble_Stairs",
      "rotation": 2
    },
    {
      "x": -1,
      "y": 12,
      "z": 0,
      "name": "Empty"
    },
    {
      "x": -1,
      "y": 13,
      "z": 0,
      "name": "Empty"
    },
    {
      "x": -1,
      "y": 14,
      "z": 0,
      "name": "Empty"
    },
    {
      "x": -1,
      "y": 15,
      "z": 0,
      "name": "Empty"
    },
    {
      "x": -1,
      "y": 16,
      "z": 0,
      "name": "Empty"
    },
    {
      "x": -1,
      "y": 17,
      "z": 0,
      "name": "Rock_Quartzite_Brick"
    },
    {
      "x": -1,
      "y": 11,
      "z": 1,
      "name": "Rock_Stone_Cobble"
    },
    {
      "x": -1,
      "y": 12,
      "z": 1,
      "name": "Rock_Stone_Cobble_Half",
      "rotation": 6
    },
    {
      "x": -1,
      "y": 13,
      "z": 1,
      "name": "Empty"
    },
    {
      "x": -1,
      "y": 14,
      "z": 1,
      "name": "Empty"
    },
    {
      "x": -1,
      "y": 15,
      "z": 1,
      "name": "Empty"
    },
    {
      "x": -1,
      "y": 16,
      "z": 1,
      "name": "Empty"
    },
    {
      "x": -1,
      "y": 17,
      "z": 1,
      "name": "Empty"
    },
    {
      "x": -1,
      "y": 18,
      "z": 1,
      "name": "Rock_Quartzite_Brick"
    },
    {
      "x": -1,
      "y": 12,
      "z": 2,
      "name": "Rock_Stone_Brick"
    },
    {
      "x": -1,
      "y": 13,
      "z": 2,
      "name": "Rock_Stone_Cobble_Stairs",
      "rotation": 2
    },
    {
      "x": -1,
      "y": 14,
      "z": 2,
      "name": "Empty"
    },
    {
      "x": -1,
      "y": 15,
      "z": 2,
      "name": "Empty"
    },
    {
      "x": -1,
      "y": 16,
      "z": 2,
      "name": "Empty"
    },
    {
      "x": -1,
      "y": 17,
      "z": 2,
      "name": "Empty"
    },
    {
      "x": -1,
      "y": 18,
      "z": 2,
      "name": "Rock_Quartzite"
    },
    {
      "x": -1,
      "y": 19,
      "z": 2,
      "name": "Rock_Quartzite_Brick"
    },
    {
      "x": -1,
      "y": 0,
      "z": 3,
      "name": "Rock_Stone"
    },
    {
      "x": -1,
      "y": 1,
      "z": 3,
      "name": "Rock_Stone"
    },
    {
      "x": -1,
      "y": 2,
      "z": 3,
      "name": "Rock_Stone_Brick"
    },
    {
      "x": -1,
      "y": 3,
      "z": 3,
      "name": "Rock_Stone_Brick"
    },
    {
      "x": -1,
      "y": 4,
      "z": 3,
      "name": "Rock_Stone"
    },
    {
      "x": -1,
      "y": 5,
      "z": 3,
      "name": "Rock_Stone"
    },
    {
      "x": -1,
      "y": 6,
      "z": 3,
      "name": "Rock_Stone"
    },
    {
      "x": -1,
      "y": 7,
      "z": 3,
      "name": "Rock_Stone"
    },
    {
      "x": -1,
      "y": 13,
      "z": 3,
      "name": "Rock_Stone"
    },
    {
      "x": -1,
      "y": 14,
      "z": 3,
      "name": "Rock_Stone_Cobble_Stairs",
      "rotation": 2
    },
    {
      "x": -1,
      "y": 15,
      "z": 3,
      "name": "Empty"
    },
    {
      "x": -1,
      "y": 16,
      "z": 3,
      "name": "Empty"
    },
    {
      "x": -1,
      "y": 17,
      "z": 3,
      "name": "Empty"
    },
    {
      "x": -1,
      "y": 18,
      "z": 3,
      "name": "Empty"
    },
    {
      "x": -1,
      "y": 19,
      "z": 3,
      "name": "Rock_Quartzite"
    },
    {
      "x": -1,
      "y": 20,
      "z": 3,
      "name": "Rock_Quartzite_Brick"
    },
    {
      "x": -1,
      "y": 0,
      "z": 4,
      "name": "Rock_Stone"
    },
    {
      "x": -1,
      "y": 1,
      "z": 4,
      "name": "Rock_Stone"
    },
    {
      "x": -1,
      "y": 2,
      "z": 4,
      "name": "Rock_Stone_Brick_Decorative"
    },
    {
      "x": -1,
      "y": 3,
      "z": 4,
      "name": "Rock_Stone_Brick"
    },
    {
      "x": -1,
      "y": 4,
      "z": 4,
      "name": "Rock_Stone_Brick"
    },
    {
      "x": -1,
      "y": 5,
      "z": 4,
      "name": "Rock_Stone_Brick"
    },
    {
      "x": -1,
      "y": 6,
      "z": 4,
      "name": "Rock_Stone_Brick"
    },
    {
      "x": -1,
      "y": 7,
      "z": 4,
      "name": "Rock_Stone_Brick"
    },
    {
      "x": -1,
      "y": 14,
      "z": 4,
      "name": "Rock_Stone"
    },
    {
      "x": -1,
      "y": 15,
      "z": 4,
      "name": "Rock_Stone_Cobble_Stairs",
      "rotation": 2
    },
    {
      "x": -1,
      "y": 16,
      "z": 4,
      "name": "Empty"
    },
    {
      "x": -1,
      "y": 17,
      "z": 4,
      "name": "Empty"
    },
    {
      "x": -1,
      "y": 18,
      "z": 4,
      "name": "Empty"
    },
    {
      "x": -1,
      "y": 19,
      "z": 4,
      "name": "Plant_Vine_Wall"
    },
    {
      "x": -1,
      "y": 20,
      "z": 4,
      "name": "Plant_Vine"
    },
    {
      "x": -1,
      "y": 21,
      "z": 4,
      "name": "Rock_Quartzite_Brick"
    },
    {
      "x": -1,
      "y": 22,
      "z": 4,
      "name": "Rock_Quartzite_Brick"
    },
    {
      "x": -1,
      "y": 23,
      "z": 4,
      "name": "Rock_Quartzite_Brick"
    },
    {
      "x": -1,
      "y": 0,
      "z": 5,
      "name": "Rock_Stone"
    },
    {
      "x": -1,
      "y": 1,
      "z": 5,
      "name": "Soil_Gravel"
    },
    {
      "x": -1,
      "y": 2,
      "z": 5,
      "name": "Deco_Bone_Pile"
    },
    {
      "x": -1,
      "y": 3,
      "z": 5,
      "name": "Empty"
    },
    {
      "x": -1,
      "y": 4,
      "z": 5,
      "name": "Empty"
    },
    {
      "x": -1,
      "y": 5,
      "z": 5,
      "name": "Empty"
    },
    {
      "x": -1,
      "y": 6,
      "z": 5,
      "name": "Rock_Stone_Brick_Half",
      "rotation": 8
    },
    {
      "x": -1,
      "y": 7,
      "z": 5,
      "name": "Rock_Stone"
    },
    {
      "x": -1,
      "y": 15,
      "z": 5,
      "name": "Rock_Stone"
    },
    {
      "x": -1,
      "y": 16,
      "z": 5,
      "name": "Rock_Stone_Cobble_Stairs",
      "rotation": 2
    },
    {
      "x": -1,
      "y": 17,
      "z": 5,
      "name": "Empty"
    },
    {
      "x": -1,
      "y": 18,
      "z": 5,
      "name": "Empty"
    },
    {
      "x": -1,
      "y": 19,
      "z": 5,
      "name": "Empty"
    },
    {
      "x": -1,
      "y": 20,
      "z": 5,
      "name": "Rock_Stone_Stalactite_Large",
      "filler": 31744,
      "rotation": 8
    },
    {
      "x": -1,
      "y": 21,
      "z": 5,
      "name": "Rock_Stone_Stalactite_Large",
      "rotation": 8
    },
    {
      "x": -1,
      "y": 22,
      "z": 5,
      "name": "Rock_Quartzite_Cobble"
    },
    {
      "x": -1,
      "y": 23,
      "z": 5,
      "name": "Rock_Stone"
    },
    {
      "x": -1,
      "y": 0,
      "z": 6,
      "name": "Rock_Stone"
    },
    {
      "x": -1,
      "y": 1,
      "z": 6,
      "name": "Soil_Gravel"
    },
    {
      "x": -1,
      "y": 2,
      "z": 6,
      "name": "Deco_Campfire_Off"
    },
    {
      "x": -1,
      "y": 3,
      "z": 6,
      "name": "Empty"
    },
    {
      "x": -1,
      "y": 4,
      "z": 6,
      "name": "Empty"
    },
    {
      "x": -1,
      "y": 5,
      "z": 6,
      "name": "Empty"
    },
    {
      "x": -1,
      "y": 6,
      "z": 6,
      "name": "Empty"
    },
    {
      "x": -1,
      "y": 7,
      "z": 6,
      "name": "Rock_Stone"
    },
    {
      "x": -1,
      "y": 16,
      "z": 6,
      "name": "Rock_Stone"
    },
    {
      "x": -1,
      "y": 17,
      "z": 6,
      "name": "Rock_Stone_Brick_Half"
    },
    {
      "x": -1,
      "y": 18,
      "z": 6,
      "name": "Empty"
    },
    {
      "x": -1,
      "y": 19,
      "z": 6,
      "name": "Empty"
    },
    {
      "x": -1,
      "y": 20,
      "z": 6,
      "name": "Empty"
    },
    {
      "x": -1,
      "y": 21,
      "z": 6,
      "name": "Empty"
    },
    {
      "x": -1,
      "y": 22,
      "z": 6,
      "name": "Rock_Stone"
    },
    {
      "x": -1,
      "y": 23,
      "z": 6,
      "name": "Rock_Stone"
    },
    {
      "x": -1,
      "y": 0,
      "z": 7,
      "name": "Rock_Stone"
    },
    {
      "x": -1,
      "y": 1,
      "z": 7,
      "name": "Soil_Gravel"
    },
    {
      "x": -1,
      "y": 2,
      "z": 7,
      "name": "Empty"
    },
    {
      "x": -1,
      "y": 3,
      "z": 7,
      "name": "Empty"
    },
    {
      "x": -1,
      "y": 4,
      "z": 7,
      "name": "Empty"
    },
    {
      "x": -1,
      "y": 5,
      "z": 7,
      "name": "Empty"
    },
    {
      "x": -1,
      "y": 6,
      "z": 7,
      "name": "Empty"
    },
    {
      "x": -1,
      "y": 7,
      "z": 7,
      "name": "Rock_Stone"
    },
    {
      "x": -1,
      "y": 16,
      "z": 7,
      "name": "Rock_Stone"
    },
    {
      "x": -1,
      "y": 17,
      "z": 7,
      "name": "Soil_Pathway"
    },
    {
      "x": -1,
      "y": 18,
      "z": 7,
      "name": "Empty"
    },
    {
      "x": -1,
      "y": 19,
      "z": 7,
      "name": "Empty"
    },
    {
      "x": -1,
      "y": 20,
      "z": 7,
      "name": "Empty"
    },
    {
      "x": -1,
      "y": 21,
      "z": 7,
      "name": "Empty"
    },
    {
      "x": -1,
      "y": 22,
      "z": 7,
      "name": "Empty"
    },
    {
      "x": -1,
      "y": 23,
      "z": 7,
      "name": "Rock_Stone"
    },
    {
      "x": -1,
      "y": 0,
      "z": 8,
      "name": "Rock_Stone"
    },
    {
      "x": -1,
      "y": 1,
      "z": 8,
      "name": "Soil_Gravel"
    },
    {
      "x": -1,
      "y": 2,
      "z": 8,
      "name": "Empty"
    },
    {
      "x": -1,
      "y": 3,
      "z": 8,
      "name": "Empty"
    },
    {
      "x": -1,
      "y": 4,
      "z": 8,
      "name": "Empty"
    },
    {
      "x": -1,
      "y": 5,
      "z": 8,
      "name": "Empty"
    },
    {
      "x": -1,
      "y": 6,
      "z": 8,
      "name": "Rock_Stone"
    },
    {
      "x": -1,
      "y": 7,
      "z": 8,
      "name": "Rock_Stone"
    },
    {
      "x": -1,
      "y": 16,
      "z": 8,
      "name": "Rock_Stone"
    },
    {
      "x": -1,
      "y": 17,
      "z": 8,
      "name": "Soil_Pathway"
    },
    {
      "x": -1,
      "y": 18,
      "z": 8,
      "name": "Empty"
    },
    {
      "x": -1,
      "y": 19,
      "z": 8,
      "name": "Empty"
    },
    {
      "x": -1,
      "y": 20,
      "z": 8,
      "name": "Empty"
    },
    {
      "x": -1,
      "y": 21,
      "z": 8,
      "name": "Empty"
    },
    {
      "x": -1,
      "y": 22,
      "z": 8,
      "name": "Empty"
    },
    {
      "x": -1,
      "y": 23,
      "z": 8,
      "name": "Rock_Stone"
    },
    {
      "x": -1,
      "y": 0,
      "z": 9,
      "name": "Rock_Stone"
    },
    {
      "x": -1,
      "y": 1,
      "z": 9,
      "name": "Rock_Stone"
    },
    {
      "x": -1,
      "y": 2,
      "z": 9,
      "name": "Empty"
    },
    {
      "x": -1,
      "y": 3,
      "z": 9,
      "name": "Empty"
    },
    {
      "x": -1,
      "y": 4,
      "z": 9,
      "name": "Empty"
    },
    {
      "x": -1,
      "y": 5,
      "z": 9,
      "name": "Empty"
    },
    {
      "x": -1,
      "y": 6,
      "z": 9,
      "name": "Rock_Stone_Brick_Half",
      "rotation": 8
    },
    {
      "x": -1,
      "y": 7,
      "z": 9,
      "name": "Rock_Stone"
    },
    {
      "x": -1,
      "y": 16,
      "z": 9,
      "name": "Rock_Stone"
    },
    {
      "x": -1,
      "y": 17,
      "z": 9,
      "name": "Soil_Pathway"
    },
    {
      "x": -1,
      "y": 18,
      "z": 9,
      "name": "Empty"
    },
    {
      "x": -1,
      "y": 19,
      "z": 9,
      "name": "Empty"
    },
    {
      "x": -1,
      "y": 20,
      "z": 9,
      "name": "Empty"
    },
    {
      "x": -1,
      "y": 21,
      "z": 9,
      "name": "Empty"
    },
    {
      "x": -1,
      "y": 22,
      "z": 9,
      "name": "Empty"
    },
    {
      "x": -1,
      "y": 23,
      "z": 9,
      "name": "Rock_Stone"
    },
    {
      "x": 0,
      "y": 6,
      "z": -9,
      "name": "Rock_Stone"
    },
    {
      "x": 0,
      "y": 7,
      "z": -9,
      "name": "Rock_Stone"
    },
    {
      "x": 0,
      "y": 8,
      "z": -9,
      "name": "Rock_Quartzite_Brick"
    },
    {
      "x": 0,
      "y": 9,
      "z": -9,
      "name": "Rock_Quartzite_Brick"
    },
    {
      "x": 0,
      "y": 10,
      "z": -9,
      "name": "Rock_Quartzite"
    },
    {
      "x": 0,
      "y": 11,
      "z": -9,
      "name": "Rock_Quartzite"
    },
    {
      "x": 0,
      "y": 12,
      "z": -9,
      "name": "Rock_Quartzite"
    },
    {
      "x": 0,
      "y": 13,
      "z": -9,
      "name": "Rock_Quartzite"
    },
    {
      "x": 0,
      "y": 14,
      "z": -9,
      "name": "Rock_Quartzite"
    },
    {
      "x": 0,
      "y": 15,
      "z": -9,
      "name": "Rock_Quartzite"
    },
    {
      "x": 0,
      "y": 6,
      "z": -8,
      "name": "Rock_Stone"
    },
    {
      "x": 0,
      "y": 7,
      "z": -8,
      "name": "Rock_Stone"
    },
    {
      "x": 0,
      "y": 8,
      "z": -8,
      "name": "Empty"
    },
    {
      "x": 0,
      "y": 9,
      "z": -8,
      "name": "Empty"
    },
    {
      "x": 0,
      "y": 10,
      "z": -8,
      "name": "Empty"
    },
    {
      "x": 0,
      "y": 11,
      "z": -8,
      "name": "Empty"
    },
    {
      "x": 0,
      "y": 12,
      "z": -8,
      "name": "Empty"
    },
    {
      "x": 0,
      "y": 13,
      "z": -8,
      "name": "Empty"
    },
    {
      "x": 0,
      "y": 14,
      "z": -8,
      "name": "Rock_Stone_Brick_Half",
      "rotation": 8
    },
    {
      "x": 0,
      "y": 15,
      "z": -8,
      "name": "Rock_Quartzite_Cobble"
    },
    {
      "x": 0,
      "y": 6,
      "z": -7,
      "name": "Rock_Stone"
    },
    {
      "x": 0,
      "y": 7,
      "z": -7,
      "name": "Rock_Stone"
    },
    {
      "x": 0,
      "y": 8,
      "z": -7,
      "name": "Empty"
    },
    {
      "x": 0,
      "y": 9,
      "z": -7,
      "name": "Empty"
    },
    {
      "x": 0,
      "y": 10,
      "z": -7,
      "name": "Empty"
    },
    {
      "x": 0,
      "y": 11,
      "z": -7,
      "name": "Empty"
    },
    {
      "x": 0,
      "y": 12,
      "z": -7,
      "name": "Empty"
    },
    {
      "x": 0,
      "y": 13,
      "z": -7,
      "name": "Empty"
    },
    {
      "x": 0,
      "y": 14,
      "z": -7,
      "name": "Empty"
    },
    {
