{
  "version": 8,
  "blockIdVersion": 8,
  "anchorX": 6,
  "anchorY": 6,
  "anchorZ": 5,
  "blocks": [
    {
      "x": 2,
      "y": 6,
      "z": 3,
      "name": "Rock_Ice"
    },
    {
      "x": 2,
      "y": 7,
      "z": 3,
      "name": "Rock_Ice"
    },
    {
      "x": 2,
      "y": 8,
      "z": 3,
      "name": "Soil_Snow"
    },
    {
      "x": 2,
      "y": 6,
      "z": 4,
      "name": "Rock_Ice"
    },
    {
      "x": 2,
      "y": 6,
      "z": 5,
      "name": "Rock_Ice"
    },
    {
      "x": 2,
      "y": 7,
      "z": 5,
      "name": "Soil_Snow"
    },
    {
      "x": 2,
      "y": 6,
      "z": 6,
      "name": "Rock_Ice"
    },
    {
      "x": 2,
      "y": 7,
      "z": 6,
      "name": "Soil_Snow"
    },
    {
      "x": 3,
      "y": 6,
      "z": 2,
      "name": "Rock_Ice"
    },
    {
      "x": 3,
      "y": 7,
      "z": 2,
      "name": "Rock_Ice"
    },
    {
      "x": 3,
      "y": 8,
      "z": 2,
      "name": "Soil_Snow"
    },
    {
      "x": 3,
      "y": 6,
      "z": 3,
      "name": "Rock_Ice"
    },
    {
      "x": 3,
      "y": 7,
      "z": 3,
      "name": "Rock_Ice"
    },
    {
      "x": 3,
      "y": 8,
      "z": 3,
      "name": "Soil_Snow"
    },
    {
      "x": 3,
      "y": 6,
      "z": 4,
      "name": "Rock_Ice"
    },
    {
      "x": 3,
      "y": 7,
      "z": 4,
      "name": "Rock_Ice"
    },
    {
      "x": 3,
      "y": 8,
      "z": 4,
      "name": "Soil_Snow"
    },
    {
      "x": 3,
      "y": 6,
      "z": 5,
      "name": "Rock_Ice"
    },
    {
      "x": 3,
      "y": 7,
      "z": 5,
      "name": "Soil_Snow"
    },
    {
      "x": 3,
      "y": 6,
      "z": 6,
      "name": "Rock_Ice"
    },
    {
      "x": 3,
      "y": 7,
      "z": 6,
      "name": "Soil_Snow"
    },
    {
      "x": 3,
      "y": 6,
      "z": 7,
      "name": "Rock_Ice"
    },
    {
      "x": 3,
      "y": 7,
      "z": 7,
      "name": "Soil_Snow"
    },
    {
      "x": 4,
      "y": 6,
      "z": 2,
      "name": "Rock_Ice"
    },
    {
      "x": 4,
      "y": 7,
      "z": 2,
      "name": "Rock_Ice"
    },
    {
      "x": 4,
      "y": 8,
      "z": 2,
      "name": "Soil_Snow"
    },
    {
      "x": 4,
      "y": 5,
      "z": 3,
      "name": "Rock_Ice"
    },
    {
      "x": 4,
      "y": 6,
      "z": 3,
      "name": "Rock_Ice"
    },
    {
      "x": 4,
      "y": 7,
      "z": 3,
      "name": "Rock_Ice"
    },
    {
      "x": 4,
      "y": 8,
      "z": 3,
      "name": "Soil_Snow"
    },
    {
      "x": 4,
      "y": 5,
      "z": 4,
      "name": "Rock_Ice"
    },
    {
      "x": 4,
      "y": 6,
      "z": 4,
      "name": "Rock_Ice"
    },
    {
      "x": 4,
      "y": 7,
      "z": 4,
      "name": "Rock_Ice"
    },
    {
      "x": 4,
      "y": 8,
      "z": 4,
      "name": "Soil_Snow"
    },
    {
      "x": 4,
      "y": 5,
      "z": 5,
      "name": "Rock_Ice"
    },
    {
      "x": 4,
      "y": 6,
      "z": 5,
      "name": "Rock_Ice"
    },
    {
      "x": 4,
      "y": 7,
      "z": 5,
      "name": "Soil_Snow"
    },
    {
      "x": 4,
      "y": 6,
      "z": 6,
      "name": "Rock_Ice"
    },
    {
      "x": 4,
      "y": 7,
      "z": 6,
      "name": "Soil_Snow"
    },
    {
      "x": 4,
      "y": 6,
      "z": 7,
      "name": "Rock_Ice"
    },
    {
      "x": 4,
      "y": 7,
      "z": 7,
      "name": "Soil_Snow"
    },
    {
      "x": 5,
      "y": 6,
      "z": 2,
      "name": "Rock_Ice"
    },
    {
      "x": 5,
      "y": 7,
      "z": 2,
      "name": "Rock_Ice"
    },
    {
      "x": 5,
      "y": 8,
      "z": 2,
      "name": "Soil_Snow"
    },
    {
      "x": 5,
      "y": 5,
      "z": 3,
      "name": "Rock_Ice"
    },
    {
      "x": 5,
      "y": 6,
      "z": 3,
      "name": "Rock_Ice"
    },
    {
      "x": 5,
      "y": 7,
      "z": 3,
      "name": "Rock_Ice"
    },
    {
      "x": 5,
      "y": 8,
      "z": 3,
      "name": "Soil_Snow"
    },
    {
      "x": 5,
      "y": 5,
      "z": 4,
      "name": "Rock_Ice"
    },
    {
      "x": 5,
      "y": 6,
      "z": 4,
      "name": "Rock_Ice"
    },
    {
      "x": 5,
      "y": 7,
      "z": 4,
      "name": "Rock_Ice"
    },
    {
      "x": 5,
      "y": 8,
      "z": 4,
      "name": "Soil_Snow"
    },
    {
      "x": 5,
      "y": 5,
      "z": 5,
      "name": "Rock_Ice"
    },
    {
      "x": 5,
      "y": 6,
      "z": 5,
      "name": "Rock_Ice"
    },
    {
      "x": 5,
      "y": 7,
      "z": 5,
      "name": "Soil_Snow"
    },
    {
      "x": 5,
      "y": 5,
      "z": 6,
      "name": "Rock_Ice"
    },
    {
      "x": 5,
      "y": 6,
      "z": 6,
      "name": "Rock_Ice"
    },
    {
      "x": 5,
      "y": 7,
      "z": 6,
      "name": "Soil_Snow"
    },
    {
      "x": 5,
      "y": 6,
      "z": 7,
      "name": "Rock_Ice"
    },
    {
      "x": 5,
      "y": 7,
      "z": 7,
      "name": "Soil_Snow"
    },
    {
      "x": 5,
      "y": 6,
      "z": 8,
      "name": "Rock_Ice"
    },
    {
      "x": 5,
      "y": 7,
      "z": 8,
      "name": "Soil_Snow"
    },
    {
      "x": 6,
      "y": 6,
      "z": 2,
      "name": "Rock_Ice"
    },
    {
      "x": 6,
      "y": 7,
      "z": 2,
      "name": "Rock_Ice"
    },
    {
      "x": 6,
      "y": 8,
      "z": 2,
      "name": "Soil_Snow"
    },
    {
      "x": 6,
      "y": 5,
      "z": 3,
      "name": "Rock_Ice"
    },
    {
      "x": 6,
      "y": 6,
      "z": 3,
      "name": "Rock_Ice"
    },
    {
      "x": 6,
      "y": 7,
      "z": 3,
      "name": "Rock_Ice"
    },
    {
      "x": 6,
      "y": 8,
      "z": 3,
      "name": "Soil_Snow"
    },
    {
      "x": 6,
      "y": 4,
      "z": 4,
      "name": "Rock_Ice"
    },
    {
      "x": 6,
      "y": 5,
      "z": 4,
      "name": "Rock_Ice"
    },
    {
      "x": 6,
      "y": 6,
      "z": 4,
      "name": "Rock_Ice"
    },
    {
      "x": 6,
      "y": 7,
      "z": 4,
      "name": "Rock_Ice"
    },
    {
      "x": 6,
      "y": 8,
      "z": 4,
      "name": "Soil_Snow"
    },
    {
      "x": 6,
      "y": 4,
      "z": 5,
      "name": "Rock_Ice"
    },
    {
      "x": 6,
      "y": 5,
      "z": 5,
      "name": "Rock_Ice"
    },
    {
      "x": 6,
      "y": 6,
      "z": 5,
      "name": "Rock_Ice"
    },
    {
      "x": 6,
      "y": 7,
      "z": 5,
      "name": "Soil_Snow"
    },
    {
      "x": 6,
      "y": 4,
      "z": 6,
      "name": "Rock_Ice"
    },
    {
      "x": 6,
      "y": 5,
      "z": 6,
      "name": "Rock_Ice"
    },
    {
      "x": 6,
      "y": 6,
      "z": 6,
      "name": "Rock_Ice"
    },
    {
      "x": 6,
      "y": 7,
      "z": 6,
      "name": "Soil_Snow"
    },
    {
      "x": 6,
      "y": 5,
      "z": 7,
      "name": "Rock_Ice"
    },
    {
      "x": 6,
      "y": 6,
      "z": 7,
      "name": "Rock_Ice"
    },
    {
      "x": 6,
      "y": 7,
      "z": 7,
      "name": "Soil_Snow"
    },
    {
      "x": 6,
      "y": 6,
      "z": 8,
      "name": "Rock_Ice"
    },
    {
      "x": 6,
      "y": 7,
      "z": 8,
      "name": "Soil_Snow"
    },
    {
      "x": 7,
      "y": 6,
      "z": 2,
      "name": "Rock_Ice"
    },
    {
      "x": 7,
      "y": 7,
      "z": 2,
      "name": "Rock_Ice"
    },
    {
      "x": 7,
      "y": 8,
      "z": 2,
      "name": "Soil_Snow"
    },
    {
      "x": 7,
      "y": 5,
      "z": 3,
      "name": "Rock_Ice"
    },
    {
      "x": 7,
      "y": 6,
      "z": 3,
      "name": "Rock_Ice"
    },
    {
      "x": 7,
      "y": 7,
      "z": 3,
      "name": "Rock_Ice"
    },
    {
      "x": 7,
      "y": 8,
      "z": 3,
      "name": "Soil_Snow"
    },
    {
      "x": 7,
      "y": 5,
      "z": 4,
      "name": "Rock_Ice"
    },
    {
      "x": 7,
      "y": 6,
      "z": 4,
      "name": "Rock_Ice"
    },
    {
      "x": 7,
      "y": 7,
      "z": 4,
      "name": "Soil_Snow"
    },
    {
      "x": 7,
      "y": 4,
      "z": 5,
      "name": "Rock_Ice"
    },
    {
      "x": 7,
      "y": 5,
      "z": 5,
      "name": "Rock_Ice"
    },
    {
      "x": 7,
      "y": 6,
      "z": 5,
      "name": "Rock_Ice"
    },
    {
      "x": 7,
      "y": 7,
      "z": 5,
      "name": "Soil_Snow"
    },
    {
      "x": 7,
      "y": 4,
      "z": 6,
      "name": "Rock_Ice"
    },
    {
      "x": 7,
      "y": 5,
      "z": 6,
      "name": "Rock_Ice"
    },
    {
      "x": 7,
      "y": 6,
      "z": 6,
      "name": "Rock_Ice"
    },
    {
      "x": 7,
      "y": 7,
      "z": 6,
      "name": "Soil_Snow"
    },
    {
      "x": 7,
      "y": 5,
      "z": 7,
      "name": "Rock_Ice"
    },
    {
      "x": 7,
      "y": 6,
      "z": 7,
      "name": "Rock_Ice"
    },
    {
      "x": 7,
      "y": 7,
      "z": 7,
      "name": "Soil_Snow"
    },
    {
      "x": 7,
      "y": 6,
      "z": 8,
      "name": "Rock_Ice"
    },
    {
      "x": 7,
      "y": 7,
      "z": 8,
      "name": "Soil_Snow"
    },
    {
      "x": 8,
      "y": 6,
      "z": 3,
      "name": "Rock_Ice"
    },
    {
      "x": 8,
      "y": 7,
      "z": 3,
      "name": "Soil_Snow"
    },
    {
      "x": 8,
      "y": 5,
      "z": 4,
      "name": "Rock_Ice"
    },
    {
      "x": 8,
      "y": 6,
      "z": 4,
      "name": "Rock_Ice"
    },
    {
      "x": 8,
      "y": 7,
      "z": 4,
      "name": "Soil_Snow"
    },
    {
      "x": 8,
      "y": 5,
      "z": 5,
      "name": "Rock_Ice"
    },
    {
      "x": 8,
      "y": 6,
      "z": 5,
      "name": "Rock_Ice"
    },
    {
      "x": 8,
      "y": 7,
      "z": 5,
      "name": "Soil_Snow"
    },
    {
      "x": 8,
      "y": 5,
      "z": 6,
      "name": "Rock_Ice"
    },
    {
      "x": 8,
      "y": 6,
      "z": 6,
      "name": "Rock_Ice"
    },
    {
      "x": 8,
      "y": 7,
      "z": 6,
      "name": "Soil_Snow"
    },
    {
      "x": 8,
      "y": 5,
      "z": 7,
      "name": "Rock_Ice"
    },
    {
      "x": 8,
      "y": 6,
      "z": 7,
      "name": "Rock_Ice"
    },
    {
      "x": 8,
      "y": 7,
      "z": 7,
      "name": "Soil_Snow"
    },
    {
      "x": 9,
      "y": 6,
      "z": 4,
      "name": "Rock_Ice"
    },
    {
      "x": 9,
      "y": 7,
      "z": 4,
      "name": "Soil_Snow"
    },
    {
      "x": 9,
      "y": 6,
      "z": 5,
      "name": "Rock_Ice"
    },
    {
      "x": 9,
      "y": 7,
      "z": 5,
      "name": "Soil_Snow"
    },
    {
      "x": 9,
      "y": 6,
      "z": 6,
      "name": "Rock_Ice"
    },
    {
      "x": 9,
      "y": 7,
      "z": 6,
      "name": "Soil_Snow"
    }
  ]
}