{
  "version": 8,
  "blockIdVersion": 8,
  "anchorX": 1,
  "anchorY": 8,
  "anchorZ": 0,
  "blocks": [
    {
      "x": -7,
      "y": 6,
      "z": 2,
      "name": "Rock_Sandstone_White"
    },
    {
      "x": -7,
      "y": 7,
      "z": 2,
      "name": "Rock_Sandstone_White"
    },
    {
      "x": -7,
      "y": 8,
      "z": 2,
      "name": "Rock_Sandstone_White"
    },
    {
      "x": -7,
      "y": 9,
      "z": 2,
      "name": "Soil_Sand_White"
    },
    {
      "x": -7,
      "y": 6,
      "z": 3,
      "name": "Rock_Sandstone_White"
    },
    {
      "x": -7,
      "y": 7,
      "z": 3,
      "name": "Rock_Sandstone_White"
    },
    {
      "x": -7,
      "y": 8,
      "z": 3,
      "name": "Rock_Sandstone_White"
    },
    {
      "x": -7,
      "y": 9,
      "z": 3,
      "name": "Soil_Sand_White"
    },
    {
      "x": -7,
      "y": 10,
      "z": 3,
      "name": "Soil_Sand_White"
    },
    {
      "x": -7,
      "y": 6,
      "z": 4,
      "name": "Rock_Sandstone_White"
    },
    {
      "x": -7,
      "y": 7,
      "z": 4,
      "name": "Rock_Sandstone_White"
    },
    {
      "x": -7,
      "y": 8,
      "z": 4,
      "name": "Rock_Sandstone_White"
    },
    {
      "x": -7,
      "y": 9,
      "z": 4,
      "name": "Rock_Sandstone_White"
    },
    {
      "x": -7,
      "y": 10,
      "z": 4,
      "name": "Soil_Sand_White"
    },
    {
      "x": -7,
      "y": 6,
      "z": 5,
      "name": "Rock_Sandstone_White"
    },
    {
      "x": -7,
      "y": 7,
      "z": 5,
      "name": "Rock_Sandstone_White"
    },
    {
      "x": -7,
      "y": 8,
      "z": 5,
      "name": "Rock_Sandstone_White"
    },
    {
      "x": -7,
      "y": 9,
      "z": 5,
      "name": "Rock_Sandstone_White"
    },
    {
      "x": -7,
      "y": 10,
      "z": 5,
      "name": "Soil_Sand_White"
    },
    {
      "x": -7,
      "y": 6,
      "z": 6,
      "name": "Rock_Sandstone_White"
    },
    {
      "x": -7,
      "y": 7,
      "z": 6,
      "name": "Rock_Sandstone_White"
    },
    {
      "x": -7,
      "y": 8,
      "z": 6,
      "name": "Rock_Sandstone_White"
    },
    {
      "x": -7,
      "y": 9,
      "z": 6,
      "name": "Soil_Sand_White"
    },
    {
      "x": -7,
      "y": 10,
      "z": 6,
      "name": "Soil_Sand_White"
    },
    {
      "x": -7,
      "y": 7,
      "z": 7,
      "name": "Rock_Sandstone_White"
    },
    {
      "x": -7,
      "y": 8,
      "z": 7,
      "name": "Rock_Sandstone_White"
    },
    {
      "x": -7,
      "y": 9,
      "z": 7,
      "name": "Soil_Sand_White"
    },
    {
      "x": -6,
      "y": 6,
      "z": 0,
      "name": "Rock_Sandstone_White"
    },
    {
      "x": -6,
      "y": 7,
      "z": 0,
      "name": "Rock_Sandstone_White"
    },
    {
      "x": -6,
      "y": 8,
      "z": 0,
      "name": "Rock_Sandstone_White"
    },
    {
      "x": -6,
      "y": 9,
      "z": 0,
      "name": "Soil_Sand_White"
    },
    {
      "x": -6,
      "y": 6,
      "z": 1,
      "name": "Rock_Sandstone_White"
    },
    {
      "x": -6,
      "y": 7,
      "z": 1,
      "name": "Rock_Sandstone_White"
    },
    {
      "x": -6,
      "y": 8,
      "z": 1,
      "name": "Rock_Sandstone_White"
    },
    {
      "x": -6,
      "y": 9,
      "z": 1,
      "name": "Soil_Sand_White"
    },
    {
      "x": -6,
      "y": 10,
      "z": 1,
      "name": "Soil_Sand_White"
    },
    {
      "x": -6,
      "y": 5,
      "z": 2,
      "name": "Rock_Sandstone_White"
    },
    {
      "x": -6,
      "y": 6,
      "z": 2,
      "name": "Rock_Sandstone_White"
    },
    {
      "x": -6,
      "y": 7,
      "z": 2,
      "name": "Rock_Sandstone_White"
    },
    {
      "x": -6,
      "y": 8,
      "z": 2,
      "name": "Rock_Sandstone_White"
    },
    {
      "x": -6,
      "y": 9,
      "z": 2,
      "name": "Rock_Sandstone_White"
    },
    {
      "x": -6,
      "y": 10,
      "z": 2,
      "name": "Soil_Sand_White"
    },
    {
      "x": -6,
      "y": 25,
      "z": 2,
      "name": "Soil_Gravel_Sand_White"
    },
    {
      "x": -6,
      "y": 26,
      "z": 2,
      "name": "Soil_Gravel_Sand_White"
    },
    {
      "x": -6,
      "y": 27,
      "z": 2,
      "name": "Soil_Gravel_Sand_White"
    },
    {
      "x": -6,
      "y": 28,
      "z": 2,
      "name": "Rock_Sandstone"
    },
    {
      "x": -6,
      "y": 5,
      "z": 3,
      "name": "Rock_Sandstone_White"
    },
    {
      "x": -6,
      "y": 6,
      "z": 3,
      "name": "Rock_Sandstone_White"
    },
    {
      "x": -6,
      "y": 7,
      "z": 3,
      "name": "Rock_Sandstone_White"
    },
    {
      "x": -6,
      "y": 8,
      "z": 3,
      "name": "Rock_Sandstone_White"
    },
    {
      "x": -6,
      "y": 9,
      "z": 3,
      "name": "Rock_Sandstone_White"
    },
    {
      "x": -6,
      "y": 10,
      "z": 3,
      "name": "Soil_Sand_White"
    },
    {
      "x": -6,
      "y": 11,
      "z": 3,
      "name": "Soil_Gravel_Sand"
    },
    {
      "x": -6,
      "y": 12,
      "z": 3,
      "name": "Soil_Gravel_Sand"
    },
    {
      "x": -6,
      "y": 25,
      "z": 3,
      "name": "Soil_Gravel_Sand_White"
    },
    {
      "x": -6,
      "y": 26,
      "z": 3,
      "name": "Soil_Gravel_Sand_White"
    },
    {
      "x": -6,
      "y": 27,
      "z": 3,
      "name": "Soil_Gravel_Sand_White"
    },
    {
      "x": -6,
      "y": 28,
      "z": 3,
      "name": "Rock_Sandstone"
    },
    {
      "x": -6,
      "y": 5,
      "z": 4,
      "name": "Rock_Sandstone_White"
    },
    {
      "x": -6,
      "y": 6,
      "z": 4,
      "name": "Rock_Sandstone_White"
    },
    {
      "x": -6,
      "y": 7,
      "z": 4,
      "name": "Rock_Sandstone_White"
    },
    {
      "x": -6,
      "y": 8,
      "z": 4,
      "name": "Rock_Sandstone_White"
    },
    {
      "x": -6,
      "y": 9,
      "z": 4,
      "name": "Rock_Sandstone_White"
    },
    {
      "x": -6,
      "y": 10,
      "z": 4,
      "name": "Rock_Sandstone_White"
    },
    {
      "x": -6,
      "y": 11,
      "z": 4,
      "name": "Soil_Gravel_Sand"
    },
    {
      "x": -6,
      "y": 12,
      "z": 4,
      "name": "Soil_Gravel_Sand"
    },
    {
      "x": -6,
      "y": 25,
      "z": 4,
      "name": "Soil_Gravel_Sand_White"
    },
    {
      "x": -6,
      "y": 26,
      "z": 4,
      "name": "Soil_Gravel_Sand_White"
    },
    {
      "x": -6,
      "y": 27,
      "z": 4,
      "name": "Soil_Gravel_Sand_White"
    },
    {
      "x": -6,
      "y": 28,
      "z": 4,
      "name": "Rock_Sandstone"
    },
    {
      "x": -6,
      "y": 6,
      "z": 5,
      "name": "Rock_Sandstone_White"
    },
    {
      "x": -6,
      "y": 7,
      "z": 5,
      "name": "Rock_Sandstone_White"
    },
    {
      "x": -6,
      "y": 8,
      "z": 5,
      "name": "Rock_Sandstone_White"
    },
    {
      "x": -6,
      "y": 9,
      "z": 5,
      "name": "Rock_Sandstone_White"
    },
    {
      "x": -6,
      "y": 10,
      "z": 5,
      "name": "Rock_Sandstone_White"
    },
    {
      "x": -6,
      "y": 11,
      "z": 5,
      "name": "Soil_Gravel_Sand"
    },
    {
      "x": -6,
      "y": 12,
      "z": 5,
      "name": "Soil_Gravel_Sand"
    },
    {
      "x": -6,
      "y": 25,
      "z": 5,
      "name": "Soil_Gravel_Sand_White"
    },
    {
      "x": -6,
      "y": 26,
      "z": 5,
      "name": "Soil_Gravel_Sand_White"
    },
    {
      "x": -6,
      "y": 27,
      "z": 5,
      "name": "Soil_Gravel_Sand_White"
    },
    {
      "x": -6,
      "y": 28,
      "z": 5,
      "name": "Rock_Sandstone"
    },
    {
      "x": -6,
      "y": 6,
      "z": 6,
      "name": "Rock_Sandstone_White"
    },
    {
      "x": -6,
      "y": 7,
      "z": 6,
      "name": "Rock_Sandstone_White"
    },
    {
      "x": -6,
      "y": 8,
      "z": 6,
      "name": "Rock_Sandstone_White"
    },
    {
      "x": -6,
      "y": 9,
      "z": 6,
      "name": "Rock_Sandstone_White"
    },
    {
      "x": -6,
      "y": 10,
      "z": 6,
      "name": "Soil_Sand_White"
    },
    {
      "x": -6,
      "y": 11,
      "z": 6,
      "name": "Soil_Gravel_Sand"
    },
    {
      "x": -6,
      "y": 12,
      "z": 6,
      "name": "Soil_Gravel_Sand"
    },
    {
      "x": -6,
      "y": 25,
      "z": 6,
      "name": "Soil_Gravel_Sand_White"
    },
    {
      "x": -6,
      "y": 26,
      "z": 6,
      "name": "Soil_Gravel_Sand_White"
    },
    {
      "x": -6,
      "y": 27,
      "z": 6,
      "name": "Soil_Gravel_Sand_White"
    },
    {
      "x": -6,
      "y": 28,
      "z": 6,
      "name": "Rock_Sandstone"
    },
    {
      "x": -6,
      "y": 6,
      "z": 7,
      "name": "Rock_Sandstone_White"
    },
    {
      "x": -6,
      "y": 7,
      "z": 7,
      "name": "Rock_Sandstone_White"
    },
    {
      "x": -6,
      "y": 8,
      "z": 7,
      "name": "Rock_Sandstone_White"
    },
    {
      "x": -6,
      "y": 9,
      "z": 7,
      "name": "Rock_Sandstone_White"
    },
    {
      "x": -6,
      "y": 10,
      "z": 7,
      "name": "Soil_Sand_White"
    },
    {
      "x": -6,
      "y": 6,
      "z": 8,
      "name": "Rock_Sandstone_White"
    },
    {
      "x": -6,
      "y": 7,
      "z": 8,
      "name": "Rock_Sandstone_White"
    },
    {
      "x": -6,
      "y": 8,
      "z": 8,
      "name": "Rock_Sandstone_White"
    },
    {
      "x": -6,
      "y": 9,
      "z": 8,
      "name": "Rock_Sandstone_White"
    },
    {
      "x": -6,
      "y": 10,
      "z": 8,
      "name": "Soil_Sand_White"
    },
    {
      "x": -6,
      "y": 7,
      "z": 9,
      "name": "Rock_Sandstone_White"
    },
    {
      "x": -6,
      "y": 8,
      "z": 9,
      "name": "Rock_Sandstone_White"
    },
    {
      "x": -6,
      "y": 9,
      "z": 9,
      "name": "Rock_Sandstone_White"
    },
    {
      "x": -6,
      "y": 10,
      "z": 9,
      "name": "Soil_Sand_White"
    },
    {
      "x": -5,
      "y": 6,
      "z": -1,
      "name": "Rock_Sandstone_White"
    },
    {
      "x": -5,
      "y": 7,
      "z": -1,
      "name": "Rock_Sandstone_White"
    },
    {
      "x": -5,
      "y": 8,
      "z": -1,
      "name": "Rock_Sandstone_White"
    },
    {
      "x": -5,
      "y": 9,
      "z": -1,
      "name": "Soil_Sand_White"
    },
    {
      "x": -5,
      "y": 5,
      "z": 0,
      "name": "Rock_Sandstone_White"
    },
    {
      "x": -5,
      "y": 6,
      "z": 0,
      "name": "Rock_Sandstone_White"
    },
    {
      "x": -5,
      "y": 7,
      "z": 0,
      "name": "Rock_Sandstone_White"
    },
    {
      "x": -5,
      "y": 8,
      "z": 0,
      "name": "Rock_Sandstone_White"
    },
    {
      "x": -5,
      "y": 9,
      "z": 0,
      "name": "Rock_Sandstone_White"
    },
    {
      "x": -5,
      "y": 10,
      "z": 0,
      "name": "Soil_Sand_White"
    },
    {
      "x": -5,
      "y": 25,
      "z": 0,
      "name": "Soil_Gravel_Sand_White"
    },
    {
      "x": -5,
      "y": 26,
      "z": 0,
      "name": "Soil_Gravel_Sand_White"
    },
    {
      "x": -5,
      "y": 27,
      "z": 0,
      "name": "Soil_Gravel_Sand_White"
    },
    {
      "x": -5,
      "y": 28,
      "z": 0,
      "name": "Rock_Sandstone"
    },
    {
      "x": -5,
      "y": 5,
      "z": 1,
      "name": "Rock_Sandstone_White"
    },
    {
      "x": -5,
      "y": 6,
      "z": 1,
      "name": "Rock_Sandstone_White"
    },
    {
      "x": -5,
      "y": 7,
      "z": 1,
      "name": "Rock_Sandstone_White"
    },
    {
      "x": -5,
      "y": 8,
      "z": 1,
      "name": "Rock_Sandstone_White"
    },
    {
      "x": -5,
      "y": 9,
      "z": 1,
      "name": "Rock_Sandstone_White"
    },
    {
      "x": -5,
      "y": 10,
      "z": 1,
      "name": "Soil_Sand_White"
    },
    {
      "x": -5,
      "y": 11,
      "z": 1,
      "name": "Soil_Gravel_Sand"
    },
    {
      "x": -5,
      "y": 12,
      "z": 1,
      "name": "Soil_Gravel_Sand"
    },
    {
      "x": -5,
      "y": 25,
      "z": 1,
      "name": "Soil_Gravel_Sand_White"
    },
    {
      "x": -5,
      "y": 26,
      "z": 1,
      "name": "Soil_Gravel_Sand_White"
    },
    {
      "x": -5,
      "y": 27,
      "z": 1,
      "name": "Soil_Gravel_Sand_White"
    },
    {
      "x": -5,
      "y": 28,
      "z": 1,
      "name": "Rock_Sandstone"
    },
    {
      "x": -5,
      "y": 5,
      "z": 2,
      "name": "Rock_Sandstone_White"
    },
    {
      "x": -5,
      "y": 6,
      "z": 2,
      "name": "Rock_Sandstone_White"
    },
    {
      "x": -5,
      "y": 7,
      "z": 2,
      "name": "Rock_Sandstone_White"
    },
    {
      "x": -5,
      "y": 8,
      "z": 2,
      "name": "Rock_Sandstone_White"
    },
    {
      "x": -5,
      "y": 9,
      "z": 2,
      "name": "Rock_Sandstone_White"
    },
    {
      "x": -5,
      "y": 10,
      "z": 2,
      "name": "Rock_Sandstone_White"
    },
    {
      "x": -5,
      "y": 11,
      "z": 2,
      "name": "Soil_Gravel_Sand"
    },
    {
      "x": -5,
      "y": 12,
      "z": 2,
      "name": "Soil_Gravel_Sand"
    },
    {
      "x": -5,
      "y": 25,
      "z": 2,
      "name": "Soil_Gravel_Sand_White"
    },
    {
      "x": -5,
      "y": 26,
      "z": 2,
      "name": "Soil_Gravel_Sand_White"
    },
    {
      "x": -5,
      "y": 27,
      "z": 2,
      "name": "Soil_Gravel_Sand_White"
    },
    {
      "x": -5,
      "y": 28,
      "z": 2,
      "name": "Rock_Sandstone"
    },
    {
      "x": -5,
      "y": 4,
      "z": 3,
      "name": "Rock_Sandstone_White"
    },
    {
      "x": -5,
      "y": 5,
      "z": 3,
      "name": "Rock_Sandstone_White"
    },
    {
      "x": -5,
      "y": 6,
      "z": 3,
      "name": "Rock_Sandstone_White"
    },
    {
      "x": -5,
      "y": 7,
      "z": 3,
      "name": "Rock_Sandstone_White"
    },
    {
      "x": -5,
      "y": 8,
      "z": 3,
      "name": "Rock_Sandstone_White"
    },
    {
      "x": -5,
      "y": 9,
      "z": 3,
      "name": "Rock_Sandstone_White"
    },
    {
      "x": -5,
      "y": 10,
      "z": 3,
      "name": "Rock_Sandstone_White"
    },
    {
      "x": -5,
      "y": 11,
      "z": 3,
      "name": "Soil_Gravel_Sand"
    },
    {
      "x": -5,
      "y": 12,
      "z": 3,
      "name": "Soil_Gravel_Sand"
    },
    {
      "x": -5,
      "y": 23,
      "z": 3,
      "name": "Soil_Gravel_Sand"
    },
    {
      "x": -5,
      "y": 24,
      "z": 3,
      "name": "Soil_Gravel_Sand_White"
    },
    {
      "x": -5,
      "y": 25,
      "z": 3,
      "name": "Soil_Gravel_Sand_White"
    },
    {
      "x": -5,
      "y": 26,
      "z": 3,
      "name": "Soil_Gravel_Sand_White"
    },
    {
      "x": -5,
      "y": 27,
      "z": 3,
      "name": "Soil_Gravel_Sand_White"
    },
    {
      "x": -5,
      "y": 28,
      "z": 3,
      "name": "Rock_Sandstone"
    },
    {
      "x": -5,
      "y": 4,
      "z": 4,
      "name": "Rock_Sandstone_White"
    },
    {
      "x": -5,
      "y": 5,
      "z": 4,
      "name": "Rock_Sandstone_White"
    },
    {
      "x": -5,
      "y": 6,
      "z": 4,
      "name": "Rock_Sandstone_White"
    },
    {
      "x": -5,
      "y": 7,
      "z": 4,
      "name": "Rock_Sandstone_White"
    },
    {
      "x": -5,
      "y": 8,
      "z": 4,
      "name": "Rock_Sandstone_White"
    },
    {
      "x": -5,
      "y": 9,
      "z": 4,
      "name": "Rock_Sandstone_White"
    },
    {
      "x": -5,
      "y": 10,
      "z": 4,
      "name": "Rock_Sandstone_White"
    },
    {
      "x": -5,
      "y": 11,
      "z": 4,
      "name": "Soil_Gravel_Sand"
    },
    {
      "x": -5,
      "y": 12,
      "z": 4,
      "name": "Soil_Gravel_Sand"
    },
    {
      "x": -5,
      "y": 13,
      "z": 4,
      "name": "Soil_Gravel_Sand"
    },
    {
      "x": -5,
      "y": 23,
      "z": 4,
      "name": "Soil_Gravel_Sand"
    },
    {
      "x": -5,
      "y": 24,
      "z": 4,
      "name": "Soil_Gravel_Sand_White"
    },
    {
      "x": -5,
      "y": 25,
      "z": 4,
      "name": "Soil_Gravel_Sand_White"
    },
    {
      "x": -5,
      "y": 26,
      "z": 4,
      "name": "Soil_Gravel_Sand_White"
    },
    {
      "x": -5,
      "y": 27,
      "z": 4,
      "name": "Soil_Gravel_Sand_White"
    },
    {
      "x": -5,
      "y": 28,
      "z": 4,
      "name": "Rock_Sandstone"
    },
    {
      "x": -5,
      "y": 4,
      "z": 5,
      "name": "Rock_Sandstone_White"
    },
    {
      "x": -5,
      "y": 5,
      "z": 5,
      "name": "Rock_Sandstone_White"
    },
    {
      "x": -5,
      "y": 6,
      "z": 5,
      "name": "Rock_Sandstone_White"
    },
    {
      "x": -5,
      "y": 7,
      "z": 5,
      "name": "Rock_Sandstone_White"
    },
    {
      "x": -5,
      "y": 8,
      "z": 5,
      "name": "Rock_Sandstone_White"
    },
    {
      "x": -5,
      "y": 9,
      "z": 5,
      "name": "Rock_Sandstone_White"
    },
    {
      "x": -5,
      "y": 10,
      "z": 5,
      "name": "Rock_Sandstone_White"
    },
    {
      "x": -5,
      "y": 11,
      "z": 5,
      "name": "Soil_Gravel_Sand"
    },
    {
      "x": -5,
      "y": 12,
      "z": 5,
      "name": "Soil_Gravel_Sand"
    },
    {
      "x": -5,
      "y": 13,
      "z": 5,
      "name": "Soil_Gravel_Sand"
    },
    {
      "x": -5,
      "y": 23,
      "z": 5,
      "name": "Soil_Gravel_Sand"
    },
    {
      "x": -5,
      "y": 24,
      "z": 5,
      "name": "Soil_Gravel_Sand_White"
    },
    {
      "x": -5,
      "y": 25,
      "z": 5,
      "name": "Soil_Gravel_Sand_White"
    },
    {
      "x": -5,
      "y": 26,
      "z": 5,
      "name": "Soil_Gravel_Sand_White"
    },
    {
      "x": -5,
      "y": 27,
      "z": 5,
      "name": "Soil_Gravel_Sand_White"
    },
    {
      "x": -5,
      "y": 28,
      "z": 5,
      "name": "Rock_Sandstone"
    },
    {
      "x": -5,
      "y": 5,
      "z": 6,
      "name": "Rock_Sandstone_White"
    },
    {
      "x": -5,
      "y": 6,
      "z": 6,
      "name": "Rock_Sandstone_White"
    },
    {
      "x": -5,
      "y": 7,
      "z": 6,
      "name": "Rock_Sandstone_White"
    },
    {
      "x": -5,
      "y": 8,
      "z": 6,
      "name": "Rock_Sandstone_White"
    },
    {
      "x": -5,
      "y": 9,
      "z": 6,
      "name": "Rock_Sandstone_White"
    },
    {
      "x": -5,
      "y": 10,
      "z": 6,
      "name": "Rock_Sandstone_White"
    },
    {
      "x": -5,
      "y": 11,
      "z": 6,
      "name": "Soil_Gravel_Sand"
    },
    {
      "x": -5,
      "y": 12,
      "z": 6,
      "name": "Soil_Gravel_Sand"
    },
    {
      "x": -5,
      "y": 13,
      "z": 6,
      "name": "Soil_Gravel_Sand"
    },
    {
      "x": -5,
      "y": 25,
      "z": 6,
      "name": "Soil_Gravel_Sand_White"
    },
    {
      "x": -5,
      "y": 26,
      "z": 6,
      "name": "Soil_Gravel_Sand_White"
    },
    {
      "x": -5,
      "y": 27,
      "z": 6,
      "name": "Soil_Gravel_Sand_White"
    },
    {
      "x": -5,
      "y": 28,
      "z": 6,
      "name": "Rock_Sandstone"
    },
    {
      "x": -5,
      "y": 5,
      "z": 7,
      "name": "Rock_Sandstone_White"
    },
    {
      "x": -5,
      "y": 6,
      "z": 7,
      "name": "Rock_Sandstone_White"
    },
    {
      "x": -5,
      "y": 7,
      "z": 7,
      "name": "Rock_Sandstone_White"
    },
    {
      "x": -5,
      "y": 8,
      "z": 7,
      "name": "Rock_Sandstone_White"
    },
    {
      "x": -5,
      "y": 9,
      "z": 7,
      "name": "Rock_Sandstone_White"
    },
    {
      "x": -5,
      "y": 10,
      "z": 7,
      "name": "Rock_Sandstone_White"
    },
    {
      "x": -5,
      "y": 11,
      "z": 7,
      "name": "Soil_Gravel_Sand"
    },
    {
      "x": -5,
      "y": 12,
      "z": 7,
      "name": "Soil_Gravel_Sand"
    },
    {
      "x": -5,
      "y": 25,
      "z": 7,
      "name": "Soil_Gravel_Sand_White"
    },
    {
      "x": -5,
      "y": 26,
      "z": 7,
      "name": "Soil_Gravel_Sand_White"
    },
    {
      "x": -5,
      "y": 27,
      "z": 7,
      "name": "Soil_Gravel_Sand_White"
    },
    {
      "x": -5,
      "y": 28,
      "z": 7,
      "name": "Rock_Sandstone"
    },
    {
      "x": -5,
      "y": 5,
      "z": 8,
      "name": "Rock_Sandstone_White"
    },
    {
      "x": -5,
      "y": 6,
      "z": 8,
      "name": "Rock_Sandstone_White"
    },
    {
      "x": -5,
      "y": 7,
      "z": 8,
      "name": "Rock_Sandstone_White"
    },
    {
      "x": -5,
      "y": 8,
      "z": 8,
      "name": "Rock_Sandstone_White"
    },
    {
      "x": -5,
      "y": 9,
      "z": 8,
      "name": "Rock_Sandstone_White"
    },
    {
      "x": -5,
      "y": 10,
      "z": 8,
      "name": "Soil_Sand_White"
    },
    {
      "x": -5,
      "y": 11,
      "z": 8,
      "name": "Soil_Gravel_Sand"
    },
    {
      "x": -5,
      "y": 12,
      "z": 8,
      "name": "Soil_Gravel_Sand"
    },
    {
      "x": -5,
      "y": 25,
      "z": 8,
      "name": "Soil_Gravel_Sand_White"
    },
    {
      "x": -5,
      "y": 26,
      "z": 8,
      "name": "Soil_Gravel_Sand_White"
    },
    {
      "x": -5,
      "y": 27,
      "z": 8,
      "name": "Soil_Gravel_Sand_White"
    },
    {
      "x": -5,
      "y": 28,
      "z": 8,
      "name": "Rock_Sandstone"
    },
    {
      "x": -5,
      "y": 6,
      "z": 9,
      "name": "Rock_Sandstone_White"
    },
    {
      "x": -5,
      "y": 7,
      "z": 9,
      "name": "Rock_Sandstone_White"
    },
    {
      "x": -5,
      "y": 8,
      "z": 9,
      "name": "Rock_Sandstone_White"
    },
    {
      "x": -5,
      "y": 9,
      "z": 9,
      "name": "Rock_Sandstone_White"
    },
    {
      "x": -5,
      "y": 10,
      "z": 9,
      "name": "Soil_Sand_White"
    },
    {
      "x": -5,
      "y": 7,
      "z": 10,
      "name": "Rock_Sandstone_White"
    },
    {
      "x": -5,
      "y": 8,
      "z": 10,
      "name": "Rock_Sandstone_White"
    },
    {
      "x": -5,
      "y": 9,
      "z": 10,
      "name": "Soil_Sand_White"
    },
    {
      "x": -4,
      "y": 6,
      "z": -1,
      "name": "Rock_Sandstone_White"
    },
    {
      "x": -4,
      "y": 7,
      "z": -1,
      "name": "Rock_Sandstone_White"
    },
    {
      "x": -4,
      "y": 8,
      "z": -1,
      "name": "Rock_Sandstone_White"
    },
    {
      "x": -4,
      "y": 9,
      "z": -1,
      "name": "Soil_Sand_White"
    },
    {
      "x": -4,
      "y": 25,
      "z": -1,
      "name": "Soil_Gravel_Sand_White"
    },
    {
      "x": -4,
      "y": 26,
      "z": -1,
      "name": "Soil_Gravel_Sand_White"
    },
    {
      "x": -4,
      "y": 27,
      "z": -1,
      "name": "Soil_Gravel_Sand_White"
    },
    {
      "x": -4,
      "y": 28,
      "z": -1,
      "name": "Rock_Sandstone"
    },
    {
      "x": -4,
      "y": 5,
      "z": 0,
      "name": "Rock_Sandstone_White"
    },
    {
      "x": -4,
      "y": 6,
      "z": 0,
      "name": "Rock_Sandstone_White"
    },
    {
      "x": -4,
      "y": 7,
      "z": 0,
      "name": "Rock_Sandstone_White"
    },
    {
      "x": -4,
      "y": 8,
      "z": 0,
      "name": "Rock_Sandstone_White"
    },
    {
      "x": -4,
      "y": 9,
      "z": 0,
      "name": "Rock_Sandstone_White"
    },
    {
      "x": -4,
      "y": 10,
      "z": 0,
      "name": "Soil_Sand_White"
    },
    {
      "x": -4,
      "y": 25,
      "z": 0,
      "name": "Soil_Gravel_Sand_White"
    },
    {
      "x": -4,
      "y": 26,
      "z": 0,
      "name": "Soil_Gravel_Sand_White"
    },
    {
      "x": -4,
      "y": 27,
      "z": 0,
      "name": "Soil_Gravel_Sand_White"
    },
    {
      "x": -4,
      "y": 28,
      "z": 0,
      "name": "Rock_Sandstone"
    },
    {
      "x": -4,
      "y": 4,
      "z": 1,
      "name": "Rock_Sandstone_White"
    },
    {
      "x": -4,
      "y": 5,
      "z": 1,
      "name": "Rock_Sandstone_White"
    },
    {
      "x": -4,
      "y": 6,
      "z": 1,
      "name": "Rock_Sandstone_White"
    },
    {
      "x": -4,
      "y": 7,
      "z": 1,
      "name": "Rock_Sandstone_White"
    },
    {
      "x": -4,
      "y": 8,
      "z": 1,
      "name": "Rock_Sandstone_White"
    },
    {
      "x": -4,
      "y": 9,
      "z": 1,
      "name": "Rock_Sandstone_White"
    },
    {
      "x": -4,
      "y": 10,
      "z": 1,
      "name": "Rock_Sandstone_White"
    },
    {
      "x": -4,
      "y": 11,
      "z": 1,
      "name": "Soil_Gravel_Sand"
    },
    {
      "x": -4,
      "y": 12,
      "z": 1,
      "name": "Soil_Gravel_Sand"
    },
    {
      "x": -4,
      "y": 23,
      "z": 1,
      "name": "Soil_Gravel_Sand"
    },
    {
      "x": -4,
      "y": 24,
      "z": 1,
      "name": "Soil_Gravel_Sand_White"
    },
    {
      "x": -4,
      "y": 25,
      "z": 1,
      "name": "Soil_Gravel_Sand_White"
    },
    {
      "x": -4,
      "y": 26,
      "z": 1,
      "name": "Soil_Gravel_Sand_White"
    },
    {
      "x": -4,
      "y": 27,
      "z": 1,
      "name": "Soil_Gravel_Sand_White"
    },
    {
      "x": -4,
      "y": 28,
      "z": 1,
      "name": "Rock_Sandstone"
    },
    {
      "x": -4,
      "y": 3,
      "z": 2,
      "name": "Rock_Sandstone_White"
    },
    {
      "x": -4,
      "y": 4,
      "z": 2,
      "name": "Rock_Sandstone_White"
    },
    {
      "x": -4,
      "y": 5,
      "z": 2,
      "name": "Rock_Sandstone_White"
    },
    {
      "x": -4,
      "y": 6,
      "z": 2,
      "name": "Rock_Sandstone_White"
    },
    {
      "x": -4,
      "y": 7,
      "z": 2,
      "name": "Rock_Sandstone_White"
    },
    {
      "x": -4,
      "y": 8,
      "z": 2,
      "name": "Rock_Sandstone_White"
    },
    {
      "x": -4,
      "y": 9,
      "z": 2,
      "name": "Rock_Sandstone_White"
    },
    {
      "x": -4,
      "y": 10,
      "z": 2,
      "name": "Rock_Sandstone_White"
    },
    {
      "x": -4,
      "y": 11,
      "z": 2,
      "name": "Soil_Gravel_Sand"
    },
    {
      "x": -4,
      "y": 12,
      "z": 2,
      "name": "Soil_Gravel_Sand"
    },
    {
      "x": -4,
      "y": 23,
      "z": 2,
      "name": "Soil_Gravel_Sand"
    },
    {
      "x": -4,
      "y": 24,
      "z": 2,
      "name": "Soil_Gravel_Sand_White"
    },
    {
      "x": -4,
      "y": 25,
      "z": 2,
      "name": "Soil_Gravel_Sand_White"
    },
    {
      "x": -4,
      "y": 26,
      "z": 2,
      "name": "Soil_Gravel_Sand_White"
    },
    {
      "x": -4,
      "y": 27,
      "z": 2,
      "name": "Soil_Gravel_Sand_White"
    },
    {
      "x": -4,
      "y": 28,
      "z": 2,
      "name": "Rock_Sandstone"
    },
    {
      "x": -4,
      "y": 3,
      "z": 3,
      "name": "Rock_Sandstone_White"
    },
    {
      "x": -4,
      "y": 4,
      "z": 3,
      "name": "Rock_Sandstone_White"
    },
    {
      "x": -4,
      "y": 5,
      "z": 3,
      "name": "Rock_Sandstone_White"
    },
    {
      "x": -4,
      "y": 6,
      "z": 3,
      "name": "Rock_Sandstone_White"
    },
    {
      "x": -4,
      "y": 7,
      "z": 3,
      "name": "Rock_Sandstone_White"
    },
    {
      "x": -4,
      "y": 8,
      "z": 3,
      "name": "Rock_Sandstone_White"
    },
    {
      "x": -4,
      "y": 9,
      "z": 3,
      "name": "Rock_Sandstone_White"
    },
    {
      "x": -4,
      "y": 10,
      "z": 3,
      "name": "Rock_Sandstone_White"
    },
    {
      "x": -4,
      "y": 11,
      "z": 3,
      "name": "Soil_Gravel_Sand"
    },
    {
      "x": -4,
      "y": 12,
      "z": 3,
      "name": "Soil_Gravel_Sand"
    },
    {
      "x": -4,
      "y": 13,
      "z": 3,
      "name": "Soil_Gravel_Sand"
    },
    {
      "x": -4,
      "y": 23,
      "z": 3,
      "name": "Soil_Gravel_Sand"
    },
    {
      "x": -4,
      "y": 24,
      "z": 3,
      "name": "Soil_Gravel_Sand_White"
    },
    {
      "x": -4,
      "y": 25,
      "z": 3,
      "name": "Soil_Gravel_Sand_White"
    },
    {
      "x": -4,
      "y": 26,
      "z": 3,
      "name": "Soil_Gravel_Sand_White"
    },
    {
      "x": -4,
      "y": 27,
      "z": 3,
      "name": "Soil_Gravel_Sand_White"
    },
    {
      "x": -4,
      "y": 28,
      "z": 3,
      "name": "Rock_Sandstone"
    },
    {
      "x": -4,
      "y": 3,
      "z": 4,
      "name": "Rock_Sandstone_White"
    },
    {
      "x": -4,
      "y": 4,
      "z": 4,
      "name": "Rock_Sandstone_White"
    },
    {
      "x": -4,
      "y": 5,
      "z": 4,
      "name": "Rock_Sandstone_White"
    },
    {
      "x": -4,
      "y": 6,
      "z": 4,
      "name": "Rock_Sandstone_White"
    },
    {
      "x": -4,
      "y": 7,
      "z": 4,
      "name": "Rock_Sandstone_White"
    },
    {
      "x": -4,
      "y": 8,
      "z": 4,
      "name": "Rock_Sandstone_White"
    },
    {
      "x": -4,
      "y": 9,
      "z": 4,
      "name": "Rock_Sandstone_White"
    },
    {
      "x": -4,
      "y": 10,
      "z": 4,
      "name": "Rock_Sandstone_White"
    },
    {
      "x": -4,
      "y": 11,
      "z": 4,
      "name": "Soil_Gravel_Sand"
    },
    {
      "x": -4,
      "y": 12,
      "z": 4,
      "name": "Soil_Gravel_Sand"
    },
    {
      "x": -4,
      "y": 13,
      "z": 4,
      "name": "Soil_Gravel_Sand"
    },
    {
      "x": -4,
      "y": 23,
      "z": 4,
      "name": "Soil_Gravel_Sand"
    },
    {
      "x": -4,
      "y": 24,
      "z": 4,
      "name": "Soil_Gravel_Sand_White"
    },
    {
      "x": -4,
      "y": 25,
      "z": 4,
      "name": "Soil_Gravel_Sand_White"
    },
    {
      "x": -4,
      "y": 26,
      "z": 4,
      "name": "Soil_Gravel_Sand_White"
    },
    {
      "x": -4,
      "y": 27,
      "z": 4,
      "name": "Soil_Gravel_Sand_White"
    },
    {
      "x": -4,
      "y": 28,
      "z": 4,
      "name": "Rock_Sandstone"
    },
    {
      "x": -4,
      "y": 4,
      "z": 5,
      "name": "Rock_Sandstone_White"
    },
    {
      "x": -4,
      "y": 5,
      "z": 5,
      "name": "Rock_Sandstone_White"
    },
    {
      "x": -4,
      "y": 6,
      "z": 5,
      "name": "Rock_Sandstone_White"
    },
    {
      "x": -4,
      "y": 7,
      "z": 5,
      "name": "Rock_Sandstone_White"
    },
    {
      "x": -4,
      "y": 8,
      "z": 5,
      "name": "Rock_Sandstone_White"
    },
    {
      "x": -4,
      "y": 9,
      "z": 5,
      "name": "Rock_Sandstone_White"
    },
    {
      "x": -4,
      "y": 10,
      "z": 5,
      "name": "Rock_Sandstone_White"
    },
    {
      "x": -4,
      "y": 11,
      "z": 5,
      "name": "Soil_Gravel_Sand"
    },
    {
      "x": -4,
      "y": 12,
      "z": 5,
      "name": "Soil_Gravel_Sand"
    },
    {
      "x": -4,
      "y": 13,
      "z": 5,
      "name": "Soil_Gravel_Sand"
    },
    {
      "x": -4,
      "y": 23,
      "z": 5,
      "name": "Soil_Gravel_Sand"
    },
    {
      "x": -4,
      "y": 24,
      "z": 5,
      "name": "Soil_Gravel_Sand_White"
    },
    {
      "x": -4,
      "y": 25,
      "z": 5,
      "name": "Soil_Gravel_Sand_White"
    },
    {
      "x": -4,
      "y": 26,
      "z": 5,
      "name": "Soil_Gravel_Sand_White"
    },
    {
      "x": -4,
      "y": 27,
      "z": 5,
      "name": "Soil_Gravel_Sand_White"
    },
    {
      "x": -4,
      "y": 28,
      "z": 5,
      "name": "Rock_Sandstone"
    },
    {
      "x": -4,
      "y": 4,
      "z": 6,
      "name": "Rock_Sandstone_White"
    },
    {
      "x": -4,
      "y": 5,
      "z": 6,
      "name": "Rock_Sandstone_White"
    },
    {
      "x": -4,
      "y": 6,
      "z": 6,
      "name": "Rock_Sandstone_White"
    },
    {
      "x": -4,
      "y": 7,
      "z": 6,
      "name": "Rock_Sandstone_White"
    },
    {
      "x": -4,
      "y": 8,
      "z": 6,
      "name": "Rock_Sandstone_White"
    },
    {
      "x": -4,
      "y": 9,
      "z": 6,
      "name": "Rock_Sandstone_White"
    },
    {
      "x": -4,
      "y": 10,
      "z": 6,
      "name": "Rock_Sandstone_White"
    },
    {
      "x": -4,
      "y": 11,
      "z": 6,
      "name": "Soil_Gravel_Sand"
    },
    {
      "x": -4,
      "y": 12,
      "z": 6,
      "name": "Soil_Gravel_Sand"
    },
    {
      "x": -4,
      "y": 13,
      "z": 6,
      "name": "Soil_Gravel_Sand"
    },
    {
      "x": -4,
      "y": 23,
      "z": 6,
      "name": "Soil_Gravel_Sand"
    },
    {
      "x": -4,
      "y": 24,
      "z": 6,
      "name": "Soil_Gravel_Sand_White"
    },
    {
      "x": -4,
      "y": 25,
      "z": 6,
      "name": "Soil_Gravel_Sand_White"
    },
    {
      "x": -4,
      "y": 26,
      "z": 6,
      "name": "Soil_Gravel_Sand_White"
    },
    {
      "x": -4,
      "y": 27,
      "z": 6,
      "name": "Soil_Gravel_Sand_White"
    },
    {
      "x": -4,
      "y": 28,
      "z": 6,
      "name": "Rock_Sandstone"
    },
    {
      "x": -4,
      "y": 5,
      "z": 7,
      "name": "Rock_Sandstone_White"
    },
    {
      "x": -4,
      "y": 6,
      "z": 7,
      "name": "Rock_Sandstone_White"
    },
    {
      "x": -4,
      "y": 7,
      "z": 7,
      "name": "Rock_Sandstone_White"
    },
    {
      "x": -4,
      "y": 8,
      "z": 7,
      "name": "Rock_Sandstone_White"
    },
    {
      "x": -4,
      "y": 9,
      "z": 7,
      "name": "Rock_Sandstone_White"
    },
    {
      "x": -4,
      "y": 10,
      "z": 7,
      "name": "Rock_Sandstone_White"
    },
    {
      "x": -4,
      "y": 11,
      "z": 7,
      "name": "Soil_Gravel_Sand"
    },
    {
      "x": -4,
      "y": 12,
      "z": 7,
      "name": "Soil_Gravel_Sand"
    },
    {
      "x": -4,
      "y": 13,
      "z": 7,
      "name": "Soil_Gravel_Sand"
    },
    {
      "x": -4,
      "y": 23,
      "z": 7,
      "name": "Soil_Gravel_Sand"
    },
    {
      "x": -4,
      "y": 24,
      "z": 7,
      "name": "Soil_Gravel_Sand_White"
    },
    {
      "x": -4,
      "y": 25,
      "z": 7,
      "name": "Soil_Gravel_Sand_White"
    },
    {
      "x": -4,
      "y": 26,
      "z": 7,
      "name": "Soil_Gravel_Sand_White"
    },
    {
      "x": -4,
      "y": 27,
      "z": 7,
      "name": "Soil_Gravel_Sand_White"
    },
    {
      "x": -4,
      "y": 28,
      "z": 7,
      "name": "Rock_Sandstone"
    },
    {
      "x": -4,
      "y": 5,
      "z": 8,
      "name": "Rock_Sandstone_White"
    },
    {
      "x": -4,
      "y": 6,
      "z": 8,
      "name": "Rock_Sandstone_White"
    },
    {
      "x": -4,
      "y": 7,
      "z": 8,
      "name": "Rock_Sandstone_White"
    },
    {
      "x": -4,
      "y": 8,
      "z": 8,
      "name": "Rock_Sandstone_White"
    },
    {
      "x": -4,
      "y": 9,
      "z": 8,
      "name": "Rock_Sandstone_White"
    },
    {
      "x": -4,
      "y": 10,
      "z": 8,
      "name": "Rock_Sandstone_White"
    },
    {
      "x": -4,
      "y": 11,
      "z": 8,
      "name": "Soil_Gravel_Sand"
    },
    {
      "x": -4,
      "y": 12,
      "z": 8,
      "name": "Soil_Gravel_Sand"
    },
    {
      "x": -4,
      "y": 25,
      "z": 8,
      "name": "Soil_Gravel_Sand_White"
    },
    {
      "x": -4,
      "y": 26,
      "z": 8,
      "name": "Soil_Gravel_Sand_White"
    },
    {
      "x": -4,
      "y": 27,
      "z": 8,
      "name": "Soil_Gravel_Sand_White"
    },
    {
      "x": -4,
      "y": 28,
      "z": 8,
      "name": "Rock_Sandstone"
    },
    {
      "x": -4,
      "y": 5,
      "z": 9,
      "name": "Rock_Sandstone_White"
    },
    {
      "x": -4,
      "y": 6,
      "z": 9,
      "name": "Rock_Sandstone_White"
    },
    {
      "x": -4,
      "y": 7,
      "z": 9,
      "name": "Rock_Sandstone_White"
    },
    {
      "x": -4,
      "y": 8,
      "z": 9,
      "name": "Rock_Sandstone_White"
    },
    {
      "x": -4,
      "y": 9,
      "z": 9,
      "name": "Rock_Sandstone_White"
    },
    {
      "x": -4,
      "y": 10,
      "z": 9,
      "name": "Soil_Sand_White"
    },
    {
      "x": -4,
      "y": 25,
      "z": 9,
      "name": "Soil_Gravel_Sand_White"
    },
    {
      "x": -4,
      "y": 26,
      "z": 9,
      "name": "Soil_Gravel_Sand_White"
    },
    {
      "x": -4,
      "y": 27,
      "z": 9,
      "name": "Soil_Gravel_Sand_White"
    },
    {
      "x": -4,
      "y": 28,
      "z": 9,
      "name": "Rock_Sandstone"
    },
    {
      "x": -4,
      "y": 7,
      "z": 10,
      "name": "Rock_Sandstone_White"
    },
    {
      "x": -4,
      "y": 8,
      "z": 10,
      "name": "Rock_Sandstone_White"
    },
    {
      "x": -4,
      "y": 9,
      "z": 10,
      "name": "Rock_Sandstone_White"
    },
    {
      "x": -4,
      "y": 10,
      "z": 10,
      "name": "Soil_Sand_White"
    },
    {
      "x": -3,
      "y": 6,
      "z": -3,
      "name": "Rock_Sandstone_White"
    },
    {
      "x": -3,
      "y": 7,
      "z": -3,
      "name": "Rock_Sandstone_White"
    },
    {
      "x": -3,
      "y": 8,
      "z": -3,
      "name": "Rock_Sandstone_White"
    },
    {
      "x": -3,
      "y": 9,
      "z": -3,
      "name": "Soil_Sand_White"
    },
    {
      "x": -3,
      "y": 11,
      "z": -3,
      "name": "Soil_Gravel_Sand"
    },
    {
      "x": -3,
      "y": 12,
      "z": -3,
      "name": "Soil_Gravel_Sand"
    },
    {
      "x": -3,
      "y": 13,
      "z": -3,
      "name": "Soil_Gravel_Sand"
    },
    {
      "x": -3,
      "y": 6,
      "z": -2,
      "name": "Rock_Sandstone_White"
    },
    {
      "x": -3,
      "y": 7,
      "z": -2,
      "name": "Rock_Sandstone_White"
    },
    {
      "x": -3,
      "y": 8,
      "z": -2,
      "name": "Rock_Sandstone_White"
    },
    {
      "x": -3,
      "y": 9,
      "z": -2,
      "name": "Soil_Sand_White"
    },
    {
      "x": -3,
      "y": 10,
      "z": -2,
      "name": "Soil_Sand_White"
    },
    {
      "x": -3,
      "y": 11,
      "z": -2,
      "name": "Soil_Gravel_Sand"
    },
    {
      "x": -3,
      "y": 12,
      "z": -2,
      "name": "Soil_Gravel_Sand"
    },
    {
      "x": -3,
      "y": 13,
      "z": -2,
      "name": "Soil_Gravel_Sand"
    },
    {
      "x": -3,
      "y": 14,
      "z": -2,
      "name": "Rock_Sandstone"
    },
    {
      "x": -3,
      "y": 27,
      "z": -2,
      "name": "Soil_Gravel_Sand_White"
    },
    {
      "x": -3,
      "y": 28,
      "z": -2,
      "name": "Rock_Sandstone"
    },
    {
      "x": -3,
      "y": 29,
      "z": -2,
      "name": "Rock_Sandstone"
    },
    {
      "x": -3,
      "y": 5,
      "z": -1,
      "name": "Rock_Sandstone_White"
    },
    {
      "x": -3,
      "y": 6,
      "z": -1,
      "name": "Rock_Sandstone_White"
    },
    {
      "x": -3,
      "y": 7,
      "z": -1,
      "name": "Rock_Sandstone_White"
    },
    {
      "x": -3,
      "y": 8,
      "z": -1,
      "name": "Rock_Sandstone_White"
    },
    {
      "x": -3,
      "y": 9,
      "z": -1,
      "name": "Rock_Sandstone_White"
    },
    {
      "x": -3,
      "y": 10,
      "z": -1,
      "name": "Soil_Sand_White"
    },
    {
      "x": -3,
      "y": 11,
      "z": -1,
      "name": "Soil_Gravel_Sand"
    },
    {
      "x": -3,
      "y": 12,
      "z": -1,
      "name": "Soil_Gravel_Sand"
    },
    {
      "x": -3,
      "y": 13,
      "z": -1,
      "name": "Soil_Gravel_Sand"
    },
    {
      "x": -3,
      "y": 14,
      "z": -1,
      "name": "Rock_Sandstone"
    },
    {
      "x": -3,
      "y": 25,
      "z": -1,
      "name": "Soil_Gravel_Sand_White"
    },
    {
      "x": -3,
      "y": 26,
      "z": -1,
      "name": "Soil_Gravel_Sand_White"
    },
    {
      "x": -3,
      "y": 27,
      "z": -1,
      "name": "Soil_Gravel_Sand_White"
    },
    {
      "x": -3,
      "y": 28,
      "z": -1,
      "name": "Rock_Sandstone"
    },
    {
      "x": -3,
      "y": 29,
      "z": -1,
      "name": "Rock_Sandstone"
    },
    {
      "x": -3,
      "y": 3,
      "z": 0,
      "name": "Rock_Sandstone_White"
    },
    {
      "x": -3,
      "y": 4,
      "z": 0,
      "name": "Rock_Sandstone_White"
    },
    {
      "x": -3,
      "y": 5,
      "z": 0,
      "name": "Rock_Sandstone_White"
    },
    {
      "x": -3,
      "y": 6,
      "z": 0,
      "name": "Rock_Sandstone_White"
    },
    {
      "x": -3,
      "y": 7,
      "z": 0,
      "name": "Rock_Sandstone_White"
    },
    {
      "x": -3,
      "y": 8,
      "z": 0,
      "name": "Rock_Sandstone_White"
    },
    {
      "x": -3,
      "y": 9,
      "z": 0,
      "name": "Rock_Sandstone_White"
    },
    {
      "x": -3,
      "y": 10,
      "z": 0,
      "name": "Rock_Sandstone_White"
    },
    {
      "x": -3,
      "y": 11,
      "z": 0,
      "name": "Soil_Gravel_Sand"
    },
    {
      "x": -3,
      "y": 12,
      "z": 0,
      "name": "Soil_Gravel_Sand"
    },
    {
      "x": -3,
      "y": 13,
      "z": 0,
      "name": "Soil_Gravel_Sand"
    },
    {
      "x": -3,
      "y": 14,
      "z": 0,
      "name": "Rock_Sandstone"
    },
    {
      "x": -3,
      "y": 25,
      "z": 0,
      "name": "Soil_Gravel_Sand_White"
    },
    {
      "x": -3,
      "y": 26,
      "z": 0,
      "name": "Soil_Gravel_Sand_White"
    },
    {
      "x": -3,
      "y": 27,
      "z": 0,
      "name": "Soil_Gravel_Sand_White"
    },
    {
      "x": -3,
      "y": 28,
      "z": 0,
      "name": "Rock_Sandstone"
    },
    {
      "x": -3,
      "y": 29,
      "z": 0,
      "name": "Rock_Sandstone"
    },
    {
      "x": -3,
      "y": 3,
      "z": 1,
      "name": "Rock_Sandstone_White"
    },
    {
      "x": -3,
      "y": 4,
      "z": 1,
      "name": "Rock_Sandstone_White"
    },
    {
      "x": -3,
      "y": 5,
      "z": 1,
      "name": "Rock_Sandstone_White"
    },
    {
      "x": -3,
      "y": 6,
      "z": 1,
      "name": "Rock_Sandstone_White"
    },
    {
      "x": -3,
      "y": 7,
      "z": 1,
      "name": "Rock_Sandstone_White"
    },
    {
      "x": -3,
      "y": 8,
      "z": 1,
      "name": "Rock_Sandstone_White"
    },
    {
      "x": -3,
      "y": 9,
      "z": 1,
      "name": "Rock_Sandstone_White"
    },
    {
      "x": -3,
      "y": 10,
      "z": 1,
      "name": "Rock_Sandstone_White"
    },
    {
      "x": -3,
      "y": 11,
      "z": 1,
      "name": "Soil_Gravel_Sand"
    },
    {
      "x": -3,
      "y": 12,
      "z": 1,
      "name": "Soil_Gravel_Sand"
    },
    {
      "x": -3,
      "y": 13,
      "z": 1,
      "name": "Soil_Gravel_Sand"
    },
    {
      "x": -3,
      "y": 23,
      "z": 1,
      "name": "Soil_Gravel_Sand"
    },
    {
      "x": -3,
      "y": 24,
      "z": 1,
      "name": "Soil_Gravel_Sand_White"
    },
    {
      "x": -3,
      "y": 25,
      "z": 1,
      "name": "Soil_Gravel_Sand_White"
    },
    {
      "x": -3,
      "y": 26,
      "z": 1,
      "name": "Soil_Gravel_Sand_White"
    },
    {
      "x": -3,
      "y": 27,
      "z": 1,
      "name": "Soil_Gravel_Sand_White"
    },
    {
      "x": -3,
      "y": 28,
      "z": 1,
      "name": "Rock_Sandstone"
    },
    {
      "x": -3,
      "y": 29,
      "z": 1,
      "name": "Rock_Sandstone"
    },
    {
      "x": -3,
      "y": 3,
      "z": 2,
      "name": "Rock_Sandstone_White"
    },
    {
      "x": -3,
      "y": 4,
      "z": 2,
      "name": "Rock_Sandstone_White"
    },
    {
      "x": -3,
      "y": 5,
      "z": 2,
      "name": "Rock_Sandstone_White"
    },
    {
      "x": -3,
      "y": 6,
      "z": 2,
      "name": "Rock_Sandstone_White"
    },
    {
      "x": -3,
      "y": 7,
      "z": 2,
      "name": "Rock_Sandstone_White"
    },
    {
      "x": -3,
      "y": 8,
      "z": 2,
      "name": "Rock_Sandstone_White"
    },
    {
      "x": -3,
      "y": 9,
      "z": 2,
      "name": "Rock_Sandstone_White"
    },
    {
      "x": -3,
      "y": 10,
      "z": 2,
      "name": "Rock_Sandstone_White"
    },
    {
      "x": -3,
      "y": 11,
      "z": 2,
      "name": "Soil_Gravel_Sand"
    },
    {
      "x": -3,
      "y": 12,
      "z": 2,
      "name": "Soil_Gravel_Sand"
    },
    {
      "x": -3,
      "y": 13,
      "z": 2,
      "name": "Soil_Gravel_Sand"
    },
    {
      "x": -3,
      "y": 23,
      "z": 2,
      "name": "Soil_Gravel_Sand"
    },
    {
      "x": -3,
      "y": 24,
      "z": 2,
      "name": "Soil_Gravel_Sand_White"
    },
    {
      "x": -3,
      "y": 25,
      "z": 2,
      "name": "Soil_Gravel_Sand_White"
    },
    {
      "x": -3,
      "y": 26,
      "z": 2,
      "name": "Soil_Gravel_Sand_White"
    },
    {
      "x": -3,
      "y": 27,
      "z": 2,
      "name": "Soil_Gravel_Sand_White"
    },
    {
      "x": -3,
      "y": 28,
      "z": 2,
      "name": "Rock_Sandstone"
    },
    {
      "x": -3,
      "y": 29,
      "z": 2,
      "name": "Rock_Sandstone"
    },
    {
      "x": -3,
      "y": 3,
      "z": 3,
      "name": "Rock_Sandstone_White"
    },
    {
      "x": -3,
      "y": 4,
      "z": 3,
      "name": "Rock_Sandstone_White"
    },
    {
      "x": -3,
      "y": 5,
      "z": 3,
      "name": "Rock_Sandstone_White"
    },
    {
      "x": -3,
      "y": 6,
      "z": 3,
      "name": "Rock_Sandstone_White"
    },
    {
      "x": -3,
      "y": 7,
      "z": 3,
      "name": "Rock_Sandstone_White"
    },
    {
      "x": -3,
      "y": 8,
      "z": 3,
      "name": "Rock_Sandstone_White"
    },
    {
      "x": -3,
      "y": 9,
      "z": 3,
      "name": "Rock_Sandstone_White"
    },
    {
      "x": -3,
      "y": 10,
      "z": 3,
      "name": "Rock_Sandstone_White"
    },
    {
      "x": -3,
      "y": 11,
      "z": 3,
      "name": "Soil_Gravel_Sand"
    },
    {
      "x": -3,
      "y": 12,
      "z": 3,
      "name": "Soil_Gravel_Sand"
    },
    {
      "x": -3,
      "y": 13,
      "z": 3,
      "name": "Soil_Gravel_Sand"
    },
    {
      "x": -3,
      "y": 23,
      "z": 3,
      "name": "Soil_Gravel_Sand"
    },
    {
      "x": -3,
      "y": 24,
      "z": 3,
      "name": "Soil_Gravel_Sand_White"
    },
    {
      "x": -3,
      "y": 25,
      "z": 3,
      "name": "Soil_Gravel_Sand_White"
    },
    {
      "x": -3,
      "y": 26,
      "z": 3,
      "name": "Soil_Gravel_Sand_White"
    },
    {
      "x": -3,
      "y": 27,
      "z": 3,
      "name": "Soil_Gravel_Sand_White"
    },
    {
      "x": -3,
      "y": 28,
      "z": 3,
      "name": "Rock_Sandstone"
    },
    {
      "x": -3,
      "y": 3,
      "z": 4,
      "name": "Rock_Sandstone_White"
    },
    {
      "x": -3,
      "y": 4,
      "z": 4,
      "name": "Rock_Sandstone_White"
    },
    {
      "x": -3,
      "y": 5,
      "z": 4,
      "name": "Rock_Sandstone_White"
    },
    {
      "x": -3,
      "y": 6,
      "z": 4,
      "name": "Rock_Sandstone_White"
    },
    {
      "x": -3,
      "y": 7,
      "z": 4,
      "name": "Rock_Sandstone_White"
    },
    {
      "x": -3,
      "y": 8,
      "z": 4,
      "name": "Rock_Sandstone_White"
    },
    {
      "x": -3,
      "y": 9,
      "z": 4,
      "name": "Rock_Sandstone_White"
    },
    {
      "x": -3,
      "y": 10,
      "z": 4,
      "name": "Rock_Sandstone_White"
    },
    {
      "x": -3,
      "y": 11,
      "z": 4,
      "name": "Soil_Gravel_Sand"
    },
    {
      "x": -3,
      "y": 12,
      "z": 4,
      "name": "Soil_Gravel_Sand"
    },
    {
      "x": -3,
      "y": 13,
      "z": 4,
      "name": "Soil_Gravel_Sand"
    },
    {
      "x": -3,
      "y": 14,
      "z": 4,
      "name": "Rock_Sandstone"
    },
    {
      "x": -3,
      "y": 23,
      "z": 4,
      "name": "Soil_Gravel_Sand"
    },
    {
      "x": -3,
      "y": 24,
      "z": 4,
      "name": "Soil_Gravel_Sand_White"
    },
    {
      "x": -3,
      "y": 25,
      "z": 4,
      "name": "Soil_Gravel_Sand_White"
    },
    {
      "x": -3,
      "y": 26,
      "z": 4,
      "name": "Soil_Gravel_Sand_White"
    },
    {
      "x": -3,
      "y": 27,
      "z": 4,
      "name": "Soil_Gravel_Sand_White"
    },
    {
      "x": -3,
      "y": 28,
      "z": 4,
      "name": "Rock_Sandstone"
    },
    {
      "x": -3,
      "y": 3,
      "z": 5,
      "name": "Rock_Sandstone_White"
    },
    {
      "x": -3,
      "y": 4,
      "z": 5,
      "name": "Rock_Sandstone_White"
    },
    {
      "x": -3,
      "y": 5,
      "z": 5,
      "name": "Rock_Sandstone_White"
    },
    {
      "x": -3,
      "y": 6,
      "z": 5,
      "name": "Rock_Sandstone_White"
    },
    {
      "x": -3,
      "y": 7,
      "z": 5,
      "name": "Rock_Sandstone_White"
    },
    {
      "x": -3,
      "y": 8,
      "z": 5,
      "name": "Rock_Sandstone_White"
    },
    {
      "x": -3,
      "y": 9,
      "z": 5,
      "name": "Rock_Sandstone_White"
    },
    {
      "x": -3,
      "y": 10,
      "z": 5,
      "name": "Rock_Sandstone_White"
    },
    {
      "x": -3,
      "y": 11,
      "z": 5,
      "name": "Soil_Gravel_Sand"
    },
    {
      "x": -3,
      "y": 12,
      "z": 5,
      "name": "Soil_Gravel_Sand"
    },
    {
      "x": -3,
      "y": 13,
      "z": 5,
      "name": "Soil_Gravel_Sand"
    },
    {
      "x": -3,
      "y": 14,
      "z": 5,
      "name": "Rock_Sandstone"
    },
    {
      "x": -3,
      "y": 23,
      "z": 5,
      "name": "Soil_Gravel_Sand"
    },
    {
      "x": -3,
      "y": 24,
      "z": 5,
      "name": "Soil_Gravel_Sand_White"
    },
    {
      "x": -3,
      "y": 25,
      "z": 5,
      "name": "Soil_Gravel_Sand_White"
    },
    {
      "x": -3,
      "y": 26,
      "z": 5,
      "name": "Soil_Gravel_Sand_White"
    },
    {
      "x": -3,
      "y": 27,
      "z": 5,
      "name": "Soil_Gravel_Sand_White"
    },
    {
      "x": -3,
      "y": 28,
      "z": 5,
      "name": "Rock_Sandstone"
    },
    {
      "x": -3,
      "y": 3,
      "z": 6,
      "name": "Rock_Sandstone_White"
    },
    {
      "x": -3,
      "y": 4,
      "z": 6,
      "name": "Rock_Sandstone_White"
    },
    {
      "x": -3,
      "y": 5,
      "z": 6,
      "name": "Rock_Sandstone_White"
    },
    {
      "x": -3,
      "y": 6,
      "z": 6,
      "name": "Rock_Sandstone_White"
    },
    {
      "x": -3,
      "y": 7,
      "z": 6,
      "name": "Rock_Sandstone_White"
    },
    {
      "x": -3,
      "y": 8,
      "z": 6,
      "name": "Rock_Sandstone_White"
    },
    {
      "x": -3,
      "y": 9,
      "z": 6,
      "name": "Rock_Sandstone_White"
    },
    {
      "x": -3,
      "y": 10,
      "z": 6,
      "name": "Rock_Sandstone_White"
    },
    {
      "x": -3,
      "y": 11,
      "z": 6,
      "name": "Soil_Gravel_Sand"
    },
    {
      "x": -3,
      "y": 12,
      "z": 6,
      "name": "Soil_Gravel_Sand"
    },
    {
      "x": -3,
      "y": 13,
      "z": 6,
      "name": "Soil_Gravel_Sand"
    },
    {
      "x": -3,
      "y": 23,
      "z": 6,
      "name": "Soil_Gravel_Sand"
    },
    {
      "x": -3,
      "y": 24,
      "z": 6,
      "name": "Soil_Gravel_Sand_White"
    },
    {
      "x": -3,
      "y": 25,
      "z": 6,
      "name": "Soil_Gravel_Sand_White"
    },
    {
      "x": -3,
      "y": 26,
      "z": 6,
      "name": "Soil_Gravel_Sand_White"
    },
    {
      "x": -3,
      "y": 27,
      "z": 6,
      "name": "Soil_Gravel_Sand_White"
    },
    {
      "x": -3,
      "y": 28,
      "z": 6,
      "name": "Rock_Sandstone"
    },
    {
      "x": -3,
      "y": 4,
      "z": 7,
      "name": "Rock_Sandstone_White"
    },
    {
      "x": -3,
      "y": 5,
      "z": 7,
      "name": "Rock_Sandstone_White"
    },
    {
      "x": -3,
      "y": 6,
      "z": 7,
      "name": "Rock_Sandstone_White"
    },
    {
      "x": -3,
      "y": 7,
      "z": 7,
      "name": "Rock_Sandstone_White"
    },
    {
      "x": -3,
      "y": 8,
      "z": 7,
      "name": "Rock_Sandstone_White"
    },
    {
      "x": -3,
      "y": 9,
      "z": 7,
      "name": "Rock_Sandstone_White"
    },
    {
      "x": -3,
      "y": 10,
      "z": 7,
      "name": "Rock_Sandstone_White"
    },
    {
      "x": -3,
      "y": 11,
      "z": 7,
      "name": "Soil_Gravel_Sand"
    },
    {
      "x": -3,
      "y": 12,
      "z": 7,
      "name": "Soil_Gravel_Sand"
    },
    {
      "x": -3,
      "y": 13,
      "z": 7,
      "name": "Soil_Gravel_Sand"
    },
    {
      "x": -3,
      "y": 23,
      "z": 7,
      "name": "Soil_Gravel_Sand"
    },
    {
      "x": -3,
      "y": 24,
      "z": 7,
      "name": "Soil_Gravel_Sand_White"
    },
    {
      "x": -3,
      "y": 25,
      "z": 7,
      "name": "Soil_Gravel_Sand_White"
    },
    {
      "x": -3,
      "y": 26,
      "z": 7,
      "name": "Soil_Gravel_Sand_White"
    },
    {
      "x": -3,
      "y": 27,
      "z": 7,
      "name": "Soil_Gravel_Sand_White"
    },
    {
      "x": -3,
      "y": 28,
      "z": 7,
      "name": "Rock_Sandstone"
    },
    {
      "x": -3,
      "y": 4,
      "z": 8,
      "name": "Rock_Sandstone_White"
    },
    {
      "x": -3,
      "y": 5,
      "z": 8,
      "name": "Rock_Sandstone_White"
    },
    {
      "x": -3,
      "y": 6,
      "z": 8,
      "name": "Rock_Sandstone_White"
    },
    {
      "x": -3,
      "y": 7,
      "z": 8,
      "name": "Rock_Sandstone_White"
    },
    {
      "x": -3,
      "y": 8,
      "z": 8,
      "name": "Rock_Sandstone_White"
    },
    {
      "x": -3,
      "y": 9,
      "z": 8,
      "name": "Rock_Sandstone_White"
    },
    {
      "x": -3,
      "y": 10,
      "z": 8,
      "name": "Rock_Sandstone_White"
    },
    {
      "x": -3,
      "y": 11,
      "z": 8,
      "name": "Soil_Gravel_Sand"
    },
    {
      "x": -3,
      "y": 12,
      "z": 8,
      "name": "Soil_Gravel_Sand"
    },
    {
      "x": -3,
      "y": 13,
      "z": 8,
      "name": "Soil_Gravel_Sand"
    },
    {
      "x": -3,
      "y": 25,
      "z": 8,
      "name": "Soil_Gravel_Sand_White"
    },
    {
      "x": -3,
      "y": 26,
      "z": 8,
      "name": "Soil_Gravel_Sand_White"
    },
    {
      "x": -3,
      "y": 27,
      "z": 8,
      "name": "Soil_Gravel_Sand_White"
    },
    {
      "x": -3,
      "y": 28,
      "z": 8,
      "name": "Rock_Sandstone"
    },
    {
      "x": -3,
      "y": 5,
      "z": 9,
      "name": "Rock_Sandstone_White"
    },
    {
      "x": -3,
      "y": 6,
      "z": 9,
      "name": "Rock_Sandstone_White"
    },
    {
      "x": -3,
      "y": 7,
      "z": 9,
      "name": "Rock_Sandstone_White"
    },
    {
      "x": -3,
      "y": 8,
      "z": 9,
      "name": "Rock_Sandstone_White"
    },
    {
      "x": -3,
      "y": 9,
      "z": 9,
      "name": "Rock_Sandstone_White"
    },
    {
      "x": -3,
      "y": 10,
      "z": 9,
      "name": "Soil_Sand_White"
    },
    {
      "x": -3,
      "y": 11,
      "z": 9,
      "name": "Soil_Gravel_Sand"
    },
    {
      "x": -3,
      "y": 25,
      "z": 9,
      "name": "Soil_Gravel_Sand_White"
    },
    {
      "x": -3,
      "y": 26,
      "z": 9,
      "name": "Soil_Gravel_Sand_White"
    },
    {
      "x": -3,
      "y": 27,
      "z": 9,
      "name": "Soil_Gravel_Sand_White"
    },
    {
      "x": -3,
      "y": 28,
      "z": 9,
      "name": "Rock_Sandstone"
    },
    {
      "x": -3,
      "y": 6,
      "z": 10,
      "name": "Rock_Sandstone_White"
    },
    {
      "x": -3,
      "y": 7,
      "z": 10,
      "name": "Rock_Sandstone_White"
    },
    {
      "x": -3,
      "y": 8,
      "z": 10,
      "name": "Rock_Sandstone_White"
    },
    {
      "x": -3,
      "y": 9,
      "z": 10,
      "name": "Rock_Sandstone_White"
    },
    {
      "x": -3,
      "y": 10,
      "z": 10,
      "name": "Soil_Sand_White"
    },
    {
      "x": -3,
      "y": 8,
      "z": 11,
      "name": "Rock_Sandstone_White"
    },
    {
      "x": -3,
      "y": 9,
      "z": 11,
      "name": "Rock_Sandstone_White"
    },
    {
      "x": -3,
      "y": 10,
      "z": 11,
      "name": "Soil_Sand_White"
    },
    {
      "x": -2,
      "y": 6,
      "z": -5,
      "name": "Rock_Sandstone_White"
    },
    {
      "x": -2,
      "y": 7,
      "z": -5,
      "name": "Rock_Sandstone_White"
    },
    {
      "x": -2,
      "y": 8,
      "z": -5,
      "name": "Rock_Sandstone_White"
    },
    {
      "x": -2,
      "y": 9,
      "z": -5,
      "name": "Soil_Sand_White"
    },
    {
      "x": -2,
      "y": 11,
      "z": -5,
      "name": "Soil_Gravel_Sand"
    },
    {
      "x": -2,
      "y": 12,
      "z": -5,
      "name": "Soil_Gravel_Sand"
    },
    {
      "x": -2,
      "y": 13,
      "z": -5,
      "name": "Soil_Gravel_Sand"
    },
    {
      "x": -2,
      "y": 5,
      "z": -4,
      "name": "Rock_Sandstone_White"
    },
    {
      "x": -2,
      "y": 6,
      "z": -4,
      "name": "Rock_Sandstone_White"
    },
    {
      "x": -2,
      "y": 7,
      "z": -4,
      "name": "Rock_Sandstone_White"
    },
    {
      "x": -2,
      "y": 8,
      "z": -4,
      "name": "Rock_Sandstone_White"
    },
    {
      "x": -2,
      "y": 9,
      "z": -4,
      "name": "Soil_Sand_White"
    },
    {
      "x": -2,
      "y": 11,
      "z": -4,
      "name": "Soil_Gravel_Sand"
    },
    {
      "x": -2,
      "y": 12,
      "z": -4,
      "name": "Soil_Gravel_Sand"
    },
    {
      "x": -2,
      "y": 13,
      "z": -4,
      "name": "Soil_Gravel_Sand"
    },
    {
      "x": -2,
      "y": 14,
      "z": -4,
      "name": "Rock_Sandstone"
    },
    {
      "x": -2,
      "y": 26,
      "z": -4,
      "name": "Soil_Gravel_Sand_White"
    },
    {
      "x": -2,
      "y": 27,
      "z": -4,
      "name": "Soil_Gravel_Sand_White"
    },
    {
      "x": -2,
      "y": 28,
      "z": -4,
      "name": "Rock_Sandstone"
    },
    {
      "x": -2,
      "y": 29,
      "z": -4,
      "name": "Rock_Sandstone"
    },
    {
      "x": -2,
      "y": 5,
      "z": -3,
      "name": "Rock_Sandstone_White"
    },
    {
      "x": -2,
      "y": 6,
      "z": -3,
      "name": "Rock_Sandstone_White"
    },
    {
      "x": -2,
      "y": 7,
      "z": -3,
      "name": "Rock_Sandstone_White"
    },
    {
      "x": -2,
      "y": 8,
      "z": -3,
      "name": "Rock_Sandstone_White"
    },
    {
      "x": -2,
      "y": 9,
      "z": -3,
      "name": "Rock_Sandstone_White"
    },
    {
      "x": -2,
      "y": 10,
      "z": -3,
      "name": "Rock_Sandstone_White"
    },
    {
      "x": -2,
      "y": 11,
      "z": -3,
      "name": "Soil_Gravel_Sand"
    },
    {
      "x": -2,
      "y": 12,
      "z": -3,
      "name": "Soil_Gravel_Sand"
    },
    {
      "x": -2,
      "y": 13,
      "z": -3,
      "name": "Soil_Gravel_Sand"
    },
    {
      "x": -2,
      "y": 14,
      "z": -3,
      "name": "Rock_Sandstone"
    },
    {
      "x": -2,
      "y": 21,
      "z": -3,
      "name": "Rock_Sandstone"
    },
    {
      "x": -2,
      "y": 22,
      "z": -3,
      "name": "Rock_Sandstone"
    },
    {
      "x": -2,
      "y": 23,
      "z": -3,
      "name": "Soil_Gravel_Sand"
    },
    {
      "x": -2,
      "y": 26,
      "z": -3,
      "name": "Soil_Gravel_Sand_White"
    },
    {
      "x": -2,
      "y": 27,
      "z": -3,
      "name": "Soil_Gravel_Sand_White"
    },
    {
      "x": -2,
      "y": 28,
      "z": -3,
      "name": "Rock_Sandstone"
    },
    {
      "x": -2,
      "y": 29,
      "z": -3,
      "name": "Rock_Sandstone"
    },
    {
      "x": -2,
      "y": 5,
      "z": -2,
      "name": "Rock_Sandstone_White"
    },
    {
      "x": -2,
      "y": 6,
      "z": -2,
      "name": "Rock_Sandstone_White"
    },
    {
      "x": -2,
      "y": 7,
      "z": -2,
      "name": "Rock_Sandstone_White"
    },
    {
      "x": -2,
      "y": 8,
      "z": -2,
      "name": "Rock_Sandstone_White"
    },
    {
      "x": -2,
      "y": 9,
      "z": -2,
      "name": "Rock_Sandstone_White"
    },
    {
      "x": -2,
      "y": 10,
      "z": -2,
      "name": "Rock_Sandstone_White"
    },
    {
      "x": -2,
      "y": 11,
      "z": -2,
      "name": "Soil_Gravel_Sand"
    },
    {
      "x": -2,
      "y": 12,
      "z": -2,
      "name": "Soil_Gravel_Sand"
    },
    {
      "x": -2,
      "y": 13,
      "z": -2,
      "name": "Soil_Gravel_Sand"
    },
    {
      "x": -2,
      "y": 14,
      "z": -2,
      "name": "Rock_Sandstone"
    },
    {
      "x": -2,
      "y": 21,
      "z": -2,
      "name": "Rock_Sandstone"
    },
    {
      "x": -2,
      "y": 22,
      "z": -2,
      "name": "Rock_Sandstone"
    },
    {
      "x": -2,
      "y": 23,
      "z": -2,
      "name": "Soil_Gravel_Sand"
    },
    {
      "x": -2,
      "y": 25,
      "z": -2,
      "name": "Soil_Gravel_Sand_White"
    },
    {
      "x": -2,
      "y": 26,
      "z": -2,
      "name": "Soil_Gravel_Sand_White"
    },
    {
      "x": -2,
      "y": 27,
      "z": -2,
      "name": "Soil_Gravel_Sand_White"
    },
    {
      "x": -2,
      "y": 28,
      "z": -2,
      "name": "Rock_Sandstone"
    },
    {
      "x": -2,
      "y": 29,
      "z": -2,
      "name": "Rock_Sandstone"
    },
    {
      "x": -2,
      "y": 4,
      "z": -1,
      "name": "Rock_Sandstone_White"
    },
    {
      "x": -2,
      "y": 5,
      "z": -1,
      "name": "Rock_Sandstone_White"
    },
    {
      "x": -2,
      "y": 6,
      "z": -1,
      "name": "Rock_Sandstone_White"
    },
    {
      "x": -2,
      "y": 7,
      "z": -1,
      "name": "Rock_Sandstone_White"
    },
    {
      "x": -2,
      "y": 8,
      "z": -1,
      "name": "Rock_Sandstone_White"
    },
    {
      "x": -2,
      "y": 9,
      "z": -1,
      "name": "Rock_Sandstone_White"
    },
    {
      "x": -2,
      "y": 10,
      "z": -1,
      "name": "Rock_Sandstone_White"
    },
    {
      "x": -2,
      "y": 11,
      "z": -1,
      "name": "Soil_Gravel_Sand"
    },
    {
      "x": -2,
      "y": 12,
      "z": -1,
      "name": "Soil_Gravel_Sand"
    },
    {
      "x": -2,
      "y": 13,
      "z": -1,
      "name": "Soil_Gravel_Sand"
    },
    {
      "x": -2,
      "y": 14,
      "z": -1,
      "name": "Rock_Sandstone"
    },
    {
      "x": -2,
      "y": 21,
      "z": -1,
      "name": "Rock_Sandstone"
    },
    {
      "x": -2,
      "y": 22,
      "z": -1,
      "name": "Rock_Sandstone"
    },
    {
      "x": -2,
      "y": 23,
      "z": -1,
      "name": "Soil_Gravel_Sand"
    },
    {
      "x": -2,
      "y": 25,
      "z": -1,
      "name": "Soil_Gravel_Sand_White"
    },
    {
      "x": -2,
      "y": 26,
      "z": -1,
      "name": "Soil_Gravel_Sand_White"
    },
    {
      "x": -2,
      "y": 27,
      "z": -1,
      "name": "Soil_Gravel_Sand_White"
    },
    {
      "x": -2,
      "y": 28,
      "z": -1,
      "name": "Rock_Sandstone"
    },
    {
      "x": -2,
      "y": 29,
      "z": -1,
      "name": "Rock_Sandstone"
    },
    {
      "x": -2,
      "y": 3,
      "z": 0,
      "name": "Rock_Sandstone_White"
    },
    {
      "x": -2,
      "y": 4,
      "z": 0,
      "name": "Rock_Sandstone_White"
    },
    {
      "x": -2,
      "y": 5,
      "z": 0,
      "name": "Rock_Sandstone_White"
    },
    {
      "x": -2,
      "y": 6,
      "z": 0,
      "name": "Rock_Sandstone_White"
    },
    {
      "x": -2,
      "y": 7,
      "z": 0,
      "name": "Rock_Sandstone_White"
    },
    {
      "x": -2,
      "y": 8,
      "z": 0,
      "name": "Rock_Sandstone_White"
    },
    {
      "x": -2,
      "y": 9,
      "z": 0,
      "name": "Rock_Sandstone_White"
    },
    {
      "x": -2,
      "y": 10,
      "z": 0,
      "name": "Rock_Sandstone_White"
    },
    {
      "x": -2,
      "y": 11,
      "z": 0,
      "name": "Soil_Gravel_Sand"
    },
    {
      "x": -2,
      "y": 12,
      "z": 0,
      "name": "Soil_Gravel_Sand"
    },
    {
      "x": -2,
      "y": 13,
      "z": 0,
      "name": "Soil_Gravel_Sand"
    },
    {
      "x": -2,
      "y": 14,
      "z": 0,
      "name": "Rock_Sandstone"
    },
    {
      "x": -2,
      "y": 21,
      "z": 0,
      "name": "Rock_Sandstone"
    },
    {
      "x": -2,
      "y": 22,
      "z": 0,
      "name": "Rock_Sandstone"
    },
    {
      "x": -2,
      "y": 25,
      "z": 0,
      "name": "Soil_Gravel_Sand_White"
    },
    {
      "x": -2,
      "y": 26,
      "z": 0,
      "name": "Soil_Gravel_Sand_White"
    },
    {
      "x": -2,
      "y": 27,
      "z": 0,
      "name": "Soil_Gravel_Sand_White"
    },
    {
      "x": -2,
      "y": 28,
      "z": 0,
      "name": "Rock_Sandstone"
    },
    {
      "x": -2,
      "y": 29,
      "z": 0,
      "name": "Rock_Sandstone"
    },
    {
      "x": -2,
      "y": 3,
      "z": 1,
      "name": "Rock_Sandstone_White"
    },
    {
      "x": -2,
      "y": 4,
      "z": 1,
      "name": "Rock_Sandstone_White"
    },
    {
      "x": -2,
      "y": 5,
      "z": 1,
      "name": "Rock_Sandstone_White"
    },
    {
      "x": -2,
      "y": 6,
      "z": 1,
      "name": "Rock_Sandstone_White"
    },
    {
      "x": -2,
      "y": 7,
      "z": 1,
      "name": "Rock_Sandstone_White"
    },
    {
      "x": -2,
      "y": 8,
      "z": 1,
      "name": "Rock_Sandstone_White"
    },
    {
      "x": -2,
      "y": 9,
      "z": 1,
      "name": "Rock_Sandstone_White"
    },
    {
      "x": -2,
      "y": 10,
      "z": 1,
      "name": "Rock_Sandstone_White"
    },
    {
      "x": -2,
      "y": 11,
      "z": 1,
      "name": "Soil_Gravel_Sand"
    },
    {
      "x": -2,
      "y": 12,
      "z": 1,
      "name": "Soil_Gravel_Sand"
    },
    {
      "x": -2,
      "y": 13,
      "z": 1,
      "name": "Soil_Gravel_Sand"
    },
    {
      "x": -2,
      "y": 14,
      "z": 1,
      "name": "Rock_Sandstone"
    },
    {
      "x": -2,
      "y": 21,
      "z": 1,
      "name": "Rock_Sandstone"
    },
    {
      "x": -2,
      "y": 22,
      "z": 1,
      "name": "Rock_Sandstone"
    },
    {
      "x": -2,
      "y": 23,
      "z": 1,
      "name": "Soil_Gravel_Sand"
    },
    {
      "x": -2,
      "y": 24,
      "z": 1,
      "name": "Soil_Gravel_Sand_White"
    },
    {
      "x": -2,
      "y": 25,
      "z": 1,
      "name": "Soil_Gravel_Sand_White"
    },
    {
      "x": -2,
      "y": 26,
      "z": 1,
      "name": "Soil_Gravel_Sand_White"
    },
    {
      "x": -2,
      "y": 27,
      "z": 1,
      "name": "Soil_Gravel_Sand_White"
    },
    {
      "x": -2,
      "y": 28,
      "z": 1,
      "name": "Rock_Sandstone"
    },
    {
      "x": -2,
      "y": 29,
      "z": 1,
      "name": "Rock_Sandstone"
    },
    {
      "x": -2,
      "y": 3,
      "z": 2,
      "name": "Rock_Sandstone_White"
    },
    {
      "x": -2,
      "y": 4,
      "z": 2,
      "name": "Rock_Sandstone_White"
    },
    {
      "x": -2,
      "y": 5,
      "z": 2,
      "name": "Rock_Sandstone_White"
    },
    {
      "x": -2,
      "y": 6,
      "z": 2,
      "name": "Rock_Sandstone_White"
    },
    {
      "x": -2,
      "y": 7,
      "z": 2,
      "name": "Rock_Sandstone_White"
    },
    {
      "x": -2,
      "y": 8,
      "z": 2,
      "name": "Rock_Sandstone_White"
    },
    {
      "x": -2,
      "y": 9,
      "z": 2,
      "name": "Rock_Sandstone_White"
    },
    {
      "x": -2,
      "y": 10,
      "z": 2,
      "name": "Rock_Sandstone_White"
    },
    {
      "x": -2,
      "y": 11,
      "z": 2,
      "name": "Soil_Gravel_Sand"
    },
    {
      "x": -2,
      "y": 12,
      "z": 2,
      "name": "Soil_Gravel_Sand"
    },
    {
      "x": -2,
      "y": 13,
      "z": 2,
      "name": "Soil_Gravel_Sand"
    },
    {
      "x": -2,
      "y": 14,
      "z": 2,
      "name": "Rock_Sandstone"
    },
    {
      "x": -2,
      "y": 23,
      "z": 2,
      "name": "Soil_Gravel_Sand"
    },
    {
      "x": -2,
      "y": 24,
      "z": 2,
      "name": "Soil_Gravel_Sand_White"
    },
    {
      "x": -2,
      "y": 25,
      "z": 2,
      "name": "Soil_Gravel_Sand_White"
    },
    {
      "x": -2,
      "y": 26,
      "z": 2,
      "name": "Soil_Gravel_Sand_White"
    },
    {
      "x": -2,
      "y": 27,
      "z": 2,
      "name": "Soil_Gravel_Sand_White"
    },
    {
      "x": -2,
      "y": 28,
      "z": 2,
      "name": "Rock_Sandstone"
    },
    {
      "x": -2,
      "y": 29,
      "z": 2,
      "name": "Rock_Sandstone"
    },
    {
      "x": -2,
      "y": 3,
      "z": 3,
      "name": "Rock_Sandstone_White"
    },
    {
      "x": -2,
      "y": 4,
      "z": 3,
      "name": "Rock_Sandstone_White"
    },
    {
      "x": -2,
      "y": 5,
      "z": 3,
      "name": "Rock_Sandstone_White"
    },
    {
      "x": -2,
      "y": 6,
      "z": 3,
      "name": "Rock_Sandstone_White"
    },
    {
      "x": -2,
      "y": 7,
      "z": 3,
      "name": "Rock_Sandstone_White"
    },
    {
      "x": -2,
      "y": 8,
      "z": 3,
      "name": "Rock_Sandstone_White"
    },
    {
      "x": -2,
      "y": 9,
      "z": 3,
      "name": "Rock_Sandstone_White"
    },
    {
      "x": -2,
      "y": 10,
      "z": 3,
      "name": "Rock_Sandstone_White"
    },
    {
      "x": -2,
      "y": 11,
      "z": 3,
      "name": "Soil_Gravel_Sand"
    },
    {
      "x": -2,
      "y": 12,
      "z": 3,
      "name": "Soil_Gravel_Sand"
    },
    {
      "x": -2,
      "y": 13,
      "z": 3,
      "name": "Soil_Gravel_Sand"
    },
    {
      "x": -2,
      "y": 14,
      "z": 3,
      "name": "Rock_Sandstone"
    },
    {
      "x": -2,
      "y": 23,
      "z": 3,
      "name": "Soil_Gravel_Sand"
    },
    {
      "x": -2,
      "y": 24,
      "z": 3,
      "name": "Soil_Gravel_Sand_White"
    },
    {
      "x": -2,
      "y": 25,
      "z": 3,
      "name": "Soil_Gravel_Sand_White"
    },
    {
      "x": -2,
      "y": 26,
      "z": 3,
      "name": "Soil_Gravel_Sand_White"
    },
    {
      "x": -2,
      "y": 27,
      "z": 3,
      "name": "Soil_Gravel_Sand_White"
    },
    {
      "x": -2,
      "y": 28,
      "z": 3,
      "name": "Rock_Sandstone"
    },
    {
      "x": -2,
      "y": 29,
      "z": 3,
      "name": "Rock_Sandstone"
    },
    {
      "x": -2,
      "y": 3,
      "z": 4,
      "name": "Rock_Sandstone_White"
    },
    {
      "x": -2,
      "y": 4,
      "z": 4,
      "name": "Rock_Sandstone_White"
    },
    {
      "x": -2,
      "y": 5,
      "z": 4,
      "name": "Rock_Sandstone_White"
    },
    {
      "x": -2,
      "y": 6,
      "z": 4,
      "name": "Rock_Sandstone_White"
    },
    {
      "x": -2,
      "y": 7,
      "z": 4,
      "name": "Rock_Sandstone_White"
    },
    {
      "x": -2,
      "y": 8,
      "z": 4,
      "name": "Rock_Sandstone_White"
    },
    {
      "x": -2,
      "y": 9,
      "z": 4,
      "name": "Rock_Sandstone_White"
    },
    {
      "x": -2,
      "y": 10,
      "z": 4,
      "name": "Rock_Sandstone_White"
    },
    {
      "x": -2,
      "y": 11,
      "z": 4,
      "name": "Soil_Gravel_Sand"
    },
    {
      "x": -2,
      "y": 12,
      "z": 4,
      "name": "Soil_Gravel_Sand"
    },
    {
      "x": -2,
      "y": 13,
      "z": 4,
      "name": "Soil_Gravel_Sand"
    },
    {
      "x": -2,
      "y": 14,
      "z": 4,
      "name": "Rock_Sandstone"
    },
    {
      "x": -2,
      "y": 23,
      "z": 4,
      "name": "Soil_Gravel_Sand"
    },
    {
      "x": -2,
      "y": 24,
      "z": 4,
      "name": "Soil_Gravel_Sand_White"
    },
    {
      "x": -2,
      "y": 25,
      "z": 4,
      "name": "Soil_Gravel_Sand_White"
    },
    {
      "x": -2,
      "y": 26,
      "z": 4,
      "name": "Soil_Gravel_Sand_White"
    },
    {
      "x": -2,
      "y": 27,
      "z": 4,
      "name": "Soil_Gravel_Sand_White"
    },
    {
      "x": -2,
      "y": 28,
      "z": 4,
      "name": "Rock_Sandstone"
    },
    {
      "x": -2,
      "y": 29,
      "z": 4,
      "name": "Rock_Sandstone"
    },
    {
      "x": -2,
      "y": 3,
      "z": 5,
      "name": "Rock_Sandstone_White"
    },
    {
      "x": -2,
      "y": 4,
      "z": 5,
      "name": "Rock_Sandstone_White"
    },
    {
      "x": -2,
      "y": 5,
      "z": 5,
      "name": "Rock_Sandstone_White"
    },
    {
      "x": -2,
      "y": 6,
      "z": 5,
      "name": "Rock_Sandstone_White"
    },
    {
      "x": -2,
      "y": 7,
      "z": 5,
      "name": "Rock_Sandstone_White"
    },
    {
      "x": -2,
      "y": 8,
      "z": 5,
      "name": "Rock_Sandstone_White"
    },
    {
      "x": -2,
      "y": 9,
      "z": 5,
      "name": "Rock_Sandstone_White"
    },
    {
      "x": -2,
      "y": 10,
      "z": 5,
      "name": "Rock_Sandstone_White"
    },
    {
      "x": -2,
      "y": 11,
      "z": 5,
      "name": "Soil_Gravel_Sand"
    },
    {
      "x": -2,
      "y": 12,
      "z": 5,
      "name": "Soil_Gravel_Sand"
    },
    {
      "x": -2,
      "y": 13,
      "z": 5,
      "name": "Soil_Gravel_Sand"
    },
    {
      "x": -2,
      "y": 14,
      "z": 5,
      "name": "Rock_Sandstone"
    },
    {
      "x": -2,
      "y": 23,
      "z": 5,
      "name": "Soil_Gravel_Sand"
    },
    {
      "x": -2,
      "y": 24,
      "z": 5,
      "name": "Soil_Gravel_Sand_White"
    },
    {
      "x": -2,
      "y": 25,
      "z": 5,
      "name": "Soil_Gravel_Sand_White"
    },
    {
      "x": -2,
      "y": 26,
      "z": 5,
      "name": "Soil_Gravel_Sand_White"
    },
    {
      "x": -2,
      "y": 27,
      "z": 5,
      "name": "Soil_Gravel_Sand_White"
    },
    {
      "x": -2,
      "y": 28,
      "z": 5,
      "name": "Rock_Sandstone"
    },
    {
      "x": -2,
      "y": 3,
      "z": 6,
      "name": "Rock_Sandstone_White"
    },
    {
      "x": -2,
      "y": 4,
      "z": 6,
      "name": "Rock_Sandstone_White"
    },
    {
      "x": -2,
      "y": 5,
      "z": 6,
      "name": "Rock_Sandstone_White"
    },
    {
      "x": -2,
      "y": 6,
      "z": 6,
      "name": "Rock_Sandstone_White"
    },
    {
      "x": -2,
      "y": 7,
      "z": 6,
      "name": "Rock_Sandstone_White"
    },
    {
      "x": -2,
      "y": 8,
      "z": 6,
      "name": "Rock_Sandstone_White"
    },
    {
      "x": -2,
      "y": 9,
      "z": 6,
      "name": "Rock_Sandstone_White"
    },
    {
      "x": -2,
      "y": 10,
      "z": 6,
      "name": "Rock_Sandstone_White"
    },
    {
      "x": -2,
      "y": 11,
      "z": 6,
      "name": "Soil_Gravel_Sand"
    },
    {
      "x": -2,
      "y": 12,
      "z": 6,
      "name": "Soil_Gravel_Sand"
    },
    {
      "x": -2,
      "y": 13,
      "z": 6,
      "name": "Soil_Gravel_Sand"
    },
    {
      "x": -2,
      "y": 14,
      "z": 6,
      "name": "Rock_Sandstone"
    },
    {
      "x": -2,
      "y": 23,
      "z": 6,
      "name": "Soil_Gravel_Sand"
    },
    {
      "x": -2,
      "y": 24,
      "z": 6,
      "name": "Soil_Gravel_Sand_White"
    },
    {
      "x": -2,
      "y": 25,
      "z": 6,
      "name": "Soil_Gravel_Sand_White"
    },
    {
      "x": -2,
      "y": 26,
      "z": 6,
      "name": "Soil_Gravel_Sand_White"
    },
    {
      "x": -2,
      "y": 27,
      "z": 6,
      "name": "Soil_Gravel_Sand_White"
    },
    {
      "x": -2,
      "y": 28,
      "z": 6,
      "name": "Rock_Sandstone"
    },
    {
      "x": -2,
      "y": 4,
      "z": 7,
      "name": "Rock_Sandstone_White"
    },
    {
      "x": -2,
      "y": 5,
      "z": 7,
      "name": "Rock_Sandstone_White"
    },
    {
      "x": -2,
      "y": 6,
      "z": 7,
      "name": "Rock_Sandstone_White"
    },
    {
      "x": -2,
      "y": 7,
      "z": 7,
      "name": "Rock_Sandstone_White"
    },
    {
      "x": -2,
      "y": 8,
      "z": 7,
      "name": "Rock_Sandstone_White"
    },
    {
      "x": -2,
      "y": 9,
      "z": 7,
      "name": "Rock_Sandstone_White"
    },
    {
      "x": -2,
      "y": 10,
      "z": 7,
      "name": "Rock_Sandstone_White"
    },
    {
      "x": -2,
      "y": 11,
      "z": 7,
      "name": "Soil_Gravel_Sand"
    },
    {
      "x": -2,
      "y": 12,
      "z": 7,
      "name": "Soil_Gravel_Sand"
    },
    {
      "x": -2,
      "y": 13,
      "z": 7,
      "name": "Soil_Gravel_Sand"
    },
    {
      "x": -2,
      "y": 23,
      "z": 7,
      "name": "Soil_Gravel_Sand"
    },
    {
      "x": -2,
      "y": 24,
      "z": 7,
      "name": "Soil_Gravel_Sand_White"
    },
    {
      "x": -2,
      "y": 25,
      "z": 7,
      "name": "Soil_Gravel_Sand_White"
    },
    {
      "x": -2,
      "y": 26,
      "z": 7,
      "name": "Soil_Gravel_Sand_White"
    },
    {
      "x": -2,
      "y": 27,
      "z": 7,
      "name": "Soil_Gravel_Sand_White"
    },
    {
      "x": -2,
      "y": 28,
      "z": 7,
      "name": "Rock_Sandstone"
    },
    {
      "x": -2,
      "y": 4,
      "z": 8,
      "name": "Rock_Sandstone_White"
    },
    {
      "x": -2,
      "y": 5,
      "z": 8,
      "name": "Rock_Sandstone_White"
    },
    {
      "x": -2,
      "y": 6,
      "z": 8,
      "name": "Rock_Sandstone_White"
    },
    {
      "x": -2,
      "y": 7,
      "z": 8,
      "name": "Rock_Sandstone_White"
    },
    {
      "x": -2,
      "y": 8,
      "z": 8,
      "name": "Rock_Sandstone_White"
    },
    {
      "x": -2,
      "y": 9,
      "z": 8,
      "name": "Rock_Sandstone_White"
    },
    {
      "x": -2,
      "y": 10,
      "z": 8,
      "name": "Rock_Sandstone_White"
    },
    {
      "x": -2,
      "y": 11,
      "z": 8,
      "name": "Soil_Gravel_Sand"
    },
    {
      "x": -2,
      "y": 12,
      "z": 8,
      "name": "Soil_Gravel_Sand"
    },
    {
      "x": -2,
      "y": 13,
      "z": 8,
      "name": "Soil_Gravel_Sand"
    },
    {
      "x": -2,
      "y": 23,
      "z": 8,
      "name": "Soil_Gravel_Sand"
    },
    {
      "x": -2,
      "y": 24,
      "z": 8,
      "name": "Soil_Gravel_Sand_White"
    },
    {
      "x": -2,
      "y": 25,
      "z": 8,
      "name": "Soil_Gravel_Sand_White"
    },
    {
      "x": -2,
      "y": 26,
      "z": 8,
      "name": "Soil_Gravel_Sand_White"
    },
    {
      "x": -2,
      "y": 27,
      "z": 8,
      "name": "Soil_Gravel_Sand_White"
    },
    {
      "x": -2,
      "y": 28,
      "z": 8,
      "name": "Rock_Sandstone"
    },
    {
      "x": -2,
      "y": 4,
      "z": 9,
      "name": "Rock_Sandstone_White"
    },
    {
      "x": -2,
      "y": 5,
      "z": 9,
      "name": "Rock_Sandstone_White"
    },
    {
      "x": -2,
      "y": 6,
      "z": 9,
      "name": "Rock_Sandstone_White"
    },
    {
      "x": -2,
      "y": 7,
      "z": 9,
      "name": "Rock_Sandstone_White"
    },
    {
      "x": -2,
      "y": 8,
      "z": 9,
      "name": "Rock_Sandstone_White"
    },
    {
      "x": -2,
      "y": 9,
      "z": 9,
      "name": "Rock_Sandstone_White"
    },
    {
      "x": -2,
      "y": 10,
      "z": 9,
      "name": "Rock_Sandstone_White"
    },
    {
      "x": -2,
      "y": 11,
      "z": 9,
      "name": "Soil_Gravel_Sand"
    },
    {
      "x": -2,
      "y": 12,
      "z": 9,
      "name": "Soil_Gravel_Sand"
    },
    {
      "x": -2,
      "y": 25,
      "z": 9,
      "name": "Soil_Gravel_Sand_White"
    },
    {
      "x": -2,
      "y": 26,
      "z": 9,
      "name": "Soil_Gravel_Sand_White"
    },
    {
      "x": -2,
      "y": 27,
      "z": 9,
      "name": "Soil_Gravel_Sand_White"
    },
    {
      "x": -2,
      "y": 28,
      "z": 9,
      "name": "Rock_Sandstone"
    },
    {
      "x": -2,
      "y": 6,
      "z": 10,
      "name": "Rock_Sandstone_White"
    },
    {
      "x": -2,
      "y": 7,
      "z": 10,
      "name": "Rock_Sandstone_White"
    },
    {
      "x": -2,
      "y": 8,
      "z": 10,
      "name": "Rock_Sandstone_White"
    },
    {
      "x": -2,
      "y": 9,
      "z": 10,
      "name": "Rock_Sandstone_White"
    },
    {
      "x": -2,
      "y": 10,
      "z": 10,
      "name": "Soil_Sand_White"
    },
    {
      "x": -2,
      "y": 25,
      "z": 10,
      "name": "Soil_Gravel_Sand_White"
    },
    {
      "x": -2,
      "y": 26,
      "z": 10,
      "name": "Soil_Gravel_Sand_White"
    },
    {
      "x": -2,
      "y": 27,
      "z": 10,
      "name": "Soil_Gravel_Sand_White"
    },
    {
      "x": -2,
      "y": 28,
      "z": 10,
      "name": "Rock_Sandstone"
    },
    {
      "x": -2,
      "y": 7,
      "z": 11,
      "name": "Rock_Sandstone_White"
    },
    {
      "x": -2,
      "y": 8,
      "z": 11,
      "name": "Rock_Sandstone_White"
    },
    {
      "x": -2,
      "y": 9,
      "z": 11,
      "name": "Rock_Sandstone_White"
    },
    {
      "x": -2,
      "y": 10,
      "z": 11,
      "name": "Soil_Sand_White"
    },
    {
      "x": -1,
      "y": 5,
      "z": -6,
      "name": "Rock_Sandstone_White"
    },
    {
      "x": -1,
      "y": 6,
      "z": -6,
      "name": "Rock_Sandstone_White"
    },
    {
      "x": -1,
      "y": 7,
      "z": -6,
      "name": "Rock_Sandstone_White"
    },
    {
      "x": -1,
      "y": 8,
      "z": -6,
      "name": "Rock_Sandstone_White"
    },
    {
      "x": -1,
      "y": 9,
      "z": -6,
      "name": "Soil_Sand_White"
    },
    {
      "x": -1,
      "y": 12,
      "z": -6,
      "name": "Soil_Gravel_Sand"
    },
    {
      "x": -1,
      "y": 13,
      "z": -6,
      "name": "Soil_Gravel_Sand"
    },
    {
      "x": -1,
      "y": 26,
      "z": -6,
      "name": "Soil_Gravel_Sand_White"
    },
    {
      "x": -1,
      "y": 27,
      "z": -6,
      "name": "Soil_Gravel_Sand_White"
    },
    {
      "x": -1,
      "y": 28,
      "z": -6,
      "name": "Rock_Sandstone"
    },
    {
      "x": -1,
      "y": 4,
      "z": -5,
      "name": "Rock_Sandstone_White"
    },
    {
      "x": -1,
      "y": 5,
      "z": -5,
      "name": "Rock_Sandstone_White"
    },
    {
      "x": -1,
      "y": 6,
      "z": -5,
      "name": "Rock_Sandstone_White"
    },
    {
      "x": -1,
      "y": 7,
      "z": -5,
      "name": "Rock_Sandstone_White"
    },
    {
      "x": -1,
      "y": 8,
      "z": -5,
      "name": "Rock_Sandstone_White"
    },
    {
      "x": -1,
      "y": 9,
      "z": -5,
      "name": "Soil_Sand_White"
    },
    {
      "x": -1,
      "y": 11,
      "z": -5,
      "name": "Soil_Gravel_Sand"
    },
    {
      "x": -1,
      "y": 12,
      "z": -5,
      "name": "Soil_Gravel_Sand"
    },
    {
      "x": -1,
      "y": 13,
      "z": -5,
      "name": "Soil_Gravel_Sand"
    },
    {
      "x": -1,
      "y": 14,
      "z": -5,
      "name": "Rock_Sandstone"
    },
    {
      "x": -1,
      "y": 22,
      "z": -5,
      "name": "Rock_Sandstone"
    },
    {
      "x": -1,
      "y": 23,
      "z": -5,
      "name": "Soil_Gravel_Sand"
    },
    {
      "x": -1,
      "y": 24,
      "z": -5,
      "name": "Soil_Gravel_Sand_White"
    },
    {
      "x": -1,
      "y": 26,
      "z": -5,
      "name": "Soil_Gravel_Sand_White"
    },
    {
      "x": -1,
      "y": 27,
      "z": -5,
      "name": "Soil_Gravel_Sand_White"
    },
    {
      "x": -1,
      "y": 28,
      "z": -5,
      "name": "Rock_Sandstone"
    },
    {
      "x": -1,
      "y": 29,
      "z": -5,
      "name": "Rock_Sandstone"
    },
    {
      "x": -1,
      "y": 4,
      "z": -4,
      "name": "Rock_Sandstone_White"
    },
    {
      "x": -1,
      "y": 5,
      "z": -4,
      "name": "Rock_Sandstone_White"
    },
    {
      "x": -1,
      "y": 6,
      "z": -4,
      "name": "Rock_Sandstone_White"
    },
    {
      "x": -1,
      "y": 7,
      "z": -4,
      "name": "Rock_Sandstone_White"
    },
    {
      "x": -1,
      "y": 8,
      "z": -4,
      "name": "Rock_Sandstone_White"
    },
    {
      "x": -1,
      "y": 9,
      "z": -4,
      "name": "Rock_Sandstone_White"
    },
    {
      "x": -1,
      "y": 10,
      "z": -4,
      "name": "Rock_Sandstone_White"
    },
    {
      "x": -1,
      "y": 11,
      "z": -4,
      "name": "Soil_Gravel_Sand"
    },
    {
      "x": -1,
      "y": 12,
      "z": -4,
      "name": "Soil_Gravel_Sand"
    },
    {
      "x": -1,
      "y": 13,
      "z": -4,
      "name": "Soil_Gravel_Sand"
    },
    {
      "x": -1,
      "y": 14,
      "z": -4,
      "name": "Rock_Sandstone"
    },
    {
      "x": -1,
      "y": 16,
      "z": -4,
      "name": "Rock_Sandstone_White"
    },
    {
      "x": -1,
      "y": 17,
      "z": -4,
      "name": "Soil_Gravel_Sand"
    },
    {
      "x": -1,
      "y": 21,
      "z": -4,
      "name": "Rock_Sandstone"
    },
    {
      "x": -1,
      "y": 22,
      "z": -4,
      "name": "Rock_Sandstone"
    },
    {
      "x": -1,
      "y": 23,
      "z": -4,
      "name": "Soil_Gravel_Sand"
    },
    {
      "x": -1,
      "y": 24,
      "z": -4,
      "name": "Soil_Gravel_Sand_White"
    },
    {
      "x": -1,
      "y": 26,
      "z": -4,
      "name": "Soil_Gravel_Sand_White"
    },
    {
      "x": -1,
      "y": 27,
      "z": -4,
      "name": "Soil_Gravel_Sand_White"
    },
    {
      "x": -1,
      "y": 28,
      "z": -4,
      "name": "Rock_Sandstone"
    },
    {
      "x": -1,
      "y": 29,
      "z": -4,
      "name": "Rock_Sandstone"
    },
    {
      "x": -1,
      "y": 4,
      "z": -3,
      "name": "Rock_Sandstone_White"
    },
    {
      "x": -1,
      "y": 5,
      "z": -3,
      "name": "Rock_Sandstone_White"
    },
    {
      "x": -1,
      "y": 6,
      "z": -3,
      "name": "Rock_Sandstone_White"
    },
    {
      "x": -1,
      "y": 7,
      "z": -3,
      "name": "Rock_Sandstone_White"
    },
    {
      "x": -1,
      "y": 8,
      "z": -3,
      "name": "Rock_Sandstone_White"
    },
    {
      "x": -1,
      "y": 9,
      "z": -3,
      "name": "Rock_Sandstone_White"
    },
    {
      "x": -1,
      "y": 10,
      "z": -3,
      "name": "Rock_Sandstone_White"
    },
    {
      "x": -1,
      "y": 11,
      "z": -3,
      "name": "Soil_Gravel_Sand"
    },
    {
      "x": -1,
      "y": 12,
      "z": -3,
      "name": "Soil_Gravel_Sand"
    },
    {
      "x": -1,
      "y": 13,
      "z": -3,
      "name": "Soil_Gravel_Sand"
    },
    {
      "x": -1,
      "y": 14,
      "z": -3,
      "name": "Rock_Sandstone"
    },
    {
      "x": -1,
      "y": 15,
      "z": -3,
      "name": "Rock_Sandstone_White"
    },
    {
      "x": -1,
      "y": 16,
      "z": -3,
      "name": "Rock_Sandstone_White"
    },
    {
      "x": -1,
      "y": 17,
      "z": -3,
      "name": "Soil_Gravel_Sand"
    },
    {
      "x": -1,
      "y": 18,
      "z": -3,
      "name": "Soil_Gravel_Sand"
    },
    {
      "x": -1,
      "y": 20,
      "z": -3,
      "name": "Rock_Sandstone"
    },
    {
      "x": -1,
      "y": 21,
      "z": -3,
      "name": "Rock_Sandstone"
    },
    {
      "x": -1,
      "y": 22,
      "z": -3,
      "name": "Rock_Sandstone"
    },
    {
      "x": -1,
      "y": 23,
      "z": -3,
      "name": "Soil_Gravel_Sand"
    },
    {
      "x": -1,
      "y": 24,
      "z": -3,
      "name": "Soil_Gravel_Sand_White"
    },
    {
      "x": -1,
      "y": 25,
      "z": -3,
      "name": "Soil_Gravel_Sand_White"
    },
    {
      "x": -1,
      "y": 26,
      "z": -3,
      "name": "Soil_Gravel_Sand_White"
    },
    {
      "x": -1,
      "y": 27,
      "z": -3,
      "name": "Soil_Gravel_Sand_White"
    },
    {
      "x": -1,
      "y": 28,
      "z": -3,
      "name": "Rock_Sandstone"
    },
    {
      "x": -1,
      "y": 29,
      "z": -3,
      "name": "Rock_Sandstone"
    },
    {
      "x": -1,
      "y": 4,
      "z": -2,
      "name": "Rock_Sandstone_White"
    },
    {
      "x": -1,
      "y": 5,
      "z": -2,
      "name": "Rock_Sandstone_White"
    },
    {
      "x": -1,
      "y": 6,
      "z": -2,
      "name": "Rock_Sandstone_White"
    },
    {
      "x": -1,
      "y": 7,
      "z": -2,
      "name": "Rock_Sandstone_White"
    },
    {
      "x": -1,
      "y": 8,
      "z": -2,
      "name": "Rock_Sandstone_White"
    },
    {
      "x": -1,
      "y": 9,
      "z": -2,
      "name": "Rock_Sandstone_White"
    },
    {
      "x": -1,
      "y": 10,
      "z": -2,
      "name": "Rock_Sandstone_White"
    },
    {
      "x": -1,
      "y": 11,
      "z": -2,
      "name": "Soil_Gravel_Sand"
    },
    {
      "x": -1,
      "y": 12,
      "z": -2,
      "name": "Soil_Gravel_Sand"
    },
    {
      "x": -1,
      "y": 13,
      "z": -2,
      "name": "Soil_Gravel_Sand"
    },
    {
      "x": -1,
      "y": 14,
      "z": -2,
      "name": "Rock_Sandstone"
    },
    {
      "x": -1,
      "y": 15,
      "z": -2,
      "name": "Rock_Sandstone_White"
    },
    {
      "x": -1,
      "y": 16,
      "z": -2,
      "name": "Rock_Sandstone_White"
    },
    {
      "x": -1,
      "y": 17,
      "z": -2,
      "name": "Soil_Gravel_Sand"
    },
    {
      "x": -1,
      "y": 18,
      "z": -2,
      "name": "Soil_Gravel_Sand"
    },
    {
      "x": -1,
      "y": 20,
      "z": -2,
      "name": "Rock_Sandstone"
    },
    {
      "x": -1,
      "y": 21,
      "z": -2,
      "name": "Rock_Sandstone"
    },
    {
      "x": -1,
      "y": 22,
      "z": -2,
      "name": "Rock_Sandstone"
    },
    {
      "x": -1,
      "y": 23,
      "z": -2,
      "name": "Soil_Gravel_Sand"
    },
    {
      "x": -1,
      "y": 24,
      "z": -2,
      "name": "Soil_Gravel_Sand_White"
    },
    {
      "x": -1,
      "y": 25,
      "z": -2,
      "name": "Soil_Gravel_Sand_White"
    },
    {
      "x": -1,
      "y": 26,
      "z": -2,
      "name": "Soil_Gravel_Sand_White"
    },
    {
      "x": -1,
      "y": 27,
      "z": -2,
      "name": "Soil_Gravel_Sand_White"
    },
    {
      "x": -1,
      "y": 28,
      "z": -2,
      "name": "Rock_Sandstone"
    },
    {
      "x": -1,
      "y": 29,
      "z": -2,
      "name": "Rock_Sandstone"
    },
    {
      "x": -1,
      "y": 3,
      "z": -1,
      "name": "Rock_Sandstone_White"
    },
    {
      "x": -1,
      "y": 4,
      "z": -1,
      "name": "Rock_Sandstone_White"
    },
    {
      "x": -1,
      "y": 5,
      "z": -1,
      "name": "Rock_Sandstone_White"
    },
    {
      "x": -1,
      "y": 6,
      "z": -1,
      "name": "Rock_Sandstone_White"
    },
    {
      "x": -1,
      "y": 7,
      "z": -1,
      "name": "Rock_Sandstone_White"
    },
    {
      "x": -1,
      "y": 8,
      "z": -1,
      "name": "Rock_Sandstone_White"
    },
    {
      "x": -1,
      "y": 9,
      "z": -1,
      "name": "Rock_Sandstone_White"
    },
    {
      "x": -1,
      "y": 10,
      "z": -1,
      "name": "Rock_Sandstone_White"
    },
    {
      "x": -1,
      "y": 11,
      "z": -1,
      "name": "Soil_Gravel_Sand"
    },
    {
      "x": -1,
      "y": 12,
      "z": -1,
      "name": "Soil_Gravel_Sand"
    },
    {
      "x": -1,
      "y": 13,
      "z": -1,
      "name": "Soil_Gravel_Sand"
    },
    {
      "x": -1,
      "y": 14,
      "z": -1,
      "name": "Rock_Sandstone"
    },
    {
      "x": -1,
      "y": 15,
      "z": -1,
      "name": "Rock_Sandstone_White"
    },
    {
      "x": -1,
      "y": 16,
      "z": -1,
      "name": "Rock_Sandstone_White"
    },
    {
      "x": -1,
      "y": 17,
      "z": -1,
      "name": "Soil_Gravel_Sand"
    },
    {
      "x": -1,
      "y": 18,
      "z": -1,
      "name": "Soil_Gravel_Sand"
    },
    {
      "x": -1,
      "y": 20,
      "z": -1,
      "name": "Rock_Sandstone"
    },
    {
      "x": -1,
      "y": 21,
      "z": -1,
      "name": "Rock_Sandstone"
    },
    {
      "x": -1,
      "y": 22,
      "z": -1,
      "name": "Rock_Sandstone"
    },
    {
      "x": -1,
      "y": 23,
      "z": -1,
      "name": "Soil_Gravel_Sand"
    },
    {
      "x": -1,
      "y": 24,
      "z": -1,
      "name": "Soil_Gravel_Sand_White"
    },
    {
      "x": -1,
      "y": 25,
      "z": -1,
      "name": "Soil_Gravel_Sand_White"
    },
    {
      "x": -1,
      "y": 26,
      "z": -1,
      "name": "Soil_Gravel_Sand_White"
    },
    {
      "x": -1,
      "y": 27,
      "z": -1,
      "name": "Soil_Gravel_Sand_White"
    },
    {
      "x": -1,
      "y": 28,
      "z": -1,
      "name": "Rock_Sandstone"
    },
    {
      "x": -1,
      "y": 29,
      "z": -1,
      "name": "Rock_Sandstone"
    },
    {
      "x": -1,
      "y": 30,
      "z": -1,
      "name": "Rock_Sandstone"
    },
    {
      "x": -1,
      "y": 3,
      "z": 0,
      "name": "Rock_Sandstone_White"
    },
    {
      "x": -1,
      "y": 4,
      "z": 0,
      "name": "Rock_Sandstone_White"
    },
    {
      "x": -1,
      "y": 5,
      "z": 0,
      "name": "Rock_Sandstone_White"
    },
    {
      "x": -1,
      "y": 6,
      "z": 0,
      "name": "Rock_Sandstone_White"
    },
    {
      "x": -1,
      "y": 7,
      "z": 0,
      "name": "Rock_Sandstone_White"
    },
    {
      "x": -1,
      "y": 8,
      "z": 0,
      "name": "Rock_Sandstone_White"
    },
    {
      "x": -1,
      "y": 9,
      "z": 0,
      "name": "Rock_Sandstone_White"
    },
    {
      "x": -1,
      "y": 10,
      "z": 0,
      "name": "Rock_Sandstone_White"
    },
    {
      "x": -1,
      "y": 11,
      "z": 0,
      "name": "Soil_Gravel_Sand"
    },
    {
      "x": -1,
      "y": 12,
      "z": 0,
      "name": "Soil_Gravel_Sand"
    },
    {
      "x": -1,
      "y": 13,
      "z": 0,
      "name": "Soil_Gravel_Sand"
    },
    {
      "x": -1,
      "y": 14,
      "z": 0,
      "name": "Rock_Sandstone"
    },
    {
      "x": -1,
      "y": 16,
      "z": 0,
      "name": "Rock_Sandstone_White"
    },
    {
      "x": -1,
      "y": 17,
      "z": 0,
      "name": "Soil_Gravel_Sand"
    },
    {
      "x": -1,
      "y": 18,
      "z": 0,
      "name": "Soil_Gravel_Sand"
    },
    {
      "x": -1,
      "y": 20,
      "z": 0,
      "name": "Rock_Sandstone"
    },
    {
      "x": -1,
      "y": 21,
      "z": 0,
      "name": "Rock_Sandstone"
    },
    {
      "x": -1,
      "y": 22,
      "z": 0,
      "name": "Rock_Sandstone"
    },
    {
      "x": -1,
      "y": 23,
      "z": 0,
      "name": "Soil_Gravel_Sand"
    },
    {
      "x": -1,
      "y": 24,
      "z": 0,
      "name": "Soil_Gravel_Sand_White"
    },
    {
      "x": -1,
      "y": 25,
      "z": 0,
      "name": "Soil_Gravel_Sand_White"
    },
    {
      "x": -1,
      "y": 26,
      "z": 0,
      "name": "Soil_Gravel_Sand_White"
    },
    {
      "x": -1,
      "y": 27,
      "z": 0,
      "name": "Soil_Gravel_Sand_White"
    },
    {
      "x": -1,
      "y": 28,
      "z": 0,
      "name": "Rock_Sandstone"
    },
    {
      "x": -1,
      "y": 29,
      "z": 0,
      "name": "Rock_Sandstone"
    },
    {
      "x": -1,
      "y": 30,
      "z": 0,
      "name": "Rock_Sandstone"
    },
    {
      "x": -1,
      "y": 3,
      "z": 1,
      "name": "Rock_Sandstone_White"
    },
    {
      "x": -1,
      "y": 4,
      "z": 1,
      "name": "Rock_Sandstone_White"
    },
    {
      "x": -1,
      "y": 5,
      "z": 1,
      "name": "Rock_Sandstone_White"
    },
    {
      "x": -1,
      "y": 6,
      "z": 1,
      "name": "Rock_Sandstone_White"
    },
    {
      "x": -1,
      "y": 7,
      "z": 1,
      "name": "Rock_Sandstone_White"
    },
    {
      "x": -1,
      "y": 8,
      "z": 1,
      "name": "Rock_Sandstone_White"
    },
    {
      "x": -1,
      "y": 9,
      "z": 1,
      "name": "Rock_Sandstone_White"
    },
    {
      "x": -1,
      "y": 10,
      "z": 1,
      "name": "Rock_Sandstone_White"
    },
    {
      "x": -1,
      "y": 11,
      "z": 1,
      "name": "Soil_Gravel_Sand"
    },
    {
      "x": -1,
      "y": 12,
      "z": 1,
      "name": "Soil_Gravel_Sand"
    },
    {
      "x": -1,
      "y": 13,
      "z": 1,
      "name": "Soil_Gravel_Sand"
    },
    {
      "x": -1,
      "y": 14,
      "z": 1,
      "name": "Rock_Sandstone"
    },
    {
      "x": -1,
      "y": 16,
      "z": 1,
      "name": "Rock_Sandstone_White"
    },
    {
      "x": -1,
      "y": 17,
      "z": 1,
      "name": "Soil_Gravel_Sand"
    },
    {
      "x": -1,
      "y": 20,
      "z": 1,
      "name": "Rock_Sandstone"
    },
    {
      "x": -1,
      "y": 21,
      "z": 1,
      "name": "Rock_Sandstone"
    },
    {
      "x": -1,
      "y": 22,
      "z": 1,
      "name": "Rock_Sandstone"
    },
    {
      "x": -1,
      "y": 23,
      "z": 1,
      "name": "Soil_Gravel_Sand"
    },
    {
      "x": -1,
      "y": 24,
      "z": 1,
      "name": "Soil_Gravel_Sand_White"
    },
    {
      "x": -1,
      "y": 25,
      "z": 1,
      "name": "Soil_Gravel_Sand_White"
    },
    {
      "x": -1,
      "y": 26,
      "z": 1,
      "name": "Soil_Gravel_Sand_White"
    },
    {
      "x": -1,
      "y": 27,
      "z": 1,
      "name": "Soil_Gravel_Sand_White"
    },
    {
      "x": -1,
      "y": 28,
      "z": 1,
      "name": "Rock_Sandstone"
    },
    {
      "x": -1,
      "y": 29,
      "z": 1,
      "name": "Rock_Sandstone"
    },
    {
      "x": -1,
      "y": 30,
      "z": 1,
      "name": "Rock_Sandstone"
    },
    {
      "x": -1,
      "y": 3,
      "z": 2,
      "name": "Rock_Sandstone_White"
    },
    {
      "x": -1,
      "y": 4,
      "z": 2,
      "name": "Rock_Sandstone_White"
    },
    {
      "x": -1,
      "y": 5,
      "z": 2,
      "name": "Rock_Sandstone_White"
    },
    {
      "x": -1,
      "y": 6,
      "z": 2,
      "name": "Rock_Sandstone_White"
    },
    {
      "x": -1,
      "y": 7,
      "z": 2,
      "name": "Rock_Sandstone_White"
    },
    {
      "x": -1,
      "y": 8,
      "z": 2,
      "name": "Rock_Sandstone_White"
    },
    {
      "x": -1,
      "y": 9,
      "z": 2,
      "name": "Rock_Sandstone_White"
    },
    {
      "x": -1,
      "y": 10,
      "z": 2,
      "name": "Rock_Sandstone_White"
    },
    {
      "x": -1,
      "y": 11,
      "z": 2,
      "name": "Soil_Gravel_Sand"
    },
    {
      "x": -1,
      "y": 12,
      "z": 2,
      "name": "Soil_Gravel_Sand"
    },
    {
      "x": -1,
      "y": 13,
      "z": 2,
      "name": "Soil_Gravel_Sand"
    },
    {
      "x": -1,
      "y": 14,
      "z": 2,
      "name": "Rock_Sandstone"
    },
    {
      "x": -1,
      "y": 20,
      "z": 2,
      "name": "Rock_Sandstone"
    },
    {
      "x": -1,
      "y": 21,
      "z": 2,
      "name": "Rock_Sandstone"
    },
    {
      "x": -1,
      "y": 22,
      "z": 2,
      "name": "Rock_Sandstone"
    },
    {
      "x": -1,
      "y": 23,
      "z": 2,
      "name": "Soil_Gravel_Sand"
    },
    {
      "x": -1,
      "y": 24,
      "z": 2,
      "name": "Soil_Gravel_Sand_White"
    },
    {
      "x": -1,
      "y": 25,
      "z": 2,
      "name": "Soil_Gravel_Sand_White"
    },
    {
      "x": -1,
      "y": 26,
      "z": 2,
      "name": "Soil_Gravel_Sand_White"
    },
    {
      "x": -1,
      "y": 27,
      "z": 2,
      "name": "Soil_Gravel_Sand_White"
    },
    {
      "x": -1,
      "y": 28,
      "z": 2,
      "name": "Rock_Sandstone"
    },
    {
      "x": -1,
      "y": 29,
      "z": 2,
      "name": "Rock_Sandstone"
    },
    {
      "x": -1,
      "y": 3,
      "z": 3,
      "name": "Rock_Sandstone_White"
    },
    {
      "x": -1,
      "y": 4,
      "z": 3,
      "name": "Rock_Sandstone_White"
    },
    {
      "x": -1,
      "y": 5,
      "z": 3,
      "name": "Rock_Sandstone_White"
    },
    {
      "x": -1,
      "y": 6,
      "z": 3,
      "name": "Rock_Sandstone_White"
    },
    {
      "x": -1,
      "y": 7,
      "z": 3,
      "name": "Rock_Sandstone_White"
    },
    {
      "x": -1,
      "y": 8,
      "z": 3,
      "name": "Rock_Sandstone_White"
    },
    {
      "x": -1,
      "y": 9,
      "z": 3,
      "name": "Rock_Sandstone_White"
    },
    {
      "x": -1,
      "y": 10,
      "z": 3,
      "name": "Rock_Sandstone_White"
    },
    {
      "x": -1,
      "y": 11,
      "z": 3,
      "name": "Soil_Gravel_Sand"
    },
    {
      "x": -1,
      "y": 12,
      "z": 3,
      "name": "Soil_Gravel_Sand"
    },
    {
      "x": -1,
      "y": 13,
      "z": 3,
      "name": "Soil_Gravel_Sand"
    },
    {
      "x": -1,
      "y": 14,
      "z": 3,
      "name": "Rock_Sandstone"
    },
    {
      "x": -1,
      "y": 21,
      "z": 3,
      "name": "Rock_Sandstone"
    },
    {
      "x": -1,
      "y": 22,
      "z": 3,
      "name": "Rock_Sandstone"
    },
    {
      "x": -1,
      "y": 23,
      "z": 3,
      "name": "Soil_Gravel_Sand"
    },
    {
      "x": -1,
      "y": 24,
      "z": 3,
      "name": "Soil_Gravel_Sand_White"
    },
    {
      "x": -1,
      "y": 25,
      "z": 3,
      "name": "Soil_Gravel_Sand_White"
    },
    {
      "x": -1,
      "y": 26,
      "z": 3,
      "name": "Soil_Gravel_Sand_White"
    },
    {
      "x": -1,
      "y": 27,
      "z": 3,
      "name": "Soil_Gravel_Sand_White"
    },
