{
  "version": 8,
  "blockIdVersion": 8,
  "anchorX": 3,
  "anchorY": 6,
  "anchorZ": 16,
  "blocks": [
    {
      "x": 1,
      "y": 6,
      "z": 7,
      "name": "Rock_Slate"
    },
    {
      "x": 1,
      "y": 7,
      "z": 7,
      "name": "Rock_Slate"
    },
    {
      "x": 1,
      "y": 8,
      "z": 7,
      "name": "Rock_Slate"
    },
    {
      "x": 1,
      "y": 9,
      "z": 7,
      "name": "Rock_Slate"
    },
    {
      "x": 1,
      "y": 10,
      "z": 7,
      "name": "Rock_Slate"
    },
    {
      "x": 1,
      "y": 6,
      "z": 8,
      "name": "Rock_Slate"
    },
    {
      "x": 1,
      "y": 7,
      "z": 8,
      "name": "Rock_Slate"
    },
    {
      "x": 1,
      "y": 8,
      "z": 8,
      "name": "Rock_Slate"
    },
    {
      "x": 1,
      "y": 9,
      "z": 8,
      "name": "Rock_Slate"
    },
    {
      "x": 1,
      "y": 10,
      "z": 8,
      "name": "Rock_Slate"
    },
    {
      "x": 1,
      "y": 6,
      "z": 9,
      "name": "Rock_Slate"
    },
    {
      "x": 1,
      "y": 7,
      "z": 9,
      "name": "Rock_Slate"
    },
    {
      "x": 1,
      "y": 8,
      "z": 9,
      "name": "Rock_Slate"
    },
    {
      "x": 1,
      "y": 9,
      "z": 9,
      "name": "Rock_Slate"
    },
    {
      "x": 1,
      "y": 10,
      "z": 9,
      "name": "Rock_Slate"
    },
    {
      "x": 1,
      "y": 6,
      "z": 10,
      "name": "Rock_Slate"
    },
    {
      "x": 1,
      "y": 7,
      "z": 10,
      "name": "Rock_Slate"
    },
    {
      "x": 1,
      "y": 8,
      "z": 10,
      "name": "Rock_Slate"
    },
    {
      "x": 1,
      "y": 9,
      "z": 10,
      "name": "Rock_Slate"
    },
    {
      "x": 1,
      "y": 10,
      "z": 10,
      "name": "Rock_Slate"
    },
    {
      "x": 1,
      "y": 6,
      "z": 11,
      "name": "Rock_Slate"
    },
    {
      "x": 1,
      "y": 7,
      "z": 11,
      "name": "Rock_Slate"
    },
    {
      "x": 1,
      "y": 8,
      "z": 11,
      "name": "Rock_Slate"
    },
    {
      "x": 1,
      "y": 9,
      "z": 11,
      "name": "Rock_Slate"
    },
    {
      "x": 1,
      "y": 10,
      "z": 11,
      "name": "Rock_Slate"
    },
    {
      "x": 1,
      "y": 6,
      "z": 12,
      "name": "Rock_Slate"
    },
    {
      "x": 1,
      "y": 7,
      "z": 12,
      "name": "Rock_Slate"
    },
    {
      "x": 1,
      "y": 8,
      "z": 12,
      "name": "Rock_Slate"
    },
    {
      "x": 1,
      "y": 9,
      "z": 12,
      "name": "Rock_Slate"
    },
    {
      "x": 1,
      "y": 10,
      "z": 12,
      "name": "Rock_Slate"
    },
    {
      "x": 1,
      "y": 6,
      "z": 13,
      "name": "Rock_Slate"
    },
    {
      "x": 1,
      "y": 7,
      "z": 13,
      "name": "Rock_Slate"
    },
    {
      "x": 1,
      "y": 8,
      "z": 13,
      "name": "Rock_Slate"
    },
    {
      "x": 1,
      "y": 9,
      "z": 13,
      "name": "Rock_Slate"
    },
    {
      "x": 1,
      "y": 10,
      "z": 13,
      "name": "Rock_Slate"
    },
    {
      "x": 1,
      "y": 6,
      "z": 14,
      "name": "Rock_Slate"
    },
    {
      "x": 1,
      "y": 7,
      "z": 14,
      "name": "Rock_Slate"
    },
    {
      "x": 1,
      "y": 8,
      "z": 14,
      "name": "Rock_Slate"
    },
    {
      "x": 1,
      "y": 9,
      "z": 14,
      "name": "Rock_Slate"
    },
    {
      "x": 1,
      "y": 10,
      "z": 14,
      "name": "Rock_Slate"
    },
    {
      "x": 1,
      "y": 6,
      "z": 15,
      "name": "Rock_Slate"
    },
    {
      "x": 1,
      "y": 7,
      "z": 15,
      "name": "Rock_Slate"
    },
    {
      "x": 1,
      "y": 8,
      "z": 15,
      "name": "Rock_Slate"
    },
    {
      "x": 1,
      "y": 9,
      "z": 15,
      "name": "Rock_Slate"
    },
    {
      "x": 1,
      "y": 10,
      "z": 15,
      "name": "Rock_Slate"
    },
    {
      "x": 2,
      "y": 6,
      "z": 7,
      "name": "Rock_Slate"
    },
    {
      "x": 2,
      "y": 7,
      "z": 7,
      "name": "Rock_Slate"
    },
    {
      "x": 2,
      "y": 8,
      "z": 7,
      "name": "Rock_Slate"
    },
    {
      "x": 2,
      "y": 9,
      "z": 7,
      "name": "Rock_Slate"
    },
    {
      "x": 2,
      "y": 10,
      "z": 7,
      "name": "Rock_Slate"
    },
    {
      "x": 2,
      "y": 6,
      "z": 8,
      "name": "Rock_Slate"
    },
    {
      "x": 2,
      "y": 7,
      "z": 8,
      "name": "Empty"
    },
    {
      "x": 2,
      "y": 8,
      "z": 8,
      "name": "Empty"
    },
    {
      "x": 2,
      "y": 9,
      "z": 8,
      "name": "Empty"
    },
    {
      "x": 2,
      "y": 10,
      "z": 8,
      "name": "Rock_Slate"
    },
    {
      "x": 2,
      "y": 6,
      "z": 9,
      "name": "Rock_Slate"
    },
    {
      "x": 2,
      "y": 7,
      "z": 9,
      "name": "Empty"
    },
    {
      "x": 2,
      "y": 8,
      "z": 9,
      "name": "Empty"
    },
    {
      "x": 2,
      "y": 9,
      "z": 9,
      "name": "Empty"
    },
    {
      "x": 2,
      "y": 10,
      "z": 9,
      "name": "Rock_Slate"
    },
    {
      "x": 2,
      "y": 6,
      "z": 10,
      "name": "Rock_Slate"
    },
    {
      "x": 2,
      "y": 7,
      "z": 10,
      "name": "Empty"
    },
    {
      "x": 2,
      "y": 8,
      "z": 10,
      "name": "Empty"
    },
    {
      "x": 2,
      "y": 9,
      "z": 10,
      "name": "Empty"
    },
    {
      "x": 2,
      "y": 10,
      "z": 10,
      "name": "Rock_Slate"
    },
    {
      "x": 2,
      "y": 6,
      "z": 11,
      "name": "Rock_Slate"
    },
    {
      "x": 2,
      "y": 7,
      "z": 11,
      "name": "Empty"
    },
    {
      "x": 2,
      "y": 8,
      "z": 11,
      "name": "Empty"
    },
    {
      "x": 2,
      "y": 9,
      "z": 11,
      "name": "Empty"
    },
    {
      "x": 2,
      "y": 10,
      "z": 11,
      "name": "Rock_Slate"
    },
    {
      "x": 2,
      "y": 6,
      "z": 12,
      "name": "Rock_Slate"
    },
    {
      "x": 2,
      "y": 7,
      "z": 12,
      "name": "Empty"
    },
    {
      "x": 2,
      "y": 8,
      "z": 12,
      "name": "Empty"
    },
    {
      "x": 2,
      "y": 9,
      "z": 12,
      "name": "Empty"
    },
    {
      "x": 2,
      "y": 10,
      "z": 12,
      "name": "Rock_Slate"
    },
    {
      "x": 2,
      "y": 6,
      "z": 13,
      "name": "Rock_Slate"
    },
    {
      "x": 2,
      "y": 7,
      "z": 13,
      "name": "Empty"
    },
    {
      "x": 2,
      "y": 8,
      "z": 13,
      "name": "Empty"
    },
    {
      "x": 2,
      "y": 9,
      "z": 13,
      "name": "Empty"
    },
    {
      "x": 2,
      "y": 10,
      "z": 13,
      "name": "Rock_Slate"
    },
    {
      "x": 2,
      "y": 6,
      "z": 14,
      "name": "Rock_Slate"
    },
    {
      "x": 2,
      "y": 7,
      "z": 14,
      "name": "Empty"
    },
    {
      "x": 2,
      "y": 8,
      "z": 14,
      "name": "Empty"
    },
    {
      "x": 2,
      "y": 9,
      "z": 14,
      "name": "Empty"
    },
    {
      "x": 2,
      "y": 10,
      "z": 14,
      "name": "Rock_Slate"
    },
    {
      "x": 2,
      "y": 6,
      "z": 15,
      "name": "Rock_Slate"
    },
    {
      "x": 2,
      "y": 7,
      "z": 15,
      "name": "Empty"
    },
    {
      "x": 2,
      "y": 8,
      "z": 15,
      "name": "Empty"
    },
    {
      "x": 2,
      "y": 9,
      "z": 15,
      "name": "Empty"
    },
    {
      "x": 2,
      "y": 10,
      "z": 15,
      "name": "Rock_Slate"
    },
    {
      "x": 2,
      "y": 7,
      "z": 16,
      "name": "Empty"
    },
    {
      "x": 2,
      "y": 8,
      "z": 16,
      "name": "Empty"
    },
    {
      "x": 2,
      "y": 9,
      "z": 16,
      "name": "Empty"
    },
    {
      "x": 3,
      "y": 6,
      "z": 7,
      "name": "Rock_Slate"
    },
    {
      "x": 3,
      "y": 7,
      "z": 7,
      "name": "Rock_Slate"
    },
    {
      "x": 3,
      "y": 8,
      "z": 7,
      "name": "Rock_Slate"
    },
    {
      "x": 3,
      "y": 9,
      "z": 7,
      "name": "Rock_Slate"
    },
    {
      "x": 3,
      "y": 10,
      "z": 7,
      "name": "Rock_Slate"
    },
    {
      "x": 3,
      "y": 6,
      "z": 8,
      "name": "Rock_Slate"
    },
    {
      "x": 3,
      "y": 7,
      "z": 8,
      "name": "Empty"
    },
    {
      "x": 3,
      "y": 8,
      "z": 8,
      "name": "Empty"
    },
    {
      "x": 3,
      "y": 9,
      "z": 8,
      "name": "Empty"
    },
    {
      "x": 3,
      "y": 10,
      "z": 8,
      "name": "Rock_Slate"
    },
    {
      "x": 3,
      "y": 6,
      "z": 9,
      "name": "Rock_Slate"
    },
    {
      "x": 3,
      "y": 7,
      "z": 9,
      "name": "Empty"
    },
    {
      "x": 3,
      "y": 8,
      "z": 9,
      "name": "Empty"
    },
    {
      "x": 3,
      "y": 9,
      "z": 9,
      "name": "Empty"
    },
    {
      "x": 3,
      "y": 10,
      "z": 9,
      "name": "Rock_Slate"
    },
    {
      "x": 3,
      "y": 6,
      "z": 10,
      "name": "Rock_Slate"
    },
    {
      "x": 3,
      "y": 7,
      "z": 10,
      "name": "Empty"
    },
    {
      "x": 3,
      "y": 8,
      "z": 10,
      "name": "Empty"
    },
    {
      "x": 3,
      "y": 9,
      "z": 10,
      "name": "Empty"
    },
    {
      "x": 3,
      "y": 10,
      "z": 10,
      "name": "Rock_Slate"
    },
    {
      "x": 3,
      "y": 6,
      "z": 11,
      "name": "Rock_Slate"
    },
    {
      "x": 3,
      "y": 7,
      "z": 11,
      "name": "Empty"
    },
    {
      "x": 3,
      "y": 8,
      "z": 11,
      "name": "Empty"
    },
    {
      "x": 3,
      "y": 9,
      "z": 11,
      "name": "Empty"
    },
    {
      "x": 3,
      "y": 10,
      "z": 11,
      "name": "Rock_Slate"
    },
    {
      "x": 3,
      "y": 6,
      "z": 12,
      "name": "Rock_Slate"
    },
    {
      "x": 3,
      "y": 7,
      "z": 12,
      "name": "Empty"
    },
    {
      "x": 3,
      "y": 8,
      "z": 12,
      "name": "Empty"
    },
    {
      "x": 3,
      "y": 9,
      "z": 12,
      "name": "Empty"
    },
    {
      "x": 3,
      "y": 10,
      "z": 12,
      "name": "Rock_Slate"
    },
    {
      "x": 3,
      "y": 6,
      "z": 13,
      "name": "Rock_Slate"
    },
    {
      "x": 3,
      "y": 7,
      "z": 13,
      "name": "Rock_Crystal_White_Block"
    },
    {
      "x": 3,
      "y": 8,
      "z": 13,
      "name": "Empty"
    },
    {
      "x": 3,
      "y": 9,
      "z": 13,
      "name": "Empty"
    },
    {
      "x": 3,
      "y": 10,
      "z": 13,
      "name": "Rock_Slate"
    },
    {
      "x": 3,
      "y": 6,
      "z": 14,
      "name": "Rock_Slate"
    },
    {
      "x": 3,
      "y": 7,
      "z": 14,
      "name": "Rock_Crystal_White_Block"
    },
    {
      "x": 3,
      "y": 8,
      "z": 14,
      "name": "Empty"
    },
    {
      "x": 3,
      "y": 9,
      "z": 14,
      "name": "Empty"
    },
    {
      "x": 3,
      "y": 10,
      "z": 14,
      "name": "Rock_Slate"
    },
    {
      "x": 3,
      "y": 6,
      "z": 15,
      "name": "Rock_Slate"
    },
    {
      "x": 3,
      "y": 7,
      "z": 15,
      "name": "Rock_Crystal_White_Block"
    },
    {
      "x": 3,
      "y": 8,
      "z": 15,
      "name": "Empty"
    },
    {
      "x": 3,
      "y": 9,
      "z": 15,
      "name": "Empty"
    },
    {
      "x": 3,
      "y": 10,
      "z": 15,
      "name": "Rock_Slate"
    },
    {
      "x": 3,
      "y": 6,
      "z": 16,
      "name": "Rock_Slate"
    },
    {
      "x": 3,
      "y": 7,
      "z": 16,
      "name": "Empty"
    },
    {
      "x": 3,
      "y": 8,
      "z": 16,
      "name": "Empty"
    },
    {
      "x": 3,
      "y": 9,
      "z": 16,
      "name": "Empty"
    },
    {
      "x": 4,
      "y": 6,
      "z": 7,
      "name": "Rock_Slate"
    },
    {
      "x": 4,
      "y": 7,
      "z": 7,
      "name": "Rock_Slate"
    },
    {
      "x": 4,
      "y": 8,
      "z": 7,
      "name": "Rock_Slate"
    },
    {
      "x": 4,
      "y": 9,
      "z": 7,
      "name": "Rock_Slate"
    },
    {
      "x": 4,
      "y": 10,
      "z": 7,
      "name": "Rock_Slate"
    },
    {
      "x": 4,
      "y": 6,
      "z": 8,
      "name": "Rock_Slate"
    },
    {
      "x": 4,
      "y": 7,
      "z": 8,
      "name": "Empty"
    },
    {
      "x": 4,
      "y": 8,
      "z": 8,
      "name": "Empty"
    },
    {
      "x": 4,
      "y": 9,
      "z": 8,
      "name": "Empty"
    },
    {
      "x": 4,
      "y": 10,
      "z": 8,
      "name": "Rock_Slate"
    },
    {
      "x": 4,
      "y": 6,
      "z": 9,
      "name": "Rock_Slate"
    },
    {
      "x": 4,
      "y": 7,
      "z": 9,
      "name": "Empty"
    },
    {
      "x": 4,
      "y": 8,
      "z": 9,
      "name": "Empty"
    },
    {
      "x": 4,
      "y": 9,
      "z": 9,
      "name": "Empty"
    },
    {
      "x": 4,
      "y": 10,
      "z": 9,
      "name": "Rock_Slate"
    },
    {
      "x": 4,
      "y": 6,
      "z": 10,
      "name": "Rock_Slate"
    },
    {
      "x": 4,
      "y": 7,
      "z": 10,
      "name": "Empty"
    },
    {
      "x": 4,
      "y": 8,
      "z": 10,
      "name": "Empty"
    },
    {
      "x": 4,
      "y": 9,
      "z": 10,
      "name": "Empty"
    },
    {
      "x": 4,
      "y": 10,
      "z": 10,
      "name": "Rock_Slate"
    },
    {
      "x": 4,
      "y": 6,
      "z": 11,
      "name": "Rock_Slate"
    },
    {
      "x": 4,
      "y": 7,
      "z": 11,
      "name": "Empty"
    },
    {
      "x": 4,
      "y": 8,
      "z": 11,
      "name": "Empty"
    },
    {
      "x": 4,
      "y": 9,
      "z": 11,
      "name": "Empty"
    },
    {
      "x": 4,
      "y": 10,
      "z": 11,
      "name": "Rock_Slate"
    },
    {
      "x": 4,
      "y": 6,
      "z": 12,
      "name": "Rock_Slate"
    },
    {
      "x": 4,
      "y": 7,
      "z": 12,
      "name": "Empty"
    },
    {
      "x": 4,
      "y": 8,
      "z": 12,
      "name": "Empty"
    },
    {
      "x": 4,
      "y": 9,
      "z": 12,
      "name": "Empty"
    },
    {
      "x": 4,
      "y": 10,
      "z": 12,
      "name": "Rock_Slate"
    },
    {
      "x": 4,
      "y": 6,
      "z": 13,
      "name": "Rock_Slate"
    },
    {
      "x": 4,
      "y": 7,
      "z": 13,
      "name": "Empty"
    },
    {
      "x": 4,
      "y": 8,
      "z": 13,
      "name": "Empty"
    },
    {
      "x": 4,
      "y": 9,
      "z": 13,
      "name": "Empty"
    },
    {
      "x": 4,
      "y": 10,
      "z": 13,
      "name": "Rock_Slate"
    },
    {
      "x": 4,
      "y": 6,
      "z": 14,
      "name": "Rock_Slate"
    },
    {
      "x": 4,
      "y": 7,
      "z": 14,
      "name": "Empty"
    },
    {
      "x": 4,
      "y": 8,
      "z": 14,
      "name": "Empty"
    },
    {
      "x": 4,
      "y": 9,
      "z": 14,
      "name": "Empty"
    },
    {
      "x": 4,
      "y": 10,
      "z": 14,
      "name": "Rock_Slate"
    },
    {
      "x": 4,
      "y": 6,
      "z": 15,
      "name": "Rock_Slate"
    },
    {
      "x": 4,
      "y": 7,
      "z": 15,
      "name": "Empty"
    },
    {
      "x": 4,
      "y": 8,
      "z": 15,
      "name": "Empty"
    },
    {
      "x": 4,
      "y": 9,
      "z": 15,
      "name": "Empty"
    },
    {
      "x": 4,
      "y": 10,
      "z": 15,
      "name": "Rock_Slate"
    },
    {
      "x": 4,
      "y": 7,
      "z": 16,
      "name": "Empty"
    },
    {
      "x": 4,
      "y": 8,
      "z": 16,
      "name": "Empty"
    },
    {
      "x": 4,
      "y": 9,
      "z": 16,
      "name": "Empty"
    },
    {
      "x": 5,
      "y": 6,
      "z": 7,
      "name": "Rock_Slate"
    },
    {
      "x": 5,
      "y": 7,
      "z": 7,
      "name": "Rock_Slate"
    },
    {
      "x": 5,
      "y": 8,
      "z": 7,
      "name": "Rock_Slate"
    },
    {
      "x": 5,
      "y": 9,
      "z": 7,
      "name": "Rock_Slate"
    },
    {
      "x": 5,
      "y": 10,
      "z": 7,
      "name": "Rock_Slate"
    },
    {
      "x": 5,
      "y": 6,
      "z": 8,
      "name": "Rock_Slate"
    },
    {
      "x": 5,
      "y": 7,
      "z": 8,
      "name": "Empty"
    },
    {
      "x": 5,
      "y": 8,
      "z": 8,
      "name": "Empty"
    },
    {
      "x": 5,
      "y": 9,
      "z": 8,
      "name": "Empty"
    },
    {
      "x": 5,
      "y": 10,
      "z": 8,
      "name": "Rock_Slate"
    },
    {
      "x": 5,
      "y": 6,
      "z": 9,
      "name": "Rock_Slate"
    },
    {
      "x": 5,
      "y": 7,
      "z": 9,
      "name": "Empty"
    },
    {
      "x": 5,
      "y": 8,
      "z": 9,
      "name": "Empty"
    },
    {
      "x": 5,
      "y": 9,
      "z": 9,
      "name": "Empty"
    },
    {
      "x": 5,
      "y": 10,
      "z": 9,
      "name": "Rock_Slate"
    },
    {
      "x": 5,
      "y": 6,
      "z": 10,
      "name": "Rock_Slate"
    },
    {
      "x": 5,
      "y": 7,
      "z": 10,
      "name": "Empty"
    },
    {
      "x": 5,
      "y": 8,
      "z": 10,
      "name": "Empty"
    },
    {
      "x": 5,
      "y": 9,
      "z": 10,
      "name": "Empty"
    },
    {
      "x": 5,
      "y": 10,
      "z": 10,
      "name": "Rock_Slate"
    },
    {
      "x": 5,
      "y": 6,
      "z": 11,
      "name": "Rock_Slate"
    },
    {
      "x": 5,
      "y": 7,
      "z": 11,
      "name": "Rock_Slate"
    },
    {
      "x": 5,
      "y": 8,
      "z": 11,
      "name": "Rock_Slate"
    },
    {
      "x": 5,
      "y": 9,
      "z": 11,
      "name": "Rock_Slate"
    },
    {
      "x": 5,
      "y": 10,
      "z": 11,
      "name": "Rock_Slate"
    },
    {
      "x": 5,
      "y": 6,
      "z": 12,
      "name": "Rock_Slate"
    },
    {
      "x": 5,
      "y": 7,
      "z": 12,
      "name": "Rock_Slate"
    },
    {
      "x": 5,
      "y": 8,
      "z": 12,
      "name": "Rock_Slate"
    },
    {
      "x": 5,
      "y": 9,
      "z": 12,
      "name": "Rock_Slate"
    },
    {
      "x": 5,
      "y": 10,
      "z": 12,
      "name": "Rock_Slate"
    },
    {
      "x": 5,
      "y": 6,
      "z": 13,
      "name": "Rock_Slate"
    },
    {
      "x": 5,
      "y": 7,
      "z": 13,
      "name": "Rock_Slate"
    },
    {
      "x": 5,
      "y": 8,
      "z": 13,
      "name": "Rock_Slate"
    },
    {
      "x": 5,
      "y": 9,
      "z": 13,
      "name": "Rock_Slate"
    },
    {
      "x": 5,
      "y": 10,
      "z": 13,
      "name": "Rock_Slate"
    },
    {
      "x": 5,
      "y": 6,
      "z": 14,
      "name": "Rock_Slate"
    },
    {
      "x": 5,
      "y": 7,
      "z": 14,
      "name": "Rock_Slate"
    },
    {
      "x": 5,
      "y": 8,
      "z": 14,
      "name": "Rock_Slate"
    },
    {
      "x": 5,
      "y": 9,
      "z": 14,
      "name": "Rock_Slate"
    },
    {
      "x": 5,
      "y": 10,
      "z": 14,
      "name": "Rock_Slate"
    },
    {
      "x": 5,
      "y": 6,
      "z": 15,
      "name": "Rock_Slate"
    },
    {
      "x": 5,
      "y": 7,
      "z": 15,
      "name": "Rock_Slate"
    },
    {
      "x": 5,
      "y": 8,
      "z": 15,
      "name": "Rock_Slate"
    },
    {
      "x": 5,
      "y": 9,
      "z": 15,
      "name": "Rock_Slate"
    },
    {
      "x": 5,
      "y": 10,
      "z": 15,
      "name": "Rock_Slate"
    },
    {
      "x": 6,
      "y": 6,
      "z": 7,
      "name": "Rock_Slate"
    },
    {
      "x": 6,
      "y": 7,
      "z": 7,
      "name": "Rock_Slate"
    },
    {
      "x": 6,
      "y": 8,
      "z": 7,
      "name": "Rock_Slate"
    },
    {
      "x": 6,
      "y": 9,
      "z": 7,
      "name": "Rock_Slate"
    },
    {
      "x": 6,
      "y": 10,
      "z": 7,
      "name": "Rock_Slate"
    },
    {
      "x": 6,
      "y": 6,
      "z": 8,
      "name": "Rock_Slate"
    },
    {
      "x": 6,
      "y": 7,
      "z": 8,
      "name": "Empty"
    },
    {
      "x": 6,
      "y": 8,
      "z": 8,
      "name": "Empty"
    },
    {
      "x": 6,
      "y": 9,
      "z": 8,
      "name": "Empty"
    },
    {
      "x": 6,
      "y": 10,
      "z": 8,
      "name": "Rock_Slate"
    },
    {
      "x": 6,
      "y": 6,
      "z": 9,
      "name": "Rock_Slate"
    },
    {
      "x": 6,
      "y": 7,
      "z": 9,
      "name": "Empty"
    },
    {
      "x": 6,
      "y": 8,
      "z": 9,
      "name": "Empty"
    },
    {
      "x": 6,
      "y": 9,
      "z": 9,
      "name": "Empty"
    },
    {
      "x": 6,
      "y": 10,
      "z": 9,
      "name": "Rock_Slate"
    },
    {
      "x": 6,
      "y": 6,
      "z": 10,
      "name": "Rock_Slate"
    },
    {
      "x": 6,
      "y": 7,
      "z": 10,
      "name": "Empty"
    },
    {
      "x": 6,
      "y": 8,
      "z": 10,
      "name": "Empty"
    },
    {
      "x": 6,
      "y": 9,
      "z": 10,
      "name": "Empty"
    },
    {
      "x": 6,
      "y": 10,
      "z": 10,
      "name": "Rock_Slate"
    },
    {
      "x": 6,
      "y": 6,
      "z": 11,
      "name": "Rock_Slate"
    },
    {
      "x": 6,
      "y": 7,
      "z": 11,
      "name": "Rock_Slate"
    },
    {
      "x": 6,
      "y": 8,
      "z": 11,
      "name": "Rock_Slate"
    },
    {
      "x": 6,
      "y": 9,
      "z": 11,
      "name": "Rock_Slate"
    },
    {
      "x": 6,
      "y": 10,
      "z": 11,
      "name": "Rock_Slate"
    },
    {
      "x": 7,
      "y": 6,
      "z": 7,
      "name": "Rock_Slate"
    },
    {
      "x": 7,
      "y": 7,
      "z": 7,
      "name": "Rock_Slate"
    },
    {
      "x": 7,
      "y": 8,
      "z": 7,
      "name": "Rock_Slate"
    },
    {
      "x": 7,
      "y": 9,
      "z": 7,
      "name": "Rock_Slate"
    },
    {
      "x": 7,
      "y": 10,
      "z": 7,
      "name": "Rock_Slate"
    },
    {
      "x": 7,
      "y": 6,
      "z": 8,
      "name": "Rock_Slate"
    },
    {
      "x": 7,
      "y": 7,
      "z": 8,
      "name": "Empty"
    },
    {
      "x": 7,
      "y": 8,
      "z": 8,
      "name": "Empty"
    },
    {
      "x": 7,
      "y": 9,
      "z": 8,
      "name": "Empty"
    },
    {
      "x": 7,
      "y": 10,
      "z": 8,
      "name": "Rock_Slate"
    },
    {
      "x": 7,
      "y": 6,
      "z": 9,
      "name": "Rock_Slate"
    },
    {
      "x": 7,
      "y": 7,
      "z": 9,
      "name": "Empty"
    },
    {
      "x": 7,
      "y": 8,
      "z": 9,
      "name": "Empty"
    },
    {
      "x": 7,
      "y": 9,
      "z": 9,
      "name": "Empty"
    },
    {
      "x": 7,
      "y": 10,
      "z": 9,
      "name": "Rock_Slate"
    },
    {
      "x": 7,
      "y": 6,
      "z": 10,
      "name": "Rock_Slate"
    },
    {
      "x": 7,
      "y": 7,
      "z": 10,
      "name": "Empty"
    },
    {
      "x": 7,
      "y": 8,
      "z": 10,
      "name": "Empty"
    },
    {
      "x": 7,
      "y": 9,
      "z": 10,
      "name": "Empty"
    },
    {
      "x": 7,
      "y": 10,
      "z": 10,
      "name": "Rock_Slate"
    },
    {
      "x": 7,
      "y": 6,
      "z": 11,
      "name": "Rock_Slate"
    },
    {
      "x": 7,
      "y": 7,
      "z": 11,
      "name": "Rock_Slate"
    },
    {
      "x": 7,
      "y": 8,
      "z": 11,
      "name": "Rock_Slate"
    },
    {
      "x": 7,
      "y": 9,
      "z": 11,
      "name": "Rock_Slate"
    },
    {
      "x": 7,
      "y": 10,
      "z": 11,
      "name": "Rock_Slate"
    },
    {
      "x": 8,
      "y": 6,
      "z": 7,
      "name": "Rock_Slate"
    },
    {
      "x": 8,
      "y": 7,
      "z": 7,
      "name": "Rock_Slate"
    },
    {
      "x": 8,
      "y": 8,
      "z": 7,
      "name": "Rock_Slate"
    },
    {
      "x": 8,
      "y": 9,
      "z": 7,
      "name": "Rock_Slate"
    },
    {
      "x": 8,
      "y": 10,
      "z": 7,
      "name": "Rock_Slate"
    },
    {
      "x": 8,
      "y": 6,
      "z": 8,
      "name": "Rock_Slate"
    },
    {
      "x": 8,
      "y": 7,
      "z": 8,
      "name": "Empty"
    },
    {
      "x": 8,
      "y": 8,
      "z": 8,
      "name": "Empty"
    },
    {
      "x": 8,
      "y": 9,
      "z": 8,
      "name": "Empty"
    },
    {
      "x": 8,
      "y": 10,
      "z": 8,
      "name": "Rock_Slate"
    },
    {
      "x": 8,
      "y": 6,
      "z": 9,
      "name": "Rock_Slate"
    },
    {
      "x": 8,
      "y": 7,
      "z": 9,
      "name": "Empty"
    },
    {
      "x": 8,
      "y": 8,
      "z": 9,
      "name": "Empty"
    },
    {
      "x": 8,
      "y": 9,
      "z": 9,
      "name": "Empty"
    },
    {
      "x": 8,
      "y": 10,
      "z": 9,
      "name": "Rock_Slate"
    },
    {
      "x": 8,
      "y": 6,
      "z": 10,
      "name": "Rock_Slate"
    },
    {
      "x": 8,
      "y": 7,
      "z": 10,
      "name": "Empty"
    },
    {
      "x": 8,
      "y": 8,
      "z": 10,
      "name": "Empty"
    },
    {
      "x": 8,
      "y": 9,
      "z": 10,
      "name": "Empty"
    },
    {
      "x": 8,
      "y": 10,
      "z": 10,
      "name": "Rock_Slate"
    },
    {
      "x": 8,
      "y": 6,
      "z": 11,
      "name": "Rock_Slate"
    },
    {
      "x": 8,
      "y": 7,
      "z": 11,
      "name": "Rock_Slate"
    },
    {
      "x": 8,
      "y": 8,
      "z": 11,
      "name": "Rock_Slate"
    },
    {
      "x": 8,
      "y": 9,
      "z": 11,
      "name": "Rock_Slate"
    },
    {
      "x": 8,
      "y": 10,
      "z": 11,
      "name": "Rock_Slate"
    },
    {
      "x": 9,
      "y": 6,
      "z": 7,
      "name": "Rock_Slate"
    },
    {
      "x": 9,
      "y": 7,
      "z": 7,
      "name": "Rock_Slate"
    },
    {
      "x": 9,
      "y": 8,
      "z": 7,
      "name": "Rock_Slate"
    },
    {
      "x": 9,
      "y": 9,
      "z": 7,
      "name": "Rock_Slate"
    },
    {
      "x": 9,
      "y": 10,
      "z": 7,
      "name": "Rock_Slate"
    },
    {
      "x": 9,
      "y": 6,
      "z": 8,
      "name": "Rock_Slate"
    },
    {
      "x": 9,
      "y": 7,
      "z": 8,
      "name": "Empty"
    },
    {
      "x": 9,
      "y": 8,
      "z": 8,
      "name": "Empty"
    },
    {
      "x": 9,
      "y": 9,
      "z": 8,
      "name": "Empty"
    },
    {
      "x": 9,
      "y": 10,
      "z": 8,
      "name": "Rock_Slate"
    },
    {
      "x": 9,
      "y": 6,
      "z": 9,
      "name": "Rock_Slate"
    },
    {
      "x": 9,
      "y": 7,
      "z": 9,
      "name": "Empty"
    },
    {
      "x": 9,
      "y": 8,
      "z": 9,
      "name": "Empty"
    },
    {
      "x": 9,
      "y": 9,
      "z": 9,
      "name": "Empty"
    },
    {
      "x": 9,
      "y": 10,
      "z": 9,
      "name": "Rock_Slate"
    },
    {
      "x": 9,
      "y": 6,
      "z": 10,
      "name": "Rock_Slate"
    },
    {
      "x": 9,
      "y": 7,
      "z": 10,
      "name": "Empty"
    },
    {
      "x": 9,
      "y": 8,
      "z": 10,
      "name": "Empty"
    },
    {
      "x": 9,
      "y": 9,
      "z": 10,
      "name": "Empty"
    },
    {
      "x": 9,
      "y": 10,
      "z": 10,
      "name": "Rock_Slate"
    },
    {
      "x": 9,
      "y": 6,
      "z": 11,
      "name": "Rock_Slate"
    },
    {
      "x": 9,
      "y": 7,
      "z": 11,
      "name": "Rock_Slate"
    },
    {
      "x": 9,
      "y": 8,
      "z": 11,
      "name": "Rock_Slate"
    },
    {
      "x": 9,
      "y": 9,
      "z": 11,
      "name": "Rock_Slate"
    },
    {
      "x": 9,
      "y": 10,
      "z": 11,
      "name": "Rock_Slate"
    },
    {
      "x": 10,
      "y": 7,
      "z": 8,
      "name": "Empty"
    },
    {
      "x": 10,
      "y": 8,
      "z": 8,
      "name": "Empty"
    },
    {
      "x": 10,
      "y": 9,
      "z": 8,
      "name": "Empty"
    },
    {
      "x": 10,
      "y": 7,
      "z": 9,
      "name": "Empty"
    },
    {
      "x": 10,
      "y": 8,
      "z": 9,
      "name": "Empty"
    },
    {
      "x": 10,
      "y": 9,
      "z": 9,
      "name": "Empty"
    },
    {
      "x": 10,
      "y": 7,
      "z": 10,
      "name": "Empty"
    },
    {
      "x": 10,
      "y": 8,
      "z": 10,
      "name": "Empty"
    },
    {
      "x": 10,
      "y": 9,
      "z": 10,
      "name": "Empty"
    }
  ]
}