{
  "version": 8,
  "blockIdVersion": 8,
  "anchorX": 1,
  "anchorY": 4,
  "anchorZ": 0,
  "blocks": [
    {
      "x": -2,
      "y": 4,
      "z": -2,
      "name": "Rock_Slate_Cobble"
    },
    {
      "x": -2,
      "y": 5,
      "z": -2,
      "name": "Rock_Slate_Cobble"
    },
    {
      "x": -2,
      "y": 6,
      "z": -2,
      "name": "Rock_Slate_Cobble"
    },
    {
      "x": -2,
      "y": 4,
      "z": -1,
      "name": "Rock_Slate_Cobble"
    },
    {
      "x": -2,
      "y": 5,
      "z": -1,
      "name": "Rock_Slate_Cobble"
    },
    {
      "x": -2,
      "y": 3,
      "z": 0,
      "name": "Rock_Slate_Cobble"
    },
    {
      "x": -2,
      "y": 4,
      "z": 0,
      "name": "Rock_Slate_Cobble"
    },
    {
      "x": -2,
      "y": 5,
      "z": 0,
      "name": "Rock_Slate_Cobble"
    },
    {
      "x": -2,
      "y": 3,
      "z": 1,
      "name": "Rock_Slate_Cobble"
    },
    {
      "x": -2,
      "y": 3,
      "z": 2,
      "name": "Rock_Slate_Cobble"
    },
    {
      "x": -2,
      "y": 4,
      "z": 2,
      "name": "Rock_Slate"
    },
    {
      "x": -2,
      "y": 5,
      "z": 3,
      "name": "Rock_Slate"
    },
    {
      "x": -2,
      "y": 6,
      "z": 3,
      "name": "Rock_Slate"
    },
    {
      "x": -1,
      "y": 2,
      "z": -1,
      "name": "Rock_Slate_Cobble"
    },
    {
      "x": -1,
      "y": 3,
      "z": -1,
      "name": "Rock_Slate_Cobble"
    },
    {
      "x": -1,
      "y": 4,
      "z": -1,
      "name": "Rock_Crystal_Blue_Block"
    },
    {
      "x": -1,
      "y": 5,
      "z": -1,
      "name": "Rock_Crystal_Blue_Block"
    },
    {
      "x": -1,
      "y": 6,
      "z": -1,
      "name": "Rock_Crystal_Blue_Block"
    },
    {
      "x": -1,
      "y": 7,
      "z": -1,
      "name": "Rock_Crystal_Blue_Block"
    },
    {
      "x": -1,
      "y": 8,
      "z": -1,
      "name": "Rock_Crystal_Blue_Block"
    },
    {
      "x": -1,
      "y": 1,
      "z": 0,
      "name": "Rock_Slate_Cobble"
    },
    {
      "x": -1,
      "y": 2,
      "z": 0,
      "name": "Rock_Slate_Cobble"
    },
    {
      "x": -1,
      "y": 3,
      "z": 0,
      "name": "Rock_Slate_Cobble"
    },
    {
      "x": -1,
      "y": 4,
      "z": 0,
      "name": "Rock_Slate_Cobble"
    },
    {
      "x": -1,
      "y": 5,
      "z": 0,
      "name": "Rock_Slate_Cobble"
    },
    {
      "x": -1,
      "y": 6,
      "z": 0,
      "name": "Rock_Crystal_Blue_Block"
    },
    {
      "x": -1,
      "y": 7,
      "z": 0,
      "name": "Rock_Crystal_Blue_Block"
    },
    {
      "x": -1,
      "y": 8,
      "z": 0,
      "name": "Rock_Crystal_Blue_Block"
    },
    {
      "x": -1,
      "y": 9,
      "z": 0,
      "name": "Rock_Crystal_Blue_Block"
    },
    {
      "x": -1,
      "y": 1,
      "z": 1,
      "name": "Rock_Slate_Cobble"
    },
    {
      "x": -1,
      "y": 2,
      "z": 1,
      "name": "Rock_Slate_Cobble"
    },
    {
      "x": -1,
      "y": 3,
      "z": 1,
      "name": "Rock_Slate_Cobble"
    },
    {
      "x": -1,
      "y": 4,
      "z": 1,
      "name": "Rock_Crystal_Blue_Block"
    },
    {
      "x": -1,
      "y": 5,
      "z": 1,
      "name": "Rock_Crystal_Blue_Block"
    },
    {
      "x": -1,
      "y": 6,
      "z": 1,
      "name": "Rock_Crystal_Blue_Block"
    },
    {
      "x": -1,
      "y": 7,
      "z": 1,
      "name": "Rock_Crystal_Blue_Block"
    },
    {
      "x": -1,
      "y": 8,
      "z": 1,
      "name": "Rock_Crystal_Blue_Small"
    },
    {
      "x": -1,
      "y": 1,
      "z": 2,
      "name": "Rock_Slate_Cobble"
    },
    {
      "x": -1,
      "y": 2,
      "z": 2,
      "name": "Rock_Slate_Cobble"
    },
    {
      "x": -1,
      "y": 3,
      "z": 2,
      "name": "Rock_Slate_Cobble"
    },
    {
      "x": -1,
      "y": 4,
      "z": 2,
      "name": "Rock_Slate"
    },
    {
      "x": -1,
      "y": 5,
      "z": 2,
      "name": "Rock_Crystal_Blue_Block"
    },
    {
      "x": -1,
      "y": 6,
      "z": 2,
      "name": "Rock_Crystal_Blue_Block"
    },
    {
      "x": -1,
      "y": 7,
      "z": 2,
      "name": "Rock_Crystal_Blue_Block"
    },
    {
      "x": -1,
      "y": 1,
      "z": 3,
      "name": "Rock_Slate_Cobble"
    },
    {
      "x": -1,
      "y": 2,
      "z": 3,
      "name": "Rock_Slate_Cobble"
    },
    {
      "x": -1,
      "y": 3,
      "z": 3,
      "name": "Rock_Slate_Cobble"
    },
    {
      "x": -1,
      "y": 4,
      "z": 3,
      "name": "Rock_Slate"
    },
    {
      "x": -1,
      "y": 5,
      "z": 3,
      "name": "Rock_Slate"
    },
    {
      "x": 0,
      "y": 2,
      "z": -2,
      "name": "Rock_Slate_Cobble"
    },
    {
      "x": 0,
      "y": 3,
      "z": -2,
      "name": "Rock_Slate_Cobble"
    },
    {
      "x": 0,
      "y": 4,
      "z": -2,
      "name": "Rock_Slate_Cobble"
    },
    {
      "x": 0,
      "y": 1,
      "z": -1,
      "name": "Rock_Slate_Cobble"
    },
    {
      "x": 0,
      "y": 2,
      "z": -1,
      "name": "Rock_Slate_Cobble"
    },
    {
      "x": 0,
      "y": 3,
      "z": -1,
      "name": "Rock_Slate_Cobble"
    },
    {
      "x": 0,
      "y": 4,
      "z": -1,
      "name": "Rock_Slate_Cobble"
    },
    {
      "x": 0,
      "y": 5,
      "z": -1,
      "name": "Rock_Crystal_Blue_Block"
    },
    {
      "x": 0,
      "y": 6,
      "z": -1,
      "name": "Rock_Crystal_Blue_Block"
    },
    {
      "x": 0,
      "y": 7,
      "z": -1,
      "name": "Rock_Crystal_Blue_Block"
    },
    {
      "x": 0,
      "y": 8,
      "z": -1,
      "name": "Rock_Crystal_Blue_Block"
    },
    {
      "x": 0,
      "y": 9,
      "z": -1,
      "name": "Rock_Crystal_Blue_Block"
    },
    {
      "x": 0,
      "y": 10,
      "z": -1,
      "name": "Rock_Crystal_Blue_Small"
    },
    {
      "x": 0,
      "y": 1,
      "z": 0,
      "name": "Rock_Slate_Cobble"
    },
    {
      "x": 0,
      "y": 2,
      "z": 0,
      "name": "Rock_Slate_Cobble"
    },
    {
      "x": 0,
      "y": 3,
      "z": 0,
      "name": "Rock_Slate_Cobble"
    },
    {
      "x": 0,
      "y": 4,
      "z": 0,
      "name": "Rock_Slate_Cobble"
    },
    {
      "x": 0,
      "y": 5,
      "z": 0,
      "name": "Rock_Crystal_Blue_Block"
    },
    {
      "x": 0,
      "y": 6,
      "z": 0,
      "name": "Rock_Crystal_Blue_Block"
    },
    {
      "x": 0,
      "y": 7,
      "z": 0,
      "name": "Rock_Crystal_Blue_Block"
    },
    {
      "x": 0,
      "y": 8,
      "z": 0,
      "name": "Rock_Crystal_Blue_Block"
    },
    {
      "x": 0,
      "y": 9,
      "z": 0,
      "name": "Rock_Crystal_Blue_Block"
    },
    {
      "x": 0,
      "y": 10,
      "z": 0,
      "name": "Rock_Crystal_Blue_Small"
    },
    {
      "x": 0,
      "y": 1,
      "z": 1,
      "name": "Rock_Slate_Cobble"
    },
    {
      "x": 0,
      "y": 2,
      "z": 1,
      "name": "Rock_Slate_Cobble"
    },
    {
      "x": 0,
      "y": 3,
      "z": 1,
      "name": "Rock_Slate_Cobble"
    },
    {
      "x": 0,
      "y": 4,
      "z": 1,
      "name": "Rock_Slate_Cobble"
    },
    {
      "x": 0,
      "y": 5,
      "z": 1,
      "name": "Rock_Crystal_Blue_Block"
    },
    {
      "x": 0,
      "y": 6,
      "z": 1,
      "name": "Rock_Crystal_Blue_Block"
    },
    {
      "x": 0,
      "y": 7,
      "z": 1,
      "name": "Rock_Crystal_Blue_Block"
    },
    {
      "x": 0,
      "y": 8,
      "z": 1,
      "name": "Rock_Crystal_Blue_Block"
    },
    {
      "x": 0,
      "y": 9,
      "z": 1,
      "name": "Rock_Crystal_Blue_Block"
    },
    {
      "x": 0,
      "y": 10,
      "z": 1,
      "name": "Rock_Crystal_Blue_Block"
    },
    {
      "x": 0,
      "y": 11,
      "z": 1,
      "name": "Rock_Crystal_Blue_Medium"
    },
    {
      "x": 0,
      "y": 1,
      "z": 2,
      "name": "Rock_Slate_Cobble"
    },
    {
      "x": 0,
      "y": 2,
      "z": 2,
      "name": "Rock_Slate_Cobble"
    },
    {
      "x": 0,
      "y": 3,
      "z": 2,
      "name": "Rock_Slate_Cobble"
    },
    {
      "x": 0,
      "y": 4,
      "z": 2,
      "name": "Rock_Slate"
    },
    {
      "x": 0,
      "y": 5,
      "z": 2,
      "name": "Rock_Crystal_Blue_Block"
    },
    {
      "x": 0,
      "y": 6,
      "z": 2,
      "name": "Rock_Crystal_Blue_Block"
    },
    {
      "x": 0,
      "y": 7,
      "z": 2,
      "name": "Rock_Crystal_Blue_Block"
    },
    {
      "x": 0,
      "y": 8,
      "z": 2,
      "name": "Rock_Crystal_Blue_Block"
    },
    {
      "x": 0,
      "y": 9,
      "z": 2,
      "name": "Rock_Crystal_Blue_Block"
    },
    {
      "x": 0,
      "y": 10,
      "z": 2,
      "name": "Rock_Crystal_Blue_Medium"
    },
    {
      "x": 0,
      "y": 1,
      "z": 3,
      "name": "Rock_Slate_Cobble"
    },
    {
      "x": 0,
      "y": 2,
      "z": 3,
      "name": "Rock_Slate_Cobble"
    },
    {
      "x": 0,
      "y": 3,
      "z": 3,
      "name": "Rock_Slate_Cobble"
    },
    {
      "x": 0,
      "y": 4,
      "z": 3,
      "name": "Rock_Slate"
    },
    {
      "x": 1,
      "y": 2,
      "z": -2,
      "name": "Rock_Slate_Cobble"
    },
    {
      "x": 1,
      "y": 3,
      "z": -2,
      "name": "Rock_Slate_Cobble"
    },
    {
      "x": 1,
      "y": 4,
      "z": -2,
      "name": "Rock_Slate_Cobble"
    },
    {
      "x": 1,
      "y": 5,
      "z": -2,
      "name": "Rock_Slate_Cobble"
    },
    {
      "x": 1,
      "y": 6,
      "z": -2,
      "name": "Rock_Slate"
    },
    {
      "x": 1,
      "y": 7,
      "z": -2,
      "name": "Rock_Slate"
    },
    {
      "x": 1,
      "y": 8,
      "z": -2,
      "name": "Rock_Slate"
    },
    {
      "x": 1,
      "y": 9,
      "z": -2,
      "name": "Rock_Slate"
    },
    {
      "x": 1,
      "y": 1,
      "z": -1,
      "name": "Rock_Slate_Cobble"
    },
    {
      "x": 1,
      "y": 2,
      "z": -1,
      "name": "Rock_Slate_Cobble"
    },
    {
      "x": 1,
      "y": 3,
      "z": -1,
      "name": "Rock_Slate_Cobble"
    },
    {
      "x": 1,
      "y": 4,
      "z": -1,
      "name": "Rock_Slate_Cobble"
    },
    {
      "x": 1,
      "y": 5,
      "z": -1,
      "name": "Rock_Slate_Cobble"
    },
    {
      "x": 1,
      "y": 6,
      "z": -1,
      "name": "Rock_Slate"
    },
    {
      "x": 1,
      "y": 7,
      "z": -1,
      "name": "Rock_Slate"
    },
    {
      "x": 1,
      "y": 8,
      "z": -1,
      "name": "Rock_Slate"
    },
    {
      "x": 1,
      "y": 9,
      "z": -1,
      "name": "Rock_Slate"
    },
    {
      "x": 1,
      "y": 1,
      "z": 0,
      "name": "Rock_Slate_Cobble"
    },
    {
      "x": 1,
      "y": 2,
      "z": 0,
      "name": "Rock_Slate_Cobble"
    },
    {
      "x": 1,
      "y": 3,
      "z": 0,
      "name": "Rock_Slate_Cobble"
    },
    {
      "x": 1,
      "y": 4,
      "z": 0,
      "name": "Rock_Crystal_Blue_Block"
    },
    {
      "x": 1,
      "y": 5,
      "z": 0,
      "name": "Rock_Slate"
    },
    {
      "x": 1,
      "y": 6,
      "z": 0,
      "name": "Rock_Crystal_Blue_Block"
    },
    {
      "x": 1,
      "y": 7,
      "z": 0,
      "name": "Rock_Crystal_Blue_Block"
    },
    {
      "x": 1,
      "y": 8,
      "z": 0,
      "name": "Rock_Crystal_Blue_Block"
    },
    {
      "x": 1,
      "y": 9,
      "z": 0,
      "name": "Rock_Crystal_Blue_Block"
    },
    {
      "x": 1,
      "y": 10,
      "z": 0,
      "name": "Rock_Crystal_Blue_Block"
    },
    {
      "x": 1,
      "y": 1,
      "z": 1,
      "name": "Rock_Slate_Cobble"
    },
    {
      "x": 1,
      "y": 2,
      "z": 1,
      "name": "Rock_Slate_Cobble"
    },
    {
      "x": 1,
      "y": 3,
      "z": 1,
      "name": "Rock_Slate_Cobble"
    },
    {
      "x": 1,
      "y": 4,
      "z": 1,
      "name": "Rock_Crystal_Blue_Block"
    },
    {
      "x": 1,
      "y": 5,
      "z": 1,
      "name": "Rock_Crystal_Blue_Block"
    },
    {
      "x": 1,
      "y": 6,
      "z": 1,
      "name": "Rock_Crystal_Blue_Block"
    },
    {
      "x": 1,
      "y": 7,
      "z": 1,
      "name": "Rock_Crystal_Blue_Block"
    },
    {
      "x": 1,
      "y": 8,
      "z": 1,
      "name": "Rock_Crystal_Blue_Block"
    },
    {
      "x": 1,
      "y": 9,
      "z": 1,
      "name": "Rock_Crystal_Blue_Block"
    },
    {
      "x": 1,
      "y": 10,
      "z": 1,
      "name": "Rock_Crystal_Blue_Block"
    },
    {
      "x": 1,
      "y": 11,
      "z": 1,
      "name": "Rock_Crystal_Blue_Large"
    },
    {
      "x": 1,
      "y": 1,
      "z": 2,
      "name": "Rock_Slate_Cobble"
    },
    {
      "x": 1,
      "y": 2,
      "z": 2,
      "name": "Rock_Slate_Cobble"
    },
    {
      "x": 1,
      "y": 3,
      "z": 2,
      "name": "Rock_Slate_Cobble"
    },
    {
      "x": 1,
      "y": 4,
      "z": 2,
      "name": "Rock_Slate"
    },
    {
      "x": 1,
      "y": 5,
      "z": 2,
      "name": "Rock_Crystal_Blue_Block"
    },
    {
      "x": 1,
      "y": 6,
      "z": 2,
      "name": "Rock_Crystal_Blue_Block"
    },
    {
      "x": 1,
      "y": 7,
      "z": 2,
      "name": "Rock_Crystal_Blue_Block"
    },
    {
      "x": 1,
      "y": 2,
      "z": 3,
      "name": "Rock_Slate_Cobble"
    },
    {
      "x": 1,
      "y": 3,
      "z": 3,
      "name": "Rock_Slate"
    },
    {
      "x": 1,
      "y": 4,
      "z": 3,
      "name": "Rock_Slate"
    },
    {
      "x": 2,
      "y": 4,
      "z": -2,
      "name": "Rock_Slate_Cobble"
    },
    {
      "x": 2,
      "y": 5,
      "z": -2,
      "name": "Rock_Slate_Cobble"
    },
    {
      "x": 2,
      "y": 6,
      "z": -2,
      "name": "Rock_Slate"
    },
    {
      "x": 2,
      "y": 7,
      "z": -2,
      "name": "Rock_Slate"
    },
    {
      "x": 2,
      "y": 3,
      "z": -1,
      "name": "Rock_Slate_Cobble"
    },
    {
      "x": 2,
      "y": 4,
      "z": -1,
      "name": "Rock_Slate_Cobble"
    },
    {
      "x": 2,
      "y": 5,
      "z": -1,
      "name": "Rock_Slate"
    },
    {
      "x": 2,
      "y": 6,
      "z": -1,
      "name": "Rock_Slate"
    },
    {
      "x": 2,
      "y": 7,
      "z": -1,
      "name": "Rock_Slate"
    },
    {
      "x": 2,
      "y": 8,
      "z": -1,
      "name": "Rock_Slate"
    },
    {
      "x": 2,
      "y": 9,
      "z": -1,
      "name": "Rock_Slate"
    },
    {
      "x": 2,
      "y": 2,
      "z": 0,
      "name": "Rock_Slate_Cobble"
    },
    {
      "x": 2,
      "y": 3,
      "z": 0,
      "name": "Rock_Slate_Cobble"
    },
    {
      "x": 2,
      "y": 4,
      "z": 0,
      "name": "Rock_Slate_Cobble"
    },
    {
      "x": 2,
      "y": 5,
      "z": 0,
      "name": "Rock_Slate"
    },
    {
      "x": 2,
      "y": 8,
      "z": 0,
      "name": "Rock_Slate"
    },
    {
      "x": 2,
      "y": 9,
      "z": 0,
      "name": "Rock_Slate"
    },
    {
      "x": 2,
      "y": 1,
      "z": 1,
      "name": "Rock_Slate_Cobble"
    },
    {
      "x": 2,
      "y": 2,
      "z": 1,
      "name": "Rock_Slate_Cobble"
    },
    {
      "x": 2,
      "y": 3,
      "z": 1,
      "name": "Rock_Slate_Cobble"
    },
    {
      "x": 2,
      "y": 1,
      "z": 2,
      "name": "Rock_Slate_Cobble"
    },
    {
      "x": 2,
      "y": 2,
      "z": 2,
      "name": "Rock_Slate_Cobble"
    },
    {
      "x": 2,
      "y": 3,
      "z": 2,
      "name": "Rock_Slate_Cobble"
    },
    {
      "x": 2,
      "y": 4,
      "z": 2,
      "name": "Rock_Slate"
    }
  ]
}