{
  "version": 8,
  "blockIdVersion": 8,
  "anchorX": 0,
  "anchorY": 4,
  "anchorZ": 1,
  "blocks": [
    {
      "x": -3,
      "y": 4,
      "z": -1,
      "name": "Rock_Slate"
    },
    {
      "x": -3,
      "y": 5,
      "z": -1,
      "name": "Rock_Slate"
    },
    {
      "x": -3,
      "y": 6,
      "z": -1,
      "name": "Rock_Slate"
    },
    {
      "x": -3,
      "y": 7,
      "z": -1,
      "name": "Rock_Slate"
    },
    {
      "x": -3,
      "y": 3,
      "z": 0,
      "name": "Rock_Slate_Cobble"
    },
    {
      "x": -3,
      "y": 4,
      "z": 0,
      "name": "Rock_Slate_Cobble"
    },
    {
      "x": -3,
      "y": 7,
      "z": 0,
      "name": "Rock_Slate"
    },
    {
      "x": -3,
      "y": 8,
      "z": 0,
      "name": "Rock_Slate"
    },
    {
      "x": -3,
      "y": 9,
      "z": 0,
      "name": "Rock_Slate"
    },
    {
      "x": -3,
      "y": 3,
      "z": 1,
      "name": "Rock_Slate_Cobble"
    },
    {
      "x": -3,
      "y": 4,
      "z": 1,
      "name": "Rock_Slate_Cobble"
    },
    {
      "x": -3,
      "y": 4,
      "z": 2,
      "name": "Rock_Slate_Cobble"
    },
    {
      "x": -3,
      "y": 5,
      "z": 2,
      "name": "Rock_Slate_Cobble"
    },
    {
      "x": -3,
      "y": 4,
      "z": 3,
      "name": "Rock_Slate_Cobble"
    },
    {
      "x": -3,
      "y": 5,
      "z": 3,
      "name": "Rock_Slate_Cobble"
    },
    {
      "x": -3,
      "y": 6,
      "z": 3,
      "name": "Rock_Slate_Cobble"
    },
    {
      "x": -3,
      "y": 7,
      "z": 3,
      "name": "Rock_Slate"
    },
    {
      "x": -2,
      "y": 3,
      "z": -1,
      "name": "Rock_Slate_Cobble"
    },
    {
      "x": -2,
      "y": 4,
      "z": -1,
      "name": "Rock_Slate_Cobble"
    },
    {
      "x": -2,
      "y": 5,
      "z": -1,
      "name": "Rock_Slate"
    },
    {
      "x": -2,
      "y": 6,
      "z": -1,
      "name": "Rock_Slate"
    },
    {
      "x": -2,
      "y": 7,
      "z": -1,
      "name": "Rock_Slate"
    },
    {
      "x": -2,
      "y": 8,
      "z": -1,
      "name": "Rock_Slate"
    },
    {
      "x": -2,
      "y": 3,
      "z": 0,
      "name": "Rock_Slate_Cobble"
    },
    {
      "x": -2,
      "y": 4,
      "z": 0,
      "name": "Rock_Slate_Cobble"
    },
    {
      "x": -2,
      "y": 5,
      "z": 0,
      "name": "Rock_Crystal_Blue_Block"
    },
    {
      "x": -2,
      "y": 6,
      "z": 0,
      "name": "Rock_Crystal_Blue_Block"
    },
    {
      "x": -2,
      "y": 7,
      "z": 0,
      "name": "Rock_Slate"
    },
    {
      "x": -2,
      "y": 8,
      "z": 0,
      "name": "Rock_Slate"
    },
    {
      "x": -2,
      "y": 9,
      "z": 0,
      "name": "Rock_Slate"
    },
    {
      "x": -2,
      "y": 3,
      "z": 1,
      "name": "Rock_Slate_Cobble"
    },
    {
      "x": -2,
      "y": 4,
      "z": 1,
      "name": "Rock_Slate_Cobble"
    },
    {
      "x": -2,
      "y": 5,
      "z": 1,
      "name": "Rock_Crystal_Blue_Block"
    },
    {
      "x": -2,
      "y": 6,
      "z": 1,
      "name": "Rock_Crystal_Blue_Block"
    },
    {
      "x": -2,
      "y": 7,
      "z": 1,
      "name": "Rock_Crystal_Blue_Block"
    },
    {
      "x": -2,
      "y": 8,
      "z": 1,
      "name": "Rock_Crystal_Blue_Block"
    },
    {
      "x": -2,
      "y": 9,
      "z": 1,
      "name": "Rock_Crystal_Blue_Block"
    },
    {
      "x": -2,
      "y": 10,
      "z": 1,
      "name": "Rock_Crystal_Blue_Block"
    },
    {
      "x": -2,
      "y": 11,
      "z": 1,
      "name": "Rock_Crystal_Blue_Block"
    },
    {
      "x": -2,
      "y": 3,
      "z": 2,
      "name": "Rock_Slate_Cobble"
    },
    {
      "x": -2,
      "y": 4,
      "z": 2,
      "name": "Rock_Slate_Cobble"
    },
    {
      "x": -2,
      "y": 5,
      "z": 2,
      "name": "Rock_Slate_Cobble"
    },
    {
      "x": -2,
      "y": 6,
      "z": 2,
      "name": "Rock_Crystal_Blue_Block"
    },
    {
      "x": -2,
      "y": 7,
      "z": 2,
      "name": "Rock_Crystal_Blue_Block"
    },
    {
      "x": -2,
      "y": 8,
      "z": 2,
      "name": "Rock_Crystal_Blue_Block"
    },
    {
      "x": -2,
      "y": 9,
      "z": 2,
      "name": "Rock_Crystal_Blue_Block"
    },
    {
      "x": -2,
      "y": 10,
      "z": 2,
      "name": "Rock_Crystal_Blue_Block"
    },
    {
      "x": -2,
      "y": 11,
      "z": 2,
      "name": "Rock_Crystal_Blue_Small"
    },
    {
      "x": -2,
      "y": 3,
      "z": 3,
      "name": "Rock_Slate_Cobble"
    },
    {
      "x": -2,
      "y": 4,
      "z": 3,
      "name": "Rock_Slate_Cobble"
    },
    {
      "x": -2,
      "y": 5,
      "z": 3,
      "name": "Rock_Slate_Cobble"
    },
    {
      "x": -2,
      "y": 6,
      "z": 3,
      "name": "Rock_Slate_Cobble"
    },
    {
      "x": -2,
      "y": 7,
      "z": 3,
      "name": "Rock_Slate"
    },
    {
      "x": -2,
      "y": 8,
      "z": 3,
      "name": "Rock_Slate"
    },
    {
      "x": -2,
      "y": 5,
      "z": 4,
      "name": "Rock_Slate_Cobble"
    },
    {
      "x": -2,
      "y": 6,
      "z": 4,
      "name": "Rock_Slate_Cobble"
    },
    {
      "x": -1,
      "y": 3,
      "z": -1,
      "name": "Rock_Slate_Cobble"
    },
    {
      "x": -1,
      "y": 4,
      "z": -1,
      "name": "Rock_Slate_Cobble"
    },
    {
      "x": -1,
      "y": 5,
      "z": -1,
      "name": "Rock_Slate_Cobble"
    },
    {
      "x": -1,
      "y": 6,
      "z": -1,
      "name": "Rock_Slate"
    },
    {
      "x": -1,
      "y": 7,
      "z": -1,
      "name": "Rock_Slate"
    },
    {
      "x": -1,
      "y": 8,
      "z": -1,
      "name": "Rock_Crystal_Blue_Block"
    },
    {
      "x": -1,
      "y": 9,
      "z": -1,
      "name": "Rock_Crystal_Blue_Block"
    },
    {
      "x": -1,
      "y": 10,
      "z": -1,
      "name": "Rock_Crystal_Blue_Block"
    },
    {
      "x": -1,
      "y": 11,
      "z": -1,
      "name": "Rock_Crystal_Blue_Block"
    },
    {
      "x": -1,
      "y": 3,
      "z": 0,
      "name": "Rock_Slate_Cobble"
    },
    {
      "x": -1,
      "y": 4,
      "z": 0,
      "name": "Rock_Slate_Cobble"
    },
    {
      "x": -1,
      "y": 5,
      "z": 0,
      "name": "Rock_Slate_Cobble"
    },
    {
      "x": -1,
      "y": 6,
      "z": 0,
      "name": "Rock_Slate"
    },
    {
      "x": -1,
      "y": 7,
      "z": 0,
      "name": "Rock_Slate"
    },
    {
      "x": -1,
      "y": 8,
      "z": 0,
      "name": "Rock_Crystal_Blue_Block"
    },
    {
      "x": -1,
      "y": 9,
      "z": 0,
      "name": "Rock_Crystal_Blue_Block"
    },
    {
      "x": -1,
      "y": 10,
      "z": 0,
      "name": "Rock_Crystal_Blue_Block"
    },
    {
      "x": -1,
      "y": 11,
      "z": 0,
      "name": "Rock_Crystal_Blue_Block"
    },
    {
      "x": -1,
      "y": 12,
      "z": 0,
      "name": "Rock_Crystal_Blue_Small"
    },
    {
      "x": -1,
      "y": 3,
      "z": 1,
      "name": "Rock_Slate_Cobble"
    },
    {
      "x": -1,
      "y": 4,
      "z": 1,
      "name": "Rock_Slate_Cobble"
    },
    {
      "x": -1,
      "y": 5,
      "z": 1,
      "name": "Rock_Slate_Cobble"
    },
    {
      "x": -1,
      "y": 6,
      "z": 1,
      "name": "Rock_Slate"
    },
    {
      "x": -1,
      "y": 7,
      "z": 1,
      "name": "Rock_Crystal_Blue_Block"
    },
    {
      "x": -1,
      "y": 8,
      "z": 1,
      "name": "Rock_Crystal_Blue_Block"
    },
    {
      "x": -1,
      "y": 9,
      "z": 1,
      "name": "Rock_Crystal_Blue_Block"
    },
    {
      "x": -1,
      "y": 10,
      "z": 1,
      "name": "Rock_Crystal_Blue_Block"
    },
    {
      "x": -1,
      "y": 11,
      "z": 1,
      "name": "Rock_Crystal_Blue_Block"
    },
    {
      "x": -1,
      "y": 12,
      "z": 1,
      "name": "Rock_Crystal_Blue_Block"
    },
    {
      "x": -1,
      "y": 13,
      "z": 1,
      "name": "Rock_Crystal_Blue_Large"
    },
    {
      "x": -1,
      "y": 3,
      "z": 2,
      "name": "Rock_Slate_Cobble"
    },
    {
      "x": -1,
      "y": 4,
      "z": 2,
      "name": "Rock_Slate_Cobble"
    },
    {
      "x": -1,
      "y": 5,
      "z": 2,
      "name": "Rock_Slate_Cobble"
    },
    {
      "x": -1,
      "y": 6,
      "z": 2,
      "name": "Rock_Slate"
    },
    {
      "x": -1,
      "y": 7,
      "z": 2,
      "name": "Rock_Crystal_Blue_Block"
    },
    {
      "x": -1,
      "y": 8,
      "z": 2,
      "name": "Rock_Crystal_Blue_Block"
    },
    {
      "x": -1,
      "y": 9,
      "z": 2,
      "name": "Rock_Crystal_Blue_Block"
    },
    {
      "x": -1,
      "y": 10,
      "z": 2,
      "name": "Rock_Crystal_Blue_Block"
    },
    {
      "x": -1,
      "y": 11,
      "z": 2,
      "name": "Rock_Crystal_Blue_Block"
    },
    {
      "x": -1,
      "y": 12,
      "z": 2,
      "name": "Rock_Crystal_Blue_Block"
    },
    {
      "x": -1,
      "y": 13,
      "z": 2,
      "name": "Rock_Crystal_Blue_Medium"
    },
    {
      "x": -1,
      "y": 3,
      "z": 3,
      "name": "Rock_Slate_Cobble"
    },
    {
      "x": -1,
      "y": 4,
      "z": 3,
      "name": "Rock_Slate_Cobble"
    },
    {
      "x": -1,
      "y": 5,
      "z": 3,
      "name": "Rock_Slate_Cobble"
    },
    {
      "x": -1,
      "y": 6,
      "z": 3,
      "name": "Rock_Slate"
    },
    {
      "x": -1,
      "y": 7,
      "z": 3,
      "name": "Rock_Crystal_Blue_Block"
    },
    {
      "x": -1,
      "y": 8,
      "z": 3,
      "name": "Rock_Crystal_Blue_Block"
    },
    {
      "x": -1,
      "y": 9,
      "z": 3,
      "name": "Rock_Crystal_Blue_Block"
    },
    {
      "x": -1,
      "y": 10,
      "z": 3,
      "name": "Rock_Crystal_Blue_Block"
    },
    {
      "x": -1,
      "y": 11,
      "z": 3,
      "name": "Rock_Crystal_Blue_Block"
    },
    {
      "x": -1,
      "y": 4,
      "z": 4,
      "name": "Rock_Slate_Cobble"
    },
    {
      "x": -1,
      "y": 5,
      "z": 4,
      "name": "Rock_Slate_Cobble"
    },
    {
      "x": -1,
      "y": 6,
      "z": 4,
      "name": "Rock_Slate"
    },
    {
      "x": 0,
      "y": 5,
      "z": -2,
      "name": "Rock_Slate"
    },
    {
      "x": 0,
      "y": 6,
      "z": -2,
      "name": "Rock_Slate"
    },
    {
      "x": 0,
      "y": 4,
      "z": -1,
      "name": "Rock_Slate_Cobble"
    },
    {
      "x": 0,
      "y": 5,
      "z": -1,
      "name": "Rock_Crystal_Blue_Block"
    },
    {
      "x": 0,
      "y": 6,
      "z": -1,
      "name": "Rock_Crystal_Blue_Block"
    },
    {
      "x": 0,
      "y": 7,
      "z": -1,
      "name": "Rock_Crystal_Blue_Block"
    },
    {
      "x": 0,
      "y": 8,
      "z": -1,
      "name": "Rock_Crystal_Blue_Block"
    },
    {
      "x": 0,
      "y": 9,
      "z": -1,
      "name": "Rock_Crystal_Blue_Block"
    },
    {
      "x": 0,
      "y": 10,
      "z": -1,
      "name": "Rock_Crystal_Blue_Block"
    },
    {
      "x": 0,
      "y": 11,
      "z": -1,
      "name": "Rock_Crystal_Blue_Block"
    },
    {
      "x": 0,
      "y": 3,
      "z": 0,
      "name": "Rock_Slate_Cobble"
    },
    {
      "x": 0,
      "y": 4,
      "z": 0,
      "name": "Rock_Slate_Cobble"
    },
    {
      "x": 0,
      "y": 5,
      "z": 0,
      "name": "Rock_Crystal_Blue_Block"
    },
    {
      "x": 0,
      "y": 6,
      "z": 0,
      "name": "Rock_Crystal_Blue_Block"
    },
    {
      "x": 0,
      "y": 7,
      "z": 0,
      "name": "Rock_Crystal_Blue_Block"
    },
    {
      "x": 0,
      "y": 8,
      "z": 0,
      "name": "Rock_Crystal_Blue_Block"
    },
    {
      "x": 0,
      "y": 9,
      "z": 0,
      "name": "Rock_Crystal_Blue_Block"
    },
    {
      "x": 0,
      "y": 10,
      "z": 0,
      "name": "Rock_Crystal_Blue_Block"
    },
    {
      "x": 0,
      "y": 11,
      "z": 0,
      "name": "Rock_Crystal_Blue_Block"
    },
    {
      "x": 0,
      "y": 12,
      "z": 0,
      "name": "Rock_Crystal_Blue_Block"
    },
    {
      "x": 0,
      "y": 3,
      "z": 1,
      "name": "Rock_Slate_Cobble"
    },
    {
      "x": 0,
      "y": 4,
      "z": 1,
      "name": "Rock_Slate_Cobble"
    },
    {
      "x": 0,
      "y": 5,
      "z": 1,
      "name": "Rock_Crystal_Blue_Block"
    },
    {
      "x": 0,
      "y": 6,
      "z": 1,
      "name": "Rock_Crystal_Blue_Block"
    },
    {
      "x": 0,
      "y": 7,
      "z": 1,
      "name": "Rock_Crystal_Blue_Block"
    },
    {
      "x": 0,
      "y": 8,
      "z": 1,
      "name": "Rock_Crystal_Blue_Block"
    },
    {
      "x": 0,
      "y": 9,
      "z": 1,
      "name": "Rock_Crystal_Blue_Block"
    },
    {
      "x": 0,
      "y": 10,
      "z": 1,
      "name": "Rock_Crystal_Blue_Block"
    },
    {
      "x": 0,
      "y": 11,
      "z": 1,
      "name": "Rock_Crystal_Blue_Block"
    },
    {
      "x": 0,
      "y": 12,
      "z": 1,
      "name": "Rock_Crystal_Blue_Block"
    },
    {
      "x": 0,
      "y": 13,
      "z": 1,
      "name": "Rock_Crystal_Blue_Large"
    },
    {
      "x": 0,
      "y": 14,
      "z": 1,
      "name": "Rock_Crystal_Blue_Large"
    },
    {
      "x": 0,
      "y": 3,
      "z": 2,
      "name": "Rock_Slate_Cobble"
    },
    {
      "x": 0,
      "y": 4,
      "z": 2,
      "name": "Rock_Slate_Cobble"
    },
    {
      "x": 0,
      "y": 5,
      "z": 2,
      "name": "Rock_Crystal_Blue_Block"
    },
    {
      "x": 0,
      "y": 6,
      "z": 2,
      "name": "Rock_Crystal_Blue_Block"
    },
    {
      "x": 0,
      "y": 7,
      "z": 2,
      "name": "Rock_Crystal_Blue_Block"
    },
    {
      "x": 0,
      "y": 8,
      "z": 2,
      "name": "Rock_Crystal_Blue_Block"
    },
    {
      "x": 0,
      "y": 9,
      "z": 2,
      "name": "Rock_Crystal_Blue_Block"
    },
    {
      "x": 0,
      "y": 10,
      "z": 2,
      "name": "Rock_Crystal_Blue_Block"
    },
    {
      "x": 0,
      "y": 11,
      "z": 2,
      "name": "Rock_Crystal_Blue_Block"
    },
    {
      "x": 0,
      "y": 12,
      "z": 2,
      "name": "Rock_Crystal_Blue_Block"
    },
    {
      "x": 0,
      "y": 13,
      "z": 2,
      "name": "Rock_Crystal_Blue_Medium"
    },
    {
      "x": 0,
      "y": 4,
      "z": 3,
      "name": "Rock_Slate_Cobble"
    },
    {
      "x": 0,
      "y": 5,
      "z": 3,
      "name": "Rock_Crystal_Blue_Block"
    },
    {
      "x": 0,
      "y": 6,
      "z": 3,
      "name": "Rock_Crystal_Blue_Block"
    },
    {
      "x": 0,
      "y": 7,
      "z": 3,
      "name": "Rock_Crystal_Blue_Block"
    },
    {
      "x": 0,
      "y": 8,
      "z": 3,
      "name": "Rock_Crystal_Blue_Block"
    },
    {
      "x": 0,
      "y": 9,
      "z": 3,
      "name": "Rock_Crystal_Blue_Block"
    },
    {
      "x": 0,
      "y": 10,
      "z": 3,
      "name": "Rock_Crystal_Blue_Block"
    },
    {
      "x": 0,
      "y": 11,
      "z": 3,
      "name": "Rock_Crystal_Blue_Block"
    },
    {
      "x": 0,
      "y": 12,
      "z": 3,
      "name": "Rock_Crystal_Blue_Block"
    },
    {
      "x": 0,
      "y": 4,
      "z": 4,
      "name": "Rock_Slate_Cobble"
    },
    {
      "x": 1,
      "y": 4,
      "z": -2,
      "name": "Rock_Slate_Cobble"
    },
    {
      "x": 1,
      "y": 5,
      "z": -2,
      "name": "Rock_Slate"
    },
    {
      "x": 1,
      "y": 6,
      "z": -2,
      "name": "Rock_Slate"
    },
    {
      "x": 1,
      "y": 7,
      "z": -2,
      "name": "Rock_Slate"
    },
    {
      "x": 1,
      "y": 8,
      "z": -2,
      "name": "Rock_Slate"
    },
    {
      "x": 1,
      "y": 4,
      "z": -1,
      "name": "Rock_Slate_Cobble"
    },
    {
      "x": 1,
      "y": 5,
      "z": -1,
      "name": "Rock_Crystal_Blue_Block"
    },
    {
      "x": 1,
      "y": 6,
      "z": -1,
      "name": "Rock_Crystal_Blue_Block"
    },
    {
      "x": 1,
      "y": 7,
      "z": -1,
      "name": "Rock_Crystal_Blue_Block"
    },
    {
      "x": 1,
      "y": 8,
      "z": -1,
      "name": "Rock_Crystal_Blue_Block"
    },
    {
      "x": 1,
      "y": 9,
      "z": -1,
      "name": "Rock_Crystal_Blue_Block"
    },
    {
      "x": 1,
      "y": 3,
      "z": 0,
      "name": "Rock_Slate_Cobble"
    },
    {
      "x": 1,
      "y": 4,
      "z": 0,
      "name": "Rock_Slate_Cobble"
    },
    {
      "x": 1,
      "y": 5,
      "z": 0,
      "name": "Rock_Crystal_Blue_Block"
    },
    {
      "x": 1,
      "y": 6,
      "z": 0,
      "name": "Rock_Crystal_Blue_Block"
    },
    {
      "x": 1,
      "y": 7,
      "z": 0,
      "name": "Rock_Crystal_Blue_Block"
    },
    {
      "x": 1,
      "y": 8,
      "z": 0,
      "name": "Rock_Crystal_Blue_Block"
    },
    {
      "x": 1,
      "y": 9,
      "z": 0,
      "name": "Rock_Crystal_Blue_Block"
    },
    {
      "x": 1,
      "y": 10,
      "z": 0,
      "name": "Rock_Crystal_Blue_Block"
    },
    {
      "x": 1,
      "y": 11,
      "z": 0,
      "name": "Rock_Crystal_Blue_Block"
    },
    {
      "x": 1,
      "y": 12,
      "z": 0,
      "name": "Rock_Crystal_Blue_Large"
    },
    {
      "x": 1,
      "y": 3,
      "z": 1,
      "name": "Rock_Slate_Cobble"
    },
    {
      "x": 1,
      "y": 4,
      "z": 1,
      "name": "Rock_Slate_Cobble"
    },
    {
      "x": 1,
      "y": 5,
      "z": 1,
      "name": "Rock_Crystal_Blue_Block"
    },
    {
      "x": 1,
      "y": 6,
      "z": 1,
      "name": "Rock_Crystal_Blue_Block"
    },
    {
      "x": 1,
      "y": 7,
      "z": 1,
      "name": "Rock_Crystal_Blue_Block"
    },
    {
      "x": 1,
      "y": 8,
      "z": 1,
      "name": "Rock_Crystal_Blue_Block"
    },
    {
      "x": 1,
      "y": 9,
      "z": 1,
      "name": "Rock_Crystal_Blue_Block"
    },
    {
      "x": 1,
      "y": 10,
      "z": 1,
      "name": "Rock_Crystal_Blue_Block"
    },
    {
      "x": 1,
      "y": 11,
      "z": 1,
      "name": "Rock_Crystal_Blue_Block"
    },
    {
      "x": 1,
      "y": 12,
      "z": 1,
      "name": "Rock_Crystal_Blue_Block"
    },
    {
      "x": 1,
      "y": 4,
      "z": 2,
      "name": "Rock_Slate_Cobble"
    },
    {
      "x": 1,
      "y": 5,
      "z": 2,
      "name": "Rock_Slate"
    },
    {
      "x": 1,
      "y": 8,
      "z": 2,
      "name": "Rock_Crystal_Blue_Block"
    },
    {
      "x": 1,
      "y": 9,
      "z": 2,
      "name": "Rock_Crystal_Blue_Block"
    },
    {
      "x": 1,
      "y": 10,
      "z": 2,
      "name": "Rock_Crystal_Blue_Block"
    },
    {
      "x": 1,
      "y": 11,
      "z": 2,
      "name": "Rock_Crystal_Blue_Block"
    },
    {
      "x": 1,
      "y": 4,
      "z": 3,
      "name": "Rock_Slate_Cobble"
    },
    {
      "x": 1,
      "y": 5,
      "z": 3,
      "name": "Rock_Slate"
    },
    {
      "x": 1,
      "y": 6,
      "z": 3,
      "name": "Rock_Crystal_Blue_Block"
    },
    {
      "x": 1,
      "y": 7,
      "z": 3,
      "name": "Rock_Crystal_Blue_Block"
    },
    {
      "x": 1,
      "y": 8,
      "z": 3,
      "name": "Rock_Crystal_Blue_Block"
    },
    {
      "x": 1,
      "y": 9,
      "z": 3,
      "name": "Rock_Crystal_Blue_Block"
    },
    {
      "x": 1,
      "y": 10,
      "z": 3,
      "name": "Rock_Crystal_Blue_Block"
    },
    {
      "x": 1,
      "y": 4,
      "z": 4,
      "name": "Rock_Slate"
    },
    {
      "x": 1,
      "y": 5,
      "z": 4,
      "name": "Rock_Slate"
    },
    {
      "x": 2,
      "y": 4,
      "z": -2,
      "name": "Rock_Slate_Cobble"
    },
    {
      "x": 2,
      "y": 5,
      "z": -2,
      "name": "Rock_Slate_Cobble"
    },
    {
      "x": 2,
      "y": 6,
      "z": -2,
      "name": "Rock_Slate_Cobble"
    },
    {
      "x": 2,
      "y": 7,
      "z": -2,
      "name": "Rock_Slate"
    },
    {
      "x": 2,
      "y": 8,
      "z": -2,
      "name": "Rock_Slate"
    },
    {
      "x": 2,
      "y": 4,
      "z": -1,
      "name": "Rock_Slate_Cobble"
    },
    {
      "x": 2,
      "y": 5,
      "z": -1,
      "name": "Rock_Slate_Cobble"
    },
    {
      "x": 2,
      "y": 6,
      "z": -1,
      "name": "Rock_Slate_Cobble"
    },
    {
      "x": 2,
      "y": 7,
      "z": -1,
      "name": "Rock_Slate_Cobble"
    },
    {
      "x": 2,
      "y": 8,
      "z": -1,
      "name": "Rock_Slate"
    },
    {
      "x": 2,
      "y": 9,
      "z": -1,
      "name": "Rock_Slate"
    },
    {
      "x": 2,
      "y": 10,
      "z": -1,
      "name": "Rock_Slate"
    },
    {
      "x": 2,
      "y": 4,
      "z": 0,
      "name": "Rock_Slate_Cobble"
    },
    {
      "x": 2,
      "y": 5,
      "z": 0,
      "name": "Rock_Slate_Cobble"
    },
    {
      "x": 2,
      "y": 6,
      "z": 0,
      "name": "Rock_Slate_Cobble"
    },
    {
      "x": 2,
      "y": 7,
      "z": 0,
      "name": "Rock_Slate"
    },
    {
      "x": 2,
      "y": 8,
      "z": 0,
      "name": "Rock_Slate"
    },
    {
      "x": 2,
      "y": 9,
      "z": 0,
      "name": "Rock_Crystal_Blue_Block"
    },
    {
      "x": 2,
      "y": 10,
      "z": 0,
      "name": "Rock_Crystal_Blue_Block"
    },
    {
      "x": 2,
      "y": 11,
      "z": 0,
      "name": "Rock_Crystal_Blue_Block"
    },
    {
      "x": 2,
      "y": 4,
      "z": 1,
      "name": "Rock_Slate_Cobble"
    },
    {
      "x": 2,
      "y": 5,
      "z": 1,
      "name": "Rock_Crystal_Blue_Block"
    },
    {
      "x": 2,
      "y": 6,
      "z": 1,
      "name": "Rock_Crystal_Blue_Block"
    },
    {
      "x": 2,
      "y": 7,
      "z": 1,
      "name": "Rock_Crystal_Blue_Block"
    },
    {
      "x": 2,
      "y": 8,
      "z": 1,
      "name": "Rock_Crystal_Blue_Block"
    },
    {
      "x": 2,
      "y": 9,
      "z": 1,
      "name": "Rock_Crystal_Blue_Block"
    },
    {
      "x": 2,
      "y": 10,
      "z": 1,
      "name": "Rock_Crystal_Blue_Block"
    },
    {
      "x": 2,
      "y": 11,
      "z": 1,
      "name": "Rock_Crystal_Blue_Block"
    },
    {
      "x": 2,
      "y": 12,
      "z": 1,
      "name": "Rock_Crystal_Blue_Small"
    },
    {
      "x": 2,
      "y": 4,
      "z": 2,
      "name": "Rock_Slate_Cobble"
    },
    {
      "x": 2,
      "y": 5,
      "z": 2,
      "name": "Rock_Slate"
    },
    {
      "x": 2,
      "y": 6,
      "z": 2,
      "name": "Rock_Slate"
    },
    {
      "x": 2,
      "y": 7,
      "z": 2,
      "name": "Rock_Slate"
    },
    {
      "x": 2,
      "y": 8,
      "z": 2,
      "name": "Rock_Crystal_Blue_Block"
    },
    {
      "x": 2,
      "y": 9,
      "z": 2,
      "name": "Rock_Crystal_Blue_Block"
    },
    {
      "x": 2,
      "y": 10,
      "z": 2,
      "name": "Rock_Crystal_Blue_Medium"
    },
    {
      "x": 2,
      "y": 4,
      "z": 3,
      "name": "Rock_Slate"
    },
    {
      "x": 2,
      "y": 5,
      "z": 3,
      "name": "Rock_Slate"
    },
    {
      "x": 2,
      "y": 6,
      "z": 3,
      "name": "Rock_Slate"
    },
    {
      "x": 2,
      "y": 7,
      "z": 3,
      "name": "Rock_Slate"
    },
    {
      "x": 2,
      "y": 8,
      "z": 3,
      "name": "Rock_Slate"
    },
    {
      "x": 2,
      "y": 5,
      "z": 4,
      "name": "Rock_Slate"
    },
    {
      "x": 2,
      "y": 6,
      "z": 4,
      "name": "Rock_Slate"
    },
    {
      "x": 2,
      "y": 7,
      "z": 4,
      "name": "Rock_Slate"
    },
    {
      "x": 3,
      "y": 5,
      "z": -1,
      "name": "Rock_Slate_Cobble"
    },
    {
      "x": 3,
      "y": 6,
      "z": -1,
      "name": "Rock_Slate_Cobble"
    },
    {
      "x": 3,
      "y": 7,
      "z": -1,
      "name": "Rock_Slate_Cobble"
    },
    {
      "x": 3,
      "y": 8,
      "z": -1,
      "name": "Rock_Slate"
    },
    {
      "x": 3,
      "y": 9,
      "z": -1,
      "name": "Rock_Slate"
    },
    {
      "x": 3,
      "y": 10,
      "z": -1,
      "name": "Rock_Slate"
    },
    {
      "x": 3,
      "y": 4,
      "z": 0,
      "name": "Rock_Slate_Cobble"
    },
    {
      "x": 3,
      "y": 5,
      "z": 0,
      "name": "Rock_Slate_Cobble"
    },
    {
      "x": 3,
      "y": 6,
      "z": 0,
      "name": "Rock_Slate_Cobble"
    },
    {
      "x": 3,
      "y": 7,
      "z": 0,
      "name": "Rock_Slate"
    },
    {
      "x": 3,
      "y": 8,
      "z": 0,
      "name": "Rock_Slate"
    },
    {
      "x": 3,
      "y": 4,
      "z": 1,
      "name": "Rock_Slate_Cobble"
    },
    {
      "x": 3,
      "y": 4,
      "z": 2,
      "name": "Rock_Slate_Cobble"
    },
    {
      "x": 3,
      "y": 5,
      "z": 2,
      "name": "Rock_Slate"
    },
    {
      "x": 3,
      "y": 6,
      "z": 2,
      "name": "Rock_Slate"
    },
    {
      "x": 3,
      "y": 7,
      "z": 2,
      "name": "Rock_Slate"
    },
    {
      "x": 3,
      "y": 6,
      "z": 3,
      "name": "Rock_Slate"
    }
  ]
}