{
  "version": 8,
  "blockIdVersion": 8,
  "anchorX": 12,
  "anchorY": 9,
  "anchorZ": 18,
  "blocks": [
    {
      "x": 8,
      "y": 7,
      "z": 16,
      "name": "Rock_Sandstone_White"
    },
    {
      "x": 8,
      "y": 8,
      "z": 16,
      "name": "Rock_Sandstone_White"
    },
    {
      "x": 8,
      "y": 9,
      "z": 16,
      "name": "Rock_Sandstone_White"
    },
    {
      "x": 8,
      "y": 5,
      "z": 17,
      "name": "Rock_Sandstone_White"
    },
    {
      "x": 8,
      "y": 6,
      "z": 17,
      "name": "Rock_Sandstone_White"
    },
    {
      "x": 8,
      "y": 7,
      "z": 17,
      "name": "Rock_Sandstone_White"
    },
    {
      "x": 8,
      "y": 8,
      "z": 17,
      "name": "Rock_Sandstone_White"
    },
    {
      "x": 8,
      "y": 9,
      "z": 17,
      "name": "Rock_Sandstone_White"
    },
    {
      "x": 8,
      "y": 5,
      "z": 18,
      "name": "Rock_Sandstone_White"
    },
    {
      "x": 8,
      "y": 6,
      "z": 18,
      "name": "Rock_Sandstone_White"
    },
    {
      "x": 8,
      "y": 7,
      "z": 18,
      "name": "Rock_Sandstone_White"
    },
    {
      "x": 8,
      "y": 8,
      "z": 18,
      "name": "Rock_Sandstone_White"
    },
    {
      "x": 8,
      "y": 9,
      "z": 18,
      "name": "Rock_Sandstone_White"
    },
    {
      "x": 9,
      "y": 26,
      "z": 14,
      "name": "Soil_Dirt_Dry"
    },
    {
      "x": 9,
      "y": 27,
      "z": 14,
      "name": "Rock_Sandstone"
    },
    {
      "x": 9,
      "y": 28,
      "z": 14,
      "name": "Rock_Sandstone_White"
    },
    {
      "x": 9,
      "y": 6,
      "z": 15,
      "name": "Rock_Sandstone_White"
    },
    {
      "x": 9,
      "y": 7,
      "z": 15,
      "name": "Rock_Sandstone_White"
    },
    {
      "x": 9,
      "y": 8,
      "z": 15,
      "name": "Rock_Sandstone_White"
    },
    {
      "x": 9,
      "y": 9,
      "z": 15,
      "name": "Rock_Sandstone_White"
    },
    {
      "x": 9,
      "y": 10,
      "z": 15,
      "name": "Rock_Sandstone_White"
    },
    {
      "x": 9,
      "y": 16,
      "z": 15,
      "name": "Rock_Sandstone_White"
    },
    {
      "x": 9,
      "y": 17,
      "z": 15,
      "name": "Rock_Sandstone"
    },
    {
      "x": 9,
      "y": 23,
      "z": 15,
      "name": "Rock_Sandstone_White"
    },
    {
      "x": 9,
      "y": 24,
      "z": 15,
      "name": "Rock_Sandstone_White"
    },
    {
      "x": 9,
      "y": 25,
      "z": 15,
      "name": "Rock_Sandstone_White"
    },
    {
      "x": 9,
      "y": 26,
      "z": 15,
      "name": "Soil_Dirt_Dry"
    },
    {
      "x": 9,
      "y": 27,
      "z": 15,
      "name": "Rock_Sandstone"
    },
    {
      "x": 9,
      "y": 28,
      "z": 15,
      "name": "Rock_Sandstone_White"
    },
    {
      "x": 9,
      "y": 29,
      "z": 15,
      "name": "Rock_Sandstone_White"
    },
    {
      "x": 9,
      "y": 32,
      "z": 15,
      "name": "Rock_Sandstone_White"
    },
    {
      "x": 9,
      "y": 33,
      "z": 15,
      "name": "Rock_Sandstone_White"
    },
    {
      "x": 9,
      "y": 34,
      "z": 15,
      "name": "Rock_Sandstone_White"
    },
    {
      "x": 9,
      "y": 35,
      "z": 15,
      "name": "Rock_Sandstone"
    },
    {
      "x": 9,
      "y": 4,
      "z": 16,
      "name": "Rock_Sandstone_White"
    },
    {
      "x": 9,
      "y": 5,
      "z": 16,
      "name": "Soil_Dirt_Dry"
    },
    {
      "x": 9,
      "y": 6,
      "z": 16,
      "name": "Rock_Sandstone"
    },
    {
      "x": 9,
      "y": 7,
      "z": 16,
      "name": "Rock_Sandstone"
    },
    {
      "x": 9,
      "y": 8,
      "z": 16,
      "name": "Rock_Sandstone_White"
    },
    {
      "x": 9,
      "y": 9,
      "z": 16,
      "name": "Rock_Sandstone_White"
    },
    {
      "x": 9,
      "y": 10,
      "z": 16,
      "name": "Rock_Sandstone_White"
    },
    {
      "x": 9,
      "y": 11,
      "z": 16,
      "name": "Rock_Sandstone_White"
    },
    {
      "x": 9,
      "y": 12,
      "z": 16,
      "name": "Rock_Sandstone_White"
    },
    {
      "x": 9,
      "y": 13,
      "z": 16,
      "name": "Rock_Sandstone_White"
    },
    {
      "x": 9,
      "y": 15,
      "z": 16,
      "name": "Rock_Sandstone_White"
    },
    {
      "x": 9,
      "y": 16,
      "z": 16,
      "name": "Rock_Sandstone_White"
    },
    {
      "x": 9,
      "y": 17,
      "z": 16,
      "name": "Rock_Sandstone"
    },
    {
      "x": 9,
      "y": 23,
      "z": 16,
      "name": "Rock_Sandstone_White"
    },
    {
      "x": 9,
      "y": 24,
      "z": 16,
      "name": "Rock_Sandstone_White"
    },
    {
      "x": 9,
      "y": 25,
      "z": 16,
      "name": "Rock_Sandstone_White"
    },
    {
      "x": 9,
      "y": 26,
      "z": 16,
      "name": "Soil_Dirt_Dry"
    },
    {
      "x": 9,
      "y": 27,
      "z": 16,
      "name": "Rock_Sandstone"
    },
    {
      "x": 9,
      "y": 28,
      "z": 16,
      "name": "Rock_Sandstone_White"
    },
    {
      "x": 9,
      "y": 29,
      "z": 16,
      "name": "Rock_Sandstone_White"
    },
    {
      "x": 9,
      "y": 31,
      "z": 16,
      "name": "Rock_Sandstone_White"
    },
    {
      "x": 9,
      "y": 32,
      "z": 16,
      "name": "Rock_Sandstone_White"
    },
    {
      "x": 9,
      "y": 33,
      "z": 16,
      "name": "Rock_Sandstone_White"
    },
    {
      "x": 9,
      "y": 34,
      "z": 16,
      "name": "Rock_Sandstone_White"
    },
    {
      "x": 9,
      "y": 35,
      "z": 16,
      "name": "Rock_Sandstone"
    },
    {
      "x": 9,
      "y": 36,
      "z": 16,
      "name": "Rock_Sandstone_White"
    },
    {
      "x": 9,
      "y": 3,
      "z": 17,
      "name": "Rock_Sandstone_White"
    },
    {
      "x": 9,
      "y": 4,
      "z": 17,
      "name": "Rock_Sandstone_White"
    },
    {
      "x": 9,
      "y": 5,
      "z": 17,
      "name": "Soil_Dirt_Dry"
    },
    {
      "x": 9,
      "y": 6,
      "z": 17,
      "name": "Rock_Sandstone"
    },
    {
      "x": 9,
      "y": 7,
      "z": 17,
      "name": "Rock_Sandstone"
    },
    {
      "x": 9,
      "y": 8,
      "z": 17,
      "name": "Rock_Sandstone_White"
    },
    {
      "x": 9,
      "y": 9,
      "z": 17,
      "name": "Rock_Sandstone_White"
    },
    {
      "x": 9,
      "y": 10,
      "z": 17,
      "name": "Rock_Sandstone_White"
    },
    {
      "x": 9,
      "y": 11,
      "z": 17,
      "name": "Rock_Sandstone_White"
    },
    {
      "x": 9,
      "y": 12,
      "z": 17,
      "name": "Rock_Sandstone_White"
    },
    {
      "x": 9,
      "y": 13,
      "z": 17,
      "name": "Rock_Sandstone_White"
    },
    {
      "x": 9,
      "y": 15,
      "z": 17,
      "name": "Rock_Sandstone_White"
    },
    {
      "x": 9,
      "y": 16,
      "z": 17,
      "name": "Rock_Sandstone_White"
    },
    {
      "x": 9,
      "y": 17,
      "z": 17,
      "name": "Rock_Sandstone"
    },
    {
      "x": 9,
      "y": 23,
      "z": 17,
      "name": "Rock_Sandstone_White"
    },
    {
      "x": 9,
      "y": 24,
      "z": 17,
      "name": "Rock_Sandstone_White"
    },
    {
      "x": 9,
      "y": 25,
      "z": 17,
      "name": "Rock_Sandstone_White"
    },
    {
      "x": 9,
      "y": 26,
      "z": 17,
      "name": "Soil_Dirt_Dry"
    },
    {
      "x": 9,
      "y": 27,
      "z": 17,
      "name": "Rock_Sandstone"
    },
    {
      "x": 9,
      "y": 28,
      "z": 17,
      "name": "Rock_Sandstone_White"
    },
    {
      "x": 9,
      "y": 29,
      "z": 17,
      "name": "Rock_Sandstone_White"
    },
    {
      "x": 9,
      "y": 31,
      "z": 17,
      "name": "Rock_Sandstone_White"
    },
    {
      "x": 9,
      "y": 32,
      "z": 17,
      "name": "Rock_Sandstone_White"
    },
    {
      "x": 9,
      "y": 33,
      "z": 17,
      "name": "Rock_Sandstone_White"
    },
    {
      "x": 9,
      "y": 34,
      "z": 17,
      "name": "Rock_Sandstone_White"
    },
    {
      "x": 9,
      "y": 35,
      "z": 17,
      "name": "Rock_Sandstone"
    },
    {
      "x": 9,
      "y": 36,
      "z": 17,
      "name": "Rock_Sandstone_White"
    },
    {
      "x": 9,
      "y": 3,
      "z": 18,
      "name": "Rock_Sandstone_White"
    },
    {
      "x": 9,
      "y": 4,
      "z": 18,
      "name": "Rock_Sandstone_White"
    },
    {
      "x": 9,
      "y": 5,
      "z": 18,
      "name": "Soil_Dirt_Dry"
    },
    {
      "x": 9,
      "y": 6,
      "z": 18,
      "name": "Rock_Sandstone"
    },
    {
      "x": 9,
      "y": 7,
      "z": 18,
      "name": "Rock_Sandstone_White"
    },
    {
      "x": 9,
      "y": 8,
      "z": 18,
      "name": "Rock_Sandstone_White"
    },
    {
      "x": 9,
      "y": 9,
      "z": 18,
      "name": "Rock_Sandstone_White"
    },
    {
      "x": 9,
      "y": 10,
      "z": 18,
      "name": "Rock_Sandstone_White"
    },
    {
      "x": 9,
      "y": 11,
      "z": 18,
      "name": "Rock_Sandstone_White"
    },
    {
      "x": 9,
      "y": 12,
      "z": 18,
      "name": "Rock_Sandstone_White"
    },
    {
      "x": 9,
      "y": 13,
      "z": 18,
      "name": "Rock_Sandstone_White"
    },
    {
      "x": 9,
      "y": 15,
      "z": 18,
      "name": "Rock_Sandstone_White"
    },
    {
      "x": 9,
      "y": 16,
      "z": 18,
      "name": "Rock_Sandstone_White"
    },
    {
      "x": 9,
      "y": 17,
      "z": 18,
      "name": "Rock_Sandstone"
    },
    {
      "x": 9,
      "y": 18,
      "z": 18,
      "name": "Rock_Sandstone_White"
    },
    {
      "x": 9,
      "y": 24,
      "z": 18,
      "name": "Rock_Sandstone_White"
    },
    {
      "x": 9,
      "y": 25,
      "z": 18,
      "name": "Rock_Sandstone_White"
    },
    {
      "x": 9,
      "y": 26,
      "z": 18,
      "name": "Soil_Dirt_Dry"
    },
    {
      "x": 9,
      "y": 27,
      "z": 18,
      "name": "Rock_Sandstone"
    },
    {
      "x": 9,
      "y": 28,
      "z": 18,
      "name": "Rock_Sandstone_White"
    },
    {
      "x": 9,
      "y": 29,
      "z": 18,
      "name": "Rock_Sandstone_White"
    },
    {
      "x": 9,
      "y": 31,
      "z": 18,
      "name": "Rock_Sandstone_White"
    },
    {
      "x": 9,
      "y": 32,
      "z": 18,
      "name": "Rock_Sandstone_White"
    },
    {
      "x": 9,
      "y": 33,
      "z": 18,
      "name": "Rock_Sandstone_White"
    },
    {
      "x": 9,
      "y": 34,
      "z": 18,
      "name": "Rock_Sandstone_White"
    },
    {
      "x": 9,
      "y": 35,
      "z": 18,
      "name": "Rock_Sandstone"
    },
    {
      "x": 9,
      "y": 36,
      "z": 18,
      "name": "Rock_Sandstone_White"
    },
    {
      "x": 9,
      "y": 3,
      "z": 19,
      "name": "Rock_Sandstone_White"
    },
    {
      "x": 9,
      "y": 4,
      "z": 19,
      "name": "Rock_Sandstone_White"
    },
    {
      "x": 9,
      "y": 5,
      "z": 19,
      "name": "Soil_Dirt_Dry"
    },
    {
      "x": 9,
      "y": 6,
      "z": 19,
      "name": "Rock_Sandstone"
    },
    {
      "x": 9,
      "y": 7,
      "z": 19,
      "name": "Rock_Sandstone_White"
    },
    {
      "x": 9,
      "y": 8,
      "z": 19,
      "name": "Rock_Sandstone_White"
    },
    {
      "x": 9,
      "y": 9,
      "z": 19,
      "name": "Rock_Sandstone_White"
    },
    {
      "x": 9,
      "y": 10,
      "z": 19,
      "name": "Rock_Sandstone_White"
    },
    {
      "x": 9,
      "y": 11,
      "z": 19,
      "name": "Rock_Sandstone_White"
    },
    {
      "x": 9,
      "y": 15,
      "z": 19,
      "name": "Rock_Sandstone_White"
    },
    {
      "x": 9,
      "y": 16,
      "z": 19,
      "name": "Rock_Sandstone_White"
    },
    {
      "x": 9,
      "y": 17,
      "z": 19,
      "name": "Rock_Sandstone"
    },
    {
      "x": 9,
      "y": 18,
      "z": 19,
      "name": "Rock_Sandstone_White"
    },
    {
      "x": 9,
      "y": 34,
      "z": 19,
      "name": "Rock_Sandstone_White"
    },
    {
      "x": 9,
      "y": 35,
      "z": 19,
      "name": "Rock_Sandstone"
    },
    {
      "x": 9,
      "y": 3,
      "z": 20,
      "name": "Rock_Sandstone_White"
    },
    {
      "x": 9,
      "y": 4,
      "z": 20,
      "name": "Rock_Sandstone_White"
    },
    {
      "x": 9,
      "y": 5,
      "z": 20,
      "name": "Soil_Dirt_Dry"
    },
    {
      "x": 9,
      "y": 6,
      "z": 20,
      "name": "Rock_Sandstone"
    },
    {
      "x": 9,
      "y": 15,
      "z": 20,
      "name": "Rock_Sandstone_White"
    },
    {
      "x": 9,
      "y": 16,
      "z": 20,
      "name": "Rock_Sandstone_White"
    },
    {
      "x": 9,
      "y": 17,
      "z": 20,
      "name": "Rock_Sandstone"
    },
    {
      "x": 9,
      "y": 18,
      "z": 20,
      "name": "Rock_Sandstone_White"
    },
    {
      "x": 9,
      "y": 16,
      "z": 21,
      "name": "Rock_Sandstone_White"
    },
    {
      "x": 9,
      "y": 17,
      "z": 21,
      "name": "Rock_Sandstone"
    },
    {
      "x": 9,
      "y": 18,
      "z": 21,
      "name": "Rock_Sandstone_White"
    },
    {
      "x": 9,
      "y": 16,
      "z": 22,
      "name": "Rock_Sandstone_White"
    },
    {
      "x": 9,
      "y": 17,
      "z": 22,
      "name": "Rock_Sandstone"
    },
    {
      "x": 9,
      "y": 18,
      "z": 22,
      "name": "Rock_Sandstone"
    },
    {
      "x": 9,
      "y": 22,
      "z": 22,
      "name": "Rock_Sandstone_White"
    },
    {
      "x": 9,
      "y": 23,
      "z": 22,
      "name": "Rock_Sandstone_White"
    },
    {
      "x": 9,
      "y": 24,
      "z": 22,
      "name": "Rock_Sandstone_White"
    },
    {
      "x": 9,
      "y": 16,
      "z": 23,
      "name": "Rock_Sandstone_White"
    },
    {
      "x": 9,
      "y": 17,
      "z": 23,
      "name": "Rock_Sandstone_White"
    },
    {
      "x": 9,
      "y": 18,
      "z": 23,
      "name": "Rock_Sandstone"
    },
    {
      "x": 9,
      "y": 19,
      "z": 23,
      "name": "Rock_Sandstone_White"
    },
    {
      "x": 9,
      "y": 21,
      "z": 23,
      "name": "Rock_Sandstone_White"
    },
    {
      "x": 9,
      "y": 22,
      "z": 23,
      "name": "Rock_Sandstone_White"
    },
    {
      "x": 9,
      "y": 23,
      "z": 23,
      "name": "Rock_Sandstone_White"
    },
    {
      "x": 9,
      "y": 24,
      "z": 23,
      "name": "Rock_Sandstone_White"
    },
    {
      "x": 9,
      "y": 25,
      "z": 23,
      "name": "Rock_Sandstone"
    },
    {
      "x": 9,
      "y": 16,
      "z": 24,
      "name": "Rock_Sandstone_White"
    },
    {
      "x": 9,
      "y": 17,
      "z": 24,
      "name": "Rock_Sandstone_White"
    },
    {
      "x": 9,
      "y": 18,
      "z": 24,
      "name": "Rock_Sandstone"
    },
    {
      "x": 9,
      "y": 19,
      "z": 24,
      "name": "Rock_Sandstone_White"
    },
    {
      "x": 9,
      "y": 20,
      "z": 24,
      "name": "Rock_Sandstone_White"
    },
    {
      "x": 9,
      "y": 21,
      "z": 24,
      "name": "Rock_Sandstone_White"
    },
    {
      "x": 9,
      "y": 22,
      "z": 24,
      "name": "Rock_Sandstone_White"
    },
    {
      "x": 9,
      "y": 23,
      "z": 24,
      "name": "Rock_Sandstone_White"
    },
    {
      "x": 9,
      "y": 24,
      "z": 24,
      "name": "Rock_Sandstone_White"
    },
    {
      "x": 9,
      "y": 25,
      "z": 24,
      "name": "Rock_Sandstone"
    },
    {
      "x": 9,
      "y": 16,
      "z": 25,
      "name": "Rock_Sandstone_White"
    },
    {
      "x": 9,
      "y": 17,
      "z": 25,
      "name": "Rock_Sandstone_White"
    },
    {
      "x": 9,
      "y": 18,
      "z": 25,
      "name": "Rock_Sandstone"
    },
    {
      "x": 9,
      "y": 19,
      "z": 25,
      "name": "Rock_Sandstone_White"
    },
    {
      "x": 9,
      "y": 20,
      "z": 25,
      "name": "Rock_Sandstone_White"
    },
    {
      "x": 9,
      "y": 21,
      "z": 25,
      "name": "Rock_Sandstone_White"
    },
    {
      "x": 9,
      "y": 22,
      "z": 25,
      "name": "Rock_Sandstone_White"
    },
    {
      "x": 9,
      "y": 23,
      "z": 25,
      "name": "Rock_Sandstone_White"
    },
    {
      "x": 9,
      "y": 24,
      "z": 25,
      "name": "Rock_Sandstone_White"
    },
    {
      "x": 9,
      "y": 25,
      "z": 25,
      "name": "Rock_Sandstone"
    },
    {
      "x": 9,
      "y": 17,
      "z": 26,
      "name": "Rock_Sandstone_White"
    },
    {
      "x": 9,
      "y": 18,
      "z": 26,
      "name": "Rock_Sandstone"
    },
    {
      "x": 9,
      "y": 19,
      "z": 26,
      "name": "Rock_Sandstone_White"
    },
    {
      "x": 9,
      "y": 21,
      "z": 26,
      "name": "Rock_Sandstone_White"
    },
    {
      "x": 9,
      "y": 22,
      "z": 26,
      "name": "Rock_Sandstone_White"
    },
    {
      "x": 9,
      "y": 23,
      "z": 26,
      "name": "Rock_Sandstone_White"
    },
    {
      "x": 9,
      "y": 24,
      "z": 26,
      "name": "Rock_Sandstone_White"
    },
    {
      "x": 9,
      "y": 25,
      "z": 26,
      "name": "Rock_Sandstone"
    },
    {
      "x": 9,
      "y": 18,
      "z": 27,
      "name": "Rock_Sandstone"
    },
    {
      "x": 9,
      "y": 19,
      "z": 27,
      "name": "Rock_Sandstone_White"
    },
    {
      "x": 10,
      "y": 14,
      "z": 7,
      "name": "Rock_Sandstone_White"
    },
    {
      "x": 10,
      "y": 15,
      "z": 7,
      "name": "Rock_Sandstone"
    },
    {
      "x": 10,
      "y": 14,
      "z": 8,
      "name": "Rock_Sandstone_White"
    },
    {
      "x": 10,
      "y": 15,
      "z": 8,
      "name": "Rock_Sandstone"
    },
    {
      "x": 10,
      "y": 16,
      "z": 8,
      "name": "Rock_Sandstone_White"
    },
    {
      "x": 10,
      "y": 18,
      "z": 8,
      "name": "Rock_Sandstone_White"
    },
    {
      "x": 10,
      "y": 19,
      "z": 8,
      "name": "Rock_Sandstone_White"
    },
    {
      "x": 10,
      "y": 20,
      "z": 8,
      "name": "Rock_Sandstone"
    },
    {
      "x": 10,
      "y": 21,
      "z": 8,
      "name": "Rock_Sandstone_White"
    },
    {
      "x": 10,
      "y": 14,
      "z": 9,
      "name": "Rock_Sandstone_White"
    },
    {
      "x": 10,
      "y": 15,
      "z": 9,
      "name": "Rock_Sandstone"
    },
    {
      "x": 10,
      "y": 16,
      "z": 9,
      "name": "Rock_Sandstone_White"
    },
    {
      "x": 10,
      "y": 18,
      "z": 9,
      "name": "Rock_Sandstone_White"
    },
    {
      "x": 10,
      "y": 19,
      "z": 9,
      "name": "Rock_Sandstone_White"
    },
    {
      "x": 10,
      "y": 20,
      "z": 9,
      "name": "Rock_Sandstone"
    },
    {
      "x": 10,
      "y": 21,
      "z": 9,
      "name": "Rock_Sandstone_White"
    },
    {
      "x": 10,
      "y": 22,
      "z": 9,
      "name": "Rock_Sandstone_White"
    },
    {
      "x": 10,
      "y": 14,
      "z": 10,
      "name": "Rock_Sandstone_White"
    },
    {
      "x": 10,
      "y": 15,
      "z": 10,
      "name": "Rock_Sandstone"
    },
    {
      "x": 10,
      "y": 16,
      "z": 10,
      "name": "Rock_Sandstone"
    },
    {
      "x": 10,
      "y": 18,
      "z": 10,
      "name": "Rock_Sandstone_White"
    },
    {
      "x": 10,
      "y": 19,
      "z": 10,
      "name": "Rock_Sandstone"
    },
    {
      "x": 10,
      "y": 20,
      "z": 10,
      "name": "Rock_Sandstone"
    },
    {
      "x": 10,
      "y": 21,
      "z": 10,
      "name": "Rock_Sandstone_White"
    },
    {
      "x": 10,
      "y": 22,
      "z": 10,
      "name": "Rock_Sandstone_White"
    },
    {
      "x": 10,
      "y": 14,
      "z": 11,
      "name": "Rock_Sandstone_White"
    },
    {
      "x": 10,
      "y": 15,
      "z": 11,
      "name": "Rock_Sandstone_White"
    },
    {
      "x": 10,
      "y": 16,
      "z": 11,
      "name": "Rock_Sandstone"
    },
    {
      "x": 10,
      "y": 17,
      "z": 11,
      "name": "Rock_Sandstone_White"
    },
    {
      "x": 10,
      "y": 18,
      "z": 11,
      "name": "Rock_Sandstone_White"
    },
    {
      "x": 10,
      "y": 19,
      "z": 11,
      "name": "Rock_Sandstone"
    },
    {
      "x": 10,
      "y": 20,
      "z": 11,
      "name": "Rock_Sandstone"
    },
    {
      "x": 10,
      "y": 21,
      "z": 11,
      "name": "Rock_Sandstone_White"
    },
    {
      "x": 10,
      "y": 14,
      "z": 12,
      "name": "Rock_Sandstone_White"
    },
    {
      "x": 10,
      "y": 15,
      "z": 12,
      "name": "Rock_Sandstone_White"
    },
    {
      "x": 10,
      "y": 16,
      "z": 12,
      "name": "Rock_Sandstone"
    },
    {
      "x": 10,
      "y": 17,
      "z": 12,
      "name": "Rock_Sandstone_White"
    },
    {
      "x": 10,
      "y": 20,
      "z": 12,
      "name": "Rock_Sandstone"
    },
    {
      "x": 10,
      "y": 21,
      "z": 12,
      "name": "Rock_Sandstone_White"
    },
    {
      "x": 10,
      "y": 14,
      "z": 13,
      "name": "Rock_Sandstone_White"
    },
    {
      "x": 10,
      "y": 15,
      "z": 13,
      "name": "Rock_Sandstone_White"
    },
    {
      "x": 10,
      "y": 16,
      "z": 13,
      "name": "Rock_Sandstone"
    },
    {
      "x": 10,
      "y": 17,
      "z": 13,
      "name": "Rock_Sandstone_White"
    },
    {
      "x": 10,
      "y": 14,
      "z": 14,
      "name": "Rock_Sandstone_White"
    },
    {
      "x": 10,
      "y": 15,
      "z": 14,
      "name": "Rock_Sandstone_White"
    },
    {
      "x": 10,
      "y": 16,
      "z": 14,
      "name": "Rock_Sandstone"
    },
    {
      "x": 10,
      "y": 17,
      "z": 14,
      "name": "Rock_Sandstone"
    },
    {
      "x": 10,
      "y": 18,
      "z": 14,
      "name": "Rock_Sandstone_White"
    },
    {
      "x": 10,
      "y": 24,
      "z": 14,
      "name": "Rock_Sandstone_White"
    },
    {
      "x": 10,
      "y": 25,
      "z": 14,
      "name": "Rock_Sandstone_White"
    },
    {
      "x": 10,
      "y": 26,
      "z": 14,
      "name": "Soil_Dirt_Dry"
    },
    {
      "x": 10,
      "y": 27,
      "z": 14,
      "name": "Rock_Sandstone"
    },
    {
      "x": 10,
      "y": 28,
      "z": 14,
      "name": "Rock_Sandstone_White"
    },
    {
      "x": 10,
      "y": 29,
      "z": 14,
      "name": "Rock_Sandstone_White"
    },
    {
      "x": 10,
      "y": 32,
      "z": 14,
      "name": "Rock_Sandstone_White"
    },
    {
      "x": 10,
      "y": 33,
      "z": 14,
      "name": "Rock_Sandstone_White"
    },
    {
      "x": 10,
      "y": 34,
      "z": 14,
      "name": "Rock_Sandstone_White"
    },
    {
      "x": 10,
      "y": 35,
      "z": 14,
      "name": "Rock_Sandstone"
    },
    {
      "x": 10,
      "y": 36,
      "z": 14,
      "name": "Rock_Sandstone_White"
    },
    {
      "x": 10,
      "y": 3,
      "z": 15,
      "name": "Rock_Sandstone_White"
    },
    {
      "x": 10,
      "y": 4,
      "z": 15,
      "name": "Rock_Sandstone_White"
    },
    {
      "x": 10,
      "y": 5,
      "z": 15,
      "name": "Rock_Sandstone_White"
    },
    {
      "x": 10,
      "y": 6,
      "z": 15,
      "name": "Soil_Dirt_Dry"
    },
    {
      "x": 10,
      "y": 7,
      "z": 15,
      "name": "Rock_Sandstone"
    },
    {
      "x": 10,
      "y": 8,
      "z": 15,
      "name": "Rock_Sandstone_White"
    },
    {
      "x": 10,
      "y": 9,
      "z": 15,
      "name": "Rock_Sandstone_White"
    },
    {
      "x": 10,
      "y": 10,
      "z": 15,
      "name": "Rock_Sandstone_White"
    },
    {
      "x": 10,
      "y": 11,
      "z": 15,
      "name": "Rock_Sandstone_White"
    },
    {
      "x": 10,
      "y": 12,
      "z": 15,
      "name": "Rock_Sandstone_White"
    },
    {
      "x": 10,
      "y": 14,
      "z": 15,
      "name": "Rock_Sandstone_White"
    },
    {
      "x": 10,
      "y": 15,
      "z": 15,
      "name": "Rock_Sandstone_White"
    },
    {
      "x": 10,
      "y": 16,
      "z": 15,
      "name": "Rock_Sandstone_White"
    },
    {
      "x": 10,
      "y": 17,
      "z": 15,
      "name": "Rock_Sandstone"
    },
    {
      "x": 10,
      "y": 18,
      "z": 15,
      "name": "Rock_Sandstone_White"
    },
    {
      "x": 10,
      "y": 20,
      "z": 15,
      "name": "Rock_Sandstone_White"
    },
    {
      "x": 10,
      "y": 21,
      "z": 15,
      "name": "Rock_Sandstone_White"
    },
    {
      "x": 10,
      "y": 22,
      "z": 15,
      "name": "Rock_Sandstone_White"
    },
    {
      "x": 10,
      "y": 23,
      "z": 15,
      "name": "Rock_Sandstone_White"
    },
    {
      "x": 10,
      "y": 24,
      "z": 15,
      "name": "Rock_Sandstone_White"
    },
    {
      "x": 10,
      "y": 25,
      "z": 15,
      "name": "Rock_Sandstone_White"
    },
    {
      "x": 10,
      "y": 26,
      "z": 15,
      "name": "Soil_Dirt_Dry"
    },
    {
      "x": 10,
      "y": 27,
      "z": 15,
      "name": "Rock_Sandstone"
    },
    {
      "x": 10,
      "y": 28,
      "z": 15,
      "name": "Rock_Sandstone_White"
    },
    {
      "x": 10,
      "y": 29,
      "z": 15,
      "name": "Rock_Sandstone_White"
    },
    {
      "x": 10,
      "y": 31,
      "z": 15,
      "name": "Rock_Sandstone_White"
    },
    {
      "x": 10,
      "y": 32,
      "z": 15,
      "name": "Rock_Sandstone_White"
    },
    {
      "x": 10,
      "y": 33,
      "z": 15,
      "name": "Rock_Sandstone_White"
    },
    {
      "x": 10,
      "y": 34,
      "z": 15,
      "name": "Rock_Sandstone_White"
    },
    {
      "x": 10,
      "y": 35,
      "z": 15,
      "name": "Rock_Sandstone"
    },
    {
      "x": 10,
      "y": 36,
      "z": 15,
      "name": "Rock_Sandstone_White"
    },
    {
      "x": 10,
      "y": 37,
      "z": 15,
      "name": "Rock_Sandstone_White"
    },
    {
      "x": 10,
      "y": 3,
      "z": 16,
      "name": "Rock_Sandstone_White"
    },
    {
      "x": 10,
      "y": 4,
      "z": 16,
      "name": "Rock_Sandstone_White"
    },
    {
      "x": 10,
      "y": 5,
      "z": 16,
      "name": "Soil_Dirt_Dry"
    },
    {
      "x": 10,
      "y": 6,
      "z": 16,
      "name": "Soil_Dirt_Dry"
    },
    {
      "x": 10,
      "y": 7,
      "z": 16,
      "name": "Rock_Sandstone"
    },
    {
      "x": 10,
      "y": 8,
      "z": 16,
      "name": "Rock_Sandstone_White"
    },
    {
      "x": 10,
      "y": 9,
      "z": 16,
      "name": "Rock_Sandstone_White"
    },
    {
      "x": 10,
      "y": 10,
      "z": 16,
      "name": "Rock_Sandstone_White"
    },
    {
      "x": 10,
      "y": 11,
      "z": 16,
      "name": "Rock_Sandstone_White"
    },
    {
      "x": 10,
      "y": 12,
      "z": 16,
      "name": "Rock_Sandstone_White"
    },
    {
      "x": 10,
      "y": 13,
      "z": 16,
      "name": "Rock_Sandstone_White"
    },
    {
      "x": 10,
      "y": 14,
      "z": 16,
      "name": "Rock_Sandstone_White"
    },
    {
      "x": 10,
      "y": 15,
      "z": 16,
      "name": "Rock_Sandstone_White"
    },
    {
      "x": 10,
      "y": 16,
      "z": 16,
      "name": "Rock_Sandstone_White"
    },
    {
      "x": 10,
      "y": 17,
      "z": 16,
      "name": "Rock_Sandstone"
    },
    {
      "x": 10,
      "y": 18,
      "z": 16,
      "name": "Rock_Sandstone_White"
    },
    {
      "x": 10,
      "y": 19,
      "z": 16,
      "name": "Rock_Sandstone_White"
    },
    {
      "x": 10,
      "y": 20,
      "z": 16,
      "name": "Rock_Sandstone_White"
    },
    {
      "x": 10,
      "y": 21,
      "z": 16,
      "name": "Rock_Sandstone_White"
    },
    {
      "x": 10,
      "y": 22,
      "z": 16,
      "name": "Rock_Sandstone_White"
    },
    {
      "x": 10,
      "y": 23,
      "z": 16,
      "name": "Rock_Sandstone_White"
    },
    {
      "x": 10,
      "y": 24,
      "z": 16,
      "name": "Rock_Sandstone_White"
    },
    {
      "x": 10,
      "y": 25,
      "z": 16,
      "name": "Rock_Sandstone_White"
    },
    {
      "x": 10,
      "y": 26,
      "z": 16,
      "name": "Soil_Dirt_Dry"
    },
    {
      "x": 10,
      "y": 27,
      "z": 16,
      "name": "Rock_Sandstone"
    },
    {
      "x": 10,
      "y": 28,
      "z": 16,
      "name": "Rock_Sandstone_White"
    },
    {
      "x": 10,
      "y": 29,
      "z": 16,
      "name": "Rock_Sandstone_White"
    },
    {
      "x": 10,
      "y": 30,
      "z": 16,
      "name": "Rock_Sandstone_White"
    },
    {
      "x": 10,
      "y": 31,
      "z": 16,
      "name": "Rock_Sandstone_White"
    },
    {
      "x": 10,
      "y": 32,
      "z": 16,
      "name": "Rock_Sandstone_White"
    },
    {
      "x": 10,
      "y": 33,
      "z": 16,
      "name": "Rock_Sandstone_White"
    },
    {
      "x": 10,
      "y": 34,
      "z": 16,
      "name": "Rock_Sandstone_White"
    },
    {
      "x": 10,
      "y": 35,
      "z": 16,
      "name": "Rock_Sandstone"
    },
    {
      "x": 10,
      "y": 36,
      "z": 16,
      "name": "Rock_Sandstone_White"
    },
    {
      "x": 10,
      "y": 37,
      "z": 16,
      "name": "Rock_Sandstone_White"
    },
    {
      "x": 10,
      "y": 3,
      "z": 17,
      "name": "Rock_Sandstone_White"
    },
    {
      "x": 10,
      "y": 4,
      "z": 17,
      "name": "Rock_Sandstone_White"
    },
    {
      "x": 10,
      "y": 5,
      "z": 17,
      "name": "Soil_Dirt_Dry"
    },
    {
      "x": 10,
      "y": 6,
      "z": 17,
      "name": "Rock_Sandstone"
    },
    {
      "x": 10,
      "y": 7,
      "z": 17,
      "name": "Rock_Sandstone"
    },
    {
      "x": 10,
      "y": 8,
      "z": 17,
      "name": "Rock_Sandstone_White"
    },
    {
      "x": 10,
      "y": 9,
      "z": 17,
      "name": "Rock_Sandstone_White"
    },
    {
      "x": 10,
      "y": 10,
      "z": 17,
      "name": "Rock_Sandstone_White"
    },
    {
      "x": 10,
      "y": 11,
      "z": 17,
      "name": "Rock_Sandstone_White"
    },
    {
      "x": 10,
      "y": 12,
      "z": 17,
      "name": "Rock_Sandstone_White"
    },
    {
      "x": 10,
      "y": 13,
      "z": 17,
      "name": "Rock_Sandstone_White"
    },
    {
      "x": 10,
      "y": 14,
      "z": 17,
      "name": "Rock_Sandstone_White"
    },
    {
      "x": 10,
      "y": 15,
      "z": 17,
      "name": "Rock_Sandstone_White"
    },
    {
      "x": 10,
      "y": 16,
      "z": 17,
      "name": "Rock_Sandstone_White"
    },
    {
      "x": 10,
      "y": 17,
      "z": 17,
      "name": "Rock_Sandstone"
    },
    {
      "x": 10,
      "y": 18,
      "z": 17,
      "name": "Rock_Sandstone_White"
    },
    {
      "x": 10,
      "y": 19,
      "z": 17,
      "name": "Rock_Sandstone_White"
    },
    {
      "x": 10,
      "y": 20,
      "z": 17,
      "name": "Rock_Sandstone_White"
    },
    {
      "x": 10,
      "y": 21,
      "z": 17,
      "name": "Rock_Sandstone_White"
    },
    {
      "x": 10,
      "y": 22,
      "z": 17,
      "name": "Rock_Sandstone_White"
    },
    {
      "x": 10,
      "y": 23,
      "z": 17,
      "name": "Rock_Sandstone_White"
    },
    {
      "x": 10,
      "y": 24,
      "z": 17,
      "name": "Rock_Sandstone_White"
    },
    {
      "x": 10,
      "y": 25,
      "z": 17,
      "name": "Rock_Sandstone_White"
    },
    {
      "x": 10,
      "y": 26,
      "z": 17,
      "name": "Soil_Dirt_Dry"
    },
    {
      "x": 10,
      "y": 27,
      "z": 17,
      "name": "Rock_Sandstone"
    },
    {
      "x": 10,
      "y": 28,
      "z": 17,
      "name": "Rock_Sandstone_White"
    },
    {
      "x": 10,
      "y": 29,
      "z": 17,
      "name": "Rock_Sandstone_White"
    },
    {
      "x": 10,
      "y": 30,
      "z": 17,
      "name": "Rock_Sandstone_White"
    },
    {
      "x": 10,
      "y": 31,
      "z": 17,
      "name": "Rock_Sandstone_White"
    },
    {
      "x": 10,
      "y": 32,
      "z": 17,
      "name": "Rock_Sandstone_White"
    },
    {
      "x": 10,
      "y": 33,
      "z": 17,
      "name": "Rock_Sandstone_White"
    },
    {
      "x": 10,
      "y": 34,
      "z": 17,
      "name": "Rock_Sandstone_White"
    },
    {
      "x": 10,
      "y": 35,
      "z": 17,
      "name": "Rock_Sandstone"
    },
    {
      "x": 10,
      "y": 36,
      "z": 17,
      "name": "Rock_Sandstone_White"
    },
    {
      "x": 10,
      "y": 37,
      "z": 17,
      "name": "Rock_Sandstone_White"
    },
    {
      "x": 10,
      "y": 3,
      "z": 18,
      "name": "Rock_Sandstone_White"
    },
    {
      "x": 10,
      "y": 4,
      "z": 18,
      "name": "Rock_Sandstone_White"
    },
    {
      "x": 10,
      "y": 5,
      "z": 18,
      "name": "Soil_Dirt_Dry"
    },
    {
      "x": 10,
      "y": 6,
      "z": 18,
      "name": "Rock_Sandstone"
    },
    {
      "x": 10,
      "y": 7,
      "z": 18,
      "name": "Rock_Sandstone"
    },
    {
      "x": 10,
      "y": 8,
      "z": 18,
      "name": "Rock_Sandstone_White"
    },
    {
      "x": 10,
      "y": 9,
      "z": 18,
      "name": "Rock_Sandstone_White"
    },
    {
      "x": 10,
      "y": 10,
      "z": 18,
      "name": "Rock_Sandstone_White"
    },
    {
      "x": 10,
      "y": 11,
      "z": 18,
      "name": "Rock_Sandstone_White"
    },
    {
      "x": 10,
      "y": 12,
      "z": 18,
      "name": "Rock_Sandstone_White"
    },
    {
      "x": 10,
      "y": 13,
      "z": 18,
      "name": "Rock_Sandstone_White"
    },
    {
      "x": 10,
      "y": 14,
      "z": 18,
      "name": "Rock_Sandstone_White"
    },
    {
      "x": 10,
      "y": 15,
      "z": 18,
      "name": "Rock_Sandstone_White"
    },
    {
      "x": 10,
      "y": 16,
      "z": 18,
      "name": "Rock_Sandstone_White"
    },
    {
      "x": 10,
      "y": 17,
      "z": 18,
      "name": "Rock_Sandstone"
    },
    {
      "x": 10,
      "y": 18,
      "z": 18,
      "name": "Rock_Sandstone_White"
    },
    {
      "x": 10,
      "y": 19,
      "z": 18,
      "name": "Rock_Sandstone_White"
    },
    {
      "x": 10,
      "y": 20,
      "z": 18,
      "name": "Rock_Sandstone_White"
    },
    {
      "x": 10,
      "y": 21,
      "z": 18,
      "name": "Rock_Sandstone_White"
    },
    {
      "x": 10,
      "y": 22,
      "z": 18,
      "name": "Rock_Sandstone_White"
    },
    {
      "x": 10,
      "y": 23,
      "z": 18,
      "name": "Rock_Sandstone_White"
    },
    {
      "x": 10,
      "y": 24,
      "z": 18,
      "name": "Rock_Sandstone_White"
    },
    {
      "x": 10,
      "y": 25,
      "z": 18,
      "name": "Rock_Sandstone_White"
    },
    {
      "x": 10,
      "y": 26,
      "z": 18,
      "name": "Soil_Dirt_Dry"
    },
    {
      "x": 10,
      "y": 27,
      "z": 18,
      "name": "Rock_Sandstone"
    },
    {
      "x": 10,
      "y": 28,
      "z": 18,
      "name": "Rock_Sandstone_White"
    },
    {
      "x": 10,
      "y": 29,
      "z": 18,
      "name": "Rock_Sandstone_White"
    },
    {
      "x": 10,
      "y": 30,
      "z": 18,
      "name": "Rock_Sandstone_White"
    },
    {
      "x": 10,
      "y": 31,
      "z": 18,
      "name": "Rock_Sandstone_White"
    },
    {
      "x": 10,
      "y": 32,
      "z": 18,
      "name": "Rock_Sandstone_White"
    },
    {
      "x": 10,
      "y": 33,
      "z": 18,
      "name": "Rock_Sandstone_White"
    },
    {
      "x": 10,
      "y": 34,
      "z": 18,
      "name": "Rock_Sandstone_White"
    },
    {
      "x": 10,
      "y": 35,
      "z": 18,
      "name": "Rock_Sandstone"
    },
    {
      "x": 10,
      "y": 36,
      "z": 18,
      "name": "Rock_Sandstone_White"
    },
    {
      "x": 10,
      "y": 37,
      "z": 18,
      "name": "Rock_Sandstone_White"
    },
    {
      "x": 10,
      "y": 3,
      "z": 19,
      "name": "Rock_Sandstone_White"
    },
    {
      "x": 10,
      "y": 4,
      "z": 19,
      "name": "Rock_Sandstone_White"
    },
    {
      "x": 10,
      "y": 5,
      "z": 19,
      "name": "Soil_Dirt_Dry"
    },
    {
      "x": 10,
      "y": 6,
      "z": 19,
      "name": "Rock_Sandstone"
    },
    {
      "x": 10,
      "y": 7,
      "z": 19,
      "name": "Rock_Sandstone_White"
    },
    {
      "x": 10,
      "y": 8,
      "z": 19,
      "name": "Rock_Sandstone_White"
    },
    {
      "x": 10,
      "y": 9,
      "z": 19,
      "name": "Rock_Sandstone_White"
    },
    {
      "x": 10,
      "y": 10,
      "z": 19,
      "name": "Rock_Sandstone_White"
    },
    {
      "x": 10,
      "y": 11,
      "z": 19,
      "name": "Rock_Sandstone_White"
    },
    {
      "x": 10,
      "y": 12,
      "z": 19,
      "name": "Rock_Sandstone_White"
    },
    {
      "x": 10,
      "y": 13,
      "z": 19,
      "name": "Rock_Sandstone_White"
    },
    {
      "x": 10,
      "y": 14,
      "z": 19,
      "name": "Rock_Sandstone_White"
    },
    {
      "x": 10,
      "y": 15,
      "z": 19,
      "name": "Rock_Sandstone_White"
    },
    {
      "x": 10,
      "y": 16,
      "z": 19,
      "name": "Rock_Sandstone_White"
    },
    {
      "x": 10,
      "y": 17,
      "z": 19,
      "name": "Rock_Sandstone"
    },
    {
      "x": 10,
      "y": 18,
      "z": 19,
      "name": "Rock_Sandstone_White"
    },
    {
      "x": 10,
      "y": 21,
      "z": 19,
      "name": "Rock_Sandstone_White"
    },
    {
      "x": 10,
      "y": 22,
      "z": 19,
      "name": "Rock_Sandstone_White"
    },
    {
      "x": 10,
      "y": 23,
      "z": 19,
      "name": "Rock_Sandstone_White"
    },
    {
      "x": 10,
      "y": 24,
      "z": 19,
      "name": "Rock_Sandstone_White"
    },
    {
      "x": 10,
      "y": 25,
      "z": 19,
      "name": "Rock_Sandstone_White"
    },
    {
      "x": 10,
      "y": 26,
      "z": 19,
      "name": "Soil_Dirt_Dry"
    },
    {
      "x": 10,
      "y": 27,
      "z": 19,
      "name": "Rock_Sandstone"
    },
    {
      "x": 10,
      "y": 28,
      "z": 19,
      "name": "Rock_Sandstone_White"
    },
    {
      "x": 10,
      "y": 33,
      "z": 19,
      "name": "Rock_Sandstone_White"
    },
    {
      "x": 10,
      "y": 34,
      "z": 19,
      "name": "Rock_Sandstone_White"
    },
    {
      "x": 10,
      "y": 35,
      "z": 19,
      "name": "Rock_Sandstone"
    },
    {
      "x": 10,
      "y": 36,
      "z": 19,
      "name": "Rock_Sandstone_White"
    },
    {
      "x": 10,
      "y": 37,
      "z": 19,
      "name": "Rock_Sandstone_White"
    },
    {
      "x": 10,
      "y": 3,
      "z": 20,
      "name": "Rock_Sandstone_White"
    },
    {
      "x": 10,
      "y": 4,
      "z": 20,
      "name": "Rock_Sandstone_White"
    },
    {
      "x": 10,
      "y": 5,
      "z": 20,
      "name": "Soil_Dirt_Dry"
    },
    {
      "x": 10,
      "y": 6,
      "z": 20,
      "name": "Rock_Sandstone"
    },
    {
      "x": 10,
      "y": 7,
      "z": 20,
      "name": "Rock_Sandstone_White"
    },
    {
      "x": 10,
      "y": 8,
      "z": 20,
      "name": "Rock_Sandstone_White"
    },
    {
      "x": 10,
      "y": 9,
      "z": 20,
      "name": "Rock_Sandstone_White"
    },
    {
      "x": 10,
      "y": 10,
      "z": 20,
      "name": "Rock_Sandstone_White"
    },
    {
      "x": 10,
      "y": 11,
      "z": 20,
      "name": "Rock_Sandstone_White"
    },
    {
      "x": 10,
      "y": 12,
      "z": 20,
      "name": "Rock_Sandstone_White"
    },
    {
      "x": 10,
      "y": 13,
      "z": 20,
      "name": "Rock_Sandstone_White"
    },
    {
      "x": 10,
      "y": 15,
      "z": 20,
      "name": "Rock_Sandstone_White"
    },
    {
      "x": 10,
      "y": 16,
      "z": 20,
      "name": "Rock_Sandstone_White"
    },
    {
      "x": 10,
      "y": 17,
      "z": 20,
      "name": "Rock_Sandstone"
    },
    {
      "x": 10,
      "y": 18,
      "z": 20,
      "name": "Rock_Sandstone_White"
    },
    {
      "x": 10,
      "y": 3,
      "z": 21,
      "name": "Rock_Sandstone_White"
    },
    {
      "x": 10,
      "y": 4,
      "z": 21,
      "name": "Rock_Sandstone_White"
    },
    {
      "x": 10,
      "y": 5,
      "z": 21,
      "name": "Soil_Dirt_Dry"
    },
    {
      "x": 10,
      "y": 6,
      "z": 21,
      "name": "Rock_Sandstone"
    },
    {
      "x": 10,
      "y": 7,
      "z": 21,
      "name": "Rock_Sandstone_White"
    },
    {
      "x": 10,
      "y": 8,
      "z": 21,
      "name": "Rock_Sandstone_White"
    },
    {
      "x": 10,
      "y": 15,
      "z": 21,
      "name": "Rock_Sandstone_White"
    },
    {
      "x": 10,
      "y": 16,
      "z": 21,
      "name": "Rock_Sandstone_White"
    },
    {
      "x": 10,
      "y": 17,
      "z": 21,
      "name": "Rock_Sandstone"
    },
    {
      "x": 10,
      "y": 18,
      "z": 21,
      "name": "Rock_Sandstone"
    },
    {
      "x": 10,
      "y": 19,
      "z": 21,
      "name": "Rock_Sandstone_White"
    },
    {
      "x": 10,
      "y": 15,
      "z": 22,
      "name": "Rock_Sandstone_White"
    },
    {
      "x": 10,
      "y": 16,
      "z": 22,
      "name": "Rock_Sandstone_White"
    },
    {
      "x": 10,
      "y": 17,
      "z": 22,
      "name": "Rock_Sandstone_White"
    },
    {
      "x": 10,
      "y": 18,
      "z": 22,
      "name": "Rock_Sandstone"
    },
    {
      "x": 10,
      "y": 19,
      "z": 22,
      "name": "Rock_Sandstone_White"
    },
    {
      "x": 10,
      "y": 20,
      "z": 22,
      "name": "Rock_Sandstone_White"
    },
    {
      "x": 10,
      "y": 21,
      "z": 22,
      "name": "Rock_Sandstone_White"
    },
    {
      "x": 10,
      "y": 22,
      "z": 22,
      "name": "Rock_Sandstone_White"
    },
    {
      "x": 10,
      "y": 23,
      "z": 22,
      "name": "Rock_Sandstone_White"
    },
    {
      "x": 10,
      "y": 24,
      "z": 22,
      "name": "Rock_Sandstone_White"
    },
    {
      "x": 10,
      "y": 16,
      "z": 23,
      "name": "Rock_Sandstone_White"
    },
    {
      "x": 10,
      "y": 17,
      "z": 23,
      "name": "Rock_Sandstone_White"
    },
    {
      "x": 10,
      "y": 18,
      "z": 23,
      "name": "Rock_Sandstone"
    },
    {
      "x": 10,
      "y": 19,
      "z": 23,
      "name": "Rock_Sandstone_White"
    },
    {
      "x": 10,
      "y": 20,
      "z": 23,
      "name": "Rock_Sandstone_White"
    },
    {
      "x": 10,
      "y": 21,
      "z": 23,
      "name": "Rock_Sandstone_White"
    },
    {
      "x": 10,
      "y": 22,
      "z": 23,
      "name": "Rock_Sandstone_White"
    },
    {
      "x": 10,
      "y": 23,
      "z": 23,
      "name": "Rock_Sandstone_White"
    },
    {
      "x": 10,
      "y": 24,
      "z": 23,
      "name": "Rock_Sandstone_White"
    },
    {
      "x": 10,
      "y": 25,
      "z": 23,
      "name": "Rock_Sandstone"
    },
    {
      "x": 10,
      "y": 26,
      "z": 23,
      "name": "Rock_Sandstone_White"
    },
    {
      "x": 10,
      "y": 16,
      "z": 24,
      "name": "Rock_Sandstone_White"
    },
    {
      "x": 10,
      "y": 17,
      "z": 24,
      "name": "Rock_Sandstone_White"
    },
    {
      "x": 10,
      "y": 18,
      "z": 24,
      "name": "Rock_Sandstone"
    },
    {
      "x": 10,
      "y": 19,
      "z": 24,
      "name": "Rock_Sandstone_White"
    },
    {
      "x": 10,
      "y": 20,
      "z": 24,
      "name": "Rock_Sandstone_White"
    },
    {
      "x": 10,
      "y": 21,
      "z": 24,
      "name": "Rock_Sandstone_White"
    },
    {
      "x": 10,
      "y": 22,
      "z": 24,
      "name": "Rock_Sandstone_White"
    },
    {
      "x": 10,
      "y": 23,
      "z": 24,
      "name": "Rock_Sandstone_White"
    },
    {
      "x": 10,
      "y": 24,
      "z": 24,
      "name": "Rock_Sandstone_White"
    },
    {
      "x": 10,
      "y": 25,
      "z": 24,
      "name": "Rock_Sandstone"
    },
    {
      "x": 10,
      "y": 26,
      "z": 24,
      "name": "Rock_Sandstone_White"
    },
    {
      "x": 10,
      "y": 16,
      "z": 25,
      "name": "Rock_Sandstone_White"
    },
    {
      "x": 10,
      "y": 17,
      "z": 25,
      "name": "Rock_Sandstone_White"
    },
    {
      "x": 10,
      "y": 18,
      "z": 25,
      "name": "Rock_Sandstone"
    },
    {
      "x": 10,
      "y": 19,
      "z": 25,
      "name": "Rock_Sandstone_White"
    },
    {
      "x": 10,
      "y": 20,
      "z": 25,
      "name": "Rock_Sandstone_White"
    },
    {
      "x": 10,
      "y": 21,
      "z": 25,
      "name": "Rock_Sandstone_White"
    },
    {
      "x": 10,
      "y": 22,
      "z": 25,
      "name": "Rock_Sandstone_White"
    },
    {
      "x": 10,
      "y": 23,
      "z": 25,
      "name": "Rock_Sandstone_White"
    },
    {
      "x": 10,
      "y": 24,
      "z": 25,
      "name": "Rock_Sandstone_White"
    },
    {
      "x": 10,
      "y": 25,
      "z": 25,
      "name": "Rock_Sandstone"
    },
    {
      "x": 10,
      "y": 26,
      "z": 25,
      "name": "Rock_Sandstone_White"
    },
    {
      "x": 10,
      "y": 16,
      "z": 26,
      "name": "Rock_Sandstone_White"
    },
    {
      "x": 10,
      "y": 17,
      "z": 26,
      "name": "Rock_Sandstone_White"
    },
    {
      "x": 10,
      "y": 18,
      "z": 26,
      "name": "Rock_Sandstone"
    },
    {
      "x": 10,
      "y": 19,
      "z": 26,
      "name": "Rock_Sandstone_White"
    },
    {
      "x": 10,
      "y": 20,
      "z": 26,
      "name": "Rock_Sandstone_White"
    },
    {
      "x": 10,
      "y": 21,
      "z": 26,
      "name": "Rock_Sandstone_White"
    },
    {
      "x": 10,
      "y": 22,
      "z": 26,
      "name": "Rock_Sandstone_White"
    },
    {
      "x": 10,
      "y": 23,
      "z": 26,
      "name": "Rock_Sandstone_White"
    },
    {
      "x": 10,
      "y": 24,
      "z": 26,
      "name": "Rock_Sandstone_White"
    },
    {
      "x": 10,
      "y": 25,
      "z": 26,
      "name": "Rock_Sandstone"
    },
    {
      "x": 10,
      "y": 26,
      "z": 26,
      "name": "Rock_Sandstone_White"
    },
    {
      "x": 10,
      "y": 16,
      "z": 27,
      "name": "Rock_Sandstone_White"
    },
    {
      "x": 10,
      "y": 17,
      "z": 27,
      "name": "Rock_Sandstone_White"
    },
    {
      "x": 10,
      "y": 18,
      "z": 27,
      "name": "Rock_Sandstone"
    },
    {
      "x": 10,
      "y": 19,
      "z": 27,
      "name": "Rock_Sandstone_White"
    },
    {
      "x": 11,
      "y": 14,
      "z": 6,
      "name": "Rock_Sandstone_White"
    },
    {
      "x": 11,
      "y": 15,
      "z": 6,
      "name": "Rock_Sandstone"
    },
    {
      "x": 11,
      "y": 16,
      "z": 6,
      "name": "Rock_Sandstone_White"
    },
    {
      "x": 11,
      "y": 14,
      "z": 7,
      "name": "Rock_Sandstone_White"
    },
    {
      "x": 11,
      "y": 15,
      "z": 7,
      "name": "Rock_Sandstone"
    },
    {
      "x": 11,
      "y": 16,
      "z": 7,
      "name": "Rock_Sandstone_White"
    },
    {
      "x": 11,
      "y": 14,
      "z": 8,
      "name": "Rock_Sandstone_White"
    },
    {
      "x": 11,
      "y": 15,
      "z": 8,
      "name": "Rock_Sandstone"
    },
    {
      "x": 11,
      "y": 16,
      "z": 8,
      "name": "Rock_Sandstone_White"
    },
    {
      "x": 11,
      "y": 17,
      "z": 8,
      "name": "Rock_Sandstone_White"
    },
    {
      "x": 11,
      "y": 18,
      "z": 8,
      "name": "Rock_Sandstone_White"
    },
    {
      "x": 11,
      "y": 19,
      "z": 8,
      "name": "Rock_Sandstone_White"
    },
    {
      "x": 11,
      "y": 20,
      "z": 8,
      "name": "Rock_Sandstone"
    },
    {
      "x": 11,
      "y": 21,
      "z": 8,
      "name": "Rock_Sandstone_White"
    },
    {
      "x": 11,
      "y": 22,
      "z": 8,
      "name": "Rock_Sandstone_White"
    },
    {
      "x": 11,
      "y": 14,
      "z": 9,
      "name": "Rock_Sandstone_White"
    },
    {
      "x": 11,
      "y": 15,
      "z": 9,
      "name": "Rock_Sandstone"
    },
    {
      "x": 11,
      "y": 16,
      "z": 9,
      "name": "Rock_Sandstone_White"
    },
    {
      "x": 11,
      "y": 17,
      "z": 9,
      "name": "Rock_Sandstone_White"
    },
    {
      "x": 11,
      "y": 18,
      "z": 9,
      "name": "Rock_Sandstone_White"
    },
    {
      "x": 11,
      "y": 19,
      "z": 9,
      "name": "Rock_Sandstone_White"
    },
    {
      "x": 11,
      "y": 20,
      "z": 9,
      "name": "Rock_Sandstone"
    },
    {
      "x": 11,
      "y": 21,
      "z": 9,
      "name": "Rock_Sandstone_White"
    },
    {
      "x": 11,
      "y": 22,
      "z": 9,
      "name": "Rock_Sandstone_White"
    },
    {
      "x": 11,
      "y": 14,
      "z": 10,
      "name": "Rock_Sandstone_White"
    },
    {
      "x": 11,
      "y": 15,
      "z": 10,
      "name": "Rock_Sandstone_White"
    },
    {
      "x": 11,
      "y": 16,
      "z": 10,
      "name": "Rock_Sandstone_White"
    },
    {
      "x": 11,
      "y": 17,
      "z": 10,
      "name": "Rock_Sandstone_White"
    },
    {
      "x": 11,
      "y": 18,
      "z": 10,
      "name": "Rock_Sandstone_White"
    },
    {
      "x": 11,
      "y": 19,
      "z": 10,
      "name": "Rock_Sandstone_White"
    },
    {
      "x": 11,
      "y": 20,
      "z": 10,
      "name": "Rock_Sandstone"
    },
    {
      "x": 11,
      "y": 21,
      "z": 10,
      "name": "Rock_Sandstone_White"
    },
    {
      "x": 11,
      "y": 22,
      "z": 10,
      "name": "Rock_Sandstone_White"
    },
    {
      "x": 11,
      "y": 14,
      "z": 11,
      "name": "Rock_Sandstone_White"
    },
    {
      "x": 11,
      "y": 15,
      "z": 11,
      "name": "Rock_Sandstone_White"
    },
    {
      "x": 11,
      "y": 16,
      "z": 11,
      "name": "Rock_Sandstone"
    },
    {
      "x": 11,
      "y": 17,
      "z": 11,
      "name": "Rock_Sandstone_White"
    },
    {
      "x": 11,
      "y": 18,
      "z": 11,
      "name": "Rock_Sandstone_White"
    },
    {
      "x": 11,
      "y": 19,
      "z": 11,
      "name": "Rock_Sandstone"
    },
    {
      "x": 11,
      "y": 20,
      "z": 11,
      "name": "Rock_Sandstone"
    },
    {
      "x": 11,
      "y": 21,
      "z": 11,
      "name": "Rock_Sandstone_White"
    },
    {
      "x": 11,
      "y": 22,
      "z": 11,
      "name": "Rock_Sandstone_White"
    },
    {
      "x": 11,
      "y": 14,
      "z": 12,
      "name": "Rock_Sandstone_White"
    },
    {
      "x": 11,
      "y": 15,
      "z": 12,
      "name": "Rock_Sandstone_White"
    },
    {
      "x": 11,
      "y": 16,
      "z": 12,
      "name": "Rock_Sandstone"
    },
    {
      "x": 11,
      "y": 17,
      "z": 12,
      "name": "Rock_Sandstone_White"
    },
    {
      "x": 11,
      "y": 20,
      "z": 12,
      "name": "Rock_Sandstone"
    },
    {
      "x": 11,
      "y": 21,
      "z": 12,
      "name": "Rock_Sandstone_White"
    },
    {
      "x": 11,
      "y": 14,
      "z": 13,
      "name": "Rock_Sandstone_White"
    },
    {
      "x": 11,
      "y": 15,
      "z": 13,
      "name": "Rock_Sandstone_White"
    },
    {
      "x": 11,
      "y": 16,
      "z": 13,
      "name": "Rock_Sandstone"
    },
    {
      "x": 11,
      "y": 17,
      "z": 13,
      "name": "Rock_Sandstone_White"
    },
    {
      "x": 11,
      "y": 18,
      "z": 13,
      "name": "Rock_Sandstone_White"
    },
    {
      "x": 11,
      "y": 4,
      "z": 14,
      "name": "Rock_Sandstone_White"
    },
    {
      "x": 11,
      "y": 5,
      "z": 14,
      "name": "Rock_Sandstone_White"
    },
    {
      "x": 11,
      "y": 6,
      "z": 14,
      "name": "Rock_Sandstone_White"
    },
    {
      "x": 11,
      "y": 7,
      "z": 14,
      "name": "Rock_Sandstone_White"
    },
    {
      "x": 11,
      "y": 8,
      "z": 14,
      "name": "Rock_Sandstone_White"
    },
    {
      "x": 11,
      "y": 9,
      "z": 14,
      "name": "Rock_Sandstone_White"
    },
    {
      "x": 11,
      "y": 10,
      "z": 14,
      "name": "Rock_Sandstone_White"
    },
    {
      "x": 11,
      "y": 11,
      "z": 14,
      "name": "Rock_Sandstone_White"
    },
    {
      "x": 11,
      "y": 14,
      "z": 14,
      "name": "Rock_Sandstone_White"
    },
    {
      "x": 11,
      "y": 15,
      "z": 14,
      "name": "Rock_Sandstone_White"
    },
    {
      "x": 11,
      "y": 16,
      "z": 14,
      "name": "Rock_Sandstone_White"
    },
    {
      "x": 11,
      "y": 17,
      "z": 14,
      "name": "Rock_Sandstone_White"
    },
    {
      "x": 11,
      "y": 18,
      "z": 14,
      "name": "Rock_Sandstone_White"
    },
    {
      "x": 11,
      "y": 20,
      "z": 14,
      "name": "Rock_Sandstone_White"
    },
    {
      "x": 11,
      "y": 21,
      "z": 14,
      "name": "Rock_Sandstone_White"
    },
    {
      "x": 11,
      "y": 22,
      "z": 14,
      "name": "Rock_Sandstone_White"
    },
    {
      "x": 11,
      "y": 23,
      "z": 14,
      "name": "Rock_Sandstone_White"
    },
    {
      "x": 11,
      "y": 24,
      "z": 14,
      "name": "Rock_Sandstone_White"
    },
    {
      "x": 11,
      "y": 25,
      "z": 14,
      "name": "Rock_Sandstone_White"
    },
    {
      "x": 11,
      "y": 26,
      "z": 14,
      "name": "Soil_Dirt_Dry"
    },
    {
      "x": 11,
      "y": 27,
      "z": 14,
      "name": "Rock_Sandstone"
    },
    {
      "x": 11,
      "y": 28,
      "z": 14,
      "name": "Rock_Sandstone_White"
    },
    {
      "x": 11,
      "y": 29,
      "z": 14,
      "name": "Rock_Sandstone_White"
    },
    {
      "x": 11,
      "y": 32,
      "z": 14,
      "name": "Rock_Sandstone_White"
    },
    {
      "x": 11,
      "y": 33,
      "z": 14,
      "name": "Rock_Sandstone_White"
    },
    {
      "x": 11,
      "y": 34,
      "z": 14,
      "name": "Rock_Sandstone_White"
    },
    {
      "x": 11,
      "y": 35,
      "z": 14,
      "name": "Rock_Sandstone"
    },
    {
      "x": 11,
      "y": 36,
      "z": 14,
      "name": "Rock_Sandstone_White"
    },
    {
      "x": 11,
      "y": 3,
      "z": 15,
      "name": "Rock_Sandstone_White"
    },
    {
      "x": 11,
      "y": 4,
      "z": 15,
      "name": "Rock_Sandstone_White"
    },
    {
      "x": 11,
      "y": 5,
      "z": 15,
      "name": "Rock_Sandstone_White"
    },
    {
      "x": 11,
      "y": 6,
      "z": 15,
      "name": "Soil_Dirt_Dry"
    },
    {
      "x": 11,
      "y": 7,
      "z": 15,
      "name": "Rock_Sandstone"
    },
    {
      "x": 11,
      "y": 8,
      "z": 15,
      "name": "Rock_Sandstone_White"
    },
    {
      "x": 11,
      "y": 9,
      "z": 15,
      "name": "Rock_Sandstone_White"
    },
    {
      "x": 11,
      "y": 10,
      "z": 15,
      "name": "Rock_Sandstone_White"
    },
    {
      "x": 11,
      "y": 11,
      "z": 15,
      "name": "Rock_Sandstone_White"
    },
    {
      "x": 11,
      "y": 12,
      "z": 15,
      "name": "Rock_Sandstone_White"
    },
    {
      "x": 11,
      "y": 13,
      "z": 15,
      "name": "Rock_Sandstone_White"
    },
    {
      "x": 11,
      "y": 14,
      "z": 15,
      "name": "Rock_Sandstone_White"
    },
    {
      "x": 11,
      "y": 15,
      "z": 15,
      "name": "Rock_Sandstone_White"
    },
    {
      "x": 11,
      "y": 16,
      "z": 15,
      "name": "Rock_Sandstone_White"
    },
    {
      "x": 11,
      "y": 17,
      "z": 15,
      "name": "Rock_Sandstone"
    },
    {
      "x": 11,
      "y": 18,
      "z": 15,
      "name": "Rock_Sandstone_White"
    },
    {
      "x": 11,
      "y": 19,
      "z": 15,
      "name": "Rock_Sandstone_White"
    },
    {
      "x": 11,
      "y": 20,
      "z": 15,
      "name": "Rock_Sandstone_White"
    },
    {
      "x": 11,
      "y": 21,
      "z": 15,
      "name": "Rock_Sandstone_White"
    },
    {
      "x": 11,
      "y": 22,
      "z": 15,
      "name": "Rock_Sandstone_White"
    },
    {
      "x": 11,
      "y": 23,
      "z": 15,
      "name": "Rock_Sandstone_White"
    },
    {
      "x": 11,
      "y": 24,
      "z": 15,
      "name": "Rock_Sandstone_White"
    },
    {
      "x": 11,
      "y": 25,
      "z": 15,
      "name": "Rock_Sandstone_White"
    },
    {
      "x": 11,
      "y": 26,
      "z": 15,
      "name": "Soil_Dirt_Dry"
    },
    {
      "x": 11,
      "y": 27,
      "z": 15,
      "name": "Rock_Sandstone"
    },
    {
      "x": 11,
      "y": 28,
      "z": 15,
      "name": "Rock_Sandstone_White"
    },
    {
      "x": 11,
      "y": 29,
      "z": 15,
      "name": "Rock_Sandstone_White"
    },
    {
      "x": 11,
      "y": 30,
      "z": 15,
      "name": "Rock_Sandstone_White"
    },
    {
      "x": 11,
      "y": 31,
      "z": 15,
      "name": "Rock_Sandstone_White"
    },
    {
      "x": 11,
      "y": 32,
      "z": 15,
      "name": "Rock_Sandstone_White"
    },
    {
      "x": 11,
      "y": 33,
      "z": 15,
      "name": "Rock_Sandstone_White"
    },
    {
      "x": 11,
      "y": 34,
      "z": 15,
      "name": "Rock_Sandstone_White"
    },
    {
      "x": 11,
      "y": 35,
      "z": 15,
      "name": "Rock_Sandstone"
    },
    {
      "x": 11,
      "y": 36,
      "z": 15,
      "name": "Rock_Sandstone_White"
    },
    {
      "x": 11,
      "y": 37,
      "z": 15,
      "name": "Rock_Sandstone_White"
    },
    {
      "x": 11,
      "y": 3,
      "z": 16,
      "name": "Rock_Sandstone_White"
    },
    {
      "x": 11,
      "y": 4,
      "z": 16,
      "name": "Rock_Sandstone_White"
    },
    {
      "x": 11,
      "y": 5,
      "z": 16,
      "name": "Rock_Sandstone_White"
    },
    {
      "x": 11,
      "y": 6,
      "z": 16,
      "name": "Soil_Dirt_Dry"
    },
    {
      "x": 11,
      "y": 7,
      "z": 16,
      "name": "Rock_Sandstone"
    },
    {
      "x": 11,
      "y": 8,
      "z": 16,
      "name": "Rock_Sandstone_White"
    },
    {
      "x": 11,
      "y": 9,
      "z": 16,
      "name": "Rock_Sandstone_White"
    },
    {
      "x": 11,
      "y": 10,
      "z": 16,
      "name": "Rock_Sandstone_White"
    },
    {
      "x": 11,
      "y": 11,
      "z": 16,
      "name": "Rock_Sandstone_White"
    },
    {
      "x": 11,
      "y": 12,
      "z": 16,
      "name": "Rock_Sandstone_White"
    },
    {
      "x": 11,
      "y": 13,
      "z": 16,
      "name": "Rock_Sandstone_White"
    },
    {
      "x": 11,
      "y": 14,
      "z": 16,
      "name": "Rock_Sandstone_White"
    },
    {
      "x": 11,
      "y": 15,
      "z": 16,
      "name": "Rock_Sandstone_White"
    },
    {
      "x": 11,
      "y": 16,
      "z": 16,
      "name": "Rock_Sandstone_White"
    },
    {
      "x": 11,
      "y": 17,
      "z": 16,
      "name": "Rock_Sandstone"
    },
    {
      "x": 11,
      "y": 18,
      "z": 16,
      "name": "Rock_Sandstone_White"
    },
    {
      "x": 11,
      "y": 19,
      "z": 16,
      "name": "Rock_Sandstone_White"
    },
    {
      "x": 11,
      "y": 20,
      "z": 16,
      "name": "Rock_Sandstone_White"
    },
    {
      "x": 11,
      "y": 21,
      "z": 16,
      "name": "Rock_Sandstone_White"
    },
    {
      "x": 11,
      "y": 22,
      "z": 16,
      "name": "Rock_Sandstone_White"
    },
    {
      "x": 11,
      "y": 23,
      "z": 16,
      "name": "Rock_Sandstone_White"
    },
    {
      "x": 11,
      "y": 24,
      "z": 16,
      "name": "Rock_Sandstone_White"
    },
    {
      "x": 11,
      "y": 25,
      "z": 16,
      "name": "Rock_Sandstone_White"
    },
    {
      "x": 11,
      "y": 26,
      "z": 16,
      "name": "Rock_Sandstone_White"
    },
    {
      "x": 11,
      "y": 27,
      "z": 16,
      "name": "Rock_Sandstone"
    },
    {
      "x": 11,
      "y": 28,
      "z": 16,
      "name": "Rock_Sandstone_White"
    },
    {
      "x": 11,
      "y": 29,
      "z": 16,
      "name": "Rock_Sandstone_White"
    },
    {
      "x": 11,
      "y": 30,
      "z": 16,
      "name": "Rock_Sandstone_White"
    },
    {
      "x": 11,
      "y": 31,
      "z": 16,
      "name": "Rock_Sandstone_White"
    },
    {
      "x": 11,
      "y": 32,
      "z": 16,
      "name": "Rock_Sandstone_White"
    },
    {
      "x": 11,
      "y": 33,
      "z": 16,
      "name": "Rock_Sandstone_White"
    },
    {
      "x": 11,
      "y": 34,
      "z": 16,
      "name": "Rock_Sandstone_White"
    },
    {
      "x": 11,
      "y": 35,
      "z": 16,
      "name": "Rock_Sandstone"
    },
    {
      "x": 11,
      "y": 36,
      "z": 16,
      "name": "Rock_Sandstone_White"
    },
    {
      "x": 11,
      "y": 37,
      "z": 16,
      "name": "Rock_Sandstone_White"
    },
    {
      "x": 11,
      "y": 3,
      "z": 17,
      "name": "Rock_Sandstone_White"
    },
    {
      "x": 11,
      "y": 4,
      "z": 17,
      "name": "Rock_Sandstone_White"
    },
    {
      "x": 11,
      "y": 5,
      "z": 17,
      "name": "Soil_Dirt_Dry"
    },
    {
      "x": 11,
      "y": 6,
      "z": 17,
      "name": "Soil_Dirt_Dry"
    },
    {
      "x": 11,
      "y": 7,
      "z": 17,
      "name": "Rock_Sandstone"
    },
    {
      "x": 11,
      "y": 8,
      "z": 17,
      "name": "Rock_Sandstone_White"
    },
    {
      "x": 11,
      "y": 9,
      "z": 17,
      "name": "Rock_Sandstone_White"
    },
    {
      "x": 11,
      "y": 10,
      "z": 17,
      "name": "Rock_Sandstone_White"
    },
    {
      "x": 11,
      "y": 11,
      "z": 17,
      "name": "Rock_Sandstone_White"
    },
    {
      "x": 11,
      "y": 12,
      "z": 17,
      "name": "Rock_Sandstone_White"
    },
    {
      "x": 11,
      "y": 13,
      "z": 17,
      "name": "Rock_Sandstone_White"
    },
    {
      "x": 11,
      "y": 14,
      "z": 17,
      "name": "Rock_Sandstone_White"
    },
    {
      "x": 11,
      "y": 15,
      "z": 17,
      "name": "Rock_Sandstone_White"
    },
    {
      "x": 11,
      "y": 16,
      "z": 17,
      "name": "Rock_Sandstone_White"
    },
    {
      "x": 11,
      "y": 17,
      "z": 17,
      "name": "Rock_Sandstone"
    },
    {
      "x": 11,
      "y": 18,
      "z": 17,
      "name": "Rock_Sandstone_White"
    },
    {
      "x": 11,
      "y": 19,
      "z": 17,
      "name": "Rock_Sandstone_White"
    },
    {
      "x": 11,
      "y": 20,
      "z": 17,
      "name": "Rock_Sandstone_White"
    },
    {
      "x": 11,
      "y": 21,
      "z": 17,
      "name": "Rock_Sandstone_White"
    },
    {
      "x": 11,
      "y": 22,
      "z": 17,
      "name": "Rock_Sandstone_White"
    },
    {
      "x": 11,
      "y": 23,
      "z": 17,
      "name": "Rock_Sandstone_White"
    },
    {
      "x": 11,
      "y": 24,
      "z": 17,
      "name": "Rock_Sandstone_White"
    },
    {
      "x": 11,
      "y": 25,
      "z": 17,
      "name": "Rock_Sandstone_White"
    },
    {
      "x": 11,
      "y": 26,
      "z": 17,
      "name": "Soil_Dirt_Dry"
    },
    {
      "x": 11,
      "y": 27,
      "z": 17,
      "name": "Rock_Sandstone_White"
    },
    {
      "x": 11,
      "y": 28,
      "z": 17,
      "name": "Rock_Sandstone_White"
    },
    {
      "x": 11,
      "y": 29,
      "z": 17,
      "name": "Rock_Sandstone_White"
    },
    {
      "x": 11,
      "y": 30,
      "z": 17,
      "name": "Rock_Sandstone_White"
    },
    {
      "x": 11,
      "y": 31,
      "z": 17,
      "name": "Rock_Sandstone_White"
    },
    {
      "x": 11,
      "y": 32,
      "z": 17,
      "name": "Rock_Sandstone_White"
    },
    {
      "x": 11,
      "y": 33,
      "z": 17,
      "name": "Rock_Sandstone_White"
    },
    {
      "x": 11,
      "y": 34,
      "z": 17,
      "name": "Rock_Sandstone_White"
    },
    {
      "x": 11,
      "y": 35,
      "z": 17,
      "name": "Rock_Sandstone"
    },
    {
      "x": 11,
      "y": 36,
      "z": 17,
      "name": "Rock_Sandstone_White"
    },
    {
      "x": 11,
      "y": 37,
      "z": 17,
      "name": "Rock_Sandstone_White"
    },
    {
      "x": 11,
      "y": 3,
      "z": 18,
      "name": "Rock_Sandstone_White"
    },
    {
      "x": 11,
      "y": 4,
      "z": 18,
      "name": "Rock_Sandstone_White"
    },
    {
      "x": 11,
      "y": 5,
      "z": 18,
      "name": "Rock_Sandstone_White"
    },
    {
      "x": 11,
      "y": 6,
      "z": 18,
      "name": "Rock_Sandstone"
    },
    {
      "x": 11,
      "y": 7,
      "z": 18,
      "name": "Rock_Sandstone"
    },
    {
      "x": 11,
      "y": 8,
      "z": 18,
      "name": "Rock_Sandstone_White"
    },
    {
      "x": 11,
      "y": 9,
      "z": 18,
      "name": "Rock_Sandstone_White"
    },
    {
      "x": 11,
      "y": 10,
      "z": 18,
      "name": "Rock_Sandstone_White"
    },
    {
      "x": 11,
      "y": 11,
      "z": 18,
      "name": "Rock_Sandstone_White"
    },
    {
      "x": 11,
      "y": 12,
      "z": 18,
      "name": "Rock_Sandstone_White"
    },
    {
      "x": 11,
      "y": 13,
      "z": 18,
      "name": "Rock_Sandstone_White"
    },
    {
      "x": 11,
      "y": 14,
      "z": 18,
      "name": "Rock_Sandstone_White"
    },
    {
      "x": 11,
      "y": 15,
      "z": 18,
      "name": "Rock_Sandstone_White"
    },
    {
      "x": 11,
      "y": 16,
      "z": 18,
      "name": "Rock_Sandstone_White"
    },
    {
      "x": 11,
      "y": 17,
      "z": 18,
      "name": "Rock_Sandstone"
    },
    {
      "x": 11,
      "y": 18,
      "z": 18,
      "name": "Rock_Sandstone_White"
    },
    {
      "x": 11,
      "y": 19,
      "z": 18,
      "name": "Rock_Sandstone_White"
    },
    {
      "x": 11,
      "y": 20,
      "z": 18,
      "name": "Rock_Sandstone_White"
    },
    {
      "x": 11,
      "y": 21,
      "z": 18,
      "name": "Rock_Sandstone_White"
    },
    {
      "x": 11,
      "y": 22,
      "z": 18,
      "name": "Rock_Sandstone_White"
    },
    {
      "x": 11,
      "y": 23,
      "z": 18,
      "name": "Rock_Sandstone_White"
    },
    {
      "x": 11,
      "y": 24,
      "z": 18,
      "name": "Rock_Sandstone_White"
    },
    {
      "x": 11,
      "y": 25,
      "z": 18,
      "name": "Rock_Sandstone_White"
    },
    {
      "x": 11,
      "y": 26,
      "z": 18,
      "name": "Soil_Dirt_Dry"
    },
    {
      "x": 11,
      "y": 27,
      "z": 18,
      "name": "Rock_Sandstone"
    },
    {
      "x": 11,
      "y": 28,
      "z": 18,
      "name": "Rock_Sandstone_White"
    },
    {
      "x": 11,
      "y": 29,
      "z": 18,
      "name": "Rock_Sandstone_White"
    },
    {
      "x": 11,
      "y": 30,
      "z": 18,
      "name": "Rock_Sandstone_White"
    },
    {
      "x": 11,
      "y": 31,
      "z": 18,
      "name": "Rock_Sandstone_White"
    },
    {
      "x": 11,
      "y": 32,
      "z": 18,
      "name": "Rock_Sandstone_White"
    },
    {
      "x": 11,
      "y": 33,
      "z": 18,
      "name": "Rock_Sandstone_White"
    },
    {
      "x": 11,
      "y": 34,
      "z": 18,
      "name": "Rock_Sandstone_White"
    },
    {
      "x": 11,
      "y": 35,
      "z": 18,
      "name": "Rock_Sandstone"
    },
    {
      "x": 11,
      "y": 36,
      "z": 18,
      "name": "Rock_Sandstone_White"
    },
    {
      "x": 11,
      "y": 37,
      "z": 18,
      "name": "Rock_Sandstone_White"
    },
    {
      "x": 11,
      "y": 3,
      "z": 19,
      "name": "Rock_Sandstone_White"
    },
    {
      "x": 11,
      "y": 4,
      "z": 19,
      "name": "Rock_Sandstone_White"
    },
    {
      "x": 11,
      "y": 5,
      "z": 19,
      "name": "Rock_Sandstone"
    },
    {
      "x": 11,
      "y": 6,
      "z": 19,
      "name": "Rock_Sandstone"
    },
    {
      "x": 11,
      "y": 7,
      "z": 19,
      "name": "Rock_Sandstone_White"
    },
    {
      "x": 11,
      "y": 8,
      "z": 19,
      "name": "Rock_Sandstone_White"
    },
    {
      "x": 11,
      "y": 9,
      "z": 19,
      "name": "Rock_Sandstone_White"
    },
    {
      "x": 11,
      "y": 10,
      "z": 19,
      "name": "Rock_Sandstone_White"
    },
    {
      "x": 11,
      "y": 11,
      "z": 19,
      "name": "Rock_Sandstone_White"
    },
    {
      "x": 11,
      "y": 12,
      "z": 19,
      "name": "Rock_Sandstone_White"
    },
    {
      "x": 11,
      "y": 13,
      "z": 19,
      "name": "Rock_Sandstone_White"
    },
    {
      "x": 11,
      "y": 14,
      "z": 19,
      "name": "Rock_Sandstone_White"
    },
    {
      "x": 11,
      "y": 15,
      "z": 19,
      "name": "Rock_Sandstone_White"
    },
    {
      "x": 11,
      "y": 16,
      "z": 19,
      "name": "Rock_Sandstone_White"
    },
    {
      "x": 11,
      "y": 17,
      "z": 19,
      "name": "Rock_Sandstone_White"
    },
    {
      "x": 11,
      "y": 18,
      "z": 19,
      "name": "Rock_Sandstone_White"
    },
    {
      "x": 11,
      "y": 21,
      "z": 19,
      "name": "Rock_Sandstone_White"
    },
    {
      "x": 11,
      "y": 22,
      "z": 19,
      "name": "Rock_Sandstone_White"
    },
    {
      "x": 11,
      "y": 23,
      "z": 19,
      "name": "Rock_Sandstone_White"
    },
    {
      "x": 11,
      "y": 24,
      "z": 19,
      "name": "Rock_Sandstone_White"
    },
    {
      "x": 11,
      "y": 25,
      "z": 19,
      "name": "Rock_Sandstone_White"
    },
    {
      "x": 11,
      "y": 26,
      "z": 19,
      "name": "Soil_Dirt_Dry"
    },
    {
      "x": 11,
      "y": 27,
      "z": 19,
      "name": "Rock_Sandstone"
    },
    {
      "x": 11,
      "y": 28,
      "z": 19,
      "name": "Rock_Sandstone_White"
    },
    {
      "x": 11,
      "y": 29,
      "z": 19,
      "name": "Rock_Sandstone_White"
    },
    {
      "x": 11,
      "y": 33,
      "z": 19,
      "name": "Rock_Sandstone_White"
    },
    {
      "x": 11,
      "y": 34,
      "z": 19,
      "name": "Rock_Sandstone_White"
    },
    {
      "x": 11,
      "y": 35,
      "z": 19,
      "name": "Rock_Sandstone"
    },
    {
      "x": 11,
      "y": 36,
      "z": 19,
      "name": "Rock_Sandstone_White"
    },
    {
      "x": 11,
      "y": 37,
      "z": 19,
      "name": "Rock_Sandstone_White"
    },
    {
      "x": 11,
      "y": 3,
      "z": 20,
      "name": "Rock_Sandstone_White"
    },
    {
      "x": 11,
      "y": 4,
      "z": 20,
      "name": "Rock_Sandstone_White"
    },
    {
      "x": 11,
      "y": 5,
      "z": 20,
      "name": "Soil_Dirt_Dry"
    },
    {
      "x": 11,
      "y": 6,
      "z": 20,
      "name": "Rock_Sandstone"
    },
    {
      "x": 11,
      "y": 7,
      "z": 20,
      "name": "Rock_Sandstone_White"
    },
    {
      "x": 11,
      "y": 8,
      "z": 20,
      "name": "Rock_Sandstone_White"
    },
    {
      "x": 11,
      "y": 9,
      "z": 20,
      "name": "Rock_Sandstone_White"
    },
    {
      "x": 11,
      "y": 10,
      "z": 20,
      "name": "Rock_Sandstone_White"
    },
    {
      "x": 11,
      "y": 11,
      "z": 20,
      "name": "Rock_Sandstone_White"
    },
    {
      "x": 11,
      "y": 12,
      "z": 20,
      "name": "Rock_Sandstone_White"
    },
    {
      "x": 11,
      "y": 13,
      "z": 20,
      "name": "Rock_Sandstone_White"
    },
    {
      "x": 11,
      "y": 14,
      "z": 20,
      "name": "Rock_Sandstone_White"
    },
    {
      "x": 11,
      "y": 15,
      "z": 20,
      "name": "Rock_Sandstone_White"
    },
    {
      "x": 11,
      "y": 16,
      "z": 20,
      "name": "Rock_Sandstone_White"
    },
    {
      "x": 11,
      "y": 17,
      "z": 20,
      "name": "Rock_Sandstone"
    },
    {
      "x": 11,
      "y": 18,
      "z": 20,
      "name": "Rock_Sandstone_White"
    },
    {
      "x": 11,
      "y": 3,
      "z": 21,
      "name": "Rock_Sandstone_White"
    },
    {
      "x": 11,
      "y": 4,
      "z": 21,
      "name": "Soil_Dirt_Dry"
    },
    {
      "x": 11,
      "y": 5,
      "z": 21,
      "name": "Soil_Dirt_Dry"
    },
    {
      "x": 11,
      "y": 6,
      "z": 21,
      "name": "Rock_Sandstone"
    },
    {
      "x": 11,
      "y": 7,
      "z": 21,
      "name": "Rock_Sandstone_White"
    },
    {
      "x": 11,
      "y": 8,
      "z": 21,
      "name": "Rock_Sandstone_White"
    },
    {
      "x": 11,
      "y": 15,
      "z": 21,
      "name": "Rock_Sandstone_White"
    },
    {
      "x": 11,
      "y": 16,
      "z": 21,
      "name": "Rock_Sandstone_White"
    },
    {
      "x": 11,
      "y": 17,
      "z": 21,
      "name": "Rock_Sandstone_White"
    },
    {
      "x": 11,
      "y": 18,
      "z": 21,
      "name": "Rock_Sandstone"
    },
    {
      "x": 11,
      "y": 19,
      "z": 21,
      "name": "Rock_Sandstone_White"
    },
    {
      "x": 11,
      "y": 5,
      "z": 22,
      "name": "Soil_Dirt_Dry"
    },
    {
      "x": 11,
      "y": 6,
      "z": 22,
      "name": "Rock_Sandstone"
    },
    {
      "x": 11,
      "y": 15,
      "z": 22,
      "name": "Rock_Sandstone_White"
    },
    {
      "x": 11,
      "y": 16,
      "z": 22,
      "name": "Rock_Sandstone_White"
    },
    {
      "x": 11,
      "y": 17,
      "z": 22,
      "name": "Rock_Sandstone_White"
    },
    {
      "x": 11,
      "y": 18,
      "z": 22,
      "name": "Rock_Sandstone"
    },
    {
      "x": 11,
      "y": 19,
      "z": 22,
      "name": "Rock_Sandstone_White"
    },
    {
      "x": 11,
      "y": 20,
      "z": 22,
      "name": "Rock_Sandstone_White"
    },
    {
      "x": 11,
      "y": 21,
      "z": 22,
      "name": "Rock_Sandstone_White"
    },
    {
      "x": 11,
      "y": 22,
      "z": 22,
      "name": "Rock_Sandstone_White"
    },
    {
      "x": 11,
      "y": 23,
      "z": 22,
      "name": "Rock_Sandstone_White"
    },
    {
      "x": 11,
      "y": 24,
      "z": 22,
      "name": "Rock_Sandstone"
    },
    {
      "x": 11,
      "y": 15,
      "z": 23,
      "name": "Rock_Sandstone_White"
    },
    {
      "x": 11,
      "y": 16,
      "z": 23,
      "name": "Rock_Sandstone_White"
    },
    {
      "x": 11,
      "y": 17,
      "z": 23,
      "name": "Rock_Sandstone_White"
    },
    {
      "x": 11,
      "y": 18,
      "z": 23,
      "name": "Rock_Sandstone"
    },
    {
      "x": 11,
      "y": 19,
      "z": 23,
      "name": "Rock_Sandstone_White"
    },
    {
      "x": 11,
      "y": 20,
      "z": 23,
      "name": "Rock_Sandstone_White"
    },
    {
      "x": 11,
      "y": 21,
      "z": 23,
      "name": "Rock_Sandstone_White"
    },
    {
      "x": 11,
      "y": 22,
      "z": 23,
      "name": "Rock_Sandstone_White"
    },
    {
      "x": 11,
      "y": 23,
      "z": 23,
      "name": "Rock_Sandstone_White"
    },
    {
      "x": 11,
      "y": 24,
      "z": 23,
      "name": "Rock_Sandstone_White"
    },
    {
      "x": 11,
      "y": 25,
      "z": 23,
      "name": "Rock_Sandstone"
    },
    {
      "x": 11,
      "y": 26,
      "z": 23,
      "name": "Rock_Sandstone_White"
    },
    {
      "x": 11,
      "y": 15,
      "z": 24,
      "name": "Rock_Sandstone_White"
    },
    {
      "x": 11,
      "y": 16,
      "z": 24,
      "name": "Rock_Sandstone_White"
    },
    {
      "x": 11,
      "y": 17,
      "z": 24,
      "name": "Rock_Sandstone_White"
    },
    {
      "x": 11,
      "y": 18,
      "z": 24,
      "name": "Rock_Sandstone"
    },
    {
      "x": 11,
      "y": 19,
      "z": 24,
      "name": "Rock_Sandstone_White"
    },
    {
      "x": 11,
      "y": 20,
      "z": 24,
      "name": "Rock_Sandstone_White"
    },
    {
      "x": 11,
      "y": 21,
      "z": 24,
      "name": "Rock_Sandstone_White"
    },
    {
      "x": 11,
      "y": 22,
      "z": 24,
      "name": "Rock_Sandstone_White"
    },
    {
      "x": 11,
      "y": 23,
      "z": 24,
      "name": "Rock_Sandstone_White"
    },
    {
      "x": 11,
      "y": 24,
      "z": 24,
      "name": "Rock_Sandstone_White"
    },
    {
      "x": 11,
      "y": 25,
      "z": 24,
      "name": "Rock_Sandstone"
    },
    {
      "x": 11,
      "y": 26,
      "z": 24,
      "name": "Rock_Sandstone_White"
    },
    {
      "x": 11,
      "y": 15,
      "z": 25,
      "name": "Rock_Sandstone_White"
    },
    {
      "x": 11,
      "y": 16,
      "z": 25,
      "name": "Rock_Sandstone_White"
    },
    {
      "x": 11,
      "y": 17,
      "z": 25,
      "name": "Rock_Sandstone_White"
    },
    {
      "x": 11,
      "y": 18,
      "z": 25,
      "name": "Rock_Sandstone"
    },
    {
      "x": 11,
      "y": 19,
      "z": 25,
      "name": "Rock_Sandstone_White"
    },
    {
      "x": 11,
      "y": 20,
      "z": 25,
      "name": "Rock_Sandstone_White"
    },
    {
      "x": 11,
      "y": 21,
      "z": 25,
      "name": "Rock_Sandstone_White"
    },
    {
      "x": 11,
      "y": 22,
      "z": 25,
      "name": "Rock_Sandstone_White"
    },
    {
      "x": 11,
      "y": 23,
      "z": 25,
      "name": "Rock_Sandstone_White"
    },
    {
      "x": 11,
      "y": 24,
      "z": 25,
      "name": "Rock_Sandstone_White"
    },
    {
      "x": 11,
      "y": 25,
      "z": 25,
      "name": "Rock_Sandstone"
    },
    {
      "x": 11,
      "y": 26,
      "z": 25,
      "name": "Rock_Sandstone_White"
    },
    {
      "x": 11,
      "y": 16,
      "z": 26,
      "name": "Rock_Sandstone_White"
    },
    {
      "x": 11,
      "y": 17,
      "z": 26,
      "name": "Rock_Sandstone_White"
    },
    {
      "x": 11,
      "y": 18,
      "z": 26,
      "name": "Rock_Sandstone"
    },
    {
      "x": 11,
      "y": 19,
      "z": 26,
      "name": "Rock_Sandstone_White"
    },
    {
      "x": 11,
      "y": 20,
      "z": 26,
      "name": "Rock_Sandstone_White"
    },
    {
      "x": 11,
      "y": 21,
      "z": 26,
      "name": "Rock_Sandstone_White"
    },
    {
      "x": 11,
      "y": 22,
      "z": 26,
      "name": "Rock_Sandstone_White"
    },
    {
      "x": 11,
      "y": 23,
      "z": 26,
      "name": "Rock_Sandstone_White"
    },
    {
      "x": 11,
      "y": 24,
      "z": 26,
      "name": "Rock_Sandstone_White"
    },
    {
      "x": 11,
      "y": 25,
      "z": 26,
      "name": "Rock_Sandstone"
    },
    {
      "x": 11,
      "y": 26,
      "z": 26,
      "name": "Rock_Sandstone_White"
    },
    {
      "x": 11,
      "y": 16,
      "z": 27,
      "name": "Rock_Sandstone_White"
    },
    {
      "x": 11,
      "y": 17,
      "z": 27,
      "name": "Rock_Sandstone_White"
    },
    {
      "x": 11,
      "y": 18,
      "z": 27,
      "name": "Rock_Sandstone"
    },
    {
      "x": 11,
      "y": 19,
      "z": 27,
      "name": "Rock_Sandstone_White"
    },
    {
      "x": 12,
      "y": 14,
      "z": 6,
      "name": "Rock_Sandstone_White"
    },
    {
      "x": 12,
      "y": 15,
      "z": 6,
      "name": "Rock_Sandstone"
    },
    {
      "x": 12,
      "y": 16,
      "z": 6,
      "name": "Rock_Sandstone_White"
    },
    {
      "x": 12,
      "y": 14,
      "z": 7,
      "name": "Rock_Sandstone_White"
    },
    {
      "x": 12,
      "y": 15,
      "z": 7,
      "name": "Rock_Sandstone"
    },
    {
      "x": 12,
      "y": 16,
      "z": 7,
      "name": "Rock_Sandstone_White"
    },
    {
      "x": 12,
      "y": 14,
      "z": 8,
      "name": "Rock_Sandstone_White"
    },
    {
      "x": 12,
      "y": 15,
      "z": 8,
      "name": "Rock_Sandstone"
    },
    {
      "x": 12,
      "y": 16,
      "z": 8,
      "name": "Rock_Sandstone_White"
    },
    {
      "x": 12,
      "y": 17,
      "z": 8,
      "name": "Rock_Sandstone_White"
    },
    {
      "x": 12,
      "y": 18,
      "z": 8,
      "name": "Rock_Sandstone_White"
    },
    {
      "x": 12,
      "y": 19,
      "z": 8,
      "name": "Rock_Sandstone_White"
    },
    {
      "x": 12,
      "y": 20,
      "z": 8,
      "name": "Rock_Sandstone"
    },
    {
      "x": 12,
      "y": 21,
      "z": 8,
      "name": "Rock_Sandstone_White"
    },
    {
      "x": 12,
      "y": 22,
      "z": 8,
      "name": "Rock_Sandstone_White"
    },
    {
      "x": 12,
      "y": 14,
      "z": 9,
      "name": "Rock_Sandstone_White"
    },
    {
      "x": 12,
      "y": 15,
      "z": 9,
      "name": "Rock_Sandstone_White"
    },
    {
      "x": 12,
      "y": 16,
      "z": 9,
      "name": "Rock_Sandstone_White"
    },
    {
      "x": 12,
      "y": 17,
      "z": 9,
      "name": "Rock_Sandstone_White"
    },
    {
      "x": 12,
      "y": 18,
      "z": 9,
      "name": "Rock_Sandstone_White"
    },
    {
      "x": 12,
      "y": 19,
      "z": 9,
      "name": "Rock_Sandstone_White"
    },
    {
      "x": 12,
      "y": 20,
      "z": 9,
      "name": "Rock_Sandstone"
    },
    {
      "x": 12,
      "y": 21,
      "z": 9,
      "name": "Rock_Sandstone_White"
    },
    {
      "x": 12,
      "y": 22,
      "z": 9,
      "name": "Rock_Sandstone_White"
    },
    {
      "x": 12,
      "y": 14,
      "z": 10,
      "name": "Rock_Sandstone_White"
    },
    {
      "x": 12,
      "y": 15,
      "z": 10,
      "name": "Rock_Sandstone_White"
    },
    {
      "x": 12,
      "y": 16,
      "z": 10,
      "name": "Rock_Sandstone"
    },
    {
      "x": 12,
      "y": 17,
      "z": 10,
      "name": "Rock_Sandstone_White"
    },
    {
      "x": 12,
      "y": 18,
      "z": 10,
      "name": "Rock_Sandstone_White"
    },
    {
      "x": 12,
      "y": 19,
      "z": 10,
      "name": "Rock_Sandstone_White"
    },
    {
      "x": 12,
      "y": 20,
      "z": 10,
      "name": "Rock_Sandstone"
    },
    {
      "x": 12,
      "y": 21,
      "z": 10,
      "name": "Rock_Sandstone_White"
    },
    {
      "x": 12,
      "y": 22,
      "z": 10,
      "name": "Rock_Sandstone_White"
    },
    {
      "x": 12,
      "y": 14,
      "z": 11,
      "name": "Rock_Sandstone_White"
    },
    {
      "x": 12,
      "y": 15,
      "z": 11,
      "name": "Rock_Sandstone_White"
    },
    {
      "x": 12,
      "y": 16,
      "z": 11,
      "name": "Rock_Sandstone"
    },
    {
      "x": 12,
      "y": 17,
      "z": 11,
      "name": "Rock_Sandstone_White"
    },
    {
      "x": 12,
      "y": 18,
      "z": 11,
      "name": "Rock_Sandstone_White"
    },
    {
      "x": 12,
      "y": 19,
      "z": 11,
      "name": "Rock_Sandstone"
    },
    {
      "x": 12,
      "y": 20,
      "z": 11,
      "name": "Rock_Sandstone"
    },
    {
      "x": 12,
      "y": 21,
      "z": 11,
      "name": "Rock_Sandstone_White"
    },
    {
      "x": 12,
      "y": 22,
      "z": 11,
      "name": "Rock_Sandstone_White"
    },
    {
      "x": 12,
      "y": 14,
      "z": 12,
      "name": "Rock_Sandstone_White"
    },
    {
      "x": 12,
      "y": 15,
      "z": 12,
      "name": "Rock_Sandstone_White"
    },
    {
      "x": 12,
      "y": 16,
      "z": 12,
      "name": "Rock_Sandstone"
    },
    {
      "x": 12,
      "y": 17,
      "z": 12,
      "name": "Rock_Sandstone_White"
    },
    {
      "x": 12,
      "y": 19,
      "z": 12,
      "name": "Rock_Sandstone_White"
    },
    {
      "x": 12,
      "y": 20,
      "z": 12,
      "name": "Rock_Sandstone_White"
    },
    {
      "x": 12,
      "y": 21,
      "z": 12,
      "name": "Rock_Sandstone_White"
    },
    {
      "x": 12,
      "y": 14,
      "z": 13,
      "name": "Rock_Sandstone_White"
    },
    {
      "x": 12,
      "y": 15,
      "z": 13,
      "name": "Rock_Sandstone_White"
    },
    {
      "x": 12,
      "y": 16,
      "z": 13,
      "name": "Rock_Sandstone"
    },
    {
      "x": 12,
      "y": 17,
      "z": 13,
      "name": "Rock_Sandstone_White"
    },
    {
      "x": 12,
      "y": 18,
      "z": 13,
      "name": "Rock_Sandstone_White"
    },
    {
      "x": 12,
      "y": 4,
      "z": 14,
      "name": "Rock_Sandstone_White"
    },
    {
      "x": 12,
      "y": 5,
      "z": 14,
      "name": "Rock_Sandstone_White"
    },
    {
      "x": 12,
      "y": 6,
      "z": 14,
      "name": "Rock_Sandstone_White"
    },
    {
      "x": 12,
      "y": 7,
      "z": 14,
      "name": "Rock_Sandstone_White"
    },
    {
      "x": 12,
      "y": 8,
      "z": 14,
      "name": "Rock_Sandstone_White"
    },
    {
      "x": 12,
      "y": 9,
      "z": 14,
      "name": "Rock_Sandstone_White"
    },
    {
      "x": 12,
      "y": 10,
      "z": 14,
      "name": "Rock_Sandstone_White"
    },
    {
      "x": 12,
      "y": 11,
      "z": 14,
      "name": "Rock_Sandstone_White"
    },
    {
      "x": 12,
      "y": 12,
      "z": 14,
      "name": "Rock_Sandstone_White"
    },
    {
      "x": 12,
      "y": 13,
      "z": 14,
      "name": "Rock_Sandstone_White"
    },
    {
      "x": 12,
      "y": 14,
      "z": 14,
      "name": "Rock_Sandstone_White"
    },
    {
      "x": 12,
      "y": 15,
      "z": 14,
      "name": "Rock_Sandstone_White"
    },
    {
      "x": 12,
      "y": 16,
      "z": 14,
      "name": "Rock_Sandstone_White"
    },
    {
      "x": 12,
      "y": 17,
      "z": 14,
      "name": "Rock_Sandstone_White"
    },
    {
      "x": 12,
      "y": 18,
      "z": 14,
      "name": "Rock_Sandstone_White"
    },
    {
      "x": 12,
      "y": 20,
      "z": 14,
      "name": "Rock_Sandstone_White"
    },
    {
      "x": 12,
      "y": 21,
      "z": 14,
      "name": "Rock_Sandstone_White"
    },
    {
      "x": 12,
      "y": 22,
      "z": 14,
      "name": "Rock_Sandstone_White"
    },
    {
      "x": 12,
      "y": 23,
      "z": 14,
      "name": "Rock_Sandstone_White"
    },
    {
      "x": 12,
      "y": 24,
      "z": 14,
      "name": "Rock_Sandstone_White"
    },
    {
      "x": 12,
      "y": 25,
      "z": 14,
      "name": "Rock_Sandstone_White"
    },
    {
      "x": 12,
      "y": 26,
      "z": 14,
      "name": "Soil_Dirt_Dry"
    },
    {
      "x": 12,
      "y": 27,
      "z": 14,
      "name": "Rock_Sandstone"
    },
    {
      "x": 12,
      "y": 28,
      "z": 14,
      "name": "Rock_Sandstone_White"
    },
    {
      "x": 12,
      "y": 29,
      "z": 14,
      "name": "Rock_Sandstone_White"
    },
    {
      "x": 12,
      "y": 32,
      "z": 14,
      "name": "Rock_Sandstone_White"
    },
    {
      "x": 12,
      "y": 33,
      "z": 14,
      "name": "Rock_Sandstone_White"
    },
    {
      "x": 12,
      "y": 34,
      "z": 14,
      "name": "Rock_Sandstone_White"
    },
    {
      "x": 12,
      "y": 35,
      "z": 14,
      "name": "Rock_Sandstone"
    },
    {
      "x": 12,
      "y": 36,
      "z": 14,
      "name": "Rock_Sandstone_White"
    },
    {
      "x": 12,
      "y": 37,
      "z": 14,
      "name": "Rock_Sandstone_White"
    },
    {
      "x": 12,
      "y": 3,
      "z": 15,
      "name": "Rock_Sandstone_White"
    },
    {
      "x": 12,
      "y": 4,
      "z": 15,
      "name": "Rock_Sandstone_White"
    },
    {
      "x": 12,
      "y": 5,
      "z": 15,
      "name": "Rock_Sandstone_White"
    },
    {
      "x": 12,
      "y": 6,
      "z": 15,
      "name": "Soil_Dirt_Dry"
    },
    {
      "x": 12,
      "y": 7,
      "z": 15,
      "name": "Rock_Sandstone"
    },
    {
      "x": 12,
      "y": 8,
      "z": 15,
      "name": "Rock_Sandstone_White"
    },
    {
      "x": 12,
      "y": 9,
      "z": 15,
      "name": "Rock_Sandstone_White"
    },
    {
      "x": 12,
      "y": 10,
      "z": 15,
      "name": "Rock_Sandstone_White"
    },
    {
      "x": 12,
      "y": 11,
      "z": 15,
      "name": "Rock_Sandstone_White"
    },
    {
      "x": 12,
      "y": 12,
      "z": 15,
      "name": "Rock_Sandstone_White"
    },
    {
      "x": 12,
      "y": 13,
      "z": 15,
      "name": "Rock_Sandstone_White"
    },
    {
      "x": 12,
      "y": 14,
      "z": 15,
      "name": "Rock_Sandstone_White"
    },
    {
      "x": 12,
      "y": 15,
      "z": 15,
      "name": "Rock_Sandstone_White"
    },
    {
      "x": 12,
      "y": 16,
      "z": 15,
      "name": "Rock_Sandstone_White"
    },
    {
      "x": 12,
      "y": 17,
      "z": 15,
      "name": "Rock_Sandstone_White"
    },
    {
      "x": 12,
      "y": 18,
      "z": 15,
      "name": "Rock_Sandstone_White"
    },
    {
      "x": 12,
      "y": 19,
      "z": 15,
      "name": "Rock_Sandstone_White"
    },
    {
      "x": 12,
      "y": 20,
      "z": 15,
      "name": "Rock_Sandstone_White"
    },
    {
      "x": 12,
      "y": 21,
      "z": 15,
      "name": "Rock_Sandstone_White"
    },
    {
      "x": 12,
      "y": 22,
      "z": 15,
      "name": "Rock_Sandstone_White"
    },
    {
      "x": 12,
      "y": 23,
      "z": 15,
      "name": "Rock_Sandstone_White"
    },
    {
      "x": 12,
      "y": 24,
      "z": 15,
      "name": "Rock_Sandstone_White"
    },
    {
      "x": 12,
      "y": 25,
      "z": 15,
      "name": "Rock_Sandstone_White"
    },
    {
      "x": 12,
      "y": 26,
      "z": 15,
      "name": "Soil_Dirt_Dry"
    },
    {
      "x": 12,
      "y": 27,
      "z": 15,
      "name": "Rock_Sandstone"
    },
    {
      "x": 12,
      "y": 28,
      "z": 15,
      "name": "Rock_Sandstone_White"
    },
    {
      "x": 12,
      "y": 29,
      "z": 15,
      "name": "Rock_Sandstone_White"
    },
    {
      "x": 12,
      "y": 30,
      "z": 15,
      "name": "Rock_Sandstone_White"
    },
    {
      "x": 12,
      "y": 31,
      "z": 15,
      "name": "Rock_Sandstone_White"
    },
    {
      "x": 12,
      "y": 32,
      "z": 15,
      "name": "Rock_Sandstone_White"
    },
    {
      "x": 12,
      "y": 33,
      "z": 15,
      "name": "Rock_Sandstone_White"
    },
    {
      "x": 12,
      "y": 34,
      "z": 15,
      "name": "Rock_Sandstone_White"
    },
    {
      "x": 12,
      "y": 35,
      "z": 15,
      "name": "Rock_Sandstone"
    },
    {
      "x": 12,
      "y": 36,
      "z": 15,
      "name": "Rock_Sandstone_White"
    },
    {
      "x": 12,
      "y": 37,
      "z": 15,
      "name": "Rock_Sandstone_White"
    },
    {
      "x": 12,
      "y": 3,
      "z": 16,
      "name": "Rock_Sandstone_White"
    },
    {
      "x": 12,
      "y": 4,
      "z": 16,
      "name": "Rock_Sandstone_White"
    },
    {
      "x": 12,
      "y": 5,
      "z": 16,
      "name": "Rock_Sandstone_White"
    },
    {
      "x": 12,
      "y": 6,
      "z": 16,
      "name": "Soil_Dirt_Dry"
    },
    {
      "x": 12,
      "y": 7,
      "z": 16,
      "name": "Rock_Sandstone"
    },
    {
      "x": 12,
      "y": 8,
      "z": 16,
      "name": "Rock_Sandstone_White"
    },
    {
      "x": 12,
      "y": 9,
      "z": 16,
      "name": "Rock_Sandstone_White"
    },
    {
      "x": 12,
      "y": 10,
      "z": 16,
      "name": "Rock_Sandstone_White"
    },
    {
      "x": 12,
      "y": 11,
      "z": 16,
      "name": "Rock_Sandstone_White"
    },
    {
      "x": 12,
      "y": 12,
      "z": 16,
      "name": "Rock_Sandstone_White"
    },
    {
      "x": 12,
      "y": 13,
      "z": 16,
      "name": "Rock_Sandstone_White"
    },
    {
      "x": 12,
      "y": 14,
      "z": 16,
      "name": "Rock_Sandstone_White"
    },
    {
      "x": 12,
      "y": 15,
      "z": 16,
      "name": "Rock_Sandstone_White"
    },
    {
      "x": 12,
      "y": 16,
      "z": 16,
      "name": "Rock_Sandstone_White"
    },
    {
      "x": 12,
      "y": 17,
      "z": 16,
      "name": "Rock_Sandstone_White"
    },
    {
      "x": 12,
      "y": 18,
      "z": 16,
      "name": "Rock_Sandstone_White"
    },
    {
      "x": 12,
      "y": 19,
      "z": 16,
      "name": "Rock_Sandstone_White"
    },
    {
      "x": 12,
      "y": 20,
      "z": 16,
      "name": "Rock_Sandstone_White"
    },
    {
      "x": 12,
      "y": 21,
      "z": 16,
      "name": "Rock_Sandstone_White"
    },
    {
      "x": 12,
      "y": 22,
      "z": 16,
      "name": "Rock_Sandstone_White"
    },
    {
      "x": 12,
      "y": 23,
      "z": 16,
      "name": "Rock_Sandstone_White"
    },
    {
      "x": 12,
      "y": 24,
      "z": 16,
      "name": "Rock_Sandstone_White"
    },
    {
      "x": 12,
      "y": 25,
      "z": 16,
      "name": "Rock_Sandstone_White"
    },
    {
      "x": 12,
      "y": 26,
      "z": 16,
      "name": "Soil_Dirt_Dry"
    },
    {
      "x": 12,
      "y": 27,
      "z": 16,
      "name": "Rock_Sandstone"
    },
    {
      "x": 12,
      "y": 28,
      "z": 16,
      "name": "Rock_Sandstone_White"
    },
    {
      "x": 12,
      "y": 29,
      "z": 16,
      "name": "Rock_Sandstone_White"
    },
    {
      "x": 12,
      "y": 30,
      "z": 16,
      "name": "Rock_Sandstone_White"
    },
    {
      "x": 12,
      "y": 31,
      "z": 16,
      "name": "Rock_Sandstone_White"
    },
    {
      "x": 12,
      "y": 32,
      "z": 16,
      "name": "Rock_Sandstone_White"
    },
    {
      "x": 12,
      "y": 33,
      "z": 16,
      "name": "Rock_Sandstone_White"
    },
    {
      "x": 12,
      "y": 34,
      "z": 16,
      "name": "Rock_Sandstone_White"
    },
    {
      "x": 12,
      "y": 35,
      "z": 16,
      "name": "Rock_Sandstone"
    },
    {
      "x": 12,
      "y": 36,
      "z": 16,
      "name": "Rock_Sandstone_White"
    },
    {
      "x": 12,
      "y": 37,
      "z": 16,
      "name": "Rock_Sandstone_White"
    },
    {
      "x": 12,
      "y": 3,
      "z": 17,
      "name": "Rock_Sandstone_White"
    },
    {
      "x": 12,
      "y": 4,
      "z": 17,
      "name": "Rock_Sandstone_White"
    },
    {
      "x": 12,
      "y": 5,
      "z": 17,
      "name": "Rock_Sandstone_White"
    },
    {
      "x": 12,
      "y": 6,
      "z": 17,
      "name": "Soil_Dirt_Dry"
    },
    {
      "x": 12,
      "y": 7,
      "z": 17,
      "name": "Rock_Sandstone"
    },
    {
      "x": 12,
      "y": 8,
      "z": 17,
      "name": "Rock_Sandstone_White"
    },
    {
      "x": 12,
      "y": 9,
      "z": 17,
      "name": "Rock_Sandstone_White"
    },
    {
      "x": 12,
      "y": 10,
      "z": 17,
      "name": "Rock_Sandstone_White"
    },
    {
      "x": 12,
      "y": 11,
      "z": 17,
      "name": "Rock_Sandstone_White"
    },
    {
      "x": 12,
      "y": 12,
      "z": 17,
      "name": "Rock_Sandstone_White"
    },
    {
      "x": 12,
      "y": 13,
      "z": 17,
      "name": "Rock_Sandstone_White"
    },
    {
      "x": 12,
      "y": 14,
      "z": 17,
      "name": "Rock_Sandstone_White"
    },
    {
      "x": 12,
      "y": 15,
      "z": 17,
      "name": "Rock_Sandstone_White"
    },
    {
      "x": 12,
      "y": 16,
      "z": 17,
      "name": "Rock_Sandstone_White"
    },
    {
      "x": 12,
      "y": 17,
      "z": 17,
      "name": "Rock_Sandstone_White"
    },
    {
      "x": 12,
      "y": 18,
      "z": 17,
      "name": "Rock_Sandstone_White"
    },
    {
      "x": 12,
      "y": 19,
      "z": 17,
      "name": "Rock_Sandstone_White"
    },
    {
      "x": 12,
      "y": 20,
      "z": 17,
      "name": "Rock_Sandstone_White"
    },
    {
      "x": 12,
      "y": 21,
      "z": 17,
      "name": "Rock_Sandstone_White"
    },
    {
      "x": 12,
      "y": 22,
      "z": 17,
      "name": "Rock_Sandstone_White"
    },
    {
      "x": 12,
      "y": 23,
      "z": 17,
      "name": "Rock_Sandstone_White"
    },
    {
      "x": 12,
      "y": 24,
      "z": 17,
      "name": "Rock_Sandstone_White"
    },
    {
      "x": 12,
      "y": 25,
      "z": 17,
      "name": "Rock_Sandstone_White"
    },
    {
      "x": 12,
      "y": 26,
      "z": 17,
      "name": "Soil_Dirt_Dry"
    },
    {
      "x": 12,
      "y": 27,
      "z": 17,
      "name": "Rock_Sandstone_White"
    },
    {
      "x": 12,
      "y": 28,
      "z": 17,
      "name": "Rock_Sandstone_White"
    },
    {
      "x": 12,
      "y": 29,
      "z": 17,
      "name": "Rock_Sandstone_White"
    },
    {
      "x": 12,
      "y": 30,
      "z": 17,
      "name": "Rock_Sandstone_White"
    },
    {
      "x": 12,
      "y": 31,
      "z": 17,
      "name": "Rock_Sandstone_White"
    },
    {
      "x": 12,
      "y": 32,
      "z": 17,
      "name": "Rock_Sandstone_White"
    },
    {
      "x": 12,
      "y": 33,
      "z": 17,
      "name": "Rock_Sandstone_White"
    },
    {
      "x": 12,
      "y": 34,
      "z": 17,
      "name": "Rock_Sandstone_White"
    },
    {
      "x": 12,
      "y": 35,
      "z": 17,
      "name": "Rock_Sandstone"
    },
    {
      "x": 12,
      "y": 36,
      "z": 17,
      "name": "Rock_Sandstone_White"
    },
    {
      "x": 12,
      "y": 37,
      "z": 17,
      "name": "Rock_Sandstone_White"
    },
    {
      "x": 12,
      "y": 3,
      "z": 18,
      "name": "Rock_Sandstone_White"
    },
    {
      "x": 12,
      "y": 4,
      "z": 18,
      "name": "Rock_Sandstone_White"
    },
    {
      "x": 12,
      "y": 5,
      "z": 18,
      "name": "Rock_Sandstone_White"
    },
    {
      "x": 12,
      "y": 6,
      "z": 18,
      "name": "Rock_Sandstone"
    },
    {
      "x": 12,
      "y": 7,
      "z": 18,
      "name": "Rock_Sandstone"
    },
    {
      "x": 12,
      "y": 8,
      "z": 18,
      "name": "Rock_Sandstone_White"
    },
    {
      "x": 12,
      "y": 9,
      "z": 18,
      "name": "Rock_Sandstone_White"
    },
    {
      "x": 12,
      "y": 10,
      "z": 18,
      "name": "Rock_Sandstone_White"
    },
    {
      "x": 12,
      "y": 11,
      "z": 18,
      "name": "Rock_Sandstone_White"
    },
    {
      "x": 12,
      "y": 12,
      "z": 18,
      "name": "Rock_Sandstone_White"
    },
    {
      "x": 12,
      "y": 13,
      "z": 18,
      "name": "Rock_Sandstone_White"
    },
    {
      "x": 12,
      "y": 14,
      "z": 18,
      "name": "Rock_Sandstone_White"
    },
    {
      "x": 12,
      "y": 15,
      "z": 18,
      "name": "Rock_Sandstone_White"
    },
    {
      "x": 12,
      "y": 16,
      "z": 18,
      "name": "Rock_Sandstone_White"
    },
    {
      "x": 12,
      "y": 17,
      "z": 18,
      "name": "Rock_Sandstone_White"
    },
    {
      "x": 12,
      "y": 18,
      "z": 18,
      "name": "Rock_Sandstone_White"
    },
    {
      "x": 12,
      "y": 19,
      "z": 18,
      "name": "Rock_Sandstone_White"
    },
    {
      "x": 12,
      "y": 20,
      "z": 18,
      "name": "Rock_Sandstone_White"
    },
    {
      "x": 12,
      "y": 21,
      "z": 18,
      "name": "Rock_Sandstone_White"
    },
    {
      "x": 12,
      "y": 22,
      "z": 18,
      "name": "Rock_Sandstone_White"
    },
    {
      "x": 12,
      "y": 23,
      "z": 18,
      "name": "Rock_Sandstone_White"
    },
    {
      "x": 12,
      "y": 24,
      "z": 18,
      "name": "Rock_Sandstone_White"
    },
    {
      "x": 12,
      "y": 25,
      "z": 18,
      "name": "Rock_Sandstone_White"
    },
    {
      "x": 12,
      "y": 26,
      "z": 18,
      "name": "Soil_Dirt_Dry"
    },
    {
      "x": 12,
      "y": 27,
      "z": 18,
      "name": "Rock_Sandstone"
    },
    {
      "x": 12,
      "y": 28,
      "z": 18,
      "name": "Rock_Sandstone_White"
    },
    {
      "x": 12,
      "y": 29,
      "z": 18,
      "name": "Rock_Sandstone_White"
    },
    {
      "x": 12,
      "y": 30,
      "z": 18,
      "name": "Rock_Sandstone_White"
    },
    {
      "x": 12,
      "y": 31,
      "z": 18,
      "name": "Rock_Sandstone_White"
    },
    {
      "x": 12,
      "y": 32,
      "z": 18,
      "name": "Rock_Sandstone_White"
    },
    {
      "x": 12,
      "y": 33,
      "z": 18,
      "name": "Rock_Sandstone_White"
    },
    {
      "x": 12,
      "y": 34,
      "z": 18,
      "name": "Rock_Sandstone_White"
    },
    {
      "x": 12,
      "y": 35,
      "z": 18,
      "name": "Rock_Sandstone"
    },
    {
      "x": 12,
      "y": 36,
      "z": 18,
      "name": "Rock_Sandstone_White"
    },
    {
      "x": 12,
      "y": 37,
      "z": 18,
      "name": "Rock_Sandstone_White"
    },
    {
      "x": 12,
      "y": 3,
      "z": 19,
      "name": "Rock_Sandstone_White"
    },
    {
      "x": 12,
      "y": 4,
      "z": 19,
      "name": "Rock_Sandstone_White"
    },
    {
      "x": 12,
      "y": 5,
      "z": 19,
      "name": "Rock_Sandstone"
    },
    {
      "x": 12,
      "y": 6,
      "z": 19,
      "name": "Rock_Sandstone"
    },
    {
      "x": 12,
      "y": 7,
      "z": 19,
      "name": "Rock_Sandstone"
    },
    {
      "x": 12,
      "y": 8,
      "z": 19,
      "name": "Rock_Sandstone_White"
    },
    {
      "x": 12,
      "y": 9,
      "z": 19,
      "name": "Rock_Sandstone_White"
    },
    {
      "x": 12,
      "y": 10,
      "z": 19,
      "name": "Rock_Sandstone_White"
    },
    {
      "x": 12,
      "y": 11,
      "z": 19,
      "name": "Rock_Sandstone_White"
    },
    {
      "x": 12,
      "y": 12,
      "z": 19,
      "name": "Rock_Sandstone_White"
    },
    {
      "x": 12,
