{
  "version": 8,
  "blockIdVersion": 8,
  "anchorX": 12,
  "anchorY": 9,
  "anchorZ": 12,
  "blocks": [
    {
      "x": 5,
      "y": 17,
      "z": 7,
      "name": "Rock_Sandstone"
    },
    {
      "x": 5,
      "y": 18,
      "z": 7,
      "name": "Rock_Sandstone"
    },
    {
      "x": 5,
      "y": 16,
      "z": 8,
      "name": "Rock_Sandstone_White"
    },
    {
      "x": 5,
      "y": 17,
      "z": 8,
      "name": "Rock_Sandstone"
    },
    {
      "x": 5,
      "y": 18,
      "z": 8,
      "name": "Rock_Sandstone_White"
    },
    {
      "x": 5,
      "y": 16,
      "z": 9,
      "name": "Rock_Sandstone_White"
    },
    {
      "x": 5,
      "y": 17,
      "z": 9,
      "name": "Rock_Sandstone"
    },
    {
      "x": 5,
      "y": 18,
      "z": 9,
      "name": "Rock_Sandstone_White"
    },
    {
      "x": 5,
      "y": 16,
      "z": 10,
      "name": "Rock_Sandstone_White"
    },
    {
      "x": 5,
      "y": 17,
      "z": 10,
      "name": "Rock_Sandstone"
    },
    {
      "x": 5,
      "y": 18,
      "z": 10,
      "name": "Rock_Sandstone_White"
    },
    {
      "x": 5,
      "y": 15,
      "z": 11,
      "name": "Rock_Sandstone_White"
    },
    {
      "x": 5,
      "y": 16,
      "z": 11,
      "name": "Rock_Sandstone_White"
    },
    {
      "x": 5,
      "y": 17,
      "z": 11,
      "name": "Rock_Sandstone"
    },
    {
      "x": 5,
      "y": 18,
      "z": 11,
      "name": "Rock_Sandstone_White"
    },
    {
      "x": 5,
      "y": 15,
      "z": 12,
      "name": "Rock_Sandstone_White"
    },
    {
      "x": 5,
      "y": 16,
      "z": 12,
      "name": "Rock_Sandstone_White"
    },
    {
      "x": 5,
      "y": 17,
      "z": 12,
      "name": "Rock_Sandstone"
    },
    {
      "x": 5,
      "y": 18,
      "z": 12,
      "name": "Rock_Sandstone_White"
    },
    {
      "x": 5,
      "y": 15,
      "z": 13,
      "name": "Rock_Sandstone_White"
    },
    {
      "x": 5,
      "y": 16,
      "z": 13,
      "name": "Rock_Sandstone_White"
    },
    {
      "x": 5,
      "y": 17,
      "z": 13,
      "name": "Rock_Sandstone"
    },
    {
      "x": 5,
      "y": 18,
      "z": 13,
      "name": "Rock_Sandstone_White"
    },
    {
      "x": 5,
      "y": 15,
      "z": 14,
      "name": "Rock_Sandstone_White"
    },
    {
      "x": 5,
      "y": 16,
      "z": 14,
      "name": "Rock_Sandstone_White"
    },
    {
      "x": 5,
      "y": 17,
      "z": 14,
      "name": "Rock_Sandstone"
    },
    {
      "x": 5,
      "y": 18,
      "z": 14,
      "name": "Rock_Sandstone_White"
    },
    {
      "x": 5,
      "y": 15,
      "z": 15,
      "name": "Rock_Sandstone_White"
    },
    {
      "x": 5,
      "y": 16,
      "z": 15,
      "name": "Rock_Sandstone_White"
    },
    {
      "x": 5,
      "y": 17,
      "z": 15,
      "name": "Rock_Sandstone"
    },
    {
      "x": 5,
      "y": 16,
      "z": 16,
      "name": "Rock_Sandstone_White"
    },
    {
      "x": 5,
      "y": 17,
      "z": 16,
      "name": "Rock_Sandstone"
    },
    {
      "x": 6,
      "y": 16,
      "z": 6,
      "name": "Rock_Sandstone_White"
    },
    {
      "x": 6,
      "y": 17,
      "z": 6,
      "name": "Rock_Sandstone"
    },
    {
      "x": 6,
      "y": 18,
      "z": 6,
      "name": "Rock_Sandstone"
    },
    {
      "x": 6,
      "y": 19,
      "z": 6,
      "name": "Rock_Sandstone_White"
    },
    {
      "x": 6,
      "y": 15,
      "z": 7,
      "name": "Rock_Sandstone_White"
    },
    {
      "x": 6,
      "y": 16,
      "z": 7,
      "name": "Rock_Sandstone_White"
    },
    {
      "x": 6,
      "y": 17,
      "z": 7,
      "name": "Rock_Sandstone"
    },
    {
      "x": 6,
      "y": 18,
      "z": 7,
      "name": "Rock_Sandstone"
    },
    {
      "x": 6,
      "y": 19,
      "z": 7,
      "name": "Rock_Sandstone_White"
    },
    {
      "x": 6,
      "y": 15,
      "z": 8,
      "name": "Rock_Sandstone_White"
    },
    {
      "x": 6,
      "y": 16,
      "z": 8,
      "name": "Rock_Sandstone_White"
    },
    {
      "x": 6,
      "y": 17,
      "z": 8,
      "name": "Rock_Sandstone"
    },
    {
      "x": 6,
      "y": 18,
      "z": 8,
      "name": "Rock_Sandstone"
    },
    {
      "x": 6,
      "y": 19,
      "z": 8,
      "name": "Rock_Sandstone_White"
    },
    {
      "x": 6,
      "y": 15,
      "z": 9,
      "name": "Rock_Sandstone_White"
    },
    {
      "x": 6,
      "y": 16,
      "z": 9,
      "name": "Rock_Sandstone_White"
    },
    {
      "x": 6,
      "y": 17,
      "z": 9,
      "name": "Rock_Sandstone"
    },
    {
      "x": 6,
      "y": 18,
      "z": 9,
      "name": "Rock_Sandstone_White"
    },
    {
      "x": 6,
      "y": 19,
      "z": 9,
      "name": "Rock_Sandstone_White"
    },
    {
      "x": 6,
      "y": 15,
      "z": 10,
      "name": "Rock_Sandstone_White"
    },
    {
      "x": 6,
      "y": 16,
      "z": 10,
      "name": "Rock_Sandstone_White"
    },
    {
      "x": 6,
      "y": 17,
      "z": 10,
      "name": "Rock_Sandstone"
    },
    {
      "x": 6,
      "y": 18,
      "z": 10,
      "name": "Rock_Sandstone_White"
    },
    {
      "x": 6,
      "y": 15,
      "z": 11,
      "name": "Rock_Sandstone_White"
    },
    {
      "x": 6,
      "y": 16,
      "z": 11,
      "name": "Rock_Sandstone_White"
    },
    {
      "x": 6,
      "y": 17,
      "z": 11,
      "name": "Rock_Sandstone"
    },
    {
      "x": 6,
      "y": 18,
      "z": 11,
      "name": "Rock_Sandstone_White"
    },
    {
      "x": 6,
      "y": 15,
      "z": 12,
      "name": "Rock_Sandstone_White"
    },
    {
      "x": 6,
      "y": 16,
      "z": 12,
      "name": "Rock_Sandstone_White"
    },
    {
      "x": 6,
      "y": 17,
      "z": 12,
      "name": "Rock_Sandstone"
    },
    {
      "x": 6,
      "y": 18,
      "z": 12,
      "name": "Rock_Sandstone_White"
    },
    {
      "x": 6,
      "y": 15,
      "z": 13,
      "name": "Rock_Sandstone_White"
    },
    {
      "x": 6,
      "y": 16,
      "z": 13,
      "name": "Rock_Sandstone_White"
    },
    {
      "x": 6,
      "y": 17,
      "z": 13,
      "name": "Rock_Sandstone"
    },
    {
      "x": 6,
      "y": 18,
      "z": 13,
      "name": "Rock_Sandstone_White"
    },
    {
      "x": 6,
      "y": 15,
      "z": 14,
      "name": "Rock_Sandstone_White"
    },
    {
      "x": 6,
      "y": 16,
      "z": 14,
      "name": "Rock_Sandstone_White"
    },
    {
      "x": 6,
      "y": 17,
      "z": 14,
      "name": "Rock_Sandstone"
    },
    {
      "x": 6,
      "y": 18,
      "z": 14,
      "name": "Rock_Sandstone_White"
    },
    {
      "x": 6,
      "y": 15,
      "z": 15,
      "name": "Rock_Sandstone_White"
    },
    {
      "x": 6,
      "y": 16,
      "z": 15,
      "name": "Rock_Sandstone_White"
    },
    {
      "x": 6,
      "y": 17,
      "z": 15,
      "name": "Rock_Sandstone"
    },
    {
      "x": 6,
      "y": 18,
      "z": 15,
      "name": "Rock_Sandstone_White"
    },
    {
      "x": 6,
      "y": 15,
      "z": 16,
      "name": "Rock_Sandstone_White"
    },
    {
      "x": 6,
      "y": 16,
      "z": 16,
      "name": "Rock_Sandstone_White"
    },
    {
      "x": 6,
      "y": 17,
      "z": 16,
      "name": "Rock_Sandstone"
    },
    {
      "x": 6,
      "y": 15,
      "z": 17,
      "name": "Rock_Sandstone_White"
    },
    {
      "x": 6,
      "y": 16,
      "z": 17,
      "name": "Rock_Sandstone_White"
    },
    {
      "x": 6,
      "y": 17,
      "z": 17,
      "name": "Rock_Sandstone"
    },
    {
      "x": 7,
      "y": 15,
      "z": 6,
      "name": "Rock_Sandstone_White"
    },
    {
      "x": 7,
      "y": 16,
      "z": 6,
      "name": "Rock_Sandstone_White"
    },
    {
      "x": 7,
      "y": 17,
      "z": 6,
      "name": "Rock_Sandstone_White"
    },
    {
      "x": 7,
      "y": 18,
      "z": 6,
      "name": "Rock_Sandstone"
    },
    {
      "x": 7,
      "y": 19,
      "z": 6,
      "name": "Rock_Sandstone_White"
    },
    {
      "x": 7,
      "y": 15,
      "z": 7,
      "name": "Rock_Sandstone_White"
    },
    {
      "x": 7,
      "y": 16,
      "z": 7,
      "name": "Rock_Sandstone_White"
    },
    {
      "x": 7,
      "y": 17,
      "z": 7,
      "name": "Rock_Sandstone"
    },
    {
      "x": 7,
      "y": 18,
      "z": 7,
      "name": "Rock_Sandstone"
    },
    {
      "x": 7,
      "y": 19,
      "z": 7,
      "name": "Rock_Sandstone_White"
    },
    {
      "x": 7,
      "y": 15,
      "z": 8,
      "name": "Rock_Sandstone_White"
    },
    {
      "x": 7,
      "y": 16,
      "z": 8,
      "name": "Rock_Sandstone_White"
    },
    {
      "x": 7,
      "y": 17,
      "z": 8,
      "name": "Rock_Sandstone_White"
    },
    {
      "x": 7,
      "y": 18,
      "z": 8,
      "name": "Rock_Sandstone_White"
    },
    {
      "x": 7,
      "y": 19,
      "z": 8,
      "name": "Rock_Sandstone_White"
    },
    {
      "x": 7,
      "y": 15,
      "z": 9,
      "name": "Rock_Sandstone_White"
    },
    {
      "x": 7,
      "y": 16,
      "z": 9,
      "name": "Rock_Sandstone_White"
    },
    {
      "x": 7,
      "y": 17,
      "z": 9,
      "name": "Rock_Sandstone_White"
    },
    {
      "x": 7,
      "y": 18,
      "z": 9,
      "name": "Rock_Sandstone_White"
    },
    {
      "x": 7,
      "y": 19,
      "z": 9,
      "name": "Rock_Sandstone_White"
    },
    {
      "x": 7,
      "y": 26,
      "z": 9,
      "name": "Rock_Sandstone_White"
    },
    {
      "x": 7,
      "y": 27,
      "z": 9,
      "name": "Rock_Sandstone_White"
    },
    {
      "x": 7,
      "y": 15,
      "z": 10,
      "name": "Rock_Sandstone_White"
    },
    {
      "x": 7,
      "y": 16,
      "z": 10,
      "name": "Rock_Sandstone_White"
    },
    {
      "x": 7,
      "y": 17,
      "z": 10,
      "name": "Rock_Sandstone"
    },
    {
      "x": 7,
      "y": 18,
      "z": 10,
      "name": "Rock_Sandstone_White"
    },
    {
      "x": 7,
      "y": 19,
      "z": 10,
      "name": "Rock_Sandstone_White"
    },
    {
      "x": 7,
      "y": 25,
      "z": 10,
      "name": "Rock_Sandstone_White"
    },
    {
      "x": 7,
      "y": 26,
      "z": 10,
      "name": "Rock_Sandstone_White"
    },
    {
      "x": 7,
      "y": 27,
      "z": 10,
      "name": "Rock_Sandstone_White"
    },
    {
      "x": 7,
      "y": 28,
      "z": 10,
      "name": "Rock_Sandstone"
    },
    {
      "x": 7,
      "y": 15,
      "z": 11,
      "name": "Rock_Sandstone_White"
    },
    {
      "x": 7,
      "y": 16,
      "z": 11,
      "name": "Rock_Sandstone_White"
    },
    {
      "x": 7,
      "y": 17,
      "z": 11,
      "name": "Rock_Sandstone"
    },
    {
      "x": 7,
      "y": 18,
      "z": 11,
      "name": "Rock_Sandstone_White"
    },
    {
      "x": 7,
      "y": 19,
      "z": 11,
      "name": "Rock_Sandstone_White"
    },
    {
      "x": 7,
      "y": 25,
      "z": 11,
      "name": "Rock_Sandstone_White"
    },
    {
      "x": 7,
      "y": 26,
      "z": 11,
      "name": "Rock_Sandstone_White"
    },
    {
      "x": 7,
      "y": 27,
      "z": 11,
      "name": "Rock_Sandstone_White"
    },
    {
      "x": 7,
      "y": 28,
      "z": 11,
      "name": "Rock_Sandstone"
    },
    {
      "x": 7,
      "y": 15,
      "z": 12,
      "name": "Rock_Sandstone_White"
    },
    {
      "x": 7,
      "y": 16,
      "z": 12,
      "name": "Rock_Sandstone_White"
    },
    {
      "x": 7,
      "y": 17,
      "z": 12,
      "name": "Rock_Sandstone_White"
    },
    {
      "x": 7,
      "y": 18,
      "z": 12,
      "name": "Rock_Sandstone_White"
    },
    {
      "x": 7,
      "y": 19,
      "z": 12,
      "name": "Rock_Sandstone_White"
    },
    {
      "x": 7,
      "y": 25,
      "z": 12,
      "name": "Rock_Sandstone_White"
    },
    {
      "x": 7,
      "y": 26,
      "z": 12,
      "name": "Rock_Sandstone_White"
    },
    {
      "x": 7,
      "y": 27,
      "z": 12,
      "name": "Rock_Sandstone_White"
    },
    {
      "x": 7,
      "y": 28,
      "z": 12,
      "name": "Rock_Sandstone"
    },
    {
      "x": 7,
      "y": 15,
      "z": 13,
      "name": "Rock_Sandstone_White"
    },
    {
      "x": 7,
      "y": 16,
      "z": 13,
      "name": "Rock_Sandstone_White"
    },
    {
      "x": 7,
      "y": 17,
      "z": 13,
      "name": "Rock_Sandstone"
    },
    {
      "x": 7,
      "y": 18,
      "z": 13,
      "name": "Rock_Sandstone_White"
    },
    {
      "x": 7,
      "y": 19,
      "z": 13,
      "name": "Rock_Sandstone_White"
    },
    {
      "x": 7,
      "y": 27,
      "z": 13,
      "name": "Rock_Sandstone_White"
    },
    {
      "x": 7,
      "y": 28,
      "z": 13,
      "name": "Rock_Sandstone"
    },
    {
      "x": 7,
      "y": 15,
      "z": 14,
      "name": "Rock_Sandstone_White"
    },
    {
      "x": 7,
      "y": 16,
      "z": 14,
      "name": "Rock_Sandstone_White"
    },
    {
      "x": 7,
      "y": 17,
      "z": 14,
      "name": "Rock_Sandstone_White"
    },
    {
      "x": 7,
      "y": 18,
      "z": 14,
      "name": "Rock_Sandstone_White"
    },
    {
      "x": 7,
      "y": 15,
      "z": 15,
      "name": "Rock_Sandstone_White"
    },
    {
      "x": 7,
      "y": 16,
      "z": 15,
      "name": "Rock_Sandstone_White"
    },
    {
      "x": 7,
      "y": 17,
      "z": 15,
      "name": "Rock_Sandstone"
    },
    {
      "x": 7,
      "y": 18,
      "z": 15,
      "name": "Rock_Sandstone_White"
    },
    {
      "x": 7,
      "y": 15,
      "z": 16,
      "name": "Rock_Sandstone_White"
    },
    {
      "x": 7,
      "y": 16,
      "z": 16,
      "name": "Rock_Sandstone_White"
    },
    {
      "x": 7,
      "y": 17,
      "z": 16,
      "name": "Rock_Sandstone"
    },
    {
      "x": 7,
      "y": 18,
      "z": 16,
      "name": "Rock_Sandstone_White"
    },
    {
      "x": 7,
      "y": 15,
      "z": 17,
      "name": "Rock_Sandstone_White"
    },
    {
      "x": 7,
      "y": 16,
      "z": 17,
      "name": "Rock_Sandstone_White"
    },
    {
      "x": 7,
      "y": 17,
      "z": 17,
      "name": "Rock_Sandstone"
    },
    {
      "x": 7,
      "y": 18,
      "z": 17,
      "name": "Rock_Sandstone_White"
    },
    {
      "x": 8,
      "y": 15,
      "z": 6,
      "name": "Rock_Sandstone_White"
    },
    {
      "x": 8,
      "y": 16,
      "z": 6,
      "name": "Rock_Sandstone_White"
    },
    {
      "x": 8,
      "y": 17,
      "z": 6,
      "name": "Rock_Sandstone_White"
    },
    {
      "x": 8,
      "y": 18,
      "z": 6,
      "name": "Rock_Sandstone"
    },
    {
      "x": 8,
      "y": 19,
      "z": 6,
      "name": "Rock_Sandstone_White"
    },
    {
      "x": 8,
      "y": 20,
      "z": 6,
      "name": "Rock_Sandstone_White"
    },
    {
      "x": 8,
      "y": 15,
      "z": 7,
      "name": "Rock_Sandstone_White"
    },
    {
      "x": 8,
      "y": 16,
      "z": 7,
      "name": "Rock_Sandstone_White"
    },
    {
      "x": 8,
      "y": 17,
      "z": 7,
      "name": "Rock_Sandstone_White"
    },
    {
      "x": 8,
      "y": 18,
      "z": 7,
      "name": "Rock_Sandstone"
    },
    {
      "x": 8,
      "y": 19,
      "z": 7,
      "name": "Rock_Sandstone_White"
    },
    {
      "x": 8,
      "y": 20,
      "z": 7,
      "name": "Rock_Sandstone_White"
    },
    {
      "x": 8,
      "y": 15,
      "z": 8,
      "name": "Rock_Sandstone_White"
    },
    {
      "x": 8,
      "y": 16,
      "z": 8,
      "name": "Rock_Sandstone_White"
    },
    {
      "x": 8,
      "y": 17,
      "z": 8,
      "name": "Rock_Sandstone_White"
    },
    {
      "x": 8,
      "y": 18,
      "z": 8,
      "name": "Rock_Sandstone"
    },
    {
      "x": 8,
      "y": 19,
      "z": 8,
      "name": "Rock_Sandstone_White"
    },
    {
      "x": 8,
      "y": 20,
      "z": 8,
      "name": "Rock_Sandstone_White"
    },
    {
      "x": 8,
      "y": 15,
      "z": 9,
      "name": "Rock_Sandstone_White"
    },
    {
      "x": 8,
      "y": 16,
      "z": 9,
      "name": "Rock_Sandstone_White"
    },
    {
      "x": 8,
      "y": 17,
      "z": 9,
      "name": "Rock_Sandstone_White"
    },
    {
      "x": 8,
      "y": 18,
      "z": 9,
      "name": "Rock_Sandstone_White"
    },
    {
      "x": 8,
      "y": 19,
      "z": 9,
      "name": "Rock_Sandstone_White"
    },
    {
      "x": 8,
      "y": 25,
      "z": 9,
      "name": "Rock_Sandstone_White"
    },
    {
      "x": 8,
      "y": 26,
      "z": 9,
      "name": "Rock_Sandstone_White"
    },
    {
      "x": 8,
      "y": 27,
      "z": 9,
      "name": "Rock_Sandstone_White"
    },
    {
      "x": 8,
      "y": 28,
      "z": 9,
      "name": "Rock_Sandstone"
    },
    {
      "x": 8,
      "y": 15,
      "z": 10,
      "name": "Rock_Sandstone_White"
    },
    {
      "x": 8,
      "y": 16,
      "z": 10,
      "name": "Rock_Sandstone_White"
    },
    {
      "x": 8,
      "y": 17,
      "z": 10,
      "name": "Rock_Sandstone_White"
    },
    {
      "x": 8,
      "y": 18,
      "z": 10,
      "name": "Rock_Sandstone_White"
    },
    {
      "x": 8,
      "y": 19,
      "z": 10,
      "name": "Rock_Sandstone_White"
    },
    {
      "x": 8,
      "y": 25,
      "z": 10,
      "name": "Rock_Sandstone_White"
    },
    {
      "x": 8,
      "y": 26,
      "z": 10,
      "name": "Rock_Sandstone_White"
    },
    {
      "x": 8,
      "y": 27,
      "z": 10,
      "name": "Rock_Sandstone_White"
    },
    {
      "x": 8,
      "y": 28,
      "z": 10,
      "name": "Rock_Sandstone"
    },
    {
      "x": 8,
      "y": 15,
      "z": 11,
      "name": "Rock_Sandstone_White"
    },
    {
      "x": 8,
      "y": 16,
      "z": 11,
      "name": "Rock_Sandstone_White"
    },
    {
      "x": 8,
      "y": 17,
      "z": 11,
      "name": "Rock_Sandstone_White"
    },
    {
      "x": 8,
      "y": 18,
      "z": 11,
      "name": "Rock_Sandstone_White"
    },
    {
      "x": 8,
      "y": 19,
      "z": 11,
      "name": "Rock_Sandstone_White"
    },
    {
      "x": 8,
      "y": 25,
      "z": 11,
      "name": "Rock_Sandstone_White"
    },
    {
      "x": 8,
      "y": 26,
      "z": 11,
      "name": "Rock_Sandstone_White"
    },
    {
      "x": 8,
      "y": 27,
      "z": 11,
      "name": "Rock_Sandstone_White"
    },
    {
      "x": 8,
      "y": 28,
      "z": 11,
      "name": "Rock_Sandstone"
    },
    {
      "x": 8,
      "y": 15,
      "z": 12,
      "name": "Rock_Sandstone_White"
    },
    {
      "x": 8,
      "y": 16,
      "z": 12,
      "name": "Rock_Sandstone_White"
    },
    {
      "x": 8,
      "y": 17,
      "z": 12,
      "name": "Rock_Sandstone_White"
    },
    {
      "x": 8,
      "y": 18,
      "z": 12,
      "name": "Rock_Sandstone_White"
    },
    {
      "x": 8,
      "y": 19,
      "z": 12,
      "name": "Rock_Sandstone_White"
    },
    {
      "x": 8,
      "y": 25,
      "z": 12,
      "name": "Rock_Sandstone_White"
    },
    {
      "x": 8,
      "y": 26,
      "z": 12,
      "name": "Rock_Sandstone_White"
    },
    {
      "x": 8,
      "y": 27,
      "z": 12,
      "name": "Rock_Sandstone_White"
    },
    {
      "x": 8,
      "y": 28,
      "z": 12,
      "name": "Rock_Sandstone"
    },
    {
      "x": 8,
      "y": 15,
      "z": 13,
      "name": "Rock_Sandstone_White"
    },
    {
      "x": 8,
      "y": 16,
      "z": 13,
      "name": "Rock_Sandstone_White"
    },
    {
      "x": 8,
      "y": 17,
      "z": 13,
      "name": "Rock_Sandstone_White"
    },
    {
      "x": 8,
      "y": 18,
      "z": 13,
      "name": "Rock_Sandstone_White"
    },
    {
      "x": 8,
      "y": 19,
      "z": 13,
      "name": "Rock_Sandstone_White"
    },
    {
      "x": 8,
      "y": 25,
      "z": 13,
      "name": "Rock_Sandstone_White"
    },
    {
      "x": 8,
      "y": 26,
      "z": 13,
      "name": "Rock_Sandstone_White"
    },
    {
      "x": 8,
      "y": 27,
      "z": 13,
      "name": "Rock_Sandstone_White"
    },
    {
      "x": 8,
      "y": 28,
      "z": 13,
      "name": "Rock_Sandstone"
    },
    {
      "x": 8,
      "y": 15,
      "z": 14,
      "name": "Rock_Sandstone_White"
    },
    {
      "x": 8,
      "y": 16,
      "z": 14,
      "name": "Rock_Sandstone_White"
    },
    {
      "x": 8,
      "y": 17,
      "z": 14,
      "name": "Rock_Sandstone_White"
    },
    {
      "x": 8,
      "y": 18,
      "z": 14,
      "name": "Rock_Sandstone_White"
    },
    {
      "x": 8,
      "y": 19,
      "z": 14,
      "name": "Rock_Sandstone_White"
    },
    {
      "x": 8,
      "y": 15,
      "z": 15,
      "name": "Rock_Sandstone_White"
    },
    {
      "x": 8,
      "y": 16,
      "z": 15,
      "name": "Rock_Sandstone_White"
    },
    {
      "x": 8,
      "y": 17,
      "z": 15,
      "name": "Rock_Sandstone"
    },
    {
      "x": 8,
      "y": 18,
      "z": 15,
      "name": "Rock_Sandstone_White"
    },
    {
      "x": 8,
      "y": 19,
      "z": 15,
      "name": "Rock_Sandstone_White"
    },
    {
      "x": 8,
      "y": 15,
      "z": 16,
      "name": "Rock_Sandstone_White"
    },
    {
      "x": 8,
      "y": 16,
      "z": 16,
      "name": "Rock_Sandstone_White"
    },
    {
      "x": 8,
      "y": 17,
      "z": 16,
      "name": "Rock_Sandstone"
    },
    {
      "x": 8,
      "y": 18,
      "z": 16,
      "name": "Rock_Sandstone_White"
    },
    {
      "x": 8,
      "y": 15,
      "z": 17,
      "name": "Rock_Sandstone_White"
    },
    {
      "x": 8,
      "y": 16,
      "z": 17,
      "name": "Rock_Sandstone_White"
    },
    {
      "x": 8,
      "y": 17,
      "z": 17,
      "name": "Rock_Sandstone"
    },
    {
      "x": 8,
      "y": 18,
      "z": 17,
      "name": "Rock_Sandstone_White"
    },
    {
      "x": 9,
      "y": 16,
      "z": 5,
      "name": "Rock_Sandstone_White"
    },
    {
      "x": 9,
      "y": 17,
      "z": 5,
      "name": "Rock_Sandstone_White"
    },
    {
      "x": 9,
      "y": 18,
      "z": 5,
      "name": "Rock_Sandstone"
    },
    {
      "x": 9,
      "y": 19,
      "z": 5,
      "name": "Rock_Sandstone_White"
    },
    {
      "x": 9,
      "y": 15,
      "z": 6,
      "name": "Rock_Sandstone_White"
    },
    {
      "x": 9,
      "y": 16,
      "z": 6,
      "name": "Rock_Sandstone_White"
    },
    {
      "x": 9,
      "y": 17,
      "z": 6,
      "name": "Rock_Sandstone_White"
    },
    {
      "x": 9,
      "y": 18,
      "z": 6,
      "name": "Rock_Sandstone"
    },
    {
      "x": 9,
      "y": 19,
      "z": 6,
      "name": "Rock_Sandstone_White"
    },
    {
      "x": 9,
      "y": 20,
      "z": 6,
      "name": "Rock_Sandstone_White"
    },
    {
      "x": 9,
      "y": 15,
      "z": 7,
      "name": "Rock_Sandstone_White"
    },
    {
      "x": 9,
      "y": 16,
      "z": 7,
      "name": "Rock_Sandstone_White"
    },
    {
      "x": 9,
      "y": 17,
      "z": 7,
      "name": "Rock_Sandstone_White"
    },
    {
      "x": 9,
      "y": 18,
      "z": 7,
      "name": "Rock_Sandstone"
    },
    {
      "x": 9,
      "y": 19,
      "z": 7,
      "name": "Rock_Sandstone_White"
    },
    {
      "x": 9,
      "y": 20,
      "z": 7,
      "name": "Rock_Sandstone_White"
    },
    {
      "x": 9,
      "y": 15,
      "z": 8,
      "name": "Rock_Sandstone_White"
    },
    {
      "x": 9,
      "y": 16,
      "z": 8,
      "name": "Rock_Sandstone_White"
    },
    {
      "x": 9,
      "y": 17,
      "z": 8,
      "name": "Rock_Sandstone_White"
    },
    {
      "x": 9,
      "y": 18,
      "z": 8,
      "name": "Rock_Sandstone_White"
    },
    {
      "x": 9,
      "y": 19,
      "z": 8,
      "name": "Rock_Sandstone_White"
    },
    {
      "x": 9,
      "y": 20,
      "z": 8,
      "name": "Rock_Sandstone_White"
    },
    {
      "x": 9,
      "y": 15,
      "z": 9,
      "name": "Rock_Sandstone_White"
    },
    {
      "x": 9,
      "y": 16,
      "z": 9,
      "name": "Rock_Sandstone_White"
    },
    {
      "x": 9,
      "y": 17,
      "z": 9,
      "name": "Rock_Sandstone_White"
    },
    {
      "x": 9,
      "y": 18,
      "z": 9,
      "name": "Rock_Sandstone_White"
    },
    {
      "x": 9,
      "y": 19,
      "z": 9,
      "name": "Rock_Sandstone_White"
    },
    {
      "x": 9,
      "y": 20,
      "z": 9,
      "name": "Rock_Sandstone_White"
    },
    {
      "x": 9,
      "y": 25,
      "z": 9,
      "name": "Rock_Sandstone_White"
    },
    {
      "x": 9,
      "y": 26,
      "z": 9,
      "name": "Rock_Sandstone_White"
    },
    {
      "x": 9,
      "y": 27,
      "z": 9,
      "name": "Rock_Sandstone_White"
    },
    {
      "x": 9,
      "y": 28,
      "z": 9,
      "name": "Rock_Sandstone"
    },
    {
      "x": 9,
      "y": 15,
      "z": 10,
      "name": "Rock_Sandstone_White"
    },
    {
      "x": 9,
      "y": 16,
      "z": 10,
      "name": "Rock_Sandstone_White"
    },
    {
      "x": 9,
      "y": 17,
      "z": 10,
      "name": "Rock_Sandstone_White"
    },
    {
      "x": 9,
      "y": 18,
      "z": 10,
      "name": "Rock_Sandstone_White"
    },
    {
      "x": 9,
      "y": 19,
      "z": 10,
      "name": "Rock_Sandstone_White"
    },
    {
      "x": 9,
      "y": 20,
      "z": 10,
      "name": "Rock_Sandstone"
    },
    {
      "x": 9,
      "y": 21,
      "z": 10,
      "name": "Rock_Sandstone"
    },
    {
      "x": 9,
      "y": 22,
      "z": 10,
      "name": "Rock_Sandstone"
    },
    {
      "x": 9,
      "y": 23,
      "z": 10,
      "name": "Soil_Dirt_Dry"
    },
    {
      "x": 9,
      "y": 24,
      "z": 10,
      "name": "Soil_Dirt_Dry"
    },
    {
      "x": 9,
      "y": 25,
      "z": 10,
      "name": "Rock_Sandstone_White"
    },
    {
      "x": 9,
      "y": 26,
      "z": 10,
      "name": "Rock_Sandstone_White"
    },
    {
      "x": 9,
      "y": 27,
      "z": 10,
      "name": "Rock_Sandstone_White"
    },
    {
      "x": 9,
      "y": 28,
      "z": 10,
      "name": "Rock_Sandstone"
    },
    {
      "x": 9,
      "y": 4,
      "z": 11,
      "name": "Rock_Sandstone_White"
    },
    {
      "x": 9,
      "y": 5,
      "z": 11,
      "name": "Rock_Sandstone_White"
    },
    {
      "x": 9,
      "y": 6,
      "z": 11,
      "name": "Rock_Sandstone_White"
    },
    {
      "x": 9,
      "y": 7,
      "z": 11,
      "name": "Rock_Sandstone_White"
    },
    {
      "x": 9,
      "y": 8,
      "z": 11,
      "name": "Rock_Sandstone_White"
    },
    {
      "x": 9,
      "y": 9,
      "z": 11,
      "name": "Rock_Sandstone_White"
    },
    {
      "x": 9,
      "y": 15,
      "z": 11,
      "name": "Rock_Sandstone_White"
    },
    {
      "x": 9,
      "y": 16,
      "z": 11,
      "name": "Rock_Sandstone_White"
    },
    {
      "x": 9,
      "y": 17,
      "z": 11,
      "name": "Rock_Sandstone_White"
    },
    {
      "x": 9,
      "y": 18,
      "z": 11,
      "name": "Rock_Sandstone_White"
    },
    {
      "x": 9,
      "y": 19,
      "z": 11,
      "name": "Rock_Sandstone_White"
    },
    {
      "x": 9,
      "y": 20,
      "z": 11,
      "name": "Rock_Sandstone"
    },
    {
      "x": 9,
      "y": 21,
      "z": 11,
      "name": "Rock_Sandstone"
    },
    {
      "x": 9,
      "y": 22,
      "z": 11,
      "name": "Rock_Sandstone"
    },
    {
      "x": 9,
      "y": 23,
      "z": 11,
      "name": "Soil_Dirt_Dry"
    },
    {
      "x": 9,
      "y": 24,
      "z": 11,
      "name": "Soil_Dirt_Dry"
    },
    {
      "x": 9,
      "y": 25,
      "z": 11,
      "name": "Rock_Sandstone_White"
    },
    {
      "x": 9,
      "y": 26,
      "z": 11,
      "name": "Rock_Sandstone_White"
    },
    {
      "x": 9,
      "y": 27,
      "z": 11,
      "name": "Rock_Sandstone_White"
    },
    {
      "x": 9,
      "y": 28,
      "z": 11,
      "name": "Rock_Sandstone"
    },
    {
      "x": 9,
      "y": 4,
      "z": 12,
      "name": "Rock_Sandstone_White"
    },
    {
      "x": 9,
      "y": 5,
      "z": 12,
      "name": "Rock_Sandstone_White"
    },
    {
      "x": 9,
      "y": 6,
      "z": 12,
      "name": "Rock_Sandstone_White"
    },
    {
      "x": 9,
      "y": 7,
      "z": 12,
      "name": "Rock_Sandstone_White"
    },
    {
      "x": 9,
      "y": 8,
      "z": 12,
      "name": "Rock_Sandstone_White"
    },
    {
      "x": 9,
      "y": 9,
      "z": 12,
      "name": "Rock_Sandstone_White"
    },
    {
      "x": 9,
      "y": 10,
      "z": 12,
      "name": "Rock_Sandstone_White"
    },
    {
      "x": 9,
      "y": 15,
      "z": 12,
      "name": "Rock_Sandstone_White"
    },
    {
      "x": 9,
      "y": 16,
      "z": 12,
      "name": "Rock_Sandstone_White"
    },
    {
      "x": 9,
      "y": 17,
      "z": 12,
      "name": "Rock_Sandstone_White"
    },
    {
      "x": 9,
      "y": 18,
      "z": 12,
      "name": "Rock_Sandstone_White"
    },
    {
      "x": 9,
      "y": 19,
      "z": 12,
      "name": "Rock_Sandstone_White"
    },
    {
      "x": 9,
      "y": 20,
      "z": 12,
      "name": "Rock_Sandstone"
    },
    {
      "x": 9,
      "y": 21,
      "z": 12,
      "name": "Rock_Sandstone"
    },
    {
      "x": 9,
      "y": 22,
      "z": 12,
      "name": "Rock_Sandstone"
    },
    {
      "x": 9,
      "y": 23,
      "z": 12,
      "name": "Soil_Dirt_Dry"
    },
    {
      "x": 9,
      "y": 24,
      "z": 12,
      "name": "Soil_Dirt_Dry"
    },
    {
      "x": 9,
      "y": 25,
      "z": 12,
      "name": "Rock_Sandstone_White"
    },
    {
      "x": 9,
      "y": 26,
      "z": 12,
      "name": "Rock_Sandstone_White"
    },
    {
      "x": 9,
      "y": 27,
      "z": 12,
      "name": "Rock_Sandstone_White"
    },
    {
      "x": 9,
      "y": 28,
      "z": 12,
      "name": "Rock_Sandstone_White"
    },
    {
      "x": 9,
      "y": 4,
      "z": 13,
      "name": "Rock_Sandstone_White"
    },
    {
      "x": 9,
      "y": 5,
      "z": 13,
      "name": "Rock_Sandstone_White"
    },
    {
      "x": 9,
      "y": 6,
      "z": 13,
      "name": "Rock_Sandstone_White"
    },
    {
      "x": 9,
      "y": 7,
      "z": 13,
      "name": "Rock_Sandstone_White"
    },
    {
      "x": 9,
      "y": 8,
      "z": 13,
      "name": "Rock_Sandstone_White"
    },
    {
      "x": 9,
      "y": 9,
      "z": 13,
      "name": "Rock_Sandstone_White"
    },
    {
      "x": 9,
      "y": 10,
      "z": 13,
      "name": "Rock_Sandstone_White"
    },
    {
      "x": 9,
      "y": 15,
      "z": 13,
      "name": "Rock_Sandstone_White"
    },
    {
      "x": 9,
      "y": 16,
      "z": 13,
      "name": "Rock_Sandstone_White"
    },
    {
      "x": 9,
      "y": 17,
      "z": 13,
      "name": "Rock_Sandstone_White"
    },
    {
      "x": 9,
      "y": 18,
      "z": 13,
      "name": "Rock_Sandstone_White"
    },
    {
      "x": 9,
      "y": 19,
      "z": 13,
      "name": "Rock_Sandstone_White"
    },
    {
      "x": 9,
      "y": 21,
      "z": 13,
      "name": "Rock_Sandstone"
    },
    {
      "x": 9,
      "y": 22,
      "z": 13,
      "name": "Rock_Sandstone"
    },
    {
      "x": 9,
      "y": 23,
      "z": 13,
      "name": "Soil_Dirt_Dry"
    },
    {
      "x": 9,
      "y": 24,
      "z": 13,
      "name": "Soil_Dirt_Dry"
    },
    {
      "x": 9,
      "y": 25,
      "z": 13,
      "name": "Rock_Sandstone_White"
    },
    {
      "x": 9,
      "y": 26,
      "z": 13,
      "name": "Rock_Sandstone_White"
    },
    {
      "x": 9,
      "y": 27,
      "z": 13,
      "name": "Rock_Sandstone"
    },
    {
      "x": 9,
      "y": 28,
      "z": 13,
      "name": "Rock_Sandstone"
    },
    {
      "x": 9,
      "y": 4,
      "z": 14,
      "name": "Rock_Sandstone_White"
    },
    {
      "x": 9,
      "y": 5,
      "z": 14,
      "name": "Rock_Sandstone_White"
    },
    {
      "x": 9,
      "y": 6,
      "z": 14,
      "name": "Rock_Sandstone_White"
    },
    {
      "x": 9,
      "y": 7,
      "z": 14,
      "name": "Rock_Sandstone_White"
    },
    {
      "x": 9,
      "y": 8,
      "z": 14,
      "name": "Rock_Sandstone_White"
    },
    {
      "x": 9,
      "y": 9,
      "z": 14,
      "name": "Rock_Sandstone_White"
    },
    {
      "x": 9,
      "y": 10,
      "z": 14,
      "name": "Rock_Sandstone_White"
    },
    {
      "x": 9,
      "y": 15,
      "z": 14,
      "name": "Rock_Sandstone_White"
    },
    {
      "x": 9,
      "y": 16,
      "z": 14,
      "name": "Rock_Sandstone_White"
    },
    {
      "x": 9,
      "y": 17,
      "z": 14,
      "name": "Rock_Sandstone_White"
    },
    {
      "x": 9,
      "y": 18,
      "z": 14,
      "name": "Rock_Sandstone_White"
    },
    {
      "x": 9,
      "y": 19,
      "z": 14,
      "name": "Rock_Sandstone_White"
    },
    {
      "x": 9,
      "y": 25,
      "z": 14,
      "name": "Rock_Sandstone_White"
    },
    {
      "x": 9,
      "y": 26,
      "z": 14,
      "name": "Rock_Sandstone_White"
    },
    {
      "x": 9,
      "y": 27,
      "z": 14,
      "name": "Rock_Sandstone"
    },
    {
      "x": 9,
      "y": 28,
      "z": 14,
      "name": "Rock_Sandstone_White"
    },
    {
      "x": 9,
      "y": 5,
      "z": 15,
      "name": "Rock_Sandstone_White"
    },
    {
      "x": 9,
      "y": 6,
      "z": 15,
      "name": "Rock_Sandstone_White"
    },
    {
      "x": 9,
      "y": 7,
      "z": 15,
      "name": "Rock_Sandstone_White"
    },
    {
      "x": 9,
      "y": 8,
      "z": 15,
      "name": "Rock_Sandstone_White"
    },
    {
      "x": 9,
      "y": 15,
      "z": 15,
      "name": "Rock_Sandstone_White"
    },
    {
      "x": 9,
      "y": 16,
      "z": 15,
      "name": "Rock_Sandstone_White"
    },
    {
      "x": 9,
      "y": 17,
      "z": 15,
      "name": "Rock_Sandstone"
    },
    {
      "x": 9,
      "y": 18,
      "z": 15,
      "name": "Rock_Sandstone_White"
    },
    {
      "x": 9,
      "y": 19,
      "z": 15,
      "name": "Rock_Sandstone_White"
    },
    {
      "x": 9,
      "y": 27,
      "z": 15,
      "name": "Rock_Sandstone"
    },
    {
      "x": 9,
      "y": 28,
      "z": 15,
      "name": "Rock_Sandstone_White"
    },
    {
      "x": 9,
      "y": 15,
      "z": 16,
      "name": "Rock_Sandstone_White"
    },
    {
      "x": 9,
      "y": 16,
      "z": 16,
      "name": "Rock_Sandstone_White"
    },
    {
      "x": 9,
      "y": 17,
      "z": 16,
      "name": "Rock_Sandstone"
    },
    {
      "x": 9,
      "y": 18,
      "z": 16,
      "name": "Rock_Sandstone_White"
    },
    {
      "x": 9,
      "y": 15,
      "z": 17,
      "name": "Rock_Sandstone_White"
    },
    {
      "x": 9,
      "y": 16,
      "z": 17,
      "name": "Rock_Sandstone_White"
    },
    {
      "x": 9,
      "y": 17,
      "z": 17,
      "name": "Rock_Sandstone"
    },
    {
      "x": 9,
      "y": 18,
      "z": 17,
      "name": "Rock_Sandstone_White"
    },
    {
      "x": 10,
      "y": 16,
      "z": 5,
      "name": "Rock_Sandstone_White"
    },
    {
      "x": 10,
      "y": 17,
      "z": 5,
      "name": "Rock_Sandstone_White"
    },
    {
      "x": 10,
      "y": 18,
      "z": 5,
      "name": "Rock_Sandstone"
    },
    {
      "x": 10,
      "y": 19,
      "z": 5,
      "name": "Rock_Sandstone_White"
    },
    {
      "x": 10,
      "y": 15,
      "z": 6,
      "name": "Rock_Sandstone_White"
    },
    {
      "x": 10,
      "y": 16,
      "z": 6,
      "name": "Rock_Sandstone_White"
    },
    {
      "x": 10,
      "y": 17,
      "z": 6,
      "name": "Rock_Sandstone_White"
    },
    {
      "x": 10,
      "y": 18,
      "z": 6,
      "name": "Rock_Sandstone"
    },
    {
      "x": 10,
      "y": 19,
      "z": 6,
      "name": "Rock_Sandstone_White"
    },
    {
      "x": 10,
      "y": 20,
      "z": 6,
      "name": "Rock_Sandstone_White"
    },
    {
      "x": 10,
      "y": 15,
      "z": 7,
      "name": "Rock_Sandstone_White"
    },
    {
      "x": 10,
      "y": 16,
      "z": 7,
      "name": "Rock_Sandstone_White"
    },
    {
      "x": 10,
      "y": 17,
      "z": 7,
      "name": "Rock_Sandstone_White"
    },
    {
      "x": 10,
      "y": 18,
      "z": 7,
      "name": "Rock_Sandstone_White"
    },
    {
      "x": 10,
      "y": 19,
      "z": 7,
      "name": "Rock_Sandstone_White"
    },
    {
      "x": 10,
      "y": 20,
      "z": 7,
      "name": "Rock_Sandstone_White"
    },
    {
      "x": 10,
      "y": 15,
      "z": 8,
      "name": "Rock_Sandstone_White"
    },
    {
      "x": 10,
      "y": 16,
      "z": 8,
      "name": "Rock_Sandstone_White"
    },
    {
      "x": 10,
      "y": 17,
      "z": 8,
      "name": "Rock_Sandstone_White"
    },
    {
      "x": 10,
      "y": 18,
      "z": 8,
      "name": "Rock_Sandstone_White"
    },
    {
      "x": 10,
      "y": 19,
      "z": 8,
      "name": "Rock_Sandstone_White"
    },
    {
      "x": 10,
      "y": 20,
      "z": 8,
      "name": "Rock_Sandstone_White"
    },
    {
      "x": 10,
      "y": 6,
      "z": 9,
      "name": "Rock_Sandstone_White"
    },
    {
      "x": 10,
      "y": 7,
      "z": 9,
      "name": "Rock_Sandstone_White"
    },
    {
      "x": 10,
      "y": 8,
      "z": 9,
      "name": "Rock_Sandstone_White"
    },
    {
      "x": 10,
      "y": 9,
      "z": 9,
      "name": "Rock_Sandstone_White"
    },
    {
      "x": 10,
      "y": 10,
      "z": 9,
      "name": "Rock_Sandstone_White"
    },
    {
      "x": 10,
      "y": 15,
      "z": 9,
      "name": "Rock_Sandstone_White"
    },
    {
      "x": 10,
      "y": 16,
      "z": 9,
      "name": "Rock_Sandstone_White"
    },
    {
      "x": 10,
      "y": 17,
      "z": 9,
      "name": "Rock_Sandstone_White"
    },
    {
      "x": 10,
      "y": 18,
      "z": 9,
      "name": "Rock_Sandstone_White"
    },
    {
      "x": 10,
      "y": 19,
      "z": 9,
      "name": "Rock_Sandstone_White"
    },
    {
      "x": 10,
      "y": 20,
      "z": 9,
      "name": "Rock_Sandstone"
    },
    {
      "x": 10,
      "y": 21,
      "z": 9,
      "name": "Rock_Sandstone"
    },
    {
      "x": 10,
      "y": 22,
      "z": 9,
      "name": "Rock_Sandstone"
    },
    {
      "x": 10,
      "y": 23,
      "z": 9,
      "name": "Rock_Sandstone"
    },
    {
      "x": 10,
      "y": 26,
      "z": 9,
      "name": "Rock_Sandstone_White"
    },
    {
      "x": 10,
      "y": 27,
      "z": 9,
      "name": "Rock_Sandstone_White"
    },
    {
      "x": 10,
      "y": 28,
      "z": 9,
      "name": "Rock_Sandstone"
    },
    {
      "x": 10,
      "y": 5,
      "z": 10,
      "name": "Rock_Sandstone_White"
    },
    {
      "x": 10,
      "y": 6,
      "z": 10,
      "name": "Rock_Sandstone_White"
    },
    {
      "x": 10,
      "y": 7,
      "z": 10,
      "name": "Rock_Sandstone_White"
    },
    {
      "x": 10,
      "y": 8,
      "z": 10,
      "name": "Rock_Sandstone_White"
    },
    {
      "x": 10,
      "y": 9,
      "z": 10,
      "name": "Rock_Sandstone_White"
    },
    {
      "x": 10,
      "y": 10,
      "z": 10,
      "name": "Rock_Sandstone_White"
    },
    {
      "x": 10,
      "y": 11,
      "z": 10,
      "name": "Rock_Sandstone"
    },
    {
      "x": 10,
      "y": 12,
      "z": 10,
      "name": "Rock_Sandstone_White"
    },
    {
      "x": 10,
      "y": 13,
      "z": 10,
      "name": "Rock_Sandstone_White"
    },
    {
      "x": 10,
      "y": 14,
      "z": 10,
      "name": "Rock_Sandstone_White"
    },
    {
      "x": 10,
      "y": 15,
      "z": 10,
      "name": "Rock_Sandstone_White"
    },
    {
      "x": 10,
      "y": 16,
      "z": 10,
      "name": "Rock_Sandstone_White"
    },
    {
      "x": 10,
      "y": 17,
      "z": 10,
      "name": "Rock_Sandstone_White"
    },
    {
      "x": 10,
      "y": 18,
      "z": 10,
      "name": "Rock_Sandstone_White"
    },
    {
      "x": 10,
      "y": 19,
      "z": 10,
      "name": "Rock_Sandstone_White"
    },
    {
      "x": 10,
      "y": 20,
      "z": 10,
      "name": "Rock_Sandstone"
    },
    {
      "x": 10,
      "y": 21,
      "z": 10,
      "name": "Rock_Sandstone"
    },
    {
      "x": 10,
      "y": 22,
      "z": 10,
      "name": "Rock_Sandstone"
    },
    {
      "x": 10,
      "y": 23,
      "z": 10,
      "name": "Soil_Dirt_Dry"
    },
    {
      "x": 10,
      "y": 24,
      "z": 10,
      "name": "Soil_Dirt_Dry"
    },
    {
      "x": 10,
      "y": 25,
      "z": 10,
      "name": "Rock_Sandstone"
    },
    {
      "x": 10,
      "y": 26,
      "z": 10,
      "name": "Rock_Sandstone_White"
    },
    {
      "x": 10,
      "y": 27,
      "z": 10,
      "name": "Rock_Sandstone_White"
    },
    {
      "x": 10,
      "y": 28,
      "z": 10,
      "name": "Rock_Sandstone"
    },
    {
      "x": 10,
      "y": 3,
      "z": 11,
      "name": "Rock_Sandstone_White"
    },
    {
      "x": 10,
      "y": 4,
      "z": 11,
      "name": "Rock_Sandstone_White"
    },
    {
      "x": 10,
      "y": 5,
      "z": 11,
      "name": "Rock_Sandstone_White"
    },
    {
      "x": 10,
      "y": 6,
      "z": 11,
      "name": "Rock_Sandstone_White"
    },
    {
      "x": 10,
      "y": 7,
      "z": 11,
      "name": "Rock_Sandstone_White"
    },
    {
      "x": 10,
      "y": 8,
      "z": 11,
      "name": "Rock_Sandstone_White"
    },
    {
      "x": 10,
      "y": 9,
      "z": 11,
      "name": "Rock_Sandstone_White"
    },
    {
      "x": 10,
      "y": 10,
      "z": 11,
      "name": "Rock_Sandstone_White"
    },
    {
      "x": 10,
      "y": 11,
      "z": 11,
      "name": "Rock_Sandstone"
    },
    {
      "x": 10,
      "y": 12,
      "z": 11,
      "name": "Rock_Sandstone_White"
    },
    {
      "x": 10,
      "y": 13,
      "z": 11,
      "name": "Rock_Sandstone_White"
    },
    {
      "x": 10,
      "y": 14,
      "z": 11,
      "name": "Rock_Sandstone_White"
    },
    {
      "x": 10,
      "y": 15,
      "z": 11,
      "name": "Rock_Sandstone_White"
    },
    {
      "x": 10,
      "y": 16,
      "z": 11,
      "name": "Rock_Sandstone_White"
    },
    {
      "x": 10,
      "y": 17,
      "z": 11,
      "name": "Rock_Sandstone_White"
    },
    {
      "x": 10,
      "y": 18,
      "z": 11,
      "name": "Rock_Sandstone_White"
    },
    {
      "x": 10,
      "y": 19,
      "z": 11,
      "name": "Rock_Sandstone_White"
    },
    {
      "x": 10,
      "y": 20,
      "z": 11,
      "name": "Rock_Sandstone"
    },
    {
      "x": 10,
      "y": 21,
      "z": 11,
      "name": "Rock_Sandstone"
    },
    {
      "x": 10,
      "y": 22,
      "z": 11,
      "name": "Rock_Sandstone"
    },
    {
      "x": 10,
      "y": 23,
      "z": 11,
      "name": "Soil_Dirt_Dry"
    },
    {
      "x": 10,
      "y": 24,
      "z": 11,
      "name": "Soil_Dirt_Dry"
    },
    {
      "x": 10,
      "y": 25,
      "z": 11,
      "name": "Rock_Sandstone_White"
    },
    {
      "x": 10,
      "y": 26,
      "z": 11,
      "name": "Rock_Sandstone_White"
    },
    {
      "x": 10,
      "y": 27,
      "z": 11,
      "name": "Rock_Sandstone_White"
    },
    {
      "x": 10,
      "y": 28,
      "z": 11,
      "name": "Rock_Sandstone"
    },
    {
      "x": 10,
      "y": 3,
      "z": 12,
      "name": "Rock_Sandstone_White"
    },
    {
      "x": 10,
      "y": 4,
      "z": 12,
      "name": "Rock_Sandstone_White"
    },
    {
      "x": 10,
      "y": 5,
      "z": 12,
      "name": "Rock_Sandstone_White"
    },
    {
      "x": 10,
      "y": 6,
      "z": 12,
      "name": "Rock_Sandstone_White"
    },
    {
      "x": 10,
      "y": 7,
      "z": 12,
      "name": "Rock_Sandstone_White"
    },
    {
      "x": 10,
      "y": 8,
      "z": 12,
      "name": "Rock_Sandstone_White"
    },
    {
      "x": 10,
      "y": 9,
      "z": 12,
      "name": "Rock_Sandstone_White"
    },
    {
      "x": 10,
      "y": 10,
      "z": 12,
      "name": "Rock_Sandstone_White"
    },
    {
      "x": 10,
      "y": 11,
      "z": 12,
      "name": "Rock_Sandstone"
    },
    {
      "x": 10,
      "y": 12,
      "z": 12,
      "name": "Rock_Sandstone_White"
    },
    {
      "x": 10,
      "y": 13,
      "z": 12,
      "name": "Rock_Sandstone_White"
    },
    {
      "x": 10,
      "y": 14,
      "z": 12,
      "name": "Rock_Sandstone_White"
    },
    {
      "x": 10,
      "y": 15,
      "z": 12,
      "name": "Rock_Sandstone_White"
    },
    {
      "x": 10,
      "y": 16,
      "z": 12,
      "name": "Rock_Sandstone_White"
    },
    {
      "x": 10,
      "y": 17,
      "z": 12,
      "name": "Rock_Sandstone_White"
    },
    {
      "x": 10,
      "y": 18,
      "z": 12,
      "name": "Rock_Sandstone_White"
    },
    {
      "x": 10,
      "y": 19,
      "z": 12,
      "name": "Rock_Sandstone"
    },
    {
      "x": 10,
      "y": 20,
      "z": 12,
      "name": "Rock_Sandstone"
    },
    {
      "x": 10,
      "y": 21,
      "z": 12,
      "name": "Rock_Sandstone"
    },
    {
      "x": 10,
      "y": 22,
      "z": 12,
      "name": "Rock_Sandstone"
    },
    {
      "x": 10,
      "y": 23,
      "z": 12,
      "name": "Soil_Dirt_Dry"
    },
    {
      "x": 10,
      "y": 24,
      "z": 12,
      "name": "Rock_Sandstone_White"
    },
    {
      "x": 10,
      "y": 25,
      "z": 12,
      "name": "Rock_Sandstone_White"
    },
    {
      "x": 10,
      "y": 26,
      "z": 12,
      "name": "Rock_Sandstone_White"
    },
    {
      "x": 10,
      "y": 27,
      "z": 12,
      "name": "Rock_Sandstone_White"
    },
    {
      "x": 10,
      "y": 28,
      "z": 12,
      "name": "Rock_Sandstone_White"
    },
    {
      "x": 10,
      "y": 3,
      "z": 13,
      "name": "Rock_Sandstone_White"
    },
    {
      "x": 10,
      "y": 4,
      "z": 13,
      "name": "Rock_Sandstone_White"
    },
    {
      "x": 10,
      "y": 5,
      "z": 13,
      "name": "Rock_Sandstone_White"
    },
    {
      "x": 10,
      "y": 6,
      "z": 13,
      "name": "Rock_Sandstone_White"
    },
    {
      "x": 10,
      "y": 7,
      "z": 13,
      "name": "Rock_Sandstone_White"
    },
    {
      "x": 10,
      "y": 8,
      "z": 13,
      "name": "Rock_Sandstone_White"
    },
    {
      "x": 10,
      "y": 9,
      "z": 13,
      "name": "Rock_Sandstone_White"
    },
    {
      "x": 10,
      "y": 10,
      "z": 13,
      "name": "Rock_Sandstone_White"
    },
    {
      "x": 10,
      "y": 11,
      "z": 13,
      "name": "Rock_Sandstone"
    },
    {
      "x": 10,
      "y": 12,
      "z": 13,
      "name": "Rock_Sandstone_White"
    },
    {
      "x": 10,
      "y": 13,
      "z": 13,
      "name": "Rock_Sandstone_White"
    },
    {
      "x": 10,
      "y": 14,
      "z": 13,
      "name": "Rock_Sandstone_White"
    },
    {
      "x": 10,
      "y": 15,
      "z": 13,
      "name": "Rock_Sandstone_White"
    },
    {
      "x": 10,
      "y": 16,
      "z": 13,
      "name": "Rock_Sandstone_White"
    },
    {
      "x": 10,
      "y": 17,
      "z": 13,
      "name": "Rock_Sandstone_White"
    },
    {
      "x": 10,
      "y": 18,
      "z": 13,
      "name": "Rock_Sandstone_White"
    },
    {
      "x": 10,
      "y": 19,
      "z": 13,
      "name": "Rock_Sandstone_White"
    },
    {
      "x": 10,
      "y": 20,
      "z": 13,
      "name": "Rock_Sandstone"
    },
    {
      "x": 10,
      "y": 21,
      "z": 13,
      "name": "Rock_Sandstone"
    },
    {
      "x": 10,
      "y": 22,
      "z": 13,
      "name": "Rock_Sandstone"
    },
    {
      "x": 10,
      "y": 23,
      "z": 13,
      "name": "Rock_Sandstone"
    },
    {
      "x": 10,
      "y": 24,
      "z": 13,
      "name": "Soil_Dirt_Dry"
    },
    {
      "x": 10,
      "y": 25,
      "z": 13,
      "name": "Rock_Sandstone_White"
    },
    {
      "x": 10,
      "y": 26,
      "z": 13,
      "name": "Rock_Sandstone_White"
    },
    {
      "x": 10,
      "y": 27,
      "z": 13,
      "name": "Rock_Sandstone"
    },
    {
      "x": 10,
      "y": 28,
      "z": 13,
      "name": "Rock_Sandstone_White"
    },
    {
      "x": 10,
      "y": 3,
      "z": 14,
      "name": "Rock_Sandstone_White"
    },
    {
      "x": 10,
      "y": 4,
      "z": 14,
      "name": "Rock_Sandstone_White"
    },
    {
      "x": 10,
      "y": 5,
      "z": 14,
      "name": "Rock_Sandstone_White"
    },
    {
      "x": 10,
      "y": 6,
      "z": 14,
      "name": "Rock_Sandstone_White"
    },
    {
      "x": 10,
      "y": 7,
      "z": 14,
      "name": "Rock_Sandstone_White"
    },
    {
      "x": 10,
      "y": 8,
      "z": 14,
      "name": "Rock_Sandstone_White"
    },
    {
      "x": 10,
      "y": 9,
      "z": 14,
      "name": "Rock_Sandstone_White"
    },
    {
      "x": 10,
      "y": 10,
      "z": 14,
      "name": "Rock_Sandstone_White"
    },
    {
      "x": 10,
      "y": 11,
      "z": 14,
      "name": "Rock_Sandstone"
    },
    {
      "x": 10,
      "y": 15,
      "z": 14,
      "name": "Rock_Sandstone_White"
    },
    {
      "x": 10,
      "y": 16,
      "z": 14,
      "name": "Rock_Sandstone_White"
    },
    {
      "x": 10,
      "y": 17,
      "z": 14,
      "name": "Rock_Sandstone_White"
    },
    {
      "x": 10,
      "y": 18,
      "z": 14,
      "name": "Rock_Sandstone_White"
    },
    {
      "x": 10,
      "y": 19,
      "z": 14,
      "name": "Rock_Sandstone_White"
    },
    {
      "x": 10,
      "y": 21,
      "z": 14,
      "name": "Rock_Sandstone"
    },
    {
      "x": 10,
      "y": 22,
      "z": 14,
      "name": "Rock_Sandstone"
    },
    {
      "x": 10,
      "y": 23,
      "z": 14,
      "name": "Rock_Sandstone"
    },
    {
      "x": 10,
      "y": 24,
      "z": 14,
      "name": "Soil_Dirt_Dry"
    },
    {
      "x": 10,
      "y": 25,
      "z": 14,
      "name": "Rock_Sandstone_White"
    },
    {
      "x": 10,
      "y": 26,
      "z": 14,
      "name": "Rock_Sandstone_White"
    },
    {
      "x": 10,
      "y": 27,
      "z": 14,
      "name": "Rock_Sandstone"
    },
    {
      "x": 10,
      "y": 28,
      "z": 14,
      "name": "Rock_Sandstone_White"
    },
    {
      "x": 10,
      "y": 3,
      "z": 15,
      "name": "Rock_Sandstone_White"
    },
    {
      "x": 10,
      "y": 4,
      "z": 15,
      "name": "Rock_Sandstone_White"
    },
    {
      "x": 10,
      "y": 5,
      "z": 15,
      "name": "Rock_Sandstone_White"
    },
    {
      "x": 10,
      "y": 6,
      "z": 15,
      "name": "Rock_Sandstone_White"
    },
    {
      "x": 10,
      "y": 7,
      "z": 15,
      "name": "Rock_Sandstone_White"
    },
    {
      "x": 10,
      "y": 8,
      "z": 15,
      "name": "Rock_Sandstone_White"
    },
    {
      "x": 10,
      "y": 9,
      "z": 15,
      "name": "Rock_Sandstone_White"
    },
    {
      "x": 10,
      "y": 10,
      "z": 15,
      "name": "Rock_Sandstone_White"
    },
    {
      "x": 10,
      "y": 11,
      "z": 15,
      "name": "Rock_Sandstone"
    },
    {
      "x": 10,
      "y": 15,
      "z": 15,
      "name": "Rock_Sandstone_White"
    },
    {
      "x": 10,
      "y": 16,
      "z": 15,
      "name": "Rock_Sandstone_White"
    },
    {
      "x": 10,
      "y": 17,
      "z": 15,
      "name": "Rock_Sandstone_White"
    },
    {
      "x": 10,
      "y": 18,
      "z": 15,
      "name": "Rock_Sandstone_White"
    },
    {
      "x": 10,
      "y": 19,
      "z": 15,
      "name": "Rock_Sandstone_White"
    },
    {
      "x": 10,
      "y": 25,
      "z": 15,
      "name": "Rock_Sandstone_White"
    },
    {
      "x": 10,
      "y": 26,
      "z": 15,
      "name": "Rock_Sandstone_White"
    },
    {
      "x": 10,
      "y": 27,
      "z": 15,
      "name": "Rock_Sandstone"
    },
    {
      "x": 10,
      "y": 28,
      "z": 15,
      "name": "Rock_Sandstone_White"
    },
    {
      "x": 10,
      "y": 4,
      "z": 16,
      "name": "Rock_Sandstone_White"
    },
    {
      "x": 10,
      "y": 5,
      "z": 16,
      "name": "Rock_Sandstone_White"
    },
    {
      "x": 10,
      "y": 6,
      "z": 16,
      "name": "Rock_Sandstone_White"
    },
    {
      "x": 10,
      "y": 7,
      "z": 16,
      "name": "Rock_Sandstone_White"
    },
    {
      "x": 10,
      "y": 8,
      "z": 16,
      "name": "Rock_Sandstone_White"
    },
    {
      "x": 10,
      "y": 9,
      "z": 16,
      "name": "Rock_Sandstone_White"
    },
    {
      "x": 10,
      "y": 10,
      "z": 16,
      "name": "Rock_Sandstone_White"
    },
    {
      "x": 10,
      "y": 11,
      "z": 16,
      "name": "Rock_Sandstone"
    },
    {
      "x": 10,
      "y": 15,
      "z": 16,
      "name": "Rock_Sandstone_White"
    },
    {
      "x": 10,
      "y": 16,
      "z": 16,
      "name": "Rock_Sandstone_White"
    },
    {
      "x": 10,
      "y": 17,
      "z": 16,
      "name": "Rock_Sandstone"
    },
    {
      "x": 10,
      "y": 18,
      "z": 16,
      "name": "Rock_Sandstone_White"
    },
    {
      "x": 10,
      "y": 6,
      "z": 17,
      "name": "Rock_Sandstone_White"
    },
    {
      "x": 10,
      "y": 7,
      "z": 17,
      "name": "Rock_Sandstone_White"
    },
    {
      "x": 10,
      "y": 8,
      "z": 17,
      "name": "Rock_Sandstone_White"
    },
    {
      "x": 10,
      "y": 15,
      "z": 17,
      "name": "Rock_Sandstone_White"
    },
    {
      "x": 10,
      "y": 16,
      "z": 17,
      "name": "Rock_Sandstone_White"
    },
    {
      "x": 10,
      "y": 17,
      "z": 17,
      "name": "Rock_Sandstone"
    },
    {
      "x": 10,
      "y": 18,
      "z": 17,
      "name": "Rock_Sandstone"
    },
    {
      "x": 11,
      "y": 16,
      "z": 5,
      "name": "Rock_Sandstone_White"
    },
    {
      "x": 11,
      "y": 17,
      "z": 5,
      "name": "Rock_Sandstone_White"
    },
    {
      "x": 11,
      "y": 18,
      "z": 5,
      "name": "Rock_Sandstone"
    },
    {
      "x": 11,
      "y": 19,
      "z": 5,
      "name": "Rock_Sandstone"
    },
    {
      "x": 11,
      "y": 20,
      "z": 5,
      "name": "Rock_Sandstone_White"
    },
    {
      "x": 11,
      "y": 15,
      "z": 6,
      "name": "Rock_Sandstone_White"
    },
    {
      "x": 11,
      "y": 16,
      "z": 6,
      "name": "Rock_Sandstone_White"
    },
    {
      "x": 11,
      "y": 17,
      "z": 6,
      "name": "Rock_Sandstone_White"
    },
    {
      "x": 11,
      "y": 18,
      "z": 6,
      "name": "Rock_Sandstone_White"
    },
    {
      "x": 11,
      "y": 19,
      "z": 6,
      "name": "Rock_Sandstone_White"
    },
    {
      "x": 11,
      "y": 20,
      "z": 6,
      "name": "Rock_Sandstone_White"
    },
    {
      "x": 11,
      "y": 15,
      "z": 7,
      "name": "Rock_Sandstone_White"
    },
    {
      "x": 11,
      "y": 16,
      "z": 7,
      "name": "Rock_Sandstone_White"
    },
    {
      "x": 11,
      "y": 17,
      "z": 7,
      "name": "Rock_Sandstone_White"
    },
    {
      "x": 11,
      "y": 18,
      "z": 7,
      "name": "Rock_Sandstone_White"
    },
    {
      "x": 11,
      "y": 19,
      "z": 7,
      "name": "Rock_Sandstone_White"
    },
    {
      "x": 11,
      "y": 20,
      "z": 7,
      "name": "Rock_Sandstone_White"
    },
    {
      "x": 11,
      "y": 15,
      "z": 8,
      "name": "Rock_Sandstone_White"
    },
    {
      "x": 11,
      "y": 16,
      "z": 8,
      "name": "Rock_Sandstone_White"
    },
    {
      "x": 11,
      "y": 17,
      "z": 8,
      "name": "Rock_Sandstone_White"
    },
    {
      "x": 11,
      "y": 18,
      "z": 8,
      "name": "Rock_Sandstone_White"
    },
    {
      "x": 11,
      "y": 19,
      "z": 8,
      "name": "Rock_Sandstone_White"
    },
    {
      "x": 11,
      "y": 20,
      "z": 8,
      "name": "Rock_Sandstone_White"
    },
    {
      "x": 11,
      "y": 5,
      "z": 9,
      "name": "Rock_Sandstone_White"
    },
    {
      "x": 11,
      "y": 6,
      "z": 9,
      "name": "Rock_Sandstone_White"
    },
    {
      "x": 11,
      "y": 7,
      "z": 9,
      "name": "Rock_Sandstone_White"
    },
    {
      "x": 11,
      "y": 8,
      "z": 9,
      "name": "Rock_Sandstone_White"
    },
    {
      "x": 11,
      "y": 9,
      "z": 9,
      "name": "Rock_Sandstone_White"
    },
    {
      "x": 11,
      "y": 10,
      "z": 9,
      "name": "Rock_Sandstone_White"
    },
    {
      "x": 11,
      "y": 11,
      "z": 9,
      "name": "Rock_Sandstone"
    },
    {
      "x": 11,
      "y": 12,
      "z": 9,
      "name": "Rock_Sandstone_White"
    },
    {
      "x": 11,
      "y": 13,
      "z": 9,
      "name": "Rock_Sandstone_White"
    },
    {
      "x": 11,
      "y": 14,
      "z": 9,
      "name": "Rock_Sandstone_White"
    },
    {
      "x": 11,
      "y": 15,
      "z": 9,
      "name": "Rock_Sandstone_White"
    },
    {
      "x": 11,
      "y": 16,
      "z": 9,
      "name": "Rock_Sandstone_White"
    },
    {
      "x": 11,
      "y": 17,
      "z": 9,
      "name": "Rock_Sandstone_White"
    },
    {
      "x": 11,
      "y": 18,
      "z": 9,
      "name": "Rock_Sandstone_White"
    },
    {
      "x": 11,
      "y": 19,
      "z": 9,
      "name": "Rock_Sandstone_White"
    },
    {
      "x": 11,
      "y": 20,
      "z": 9,
      "name": "Rock_Sandstone"
    },
    {
      "x": 11,
      "y": 21,
      "z": 9,
      "name": "Rock_Sandstone"
    },
    {
      "x": 11,
      "y": 22,
      "z": 9,
      "name": "Rock_Sandstone"
    },
    {
      "x": 11,
      "y": 23,
      "z": 9,
      "name": "Rock_Sandstone"
    },
    {
      "x": 11,
      "y": 26,
      "z": 9,
      "name": "Rock_Sandstone_White"
    },
    {
      "x": 11,
      "y": 27,
      "z": 9,
      "name": "Rock_Sandstone_White"
    },
    {
      "x": 11,
      "y": 28,
      "z": 9,
      "name": "Rock_Sandstone"
    },
    {
      "x": 11,
      "y": 5,
      "z": 10,
      "name": "Rock_Sandstone_White"
    },
    {
      "x": 11,
      "y": 6,
      "z": 10,
      "name": "Rock_Sandstone_White"
    },
    {
      "x": 11,
      "y": 7,
      "z": 10,
      "name": "Rock_Sandstone_White"
    },
    {
      "x": 11,
      "y": 8,
      "z": 10,
      "name": "Rock_Sandstone_White"
    },
    {
      "x": 11,
      "y": 9,
      "z": 10,
      "name": "Rock_Sandstone_White"
    },
    {
      "x": 11,
      "y": 10,
      "z": 10,
      "name": "Rock_Sandstone_White"
    },
    {
      "x": 11,
      "y": 11,
      "z": 10,
      "name": "Rock_Sandstone"
    },
    {
      "x": 11,
      "y": 12,
      "z": 10,
      "name": "Rock_Sandstone_White"
    },
    {
      "x": 11,
      "y": 13,
      "z": 10,
      "name": "Rock_Sandstone_White"
    },
    {
      "x": 11,
      "y": 14,
      "z": 10,
      "name": "Rock_Sandstone_White"
    },
    {
      "x": 11,
      "y": 15,
      "z": 10,
      "name": "Rock_Sandstone_White"
    },
    {
      "x": 11,
      "y": 16,
      "z": 10,
      "name": "Rock_Sandstone_White"
    },
    {
      "x": 11,
      "y": 17,
      "z": 10,
      "name": "Rock_Sandstone_White"
    },
    {
      "x": 11,
      "y": 18,
      "z": 10,
      "name": "Rock_Sandstone_White"
    },
    {
      "x": 11,
      "y": 19,
      "z": 10,
      "name": "Rock_Sandstone_White"
    },
    {
      "x": 11,
      "y": 20,
      "z": 10,
      "name": "Rock_Sandstone"
    },
    {
      "x": 11,
      "y": 21,
      "z": 10,
      "name": "Rock_Sandstone"
    },
    {
      "x": 11,
      "y": 22,
      "z": 10,
      "name": "Rock_Sandstone"
    },
    {
      "x": 11,
      "y": 23,
      "z": 10,
      "name": "Rock_Sandstone"
    },
    {
      "x": 11,
      "y": 24,
      "z": 10,
      "name": "Soil_Dirt_Dry"
    },
    {
      "x": 11,
      "y": 25,
      "z": 10,
      "name": "Rock_Sandstone"
    },
    {
      "x": 11,
      "y": 26,
      "z": 10,
      "name": "Rock_Sandstone_White"
    },
    {
      "x": 11,
      "y": 27,
      "z": 10,
      "name": "Rock_Sandstone_White"
    },
    {
      "x": 11,
      "y": 28,
      "z": 10,
      "name": "Rock_Sandstone"
    },
    {
      "x": 11,
      "y": 3,
      "z": 11,
      "name": "Rock_Sandstone_White"
    },
    {
      "x": 11,
      "y": 4,
      "z": 11,
      "name": "Rock_Sandstone_White"
    },
    {
      "x": 11,
      "y": 5,
      "z": 11,
      "name": "Rock_Sandstone_White"
    },
    {
      "x": 11,
      "y": 6,
      "z": 11,
      "name": "Rock_Sandstone_White"
    },
    {
      "x": 11,
      "y": 7,
      "z": 11,
      "name": "Rock_Sandstone_White"
    },
    {
      "x": 11,
      "y": 8,
      "z": 11,
      "name": "Rock_Sandstone_White"
    },
    {
      "x": 11,
      "y": 9,
      "z": 11,
      "name": "Rock_Sandstone_White"
    },
    {
      "x": 11,
      "y": 10,
      "z": 11,
      "name": "Rock_Sandstone_White"
    },
    {
      "x": 11,
      "y": 11,
      "z": 11,
      "name": "Rock_Sandstone"
    },
    {
      "x": 11,
      "y": 12,
      "z": 11,
      "name": "Rock_Sandstone_White"
    },
    {
      "x": 11,
      "y": 13,
      "z": 11,
      "name": "Rock_Sandstone_White"
    },
    {
      "x": 11,
      "y": 14,
      "z": 11,
      "name": "Rock_Sandstone_White"
    },
    {
      "x": 11,
      "y": 15,
      "z": 11,
      "name": "Rock_Sandstone_White"
    },
    {
      "x": 11,
      "y": 16,
      "z": 11,
      "name": "Rock_Sandstone_White"
    },
    {
      "x": 11,
      "y": 17,
      "z": 11,
      "name": "Rock_Sandstone_White"
    },
    {
      "x": 11,
      "y": 18,
      "z": 11,
      "name": "Rock_Sandstone_White"
    },
    {
      "x": 11,
      "y": 19,
      "z": 11,
      "name": "Rock_Sandstone_White"
    },
    {
      "x": 11,
      "y": 20,
      "z": 11,
      "name": "Rock_Sandstone"
    },
    {
      "x": 11,
      "y": 21,
      "z": 11,
      "name": "Rock_Sandstone"
    },
    {
      "x": 11,
      "y": 22,
      "z": 11,
      "name": "Rock_Sandstone"
    },
    {
      "x": 11,
      "y": 23,
      "z": 11,
      "name": "Soil_Dirt_Dry"
    },
    {
      "x": 11,
      "y": 24,
      "z": 11,
      "name": "Soil_Dirt_Dry"
    },
    {
      "x": 11,
      "y": 25,
      "z": 11,
      "name": "Rock_Sandstone"
    },
    {
      "x": 11,
      "y": 26,
      "z": 11,
      "name": "Rock_Sandstone_White"
    },
    {
      "x": 11,
      "y": 27,
      "z": 11,
      "name": "Rock_Sandstone_White"
    },
    {
      "x": 11,
      "y": 28,
      "z": 11,
      "name": "Rock_Sandstone_White"
    },
    {
      "x": 11,
      "y": 3,
      "z": 12,
      "name": "Rock_Sandstone_White"
    },
    {
      "x": 11,
      "y": 4,
      "z": 12,
      "name": "Rock_Sandstone_White"
    },
    {
      "x": 11,
      "y": 5,
      "z": 12,
      "name": "Rock_Sandstone_White"
    },
    {
      "x": 11,
      "y": 6,
      "z": 12,
      "name": "Rock_Sandstone_White"
    },
    {
      "x": 11,
      "y": 7,
      "z": 12,
      "name": "Rock_Sandstone_White"
    },
    {
      "x": 11,
      "y": 8,
      "z": 12,
      "name": "Rock_Sandstone_White"
    },
    {
      "x": 11,
      "y": 9,
      "z": 12,
      "name": "Rock_Sandstone_White"
    },
    {
      "x": 11,
      "y": 10,
      "z": 12,
      "name": "Rock_Sandstone_White"
    },
    {
      "x": 11,
      "y": 11,
      "z": 12,
      "name": "Rock_Sandstone"
    },
    {
      "x": 11,
      "y": 12,
      "z": 12,
      "name": "Rock_Sandstone_White"
    },
    {
      "x": 11,
      "y": 13,
      "z": 12,
      "name": "Rock_Sandstone_White"
    },
    {
      "x": 11,
      "y": 14,
      "z": 12,
      "name": "Rock_Sandstone_White"
    },
    {
      "x": 11,
      "y": 15,
      "z": 12,
      "name": "Rock_Sandstone_White"
    },
    {
      "x": 11,
      "y": 16,
      "z": 12,
      "name": "Rock_Sandstone_White"
    },
    {
      "x": 11,
      "y": 17,
      "z": 12,
      "name": "Rock_Sandstone_White"
    },
    {
      "x": 11,
      "y": 18,
      "z": 12,
      "name": "Rock_Sandstone_White"
    },
    {
      "x": 11,
      "y": 19,
      "z": 12,
      "name": "Rock_Sandstone_White"
    },
    {
      "x": 11,
      "y": 20,
      "z": 12,
      "name": "Rock_Sandstone"
    },
    {
      "x": 11,
      "y": 21,
      "z": 12,
      "name": "Rock_Sandstone"
    },
    {
      "x": 11,
      "y": 22,
      "z": 12,
      "name": "Rock_Sandstone"
    },
    {
      "x": 11,
      "y": 23,
      "z": 12,
      "name": "Rock_Sandstone"
    },
    {
      "x": 11,
      "y": 24,
      "z": 12,
      "name": "Rock_Sandstone"
    },
    {
      "x": 11,
      "y": 25,
      "z": 12,
      "name": "Rock_Sandstone_White"
    },
    {
      "x": 11,
      "y": 26,
      "z": 12,
      "name": "Rock_Sandstone_White"
    },
    {
      "x": 11,
      "y": 27,
      "z": 12,
      "name": "Rock_Sandstone_White"
    },
    {
      "x": 11,
      "y": 28,
      "z": 12,
      "name": "Rock_Sandstone_White"
    },
    {
      "x": 11,
      "y": 3,
      "z": 13,
      "name": "Rock_Sandstone_White"
    },
    {
      "x": 11,
      "y": 4,
      "z": 13,
      "name": "Rock_Sandstone_White"
    },
    {
      "x": 11,
      "y": 5,
      "z": 13,
      "name": "Rock_Sandstone_White"
    },
    {
      "x": 11,
      "y": 6,
      "z": 13,
      "name": "Rock_Sandstone_White"
    },
    {
      "x": 11,
      "y": 7,
      "z": 13,
      "name": "Rock_Sandstone_White"
    },
    {
      "x": 11,
      "y": 8,
      "z": 13,
      "name": "Rock_Sandstone_White"
    },
    {
      "x": 11,
      "y": 9,
      "z": 13,
      "name": "Rock_Sandstone_White"
    },
    {
      "x": 11,
      "y": 10,
      "z": 13,
      "name": "Rock_Sandstone_White"
    },
    {
      "x": 11,
      "y": 11,
      "z": 13,
      "name": "Rock_Sandstone"
    },
    {
      "x": 11,
      "y": 12,
      "z": 13,
      "name": "Rock_Sandstone_White"
    },
    {
      "x": 11,
      "y": 13,
      "z": 13,
      "name": "Rock_Sandstone_White"
    },
    {
      "x": 11,
      "y": 14,
      "z": 13,
      "name": "Rock_Sandstone_White"
    },
    {
      "x": 11,
      "y": 15,
      "z": 13,
      "name": "Rock_Sandstone_White"
    },
    {
      "x": 11,
      "y": 16,
      "z": 13,
      "name": "Rock_Sandstone_White"
    },
    {
      "x": 11,
      "y": 17,
      "z": 13,
      "name": "Rock_Sandstone_White"
    },
    {
      "x": 11,
      "y": 18,
      "z": 13,
      "name": "Rock_Sandstone_White"
    },
    {
      "x": 11,
      "y": 19,
      "z": 13,
      "name": "Rock_Sandstone_White"
    },
    {
      "x": 11,
      "y": 20,
      "z": 13,
      "name": "Rock_Sandstone"
    },
    {
      "x": 11,
      "y": 21,
      "z": 13,
      "name": "Rock_Sandstone"
    },
    {
      "x": 11,
      "y": 22,
      "z": 13,
      "name": "Rock_Sandstone"
    },
    {
      "x": 11,
      "y": 23,
      "z": 13,
      "name": "Rock_Sandstone"
    },
    {
      "x": 11,
      "y": 24,
      "z": 13,
      "name": "Soil_Dirt_Dry"
    },
    {
      "x": 11,
      "y": 25,
      "z": 13,
      "name": "Rock_Sandstone_White"
    },
    {
      "x": 11,
      "y": 26,
      "z": 13,
      "name": "Rock_Sandstone_White"
    },
    {
      "x": 11,
      "y": 27,
      "z": 13,
      "name": "Rock_Sandstone"
    },
    {
      "x": 11,
      "y": 28,
      "z": 13,
      "name": "Rock_Sandstone_White"
    },
    {
      "x": 11,
      "y": 3,
      "z": 14,
      "name": "Rock_Sandstone_White"
    },
    {
      "x": 11,
      "y": 4,
      "z": 14,
      "name": "Rock_Sandstone_White"
    },
    {
      "x": 11,
      "y": 5,
      "z": 14,
      "name": "Rock_Sandstone_White"
    },
    {
      "x": 11,
      "y": 6,
      "z": 14,
      "name": "Rock_Sandstone_White"
    },
    {
      "x": 11,
      "y": 7,
      "z": 14,
      "name": "Rock_Sandstone_White"
    },
    {
      "x": 11,
      "y": 8,
      "z": 14,
      "name": "Rock_Sandstone_White"
    },
    {
      "x": 11,
      "y": 9,
      "z": 14,
      "name": "Rock_Sandstone_White"
    },
    {
      "x": 11,
      "y": 10,
      "z": 14,
      "name": "Rock_Sandstone_White"
    },
    {
      "x": 11,
      "y": 11,
      "z": 14,
      "name": "Rock_Sandstone"
    },
    {
      "x": 11,
      "y": 12,
      "z": 14,
      "name": "Rock_Sandstone_White"
    },
    {
      "x": 11,
      "y": 13,
      "z": 14,
      "name": "Rock_Sandstone_White"
    },
    {
      "x": 11,
      "y": 15,
      "z": 14,
      "name": "Rock_Sandstone_White"
    },
    {
      "x": 11,
      "y": 16,
      "z": 14,
      "name": "Rock_Sandstone_White"
    },
    {
      "x": 11,
      "y": 17,
      "z": 14,
      "name": "Rock_Sandstone_White"
    },
    {
      "x": 11,
      "y": 18,
      "z": 14,
      "name": "Rock_Sandstone_White"
    },
    {
      "x": 11,
      "y": 19,
      "z": 14,
      "name": "Rock_Sandstone_White"
    },
    {
      "x": 11,
      "y": 20,
      "z": 14,
      "name": "Rock_Sandstone"
    },
    {
      "x": 11,
      "y": 21,
      "z": 14,
      "name": "Rock_Sandstone"
    },
    {
      "x": 11,
      "y": 22,
      "z": 14,
      "name": "Rock_Sandstone"
    },
    {
      "x": 11,
      "y": 23,
      "z": 14,
      "name": "Rock_Sandstone"
    },
    {
      "x": 11,
      "y": 24,
      "z": 14,
      "name": "Soil_Dirt_Dry"
    },
    {
      "x": 11,
      "y": 25,
      "z": 14,
      "name": "Rock_Sandstone_White"
    },
    {
      "x": 11,
      "y": 26,
      "z": 14,
      "name": "Rock_Sandstone_White"
    },
    {
      "x": 11,
      "y": 27,
      "z": 14,
      "name": "Rock_Sandstone"
    },
    {
      "x": 11,
      "y": 28,
      "z": 14,
      "name": "Rock_Sandstone_White"
    },
    {
      "x": 11,
      "y": 3,
      "z": 15,
      "name": "Rock_Sandstone_White"
    },
    {
      "x": 11,
      "y": 4,
      "z": 15,
      "name": "Rock_Sandstone_White"
    },
    {
      "x": 11,
      "y": 5,
      "z": 15,
      "name": "Rock_Sandstone_White"
    },
    {
      "x": 11,
      "y": 6,
      "z": 15,
      "name": "Rock_Sandstone_White"
    },
    {
      "x": 11,
      "y": 7,
      "z": 15,
      "name": "Rock_Sandstone_White"
    },
    {
      "x": 11,
      "y": 8,
      "z": 15,
      "name": "Rock_Sandstone_White"
    },
    {
      "x": 11,
      "y": 9,
      "z": 15,
      "name": "Rock_Sandstone_White"
    },
    {
      "x": 11,
      "y": 10,
      "z": 15,
      "name": "Rock_Sandstone_White"
    },
    {
      "x": 11,
      "y": 11,
      "z": 15,
      "name": "Rock_Sandstone"
    },
    {
      "x": 11,
      "y": 12,
      "z": 15,
      "name": "Rock_Sandstone_White"
    },
    {
      "x": 11,
      "y": 13,
      "z": 15,
      "name": "Rock_Sandstone_White"
    },
    {
      "x": 11,
      "y": 15,
      "z": 15,
      "name": "Rock_Sandstone_White"
    },
    {
      "x": 11,
      "y": 16,
      "z": 15,
      "name": "Rock_Sandstone_White"
    },
    {
      "x": 11,
      "y": 17,
      "z": 15,
      "name": "Rock_Sandstone"
    },
    {
      "x": 11,
      "y": 18,
      "z": 15,
      "name": "Rock_Sandstone_White"
    },
    {
      "x": 11,
      "y": 19,
      "z": 15,
      "name": "Rock_Sandstone_White"
    },
    {
      "x": 11,
      "y": 25,
      "z": 15,
      "name": "Rock_Sandstone_White"
    },
    {
      "x": 11,
      "y": 26,
      "z": 15,
      "name": "Rock_Sandstone_White"
    },
    {
      "x": 11,
      "y": 27,
      "z": 15,
      "name": "Rock_Sandstone"
    },
    {
      "x": 11,
      "y": 28,
      "z": 15,
      "name": "Rock_Sandstone_White"
    },
    {
      "x": 11,
      "y": 3,
      "z": 16,
      "name": "Rock_Sandstone_White"
    },
    {
      "x": 11,
      "y": 4,
      "z": 16,
      "name": "Rock_Sandstone_White"
    },
    {
      "x": 11,
      "y": 5,
      "z": 16,
      "name": "Rock_Sandstone_White"
    },
    {
      "x": 11,
      "y": 6,
      "z": 16,
      "name": "Rock_Sandstone_White"
    },
    {
      "x": 11,
      "y": 7,
      "z": 16,
      "name": "Rock_Sandstone_White"
    },
    {
      "x": 11,
      "y": 8,
      "z": 16,
      "name": "Rock_Sandstone_White"
    },
    {
      "x": 11,
      "y": 9,
      "z": 16,
      "name": "Rock_Sandstone_White"
    },
    {
      "x": 11,
      "y": 10,
      "z": 16,
      "name": "Rock_Sandstone_White"
    },
    {
      "x": 11,
      "y": 11,
      "z": 16,
      "name": "Rock_Sandstone"
    },
    {
      "x": 11,
      "y": 12,
      "z": 16,
      "name": "Rock_Sandstone_White"
    },
    {
      "x": 11,
      "y": 15,
      "z": 16,
      "name": "Rock_Sandstone_White"
    },
    {
      "x": 11,
      "y": 16,
      "z": 16,
      "name": "Rock_Sandstone_White"
    },
    {
      "x": 11,
      "y": 17,
      "z": 16,
      "name": "Rock_Sandstone"
    },
    {
      "x": 11,
      "y": 18,
      "z": 16,
      "name": "Rock_Sandstone"
    },
    {
      "x": 11,
      "y": 19,
      "z": 16,
      "name": "Rock_Sandstone_White"
    },
    {
      "x": 11,
      "y": 5,
      "z": 17,
      "name": "Rock_Sandstone_White"
    },
    {
      "x": 11,
      "y": 6,
      "z": 17,
      "name": "Rock_Sandstone_White"
    },
    {
      "x": 11,
      "y": 7,
      "z": 17,
      "name": "Rock_Sandstone_White"
    },
    {
      "x": 11,
      "y": 8,
      "z": 17,
      "name": "Rock_Sandstone_White"
    },
    {
      "x": 11,
      "y": 9,
      "z": 17,
      "name": "Rock_Sandstone_White"
    },
    {
      "x": 11,
      "y": 16,
      "z": 17,
      "name": "Rock_Sandstone_White"
    },
    {
      "x": 11,
      "y": 17,
      "z": 17,
      "name": "Rock_Sandstone"
    },
    {
      "x": 11,
      "y": 18,
      "z": 17,
      "name": "Rock_Sandstone"
    },
    {
      "x": 12,
      "y": 16,
      "z": 5,
      "name": "Rock_Sandstone_White"
    },
    {
      "x": 12,
      "y": 17,
      "z": 5,
      "name": "Rock_Sandstone_White"
    },
    {
      "x": 12,
      "y": 18,
      "z": 5,
      "name": "Rock_Sandstone_White"
    },
    {
      "x": 12,
      "y": 19,
      "z": 5,
      "name": "Rock_Sandstone"
    },
    {
      "x": 12,
      "y": 20,
      "z": 5,
      "name": "Rock_Sandstone_White"
    },
    {
      "x": 12,
      "y": 15,
      "z": 6,
      "name": "Rock_Sandstone_White"
    },
    {
      "x": 12,
      "y": 16,
      "z": 6,
      "name": "Rock_Sandstone_White"
    },
    {
      "x": 12,
      "y": 17,
      "z": 6,
      "name": "Rock_Sandstone_White"
    },
    {
      "x": 12,
      "y": 18,
      "z": 6,
      "name": "Rock_Sandstone_White"
    },
    {
      "x": 12,
      "y": 19,
      "z": 6,
      "name": "Rock_Sandstone"
    },
    {
      "x": 12,
      "y": 20,
      "z": 6,
      "name": "Rock_Sandstone_White"
    },
    {
      "x": 12,
      "y": 15,
      "z": 7,
      "name": "Rock_Sandstone_White"
    },
    {
      "x": 12,
      "y": 16,
      "z": 7,
      "name": "Rock_Sandstone_White"
    },
    {
      "x": 12,
      "y": 17,
      "z": 7,
      "name": "Rock_Sandstone_White"
    },
    {
      "x": 12,
      "y": 18,
      "z": 7,
      "name": "Rock_Sandstone_White"
    },
    {
      "x": 12,
      "y": 19,
      "z": 7,
      "name": "Rock_Sandstone_White"
    },
    {
      "x": 12,
      "y": 20,
      "z": 7,
      "name": "Rock_Sandstone_White"
    },
    {
      "x": 12,
      "y": 15,
      "z": 8,
      "name": "Rock_Sandstone_White"
    },
    {
      "x": 12,
      "y": 16,
      "z": 8,
      "name": "Rock_Sandstone_White"
    },
    {
      "x": 12,
      "y": 17,
      "z": 8,
      "name": "Rock_Sandstone_White"
    },
    {
      "x": 12,
      "y": 18,
      "z": 8,
      "name": "Rock_Sandstone_White"
    },
    {
      "x": 12,
      "y": 19,
      "z": 8,
      "name": "Rock_Sandstone_White"
    },
    {
      "x": 12,
      "y": 20,
      "z": 8,
      "name": "Rock_Sandstone_White"
    },
    {
      "x": 12,
      "y": 5,
      "z": 9,
      "name": "Rock_Sandstone_White"
    },
    {
      "x": 12,
      "y": 6,
      "z": 9,
      "name": "Rock_Sandstone_White"
    },
    {
      "x": 12,
      "y": 7,
      "z": 9,
      "name": "Rock_Sandstone_White"
    },
    {
      "x": 12,
      "y": 8,
      "z": 9,
      "name": "Rock_Sandstone_White"
    },
    {
      "x": 12,
      "y": 9,
      "z": 9,
      "name": "Rock_Sandstone_White"
    },
    {
      "x": 12,
      "y": 10,
      "z": 9,
      "name": "Rock_Sandstone_White"
    },
    {
      "x": 12,
      "y": 11,
      "z": 9,
      "name": "Rock_Sandstone"
    },
    {
      "x": 12,
      "y": 12,
      "z": 9,
      "name": "Rock_Sandstone_White"
    },
    {
      "x": 12,
      "y": 13,
      "z": 9,
      "name": "Rock_Sandstone_White"
    },
    {
      "x": 12,
      "y": 14,
      "z": 9,
      "name": "Rock_Sandstone_White"
    },
    {
      "x": 12,
      "y": 15,
      "z": 9,
      "name": "Rock_Sandstone_White"
    },
    {
      "x": 12,
      "y": 16,
      "z": 9,
      "name": "Rock_Sandstone_White"
    },
    {
      "x": 12,
      "y": 17,
      "z": 9,
      "name": "Rock_Sandstone_White"
    },
    {
      "x": 12,
      "y": 18,
      "z": 9,
      "name": "Rock_Sandstone_White"
    },
    {
      "x": 12,
      "y": 19,
      "z": 9,
      "name": "Rock_Sandstone_White"
    },
    {
      "x": 12,
      "y": 20,
      "z": 9,
      "name": "Rock_Sandstone_White"
    },
    {
      "x": 12,
      "y": 21,
      "z": 9,
      "name": "Rock_Sandstone"
    },
    {
      "x": 12,
      "y": 22,
      "z": 9,
      "name": "Rock_Sandstone"
    },
    {
      "x": 12,
      "y": 23,
      "z": 9,
      "name": "Rock_Sandstone"
    },
    {
      "x": 12,
      "y": 26,
      "z": 9,
      "name": "Rock_Sandstone_White"
    },
    {
      "x": 12,
      "y": 27,
      "z": 9,
      "name": "Rock_Sandstone_White"
    },
    {
      "x": 12,
      "y": 28,
      "z": 9,
      "name": "Rock_Sandstone"
    },
    {
      "x": 12,
      "y": 4,
      "z": 10,
      "name": "Rock_Sandstone_White"
    },
    {
      "x": 12,
      "y": 5,
      "z": 10,
      "name": "Rock_Sandstone_White"
    },
    {
      "x": 12,
      "y": 6,
      "z": 10,
      "name": "Rock_Sandstone_White"
    },
    {
      "x": 12,
      "y": 7,
      "z": 10,
      "name": "Rock_Sandstone_White"
    },
    {
      "x": 12,
      "y": 8,
      "z": 10,
      "name": "Rock_Sandstone_White"
    },
    {
      "x": 12,
      "y": 9,
      "z": 10,
      "name": "Rock_Sandstone_White"
    },
    {
      "x": 12,
      "y": 10,
      "z": 10,
      "name": "Rock_Sandstone_White"
    },
    {
      "x": 12,
      "y": 11,
      "z": 10,
      "name": "Rock_Sandstone"
    },
    {
      "x": 12,
      "y": 12,
      "z": 10,
      "name": "Rock_Sandstone_White"
    },
    {
      "x": 12,
      "y": 13,
      "z": 10,
      "name": "Rock_Sandstone_White"
    },
    {
      "x": 12,
      "y": 14,
      "z": 10,
      "name": "Rock_Sandstone_White"
    },
    {
      "x": 12,
      "y": 15,
      "z": 10,
      "name": "Rock_Sandstone_White"
    },
    {
      "x": 12,
      "y": 16,
      "z": 10,
      "name": "Rock_Sandstone_White"
    },
    {
      "x": 12,
      "y": 17,
      "z": 10,
      "name": "Rock_Sandstone_White"
    },
    {
      "x": 12,
      "y": 18,
      "z": 10,
      "name": "Rock_Sandstone_White"
    },
    {
      "x": 12,
      "y": 19,
      "z": 10,
      "name": "Rock_Sandstone_White"
    },
    {
      "x": 12,
      "y": 20,
      "z": 10,
      "name": "Rock_Sandstone"
    },
    {
      "x": 12,
      "y": 21,
      "z": 10,
      "name": "Rock_Sandstone"
    },
    {
      "x": 12,
      "y": 22,
      "z": 10,
      "name": "Rock_Sandstone"
    },
    {
      "x": 12,
      "y": 23,
      "z": 10,
      "name": "Soil_Dirt_Dry"
    },
    {
      "x": 12,
      "y": 24,
      "z": 10,
      "name": "Soil_Dirt_Dry"
    },
    {
      "x": 12,
      "y": 25,
      "z": 10,
      "name": "Rock_Sandstone"
    },
    {
      "x": 12,
      "y": 26,
      "z": 10,
      "name": "Rock_Sandstone_White"
    },
    {
      "x": 12,
      "y": 27,
      "z": 10,
      "name": "Rock_Sandstone"
    },
    {
      "x": 12,
      "y": 28,
      "z": 10,
      "name": "Rock_Sandstone"
    },
    {
      "x": 12,
      "y": 3,
      "z": 11,
      "name": "Rock_Sandstone_White"
    },
    {
      "x": 12,
      "y": 4,
      "z": 11,
      "name": "Rock_Sandstone_White"
    },
    {
      "x": 12,
      "y": 5,
      "z": 11,
      "name": "Rock_Sandstone_White"
    },
    {
      "x": 12,
      "y": 6,
      "z": 11,
      "name": "Rock_Sandstone_White"
    },
    {
      "x": 12,
      "y": 7,
      "z": 11,
      "name": "Rock_Sandstone_White"
    },
    {
      "x": 12,
      "y": 8,
      "z": 11,
      "name": "Rock_Sandstone_White"
    },
    {
      "x": 12,
      "y": 9,
      "z": 11,
      "name": "Rock_Sandstone_White"
    },
    {
      "x": 12,
      "y": 10,
      "z": 11,
      "name": "Rock_Sandstone_White"
    },
    {
      "x": 12,
      "y": 11,
      "z": 11,
      "name": "Rock_Sandstone"
    },
    {
      "x": 12,
      "y": 12,
      "z": 11,
      "name": "Rock_Sandstone_White"
    },
    {
      "x": 12,
      "y": 13,
      "z": 11,
      "name": "Rock_Sandstone_White"
    },
    {
      "x": 12,
      "y": 14,
      "z": 11,
      "name": "Rock_Sandstone_White"
    },
    {
      "x": 12,
      "y": 15,
      "z": 11,
      "name": "Rock_Sandstone_White"
    },
    {
      "x": 12,
      "y": 16,
      "z": 11,
      "name": "Rock_Sandstone_White"
    },
    {
      "x": 12,
      "y": 17,
      "z": 11,
      "name": "Rock_Sandstone_White"
    },
    {
      "x": 12,
      "y": 18,
      "z": 11,
      "name": "Rock_Sandstone_White"
    },
    {
      "x": 12,
      "y": 19,
      "z": 11,
      "name": "Rock_Sandstone_White"
    },
    {
      "x": 12,
      "y": 20,
      "z": 11,
      "name": "Rock_Sandstone"
    },
    {
      "x": 12,
      "y": 21,
      "z": 11,
      "name": "Rock_Sandstone"
    },
    {
      "x": 12,
      "y": 22,
      "z": 11,
      "name": "Rock_Sandstone"
    },
    {
      "x": 12,
      "y": 23,
      "z": 11,
      "name": "Soil_Dirt_Dry"
    },
    {
      "x": 12,
      "y": 24,
      "z": 11,
      "name": "Soil_Dirt_Dry"
    },
    {
      "x": 12,
      "y": 25,
      "z": 11,
      "name": "Rock_Sandstone"
    },
    {
      "x": 12,
      "y": 26,
      "z": 11,
      "name": "Rock_Sandstone_White"
    },
    {
      "x": 12,
      "y": 27,
      "z": 11,
      "name": "Rock_Sandstone"
    },
    {
      "x": 12,
      "y": 28,
      "z": 11,
      "name": "Rock_Sandstone"
    },
    {
      "x": 12,
      "y": 3,
      "z": 12,
      "name": "Rock_Sandstone_White"
    },
    {
      "x": 12,
      "y": 4,
      "z": 12,
      "name": "Rock_Sandstone_White"
    },
    {
      "x": 12,
      "y": 5,
      "z": 12,
      "name": "Rock_Sandstone_White"
    },
    {
      "x": 12,
      "y": 6,
      "z": 12,
      "name": "Rock_Sandstone_White"
    },
    {
      "x": 12,
      "y": 7,
      "z": 12,
      "name": "Rock_Sandstone_White"
    },
    {
      "x": 12,
      "y": 8,
      "z": 12,
      "name": "Rock_Sandstone_White"
    },
    {
      "x": 12,
      "y": 9,
      "z": 12,
      "name": "Rock_Sandstone_White"
    },
    {
      "x": 12,
      "y": 10,
      "z": 12,
      "name": "Rock_Sandstone_White"
    },
    {
      "x": 12,
      "y": 11,
      "z": 12,
      "name": "Rock_Sandstone_White"
    },
    {
      "x": 12,
      "y": 12,
      "z": 12,
      "name": "Rock_Sandstone_White"
    },
    {
      "x": 12,
      "y": 13,
      "z": 12,
      "name": "Rock_Sandstone_White"
    },
    {
      "x": 12,
      "y": 14,
      "z": 12,
      "name": "Rock_Sandstone_White"
    },
    {
      "x": 12,
      "y": 15,
      "z": 12,
      "name": "Rock_Sandstone_White"
    },
    {
      "x": 12,
      "y": 16,
      "z": 12,
      "name": "Rock_Sandstone_White"
    },
    {
      "x": 12,
      "y": 17,
      "z": 12,
      "name": "Rock_Sandstone_White"
    },
    {
      "x": 12,
      "y": 18,
      "z": 12,
      "name": "Rock_Sandstone_White"
    },
    {
      "x": 12,
      "y": 19,
      "z": 12,
      "name": "Rock_Sandstone_White"
    },
    {
      "x": 12,
      "y": 20,
      "z": 12,
      "name": "Rock_Sandstone"
    },
    {
      "x": 12,
      "y": 21,
      "z": 12,
      "name": "Rock_Sandstone"
    },
    {
      "x": 12,
      "y": 22,
      "z": 12,
      "name": "Rock_Sandstone"
    },
    {
      "x": 12,
      "y": 23,
      "z": 12,
      "name": "Soil_Dirt_Dry"
    },
    {
      "x": 12,
      "y": 24,
      "z": 12,
      "name": "Soil_Dirt_Dry"
    },
    {
      "x": 12,
      "y": 25,
      "z": 12,
      "name": "Rock_Sandstone"
    },
    {
      "x": 12,
      "y": 26,
      "z": 12,
      "name": "Rock_Sandstone_White"
    },
    {
      "x": 12,
      "y": 27,
      "z": 12,
      "name": "Rock_Sandstone_White"
    },
    {
      "x": 12,
      "y": 28,
      "z": 12,
      "name": "Rock_Sandstone_White"
    },
    {
      "x": 12,
      "y": 3,
      "z": 13,
      "name": "Rock_Sandstone_White"
    },
    {
      "x": 12,
      "y": 4,
      "z": 13,
      "name": "Rock_Sandstone_White"
    },
    {
      "x": 12,
      "y": 5,
      "z": 13,
      "name": "Rock_Sandstone_White"
    },
    {
      "x": 12,
      "y": 6,
      "z": 13,
      "name": "Rock_Sandstone_White"
    },
    {
      "x": 12,
      "y": 7,
      "z": 13,
      "name": "Rock_Sandstone_White"
    },
    {
      "x": 12,
      "y": 8,
      "z": 13,
      "name": "Rock_Sandstone_White"
    },
    {
      "x": 12,
      "y": 9,
      "z": 13,
      "name": "Rock_Sandstone_White"
    },
    {
      "x": 12,
      "y": 10,
      "z": 13,
      "name": "Rock_Sandstone_White"
    },
    {
      "x": 12,
      "y": 11,
      "z": 13,
      "name": "Rock_Sandstone"
    },
    {
      "x": 12,
      "y": 12,
      "z": 13,
      "name": "Rock_Sandstone_White"
    },
    {
      "x": 12,
      "y": 13,
      "z": 13,
      "name": "Rock_Sandstone_White"
    },
    {
      "x": 12,
      "y": 14,
      "z": 13,
      "name": "Rock_Sandstone_White"
    },
    {
      "x": 12,
      "y": 15,
      "z": 13,
      "name": "Rock_Sandstone_White"
    },
    {
      "x": 12,
      "y": 16,
      "z": 13,
      "name": "Rock_Sandstone_White"
    },
    {
      "x": 12,
      "y": 17,
      "z": 13,
      "name": "Rock_Sandstone_White"
    },
    {
      "x": 12,
      "y": 18,
      "z": 13,
      "name": "Rock_Sandstone_White"
    },
    {
      "x": 12,
      "y": 19,
      "z": 13,
      "name": "Rock_Sandstone_White"
    },
    {
      "x": 12,
      "y": 20,
      "z": 13,
      "name": "Rock_Sandstone"
    },
    {
      "x": 12,
      "y": 21,
      "z": 13,
      "name": "Rock_Sandstone"
    },
    {
      "x": 12,
      "y": 22,
      "z": 13,
      "name": "Rock_Sandstone"
    },
    {
      "x": 12,
      "y": 23,
      "z": 13,
      "name": "Rock_Sandstone"
    },
    {
      "x": 12,
      "y": 24,
      "z": 13,
      "name": "Rock_Sandstone"
    },
    {
      "x": 12,
      "y": 25,
      "z": 13,
      "name": "Rock_Sandstone_White"
    },
    {
      "x": 12,
      "y": 26,
      "z": 13,
      "name": "Rock_Sandstone_White"
    },
    {
      "x": 12,
      "y": 27,
      "z": 13,
      "name": "Rock_Sandstone"
    },
    {
      "x": 12,
      "y": 28,
      "z": 13,
      "name": "Rock_Sandstone_White"
    },
    {
      "x": 12,
      "y": 3,
      "z": 14,
      "name": "Rock_Sandstone_White"
    },
    {
      "x": 12,
      "y": 4,
      "z": 14,
      "name": "Rock_Sandstone_White"
    },
    {
      "x": 12,
      "y": 5,
      "z": 14,
      "name": "Rock_Sandstone_White"
    },
    {
      "x": 12,
      "y": 6,
      "z": 14,
      "name": "Rock_Sandstone_White"
    },
    {
      "x": 12,
      "y": 7,
      "z": 14,
      "name": "Rock_Sandstone_White"
    },
    {
      "x": 12,
      "y": 8,
      "z": 14,
      "name": "Rock_Sandstone_White"
    },
    {
      "x": 12,
      "y": 9,
      "z": 14,
      "name": "Rock_Sandstone_White"
    },
    {
      "x": 12,
      "y": 10,
      "z": 14,
      "name": "Rock_Sandstone_White"
    },
    {
      "x": 12,
      "y": 11,
      "z": 14,
      "name": "Rock_Sandstone"
    },
    {
      "x": 12,
      "y": 12,
      "z": 14,
      "name": "Rock_Sandstone_White"
    },
    {
      "x": 12,
      "y": 13,
      "z": 14,
      "name": "Rock_Sandstone_White"
    },
    {
      "x": 12,
      "y": 14,
      "z": 14,
      "name": "Rock_Sandstone_White"
    },
    {
      "x": 12,
      "y": 15,
      "z": 14,
      "name": "Rock_Sandstone_White"
    },
    {
      "x": 12,
      "y": 16,
      "z": 14,
      "name": "Rock_Sandstone_White"
    },
    {
      "x": 12,
      "y": 17,
      "z": 14,
      "name": "Rock_Sandstone_White"
    },
    {
      "x": 12,
      "y": 18,
      "z": 14,
      "name": "Rock_Sandstone_White"
    },
    {
      "x": 12,
      "y": 19,
      "z": 14,
      "name": "Rock_Sandstone_White"
    },
    {
      "x": 12,
      "y": 20,
      "z": 14,
      "name": "Rock_Sandstone"
    },
    {
      "x": 12,
      "y": 21,
      "z": 14,
      "name": "Rock_Sandstone"
    },
    {
      "x": 12,
      "y": 22,
      "z": 14,
      "name": "Rock_Sandstone"
    },
    {
      "x": 12,
      "y": 23,
      "z": 14,
      "name": "Rock_Sandstone"
    },
    {
      "x": 12,
      "y": 24,
      "z": 14,
      "name": "Soil_Dirt_Dry"
    },
    {
      "x": 12,
      "y": 25,
      "z": 14,
      "name": "Rock_Sandstone_White"
    },
    {
      "x": 12,
      "y": 26,
      "z": 14,
      "name": "Rock_Sandstone_White"
    },
    {
      "x": 12,
      "y": 27,
      "z": 14,
      "name": "Rock_Sandstone"
    },
    {
      "x": 12,
      "y": 28,
      "z": 14,
      "name": "Rock_Sandstone_White"
    },
    {
      "x": 12,
      "y": 3,
      "z": 15,
      "name": "Rock_Sandstone_White"
    },
    {
      "x": 12,
      "y": 4,
      "z": 15,
      "name": "Rock_Sandstone_White"
    },
    {
      "x": 12,
      "y": 5,
      "z": 15,
      "name": "Rock_Sandstone_White"
    },
    {
      "x": 12,
      "y": 6,
      "z": 15,
      "name": "Rock_Sandstone_White"
    },
    {
      "x": 12,
      "y": 7,
      "z": 15,
      "name": "Rock_Sandstone_White"
    },
    {
      "x": 12,
      "y": 8,
      "z": 15,
      "name": "Rock_Sandstone_White"
    },
    {
      "x": 12,
      "y": 9,
      "z": 15,
      "name": "Rock_Sandstone_White"
    },
    {
      "x": 12,
      "y": 10,
      "z": 15,
      "name": "Rock_Sandstone_White"
    },
    {
      "x": 12,
      "y": 11,
      "z": 15,
      "name": "Rock_Sandstone_White"
    },
    {
      "x": 12,
      "y": 12,
      "z": 15,
      "name": "Rock_Sandstone_White"
    },
    {
      "x": 12,
      "y": 13,
      "z": 15,
      "name": "Rock_Sandstone_White"
    },
    {
      "x": 12,
      "y": 14,
      "z": 15,
      "name": "Rock_Sandstone_White"
    },
    {
      "x": 12,
      "y": 15,
      "z": 15,
      "name": "Rock_Sandstone_White"
    },
    {
      "x": 12,
      "y": 16,
      "z": 15,
      "name": "Rock_Sandstone_White"
    },
    {
      "x": 12,
      "y": 17,
      "z": 15,
      "name": "Rock_Sandstone_White"
    },
    {
      "x": 12,
      "y": 18,
      "z": 15,
      "name": "Rock_Sandstone"
    },
    {
      "x": 12,
      "y": 19,
      "z": 15,
      "name": "Rock_Sandstone_White"
    },
    {
      "x": 12,
      "y": 25,
      "z": 15,
      "name": "Rock_Sandstone_White"
    },
    {
      "x": 12,
      "y": 26,
      "z": 15,
      "name": "Rock_Sandstone_White"
    },
    {
      "x": 12,
      "y": 27,
      "z": 15,
      "name": "Rock_Sandstone"
    },
    {
      "x": 12,
      "y": 28,
      "z": 15,
      "name": "Rock_Sandstone_White"
    },
    {
      "x": 12,
      "y": 3,
      "z": 16,
      "name": "Rock_Sandstone_White"
    },
    {
      "x": 12,
      "y": 4,
      "z": 16,
      "name": "Rock_Sandstone_White"
    },
    {
      "x": 12,
      "y": 5,
      "z": 16,
      "name": "Rock_Sandstone_White"
    },
    {
      "x": 12,
      "y": 6,
      "z": 16,
      "name": "Rock_Sandstone_White"
    },
    {
      "x": 12,
      "y": 7,
      "z": 16,
      "name": "Rock_Sandstone_White"
    },
    {
      "x": 12,
      "y": 8,
      "z": 16,
      "name": "Rock_Sandstone_White"
    },
    {
      "x": 12,
      "y": 9,
      "z": 16,
      "name": "Rock_Sandstone_White"
    },
    {
      "x": 12,
      "y": 10,
      "z": 16,
      "name": "Rock_Sandstone_White"
    },
    {
      "x": 12,
      "y": 11,
      "z": 16,
      "name": "Rock_Sandstone"
    },
    {
      "x": 12,
      "y": 12,
      "z": 16,
      "name": "Rock_Sandstone_White"
    },
    {
      "x": 12,
      "y": 13,
      "z": 16,
      "name": "Rock_Sandstone_White"
    },
    {
      "x": 12,
      "y": 15,
      "z": 16,
      "name": "Rock_Sandstone_White"
    },
    {
      "x": 12,
      "y": 16,
      "z": 16,
      "name": "Rock_Sandstone_White"
    },
    {
      "x": 12,
      "y": 17,
      "z": 16,
      "name": "Rock_Sandstone"
    },
    {
      "x": 12,
      "y": 18,
      "z": 16,
      "name": "Rock_Sandstone"
    },
    {
      "x": 12,
      "y": 19,
      "z": 16,
      "name": "Rock_Sandstone_White"
    },
    {
      "x": 12,
      "y": 5,
      "z": 17,
      "name": "Rock_Sandstone_White"
    },
    {
      "x": 12,
      "y": 6,
      "z": 17,
      "name": "Rock_Sandstone_White"
    },
    {
      "x": 12,
      "y": 7,
      "z": 17,
      "name": "Rock_Sandstone_White"
    },
    {
      "x": 12,
      "y": 8,
      "z": 17,
      "name": "Rock_Sandstone_White"
    },
    {
      "x": 12,
      "y": 9,
      "z": 17,
      "name": "Rock_Sandstone_White"
    },
    {
      "x": 12,
      "y": 10,
      "z": 17,
      "name": "Rock_Sandstone_White"
    },
    {
      "x": 12,
      "y": 16,
      "z": 17,
      "name": "Rock_Sandstone_White"
    },
    {
      "x": 12,
      "y": 17,
      "z": 17,
      "name": "Rock_Sandstone"
    },
    {
      "x": 12,
      "y": 18,
      "z": 17,
      "name": "Rock_Sandstone"
    },
    {
      "x": 13,
      "y": 16,
      "z": 5,
      "name": "Rock_Sandstone_White"
    },
    {
      "x": 13,
      "y": 17,
      "z": 5,
      "name": "Rock_Sandstone_White"
    },
    {
      "x": 13,
      "y": 18,
      "z": 5,
      "name": "Rock_Sandstone_White"
    },
    {
      "x": 13,
      "y": 19,
      "z": 5,
      "name": "Rock_Sandstone"
    },
    {
      "x": 13,
      "y": 20,
      "z": 5,
      "name": "Rock_Sandstone_White"
    },
    {
      "x": 13,
      "y": 16,
      "z": 6,
      "name": "Rock_Sandstone_White"
    },
    {
      "x": 13,
      "y": 17,
      "z": 6,
      "name": "Rock_Sandstone_White"
    },
    {
      "x": 13,
      "y": 18,
      "z": 6,
      "name": "Rock_Sandstone_White"
    },
    {
      "x": 13,
      "y": 19,
      "z": 6,
      "name": "Rock_Sandstone"
    },
    {
      "x": 13,
      "y": 20,
      "z": 6,
      "name": "Rock_Sandstone_White"
    },
    {
      "x": 13,
      "y": 15,
      "z": 7,
      "name": "Rock_Sandstone_White"
    },
    {
      "x": 13,
      "y": 16,
      "z": 7,
      "name": "Rock_Sandstone_White"
    },
    {
      "x": 13,
      "y": 17,
      "z": 7,
      "name": "Rock_Sandstone_White"
    },
    {
      "x": 13,
      "y": 18,
      "z": 7,
      "name": "Rock_Sandstone_White"
    },
    {
      "x": 13,
      "y": 19,
      "z": 7,
      "name": "Rock_Sandstone"
    },
    {
      "x": 13,
      "y": 20,
      "z": 7,
      "name": "Rock_Sandstone_White"
    },
    {
      "x": 13,
      "y": 15,
      "z": 8,
      "name": "Rock_Sandstone_White"
    },
    {
      "x": 13,
      "y": 16,
      "z": 8,
      "name": "Rock_Sandstone_White"
    },
    {
      "x": 13,
      "y": 17,
      "z": 8,
      "name": "Rock_Sandstone_White"
    },
    {
      "x": 13,
      "y": 18,
      "z": 8,
      "name": "Rock_Sandstone_White"
    },
    {
      "x": 13,
      "y": 19,
      "z": 8,
      "name": "Rock_Sandstone_White"
    },
    {
      "x": 13,
      "y": 20,
      "z": 8,
      "name": "Rock_Sandstone_White"
    },
    {
      "x": 13,
      "y": 5,
      "z": 9,
      "name": "Rock_Sandstone_White"
    },
    {
      "x": 13,
      "y": 6,
      "z": 9,
      "name": "Rock_Sandstone_White"
    },
    {
      "x": 13,
      "y": 7,
      "z": 9,
      "name": "Rock_Sandstone_White"
    },
    {
      "x": 13,
      "y": 8,
      "z": 9,
      "name": "Rock_Sandstone_White"
    },
    {
      "x": 13,
      "y": 9,
      "z": 9,
      "name": "Rock_Sandstone_White"
    },
    {
      "x": 13,
      "y": 10,
      "z": 9,
      "name": "Rock_Sandstone_White"
    },
    {
      "x": 13,
      "y": 11,
      "z": 9,
      "name": "Rock_Sandstone"
    },
    {
      "x": 13,
      "y": 12,
      "z": 9,
      "name": "Rock_Sandstone_White"
    },
    {
      "x": 13,
      "y": 13,
      "z": 9,
      "name": "Rock_Sandstone_White"
    },
    {
      "x": 13,
      "y": 15,
      "z": 9,
      "name": "Rock_Sandstone_White"
    },
    {
      "x": 13,
      "y": 16,
      "z": 9,
      "name": "Rock_Sandstone_White"
    },
    {
      "x": 13,
      "y": 17,
      "z": 9,
      "name": "Rock_Sandstone_White"
    },
    {
      "x": 13,
      "y": 18,
      "z": 9,
      "name": "Rock_Sandstone_White"
    },
    {
      "x": 13,
      "y": 19,
      "z": 9,
      "name": "Rock_Sandstone_White"
    },
    {
      "x": 13,
      "y": 20,
      "z": 9,
      "name": "Rock_Sandstone_White"
    },
    {
      "x": 13,
      "y": 26,
      "z": 9,
      "name": "Rock_Sandstone_White"
    },
    {
      "x": 13,
      "y": 27,
      "z": 9,
      "name": "Rock_Sandstone"
    },
    {
      "x": 13,
      "y": 28,
      "z": 9,
      "name": "Rock_Sandstone"
    },
    {
      "x": 13,
      "y": 4,
      "z": 10,
      "name": "Rock_Sandstone_White"
    },
    {
      "x": 13,
      "y": 5,
      "z": 10,
      "name": "Rock_Sandstone_White"
    },
    {
      "x": 13,
      "y": 6,
      "z": 10,
      "name": "Rock_Sandstone_White"
    },
    {
      "x": 13,
      "y": 7,
      "z": 10,
      "name": "Rock_Sandstone_White"
    },
    {
      "x": 13,
      "y": 8,
      "z": 10,
      "name": "Rock_Sandstone_White"
    },
    {
      "x": 13,
      "y": 9,
      "z": 10,
      "name": "Rock_Sandstone_White"
    },
    {
      "x": 13,
      "y": 10,
      "z": 10,
      "name": "Rock_Sandstone_White"
    },
    {
      "x": 13,
      "y": 11,
      "z": 10,
      "name": "Rock_Sandstone"
    },
    {
      "x": 13,
      "y": 12,
      "z": 10,
      "name": "Rock_Sandstone_White"
    },
    {
      "x": 13,
      "y": 13,
      "z": 10,
      "name": "Rock_Sandstone_White"
    },
    {
      "x": 13,
      "y": 14,
      "z": 10,
      "name": "Rock_Sandstone_White"
    },
    {
      "x": 13,
      "y": 15,
      "z": 10,
      "name": "Rock_Sandstone_White"
    },
    {
      "x": 13,
      "y": 16,
      "z": 10,
      "name": "Rock_Sandstone_White"
    },
    {
      "x": 13,
      "y": 17,
      "z": 10,
      "name": "Rock_Sandstone_White"
    },
    {
      "x": 13,
      "y": 18,
      "z": 10,
      "name": "Rock_Sandstone_White"
    },
    {
      "x": 13,
      "y": 19,
      "z": 10,
      "name": "Rock_Sandstone_White"
    },
    {
      "x": 13,
      "y": 20,
      "z": 10,
      "name": "Rock_Sandstone_White"
    },
    {
      "x": 13,
      "y": 22,
      "z": 10,
      "name": "Rock_Sandstone"
    },
    {
      "x": 13,
      "y": 23,
      "z": 10,
      "name": "Soil_Dirt_Dry"
    },
    {
      "x": 13,
      "y": 24,
      "z": 10,
      "name": "Soil_Dirt_Dry"
    },
    {
      "x": 13,
      "y": 25,
      "z": 10,
      "name": "Rock_Sandstone"
    },
    {
      "x": 13,
      "y": 26,
      "z": 10,
      "name": "Rock_Sandstone_White"
    },
    {
      "x": 13,
      "y": 27,
      "z": 10,
      "name": "Rock_Sandstone"
    },
    {
      "x": 13,
      "y": 28,
      "z": 10,
      "name": "Rock_Sandstone"
    },
    {
      "x": 13,
      "y": 4,
      "z": 11,
      "name": "Rock_Sandstone_White"
    },
    {
      "x": 13,
      "y": 5,
