{
  "version": 8,
  "blockIdVersion": 8,
  "anchorX": 0,
  "anchorY": 9,
  "anchorZ": 0,
  "blocks": [
    {
      "x": -42,
      "y": 9,
      "z": -4,
      "name": "Soil_Dirt"
    },
    {
      "x": -42,
      "y": 10,
      "z": -4,
      "name": "Empty"
    },
    {
      "x": -42,
      "y": 9,
      "z": -3,
      "name": "Soil_Pathway"
    },
    {
      "x": -42,
      "y": 10,
      "z": -3,
      "name": "Empty"
    },
    {
      "x": -42,
      "y": 9,
      "z": -2,
      "name": "Soil_Pathway"
    },
    {
      "x": -42,
      "y": 10,
      "z": -2,
      "name": "Empty"
    },
    {
      "x": -41,
      "y": 9,
      "z": -3,
      "name": "Soil_Dirt"
    },
    {
      "x": -41,
      "y": 10,
      "z": -3,
      "name": "Empty"
    },
    {
      "x": -41,
      "y": 9,
      "z": -2,
      "name": "Soil_Pathway"
    },
    {
      "x": -41,
      "y": 10,
      "z": -2,
      "name": "Empty"
    },
    {
      "x": -40,
      "y": 10,
      "z": -2,
      "name": "Furniture_Tavern_Barrel"
    },
    {
      "x": -39,
      "y": 9,
      "z": -4,
      "name": "Soil_Dirt"
    },
    {
      "x": -39,
      "y": 10,
      "z": -4,
      "name": "Empty"
    },
    {
      "x": -39,
      "y": 9,
      "z": -3,
      "name": "Soil_Dirt"
    },
    {
      "x": -39,
      "y": 10,
      "z": -3,
      "name": "Empty"
    },
    {
      "x": -39,
      "y": 10,
      "z": -2,
      "name": "Furniture_Village_Crate"
    },
    {
      "x": -39,
      "y": 10,
      "z": -1,
      "name": "Furniture_Tavern_Barrel"
    },
    {
      "x": -38,
      "y": 9,
      "z": -4,
      "name": "Soil_Pathway"
    },
    {
      "x": -38,
      "y": 10,
      "z": -4,
      "name": "Empty"
    },
    {
      "x": -38,
      "y": 9,
      "z": -3,
      "name": "Soil_Dirt"
    },
    {
      "x": -38,
      "y": 10,
      "z": -3,
      "name": "Empty"
    },
    {
      "x": -38,
      "y": 10,
      "z": -2,
      "name": "Furniture_Village_Crate"
    },
    {
      "x": -37,
      "y": 9,
      "z": -5,
      "name": "Soil_Pathway"
    },
    {
      "x": -37,
      "y": 10,
      "z": -5,
      "name": "Empty"
    },
    {
      "x": -37,
      "y": 9,
      "z": -4,
      "name": "Soil_Pathway"
    },
    {
      "x": -37,
      "y": 10,
      "z": -4,
      "name": "Empty"
    },
    {
      "x": -37,
      "y": 9,
      "z": -3,
      "name": "Soil_Dirt"
    },
    {
      "x": -37,
      "y": 10,
      "z": -3,
      "name": "Empty"
    },
    {
      "x": -37,
      "y": 7,
      "z": 11,
      "name": "Rock_Chalk"
    },
    {
      "x": -37,
      "y": 8,
      "z": 11,
      "name": "Rock_Chalk"
    },
    {
      "x": -37,
      "y": 9,
      "z": 11,
      "name": "Rock_Chalk"
    },
    {
      "x": -37,
      "y": 7,
      "z": 12,
      "name": "Rock_Chalk"
    },
    {
      "x": -37,
      "y": 8,
      "z": 12,
      "name": "Rock_Chalk"
    },
    {
      "x": -37,
      "y": 9,
      "z": 12,
      "name": "Rock_Chalk"
    },
    {
      "x": -37,
      "y": 10,
      "z": 12,
      "name": "Rock_Chalk"
    },
    {
      "x": -37,
      "y": 7,
      "z": 13,
      "name": "Rock_Chalk"
    },
    {
      "x": -37,
      "y": 8,
      "z": 13,
      "name": "Rock_Chalk"
    },
    {
      "x": -37,
      "y": 9,
      "z": 13,
      "name": "Rock_Chalk"
    },
    {
      "x": -37,
      "y": 10,
      "z": 13,
      "name": "Rock_Chalk"
    },
    {
      "x": -37,
      "y": 11,
      "z": 13,
      "name": "Rock_Chalk"
    },
    {
      "x": -37,
      "y": 7,
      "z": 14,
      "name": "Rock_Chalk"
    },
    {
      "x": -37,
      "y": 8,
      "z": 14,
      "name": "Rock_Chalk"
    },
    {
      "x": -37,
      "y": 9,
      "z": 14,
      "name": "Rock_Chalk"
    },
    {
      "x": -36,
      "y": 9,
      "z": -5,
      "name": "Soil_Pathway"
    },
    {
      "x": -36,
      "y": 10,
      "z": -5,
      "name": "Empty"
    },
    {
      "x": -36,
      "y": 9,
      "z": -4,
      "name": "Soil_Pathway"
    },
    {
      "x": -36,
      "y": 10,
      "z": -4,
      "name": "Empty"
    },
    {
      "x": -36,
      "y": 9,
      "z": -3,
      "name": "Soil_Pathway"
    },
    {
      "x": -36,
      "y": 10,
      "z": -3,
      "name": "Empty"
    },
    {
      "x": -36,
      "y": 7,
      "z": 11,
      "name": "Rock_Chalk"
    },
    {
      "x": -36,
      "y": 8,
      "z": 11,
      "name": "Rock_Chalk"
    },
    {
      "x": -36,
      "y": 9,
      "z": 11,
      "name": "Rock_Chalk"
    },
    {
      "x": -36,
      "y": 10,
      "z": 11,
      "name": "Rock_Chalk"
    },
    {
      "x": -36,
      "y": 11,
      "z": 11,
      "name": "Rock_Chalk"
    },
    {
      "x": -36,
      "y": 6,
      "z": 12,
      "name": "Rock_Chalk"
    },
    {
      "x": -36,
      "y": 7,
      "z": 12,
      "name": "Rock_Chalk"
    },
    {
      "x": -36,
      "y": 8,
      "z": 12,
      "name": "Rock_Chalk"
    },
    {
      "x": -36,
      "y": 9,
      "z": 12,
      "name": "Rock_Chalk"
    },
    {
      "x": -36,
      "y": 10,
      "z": 12,
      "name": "Rock_Chalk"
    },
    {
      "x": -36,
      "y": 11,
      "z": 12,
      "name": "Rock_Chalk"
    },
    {
      "x": -36,
      "y": 12,
      "z": 12,
      "name": "Rock_Chalk"
    },
    {
      "x": -36,
      "y": 6,
      "z": 13,
      "name": "Rock_Chalk"
    },
    {
      "x": -36,
      "y": 7,
      "z": 13,
      "name": "Rock_Chalk"
    },
    {
      "x": -36,
      "y": 8,
      "z": 13,
      "name": "Rock_Chalk"
    },
    {
      "x": -36,
      "y": 9,
      "z": 13,
      "name": "Rock_Chalk"
    },
    {
      "x": -36,
      "y": 10,
      "z": 13,
      "name": "Rock_Chalk"
    },
    {
      "x": -36,
      "y": 11,
      "z": 13,
      "name": "Rock_Chalk"
    },
    {
      "x": -36,
      "y": 12,
      "z": 13,
      "name": "Rock_Chalk"
    },
    {
      "x": -36,
      "y": 7,
      "z": 14,
      "name": "Rock_Chalk"
    },
    {
      "x": -36,
      "y": 8,
      "z": 14,
      "name": "Rock_Chalk"
    },
    {
      "x": -36,
      "y": 9,
      "z": 14,
      "name": "Rock_Chalk"
    },
    {
      "x": -36,
      "y": 10,
      "z": 14,
      "name": "Rock_Chalk"
    },
    {
      "x": -36,
      "y": 11,
      "z": 14,
      "name": "Rock_Chalk"
    },
    {
      "x": -35,
      "y": 9,
      "z": -6,
      "name": "Soil_Pathway"
    },
    {
      "x": -35,
      "y": 10,
      "z": -6,
      "name": "Empty"
    },
    {
      "x": -35,
      "y": 9,
      "z": -5,
      "name": "Soil_Pathway"
    },
    {
      "x": -35,
      "y": 10,
      "z": -5,
      "name": "Empty"
    },
    {
      "x": -35,
      "y": 9,
      "z": -4,
      "name": "Soil_Pathway"
    },
    {
      "x": -35,
      "y": 10,
      "z": -4,
      "name": "Empty"
    },
    {
      "x": -35,
      "y": 9,
      "z": -3,
      "name": "Soil_Pathway"
    },
    {
      "x": -35,
      "y": 10,
      "z": -3,
      "name": "Empty"
    },
    {
      "x": -35,
      "y": 8,
      "z": 11,
      "name": "Rock_Chalk"
    },
    {
      "x": -35,
      "y": 9,
      "z": 11,
      "name": "Rock_Chalk"
    },
    {
      "x": -35,
      "y": 10,
      "z": 11,
      "name": "Rock_Chalk"
    },
    {
      "x": -35,
      "y": 11,
      "z": 11,
      "name": "Rock_Chalk"
    },
    {
      "x": -35,
      "y": 12,
      "z": 11,
      "name": "Rock_Chalk"
    },
    {
      "x": -35,
      "y": 6,
      "z": 12,
      "name": "Rock_Chalk"
    },
    {
      "x": -35,
      "y": 7,
      "z": 12,
      "name": "Rock_Chalk"
    },
    {
      "x": -35,
      "y": 8,
      "z": 12,
      "name": "Rock_Chalk"
    },
    {
      "x": -35,
      "y": 9,
      "z": 12,
      "name": "Rock_Chalk"
    },
    {
      "x": -35,
      "y": 10,
      "z": 12,
      "name": "Rock_Chalk"
    },
    {
      "x": -35,
      "y": 11,
      "z": 12,
      "name": "Rock_Chalk"
    },
    {
      "x": -35,
      "y": 12,
      "z": 12,
      "name": "Rock_Chalk"
    },
    {
      "x": -35,
      "y": 6,
      "z": 13,
      "name": "Rock_Chalk"
    },
    {
      "x": -35,
      "y": 7,
      "z": 13,
      "name": "Rock_Chalk"
    },
    {
      "x": -35,
      "y": 8,
      "z": 13,
      "name": "Rock_Chalk"
    },
    {
      "x": -35,
      "y": 9,
      "z": 13,
      "name": "Rock_Chalk"
    },
    {
      "x": -35,
      "y": 10,
      "z": 13,
      "name": "Rock_Chalk"
    },
    {
      "x": -35,
      "y": 11,
      "z": 13,
      "name": "Rock_Chalk"
    },
    {
      "x": -35,
      "y": 12,
      "z": 13,
      "name": "Rock_Chalk"
    },
    {
      "x": -35,
      "y": 8,
      "z": 14,
      "name": "Rock_Chalk"
    },
    {
      "x": -35,
      "y": 9,
      "z": 14,
      "name": "Rock_Chalk"
    },
    {
      "x": -35,
      "y": 10,
      "z": 14,
      "name": "Rock_Chalk"
    },
    {
      "x": -35,
      "y": 11,
      "z": 14,
      "name": "Rock_Chalk"
    },
    {
      "x": -35,
      "y": 7,
      "z": 15,
      "name": "Rock_Stone"
    },
    {
      "x": -35,
      "y": 8,
      "z": 15,
      "name": "Rock_Stone"
    },
    {
      "x": -35,
      "y": 9,
      "z": 15,
      "name": "Rock_Stone"
    },
    {
      "x": -35,
      "y": 10,
      "z": 15,
      "name": "Rock_Stone"
    },
    {
      "x": -35,
      "y": 8,
      "z": 16,
      "name": "Rock_Stone"
    },
    {
      "x": -35,
      "y": 9,
      "z": 16,
      "name": "Rock_Stone"
    },
    {
      "x": -34,
      "y": 9,
      "z": -6,
      "name": "Soil_Pathway"
    },
    {
      "x": -34,
      "y": 10,
      "z": -6,
      "name": "Empty"
    },
    {
      "x": -34,
      "y": 9,
      "z": -5,
      "name": "Soil_Pathway"
    },
    {
      "x": -34,
      "y": 10,
      "z": -5,
      "name": "Empty"
    },
    {
      "x": -34,
      "y": 9,
      "z": -4,
      "name": "Soil_Pathway"
    },
    {
      "x": -34,
      "y": 10,
      "z": -4,
      "name": "Empty"
    },
    {
      "x": -34,
      "y": 10,
      "z": 10,
      "name": "Rock_Stone"
    },
    {
      "x": -34,
      "y": 11,
      "z": 10,
      "name": "Rock_Stone"
    },
    {
      "x": -34,
      "y": 10,
      "z": 11,
      "name": "Rock_Chalk"
    },
    {
      "x": -34,
      "y": 11,
      "z": 11,
      "name": "Rock_Chalk"
    },
    {
      "x": -34,
      "y": 12,
      "z": 11,
      "name": "Rock_Chalk"
    },
    {
      "x": -34,
      "y": 7,
      "z": 12,
      "name": "Rock_Chalk"
    },
    {
      "x": -34,
      "y": 8,
      "z": 12,
      "name": "Rock_Chalk"
    },
    {
      "x": -34,
      "y": 9,
      "z": 12,
      "name": "Rock_Chalk"
    },
    {
      "x": -34,
      "y": 10,
      "z": 12,
      "name": "Rock_Chalk"
    },
    {
      "x": -34,
      "y": 11,
      "z": 12,
      "name": "Rock_Chalk"
    },
    {
      "x": -34,
      "y": 12,
      "z": 12,
      "name": "Rock_Chalk"
    },
    {
      "x": -34,
      "y": 6,
      "z": 13,
      "name": "Rock_Chalk"
    },
    {
      "x": -34,
      "y": 7,
      "z": 13,
      "name": "Rock_Chalk"
    },
    {
      "x": -34,
      "y": 8,
      "z": 13,
      "name": "Rock_Chalk"
    },
    {
      "x": -34,
      "y": 9,
      "z": 13,
      "name": "Rock_Chalk"
    },
    {
      "x": -34,
      "y": 10,
      "z": 13,
      "name": "Rock_Chalk"
    },
    {
      "x": -34,
      "y": 11,
      "z": 13,
      "name": "Rock_Chalk"
    },
    {
      "x": -34,
      "y": 12,
      "z": 13,
      "name": "Rock_Chalk"
    },
    {
      "x": -34,
      "y": 10,
      "z": 14,
      "name": "Rock_Chalk"
    },
    {
      "x": -34,
      "y": 7,
      "z": 15,
      "name": "Rock_Stone"
    },
    {
      "x": -34,
      "y": 8,
      "z": 15,
      "name": "Rock_Stone"
    },
    {
      "x": -34,
      "y": 9,
      "z": 15,
      "name": "Rock_Stone"
    },
    {
      "x": -34,
      "y": 10,
      "z": 15,
      "name": "Rock_Stone"
    },
    {
      "x": -34,
      "y": 7,
      "z": 16,
      "name": "Rock_Stone"
    },
    {
      "x": -34,
      "y": 8,
      "z": 16,
      "name": "Rock_Stone"
    },
    {
      "x": -34,
      "y": 9,
      "z": 16,
      "name": "Rock_Stone"
    },
    {
      "x": -34,
      "y": 10,
      "z": 16,
      "name": "Rock_Stone"
    },
    {
      "x": -33,
      "y": 9,
      "z": -5,
      "name": "Soil_Pathway"
    },
    {
      "x": -33,
      "y": 10,
      "z": -5,
      "name": "Empty"
    },
    {
      "x": -33,
      "y": 9,
      "z": -4,
      "name": "Soil_Pathway"
    },
    {
      "x": -33,
      "y": 10,
      "z": -4,
      "name": "Empty"
    },
    {
      "x": -33,
      "y": 10,
      "z": 5,
      "name": "Rock_Stone"
    },
    {
      "x": -33,
      "y": 10,
      "z": 6,
      "name": "Rock_Stone"
    },
    {
      "x": -33,
      "y": 11,
      "z": 6,
      "name": "Rock_Stone"
    },
    {
      "x": -33,
      "y": 10,
      "z": 7,
      "name": "Rock_Stone"
    },
    {
      "x": -33,
      "y": 11,
      "z": 7,
      "name": "Rock_Stone"
    },
    {
      "x": -33,
      "y": 10,
      "z": 8,
      "name": "Rock_Stone"
    },
    {
      "x": -33,
      "y": 11,
      "z": 8,
      "name": "Rock_Stone"
    },
    {
      "x": -33,
      "y": 10,
      "z": 9,
      "name": "Rock_Stone"
    },
    {
      "x": -33,
      "y": 11,
      "z": 9,
      "name": "Rock_Stone"
    },
    {
      "x": -33,
      "y": 12,
      "z": 9,
      "name": "Rock_Stone"
    },
    {
      "x": -33,
      "y": 10,
      "z": 10,
      "name": "Rock_Stone"
    },
    {
      "x": -33,
      "y": 11,
      "z": 10,
      "name": "Rock_Stone"
    },
    {
      "x": -33,
      "y": 12,
      "z": 10,
      "name": "Rock_Stone"
    },
    {
      "x": -33,
      "y": 10,
      "z": 11,
      "name": "Rock_Stone"
    },
    {
      "x": -33,
      "y": 11,
      "z": 11,
      "name": "Rock_Stone"
    },
    {
      "x": -33,
      "y": 12,
      "z": 11,
      "name": "Rock_Stone"
    },
    {
      "x": -33,
      "y": 7,
      "z": 12,
      "name": "Rock_Stone"
    },
    {
      "x": -33,
      "y": 8,
      "z": 12,
      "name": "Rock_Stone"
    },
    {
      "x": -33,
      "y": 10,
      "z": 12,
      "name": "Rock_Stone"
    },
    {
      "x": -33,
      "y": 11,
      "z": 12,
      "name": "Rock_Stone"
    },
    {
      "x": -33,
      "y": 12,
      "z": 12,
      "name": "Rock_Stone"
    },
    {
      "x": -33,
      "y": 6,
      "z": 13,
      "name": "Rock_Stone"
    },
    {
      "x": -33,
      "y": 7,
      "z": 13,
      "name": "Rock_Stone"
    },
    {
      "x": -33,
      "y": 8,
      "z": 13,
      "name": "Rock_Stone"
    },
    {
      "x": -33,
      "y": 9,
      "z": 13,
      "name": "Rock_Stone"
    },
    {
      "x": -33,
      "y": 10,
      "z": 13,
      "name": "Rock_Stone"
    },
    {
      "x": -33,
      "y": 11,
      "z": 13,
      "name": "Rock_Stone"
    },
    {
      "x": -33,
      "y": 12,
      "z": 13,
      "name": "Rock_Stone"
    },
    {
      "x": -33,
      "y": 6,
      "z": 14,
      "name": "Rock_Stone"
    },
    {
      "x": -33,
      "y": 7,
      "z": 14,
      "name": "Rock_Stone"
    },
    {
      "x": -33,
      "y": 8,
      "z": 14,
      "name": "Rock_Stone"
    },
    {
      "x": -33,
      "y": 9,
      "z": 14,
      "name": "Rock_Stone"
    },
    {
      "x": -33,
      "y": 10,
      "z": 14,
      "name": "Rock_Stone"
    },
    {
      "x": -33,
      "y": 11,
      "z": 14,
      "name": "Rock_Stone"
    },
    {
      "x": -33,
      "y": 12,
      "z": 14,
      "name": "Rock_Stone"
    },
    {
      "x": -33,
      "y": 6,
      "z": 15,
      "name": "Rock_Stone"
    },
    {
      "x": -33,
      "y": 7,
      "z": 15,
      "name": "Rock_Stone"
    },
    {
      "x": -33,
      "y": 8,
      "z": 15,
      "name": "Rock_Stone"
    },
    {
      "x": -33,
      "y": 9,
      "z": 15,
      "name": "Rock_Stone"
    },
    {
      "x": -33,
      "y": 10,
      "z": 15,
      "name": "Rock_Stone"
    },
    {
      "x": -33,
      "y": 7,
      "z": 16,
      "name": "Rock_Stone"
    },
    {
      "x": -33,
      "y": 8,
      "z": 16,
      "name": "Rock_Stone"
    },
    {
      "x": -33,
      "y": 9,
      "z": 16,
      "name": "Rock_Stone"
    },
    {
      "x": -33,
      "y": 10,
      "z": 16,
      "name": "Rock_Stone"
    },
    {
      "x": -32,
      "y": 9,
      "z": -11,
      "name": "Soil_Pathway"
    },
    {
      "x": -32,
      "y": 10,
      "z": -11,
      "name": "Empty"
    },
    {
      "x": -32,
      "y": 9,
      "z": -10,
      "name": "Soil_Pathway"
    },
    {
      "x": -32,
      "y": 10,
      "z": -10,
      "name": "Empty"
    },
    {
      "x": -32,
      "y": 9,
      "z": -9,
      "name": "Soil_Pathway"
    },
    {
      "x": -32,
      "y": 10,
      "z": -9,
      "name": "Empty"
    },
    {
      "x": -32,
      "y": 9,
      "z": -7,
      "name": "Soil_Dirt"
    },
    {
      "x": -32,
      "y": 10,
      "z": -7,
      "name": "Empty"
    },
    {
      "x": -32,
      "y": 9,
      "z": -6,
      "name": "Soil_Dirt"
    },
    {
      "x": -32,
      "y": 10,
      "z": -6,
      "name": "Empty"
    },
    {
      "x": -32,
      "y": 10,
      "z": 3,
      "name": "Rock_Stone"
    },
    {
      "x": -32,
      "y": 10,
      "z": 4,
      "name": "Rock_Stone"
    },
    {
      "x": -32,
      "y": 10,
      "z": 5,
      "name": "Rock_Stone"
    },
    {
      "x": -32,
      "y": 11,
      "z": 5,
      "name": "Rock_Stone"
    },
    {
      "x": -32,
      "y": 10,
      "z": 6,
      "name": "Rock_Stone"
    },
    {
      "x": -32,
      "y": 11,
      "z": 6,
      "name": "Rock_Stone"
    },
    {
      "x": -32,
      "y": 12,
      "z": 6,
      "name": "Rubble_Stone_Medium"
    },
    {
      "x": -32,
      "y": 10,
      "z": 7,
      "name": "Rock_Stone"
    },
    {
      "x": -32,
      "y": 11,
      "z": 7,
      "name": "Rock_Stone"
    },
    {
      "x": -32,
      "y": 10,
      "z": 8,
      "name": "Rock_Stone"
    },
    {
      "x": -32,
      "y": 11,
      "z": 8,
      "name": "Rock_Stone"
    },
    {
      "x": -32,
      "y": 12,
      "z": 8,
      "name": "Rock_Stone"
    },
    {
      "x": -32,
      "y": 10,
      "z": 9,
      "name": "Rock_Stone"
    },
    {
      "x": -32,
      "y": 11,
      "z": 9,
      "name": "Rock_Stone"
    },
    {
      "x": -32,
      "y": 12,
      "z": 9,
      "name": "Rock_Stone"
    },
    {
      "x": -32,
      "y": 13,
      "z": 9,
      "name": "Rock_Stone"
    },
    {
      "x": -32,
      "y": 10,
      "z": 10,
      "name": "Rock_Stone"
    },
    {
      "x": -32,
      "y": 11,
      "z": 10,
      "name": "Rock_Stone"
    },
    {
      "x": -32,
      "y": 12,
      "z": 10,
      "name": "Rock_Stone"
    },
    {
      "x": -32,
      "y": 13,
      "z": 10,
      "name": "Rock_Stone"
    },
    {
      "x": -32,
      "y": 14,
      "z": 10,
      "name": "Rock_Stone"
    },
    {
      "x": -32,
      "y": 7,
      "z": 11,
      "name": "Rock_Stone"
    },
    {
      "x": -32,
      "y": 8,
      "z": 11,
      "name": "Rock_Stone"
    },
    {
      "x": -32,
      "y": 10,
      "z": 11,
      "name": "Rock_Stone"
    },
    {
      "x": -32,
      "y": 11,
      "z": 11,
      "name": "Rock_Stone"
    },
    {
      "x": -32,
      "y": 12,
      "z": 11,
      "name": "Rock_Stone"
    },
    {
      "x": -32,
      "y": 13,
      "z": 11,
      "name": "Rock_Stone"
    },
    {
      "x": -32,
      "y": 14,
      "z": 11,
      "name": "Rock_Stone"
    },
    {
      "x": -32,
      "y": 6,
      "z": 12,
      "name": "Rock_Stone"
    },
    {
      "x": -32,
      "y": 7,
      "z": 12,
      "name": "Rock_Stone"
    },
    {
      "x": -32,
      "y": 8,
      "z": 12,
      "name": "Rock_Stone"
    },
    {
      "x": -32,
      "y": 9,
      "z": 12,
      "name": "Rock_Stone"
    },
    {
      "x": -32,
      "y": 10,
      "z": 12,
      "name": "Rock_Stone"
    },
    {
      "x": -32,
      "y": 11,
      "z": 12,
      "name": "Rock_Stone"
    },
    {
      "x": -32,
      "y": 12,
      "z": 12,
      "name": "Rock_Stone"
    },
    {
      "x": -32,
      "y": 13,
      "z": 12,
      "name": "Rock_Stone"
    },
    {
      "x": -32,
      "y": 14,
      "z": 12,
      "name": "Rock_Stone"
    },
    {
      "x": -32,
      "y": 6,
      "z": 13,
      "name": "Rock_Stone"
    },
    {
      "x": -32,
      "y": 7,
      "z": 13,
      "name": "Rock_Stone"
    },
    {
      "x": -32,
      "y": 8,
      "z": 13,
      "name": "Rock_Stone"
    },
    {
      "x": -32,
      "y": 9,
      "z": 13,
      "name": "Rock_Stone"
    },
    {
      "x": -32,
      "y": 10,
      "z": 13,
      "name": "Rock_Stone"
    },
    {
      "x": -32,
      "y": 11,
      "z": 13,
      "name": "Rock_Stone"
    },
    {
      "x": -32,
      "y": 12,
      "z": 13,
      "name": "Rock_Stone"
    },
    {
      "x": -32,
      "y": 13,
      "z": 13,
      "name": "Rock_Stone"
    },
    {
      "x": -32,
      "y": 5,
      "z": 14,
      "name": "Rock_Stone"
    },
    {
      "x": -32,
      "y": 6,
      "z": 14,
      "name": "Rock_Stone"
    },
    {
      "x": -32,
      "y": 7,
      "z": 14,
      "name": "Rock_Stone"
    },
    {
      "x": -32,
      "y": 8,
      "z": 14,
      "name": "Rock_Stone"
    },
    {
      "x": -32,
      "y": 9,
      "z": 14,
      "name": "Rock_Stone"
    },
    {
      "x": -32,
      "y": 10,
      "z": 14,
      "name": "Rock_Stone"
    },
    {
      "x": -32,
      "y": 11,
      "z": 14,
      "name": "Rock_Stone"
    },
    {
      "x": -32,
      "y": 12,
      "z": 14,
      "name": "Rock_Stone"
    },
    {
      "x": -32,
      "y": 5,
      "z": 15,
      "name": "Rock_Stone"
    },
    {
      "x": -32,
      "y": 6,
      "z": 15,
      "name": "Rock_Stone"
    },
    {
      "x": -32,
      "y": 7,
      "z": 15,
      "name": "Rock_Stone"
    },
    {
      "x": -32,
      "y": 8,
      "z": 15,
      "name": "Rock_Stone"
    },
    {
      "x": -32,
      "y": 9,
      "z": 15,
      "name": "Rock_Stone"
    },
    {
      "x": -32,
      "y": 10,
      "z": 15,
      "name": "Rock_Stone"
    },
    {
      "x": -32,
      "y": 11,
      "z": 15,
      "name": "Rock_Stone"
    },
    {
      "x": -32,
      "y": 6,
      "z": 16,
      "name": "Rock_Stone"
    },
    {
      "x": -32,
      "y": 7,
      "z": 16,
      "name": "Rock_Stone"
    },
    {
      "x": -32,
      "y": 8,
      "z": 16,
      "name": "Rock_Stone"
    },
    {
      "x": -32,
      "y": 9,
      "z": 16,
      "name": "Rock_Stone"
    },
    {
      "x": -32,
      "y": 10,
      "z": 16,
      "name": "Rock_Stone"
    },
    {
      "x": -32,
      "y": 9,
      "z": 17,
      "name": "Soil_Pathway"
    },
    {
      "x": -32,
      "y": 10,
      "z": 17,
      "name": "Rock_Stone_Cobble"
    },
    {
      "x": -31,
      "y": 9,
      "z": -12,
      "name": "Soil_Pathway"
    },
    {
      "x": -31,
      "y": 10,
      "z": -12,
      "name": "Empty"
    },
    {
      "x": -31,
      "y": 9,
      "z": -11,
      "name": "Soil_Pathway"
    },
    {
      "x": -31,
      "y": 10,
      "z": -11,
      "name": "Empty"
    },
    {
      "x": -31,
      "y": 9,
      "z": -10,
      "name": "Soil_Dirt"
    },
    {
      "x": -31,
      "y": 10,
      "z": -10,
      "name": "Empty"
    },
    {
      "x": -31,
      "y": 9,
      "z": -9,
      "name": "Soil_Pathway"
    },
    {
      "x": -31,
      "y": 10,
      "z": -9,
      "name": "Empty"
    },
    {
      "x": -31,
      "y": 9,
      "z": -7,
      "name": "Soil_Pathway"
    },
    {
      "x": -31,
      "y": 10,
      "z": -7,
      "name": "Empty"
    },
    {
      "x": -31,
      "y": 9,
      "z": -6,
      "name": "Soil_Pathway"
    },
    {
      "x": -31,
      "y": 10,
      "z": -6,
      "name": "Empty"
    },
    {
      "x": -31,
      "y": 9,
      "z": -5,
      "name": "Soil_Dirt"
    },
    {
      "x": -31,
      "y": 10,
      "z": -5,
      "name": "Empty"
    },
    {
      "x": -31,
      "y": 10,
      "z": 3,
      "name": "Rock_Stone"
    },
    {
      "x": -31,
      "y": 10,
      "z": 4,
      "name": "Rock_Stone"
    },
    {
      "x": -31,
      "y": 11,
      "z": 4,
      "name": "Rock_Stone"
    },
    {
      "x": -31,
      "y": 10,
      "z": 5,
      "name": "Rock_Stone"
    },
    {
      "x": -31,
      "y": 11,
      "z": 5,
      "name": "Rock_Stone"
    },
    {
      "x": -31,
      "y": 10,
      "z": 6,
      "name": "Rock_Stone"
    },
    {
      "x": -31,
      "y": 11,
      "z": 6,
      "name": "Rock_Stone"
    },
    {
      "x": -31,
      "y": 10,
      "z": 7,
      "name": "Rock_Stone"
    },
    {
      "x": -31,
      "y": 11,
      "z": 7,
      "name": "Rock_Stone"
    },
    {
      "x": -31,
      "y": 12,
      "z": 7,
      "name": "Rock_Stone"
    },
    {
      "x": -31,
      "y": 10,
      "z": 8,
      "name": "Rock_Stone"
    },
    {
      "x": -31,
      "y": 11,
      "z": 8,
      "name": "Rock_Stone"
    },
    {
      "x": -31,
      "y": 12,
      "z": 8,
      "name": "Rock_Stone"
    },
    {
      "x": -31,
      "y": 13,
      "z": 8,
      "name": "Rock_Stone"
    },
    {
      "x": -31,
      "y": 10,
      "z": 9,
      "name": "Rock_Stone"
    },
    {
      "x": -31,
      "y": 11,
      "z": 9,
      "name": "Rock_Stone"
    },
    {
      "x": -31,
      "y": 12,
      "z": 9,
      "name": "Rock_Stone"
    },
    {
      "x": -31,
      "y": 13,
      "z": 9,
      "name": "Rock_Stone"
    },
    {
      "x": -31,
      "y": 10,
      "z": 10,
      "name": "Rock_Stone"
    },
    {
      "x": -31,
      "y": 11,
      "z": 10,
      "name": "Rock_Stone"
    },
    {
      "x": -31,
      "y": 12,
      "z": 10,
      "name": "Rock_Stone"
    },
    {
      "x": -31,
      "y": 13,
      "z": 10,
      "name": "Rock_Stone"
    },
    {
      "x": -31,
      "y": 14,
      "z": 10,
      "name": "Rock_Stone"
    },
    {
      "x": -31,
      "y": 8,
      "z": 11,
      "name": "Rock_Stone"
    },
    {
      "x": -31,
      "y": 10,
      "z": 11,
      "name": "Rock_Stone"
    },
    {
      "x": -31,
      "y": 11,
      "z": 11,
      "name": "Rock_Stone"
    },
    {
      "x": -31,
      "y": 12,
      "z": 11,
      "name": "Rock_Stone"
    },
    {
      "x": -31,
      "y": 13,
      "z": 11,
      "name": "Rock_Stone"
    },
    {
      "x": -31,
      "y": 14,
      "z": 11,
      "name": "Rock_Stone"
    },
    {
      "x": -31,
      "y": 6,
      "z": 12,
      "name": "Rock_Stone"
    },
    {
      "x": -31,
      "y": 7,
      "z": 12,
      "name": "Rock_Stone"
    },
    {
      "x": -31,
      "y": 8,
      "z": 12,
      "name": "Rock_Stone"
    },
    {
      "x": -31,
      "y": 9,
      "z": 12,
      "name": "Rock_Stone"
    },
    {
      "x": -31,
      "y": 10,
      "z": 12,
      "name": "Rock_Stone"
    },
    {
      "x": -31,
      "y": 11,
      "z": 12,
      "name": "Rock_Stone"
    },
    {
      "x": -31,
      "y": 12,
      "z": 12,
      "name": "Rock_Stone"
    },
    {
      "x": -31,
      "y": 13,
      "z": 12,
      "name": "Rock_Stone"
    },
    {
      "x": -31,
      "y": 14,
      "z": 12,
      "name": "Rock_Stone"
    },
    {
      "x": -31,
      "y": 5,
      "z": 13,
      "name": "Rock_Stone"
    },
    {
      "x": -31,
      "y": 6,
      "z": 13,
      "name": "Rock_Stone"
    },
    {
      "x": -31,
      "y": 7,
      "z": 13,
      "name": "Rock_Stone"
    },
    {
      "x": -31,
      "y": 8,
      "z": 13,
      "name": "Rock_Stone"
    },
    {
      "x": -31,
      "y": 9,
      "z": 13,
      "name": "Rock_Stone"
    },
    {
      "x": -31,
      "y": 10,
      "z": 13,
      "name": "Rock_Stone"
    },
    {
      "x": -31,
      "y": 11,
      "z": 13,
      "name": "Rock_Stone"
    },
    {
      "x": -31,
      "y": 12,
      "z": 13,
      "name": "Rock_Stone"
    },
    {
      "x": -31,
      "y": 13,
      "z": 13,
      "name": "Rock_Stone"
    },
    {
      "x": -31,
      "y": 14,
      "z": 13,
      "name": "Rock_Stone"
    },
    {
      "x": -31,
      "y": 15,
      "z": 13,
      "name": "Rubble_Stone"
    },
    {
      "x": -31,
      "y": 4,
      "z": 14,
      "name": "Rock_Stone"
    },
    {
      "x": -31,
      "y": 5,
      "z": 14,
      "name": "Rock_Stone"
    },
    {
      "x": -31,
      "y": 6,
      "z": 14,
      "name": "Rock_Stone"
    },
    {
      "x": -31,
      "y": 7,
      "z": 14,
      "name": "Rock_Stone"
    },
    {
      "x": -31,
      "y": 8,
      "z": 14,
      "name": "Rock_Stone"
    },
    {
      "x": -31,
      "y": 9,
      "z": 14,
      "name": "Rock_Stone"
    },
    {
      "x": -31,
      "y": 10,
      "z": 14,
      "name": "Rock_Stone"
    },
    {
      "x": -31,
      "y": 11,
      "z": 14,
      "name": "Rock_Stone"
    },
    {
      "x": -31,
      "y": 12,
      "z": 14,
      "name": "Rock_Stone"
    },
    {
      "x": -31,
      "y": 13,
      "z": 14,
      "name": "Rock_Stone"
    },
    {
      "x": -31,
      "y": 14,
      "z": 14,
      "name": "Rock_Stone"
    },
    {
      "x": -31,
      "y": 4,
      "z": 15,
      "name": "Rock_Stone"
    },
    {
      "x": -31,
      "y": 5,
      "z": 15,
      "name": "Rock_Stone"
    },
    {
      "x": -31,
      "y": 6,
      "z": 15,
      "name": "Rock_Stone"
    },
    {
      "x": -31,
      "y": 7,
      "z": 15,
      "name": "Rock_Stone"
    },
    {
      "x": -31,
      "y": 8,
      "z": 15,
      "name": "Rock_Stone"
    },
    {
      "x": -31,
      "y": 9,
      "z": 15,
      "name": "Rock_Stone"
    },
    {
      "x": -31,
      "y": 10,
      "z": 15,
      "name": "Rock_Stone"
    },
    {
      "x": -31,
      "y": 11,
      "z": 15,
      "name": "Rock_Stone"
    },
    {
      "x": -31,
      "y": 12,
      "z": 15,
      "name": "Rock_Stone"
    },
    {
      "x": -31,
      "y": 13,
      "z": 15,
      "name": "Rock_Stone"
    },
    {
      "x": -31,
      "y": 4,
      "z": 16,
      "name": "Rock_Stone"
    },
    {
      "x": -31,
      "y": 5,
      "z": 16,
      "name": "Rock_Stone"
    },
    {
      "x": -31,
      "y": 6,
      "z": 16,
      "name": "Rock_Stone"
    },
    {
      "x": -31,
      "y": 7,
      "z": 16,
      "name": "Rock_Stone"
    },
    {
      "x": -31,
      "y": 8,
      "z": 16,
      "name": "Rock_Stone"
    },
    {
      "x": -31,
      "y": 9,
      "z": 16,
      "name": "Rock_Stone"
    },
    {
      "x": -31,
      "y": 10,
      "z": 16,
      "name": "Rock_Stone"
    },
    {
      "x": -31,
      "y": 6,
      "z": 17,
      "name": "Rock_Stone"
    },
    {
      "x": -31,
      "y": 7,
      "z": 17,
      "name": "Rock_Stone"
    },
    {
      "x": -31,
      "y": 8,
      "z": 17,
      "name": "Rock_Stone"
    },
    {
      "x": -31,
      "y": 9,
      "z": 17,
      "name": "Rock_Stone"
    },
    {
      "x": -31,
      "y": 10,
      "z": 17,
      "name": "Rock_Stone"
    },
    {
      "x": -31,
      "y": 9,
      "z": 18,
      "name": "Soil_Pathway"
    },
    {
      "x": -31,
      "y": 10,
      "z": 18,
      "name": "Rock_Stone_Cobble"
    },
    {
      "x": -31,
      "y": 11,
      "z": 18,
      "name": "Rock_Stone_Cobble"
    },
    {
      "x": -31,
      "y": 12,
      "z": 18,
      "name": "Rock_Stone_Cobble_Half"
    },
    {
      "x": -30,
      "y": 9,
      "z": -12,
      "name": "Soil_Pathway"
    },
    {
      "x": -30,
      "y": 10,
      "z": -12,
      "name": "Empty"
    },
    {
      "x": -30,
      "y": 9,
      "z": -11,
      "name": "Soil_Dirt"
    },
    {
      "x": -30,
      "y": 10,
      "z": -11,
      "name": "Empty"
    },
    {
      "x": -30,
      "y": 9,
      "z": -10,
      "name": "Soil_Dirt"
    },
    {
      "x": -30,
      "y": 10,
      "z": -10,
      "name": "Empty"
    },
    {
      "x": -30,
      "y": 9,
      "z": -9,
      "name": "Soil_Pathway"
    },
    {
      "x": -30,
      "y": 10,
      "z": -9,
      "name": "Empty"
    },
    {
      "x": -30,
      "y": 10,
      "z": -8,
      "name": "Furniture_Tavern_Barrel"
    },
    {
      "x": -30,
      "y": 9,
      "z": -7,
      "name": "Soil_Pathway"
    },
    {
      "x": -30,
      "y": 10,
      "z": -7,
      "name": "Empty"
    },
    {
      "x": -30,
      "y": 9,
      "z": -6,
      "name": "Soil_Pathway"
    },
    {
      "x": -30,
      "y": 10,
      "z": -6,
      "name": "Empty"
    },
    {
      "x": -30,
      "y": 9,
      "z": -5,
      "name": "Soil_Pathway"
    },
    {
      "x": -30,
      "y": 10,
      "z": -5,
      "name": "Empty"
    },
    {
      "x": -30,
      "y": 10,
      "z": 2,
      "name": "Rock_Stone"
    },
    {
      "x": -30,
      "y": 10,
      "z": 3,
      "name": "Rock_Stone"
    },
    {
      "x": -30,
      "y": 11,
      "z": 3,
      "name": "Rock_Stone"
    },
    {
      "x": -30,
      "y": 10,
      "z": 4,
      "name": "Rock_Stone"
    },
    {
      "x": -30,
      "y": 11,
      "z": 4,
      "name": "Rock_Stone"
    },
    {
      "x": -30,
      "y": 10,
      "z": 5,
      "name": "Rock_Stone"
    },
    {
      "x": -30,
      "y": 11,
      "z": 5,
      "name": "Rock_Stone"
    },
    {
      "x": -30,
      "y": 12,
      "z": 5,
      "name": "Rock_Stone"
    },
    {
      "x": -30,
      "y": 10,
      "z": 6,
      "name": "Rock_Stone"
    },
    {
      "x": -30,
      "y": 11,
      "z": 6,
      "name": "Rock_Stone"
    },
    {
      "x": -30,
      "y": 12,
      "z": 6,
      "name": "Rock_Stone"
    },
    {
      "x": -30,
      "y": 10,
      "z": 7,
      "name": "Rock_Stone"
    },
    {
      "x": -30,
      "y": 11,
      "z": 7,
      "name": "Rock_Stone"
    },
    {
      "x": -30,
      "y": 12,
      "z": 7,
      "name": "Rock_Stone"
    },
    {
      "x": -30,
      "y": 10,
      "z": 8,
      "name": "Rock_Stone"
    },
    {
      "x": -30,
      "y": 11,
      "z": 8,
      "name": "Rock_Stone"
    },
    {
      "x": -30,
      "y": 12,
      "z": 8,
      "name": "Rock_Stone"
    },
    {
      "x": -30,
      "y": 13,
      "z": 8,
      "name": "Rock_Stone"
    },
    {
      "x": -30,
      "y": 10,
      "z": 9,
      "name": "Rock_Stone"
    },
    {
      "x": -30,
      "y": 11,
      "z": 9,
      "name": "Rock_Stone"
    },
    {
      "x": -30,
      "y": 12,
      "z": 9,
      "name": "Rock_Stone"
    },
    {
      "x": -30,
      "y": 13,
      "z": 9,
      "name": "Rock_Stone"
    },
    {
      "x": -30,
      "y": 10,
      "z": 10,
      "name": "Rock_Stone"
    },
    {
      "x": -30,
      "y": 11,
      "z": 10,
      "name": "Rock_Stone"
    },
    {
      "x": -30,
      "y": 12,
      "z": 10,
      "name": "Rock_Stone"
    },
    {
      "x": -30,
      "y": 13,
      "z": 10,
      "name": "Rock_Stone"
    },
    {
      "x": -30,
      "y": 14,
      "z": 10,
      "name": "Rock_Stone"
    },
    {
      "x": -30,
      "y": 10,
      "z": 11,
      "name": "Rock_Stone"
    },
    {
      "x": -30,
      "y": 11,
      "z": 11,
      "name": "Rock_Stone"
    },
    {
      "x": -30,
      "y": 12,
      "z": 11,
      "name": "Rock_Stone"
    },
    {
      "x": -30,
      "y": 13,
      "z": 11,
      "name": "Rock_Stone"
    },
    {
      "x": -30,
      "y": 14,
      "z": 11,
      "name": "Rock_Stone"
    },
    {
      "x": -30,
      "y": 6,
      "z": 12,
      "name": "Rock_Stone"
    },
    {
      "x": -30,
      "y": 7,
      "z": 12,
      "name": "Rock_Stone"
    },
    {
      "x": -30,
      "y": 8,
      "z": 12,
      "name": "Rock_Stone"
    },
    {
      "x": -30,
      "y": 9,
      "z": 12,
      "name": "Rock_Stone"
    },
    {
      "x": -30,
      "y": 10,
      "z": 12,
      "name": "Rock_Stone"
    },
    {
      "x": -30,
      "y": 11,
      "z": 12,
      "name": "Rock_Stone"
    },
    {
      "x": -30,
      "y": 12,
      "z": 12,
      "name": "Rock_Stone"
    },
    {
      "x": -30,
      "y": 13,
      "z": 12,
      "name": "Rock_Stone"
    },
    {
      "x": -30,
      "y": 14,
      "z": 12,
      "name": "Rock_Stone"
    },
    {
      "x": -30,
      "y": 5,
      "z": 13,
      "name": "Rock_Stone"
    },
    {
      "x": -30,
      "y": 6,
      "z": 13,
      "name": "Rock_Stone"
    },
    {
      "x": -30,
      "y": 7,
      "z": 13,
      "name": "Rock_Stone"
    },
    {
      "x": -30,
      "y": 8,
      "z": 13,
      "name": "Rock_Stone"
    },
    {
      "x": -30,
      "y": 9,
      "z": 13,
      "name": "Rock_Stone"
    },
    {
      "x": -30,
      "y": 10,
      "z": 13,
      "name": "Rock_Stone"
    },
    {
      "x": -30,
      "y": 11,
      "z": 13,
      "name": "Rock_Stone"
    },
    {
      "x": -30,
      "y": 12,
      "z": 13,
      "name": "Rock_Stone"
    },
    {
      "x": -30,
      "y": 13,
      "z": 13,
      "name": "Rock_Stone"
    },
    {
      "x": -30,
      "y": 14,
      "z": 13,
      "name": "Rock_Stone"
    },
    {
      "x": -30,
      "y": 4,
      "z": 14,
      "name": "Rock_Stone"
    },
    {
      "x": -30,
      "y": 5,
      "z": 14,
      "name": "Rock_Stone"
    },
    {
      "x": -30,
      "y": 6,
      "z": 14,
      "name": "Rock_Stone"
    },
    {
      "x": -30,
      "y": 7,
      "z": 14,
      "name": "Rock_Stone"
    },
    {
      "x": -30,
      "y": 8,
      "z": 14,
      "name": "Rock_Stone"
    },
    {
      "x": -30,
      "y": 9,
      "z": 14,
      "name": "Rock_Stone"
    },
    {
      "x": -30,
      "y": 10,
      "z": 14,
      "name": "Rock_Stone"
    },
    {
      "x": -30,
      "y": 11,
      "z": 14,
      "name": "Rock_Stone"
    },
    {
      "x": -30,
      "y": 12,
      "z": 14,
      "name": "Rock_Stone"
    },
    {
      "x": -30,
      "y": 13,
      "z": 14,
      "name": "Rock_Stone"
    },
    {
      "x": -30,
      "y": 14,
      "z": 14,
      "name": "Rock_Stone"
    },
    {
      "x": -30,
      "y": 4,
      "z": 15,
      "name": "Rock_Stone"
    },
    {
      "x": -30,
      "y": 5,
      "z": 15,
      "name": "Rock_Stone"
    },
    {
      "x": -30,
      "y": 6,
      "z": 15,
      "name": "Rock_Stone"
    },
    {
      "x": -30,
      "y": 7,
      "z": 15,
      "name": "Rock_Stone"
    },
    {
      "x": -30,
      "y": 8,
      "z": 15,
      "name": "Rock_Stone"
    },
    {
      "x": -30,
      "y": 9,
      "z": 15,
      "name": "Rock_Stone"
    },
    {
      "x": -30,
      "y": 10,
      "z": 15,
      "name": "Rock_Stone"
    },
    {
      "x": -30,
      "y": 11,
      "z": 15,
      "name": "Rock_Stone"
    },
    {
      "x": -30,
      "y": 12,
      "z": 15,
      "name": "Rock_Stone"
    },
    {
      "x": -30,
      "y": 13,
      "z": 15,
      "name": "Rock_Stone"
    },
    {
      "x": -30,
      "y": 14,
      "z": 15,
      "name": "Rock_Stone"
    },
    {
      "x": -30,
      "y": 4,
      "z": 16,
      "name": "Rock_Stone"
    },
    {
      "x": -30,
      "y": 5,
      "z": 16,
      "name": "Rock_Stone"
    },
    {
      "x": -30,
      "y": 6,
      "z": 16,
      "name": "Rock_Stone"
    },
    {
      "x": -30,
      "y": 7,
      "z": 16,
      "name": "Rock_Stone"
    },
    {
      "x": -30,
      "y": 8,
      "z": 16,
      "name": "Rock_Stone"
    },
    {
      "x": -30,
      "y": 9,
      "z": 16,
      "name": "Rock_Stone"
    },
    {
      "x": -30,
      "y": 10,
      "z": 16,
      "name": "Rock_Stone"
    },
    {
      "x": -30,
      "y": 11,
      "z": 16,
      "name": "Rock_Stone"
    },
    {
      "x": -30,
      "y": 5,
      "z": 17,
      "name": "Rock_Stone"
    },
    {
      "x": -30,
      "y": 6,
      "z": 17,
      "name": "Rock_Stone"
    },
    {
      "x": -30,
      "y": 7,
      "z": 17,
      "name": "Rock_Stone"
    },
    {
      "x": -30,
      "y": 8,
      "z": 17,
      "name": "Rock_Stone"
    },
    {
      "x": -30,
      "y": 9,
      "z": 17,
      "name": "Rock_Stone"
    },
    {
      "x": -30,
      "y": 10,
      "z": 17,
      "name": "Rock_Stone"
    },
    {
      "x": -30,
      "y": 9,
      "z": 18,
      "name": "Soil_Pathway"
    },
    {
      "x": -30,
      "y": 10,
      "z": 18,
      "name": "Rock_Stone_Cobble"
    },
    {
      "x": -30,
      "y": 11,
      "z": 18,
      "name": "Rock_Stone_Cobble"
    },
    {
      "x": -30,
      "y": 12,
      "z": 18,
      "name": "Rock_Stone_Cobble_Half"
    },
    {
      "x": -30,
      "y": 9,
      "z": 25,
      "name": "Soil_Pathway"
    },
    {
      "x": -30,
      "y": 10,
      "z": 25,
      "name": "Empty"
    },
    {
      "x": -30,
      "y": 9,
      "z": 26,
      "name": "Soil_Pathway"
    },
    {
      "x": -30,
      "y": 10,
      "z": 26,
      "name": "Empty"
    },
    {
      "x": -29,
      "y": 9,
      "z": -12,
      "name": "Soil_Dirt"
    },
    {
      "x": -29,
      "y": 10,
      "z": -12,
      "name": "Empty"
    },
    {
      "x": -29,
      "y": 9,
      "z": -11,
      "name": "Soil_Dirt"
    },
    {
      "x": -29,
      "y": 10,
      "z": -11,
      "name": "Empty"
    },
    {
      "x": -29,
      "y": 9,
      "z": -10,
      "name": "Prefab_Spawner_Block",
      "components": {
        "Components": {
          "prefabspawner": {
            "PrefabPath": "Npc.Trork.Resource.Lumber.*",
            "FitHeightmap": false,
            "InheritSeed": true,
            "InheritHeightCondition": true
          }
        }
      },
      "rotation": 3
    },
    {
      "x": -29,
      "y": 10,
      "z": -10,
      "name": "Empty"
    },
    {
      "x": -29,
      "y": 9,
      "z": -9,
      "name": "Soil_Pathway"
    },
    {
      "x": -29,
      "y": 10,
      "z": -9,
      "name": "Empty"
    },
    {
      "x": -29,
      "y": 9,
      "z": -6,
      "name": "Soil_Pathway"
    },
    {
      "x": -29,
      "y": 10,
      "z": -6,
      "name": "Empty"
    },
    {
      "x": -29,
      "y": 9,
      "z": -5,
      "name": "Soil_Pathway"
    },
    {
      "x": -29,
      "y": 10,
      "z": -5,
      "name": "Empty"
    },
    {
      "x": -29,
      "y": 9,
      "z": -4,
      "name": "Soil_Pathway"
    },
    {
      "x": -29,
      "y": 10,
      "z": -4,
      "name": "Empty"
    },
    {
      "x": -29,
      "y": 10,
      "z": 2,
      "name": "Rock_Stone"
    },
    {
      "x": -29,
      "y": 11,
      "z": 2,
      "name": "Rock_Stone"
    },
    {
      "x": -29,
      "y": 10,
      "z": 3,
      "name": "Rock_Stone"
    },
    {
      "x": -29,
      "y": 11,
      "z": 3,
      "name": "Rock_Stone"
    },
    {
      "x": -29,
      "y": 12,
      "z": 3,
      "name": "Rubble_Stone"
    },
    {
      "x": -29,
      "y": 10,
      "z": 4,
      "name": "Rock_Stone"
    },
    {
      "x": -29,
      "y": 11,
      "z": 4,
      "name": "Rock_Stone"
    },
    {
      "x": -29,
      "y": 12,
      "z": 4,
      "name": "Rock_Stone"
    },
    {
      "x": -29,
      "y": 13,
      "z": 4,
      "name": "Furniture_Tavern_Barrel"
    },
    {
      "x": -29,
      "y": 10,
      "z": 5,
      "name": "Rock_Stone"
    },
    {
      "x": -29,
      "y": 11,
      "z": 5,
      "name": "Rock_Stone"
    },
    {
      "x": -29,
      "y": 12,
      "z": 5,
      "name": "Rock_Stone"
    },
    {
      "x": -29,
      "y": 13,
      "z": 5,
      "name": "Furniture_Village_Crate"
    },
    {
      "x": -29,
      "y": 10,
      "z": 6,
      "name": "Rock_Stone"
    },
    {
      "x": -29,
      "y": 11,
      "z": 6,
      "name": "Rock_Stone"
    },
    {
      "x": -29,
      "y": 12,
      "z": 6,
      "name": "Soil_Pathway"
    },
    {
      "x": -29,
      "y": 10,
      "z": 7,
      "name": "Rock_Stone"
    },
    {
      "x": -29,
      "y": 11,
      "z": 7,
      "name": "Rock_Stone"
    },
    {
      "x": -29,
      "y": 12,
      "z": 7,
      "name": "Rock_Stone"
    },
    {
      "x": -29,
      "y": 10,
      "z": 8,
      "name": "Rock_Stone"
    },
    {
      "x": -29,
      "y": 11,
      "z": 8,
      "name": "Rock_Stone"
    },
    {
      "x": -29,
      "y": 12,
      "z": 8,
      "name": "Rock_Stone"
    },
    {
      "x": -29,
      "y": 13,
      "z": 8,
      "name": "Rock_Stone"
    },
    {
      "x": -29,
      "y": 14,
      "z": 8,
      "name": "Rubble_Stone_Medium"
    },
    {
      "x": -29,
      "y": 10,
      "z": 9,
      "name": "Rock_Stone"
    },
    {
      "x": -29,
      "y": 11,
      "z": 9,
      "name": "Rock_Stone"
    },
    {
      "x": -29,
      "y": 12,
      "z": 9,
      "name": "Rock_Stone"
    },
    {
      "x": -29,
      "y": 13,
      "z": 9,
      "name": "Soil_Pathway"
    },
    {
      "x": -29,
      "y": 14,
      "z": 9,
      "name": "Furniture_Village_Crate"
    },
    {
      "x": -29,
      "y": 10,
      "z": 10,
      "name": "Rock_Stone"
    },
    {
      "x": -29,
      "y": 11,
      "z": 10,
      "name": "Rock_Stone"
    },
    {
      "x": -29,
      "y": 12,
      "z": 10,
      "name": "Rock_Stone"
    },
    {
      "x": -29,
      "y": 13,
      "z": 10,
      "name": "Rock_Stone"
    },
    {
      "x": -29,
      "y": 14,
      "z": 10,
      "name": "Rock_Stone"
    },
    {
      "x": -29,
      "y": 10,
      "z": 11,
      "name": "Rock_Stone"
    },
    {
      "x": -29,
      "y": 11,
      "z": 11,
      "name": "Rock_Stone"
    },
    {
      "x": -29,
      "y": 12,
      "z": 11,
      "name": "Rock_Stone"
    },
    {
      "x": -29,
      "y": 13,
      "z": 11,
      "name": "Rock_Stone"
    },
    {
      "x": -29,
      "y": 14,
      "z": 11,
      "name": "Rock_Stone"
    },
    {
      "x": -29,
      "y": 10,
      "z": 12,
      "name": "Rock_Stone"
    },
    {
      "x": -29,
      "y": 11,
      "z": 12,
      "name": "Rock_Stone"
    },
    {
      "x": -29,
      "y": 12,
      "z": 12,
      "name": "Rock_Stone"
    },
    {
      "x": -29,
      "y": 13,
      "z": 12,
      "name": "Rock_Stone"
    },
    {
      "x": -29,
      "y": 14,
      "z": 12,
      "name": "Prefab_Spawner_Block",
      "components": {
        "Components": {
          "prefabspawner": {
            "PrefabPath": "Npc.Trork.Warning.*",
            "FitHeightmap": false,
            "InheritSeed": true,
            "InheritHeightCondition": true
          }
        }
      },
      "rotation": 3
    },
    {
      "x": -29,
      "y": 4,
      "z": 13,
      "name": "Rock_Stone"
    },
    {
      "x": -29,
      "y": 5,
      "z": 13,
      "name": "Rock_Stone"
    },
    {
      "x": -29,
      "y": 6,
      "z": 13,
      "name": "Rock_Stone"
    },
    {
      "x": -29,
      "y": 7,
      "z": 13,
      "name": "Rock_Stone"
    },
    {
      "x": -29,
      "y": 8,
      "z": 13,
      "name": "Rock_Stone"
    },
    {
      "x": -29,
      "y": 9,
      "z": 13,
      "name": "Rock_Stone"
    },
    {
      "x": -29,
      "y": 10,
      "z": 13,
      "name": "Rock_Stone"
    },
    {
      "x": -29,
      "y": 11,
      "z": 13,
      "name": "Rock_Stone"
    },
    {
      "x": -29,
      "y": 12,
      "z": 13,
      "name": "Rock_Stone"
    },
    {
      "x": -29,
      "y": 13,
      "z": 13,
      "name": "Rock_Stone"
    },
    {
      "x": -29,
      "y": 14,
      "z": 13,
      "name": "Rock_Stone"
    },
    {
      "x": -29,
      "y": 4,
      "z": 14,
      "name": "Rock_Stone"
    },
    {
      "x": -29,
      "y": 5,
      "z": 14,
      "name": "Rock_Stone"
    },
    {
      "x": -29,
      "y": 6,
      "z": 14,
      "name": "Rock_Stone"
    },
    {
      "x": -29,
      "y": 7,
      "z": 14,
      "name": "Rock_Stone"
    },
    {
      "x": -29,
      "y": 8,
      "z": 14,
      "name": "Rock_Stone"
    },
    {
      "x": -29,
      "y": 9,
      "z": 14,
      "name": "Rock_Stone"
    },
    {
      "x": -29,
      "y": 10,
      "z": 14,
      "name": "Rock_Stone"
    },
    {
      "x": -29,
      "y": 11,
      "z": 14,
      "name": "Rock_Stone"
    },
    {
      "x": -29,
      "y": 12,
      "z": 14,
      "name": "Rock_Stone"
    },
    {
      "x": -29,
      "y": 13,
      "z": 14,
      "name": "Rock_Stone"
    },
    {
      "x": -29,
      "y": 14,
      "z": 14,
      "name": "Rock_Stone"
    },
    {
      "x": -29,
      "y": 15,
      "z": 14,
      "name": "Rubble_Stone_Medium"
    },
    {
      "x": -29,
      "y": 3,
      "z": 15,
      "name": "Rock_Stone"
    },
    {
      "x": -29,
      "y": 4,
      "z": 15,
      "name": "Rock_Stone"
    },
    {
      "x": -29,
      "y": 5,
      "z": 15,
      "name": "Rock_Stone"
    },
    {
      "x": -29,
      "y": 6,
      "z": 15,
      "name": "Rock_Stone"
    },
    {
      "x": -29,
      "y": 7,
      "z": 15,
      "name": "Rock_Stone"
    },
    {
      "x": -29,
      "y": 8,
      "z": 15,
      "name": "Rock_Stone"
    },
    {
      "x": -29,
      "y": 9,
      "z": 15,
      "name": "Rock_Stone"
    },
    {
      "x": -29,
      "y": 10,
      "z": 15,
      "name": "Rock_Stone"
    },
    {
      "x": -29,
      "y": 11,
      "z": 15,
      "name": "Rock_Stone"
    },
    {
      "x": -29,
      "y": 12,
      "z": 15,
      "name": "Rock_Stone"
    },
    {
      "x": -29,
      "y": 13,
      "z": 15,
      "name": "Rock_Stone"
    },
    {
      "x": -29,
      "y": 14,
      "z": 15,
      "name": "Rock_Stone"
    },
    {
      "x": -29,
      "y": 4,
      "z": 16,
      "name": "Rock_Stone"
    },
    {
      "x": -29,
      "y": 5,
      "z": 16,
      "name": "Rock_Stone"
    },
    {
      "x": -29,
      "y": 6,
      "z": 16,
      "name": "Rock_Stone"
    },
    {
      "x": -29,
      "y": 7,
      "z": 16,
      "name": "Rock_Stone"
    },
    {
      "x": -29,
      "y": 8,
      "z": 16,
      "name": "Rock_Stone"
    },
    {
      "x": -29,
      "y": 9,
      "z": 16,
      "name": "Rock_Stone"
    },
    {
      "x": -29,
      "y": 10,
      "z": 16,
      "name": "Rock_Stone"
    },
    {
      "x": -29,
      "y": 11,
      "z": 16,
      "name": "Rock_Stone"
    },
    {
      "x": -29,
      "y": 5,
      "z": 17,
      "name": "Rock_Stone"
    },
    {
      "x": -29,
      "y": 6,
      "z": 17,
      "name": "Rock_Stone"
    },
    {
      "x": -29,
      "y": 7,
      "z": 17,
      "name": "Rock_Stone"
    },
    {
      "x": -29,
      "y": 8,
      "z": 17,
      "name": "Rock_Stone"
    },
    {
      "x": -29,
      "y": 9,
      "z": 17,
      "name": "Rock_Stone"
    },
    {
      "x": -29,
      "y": 10,
      "z": 17,
      "name": "Rock_Stone"
    },
    {
      "x": -29,
      "y": 11,
      "z": 17,
      "name": "Rock_Stone"
    },
    {
      "x": -29,
      "y": 6,
      "z": 18,
      "name": "Rock_Stone"
    },
    {
      "x": -29,
      "y": 7,
      "z": 18,
      "name": "Rock_Stone"
    },
    {
      "x": -29,
      "y": 8,
      "z": 18,
      "name": "Rock_Stone"
    },
    {
      "x": -29,
      "y": 9,
      "z": 18,
      "name": "Rock_Stone"
    },
    {
      "x": -29,
      "y": 10,
      "z": 18,
      "name": "Rock_Stone"
    },
    {
      "x": -29,
      "y": 9,
      "z": 19,
      "name": "Soil_Pathway"
    },
    {
      "x": -29,
      "y": 10,
      "z": 19,
      "name": "Rock_Stone_Cobble"
    },
    {
      "x": -29,
      "y": 11,
      "z": 19,
      "name": "Rock_Stone_Cobble"
    },
    {
      "x": -29,
      "y": 12,
      "z": 19,
      "name": "Rock_Stone_Cobble_Half"
    },
    {
      "x": -29,
      "y": 9,
      "z": 25,
      "name": "Soil_Pathway"
    },
    {
      "x": -29,
      "y": 10,
      "z": 25,
      "name": "Empty"
    },
    {
      "x": -29,
      "y": 9,
      "z": 26,
      "name": "Soil_Pathway"
    },
    {
      "x": -29,
      "y": 10,
      "z": 26,
      "name": "Empty"
    },
    {
      "x": -29,
      "y": 9,
      "z": 27,
      "name": "Soil_Pathway"
    },
    {
      "x": -29,
      "y": 10,
      "z": 27,
      "name": "Empty"
    },
    {
      "x": -28,
      "y": 9,
      "z": -14,
      "name": "Soil_Pathway"
    },
    {
      "x": -28,
      "y": 10,
      "z": -14,
      "name": "Empty"
    },
    {
      "x": -28,
      "y": 9,
      "z": -13,
      "name": "Soil_Pathway"
    },
    {
      "x": -28,
      "y": 10,
      "z": -13,
      "name": "Empty"
    },
    {
      "x": -28,
      "y": 9,
      "z": -12,
      "name": "Soil_Dirt"
    },
    {
      "x": -28,
      "y": 10,
      "z": -12,
      "name": "Empty"
    },
    {
      "x": -28,
      "y": 9,
      "z": -11,
      "name": "Soil_Dirt"
    },
    {
      "x": -28,
      "y": 10,
      "z": -11,
      "name": "Empty"
    },
    {
      "x": -28,
      "y": 9,
      "z": -10,
      "name": "Soil_Dirt"
    },
    {
      "x": -28,
      "y": 10,
      "z": -10,
      "name": "Empty"
    },
    {
      "x": -28,
      "y": 9,
      "z": -9,
      "name": "Soil_Pathway"
    },
    {
      "x": -28,
      "y": 10,
      "z": -9,
      "name": "Empty"
    },
    {
      "x": -28,
      "y": 9,
      "z": -8,
      "name": "Soil_Pathway"
    },
    {
      "x": -28,
      "y": 10,
      "z": -8,
      "name": "Furniture_Village_Crate"
    },
    {
      "x": -28,
      "y": 9,
      "z": -7,
      "name": "Soil_Pathway"
    },
    {
      "x": -28,
      "y": 10,
      "z": -7,
      "name": "Furniture_Tavern_Barrel"
    },
    {
      "x": -28,
      "y": 9,
      "z": -6,
      "name": "Soil_Pathway"
    },
    {
      "x": -28,
      "y": 10,
      "z": -6,
      "name": "Empty"
    },
    {
      "x": -28,
      "y": 9,
      "z": -5,
      "name": "Soil_Pathway"
    },
    {
      "x": -28,
      "y": 10,
      "z": -5,
      "name": "Empty"
    },
    {
      "x": -28,
      "y": 9,
      "z": -4,
      "name": "Soil_Pathway"
    },
    {
      "x": -28,
      "y": 10,
      "z": -4,
      "name": "Empty"
    },
    {
      "x": -28,
      "y": 9,
      "z": 1,
      "name": "Soil_Pathway"
    },
    {
      "x": -28,
      "y": 10,
      "z": 1,
      "name": "Wood_Beech_Trunk",
      "support": 15
    },
    {
      "x": -28,
      "y": 11,
      "z": 1,
      "name": "Wood_Beech_Trunk",
      "support": 15
    },
    {
      "x": -28,
      "y": 12,
      "z": 1,
      "name": "Wood_Beech_Trunk",
      "support": 15
    },
    {
      "x": -28,
      "y": 13,
      "z": 1,
      "name": "Wood_Beech_Trunk",
      "support": 15
    },
    {
      "x": -28,
      "y": 14,
      "z": 1,
      "name": "Wood_Beech_Trunk_Full",
      "support": 15
    },
    {
      "x": -28,
      "y": 15,
      "z": 1,
      "name": "Wood_Beech_Branch_Long",
      "support": 15
    },
    {
      "x": -28,
      "y": 16,
      "z": 1,
      "name": "Survival_Trap_Spike_Wood_Large"
    },
    {
      "x": -28,
      "y": 7,
      "z": 2,
      "name": "Rock_Stone"
    },
    {
      "x": -28,
      "y": 8,
      "z": 2,
      "name": "Rock_Stone"
    },
    {
      "x": -28,
      "y": 9,
      "z": 2,
      "name": "Rock_Stone"
    },
    {
      "x": -28,
      "y": 10,
      "z": 2,
      "name": "Rock_Stone"
    },
    {
      "x": -28,
      "y": 11,
      "z": 2,
      "name": "Rock_Stone"
    },
    {
      "x": -28,
      "y": 12,
      "z": 2,
      "name": "Rock_Stone"
    },
    {
      "x": -28,
      "y": 6,
      "z": 3,
      "name": "Rock_Stone"
    },
    {
      "x": -28,
      "y": 7,
      "z": 3,
      "name": "Rock_Stone"
    },
    {
      "x": -28,
      "y": 8,
      "z": 3,
      "name": "Rock_Stone"
    },
    {
      "x": -28,
      "y": 9,
      "z": 3,
      "name": "Rock_Stone"
    },
    {
      "x": -28,
      "y": 10,
      "z": 3,
      "name": "Rock_Stone"
    },
    {
      "x": -28,
      "y": 11,
      "z": 3,
      "name": "Rock_Stone"
    },
    {
      "x": -28,
      "y": 12,
      "z": 3,
      "name": "Rock_Stone"
    },
    {
      "x": -28,
      "y": 6,
      "z": 4,
      "name": "Rock_Stone"
    },
    {
      "x": -28,
      "y": 7,
      "z": 4,
      "name": "Rock_Stone"
    },
    {
      "x": -28,
      "y": 8,
      "z": 4,
      "name": "Rock_Stone"
    },
    {
      "x": -28,
      "y": 9,
      "z": 4,
      "name": "Rock_Stone"
    },
    {
      "x": -28,
      "y": 10,
      "z": 4,
      "name": "Rock_Stone"
    },
    {
      "x": -28,
      "y": 11,
      "z": 4,
      "name": "Rock_Stone"
    },
    {
      "x": -28,
      "y": 12,
      "z": 4,
      "name": "Rock_Stone"
    },
    {
      "x": -28,
      "y": 13,
      "z": 4,
      "name": "Furniture_Tavern_Barrel"
    },
    {
      "x": -28,
      "y": 7,
      "z": 5,
      "name": "Rock_Stone"
    },
    {
      "x": -28,
      "y": 8,
      "z": 5,
      "name": "Rock_Stone"
    },
    {
      "x": -28,
      "y": 10,
      "z": 5,
      "name": "Rock_Stone"
    },
    {
      "x": -28,
      "y": 11,
      "z": 5,
      "name": "Rock_Stone"
    },
    {
      "x": -28,
      "y": 12,
      "z": 5,
      "name": "Rock_Stone"
    },
    {
      "x": -28,
      "y": 13,
      "z": 5,
      "name": "Furniture_Village_Crate"
    },
    {
      "x": -28,
      "y": 8,
      "z": 6,
      "name": "Rock_Stone"
    },
    {
      "x": -28,
      "y": 10,
      "z": 6,
      "name": "Rock_Stone"
    },
    {
      "x": -28,
      "y": 11,
      "z": 6,
      "name": "Rock_Stone"
    },
    {
      "x": -28,
      "y": 12,
      "z": 6,
      "name": "Soil_Pathway"
    },
    {
      "x": -28,
      "y": 10,
      "z": 7,
      "name": "Rock_Stone"
    },
    {
      "x": -28,
      "y": 11,
      "z": 7,
      "name": "Rock_Stone"
    },
    {
      "x": -28,
      "y": 12,
      "z": 7,
      "name": "Soil_Pathway"
    },
    {
      "x": -28,
      "y": 13,
      "z": 7,
      "name": "Soil_Pathway_Half"
    },
    {
      "x": -28,
      "y": 10,
      "z": 8,
      "name": "Rock_Stone"
    },
    {
      "x": -28,
      "y": 11,
      "z": 8,
      "name": "Rock_Stone"
    },
    {
      "x": -28,
      "y": 12,
      "z": 8,
      "name": "Rock_Stone"
    },
    {
      "x": -28,
      "y": 13,
      "z": 8,
      "name": "Soil_Pathway"
    },
    {
      "x": -28,
      "y": 10,
      "z": 9,
      "name": "Rock_Stone"
    },
    {
      "x": -28,
      "y": 11,
      "z": 9,
      "name": "Rock_Stone"
    },
    {
      "x": -28,
      "y": 12,
      "z": 9,
      "name": "Rock_Stone"
    },
    {
      "x": -28,
      "y": 13,
      "z": 9,
      "name": "Soil_Pathway"
    },
    {
      "x": -28,
      "y": 14,
      "z": 9,
      "name": "Furniture_Tavern_Barrel"
    },
    {
      "x": -28,
      "y": 10,
      "z": 10,
      "name": "Rock_Stone"
    },
    {
      "x": -28,
      "y": 11,
      "z": 10,
      "name": "Rock_Stone"
    },
    {
      "x": -28,
      "y": 12,
      "z": 10,
      "name": "Rock_Stone"
    },
    {
      "x": -28,
      "y": 13,
      "z": 10,
      "name": "Rock_Stone"
    },
    {
      "x": -28,
      "y": 14,
      "z": 10,
      "name": "Rock_Stone"
    },
    {
      "x": -28,
      "y": 10,
      "z": 11,
      "name": "Rock_Stone"
    },
    {
      "x": -28,
      "y": 11,
      "z": 11,
      "name": "Rock_Stone"
    },
    {
      "x": -28,
      "y": 12,
      "z": 11,
      "name": "Rock_Stone"
    },
    {
      "x": -28,
      "y": 13,
      "z": 11,
      "name": "Rock_Stone"
    },
    {
      "x": -28,
      "y": 14,
      "z": 11,
      "name": "Rock_Stone"
    },
    {
      "x": -28,
      "y": 10,
      "z": 12,
      "name": "Rock_Stone"
    },
    {
      "x": -28,
      "y": 11,
      "z": 12,
      "name": "Rock_Stone"
    },
    {
      "x": -28,
      "y": 12,
      "z": 12,
      "name": "Rock_Stone"
    },
    {
      "x": -28,
      "y": 13,
      "z": 12,
      "name": "Rock_Stone"
    },
    {
      "x": -28,
      "y": 14,
      "z": 12,
      "name": "Rock_Stone"
    },
    {
      "x": -28,
      "y": 4,
      "z": 13,
      "name": "Rock_Stone"
    },
    {
      "x": -28,
      "y": 5,
      "z": 13,
      "name": "Rock_Stone"
    },
    {
      "x": -28,
      "y": 6,
      "z": 13,
      "name": "Rock_Stone"
    },
    {
      "x": -28,
      "y": 7,
      "z": 13,
      "name": "Rock_Stone"
    },
    {
      "x": -28,
      "y": 8,
      "z": 13,
      "name": "Rock_Stone"
    },
    {
      "x": -28,
      "y": 9,
      "z": 13,
      "name": "Rock_Stone"
    },
    {
      "x": -28,
      "y": 10,
      "z": 13,
      "name": "Rock_Stone"
    },
    {
      "x": -28,
      "y": 11,
      "z": 13,
      "name": "Rock_Stone"
    },
    {
      "x": -28,
      "y": 12,
      "z": 13,
      "name": "Rock_Stone"
    },
    {
      "x": -28,
      "y": 13,
      "z": 13,
      "name": "Rock_Stone"
    },
    {
      "x": -28,
      "y": 14,
      "z": 13,
      "name": "Rock_Stone"
    },
    {
      "x": -28,
      "y": 3,
      "z": 14,
      "name": "Rock_Stone"
    },
    {
      "x": -28,
      "y": 4,
      "z": 14,
      "name": "Rock_Stone"
    },
    {
      "x": -28,
      "y": 5,
      "z": 14,
      "name": "Rock_Stone"
    },
    {
      "x": -28,
      "y": 6,
      "z": 14,
      "name": "Rock_Stone"
    },
    {
      "x": -28,
      "y": 7,
      "z": 14,
      "name": "Rock_Stone"
    },
    {
      "x": -28,
      "y": 8,
      "z": 14,
      "name": "Rock_Stone"
    },
    {
      "x": -28,
      "y": 9,
      "z": 14,
      "name": "Rock_Stone"
    },
    {
      "x": -28,
      "y": 10,
      "z": 14,
      "name": "Rock_Stone"
    },
    {
      "x": -28,
      "y": 11,
      "z": 14,
      "name": "Rock_Stone"
    },
    {
      "x": -28,
      "y": 12,
      "z": 14,
      "name": "Rock_Stone"
    },
    {
      "x": -28,
      "y": 13,
      "z": 14,
      "name": "Rock_Stone"
    },
    {
      "x": -28,
      "y": 14,
      "z": 14,
      "name": "Rock_Stone"
    },
    {
      "x": -28,
      "y": 3,
      "z": 15,
      "name": "Rock_Stone"
    },
    {
      "x": -28,
      "y": 4,
      "z": 15,
      "name": "Rock_Stone"
    },
    {
      "x": -28,
      "y": 5,
      "z": 15,
      "name": "Rock_Stone"
    },
    {
      "x": -28,
      "y": 6,
      "z": 15,
      "name": "Rock_Stone"
    },
    {
      "x": -28,
      "y": 7,
      "z": 15,
      "name": "Rock_Stone"
    },
    {
      "x": -28,
      "y": 8,
      "z": 15,
      "name": "Rock_Stone"
    },
    {
      "x": -28,
      "y": 9,
      "z": 15,
      "name": "Rock_Stone"
    },
    {
      "x": -28,
      "y": 10,
      "z": 15,
      "name": "Rock_Stone"
    },
    {
      "x": -28,
      "y": 11,
      "z": 15,
      "name": "Rock_Stone"
    },
    {
      "x": -28,
      "y": 12,
      "z": 15,
      "name": "Rock_Stone"
    },
    {
      "x": -28,
      "y": 13,
      "z": 15,
      "name": "Rock_Stone"
    },
    {
      "x": -28,
      "y": 3,
      "z": 16,
      "name": "Rock_Stone"
    },
    {
      "x": -28,
      "y": 4,
      "z": 16,
      "name": "Rock_Stone"
    },
    {
      "x": -28,
      "y": 5,
      "z": 16,
      "name": "Rock_Stone"
    },
    {
      "x": -28,
      "y": 6,
      "z": 16,
      "name": "Rock_Stone"
    },
    {
      "x": -28,
      "y": 7,
      "z": 16,
      "name": "Rock_Stone"
    },
    {
      "x": -28,
      "y": 8,
      "z": 16,
      "name": "Rock_Stone"
    },
    {
      "x": -28,
      "y": 9,
      "z": 16,
      "name": "Rock_Stone"
    },
    {
      "x": -28,
      "y": 10,
      "z": 16,
      "name": "Rock_Stone"
    },
    {
      "x": -28,
      "y": 11,
      "z": 16,
      "name": "Rock_Stone"
    },
    {
      "x": -28,
      "y": 12,
      "z": 16,
      "name": "Rock_Stone"
    },
    {
      "x": -28,
      "y": 13,
      "z": 16,
      "name": "Rock_Stone"
    },
    {
      "x": -28,
      "y": 4,
      "z": 17,
      "name": "Rock_Stone"
    },
    {
      "x": -28,
      "y": 5,
      "z": 17,
      "name": "Rock_Stone"
    },
    {
      "x": -28,
      "y": 6,
      "z": 17,
      "name": "Rock_Stone"
    },
    {
      "x": -28,
      "y": 7,
      "z": 17,
      "name": "Rock_Stone"
    },
    {
      "x": -28,
      "y": 8,
      "z": 17,
      "name": "Rock_Stone"
    },
    {
      "x": -28,
      "y": 9,
      "z": 17,
      "name": "Rock_Stone"
    },
    {
      "x": -28,
      "y": 10,
      "z": 17,
      "name": "Rock_Stone"
    },
    {
      "x": -28,
      "y": 11,
      "z": 17,
      "name": "Rock_Stone"
    },
    {
      "x": -28,
      "y": 5,
      "z": 18,
      "name": "Rock_Stone"
    },
    {
      "x": -28,
      "y": 6,
      "z": 18,
      "name": "Rock_Stone"
    },
    {
      "x": -28,
      "y": 7,
      "z": 18,
      "name": "Rock_Stone"
    },
    {
      "x": -28,
      "y": 8,
      "z": 18,
      "name": "Rock_Stone"
    },
    {
      "x": -28,
      "y": 9,
      "z": 18,
      "name": "Rock_Stone"
    },
    {
      "x": -28,
      "y": 10,
      "z": 18,
      "name": "Rock_Stone"
    },
    {
      "x": -28,
      "y": 9,
      "z": 19,
      "name": "Soil_Pathway"
    },
    {
      "x": -28,
      "y": 10,
      "z": 19,
      "name": "Wood_Beech_Trunk",
      "support": 15
    },
    {
      "x": -28,
      "y": 11,
      "z": 19,
      "name": "Wood_Beech_Trunk",
      "support": 15
    },
    {
      "x": -28,
      "y": 12,
      "z": 19,
      "name": "Wood_Beech_Trunk",
      "support": 15
    },
    {
      "x": -28,
      "y": 9,
      "z": 20,
      "name": "Soil_Pathway"
    },
    {
      "x": -28,
      "y": 10,
      "z": 20,
      "name": "Rock_Stone_Cobble"
    },
    {
      "x": -28,
      "y": 11,
      "z": 20,
      "name": "Rock_Stone_Cobble"
    },
    {
      "x": -28,
      "y": 9,
      "z": 24,
      "name": "Soil_Pathway"
    },
    {
      "x": -28,
      "y": 10,
      "z": 24,
      "name": "Empty"
    },
    {
      "x": -28,
      "y": 9,
      "z": 25,
      "name": "Prefab_Spawner_Block",
      "components": {
        "Components": {
          "prefabspawner": {
            "PrefabPath": "Npc.Trork.Resource.Rock.Stone.*",
            "FitHeightmap": false,
            "InheritSeed": true,
            "InheritHeightCondition": true
          }
        }
      }
    },
    {
      "x": -28,
      "y": 9,
      "z": 26,
      "name": "Soil_Pathway"
    },
    {
      "x": -28,
      "y": 10,
      "z": 26,
      "name": "Empty"
    },
    {
      "x": -28,
      "y": 9,
      "z": 27,
      "name": "Soil_Pathway"
    },
    {
      "x": -28,
      "y": 10,
      "z": 27,
      "name": "Empty"
    },
    {
      "x": -28,
      "y": 9,
      "z": 28,
      "name": "Prefab_Spawner_Block",
      "components": {
        "Components": {
          "prefabspawner": {
            "PrefabPath": "Npc.Trork.Resource.Rock.Stone.*",
            "FitHeightmap": false,
            "InheritSeed": true,
            "InheritHeightCondition": true
          }
        }
      }
    },
    {
      "x": -28,
      "y": 9,
      "z": 29,
      "name": "Soil_Dirt"
    },
    {
      "x": -28,
      "y": 10,
      "z": 29,
      "name": "Empty"
    },
    {
      "x": -27,
      "y": 9,
      "z": -14,
      "name": "Soil_Pathway"
    },
    {
      "x": -27,
      "y": 10,
      "z": -14,
      "name": "Empty"
    },
    {
      "x": -27,
      "y": 9,
      "z": -13,
      "name": "Soil_Pathway"
    },
    {
      "x": -27,
      "y": 10,
      "z": -13,
      "name": "Empty"
    },
    {
      "x": -27,
      "y": 9,
      "z": -12,
      "name": "Soil_Dirt"
    },
    {
      "x": -27,
      "y": 10,
      "z": -12,
      "name": "Empty"
    },
    {
      "x": -27,
      "y": 9,
      "z": -11,
      "name": "Soil_Dirt"
    },
    {
      "x": -27,
      "y": 10,
      "z": -11,
      "name": "Empty"
    },
    {
      "x": -27,
      "y": 9,
      "z": -10,
      "name": "Soil_Dirt"
    },
    {
      "x": -27,
      "y": 10,
      "z": -10,
      "name": "Empty"
    },
    {
      "x": -27,
      "y": 9,
      "z": -9,
      "name": "Soil_Pathway"
    },
    {
      "x": -27,
      "y": 10,
      "z": -9,
      "name": "Empty"
    },
    {
      "x": -27,
      "y": 9,
      "z": -8,
      "name": "Soil_Pathway"
    },
    {
      "x": -27,
      "y": 10,
      "z": -8,
      "name": "Furniture_Village_Crate"
    },
    {
      "x": -27,
      "y": 9,
      "z": -7,
      "name": "Soil_Pathway"
    },
    {
      "x": -27,
      "y": 10,
      "z": -7,
      "name": "Furniture_Village_Crate"
    },
    {
      "x": -27,
      "y": 9,
      "z": -6,
      "name": "Soil_Pathway"
    },
    {
      "x": -27,
      "y": 10,
      "z": -6,
      "name": "Empty"
    },
    {
      "x": -27,
      "y": 9,
      "z": -5,
      "name": "Soil_Pathway"
    },
    {
      "x": -27,
      "y": 10,
      "z": -5,
      "name": "Empty"
    },
    {
      "x": -27,
      "y": 9,
      "z": -4,
      "name": "Soil_Pathway"
    },
    {
      "x": -27,
      "y": 10,
      "z": -4,
      "name": "Empty"
    },
    {
      "x": -27,
      "y": 9,
      "z": 0,
      "name": "Soil_Pathway"
    },
    {
      "x": -27,
      "y": 10,
      "z": 0,
      "name": "Wood_Beech_Trunk",
      "support": 15
    },
    {
      "x": -27,
      "y": 11,
      "z": 0,
      "name": "Wood_Beech_Trunk",
      "support": 15
    },
    {
      "x": -27,
      "y": 12,
      "z": 0,
      "name": "Wood_Beech_Trunk",
      "support": 15
    },
    {
      "x": -27,
      "y": 13,
      "z": 0,
      "name": "Wood_Beech_Trunk",
      "support": 15
    },
    {
      "x": -27,
      "y": 14,
      "z": 0,
      "name": "Wood_Beech_Trunk",
      "support": 15
    },
    {
      "x": -27,
      "y": 15,
      "z": 0,
      "name": "Wood_Beech_Trunk_Full",
      "support": 15
    },
    {
      "x": -27,
      "y": 16,
      "z": 0,
      "name": "Wood_Beech_Branch_Long",
      "support": 15
    },
    {
      "x": -27,
      "y": 17,
      "z": 0,
      "name": "Survival_Trap_Spike_Wood_Large"
    },
    {
      "x": -27,
      "y": 6,
      "z": 1,
      "name": "Rock_Stone"
    },
    {
      "x": -27,
      "y": 7,
      "z": 1,
      "name": "Rock_Stone"
    },
    {
      "x": -27,
      "y": 8,
      "z": 1,
      "name": "Rock_Stone"
    },
    {
      "x": -27,
      "y": 9,
      "z": 1,
      "name": "Rock_Stone"
    },
    {
      "x": -27,
      "y": 10,
      "z": 1,
      "name": "Rock_Stone"
    },
    {
      "x": -27,
      "y": 11,
      "z": 1,
      "name": "Rock_Stone"
    },
    {
      "x": -27,
      "y": 12,
      "z": 1,
      "name": "Soil_Dirt_Burnt"
    },
    {
      "x": -27,
      "y": 5,
      "z": 2,
      "name": "Rock_Stone"
    },
    {
      "x": -27,
      "y": 6,
      "z": 2,
      "name": "Rock_Stone"
    },
    {
      "x": -27,
      "y": 7,
      "z": 2,
      "name": "Rock_Stone"
    },
    {
      "x": -27,
      "y": 8,
      "z": 2,
      "name": "Rock_Stone"
    },
    {
      "x": -27,
      "y": 9,
      "z": 2,
      "name": "Rock_Stone"
    },
    {
      "x": -27,
      "y": 10,
      "z": 2,
      "name": "Rock_Stone"
    },
    {
      "x": -27,
      "y": 11,
      "z": 2,
      "name": "Rock_Stone"
    },
    {
      "x": -27,
      "y": 12,
      "z": 2,
      "name": "Soil_Dirt_Burnt"
    },
    {
      "x": -27,
      "y": 5,
      "z": 3,
      "name": "Rock_Stone"
    },
    {
      "x": -27,
      "y": 6,
      "z": 3,
      "name": "Rock_Stone"
    },
    {
      "x": -27,
      "y": 7,
      "z": 3,
      "name": "Rock_Stone"
    },
    {
      "x": -27,
      "y": 8,
      "z": 3,
      "name": "Rock_Stone"
    },
    {
      "x": -27,
      "y": 9,
      "z": 3,
      "name": "Rock_Stone"
    },
    {
      "x": -27,
      "y": 10,
      "z": 3,
      "name": "Rock_Stone"
    },
    {
      "x": -27,
      "y": 11,
      "z": 3,
      "name": "Rock_Stone"
    },
    {
      "x": -27,
      "y": 12,
      "z": 3,
      "name": "Soil_Dirt_Burnt"
    },
    {
      "x": -27,
      "y": 5,
      "z": 4,
      "name": "Rock_Stone"
    },
    {
      "x": -27,
      "y": 6,
      "z": 4,
      "name": "Rock_Stone"
    },
    {
      "x": -27,
      "y": 7,
      "z": 4,
      "name": "Rock_Stone"
    },
    {
      "x": -27,
      "y": 8,
      "z": 4,
      "name": "Rock_Stone"
    },
    {
      "x": -27,
      "y": 9,
      "z": 4,
      "name": "Rock_Stone"
    },
    {
      "x": -27,
      "y": 10,
      "z": 4,
      "name": "Rock_Stone"
    },
    {
      "x": -27,
      "y": 11,
      "z": 4,
      "name": "Rock_Stone"
    },
    {
      "x": -27,
      "y": 12,
      "z": 4,
      "name": "Soil_Pathway"
    },
    {
      "x": -27,
      "y": 5,
      "z": 5,
      "name": "Rock_Stone"
    },
    {
      "x": -27,
      "y": 6,
      "z": 5,
      "name": "Rock_Stone"
    },
    {
      "x": -27,
      "y": 7,
      "z": 5,
      "name": "Rock_Stone"
    },
    {
      "x": -27,
      "y": 8,
      "z": 5,
      "name": "Rock_Stone"
    },
    {
      "x": -27,
      "y": 9,
      "z": 5,
      "name": "Rock_Stone"
    },
    {
      "x": -27,
      "y": 10,
      "z": 5,
      "name": "Rock_Stone"
    },
    {
      "x": -27,
      "y": 11,
      "z": 5,
      "name": "Rock_Stone"
    },
    {
      "x": -27,
      "y": 12,
      "z": 5,
      "name": "Soil_Pathway"
    },
    {
      "x": -27,
      "y": 6,
      "z": 6,
      "name": "Rock_Stone"
    },
    {
      "x": -27,
      "y": 7,
      "z": 6,
      "name": "Rock_Stone"
    },
    {
      "x": -27,
      "y": 8,
      "z": 6,
      "name": "Rock_Stone"
    },
    {
      "x": -27,
      "y": 9,
      "z": 6,
      "name": "Rock_Stone"
    },
    {
      "x": -27,
      "y": 10,
      "z": 6,
      "name": "Rock_Stone"
    },
    {
      "x": -27,
      "y": 11,
      "z": 6,
      "name": "Rock_Stone"
    },
    {
      "x": -27,
      "y": 12,
      "z": 6,
      "name": "Soil_Pathway"
    },
    {
      "x": -27,
      "y": 7,
      "z": 7,
      "name": "Rock_Stone"
    },
    {
      "x": -27,
      "y": 8,
      "z": 7,
      "name": "Rock_Stone"
    },
    {
      "x": -27,
      "y": 9,
      "z": 7,
      "name": "Rock_Stone"
    },
    {
      "x": -27,
      "y": 10,
      "z": 7,
      "name": "Rock_Stone"
    },
    {
      "x": -27,
      "y": 11,
      "z": 7,
      "name": "Rock_Stone"
    },
    {
      "x": -27,
      "y": 12,
      "z": 7,
      "name": "Soil_Pathway"
    },
    {
      "x": -27,
      "y": 13,
      "z": 7,
      "name": "Soil_Pathway_Half"
    },
    {
      "x": -27,
      "y": 7,
      "z": 8,
      "name": "Rock_Stone"
    },
    {
      "x": -27,
      "y": 8,
      "z": 8,
      "name": "Rock_Stone"
    },
    {
      "x": -27,
      "y": 9,
      "z": 8,
      "name": "Rock_Stone"
    },
    {
      "x": -27,
      "y": 10,
      "z": 8,
      "name": "Rock_Stone"
    },
    {
      "x": -27,
      "y": 11,
      "z": 8,
      "name": "Rock_Stone"
    },
    {
      "x": -27,
      "y": 12,
      "z": 8,
      "name": "Soil_Pathway"
    },
    {
      "x": -27,
      "y": 13,
      "z": 8,
      "name": "Soil_Pathway_Half"
    },
    {
      "x": -27,
      "y": 7,
      "z": 9,
      "name": "Rock_Stone"
    },
    {
      "x": -27,
      "y": 8,
      "z": 9,
      "name": "Rock_Stone"
    },
    {
      "x": -27,
      "y": 9,
      "z": 9,
      "name": "Rock_Stone"
    },
    {
      "x": -27,
      "y": 10,
      "z": 9,
      "name": "Rock_Stone"
    },
    {
      "x": -27,
      "y": 11,
      "z": 9,
      "name": "Rock_Stone"
    },
    {
      "x": -27,
      "y": 12,
      "z": 9,
      "name": "Rock_Stone"
    },
    {
      "x": -27,
      "y": 13,
      "z": 9,
      "name": "Soil_Pathway"
    },
    {
      "x": -27,
      "y": 6,
      "z": 10,
      "name": "Rock_Stone"
    },
    {
      "x": -27,
      "y": 7,
      "z": 10,
      "name": "Rock_Stone"
    },
    {
      "x": -27,
      "y": 8,
      "z": 10,
      "name": "Rock_Stone"
    },
    {
      "x": -27,
      "y": 9,
      "z": 10,
      "name": "Rock_Stone"
    },
    {
      "x": -27,
      "y": 10,
      "z": 10,
      "name": "Rock_Stone"
    },
    {
      "x": -27,
      "y": 11,
      "z": 10,
      "name": "Rock_Stone"
    },
    {
      "x": -27,
      "y": 12,
      "z": 10,
      "name": "Rock_Stone"
    },
    {
      "x": -27,
      "y": 13,
      "z": 10,
      "name": "Rock_Stone"
    },
    {
      "x": -27,
      "y": 5,
      "z": 11,
      "name": "Rock_Stone"
    },
    {
      "x": -27,
      "y": 6,
      "z": 11,
      "name": "Rock_Stone"
    },
    {
      "x": -27,
      "y": 7,
      "z": 11,
      "name": "Rock_Stone"
    },
    {
      "x": -27,
      "y": 8,
      "z": 11,
      "name": "Rock_Stone"
    },
    {
      "x": -27,
      "y": 9,
      "z": 11,
      "name": "Rock_Stone"
    },
    {
      "x": -27,
      "y": 10,
      "z": 11,
      "name": "Rock_Stone"
    },
    {
      "x": -27,
      "y": 11,
      "z": 11,
      "name": "Rock_Stone"
    },
    {
      "x": -27,
      "y": 12,
      "z": 11,
      "name": "Rock_Stone"
    },
    {
      "x": -27,
      "y": 13,
      "z": 11,
      "name": "Rock_Stone"
    },
    {
      "x": -27,
      "y": 14,
      "z": 11,
      "name": "Rock_Stone"
    },
    {
      "x": -27,
      "y": 4,
      "z": 12,
      "name": "Rock_Stone"
    },
    {
      "x": -27,
      "y": 5,
      "z": 12,
      "name": "Rock_Stone"
    },
    {
      "x": -27,
      "y": 6,
      "z": 12,
      "name": "Rock_Stone"
    },
    {
      "x": -27,
      "y": 7,
      "z": 12,
      "name": "Rock_Stone"
    },
    {
      "x": -27,
      "y": 8,
      "z": 12,
      "name": "Rock_Stone"
    },
    {
      "x": -27,
      "y": 9,
      "z": 12,
      "name": "Rock_Stone"
    },
    {
      "x": -27,
      "y": 10,
      "z": 12,
      "name": "Rock_Stone"
    },
    {
      "x": -27,
      "y": 11,
      "z": 12,
      "name": "Rock_Stone"
    },
    {
      "x": -27,
      "y": 12,
      "z": 12,
      "name": "Rock_Stone"
    },
    {
      "x": -27,
      "y": 13,
      "z": 12,
      "name": "Rock_Stone"
    },
    {
      "x": -27,
      "y": 14,
      "z": 12,
      "name": "Rock_Stone"
    },
    {
      "x": -27,
      "y": 4,
      "z": 13,
      "name": "Rock_Stone"
    },
    {
      "x": -27,
      "y": 5,
      "z": 13,
      "name": "Rock_Stone"
    },
    {
      "x": -27,
      "y": 6,
      "z": 13,
      "name": "Rock_Stone"
    },
    {
      "x": -27,
      "y": 7,
      "z": 13,
      "name": "Rock_Stone"
    },
    {
      "x": -27,
      "y": 8,
      "z": 13,
      "name": "Rock_Stone"
    },
    {
      "x": -27,
      "y": 9,
      "z": 13,
      "name": "Rock_Stone"
    },
    {
      "x": -27,
      "y": 10,
      "z": 13,
      "name": "Rock_Stone"
    },
    {
      "x": -27,
      "y": 11,
      "z": 13,
      "name": "Rock_Stone"
    },
    {
      "x": -27,
      "y": 12,
      "z": 13,
      "name": "Rock_Stone"
    },
    {
      "x": -27,
      "y": 13,
      "z": 13,
      "name": "Rock_Stone"
    },
    {
      "x": -27,
      "y": 14,
      "z": 13,
      "name": "Rock_Stone"
    },
    {
      "x": -27,
      "y": 3,
      "z": 14,
      "name": "Rock_Stone"
    },
    {
      "x": -27,
      "y": 4,
      "z": 14,
      "name": "Rock_Stone"
    },
    {
      "x": -27,
      "y": 5,
      "z": 14,
      "name": "Rock_Stone"
    },
    {
      "x": -27,
      "y": 6,
      "z": 14,
      "name": "Rock_Stone"
    },
    {
      "x": -27,
      "y": 7,
      "z": 14,
      "name": "Rock_Stone"
    },
    {
      "x": -27,
      "y": 8,
      "z": 14,
      "name": "Rock_Stone"
    },
    {
      "x": -27,
      "y": 9,
      "z": 14,
      "name": "Rock_Stone"
    },
    {
      "x": -27,
      "y": 10,
      "z": 14,
      "name": "Rock_Stone"
    },
    {
      "x": -27,
      "y": 11,
      "z": 14,
      "name": "Rock_Stone"
    },
    {
      "x": -27,
      "y": 12,
      "z": 14,
      "name": "Rock_Stone"
    },
    {
      "x": -27,
      "y": 13,
      "z": 14,
      "name": "Rock_Stone"
    },
    {
      "x": -27,
      "y": 14,
      "z": 14,
      "name": "Rock_Stone"
    },
    {
      "x": -27,
      "y": 3,
      "z": 15,
      "name": "Rock_Stone"
    },
    {
      "x": -27,
      "y": 4,
      "z": 15,
      "name": "Rock_Stone"
    },
    {
      "x": -27,
      "y": 5,
      "z": 15,
      "name": "Rock_Stone"
    },
    {
      "x": -27,
      "y": 6,
      "z": 15,
      "name": "Rock_Stone"
    },
    {
      "x": -27,
      "y": 7,
      "z": 15,
      "name": "Rock_Stone"
    },
    {
      "x": -27,
      "y": 8,
      "z": 15,
      "name": "Rock_Stone"
    },
    {
      "x": -27,
      "y": 9,
      "z": 15,
      "name": "Rock_Stone"
    },
    {
      "x": -27,
      "y": 10,
      "z": 15,
      "name": "Rock_Stone"
    },
    {
      "x": -27,
      "y": 11,
      "z": 15,
      "name": "Rock_Stone"
    },
    {
      "x": -27,
      "y": 12,
      "z": 15,
      "name": "Rock_Stone"
    },
    {
      "x": -27,
      "y": 13,
      "z": 15,
      "name": "Rock_Stone"
    },
    {
      "x": -27,
      "y": 3,
      "z": 16,
      "name": "Rock_Stone"
    },
    {
      "x": -27,
      "y": 4,
      "z": 16,
      "name": "Rock_Stone"
    },
    {
      "x": -27,
      "y": 5,
      "z": 16,
      "name": "Rock_Stone"
    },
    {
      "x": -27,
      "y": 6,
      "z": 16,
      "name": "Rock_Stone"
    },
    {
      "x": -27,
      "y": 7,
      "z": 16,
      "name": "Rock_Stone"
    },
    {
      "x": -27,
      "y": 8,
      "z": 16,
      "name": "Rock_Stone"
    },
    {
      "x": -27,
      "y": 9,
      "z": 16,
      "name": "Rock_Stone"
    },
    {
      "x": -27,
      "y": 10,
      "z": 16,
      "name": "Rock_Stone"
    },
    {
      "x": -27,
      "y": 11,
      "z": 16,
      "name": "Rock_Stone"
    },
    {
      "x": -27,
      "y": 12,
      "z": 16,
      "name": "Rock_Stone"
    },
    {
      "x": -27,
      "y": 13,
      "z": 16,
      "name": "Rock_Stone"
    },
    {
      "x": -27,
      "y": 4,
      "z": 17,
      "name": "Rock_Stone"
    },
    {
      "x": -27,
      "y": 5,
      "z": 17,
      "name": "Rock_Stone"
    },
    {
      "x": -27,
      "y": 6,
      "z": 17,
      "name": "Rock_Stone"
    },
    {
      "x": -27,
      "y": 7,
      "z": 17,
      "name": "Rock_Stone"
    },
    {
      "x": -27,
      "y": 8,
      "z": 17,
      "name": "Rock_Stone"
    },
    {
      "x": -27,
      "y": 9,
      "z": 17,
      "name": "Rock_Stone"
    },
    {
      "x": -27,
      "y": 10,
      "z": 17,
      "name": "Rock_Stone"
    },
    {
      "x": -27,
      "y": 11,
      "z": 17,
      "name": "Rock_Stone"
    },
    {
      "x": -27,
      "y": 12,
      "z": 17,
      "name": "Rock_Stone"
    },
    {
      "x": -27,
      "y": 13,
      "z": 17,
      "name": "Rock_Stone"
    },
    {
      "x": -27,
      "y": 5,
      "z": 18,
      "name": "Rock_Stone"
    },
    {
      "x": -27,
      "y": 6,
      "z": 18,
      "name": "Rock_Stone"
    },
    {
      "x": -27,
      "y": 7,
      "z": 18,
      "name": "Rock_Stone"
    },
    {
      "x": -27,
      "y": 8,
      "z": 18,
      "name": "Rock_Stone"
    },
    {
      "x": -27,
      "y": 9,
      "z": 18,
      "name": "Rock_Stone"
    },
    {
      "x": -27,
      "y": 10,
      "z": 18,
      "name": "Rock_Stone"
    },
    {
      "x": -27,
      "y": 6,
      "z": 19,
      "name": "Rock_Stone"
    },
    {
      "x": -27,
      "y": 7,
      "z": 19,
      "name": "Rock_Stone"
    },
    {
      "x": -27,
      "y": 8,
      "z": 19,
      "name": "Rock_Stone"
    },
    {
      "x": -27,
      "y": 9,
      "z": 19,
      "name": "Rock_Stone"
    },
    {
      "x": -27,
      "y": 10,
      "z": 19,
      "name": "Rock_Stone"
    },
    {
      "x": -27,
      "y": 9,
      "z": 20,
      "name": "Soil_Pathway"
    },
    {
      "x": -27,
      "y": 10,
      "z": 20,
      "name": "Wood_Beech_Trunk",
      "support": 15
    },
    {
      "x": -27,
      "y": 11,
      "z": 20,
      "name": "Wood_Beech_Trunk",
      "support": 15
    },
    {
      "x": -27,
      "y": 12,
      "z": 20,
      "name": "Wood_Beech_Trunk",
      "support": 15
    },
    {
      "x": -27,
      "y": 13,
      "z": 20,
      "name": "Wood_Beech_Trunk_Full",
      "support": 15
    },
    {
      "x": -27,
      "y": 14,
      "z": 20,
      "name": "Wood_Beech_Branch_Long",
      "support": 15
    },
    {
      "x": -27,
      "y": 15,
      "z": 20,
      "name": "Survival_Trap_Spike_Wood_Large"
    },
    {
      "x": -27,
      "y": 9,
      "z": 21,
      "name": "Soil_Pathway"
    },
    {
      "x": -27,
      "y": 10,
      "z": 21,
      "name": "Rock_Stone_Cobble"
    },
    {
      "x": -27,
      "y": 11,
      "z": 21,
      "name": "Rock_Stone_Cobble"
    },
    {
      "x": -27,
      "y": 9,
      "z": 24,
      "name": "Soil_Pathway"
    },
    {
      "x": -27,
      "y": 10,
      "z": 24,
      "name": "Empty"
    },
    {
      "x": -27,
      "y": 9,
      "z": 25,
      "name": "Soil_Pathway"
    },
    {
      "x": -27,
      "y": 10,
      "z": 25,
      "name": "Empty"
    },
    {
      "x": -27,
      "y": 9,
      "z": 26,
      "name": "Soil_Pathway"
    },
    {
      "x": -27,
      "y": 10,
      "z": 26,
      "name": "Empty"
    },
    {
      "x": -27,
      "y": 9,
      "z": 27,
      "name": "Soil_Pathway"
    },
    {
      "x": -27,
      "y": 10,
      "z": 27,
      "name": "Empty"
    },
    {
      "x": -27,
      "y": 9,
      "z": 28,
      "name": "Soil_Pathway"
    },
    {
      "x": -27,
      "y": 10,
      "z": 28,
      "name": "Empty"
    },
    {
      "x": -27,
      "y": 9,
      "z": 29,
      "name": "Soil_Dirt"
    },
    {
      "x": -27,
      "y": 10,
      "z": 29,
      "name": "Empty"
    },
    {
      "x": -27,
      "y": 9,
      "z": 30,
      "name": "Soil_Dirt"
    },
    {
      "x": -27,
      "y": 10,
      "z": 30,
      "name": "Empty"
    },
    {
      "x": -27,
      "y": 9,
      "z": 31,
      "name": "Soil_Pathway"
    },
    {
      "x": -27,
      "y": 10,
      "z": 31,
      "name": "Empty"
    },
    {
      "x": -26,
      "y": 7,
      "z": -24,
      "name": "Rock_Chalk"
    },
    {
      "x": -26,
      "y": 8,
      "z": -24,
      "name": "Rock_Chalk"
    },
    {
      "x": -26,
      "y": 9,
      "z": -24,
      "name": "Rock_Marble"
    },
    {
      "x": -26,
      "y": 10,
      "z": -24,
      "name": "Rock_Marble"
    },
    {
      "x": -26,
      "y": 11,
      "z": -24,
      "name": "Rock_Marble"
    },
    {
      "x": -26,
      "y": 12,
      "z": -24,
      "name": "Rock_Marble"
    },
    {
      "x": -26,
      "y": 6,
      "z": -23,
      "name": "Rock_Chalk"
    },
    {
      "x": -26,
      "y": 7,
      "z": -23,
      "name": "Rock_Chalk"
    },
    {
      "x": -26,
      "y": 8,
      "z": -23,
      "name": "Rock_Chalk"
    },
    {
      "x": -26,
      "y": 9,
      "z": -23,
      "name": "Rock_Marble"
    },
    {
      "x": -26,
      "y": 10,
      "z": -23,
      "name": "Rock_Marble"
    },
    {
      "x": -26,
      "y": 11,
      "z": -23,
      "name": "Rock_Marble"
    },
    {
      "x": -26,
      "y": 12,
      "z": -23,
      "name": "Rock_Marble"
    },
    {
      "x": -26,
      "y": 10,
      "z": -22,
      "name": "Rock_Marble"
    },
    {
      "x": -26,
      "y": 11,
      "z": -22,
      "name": "Rock_Marble"
    },
    {
      "x": -26,
      "y": 9,
      "z": -18,
      "name": "Rock_Stone"
    },
    {
      "x": -26,
      "y": 9,
      "z": -16,
      "name": "Soil_Pathway"
    },
    {
      "x": -26,
      "y": 10,
      "z": -16,
      "name": "Rock_Stone_Cobble"
    },
    {
      "x": -26,
      "y": 11,
      "z": -16,
      "name": "Rock_Stone_Cobble"
    },
    {
      "x": -26,
      "y": 9,
      "z": -15,
      "name": "Soil_Pathway"
    },
    {
      "x": -26,
      "y": 10,
      "z": -15,
      "name": "Wood_Beech_Trunk",
      "support": 15
    },
    {
      "x": -26,
      "y": 11,
      "z": -15,
      "name": "Wood_Beech_Trunk",
      "support": 15
    },
    {
      "x": -26,
      "y": 12,
      "z": -15,
      "name": "Wood_Beech_Trunk",
      "support": 15
    },
    {
      "x": -26,
      "y": 9,
      "z": -14,
      "name": "Soil_Pathway"
    },
    {
      "x": -26,
      "y": 10,
      "z": -14,
      "name": "Wood_Beech_Trunk",
      "support": 15
    },
    {
      "x": -26,
      "y": 11,
      "z": -14,
      "name": "Wood_Beech_Trunk",
      "support": 15
    },
    {
      "x": -26,
      "y": 12,
      "z": -14,
      "name": "Wood_Beech_Trunk",
      "support": 15
    },
    {
      "x": -26,
      "y": 9,
      "z": -13,
      "name": "Soil_Pathway"
    },
    {
      "x": -26,
      "y": 10,
      "z": -13,
      "name": "Wood_Beech_Trunk",
      "support": 15
    },
    {
      "x": -26,
      "y": 11,
      "z": -13,
      "name": "Wood_Beech_Trunk",
      "support": 15
    },
    {
      "x": -26,
      "y": 12,
      "z": -13,
      "name": "Wood_Beech_Trunk",
      "support": 15
    },
    {
      "x": -26,
      "y": 13,
      "z": -13,
      "name": "Wood_Beech_Trunk_Full",
      "support": 15
    },
    {
      "x": -26,
      "y": 14,
      "z": -13,
      "name": "Wood_Beech_Branch_Long",
      "support": 15
    },
    {
      "x": -26,
      "y": 15,
      "z": -13,
      "name": "Survival_Trap_Spike_Wood_Large"
    },
    {
      "x": -26,
      "y": 9,
      "z": -12,
      "name": "Soil_Dirt"
    },
    {
      "x": -26,
      "y": 10,
      "z": -12,
      "name": "Empty"
    },
    {
      "x": -26,
      "y": 9,
      "z": -11,
      "name": "Soil_Dirt"
    },
    {
      "x": -26,
      "y": 10,
      "z": -11,
      "name": "Empty"
    },
    {
      "x": -26,
      "y": 9,
      "z": -10,
      "name": "Soil_Dirt"
    },
    {
      "x": -26,
      "y": 10,
      "z": -10,
      "name": "Empty"
    },
    {
      "x": -26,
      "y": 9,
      "z": -9,
      "name": "Soil_Pathway"
    },
    {
      "x": -26,
      "y": 10,
      "z": -9,
      "name": "Empty"
    },
    {
      "x": -26,
      "y": 9,
      "z": -8,
      "name": "Soil_Pathway"
    },
    {
      "x": -26,
      "y": 10,
      "z": -8,
      "name": "Empty"
    },
    {
      "x": -26,
      "y": 9,
      "z": -7,
      "name": "Soil_Dirt"
    },
    {
      "x": -26,
      "y": 10,
      "z": -7,
      "name": "Empty"
    },
    {
      "x": -26,
      "y": 9,
      "z": -6,
      "name": "Soil_Pathway"
    },
    {
      "x": -26,
      "y": 10,
      "z": -6,
      "name": "Empty"
    },
    {
      "x": -26,
      "y": 9,
      "z": -5,
      "name": "Soil_Pathway"
    },
    {
      "x": -26,
      "y": 10,
      "z": -5,
      "name": "Empty"
    },
    {
      "x": -26,
      "y": 9,
      "z": -4,
      "name": "Soil_Pathway"
    },
    {
      "x": -26,
      "y": 10,
      "z": -4,
      "name": "Empty"
    },
    {
      "x": -26,
      "y": 9,
      "z": -3,
      "name": "Soil_Pathway"
    },
    {
      "x": -26,
      "y": 10,
      "z": -3,
      "name": "Empty"
    },
    {
      "x": -26,
      "y": 9,
      "z": -2,
      "name": "Soil_Pathway"
    },
    {
      "x": -26,
      "y": 10,
      "z": -2,
      "name": "Wood_Beech_Trunk",
      "support": 15
    },
    {
      "x": -26,
      "y": 11,
      "z": -2,
      "name": "Wood_Beech_Trunk",
      "support": 15
    },
    {
      "x": -26,
      "y": 12,
      "z": -2,
      "name": "Wood_Beech_Trunk_Full",
      "support": 15
    },
    {
      "x": -26,
      "y": 13,
      "z": -2,
      "name": "Wood_Beech_Branch_Long",
      "support": 15
    },
    {
      "x": -26,
      "y": 14,
      "z": -2,
      "name": "Survival_Trap_Spike_Wood_Large"
    },
    {
      "x": -26,
      "y": 9,
      "z": -1,
      "name": "Soil_Pathway"
    },
    {
      "x": -26,
      "y": 10,
      "z": -1,
      "name": "Wood_Beech_Trunk",
      "support": 15
    },
    {
      "x": -26,
      "y": 11,
      "z": -1,
      "name": "Wood_Beech_Trunk",
      "support": 15
    },
    {
      "x": -26,
      "y": 12,
      "z": -1,
      "name": "Wood_Beech_Trunk",
      "support": 15
    },
    {
      "x": -26,
      "y": 13,
      "z": -1,
      "name": "Wood_Beech_Trunk",
      "support": 15
    },
    {
      "x": -26,
      "y": 6,
      "z": 0,
      "name": "Rock_Stone"
    },
    {
      "x": -26,
      "y": 7,
      "z": 0,
      "name": "Rock_Stone"
    },
    {
      "x": -26,
      "y": 8,
      "z": 0,
      "name": "Rock_Stone"
    },
    {
      "x": -26,
      "y": 9,
      "z": 0,
      "name": "Rock_Stone"
    },
    {
      "x": -26,
      "y": 10,
      "z": 0,
      "name": "Rock_Stone"
    },
    {
      "x": -26,
      "y": 11,
      "z": 0,
      "name": "Rock_Stone"
    },
    {
      "x": -26,
      "y": 12,
      "z": 0,
      "name": "Soil_Dirt_Burnt"
    },
    {
      "x": -26,
      "y": 5,
      "z": 1,
      "name": "Rock_Stone"
    },
    {
      "x": -26,
      "y": 6,
      "z": 1,
      "name": "Rock_Stone"
    },
    {
      "x": -26,
      "y": 7,
      "z": 1,
      "name": "Rock_Stone"
    },
    {
      "x": -26,
      "y": 8,
      "z": 1,
      "name": "Rock_Stone"
    },
    {
      "x": -26,
      "y": 9,
      "z": 1,
      "name": "Rock_Stone"
    },
    {
      "x": -26,
      "y": 10,
      "z": 1,
      "name": "Rock_Stone"
    },
    {
      "x": -26,
      "y": 11,
      "z": 1,
      "name": "Rock_Stone"
    },
    {
      "x": -26,
      "y": 12,
      "z": 1,
      "name": "Soil_Dirt_Burnt"
    },
    {
      "x": -26,
      "y": 4,
      "z": 2,
      "name": "Rock_Stone"
    },
    {
      "x": -26,
      "y": 5,
      "z": 2,
      "name": "Rock_Stone"
    },
    {
      "x": -26,
      "y": 6,
      "z": 2,
      "name": "Rock_Stone"
    },
    {
      "x": -26,
      "y": 7,
      "z": 2,
      "name": "Rock_Stone"
    },
    {
      "x": -26,
      "y": 8,
      "z": 2,
      "name": "Rock_Stone"
    },
    {
      "x": -26,
      "y": 9,
      "z": 2,
      "name": "Rock_Stone"
    },
    {
      "x": -26,
      "y": 10,
      "z": 2,
      "name": "Rock_Stone"
    },
    {
      "x": -26,
      "y": 11,
      "z": 2,
      "name": "Rock_Stone"
    },
    {
      "x": -26,
      "y": 12,
      "z": 2,
      "name": "Prefab_Spawner_Block",
      "components": {
        "Components": {
          "prefabspawner": {
            "PrefabPath": "Npc.Trork.Fireplace.*",
            "FitHeightmap": false,
            "InheritSeed": true,
            "InheritHeightCondition": true
          }
        }
      }
    },
    {
      "x": -26,
      "y": 4,
      "z": 3,
      "name": "Rock_Stone"
    },
    {
      "x": -26,
      "y": 5,
      "z": 3,
      "name": "Rock_Stone"
    },
    {
      "x": -26,
      "y": 6,
      "z": 3,
      "name": "Rock_Stone"
    },
    {
      "x": -26,
      "y": 7,
      "z": 3,
      "name": "Rock_Stone"
    },
    {
      "x": -26,
      "y": 8,
      "z": 3,
      "name": "Rock_Stone"
    },
    {
      "x": -26,
      "y": 9,
      "z": 3,
      "name": "Rock_Stone"
    },
    {
      "x": -26,
      "y": 10,
      "z": 3,
      "name": "Rock_Stone"
    },
    {
      "x": -26,
      "y": 11,
      "z": 3,
      "name": "Rock_Stone"
    },
    {
      "x": -26,
      "y": 12,
      "z": 3,
      "name": "Soil_Dirt_Burnt"
    },
    {
      "x": -26,
      "y": 4,
      "z": 4,
      "name": "Rock_Stone"
    },
    {
      "x": -26,
      "y": 5,
      "z": 4,
      "name": "Rock_Stone"
    },
    {
      "x": -26,
      "y": 6,
      "z": 4,
      "name": "Rock_Stone"
    },
    {
      "x": -26,
      "y": 7,
      "z": 4,
      "name": "Rock_Stone"
    },
    {
      "x": -26,
      "y": 8,
      "z": 4,
      "name": "Rock_Stone"
    },
    {
      "x": -26,
      "y": 9,
      "z": 4,
      "name": "Rock_Stone"
    },
    {
      "x": -26,
      "y": 10,
      "z": 4,
      "name": "Rock_Stone"
    },
    {
      "x": -26,
      "y": 11,
      "z": 4,
      "name": "Rock_Stone"
    },
    {
      "x": -26,
      "y": 12,
      "z": 4,
      "name": "Soil_Dirt_Burnt"
    },
    {
      "x": -26,
      "y": 4,
      "z": 5,
      "name": "Rock_Stone"
    },
    {
      "x": -26,
      "y": 5,
      "z": 5,
      "name": "Rock_Stone"
    },
    {
      "x": -26,
      "y": 6,
      "z": 5,
      "name": "Rock_Stone"
    },
    {
      "x": -26,
      "y": 7,
      "z": 5,
      "name": "Rock_Stone"
    },
    {
      "x": -26,
      "y": 8,
      "z": 5,
      "name": "Rock_Stone"
    },
    {
      "x": -26,
      "y": 9,
      "z": 5,
      "name": "Rock_Stone"
    },
    {
      "x": -26,
      "y": 10,
      "z": 5,
      "name": "Rock_Stone"
    },
    {
      "x": -26,
      "y": 11,
      "z": 5,
      "name": "Rock_Stone"
    },
    {
      "x": -26,
      "y": 12,
      "z": 5,
      "name": "Soil_Pathway"
    },
    {
      "x": -26,
      "y": 4,
      "z": 6,
      "name": "Rock_Stone"
    },
    {
      "x": -26,
      "y": 5,
      "z": 6,
      "name": "Rock_Stone"
    },
    {
      "x": -26,
      "y": 6,
      "z": 6,
      "name": "Rock_Stone"
    },
    {
      "x": -26,
      "y": 7,
      "z": 6,
      "name": "Rock_Stone"
    },
    {
      "x": -26,
      "y": 8,
      "z": 6,
      "name": "Rock_Stone"
    },
    {
      "x": -26,
      "y": 9,
      "z": 6,
      "name": "Rock_Stone"
    },
    {
      "x": -26,
      "y": 10,
      "z": 6,
      "name": "Rock_Stone"
    },
    {
      "x": -26,
      "y": 11,
      "z": 6,
      "name": "Rock_Stone"
    },
    {
      "x": -26,
      "y": 12,
      "z": 6,
      "name": "Soil_Pathway"
    },
    {
      "x": -26,
      "y": 4,
      "z": 7,
      "name": "Rock_Stone"
    },
    {
      "x": -26,
      "y": 5,
      "z": 7,
      "name": "Rock_Stone"
    },
    {
      "x": -26,
      "y": 6,
      "z": 7,
      "name": "Rock_Stone"
    },
    {
      "x": -26,
      "y": 7,
      "z": 7,
      "name": "Rock_Stone"
    },
    {
      "x": -26,
      "y": 8,
      "z": 7,
      "name": "Rock_Stone"
    },
    {
      "x": -26,
      "y": 9,
      "z": 7,
      "name": "Rock_Stone"
    },
    {
      "x": -26,
      "y": 10,
      "z": 7,
      "name": "Rock_Stone"
    },
    {
      "x": -26,
      "y": 11,
      "z": 7,
      "name": "Rock_Stone"
    },
    {
      "x": -26,
      "y": 12,
      "z": 7,
      "name": "Soil_Pathway"
    },
    {
      "x": -26,
      "y": 6,
      "z": 8,
      "name": "Rock_Stone"
    },
    {
      "x": -26,
      "y": 7,
      "z": 8,
      "name": "Rock_Stone"
    },
    {
      "x": -26,
      "y": 8,
      "z": 8,
      "name": "Rock_Stone"
    },
    {
      "x": -26,
      "y": 9,
      "z": 8,
      "name": "Rock_Stone"
    },
    {
      "x": -26,
      "y": 10,
      "z": 8,
      "name": "Rock_Stone"
    },
    {
      "x": -26,
      "y": 11,
      "z": 8,
      "name": "Rock_Stone"
    },
    {
      "x": -26,
      "y": 12,
      "z": 8,
      "name": "Soil_Pathway"
    },
    {
      "x": -26,
      "y": 13,
      "z": 8,
      "name": "Soil_Pathway_Half"
    },
    {
      "x": -26,
      "y": 6,
      "z": 9,
      "name": "Rock_Stone"
    },
    {
      "x": -26,
      "y": 7,
      "z": 9,
      "name": "Rock_Stone"
    },
    {
      "x": -26,
      "y": 8,
      "z": 9,
      "name": "Rock_Stone"
    },
    {
      "x": -26,
      "y": 9,
      "z": 9,
      "name": "Rock_Stone"
    },
    {
      "x": -26,
      "y": 10,
      "z": 9,
      "name": "Rock_Stone"
    },
    {
      "x": -26,
      "y": 11,
      "z": 9,
      "name": "Rock_Stone"
    },
    {
      "x": -26,
      "y": 12,
      "z": 9,
      "name": "Rock_Stone"
    },
    {
      "x": -26,
      "y": 13,
      "z": 9,
      "name": "Soil_Pathway"
    },
    {
      "x": -26,
      "y": 5,
      "z": 10,
      "name": "Rock_Stone"
    },
    {
      "x": -26,
      "y": 6,
      "z": 10,
      "name": "Rock_Stone"
    },
    {
      "x": -26,
      "y": 7,
