{
  "version": 8,
  "blockIdVersion": 8,
  "anchorX": 0,
  "anchorY": 11,
  "anchorZ": -1,
  "blocks": [
    {
      "x": -1,
      "y": 12,
      "z": -2,
      "name": "Rock_Basalt"
    },
    {
      "x": -1,
      "y": 13,
      "z": -2,
      "name": "Rock_Basalt"
    },
    {
      "x": -1,
      "y": 8,
      "z": -1,
      "name": "Rock_Basalt_Stalactite_Large",
      "filler": 31744,
      "rotation": 8
    },
    {
      "x": -1,
      "y": 9,
      "z": -1,
      "name": "Rock_Basalt_Stalactite_Large",
      "rotation": 8
    },
    {
      "x": -1,
      "y": 10,
      "z": -1,
      "name": "Rock_Basalt"
    },
    {
      "x": -1,
      "y": 11,
      "z": -1,
      "name": "Rock_Basalt"
    },
    {
      "x": -1,
      "y": 12,
      "z": -1,
      "name": "Rock_Basalt"
    },
    {
      "x": -1,
      "y": 13,
      "z": -1,
      "name": "Rock_Basalt"
    },
    {
      "x": -1,
      "y": 14,
      "z": -1,
      "name": "Rock_Basalt"
    },
    {
      "x": -1,
      "y": 15,
      "z": -1,
      "name": "Rock_Basalt"
    },
    {
      "x": -1,
      "y": 16,
      "z": -1,
      "name": "Rock_Basalt"
    },
    {
      "x": -1,
      "y": 17,
      "z": -1,
      "name": "Rock_Basalt_Stalactite_Large"
    },
    {
      "x": -1,
      "y": 18,
      "z": -1,
      "name": "Rock_Basalt_Stalactite_Large",
      "filler": 1024
    },
    {
      "x": -1,
      "y": 11,
      "z": 0,
      "name": "Rock_Basalt"
    },
    {
      "x": -1,
      "y": 12,
      "z": 0,
      "name": "Rock_Basalt"
    },
    {
      "x": -1,
      "y": 13,
      "z": 0,
      "name": "Rock_Basalt"
    },
    {
      "x": -1,
      "y": 14,
      "z": 0,
      "name": "Rock_Basalt"
    },
    {
      "x": -1,
      "y": 15,
      "z": 0,
      "name": "Rock_Basalt_Stalactite_Small"
    },
    {
      "x": 0,
      "y": 9,
      "z": -2,
      "name": "Rock_Basalt_Stalactite_Large",
      "filler": 31744,
      "rotation": 8
    },
    {
      "x": 0,
      "y": 10,
      "z": -2,
      "name": "Rock_Basalt_Stalactite_Large",
      "rotation": 8
    },
    {
      "x": 0,
      "y": 11,
      "z": -2,
      "name": "Rock_Basalt"
    },
    {
      "x": 0,
      "y": 12,
      "z": -2,
      "name": "Rock_Basalt"
    },
    {
      "x": 0,
      "y": 13,
      "z": -2,
      "name": "Rock_Basalt"
    },
    {
      "x": 0,
      "y": 14,
      "z": -2,
      "name": "Rock_Basalt"
    },
    {
      "x": 0,
      "y": 15,
      "z": -2,
      "name": "Rock_Basalt"
    },
    {
      "x": 0,
      "y": 16,
      "z": -2,
      "name": "Rock_Basalt_Stalactite_Large"
    },
    {
      "x": 0,
      "y": 17,
      "z": -2,
      "name": "Rock_Basalt_Stalactite_Large",
      "filler": 1024
    },
    {
      "x": 0,
      "y": 6,
      "z": -1,
      "name": "Rock_Basalt_Stalactite_Large",
      "filler": 31744,
      "rotation": 8
    },
    {
      "x": 0,
      "y": 7,
      "z": -1,
      "name": "Rock_Basalt_Stalactite_Large",
      "rotation": 8
    },
    {
      "x": 0,
      "y": 8,
      "z": -1,
      "name": "Rock_Basalt"
    },
    {
      "x": 0,
      "y": 9,
      "z": -1,
      "name": "Rock_Basalt"
    },
    {
      "x": 0,
      "y": 10,
      "z": -1,
      "name": "Rock_Basalt"
    },
    {
      "x": 0,
      "y": 11,
      "z": -1,
      "name": "Rock_Basalt"
    },
    {
      "x": 0,
      "y": 12,
      "z": -1,
      "name": "Rock_Basalt"
    },
    {
      "x": 0,
      "y": 13,
      "z": -1,
      "name": "Rock_Basalt"
    },
    {
      "x": 0,
      "y": 14,
      "z": -1,
      "name": "Rock_Basalt"
    },
    {
      "x": 0,
      "y": 15,
      "z": -1,
      "name": "Rock_Basalt"
    },
    {
      "x": 0,
      "y": 16,
      "z": -1,
      "name": "Rock_Basalt"
    },
    {
      "x": 0,
      "y": 17,
      "z": -1,
      "name": "Rock_Basalt"
    },
    {
      "x": 0,
      "y": 18,
      "z": -1,
      "name": "Rock_Basalt_Stalactite_Large"
    },
    {
      "x": 0,
      "y": 19,
      "z": -1,
      "name": "Rock_Basalt_Stalactite_Large",
      "filler": 1024
    },
    {
      "x": 0,
      "y": 7,
      "z": 0,
      "name": "Rock_Basalt_Stalactite_Large",
      "filler": 31744,
      "rotation": 8
    },
    {
      "x": 0,
      "y": 8,
      "z": 0,
      "name": "Rock_Basalt_Stalactite_Large",
      "rotation": 8
    },
    {
      "x": 0,
      "y": 9,
      "z": 0,
      "name": "Rock_Basalt"
    },
    {
      "x": 0,
      "y": 10,
      "z": 0,
      "name": "Rock_Basalt"
    },
    {
      "x": 0,
      "y": 11,
      "z": 0,
      "name": "Rock_Basalt"
    },
    {
      "x": 0,
      "y": 12,
      "z": 0,
      "name": "Rock_Basalt"
    },
    {
      "x": 0,
      "y": 13,
      "z": 0,
      "name": "Rock_Basalt"
    },
    {
      "x": 0,
      "y": 14,
      "z": 0,
      "name": "Rock_Basalt"
    },
    {
      "x": 0,
      "y": 15,
      "z": 0,
      "name": "Rock_Basalt"
    },
    {
      "x": 0,
      "y": 16,
      "z": 0,
      "name": "Rock_Basalt"
    },
    {
      "x": 0,
      "y": 17,
      "z": 0,
      "name": "Rock_Basalt"
    },
    {
      "x": 0,
      "y": 18,
      "z": 0,
      "name": "Rock_Basalt_Stalactite_Small"
    },
    {
      "x": 0,
      "y": 10,
      "z": 1,
      "name": "Rock_Basalt_Stalactite_Large",
      "filler": 31744,
      "rotation": 8
    },
    {
      "x": 0,
      "y": 11,
      "z": 1,
      "name": "Rock_Basalt_Stalactite_Large",
      "rotation": 8
    },
    {
      "x": 0,
      "y": 12,
      "z": 1,
      "name": "Rock_Basalt"
    },
    {
      "x": 0,
      "y": 13,
      "z": 1,
      "name": "Rock_Basalt"
    },
    {
      "x": 0,
      "y": 14,
      "z": 1,
      "name": "Rock_Basalt_Stalactite_Large"
    },
    {
      "x": 0,
      "y": 15,
      "z": 1,
      "name": "Rock_Basalt_Stalactite_Large",
      "filler": 1024
    },
    {
      "x": 1,
      "y": 8,
      "z": -1,
      "name": "Rock_Basalt_Stalactite_Small",
      "rotation": 8
    },
    {
      "x": 1,
      "y": 9,
      "z": -1,
      "name": "Rock_Basalt"
    },
    {
      "x": 1,
      "y": 10,
      "z": -1,
      "name": "Rock_Basalt"
    },
    {
      "x": 1,
      "y": 11,
      "z": -1,
      "name": "Rock_Basalt"
    },
    {
      "x": 1,
      "y": 12,
      "z": -1,
      "name": "Rock_Basalt"
    },
    {
      "x": 1,
      "y": 13,
      "z": -1,
      "name": "Rock_Basalt"
    },
    {
      "x": 1,
      "y": 14,
      "z": -1,
      "name": "Rock_Basalt"
    },
    {
      "x": 1,
      "y": 15,
      "z": -1,
      "name": "Rock_Basalt"
    },
    {
      "x": 1,
      "y": 16,
      "z": -1,
      "name": "Rock_Basalt_Stalactite_Large"
    },
    {
      "x": 1,
      "y": 17,
      "z": -1,
      "name": "Rock_Basalt_Stalactite_Large",
      "filler": 1024
    },
    {
      "x": 1,
      "y": 10,
      "z": 0,
      "name": "Rock_Basalt_Stalactite_Small",
      "rotation": 8
    },
    {
      "x": 1,
      "y": 11,
      "z": 0,
      "name": "Rock_Basalt"
    },
    {
      "x": 1,
      "y": 12,
      "z": 0,
      "name": "Rock_Basalt"
    },
    {
      "x": 1,
      "y": 13,
      "z": 0,
      "name": "Rock_Basalt"
    },
    {
      "x": 1,
      "y": 14,
      "z": 0,
      "name": "Rock_Basalt"
    },
    {
      "x": 1,
      "y": 12,
      "z": 1,
      "name": "Rock_Basalt"
    },
    {
      "x": 1,
      "y": 13,
      "z": 1,
      "name": "Rock_Basalt"
    }
  ]
}