{
  "version": 8,
  "blockIdVersion": 8,
  "anchorX": 0,
  "anchorY": 0,
  "anchorZ": 0,
  "blocks": [
    {
      "x": -11,
      "y": 38,
      "z": 1,
      "name": "Rock_Slate"
    },
    {
      "x": -11,
      "y": 39,
      "z": 1,
      "name": "Rock_Slate"
    },
    {
      "x": -11,
      "y": 40,
      "z": 1,
      "name": "Rock_Slate"
    },
    {
      "x": -11,
      "y": 37,
      "z": 2,
      "name": "Rock_Slate"
    },
    {
      "x": -11,
      "y": 38,
      "z": 2,
      "name": "Rock_Slate"
    },
    {
      "x": -11,
      "y": 39,
      "z": 2,
      "name": "Rock_Slate"
    },
    {
      "x": -11,
      "y": 40,
      "z": 2,
      "name": "Rock_Slate"
    },
    {
      "x": -11,
      "y": 41,
      "z": 2,
      "name": "Rock_Slate"
    },
    {
      "x": -11,
      "y": 37,
      "z": 3,
      "name": "Rock_Slate"
    },
    {
      "x": -11,
      "y": 38,
      "z": 3,
      "name": "Rock_Slate"
    },
    {
      "x": -11,
      "y": 39,
      "z": 3,
      "name": "Rock_Slate"
    },
    {
      "x": -11,
      "y": 40,
      "z": 3,
      "name": "Rock_Slate"
    },
    {
      "x": -11,
      "y": 41,
      "z": 3,
      "name": "Rock_Slate"
    },
    {
      "x": -11,
      "y": 37,
      "z": 4,
      "name": "Rock_Slate"
    },
    {
      "x": -11,
      "y": 38,
      "z": 4,
      "name": "Rock_Slate"
    },
    {
      "x": -11,
      "y": 39,
      "z": 4,
      "name": "Rock_Slate"
    },
    {
      "x": -11,
      "y": 40,
      "z": 4,
      "name": "Rock_Slate"
    },
    {
      "x": -11,
      "y": 38,
      "z": 5,
      "name": "Rock_Slate"
    },
    {
      "x": -11,
      "y": 39,
      "z": 5,
      "name": "Rock_Slate"
    },
    {
      "x": -11,
      "y": 40,
      "z": 5,
      "name": "Rock_Slate"
    },
    {
      "x": -10,
      "y": 38,
      "z": -1,
      "name": "Rock_Slate"
    },
    {
      "x": -10,
      "y": 39,
      "z": -1,
      "name": "Rock_Slate"
    },
    {
      "x": -10,
      "y": 40,
      "z": -1,
      "name": "Rock_Slate"
    },
    {
      "x": -10,
      "y": 37,
      "z": 0,
      "name": "Rock_Slate"
    },
    {
      "x": -10,
      "y": 38,
      "z": 0,
      "name": "Rock_Slate"
    },
    {
      "x": -10,
      "y": 39,
      "z": 0,
      "name": "Rock_Slate"
    },
    {
      "x": -10,
      "y": 40,
      "z": 0,
      "name": "Rock_Slate"
    },
    {
      "x": -10,
      "y": 41,
      "z": 0,
      "name": "Rock_Slate"
    },
    {
      "x": -10,
      "y": 36,
      "z": 1,
      "name": "Rock_Slate"
    },
    {
      "x": -10,
      "y": 37,
      "z": 1,
      "name": "Rock_Slate"
    },
    {
      "x": -10,
      "y": 38,
      "z": 1,
      "name": "Rock_Slate"
    },
    {
      "x": -10,
      "y": 39,
      "z": 1,
      "name": "Rock_Slate"
    },
    {
      "x": -10,
      "y": 40,
      "z": 1,
      "name": "Rock_Slate"
    },
    {
      "x": -10,
      "y": 41,
      "z": 1,
      "name": "Rock_Slate"
    },
    {
      "x": -10,
      "y": 42,
      "z": 1,
      "name": "Rock_Slate"
    },
    {
      "x": -10,
      "y": 35,
      "z": 2,
      "name": "Rock_Slate"
    },
    {
      "x": -10,
      "y": 36,
      "z": 2,
      "name": "Rock_Slate"
    },
    {
      "x": -10,
      "y": 37,
      "z": 2,
      "name": "Rock_Slate"
    },
    {
      "x": -10,
      "y": 38,
      "z": 2,
      "name": "Rock_Slate"
    },
    {
      "x": -10,
      "y": 39,
      "z": 2,
      "name": "Rock_Slate"
    },
    {
      "x": -10,
      "y": 40,
      "z": 2,
      "name": "Rock_Slate"
    },
    {
      "x": -10,
      "y": 41,
      "z": 2,
      "name": "Rock_Slate"
    },
    {
      "x": -10,
      "y": 42,
      "z": 2,
      "name": "Rock_Slate"
    },
    {
      "x": -10,
      "y": 35,
      "z": 3,
      "name": "Rock_Slate"
    },
    {
      "x": -10,
      "y": 36,
      "z": 3,
      "name": "Rock_Slate"
    },
    {
      "x": -10,
      "y": 37,
      "z": 3,
      "name": "Rock_Slate"
    },
    {
      "x": -10,
      "y": 38,
      "z": 3,
      "name": "Rock_Slate"
    },
    {
      "x": -10,
      "y": 39,
      "z": 3,
      "name": "Rock_Slate"
    },
    {
      "x": -10,
      "y": 40,
      "z": 3,
      "name": "Rock_Slate"
    },
    {
      "x": -10,
      "y": 41,
      "z": 3,
      "name": "Rock_Slate"
    },
    {
      "x": -10,
      "y": 42,
      "z": 3,
      "name": "Rock_Slate"
    },
    {
      "x": -10,
      "y": 35,
      "z": 4,
      "name": "Rock_Slate"
    },
    {
      "x": -10,
      "y": 36,
      "z": 4,
      "name": "Rock_Slate"
    },
    {
      "x": -10,
      "y": 37,
      "z": 4,
      "name": "Rock_Slate"
    },
    {
      "x": -10,
      "y": 38,
      "z": 4,
      "name": "Rock_Slate"
    },
    {
      "x": -10,
      "y": 39,
      "z": 4,
      "name": "Rock_Slate"
    },
    {
      "x": -10,
      "y": 40,
      "z": 4,
      "name": "Rock_Slate"
    },
    {
      "x": -10,
      "y": 41,
      "z": 4,
      "name": "Rock_Slate"
    },
    {
      "x": -10,
      "y": 42,
      "z": 4,
      "name": "Rock_Slate"
    },
    {
      "x": -10,
      "y": 35,
      "z": 5,
      "name": "Rock_Slate"
    },
    {
      "x": -10,
      "y": 36,
      "z": 5,
      "name": "Rock_Slate"
    },
    {
      "x": -10,
      "y": 37,
      "z": 5,
      "name": "Rock_Slate"
    },
    {
      "x": -10,
      "y": 38,
      "z": 5,
      "name": "Rock_Slate"
    },
    {
      "x": -10,
      "y": 39,
      "z": 5,
      "name": "Rock_Slate"
    },
    {
      "x": -10,
      "y": 40,
      "z": 5,
      "name": "Rock_Slate"
    },
    {
      "x": -10,
      "y": 41,
      "z": 5,
      "name": "Rock_Slate"
    },
    {
      "x": -10,
      "y": 42,
      "z": 5,
      "name": "Rock_Slate"
    },
    {
      "x": -10,
      "y": 36,
      "z": 6,
      "name": "Rock_Slate"
    },
    {
      "x": -10,
      "y": 37,
      "z": 6,
      "name": "Rock_Slate"
    },
    {
      "x": -10,
      "y": 38,
      "z": 6,
      "name": "Rock_Slate"
    },
    {
      "x": -10,
      "y": 39,
      "z": 6,
      "name": "Rock_Slate"
    },
    {
      "x": -10,
      "y": 40,
      "z": 6,
      "name": "Rock_Slate"
    },
    {
      "x": -10,
      "y": 41,
      "z": 6,
      "name": "Rock_Slate"
    },
    {
      "x": -10,
      "y": 37,
      "z": 7,
      "name": "Rock_Slate"
    },
    {
      "x": -10,
      "y": 38,
      "z": 7,
      "name": "Rock_Slate"
    },
    {
      "x": -10,
      "y": 39,
      "z": 7,
      "name": "Rock_Slate"
    },
    {
      "x": -10,
      "y": 40,
      "z": 7,
      "name": "Rock_Slate"
    },
    {
      "x": -9,
      "y": 38,
      "z": -2,
      "name": "Rock_Slate"
    },
    {
      "x": -9,
      "y": 39,
      "z": -2,
      "name": "Rock_Slate"
    },
    {
      "x": -9,
      "y": 40,
      "z": -2,
      "name": "Rock_Slate"
    },
    {
      "x": -9,
      "y": 37,
      "z": -1,
      "name": "Rock_Slate"
    },
    {
      "x": -9,
      "y": 38,
      "z": -1,
      "name": "Rock_Slate"
    },
    {
      "x": -9,
      "y": 39,
      "z": -1,
      "name": "Rock_Slate"
    },
    {
      "x": -9,
      "y": 40,
      "z": -1,
      "name": "Rock_Slate"
    },
    {
      "x": -9,
      "y": 41,
      "z": -1,
      "name": "Rock_Slate"
    },
    {
      "x": -9,
      "y": 34,
      "z": 0,
      "name": "Rock_Crystal_Red_Small",
      "components": {
        "Components": {
          "FarmingBlock": {}
        }
      },
      "rotation": 7
    },
    {
      "x": -9,
      "y": 35,
      "z": 0,
      "name": "Rock_Crystal_Red_Block"
    },
    {
      "x": -9,
      "y": 36,
      "z": 0,
      "name": "Rock_Slate"
    },
    {
      "x": -9,
      "y": 37,
      "z": 0,
      "name": "Rock_Slate"
    },
    {
      "x": -9,
      "y": 38,
      "z": 0,
      "name": "Rock_Slate"
    },
    {
      "x": -9,
      "y": 39,
      "z": 0,
      "name": "Rock_Slate"
    },
    {
      "x": -9,
      "y": 40,
      "z": 0,
      "name": "Rock_Slate"
    },
    {
      "x": -9,
      "y": 41,
      "z": 0,
      "name": "Rock_Slate"
    },
    {
      "x": -9,
      "y": 42,
      "z": 0,
      "name": "Rock_Slate"
    },
    {
      "x": -9,
      "y": 33,
      "z": 1,
      "name": "Rock_Crystal_Red_Small",
      "components": {
        "Components": {
          "FarmingBlock": {}
        }
      },
      "rotation": 7
    },
    {
      "x": -9,
      "y": 34,
      "z": 1,
      "name": "Rock_Crystal_Red_Block"
    },
    {
      "x": -9,
      "y": 35,
      "z": 1,
      "name": "Rock_Crystal_Red_Block"
    },
    {
      "x": -9,
      "y": 36,
      "z": 1,
      "name": "Rock_Slate"
    },
    {
      "x": -9,
      "y": 37,
      "z": 1,
      "name": "Rock_Slate"
    },
    {
      "x": -9,
      "y": 38,
      "z": 1,
      "name": "Rock_Slate"
    },
    {
      "x": -9,
      "y": 39,
      "z": 1,
      "name": "Rock_Slate"
    },
    {
      "x": -9,
      "y": 40,
      "z": 1,
      "name": "Rock_Slate"
    },
    {
      "x": -9,
      "y": 41,
      "z": 1,
      "name": "Rock_Slate"
    },
    {
      "x": -9,
      "y": 42,
      "z": 1,
      "name": "Rock_Slate"
    },
    {
      "x": -9,
      "y": 43,
      "z": 1,
      "name": "Rock_Slate"
    },
    {
      "x": -9,
      "y": 33,
      "z": 2,
      "name": "Rock_Crystal_Red_Block"
    },
    {
      "x": -9,
      "y": 34,
      "z": 2,
      "name": "Rock_Slate"
    },
    {
      "x": -9,
      "y": 35,
      "z": 2,
      "name": "Rock_Slate"
    },
    {
      "x": -9,
      "y": 36,
      "z": 2,
      "name": "Rock_Slate"
    },
    {
      "x": -9,
      "y": 37,
      "z": 2,
      "name": "Rock_Slate"
    },
    {
      "x": -9,
      "y": 38,
      "z": 2,
      "name": "Rock_Slate"
    },
    {
      "x": -9,
      "y": 39,
      "z": 2,
      "name": "Rock_Slate"
    },
    {
      "x": -9,
      "y": 40,
      "z": 2,
      "name": "Rock_Slate"
    },
    {
      "x": -9,
      "y": 41,
      "z": 2,
      "name": "Rock_Slate"
    },
    {
      "x": -9,
      "y": 42,
      "z": 2,
      "name": "Rock_Slate"
    },
    {
      "x": -9,
      "y": 43,
      "z": 2,
      "name": "Rock_Slate"
    },
    {
      "x": -9,
      "y": 33,
      "z": 3,
      "name": "Rock_Slate"
    },
    {
      "x": -9,
      "y": 34,
      "z": 3,
      "name": "Rock_Slate"
    },
    {
      "x": -9,
      "y": 35,
      "z": 3,
      "name": "Rock_Slate"
    },
    {
      "x": -9,
      "y": 36,
      "z": 3,
      "name": "Rock_Slate"
    },
    {
      "x": -9,
      "y": 37,
      "z": 3,
      "name": "Rock_Slate"
    },
    {
      "x": -9,
      "y": 38,
      "z": 3,
      "name": "Rock_Slate"
    },
    {
      "x": -9,
      "y": 39,
      "z": 3,
      "name": "Rock_Slate"
    },
    {
      "x": -9,
      "y": 40,
      "z": 3,
      "name": "Rock_Slate"
    },
    {
      "x": -9,
      "y": 41,
      "z": 3,
      "name": "Rock_Slate"
    },
    {
      "x": -9,
      "y": 42,
      "z": 3,
      "name": "Rock_Slate"
    },
    {
      "x": -9,
      "y": 43,
      "z": 3,
      "name": "Rock_Slate"
    },
    {
      "x": -9,
      "y": 33,
      "z": 4,
      "name": "Rock_Slate"
    },
    {
      "x": -9,
      "y": 34,
      "z": 4,
      "name": "Rock_Slate"
    },
    {
      "x": -9,
      "y": 35,
      "z": 4,
      "name": "Rock_Slate"
    },
    {
      "x": -9,
      "y": 36,
      "z": 4,
      "name": "Rock_Slate"
    },
    {
      "x": -9,
      "y": 37,
      "z": 4,
      "name": "Rock_Slate"
    },
    {
      "x": -9,
      "y": 38,
      "z": 4,
      "name": "Rock_Slate"
    },
    {
      "x": -9,
      "y": 39,
      "z": 4,
      "name": "Rock_Slate"
    },
    {
      "x": -9,
      "y": 40,
      "z": 4,
      "name": "Rock_Slate"
    },
    {
      "x": -9,
      "y": 41,
      "z": 4,
      "name": "Rock_Slate"
    },
    {
      "x": -9,
      "y": 42,
      "z": 4,
      "name": "Rock_Slate"
    },
    {
      "x": -9,
      "y": 43,
      "z": 4,
      "name": "Rock_Slate"
    },
    {
      "x": -9,
      "y": 33,
      "z": 5,
      "name": "Rock_Slate"
    },
    {
      "x": -9,
      "y": 34,
      "z": 5,
      "name": "Rock_Slate"
    },
    {
      "x": -9,
      "y": 35,
      "z": 5,
      "name": "Rock_Slate"
    },
    {
      "x": -9,
      "y": 36,
      "z": 5,
      "name": "Rock_Slate"
    },
    {
      "x": -9,
      "y": 37,
      "z": 5,
      "name": "Rock_Slate"
    },
    {
      "x": -9,
      "y": 38,
      "z": 5,
      "name": "Rock_Slate"
    },
    {
      "x": -9,
      "y": 39,
      "z": 5,
      "name": "Rock_Slate"
    },
    {
      "x": -9,
      "y": 40,
      "z": 5,
      "name": "Rock_Slate"
    },
    {
      "x": -9,
      "y": 41,
      "z": 5,
      "name": "Rock_Slate"
    },
    {
      "x": -9,
      "y": 42,
      "z": 5,
      "name": "Rock_Slate"
    },
    {
      "x": -9,
      "y": 43,
      "z": 5,
      "name": "Rock_Slate"
    },
    {
      "x": -9,
      "y": 34,
      "z": 6,
      "name": "Rock_Slate"
    },
    {
      "x": -9,
      "y": 35,
      "z": 6,
      "name": "Rock_Slate"
    },
    {
      "x": -9,
      "y": 36,
      "z": 6,
      "name": "Rock_Slate"
    },
    {
      "x": -9,
      "y": 37,
      "z": 6,
      "name": "Rock_Slate"
    },
    {
      "x": -9,
      "y": 38,
      "z": 6,
      "name": "Rock_Slate"
    },
    {
      "x": -9,
      "y": 39,
      "z": 6,
      "name": "Rock_Slate"
    },
    {
      "x": -9,
      "y": 40,
      "z": 6,
      "name": "Rock_Slate"
    },
    {
      "x": -9,
      "y": 41,
      "z": 6,
      "name": "Rock_Slate"
    },
    {
      "x": -9,
      "y": 42,
      "z": 6,
      "name": "Rock_Slate"
    },
    {
      "x": -9,
      "y": 35,
      "z": 7,
      "name": "Rock_Slate"
    },
    {
      "x": -9,
      "y": 36,
      "z": 7,
      "name": "Rock_Slate"
    },
    {
      "x": -9,
      "y": 37,
      "z": 7,
      "name": "Rock_Slate"
    },
    {
      "x": -9,
      "y": 38,
      "z": 7,
      "name": "Rock_Slate"
    },
    {
      "x": -9,
      "y": 39,
      "z": 7,
      "name": "Rock_Slate"
    },
    {
      "x": -9,
      "y": 40,
      "z": 7,
      "name": "Rock_Slate"
    },
    {
      "x": -9,
      "y": 41,
      "z": 7,
      "name": "Rock_Slate"
    },
    {
      "x": -9,
      "y": 42,
      "z": 7,
      "name": "Rock_Slate"
    },
    {
      "x": -9,
      "y": 36,
      "z": 8,
      "name": "Rock_Slate"
    },
    {
      "x": -9,
      "y": 37,
      "z": 8,
      "name": "Rock_Slate"
    },
    {
      "x": -9,
      "y": 38,
      "z": 8,
      "name": "Rock_Slate"
    },
    {
      "x": -9,
      "y": 39,
      "z": 8,
      "name": "Rock_Slate"
    },
    {
      "x": -9,
      "y": 40,
      "z": 8,
      "name": "Rock_Slate"
    },
    {
      "x": -9,
      "y": 41,
      "z": 8,
      "name": "Rock_Slate"
    },
    {
      "x": -8,
      "y": 39,
      "z": -3,
      "name": "Rock_Slate"
    },
    {
      "x": -8,
      "y": 40,
      "z": -3,
      "name": "Rock_Slate"
    },
    {
      "x": -8,
      "y": 37,
      "z": -2,
      "name": "Rock_Slate"
    },
    {
      "x": -8,
      "y": 38,
      "z": -2,
      "name": "Rock_Slate"
    },
    {
      "x": -8,
      "y": 39,
      "z": -2,
      "name": "Rock_Slate"
    },
    {
      "x": -8,
      "y": 40,
      "z": -2,
      "name": "Rock_Slate"
    },
    {
      "x": -8,
      "y": 41,
      "z": -2,
      "name": "Rock_Slate"
    },
    {
      "x": -8,
      "y": 35,
      "z": -1,
      "name": "Rock_Crystal_Red_Block"
    },
    {
      "x": -8,
      "y": 36,
      "z": -1,
      "name": "Rock_Slate"
    },
    {
      "x": -8,
      "y": 37,
      "z": -1,
      "name": "Rock_Slate"
    },
    {
      "x": -8,
      "y": 38,
      "z": -1,
      "name": "Rock_Slate"
    },
    {
      "x": -8,
      "y": 39,
      "z": -1,
      "name": "Rock_Slate"
    },
    {
      "x": -8,
      "y": 40,
      "z": -1,
      "name": "Rock_Slate"
    },
    {
      "x": -8,
      "y": 41,
      "z": -1,
      "name": "Rock_Slate"
    },
    {
      "x": -8,
      "y": 42,
      "z": -1,
      "name": "Rock_Slate"
    },
    {
      "x": -8,
      "y": 32,
      "z": 0,
      "name": "Rock_Crystal_Red_Large",
      "rotation": 7
    },
    {
      "x": -8,
      "y": 33,
      "z": 0,
      "name": "Rock_Crystal_Red_Large",
      "rotation": 7
    },
    {
      "x": -8,
      "y": 34,
      "z": 0,
      "name": "Rock_Crystal_Red_Block"
    },
    {
      "x": -8,
      "y": 35,
      "z": 0,
      "name": "Rock_Crystal_Red_Block"
    },
    {
      "x": -8,
      "y": 36,
      "z": 0,
      "name": "Rock_Slate"
    },
    {
      "x": -8,
      "y": 37,
      "z": 0,
      "name": "Rock_Slate"
    },
    {
      "x": -8,
      "y": 38,
      "z": 0,
      "name": "Rock_Slate"
    },
    {
      "x": -8,
      "y": 39,
      "z": 0,
      "name": "Rock_Slate"
    },
    {
      "x": -8,
      "y": 40,
      "z": 0,
      "name": "Rock_Slate"
    },
    {
      "x": -8,
      "y": 41,
      "z": 0,
      "name": "Rock_Slate"
    },
    {
      "x": -8,
      "y": 42,
      "z": 0,
      "name": "Rock_Slate"
    },
    {
      "x": -8,
      "y": 43,
      "z": 0,
      "name": "Rock_Slate"
    },
    {
      "x": -8,
      "y": 32,
      "z": 1,
      "name": "Rock_Crystal_Red_Block"
    },
    {
      "x": -8,
      "y": 33,
      "z": 1,
      "name": "Rock_Crystal_Red_Block"
    },
    {
      "x": -8,
      "y": 34,
      "z": 1,
      "name": "Rock_Crystal_Red_Block"
    },
    {
      "x": -8,
      "y": 35,
      "z": 1,
      "name": "Rock_Crystal_Red_Block"
    },
    {
      "x": -8,
      "y": 36,
      "z": 1,
      "name": "Rock_Slate"
    },
    {
      "x": -8,
      "y": 37,
      "z": 1,
      "name": "Rock_Slate"
    },
    {
      "x": -8,
      "y": 38,
      "z": 1,
      "name": "Rock_Slate"
    },
    {
      "x": -8,
      "y": 39,
      "z": 1,
      "name": "Rock_Slate"
    },
    {
      "x": -8,
      "y": 40,
      "z": 1,
      "name": "Rock_Slate"
    },
    {
      "x": -8,
      "y": 41,
      "z": 1,
      "name": "Rock_Slate"
    },
    {
      "x": -8,
      "y": 42,
      "z": 1,
      "name": "Rock_Slate"
    },
    {
      "x": -8,
      "y": 43,
      "z": 1,
      "name": "Rock_Slate"
    },
    {
      "x": -8,
      "y": 32,
      "z": 2,
      "name": "Rock_Crystal_Red_Block"
    },
    {
      "x": -8,
      "y": 33,
      "z": 2,
      "name": "Rock_Crystal_Red_Block"
    },
    {
      "x": -8,
      "y": 34,
      "z": 2,
      "name": "Rock_Slate"
    },
    {
      "x": -8,
      "y": 35,
      "z": 2,
      "name": "Rock_Slate"
    },
    {
      "x": -8,
      "y": 36,
      "z": 2,
      "name": "Rock_Slate"
    },
    {
      "x": -8,
      "y": 37,
      "z": 2,
      "name": "Rock_Slate"
    },
    {
      "x": -8,
      "y": 38,
      "z": 2,
      "name": "Rock_Slate"
    },
    {
      "x": -8,
      "y": 39,
      "z": 2,
      "name": "Rock_Slate"
    },
    {
      "x": -8,
      "y": 40,
      "z": 2,
      "name": "Rock_Slate"
    },
    {
      "x": -8,
      "y": 41,
      "z": 2,
      "name": "Rock_Slate"
    },
    {
      "x": -8,
      "y": 42,
      "z": 2,
      "name": "Rock_Slate"
    },
    {
      "x": -8,
      "y": 43,
      "z": 2,
      "name": "Rock_Slate"
    },
    {
      "x": -8,
      "y": 44,
      "z": 2,
      "name": "Rock_Slate"
    },
    {
      "x": -8,
      "y": 32,
      "z": 3,
      "name": "Rock_Slate"
    },
    {
      "x": -8,
      "y": 33,
      "z": 3,
      "name": "Rock_Slate"
    },
    {
      "x": -8,
      "y": 34,
      "z": 3,
      "name": "Rock_Slate"
    },
    {
      "x": -8,
      "y": 35,
      "z": 3,
      "name": "Rock_Slate"
    },
    {
      "x": -8,
      "y": 36,
      "z": 3,
      "name": "Rock_Slate"
    },
    {
      "x": -8,
      "y": 37,
      "z": 3,
      "name": "Rock_Slate"
    },
    {
      "x": -8,
      "y": 38,
      "z": 3,
      "name": "Rock_Slate"
    },
    {
      "x": -8,
      "y": 39,
      "z": 3,
      "name": "Rock_Slate"
    },
    {
      "x": -8,
      "y": 40,
      "z": 3,
      "name": "Rock_Slate"
    },
    {
      "x": -8,
      "y": 41,
      "z": 3,
      "name": "Rock_Slate"
    },
    {
      "x": -8,
      "y": 42,
      "z": 3,
      "name": "Rock_Slate"
    },
    {
      "x": -8,
      "y": 43,
      "z": 3,
      "name": "Rock_Slate"
    },
    {
      "x": -8,
      "y": 44,
      "z": 3,
      "name": "Rock_Slate"
    },
    {
      "x": -8,
      "y": 31,
      "z": 4,
      "name": "Rock_Slate"
    },
    {
      "x": -8,
      "y": 32,
      "z": 4,
      "name": "Rock_Slate"
    },
    {
      "x": -8,
      "y": 33,
      "z": 4,
      "name": "Rock_Slate"
    },
    {
      "x": -8,
      "y": 34,
      "z": 4,
      "name": "Rock_Slate"
    },
    {
      "x": -8,
      "y": 35,
      "z": 4,
      "name": "Rock_Slate"
    },
    {
      "x": -8,
      "y": 36,
      "z": 4,
      "name": "Rock_Slate"
    },
    {
      "x": -8,
      "y": 37,
      "z": 4,
      "name": "Rock_Slate"
    },
    {
      "x": -8,
      "y": 38,
      "z": 4,
      "name": "Rock_Slate"
    },
    {
      "x": -8,
      "y": 39,
      "z": 4,
      "name": "Rock_Slate"
    },
    {
      "x": -8,
      "y": 40,
      "z": 4,
      "name": "Rock_Slate"
    },
    {
      "x": -8,
      "y": 41,
      "z": 4,
      "name": "Rock_Slate"
    },
    {
      "x": -8,
      "y": 42,
      "z": 4,
      "name": "Rock_Slate"
    },
    {
      "x": -8,
      "y": 43,
      "z": 4,
      "name": "Rock_Slate"
    },
    {
      "x": -8,
      "y": 31,
      "z": 5,
      "name": "Rock_Slate"
    },
    {
      "x": -8,
      "y": 32,
      "z": 5,
      "name": "Rock_Slate"
    },
    {
      "x": -8,
      "y": 33,
      "z": 5,
      "name": "Rock_Slate"
    },
    {
      "x": -8,
      "y": 34,
      "z": 5,
      "name": "Rock_Slate"
    },
    {
      "x": -8,
      "y": 35,
      "z": 5,
      "name": "Rock_Slate"
    },
    {
      "x": -8,
      "y": 36,
      "z": 5,
      "name": "Rock_Slate"
    },
    {
      "x": -8,
      "y": 37,
      "z": 5,
      "name": "Rock_Slate"
    },
    {
      "x": -8,
      "y": 38,
      "z": 5,
      "name": "Rock_Slate"
    },
    {
      "x": -8,
      "y": 39,
      "z": 5,
      "name": "Rock_Slate"
    },
    {
      "x": -8,
      "y": 40,
      "z": 5,
      "name": "Rock_Slate"
    },
    {
      "x": -8,
      "y": 41,
      "z": 5,
      "name": "Rock_Slate"
    },
    {
      "x": -8,
      "y": 42,
      "z": 5,
      "name": "Rock_Slate"
    },
    {
      "x": -8,
      "y": 43,
      "z": 5,
      "name": "Rock_Slate"
    },
    {
      "x": -8,
      "y": 32,
      "z": 6,
      "name": "Rock_Slate"
    },
    {
      "x": -8,
      "y": 33,
      "z": 6,
      "name": "Rock_Slate"
    },
    {
      "x": -8,
      "y": 34,
      "z": 6,
      "name": "Rock_Slate"
    },
    {
      "x": -8,
      "y": 35,
      "z": 6,
      "name": "Rock_Slate"
    },
    {
      "x": -8,
      "y": 36,
      "z": 6,
      "name": "Rock_Slate"
    },
    {
      "x": -8,
      "y": 37,
      "z": 6,
      "name": "Rock_Slate"
    },
    {
      "x": -8,
      "y": 38,
      "z": 6,
      "name": "Rock_Slate"
    },
    {
      "x": -8,
      "y": 39,
      "z": 6,
      "name": "Rock_Slate"
    },
    {
      "x": -8,
      "y": 40,
      "z": 6,
      "name": "Rock_Slate"
    },
    {
      "x": -8,
      "y": 41,
      "z": 6,
      "name": "Rock_Slate"
    },
    {
      "x": -8,
      "y": 42,
      "z": 6,
      "name": "Rock_Slate"
    },
    {
      "x": -8,
      "y": 43,
      "z": 6,
      "name": "Rock_Slate"
    },
    {
      "x": -8,
      "y": 33,
      "z": 7,
      "name": "Rock_Slate"
    },
    {
      "x": -8,
      "y": 34,
      "z": 7,
      "name": "Rock_Slate"
    },
    {
      "x": -8,
      "y": 35,
      "z": 7,
      "name": "Rock_Slate"
    },
    {
      "x": -8,
      "y": 36,
      "z": 7,
      "name": "Rock_Slate"
    },
    {
      "x": -8,
      "y": 37,
      "z": 7,
      "name": "Rock_Slate"
    },
    {
      "x": -8,
      "y": 38,
      "z": 7,
      "name": "Rock_Slate"
    },
    {
      "x": -8,
      "y": 39,
      "z": 7,
      "name": "Rock_Slate"
    },
    {
      "x": -8,
      "y": 40,
      "z": 7,
      "name": "Rock_Slate"
    },
    {
      "x": -8,
      "y": 41,
      "z": 7,
      "name": "Rock_Slate"
    },
    {
      "x": -8,
      "y": 42,
      "z": 7,
      "name": "Rock_Slate"
    },
    {
      "x": -8,
      "y": 43,
      "z": 7,
      "name": "Rock_Slate"
    },
    {
      "x": -8,
      "y": 34,
      "z": 8,
      "name": "Rock_Slate"
    },
    {
      "x": -8,
      "y": 35,
      "z": 8,
      "name": "Rock_Slate"
    },
    {
      "x": -8,
      "y": 36,
      "z": 8,
      "name": "Rock_Slate"
    },
    {
      "x": -8,
      "y": 37,
      "z": 8,
      "name": "Rock_Slate"
    },
    {
      "x": -8,
      "y": 38,
      "z": 8,
      "name": "Rock_Slate"
    },
    {
      "x": -8,
      "y": 39,
      "z": 8,
      "name": "Rock_Slate"
    },
    {
      "x": -8,
      "y": 40,
      "z": 8,
      "name": "Rock_Slate"
    },
    {
      "x": -8,
      "y": 41,
      "z": 8,
      "name": "Rock_Slate"
    },
    {
      "x": -8,
      "y": 42,
      "z": 8,
      "name": "Rock_Slate"
    },
    {
      "x": -8,
      "y": 36,
      "z": 9,
      "name": "Rock_Slate"
    },
    {
      "x": -8,
      "y": 37,
      "z": 9,
      "name": "Rock_Slate"
    },
    {
      "x": -8,
      "y": 38,
      "z": 9,
      "name": "Rock_Slate"
    },
    {
      "x": -8,
      "y": 39,
      "z": 9,
      "name": "Rock_Slate"
    },
    {
      "x": -8,
      "y": 40,
      "z": 9,
      "name": "Rock_Slate"
    },
    {
      "x": -8,
      "y": 41,
      "z": 9,
      "name": "Rock_Slate"
    },
    {
      "x": -7,
      "y": 37,
      "z": -3,
      "name": "Rock_Slate"
    },
    {
      "x": -7,
      "y": 38,
      "z": -3,
      "name": "Rock_Slate"
    },
    {
      "x": -7,
      "y": 39,
      "z": -3,
      "name": "Rock_Slate"
    },
    {
      "x": -7,
      "y": 40,
      "z": -3,
      "name": "Rock_Slate"
    },
    {
      "x": -7,
      "y": 41,
      "z": -3,
      "name": "Rock_Slate"
    },
    {
      "x": -7,
      "y": 36,
      "z": -2,
      "name": "Rock_Slate"
    },
    {
      "x": -7,
      "y": 37,
      "z": -2,
      "name": "Rock_Slate"
    },
    {
      "x": -7,
      "y": 38,
      "z": -2,
      "name": "Rock_Slate"
    },
    {
      "x": -7,
      "y": 39,
      "z": -2,
      "name": "Rock_Slate"
    },
    {
      "x": -7,
      "y": 40,
      "z": -2,
      "name": "Rock_Slate"
    },
    {
      "x": -7,
      "y": 41,
      "z": -2,
      "name": "Rock_Slate"
    },
    {
      "x": -7,
      "y": 42,
      "z": -2,
      "name": "Rock_Slate"
    },
    {
      "x": -7,
      "y": 32,
      "z": -1,
      "name": "Rock_Crystal_Red_Large",
      "rotation": 6
    },
    {
      "x": -7,
      "y": 33,
      "z": -1,
      "name": "Rock_Crystal_Red_Large",
      "rotation": 6
    },
    {
      "x": -7,
      "y": 34,
      "z": -1,
      "name": "Rock_Crystal_Red_Block"
    },
    {
      "x": -7,
      "y": 35,
      "z": -1,
      "name": "Rock_Crystal_Red_Block"
    },
    {
      "x": -7,
      "y": 36,
      "z": -1,
      "name": "Rock_Slate"
    },
    {
      "x": -7,
      "y": 37,
      "z": -1,
      "name": "Rock_Slate"
    },
    {
      "x": -7,
      "y": 38,
      "z": -1,
      "name": "Rock_Slate"
    },
    {
      "x": -7,
      "y": 39,
      "z": -1,
      "name": "Rock_Slate"
    },
    {
      "x": -7,
      "y": 40,
      "z": -1,
      "name": "Rock_Slate"
    },
    {
      "x": -7,
      "y": 41,
      "z": -1,
      "name": "Rock_Slate"
    },
    {
      "x": -7,
      "y": 42,
      "z": -1,
      "name": "Rock_Slate"
    },
    {
      "x": -7,
      "y": 43,
      "z": -1,
      "name": "Rock_Slate"
    },
    {
      "x": -7,
      "y": 31,
      "z": 0,
      "name": "Rock_Crystal_Red_Large",
      "rotation": 8
    },
    {
      "x": -7,
      "y": 32,
      "z": 0,
      "name": "Rock_Crystal_Red_Block"
    },
    {
      "x": -7,
      "y": 33,
      "z": 0,
      "name": "Rock_Crystal_Red_Block"
    },
    {
      "x": -7,
      "y": 34,
      "z": 0,
      "name": "Rock_Crystal_Red_Block"
    },
    {
      "x": -7,
      "y": 35,
      "z": 0,
      "name": "Rock_Crystal_Red_Block"
    },
    {
      "x": -7,
      "y": 36,
      "z": 0,
      "name": "Rock_Slate"
    },
    {
      "x": -7,
      "y": 37,
      "z": 0,
      "name": "Rock_Slate"
    },
    {
      "x": -7,
      "y": 38,
      "z": 0,
      "name": "Rock_Slate"
    },
    {
      "x": -7,
      "y": 39,
      "z": 0,
      "name": "Rock_Slate"
    },
    {
      "x": -7,
      "y": 40,
      "z": 0,
      "name": "Rock_Slate"
    },
    {
      "x": -7,
      "y": 41,
      "z": 0,
      "name": "Rock_Slate"
    },
    {
      "x": -7,
      "y": 42,
      "z": 0,
      "name": "Rock_Slate"
    },
    {
      "x": -7,
      "y": 43,
      "z": 0,
      "name": "Rock_Slate"
    },
    {
      "x": -7,
      "y": 5,
      "z": 1,
      "name": "Rock_Slate"
    },
    {
      "x": -7,
      "y": 6,
      "z": 1,
      "name": "Rock_Slate"
    },
    {
      "x": -7,
      "y": 31,
      "z": 1,
      "name": "Rock_Crystal_Red_Block"
    },
    {
      "x": -7,
      "y": 32,
      "z": 1,
      "name": "Rock_Crystal_Red_Block"
    },
    {
      "x": -7,
      "y": 33,
      "z": 1,
      "name": "Rock_Crystal_Red_Block"
    },
    {
      "x": -7,
      "y": 34,
      "z": 1,
      "name": "Rock_Crystal_Red_Block"
    },
    {
      "x": -7,
      "y": 35,
      "z": 1,
      "name": "Rock_Crystal_Red_Block"
    },
    {
      "x": -7,
      "y": 36,
      "z": 1,
      "name": "Rock_Slate"
    },
    {
      "x": -7,
      "y": 37,
      "z": 1,
      "name": "Rock_Slate"
    },
    {
      "x": -7,
      "y": 38,
      "z": 1,
      "name": "Rock_Slate"
    },
    {
      "x": -7,
      "y": 39,
      "z": 1,
      "name": "Rock_Slate"
    },
    {
      "x": -7,
      "y": 40,
      "z": 1,
      "name": "Rock_Slate"
    },
    {
      "x": -7,
      "y": 41,
      "z": 1,
      "name": "Rock_Slate"
    },
    {
      "x": -7,
      "y": 42,
      "z": 1,
      "name": "Rock_Slate"
    },
    {
      "x": -7,
      "y": 43,
      "z": 1,
      "name": "Rock_Slate"
    },
    {
      "x": -7,
      "y": 44,
      "z": 1,
      "name": "Rock_Slate"
    },
    {
      "x": -7,
      "y": 4,
      "z": 2,
      "name": "Rock_Slate"
    },
    {
      "x": -7,
      "y": 5,
      "z": 2,
      "name": "Rock_Slate"
    },
    {
      "x": -7,
      "y": 6,
      "z": 2,
      "name": "Rock_Slate"
    },
    {
      "x": -7,
      "y": 7,
      "z": 2,
      "name": "Rock_Slate"
    },
    {
      "x": -7,
      "y": 31,
      "z": 2,
      "name": "Rock_Crystal_Red_Block"
    },
    {
      "x": -7,
      "y": 32,
      "z": 2,
      "name": "Rock_Crystal_Red_Block"
    },
    {
      "x": -7,
      "y": 33,
      "z": 2,
      "name": "Rock_Crystal_Red_Block"
    },
    {
      "x": -7,
      "y": 34,
      "z": 2,
      "name": "Rock_Slate"
    },
    {
      "x": -7,
      "y": 35,
      "z": 2,
      "name": "Rock_Slate"
    },
    {
      "x": -7,
      "y": 36,
      "z": 2,
      "name": "Rock_Slate"
    },
    {
      "x": -7,
      "y": 37,
      "z": 2,
      "name": "Rock_Slate"
    },
    {
      "x": -7,
      "y": 38,
      "z": 2,
      "name": "Rock_Slate"
    },
    {
      "x": -7,
      "y": 39,
      "z": 2,
      "name": "Rock_Slate"
    },
    {
      "x": -7,
      "y": 40,
      "z": 2,
      "name": "Rock_Slate"
    },
    {
      "x": -7,
      "y": 41,
      "z": 2,
      "name": "Rock_Slate"
    },
    {
      "x": -7,
      "y": 42,
      "z": 2,
      "name": "Rock_Slate"
    },
    {
      "x": -7,
      "y": 43,
      "z": 2,
      "name": "Rock_Slate"
    },
    {
      "x": -7,
      "y": 44,
      "z": 2,
      "name": "Rock_Slate"
    },
    {
      "x": -7,
      "y": 3,
      "z": 3,
      "name": "Rock_Slate"
    },
    {
      "x": -7,
      "y": 4,
      "z": 3,
      "name": "Rock_Slate"
    },
    {
      "x": -7,
      "y": 5,
      "z": 3,
      "name": "Rock_Slate"
    },
    {
      "x": -7,
      "y": 6,
      "z": 3,
      "name": "Rock_Slate"
    },
    {
      "x": -7,
      "y": 7,
      "z": 3,
      "name": "Rock_Slate"
    },
    {
      "x": -7,
      "y": 8,
      "z": 3,
      "name": "Rock_Slate"
    },
    {
      "x": -7,
      "y": 30,
      "z": 3,
      "name": "Rock_Slate"
    },
    {
      "x": -7,
      "y": 31,
      "z": 3,
      "name": "Rock_Slate"
    },
    {
      "x": -7,
      "y": 32,
      "z": 3,
      "name": "Rock_Slate"
    },
    {
      "x": -7,
      "y": 33,
      "z": 3,
      "name": "Rock_Slate"
    },
    {
      "x": -7,
      "y": 34,
      "z": 3,
      "name": "Rock_Slate"
    },
    {
      "x": -7,
      "y": 35,
      "z": 3,
      "name": "Rock_Slate"
    },
    {
      "x": -7,
      "y": 36,
      "z": 3,
      "name": "Rock_Slate"
    },
    {
      "x": -7,
      "y": 37,
      "z": 3,
      "name": "Rock_Slate"
    },
    {
      "x": -7,
      "y": 38,
      "z": 3,
      "name": "Rock_Slate"
    },
    {
      "x": -7,
      "y": 39,
      "z": 3,
      "name": "Rock_Slate"
    },
    {
      "x": -7,
      "y": 40,
      "z": 3,
      "name": "Rock_Slate"
    },
    {
      "x": -7,
      "y": 41,
      "z": 3,
      "name": "Rock_Slate"
    },
    {
      "x": -7,
      "y": 42,
      "z": 3,
      "name": "Rock_Slate"
    },
    {
      "x": -7,
      "y": 43,
      "z": 3,
      "name": "Rock_Slate"
    },
    {
      "x": -7,
      "y": 44,
      "z": 3,
      "name": "Rock_Slate"
    },
    {
      "x": -7,
      "y": 4,
      "z": 4,
      "name": "Rock_Slate"
    },
    {
      "x": -7,
      "y": 5,
      "z": 4,
      "name": "Rock_Slate"
    },
    {
      "x": -7,
      "y": 6,
      "z": 4,
      "name": "Rock_Slate"
    },
    {
      "x": -7,
      "y": 7,
      "z": 4,
      "name": "Rock_Slate"
    },
    {
      "x": -7,
      "y": 30,
      "z": 4,
      "name": "Rock_Slate"
    },
    {
      "x": -7,
      "y": 31,
      "z": 4,
      "name": "Rock_Slate"
    },
    {
      "x": -7,
      "y": 32,
      "z": 4,
      "name": "Rock_Slate"
    },
    {
      "x": -7,
      "y": 33,
      "z": 4,
      "name": "Rock_Slate"
    },
    {
      "x": -7,
      "y": 34,
      "z": 4,
      "name": "Rock_Slate"
    },
    {
      "x": -7,
      "y": 35,
      "z": 4,
      "name": "Rock_Slate"
    },
    {
      "x": -7,
      "y": 36,
      "z": 4,
      "name": "Rock_Slate"
    },
    {
      "x": -7,
      "y": 37,
      "z": 4,
      "name": "Rock_Slate"
    },
    {
      "x": -7,
      "y": 38,
      "z": 4,
      "name": "Rock_Slate"
    },
    {
      "x": -7,
      "y": 39,
      "z": 4,
      "name": "Rock_Slate"
    },
    {
      "x": -7,
      "y": 40,
      "z": 4,
      "name": "Rock_Slate"
    },
    {
      "x": -7,
      "y": 41,
      "z": 4,
      "name": "Rock_Slate"
    },
    {
      "x": -7,
      "y": 42,
      "z": 4,
      "name": "Rock_Slate"
    },
    {
      "x": -7,
      "y": 43,
      "z": 4,
      "name": "Rock_Slate"
    },
    {
      "x": -7,
      "y": 44,
      "z": 4,
      "name": "Rock_Slate"
    },
    {
      "x": -7,
      "y": 30,
      "z": 5,
      "name": "Rock_Slate"
    },
    {
      "x": -7,
      "y": 31,
      "z": 5,
      "name": "Rock_Slate"
    },
    {
      "x": -7,
      "y": 32,
      "z": 5,
      "name": "Rock_Slate"
    },
    {
      "x": -7,
      "y": 33,
      "z": 5,
      "name": "Rock_Slate"
    },
    {
      "x": -7,
      "y": 34,
      "z": 5,
      "name": "Rock_Slate"
    },
    {
      "x": -7,
      "y": 35,
      "z": 5,
      "name": "Rock_Slate"
    },
    {
      "x": -7,
      "y": 36,
      "z": 5,
      "name": "Rock_Slate"
    },
    {
      "x": -7,
      "y": 37,
      "z": 5,
      "name": "Rock_Slate"
    },
    {
      "x": -7,
      "y": 38,
      "z": 5,
      "name": "Rock_Slate"
    },
    {
      "x": -7,
      "y": 39,
      "z": 5,
      "name": "Rock_Slate"
    },
    {
      "x": -7,
      "y": 40,
      "z": 5,
      "name": "Rock_Slate"
    },
    {
      "x": -7,
      "y": 41,
      "z": 5,
      "name": "Rock_Slate"
    },
    {
      "x": -7,
      "y": 42,
      "z": 5,
      "name": "Rock_Slate"
    },
    {
      "x": -7,
      "y": 43,
      "z": 5,
      "name": "Rock_Slate"
    },
    {
      "x": -7,
      "y": 44,
      "z": 5,
      "name": "Rock_Slate"
    },
    {
      "x": -7,
      "y": 30,
      "z": 6,
      "name": "Rock_Slate"
    },
    {
      "x": -7,
      "y": 31,
      "z": 6,
      "name": "Rock_Slate"
    },
    {
      "x": -7,
      "y": 32,
      "z": 6,
      "name": "Rock_Slate"
    },
    {
      "x": -7,
      "y": 33,
      "z": 6,
      "name": "Rock_Slate"
    },
    {
      "x": -7,
      "y": 34,
      "z": 6,
      "name": "Rock_Slate"
    },
    {
      "x": -7,
      "y": 35,
      "z": 6,
      "name": "Rock_Slate"
    },
    {
      "x": -7,
      "y": 36,
      "z": 6,
      "name": "Rock_Slate"
    },
    {
      "x": -7,
      "y": 37,
      "z": 6,
      "name": "Rock_Slate"
    },
    {
      "x": -7,
      "y": 38,
      "z": 6,
      "name": "Rock_Slate"
    },
    {
      "x": -7,
      "y": 39,
      "z": 6,
      "name": "Rock_Slate"
    },
    {
      "x": -7,
      "y": 40,
      "z": 6,
      "name": "Rock_Slate"
    },
    {
      "x": -7,
      "y": 41,
      "z": 6,
      "name": "Rock_Slate"
    },
    {
      "x": -7,
      "y": 42,
      "z": 6,
      "name": "Rock_Slate"
    },
    {
      "x": -7,
      "y": 43,
      "z": 6,
      "name": "Rock_Slate"
    },
    {
      "x": -7,
      "y": 31,
      "z": 7,
      "name": "Rock_Slate"
    },
    {
      "x": -7,
      "y": 32,
      "z": 7,
      "name": "Rock_Slate"
    },
    {
      "x": -7,
      "y": 33,
      "z": 7,
      "name": "Rock_Slate"
    },
    {
      "x": -7,
      "y": 34,
      "z": 7,
      "name": "Rock_Slate"
    },
    {
      "x": -7,
      "y": 35,
      "z": 7,
      "name": "Rock_Slate"
    },
    {
      "x": -7,
      "y": 36,
      "z": 7,
      "name": "Rock_Slate"
    },
    {
      "x": -7,
      "y": 37,
      "z": 7,
      "name": "Rock_Slate"
    },
    {
      "x": -7,
      "y": 38,
      "z": 7,
      "name": "Rock_Slate"
    },
    {
      "x": -7,
      "y": 39,
      "z": 7,
      "name": "Rock_Slate"
    },
    {
      "x": -7,
      "y": 40,
      "z": 7,
      "name": "Rock_Slate"
    },
    {
      "x": -7,
      "y": 41,
      "z": 7,
      "name": "Rock_Slate"
    },
    {
      "x": -7,
      "y": 42,
      "z": 7,
      "name": "Rock_Slate"
    },
    {
      "x": -7,
      "y": 43,
      "z": 7,
      "name": "Rock_Slate"
    },
    {
      "x": -7,
      "y": 33,
      "z": 8,
      "name": "Rock_Slate"
    },
    {
      "x": -7,
      "y": 34,
      "z": 8,
      "name": "Rock_Slate"
    },
    {
      "x": -7,
      "y": 35,
      "z": 8,
      "name": "Rock_Slate"
    },
    {
      "x": -7,
      "y": 36,
      "z": 8,
      "name": "Rock_Slate"
    },
    {
      "x": -7,
      "y": 37,
      "z": 8,
      "name": "Rock_Slate"
    },
    {
      "x": -7,
      "y": 38,
      "z": 8,
      "name": "Rock_Slate"
    },
    {
      "x": -7,
      "y": 39,
      "z": 8,
      "name": "Rock_Slate"
    },
    {
      "x": -7,
      "y": 40,
      "z": 8,
      "name": "Rock_Slate"
    },
    {
      "x": -7,
      "y": 41,
      "z": 8,
      "name": "Rock_Slate"
    },
    {
      "x": -7,
      "y": 42,
      "z": 8,
      "name": "Rock_Slate"
    },
    {
      "x": -7,
      "y": 43,
      "z": 8,
      "name": "Rock_Slate"
    },
    {
      "x": -7,
      "y": 35,
      "z": 9,
      "name": "Rock_Slate"
    },
    {
      "x": -7,
      "y": 36,
      "z": 9,
      "name": "Rock_Slate"
    },
    {
      "x": -7,
      "y": 37,
      "z": 9,
      "name": "Rock_Slate"
    },
    {
      "x": -7,
      "y": 38,
      "z": 9,
      "name": "Rock_Slate"
    },
    {
      "x": -7,
      "y": 39,
      "z": 9,
      "name": "Rock_Slate"
    },
    {
      "x": -7,
      "y": 40,
      "z": 9,
      "name": "Rock_Slate"
    },
    {
      "x": -7,
      "y": 41,
      "z": 9,
      "name": "Rock_Slate"
    },
    {
      "x": -7,
      "y": 42,
      "z": 9,
      "name": "Rock_Slate"
    },
    {
      "x": -7,
      "y": 37,
      "z": 10,
      "name": "Rock_Slate"
    },
    {
      "x": -7,
      "y": 38,
      "z": 10,
      "name": "Rock_Slate"
    },
    {
      "x": -7,
      "y": 39,
      "z": 10,
      "name": "Rock_Slate"
    },
    {
      "x": -7,
      "y": 40,
      "z": 10,
      "name": "Rock_Slate"
    },
    {
      "x": -6,
      "y": 38,
      "z": -4,
      "name": "Rock_Slate"
    },
    {
      "x": -6,
      "y": 39,
      "z": -4,
      "name": "Rock_Slate"
    },
    {
      "x": -6,
      "y": 40,
      "z": -4,
      "name": "Rock_Slate"
    },
    {
      "x": -6,
      "y": 36,
      "z": -3,
      "name": "Rock_Slate"
    },
    {
      "x": -6,
      "y": 37,
      "z": -3,
      "name": "Rock_Slate"
    },
    {
      "x": -6,
      "y": 38,
      "z": -3,
      "name": "Rock_Slate"
    },
    {
      "x": -6,
      "y": 39,
      "z": -3,
      "name": "Rock_Slate"
    },
    {
      "x": -6,
      "y": 40,
      "z": -3,
      "name": "Rock_Slate"
    },
    {
      "x": -6,
      "y": 41,
      "z": -3,
      "name": "Rock_Slate"
    },
    {
      "x": -6,
      "y": 42,
      "z": -3,
      "name": "Rock_Slate"
    },
    {
      "x": -6,
      "y": 33,
      "z": -2,
      "name": "Rock_Crystal_Red_Large",
      "rotation": 6
    },
    {
      "x": -6,
      "y": 34,
      "z": -2,
      "name": "Rock_Crystal_Red_Small",
      "components": {
        "Components": {
          "FarmingBlock": {}
        }
      },
      "rotation": 6
    },
    {
      "x": -6,
      "y": 35,
      "z": -2,
      "name": "Rock_Crystal_Red_Block"
    },
    {
      "x": -6,
      "y": 36,
      "z": -2,
      "name": "Rock_Slate"
    },
    {
      "x": -6,
      "y": 37,
      "z": -2,
      "name": "Rock_Slate"
    },
    {
      "x": -6,
      "y": 38,
      "z": -2,
      "name": "Rock_Slate"
    },
    {
      "x": -6,
      "y": 39,
      "z": -2,
      "name": "Rock_Slate"
    },
    {
      "x": -6,
      "y": 40,
      "z": -2,
      "name": "Rock_Slate"
    },
    {
      "x": -6,
      "y": 41,
      "z": -2,
      "name": "Rock_Slate"
    },
    {
      "x": -6,
      "y": 42,
      "z": -2,
      "name": "Rock_Slate"
    },
    {
      "x": -6,
      "y": 43,
      "z": -2,
      "name": "Rock_Slate"
    },
    {
      "x": -6,
      "y": 4,
      "z": -1,
      "name": "Rock_Slate"
    },
    {
      "x": -6,
      "y": 5,
      "z": -1,
      "name": "Rock_Slate"
    },
    {
      "x": -6,
      "y": 6,
      "z": -1,
      "name": "Rock_Slate"
    },
    {
      "x": -6,
      "y": 7,
      "z": -1,
      "name": "Rock_Slate"
    },
    {
      "x": -6,
      "y": 32,
      "z": -1,
      "name": "Rock_Crystal_Red_Large",
      "rotation": 6
    },
    {
      "x": -6,
      "y": 33,
      "z": -1,
      "name": "Rock_Crystal_Red_Block"
    },
    {
      "x": -6,
      "y": 34,
      "z": -1,
      "name": "Rock_Crystal_Red_Block"
    },
    {
      "x": -6,
      "y": 35,
      "z": -1,
      "name": "Rock_Crystal_Red_Block"
    },
    {
      "x": -6,
      "y": 36,
      "z": -1,
      "name": "Rock_Slate"
    },
    {
      "x": -6,
      "y": 37,
      "z": -1,
      "name": "Rock_Slate"
    },
    {
      "x": -6,
      "y": 38,
      "z": -1,
      "name": "Rock_Slate"
    },
    {
      "x": -6,
      "y": 39,
      "z": -1,
      "name": "Rock_Slate"
    },
    {
      "x": -6,
      "y": 40,
      "z": -1,
      "name": "Rock_Slate"
    },
    {
      "x": -6,
      "y": 41,
      "z": -1,
      "name": "Rock_Slate"
    },
    {
      "x": -6,
      "y": 42,
      "z": -1,
      "name": "Rock_Slate"
    },
    {
      "x": -6,
      "y": 43,
      "z": -1,
      "name": "Rock_Slate"
    },
    {
      "x": -6,
      "y": -2,
      "z": 0,
      "name": "Rock_Slate"
    },
    {
      "x": -6,
      "y": -1,
      "z": 0,
      "name": "Rock_Slate"
    },
    {
      "x": -6,
      "y": 0,
      "z": 0,
      "name": "Rock_Slate"
    },
    {
      "x": -6,
      "y": 1,
      "z": 0,
      "name": "Rock_Slate"
    },
    {
      "x": -6,
      "y": 2,
      "z": 0,
      "name": "Rock_Slate"
    },
    {
      "x": -6,
      "y": 3,
      "z": 0,
      "name": "Rock_Slate"
    },
    {
      "x": -6,
      "y": 4,
      "z": 0,
      "name": "Rock_Slate"
    },
    {
      "x": -6,
      "y": 5,
      "z": 0,
      "name": "Rock_Slate"
    },
    {
      "x": -6,
      "y": 6,
      "z": 0,
      "name": "Rock_Slate"
    },
    {
      "x": -6,
      "y": 7,
      "z": 0,
      "name": "Rock_Slate"
    },
    {
      "x": -6,
      "y": 8,
      "z": 0,
      "name": "Rock_Slate"
    },
    {
      "x": -6,
      "y": 9,
      "z": 0,
      "name": "Rock_Slate"
    },
    {
      "x": -6,
      "y": 31,
      "z": 0,
      "name": "Rock_Crystal_Red_Block"
    },
    {
      "x": -6,
      "y": 32,
      "z": 0,
      "name": "Rock_Crystal_Red_Block"
    },
    {
      "x": -6,
      "y": 33,
      "z": 0,
      "name": "Rock_Crystal_Red_Block"
    },
    {
      "x": -6,
      "y": 34,
      "z": 0,
      "name": "Rock_Crystal_Red_Block"
    },
    {
      "x": -6,
      "y": 35,
      "z": 0,
      "name": "Rock_Crystal_Red_Block"
    },
    {
      "x": -6,
      "y": 36,
      "z": 0,
      "name": "Rock_Slate"
    },
    {
      "x": -6,
      "y": 37,
      "z": 0,
      "name": "Rock_Slate"
    },
    {
      "x": -6,
      "y": 38,
      "z": 0,
      "name": "Rock_Slate"
    },
    {
      "x": -6,
      "y": 39,
      "z": 0,
      "name": "Rock_Slate"
    },
    {
      "x": -6,
      "y": 40,
      "z": 0,
      "name": "Rock_Slate"
    },
    {
      "x": -6,
      "y": 41,
      "z": 0,
      "name": "Rock_Slate"
    },
    {
      "x": -6,
      "y": 42,
      "z": 0,
      "name": "Rock_Slate"
    },
    {
      "x": -6,
      "y": 43,
      "z": 0,
      "name": "Rock_Slate"
    },
    {
      "x": -6,
      "y": 44,
      "z": 0,
      "name": "Rock_Slate"
    },
    {
      "x": -6,
      "y": -3,
      "z": 1,
      "name": "Rock_Slate"
    },
    {
      "x": -6,
      "y": -2,
      "z": 1,
      "name": "Rock_Slate"
    },
    {
      "x": -6,
      "y": -1,
      "z": 1,
      "name": "Rock_Slate"
    },
    {
      "x": -6,
      "y": 0,
      "z": 1,
      "name": "Rock_Slate"
    },
    {
      "x": -6,
      "y": 1,
      "z": 1,
      "name": "Rock_Slate"
    },
    {
      "x": -6,
      "y": 2,
      "z": 1,
      "name": "Rock_Slate"
    },
    {
      "x": -6,
      "y": 3,
      "z": 1,
      "name": "Rock_Slate"
    },
    {
      "x": -6,
      "y": 4,
      "z": 1,
      "name": "Rock_Slate"
    },
    {
      "x": -6,
      "y": 5,
      "z": 1,
      "name": "Rock_Slate"
    },
    {
      "x": -6,
      "y": 6,
      "z": 1,
      "name": "Rock_Slate"
    },
    {
      "x": -6,
      "y": 7,
      "z": 1,
      "name": "Rock_Slate"
    },
    {
      "x": -6,
      "y": 8,
      "z": 1,
      "name": "Rock_Slate"
    },
    {
      "x": -6,
      "y": 9,
      "z": 1,
      "name": "Rock_Slate"
    },
    {
      "x": -6,
      "y": 10,
      "z": 1,
      "name": "Rock_Slate"
    },
    {
      "x": -6,
      "y": 11,
      "z": 1,
      "name": "Rock_Slate"
    },
    {
      "x": -6,
      "y": 30,
      "z": 1,
      "name": "Rock_Slate"
    },
    {
      "x": -6,
      "y": 31,
      "z": 1,
      "name": "Rock_Crystal_Red_Block"
    },
    {
      "x": -6,
      "y": 32,
      "z": 1,
      "name": "Rock_Crystal_Red_Block"
    },
    {
      "x": -6,
      "y": 33,
      "z": 1,
      "name": "Rock_Crystal_Red_Block"
    },
    {
      "x": -6,
      "y": 34,
      "z": 1,
      "name": "Rock_Crystal_Red_Block"
    },
    {
      "x": -6,
      "y": 35,
      "z": 1,
      "name": "Rock_Crystal_Red_Block"
    },
    {
      "x": -6,
      "y": 36,
      "z": 1,
      "name": "Rock_Slate"
    },
    {
      "x": -6,
      "y": 37,
      "z": 1,
      "name": "Rock_Slate"
    },
    {
      "x": -6,
      "y": 38,
      "z": 1,
      "name": "Rock_Slate"
    },
    {
      "x": -6,
      "y": 39,
      "z": 1,
      "name": "Rock_Slate"
    },
    {
      "x": -6,
      "y": 40,
      "z": 1,
      "name": "Rock_Slate"
    },
    {
      "x": -6,
      "y": 41,
      "z": 1,
      "name": "Rock_Slate"
    },
    {
      "x": -6,
      "y": 42,
      "z": 1,
      "name": "Rock_Slate"
    },
    {
      "x": -6,
      "y": 43,
      "z": 1,
      "name": "Rock_Slate"
    },
    {
      "x": -6,
      "y": 44,
      "z": 1,
      "name": "Rock_Slate"
    },
    {
      "x": -6,
      "y": -3,
      "z": 2,
      "name": "Rock_Slate"
    },
    {
      "x": -6,
      "y": -2,
      "z": 2,
      "name": "Rock_Slate"
    },
    {
      "x": -6,
      "y": -1,
      "z": 2,
      "name": "Rock_Slate"
    },
    {
      "x": -6,
      "y": 0,
      "z": 2,
      "name": "Rock_Slate"
    },
    {
      "x": -6,
      "y": 1,
      "z": 2,
      "name": "Rock_Slate"
    },
    {
      "x": -6,
      "y": 2,
      "z": 2,
      "name": "Rock_Slate"
    },
    {
      "x": -6,
      "y": 3,
      "z": 2,
      "name": "Rock_Slate"
    },
    {
      "x": -6,
      "y": 4,
      "z": 2,
      "name": "Rock_Slate"
    },
    {
      "x": -6,
      "y": 5,
      "z": 2,
      "name": "Rock_Slate"
    },
    {
      "x": -6,
      "y": 6,
      "z": 2,
      "name": "Rock_Slate"
    },
    {
      "x": -6,
      "y": 7,
      "z": 2,
      "name": "Rock_Slate"
    },
    {
      "x": -6,
      "y": 8,
      "z": 2,
      "name": "Rock_Slate"
    },
    {
      "x": -6,
      "y": 9,
      "z": 2,
      "name": "Rock_Slate"
    },
    {
      "x": -6,
      "y": 10,
      "z": 2,
      "name": "Rock_Slate"
    },
    {
      "x": -6,
      "y": 11,
      "z": 2,
      "name": "Rock_Slate"
    },
    {
      "x": -6,
      "y": 12,
      "z": 2,
      "name": "Rock_Slate"
    },
    {
      "x": -6,
      "y": 30,
      "z": 2,
      "name": "Rock_Slate"
    },
    {
      "x": -6,
      "y": 31,
      "z": 2,
      "name": "Rock_Crystal_Red_Block"
    },
    {
      "x": -6,
      "y": 32,
      "z": 2,
      "name": "Rock_Crystal_Red_Block"
    },
    {
      "x": -6,
      "y": 33,
      "z": 2,
      "name": "Rock_Crystal_Red_Block"
    },
    {
      "x": -6,
      "y": 34,
      "z": 2,
      "name": "Rock_Slate"
    },
    {
      "x": -6,
      "y": 35,
      "z": 2,
      "name": "Rock_Slate"
    },
    {
      "x": -6,
      "y": 36,
      "z": 2,
      "name": "Rock_Slate"
    },
    {
      "x": -6,
      "y": 37,
      "z": 2,
      "name": "Rock_Slate"
    },
    {
      "x": -6,
      "y": 38,
      "z": 2,
      "name": "Rock_Slate"
    },
    {
      "x": -6,
      "y": 39,
      "z": 2,
      "name": "Rock_Slate"
    },
    {
      "x": -6,
      "y": 40,
      "z": 2,
      "name": "Rock_Slate"
    },
    {
      "x": -6,
      "y": 41,
      "z": 2,
      "name": "Rock_Slate"
    },
    {
      "x": -6,
      "y": 42,
      "z": 2,
      "name": "Rock_Slate"
    },
    {
      "x": -6,
      "y": 43,
      "z": 2,
      "name": "Rock_Slate"
    },
    {
      "x": -6,
      "y": 44,
      "z": 2,
      "name": "Rock_Slate"
    },
    {
      "x": -6,
      "y": -3,
      "z": 3,
      "name": "Rock_Slate"
    },
    {
      "x": -6,
      "y": -2,
      "z": 3,
      "name": "Rock_Slate"
    },
    {
      "x": -6,
      "y": -1,
      "z": 3,
      "name": "Rock_Slate"
    },
    {
      "x": -6,
      "y": 0,
      "z": 3,
      "name": "Rock_Slate"
    },
    {
      "x": -6,
      "y": 1,
      "z": 3,
      "name": "Rock_Slate"
    },
    {
      "x": -6,
      "y": 2,
      "z": 3,
      "name": "Rock_Slate"
    },
    {
      "x": -6,
      "y": 3,
      "z": 3,
      "name": "Rock_Slate"
    },
    {
      "x": -6,
      "y": 4,
      "z": 3,
      "name": "Rock_Slate"
    },
    {
      "x": -6,
      "y": 5,
      "z": 3,
      "name": "Rock_Slate"
    },
    {
      "x": -6,
      "y": 6,
      "z": 3,
      "name": "Rock_Slate"
    },
    {
      "x": -6,
      "y": 7,
      "z": 3,
      "name": "Rock_Slate"
    },
    {
      "x": -6,
      "y": 8,
      "z": 3,
      "name": "Rock_Slate"
    },
    {
      "x": -6,
      "y": 9,
      "z": 3,
      "name": "Rock_Slate"
    },
    {
      "x": -6,
      "y": 10,
      "z": 3,
      "name": "Rock_Slate"
    },
    {
      "x": -6,
      "y": 11,
      "z": 3,
      "name": "Rock_Slate"
    },
    {
      "x": -6,
      "y": 29,
      "z": 3,
      "name": "Rock_Slate"
    },
    {
      "x": -6,
      "y": 30,
      "z": 3,
      "name": "Rock_Slate"
    },
    {
      "x": -6,
      "y": 31,
      "z": 3,
      "name": "Rock_Slate"
    },
    {
      "x": -6,
      "y": 32,
      "z": 3,
      "name": "Rock_Slate"
    },
    {
      "x": -6,
      "y": 33,
      "z": 3,
      "name": "Rock_Slate"
    },
    {
      "x": -6,
      "y": 34,
      "z": 3,
      "name": "Rock_Slate"
    },
    {
      "x": -6,
      "y": 35,
      "z": 3,
      "name": "Rock_Slate"
    },
    {
      "x": -6,
      "y": 36,
      "z": 3,
      "name": "Rock_Slate"
    },
    {
      "x": -6,
      "y": 37,
      "z": 3,
      "name": "Rock_Slate"
    },
    {
      "x": -6,
      "y": 38,
      "z": 3,
      "name": "Rock_Slate"
    },
    {
      "x": -6,
      "y": 39,
      "z": 3,
      "name": "Rock_Slate"
    },
    {
      "x": -6,
      "y": 40,
      "z": 3,
      "name": "Rock_Slate"
    },
    {
      "x": -6,
      "y": 41,
      "z": 3,
      "name": "Rock_Slate"
    },
    {
      "x": -6,
      "y": 42,
      "z": 3,
      "name": "Rock_Slate"
    },
    {
      "x": -6,
      "y": 43,
      "z": 3,
      "name": "Rock_Slate"
    },
    {
      "x": -6,
      "y": 44,
      "z": 3,
      "name": "Rock_Slate"
    },
    {
      "x": -6,
      "y": 0,
      "z": 4,
      "name": "Rock_Slate"
    },
    {
      "x": -6,
      "y": 1,
      "z": 4,
      "name": "Rock_Slate"
    },
    {
      "x": -6,
      "y": 2,
      "z": 4,
      "name": "Rock_Slate"
    },
    {
      "x": -6,
      "y": 3,
      "z": 4,
      "name": "Rock_Slate"
    },
    {
      "x": -6,
      "y": 4,
      "z": 4,
      "name": "Rock_Slate"
    },
    {
      "x": -6,
      "y": 5,
      "z": 4,
      "name": "Rock_Slate"
    },
    {
      "x": -6,
      "y": 6,
      "z": 4,
      "name": "Rock_Slate"
    },
    {
      "x": -6,
      "y": 7,
      "z": 4,
      "name": "Rock_Slate"
    },
    {
      "x": -6,
      "y": 8,
      "z": 4,
      "name": "Rock_Slate"
    },
    {
      "x": -6,
      "y": 9,
      "z": 4,
      "name": "Rock_Slate"
    },
    {
      "x": -6,
      "y": 10,
      "z": 4,
      "name": "Rock_Slate"
    },
    {
      "x": -6,
      "y": 29,
      "z": 4,
      "name": "Rock_Slate"
    },
    {
      "x": -6,
      "y": 30,
      "z": 4,
      "name": "Rock_Slate"
    },
    {
      "x": -6,
      "y": 31,
      "z": 4,
      "name": "Rock_Slate"
    },
    {
      "x": -6,
      "y": 32,
      "z": 4,
      "name": "Rock_Slate"
    },
    {
      "x": -6,
      "y": 33,
      "z": 4,
      "name": "Rock_Slate"
    },
    {
      "x": -6,
      "y": 34,
      "z": 4,
      "name": "Rock_Slate"
    },
    {
      "x": -6,
      "y": 35,
      "z": 4,
      "name": "Rock_Slate"
    },
    {
      "x": -6,
      "y": 36,
      "z": 4,
      "name": "Rock_Slate"
    },
    {
      "x": -6,
      "y": 37,
      "z": 4,
      "name": "Rock_Slate"
    },
    {
      "x": -6,
      "y": 38,
      "z": 4,
      "name": "Rock_Slate"
    },
    {
      "x": -6,
      "y": 39,
      "z": 4,
      "name": "Rock_Slate"
    },
    {
      "x": -6,
      "y": 40,
      "z": 4,
      "name": "Rock_Slate"
    },
    {
      "x": -6,
      "y": 41,
      "z": 4,
      "name": "Rock_Slate"
    },
    {
      "x": -6,
      "y": 42,
      "z": 4,
      "name": "Rock_Slate"
    },
    {
      "x": -6,
      "y": 43,
      "z": 4,
      "name": "Rock_Slate"
    },
    {
      "x": -6,
      "y": 44,
      "z": 4,
      "name": "Rock_Slate"
    },
    {
      "x": -6,
      "y": 1,
      "z": 5,
      "name": "Rock_Slate"
    },
    {
      "x": -6,
      "y": 2,
      "z": 5,
      "name": "Rock_Slate"
    },
    {
      "x": -6,
      "y": 3,
      "z": 5,
      "name": "Rock_Slate"
    },
    {
      "x": -6,
      "y": 4,
      "z": 5,
      "name": "Rock_Slate"
    },
    {
      "x": -6,
      "y": 5,
      "z": 5,
      "name": "Rock_Slate"
    },
    {
      "x": -6,
      "y": 6,
      "z": 5,
      "name": "Rock_Slate"
    },
    {
      "x": -6,
      "y": 7,
      "z": 5,
      "name": "Rock_Slate"
    },
    {
      "x": -6,
      "y": 8,
      "z": 5,
      "name": "Rock_Slate"
    },
    {
      "x": -6,
      "y": 9,
      "z": 5,
      "name": "Rock_Slate"
    },
    {
      "x": -6,
      "y": 13,
      "z": 5,
      "name": "Rock_Crystal_Red_Large",
      "rotation": 7
    },
    {
      "x": -6,
      "y": 29,
      "z": 5,
      "name": "Rock_Slate"
    },
    {
      "x": -6,
      "y": 30,
      "z": 5,
      "name": "Rock_Slate"
    },
    {
      "x": -6,
      "y": 31,
      "z": 5,
      "name": "Rock_Slate"
    },
    {
      "x": -6,
      "y": 32,
      "z": 5,
      "name": "Rock_Slate"
    },
    {
      "x": -6,
      "y": 33,
      "z": 5,
      "name": "Rock_Slate"
    },
    {
      "x": -6,
      "y": 34,
      "z": 5,
      "name": "Rock_Slate"
    },
    {
      "x": -6,
      "y": 35,
      "z": 5,
      "name": "Rock_Slate"
    },
    {
      "x": -6,
      "y": 36,
      "z": 5,
      "name": "Rock_Slate"
    },
    {
      "x": -6,
      "y": 37,
      "z": 5,
      "name": "Rock_Slate"
    },
    {
      "x": -6,
      "y": 38,
      "z": 5,
      "name": "Rock_Slate"
    },
    {
      "x": -6,
      "y": 39,
      "z": 5,
      "name": "Rock_Slate"
    },
    {
      "x": -6,
      "y": 40,
      "z": 5,
      "name": "Rock_Slate"
    },
    {
      "x": -6,
      "y": 41,
      "z": 5,
      "name": "Rock_Slate"
    },
    {
      "x": -6,
      "y": 42,
      "z": 5,
      "name": "Rock_Slate"
    },
    {
      "x": -6,
      "y": 43,
      "z": 5,
      "name": "Rock_Slate"
    },
    {
      "x": -6,
      "y": 44,
      "z": 5,
      "name": "Rock_Slate"
    },
    {
      "x": -6,
      "y": 3,
      "z": 6,
      "name": "Rock_Slate"
    },
    {
      "x": -6,
      "y": 4,
      "z": 6,
      "name": "Rock_Slate"
    },
    {
      "x": -6,
      "y": 5,
      "z": 6,
      "name": "Rock_Slate"
    },
    {
      "x": -6,
      "y": 6,
      "z": 6,
      "name": "Rock_Slate"
    },
    {
      "x": -6,
      "y": 7,
      "z": 6,
      "name": "Rock_Slate"
    },
    {
      "x": -6,
      "y": 8,
      "z": 6,
      "name": "Rock_Slate"
    },
    {
      "x": -6,
      "y": 13,
      "z": 6,
      "name": "Rock_Crystal_Red_Large",
      "rotation": 7
    },
    {
      "x": -6,
      "y": 14,
      "z": 6,
      "name": "Rock_Crystal_Red_Large",
      "rotation": 7
    },
    {
      "x": -6,
      "y": 30,
      "z": 6,
      "name": "Rock_Slate"
    },
    {
      "x": -6,
      "y": 31,
      "z": 6,
      "name": "Rock_Slate"
    },
    {
      "x": -6,
      "y": 32,
      "z": 6,
      "name": "Rock_Slate"
    },
    {
      "x": -6,
      "y": 33,
      "z": 6,
      "name": "Rock_Slate"
    },
    {
      "x": -6,
      "y": 34,
      "z": 6,
      "name": "Rock_Slate"
    },
    {
      "x": -6,
      "y": 35,
      "z": 6,
      "name": "Rock_Slate"
    },
    {
      "x": -6,
      "y": 36,
      "z": 6,
      "name": "Rock_Slate"
    },
    {
      "x": -6,
      "y": 37,
      "z": 6,
      "name": "Rock_Slate"
    },
    {
      "x": -6,
      "y": 38,
      "z": 6,
      "name": "Rock_Slate"
    },
    {
      "x": -6,
      "y": 39,
      "z": 6,
      "name": "Rock_Slate"
    },
    {
      "x": -6,
      "y": 40,
      "z": 6,
      "name": "Rock_Slate"
    },
    {
      "x": -6,
      "y": 41,
      "z": 6,
      "name": "Rock_Slate"
    },
    {
      "x": -6,
      "y": 42,
      "z": 6,
      "name": "Rock_Slate"
    },
    {
      "x": -6,
      "y": 43,
      "z": 6,
      "name": "Rock_Slate"
    },
    {
      "x": -6,
      "y": 44,
      "z": 6,
      "name": "Rock_Slate"
    },
    {
      "x": -6,
      "y": 31,
      "z": 7,
      "name": "Rock_Slate"
    },
    {
      "x": -6,
      "y": 32,
      "z": 7,
      "name": "Rock_Slate"
    },
    {
      "x": -6,
      "y": 33,
      "z": 7,
      "name": "Rock_Slate"
    },
    {
      "x": -6,
      "y": 34,
      "z": 7,
      "name": "Rock_Slate"
    },
    {
      "x": -6,
      "y": 35,
      "z": 7,
      "name": "Rock_Slate"
    },
    {
      "x": -6,
      "y": 36,
      "z": 7,
      "name": "Rock_Slate"
    },
    {
      "x": -6,
      "y": 37,
      "z": 7,
      "name": "Rock_Slate"
    },
    {
      "x": -6,
      "y": 38,
      "z": 7,
      "name": "Rock_Slate"
    },
    {
      "x": -6,
      "y": 39,
      "z": 7,
      "name": "Rock_Slate"
    },
    {
      "x": -6,
      "y": 40,
      "z": 7,
      "name": "Rock_Slate"
    },
    {
      "x": -6,
      "y": 41,
      "z": 7,
      "name": "Rock_Slate"
    },
    {
      "x": -6,
      "y": 42,
      "z": 7,
      "name": "Rock_Slate"
    },
    {
      "x": -6,
      "y": 43,
      "z": 7,
      "name": "Rock_Slate"
    },
    {
      "x": -6,
      "y": 32,
      "z": 8,
      "name": "Rock_Slate"
    },
    {
      "x": -6,
      "y": 33,
      "z": 8,
      "name": "Rock_Slate"
    },
    {
      "x": -6,
      "y": 34,
      "z": 8,
      "name": "Rock_Slate"
    },
    {
      "x": -6,
      "y": 35,
      "z": 8,
      "name": "Rock_Slate"
    },
    {
      "x": -6,
      "y": 36,
      "z": 8,
      "name": "Rock_Slate"
    },
    {
      "x": -6,
      "y": 37,
      "z": 8,
      "name": "Rock_Slate"
    },
    {
      "x": -6,
      "y": 38,
      "z": 8,
      "name": "Rock_Slate"
    },
    {
      "x": -6,
      "y": 39,
      "z": 8,
      "name": "Rock_Slate"
    },
    {
      "x": -6,
      "y": 40,
      "z": 8,
      "name": "Rock_Slate"
    },
    {
      "x": -6,
      "y": 41,
      "z": 8,
      "name": "Rock_Slate"
    },
    {
      "x": -6,
      "y": 42,
      "z": 8,
      "name": "Rock_Slate"
    },
    {
      "x": -6,
      "y": 43,
      "z": 8,
      "name": "Rock_Slate"
    },
    {
      "x": -6,
      "y": 34,
      "z": 9,
      "name": "Rock_Slate"
    },
    {
      "x": -6,
      "y": 35,
      "z": 9,
      "name": "Rock_Slate"
    },
    {
      "x": -6,
      "y": 36,
      "z": 9,
      "name": "Rock_Slate"
    },
    {
      "x": -6,
      "y": 37,
      "z": 9,
      "name": "Rock_Slate"
    },
    {
      "x": -6,
      "y": 38,
      "z": 9,
      "name": "Rock_Slate"
    },
    {
      "x": -6,
      "y": 39,
      "z": 9,
      "name": "Rock_Slate"
    },
    {
      "x": -6,
      "y": 40,
      "z": 9,
      "name": "Rock_Slate"
    },
    {
      "x": -6,
      "y": 41,
      "z": 9,
      "name": "Rock_Slate"
    },
    {
      "x": -6,
      "y": 42,
      "z": 9,
      "name": "Rock_Slate"
    },
    {
      "x": -6,
      "y": 36,
      "z": 10,
      "name": "Rock_Slate"
    },
    {
      "x": -6,
      "y": 37,
      "z": 10,
      "name": "Rock_Slate"
    },
    {
      "x": -6,
      "y": 38,
      "z": 10,
      "name": "Rock_Slate"
    },
    {
      "x": -6,
      "y": 39,
      "z": 10,
      "name": "Rock_Slate"
    },
    {
      "x": -6,
      "y": 40,
      "z": 10,
      "name": "Rock_Slate"
    },
    {
      "x": -6,
      "y": 41,
      "z": 10,
      "name": "Rock_Slate"
    },
    {
      "x": -6,
      "y": 38,
      "z": 11,
      "name": "Rock_Slate"
    },
    {
      "x": -6,
      "y": 39,
      "z": 11,
      "name": "Rock_Slate"
    },
    {
      "x": -5,
      "y": 38,
      "z": -4,
      "name": "Rock_Slate"
    },
    {
      "x": -5,
      "y": 39,
      "z": -4,
      "name": "Rock_Slate"
    },
    {
      "x": -5,
      "y": 40,
      "z": -4,
      "name": "Rock_Slate"
    },
    {
      "x": -5,
      "y": 36,
      "z": -3,
      "name": "Rock_Slate"
    },
    {
      "x": -5,
      "y": 37,
      "z": -3,
      "name": "Rock_Slate"
    },
    {
      "x": -5,
      "y": 38,
      "z": -3,
      "name": "Rock_Slate"
    },
    {
      "x": -5,
      "y": 39,
      "z": -3,
      "name": "Rock_Slate"
    },
    {
      "x": -5,
      "y": 40,
      "z": -3,
      "name": "Rock_Slate"
    },
    {
      "x": -5,
      "y": 41,
      "z": -3,
      "name": "Rock_Slate"
    },
    {
      "x": -5,
      "y": 42,
      "z": -3,
      "name": "Rock_Slate"
    },
    {
      "x": -5,
      "y": -2,
      "z": -2,
      "name": "Rock_Slate"
    },
    {
      "x": -5,
      "y": -1,
      "z": -2,
      "name": "Rock_Slate"
    },
    {
      "x": -5,
      "y": 0,
      "z": -2,
      "name": "Rock_Slate"
    },
    {
      "x": -5,
      "y": 3,
      "z": -2,
      "name": "Rock_Slate"
    },
    {
      "x": -5,
      "y": 4,
      "z": -2,
      "name": "Rock_Slate"
    },
    {
      "x": -5,
      "y": 5,
      "z": -2,
      "name": "Rock_Slate"
    },
    {
      "x": -5,
      "y": 6,
      "z": -2,
      "name": "Rock_Slate"
    },
    {
      "x": -5,
      "y": 7,
      "z": -2,
      "name": "Rock_Slate"
    },
    {
      "x": -5,
      "y": 8,
      "z": -2,
      "name": "Rock_Slate"
    },
    {
      "x": -5,
      "y": 33,
      "z": -2,
      "name": "Rock_Crystal_Red_Block"
    },
    {
      "x": -5,
      "y": 34,
      "z": -2,
      "name": "Rock_Crystal_Red_Block"
    },
    {
      "x": -5,
      "y": 35,
      "z": -2,
      "name": "Rock_Crystal_Red_Block"
    },
    {
      "x": -5,
      "y": 36,
      "z": -2,
      "name": "Rock_Slate"
    },
    {
      "x": -5,
      "y": 37,
      "z": -2,
      "name": "Rock_Slate"
    },
    {
      "x": -5,
      "y": 38,
      "z": -2,
      "name": "Rock_Slate"
    },
    {
      "x": -5,
      "y": 39,
      "z": -2,
      "name": "Rock_Slate"
    },
    {
      "x": -5,
      "y": 40,
      "z": -2,
      "name": "Rock_Slate"
    },
    {
      "x": -5,
      "y": 41,
      "z": -2,
      "name": "Rock_Slate"
    },
    {
      "x": -5,
      "y": 42,
      "z": -2,
      "name": "Rock_Slate"
    },
    {
      "x": -5,
      "y": 43,
      "z": -2,
      "name": "Rock_Slate"
    },
    {
      "x": -5,
      "y": -4,
      "z": -1,
      "name": "Rock_Slate"
    },
    {
      "x": -5,
      "y": -3,
      "z": -1,
      "name": "Rock_Slate"
    },
    {
      "x": -5,
      "y": -2,
      "z": -1,
      "name": "Rock_Slate"
    },
    {
      "x": -5,
      "y": -1,
      "z": -1,
      "name": "Rock_Slate"
    },
    {
      "x": -5,
      "y": 0,
      "z": -1,
      "name": "Rock_Slate"
    },
    {
      "x": -5,
      "y": 1,
      "z": -1,
      "name": "Rock_Slate"
    },
    {
      "x": -5,
      "y": 2,
      "z": -1,
      "name": "Rock_Slate"
    },
    {
      "x": -5,
      "y": 3,
      "z": -1,
      "name": "Rock_Slate"
    },
    {
      "x": -5,
      "y": 4,
      "z": -1,
      "name": "Rock_Slate"
    },
    {
      "x": -5,
      "y": 5,
      "z": -1,
      "name": "Rock_Slate"
    },
    {
      "x": -5,
      "y": 6,
      "z": -1,
      "name": "Rock_Slate"
    },
    {
      "x": -5,
      "y": 7,
      "z": -1,
      "name": "Rock_Slate"
    },
    {
      "x": -5,
      "y": 8,
      "z": -1,
      "name": "Rock_Slate"
    },
    {
      "x": -5,
      "y": 9,
      "z": -1,
      "name": "Rock_Slate"
    },
    {
      "x": -5,
      "y": 10,
      "z": -1,
      "name": "Rock_Slate"
    },
    {
      "x": -5,
      "y": 11,
      "z": -1,
      "name": "Rock_Slate"
    },
    {
      "x": -5,
      "y": 31,
      "z": -1,
      "name": "Rock_Crystal_Red_Block"
    },
    {
      "x": -5,
      "y": 32,
      "z": -1,
      "name": "Rock_Crystal_Red_Block"
    },
    {
      "x": -5,
      "y": 33,
      "z": -1,
      "name": "Rock_Crystal_Red_Block"
    },
    {
      "x": -5,
      "y": 34,
      "z": -1,
      "name": "Rock_Crystal_Red_Block"
    },
    {
      "x": -5,
      "y": 35,
      "z": -1,
      "name": "Rock_Crystal_Red_Block"
    },
    {
      "x": -5,
      "y": 36,
      "z": -1,
      "name": "Rock_Slate"
    },
    {
      "x": -5,
      "y": 37,
      "z": -1,
      "name": "Rock_Slate"
    },
    {
      "x": -5,
      "y": 38,
      "z": -1,
      "name": "Rock_Slate"
    },
    {
      "x": -5,
      "y": 39,
      "z": -1,
      "name": "Rock_Slate"
    },
    {
      "x": -5,
      "y": 40,
      "z": -1,
      "name": "Rock_Slate"
    },
    {
      "x": -5,
      "y": 41,
      "z": -1,
      "name": "Rock_Slate"
    },
    {
      "x": -5,
      "y": 42,
      "z": -1,
      "name": "Rock_Slate"
    },
    {
      "x": -5,
      "y": 43,
      "z": -1,
      "name": "Rock_Slate"
    },
    {
      "x": -5,
      "y": 44,
      "z": -1,
      "name": "Rock_Slate"
    },
    {
      "x": -5,
      "y": -4,
      "z": 0,
      "name": "Rock_Slate"
    },
    {
      "x": -5,
      "y": -3,
      "z": 0,
      "name": "Rock_Slate"
    },
    {
      "x": -5,
      "y": -2,
      "z": 0,
      "name": "Rock_Slate"
    },
    {
      "x": -5,
      "y": -1,
      "z": 0,
      "name": "Rock_Slate"
    },
    {
      "x": -5,
      "y": 0,
      "z": 0,
      "name": "Rock_Slate"
    },
    {
      "x": -5,
      "y": 1,
      "z": 0,
      "name": "Rock_Slate"
    },
    {
      "x": -5,
      "y": 2,
      "z": 0,
      "name": "Rock_Slate"
    },
    {
      "x": -5,
      "y": 3,
      "z": 0,
      "name": "Rock_Slate"
    },
    {
      "x": -5,
      "y": 4,
      "z": 0,
      "name": "Rock_Slate"
    },
    {
      "x": -5,
      "y": 5,
      "z": 0,
      "name": "Rock_Slate"
    },
    {
      "x": -5,
      "y": 6,
      "z": 0,
      "name": "Rock_Slate"
    },
    {
      "x": -5,
      "y": 7,
      "z": 0,
      "name": "Rock_Slate"
    },
    {
      "x": -5,
      "y": 8,
      "z": 0,
      "name": "Rock_Slate"
    },
    {
      "x": -5,
      "y": 9,
      "z": 0,
      "name": "Rock_Slate"
    },
    {
      "x": -5,
      "y": 10,
      "z": 0,
      "name": "Rock_Slate"
    },
    {
      "x": -5,
      "y": 11,
      "z": 0,
      "name": "Rock_Slate"
    },
    {
      "x": -5,
      "y": 12,
      "z": 0,
      "name": "Rock_Slate"
    },
    {
      "x": -5,
      "y": 13,
      "z": 0,
      "name": "Rock_Slate"
    },
    {
      "x": -5,
      "y": 14,
      "z": 0,
      "name": "Rock_Slate"
    },
    {
      "x": -5,
      "y": 30,
      "z": 0,
      "name": "Rock_Slate"
    },
    {
      "x": -5,
      "y": 31,
      "z": 0,
      "name": "Rock_Crystal_Red_Block"
    },
    {
      "x": -5,
      "y": 32,
      "z": 0,
      "name": "Rock_Crystal_Red_Block"
    },
    {
      "x": -5,
      "y": 33,
      "z": 0,
      "name": "Rock_Crystal_Red_Block"
    },
    {
      "x": -5,
      "y": 34,
      "z": 0,
      "name": "Rock_Crystal_Red_Block"
    },
    {
      "x": -5,
      "y": 35,
      "z": 0,
      "name": "Rock_Crystal_Red_Block"
    },
    {
      "x": -5,
      "y": 36,
      "z": 0,
      "name": "Rock_Slate"
    },
    {
      "x": -5,
      "y": 37,
      "z": 0,
      "name": "Rock_Slate"
    },
    {
      "x": -5,
      "y": 38,
      "z": 0,
      "name": "Rock_Slate"
    },
    {
      "x": -5,
      "y": 39,
      "z": 0,
      "name": "Rock_Slate"
    },
    {
      "x": -5,
      "y": 40,
      "z": 0,
      "name": "Rock_Slate"
    },
    {
      "x": -5,
      "y": 41,
      "z": 0,
      "name": "Rock_Slate"
    },
    {
      "x": -5,
      "y": 42,
      "z": 0,
      "name": "Rock_Slate"
    },
    {
      "x": -5,
      "y": 43,
      "z": 0,
      "name": "Rock_Slate"
    },
    {
      "x": -5,
      "y": 44,
      "z": 0,
      "name": "Rock_Slate"
    },
    {
      "x": -5,
      "y": -5,
      "z": 1,
      "name": "Rock_Slate"
    },
    {
      "x": -5,
      "y": -4,
      "z": 1,
      "name": "Rock_Slate"
    },
    {
      "x": -5,
      "y": -3,
      "z": 1,
      "name": "Rock_Slate"
    },
    {
      "x": -5,
      "y": -2,
      "z": 1,
      "name": "Rock_Slate"
    },
    {
      "x": -5,
      "y": -1,
      "z": 1,
      "name": "Rock_Slate"
    },
    {
      "x": -5,
      "y": 0,
      "z": 1,
      "name": "Rock_Slate"
    },
    {
      "x": -5,
      "y": 1,
      "z": 1,
      "name": "Rock_Slate"
    },
    {
      "x": -5,
      "y": 2,
      "z": 1,
      "name": "Rock_Slate"
    },
    {
      "x": -5,
      "y": 3,
      "z": 1,
      "name": "Rock_Slate"
    },
    {
      "x": -5,
      "y": 4,
      "z": 1,
      "name": "Rock_Slate"
    },
    {
      "x": -5,
      "y": 5,
      "z": 1,
      "name": "Rock_Slate"
    },
    {
      "x": -5,
      "y": 6,
      "z": 1,
      "name": "Rock_Slate"
    },
    {
      "x": -5,
      "y": 7,
      "z": 1,
      "name": "Rock_Slate"
    },
    {
      "x": -5,
      "y": 8,
      "z": 1,
      "name": "Rock_Slate"
    },
    {
      "x": -5,
      "y": 9,
      "z": 1,
      "name": "Rock_Slate"
    },
    {
      "x": -5,
      "y": 10,
      "z": 1,
      "name": "Rock_Slate"
    },
    {
      "x": -5,
      "y": 11,
      "z": 1,
      "name": "Rock_Slate"
    },
    {
      "x": -5,
      "y": 12,
      "z": 1,
      "name": "Rock_Slate"
    },
    {
      "x": -5,
      "y": 13,
      "z": 1,
      "name": "Rock_Crystal_Red_Block"
    },
    {
      "x": -5,
      "y": 14,
      "z": 1,
      "name": "Rock_Crystal_Red_Block"
    },
    {
      "x": -5,
      "y": 15,
      "z": 1,
      "name": "Rock_Crystal_Red_Block"
    },
    {
      "x": -5,
      "y": 16,
      "z": 1,
      "name": "Rock_Slate"
    },
    {
      "x": -5,
      "y": 29,
      "z": 1,
      "name": "Rock_Slate"
    },
    {
      "x": -5,
      "y": 30,
      "z": 1,
      "name": "Rock_Slate"
    },
    {
      "x": -5,
      "y": 31,
      "z": 1,
      "name": "Rock_Crystal_Red_Block"
    },
    {
      "x": -5,
      "y": 32,
      "z": 1,
      "name": "Rock_Crystal_Red_Block"
    },
    {
      "x": -5,
      "y": 33,
      "z": 1,
      "name": "Rock_Crystal_Red_Block"
    },
    {
      "x": -5,
      "y": 34,
      "z": 1,
      "name": "Rock_Crystal_Red_Block"
    },
    {
      "x": -5,
      "y": 35,
      "z": 1,
      "name": "Rock_Crystal_Red_Block"
    },
    {
      "x": -5,
      "y": 36,
      "z": 1,
      "name": "Rock_Slate"
    },
    {
      "x": -5,
      "y": 37,
      "z": 1,
      "name": "Rock_Slate"
    },
    {
      "x": -5,
      "y": 38,
      "z": 1,
      "name": "Rock_Slate"
    },
    {
      "x": -5,
      "y": 39,
      "z": 1,
      "name": "Rock_Slate"
    },
    {
      "x": -5,
      "y": 40,
      "z": 1,
      "name": "Rock_Slate"
    },
    {
      "x": -5,
      "y": 41,
      "z": 1,
      "name": "Rock_Slate"
    },
    {
      "x": -5,
      "y": 42,
      "z": 1,
      "name": "Rock_Slate"
    },
    {
      "x": -5,
      "y": 43,
      "z": 1,
      "name": "Rock_Slate"
    },
    {
      "x": -5,
      "y": 44,
      "z": 1,
      "name": "Rock_Slate"
    },
    {
      "x": -5,
      "y": -5,
      "z": 2,
      "name": "Rock_Slate"
    },
    {
      "x": -5,
      "y": -4,
      "z": 2,
      "name": "Rock_Slate"
    },
    {
      "x": -5,
      "y": -3,
      "z": 2,
      "name": "Rock_Slate"
    },
    {
      "x": -5,
      "y": -2,
      "z": 2,
      "name": "Rock_Slate"
    },
    {
      "x": -5,
      "y": -1,
      "z": 2,
      "name": "Rock_Slate"
    },
    {
      "x": -5,
      "y": 0,
      "z": 2,
      "name": "Rock_Slate"
    },
    {
      "x": -5,
      "y": 1,
      "z": 2,
      "name": "Rock_Slate"
    },
    {
      "x": -5,
      "y": 2,
      "z": 2,
      "name": "Rock_Slate"
    },
    {
      "x": -5,
      "y": 3,
      "z": 2,
      "name": "Rock_Slate"
    },
    {
      "x": -5,
      "y": 4,
      "z": 2,
      "name": "Rock_Slate"
    },
    {
      "x": -5,
      "y": 5,
      "z": 2,
      "name": "Rock_Slate"
    },
    {
      "x": -5,
      "y": 6,
      "z": 2,
      "name": "Rock_Slate"
    },
    {
      "x": -5,
      "y": 7,
      "z": 2,
      "name": "Rock_Slate"
    },
    {
      "x": -5,
      "y": 8,
      "z": 2,
      "name": "Rock_Slate"
    },
    {
      "x": -5,
      "y": 9,
      "z": 2,
      "name": "Rock_Slate"
    },
    {
      "x": -5,
      "y": 10,
      "z": 2,
      "name": "Rock_Slate"
    },
    {
      "x": -5,
      "y": 11,
      "z": 2,
      "name": "Rock_Slate"
    },
    {
      "x": -5,
      "y": 12,
      "z": 2,
      "name": "Rock_Slate"
    },
    {
      "x": -5,
      "y": 13,
      "z": 2,
      "name": "Rock_Crystal_Red_Block"
    },
    {
      "x": -5,
      "y": 14,
      "z": 2,
      "name": "Rock_Crystal_Red_Block"
    },
    {
      "x": -5,
      "y": 15,
      "z": 2,
      "name": "Rock_Crystal_Red_Block"
    },
    {
      "x": -5,
      "y": 28,
      "z": 2,
      "name": "Rock_Slate"
    },
    {
      "x": -5,
      "y": 29,
      "z": 2,
      "name": "Rock_Slate"
    },
    {
      "x": -5,
      "y": 30,
      "z": 2,
      "name": "Rock_Slate"
    },
    {
      "x": -5,
      "y": 31,
      "z": 2,
      "name": "Rock_Crystal_Red_Block"
    },
    {
      "x": -5,
      "y": 32,
      "z": 2,
      "name": "Rock_Crystal_Red_Block"
    },
    {
      "x": -5,
      "y": 33,
      "z": 2,
      "name": "Rock_Crystal_Red_Block"
    },
    {
      "x": -5,
      "y": 34,
      "z": 2,
      "name": "Rock_Slate"
    },
    {
      "x": -5,
      "y": 35,
      "z": 2,
      "name": "Rock_Slate"
    },
    {
      "x": -5,
      "y": 36,
      "z": 2,
      "name": "Rock_Slate"
    },
    {
      "x": -5,
      "y": 37,
      "z": 2,
      "name": "Rock_Slate"
    },
    {
      "x": -5,
      "y": 38,
      "z": 2,
      "name": "Rock_Slate"
    },
    {
      "x": -5,
      "y": 39,
      "z": 2,
      "name": "Rock_Slate"
    },
    {
      "x": -5,
      "y": 40,
      "z": 2,
      "name": "Rock_Slate"
    },
    {
      "x": -5,
      "y": 41,
      "z": 2,
      "name": "Rock_Slate"
    },
    {
      "x": -5,
      "y": 42,
      "z": 2,
      "name": "Rock_Slate"
    },
    {
      "x": -5,
      "y": 43,
      "z": 2,
      "name": "Rock_Slate"
    },
    {
      "x": -5,
      "y": 44,
      "z": 2,
      "name": "Rock_Slate"
    },
    {
      "x": -5,
      "y": 45,
      "z": 2,
      "name": "Rock_Slate"
    },
    {
      "x": -5,
      "y": -5,
      "z": 3,
      "name": "Rock_Slate"
    },
    {
      "x": -5,
      "y": -4,
      "z": 3,
      "name": "Rock_Slate"
    },
    {
      "x": -5,
      "y": -3,
      "z": 3,
      "name": "Rock_Slate"
    },
    {
      "x": -5,
      "y": -2,
      "z": 3,
      "name": "Rock_Slate"
    },
    {
      "x": -5,
      "y": -1,
      "z": 3,
      "name": "Rock_Slate"
    },
    {
      "x": -5,
      "y": 0,
      "z": 3,
      "name": "Rock_Slate"
    },
    {
      "x": -5,
      "y": 1,
      "z": 3,
      "name": "Rock_Slate"
    },
    {
      "x": -5,
      "y": 2,
      "z": 3,
      "name": "Rock_Slate"
    },
    {
      "x": -5,
      "y": 3,
      "z": 3,
      "name": "Rock_Slate"
    },
    {
      "x": -5,
      "y": 4,
      "z": 3,
      "name": "Rock_Slate"
    },
    {
      "x": -5,
      "y": 5,
      "z": 3,
      "name": "Rock_Slate"
    },
    {
      "x": -5,
      "y": 6,
      "z": 3,
      "name": "Rock_Slate"
    },
    {
      "x": -5,
      "y": 7,
      "z": 3,
      "name": "Rock_Slate"
    },
    {
      "x": -5,
      "y": 8,
      "z": 3,
      "name": "Rock_Slate"
    },
    {
      "x": -5,
      "y": 9,
      "z": 3,
      "name": "Rock_Slate"
    },
    {
      "x": -5,
      "y": 10,
      "z": 3,
      "name": "Rock_Slate"
    },
    {
      "x": -5,
      "y": 11,
      "z": 3,
      "name": "Rock_Slate"
    },
    {
      "x": -5,
      "y": 12,
      "z": 3,
      "name": "Rock_Slate"
    },
    {
      "x": -5,
      "y": 13,
      "z": 3,
      "name": "Rock_Crystal_Red_Block"
    },
    {
      "x": -5,
      "y": 14,
      "z": 3,
      "name": "Rock_Crystal_Red_Block"
    },
    {
      "x": -5,
      "y": 27,
      "z": 3,
      "name": "Rock_Slate"
    },
    {
      "x": -5,
      "y": 28,
      "z": 3,
      "name": "Rock_Slate"
    },
    {
      "x": -5,
      "y": 29,
      "z": 3,
      "name": "Rock_Slate"
    },
    {
      "x": -5,
      "y": 30,
      "z": 3,
      "name": "Rock_Slate"
    },
    {
      "x": -5,
      "y": 31,
      "z": 3,
      "name": "Rock_Slate"
    },
    {
      "x": -5,
      "y": 32,
      "z": 3,
      "name": "Rock_Slate"
    },
    {
      "x": -5,
      "y": 33,
      "z": 3,
      "name": "Rock_Slate"
    },
    {
      "x": -5,
      "y": 34,
      "z": 3,
      "name": "Rock_Slate"
    },
    {
      "x": -5,
      "y": 35,
      "z": 3,
      "name": "Rock_Slate"
    },
    {
      "x": -5,
      "y": 36,
      "z": 3,
      "name": "Rock_Slate"
    },
    {
      "x": -5,
      "y": 37,
      "z": 3,
      "name": "Rock_Slate"
    },
    {
      "x": -5,
      "y": 38,
      "z": 3,
      "name": "Rock_Slate"
    },
    {
      "x": -5,
      "y": 39,
      "z": 3,
      "name": "Rock_Slate"
    },
    {
      "x": -5,
      "y": 40,
      "z": 3,
      "name": "Rock_Slate"
    },
    {
      "x": -5,
      "y": 41,
      "z": 3,
      "name": "Rock_Slate"
    },
    {
      "x": -5,
      "y": 42,
      "z": 3,
      "name": "Rock_Slate"
    },
    {
      "x": -5,
      "y": 43,
      "z": 3,
      "name": "Rock_Slate"
    },
    {
      "x": -5,
      "y": 44,
      "z": 3,
      "name": "Rock_Slate"
    },
    {
      "x": -5,
      "y": 45,
      "z": 3,
      "name": "Rock_Slate"
    },
    {
      "x": -5,
      "y": -4,
      "z": 4,
      "name": "Rock_Slate"
    },
    {
      "x": -5,
      "y": -3,
      "z": 4,
      "name": "Rock_Slate"
    },
    {
      "x": -5,
      "y": -2,
      "z": 4,
      "name": "Rock_Slate"
    },
    {
      "x": -5,
      "y": -1,
      "z": 4,
      "name": "Rock_Slate"
    },
    {
      "x": -5,
      "y": 0,
      "z": 4,
      "name": "Rock_Slate"
    },
    {
      "x": -5,
      "y": 1,
      "z": 4,
      "name": "Rock_Slate"
    },
    {
      "x": -5,
      "y": 2,
      "z": 4,
      "name": "Rock_Slate"
    },
    {
      "x": -5,
      "y": 3,
      "z": 4,
      "name": "Rock_Slate"
    },
    {
      "x": -5,
      "y": 4,
      "z": 4,
      "name": "Rock_Slate"
    },
    {
      "x": -5,
      "y": 5,
      "z": 4,
      "name": "Rock_Slate"
    },
    {
      "x": -5,
      "y": 6,
      "z": 4,
      "name": "Rock_Slate"
    },
    {
      "x": -5,
      "y": 7,
      "z": 4,
      "name": "Rock_Slate"
    },
    {
      "x": -5,
      "y": 8,
      "z": 4,
      "name": "Rock_Slate"
    },
    {
      "x": -5,
      "y": 9,
      "z": 4,
      "name": "Rock_Slate"
    },
    {
      "x": -5,
      "y": 10,
      "z": 4,
      "name": "Rock_Slate"
    },
    {
      "x": -5,
      "y": 11,
      "z": 4,
      "name": "Rock_Crystal_Red_Block"
    },
    {
      "x": -5,
      "y": 12,
      "z": 4,
      "name": "Rock_Crystal_Red_Block"
    },
    {
      "x": -5,
      "y": 13,
      "z": 4,
      "name": "Rock_Crystal_Red_Block"
    },
    {
      "x": -5,
      "y": 14,
      "z": 4,
      "name": "Rock_Crystal_Red_Block"
    },
    {
      "x": -5,
      "y": 15,
      "z": 4,
      "name": "Rock_Crystal_Red_Small",
      "components": {
        "Components": {
          "FarmingBlock": {}
        }
      }
    },
    {
      "x": -5,
      "y": 28,
      "z": 4,
      "name": "Rock_Slate"
    },
    {
      "x": -5,
      "y": 29,
      "z": 4,
      "name": "Rock_Slate"
    },
    {
      "x": -5,
      "y": 30,
      "z": 4,
      "name": "Rock_Slate"
    },
    {
      "x": -5,
      "y": 31,
      "z": 4,
      "name": "Rock_Slate"
    },
    {
      "x": -5,
      "y": 32,
      "z": 4,
      "name": "Rock_Slate"
    },
    {
      "x": -5,
      "y": 33,
      "z": 4,
      "name": "Rock_Slate"
    },
    {
      "x": -5,
      "y": 34,
      "z": 4,
      "name": "Rock_Slate"
    },
    {
      "x": -5,
      "y": 35,
      "z": 4,
      "name": "Rock_Slate"
    },
    {
      "x": -5,
      "y": 36,
      "z": 4,
      "name": "Rock_Slate"
    },
    {
      "x": -5,
      "y": 37,
      "z": 4,
      "name": "Rock_Slate"
    },
    {
      "x": -5,
      "y": 38,
      "z": 4,
      "name": "Rock_Slate"
    },
    {
      "x": -5,
      "y": 39,
      "z": 4,
      "name": "Rock_Slate"
    },
    {
      "x": -5,
      "y": 40,
      "z": 4,
      "name": "Rock_Slate"
    },
    {
      "x": -5,
      "y": 41,
      "z": 4,
      "name": "Rock_Slate"
    },
    {
      "x": -5,
      "y": 42,
      "z": 4,
      "name": "Rock_Slate"
    },
    {
      "x": -5,
      "y": 43,
      "z": 4,
      "name": "Rock_Slate"
    },
    {
      "x": -5,
      "y": 44,
      "z": 4,
      "name": "Rock_Slate"
    },
    {
      "x": -5,
      "y": -4,
      "z": 5,
      "name": "Rock_Slate"
    },
    {
      "x": -5,
      "y": -3,
      "z": 5,
      "name": "Rock_Slate"
    },
    {
      "x": -5,
      "y": -2,
      "z": 5,
      "name": "Rock_Slate"
    },
    {
      "x": -5,
      "y": -1,
      "z": 5,
      "name": "Rock_Slate"
    },
    {
      "x": -5,
      "y": 0,
      "z": 5,
      "name": "Rock_Slate"
    },
    {
      "x": -5,
      "y": 1,
      "z": 5,
      "name": "Rock_Slate"
    },
    {
      "x": -5,
      "y": 2,
      "z": 5,
      "name": "Rock_Slate"
    },
    {
      "x": -5,
      "y": 3,
      "z": 5,
      "name": "Rock_Slate"
    },
    {
      "x": -5,
      "y": 4,
      "z": 5,
      "name": "Rock_Slate"
    },
    {
      "x": -5,
      "y": 5,
      "z": 5,
      "name": "Rock_Slate"
    },
    {
      "x": -5,
      "y": 6,
      "z": 5,
      "name": "Rock_Slate"
    },
    {
      "x": -5,
      "y": 7,
      "z": 5,
      "name": "Rock_Slate"
    },
    {
      "x": -5,
      "y": 8,
      "z": 5,
      "name": "Rock_Slate"
    },
    {
      "x": -5,
      "y": 9,
      "z": 5,
      "name": "Rock_Slate"
    },
    {
      "x": -5,
      "y": 10,
      "z": 5,
      "name": "Rock_Slate"
    },
    {
      "x": -5,
      "y": 11,
      "z": 5,
      "name": "Rock_Crystal_Red_Block"
    },
    {
      "x": -5,
      "y": 12,
      "z": 5,
      "name": "Rock_Crystal_Red_Block"
    },
    {
      "x": -5,
      "y": 13,
      "z": 5,
      "name": "Rock_Crystal_Red_Block"
    },
    {
      "x": -5,
      "y": 14,
      "z": 5,
      "name": "Rock_Crystal_Red_Block"
    },
    {
      "x": -5,
      "y": 15,
      "z": 5,
      "name": "Rock_Crystal_Red_Large"
    },
    {
      "x": -5,
      "y": 28,
      "z": 5,
      "name": "Rock_Slate"
    },
    {
      "x": -5,
      "y": 29,
      "z": 5,
      "name": "Rock_Slate"
    },
    {
      "x": -5,
      "y": 30,
      "z": 5,
      "name": "Rock_Slate"
    },
    {
      "x": -5,
      "y": 31,
      "z": 5,
      "name": "Rock_Slate"
    },
    {
      "x": -5,
      "y": 32,
      "z": 5,
      "name": "Rock_Slate"
    },
    {
      "x": -5,
      "y": 33,
      "z": 5,
      "name": "Rock_Slate"
    },
    {
      "x": -5,
      "y": 34,
      "z": 5,
      "name": "Rock_Slate"
    },
    {
      "x": -5,
      "y": 35,
      "z": 5,
      "name": "Rock_Slate"
    },
    {
      "x": -5,
      "y": 36,
      "z": 5,
      "name": "Rock_Slate"
    },
    {
      "x": -5,
      "y": 37,
      "z": 5,
      "name": "Rock_Slate"
    },
    {
      "x": -5,
      "y": 38,
      "z": 5,
      "name": "Rock_Slate"
    },
    {
      "x": -5,
      "y": 39,
      "z": 5,
      "name": "Rock_Slate"
    },
    {
      "x": -5,
      "y": 40,
      "z": 5,
      "name": "Rock_Slate"
    },
    {
      "x": -5,
      "y": 41,
      "z": 5,
      "name": "Rock_Slate"
    },
    {
      "x": -5,
      "y": 42,
      "z": 5,
      "name": "Rock_Slate"
    },
    {
      "x": -5,
      "y": 43,
      "z": 5,
      "name": "Rock_Slate"
    },
    {
      "x": -5,
      "y": 44,
      "z": 5,
      "name": "Rock_Slate"
    },
    {
      "x": -5,
      "y": 0,
      "z": 6,
      "name": "Rock_Slate"
    },
    {
      "x": -5,
      "y": 1,
      "z": 6,
      "name": "Rock_Slate"
    },
    {
      "x": -5,
      "y": 2,
      "z": 6,
      "name": "Rock_Slate"
    },
    {
      "x": -5,
      "y": 3,
      "z": 6,
      "name": "Rock_Slate"
    },
    {
      "x": -5,
      "y": 4,
      "z": 6,
      "name": "Rock_Slate"
    },
    {
      "x": -5,
      "y": 5,
      "z": 6,
      "name": "Rock_Slate"
    },
    {
      "x": -5,
      "y": 6,
      "z": 6,
      "name": "Rock_Slate"
    },
    {
      "x": -5,
      "y": 7,
      "z": 6,
      "name": "Rock_Slate"
    },
    {
      "x": -5,
      "y": 8,
      "z": 6,
      "name": "Rock_Slate"
    },
    {
      "x": -5,
      "y": 9,
      "z": 6,
      "name": "Rock_Slate"
    },
    {
      "x": -5,
      "y": 10,
      "z": 6,
      "name": "Rock_Slate"
    },
    {
      "x": -5,
      "y": 12,
      "z": 6,
      "name": "Rock_Crystal_Red_Block"
    },
    {
      "x": -5,
      "y": 13,
      "z": 6,
      "name": "Rock_Crystal_Red_Block"
    },
    {
      "x": -5,
      "y": 14,
      "z": 6,
      "name": "Rock_Crystal_Red_Block"
    },
    {
      "x": -5,
      "y": 15,
      "z": 6,
      "name": "Rock_Crystal_Red_Large"
    },
    {
      "x": -5,
      "y": 29,
      "z": 6,
      "name": "Rock_Slate"
    },
    {
      "x": -5,
      "y": 30,
      "z": 6,
      "name": "Rock_Slate"
    },
    {
      "x": -5,
      "y": 31,
      "z": 6,
      "name": "Rock_Slate"
    },
    {
      "x": -5,
      "y": 32,
      "z": 6,
      "name": "Rock_Slate"
    },
    {
      "x": -5,
      "y": 33,
      "z": 6,
      "name": "Rock_Slate"
    },
    {
      "x": -5,
      "y": 34,
      "z": 6,
      "name": "Rock_Slate"
    },
    {
      "x": -5,
      "y": 35,
      "z": 6,
      "name": "Rock_Slate"
    },
    {
      "x": -5,
      "y": 36,
      "z": 6,
      "name": "Rock_Slate"
    },
    {
      "x": -5,
      "y": 37,
      "z": 6,
      "name": "Rock_Slate"
    },
    {
      "x": -5,
      "y": 38,
      "z": 6,
      "name": "Rock_Slate"
    },
    {
      "x": -5,
      "y": 39,
      "z": 6,
      "name": "Rock_Slate"
    },
    {
      "x": -5,
      "y": 40,
      "z": 6,
      "name": "Rock_Slate"
    },
    {
      "x": -5,
      "y": 41,
      "z": 6,
      "name": "Rock_Slate"
    },
    {
      "x": -5,
      "y": 42,
      "z": 6,
      "name": "Rock_Slate"
    },
    {
      "x": -5,
      "y": 43,
      "z": 6,
      "name": "Rock_Slate"
    },
    {
      "x": -5,
      "y": 44,
      "z": 6,
      "name": "Rock_Slate"
    },
    {
      "x": -5,
      "y": 2,
      "z": 7,
      "name": "Rock_Slate"
    },
    {
      "x": -5,
      "y": 3,
      "z": 7,
      "name": "Rock_Slate"
    },
    {
      "x": -5,
      "y": 4,
      "z": 7,
      "name": "Rock_Slate"
    },
    {
      "x": -5,
      "y": 5,
      "z": 7,
      "name": "Rock_Slate"
    },
    {
      "x": -5,
      "y": 6,
      "z": 7,
      "name": "Rock_Slate"
    },
    {
      "x": -5,
      "y": 7,
      "z": 7,
      "name": "Rock_Slate"
    },
    {
      "x": -5,
      "y": 8,
      "z": 7,
      "name": "Rock_Slate"
    },
    {
      "x": -5,
      "y": 13,
      "z": 7,
      "name": "Rock_Crystal_Red_Large",
      "rotation": 4
    },
    {
      "x": -5,
      "y": 14,
      "z": 7,
      "name": "Rock_Crystal_Red_Large",
      "rotation": 4
    },
    {
      "x": -5,
      "y": 30,
      "z": 7,
      "name": "Rock_Slate"
    },
    {
      "x": -5,
      "y": 31,
      "z": 7,
      "name": "Rock_Slate"
    },
    {
      "x": -5,
      "y": 32,
      "z": 7,
      "name": "Rock_Slate"
    },
    {
      "x": -5,
      "y": 33,
      "z": 7,
      "name": "Rock_Slate"
    },
    {
      "x": -5,
      "y": 34,
      "z": 7,
      "name": "Rock_Slate"
    },
    {
      "x": -5,
      "y": 35,
      "z": 7,
      "name": "Rock_Slate"
    },
    {
      "x": -5,
      "y": 36,
      "z": 7,
      "name": "Rock_Slate"
    },
    {
      "x": -5,
      "y": 37,
      "z": 7,
      "name": "Rock_Slate"
    },
    {
      "x": -5,
      "y": 38,
      "z": 7,
      "name": "Rock_Slate"
    },
    {
      "x": -5,
      "y": 39,
      "z": 7,
      "name": "Rock_Slate"
    },
    {
      "x": -5,
      "y": 40,
      "z": 7,
      "name": "Rock_Slate"
    },
    {
      "x": -5,
      "y": 41,
      "z": 7,
      "name": "Rock_Slate"
    },
    {
      "x": -5,
      "y": 42,
      "z": 7,
      "name": "Rock_Slate"
    },
    {
      "x": -5,
      "y": 43,
      "z": 7,
      "name": "Rock_Slate"
    },
    {
      "x": -5,
      "y": 44,
      "z": 7,
      "name": "Rock_Slate"
    },
    {
      "x": -5,
      "y": 31,
      "z": 8,
      "name": "Rock_Slate"
    },
    {
      "x": -5,
      "y": 32,
      "z": 8,
      "name": "Rock_Slate"
    },
    {
      "x": -5,
      "y": 33,
      "z": 8,
      "name": "Rock_Slate"
    },
    {
      "x": -5,
      "y": 34,
      "z": 8,
      "name": "Rock_Slate"
    },
    {
      "x": -5,
      "y": 35,
      "z": 8,
      "name": "Rock_Slate"
    },
    {
      "x": -5,
      "y": 36,
      "z": 8,
      "name": "Rock_Slate"
    },
    {
      "x": -5,
      "y": 37,
      "z": 8,
      "name": "Rock_Slate"
    },
    {
      "x": -5,
      "y": 38,
      "z": 8,
      "name": "Rock_Slate"
    },
    {
      "x": -5,
      "y": 39,
      "z": 8,
      "name": "Rock_Slate"
    },
    {
      "x": -5,
      "y": 40,
      "z": 8,
      "name": "Rock_Slate"
    },
    {
      "x": -5,
      "y": 41,
      "z": 8,
      "name": "Rock_Slate"
    },
    {
      "x": -5,
      "y": 42,
      "z": 8,
      "name": "Rock_Slate"
    },
    {
      "x": -5,
      "y": 43,
      "z": 8,
      "name": "Rock_Slate"
    },
    {
      "x": -5,
      "y": 33,
      "z": 9,
      "name": "Rock_Slate"
    },
    {
      "x": -5,
      "y": 34,
      "z": 9,
      "name": "Rock_Slate"
    },
    {
      "x": -5,
      "y": 35,
      "z": 9,
      "name": "Rock_Slate"
    },
    {
      "x": -5,
      "y": 36,
      "z": 9,
      "name": "Rock_Slate"
    },
    {
      "x": -5,
      "y": 37,
      "z": 9,
      "name": "Rock_Slate"
    },
    {
      "x": -5,
      "y": 38,
      "z": 9,
      "name": "Rock_Slate"
    },
    {
      "x": -5,
      "y": 39,
      "z": 9,
      "name": "Rock_Slate"
    },
    {
      "x": -5,
      "y": 40,
      "z": 9,
      "name": "Rock_Slate"
    },
    {
      "x": -5,
      "y": 41,
      "z": 9,
      "name": "Rock_Slate"
    },
    {
      "x": -5,
      "y": 42,
      "z": 9,
      "name": "Rock_Slate"
    },
    {
      "x": -5,
      "y": 43,
      "z": 9,
      "name": "Rock_Slate"
    },
    {
      "x": -5,
      "y": 35,
      "z": 10,
      "name": "Rock_Slate"
    },
    {
      "x": -5,
      "y": 36,
      "z": 10,
      "name": "Rock_Slate"
    },
    {
      "x": -5,
      "y": 37,
      "z": 10,
      "name": "Rock_Slate"
    },
    {
      "x": -5,
      "y": 38,
      "z": 10,
      "name": "Rock_Slate"
    },
    {
      "x": -5,
      "y": 39,
      "z": 10,
      "name": "Rock_Slate"
    },
    {
      "x": -5,
      "y": 40,
      "z": 10,
      "name": "Rock_Slate"
    },
    {
      "x": -5,
      "y": 41,
      "z": 10,
      "name": "Rock_Slate"
    },
    {
      "x": -5,
      "y": 42,
      "z": 10,
      "name": "Rock_Slate"
    },
    {
      "x": -5,
      "y": 37,
      "z": 11,
      "name": "Rock_Slate"
    },
    {
      "x": -5,
      "y": 38,
      "z": 11,
      "name": "Rock_Slate"
    },
    {
      "x": -5,
      "y": 39,
      "z": 11,
      "name": "Rock_Slate"
    },
    {
      "x": -5,
      "y": 40,
      "z": 11,
      "name": "Rock_Slate"
    },
    {
      "x": -4,
      "y": 38,
      "z": -4,
      "name": "Rock_Slate"
    },
    {
      "x": -4,
      "y": 39,
      "z": -4,
      "name": "Rock_Slate"
    },
    {
      "x": -4,
      "y": 40,
      "z": -4,
      "name": "Rock_Slate"
    },
    {
      "x": -4,
      "y": -3,
      "z": -3,
      "name": "Rock_Slate"
    },
    {
      "x": -4,
      "y": -2,
      "z": -3,
      "name": "Rock_Slate"
    },
    {
      "x": -4,
      "y": -1,
      "z": -3,
      "name": "Rock_Slate"
    },
    {
      "x": -4,
      "y": 0,
      "z": -3,
      "name": "Rock_Slate"
    },
    {
      "x": -4,
      "y": 1,
      "z": -3,
      "name": "Rock_Slate"
    },
    {
      "x": -4,
      "y": 3,
      "z": -3,
      "name": "Rock_Slate"
    },
    {
      "x": -4,
      "y": 4,
      "z": -3,
      "name": "Rock_Slate"
    },
    {
      "x": -4,
      "y": 5,
      "z": -3,
      "name": "Rock_Slate"
    },
    {
      "x": -4,
      "y": 6,
      "z": -3,
      "name": "Rock_Slate"
    },
    {
      "x": -4,
      "y": 7,
      "z": -3,
      "name": "Rock_Slate"
    },
    {
      "x": -4,
      "y": 8,
      "z": -3,
      "name": "Rock_Slate"
    },
    {
      "x": -4,
      "y": 36,
      "z": -3,
      "name": "Rock_Slate"
    },
    {
      "x": -4,
      "y": 37,
      "z": -3,
      "name": "Rock_Slate"
    },
    {
      "x": -4,
      "y": 38,
      "z": -3,
      "name": "Rock_Slate"
    },
    {
      "x": -4,
      "y": 39,
      "z": -3,
      "name": "Rock_Slate"
    },
    {
      "x": -4,
      "y": 40,
      "z": -3,
      "name": "Rock_Slate"
    },
    {
      "x": -4,
      "y": 41,
      "z": -3,
      "name": "Rock_Slate"
    },
    {
      "x": -4,
      "y": 42,
      "z": -3,
      "name": "Rock_Slate"
    },
    {
      "x": -4,
      "y": -4,
      "z": -2,
      "name": "Rock_Slate"
    },
    {
      "x": -4,
      "y": -3,
      "z": -2,
      "name": "Rock_Slate"
    },
    {
      "x": -4,
      "y": -2,
      "z": -2,
      "name": "Rock_Slate"
    },
    {
      "x": -4,
      "y": -1,
      "z": -2,
      "name": "Rock_Slate"
    },
    {
      "x": -4,
      "y": 0,
      "z": -2,
      "name": "Rock_Slate"
    },
    {
      "x": -4,
      "y": 1,
      "z": -2,
      "name": "Rock_Slate"
    },
    {
      "x": -4,
      "y": 2,
      "z": -2,
      "name": "Rock_Slate"
    },
    {
      "x": -4,
      "y": 3,
      "z": -2,
      "name": "Rock_Slate"
    },
    {
      "x": -4,
      "y": 4,
      "z": -2,
      "name": "Rock_Slate"
    },
    {
      "x": -4,
      "y": 5,
      "z": -2,
      "name": "Rock_Slate"
    },
    {
      "x": -4,
      "y": 6,
      "z": -2,
      "name": "Rock_Slate"
    },
    {
      "x": -4,
      "y": 7,
      "z": -2,
      "name": "Rock_Slate"
    },
    {
      "x": -4,
      "y": 8,
      "z": -2,
      "name": "Rock_Slate"
    },
    {
      "x": -4,
      "y": 9,
      "z": -2,
      "name": "Rock_Slate"
    },
    {
      "x": -4,
      "y": 10,
      "z": -2,
      "name": "Rock_Slate"
    },
    {
      "x": -4,
      "y": 11,
      "z": -2,
      "name": "Rock_Slate"
    },
    {
      "x": -4,
      "y": 12,
      "z": -2,
      "name": "Rock_Slate"
    },
    {
      "x": -4,
      "y": 33,
      "z": -2,
      "name": "Rock_Slate"
    },
    {
      "x": -4,
      "y": 34,
      "z": -2,
      "name": "Rock_Slate"
    },
    {
      "x": -4,
