{
  "version": 8,
  "blockIdVersion": 8,
  "anchorX": 0,
  "anchorY": 22,
  "anchorZ": 1,
  "blocks": [
    {
      "x": -13,
      "y": 17,
      "z": -8,
      "name": "Rock_Stone"
    },
    {
      "x": -13,
      "y": 16,
      "z": -7,
      "name": "Rock_Stone"
    },
    {
      "x": -13,
      "y": 17,
      "z": -7,
      "name": "Rock_Stone"
    },
    {
      "x": -13,
      "y": 15,
      "z": -6,
      "name": "Rock_Stone"
    },
    {
      "x": -13,
      "y": 16,
      "z": -6,
      "name": "Rock_Stone"
    },
    {
      "x": -13,
      "y": 17,
      "z": -6,
      "name": "Rock_Stone"
    },
    {
      "x": -13,
      "y": 16,
      "z": -5,
      "name": "Rock_Stone"
    },
    {
      "x": -13,
      "y": 39,
      "z": 2,
      "name": "Soil_Grass"
    },
    {
      "x": -13,
      "y": 39,
      "z": 3,
      "name": "Soil_Grass"
    },
    {
      "x": -13,
      "y": 39,
      "z": 4,
      "name": "Soil_Grass"
    },
    {
      "x": -13,
      "y": 39,
      "z": 5,
      "name": "Soil_Grass"
    },
    {
      "x": -13,
      "y": 40,
      "z": 5,
      "name": "Plant_Grass_Sharp_Tall"
    },
    {
      "x": -13,
      "y": 41,
      "z": 5,
      "name": "Plant_Grass_Sharp_Tall",
      "filler": 1024
    },
    {
      "x": -12,
      "y": 16,
      "z": -9,
      "name": "Rock_Stone"
    },
    {
      "x": -12,
      "y": 17,
      "z": -9,
      "name": "Rock_Stone"
    },
    {
      "x": -12,
      "y": 18,
      "z": -9,
      "name": "Rock_Stone"
    },
    {
      "x": -12,
      "y": 15,
      "z": -8,
      "name": "Rock_Stone"
    },
    {
      "x": -12,
      "y": 16,
      "z": -8,
      "name": "Rock_Stone"
    },
    {
      "x": -12,
      "y": 17,
      "z": -8,
      "name": "Rock_Stone"
    },
    {
      "x": -12,
      "y": 18,
      "z": -8,
      "name": "Rock_Stone"
    },
    {
      "x": -12,
      "y": 15,
      "z": -7,
      "name": "Rock_Stone"
    },
    {
      "x": -12,
      "y": 16,
      "z": -7,
      "name": "Rock_Stone"
    },
    {
      "x": -12,
      "y": 17,
      "z": -7,
      "name": "Rock_Stone"
    },
    {
      "x": -12,
      "y": 18,
      "z": -7,
      "name": "Rock_Stone"
    },
    {
      "x": -12,
      "y": 15,
      "z": -6,
      "name": "Rock_Stone"
    },
    {
      "x": -12,
      "y": 16,
      "z": -6,
      "name": "Rock_Stone"
    },
    {
      "x": -12,
      "y": 17,
      "z": -6,
      "name": "Rock_Stone"
    },
    {
      "x": -12,
      "y": 18,
      "z": -6,
      "name": "Rock_Stone"
    },
    {
      "x": -12,
      "y": 15,
      "z": -5,
      "name": "Rock_Stone"
    },
    {
      "x": -12,
      "y": 16,
      "z": -5,
      "name": "Rock_Stone"
    },
    {
      "x": -12,
      "y": 17,
      "z": -5,
      "name": "Rock_Stone"
    },
    {
      "x": -12,
      "y": 18,
      "z": -5,
      "name": "Rock_Stone"
    },
    {
      "x": -12,
      "y": 15,
      "z": -4,
      "name": "Rock_Stone"
    },
    {
      "x": -12,
      "y": 16,
      "z": -4,
      "name": "Rock_Stone"
    },
    {
      "x": -12,
      "y": 17,
      "z": -4,
      "name": "Rock_Stone"
    },
    {
      "x": -12,
      "y": 16,
      "z": -3,
      "name": "Rock_Stone"
    },
    {
      "x": -12,
      "y": 39,
      "z": 1,
      "name": "Soil_Grass"
    },
    {
      "x": -12,
      "y": 39,
      "z": 2,
      "name": "Soil_Grass"
    },
    {
      "x": -12,
      "y": 38,
      "z": 3,
      "name": "Soil_Dirt"
    },
    {
      "x": -12,
      "y": 39,
      "z": 3,
      "name": "Soil_Grass"
    },
    {
      "x": -12,
      "y": 40,
      "z": 3,
      "name": "Plant_Grass_Sharp_Tall"
    },
    {
      "x": -12,
      "y": 41,
      "z": 3,
      "name": "Plant_Grass_Sharp_Tall",
      "filler": 1024
    },
    {
      "x": -12,
      "y": 38,
      "z": 4,
      "name": "Soil_Dirt"
    },
    {
      "x": -12,
      "y": 39,
      "z": 4,
      "name": "Soil_Grass"
    },
    {
      "x": -12,
      "y": 40,
      "z": 4,
      "name": "Plant_Grass_Sharp_Tall"
    },
    {
      "x": -12,
      "y": 41,
      "z": 4,
      "name": "Plant_Grass_Sharp_Tall",
      "filler": 1024
    },
    {
      "x": -12,
      "y": 38,
      "z": 5,
      "name": "Soil_Dirt"
    },
    {
      "x": -12,
      "y": 39,
      "z": 5,
      "name": "Soil_Grass"
    },
    {
      "x": -12,
      "y": 40,
      "z": 5,
      "name": "Plant_Grass_Sharp"
    },
    {
      "x": -12,
      "y": 38,
      "z": 6,
      "name": "Soil_Dirt"
    },
    {
      "x": -12,
      "y": 39,
      "z": 6,
      "name": "Soil_Grass"
    },
    {
      "x": -12,
      "y": 40,
      "z": 6,
      "name": "Plant_Grass_Sharp"
    },
    {
      "x": -11,
      "y": 17,
      "z": -10,
      "name": "Rock_Stone"
    },
    {
      "x": -11,
      "y": 15,
      "z": -9,
      "name": "Rock_Stone"
    },
    {
      "x": -11,
      "y": 16,
      "z": -9,
      "name": "Rock_Stone"
    },
    {
      "x": -11,
      "y": 17,
      "z": -9,
      "name": "Rock_Stone"
    },
    {
      "x": -11,
      "y": 18,
      "z": -9,
      "name": "Rock_Stone"
    },
    {
      "x": -11,
      "y": 15,
      "z": -8,
      "name": "Rock_Stone"
    },
    {
      "x": -11,
      "y": 16,
      "z": -8,
      "name": "Rock_Stone"
    },
    {
      "x": -11,
      "y": 17,
      "z": -8,
      "name": "Rock_Stone"
    },
    {
      "x": -11,
      "y": 18,
      "z": -8,
      "name": "Rock_Stone"
    },
    {
      "x": -11,
      "y": 14,
      "z": -7,
      "name": "Rock_Stone"
    },
    {
      "x": -11,
      "y": 15,
      "z": -7,
      "name": "Rock_Stone"
    },
    {
      "x": -11,
      "y": 16,
      "z": -7,
      "name": "Rock_Stone"
    },
    {
      "x": -11,
      "y": 17,
      "z": -7,
      "name": "Rock_Stone"
    },
    {
      "x": -11,
      "y": 18,
      "z": -7,
      "name": "Rock_Stone"
    },
    {
      "x": -11,
      "y": 19,
      "z": -7,
      "name": "Rock_Stone"
    },
    {
      "x": -11,
      "y": 14,
      "z": -6,
      "name": "Rock_Stone"
    },
    {
      "x": -11,
      "y": 15,
      "z": -6,
      "name": "Rock_Stone"
    },
    {
      "x": -11,
      "y": 16,
      "z": -6,
      "name": "Rock_Stone"
    },
    {
      "x": -11,
      "y": 17,
      "z": -6,
      "name": "Rock_Stone"
    },
    {
      "x": -11,
      "y": 18,
      "z": -6,
      "name": "Rock_Stone"
    },
    {
      "x": -11,
      "y": 19,
      "z": -6,
      "name": "Rock_Stone"
    },
    {
      "x": -11,
      "y": 14,
      "z": -5,
      "name": "Rock_Stone"
    },
    {
      "x": -11,
      "y": 15,
      "z": -5,
      "name": "Rock_Stone"
    },
    {
      "x": -11,
      "y": 16,
      "z": -5,
      "name": "Rock_Stone"
    },
    {
      "x": -11,
      "y": 17,
      "z": -5,
      "name": "Rock_Stone"
    },
    {
      "x": -11,
      "y": 18,
      "z": -5,
      "name": "Rock_Stone"
    },
    {
      "x": -11,
      "y": 19,
      "z": -5,
      "name": "Rock_Stone"
    },
    {
      "x": -11,
      "y": 15,
      "z": -4,
      "name": "Rock_Stone"
    },
    {
      "x": -11,
      "y": 16,
      "z": -4,
      "name": "Rock_Stone"
    },
    {
      "x": -11,
      "y": 17,
      "z": -4,
      "name": "Rock_Stone"
    },
    {
      "x": -11,
      "y": 18,
      "z": -4,
      "name": "Rock_Stone"
    },
    {
      "x": -11,
      "y": 19,
      "z": -4,
      "name": "Rock_Stone"
    },
    {
      "x": -11,
      "y": 15,
      "z": -3,
      "name": "Rock_Stone"
    },
    {
      "x": -11,
      "y": 16,
      "z": -3,
      "name": "Rock_Stone"
    },
    {
      "x": -11,
      "y": 17,
      "z": -3,
      "name": "Rock_Stone"
    },
    {
      "x": -11,
      "y": 18,
      "z": -3,
      "name": "Rock_Stone"
    },
    {
      "x": -11,
      "y": 19,
      "z": -3,
      "name": "Rock_Stone"
    },
    {
      "x": -11,
      "y": 17,
      "z": -2,
      "name": "Rock_Stone"
    },
    {
      "x": -11,
      "y": 18,
      "z": -2,
      "name": "Rock_Stone"
    },
    {
      "x": -11,
      "y": 38,
      "z": 1,
      "name": "Soil_Dirt"
    },
    {
      "x": -11,
      "y": 39,
      "z": 1,
      "name": "Soil_Grass"
    },
    {
      "x": -11,
      "y": 38,
      "z": 2,
      "name": "Soil_Dirt"
    },
    {
      "x": -11,
      "y": 39,
      "z": 2,
      "name": "Soil_Grass"
    },
    {
      "x": -11,
      "y": 40,
      "z": 2,
      "name": "Plant_Grass_Sharp"
    },
    {
      "x": -11,
      "y": 38,
      "z": 3,
      "name": "Soil_Dirt"
    },
    {
      "x": -11,
      "y": 39,
      "z": 3,
      "name": "Soil_Grass"
    },
    {
      "x": -11,
      "y": 40,
      "z": 3,
      "name": "Plant_Grass_Sharp_Tall"
    },
    {
      "x": -11,
      "y": 41,
      "z": 3,
      "name": "Plant_Grass_Sharp_Tall",
      "filler": 1024
    },
    {
      "x": -11,
      "y": 38,
      "z": 4,
      "name": "Soil_Dirt"
    },
    {
      "x": -11,
      "y": 39,
      "z": 4,
      "name": "Soil_Dirt"
    },
    {
      "x": -11,
      "y": 40,
      "z": 4,
      "name": "Soil_Grass"
    },
    {
      "x": -11,
      "y": 38,
      "z": 5,
      "name": "Soil_Dirt"
    },
    {
      "x": -11,
      "y": 39,
      "z": 5,
      "name": "Soil_Dirt"
    },
    {
      "x": -11,
      "y": 40,
      "z": 5,
      "name": "Soil_Grass"
    },
    {
      "x": -11,
      "y": 38,
      "z": 6,
      "name": "Soil_Dirt"
    },
    {
      "x": -11,
      "y": 39,
      "z": 6,
      "name": "Soil_Dirt"
    },
    {
      "x": -11,
      "y": 40,
      "z": 6,
      "name": "Soil_Grass"
    },
    {
      "x": -11,
      "y": 38,
      "z": 7,
      "name": "Soil_Dirt"
    },
    {
      "x": -11,
      "y": 39,
      "z": 7,
      "name": "Soil_Dirt"
    },
    {
      "x": -11,
      "y": 40,
      "z": 7,
      "name": "Soil_Grass"
    },
    {
      "x": -11,
      "y": 41,
      "z": 7,
      "name": "Plant_Bush_Arid_Red"
    },
    {
      "x": -10,
      "y": 16,
      "z": -10,
      "name": "Rock_Stone"
    },
    {
      "x": -10,
      "y": 17,
      "z": -10,
      "name": "Rock_Stone"
    },
    {
      "x": -10,
      "y": 18,
      "z": -10,
      "name": "Rock_Stone"
    },
    {
      "x": -10,
      "y": 15,
      "z": -9,
      "name": "Rock_Stone"
    },
    {
      "x": -10,
      "y": 16,
      "z": -9,
      "name": "Rock_Stone"
    },
    {
      "x": -10,
      "y": 17,
      "z": -9,
      "name": "Rock_Stone"
    },
    {
      "x": -10,
      "y": 18,
      "z": -9,
      "name": "Rock_Stone"
    },
    {
      "x": -10,
      "y": 14,
      "z": -8,
      "name": "Rock_Stone"
    },
    {
      "x": -10,
      "y": 15,
      "z": -8,
      "name": "Rock_Stone"
    },
    {
      "x": -10,
      "y": 16,
      "z": -8,
      "name": "Rock_Stone"
    },
    {
      "x": -10,
      "y": 17,
      "z": -8,
      "name": "Rock_Stone"
    },
    {
      "x": -10,
      "y": 18,
      "z": -8,
      "name": "Rock_Stone"
    },
    {
      "x": -10,
      "y": 19,
      "z": -8,
      "name": "Rock_Stone"
    },
    {
      "x": -10,
      "y": 14,
      "z": -7,
      "name": "Rock_Stone"
    },
    {
      "x": -10,
      "y": 15,
      "z": -7,
      "name": "Rock_Stone"
    },
    {
      "x": -10,
      "y": 16,
      "z": -7,
      "name": "Rock_Stone"
    },
    {
      "x": -10,
      "y": 17,
      "z": -7,
      "name": "Rock_Stone"
    },
    {
      "x": -10,
      "y": 18,
      "z": -7,
      "name": "Rock_Stone"
    },
    {
      "x": -10,
      "y": 19,
      "z": -7,
      "name": "Rock_Stone"
    },
    {
      "x": -10,
      "y": 20,
      "z": -7,
      "name": "Rock_Stone"
    },
    {
      "x": -10,
      "y": 14,
      "z": -6,
      "name": "Rock_Stone"
    },
    {
      "x": -10,
      "y": 15,
      "z": -6,
      "name": "Rock_Stone"
    },
    {
      "x": -10,
      "y": 16,
      "z": -6,
      "name": "Rock_Stone"
    },
    {
      "x": -10,
      "y": 17,
      "z": -6,
      "name": "Rock_Stone"
    },
    {
      "x": -10,
      "y": 18,
      "z": -6,
      "name": "Rock_Stone"
    },
    {
      "x": -10,
      "y": 19,
      "z": -6,
      "name": "Rock_Stone"
    },
    {
      "x": -10,
      "y": 20,
      "z": -6,
      "name": "Rock_Stone"
    },
    {
      "x": -10,
      "y": 14,
      "z": -5,
      "name": "Rock_Stone"
    },
    {
      "x": -10,
      "y": 15,
      "z": -5,
      "name": "Rock_Stone"
    },
    {
      "x": -10,
      "y": 16,
      "z": -5,
      "name": "Rock_Stone"
    },
    {
      "x": -10,
      "y": 17,
      "z": -5,
      "name": "Rock_Stone"
    },
    {
      "x": -10,
      "y": 18,
      "z": -5,
      "name": "Rock_Stone"
    },
    {
      "x": -10,
      "y": 19,
      "z": -5,
      "name": "Rock_Stone"
    },
    {
      "x": -10,
      "y": 20,
      "z": -5,
      "name": "Rock_Stone"
    },
    {
      "x": -10,
      "y": 14,
      "z": -4,
      "name": "Rock_Stone"
    },
    {
      "x": -10,
      "y": 15,
      "z": -4,
      "name": "Rock_Stone"
    },
    {
      "x": -10,
      "y": 16,
      "z": -4,
      "name": "Rock_Stone"
    },
    {
      "x": -10,
      "y": 17,
      "z": -4,
      "name": "Rock_Stone"
    },
    {
      "x": -10,
      "y": 18,
      "z": -4,
      "name": "Rock_Stone"
    },
    {
      "x": -10,
      "y": 19,
      "z": -4,
      "name": "Rock_Stone"
    },
    {
      "x": -10,
      "y": 20,
      "z": -4,
      "name": "Rock_Stone"
    },
    {
      "x": -10,
      "y": 14,
      "z": -3,
      "name": "Rock_Stone"
    },
    {
      "x": -10,
      "y": 15,
      "z": -3,
      "name": "Rock_Stone"
    },
    {
      "x": -10,
      "y": 16,
      "z": -3,
      "name": "Rock_Stone"
    },
    {
      "x": -10,
      "y": 17,
      "z": -3,
      "name": "Rock_Stone"
    },
    {
      "x": -10,
      "y": 18,
      "z": -3,
      "name": "Rock_Stone"
    },
    {
      "x": -10,
      "y": 19,
      "z": -3,
      "name": "Rock_Stone"
    },
    {
      "x": -10,
      "y": 20,
      "z": -3,
      "name": "Rock_Stone"
    },
    {
      "x": -10,
      "y": 15,
      "z": -2,
      "name": "Rock_Stone"
    },
    {
      "x": -10,
      "y": 16,
      "z": -2,
      "name": "Rock_Stone"
    },
    {
      "x": -10,
      "y": 17,
      "z": -2,
      "name": "Rock_Stone"
    },
    {
      "x": -10,
      "y": 18,
      "z": -2,
      "name": "Rock_Stone"
    },
    {
      "x": -10,
      "y": 19,
      "z": -2,
      "name": "Rock_Stone"
    },
    {
      "x": -10,
      "y": 20,
      "z": -2,
      "name": "Rock_Stone"
    },
    {
      "x": -10,
      "y": 21,
      "z": -2,
      "name": "Rock_Stone"
    },
    {
      "x": -10,
      "y": 16,
      "z": -1,
      "name": "Rock_Stone"
    },
    {
      "x": -10,
      "y": 17,
      "z": -1,
      "name": "Rock_Stone"
    },
    {
      "x": -10,
      "y": 18,
      "z": -1,
      "name": "Rock_Stone"
    },
    {
      "x": -10,
      "y": 19,
      "z": -1,
      "name": "Rock_Stone"
    },
    {
      "x": -10,
      "y": 20,
      "z": -1,
      "name": "Rock_Stone"
    },
    {
      "x": -10,
      "y": 21,
      "z": -1,
      "name": "Rock_Stone"
    },
    {
      "x": -10,
      "y": 18,
      "z": 0,
      "name": "Rock_Stone"
    },
    {
      "x": -10,
      "y": 19,
      "z": 0,
      "name": "Rock_Stone"
    },
    {
      "x": -10,
      "y": 38,
      "z": 1,
      "name": "Soil_Dirt"
    },
    {
      "x": -10,
      "y": 39,
      "z": 1,
      "name": "Soil_Grass"
    },
    {
      "x": -10,
      "y": 38,
      "z": 2,
      "name": "Soil_Dirt"
    },
    {
      "x": -10,
      "y": 39,
      "z": 2,
      "name": "Soil_Dirt"
    },
    {
      "x": -10,
      "y": 40,
      "z": 2,
      "name": "Soil_Grass"
    },
    {
      "x": -10,
      "y": 41,
      "z": 2,
      "name": "Plant_Grass_Sharp"
    },
    {
      "x": -10,
      "y": 38,
      "z": 3,
      "name": "Soil_Dirt"
    },
    {
      "x": -10,
      "y": 39,
      "z": 3,
      "name": "Soil_Dirt"
    },
    {
      "x": -10,
      "y": 40,
      "z": 3,
      "name": "Soil_Grass"
    },
    {
      "x": -10,
      "y": 41,
      "z": 3,
      "name": "Plant_Grass_Sharp"
    },
    {
      "x": -10,
      "y": 38,
      "z": 4,
      "name": "Soil_Dirt"
    },
    {
      "x": -10,
      "y": 39,
      "z": 4,
      "name": "Soil_Dirt"
    },
    {
      "x": -10,
      "y": 40,
      "z": 4,
      "name": "Soil_Grass"
    },
    {
      "x": -10,
      "y": 41,
      "z": 4,
      "name": "Plant_Grass_Sharp"
    },
    {
      "x": -10,
      "y": 38,
      "z": 5,
      "name": "Soil_Dirt"
    },
    {
      "x": -10,
      "y": 39,
      "z": 5,
      "name": "Soil_Dirt"
    },
    {
      "x": -10,
      "y": 40,
      "z": 5,
      "name": "Soil_Grass"
    },
    {
      "x": -10,
      "y": 38,
      "z": 6,
      "name": "Soil_Dirt"
    },
    {
      "x": -10,
      "y": 39,
      "z": 6,
      "name": "Soil_Dirt"
    },
    {
      "x": -10,
      "y": 40,
      "z": 6,
      "name": "Soil_Grass"
    },
    {
      "x": -10,
      "y": 41,
      "z": 6,
      "name": "Plant_Bush_Arid_Red"
    },
    {
      "x": -10,
      "y": 38,
      "z": 7,
      "name": "Soil_Dirt"
    },
    {
      "x": -10,
      "y": 39,
      "z": 7,
      "name": "Soil_Dirt"
    },
    {
      "x": -10,
      "y": 40,
      "z": 7,
      "name": "Soil_Grass"
    },
    {
      "x": -10,
      "y": 41,
      "z": 7,
      "name": "Plant_Bush_Arid_Red"
    },
    {
      "x": -9,
      "y": 17,
      "z": -11,
      "name": "Rock_Stone"
    },
    {
      "x": -9,
      "y": 15,
      "z": -10,
      "name": "Rock_Stone"
    },
    {
      "x": -9,
      "y": 16,
      "z": -10,
      "name": "Rock_Stone"
    },
    {
      "x": -9,
      "y": 17,
      "z": -10,
      "name": "Rock_Stone"
    },
    {
      "x": -9,
      "y": 18,
      "z": -10,
      "name": "Rock_Stone"
    },
    {
      "x": -9,
      "y": 15,
      "z": -9,
      "name": "Rock_Stone"
    },
    {
      "x": -9,
      "y": 16,
      "z": -9,
      "name": "Rock_Stone"
    },
    {
      "x": -9,
      "y": 17,
      "z": -9,
      "name": "Rock_Stone"
    },
    {
      "x": -9,
      "y": 18,
      "z": -9,
      "name": "Rock_Stone"
    },
    {
      "x": -9,
      "y": 19,
      "z": -9,
      "name": "Rock_Stone"
    },
    {
      "x": -9,
      "y": 14,
      "z": -8,
      "name": "Rock_Stone"
    },
    {
      "x": -9,
      "y": 15,
      "z": -8,
      "name": "Rock_Stone"
    },
    {
      "x": -9,
      "y": 16,
      "z": -8,
      "name": "Rock_Stone"
    },
    {
      "x": -9,
      "y": 17,
      "z": -8,
      "name": "Rock_Stone"
    },
    {
      "x": -9,
      "y": 18,
      "z": -8,
      "name": "Rock_Stone"
    },
    {
      "x": -9,
      "y": 19,
      "z": -8,
      "name": "Rock_Stone"
    },
    {
      "x": -9,
      "y": 14,
      "z": -7,
      "name": "Rock_Stone"
    },
    {
      "x": -9,
      "y": 15,
      "z": -7,
      "name": "Rock_Stone"
    },
    {
      "x": -9,
      "y": 16,
      "z": -7,
      "name": "Rock_Stone"
    },
    {
      "x": -9,
      "y": 17,
      "z": -7,
      "name": "Rock_Stone"
    },
    {
      "x": -9,
      "y": 18,
      "z": -7,
      "name": "Rock_Stone"
    },
    {
      "x": -9,
      "y": 19,
      "z": -7,
      "name": "Rock_Stone"
    },
    {
      "x": -9,
      "y": 20,
      "z": -7,
      "name": "Rock_Stone"
    },
    {
      "x": -9,
      "y": 14,
      "z": -6,
      "name": "Rock_Stone"
    },
    {
      "x": -9,
      "y": 15,
      "z": -6,
      "name": "Rock_Stone"
    },
    {
      "x": -9,
      "y": 16,
      "z": -6,
      "name": "Rock_Stone"
    },
    {
      "x": -9,
      "y": 17,
      "z": -6,
      "name": "Rock_Stone"
    },
    {
      "x": -9,
      "y": 18,
      "z": -6,
      "name": "Rock_Stone"
    },
    {
      "x": -9,
      "y": 19,
      "z": -6,
      "name": "Rock_Stone"
    },
    {
      "x": -9,
      "y": 20,
      "z": -6,
      "name": "Rock_Stone"
    },
    {
      "x": -9,
      "y": 14,
      "z": -5,
      "name": "Rock_Stone"
    },
    {
      "x": -9,
      "y": 15,
      "z": -5,
      "name": "Rock_Stone"
    },
    {
      "x": -9,
      "y": 16,
      "z": -5,
      "name": "Rock_Stone"
    },
    {
      "x": -9,
      "y": 17,
      "z": -5,
      "name": "Rock_Stone"
    },
    {
      "x": -9,
      "y": 18,
      "z": -5,
      "name": "Rock_Stone"
    },
    {
      "x": -9,
      "y": 19,
      "z": -5,
      "name": "Rock_Stone"
    },
    {
      "x": -9,
      "y": 20,
      "z": -5,
      "name": "Rock_Stone"
    },
    {
      "x": -9,
      "y": 13,
      "z": -4,
      "name": "Rock_Stone"
    },
    {
      "x": -9,
      "y": 14,
      "z": -4,
      "name": "Rock_Stone"
    },
    {
      "x": -9,
      "y": 15,
      "z": -4,
      "name": "Rock_Stone"
    },
    {
      "x": -9,
      "y": 16,
      "z": -4,
      "name": "Rock_Stone"
    },
    {
      "x": -9,
      "y": 17,
      "z": -4,
      "name": "Rock_Stone"
    },
    {
      "x": -9,
      "y": 18,
      "z": -4,
      "name": "Rock_Stone"
    },
    {
      "x": -9,
      "y": 19,
      "z": -4,
      "name": "Rock_Stone"
    },
    {
      "x": -9,
      "y": 20,
      "z": -4,
      "name": "Rock_Stone"
    },
    {
      "x": -9,
      "y": 21,
      "z": -4,
      "name": "Rock_Stone"
    },
    {
      "x": -9,
      "y": 14,
      "z": -3,
      "name": "Rock_Stone"
    },
    {
      "x": -9,
      "y": 15,
      "z": -3,
      "name": "Rock_Stone"
    },
    {
      "x": -9,
      "y": 16,
      "z": -3,
      "name": "Rock_Stone"
    },
    {
      "x": -9,
      "y": 17,
      "z": -3,
      "name": "Rock_Stone"
    },
    {
      "x": -9,
      "y": 18,
      "z": -3,
      "name": "Rock_Stone"
    },
    {
      "x": -9,
      "y": 19,
      "z": -3,
      "name": "Rock_Stone"
    },
    {
      "x": -9,
      "y": 20,
      "z": -3,
      "name": "Rock_Stone"
    },
    {
      "x": -9,
      "y": 21,
      "z": -3,
      "name": "Rock_Stone"
    },
    {
      "x": -9,
      "y": 14,
      "z": -2,
      "name": "Rock_Stone"
    },
    {
      "x": -9,
      "y": 15,
      "z": -2,
      "name": "Rock_Stone"
    },
    {
      "x": -9,
      "y": 16,
      "z": -2,
      "name": "Rock_Stone"
    },
    {
      "x": -9,
      "y": 17,
      "z": -2,
      "name": "Rock_Stone"
    },
    {
      "x": -9,
      "y": 18,
      "z": -2,
      "name": "Rock_Stone"
    },
    {
      "x": -9,
      "y": 19,
      "z": -2,
      "name": "Rock_Stone"
    },
    {
      "x": -9,
      "y": 20,
      "z": -2,
      "name": "Rock_Stone"
    },
    {
      "x": -9,
      "y": 21,
      "z": -2,
      "name": "Rock_Stone"
    },
    {
      "x": -9,
      "y": 16,
      "z": -1,
      "name": "Rock_Stone"
    },
    {
      "x": -9,
      "y": 17,
      "z": -1,
      "name": "Rock_Stone"
    },
    {
      "x": -9,
      "y": 18,
      "z": -1,
      "name": "Rock_Stone"
    },
    {
      "x": -9,
      "y": 19,
      "z": -1,
      "name": "Rock_Stone"
    },
    {
      "x": -9,
      "y": 20,
      "z": -1,
      "name": "Rock_Stone"
    },
    {
      "x": -9,
      "y": 21,
      "z": -1,
      "name": "Rock_Stone"
    },
    {
      "x": -9,
      "y": 16,
      "z": 0,
      "name": "Rock_Stone"
    },
    {
      "x": -9,
      "y": 17,
      "z": 0,
      "name": "Rock_Stone"
    },
    {
      "x": -9,
      "y": 18,
      "z": 0,
      "name": "Rock_Stone"
    },
    {
      "x": -9,
      "y": 19,
      "z": 0,
      "name": "Rock_Stone"
    },
    {
      "x": -9,
      "y": 20,
      "z": 0,
      "name": "Rock_Stone"
    },
    {
      "x": -9,
      "y": 21,
      "z": 0,
      "name": "Rock_Stone"
    },
    {
      "x": -9,
      "y": 38,
      "z": 0,
      "name": "Soil_Grass"
    },
    {
      "x": -9,
      "y": 17,
      "z": 1,
      "name": "Rock_Stone"
    },
    {
      "x": -9,
      "y": 18,
      "z": 1,
      "name": "Rock_Stone"
    },
    {
      "x": -9,
      "y": 19,
      "z": 1,
      "name": "Rock_Stone"
    },
    {
      "x": -9,
      "y": 20,
      "z": 1,
      "name": "Rock_Stone"
    },
    {
      "x": -9,
      "y": 38,
      "z": 1,
      "name": "Soil_Dirt"
    },
    {
      "x": -9,
      "y": 39,
      "z": 1,
      "name": "Soil_Grass"
    },
    {
      "x": -9,
      "y": 40,
      "z": 1,
      "name": "Plant_Grass_Sharp_Tall"
    },
    {
      "x": -9,
      "y": 41,
      "z": 1,
      "name": "Plant_Grass_Sharp_Tall",
      "filler": 1024
    },
    {
      "x": -9,
      "y": 37,
      "z": 2,
      "name": "Soil_Dirt"
    },
    {
      "x": -9,
      "y": 38,
      "z": 2,
      "name": "Soil_Dirt"
    },
    {
      "x": -9,
      "y": 39,
      "z": 2,
      "name": "Soil_Dirt"
    },
    {
      "x": -9,
      "y": 40,
      "z": 2,
      "name": "Soil_Grass"
    },
    {
      "x": -9,
      "y": 41,
      "z": 2,
      "name": "Plant_Grass_Sharp"
    },
    {
      "x": -9,
      "y": 37,
      "z": 3,
      "name": "Soil_Dirt"
    },
    {
      "x": -9,
      "y": 38,
      "z": 3,
      "name": "Soil_Dirt"
    },
    {
      "x": -9,
      "y": 39,
      "z": 3,
      "name": "Soil_Dirt"
    },
    {
      "x": -9,
      "y": 40,
      "z": 3,
      "name": "Soil_Grass"
    },
    {
      "x": -9,
      "y": 41,
      "z": 3,
      "name": "Plant_Grass_Sharp"
    },
    {
      "x": -9,
      "y": 38,
      "z": 4,
      "name": "Soil_Dirt"
    },
    {
      "x": -9,
      "y": 39,
      "z": 4,
      "name": "Soil_Dirt"
    },
    {
      "x": -9,
      "y": 40,
      "z": 4,
      "name": "Soil_Grass"
    },
    {
      "x": -9,
      "y": 41,
      "z": 4,
      "name": "Plant_Grass_Sharp_Tall"
    },
    {
      "x": -9,
      "y": 42,
      "z": 4,
      "name": "Plant_Grass_Sharp_Tall",
      "filler": 1024
    },
    {
      "x": -9,
      "y": 38,
      "z": 5,
      "name": "Soil_Dirt"
    },
    {
      "x": -9,
      "y": 39,
      "z": 5,
      "name": "Soil_Dirt"
    },
    {
      "x": -9,
      "y": 40,
      "z": 5,
      "name": "Soil_Grass"
    },
    {
      "x": -9,
      "y": 41,
      "z": 5,
      "name": "Plant_Grass_Sharp_Tall"
    },
    {
      "x": -9,
      "y": 42,
      "z": 5,
      "name": "Plant_Grass_Sharp_Tall",
      "filler": 1024
    },
    {
      "x": -9,
      "y": 38,
      "z": 6,
      "name": "Soil_Dirt"
    },
    {
      "x": -9,
      "y": 39,
      "z": 6,
      "name": "Soil_Dirt"
    },
    {
      "x": -9,
      "y": 40,
      "z": 6,
      "name": "Soil_Grass"
    },
    {
      "x": -9,
      "y": 38,
      "z": 7,
      "name": "Soil_Dirt"
    },
    {
      "x": -9,
      "y": 39,
      "z": 7,
      "name": "Soil_Dirt"
    },
    {
      "x": -9,
      "y": 40,
      "z": 7,
      "name": "Soil_Grass"
    },
    {
      "x": -8,
      "y": 17,
      "z": -11,
      "name": "Rock_Stone"
    },
    {
      "x": -8,
      "y": 16,
      "z": -10,
      "name": "Rock_Stone"
    },
    {
      "x": -8,
      "y": 17,
      "z": -10,
      "name": "Rock_Stone"
    },
    {
      "x": -8,
      "y": 18,
      "z": -10,
      "name": "Rock_Stone"
    },
    {
      "x": -8,
      "y": 15,
      "z": -9,
      "name": "Rock_Stone"
    },
    {
      "x": -8,
      "y": 16,
      "z": -9,
      "name": "Rock_Stone"
    },
    {
      "x": -8,
      "y": 17,
      "z": -9,
      "name": "Rock_Stone"
    },
    {
      "x": -8,
      "y": 18,
      "z": -9,
      "name": "Rock_Stone"
    },
    {
      "x": -8,
      "y": 19,
      "z": -9,
      "name": "Rock_Stone"
    },
    {
      "x": -8,
      "y": 14,
      "z": -8,
      "name": "Rock_Stone"
    },
    {
      "x": -8,
      "y": 15,
      "z": -8,
      "name": "Rock_Stone"
    },
    {
      "x": -8,
      "y": 16,
      "z": -8,
      "name": "Rock_Stone"
    },
    {
      "x": -8,
      "y": 17,
      "z": -8,
      "name": "Rock_Stone"
    },
    {
      "x": -8,
      "y": 18,
      "z": -8,
      "name": "Rock_Stone"
    },
    {
      "x": -8,
      "y": 19,
      "z": -8,
      "name": "Rock_Stone"
    },
    {
      "x": -8,
      "y": 20,
      "z": -8,
      "name": "Rock_Stone"
    },
    {
      "x": -8,
      "y": 14,
      "z": -7,
      "name": "Rock_Stone"
    },
    {
      "x": -8,
      "y": 15,
      "z": -7,
      "name": "Rock_Stone"
    },
    {
      "x": -8,
      "y": 16,
      "z": -7,
      "name": "Rock_Stone"
    },
    {
      "x": -8,
      "y": 17,
      "z": -7,
      "name": "Rock_Stone"
    },
    {
      "x": -8,
      "y": 18,
      "z": -7,
      "name": "Rock_Stone"
    },
    {
      "x": -8,
      "y": 19,
      "z": -7,
      "name": "Rock_Stone"
    },
    {
      "x": -8,
      "y": 20,
      "z": -7,
      "name": "Rock_Stone"
    },
    {
      "x": -8,
      "y": 13,
      "z": -6,
      "name": "Rock_Stone"
    },
    {
      "x": -8,
      "y": 14,
      "z": -6,
      "name": "Rock_Stone"
    },
    {
      "x": -8,
      "y": 15,
      "z": -6,
      "name": "Rock_Stone"
    },
    {
      "x": -8,
      "y": 16,
      "z": -6,
      "name": "Rock_Stone"
    },
    {
      "x": -8,
      "y": 17,
      "z": -6,
      "name": "Rock_Stone"
    },
    {
      "x": -8,
      "y": 18,
      "z": -6,
      "name": "Rock_Stone"
    },
    {
      "x": -8,
      "y": 19,
      "z": -6,
      "name": "Rock_Stone"
    },
    {
      "x": -8,
      "y": 20,
      "z": -6,
      "name": "Rock_Stone"
    },
    {
      "x": -8,
      "y": 21,
      "z": -6,
      "name": "Rock_Stone"
    },
    {
      "x": -8,
      "y": 13,
      "z": -5,
      "name": "Rock_Stone"
    },
    {
      "x": -8,
      "y": 14,
      "z": -5,
      "name": "Rock_Stone"
    },
    {
      "x": -8,
      "y": 15,
      "z": -5,
      "name": "Rock_Stone"
    },
    {
      "x": -8,
      "y": 16,
      "z": -5,
      "name": "Rock_Stone"
    },
    {
      "x": -8,
      "y": 17,
      "z": -5,
      "name": "Rock_Stone"
    },
    {
      "x": -8,
      "y": 18,
      "z": -5,
      "name": "Rock_Stone"
    },
    {
      "x": -8,
      "y": 19,
      "z": -5,
      "name": "Rock_Stone"
    },
    {
      "x": -8,
      "y": 20,
      "z": -5,
      "name": "Rock_Stone"
    },
    {
      "x": -8,
      "y": 21,
      "z": -5,
      "name": "Rock_Stone"
    },
    {
      "x": -8,
      "y": 22,
      "z": -5,
      "name": "Rock_Stone"
    },
    {
      "x": -8,
      "y": 13,
      "z": -4,
      "name": "Rock_Stone"
    },
    {
      "x": -8,
      "y": 14,
      "z": -4,
      "name": "Rock_Stone"
    },
    {
      "x": -8,
      "y": 15,
      "z": -4,
      "name": "Rock_Stone"
    },
    {
      "x": -8,
      "y": 16,
      "z": -4,
      "name": "Rock_Stone"
    },
    {
      "x": -8,
      "y": 17,
      "z": -4,
      "name": "Rock_Stone"
    },
    {
      "x": -8,
      "y": 18,
      "z": -4,
      "name": "Rock_Stone"
    },
    {
      "x": -8,
      "y": 19,
      "z": -4,
      "name": "Rock_Stone"
    },
    {
      "x": -8,
      "y": 20,
      "z": -4,
      "name": "Rock_Stone"
    },
    {
      "x": -8,
      "y": 21,
      "z": -4,
      "name": "Rock_Stone"
    },
    {
      "x": -8,
      "y": 22,
      "z": -4,
      "name": "Rock_Stone"
    },
    {
      "x": -8,
      "y": 13,
      "z": -3,
      "name": "Rock_Stone"
    },
    {
      "x": -8,
      "y": 14,
      "z": -3,
      "name": "Rock_Stone"
    },
    {
      "x": -8,
      "y": 15,
      "z": -3,
      "name": "Rock_Stone"
    },
    {
      "x": -8,
      "y": 16,
      "z": -3,
      "name": "Rock_Stone"
    },
    {
      "x": -8,
      "y": 17,
      "z": -3,
      "name": "Rock_Stone"
    },
    {
      "x": -8,
      "y": 18,
      "z": -3,
      "name": "Rock_Stone"
    },
    {
      "x": -8,
      "y": 19,
      "z": -3,
      "name": "Rock_Stone"
    },
    {
      "x": -8,
      "y": 20,
      "z": -3,
      "name": "Rock_Stone"
    },
    {
      "x": -8,
      "y": 21,
      "z": -3,
      "name": "Rock_Stone"
    },
    {
      "x": -8,
      "y": 22,
      "z": -3,
      "name": "Rock_Stone"
    },
    {
      "x": -8,
      "y": 13,
      "z": -2,
      "name": "Rock_Stone"
    },
    {
      "x": -8,
      "y": 14,
      "z": -2,
      "name": "Rock_Stone"
    },
    {
      "x": -8,
      "y": 15,
      "z": -2,
      "name": "Rock_Stone"
    },
    {
      "x": -8,
      "y": 16,
      "z": -2,
      "name": "Rock_Stone"
    },
    {
      "x": -8,
      "y": 17,
      "z": -2,
      "name": "Rock_Stone"
    },
    {
      "x": -8,
      "y": 18,
      "z": -2,
      "name": "Rock_Stone"
    },
    {
      "x": -8,
      "y": 19,
      "z": -2,
      "name": "Rock_Stone"
    },
    {
      "x": -8,
      "y": 20,
      "z": -2,
      "name": "Rock_Stone"
    },
    {
      "x": -8,
      "y": 21,
      "z": -2,
      "name": "Rock_Stone"
    },
    {
      "x": -8,
      "y": 22,
      "z": -2,
      "name": "Rock_Stone"
    },
    {
      "x": -8,
      "y": 14,
      "z": -1,
      "name": "Rock_Stone"
    },
    {
      "x": -8,
      "y": 15,
      "z": -1,
      "name": "Rock_Stone"
    },
    {
      "x": -8,
      "y": 16,
      "z": -1,
      "name": "Rock_Stone"
    },
    {
      "x": -8,
      "y": 17,
      "z": -1,
      "name": "Rock_Stone"
    },
    {
      "x": -8,
      "y": 18,
      "z": -1,
      "name": "Rock_Stone"
    },
    {
      "x": -8,
      "y": 19,
      "z": -1,
      "name": "Rock_Stone"
    },
    {
      "x": -8,
      "y": 20,
      "z": -1,
      "name": "Rock_Stone"
    },
    {
      "x": -8,
      "y": 21,
      "z": -1,
      "name": "Rock_Stone"
    },
    {
      "x": -8,
      "y": 22,
      "z": -1,
      "name": "Rock_Stone"
    },
    {
      "x": -8,
      "y": 16,
      "z": 0,
      "name": "Rock_Stone"
    },
    {
      "x": -8,
      "y": 17,
      "z": 0,
      "name": "Rock_Stone"
    },
    {
      "x": -8,
      "y": 18,
      "z": 0,
      "name": "Rock_Stone"
    },
    {
      "x": -8,
      "y": 19,
      "z": 0,
      "name": "Rock_Stone"
    },
    {
      "x": -8,
      "y": 20,
      "z": 0,
      "name": "Rock_Stone"
    },
    {
      "x": -8,
      "y": 21,
      "z": 0,
      "name": "Rock_Stone"
    },
    {
      "x": -8,
      "y": 37,
      "z": 0,
      "name": "Soil_Dirt"
    },
    {
      "x": -8,
      "y": 38,
      "z": 0,
      "name": "Soil_Grass"
    },
    {
      "x": -8,
      "y": 16,
      "z": 1,
      "name": "Rock_Stone"
    },
    {
      "x": -8,
      "y": 17,
      "z": 1,
      "name": "Rock_Stone"
    },
    {
      "x": -8,
      "y": 18,
      "z": 1,
      "name": "Rock_Stone"
    },
    {
      "x": -8,
      "y": 19,
      "z": 1,
      "name": "Rock_Stone"
    },
    {
      "x": -8,
      "y": 20,
      "z": 1,
      "name": "Rock_Stone"
    },
    {
      "x": -8,
      "y": 21,
      "z": 1,
      "name": "Rock_Stone"
    },
    {
      "x": -8,
      "y": 37,
      "z": 1,
      "name": "Soil_Dirt"
    },
    {
      "x": -8,
      "y": 38,
      "z": 1,
      "name": "Soil_Dirt"
    },
    {
      "x": -8,
      "y": 39,
      "z": 1,
      "name": "Soil_Grass"
    },
    {
      "x": -8,
      "y": 40,
      "z": 1,
      "name": "Plant_Bush_Arid_Red"
    },
    {
      "x": -8,
      "y": 19,
      "z": 2,
      "name": "Rock_Stone"
    },
    {
      "x": -8,
      "y": 20,
      "z": 2,
      "name": "Rock_Stone"
    },
    {
      "x": -8,
      "y": 37,
      "z": 2,
      "name": "Soil_Dirt"
    },
    {
      "x": -8,
      "y": 38,
      "z": 2,
      "name": "Soil_Dirt"
    },
    {
      "x": -8,
      "y": 39,
      "z": 2,
      "name": "Soil_Grass"
    },
    {
      "x": -8,
      "y": 40,
      "z": 2,
      "name": "Plant_Bush_Arid_Red"
    },
    {
      "x": -8,
      "y": 37,
      "z": 3,
      "name": "Soil_Dirt"
    },
    {
      "x": -8,
      "y": 38,
      "z": 3,
      "name": "Soil_Dirt"
    },
    {
      "x": -8,
      "y": 39,
      "z": 3,
      "name": "Soil_Dirt"
    },
    {
      "x": -8,
      "y": 40,
      "z": 3,
      "name": "Soil_Grass"
    },
    {
      "x": -8,
      "y": 41,
      "z": 3,
      "name": "Plant_Grass_Sharp_Tall"
    },
    {
      "x": -8,
      "y": 42,
      "z": 3,
      "name": "Plant_Grass_Sharp_Tall",
      "filler": 1024
    },
    {
      "x": -8,
      "y": 37,
      "z": 4,
      "name": "Soil_Dirt"
    },
    {
      "x": -8,
      "y": 38,
      "z": 4,
      "name": "Soil_Dirt"
    },
    {
      "x": -8,
      "y": 39,
      "z": 4,
      "name": "Soil_Dirt"
    },
    {
      "x": -8,
      "y": 40,
      "z": 4,
      "name": "Soil_Grass"
    },
    {
      "x": -8,
      "y": 37,
      "z": 5,
      "name": "Soil_Dirt"
    },
    {
      "x": -8,
      "y": 38,
      "z": 5,
      "name": "Soil_Dirt"
    },
    {
      "x": -8,
      "y": 39,
      "z": 5,
      "name": "Soil_Dirt"
    },
    {
      "x": -8,
      "y": 40,
      "z": 5,
      "name": "Soil_Grass"
    },
    {
      "x": -8,
      "y": 37,
      "z": 6,
      "name": "Rock_Stone"
    },
    {
      "x": -8,
      "y": 38,
      "z": 6,
      "name": "Soil_Dirt"
    },
    {
      "x": -8,
      "y": 39,
      "z": 6,
      "name": "Soil_Dirt"
    },
    {
      "x": -8,
      "y": 40,
      "z": 6,
      "name": "Soil_Grass"
    },
    {
      "x": -8,
      "y": 38,
      "z": 7,
      "name": "Soil_Dirt"
    },
    {
      "x": -8,
      "y": 39,
      "z": 7,
      "name": "Soil_Dirt"
    },
    {
      "x": -8,
      "y": 40,
      "z": 7,
      "name": "Soil_Grass"
    },
    {
      "x": -7,
      "y": 17,
      "z": -10,
      "name": "Rock_Stone"
    },
    {
      "x": -7,
      "y": 18,
      "z": -10,
      "name": "Rock_Stone"
    },
    {
      "x": -7,
      "y": 19,
      "z": -10,
      "name": "Rock_Stone"
    },
    {
      "x": -7,
      "y": 15,
      "z": -9,
      "name": "Rock_Stone"
    },
    {
      "x": -7,
      "y": 16,
      "z": -9,
      "name": "Rock_Stone"
    },
    {
      "x": -7,
      "y": 17,
      "z": -9,
      "name": "Rock_Stone"
    },
    {
      "x": -7,
      "y": 18,
      "z": -9,
      "name": "Rock_Stone"
    },
    {
      "x": -7,
      "y": 19,
      "z": -9,
      "name": "Rock_Stone"
    },
    {
      "x": -7,
      "y": 15,
      "z": -8,
      "name": "Rock_Stone"
    },
    {
      "x": -7,
      "y": 16,
      "z": -8,
      "name": "Rock_Stone"
    },
    {
      "x": -7,
      "y": 17,
      "z": -8,
      "name": "Rock_Stone"
    },
    {
      "x": -7,
      "y": 18,
      "z": -8,
      "name": "Rock_Stone"
    },
    {
      "x": -7,
      "y": 19,
      "z": -8,
      "name": "Rock_Stone"
    },
    {
      "x": -7,
      "y": 20,
      "z": -8,
      "name": "Rock_Stone"
    },
    {
      "x": -7,
      "y": 13,
      "z": -7,
      "name": "Rock_Stone"
    },
    {
      "x": -7,
      "y": 14,
      "z": -7,
      "name": "Rock_Stone"
    },
    {
      "x": -7,
      "y": 15,
      "z": -7,
      "name": "Rock_Stone"
    },
    {
      "x": -7,
      "y": 16,
      "z": -7,
      "name": "Rock_Stone"
    },
    {
      "x": -7,
      "y": 17,
      "z": -7,
      "name": "Rock_Stone"
    },
    {
      "x": -7,
      "y": 18,
      "z": -7,
      "name": "Rock_Stone"
    },
    {
      "x": -7,
      "y": 19,
      "z": -7,
      "name": "Rock_Stone"
    },
    {
      "x": -7,
      "y": 20,
      "z": -7,
      "name": "Rock_Stone"
    },
    {
      "x": -7,
      "y": 13,
      "z": -6,
      "name": "Rock_Stone"
    },
    {
      "x": -7,
      "y": 14,
      "z": -6,
      "name": "Rock_Stone"
    },
    {
      "x": -7,
      "y": 15,
      "z": -6,
      "name": "Rock_Stone"
    },
    {
      "x": -7,
      "y": 16,
      "z": -6,
      "name": "Rock_Stone"
    },
    {
      "x": -7,
      "y": 17,
      "z": -6,
      "name": "Rock_Stone"
    },
    {
      "x": -7,
      "y": 18,
      "z": -6,
      "name": "Rock_Stone"
    },
    {
      "x": -7,
      "y": 19,
      "z": -6,
      "name": "Rock_Stone"
    },
    {
      "x": -7,
      "y": 20,
      "z": -6,
      "name": "Rock_Stone"
    },
    {
      "x": -7,
      "y": 21,
      "z": -6,
      "name": "Rock_Stone"
    },
    {
      "x": -7,
      "y": 12,
      "z": -5,
      "name": "Rock_Stone"
    },
    {
      "x": -7,
      "y": 13,
      "z": -5,
      "name": "Rock_Stone"
    },
    {
      "x": -7,
      "y": 14,
      "z": -5,
      "name": "Rock_Stone"
    },
    {
      "x": -7,
      "y": 15,
      "z": -5,
      "name": "Rock_Stone"
    },
    {
      "x": -7,
      "y": 16,
      "z": -5,
      "name": "Rock_Stone"
    },
    {
      "x": -7,
      "y": 17,
      "z": -5,
      "name": "Rock_Stone"
    },
    {
      "x": -7,
      "y": 18,
      "z": -5,
      "name": "Rock_Stone"
    },
    {
      "x": -7,
      "y": 19,
      "z": -5,
      "name": "Rock_Stone"
    },
    {
      "x": -7,
      "y": 20,
      "z": -5,
      "name": "Rock_Stone"
    },
    {
      "x": -7,
      "y": 21,
      "z": -5,
      "name": "Rock_Stone"
    },
    {
      "x": -7,
      "y": 22,
      "z": -5,
      "name": "Rock_Stone"
    },
    {
      "x": -7,
      "y": 12,
      "z": -4,
      "name": "Rock_Stone"
    },
    {
      "x": -7,
      "y": 13,
      "z": -4,
      "name": "Rock_Stone"
    },
    {
      "x": -7,
      "y": 14,
      "z": -4,
      "name": "Rock_Stone"
    },
    {
      "x": -7,
      "y": 15,
      "z": -4,
      "name": "Rock_Stone"
    },
    {
      "x": -7,
      "y": 16,
      "z": -4,
      "name": "Rock_Stone"
    },
    {
      "x": -7,
      "y": 17,
      "z": -4,
      "name": "Rock_Stone"
    },
    {
      "x": -7,
      "y": 18,
      "z": -4,
      "name": "Rock_Stone"
    },
    {
      "x": -7,
      "y": 19,
      "z": -4,
      "name": "Rock_Stone"
    },
    {
      "x": -7,
      "y": 20,
      "z": -4,
      "name": "Rock_Stone"
    },
    {
      "x": -7,
      "y": 21,
      "z": -4,
      "name": "Rock_Stone"
    },
    {
      "x": -7,
      "y": 22,
      "z": -4,
      "name": "Soil_Dirt"
    },
    {
      "x": -7,
      "y": 23,
      "z": -4,
      "name": "Soil_Grass"
    },
    {
      "x": -7,
      "y": 12,
      "z": -3,
      "name": "Rock_Stone"
    },
    {
      "x": -7,
      "y": 13,
      "z": -3,
      "name": "Rock_Stone"
    },
    {
      "x": -7,
      "y": 14,
      "z": -3,
      "name": "Rock_Stone"
    },
    {
      "x": -7,
      "y": 15,
      "z": -3,
      "name": "Rock_Stone"
    },
    {
      "x": -7,
      "y": 16,
      "z": -3,
      "name": "Rock_Stone"
    },
    {
      "x": -7,
      "y": 17,
      "z": -3,
      "name": "Rock_Stone"
    },
    {
      "x": -7,
      "y": 18,
      "z": -3,
      "name": "Rock_Stone"
    },
    {
      "x": -7,
      "y": 19,
      "z": -3,
      "name": "Rock_Stone"
    },
    {
      "x": -7,
      "y": 20,
      "z": -3,
      "name": "Rock_Stone"
    },
    {
      "x": -7,
      "y": 21,
      "z": -3,
      "name": "Rock_Stone"
    },
    {
      "x": -7,
      "y": 22,
      "z": -3,
      "name": "Soil_Dirt"
    },
    {
      "x": -7,
      "y": 23,
      "z": -3,
      "name": "Soil_Grass"
    },
    {
      "x": -7,
      "y": 13,
      "z": -2,
      "name": "Rock_Stone"
    },
    {
      "x": -7,
      "y": 14,
      "z": -2,
      "name": "Rock_Stone"
    },
    {
      "x": -7,
      "y": 15,
      "z": -2,
      "name": "Rock_Stone"
    },
    {
      "x": -7,
      "y": 16,
      "z": -2,
      "name": "Rock_Stone"
    },
    {
      "x": -7,
      "y": 17,
      "z": -2,
      "name": "Rock_Stone"
    },
    {
      "x": -7,
      "y": 18,
      "z": -2,
      "name": "Rock_Stone"
    },
    {
      "x": -7,
      "y": 19,
      "z": -2,
      "name": "Rock_Stone"
    },
    {
      "x": -7,
      "y": 20,
      "z": -2,
      "name": "Rock_Stone"
    },
    {
      "x": -7,
      "y": 21,
      "z": -2,
      "name": "Rock_Stone"
    },
    {
      "x": -7,
      "y": 22,
      "z": -2,
      "name": "Soil_Dirt"
    },
    {
      "x": -7,
      "y": 23,
      "z": -2,
      "name": "Soil_Grass"
    },
    {
      "x": -7,
      "y": 13,
      "z": -1,
      "name": "Rock_Stone"
    },
    {
      "x": -7,
      "y": 14,
      "z": -1,
      "name": "Rock_Stone"
    },
    {
      "x": -7,
      "y": 15,
      "z": -1,
      "name": "Rock_Stone"
    },
    {
      "x": -7,
      "y": 16,
      "z": -1,
      "name": "Rock_Stone"
    },
    {
      "x": -7,
      "y": 17,
      "z": -1,
      "name": "Rock_Stone"
    },
    {
      "x": -7,
      "y": 18,
      "z": -1,
      "name": "Rock_Stone"
    },
    {
      "x": -7,
      "y": 19,
      "z": -1,
      "name": "Rock_Stone"
    },
    {
      "x": -7,
      "y": 20,
      "z": -1,
      "name": "Rock_Stone"
    },
    {
      "x": -7,
      "y": 21,
      "z": -1,
      "name": "Rock_Stone"
    },
    {
      "x": -7,
      "y": 22,
      "z": -1,
      "name": "Rock_Stone"
    },
    {
      "x": -7,
      "y": 23,
      "z": -1,
      "name": "Soil_Grass"
    },
    {
      "x": -7,
      "y": 15,
      "z": 0,
      "name": "Rock_Stone"
    },
    {
      "x": -7,
      "y": 16,
      "z": 0,
      "name": "Rock_Stone"
    },
    {
      "x": -7,
      "y": 17,
      "z": 0,
      "name": "Rock_Stone"
    },
    {
      "x": -7,
      "y": 18,
      "z": 0,
      "name": "Rock_Stone"
    },
    {
      "x": -7,
      "y": 19,
      "z": 0,
      "name": "Rock_Stone"
    },
    {
      "x": -7,
      "y": 20,
      "z": 0,
      "name": "Rock_Stone"
    },
    {
      "x": -7,
      "y": 21,
      "z": 0,
      "name": "Rock_Stone"
    },
    {
      "x": -7,
      "y": 22,
      "z": 0,
      "name": "Rock_Stone"
    },
    {
      "x": -7,
      "y": 23,
      "z": 0,
      "name": "Soil_Grass"
    },
    {
      "x": -7,
      "y": 37,
      "z": 0,
      "name": "Soil_Dirt"
    },
    {
      "x": -7,
      "y": 38,
      "z": 0,
      "name": "Soil_Dirt"
    },
    {
      "x": -7,
      "y": 39,
      "z": 0,
      "name": "Soil_Grass"
    },
    {
      "x": -7,
      "y": 40,
      "z": 0,
      "name": "Plant_Bush_Arid_Red"
    },
    {
      "x": -7,
      "y": 16,
      "z": 1,
      "name": "Rock_Stone"
    },
    {
      "x": -7,
      "y": 17,
      "z": 1,
      "name": "Rock_Stone"
    },
    {
      "x": -7,
      "y": 18,
      "z": 1,
      "name": "Rock_Stone"
    },
    {
      "x": -7,
      "y": 19,
      "z": 1,
      "name": "Rock_Stone"
    },
    {
      "x": -7,
      "y": 20,
      "z": 1,
      "name": "Rock_Stone"
    },
    {
      "x": -7,
      "y": 21,
      "z": 1,
      "name": "Rock_Stone"
    },
    {
      "x": -7,
      "y": 22,
      "z": 1,
      "name": "Rock_Stone"
    },
    {
      "x": -7,
      "y": 36,
      "z": 1,
      "name": "Soil_Dirt"
    },
    {
      "x": -7,
      "y": 37,
      "z": 1,
      "name": "Soil_Dirt"
    },
    {
      "x": -7,
      "y": 38,
      "z": 1,
      "name": "Soil_Dirt"
    },
    {
      "x": -7,
      "y": 39,
      "z": 1,
      "name": "Soil_Grass"
    },
    {
      "x": -7,
      "y": 40,
      "z": 1,
      "name": "Plant_Bush_Arid_Red"
    },
    {
      "x": -7,
      "y": 17,
      "z": 2,
      "name": "Rock_Stone"
    },
    {
      "x": -7,
      "y": 18,
      "z": 2,
      "name": "Rock_Stone"
    },
    {
      "x": -7,
      "y": 19,
      "z": 2,
      "name": "Rock_Stone"
    },
    {
      "x": -7,
      "y": 20,
      "z": 2,
      "name": "Rock_Stone"
    },
    {
      "x": -7,
      "y": 21,
      "z": 2,
      "name": "Rock_Stone"
    },
    {
      "x": -7,
      "y": 22,
      "z": 2,
      "name": "Rock_Stone"
    },
    {
      "x": -7,
      "y": 36,
      "z": 2,
      "name": "Soil_Dirt"
    },
    {
      "x": -7,
      "y": 37,
      "z": 2,
      "name": "Soil_Dirt"
    },
    {
      "x": -7,
      "y": 38,
      "z": 2,
      "name": "Soil_Dirt"
    },
    {
      "x": -7,
      "y": 39,
      "z": 2,
      "name": "Soil_Grass"
    },
    {
      "x": -7,
      "y": 40,
      "z": 2,
      "name": "Plant_Bush_Arid_Red"
    },
    {
      "x": -7,
      "y": 36,
      "z": 3,
      "name": "Soil_Dirt"
    },
    {
      "x": -7,
      "y": 37,
      "z": 3,
      "name": "Soil_Dirt"
    },
    {
      "x": -7,
      "y": 38,
      "z": 3,
      "name": "Soil_Dirt"
    },
    {
      "x": -7,
      "y": 39,
      "z": 3,
      "name": "Soil_Dirt"
    },
    {
      "x": -7,
      "y": 40,
      "z": 3,
      "name": "Soil_Grass"
    },
    {
      "x": -7,
      "y": 36,
      "z": 4,
      "name": "Rock_Stone"
    },
    {
      "x": -7,
      "y": 37,
      "z": 4,
      "name": "Soil_Dirt"
    },
    {
      "x": -7,
      "y": 38,
      "z": 4,
      "name": "Soil_Dirt"
    },
    {
      "x": -7,
      "y": 39,
      "z": 4,
      "name": "Soil_Dirt"
    },
    {
      "x": -7,
      "y": 40,
      "z": 4,
      "name": "Soil_Grass"
    },
    {
      "x": -7,
      "y": 37,
      "z": 5,
      "name": "Soil_Dirt"
    },
    {
      "x": -7,
      "y": 38,
      "z": 5,
      "name": "Soil_Dirt"
    },
    {
      "x": -7,
      "y": 39,
      "z": 5,
      "name": "Soil_Dirt"
    },
    {
      "x": -7,
      "y": 40,
      "z": 5,
      "name": "Soil_Grass"
    },
    {
      "x": -7,
      "y": 37,
      "z": 6,
      "name": "Rock_Stone"
    },
    {
      "x": -7,
      "y": 38,
      "z": 6,
      "name": "Soil_Dirt"
    },
    {
      "x": -7,
      "y": 39,
      "z": 6,
      "name": "Soil_Grass"
    },
    {
      "x": -7,
      "y": 37,
      "z": 7,
      "name": "Rock_Stone"
    },
    {
      "x": -7,
      "y": 38,
      "z": 7,
      "name": "Soil_Dirt"
    },
    {
      "x": -7,
      "y": 39,
      "z": 7,
      "name": "Soil_Grass"
    },
    {
      "x": -6,
      "y": 17,
      "z": -10,
      "name": "Rock_Stone"
    },
    {
      "x": -6,
      "y": 18,
      "z": -10,
      "name": "Rock_Stone"
    },
    {
      "x": -6,
      "y": 19,
      "z": -10,
      "name": "Rock_Stone"
    },
    {
      "x": -6,
      "y": 16,
      "z": -9,
      "name": "Rock_Stone"
    },
    {
      "x": -6,
      "y": 17,
      "z": -9,
      "name": "Rock_Stone"
    },
    {
      "x": -6,
      "y": 18,
      "z": -9,
      "name": "Rock_Stone"
    },
    {
      "x": -6,
      "y": 19,
      "z": -9,
      "name": "Rock_Stone"
    },
    {
      "x": -6,
      "y": 14,
      "z": -8,
      "name": "Rock_Stone"
    },
    {
      "x": -6,
      "y": 15,
      "z": -8,
      "name": "Rock_Stone"
    },
    {
      "x": -6,
      "y": 16,
      "z": -8,
      "name": "Rock_Stone"
    },
    {
      "x": -6,
      "y": 17,
      "z": -8,
      "name": "Rock_Stone"
    },
    {
      "x": -6,
      "y": 18,
      "z": -8,
      "name": "Rock_Stone"
    },
    {
      "x": -6,
      "y": 19,
      "z": -8,
      "name": "Rock_Stone"
    },
    {
      "x": -6,
      "y": 20,
      "z": -8,
      "name": "Rock_Stone"
    },
    {
      "x": -6,
      "y": 13,
      "z": -7,
      "name": "Rock_Stone"
    },
    {
      "x": -6,
      "y": 14,
      "z": -7,
      "name": "Rock_Stone"
    },
    {
      "x": -6,
      "y": 15,
      "z": -7,
      "name": "Rock_Stone"
    },
    {
      "x": -6,
      "y": 16,
      "z": -7,
      "name": "Rock_Stone"
    },
    {
      "x": -6,
      "y": 17,
      "z": -7,
      "name": "Rock_Stone"
    },
    {
      "x": -6,
      "y": 18,
      "z": -7,
      "name": "Rock_Stone"
    },
    {
      "x": -6,
      "y": 19,
      "z": -7,
      "name": "Rock_Stone"
    },
    {
      "x": -6,
      "y": 20,
      "z": -7,
      "name": "Rock_Stone"
    },
    {
      "x": -6,
      "y": 21,
      "z": -7,
      "name": "Rock_Stone"
    },
    {
      "x": -6,
      "y": 12,
      "z": -6,
      "name": "Rock_Stone"
    },
    {
      "x": -6,
      "y": 13,
      "z": -6,
      "name": "Rock_Stone"
    },
    {
      "x": -6,
      "y": 14,
      "z": -6,
      "name": "Rock_Stone"
    },
    {
      "x": -6,
      "y": 15,
      "z": -6,
      "name": "Rock_Stone"
    },
    {
      "x": -6,
      "y": 16,
      "z": -6,
      "name": "Rock_Stone"
    },
    {
      "x": -6,
      "y": 17,
      "z": -6,
      "name": "Rock_Stone"
    },
    {
      "x": -6,
      "y": 18,
      "z": -6,
      "name": "Rock_Stone"
    },
    {
      "x": -6,
      "y": 19,
      "z": -6,
      "name": "Rock_Stone"
    },
    {
      "x": -6,
      "y": 20,
      "z": -6,
      "name": "Rock_Stone"
    },
    {
      "x": -6,
      "y": 21,
      "z": -6,
      "name": "Rock_Stone"
    },
    {
      "x": -6,
      "y": 12,
      "z": -5,
      "name": "Rock_Stone"
    },
    {
      "x": -6,
      "y": 13,
      "z": -5,
      "name": "Rock_Stone"
    },
    {
      "x": -6,
      "y": 14,
      "z": -5,
      "name": "Rock_Stone"
    },
    {
      "x": -6,
      "y": 15,
      "z": -5,
      "name": "Rock_Stone"
    },
    {
      "x": -6,
      "y": 16,
      "z": -5,
      "name": "Rock_Stone"
    },
    {
      "x": -6,
      "y": 17,
      "z": -5,
      "name": "Rock_Stone"
    },
    {
      "x": -6,
      "y": 18,
      "z": -5,
      "name": "Rock_Stone"
    },
    {
      "x": -6,
      "y": 19,
      "z": -5,
      "name": "Rock_Stone"
    },
    {
      "x": -6,
      "y": 20,
      "z": -5,
      "name": "Rock_Stone"
    },
    {
      "x": -6,
      "y": 21,
      "z": -5,
      "name": "Rock_Stone"
    },
    {
      "x": -6,
      "y": 22,
      "z": -5,
      "name": "Soil_Dirt"
    },
    {
      "x": -6,
      "y": 23,
      "z": -5,
      "name": "Soil_Grass"
    },
    {
      "x": -6,
      "y": 12,
      "z": -4,
      "name": "Rock_Stone"
    },
    {
      "x": -6,
      "y": 13,
      "z": -4,
      "name": "Rock_Stone"
    },
    {
      "x": -6,
      "y": 14,
      "z": -4,
      "name": "Rock_Stone"
    },
    {
      "x": -6,
      "y": 15,
      "z": -4,
      "name": "Rock_Stone"
    },
    {
      "x": -6,
      "y": 16,
      "z": -4,
      "name": "Rock_Stone"
    },
    {
      "x": -6,
      "y": 17,
      "z": -4,
      "name": "Rock_Stone"
    },
    {
      "x": -6,
      "y": 18,
      "z": -4,
      "name": "Rock_Stone"
    },
    {
      "x": -6,
      "y": 19,
      "z": -4,
      "name": "Rock_Stone"
    },
    {
      "x": -6,
      "y": 20,
      "z": -4,
      "name": "Rock_Stone"
    },
    {
      "x": -6,
      "y": 21,
      "z": -4,
      "name": "Rock_Stone"
    },
    {
      "x": -6,
      "y": 22,
      "z": -4,
      "name": "Soil_Dirt"
    },
    {
      "x": -6,
      "y": 23,
      "z": -4,
      "name": "Soil_Grass"
    },
    {
      "x": -6,
      "y": 12,
      "z": -3,
      "name": "Rock_Stone"
    },
    {
      "x": -6,
      "y": 13,
      "z": -3,
      "name": "Rock_Stone"
    },
    {
      "x": -6,
      "y": 14,
      "z": -3,
      "name": "Rock_Stone"
    },
    {
      "x": -6,
      "y": 15,
      "z": -3,
      "name": "Rock_Stone"
    },
    {
      "x": -6,
      "y": 16,
      "z": -3,
      "name": "Rock_Stone"
    },
    {
      "x": -6,
      "y": 17,
      "z": -3,
      "name": "Rock_Stone"
    },
    {
      "x": -6,
      "y": 18,
      "z": -3,
      "name": "Rock_Stone"
    },
    {
      "x": -6,
      "y": 19,
      "z": -3,
      "name": "Rock_Stone"
    },
    {
      "x": -6,
      "y": 20,
      "z": -3,
      "name": "Rock_Stone"
    },
    {
      "x": -6,
      "y": 21,
      "z": -3,
      "name": "Rock_Stone"
    },
    {
      "x": -6,
      "y": 22,
      "z": -3,
      "name": "Soil_Dirt"
    },
    {
      "x": -6,
      "y": 23,
      "z": -3,
      "name": "Soil_Grass"
    },
    {
      "x": -6,
      "y": 12,
      "z": -2,
      "name": "Rock_Stone"
    },
    {
      "x": -6,
      "y": 13,
      "z": -2,
      "name": "Rock_Stone"
    },
    {
      "x": -6,
      "y": 14,
      "z": -2,
      "name": "Rock_Stone"
    },
    {
      "x": -6,
      "y": 15,
      "z": -2,
      "name": "Rock_Stone"
    },
    {
      "x": -6,
      "y": 16,
      "z": -2,
      "name": "Rock_Stone"
    },
    {
      "x": -6,
      "y": 17,
      "z": -2,
      "name": "Rock_Stone"
    },
    {
      "x": -6,
      "y": 18,
      "z": -2,
      "name": "Rock_Stone"
    },
    {
      "x": -6,
      "y": 19,
      "z": -2,
      "name": "Rock_Stone"
    },
    {
      "x": -6,
      "y": 20,
      "z": -2,
      "name": "Rock_Stone"
    },
    {
      "x": -6,
      "y": 21,
      "z": -2,
      "name": "Rock_Stone"
    },
    {
      "x": -6,
      "y": 22,
      "z": -2,
      "name": "Soil_Dirt"
    },
    {
      "x": -6,
      "y": 23,
      "z": -2,
      "name": "Soil_Dirt"
    },
    {
      "x": -6,
      "y": 24,
      "z": -2,
      "name": "Soil_Grass"
    },
    {
      "x": -6,
      "y": 13,
      "z": -1,
      "name": "Rock_Stone"
    },
    {
      "x": -6,
      "y": 14,
      "z": -1,
      "name": "Rock_Stone"
    },
    {
      "x": -6,
      "y": 15,
      "z": -1,
      "name": "Rock_Stone"
    },
    {
      "x": -6,
      "y": 16,
      "z": -1,
      "name": "Rock_Stone"
    },
    {
      "x": -6,
      "y": 17,
      "z": -1,
      "name": "Rock_Stone"
    },
    {
      "x": -6,
      "y": 18,
      "z": -1,
      "name": "Rock_Stone"
    },
    {
      "x": -6,
      "y": 19,
      "z": -1,
      "name": "Rock_Stone"
    },
    {
      "x": -6,
      "y": 20,
      "z": -1,
      "name": "Rock_Stone"
    },
    {
      "x": -6,
      "y": 21,
      "z": -1,
      "name": "Rock_Stone"
    },
    {
      "x": -6,
      "y": 22,
      "z": -1,
      "name": "Rock_Stone"
    },
    {
      "x": -6,
      "y": 23,
      "z": -1,
      "name": "Soil_Dirt"
    },
    {
      "x": -6,
      "y": 24,
      "z": -1,
      "name": "Soil_Grass"
    },
    {
      "x": -6,
      "y": 25,
      "z": -1,
      "name": "Plant_Grass_Sharp_Tall"
    },
    {
      "x": -6,
      "y": 26,
      "z": -1,
      "name": "Plant_Grass_Sharp_Tall",
      "filler": 1024
    },
    {
      "x": -6,
      "y": 14,
      "z": 0,
      "name": "Rock_Stone"
    },
    {
      "x": -6,
      "y": 15,
      "z": 0,
      "name": "Rock_Stone"
    },
    {
      "x": -6,
      "y": 16,
      "z": 0,
      "name": "Rock_Stone"
    },
    {
      "x": -6,
      "y": 17,
      "z": 0,
      "name": "Rock_Stone"
    },
    {
      "x": -6,
      "y": 18,
      "z": 0,
      "name": "Rock_Stone"
    },
    {
      "x": -6,
      "y": 19,
      "z": 0,
      "name": "Rock_Stone"
    },
    {
      "x": -6,
      "y": 20,
      "z": 0,
      "name": "Rock_Stone"
    },
    {
      "x": -6,
      "y": 21,
      "z": 0,
      "name": "Rock_Stone"
    },
    {
      "x": -6,
      "y": 22,
      "z": 0,
      "name": "Rock_Stone"
    },
    {
      "x": -6,
      "y": 23,
      "z": 0,
      "name": "Soil_Dirt"
    },
    {
      "x": -6,
      "y": 24,
      "z": 0,
      "name": "Soil_Grass"
    },
    {
      "x": -6,
      "y": 25,
      "z": 0,
      "name": "Plant_Grass_Sharp_Tall"
    },
    {
      "x": -6,
      "y": 26,
      "z": 0,
      "name": "Plant_Grass_Sharp_Tall",
      "filler": 1024
    },
    {
      "x": -6,
      "y": 36,
      "z": 0,
      "name": "Rock_Stone"
    },
    {
      "x": -6,
      "y": 37,
      "z": 0,
      "name": "Soil_Dirt"
    },
    {
      "x": -6,
      "y": 38,
      "z": 0,
      "name": "Soil_Dirt"
    },
    {
      "x": -6,
      "y": 39,
      "z": 0,
      "name": "Soil_Grass"
    },
    {
      "x": -6,
      "y": 16,
      "z": 1,
      "name": "Rock_Stone"
    },
    {
      "x": -6,
      "y": 17,
      "z": 1,
      "name": "Rock_Stone"
    },
    {
      "x": -6,
      "y": 18,
      "z": 1,
      "name": "Rock_Stone"
    },
    {
      "x": -6,
      "y": 19,
      "z": 1,
      "name": "Rock_Stone"
    },
    {
      "x": -6,
      "y": 20,
      "z": 1,
      "name": "Rock_Stone"
    },
    {
      "x": -6,
      "y": 21,
      "z": 1,
      "name": "Rock_Stone"
    },
    {
      "x": -6,
      "y": 22,
      "z": 1,
      "name": "Rock_Stone"
    },
    {
      "x": -6,
      "y": 23,
      "z": 1,
      "name": "Soil_Dirt"
    },
    {
      "x": -6,
      "y": 24,
      "z": 1,
      "name": "Soil_Dirt"
    },
    {
      "x": -6,
      "y": 25,
      "z": 1,
      "name": "Soil_Grass"
    },
    {
      "x": -6,
      "y": 26,
      "z": 1,
      "name": "Plant_Grass_Sharp"
    },
    {
      "x": -6,
      "y": 36,
      "z": 1,
      "name": "Rock_Stone"
    },
    {
      "x": -6,
      "y": 37,
      "z": 1,
      "name": "Soil_Dirt"
    },
    {
      "x": -6,
      "y": 38,
      "z": 1,
      "name": "Soil_Dirt"
    },
    {
      "x": -6,
      "y": 39,
      "z": 1,
      "name": "Soil_Grass"
    },
    {
      "x": -6,
      "y": 17,
      "z": 2,
      "name": "Rock_Stone"
    },
    {
      "x": -6,
      "y": 18,
      "z": 2,
      "name": "Rock_Stone"
    },
    {
      "x": -6,
      "y": 19,
      "z": 2,
      "name": "Rock_Stone"
    },
    {
      "x": -6,
      "y": 20,
      "z": 2,
      "name": "Rock_Stone"
    },
    {
      "x": -6,
      "y": 21,
      "z": 2,
      "name": "Rock_Stone"
    },
    {
      "x": -6,
      "y": 22,
      "z": 2,
      "name": "Rock_Stone"
    },
    {
      "x": -6,
      "y": 23,
      "z": 2,
      "name": "Soil_Dirt"
    },
    {
      "x": -6,
      "y": 24,
      "z": 2,
      "name": "Soil_Dirt"
    },
    {
      "x": -6,
      "y": 25,
      "z": 2,
      "name": "Soil_Grass"
    },
    {
      "x": -6,
      "y": 35,
      "z": 2,
      "name": "Rock_Stone"
    },
    {
      "x": -6,
      "y": 36,
      "z": 2,
      "name": "Soil_Dirt"
    },
    {
      "x": -6,
      "y": 37,
      "z": 2,
      "name": "Soil_Dirt"
    },
    {
      "x": -6,
      "y": 38,
      "z": 2,
      "name": "Soil_Dirt"
    },
    {
      "x": -6,
      "y": 39,
      "z": 2,
      "name": "Soil_Grass"
    },
    {
      "x": -6,
      "y": 40,
      "z": 2,
      "name": "Plant_Bush_Arid_Red"
    },
    {
      "x": -6,
      "y": 19,
      "z": 3,
      "name": "Rock_Stone"
    },
    {
      "x": -6,
      "y": 20,
      "z": 3,
      "name": "Rock_Stone"
    },
    {
      "x": -6,
      "y": 21,
      "z": 3,
      "name": "Rock_Stone"
    },
    {
      "x": -6,
      "y": 22,
      "z": 3,
      "name": "Rock_Stone"
    },
    {
      "x": -6,
      "y": 23,
      "z": 3,
      "name": "Soil_Dirt"
    },
    {
      "x": -6,
      "y": 24,
      "z": 3,
      "name": "Soil_Grass"
    },
    {
      "x": -6,
      "y": 35,
      "z": 3,
      "name": "Rock_Stone"
    },
    {
      "x": -6,
      "y": 36,
      "z": 3,
      "name": "Rock_Stone"
    },
    {
      "x": -6,
      "y": 37,
      "z": 3,
      "name": "Soil_Dirt"
    },
    {
      "x": -6,
      "y": 38,
      "z": 3,
      "name": "Soil_Dirt"
    },
    {
      "x": -6,
      "y": 39,
      "z": 3,
      "name": "Soil_Grass"
    },
    {
      "x": -6,
      "y": 35,
      "z": 4,
      "name": "Rock_Stone"
    },
    {
      "x": -6,
      "y": 36,
      "z": 4,
      "name": "Rock_Stone"
    },
    {
      "x": -6,
      "y": 37,
      "z": 4,
      "name": "Soil_Dirt"
    },
    {
      "x": -6,
      "y": 38,
      "z": 4,
      "name": "Soil_Dirt"
    },
    {
      "x": -6,
      "y": 39,
      "z": 4,
      "name": "Soil_Grass"
    },
    {
      "x": -6,
      "y": 40,
      "z": 4,
      "name": "Plant_Grass_Sharp_Tall"
    },
    {
      "x": -6,
      "y": 41,
      "z": 4,
      "name": "Plant_Grass_Sharp_Tall",
      "filler": 1024
    },
    {
      "x": -6,
      "y": 35,
      "z": 5,
      "name": "Rock_Stone"
    },
    {
      "x": -6,
      "y": 36,
      "z": 5,
      "name": "Rock_Stone"
    },
    {
      "x": -6,
      "y": 37,
      "z": 5,
      "name": "Rock_Stone"
    },
    {
      "x": -6,
      "y": 38,
      "z": 5,
      "name": "Soil_Dirt"
    },
    {
      "x": -6,
      "y": 39,
      "z": 5,
      "name": "Soil_Grass"
    },
    {
      "x": -6,
      "y": 40,
      "z": 5,
      "name": "Plant_Grass_Sharp_Tall"
    },
    {
      "x": -6,
      "y": 41,
      "z": 5,
      "name": "Plant_Grass_Sharp_Tall",
      "filler": 1024
    },
    {
      "x": -6,
      "y": 36,
      "z": 6,
      "name": "Rock_Stone"
    },
    {
      "x": -6,
      "y": 37,
      "z": 6,
      "name": "Rock_Stone"
    },
    {
      "x": -6,
      "y": 38,
      "z": 6,
      "name": "Soil_Dirt"
    },
    {
      "x": -6,
      "y": 39,
      "z": 6,
      "name": "Soil_Grass"
    },
    {
      "x": -6,
      "y": 40,
      "z": 6,
      "name": "Plant_Grass_Sharp_Tall"
    },
    {
      "x": -6,
      "y": 41,
      "z": 6,
      "name": "Plant_Grass_Sharp_Tall",
      "filler": 1024
    },
    {
      "x": -6,
      "y": 37,
      "z": 7,
      "name": "Rock_Stone"
    },
    {
      "x": -6,
      "y": 38,
      "z": 7,
      "name": "Soil_Dirt"
    },
    {
      "x": -6,
      "y": 39,
      "z": 7,
      "name": "Soil_Grass"
    },
    {
      "x": -5,
      "y": 18,
      "z": -10,
      "name": "Rock_Stone"
    },
    {
      "x": -5,
      "y": 19,
      "z": -10,
      "name": "Rock_Stone"
    },
    {
      "x": -5,
      "y": 17,
      "z": -9,
      "name": "Rock_Stone"
    },
    {
      "x": -5,
      "y": 18,
      "z": -9,
      "name": "Rock_Stone"
    },
    {
      "x": -5,
      "y": 19,
      "z": -9,
      "name": "Rock_Stone"
    },
    {
      "x": -5,
      "y": 20,
      "z": -9,
      "name": "Rock_Stone"
    },
    {
      "x": -5,
      "y": 21,
      "z": -9,
      "name": "Rock_Stone"
    },
    {
      "x": -5,
      "y": 14,
      "z": -8,
      "name": "Rock_Stone"
    },
    {
      "x": -5,
      "y": 15,
      "z": -8,
      "name": "Rock_Stone"
    },
    {
      "x": -5,
      "y": 16,
      "z": -8,
      "name": "Rock_Stone"
    },
    {
      "x": -5,
      "y": 17,
      "z": -8,
      "name": "Rock_Stone"
    },
    {
      "x": -5,
      "y": 18,
      "z": -8,
      "name": "Rock_Stone"
    },
    {
      "x": -5,
      "y": 19,
      "z": -8,
      "name": "Rock_Stone"
    },
    {
      "x": -5,
      "y": 20,
      "z": -8,
      "name": "Rock_Stone"
    },
    {
      "x": -5,
      "y": 21,
      "z": -8,
      "name": "Rock_Stone"
    },
    {
      "x": -5,
      "y": 13,
      "z": -7,
      "name": "Rock_Stone"
    },
    {
      "x": -5,
      "y": 14,
      "z": -7,
      "name": "Rock_Stone"
    },
    {
      "x": -5,
      "y": 15,
      "z": -7,
      "name": "Rock_Stone"
    },
    {
      "x": -5,
      "y": 16,
      "z": -7,
      "name": "Rock_Stone"
    },
    {
      "x": -5,
      "y": 17,
      "z": -7,
      "name": "Rock_Stone"
    },
    {
      "x": -5,
      "y": 18,
      "z": -7,
      "name": "Rock_Stone"
    },
    {
      "x": -5,
      "y": 19,
      "z": -7,
      "name": "Rock_Stone"
    },
    {
      "x": -5,
      "y": 20,
      "z": -7,
      "name": "Rock_Stone"
    },
    {
      "x": -5,
      "y": 21,
      "z": -7,
      "name": "Rock_Stone"
    },
    {
      "x": -5,
      "y": 12,
      "z": -6,
      "name": "Rock_Stone"
    },
    {
      "x": -5,
      "y": 13,
      "z": -6,
      "name": "Rock_Stone"
    },
    {
      "x": -5,
      "y": 14,
      "z": -6,
      "name": "Rock_Stone"
    },
    {
      "x": -5,
      "y": 15,
      "z": -6,
      "name": "Rock_Stone"
    },
    {
      "x": -5,
      "y": 16,
      "z": -6,
      "name": "Rock_Stone"
    },
    {
      "x": -5,
      "y": 17,
      "z": -6,
      "name": "Rock_Stone"
    },
    {
      "x": -5,
      "y": 18,
      "z": -6,
      "name": "Rock_Stone"
    },
    {
      "x": -5,
      "y": 19,
      "z": -6,
      "name": "Rock_Stone"
    },
    {
      "x": -5,
      "y": 20,
      "z": -6,
      "name": "Rock_Stone"
    },
    {
      "x": -5,
      "y": 21,
      "z": -6,
      "name": "Rock_Stone"
    },
    {
      "x": -5,
      "y": 12,
      "z": -5,
      "name": "Rock_Stone"
    },
    {
      "x": -5,
      "y": 13,
      "z": -5,
      "name": "Rock_Stone"
    },
    {
      "x": -5,
      "y": 14,
      "z": -5,
      "name": "Rock_Stone"
    },
    {
      "x": -5,
      "y": 15,
      "z": -5,
      "name": "Rock_Stone"
    },
    {
      "x": -5,
      "y": 16,
      "z": -5,
      "name": "Rock_Stone"
    },
    {
      "x": -5,
      "y": 17,
      "z": -5,
      "name": "Rock_Stone"
    },
    {
      "x": -5,
      "y": 18,
      "z": -5,
      "name": "Rock_Stone"
    },
    {
      "x": -5,
      "y": 19,
      "z": -5,
      "name": "Rock_Stone"
    },
    {
      "x": -5,
      "y": 20,
      "z": -5,
      "name": "Rock_Stone"
    },
    {
      "x": -5,
      "y": 21,
      "z": -5,
      "name": "Rock_Stone"
    },
    {
      "x": -5,
      "y": 22,
      "z": -5,
      "name": "Soil_Dirt"
    },
    {
      "x": -5,
      "y": 23,
      "z": -5,
      "name": "Soil_Grass"
    },
    {
      "x": -5,
      "y": 12,
      "z": -4,
      "name": "Rock_Stone"
    },
    {
      "x": -5,
      "y": 13,
      "z": -4,
      "name": "Rock_Stone"
    },
    {
      "x": -5,
      "y": 14,
      "z": -4,
      "name": "Rock_Stone"
    },
    {
      "x": -5,
      "y": 15,
      "z": -4,
      "name": "Rock_Stone"
    },
    {
      "x": -5,
      "y": 16,
      "z": -4,
      "name": "Rock_Stone"
    },
    {
      "x": -5,
      "y": 17,
      "z": -4,
      "name": "Rock_Stone"
    },
    {
      "x": -5,
      "y": 18,
      "z": -4,
      "name": "Rock_Stone"
    },
    {
      "x": -5,
      "y": 19,
      "z": -4,
      "name": "Rock_Stone"
    },
    {
      "x": -5,
      "y": 20,
      "z": -4,
      "name": "Rock_Stone"
    },
    {
      "x": -5,
      "y": 21,
      "z": -4,
      "name": "Rock_Stone"
    },
    {
      "x": -5,
      "y": 22,
      "z": -4,
      "name": "Soil_Dirt"
    },
    {
      "x": -5,
      "y": 23,
      "z": -4,
      "name": "Soil_Grass"
    },
    {
      "x": -5,
      "y": 24,
      "z": -4,
      "name": "Plant_Grass_Sharp_Tall"
    },
    {
      "x": -5,
      "y": 25,
      "z": -4,
      "name": "Plant_Grass_Sharp_Tall",
      "filler": 1024
    },
    {
      "x": -5,
      "y": 12,
      "z": -3,
      "name": "Rock_Stone"
    },
    {
      "x": -5,
      "y": 13,
      "z": -3,
      "name": "Rock_Stone"
    },
    {
      "x": -5,
      "y": 14,
      "z": -3,
      "name": "Rock_Stone"
    },
    {
      "x": -5,
      "y": 15,
      "z": -3,
      "name": "Rock_Stone"
    },
    {
      "x": -5,
      "y": 16,
      "z": -3,
      "name": "Rock_Stone"
    },
    {
      "x": -5,
      "y": 17,
      "z": -3,
      "name": "Rock_Stone"
    },
    {
      "x": -5,
      "y": 18,
      "z": -3,
      "name": "Rock_Stone"
    },
    {
      "x": -5,
      "y": 19,
      "z": -3,
      "name": "Rock_Stone"
    },
    {
      "x": -5,
      "y": 20,
      "z": -3,
      "name": "Rock_Stone"
    },
    {
      "x": -5,
      "y": 21,
      "z": -3,
      "name": "Rock_Stone"
    },
    {
      "x": -5,
      "y": 22,
      "z": -3,
      "name": "Soil_Dirt"
    },
    {
      "x": -5,
      "y": 23,
      "z": -3,
      "name": "Soil_Dirt"
    },
    {
      "x": -5,
      "y": 24,
      "z": -3,
      "name": "Soil_Grass"
    },
    {
      "x": -5,
      "y": 12,
      "z": -2,
      "name": "Rock_Stone"
    },
    {
      "x": -5,
      "y": 13,
      "z": -2,
      "name": "Rock_Stone"
    },
    {
      "x": -5,
      "y": 14,
      "z": -2,
      "name": "Rock_Stone"
    },
    {
      "x": -5,
      "y": 15,
      "z": -2,
      "name": "Rock_Stone"
    },
    {
      "x": -5,
      "y": 16,
      "z": -2,
      "name": "Rock_Stone"
    },
    {
      "x": -5,
      "y": 17,
      "z": -2,
      "name": "Rock_Stone"
    },
    {
      "x": -5,
      "y": 18,
      "z": -2,
      "name": "Rock_Stone"
    },
    {
      "x": -5,
      "y": 19,
      "z": -2,
      "name": "Rock_Stone"
    },
    {
      "x": -5,
      "y": 20,
      "z": -2,
      "name": "Rock_Stone"
    },
    {
      "x": -5,
      "y": 21,
      "z": -2,
      "name": "Rock_Stone"
    },
    {
      "x": -5,
      "y": 22,
      "z": -2,
      "name": "Soil_Dirt"
    },
    {
      "x": -5,
      "y": 23,
      "z": -2,
      "name": "Soil_Dirt"
    },
    {
      "x": -5,
      "y": 24,
      "z": -2,
      "name": "Soil_Grass"
    },
    {
      "x": -5,
      "y": 13,
      "z": -1,
      "name": "Rock_Stone"
    },
    {
      "x": -5,
      "y": 14,
      "z": -1,
      "name": "Rock_Stone"
    },
    {
      "x": -5,
      "y": 15,
      "z": -1,
      "name": "Rock_Stone"
    },
    {
      "x": -5,
      "y": 16,
      "z": -1,
      "name": "Rock_Stone"
    },
    {
      "x": -5,
      "y": 17,
      "z": -1,
      "name": "Rock_Stone"
    },
    {
      "x": -5,
      "y": 18,
      "z": -1,
      "name": "Rock_Stone"
    },
    {
      "x": -5,
      "y": 19,
      "z": -1,
      "name": "Rock_Stone"
    },
    {
      "x": -5,
      "y": 20,
      "z": -1,
      "name": "Rock_Stone"
    },
    {
      "x": -5,
      "y": 21,
      "z": -1,
      "name": "Rock_Stone"
    },
    {
      "x": -5,
      "y": 22,
      "z": -1,
      "name": "Rock_Stone"
    },
    {
      "x": -5,
      "y": 23,
      "z": -1,
      "name": "Soil_Dirt"
    },
    {
      "x": -5,
      "y": 24,
      "z": -1,
      "name": "Soil_Dirt"
    },
    {
      "x": -5,
      "y": 25,
      "z": -1,
      "name": "Soil_Grass"
    },
    {
      "x": -5,
      "y": 37,
      "z": -1,
      "name": "Rock_Stone"
    },
    {
      "x": -5,
      "y": 14,
      "z": 0,
      "name": "Rock_Stone"
    },
    {
      "x": -5,
      "y": 15,
      "z": 0,
      "name": "Rock_Stone"
    },
    {
      "x": -5,
      "y": 16,
      "z": 0,
      "name": "Rock_Stone"
    },
    {
      "x": -5,
      "y": 17,
      "z": 0,
      "name": "Rock_Stone"
    },
    {
      "x": -5,
      "y": 18,
      "z": 0,
      "name": "Rock_Stone"
    },
    {
      "x": -5,
      "y": 19,
      "z": 0,
      "name": "Rock_Stone"
    },
    {
      "x": -5,
      "y": 20,
      "z": 0,
      "name": "Rock_Stone"
    },
    {
      "x": -5,
      "y": 21,
      "z": 0,
      "name": "Rock_Stone"
    },
    {
      "x": -5,
      "y": 22,
      "z": 0,
      "name": "Rock_Stone"
    },
    {
      "x": -5,
      "y": 23,
      "z": 0,
      "name": "Soil_Dirt"
    },
    {
      "x": -5,
      "y": 24,
      "z": 0,
      "name": "Soil_Dirt"
    },
    {
      "x": -5,
      "y": 25,
      "z": 0,
      "name": "Soil_Grass"
    },
    {
      "x": -5,
      "y": 36,
      "z": 0,
      "name": "Rock_Stone"
    },
    {
      "x": -5,
      "y": 37,
      "z": 0,
      "name": "Soil_Dirt"
    },
    {
      "x": -5,
      "y": 38,
      "z": 0,
      "name": "Soil_Dirt"
    },
    {
      "x": -5,
      "y": 39,
      "z": 0,
      "name": "Soil_Grass"
    },
    {
      "x": -5,
      "y": 15,
      "z": 1,
      "name": "Rock_Stone"
    },
    {
      "x": -5,
      "y": 16,
      "z": 1,
      "name": "Rock_Stone"
    },
    {
      "x": -5,
      "y": 17,
      "z": 1,
      "name": "Rock_Stone"
    },
    {
      "x": -5,
      "y": 18,
      "z": 1,
      "name": "Rock_Stone"
    },
    {
      "x": -5,
      "y": 19,
      "z": 1,
      "name": "Rock_Stone"
    },
    {
      "x": -5,
      "y": 20,
      "z": 1,
      "name": "Rock_Stone"
    },
    {
      "x": -5,
      "y": 21,
      "z": 1,
      "name": "Rock_Stone"
    },
    {
      "x": -5,
      "y": 22,
      "z": 1,
      "name": "Rock_Stone"
    },
    {
      "x": -5,
      "y": 23,
      "z": 1,
      "name": "Rock_Stone"
    },
    {
      "x": -5,
      "y": 24,
      "z": 1,
      "name": "Soil_Dirt"
    },
    {
      "x": -5,
      "y": 25,
      "z": 1,
      "name": "Soil_Grass"
    },
    {
      "x": -5,
      "y": 26,
      "z": 1,
      "name": "Plant_Grass_Sharp"
    },
    {
      "x": -5,
      "y": 35,
      "z": 1,
      "name": "Rock_Stone"
    },
    {
      "x": -5,
      "y": 36,
      "z": 1,
      "name": "Rock_Stone"
    },
    {
      "x": -5,
      "y": 37,
      "z": 1,
      "name": "Soil_Dirt"
    },
    {
      "x": -5,
      "y": 38,
      "z": 1,
      "name": "Soil_Dirt"
    },
    {
      "x": -5,
      "y": 39,
      "z": 1,
      "name": "Soil_Grass"
    },
    {
      "x": -5,
      "y": 16,
      "z": 2,
      "name": "Rock_Stone"
    },
    {
      "x": -5,
      "y": 17,
      "z": 2,
      "name": "Rock_Stone"
    },
    {
      "x": -5,
      "y": 18,
      "z": 2,
      "name": "Rock_Stone"
    },
    {
      "x": -5,
      "y": 19,
      "z": 2,
      "name": "Rock_Stone"
    },
    {
      "x": -5,
      "y": 20,
      "z": 2,
      "name": "Rock_Stone"
    },
    {
      "x": -5,
      "y": 21,
      "z": 2,
      "name": "Rock_Stone"
    },
    {
      "x": -5,
      "y": 22,
      "z": 2,
      "name": "Rock_Stone"
    },
    {
      "x": -5,
      "y": 23,
      "z": 2,
      "name": "Soil_Dirt"
    },
    {
      "x": -5,
      "y": 24,
      "z": 2,
      "name": "Soil_Dirt"
    },
    {
      "x": -5,
      "y": 25,
      "z": 2,
      "name": "Soil_Grass"
    },
    {
      "x": -5,
      "y": 26,
      "z": 2,
      "name": "Plant_Grass_Sharp_Tall"
    },
    {
      "x": -5,
      "y": 27,
      "z": 2,
      "name": "Plant_Grass_Sharp_Tall",
      "filler": 1024
    },
    {
      "x": -5,
      "y": 35,
      "z": 2,
      "name": "Rock_Stone"
    },
    {
      "x": -5,
      "y": 36,
      "z": 2,
      "name": "Rock_Stone"
    },
    {
      "x": -5,
      "y": 37,
      "z": 2,
      "name": "Soil_Dirt"
    },
    {
      "x": -5,
      "y": 38,
      "z": 2,
      "name": "Soil_Dirt"
    },
    {
      "x": -5,
      "y": 39,
      "z": 2,
      "name": "Soil_Grass"
    },
    {
      "x": -5,
      "y": 18,
      "z": 3,
      "name": "Rock_Stone"
    },
    {
      "x": -5,
      "y": 19,
      "z": 3,
      "name": "Rock_Stone"
    },
    {
      "x": -5,
      "y": 20,
      "z": 3,
      "name": "Rock_Stone"
    },
    {
      "x": -5,
      "y": 21,
      "z": 3,
      "name": "Rock_Stone"
    },
    {
      "x": -5,
      "y": 22,
      "z": 3,
      "name": "Rock_Stone"
    },
    {
      "x": -5,
      "y": 23,
      "z": 3,
      "name": "Soil_Dirt"
    },
    {
      "x": -5,
      "y": 24,
      "z": 3,
      "name": "Soil_Dirt"
    },
    {
      "x": -5,
      "y": 25,
      "z": 3,
      "name": "Soil_Grass"
    },
    {
      "x": -5,
      "y": 26,
      "z": 3,
      "name": "Plant_Grass_Sharp_Tall"
    },
    {
      "x": -5,
      "y": 27,
      "z": 3,
      "name": "Plant_Grass_Sharp_Tall",
      "filler": 1024
    },
    {
      "x": -5,
      "y": 35,
      "z": 3,
      "name": "Rock_Stone"
    },
    {
      "x": -5,
      "y": 36,
      "z": 3,
      "name": "Rock_Stone"
    },
    {
      "x": -5,
      "y": 37,
      "z": 3,
      "name": "Soil_Dirt"
    },
    {
      "x": -5,
      "y": 38,
      "z": 3,
      "name": "Soil_Dirt"
    },
    {
      "x": -5,
      "y": 39,
      "z": 3,
      "name": "Soil_Grass"
    },
    {
      "x": -5,
      "y": 40,
      "z": 3,
      "name": "Plant_Grass_Sharp_Tall"
    },
    {
      "x": -5,
      "y": 41,
      "z": 3,
      "name": "Plant_Grass_Sharp_Tall",
      "filler": 1024
    },
    {
      "x": -5,
      "y": 21,
      "z": 4,
      "name": "Rock_Stone"
    },
    {
      "x": -5,
      "y": 22,
      "z": 4,
      "name": "Soil_Dirt"
    },
    {
      "x": -5,
      "y": 23,
      "z": 4,
      "name": "Soil_Dirt"
    },
    {
      "x": -5,
      "y": 24,
      "z": 4,
      "name": "Soil_Dirt"
    },
    {
      "x": -5,
      "y": 25,
      "z": 4,
      "name": "Soil_Grass"
    },
    {
      "x": -5,
      "y": 33,
      "z": 4,
      "name": "Rock_Stone"
    },
    {
      "x": -5,
      "y": 34,
      "z": 4,
      "name": "Rock_Stone"
    },
    {
      "x": -5,
      "y": 35,
      "z": 4,
      "name": "Rock_Stone"
    },
    {
      "x": -5,
      "y": 36,
      "z": 4,
      "name": "Rock_Stone"
    },
    {
      "x": -5,
      "y": 37,
      "z": 4,
      "name": "Rock_Stone"
    },
    {
      "x": -5,
      "y": 38,
      "z": 4,
      "name": "Soil_Dirt"
    },
    {
      "x": -5,
      "y": 39,
      "z": 4,
      "name": "Soil_Grass"
    },
    {
      "x": -5,
      "y": 40,
      "z": 4,
      "name": "Plant_Grass_Sharp_Tall"
    },
    {
      "x": -5,
      "y": 41,
      "z": 4,
      "name": "Plant_Grass_Sharp_Tall",
      "filler": 1024
    },
    {
      "x": -5,
      "y": 22,
      "z": 5,
      "name": "Soil_Dirt"
    },
    {
      "x": -5,
      "y": 23,
      "z": 5,
      "name": "Soil_Grass"
    },
    {
      "x": -5,
      "y": 32,
      "z": 5,
      "name": "Rock_Stone"
    },
    {
      "x": -5,
      "y": 33,
      "z": 5,
      "name": "Rock_Stone"
    },
    {
      "x": -5,
      "y": 34,
      "z": 5,
      "name": "Rock_Stone"
    },
    {
      "x": -5,
      "y": 35,
      "z": 5,
      "name": "Rock_Stone"
    },
    {
      "x": -5,
      "y": 36,
      "z": 5,
      "name": "Rock_Stone"
    },
    {
      "x": -5,
      "y": 37,
      "z": 5,
      "name": "Rock_Stone"
    },
    {
      "x": -5,
      "y": 38,
      "z": 5,
      "name": "Soil_Dirt"
    },
    {
      "x": -5,
      "y": 39,
      "z": 5,
      "name": "Soil_Grass"
    },
    {
      "x": -5,
      "y": 34,
      "z": 6,
      "name": "Rock_Stone"
    },
    {
      "x": -5,
      "y": 35,
      "z": 6,
      "name": "Rock_Stone"
    },
    {
      "x": -5,
      "y": 36,
      "z": 6,
      "name": "Rock_Stone"
    },
    {
      "x": -5,
      "y": 37,
      "z": 6,
      "name": "Rock_Stone"
    },
    {
      "x": -5,
      "y": 38,
      "z": 6,
      "name": "Soil_Dirt"
    },
    {
      "x": -5,
      "y": 39,
      "z": 6,
      "name": "Soil_Grass"
    },
    {
      "x": -5,
      "y": 35,
      "z": 7,
      "name": "Rock_Stone"
    },
    {
      "x": -5,
      "y": 36,
      "z": 7,
      "name": "Rock_Stone"
    },
    {
      "x": -5,
      "y": 37,
      "z": 7,
      "name": "Rock_Stone"
    },
    {
      "x": -5,
      "y": 38,
      "z": 7,
      "name": "Soil_Dirt"
    },
    {
      "x": -5,
      "y": 39,
      "z": 7,
      "name": "Soil_Grass"
    },
    {
      "x": -4,
      "y": 17,
      "z": -9,
      "name": "Rock_Stone"
    },
    {
      "x": -4,
      "y": 18,
      "z": -9,
      "name": "Rock_Stone"
    },
    {
      "x": -4,
      "y": 19,
      "z": -9,
      "name": "Rock_Stone"
    },
    {
      "x": -4,
      "y": 20,
      "z": -9,
      "name": "Rock_Stone"
    },
    {
      "x": -4,
      "y": 21,
      "z": -9,
      "name": "Rock_Stone"
    },
    {
      "x": -4,
      "y": 14,
      "z": -8,
      "name": "Rock_Stone"
    },
    {
      "x": -4,
      "y": 15,
      "z": -8,
      "name": "Rock_Stone"
    },
    {
      "x": -4,
      "y": 16,
      "z": -8,
      "name": "Rock_Stone"
    },
    {
      "x": -4,
      "y": 17,
      "z": -8,
      "name": "Rock_Stone"
    },
    {
      "x": -4,
      "y": 18,
      "z": -8,
      "name": "Rock_Stone"
    },
    {
      "x": -4,
      "y": 19,
      "z": -8,
      "name": "Rock_Stone"
    },
    {
      "x": -4,
      "y": 20,
      "z": -8,
      "name": "Rock_Stone"
    },
    {
      "x": -4,
      "y": 21,
      "z": -8,
      "name": "Soil_Dirt"
    },
    {
      "x": -4,
      "y": 22,
      "z": -8,
      "name": "Soil_Grass"
    },
    {
      "x": -4,
      "y": 13,
      "z": -7,
      "name": "Rock_Stone"
    },
    {
      "x": -4,
      "y": 14,
      "z": -7,
      "name": "Rock_Stone"
    },
    {
      "x": -4,
      "y": 15,
      "z": -7,
      "name": "Rock_Stone"
    },
    {
      "x": -4,
      "y": 16,
      "z": -7,
      "name": "Rock_Stone"
    },
    {
      "x": -4,
      "y": 17,
      "z": -7,
      "name": "Rock_Stone"
    },
    {
      "x": -4,
      "y": 18,
      "z": -7,
      "name": "Rock_Stone"
    },
    {
      "x": -4,
      "y": 19,
      "z": -7,
      "name": "Rock_Stone"
    },
    {
      "x": -4,
      "y": 20,
      "z": -7,
      "name": "Rock_Stone"
    },
    {
      "x": -4,
      "y": 21,
      "z": -7,
      "name": "Soil_Dirt"
    },
    {
      "x": -4,
      "y": 22,
      "z": -7,
      "name": "Soil_Grass"
    },
    {
      "x": -4,
      "y": 23,
      "z": -7,
      "name": "Plant_Grass_Sharp"
    },
    {
      "x": -4,
      "y": 12,
      "z": -6,
      "name": "Rock_Stone"
    },
    {
      "x": -4,
      "y": 13,
      "z": -6,
      "name": "Rock_Stone"
    },
    {
      "x": -4,
      "y": 14,
      "z": -6,
      "name": "Rock_Stone"
    },
    {
      "x": -4,
      "y": 15,
      "z": -6,
      "name": "Rock_Stone"
    },
    {
      "x": -4,
      "y": 16,
      "z": -6,
      "name": "Rock_Stone"
    },
    {
      "x": -4,
      "y": 17,
      "z": -6,
      "name": "Rock_Stone"
    },
    {
      "x": -4,
      "y": 18,
      "z": -6,
      "name": "Rock_Stone"
    },
    {
      "x": -4,
      "y": 19,
      "z": -6,
      "name": "Rock_Stone"
    },
    {
      "x": -4,
      "y": 20,
      "z": -6,
      "name": "Rock_Stone"
    },
    {
      "x": -4,
      "y": 21,
      "z": -6,
      "name": "Soil_Dirt"
    },
    {
      "x": -4,
      "y": 22,
      "z": -6,
      "name": "Soil_Grass"
    },
    {
      "x": -4,
      "y": 12,
      "z": -5,
      "name": "Rock_Stone"
    },
    {
      "x": -4,
      "y": 13,
      "z": -5,
      "name": "Rock_Stone"
    },
    {
      "x": -4,
      "y": 14,
      "z": -5,
      "name": "Rock_Stone"
    },
    {
      "x": -4,
      "y": 15,
      "z": -5,
      "name": "Rock_Stone"
    },
    {
      "x": -4,
      "y": 16,
      "z": -5,
      "name": "Rock_Stone"
    },
    {
      "x": -4,
      "y": 17,
      "z": -5,
      "name": "Rock_Stone"
    },
    {
      "x": -4,
      "y": 18,
      "z": -5,
      "name": "Rock_Stone"
    },
    {
      "x": -4,
      "y": 19,
      "z": -5,
      "name": "Rock_Stone"
    },
    {
      "x": -4,
      "y": 20,
      "z": -5,
      "name": "Rock_Stone"
    },
    {
      "x": -4,
      "y": 21,
      "z": -5,
      "name": "Rock_Stone"
    },
    {
      "x": -4,
      "y": 22,
      "z": -5,
      "name": "Soil_Dirt"
    },
    {
      "x": -4,
      "y": 23,
      "z": -5,
      "name": "Soil_Grass"
    },
    {
      "x": -4,
      "y": 12,
      "z": -4,
      "name": "Rock_Stone"
    },
    {
      "x": -4,
      "y": 13,
      "z": -4,
      "name": "Rock_Stone"
    },
    {
      "x": -4,
      "y": 14,
      "z": -4,
      "name": "Rock_Stone"
    },
    {
      "x": -4,
      "y": 15,
      "z": -4,
      "name": "Rock_Stone"
    },
    {
      "x": -4,
      "y": 16,
      "z": -4,
      "name": "Rock_Stone"
    },
    {
      "x": -4,
      "y": 17,
      "z": -4,
      "name": "Rock_Stone"
    },
    {
      "x": -4,
      "y": 18,
      "z": -4,
      "name": "Rock_Stone"
    },
    {
      "x": -4,
      "y": 19,
      "z": -4,
      "name": "Rock_Stone"
    },
    {
      "x": -4,
      "y": 20,
      "z": -4,
      "name": "Rock_Stone"
    },
    {
      "x": -4,
      "y": 21,
      "z": -4,
      "name": "Rock_Stone"
    },
    {
      "x": -4,
      "y": 22,
      "z": -4,
      "name": "Soil_Dirt"
    },
    {
      "x": -4,
      "y": 23,
      "z": -4,
      "name": "Soil_Grass"
    },
    {
      "x": -4,
      "y": 24,
      "z": -4,
      "name": "Plant_Grass_Sharp"
    },
    {
      "x": -4,
      "y": 12,
      "z": -3,
      "name": "Rock_Stone"
    },
    {
      "x": -4,
      "y": 13,
      "z": -3,
      "name": "Rock_Stone"
    },
    {
      "x": -4,
      "y": 14,
      "z": -3,
      "name": "Rock_Stone"
    },
    {
      "x": -4,
      "y": 15,
      "z": -3,
      "name": "Rock_Stone"
    },
    {
      "x": -4,
      "y": 16,
      "z": -3,
      "name": "Rock_Stone"
    },
    {
      "x": -4,
      "y": 17,
      "z": -3,
      "name": "Rock_Stone"
    },
    {
      "x": -4,
      "y": 18,
      "z": -3,
      "name": "Rock_Stone"
    },
    {
      "x": -4,
      "y": 19,
      "z": -3,
      "name": "Rock_Stone"
    },
    {
      "x": -4,
      "y": 20,
      "z": -3,
      "name": "Rock_Stone"
    },
    {
      "x": -4,
      "y": 21,
      "z": -3,
      "name": "Rock_Stone"
    },
    {
      "x": -4,
      "y": 22,
      "z": -3,
      "name": "Soil_Dirt"
    },
    {
      "x": -4,
      "y": 23,
      "z": -3,
      "name": "Soil_Dirt"
    },
    {
      "x": -4,
      "y": 24,
      "z": -3,
      "name": "Soil_Grass"
    },
    {
      "x": -4,
      "y": 12,
      "z": -2,
      "name": "Rock_Stone"
    },
    {
      "x": -4,
      "y": 13,
      "z": -2,
      "name": "Rock_Stone"
    },
    {
      "x": -4,
      "y": 14,
      "z": -2,
      "name": "Rock_Stone"
    },
    {
      "x": -4,
      "y": 15,
      "z": -2,
      "name": "Rock_Stone"
    },
    {
      "x": -4,
      "y": 16,
      "z": -2,
      "name": "Rock_Stone"
    },
    {
      "x": -4,
      "y": 17,
      "z": -2,
      "name": "Rock_Stone"
    },
    {
      "x": -4,
      "y": 18,
      "z": -2,
      "name": "Rock_Stone"
    },
    {
      "x": -4,
      "y": 19,
      "z": -2,
      "name": "Rock_Stone"
    },
    {
      "x": -4,
      "y": 20,
      "z": -2,
      "name": "Rock_Stone"
    },
    {
      "x": -4,
      "y": 21,
      "z": -2,
      "name": "Rock_Stone"
    },
    {
      "x": -4,
      "y": 22,
      "z": -2,
      "name": "Rock_Stone"
    },
    {
      "x": -4,
      "y": 23,
      "z": -2,
      "name": "Soil_Dirt"
    },
    {
      "x": -4,
      "y": 24,
      "z": -2,
      "name": "Soil_Dirt"
    },
    {
      "x": -4,
      "y": 25,
      "z": -2,
      "name": "Soil_Grass"
    },
    {
      "x": -4,
      "y": 13,
      "z": -1,
      "name": "Rock_Stone"
    },
    {
      "x": -4,
      "y": 14,
      "z": -1,
      "name": "Rock_Stone"
    },
    {
      "x": -4,
      "y": 15,
      "z": -1,
      "name": "Rock_Stone"
    },
    {
      "x": -4,
      "y": 16,
      "z": -1,
      "name": "Rock_Stone"
    },
    {
      "x": -4,
      "y": 17,
      "z": -1,
      "name": "Rock_Stone"
    },
    {
      "x": -4,
      "y": 18,
      "z": -1,
      "name": "Rock_Stone"
    },
    {
      "x": -4,
      "y": 19,
      "z": -1,
      "name": "Rock_Stone"
    },
    {
      "x": -4,
      "y": 20,
      "z": -1,
      "name": "Rock_Stone"
    },
    {
      "x": -4,
      "y": 21,
      "z": -1,
      "name": "Rock_Stone"
    },
    {
      "x": -4,
      "y": 22,
      "z": -1,
      "name": "Rock_Stone"
    },
    {
      "x": -4,
      "y": 23,
      "z": -1,
      "name": "Rock_Stone"
    },
    {
      "x": -4,
      "y": 24,
      "z": -1,
      "name": "Soil_Dirt"
    },
    {
      "x": -4,
      "y": 25,
      "z": -1,
      "name": "Soil_Grass"
    },
    {
      "x": -4,
      "y": 26,
      "z": -1,
      "name": "Plant_Grass_Sharp_Tall"
    },
    {
      "x": -4,
      "y": 27,
      "z": -1,
      "name": "Plant_Grass_Sharp_Tall",
      "filler": 1024
    },
    {
      "x": -4,
      "y": 36,
      "z": -1,
      "name": "Rock_Stone"
    },
    {
      "x": -4,
      "y": 37,
      "z": -1,
      "name": "Rock_Stone"
    },
    {
      "x": -4,
      "y": 38,
      "z": -1,
      "name": "Rock_Stone"
    },
    {
      "x": -4,
      "y": 14,
      "z": 0,
      "name": "Rock_Stone"
    },
    {
      "x": -4,
      "y": 15,
      "z": 0,
      "name": "Rock_Stone"
    },
    {
      "x": -4,
      "y": 16,
      "z": 0,
      "name": "Rock_Stone"
    },
    {
      "x": -4,
      "y": 17,
      "z": 0,
      "name": "Rock_Stone"
    },
    {
      "x": -4,
      "y": 18,
      "z": 0,
      "name": "Rock_Stone"
    },
    {
      "x": -4,
      "y": 19,
      "z": 0,
      "name": "Rock_Stone"
    },
    {
      "x": -4,
      "y": 20,
      "z": 0,
      "name": "Rock_Stone"
    },
    {
      "x": -4,
      "y": 21,
      "z": 0,
      "name": "Rock_Stone"
    },
    {
      "x": -4,
      "y": 22,
      "z": 0,
      "name": "Rock_Stone"
    },
    {
      "x": -4,
      "y": 23,
      "z": 0,
      "name": "Rock_Stone"
    },
    {
      "x": -4,
      "y": 24,
      "z": 0,
      "name": "Soil_Dirt"
    },
    {
      "x": -4,
      "y": 25,
      "z": 0,
      "name": "Soil_Dirt"
    },
    {
      "x": -4,
      "y": 26,
      "z": 0,
      "name": "Rock_Stone"
    },
    {
      "x": -4,
      "y": 36,
      "z": 0,
      "name": "Rock_Stone"
    },
    {
      "x": -4,
      "y": 37,
      "z": 0,
      "name": "Soil_Dirt"
    },
    {
      "x": -4,
      "y": 38,
      "z": 0,
      "name": "Soil_Grass"
    },
    {
      "x": -4,
      "y": 15,
      "z": 1,
      "name": "Rock_Stone"
    },
    {
      "x": -4,
      "y": 16,
      "z": 1,
      "name": "Rock_Stone"
    },
    {
      "x": -4,
      "y": 17,
      "z": 1,
      "name": "Rock_Stone"
    },
    {
      "x": -4,
      "y": 18,
      "z": 1,
      "name": "Rock_Stone"
    },
    {
      "x": -4,
      "y": 19,
      "z": 1,
      "name": "Rock_Stone"
    },
    {
      "x": -4,
      "y": 20,
      "z": 1,
      "name": "Rock_Stone"
    },
    {
      "x": -4,
      "y": 21,
      "z": 1,
      "name": "Rock_Stone"
    },
    {
      "x": -4,
      "y": 22,
      "z": 1,
      "name": "Rock_Stone"
    },
    {
      "x": -4,
      "y": 23,
      "z": 1,
      "name": "Rock_Stone"
    },
    {
      "x": -4,
      "y": 24,
      "z": 1,
      "name": "Soil_Dirt"
    },
    {
      "x": -4,
      "y": 25,
      "z": 1,
      "name": "Soil_Dirt"
    },
    {
      "x": -4,
      "y": 26,
      "z": 1,
      "name": "Rock_Stone"
    },
    {
      "x": -4,
      "y": 35,
      "z": 1,
      "name": "Rock_Stone"
    },
    {
      "x": -4,
      "y": 36,
      "z": 1,
      "name": "Rock_Stone"
    },
    {
      "x": -4,
      "y": 37,
      "z": 1,
      "name": "Soil_Dirt"
    },
    {
      "x": -4,
      "y": 38,
      "z": 1,
      "name": "Soil_Dirt"
    },
    {
      "x": -4,
      "y": 39,
      "z": 1,
      "name": "Soil_Grass"
    },
    {
      "x": -4,
      "y": 16,
      "z": 2,
      "name": "Rock_Stone"
    },
    {
      "x": -4,
      "y": 17,
      "z": 2,
      "name": "Rock_Stone"
    },
    {
      "x": -4,
      "y": 18,
      "z": 2,
      "name": "Rock_Stone"
    },
    {
      "x": -4,
      "y": 19,
      "z": 2,
      "name": "Rock_Stone"
    },
    {
      "x": -4,
      "y": 20,
      "z": 2,
      "name": "Rock_Stone"
    },
    {
      "x": -4,
      "y": 21,
      "z": 2,
      "name": "Rock_Stone"
    },
    {
      "x": -4,
      "y": 22,
      "z": 2,
      "name": "Rock_Stone"
    },
    {
      "x": -4,
      "y": 23,
      "z": 2,
      "name": "Rock_Stone"
    },
    {
      "x": -4,
      "y": 24,
      "z": 2,
      "name": "Soil_Dirt"
    },
    {
      "x": -4,
      "y": 25,
      "z": 2,
      "name": "Soil_Dirt"
    },
    {
      "x": -4,
      "y": 26,
      "z": 2,
      "name": "Soil_Grass"
    },
    {
      "x": -4,
      "y": 34,
      "z": 2,
      "name": "Rock_Stone"
    },
    {
      "x": -4,
      "y": 35,
      "z": 2,
      "name": "Rock_Stone"
    },
    {
      "x": -4,
      "y": 36,
      "z": 2,
      "name": "Rock_Stone"
    },
    {
      "x": -4,
      "y": 37,
      "z": 2,
      "name": "Rock_Stone"
    },
    {
      "x": -4,
      "y": 38,
      "z": 2,
      "name": "Soil_Dirt"
    },
    {
      "x": -4,
      "y": 39,
      "z": 2,
      "name": "Soil_Grass"
    },
    {
      "x": -4,
      "y": 17,
      "z": 3,
      "name": "Rock_Stone"
    },
    {
      "x": -4,
      "y": 18,
      "z": 3,
      "name": "Rock_Stone"
    },
    {
      "x": -4,
      "y": 19,
      "z": 3,
      "name": "Rock_Stone"
    },
    {
      "x": -4,
      "y": 20,
      "z": 3,
      "name": "Rock_Stone"
    },
    {
      "x": -4,
      "y": 21,
      "z": 3,
      "name": "Rock_Stone"
    },
    {
      "x": -4,
      "y": 22,
      "z": 3,
      "name": "Rock_Stone"
    },
    {
      "x": -4,
      "y": 23,
      "z": 3,
      "name": "Soil_Dirt"
    },
    {
      "x": -4,
      "y": 24,
      "z": 3,
      "name": "Soil_Dirt"
    },
    {
      "x": -4,
      "y": 25,
      "z": 3,
      "name": "Soil_Grass"
    },
    {
      "x": -4,
      "y": 26,
      "z": 3,
      "name": "Plant_Grass_Sharp_Tall"
    },
    {
      "x": -4,
      "y": 27,
      "z": 3,
      "name": "Plant_Grass_Sharp_Tall",
      "filler": 1024
    },
    {
      "x": -4,
      "y": 32,
      "z": 3,
      "name": "Rock_Stone"
    },
    {
      "x": -4,
      "y": 33,
      "z": 3,
      "name": "Rock_Stone"
    },
    {
      "x": -4,
      "y": 34,
      "z": 3,
      "name": "Rock_Stone"
    },
    {
      "x": -4,
      "y": 35,
      "z": 3,
      "name": "Rock_Stone"
    },
    {
      "x": -4,
      "y": 36,
      "z": 3,
      "name": "Rock_Stone"
    },
    {
      "x": -4,
      "y": 37,
      "z": 3,
      "name": "Rock_Stone"
    },
    {
      "x": -4,
      "y": 38,
      "z": 3,
      "name": "Soil_Dirt"
    },
    {
      "x": -4,
      "y": 39,
      "z": 3,
      "name": "Soil_Grass"
    },
    {
      "x": -4,
      "y": 19,
      "z": 4,
      "name": "Rock_Stone"
    },
    {
      "x": -4,
      "y": 20,
      "z": 4,
      "name": "Rock_Stone"
    },
    {
      "x": -4,
      "y": 21,
      "z": 4,
      "name": "Rock_Stone"
    },
    {
      "x": -4,
      "y": 22,
      "z": 4,
      "name": "Soil_Dirt"
    },
    {
      "x": -4,
      "y": 23,
      "z": 4,
      "name": "Rock_Stone"
    },
    {
      "x": -4,
      "y": 24,
      "z": 4,
      "name": "Rock_Stone"
    },
    {
      "x": -4,
      "y": 25,
      "z": 4,
      "name": "Soil_Grass"
    },
    {
      "x": -4,
      "y": 26,
      "z": 4,
      "name": "Plant_Grass_Sharp"
    },
    {
      "x": -4,
      "y": 31,
      "z": 4,
      "name": "Rock_Stone"
    },
    {
      "x": -4,
      "y": 32,
      "z": 4,
      "name": "Rock_Stone"
    },
    {
      "x": -4,
      "y": 33,
      "z": 4,
      "name": "Rock_Stone"
    },
    {
      "x": -4,
      "y": 34,
      "z": 4,
      "name": "Rock_Stone"
    },
    {
      "x": -4,
      "y": 35,
      "z": 4,
      "name": "Rock_Stone"
    },
    {
      "x": -4,
      "y": 36,
      "z": 4,
      "name": "Rock_Stone"
    },
    {
      "x": -4,
      "y": 37,
      "z": 4,
      "name": "Rock_Stone"
    },
    {
      "x": -4,
      "y": 38,
      "z": 4,
      "name": "Soil_Dirt"
    },
    {
      "x": -4,
      "y": 39,
      "z": 4,
      "name": "Soil_Grass"
    },
    {
      "x": -4,
      "y": 20,
      "z": 5,
      "name": "Rock_Stone"
    },
    {
      "x": -4,
      "y": 21,
      "z": 5,
      "name": "Rock_Stone"
    },
    {
      "x": -4,
      "y": 22,
      "z": 5,
      "name": "Rock_Stone"
    },
    {
      "x": -4,
      "y": 23,
      "z": 5,
      "name": "Rock_Stone"
    },
    {
      "x": -4,
      "y": 24,
      "z": 5,
      "name": "Rock_Stone"
    },
    {
      "x": -4,
      "y": 25,
      "z": 5,
      "name": "Rock_Stone"
    },
    {
      "x": -4,
      "y": 26,
      "z": 5,
      "name": "Rock_Stone"
    },
    {
      "x": -4,
      "y": 27,
      "z": 5,
      "name": "Rock_Stone"
    },
    {
      "x": -4,
      "y": 28,
      "z": 5,
      "name": "Rock_Stone"
    },
    {
      "x": -4,
      "y": 31,
      "z": 5,
      "name": "Rock_Stone"
    },
    {
      "x": -4,
      "y": 32,
      "z": 5,
      "name": "Rock_Stone"
    },
    {
      "x": -4,
      "y": 33,
      "z": 5,
      "name": "Rock_Stone"
    },
    {
      "x": -4,
      "y": 34,
      "z": 5,
      "name": "Rock_Stone"
    },
    {
      "x": -4,
      "y": 35,
      "z": 5,
      "name": "Rock_Stone"
    },
    {
      "x": -4,
      "y": 36,
      "z": 5,
      "name": "Rock_Stone"
    },
    {
      "x": -4,
      "y": 37,
      "z": 5,
      "name": "Rock_Stone"
    },
    {
      "x": -4,
      "y": 38,
      "z": 5,
