{
  "version": 8,
  "blockIdVersion": 8,
  "anchorX": -2,
  "anchorY": 29,
  "anchorZ": -1,
  "blocks": [
    {
      "x": -7,
      "y": 26,
      "z": -3,
      "name": "Rock_Stone"
    },
    {
      "x": -7,
      "y": 27,
      "z": -3,
      "name": "Rock_Stone"
    },
    {
      "x": -7,
      "y": 28,
      "z": -3,
      "name": "Rock_Stone"
    },
    {
      "x": -7,
      "y": 29,
      "z": -3,
      "name": "Rock_Stone"
    },
    {
      "x": -7,
      "y": 25,
      "z": -2,
      "name": "Rock_Stone"
    },
    {
      "x": -7,
      "y": 26,
      "z": -2,
      "name": "Rock_Stone"
    },
    {
      "x": -7,
      "y": 27,
      "z": -2,
      "name": "Rock_Stone"
    },
    {
      "x": -7,
      "y": 28,
      "z": -2,
      "name": "Rock_Stone"
    },
    {
      "x": -7,
      "y": 29,
      "z": -2,
      "name": "Rock_Stone"
    },
    {
      "x": -7,
      "y": 30,
      "z": -2,
      "name": "Rock_Stone"
    },
    {
      "x": -7,
      "y": 31,
      "z": -2,
      "name": "Soil_Dirt"
    },
    {
      "x": -7,
      "y": 32,
      "z": -2,
      "name": "Soil_Dirt"
    },
    {
      "x": -7,
      "y": 33,
      "z": -2,
      "name": "Soil_Grass"
    },
    {
      "x": -7,
      "y": 25,
      "z": -1,
      "name": "Rock_Stone"
    },
    {
      "x": -7,
      "y": 26,
      "z": -1,
      "name": "Rock_Stone"
    },
    {
      "x": -7,
      "y": 27,
      "z": -1,
      "name": "Rock_Stone"
    },
    {
      "x": -7,
      "y": 28,
      "z": -1,
      "name": "Rock_Stone"
    },
    {
      "x": -7,
      "y": 29,
      "z": -1,
      "name": "Rock_Stone"
    },
    {
      "x": -7,
      "y": 30,
      "z": -1,
      "name": "Rock_Stone"
    },
    {
      "x": -7,
      "y": 31,
      "z": -1,
      "name": "Rock_Stone"
    },
    {
      "x": -7,
      "y": 32,
      "z": -1,
      "name": "Soil_Dirt"
    },
    {
      "x": -7,
      "y": 33,
      "z": -1,
      "name": "Soil_Grass"
    },
    {
      "x": -7,
      "y": 25,
      "z": 0,
      "name": "Rock_Stone"
    },
    {
      "x": -7,
      "y": 26,
      "z": 0,
      "name": "Rock_Stone"
    },
    {
      "x": -7,
      "y": 27,
      "z": 0,
      "name": "Rock_Stone"
    },
    {
      "x": -7,
      "y": 28,
      "z": 0,
      "name": "Rock_Stone"
    },
    {
      "x": -7,
      "y": 29,
      "z": 0,
      "name": "Rock_Stone"
    },
    {
      "x": -7,
      "y": 30,
      "z": 0,
      "name": "Rock_Stone"
    },
    {
      "x": -7,
      "y": 31,
      "z": 0,
      "name": "Rock_Stone"
    },
    {
      "x": -7,
      "y": 32,
      "z": 0,
      "name": "Rock_Stone"
    },
    {
      "x": -7,
      "y": 33,
      "z": 0,
      "name": "Soil_Dirt"
    },
    {
      "x": -7,
      "y": 34,
      "z": 0,
      "name": "Soil_Dirt"
    },
    {
      "x": -7,
      "y": 35,
      "z": 0,
      "name": "Soil_Grass"
    },
    {
      "x": -7,
      "y": 26,
      "z": 1,
      "name": "Rock_Stone"
    },
    {
      "x": -7,
      "y": 27,
      "z": 1,
      "name": "Rock_Stone"
    },
    {
      "x": -7,
      "y": 28,
      "z": 1,
      "name": "Rock_Stone"
    },
    {
      "x": -7,
      "y": 29,
      "z": 1,
      "name": "Rock_Stone"
    },
    {
      "x": -7,
      "y": 30,
      "z": 1,
      "name": "Rock_Stone"
    },
    {
      "x": -7,
      "y": 31,
      "z": 1,
      "name": "Rock_Stone"
    },
    {
      "x": -7,
      "y": 32,
      "z": 1,
      "name": "Rock_Stone"
    },
    {
      "x": -7,
      "y": 33,
      "z": 1,
      "name": "Soil_Dirt"
    },
    {
      "x": -7,
      "y": 34,
      "z": 1,
      "name": "Soil_Dirt"
    },
    {
      "x": -7,
      "y": 35,
      "z": 1,
      "name": "Soil_Grass"
    },
    {
      "x": -7,
      "y": 31,
      "z": 2,
      "name": "Rock_Stone"
    },
    {
      "x": -7,
      "y": 32,
      "z": 2,
      "name": "Rock_Stone"
    },
    {
      "x": -7,
      "y": 33,
      "z": 2,
      "name": "Rock_Stone"
    },
    {
      "x": -7,
      "y": 34,
      "z": 2,
      "name": "Soil_Dirt"
    },
    {
      "x": -7,
      "y": 35,
      "z": 2,
      "name": "Soil_Grass"
    },
    {
      "x": -7,
      "y": 36,
      "z": 2,
      "name": "Plant_Grass_Sharp"
    },
    {
      "x": -7,
      "y": 28,
      "z": 3,
      "name": "Soil_Dirt"
    },
    {
      "x": -7,
      "y": 29,
      "z": 3,
      "name": "Soil_Grass"
    },
    {
      "x": -7,
      "y": 33,
      "z": 3,
      "name": "Rock_Stone"
    },
    {
      "x": -7,
      "y": 34,
      "z": 3,
      "name": "Soil_Dirt"
    },
    {
      "x": -7,
      "y": 35,
      "z": 3,
      "name": "Soil_Grass"
    },
    {
      "x": -7,
      "y": 27,
      "z": 4,
      "name": "Soil_Dirt"
    },
    {
      "x": -7,
      "y": 28,
      "z": 4,
      "name": "Soil_Dirt"
    },
    {
      "x": -7,
      "y": 29,
      "z": 4,
      "name": "Soil_Grass"
    },
    {
      "x": -7,
      "y": 27,
      "z": 5,
      "name": "Soil_Dirt"
    },
    {
      "x": -7,
      "y": 28,
      "z": 5,
      "name": "Soil_Dirt"
    },
    {
      "x": -7,
      "y": 29,
      "z": 5,
      "name": "Soil_Grass"
    },
    {
      "x": -7,
      "y": 30,
      "z": 5,
      "name": "Plant_Grass_Sharp"
    },
    {
      "x": -6,
      "y": 25,
      "z": -4,
      "name": "Rock_Stone"
    },
    {
      "x": -6,
      "y": 26,
      "z": -4,
      "name": "Rock_Stone"
    },
    {
      "x": -6,
      "y": 27,
      "z": -4,
      "name": "Rock_Stone"
    },
    {
      "x": -6,
      "y": 28,
      "z": -4,
      "name": "Rock_Stone"
    },
    {
      "x": -6,
      "y": 29,
      "z": -4,
      "name": "Rock_Stone"
    },
    {
      "x": -6,
      "y": 30,
      "z": -4,
      "name": "Rock_Stone"
    },
    {
      "x": -6,
      "y": 31,
      "z": -4,
      "name": "Soil_Dirt"
    },
    {
      "x": -6,
      "y": 32,
      "z": -4,
      "name": "Soil_Grass"
    },
    {
      "x": -6,
      "y": 25,
      "z": -3,
      "name": "Rock_Stone"
    },
    {
      "x": -6,
      "y": 26,
      "z": -3,
      "name": "Rock_Stone"
    },
    {
      "x": -6,
      "y": 27,
      "z": -3,
      "name": "Rock_Stone"
    },
    {
      "x": -6,
      "y": 28,
      "z": -3,
      "name": "Rock_Stone"
    },
    {
      "x": -6,
      "y": 29,
      "z": -3,
      "name": "Rock_Stone"
    },
    {
      "x": -6,
      "y": 30,
      "z": -3,
      "name": "Rock_Stone"
    },
    {
      "x": -6,
      "y": 31,
      "z": -3,
      "name": "Soil_Dirt"
    },
    {
      "x": -6,
      "y": 32,
      "z": -3,
      "name": "Soil_Dirt"
    },
    {
      "x": -6,
      "y": 33,
      "z": -3,
      "name": "Soil_Dirt"
    },
    {
      "x": -6,
      "y": 34,
      "z": -3,
      "name": "Soil_Grass"
    },
    {
      "x": -6,
      "y": 25,
      "z": -2,
      "name": "Rock_Stone"
    },
    {
      "x": -6,
      "y": 26,
      "z": -2,
      "name": "Rock_Stone"
    },
    {
      "x": -6,
      "y": 27,
      "z": -2,
      "name": "Rock_Stone"
    },
    {
      "x": -6,
      "y": 28,
      "z": -2,
      "name": "Rock_Stone"
    },
    {
      "x": -6,
      "y": 29,
      "z": -2,
      "name": "Rock_Stone"
    },
    {
      "x": -6,
      "y": 30,
      "z": -2,
      "name": "Rock_Stone"
    },
    {
      "x": -6,
      "y": 31,
      "z": -2,
      "name": "Soil_Dirt"
    },
    {
      "x": -6,
      "y": 32,
      "z": -2,
      "name": "Soil_Dirt"
    },
    {
      "x": -6,
      "y": 33,
      "z": -2,
      "name": "Soil_Dirt"
    },
    {
      "x": -6,
      "y": 34,
      "z": -2,
      "name": "Soil_Grass"
    },
    {
      "x": -6,
      "y": 24,
      "z": -1,
      "name": "Rock_Stone"
    },
    {
      "x": -6,
      "y": 25,
      "z": -1,
      "name": "Rock_Stone"
    },
    {
      "x": -6,
      "y": 26,
      "z": -1,
      "name": "Rock_Stone"
    },
    {
      "x": -6,
      "y": 27,
      "z": -1,
      "name": "Rock_Stone"
    },
    {
      "x": -6,
      "y": 28,
      "z": -1,
      "name": "Rock_Stone"
    },
    {
      "x": -6,
      "y": 29,
      "z": -1,
      "name": "Rock_Stone"
    },
    {
      "x": -6,
      "y": 30,
      "z": -1,
      "name": "Rock_Stone"
    },
    {
      "x": -6,
      "y": 31,
      "z": -1,
      "name": "Rock_Stone"
    },
    {
      "x": -6,
      "y": 32,
      "z": -1,
      "name": "Soil_Dirt"
    },
    {
      "x": -6,
      "y": 33,
      "z": -1,
      "name": "Soil_Dirt"
    },
    {
      "x": -6,
      "y": 34,
      "z": -1,
      "name": "Soil_Dirt"
    },
    {
      "x": -6,
      "y": 35,
      "z": -1,
      "name": "Soil_Grass"
    },
    {
      "x": -6,
      "y": 23,
      "z": 0,
      "name": "Rock_Stone"
    },
    {
      "x": -6,
      "y": 24,
      "z": 0,
      "name": "Rock_Stone"
    },
    {
      "x": -6,
      "y": 25,
      "z": 0,
      "name": "Rock_Stone"
    },
    {
      "x": -6,
      "y": 26,
      "z": 0,
      "name": "Rock_Stone"
    },
    {
      "x": -6,
      "y": 27,
      "z": 0,
      "name": "Rock_Stone"
    },
    {
      "x": -6,
      "y": 28,
      "z": 0,
      "name": "Rock_Stone"
    },
    {
      "x": -6,
      "y": 29,
      "z": 0,
      "name": "Rock_Stone"
    },
    {
      "x": -6,
      "y": 30,
      "z": 0,
      "name": "Rock_Stone"
    },
    {
      "x": -6,
      "y": 31,
      "z": 0,
      "name": "Rock_Stone"
    },
    {
      "x": -6,
      "y": 32,
      "z": 0,
      "name": "Rock_Stone"
    },
    {
      "x": -6,
      "y": 33,
      "z": 0,
      "name": "Soil_Dirt"
    },
    {
      "x": -6,
      "y": 34,
      "z": 0,
      "name": "Soil_Dirt"
    },
    {
      "x": -6,
      "y": 35,
      "z": 0,
      "name": "Soil_Grass"
    },
    {
      "x": -6,
      "y": 23,
      "z": 1,
      "name": "Rock_Stone"
    },
    {
      "x": -6,
      "y": 24,
      "z": 1,
      "name": "Rock_Stone"
    },
    {
      "x": -6,
      "y": 25,
      "z": 1,
      "name": "Rock_Stone"
    },
    {
      "x": -6,
      "y": 26,
      "z": 1,
      "name": "Rock_Stone"
    },
    {
      "x": -6,
      "y": 27,
      "z": 1,
      "name": "Rock_Stone"
    },
    {
      "x": -6,
      "y": 28,
      "z": 1,
      "name": "Rock_Stone"
    },
    {
      "x": -6,
      "y": 29,
      "z": 1,
      "name": "Rock_Stone"
    },
    {
      "x": -6,
      "y": 30,
      "z": 1,
      "name": "Rock_Stone"
    },
    {
      "x": -6,
      "y": 31,
      "z": 1,
      "name": "Rock_Stone"
    },
    {
      "x": -6,
      "y": 32,
      "z": 1,
      "name": "Rock_Stone"
    },
    {
      "x": -6,
      "y": 33,
      "z": 1,
      "name": "Soil_Dirt"
    },
    {
      "x": -6,
      "y": 34,
      "z": 1,
      "name": "Soil_Dirt"
    },
    {
      "x": -6,
      "y": 35,
      "z": 1,
      "name": "Soil_Grass"
    },
    {
      "x": -6,
      "y": 36,
      "z": 1,
      "name": "Plant_Grass_Sharp_Tall"
    },
    {
      "x": -6,
      "y": 37,
      "z": 1,
      "name": "Plant_Grass_Sharp_Tall",
      "filler": 1024
    },
    {
      "x": -6,
      "y": 25,
      "z": 2,
      "name": "Rock_Stone"
    },
    {
      "x": -6,
      "y": 26,
      "z": 2,
      "name": "Rock_Stone"
    },
    {
      "x": -6,
      "y": 27,
      "z": 2,
      "name": "Rock_Stone"
    },
    {
      "x": -6,
      "y": 28,
      "z": 2,
      "name": "Rock_Stone"
    },
    {
      "x": -6,
      "y": 29,
      "z": 2,
      "name": "Rock_Stone"
    },
    {
      "x": -6,
      "y": 30,
      "z": 2,
      "name": "Rock_Stone"
    },
    {
      "x": -6,
      "y": 31,
      "z": 2,
      "name": "Rock_Stone"
    },
    {
      "x": -6,
      "y": 32,
      "z": 2,
      "name": "Rock_Stone"
    },
    {
      "x": -6,
      "y": 33,
      "z": 2,
      "name": "Rock_Stone"
    },
    {
      "x": -6,
      "y": 34,
      "z": 2,
      "name": "Soil_Dirt"
    },
    {
      "x": -6,
      "y": 35,
      "z": 2,
      "name": "Soil_Grass"
    },
    {
      "x": -6,
      "y": 36,
      "z": 2,
      "name": "Plant_Grass_Sharp"
    },
    {
      "x": -6,
      "y": 26,
      "z": 3,
      "name": "Rock_Stone"
    },
    {
      "x": -6,
      "y": 27,
      "z": 3,
      "name": "Rock_Stone"
    },
    {
      "x": -6,
      "y": 28,
      "z": 3,
      "name": "Soil_Dirt"
    },
    {
      "x": -6,
      "y": 29,
      "z": 3,
      "name": "Rock_Stone"
    },
    {
      "x": -6,
      "y": 30,
      "z": 3,
      "name": "Rock_Stone"
    },
    {
      "x": -6,
      "y": 31,
      "z": 3,
      "name": "Rock_Stone"
    },
    {
      "x": -6,
      "y": 32,
      "z": 3,
      "name": "Rock_Stone"
    },
    {
      "x": -6,
      "y": 33,
      "z": 3,
      "name": "Soil_Dirt"
    },
    {
      "x": -6,
      "y": 34,
      "z": 3,
      "name": "Soil_Dirt"
    },
    {
      "x": -6,
      "y": 35,
      "z": 3,
      "name": "Soil_Grass"
    },
    {
      "x": -6,
      "y": 26,
      "z": 4,
      "name": "Rock_Stone"
    },
    {
      "x": -6,
      "y": 27,
      "z": 4,
      "name": "Soil_Dirt"
    },
    {
      "x": -6,
      "y": 28,
      "z": 4,
      "name": "Soil_Dirt"
    },
    {
      "x": -6,
      "y": 29,
      "z": 4,
      "name": "Soil_Grass"
    },
    {
      "x": -6,
      "y": 30,
      "z": 4,
      "name": "Plant_Grass_Sharp"
    },
    {
      "x": -6,
      "y": 32,
      "z": 4,
      "name": "Rock_Stone"
    },
    {
      "x": -6,
      "y": 33,
      "z": 4,
      "name": "Soil_Dirt"
    },
    {
      "x": -6,
      "y": 34,
      "z": 4,
      "name": "Soil_Dirt"
    },
    {
      "x": -6,
      "y": 35,
      "z": 4,
      "name": "Soil_Grass"
    },
    {
      "x": -6,
      "y": 27,
      "z": 5,
      "name": "Soil_Dirt"
    },
    {
      "x": -6,
      "y": 28,
      "z": 5,
      "name": "Soil_Dirt"
    },
    {
      "x": -6,
      "y": 29,
      "z": 5,
      "name": "Soil_Grass"
    },
    {
      "x": -5,
      "y": 30,
      "z": -5,
      "name": "Rock_Stone"
    },
    {
      "x": -5,
      "y": 31,
      "z": -5,
      "name": "Soil_Dirt"
    },
    {
      "x": -5,
      "y": 32,
      "z": -5,
      "name": "Soil_Dirt"
    },
    {
      "x": -5,
      "y": 33,
      "z": -5,
      "name": "Soil_Grass"
    },
    {
      "x": -5,
      "y": 25,
      "z": -4,
      "name": "Rock_Stone"
    },
    {
      "x": -5,
      "y": 26,
      "z": -4,
      "name": "Rock_Stone"
    },
    {
      "x": -5,
      "y": 27,
      "z": -4,
      "name": "Rock_Stone"
    },
    {
      "x": -5,
      "y": 28,
      "z": -4,
      "name": "Rock_Stone"
    },
    {
      "x": -5,
      "y": 29,
      "z": -4,
      "name": "Rock_Stone"
    },
    {
      "x": -5,
      "y": 30,
      "z": -4,
      "name": "Rock_Stone"
    },
    {
      "x": -5,
      "y": 31,
      "z": -4,
      "name": "Soil_Dirt"
    },
    {
      "x": -5,
      "y": 32,
      "z": -4,
      "name": "Soil_Dirt"
    },
    {
      "x": -5,
      "y": 33,
      "z": -4,
      "name": "Soil_Dirt"
    },
    {
      "x": -5,
      "y": 34,
      "z": -4,
      "name": "Soil_Grass"
    },
    {
      "x": -5,
      "y": 24,
      "z": -3,
      "name": "Rock_Stone"
    },
    {
      "x": -5,
      "y": 25,
      "z": -3,
      "name": "Rock_Stone"
    },
    {
      "x": -5,
      "y": 26,
      "z": -3,
      "name": "Rock_Stone"
    },
    {
      "x": -5,
      "y": 27,
      "z": -3,
      "name": "Rock_Stone"
    },
    {
      "x": -5,
      "y": 28,
      "z": -3,
      "name": "Rock_Stone"
    },
    {
      "x": -5,
      "y": 29,
      "z": -3,
      "name": "Rock_Stone"
    },
    {
      "x": -5,
      "y": 30,
      "z": -3,
      "name": "Rock_Stone"
    },
    {
      "x": -5,
      "y": 31,
      "z": -3,
      "name": "Soil_Dirt"
    },
    {
      "x": -5,
      "y": 32,
      "z": -3,
      "name": "Soil_Dirt"
    },
    {
      "x": -5,
      "y": 33,
      "z": -3,
      "name": "Soil_Dirt"
    },
    {
      "x": -5,
      "y": 34,
      "z": -3,
      "name": "Soil_Grass"
    },
    {
      "x": -5,
      "y": 23,
      "z": -2,
      "name": "Rock_Stone"
    },
    {
      "x": -5,
      "y": 24,
      "z": -2,
      "name": "Rock_Stone"
    },
    {
      "x": -5,
      "y": 25,
      "z": -2,
      "name": "Rock_Stone"
    },
    {
      "x": -5,
      "y": 26,
      "z": -2,
      "name": "Rock_Stone"
    },
    {
      "x": -5,
      "y": 27,
      "z": -2,
      "name": "Rock_Stone"
    },
    {
      "x": -5,
      "y": 28,
      "z": -2,
      "name": "Rock_Stone"
    },
    {
      "x": -5,
      "y": 29,
      "z": -2,
      "name": "Rock_Stone"
    },
    {
      "x": -5,
      "y": 30,
      "z": -2,
      "name": "Rock_Stone"
    },
    {
      "x": -5,
      "y": 31,
      "z": -2,
      "name": "Soil_Dirt"
    },
    {
      "x": -5,
      "y": 32,
      "z": -2,
      "name": "Soil_Dirt"
    },
    {
      "x": -5,
      "y": 33,
      "z": -2,
      "name": "Soil_Dirt"
    },
    {
      "x": -5,
      "y": 34,
      "z": -2,
      "name": "Soil_Grass"
    },
    {
      "x": -5,
      "y": 35,
      "z": -2,
      "name": "Plant_Grass_Sharp"
    },
    {
      "x": -5,
      "y": 23,
      "z": -1,
      "name": "Rock_Stone"
    },
    {
      "x": -5,
      "y": 24,
      "z": -1,
      "name": "Rock_Stone"
    },
    {
      "x": -5,
      "y": 25,
      "z": -1,
      "name": "Rock_Stone"
    },
    {
      "x": -5,
      "y": 26,
      "z": -1,
      "name": "Rock_Stone"
    },
    {
      "x": -5,
      "y": 27,
      "z": -1,
      "name": "Rock_Stone"
    },
    {
      "x": -5,
      "y": 28,
      "z": -1,
      "name": "Rock_Stone"
    },
    {
      "x": -5,
      "y": 29,
      "z": -1,
      "name": "Rock_Stone"
    },
    {
      "x": -5,
      "y": 30,
      "z": -1,
      "name": "Rock_Stone"
    },
    {
      "x": -5,
      "y": 31,
      "z": -1,
      "name": "Rock_Stone"
    },
    {
      "x": -5,
      "y": 32,
      "z": -1,
      "name": "Soil_Dirt"
    },
    {
      "x": -5,
      "y": 33,
      "z": -1,
      "name": "Soil_Dirt"
    },
    {
      "x": -5,
      "y": 34,
      "z": -1,
      "name": "Soil_Dirt"
    },
    {
      "x": -5,
      "y": 35,
      "z": -1,
      "name": "Soil_Grass"
    },
    {
      "x": -5,
      "y": 23,
      "z": 0,
      "name": "Rock_Stone"
    },
    {
      "x": -5,
      "y": 24,
      "z": 0,
      "name": "Rock_Stone"
    },
    {
      "x": -5,
      "y": 25,
      "z": 0,
      "name": "Rock_Stone"
    },
    {
      "x": -5,
      "y": 26,
      "z": 0,
      "name": "Rock_Stone"
    },
    {
      "x": -5,
      "y": 27,
      "z": 0,
      "name": "Rock_Stone"
    },
    {
      "x": -5,
      "y": 28,
      "z": 0,
      "name": "Rock_Stone"
    },
    {
      "x": -5,
      "y": 29,
      "z": 0,
      "name": "Rock_Stone"
    },
    {
      "x": -5,
      "y": 30,
      "z": 0,
      "name": "Rock_Stone"
    },
    {
      "x": -5,
      "y": 31,
      "z": 0,
      "name": "Rock_Stone"
    },
    {
      "x": -5,
      "y": 32,
      "z": 0,
      "name": "Rock_Stone"
    },
    {
      "x": -5,
      "y": 33,
      "z": 0,
      "name": "Rock_Stone"
    },
    {
      "x": -5,
      "y": 34,
      "z": 0,
      "name": "Soil_Dirt"
    },
    {
      "x": -5,
      "y": 35,
      "z": 0,
      "name": "Soil_Grass"
    },
    {
      "x": -5,
      "y": 23,
      "z": 1,
      "name": "Rock_Stone"
    },
    {
      "x": -5,
      "y": 24,
      "z": 1,
      "name": "Rock_Stone"
    },
    {
      "x": -5,
      "y": 25,
      "z": 1,
      "name": "Rock_Stone"
    },
    {
      "x": -5,
      "y": 26,
      "z": 1,
      "name": "Rock_Stone"
    },
    {
      "x": -5,
      "y": 27,
      "z": 1,
      "name": "Rock_Stone"
    },
    {
      "x": -5,
      "y": 28,
      "z": 1,
      "name": "Rock_Stone"
    },
    {
      "x": -5,
      "y": 29,
      "z": 1,
      "name": "Rock_Stone"
    },
    {
      "x": -5,
      "y": 30,
      "z": 1,
      "name": "Rock_Stone"
    },
    {
      "x": -5,
      "y": 31,
      "z": 1,
      "name": "Rock_Stone"
    },
    {
      "x": -5,
      "y": 32,
      "z": 1,
      "name": "Rock_Stone"
    },
    {
      "x": -5,
      "y": 33,
      "z": 1,
      "name": "Rock_Stone"
    },
    {
      "x": -5,
      "y": 34,
      "z": 1,
      "name": "Soil_Dirt"
    },
    {
      "x": -5,
      "y": 35,
      "z": 1,
      "name": "Soil_Grass"
    },
    {
      "x": -5,
      "y": 36,
      "z": 1,
      "name": "Plant_Bush_Arid_Red"
    },
    {
      "x": -5,
      "y": 23,
      "z": 2,
      "name": "Rock_Stone"
    },
    {
      "x": -5,
      "y": 24,
      "z": 2,
      "name": "Rock_Stone"
    },
    {
      "x": -5,
      "y": 25,
      "z": 2,
      "name": "Rock_Stone"
    },
    {
      "x": -5,
      "y": 26,
      "z": 2,
      "name": "Rock_Stone"
    },
    {
      "x": -5,
      "y": 27,
      "z": 2,
      "name": "Rock_Stone"
    },
    {
      "x": -5,
      "y": 28,
      "z": 2,
      "name": "Rock_Stone"
    },
    {
      "x": -5,
      "y": 29,
      "z": 2,
      "name": "Rock_Stone"
    },
    {
      "x": -5,
      "y": 30,
      "z": 2,
      "name": "Rock_Stone"
    },
    {
      "x": -5,
      "y": 31,
      "z": 2,
      "name": "Rock_Stone"
    },
    {
      "x": -5,
      "y": 32,
      "z": 2,
      "name": "Rock_Stone"
    },
    {
      "x": -5,
      "y": 33,
      "z": 2,
      "name": "Rock_Stone"
    },
    {
      "x": -5,
      "y": 34,
      "z": 2,
      "name": "Soil_Dirt"
    },
    {
      "x": -5,
      "y": 35,
      "z": 2,
      "name": "Soil_Grass"
    },
    {
      "x": -5,
      "y": 36,
      "z": 2,
      "name": "Plant_Grass_Sharp"
    },
    {
      "x": -5,
      "y": 24,
      "z": 3,
      "name": "Rock_Stone"
    },
    {
      "x": -5,
      "y": 25,
      "z": 3,
      "name": "Rock_Stone"
    },
    {
      "x": -5,
      "y": 26,
      "z": 3,
      "name": "Rock_Stone"
    },
    {
      "x": -5,
      "y": 27,
      "z": 3,
      "name": "Rock_Stone"
    },
    {
      "x": -5,
      "y": 28,
      "z": 3,
      "name": "Rock_Stone"
    },
    {
      "x": -5,
      "y": 29,
      "z": 3,
      "name": "Rock_Stone"
    },
    {
      "x": -5,
      "y": 30,
      "z": 3,
      "name": "Rock_Stone"
    },
    {
      "x": -5,
      "y": 31,
      "z": 3,
      "name": "Rock_Stone"
    },
    {
      "x": -5,
      "y": 32,
      "z": 3,
      "name": "Rock_Stone"
    },
    {
      "x": -5,
      "y": 33,
      "z": 3,
      "name": "Soil_Dirt"
    },
    {
      "x": -5,
      "y": 34,
      "z": 3,
      "name": "Soil_Dirt"
    },
    {
      "x": -5,
      "y": 35,
      "z": 3,
      "name": "Soil_Grass"
    },
    {
      "x": -5,
      "y": 36,
      "z": 3,
      "name": "Plant_Grass_Sharp"
    },
    {
      "x": -5,
      "y": 24,
      "z": 4,
      "name": "Rock_Stone"
    },
    {
      "x": -5,
      "y": 25,
      "z": 4,
      "name": "Rock_Stone"
    },
    {
      "x": -5,
      "y": 26,
      "z": 4,
      "name": "Rock_Stone"
    },
    {
      "x": -5,
      "y": 27,
      "z": 4,
      "name": "Soil_Dirt"
    },
    {
      "x": -5,
      "y": 28,
      "z": 4,
      "name": "Soil_Dirt"
    },
    {
      "x": -5,
      "y": 29,
      "z": 4,
      "name": "Rock_Stone"
    },
    {
      "x": -5,
      "y": 30,
      "z": 4,
      "name": "Rock_Stone"
    },
    {
      "x": -5,
      "y": 31,
      "z": 4,
      "name": "Rock_Stone"
    },
    {
      "x": -5,
      "y": 32,
      "z": 4,
      "name": "Rock_Stone"
    },
    {
      "x": -5,
      "y": 33,
      "z": 4,
      "name": "Soil_Dirt"
    },
    {
      "x": -5,
      "y": 34,
      "z": 4,
      "name": "Soil_Dirt"
    },
    {
      "x": -5,
      "y": 35,
      "z": 4,
      "name": "Soil_Grass"
    },
    {
      "x": -5,
      "y": 24,
      "z": 5,
      "name": "Rock_Stone"
    },
    {
      "x": -5,
      "y": 25,
      "z": 5,
      "name": "Rock_Stone"
    },
    {
      "x": -5,
      "y": 26,
      "z": 5,
      "name": "Soil_Dirt"
    },
    {
      "x": -5,
      "y": 27,
      "z": 5,
      "name": "Soil_Dirt"
    },
    {
      "x": -5,
      "y": 28,
      "z": 5,
      "name": "Soil_Dirt"
    },
    {
      "x": -5,
      "y": 29,
      "z": 5,
      "name": "Soil_Grass"
    },
    {
      "x": -5,
      "y": 30,
      "z": 5,
      "name": "Plant_Grass_Sharp"
    },
    {
      "x": -5,
      "y": 25,
      "z": 6,
      "name": "Rock_Stone"
    },
    {
      "x": -5,
      "y": 26,
      "z": 6,
      "name": "Soil_Dirt"
    },
    {
      "x": -5,
      "y": 27,
      "z": 6,
      "name": "Soil_Dirt"
    },
    {
      "x": -5,
      "y": 28,
      "z": 6,
      "name": "Soil_Dirt"
    },
    {
      "x": -5,
      "y": 29,
      "z": 6,
      "name": "Soil_Grass"
    },
    {
      "x": -5,
      "y": 30,
      "z": 6,
      "name": "Plant_Grass_Sharp"
    },
    {
      "x": -5,
      "y": 27,
      "z": 7,
      "name": "Soil_Dirt"
    },
    {
      "x": -5,
      "y": 28,
      "z": 7,
      "name": "Soil_Dirt"
    },
    {
      "x": -5,
      "y": 29,
      "z": 7,
      "name": "Soil_Grass"
    },
    {
      "x": -4,
      "y": 32,
      "z": -6,
      "name": "Soil_Dirt"
    },
    {
      "x": -4,
      "y": 33,
      "z": -6,
      "name": "Soil_Grass"
    },
    {
      "x": -4,
      "y": 26,
      "z": -5,
      "name": "Rock_Stone"
    },
    {
      "x": -4,
      "y": 27,
      "z": -5,
      "name": "Rock_Stone"
    },
    {
      "x": -4,
      "y": 28,
      "z": -5,
      "name": "Rock_Stone"
    },
    {
      "x": -4,
      "y": 29,
      "z": -5,
      "name": "Rock_Stone"
    },
    {
      "x": -4,
      "y": 30,
      "z": -5,
      "name": "Rock_Stone"
    },
    {
      "x": -4,
      "y": 31,
      "z": -5,
      "name": "Rock_Stone"
    },
    {
      "x": -4,
      "y": 32,
      "z": -5,
      "name": "Soil_Dirt"
    },
    {
      "x": -4,
      "y": 33,
      "z": -5,
      "name": "Soil_Grass"
    },
    {
      "x": -4,
      "y": 24,
      "z": -4,
      "name": "Rock_Stone"
    },
    {
      "x": -4,
      "y": 25,
      "z": -4,
      "name": "Rock_Stone"
    },
    {
      "x": -4,
      "y": 26,
      "z": -4,
      "name": "Rock_Stone"
    },
    {
      "x": -4,
      "y": 27,
      "z": -4,
      "name": "Rock_Stone"
    },
    {
      "x": -4,
      "y": 28,
      "z": -4,
      "name": "Rock_Stone"
    },
    {
      "x": -4,
      "y": 29,
      "z": -4,
      "name": "Rock_Stone"
    },
    {
      "x": -4,
      "y": 30,
      "z": -4,
      "name": "Rock_Stone"
    },
    {
      "x": -4,
      "y": 31,
      "z": -4,
      "name": "Rock_Stone"
    },
    {
      "x": -4,
      "y": 32,
      "z": -4,
      "name": "Soil_Dirt"
    },
    {
      "x": -4,
      "y": 33,
      "z": -4,
      "name": "Soil_Dirt"
    },
    {
      "x": -4,
      "y": 34,
      "z": -4,
      "name": "Soil_Grass"
    },
    {
      "x": -4,
      "y": 35,
      "z": -4,
      "name": "Plant_Grass_Sharp"
    },
    {
      "x": -4,
      "y": 23,
      "z": -3,
      "name": "Rock_Stone"
    },
    {
      "x": -4,
      "y": 24,
      "z": -3,
      "name": "Rock_Stone"
    },
    {
      "x": -4,
      "y": 25,
      "z": -3,
      "name": "Rock_Stone"
    },
    {
      "x": -4,
      "y": 26,
      "z": -3,
      "name": "Rock_Stone"
    },
    {
      "x": -4,
      "y": 27,
      "z": -3,
      "name": "Rock_Stone"
    },
    {
      "x": -4,
      "y": 28,
      "z": -3,
      "name": "Rock_Stone"
    },
    {
      "x": -4,
      "y": 29,
      "z": -3,
      "name": "Rock_Stone"
    },
    {
      "x": -4,
      "y": 30,
      "z": -3,
      "name": "Rock_Stone"
    },
    {
      "x": -4,
      "y": 31,
      "z": -3,
      "name": "Rock_Stone"
    },
    {
      "x": -4,
      "y": 32,
      "z": -3,
      "name": "Soil_Dirt"
    },
    {
      "x": -4,
      "y": 33,
      "z": -3,
      "name": "Soil_Dirt"
    },
    {
      "x": -4,
      "y": 34,
      "z": -3,
      "name": "Soil_Grass"
    },
    {
      "x": -4,
      "y": 35,
      "z": -3,
      "name": "Plant_Grass_Sharp"
    },
    {
      "x": -4,
      "y": 23,
      "z": -2,
      "name": "Rock_Stone"
    },
    {
      "x": -4,
      "y": 24,
      "z": -2,
      "name": "Rock_Stone"
    },
    {
      "x": -4,
      "y": 25,
      "z": -2,
      "name": "Rock_Stone"
    },
    {
      "x": -4,
      "y": 26,
      "z": -2,
      "name": "Rock_Stone"
    },
    {
      "x": -4,
      "y": 27,
      "z": -2,
      "name": "Rock_Stone"
    },
    {
      "x": -4,
      "y": 28,
      "z": -2,
      "name": "Rock_Stone"
    },
    {
      "x": -4,
      "y": 29,
      "z": -2,
      "name": "Rock_Stone"
    },
    {
      "x": -4,
      "y": 30,
      "z": -2,
      "name": "Rock_Stone"
    },
    {
      "x": -4,
      "y": 31,
      "z": -2,
      "name": "Rock_Stone"
    },
    {
      "x": -4,
      "y": 32,
      "z": -2,
      "name": "Soil_Dirt"
    },
    {
      "x": -4,
      "y": 33,
      "z": -2,
      "name": "Soil_Dirt"
    },
    {
      "x": -4,
      "y": 34,
      "z": -2,
      "name": "Soil_Dirt"
    },
    {
      "x": -4,
      "y": 35,
      "z": -2,
      "name": "Soil_Grass"
    },
    {
      "x": -4,
      "y": 22,
      "z": -1,
      "name": "Rock_Stone"
    },
    {
      "x": -4,
      "y": 23,
      "z": -1,
      "name": "Rock_Stone"
    },
    {
      "x": -4,
      "y": 24,
      "z": -1,
      "name": "Rock_Stone"
    },
    {
      "x": -4,
      "y": 25,
      "z": -1,
      "name": "Rock_Stone"
    },
    {
      "x": -4,
      "y": 26,
      "z": -1,
      "name": "Rock_Stone"
    },
    {
      "x": -4,
      "y": 27,
      "z": -1,
      "name": "Rock_Stone"
    },
    {
      "x": -4,
      "y": 28,
      "z": -1,
      "name": "Rock_Stone"
    },
    {
      "x": -4,
      "y": 29,
      "z": -1,
      "name": "Rock_Stone"
    },
    {
      "x": -4,
      "y": 30,
      "z": -1,
      "name": "Rock_Stone"
    },
    {
      "x": -4,
      "y": 31,
      "z": -1,
      "name": "Rock_Stone"
    },
    {
      "x": -4,
      "y": 32,
      "z": -1,
      "name": "Rock_Stone"
    },
    {
      "x": -4,
      "y": 33,
      "z": -1,
      "name": "Rock_Stone"
    },
    {
      "x": -4,
      "y": 34,
      "z": -1,
      "name": "Soil_Dirt"
    },
    {
      "x": -4,
      "y": 35,
      "z": -1,
      "name": "Soil_Grass"
    },
    {
      "x": -4,
      "y": 22,
      "z": 0,
      "name": "Rock_Stone"
    },
    {
      "x": -4,
      "y": 23,
      "z": 0,
      "name": "Rock_Stone"
    },
    {
      "x": -4,
      "y": 24,
      "z": 0,
      "name": "Rock_Stone"
    },
    {
      "x": -4,
      "y": 25,
      "z": 0,
      "name": "Rock_Stone"
    },
    {
      "x": -4,
      "y": 26,
      "z": 0,
      "name": "Rock_Stone"
    },
    {
      "x": -4,
      "y": 27,
      "z": 0,
      "name": "Rock_Stone"
    },
    {
      "x": -4,
      "y": 28,
      "z": 0,
      "name": "Rock_Stone"
    },
    {
      "x": -4,
      "y": 29,
      "z": 0,
      "name": "Rock_Stone"
    },
    {
      "x": -4,
      "y": 30,
      "z": 0,
      "name": "Rock_Stone"
    },
    {
      "x": -4,
      "y": 31,
      "z": 0,
      "name": "Rock_Stone"
    },
    {
      "x": -4,
      "y": 32,
      "z": 0,
      "name": "Rock_Stone"
    },
    {
      "x": -4,
      "y": 33,
      "z": 0,
      "name": "Rock_Stone"
    },
    {
      "x": -4,
      "y": 34,
      "z": 0,
      "name": "Rock_Stone"
    },
    {
      "x": -4,
      "y": 35,
      "z": 0,
      "name": "Soil_Grass"
    },
    {
      "x": -4,
      "y": 36,
      "z": 0,
      "name": "Plant_Bush_Arid_Red"
    },
    {
      "x": -4,
      "y": 22,
      "z": 1,
      "name": "Rock_Stone"
    },
    {
      "x": -4,
      "y": 23,
      "z": 1,
      "name": "Rock_Stone"
    },
    {
      "x": -4,
      "y": 24,
      "z": 1,
      "name": "Rock_Stone"
    },
    {
      "x": -4,
      "y": 25,
      "z": 1,
      "name": "Rock_Stone"
    },
    {
      "x": -4,
      "y": 26,
      "z": 1,
      "name": "Rock_Stone"
    },
    {
      "x": -4,
      "y": 27,
      "z": 1,
      "name": "Rock_Stone"
    },
    {
      "x": -4,
      "y": 28,
      "z": 1,
      "name": "Rock_Stone"
    },
    {
      "x": -4,
      "y": 29,
      "z": 1,
      "name": "Rock_Stone"
    },
    {
      "x": -4,
      "y": 30,
      "z": 1,
      "name": "Rock_Stone"
    },
    {
      "x": -4,
      "y": 31,
      "z": 1,
      "name": "Rock_Stone"
    },
    {
      "x": -4,
      "y": 32,
      "z": 1,
      "name": "Rock_Stone"
    },
    {
      "x": -4,
      "y": 33,
      "z": 1,
      "name": "Rock_Stone"
    },
    {
      "x": -4,
      "y": 34,
      "z": 1,
      "name": "Rock_Stone"
    },
    {
      "x": -4,
      "y": 35,
      "z": 1,
      "name": "Soil_Grass"
    },
    {
      "x": -4,
      "y": 36,
      "z": 1,
      "name": "Plant_Grass_Sharp"
    },
    {
      "x": -4,
      "y": 23,
      "z": 2,
      "name": "Rock_Stone"
    },
    {
      "x": -4,
      "y": 24,
      "z": 2,
      "name": "Rock_Stone"
    },
    {
      "x": -4,
      "y": 25,
      "z": 2,
      "name": "Rock_Stone"
    },
    {
      "x": -4,
      "y": 26,
      "z": 2,
      "name": "Rock_Stone"
    },
    {
      "x": -4,
      "y": 27,
      "z": 2,
      "name": "Rock_Stone"
    },
    {
      "x": -4,
      "y": 28,
      "z": 2,
      "name": "Rock_Stone"
    },
    {
      "x": -4,
      "y": 29,
      "z": 2,
      "name": "Rock_Stone"
    },
    {
      "x": -4,
      "y": 30,
      "z": 2,
      "name": "Rock_Stone"
    },
    {
      "x": -4,
      "y": 31,
      "z": 2,
      "name": "Rock_Stone"
    },
    {
      "x": -4,
      "y": 32,
      "z": 2,
      "name": "Rock_Stone"
    },
    {
      "x": -4,
      "y": 33,
      "z": 2,
      "name": "Rock_Stone"
    },
    {
      "x": -4,
      "y": 34,
      "z": 2,
      "name": "Soil_Dirt"
    },
    {
      "x": -4,
      "y": 35,
      "z": 2,
      "name": "Soil_Grass"
    },
    {
      "x": -4,
      "y": 36,
      "z": 2,
      "name": "Plant_Bush_Arid_Red"
    },
    {
      "x": -4,
      "y": 23,
      "z": 3,
      "name": "Rock_Stone"
    },
    {
      "x": -4,
      "y": 24,
      "z": 3,
      "name": "Rock_Stone"
    },
    {
      "x": -4,
      "y": 25,
      "z": 3,
      "name": "Rock_Stone"
    },
    {
      "x": -4,
      "y": 26,
      "z": 3,
      "name": "Rock_Stone"
    },
    {
      "x": -4,
      "y": 27,
      "z": 3,
      "name": "Rock_Stone"
    },
    {
      "x": -4,
      "y": 28,
      "z": 3,
      "name": "Rock_Stone"
    },
    {
      "x": -4,
      "y": 29,
      "z": 3,
      "name": "Rock_Stone"
    },
    {
      "x": -4,
      "y": 30,
      "z": 3,
      "name": "Rock_Stone"
    },
    {
      "x": -4,
      "y": 31,
      "z": 3,
      "name": "Rock_Stone"
    },
    {
      "x": -4,
      "y": 32,
      "z": 3,
      "name": "Rock_Stone"
    },
    {
      "x": -4,
      "y": 33,
      "z": 3,
      "name": "Soil_Dirt"
    },
    {
      "x": -4,
      "y": 34,
      "z": 3,
      "name": "Soil_Dirt"
    },
    {
      "x": -4,
      "y": 35,
      "z": 3,
      "name": "Soil_Grass"
    },
    {
      "x": -4,
      "y": 36,
      "z": 3,
      "name": "Plant_Grass_Sharp"
    },
    {
      "x": -4,
      "y": 23,
      "z": 4,
      "name": "Rock_Stone"
    },
    {
      "x": -4,
      "y": 24,
      "z": 4,
      "name": "Rock_Stone"
    },
    {
      "x": -4,
      "y": 25,
      "z": 4,
      "name": "Rock_Stone"
    },
    {
      "x": -4,
      "y": 26,
      "z": 4,
      "name": "Rock_Stone"
    },
    {
      "x": -4,
      "y": 27,
      "z": 4,
      "name": "Soil_Dirt"
    },
    {
      "x": -4,
      "y": 28,
      "z": 4,
      "name": "Rock_Stone"
    },
    {
      "x": -4,
      "y": 29,
      "z": 4,
      "name": "Rock_Stone"
    },
    {
      "x": -4,
      "y": 30,
      "z": 4,
      "name": "Rock_Stone"
    },
    {
      "x": -4,
      "y": 31,
      "z": 4,
      "name": "Rock_Stone"
    },
    {
      "x": -4,
      "y": 32,
      "z": 4,
      "name": "Rock_Stone"
    },
    {
      "x": -4,
      "y": 33,
      "z": 4,
      "name": "Soil_Dirt"
    },
    {
      "x": -4,
      "y": 34,
      "z": 4,
      "name": "Soil_Dirt"
    },
    {
      "x": -4,
      "y": 35,
      "z": 4,
      "name": "Soil_Grass"
    },
    {
      "x": -4,
      "y": 23,
      "z": 5,
      "name": "Rock_Stone"
    },
    {
      "x": -4,
      "y": 24,
      "z": 5,
      "name": "Rock_Stone"
    },
    {
      "x": -4,
      "y": 25,
      "z": 5,
      "name": "Rock_Stone"
    },
    {
      "x": -4,
      "y": 26,
      "z": 5,
      "name": "Soil_Dirt"
    },
    {
      "x": -4,
      "y": 27,
      "z": 5,
      "name": "Soil_Dirt"
    },
    {
      "x": -4,
      "y": 28,
      "z": 5,
      "name": "Soil_Dirt"
    },
    {
      "x": -4,
      "y": 29,
      "z": 5,
      "name": "Soil_Grass"
    },
    {
      "x": -4,
      "y": 23,
      "z": 6,
      "name": "Rock_Stone"
    },
    {
      "x": -4,
      "y": 24,
      "z": 6,
      "name": "Rock_Stone"
    },
    {
      "x": -4,
      "y": 25,
      "z": 6,
      "name": "Rock_Stone"
    },
    {
      "x": -4,
      "y": 26,
      "z": 6,
      "name": "Soil_Dirt"
    },
    {
      "x": -4,
      "y": 27,
      "z": 6,
      "name": "Soil_Dirt"
    },
    {
      "x": -4,
      "y": 28,
      "z": 6,
      "name": "Soil_Dirt"
    },
    {
      "x": -4,
      "y": 29,
      "z": 6,
      "name": "Soil_Grass"
    },
    {
      "x": -4,
      "y": 25,
      "z": 7,
      "name": "Rock_Stone"
    },
    {
      "x": -4,
      "y": 26,
      "z": 7,
      "name": "Soil_Dirt"
    },
    {
      "x": -4,
      "y": 27,
      "z": 7,
      "name": "Soil_Dirt"
    },
    {
      "x": -4,
      "y": 28,
      "z": 7,
      "name": "Soil_Dirt"
    },
    {
      "x": -4,
      "y": 29,
      "z": 7,
      "name": "Soil_Grass"
    },
    {
      "x": -4,
      "y": 29,
      "z": 8,
      "name": "Soil_Grass"
    },
    {
      "x": -3,
      "y": 30,
      "z": -7,
      "name": "Rock_Stone"
    },
    {
      "x": -3,
      "y": 31,
      "z": -7,
      "name": "Rock_Stone"
    },
    {
      "x": -3,
      "y": 32,
      "z": -7,
      "name": "Soil_Dirt"
    },
    {
      "x": -3,
      "y": 33,
      "z": -7,
      "name": "Soil_Grass"
    },
    {
      "x": -3,
      "y": 28,
      "z": -6,
      "name": "Rock_Stone"
    },
    {
      "x": -3,
      "y": 29,
      "z": -6,
      "name": "Rock_Stone"
    },
    {
      "x": -3,
      "y": 30,
      "z": -6,
      "name": "Rock_Stone"
    },
    {
      "x": -3,
      "y": 31,
      "z": -6,
      "name": "Rock_Stone"
    },
    {
      "x": -3,
      "y": 32,
      "z": -6,
      "name": "Soil_Dirt"
    },
    {
      "x": -3,
      "y": 33,
      "z": -6,
      "name": "Soil_Grass"
    },
    {
      "x": -3,
      "y": 25,
      "z": -5,
      "name": "Rock_Stone"
    },
    {
      "x": -3,
      "y": 26,
      "z": -5,
      "name": "Rock_Stone"
    },
    {
      "x": -3,
      "y": 27,
      "z": -5,
      "name": "Rock_Stone"
    },
    {
      "x": -3,
      "y": 28,
      "z": -5,
      "name": "Rock_Stone"
    },
    {
      "x": -3,
      "y": 29,
      "z": -5,
      "name": "Rock_Stone"
    },
    {
      "x": -3,
      "y": 30,
      "z": -5,
      "name": "Rock_Stone"
    },
    {
      "x": -3,
      "y": 31,
      "z": -5,
      "name": "Rock_Stone"
    },
    {
      "x": -3,
      "y": 32,
      "z": -5,
      "name": "Soil_Dirt"
    },
    {
      "x": -3,
      "y": 33,
      "z": -5,
      "name": "Soil_Grass"
    },
    {
      "x": -3,
      "y": 24,
      "z": -4,
      "name": "Rock_Stone"
    },
    {
      "x": -3,
      "y": 25,
      "z": -4,
      "name": "Rock_Stone"
    },
    {
      "x": -3,
      "y": 26,
      "z": -4,
      "name": "Rock_Stone"
    },
    {
      "x": -3,
      "y": 27,
      "z": -4,
      "name": "Rock_Stone"
    },
    {
      "x": -3,
      "y": 28,
      "z": -4,
      "name": "Rock_Stone"
    },
    {
      "x": -3,
      "y": 29,
      "z": -4,
      "name": "Rock_Stone"
    },
    {
      "x": -3,
      "y": 30,
      "z": -4,
      "name": "Rock_Stone"
    },
    {
      "x": -3,
      "y": 31,
      "z": -4,
      "name": "Rock_Stone"
    },
    {
      "x": -3,
      "y": 32,
      "z": -4,
      "name": "Rock_Stone"
    },
    {
      "x": -3,
      "y": 33,
      "z": -4,
      "name": "Soil_Dirt"
    },
    {
      "x": -3,
      "y": 34,
      "z": -4,
      "name": "Soil_Grass"
    },
    {
      "x": -3,
      "y": 35,
      "z": -4,
      "name": "Plant_Grass_Sharp"
    },
    {
      "x": -3,
      "y": 23,
      "z": -3,
      "name": "Rock_Stone"
    },
    {
      "x": -3,
      "y": 24,
      "z": -3,
      "name": "Rock_Stone"
    },
    {
      "x": -3,
      "y": 25,
      "z": -3,
      "name": "Rock_Stone"
    },
    {
      "x": -3,
      "y": 26,
      "z": -3,
      "name": "Rock_Stone"
    },
    {
      "x": -3,
      "y": 27,
      "z": -3,
      "name": "Rock_Stone"
    },
    {
      "x": -3,
      "y": 28,
      "z": -3,
      "name": "Rock_Stone"
    },
    {
      "x": -3,
      "y": 29,
      "z": -3,
      "name": "Rock_Stone"
    },
    {
      "x": -3,
      "y": 30,
      "z": -3,
      "name": "Rock_Stone"
    },
    {
      "x": -3,
      "y": 31,
      "z": -3,
      "name": "Rock_Stone"
    },
    {
      "x": -3,
      "y": 32,
      "z": -3,
      "name": "Rock_Stone"
    },
    {
      "x": -3,
      "y": 33,
      "z": -3,
      "name": "Soil_Dirt"
    },
    {
      "x": -3,
      "y": 34,
      "z": -3,
      "name": "Soil_Grass"
    },
    {
      "x": -3,
      "y": 35,
      "z": -3,
      "name": "Plant_Grass_Sharp_Tall"
    },
    {
      "x": -3,
      "y": 36,
      "z": -3,
      "name": "Plant_Grass_Sharp_Tall",
      "filler": 1024
    },
    {
      "x": -3,
      "y": 22,
      "z": -2,
      "name": "Rock_Stone"
    },
    {
      "x": -3,
      "y": 23,
      "z": -2,
      "name": "Rock_Stone"
    },
    {
      "x": -3,
      "y": 24,
      "z": -2,
      "name": "Rock_Stone"
    },
    {
      "x": -3,
      "y": 25,
      "z": -2,
      "name": "Rock_Stone"
    },
    {
      "x": -3,
      "y": 26,
      "z": -2,
      "name": "Rock_Stone"
    },
    {
      "x": -3,
      "y": 27,
      "z": -2,
      "name": "Rock_Stone"
    },
    {
      "x": -3,
      "y": 28,
      "z": -2,
      "name": "Rock_Stone"
    },
    {
      "x": -3,
      "y": 29,
      "z": -2,
      "name": "Rock_Stone"
    },
    {
      "x": -3,
      "y": 30,
      "z": -2,
      "name": "Rock_Stone"
    },
    {
      "x": -3,
      "y": 31,
      "z": -2,
      "name": "Rock_Stone"
    },
    {
      "x": -3,
      "y": 32,
      "z": -2,
      "name": "Rock_Stone"
    },
    {
      "x": -3,
      "y": 33,
      "z": -2,
      "name": "Soil_Dirt"
    },
    {
      "x": -3,
      "y": 34,
      "z": -2,
      "name": "Soil_Dirt"
    },
    {
      "x": -3,
      "y": 35,
      "z": -2,
      "name": "Soil_Grass"
    },
    {
      "x": -3,
      "y": 22,
      "z": -1,
      "name": "Rock_Stone"
    },
    {
      "x": -3,
      "y": 23,
      "z": -1,
      "name": "Rock_Stone"
    },
    {
      "x": -3,
      "y": 24,
      "z": -1,
      "name": "Rock_Stone"
    },
    {
      "x": -3,
      "y": 25,
      "z": -1,
      "name": "Rock_Stone"
    },
    {
      "x": -3,
      "y": 26,
      "z": -1,
      "name": "Rock_Stone"
    },
    {
      "x": -3,
      "y": 27,
      "z": -1,
      "name": "Rock_Stone"
    },
    {
      "x": -3,
      "y": 28,
      "z": -1,
      "name": "Rock_Stone"
    },
    {
      "x": -3,
      "y": 29,
      "z": -1,
      "name": "Rock_Stone"
    },
    {
      "x": -3,
      "y": 30,
      "z": -1,
      "name": "Rock_Stone"
    },
    {
      "x": -3,
      "y": 31,
      "z": -1,
      "name": "Rock_Stone"
    },
    {
      "x": -3,
      "y": 32,
      "z": -1,
      "name": "Rock_Stone"
    },
    {
      "x": -3,
      "y": 33,
      "z": -1,
      "name": "Rock_Stone"
    },
    {
      "x": -3,
      "y": 34,
      "z": -1,
      "name": "Soil_Dirt"
    },
    {
      "x": -3,
      "y": 35,
      "z": -1,
      "name": "Soil_Grass"
    },
    {
      "x": -3,
      "y": 22,
      "z": 0,
      "name": "Rock_Stone"
    },
    {
      "x": -3,
      "y": 23,
      "z": 0,
      "name": "Rock_Stone"
    },
    {
      "x": -3,
      "y": 24,
      "z": 0,
      "name": "Rock_Stone"
    },
    {
      "x": -3,
      "y": 25,
      "z": 0,
      "name": "Rock_Stone"
    },
    {
      "x": -3,
      "y": 26,
      "z": 0,
      "name": "Rock_Stone"
    },
    {
      "x": -3,
      "y": 27,
      "z": 0,
      "name": "Rock_Stone"
    },
    {
      "x": -3,
      "y": 28,
      "z": 0,
      "name": "Rock_Stone"
    },
    {
      "x": -3,
      "y": 29,
      "z": 0,
      "name": "Rock_Stone"
    },
    {
      "x": -3,
      "y": 30,
      "z": 0,
      "name": "Rock_Stone"
    },
    {
      "x": -3,
      "y": 31,
      "z": 0,
      "name": "Rock_Stone"
    },
    {
      "x": -3,
      "y": 32,
      "z": 0,
      "name": "Rock_Stone"
    },
    {
      "x": -3,
      "y": 33,
      "z": 0,
      "name": "Rock_Stone"
    },
    {
      "x": -3,
      "y": 34,
      "z": 0,
      "name": "Soil_Dirt"
    },
    {
      "x": -3,
      "y": 35,
      "z": 0,
      "name": "Soil_Grass"
    },
    {
      "x": -3,
      "y": 36,
      "z": 0,
      "name": "Plant_Grass_Sharp"
    },
    {
      "x": -3,
      "y": 22,
      "z": 1,
      "name": "Rock_Stone"
    },
    {
      "x": -3,
      "y": 23,
      "z": 1,
      "name": "Rock_Stone"
    },
    {
      "x": -3,
      "y": 24,
      "z": 1,
      "name": "Rock_Stone"
    },
    {
      "x": -3,
      "y": 25,
      "z": 1,
      "name": "Rock_Stone"
    },
    {
      "x": -3,
      "y": 26,
      "z": 1,
      "name": "Rock_Stone"
    },
    {
      "x": -3,
      "y": 27,
      "z": 1,
      "name": "Rock_Stone"
    },
    {
      "x": -3,
      "y": 28,
      "z": 1,
      "name": "Rock_Stone"
    },
    {
      "x": -3,
      "y": 29,
      "z": 1,
      "name": "Rock_Stone"
    },
    {
      "x": -3,
      "y": 30,
      "z": 1,
      "name": "Rock_Stone"
    },
    {
      "x": -3,
      "y": 31,
      "z": 1,
      "name": "Rock_Stone"
    },
    {
      "x": -3,
      "y": 32,
      "z": 1,
      "name": "Rock_Stone"
    },
    {
      "x": -3,
      "y": 33,
      "z": 1,
      "name": "Rock_Stone"
    },
    {
      "x": -3,
      "y": 34,
      "z": 1,
      "name": "Soil_Dirt"
    },
    {
      "x": -3,
      "y": 35,
      "z": 1,
      "name": "Soil_Grass"
    },
    {
      "x": -3,
      "y": 36,
      "z": 1,
      "name": "Plant_Grass_Sharp"
    },
    {
      "x": -3,
      "y": 22,
      "z": 2,
      "name": "Rock_Stone"
    },
    {
      "x": -3,
      "y": 23,
      "z": 2,
      "name": "Rock_Stone"
    },
    {
      "x": -3,
      "y": 24,
      "z": 2,
      "name": "Rock_Stone"
    },
    {
      "x": -3,
      "y": 25,
      "z": 2,
      "name": "Rock_Stone"
    },
    {
      "x": -3,
      "y": 26,
      "z": 2,
      "name": "Rock_Stone"
    },
    {
      "x": -3,
      "y": 27,
      "z": 2,
      "name": "Rock_Stone"
    },
    {
      "x": -3,
      "y": 28,
      "z": 2,
      "name": "Rock_Stone"
    },
    {
      "x": -3,
      "y": 29,
      "z": 2,
      "name": "Rock_Stone"
    },
    {
      "x": -3,
      "y": 30,
      "z": 2,
      "name": "Rock_Stone"
    },
    {
      "x": -3,
      "y": 31,
      "z": 2,
      "name": "Rock_Stone"
    },
    {
      "x": -3,
      "y": 32,
      "z": 2,
      "name": "Rock_Stone"
    },
    {
      "x": -3,
      "y": 33,
      "z": 2,
      "name": "Rock_Stone"
    },
    {
      "x": -3,
      "y": 34,
      "z": 2,
      "name": "Soil_Dirt"
    },
    {
      "x": -3,
      "y": 35,
      "z": 2,
      "name": "Soil_Grass"
    },
    {
      "x": -3,
      "y": 23,
      "z": 3,
      "name": "Rock_Stone"
    },
    {
      "x": -3,
      "y": 24,
      "z": 3,
      "name": "Rock_Stone"
    },
    {
      "x": -3,
      "y": 25,
      "z": 3,
      "name": "Rock_Stone"
    },
    {
      "x": -3,
      "y": 26,
      "z": 3,
      "name": "Rock_Stone"
    },
    {
      "x": -3,
      "y": 27,
      "z": 3,
      "name": "Rock_Stone"
    },
    {
      "x": -3,
      "y": 28,
      "z": 3,
      "name": "Rock_Stone"
    },
    {
      "x": -3,
      "y": 29,
      "z": 3,
      "name": "Rock_Stone"
    },
    {
      "x": -3,
      "y": 30,
      "z": 3,
      "name": "Rock_Stone"
    },
    {
      "x": -3,
      "y": 31,
      "z": 3,
      "name": "Rock_Stone"
    },
    {
      "x": -3,
      "y": 32,
      "z": 3,
      "name": "Rock_Stone"
    },
    {
      "x": -3,
      "y": 33,
      "z": 3,
      "name": "Rock_Stone"
    },
    {
      "x": -3,
      "y": 34,
      "z": 3,
      "name": "Soil_Dirt"
    },
    {
      "x": -3,
      "y": 35,
      "z": 3,
      "name": "Soil_Grass"
    },
    {
      "x": -3,
      "y": 23,
      "z": 4,
      "name": "Rock_Stone"
    },
    {
      "x": -3,
      "y": 24,
      "z": 4,
      "name": "Rock_Stone"
    },
    {
      "x": -3,
      "y": 25,
      "z": 4,
      "name": "Rock_Stone"
    },
    {
      "x": -3,
      "y": 26,
      "z": 4,
      "name": "Rock_Stone"
    },
    {
      "x": -3,
      "y": 27,
      "z": 4,
      "name": "Rock_Stone"
    },
    {
      "x": -3,
      "y": 28,
      "z": 4,
      "name": "Rock_Stone"
    },
    {
      "x": -3,
      "y": 29,
      "z": 4,
      "name": "Rock_Stone"
    },
    {
      "x": -3,
      "y": 30,
      "z": 4,
      "name": "Soil_Grass"
    },
    {
      "x": -3,
      "y": 34,
      "z": 4,
      "name": "Soil_Dirt"
    },
    {
      "x": -3,
      "y": 35,
      "z": 4,
      "name": "Soil_Grass"
    },
    {
      "x": -3,
      "y": 23,
      "z": 5,
      "name": "Rock_Stone"
    },
    {
      "x": -3,
      "y": 24,
      "z": 5,
      "name": "Rock_Stone"
    },
    {
      "x": -3,
      "y": 25,
      "z": 5,
      "name": "Rock_Stone"
    },
    {
      "x": -3,
      "y": 26,
      "z": 5,
      "name": "Rock_Stone"
    },
    {
      "x": -3,
      "y": 27,
      "z": 5,
      "name": "Soil_Dirt"
    },
    {
      "x": -3,
      "y": 28,
      "z": 5,
      "name": "Rock_Stone"
    },
    {
      "x": -3,
      "y": 29,
      "z": 5,
      "name": "Rock_Stone"
    },
    {
      "x": -3,
      "y": 30,
      "z": 5,
      "name": "Soil_Grass"
    },
    {
      "x": -3,
      "y": 23,
      "z": 6,
      "name": "Rock_Stone"
    },
    {
      "x": -3,
      "y": 24,
      "z": 6,
      "name": "Rock_Stone"
    },
    {
      "x": -3,
      "y": 25,
      "z": 6,
      "name": "Rock_Stone"
    },
    {
      "x": -3,
      "y": 26,
      "z": 6,
      "name": "Soil_Dirt"
    },
    {
      "x": -3,
      "y": 27,
      "z": 6,
      "name": "Soil_Dirt"
    },
    {
      "x": -3,
      "y": 28,
      "z": 6,
      "name": "Soil_Dirt"
    },
    {
      "x": -3,
      "y": 29,
      "z": 6,
      "name": "Soil_Dirt"
    },
    {
      "x": -3,
      "y": 30,
      "z": 6,
      "name": "Soil_Grass"
    },
    {
      "x": -3,
      "y": 31,
      "z": 6,
      "name": "Plant_Bush_Arid_Red"
    },
    {
      "x": -3,
      "y": 24,
      "z": 7,
      "name": "Rock_Stone"
    },
    {
      "x": -3,
      "y": 25,
      "z": 7,
      "name": "Rock_Stone"
    },
    {
      "x": -3,
      "y": 26,
      "z": 7,
      "name": "Soil_Dirt"
    },
    {
      "x": -3,
      "y": 27,
      "z": 7,
      "name": "Soil_Dirt"
    },
    {
      "x": -3,
      "y": 28,
      "z": 7,
      "name": "Soil_Dirt"
    },
    {
      "x": -3,
      "y": 29,
      "z": 7,
      "name": "Soil_Grass"
    },
    {
      "x": -3,
      "y": 30,
      "z": 7,
      "name": "Plant_Bush_Arid_Red"
    },
    {
      "x": -3,
      "y": 26,
      "z": 8,
      "name": "Soil_Dirt"
    },
    {
      "x": -3,
      "y": 27,
      "z": 8,
      "name": "Soil_Dirt"
    },
    {
      "x": -3,
      "y": 28,
      "z": 8,
      "name": "Soil_Dirt"
    },
    {
      "x": -3,
      "y": 29,
      "z": 8,
      "name": "Soil_Grass"
    },
    {
      "x": -2,
      "y": 29,
      "z": -7,
      "name": "Rock_Stone"
    },
    {
      "x": -2,
      "y": 30,
      "z": -7,
      "name": "Rock_Stone"
    },
    {
      "x": -2,
      "y": 31,
      "z": -7,
      "name": "Rock_Stone"
    },
    {
      "x": -2,
      "y": 32,
      "z": -7,
      "name": "Soil_Dirt"
    },
    {
      "x": -2,
      "y": 33,
      "z": -7,
      "name": "Soil_Grass"
    },
    {
      "x": -2,
      "y": 26,
      "z": -6,
      "name": "Rock_Stone"
    },
    {
      "x": -2,
      "y": 27,
      "z": -6,
      "name": "Rock_Stone"
    },
    {
      "x": -2,
      "y": 28,
      "z": -6,
      "name": "Rock_Stone"
    },
    {
      "x": -2,
      "y": 29,
      "z": -6,
      "name": "Rock_Stone"
    },
    {
      "x": -2,
      "y": 30,
      "z": -6,
      "name": "Rock_Stone"
    },
    {
      "x": -2,
      "y": 31,
      "z": -6,
      "name": "Rock_Stone"
    },
    {
      "x": -2,
      "y": 32,
      "z": -6,
      "name": "Soil_Dirt"
    },
    {
      "x": -2,
      "y": 33,
      "z": -6,
      "name": "Soil_Grass"
    },
    {
      "x": -2,
      "y": 25,
      "z": -5,
      "name": "Rock_Stone"
    },
    {
      "x": -2,
      "y": 26,
      "z": -5,
      "name": "Rock_Stone"
    },
    {
      "x": -2,
      "y": 27,
      "z": -5,
      "name": "Rock_Stone"
    },
    {
      "x": -2,
      "y": 28,
      "z": -5,
      "name": "Rock_Stone"
    },
    {
      "x": -2,
      "y": 29,
      "z": -5,
      "name": "Rock_Stone"
    },
    {
      "x": -2,
      "y": 30,
      "z": -5,
      "name": "Rock_Stone"
    },
    {
      "x": -2,
      "y": 31,
      "z": -5,
      "name": "Rock_Stone"
    },
    {
      "x": -2,
      "y": 32,
      "z": -5,
      "name": "Soil_Dirt"
    },
    {
      "x": -2,
      "y": 33,
      "z": -5,
      "name": "Soil_Grass"
    },
    {
      "x": -2,
      "y": 23,
      "z": -4,
      "name": "Rock_Stone"
    },
    {
      "x": -2,
      "y": 24,
      "z": -4,
      "name": "Rock_Stone"
    },
    {
      "x": -2,
      "y": 25,
      "z": -4,
      "name": "Rock_Stone"
    },
    {
      "x": -2,
      "y": 26,
      "z": -4,
      "name": "Rock_Stone"
    },
    {
      "x": -2,
      "y": 27,
      "z": -4,
      "name": "Rock_Stone"
    },
    {
      "x": -2,
      "y": 28,
      "z": -4,
      "name": "Rock_Stone"
    },
    {
      "x": -2,
      "y": 29,
      "z": -4,
      "name": "Rock_Stone"
    },
    {
      "x": -2,
      "y": 30,
      "z": -4,
      "name": "Rock_Stone"
    },
    {
      "x": -2,
      "y": 31,
      "z": -4,
      "name": "Rock_Stone"
    },
    {
      "x": -2,
      "y": 32,
      "z": -4,
      "name": "Rock_Stone"
    },
    {
      "x": -2,
      "y": 33,
      "z": -4,
      "name": "Soil_Dirt"
    },
    {
      "x": -2,
      "y": 34,
      "z": -4,
      "name": "Soil_Grass"
    },
    {
      "x": -2,
      "y": 23,
      "z": -3,
      "name": "Rock_Stone"
    },
    {
      "x": -2,
      "y": 24,
      "z": -3,
      "name": "Rock_Stone"
    },
    {
      "x": -2,
      "y": 25,
      "z": -3,
      "name": "Rock_Stone"
    },
    {
      "x": -2,
      "y": 26,
      "z": -3,
      "name": "Rock_Stone"
    },
    {
      "x": -2,
      "y": 27,
      "z": -3,
      "name": "Rock_Stone"
    },
    {
      "x": -2,
      "y": 28,
      "z": -3,
      "name": "Rock_Stone"
    },
    {
      "x": -2,
      "y": 29,
      "z": -3,
      "name": "Rock_Stone"
    },
    {
      "x": -2,
      "y": 30,
      "z": -3,
      "name": "Rock_Stone"
    },
    {
      "x": -2,
      "y": 31,
      "z": -3,
      "name": "Rock_Stone"
    },
    {
      "x": -2,
      "y": 32,
      "z": -3,
      "name": "Rock_Stone"
    },
    {
      "x": -2,
      "y": 33,
      "z": -3,
      "name": "Soil_Dirt"
    },
    {
      "x": -2,
      "y": 34,
      "z": -3,
      "name": "Soil_Grass"
    },
    {
      "x": -2,
      "y": 35,
      "z": -3,
      "name": "Plant_Grass_Sharp_Tall"
    },
    {
      "x": -2,
      "y": 36,
      "z": -3,
      "name": "Plant_Grass_Sharp_Tall",
      "filler": 1024
    },
    {
      "x": -2,
      "y": 22,
      "z": -2,
      "name": "Rock_Stone"
    },
    {
      "x": -2,
      "y": 23,
      "z": -2,
      "name": "Rock_Stone"
    },
    {
      "x": -2,
      "y": 24,
      "z": -2,
      "name": "Rock_Stone"
    },
    {
      "x": -2,
      "y": 25,
      "z": -2,
      "name": "Rock_Stone"
    },
    {
      "x": -2,
      "y": 26,
      "z": -2,
      "name": "Rock_Stone"
    },
    {
      "x": -2,
      "y": 27,
      "z": -2,
      "name": "Rock_Stone"
    },
    {
      "x": -2,
      "y": 28,
      "z": -2,
      "name": "Rock_Stone"
    },
    {
      "x": -2,
      "y": 29,
      "z": -2,
      "name": "Rock_Stone"
    },
    {
      "x": -2,
      "y": 30,
      "z": -2,
      "name": "Rock_Stone"
    },
    {
      "x": -2,
      "y": 31,
      "z": -2,
      "name": "Rock_Stone"
    },
    {
      "x": -2,
      "y": 32,
      "z": -2,
      "name": "Rock_Stone"
    },
    {
      "x": -2,
      "y": 33,
      "z": -2,
      "name": "Soil_Dirt"
    },
    {
      "x": -2,
      "y": 34,
      "z": -2,
      "name": "Soil_Grass"
    },
    {
      "x": -2,
      "y": 35,
      "z": -2,
      "name": "Plant_Grass_Sharp_Tall"
    },
    {
      "x": -2,
      "y": 36,
      "z": -2,
      "name": "Plant_Grass_Sharp_Tall",
      "filler": 1024
    },
    {
      "x": -2,
      "y": 22,
      "z": -1,
      "name": "Rock_Stone"
    },
    {
      "x": -2,
      "y": 23,
      "z": -1,
      "name": "Rock_Stone"
    },
    {
      "x": -2,
      "y": 24,
      "z": -1,
      "name": "Rock_Stone"
    },
    {
      "x": -2,
      "y": 25,
      "z": -1,
      "name": "Rock_Stone"
    },
    {
      "x": -2,
      "y": 26,
      "z": -1,
      "name": "Rock_Stone"
    },
    {
      "x": -2,
      "y": 27,
      "z": -1,
      "name": "Rock_Stone"
    },
    {
      "x": -2,
      "y": 28,
      "z": -1,
      "name": "Rock_Stone"
    },
    {
      "x": -2,
      "y": 29,
      "z": -1,
      "name": "Rock_Stone"
    },
    {
      "x": -2,
      "y": 30,
      "z": -1,
      "name": "Rock_Stone"
    },
    {
      "x": -2,
      "y": 31,
      "z": -1,
      "name": "Rock_Stone"
    },
    {
      "x": -2,
      "y": 32,
      "z": -1,
      "name": "Rock_Stone"
    },
    {
      "x": -2,
      "y": 33,
      "z": -1,
      "name": "Soil_Dirt"
    },
    {
      "x": -2,
      "y": 34,
      "z": -1,
      "name": "Soil_Dirt"
    },
    {
      "x": -2,
      "y": 35,
      "z": -1,
      "name": "Soil_Grass"
    },
    {
      "x": -2,
      "y": 22,
      "z": 0,
      "name": "Rock_Stone"
    },
    {
      "x": -2,
      "y": 23,
      "z": 0,
      "name": "Rock_Stone"
    },
    {
      "x": -2,
      "y": 24,
      "z": 0,
      "name": "Rock_Stone"
    },
    {
      "x": -2,
      "y": 25,
      "z": 0,
      "name": "Rock_Stone"
    },
    {
      "x": -2,
      "y": 26,
      "z": 0,
      "name": "Rock_Stone"
    },
    {
      "x": -2,
      "y": 27,
      "z": 0,
      "name": "Rock_Stone"
    },
    {
      "x": -2,
      "y": 28,
      "z": 0,
      "name": "Rock_Stone"
    },
    {
      "x": -2,
      "y": 29,
      "z": 0,
      "name": "Rock_Stone"
    },
    {
      "x": -2,
      "y": 30,
      "z": 0,
      "name": "Rock_Stone"
    },
    {
      "x": -2,
      "y": 31,
      "z": 0,
      "name": "Soil_Dirt"
    },
    {
      "x": -2,
      "y": 32,
      "z": 0,
      "name": "Rock_Stone"
    },
    {
      "x": -2,
      "y": 33,
      "z": 0,
      "name": "Rock_Stone"
    },
    {
      "x": -2,
      "y": 34,
      "z": 0,
      "name": "Soil_Dirt"
    },
    {
      "x": -2,
      "y": 35,
      "z": 0,
      "name": "Soil_Grass"
    },
    {
      "x": -2,
      "y": 22,
      "z": 1,
      "name": "Rock_Stone"
    },
    {
      "x": -2,
      "y": 23,
      "z": 1,
      "name": "Rock_Stone"
    },
    {
      "x": -2,
      "y": 24,
      "z": 1,
      "name": "Rock_Stone"
    },
    {
      "x": -2,
      "y": 25,
      "z": 1,
      "name": "Rock_Stone"
    },
    {
      "x": -2,
      "y": 26,
      "z": 1,
      "name": "Rock_Stone"
    },
    {
      "x": -2,
      "y": 27,
      "z": 1,
      "name": "Rock_Stone"
    },
    {
      "x": -2,
      "y": 28,
      "z": 1,
      "name": "Rock_Stone"
    },
    {
      "x": -2,
      "y": 29,
      "z": 1,
      "name": "Rock_Stone"
    },
    {
      "x": -2,
      "y": 30,
      "z": 1,
      "name": "Rock_Stone"
    },
    {
      "x": -2,
      "y": 31,
      "z": 1,
      "name": "Rock_Stone"
    },
    {
      "x": -2,
      "y": 32,
      "z": 1,
      "name": "Rock_Stone"
    },
    {
      "x": -2,
      "y": 33,
      "z": 1,
      "name": "Rock_Stone"
    },
    {
      "x": -2,
      "y": 34,
      "z": 1,
      "name": "Soil_Dirt"
    },
    {
      "x": -2,
      "y": 35,
      "z": 1,
      "name": "Soil_Grass"
    },
    {
      "x": -2,
      "y": 22,
      "z": 2,
      "name": "Rock_Stone"
    },
    {
      "x": -2,
      "y": 23,
      "z": 2,
      "name": "Rock_Stone"
    },
    {
      "x": -2,
      "y": 24,
      "z": 2,
      "name": "Rock_Stone"
    },
    {
      "x": -2,
      "y": 25,
      "z": 2,
      "name": "Rock_Stone"
    },
    {
      "x": -2,
      "y": 26,
      "z": 2,
      "name": "Rock_Stone"
    },
    {
      "x": -2,
      "y": 27,
      "z": 2,
      "name": "Rock_Stone"
    },
    {
      "x": -2,
      "y": 28,
      "z": 2,
      "name": "Rock_Stone"
    },
    {
      "x": -2,
      "y": 29,
      "z": 2,
      "name": "Rock_Stone"
    },
    {
      "x": -2,
      "y": 30,
      "z": 2,
      "name": "Rock_Stone"
    },
    {
      "x": -2,
      "y": 31,
      "z": 2,
      "name": "Rock_Stone"
    },
    {
      "x": -2,
      "y": 32,
      "z": 2,
      "name": "Rock_Stone"
    },
    {
      "x": -2,
      "y": 33,
      "z": 2,
      "name": "Rock_Stone"
    },
    {
      "x": -2,
      "y": 34,
      "z": 2,
      "name": "Soil_Dirt"
    },
    {
      "x": -2,
      "y": 35,
      "z": 2,
      "name": "Soil_Grass"
    },
    {
      "x": -2,
      "y": 36,
      "z": 2,
      "name": "Plant_Grass_Sharp"
    },
    {
      "x": -2,
      "y": 23,
      "z": 3,
      "name": "Rock_Stone"
    },
    {
      "x": -2,
      "y": 24,
      "z": 3,
      "name": "Rock_Stone"
    },
    {
      "x": -2,
      "y": 25,
      "z": 3,
      "name": "Rock_Stone"
    },
    {
      "x": -2,
      "y": 26,
      "z": 3,
      "name": "Rock_Stone"
    },
    {
      "x": -2,
      "y": 27,
      "z": 3,
      "name": "Rock_Stone"
    },
    {
      "x": -2,
      "y": 28,
      "z": 3,
      "name": "Rock_Stone"
    },
    {
      "x": -2,
      "y": 29,
      "z": 3,
      "name": "Rock_Stone"
    },
    {
      "x": -2,
      "y": 30,
      "z": 3,
      "name": "Rock_Stone"
    },
    {
      "x": -2,
      "y": 31,
      "z": 3,
      "name": "Rock_Stone"
    },
    {
      "x": -2,
      "y": 32,
      "z": 3,
      "name": "Rock_Stone"
    },
    {
      "x": -2,
      "y": 33,
      "z": 3,
      "name": "Rock_Stone"
    },
    {
      "x": -2,
      "y": 34,
      "z": 3,
      "name": "Rock_Stone"
    },
    {
      "x": -2,
      "y": 23,
      "z": 4,
      "name": "Rock_Stone"
    },
    {
      "x": -2,
      "y": 24,
      "z": 4,
      "name": "Rock_Stone"
    },
    {
      "x": -2,
      "y": 25,
      "z": 4,
      "name": "Rock_Stone"
    },
    {
      "x": -2,
      "y": 26,
      "z": 4,
      "name": "Rock_Stone"
    },
    {
      "x": -2,
      "y": 27,
      "z": 4,
      "name": "Rock_Stone"
    },
    {
      "x": -2,
      "y": 28,
      "z": 4,
      "name": "Rock_Stone"
    },
    {
      "x": -2,
      "y": 29,
      "z": 4,
      "name": "Rock_Stone"
    },
    {
      "x": -2,
      "y": 30,
      "z": 4,
      "name": "Soil_Grass"
    },
    {
      "x": -2,
      "y": 23,
      "z": 5,
      "name": "Rock_Stone"
    },
    {
      "x": -2,
      "y": 24,
      "z": 5,
      "name": "Rock_Stone"
    },
    {
      "x": -2,
      "y": 25,
      "z": 5,
      "name": "Rock_Stone"
    },
    {
      "x": -2,
      "y": 26,
      "z": 5,
      "name": "Rock_Stone"
    },
    {
      "x": -2,
      "y": 27,
      "z": 5,
      "name": "Rock_Stone"
    },
    {
      "x": -2,
      "y": 28,
      "z": 5,
      "name": "Rock_Stone"
    },
    {
      "x": -2,
      "y": 29,
      "z": 5,
      "name": "Rock_Stone"
    },
    {
      "x": -2,
      "y": 30,
      "z": 5,
      "name": "Soil_Grass"
    },
    {
      "x": -2,
      "y": 23,
      "z": 6,
      "name": "Rock_Stone"
    },
    {
      "x": -2,
      "y": 24,
      "z": 6,
      "name": "Rock_Stone"
    },
    {
      "x": -2,
      "y": 25,
      "z": 6,
      "name": "Rock_Stone"
    },
    {
      "x": -2,
      "y": 26,
      "z": 6,
      "name": "Rock_Stone"
    },
    {
      "x": -2,
      "y": 27,
      "z": 6,
      "name": "Soil_Dirt"
    },
    {
      "x": -2,
      "y": 28,
      "z": 6,
      "name": "Rock_Stone"
    },
    {
      "x": -2,
      "y": 29,
      "z": 6,
      "name": "Soil_Dirt"
    },
    {
      "x": -2,
      "y": 30,
      "z": 6,
      "name": "Soil_Grass"
    },
    {
      "x": -2,
      "y": 31,
      "z": 6,
      "name": "Plant_Bush_Arid_Red"
    },
    {
      "x": -2,
      "y": 24,
      "z": 7,
      "name": "Rock_Stone"
    },
    {
      "x": -2,
      "y": 25,
      "z": 7,
      "name": "Rock_Stone"
    },
    {
      "x": -2,
      "y": 26,
      "z": 7,
      "name": "Rock_Stone"
    },
    {
      "x": -2,
      "y": 27,
      "z": 7,
      "name": "Soil_Dirt"
    },
    {
      "x": -2,
      "y": 28,
      "z": 7,
      "name": "Soil_Dirt"
    },
    {
      "x": -2,
      "y": 29,
      "z": 7,
      "name": "Soil_Grass"
    },
    {
      "x": -2,
      "y": 25,
      "z": 8,
      "name": "Rock_Stone"
    },
    {
      "x": -2,
      "y": 26,
      "z": 8,
      "name": "Rock_Stone"
    },
    {
      "x": -2,
      "y": 27,
      "z": 8,
      "name": "Soil_Dirt"
    },
    {
      "x": -2,
      "y": 28,
      "z": 8,
      "name": "Soil_Dirt"
    },
    {
      "x": -2,
      "y": 29,
      "z": 8,
      "name": "Soil_Grass"
    },
    {
      "x": -1,
      "y": 31,
      "z": -7,
      "name": "Soil_Dirt"
    },
    {
      "x": -1,
      "y": 32,
      "z": -7,
      "name": "Soil_Dirt"
    },
    {
      "x": -1,
      "y": 33,
      "z": -7,
      "name": "Soil_Grass"
    },
    {
      "x": -1,
      "y": 26,
      "z": -6,
      "name": "Rock_Stone"
    },
    {
      "x": -1,
      "y": 27,
      "z": -6,
      "name": "Rock_Stone"
    },
    {
      "x": -1,
      "y": 28,
      "z": -6,
      "name": "Rock_Stone"
    },
    {
      "x": -1,
      "y": 29,
      "z": -6,
      "name": "Rock_Stone"
    },
    {
      "x": -1,
      "y": 30,
      "z": -6,
      "name": "Rock_Stone"
    },
    {
      "x": -1,
      "y": 31,
      "z": -6,
      "name": "Soil_Dirt"
    },
    {
      "x": -1,
      "y": 32,
      "z": -6,
      "name": "Soil_Dirt"
    },
    {
      "x": -1,
      "y": 33,
      "z": -6,
      "name": "Soil_Grass"
    },
    {
      "x": -1,
      "y": 25,
      "z": -5,
      "name": "Rock_Stone"
    },
    {
      "x": -1,
      "y": 26,
      "z": -5,
      "name": "Rock_Stone"
    },
    {
      "x": -1,
      "y": 27,
      "z": -5,
      "name": "Rock_Stone"
    },
    {
      "x": -1,
      "y": 28,
      "z": -5,
      "name": "Rock_Stone"
    },
    {
      "x": -1,
      "y": 29,
      "z": -5,
      "name": "Rock_Stone"
    },
    {
      "x": -1,
      "y": 30,
      "z": -5,
      "name": "Rock_Stone"
    },
    {
      "x": -1,
      "y": 31,
      "z": -5,
      "name": "Soil_Dirt"
    },
    {
      "x": -1,
      "y": 32,
      "z": -5,
      "name": "Soil_Dirt"
    },
    {
      "x": -1,
      "y": 33,
      "z": -5,
      "name": "Soil_Grass"
    },
    {
      "x": -1,
      "y": 24,
      "z": -4,
      "name": "Rock_Stone"
    },
    {
      "x": -1,
      "y": 25,
      "z": -4,
      "name": "Rock_Stone"
    },
    {
      "x": -1,
      "y": 26,
      "z": -4,
      "name": "Rock_Stone"
    },
    {
      "x": -1,
      "y": 27,
      "z": -4,
      "name": "Rock_Stone"
    },
    {
      "x": -1,
      "y": 28,
      "z": -4,
      "name": "Rock_Stone"
    },
    {
      "x": -1,
      "y": 29,
      "z": -4,
      "name": "Rock_Stone"
    },
    {
      "x": -1,
      "y": 30,
      "z": -4,
      "name": "Rock_Stone"
    },
    {
      "x": -1,
      "y": 31,
      "z": -4,
      "name": "Rock_Stone"
    },
    {
      "x": -1,
      "y": 32,
      "z": -4,
      "name": "Soil_Dirt"
    },
    {
      "x": -1,
      "y": 33,
      "z": -4,
      "name": "Soil_Grass"
    },
    {
      "x": -1,
      "y": 34,
      "z": -4,
      "name": "Plant_Grass_Sharp"
    },
    {
      "x": -1,
      "y": 23,
      "z": -3,
      "name": "Rock_Stone"
    },
    {
      "x": -1,
      "y": 24,
      "z": -3,
      "name": "Rock_Stone"
    },
    {
      "x": -1,
      "y": 25,
      "z": -3,
      "name": "Rock_Stone"
    },
    {
      "x": -1,
      "y": 26,
      "z": -3,
      "name": "Rock_Stone"
    },
    {
      "x": -1,
      "y": 27,
      "z": -3,
      "name": "Rock_Stone"
    },
    {
      "x": -1,
      "y": 28,
      "z": -3,
      "name": "Rock_Stone"
    },
    {
      "x": -1,
      "y": 29,
      "z": -3,
      "name": "Rock_Stone"
    },
    {
      "x": -1,
      "y": 30,
      "z": -3,
      "name": "Rock_Stone"
    },
    {
      "x": -1,
      "y": 31,
      "z": -3,
      "name": "Rock_Stone"
    },
    {
      "x": -1,
      "y": 32,
      "z": -3,
      "name": "Soil_Dirt"
    },
    {
      "x": -1,
      "y": 33,
      "z": -3,
      "name": "Soil_Dirt"
    },
    {
      "x": -1,
      "y": 34,
      "z": -3,
      "name": "Soil_Grass"
    },
    {
      "x": -1,
      "y": 22,
      "z": -2,
      "name": "Rock_Stone"
    },
    {
      "x": -1,
      "y": 23,
      "z": -2,
      "name": "Rock_Stone"
    },
    {
      "x": -1,
      "y": 24,
      "z": -2,
      "name": "Rock_Stone"
    },
    {
      "x": -1,
      "y": 25,
      "z": -2,
      "name": "Rock_Stone"
    },
    {
      "x": -1,
      "y": 26,
      "z": -2,
      "name": "Rock_Stone"
    },
    {
      "x": -1,
      "y": 27,
      "z": -2,
      "name": "Rock_Stone"
    },
    {
      "x": -1,
      "y": 28,
      "z": -2,
      "name": "Rock_Stone"
    },
    {
      "x": -1,
      "y": 29,
      "z": -2,
      "name": "Rock_Stone"
    },
    {
      "x": -1,
      "y": 30,
      "z": -2,
      "name": "Rock_Stone"
    },
    {
      "x": -1,
      "y": 31,
      "z": -2,
      "name": "Rock_Stone"
    },
    {
      "x": -1,
      "y": 32,
      "z": -2,
      "name": "Soil_Dirt"
    },
    {
      "x": -1,
      "y": 33,
      "z": -2,
      "name": "Soil_Dirt"
    },
    {
      "x": -1,
      "y": 34,
      "z": -2,
      "name": "Soil_Grass"
    },
    {
      "x": -1,
      "y": 22,
      "z": -1,
      "name": "Rock_Stone"
    },
    {
      "x": -1,
      "y": 23,
      "z": -1,
      "name": "Rock_Stone"
    },
    {
      "x": -1,
      "y": 24,
      "z": -1,
      "name": "Rock_Stone"
    },
    {
      "x": -1,
      "y": 25,
      "z": -1,
      "name": "Rock_Stone"
    },
    {
      "x": -1,
      "y": 26,
      "z": -1,
      "name": "Rock_Stone"
    },
    {
      "x": -1,
      "y": 27,
      "z": -1,
      "name": "Rock_Stone"
    },
    {
      "x": -1,
      "y": 28,
      "z": -1,
      "name": "Rock_Stone"
    },
    {
      "x": -1,
      "y": 29,
      "z": -1,
      "name": "Rock_Stone"
    },
    {
      "x": -1,
      "y": 30,
      "z": -1,
      "name": "Rock_Stone"
    },
    {
      "x": -1,
      "y": 31,
      "z": -1,
      "name": "Soil_Dirt"
    },
    {
      "x": -1,
      "y": 32,
      "z": -1,
      "name": "Soil_Dirt"
    },
    {
      "x": -1,
      "y": 33,
      "z": -1,
      "name": "Soil_Grass"
    },
    {
      "x": -1,
      "y": 22,
      "z": 0,
      "name": "Rock_Stone"
    },
    {
      "x": -1,
      "y": 23,
      "z": 0,
      "name": "Rock_Stone"
    },
    {
      "x": -1,
      "y": 24,
      "z": 0,
      "name": "Rock_Stone"
    },
    {
      "x": -1,
      "y": 25,
      "z": 0,
      "name": "Rock_Stone"
    },
    {
      "x": -1,
      "y": 26,
      "z": 0,
      "name": "Rock_Stone"
    },
    {
      "x": -1,
      "y": 27,
      "z": 0,
      "name": "Rock_Stone"
    },
    {
      "x": -1,
      "y": 28,
      "z": 0,
      "name": "Rock_Stone"
    },
    {
      "x": -1,
      "y": 29,
      "z": 0,
      "name": "Rock_Stone"
    },
    {
      "x": -1,
      "y": 30,
      "z": 0,
      "name": "Soil_Dirt"
    },
    {
      "x": -1,
      "y": 31,
      "z": 0,
      "name": "Soil_Dirt"
    },
    {
      "x": -1,
      "y": 32,
      "z": 0,
      "name": "Soil_Dirt"
    },
    {
      "x": -1,
      "y": 33,
      "z": 0,
      "name": "Soil_Grass"
    },
    {
      "x": -1,
      "y": 22,
      "z": 1,
      "name": "Rock_Stone"
    },
    {
      "x": -1,
      "y": 23,
      "z": 1,
      "name": "Rock_Stone"
    },
    {
      "x": -1,
      "y": 24,
      "z": 1,
      "name": "Rock_Stone"
    },
    {
      "x": -1,
      "y": 25,
      "z": 1,
      "name": "Rock_Stone"
    },
    {
      "x": -1,
      "y": 26,
      "z": 1,
      "name": "Rock_Stone"
    },
    {
      "x": -1,
      "y": 27,
      "z": 1,
      "name": "Rock_Stone"
    },
    {
      "x": -1,
      "y": 28,
      "z": 1,
      "name": "Rock_Stone"
    },
    {
      "x": -1,
      "y": 29,
      "z": 1,
      "name": "Rock_Stone"
    },
    {
      "x": -1,
      "y": 30,
      "z": 1,
      "name": "Soil_Dirt"
    },
    {
      "x": -1,
      "y": 31,
      "z": 1,
      "name": "Rock_Stone"
    },
    {
      "x": -1,
      "y": 32,
      "z": 1,
      "name": "Rock_Stone"
    },
    {
      "x": -1,
      "y": 33,
      "z": 1,
      "name": "Rock_Stone"
    },
    {
      "x": -1,
      "y": 34,
      "z": 1,
      "name": "Soil_Dirt"
    },
    {
      "x": -1,
      "y": 35,
      "z": 1,
      "name": "Soil_Grass"
    },
    {
      "x": -1,
      "y": 22,
      "z": 2,
      "name": "Rock_Stone"
    },
    {
      "x": -1,
      "y": 23,
      "z": 2,
      "name": "Rock_Stone"
    },
    {
      "x": -1,
      "y": 24,
      "z": 2,
      "name": "Rock_Stone"
    },
    {
      "x": -1,
      "y": 25,
      "z": 2,
      "name": "Rock_Stone"
    },
    {
      "x": -1,
      "y": 26,
      "z": 2,
      "name": "Rock_Stone"
    },
    {
      "x": -1,
      "y": 27,
      "z": 2,
      "name": "Rock_Stone"
    },
    {
      "x": -1,
      "y": 28,
      "z": 2,
      "name": "Rock_Stone"
    },
    {
      "x": -1,
      "y": 29,
      "z": 2,
      "name": "Rock_Stone"
    },
    {
      "x": -1,
      "y": 30,
      "z": 2,
      "name": "Soil_Dirt"
    },
    {
      "x": -1,
      "y": 31,
      "z": 2,
      "name": "Rock_Stone"
    },
    {
      "x": -1,
      "y": 32,
      "z": 2,
      "name": "Rock_Stone"
    },
    {
      "x": -1,
      "y": 33,
      "z": 2,
      "name": "Rock_Stone"
    },
    {
      "x": -1,
      "y": 34,
      "z": 2,
      "name": "Soil_Dirt"
    },
    {
      "x": -1,
      "y": 35,
      "z": 2,
      "name": "Soil_Grass"
    },
    {
      "x": -1,
      "y": 23,
      "z": 3,
      "name": "Rock_Stone"
    },
    {
      "x": -1,
      "y": 24,
      "z": 3,
      "name": "Rock_Stone"
    },
    {
      "x": -1,
      "y": 25,
      "z": 3,
      "name": "Rock_Stone"
    },
    {
      "x": -1,
      "y": 26,
      "z": 3,
      "name": "Rock_Stone"
    },
    {
      "x": -1,
      "y": 27,
      "z": 3,
      "name": "Rock_Stone"
    },
    {
      "x": -1,
      "y": 28,
      "z": 3,
      "name": "Rock_Stone"
    },
    {
      "x": -1,
      "y": 29,
      "z": 3,
      "name": "Rock_Stone"
    },
    {
      "x": -1,
      "y": 30,
      "z": 3,
      "name": "Soil_Dirt"
    },
    {
      "x": -1,
      "y": 31,
      "z": 3,
      "name": "Soil_Dirt"
    },
    {
      "x": -1,
      "y": 32,
      "z": 3,
      "name": "Rock_Stone"
    },
    {
      "x": -1,
      "y": 33,
      "z": 3,
      "name": "Rock_Stone"
    },
    {
      "x": -1,
      "y": 23,
      "z": 4,
      "name": "Rock_Stone"
    },
    {
      "x": -1,
      "y": 24,
      "z": 4,
      "name": "Rock_Stone"
    },
    {
      "x": -1,
      "y": 25,
      "z": 4,
      "name": "Rock_Stone"
    },
    {
      "x": -1,
      "y": 26,
      "z": 4,
      "name": "Rock_Stone"
    },
    {
      "x": -1,
      "y": 27,
      "z": 4,
      "name": "Rock_Stone"
    },
    {
      "x": -1,
      "y": 28,
      "z": 4,
      "name": "Rock_Stone"
    },
    {
      "x": -1,
      "y": 29,
      "z": 4,
      "name": "Soil_Dirt"
    },
    {
      "x": -1,
      "y": 30,
      "z": 4,
      "name": "Soil_Dirt"
    },
    {
      "x": -1,
      "y": 31,
      "z": 4,
      "name": "Soil_Grass"
    },
    {
      "x": -1,
      "y": 23,
      "z": 5,
      "name": "Rock_Stone"
    },
    {
      "x": -1,
      "y": 24,
      "z": 5,
      "name": "Rock_Stone"
    },
    {
      "x": -1,
      "y": 25,
      "z": 5,
      "name": "Rock_Stone"
    },
    {
      "x": -1,
      "y": 26,
      "z": 5,
      "name": "Rock_Stone"
    },
    {
      "x": -1,
      "y": 27,
      "z": 5,
      "name": "Rock_Stone"
    },
    {
      "x": -1,
      "y": 28,
      "z": 5,
      "name": "Rock_Stone"
    },
    {
      "x": -1,
      "y": 29,
      "z": 5,
      "name": "Soil_Dirt"
    },
    {
      "x": -1,
      "y": 30,
      "z": 5,
      "name": "Soil_Grass"
    },
    {
      "x": -1,
      "y": 23,
      "z": 6,
      "name": "Rock_Stone"
    },
    {
      "x": -1,
      "y": 24,
      "z": 6,
      "name": "Rock_Stone"
    },
    {
      "x": -1,
      "y": 25,
      "z": 6,
      "name": "Rock_Stone"
    },
    {
      "x": -1,
      "y": 26,
      "z": 6,
      "name": "Rock_Stone"
    },
    {
      "x": -1,
      "y": 27,
      "z": 6,
      "name": "Rock_Stone"
    },
    {
      "x": -1,
      "y": 28,
      "z": 6,
      "name": "Rock_Stone"
    },
    {
      "x": -1,
      "y": 29,
      "z": 6,
      "name": "Soil_Dirt"
    },
    {
      "x": -1,
      "y": 30,
      "z": 6,
      "name": "Soil_Grass"
    },
    {
      "x": -1,
      "y": 31,
      "z": 6,
      "name": "Plant_Grass_Sharp"
    },
    {
      "x": -1,
      "y": 24,
      "z": 7,
      "name": "Rock_Stone"
    },
    {
      "x": -1,
      "y": 25,
      "z": 7,
      "name": "Rock_Stone"
    },
    {
      "x": -1,
      "y": 26,
      "z": 7,
      "name": "Rock_Stone"
    },
    {
      "x": -1,
      "y": 27,
      "z": 7,
      "name": "Rock_Stone"
    },
    {
      "x": -1,
      "y": 28,
      "z": 7,
      "name": "Soil_Dirt"
    },
    {
      "x": -1,
      "y": 29,
      "z": 7,
      "name": "Soil_Dirt"
    },
    {
      "x": -1,
      "y": 30,
      "z": 7,
      "name": "Soil_Grass"
    },
    {
      "x": -1,
      "y": 31,
      "z": 7,
      "name": "Plant_Grass_Sharp"
    },
    {
      "x": -1,
      "y": 25,
      "z": 8,
      "name": "Rock_Stone"
    },
    {
      "x": -1,
      "y": 26,
      "z": 8,
      "name": "Rock_Stone"
    },
    {
      "x": -1,
      "y": 27,
      "z": 8,
      "name": "Rock_Stone"
    },
    {
      "x": -1,
      "y": 28,
      "z": 8,
      "name": "Soil_Dirt"
    },
    {
      "x": -1,
      "y": 29,
      "z": 8,
      "name": "Soil_Grass"
    },
    {
      "x": 0,
      "y": 26,
      "z": -6,
      "name": "Rock_Stone"
    },
    {
      "x": 0,
      "y": 27,
      "z": -6,
      "name": "Rock_Stone"
    },
    {
      "x": 0,
      "y": 28,
      "z": -6,
      "name": "Rock_Stone"
    },
    {
      "x": 0,
      "y": 29,
      "z": -6,
      "name": "Rock_Stone"
    },
    {
      "x": 0,
      "y": 30,
      "z": -6,
      "name": "Rock_Stone"
    },
    {
      "x": 0,
      "y": 31,
      "z": -6,
      "name": "Soil_Dirt"
    },
    {
      "x": 0,
      "y": 32,
      "z": -6,
      "name": "Soil_Dirt"
    },
    {
      "x": 0,
      "y": 33,
      "z": -6,
      "name": "Soil_Grass"
    },
    {
      "x": 0,
      "y": 26,
      "z": -5,
      "name": "Rock_Stone"
    },
    {
      "x": 0,
      "y": 27,
      "z": -5,
      "name": "Rock_Stone"
    },
    {
      "x": 0,
      "y": 28,
      "z": -5,
      "name": "Rock_Stone"
    },
    {
      "x": 0,
      "y": 29,
      "z": -5,
      "name": "Rock_Stone"
    },
    {
      "x": 0,
      "y": 30,
      "z": -5,
      "name": "Rock_Stone"
    },
    {
      "x": 0,
      "y": 31,
      "z": -5,
      "name": "Soil_Dirt"
    },
    {
      "x": 0,
      "y": 32,
      "z": -5,
      "name": "Soil_Dirt"
    },
    {
      "x": 0,
      "y": 33,
      "z": -5,
      "name": "Soil_Grass"
    },
    {
      "x": 0,
      "y": 25,
      "z": -4,
      "name": "Rock_Stone"
    },
    {
      "x": 0,
      "y": 26,
      "z": -4,
      "name": "Rock_Stone"
    },
    {
      "x": 0,
      "y": 27,
      "z": -4,
      "name": "Rock_Stone"
    },
    {
      "x": 0,
      "y": 28,
      "z": -4,
      "name": "Rock_Stone"
    },
    {
      "x": 0,
      "y": 29,
      "z": -4,
      "name": "Rock_Stone"
    },
    {
      "x": 0,
      "y": 30,
      "z": -4,
      "name": "Rock_Stone"
    },
    {
      "x": 0,
      "y": 31,
      "z": -4,
      "name": "Rock_Stone"
    },
    {
      "x": 0,
      "y": 32,
      "z": -4,
      "name": "Soil_Dirt"
    },
    {
      "x": 0,
      "y": 33,
      "z": -4,
      "name": "Soil_Grass"
    },
    {
      "x": 0,
      "y": 34,
      "z": -4,
      "name": "Plant_Grass_Sharp"
    },
    {
      "x": 0,
      "y": 23,
      "z": -3,
      "name": "Rock_Stone"
    },
    {
      "x": 0,
      "y": 24,
      "z": -3,
      "name": "Rock_Stone"
    },
    {
      "x": 0,
      "y": 25,
      "z": -3,
      "name": "Rock_Stone"
    },
    {
      "x": 0,
      "y": 26,
      "z": -3,
      "name": "Rock_Stone"
    },
    {
      "x": 0,
      "y": 27,
      "z": -3,
      "name": "Rock_Stone"
    },
    {
      "x": 0,
      "y": 28,
      "z": -3,
      "name": "Rock_Stone"
    },
    {
      "x": 0,
      "y": 29,
      "z": -3,
      "name": "Rock_Stone"
    },
    {
      "x": 0,
      "y": 30,
      "z": -3,
      "name": "Rock_Stone"
    },
    {
      "x": 0,
      "y": 31,
      "z": -3,
      "name": "Rock_Stone"
    },
    {
      "x": 0,
      "y": 32,
      "z": -3,
      "name": "Soil_Dirt"
    },
    {
      "x": 0,
      "y": 33,
      "z": -3,
      "name": "Soil_Grass"
    },
    {
      "x": 0,
      "y": 34,
      "z": -3,
      "name": "Plant_Grass_Sharp"
    },
    {
      "x": 0,
      "y": 23,
      "z": -2,
      "name": "Rock_Stone"
    },
    {
      "x": 0,
      "y": 24,
      "z": -2,
      "name": "Rock_Stone"
    },
    {
      "x": 0,
      "y": 25,
      "z": -2,
      "name": "Rock_Stone"
    },
    {
      "x": 0,
      "y": 26,
      "z": -2,
      "name": "Rock_Stone"
    },
    {
      "x": 0,
      "y": 27,
      "z": -2,
      "name": "Rock_Stone"
    },
    {
      "x": 0,
      "y": 28,
      "z": -2,
      "name": "Rock_Stone"
    },
    {
      "x": 0,
      "y": 29,
      "z": -2,
      "name": "Rock_Stone"
    },
    {
      "x": 0,
      "y": 30,
      "z": -2,
      "name": "Rock_Stone"
    },
    {
      "x": 0,
      "y": 31,
      "z": -2,
      "name": "Rock_Stone"
    },
    {
      "x": 0,
      "y": 32,
      "z": -2,
      "name": "Soil_Dirt"
    },
    {
      "x": 0,
      "y": 33,
      "z": -2,
      "name": "Soil_Grass"
    },
    {
      "x": 0,
      "y": 22,
      "z": -1,
      "name": "Rock_Stone"
    },
    {
      "x": 0,
      "y": 23,
      "z": -1,
      "name": "Rock_Stone"
    },
    {
      "x": 0,
      "y": 24,
      "z": -1,
      "name": "Rock_Stone"
    },
    {
      "x": 0,
      "y": 25,
      "z": -1,
      "name": "Rock_Stone"
    },
    {
      "x": 0,
      "y": 26,
      "z": -1,
      "name": "Rock_Stone"
    },
    {
      "x": 0,
      "y": 27,
      "z": -1,
      "name": "Rock_Stone"
    },
    {
      "x": 0,
      "y": 28,
      "z": -1,
      "name": "Rock_Stone"
    },
    {
      "x": 0,
      "y": 29,
      "z": -1,
      "name": "Rock_Stone"
    },
    {
      "x": 0,
      "y": 30,
      "z": -1,
      "name": "Rock_Stone"
    },
    {
      "x": 0,
      "y": 31,
      "z": -1,
      "name": "Soil_Dirt"
    },
    {
      "x": 0,
      "y": 32,
      "z": -1,
      "name": "Soil_Dirt"
    },
    {
      "x": 0,
      "y": 33,
      "z": -1,
      "name": "Soil_Grass"
    },
    {
      "x": 0,
      "y": 22,
      "z": 0,
      "name": "Rock_Stone"
    },
    {
      "x": 0,
      "y": 23,
      "z": 0,
      "name": "Rock_Stone"
    },
    {
      "x": 0,
      "y": 24,
      "z": 0,
      "name": "Rock_Stone"
    },
    {
      "x": 0,
      "y": 25,
      "z": 0,
      "name": "Rock_Stone"
    },
    {
      "x": 0,
      "y": 26,
      "z": 0,
      "name": "Rock_Stone"
    },
    {
      "x": 0,
      "y": 27,
      "z": 0,
      "name": "Rock_Stone"
    },
    {
      "x": 0,
      "y": 28,
      "z": 0,
      "name": "Rock_Stone"
    },
    {
      "x": 0,
      "y": 29,
      "z": 0,
      "name": "Rock_Stone"
    },
    {
      "x": 0,
      "y": 30,
      "z": 0,
      "name": "Soil_Dirt"
    },
    {
      "x": 0,
      "y": 31,
      "z": 0,
      "name": "Soil_Dirt"
    },
    {
      "x": 0,
      "y": 32,
      "z": 0,
      "name": "Soil_Grass"
    },
    {
      "x": 0,
      "y": 22,
      "z": 1,
      "name": "Rock_Stone"
    },
    {
      "x": 0,
      "y": 23,
      "z": 1,
      "name": "Rock_Stone"
    },
    {
      "x": 0,
      "y": 24,
      "z": 1,
      "name": "Rock_Stone"
    },
    {
      "x": 0,
      "y": 25,
      "z": 1,
      "name": "Rock_Stone"
    },
    {
      "x": 0,
      "y": 26,
      "z": 1,
      "name": "Rock_Stone"
    },
    {
      "x": 0,
      "y": 27,
      "z": 1,
      "name": "Rock_Stone"
    },
    {
      "x": 0,
      "y": 28,
      "z": 1,
      "name": "Rock_Stone"
    },
    {
      "x": 0,
      "y": 29,
      "z": 1,
      "name": "Rock_Stone"
    },
    {
      "x": 0,
      "y": 30,
      "z": 1,
      "name": "Soil_Dirt"
    },
    {
      "x": 0,
      "y": 31,
      "z": 1,
      "name": "Soil_Grass"
    },
    {
      "x": 0,
      "y": 23,
      "z": 2,
      "name": "Rock_Stone"
    },
    {
      "x": 0,
      "y": 24,
      "z": 2,
      "name": "Rock_Stone"
    },
    {
      "x": 0,
      "y": 25,
      "z": 2,
      "name": "Rock_Stone"
    },
    {
      "x": 0,
      "y": 26,
      "z": 2,
      "name": "Rock_Stone"
    },
    {
      "x": 0,
      "y": 27,
      "z": 2,
      "name": "Rock_Stone"
    },
    {
      "x": 0,
      "y": 28,
      "z": 2,
      "name": "Rock_Stone"
    },
    {
      "x": 0,
      "y": 29,
      "z": 2,
      "name": "Rock_Stone"
    },
    {
      "x": 0,
      "y": 30,
      "z": 2,
      "name": "Soil_Dirt"
    },
    {
      "x": 0,
      "y": 31,
      "z": 2,
      "name": "Soil_Grass"
    },
    {
      "x": 0,
      "y": 23,
      "z": 3,
      "name": "Rock_Stone"
    },
    {
      "x": 0,
      "y": 24,
      "z": 3,
      "name": "Rock_Stone"
    },
    {
      "x": 0,
      "y": 25,
      "z": 3,
      "name": "Rock_Stone"
    },
    {
      "x": 0,
      "y": 26,
      "z": 3,
      "name": "Rock_Stone"
    },
    {
      "x": 0,
      "y": 27,
      "z": 3,
      "name": "Rock_Stone"
    },
    {
      "x": 0,
      "y": 28,
      "z": 3,
      "name": "Rock_Stone"
    },
    {
      "x": 0,
      "y": 29,
      "z": 3,
      "name": "Rock_Stone"
    },
    {
      "x": 0,
      "y": 30,
      "z": 3,
      "name": "Soil_Dirt"
    },
    {
      "x": 0,
      "y": 31,
      "z": 3,
      "name": "Soil_Grass"
    },
    {
      "x": 0,
      "y": 32,
      "z": 3,
      "name": "Plant_Grass_Sharp"
    },
    {
      "x": 0,
      "y": 23,
      "z": 4,
      "name": "Rock_Stone"
    },
    {
      "x": 0,
      "y": 24,
      "z": 4,
      "name": "Rock_Stone"
    },
    {
      "x": 0,
      "y": 25,
      "z": 4,
      "name": "Rock_Stone"
    },
    {
      "x": 0,
      "y": 26,
      "z": 4,
      "name": "Rock_Stone"
    },
    {
      "x": 0,
      "y": 27,
      "z": 4,
      "name": "Rock_Stone"
    },
    {
      "x": 0,
      "y": 28,
      "z": 4,
      "name": "Rock_Stone"
    },
    {
      "x": 0,
      "y": 29,
      "z": 4,
      "name": "Soil_Dirt"
    },
    {
      "x": 0,
      "y": 30,
      "z": 4,
      "name": "Soil_Dirt"
    },
    {
      "x": 0,
      "y": 31,
      "z": 4,
      "name": "Soil_Grass"
    },
    {
      "x": 0,
      "y": 32,
      "z": 4,
      "name": "Plant_Grass_Sharp"
    },
    {
      "x": 0,
      "y": 23,
      "z": 5,
      "name": "Rock_Stone"
    },
    {
      "x": 0,
      "y": 24,
      "z": 5,
      "name": "Rock_Stone"
    },
    {
      "x": 0,
      "y": 25,
      "z": 5,
      "name": "Rock_Stone"
    },
    {
      "x": 0,
      "y": 26,
      "z": 5,
      "name": "Rock_Stone"
    },
    {
      "x": 0,
      "y": 27,
      "z": 5,
      "name": "Rock_Stone"
    },
    {
      "x": 0,
      "y": 28,
      "z": 5,
      "name": "Rock_Stone"
    },
    {
      "x": 0,
      "y": 29,
      "z": 5,
      "name": "Soil_Dirt"
    },
    {
      "x": 0,
      "y": 30,
      "z": 5,
      "name": "Soil_Grass"
    },
    {
      "x": 0,
      "y": 23,
      "z": 6,
      "name": "Rock_Stone"
    },
    {
      "x": 0,
      "y": 24,
      "z": 6,
      "name": "Rock_Stone"
    },
    {
      "x": 0,
      "y": 25,
      "z": 6,
      "name": "Rock_Stone"
    },
    {
      "x": 0,
      "y": 26,
      "z": 6,
      "name": "Rock_Stone"
    },
    {
      "x": 0,
      "y": 27,
      "z": 6,
      "name": "Rock_Stone"
    },
    {
      "x": 0,
      "y": 28,
      "z": 6,
      "name": "Rock_Stone"
    },
    {
      "x": 0,
      "y": 29,
      "z": 6,
      "name": "Soil_Dirt"
    },
    {
      "x": 0,
      "y": 30,
      "z": 6,
      "name": "Soil_Grass"
    },
    {
      "x": 0,
      "y": 24,
      "z": 7,
      "name": "Rock_Stone"
    },
    {
      "x": 0,
      "y": 25,
      "z": 7,
      "name": "Rock_Stone"
    },
    {
      "x": 0,
      "y": 26,
      "z": 7,
      "name": "Rock_Stone"
    },
    {
      "x": 0,
      "y": 27,
      "z": 7,
      "name": "Rock_Stone"
    },
    {
      "x": 0,
      "y": 28,
      "z": 7,
      "name": "Soil_Dirt"
    },
    {
      "x": 0,
      "y": 29,
      "z": 7,
      "name": "Soil_Dirt"
    },
    {
      "x": 0,
      "y": 30,
      "z": 7,
      "name": "Soil_Grass"
    },
    {
      "x": 0,
      "y": 31,
      "z": 7,
      "name": "Plant_Grass_Sharp"
    },
    {
      "x": 0,
      "y": 26,
      "z": 8,
      "name": "Rock_Stone"
    },
    {
      "x": 0,
      "y": 27,
      "z": 8,
      "name": "Rock_Stone"
    },
    {
      "x": 0,
      "y": 28,
      "z": 8,
      "name": "Soil_Dirt"
    },
    {
      "x": 0,
      "y": 29,
      "z": 8,
      "name": "Soil_Grass"
    },
    {
      "x": 1,
      "y": 28,
      "z": -6,
      "name": "Rock_Stone"
    },
    {
      "x": 1,
      "y": 29,
      "z": -6,
      "name": "Rock_Stone"
    },
    {
      "x": 1,
      "y": 30,
      "z": -6,
      "name": "Rock_Stone"
    },
    {
      "x": 1,
      "y": 31,
      "z": -6,
      "name": "Soil_Dirt"
    },
    {
      "x": 1,
      "y": 32,
      "z": -6,
      "name": "Soil_Dirt"
    },
    {
      "x": 1,
      "y": 33,
      "z": -6,
      "name": "Soil_Grass"
    },
    {
      "x": 1,
      "y": 26,
      "z": -5,
      "name": "Rock_Stone"
    },
    {
      "x": 1,
      "y": 27,
      "z": -5,
      "name": "Rock_Stone"
    },
    {
      "x": 1,
      "y": 28,
      "z": -5,
      "name": "Rock_Stone"
    },
    {
      "x": 1,
      "y": 29,
      "z": -5,
      "name": "Rock_Stone"
    },
    {
      "x": 1,
      "y": 30,
      "z": -5,
      "name": "Rock_Stone"
    },
    {
      "x": 1,
      "y": 31,
      "z": -5,
      "name": "Soil_Dirt"
    },
    {
      "x": 1,
      "y": 32,
      "z": -5,
      "name": "Soil_Dirt"
    },
    {
      "x": 1,
      "y": 33,
      "z": -5,
      "name": "Soil_Grass"
    },
    {
      "x": 1,
      "y": 34,
      "z": -5,
      "name": "Plant_Grass_Sharp_Tall"
    },
    {
      "x": 1,
      "y": 35,
      "z": -5,
      "name": "Plant_Grass_Sharp_Tall",
      "filler": 1024
    },
    {
      "x": 1,
      "y": 26,
      "z": -4,
      "name": "Rock_Stone"
    },
    {
      "x": 1,
      "y": 27,
      "z": -4,
      "name": "Rock_Stone"
    },
    {
      "x": 1,
      "y": 28,
      "z": -4,
      "name": "Rock_Stone"
    },
    {
      "x": 1,
      "y": 29,
      "z": -4,
      "name": "Rock_Stone"
    },
    {
      "x": 1,
      "y": 30,
      "z": -4,
      "name": "Rock_Stone"
    },
    {
      "x": 1,
      "y": 31,
      "z": -4,
      "name": "Soil_Dirt"
    },
    {
      "x": 1,
      "y": 32,
      "z": -4,
      "name": "Soil_Dirt"
    },
    {
      "x": 1,
      "y": 33,
      "z": -4,
      "name": "Soil_Grass"
    },
    {
      "x": 1,
      "y": 34,
      "z": -4,
      "name": "Plant_Grass_Sharp"
    },
    {
      "x": 1,
      "y": 24,
      "z": -3,
      "name": "Rock_Stone"
    },
    {
      "x": 1,
      "y": 25,
      "z": -3,
      "name": "Rock_Stone"
    },
    {
      "x": 1,
      "y": 26,
      "z": -3,
      "name": "Rock_Stone"
    },
    {
      "x": 1,
      "y": 27,
      "z": -3,
      "name": "Rock_Stone"
    },
    {
      "x": 1,
      "y": 28,
      "z": -3,
      "name": "Rock_Stone"
    },
    {
      "x": 1,
      "y": 29,
      "z": -3,
      "name": "Rock_Stone"
    },
    {
      "x": 1,
      "y": 30,
      "z": -3,
      "name": "Rock_Stone"
    },
    {
      "x": 1,
      "y": 31,
      "z": -3,
      "name": "Soil_Dirt"
    },
    {
      "x": 1,
      "y": 32,
      "z": -3,
      "name": "Soil_Dirt"
    },
    {
      "x": 1,
      "y": 33,
      "z": -3,
      "name": "Soil_Grass"
    },
    {
      "x": 1,
      "y": 23,
      "z": -2,
      "name": "Rock_Stone"
    },
    {
      "x": 1,
      "y": 24,
      "z": -2,
      "name": "Rock_Stone"
    },
    {
      "x": 1,
      "y": 25,
      "z": -2,
      "name": "Rock_Stone"
    },
    {
      "x": 1,
      "y": 26,
      "z": -2,
      "name": "Rock_Stone"
    },
    {
      "x": 1,
      "y": 27,
      "z": -2,
      "name": "Rock_Stone"
    },
    {
      "x": 1,
      "y": 28,
      "z": -2,
      "name": "Rock_Stone"
    },
    {
      "x": 1,
      "y": 29,
      "z": -2,
      "name": "Rock_Stone"
    },
    {
      "x": 1,
      "y": 30,
      "z": -2,
      "name": "Rock_Stone"
    },
    {
      "x": 1,
      "y": 31,
      "z": -2,
      "name": "Rock_Stone"
    },
    {
      "x": 1,
      "y": 32,
      "z": -2,
      "name": "Soil_Dirt"
    },
    {
      "x": 1,
      "y": 33,
      "z": -2,
      "name": "Soil_Grass"
    },
    {
      "x": 1,
      "y": 23,
      "z": -1,
      "name": "Rock_Stone"
    },
    {
      "x": 1,
      "y": 24,
      "z": -1,
      "name": "Rock_Stone"
    },
    {
      "x": 1,
      "y": 25,
      "z": -1,
      "name": "Rock_Stone"
    },
    {
      "x": 1,
      "y": 26,
      "z": -1,
      "name": "Rock_Stone"
    },
    {
      "x": 1,
      "y": 27,
      "z": -1,
      "name": "Rock_Stone"
    },
    {
      "x": 1,
      "y": 28,
      "z": -1,
      "name": "Rock_Stone"
    },
    {
      "x": 1,
      "y": 29,
      "z": -1,
      "name": "Rock_Stone"
    },
    {
      "x": 1,
      "y": 30,
      "z": -1,
      "name": "Rock_Stone"
    },
    {
      "x": 1,
      "y": 31,
      "z": -1,
      "name": "Soil_Dirt"
    },
    {
      "x": 1,
      "y": 32,
      "z": -1,
      "name": "Soil_Dirt"
    },
    {
      "x": 1,
      "y": 33,
      "z": -1,
      "name": "Soil_Grass"
    },
    {
      "x": 1,
      "y": 23,
      "z": 0,
      "name": "Rock_Stone"
    },
    {
      "x": 1,
      "y": 24,
      "z": 0,
      "name": "Rock_Stone"
    },
    {
      "x": 1,
      "y": 25,
      "z": 0,
      "name": "Rock_Stone"
    },
    {
      "x": 1,
      "y": 26,
      "z": 0,
      "name": "Rock_Stone"
    },
    {
      "x": 1,
      "y": 27,
      "z": 0,
      "name": "Rock_Stone"
    },
    {
      "x": 1,
      "y": 28,
      "z": 0,
      "name": "Rock_Stone"
    },
    {
      "x": 1,
      "y": 29,
      "z": 0,
      "name": "Rock_Stone"
    },
    {
      "x": 1,
      "y": 30,
      "z": 0,
      "name": "Soil_Dirt"
    },
    {
      "x": 1,
      "y": 31,
      "z": 0,
      "name": "Soil_Dirt"
    },
    {
      "x": 1,
      "y": 32,
      "z": 0,
      "name": "Soil_Grass"
    },
    {
      "x": 1,
      "y": 23,
      "z": 1,
      "name": "Rock_Stone"
    },
    {
      "x": 1,
      "y": 24,
      "z": 1,
      "name": "Rock_Stone"
    },
    {
      "x": 1,
      "y": 25,
      "z": 1,
      "name": "Rock_Stone"
    },
    {
      "x": 1,
      "y": 26,
      "z": 1,
      "name": "Rock_Stone"
    },
    {
      "x": 1,
      "y": 27,
      "z": 1,
      "name": "Rock_Stone"
    },
    {
      "x": 1,
      "y": 28,
      "z": 1,
      "name": "Rock_Stone"
    },
    {
      "x": 1,
      "y": 29,
      "z": 1,
      "name": "Rock_Stone"
    },
    {
      "x": 1,
      "y": 30,
      "z": 1,
      "name": "Soil_Dirt"
    },
    {
      "x": 1,
      "y": 31,
      "z": 1,
      "name": "Soil_Dirt"
    },
    {
      "x": 1,
      "y": 32,
      "z": 1,
      "name": "Soil_Grass"
    },
    {
      "x": 1,
      "y": 23,
      "z": 2,
      "name": "Rock_Stone"
    },
    {
      "x": 1,
      "y": 24,
      "z": 2,
      "name": "Rock_Stone"
    },
    {
      "x": 1,
      "y": 25,
      "z": 2,
      "name": "Rock_Stone"
    },
    {
      "x": 1,
      "y": 26,
      "z": 2,
      "name": "Rock_Stone"
    },
    {
      "x": 1,
      "y": 27,
      "z": 2,
      "name": "Rock_Stone"
    },
    {
      "x": 1,
      "y": 28,
      "z": 2,
      "name": "Rock_Stone"
    },
    {
      "x": 1,
      "y": 29,
      "z": 2,
      "name": "Rock_Stone"
    },
    {
      "x": 1,
      "y": 30,
      "z": 2,
      "name": "Soil_Dirt"
    },
    {
      "x": 1,
      "y": 31,
      "z": 2,
      "name": "Soil_Grass"
    },
    {
      "x": 1,
      "y": 32,
      "z": 2,
      "name": "Plant_Grass_Sharp_Tall"
    },
    {
      "x": 1,
      "y": 33,
      "z": 2,
      "name": "Plant_Grass_Sharp_Tall",
      "filler": 1024
    },
    {
      "x": 1,
      "y": 23,
      "z": 3,
      "name": "Rock_Stone"
    },
    {
      "x": 1,
      "y": 24,
      "z": 3,
      "name": "Rock_Stone"
    },
    {
      "x": 1,
      "y": 25,
      "z": 3,
      "name": "Rock_Stone"
    },
    {
      "x": 1,
      "y": 26,
      "z": 3,
      "name": "Rock_Stone"
    },
    {
      "x": 1,
      "y": 27,
      "z": 3,
      "name": "Rock_Stone"
    },
    {
      "x": 1,
      "y": 28,
      "z": 3,
      "name": "Rock_Stone"
    },
    {
      "x": 1,
      "y": 29,
      "z": 3,
      "name": "Rock_Stone"
    },
    {
      "x": 1,
      "y": 30,
      "z": 3,
      "name": "Soil_Dirt"
    },
    {
      "x": 1,
      "y": 31,
      "z": 3,
      "name": "Soil_Grass"
    },
    {
      "x": 1,
      "y": 32,
      "z": 3,
      "name": "Plant_Grass_Sharp_Tall"
    },
    {
      "x": 1,
      "y": 33,
      "z": 3,
      "name": "Plant_Grass_Sharp_Tall",
      "filler": 1024
    },
    {
      "x": 1,
      "y": 23,
      "z": 4,
