{
  "version": 8,
  "blockIdVersion": 8,
  "anchorX": 7,
  "anchorY": 10,
  "anchorZ": 7,
  "blocks": [
    {
      "x": 2,
      "y": 16,
      "z": 7,
      "name": "Plant_Leaves_Fir_Red"
    },
    {
      "x": 3,
      "y": 16,
      "z": 7,
      "name": "Plant_Leaves_Fir_Red"
    },
    {
      "x": 3,
      "y": 17,
      "z": 7,
      "name": "Plant_Leaves_Fir_Red"
    },
    {
      "x": 4,
      "y": 17,
      "z": 6,
      "name": "Plant_Leaves_Fir_Red"
    },
    {
      "x": 4,
      "y": 17,
      "z": 7,
      "name": "Plant_Leaves_Fir_Red"
    },
    {
      "x": 4,
      "y": 18,
      "z": 7,
      "name": "Plant_Leaves_Fir_Red"
    },
    {
      "x": 4,
      "y": 20,
      "z": 7,
      "name": "Plant_Leaves_Fir_Red"
    },
    {
      "x": 4,
      "y": 23,
      "z": 7,
      "name": "Plant_Leaves_Fir_Red"
    },
    {
      "x": 4,
      "y": 17,
      "z": 8,
      "name": "Plant_Leaves_Fir_Red"
    },
    {
      "x": 5,
      "y": 19,
      "z": 4,
      "name": "Plant_Leaves_Fir_Red"
    },
    {
      "x": 5,
      "y": 17,
      "z": 5,
      "name": "Plant_Leaves_Fir_Red"
    },
    {
      "x": 5,
      "y": 17,
      "z": 6,
      "name": "Plant_Leaves_Fir_Red"
    },
    {
      "x": 5,
      "y": 27,
      "z": 6,
      "name": "Plant_Leaves_Fir_Red"
    },
    {
      "x": 5,
      "y": 17,
      "z": 7,
      "name": "Wood_Fir_Branch_Long",
      "rotation": 5
    },
    {
      "x": 5,
      "y": 18,
      "z": 7,
      "name": "Plant_Leaves_Fir_Red"
    },
    {
      "x": 5,
      "y": 20,
      "z": 7,
      "name": "Plant_Leaves_Fir_Red"
    },
    {
      "x": 5,
      "y": 21,
      "z": 7,
      "name": "Plant_Leaves_Fir_Red"
    },
    {
      "x": 5,
      "y": 23,
      "z": 7,
      "name": "Plant_Leaves_Fir_Red"
    },
    {
      "x": 5,
      "y": 24,
      "z": 7,
      "name": "Plant_Leaves_Fir_Red"
    },
    {
      "x": 5,
      "y": 18,
      "z": 8,
      "name": "Plant_Leaves_Fir_Red"
    },
    {
      "x": 5,
      "y": 23,
      "z": 8,
      "name": "Plant_Leaves_Fir_Red"
    },
    {
      "x": 5,
      "y": 18,
      "z": 9,
      "name": "Plant_Leaves_Fir_Red"
    },
    {
      "x": 6,
      "y": 19,
      "z": 4,
      "name": "Plant_Leaves_Fir_Red"
    },
    {
      "x": 6,
      "y": 20,
      "z": 5,
      "name": "Plant_Leaves_Fir_Red"
    },
    {
      "x": 6,
      "y": 18,
      "z": 6,
      "name": "Plant_Leaves_Fir_Red"
    },
    {
      "x": 6,
      "y": 21,
      "z": 6,
      "name": "Plant_Leaves_Fir_Red"
    },
    {
      "x": 6,
      "y": 24,
      "z": 6,
      "name": "Plant_Leaves_Fir_Red"
    },
    {
      "x": 6,
      "y": 27,
      "z": 6,
      "name": "Plant_Leaves_Fir_Red"
    },
    {
      "x": 6,
      "y": 28,
      "z": 6,
      "name": "Plant_Leaves_Fir_Red"
    },
    {
      "x": 6,
      "y": 5,
      "z": 7,
      "name": "Wood_Fir_Roots"
    },
    {
      "x": 6,
      "y": 6,
      "z": 7,
      "name": "Wood_Fir_Trunk_Full"
    },
    {
      "x": 6,
      "y": 7,
      "z": 7,
      "name": "Wood_Fir_Trunk"
    },
    {
      "x": 6,
      "y": 8,
      "z": 7,
      "name": "Wood_Fir_Trunk"
    },
    {
      "x": 6,
      "y": 9,
      "z": 7,
      "name": "Wood_Fir_Trunk"
    },
    {
      "x": 6,
      "y": 10,
      "z": 7,
      "name": "Wood_Fir_Trunk_Full"
    },
    {
      "x": 6,
      "y": 17,
      "z": 7,
      "name": "Wood_Fir_Branch_Long",
      "rotation": 5
    },
    {
      "x": 6,
      "y": 18,
      "z": 7,
      "name": "Plant_Leaves_Fir_Red"
    },
    {
      "x": 6,
      "y": 19,
      "z": 7,
      "name": "Plant_Leaves_Fir_Red"
    },
    {
      "x": 6,
      "y": 21,
      "z": 7,
      "name": "Plant_Leaves_Fir_Red"
    },
    {
      "x": 6,
      "y": 22,
      "z": 7,
      "name": "Plant_Leaves_Fir_Red"
    },
    {
      "x": 6,
      "y": 24,
      "z": 7,
      "name": "Wood_Fir_Branch_Long",
      "rotation": 5
    },
    {
      "x": 6,
      "y": 25,
      "z": 7,
      "name": "Plant_Leaves_Fir_Red"
    },
    {
      "x": 6,
      "y": 28,
      "z": 7,
      "name": "Plant_Leaves_Fir_Red"
    },
    {
      "x": 6,
      "y": 29,
      "z": 7,
      "name": "Plant_Leaves_Fir_Red"
    },
    {
      "x": 6,
      "y": 7,
      "z": 8,
      "name": "Wood_Fir_Roots"
    },
    {
      "x": 6,
      "y": 8,
      "z": 8,
      "name": "Wood_Fir_Trunk_Full"
    },
    {
      "x": 6,
      "y": 24,
      "z": 8,
      "name": "Plant_Leaves_Fir_Red"
    },
    {
      "x": 6,
      "y": 17,
      "z": 9,
      "name": "Plant_Leaves_Fir_Red"
    },
    {
      "x": 6,
      "y": 20,
      "z": 9,
      "name": "Plant_Leaves_Fir_Red"
    },
    {
      "x": 6,
      "y": 20,
      "z": 10,
      "name": "Plant_Leaves_Fir_Red"
    },
    {
      "x": 6,
      "y": 19,
      "z": 11,
      "name": "Plant_Leaves_Fir_Red"
    },
    {
      "x": 7,
      "y": 17,
      "z": 3,
      "name": "Plant_Leaves_Fir_Red"
    },
    {
      "x": 7,
      "y": 17,
      "z": 4,
      "name": "Plant_Leaves_Fir_Red"
    },
    {
      "x": 7,
      "y": 20,
      "z": 4,
      "name": "Plant_Leaves_Fir_Red"
    },
    {
      "x": 7,
      "y": 9,
      "z": 5,
      "name": "Wood_Fir_Trunk_Full"
    },
    {
      "x": 7,
      "y": 18,
      "z": 5,
      "name": "Plant_Leaves_Fir_Red"
    },
    {
      "x": 7,
      "y": 20,
      "z": 5,
      "name": "Plant_Leaves_Fir_Red"
    },
    {
      "x": 7,
      "y": 21,
      "z": 5,
      "name": "Plant_Leaves_Fir_Red"
    },
    {
      "x": 7,
      "y": 8,
      "z": 6,
      "name": "Wood_Fir_Roots"
    },
    {
      "x": 7,
      "y": 9,
      "z": 6,
      "name": "Wood_Fir_Trunk_Full"
    },
    {
      "x": 7,
      "y": 10,
      "z": 6,
      "name": "Wood_Fir_Trunk"
    },
    {
      "x": 7,
      "y": 11,
      "z": 6,
      "name": "Wood_Fir_Trunk"
    },
    {
      "x": 7,
      "y": 12,
      "z": 6,
      "name": "Wood_Fir_Trunk"
    },
    {
      "x": 7,
      "y": 13,
      "z": 6,
      "name": "Wood_Fir_Trunk"
    },
    {
      "x": 7,
      "y": 14,
      "z": 6,
      "name": "Wood_Fir_Trunk"
    },
    {
      "x": 7,
      "y": 15,
      "z": 6,
      "name": "Wood_Fir_Trunk"
    },
    {
      "x": 7,
      "y": 16,
      "z": 6,
      "name": "Wood_Fir_Trunk"
    },
    {
      "x": 7,
      "y": 17,
      "z": 6,
      "name": "Wood_Fir_Trunk"
    },
    {
      "x": 7,
      "y": 18,
      "z": 6,
      "name": "Wood_Fir_Trunk_Full"
    },
    {
      "x": 7,
      "y": 20,
      "z": 6,
      "name": "Plant_Leaves_Fir_Red"
    },
    {
      "x": 7,
      "y": 21,
      "z": 6,
      "name": "Plant_Leaves_Fir_Red"
    },
    {
      "x": 7,
      "y": 22,
      "z": 6,
      "name": "Plant_Leaves_Fir_Red"
    },
    {
      "x": 7,
      "y": 24,
      "z": 6,
      "name": "Plant_Leaves_Fir_Red"
    },
    {
      "x": 7,
      "y": 9,
      "z": 7,
      "name": "Wood_Fir_Trunk_Full"
    },
    {
      "x": 7,
      "y": 10,
      "z": 7,
      "name": "Wood_Fir_Trunk_Full"
    },
    {
      "x": 7,
      "y": 11,
      "z": 7,
      "name": "Wood_Fir_Trunk"
    },
    {
      "x": 7,
      "y": 12,
      "z": 7,
      "name": "Wood_Fir_Trunk"
    },
    {
      "x": 7,
      "y": 13,
      "z": 7,
      "name": "Wood_Fir_Trunk"
    },
    {
      "x": 7,
      "y": 14,
      "z": 7,
      "name": "Wood_Fir_Trunk"
    },
    {
      "x": 7,
      "y": 15,
      "z": 7,
      "name": "Wood_Fir_Trunk"
    },
    {
      "x": 7,
      "y": 16,
      "z": 7,
      "name": "Wood_Fir_Trunk"
    },
    {
      "x": 7,
      "y": 17,
      "z": 7,
      "name": "Wood_Fir_Trunk"
    },
    {
      "x": 7,
      "y": 18,
      "z": 7,
      "name": "Wood_Fir_Trunk"
    },
    {
      "x": 7,
      "y": 19,
      "z": 7,
      "name": "Wood_Fir_Trunk"
    },
    {
      "x": 7,
      "y": 20,
      "z": 7,
      "name": "Wood_Fir_Trunk"
    },
    {
      "x": 7,
      "y": 21,
      "z": 7,
      "name": "Wood_Fir_Trunk"
    },
    {
      "x": 7,
      "y": 22,
      "z": 7,
      "name": "Wood_Fir_Trunk_Full"
    },
    {
      "x": 7,
      "y": 24,
      "z": 7,
      "name": "Wood_Fir_Branch_Long",
      "rotation": 5
    },
    {
      "x": 7,
      "y": 25,
      "z": 7,
      "name": "Plant_Leaves_Fir_Red"
    },
    {
      "x": 7,
      "y": 26,
      "z": 7,
      "name": "Wood_Fir_Branch_Long",
      "rotation": 5
    },
    {
      "x": 7,
      "y": 28,
      "z": 7,
      "name": "Plant_Leaves_Fir_Red"
    },
    {
      "x": 7,
      "y": 29,
      "z": 7,
      "name": "Wood_Fir_Branch_Short",
      "rotation": 3
    },
    {
      "x": 7,
      "y": 30,
      "z": 7,
      "name": "Plant_Leaves_Fir_Red"
    },
    {
      "x": 7,
      "y": 31,
      "z": 7,
      "name": "Plant_Leaves_Fir_Red"
    },
    {
      "x": 7,
      "y": 10,
      "z": 8,
      "name": "Wood_Fir_Trunk_Full"
    },
    {
      "x": 7,
      "y": 11,
      "z": 8,
      "name": "Wood_Fir_Trunk_Full"
    },
    {
      "x": 7,
      "y": 18,
      "z": 8,
      "name": "Plant_Leaves_Fir_Red"
    },
    {
      "x": 7,
      "y": 21,
      "z": 8,
      "name": "Plant_Leaves_Fir_Red"
    },
    {
      "x": 7,
      "y": 25,
      "z": 8,
      "name": "Plant_Leaves_Fir_Red"
    },
    {
      "x": 7,
      "y": 29,
      "z": 8,
      "name": "Plant_Leaves_Fir_Red"
    },
    {
      "x": 7,
      "y": 17,
      "z": 9,
      "name": "Plant_Leaves_Fir_Red"
    },
    {
      "x": 7,
      "y": 18,
      "z": 9,
      "name": "Plant_Leaves_Fir_Red"
    },
    {
      "x": 7,
      "y": 21,
      "z": 9,
      "name": "Plant_Leaves_Fir_Red"
    },
    {
      "x": 7,
      "y": 24,
      "z": 9,
      "name": "Plant_Leaves_Fir_Red"
    },
    {
      "x": 7,
      "y": 27,
      "z": 9,
      "name": "Plant_Leaves_Fir_Red"
    },
    {
      "x": 7,
      "y": 28,
      "z": 9,
      "name": "Plant_Leaves_Fir_Red"
    },
    {
      "x": 7,
      "y": 18,
      "z": 10,
      "name": "Plant_Leaves_Fir_Red"
    },
    {
      "x": 7,
      "y": 20,
      "z": 10,
      "name": "Plant_Leaves_Fir_Red"
    },
    {
      "x": 7,
      "y": 27,
      "z": 10,
      "name": "Plant_Leaves_Fir_Red"
    },
    {
      "x": 7,
      "y": 17,
      "z": 11,
      "name": "Plant_Leaves_Fir_Red"
    },
    {
      "x": 8,
      "y": 16,
      "z": 2,
      "name": "Plant_Leaves_Fir_Red"
    },
    {
      "x": 8,
      "y": 16,
      "z": 3,
      "name": "Plant_Leaves_Fir_Red"
    },
    {
      "x": 8,
      "y": 17,
      "z": 3,
      "name": "Plant_Leaves_Fir_Red"
    },
    {
      "x": 8,
      "y": 17,
      "z": 4,
      "name": "Wood_Fir_Branch_Long",
      "rotation": 4
    },
    {
      "x": 8,
      "y": 18,
      "z": 4,
      "name": "Plant_Leaves_Fir_Red"
    },
    {
      "x": 8,
      "y": 23,
      "z": 4,
      "name": "Plant_Leaves_Fir_Red"
    },
    {
      "x": 8,
      "y": 4,
      "z": 5,
      "name": "Wood_Fir_Roots"
    },
    {
      "x": 8,
      "y": 5,
      "z": 5,
      "name": "Wood_Fir_Trunk_Full"
    },
    {
      "x": 8,
      "y": 6,
      "z": 5,
      "name": "Wood_Fir_Trunk"
    },
    {
      "x": 8,
      "y": 7,
      "z": 5,
      "name": "Wood_Fir_Trunk"
    },
    {
      "x": 8,
      "y": 8,
      "z": 5,
      "name": "Wood_Fir_Trunk"
    },
    {
      "x": 8,
      "y": 9,
      "z": 5,
      "name": "Wood_Fir_Trunk"
    },
    {
      "x": 8,
      "y": 10,
      "z": 5,
      "name": "Wood_Fir_Trunk_Full"
    },
    {
      "x": 8,
      "y": 17,
      "z": 5,
      "name": "Wood_Fir_Branch_Long",
      "rotation": 4
    },
    {
      "x": 8,
      "y": 18,
      "z": 5,
      "name": "Plant_Leaves_Fir_Red"
    },
    {
      "x": 8,
      "y": 19,
      "z": 5,
      "name": "Plant_Leaves_Fir_Red"
    },
    {
      "x": 8,
      "y": 20,
      "z": 5,
      "name": "Wood_Fir_Branch_Long",
      "rotation": 4
    },
    {
      "x": 8,
      "y": 21,
      "z": 5,
      "name": "Plant_Leaves_Fir_Red"
    },
    {
      "x": 8,
      "y": 23,
      "z": 5,
      "name": "Plant_Leaves_Fir_Red"
    },
    {
      "x": 8,
      "y": 24,
      "z": 5,
      "name": "Plant_Leaves_Fir_Red"
    },
    {
      "x": 8,
      "y": 25,
      "z": 5,
      "name": "Plant_Leaves_Fir_Red"
    },
    {
      "x": 8,
      "y": 28,
      "z": 5,
      "name": "Plant_Leaves_Fir_Red"
    },
    {
      "x": 8,
      "y": 9,
      "z": 6,
      "name": "Wood_Fir_Trunk_Full"
    },
    {
      "x": 8,
      "y": 10,
      "z": 6,
      "name": "Wood_Fir_Trunk"
    },
    {
      "x": 8,
      "y": 11,
      "z": 6,
      "name": "Wood_Fir_Trunk"
    },
    {
      "x": 8,
      "y": 12,
      "z": 6,
      "name": "Wood_Fir_Trunk"
    },
    {
      "x": 8,
      "y": 13,
      "z": 6,
      "name": "Wood_Fir_Trunk"
    },
    {
      "x": 8,
      "y": 14,
      "z": 6,
      "name": "Wood_Fir_Trunk"
    },
    {
      "x": 8,
      "y": 15,
      "z": 6,
      "name": "Wood_Fir_Trunk"
    },
    {
      "x": 8,
      "y": 16,
      "z": 6,
      "name": "Wood_Fir_Trunk_Full"
    },
    {
      "x": 8,
      "y": 17,
      "z": 6,
      "name": "Wood_Fir_Branch_Long",
      "rotation": 4
    },
    {
      "x": 8,
      "y": 18,
      "z": 6,
      "name": "Plant_Leaves_Fir_Red"
    },
    {
      "x": 8,
      "y": 19,
      "z": 6,
      "name": "Plant_Leaves_Fir_Red"
    },
    {
      "x": 8,
      "y": 20,
      "z": 6,
      "name": "Wood_Fir_Branch_Long",
      "rotation": 4
    },
    {
      "x": 8,
      "y": 21,
      "z": 6,
      "name": "Plant_Leaves_Fir_Red"
    },
    {
      "x": 8,
      "y": 22,
      "z": 6,
      "name": "Wood_Fir_Branch_Long",
      "rotation": 4
    },
    {
      "x": 8,
      "y": 24,
      "z": 6,
      "name": "Plant_Leaves_Fir_Red"
    },
    {
      "x": 8,
      "y": 25,
      "z": 6,
      "name": "Wood_Fir_Branch_Long",
      "rotation": 4
    },
    {
      "x": 8,
      "y": 26,
      "z": 6,
      "name": "Plant_Leaves_Fir_Red"
    },
    {
      "x": 8,
      "y": 28,
      "z": 6,
      "name": "Wood_Fir_Branch_Long",
      "rotation": 4
    },
    {
      "x": 8,
      "y": 29,
      "z": 6,
      "name": "Plant_Leaves_Fir_Red"
    },
    {
      "x": 8,
      "y": 30,
      "z": 6,
      "name": "Plant_Leaves_Fir_Red"
    },
    {
      "x": 8,
      "y": 5,
      "z": 7,
      "name": "Wood_Fir_Roots"
    },
    {
      "x": 8,
      "y": 6,
      "z": 7,
      "name": "Wood_Fir_Trunk_Full"
    },
    {
      "x": 8,
      "y": 7,
      "z": 7,
      "name": "Wood_Fir_Trunk"
    },
    {
      "x": 8,
      "y": 8,
      "z": 7,
      "name": "Wood_Fir_Trunk"
    },
    {
      "x": 8,
      "y": 9,
      "z": 7,
      "name": "Wood_Fir_Trunk"
    },
    {
      "x": 8,
      "y": 10,
      "z": 7,
      "name": "Wood_Fir_Trunk"
    },
    {
      "x": 8,
      "y": 11,
      "z": 7,
      "name": "Wood_Fir_Trunk"
    },
    {
      "x": 8,
      "y": 12,
      "z": 7,
      "name": "Wood_Fir_Trunk"
    },
    {
      "x": 8,
      "y": 13,
      "z": 7,
      "name": "Wood_Fir_Trunk"
    },
    {
      "x": 8,
      "y": 14,
      "z": 7,
      "name": "Wood_Fir_Trunk"
    },
    {
      "x": 8,
      "y": 15,
      "z": 7,
      "name": "Wood_Fir_Trunk"
    },
    {
      "x": 8,
      "y": 16,
      "z": 7,
      "name": "Wood_Fir_Trunk"
    },
    {
      "x": 8,
      "y": 17,
      "z": 7,
      "name": "Wood_Fir_Trunk"
    },
    {
      "x": 8,
      "y": 18,
      "z": 7,
      "name": "Wood_Fir_Trunk"
    },
    {
      "x": 8,
      "y": 19,
      "z": 7,
      "name": "Wood_Fir_Trunk"
    },
    {
      "x": 8,
      "y": 20,
      "z": 7,
      "name": "Wood_Fir_Trunk"
    },
    {
      "x": 8,
      "y": 21,
      "z": 7,
      "name": "Wood_Fir_Trunk"
    },
    {
      "x": 8,
      "y": 22,
      "z": 7,
      "name": "Wood_Fir_Trunk"
    },
    {
      "x": 8,
      "y": 23,
      "z": 7,
      "name": "Wood_Fir_Trunk"
    },
    {
      "x": 8,
      "y": 24,
      "z": 7,
      "name": "Wood_Fir_Trunk"
    },
    {
      "x": 8,
      "y": 25,
      "z": 7,
      "name": "Wood_Fir_Trunk"
    },
    {
      "x": 8,
      "y": 26,
      "z": 7,
      "name": "Wood_Fir_Trunk"
    },
    {
      "x": 8,
      "y": 27,
      "z": 7,
      "name": "Wood_Fir_Trunk"
    },
    {
      "x": 8,
      "y": 28,
      "z": 7,
      "name": "Wood_Fir_Trunk"
    },
    {
      "x": 8,
      "y": 29,
      "z": 7,
      "name": "Wood_Fir_Trunk"
    },
    {
      "x": 8,
      "y": 30,
      "z": 7,
      "name": "Wood_Fir_Trunk_Full"
    },
    {
      "x": 8,
      "y": 31,
      "z": 7,
      "name": "Plant_Leaves_Fir_Red"
    },
    {
      "x": 8,
      "y": 32,
      "z": 7,
      "name": "Plant_Leaves_Fir_Red"
    },
    {
      "x": 8,
      "y": 33,
      "z": 7,
      "name": "Plant_Leaves_Fir_Red"
    },
    {
      "x": 8,
      "y": 34,
      "z": 7,
      "name": "Plant_Leaves_Fir_Red"
    },
    {
      "x": 8,
      "y": 8,
      "z": 8,
      "name": "Wood_Fir_Trunk_Full"
    },
    {
      "x": 8,
      "y": 9,
      "z": 8,
      "name": "Wood_Fir_Trunk"
    },
    {
      "x": 8,
      "y": 10,
      "z": 8,
      "name": "Wood_Fir_Trunk"
    },
    {
      "x": 8,
      "y": 11,
      "z": 8,
      "name": "Wood_Fir_Trunk"
    },
    {
      "x": 8,
      "y": 12,
      "z": 8,
      "name": "Wood_Fir_Trunk"
    },
    {
      "x": 8,
      "y": 13,
      "z": 8,
      "name": "Wood_Fir_Trunk_Full"
    },
    {
      "x": 8,
      "y": 17,
      "z": 8,
      "name": "Wood_Fir_Branch_Long",
      "rotation": 4
    },
    {
      "x": 8,
      "y": 18,
      "z": 8,
      "name": "Plant_Leaves_Fir_Red"
    },
    {
      "x": 8,
      "y": 19,
      "z": 8,
      "name": "Plant_Leaves_Fir_Red"
    },
    {
      "x": 8,
      "y": 20,
      "z": 8,
      "name": "Wood_Fir_Branch_Long",
      "rotation": 4
    },
    {
      "x": 8,
      "y": 21,
      "z": 8,
      "name": "Plant_Leaves_Fir_Red"
    },
    {
      "x": 8,
      "y": 22,
      "z": 8,
      "name": "Plant_Leaves_Fir_Red"
    },
    {
      "x": 8,
      "y": 24,
      "z": 8,
      "name": "Wood_Fir_Branch_Long",
      "rotation": 4
    },
    {
      "x": 8,
      "y": 25,
      "z": 8,
      "name": "Plant_Leaves_Fir_Red"
    },
    {
      "x": 8,
      "y": 27,
      "z": 8,
      "name": "Wood_Fir_Branch_Long",
      "rotation": 4
    },
    {
      "x": 8,
      "y": 28,
      "z": 8,
      "name": "Plant_Leaves_Fir_Red"
    },
    {
      "x": 8,
      "y": 29,
      "z": 8,
      "name": "Plant_Leaves_Fir_Red"
    },
    {
      "x": 8,
      "y": 30,
      "z": 8,
      "name": "Plant_Leaves_Fir_Red"
    },
    {
      "x": 8,
      "y": 31,
      "z": 8,
      "name": "Plant_Leaves_Fir_Red"
    },
    {
      "x": 8,
      "y": 3,
      "z": 9,
      "name": "Wood_Fir_Roots"
    },
    {
      "x": 8,
      "y": 4,
      "z": 9,
      "name": "Wood_Fir_Trunk_Full"
    },
    {
      "x": 8,
      "y": 5,
      "z": 9,
      "name": "Wood_Fir_Trunk"
    },
    {
      "x": 8,
      "y": 6,
      "z": 9,
      "name": "Wood_Fir_Trunk"
    },
    {
      "x": 8,
      "y": 7,
      "z": 9,
      "name": "Wood_Fir_Trunk"
    },
    {
      "x": 8,
      "y": 8,
      "z": 9,
      "name": "Wood_Fir_Trunk_Full"
    },
    {
      "x": 8,
      "y": 17,
      "z": 9,
      "name": "Wood_Fir_Branch_Long",
      "rotation": 4
    },
    {
      "x": 8,
      "y": 18,
      "z": 9,
      "name": "Plant_Leaves_Fir_Red"
    },
    {
      "x": 8,
      "y": 19,
      "z": 9,
      "name": "Plant_Leaves_Fir_Red"
    },
    {
      "x": 8,
      "y": 20,
      "z": 9,
      "name": "Wood_Fir_Branch_Long",
      "rotation": 4
    },
    {
      "x": 8,
      "y": 21,
      "z": 9,
      "name": "Plant_Leaves_Fir_Red"
    },
    {
      "x": 8,
      "y": 23,
      "z": 9,
      "name": "Plant_Leaves_Fir_Red"
    },
    {
      "x": 8,
      "y": 24,
      "z": 9,
      "name": "Plant_Leaves_Fir_Red"
    },
    {
      "x": 8,
      "y": 25,
      "z": 9,
      "name": "Plant_Leaves_Fir_Red"
    },
    {
      "x": 8,
      "y": 28,
      "z": 9,
      "name": "Plant_Leaves_Fir_Red"
    },
    {
      "x": 8,
      "y": 29,
      "z": 9,
      "name": "Plant_Leaves_Fir_Red"
    },
    {
      "x": 8,
      "y": 17,
      "z": 10,
      "name": "Wood_Fir_Branch_Long",
      "rotation": 4
    },
    {
      "x": 8,
      "y": 18,
      "z": 10,
      "name": "Plant_Leaves_Fir_Red"
    },
    {
      "x": 8,
      "y": 20,
      "z": 10,
      "name": "Plant_Leaves_Fir_Red"
    },
    {
      "x": 8,
      "y": 23,
      "z": 10,
      "name": "Plant_Leaves_Fir_Red"
    },
    {
      "x": 8,
      "y": 16,
      "z": 11,
      "name": "Plant_Leaves_Fir_Red"
    },
    {
      "x": 8,
      "y": 17,
      "z": 11,
      "name": "Plant_Leaves_Fir_Red"
    },
    {
      "x": 8,
      "y": 16,
      "z": 12,
      "name": "Plant_Leaves_Fir_Red"
    },
    {
      "x": 8,
      "y": 17,
      "z": 12,
      "name": "Plant_Leaves_Fir_Red"
    },
    {
      "x": 8,
      "y": 16,
      "z": 13,
      "name": "Plant_Leaves_Fir_Red"
    },
    {
      "x": 9,
      "y": 16,
      "z": 2,
      "name": "Plant_Leaves_Fir_Red"
    },
    {
      "x": 9,
      "y": 17,
      "z": 3,
      "name": "Plant_Leaves_Fir_Red"
    },
    {
      "x": 9,
      "y": 17,
      "z": 4,
      "name": "Plant_Leaves_Fir_Red"
    },
    {
      "x": 9,
      "y": 18,
      "z": 4,
      "name": "Plant_Leaves_Fir_Red"
    },
    {
      "x": 9,
      "y": 23,
      "z": 4,
      "name": "Plant_Leaves_Fir_Red"
    },
    {
      "x": 9,
      "y": 18,
      "z": 5,
      "name": "Plant_Leaves_Fir_Red"
    },
    {
      "x": 9,
      "y": 24,
      "z": 5,
      "name": "Plant_Leaves_Fir_Red"
    },
    {
      "x": 9,
      "y": 27,
      "z": 5,
      "name": "Plant_Leaves_Fir_Red"
    },
    {
      "x": 9,
      "y": 28,
      "z": 5,
      "name": "Plant_Leaves_Fir_Red"
    },
    {
      "x": 9,
      "y": 10,
      "z": 6,
      "name": "Wood_Fir_Trunk_Full"
    },
    {
      "x": 9,
      "y": 18,
      "z": 6,
      "name": "Plant_Leaves_Fir_Red"
    },
    {
      "x": 9,
      "y": 22,
      "z": 6,
      "name": "Plant_Leaves_Fir_Red"
    },
    {
      "x": 9,
      "y": 24,
      "z": 6,
      "name": "Plant_Leaves_Fir_Red"
    },
    {
      "x": 9,
      "y": 25,
      "z": 6,
      "name": "Plant_Leaves_Fir_Red"
    },
    {
      "x": 9,
      "y": 28,
      "z": 6,
      "name": "Plant_Leaves_Fir_Red"
    },
    {
      "x": 9,
      "y": 29,
      "z": 6,
      "name": "Plant_Leaves_Fir_Red"
    },
    {
      "x": 9,
      "y": 9,
      "z": 7,
      "name": "Wood_Fir_Trunk_Full"
    },
    {
      "x": 9,
      "y": 10,
      "z": 7,
      "name": "Wood_Fir_Trunk"
    },
    {
      "x": 9,
      "y": 11,
      "z": 7,
      "name": "Wood_Fir_Trunk"
    },
    {
      "x": 9,
      "y": 12,
      "z": 7,
      "name": "Wood_Fir_Trunk"
    },
    {
      "x": 9,
      "y": 13,
      "z": 7,
      "name": "Wood_Fir_Trunk"
    },
    {
      "x": 9,
      "y": 14,
      "z": 7,
      "name": "Wood_Fir_Trunk_Full"
    },
    {
      "x": 9,
      "y": 17,
      "z": 7,
      "name": "Wood_Fir_Branch_Long",
      "rotation": 5
    },
    {
      "x": 9,
      "y": 18,
      "z": 7,
      "name": "Plant_Leaves_Fir_Red"
    },
    {
      "x": 9,
      "y": 19,
      "z": 7,
      "name": "Plant_Leaves_Fir_Red"
    },
    {
      "x": 9,
      "y": 21,
      "z": 7,
      "name": "Wood_Fir_Branch_Long",
      "rotation": 5
    },
    {
      "x": 9,
      "y": 22,
      "z": 7,
      "name": "Plant_Leaves_Fir_Red"
    },
    {
      "x": 9,
      "y": 23,
      "z": 7,
      "name": "Plant_Leaves_Fir_Red"
    },
    {
      "x": 9,
      "y": 25,
      "z": 7,
      "name": "Wood_Fir_Branch_Long",
      "rotation": 5
    },
    {
      "x": 9,
      "y": 26,
      "z": 7,
      "name": "Plant_Leaves_Fir_Red"
    },
    {
      "x": 9,
      "y": 27,
      "z": 7,
      "name": "Wood_Fir_Branch_Short",
      "rotation": 1
    },
    {
      "x": 9,
      "y": 29,
      "z": 7,
      "name": "Plant_Leaves_Fir_Red"
    },
    {
      "x": 9,
      "y": 30,
      "z": 7,
      "name": "Plant_Leaves_Fir_Red"
    },
    {
      "x": 9,
      "y": 31,
      "z": 7,
      "name": "Plant_Leaves_Fir_Red"
    },
    {
      "x": 9,
      "y": 32,
      "z": 7,
      "name": "Plant_Leaves_Fir_Red"
    },
    {
      "x": 9,
      "y": 17,
      "z": 8,
      "name": "Plant_Leaves_Fir_Red"
    },
    {
      "x": 9,
      "y": 18,
      "z": 8,
      "name": "Plant_Leaves_Fir_Red"
    },
    {
      "x": 9,
      "y": 21,
      "z": 8,
      "name": "Plant_Leaves_Fir_Red"
    },
    {
      "x": 9,
      "y": 24,
      "z": 8,
      "name": "Plant_Leaves_Fir_Red"
    },
    {
      "x": 9,
      "y": 25,
      "z": 8,
      "name": "Plant_Leaves_Fir_Red"
    },
    {
      "x": 9,
      "y": 26,
      "z": 8,
      "name": "Plant_Leaves_Fir_Red"
    },
    {
      "x": 9,
      "y": 29,
      "z": 8,
      "name": "Plant_Leaves_Fir_Red"
    },
    {
      "x": 9,
      "y": 5,
      "z": 9,
      "name": "Wood_Fir_Roots"
    },
    {
      "x": 9,
      "y": 6,
      "z": 9,
      "name": "Wood_Fir_Trunk_Full"
    },
    {
      "x": 9,
      "y": 17,
      "z": 9,
      "name": "Plant_Leaves_Fir_Red"
    },
    {
      "x": 9,
      "y": 18,
      "z": 9,
      "name": "Plant_Leaves_Fir_Red"
    },
    {
      "x": 9,
      "y": 23,
      "z": 9,
      "name": "Plant_Leaves_Fir_Red"
    },
    {
      "x": 9,
      "y": 24,
      "z": 9,
      "name": "Plant_Leaves_Fir_Red"
    },
    {
      "x": 9,
      "y": 17,
      "z": 10,
      "name": "Plant_Leaves_Fir_Red"
    },
    {
      "x": 9,
      "y": 18,
      "z": 10,
      "name": "Plant_Leaves_Fir_Red"
    },
    {
      "x": 9,
      "y": 22,
      "z": 10,
      "name": "Plant_Leaves_Fir_Red"
    },
    {
      "x": 9,
      "y": 23,
      "z": 10,
      "name": "Plant_Leaves_Fir_Red"
    },
    {
      "x": 9,
      "y": 17,
      "z": 11,
      "name": "Plant_Leaves_Fir_Red"
    },
    {
      "x": 9,
      "y": 22,
      "z": 11,
      "name": "Plant_Leaves_Fir_Red"
    },
    {
      "x": 10,
      "y": 17,
      "z": 4,
      "name": "Plant_Leaves_Fir_Red"
    },
    {
      "x": 10,
      "y": 21,
      "z": 5,
      "name": "Plant_Leaves_Fir_Red"
    },
    {
      "x": 10,
      "y": 17,
      "z": 6,
      "name": "Plant_Leaves_Fir_Red"
    },
    {
      "x": 10,
      "y": 21,
      "z": 6,
      "name": "Plant_Leaves_Fir_Red"
    },
    {
      "x": 10,
      "y": 7,
      "z": 7,
      "name": "Wood_Fir_Roots"
    },
    {
      "x": 10,
      "y": 8,
      "z": 7,
      "name": "Wood_Fir_Trunk_Full"
    },
    {
      "x": 10,
      "y": 9,
      "z": 7,
      "name": "Wood_Fir_Trunk_Full"
    },
    {
      "x": 10,
      "y": 17,
      "z": 7,
      "name": "Wood_Fir_Branch_Long",
      "rotation": 5
    },
    {
      "x": 10,
      "y": 18,
      "z": 7,
      "name": "Plant_Leaves_Fir_Red"
    },
    {
      "x": 10,
      "y": 21,
      "z": 7,
      "name": "Plant_Leaves_Fir_Red"
    },
    {
      "x": 10,
      "y": 22,
      "z": 7,
      "name": "Plant_Leaves_Fir_Red"
    },
    {
      "x": 10,
      "y": 24,
      "z": 7,
      "name": "Plant_Leaves_Fir_Red"
    },
    {
      "x": 10,
      "y": 25,
      "z": 7,
      "name": "Plant_Leaves_Fir_Red"
    },
    {
      "x": 10,
      "y": 17,
      "z": 8,
      "name": "Plant_Leaves_Fir_Red"
    },
    {
      "x": 10,
      "y": 18,
      "z": 8,
      "name": "Plant_Leaves_Fir_Red"
    },
    {
      "x": 10,
      "y": 21,
      "z": 8,
      "name": "Plant_Leaves_Fir_Red"
    },
    {
      "x": 10,
      "y": 24,
      "z": 8,
      "name": "Plant_Leaves_Fir_Red"
    },
    {
      "x": 10,
      "y": 28,
      "z": 8,
      "name": "Plant_Leaves_Fir_Red"
    },
    {
      "x": 10,
      "y": 29,
      "z": 8,
      "name": "Plant_Leaves_Fir_Red"
    },
    {
      "x": 10,
      "y": 18,
      "z": 9,
      "name": "Plant_Leaves_Fir_Red"
    },
    {
      "x": 10,
      "y": 22,
      "z": 11,
      "name": "Plant_Leaves_Fir_Red"
    },
    {
      "x": 11,
      "y": 16,
      "z": 6,
      "name": "Plant_Leaves_Fir_Red"
    },
    {
      "x": 11,
      "y": 20,
      "z": 6,
      "name": "Plant_Leaves_Fir_Red"
    },
    {
      "x": 11,
      "y": 21,
      "z": 6,
      "name": "Plant_Leaves_Fir_Red"
    },
    {
      "x": 11,
      "y": 16,
      "z": 7,
      "name": "Plant_Leaves_Fir_Red"
    },
    {
      "x": 11,
      "y": 17,
      "z": 7,
      "name": "Plant_Leaves_Fir_Red"
    },
    {
      "x": 11,
      "y": 21,
      "z": 7,
      "name": "Plant_Leaves_Fir_Red"
    },
    {
      "x": 11,
      "y": 24,
      "z": 7,
      "name": "Plant_Leaves_Fir_Red"
    },
    {
      "x": 11,
      "y": 23,
      "z": 8,
      "name": "Plant_Leaves_Fir_Red"
    },
    {
      "x": 11,
      "y": 24,
      "z": 8,
      "name": "Plant_Leaves_Fir_Red"
    },
    {
      "x": 12,
      "y": 16,
      "z": 6,
      "name": "Plant_Leaves_Fir_Red"
    },
    {
      "x": 12,
      "y": 20,
      "z": 6,
      "name": "Plant_Leaves_Fir_Red"
    },
    {
      "x": 12,
      "y": 23,
      "z": 8,
      "name": "Plant_Leaves_Fir_Red"
    }
  ]
}