{
  "version": 8,
  "blockIdVersion": 8,
  "anchorX": 8,
  "anchorY": 12,
  "anchorZ": 6,
  "blocks": [
    {
      "x": 4,
      "y": 16,
      "z": 6,
      "name": "Plant_Leaves_Fir_Red"
    },
    {
      "x": 5,
      "y": 17,
      "z": 5,
      "name": "Plant_Leaves_Fir_Red"
    },
    {
      "x": 5,
      "y": 17,
      "z": 6,
      "name": "Plant_Leaves_Fir_Red"
    },
    {
      "x": 5,
      "y": 18,
      "z": 6,
      "name": "Plant_Leaves_Fir_Red"
    },
    {
      "x": 5,
      "y": 17,
      "z": 7,
      "name": "Plant_Leaves_Fir_Red"
    },
    {
      "x": 6,
      "y": 19,
      "z": 3,
      "name": "Plant_Leaves_Fir_Red"
    },
    {
      "x": 6,
      "y": 19,
      "z": 4,
      "name": "Plant_Leaves_Fir_Red"
    },
    {
      "x": 6,
      "y": 20,
      "z": 4,
      "name": "Plant_Leaves_Fir_Red"
    },
    {
      "x": 6,
      "y": 17,
      "z": 5,
      "name": "Plant_Leaves_Fir_Red"
    },
    {
      "x": 6,
      "y": 17,
      "z": 6,
      "name": "Wood_Fir_Branch_Long",
      "rotation": 5
    },
    {
      "x": 6,
      "y": 18,
      "z": 6,
      "name": "Plant_Leaves_Fir_Red"
    },
    {
      "x": 6,
      "y": 19,
      "z": 6,
      "name": "Plant_Leaves_Fir_Red"
    },
    {
      "x": 6,
      "y": 23,
      "z": 6,
      "name": "Plant_Leaves_Fir_Red"
    },
    {
      "x": 6,
      "y": 17,
      "z": 7,
      "name": "Plant_Leaves_Fir_Red"
    },
    {
      "x": 6,
      "y": 18,
      "z": 7,
      "name": "Plant_Leaves_Fir_Red"
    },
    {
      "x": 6,
      "y": 21,
      "z": 7,
      "name": "Plant_Leaves_Fir_Red"
    },
    {
      "x": 6,
      "y": 20,
      "z": 8,
      "name": "Plant_Leaves_Fir_Red"
    },
    {
      "x": 6,
      "y": 24,
      "z": 8,
      "name": "Plant_Leaves_Fir_Red"
    },
    {
      "x": 7,
      "y": 17,
      "z": 4,
      "name": "Plant_Leaves_Fir_Red"
    },
    {
      "x": 7,
      "y": 20,
      "z": 4,
      "name": "Plant_Leaves_Fir_Red"
    },
    {
      "x": 7,
      "y": 5,
      "z": 5,
      "name": "Wood_Fir_Roots"
    },
    {
      "x": 7,
      "y": 6,
      "z": 5,
      "name": "Wood_Fir_Trunk_Full"
    },
    {
      "x": 7,
      "y": 7,
      "z": 5,
      "name": "Wood_Fir_Trunk"
    },
    {
      "x": 7,
      "y": 8,
      "z": 5,
      "name": "Wood_Fir_Trunk"
    },
    {
      "x": 7,
      "y": 9,
      "z": 5,
      "name": "Wood_Fir_Trunk_Full"
    },
    {
      "x": 7,
      "y": 17,
      "z": 5,
      "name": "Plant_Leaves_Fir_Red"
    },
    {
      "x": 7,
      "y": 18,
      "z": 5,
      "name": "Plant_Leaves_Fir_Red"
    },
    {
      "x": 7,
      "y": 20,
      "z": 5,
      "name": "Plant_Leaves_Fir_Red"
    },
    {
      "x": 7,
      "y": 21,
      "z": 5,
      "name": "Plant_Leaves_Fir_Red"
    },
    {
      "x": 7,
      "y": 24,
      "z": 5,
      "name": "Plant_Leaves_Fir_Red"
    },
    {
      "x": 7,
      "y": 9,
      "z": 6,
      "name": "Wood_Fir_Trunk_Full"
    },
    {
      "x": 7,
      "y": 10,
      "z": 6,
      "name": "Wood_Fir_Trunk"
    },
    {
      "x": 7,
      "y": 11,
      "z": 6,
      "name": "Wood_Fir_Trunk"
    },
    {
      "x": 7,
      "y": 12,
      "z": 6,
      "name": "Wood_Fir_Trunk"
    },
    {
      "x": 7,
      "y": 13,
      "z": 6,
      "name": "Wood_Fir_Trunk"
    },
    {
      "x": 7,
      "y": 14,
      "z": 6,
      "name": "Wood_Fir_Trunk"
    },
    {
      "x": 7,
      "y": 15,
      "z": 6,
      "name": "Wood_Fir_Trunk"
    },
    {
      "x": 7,
      "y": 16,
      "z": 6,
      "name": "Wood_Fir_Trunk"
    },
    {
      "x": 7,
      "y": 17,
      "z": 6,
      "name": "Wood_Fir_Trunk"
    },
    {
      "x": 7,
      "y": 18,
      "z": 6,
      "name": "Wood_Fir_Trunk"
    },
    {
      "x": 7,
      "y": 19,
      "z": 6,
      "name": "Wood_Fir_Trunk_Full"
    },
    {
      "x": 7,
      "y": 21,
      "z": 6,
      "name": "Wood_Fir_Branch_Long",
      "rotation": 5
    },
    {
      "x": 7,
      "y": 22,
      "z": 6,
      "name": "Plant_Leaves_Fir_Red"
    },
    {
      "x": 7,
      "y": 23,
      "z": 6,
      "name": "Wood_Fir_Branch_Long",
      "rotation": 5
    },
    {
      "x": 7,
      "y": 24,
      "z": 6,
      "name": "Plant_Leaves_Fir_Red"
    },
    {
      "x": 7,
      "y": 25,
      "z": 6,
      "name": "Plant_Leaves_Fir_Red"
    },
    {
      "x": 7,
      "y": 26,
      "z": 6,
      "name": "Plant_Leaves_Fir_Red"
    },
    {
      "x": 7,
      "y": 10,
      "z": 7,
      "name": "Wood_Fir_Trunk_Full"
    },
    {
      "x": 7,
      "y": 11,
      "z": 7,
      "name": "Wood_Fir_Trunk"
    },
    {
      "x": 7,
      "y": 12,
      "z": 7,
      "name": "Wood_Fir_Trunk"
    },
    {
      "x": 7,
      "y": 13,
      "z": 7,
      "name": "Wood_Fir_Trunk_Full"
    },
    {
      "x": 7,
      "y": 18,
      "z": 7,
      "name": "Plant_Leaves_Fir_Red"
    },
    {
      "x": 7,
      "y": 20,
      "z": 7,
      "name": "Plant_Leaves_Fir_Red"
    },
    {
      "x": 7,
      "y": 21,
      "z": 7,
      "name": "Plant_Leaves_Fir_Red"
    },
    {
      "x": 7,
      "y": 25,
      "z": 7,
      "name": "Plant_Leaves_Fir_Red"
    },
    {
      "x": 7,
      "y": 7,
      "z": 8,
      "name": "Wood_Fir_Roots"
    },
    {
      "x": 7,
      "y": 8,
      "z": 8,
      "name": "Wood_Fir_Trunk_Full"
    },
    {
      "x": 7,
      "y": 17,
      "z": 8,
      "name": "Plant_Leaves_Fir_Red"
    },
    {
      "x": 7,
      "y": 18,
      "z": 8,
      "name": "Plant_Leaves_Fir_Red"
    },
    {
      "x": 7,
      "y": 20,
      "z": 8,
      "name": "Plant_Leaves_Fir_Red"
    },
    {
      "x": 7,
      "y": 24,
      "z": 8,
      "name": "Plant_Leaves_Fir_Red"
    },
    {
      "x": 7,
      "y": 25,
      "z": 8,
      "name": "Plant_Leaves_Fir_Red"
    },
    {
      "x": 8,
      "y": 16,
      "z": 2,
      "name": "Plant_Leaves_Fir_Red"
    },
    {
      "x": 8,
      "y": 16,
      "z": 3,
      "name": "Plant_Leaves_Fir_Red"
    },
    {
      "x": 8,
      "y": 17,
      "z": 3,
      "name": "Plant_Leaves_Fir_Red"
    },
    {
      "x": 8,
      "y": 22,
      "z": 3,
      "name": "Plant_Leaves_Fir_Red"
    },
    {
      "x": 8,
      "y": 23,
      "z": 3,
      "name": "Plant_Leaves_Fir_Red"
    },
    {
      "x": 8,
      "y": 16,
      "z": 4,
      "name": "Plant_Leaves_Fir_Red"
    },
    {
      "x": 8,
      "y": 17,
      "z": 4,
      "name": "Plant_Leaves_Fir_Red"
    },
    {
      "x": 8,
      "y": 18,
      "z": 4,
      "name": "Plant_Leaves_Fir_Red"
    },
    {
      "x": 8,
      "y": 20,
      "z": 4,
      "name": "Plant_Leaves_Fir_Red"
    },
    {
      "x": 8,
      "y": 23,
      "z": 4,
      "name": "Plant_Leaves_Fir_Red"
    },
    {
      "x": 8,
      "y": 24,
      "z": 4,
      "name": "Plant_Leaves_Fir_Red"
    },
    {
      "x": 8,
      "y": 8,
      "z": 5,
      "name": "Wood_Fir_Roots"
    },
    {
      "x": 8,
      "y": 9,
      "z": 5,
      "name": "Wood_Fir_Trunk_Full"
    },
    {
      "x": 8,
      "y": 10,
      "z": 5,
      "name": "Wood_Fir_Trunk"
    },
    {
      "x": 8,
      "y": 11,
      "z": 5,
      "name": "Wood_Fir_Trunk"
    },
    {
      "x": 8,
      "y": 12,
      "z": 5,
      "name": "Wood_Fir_Trunk"
    },
    {
      "x": 8,
      "y": 13,
      "z": 5,
      "name": "Wood_Fir_Trunk_Full"
    },
    {
      "x": 8,
      "y": 17,
      "z": 5,
      "name": "Wood_Fir_Branch_Long",
      "rotation": 4
    },
    {
      "x": 8,
      "y": 18,
      "z": 5,
      "name": "Plant_Leaves_Fir_Red"
    },
    {
      "x": 8,
      "y": 20,
      "z": 5,
      "name": "Wood_Fir_Branch_Long",
      "rotation": 4
    },
    {
      "x": 8,
      "y": 21,
      "z": 5,
      "name": "Plant_Leaves_Fir_Red"
    },
    {
      "x": 8,
      "y": 23,
      "z": 5,
      "name": "Wood_Fir_Branch_Long",
      "rotation": 4
    },
    {
      "x": 8,
      "y": 24,
      "z": 5,
      "name": "Plant_Leaves_Fir_Red"
    },
    {
      "x": 8,
      "y": 25,
      "z": 5,
      "name": "Plant_Leaves_Fir_Red"
    },
    {
      "x": 8,
      "y": 26,
      "z": 5,
      "name": "Plant_Leaves_Fir_Red"
    },
    {
      "x": 8,
      "y": 9,
      "z": 6,
      "name": "Wood_Fir_Trunk_Full"
    },
    {
      "x": 8,
      "y": 10,
      "z": 6,
      "name": "Wood_Fir_Trunk"
    },
    {
      "x": 8,
      "y": 11,
      "z": 6,
      "name": "Wood_Fir_Trunk"
    },
    {
      "x": 8,
      "y": 12,
      "z": 6,
      "name": "Wood_Fir_Trunk"
    },
    {
      "x": 8,
      "y": 13,
      "z": 6,
      "name": "Wood_Fir_Trunk"
    },
    {
      "x": 8,
      "y": 14,
      "z": 6,
      "name": "Wood_Fir_Trunk"
    },
    {
      "x": 8,
      "y": 15,
      "z": 6,
      "name": "Wood_Fir_Trunk"
    },
    {
      "x": 8,
      "y": 16,
      "z": 6,
      "name": "Wood_Fir_Trunk"
    },
    {
      "x": 8,
      "y": 17,
      "z": 6,
      "name": "Wood_Fir_Trunk"
    },
    {
      "x": 8,
      "y": 18,
      "z": 6,
      "name": "Wood_Fir_Trunk"
    },
    {
      "x": 8,
      "y": 19,
      "z": 6,
      "name": "Wood_Fir_Trunk"
    },
    {
      "x": 8,
      "y": 20,
      "z": 6,
      "name": "Wood_Fir_Trunk"
    },
    {
      "x": 8,
      "y": 21,
      "z": 6,
      "name": "Wood_Fir_Trunk"
    },
    {
      "x": 8,
      "y": 22,
      "z": 6,
      "name": "Wood_Fir_Trunk"
    },
    {
      "x": 8,
      "y": 23,
      "z": 6,
      "name": "Wood_Fir_Trunk"
    },
    {
      "x": 8,
      "y": 24,
      "z": 6,
      "name": "Wood_Fir_Trunk"
    },
    {
      "x": 8,
      "y": 25,
      "z": 6,
      "name": "Wood_Fir_Trunk"
    },
    {
      "x": 8,
      "y": 26,
      "z": 6,
      "name": "Wood_Fir_Trunk_Full"
    },
    {
      "x": 8,
      "y": 27,
      "z": 6,
      "name": "Plant_Leaves_Fir_Red"
    },
    {
      "x": 8,
      "y": 28,
      "z": 6,
      "name": "Plant_Leaves_Fir_Red"
    },
    {
      "x": 8,
      "y": 29,
      "z": 6,
      "name": "Plant_Leaves_Fir_Red"
    },
    {
      "x": 8,
      "y": 9,
      "z": 7,
      "name": "Wood_Fir_Trunk_Full"
    },
    {
      "x": 8,
      "y": 10,
      "z": 7,
      "name": "Wood_Fir_Trunk_Full"
    },
    {
      "x": 8,
      "y": 11,
      "z": 7,
      "name": "Wood_Fir_Trunk"
    },
    {
      "x": 8,
      "y": 12,
      "z": 7,
      "name": "Wood_Fir_Trunk"
    },
    {
      "x": 8,
      "y": 13,
      "z": 7,
      "name": "Wood_Fir_Trunk"
    },
    {
      "x": 8,
      "y": 14,
      "z": 7,
      "name": "Wood_Fir_Trunk"
    },
    {
      "x": 8,
      "y": 15,
      "z": 7,
      "name": "Wood_Fir_Trunk"
    },
    {
      "x": 8,
      "y": 16,
      "z": 7,
      "name": "Wood_Fir_Trunk"
    },
    {
      "x": 8,
      "y": 17,
      "z": 7,
      "name": "Wood_Fir_Trunk_Full"
    },
    {
      "x": 8,
      "y": 18,
      "z": 7,
      "name": "Plant_Leaves_Fir_Red"
    },
    {
      "x": 8,
      "y": 19,
      "z": 7,
      "name": "Plant_Leaves_Fir_Red"
    },
    {
      "x": 8,
      "y": 20,
      "z": 7,
      "name": "Wood_Fir_Branch_Long",
      "rotation": 4
    },
    {
      "x": 8,
      "y": 21,
      "z": 7,
      "name": "Plant_Leaves_Fir_Red"
    },
    {
      "x": 8,
      "y": 22,
      "z": 7,
      "name": "Plant_Leaves_Fir_Red"
    },
    {
      "x": 8,
      "y": 24,
      "z": 7,
      "name": "Wood_Fir_Branch_Long",
      "rotation": 4
    },
    {
      "x": 8,
      "y": 25,
      "z": 7,
      "name": "Plant_Leaves_Fir_Red"
    },
    {
      "x": 8,
      "y": 26,
      "z": 7,
      "name": "Plant_Leaves_Fir_Red"
    },
    {
      "x": 8,
      "y": 27,
      "z": 7,
      "name": "Plant_Leaves_Fir_Red"
    },
    {
      "x": 8,
      "y": 5,
      "z": 8,
      "name": "Wood_Fir_Roots"
    },
    {
      "x": 8,
      "y": 6,
      "z": 8,
      "name": "Wood_Fir_Trunk_Full"
    },
    {
      "x": 8,
      "y": 7,
      "z": 8,
      "name": "Wood_Fir_Trunk"
    },
    {
      "x": 8,
      "y": 8,
      "z": 8,
      "name": "Wood_Fir_Trunk"
    },
    {
      "x": 8,
      "y": 9,
      "z": 8,
      "name": "Wood_Fir_Trunk"
    },
    {
      "x": 8,
      "y": 10,
      "z": 8,
      "name": "Wood_Fir_Trunk_Full"
    },
    {
      "x": 8,
      "y": 17,
      "z": 8,
      "name": "Wood_Fir_Branch_Long",
      "rotation": 4
    },
    {
      "x": 8,
      "y": 18,
      "z": 8,
      "name": "Plant_Leaves_Fir_Red"
    },
    {
      "x": 8,
      "y": 24,
      "z": 8,
      "name": "Plant_Leaves_Fir_Red"
    },
    {
      "x": 8,
      "y": 16,
      "z": 9,
      "name": "Plant_Leaves_Fir_Red"
    },
    {
      "x": 8,
      "y": 17,
      "z": 9,
      "name": "Plant_Leaves_Fir_Red"
    },
    {
      "x": 8,
      "y": 16,
      "z": 10,
      "name": "Plant_Leaves_Fir_Red"
    },
    {
      "x": 9,
      "y": 17,
      "z": 4,
      "name": "Plant_Leaves_Fir_Red"
    },
    {
      "x": 9,
      "y": 10,
      "z": 5,
      "name": "Wood_Fir_Trunk_Full"
    },
    {
      "x": 9,
      "y": 11,
      "z": 5,
      "name": "Wood_Fir_Trunk_Full"
    },
    {
      "x": 9,
      "y": 17,
      "z": 5,
      "name": "Plant_Leaves_Fir_Red"
    },
    {
      "x": 9,
      "y": 20,
      "z": 5,
      "name": "Plant_Leaves_Fir_Red"
    },
    {
      "x": 9,
      "y": 21,
      "z": 5,
      "name": "Plant_Leaves_Fir_Red"
    },
    {
      "x": 9,
      "y": 4,
      "z": 6,
      "name": "Wood_Fir_Roots"
    },
    {
      "x": 9,
      "y": 5,
      "z": 6,
      "name": "Wood_Fir_Trunk_Full"
    },
    {
      "x": 9,
      "y": 6,
      "z": 6,
      "name": "Wood_Fir_Trunk"
    },
    {
      "x": 9,
      "y": 7,
      "z": 6,
      "name": "Wood_Fir_Trunk"
    },
    {
      "x": 9,
      "y": 8,
      "z": 6,
      "name": "Wood_Fir_Trunk"
    },
    {
      "x": 9,
      "y": 9,
      "z": 6,
      "name": "Wood_Fir_Trunk"
    },
    {
      "x": 9,
      "y": 10,
      "z": 6,
      "name": "Wood_Fir_Trunk"
    },
    {
      "x": 9,
      "y": 11,
      "z": 6,
      "name": "Wood_Fir_Trunk"
    },
    {
      "x": 9,
      "y": 12,
      "z": 6,
      "name": "Wood_Fir_Trunk"
    },
    {
      "x": 9,
      "y": 13,
      "z": 6,
      "name": "Wood_Fir_Trunk_Full"
    },
    {
      "x": 9,
      "y": 17,
      "z": 6,
      "name": "Wood_Fir_Branch_Long",
      "rotation": 5
    },
    {
      "x": 9,
      "y": 18,
      "z": 6,
      "name": "Plant_Leaves_Fir_Red"
    },
    {
      "x": 9,
      "y": 19,
      "z": 6,
      "name": "Plant_Leaves_Fir_Red"
    },
    {
      "x": 9,
      "y": 20,
      "z": 6,
      "name": "Wood_Fir_Branch_Long",
      "rotation": 5
    },
    {
      "x": 9,
      "y": 21,
      "z": 6,
      "name": "Plant_Leaves_Fir_Red"
    },
    {
      "x": 9,
      "y": 23,
      "z": 6,
      "name": "Wood_Fir_Branch_Long",
      "rotation": 5
    },
    {
      "x": 9,
      "y": 24,
      "z": 6,
      "name": "Plant_Leaves_Fir_Red"
    },
    {
      "x": 9,
      "y": 25,
      "z": 6,
      "name": "Plant_Leaves_Fir_Red"
    },
    {
      "x": 9,
      "y": 26,
      "z": 6,
      "name": "Plant_Leaves_Fir_Red"
    },
    {
      "x": 9,
      "y": 18,
      "z": 7,
      "name": "Plant_Leaves_Fir_Red"
    },
    {
      "x": 9,
      "y": 21,
      "z": 7,
      "name": "Plant_Leaves_Fir_Red"
    },
    {
      "x": 9,
      "y": 24,
      "z": 7,
      "name": "Plant_Leaves_Fir_Red"
    },
    {
      "x": 9,
      "y": 25,
      "z": 7,
      "name": "Plant_Leaves_Fir_Red"
    },
    {
      "x": 9,
      "y": 17,
      "z": 8,
      "name": "Plant_Leaves_Fir_Red"
    },
    {
      "x": 9,
      "y": 20,
      "z": 8,
      "name": "Plant_Leaves_Fir_Red"
    },
    {
      "x": 9,
      "y": 23,
      "z": 8,
      "name": "Plant_Leaves_Fir_Red"
    },
    {
      "x": 9,
      "y": 24,
      "z": 8,
      "name": "Plant_Leaves_Fir_Red"
    },
    {
      "x": 9,
      "y": 17,
      "z": 9,
      "name": "Plant_Leaves_Fir_Red"
    },
    {
      "x": 9,
      "y": 22,
      "z": 9,
      "name": "Plant_Leaves_Fir_Red"
    },
    {
      "x": 9,
      "y": 23,
      "z": 9,
      "name": "Plant_Leaves_Fir_Red"
    },
    {
      "x": 10,
      "y": 19,
      "z": 4,
      "name": "Plant_Leaves_Fir_Red"
    },
    {
      "x": 10,
      "y": 20,
      "z": 4,
      "name": "Plant_Leaves_Fir_Red"
    },
    {
      "x": 10,
      "y": 17,
      "z": 5,
      "name": "Plant_Leaves_Fir_Red"
    },
    {
      "x": 10,
      "y": 20,
      "z": 5,
      "name": "Plant_Leaves_Fir_Red"
    },
    {
      "x": 10,
      "y": 21,
      "z": 5,
      "name": "Plant_Leaves_Fir_Red"
    },
    {
      "x": 10,
      "y": 17,
      "z": 6,
      "name": "Wood_Fir_Branch_Long",
      "rotation": 5
    },
    {
      "x": 10,
      "y": 18,
      "z": 6,
      "name": "Plant_Leaves_Fir_Red"
    },
    {
      "x": 10,
      "y": 20,
      "z": 6,
      "name": "Plant_Leaves_Fir_Red"
    },
    {
      "x": 10,
      "y": 23,
      "z": 6,
      "name": "Plant_Leaves_Fir_Red"
    },
    {
      "x": 10,
      "y": 24,
      "z": 6,
      "name": "Plant_Leaves_Fir_Red"
    },
    {
      "x": 10,
      "y": 17,
      "z": 7,
      "name": "Plant_Leaves_Fir_Red"
    },
    {
      "x": 10,
      "y": 18,
      "z": 7,
      "name": "Plant_Leaves_Fir_Red"
    },
    {
      "x": 10,
      "y": 20,
      "z": 8,
      "name": "Plant_Leaves_Fir_Red"
    },
    {
      "x": 11,
      "y": 17,
      "z": 6,
      "name": "Plant_Leaves_Fir_Red"
    },
    {
      "x": 11,
      "y": 23,
      "z": 6,
      "name": "Plant_Leaves_Fir_Red"
    },
    {
      "x": 11,
      "y": 17,
      "z": 7,
      "name": "Plant_Leaves_Fir_Red"
    },
    {
      "x": 12,
      "y": 16,
      "z": 6,
      "name": "Plant_Leaves_Fir_Red"
    },
    {
      "x": 12,
      "y": 17,
      "z": 6,
      "name": "Plant_Leaves_Fir_Red"
    },
    {
      "x": 13,
      "y": 16,
      "z": 6,
      "name": "Plant_Leaves_Fir_Red"
    }
  ]
}