{
  "version": 8,
  "blockIdVersion": 8,
  "anchorX": 1,
  "anchorY": 61,
  "anchorZ": 21,
  "blocks": [
    {
      "x": -5,
      "y": 59,
      "z": 22,
      "name": "Soil_Dirt_Cold"
    },
    {
      "x": -5,
      "y": 60,
      "z": 22,
      "name": "Soil_Dirt_Cold"
    },
    {
      "x": -5,
      "y": 61,
      "z": 22,
      "name": "Soil_Dirt_Cold"
    },
    {
      "x": -5,
      "y": 62,
      "z": 22,
      "name": "Empty"
    },
    {
      "x": -5,
      "y": 63,
      "z": 22,
      "name": "Empty"
    },
    {
      "x": -5,
      "y": 64,
      "z": 22,
      "name": "Empty"
    },
    {
      "x": -5,
      "y": 59,
      "z": 23,
      "name": "Soil_Dirt_Cold"
    },
    {
      "x": -5,
      "y": 60,
      "z": 23,
      "name": "Soil_Dirt_Cold"
    },
    {
      "x": -5,
      "y": 61,
      "z": 23,
      "name": "Soil_Dirt_Cold"
    },
    {
      "x": -5,
      "y": 62,
      "z": 23,
      "name": "Empty"
    },
    {
      "x": -5,
      "y": 63,
      "z": 23,
      "name": "Empty"
    },
    {
      "x": -5,
      "y": 64,
      "z": 23,
      "name": "Empty"
    },
    {
      "x": -5,
      "y": 59,
      "z": 24,
      "name": "Soil_Dirt_Cold"
    },
    {
      "x": -5,
      "y": 60,
      "z": 24,
      "name": "Soil_Pebbles_Frozen"
    },
    {
      "x": -5,
      "y": 61,
      "z": 24,
      "name": "Soil_Pebbles_Frozen"
    },
    {
      "x": -5,
      "y": 62,
      "z": 24,
      "name": "Empty"
    },
    {
      "x": -5,
      "y": 63,
      "z": 24,
      "name": "Empty"
    },
    {
      "x": -5,
      "y": 64,
      "z": 24,
      "name": "Empty"
    },
    {
      "x": -5,
      "y": 60,
      "z": 25,
      "name": "Soil_Pebbles_Frozen"
    },
    {
      "x": -5,
      "y": 61,
      "z": 25,
      "name": "Soil_Pebbles_Frozen"
    },
    {
      "x": -5,
      "y": 62,
      "z": 25,
      "name": "Furniture_Crude_Brazier"
    },
    {
      "x": -5,
      "y": 63,
      "z": 25,
      "name": "Empty"
    },
    {
      "x": -4,
      "y": 64,
      "z": 20,
      "name": "Wood_Redwood_Trunk",
      "rotation": 5
    },
    {
      "x": -4,
      "y": 59,
      "z": 21,
      "name": "Soil_Dirt_Cold"
    },
    {
      "x": -4,
      "y": 60,
      "z": 21,
      "name": "Soil_Dirt_Cold"
    },
    {
      "x": -4,
      "y": 61,
      "z": 21,
      "name": "Soil_Dirt_Cold"
    },
    {
      "x": -4,
      "y": 62,
      "z": 21,
      "name": "Wood_Redwood_Branch_Long"
    },
    {
      "x": -4,
      "y": 63,
      "z": 21,
      "name": "Wood_Redwood_Branch_Long"
    },
    {
      "x": -4,
      "y": 64,
      "z": 21,
      "name": "*Wood_Deadwood_Roof_State_Definitions_Corner_Right",
      "rotation": 3
    },
    {
      "x": -4,
      "y": 59,
      "z": 22,
      "name": "Soil_Dirt_Cold"
    },
    {
      "x": -4,
      "y": 60,
      "z": 22,
      "name": "Soil_Dirt_Cold"
    },
    {
      "x": -4,
      "y": 61,
      "z": 22,
      "name": "Soil_Dirt_Cold"
    },
    {
      "x": -4,
      "y": 62,
      "z": 22,
      "name": "Empty"
    },
    {
      "x": -4,
      "y": 63,
      "z": 22,
      "name": "Empty"
    },
    {
      "x": -4,
      "y": 64,
      "z": 22,
      "name": "Wood_Deadwood_Roof",
      "rotation": 3
    },
    {
      "x": -4,
      "y": 59,
      "z": 23,
      "name": "Soil_Dirt_Cold"
    },
    {
      "x": -4,
      "y": 60,
      "z": 23,
      "name": "Soil_Dirt_Cold"
    },
    {
      "x": -4,
      "y": 61,
      "z": 23,
      "name": "Soil_Dirt_Cold"
    },
    {
      "x": -4,
      "y": 62,
      "z": 23,
      "name": "Empty"
    },
    {
      "x": -4,
      "y": 63,
      "z": 23,
      "name": "Empty"
    },
    {
      "x": -4,
      "y": 64,
      "z": 23,
      "name": "Wood_Deadwood_Roof",
      "rotation": 3
    },
    {
      "x": -4,
      "y": 67,
      "z": 23,
      "name": "Wood_Redwood_Trunk",
      "rotation": 5
    },
    {
      "x": -4,
      "y": 59,
      "z": 24,
      "name": "Soil_Dirt_Cold"
    },
    {
      "x": -4,
      "y": 60,
      "z": 24,
      "name": "Soil_Pebbles_Frozen"
    },
    {
      "x": -4,
      "y": 61,
      "z": 24,
      "name": "Soil_Pebbles_Frozen"
    },
    {
      "x": -4,
      "y": 62,
      "z": 24,
      "name": "Empty"
    },
    {
      "x": -4,
      "y": 63,
      "z": 24,
      "name": "Empty"
    },
    {
      "x": -4,
      "y": 64,
      "z": 24,
      "name": "Wood_Deadwood_Roof",
      "rotation": 3
    },
    {
      "x": -4,
      "y": 59,
      "z": 25,
      "name": "Soil_Dirt_Cold"
    },
    {
      "x": -4,
      "y": 60,
      "z": 25,
      "name": "Soil_Pebbles_Frozen"
    },
    {
      "x": -4,
      "y": 61,
      "z": 25,
      "name": "Soil_Pebbles_Frozen"
    },
    {
      "x": -4,
      "y": 62,
      "z": 25,
      "name": "Wood_Redwood_Branch_Long"
    },
    {
      "x": -4,
      "y": 63,
      "z": 25,
      "name": "Wood_Redwood_Branch_Long"
    },
    {
      "x": -4,
      "y": 64,
      "z": 25,
      "name": "Wood_Deadwood_Roof_Flat",
      "rotation": 1
    },
    {
      "x": -4,
      "y": 64,
      "z": 26,
      "name": "Wood_Redwood_Trunk",
      "rotation": 5
    },
    {
      "x": -3,
      "y": 64,
      "z": 14,
      "name": "Wood_Redwood_Trunk",
      "rotation": 4
    },
    {
      "x": -3,
      "y": 59,
      "z": 15,
      "name": "Soil_Dirt_Cold"
    },
    {
      "x": -3,
      "y": 60,
      "z": 15,
      "name": "Soil_Dirt_Cold"
    },
    {
      "x": -3,
      "y": 61,
      "z": 15,
      "name": "Soil_Dirt_Cold"
    },
    {
      "x": -3,
      "y": 64,
      "z": 15,
      "name": "Wood_Redwood_Trunk",
      "rotation": 4
    },
    {
      "x": -3,
      "y": 65,
      "z": 15,
      "name": "Wood_Deadwood_Roof",
      "rotation": 3
    },
    {
      "x": -3,
      "y": 59,
      "z": 16,
      "name": "Soil_Dirt_Cold"
    },
    {
      "x": -3,
      "y": 60,
      "z": 16,
      "name": "Soil_Dirt_Cold"
    },
    {
      "x": -3,
      "y": 61,
      "z": 16,
      "name": "Soil_Dirt_Cold"
    },
    {
      "x": -3,
      "y": 62,
      "z": 16,
      "name": "Rock_Shale_Brick_Half",
      "rotation": 7
    },
    {
      "x": -3,
      "y": 63,
      "z": 16,
      "name": "Rock_Shale_Brick_Half",
      "rotation": 7
    },
    {
      "x": -3,
      "y": 64,
      "z": 16,
      "name": "Wood_Redwood_Trunk",
      "rotation": 4
    },
    {
      "x": -3,
      "y": 65,
      "z": 16,
      "name": "Wood_Deadwood_Roof",
      "rotation": 3
    },
    {
      "x": -3,
      "y": 59,
      "z": 17,
      "name": "Soil_Dirt_Cold"
    },
    {
      "x": -3,
      "y": 60,
      "z": 17,
      "name": "Soil_Dirt_Cold"
    },
    {
      "x": -3,
      "y": 61,
      "z": 17,
      "name": "Soil_Dirt_Cold"
    },
    {
      "x": -3,
      "y": 62,
      "z": 17,
      "name": "Rock_Shale_Brick_Half",
      "rotation": 7
    },
    {
      "x": -3,
      "y": 63,
      "z": 17,
      "name": "Rock_Shale_Brick_Half",
      "rotation": 7
    },
    {
      "x": -3,
      "y": 64,
      "z": 17,
      "name": "Wood_Redwood_Trunk",
      "rotation": 4
    },
    {
      "x": -3,
      "y": 65,
      "z": 17,
      "name": "Wood_Deadwood_Roof",
      "rotation": 3
    },
    {
      "x": -3,
      "y": 59,
      "z": 18,
      "name": "Soil_Dirt_Cold"
    },
    {
      "x": -3,
      "y": 60,
      "z": 18,
      "name": "Soil_Dirt_Cold"
    },
    {
      "x": -3,
      "y": 61,
      "z": 18,
      "name": "Soil_Dirt_Cold"
    },
    {
      "x": -3,
      "y": 62,
      "z": 18,
      "name": "Rock_Shale_Brick"
    },
    {
      "x": -3,
      "y": 63,
      "z": 18,
      "name": "Rock_Shale_Brick_Half",
      "rotation": 7
    },
    {
      "x": -3,
      "y": 64,
      "z": 18,
      "name": "Wood_Redwood_Trunk",
      "rotation": 4
    },
    {
      "x": -3,
      "y": 65,
      "z": 18,
      "name": "Wood_Deadwood_Roof",
      "rotation": 3
    },
    {
      "x": -3,
      "y": 59,
      "z": 19,
      "name": "Soil_Dirt_Cold"
    },
    {
      "x": -3,
      "y": 60,
      "z": 19,
      "name": "Soil_Dirt_Cold"
    },
    {
      "x": -3,
      "y": 61,
      "z": 19,
      "name": "Soil_Dirt_Cold"
    },
    {
      "x": -3,
      "y": 62,
      "z": 19,
      "name": "Rock_Shale_Brick"
    },
    {
      "x": -3,
      "y": 63,
      "z": 19,
      "name": "Rock_Shale_Brick_Half",
      "rotation": 7
    },
    {
      "x": -3,
      "y": 64,
      "z": 19,
      "name": "Wood_Redwood_Trunk",
      "rotation": 4
    },
    {
      "x": -3,
      "y": 65,
      "z": 19,
      "name": "Wood_Deadwood_Roof",
      "rotation": 3
    },
    {
      "x": -3,
      "y": 59,
      "z": 20,
      "name": "Soil_Dirt_Cold"
    },
    {
      "x": -3,
      "y": 60,
      "z": 20,
      "name": "Soil_Dirt_Cold"
    },
    {
      "x": -3,
      "y": 61,
      "z": 20,
      "name": "Soil_Dirt_Cold"
    },
    {
      "x": -3,
      "y": 62,
      "z": 20,
      "name": "Rock_Shale_Brick_Half",
      "rotation": 7
    },
    {
      "x": -3,
      "y": 63,
      "z": 20,
      "name": "Rock_Shale_Brick_Half",
      "rotation": 7
    },
    {
      "x": -3,
      "y": 64,
      "z": 20,
      "name": "Wood_Redwood_Trunk",
      "rotation": 4
    },
    {
      "x": -3,
      "y": 65,
      "z": 20,
      "name": "*Wood_Deadwood_Roof_State_Definitions_Inverted_Corner_Right",
      "rotation": 3
    },
    {
      "x": -3,
      "y": 59,
      "z": 21,
      "name": "Soil_Dirt_Cold"
    },
    {
      "x": -3,
      "y": 60,
      "z": 21,
      "name": "Soil_Dirt_Cold"
    },
    {
      "x": -3,
      "y": 61,
      "z": 21,
      "name": "Soil_Dirt_Cold"
    },
    {
      "x": -3,
      "y": 62,
      "z": 21,
      "name": "Rock_Shale_Brick_Half",
      "rotation": 7
    },
    {
      "x": -3,
      "y": 63,
      "z": 21,
      "name": "Rock_Shale_Brick_Half",
      "rotation": 7
    },
    {
      "x": -3,
      "y": 64,
      "z": 21,
      "name": "Wood_Redwood_Trunk",
      "rotation": 4
    },
    {
      "x": -3,
      "y": 65,
      "z": 21,
      "name": "Wood_Redwood_Stairs",
      "rotation": 2
    },
    {
      "x": -3,
      "y": 59,
      "z": 22,
      "name": "Soil_Dirt_Cold"
    },
    {
      "x": -3,
      "y": 60,
      "z": 22,
      "name": "Soil_Dirt_Cold"
    },
    {
      "x": -3,
      "y": 61,
      "z": 22,
      "name": "Soil_Dirt_Cold"
    },
    {
      "x": -3,
      "y": 62,
      "z": 22,
      "name": "Rock_Shale"
    },
    {
      "x": -3,
      "y": 63,
      "z": 22,
      "name": "Rock_Shale_Brick"
    },
    {
      "x": -3,
      "y": 64,
      "z": 22,
      "name": "Wood_Redwood_Planks"
    },
    {
      "x": -3,
      "y": 65,
      "z": 22,
      "name": "Wood_Redwood_Stairs",
      "rotation": 10
    },
    {
      "x": -3,
      "y": 66,
      "z": 22,
      "name": "Wood_Redwood_Stairs",
      "rotation": 2
    },
    {
      "x": -3,
      "y": 67,
      "z": 22,
      "name": "Wood_Deadwood_Roof",
      "rotation": 2
    },
    {
      "x": -3,
      "y": 59,
      "z": 23,
      "name": "Soil_Dirt_Cold"
    },
    {
      "x": -3,
      "y": 60,
      "z": 23,
      "name": "Soil_Dirt_Cold"
    },
    {
      "x": -3,
      "y": 61,
      "z": 23,
      "name": "Soil_Dirt_Cold"
    },
    {
      "x": -3,
      "y": 62,
      "z": 23,
      "name": "Furniture_Lumberjack_Door",
      "rotation": 3
    },
    {
      "x": -3,
      "y": 63,
      "z": 23,
      "name": "Furniture_Lumberjack_Door",
      "filler": 1024,
      "rotation": 3
    },
    {
      "x": -3,
      "y": 64,
      "z": 23,
      "name": "Wood_Redwood_Planks"
    },
    {
      "x": -3,
      "y": 66,
      "z": 23,
      "name": "Wood_Redwood_Stairs",
      "rotation": 9
    },
    {
      "x": -3,
      "y": 67,
      "z": 23,
      "name": "Wood_Redwood_Trunk",
      "rotation": 5
    },
    {
      "x": -3,
      "y": 68,
      "z": 23,
      "name": "Wood_Deadwood_Roof_Flat"
    },
    {
      "x": -3,
      "y": 59,
      "z": 24,
      "name": "Soil_Dirt_Cold"
    },
    {
      "x": -3,
      "y": 60,
      "z": 24,
      "name": "Soil_Dirt_Cold"
    },
    {
      "x": -3,
      "y": 61,
      "z": 24,
      "name": "Soil_Dirt_Cold"
    },
    {
      "x": -3,
      "y": 62,
      "z": 24,
      "name": "Rock_Shale_Brick"
    },
    {
      "x": -3,
      "y": 63,
      "z": 24,
      "name": "Rock_Shale_Brick"
    },
    {
      "x": -3,
      "y": 64,
      "z": 24,
      "name": "Wood_Redwood_Planks"
    },
    {
      "x": -3,
      "y": 65,
      "z": 24,
      "name": "Wood_Redwood_Stairs",
      "rotation": 8
    },
    {
      "x": -3,
      "y": 66,
      "z": 24,
      "name": "Wood_Redwood_Stairs"
    },
    {
      "x": -3,
      "y": 59,
      "z": 25,
      "name": "Soil_Dirt_Cold"
    },
    {
      "x": -3,
      "y": 60,
      "z": 25,
      "name": "Soil_Dirt_Cold"
    },
    {
      "x": -3,
      "y": 61,
      "z": 25,
      "name": "Soil_Dirt_Cold"
    },
    {
      "x": -3,
      "y": 62,
      "z": 25,
      "name": "Rock_Shale_Brick_Half",
      "rotation": 7
    },
    {
      "x": -3,
      "y": 63,
      "z": 25,
      "name": "Rock_Shale_Brick_Half",
      "rotation": 7
    },
    {
      "x": -3,
      "y": 64,
      "z": 25,
      "name": "Wood_Redwood_Planks"
    },
    {
      "x": -3,
      "y": 65,
      "z": 25,
      "name": "Wood_Redwood_Stairs"
    },
    {
      "x": -3,
      "y": 59,
      "z": 26,
      "name": "Soil_Dirt_Cold"
    },
    {
      "x": -3,
      "y": 60,
      "z": 26,
      "name": "Soil_Dirt_Cold"
    },
    {
      "x": -3,
      "y": 61,
      "z": 26,
      "name": "Soil_Dirt_Cold"
    },
    {
      "x": -3,
      "y": 62,
      "z": 26,
      "name": "Rock_Shale_Brick_Half",
      "rotation": 7
    },
    {
      "x": -3,
      "y": 63,
      "z": 26,
      "name": "Rock_Shale_Brick_Half",
      "rotation": 7
    },
    {
      "x": -3,
      "y": 64,
      "z": 26,
      "name": "Wood_Redwood_Trunk",
      "rotation": 4
    },
    {
      "x": -3,
      "y": 65,
      "z": 26,
      "name": "*Wood_Deadwood_Roof_State_Definitions_Inverted_Corner_Right"
    },
    {
      "x": -3,
      "y": 59,
      "z": 27,
      "name": "Soil_Dirt_Cold"
    },
    {
      "x": -3,
      "y": 60,
      "z": 27,
      "name": "Soil_Dirt_Cold"
    },
    {
      "x": -3,
      "y": 61,
      "z": 27,
      "name": "Soil_Dirt_Cold"
    },
    {
      "x": -3,
      "y": 62,
      "z": 27,
      "name": "Rock_Shale_Brick_Half",
      "rotation": 7
    },
    {
      "x": -3,
      "y": 63,
      "z": 27,
      "name": "Rock_Shale_Brick_Half",
      "rotation": 7
    },
    {
      "x": -3,
      "y": 64,
      "z": 27,
      "name": "Wood_Redwood_Trunk",
      "rotation": 4
    },
    {
      "x": -3,
      "y": 65,
      "z": 27,
      "name": "Wood_Deadwood_Roof",
      "rotation": 3
    },
    {
      "x": -3,
      "y": 64,
      "z": 28,
      "name": "Wood_Redwood_Trunk",
      "rotation": 4
    },
    {
      "x": -3,
      "y": 65,
      "z": 28,
      "name": "Wood_Deadwood_Roof",
      "rotation": 3
    },
    {
      "x": -3,
      "y": 64,
      "z": 29,
      "name": "Wood_Redwood_Trunk",
      "rotation": 4
    },
    {
      "x": -2,
      "y": 59,
      "z": 15,
      "name": "Soil_Dirt_Cold"
    },
    {
      "x": -2,
      "y": 60,
      "z": 15,
      "name": "Soil_Dirt_Cold"
    },
    {
      "x": -2,
      "y": 61,
      "z": 15,
      "name": "Soil_Dirt_Cold"
    },
    {
      "x": -2,
      "y": 64,
      "z": 15,
      "name": "Wood_Redwood_Stairs",
      "rotation": 11
    },
    {
      "x": -2,
      "y": 65,
      "z": 15,
      "name": "Wood_Redwood_Stairs",
      "rotation": 3
    },
    {
      "x": -2,
      "y": 58,
      "z": 16,
      "name": "Soil_Dirt_Cold"
    },
    {
      "x": -2,
      "y": 59,
      "z": 16,
      "name": "Soil_Dirt_Cold"
    },
    {
      "x": -2,
      "y": 60,
      "z": 16,
      "name": "Soil_Dirt_Cold"
    },
    {
      "x": -2,
      "y": 61,
      "z": 16,
      "name": "Soil_Dirt_Cold"
    },
    {
      "x": -2,
      "y": 62,
      "z": 16,
      "name": "Rock_Shale"
    },
    {
      "x": -2,
      "y": 63,
      "z": 16,
      "name": "Rock_Shale"
    },
    {
      "x": -2,
      "y": 64,
      "z": 16,
      "name": "Wood_Redwood_Planks"
    },
    {
      "x": -2,
      "y": 65,
      "z": 16,
      "name": "Wood_Redwood_Planks"
    },
    {
      "x": -2,
      "y": 66,
      "z": 16,
      "name": "Wood_Deadwood_Roof",
      "rotation": 3
    },
    {
      "x": -2,
      "y": 58,
      "z": 17,
      "name": "Soil_Dirt_Cold"
    },
    {
      "x": -2,
      "y": 59,
      "z": 17,
      "name": "Soil_Dirt_Cold"
    },
    {
      "x": -2,
      "y": 60,
      "z": 17,
      "name": "Soil_Dirt_Cold"
    },
    {
      "x": -2,
      "y": 61,
      "z": 17,
      "name": "Soil_Dirt_Cold"
    },
    {
      "x": -2,
      "y": 62,
      "z": 17,
      "name": "Wood_Redwood_Trunk"
    },
    {
      "x": -2,
      "y": 63,
      "z": 17,
      "name": "Wood_Redwood_Trunk"
    },
    {
      "x": -2,
      "y": 64,
      "z": 17,
      "name": "Wood_Redwood_Trunk"
    },
    {
      "x": -2,
      "y": 65,
      "z": 17,
      "name": "Wood_Redwood_Planks"
    },
    {
      "x": -2,
      "y": 66,
      "z": 17,
      "name": "*Wood_Deadwood_Roof_State_Definitions_Corner_Right"
    },
    {
      "x": -2,
      "y": 58,
      "z": 18,
      "name": "Soil_Dirt_Cold"
    },
    {
      "x": -2,
      "y": 59,
      "z": 18,
      "name": "Soil_Dirt_Cold"
    },
    {
      "x": -2,
      "y": 60,
      "z": 18,
      "name": "Soil_Dirt_Cold"
    },
    {
      "x": -2,
      "y": 61,
      "z": 18,
      "name": "Soil_Dirt_Cold"
    },
    {
      "x": -2,
      "y": 62,
      "z": 18,
      "name": "Bench_Cooking",
      "components": {
        "Components": {
          "crafting": {
            "Position": {
              "X": -3,
              "Y": 1,
              "Z": -3
            },
            "TierLevel": 1,
            "UpgradeItems": []
          }
        }
      },
      "rotation": 1
    },
    {
      "x": -2,
      "y": 63,
      "z": 18,
      "name": "Bench_Cooking",
      "components": {
        "Components": {
          "crafting": {
            "Position": {
              "X": 30,
              "Y": 63,
              "Z": 18
            },
            "TierLevel": 1,
            "UpgradeItems": []
          }
        }
      },
      "filler": 1024,
      "rotation": 1
    },
    {
      "x": -2,
      "y": 64,
      "z": 18,
      "name": "Empty"
    },
    {
      "x": -2,
      "y": 65,
      "z": 18,
      "name": "Empty"
    },
    {
      "x": -2,
      "y": 66,
      "z": 18,
      "name": "Empty"
    },
    {
      "x": -2,
      "y": 58,
      "z": 19,
      "name": "Soil_Dirt_Cold"
    },
    {
      "x": -2,
      "y": 59,
      "z": 19,
      "name": "Soil_Dirt_Cold"
    },
    {
      "x": -2,
      "y": 60,
      "z": 19,
      "name": "Soil_Dirt_Cold"
    },
    {
      "x": -2,
      "y": 61,
      "z": 19,
      "name": "Soil_Dirt_Cold"
    },
    {
      "x": -2,
      "y": 62,
      "z": 19,
      "name": "Bench_Cooking",
      "components": {
        "Components": {
          "crafting": {
            "Position": {
              "X": 30,
              "Y": 62,
              "Z": 19
            },
            "TierLevel": 1,
            "UpgradeItems": []
          }
        }
      },
      "filler": 32,
      "rotation": 1
    },
    {
      "x": -2,
      "y": 63,
      "z": 19,
      "name": "Bench_Cooking",
      "components": {
        "Components": {
          "crafting": {
            "Position": {
              "X": 30,
              "Y": 63,
              "Z": 19
            },
            "TierLevel": 1,
            "UpgradeItems": []
          }
        }
      },
      "filler": 1056,
      "rotation": 1
    },
    {
      "x": -2,
      "y": 64,
      "z": 19,
      "name": "Empty"
    },
    {
      "x": -2,
      "y": 65,
      "z": 19,
      "name": "Wood_Redwood_Planks"
    },
    {
      "x": -2,
      "y": 66,
      "z": 19,
      "name": "*Wood_Deadwood_Roof_State_Definitions_Corner_Right",
      "rotation": 3
    },
    {
      "x": -2,
      "y": 58,
      "z": 20,
      "name": "Soil_Dirt_Cold"
    },
    {
      "x": -2,
      "y": 59,
      "z": 20,
      "name": "Soil_Dirt_Cold"
    },
    {
      "x": -2,
      "y": 60,
      "z": 20,
      "name": "Soil_Dirt_Cold"
    },
    {
      "x": -2,
      "y": 61,
      "z": 20,
      "name": "Soil_Dirt_Cold"
    },
    {
      "x": -2,
      "y": 62,
      "z": 20,
      "name": "Furniture_Lumberjack_Shelf",
      "rotation": 1
    },
    {
      "x": -2,
      "y": 63,
      "z": 20,
      "name": "Empty"
    },
    {
      "x": -2,
      "y": 64,
      "z": 20,
      "name": "Wood_Redwood_Trunk",
      "rotation": 5
    },
    {
      "x": -2,
      "y": 65,
      "z": 20,
      "name": "Wood_Redwood_Planks"
    },
    {
      "x": -2,
      "y": 66,
      "z": 20,
      "name": "Wood_Deadwood_Roof",
      "rotation": 3
    },
    {
      "x": -2,
      "y": 58,
      "z": 21,
      "name": "Soil_Dirt_Cold"
    },
    {
      "x": -2,
      "y": 59,
      "z": 21,
      "name": "Soil_Dirt_Cold"
    },
    {
      "x": -2,
      "y": 60,
      "z": 21,
      "name": "Soil_Dirt_Cold"
    },
    {
      "x": -2,
      "y": 61,
      "z": 21,
      "name": "Soil_Dirt_Cold"
    },
    {
      "x": -2,
      "y": 62,
      "z": 21,
      "name": "Furniture_Lumberjack_Shelf",
      "rotation": 1
    },
    {
      "x": -2,
      "y": 63,
      "z": 21,
      "name": "Furniture_Lumberjack_Shelf",
      "rotation": 1
    },
    {
      "x": -2,
      "y": 64,
      "z": 21,
      "name": "Wood_Redwood_Planks_Half",
      "rotation": 8
    },
    {
      "x": -2,
      "y": 65,
      "z": 21,
      "name": "Wood_Redwood_Planks"
    },
    {
      "x": -2,
      "y": 66,
      "z": 21,
      "name": "*Wood_Deadwood_Roof_State_Definitions_Inverted_Corner_Right",
      "rotation": 3
    },
    {
      "x": -2,
      "y": 58,
      "z": 22,
      "name": "Soil_Dirt_Cold"
    },
    {
      "x": -2,
      "y": 59,
      "z": 22,
      "name": "Soil_Dirt_Cold"
    },
    {
      "x": -2,
      "y": 60,
      "z": 22,
      "name": "Soil_Dirt_Cold"
    },
    {
      "x": -2,
      "y": 61,
      "z": 22,
      "name": "Soil_Dirt_Cold"
    },
    {
      "x": -2,
      "y": 62,
      "z": 22,
      "name": "Wood_Softwood_Fence"
    },
    {
      "x": -2,
      "y": 63,
      "z": 22,
      "name": "Wood_Softwood_Fence"
    },
    {
      "x": -2,
      "y": 64,
      "z": 22,
      "name": "Wood_Redwood_Planks"
    },
    {
      "x": -2,
      "y": 65,
      "z": 22,
      "name": "Wood_Redwood_Planks"
    },
    {
      "x": -2,
      "y": 66,
      "z": 22,
      "name": "Wood_Redwood_Trunk",
      "rotation": 4
    },
    {
      "x": -2,
      "y": 67,
      "z": 22,
      "name": "Wood_Deadwood_Roof",
      "rotation": 2
    },
    {
      "x": -2,
      "y": 58,
      "z": 23,
      "name": "Soil_Dirt_Cold"
    },
    {
      "x": -2,
      "y": 59,
      "z": 23,
      "name": "Soil_Dirt_Cold"
    },
    {
      "x": -2,
      "y": 60,
      "z": 23,
      "name": "Soil_Dirt_Cold"
    },
    {
      "x": -2,
      "y": 61,
      "z": 23,
      "name": "Soil_Dirt_Cold"
    },
    {
      "x": -2,
      "y": 62,
      "z": 23,
      "name": "Empty"
    },
    {
      "x": -2,
      "y": 63,
      "z": 23,
      "name": "Empty"
    },
    {
      "x": -2,
      "y": 64,
      "z": 23,
      "name": "Wood_Redwood_Planks_Half",
      "rotation": 8
    },
    {
      "x": -2,
      "y": 65,
      "z": 23,
      "name": "Wood_Redwood_Planks"
    },
    {
      "x": -2,
      "y": 66,
      "z": 23,
      "name": "Wood_Redwood_Trunk",
      "rotation": 4
    },
    {
      "x": -2,
      "y": 67,
      "z": 23,
      "name": "Wood_Redwood_Trunk",
      "rotation": 5
    },
    {
      "x": -2,
      "y": 68,
      "z": 23,
      "name": "Wood_Deadwood_Roof_Flat"
    },
    {
      "x": -2,
      "y": 58,
      "z": 24,
      "name": "Soil_Dirt_Cold"
    },
    {
      "x": -2,
      "y": 59,
      "z": 24,
      "name": "Soil_Dirt_Cold"
    },
    {
      "x": -2,
      "y": 60,
      "z": 24,
      "name": "Soil_Dirt_Cold"
    },
    {
      "x": -2,
      "y": 61,
      "z": 24,
      "name": "Soil_Dirt_Cold"
    },
    {
      "x": -2,
      "y": 62,
      "z": 24,
      "name": "Empty"
    },
    {
      "x": -2,
      "y": 63,
      "z": 24,
      "name": "Empty"
    },
    {
      "x": -2,
      "y": 64,
      "z": 24,
      "name": "Wood_Redwood_Planks_Half",
      "rotation": 8
    },
    {
      "x": -2,
      "y": 65,
      "z": 24,
      "name": "Wood_Redwood_Planks"
    },
    {
      "x": -2,
      "y": 66,
      "z": 24,
      "name": "Wood_Redwood_Trunk",
      "rotation": 4
    },
    {
      "x": -2,
      "y": 67,
      "z": 24,
      "name": "Wood_Deadwood_Roof"
    },
    {
      "x": -2,
      "y": 58,
      "z": 25,
      "name": "Soil_Dirt_Cold"
    },
    {
      "x": -2,
      "y": 59,
      "z": 25,
      "name": "Soil_Dirt_Cold"
    },
    {
      "x": -2,
      "y": 60,
      "z": 25,
      "name": "Soil_Dirt_Cold"
    },
    {
      "x": -2,
      "y": 61,
      "z": 25,
      "name": "Soil_Dirt_Cold"
    },
    {
      "x": -2,
      "y": 62,
      "z": 25,
      "name": "Furniture_Lumberjack_Table"
    },
    {
      "x": -2,
      "y": 63,
      "z": 25,
      "name": "Empty"
    },
    {
      "x": -2,
      "y": 64,
      "z": 25,
      "name": "Wood_Redwood_Planks_Half",
      "rotation": 8
    },
    {
      "x": -2,
      "y": 65,
      "z": 25,
      "name": "Wood_Redwood_Planks"
    },
    {
      "x": -2,
      "y": 66,
      "z": 25,
      "name": "*Wood_Deadwood_Roof_State_Definitions_Inverted_Corner_Right"
    },
    {
      "x": -2,
      "y": 58,
      "z": 26,
      "name": "Soil_Dirt_Cold"
    },
    {
      "x": -2,
      "y": 59,
      "z": 26,
      "name": "Soil_Dirt_Cold"
    },
    {
      "x": -2,
      "y": 60,
      "z": 26,
      "name": "Soil_Dirt_Cold"
    },
    {
      "x": -2,
      "y": 61,
      "z": 26,
      "name": "Soil_Dirt_Cold"
    },
    {
      "x": -2,
      "y": 62,
      "z": 26,
      "name": "Furniture_Lumberjack_Table",
      "filler": 32
    },
    {
      "x": -2,
      "y": 63,
      "z": 26,
      "name": "Empty"
    },
    {
      "x": -2,
      "y": 64,
      "z": 26,
      "name": "Wood_Redwood_Planks_Half",
      "rotation": 8
    },
    {
      "x": -2,
      "y": 65,
      "z": 26,
      "name": "Wood_Redwood_Planks"
    },
    {
      "x": -2,
      "y": 66,
      "z": 26,
      "name": "Wood_Deadwood_Roof",
      "rotation": 3
    },
    {
      "x": -2,
      "y": 59,
      "z": 27,
      "name": "Soil_Dirt_Cold"
    },
    {
      "x": -2,
      "y": 60,
      "z": 27,
      "name": "Soil_Dirt_Cold"
    },
    {
      "x": -2,
      "y": 61,
      "z": 27,
      "name": "Soil_Dirt_Cold"
    },
    {
      "x": -2,
      "y": 62,
      "z": 27,
      "name": "Rock_Shale"
    },
    {
      "x": -2,
      "y": 63,
      "z": 27,
      "name": "Rock_Shale"
    },
    {
      "x": -2,
      "y": 64,
      "z": 27,
      "name": "Wood_Redwood_Planks"
    },
    {
      "x": -2,
      "y": 65,
      "z": 27,
      "name": "Wood_Redwood_Planks"
    },
    {
      "x": -2,
      "y": 66,
      "z": 27,
      "name": "Wood_Deadwood_Roof",
      "rotation": 3
    },
    {
      "x": -2,
      "y": 64,
      "z": 28,
      "name": "Wood_Redwood_Stairs",
      "rotation": 11
    },
    {
      "x": -2,
      "y": 65,
      "z": 28,
      "name": "Wood_Redwood_Planks"
    },
    {
      "x": -2,
      "y": 66,
      "z": 28,
      "name": "Wood_Deadwood_Roof",
      "rotation": 3
    },
    {
      "x": -1,
      "y": 59,
      "z": 15,
      "name": "Soil_Dirt_Cold"
    },
    {
      "x": -1,
      "y": 60,
      "z": 15,
      "name": "Soil_Dirt_Cold"
    },
    {
      "x": -1,
      "y": 61,
      "z": 15,
      "name": "Soil_Dirt_Cold"
    },
    {
      "x": -1,
      "y": 64,
      "z": 15,
      "name": "Wood_Redwood_Planks_Half",
      "rotation": 6
    },
    {
      "x": -1,
      "y": 65,
      "z": 15,
      "name": "Wood_Redwood_Stairs",
      "rotation": 11
    },
    {
      "x": -1,
      "y": 66,
      "z": 15,
      "name": "Wood_Redwood_Stairs",
      "rotation": 3
    },
    {
      "x": -1,
      "y": 58,
      "z": 16,
      "name": "Soil_Dirt_Cold"
    },
    {
      "x": -1,
      "y": 59,
      "z": 16,
      "name": "Soil_Dirt_Cold"
    },
    {
      "x": -1,
      "y": 60,
      "z": 16,
      "name": "Soil_Dirt_Cold"
    },
    {
      "x": -1,
      "y": 61,
      "z": 16,
      "name": "Soil_Dirt_Cold"
    },
    {
      "x": -1,
      "y": 62,
      "z": 16,
      "name": "Rock_Shale"
    },
    {
      "x": -1,
      "y": 63,
      "z": 16,
      "name": "Rock_Shale_Brick"
    },
    {
      "x": -1,
      "y": 64,
      "z": 16,
      "name": "Wood_Redwood_Planks"
    },
    {
      "x": -1,
      "y": 65,
      "z": 16,
      "name": "Wood_Redwood_Trunk",
      "rotation": 5
    },
    {
      "x": -1,
      "y": 66,
      "z": 16,
      "name": "Wood_Redwood_Planks"
    },
    {
      "x": -1,
      "y": 67,
      "z": 16,
      "name": "Wood_Deadwood_Roof",
      "rotation": 3
    },
    {
      "x": -1,
      "y": 58,
      "z": 17,
      "name": "Soil_Dirt_Cold"
    },
    {
      "x": -1,
      "y": 59,
      "z": 17,
      "name": "Soil_Dirt_Cold"
    },
    {
      "x": -1,
      "y": 60,
      "z": 17,
      "name": "Soil_Dirt_Cold"
    },
    {
      "x": -1,
      "y": 61,
      "z": 17,
      "name": "Soil_Dirt_Cold"
    },
    {
      "x": -1,
      "y": 62,
      "z": 17,
      "name": "Furniture_Faun_Stool"
    },
    {
      "x": -1,
      "y": 63,
      "z": 17,
      "name": "Empty"
    },
    {
      "x": -1,
      "y": 64,
      "z": 17,
      "name": "Furniture_Lumberjack_Platform",
      "rotation": 1
    },
    {
      "x": -1,
      "y": 65,
      "z": 17,
      "name": "Wood_Redwood_Planks_Half",
      "rotation": 5
    },
    {
      "x": -1,
      "y": 66,
      "z": 17,
      "name": "Wood_Redwood_Planks"
    },
    {
      "x": -1,
      "y": 67,
      "z": 17,
      "name": "Wood_Deadwood_Roof",
      "rotation": 3
    },
    {
      "x": -1,
      "y": 58,
      "z": 18,
      "name": "Soil_Dirt_Cold"
    },
    {
      "x": -1,
      "y": 59,
      "z": 18,
      "name": "Soil_Dirt_Cold"
    },
    {
      "x": -1,
      "y": 60,
      "z": 18,
      "name": "Soil_Dirt_Cold"
    },
    {
      "x": -1,
      "y": 61,
      "z": 18,
      "name": "Soil_Dirt_Cold"
    },
    {
      "x": -1,
      "y": 62,
      "z": 18,
      "name": "Empty"
    },
    {
      "x": -1,
      "y": 63,
      "z": 18,
      "name": "Empty"
    },
    {
      "x": -1,
      "y": 64,
      "z": 18,
      "name": "Furniture_Lumberjack_Platform",
      "rotation": 1
    },
    {
      "x": -1,
      "y": 65,
      "z": 18,
      "name": "Wood_Redwood_Planks_Half",
      "rotation": 5
    },
    {
      "x": -1,
      "y": 66,
      "z": 18,
      "name": "Wood_Redwood_Planks"
    },
    {
      "x": -1,
      "y": 67,
      "z": 18,
      "name": "Wood_Deadwood_Roof",
      "rotation": 3
    },
    {
      "x": -1,
      "y": 58,
      "z": 19,
      "name": "Soil_Dirt_Cold"
    },
    {
      "x": -1,
      "y": 59,
      "z": 19,
      "name": "Soil_Dirt_Cold"
    },
    {
      "x": -1,
      "y": 60,
      "z": 19,
      "name": "Soil_Dirt_Cold"
    },
    {
      "x": -1,
      "y": 61,
      "z": 19,
      "name": "Soil_Dirt_Cold"
    },
    {
      "x": -1,
      "y": 62,
      "z": 19,
      "name": "Empty"
    },
    {
      "x": -1,
      "y": 63,
      "z": 19,
      "name": "Empty"
    },
    {
      "x": -1,
      "y": 64,
      "z": 19,
      "name": "Furniture_Lumberjack_Platform",
      "rotation": 1
    },
    {
      "x": -1,
      "y": 65,
      "z": 19,
      "name": "Wood_Redwood_Planks_Half",
      "rotation": 5
    },
    {
      "x": -1,
      "y": 66,
      "z": 19,
      "name": "Wood_Redwood_Planks"
    },
    {
      "x": -1,
      "y": 67,
      "z": 19,
      "name": "Wood_Deadwood_Roof",
      "rotation": 3
    },
    {
      "x": -1,
      "y": 58,
      "z": 20,
      "name": "Soil_Dirt_Cold"
    },
    {
      "x": -1,
      "y": 59,
      "z": 20,
      "name": "Soil_Dirt_Cold"
    },
    {
      "x": -1,
      "y": 60,
      "z": 20,
      "name": "Soil_Dirt_Cold"
    },
    {
      "x": -1,
      "y": 61,
      "z": 20,
      "name": "Soil_Dirt_Cold"
    },
    {
      "x": -1,
      "y": 62,
      "z": 20,
      "name": "Empty"
    },
    {
      "x": -1,
      "y": 63,
      "z": 20,
      "name": "Empty"
    },
    {
      "x": -1,
      "y": 64,
      "z": 20,
      "name": "Wood_Redwood_Trunk",
      "rotation": 5
    },
    {
      "x": -1,
      "y": 65,
      "z": 20,
      "name": "Furniture_Village_Crate"
    },
    {
      "x": -1,
      "y": 66,
      "z": 20,
      "name": "Wood_Redwood_Planks"
    },
    {
      "x": -1,
      "y": 67,
      "z": 20,
      "name": "Wood_Deadwood_Roof",
      "rotation": 3
    },
    {
      "x": -1,
      "y": 58,
      "z": 21,
      "name": "Soil_Dirt_Cold"
    },
    {
      "x": -1,
      "y": 59,
      "z": 21,
      "name": "Soil_Dirt_Cold"
    },
    {
      "x": -1,
      "y": 60,
      "z": 21,
      "name": "Soil_Dirt_Cold"
    },
    {
      "x": -1,
      "y": 61,
      "z": 21,
      "name": "Soil_Dirt_Cold"
    },
    {
      "x": -1,
      "y": 62,
      "z": 21,
      "name": "Empty"
    },
    {
      "x": -1,
      "y": 63,
      "z": 21,
      "name": "Empty"
    },
    {
      "x": -1,
      "y": 64,
      "z": 21,
      "name": "Wood_Redwood_Planks_Half",
      "rotation": 8
    },
    {
      "x": -1,
      "y": 65,
      "z": 21,
      "name": "Furniture_Village_Crate"
    },
    {
      "x": -1,
      "y": 66,
      "z": 21,
      "name": "Wood_Redwood_Planks"
    },
    {
      "x": -1,
      "y": 67,
      "z": 21,
      "name": "Wood_Deadwood_Roof",
      "rotation": 3
    },
    {
      "x": -1,
      "y": 58,
      "z": 22,
      "name": "Soil_Dirt_Cold"
    },
    {
      "x": -1,
      "y": 59,
      "z": 22,
      "name": "Soil_Dirt_Cold"
    },
    {
      "x": -1,
      "y": 60,
      "z": 22,
      "name": "Soil_Dirt_Cold"
    },
    {
      "x": -1,
      "y": 61,
      "z": 22,
      "name": "Soil_Dirt_Cold"
    },
    {
      "x": -1,
      "y": 62,
      "z": 22,
      "name": "Empty"
    },
    {
      "x": -1,
      "y": 63,
      "z": 22,
      "name": "Empty"
    },
    {
      "x": -1,
      "y": 64,
      "z": 22,
      "name": "Wood_Redwood_Planks_Half",
      "rotation": 8
    },
    {
      "x": -1,
      "y": 65,
      "z": 22,
      "name": "Empty"
    },
    {
      "x": -1,
      "y": 66,
      "z": 22,
      "name": "Wood_Redwood_Planks"
    },
    {
      "x": -1,
      "y": 67,
      "z": 22,
      "name": "*Wood_Deadwood_Roof_State_Definitions_Inverted_Corner_Right",
      "rotation": 3
    },
    {
      "x": -1,
      "y": 58,
      "z": 23,
      "name": "Soil_Dirt_Cold"
    },
    {
      "x": -1,
      "y": 59,
      "z": 23,
      "name": "Soil_Dirt_Cold"
    },
    {
      "x": -1,
      "y": 60,
      "z": 23,
      "name": "Soil_Dirt_Cold"
    },
    {
      "x": -1,
      "y": 61,
      "z": 23,
      "name": "Soil_Dirt_Cold"
    },
    {
      "x": -1,
      "y": 62,
      "z": 23,
      "name": "Empty"
    },
    {
      "x": -1,
      "y": 63,
      "z": 23,
      "name": "Empty"
    },
    {
      "x": -1,
      "y": 64,
      "z": 23,
      "name": "Wood_Redwood_Planks_Half",
      "rotation": 8
    },
    {
      "x": -1,
      "y": 65,
      "z": 23,
      "name": "Furniture_Ancient_Barrel"
    },
    {
      "x": -1,
      "y": 66,
      "z": 23,
      "name": "Wood_Redwood_Planks"
    },
    {
      "x": -1,
      "y": 67,
      "z": 23,
      "name": "Wood_Redwood_Trunk",
      "rotation": 5
    },
    {
      "x": -1,
      "y": 68,
      "z": 23,
      "name": "Wood_Deadwood_Roof_Flat"
    },
    {
      "x": -1,
      "y": 58,
      "z": 24,
      "name": "Soil_Dirt_Cold"
    },
    {
      "x": -1,
      "y": 59,
      "z": 24,
      "name": "Soil_Dirt_Cold"
    },
    {
      "x": -1,
      "y": 60,
      "z": 24,
      "name": "Soil_Dirt_Cold"
    },
    {
      "x": -1,
      "y": 61,
      "z": 24,
      "name": "Soil_Dirt_Cold"
    },
    {
      "x": -1,
      "y": 62,
      "z": 24,
      "name": "Empty"
    },
    {
      "x": -1,
      "y": 63,
      "z": 24,
      "name": "Empty"
    },
    {
      "x": -1,
      "y": 64,
      "z": 24,
      "name": "Wood_Redwood_Planks_Half",
      "rotation": 8
    },
    {
      "x": -1,
      "y": 65,
      "z": 24,
      "name": "Empty"
    },
    {
      "x": -1,
      "y": 66,
      "z": 24,
      "name": "Wood_Redwood_Planks"
    },
    {
      "x": -1,
      "y": 67,
      "z": 24,
      "name": "*Wood_Deadwood_Roof_State_Definitions_Inverted_Corner_Right"
    },
    {
      "x": -1,
      "y": 58,
      "z": 25,
      "name": "Soil_Dirt_Cold"
    },
    {
      "x": -1,
      "y": 59,
      "z": 25,
      "name": "Soil_Dirt_Cold"
    },
    {
      "x": -1,
      "y": 60,
      "z": 25,
      "name": "Soil_Dirt_Cold"
    },
    {
      "x": -1,
      "y": 61,
      "z": 25,
      "name": "Soil_Dirt_Cold"
    },
    {
      "x": -1,
      "y": 62,
      "z": 25,
      "name": "Furniture_Lumberjack_Table",
      "filler": 1
    },
    {
      "x": -1,
      "y": 63,
      "z": 25,
      "name": "Furniture_Crude_Candle"
    },
    {
      "x": -1,
      "y": 64,
      "z": 25,
      "name": "Wood_Redwood_Planks_Half",
      "rotation": 8
    },
    {
      "x": -1,
      "y": 65,
      "z": 25,
      "name": "Furniture_Village_Crate"
    },
    {
      "x": -1,
      "y": 66,
      "z": 25,
      "name": "Wood_Redwood_Planks"
    },
    {
      "x": -1,
      "y": 67,
      "z": 25,
      "name": "Wood_Deadwood_Roof",
      "rotation": 3
    },
    {
      "x": -1,
      "y": 58,
      "z": 26,
      "name": "Soil_Dirt_Cold"
    },
    {
      "x": -1,
      "y": 59,
      "z": 26,
      "name": "Soil_Dirt_Cold"
    },
    {
      "x": -1,
      "y": 60,
      "z": 26,
      "name": "Soil_Dirt_Cold"
    },
    {
      "x": -1,
      "y": 61,
      "z": 26,
      "name": "Soil_Dirt_Cold"
    },
    {
      "x": -1,
      "y": 62,
      "z": 26,
      "name": "Furniture_Lumberjack_Table",
      "filler": 33
    },
    {
      "x": -1,
      "y": 63,
      "z": 26,
      "name": "Empty"
    },
    {
      "x": -1,
      "y": 64,
      "z": 26,
      "name": "Wood_Redwood_Planks_Half",
      "rotation": 8
    },
    {
      "x": -1,
      "y": 65,
      "z": 26,
      "name": "Furniture_Village_Crate"
    },
    {
      "x": -1,
      "y": 66,
      "z": 26,
      "name": "Wood_Redwood_Planks"
    },
    {
      "x": -1,
      "y": 67,
      "z": 26,
      "name": "Wood_Deadwood_Roof",
      "rotation": 3
    },
    {
      "x": -1,
      "y": 59,
      "z": 27,
      "name": "Soil_Dirt_Cold"
    },
    {
      "x": -1,
      "y": 60,
      "z": 27,
      "name": "Soil_Dirt_Cold"
    },
    {
      "x": -1,
      "y": 61,
      "z": 27,
      "name": "Soil_Dirt_Cold"
    },
    {
      "x": -1,
      "y": 62,
      "z": 27,
      "name": "Rock_Shale"
    },
    {
      "x": -1,
      "y": 63,
      "z": 27,
      "name": "Rock_Shale_Brick"
    },
    {
      "x": -1,
      "y": 64,
      "z": 27,
      "name": "Wood_Redwood_Planks"
    },
    {
      "x": -1,
      "y": 65,
      "z": 27,
      "name": "Wood_Redwood_Trunk",
      "rotation": 5
    },
    {
      "x": -1,
      "y": 66,
      "z": 27,
      "name": "Wood_Redwood_Planks"
    },
    {
      "x": -1,
      "y": 67,
      "z": 27,
      "name": "Wood_Deadwood_Roof",
      "rotation": 3
    },
    {
      "x": -1,
      "y": 65,
      "z": 28,
      "name": "Wood_Redwood_Stairs",
      "rotation": 11
    },
    {
      "x": -1,
      "y": 66,
      "z": 28,
      "name": "Wood_Redwood_Stairs",
      "rotation": 3
    },
    {
      "x": 0,
      "y": 59,
      "z": 15,
      "name": "Soil_Dirt_Cold"
    },
    {
      "x": 0,
      "y": 60,
      "z": 15,
      "name": "Soil_Dirt_Cold"
    },
    {
      "x": 0,
      "y": 61,
      "z": 15,
      "name": "Soil_Dirt_Cold"
    },
    {
      "x": 0,
      "y": 62,
      "z": 15,
      "name": "Furniture_Lumberjack_Platform"
    },
    {
      "x": 0,
      "y": 63,
      "z": 15,
      "name": "Furniture_Lumberjack_Lantern"
    },
    {
      "x": 0,
      "y": 66,
      "z": 15,
      "name": "Wood_Redwood_Stairs",
      "rotation": 11
    },
    {
      "x": 0,
      "y": 67,
      "z": 15,
      "name": "Wood_Redwood_Stairs",
      "rotation": 3
    },
    {
      "x": 0,
      "y": 58,
      "z": 16,
      "name": "Soil_Dirt_Cold"
    },
    {
      "x": 0,
      "y": 59,
      "z": 16,
      "name": "Soil_Dirt_Cold"
    },
    {
      "x": 0,
      "y": 60,
      "z": 16,
      "name": "Soil_Dirt_Cold"
    },
    {
      "x": 0,
      "y": 61,
      "z": 16,
      "name": "Soil_Dirt_Cold"
    },
    {
      "x": 0,
      "y": 62,
      "z": 16,
      "name": "Rock_Shale_Brick"
    },
    {
      "x": 0,
      "y": 63,
      "z": 16,
      "name": "Furniture_Lumberjack_Window"
    },
    {
      "x": 0,
      "y": 64,
      "z": 16,
      "name": "Wood_Redwood_Planks"
    },
    {
      "x": 0,
      "y": 65,
      "z": 16,
      "name": "Wood_Redwood_Trunk",
      "rotation": 5
    },
    {
      "x": 0,
      "y": 66,
      "z": 16,
      "name": "Wood_Redwood_Trunk",
      "rotation": 5
    },
    {
      "x": 0,
      "y": 67,
      "z": 16,
      "name": "Wood_Redwood_Planks"
    },
    {
      "x": 0,
      "y": 68,
      "z": 16,
      "name": "Wood_Deadwood_Roof",
      "rotation": 3
    },
    {
      "x": 0,
      "y": 58,
      "z": 17,
      "name": "Soil_Dirt_Cold"
    },
    {
      "x": 0,
      "y": 59,
      "z": 17,
      "name": "Soil_Dirt_Cold"
    },
    {
      "x": 0,
      "y": 60,
      "z": 17,
      "name": "Soil_Dirt_Cold"
    },
    {
      "x": 0,
      "y": 61,
      "z": 17,
      "name": "Soil_Dirt_Cold"
    },
    {
      "x": 0,
      "y": 62,
      "z": 17,
      "name": "Empty"
    },
    {
      "x": 0,
      "y": 63,
      "z": 17,
      "name": "Empty"
    },
    {
      "x": 0,
      "y": 64,
      "z": 17,
      "name": "Furniture_Lumberjack_Platform",
      "rotation": 1
    },
    {
      "x": 0,
      "y": 65,
      "z": 17,
      "name": "Empty"
    },
    {
      "x": 0,
      "y": 66,
      "z": 17,
      "name": "Empty"
    },
    {
      "x": 0,
      "y": 67,
      "z": 17,
      "name": "Wood_Redwood_Planks"
    },
    {
      "x": 0,
      "y": 68,
      "z": 17,
      "name": "Wood_Deadwood_Roof",
      "rotation": 3
    },
    {
      "x": 0,
      "y": 58,
      "z": 18,
      "name": "Soil_Dirt_Cold"
    },
    {
      "x": 0,
      "y": 59,
      "z": 18,
      "name": "Soil_Dirt_Cold"
    },
    {
      "x": 0,
      "y": 60,
      "z": 18,
      "name": "Soil_Dirt_Cold"
    },
    {
      "x": 0,
      "y": 61,
      "z": 18,
      "name": "Soil_Dirt_Cold"
    },
    {
      "x": 0,
      "y": 62,
      "z": 18,
      "name": "Empty"
    },
    {
      "x": 0,
      "y": 63,
      "z": 18,
      "name": "Empty"
    },
    {
      "x": 0,
      "y": 64,
      "z": 18,
      "name": "Furniture_Lumberjack_Platform",
      "rotation": 1
    },
    {
      "x": 0,
      "y": 65,
      "z": 18,
      "name": "Block_Spawner_Block",
      "components": {
        "Components": {
          "BlockSpawner": {
            "BlockSpawnerId": "Zone3_Outlander_Tier1"
          }
        }
      },
      "rotation": 1
    },
    {
      "x": 0,
      "y": 66,
      "z": 18,
      "name": "Empty"
    },
    {
      "x": 0,
      "y": 67,
      "z": 18,
      "name": "Wood_Redwood_Planks"
    },
    {
      "x": 0,
      "y": 68,
      "z": 18,
      "name": "Wood_Deadwood_Roof",
      "rotation": 3
    },
    {
      "x": 0,
      "y": 58,
      "z": 19,
      "name": "Soil_Dirt_Cold"
    },
    {
      "x": 0,
      "y": 59,
      "z": 19,
      "name": "Soil_Dirt_Cold"
    },
    {
      "x": 0,
      "y": 60,
      "z": 19,
      "name": "Soil_Dirt_Cold"
    },
    {
      "x": 0,
      "y": 61,
      "z": 19,
      "name": "Soil_Dirt_Cold"
    },
    {
      "x": 0,
      "y": 62,
      "z": 19,
      "name": "Empty"
    },
    {
      "x": 0,
      "y": 63,
      "z": 19,
      "name": "Empty"
    },
    {
      "x": 0,
      "y": 64,
      "z": 19,
      "name": "Furniture_Lumberjack_Platform",
      "rotation": 1
    },
    {
      "x": 0,
      "y": 65,
      "z": 19,
      "name": "Empty"
    },
    {
      "x": 0,
      "y": 66,
      "z": 19,
      "name": "Empty"
    },
    {
      "x": 0,
      "y": 67,
      "z": 19,
      "name": "Wood_Redwood_Planks"
    },
    {
      "x": 0,
      "y": 68,
      "z": 19,
      "name": "Wood_Deadwood_Roof",
      "rotation": 3
    },
    {
      "x": 0,
      "y": 58,
      "z": 20,
      "name": "Soil_Dirt_Cold"
    },
    {
      "x": 0,
      "y": 59,
      "z": 20,
      "name": "Soil_Dirt_Cold"
    },
    {
      "x": 0,
      "y": 60,
      "z": 20,
      "name": "Soil_Dirt_Cold"
    },
    {
      "x": 0,
      "y": 61,
      "z": 20,
      "name": "Soil_Dirt_Cold"
    },
    {
      "x": 0,
      "y": 62,
      "z": 20,
      "name": "Empty"
    },
    {
      "x": 0,
      "y": 63,
      "z": 20,
      "name": "Empty"
    },
    {
      "x": 0,
      "y": 64,
      "z": 20,
      "name": "Wood_Redwood_Trunk",
      "rotation": 5
    },
    {
      "x": 0,
      "y": 65,
      "z": 20,
      "name": "Furniture_Village_Crate"
    },
    {
      "x": 0,
      "y": 66,
      "z": 20,
      "name": "Empty"
    },
    {
      "x": 0,
      "y": 67,
      "z": 20,
      "name": "Wood_Redwood_Planks"
    },
    {
      "x": 0,
      "y": 68,
      "z": 20,
      "name": "Wood_Deadwood_Roof",
      "rotation": 3
    },
    {
      "x": 0,
      "y": 58,
      "z": 21,
      "name": "Soil_Dirt_Cold"
    },
    {
      "x": 0,
      "y": 59,
      "z": 21,
      "name": "Soil_Dirt_Cold"
    },
    {
      "x": 0,
      "y": 60,
      "z": 21,
      "name": "Soil_Dirt_Cold"
    },
    {
      "x": 0,
      "y": 61,
      "z": 21,
      "name": "Soil_Dirt_Cold"
    },
    {
      "x": 0,
      "y": 62,
      "z": 21,
      "name": "Empty"
    },
    {
      "x": 0,
      "y": 63,
      "z": 21,
      "name": "Empty"
    },
    {
      "x": 0,
      "y": 64,
      "z": 21,
      "name": "Wood_Redwood_Planks_Half",
      "rotation": 8
    },
    {
      "x": 0,
      "y": 65,
      "z": 21,
      "name": "Empty"
    },
    {
      "x": 0,
      "y": 66,
      "z": 21,
      "name": "Empty"
    },
    {
      "x": 0,
      "y": 67,
      "z": 21,
      "name": "Wood_Redwood_Planks"
    },
    {
      "x": 0,
      "y": 68,
      "z": 21,
      "name": "Wood_Deadwood_Roof",
      "rotation": 3
    },
    {
      "x": 0,
      "y": 58,
      "z": 22,
      "name": "Soil_Dirt_Cold"
    },
    {
      "x": 0,
      "y": 59,
      "z": 22,
      "name": "Soil_Dirt_Cold"
    },
    {
      "x": 0,
      "y": 60,
      "z": 22,
      "name": "Soil_Dirt_Cold"
    },
    {
      "x": 0,
      "y": 61,
      "z": 22,
      "name": "Soil_Dirt_Cold"
    },
    {
      "x": 0,
      "y": 62,
      "z": 22,
      "name": "Empty"
    },
    {
      "x": 0,
      "y": 63,
      "z": 22,
      "name": "Empty"
    },
    {
      "x": 0,
      "y": 64,
      "z": 22,
      "name": "Wood_Redwood_Planks_Half",
      "rotation": 8
    },
    {
      "x": 0,
      "y": 65,
      "z": 22,
      "name": "Empty"
    },
    {
      "x": 0,
      "y": 66,
      "z": 22,
      "name": "Empty"
    },
    {
      "x": 0,
      "y": 67,
      "z": 22,
      "name": "Wood_Redwood_Planks"
    },
    {
      "x": 0,
      "y": 68,
      "z": 22,
      "name": "Wood_Deadwood_Roof",
      "rotation": 3
    },
    {
      "x": 0,
      "y": 58,
      "z": 23,
      "name": "Soil_Dirt_Cold"
    },
    {
      "x": 0,
      "y": 59,
      "z": 23,
      "name": "Soil_Dirt_Cold"
    },
    {
      "x": 0,
      "y": 60,
      "z": 23,
      "name": "Soil_Dirt_Cold"
    },
    {
      "x": 0,
      "y": 61,
      "z": 23,
      "name": "Soil_Dirt_Cold"
    },
    {
      "x": 0,
      "y": 62,
      "z": 23,
      "name": "Empty"
    },
    {
      "x": 0,
      "y": 63,
      "z": 23,
      "name": "Empty"
    },
    {
      "x": 0,
      "y": 64,
      "z": 23,
      "name": "Wood_Redwood_Planks_Half",
      "rotation": 8
    },
    {
      "x": 0,
      "y": 65,
      "z": 23,
      "name": "Empty"
    },
    {
      "x": 0,
      "y": 66,
      "z": 23,
      "name": "Empty"
    },
    {
      "x": 0,
      "y": 67,
      "z": 23,
      "name": "Wood_Redwood_Planks"
    },
    {
      "x": 0,
      "y": 68,
      "z": 23,
      "name": "Wood_Deadwood_Roof",
      "rotation": 3
    },
    {
      "x": 0,
      "y": 58,
      "z": 24,
      "name": "Soil_Dirt_Cold"
    },
    {
      "x": 0,
      "y": 59,
      "z": 24,
      "name": "Soil_Dirt_Cold"
    },
    {
      "x": 0,
      "y": 60,
      "z": 24,
      "name": "Soil_Dirt_Cold"
    },
    {
      "x": 0,
      "y": 61,
      "z": 24,
      "name": "Soil_Dirt_Cold"
    },
    {
      "x": 0,
      "y": 62,
      "z": 24,
      "name": "Empty"
    },
    {
      "x": 0,
      "y": 63,
      "z": 24,
      "name": "Empty"
    },
    {
      "x": 0,
      "y": 64,
      "z": 24,
      "name": "Wood_Redwood_Planks_Half",
      "rotation": 8
    },
    {
      "x": 0,
      "y": 65,
      "z": 24,
      "name": "Empty"
    },
    {
      "x": 0,
      "y": 66,
      "z": 24,
      "name": "Empty"
    },
    {
      "x": 0,
      "y": 67,
      "z": 24,
      "name": "Wood_Redwood_Planks"
    },
    {
      "x": 0,
      "y": 68,
      "z": 24,
      "name": "Wood_Deadwood_Roof",
      "rotation": 3
    },
    {
      "x": 0,
      "y": 58,
      "z": 25,
      "name": "Soil_Dirt_Cold"
    },
    {
      "x": 0,
      "y": 59,
      "z": 25,
      "name": "Soil_Dirt_Cold"
    },
    {
      "x": 0,
      "y": 60,
      "z": 25,
      "name": "Soil_Dirt_Cold"
    },
    {
      "x": 0,
      "y": 61,
      "z": 25,
      "name": "Soil_Dirt_Cold"
    },
    {
      "x": 0,
      "y": 62,
      "z": 25,
      "name": "Empty"
    },
    {
      "x": 0,
      "y": 63,
      "z": 25,
      "name": "Empty"
    },
    {
      "x": 0,
      "y": 64,
      "z": 25,
      "name": "Wood_Redwood_Planks_Half",
      "rotation": 8
    },
    {
      "x": 0,
      "y": 65,
      "z": 25,
      "name": "Furniture_Village_Crate"
    },
    {
      "x": 0,
      "y": 66,
      "z": 25,
      "name": "Furniture_Village_Crate"
    },
    {
      "x": 0,
      "y": 67,
      "z": 25,
      "name": "Wood_Redwood_Planks"
    },
    {
      "x": 0,
      "y": 68,
      "z": 25,
      "name": "Wood_Deadwood_Roof",
      "rotation": 3
    },
    {
      "x": 0,
      "y": 58,
      "z": 26,
      "name": "Soil_Dirt_Cold"
    },
    {
      "x": 0,
      "y": 59,
      "z": 26,
      "name": "Soil_Dirt_Cold"
    },
    {
      "x": 0,
      "y": 60,
      "z": 26,
      "name": "Soil_Dirt_Cold"
    },
    {
      "x": 0,
      "y": 61,
      "z": 26,
      "name": "Soil_Dirt_Cold"
    },
    {
      "x": 0,
      "y": 62,
      "z": 26,
      "name": "Empty"
    },
    {
      "x": 0,
      "y": 63,
      "z": 26,
      "name": "Empty"
    },
    {
      "x": 0,
      "y": 64,
      "z": 26,
      "name": "Wood_Redwood_Planks_Half",
      "rotation": 8
    },
    {
      "x": 0,
      "y": 65,
      "z": 26,
      "name": "Furniture_Village_Crate"
    },
    {
      "x": 0,
      "y": 66,
      "z": 26,
      "name": "Furniture_Village_Crate"
    },
    {
      "x": 0,
      "y": 67,
      "z": 26,
      "name": "Wood_Redwood_Planks"
    },
    {
      "x": 0,
      "y": 68,
      "z": 26,
      "name": "Wood_Deadwood_Roof",
      "rotation": 3
    },
    {
      "x": 0,
      "y": 59,
      "z": 27,
      "name": "Soil_Dirt_Cold"
    },
    {
      "x": 0,
      "y": 60,
      "z": 27,
      "name": "Soil_Dirt_Cold"
    },
    {
      "x": 0,
      "y": 61,
      "z": 27,
      "name": "Soil_Dirt_Cold"
    },
    {
      "x": 0,
      "y": 62,
      "z": 27,
      "name": "Rock_Shale_Brick"
    },
    {
      "x": 0,
      "y": 63,
      "z": 27,
      "name": "Rock_Shale_Brick"
    },
    {
      "x": 0,
      "y": 64,
      "z": 27,
      "name": "Wood_Redwood_Planks"
    },
    {
      "x": 0,
      "y": 65,
      "z": 27,
      "name": "Wood_Redwood_Trunk",
      "rotation": 5
    },
    {
      "x": 0,
      "y": 66,
      "z": 27,
      "name": "Wood_Redwood_Planks"
    },
    {
      "x": 0,
      "y": 67,
      "z": 27,
      "name": "Wood_Redwood_Planks"
    },
    {
      "x": 0,
      "y": 68,
      "z": 27,
      "name": "Wood_Deadwood_Roof",
      "rotation": 3
    },
    {
      "x": 0,
      "y": 66,
      "z": 28,
      "name": "Wood_Redwood_Stairs",
      "rotation": 11
    },
    {
      "x": 0,
      "y": 67,
      "z": 28,
      "name": "Wood_Redwood_Stairs",
      "rotation": 3
    },
    {
      "x": 1,
      "y": 67,
      "z": 14,
      "name": "Wood_Redwood_Stairs",
      "rotation": 8
    },
    {
      "x": 1,
      "y": 68,
      "z": 14,
      "name": "Wood_Redwood_Trunk",
      "rotation": 4
    },
    {
      "x": 1,
      "y": 59,
      "z": 15,
      "name": "Soil_Dirt_Cold"
    },
    {
      "x": 1,
      "y": 60,
      "z": 15,
      "name": "Soil_Dirt_Cold"
    },
    {
      "x": 1,
      "y": 61,
      "z": 15,
      "name": "Soil_Dirt_Cold"
    },
    {
      "x": 1,
      "y": 67,
      "z": 15,
      "name": "Wood_Redwood_Planks"
    },
    {
      "x": 1,
      "y": 68,
      "z": 15,
      "name": "Wood_Redwood_Trunk",
      "rotation": 4
    },
    {
      "x": 1,
      "y": 69,
      "z": 15,
      "name": "Wood_Deadwood_Roof_Flat",
      "rotation": 1
    },
    {
      "x": 1,
      "y": 58,
      "z": 16,
      "name": "Soil_Dirt_Cold"
    },
    {
      "x": 1,
      "y": 59,
      "z": 16,
      "name": "Soil_Dirt_Cold"
    },
    {
      "x": 1,
      "y": 60,
      "z": 16,
      "name": "Soil_Dirt_Cold"
    },
    {
      "x": 1,
      "y": 61,
      "z": 16,
      "name": "Soil_Dirt_Cold"
    },
    {
      "x": 1,
      "y": 62,
      "z": 16,
      "name": "Rock_Shale_Brick"
    },
    {
      "x": 1,
      "y": 63,
      "z": 16,
      "name": "Rock_Shale_Brick"
    },
    {
      "x": 1,
      "y": 64,
      "z": 16,
      "name": "Wood_Redwood_Trunk_Full",
      "rotation": 5
    },
    {
      "x": 1,
      "y": 65,
      "z": 16,
      "name": "Furniture_Lumberjack_Window"
    },
    {
      "x": 1,
      "y": 66,
      "z": 16,
      "name": "Wood_Redwood_Trunk",
      "rotation": 5
    },
    {
      "x": 1,
      "y": 67,
      "z": 16,
      "name": "Wood_Redwood_Planks"
    },
    {
      "x": 1,
      "y": 68,
      "z": 16,
      "name": "Wood_Redwood_Trunk",
      "rotation": 4
    },
    {
      "x": 1,
      "y": 69,
      "z": 16,
      "name": "Wood_Deadwood_Roof_Flat",
      "rotation": 1
    },
    {
      "x": 1,
      "y": 58,
      "z": 17,
      "name": "Soil_Dirt_Cold"
    },
    {
      "x": 1,
      "y": 59,
      "z": 17,
      "name": "Soil_Dirt_Cold"
    },
    {
      "x": 1,
      "y": 60,
      "z": 17,
      "name": "Soil_Dirt_Cold"
    },
    {
      "x": 1,
      "y": 61,
      "z": 17,
      "name": "Soil_Dirt_Cold"
    },
    {
      "x": 1,
      "y": 62,
      "z": 17,
      "name": "Empty"
    },
    {
      "x": 1,
      "y": 63,
      "z": 17,
      "name": "Wood_Torch_Wall"
    },
    {
      "x": 1,
      "y": 64,
      "z": 17,
      "name": "Furniture_Lumberjack_Platform",
      "rotation": 1
    },
    {
      "x": 1,
      "y": 65,
      "z": 17,
      "name": "Empty"
    },
    {
      "x": 1,
      "y": 66,
      "z": 17,
      "name": "Empty"
    },
    {
      "x": 1,
      "y": 67,
      "z": 17,
      "name": "Empty"
    },
    {
      "x": 1,
      "y": 68,
      "z": 17,
      "name": "Wood_Redwood_Trunk",
      "rotation": 4
    },
    {
      "x": 1,
      "y": 69,
      "z": 17,
      "name": "Wood_Deadwood_Roof_Flat",
      "rotation": 1
    },
    {
      "x": 1,
      "y": 58,
      "z": 18,
      "name": "Soil_Dirt_Cold"
    },
    {
      "x": 1,
      "y": 59,
      "z": 18,
      "name": "Soil_Dirt_Cold"
    },
    {
      "x": 1,
      "y": 60,
      "z": 18,
      "name": "Soil_Dirt_Cold"
    },
    {
      "x": 1,
      "y": 61,
      "z": 18,
      "name": "Soil_Dirt_Cold"
    },
    {
      "x": 1,
      "y": 62,
      "z": 18,
      "name": "Empty"
    },
    {
      "x": 1,
      "y": 63,
      "z": 18,
      "name": "Empty"
    },
    {
      "x": 1,
      "y": 64,
      "z": 18,
      "name": "Furniture_Lumberjack_Platform",
      "rotation": 1
    },
    {
      "x": 1,
      "y": 65,
      "z": 18,
      "name": "Empty"
    },
    {
      "x": 1,
      "y": 66,
      "z": 18,
      "name": "Empty"
    },
    {
      "x": 1,
      "y": 67,
      "z": 18,
      "name": "Empty"
    },
    {
      "x": 1,
      "y": 68,
      "z": 18,
      "name": "Wood_Redwood_Trunk",
      "rotation": 4
    },
    {
      "x": 1,
      "y": 69,
      "z": 18,
      "name": "Wood_Deadwood_Roof_Flat",
      "rotation": 1
    },
    {
      "x": 1,
      "y": 58,
      "z": 19,
      "name": "Soil_Dirt_Cold"
    },
    {
      "x": 1,
      "y": 59,
      "z": 19,
      "name": "Soil_Dirt_Cold"
    },
    {
      "x": 1,
      "y": 60,
      "z": 19,
      "name": "Soil_Dirt_Cold"
    },
    {
      "x": 1,
      "y": 61,
      "z": 19,
      "name": "Soil_Dirt_Cold"
    },
    {
      "x": 1,
      "y": 62,
      "z": 19,
      "name": "Empty"
    },
    {
      "x": 1,
      "y": 63,
      "z": 19,
      "name": "Empty"
    },
    {
      "x": 1,
      "y": 64,
      "z": 19,
      "name": "Furniture_Lumberjack_Platform",
      "rotation": 1
    },
    {
      "x": 1,
      "y": 65,
      "z": 19,
      "name": "Empty"
    },
    {
      "x": 1,
      "y": 66,
      "z": 19,
      "name": "Empty"
    },
    {
      "x": 1,
      "y": 67,
      "z": 19,
      "name": "Empty"
    },
    {
      "x": 1,
      "y": 68,
      "z": 19,
      "name": "Wood_Redwood_Trunk",
      "rotation": 4
    },
    {
      "x": 1,
      "y": 69,
      "z": 19,
      "name": "Wood_Deadwood_Roof_Flat",
      "rotation": 1
    },
    {
      "x": 1,
      "y": 58,
      "z": 20,
      "name": "Soil_Dirt_Cold"
    },
    {
      "x": 1,
      "y": 59,
      "z": 20,
      "name": "Soil_Dirt_Cold"
    },
    {
      "x": 1,
      "y": 60,
      "z": 20,
      "name": "Soil_Dirt_Cold"
    },
    {
      "x": 1,
      "y": 61,
      "z": 20,
      "name": "Soil_Dirt_Cold"
    },
    {
      "x": 1,
      "y": 62,
      "z": 20,
      "name": "Empty"
    },
    {
      "x": 1,
      "y": 63,
      "z": 20,
      "name": "Empty"
    },
    {
      "x": 1,
      "y": 64,
      "z": 20,
      "name": "Wood_Redwood_Trunk",
      "rotation": 5
    },
    {
      "x": 1,
      "y": 65,
      "z": 20,
      "name": "Empty"
    },
    {
      "x": 1,
      "y": 66,
      "z": 20,
      "name": "Empty"
    },
    {
      "x": 1,
      "y": 67,
      "z": 20,
      "name": "Empty"
    },
    {
      "x": 1,
      "y": 68,
      "z": 20,
      "name": "Wood_Redwood_Trunk",
      "rotation": 4
    },
    {
      "x": 1,
      "y": 69,
      "z": 20,
      "name": "Wood_Deadwood_Roof_Flat",
      "rotation": 1
    },
    {
      "x": 1,
      "y": 58,
      "z": 21,
      "name": "Soil_Dirt_Cold"
    },
    {
      "x": 1,
      "y": 59,
      "z": 21,
      "name": "Soil_Dirt_Cold"
    },
    {
      "x": 1,
      "y": 60,
      "z": 21,
      "name": "Soil_Dirt_Cold"
    },
    {
      "x": 1,
      "y": 61,
      "z": 21,
      "name": "Soil_Dirt_Cold"
    },
    {
      "x": 1,
      "y": 62,
      "z": 21,
      "name": "Empty"
    },
    {
      "x": 1,
      "y": 63,
      "z": 21,
      "name": "Empty"
    },
    {
      "x": 1,
      "y": 64,
      "z": 21,
      "name": "Wood_Redwood_Planks_Half",
      "rotation": 8
    },
    {
      "x": 1,
      "y": 65,
      "z": 21,
      "name": "Empty"
    },
    {
      "x": 1,
      "y": 66,
      "z": 21,
      "name": "Empty"
    },
    {
      "x": 1,
      "y": 67,
      "z": 21,
      "name": "Empty"
    },
    {
      "x": 1,
      "y": 68,
      "z": 21,
      "name": "Wood_Redwood_Trunk",
      "rotation": 4
    },
    {
      "x": 1,
      "y": 69,
      "z": 21,
      "name": "Wood_Deadwood_Roof_Flat",
      "rotation": 1
    },
    {
      "x": 1,
      "y": 58,
      "z": 22,
      "name": "Soil_Dirt_Cold"
    },
    {
      "x": 1,
      "y": 59,
      "z": 22,
      "name": "Soil_Dirt_Cold"
    },
    {
      "x": 1,
      "y": 60,
      "z": 22,
      "name": "Soil_Dirt_Cold"
    },
    {
      "x": 1,
      "y": 61,
      "z": 22,
      "name": "Soil_Dirt_Cold"
    },
    {
      "x": 1,
      "y": 62,
      "z": 22,
      "name": "Empty"
    },
    {
      "x": 1,
      "y": 63,
      "z": 22,
      "name": "Empty"
    },
    {
      "x": 1,
      "y": 64,
      "z": 22,
      "name": "Wood_Redwood_Planks_Half",
      "rotation": 8
    },
    {
      "x": 1,
      "y": 65,
      "z": 22,
      "name": "Empty"
    },
    {
      "x": 1,
      "y": 66,
      "z": 22,
      "name": "Empty"
    },
    {
      "x": 1,
      "y": 67,
      "z": 22,
      "name": "Empty"
    },
    {
      "x": 1,
      "y": 68,
      "z": 22,
      "name": "Wood_Redwood_Trunk",
      "rotation": 4
    },
    {
      "x": 1,
      "y": 69,
      "z": 22,
      "name": "Wood_Deadwood_Roof_Flat",
      "rotation": 1
    },
    {
      "x": 1,
      "y": 58,
      "z": 23,
      "name": "Soil_Dirt_Cold"
    },
    {
      "x": 1,
      "y": 59,
      "z": 23,
      "name": "Soil_Dirt_Cold"
    },
    {
      "x": 1,
      "y": 60,
      "z": 23,
      "name": "Soil_Dirt_Cold"
    },
    {
      "x": 1,
      "y": 61,
      "z": 23,
      "name": "Soil_Dirt_Cold"
    },
    {
      "x": 1,
      "y": 62,
      "z": 23,
      "name": "Empty"
    },
    {
      "x": 1,
      "y": 63,
      "z": 23,
      "name": "Empty"
    },
    {
      "x": 1,
      "y": 64,
      "z": 23,
      "name": "Wood_Redwood_Planks_Half",
      "rotation": 8
    },
    {
      "x": 1,
      "y": 65,
      "z": 23,
      "name": "Empty"
    },
    {
      "x": 1,
      "y": 66,
      "z": 23,
      "name": "Empty"
    },
    {
      "x": 1,
      "y": 67,
      "z": 23,
      "name": "Empty"
    },
    {
      "x": 1,
      "y": 68,
      "z": 23,
      "name": "Wood_Redwood_Trunk",
      "rotation": 4
    },
    {
      "x": 1,
      "y": 69,
      "z": 23,
      "name": "Wood_Deadwood_Roof_Flat",
      "rotation": 1
    },
    {
      "x": 1,
      "y": 58,
      "z": 24,
      "name": "Soil_Dirt_Cold"
    },
    {
      "x": 1,
      "y": 59,
      "z": 24,
      "name": "Soil_Dirt_Cold"
    },
    {
      "x": 1,
      "y": 60,
      "z": 24,
      "name": "Soil_Dirt_Cold"
    },
    {
      "x": 1,
      "y": 61,
      "z": 24,
      "name": "Soil_Dirt_Cold"
    },
    {
      "x": 1,
      "y": 62,
      "z": 24,
      "name": "Empty"
    },
    {
      "x": 1,
      "y": 63,
      "z": 24,
      "name": "Empty"
    },
    {
      "x": 1,
      "y": 64,
      "z": 24,
      "name": "Empty"
    },
    {
      "x": 1,
      "y": 65,
      "z": 24,
      "name": "Empty"
    },
    {
      "x": 1,
      "y": 66,
      "z": 24,
      "name": "Empty"
    },
    {
      "x": 1,
      "y": 67,
      "z": 24,
      "name": "Empty"
    },
    {
      "x": 1,
      "y": 68,
      "z": 24,
      "name": "Wood_Redwood_Trunk",
      "rotation": 4
    },
    {
      "x": 1,
      "y": 69,
      "z": 24,
      "name": "Wood_Deadwood_Roof_Flat",
      "rotation": 1
    },
    {
      "x": 1,
      "y": 58,
      "z": 25,
      "name": "Soil_Dirt_Cold"
    },
    {
      "x": 1,
      "y": 59,
      "z": 25,
      "name": "Soil_Dirt_Cold"
    },
    {
      "x": 1,
      "y": 60,
      "z": 25,
      "name": "Soil_Dirt_Cold"
    },
    {
      "x": 1,
      "y": 61,
      "z": 25,
      "name": "Soil_Dirt_Cold"
    },
    {
      "x": 1,
      "y": 62,
      "z": 25,
      "name": "Furniture_Lumberjack_Ladder",
      "rotation": 2
    },
    {
      "x": 1,
      "y": 63,
      "z": 25,
      "name": "Furniture_Lumberjack_Ladder",
      "rotation": 2
    },
    {
      "x": 1,
      "y": 64,
      "z": 25,
      "name": "Furniture_Lumberjack_Ladder",
      "rotation": 2
    },
    {
      "x": 1,
      "y": 65,
      "z": 25,
      "name": "Furniture_Lumberjack_Ladder",
      "rotation": 2
    },
    {
      "x": 1,
      "y": 66,
      "z": 25,
      "name": "Empty"
    },
    {
      "x": 1,
      "y": 67,
      "z": 25,
      "name": "Empty"
    },
    {
      "x": 1,
      "y": 68,
      "z": 25,
      "name": "Wood_Redwood_Trunk",
      "rotation": 4
    },
    {
      "x": 1,
      "y": 69,
      "z": 25,
      "name": "Wood_Deadwood_Roof_Flat",
      "rotation": 1
    },
    {
      "x": 1,
      "y": 58,
      "z": 26,
      "name": "Soil_Dirt_Cold"
    },
    {
      "x": 1,
      "y": 59,
      "z": 26,
      "name": "Soil_Dirt_Cold"
    },
    {
      "x": 1,
      "y": 60,
      "z": 26,
      "name": "Soil_Dirt_Cold"
    },
    {
      "x": 1,
      "y": 61,
      "z": 26,
      "name": "Soil_Dirt_Cold"
    },
    {
      "x": 1,
      "y": 62,
      "z": 26,
      "name": "Empty"
    },
    {
      "x": 1,
      "y": 63,
      "z": 26,
      "name": "Empty"
    },
    {
      "x": 1,
      "y": 64,
      "z": 26,
      "name": "Wood_Redwood_Planks_Half",
      "rotation": 8
    },
    {
      "x": 1,
      "y": 65,
      "z": 26,
      "name": "Empty"
    },
    {
      "x": 1,
      "y": 66,
      "z": 26,
      "name": "Empty"
    },
    {
      "x": 1,
      "y": 67,
      "z": 26,
      "name": "Empty"
    },
    {
      "x": 1,
      "y": 68,
      "z": 26,
      "name": "Wood_Redwood_Trunk",
      "rotation": 4
    },
    {
      "x": 1,
      "y": 69,
      "z": 26,
      "name": "Wood_Deadwood_Roof_Flat",
      "rotation": 1
    },
    {
      "x": 1,
      "y": 59,
      "z": 27,
      "name": "Soil_Dirt_Cold"
    },
    {
      "x": 1,
      "y": 60,
      "z": 27,
      "name": "Soil_Dirt_Cold"
    },
    {
      "x": 1,
      "y": 61,
      "z": 27,
      "name": "Soil_Dirt_Cold"
    },
    {
      "x": 1,
      "y": 62,
      "z": 27,
      "name": "Rock_Shale_Brick"
    },
    {
      "x": 1,
      "y": 63,
      "z": 27,
      "name": "Rock_Shale_Brick"
    },
    {
      "x": 1,
      "y": 64,
      "z": 27,
      "name": "Wood_Redwood_Planks"
    },
    {
      "x": 1,
      "y": 65,
      "z": 27,
      "name": "Wood_Redwood_Trunk",
      "rotation": 5
    },
    {
      "x": 1,
      "y": 66,
      "z": 27,
      "name": "Wood_Redwood_Planks"
    },
    {
      "x": 1,
      "y": 67,
      "z": 27,
      "name": "Wood_Redwood_Trunk",
      "rotation": 5
    },
    {
      "x": 1,
      "y": 68,
      "z": 27,
      "name": "Wood_Redwood_Trunk",
      "rotation": 4
    },
    {
      "x": 1,
      "y": 69,
      "z": 27,
      "name": "Wood_Deadwood_Roof_Flat",
      "rotation": 1
    },
    {
      "x": 1,
      "y": 66,
      "z": 28,
      "name": "Wood_Redwood_Planks_Half",
      "rotation": 4
    },
    {
      "x": 1,
      "y": 67,
      "z": 28,
      "name": "Wood_Redwood_Planks"
    },
    {
      "x": 1,
      "y": 68,
      "z": 28,
      "name": "Wood_Redwood_Trunk",
      "rotation": 4
    },
    {
      "x": 1,
      "y": 67,
      "z": 29,
      "name": "Wood_Redwood_Stairs",
      "rotation": 10
    },
    {
      "x": 1,
      "y": 68,
      "z": 29,
      "name": "Wood_Redwood_Trunk",
      "rotation": 4
    },
    {
      "x": 2,
      "y": 60,
      "z": 14,
      "name": "Soil_Dirt_Cold"
    },
    {
      "x": 2,
      "y": 61,
      "z": 14,
      "name": "Soil_Dirt_Cold"
    },
    {
      "x": 2,
      "y": 62,
      "z": 14,
      "name": "Empty"
    },
    {
      "x": 2,
      "y": 63,
      "z": 14,
      "name": "Empty"
    },
    {
      "x": 2,
      "y": 64,
      "z": 14,
      "name": "Empty"
    },
    {
      "x": 2,
      "y": 59,
      "z": 15,
      "name": "Soil_Dirt_Cold"
    },
    {
      "x": 2,
      "y": 60,
      "z": 15,
      "name": "Soil_Dirt_Cold"
    },
    {
      "x": 2,
      "y": 61,
      "z": 15,
      "name": "Soil_Dirt_Cold"
    },
    {
      "x": 2,
      "y": 62,
      "z": 15,
      "name": "Wood_Redwood_Branch_Long"
    },
    {
      "x": 2,
      "y": 63,
      "z": 15,
      "name": "Wood_Redwood_Branch_Long"
    },
    {
      "x": 2,
      "y": 64,
      "z": 15,
      "name": "*Wood_Deadwood_Roof_State_Definitions_Corner_Right",
      "rotation": 3
    },
    {
      "x": 2,
      "y": 66,
      "z": 15,
      "name": "Wood_Redwood_Stairs",
      "rotation": 9
    },
    {
      "x": 2,
      "y": 67,
      "z": 15,
      "name": "Wood_Redwood_Stairs",
      "rotation": 1
    },
    {
      "x": 2,
      "y": 68,
      "z": 15,
      "name": "Wood_Deadwood_Roof",
      "rotation": 1
    },
    {
      "x": 2,
      "y": 58,
      "z": 16,
      "name": "Soil_Dirt_Cold"
    },
    {
      "x": 2,
      "y": 59,
      "z": 16,
      "name": "Soil_Dirt_Cold"
    },
    {
      "x": 2,
      "y": 60,
      "z": 16,
      "name": "Soil_Dirt_Cold"
    },
    {
      "x": 2,
      "y": 61,
      "z": 16,
      "name": "Soil_Dirt_Cold"
    },
    {
      "x": 2,
      "y": 62,
      "z": 16,
      "name": "Rock_Shale_Brick"
    },
    {
      "x": 2,
      "y": 63,
      "z": 16,
      "name": "Rock_Shale_Brick"
    },
    {
      "x": 2,
      "y": 64,
      "z": 16,
      "name": "Wood_Redwood_Trunk",
      "rotation": 5
    },
    {
      "x": 2,
      "y": 65,
      "z": 16,
      "name": "Wood_Redwood_Planks"
    },
    {
      "x": 2,
      "y": 66,
      "z": 16,
      "name": "Wood_Redwood_Trunk",
      "rotation": 5
    },
    {
      "x": 2,
      "y": 67,
      "z": 16,
      "name": "Wood_Redwood_Planks"
    },
    {
      "x": 2,
      "y": 68,
      "z": 16,
      "name": "Wood_Deadwood_Roof",
      "rotation": 1
    },
    {
      "x": 2,
      "y": 58,
      "z": 17,
      "name": "Soil_Dirt_Cold"
    },
    {
      "x": 2,
      "y": 59,
      "z": 17,
      "name": "Soil_Dirt_Cold"
    },
    {
      "x": 2,
      "y": 60,
      "z": 17,
      "name": "Soil_Dirt_Cold"
    },
    {
      "x": 2,
      "y": 61,
      "z": 17,
      "name": "Soil_Dirt_Cold"
    },
    {
      "x": 2,
      "y": 62,
      "z": 17,
      "name": "Empty"
    },
    {
      "x": 2,
      "y": 63,
      "z": 17,
      "name": "Empty"
    },
    {
      "x": 2,
      "y": 64,
      "z": 17,
      "name": "Furniture_Lumberjack_Platform",
      "rotation": 1
    },
    {
      "x": 2,
      "y": 65,
      "z": 17,
      "name": "Furniture_Village_Crate"
    },
    {
      "x": 2,
      "y": 66,
      "z": 17,
      "name": "Empty"
    },
    {
      "x": 2,
      "y": 67,
      "z": 17,
      "name": "Wood_Redwood_Planks"
    },
    {
      "x": 2,
      "y": 68,
      "z": 17,
      "name": "Wood_Deadwood_Roof",
      "rotation": 1
    },
    {
      "x": 2,
      "y": 58,
      "z": 18,
      "name": "Soil_Dirt_Cold"
    },
    {
      "x": 2,
      "y": 59,
      "z": 18,
      "name": "Soil_Dirt_Cold"
    },
    {
      "x": 2,
      "y": 60,
      "z": 18,
      "name": "Soil_Dirt_Cold"
    },
    {
      "x": 2,
      "y": 61,
      "z": 18,
      "name": "Soil_Dirt_Cold"
    },
    {
      "x": 2,
      "y": 62,
      "z": 18,
      "name": "Empty"
    },
    {
      "x": 2,
      "y": 63,
      "z": 18,
      "name": "Empty"
    },
    {
      "x": 2,
      "y": 64,
      "z": 18,
      "name": "Furniture_Lumberjack_Platform"
    },
    {
      "x": 2,
      "y": 65,
      "z": 18,
      "name": "Furniture_Lumberjack_Lantern"
    },
    {
      "x": 2,
      "y": 66,
      "z": 18,
      "name": "Empty"
    },
    {
      "x": 2,
      "y": 67,
      "z": 18,
      "name": "Wood_Redwood_Planks"
    },
    {
      "x": 2,
      "y": 68,
      "z": 18,
      "name": "Wood_Deadwood_Roof",
      "rotation": 1
    },
    {
      "x": 2,
      "y": 58,
      "z": 19,
      "name": "Soil_Dirt_Cold"
    },
    {
      "x": 2,
      "y": 59,
      "z": 19,
      "name": "Soil_Dirt_Cold"
    },
    {
      "x": 2,
      "y": 60,
      "z": 19,
      "name": "Soil_Dirt_Cold"
    },
    {
      "x": 2,
      "y": 61,
      "z": 19,
      "name": "Soil_Dirt_Cold"
    },
    {
      "x": 2,
      "y": 62,
      "z": 19,
      "name": "Furniture_Lumberjack_Shelf",
      "rotation": 2
    },
    {
      "x": 2,
      "y": 63,
      "z": 19,
      "name": "Empty"
    },
    {
      "x": 2,
      "y": 64,
      "z": 19,
      "name": "Furniture_Lumberjack_Platform",
      "rotation": 1
    },
    {
      "x": 2,
      "y": 65,
      "z": 19,
      "name": "Empty"
    },
    {
      "x": 2,
      "y": 66,
      "z": 19,
      "name": "Empty"
    },
    {
      "x": 2,
      "y": 67,
      "z": 19,
      "name": "Wood_Redwood_Planks"
    },
    {
      "x": 2,
      "y": 68,
      "z": 19,
      "name": "Wood_Deadwood_Roof",
      "rotation": 1
    },
    {
      "x": 2,
      "y": 58,
      "z": 20,
      "name": "Soil_Dirt_Cold"
    },
    {
      "x": 2,
      "y": 59,
      "z": 20,
      "name": "Soil_Dirt_Cold"
    },
    {
      "x": 2,
      "y": 60,
      "z": 20,
      "name": "Soil_Dirt_Cold"
    },
    {
      "x": 2,
      "y": 61,
      "z": 20,
      "name": "Soil_Dirt_Cold"
    },
    {
      "x": 2,
      "y": 62,
      "z": 20,
      "name": "Wood_Redwood_Trunk"
    },
    {
      "x": 2,
      "y": 63,
      "z": 20,
      "name": "Wood_Redwood_Trunk"
    },
    {
      "x": 2,
      "y": 64,
      "z": 20,
      "name": "Wood_Redwood_Trunk",
      "rotation": 5
    },
    {
      "x": 2,
      "y": 65,
      "z": 20,
      "name": "Empty"
    },
    {
      "x": 2,
      "y": 66,
      "z": 20,
      "name": "Empty"
    },
    {
      "x": 2,
      "y": 67,
      "z": 20,
      "name": "Wood_Redwood_Planks"
    },
    {
      "x": 2,
      "y": 68,
      "z": 20,
      "name": "Wood_Deadwood_Roof",
      "rotation": 1
    },
    {
      "x": 2,
      "y": 58,
      "z": 21,
      "name": "Soil_Dirt_Cold"
    },
    {
      "x": 2,
      "y": 59,
      "z": 21,
      "name": "Soil_Dirt_Cold"
    },
    {
      "x": 2,
      "y": 60,
      "z": 21,
      "name": "Soil_Dirt_Cold"
    },
    {
      "x": 2,
      "y": 61,
      "z": 21,
      "name": "Soil_Dirt_Cold"
    },
    {
      "x": 2,
      "y": 62,
      "z": 21,
      "name": "Wood_Softwood_Fence",
      "rotation": 3
    },
    {
      "x": 2,
      "y": 63,
      "z": 21,
      "name": "Wood_Softwood_Fence",
      "rotation": 3
    },
    {
      "x": 2,
      "y": 64,
      "z": 21,
      "name": "Wood_Redwood_Trunk",
      "rotation": 4
    },
    {
      "x": 2,
      "y": 65,
      "z": 21,
      "name": "Empty"
    },
    {
      "x": 2,
      "y": 66,
      "z": 21,
      "name": "Empty"
    },
    {
      "x": 2,
      "y": 67,
      "z": 21,
      "name": "Wood_Redwood_Planks"
    },
    {
      "x": 2,
      "y": 68,
      "z": 21,
      "name": "Wood_Deadwood_Roof",
      "rotation": 1
    },
    {
      "x": 2,
      "y": 58,
      "z": 22,
      "name": "Soil_Dirt_Cold"
    },
    {
      "x": 2,
      "y": 59,
      "z": 22,
      "name": "Soil_Dirt_Cold"
    },
    {
      "x": 2,
      "y": 60,
      "z": 22,
      "name": "Soil_Dirt_Cold"
    },
    {
      "x": 2,
      "y": 61,
      "z": 22,
      "name": "Soil_Dirt_Cold"
    },
    {
      "x": 2,
      "y": 62,
      "z": 22,
      "name": "Wood_Softwood_Fence",
      "rotation": 3
    },
    {
      "x": 2,
      "y": 63,
      "z": 22,
      "name": "Wood_Softwood_Fence",
      "rotation": 3
    },
    {
      "x": 2,
      "y": 64,
      "z": 22,
      "name": "Wood_Redwood_Trunk",
      "rotation": 4
    },
    {
      "x": 2,
      "y": 65,
      "z": 22,
      "name": "Empty"
    },
    {
      "x": 2,
      "y": 66,
      "z": 22,
      "name": "Empty"
    },
    {
      "x": 2,
      "y": 67,
      "z": 22,
      "name": "Wood_Redwood_Planks"
    },
    {
      "x": 2,
      "y": 68,
      "z": 22,
      "name": "Wood_Deadwood_Roof",
      "rotation": 1
    },
    {
      "x": 2,
      "y": 58,
      "z": 23,
      "name": "Soil_Dirt_Cold"
    },
    {
      "x": 2,
      "y": 59,
      "z": 23,
      "name": "Soil_Dirt_Cold"
    },
    {
      "x": 2,
      "y": 60,
      "z": 23,
      "name": "Soil_Dirt_Cold"
    },
    {
      "x": 2,
      "y": 61,
      "z": 23,
      "name": "Soil_Dirt_Cold"
    },
    {
      "x": 2,
      "y": 62,
      "z": 23,
      "name": "Empty"
    },
    {
      "x": 2,
      "y": 63,
      "z": 23,
      "name": "Empty"
    },
    {
      "x": 2,
      "y": 64,
      "z": 23,
      "name": "Wood_Redwood_Trunk",
      "rotation": 4
    },
    {
      "x": 2,
      "y": 65,
      "z": 23,
      "name": "Empty"
    },
    {
      "x": 2,
      "y": 66,
      "z": 23,
      "name": "Empty"
    },
    {
      "x": 2,
      "y": 67,
      "z": 23,
      "name": "Wood_Redwood_Planks"
    },
    {
      "x": 2,
      "y": 68,
      "z": 23,
      "name": "Wood_Deadwood_Roof",
      "rotation": 1
    },
    {
      "x": 2,
      "y": 58,
      "z": 24,
      "name": "Soil_Dirt_Cold"
    },
    {
      "x": 2,
      "y": 59,
      "z": 24,
      "name": "Soil_Dirt_Cold"
    },
    {
      "x": 2,
      "y": 60,
      "z": 24,
      "name": "Soil_Dirt_Cold"
    },
    {
      "x": 2,
      "y": 61,
      "z": 24,
      "name": "Soil_Dirt_Cold"
    },
    {
      "x": 2,
      "y": 62,
      "z": 24,
      "name": "Empty"
    },
    {
      "x": 2,
      "y": 63,
      "z": 24,
      "name": "Empty"
    },
    {
      "x": 2,
      "y": 64,
      "z": 24,
      "name": "Wood_Redwood_Trunk",
      "rotation": 4
    },
    {
      "x": 2,
      "y": 65,
      "z": 24,
      "name": "Empty"
    },
    {
      "x": 2,
      "y": 66,
      "z": 24,
      "name": "Empty"
    },
    {
      "x": 2,
      "y": 67,
      "z": 24,
      "name": "Wood_Redwood_Planks"
    },
    {
      "x": 2,
      "y": 68,
      "z": 24,
      "name": "Wood_Deadwood_Roof",
      "rotation": 1
    },
    {
      "x": 2,
      "y": 58,
      "z": 25,
      "name": "Soil_Dirt_Cold"
    },
    {
      "x": 2,
      "y": 59,
      "z": 25,
      "name": "Soil_Dirt_Cold"
    },
    {
      "x": 2,
      "y": 60,
      "z": 25,
      "name": "Soil_Dirt_Cold"
    },
    {
      "x": 2,
      "y": 61,
      "z": 25,
      "name": "Soil_Dirt_Cold"
    },
    {
      "x": 2,
      "y": 62,
      "z": 25,
      "name": "Empty"
    },
    {
      "x": 2,
      "y": 63,
      "z": 25,
      "name": "Empty"
    },
    {
      "x": 2,
      "y": 64,
      "z": 25,
      "name": "Wood_Redwood_Trunk",
      "rotation": 4
    },
    {
      "x": 2,
      "y": 65,
      "z": 25,
      "name": "Empty"
    },
    {
      "x": 2,
      "y": 66,
      "z": 25,
      "name": "Empty"
    },
    {
      "x": 2,
      "y": 67,
      "z": 25,
      "name": "Wood_Redwood_Planks"
    },
    {
      "x": 2,
      "y": 68,
      "z": 25,
      "name": "Wood_Deadwood_Roof",
      "rotation": 1
    },
    {
      "x": 2,
      "y": 58,
      "z": 26,
      "name": "Soil_Dirt_Cold"
    },
    {
      "x": 2,
      "y": 59,
      "z": 26,
      "name": "Soil_Dirt_Cold"
    },
    {
      "x": 2,
      "y": 60,
      "z": 26,
      "name": "Soil_Dirt_Cold"
    },
    {
      "x": 2,
      "y": 61,
      "z": 26,
      "name": "Soil_Dirt_Cold"
    },
    {
      "x": 2,
      "y": 62,
      "z": 26,
      "name": "Empty"
    },
    {
      "x": 2,
      "y": 63,
      "z": 26,
      "name": "Empty"
    },
    {
      "x": 2,
      "y": 64,
      "z": 26,
      "name": "Wood_Redwood_Trunk",
      "rotation": 4
    },
    {
      "x": 2,
      "y": 65,
      "z": 26,
      "name": "Empty"
    },
    {
      "x": 2,
      "y": 66,
      "z": 26,
      "name": "Empty"
    },
    {
      "x": 2,
      "y": 67,
      "z": 26,
      "name": "Wood_Redwood_Planks"
    },
    {
      "x": 2,
      "y": 68,
      "z": 26,
      "name": "Wood_Deadwood_Roof",
      "rotation": 1
    },
    {
      "x": 2,
      "y": 59,
      "z": 27,
      "name": "Soil_Dirt_Cold"
    },
    {
      "x": 2,
      "y": 60,
      "z": 27,
      "name": "Soil_Dirt_Cold"
    },
    {
      "x": 2,
      "y": 61,
      "z": 27,
      "name": "Soil_Dirt_Cold"
    },
    {
      "x": 2,
      "y": 62,
      "z": 27,
      "name": "Rock_Shale"
    },
    {
      "x": 2,
      "y": 63,
      "z": 27,
      "name": "Rock_Shale"
    },
    {
      "x": 2,
      "y": 64,
      "z": 27,
      "name": "Wood_Redwood_Planks"
    },
    {
      "x": 2,
      "y": 65,
      "z": 27,
      "name": "Wood_Redwood_Trunk",
      "rotation": 5
    },
    {
      "x": 2,
      "y": 66,
      "z": 27,
      "name": "Wood_Redwood_Planks"
    },
    {
      "x": 2,
      "y": 67,
      "z": 27,
      "name": "Wood_Redwood_Planks"
    },
    {
      "x": 2,
      "y": 68,
      "z": 27,
      "name": "Wood_Deadwood_Roof",
      "rotation": 1
    },
    {
      "x": 2,
      "y": 66,
      "z": 28,
      "name": "Wood_Redwood_Stairs",
      "rotation": 9
    },
    {
      "x": 2,
      "y": 67,
      "z": 28,
      "name": "Wood_Redwood_Planks"
    },
    {
      "x": 2,
      "y": 68,
      "z": 28,
      "name": "Wood_Deadwood_Roof",
      "rotation": 1
    },
    {
      "x": 3,
      "y": 60,
      "z": 14,
      "name": "Soil_Dirt_Cold"
    },
    {
      "x": 3,
      "y": 61,
      "z": 14,
      "name": "Soil_Dirt_Cold"
    },
    {
      "x": 3,
      "y": 62,
      "z": 14,
      "name": "Empty"
    },
    {
      "x": 3,
      "y": 63,
      "z": 14,
      "name": "Empty"
    },
    {
      "x": 3,
      "y": 64,
      "z": 14,
      "name": "Empty"
    },
    {
      "x": 3,
      "y": 59,
      "z": 15,
      "name": "Soil_Dirt_Cold"
    },
    {
      "x": 3,
      "y": 60,
      "z": 15,
      "name": "Soil_Dirt_Cold"
    },
    {
      "x": 3,
      "y": 61,
      "z": 15,
      "name": "Soil_Dirt_Cold"
    },
    {
      "x": 3,
      "y": 62,
      "z": 15,
      "name": "Empty"
    },
    {
      "x": 3,
      "y": 63,
      "z": 15,
      "name": "Empty"
    },
    {
      "x": 3,
      "y": 64,
      "z": 15,
      "name": "Wood_Deadwood_Roof",
      "rotation": 2
    },
    {
      "x": 3,
      "y": 65,
      "z": 15,
      "name": "Wood_Redwood_Stairs",
      "rotation": 9
    },
    {
      "x": 3,
      "y": 66,
      "z": 15,
      "name": "Wood_Redwood_Stairs",
      "rotation": 1
    },
    {
      "x": 3,
      "y": 58,
      "z": 16,
      "name": "Soil_Dirt_Cold"
    },
    {
      "x": 3,
      "y": 59,
      "z": 16,
      "name": "Soil_Dirt_Cold"
    },
    {
      "x": 3,
      "y": 60,
      "z": 16,
      "name": "Soil_Dirt_Cold"
    },
    {
      "x": 3,
      "y": 61,
      "z": 16,
      "name": "Soil_Dirt_Cold"
    },
    {
      "x": 3,
      "y": 62,
      "z": 16,
      "name": "Furniture_Lumberjack_Door",
      "rotation": 2
    },
    {
      "x": 3,
      "y": 63,
      "z": 16,
      "name": "Furniture_Lumberjack_Door",
      "filler": 1024,
      "rotation": 2
    },
    {
      "x": 3,
      "y": 64,
      "z": 16,
      "name": "Wood_Redwood_Trunk",
      "rotation": 5
    },
    {
      "x": 3,
      "y": 65,
      "z": 16,
      "name": "Wood_Redwood_Planks"
    },
    {
      "x": 3,
      "y": 66,
      "z": 16,
      "name": "Wood_Redwood_Planks"
    },
    {
      "x": 3,
      "y": 67,
      "z": 16,
      "name": "Wood_Deadwood_Roof",
      "rotation": 1
    },
    {
      "x": 3,
      "y": 58,
      "z": 17,
      "name": "Soil_Dirt_Cold"
    },
    {
      "x": 3,
      "y": 59,
      "z": 17,
      "name": "Soil_Dirt_Cold"
    },
    {
      "x": 3,
      "y": 60,
      "z": 17,
      "name": "Soil_Dirt_Cold"
    },
    {
      "x": 3,
      "y": 61,
      "z": 17,
      "name": "Soil_Dirt_Cold"
    },
    {
      "x": 3,
      "y": 62,
      "z": 17,
      "name": "Empty"
    },
    {
      "x": 3,
      "y": 63,
      "z": 17,
      "name": "Empty"
    },
    {
      "x": 3,
      "y": 64,
      "z": 17,
      "name": "Furniture_Lumberjack_Platform",
      "rotation": 1
    },
    {
      "x": 3,
      "y": 65,
      "z": 17,
      "name": "Furniture_Village_Crate"
    },
    {
      "x": 3,
      "y": 66,
      "z": 17,
      "name": "Wood_Redwood_Planks"
    },
    {
      "x": 3,
      "y": 67,
      "z": 17,
      "name": "Wood_Deadwood_Roof",
      "rotation": 1
    },
    {
      "x": 3,
      "y": 58,
      "z": 18,
      "name": "Soil_Dirt_Cold"
    },
    {
      "x": 3,
      "y": 59,
      "z": 18,
      "name": "Soil_Dirt_Cold"
    },
    {
      "x": 3,
      "y": 60,
      "z": 18,
      "name": "Soil_Dirt_Cold"
    },
    {
      "x": 3,
      "y": 61,
      "z": 18,
      "name": "Soil_Dirt_Cold"
    },
    {
      "x": 3,
      "y": 62,
      "z": 18,
      "name": "Empty"
    },
    {
      "x": 3,
      "y": 63,
      "z": 18,
      "name": "Empty"
    },
    {
      "x": 3,
      "y": 64,
      "z": 18,
      "name": "Furniture_Lumberjack_Platform",
      "rotation": 1
    },
    {
      "x": 3,
      "y": 65,
      "z": 18,
      "name": "Empty"
    },
    {
      "x": 3,
      "y": 66,
      "z": 18,
      "name": "Wood_Redwood_Planks"
    },
    {
      "x": 3,
      "y": 67,
      "z": 18,
      "name": "Wood_Deadwood_Roof",
      "rotation": 1
    },
    {
      "x": 3,
      "y": 58,
      "z": 19,
      "name": "Soil_Dirt_Cold"
    },
    {
      "x": 3,
      "y": 59,
      "z": 19,
      "name": "Soil_Dirt_Cold"
    },
    {
      "x": 3,
      "y": 60,
      "z": 19,
      "name": "Soil_Dirt_Cold"
    },
    {
      "x": 3,
      "y": 61,
      "z": 19,
      "name": "Soil_Dirt_Cold"
    },
    {
      "x": 3,
      "y": 62,
      "z": 19,
      "name": "Block_Spawner_Block",
      "components": {
        "Components": {
          "BlockSpawner": {
            "BlockSpawnerId": "Zone3_Outlander_Tier1"
          }
        }
      },
      "rotation": 2
    },
    {
      "x": 3,
      "y": 63,
      "z": 19,
      "name": "Empty"
    },
    {
      "x": 3,
      "y": 64,
      "z": 19,
      "name": "Furniture_Lumberjack_Platform",
      "rotation": 1
    },
    {
      "x": 3,
      "y": 65,
      "z": 19,
      "name": "Empty"
    },
    {
      "x": 3,
      "y": 66,
      "z": 19,
      "name": "Wood_Redwood_Planks"
    },
    {
      "x": 3,
      "y": 67,
      "z": 19,
      "name": "Wood_Deadwood_Roof",
      "rotation": 1
    },
    {
      "x": 3,
      "y": 58,
      "z": 20,
      "name": "Soil_Dirt_Cold"
    },
    {
      "x": 3,
      "y": 59,
      "z": 20,
      "name": "Soil_Dirt_Cold"
    },
    {
      "x": 3,
      "y": 60,
      "z": 20,
      "name": "Soil_Dirt_Cold"
    },
    {
      "x": 3,
      "y": 61,
      "z": 20,
      "name": "Soil_Dirt_Cold"
    },
    {
      "x": 3,
      "y": 62,
      "z": 20,
      "name": "Furniture_Lumberjack_Bed",
      "components": {
        "Components": {
          "RespawnBlock": {}
        }
      },
      "filler": 991,
      "rotation": 2
    },
    {
      "x": 3,
      "y": 63,
      "z": 20,
      "name": "Furniture_Lumberjack_Bed",
      "components": {
        "Components": {
          "RespawnBlock": {}
        }
      },
      "filler": 2015,
      "rotation": 2
    },
    {
      "x": 3,
      "y": 64,
      "z": 20,
      "name": "Wood_Redwood_Trunk",
      "rotation": 5
    },
    {
      "x": 3,
      "y": 65,
      "z": 20,
      "name": "Furniture_Ancient_Barrel"
    },
    {
      "x": 3,
      "y": 66,
      "z": 20,
      "name": "Wood_Redwood_Planks"
    },
    {
      "x": 3,
      "y": 67,
      "z": 20,
      "name": "Wood_Deadwood_Roof",
      "rotation": 1
    },
    {
      "x": 3,
      "y": 58,
      "z": 21,
      "name": "Soil_Dirt_Cold"
    },
    {
      "x": 3,
      "y": 59,
      "z": 21,
      "name": "Soil_Dirt_Cold"
    },
    {
      "x": 3,
      "y": 60,
      "z": 21,
      "name": "Soil_Dirt_Cold"
    },
    {
      "x": 3,
      "y": 61,
      "z": 21,
      "name": "Soil_Dirt_Cold"
    },
    {
      "x": 3,
      "y": 62,
      "z": 21,
      "name": "Furniture_Lumberjack_Bed",
      "components": {
        "Components": {
          "RespawnBlock": {}
        }
      },
      "filler": 1023,
      "rotation": 2
    },
    {
      "x": 3,
      "y": 63,
      "z": 21,
      "name": "Furniture_Lumberjack_Bed",
      "components": {
        "Components": {
          "RespawnBlock": {}
        }
      },
      "filler": 2047,
      "rotation": 2
    },
    {
      "x": 3,
      "y": 64,
      "z": 21,
      "name": "Furniture_Lumberjack_Platform"
    },
    {
      "x": 3,
      "y": 65,
      "z": 21,
      "name": "Furniture_Village_Crate"
    },
    {
      "x": 3,
      "y": 66,
      "z": 21,
      "name": "Wood_Redwood_Planks"
    },
    {
      "x": 3,
      "y": 67,
      "z": 21,
      "name": "Wood_Deadwood_Roof",
      "rotation": 1
    },
    {
      "x": 3,
      "y": 58,
      "z": 22,
      "name": "Soil_Dirt_Cold"
    },
    {
      "x": 3,
      "y": 59,
      "z": 22,
      "name": "Soil_Dirt_Cold"
    },
    {
      "x": 3,
      "y": 60,
      "z": 22,
      "name": "Soil_Dirt_Cold"
    },
    {
      "x": 3,
      "y": 61,
      "z": 22,
      "name": "Soil_Dirt_Cold"
    },
    {
      "x": 3,
      "y": 62,
      "z": 22,
      "name": "Furniture_Lumberjack_Bed",
      "components": {
        "Components": {
          "RespawnBlock": {}
        }
      },
      "filler": 31,
      "rotation": 2
    },
    {
      "x": 3,
      "y": 63,
      "z": 22,
      "name": "Furniture_Lumberjack_Bed",
      "components": {
        "Components": {
          "RespawnBlock": {}
        }
      },
      "filler": 1055,
      "rotation": 2
    },
    {
      "x": 3,
      "y": 64,
      "z": 22,
      "name": "Furniture_Lumberjack_Platform"
    },
    {
      "x": 3,
      "y": 65,
      "z": 22,
      "name": "Furniture_Village_Crate"
    },
    {
      "x": 3,
      "y": 66,
      "z": 22,
      "name": "Wood_Redwood_Planks"
    },
    {
      "x": 3,
      "y": 67,
      "z": 22,
      "name": "Wood_Deadwood_Roof",
      "rotation": 1
    },
    {
      "x": 3,
      "y": 58,
      "z": 23,
      "name": "Soil_Dirt_Cold"
    },
    {
      "x": 3,
      "y": 59,
      "z": 23,
      "name": "Soil_Dirt_Cold"
    },
    {
      "x": 3,
      "y": 60,
      "z": 23,
      "name": "Soil_Dirt_Cold"
    },
    {
      "x": 3,
      "y": 61,
      "z": 23,
      "name": "Soil_Dirt_Cold"
    },
    {
      "x": 3,
      "y": 62,
      "z": 23,
      "name": "Empty"
    },
    {
      "x": 3,
      "y": 63,
      "z": 23,
      "name": "Empty"
    },
    {
      "x": 3,
      "y": 64,
      "z": 23,
      "name": "Furniture_Lumberjack_Platform"
    },
    {
      "x": 3,
      "y": 65,
      "z": 23,
      "name": "Furniture_Ancient_Barrel"
    },
    {
      "x": 3,
      "y": 66,
      "z": 23,
      "name": "Wood_Redwood_Planks"
    },
    {
      "x": 3,
      "y": 67,
      "z": 23,
      "name": "Wood_Deadwood_Roof",
      "rotation": 1
    },
    {
      "x": 3,
      "y": 58,
      "z": 24,
      "name": "Soil_Dirt_Cold"
    },
    {
      "x": 3,
      "y": 59,
      "z": 24,
      "name": "Soil_Dirt_Cold"
    },
    {
      "x": 3,
      "y": 60,
      "z": 24,
      "name": "Soil_Dirt_Cold"
    },
    {
      "x": 3,
      "y": 61,
      "z": 24,
      "name": "Soil_Dirt_Cold"
    },
    {
      "x": 3,
      "y": 62,
      "z": 24,
      "name": "Empty"
    },
    {
      "x": 3,
      "y": 63,
      "z": 24,
      "name": "Empty"
    },
    {
      "x": 3,
      "y": 64,
      "z": 24,
      "name": "Furniture_Lumberjack_Platform"
    },
    {
      "x": 3,
      "y": 65,
      "z": 24,
      "name": "Empty"
    },
    {
      "x": 3,
      "y": 66,
      "z": 24,
      "name": "Wood_Redwood_Planks"
    },
    {
      "x": 3,
      "y": 67,
      "z": 24,
      "name": "Wood_Deadwood_Roof",
      "rotation": 1
    },
    {
      "x": 3,
      "y": 58,
      "z": 25,
      "name": "Soil_Dirt_Cold"
    },
    {
      "x": 3,
      "y": 59,
      "z": 25,
      "name": "Soil_Dirt_Cold"
    },
    {
      "x": 3,
      "y": 60,
      "z": 25,
      "name": "Soil_Dirt_Cold"
    },
    {
      "x": 3,
      "y": 61,
      "z": 25,
      "name": "Soil_Dirt_Cold"
    },
    {
      "x": 3,
      "y": 62,
      "z": 25,
      "name": "Empty"
    },
    {
      "x": 3,
      "y": 63,
      "z": 25,
      "name": "Empty"
    },
    {
      "x": 3,
      "y": 64,
      "z": 25,
      "name": "Furniture_Lumberjack_Platform"
    },
    {
      "x": 3,
      "y": 65,
      "z": 25,
      "name": "Furniture_Ancient_Barrel"
    },
    {
      "x": 3,
      "y": 66,
      "z": 25,
      "name": "Wood_Redwood_Planks"
    },
    {
      "x": 3,
      "y": 67,
      "z": 25,
      "name": "Wood_Deadwood_Roof",
      "rotation": 1
    },
    {
      "x": 3,
      "y": 58,
      "z": 26,
      "name": "Soil_Dirt_Cold"
    },
    {
      "x": 3,
      "y": 59,
      "z": 26,
      "name": "Soil_Dirt_Cold"
    },
    {
      "x": 3,
      "y": 60,
      "z": 26,
      "name": "Soil_Dirt_Cold"
    },
    {
      "x": 3,
      "y": 61,
      "z": 26,
      "name": "Soil_Dirt_Cold"
    },
    {
      "x": 3,
      "y": 62,
      "z": 26,
      "name": "Furniture_Lumberjack_Wardrobe",
      "rotation": 2
    },
    {
      "x": 3,
      "y": 63,
      "z": 26,
      "name": "Furniture_Lumberjack_Wardrobe",
      "filler": 1024,
      "rotation": 2
    },
    {
      "x": 3,
      "y": 64,
      "z": 26,
      "name": "Furniture_Lumberjack_Platform"
    },
    {
      "x": 3,
      "y": 65,
      "z": 26,
      "name": "Furniture_Village_Crate"
    },
    {
      "x": 3,
      "y": 66,
      "z": 26,
      "name": "Wood_Redwood_Planks"
    },
    {
      "x": 3,
      "y": 67,
      "z": 26,
      "name": "Wood_Deadwood_Roof",
      "rotation": 1
    },
    {
      "x": 3,
      "y": 59,
      "z": 27,
      "name": "Soil_Dirt_Cold"
    },
    {
      "x": 3,
      "y": 60,
      "z": 27,
      "name": "Soil_Dirt_Cold"
    },
    {
      "x": 3,
      "y": 61,
      "z": 27,
      "name": "Soil_Dirt_Cold"
    },
    {
      "x": 3,
      "y": 62,
      "z": 27,
      "name": "Rock_Shale"
    },
    {
      "x": 3,
      "y": 63,
      "z": 27,
      "name": "Rock_Shale"
    },
    {
      "x": 3,
      "y": 64,
      "z": 27,
      "name": "Wood_Redwood_Planks"
    },
    {
      "x": 3,
      "y": 65,
      "z": 27,
      "name": "Wood_Redwood_Trunk",
      "rotation": 5
    },
    {
      "x": 3,
      "y": 66,
      "z": 27,
      "name": "Wood_Redwood_Planks"
    },
    {
      "x": 3,
      "y": 67,
      "z": 27,
      "name": "Wood_Deadwood_Roof",
      "rotation": 1
    },
    {
      "x": 3,
      "y": 65,
      "z": 28,
      "name": "Wood_Redwood_Stairs",
      "rotation": 9
    },
    {
      "x": 3,
      "y": 66,
      "z": 28,
      "name": "Wood_Redwood_Stairs",
      "rotation": 1
    },
    {
      "x": 3,
      "y": 67,
      "z": 28,
      "name": "Wood_Deadwood_Roof",
      "rotation": 1
    },
    {
      "x": 4,
      "y": 60,
      "z": 14,
      "name": "Soil_Dirt_Cold"
    },
    {
      "x": 4,
      "y": 61,
      "z": 14,
      "name": "Soil_Dirt_Cold"
    },
    {
      "x": 4,
      "y": 62,
      "z": 14,
      "name": "Empty"
    },
    {
      "x": 4,
      "y": 63,
      "z": 14,
      "name": "Empty"
    },
    {
      "x": 4,
      "y": 64,
      "z": 14,
      "name": "Empty"
    },
    {
      "x": 4,
      "y": 59,
      "z": 15,
      "name": "Soil_Dirt_Cold"
    },
    {
      "x": 4,
      "y": 60,
      "z": 15,
      "name": "Soil_Dirt_Cold"
    },
    {
      "x": 4,
      "y": 61,
      "z": 15,
      "name": "Soil_Dirt_Cold"
    },
    {
      "x": 4,
      "y": 62,
      "z": 15,
      "name": "Empty"
    },
    {
      "x": 4,
      "y": 63,
      "z": 15,
      "name": "Empty"
    },
    {
      "x": 4,
      "y": 64,
      "z": 15,
      "name": "Wood_Redwood_Stairs",
      "rotation": 9
    },
    {
      "x": 4,
      "y": 65,
      "z": 15,
      "name": "Wood_Redwood_Planks"
    },
    {
      "x": 4,
      "y": 66,
      "z": 15,
      "name": "Wood_Deadwood_Roof",
      "rotation": 1
    },
    {
      "x": 4,
      "y": 58,
      "z": 16,
      "name": "Soil_Dirt_Cold"
    },
    {
      "x": 4,
      "y": 59,
      "z": 16,
      "name": "Soil_Dirt_Cold"
    },
    {
      "x": 4,
      "y": 60,
      "z": 16,
      "name": "Soil_Dirt_Cold"
    },
    {
      "x": 4,
      "y": 61,
      "z": 16,
      "name": "Soil_Dirt_Cold"
    },
    {
      "x": 4,
      "y": 62,
      "z": 16,
      "name": "Rock_Shale_Brick"
    },
    {
      "x": 4,
      "y": 63,
      "z": 16,
      "name": "Rock_Shale_Brick"
    },
    {
      "x": 4,
      "y": 64,
      "z": 16,
      "name": "Wood_Redwood_Trunk",
      "rotation": 5
    },
    {
      "x": 4,
      "y": 65,
      "z": 16,
      "name": "Wood_Redwood_Planks"
    },
    {
      "x": 4,
      "y": 66,
      "z": 16,
      "name": "Wood_Deadwood_Roof",
      "rotation": 1
    },
    {
      "x": 4,
      "y": 58,
      "z": 17,
      "name": "Soil_Dirt_Cold"
    },
    {
      "x": 4,
      "y": 59,
      "z": 17,
      "name": "Soil_Dirt_Cold"
    },
    {
      "x": 4,
      "y": 60,
      "z": 17,
      "name": "Soil_Dirt_Cold"
    },
    {
      "x": 4,
      "y": 61,
      "z": 17,
      "name": "Soil_Dirt_Cold"
    },
    {
      "x": 4,
      "y": 62,
      "z": 17,
      "name": "Empty"
    },
    {
      "x": 4,
      "y": 63,
      "z": 17,
      "name": "Empty"
    },
    {
      "x": 4,
      "y": 64,
      "z": 17,
      "name": "Furniture_Lumberjack_Platform",
      "rotation": 1
    },
    {
      "x": 4,
      "y": 65,
      "z": 17,
      "name": "Wood_Redwood_Planks"
    },
    {
      "x": 4,
      "y": 66,
      "z": 17,
      "name": "Wood_Deadwood_Roof",
      "rotation": 1
    },
    {
      "x": 4,
      "y": 58,
      "z": 18,
      "name": "Soil_Dirt_Cold"
    },
    {
      "x": 4,
      "y": 59,
      "z": 18,
      "name": "Soil_Dirt_Cold"
    },
    {
      "x": 4,
      "y": 60,
      "z": 18,
      "name": "Soil_Dirt_Cold"
    },
    {
      "x": 4,
      "y": 61,
      "z": 18,
      "name": "Soil_Dirt_Cold"
    },
    {
      "x": 4,
      "y": 62,
      "z": 18,
      "name": "Empty"
    },
    {
      "x": 4,
      "y": 63,
      "z": 18,
      "name": "Empty"
    },
    {
      "x": 4,
      "y": 64,
      "z": 18,
      "name": "Furniture_Lumberjack_Platform",
      "rotation": 1
    },
    {
      "x": 4,
      "y": 65,
      "z": 18,
      "name": "Wood_Redwood_Planks"
    },
    {
      "x": 4,
      "y": 66,
      "z": 18,
      "name": "Wood_Deadwood_Roof",
      "rotation": 1
    },
    {
      "x": 4,
      "y": 58,
      "z": 19,
      "name": "Soil_Dirt_Cold"
    },
    {
      "x": 4,
      "y": 59,
      "z": 19,
      "name": "Soil_Dirt_Cold"
    },
    {
      "x": 4,
      "y": 60,
      "z": 19,
      "name": "Soil_Dirt_Cold"
    },
    {
      "x": 4,
      "y": 61,
      "z": 19,
      "name": "Soil_Dirt_Cold"
    },
    {
      "x": 4,
      "y": 62,
      "z": 19,
      "name": "Empty"
    },
    {
      "x": 4,
      "y": 63,
      "z": 19,
      "name": "Empty"
    },
