{
  "version": 8,
  "blockIdVersion": 8,
  "anchorX": -1,
  "anchorY": 8,
  "anchorZ": -2,
  "blocks": [
    {
      "x": -6,
      "y": 9,
      "z": -2,
      "name": "Rock_Slate"
    },
    {
      "x": -6,
      "y": 10,
      "z": -2,
      "name": "Rock_Slate"
    },
    {
      "x": -6,
      "y": 11,
      "z": -2,
      "name": "Rock_Slate"
    },
    {
      "x": -6,
      "y": 12,
      "z": -2,
      "name": "Rock_Slate"
    },
    {
      "x": -6,
      "y": 13,
      "z": -2,
      "name": "Rock_Slate"
    },
    {
      "x": -6,
      "y": 9,
      "z": -1,
      "name": "Rock_Slate"
    },
    {
      "x": -6,
      "y": 10,
      "z": -1,
      "name": "Rock_Slate"
    },
    {
      "x": -6,
      "y": 11,
      "z": -1,
      "name": "Rock_Slate"
    },
    {
      "x": -6,
      "y": 12,
      "z": -1,
      "name": "Rock_Slate"
    },
    {
      "x": -6,
      "y": 13,
      "z": -1,
      "name": "Rock_Slate"
    },
    {
      "x": -5,
      "y": 6,
      "z": -3,
      "name": "Rock_Slate"
    },
    {
      "x": -5,
      "y": 7,
      "z": -3,
      "name": "Rock_Slate"
    },
    {
      "x": -5,
      "y": 8,
      "z": -3,
      "name": "Rock_Slate"
    },
    {
      "x": -5,
      "y": 9,
      "z": -3,
      "name": "Rock_Slate"
    },
    {
      "x": -5,
      "y": 10,
      "z": -3,
      "name": "Rock_Slate"
    },
    {
      "x": -5,
      "y": 11,
      "z": -3,
      "name": "Rock_Slate"
    },
    {
      "x": -5,
      "y": 12,
      "z": -3,
      "name": "Rock_Slate"
    },
    {
      "x": -5,
      "y": 13,
      "z": -3,
      "name": "Rock_Slate"
    },
    {
      "x": -5,
      "y": 5,
      "z": -2,
      "name": "Rock_Slate"
    },
    {
      "x": -5,
      "y": 6,
      "z": -2,
      "name": "Rock_Slate"
    },
    {
      "x": -5,
      "y": 7,
      "z": -2,
      "name": "Rock_Slate"
    },
    {
      "x": -5,
      "y": 8,
      "z": -2,
      "name": "Rock_Slate"
    },
    {
      "x": -5,
      "y": 9,
      "z": -2,
      "name": "Rock_Slate"
    },
    {
      "x": -5,
      "y": 10,
      "z": -2,
      "name": "Rock_Slate"
    },
    {
      "x": -5,
      "y": 11,
      "z": -2,
      "name": "Rock_Slate"
    },
    {
      "x": -5,
      "y": 12,
      "z": -2,
      "name": "Rock_Slate"
    },
    {
      "x": -5,
      "y": 13,
      "z": -2,
      "name": "Rock_Slate"
    },
    {
      "x": -5,
      "y": 14,
      "z": -2,
      "name": "Rubble_Slate_Medium"
    },
    {
      "x": -5,
      "y": 6,
      "z": -1,
      "name": "Rock_Slate"
    },
    {
      "x": -5,
      "y": 7,
      "z": -1,
      "name": "Rock_Slate"
    },
    {
      "x": -5,
      "y": 8,
      "z": -1,
      "name": "Rock_Slate"
    },
    {
      "x": -5,
      "y": 9,
      "z": -1,
      "name": "Rock_Slate"
    },
    {
      "x": -5,
      "y": 10,
      "z": -1,
      "name": "Rock_Slate"
    },
    {
      "x": -5,
      "y": 11,
      "z": -1,
      "name": "Rock_Slate"
    },
    {
      "x": -5,
      "y": 12,
      "z": -1,
      "name": "Rock_Slate"
    },
    {
      "x": -5,
      "y": 13,
      "z": -1,
      "name": "Rock_Slate"
    },
    {
      "x": -5,
      "y": 14,
      "z": -1,
      "name": "Rubble_Slate"
    },
    {
      "x": -5,
      "y": 7,
      "z": 0,
      "name": "Rock_Slate"
    },
    {
      "x": -5,
      "y": 8,
      "z": 0,
      "name": "Rock_Slate"
    },
    {
      "x": -5,
      "y": 9,
      "z": 0,
      "name": "Rock_Slate"
    },
    {
      "x": -5,
      "y": 10,
      "z": 0,
      "name": "Rock_Slate"
    },
    {
      "x": -5,
      "y": 11,
      "z": 0,
      "name": "Rock_Slate"
    },
    {
      "x": -5,
      "y": 12,
      "z": 0,
      "name": "Rock_Slate"
    },
    {
      "x": -5,
      "y": 13,
      "z": 0,
      "name": "Rock_Slate"
    },
    {
      "x": -4,
      "y": 8,
      "z": -5,
      "name": "Rock_Slate"
    },
    {
      "x": -4,
      "y": 9,
      "z": -5,
      "name": "Rock_Slate"
    },
    {
      "x": -4,
      "y": 10,
      "z": -5,
      "name": "Rock_Slate"
    },
    {
      "x": -4,
      "y": 11,
      "z": -5,
      "name": "Rock_Slate"
    },
    {
      "x": -4,
      "y": 12,
      "z": -5,
      "name": "Rock_Slate"
    },
    {
      "x": -4,
      "y": 13,
      "z": -5,
      "name": "Rock_Slate"
    },
    {
      "x": -4,
      "y": 5,
      "z": -4,
      "name": "Rock_Slate"
    },
    {
      "x": -4,
      "y": 6,
      "z": -4,
      "name": "Rock_Slate"
    },
    {
      "x": -4,
      "y": 7,
      "z": -4,
      "name": "Rock_Slate"
    },
    {
      "x": -4,
      "y": 8,
      "z": -4,
      "name": "Rock_Slate"
    },
    {
      "x": -4,
      "y": 9,
      "z": -4,
      "name": "Rock_Slate"
    },
    {
      "x": -4,
      "y": 10,
      "z": -4,
      "name": "Rock_Slate"
    },
    {
      "x": -4,
      "y": 11,
      "z": -4,
      "name": "Rock_Slate"
    },
    {
      "x": -4,
      "y": 12,
      "z": -4,
      "name": "Rock_Slate"
    },
    {
      "x": -4,
      "y": 13,
      "z": -4,
      "name": "Rock_Slate"
    },
    {
      "x": -4,
      "y": 14,
      "z": -4,
      "name": "Rubble_Slate"
    },
    {
      "x": -4,
      "y": 3,
      "z": -3,
      "name": "Rock_Slate"
    },
    {
      "x": -4,
      "y": 4,
      "z": -3,
      "name": "Rock_Slate"
    },
    {
      "x": -4,
      "y": 5,
      "z": -3,
      "name": "Rock_Slate"
    },
    {
      "x": -4,
      "y": 6,
      "z": -3,
      "name": "Rock_Slate"
    },
    {
      "x": -4,
      "y": 7,
      "z": -3,
      "name": "Rock_Slate"
    },
    {
      "x": -4,
      "y": 8,
      "z": -3,
      "name": "Rock_Slate"
    },
    {
      "x": -4,
      "y": 9,
      "z": -3,
      "name": "Rock_Slate"
    },
    {
      "x": -4,
      "y": 10,
      "z": -3,
      "name": "Rock_Slate"
    },
    {
      "x": -4,
      "y": 11,
      "z": -3,
      "name": "Rock_Slate"
    },
    {
      "x": -4,
      "y": 12,
      "z": -3,
      "name": "Rock_Slate"
    },
    {
      "x": -4,
      "y": 13,
      "z": -3,
      "name": "Rock_Slate"
    },
    {
      "x": -4,
      "y": 3,
      "z": -2,
      "name": "Rock_Slate"
    },
    {
      "x": -4,
      "y": 4,
      "z": -2,
      "name": "Rock_Slate"
    },
    {
      "x": -4,
      "y": 5,
      "z": -2,
      "name": "Rock_Slate"
    },
    {
      "x": -4,
      "y": 6,
      "z": -2,
      "name": "Rock_Slate"
    },
    {
      "x": -4,
      "y": 7,
      "z": -2,
      "name": "Rock_Slate"
    },
    {
      "x": -4,
      "y": 8,
      "z": -2,
      "name": "Rock_Slate"
    },
    {
      "x": -4,
      "y": 9,
      "z": -2,
      "name": "Rock_Slate"
    },
    {
      "x": -4,
      "y": 10,
      "z": -2,
      "name": "Rock_Slate"
    },
    {
      "x": -4,
      "y": 11,
      "z": -2,
      "name": "Rock_Slate"
    },
    {
      "x": -4,
      "y": 12,
      "z": -2,
      "name": "Rock_Slate"
    },
    {
      "x": -4,
      "y": 13,
      "z": -2,
      "name": "Rock_Slate"
    },
    {
      "x": -4,
      "y": 4,
      "z": -1,
      "name": "Rock_Slate"
    },
    {
      "x": -4,
      "y": 5,
      "z": -1,
      "name": "Rock_Slate"
    },
    {
      "x": -4,
      "y": 6,
      "z": -1,
      "name": "Rock_Slate"
    },
    {
      "x": -4,
      "y": 7,
      "z": -1,
      "name": "Rock_Slate"
    },
    {
      "x": -4,
      "y": 8,
      "z": -1,
      "name": "Rock_Slate"
    },
    {
      "x": -4,
      "y": 9,
      "z": -1,
      "name": "Rock_Slate"
    },
    {
      "x": -4,
      "y": 10,
      "z": -1,
      "name": "Rock_Slate"
    },
    {
      "x": -4,
      "y": 11,
      "z": -1,
      "name": "Rock_Slate"
    },
    {
      "x": -4,
      "y": 12,
      "z": -1,
      "name": "Rock_Slate"
    },
    {
      "x": -4,
      "y": 13,
      "z": -1,
      "name": "Rock_Slate"
    },
    {
      "x": -4,
      "y": 14,
      "z": -1,
      "name": "Rubble_Slate_Medium"
    },
    {
      "x": -4,
      "y": 5,
      "z": 0,
      "name": "Rock_Slate"
    },
    {
      "x": -4,
      "y": 6,
      "z": 0,
      "name": "Rock_Slate"
    },
    {
      "x": -4,
      "y": 7,
      "z": 0,
      "name": "Rock_Slate"
    },
    {
      "x": -4,
      "y": 8,
      "z": 0,
      "name": "Rock_Slate"
    },
    {
      "x": -4,
      "y": 9,
      "z": 0,
      "name": "Rock_Slate"
    },
    {
      "x": -4,
      "y": 10,
      "z": 0,
      "name": "Rock_Slate"
    },
    {
      "x": -4,
      "y": 11,
      "z": 0,
      "name": "Rock_Slate"
    },
    {
      "x": -4,
      "y": 12,
      "z": 0,
      "name": "Rock_Slate"
    },
    {
      "x": -4,
      "y": 13,
      "z": 0,
      "name": "Rock_Slate"
    },
    {
      "x": -4,
      "y": 5,
      "z": 1,
      "name": "Rock_Slate"
    },
    {
      "x": -4,
      "y": 6,
      "z": 1,
      "name": "Rock_Slate"
    },
    {
      "x": -4,
      "y": 7,
      "z": 1,
      "name": "Rock_Slate"
    },
    {
      "x": -4,
      "y": 8,
      "z": 1,
      "name": "Rock_Slate"
    },
    {
      "x": -4,
      "y": 9,
      "z": 1,
      "name": "Rock_Slate"
    },
    {
      "x": -4,
      "y": 10,
      "z": 1,
      "name": "Rock_Slate"
    },
    {
      "x": -4,
      "y": 11,
      "z": 1,
      "name": "Rock_Slate"
    },
    {
      "x": -4,
      "y": 12,
      "z": 1,
      "name": "Rock_Slate"
    },
    {
      "x": -4,
      "y": 13,
      "z": 1,
      "name": "Rock_Slate"
    },
    {
      "x": -3,
      "y": 10,
      "z": -6,
      "name": "Rock_Slate"
    },
    {
      "x": -3,
      "y": 11,
      "z": -6,
      "name": "Rock_Slate"
    },
    {
      "x": -3,
      "y": 12,
      "z": -6,
      "name": "Rock_Slate"
    },
    {
      "x": -3,
      "y": 13,
      "z": -6,
      "name": "Soil_Grass_Burnt"
    },
    {
      "x": -3,
      "y": 5,
      "z": -5,
      "name": "Rock_Slate"
    },
    {
      "x": -3,
      "y": 6,
      "z": -5,
      "name": "Rock_Slate"
    },
    {
      "x": -3,
      "y": 7,
      "z": -5,
      "name": "Rock_Slate"
    },
    {
      "x": -3,
      "y": 8,
      "z": -5,
      "name": "Rock_Slate"
    },
    {
      "x": -3,
      "y": 9,
      "z": -5,
      "name": "Rock_Slate"
    },
    {
      "x": -3,
      "y": 10,
      "z": -5,
      "name": "Rock_Slate"
    },
    {
      "x": -3,
      "y": 11,
      "z": -5,
      "name": "Rock_Slate"
    },
    {
      "x": -3,
      "y": 12,
      "z": -5,
      "name": "Rock_Slate"
    },
    {
      "x": -3,
      "y": 13,
      "z": -5,
      "name": "Soil_Grass_Burnt"
    },
    {
      "x": -3,
      "y": 14,
      "z": -5,
      "name": "Plant_Grass_Gnarled"
    },
    {
      "x": -3,
      "y": 4,
      "z": -4,
      "name": "Rock_Slate"
    },
    {
      "x": -3,
      "y": 5,
      "z": -4,
      "name": "Rock_Slate"
    },
    {
      "x": -3,
      "y": 6,
      "z": -4,
      "name": "Rock_Slate"
    },
    {
      "x": -3,
      "y": 7,
      "z": -4,
      "name": "Rock_Slate"
    },
    {
      "x": -3,
      "y": 8,
      "z": -4,
      "name": "Rock_Slate"
    },
    {
      "x": -3,
      "y": 9,
      "z": -4,
      "name": "Rock_Slate"
    },
    {
      "x": -3,
      "y": 10,
      "z": -4,
      "name": "Rock_Slate"
    },
    {
      "x": -3,
      "y": 11,
      "z": -4,
      "name": "Rock_Slate"
    },
    {
      "x": -3,
      "y": 12,
      "z": -4,
      "name": "Rock_Slate"
    },
    {
      "x": -3,
      "y": 13,
      "z": -4,
      "name": "Rock_Slate"
    },
    {
      "x": -3,
      "y": 3,
      "z": -3,
      "name": "Rock_Slate"
    },
    {
      "x": -3,
      "y": 4,
      "z": -3,
      "name": "Rock_Slate"
    },
    {
      "x": -3,
      "y": 5,
      "z": -3,
      "name": "Rock_Slate"
    },
    {
      "x": -3,
      "y": 6,
      "z": -3,
      "name": "Rock_Slate"
    },
    {
      "x": -3,
      "y": 7,
      "z": -3,
      "name": "Rock_Slate"
    },
    {
      "x": -3,
      "y": 8,
      "z": -3,
      "name": "Rock_Slate"
    },
    {
      "x": -3,
      "y": 9,
      "z": -3,
      "name": "Rock_Slate"
    },
    {
      "x": -3,
      "y": 10,
      "z": -3,
      "name": "Rock_Slate"
    },
    {
      "x": -3,
      "y": 11,
      "z": -3,
      "name": "Rock_Slate"
    },
    {
      "x": -3,
      "y": 12,
      "z": -3,
      "name": "Rock_Slate"
    },
    {
      "x": -3,
      "y": 13,
      "z": -3,
      "name": "Rock_Slate"
    },
    {
      "x": -3,
      "y": 3,
      "z": -2,
      "name": "Rock_Slate"
    },
    {
      "x": -3,
      "y": 4,
      "z": -2,
      "name": "Rock_Slate"
    },
    {
      "x": -3,
      "y": 5,
      "z": -2,
      "name": "Rock_Slate"
    },
    {
      "x": -3,
      "y": 6,
      "z": -2,
      "name": "Rock_Slate"
    },
    {
      "x": -3,
      "y": 7,
      "z": -2,
      "name": "Rock_Slate"
    },
    {
      "x": -3,
      "y": 8,
      "z": -2,
      "name": "Rock_Slate"
    },
    {
      "x": -3,
      "y": 9,
      "z": -2,
      "name": "Rock_Slate"
    },
    {
      "x": -3,
      "y": 10,
      "z": -2,
      "name": "Rock_Slate"
    },
    {
      "x": -3,
      "y": 11,
      "z": -2,
      "name": "Rock_Slate"
    },
    {
      "x": -3,
      "y": 12,
      "z": -2,
      "name": "Rock_Slate"
    },
    {
      "x": -3,
      "y": 13,
      "z": -2,
      "name": "Rock_Slate"
    },
    {
      "x": -3,
      "y": 3,
      "z": -1,
      "name": "Rock_Slate"
    },
    {
      "x": -3,
      "y": 4,
      "z": -1,
      "name": "Rock_Slate"
    },
    {
      "x": -3,
      "y": 5,
      "z": -1,
      "name": "Rock_Slate"
    },
    {
      "x": -3,
      "y": 6,
      "z": -1,
      "name": "Rock_Slate"
    },
    {
      "x": -3,
      "y": 7,
      "z": -1,
      "name": "Rock_Slate"
    },
    {
      "x": -3,
      "y": 8,
      "z": -1,
      "name": "Rock_Slate"
    },
    {
      "x": -3,
      "y": 9,
      "z": -1,
      "name": "Rock_Slate"
    },
    {
      "x": -3,
      "y": 10,
      "z": -1,
      "name": "Rock_Slate"
    },
    {
      "x": -3,
      "y": 11,
      "z": -1,
      "name": "Rock_Slate"
    },
    {
      "x": -3,
      "y": 12,
      "z": -1,
      "name": "Rock_Slate"
    },
    {
      "x": -3,
      "y": 13,
      "z": -1,
      "name": "Rock_Slate"
    },
    {
      "x": -3,
      "y": 3,
      "z": 0,
      "name": "Rock_Slate"
    },
    {
      "x": -3,
      "y": 4,
      "z": 0,
      "name": "Rock_Slate"
    },
    {
      "x": -3,
      "y": 5,
      "z": 0,
      "name": "Rock_Slate"
    },
    {
      "x": -3,
      "y": 6,
      "z": 0,
      "name": "Rock_Slate"
    },
    {
      "x": -3,
      "y": 7,
      "z": 0,
      "name": "Rock_Slate"
    },
    {
      "x": -3,
      "y": 8,
      "z": 0,
      "name": "Rock_Slate"
    },
    {
      "x": -3,
      "y": 9,
      "z": 0,
      "name": "Rock_Slate"
    },
    {
      "x": -3,
      "y": 10,
      "z": 0,
      "name": "Rock_Slate"
    },
    {
      "x": -3,
      "y": 11,
      "z": 0,
      "name": "Rock_Slate"
    },
    {
      "x": -3,
      "y": 12,
      "z": 0,
      "name": "Rock_Slate"
    },
    {
      "x": -3,
      "y": 13,
      "z": 0,
      "name": "Rock_Slate"
    },
    {
      "x": -3,
      "y": 5,
      "z": 1,
      "name": "Rock_Slate"
    },
    {
      "x": -3,
      "y": 6,
      "z": 1,
      "name": "Rock_Slate"
    },
    {
      "x": -3,
      "y": 7,
      "z": 1,
      "name": "Rock_Slate"
    },
    {
      "x": -3,
      "y": 8,
      "z": 1,
      "name": "Rock_Slate"
    },
    {
      "x": -3,
      "y": 9,
      "z": 1,
      "name": "Rock_Slate"
    },
    {
      "x": -3,
      "y": 10,
      "z": 1,
      "name": "Rock_Slate"
    },
    {
      "x": -3,
      "y": 11,
      "z": 1,
      "name": "Rock_Slate"
    },
    {
      "x": -3,
      "y": 12,
      "z": 1,
      "name": "Rock_Slate"
    },
    {
      "x": -3,
      "y": 13,
      "z": 1,
      "name": "Rock_Slate"
    },
    {
      "x": -3,
      "y": 14,
      "z": 1,
      "name": "Rubble_Slate"
    },
    {
      "x": -3,
      "y": 6,
      "z": 2,
      "name": "Rock_Slate"
    },
    {
      "x": -3,
      "y": 7,
      "z": 2,
      "name": "Rock_Slate"
    },
    {
      "x": -3,
      "y": 8,
      "z": 2,
      "name": "Rock_Slate"
    },
    {
      "x": -3,
      "y": 9,
      "z": 2,
      "name": "Rock_Slate"
    },
    {
      "x": -3,
      "y": 10,
      "z": 2,
      "name": "Rock_Slate"
    },
    {
      "x": -3,
      "y": 11,
      "z": 2,
      "name": "Rock_Slate"
    },
    {
      "x": -3,
      "y": 12,
      "z": 2,
      "name": "Rock_Slate"
    },
    {
      "x": -3,
      "y": 13,
      "z": 2,
      "name": "Rock_Slate"
    },
    {
      "x": -2,
      "y": 10,
      "z": -7,
      "name": "Rock_Slate"
    },
    {
      "x": -2,
      "y": 11,
      "z": -7,
      "name": "Rock_Slate"
    },
    {
      "x": -2,
      "y": 12,
      "z": -7,
      "name": "Rock_Slate"
    },
    {
      "x": -2,
      "y": 13,
      "z": -7,
      "name": "Soil_Grass_Burnt"
    },
    {
      "x": -2,
      "y": 14,
      "z": -7,
      "name": "Plant_Grass_Gnarled_Short"
    },
    {
      "x": -2,
      "y": 7,
      "z": -6,
      "name": "Rock_Slate"
    },
    {
      "x": -2,
      "y": 8,
      "z": -6,
      "name": "Rock_Slate"
    },
    {
      "x": -2,
      "y": 9,
      "z": -6,
      "name": "Rock_Slate"
    },
    {
      "x": -2,
      "y": 10,
      "z": -6,
      "name": "Rock_Slate"
    },
    {
      "x": -2,
      "y": 11,
      "z": -6,
      "name": "Rock_Slate"
    },
    {
      "x": -2,
      "y": 12,
      "z": -6,
      "name": "Rock_Slate"
    },
    {
      "x": -2,
      "y": 13,
      "z": -6,
      "name": "Soil_Grass_Burnt"
    },
    {
      "x": -2,
      "y": 5,
      "z": -5,
      "name": "Rock_Slate"
    },
    {
      "x": -2,
      "y": 6,
      "z": -5,
      "name": "Rock_Slate"
    },
    {
      "x": -2,
      "y": 7,
      "z": -5,
      "name": "Rock_Slate"
    },
    {
      "x": -2,
      "y": 8,
      "z": -5,
      "name": "Rock_Slate"
    },
    {
      "x": -2,
      "y": 9,
      "z": -5,
      "name": "Rock_Slate"
    },
    {
      "x": -2,
      "y": 10,
      "z": -5,
      "name": "Rock_Slate"
    },
    {
      "x": -2,
      "y": 11,
      "z": -5,
      "name": "Rock_Slate"
    },
    {
      "x": -2,
      "y": 12,
      "z": -5,
      "name": "Rock_Slate"
    },
    {
      "x": -2,
      "y": 13,
      "z": -5,
      "name": "Soil_Grass_Burnt"
    },
    {
      "x": -2,
      "y": 3,
      "z": -4,
      "name": "Rock_Slate"
    },
    {
      "x": -2,
      "y": 4,
      "z": -4,
      "name": "Rock_Slate"
    },
    {
      "x": -2,
      "y": 5,
      "z": -4,
      "name": "Rock_Slate"
    },
    {
      "x": -2,
      "y": 6,
      "z": -4,
      "name": "Rock_Slate"
    },
    {
      "x": -2,
      "y": 7,
      "z": -4,
      "name": "Rock_Slate"
    },
    {
      "x": -2,
      "y": 8,
      "z": -4,
      "name": "Rock_Slate"
    },
    {
      "x": -2,
      "y": 9,
      "z": -4,
      "name": "Rock_Slate"
    },
    {
      "x": -2,
      "y": 10,
      "z": -4,
      "name": "Rock_Slate"
    },
    {
      "x": -2,
      "y": 11,
      "z": -4,
      "name": "Rock_Slate"
    },
    {
      "x": -2,
      "y": 12,
      "z": -4,
      "name": "Rock_Slate"
    },
    {
      "x": -2,
      "y": 13,
      "z": -4,
      "name": "Soil_Grass_Burnt"
    },
    {
      "x": -2,
      "y": 14,
      "z": -4,
      "name": "Plant_Grass_Gnarled_Short"
    },
    {
      "x": -2,
      "y": 3,
      "z": -3,
      "name": "Rock_Slate"
    },
    {
      "x": -2,
      "y": 4,
      "z": -3,
      "name": "Rock_Slate"
    },
    {
      "x": -2,
      "y": 5,
      "z": -3,
      "name": "Rock_Slate"
    },
    {
      "x": -2,
      "y": 6,
      "z": -3,
      "name": "Rock_Slate"
    },
    {
      "x": -2,
      "y": 7,
      "z": -3,
      "name": "Rock_Slate"
    },
    {
      "x": -2,
      "y": 8,
      "z": -3,
      "name": "Rock_Slate"
    },
    {
      "x": -2,
      "y": 9,
      "z": -3,
      "name": "Rock_Slate"
    },
    {
      "x": -2,
      "y": 10,
      "z": -3,
      "name": "Rock_Slate"
    },
    {
      "x": -2,
      "y": 11,
      "z": -3,
      "name": "Rock_Slate"
    },
    {
      "x": -2,
      "y": 12,
      "z": -3,
      "name": "Rock_Slate"
    },
    {
      "x": -2,
      "y": 13,
      "z": -3,
      "name": "Soil_Grass_Burnt"
    },
    {
      "x": -2,
      "y": 14,
      "z": -3,
      "name": "Plant_Grass_Gnarled_Short"
    },
    {
      "x": -2,
      "y": 3,
      "z": -2,
      "name": "Rock_Slate"
    },
    {
      "x": -2,
      "y": 4,
      "z": -2,
      "name": "Rock_Slate"
    },
    {
      "x": -2,
      "y": 5,
      "z": -2,
      "name": "Rock_Slate"
    },
    {
      "x": -2,
      "y": 6,
      "z": -2,
      "name": "Rock_Slate"
    },
    {
      "x": -2,
      "y": 7,
      "z": -2,
      "name": "Rock_Slate"
    },
    {
      "x": -2,
      "y": 8,
      "z": -2,
      "name": "Rock_Slate"
    },
    {
      "x": -2,
      "y": 9,
      "z": -2,
      "name": "Rock_Slate"
    },
    {
      "x": -2,
      "y": 10,
      "z": -2,
      "name": "Rock_Slate"
    },
    {
      "x": -2,
      "y": 11,
      "z": -2,
      "name": "Rock_Slate"
    },
    {
      "x": -2,
      "y": 12,
      "z": -2,
      "name": "Rock_Slate"
    },
    {
      "x": -2,
      "y": 13,
      "z": -2,
      "name": "Rock_Slate"
    },
    {
      "x": -2,
      "y": 3,
      "z": -1,
      "name": "Rock_Slate"
    },
    {
      "x": -2,
      "y": 4,
      "z": -1,
      "name": "Rock_Slate"
    },
    {
      "x": -2,
      "y": 5,
      "z": -1,
      "name": "Rock_Slate"
    },
    {
      "x": -2,
      "y": 6,
      "z": -1,
      "name": "Rock_Slate"
    },
    {
      "x": -2,
      "y": 7,
      "z": -1,
      "name": "Rock_Slate"
    },
    {
      "x": -2,
      "y": 8,
      "z": -1,
      "name": "Rock_Slate"
    },
    {
      "x": -2,
      "y": 9,
      "z": -1,
      "name": "Rock_Slate"
    },
    {
      "x": -2,
      "y": 10,
      "z": -1,
      "name": "Rock_Slate"
    },
    {
      "x": -2,
      "y": 11,
      "z": -1,
      "name": "Rock_Slate"
    },
    {
      "x": -2,
      "y": 12,
      "z": -1,
      "name": "Rock_Slate"
    },
    {
      "x": -2,
      "y": 13,
      "z": -1,
      "name": "Rock_Slate"
    },
    {
      "x": -2,
      "y": 3,
      "z": 0,
      "name": "Rock_Slate"
    },
    {
      "x": -2,
      "y": 4,
      "z": 0,
      "name": "Rock_Slate"
    },
    {
      "x": -2,
      "y": 5,
      "z": 0,
      "name": "Rock_Slate"
    },
    {
      "x": -2,
      "y": 6,
      "z": 0,
      "name": "Rock_Slate"
    },
    {
      "x": -2,
      "y": 7,
      "z": 0,
      "name": "Rock_Slate"
    },
    {
      "x": -2,
      "y": 8,
      "z": 0,
      "name": "Rock_Slate"
    },
    {
      "x": -2,
      "y": 9,
      "z": 0,
      "name": "Rock_Slate"
    },
    {
      "x": -2,
      "y": 10,
      "z": 0,
      "name": "Rock_Slate"
    },
    {
      "x": -2,
      "y": 11,
      "z": 0,
      "name": "Rock_Slate"
    },
    {
      "x": -2,
      "y": 12,
      "z": 0,
      "name": "Rock_Slate"
    },
    {
      "x": -2,
      "y": 13,
      "z": 0,
      "name": "Rock_Slate"
    },
    {
      "x": -2,
      "y": 4,
      "z": 1,
      "name": "Rock_Slate"
    },
    {
      "x": -2,
      "y": 5,
      "z": 1,
      "name": "Rock_Slate"
    },
    {
      "x": -2,
      "y": 6,
      "z": 1,
      "name": "Rock_Slate"
    },
    {
      "x": -2,
      "y": 7,
      "z": 1,
      "name": "Rock_Slate"
    },
    {
      "x": -2,
      "y": 8,
      "z": 1,
      "name": "Rock_Slate"
    },
    {
      "x": -2,
      "y": 9,
      "z": 1,
      "name": "Rock_Slate"
    },
    {
      "x": -2,
      "y": 10,
      "z": 1,
      "name": "Rock_Slate"
    },
    {
      "x": -2,
      "y": 11,
      "z": 1,
      "name": "Rock_Slate"
    },
    {
      "x": -2,
      "y": 12,
      "z": 1,
      "name": "Rock_Slate"
    },
    {
      "x": -2,
      "y": 13,
      "z": 1,
      "name": "Rock_Slate"
    },
    {
      "x": -2,
      "y": 5,
      "z": 2,
      "name": "Rock_Slate"
    },
    {
      "x": -2,
      "y": 6,
      "z": 2,
      "name": "Rock_Slate"
    },
    {
      "x": -2,
      "y": 7,
      "z": 2,
      "name": "Rock_Slate"
    },
    {
      "x": -2,
      "y": 8,
      "z": 2,
      "name": "Rock_Slate"
    },
    {
      "x": -2,
      "y": 9,
      "z": 2,
      "name": "Rock_Slate"
    },
    {
      "x": -2,
      "y": 10,
      "z": 2,
      "name": "Rock_Slate"
    },
    {
      "x": -2,
      "y": 11,
      "z": 2,
      "name": "Rock_Slate"
    },
    {
      "x": -2,
      "y": 12,
      "z": 2,
      "name": "Rock_Slate"
    },
    {
      "x": -2,
      "y": 13,
      "z": 2,
      "name": "Rock_Slate"
    },
    {
      "x": -2,
      "y": 14,
      "z": 2,
      "name": "Rock_Slate"
    },
    {
      "x": -2,
      "y": 9,
      "z": 3,
      "name": "Rock_Slate"
    },
    {
      "x": -2,
      "y": 10,
      "z": 3,
      "name": "Rock_Slate"
    },
    {
      "x": -2,
      "y": 11,
      "z": 3,
      "name": "Rock_Slate"
    },
    {
      "x": -2,
      "y": 12,
      "z": 3,
      "name": "Rock_Slate"
    },
    {
      "x": -2,
      "y": 13,
      "z": 3,
      "name": "Rock_Slate"
    },
    {
      "x": -2,
      "y": 14,
      "z": 3,
      "name": "Rock_Slate"
    },
    {
      "x": -1,
      "y": 6,
      "z": -6,
      "name": "Rock_Slate"
    },
    {
      "x": -1,
      "y": 7,
      "z": -6,
      "name": "Rock_Slate"
    },
    {
      "x": -1,
      "y": 8,
      "z": -6,
      "name": "Rock_Slate"
    },
    {
      "x": -1,
      "y": 9,
      "z": -6,
      "name": "Rock_Slate"
    },
    {
      "x": -1,
      "y": 10,
      "z": -6,
      "name": "Rock_Slate"
    },
    {
      "x": -1,
      "y": 11,
      "z": -6,
      "name": "Rock_Slate"
    },
    {
      "x": -1,
      "y": 12,
      "z": -6,
      "name": "Rock_Slate"
    },
    {
      "x": -1,
      "y": 13,
      "z": -6,
      "name": "Soil_Grass_Burnt"
    },
    {
      "x": -1,
      "y": 4,
      "z": -5,
      "name": "Rock_Slate"
    },
    {
      "x": -1,
      "y": 5,
      "z": -5,
      "name": "Rock_Slate"
    },
    {
      "x": -1,
      "y": 6,
      "z": -5,
      "name": "Rock_Slate"
    },
    {
      "x": -1,
      "y": 7,
      "z": -5,
      "name": "Rock_Slate"
    },
    {
      "x": -1,
      "y": 8,
      "z": -5,
      "name": "Rock_Slate"
    },
    {
      "x": -1,
      "y": 9,
      "z": -5,
      "name": "Rock_Slate"
    },
    {
      "x": -1,
      "y": 10,
      "z": -5,
      "name": "Rock_Slate"
    },
    {
      "x": -1,
      "y": 11,
      "z": -5,
      "name": "Rock_Slate"
    },
    {
      "x": -1,
      "y": 12,
      "z": -5,
      "name": "Rock_Slate"
    },
    {
      "x": -1,
      "y": 13,
      "z": -5,
      "name": "Soil_Grass_Burnt"
    },
    {
      "x": -1,
      "y": 14,
      "z": -5,
      "name": "Plant_Grass_Gnarled_Short"
    },
    {
      "x": -1,
      "y": 3,
      "z": -4,
      "name": "Rock_Slate"
    },
    {
      "x": -1,
      "y": 4,
      "z": -4,
      "name": "Rock_Slate"
    },
    {
      "x": -1,
      "y": 5,
      "z": -4,
      "name": "Rock_Slate"
    },
    {
      "x": -1,
      "y": 6,
      "z": -4,
      "name": "Rock_Slate"
    },
    {
      "x": -1,
      "y": 7,
      "z": -4,
      "name": "Rock_Slate"
    },
    {
      "x": -1,
      "y": 8,
      "z": -4,
      "name": "Rock_Slate"
    },
    {
      "x": -1,
      "y": 9,
      "z": -4,
      "name": "Rock_Slate"
    },
    {
      "x": -1,
      "y": 10,
      "z": -4,
      "name": "Rock_Slate"
    },
    {
      "x": -1,
      "y": 11,
      "z": -4,
      "name": "Rock_Slate"
    },
    {
      "x": -1,
      "y": 12,
      "z": -4,
      "name": "Rock_Slate"
    },
    {
      "x": -1,
      "y": 13,
      "z": -4,
      "name": "Soil_Grass_Burnt"
    },
    {
      "x": -1,
      "y": 3,
      "z": -3,
      "name": "Rock_Slate"
    },
    {
      "x": -1,
      "y": 4,
      "z": -3,
      "name": "Rock_Slate"
    },
    {
      "x": -1,
      "y": 5,
      "z": -3,
      "name": "Rock_Slate"
    },
    {
      "x": -1,
      "y": 6,
      "z": -3,
      "name": "Rock_Slate"
    },
    {
      "x": -1,
      "y": 7,
      "z": -3,
      "name": "Rock_Slate"
    },
    {
      "x": -1,
      "y": 8,
      "z": -3,
      "name": "Rock_Slate"
    },
    {
      "x": -1,
      "y": 9,
      "z": -3,
      "name": "Rock_Slate"
    },
    {
      "x": -1,
      "y": 10,
      "z": -3,
      "name": "Rock_Slate"
    },
    {
      "x": -1,
      "y": 11,
      "z": -3,
      "name": "Rock_Slate"
    },
    {
      "x": -1,
      "y": 12,
      "z": -3,
      "name": "Rock_Slate"
    },
    {
      "x": -1,
      "y": 13,
      "z": -3,
      "name": "Soil_Grass_Burnt"
    },
    {
      "x": -1,
      "y": 3,
      "z": -2,
      "name": "Rock_Slate"
    },
    {
      "x": -1,
      "y": 4,
      "z": -2,
      "name": "Rock_Slate"
    },
    {
      "x": -1,
      "y": 5,
      "z": -2,
      "name": "Rock_Slate"
    },
    {
      "x": -1,
      "y": 6,
      "z": -2,
      "name": "Rock_Slate"
    },
    {
      "x": -1,
      "y": 7,
      "z": -2,
      "name": "Rock_Slate"
    },
    {
      "x": -1,
      "y": 8,
      "z": -2,
      "name": "Rock_Slate"
    },
    {
      "x": -1,
      "y": 9,
      "z": -2,
      "name": "Rock_Slate"
    },
    {
      "x": -1,
      "y": 10,
      "z": -2,
      "name": "Rock_Slate"
    },
    {
      "x": -1,
      "y": 11,
      "z": -2,
      "name": "Rock_Slate"
    },
    {
      "x": -1,
      "y": 12,
      "z": -2,
      "name": "Rock_Slate"
    },
    {
      "x": -1,
      "y": 13,
      "z": -2,
      "name": "Soil_Grass_Burnt"
    },
    {
      "x": -1,
      "y": 3,
      "z": -1,
      "name": "Rock_Slate"
    },
    {
      "x": -1,
      "y": 4,
      "z": -1,
      "name": "Rock_Slate"
    },
    {
      "x": -1,
      "y": 5,
      "z": -1,
      "name": "Rock_Slate"
    },
    {
      "x": -1,
      "y": 6,
      "z": -1,
      "name": "Rock_Slate"
    },
    {
      "x": -1,
      "y": 7,
      "z": -1,
      "name": "Rock_Slate"
    },
    {
      "x": -1,
      "y": 8,
      "z": -1,
      "name": "Rock_Slate"
    },
    {
      "x": -1,
      "y": 9,
      "z": -1,
      "name": "Rock_Slate"
    },
    {
      "x": -1,
      "y": 10,
      "z": -1,
      "name": "Rock_Slate"
    },
    {
      "x": -1,
      "y": 11,
      "z": -1,
      "name": "Rock_Slate"
    },
    {
      "x": -1,
      "y": 12,
      "z": -1,
      "name": "Rock_Slate"
    },
    {
      "x": -1,
      "y": 13,
      "z": -1,
      "name": "Rock_Slate"
    },
    {
      "x": -1,
      "y": 3,
      "z": 0,
      "name": "Rock_Slate"
    },
    {
      "x": -1,
      "y": 4,
      "z": 0,
      "name": "Rock_Slate"
    },
    {
      "x": -1,
      "y": 5,
      "z": 0,
      "name": "Rock_Slate"
    },
    {
      "x": -1,
      "y": 6,
      "z": 0,
      "name": "Rock_Slate"
    },
    {
      "x": -1,
      "y": 7,
      "z": 0,
      "name": "Rock_Slate"
    },
    {
      "x": -1,
      "y": 8,
      "z": 0,
      "name": "Rock_Slate"
    },
    {
      "x": -1,
      "y": 9,
      "z": 0,
      "name": "Rock_Slate"
    },
    {
      "x": -1,
      "y": 10,
      "z": 0,
      "name": "Rock_Slate"
    },
    {
      "x": -1,
      "y": 11,
      "z": 0,
      "name": "Rock_Slate"
    },
    {
      "x": -1,
      "y": 12,
      "z": 0,
      "name": "Rock_Slate"
    },
    {
      "x": -1,
      "y": 13,
      "z": 0,
      "name": "Rock_Slate"
    },
    {
      "x": -1,
      "y": 14,
      "z": 0,
      "name": "Rock_Slate"
    },
    {
      "x": -1,
      "y": 3,
      "z": 1,
      "name": "Rock_Slate"
    },
    {
      "x": -1,
      "y": 4,
      "z": 1,
      "name": "Rock_Slate"
    },
    {
      "x": -1,
      "y": 5,
      "z": 1,
      "name": "Rock_Slate"
    },
    {
      "x": -1,
      "y": 6,
      "z": 1,
      "name": "Rock_Slate"
    },
    {
      "x": -1,
      "y": 7,
      "z": 1,
      "name": "Rock_Slate"
    },
    {
      "x": -1,
      "y": 8,
      "z": 1,
      "name": "Rock_Slate"
    },
    {
      "x": -1,
      "y": 9,
      "z": 1,
      "name": "Rock_Slate"
    },
    {
      "x": -1,
      "y": 10,
      "z": 1,
      "name": "Rock_Slate"
    },
    {
      "x": -1,
      "y": 11,
      "z": 1,
      "name": "Rock_Slate"
    },
    {
      "x": -1,
      "y": 12,
      "z": 1,
      "name": "Rock_Slate"
    },
    {
      "x": -1,
      "y": 13,
      "z": 1,
      "name": "Rock_Slate"
    },
    {
      "x": -1,
      "y": 14,
      "z": 1,
      "name": "Rock_Slate"
    },
    {
      "x": -1,
      "y": 5,
      "z": 2,
      "name": "Rock_Slate"
    },
    {
      "x": -1,
      "y": 6,
      "z": 2,
      "name": "Rock_Slate"
    },
    {
      "x": -1,
      "y": 7,
      "z": 2,
      "name": "Rock_Slate"
    },
    {
      "x": -1,
      "y": 8,
      "z": 2,
      "name": "Rock_Slate"
    },
    {
      "x": -1,
      "y": 9,
      "z": 2,
      "name": "Rock_Slate"
    },
    {
      "x": -1,
      "y": 10,
      "z": 2,
      "name": "Rock_Slate"
    },
    {
      "x": -1,
      "y": 11,
      "z": 2,
      "name": "Rock_Slate"
    },
    {
      "x": -1,
      "y": 12,
      "z": 2,
      "name": "Rock_Slate"
    },
    {
      "x": -1,
      "y": 13,
      "z": 2,
      "name": "Rock_Slate"
    },
    {
      "x": -1,
      "y": 14,
      "z": 2,
      "name": "Rock_Slate"
    },
    {
      "x": -1,
      "y": 15,
      "z": 2,
      "name": "Rubble_Slate"
    },
    {
      "x": -1,
      "y": 8,
      "z": 3,
      "name": "Rock_Slate"
    },
    {
      "x": -1,
      "y": 9,
      "z": 3,
      "name": "Rock_Slate"
    },
    {
      "x": -1,
      "y": 10,
      "z": 3,
      "name": "Rock_Slate"
    },
    {
      "x": -1,
      "y": 11,
      "z": 3,
      "name": "Rock_Slate"
    },
    {
      "x": -1,
      "y": 12,
      "z": 3,
      "name": "Rock_Slate"
    },
    {
      "x": -1,
      "y": 13,
      "z": 3,
      "name": "Rock_Slate"
    },
    {
      "x": -1,
      "y": 14,
      "z": 3,
      "name": "Rock_Slate"
    },
    {
      "x": 0,
      "y": 6,
      "z": -6,
      "name": "Rock_Slate"
    },
    {
      "x": 0,
      "y": 7,
      "z": -6,
      "name": "Rock_Slate"
    },
    {
      "x": 0,
      "y": 8,
      "z": -6,
      "name": "Rock_Slate"
    },
    {
      "x": 0,
      "y": 9,
      "z": -6,
      "name": "Rock_Slate"
    },
    {
      "x": 0,
      "y": 10,
      "z": -6,
      "name": "Rock_Slate"
    },
    {
      "x": 0,
      "y": 11,
      "z": -6,
      "name": "Rock_Slate"
    },
    {
      "x": 0,
      "y": 12,
      "z": -6,
      "name": "Rock_Slate"
    },
    {
      "x": 0,
      "y": 13,
      "z": -6,
      "name": "Soil_Grass_Burnt"
    },
    {
      "x": 0,
      "y": 4,
      "z": -5,
      "name": "Rock_Slate"
    },
    {
      "x": 0,
      "y": 5,
      "z": -5,
      "name": "Rock_Slate"
    },
    {
      "x": 0,
      "y": 6,
      "z": -5,
      "name": "Rock_Slate"
    },
    {
      "x": 0,
      "y": 7,
      "z": -5,
      "name": "Rock_Slate"
    },
    {
      "x": 0,
      "y": 8,
      "z": -5,
      "name": "Rock_Slate"
    },
    {
      "x": 0,
      "y": 9,
      "z": -5,
      "name": "Rock_Slate"
    },
    {
      "x": 0,
      "y": 10,
      "z": -5,
      "name": "Rock_Slate"
    },
    {
      "x": 0,
      "y": 11,
      "z": -5,
      "name": "Rock_Slate"
    },
    {
      "x": 0,
      "y": 12,
      "z": -5,
      "name": "Rock_Slate"
    },
    {
      "x": 0,
      "y": 13,
      "z": -5,
      "name": "Soil_Grass_Burnt"
    },
    {
      "x": 0,
      "y": 3,
      "z": -4,
      "name": "Rock_Slate"
    },
    {
      "x": 0,
      "y": 4,
      "z": -4,
      "name": "Rock_Slate"
    },
    {
      "x": 0,
      "y": 5,
      "z": -4,
      "name": "Rock_Slate"
    },
    {
      "x": 0,
      "y": 6,
      "z": -4,
      "name": "Rock_Slate"
    },
    {
      "x": 0,
      "y": 7,
      "z": -4,
      "name": "Rock_Slate"
    },
    {
      "x": 0,
      "y": 8,
      "z": -4,
      "name": "Rock_Slate"
    },
    {
      "x": 0,
      "y": 9,
      "z": -4,
      "name": "Rock_Slate"
    },
    {
      "x": 0,
      "y": 10,
      "z": -4,
      "name": "Rock_Slate"
    },
    {
      "x": 0,
      "y": 11,
      "z": -4,
      "name": "Rock_Slate"
    },
    {
      "x": 0,
      "y": 12,
      "z": -4,
      "name": "Rock_Slate"
    },
    {
      "x": 0,
      "y": 13,
      "z": -4,
      "name": "Soil_Grass_Burnt"
    },
    {
      "x": 0,
      "y": 3,
      "z": -3,
      "name": "Rock_Slate"
    },
    {
      "x": 0,
      "y": 4,
      "z": -3,
      "name": "Rock_Slate"
    },
    {
      "x": 0,
      "y": 5,
      "z": -3,
      "name": "Rock_Slate"
    },
    {
      "x": 0,
      "y": 6,
      "z": -3,
      "name": "Rock_Slate"
    },
    {
      "x": 0,
      "y": 7,
      "z": -3,
      "name": "Rock_Slate"
    },
    {
      "x": 0,
      "y": 8,
      "z": -3,
      "name": "Rock_Slate"
    },
    {
      "x": 0,
      "y": 9,
      "z": -3,
      "name": "Rock_Slate"
    },
    {
      "x": 0,
      "y": 10,
      "z": -3,
      "name": "Rock_Slate"
    },
    {
      "x": 0,
      "y": 11,
      "z": -3,
      "name": "Rock_Slate"
    },
    {
      "x": 0,
      "y": 12,
      "z": -3,
      "name": "Rock_Slate"
    },
    {
      "x": 0,
      "y": 13,
      "z": -3,
      "name": "Rock_Slate"
    },
    {
      "x": 0,
      "y": 14,
      "z": -3,
      "name": "Soil_Grass_Burnt"
    },
    {
      "x": 0,
      "y": 15,
      "z": -3,
      "name": "Plant_Grass_Gnarled_Short"
    },
    {
      "x": 0,
      "y": 3,
      "z": -2,
      "name": "Rock_Slate"
    },
    {
      "x": 0,
      "y": 4,
      "z": -2,
      "name": "Rock_Slate"
    },
    {
      "x": 0,
      "y": 5,
      "z": -2,
      "name": "Rock_Slate"
    },
    {
      "x": 0,
      "y": 6,
      "z": -2,
      "name": "Rock_Slate"
    },
    {
      "x": 0,
      "y": 7,
      "z": -2,
      "name": "Rock_Slate"
    },
    {
      "x": 0,
      "y": 8,
      "z": -2,
      "name": "Rock_Slate"
    },
    {
      "x": 0,
      "y": 9,
      "z": -2,
      "name": "Rock_Slate"
    },
    {
      "x": 0,
      "y": 10,
      "z": -2,
      "name": "Rock_Slate"
    },
    {
      "x": 0,
      "y": 11,
      "z": -2,
      "name": "Rock_Slate"
    },
    {
      "x": 0,
      "y": 12,
      "z": -2,
      "name": "Rock_Slate"
    },
    {
      "x": 0,
      "y": 13,
      "z": -2,
      "name": "Rock_Slate"
    },
    {
      "x": 0,
      "y": 14,
      "z": -2,
      "name": "Soil_Grass_Burnt"
    },
    {
      "x": 0,
      "y": 3,
      "z": -1,
      "name": "Rock_Slate"
    },
    {
      "x": 0,
      "y": 4,
      "z": -1,
      "name": "Rock_Slate"
    },
    {
      "x": 0,
      "y": 5,
      "z": -1,
      "name": "Rock_Slate"
    },
    {
      "x": 0,
      "y": 6,
      "z": -1,
      "name": "Rock_Slate"
    },
    {
      "x": 0,
      "y": 7,
      "z": -1,
      "name": "Rock_Slate"
    },
    {
      "x": 0,
      "y": 8,
      "z": -1,
      "name": "Rock_Slate"
    },
    {
      "x": 0,
      "y": 9,
      "z": -1,
      "name": "Rock_Slate"
    },
    {
      "x": 0,
      "y": 10,
      "z": -1,
      "name": "Rock_Slate"
    },
    {
      "x": 0,
      "y": 11,
      "z": -1,
      "name": "Rock_Slate"
    },
    {
      "x": 0,
      "y": 12,
      "z": -1,
      "name": "Rock_Slate"
    },
    {
      "x": 0,
      "y": 13,
      "z": -1,
      "name": "Rock_Slate"
    },
    {
      "x": 0,
      "y": 14,
      "z": -1,
      "name": "Soil_Grass_Burnt"
    },
    {
      "x": 0,
      "y": 3,
      "z": 0,
      "name": "Rock_Slate"
    },
    {
      "x": 0,
      "y": 4,
      "z": 0,
      "name": "Rock_Slate"
    },
    {
      "x": 0,
      "y": 5,
      "z": 0,
      "name": "Rock_Slate"
    },
    {
      "x": 0,
      "y": 6,
      "z": 0,
      "name": "Rock_Slate"
    },
    {
      "x": 0,
      "y": 7,
      "z": 0,
      "name": "Rock_Slate"
    },
    {
      "x": 0,
      "y": 8,
      "z": 0,
      "name": "Rock_Slate"
    },
    {
      "x": 0,
      "y": 9,
      "z": 0,
      "name": "Rock_Slate"
    },
    {
      "x": 0,
      "y": 10,
      "z": 0,
      "name": "Rock_Slate"
    },
    {
      "x": 0,
      "y": 11,
      "z": 0,
      "name": "Rock_Slate"
    },
    {
      "x": 0,
      "y": 12,
      "z": 0,
      "name": "Rock_Slate"
    },
    {
      "x": 0,
      "y": 13,
      "z": 0,
      "name": "Rock_Slate"
    },
    {
      "x": 0,
      "y": 14,
      "z": 0,
      "name": "Soil_Grass_Burnt"
    },
    {
      "x": 0,
      "y": 15,
      "z": 0,
      "name": "Plant_Grass_Gnarled"
    },
    {
      "x": 0,
      "y": 3,
      "z": 1,
      "name": "Rock_Slate"
    },
    {
      "x": 0,
      "y": 4,
      "z": 1,
      "name": "Rock_Slate"
    },
    {
      "x": 0,
      "y": 5,
      "z": 1,
      "name": "Rock_Slate"
    },
    {
      "x": 0,
      "y": 6,
      "z": 1,
      "name": "Rock_Slate"
    },
    {
      "x": 0,
      "y": 7,
      "z": 1,
      "name": "Rock_Slate"
    },
    {
      "x": 0,
      "y": 8,
      "z": 1,
      "name": "Rock_Slate"
    },
    {
      "x": 0,
      "y": 9,
      "z": 1,
      "name": "Rock_Slate"
    },
    {
      "x": 0,
      "y": 10,
      "z": 1,
      "name": "Rock_Slate"
    },
    {
      "x": 0,
      "y": 11,
      "z": 1,
      "name": "Rock_Slate"
    },
    {
      "x": 0,
      "y": 12,
      "z": 1,
      "name": "Rock_Slate"
    },
    {
      "x": 0,
      "y": 13,
      "z": 1,
      "name": "Rock_Slate"
    },
    {
      "x": 0,
      "y": 14,
      "z": 1,
      "name": "Rock_Slate"
    },
    {
      "x": 0,
      "y": 15,
      "z": 1,
      "name": "Rubble_Slate"
    },
    {
      "x": 0,
      "y": 5,
      "z": 2,
      "name": "Rock_Slate"
    },
    {
      "x": 0,
      "y": 6,
      "z": 2,
      "name": "Rock_Slate"
    },
    {
      "x": 0,
      "y": 7,
      "z": 2,
      "name": "Rock_Slate"
    },
    {
      "x": 0,
      "y": 8,
      "z": 2,
      "name": "Rock_Slate"
    },
    {
      "x": 0,
      "y": 9,
      "z": 2,
      "name": "Rock_Slate"
    },
    {
      "x": 0,
      "y": 10,
      "z": 2,
      "name": "Rock_Slate"
    },
    {
      "x": 0,
      "y": 11,
      "z": 2,
      "name": "Rock_Slate"
    },
    {
      "x": 0,
      "y": 12,
      "z": 2,
      "name": "Rock_Slate"
    },
    {
      "x": 0,
      "y": 13,
      "z": 2,
      "name": "Rock_Slate"
    },
    {
      "x": 0,
      "y": 14,
      "z": 2,
      "name": "Rock_Slate"
    },
    {
      "x": 1,
      "y": 5,
      "z": -5,
      "name": "Rock_Slate"
    },
    {
      "x": 1,
      "y": 6,
      "z": -5,
      "name": "Rock_Slate"
    },
    {
      "x": 1,
      "y": 7,
      "z": -5,
      "name": "Rock_Slate"
    },
    {
      "x": 1,
      "y": 8,
      "z": -5,
      "name": "Rock_Slate"
    },
    {
      "x": 1,
      "y": 9,
      "z": -5,
      "name": "Rock_Slate"
    },
    {
      "x": 1,
      "y": 10,
      "z": -5,
      "name": "Rock_Slate"
    },
    {
      "x": 1,
      "y": 11,
      "z": -5,
      "name": "Rock_Slate"
    },
    {
      "x": 1,
      "y": 12,
      "z": -5,
      "name": "Rock_Slate"
    },
    {
      "x": 1,
      "y": 13,
      "z": -5,
      "name": "Rock_Slate"
    },
    {
      "x": 1,
      "y": 14,
      "z": -5,
      "name": "Soil_Grass_Burnt"
    },
    {
      "x": 1,
      "y": 3,
      "z": -4,
      "name": "Rock_Slate"
    },
    {
      "x": 1,
      "y": 4,
      "z": -4,
      "name": "Rock_Slate"
    },
    {
      "x": 1,
      "y": 5,
      "z": -4,
      "name": "Rock_Slate"
    },
    {
      "x": 1,
      "y": 6,
      "z": -4,
      "name": "Rock_Slate"
    },
    {
      "x": 1,
      "y": 7,
      "z": -4,
      "name": "Rock_Slate"
    },
    {
      "x": 1,
      "y": 8,
      "z": -4,
      "name": "Rock_Slate"
    },
    {
      "x": 1,
      "y": 9,
      "z": -4,
      "name": "Rock_Slate"
    },
    {
      "x": 1,
      "y": 10,
      "z": -4,
      "name": "Rock_Slate"
    },
    {
      "x": 1,
      "y": 11,
      "z": -4,
      "name": "Rock_Slate"
    },
    {
      "x": 1,
      "y": 12,
      "z": -4,
      "name": "Rock_Slate"
    },
    {
      "x": 1,
      "y": 13,
      "z": -4,
      "name": "Rock_Slate"
    },
    {
      "x": 1,
      "y": 14,
      "z": -4,
      "name": "Soil_Grass_Burnt"
    },
    {
      "x": 1,
      "y": 3,
      "z": -3,
      "name": "Rock_Slate"
    },
    {
      "x": 1,
      "y": 4,
      "z": -3,
      "name": "Rock_Slate"
    },
    {
      "x": 1,
      "y": 5,
      "z": -3,
      "name": "Rock_Slate"
    },
    {
      "x": 1,
      "y": 6,
      "z": -3,
      "name": "Rock_Slate"
    },
    {
      "x": 1,
      "y": 7,
      "z": -3,
      "name": "Rock_Slate"
    },
    {
      "x": 1,
      "y": 8,
      "z": -3,
      "name": "Rock_Slate"
    },
    {
      "x": 1,
      "y": 9,
      "z": -3,
      "name": "Rock_Slate"
    },
    {
      "x": 1,
      "y": 10,
      "z": -3,
      "name": "Rock_Slate"
    },
    {
      "x": 1,
      "y": 11,
      "z": -3,
      "name": "Rock_Slate"
    },
    {
      "x": 1,
      "y": 12,
      "z": -3,
      "name": "Rock_Slate"
    },
    {
      "x": 1,
      "y": 13,
      "z": -3,
      "name": "Rock_Slate"
    },
    {
      "x": 1,
      "y": 14,
      "z": -3,
      "name": "Soil_Grass_Burnt"
    },
    {
      "x": 1,
      "y": 15,
      "z": -3,
      "name": "Plant_Grass_Gnarled_Short"
    },
    {
      "x": 1,
      "y": 3,
      "z": -2,
      "name": "Rock_Slate"
    },
    {
      "x": 1,
      "y": 4,
      "z": -2,
      "name": "Rock_Slate"
    },
    {
      "x": 1,
      "y": 5,
      "z": -2,
      "name": "Rock_Slate"
    },
    {
      "x": 1,
      "y": 6,
      "z": -2,
      "name": "Rock_Slate"
    },
    {
      "x": 1,
      "y": 7,
      "z": -2,
      "name": "Rock_Slate"
    },
    {
      "x": 1,
      "y": 8,
      "z": -2,
      "name": "Rock_Slate"
    },
    {
      "x": 1,
      "y": 9,
      "z": -2,
      "name": "Rock_Slate"
    },
    {
      "x": 1,
      "y": 10,
      "z": -2,
      "name": "Rock_Slate"
    },
    {
      "x": 1,
      "y": 11,
      "z": -2,
      "name": "Rock_Slate"
    },
    {
      "x": 1,
      "y": 12,
      "z": -2,
      "name": "Rock_Slate"
    },
    {
      "x": 1,
      "y": 13,
      "z": -2,
      "name": "Rock_Slate"
    },
    {
      "x": 1,
      "y": 14,
      "z": -2,
      "name": "Soil_Grass_Burnt"
    },
    {
      "x": 1,
      "y": 15,
      "z": -2,
      "name": "Plant_Grass_Gnarled_Short"
    },
    {
      "x": 1,
      "y": 3,
      "z": -1,
      "name": "Rock_Slate"
    },
    {
      "x": 1,
      "y": 4,
      "z": -1,
      "name": "Rock_Slate"
    },
    {
      "x": 1,
      "y": 5,
      "z": -1,
      "name": "Rock_Slate"
    },
    {
      "x": 1,
      "y": 6,
      "z": -1,
      "name": "Rock_Slate"
    },
    {
      "x": 1,
      "y": 7,
      "z": -1,
      "name": "Rock_Slate"
    },
    {
      "x": 1,
      "y": 8,
      "z": -1,
      "name": "Rock_Slate"
    },
    {
      "x": 1,
      "y": 9,
      "z": -1,
      "name": "Rock_Slate"
    },
    {
      "x": 1,
      "y": 10,
      "z": -1,
      "name": "Rock_Slate"
    },
    {
      "x": 1,
      "y": 11,
      "z": -1,
      "name": "Rock_Slate"
    },
    {
      "x": 1,
      "y": 12,
      "z": -1,
      "name": "Rock_Slate"
    },
    {
      "x": 1,
      "y": 13,
      "z": -1,
      "name": "Rock_Slate"
    },
    {
      "x": 1,
      "y": 14,
      "z": -1,
      "name": "Soil_Grass_Burnt"
    },
    {
      "x": 1,
      "y": 3,
      "z": 0,
      "name": "Rock_Slate"
    },
    {
      "x": 1,
      "y": 4,
      "z": 0,
      "name": "Rock_Slate"
    },
    {
      "x": 1,
      "y": 5,
      "z": 0,
      "name": "Rock_Slate"
    },
    {
      "x": 1,
      "y": 6,
      "z": 0,
      "name": "Rock_Slate"
    },
    {
      "x": 1,
      "y": 7,
      "z": 0,
      "name": "Rock_Slate"
    },
    {
      "x": 1,
      "y": 8,
      "z": 0,
      "name": "Rock_Slate"
    },
    {
      "x": 1,
      "y": 9,
      "z": 0,
      "name": "Rock_Slate"
    },
    {
      "x": 1,
      "y": 10,
      "z": 0,
      "name": "Rock_Slate"
    },
    {
      "x": 1,
      "y": 11,
      "z": 0,
      "name": "Rock_Slate"
    },
    {
      "x": 1,
      "y": 12,
      "z": 0,
      "name": "Rock_Slate"
    },
    {
      "x": 1,
      "y": 13,
      "z": 0,
      "name": "Rock_Slate"
    },
    {
      "x": 1,
      "y": 14,
      "z": 0,
      "name": "Soil_Grass_Burnt"
    },
    {
      "x": 1,
      "y": 4,
      "z": 1,
      "name": "Rock_Slate"
    },
    {
      "x": 1,
      "y": 5,
      "z": 1,
      "name": "Rock_Slate"
    },
    {
      "x": 1,
      "y": 6,
      "z": 1,
      "name": "Rock_Slate"
    },
    {
      "x": 1,
      "y": 7,
      "z": 1,
      "name": "Rock_Slate"
    },
    {
      "x": 1,
      "y": 8,
      "z": 1,
      "name": "Rock_Slate"
    },
    {
      "x": 1,
      "y": 9,
      "z": 1,
      "name": "Rock_Slate"
    },
    {
      "x": 1,
      "y": 10,
      "z": 1,
      "name": "Rock_Slate"
    },
    {
      "x": 1,
      "y": 11,
      "z": 1,
      "name": "Rock_Slate"
    },
    {
      "x": 1,
      "y": 12,
      "z": 1,
      "name": "Rock_Slate"
    },
    {
      "x": 1,
      "y": 13,
      "z": 1,
      "name": "Rock_Slate"
    },
    {
      "x": 1,
      "y": 14,
      "z": 1,
      "name": "Soil_Grass_Burnt"
    },
    {
      "x": 1,
      "y": 15,
      "z": 1,
      "name": "Plant_Grass_Gnarled_Short"
    },
    {
      "x": 1,
      "y": 9,
      "z": 2,
      "name": "Rock_Slate"
    },
    {
      "x": 1,
      "y": 10,
      "z": 2,
      "name": "Rock_Slate"
    },
    {
      "x": 1,
      "y": 11,
      "z": 2,
      "name": "Rock_Slate"
    },
    {
      "x": 1,
      "y": 12,
      "z": 2,
      "name": "Rock_Slate"
    },
    {
      "x": 1,
      "y": 13,
      "z": 2,
      "name": "Rock_Slate"
    },
    {
      "x": 1,
      "y": 14,
      "z": 2,
      "name": "Rock_Slate"
    },
    {
      "x": 2,
      "y": 5,
      "z": -5,
      "name": "Rock_Slate"
    },
    {
      "x": 2,
      "y": 6,
      "z": -5,
      "name": "Rock_Slate"
    },
    {
      "x": 2,
      "y": 7,
      "z": -5,
      "name": "Rock_Slate"
    },
    {
      "x": 2,
      "y": 8,
      "z": -5,
      "name": "Rock_Slate"
    },
    {
      "x": 2,
      "y": 9,
      "z": -5,
      "name": "Rock_Slate"
    },
    {
      "x": 2,
      "y": 10,
      "z": -5,
      "name": "Rock_Slate"
    },
    {
      "x": 2,
      "y": 11,
      "z": -5,
      "name": "Rock_Slate"
    },
    {
      "x": 2,
      "y": 12,
      "z": -5,
      "name": "Rock_Slate"
    },
    {
      "x": 2,
      "y": 13,
      "z": -5,
      "name": "Rock_Slate"
    },
    {
      "x": 2,
      "y": 14,
      "z": -5,
      "name": "Soil_Grass_Burnt"
    },
    {
      "x": 2,
      "y": 5,
      "z": -4,
      "name": "Rock_Slate"
    },
    {
      "x": 2,
      "y": 6,
      "z": -4,
      "name": "Rock_Slate"
    },
    {
      "x": 2,
      "y": 7,
      "z": -4,
      "name": "Rock_Slate"
    },
    {
      "x": 2,
      "y": 8,
      "z": -4,
      "name": "Rock_Slate"
    },
    {
      "x": 2,
      "y": 9,
      "z": -4,
      "name": "Rock_Slate"
    },
    {
      "x": 2,
      "y": 10,
      "z": -4,
      "name": "Rock_Slate"
    },
    {
      "x": 2,
      "y": 11,
      "z": -4,
      "name": "Rock_Slate"
    },
    {
      "x": 2,
      "y": 12,
      "z": -4,
      "name": "Rock_Slate"
    },
    {
      "x": 2,
      "y": 13,
      "z": -4,
      "name": "Rock_Slate"
    },
    {
      "x": 2,
      "y": 14,
      "z": -4,
      "name": "Soil_Grass_Burnt"
    },
    {
      "x": 2,
      "y": 15,
      "z": -4,
      "name": "Plant_Grass_Gnarled"
    },
    {
      "x": 2,
      "y": 3,
      "z": -3,
      "name": "Rock_Slate"
    },
    {
      "x": 2,
      "y": 4,
      "z": -3,
      "name": "Rock_Slate"
    },
    {
      "x": 2,
      "y": 5,
      "z": -3,
      "name": "Rock_Slate"
    },
    {
      "x": 2,
      "y": 6,
      "z": -3,
      "name": "Rock_Slate"
    },
    {
      "x": 2,
      "y": 7,
      "z": -3,
      "name": "Rock_Slate"
    },
    {
      "x": 2,
      "y": 8,
      "z": -3,
      "name": "Rock_Slate"
    },
    {
      "x": 2,
      "y": 9,
      "z": -3,
      "name": "Rock_Slate"
    },
    {
      "x": 2,
      "y": 10,
      "z": -3,
      "name": "Rock_Slate"
    },
    {
      "x": 2,
      "y": 11,
      "z": -3,
      "name": "Rock_Slate"
    },
    {
      "x": 2,
      "y": 12,
      "z": -3,
      "name": "Rock_Slate"
    },
    {
      "x": 2,
      "y": 13,
      "z": -3,
      "name": "Rock_Slate"
    },
    {
      "x": 2,
      "y": 14,
      "z": -3,
      "name": "Soil_Grass_Burnt"
    },
    {
      "x": 2,
      "y": 15,
      "z": -3,
      "name": "Plant_Grass_Gnarled"
    },
    {
      "x": 2,
      "y": 3,
      "z": -2,
      "name": "Rock_Slate"
    },
    {
      "x": 2,
      "y": 4,
      "z": -2,
      "name": "Rock_Slate"
    },
    {
      "x": 2,
      "y": 5,
      "z": -2,
      "name": "Rock_Slate"
    },
    {
      "x": 2,
      "y": 6,
      "z": -2,
      "name": "Rock_Slate"
    },
    {
      "x": 2,
      "y": 7,
      "z": -2,
      "name": "Rock_Slate"
    },
    {
      "x": 2,
      "y": 8,
      "z": -2,
      "name": "Rock_Slate"
    },
    {
      "x": 2,
      "y": 9,
      "z": -2,
      "name": "Rock_Slate"
    },
    {
      "x": 2,
      "y": 10,
      "z": -2,
      "name": "Rock_Slate"
    },
    {
      "x": 2,
      "y": 11,
      "z": -2,
      "name": "Rock_Slate"
    },
    {
      "x": 2,
      "y": 12,
      "z": -2,
      "name": "Rock_Slate"
    },
    {
      "x": 2,
      "y": 13,
      "z": -2,
      "name": "Rock_Slate"
    },
    {
      "x": 2,
      "y": 14,
      "z": -2,
      "name": "Soil_Grass_Burnt"
    },
    {
      "x": 2,
      "y": 15,
      "z": -2,
      "name": "Plant_Grass_Gnarled_Tall"
    },
    {
      "x": 2,
      "y": 16,
      "z": -2,
      "name": "Plant_Grass_Gnarled_Tall",
      "filler": 1024
    },
    {
      "x": 2,
      "y": 3,
      "z": -1,
      "name": "Rock_Slate"
    },
    {
      "x": 2,
      "y": 4,
      "z": -1,
      "name": "Rock_Slate"
    },
    {
      "x": 2,
      "y": 5,
      "z": -1,
      "name": "Rock_Slate"
    },
    {
      "x": 2,
      "y": 6,
      "z": -1,
      "name": "Rock_Slate"
    },
    {
      "x": 2,
      "y": 7,
      "z": -1,
      "name": "Rock_Slate"
    },
    {
      "x": 2,
      "y": 8,
      "z": -1,
      "name": "Rock_Slate"
    },
    {
      "x": 2,
      "y": 9,
      "z": -1,
      "name": "Rock_Slate"
    },
    {
      "x": 2,
      "y": 10,
      "z": -1,
      "name": "Rock_Slate"
    },
    {
      "x": 2,
      "y": 11,
      "z": -1,
      "name": "Rock_Slate"
    },
    {
      "x": 2,
      "y": 12,
      "z": -1,
      "name": "Rock_Slate"
    },
    {
      "x": 2,
      "y": 13,
      "z": -1,
      "name": "Rock_Slate"
    },
    {
      "x": 2,
      "y": 14,
      "z": -1,
      "name": "Soil_Grass_Burnt"
    },
    {
      "x": 2,
      "y": 15,
      "z": -1,
      "name": "Plant_Grass_Gnarled_Short"
    },
    {
      "x": 2,
      "y": 4,
      "z": 0,
      "name": "Rock_Slate"
    },
    {
      "x": 2,
      "y": 5,
      "z": 0,
      "name": "Rock_Slate"
    },
    {
      "x": 2,
      "y": 6,
      "z": 0,
      "name": "Rock_Slate"
    },
    {
      "x": 2,
      "y": 7,
      "z": 0,
      "name": "Rock_Slate"
    },
    {
      "x": 2,
      "y": 8,
      "z": 0,
      "name": "Rock_Slate"
    },
    {
      "x": 2,
      "y": 9,
      "z": 0,
      "name": "Rock_Slate"
    },
    {
      "x": 2,
      "y": 10,
      "z": 0,
      "name": "Rock_Slate"
    },
    {
      "x": 2,
      "y": 11,
      "z": 0,
      "name": "Rock_Slate"
    },
    {
      "x": 2,
      "y": 12,
      "z": 0,
      "name": "Rock_Slate"
    },
    {
      "x": 2,
      "y": 13,
      "z": 0,
      "name": "Rock_Slate"
    },
    {
      "x": 2,
      "y": 14,
      "z": 0,
      "name": "Soil_Grass_Burnt"
    },
    {
      "x": 2,
      "y": 10,
      "z": 1,
      "name": "Rock_Slate"
    },
    {
      "x": 2,
      "y": 11,
      "z": 1,
      "name": "Rock_Slate"
    },
    {
      "x": 2,
      "y": 12,
      "z": 1,
      "name": "Rock_Slate"
    },
    {
      "x": 2,
      "y": 13,
      "z": 1,
      "name": "Rock_Slate"
    },
    {
      "x": 2,
      "y": 14,
      "z": 1,
      "name": "Soil_Grass_Burnt"
    },
    {
      "x": 3,
      "y": 5,
      "z": -4,
      "name": "Rock_Slate"
    },
    {
      "x": 3,
      "y": 6,
      "z": -4,
      "name": "Rock_Slate"
    },
    {
      "x": 3,
      "y": 7,
      "z": -4,
      "name": "Rock_Slate"
    },
    {
      "x": 3,
      "y": 8,
      "z": -4,
      "name": "Rock_Slate"
    },
    {
      "x": 3,
      "y": 9,
      "z": -4,
      "name": "Rock_Slate"
    },
    {
      "x": 3,
      "y": 10,
      "z": -4,
      "name": "Rock_Slate"
    },
    {
      "x": 3,
      "y": 11,
      "z": -4,
      "name": "Rock_Slate"
    },
    {
      "x": 3,
      "y": 12,
      "z": -4,
      "name": "Rock_Slate"
    },
    {
      "x": 3,
      "y": 13,
      "z": -4,
      "name": "Rock_Slate"
    },
    {
      "x": 3,
      "y": 14,
      "z": -4,
      "name": "Soil_Grass_Burnt"
    },
    {
      "x": 3,
      "y": 15,
      "z": -4,
      "name": "Plant_Grass_Gnarled_Tall"
    },
    {
      "x": 3,
      "y": 16,
      "z": -4,
      "name": "Plant_Grass_Gnarled_Tall",
      "filler": 1024
    },
    {
      "x": 3,
      "y": 5,
      "z": -3,
      "name": "Rock_Slate"
    },
    {
      "x": 3,
      "y": 6,
      "z": -3,
      "name": "Rock_Slate"
    },
    {
      "x": 3,
      "y": 7,
      "z": -3,
      "name": "Rock_Slate"
    },
    {
      "x": 3,
      "y": 8,
      "z": -3,
      "name": "Rock_Slate"
    },
    {
      "x": 3,
      "y": 9,
      "z": -3,
      "name": "Rock_Slate"
    },
    {
      "x": 3,
      "y": 10,
      "z": -3,
      "name": "Rock_Slate"
    },
    {
      "x": 3,
      "y": 11,
      "z": -3,
      "name": "Rock_Slate"
    },
    {
      "x": 3,
      "y": 12,
      "z": -3,
      "name": "Rock_Slate"
    },
    {
      "x": 3,
      "y": 13,
      "z": -3,
      "name": "Rock_Slate"
    },
    {
      "x": 3,
      "y": 14,
      "z": -3,
      "name": "Soil_Grass_Burnt"
    },
    {
      "x": 3,
      "y": 15,
      "z": -3,
      "name": "Plant_Grass_Gnarled_Tall"
    },
    {
      "x": 3,
      "y": 16,
      "z": -3,
      "name": "Plant_Grass_Gnarled_Tall",
      "filler": 1024
    },
    {
      "x": 3,
      "y": 5,
      "z": -2,
      "name": "Rock_Slate"
    },
    {
      "x": 3,
      "y": 6,
      "z": -2,
      "name": "Rock_Slate"
    },
    {
      "x": 3,
      "y": 7,
      "z": -2,
      "name": "Rock_Slate"
    },
    {
      "x": 3,
      "y": 8,
      "z": -2,
      "name": "Rock_Slate"
    },
    {
      "x": 3,
      "y": 9,
      "z": -2,
      "name": "Rock_Slate"
    },
    {
      "x": 3,
      "y": 10,
      "z": -2,
      "name": "Rock_Slate"
    },
    {
      "x": 3,
      "y": 11,
      "z": -2,
      "name": "Rock_Slate"
    },
    {
      "x": 3,
      "y": 12,
      "z": -2,
      "name": "Rock_Slate"
    },
    {
      "x": 3,
      "y": 13,
      "z": -2,
      "name": "Rock_Slate"
    },
    {
      "x": 3,
      "y": 14,
      "z": -2,
      "name": "Soil_Grass_Burnt"
    },
    {
      "x": 3,
      "y": 5,
      "z": -1,
      "name": "Rock_Slate"
    },
    {
      "x": 3,
      "y": 6,
      "z": -1,
      "name": "Rock_Slate"
    },
    {
      "x": 3,
      "y": 7,
      "z": -1,
      "name": "Rock_Slate"
    },
    {
      "x": 3,
      "y": 8,
      "z": -1,
      "name": "Rock_Slate"
    },
    {
      "x": 3,
      "y": 9,
      "z": -1,
      "name": "Rock_Slate"
    },
    {
      "x": 3,
      "y": 10,
      "z": -1,
      "name": "Rock_Slate"
    },
    {
      "x": 3,
      "y": 11,
      "z": -1,
      "name": "Rock_Slate"
    },
    {
      "x": 3,
      "y": 12,
      "z": -1,
      "name": "Rock_Slate"
    },
    {
      "x": 3,
      "y": 13,
      "z": -1,
      "name": "Rock_Slate"
    },
    {
      "x": 3,
      "y": 14,
      "z": -1,
      "name": "Soil_Grass_Burnt"
    },
    {
      "x": 4,
      "y": 8,
      "z": -4,
      "name": "Rock_Slate"
    },
    {
      "x": 4,
      "y": 9,
      "z": -4,
      "name": "Rock_Slate"
    },
    {
      "x": 4,
      "y": 10,
      "z": -4,
      "name": "Rock_Slate"
    },
    {
      "x": 4,
      "y": 11,
      "z": -4,
      "name": "Rock_Slate"
    },
    {
      "x": 4,
      "y": 12,
      "z": -4,
      "name": "Rock_Slate"
    },
    {
      "x": 4,
      "y": 13,
      "z": -4,
      "name": "Rock_Slate"
    },
    {
      "x": 4,
      "y": 14,
      "z": -4,
      "name": "Soil_Grass_Burnt"
    },
    {
      "x": 4,
      "y": 7,
      "z": -3,
      "name": "Rock_Slate"
    },
    {
      "x": 4,
      "y": 8,
      "z": -3,
      "name": "Rock_Slate"
    },
    {
      "x": 4,
      "y": 9,
      "z": -3,
      "name": "Rock_Slate"
    },
    {
      "x": 4,
      "y": 10,
      "z": -3,
      "name": "Rock_Slate"
    },
    {
      "x": 4,
      "y": 11,
      "z": -3,
      "name": "Rock_Slate"
    },
    {
      "x": 4,
      "y": 12,
      "z": -3,
      "name": "Rock_Slate"
    },
    {
      "x": 4,
      "y": 13,
      "z": -3,
      "name": "Rock_Slate"
    },
    {
      "x": 4,
      "y": 14,
      "z": -3,
      "name": "Soil_Grass_Burnt"
    },
    {
      "x": 4,
      "y": 15,
      "z": -3,
      "name": "Plant_Grass_Gnarled_Short"
    }
  ]
}