{
  "version": 8,
  "blockIdVersion": 8,
  "anchorX": 4,
  "anchorY": 3,
  "anchorZ": 6,
  "blocks": [
    {
      "x": -5,
      "y": 8,
      "z": -1,
      "name": "Rock_Ice"
    },
    {
      "x": -4,
      "y": 6,
      "z": -4,
      "name": "Empty"
    },
    {
      "x": -4,
      "y": 7,
      "z": -4,
      "name": "Empty"
    },
    {
      "x": -4,
      "y": 5,
      "z": -3,
      "name": "Empty"
    },
    {
      "x": -4,
      "y": 6,
      "z": -3,
      "name": "Empty"
    },
    {
      "x": -4,
      "y": 7,
      "z": -3,
      "name": "Empty"
    },
    {
      "x": -4,
      "y": 7,
      "z": -2,
      "name": "Empty"
    },
    {
      "x": -4,
      "y": 7,
      "z": -1,
      "name": "Rock_Ice"
    },
    {
      "x": -4,
      "y": 8,
      "z": -1,
      "name": "Rock_Ice"
    },
    {
      "x": -4,
      "y": 9,
      "z": -1,
      "name": "Rock_Ice"
    },
    {
      "x": -4,
      "y": 8,
      "z": 0,
      "name": "Rock_Ice"
    },
    {
      "x": -4,
      "y": 11,
      "z": 0,
      "name": "Rock_Ice"
    },
    {
      "x": -4,
      "y": 12,
      "z": 0,
      "name": "Rock_Ice"
    },
    {
      "x": -4,
      "y": 13,
      "z": 0,
      "name": "Rock_Ice"
    },
    {
      "x": -4,
      "y": 12,
      "z": 1,
      "name": "Rock_Ice"
    },
    {
      "x": -4,
      "y": 13,
      "z": 1,
      "name": "Rock_Ice"
    },
    {
      "x": -3,
      "y": 3,
      "z": -4,
      "name": "Soil_Dirt_Cold"
    },
    {
      "x": -3,
      "y": 4,
      "z": -4,
      "name": "Empty"
    },
    {
      "x": -3,
      "y": 5,
      "z": -4,
      "name": "Empty"
    },
    {
      "x": -3,
      "y": 6,
      "z": -4,
      "name": "Empty"
    },
    {
      "x": -3,
      "y": 7,
      "z": -4,
      "name": "Empty"
    },
    {
      "x": -3,
      "y": 3,
      "z": -3,
      "name": "Soil_Dirt_Cold"
    },
    {
      "x": -3,
      "y": 4,
      "z": -3,
      "name": "Empty"
    },
    {
      "x": -3,
      "y": 5,
      "z": -3,
      "name": "Empty"
    },
    {
      "x": -3,
      "y": 6,
      "z": -3,
      "name": "Empty"
    },
    {
      "x": -3,
      "y": 7,
      "z": -3,
      "name": "Empty"
    },
    {
      "x": -3,
      "y": 3,
      "z": -2,
      "name": "Soil_Dirt_Cold"
    },
    {
      "x": -3,
      "y": 4,
      "z": -2,
      "name": "Empty"
    },
    {
      "x": -3,
      "y": 5,
      "z": -2,
      "name": "Empty"
    },
    {
      "x": -3,
      "y": 6,
      "z": -2,
      "name": "Empty"
    },
    {
      "x": -3,
      "y": 7,
      "z": -2,
      "name": "Empty"
    },
    {
      "x": -3,
      "y": 3,
      "z": -1,
      "name": "Soil_Dirt_Cold"
    },
    {
      "x": -3,
      "y": 4,
      "z": -1,
      "name": "Empty"
    },
    {
      "x": -3,
      "y": 5,
      "z": -1,
      "name": "Empty"
    },
    {
      "x": -3,
      "y": 6,
      "z": -1,
      "name": "Empty"
    },
    {
      "x": -3,
      "y": 7,
      "z": -1,
      "name": "Empty"
    },
    {
      "x": -3,
      "y": 8,
      "z": -1,
      "name": "Rock_Ice_Icicles",
      "rotation": 8
    },
    {
      "x": -3,
      "y": 9,
      "z": -1,
      "name": "Rock_Ice"
    },
    {
      "x": -3,
      "y": 10,
      "z": -1,
      "name": "Rock_Ice"
    },
    {
      "x": -3,
      "y": 11,
      "z": -1,
      "name": "Rock_Ice"
    },
    {
      "x": -3,
      "y": 12,
      "z": -1,
      "name": "Rock_Ice"
    },
    {
      "x": -3,
      "y": 13,
      "z": -1,
      "name": "Rock_Ice"
    },
    {
      "x": -3,
      "y": 14,
      "z": -1,
      "name": "Rock_Ice"
    },
    {
      "x": -3,
      "y": 7,
      "z": 0,
      "name": "Rock_Ice"
    },
    {
      "x": -3,
      "y": 8,
      "z": 0,
      "name": "Rock_Ice"
    },
    {
      "x": -3,
      "y": 9,
      "z": 0,
      "name": "Rock_Ice"
    },
    {
      "x": -3,
      "y": 10,
      "z": 0,
      "name": "Rock_Ice"
    },
    {
      "x": -3,
      "y": 11,
      "z": 0,
      "name": "Rock_Ice"
    },
    {
      "x": -3,
      "y": 12,
      "z": 0,
      "name": "Rock_Ice"
    },
    {
      "x": -3,
      "y": 13,
      "z": 0,
      "name": "Rock_Ice"
    },
    {
      "x": -3,
      "y": 14,
      "z": 0,
      "name": "Rock_Ice"
    },
    {
      "x": -3,
      "y": 15,
      "z": 0,
      "name": "Rock_Ice"
    },
    {
      "x": -3,
      "y": 16,
      "z": 0,
      "name": "Rock_Ice"
    },
    {
      "x": -3,
      "y": 6,
      "z": 1,
      "name": "Empty"
    },
    {
      "x": -3,
      "y": 7,
      "z": 1,
      "name": "Empty"
    },
    {
      "x": -3,
      "y": 8,
      "z": 1,
      "name": "Empty"
    },
    {
      "x": -3,
      "y": 10,
      "z": 1,
      "name": "Rock_Ice"
    },
    {
      "x": -3,
      "y": 11,
      "z": 1,
      "name": "Rock_Ice"
    },
    {
      "x": -3,
      "y": 12,
      "z": 1,
      "name": "Rock_Ice"
    },
    {
      "x": -3,
      "y": 13,
      "z": 1,
      "name": "Rock_Ice"
    },
    {
      "x": -3,
      "y": 14,
      "z": 1,
      "name": "Rock_Ice"
    },
    {
      "x": -3,
      "y": 15,
      "z": 1,
      "name": "Rock_Ice"
    },
    {
      "x": -3,
      "y": 16,
      "z": 1,
      "name": "Rock_Ice"
    },
    {
      "x": -3,
      "y": 4,
      "z": 2,
      "name": "Empty"
    },
    {
      "x": -3,
      "y": 5,
      "z": 2,
      "name": "Empty"
    },
    {
      "x": -3,
      "y": 6,
      "z": 2,
      "name": "Empty"
    },
    {
      "x": -3,
      "y": 7,
      "z": 2,
      "name": "Empty"
    },
    {
      "x": -3,
      "y": 8,
      "z": 2,
      "name": "Rock_Ice_Icicles",
      "rotation": 8
    },
    {
      "x": -3,
      "y": 9,
      "z": 2,
      "name": "Rock_Ice"
    },
    {
      "x": -3,
      "y": 10,
      "z": 2,
      "name": "Rock_Ice"
    },
    {
      "x": -3,
      "y": 11,
      "z": 2,
      "name": "Rock_Ice"
    },
    {
      "x": -3,
      "y": 12,
      "z": 2,
      "name": "Rock_Ice"
    },
    {
      "x": -3,
      "y": 13,
      "z": 2,
      "name": "Rock_Ice"
    },
    {
      "x": -3,
      "y": 14,
      "z": 2,
      "name": "Rock_Ice"
    },
    {
      "x": -3,
      "y": 15,
      "z": 2,
      "name": "Rock_Ice"
    },
    {
      "x": -3,
      "y": 4,
      "z": 3,
      "name": "Empty"
    },
    {
      "x": -3,
      "y": 5,
      "z": 3,
      "name": "Empty"
    },
    {
      "x": -3,
      "y": 6,
      "z": 3,
      "name": "Empty"
    },
    {
      "x": -3,
      "y": 7,
      "z": 3,
      "name": "Rock_Ice_Icicles",
      "rotation": 8
    },
    {
      "x": -3,
      "y": 8,
      "z": 3,
      "name": "Rock_Ice"
    },
    {
      "x": -3,
      "y": 9,
      "z": 3,
      "name": "Rock_Ice"
    },
    {
      "x": -3,
      "y": 10,
      "z": 3,
      "name": "Rock_Ice"
    },
    {
      "x": -3,
      "y": 11,
      "z": 3,
      "name": "Rock_Ice"
    },
    {
      "x": -3,
      "y": 12,
      "z": 3,
      "name": "Rock_Ice"
    },
    {
      "x": -3,
      "y": 13,
      "z": 3,
      "name": "Rock_Ice"
    },
    {
      "x": -3,
      "y": 5,
      "z": 4,
      "name": "Empty"
    },
    {
      "x": -3,
      "y": 6,
      "z": 4,
      "name": "Empty"
    },
    {
      "x": -3,
      "y": 7,
      "z": 4,
      "name": "Empty"
    },
    {
      "x": -2,
      "y": 3,
      "z": -4,
      "name": "Soil_Dirt_Cold"
    },
    {
      "x": -2,
      "y": 4,
      "z": -4,
      "name": "Empty"
    },
    {
      "x": -2,
      "y": 5,
      "z": -4,
      "name": "Empty"
    },
    {
      "x": -2,
      "y": 6,
      "z": -4,
      "name": "Empty"
    },
    {
      "x": -2,
      "y": 7,
      "z": -4,
      "name": "Empty"
    },
    {
      "x": -2,
      "y": 3,
      "z": -3,
      "name": "Soil_Dirt_Cold"
    },
    {
      "x": -2,
      "y": 4,
      "z": -3,
      "name": "Empty"
    },
    {
      "x": -2,
      "y": 5,
      "z": -3,
      "name": "Empty"
    },
    {
      "x": -2,
      "y": 6,
      "z": -3,
      "name": "Empty"
    },
    {
      "x": -2,
      "y": 7,
      "z": -3,
      "name": "Empty"
    },
    {
      "x": -2,
      "y": 8,
      "z": -3,
      "name": "Empty"
    },
    {
      "x": -2,
      "y": 9,
      "z": -3,
      "name": "Rock_Ice"
    },
    {
      "x": -2,
      "y": 3,
      "z": -2,
      "name": "Soil_Dirt_Cold"
    },
    {
      "x": -2,
      "y": 4,
      "z": -2,
      "name": "Empty"
    },
    {
      "x": -2,
      "y": 5,
      "z": -2,
      "name": "Empty"
    },
    {
      "x": -2,
      "y": 6,
      "z": -2,
      "name": "Empty"
    },
    {
      "x": -2,
      "y": 7,
      "z": -2,
      "name": "Empty"
    },
    {
      "x": -2,
      "y": 8,
      "z": -2,
      "name": "Empty"
    },
    {
      "x": -2,
      "y": 9,
      "z": -2,
      "name": "Rock_Ice"
    },
    {
      "x": -2,
      "y": 3,
      "z": -1,
      "name": "Soil_Dirt_Cold"
    },
    {
      "x": -2,
      "y": 4,
      "z": -1,
      "name": "Rubble_Shale_Medium"
    },
    {
      "x": -2,
      "y": 5,
      "z": -1,
      "name": "Empty"
    },
    {
      "x": -2,
      "y": 6,
      "z": -1,
      "name": "Empty"
    },
    {
      "x": -2,
      "y": 7,
      "z": -1,
      "name": "Empty"
    },
    {
      "x": -2,
      "y": 8,
      "z": -1,
      "name": "Rock_Crystal_Cyan_Medium",
      "rotation": 8
    },
    {
      "x": -2,
      "y": 9,
      "z": -1,
      "name": "Rock_Ice"
    },
    {
      "x": -2,
      "y": 10,
      "z": -1,
      "name": "Rock_Ice"
    },
    {
      "x": -2,
      "y": 11,
      "z": -1,
      "name": "Rock_Ice"
    },
    {
      "x": -2,
      "y": 12,
      "z": -1,
      "name": "Rock_Ice"
    },
    {
      "x": -2,
      "y": 13,
      "z": -1,
      "name": "Rock_Ice"
    },
    {
      "x": -2,
      "y": 14,
      "z": -1,
      "name": "Rock_Ice"
    },
    {
      "x": -2,
      "y": 15,
      "z": -1,
      "name": "Rock_Ice"
    },
    {
      "x": -2,
      "y": 3,
      "z": 0,
      "name": "Soil_Dirt_Cold"
    },
    {
      "x": -2,
      "y": 4,
      "z": 0,
      "name": "Empty"
    },
    {
      "x": -2,
      "y": 5,
      "z": 0,
      "name": "Empty"
    },
    {
      "x": -2,
      "y": 6,
      "z": 0,
      "name": "Empty"
    },
    {
      "x": -2,
      "y": 7,
      "z": 0,
      "name": "Empty"
    },
    {
      "x": -2,
      "y": 8,
      "z": 0,
      "name": "Empty"
    },
    {
      "x": -2,
      "y": 9,
      "z": 0,
      "name": "Rock_Ice"
    },
    {
      "x": -2,
      "y": 10,
      "z": 0,
      "name": "Rock_Ice"
    },
    {
      "x": -2,
      "y": 11,
      "z": 0,
      "name": "Rock_Ice"
    },
    {
      "x": -2,
      "y": 12,
      "z": 0,
      "name": "Rock_Ice"
    },
    {
      "x": -2,
      "y": 13,
      "z": 0,
      "name": "Rock_Ice"
    },
    {
      "x": -2,
      "y": 14,
      "z": 0,
      "name": "Rock_Ice"
    },
    {
      "x": -2,
      "y": 15,
      "z": 0,
      "name": "Rock_Ice"
    },
    {
      "x": -2,
      "y": 16,
      "z": 0,
      "name": "Rock_Ice"
    },
    {
      "x": -2,
      "y": 3,
      "z": 1,
      "name": "Soil_Dirt_Cold"
    },
    {
      "x": -2,
      "y": 4,
      "z": 1,
      "name": "Rubble_Ice"
    },
    {
      "x": -2,
      "y": 5,
      "z": 1,
      "name": "Empty"
    },
    {
      "x": -2,
      "y": 6,
      "z": 1,
      "name": "Empty"
    },
    {
      "x": -2,
      "y": 7,
      "z": 1,
      "name": "Rock_Ice_Icicles",
      "rotation": 8
    },
    {
      "x": -2,
      "y": 8,
      "z": 1,
      "name": "Rock_Ice"
    },
    {
      "x": -2,
      "y": 9,
      "z": 1,
      "name": "Rock_Ice"
    },
    {
      "x": -2,
      "y": 10,
      "z": 1,
      "name": "Rock_Ice"
    },
    {
      "x": -2,
      "y": 11,
      "z": 1,
      "name": "Rock_Ice"
    },
    {
      "x": -2,
      "y": 12,
      "z": 1,
      "name": "Rock_Ice"
    },
    {
      "x": -2,
      "y": 13,
      "z": 1,
      "name": "Rock_Ice"
    },
    {
      "x": -2,
      "y": 14,
      "z": 1,
      "name": "Rock_Ice"
    },
    {
      "x": -2,
      "y": 15,
      "z": 1,
      "name": "Rock_Ice"
    },
    {
      "x": -2,
      "y": 16,
      "z": 1,
      "name": "Rock_Ice"
    },
    {
      "x": -2,
      "y": 3,
      "z": 2,
      "name": "Soil_Dirt_Cold"
    },
    {
      "x": -2,
      "y": 4,
      "z": 2,
      "name": "Empty"
    },
    {
      "x": -2,
      "y": 5,
      "z": 2,
      "name": "Empty"
    },
    {
      "x": -2,
      "y": 6,
      "z": 2,
      "name": "Empty"
    },
    {
      "x": -2,
      "y": 7,
      "z": 2,
      "name": "Rock_Crystal_Cyan_Small",
      "rotation": 8
    },
    {
      "x": -2,
      "y": 8,
      "z": 2,
      "name": "Rock_Ice"
    },
    {
      "x": -2,
      "y": 9,
      "z": 2,
      "name": "Rock_Ice"
    },
    {
      "x": -2,
      "y": 10,
      "z": 2,
      "name": "Rock_Ice"
    },
    {
      "x": -2,
      "y": 11,
      "z": 2,
      "name": "Rock_Ice"
    },
    {
      "x": -2,
      "y": 12,
      "z": 2,
      "name": "Rock_Ice"
    },
    {
      "x": -2,
      "y": 13,
      "z": 2,
      "name": "Rock_Ice"
    },
    {
      "x": -2,
      "y": 14,
      "z": 2,
      "name": "Rock_Ice"
    },
    {
      "x": -2,
      "y": 15,
      "z": 2,
      "name": "Rock_Ice"
    },
    {
      "x": -2,
      "y": 16,
      "z": 2,
      "name": "Rock_Ice"
    },
    {
      "x": -2,
      "y": 3,
      "z": 3,
      "name": "Soil_Dirt_Cold"
    },
    {
      "x": -2,
      "y": 4,
      "z": 3,
      "name": "Plant_Bush_Winter"
    },
    {
      "x": -2,
      "y": 5,
      "z": 3,
      "name": "Empty"
    },
    {
      "x": -2,
      "y": 6,
      "z": 3,
      "name": "Empty"
    },
    {
      "x": -2,
      "y": 7,
      "z": 3,
      "name": "Empty"
    },
    {
      "x": -2,
      "y": 8,
      "z": 3,
      "name": "Rock_Ice"
    },
    {
      "x": -2,
      "y": 12,
      "z": 3,
      "name": "Rock_Ice"
    },
    {
      "x": -2,
      "y": 13,
      "z": 3,
      "name": "Rock_Ice"
    },
    {
      "x": -2,
      "y": 3,
      "z": 4,
      "name": "Soil_Dirt_Cold"
    },
    {
      "x": -2,
      "y": 4,
      "z": 4,
      "name": "Plant_Flower_Orchid_Blue"
    },
    {
      "x": -2,
      "y": 5,
      "z": 4,
      "name": "Empty"
    },
    {
      "x": -2,
      "y": 6,
      "z": 4,
      "name": "Empty"
    },
    {
      "x": -2,
      "y": 7,
      "z": 4,
      "name": "Empty"
    },
    {
      "x": -2,
      "y": 3,
      "z": 5,
      "name": "Soil_Dirt_Cold"
    },
    {
      "x": -2,
      "y": 4,
      "z": 5,
      "name": "Empty"
    },
    {
      "x": -2,
      "y": 5,
      "z": 5,
      "name": "Empty"
    },
    {
      "x": -2,
      "y": 6,
      "z": 5,
      "name": "Empty"
    },
    {
      "x": -1,
      "y": 3,
      "z": -4,
      "name": "Soil_Dirt_Cold"
    },
    {
      "x": -1,
      "y": 4,
      "z": -4,
      "name": "Rail"
    },
    {
      "x": -1,
      "y": 5,
      "z": -4,
      "name": "Empty"
    },
    {
      "x": -1,
      "y": 6,
      "z": -4,
      "name": "Empty"
    },
    {
      "x": -1,
      "y": 7,
      "z": -4,
      "name": "Empty"
    },
    {
      "x": -1,
      "y": 3,
      "z": -3,
      "name": "Soil_Dirt_Cold"
    },
    {
      "x": -1,
      "y": 4,
      "z": -3,
      "name": "Rail"
    },
    {
      "x": -1,
      "y": 5,
      "z": -3,
      "name": "Empty"
    },
    {
      "x": -1,
      "y": 6,
      "z": -3,
      "name": "Empty"
    },
    {
      "x": -1,
      "y": 7,
      "z": -3,
      "name": "Empty"
    },
    {
      "x": -1,
      "y": 8,
      "z": -3,
      "name": "Empty"
    },
    {
      "x": -1,
      "y": 9,
      "z": -3,
      "name": "Rock_Ice"
    },
    {
      "x": -1,
      "y": 10,
      "z": -3,
      "name": "Rock_Ice"
    },
    {
      "x": -1,
      "y": 11,
      "z": -3,
      "name": "Rock_Ice"
    },
    {
      "x": -1,
      "y": 12,
      "z": -3,
      "name": "Rock_Ice"
    },
    {
      "x": -1,
      "y": 13,
      "z": -3,
      "name": "Rock_Ice"
    },
    {
      "x": -1,
      "y": 14,
      "z": -3,
      "name": "Rock_Ice"
    },
    {
      "x": -1,
      "y": 3,
      "z": -2,
      "name": "Soil_Dirt_Cold"
    },
    {
      "x": -1,
      "y": 4,
      "z": -2,
      "name": "Rail"
    },
    {
      "x": -1,
      "y": 5,
      "z": -2,
      "name": "Empty"
    },
    {
      "x": -1,
      "y": 6,
      "z": -2,
      "name": "Empty"
    },
    {
      "x": -1,
      "y": 7,
      "z": -2,
      "name": "Empty"
    },
    {
      "x": -1,
      "y": 8,
      "z": -2,
      "name": "Empty"
    },
    {
      "x": -1,
      "y": 9,
      "z": -2,
      "name": "Rock_Ice"
    },
    {
      "x": -1,
      "y": 10,
      "z": -2,
      "name": "Rock_Ice"
    },
    {
      "x": -1,
      "y": 11,
      "z": -2,
      "name": "Rock_Ice"
    },
    {
      "x": -1,
      "y": 12,
      "z": -2,
      "name": "Rock_Ice"
    },
    {
      "x": -1,
      "y": 13,
      "z": -2,
      "name": "Rock_Ice"
    },
    {
      "x": -1,
      "y": 14,
      "z": -2,
      "name": "Rock_Ice"
    },
    {
      "x": -1,
      "y": 3,
      "z": -1,
      "name": "Soil_Dirt_Cold"
    },
    {
      "x": -1,
      "y": 4,
      "z": -1,
      "name": "Rail"
    },
    {
      "x": -1,
      "y": 5,
      "z": -1,
      "name": "Empty"
    },
    {
      "x": -1,
      "y": 6,
      "z": -1,
      "name": "Empty"
    },
    {
      "x": -1,
      "y": 7,
      "z": -1,
      "name": "Empty"
    },
    {
      "x": -1,
      "y": 8,
      "z": -1,
      "name": "Rock_Crystal_Cyan_Small",
      "rotation": 8
    },
    {
      "x": -1,
      "y": 9,
      "z": -1,
      "name": "Rock_Ice"
    },
    {
      "x": -1,
      "y": 10,
      "z": -1,
      "name": "Rock_Ice"
    },
    {
      "x": -1,
      "y": 11,
      "z": -1,
      "name": "Rock_Ice"
    },
    {
      "x": -1,
      "y": 12,
      "z": -1,
      "name": "Rock_Ice"
    },
    {
      "x": -1,
      "y": 13,
      "z": -1,
      "name": "Rock_Ice"
    },
    {
      "x": -1,
      "y": 14,
      "z": -1,
      "name": "Rock_Ice"
    },
    {
      "x": -1,
      "y": 15,
      "z": -1,
      "name": "Rock_Ice"
    },
    {
      "x": -1,
      "y": 3,
      "z": 0,
      "name": "Soil_Dirt_Cold"
    },
    {
      "x": -1,
      "y": 4,
      "z": 0,
      "name": "*Rail_State_Definitions_Corner_Left",
      "rotation": 2
    },
    {
      "x": -1,
      "y": 5,
      "z": 0,
      "name": "Empty"
    },
    {
      "x": -1,
      "y": 6,
      "z": 0,
      "name": "Empty"
    },
    {
      "x": -1,
      "y": 7,
      "z": 0,
      "name": "Empty"
    },
    {
      "x": -1,
      "y": 8,
      "z": 0,
      "name": "Rock_Ice_Icicles",
      "rotation": 8
    },
    {
      "x": -1,
      "y": 9,
      "z": 0,
      "name": "Rock_Ice"
    },
    {
      "x": -1,
      "y": 10,
      "z": 0,
      "name": "Rock_Ice"
    },
    {
      "x": -1,
      "y": 11,
      "z": 0,
      "name": "Rock_Ice"
    },
    {
      "x": -1,
      "y": 12,
      "z": 0,
      "name": "Rock_Ice"
    },
    {
      "x": -1,
      "y": 13,
      "z": 0,
      "name": "Rock_Ice"
    },
    {
      "x": -1,
      "y": 14,
      "z": 0,
      "name": "Rock_Ice"
    },
    {
      "x": -1,
      "y": 15,
      "z": 0,
      "name": "Rock_Ice"
    },
    {
      "x": -1,
      "y": 16,
      "z": 0,
      "name": "Rock_Ice"
    },
    {
      "x": -1,
      "y": 3,
      "z": 1,
      "name": "Soil_Dirt_Cold"
    },
    {
      "x": -1,
      "y": 4,
      "z": 1,
      "name": "Empty"
    },
    {
      "x": -1,
      "y": 5,
      "z": 1,
      "name": "Empty"
    },
    {
      "x": -1,
      "y": 6,
      "z": 1,
      "name": "Empty"
    },
    {
      "x": -1,
      "y": 7,
      "z": 1,
      "name": "Rock_Ice_Icicles",
      "rotation": 8
    },
    {
      "x": -1,
      "y": 8,
      "z": 1,
      "name": "Rock_Ice"
    },
    {
      "x": -1,
      "y": 9,
      "z": 1,
      "name": "Rock_Ice"
    },
    {
      "x": -1,
      "y": 10,
      "z": 1,
      "name": "Rock_Ice"
    },
    {
      "x": -1,
      "y": 11,
      "z": 1,
      "name": "Rock_Ice"
    },
    {
      "x": -1,
      "y": 12,
      "z": 1,
      "name": "Rock_Ice"
    },
    {
      "x": -1,
      "y": 13,
      "z": 1,
      "name": "Rock_Ice"
    },
    {
      "x": -1,
      "y": 14,
      "z": 1,
      "name": "Rock_Ice"
    },
    {
      "x": -1,
      "y": 15,
      "z": 1,
      "name": "Rock_Ice"
    },
    {
      "x": -1,
      "y": 16,
      "z": 1,
      "name": "Rock_Ice"
    },
    {
      "x": -1,
      "y": 3,
      "z": 2,
      "name": "Soil_Dirt_Cold"
    },
    {
      "x": -1,
      "y": 4,
      "z": 2,
      "name": "Empty"
    },
    {
      "x": -1,
      "y": 5,
      "z": 2,
      "name": "Empty"
    },
    {
      "x": -1,
      "y": 6,
      "z": 2,
      "name": "Empty"
    },
    {
      "x": -1,
      "y": 7,
      "z": 2,
      "name": "Empty"
    },
    {
      "x": -1,
      "y": 10,
      "z": 2,
      "name": "Rock_Ice"
    },
    {
      "x": -1,
      "y": 11,
      "z": 2,
      "name": "Rock_Ice"
    },
    {
      "x": -1,
      "y": 12,
      "z": 2,
      "name": "Rock_Ice"
    },
    {
      "x": -1,
      "y": 13,
      "z": 2,
      "name": "Rock_Ice"
    },
    {
      "x": -1,
      "y": 14,
      "z": 2,
      "name": "Rock_Ice"
    },
    {
      "x": -1,
      "y": 15,
      "z": 2,
      "name": "Rock_Ice"
    },
    {
      "x": -1,
      "y": 16,
      "z": 2,
      "name": "Rock_Ice"
    },
    {
      "x": -1,
      "y": 3,
      "z": 3,
      "name": "Soil_Dirt_Cold"
    },
    {
      "x": -1,
      "y": 4,
      "z": 3,
      "name": "Plant_Bush_Dead_Twisted"
    },
    {
      "x": -1,
      "y": 5,
      "z": 3,
      "name": "Empty"
    },
    {
      "x": -1,
      "y": 6,
      "z": 3,
      "name": "Empty"
    },
    {
      "x": -1,
      "y": 3,
      "z": 4,
      "name": "Soil_Dirt_Cold"
    },
    {
      "x": -1,
      "y": 4,
      "z": 4,
      "name": "Empty"
    },
    {
      "x": -1,
      "y": 5,
      "z": 4,
      "name": "Empty"
    },
    {
      "x": -1,
      "y": 6,
      "z": 4,
      "name": "Empty"
    },
    {
      "x": -1,
      "y": 3,
      "z": 5,
      "name": "Soil_Dirt_Cold"
    },
    {
      "x": -1,
      "y": 4,
      "z": 5,
      "name": "Empty"
    },
    {
      "x": -1,
      "y": 5,
      "z": 5,
      "name": "Empty"
    },
    {
      "x": -1,
      "y": 6,
      "z": 5,
      "name": "Empty"
    },
    {
      "x": 0,
      "y": 3,
      "z": -4,
      "name": "Soil_Dirt_Cold"
    },
    {
      "x": 0,
      "y": 4,
      "z": -4,
      "name": "Empty"
    },
    {
      "x": 0,
      "y": 5,
      "z": -4,
      "name": "Empty"
    },
    {
      "x": 0,
      "y": 6,
      "z": -4,
      "name": "Empty"
    },
    {
      "x": 0,
      "y": 7,
      "z": -4,
      "name": "Empty"
    },
    {
      "x": 0,
      "y": 3,
      "z": -3,
      "name": "Soil_Dirt_Cold"
    },
    {
      "x": 0,
      "y": 4,
      "z": -3,
      "name": "Empty"
    },
    {
      "x": 0,
      "y": 5,
      "z": -3,
      "name": "Empty"
    },
    {
      "x": 0,
      "y": 6,
      "z": -3,
      "name": "Empty"
    },
    {
      "x": 0,
      "y": 7,
      "z": -3,
      "name": "Empty"
    },
    {
      "x": 0,
      "y": 8,
      "z": -3,
      "name": "Empty"
    },
    {
      "x": 0,
      "y": 9,
      "z": -3,
      "name": "Rock_Ice"
    },
    {
      "x": 0,
      "y": 10,
      "z": -3,
      "name": "Rock_Ice"
    },
    {
      "x": 0,
      "y": 11,
      "z": -3,
      "name": "Rock_Ice"
    },
    {
      "x": 0,
      "y": 12,
      "z": -3,
      "name": "Rock_Ice"
    },
    {
      "x": 0,
      "y": 13,
      "z": -3,
      "name": "Rock_Ice"
    },
    {
      "x": 0,
      "y": 14,
      "z": -3,
      "name": "Rock_Ice"
    },
    {
      "x": 0,
      "y": 3,
      "z": -2,
      "name": "Soil_Dirt_Cold"
    },
    {
      "x": 0,
      "y": 4,
      "z": -2,
      "name": "Plant_Crop_Mushroom_Glowing_Blue"
    },
    {
      "x": 0,
      "y": 5,
      "z": -2,
      "name": "Empty"
    },
    {
      "x": 0,
      "y": 6,
      "z": -2,
      "name": "Empty"
    },
    {
      "x": 0,
      "y": 7,
      "z": -2,
      "name": "Empty"
    },
    {
      "x": 0,
      "y": 8,
      "z": -2,
      "name": "Empty"
    },
    {
      "x": 0,
      "y": 9,
      "z": -2,
      "name": "Rock_Ice"
    },
    {
      "x": 0,
      "y": 10,
      "z": -2,
      "name": "Rock_Ice"
    },
    {
      "x": 0,
      "y": 11,
      "z": -2,
      "name": "Rock_Ice"
    },
    {
      "x": 0,
      "y": 12,
      "z": -2,
      "name": "Rock_Ice"
    },
    {
      "x": 0,
      "y": 13,
      "z": -2,
      "name": "Rock_Ice"
    },
    {
      "x": 0,
      "y": 14,
      "z": -2,
      "name": "Rock_Ice"
    },
    {
      "x": 0,
      "y": 3,
      "z": -1,
      "name": "Soil_Dirt_Cold"
    },
    {
      "x": 0,
      "y": 4,
      "z": -1,
      "name": "Empty"
    },
    {
      "x": 0,
      "y": 5,
      "z": -1,
      "name": "Empty"
    },
    {
      "x": 0,
      "y": 6,
      "z": -1,
      "name": "Empty"
    },
    {
      "x": 0,
      "y": 7,
      "z": -1,
      "name": "Empty"
    },
    {
      "x": 0,
      "y": 8,
      "z": -1,
      "name": "Empty"
    },
    {
      "x": 0,
      "y": 9,
      "z": -1,
      "name": "Rock_Ice"
    },
    {
      "x": 0,
      "y": 10,
      "z": -1,
      "name": "Rock_Ice"
    },
    {
      "x": 0,
      "y": 11,
      "z": -1,
      "name": "Rock_Ice"
    },
    {
      "x": 0,
      "y": 12,
      "z": -1,
      "name": "Rock_Ice"
    },
    {
      "x": 0,
      "y": 13,
      "z": -1,
      "name": "Rock_Ice"
    },
    {
      "x": 0,
      "y": 14,
      "z": -1,
      "name": "Rock_Ice"
    },
    {
      "x": 0,
      "y": 15,
      "z": -1,
      "name": "Rock_Ice"
    },
    {
      "x": 0,
      "y": 3,
      "z": 0,
      "name": "Soil_Dirt_Cold"
    },
    {
      "x": 0,
      "y": 4,
      "z": 0,
      "name": "*Rail_State_Definitions_Corner_Left"
    },
    {
      "x": 0,
      "y": 5,
      "z": 0,
      "name": "Empty"
    },
    {
      "x": 0,
      "y": 6,
      "z": 0,
      "name": "Empty"
    },
    {
      "x": 0,
      "y": 7,
      "z": 0,
      "name": "Empty"
    },
    {
      "x": 0,
      "y": 8,
      "z": 0,
      "name": "Empty"
    },
    {
      "x": 0,
      "y": 9,
      "z": 0,
      "name": "Rock_Ice"
    },
    {
      "x": 0,
      "y": 10,
      "z": 0,
      "name": "Rock_Ice"
    },
    {
      "x": 0,
      "y": 11,
      "z": 0,
      "name": "Rock_Ice"
    },
    {
      "x": 0,
      "y": 12,
      "z": 0,
      "name": "Rock_Ice"
    },
    {
      "x": 0,
      "y": 13,
      "z": 0,
      "name": "Rock_Ice"
    },
    {
      "x": 0,
      "y": 14,
      "z": 0,
      "name": "Rock_Ice"
    },
    {
      "x": 0,
      "y": 15,
      "z": 0,
      "name": "Rock_Ice"
    },
    {
      "x": 0,
      "y": 16,
      "z": 0,
      "name": "Rock_Ice"
    },
    {
      "x": 0,
      "y": 3,
      "z": 1,
      "name": "Soil_Dirt_Cold"
    },
    {
      "x": 0,
      "y": 4,
      "z": 1,
      "name": "Rail"
    },
    {
      "x": 0,
      "y": 5,
      "z": 1,
      "name": "Empty"
    },
    {
      "x": 0,
      "y": 6,
      "z": 1,
      "name": "Empty"
    },
    {
      "x": 0,
      "y": 7,
      "z": 1,
      "name": "Empty"
    },
    {
      "x": 0,
      "y": 8,
      "z": 1,
      "name": "Rock_Ice"
    },
    {
      "x": 0,
      "y": 9,
      "z": 1,
      "name": "Rock_Ice"
    },
    {
      "x": 0,
      "y": 10,
      "z": 1,
      "name": "Rock_Ice"
    },
    {
      "x": 0,
      "y": 11,
      "z": 1,
      "name": "Rock_Ice"
    },
    {
      "x": 0,
      "y": 12,
      "z": 1,
      "name": "Rock_Ice"
    },
    {
      "x": 0,
      "y": 13,
      "z": 1,
      "name": "Rock_Ice"
    },
    {
      "x": 0,
      "y": 14,
      "z": 1,
      "name": "Rock_Ice"
    },
    {
      "x": 0,
      "y": 15,
      "z": 1,
      "name": "Rock_Ice"
    },
    {
      "x": 0,
      "y": 16,
      "z": 1,
      "name": "Rock_Ice"
    },
    {
      "x": 0,
      "y": 3,
      "z": 2,
      "name": "Soil_Dirt_Cold"
    },
    {
      "x": 0,
      "y": 4,
      "z": 2,
      "name": "Rail"
    },
    {
      "x": 0,
      "y": 5,
      "z": 2,
      "name": "Empty"
    },
    {
      "x": 0,
      "y": 6,
      "z": 2,
      "name": "Empty"
    },
    {
      "x": 0,
      "y": 7,
      "z": 2,
      "name": "Empty"
    },
    {
      "x": 0,
      "y": 10,
      "z": 2,
      "name": "Rock_Ice"
    },
    {
      "x": 0,
      "y": 11,
      "z": 2,
      "name": "Rock_Ice"
    },
    {
      "x": 0,
      "y": 12,
      "z": 2,
      "name": "Rock_Ice"
    },
    {
      "x": 0,
      "y": 13,
      "z": 2,
      "name": "Rock_Ice"
    },
    {
      "x": 0,
      "y": 14,
      "z": 2,
      "name": "Rock_Ice"
    },
    {
      "x": 0,
      "y": 15,
      "z": 2,
      "name": "Rock_Ice"
    },
    {
      "x": 0,
      "y": 16,
      "z": 2,
      "name": "Rock_Ice"
    },
    {
      "x": 0,
      "y": 3,
      "z": 3,
      "name": "Soil_Dirt_Cold"
    },
    {
      "x": 0,
      "y": 4,
      "z": 3,
      "name": "Rail"
    },
    {
      "x": 0,
      "y": 5,
      "z": 3,
      "name": "Empty"
    },
    {
      "x": 0,
      "y": 6,
      "z": 3,
      "name": "Empty"
    },
    {
      "x": 0,
      "y": 3,
      "z": 4,
      "name": "Soil_Dirt_Cold"
    },
    {
      "x": 0,
      "y": 4,
      "z": 4,
      "name": "Rail"
    },
    {
      "x": 0,
      "y": 5,
      "z": 4,
      "name": "Empty"
    },
    {
      "x": 0,
      "y": 6,
      "z": 4,
      "name": "Empty"
    },
    {
      "x": 0,
      "y": 3,
      "z": 5,
      "name": "Soil_Dirt_Cold"
    },
    {
      "x": 0,
      "y": 4,
      "z": 5,
      "name": "Rail"
    },
    {
      "x": 0,
      "y": 5,
      "z": 5,
      "name": "Empty"
    },
    {
      "x": 0,
      "y": 6,
      "z": 5,
      "name": "Empty"
    },
    {
      "x": 1,
      "y": 3,
      "z": -4,
      "name": "Soil_Dirt_Cold"
    },
    {
      "x": 1,
      "y": 4,
      "z": -4,
      "name": "Plant_Bush_Dead_Twisted"
    },
    {
      "x": 1,
      "y": 5,
      "z": -4,
      "name": "Empty"
    },
    {
      "x": 1,
      "y": 6,
      "z": -4,
      "name": "Empty"
    },
    {
      "x": 1,
      "y": 7,
      "z": -4,
      "name": "Empty"
    },
    {
      "x": 1,
      "y": 3,
      "z": -3,
      "name": "Soil_Dirt_Cold"
    },
    {
      "x": 1,
      "y": 4,
      "z": -3,
      "name": "Plant_Crop_Mushroom_Flatcap_Blue",
      "components": {
        "Components": {
          "FarmingBlock": {}
        }
      }
    },
    {
      "x": 1,
      "y": 5,
      "z": -3,
      "name": "Empty"
    },
    {
      "x": 1,
      "y": 6,
      "z": -3,
      "name": "Empty"
    },
    {
      "x": 1,
      "y": 7,
      "z": -3,
      "name": "Empty"
    },
    {
      "x": 1,
      "y": 8,
      "z": -3,
      "name": "Empty"
    },
    {
      "x": 1,
      "y": 10,
      "z": -3,
      "name": "Rock_Ice"
    },
    {
      "x": 1,
      "y": 11,
      "z": -3,
      "name": "Rock_Ice"
    },
    {
      "x": 1,
      "y": 12,
      "z": -3,
      "name": "Rock_Ice"
    },
    {
      "x": 1,
      "y": 13,
      "z": -3,
      "name": "Rock_Ice"
    },
    {
      "x": 1,
      "y": 14,
      "z": -3,
      "name": "Rock_Ice"
    },
    {
      "x": 1,
      "y": 3,
      "z": -2,
      "name": "Soil_Dirt_Cold"
    },
    {
      "x": 1,
      "y": 4,
      "z": -2,
      "name": "Plant_Bush_Winter"
    },
    {
      "x": 1,
      "y": 5,
      "z": -2,
      "name": "Empty"
    },
    {
      "x": 1,
      "y": 6,
      "z": -2,
      "name": "Empty"
    },
    {
      "x": 1,
      "y": 7,
      "z": -2,
      "name": "Empty"
    },
    {
      "x": 1,
      "y": 8,
      "z": -2,
      "name": "Empty"
    },
    {
      "x": 1,
      "y": 9,
      "z": -2,
      "name": "Rock_Ice"
    },
    {
      "x": 1,
      "y": 10,
      "z": -2,
      "name": "Rock_Ice"
    },
    {
      "x": 1,
      "y": 11,
      "z": -2,
      "name": "Rock_Ice"
    },
    {
      "x": 1,
      "y": 12,
      "z": -2,
      "name": "Rock_Ice"
    },
    {
      "x": 1,
      "y": 13,
      "z": -2,
      "name": "Rock_Ice"
    },
    {
      "x": 1,
      "y": 14,
      "z": -2,
      "name": "Rock_Ice"
    },
    {
      "x": 1,
      "y": 3,
      "z": -1,
      "name": "Soil_Dirt_Cold"
    },
    {
      "x": 1,
      "y": 4,
      "z": -1,
      "name": "Block_Spawner_Block",
      "components": {
        "Components": {
          "BlockSpawner": {
            "BlockSpawnerId": "Zone2_Encounters_Tier2"
          }
        }
      },
      "rotation": 3
    },
    {
      "x": 1,
      "y": 5,
      "z": -1,
      "name": "Empty"
    },
    {
      "x": 1,
      "y": 6,
      "z": -1,
      "name": "Empty"
    },
    {
      "x": 1,
      "y": 7,
      "z": -1,
      "name": "Empty"
    },
    {
      "x": 1,
      "y": 8,
      "z": -1,
      "name": "Empty"
    },
    {
      "x": 1,
      "y": 9,
      "z": -1,
      "name": "Rock_Ice"
    },
    {
      "x": 1,
      "y": 10,
      "z": -1,
      "name": "Rock_Ice"
    },
    {
      "x": 1,
      "y": 11,
      "z": -1,
      "name": "Rock_Ice"
    },
    {
      "x": 1,
      "y": 12,
      "z": -1,
      "name": "Rock_Ice"
    },
    {
      "x": 1,
      "y": 13,
      "z": -1,
      "name": "Rock_Ice"
    },
    {
      "x": 1,
      "y": 14,
      "z": -1,
      "name": "Rock_Ice"
    },
    {
      "x": 1,
      "y": 15,
      "z": -1,
      "name": "Rock_Ice"
    },
    {
      "x": 1,
      "y": 3,
      "z": 0,
      "name": "Soil_Dirt_Cold"
    },
    {
      "x": 1,
      "y": 4,
      "z": 0,
      "name": "Empty"
    },
    {
      "x": 1,
      "y": 5,
      "z": 0,
      "name": "Empty"
    },
    {
      "x": 1,
      "y": 6,
      "z": 0,
      "name": "Empty"
    },
    {
      "x": 1,
      "y": 7,
      "z": 0,
      "name": "Empty"
    },
    {
      "x": 1,
      "y": 8,
      "z": 0,
      "name": "Empty"
    },
    {
      "x": 1,
      "y": 9,
      "z": 0,
      "name": "Rock_Ice"
    },
    {
      "x": 1,
      "y": 10,
      "z": 0,
      "name": "Rock_Ice"
    },
    {
      "x": 1,
      "y": 11,
      "z": 0,
      "name": "Rock_Ice"
    },
    {
      "x": 1,
      "y": 12,
      "z": 0,
      "name": "Rock_Ice"
    },
    {
      "x": 1,
      "y": 13,
      "z": 0,
      "name": "Rock_Ice"
    },
    {
      "x": 1,
      "y": 14,
      "z": 0,
      "name": "Rock_Ice"
    },
    {
      "x": 1,
      "y": 15,
      "z": 0,
      "name": "Rock_Ice"
    },
    {
      "x": 1,
      "y": 16,
      "z": 0,
      "name": "Rock_Ice"
    },
    {
      "x": 1,
      "y": 3,
      "z": 1,
      "name": "Soil_Dirt_Cold"
    },
    {
      "x": 1,
      "y": 4,
      "z": 1,
      "name": "Empty"
    },
    {
      "x": 1,
      "y": 5,
      "z": 1,
      "name": "Empty"
    },
    {
      "x": 1,
      "y": 6,
      "z": 1,
      "name": "Empty"
    },
    {
      "x": 1,
      "y": 7,
      "z": 1,
      "name": "Empty"
    },
    {
      "x": 1,
      "y": 8,
      "z": 1,
      "name": "Rock_Ice"
    },
    {
      "x": 1,
      "y": 9,
      "z": 1,
      "name": "Rock_Ice"
    },
    {
      "x": 1,
      "y": 10,
      "z": 1,
      "name": "Rock_Ice"
    },
    {
      "x": 1,
      "y": 11,
      "z": 1,
      "name": "Rock_Ice"
    },
    {
      "x": 1,
      "y": 12,
      "z": 1,
      "name": "Rock_Ice"
    },
    {
      "x": 1,
      "y": 13,
      "z": 1,
      "name": "Rock_Ice"
    },
    {
      "x": 1,
      "y": 14,
      "z": 1,
      "name": "Rock_Ice"
    },
    {
      "x": 1,
      "y": 15,
      "z": 1,
      "name": "Rock_Ice"
    },
    {
      "x": 1,
      "y": 16,
      "z": 1,
      "name": "Rock_Ice"
    },
    {
      "x": 1,
      "y": 3,
      "z": 2,
      "name": "Soil_Dirt_Cold"
    },
    {
      "x": 1,
      "y": 4,
      "z": 2,
      "name": "Empty"
    },
    {
      "x": 1,
      "y": 5,
      "z": 2,
      "name": "Empty"
    },
    {
      "x": 1,
      "y": 6,
      "z": 2,
      "name": "Empty"
    },
    {
      "x": 1,
      "y": 7,
      "z": 2,
      "name": "Empty"
    },
    {
      "x": 1,
      "y": 10,
      "z": 2,
      "name": "Rock_Ice"
    },
    {
      "x": 1,
      "y": 11,
      "z": 2,
      "name": "Rock_Ice"
    },
    {
      "x": 1,
      "y": 12,
      "z": 2,
      "name": "Rock_Ice"
    },
    {
      "x": 1,
      "y": 13,
      "z": 2,
      "name": "Rock_Ice"
    },
    {
      "x": 1,
      "y": 14,
      "z": 2,
      "name": "Rock_Ice"
    },
    {
      "x": 1,
      "y": 15,
      "z": 2,
      "name": "Rock_Ice"
    },
    {
      "x": 1,
      "y": 16,
      "z": 2,
      "name": "Rock_Ice"
    },
    {
      "x": 1,
      "y": 3,
      "z": 3,
      "name": "Soil_Dirt_Cold"
    },
    {
      "x": 1,
      "y": 4,
      "z": 3,
      "name": "Empty"
    },
    {
      "x": 1,
      "y": 5,
      "z": 3,
      "name": "Empty"
    },
    {
      "x": 1,
      "y": 6,
      "z": 3,
      "name": "Empty"
    },
    {
      "x": 1,
      "y": 3,
      "z": 4,
      "name": "Soil_Dirt_Cold"
    },
    {
      "x": 1,
      "y": 4,
      "z": 4,
      "name": "Empty"
    },
    {
      "x": 1,
      "y": 5,
      "z": 4,
      "name": "Empty"
    },
    {
      "x": 1,
      "y": 6,
      "z": 4,
      "name": "Empty"
    },
    {
      "x": 1,
      "y": 3,
      "z": 5,
      "name": "Soil_Dirt_Cold"
    },
    {
      "x": 1,
      "y": 4,
      "z": 5,
      "name": "Empty"
    },
    {
      "x": 1,
      "y": 5,
      "z": 5,
      "name": "Empty"
    },
    {
      "x": 1,
      "y": 6,
      "z": 5,
      "name": "Empty"
    },
    {
      "x": 2,
      "y": 4,
      "z": -4,
      "name": "Empty"
    },
    {
      "x": 2,
      "y": 5,
      "z": -4,
      "name": "Empty"
    },
    {
      "x": 2,
      "y": 6,
      "z": -4,
      "name": "Empty"
    },
    {
      "x": 2,
      "y": 7,
      "z": -4,
      "name": "Empty"
    },
    {
      "x": 2,
      "y": 6,
      "z": -3,
      "name": "Empty"
    },
    {
      "x": 2,
      "y": 7,
      "z": -3,
      "name": "Empty"
    },
    {
      "x": 2,
      "y": 11,
      "z": -3,
      "name": "Rock_Ice"
    },
    {
      "x": 2,
      "y": 12,
      "z": -3,
      "name": "Rock_Ice"
    },
    {
      "x": 2,
      "y": 13,
      "z": -3,
      "name": "Rock_Ice"
    },
    {
      "x": 2,
      "y": 14,
      "z": -3,
      "name": "Rock_Ice"
    },
    {
      "x": 2,
      "y": 10,
      "z": -2,
      "name": "Rock_Ice"
    },
    {
      "x": 2,
      "y": 11,
      "z": -2,
      "name": "Rock_Ice"
    },
    {
      "x": 2,
      "y": 12,
      "z": -2,
      "name": "Rock_Ice"
    },
    {
      "x": 2,
      "y": 13,
      "z": -2,
      "name": "Rock_Ice"
    },
    {
      "x": 2,
      "y": 14,
      "z": -2,
      "name": "Rock_Ice"
    },
    {
      "x": 2,
      "y": 7,
      "z": -1,
      "name": "Empty"
    },
    {
      "x": 2,
      "y": 8,
      "z": -1,
      "name": "Rock_Ice_Icicles",
      "rotation": 8
    },
    {
      "x": 2,
      "y": 9,
      "z": -1,
      "name": "Rock_Ice"
    },
    {
      "x": 2,
      "y": 10,
      "z": -1,
      "name": "Rock_Ice"
    },
    {
      "x": 2,
      "y": 11,
      "z": -1,
      "name": "Rock_Ice"
    },
    {
      "x": 2,
      "y": 12,
      "z": -1,
      "name": "Rock_Ice"
    },
    {
      "x": 2,
      "y": 13,
      "z": -1,
      "name": "Rock_Ice"
    },
    {
      "x": 2,
      "y": 14,
      "z": -1,
      "name": "Rock_Ice"
    },
    {
      "x": 2,
      "y": 15,
      "z": -1,
      "name": "Rock_Ice"
    },
    {
      "x": 2,
      "y": 3,
      "z": 0,
      "name": "Soil_Dirt_Cold"
    },
    {
      "x": 2,
      "y": 4,
      "z": 0,
      "name": "Empty"
    },
    {
      "x": 2,
      "y": 5,
      "z": 0,
      "name": "Empty"
    },
    {
      "x": 2,
      "y": 6,
      "z": 0,
      "name": "Empty"
    },
    {
      "x": 2,
      "y": 7,
      "z": 0,
      "name": "Empty"
    },
    {
      "x": 2,
      "y": 8,
      "z": 0,
      "name": "Empty"
    },
    {
      "x": 2,
      "y": 9,
      "z": 0,
      "name": "Rock_Ice"
    },
    {
      "x": 2,
      "y": 10,
      "z": 0,
      "name": "Rock_Ice"
    },
    {
      "x": 2,
      "y": 11,
      "z": 0,
      "name": "Rock_Ice"
    },
    {
      "x": 2,
      "y": 12,
      "z": 0,
      "name": "Rock_Ice"
    },
    {
      "x": 2,
      "y": 13,
      "z": 0,
      "name": "Rock_Ice"
    },
    {
      "x": 2,
      "y": 14,
      "z": 0,
      "name": "Rock_Ice"
    },
    {
      "x": 2,
      "y": 15,
      "z": 0,
      "name": "Rock_Ice"
    },
    {
      "x": 2,
      "y": 16,
      "z": 0,
      "name": "Rock_Ice"
    },
    {
      "x": 2,
      "y": 3,
      "z": 1,
      "name": "Soil_Dirt_Cold"
    },
    {
      "x": 2,
      "y": 4,
      "z": 1,
      "name": "Empty"
    },
    {
      "x": 2,
      "y": 5,
      "z": 1,
      "name": "Empty"
    },
    {
      "x": 2,
      "y": 6,
      "z": 1,
      "name": "Empty"
    },
    {
      "x": 2,
      "y": 7,
      "z": 1,
      "name": "Empty"
    },
    {
      "x": 2,
      "y": 12,
      "z": 1,
      "name": "Rock_Ice"
    },
    {
      "x": 2,
      "y": 13,
      "z": 1,
      "name": "Rock_Ice"
    },
    {
      "x": 2,
      "y": 14,
      "z": 1,
      "name": "Rock_Ice"
    },
    {
      "x": 2,
      "y": 15,
      "z": 1,
      "name": "Rock_Ice"
    },
    {
      "x": 2,
      "y": 16,
      "z": 1,
      "name": "Rock_Ice"
    },
    {
      "x": 2,
      "y": 3,
      "z": 2,
      "name": "Soil_Dirt_Cold"
    },
    {
      "x": 2,
      "y": 4,
      "z": 2,
      "name": "Empty"
    },
    {
      "x": 2,
      "y": 5,
      "z": 2,
      "name": "Empty"
    },
    {
      "x": 2,
      "y": 6,
      "z": 2,
      "name": "Empty"
    },
    {
      "x": 2,
      "y": 7,
      "z": 2,
      "name": "Empty"
    },
    {
      "x": 2,
      "y": 12,
      "z": 2,
      "name": "Rock_Ice"
    },
    {
      "x": 2,
      "y": 13,
      "z": 2,
      "name": "Rock_Ice"
    },
    {
      "x": 2,
      "y": 14,
      "z": 2,
      "name": "Rock_Ice"
    },
    {
      "x": 2,
      "y": 15,
      "z": 2,
      "name": "Rock_Ice"
    },
    {
      "x": 2,
      "y": 3,
      "z": 3,
      "name": "Soil_Dirt_Cold"
    },
    {
      "x": 2,
      "y": 4,
      "z": 3,
      "name": "Rubble_Shale"
    },
    {
      "x": 2,
      "y": 5,
      "z": 3,
      "name": "Empty"
    },
    {
      "x": 2,
      "y": 6,
      "z": 3,
      "name": "Empty"
    },
    {
      "x": 2,
      "y": 3,
      "z": 4,
      "name": "Soil_Dirt_Cold"
    },
    {
      "x": 2,
      "y": 4,
      "z": 4,
      "name": "Empty"
    },
    {
      "x": 2,
      "y": 5,
      "z": 4,
      "name": "Empty"
    },
    {
      "x": 2,
      "y": 6,
      "z": 4,
      "name": "Empty"
    },
    {
      "x": 2,
      "y": 3,
      "z": 5,
      "name": "Soil_Dirt_Cold"
    },
    {
      "x": 2,
      "y": 4,
      "z": 5,
      "name": "Empty"
    },
    {
      "x": 2,
      "y": 5,
      "z": 5,
      "name": "Empty"
    },
    {
      "x": 2,
      "y": 6,
      "z": 5,
      "name": "Empty"
    },
    {
      "x": 3,
      "y": 12,
      "z": -2,
      "name": "Rock_Ice"
    },
    {
      "x": 3,
      "y": 13,
      "z": -2,
      "name": "Rock_Ice"
    },
    {
      "x": 3,
      "y": 14,
      "z": -2,
      "name": "Rock_Ice"
    },
    {
      "x": 3,
      "y": 10,
      "z": -1,
      "name": "Rock_Ice"
    },
    {
      "x": 3,
      "y": 11,
      "z": -1,
      "name": "Rock_Ice"
    },
    {
      "x": 3,
      "y": 12,
      "z": -1,
      "name": "Rock_Ice"
    },
    {
      "x": 3,
      "y": 13,
      "z": -1,
      "name": "Rock_Ice"
    },
    {
      "x": 3,
      "y": 14,
      "z": -1,
      "name": "Rock_Ice"
    },
    {
      "x": 3,
      "y": 4,
      "z": 0,
      "name": "Rock_Shale_Brick_Beam"
    },
    {
      "x": 3,
      "y": 5,
      "z": 0,
      "name": "Furniture_Human_Ruins_Lantern"
    },
    {
      "x": 3,
      "y": 6,
      "z": 0,
      "name": "Empty"
    },
    {
      "x": 3,
      "y": 7,
      "z": 0,
      "name": "Empty"
    },
    {
      "x": 3,
      "y": 8,
      "z": 0,
      "name": "Rock_Ice_Icicles",
      "rotation": 8
    },
    {
      "x": 3,
      "y": 9,
      "z": 0,
      "name": "Rock_Ice"
    },
    {
      "x": 3,
      "y": 10,
      "z": 0,
      "name": "Rock_Ice"
    },
    {
      "x": 3,
      "y": 11,
      "z": 0,
      "name": "Rock_Ice"
    },
    {
      "x": 3,
      "y": 12,
      "z": 0,
      "name": "Rock_Ice"
    },
    {
      "x": 3,
      "y": 13,
      "z": 0,
      "name": "Rock_Ice"
    },
    {
      "x": 3,
      "y": 14,
      "z": 0,
      "name": "Rock_Ice"
    },
    {
      "x": 3,
      "y": 4,
      "z": 1,
      "name": "Empty"
    },
    {
      "x": 3,
      "y": 5,
      "z": 1,
      "name": "Empty"
    },
    {
      "x": 3,
      "y": 6,
      "z": 1,
      "name": "Empty"
    },
    {
      "x": 3,
      "y": 7,
      "z": 1,
      "name": "Empty"
    },
    {
      "x": 3,
      "y": 5,
      "z": 2,
      "name": "Empty"
    },
    {
      "x": 3,
      "y": 6,
      "z": 2,
      "name": "Empty"
    }
  ],
  "entities": [
    {
      "Components": {
        "Nameplate": {
          "Text": "Outlander"
        },
        "HiddenFromAdventurePlayer": {},
        "SpawnMarkerComponent": {
          "SpawnMarker": "Outlander",
          "RespawnTime": 0.0,
          "SpawnCount": 0
        },
        "Transform": {
          "Position": {
            "X": 1.5374123291015565,
            "Y": 4.5446624755859375,
            "Z": 2.9406291137695177
          },
          "Rotation": {
            "Pitch": 0.0,
            "Yaw": 53.36514663696289,
            "Roll": 0.0
          }
        },
        "Model": {
          "Model": {
            "Id": "NPC_Spawn_Marker",
            "Scale": 1.0
          }
        },
        "UUID": {
          "UUID": {
            "$binary": "zv6ChoaJNtyw+IHKmAGPjw==",
            "$type": "04"
          }
        },
        "HeadRotation": {
          "Rotation": {
            "Pitch": 0.0,
            "Yaw": 50.22355270385742,
            "Roll": 0.0
          }
        }
      }
    }
  ]
}