{
  "version": 8,
  "blockIdVersion": 8,
  "anchorX": 1,
  "anchorY": 15,
  "anchorZ": 0,
  "blocks": [
    {
      "x": -20,
      "y": 3,
      "z": -2,
      "name": "Rock_Shale"
    },
    {
      "x": -20,
      "y": 4,
      "z": -2,
      "name": "Rock_Shale"
    },
    {
      "x": -20,
      "y": 5,
      "z": -2,
      "name": "Rock_Shale"
    },
    {
      "x": -20,
      "y": 6,
      "z": -2,
      "name": "Rock_Shale"
    },
    {
      "x": -20,
      "y": 7,
      "z": -2,
      "name": "Rock_Shale"
    },
    {
      "x": -20,
      "y": 8,
      "z": -2,
      "name": "Rock_Shale"
    },
    {
      "x": -20,
      "y": 9,
      "z": -2,
      "name": "Rock_Shale"
    },
    {
      "x": -20,
      "y": 10,
      "z": -2,
      "name": "Rock_Shale"
    },
    {
      "x": -20,
      "y": 11,
      "z": -2,
      "name": "Rock_Shale"
    },
    {
      "x": -20,
      "y": 12,
      "z": -2,
      "name": "Rock_Shale"
    },
    {
      "x": -20,
      "y": 13,
      "z": -2,
      "name": "Rock_Shale"
    },
    {
      "x": -20,
      "y": 14,
      "z": -2,
      "name": "Rock_Shale_Cobble_Half",
      "rotation": 7
    },
    {
      "x": -20,
      "y": 15,
      "z": -2,
      "name": "Rock_Shale_Cobble_Half",
      "rotation": 7
    },
    {
      "x": -20,
      "y": 16,
      "z": -2,
      "name": "Rock_Shale_Cobble_Half",
      "rotation": 7
    },
    {
      "x": -20,
      "y": 3,
      "z": -1,
      "name": "Rock_Shale"
    },
    {
      "x": -20,
      "y": 4,
      "z": -1,
      "name": "Rock_Shale"
    },
    {
      "x": -20,
      "y": 5,
      "z": -1,
      "name": "Rock_Shale"
    },
    {
      "x": -20,
      "y": 6,
      "z": -1,
      "name": "Rock_Shale"
    },
    {
      "x": -20,
      "y": 7,
      "z": -1,
      "name": "Rock_Shale"
    },
    {
      "x": -20,
      "y": 8,
      "z": -1,
      "name": "Rock_Shale"
    },
    {
      "x": -20,
      "y": 9,
      "z": -1,
      "name": "Rock_Shale"
    },
    {
      "x": -20,
      "y": 10,
      "z": -1,
      "name": "Rock_Shale"
    },
    {
      "x": -20,
      "y": 11,
      "z": -1,
      "name": "Rock_Shale"
    },
    {
      "x": -20,
      "y": 12,
      "z": -1,
      "name": "Rock_Shale"
    },
    {
      "x": -20,
      "y": 13,
      "z": -1,
      "name": "Rock_Shale_Cobble"
    },
    {
      "x": -20,
      "y": 14,
      "z": -1,
      "name": "Rock_Shale_Cobble"
    },
    {
      "x": -20,
      "y": 15,
      "z": -1,
      "name": "Rock_Shale_Cobble"
    },
    {
      "x": -20,
      "y": 16,
      "z": -1,
      "name": "Rock_Shale_Cobble"
    },
    {
      "x": -20,
      "y": 17,
      "z": -1,
      "name": "Rock_Shale_Cobble"
    },
    {
      "x": -20,
      "y": 18,
      "z": -1,
      "name": "Soil_Snow"
    },
    {
      "x": -20,
      "y": 3,
      "z": 0,
      "name": "Rock_Shale"
    },
    {
      "x": -20,
      "y": 4,
      "z": 0,
      "name": "Rock_Shale"
    },
    {
      "x": -20,
      "y": 5,
      "z": 0,
      "name": "Rock_Shale"
    },
    {
      "x": -20,
      "y": 6,
      "z": 0,
      "name": "Rock_Shale"
    },
    {
      "x": -20,
      "y": 7,
      "z": 0,
      "name": "Rock_Shale"
    },
    {
      "x": -20,
      "y": 8,
      "z": 0,
      "name": "Rock_Shale"
    },
    {
      "x": -20,
      "y": 9,
      "z": 0,
      "name": "Rock_Shale"
    },
    {
      "x": -20,
      "y": 10,
      "z": 0,
      "name": "Rock_Shale"
    },
    {
      "x": -20,
      "y": 11,
      "z": 0,
      "name": "Rock_Shale"
    },
    {
      "x": -20,
      "y": 12,
      "z": 0,
      "name": "Rock_Shale"
    },
    {
      "x": -20,
      "y": 13,
      "z": 0,
      "name": "Rock_Shale_Cobble"
    },
    {
      "x": -20,
      "y": 14,
      "z": 0,
      "name": "Rock_Shale_Cobble"
    },
    {
      "x": -20,
      "y": 15,
      "z": 0,
      "name": "Rock_Shale_Cobble"
    },
    {
      "x": -20,
      "y": 16,
      "z": 0,
      "name": "Rock_Shale_Cobble"
    },
    {
      "x": -20,
      "y": 17,
      "z": 0,
      "name": "Rock_Shale_Cobble"
    },
    {
      "x": -20,
      "y": 18,
      "z": 0,
      "name": "Soil_Snow"
    },
    {
      "x": -19,
      "y": 3,
      "z": -2,
      "name": "Rock_Shale"
    },
    {
      "x": -19,
      "y": 4,
      "z": -2,
      "name": "Rock_Shale"
    },
    {
      "x": -19,
      "y": 5,
      "z": -2,
      "name": "Rock_Shale"
    },
    {
      "x": -19,
      "y": 6,
      "z": -2,
      "name": "Rock_Shale"
    },
    {
      "x": -19,
      "y": 7,
      "z": -2,
      "name": "Rock_Shale"
    },
    {
      "x": -19,
      "y": 8,
      "z": -2,
      "name": "Rock_Shale"
    },
    {
      "x": -19,
      "y": 9,
      "z": -2,
      "name": "Rock_Shale"
    },
    {
      "x": -19,
      "y": 10,
      "z": -2,
      "name": "Rock_Shale"
    },
    {
      "x": -19,
      "y": 11,
      "z": -2,
      "name": "Rock_Shale"
    },
    {
      "x": -19,
      "y": 12,
      "z": -2,
      "name": "Rock_Shale"
    },
    {
      "x": -19,
      "y": 13,
      "z": -2,
      "name": "Rock_Shale"
    },
    {
      "x": -19,
      "y": 14,
      "z": -2,
      "name": "Rock_Shale"
    },
    {
      "x": -19,
      "y": 15,
      "z": -2,
      "name": "Rock_Shale_Cobble"
    },
    {
      "x": -19,
      "y": 16,
      "z": -2,
      "name": "Rock_Shale_Cobble"
    },
    {
      "x": -19,
      "y": 3,
      "z": -1,
      "name": "Rock_Shale"
    },
    {
      "x": -19,
      "y": 4,
      "z": -1,
      "name": "Rock_Shale"
    },
    {
      "x": -19,
      "y": 5,
      "z": -1,
      "name": "Rock_Shale"
    },
    {
      "x": -19,
      "y": 6,
      "z": -1,
      "name": "Rock_Shale"
    },
    {
      "x": -19,
      "y": 7,
      "z": -1,
      "name": "Rock_Shale"
    },
    {
      "x": -19,
      "y": 8,
      "z": -1,
      "name": "Rock_Shale"
    },
    {
      "x": -19,
      "y": 9,
      "z": -1,
      "name": "Rock_Shale"
    },
    {
      "x": -19,
      "y": 10,
      "z": -1,
      "name": "Rock_Shale"
    },
    {
      "x": -19,
      "y": 11,
      "z": -1,
      "name": "Rock_Shale"
    },
    {
      "x": -19,
      "y": 12,
      "z": -1,
      "name": "Rock_Shale"
    },
    {
      "x": -19,
      "y": 13,
      "z": -1,
      "name": "Rock_Shale"
    },
    {
      "x": -19,
      "y": 14,
      "z": -1,
      "name": "Rock_Shale_Cobble"
    },
    {
      "x": -19,
      "y": 15,
      "z": -1,
      "name": "Rock_Shale_Cobble"
    },
    {
      "x": -19,
      "y": 16,
      "z": -1,
      "name": "Rock_Shale_Cobble"
    },
    {
      "x": -19,
      "y": 17,
      "z": -1,
      "name": "Rock_Shale_Cobble"
    },
    {
      "x": -19,
      "y": 18,
      "z": -1,
      "name": "Soil_Snow"
    },
    {
      "x": -19,
      "y": 19,
      "z": -1,
      "name": "Soil_Snow"
    },
    {
      "x": -19,
      "y": 20,
      "z": -1,
      "name": "Soil_Snow"
    },
    {
      "x": -19,
      "y": 3,
      "z": 0,
      "name": "Rock_Shale"
    },
    {
      "x": -19,
      "y": 4,
      "z": 0,
      "name": "Rock_Shale"
    },
    {
      "x": -19,
      "y": 5,
      "z": 0,
      "name": "Rock_Shale"
    },
    {
      "x": -19,
      "y": 6,
      "z": 0,
      "name": "Rock_Shale"
    },
    {
      "x": -19,
      "y": 7,
      "z": 0,
      "name": "Rock_Shale"
    },
    {
      "x": -19,
      "y": 8,
      "z": 0,
      "name": "Rock_Shale"
    },
    {
      "x": -19,
      "y": 9,
      "z": 0,
      "name": "Rock_Shale"
    },
    {
      "x": -19,
      "y": 10,
      "z": 0,
      "name": "Rock_Shale"
    },
    {
      "x": -19,
      "y": 11,
      "z": 0,
      "name": "Rock_Shale"
    },
    {
      "x": -19,
      "y": 12,
      "z": 0,
      "name": "Rock_Shale"
    },
    {
      "x": -19,
      "y": 13,
      "z": 0,
      "name": "Rock_Shale_Cobble"
    },
    {
      "x": -19,
      "y": 14,
      "z": 0,
      "name": "Rock_Shale_Cobble"
    },
    {
      "x": -19,
      "y": 15,
      "z": 0,
      "name": "Rock_Shale_Cobble"
    },
    {
      "x": -19,
      "y": 16,
      "z": 0,
      "name": "Rock_Shale_Cobble"
    },
    {
      "x": -19,
      "y": 17,
      "z": 0,
      "name": "Rock_Shale_Cobble"
    },
    {
      "x": -19,
      "y": 18,
      "z": 0,
      "name": "Soil_Snow"
    },
    {
      "x": -19,
      "y": 19,
      "z": 0,
      "name": "Soil_Snow"
    },
    {
      "x": -19,
      "y": 20,
      "z": 0,
      "name": "Soil_Snow"
    },
    {
      "x": -19,
      "y": 3,
      "z": 1,
      "name": "Rock_Shale"
    },
    {
      "x": -19,
      "y": 4,
      "z": 1,
      "name": "Rock_Shale"
    },
    {
      "x": -19,
      "y": 5,
      "z": 1,
      "name": "Rock_Shale"
    },
    {
      "x": -19,
      "y": 6,
      "z": 1,
      "name": "Rock_Shale"
    },
    {
      "x": -19,
      "y": 7,
      "z": 1,
      "name": "Rock_Shale"
    },
    {
      "x": -19,
      "y": 8,
      "z": 1,
      "name": "Rock_Shale"
    },
    {
      "x": -19,
      "y": 9,
      "z": 1,
      "name": "Rock_Shale"
    },
    {
      "x": -19,
      "y": 10,
      "z": 1,
      "name": "Rock_Shale"
    },
    {
      "x": -19,
      "y": 11,
      "z": 1,
      "name": "Rock_Shale"
    },
    {
      "x": -19,
      "y": 12,
      "z": 1,
      "name": "Rock_Shale"
    },
    {
      "x": -19,
      "y": 13,
      "z": 1,
      "name": "Rock_Shale"
    },
    {
      "x": -19,
      "y": 14,
      "z": 1,
      "name": "Rock_Shale_Cobble"
    },
    {
      "x": -19,
      "y": 15,
      "z": 1,
      "name": "Rock_Shale_Cobble"
    },
    {
      "x": -19,
      "y": 16,
      "z": 1,
      "name": "Rock_Shale_Cobble"
    },
    {
      "x": -19,
      "y": 17,
      "z": 1,
      "name": "Rock_Shale_Cobble"
    },
    {
      "x": -19,
      "y": 18,
      "z": 1,
      "name": "Soil_Snow"
    },
    {
      "x": -19,
      "y": 19,
      "z": 1,
      "name": "Soil_Snow"
    },
    {
      "x": -19,
      "y": 20,
      "z": 1,
      "name": "Soil_Snow"
    },
    {
      "x": -18,
      "y": 3,
      "z": -3,
      "name": "Rock_Shale"
    },
    {
      "x": -18,
      "y": 4,
      "z": -3,
      "name": "Rock_Shale"
    },
    {
      "x": -18,
      "y": 5,
      "z": -3,
      "name": "Rock_Shale"
    },
    {
      "x": -18,
      "y": 6,
      "z": -3,
      "name": "Rock_Shale"
    },
    {
      "x": -18,
      "y": 7,
      "z": -3,
      "name": "Rock_Shale"
    },
    {
      "x": -18,
      "y": 8,
      "z": -3,
      "name": "Rock_Shale"
    },
    {
      "x": -18,
      "y": 9,
      "z": -3,
      "name": "Rock_Shale"
    },
    {
      "x": -18,
      "y": 10,
      "z": -3,
      "name": "Rock_Shale"
    },
    {
      "x": -18,
      "y": 11,
      "z": -3,
      "name": "Rock_Shale"
    },
    {
      "x": -18,
      "y": 12,
      "z": -3,
      "name": "Rock_Shale"
    },
    {
      "x": -18,
      "y": 13,
      "z": -3,
      "name": "Rock_Shale"
    },
    {
      "x": -18,
      "y": 14,
      "z": -3,
      "name": "Rock_Shale"
    },
    {
      "x": -18,
      "y": 15,
      "z": -3,
      "name": "Rock_Shale"
    },
    {
      "x": -18,
      "y": 16,
      "z": -3,
      "name": "Soil_Snow"
    },
    {
      "x": -18,
      "y": 17,
      "z": -3,
      "name": "Soil_Snow"
    },
    {
      "x": -18,
      "y": 3,
      "z": -2,
      "name": "Rock_Shale"
    },
    {
      "x": -18,
      "y": 4,
      "z": -2,
      "name": "Rock_Shale"
    },
    {
      "x": -18,
      "y": 5,
      "z": -2,
      "name": "Rock_Shale"
    },
    {
      "x": -18,
      "y": 6,
      "z": -2,
      "name": "Rock_Shale"
    },
    {
      "x": -18,
      "y": 7,
      "z": -2,
      "name": "Rock_Shale"
    },
    {
      "x": -18,
      "y": 8,
      "z": -2,
      "name": "Rock_Shale"
    },
    {
      "x": -18,
      "y": 9,
      "z": -2,
      "name": "Rock_Shale"
    },
    {
      "x": -18,
      "y": 10,
      "z": -2,
      "name": "Rock_Shale"
    },
    {
      "x": -18,
      "y": 11,
      "z": -2,
      "name": "Rock_Shale"
    },
    {
      "x": -18,
      "y": 12,
      "z": -2,
      "name": "Rock_Shale"
    },
    {
      "x": -18,
      "y": 13,
      "z": -2,
      "name": "Rock_Shale"
    },
    {
      "x": -18,
      "y": 14,
      "z": -2,
      "name": "Rock_Shale"
    },
    {
      "x": -18,
      "y": 15,
      "z": -2,
      "name": "Rock_Shale"
    },
    {
      "x": -18,
      "y": 16,
      "z": -2,
      "name": "Rock_Shale_Cobble"
    },
    {
      "x": -18,
      "y": 17,
      "z": -2,
      "name": "Rock_Shale_Cobble"
    },
    {
      "x": -18,
      "y": 18,
      "z": -2,
      "name": "Rock_Shale_Cobble"
    },
    {
      "x": -18,
      "y": 19,
      "z": -2,
      "name": "Soil_Snow"
    },
    {
      "x": -18,
      "y": 3,
      "z": -1,
      "name": "Rock_Shale"
    },
    {
      "x": -18,
      "y": 4,
      "z": -1,
      "name": "Rock_Shale"
    },
    {
      "x": -18,
      "y": 5,
      "z": -1,
      "name": "Rock_Shale"
    },
    {
      "x": -18,
      "y": 6,
      "z": -1,
      "name": "Rock_Shale"
    },
    {
      "x": -18,
      "y": 7,
      "z": -1,
      "name": "Rock_Shale"
    },
    {
      "x": -18,
      "y": 8,
      "z": -1,
      "name": "Rock_Shale"
    },
    {
      "x": -18,
      "y": 9,
      "z": -1,
      "name": "Rock_Shale"
    },
    {
      "x": -18,
      "y": 10,
      "z": -1,
      "name": "Rock_Shale"
    },
    {
      "x": -18,
      "y": 11,
      "z": -1,
      "name": "Rock_Shale"
    },
    {
      "x": -18,
      "y": 12,
      "z": -1,
      "name": "Rock_Shale"
    },
    {
      "x": -18,
      "y": 13,
      "z": -1,
      "name": "Rock_Shale"
    },
    {
      "x": -18,
      "y": 14,
      "z": -1,
      "name": "Rock_Shale"
    },
    {
      "x": -18,
      "y": 15,
      "z": -1,
      "name": "Rock_Shale_Cobble"
    },
    {
      "x": -18,
      "y": 16,
      "z": -1,
      "name": "Rock_Shale"
    },
    {
      "x": -18,
      "y": 17,
      "z": -1,
      "name": "Rock_Shale_Cobble"
    },
    {
      "x": -18,
      "y": 18,
      "z": -1,
      "name": "Rock_Shale_Cobble"
    },
    {
      "x": -18,
      "y": 19,
      "z": -1,
      "name": "Soil_Snow"
    },
    {
      "x": -18,
      "y": 20,
      "z": -1,
      "name": "Soil_Snow"
    },
    {
      "x": -18,
      "y": 3,
      "z": 0,
      "name": "Rock_Shale"
    },
    {
      "x": -18,
      "y": 4,
      "z": 0,
      "name": "Rock_Shale"
    },
    {
      "x": -18,
      "y": 5,
      "z": 0,
      "name": "Rock_Shale"
    },
    {
      "x": -18,
      "y": 6,
      "z": 0,
      "name": "Rock_Shale"
    },
    {
      "x": -18,
      "y": 7,
      "z": 0,
      "name": "Rock_Shale"
    },
    {
      "x": -18,
      "y": 8,
      "z": 0,
      "name": "Rock_Shale"
    },
    {
      "x": -18,
      "y": 9,
      "z": 0,
      "name": "Rock_Shale"
    },
    {
      "x": -18,
      "y": 10,
      "z": 0,
      "name": "Rock_Shale"
    },
    {
      "x": -18,
      "y": 11,
      "z": 0,
      "name": "Rock_Shale"
    },
    {
      "x": -18,
      "y": 12,
      "z": 0,
      "name": "Rock_Shale"
    },
    {
      "x": -18,
      "y": 13,
      "z": 0,
      "name": "Rock_Shale"
    },
    {
      "x": -18,
      "y": 14,
      "z": 0,
      "name": "Rock_Shale_Cobble"
    },
    {
      "x": -18,
      "y": 15,
      "z": 0,
      "name": "Rock_Shale_Cobble"
    },
    {
      "x": -18,
      "y": 16,
      "z": 0,
      "name": "Rock_Shale_Cobble"
    },
    {
      "x": -18,
      "y": 17,
      "z": 0,
      "name": "Rock_Shale_Cobble"
    },
    {
      "x": -18,
      "y": 18,
      "z": 0,
      "name": "Rock_Shale_Cobble"
    },
    {
      "x": -18,
      "y": 19,
      "z": 0,
      "name": "Rock_Shale_Brick"
    },
    {
      "x": -18,
      "y": 20,
      "z": 0,
      "name": "Soil_Snow"
    },
    {
      "x": -18,
      "y": 3,
      "z": 1,
      "name": "Rock_Shale"
    },
    {
      "x": -18,
      "y": 4,
      "z": 1,
      "name": "Rock_Shale"
    },
    {
      "x": -18,
      "y": 5,
      "z": 1,
      "name": "Rock_Shale"
    },
    {
      "x": -18,
      "y": 6,
      "z": 1,
      "name": "Rock_Shale"
    },
    {
      "x": -18,
      "y": 7,
      "z": 1,
      "name": "Rock_Shale"
    },
    {
      "x": -18,
      "y": 8,
      "z": 1,
      "name": "Rock_Shale"
    },
    {
      "x": -18,
      "y": 9,
      "z": 1,
      "name": "Rock_Shale"
    },
    {
      "x": -18,
      "y": 10,
      "z": 1,
      "name": "Rock_Shale"
    },
    {
      "x": -18,
      "y": 11,
      "z": 1,
      "name": "Rock_Shale"
    },
    {
      "x": -18,
      "y": 12,
      "z": 1,
      "name": "Rock_Shale"
    },
    {
      "x": -18,
      "y": 13,
      "z": 1,
      "name": "Rock_Shale"
    },
    {
      "x": -18,
      "y": 14,
      "z": 1,
      "name": "Rock_Shale_Cobble"
    },
    {
      "x": -18,
      "y": 15,
      "z": 1,
      "name": "Rock_Shale_Cobble"
    },
    {
      "x": -18,
      "y": 16,
      "z": 1,
      "name": "Rock_Shale_Cobble"
    },
    {
      "x": -18,
      "y": 17,
      "z": 1,
      "name": "Rock_Shale_Cobble"
    },
    {
      "x": -18,
      "y": 18,
      "z": 1,
      "name": "Rock_Shale_Cobble"
    },
    {
      "x": -18,
      "y": 19,
      "z": 1,
      "name": "Rock_Shale_Brick"
    },
    {
      "x": -18,
      "y": 20,
      "z": 1,
      "name": "Soil_Snow"
    },
    {
      "x": -18,
      "y": 18,
      "z": 2,
      "name": "Rock_Ice_Icicles",
      "rotation": 8
    },
    {
      "x": -18,
      "y": 19,
      "z": 2,
      "name": "Soil_Snow"
    },
    {
      "x": -18,
      "y": 20,
      "z": 2,
      "name": "Soil_Snow"
    },
    {
      "x": -17,
      "y": 3,
      "z": -3,
      "name": "Rock_Shale"
    },
    {
      "x": -17,
      "y": 4,
      "z": -3,
      "name": "Rock_Shale"
    },
    {
      "x": -17,
      "y": 5,
      "z": -3,
      "name": "Rock_Shale"
    },
    {
      "x": -17,
      "y": 6,
      "z": -3,
      "name": "Rock_Shale"
    },
    {
      "x": -17,
      "y": 7,
      "z": -3,
      "name": "Rock_Shale"
    },
    {
      "x": -17,
      "y": 8,
      "z": -3,
      "name": "Rock_Shale"
    },
    {
      "x": -17,
      "y": 9,
      "z": -3,
      "name": "Rock_Shale"
    },
    {
      "x": -17,
      "y": 10,
      "z": -3,
      "name": "Rock_Shale"
    },
    {
      "x": -17,
      "y": 11,
      "z": -3,
      "name": "Rock_Shale"
    },
    {
      "x": -17,
      "y": 12,
      "z": -3,
      "name": "Rock_Shale"
    },
    {
      "x": -17,
      "y": 13,
      "z": -3,
      "name": "Rock_Shale"
    },
    {
      "x": -17,
      "y": 14,
      "z": -3,
      "name": "Rock_Shale"
    },
    {
      "x": -17,
      "y": 15,
      "z": -3,
      "name": "Rock_Shale"
    },
    {
      "x": -17,
      "y": 16,
      "z": -3,
      "name": "Rock_Shale_Cobble"
    },
    {
      "x": -17,
      "y": 17,
      "z": -3,
      "name": "Soil_Snow"
    },
    {
      "x": -17,
      "y": 3,
      "z": -2,
      "name": "Rock_Shale"
    },
    {
      "x": -17,
      "y": 4,
      "z": -2,
      "name": "Rock_Shale"
    },
    {
      "x": -17,
      "y": 5,
      "z": -2,
      "name": "Rock_Shale"
    },
    {
      "x": -17,
      "y": 6,
      "z": -2,
      "name": "Rock_Shale"
    },
    {
      "x": -17,
      "y": 7,
      "z": -2,
      "name": "Rock_Shale"
    },
    {
      "x": -17,
      "y": 8,
      "z": -2,
      "name": "Rock_Shale"
    },
    {
      "x": -17,
      "y": 9,
      "z": -2,
      "name": "Rock_Shale"
    },
    {
      "x": -17,
      "y": 10,
      "z": -2,
      "name": "Rock_Shale"
    },
    {
      "x": -17,
      "y": 11,
      "z": -2,
      "name": "Rock_Shale"
    },
    {
      "x": -17,
      "y": 12,
      "z": -2,
      "name": "Rock_Shale"
    },
    {
      "x": -17,
      "y": 13,
      "z": -2,
      "name": "Rock_Shale"
    },
    {
      "x": -17,
      "y": 14,
      "z": -2,
      "name": "Rock_Shale"
    },
    {
      "x": -17,
      "y": 15,
      "z": -2,
      "name": "Rock_Shale"
    },
    {
      "x": -17,
      "y": 16,
      "z": -2,
      "name": "Rock_Shale_Cobble"
    },
    {
      "x": -17,
      "y": 17,
      "z": -2,
      "name": "Rock_Shale_Cobble"
    },
    {
      "x": -17,
      "y": 18,
      "z": -2,
      "name": "Rock_Shale_Cobble"
    },
    {
      "x": -17,
      "y": 19,
      "z": -2,
      "name": "Soil_Snow"
    },
    {
      "x": -17,
      "y": 20,
      "z": -2,
      "name": "Soil_Snow"
    },
    {
      "x": -17,
      "y": 3,
      "z": -1,
      "name": "Rock_Shale"
    },
    {
      "x": -17,
      "y": 4,
      "z": -1,
      "name": "Rock_Shale"
    },
    {
      "x": -17,
      "y": 5,
      "z": -1,
      "name": "Rock_Shale"
    },
    {
      "x": -17,
      "y": 6,
      "z": -1,
      "name": "Rock_Shale"
    },
    {
      "x": -17,
      "y": 7,
      "z": -1,
      "name": "Rock_Shale"
    },
    {
      "x": -17,
      "y": 8,
      "z": -1,
      "name": "Rock_Shale"
    },
    {
      "x": -17,
      "y": 9,
      "z": -1,
      "name": "Rock_Shale"
    },
    {
      "x": -17,
      "y": 10,
      "z": -1,
      "name": "Rock_Shale"
    },
    {
      "x": -17,
      "y": 11,
      "z": -1,
      "name": "Rock_Shale"
    },
    {
      "x": -17,
      "y": 12,
      "z": -1,
      "name": "Rock_Shale"
    },
    {
      "x": -17,
      "y": 13,
      "z": -1,
      "name": "Rock_Shale"
    },
    {
      "x": -17,
      "y": 14,
      "z": -1,
      "name": "Rock_Shale"
    },
    {
      "x": -17,
      "y": 15,
      "z": -1,
      "name": "Rock_Shale"
    },
    {
      "x": -17,
      "y": 16,
      "z": -1,
      "name": "Rock_Shale"
    },
    {
      "x": -17,
      "y": 17,
      "z": -1,
      "name": "Rock_Shale_Cobble"
    },
    {
      "x": -17,
      "y": 18,
      "z": -1,
      "name": "Rock_Shale_Cobble"
    },
    {
      "x": -17,
      "y": 19,
      "z": -1,
      "name": "Rock_Shale_Cobble"
    },
    {
      "x": -17,
      "y": 20,
      "z": -1,
      "name": "Rock_Shale_Brick"
    },
    {
      "x": -17,
      "y": 21,
      "z": -1,
      "name": "Soil_Snow"
    },
    {
      "x": -17,
      "y": 3,
      "z": 0,
      "name": "Rock_Shale"
    },
    {
      "x": -17,
      "y": 4,
      "z": 0,
      "name": "Rock_Shale"
    },
    {
      "x": -17,
      "y": 5,
      "z": 0,
      "name": "Rock_Shale"
    },
    {
      "x": -17,
      "y": 6,
      "z": 0,
      "name": "Rock_Shale"
    },
    {
      "x": -17,
      "y": 7,
      "z": 0,
      "name": "Rock_Shale"
    },
    {
      "x": -17,
      "y": 8,
      "z": 0,
      "name": "Rock_Shale"
    },
    {
      "x": -17,
      "y": 9,
      "z": 0,
      "name": "Rock_Shale"
    },
    {
      "x": -17,
      "y": 10,
      "z": 0,
      "name": "Rock_Shale"
    },
    {
      "x": -17,
      "y": 11,
      "z": 0,
      "name": "Rock_Shale"
    },
    {
      "x": -17,
      "y": 12,
      "z": 0,
      "name": "Rock_Shale"
    },
    {
      "x": -17,
      "y": 13,
      "z": 0,
      "name": "Rock_Shale"
    },
    {
      "x": -17,
      "y": 14,
      "z": 0,
      "name": "Rock_Shale_Cobble"
    },
    {
      "x": -17,
      "y": 15,
      "z": 0,
      "name": "Rock_Shale_Cobble"
    },
    {
      "x": -17,
      "y": 16,
      "z": 0,
      "name": "Rock_Shale_Cobble"
    },
    {
      "x": -17,
      "y": 17,
      "z": 0,
      "name": "Rock_Shale_Cobble"
    },
    {
      "x": -17,
      "y": 18,
      "z": 0,
      "name": "Rock_Shale"
    },
    {
      "x": -17,
      "y": 19,
      "z": 0,
      "name": "Rock_Shale"
    },
    {
      "x": -17,
      "y": 20,
      "z": 0,
      "name": "Rock_Shale_Brick"
    },
    {
      "x": -17,
      "y": 21,
      "z": 0,
      "name": "Soil_Snow"
    },
    {
      "x": -17,
      "y": 3,
      "z": 1,
      "name": "Rock_Shale"
    },
    {
      "x": -17,
      "y": 4,
      "z": 1,
      "name": "Rock_Shale"
    },
    {
      "x": -17,
      "y": 5,
      "z": 1,
      "name": "Rock_Shale"
    },
    {
      "x": -17,
      "y": 6,
      "z": 1,
      "name": "Rock_Shale"
    },
    {
      "x": -17,
      "y": 7,
      "z": 1,
      "name": "Rock_Shale"
    },
    {
      "x": -17,
      "y": 8,
      "z": 1,
      "name": "Rock_Shale"
    },
    {
      "x": -17,
      "y": 9,
      "z": 1,
      "name": "Rock_Shale"
    },
    {
      "x": -17,
      "y": 10,
      "z": 1,
      "name": "Rock_Shale"
    },
    {
      "x": -17,
      "y": 11,
      "z": 1,
      "name": "Rock_Shale"
    },
    {
      "x": -17,
      "y": 12,
      "z": 1,
      "name": "Rock_Shale"
    },
    {
      "x": -17,
      "y": 13,
      "z": 1,
      "name": "Rock_Shale_Cobble"
    },
    {
      "x": -17,
      "y": 14,
      "z": 1,
      "name": "Rock_Shale_Cobble"
    },
    {
      "x": -17,
      "y": 15,
      "z": 1,
      "name": "Rock_Shale_Cobble"
    },
    {
      "x": -17,
      "y": 16,
      "z": 1,
      "name": "Rock_Shale_Cobble"
    },
    {
      "x": -17,
      "y": 17,
      "z": 1,
      "name": "Rock_Shale_Cobble"
    },
    {
      "x": -17,
      "y": 18,
      "z": 1,
      "name": "Rock_Shale_Cobble"
    },
    {
      "x": -17,
      "y": 19,
      "z": 1,
      "name": "Rock_Shale_Brick"
    },
    {
      "x": -17,
      "y": 20,
      "z": 1,
      "name": "Rock_Shale_Brick"
    },
    {
      "x": -17,
      "y": 21,
      "z": 1,
      "name": "Soil_Snow"
    },
    {
      "x": -17,
      "y": 3,
      "z": 2,
      "name": "Rock_Shale"
    },
    {
      "x": -17,
      "y": 4,
      "z": 2,
      "name": "Rock_Shale"
    },
    {
      "x": -17,
      "y": 5,
      "z": 2,
      "name": "Rock_Shale"
    },
    {
      "x": -17,
      "y": 6,
      "z": 2,
      "name": "Rock_Shale"
    },
    {
      "x": -17,
      "y": 7,
      "z": 2,
      "name": "Rock_Shale"
    },
    {
      "x": -17,
      "y": 8,
      "z": 2,
      "name": "Rock_Shale"
    },
    {
      "x": -17,
      "y": 9,
      "z": 2,
      "name": "Rock_Shale"
    },
    {
      "x": -17,
      "y": 10,
      "z": 2,
      "name": "Rock_Shale"
    },
    {
      "x": -17,
      "y": 11,
      "z": 2,
      "name": "Rock_Shale"
    },
    {
      "x": -17,
      "y": 12,
      "z": 2,
      "name": "Rock_Shale"
    },
    {
      "x": -17,
      "y": 13,
      "z": 2,
      "name": "Rock_Shale_Cobble"
    },
    {
      "x": -17,
      "y": 14,
      "z": 2,
      "name": "Rock_Shale_Cobble"
    },
    {
      "x": -17,
      "y": 15,
      "z": 2,
      "name": "Rock_Shale_Cobble"
    },
    {
      "x": -17,
      "y": 16,
      "z": 2,
      "name": "Rock_Shale_Cobble"
    },
    {
      "x": -17,
      "y": 17,
      "z": 2,
      "name": "Rock_Shale_Cobble"
    },
    {
      "x": -17,
      "y": 18,
      "z": 2,
      "name": "Rock_Shale_Cobble"
    },
    {
      "x": -17,
      "y": 19,
      "z": 2,
      "name": "Rock_Shale_Brick"
    },
    {
      "x": -17,
      "y": 20,
      "z": 2,
      "name": "Soil_Snow"
    },
    {
      "x": -17,
      "y": 21,
      "z": 2,
      "name": "Soil_Snow"
    },
    {
      "x": -16,
      "y": 3,
      "z": -2,
      "name": "Rock_Shale"
    },
    {
      "x": -16,
      "y": 4,
      "z": -2,
      "name": "Rock_Shale"
    },
    {
      "x": -16,
      "y": 5,
      "z": -2,
      "name": "Rock_Shale"
    },
    {
      "x": -16,
      "y": 6,
      "z": -2,
      "name": "Rock_Shale"
    },
    {
      "x": -16,
      "y": 7,
      "z": -2,
      "name": "Rock_Shale"
    },
    {
      "x": -16,
      "y": 8,
      "z": -2,
      "name": "Rock_Shale"
    },
    {
      "x": -16,
      "y": 9,
      "z": -2,
      "name": "Rock_Shale"
    },
    {
      "x": -16,
      "y": 10,
      "z": -2,
      "name": "Rock_Shale"
    },
    {
      "x": -16,
      "y": 11,
      "z": -2,
      "name": "Rock_Shale"
    },
    {
      "x": -16,
      "y": 12,
      "z": -2,
      "name": "Rock_Shale"
    },
    {
      "x": -16,
      "y": 13,
      "z": -2,
      "name": "Rock_Shale"
    },
    {
      "x": -16,
      "y": 14,
      "z": -2,
      "name": "Rock_Shale"
    },
    {
      "x": -16,
      "y": 15,
      "z": -2,
      "name": "Rock_Shale"
    },
    {
      "x": -16,
      "y": 16,
      "z": -2,
      "name": "Rock_Shale"
    },
    {
      "x": -16,
      "y": 17,
      "z": -2,
      "name": "Rock_Shale_Cobble"
    },
    {
      "x": -16,
      "y": 18,
      "z": -2,
      "name": "Rock_Shale_Cobble"
    },
    {
      "x": -16,
      "y": 19,
      "z": -2,
      "name": "Rock_Shale_Cobble"
    },
    {
      "x": -16,
      "y": 20,
      "z": -2,
      "name": "Soil_Snow"
    },
    {
      "x": -16,
      "y": 21,
      "z": -2,
      "name": "Soil_Snow"
    },
    {
      "x": -16,
      "y": 3,
      "z": -1,
      "name": "Rock_Shale"
    },
    {
      "x": -16,
      "y": 4,
      "z": -1,
      "name": "Rock_Shale"
    },
    {
      "x": -16,
      "y": 5,
      "z": -1,
      "name": "Rock_Shale"
    },
    {
      "x": -16,
      "y": 6,
      "z": -1,
      "name": "Rock_Shale"
    },
    {
      "x": -16,
      "y": 7,
      "z": -1,
      "name": "Rock_Shale"
    },
    {
      "x": -16,
      "y": 8,
      "z": -1,
      "name": "Rock_Shale"
    },
    {
      "x": -16,
      "y": 9,
      "z": -1,
      "name": "Rock_Shale"
    },
    {
      "x": -16,
      "y": 10,
      "z": -1,
      "name": "Rock_Shale"
    },
    {
      "x": -16,
      "y": 11,
      "z": -1,
      "name": "Rock_Shale"
    },
    {
      "x": -16,
      "y": 12,
      "z": -1,
      "name": "Rock_Shale"
    },
    {
      "x": -16,
      "y": 13,
      "z": -1,
      "name": "Rock_Shale"
    },
    {
      "x": -16,
      "y": 14,
      "z": -1,
      "name": "Rock_Shale"
    },
    {
      "x": -16,
      "y": 15,
      "z": -1,
      "name": "Rock_Shale"
    },
    {
      "x": -16,
      "y": 16,
      "z": -1,
      "name": "Rock_Shale"
    },
    {
      "x": -16,
      "y": 17,
      "z": -1,
      "name": "Rock_Shale"
    },
    {
      "x": -16,
      "y": 18,
      "z": -1,
      "name": "Rock_Shale_Cobble"
    },
    {
      "x": -16,
      "y": 19,
      "z": -1,
      "name": "Rock_Shale"
    },
    {
      "x": -16,
      "y": 20,
      "z": -1,
      "name": "Rock_Shale_Brick"
    },
    {
      "x": -16,
      "y": 21,
      "z": -1,
      "name": "Soil_Snow"
    },
    {
      "x": -16,
      "y": 3,
      "z": 0,
      "name": "Rock_Shale"
    },
    {
      "x": -16,
      "y": 4,
      "z": 0,
      "name": "Rock_Shale"
    },
    {
      "x": -16,
      "y": 5,
      "z": 0,
      "name": "Rock_Shale"
    },
    {
      "x": -16,
      "y": 6,
      "z": 0,
      "name": "Rock_Shale"
    },
    {
      "x": -16,
      "y": 7,
      "z": 0,
      "name": "Rock_Shale"
    },
    {
      "x": -16,
      "y": 8,
      "z": 0,
      "name": "Rock_Shale"
    },
    {
      "x": -16,
      "y": 9,
      "z": 0,
      "name": "Rock_Shale"
    },
    {
      "x": -16,
      "y": 10,
      "z": 0,
      "name": "Rock_Shale"
    },
    {
      "x": -16,
      "y": 11,
      "z": 0,
      "name": "Rock_Shale"
    },
    {
      "x": -16,
      "y": 12,
      "z": 0,
      "name": "Rock_Shale"
    },
    {
      "x": -16,
      "y": 13,
      "z": 0,
      "name": "Rock_Shale"
    },
    {
      "x": -16,
      "y": 14,
      "z": 0,
      "name": "Rock_Shale"
    },
    {
      "x": -16,
      "y": 15,
      "z": 0,
      "name": "Rock_Shale_Cobble"
    },
    {
      "x": -16,
      "y": 16,
      "z": 0,
      "name": "Rock_Shale_Cobble"
    },
    {
      "x": -16,
      "y": 17,
      "z": 0,
      "name": "Rock_Shale_Cobble"
    },
    {
      "x": -16,
      "y": 18,
      "z": 0,
      "name": "Rock_Shale_Cobble"
    },
    {
      "x": -16,
      "y": 19,
      "z": 0,
      "name": "Rock_Shale"
    },
    {
      "x": -16,
      "y": 20,
      "z": 0,
      "name": "Rock_Shale_Brick"
    },
    {
      "x": -16,
      "y": 21,
      "z": 0,
      "name": "Rock_Shale_Brick"
    },
    {
      "x": -16,
      "y": 22,
      "z": 0,
      "name": "Soil_Snow"
    },
    {
      "x": -16,
      "y": 3,
      "z": 1,
      "name": "Rock_Shale"
    },
    {
      "x": -16,
      "y": 4,
      "z": 1,
      "name": "Rock_Shale"
    },
    {
      "x": -16,
      "y": 5,
      "z": 1,
      "name": "Rock_Shale"
    },
    {
      "x": -16,
      "y": 6,
      "z": 1,
      "name": "Rock_Shale"
    },
    {
      "x": -16,
      "y": 7,
      "z": 1,
      "name": "Rock_Shale"
    },
    {
      "x": -16,
      "y": 8,
      "z": 1,
      "name": "Rock_Shale"
    },
    {
      "x": -16,
      "y": 9,
      "z": 1,
      "name": "Rock_Shale"
    },
    {
      "x": -16,
      "y": 10,
      "z": 1,
      "name": "Rock_Shale"
    },
    {
      "x": -16,
      "y": 11,
      "z": 1,
      "name": "Rock_Shale"
    },
    {
      "x": -16,
      "y": 12,
      "z": 1,
      "name": "Rock_Shale"
    },
    {
      "x": -16,
      "y": 13,
      "z": 1,
      "name": "Rock_Shale"
    },
    {
      "x": -16,
      "y": 14,
      "z": 1,
      "name": "Rock_Shale_Cobble"
    },
    {
      "x": -16,
      "y": 15,
      "z": 1,
      "name": "Rock_Shale_Cobble"
    },
    {
      "x": -16,
      "y": 16,
      "z": 1,
      "name": "Rock_Shale_Cobble"
    },
    {
      "x": -16,
      "y": 17,
      "z": 1,
      "name": "Rock_Shale_Cobble"
    },
    {
      "x": -16,
      "y": 18,
      "z": 1,
      "name": "Rock_Shale_Cobble"
    },
    {
      "x": -16,
      "y": 19,
      "z": 1,
      "name": "Rock_Shale_Brick"
    },
    {
      "x": -16,
      "y": 20,
      "z": 1,
      "name": "Rock_Shale_Brick"
    },
    {
      "x": -16,
      "y": 21,
      "z": 1,
      "name": "Rock_Shale_Brick"
    },
    {
      "x": -16,
      "y": 22,
      "z": 1,
      "name": "Soil_Snow"
    },
    {
      "x": -16,
      "y": 3,
      "z": 2,
      "name": "Rock_Shale"
    },
    {
      "x": -16,
      "y": 4,
      "z": 2,
      "name": "Rock_Shale"
    },
    {
      "x": -16,
      "y": 5,
      "z": 2,
      "name": "Rock_Shale"
    },
    {
      "x": -16,
      "y": 6,
      "z": 2,
      "name": "Rock_Shale"
    },
    {
      "x": -16,
      "y": 7,
      "z": 2,
      "name": "Rock_Shale"
    },
    {
      "x": -16,
      "y": 8,
      "z": 2,
      "name": "Rock_Shale"
    },
    {
      "x": -16,
      "y": 9,
      "z": 2,
      "name": "Rock_Shale"
    },
    {
      "x": -16,
      "y": 10,
      "z": 2,
      "name": "Rock_Shale"
    },
    {
      "x": -16,
      "y": 11,
      "z": 2,
      "name": "Rock_Shale"
    },
    {
      "x": -16,
      "y": 12,
      "z": 2,
      "name": "Rock_Shale"
    },
    {
      "x": -16,
      "y": 13,
      "z": 2,
      "name": "Rock_Shale_Cobble"
    },
    {
      "x": -16,
      "y": 14,
      "z": 2,
      "name": "Rock_Shale_Cobble"
    },
    {
      "x": -16,
      "y": 15,
      "z": 2,
      "name": "Rock_Shale_Cobble"
    },
    {
      "x": -16,
      "y": 16,
      "z": 2,
      "name": "Rock_Shale_Cobble"
    },
    {
      "x": -16,
      "y": 17,
      "z": 2,
      "name": "Rock_Shale_Cobble"
    },
    {
      "x": -16,
      "y": 18,
      "z": 2,
      "name": "Rock_Shale_Cobble"
    },
    {
      "x": -16,
      "y": 19,
      "z": 2,
      "name": "Rock_Shale_Brick"
    },
    {
      "x": -16,
      "y": 20,
      "z": 2,
      "name": "Rock_Shale_Brick"
    },
    {
      "x": -16,
      "y": 21,
      "z": 2,
      "name": "Soil_Snow"
    },
    {
      "x": -16,
      "y": 22,
      "z": 2,
      "name": "Soil_Snow"
    },
    {
      "x": -15,
      "y": 3,
      "z": -2,
      "name": "Rock_Shale"
    },
    {
      "x": -15,
      "y": 4,
      "z": -2,
      "name": "Rock_Shale"
    },
    {
      "x": -15,
      "y": 5,
      "z": -2,
      "name": "Rock_Shale"
    },
    {
      "x": -15,
      "y": 6,
      "z": -2,
      "name": "Rock_Shale"
    },
    {
      "x": -15,
      "y": 7,
      "z": -2,
      "name": "Rock_Shale"
    },
    {
      "x": -15,
      "y": 8,
      "z": -2,
      "name": "Rock_Shale"
    },
    {
      "x": -15,
      "y": 9,
      "z": -2,
      "name": "Rock_Shale"
    },
    {
      "x": -15,
      "y": 10,
      "z": -2,
      "name": "Rock_Shale"
    },
    {
      "x": -15,
      "y": 11,
      "z": -2,
      "name": "Rock_Shale"
    },
    {
      "x": -15,
      "y": 12,
      "z": -2,
      "name": "Rock_Shale"
    },
    {
      "x": -15,
      "y": 13,
      "z": -2,
      "name": "Rock_Shale"
    },
    {
      "x": -15,
      "y": 14,
      "z": -2,
      "name": "Rock_Shale"
    },
    {
      "x": -15,
      "y": 15,
      "z": -2,
      "name": "Rock_Shale"
    },
    {
      "x": -15,
      "y": 16,
      "z": -2,
      "name": "Rock_Shale_Cobble"
    },
    {
      "x": -15,
      "y": 17,
      "z": -2,
      "name": "Rock_Shale_Cobble"
    },
    {
      "x": -15,
      "y": 18,
      "z": -2,
      "name": "Rock_Shale_Cobble"
    },
    {
      "x": -15,
      "y": 19,
      "z": -2,
      "name": "Rock_Shale_Brick"
    },
    {
      "x": -15,
      "y": 20,
      "z": -2,
      "name": "Rock_Shale_Brick"
    },
    {
      "x": -15,
      "y": 21,
      "z": -2,
      "name": "Soil_Snow"
    },
    {
      "x": -15,
      "y": 3,
      "z": -1,
      "name": "Rock_Shale"
    },
    {
      "x": -15,
      "y": 4,
      "z": -1,
      "name": "Rock_Shale"
    },
    {
      "x": -15,
      "y": 5,
      "z": -1,
      "name": "Rock_Shale"
    },
    {
      "x": -15,
      "y": 6,
      "z": -1,
      "name": "Rock_Shale"
    },
    {
      "x": -15,
      "y": 7,
      "z": -1,
      "name": "Rock_Shale"
    },
    {
      "x": -15,
      "y": 8,
      "z": -1,
      "name": "Rock_Shale"
    },
    {
      "x": -15,
      "y": 9,
      "z": -1,
      "name": "Rock_Shale"
    },
    {
      "x": -15,
      "y": 10,
      "z": -1,
      "name": "Rock_Shale"
    },
    {
      "x": -15,
      "y": 11,
      "z": -1,
      "name": "Rock_Shale"
    },
    {
      "x": -15,
      "y": 12,
      "z": -1,
      "name": "Rock_Shale"
    },
    {
      "x": -15,
      "y": 13,
      "z": -1,
      "name": "Rock_Shale"
    },
    {
      "x": -15,
      "y": 14,
      "z": -1,
      "name": "Rock_Shale"
    },
    {
      "x": -15,
      "y": 15,
      "z": -1,
      "name": "Rock_Shale"
    },
    {
      "x": -15,
      "y": 16,
      "z": -1,
      "name": "Rock_Shale"
    },
    {
      "x": -15,
      "y": 17,
      "z": -1,
      "name": "Rock_Shale_Cobble"
    },
    {
      "x": -15,
      "y": 18,
      "z": -1,
      "name": "Rock_Shale_Cobble"
    },
    {
      "x": -15,
      "y": 19,
      "z": -1,
      "name": "Rock_Shale_Cobble"
    },
    {
      "x": -15,
      "y": 20,
      "z": -1,
      "name": "Rock_Shale_Brick"
    },
    {
      "x": -15,
      "y": 21,
      "z": -1,
      "name": "Rock_Shale_Brick"
    },
    {
      "x": -15,
      "y": 22,
      "z": -1,
      "name": "Soil_Snow"
    },
    {
      "x": -15,
      "y": 3,
      "z": 0,
      "name": "Rock_Shale"
    },
    {
      "x": -15,
      "y": 4,
      "z": 0,
      "name": "Rock_Shale"
    },
    {
      "x": -15,
      "y": 5,
      "z": 0,
      "name": "Rock_Shale"
    },
    {
      "x": -15,
      "y": 6,
      "z": 0,
      "name": "Rock_Shale"
    },
    {
      "x": -15,
      "y": 7,
      "z": 0,
      "name": "Rock_Shale"
    },
    {
      "x": -15,
      "y": 8,
      "z": 0,
      "name": "Rock_Shale"
    },
    {
      "x": -15,
      "y": 9,
      "z": 0,
      "name": "Rock_Shale"
    },
    {
      "x": -15,
      "y": 10,
      "z": 0,
      "name": "Rock_Shale"
    },
    {
      "x": -15,
      "y": 11,
      "z": 0,
      "name": "Rock_Shale"
    },
    {
      "x": -15,
      "y": 12,
      "z": 0,
      "name": "Rock_Shale"
    },
    {
      "x": -15,
      "y": 13,
      "z": 0,
      "name": "Rock_Shale"
    },
    {
      "x": -15,
      "y": 14,
      "z": 0,
      "name": "Rock_Shale"
    },
    {
      "x": -15,
      "y": 15,
      "z": 0,
      "name": "Rock_Shale"
    },
    {
      "x": -15,
      "y": 16,
      "z": 0,
      "name": "Rock_Shale"
    },
    {
      "x": -15,
      "y": 17,
      "z": 0,
      "name": "Rock_Shale_Cobble"
    },
    {
      "x": -15,
      "y": 18,
      "z": 0,
      "name": "Rock_Shale_Cobble"
    },
    {
      "x": -15,
      "y": 19,
      "z": 0,
      "name": "Rock_Shale"
    },
    {
      "x": -15,
      "y": 20,
      "z": 0,
      "name": "Rock_Shale"
    },
    {
      "x": -15,
      "y": 21,
      "z": 0,
      "name": "Rock_Shale_Brick"
    },
    {
      "x": -15,
      "y": 22,
      "z": 0,
      "name": "Soil_Snow"
    },
    {
      "x": -15,
      "y": 3,
      "z": 1,
      "name": "Rock_Shale"
    },
    {
      "x": -15,
      "y": 4,
      "z": 1,
      "name": "Rock_Shale"
    },
    {
      "x": -15,
      "y": 5,
      "z": 1,
      "name": "Rock_Shale"
    },
    {
      "x": -15,
      "y": 6,
      "z": 1,
      "name": "Rock_Shale"
    },
    {
      "x": -15,
      "y": 7,
      "z": 1,
      "name": "Rock_Shale"
    },
    {
      "x": -15,
      "y": 8,
      "z": 1,
      "name": "Rock_Shale"
    },
    {
      "x": -15,
      "y": 9,
      "z": 1,
      "name": "Rock_Shale"
    },
    {
      "x": -15,
      "y": 10,
      "z": 1,
      "name": "Rock_Shale"
    },
    {
      "x": -15,
      "y": 11,
      "z": 1,
      "name": "Rock_Shale"
    },
    {
      "x": -15,
      "y": 12,
      "z": 1,
      "name": "Rock_Shale"
    },
    {
      "x": -15,
      "y": 13,
      "z": 1,
      "name": "Rock_Shale"
    },
    {
      "x": -15,
      "y": 14,
      "z": 1,
      "name": "Rock_Shale"
    },
    {
      "x": -15,
      "y": 15,
      "z": 1,
      "name": "Rock_Shale_Cobble"
    },
    {
      "x": -15,
      "y": 16,
      "z": 1,
      "name": "Rock_Shale_Cobble"
    },
    {
      "x": -15,
      "y": 17,
      "z": 1,
      "name": "Rock_Shale_Cobble"
    },
    {
      "x": -15,
      "y": 18,
      "z": 1,
      "name": "Rock_Shale_Cobble"
    },
    {
      "x": -15,
      "y": 19,
      "z": 1,
      "name": "Rock_Shale"
    },
    {
      "x": -15,
      "y": 20,
      "z": 1,
      "name": "Rock_Shale_Brick"
    },
    {
      "x": -15,
      "y": 21,
      "z": 1,
      "name": "Rock_Shale_Brick"
    },
    {
      "x": -15,
      "y": 22,
      "z": 1,
      "name": "Soil_Snow"
    },
    {
      "x": -15,
      "y": 3,
      "z": 2,
      "name": "Rock_Shale"
    },
    {
      "x": -15,
      "y": 4,
      "z": 2,
      "name": "Rock_Shale"
    },
    {
      "x": -15,
      "y": 5,
      "z": 2,
      "name": "Rock_Shale"
    },
    {
      "x": -15,
      "y": 6,
      "z": 2,
      "name": "Rock_Shale"
    },
    {
      "x": -15,
      "y": 7,
      "z": 2,
      "name": "Rock_Shale"
    },
    {
      "x": -15,
      "y": 8,
      "z": 2,
      "name": "Rock_Shale"
    },
    {
      "x": -15,
      "y": 9,
      "z": 2,
      "name": "Rock_Shale"
    },
    {
      "x": -15,
      "y": 10,
      "z": 2,
      "name": "Rock_Shale"
    },
    {
      "x": -15,
      "y": 11,
      "z": 2,
      "name": "Rock_Shale"
    },
    {
      "x": -15,
      "y": 12,
      "z": 2,
      "name": "Rock_Shale"
    },
    {
      "x": -15,
      "y": 13,
      "z": 2,
      "name": "Rock_Shale"
    },
    {
      "x": -15,
      "y": 14,
      "z": 2,
      "name": "Rock_Shale_Cobble"
    },
    {
      "x": -15,
      "y": 15,
      "z": 2,
      "name": "Rock_Shale_Cobble"
    },
    {
      "x": -15,
      "y": 16,
      "z": 2,
      "name": "Rock_Shale_Cobble"
    },
    {
      "x": -15,
      "y": 17,
      "z": 2,
      "name": "Rock_Shale_Cobble"
    },
    {
      "x": -15,
      "y": 18,
      "z": 2,
      "name": "Rock_Shale_Cobble"
    },
    {
      "x": -15,
      "y": 19,
      "z": 2,
      "name": "Rock_Shale_Brick"
    },
    {
      "x": -15,
      "y": 20,
      "z": 2,
      "name": "Rock_Shale_Brick"
    },
    {
      "x": -15,
      "y": 21,
      "z": 2,
      "name": "Rock_Shale_Brick"
    },
    {
      "x": -15,
      "y": 22,
      "z": 2,
      "name": "Soil_Snow"
    },
    {
      "x": -15,
      "y": 20,
      "z": 3,
      "name": "Rock_Ice_Icicles",
      "rotation": 8
    },
    {
      "x": -15,
      "y": 21,
      "z": 3,
      "name": "Soil_Snow"
    },
    {
      "x": -15,
      "y": 22,
      "z": 3,
      "name": "Soil_Snow"
    },
    {
      "x": -14,
      "y": 3,
      "z": -2,
      "name": "Rock_Shale"
    },
    {
      "x": -14,
      "y": 4,
      "z": -2,
      "name": "Rock_Shale"
    },
    {
      "x": -14,
      "y": 5,
      "z": -2,
      "name": "Rock_Shale"
    },
    {
      "x": -14,
      "y": 6,
      "z": -2,
      "name": "Rock_Shale"
    },
    {
      "x": -14,
      "y": 7,
      "z": -2,
      "name": "Rock_Shale"
    },
    {
      "x": -14,
      "y": 8,
      "z": -2,
      "name": "Rock_Shale"
    },
    {
      "x": -14,
      "y": 9,
      "z": -2,
      "name": "Rock_Shale"
    },
    {
      "x": -14,
      "y": 10,
      "z": -2,
      "name": "Rock_Shale"
    },
    {
      "x": -14,
      "y": 11,
      "z": -2,
      "name": "Rock_Shale"
    },
    {
      "x": -14,
      "y": 12,
      "z": -2,
      "name": "Rock_Shale"
    },
    {
      "x": -14,
      "y": 13,
      "z": -2,
      "name": "Rock_Shale"
    },
    {
      "x": -14,
      "y": 14,
      "z": -2,
      "name": "Rock_Shale"
    },
    {
      "x": -14,
      "y": 15,
      "z": -2,
      "name": "Rock_Shale"
    },
    {
      "x": -14,
      "y": 16,
      "z": -2,
      "name": "Rock_Shale_Cobble"
    },
    {
      "x": -14,
      "y": 17,
      "z": -2,
      "name": "Rock_Shale_Cobble"
    },
    {
      "x": -14,
      "y": 18,
      "z": -2,
      "name": "Rock_Shale_Cobble"
    },
    {
      "x": -14,
      "y": 19,
      "z": -2,
      "name": "Rock_Shale_Brick"
    },
    {
      "x": -14,
      "y": 20,
      "z": -2,
      "name": "Soil_Snow"
    },
    {
      "x": -14,
      "y": 21,
      "z": -2,
      "name": "Soil_Snow"
    },
    {
      "x": -14,
      "y": 3,
      "z": -1,
      "name": "Rock_Shale"
    },
    {
      "x": -14,
      "y": 4,
      "z": -1,
      "name": "Rock_Shale"
    },
    {
      "x": -14,
      "y": 5,
      "z": -1,
      "name": "Rock_Shale"
    },
    {
      "x": -14,
      "y": 6,
      "z": -1,
      "name": "Rock_Shale"
    },
    {
      "x": -14,
      "y": 7,
      "z": -1,
      "name": "Rock_Shale"
    },
    {
      "x": -14,
      "y": 8,
      "z": -1,
      "name": "Rock_Shale"
    },
    {
      "x": -14,
      "y": 9,
      "z": -1,
      "name": "Rock_Shale"
    },
    {
      "x": -14,
      "y": 10,
      "z": -1,
      "name": "Rock_Shale"
    },
    {
      "x": -14,
      "y": 11,
      "z": -1,
      "name": "Rock_Shale"
    },
    {
      "x": -14,
      "y": 12,
      "z": -1,
      "name": "Rock_Shale"
    },
    {
      "x": -14,
      "y": 13,
      "z": -1,
      "name": "Rock_Shale"
    },
    {
      "x": -14,
      "y": 14,
      "z": -1,
      "name": "Rock_Shale"
    },
    {
      "x": -14,
      "y": 15,
      "z": -1,
      "name": "Rock_Shale"
    },
    {
      "x": -14,
      "y": 16,
      "z": -1,
      "name": "Rock_Shale_Cobble"
    },
    {
      "x": -14,
      "y": 17,
      "z": -1,
      "name": "Rock_Shale_Cobble"
    },
    {
      "x": -14,
      "y": 18,
      "z": -1,
      "name": "Rock_Shale_Cobble"
    },
    {
      "x": -14,
      "y": 19,
      "z": -1,
      "name": "Rock_Shale_Brick"
    },
    {
      "x": -14,
      "y": 20,
      "z": -1,
      "name": "Rock_Shale_Brick"
    },
    {
      "x": -14,
      "y": 21,
      "z": -1,
      "name": "Rock_Shale_Brick"
    },
    {
      "x": -14,
      "y": 22,
      "z": -1,
      "name": "Soil_Snow"
    },
    {
      "x": -14,
      "y": 3,
      "z": 0,
      "name": "Rock_Shale"
    },
    {
      "x": -14,
      "y": 4,
      "z": 0,
      "name": "Rock_Shale"
    },
    {
      "x": -14,
      "y": 5,
      "z": 0,
      "name": "Rock_Shale"
    },
    {
      "x": -14,
      "y": 6,
      "z": 0,
      "name": "Rock_Shale"
    },
    {
      "x": -14,
      "y": 7,
      "z": 0,
      "name": "Rock_Shale"
    },
    {
      "x": -14,
      "y": 8,
      "z": 0,
      "name": "Rock_Shale"
    },
    {
      "x": -14,
      "y": 9,
      "z": 0,
      "name": "Rock_Shale"
    },
    {
      "x": -14,
      "y": 10,
      "z": 0,
      "name": "Rock_Shale"
    },
    {
      "x": -14,
      "y": 11,
      "z": 0,
      "name": "Rock_Shale"
    },
    {
      "x": -14,
      "y": 12,
      "z": 0,
      "name": "Rock_Shale"
    },
    {
      "x": -14,
      "y": 13,
      "z": 0,
      "name": "Rock_Shale"
    },
    {
      "x": -14,
      "y": 14,
      "z": 0,
      "name": "Rock_Shale"
    },
    {
      "x": -14,
      "y": 15,
      "z": 0,
      "name": "Rock_Shale"
    },
    {
      "x": -14,
      "y": 16,
      "z": 0,
      "name": "Rock_Shale"
    },
    {
      "x": -14,
      "y": 17,
      "z": 0,
      "name": "Rock_Shale_Cobble"
    },
    {
      "x": -14,
      "y": 18,
      "z": 0,
      "name": "Rock_Shale_Cobble"
    },
    {
      "x": -14,
      "y": 19,
      "z": 0,
      "name": "Rock_Shale_Cobble"
    },
    {
      "x": -14,
      "y": 20,
      "z": 0,
      "name": "Rock_Shale_Brick"
    },
    {
      "x": -14,
      "y": 21,
      "z": 0,
      "name": "Rock_Shale_Brick"
    },
    {
      "x": -14,
      "y": 22,
      "z": 0,
      "name": "Soil_Snow"
    },
    {
      "x": -14,
      "y": 3,
      "z": 1,
      "name": "Rock_Shale"
    },
    {
      "x": -14,
      "y": 4,
      "z": 1,
      "name": "Rock_Shale"
    },
    {
      "x": -14,
      "y": 5,
      "z": 1,
      "name": "Rock_Shale"
    },
    {
      "x": -14,
      "y": 6,
      "z": 1,
      "name": "Rock_Shale"
    },
    {
      "x": -14,
      "y": 7,
      "z": 1,
      "name": "Rock_Shale"
    },
    {
      "x": -14,
      "y": 8,
      "z": 1,
      "name": "Rock_Shale"
    },
    {
      "x": -14,
      "y": 9,
      "z": 1,
      "name": "Rock_Shale"
    },
    {
      "x": -14,
      "y": 10,
      "z": 1,
      "name": "Rock_Shale"
    },
    {
      "x": -14,
      "y": 11,
      "z": 1,
      "name": "Rock_Shale"
    },
    {
      "x": -14,
      "y": 12,
      "z": 1,
      "name": "Rock_Shale"
    },
    {
      "x": -14,
      "y": 13,
      "z": 1,
      "name": "Rock_Shale"
    },
    {
      "x": -14,
      "y": 14,
      "z": 1,
      "name": "Rock_Shale"
    },
    {
      "x": -14,
      "y": 15,
      "z": 1,
      "name": "Rock_Shale_Cobble"
    },
    {
      "x": -14,
      "y": 16,
      "z": 1,
      "name": "Rock_Shale_Cobble"
    },
    {
      "x": -14,
      "y": 17,
      "z": 1,
      "name": "Rock_Shale_Cobble"
    },
    {
      "x": -14,
      "y": 18,
      "z": 1,
      "name": "Rock_Shale"
    },
    {
      "x": -14,
      "y": 19,
      "z": 1,
      "name": "Rock_Shale"
    },
    {
      "x": -14,
      "y": 20,
      "z": 1,
      "name": "Rock_Shale"
    },
    {
      "x": -14,
      "y": 21,
      "z": 1,
      "name": "Rock_Shale_Brick"
    },
    {
      "x": -14,
      "y": 22,
      "z": 1,
      "name": "Soil_Snow"
    },
    {
      "x": -14,
      "y": 3,
      "z": 2,
      "name": "Rock_Shale"
    },
    {
      "x": -14,
      "y": 4,
      "z": 2,
      "name": "Rock_Shale"
    },
    {
      "x": -14,
      "y": 5,
      "z": 2,
      "name": "Rock_Shale"
    },
    {
      "x": -14,
      "y": 6,
      "z": 2,
      "name": "Rock_Shale"
    },
    {
      "x": -14,
      "y": 7,
      "z": 2,
      "name": "Rock_Shale"
    },
    {
      "x": -14,
      "y": 8,
      "z": 2,
      "name": "Rock_Shale"
    },
    {
      "x": -14,
      "y": 9,
      "z": 2,
      "name": "Rock_Shale"
    },
    {
      "x": -14,
      "y": 10,
      "z": 2,
      "name": "Rock_Shale"
    },
    {
      "x": -14,
      "y": 11,
      "z": 2,
      "name": "Rock_Shale"
    },
    {
      "x": -14,
      "y": 12,
      "z": 2,
      "name": "Rock_Shale"
    },
    {
      "x": -14,
      "y": 13,
      "z": 2,
      "name": "Rock_Shale"
    },
    {
      "x": -14,
      "y": 14,
      "z": 2,
      "name": "Rock_Shale_Cobble"
    },
    {
      "x": -14,
      "y": 15,
      "z": 2,
      "name": "Rock_Shale_Cobble"
    },
    {
      "x": -14,
      "y": 16,
      "z": 2,
      "name": "Rock_Shale_Cobble"
    },
    {
      "x": -14,
      "y": 17,
      "z": 2,
      "name": "Rock_Shale_Cobble"
    },
    {
      "x": -14,
      "y": 18,
      "z": 2,
      "name": "Rock_Shale_Cobble"
    },
    {
      "x": -14,
      "y": 19,
      "z": 2,
      "name": "Rock_Shale"
    },
    {
      "x": -14,
      "y": 20,
      "z": 2,
      "name": "Rock_Shale_Brick"
    },
    {
      "x": -14,
      "y": 21,
      "z": 2,
      "name": "Rock_Shale_Brick"
    },
    {
      "x": -14,
      "y": 22,
      "z": 2,
      "name": "Soil_Snow"
    },
    {
      "x": -14,
      "y": 3,
      "z": 3,
      "name": "Rock_Shale"
    },
    {
      "x": -14,
      "y": 4,
      "z": 3,
      "name": "Rock_Shale"
    },
    {
      "x": -14,
      "y": 5,
      "z": 3,
      "name": "Rock_Shale"
    },
    {
      "x": -14,
      "y": 6,
      "z": 3,
      "name": "Rock_Shale"
    },
    {
      "x": -14,
      "y": 7,
      "z": 3,
      "name": "Rock_Shale"
    },
    {
      "x": -14,
      "y": 8,
      "z": 3,
      "name": "Rock_Shale"
    },
    {
      "x": -14,
      "y": 9,
      "z": 3,
      "name": "Rock_Shale"
    },
    {
      "x": -14,
      "y": 10,
      "z": 3,
      "name": "Rock_Shale"
    },
    {
      "x": -14,
      "y": 11,
      "z": 3,
      "name": "Rock_Shale"
    },
    {
      "x": -14,
      "y": 12,
      "z": 3,
      "name": "Rock_Shale"
    },
    {
      "x": -14,
      "y": 13,
      "z": 3,
      "name": "Rock_Shale"
    },
    {
      "x": -14,
      "y": 14,
      "z": 3,
      "name": "Rock_Shale_Cobble"
    },
    {
      "x": -14,
      "y": 15,
      "z": 3,
      "name": "Rock_Shale_Cobble"
    },
    {
      "x": -14,
      "y": 16,
      "z": 3,
      "name": "Rock_Shale_Cobble"
    },
    {
      "x": -14,
      "y": 17,
      "z": 3,
      "name": "Rock_Shale_Cobble"
    },
    {
      "x": -14,
      "y": 18,
      "z": 3,
      "name": "Rock_Shale_Cobble"
    },
    {
      "x": -14,
      "y": 19,
      "z": 3,
      "name": "Rock_Shale_Brick"
    },
    {
      "x": -14,
      "y": 20,
      "z": 3,
      "name": "Rock_Shale_Brick"
    },
    {
      "x": -14,
      "y": 21,
      "z": 3,
      "name": "Soil_Snow"
    },
    {
      "x": -14,
      "y": 22,
      "z": 3,
      "name": "Soil_Snow"
    },
    {
      "x": -13,
      "y": 19,
      "z": -2,
      "name": "Rock_Ice_Icicles",
      "rotation": 8
    },
    {
      "x": -13,
      "y": 20,
      "z": -2,
      "name": "Soil_Snow"
    },
    {
      "x": -13,
      "y": 21,
      "z": -2,
      "name": "Soil_Snow"
    },
    {
      "x": -13,
      "y": 3,
      "z": -1,
      "name": "Rock_Shale"
    },
    {
      "x": -13,
      "y": 4,
      "z": -1,
      "name": "Rock_Shale"
    },
    {
      "x": -13,
      "y": 5,
      "z": -1,
      "name": "Rock_Shale"
    },
    {
      "x": -13,
      "y": 6,
      "z": -1,
      "name": "Rock_Shale"
    },
    {
      "x": -13,
      "y": 7,
      "z": -1,
      "name": "Rock_Shale"
    },
    {
      "x": -13,
      "y": 8,
      "z": -1,
      "name": "Rock_Shale"
    },
    {
      "x": -13,
      "y": 9,
      "z": -1,
      "name": "Rock_Shale"
    },
    {
      "x": -13,
      "y": 10,
      "z": -1,
      "name": "Rock_Shale"
    },
    {
      "x": -13,
      "y": 11,
      "z": -1,
      "name": "Rock_Shale"
    },
    {
      "x": -13,
      "y": 12,
      "z": -1,
      "name": "Rock_Shale"
    },
    {
      "x": -13,
      "y": 13,
      "z": -1,
      "name": "Rock_Shale"
    },
    {
      "x": -13,
      "y": 14,
      "z": -1,
      "name": "Rock_Shale"
    },
    {
      "x": -13,
      "y": 15,
      "z": -1,
      "name": "Rock_Shale"
    },
    {
      "x": -13,
      "y": 16,
      "z": -1,
      "name": "Rock_Shale_Cobble"
    },
    {
      "x": -13,
      "y": 17,
      "z": -1,
      "name": "Rock_Shale_Cobble"
    },
    {
      "x": -13,
      "y": 18,
      "z": -1,
      "name": "Rock_Shale_Cobble"
    },
    {
      "x": -13,
      "y": 19,
      "z": -1,
      "name": "Rock_Shale_Cobble"
    },
    {
      "x": -13,
      "y": 20,
      "z": -1,
      "name": "Rock_Shale_Brick"
    },
    {
      "x": -13,
      "y": 21,
      "z": -1,
      "name": "Rock_Shale_Brick"
    },
    {
      "x": -13,
      "y": 22,
      "z": -1,
      "name": "Soil_Snow"
    },
    {
      "x": -13,
      "y": 3,
      "z": 0,
      "name": "Rock_Shale"
    },
    {
      "x": -13,
      "y": 4,
      "z": 0,
      "name": "Rock_Shale"
    },
    {
      "x": -13,
      "y": 5,
      "z": 0,
      "name": "Rock_Shale"
    },
    {
      "x": -13,
      "y": 6,
      "z": 0,
      "name": "Rock_Shale"
    },
    {
      "x": -13,
      "y": 7,
      "z": 0,
      "name": "Rock_Shale"
    },
    {
      "x": -13,
      "y": 8,
      "z": 0,
      "name": "Rock_Shale"
    },
    {
      "x": -13,
      "y": 9,
      "z": 0,
      "name": "Rock_Shale"
    },
    {
      "x": -13,
      "y": 10,
      "z": 0,
      "name": "Rock_Shale"
    },
    {
      "x": -13,
      "y": 11,
      "z": 0,
      "name": "Rock_Shale"
    },
    {
      "x": -13,
      "y": 12,
      "z": 0,
      "name": "Rock_Shale"
    },
    {
      "x": -13,
      "y": 13,
      "z": 0,
      "name": "Rock_Shale"
    },
    {
      "x": -13,
      "y": 14,
      "z": 0,
      "name": "Rock_Shale"
    },
    {
      "x": -13,
      "y": 15,
      "z": 0,
      "name": "Rock_Shale"
    },
    {
      "x": -13,
      "y": 16,
      "z": 0,
      "name": "Rock_Shale"
    },
    {
      "x": -13,
      "y": 17,
      "z": 0,
      "name": "Rock_Shale_Cobble"
    },
    {
      "x": -13,
      "y": 18,
      "z": 0,
      "name": "Rock_Shale_Cobble"
    },
    {
      "x": -13,
      "y": 19,
      "z": 0,
      "name": "Rock_Shale"
    },
    {
      "x": -13,
      "y": 20,
      "z": 0,
      "name": "Rock_Shale"
    },
    {
      "x": -13,
      "y": 21,
      "z": 0,
      "name": "Rock_Shale_Brick"
    },
    {
      "x": -13,
      "y": 22,
      "z": 0,
      "name": "Soil_Snow"
    },
    {
      "x": -13,
      "y": 3,
      "z": 1,
      "name": "Rock_Shale"
    },
    {
      "x": -13,
      "y": 4,
      "z": 1,
      "name": "Rock_Shale"
    },
    {
      "x": -13,
      "y": 5,
      "z": 1,
      "name": "Rock_Shale"
    },
    {
      "x": -13,
      "y": 6,
      "z": 1,
      "name": "Rock_Shale"
    },
    {
      "x": -13,
      "y": 7,
      "z": 1,
      "name": "Rock_Shale"
    },
    {
      "x": -13,
      "y": 8,
      "z": 1,
      "name": "Rock_Shale"
    },
    {
      "x": -13,
      "y": 9,
      "z": 1,
      "name": "Rock_Shale"
    },
    {
      "x": -13,
      "y": 10,
      "z": 1,
      "name": "Rock_Shale"
    },
    {
      "x": -13,
      "y": 11,
      "z": 1,
      "name": "Rock_Shale"
    },
    {
      "x": -13,
      "y": 12,
      "z": 1,
      "name": "Rock_Shale"
    },
    {
      "x": -13,
      "y": 13,
      "z": 1,
      "name": "Rock_Shale"
    },
    {
      "x": -13,
      "y": 14,
      "z": 1,
      "name": "Rock_Shale"
    },
    {
      "x": -13,
      "y": 15,
      "z": 1,
      "name": "Rock_Shale"
    },
    {
      "x": -13,
      "y": 16,
      "z": 1,
      "name": "Rock_Shale_Cobble"
    },
    {
      "x": -13,
      "y": 17,
      "z": 1,
      "name": "Rock_Shale"
    },
    {
      "x": -13,
      "y": 18,
      "z": 1,
      "name": "Rock_Shale"
    },
    {
      "x": -13,
      "y": 19,
      "z": 1,
      "name": "Rock_Shale"
    },
    {
      "x": -13,
      "y": 20,
      "z": 1,
      "name": "Rock_Shale_Brick"
    },
    {
      "x": -13,
      "y": 21,
      "z": 1,
      "name": "Rock_Shale"
    },
    {
      "x": -13,
      "y": 22,
      "z": 1,
      "name": "Soil_Snow"
    },
    {
      "x": -13,
      "y": 3,
      "z": 2,
      "name": "Rock_Shale"
    },
    {
      "x": -13,
      "y": 4,
      "z": 2,
      "name": "Rock_Shale"
    },
    {
      "x": -13,
      "y": 5,
      "z": 2,
      "name": "Rock_Shale"
    },
    {
      "x": -13,
      "y": 6,
      "z": 2,
      "name": "Rock_Shale"
    },
    {
      "x": -13,
      "y": 7,
      "z": 2,
      "name": "Rock_Shale"
    },
    {
      "x": -13,
      "y": 8,
      "z": 2,
      "name": "Rock_Shale"
    },
    {
      "x": -13,
      "y": 9,
      "z": 2,
      "name": "Rock_Shale"
    },
    {
      "x": -13,
      "y": 10,
      "z": 2,
      "name": "Rock_Shale"
    },
    {
      "x": -13,
      "y": 11,
      "z": 2,
      "name": "Rock_Shale"
    },
    {
      "x": -13,
      "y": 12,
      "z": 2,
      "name": "Rock_Shale"
    },
    {
      "x": -13,
      "y": 13,
      "z": 2,
      "name": "Rock_Shale"
    },
    {
      "x": -13,
      "y": 14,
      "z": 2,
      "name": "Rock_Shale"
    },
    {
      "x": -13,
      "y": 15,
      "z": 2,
      "name": "Rock_Shale_Cobble"
    },
    {
      "x": -13,
      "y": 16,
      "z": 2,
      "name": "Rock_Shale_Cobble"
    },
    {
      "x": -13,
      "y": 17,
      "z": 2,
      "name": "Rock_Shale_Cobble"
    },
    {
      "x": -13,
      "y": 18,
      "z": 2,
      "name": "Rock_Shale"
    },
    {
      "x": -13,
      "y": 19,
      "z": 2,
      "name": "Rock_Shale_Brick"
    },
    {
      "x": -13,
      "y": 20,
      "z": 2,
      "name": "Rock_Shale_Brick"
    },
    {
      "x": -13,
      "y": 21,
      "z": 2,
      "name": "Rock_Shale_Brick"
    },
    {
      "x": -13,
      "y": 22,
      "z": 2,
      "name": "Soil_Snow"
    },
    {
      "x": -13,
      "y": 3,
      "z": 3,
      "name": "Rock_Shale"
    },
    {
      "x": -13,
      "y": 4,
      "z": 3,
      "name": "Rock_Shale"
    },
    {
      "x": -13,
      "y": 5,
      "z": 3,
      "name": "Rock_Shale"
    },
    {
      "x": -13,
      "y": 6,
      "z": 3,
      "name": "Rock_Shale"
    },
    {
      "x": -13,
      "y": 7,
      "z": 3,
      "name": "Rock_Shale"
    },
    {
      "x": -13,
      "y": 8,
      "z": 3,
      "name": "Rock_Shale"
    },
    {
      "x": -13,
      "y": 9,
      "z": 3,
      "name": "Rock_Shale"
    },
    {
      "x": -13,
      "y": 10,
      "z": 3,
      "name": "Rock_Shale"
    },
    {
      "x": -13,
      "y": 11,
      "z": 3,
      "name": "Rock_Shale"
    },
    {
      "x": -13,
      "y": 12,
      "z": 3,
      "name": "Rock_Shale"
    },
    {
      "x": -13,
      "y": 13,
      "z": 3,
      "name": "Rock_Shale"
    },
    {
      "x": -13,
      "y": 14,
      "z": 3,
      "name": "Rock_Shale_Cobble"
    },
    {
      "x": -13,
      "y": 15,
      "z": 3,
      "name": "Rock_Shale_Cobble"
    },
    {
      "x": -13,
      "y": 16,
      "z": 3,
      "name": "Rock_Shale_Cobble"
    },
    {
      "x": -13,
      "y": 17,
      "z": 3,
      "name": "Rock_Shale_Cobble"
    },
    {
      "x": -13,
      "y": 18,
      "z": 3,
      "name": "Rock_Shale_Brick"
    },
    {
      "x": -13,
      "y": 19,
      "z": 3,
      "name": "Rock_Shale_Brick"
    },
    {
      "x": -13,
      "y": 20,
      "z": 3,
      "name": "Rock_Shale_Brick"
    },
    {
      "x": -13,
      "y": 21,
      "z": 3,
      "name": "Rock_Shale_Brick"
    },
    {
      "x": -13,
      "y": 22,
      "z": 3,
      "name": "Soil_Snow"
    },
    {
      "x": -12,
      "y": 3,
      "z": -1,
      "name": "Rock_Shale"
    },
    {
      "x": -12,
      "y": 4,
      "z": -1,
      "name": "Rock_Shale"
    },
    {
      "x": -12,
      "y": 5,
      "z": -1,
      "name": "Rock_Shale"
    },
    {
      "x": -12,
      "y": 6,
      "z": -1,
      "name": "Rock_Shale"
    },
    {
      "x": -12,
      "y": 7,
      "z": -1,
      "name": "Rock_Shale"
    },
    {
      "x": -12,
      "y": 8,
      "z": -1,
      "name": "Rock_Shale"
    },
    {
      "x": -12,
      "y": 9,
      "z": -1,
      "name": "Rock_Shale"
    },
    {
      "x": -12,
      "y": 10,
      "z": -1,
      "name": "Rock_Shale"
    },
    {
      "x": -12,
      "y": 11,
      "z": -1,
      "name": "Rock_Shale"
    },
    {
      "x": -12,
      "y": 12,
      "z": -1,
      "name": "Rock_Shale"
    },
    {
      "x": -12,
      "y": 13,
      "z": -1,
      "name": "Rock_Shale"
    },
    {
      "x": -12,
      "y": 14,
      "z": -1,
      "name": "Rock_Shale"
    },
    {
      "x": -12,
      "y": 15,
      "z": -1,
      "name": "Rock_Shale_Cobble"
    },
    {
      "x": -12,
      "y": 16,
      "z": -1,
      "name": "Rock_Shale_Cobble"
    },
    {
      "x": -12,
      "y": 17,
      "z": -1,
      "name": "Rock_Shale_Cobble"
    },
    {
      "x": -12,
      "y": 18,
      "z": -1,
      "name": "Rock_Shale_Cobble"
    },
    {
      "x": -12,
      "y": 19,
      "z": -1,
      "name": "Rock_Shale_Brick"
    },
    {
      "x": -12,
      "y": 20,
      "z": -1,
      "name": "Rock_Shale_Brick"
    },
    {
      "x": -12,
      "y": 21,
      "z": -1,
      "name": "Soil_Snow"
    },
    {
      "x": -12,
      "y": 22,
      "z": -1,
      "name": "Soil_Snow"
    },
    {
      "x": -12,
      "y": 3,
      "z": 0,
      "name": "Rock_Shale"
    },
    {
      "x": -12,
      "y": 4,
      "z": 0,
      "name": "Rock_Shale"
    },
    {
      "x": -12,
      "y": 5,
      "z": 0,
      "name": "Rock_Shale"
    },
    {
      "x": -12,
      "y": 6,
      "z": 0,
      "name": "Rock_Shale"
    },
    {
      "x": -12,
      "y": 7,
      "z": 0,
      "name": "Rock_Shale"
    },
    {
      "x": -12,
      "y": 8,
      "z": 0,
      "name": "Rock_Shale"
    },
    {
      "x": -12,
      "y": 9,
      "z": 0,
      "name": "Rock_Shale"
    },
    {
      "x": -12,
      "y": 10,
      "z": 0,
      "name": "Rock_Shale"
    },
    {
      "x": -12,
      "y": 11,
      "z": 0,
      "name": "Rock_Shale"
    },
    {
      "x": -12,
      "y": 12,
      "z": 0,
      "name": "Rock_Shale"
    },
    {
      "x": -12,
      "y": 13,
      "z": 0,
      "name": "Rock_Shale"
    },
    {
      "x": -12,
      "y": 14,
      "z": 0,
      "name": "Rock_Shale"
    },
    {
      "x": -12,
      "y": 15,
      "z": 0,
      "name": "Rock_Shale"
    },
    {
      "x": -12,
      "y": 16,
      "z": 0,
      "name": "Rock_Shale_Cobble"
    },
    {
      "x": -12,
      "y": 17,
      "z": 0,
      "name": "Rock_Shale_Cobble"
    },
    {
      "x": -12,
      "y": 18,
      "z": 0,
      "name": "Rock_Shale_Cobble"
    },
    {
      "x": -12,
      "y": 19,
      "z": 0,
      "name": "Rock_Shale_Brick"
    },
    {
      "x": -12,
      "y": 20,
      "z": 0,
      "name": "Rock_Shale_Brick"
    },
    {
      "x": -12,
      "y": 21,
      "z": 0,
      "name": "Rock_Shale_Brick"
    },
    {
      "x": -12,
      "y": 22,
      "z": 0,
      "name": "Soil_Snow"
    },
    {
      "x": -12,
      "y": 3,
      "z": 1,
      "name": "Rock_Shale"
    },
    {
      "x": -12,
      "y": 4,
      "z": 1,
      "name": "Rock_Shale"
    },
    {
      "x": -12,
      "y": 5,
      "z": 1,
      "name": "Rock_Shale"
    },
    {
      "x": -12,
      "y": 6,
      "z": 1,
      "name": "Rock_Shale"
    },
    {
      "x": -12,
      "y": 7,
      "z": 1,
      "name": "Rock_Shale"
    },
    {
      "x": -12,
      "y": 8,
      "z": 1,
      "name": "Rock_Shale"
    },
    {
      "x": -12,
      "y": 9,
      "z": 1,
      "name": "Rock_Shale"
    },
    {
      "x": -12,
      "y": 10,
      "z": 1,
      "name": "Rock_Shale"
    },
    {
      "x": -12,
      "y": 11,
      "z": 1,
      "name": "Rock_Shale"
    },
    {
      "x": -12,
      "y": 12,
      "z": 1,
      "name": "Rock_Shale"
    },
    {
      "x": -12,
      "y": 13,
      "z": 1,
      "name": "Rock_Shale"
    },
    {
      "x": -12,
      "y": 14,
      "z": 1,
      "name": "Rock_Shale"
    },
    {
      "x": -12,
      "y": 15,
      "z": 1,
      "name": "Rock_Shale_Cobble"
    },
    {
      "x": -12,
      "y": 16,
      "z": 1,
      "name": "Rock_Shale_Cobble"
    },
    {
      "x": -12,
      "y": 17,
      "z": 1,
      "name": "Rock_Shale_Cobble"
    },
    {
      "x": -12,
      "y": 18,
      "z": 1,
      "name": "Rock_Shale"
    },
    {
      "x": -12,
      "y": 19,
      "z": 1,
      "name": "Rock_Shale_Brick"
    },
    {
      "x": -12,
      "y": 20,
      "z": 1,
      "name": "Rock_Shale_Brick"
    },
    {
      "x": -12,
      "y": 21,
      "z": 1,
      "name": "Rock_Shale_Brick"
    },
    {
      "x": -12,
      "y": 22,
      "z": 1,
      "name": "Soil_Snow"
    },
    {
      "x": -12,
      "y": 3,
      "z": 2,
      "name": "Rock_Shale"
    },
    {
      "x": -12,
      "y": 4,
      "z": 2,
      "name": "Rock_Shale"
    },
    {
      "x": -12,
      "y": 5,
      "z": 2,
      "name": "Rock_Shale"
    },
    {
      "x": -12,
      "y": 6,
      "z": 2,
      "name": "Rock_Shale"
    },
    {
      "x": -12,
      "y": 7,
      "z": 2,
      "name": "Rock_Shale"
    },
    {
      "x": -12,
      "y": 8,
      "z": 2,
      "name": "Rock_Shale"
    },
    {
      "x": -12,
      "y": 9,
      "z": 2,
      "name": "Rock_Shale"
    },
    {
      "x": -12,
      "y": 10,
      "z": 2,
      "name": "Rock_Shale"
    },
    {
      "x": -12,
      "y": 11,
      "z": 2,
      "name": "Rock_Shale"
    },
    {
      "x": -12,
      "y": 12,
      "z": 2,
      "name": "Rock_Shale"
    },
    {
      "x": -12,
      "y": 13,
      "z": 2,
      "name": "Rock_Shale"
    },
    {
      "x": -12,
      "y": 14,
      "z": 2,
      "name": "Rock_Shale_Cobble"
    },
    {
      "x": -12,
      "y": 15,
      "z": 2,
      "name": "Rock_Shale_Cobble"
    },
    {
      "x": -12,
      "y": 16,
      "z": 2,
      "name": "Rock_Shale_Cobble"
    },
    {
      "x": -12,
      "y": 17,
      "z": 2,
      "name": "Rock_Shale_Cobble"
    },
    {
      "x": -12,
      "y": 18,
      "z": 2,
      "name": "Rock_Shale_Brick"
    },
    {
      "x": -12,
      "y": 19,
      "z": 2,
      "name": "Rock_Shale_Brick"
    },
    {
      "x": -12,
      "y": 20,
      "z": 2,
      "name": "Rock_Shale_Brick"
    },
    {
      "x": -12,
      "y": 21,
      "z": 2,
      "name": "Rock_Shale_Brick"
    },
    {
      "x": -12,
      "y": 22,
      "z": 2,
      "name": "Soil_Snow"
    },
    {
      "x": -12,
      "y": 3,
      "z": 3,
      "name": "Rock_Shale"
    },
    {
      "x": -12,
      "y": 4,
      "z": 3,
      "name": "Rock_Shale"
    },
    {
      "x": -12,
      "y": 5,
      "z": 3,
      "name": "Rock_Shale"
    },
    {
      "x": -12,
      "y": 6,
      "z": 3,
      "name": "Rock_Shale"
    },
    {
      "x": -12,
      "y": 7,
      "z": 3,
      "name": "Rock_Shale"
    },
    {
      "x": -12,
      "y": 8,
      "z": 3,
      "name": "Rock_Shale"
    },
    {
      "x": -12,
      "y": 9,
      "z": 3,
      "name": "Rock_Shale"
    },
    {
      "x": -12,
      "y": 10,
      "z": 3,
      "name": "Rock_Shale"
    },
    {
      "x": -12,
      "y": 11,
      "z": 3,
      "name": "Rock_Shale"
    },
    {
      "x": -12,
      "y": 12,
      "z": 3,
      "name": "Rock_Shale"
    },
    {
      "x": -12,
      "y": 13,
      "z": 3,
      "name": "Rock_Shale"
    },
    {
      "x": -12,
      "y": 14,
      "z": 3,
      "name": "Rock_Shale_Cobble"
    },
    {
      "x": -12,
      "y": 15,
      "z": 3,
      "name": "Rock_Shale_Cobble"
    },
    {
      "x": -12,
      "y": 16,
      "z": 3,
      "name": "Rock_Shale_Cobble"
    },
    {
      "x": -12,
      "y": 17,
      "z": 3,
      "name": "Rock_Shale_Cobble"
    },
    {
      "x": -12,
      "y": 18,
      "z": 3,
      "name": "Rock_Shale_Brick"
    },
    {
      "x": -12,
      "y": 19,
      "z": 3,
      "name": "Rock_Shale_Brick"
    },
    {
      "x": -12,
      "y": 20,
      "z": 3,
      "name": "Rock_Shale_Brick"
    },
    {
      "x": -12,
      "y": 21,
      "z": 3,
      "name": "Rock_Shale_Brick"
    },
    {
      "x": -12,
      "y": 22,
      "z": 3,
      "name": "Soil_Snow"
    },
    {
      "x": -11,
      "y": 3,
      "z": -1,
      "name": "Rock_Shale"
    },
    {
      "x": -11,
      "y": 4,
      "z": -1,
      "name": "Rock_Shale"
    },
    {
      "x": -11,
      "y": 5,
      "z": -1,
      "name": "Rock_Shale"
    },
    {
      "x": -11,
      "y": 6,
      "z": -1,
      "name": "Rock_Shale"
    },
    {
      "x": -11,
      "y": 7,
      "z": -1,
      "name": "Rock_Shale"
    },
    {
      "x": -11,
      "y": 8,
      "z": -1,
      "name": "Rock_Shale"
    },
    {
      "x": -11,
      "y": 9,
      "z": -1,
      "name": "Rock_Shale"
    },
    {
      "x": -11,
      "y": 10,
      "z": -1,
      "name": "Rock_Shale"
    },
    {
      "x": -11,
      "y": 11,
      "z": -1,
      "name": "Rock_Shale"
    },
    {
      "x": -11,
      "y": 12,
      "z": -1,
      "name": "Rock_Shale"
    },
    {
      "x": -11,
      "y": 13,
      "z": -1,
      "name": "Rock_Shale"
    },
    {
      "x": -11,
      "y": 14,
      "z": -1,
      "name": "Rock_Shale"
    },
    {
      "x": -11,
      "y": 15,
      "z": -1,
      "name": "Rock_Shale_Cobble"
    },
    {
      "x": -11,
      "y": 16,
      "z": -1,
      "name": "Rock_Shale_Cobble"
    },
    {
      "x": -11,
      "y": 17,
      "z": -1,
      "name": "Rock_Shale_Cobble"
    },
    {
      "x": -11,
      "y": 18,
      "z": -1,
      "name": "Rock_Shale_Cobble"
    },
    {
      "x": -11,
      "y": 19,
      "z": -1,
      "name": "Rock_Shale_Brick"
    },
    {
      "x": -11,
      "y": 20,
      "z": -1,
      "name": "Rock_Shale_Brick"
    },
    {
      "x": -11,
      "y": 21,
      "z": -1,
      "name": "Soil_Snow"
    },
    {
      "x": -11,
      "y": 3,
      "z": 0,
      "name": "Rock_Shale"
    },
    {
      "x": -11,
      "y": 4,
      "z": 0,
      "name": "Rock_Shale"
    },
    {
      "x": -11,
      "y": 5,
      "z": 0,
      "name": "Rock_Shale"
    },
    {
      "x": -11,
      "y": 6,
      "z": 0,
      "name": "Rock_Shale"
    },
    {
      "x": -11,
      "y": 7,
      "z": 0,
      "name": "Rock_Shale"
    },
    {
      "x": -11,
      "y": 8,
      "z": 0,
      "name": "Rock_Shale"
    },
    {
      "x": -11,
      "y": 9,
      "z": 0,
      "name": "Rock_Shale"
    },
    {
      "x": -11,
      "y": 10,
      "z": 0,
      "name": "Rock_Shale"
    },
    {
      "x": -11,
      "y": 11,
      "z": 0,
      "name": "Rock_Shale"
    },
    {
      "x": -11,
      "y": 12,
      "z": 0,
      "name": "Rock_Shale"
    },
    {
      "x": -11,
      "y": 13,
      "z": 0,
      "name": "Rock_Shale"
    },
    {
      "x": -11,
      "y": 14,
      "z": 0,
      "name": "Rock_Shale"
    },
    {
      "x": -11,
      "y": 15,
      "z": 0,
      "name": "Rock_Shale_Cobble"
    },
    {
      "x": -11,
      "y": 16,
      "z": 0,
      "name": "Rock_Shale_Cobble"
    },
    {
      "x": -11,
      "y": 17,
      "z": 0,
      "name": "Rock_Shale_Cobble"
    },
    {
      "x": -11,
      "y": 18,
      "z": 0,
      "name": "Rock_Shale_Brick"
    },
    {
      "x": -11,
      "y": 19,
      "z": 0,
      "name": "Rock_Shale_Brick"
    },
    {
      "x": -11,
      "y": 20,
      "z": 0,
      "name": "Rock_Shale_Brick"
    },
    {
      "x": -11,
      "y": 21,
      "z": 0,
      "name": "Rock_Shale_Brick"
    },
    {
      "x": -11,
      "y": 22,
      "z": 0,
      "name": "Soil_Snow"
    },
    {
      "x": -11,
      "y": 3,
      "z": 1,
      "name": "Rock_Shale"
    },
    {
      "x": -11,
      "y": 4,
      "z": 1,
      "name": "Rock_Shale"
    },
    {
      "x": -11,
      "y": 5,
      "z": 1,
      "name": "Rock_Shale"
    },
    {
      "x": -11,
      "y": 6,
      "z": 1,
      "name": "Rock_Shale"
    },
    {
      "x": -11,
      "y": 7,
      "z": 1,
      "name": "Rock_Shale"
    },
    {
      "x": -11,
      "y": 8,
      "z": 1,
      "name": "Rock_Shale"
    },
    {
      "x": -11,
      "y": 9,
      "z": 1,
      "name": "Rock_Shale"
    },
    {
      "x": -11,
      "y": 10,
      "z": 1,
      "name": "Rock_Shale"
    },
    {
      "x": -11,
      "y": 11,
      "z": 1,
      "name": "Rock_Shale"
    },
    {
      "x": -11,
      "y": 12,
      "z": 1,
      "name": "Rock_Shale"
    },
    {
      "x": -11,
      "y": 13,
      "z": 1,
      "name": "Rock_Shale"
    },
    {
      "x": -11,
      "y": 14,
      "z": 1,
      "name": "Rock_Shale"
    },
    {
      "x": -11,
      "y": 15,
      "z": 1,
      "name": "Rock_Shale"
    },
    {
      "x": -11,
      "y": 16,
      "z": 1,
      "name": "Rock_Shale_Cobble"
    },
    {
      "x": -11,
      "y": 17,
      "z": 1,
      "name": "Rock_Shale_Cobble"
    },
    {
      "x": -11,
      "y": 18,
      "z": 1,
      "name": "Rock_Shale_Cobble"
    },
    {
      "x": -11,
      "y": 19,
      "z": 1,
      "name": "Rock_Shale_Brick"
    },
    {
      "x": -11,
      "y": 20,
      "z": 1,
      "name": "Rock_Shale_Brick"
    },
    {
      "x": -11,
      "y": 21,
      "z": 1,
      "name": "Rock_Shale_Brick"
    },
    {
      "x": -11,
      "y": 22,
      "z": 1,
      "name": "Soil_Snow"
    },
    {
      "x": -11,
      "y": 3,
      "z": 2,
      "name": "Rock_Shale"
    },
    {
      "x": -11,
      "y": 4,
      "z": 2,
      "name": "Rock_Shale"
    },
    {
      "x": -11,
      "y": 5,
      "z": 2,
      "name": "Rock_Shale"
    },
    {
      "x": -11,
      "y": 6,
      "z": 2,
      "name": "Rock_Shale"
    },
    {
      "x": -11,
      "y": 7,
      "z": 2,
      "name": "Rock_Shale"
    },
    {
      "x": -11,
      "y": 8,
      "z": 2,
      "name": "Rock_Shale"
    },
    {
      "x": -11,
      "y": 9,
      "z": 2,
      "name": "Rock_Shale"
    },
    {
      "x": -11,
      "y": 10,
      "z": 2,
      "name": "Rock_Shale"
    },
    {
      "x": -11,
      "y": 11,
      "z": 2,
      "name": "Rock_Shale"
    },
    {
      "x": -11,
      "y": 12,
      "z": 2,
      "name": "Rock_Shale"
    },
    {
      "x": -11,
      "y": 13,
      "z": 2,
      "name": "Rock_Shale"
    },
    {
      "x": -11,
      "y": 14,
      "z": 2,
      "name": "Rock_Shale"
    },
    {
      "x": -11,
      "y": 15,
      "z": 2,
      "name": "Rock_Shale_Cobble"
    },
    {
      "x": -11,
      "y": 16,
      "z": 2,
      "name": "Rock_Shale_Cobble"
    },
    {
      "x": -11,
      "y": 17,
      "z": 2,
      "name": "Rock_Shale_Cobble"
    },
    {
      "x": -11,
      "y": 18,
      "z": 2,
      "name": "Rock_Shale_Brick"
    },
    {
      "x": -11,
      "y": 19,
      "z": 2,
      "name": "Rock_Shale_Brick"
    },
    {
      "x": -11,
      "y": 20,
      "z": 2,
      "name": "Rock_Shale_Brick"
    },
    {
      "x": -11,
      "y": 21,
      "z": 2,
      "name": "Rock_Shale_Brick"
    },
    {
      "x": -11,
      "y": 22,
      "z": 2,
      "name": "Soil_Snow"
    },
    {
      "x": -11,
      "y": 3,
      "z": 3,
      "name": "Rock_Shale"
    },
    {
      "x": -11,
      "y": 4,
      "z": 3,
      "name": "Rock_Shale"
    },
    {
      "x": -11,
      "y": 5,
      "z": 3,
      "name": "Rock_Shale"
    },
    {
      "x": -11,
      "y": 6,
      "z": 3,
      "name": "Rock_Shale"
    },
    {
      "x": -11,
      "y": 7,
      "z": 3,
      "name": "Rock_Shale"
    },
    {
      "x": -11,
      "y": 8,
      "z": 3,
      "name": "Rock_Shale"
    },
    {
      "x": -11,
      "y": 9,
      "z": 3,
      "name": "Rock_Shale"
    },
    {
      "x": -11,
      "y": 10,
      "z": 3,
      "name": "Rock_Shale"
    },
    {
      "x": -11,
      "y": 11,
      "z": 3,
      "name": "Rock_Shale"
    },
    {
      "x": -11,
      "y": 12,
      "z": 3,
      "name": "Rock_Shale"
    },
    {
      "x": -11,
      "y": 13,
      "z": 3,
      "name": "Rock_Shale"
    },
    {
      "x": -11,
      "y": 14,
      "z": 3,
      "name": "Rock_Shale_Cobble"
    },
    {
      "x": -11,
      "y": 15,
      "z": 3,
      "name": "Rock_Shale_Cobble"
    },
    {
      "x": -11,
      "y": 16,
      "z": 3,
      "name": "Rock_Shale_Cobble"
    },
    {
      "x": -11,
      "y": 17,
      "z": 3,
      "name": "Rock_Shale_Cobble"
    },
    {
      "x": -11,
      "y": 18,
      "z": 3,
      "name": "Rock_Shale_Brick"
    },
    {
      "x": -11,
      "y": 19,
      "z": 3,
      "name": "Rock_Shale_Brick"
    },
    {
      "x": -11,
      "y": 20,
      "z": 3,
      "name": "Rock_Shale_Brick"
    },
    {
      "x": -11,
      "y": 21,
      "z": 3,
      "name": "Rock_Shale_Brick"
    },
    {
      "x": -11,
      "y": 22,
      "z": 3,
      "name": "Soil_Snow"
    },
    {
      "x": -10,
      "y": 3,
      "z": 0,
      "name": "Rock_Shale"
    },
    {
      "x": -10,
      "y": 4,
      "z": 0,
      "name": "Rock_Shale"
    },
    {
      "x": -10,
      "y": 5,
      "z": 0,
      "name": "Rock_Shale"
    },
    {
      "x": -10,
      "y": 6,
      "z": 0,
      "name": "Rock_Shale"
    },
    {
      "x": -10,
      "y": 7,
      "z": 0,
      "name": "Rock_Shale"
    },
    {
      "x": -10,
      "y": 8,
      "z": 0,
      "name": "Rock_Shale"
    },
    {
      "x": -10,
      "y": 9,
      "z": 0,
      "name": "Rock_Shale"
    },
    {
      "x": -10,
      "y": 10,
      "z": 0,
      "name": "Rock_Shale"
    },
    {
      "x": -10,
      "y": 11,
      "z": 0,
      "name": "Rock_Shale"
    },
    {
      "x": -10,
      "y": 12,
      "z": 0,
      "name": "Rock_Shale"
    },
    {
      "x": -10,
      "y": 13,
      "z": 0,
      "name": "Rock_Shale"
    },
    {
      "x": -10,
      "y": 14,
      "z": 0,
      "name": "Rock_Shale"
    },
    {
      "x": -10,
      "y": 15,
      "z": 0,
      "name": "Rock_Shale"
    },
    {
      "x": -10,
      "y": 16,
      "z": 0,
      "name": "Rock_Shale_Cobble"
    },
    {
      "x": -10,
      "y": 17,
      "z": 0,
      "name": "Rock_Shale_Cobble"
    },
    {
      "x": -10,
      "y": 18,
      "z": 0,
      "name": "Rock_Shale_Brick"
    },
    {
      "x": -10,
      "y": 19,
      "z": 0,
      "name": "Rock_Shale_Brick"
    },
    {
      "x": -10,
      "y": 20,
      "z": 0,
      "name": "Rock_Shale_Brick"
    },
    {
      "x": -10,
      "y": 21,
      "z": 0,
      "name": "Rock_Shale_Brick"
    },
    {
      "x": -10,
      "y": 22,
      "z": 0,
      "name": "Soil_Snow"
    },
    {
      "x": -10,
      "y": 3,
      "z": 1,
      "name": "Rock_Shale"
    },
    {
      "x": -10,
      "y": 4,
      "z": 1,
      "name": "Rock_Shale"
    },
    {
      "x": -10,
      "y": 5,
      "z": 1,
      "name": "Rock_Shale"
    },
    {
      "x": -10,
      "y": 6,
      "z": 1,
      "name": "Rock_Shale"
    },
    {
      "x": -10,
      "y": 7,
      "z": 1,
      "name": "Rock_Shale"
    },
    {
      "x": -10,
      "y": 8,
      "z": 1,
      "name": "Rock_Shale"
    },
    {
      "x": -10,
      "y": 9,
      "z": 1,
      "name": "Rock_Shale"
    },
    {
      "x": -10,
      "y": 10,
      "z": 1,
      "name": "Rock_Shale"
    },
    {
      "x": -10,
      "y": 11,
      "z": 1,
      "name": "Rock_Shale"
    },
    {
      "x": -10,
      "y": 12,
      "z": 1,
      "name": "Rock_Shale"
    },
    {
      "x": -10,
      "y": 13,
      "z": 1,
      "name": "Rock_Shale"
    },
    {
      "x": -10,
      "y": 14,
      "z": 1,
      "name": "Rock_Shale"
    },
    {
      "x": -10,
      "y": 15,
      "z": 1,
      "name": "Rock_Shale"
    },
    {
      "x": -10,
      "y": 16,
      "z": 1,
      "name": "Rock_Shale"
    },
    {
      "x": -10,
      "y": 17,
      "z": 1,
      "name": "Rock_Shale_Cobble"
    },
    {
      "x": -10,
      "y": 18,
      "z": 1,
      "name": "Rock_Shale_Brick"
    },
    {
      "x": -10,
      "y": 19,
      "z": 1,
      "name": "Rock_Shale_Brick"
    },
    {
      "x": -10,
      "y": 20,
      "z": 1,
      "name": "Rock_Shale_Brick"
    },
    {
      "x": -10,
      "y": 21,
      "z": 1,
      "name": "Rock_Shale_Brick"
    },
    {
      "x": -10,
      "y": 22,
      "z": 1,
      "name": "Soil_Snow"
    },
    {
      "x": -10,
      "y": 3,
      "z": 2,
      "name": "Rock_Shale"
    },
    {
      "x": -10,
      "y": 4,
      "z": 2,
      "name": "Rock_Shale"
    },
    {
      "x": -10,
      "y": 5,
      "z": 2,
      "name": "Rock_Shale"
    },
    {
      "x": -10,
      "y": 6,
      "z": 2,
      "name": "Rock_Shale"
    },
    {
      "x": -10,
      "y": 7,
      "z": 2,
      "name": "Rock_Shale"
    },
    {
      "x": -10,
      "y": 8,
      "z": 2,
      "name": "Rock_Shale"
    },
    {
      "x": -10,
      "y": 9,
      "z": 2,
      "name": "Rock_Shale"
    },
    {
      "x": -10,
      "y": 10,
      "z": 2,
      "name": "Rock_Shale"
    },
    {
      "x": -10,
      "y": 11,
      "z": 2,
      "name": "Rock_Shale"
    },
    {
      "x": -10,
      "y": 12,
      "z": 2,
      "name": "Rock_Shale"
    },
    {
      "x": -10,
      "y": 13,
      "z": 2,
      "name": "Rock_Shale"
    },
    {
      "x": -10,
      "y": 14,
      "z": 2,
      "name": "Rock_Shale"
    },
    {
      "x": -10,
      "y": 15,
      "z": 2,
      "name": "Rock_Shale_Cobble"
    },
    {
      "x": -10,
      "y": 16,
      "z": 2,
      "name": "Rock_Shale_Cobble"
    },
    {
      "x": -10,
      "y": 17,
      "z": 2,
      "name": "Rock_Shale_Cobble"
    },
    {
      "x": -10,
      "y": 18,
      "z": 2,
      "name": "Rock_Shale"
    },
    {
      "x": -10,
      "y": 19,
      "z": 2,
      "name": "Rock_Shale_Brick"
    },
    {
      "x": -10,
      "y": 20,
      "z": 2,
      "name": "Rock_Shale_Brick"
    },
    {
      "x": -10,
      "y": 21,
      "z": 2,
      "name": "Rock_Shale_Brick"
    },
    {
      "x": -10,
      "y": 22,
      "z": 2,
      "name": "Soil_Snow"
    },
    {
      "x": -10,
      "y": 3,
      "z": 3,
      "name": "Rock_Shale"
    },
    {
      "x": -10,
      "y": 4,
      "z": 3,
      "name": "Rock_Shale"
    },
    {
      "x": -10,
      "y": 5,
      "z": 3,
      "name": "Rock_Shale"
    },
    {
      "x": -10,
      "y": 6,
      "z": 3,
      "name": "Rock_Shale"
    },
    {
      "x": -10,
      "y": 7,
      "z": 3,
      "name": "Rock_Shale"
    },
    {
      "x": -10,
      "y": 8,
      "z": 3,
      "name": "Rock_Shale"
    },
    {
      "x": -10,
      "y": 9,
      "z": 3,
      "name": "Rock_Shale"
    },
    {
      "x": -10,
      "y": 10,
      "z": 3,
      "name": "Rock_Shale"
    },
    {
      "x": -10,
      "y": 11,
      "z": 3,
      "name": "Rock_Shale"
    },
    {
      "x": -10,
      "y": 12,
      "z": 3,
      "name": "Rock_Shale"
    },
    {
      "x": -10,
      "y": 13,
      "z": 3,
      "name": "Rock_Shale"
    },
    {
      "x": -10,
      "y": 14,
      "z": 3,
      "name": "Rock_Shale_Cobble"
    },
    {
      "x": -10,
      "y": 15,
      "z": 3,
      "name": "Rock_Shale_Cobble"
    },
    {
      "x": -10,
      "y": 16,
      "z": 3,
      "name": "Rock_Shale_Cobble"
    },
    {
      "x": -10,
      "y": 17,
      "z": 3,
      "name": "Rock_Shale_Cobble"
    },
    {
      "x": -10,
      "y": 18,
      "z": 3,
      "name": "Rock_Shale_Brick"
    },
    {
      "x": -10,
      "y": 19,
      "z": 3,
      "name": "Rock_Shale_Brick"
    },
    {
      "x": -10,
      "y": 20,
      "z": 3,
      "name": "Rock_Shale_Brick"
    },
    {
      "x": -10,
      "y": 21,
      "z": 3,
      "name": "Rock_Shale_Brick"
    },
    {
      "x": -10,
      "y": 22,
      "z": 3,
      "name": "Soil_Snow"
    },
    {
      "x": -10,
      "y": 3,
      "z": 4,
      "name": "Rock_Shale"
    },
    {
      "x": -10,
      "y": 4,
      "z": 4,
      "name": "Rock_Shale"
    },
    {
      "x": -10,
      "y": 5,
      "z": 4,
      "name": "Rock_Shale"
    },
    {
      "x": -10,
      "y": 6,
      "z": 4,
      "name": "Rock_Shale"
    },
    {
      "x": -10,
      "y": 7,
      "z": 4,
      "name": "Rock_Shale"
    },
    {
      "x": -10,
      "y": 8,
      "z": 4,
      "name": "Rock_Shale"
    },
    {
      "x": -10,
      "y": 9,
      "z": 4,
      "name": "Rock_Shale"
    },
    {
      "x": -10,
      "y": 10,
      "z": 4,
      "name": "Rock_Shale"
    },
    {
      "x": -10,
      "y": 11,
      "z": 4,
      "name": "Rock_Shale"
    },
    {
      "x": -10,
      "y": 12,
      "z": 4,
      "name": "Rock_Shale"
    },
    {
      "x": -10,
      "y": 13,
      "z": 4,
      "name": "Rock_Shale"
    },
    {
      "x": -10,
      "y": 14,
      "z": 4,
      "name": "Rock_Shale_Cobble"
    },
    {
      "x": -10,
      "y": 15,
      "z": 4,
      "name": "Rock_Shale_Cobble"
    },
    {
      "x": -10,
      "y": 16,
      "z": 4,
      "name": "Rock_Shale_Cobble"
    },
    {
      "x": -10,
      "y": 17,
      "z": 4,
      "name": "Rock_Shale_Cobble"
    },
    {
      "x": -10,
      "y": 18,
      "z": 4,
      "name": "Rock_Shale_Brick"
    },
    {
      "x": -10,
      "y": 19,
      "z": 4,
      "name": "Rock_Shale_Brick"
    },
    {
      "x": -10,
      "y": 20,
      "z": 4,
      "name": "Rock_Shale_Brick"
    },
    {
      "x": -10,
      "y": 21,
      "z": 4,
      "name": "Rock_Shale_Brick"
    },
    {
      "x": -10,
      "y": 22,
      "z": 4,
      "name": "Soil_Snow"
    },
    {
      "x": -9,
      "y": 3,
      "z": 0,
      "name": "Rock_Shale"
    },
    {
      "x": -9,
      "y": 4,
      "z": 0,
      "name": "Rock_Shale"
    },
    {
      "x": -9,
      "y": 5,
      "z": 0,
      "name": "Rock_Shale"
    },
    {
      "x": -9,
      "y": 6,
      "z": 0,
      "name": "Rock_Shale"
    },
    {
      "x": -9,
      "y": 7,
      "z": 0,
      "name": "Rock_Shale"
    },
    {
      "x": -9,
      "y": 8,
      "z": 0,
      "name": "Rock_Shale"
    },
    {
      "x": -9,
      "y": 9,
      "z": 0,
      "name": "Rock_Shale"
    },
    {
      "x": -9,
      "y": 10,
      "z": 0,
      "name": "Rock_Shale"
    },
    {
      "x": -9,
      "y": 11,
      "z": 0,
      "name": "Rock_Shale"
    },
    {
      "x": -9,
      "y": 12,
      "z": 0,
      "name": "Rock_Shale"
    },
    {
      "x": -9,
      "y": 13,
      "z": 0,
      "name": "Rock_Shale"
    },
    {
      "x": -9,
      "y": 14,
      "z": 0,
      "name": "Rock_Shale"
    },
    {
      "x": -9,
      "y": 15,
      "z": 0,
      "name": "Rock_Shale"
    },
    {
      "x": -9,
      "y": 16,
      "z": 0,
      "name": "Rock_Shale"
    },
    {
      "x": -9,
      "y": 17,
      "z": 0,
      "name": "Rock_Shale_Cobble"
    },
    {
      "x": -9,
      "y": 18,
      "z": 0,
      "name": "Rock_Shale_Brick"
    },
    {
      "x": -9,
      "y": 19,
      "z": 0,
      "name": "Rock_Shale_Brick"
    },
    {
      "x": -9,
      "y": 20,
      "z": 0,
      "name": "Rock_Shale_Brick"
    },
    {
      "x": -9,
      "y": 21,
      "z": 0,
      "name": "Rock_Shale_Brick"
    },
    {
      "x": -9,
      "y": 22,
      "z": 0,
      "name": "Soil_Snow"
    },
    {
      "x": -9,
      "y": 3,
      "z": 1,
      "name": "Rock_Shale"
    },
    {
      "x": -9,
      "y": 4,
      "z": 1,
      "name": "Rock_Shale"
    },
    {
      "x": -9,
      "y": 5,
      "z": 1,
      "name": "Rock_Shale"
    },
    {
      "x": -9,
      "y": 6,
      "z": 1,
      "name": "Rock_Shale"
    },
    {
      "x": -9,
      "y": 7,
      "z": 1,
      "name": "Rock_Shale"
    },
    {
      "x": -9,
      "y": 8,
      "z": 1,
      "name": "Rock_Shale"
    },
    {
      "x": -9,
      "y": 9,
      "z": 1,
      "name": "Rock_Shale"
    },
    {
      "x": -9,
      "y": 10,
      "z": 1,
      "name": "Rock_Shale"
    },
    {
      "x": -9,
      "y": 11,
      "z": 1,
      "name": "Rock_Shale"
    },
    {
      "x": -9,
      "y": 12,
      "z": 1,
      "name": "Rock_Shale"
    },
    {
      "x": -9,
      "y": 13,
      "z": 1,
      "name": "Rock_Shale"
    },
    {
      "x": -9,
      "y": 14,
      "z": 1,
      "name": "Rock_Shale"
    },
    {
      "x": -9,
      "y": 15,
      "z": 1,
      "name": "Rock_Shale"
    },
    {
      "x": -9,
      "y": 16,
      "z": 1,
      "name": "Rock_Shale"
    },
    {
      "x": -9,
      "y": 17,
      "z": 1,
      "name": "Rock_Shale"
    },
    {
      "x": -9,
      "y": 18,
      "z": 1,
      "name": "Rock_Shale"
    },
    {
      "x": -9,
      "y": 19,
      "z": 1,
      "name": "Rock_Shale_Brick"
    },
    {
      "x": -9,
      "y": 20,
      "z": 1,
      "name": "Rock_Shale_Brick"
    },
    {
      "x": -9,
      "y": 21,
      "z": 1,
      "name": "Rock_Shale_Brick"
    },
    {
      "x": -9,
      "y": 22,
      "z": 1,
      "name": "Soil_Snow"
    },
    {
      "x": -9,
      "y": 3,
      "z": 2,
      "name": "Rock_Shale"
    },
    {
      "x": -9,
      "y": 4,
      "z": 2,
      "name": "Rock_Shale"
    },
    {
      "x": -9,
      "y": 5,
      "z": 2,
      "name": "Rock_Shale"
    },
    {
      "x": -9,
      "y": 6,
      "z": 2,
      "name": "Rock_Shale"
    },
    {
      "x": -9,
      "y": 7,
      "z": 2,
      "name": "Rock_Shale"
    },
    {
      "x": -9,
      "y": 8,
      "z": 2,
      "name": "Rock_Shale"
    },
    {
      "x": -9,
      "y": 9,
      "z": 2,
      "name": "Rock_Shale"
    },
    {
      "x": -9,
      "y": 10,
      "z": 2,
      "name": "Rock_Shale"
    },
    {
      "x": -9,
      "y": 11,
      "z": 2,
      "name": "Rock_Shale"
    },
    {
      "x": -9,
      "y": 12,
      "z": 2,
      "name": "Rock_Shale"
    },
    {
      "x": -9,
      "y": 13,
      "z": 2,
      "name": "Rock_Shale"
    },
    {
      "x": -9,
      "y": 14,
      "z": 2,
      "name": "Rock_Shale"
    },
    {
      "x": -9,
      "y": 15,
      "z": 2,
      "name": "Rock_Shale"
    },
    {
      "x": -9,
      "y": 16,
      "z": 2,
      "name": "Rock_Shale_Cobble"
    },
    {
      "x": -9,
      "y": 17,
      "z": 2,
      "name": "Rock_Shale"
    },
    {
      "x": -9,
      "y": 18,
      "z": 2,
      "name": "Rock_Shale"
    },
    {
      "x": -9,
      "y": 19,
      "z": 2,
      "name": "Rock_Shale_Brick"
    },
    {
      "x": -9,
      "y": 20,
      "z": 2,
      "name": "Rock_Shale_Brick"
    },
    {
      "x": -9,
      "y": 21,
      "z": 2,
      "name": "Rock_Shale_Brick"
    },
    {
      "x": -9,
      "y": 22,
      "z": 2,
      "name": "Soil_Snow"
    },
    {
      "x": -9,
      "y": 3,
      "z": 3,
      "name": "Rock_Shale"
    },
    {
      "x": -9,
      "y": 4,
      "z": 3,
      "name": "Rock_Shale"
    },
    {
      "x": -9,
      "y": 5,
      "z": 3,
      "name": "Rock_Shale"
    },
    {
      "x": -9,
      "y": 6,
      "z": 3,
      "name": "Rock_Shale"
    },
    {
      "x": -9,
      "y": 7,
      "z": 3,
      "name": "Rock_Shale"
    },
    {
      "x": -9,
      "y": 8,
      "z": 3,
      "name": "Rock_Shale"
    },
    {
      "x": -9,
      "y": 9,
      "z": 3,
      "name": "Rock_Shale"
    },
    {
      "x": -9,
      "y": 10,
      "z": 3,
      "name": "Rock_Shale"
    },
    {
      "x": -9,
      "y": 11,
      "z": 3,
      "name": "Rock_Shale"
    },
    {
      "x": -9,
      "y": 12,
      "z": 3,
      "name": "Rock_Shale"
    },
    {
      "x": -9,
      "y": 13,
      "z": 3,
      "name": "Rock_Shale"
    },
    {
      "x": -9,
      "y": 14,
      "z": 3,
      "name": "Rock_Shale"
    },
    {
      "x": -9,
      "y": 15,
      "z": 3,
      "name": "Rock_Shale_Cobble"
    },
    {
      "x": -9,
      "y": 16,
      "z": 3,
      "name": "Rock_Shale_Cobble"
    },
    {
      "x": -9,
      "y": 17,
      "z": 3,
      "name": "Rock_Shale_Cobble"
    },
    {
      "x": -9,
      "y": 18,
      "z": 3,
      "name": "Rock_Shale_Brick"
    },
    {
      "x": -9,
      "y": 19,
      "z": 3,
      "name": "Rock_Shale_Brick"
    },
    {
      "x": -9,
      "y": 20,
      "z": 3,
      "name": "Rock_Shale_Brick"
    },
    {
      "x": -9,
      "y": 21,
      "z": 3,
      "name": "Rock_Shale_Brick"
    },
    {
      "x": -9,
      "y": 22,
      "z": 3,
      "name": "Soil_Snow"
    },
    {
      "x": -9,
      "y": 3,
      "z": 4,
      "name": "Rock_Shale"
    },
    {
      "x": -9,
      "y": 4,
      "z": 4,
      "name": "Rock_Shale"
    },
    {
      "x": -9,
      "y": 5,
      "z": 4,
      "name": "Rock_Shale"
    },
    {
      "x": -9,
      "y": 6,
      "z": 4,
      "name": "Rock_Shale"
    },
    {
      "x": -9,
      "y": 7,
      "z": 4,
      "name": "Rock_Shale"
    },
    {
      "x": -9,
      "y": 8,
      "z": 4,
      "name": "Rock_Shale"
    },
    {
      "x": -9,
      "y": 9,
      "z": 4,
      "name": "Rock_Shale"
    },
    {
      "x": -9,
      "y": 10,
      "z": 4,
      "name": "Rock_Shale"
    },
    {
      "x": -9,
      "y": 11,
      "z": 4,
      "name": "Rock_Shale"
    },
    {
      "x": -9,
      "y": 12,
      "z": 4,
      "name": "Rock_Shale"
    },
    {
      "x": -9,
      "y": 13,
      "z": 4,
      "name": "Rock_Shale"
    },
    {
      "x": -9,
      "y": 14,
      "z": 4,
      "name": "Rock_Shale_Cobble"
    },
    {
      "x": -9,
      "y": 15,
      "z": 4,
      "name": "Rock_Shale_Cobble"
    },
    {
      "x": -9,
      "y": 16,
      "z": 4,
      "name": "Rock_Shale_Cobble"
    },
    {
      "x": -9,
      "y": 17,
      "z": 4,
      "name": "Rock_Shale_Brick"
    },
    {
      "x": -9,
      "y": 18,
      "z": 4,
      "name": "Rock_Shale_Brick"
    },
    {
      "x": -9,
      "y": 19,
      "z": 4,
      "name": "Rock_Shale_Brick"
    },
    {
      "x": -9,
      "y": 20,
      "z": 4,
      "name": "Rock_Shale_Brick"
    },
    {
      "x": -9,
      "y": 21,
      "z": 4,
      "name": "Rock_Shale_Brick"
    },
    {
      "x": -9,
      "y": 22,
      "z": 4,
      "name": "Soil_Snow"
    },
    {
      "x": -8,
      "y": 3,
      "z": 0,
      "name": "Rock_Shale"
    },
    {
      "x": -8,
      "y": 4,
      "z": 0,
      "name": "Rock_Shale"
    },
    {
      "x": -8,
      "y": 5,
      "z": 0,
      "name": "Rock_Shale"
    },
    {
      "x": -8,
      "y": 6,
      "z": 0,
      "name": "Rock_Shale"
    },
    {
      "x": -8,
      "y": 7,
      "z": 0,
      "name": "Rock_Shale"
    },
    {
      "x": -8,
      "y": 8,
      "z": 0,
      "name": "Rock_Shale"
    },
    {
      "x": -8,
      "y": 9,
      "z": 0,
      "name": "Rock_Shale"
    },
    {
      "x": -8,
      "y": 10,
      "z": 0,
      "name": "Rock_Shale"
    },
    {
      "x": -8,
      "y": 11,
      "z": 0,
      "name": "Rock_Shale"
    },
    {
      "x": -8,
      "y": 12,
      "z": 0,
      "name": "Rock_Shale"
    },
    {
      "x": -8,
      "y": 13,
      "z": 0,
      "name": "Rock_Shale"
    },
    {
      "x": -8,
      "y": 14,
      "z": 0,
      "name": "Rock_Shale"
    },
    {
      "x": -8,
      "y": 15,
      "z": 0,
      "name": "Rock_Shale"
    },
    {
      "x": -8,
      "y": 16,
      "z": 0,
      "name": "Rock_Shale_Cobble"
    },
    {
      "x": -8,
      "y": 17,
      "z": 0,
      "name": "Rock_Shale_Cobble"
    },
    {
      "x": -8,
      "y": 18,
      "z": 0,
      "name": "Rock_Shale_Cobble"
    },
    {
      "x": -8,
      "y": 19,
      "z": 0,
      "name": "Rock_Shale_Brick"
    },
    {
      "x": -8,
      "y": 20,
      "z": 0,
      "name": "Rock_Shale_Brick"
    },
    {
      "x": -8,
      "y": 21,
      "z": 0,
