{
  "version": 8,
  "blockIdVersion": 8,
  "anchorX": 13,
  "anchorY": 14,
  "anchorZ": 9,
  "blocks": [
    {
      "x": 5,
      "y": 16,
      "z": 9,
      "name": "Rock_Shale"
    },
    {
      "x": 5,
      "y": 14,
      "z": 10,
      "name": "Rock_Shale"
    },
    {
      "x": 5,
      "y": 15,
      "z": 10,
      "name": "Rock_Shale"
    },
    {
      "x": 5,
      "y": 16,
      "z": 10,
      "name": "Rock_Shale"
    },
    {
      "x": 5,
      "y": 17,
      "z": 10,
      "name": "Rock_Shale"
    },
    {
      "x": 5,
      "y": 13,
      "z": 11,
      "name": "Rock_Shale"
    },
    {
      "x": 5,
      "y": 14,
      "z": 11,
      "name": "Rock_Shale"
    },
    {
      "x": 5,
      "y": 15,
      "z": 11,
      "name": "Rock_Shale"
    },
    {
      "x": 5,
      "y": 16,
      "z": 11,
      "name": "Rock_Shale"
    },
    {
      "x": 5,
      "y": 17,
      "z": 11,
      "name": "Rock_Shale"
    },
    {
      "x": 5,
      "y": 18,
      "z": 11,
      "name": "Rock_Shale"
    },
    {
      "x": 5,
      "y": 19,
      "z": 11,
      "name": "Rock_Shale"
    },
    {
      "x": 5,
      "y": 15,
      "z": 12,
      "name": "Rock_Shale"
    },
    {
      "x": 5,
      "y": 16,
      "z": 12,
      "name": "Rock_Shale"
    },
    {
      "x": 5,
      "y": 17,
      "z": 12,
      "name": "Rock_Shale"
    },
    {
      "x": 5,
      "y": 18,
      "z": 12,
      "name": "Rock_Shale"
    },
    {
      "x": 6,
      "y": 13,
      "z": 9,
      "name": "Rock_Shale"
    },
    {
      "x": 6,
      "y": 14,
      "z": 9,
      "name": "Rock_Shale"
    },
    {
      "x": 6,
      "y": 15,
      "z": 9,
      "name": "Rock_Shale"
    },
    {
      "x": 6,
      "y": 16,
      "z": 9,
      "name": "Rock_Shale"
    },
    {
      "x": 6,
      "y": 12,
      "z": 10,
      "name": "Rock_Shale"
    },
    {
      "x": 6,
      "y": 13,
      "z": 10,
      "name": "Rock_Shale"
    },
    {
      "x": 6,
      "y": 14,
      "z": 10,
      "name": "Rock_Shale"
    },
    {
      "x": 6,
      "y": 15,
      "z": 10,
      "name": "Rock_Shale"
    },
    {
      "x": 6,
      "y": 16,
      "z": 10,
      "name": "Rock_Shale"
    },
    {
      "x": 6,
      "y": 17,
      "z": 10,
      "name": "Rock_Shale"
    },
    {
      "x": 6,
      "y": 18,
      "z": 10,
      "name": "Rock_Shale"
    },
    {
      "x": 6,
      "y": 19,
      "z": 10,
      "name": "Rock_Shale"
    },
    {
      "x": 6,
      "y": 20,
      "z": 10,
      "name": "Soil_Grass"
    },
    {
      "x": 6,
      "y": 12,
      "z": 11,
      "name": "Rock_Shale"
    },
    {
      "x": 6,
      "y": 13,
      "z": 11,
      "name": "Rock_Shale"
    },
    {
      "x": 6,
      "y": 14,
      "z": 11,
      "name": "Rock_Shale"
    },
    {
      "x": 6,
      "y": 15,
      "z": 11,
      "name": "Rock_Shale"
    },
    {
      "x": 6,
      "y": 16,
      "z": 11,
      "name": "Rock_Shale"
    },
    {
      "x": 6,
      "y": 17,
      "z": 11,
      "name": "Rock_Shale"
    },
    {
      "x": 6,
      "y": 18,
      "z": 11,
      "name": "Rock_Shale"
    },
    {
      "x": 6,
      "y": 19,
      "z": 11,
      "name": "Soil_Dirt"
    },
    {
      "x": 6,
      "y": 20,
      "z": 11,
      "name": "Soil_Dirt"
    },
    {
      "x": 6,
      "y": 21,
      "z": 11,
      "name": "Soil_Grass"
    },
    {
      "x": 6,
      "y": 22,
      "z": 11,
      "name": "Plant_Grass_Sharp_Tall"
    },
    {
      "x": 6,
      "y": 23,
      "z": 11,
      "name": "Plant_Grass_Sharp_Tall",
      "filler": 1024
    },
    {
      "x": 6,
      "y": 14,
      "z": 12,
      "name": "Rock_Shale"
    },
    {
      "x": 6,
      "y": 15,
      "z": 12,
      "name": "Rock_Shale"
    },
    {
      "x": 6,
      "y": 16,
      "z": 12,
      "name": "Rock_Shale"
    },
    {
      "x": 6,
      "y": 17,
      "z": 12,
      "name": "Rock_Shale"
    },
    {
      "x": 6,
      "y": 18,
      "z": 12,
      "name": "Rock_Shale"
    },
    {
      "x": 6,
      "y": 19,
      "z": 12,
      "name": "Rock_Shale"
    },
    {
      "x": 6,
      "y": 16,
      "z": 13,
      "name": "Rock_Shale"
    },
    {
      "x": 7,
      "y": 12,
      "z": 9,
      "name": "Rock_Shale"
    },
    {
      "x": 7,
      "y": 13,
      "z": 9,
      "name": "Rock_Shale"
    },
    {
      "x": 7,
      "y": 19,
      "z": 9,
      "name": "Rock_Shale"
    },
    {
      "x": 7,
      "y": 20,
      "z": 9,
      "name": "Rock_Shale"
    },
    {
      "x": 7,
      "y": 21,
      "z": 9,
      "name": "Soil_Dirt"
    },
    {
      "x": 7,
      "y": 22,
      "z": 9,
      "name": "Soil_Pathway"
    },
    {
      "x": 7,
      "y": 11,
      "z": 10,
      "name": "Rock_Shale"
    },
    {
      "x": 7,
      "y": 12,
      "z": 10,
      "name": "Rock_Shale"
    },
    {
      "x": 7,
      "y": 13,
      "z": 10,
      "name": "Rock_Shale"
    },
    {
      "x": 7,
      "y": 14,
      "z": 10,
      "name": "Rock_Shale"
    },
    {
      "x": 7,
      "y": 15,
      "z": 10,
      "name": "Rock_Shale"
    },
    {
      "x": 7,
      "y": 16,
      "z": 10,
      "name": "Rock_Shale"
    },
    {
      "x": 7,
      "y": 17,
      "z": 10,
      "name": "Rock_Shale"
    },
    {
      "x": 7,
      "y": 18,
      "z": 10,
      "name": "Rock_Shale"
    },
    {
      "x": 7,
      "y": 19,
      "z": 10,
      "name": "Rock_Shale"
    },
    {
      "x": 7,
      "y": 20,
      "z": 10,
      "name": "Soil_Dirt"
    },
    {
      "x": 7,
      "y": 21,
      "z": 10,
      "name": "Soil_Dirt"
    },
    {
      "x": 7,
      "y": 22,
      "z": 10,
      "name": "Soil_Pathway"
    },
    {
      "x": 7,
      "y": 23,
      "z": 10,
      "name": "Plant_Bush_Winter_Red"
    },
    {
      "x": 7,
      "y": 11,
      "z": 11,
      "name": "Rock_Shale"
    },
    {
      "x": 7,
      "y": 12,
      "z": 11,
      "name": "Rock_Shale"
    },
    {
      "x": 7,
      "y": 13,
      "z": 11,
      "name": "Rock_Shale"
    },
    {
      "x": 7,
      "y": 14,
      "z": 11,
      "name": "Rock_Shale"
    },
    {
      "x": 7,
      "y": 15,
      "z": 11,
      "name": "Rock_Shale"
    },
    {
      "x": 7,
      "y": 16,
      "z": 11,
      "name": "Rock_Shale"
    },
    {
      "x": 7,
      "y": 17,
      "z": 11,
      "name": "Rock_Shale"
    },
    {
      "x": 7,
      "y": 18,
      "z": 11,
      "name": "Rock_Shale"
    },
    {
      "x": 7,
      "y": 19,
      "z": 11,
      "name": "Rock_Shale"
    },
    {
      "x": 7,
      "y": 20,
      "z": 11,
      "name": "Soil_Dirt"
    },
    {
      "x": 7,
      "y": 21,
      "z": 11,
      "name": "Soil_Grass"
    },
    {
      "x": 7,
      "y": 11,
      "z": 12,
      "name": "Rock_Shale"
    },
    {
      "x": 7,
      "y": 12,
      "z": 12,
      "name": "Rock_Shale"
    },
    {
      "x": 7,
      "y": 13,
      "z": 12,
      "name": "Rock_Shale"
    },
    {
      "x": 7,
      "y": 14,
      "z": 12,
      "name": "Rock_Shale"
    },
    {
      "x": 7,
      "y": 15,
      "z": 12,
      "name": "Rock_Shale"
    },
    {
      "x": 7,
      "y": 16,
      "z": 12,
      "name": "Rock_Shale"
    },
    {
      "x": 7,
      "y": 17,
      "z": 12,
      "name": "Rock_Shale"
    },
    {
      "x": 7,
      "y": 18,
      "z": 12,
      "name": "Rock_Shale"
    },
    {
      "x": 7,
      "y": 14,
      "z": 13,
      "name": "Rock_Shale"
    },
    {
      "x": 7,
      "y": 15,
      "z": 13,
      "name": "Rock_Shale"
    },
    {
      "x": 7,
      "y": 16,
      "z": 13,
      "name": "Rock_Shale"
    },
    {
      "x": 8,
      "y": 17,
      "z": 4,
      "name": "Rock_Shale"
    },
    {
      "x": 8,
      "y": 18,
      "z": 4,
      "name": "Rock_Shale"
    },
    {
      "x": 8,
      "y": 15,
      "z": 5,
      "name": "Rock_Shale"
    },
    {
      "x": 8,
      "y": 16,
      "z": 5,
      "name": "Rock_Shale"
    },
    {
      "x": 8,
      "y": 17,
      "z": 5,
      "name": "Rock_Shale"
    },
    {
      "x": 8,
      "y": 18,
      "z": 5,
      "name": "Rock_Shale"
    },
    {
      "x": 8,
      "y": 19,
      "z": 5,
      "name": "Rock_Shale"
    },
    {
      "x": 8,
      "y": 20,
      "z": 5,
      "name": "Soil_Dirt"
    },
    {
      "x": 8,
      "y": 21,
      "z": 5,
      "name": "Soil_Grass"
    },
    {
      "x": 8,
      "y": 22,
      "z": 5,
      "name": "Plant_Grass_Sharp_Tall"
    },
    {
      "x": 8,
      "y": 23,
      "z": 5,
      "name": "Plant_Grass_Sharp_Tall",
      "filler": 1024
    },
    {
      "x": 8,
      "y": 14,
      "z": 6,
      "name": "Rock_Shale"
    },
    {
      "x": 8,
      "y": 15,
      "z": 6,
      "name": "Rock_Shale"
    },
    {
      "x": 8,
      "y": 16,
      "z": 6,
      "name": "Rock_Shale"
    },
    {
      "x": 8,
      "y": 21,
      "z": 8,
      "name": "Rock_Shale"
    },
    {
      "x": 8,
      "y": 22,
      "z": 8,
      "name": "Rock_Shale"
    },
    {
      "x": 8,
      "y": 23,
      "z": 8,
      "name": "Soil_Pathway"
    },
    {
      "x": 8,
      "y": 10,
      "z": 9,
      "name": "Rock_Shale"
    },
    {
      "x": 8,
      "y": 11,
      "z": 9,
      "name": "Rock_Shale"
    },
    {
      "x": 8,
      "y": 12,
      "z": 9,
      "name": "Rock_Shale"
    },
    {
      "x": 8,
      "y": 19,
      "z": 9,
      "name": "Rock_Shale"
    },
    {
      "x": 8,
      "y": 20,
      "z": 9,
      "name": "Rock_Shale"
    },
    {
      "x": 8,
      "y": 21,
      "z": 9,
      "name": "Soil_Dirt"
    },
    {
      "x": 8,
      "y": 22,
      "z": 9,
      "name": "Soil_Pathway"
    },
    {
      "x": 8,
      "y": 23,
      "z": 9,
      "name": "Soil_Pathway"
    },
    {
      "x": 8,
      "y": 10,
      "z": 10,
      "name": "Rock_Shale"
    },
    {
      "x": 8,
      "y": 11,
      "z": 10,
      "name": "Rock_Shale"
    },
    {
      "x": 8,
      "y": 12,
      "z": 10,
      "name": "Rock_Shale"
    },
    {
      "x": 8,
      "y": 13,
      "z": 10,
      "name": "Rock_Shale"
    },
    {
      "x": 8,
      "y": 14,
      "z": 10,
      "name": "Rock_Shale"
    },
    {
      "x": 8,
      "y": 18,
      "z": 10,
      "name": "Rock_Shale"
    },
    {
      "x": 8,
      "y": 19,
      "z": 10,
      "name": "Rock_Shale"
    },
    {
      "x": 8,
      "y": 20,
      "z": 10,
      "name": "Rock_Shale"
    },
    {
      "x": 8,
      "y": 21,
      "z": 10,
      "name": "Soil_Pathway"
    },
    {
      "x": 8,
      "y": 22,
      "z": 10,
      "name": "Soil_Pathway"
    },
    {
      "x": 8,
      "y": 23,
      "z": 10,
      "name": "Soil_Pathway"
    },
    {
      "x": 8,
      "y": 10,
      "z": 11,
      "name": "Rock_Shale"
    },
    {
      "x": 8,
      "y": 11,
      "z": 11,
      "name": "Rock_Shale"
    },
    {
      "x": 8,
      "y": 12,
      "z": 11,
      "name": "Rock_Shale"
    },
    {
      "x": 8,
      "y": 13,
      "z": 11,
      "name": "Rock_Shale"
    },
    {
      "x": 8,
      "y": 14,
      "z": 11,
      "name": "Rock_Shale"
    },
    {
      "x": 8,
      "y": 15,
      "z": 11,
      "name": "Rock_Shale"
    },
    {
      "x": 8,
      "y": 16,
      "z": 11,
      "name": "Rock_Shale"
    },
    {
      "x": 8,
      "y": 18,
      "z": 11,
      "name": "Rock_Shale"
    },
    {
      "x": 8,
      "y": 19,
      "z": 11,
      "name": "Rock_Shale"
    },
    {
      "x": 8,
      "y": 20,
      "z": 11,
      "name": "Soil_Grass"
    },
    {
      "x": 8,
      "y": 21,
      "z": 11,
      "name": "Plant_Bush_Winter_Red"
    },
    {
      "x": 8,
      "y": 11,
      "z": 12,
      "name": "Rock_Shale"
    },
    {
      "x": 8,
      "y": 12,
      "z": 12,
      "name": "Rock_Shale"
    },
    {
      "x": 8,
      "y": 13,
      "z": 12,
      "name": "Rock_Shale"
    },
    {
      "x": 8,
      "y": 14,
      "z": 12,
      "name": "Rock_Shale"
    },
    {
      "x": 8,
      "y": 15,
      "z": 12,
      "name": "Rock_Shale"
    },
    {
      "x": 8,
      "y": 12,
      "z": 13,
      "name": "Rock_Shale"
    },
    {
      "x": 8,
      "y": 13,
      "z": 13,
      "name": "Rock_Shale"
    },
    {
      "x": 9,
      "y": 18,
      "z": 3,
      "name": "Rock_Shale"
    },
    {
      "x": 9,
      "y": 19,
      "z": 3,
      "name": "Rock_Shale"
    },
    {
      "x": 9,
      "y": 15,
      "z": 4,
      "name": "Rock_Shale"
    },
    {
      "x": 9,
      "y": 16,
      "z": 4,
      "name": "Rock_Shale"
    },
    {
      "x": 9,
      "y": 17,
      "z": 4,
      "name": "Rock_Shale"
    },
    {
      "x": 9,
      "y": 18,
      "z": 4,
      "name": "Rock_Shale"
    },
    {
      "x": 9,
      "y": 19,
      "z": 4,
      "name": "Soil_Dirt"
    },
    {
      "x": 9,
      "y": 20,
      "z": 4,
      "name": "Soil_Dirt"
    },
    {
      "x": 9,
      "y": 21,
      "z": 4,
      "name": "Soil_Dirt"
    },
    {
      "x": 9,
      "y": 22,
      "z": 4,
      "name": "Soil_Grass"
    },
    {
      "x": 9,
      "y": 13,
      "z": 5,
      "name": "Rock_Shale"
    },
    {
      "x": 9,
      "y": 14,
      "z": 5,
      "name": "Rock_Shale"
    },
    {
      "x": 9,
      "y": 15,
      "z": 5,
      "name": "Rock_Shale"
    },
    {
      "x": 9,
      "y": 16,
      "z": 5,
      "name": "Rock_Shale"
    },
    {
      "x": 9,
      "y": 17,
      "z": 5,
      "name": "Rock_Shale"
    },
    {
      "x": 9,
      "y": 18,
      "z": 5,
      "name": "Rock_Shale"
    },
    {
      "x": 9,
      "y": 19,
      "z": 5,
      "name": "Rock_Shale"
    },
    {
      "x": 9,
      "y": 20,
      "z": 5,
      "name": "Soil_Dirt"
    },
    {
      "x": 9,
      "y": 21,
      "z": 5,
      "name": "Soil_Dirt"
    },
    {
      "x": 9,
      "y": 22,
      "z": 5,
      "name": "Soil_Grass"
    },
    {
      "x": 9,
      "y": 23,
      "z": 5,
      "name": "Plant_Grass_Sharp_Tall"
    },
    {
      "x": 9,
      "y": 24,
      "z": 5,
      "name": "Plant_Grass_Sharp_Tall",
      "filler": 1024
    },
    {
      "x": 9,
      "y": 12,
      "z": 6,
      "name": "Rock_Shale"
    },
    {
      "x": 9,
      "y": 13,
      "z": 6,
      "name": "Rock_Shale"
    },
    {
      "x": 9,
      "y": 14,
      "z": 6,
      "name": "Rock_Shale"
    },
    {
      "x": 9,
      "y": 15,
      "z": 6,
      "name": "Rock_Shale"
    },
    {
      "x": 9,
      "y": 16,
      "z": 6,
      "name": "Rock_Shale"
    },
    {
      "x": 9,
      "y": 17,
      "z": 6,
      "name": "Rock_Shale"
    },
    {
      "x": 9,
      "y": 18,
      "z": 6,
      "name": "Rock_Shale"
    },
    {
      "x": 9,
      "y": 19,
      "z": 6,
      "name": "Rock_Shale"
    },
    {
      "x": 9,
      "y": 20,
      "z": 6,
      "name": "Rock_Shale"
    },
    {
      "x": 9,
      "y": 21,
      "z": 6,
      "name": "Soil_Dirt"
    },
    {
      "x": 9,
      "y": 22,
      "z": 6,
      "name": "Soil_Grass"
    },
    {
      "x": 9,
      "y": 11,
      "z": 7,
      "name": "Rock_Shale"
    },
    {
      "x": 9,
      "y": 12,
      "z": 7,
      "name": "Rock_Shale"
    },
    {
      "x": 9,
      "y": 13,
      "z": 7,
      "name": "Rock_Shale"
    },
    {
      "x": 9,
      "y": 14,
      "z": 7,
      "name": "Rock_Shale"
    },
    {
      "x": 9,
      "y": 22,
      "z": 7,
      "name": "Soil_Grass"
    },
    {
      "x": 9,
      "y": 23,
      "z": 7,
      "name": "Plant_Grass_Sharp_Tall"
    },
    {
      "x": 9,
      "y": 24,
      "z": 7,
      "name": "Plant_Grass_Sharp_Tall",
      "filler": 1024
    },
    {
      "x": 9,
      "y": 11,
      "z": 8,
      "name": "Rock_Shale"
    },
    {
      "x": 9,
      "y": 21,
      "z": 8,
      "name": "Rock_Shale"
    },
    {
      "x": 9,
      "y": 22,
      "z": 8,
      "name": "Rock_Shale"
    },
    {
      "x": 9,
      "y": 23,
      "z": 8,
      "name": "Soil_Dirt"
    },
    {
      "x": 9,
      "y": 24,
      "z": 8,
      "name": "Soil_Grass"
    },
    {
      "x": 9,
      "y": 25,
      "z": 8,
      "name": "Plant_Grass_Sharp_Tall"
    },
    {
      "x": 9,
      "y": 26,
      "z": 8,
      "name": "Plant_Grass_Sharp_Tall",
      "filler": 1024
    },
    {
      "x": 9,
      "y": 10,
      "z": 9,
      "name": "Rock_Shale"
    },
    {
      "x": 9,
      "y": 11,
      "z": 9,
      "name": "Rock_Shale"
    },
    {
      "x": 9,
      "y": 20,
      "z": 9,
      "name": "Rock_Shale"
    },
    {
      "x": 9,
      "y": 21,
      "z": 9,
      "name": "Rock_Shale"
    },
    {
      "x": 9,
      "y": 22,
      "z": 9,
      "name": "Soil_Pathway"
    },
    {
      "x": 9,
      "y": 23,
      "z": 9,
      "name": "Soil_Pathway"
    },
    {
      "x": 9,
      "y": 24,
      "z": 9,
      "name": "Soil_Pathway"
    },
    {
      "x": 9,
      "y": 9,
      "z": 10,
      "name": "Rock_Shale"
    },
    {
      "x": 9,
      "y": 10,
      "z": 10,
      "name": "Rock_Shale"
    },
    {
      "x": 9,
      "y": 11,
      "z": 10,
      "name": "Rock_Shale"
    },
    {
      "x": 9,
      "y": 12,
      "z": 10,
      "name": "Rock_Shale"
    },
    {
      "x": 9,
      "y": 20,
      "z": 10,
      "name": "Rock_Shale"
    },
    {
      "x": 9,
      "y": 21,
      "z": 10,
      "name": "Rock_Shale"
    },
    {
      "x": 9,
      "y": 22,
      "z": 10,
      "name": "Soil_Pathway"
    },
    {
      "x": 9,
      "y": 9,
      "z": 11,
      "name": "Rock_Shale"
    },
    {
      "x": 9,
      "y": 10,
      "z": 11,
      "name": "Rock_Shale"
    },
    {
      "x": 9,
      "y": 11,
      "z": 11,
      "name": "Rock_Shale"
    },
    {
      "x": 9,
      "y": 12,
      "z": 11,
      "name": "Rock_Shale"
    },
    {
      "x": 9,
      "y": 13,
      "z": 11,
      "name": "Rock_Shale"
    },
    {
      "x": 9,
      "y": 11,
      "z": 12,
      "name": "Rock_Shale"
    },
    {
      "x": 9,
      "y": 12,
      "z": 12,
      "name": "Rock_Shale"
    },
    {
      "x": 9,
      "y": 13,
      "z": 12,
      "name": "Rock_Shale"
    },
    {
      "x": 10,
      "y": 16,
      "z": 3,
      "name": "Rock_Shale"
    },
    {
      "x": 10,
      "y": 17,
      "z": 3,
      "name": "Rock_Shale"
    },
    {
      "x": 10,
      "y": 18,
      "z": 3,
      "name": "Rock_Shale"
    },
    {
      "x": 10,
      "y": 19,
      "z": 3,
      "name": "Soil_Dirt"
    },
    {
      "x": 10,
      "y": 20,
      "z": 3,
      "name": "Soil_Dirt"
    },
    {
      "x": 10,
      "y": 21,
      "z": 3,
      "name": "Soil_Grass"
    },
    {
      "x": 10,
      "y": 16,
      "z": 4,
      "name": "Rock_Shale"
    },
    {
      "x": 10,
      "y": 17,
      "z": 4,
      "name": "Rock_Shale"
    },
    {
      "x": 10,
      "y": 18,
      "z": 4,
      "name": "Rock_Shale"
    },
    {
      "x": 10,
      "y": 19,
      "z": 4,
      "name": "Rock_Shale"
    },
    {
      "x": 10,
      "y": 20,
      "z": 4,
      "name": "Soil_Dirt"
    },
    {
      "x": 10,
      "y": 21,
      "z": 4,
      "name": "Soil_Dirt"
    },
    {
      "x": 10,
      "y": 22,
      "z": 4,
      "name": "Soil_Grass"
    },
    {
      "x": 10,
      "y": 13,
      "z": 5,
      "name": "Rock_Shale"
    },
    {
      "x": 10,
      "y": 14,
      "z": 5,
      "name": "Rock_Shale"
    },
    {
      "x": 10,
      "y": 15,
      "z": 5,
      "name": "Rock_Shale"
    },
    {
      "x": 10,
      "y": 16,
      "z": 5,
      "name": "Rock_Shale"
    },
    {
      "x": 10,
      "y": 17,
      "z": 5,
      "name": "Rock_Shale"
    },
    {
      "x": 10,
      "y": 18,
      "z": 5,
      "name": "Rock_Shale"
    },
    {
      "x": 10,
      "y": 19,
      "z": 5,
      "name": "Rock_Shale"
    },
    {
      "x": 10,
      "y": 20,
      "z": 5,
      "name": "Soil_Dirt"
    },
    {
      "x": 10,
      "y": 21,
      "z": 5,
      "name": "Soil_Dirt"
    },
    {
      "x": 10,
      "y": 22,
      "z": 5,
      "name": "Soil_Dirt"
    },
    {
      "x": 10,
      "y": 23,
      "z": 5,
      "name": "Soil_Grass"
    },
    {
      "x": 10,
      "y": 12,
      "z": 6,
      "name": "Rock_Shale"
    },
    {
      "x": 10,
      "y": 13,
      "z": 6,
      "name": "Rock_Shale"
    },
    {
      "x": 10,
      "y": 14,
      "z": 6,
      "name": "Rock_Shale"
    },
    {
      "x": 10,
      "y": 15,
      "z": 6,
      "name": "Rock_Shale"
    },
    {
      "x": 10,
      "y": 19,
      "z": 6,
      "name": "Rock_Shale"
    },
    {
      "x": 10,
      "y": 20,
      "z": 6,
      "name": "Rock_Shale"
    },
    {
      "x": 10,
      "y": 21,
      "z": 6,
      "name": "Soil_Dirt"
    },
    {
      "x": 10,
      "y": 22,
      "z": 6,
      "name": "Soil_Dirt"
    },
    {
      "x": 10,
      "y": 23,
      "z": 6,
      "name": "Soil_Snow"
    },
    {
      "x": 10,
      "y": 24,
      "z": 6,
      "name": "Soil_Snow"
    },
    {
      "x": 10,
      "y": 25,
      "z": 6,
      "name": "Soil_Snow"
    },
    {
      "x": 10,
      "y": 12,
      "z": 7,
      "name": "Rock_Shale"
    },
    {
      "x": 10,
      "y": 13,
      "z": 7,
      "name": "Rock_Shale"
    },
    {
      "x": 10,
      "y": 14,
      "z": 7,
      "name": "Rock_Shale"
    },
    {
      "x": 10,
      "y": 21,
      "z": 7,
      "name": "Rock_Shale"
    },
    {
      "x": 10,
      "y": 22,
      "z": 7,
      "name": "Soil_Dirt"
    },
    {
      "x": 10,
      "y": 23,
      "z": 7,
      "name": "Soil_Dirt"
    },
    {
      "x": 10,
      "y": 24,
      "z": 7,
      "name": "Soil_Grass"
    },
    {
      "x": 10,
      "y": 25,
      "z": 7,
      "name": "Soil_Snow"
    },
    {
      "x": 10,
      "y": 12,
      "z": 8,
      "name": "Rock_Shale"
    },
    {
      "x": 10,
      "y": 21,
      "z": 8,
      "name": "Rock_Shale"
    },
    {
      "x": 10,
      "y": 22,
      "z": 8,
      "name": "Rock_Shale"
    },
    {
      "x": 10,
      "y": 23,
      "z": 8,
      "name": "Soil_Dirt"
    },
    {
      "x": 10,
      "y": 24,
      "z": 8,
      "name": "Soil_Grass"
    },
    {
      "x": 10,
      "y": 25,
      "z": 8,
      "name": "Soil_Snow"
    },
    {
      "x": 10,
      "y": 10,
      "z": 9,
      "name": "Rock_Shale"
    },
    {
      "x": 10,
      "y": 11,
      "z": 9,
      "name": "Rock_Shale"
    },
    {
      "x": 10,
      "y": 21,
      "z": 9,
      "name": "Rock_Shale"
    },
    {
      "x": 10,
      "y": 22,
      "z": 9,
      "name": "Soil_Dirt"
    },
    {
      "x": 10,
      "y": 23,
      "z": 9,
      "name": "Soil_Dirt"
    },
    {
      "x": 10,
      "y": 24,
      "z": 9,
      "name": "Soil_Grass"
    },
    {
      "x": 10,
      "y": 25,
      "z": 9,
      "name": "Plant_Bush_Winter_Red"
    },
    {
      "x": 10,
      "y": 9,
      "z": 10,
      "name": "Rock_Shale"
    },
    {
      "x": 10,
      "y": 10,
      "z": 10,
      "name": "Rock_Shale"
    },
    {
      "x": 10,
      "y": 11,
      "z": 10,
      "name": "Rock_Shale"
    },
    {
      "x": 10,
      "y": 12,
      "z": 10,
      "name": "Rock_Shale"
    },
    {
      "x": 10,
      "y": 21,
      "z": 10,
      "name": "Rock_Shale"
    },
    {
      "x": 10,
      "y": 22,
      "z": 10,
      "name": "Rock_Shale"
    },
    {
      "x": 10,
      "y": 9,
      "z": 11,
      "name": "Rock_Shale"
    },
    {
      "x": 10,
      "y": 10,
      "z": 11,
      "name": "Rock_Shale"
    },
    {
      "x": 10,
      "y": 11,
      "z": 11,
      "name": "Rock_Shale"
    },
    {
      "x": 10,
      "y": 11,
      "z": 12,
      "name": "Rock_Shale"
    },
    {
      "x": 11,
      "y": 17,
      "z": 3,
      "name": "Rock_Shale"
    },
    {
      "x": 11,
      "y": 18,
      "z": 3,
      "name": "Rock_Shale"
    },
    {
      "x": 11,
      "y": 19,
      "z": 3,
      "name": "Rock_Shale"
    },
    {
      "x": 11,
      "y": 20,
      "z": 3,
      "name": "Soil_Dirt"
    },
    {
      "x": 11,
      "y": 18,
      "z": 4,
      "name": "Rock_Shale"
    },
    {
      "x": 11,
      "y": 19,
      "z": 4,
      "name": "Rock_Shale"
    },
    {
      "x": 11,
      "y": 20,
      "z": 4,
      "name": "Soil_Dirt"
    },
    {
      "x": 11,
      "y": 21,
      "z": 4,
      "name": "Soil_Dirt"
    },
    {
      "x": 11,
      "y": 22,
      "z": 4,
      "name": "Soil_Snow"
    },
    {
      "x": 11,
      "y": 23,
      "z": 4,
      "name": "Soil_Snow"
    },
    {
      "x": 11,
      "y": 20,
      "z": 5,
      "name": "Rock_Shale"
    },
    {
      "x": 11,
      "y": 21,
      "z": 5,
      "name": "Rock_Shale"
    },
    {
      "x": 11,
      "y": 22,
      "z": 5,
      "name": "Soil_Dirt"
    },
    {
      "x": 11,
      "y": 23,
      "z": 5,
      "name": "Soil_Grass"
    },
    {
      "x": 11,
      "y": 24,
      "z": 5,
      "name": "Soil_Snow"
    },
    {
      "x": 11,
      "y": 20,
      "z": 6,
      "name": "Rock_Shale"
    },
    {
      "x": 11,
      "y": 21,
      "z": 6,
      "name": "Rock_Shale"
    },
    {
      "x": 11,
      "y": 22,
      "z": 6,
      "name": "Soil_Dirt"
    },
    {
      "x": 11,
      "y": 23,
      "z": 6,
      "name": "Soil_Dirt"
    },
    {
      "x": 11,
      "y": 24,
      "z": 6,
      "name": "Soil_Grass"
    },
    {
      "x": 11,
      "y": 25,
      "z": 6,
      "name": "Soil_Snow"
    },
    {
      "x": 11,
      "y": 12,
      "z": 7,
      "name": "Rock_Shale"
    },
    {
      "x": 11,
      "y": 21,
      "z": 7,
      "name": "Rock_Shale"
    },
    {
      "x": 11,
      "y": 22,
      "z": 7,
      "name": "Soil_Dirt"
    },
    {
      "x": 11,
      "y": 23,
      "z": 7,
      "name": "Soil_Dirt"
    },
    {
      "x": 11,
      "y": 24,
      "z": 7,
      "name": "Soil_Grass"
    },
    {
      "x": 11,
      "y": 25,
      "z": 7,
      "name": "Soil_Snow"
    },
    {
      "x": 11,
      "y": 9,
      "z": 8,
      "name": "Rock_Shale"
    },
    {
      "x": 11,
      "y": 10,
      "z": 8,
      "name": "Rock_Shale"
    },
    {
      "x": 11,
      "y": 11,
      "z": 8,
      "name": "Rock_Shale"
    },
    {
      "x": 11,
      "y": 12,
      "z": 8,
      "name": "Rock_Shale"
    },
    {
      "x": 11,
      "y": 21,
      "z": 8,
      "name": "Rock_Shale"
    },
    {
      "x": 11,
      "y": 22,
      "z": 8,
      "name": "Rock_Shale"
    },
    {
      "x": 11,
      "y": 23,
      "z": 8,
      "name": "Soil_Dirt"
    },
    {
      "x": 11,
      "y": 24,
      "z": 8,
      "name": "Soil_Grass"
    },
    {
      "x": 11,
      "y": 25,
      "z": 8,
      "name": "Soil_Snow"
    },
    {
      "x": 11,
      "y": 9,
      "z": 9,
      "name": "Rock_Shale"
    },
    {
      "x": 11,
      "y": 10,
      "z": 9,
      "name": "Rock_Shale"
    },
    {
      "x": 11,
      "y": 11,
      "z": 9,
      "name": "Rock_Shale"
    },
    {
      "x": 11,
      "y": 22,
      "z": 9,
      "name": "Rock_Shale"
    },
    {
      "x": 11,
      "y": 23,
      "z": 9,
      "name": "Soil_Dirt"
    },
    {
      "x": 11,
      "y": 24,
      "z": 9,
      "name": "Soil_Grass"
    },
    {
      "x": 11,
      "y": 25,
      "z": 9,
      "name": "Soil_Snow"
    },
    {
      "x": 11,
      "y": 9,
      "z": 10,
      "name": "Rock_Shale"
    },
    {
      "x": 11,
      "y": 10,
      "z": 10,
      "name": "Rock_Shale"
    },
    {
      "x": 11,
      "y": 11,
      "z": 10,
      "name": "Rock_Shale"
    },
    {
      "x": 11,
      "y": 10,
      "z": 11,
      "name": "Rock_Shale"
    },
    {
      "x": 11,
      "y": 11,
      "z": 11,
      "name": "Rock_Shale"
    },
    {
      "x": 12,
      "y": 23,
      "z": 4,
      "name": "Soil_Snow"
    },
    {
      "x": 12,
      "y": 21,
      "z": 5,
      "name": "Rock_Shale"
    },
    {
      "x": 12,
      "y": 22,
      "z": 5,
      "name": "Rock_Shale"
    },
    {
      "x": 12,
      "y": 23,
      "z": 5,
      "name": "Soil_Grass"
    },
    {
      "x": 12,
      "y": 24,
      "z": 5,
      "name": "Soil_Snow"
    },
    {
      "x": 12,
      "y": 25,
      "z": 5,
      "name": "Soil_Snow"
    },
    {
      "x": 12,
      "y": 21,
      "z": 6,
      "name": "Rock_Shale"
    },
    {
      "x": 12,
      "y": 22,
      "z": 6,
      "name": "Rock_Shale"
    },
    {
      "x": 12,
      "y": 23,
      "z": 6,
      "name": "Soil_Grass"
    },
    {
      "x": 12,
      "y": 24,
      "z": 6,
      "name": "Soil_Snow"
    },
    {
      "x": 12,
      "y": 25,
      "z": 6,
      "name": "Soil_Snow"
    },
    {
      "x": 12,
      "y": 9,
      "z": 7,
      "name": "Rock_Shale"
    },
    {
      "x": 12,
      "y": 10,
      "z": 7,
      "name": "Rock_Shale"
    },
    {
      "x": 12,
      "y": 21,
      "z": 7,
      "name": "Rock_Shale"
    },
    {
      "x": 12,
      "y": 22,
      "z": 7,
      "name": "Rock_Shale"
    },
    {
      "x": 12,
      "y": 23,
      "z": 7,
      "name": "Soil_Dirt"
    },
    {
      "x": 12,
      "y": 24,
      "z": 7,
      "name": "Soil_Grass"
    },
    {
      "x": 12,
      "y": 25,
      "z": 7,
      "name": "Soil_Snow"
    },
    {
      "x": 12,
      "y": 9,
      "z": 8,
      "name": "Rock_Shale"
    },
    {
      "x": 12,
      "y": 10,
      "z": 8,
      "name": "Rock_Shale"
    },
    {
      "x": 12,
      "y": 11,
      "z": 8,
      "name": "Rock_Shale"
    },
    {
      "x": 12,
      "y": 21,
      "z": 8,
      "name": "Rock_Shale"
    },
    {
      "x": 12,
      "y": 22,
      "z": 8,
      "name": "Rock_Shale"
    },
    {
      "x": 12,
      "y": 23,
      "z": 8,
      "name": "Soil_Dirt"
    },
    {
      "x": 12,
      "y": 24,
      "z": 8,
      "name": "Soil_Dirt"
    },
    {
      "x": 12,
      "y": 25,
      "z": 8,
      "name": "Soil_Grass"
    },
    {
      "x": 12,
      "y": 26,
      "z": 8,
      "name": "Soil_Snow"
    },
    {
      "x": 12,
      "y": 9,
      "z": 9,
      "name": "Rock_Shale"
    },
    {
      "x": 12,
      "y": 10,
      "z": 9,
      "name": "Rock_Shale"
    },
    {
      "x": 12,
      "y": 11,
      "z": 9,
      "name": "Rock_Shale"
    },
    {
      "x": 12,
      "y": 22,
      "z": 9,
      "name": "Rock_Shale"
    },
    {
      "x": 12,
      "y": 23,
      "z": 9,
      "name": "Soil_Dirt"
    },
    {
      "x": 12,
      "y": 24,
      "z": 9,
      "name": "Soil_Grass"
    },
    {
      "x": 12,
      "y": 25,
      "z": 9,
      "name": "Soil_Snow"
    },
    {
      "x": 12,
      "y": 9,
      "z": 10,
      "name": "Rock_Shale"
    },
    {
      "x": 12,
      "y": 10,
      "z": 10,
      "name": "Rock_Shale"
    },
    {
      "x": 12,
      "y": 11,
      "z": 10,
      "name": "Rock_Shale"
    },
    {
      "x": 12,
      "y": 24,
      "z": 10,
      "name": "Soil_Grass"
    },
    {
      "x": 12,
      "y": 25,
      "z": 10,
      "name": "Soil_Snow"
    },
    {
      "x": 13,
      "y": 23,
      "z": 5,
      "name": "Soil_Snow"
    },
    {
      "x": 13,
      "y": 24,
      "z": 5,
      "name": "Soil_Snow"
    },
    {
      "x": 13,
      "y": 25,
      "z": 5,
      "name": "Soil_Snow"
    },
    {
      "x": 13,
      "y": 21,
      "z": 6,
      "name": "Rock_Shale"
    },
    {
      "x": 13,
      "y": 22,
      "z": 6,
      "name": "Soil_Dirt"
    },
    {
      "x": 13,
      "y": 23,
      "z": 6,
      "name": "Soil_Dirt"
    },
    {
      "x": 13,
      "y": 24,
      "z": 6,
      "name": "Soil_Grass"
    },
    {
      "x": 13,
      "y": 25,
      "z": 6,
      "name": "Soil_Snow"
    },
    {
      "x": 13,
      "y": 9,
      "z": 7,
      "name": "Rock_Shale"
    },
    {
      "x": 13,
      "y": 10,
      "z": 7,
      "name": "Rock_Shale"
    },
    {
      "x": 13,
      "y": 21,
      "z": 7,
      "name": "Rock_Shale"
    },
    {
      "x": 13,
      "y": 22,
      "z": 7,
      "name": "Rock_Shale"
    },
    {
      "x": 13,
      "y": 23,
      "z": 7,
      "name": "Soil_Dirt"
    },
    {
      "x": 13,
      "y": 24,
      "z": 7,
      "name": "Soil_Grass"
    },
    {
      "x": 13,
      "y": 25,
      "z": 7,
      "name": "Soil_Snow"
    },
    {
      "x": 13,
      "y": 9,
      "z": 8,
      "name": "Rock_Shale"
    },
    {
      "x": 13,
      "y": 10,
      "z": 8,
      "name": "Rock_Shale"
    },
    {
      "x": 13,
      "y": 11,
      "z": 8,
      "name": "Rock_Shale"
    },
    {
      "x": 13,
      "y": 22,
      "z": 8,
      "name": "Rock_Shale"
    },
    {
      "x": 13,
      "y": 23,
      "z": 8,
      "name": "Soil_Dirt"
    },
    {
      "x": 13,
      "y": 24,
      "z": 8,
      "name": "Soil_Dirt"
    },
    {
      "x": 13,
      "y": 25,
      "z": 8,
      "name": "Soil_Grass"
    },
    {
      "x": 13,
      "y": 26,
      "z": 8,
      "name": "Soil_Snow"
    },
    {
      "x": 13,
      "y": 10,
      "z": 9,
      "name": "Rock_Shale"
    },
    {
      "x": 13,
      "y": 11,
      "z": 9,
      "name": "Rock_Shale"
    },
    {
      "x": 13,
      "y": 22,
      "z": 9,
      "name": "Rock_Shale"
    },
    {
      "x": 13,
      "y": 23,
      "z": 9,
      "name": "Soil_Dirt"
    },
    {
      "x": 13,
      "y": 24,
      "z": 9,
      "name": "Soil_Dirt"
    },
    {
      "x": 13,
      "y": 25,
      "z": 9,
      "name": "Soil_Grass"
    },
    {
      "x": 13,
      "y": 26,
      "z": 9,
      "name": "Soil_Snow"
    },
    {
      "x": 13,
      "y": 11,
      "z": 10,
      "name": "Rock_Shale"
    },
    {
      "x": 13,
      "y": 23,
      "z": 10,
      "name": "Soil_Dirt"
    },
    {
      "x": 13,
      "y": 24,
      "z": 10,
      "name": "Soil_Grass"
    },
    {
      "x": 13,
      "y": 25,
      "z": 10,
      "name": "Soil_Snow"
    },
    {
      "x": 13,
      "y": 24,
      "z": 11,
      "name": "Soil_Snow"
    },
    {
      "x": 14,
      "y": 21,
      "z": 5,
      "name": "Soil_Snow"
    },
    {
      "x": 14,
      "y": 22,
      "z": 5,
      "name": "Soil_Snow"
    },
    {
      "x": 14,
      "y": 23,
      "z": 5,
      "name": "Soil_Snow"
    },
    {
      "x": 14,
      "y": 24,
      "z": 5,
      "name": "Soil_Snow"
    },
    {
      "x": 14,
      "y": 23,
      "z": 6,
      "name": "Soil_Dirt"
    },
    {
      "x": 14,
      "y": 24,
      "z": 6,
      "name": "Soil_Grass"
    },
    {
      "x": 14,
      "y": 25,
      "z": 6,
      "name": "Soil_Snow"
    },
    {
      "x": 14,
      "y": 10,
      "z": 7,
      "name": "Rock_Shale"
    },
    {
      "x": 14,
      "y": 11,
      "z": 7,
      "name": "Rock_Shale"
    },
    {
      "x": 14,
      "y": 22,
      "z": 7,
      "name": "Soil_Dirt"
    },
    {
      "x": 14,
      "y": 23,
      "z": 7,
      "name": "Soil_Dirt"
    },
    {
      "x": 14,
      "y": 24,
      "z": 7,
      "name": "Soil_Grass"
    },
    {
      "x": 14,
      "y": 25,
      "z": 7,
      "name": "Soil_Snow"
    },
    {
      "x": 14,
      "y": 10,
      "z": 8,
      "name": "Rock_Shale"
    },
    {
      "x": 14,
      "y": 11,
      "z": 8,
      "name": "Rock_Shale"
    },
    {
      "x": 14,
      "y": 22,
      "z": 8,
      "name": "Rock_Shale"
    },
    {
      "x": 14,
      "y": 23,
      "z": 8,
      "name": "Soil_Dirt"
    },
    {
      "x": 14,
      "y": 24,
      "z": 8,
      "name": "Soil_Dirt"
    },
    {
      "x": 14,
      "y": 25,
      "z": 8,
      "name": "Soil_Grass"
    },
    {
      "x": 14,
      "y": 26,
      "z": 8,
      "name": "Soil_Snow"
    },
    {
      "x": 14,
      "y": 10,
      "z": 9,
      "name": "Rock_Shale"
    },
    {
      "x": 14,
      "y": 11,
      "z": 9,
      "name": "Rock_Shale"
    },
    {
      "x": 14,
      "y": 22,
      "z": 9,
      "name": "Rock_Shale"
    },
    {
      "x": 14,
      "y": 23,
      "z": 9,
      "name": "Soil_Dirt"
    },
    {
      "x": 14,
      "y": 24,
      "z": 9,
      "name": "Soil_Dirt"
    },
    {
      "x": 14,
      "y": 25,
      "z": 9,
      "name": "Soil_Grass"
    },
    {
      "x": 14,
      "y": 26,
      "z": 9,
      "name": "Soil_Snow"
    },
    {
      "x": 14,
      "y": 23,
      "z": 10,
      "name": "Rock_Shale"
    },
    {
      "x": 14,
      "y": 24,
      "z": 10,
      "name": "Soil_Grass"
    },
    {
      "x": 14,
      "y": 25,
      "z": 10,
      "name": "Soil_Snow"
    },
    {
      "x": 14,
      "y": 22,
      "z": 11,
      "name": "Soil_Snow"
    },
    {
      "x": 14,
      "y": 23,
      "z": 11,
      "name": "Soil_Snow"
    },
    {
      "x": 14,
      "y": 24,
      "z": 11,
      "name": "Soil_Snow"
    },
    {
      "x": 15,
      "y": 24,
      "z": 5,
      "name": "Soil_Snow"
    },
    {
      "x": 15,
      "y": 22,
      "z": 6,
      "name": "Rock_Shale"
    },
    {
      "x": 15,
      "y": 23,
      "z": 6,
      "name": "Soil_Grass"
    },
    {
      "x": 15,
      "y": 24,
      "z": 6,
      "name": "Soil_Snow"
    },
    {
      "x": 15,
      "y": 11,
      "z": 7,
      "name": "Rock_Shale"
    },
    {
      "x": 15,
      "y": 12,
      "z": 7,
      "name": "Rock_Shale"
    },
    {
      "x": 15,
      "y": 13,
      "z": 7,
      "name": "Rock_Shale"
    },
    {
      "x": 15,
      "y": 22,
      "z": 7,
      "name": "Rock_Shale"
    },
    {
      "x": 15,
      "y": 23,
      "z": 7,
      "name": "Soil_Dirt"
    },
    {
      "x": 15,
      "y": 24,
      "z": 7,
      "name": "Soil_Grass"
    },
    {
      "x": 15,
      "y": 25,
      "z": 7,
      "name": "Soil_Snow"
    },
    {
      "x": 15,
      "y": 10,
      "z": 8,
      "name": "Rock_Shale"
    },
    {
      "x": 15,
      "y": 11,
      "z": 8,
      "name": "Rock_Shale"
    },
    {
      "x": 15,
      "y": 12,
      "z": 8,
      "name": "Rock_Shale"
    },
    {
      "x": 15,
      "y": 13,
      "z": 8,
      "name": "Rock_Shale"
    },
    {
      "x": 15,
      "y": 21,
      "z": 8,
      "name": "Rock_Shale"
    },
    {
      "x": 15,
      "y": 22,
      "z": 8,
      "name": "Rock_Shale"
    },
    {
      "x": 15,
      "y": 23,
      "z": 8,
      "name": "Soil_Dirt"
    },
    {
      "x": 15,
      "y": 24,
      "z": 8,
      "name": "Soil_Dirt"
    },
    {
      "x": 15,
      "y": 25,
      "z": 8,
      "name": "Soil_Grass"
    },
    {
      "x": 15,
      "y": 26,
      "z": 8,
      "name": "Soil_Snow"
    },
    {
      "x": 15,
      "y": 11,
      "z": 9,
      "name": "Rock_Shale"
    },
    {
      "x": 15,
      "y": 12,
      "z": 9,
      "name": "Rock_Shale"
    },
    {
      "x": 15,
      "y": 21,
      "z": 9,
      "name": "Rock_Shale"
    },
    {
      "x": 15,
      "y": 22,
      "z": 9,
      "name": "Rock_Shale"
    },
    {
      "x": 15,
      "y": 23,
      "z": 9,
      "name": "Soil_Dirt"
    },
    {
      "x": 15,
      "y": 24,
      "z": 9,
      "name": "Soil_Grass"
    },
    {
      "x": 15,
      "y": 25,
      "z": 9,
      "name": "Soil_Snow"
    },
    {
      "x": 15,
      "y": 23,
      "z": 10,
      "name": "Rock_Shale"
    },
    {
      "x": 15,
      "y": 24,
      "z": 10,
      "name": "Soil_Grass"
    },
    {
      "x": 15,
      "y": 25,
      "z": 10,
      "name": "Soil_Snow"
    },
    {
      "x": 15,
      "y": 23,
      "z": 11,
      "name": "Soil_Snow"
    },
    {
      "x": 15,
      "y": 24,
      "z": 11,
      "name": "Soil_Snow"
    },
    {
      "x": 16,
      "y": 23,
      "z": 5,
      "name": "Soil_Snow"
    },
    {
      "x": 16,
      "y": 22,
      "z": 6,
      "name": "Soil_Dirt"
    },
    {
      "x": 16,
      "y": 23,
      "z": 6,
      "name": "Soil_Grass"
    },
    {
      "x": 16,
      "y": 24,
      "z": 6,
      "name": "Soil_Snow"
    },
    {
      "x": 16,
      "y": 12,
      "z": 7,
      "name": "Rock_Shale"
    },
    {
      "x": 16,
      "y": 13,
      "z": 7,
      "name": "Rock_Shale"
    },
    {
      "x": 16,
      "y": 14,
      "z": 7,
      "name": "Rock_Shale"
    },
    {
      "x": 16,
      "y": 15,
      "z": 7,
      "name": "Rock_Shale"
    },
    {
      "x": 16,
      "y": 20,
      "z": 7,
      "name": "Rock_Shale"
    },
    {
      "x": 16,
      "y": 21,
      "z": 7,
      "name": "Rock_Shale"
    },
    {
      "x": 16,
      "y": 22,
      "z": 7,
      "name": "Soil_Dirt"
    },
    {
      "x": 16,
      "y": 23,
      "z": 7,
      "name": "Soil_Dirt"
    },
    {
      "x": 16,
      "y": 24,
      "z": 7,
      "name": "Soil_Grass"
    },
    {
      "x": 16,
      "y": 25,
      "z": 7,
      "name": "Soil_Snow"
    },
    {
      "x": 16,
      "y": 11,
      "z": 8,
      "name": "Rock_Shale"
    },
    {
      "x": 16,
      "y": 12,
      "z": 8,
      "name": "Rock_Shale"
    },
    {
      "x": 16,
      "y": 13,
      "z": 8,
      "name": "Rock_Shale"
    },
    {
      "x": 16,
      "y": 14,
      "z": 8,
      "name": "Rock_Shale"
    },
    {
      "x": 16,
      "y": 15,
      "z": 8,
      "name": "Rock_Shale"
    },
    {
      "x": 16,
      "y": 16,
      "z": 8,
      "name": "Rock_Shale"
    },
    {
      "x": 16,
      "y": 20,
      "z": 8,
      "name": "Rock_Shale"
    },
    {
      "x": 16,
      "y": 21,
      "z": 8,
      "name": "Rock_Shale"
    },
    {
      "x": 16,
      "y": 22,
      "z": 8,
      "name": "Soil_Dirt"
    },
    {
      "x": 16,
      "y": 23,
      "z": 8,
      "name": "Soil_Dirt"
    },
    {
      "x": 16,
      "y": 24,
      "z": 8,
      "name": "Soil_Grass"
    },
    {
      "x": 16,
      "y": 25,
      "z": 8,
      "name": "Soil_Snow"
    },
    {
      "x": 16,
      "y": 11,
      "z": 9,
      "name": "Rock_Shale"
    },
    {
      "x": 16,
      "y": 12,
      "z": 9,
      "name": "Rock_Shale"
    },
    {
      "x": 16,
      "y": 13,
      "z": 9,
      "name": "Rock_Shale"
    },
    {
      "x": 16,
      "y": 14,
      "z": 9,
      "name": "Rock_Shale"
    },
    {
      "x": 16,
      "y": 15,
      "z": 9,
      "name": "Rock_Shale"
    },
    {
      "x": 16,
      "y": 16,
      "z": 9,
      "name": "Rock_Shale"
    },
    {
      "x": 16,
      "y": 17,
      "z": 9,
      "name": "Rock_Shale"
    },
    {
      "x": 16,
      "y": 20,
      "z": 9,
      "name": "Rock_Shale"
    },
    {
      "x": 16,
      "y": 21,
      "z": 9,
      "name": "Rock_Shale"
    },
    {
      "x": 16,
      "y": 22,
      "z": 9,
      "name": "Rock_Shale"
    },
    {
      "x": 16,
      "y": 23,
      "z": 9,
      "name": "Soil_Dirt"
    },
    {
      "x": 16,
      "y": 24,
      "z": 9,
      "name": "Soil_Grass"
    },
    {
      "x": 16,
      "y": 25,
      "z": 9,
      "name": "Soil_Snow"
    },
    {
      "x": 16,
      "y": 14,
      "z": 10,
      "name": "Rock_Shale"
    },
    {
      "x": 16,
      "y": 15,
      "z": 10,
      "name": "Rock_Shale"
    },
    {
      "x": 16,
      "y": 24,
      "z": 10,
      "name": "Soil_Snow"
    },
    {
      "x": 17,
      "y": 21,
      "z": 6,
      "name": "Rock_Shale"
    },
    {
      "x": 17,
      "y": 22,
      "z": 6,
      "name": "Soil_Dirt"
    },
    {
      "x": 17,
      "y": 23,
      "z": 6,
      "name": "Soil_Grass"
    },
    {
      "x": 17,
      "y": 24,
      "z": 6,
      "name": "Soil_Snow"
    },
    {
      "x": 17,
      "y": 13,
      "z": 7,
      "name": "Rock_Shale"
    },
    {
      "x": 17,
      "y": 14,
      "z": 7,
      "name": "Rock_Shale"
    },
    {
      "x": 17,
      "y": 15,
      "z": 7,
      "name": "Rock_Shale"
    },
    {
      "x": 17,
      "y": 16,
      "z": 7,
      "name": "Rock_Shale"
    },
    {
      "x": 17,
      "y": 17,
      "z": 7,
      "name": "Rock_Shale"
    },
    {
      "x": 17,
      "y": 18,
      "z": 7,
      "name": "Rock_Shale"
    },
    {
      "x": 17,
      "y": 19,
      "z": 7,
      "name": "Rock_Shale"
    },
    {
      "x": 17,
      "y": 20,
      "z": 7,
      "name": "Rock_Shale"
    },
    {
      "x": 17,
      "y": 21,
      "z": 7,
      "name": "Soil_Dirt"
    },
    {
      "x": 17,
      "y": 22,
      "z": 7,
      "name": "Soil_Dirt"
    },
    {
      "x": 17,
      "y": 23,
      "z": 7,
      "name": "Soil_Grass"
    },
    {
      "x": 17,
      "y": 24,
      "z": 7,
      "name": "Soil_Snow"
    },
    {
      "x": 17,
      "y": 12,
      "z": 8,
      "name": "Rock_Shale"
    },
    {
      "x": 17,
      "y": 13,
      "z": 8,
      "name": "Rock_Shale"
    },
    {
      "x": 17,
      "y": 14,
      "z": 8,
      "name": "Rock_Shale"
    },
    {
      "x": 17,
      "y": 15,
      "z": 8,
      "name": "Rock_Shale"
    },
    {
      "x": 17,
      "y": 16,
      "z": 8,
      "name": "Rock_Shale"
    },
    {
      "x": 17,
      "y": 17,
      "z": 8,
      "name": "Rock_Shale"
    },
    {
      "x": 17,
      "y": 18,
      "z": 8,
      "name": "Rock_Shale"
    },
    {
      "x": 17,
      "y": 19,
      "z": 8,
      "name": "Rock_Shale"
    },
    {
      "x": 17,
      "y": 20,
      "z": 8,
      "name": "Rock_Shale"
    },
    {
      "x": 17,
      "y": 21,
      "z": 8,
      "name": "Soil_Dirt"
    },
    {
      "x": 17,
      "y": 22,
      "z": 8,
      "name": "Soil_Dirt"
    },
    {
      "x": 17,
      "y": 23,
      "z": 8,
      "name": "Soil_Dirt"
    },
    {
      "x": 17,
      "y": 24,
      "z": 8,
      "name": "Soil_Grass"
    },
    {
      "x": 17,
      "y": 25,
      "z": 8,
      "name": "Soil_Snow"
    },
    {
      "x": 17,
      "y": 12,
      "z": 9,
      "name": "Rock_Shale"
    },
    {
      "x": 17,
      "y": 13,
      "z": 9,
      "name": "Rock_Shale"
    },
    {
      "x": 17,
      "y": 14,
      "z": 9,
      "name": "Rock_Shale"
    },
    {
      "x": 17,
      "y": 15,
      "z": 9,
      "name": "Rock_Shale"
    },
    {
      "x": 17,
      "y": 16,
      "z": 9,
      "name": "Rock_Shale"
    },
    {
      "x": 17,
      "y": 17,
      "z": 9,
      "name": "Rock_Shale"
    },
    {
      "x": 17,
      "y": 18,
      "z": 9,
      "name": "Rock_Shale"
    },
    {
      "x": 17,
      "y": 19,
      "z": 9,
      "name": "Rock_Shale"
    },
    {
      "x": 17,
      "y": 20,
      "z": 9,
      "name": "Rock_Shale"
    },
    {
      "x": 17,
      "y": 21,
      "z": 9,
      "name": "Soil_Dirt"
    },
    {
      "x": 17,
      "y": 22,
      "z": 9,
      "name": "Soil_Dirt"
    },
    {
      "x": 17,
      "y": 23,
      "z": 9,
      "name": "Soil_Grass"
    },
    {
      "x": 17,
      "y": 24,
      "z": 9,
      "name": "Soil_Snow"
    },
    {
      "x": 17,
      "y": 13,
      "z": 10,
      "name": "Rock_Shale"
    },
    {
      "x": 17,
      "y": 14,
      "z": 10,
      "name": "Rock_Shale"
    },
    {
      "x": 17,
      "y": 15,
      "z": 10,
      "name": "Rock_Shale"
    },
    {
      "x": 17,
      "y": 16,
      "z": 10,
      "name": "Rock_Shale"
    },
    {
      "x": 17,
      "y": 17,
      "z": 10,
      "name": "Rock_Shale"
    },
    {
      "x": 17,
      "y": 18,
      "z": 10,
      "name": "Rock_Shale"
    },
    {
      "x": 17,
      "y": 20,
      "z": 10,
      "name": "Rock_Shale"
    },
    {
      "x": 17,
      "y": 21,
      "z": 10,
      "name": "Rock_Shale"
    },
    {
      "x": 17,
      "y": 22,
      "z": 10,
      "name": "Soil_Snow"
    },
    {
      "x": 17,
      "y": 23,
      "z": 10,
      "name": "Soil_Snow"
    },
    {
      "x": 18,
      "y": 18,
      "z": 6,
      "name": "Rock_Shale"
    },
    {
      "x": 18,
      "y": 19,
      "z": 6,
      "name": "Rock_Shale"
    },
    {
      "x": 18,
      "y": 20,
      "z": 6,
      "name": "Rock_Shale"
    },
    {
      "x": 18,
      "y": 21,
      "z": 6,
      "name": "Rock_Shale"
    },
    {
      "x": 18,
      "y": 22,
      "z": 6,
      "name": "Soil_Grass"
    },
    {
      "x": 18,
      "y": 23,
      "z": 6,
      "name": "Plant_Grass_Sharp_Tall"
    },
    {
      "x": 18,
      "y": 24,
      "z": 6,
      "name": "Plant_Grass_Sharp_Tall",
      "filler": 1024
    },
    {
      "x": 18,
      "y": 15,
      "z": 7,
      "name": "Rock_Shale"
    },
    {
      "x": 18,
      "y": 16,
      "z": 7,
      "name": "Rock_Shale"
    },
    {
      "x": 18,
      "y": 17,
      "z": 7,
      "name": "Rock_Shale"
    },
    {
      "x": 18,
      "y": 18,
      "z": 7,
      "name": "Rock_Shale"
    },
    {
      "x": 18,
      "y": 19,
      "z": 7,
      "name": "Rock_Shale"
    },
    {
      "x": 18,
      "y": 20,
      "z": 7,
      "name": "Rock_Shale"
    },
    {
      "x": 18,
      "y": 21,
      "z": 7,
      "name": "Soil_Dirt"
    },
    {
      "x": 18,
      "y": 22,
      "z": 7,
      "name": "Soil_Dirt"
    },
    {
      "x": 18,
      "y": 23,
      "z": 7,
      "name": "Soil_Grass"
    },
    {
      "x": 18,
      "y": 24,
      "z": 7,
      "name": "Plant_Grass_Sharp_Tall"
    },
    {
      "x": 18,
      "y": 25,
      "z": 7,
      "name": "Plant_Grass_Sharp_Tall",
      "filler": 1024
    },
    {
      "x": 18,
      "y": 14,
      "z": 8,
      "name": "Rock_Shale"
    },
    {
      "x": 18,
      "y": 15,
      "z": 8,
      "name": "Rock_Shale"
    },
    {
      "x": 18,
      "y": 16,
      "z": 8,
      "name": "Rock_Shale"
    },
    {
      "x": 18,
      "y": 17,
      "z": 8,
      "name": "Rock_Shale"
    },
    {
      "x": 18,
      "y": 18,
      "z": 8,
      "name": "Rock_Shale"
    },
    {
      "x": 18,
      "y": 19,
      "z": 8,
      "name": "Rock_Shale"
    },
    {
      "x": 18,
      "y": 20,
      "z": 8,
      "name": "Soil_Dirt"
    },
    {
      "x": 18,
      "y": 21,
      "z": 8,
      "name": "Soil_Dirt"
    },
    {
      "x": 18,
      "y": 22,
      "z": 8,
      "name": "Soil_Snow"
    },
    {
      "x": 18,
      "y": 23,
      "z": 8,
      "name": "Soil_Snow"
    },
    {
      "x": 18,
      "y": 24,
      "z": 8,
      "name": "Soil_Snow"
    },
    {
      "x": 18,
      "y": 13,
      "z": 9,
      "name": "Rock_Shale"
    },
    {
      "x": 18,
      "y": 14,
      "z": 9,
      "name": "Rock_Shale"
    },
    {
      "x": 18,
      "y": 15,
      "z": 9,
      "name": "Rock_Shale"
    },
    {
      "x": 18,
      "y": 16,
      "z": 9,
      "name": "Rock_Shale"
    },
    {
      "x": 18,
      "y": 17,
      "z": 9,
      "name": "Rock_Shale"
    },
    {
      "x": 18,
      "y": 18,
      "z": 9,
      "name": "Rock_Shale"
    },
    {
      "x": 18,
      "y": 19,
      "z": 9,
      "name": "Rock_Shale"
    },
    {
      "x": 18,
      "y": 20,
      "z": 9,
      "name": "Rock_Shale"
    },
    {
      "x": 18,
      "y": 21,
      "z": 9,
      "name": "Soil_Dirt"
    },
    {
      "x": 18,
      "y": 22,
      "z": 9,
      "name": "Soil_Dirt"
    },
    {
      "x": 18,
      "y": 23,
      "z": 9,
      "name": "Soil_Grass"
    },
    {
      "x": 18,
      "y": 24,
      "z": 9,
      "name": "Plant_Grass_Sharp_Tall"
    },
    {
      "x": 18,
      "y": 25,
      "z": 9,
      "name": "Plant_Grass_Sharp_Tall",
      "filler": 1024
    },
    {
      "x": 18,
      "y": 15,
      "z": 10,
      "name": "Rock_Shale"
    },
    {
      "x": 18,
      "y": 16,
      "z": 10,
      "name": "Rock_Shale"
    },
    {
      "x": 18,
      "y": 17,
      "z": 10,
      "name": "Rock_Shale"
    },
    {
      "x": 18,
      "y": 18,
      "z": 10,
      "name": "Rock_Shale"
    },
    {
      "x": 18,
      "y": 19,
      "z": 10,
      "name": "Rock_Shale"
    },
    {
      "x": 18,
      "y": 20,
      "z": 10,
      "name": "Rock_Shale"
    },
    {
      "x": 18,
      "y": 21,
      "z": 10,
      "name": "Rock_Shale"
    },
    {
      "x": 19,
      "y": 18,
      "z": 7,
      "name": "Rock_Shale"
    },
    {
      "x": 19,
      "y": 19,
      "z": 7,
      "name": "Rock_Shale"
    },
    {
      "x": 19,
      "y": 20,
      "z": 7,
      "name": "Rock_Shale"
    },
    {
      "x": 19,
      "y": 16,
      "z": 8,
      "name": "Rock_Shale"
    },
    {
      "x": 19,
      "y": 17,
      "z": 8,
      "name": "Rock_Shale"
    },
    {
      "x": 19,
      "y": 18,
      "z": 8,
      "name": "Rock_Shale"
    },
    {
      "x": 19,
      "y": 19,
      "z": 8,
      "name": "Rock_Shale"
    },
    {
      "x": 19,
      "y": 20,
      "z": 8,
      "name": "Rock_Shale"
    },
    {
      "x": 19,
      "y": 21,
      "z": 8,
      "name": "Soil_Dirt"
    },
    {
      "x": 19,
      "y": 17,
      "z": 9,
      "name": "Rock_Shale"
    },
    {
      "x": 19,
      "y": 18,
      "z": 9,
      "name": "Rock_Shale"
    },
    {
      "x": 19,
      "y": 19,
      "z": 9,
      "name": "Rock_Shale"
    }
  ]
}