{
  "version": 8,
  "blockIdVersion": 8,
  "anchorX": 0,
  "anchorY": 0,
  "anchorZ": 0,
  "blocks": [
    {
      "x": -10,
      "y": -1,
      "z": 0,
      "name": "Rock_Stone"
    },
    {
      "x": -10,
      "y": 0,
      "z": 0,
      "name": "Rock_Stone"
    },
    {
      "x": -10,
      "y": 1,
      "z": 0,
      "name": "Rock_Stone"
    },
    {
      "x": -10,
      "y": 2,
      "z": 0,
      "name": "Rock_Stone"
    },
    {
      "x": -10,
      "y": 3,
      "z": 0,
      "name": "Rock_Stone"
    },
    {
      "x": -10,
      "y": 4,
      "z": 0,
      "name": "Rock_Stone"
    },
    {
      "x": -10,
      "y": 5,
      "z": 0,
      "name": "Rock_Stone"
    },
    {
      "x": -10,
      "y": 6,
      "z": 0,
      "name": "Rock_Stone"
    },
    {
      "x": -10,
      "y": 7,
      "z": 0,
      "name": "Rock_Stone"
    },
    {
      "x": -10,
      "y": 8,
      "z": 0,
      "name": "Rock_Stone"
    },
    {
      "x": -10,
      "y": 9,
      "z": 0,
      "name": "Rock_Stone"
    },
    {
      "x": -10,
      "y": 10,
      "z": 0,
      "name": "Rock_Stone"
    },
    {
      "x": -10,
      "y": 11,
      "z": 0,
      "name": "Rock_Stone"
    },
    {
      "x": -10,
      "y": 12,
      "z": 0,
      "name": "Rock_Stone"
    },
    {
      "x": -10,
      "y": 13,
      "z": 0,
      "name": "Rock_Stone"
    },
    {
      "x": -10,
      "y": 14,
      "z": 0,
      "name": "Rock_Stone"
    },
    {
      "x": -10,
      "y": -1,
      "z": 1,
      "name": "Rock_Stone"
    },
    {
      "x": -10,
      "y": 0,
      "z": 1,
      "name": "Rock_Stone"
    },
    {
      "x": -10,
      "y": 1,
      "z": 1,
      "name": "Rock_Stone"
    },
    {
      "x": -10,
      "y": 2,
      "z": 1,
      "name": "Rock_Stone"
    },
    {
      "x": -10,
      "y": 3,
      "z": 1,
      "name": "Rock_Stone"
    },
    {
      "x": -10,
      "y": 4,
      "z": 1,
      "name": "Rock_Stone"
    },
    {
      "x": -10,
      "y": 5,
      "z": 1,
      "name": "Rock_Stone"
    },
    {
      "x": -10,
      "y": 6,
      "z": 1,
      "name": "Rock_Stone"
    },
    {
      "x": -10,
      "y": 7,
      "z": 1,
      "name": "Rock_Stone"
    },
    {
      "x": -10,
      "y": 8,
      "z": 1,
      "name": "Rock_Stone"
    },
    {
      "x": -10,
      "y": 9,
      "z": 1,
      "name": "Rock_Stone"
    },
    {
      "x": -10,
      "y": 10,
      "z": 1,
      "name": "Rock_Stone"
    },
    {
      "x": -10,
      "y": 11,
      "z": 1,
      "name": "Rock_Stone"
    },
    {
      "x": -10,
      "y": 12,
      "z": 1,
      "name": "Rock_Stone"
    },
    {
      "x": -10,
      "y": 13,
      "z": 1,
      "name": "Rock_Stone"
    },
    {
      "x": -10,
      "y": 14,
      "z": 1,
      "name": "Rock_Stone"
    },
    {
      "x": -10,
      "y": -1,
      "z": 2,
      "name": "Rock_Stone"
    },
    {
      "x": -10,
      "y": 0,
      "z": 2,
      "name": "Rock_Stone"
    },
    {
      "x": -10,
      "y": 1,
      "z": 2,
      "name": "Rock_Stone"
    },
    {
      "x": -10,
      "y": 2,
      "z": 2,
      "name": "Rock_Stone"
    },
    {
      "x": -10,
      "y": 3,
      "z": 2,
      "name": "Rock_Stone"
    },
    {
      "x": -10,
      "y": 4,
      "z": 2,
      "name": "Rock_Stone"
    },
    {
      "x": -10,
      "y": 5,
      "z": 2,
      "name": "Rock_Stone"
    },
    {
      "x": -10,
      "y": 6,
      "z": 2,
      "name": "Rock_Stone"
    },
    {
      "x": -10,
      "y": 7,
      "z": 2,
      "name": "Rock_Stone"
    },
    {
      "x": -10,
      "y": 8,
      "z": 2,
      "name": "Rock_Stone"
    },
    {
      "x": -10,
      "y": 9,
      "z": 2,
      "name": "Rock_Stone"
    },
    {
      "x": -10,
      "y": 10,
      "z": 2,
      "name": "Rock_Stone"
    },
    {
      "x": -10,
      "y": 11,
      "z": 2,
      "name": "Rock_Stone"
    },
    {
      "x": -10,
      "y": 12,
      "z": 2,
      "name": "Rock_Stone"
    },
    {
      "x": -10,
      "y": 13,
      "z": 2,
      "name": "Rock_Stone"
    },
    {
      "x": -10,
      "y": 14,
      "z": 2,
      "name": "Rock_Stone"
    },
    {
      "x": -10,
      "y": -1,
      "z": 3,
      "name": "Rock_Stone"
    },
    {
      "x": -10,
      "y": 0,
      "z": 3,
      "name": "Rock_Stone"
    },
    {
      "x": -10,
      "y": 1,
      "z": 3,
      "name": "Rock_Stone"
    },
    {
      "x": -10,
      "y": 2,
      "z": 3,
      "name": "Rock_Stone"
    },
    {
      "x": -10,
      "y": 3,
      "z": 3,
      "name": "Rock_Stone"
    },
    {
      "x": -10,
      "y": 4,
      "z": 3,
      "name": "Rock_Stone"
    },
    {
      "x": -10,
      "y": 5,
      "z": 3,
      "name": "Rock_Stone"
    },
    {
      "x": -10,
      "y": 6,
      "z": 3,
      "name": "Rock_Stone"
    },
    {
      "x": -10,
      "y": 7,
      "z": 3,
      "name": "Rock_Stone"
    },
    {
      "x": -10,
      "y": 8,
      "z": 3,
      "name": "Rock_Stone"
    },
    {
      "x": -10,
      "y": 9,
      "z": 3,
      "name": "Rock_Stone"
    },
    {
      "x": -10,
      "y": 10,
      "z": 3,
      "name": "Rock_Stone"
    },
    {
      "x": -10,
      "y": 11,
      "z": 3,
      "name": "Rock_Stone"
    },
    {
      "x": -10,
      "y": 12,
      "z": 3,
      "name": "Rock_Stone"
    },
    {
      "x": -10,
      "y": 13,
      "z": 3,
      "name": "Rock_Stone"
    },
    {
      "x": -10,
      "y": 14,
      "z": 3,
      "name": "Rock_Stone"
    },
    {
      "x": -10,
      "y": -1,
      "z": 4,
      "name": "Rock_Stone"
    },
    {
      "x": -10,
      "y": 0,
      "z": 4,
      "name": "Rock_Stone"
    },
    {
      "x": -10,
      "y": 1,
      "z": 4,
      "name": "Rock_Stone"
    },
    {
      "x": -10,
      "y": 2,
      "z": 4,
      "name": "Rock_Stone"
    },
    {
      "x": -10,
      "y": 3,
      "z": 4,
      "name": "Rock_Stone"
    },
    {
      "x": -10,
      "y": 4,
      "z": 4,
      "name": "Rock_Stone"
    },
    {
      "x": -10,
      "y": 5,
      "z": 4,
      "name": "Rock_Stone"
    },
    {
      "x": -10,
      "y": 6,
      "z": 4,
      "name": "Rock_Stone"
    },
    {
      "x": -10,
      "y": 7,
      "z": 4,
      "name": "Rock_Stone"
    },
    {
      "x": -10,
      "y": 8,
      "z": 4,
      "name": "Rock_Stone"
    },
    {
      "x": -10,
      "y": 9,
      "z": 4,
      "name": "Rock_Stone"
    },
    {
      "x": -10,
      "y": 10,
      "z": 4,
      "name": "Rock_Stone"
    },
    {
      "x": -10,
      "y": 11,
      "z": 4,
      "name": "Rock_Stone"
    },
    {
      "x": -10,
      "y": 12,
      "z": 4,
      "name": "Rock_Stone"
    },
    {
      "x": -10,
      "y": 13,
      "z": 4,
      "name": "Rock_Stone"
    },
    {
      "x": -10,
      "y": 14,
      "z": 4,
      "name": "Rock_Stone"
    },
    {
      "x": -10,
      "y": -1,
      "z": 5,
      "name": "Rock_Stone"
    },
    {
      "x": -10,
      "y": 0,
      "z": 5,
      "name": "Rock_Stone"
    },
    {
      "x": -10,
      "y": 1,
      "z": 5,
      "name": "Rock_Stone"
    },
    {
      "x": -10,
      "y": 2,
      "z": 5,
      "name": "Rock_Stone"
    },
    {
      "x": -10,
      "y": 3,
      "z": 5,
      "name": "Rock_Stone"
    },
    {
      "x": -10,
      "y": 4,
      "z": 5,
      "name": "Rock_Stone"
    },
    {
      "x": -10,
      "y": 5,
      "z": 5,
      "name": "Rock_Stone"
    },
    {
      "x": -10,
      "y": 6,
      "z": 5,
      "name": "Rock_Stone"
    },
    {
      "x": -10,
      "y": 7,
      "z": 5,
      "name": "Rock_Stone"
    },
    {
      "x": -10,
      "y": 8,
      "z": 5,
      "name": "Rock_Stone"
    },
    {
      "x": -10,
      "y": 9,
      "z": 5,
      "name": "Rock_Stone"
    },
    {
      "x": -10,
      "y": 10,
      "z": 5,
      "name": "Rock_Stone"
    },
    {
      "x": -10,
      "y": 11,
      "z": 5,
      "name": "Rock_Stone"
    },
    {
      "x": -10,
      "y": 12,
      "z": 5,
      "name": "Rock_Stone"
    },
    {
      "x": -10,
      "y": 13,
      "z": 5,
      "name": "Rock_Stone"
    },
    {
      "x": -10,
      "y": 14,
      "z": 5,
      "name": "Rock_Stone"
    },
    {
      "x": -10,
      "y": -1,
      "z": 6,
      "name": "Rock_Stone"
    },
    {
      "x": -10,
      "y": 0,
      "z": 6,
      "name": "Rock_Stone"
    },
    {
      "x": -10,
      "y": 1,
      "z": 6,
      "name": "Rock_Stone"
    },
    {
      "x": -10,
      "y": 2,
      "z": 6,
      "name": "Rock_Stone"
    },
    {
      "x": -10,
      "y": 3,
      "z": 6,
      "name": "Rock_Stone"
    },
    {
      "x": -10,
      "y": 4,
      "z": 6,
      "name": "Rock_Stone"
    },
    {
      "x": -10,
      "y": 5,
      "z": 6,
      "name": "Rock_Stone"
    },
    {
      "x": -10,
      "y": 6,
      "z": 6,
      "name": "Rock_Stone"
    },
    {
      "x": -10,
      "y": 7,
      "z": 6,
      "name": "Rock_Stone"
    },
    {
      "x": -10,
      "y": 8,
      "z": 6,
      "name": "Rock_Stone"
    },
    {
      "x": -10,
      "y": 9,
      "z": 6,
      "name": "Rock_Stone"
    },
    {
      "x": -10,
      "y": 10,
      "z": 6,
      "name": "Rock_Stone"
    },
    {
      "x": -10,
      "y": 11,
      "z": 6,
      "name": "Rock_Stone"
    },
    {
      "x": -10,
      "y": 12,
      "z": 6,
      "name": "Rock_Stone"
    },
    {
      "x": -10,
      "y": 13,
      "z": 6,
      "name": "Rock_Stone"
    },
    {
      "x": -10,
      "y": 14,
      "z": 6,
      "name": "Rock_Stone"
    },
    {
      "x": -10,
      "y": -1,
      "z": 7,
      "name": "Rock_Stone"
    },
    {
      "x": -10,
      "y": 0,
      "z": 7,
      "name": "Rock_Stone"
    },
    {
      "x": -10,
      "y": 1,
      "z": 7,
      "name": "Rock_Stone"
    },
    {
      "x": -10,
      "y": 2,
      "z": 7,
      "name": "Rock_Stone"
    },
    {
      "x": -10,
      "y": 3,
      "z": 7,
      "name": "Rock_Stone"
    },
    {
      "x": -10,
      "y": 4,
      "z": 7,
      "name": "Rock_Stone"
    },
    {
      "x": -10,
      "y": 5,
      "z": 7,
      "name": "Rock_Stone"
    },
    {
      "x": -10,
      "y": 6,
      "z": 7,
      "name": "Rock_Stone"
    },
    {
      "x": -10,
      "y": 7,
      "z": 7,
      "name": "Rock_Stone"
    },
    {
      "x": -10,
      "y": 8,
      "z": 7,
      "name": "Rock_Stone"
    },
    {
      "x": -10,
      "y": 9,
      "z": 7,
      "name": "Rock_Stone"
    },
    {
      "x": -10,
      "y": 10,
      "z": 7,
      "name": "Rock_Stone"
    },
    {
      "x": -10,
      "y": 11,
      "z": 7,
      "name": "Rock_Stone"
    },
    {
      "x": -10,
      "y": 12,
      "z": 7,
      "name": "Rock_Stone"
    },
    {
      "x": -10,
      "y": 13,
      "z": 7,
      "name": "Rock_Stone"
    },
    {
      "x": -10,
      "y": 14,
      "z": 7,
      "name": "Rock_Stone"
    },
    {
      "x": -10,
      "y": -1,
      "z": 8,
      "name": "Rock_Stone"
    },
    {
      "x": -10,
      "y": 0,
      "z": 8,
      "name": "Rock_Stone"
    },
    {
      "x": -10,
      "y": 1,
      "z": 8,
      "name": "Rock_Stone"
    },
    {
      "x": -10,
      "y": 2,
      "z": 8,
      "name": "Rock_Stone"
    },
    {
      "x": -10,
      "y": 3,
      "z": 8,
      "name": "Rock_Stone"
    },
    {
      "x": -10,
      "y": 4,
      "z": 8,
      "name": "Rock_Stone"
    },
    {
      "x": -10,
      "y": 5,
      "z": 8,
      "name": "Rock_Stone"
    },
    {
      "x": -10,
      "y": 6,
      "z": 8,
      "name": "Rock_Stone"
    },
    {
      "x": -10,
      "y": 7,
      "z": 8,
      "name": "Rock_Stone"
    },
    {
      "x": -10,
      "y": 8,
      "z": 8,
      "name": "Rock_Stone"
    },
    {
      "x": -10,
      "y": 9,
      "z": 8,
      "name": "Rock_Stone"
    },
    {
      "x": -10,
      "y": 10,
      "z": 8,
      "name": "Rock_Stone"
    },
    {
      "x": -10,
      "y": 11,
      "z": 8,
      "name": "Rock_Stone"
    },
    {
      "x": -10,
      "y": 12,
      "z": 8,
      "name": "Rock_Stone"
    },
    {
      "x": -10,
      "y": 13,
      "z": 8,
      "name": "Rock_Stone"
    },
    {
      "x": -10,
      "y": 14,
      "z": 8,
      "name": "Rock_Stone"
    },
    {
      "x": -10,
      "y": -1,
      "z": 9,
      "name": "Rock_Stone"
    },
    {
      "x": -10,
      "y": 0,
      "z": 9,
      "name": "Rock_Stone"
    },
    {
      "x": -10,
      "y": 1,
      "z": 9,
      "name": "Rock_Stone"
    },
    {
      "x": -10,
      "y": 2,
      "z": 9,
      "name": "Rock_Stone"
    },
    {
      "x": -10,
      "y": 3,
      "z": 9,
      "name": "Rock_Stone"
    },
    {
      "x": -10,
      "y": 4,
      "z": 9,
      "name": "Rock_Stone"
    },
    {
      "x": -10,
      "y": 5,
      "z": 9,
      "name": "Rock_Stone"
    },
    {
      "x": -10,
      "y": 6,
      "z": 9,
      "name": "Rock_Stone"
    },
    {
      "x": -10,
      "y": 7,
      "z": 9,
      "name": "Rock_Stone"
    },
    {
      "x": -10,
      "y": 8,
      "z": 9,
      "name": "Rock_Stone"
    },
    {
      "x": -10,
      "y": 9,
      "z": 9,
      "name": "Rock_Stone"
    },
    {
      "x": -10,
      "y": 10,
      "z": 9,
      "name": "Rock_Stone"
    },
    {
      "x": -10,
      "y": 11,
      "z": 9,
      "name": "Rock_Stone"
    },
    {
      "x": -10,
      "y": 12,
      "z": 9,
      "name": "Rock_Stone"
    },
    {
      "x": -10,
      "y": 13,
      "z": 9,
      "name": "Rock_Stone"
    },
    {
      "x": -10,
      "y": 14,
      "z": 9,
      "name": "Rock_Stone"
    },
    {
      "x": -10,
      "y": -1,
      "z": 10,
      "name": "Rock_Stone"
    },
    {
      "x": -10,
      "y": 0,
      "z": 10,
      "name": "Rock_Stone"
    },
    {
      "x": -10,
      "y": 1,
      "z": 10,
      "name": "Rock_Stone"
    },
    {
      "x": -10,
      "y": 2,
      "z": 10,
      "name": "Rock_Stone"
    },
    {
      "x": -10,
      "y": 3,
      "z": 10,
      "name": "Rock_Stone"
    },
    {
      "x": -10,
      "y": 4,
      "z": 10,
      "name": "Rock_Stone"
    },
    {
      "x": -10,
      "y": 5,
      "z": 10,
      "name": "Rock_Stone"
    },
    {
      "x": -10,
      "y": 6,
      "z": 10,
      "name": "Rock_Stone"
    },
    {
      "x": -10,
      "y": 7,
      "z": 10,
      "name": "Rock_Stone"
    },
    {
      "x": -10,
      "y": 8,
      "z": 10,
      "name": "Rock_Stone"
    },
    {
      "x": -10,
      "y": 9,
      "z": 10,
      "name": "Rock_Stone"
    },
    {
      "x": -10,
      "y": 10,
      "z": 10,
      "name": "Rock_Stone"
    },
    {
      "x": -10,
      "y": 11,
      "z": 10,
      "name": "Rock_Stone"
    },
    {
      "x": -10,
      "y": 12,
      "z": 10,
      "name": "Rock_Stone"
    },
    {
      "x": -10,
      "y": 13,
      "z": 10,
      "name": "Rock_Stone"
    },
    {
      "x": -10,
      "y": 14,
      "z": 10,
      "name": "Rock_Stone"
    },
    {
      "x": -10,
      "y": -1,
      "z": 11,
      "name": "Rock_Stone"
    },
    {
      "x": -10,
      "y": 0,
      "z": 11,
      "name": "Rock_Stone"
    },
    {
      "x": -10,
      "y": 1,
      "z": 11,
      "name": "Rock_Stone"
    },
    {
      "x": -10,
      "y": 2,
      "z": 11,
      "name": "Rock_Stone"
    },
    {
      "x": -10,
      "y": 3,
      "z": 11,
      "name": "Rock_Stone"
    },
    {
      "x": -10,
      "y": 4,
      "z": 11,
      "name": "Rock_Stone"
    },
    {
      "x": -10,
      "y": 5,
      "z": 11,
      "name": "Rock_Stone"
    },
    {
      "x": -10,
      "y": 6,
      "z": 11,
      "name": "Rock_Stone"
    },
    {
      "x": -10,
      "y": 7,
      "z": 11,
      "name": "Rock_Stone"
    },
    {
      "x": -10,
      "y": 8,
      "z": 11,
      "name": "Rock_Stone"
    },
    {
      "x": -10,
      "y": 9,
      "z": 11,
      "name": "Rock_Stone"
    },
    {
      "x": -10,
      "y": 10,
      "z": 11,
      "name": "Rock_Stone"
    },
    {
      "x": -10,
      "y": 11,
      "z": 11,
      "name": "Rock_Stone"
    },
    {
      "x": -10,
      "y": 12,
      "z": 11,
      "name": "Rock_Stone"
    },
    {
      "x": -10,
      "y": 13,
      "z": 11,
      "name": "Rock_Stone"
    },
    {
      "x": -10,
      "y": 14,
      "z": 11,
      "name": "Rock_Stone"
    },
    {
      "x": -10,
      "y": -1,
      "z": 12,
      "name": "Rock_Stone"
    },
    {
      "x": -10,
      "y": 0,
      "z": 12,
      "name": "Rock_Stone"
    },
    {
      "x": -10,
      "y": 1,
      "z": 12,
      "name": "Rock_Stone"
    },
    {
      "x": -10,
      "y": 2,
      "z": 12,
      "name": "Rock_Stone"
    },
    {
      "x": -10,
      "y": 3,
      "z": 12,
      "name": "Rock_Stone"
    },
    {
      "x": -10,
      "y": 4,
      "z": 12,
      "name": "Rock_Stone"
    },
    {
      "x": -10,
      "y": 5,
      "z": 12,
      "name": "Rock_Stone"
    },
    {
      "x": -10,
      "y": 6,
      "z": 12,
      "name": "Rock_Stone"
    },
    {
      "x": -10,
      "y": 7,
      "z": 12,
      "name": "Rock_Stone"
    },
    {
      "x": -10,
      "y": 8,
      "z": 12,
      "name": "Rock_Stone"
    },
    {
      "x": -10,
      "y": 9,
      "z": 12,
      "name": "Rock_Stone"
    },
    {
      "x": -10,
      "y": 10,
      "z": 12,
      "name": "Rock_Stone"
    },
    {
      "x": -10,
      "y": 11,
      "z": 12,
      "name": "Rock_Stone"
    },
    {
      "x": -10,
      "y": 12,
      "z": 12,
      "name": "Rock_Stone"
    },
    {
      "x": -10,
      "y": 13,
      "z": 12,
      "name": "Rock_Stone"
    },
    {
      "x": -10,
      "y": 14,
      "z": 12,
      "name": "Rock_Stone"
    },
    {
      "x": -10,
      "y": -1,
      "z": 13,
      "name": "Rock_Stone"
    },
    {
      "x": -10,
      "y": 0,
      "z": 13,
      "name": "Rock_Stone"
    },
    {
      "x": -10,
      "y": 1,
      "z": 13,
      "name": "Rock_Stone"
    },
    {
      "x": -10,
      "y": 2,
      "z": 13,
      "name": "Rock_Stone"
    },
    {
      "x": -10,
      "y": 3,
      "z": 13,
      "name": "Rock_Stone"
    },
    {
      "x": -10,
      "y": 4,
      "z": 13,
      "name": "Rock_Stone"
    },
    {
      "x": -10,
      "y": 5,
      "z": 13,
      "name": "Rock_Stone"
    },
    {
      "x": -10,
      "y": 6,
      "z": 13,
      "name": "Rock_Stone"
    },
    {
      "x": -10,
      "y": 7,
      "z": 13,
      "name": "Rock_Stone"
    },
    {
      "x": -10,
      "y": 8,
      "z": 13,
      "name": "Rock_Stone"
    },
    {
      "x": -10,
      "y": 9,
      "z": 13,
      "name": "Rock_Stone"
    },
    {
      "x": -10,
      "y": 10,
      "z": 13,
      "name": "Rock_Stone"
    },
    {
      "x": -10,
      "y": 11,
      "z": 13,
      "name": "Rock_Stone"
    },
    {
      "x": -10,
      "y": 12,
      "z": 13,
      "name": "Rock_Stone"
    },
    {
      "x": -10,
      "y": 13,
      "z": 13,
      "name": "Rock_Stone"
    },
    {
      "x": -10,
      "y": 14,
      "z": 13,
      "name": "Rock_Stone"
    },
    {
      "x": -10,
      "y": -1,
      "z": 14,
      "name": "Rock_Stone"
    },
    {
      "x": -10,
      "y": 0,
      "z": 14,
      "name": "Rock_Stone"
    },
    {
      "x": -10,
      "y": 1,
      "z": 14,
      "name": "Rock_Stone"
    },
    {
      "x": -10,
      "y": 2,
      "z": 14,
      "name": "Rock_Stone"
    },
    {
      "x": -10,
      "y": 3,
      "z": 14,
      "name": "Rock_Stone"
    },
    {
      "x": -10,
      "y": 4,
      "z": 14,
      "name": "Rock_Stone"
    },
    {
      "x": -10,
      "y": 5,
      "z": 14,
      "name": "Rock_Stone"
    },
    {
      "x": -10,
      "y": 6,
      "z": 14,
      "name": "Rock_Stone"
    },
    {
      "x": -10,
      "y": 7,
      "z": 14,
      "name": "Rock_Stone"
    },
    {
      "x": -10,
      "y": 8,
      "z": 14,
      "name": "Rock_Stone"
    },
    {
      "x": -10,
      "y": 9,
      "z": 14,
      "name": "Rock_Stone"
    },
    {
      "x": -10,
      "y": 10,
      "z": 14,
      "name": "Rock_Stone"
    },
    {
      "x": -10,
      "y": 11,
      "z": 14,
      "name": "Rock_Stone"
    },
    {
      "x": -10,
      "y": 12,
      "z": 14,
      "name": "Rock_Stone"
    },
    {
      "x": -10,
      "y": 13,
      "z": 14,
      "name": "Rock_Stone"
    },
    {
      "x": -10,
      "y": 14,
      "z": 14,
      "name": "Rock_Stone"
    },
    {
      "x": -10,
      "y": -1,
      "z": 15,
      "name": "Rock_Stone"
    },
    {
      "x": -10,
      "y": 0,
      "z": 15,
      "name": "Rock_Stone"
    },
    {
      "x": -10,
      "y": 1,
      "z": 15,
      "name": "Rock_Stone"
    },
    {
      "x": -10,
      "y": 2,
      "z": 15,
      "name": "Rock_Stone"
    },
    {
      "x": -10,
      "y": 3,
      "z": 15,
      "name": "Rock_Stone"
    },
    {
      "x": -10,
      "y": 4,
      "z": 15,
      "name": "Rock_Stone"
    },
    {
      "x": -10,
      "y": 5,
      "z": 15,
      "name": "Rock_Stone"
    },
    {
      "x": -10,
      "y": 6,
      "z": 15,
      "name": "Rock_Stone"
    },
    {
      "x": -10,
      "y": 7,
      "z": 15,
      "name": "Rock_Stone"
    },
    {
      "x": -10,
      "y": 8,
      "z": 15,
      "name": "Rock_Stone"
    },
    {
      "x": -10,
      "y": 9,
      "z": 15,
      "name": "Rock_Stone"
    },
    {
      "x": -10,
      "y": 10,
      "z": 15,
      "name": "Rock_Stone"
    },
    {
      "x": -10,
      "y": 11,
      "z": 15,
      "name": "Rock_Stone"
    },
    {
      "x": -10,
      "y": 12,
      "z": 15,
      "name": "Rock_Stone"
    },
    {
      "x": -10,
      "y": 13,
      "z": 15,
      "name": "Rock_Stone"
    },
    {
      "x": -10,
      "y": 14,
      "z": 15,
      "name": "Rock_Stone"
    },
    {
      "x": -10,
      "y": -1,
      "z": 16,
      "name": "Rock_Stone"
    },
    {
      "x": -10,
      "y": 0,
      "z": 16,
      "name": "Rock_Stone"
    },
    {
      "x": -10,
      "y": 1,
      "z": 16,
      "name": "Rock_Stone"
    },
    {
      "x": -10,
      "y": 2,
      "z": 16,
      "name": "Rock_Stone"
    },
    {
      "x": -10,
      "y": 3,
      "z": 16,
      "name": "Rock_Stone"
    },
    {
      "x": -10,
      "y": 4,
      "z": 16,
      "name": "Rock_Stone"
    },
    {
      "x": -10,
      "y": 5,
      "z": 16,
      "name": "Rock_Stone"
    },
    {
      "x": -10,
      "y": 6,
      "z": 16,
      "name": "Rock_Stone"
    },
    {
      "x": -10,
      "y": 7,
      "z": 16,
      "name": "Rock_Stone"
    },
    {
      "x": -10,
      "y": 8,
      "z": 16,
      "name": "Rock_Stone"
    },
    {
      "x": -10,
      "y": 9,
      "z": 16,
      "name": "Rock_Stone"
    },
    {
      "x": -10,
      "y": 10,
      "z": 16,
      "name": "Rock_Stone"
    },
    {
      "x": -10,
      "y": 11,
      "z": 16,
      "name": "Rock_Stone"
    },
    {
      "x": -10,
      "y": 12,
      "z": 16,
      "name": "Rock_Stone"
    },
    {
      "x": -10,
      "y": 13,
      "z": 16,
      "name": "Rock_Stone"
    },
    {
      "x": -10,
      "y": 14,
      "z": 16,
      "name": "Rock_Stone"
    },
    {
      "x": -10,
      "y": -1,
      "z": 17,
      "name": "Rock_Stone"
    },
    {
      "x": -10,
      "y": 0,
      "z": 17,
      "name": "Rock_Stone"
    },
    {
      "x": -10,
      "y": 1,
      "z": 17,
      "name": "Rock_Stone"
    },
    {
      "x": -10,
      "y": 2,
      "z": 17,
      "name": "Rock_Stone"
    },
    {
      "x": -10,
      "y": 3,
      "z": 17,
      "name": "Rock_Stone"
    },
    {
      "x": -10,
      "y": 4,
      "z": 17,
      "name": "Rock_Stone"
    },
    {
      "x": -10,
      "y": 5,
      "z": 17,
      "name": "Rock_Stone"
    },
    {
      "x": -10,
      "y": 6,
      "z": 17,
      "name": "Rock_Stone"
    },
    {
      "x": -10,
      "y": 7,
      "z": 17,
      "name": "Rock_Stone"
    },
    {
      "x": -10,
      "y": 8,
      "z": 17,
      "name": "Rock_Stone"
    },
    {
      "x": -10,
      "y": 9,
      "z": 17,
      "name": "Rock_Stone"
    },
    {
      "x": -10,
      "y": 10,
      "z": 17,
      "name": "Rock_Stone"
    },
    {
      "x": -10,
      "y": 11,
      "z": 17,
      "name": "Rock_Stone"
    },
    {
      "x": -10,
      "y": 12,
      "z": 17,
      "name": "Rock_Stone"
    },
    {
      "x": -10,
      "y": 13,
      "z": 17,
      "name": "Rock_Stone"
    },
    {
      "x": -10,
      "y": 14,
      "z": 17,
      "name": "Rock_Stone"
    },
    {
      "x": -10,
      "y": -1,
      "z": 18,
      "name": "Rock_Stone"
    },
    {
      "x": -10,
      "y": 0,
      "z": 18,
      "name": "Rock_Stone"
    },
    {
      "x": -10,
      "y": 1,
      "z": 18,
      "name": "Rock_Stone"
    },
    {
      "x": -10,
      "y": 2,
      "z": 18,
      "name": "Rock_Stone"
    },
    {
      "x": -10,
      "y": 3,
      "z": 18,
      "name": "Rock_Stone"
    },
    {
      "x": -10,
      "y": 4,
      "z": 18,
      "name": "Rock_Stone"
    },
    {
      "x": -10,
      "y": 5,
      "z": 18,
      "name": "Rock_Stone"
    },
    {
      "x": -10,
      "y": 6,
      "z": 18,
      "name": "Rock_Stone"
    },
    {
      "x": -10,
      "y": 7,
      "z": 18,
      "name": "Rock_Stone"
    },
    {
      "x": -10,
      "y": 8,
      "z": 18,
      "name": "Rock_Stone"
    },
    {
      "x": -10,
      "y": 9,
      "z": 18,
      "name": "Rock_Stone"
    },
    {
      "x": -10,
      "y": 10,
      "z": 18,
      "name": "Rock_Stone"
    },
    {
      "x": -10,
      "y": 11,
      "z": 18,
      "name": "Rock_Stone"
    },
    {
      "x": -10,
      "y": 12,
      "z": 18,
      "name": "Rock_Stone"
    },
    {
      "x": -10,
      "y": 13,
      "z": 18,
      "name": "Rock_Stone"
    },
    {
      "x": -10,
      "y": 14,
      "z": 18,
      "name": "Rock_Stone"
    },
    {
      "x": -10,
      "y": -1,
      "z": 19,
      "name": "Rock_Stone"
    },
    {
      "x": -10,
      "y": 0,
      "z": 19,
      "name": "Rock_Stone"
    },
    {
      "x": -10,
      "y": 1,
      "z": 19,
      "name": "Rock_Stone"
    },
    {
      "x": -10,
      "y": 2,
      "z": 19,
      "name": "Rock_Stone"
    },
    {
      "x": -10,
      "y": 3,
      "z": 19,
      "name": "Rock_Stone"
    },
    {
      "x": -10,
      "y": 4,
      "z": 19,
      "name": "Rock_Stone"
    },
    {
      "x": -10,
      "y": 5,
      "z": 19,
      "name": "Rock_Stone"
    },
    {
      "x": -10,
      "y": 6,
      "z": 19,
      "name": "Rock_Stone"
    },
    {
      "x": -10,
      "y": 7,
      "z": 19,
      "name": "Rock_Stone"
    },
    {
      "x": -10,
      "y": 8,
      "z": 19,
      "name": "Rock_Stone"
    },
    {
      "x": -10,
      "y": 9,
      "z": 19,
      "name": "Rock_Stone"
    },
    {
      "x": -10,
      "y": 10,
      "z": 19,
      "name": "Rock_Stone"
    },
    {
      "x": -10,
      "y": 11,
      "z": 19,
      "name": "Rock_Stone"
    },
    {
      "x": -10,
      "y": 12,
      "z": 19,
      "name": "Rock_Stone"
    },
    {
      "x": -10,
      "y": 13,
      "z": 19,
      "name": "Rock_Stone"
    },
    {
      "x": -10,
      "y": 14,
      "z": 19,
      "name": "Rock_Stone"
    },
    {
      "x": -10,
      "y": -1,
      "z": 20,
      "name": "Rock_Stone"
    },
    {
      "x": -10,
      "y": 0,
      "z": 20,
      "name": "Rock_Stone"
    },
    {
      "x": -10,
      "y": 1,
      "z": 20,
      "name": "Rock_Stone"
    },
    {
      "x": -10,
      "y": 2,
      "z": 20,
      "name": "Rock_Stone"
    },
    {
      "x": -10,
      "y": 3,
      "z": 20,
      "name": "Rock_Stone"
    },
    {
      "x": -10,
      "y": 4,
      "z": 20,
      "name": "Rock_Stone"
    },
    {
      "x": -10,
      "y": 5,
      "z": 20,
      "name": "Rock_Stone"
    },
    {
      "x": -10,
      "y": 6,
      "z": 20,
      "name": "Rock_Stone"
    },
    {
      "x": -10,
      "y": 7,
      "z": 20,
      "name": "Rock_Stone"
    },
    {
      "x": -10,
      "y": 8,
      "z": 20,
      "name": "Rock_Stone"
    },
    {
      "x": -10,
      "y": 9,
      "z": 20,
      "name": "Rock_Stone"
    },
    {
      "x": -10,
      "y": 10,
      "z": 20,
      "name": "Rock_Stone"
    },
    {
      "x": -10,
      "y": 11,
      "z": 20,
      "name": "Rock_Stone"
    },
    {
      "x": -10,
      "y": 12,
      "z": 20,
      "name": "Rock_Stone"
    },
    {
      "x": -10,
      "y": 13,
      "z": 20,
      "name": "Rock_Stone"
    },
    {
      "x": -10,
      "y": 14,
      "z": 20,
      "name": "Rock_Stone"
    },
    {
      "x": -9,
      "y": -1,
      "z": 0,
      "name": "Rock_Stone"
    },
    {
      "x": -9,
      "y": 0,
      "z": 0,
      "name": "Rock_Stone"
    },
    {
      "x": -9,
      "y": 1,
      "z": 0,
      "name": "Rock_Stone"
    },
    {
      "x": -9,
      "y": 2,
      "z": 0,
      "name": "Rock_Stone"
    },
    {
      "x": -9,
      "y": 3,
      "z": 0,
      "name": "Rock_Stone"
    },
    {
      "x": -9,
      "y": 4,
      "z": 0,
      "name": "Rock_Stone"
    },
    {
      "x": -9,
      "y": 5,
      "z": 0,
      "name": "Rock_Stone"
    },
    {
      "x": -9,
      "y": 6,
      "z": 0,
      "name": "Rock_Stone"
    },
    {
      "x": -9,
      "y": 7,
      "z": 0,
      "name": "Rock_Stone"
    },
    {
      "x": -9,
      "y": 8,
      "z": 0,
      "name": "Rock_Stone"
    },
    {
      "x": -9,
      "y": 9,
      "z": 0,
      "name": "Rock_Stone"
    },
    {
      "x": -9,
      "y": 10,
      "z": 0,
      "name": "Rock_Stone"
    },
    {
      "x": -9,
      "y": 11,
      "z": 0,
      "name": "Rock_Stone"
    },
    {
      "x": -9,
      "y": 12,
      "z": 0,
      "name": "Rock_Stone"
    },
    {
      "x": -9,
      "y": 13,
      "z": 0,
      "name": "Rock_Stone"
    },
    {
      "x": -9,
      "y": 14,
      "z": 0,
      "name": "Rock_Stone"
    },
    {
      "x": -9,
      "y": -1,
      "z": 1,
      "name": "Rock_Stone"
    },
    {
      "x": -9,
      "y": 0,
      "z": 1,
      "name": "Rock_Stone"
    },
    {
      "x": -9,
      "y": 1,
      "z": 1,
      "name": "Rock_Stone"
    },
    {
      "x": -9,
      "y": 2,
      "z": 1,
      "name": "Rock_Stone"
    },
    {
      "x": -9,
      "y": 3,
      "z": 1,
      "name": "Rock_Stone"
    },
    {
      "x": -9,
      "y": 4,
      "z": 1,
      "name": "Rock_Stone"
    },
    {
      "x": -9,
      "y": 5,
      "z": 1,
      "name": "Rock_Stone"
    },
    {
      "x": -9,
      "y": 6,
      "z": 1,
      "name": "Rock_Stone"
    },
    {
      "x": -9,
      "y": 7,
      "z": 1,
      "name": "Rock_Stone"
    },
    {
      "x": -9,
      "y": 8,
      "z": 1,
      "name": "Rock_Stone"
    },
    {
      "x": -9,
      "y": 9,
      "z": 1,
      "name": "Rock_Stone"
    },
    {
      "x": -9,
      "y": 10,
      "z": 1,
      "name": "Rock_Stone"
    },
    {
      "x": -9,
      "y": 11,
      "z": 1,
      "name": "Rock_Stone"
    },
    {
      "x": -9,
      "y": 12,
      "z": 1,
      "name": "Rock_Stone"
    },
    {
      "x": -9,
      "y": 13,
      "z": 1,
      "name": "Rock_Stone"
    },
    {
      "x": -9,
      "y": 14,
      "z": 1,
      "name": "Rock_Stone"
    },
    {
      "x": -9,
      "y": -1,
      "z": 2,
      "name": "Rock_Stone"
    },
    {
      "x": -9,
      "y": 0,
      "z": 2,
      "name": "Rock_Stone"
    },
    {
      "x": -9,
      "y": 1,
      "z": 2,
      "name": "Rock_Stone"
    },
    {
      "x": -9,
      "y": 2,
      "z": 2,
      "name": "Rock_Stone"
    },
    {
      "x": -9,
      "y": 3,
      "z": 2,
      "name": "Rock_Stone"
    },
    {
      "x": -9,
      "y": 4,
      "z": 2,
      "name": "Rock_Stone"
    },
    {
      "x": -9,
      "y": 5,
      "z": 2,
      "name": "Rock_Stone"
    },
    {
      "x": -9,
      "y": 6,
      "z": 2,
      "name": "Rock_Stone"
    },
    {
      "x": -9,
      "y": 7,
      "z": 2,
      "name": "Rock_Stone"
    },
    {
      "x": -9,
      "y": 8,
      "z": 2,
      "name": "Rock_Stone"
    },
    {
      "x": -9,
      "y": 9,
      "z": 2,
      "name": "Rock_Stone"
    },
    {
      "x": -9,
      "y": 10,
      "z": 2,
      "name": "Rock_Stone"
    },
    {
      "x": -9,
      "y": 11,
      "z": 2,
      "name": "Rock_Stone"
    },
    {
      "x": -9,
      "y": 12,
      "z": 2,
      "name": "Rock_Stone"
    },
    {
      "x": -9,
      "y": 13,
      "z": 2,
      "name": "Rock_Stone"
    },
    {
      "x": -9,
      "y": 14,
      "z": 2,
      "name": "Rock_Stone"
    },
    {
      "x": -9,
      "y": -1,
      "z": 3,
      "name": "Rock_Stone"
    },
    {
      "x": -9,
      "y": 0,
      "z": 3,
      "name": "Rock_Stone"
    },
    {
      "x": -9,
      "y": 1,
      "z": 3,
      "name": "Rock_Stone"
    },
    {
      "x": -9,
      "y": 2,
      "z": 3,
      "name": "Rock_Stone"
    },
    {
      "x": -9,
      "y": 3,
      "z": 3,
      "name": "Rock_Stone"
    },
    {
      "x": -9,
      "y": 4,
      "z": 3,
      "name": "Rock_Stone"
    },
    {
      "x": -9,
      "y": 5,
      "z": 3,
      "name": "Rock_Stone"
    },
    {
      "x": -9,
      "y": 6,
      "z": 3,
      "name": "Rock_Stone"
    },
    {
      "x": -9,
      "y": 7,
      "z": 3,
      "name": "Rock_Stone"
    },
    {
      "x": -9,
      "y": 8,
      "z": 3,
      "name": "Rock_Stone"
    },
    {
      "x": -9,
      "y": 9,
      "z": 3,
      "name": "Rock_Stone"
    },
    {
      "x": -9,
      "y": 10,
      "z": 3,
      "name": "Rock_Stone"
    },
    {
      "x": -9,
      "y": 11,
      "z": 3,
      "name": "Rock_Stone"
    },
    {
      "x": -9,
      "y": 12,
      "z": 3,
      "name": "Rock_Stone"
    },
    {
      "x": -9,
      "y": 13,
      "z": 3,
      "name": "Rock_Stone"
    },
    {
      "x": -9,
      "y": 14,
      "z": 3,
      "name": "Rock_Stone"
    },
    {
      "x": -9,
      "y": -1,
      "z": 4,
      "name": "Rock_Stone"
    },
    {
      "x": -9,
      "y": 0,
      "z": 4,
      "name": "Rock_Stone"
    },
    {
      "x": -9,
      "y": 1,
      "z": 4,
      "name": "Rock_Stone"
    },
    {
      "x": -9,
      "y": 2,
      "z": 4,
      "name": "Rock_Stone"
    },
    {
      "x": -9,
      "y": 3,
      "z": 4,
      "name": "Rock_Stone"
    },
    {
      "x": -9,
      "y": 4,
      "z": 4,
      "name": "Rock_Stone"
    },
    {
      "x": -9,
      "y": 5,
      "z": 4,
      "name": "Rock_Stone"
    },
    {
      "x": -9,
      "y": 6,
      "z": 4,
      "name": "Rock_Stone"
    },
    {
      "x": -9,
      "y": 7,
      "z": 4,
      "name": "Rock_Stone"
    },
    {
      "x": -9,
      "y": 8,
      "z": 4,
      "name": "Rock_Stone"
    },
    {
      "x": -9,
      "y": 9,
      "z": 4,
      "name": "Rock_Stone"
    },
    {
      "x": -9,
      "y": 10,
      "z": 4,
      "name": "Rock_Stone"
    },
    {
      "x": -9,
      "y": 11,
      "z": 4,
      "name": "Rock_Stone"
    },
    {
      "x": -9,
      "y": 12,
      "z": 4,
      "name": "Rock_Stone"
    },
    {
      "x": -9,
      "y": 13,
      "z": 4,
      "name": "Rock_Stone"
    },
    {
      "x": -9,
      "y": 14,
      "z": 4,
      "name": "Rock_Stone"
    },
    {
      "x": -9,
      "y": -1,
      "z": 5,
      "name": "Rock_Stone"
    },
    {
      "x": -9,
      "y": 0,
      "z": 5,
      "name": "Rock_Stone"
    },
    {
      "x": -9,
      "y": 1,
      "z": 5,
      "name": "Rock_Stone"
    },
    {
      "x": -9,
      "y": 2,
      "z": 5,
      "name": "Rock_Stone"
    },
    {
      "x": -9,
      "y": 3,
      "z": 5,
      "name": "Rock_Stone"
    },
    {
      "x": -9,
      "y": 4,
      "z": 5,
      "name": "Rock_Stone"
    },
    {
      "x": -9,
      "y": 5,
      "z": 5,
      "name": "Rock_Stone"
    },
    {
      "x": -9,
      "y": 6,
      "z": 5,
      "name": "Rock_Stone"
    },
    {
      "x": -9,
      "y": 7,
      "z": 5,
      "name": "Rock_Stone"
    },
    {
      "x": -9,
      "y": 8,
      "z": 5,
      "name": "Rock_Stone"
    },
    {
      "x": -9,
      "y": 9,
      "z": 5,
      "name": "Rock_Stone"
    },
    {
      "x": -9,
      "y": 10,
      "z": 5,
      "name": "Rock_Stone"
    },
    {
      "x": -9,
      "y": 11,
      "z": 5,
      "name": "Rock_Stone"
    },
    {
      "x": -9,
      "y": 12,
      "z": 5,
      "name": "Rock_Stone"
    },
    {
      "x": -9,
      "y": 13,
      "z": 5,
      "name": "Rock_Stone"
    },
    {
      "x": -9,
      "y": 14,
      "z": 5,
      "name": "Rock_Stone"
    },
    {
      "x": -9,
      "y": -1,
      "z": 6,
      "name": "Rock_Stone"
    },
    {
      "x": -9,
      "y": 0,
      "z": 6,
      "name": "Rock_Stone"
    },
    {
      "x": -9,
      "y": 1,
      "z": 6,
      "name": "Rock_Stone"
    },
    {
      "x": -9,
      "y": 2,
      "z": 6,
      "name": "Rock_Stone"
    },
    {
      "x": -9,
      "y": 3,
      "z": 6,
      "name": "Rock_Stone"
    },
    {
      "x": -9,
      "y": 4,
      "z": 6,
      "name": "Rock_Stone"
    },
    {
      "x": -9,
      "y": 5,
      "z": 6,
      "name": "Rock_Stone"
    },
    {
      "x": -9,
      "y": 6,
      "z": 6,
      "name": "Rock_Stone"
    },
    {
      "x": -9,
      "y": 7,
      "z": 6,
      "name": "Rock_Stone"
    },
    {
      "x": -9,
      "y": 8,
      "z": 6,
      "name": "Rock_Stone"
    },
    {
      "x": -9,
      "y": 9,
      "z": 6,
      "name": "Rock_Stone"
    },
    {
      "x": -9,
      "y": 10,
      "z": 6,
      "name": "Rock_Stone"
    },
    {
      "x": -9,
      "y": 11,
      "z": 6,
      "name": "Rock_Stone"
    },
    {
      "x": -9,
      "y": 12,
      "z": 6,
      "name": "Rock_Stone"
    },
    {
      "x": -9,
      "y": 13,
      "z": 6,
      "name": "Rock_Stone"
    },
    {
      "x": -9,
      "y": 14,
      "z": 6,
      "name": "Rock_Stone"
    },
    {
      "x": -9,
      "y": -1,
      "z": 7,
      "name": "Rock_Stone"
    },
    {
      "x": -9,
      "y": 0,
      "z": 7,
      "name": "Rock_Stone"
    },
    {
      "x": -9,
      "y": 1,
      "z": 7,
      "name": "Rock_Stone"
    },
    {
      "x": -9,
      "y": 2,
      "z": 7,
      "name": "Rock_Stone"
    },
    {
      "x": -9,
      "y": 3,
      "z": 7,
      "name": "Rock_Stone"
    },
    {
      "x": -9,
      "y": 4,
      "z": 7,
      "name": "Rock_Stone"
    },
    {
      "x": -9,
      "y": 5,
      "z": 7,
      "name": "Rock_Stone"
    },
    {
      "x": -9,
      "y": 6,
      "z": 7,
      "name": "Rock_Stone"
    },
    {
      "x": -9,
      "y": 7,
      "z": 7,
      "name": "Rock_Stone"
    },
    {
      "x": -9,
      "y": 8,
      "z": 7,
      "name": "Rock_Stone"
    },
    {
      "x": -9,
      "y": 9,
      "z": 7,
      "name": "Rock_Stone"
    },
    {
      "x": -9,
      "y": 10,
      "z": 7,
      "name": "Rock_Stone"
    },
    {
      "x": -9,
      "y": 11,
      "z": 7,
      "name": "Rock_Stone"
    },
    {
      "x": -9,
      "y": 12,
      "z": 7,
      "name": "Rock_Stone"
    },
    {
      "x": -9,
      "y": 13,
      "z": 7,
      "name": "Rock_Stone"
    },
    {
      "x": -9,
      "y": 14,
      "z": 7,
      "name": "Rock_Stone"
    },
    {
      "x": -9,
      "y": -1,
      "z": 8,
      "name": "Rock_Stone"
    },
    {
      "x": -9,
      "y": 0,
      "z": 8,
      "name": "Rock_Stone"
    },
    {
      "x": -9,
      "y": 1,
      "z": 8,
      "name": "Rock_Stone"
    },
    {
      "x": -9,
      "y": 2,
      "z": 8,
      "name": "Rock_Stone"
    },
    {
      "x": -9,
      "y": 3,
      "z": 8,
      "name": "Rock_Stone"
    },
    {
      "x": -9,
      "y": 4,
      "z": 8,
      "name": "Rock_Stone"
    },
    {
      "x": -9,
      "y": 5,
      "z": 8,
      "name": "Rock_Stone"
    },
    {
      "x": -9,
      "y": 6,
      "z": 8,
      "name": "Rock_Stone"
    },
    {
      "x": -9,
      "y": 7,
      "z": 8,
      "name": "Rock_Stone"
    },
    {
      "x": -9,
      "y": 8,
      "z": 8,
      "name": "Rock_Stone"
    },
    {
      "x": -9,
      "y": 9,
      "z": 8,
      "name": "Rock_Stone"
    },
    {
      "x": -9,
      "y": 10,
      "z": 8,
      "name": "Rock_Stone"
    },
    {
      "x": -9,
      "y": 11,
      "z": 8,
      "name": "Rock_Stone"
    },
    {
      "x": -9,
      "y": 12,
      "z": 8,
      "name": "Rock_Stone"
    },
    {
      "x": -9,
      "y": 13,
      "z": 8,
      "name": "Rock_Stone"
    },
    {
      "x": -9,
      "y": 14,
      "z": 8,
      "name": "Rock_Stone"
    },
    {
      "x": -9,
      "y": -1,
      "z": 9,
      "name": "Rock_Stone"
    },
    {
      "x": -9,
      "y": 0,
      "z": 9,
      "name": "Rock_Stone"
    },
    {
      "x": -9,
      "y": 1,
      "z": 9,
      "name": "Rock_Stone"
    },
    {
      "x": -9,
      "y": 2,
      "z": 9,
      "name": "Rock_Stone"
    },
    {
      "x": -9,
      "y": 3,
      "z": 9,
      "name": "Rock_Stone"
    },
    {
      "x": -9,
      "y": 4,
      "z": 9,
      "name": "Rock_Stone"
    },
    {
      "x": -9,
      "y": 5,
      "z": 9,
      "name": "Rock_Stone"
    },
    {
      "x": -9,
      "y": 6,
      "z": 9,
      "name": "Empty"
    },
    {
      "x": -9,
      "y": 7,
      "z": 9,
      "name": "Empty"
    },
    {
      "x": -9,
      "y": 8,
      "z": 9,
      "name": "Rock_Stone"
    },
    {
      "x": -9,
      "y": 9,
      "z": 9,
      "name": "Rock_Stone"
    },
    {
      "x": -9,
      "y": 10,
      "z": 9,
      "name": "Rock_Stone"
    },
    {
      "x": -9,
      "y": 11,
      "z": 9,
      "name": "Rock_Stone"
    },
    {
      "x": -9,
      "y": 12,
      "z": 9,
      "name": "Rock_Stone"
    },
    {
      "x": -9,
      "y": 13,
      "z": 9,
      "name": "Rock_Stone"
    },
    {
      "x": -9,
      "y": 14,
      "z": 9,
      "name": "Rock_Stone"
    },
    {
      "x": -9,
      "y": -1,
      "z": 10,
      "name": "Rock_Stone"
    },
    {
      "x": -9,
      "y": 0,
      "z": 10,
      "name": "Rock_Stone"
    },
    {
      "x": -9,
      "y": 1,
      "z": 10,
      "name": "Rock_Stone"
    },
    {
      "x": -9,
      "y": 2,
      "z": 10,
      "name": "Rock_Stone"
    },
    {
      "x": -9,
      "y": 3,
      "z": 10,
      "name": "Rock_Stone"
    },
    {
      "x": -9,
      "y": 4,
      "z": 10,
      "name": "Wood_Beech_Trunk"
    },
    {
      "x": -9,
      "y": 5,
      "z": 10,
      "name": "Wood_Beech_Trunk"
    },
    {
      "x": -9,
      "y": 6,
      "z": 10,
      "name": "Wood_Softwood_Planks_Half"
    },
    {
      "x": -9,
      "y": 7,
      "z": 10,
      "name": "Empty"
    },
    {
      "x": -9,
      "y": 8,
      "z": 10,
      "name": "Empty"
    },
    {
      "x": -9,
      "y": 9,
      "z": 10,
      "name": "Empty"
    },
    {
      "x": -9,
      "y": 10,
      "z": 10,
      "name": "Rock_Stone"
    },
    {
      "x": -9,
      "y": 11,
      "z": 10,
      "name": "Rock_Stone"
    },
    {
      "x": -9,
      "y": 12,
      "z": 10,
      "name": "Rock_Stone"
    },
    {
      "x": -9,
      "y": 13,
      "z": 10,
      "name": "Rock_Stone"
    },
    {
      "x": -9,
      "y": 14,
      "z": 10,
      "name": "Rock_Stone"
    },
    {
      "x": -9,
      "y": -1,
      "z": 11,
      "name": "Rock_Stone"
    },
    {
      "x": -9,
      "y": 0,
      "z": 11,
      "name": "Rock_Stone"
    },
    {
      "x": -9,
      "y": 1,
      "z": 11,
      "name": "Rock_Stone"
    },
    {
      "x": -9,
      "y": 2,
      "z": 11,
      "name": "Rock_Stone"
    },
    {
      "x": -9,
      "y": 3,
      "z": 11,
      "name": "Rock_Stone"
    },
    {
      "x": -9,
      "y": 4,
      "z": 11,
      "name": "Rock_Stone"
    },
    {
      "x": -9,
      "y": 5,
      "z": 11,
      "name": "Empty"
    },
    {
      "x": -9,
      "y": 6,
      "z": 11,
      "name": "Empty"
    },
    {
      "x": -9,
      "y": 7,
      "z": 11,
      "name": "Empty"
    },
    {
      "x": -9,
      "y": 8,
      "z": 11,
      "name": "Empty"
    },
    {
      "x": -9,
      "y": 9,
      "z": 11,
      "name": "Empty"
    },
    {
      "x": -9,
      "y": 10,
      "z": 11,
      "name": "Empty"
    },
    {
      "x": -9,
      "y": 11,
      "z": 11,
      "name": "Rock_Stone"
    },
    {
      "x": -9,
      "y": 12,
      "z": 11,
      "name": "Rock_Stone"
    },
    {
      "x": -9,
      "y": 13,
      "z": 11,
      "name": "Rock_Stone"
    },
    {
      "x": -9,
      "y": 14,
      "z": 11,
      "name": "Rock_Stone"
    },
    {
      "x": -9,
      "y": -1,
      "z": 12,
      "name": "Rock_Stone"
    },
    {
      "x": -9,
      "y": 0,
      "z": 12,
      "name": "Rock_Stone"
    },
    {
      "x": -9,
      "y": 1,
      "z": 12,
      "name": "Rock_Stone"
    },
    {
      "x": -9,
      "y": 2,
      "z": 12,
      "name": "Rock_Stone"
    },
    {
      "x": -9,
      "y": 3,
      "z": 12,
      "name": "Rock_Stone"
    },
    {
      "x": -9,
      "y": 4,
      "z": 12,
      "name": "Empty"
    },
    {
      "x": -9,
      "y": 5,
      "z": 12,
      "name": "Empty"
    },
    {
      "x": -9,
      "y": 6,
      "z": 12,
      "name": "Empty"
    },
    {
      "x": -9,
      "y": 7,
      "z": 12,
      "name": "Empty"
    },
    {
      "x": -9,
      "y": 8,
      "z": 12,
      "name": "Empty"
    },
    {
      "x": -9,
      "y": 9,
      "z": 12,
      "name": "Empty"
    },
    {
      "x": -9,
      "y": 10,
      "z": 12,
      "name": "Empty"
    },
    {
      "x": -9,
      "y": 11,
      "z": 12,
      "name": "Rock_Stone"
    },
    {
      "x": -9,
      "y": 12,
      "z": 12,
      "name": "Rock_Stone"
    },
    {
      "x": -9,
      "y": 13,
      "z": 12,
      "name": "Rock_Stone"
    },
    {
      "x": -9,
      "y": 14,
      "z": 12,
      "name": "Rock_Stone"
    },
    {
      "x": -9,
      "y": -1,
      "z": 13,
      "name": "Rock_Stone"
    },
    {
      "x": -9,
      "y": 0,
      "z": 13,
      "name": "Rock_Stone"
    },
    {
      "x": -9,
      "y": 1,
      "z": 13,
      "name": "Rock_Stone"
    },
    {
      "x": -9,
      "y": 2,
      "z": 13,
      "name": "Rock_Stone"
    },
    {
      "x": -9,
      "y": 3,
      "z": 13,
      "name": "Rock_Stone"
    },
    {
      "x": -9,
      "y": 4,
      "z": 13,
      "name": "Empty"
    },
    {
      "x": -9,
      "y": 5,
      "z": 13,
      "name": "Empty"
    },
    {
      "x": -9,
      "y": 6,
      "z": 13,
      "name": "Empty"
    },
    {
      "x": -9,
      "y": 7,
      "z": 13,
      "name": "Empty"
    },
    {
      "x": -9,
      "y": 8,
      "z": 13,
      "name": "Empty"
    },
    {
      "x": -9,
      "y": 9,
      "z": 13,
      "name": "Rock_Stone_Stalactite_Small",
      "rotation": 8
    },
    {
      "x": -9,
      "y": 10,
      "z": 13,
      "name": "Rock_Stone"
    },
    {
      "x": -9,
      "y": 11,
      "z": 13,
      "name": "Rock_Stone"
    },
    {
      "x": -9,
      "y": 12,
      "z": 13,
      "name": "Rock_Stone"
    },
    {
      "x": -9,
      "y": 13,
      "z": 13,
      "name": "Rock_Stone"
    },
    {
      "x": -9,
      "y": 14,
      "z": 13,
      "name": "Rock_Stone"
    },
    {
      "x": -9,
      "y": -1,
      "z": 14,
      "name": "Rock_Stone"
    },
    {
      "x": -9,
      "y": 0,
      "z": 14,
      "name": "Rock_Stone"
    },
    {
      "x": -9,
      "y": 1,
      "z": 14,
      "name": "Rock_Stone"
    },
    {
      "x": -9,
      "y": 2,
      "z": 14,
      "name": "Rock_Stone"
    },
    {
      "x": -9,
      "y": 3,
      "z": 14,
      "name": "Rock_Stone"
    },
    {
      "x": -9,
      "y": 4,
      "z": 14,
      "name": "Rock_Stone_Cobble"
    },
    {
      "x": -9,
      "y": 5,
      "z": 14,
      "name": "Empty"
    },
    {
      "x": -9,
      "y": 6,
      "z": 14,
      "name": "Empty"
    },
    {
      "x": -9,
      "y": 7,
      "z": 14,
      "name": "Empty"
    },
    {
      "x": -9,
      "y": 8,
      "z": 14,
      "name": "Empty"
    },
    {
      "x": -9,
      "y": 9,
      "z": 14,
      "name": "Empty"
    },
    {
      "x": -9,
      "y": 10,
      "z": 14,
      "name": "Rock_Stone"
    },
    {
      "x": -9,
      "y": 11,
      "z": 14,
      "name": "Rock_Stone"
    },
    {
      "x": -9,
      "y": 12,
      "z": 14,
      "name": "Rock_Stone"
    },
    {
      "x": -9,
      "y": 13,
      "z": 14,
      "name": "Rock_Stone"
    },
    {
      "x": -9,
      "y": 14,
      "z": 14,
      "name": "Rock_Stone"
    },
    {
      "x": -9,
      "y": -1,
      "z": 15,
      "name": "Rock_Stone"
    },
    {
      "x": -9,
      "y": 0,
      "z": 15,
      "name": "Rock_Stone"
    },
    {
      "x": -9,
      "y": 1,
      "z": 15,
      "name": "Rock_Stone"
    },
    {
      "x": -9,
      "y": 2,
      "z": 15,
      "name": "Rock_Stone"
    },
    {
      "x": -9,
      "y": 3,
      "z": 15,
      "name": "Rock_Stone"
    },
    {
      "x": -9,
      "y": 4,
      "z": 15,
      "name": "Rock_Stone_Cobble"
    },
    {
      "x": -9,
      "y": 5,
      "z": 15,
      "name": "Empty"
    },
    {
      "x": -9,
      "y": 6,
      "z": 15,
      "name": "Empty"
    },
    {
      "x": -9,
      "y": 7,
      "z": 15,
      "name": "Empty"
    },
    {
      "x": -9,
      "y": 8,
      "z": 15,
      "name": "Empty"
    },
    {
      "x": -9,
      "y": 9,
      "z": 15,
      "name": "Empty"
    },
    {
      "x": -9,
      "y": 10,
      "z": 15,
      "name": "Rock_Stone"
    },
    {
      "x": -9,
      "y": 11,
      "z": 15,
      "name": "Rock_Stone"
    },
    {
      "x": -9,
      "y": 12,
      "z": 15,
      "name": "Rock_Stone"
    },
    {
      "x": -9,
      "y": 13,
      "z": 15,
      "name": "Rock_Stone"
    },
    {
      "x": -9,
      "y": 14,
      "z": 15,
      "name": "Rock_Stone"
    },
    {
      "x": -9,
      "y": -1,
      "z": 16,
      "name": "Rock_Stone"
    },
    {
      "x": -9,
      "y": 0,
      "z": 16,
      "name": "Rock_Stone"
    },
    {
      "x": -9,
      "y": 1,
      "z": 16,
      "name": "Rock_Stone"
    },
    {
      "x": -9,
      "y": 2,
      "z": 16,
      "name": "Rock_Stone"
    },
    {
      "x": -9,
      "y": 3,
      "z": 16,
      "name": "Rock_Stone"
    },
    {
      "x": -9,
      "y": 4,
      "z": 16,
      "name": "Rock_Stone"
    },
    {
      "x": -9,
      "y": 5,
      "z": 16,
      "name": "Rock_Stone"
    },
    {
      "x": -9,
      "y": 6,
      "z": 16,
      "name": "Empty"
    },
    {
      "x": -9,
      "y": 7,
      "z": 16,
      "name": "Empty"
    },
    {
      "x": -9,
      "y": 8,
      "z": 16,
      "name": "Empty"
    },
    {
      "x": -9,
      "y": 9,
      "z": 16,
      "name": "Empty"
    },
    {
      "x": -9,
      "y": 10,
      "z": 16,
      "name": "Rock_Stone"
    },
    {
      "x": -9,
      "y": 11,
      "z": 16,
      "name": "Rock_Stone"
    },
    {
      "x": -9,
      "y": 12,
      "z": 16,
      "name": "Rock_Stone"
    },
    {
      "x": -9,
      "y": 13,
      "z": 16,
      "name": "Rock_Stone"
    },
    {
      "x": -9,
      "y": 14,
      "z": 16,
      "name": "Rock_Stone"
    },
    {
      "x": -9,
      "y": -1,
      "z": 17,
      "name": "Rock_Stone"
    },
    {
      "x": -9,
      "y": 0,
      "z": 17,
      "name": "Rock_Stone"
    },
    {
      "x": -9,
      "y": 1,
      "z": 17,
      "name": "Rock_Stone"
    },
    {
      "x": -9,
      "y": 2,
      "z": 17,
      "name": "Rock_Stone"
    },
    {
      "x": -9,
      "y": 3,
      "z": 17,
      "name": "Rock_Stone"
    },
    {
      "x": -9,
      "y": 4,
      "z": 17,
      "name": "Rock_Stone"
    },
    {
      "x": -9,
      "y": 5,
      "z": 17,
      "name": "Rock_Stone"
    },
    {
      "x": -9,
      "y": 6,
      "z": 17,
      "name": "Rock_Stone"
    },
    {
      "x": -9,
      "y": 7,
      "z": 17,
      "name": "Empty"
    },
    {
      "x": -9,
      "y": 8,
      "z": 17,
      "name": "Empty"
    },
    {
      "x": -9,
      "y": 9,
      "z": 17,
      "name": "Rock_Stone"
    },
    {
      "x": -9,
      "y": 10,
      "z": 17,
      "name": "Rock_Stone"
    },
    {
      "x": -9,
      "y": 11,
      "z": 17,
      "name": "Rock_Stone"
    },
    {
      "x": -9,
      "y": 12,
      "z": 17,
      "name": "Rock_Stone"
    },
    {
      "x": -9,
      "y": 13,
      "z": 17,
      "name": "Rock_Stone"
    },
    {
      "x": -9,
      "y": 14,
      "z": 17,
      "name": "Rock_Stone"
    },
    {
      "x": -9,
      "y": -1,
      "z": 18,
      "name": "Rock_Stone"
    },
    {
      "x": -9,
      "y": 0,
      "z": 18,
      "name": "Rock_Stone"
    },
    {
      "x": -9,
      "y": 1,
      "z": 18,
      "name": "Rock_Stone"
    },
    {
      "x": -9,
      "y": 2,
      "z": 18,
      "name": "Rock_Stone"
    },
    {
      "x": -9,
      "y": 3,
      "z": 18,
      "name": "Rock_Stone"
    },
    {
      "x": -9,
      "y": 4,
      "z": 18,
      "name": "Rock_Stone"
    },
    {
      "x": -9,
      "y": 5,
      "z": 18,
      "name": "Rock_Stone"
    },
    {
      "x": -9,
      "y": 6,
      "z": 18,
      "name": "Rock_Stone"
    },
    {
      "x": -9,
      "y": 7,
      "z": 18,
      "name": "Rock_Stone"
    },
    {
      "x": -9,
      "y": 8,
      "z": 18,
      "name": "Rock_Stone"
    },
    {
      "x": -9,
      "y": 9,
      "z": 18,
      "name": "Rock_Stone"
    },
    {
      "x": -9,
      "y": 10,
      "z": 18,
      "name": "Rock_Stone"
    },
    {
      "x": -9,
      "y": 11,
      "z": 18,
      "name": "Rock_Stone"
    },
    {
      "x": -9,
      "y": 12,
      "z": 18,
      "name": "Rock_Stone"
    },
    {
      "x": -9,
      "y": 13,
      "z": 18,
      "name": "Rock_Stone"
    },
    {
      "x": -9,
      "y": 14,
      "z": 18,
      "name": "Rock_Stone"
    },
    {
      "x": -9,
      "y": -1,
      "z": 19,
      "name": "Rock_Stone"
    },
    {
      "x": -9,
      "y": 0,
      "z": 19,
      "name": "Rock_Stone"
    },
    {
      "x": -9,
      "y": 1,
      "z": 19,
      "name": "Rock_Stone"
    },
    {
      "x": -9,
      "y": 2,
      "z": 19,
      "name": "Rock_Stone"
    },
    {
      "x": -9,
      "y": 3,
      "z": 19,
      "name": "Rock_Stone"
    },
    {
      "x": -9,
      "y": 4,
      "z": 19,
      "name": "Rock_Stone"
    },
    {
      "x": -9,
      "y": 5,
      "z": 19,
      "name": "Rock_Stone"
    },
    {
      "x": -9,
      "y": 6,
      "z": 19,
      "name": "Rock_Stone"
    },
    {
      "x": -9,
      "y": 7,
      "z": 19,
      "name": "Rock_Stone"
    },
    {
      "x": -9,
      "y": 8,
      "z": 19,
      "name": "Rock_Stone"
    },
    {
      "x": -9,
      "y": 9,
      "z": 19,
      "name": "Rock_Stone"
    },
    {
      "x": -9,
      "y": 10,
      "z": 19,
      "name": "Rock_Stone"
    },
    {
      "x": -9,
      "y": 11,
      "z": 19,
      "name": "Rock_Stone"
    },
    {
      "x": -9,
      "y": 12,
      "z": 19,
      "name": "Rock_Stone"
    },
    {
      "x": -9,
      "y": 13,
      "z": 19,
      "name": "Rock_Stone"
    },
    {
      "x": -9,
      "y": 14,
      "z": 19,
      "name": "Rock_Stone"
    },
    {
      "x": -9,
      "y": -1,
      "z": 20,
      "name": "Rock_Stone"
    },
    {
      "x": -9,
      "y": 0,
      "z": 20,
      "name": "Rock_Stone"
    },
    {
      "x": -9,
      "y": 1,
      "z": 20,
      "name": "Rock_Stone"
    },
    {
      "x": -9,
      "y": 2,
      "z": 20,
      "name": "Rock_Stone"
    },
    {
      "x": -9,
      "y": 3,
      "z": 20,
      "name": "Rock_Stone"
    },
    {
      "x": -9,
      "y": 4,
      "z": 20,
      "name": "Rock_Stone"
    },
    {
      "x": -9,
      "y": 5,
      "z": 20,
      "name": "Rock_Stone"
    },
    {
      "x": -9,
      "y": 6,
      "z": 20,
      "name": "Rock_Stone"
    },
    {
      "x": -9,
      "y": 7,
      "z": 20,
      "name": "Rock_Stone"
    },
    {
      "x": -9,
      "y": 8,
      "z": 20,
      "name": "Rock_Stone"
    },
    {
      "x": -9,
      "y": 9,
      "z": 20,
      "name": "Rock_Stone"
    },
    {
      "x": -9,
      "y": 10,
      "z": 20,
      "name": "Rock_Stone"
    },
    {
      "x": -9,
      "y": 11,
      "z": 20,
      "name": "Rock_Stone"
    },
    {
      "x": -9,
      "y": 12,
      "z": 20,
      "name": "Rock_Stone"
    },
    {
      "x": -9,
      "y": 13,
      "z": 20,
      "name": "Rock_Stone"
    },
    {
      "x": -9,
      "y": 14,
      "z": 20,
      "name": "Rock_Stone"
    },
    {
      "x": -8,
      "y": -1,
      "z": 0,
      "name": "Rock_Stone"
    },
    {
      "x": -8,
      "y": 0,
      "z": 0,
      "name": "Rock_Stone"
    },
    {
      "x": -8,
      "y": 1,
      "z": 0,
      "name": "Rock_Stone"
    },
    {
      "x": -8,
      "y": 2,
      "z": 0,
      "name": "Rock_Stone"
    },
    {
      "x": -8,
      "y": 3,
      "z": 0,
      "name": "Rock_Stone"
    },
    {
      "x": -8,
      "y": 4,
      "z": 0,
      "name": "Rock_Stone"
    },
    {
      "x": -8,
      "y": 5,
      "z": 0,
      "name": "Rock_Stone"
    },
    {
      "x": -8,
      "y": 6,
      "z": 0,
      "name": "Rock_Stone"
    },
    {
      "x": -8,
      "y": 7,
      "z": 0,
      "name": "Rock_Stone"
    },
    {
      "x": -8,
      "y": 8,
      "z": 0,
      "name": "Rock_Stone"
    },
    {
      "x": -8,
      "y": 9,
      "z": 0,
      "name": "Rock_Stone"
    },
    {
      "x": -8,
      "y": 10,
      "z": 0,
      "name": "Rock_Stone"
    },
    {
      "x": -8,
      "y": 11,
      "z": 0,
      "name": "Rock_Stone"
    },
    {
      "x": -8,
      "y": 12,
      "z": 0,
      "name": "Rock_Stone"
    },
    {
      "x": -8,
      "y": 13,
      "z": 0,
      "name": "Rock_Stone"
    },
    {
      "x": -8,
      "y": 14,
      "z": 0,
      "name": "Rock_Stone"
    },
    {
      "x": -8,
      "y": -1,
      "z": 1,
      "name": "Rock_Stone"
    },
    {
      "x": -8,
      "y": 0,
      "z": 1,
      "name": "Rock_Stone"
    },
    {
      "x": -8,
      "y": 1,
      "z": 1,
      "name": "Rock_Stone"
    },
    {
      "x": -8,
      "y": 2,
      "z": 1,
      "name": "Rock_Stone"
    },
    {
      "x": -8,
      "y": 3,
      "z": 1,
      "name": "Rock_Stone"
    },
    {
      "x": -8,
      "y": 4,
      "z": 1,
      "name": "Rock_Stone"
    },
    {
      "x": -8,
      "y": 5,
      "z": 1,
      "name": "Rock_Stone"
    },
    {
      "x": -8,
      "y": 6,
      "z": 1,
      "name": "Rock_Stone"
    },
    {
      "x": -8,
      "y": 7,
      "z": 1,
      "name": "Rock_Stone"
    },
    {
      "x": -8,
      "y": 8,
      "z": 1,
      "name": "Rock_Stone"
    },
    {
      "x": -8,
      "y": 9,
      "z": 1,
      "name": "Rock_Stone"
    },
    {
      "x": -8,
      "y": 10,
      "z": 1,
      "name": "Rock_Stone"
    },
    {
      "x": -8,
      "y": 11,
      "z": 1,
      "name": "Rock_Stone"
    },
    {
      "x": -8,
      "y": 12,
      "z": 1,
      "name": "Rock_Stone"
    },
    {
      "x": -8,
      "y": 13,
      "z": 1,
      "name": "Rock_Stone"
    },
    {
      "x": -8,
      "y": 14,
      "z": 1,
      "name": "Rock_Stone"
    },
    {
      "x": -8,
      "y": -1,
      "z": 2,
      "name": "Rock_Stone"
    },
    {
      "x": -8,
      "y": 0,
      "z": 2,
      "name": "Rock_Stone"
    },
    {
      "x": -8,
      "y": 1,
      "z": 2,
      "name": "Rock_Stone"
    },
    {
      "x": -8,
      "y": 2,
      "z": 2,
      "name": "Rock_Stone"
    },
    {
      "x": -8,
      "y": 3,
      "z": 2,
      "name": "Rock_Stone"
    },
    {
      "x": -8,
      "y": 4,
      "z": 2,
      "name": "Rock_Stone"
    },
    {
      "x": -8,
      "y": 5,
      "z": 2,
      "name": "Rock_Stone"
    },
    {
      "x": -8,
      "y": 6,
      "z": 2,
      "name": "Rock_Stone"
    },
    {
      "x": -8,
      "y": 7,
      "z": 2,
      "name": "Rock_Stone"
    },
    {
      "x": -8,
      "y": 8,
      "z": 2,
      "name": "Rock_Stone"
    },
    {
      "x": -8,
      "y": 9,
      "z": 2,
      "name": "Rock_Stone"
    },
    {
      "x": -8,
      "y": 10,
      "z": 2,
      "name": "Rock_Stone"
    },
    {
      "x": -8,
      "y": 11,
      "z": 2,
      "name": "Rock_Stone"
    },
    {
      "x": -8,
      "y": 12,
      "z": 2,
      "name": "Rock_Stone"
    },
    {
      "x": -8,
      "y": 13,
      "z": 2,
      "name": "Rock_Stone"
    },
    {
      "x": -8,
      "y": 14,
      "z": 2,
      "name": "Rock_Stone"
    },
    {
      "x": -8,
      "y": -1,
      "z": 3,
      "name": "Rock_Stone"
    },
    {
      "x": -8,
      "y": 0,
      "z": 3,
      "name": "Rock_Stone"
    },
    {
      "x": -8,
      "y": 1,
      "z": 3,
      "name": "Rock_Stone"
    },
    {
      "x": -8,
      "y": 2,
      "z": 3,
      "name": "Rock_Stone"
    },
    {
      "x": -8,
      "y": 3,
      "z": 3,
      "name": "Rock_Stone"
    },
    {
      "x": -8,
      "y": 4,
      "z": 3,
      "name": "Rock_Stone"
    },
    {
      "x": -8,
      "y": 5,
      "z": 3,
      "name": "Rock_Stone"
    },
    {
      "x": -8,
      "y": 6,
      "z": 3,
      "name": "Rock_Stone"
    },
    {
      "x": -8,
      "y": 7,
      "z": 3,
      "name": "Rock_Stone"
    },
    {
      "x": -8,
      "y": 8,
      "z": 3,
      "name": "Rock_Stone"
    },
    {
      "x": -8,
      "y": 9,
      "z": 3,
      "name": "Rock_Stone"
    },
    {
      "x": -8,
      "y": 10,
      "z": 3,
      "name": "Rock_Stone"
    },
    {
      "x": -8,
      "y": 11,
      "z": 3,
      "name": "Rock_Stone"
    },
    {
      "x": -8,
      "y": 12,
      "z": 3,
      "name": "Rock_Stone"
    },
    {
      "x": -8,
      "y": 13,
      "z": 3,
      "name": "Rock_Stone"
    },
    {
      "x": -8,
      "y": 14,
      "z": 3,
      "name": "Rock_Stone"
    },
    {
      "x": -8,
      "y": -1,
      "z": 4,
      "name": "Rock_Stone"
    },
    {
      "x": -8,
      "y": 0,
      "z": 4,
      "name": "Rock_Stone"
    },
    {
      "x": -8,
      "y": 1,
      "z": 4,
      "name": "Rock_Stone"
    },
    {
      "x": -8,
      "y": 2,
      "z": 4,
      "name": "Rock_Stone"
    },
    {
      "x": -8,
      "y": 3,
      "z": 4,
      "name": "Rock_Stone"
    },
    {
      "x": -8,
      "y": 4,
      "z": 4,
      "name": "Rock_Stone"
    },
    {
      "x": -8,
      "y": 5,
      "z": 4,
      "name": "Rock_Stone"
    },
    {
      "x": -8,
      "y": 6,
      "z": 4,
      "name": "Rock_Stone"
    },
    {
      "x": -8,
      "y": 7,
      "z": 4,
      "name": "Rock_Stone"
    },
    {
      "x": -8,
      "y": 8,
      "z": 4,
      "name": "Rock_Stone"
    },
    {
      "x": -8,
      "y": 9,
      "z": 4,
      "name": "Rock_Stone"
    },
    {
      "x": -8,
      "y": 10,
      "z": 4,
      "name": "Rock_Stone"
    },
    {
      "x": -8,
      "y": 11,
      "z": 4,
      "name": "Rock_Stone"
    },
    {
      "x": -8,
      "y": 12,
      "z": 4,
      "name": "Rock_Stone"
    },
    {
      "x": -8,
      "y": 13,
      "z": 4,
      "name": "Rock_Stone"
    },
    {
      "x": -8,
      "y": 14,
      "z": 4,
      "name": "Rock_Stone"
    },
    {
      "x": -8,
      "y": -1,
      "z": 5,
      "name": "Rock_Stone"
    },
    {
      "x": -8,
      "y": 0,
      "z": 5,
      "name": "Rock_Stone"
    },
    {
      "x": -8,
      "y": 1,
      "z": 5,
      "name": "Rock_Stone"
    },
    {
      "x": -8,
      "y": 2,
      "z": 5,
      "name": "Rock_Stone"
    },
    {
      "x": -8,
      "y": 3,
      "z": 5,
      "name": "Rock_Stone"
    },
    {
      "x": -8,
      "y": 4,
      "z": 5,
      "name": "Rock_Stone"
    },
    {
      "x": -8,
      "y": 5,
      "z": 5,
      "name": "Rock_Stone"
    },
    {
      "x": -8,
      "y": 6,
      "z": 5,
      "name": "Rock_Stone"
    },
    {
      "x": -8,
      "y": 7,
      "z": 5,
      "name": "Rock_Stone"
    },
    {
      "x": -8,
      "y": 8,
      "z": 5,
      "name": "Rock_Stone"
    },
    {
      "x": -8,
      "y": 9,
      "z": 5,
      "name": "Rock_Stone"
    },
    {
      "x": -8,
      "y": 10,
      "z": 5,
      "name": "Rock_Stone"
    },
    {
      "x": -8,
      "y": 11,
      "z": 5,
      "name": "Rock_Stone"
    },
    {
      "x": -8,
      "y": 12,
      "z": 5,
      "name": "Rock_Stone"
    },
    {
      "x": -8,
      "y": 13,
      "z": 5,
      "name": "Rock_Stone"
    },
    {
      "x": -8,
      "y": 14,
      "z": 5,
      "name": "Rock_Stone"
    },
    {
      "x": -8,
      "y": -1,
      "z": 6,
      "name": "Rock_Stone"
    },
    {
      "x": -8,
      "y": 0,
      "z": 6,
      "name": "Rock_Stone"
    },
    {
      "x": -8,
      "y": 1,
      "z": 6,
      "name": "Rock_Stone"
    },
    {
      "x": -8,
      "y": 2,
      "z": 6,
      "name": "Rock_Stone"
    },
    {
      "x": -8,
      "y": 3,
      "z": 6,
      "name": "Rock_Stone"
    },
    {
      "x": -8,
      "y": 4,
      "z": 6,
      "name": "Rock_Stone"
    },
    {
      "x": -8,
      "y": 5,
      "z": 6,
      "name": "Rock_Stone"
    },
    {
      "x": -8,
      "y": 6,
      "z": 6,
      "name": "Rock_Stone"
    },
    {
      "x": -8,
      "y": 7,
      "z": 6,
      "name": "Rock_Stone"
    },
    {
      "x": -8,
      "y": 8,
      "z": 6,
      "name": "Rock_Stone"
    },
    {
      "x": -8,
      "y": 9,
      "z": 6,
      "name": "Rock_Stone"
    },
    {
      "x": -8,
      "y": 10,
      "z": 6,
      "name": "Rock_Stone"
    },
    {
      "x": -8,
      "y": 11,
      "z": 6,
      "name": "Rock_Stone"
    },
    {
      "x": -8,
      "y": 12,
      "z": 6,
      "name": "Rock_Stone"
    },
    {
      "x": -8,
      "y": 13,
      "z": 6,
      "name": "Rock_Stone"
    },
    {
      "x": -8,
      "y": 14,
      "z": 6,
      "name": "Rock_Stone"
    },
    {
      "x": -8,
      "y": -1,
      "z": 7,
      "name": "Rock_Stone"
    },
    {
      "x": -8,
      "y": 0,
      "z": 7,
      "name": "Rock_Stone"
    },
    {
      "x": -8,
      "y": 1,
      "z": 7,
      "name": "Rock_Stone"
    },
    {
      "x": -8,
      "y": 2,
      "z": 7,
      "name": "Rock_Stone"
    },
    {
      "x": -8,
      "y": 3,
      "z": 7,
      "name": "Rock_Stone"
    },
    {
      "x": -8,
      "y": 4,
      "z": 7,
      "name": "Rock_Stone"
    },
    {
      "x": -8,
      "y": 5,
      "z": 7,
      "name": "Furniture_Village_Crate"
    },
    {
      "x": -8,
      "y": 6,
      "z": 7,
      "name": "Empty"
    },
    {
      "x": -8,
      "y": 7,
      "z": 7,
      "name": "Rock_Stone"
    },
    {
      "x": -8,
      "y": 8,
      "z": 7,
      "name": "Rock_Stone"
    },
    {
      "x": -8,
      "y": 9,
      "z": 7,
      "name": "Rock_Stone"
    },
    {
      "x": -8,
      "y": 10,
      "z": 7,
      "name": "Rock_Stone"
    },
    {
      "x": -8,
      "y": 11,
      "z": 7,
      "name": "Rock_Stone"
    },
    {
      "x": -8,
      "y": 12,
      "z": 7,
      "name": "Rock_Stone"
    },
    {
      "x": -8,
      "y": 13,
      "z": 7,
      "name": "Rock_Stone"
    },
    {
      "x": -8,
      "y": 14,
      "z": 7,
      "name": "Rock_Stone"
    },
    {
      "x": -8,
      "y": -1,
      "z": 8,
      "name": "Rock_Stone"
    },
    {
      "x": -8,
      "y": 0,
      "z": 8,
      "name": "Rock_Stone"
    },
    {
      "x": -8,
      "y": 1,
      "z": 8,
      "name": "Rock_Stone"
    },
    {
      "x": -8,
      "y": 2,
      "z": 8,
      "name": "Rock_Stone"
    },
    {
      "x": -8,
      "y": 3,
      "z": 8,
      "name": "Rock_Stone"
    },
    {
      "x": -8,
      "y": 4,
      "z": 8,
      "name": "Wood_Softwood_Planks"
    },
    {
      "x": -8,
      "y": 5,
      "z": 8,
      "name": "Furniture_Ancient_Crate"
    },
    {
      "x": -8,
      "y": 6,
      "z": 8,
      "name": "Empty"
    },
    {
      "x": -8,
      "y": 7,
      "z": 8,
      "name": "Empty"
    },
    {
      "x": -8,
      "y": 8,
      "z": 8,
      "name": "Empty"
    },
    {
      "x": -8,
      "y": 9,
      "z": 8,
      "name": "Rock_Stone"
    },
    {
      "x": -8,
      "y": 10,
      "z": 8,
      "name": "Rock_Stone"
    },
    {
      "x": -8,
      "y": 11,
      "z": 8,
      "name": "Rock_Stone"
    },
    {
      "x": -8,
      "y": 12,
      "z": 8,
      "name": "Rock_Stone"
    },
    {
      "x": -8,
      "y": 13,
      "z": 8,
      "name": "Rock_Stone"
    },
    {
      "x": -8,
      "y": 14,
      "z": 8,
      "name": "Rock_Stone"
    },
    {
      "x": -8,
      "y": -1,
      "z": 9,
      "name": "Rock_Stone"
    },
    {
      "x": -8,
      "y": 0,
      "z": 9,
      "name": "Rock_Stone"
    },
    {
      "x": -8,
      "y": 1,
      "z": 9,
      "name": "Rock_Stone"
    },
    {
      "x": -8,
      "y": 2,
      "z": 9,
      "name": "Rock_Stone"
    },
    {
      "x": -8,
      "y": 3,
      "z": 9,
      "name": "Rock_Stone"
    },
    {
      "x": -8,
      "y": 4,
      "z": 9,
      "name": "Wood_Softwood_Planks"
    },
    {
      "x": -8,
      "y": 5,
      "z": 9,
      "name": "Empty"
    },
    {
      "x": -8,
      "y": 6,
      "z": 9,
      "name": "Empty"
    },
    {
      "x": -8,
      "y": 7,
      "z": 9,
      "name": "Empty"
    },
    {
      "x": -8,
      "y": 8,
      "z": 9,
      "name": "Empty"
    },
    {
      "x": -8,
      "y": 9,
      "z": 9,
      "name": "Empty"
    },
    {
      "x": -8,
      "y": 10,
      "z": 9,
      "name": "Empty"
    },
    {
      "x": -8,
      "y": 11,
      "z": 9,
      "name": "Rock_Stone"
    },
    {
      "x": -8,
      "y": 12,
      "z": 9,
      "name": "Rock_Stone"
    },
    {
      "x": -8,
      "y": 13,
      "z": 9,
      "name": "Rock_Stone"
    },
    {
      "x": -8,
      "y": 14,
      "z": 9,
      "name": "Rock_Stone"
    },
    {
      "x": -8,
      "y": -1,
      "z": 10,
      "name": "Rock_Stone"
    },
    {
      "x": -8,
      "y": 0,
      "z": 10,
      "name": "Rock_Stone"
    },
    {
      "x": -8,
      "y": 1,
      "z": 10,
      "name": "Rock_Stone"
    },
    {
      "x": -8,
      "y": 2,
      "z": 10,
      "name": "Rock_Stone"
    },
    {
      "x": -8,
      "y": 3,
      "z": 10,
      "name": "Rock_Stone"
    },
    {
      "x": -8,
      "y": 4,
      "z": 10,
      "name": "Wood_Softwood_Stairs"
    },
    {
      "x": -8,
      "y": 5,
      "z": 10,
      "name": "Empty"
    },
    {
      "x": -8,
      "y": 6,
      "z": 10,
      "name": "Empty"
    },
    {
      "x": -8,
      "y": 7,
      "z": 10,
      "name": "Empty"
    },
    {
      "x": -8,
      "y": 8,
      "z": 10,
      "name": "Empty"
    },
    {
      "x": -8,
      "y": 9,
      "z": 10,
      "name": "Empty"
    },
    {
      "x": -8,
      "y": 10,
      "z": 10,
      "name": "Empty"
    },
    {
      "x": -8,
      "y": 11,
      "z": 10,
      "name": "Empty"
    },
    {
      "x": -8,
      "y": 12,
      "z": 10,
      "name": "Rock_Stone"
    },
    {
      "x": -8,
      "y": 13,
      "z": 10,
      "name": "Rock_Stone"
    },
    {
      "x": -8,
      "y": 14,
      "z": 10,
      "name": "Rock_Stone"
    },
    {
      "x": -8,
      "y": -1,
      "z": 11,
      "name": "Rock_Stone"
    },
    {
      "x": -8,
      "y": 0,
      "z": 11,
      "name": "Rock_Stone"
    },
    {
      "x": -8,
      "y": 1,
      "z": 11,
      "name": "Rock_Stone"
    },
    {
      "x": -8,
      "y": 2,
      "z": 11,
      "name": "Rock_Stone"
    },
    {
      "x": -8,
      "y": 3,
      "z": 11,
      "name": "Rock_Stone"
    },
    {
      "x": -8,
      "y": 4,
      "z": 11,
      "name": "Empty"
    },
    {
      "x": -8,
      "y": 5,
      "z": 11,
      "name": "Empty"
    },
    {
      "x": -8,
      "y": 6,
      "z": 11,
      "name": "Empty"
    },
    {
      "x": -8,
      "y": 7,
      "z": 11,
      "name": "Empty"
    },
    {
      "x": -8,
      "y": 8,
      "z": 11,
      "name": "Empty"
    },
    {
      "x": -8,
      "y": 9,
      "z": 11,
      "name": "Empty"
    },
    {
      "x": -8,
      "y": 10,
      "z": 11,
      "name": "Empty"
    },
    {
      "x": -8,
      "y": 11,
      "z": 11,
      "name": "Empty"
    },
    {
      "x": -8,
      "y": 12,
      "z": 11,
      "name": "Rock_Stone"
    },
    {
      "x": -8,
      "y": 13,
      "z": 11,
      "name": "Rock_Stone"
    },
    {
      "x": -8,
      "y": 14,
      "z": 11,
      "name": "Rock_Stone"
    },
    {
      "x": -8,
      "y": -1,
      "z": 12,
      "name": "Rock_Stone"
    },
    {
      "x": -8,
      "y": 0,
      "z": 12,
      "name": "Rock_Stone"
    },
    {
      "x": -8,
      "y": 1,
      "z": 12,
      "name": "Rock_Stone"
    },
    {
      "x": -8,
      "y": 2,
      "z": 12,
      "name": "Rock_Stone"
    },
    {
      "x": -8,
      "y": 3,
      "z": 12,
      "name": "Rock_Stone"
    },
    {
      "x": -8,
      "y": 4,
      "z": 12,
      "name": "Empty"
    },
    {
      "x": -8,
      "y": 5,
      "z": 12,
      "name": "Empty"
    },
    {
      "x": -8,
      "y": 6,
      "z": 12,
      "name": "Empty"
    },
    {
      "x": -8,
      "y": 7,
      "z": 12,
      "name": "Empty"
    },
    {
      "x": -8,
      "y": 8,
      "z": 12,
      "name": "Empty"
    },
    {
      "x": -8,
      "y": 9,
      "z": 12,
      "name": "Empty"
    },
    {
      "x": -8,
      "y": 10,
      "z": 12,
      "name": "Empty"
    },
    {
      "x": -8,
      "y": 11,
      "z": 12,
      "name": "Empty"
    },
    {
      "x": -8,
      "y": 12,
      "z": 12,
      "name": "Empty"
    },
    {
      "x": -8,
      "y": 13,
      "z": 12,
      "name": "Rock_Stone"
    },
    {
      "x": -8,
      "y": 14,
      "z": 12,
      "name": "Rock_Stone"
    },
    {
      "x": -8,
      "y": -1,
      "z": 13,
      "name": "Rock_Stone"
    },
    {
      "x": -8,
      "y": 0,
      "z": 13,
      "name": "Rock_Stone"
    },
    {
      "x": -8,
      "y": 1,
      "z": 13,
      "name": "Rock_Stone"
    },
    {
      "x": -8,
      "y": 2,
      "z": 13,
      "name": "Rock_Stone"
    },
    {
      "x": -8,
      "y": 3,
      "z": 13,
      "name": "Rock_Stone"
    },
    {
      "x": -8,
      "y": 4,
      "z": 13,
      "name": "Empty"
    },
    {
      "x": -8,
      "y": 5,
      "z": 13,
      "name": "Empty"
    },
    {
      "x": -8,
      "y": 6,
      "z": 13,
      "name": "Empty"
    },
    {
      "x": -8,
      "y": 7,
      "z": 13,
      "name": "Empty"
    },
    {
      "x": -8,
      "y": 8,
      "z": 13,
      "name": "Empty"
    },
    {
      "x": -8,
      "y": 9,
      "z": 13,
      "name": "Empty"
    },
    {
      "x": -8,
      "y": 10,
      "z": 13,
      "name": "Empty"
    },
    {
      "x": -8,
      "y": 11,
      "z": 13,
      "name": "Empty"
    },
    {
      "x": -8,
      "y": 12,
      "z": 13,
      "name": "Empty"
    },
    {
      "x": -8,
      "y": 13,
      "z": 13,
      "name": "Rock_Stone"
    },
    {
      "x": -8,
      "y": 14,
      "z": 13,
      "name": "Rock_Stone"
    },
    {
      "x": -8,
      "y": -1,
      "z": 14,
      "name": "Rock_Stone"
    },
    {
      "x": -8,
      "y": 0,
      "z": 14,
      "name": "Rock_Stone"
    },
    {
      "x": -8,
      "y": 1,
      "z": 14,
      "name": "Rock_Stone"
    },
    {
      "x": -8,
      "y": 2,
      "z": 14,
      "name": "Rock_Stone"
    },
    {
      "x": -8,
      "y": 3,
      "z": 14,
      "name": "Rock_Stone"
    },
    {
      "x": -8,
      "y": 4,
      "z": 14,
      "name": "Empty"
    },
    {
      "x": -8,
      "y": 5,
      "z": 14,
      "name": "Empty"
    },
    {
      "x": -8,
      "y": 6,
      "z": 14,
      "name": "Empty"
    },
    {
      "x": -8,
      "y": 7,
      "z": 14,
      "name": "Empty"
    },
    {
      "x": -8,
      "y": 8,
      "z": 14,
      "name": "Empty"
    },
    {
      "x": -8,
      "y": 9,
      "z": 14,
      "name": "Empty"
    },
    {
      "x": -8,
      "y": 10,
      "z": 14,
      "name": "Empty"
    },
    {
      "x": -8,
      "y": 11,
      "z": 14,
      "name": "Empty"
    },
    {
      "x": -8,
      "y": 12,
      "z": 14,
      "name": "Rock_Stone"
    },
    {
      "x": -8,
      "y": 13,
      "z": 14,
      "name": "Rock_Stone"
    },
    {
      "x": -8,
      "y": 14,
      "z": 14,
      "name": "Rock_Stone"
    },
    {
      "x": -8,
      "y": -1,
      "z": 15,
      "name": "Rock_Stone"
    },
    {
      "x": -8,
      "y": 0,
      "z": 15,
      "name": "Rock_Stone"
    },
    {
      "x": -8,
      "y": 1,
      "z": 15,
      "name": "Rock_Stone"
    },
    {
      "x": -8,
      "y": 2,
      "z": 15,
      "name": "Rock_Stone"
    },
    {
      "x": -8,
      "y": 3,
      "z": 15,
      "name": "Rock_Stone"
    },
    {
      "x": -8,
      "y": 4,
      "z": 15,
      "name": "Rubble_Stone"
    },
    {
      "x": -8,
      "y": 5,
      "z": 15,
      "name": "Empty"
    },
    {
      "x": -8,
      "y": 6,
      "z": 15,
      "name": "Empty"
    },
    {
      "x": -8,
      "y": 7,
      "z": 15,
      "name": "Empty"
    },
    {
      "x": -8,
      "y": 8,
      "z": 15,
      "name": "Empty"
    },
    {
      "x": -8,
      "y": 9,
      "z": 15,
      "name": "Empty"
    },
    {
      "x": -8,
      "y": 10,
      "z": 15,
      "name": "Empty"
    },
    {
      "x": -8,
      "y": 11,
      "z": 15,
      "name": "Rock_Stone"
    },
    {
      "x": -8,
      "y": 12,
      "z": 15,
      "name": "Rock_Stone"
    },
    {
      "x": -8,
      "y": 13,
      "z": 15,
      "name": "Rock_Stone"
    },
    {
      "x": -8,
      "y": 14,
      "z": 15,
      "name": "Rock_Stone"
    },
    {
      "x": -8,
      "y": -1,
      "z": 16,
      "name": "Rock_Stone"
    },
    {
      "x": -8,
      "y": 0,
      "z": 16,
      "name": "Rock_Stone"
    },
    {
      "x": -8,
      "y": 1,
      "z": 16,
      "name": "Rock_Stone"
    },
    {
      "x": -8,
      "y": 2,
      "z": 16,
      "name": "Rock_Stone"
    },
    {
      "x": -8,
      "y": 3,
      "z": 16,
      "name": "Rock_Stone"
    },
    {
      "x": -8,
      "y": 4,
      "z": 16,
      "name": "Rock_Stone_Cobble"
    },
    {
      "x": -8,
      "y": 5,
      "z": 16,
      "name": "Rock_Stone_Cobble_Half"
    },
    {
      "x": -8,
      "y": 6,
      "z": 16,
      "name": "Empty"
    },
    {
      "x": -8,
      "y": 7,
      "z": 16,
      "name": "Empty"
    },
    {
      "x": -8,
      "y": 8,
      "z": 16,
      "name": "Empty"
    },
    {
      "x": -8,
      "y": 9,
      "z": 16,
      "name": "Empty"
    },
    {
      "x": -8,
      "y": 10,
      "z": 16,
      "name": "Empty"
    },
    {
      "x": -8,
      "y": 11,
      "z": 16,
      "name": "Rock_Stone"
    },
    {
      "x": -8,
      "y": 12,
      "z": 16,
      "name": "Rock_Stone"
    },
    {
      "x": -8,
      "y": 13,
      "z": 16,
      "name": "Rock_Stone"
    },
    {
      "x": -8,
      "y": 14,
      "z": 16,
      "name": "Rock_Stone"
    },
    {
      "x": -8,
      "y": -1,
      "z": 17,
      "name": "Rock_Stone"
    },
    {
      "x": -8,
      "y": 0,
      "z": 17,
      "name": "Rock_Stone"
    },
    {
      "x": -8,
      "y": 1,
      "z": 17,
      "name": "Rock_Stone"
    },
    {
      "x": -8,
      "y": 2,
      "z": 17,
      "name": "Rock_Stone"
    },
    {
      "x": -8,
      "y": 3,
      "z": 17,
      "name": "Rock_Stone"
    },
    {
      "x": -8,
      "y": 4,
      "z": 17,
      "name": "Rock_Stone_Cobble"
    },
    {
      "x": -8,
      "y": 5,
      "z": 17,
      "name": "Rock_Stone_Cobble"
    },
    {
      "x": -8,
      "y": 6,
      "z": 17,
      "name": "Empty"
    },
    {
      "x": -8,
      "y": 7,
      "z": 17,
      "name": "Empty"
    },
    {
      "x": -8,
      "y": 8,
      "z": 17,
      "name": "Empty"
    },
    {
      "x": -8,
      "y": 9,
      "z": 17,
      "name": "Wood_Softwood_Planks_Half",
      "rotation": 6
    },
    {
      "x": -8,
      "y": 10,
      "z": 17,
      "name": "Empty"
    },
    {
      "x": -8,
      "y": 11,
      "z": 17,
      "name": "Rock_Stone"
    },
    {
      "x": -8,
      "y": 12,
      "z": 17,
      "name": "Rock_Stone"
    },
    {
      "x": -8,
      "y": 13,
      "z": 17,
      "name": "Rock_Stone"
    },
    {
      "x": -8,
      "y": 14,
      "z": 17,
      "name": "Rock_Stone"
    },
    {
      "x": -8,
      "y": -1,
      "z": 18,
      "name": "Rock_Stone"
    },
    {
      "x": -8,
      "y": 0,
      "z": 18,
      "name": "Rock_Stone"
    },
    {
      "x": -8,
      "y": 1,
      "z": 18,
      "name": "Rock_Stone"
    },
    {
      "x": -8,
      "y": 2,
      "z": 18,
      "name": "Rock_Stone"
    },
    {
      "x": -8,
      "y": 3,
      "z": 18,
      "name": "Rock_Stone"
    },
    {
      "x": -8,
      "y": 4,
      "z": 18,
      "name": "Wood_Beech_Trunk"
    },
    {
      "x": -8,
      "y": 5,
      "z": 18,
      "name": "Wood_Beech_Trunk"
    },
    {
      "x": -8,
      "y": 6,
      "z": 18,
      "name": "Wood_Beech_Trunk"
    },
    {
      "x": -8,
      "y": 7,
      "z": 18,
      "name": "Wood_Beech_Trunk"
    },
    {
      "x": -8,
      "y": 8,
      "z": 18,
      "name": "Wood_Beech_Trunk"
    },
    {
      "x": -8,
      "y": 9,
      "z": 18,
      "name": "Wood_Beech_Trunk",
      "rotation": 5
    },
    {
      "x": -8,
      "y": 10,
      "z": 18,
      "name": "Rock_Stone"
    },
    {
      "x": -8,
      "y": 11,
      "z": 18,
      "name": "Rock_Stone"
    },
    {
      "x": -8,
      "y": 12,
      "z": 18,
      "name": "Rock_Stone"
    },
    {
      "x": -8,
      "y": 13,
      "z": 18,
      "name": "Rock_Stone"
    },
    {
      "x": -8,
      "y": 14,
      "z": 18,
      "name": "Rock_Stone"
    },
    {
      "x": -8,
      "y": -1,
      "z": 19,
      "name": "Rock_Stone"
    },
    {
      "x": -8,
      "y": 0,
      "z": 19,
      "name": "Rock_Stone"
    },
    {
      "x": -8,
      "y": 1,
      "z": 19,
      "name": "Rock_Stone"
    },
    {
      "x": -8,
      "y": 2,
      "z": 19,
      "name": "Rock_Stone"
    },
    {
      "x": -8,
      "y": 3,
      "z": 19,
      "name": "Rock_Stone"
    },
    {
      "x": -8,
      "y": 4,
      "z": 19,
      "name": "Rock_Stone_Cobble"
    },
    {
      "x": -8,
      "y": 5,
      "z": 19,
      "name": "Rock_Stone_Cobble"
    },
    {
      "x": -8,
      "y": 6,
      "z": 19,
      "name": "Empty"
    },
    {
      "x": -8,
      "y": 7,
      "z": 19,
      "name": "Empty"
    },
    {
      "x": -8,
      "y": 8,
      "z": 19,
      "name": "Empty"
    },
    {
      "x": -8,
      "y": 9,
      "z": 19,
      "name": "Rock_Stone"
    },
    {
      "x": -8,
      "y": 10,
      "z": 19,
      "name": "Rock_Stone"
    },
    {
      "x": -8,
      "y": 11,
      "z": 19,
      "name": "Rock_Stone"
    },
    {
      "x": -8,
      "y": 12,
      "z": 19,
      "name": "Rock_Stone"
    },
    {
      "x": -8,
      "y": 13,
      "z": 19,
      "name": "Rock_Stone"
    },
    {
      "x": -8,
      "y": 14,
      "z": 19,
      "name": "Rock_Stone"
    },
    {
      "x": -8,
      "y": -1,
      "z": 20,
      "name": "Rock_Stone"
    },
    {
      "x": -8,
      "y": 0,
      "z": 20,
      "name": "Rock_Stone"
    },
    {
      "x": -8,
      "y": 1,
      "z": 20,
      "name": "Rock_Stone"
    },
    {
      "x": -8,
      "y": 2,
      "z": 20,
      "name": "Rock_Stone"
    },
    {
      "x": -8,
      "y": 3,
      "z": 20,
      "name": "Rock_Stone"
    },
    {
      "x": -8,
      "y": 4,
      "z": 20,
      "name": "Rock_Stone_Cobble"
    },
    {
      "x": -8,
      "y": 5,
      "z": 20,
      "name": "Empty"
    },
    {
      "x": -8,
      "y": 6,
      "z": 20,
      "name": "Empty"
    },
    {
      "x": -8,
      "y": 7,
      "z": 20,
      "name": "Empty"
    },
    {
      "x": -8,
      "y": 8,
      "z": 20,
      "name": "Empty"
    },
    {
      "x": -8,
      "y": 9,
      "z": 20,
      "name": "Rock_Stone"
    },
    {
      "x": -8,
      "y": 10,
      "z": 20,
      "name": "Rock_Stone"
    },
    {
      "x": -8,
      "y": 11,
      "z": 20,
      "name": "Rock_Stone"
    },
    {
      "x": -8,
      "y": 12,
      "z": 20,
      "name": "Rock_Stone"
    },
    {
      "x": -8,
      "y": 13,
      "z": 20,
      "name": "Rock_Stone"
    },
    {
      "x": -8,
      "y": 14,
      "z": 20,
      "name": "Rock_Stone"
    },
    {
      "x": -7,
      "y": -1,
      "z": 0,
      "name": "Rock_Stone"
    },
    {
      "x": -7,
      "y": 0,
      "z": 0,
      "name": "Rock_Stone"
    },
    {
      "x": -7,
      "y": 1,
      "z": 0,
      "name": "Rock_Stone"
    },
    {
      "x": -7,
      "y": 2,
      "z": 0,
      "name": "Rock_Stone"
    },
    {
      "x": -7,
      "y": 3,
      "z": 0,
      "name": "Rock_Stone"
    },
    {
      "x": -7,
      "y": 4,
      "z": 0,
      "name": "Rock_Stone"
    },
    {
      "x": -7,
      "y": 5,
      "z": 0,
      "name": "Rock_Stone"
    },
    {
      "x": -7,
      "y": 6,
      "z": 0,
      "name": "Rock_Stone"
    },
    {
      "x": -7,
      "y": 7,
      "z": 0,
      "name": "Rock_Stone"
    },
    {
      "x": -7,
      "y": 8,
      "z": 0,
      "name": "Rock_Stone"
    },
    {
      "x": -7,
      "y": 9,
      "z": 0,
      "name": "Rock_Stone"
    },
    {
      "x": -7,
      "y": 10,
      "z": 0,
      "name": "Rock_Stone"
    },
    {
      "x": -7,
      "y": 11,
      "z": 0,
      "name": "Rock_Stone"
    },
    {
      "x": -7,
      "y": 12,
      "z": 0,
      "name": "Rock_Stone"
    },
    {
      "x": -7,
      "y": 13,
      "z": 0,
      "name": "Rock_Stone"
    },
    {
      "x": -7,
      "y": 14,
      "z": 0,
      "name": "Rock_Stone"
    },
    {
      "x": -7,
      "y": -1,
      "z": 1,
      "name": "Rock_Stone"
    },
    {
      "x": -7,
      "y": 0,
      "z": 1,
      "name": "Rock_Stone"
    },
    {
      "x": -7,
      "y": 1,
      "z": 1,
      "name": "Rock_Stone"
    },
    {
      "x": -7,
      "y": 2,
      "z": 1,
      "name": "Rock_Stone"
    },
    {
      "x": -7,
      "y": 3,
      "z": 1,
      "name": "Rock_Stone"
    },
    {
      "x": -7,
      "y": 4,
      "z": 1,
      "name": "Rock_Stone"
    },
    {
      "x": -7,
      "y": 5,
      "z": 1,
      "name": "Rock_Stone"
    },
    {
      "x": -7,
      "y": 6,
      "z": 1,
      "name": "Rock_Stone"
    },
    {
      "x": -7,
      "y": 7,
      "z": 1,
      "name": "Rock_Stone"
    },
    {
      "x": -7,
      "y": 8,
      "z": 1,
      "name": "Rock_Stone"
    },
    {
      "x": -7,
      "y": 9,
      "z": 1,
      "name": "Rock_Stone"
    },
    {
      "x": -7,
      "y": 10,
      "z": 1,
      "name": "Rock_Stone"
    },
    {
      "x": -7,
      "y": 11,
      "z": 1,
      "name": "Rock_Stone"
    },
    {
      "x": -7,
      "y": 12,
      "z": 1,
      "name": "Rock_Stone"
    },
    {
      "x": -7,
      "y": 13,
      "z": 1,
      "name": "Rock_Stone"
    },
    {
      "x": -7,
      "y": 14,
      "z": 1,
      "name": "Rock_Stone"
    },
    {
      "x": -7,
      "y": -1,
      "z": 2,
      "name": "Rock_Stone"
    },
    {
      "x": -7,
      "y": 0,
      "z": 2,
      "name": "Rock_Stone"
    },
    {
      "x": -7,
      "y": 1,
      "z": 2,
      "name": "Rock_Stone"
    },
    {
      "x": -7,
      "y": 2,
      "z": 2,
      "name": "Rock_Stone"
    },
    {
      "x": -7,
      "y": 3,
      "z": 2,
      "name": "Rock_Stone"
    },
    {
      "x": -7,
      "y": 4,
      "z": 2,
      "name": "Rock_Stone"
    },
    {
      "x": -7,
      "y": 5,
      "z": 2,
      "name": "Rock_Stone"
    },
    {
      "x": -7,
      "y": 6,
      "z": 2,
      "name": "Rock_Stone"
    },
    {
      "x": -7,
      "y": 7,
      "z": 2,
      "name": "Rock_Stone"
    },
    {
      "x": -7,
      "y": 8,
      "z": 2,
      "name": "Rock_Stone"
    },
    {
      "x": -7,
      "y": 9,
      "z": 2,
      "name": "Rock_Stone"
    },
    {
      "x": -7,
      "y": 10,
      "z": 2,
      "name": "Rock_Stone"
    },
    {
      "x": -7,
      "y": 11,
      "z": 2,
      "name": "Rock_Stone"
    },
    {
      "x": -7,
      "y": 12,
      "z": 2,
      "name": "Rock_Stone"
    },
    {
      "x": -7,
      "y": 13,
      "z": 2,
      "name": "Rock_Stone"
    },
    {
      "x": -7,
      "y": 14,
      "z": 2,
      "name": "Rock_Stone"
    },
    {
      "x": -7,
      "y": -1,
      "z": 3,
      "name": "Rock_Stone"
    },
    {
      "x": -7,
      "y": 0,
      "z": 3,
      "name": "Rock_Stone"
    },
    {
      "x": -7,
      "y": 1,
      "z": 3,
      "name": "Rock_Stone"
    },
    {
      "x": -7,
      "y": 2,
      "z": 3,
      "name": "Rock_Stone"
    },
    {
      "x": -7,
      "y": 3,
      "z": 3,
      "name": "Rock_Stone"
    },
    {
      "x": -7,
      "y": 4,
      "z": 3,
      "name": "Rock_Stone"
    },
    {
      "x": -7,
      "y": 5,
      "z": 3,
      "name": "Rock_Stone"
    },
    {
      "x": -7,
      "y": 6,
      "z": 3,
      "name": "Rock_Stone"
    },
    {
      "x": -7,
      "y": 7,
      "z": 3,
      "name": "Rock_Stone"
    },
    {
      "x": -7,
      "y": 8,
      "z": 3,
      "name": "Rock_Stone"
    },
    {
      "x": -7,
      "y": 9,
      "z": 3,
      "name": "Rock_Stone"
    },
    {
      "x": -7,
      "y": 10,
      "z": 3,
      "name": "Rock_Stone"
    },
    {
      "x": -7,
      "y": 11,
      "z": 3,
      "name": "Rock_Stone"
    },
    {
      "x": -7,
      "y": 12,
      "z": 3,
      "name": "Rock_Stone"
    },
    {
      "x": -7,
      "y": 13,
      "z": 3,
      "name": "Rock_Stone"
    },
    {
      "x": -7,
      "y": 14,
      "z": 3,
      "name": "Rock_Stone"
    },
    {
      "x": -7,
      "y": -1,
      "z": 4,
      "name": "Rock_Stone"
    },
    {
      "x": -7,
      "y": 0,
      "z": 4,
      "name": "Rock_Stone"
    },
    {
      "x": -7,
      "y": 1,
      "z": 4,
      "name": "Rock_Stone"
    },
    {
      "x": -7,
      "y": 2,
      "z": 4,
      "name": "Rock_Stone"
    },
    {
      "x": -7,
      "y": 3,
      "z": 4,
      "name": "Rock_Stone"
    },
    {
      "x": -7,
      "y": 4,
      "z": 4,
      "name": "Rock_Stone"
    },
    {
      "x": -7,
      "y": 5,
      "z": 4,
      "name": "Rock_Stone"
    },
    {
      "x": -7,
      "y": 6,
      "z": 4,
      "name": "Rock_Stone"
    },
    {
      "x": -7,
      "y": 7,
      "z": 4,
      "name": "Rock_Stone"
    },
    {
      "x": -7,
      "y": 8,
      "z": 4,
      "name": "Rock_Stone"
    },
    {
      "x": -7,
      "y": 9,
      "z": 4,
      "name": "Rock_Stone"
    },
    {
      "x": -7,
      "y": 10,
      "z": 4,
      "name": "Rock_Stone"
    },
    {
      "x": -7,
      "y": 11,
      "z": 4,
      "name": "Rock_Stone"
    },
    {
      "x": -7,
      "y": 12,
      "z": 4,
      "name": "Rock_Stone"
    },
    {
      "x": -7,
      "y": 13,
      "z": 4,
      "name": "Rock_Stone"
    },
    {
      "x": -7,
      "y": 14,
      "z": 4,
      "name": "Rock_Stone"
    },
    {
      "x": -7,
      "y": -1,
      "z": 5,
      "name": "Rock_Stone"
    },
    {
      "x": -7,
      "y": 0,
      "z": 5,
      "name": "Rock_Stone"
    },
    {
      "x": -7,
      "y": 1,
      "z": 5,
      "name": "Rock_Stone"
    },
    {
      "x": -7,
      "y": 2,
      "z": 5,
      "name": "Rock_Stone"
    },
    {
      "x": -7,
      "y": 3,
      "z": 5,
      "name": "Rock_Stone"
    },
    {
      "x": -7,
      "y": 4,
      "z": 5,
      "name": "Rock_Stone"
    },
    {
      "x": -7,
      "y": 5,
      "z": 5,
      "name": "Rock_Stone"
    },
    {
      "x": -7,
      "y": 6,
      "z": 5,
      "name": "Rock_Stone"
    },
    {
      "x": -7,
      "y": 7,
      "z": 5,
      "name": "Rock_Stone"
    },
    {
      "x": -7,
      "y": 8,
      "z": 5,
      "name": "Rock_Stone"
    },
    {
      "x": -7,
      "y": 9,
      "z": 5,
      "name": "Rock_Stone"
    },
    {
      "x": -7,
      "y": 10,
      "z": 5,
      "name": "Rock_Stone"
    },
    {
      "x": -7,
      "y": 11,
      "z": 5,
      "name": "Rock_Stone"
    },
    {
      "x": -7,
      "y": 12,
      "z": 5,
      "name": "Rock_Stone"
    },
    {
      "x": -7,
      "y": 13,
      "z": 5,
      "name": "Rock_Stone"
    },
    {
      "x": -7,
      "y": 14,
      "z": 5,
      "name": "Rock_Stone"
    },
    {
      "x": -7,
      "y": -1,
      "z": 6,
      "name": "Rock_Stone"
    },
    {
      "x": -7,
      "y": 0,
      "z": 6,
      "name": "Rock_Stone"
    },
    {
      "x": -7,
      "y": 1,
      "z": 6,
      "name": "Rock_Stone"
    },
    {
      "x": -7,
      "y": 2,
      "z": 6,
      "name": "Rock_Stone"
    },
    {
      "x": -7,
      "y": 3,
      "z": 6,
      "name": "Rock_Stone"
    },
    {
      "x": -7,
      "y": 4,
      "z": 6,
      "name": "Rock_Stone"
    },
    {
      "x": -7,
      "y": 5,
      "z": 6,
      "name": "Rock_Stone"
    },
    {
      "x": -7,
      "y": 6,
      "z": 6,
      "name": "Rock_Stone"
    },
    {
      "x": -7,
      "y": 7,
      "z": 6,
      "name": "Rock_Stone"
    },
    {
      "x": -7,
      "y": 8,
      "z": 6,
      "name": "Rock_Stone"
    },
    {
      "x": -7,
      "y": 9,
      "z": 6,
      "name": "Rock_Stone"
    },
    {
      "x": -7,
      "y": 10,
      "z": 6,
      "name": "Rock_Stone"
    },
    {
      "x": -7,
      "y": 11,
      "z": 6,
      "name": "Rock_Stone"
    },
    {
      "x": -7,
      "y": 12,
      "z": 6,
      "name": "Rock_Stone"
    },
    {
      "x": -7,
      "y": 13,
      "z": 6,
      "name": "Rock_Stone"
    },
    {
      "x": -7,
      "y": 14,
      "z": 6,
      "name": "Rock_Stone"
    },
    {
      "x": -7,
      "y": -1,
      "z": 7,
      "name": "Rock_Stone"
    },
    {
      "x": -7,
      "y": 0,
      "z": 7,
      "name": "Rock_Stone"
    },
    {
      "x": -7,
      "y": 1,
      "z": 7,
      "name": "Rock_Stone"
    },
    {
      "x": -7,
      "y": 2,
      "z": 7,
      "name": "Rock_Stone"
    },
    {
      "x": -7,
      "y": 3,
      "z": 7,
      "name": "Rock_Stone"
    },
    {
      "x": -7,
      "y": 4,
      "z": 7,
      "name": "Wood_Softwood_Planks"
    },
    {
      "x": -7,
      "y": 5,
      "z": 7,
      "name": "Furniture_Village_Crate"
    },
    {
      "x": -7,
      "y": 6,
      "z": 7,
      "name": "Empty"
    },
    {
      "x": -7,
      "y": 7,
      "z": 7,
      "name": "Empty"
    },
    {
      "x": -7,
      "y": 8,
      "z": 7,
      "name": "Empty"
    },
    {
      "x": -7,
      "y": 9,
      "z": 7,
      "name": "Rock_Stone"
    },
    {
      "x": -7,
      "y": 10,
      "z": 7,
      "name": "Rock_Stone"
    },
    {
      "x": -7,
      "y": 11,
      "z": 7,
      "name": "Rock_Stone"
    },
    {
      "x": -7,
      "y": 12,
      "z": 7,
      "name": "Rock_Stone"
    },
    {
      "x": -7,
      "y": 13,
      "z": 7,
      "name": "Rock_Stone"
    },
    {
      "x": -7,
      "y": 14,
      "z": 7,
      "name": "Rock_Stone"
    },
    {
      "x": -7,
      "y": -1,
      "z": 8,
      "name": "Rock_Stone"
    },
    {
      "x": -7,
      "y": 0,
      "z": 8,
      "name": "Rock_Stone"
    },
    {
      "x": -7,
      "y": 1,
      "z": 8,
      "name": "Rock_Stone"
    },
    {
      "x": -7,
      "y": 2,
      "z": 8,
      "name": "Rock_Stone"
    },
    {
      "x": -7,
      "y": 3,
      "z": 8,
      "name": "Rock_Stone"
    },
    {
      "x": -7,
      "y": 4,
      "z": 8,
      "name": "Wood_Softwood_Planks"
    },
    {
      "x": -7,
      "y": 5,
      "z": 8,
      "name": "Empty"
    },
    {
      "x": -7,
      "y": 6,
      "z": 8,
      "name": "Empty"
    },
    {
      "x": -7,
      "y": 7,
      "z": 8,
      "name": "Empty"
    },
    {
      "x": -7,
      "y": 8,
      "z": 8,
      "name": "Empty"
    },
    {
      "x": -7,
      "y": 9,
      "z": 8,
      "name": "Rock_Stone_Stalactite_Large",
      "filler": 31744,
      "rotation": 8
    },
    {
      "x": -7,
      "y": 10,
      "z": 8,
      "name": "Rock_Stone_Stalactite_Large",
      "rotation": 8
    },
    {
      "x": -7,
      "y": 11,
      "z": 8,
      "name": "Rock_Stone"
    },
    {
      "x": -7,
      "y": 12,
      "z": 8,
      "name": "Rock_Stone"
    },
    {
      "x": -7,
      "y": 13,
      "z": 8,
      "name": "Rock_Stone"
    },
    {
      "x": -7,
      "y": 14,
      "z": 8,
      "name": "Rock_Stone"
    },
    {
      "x": -7,
      "y": -1,
      "z": 9,
      "name": "Rock_Stone"
    },
    {
      "x": -7,
      "y": 0,
      "z": 9,
      "name": "Rock_Stone"
    },
    {
      "x": -7,
      "y": 1,
      "z": 9,
      "name": "Rock_Stone"
    },
    {
      "x": -7,
      "y": 2,
      "z": 9,
      "name": "Rock_Stone"
    },
    {
      "x": -7,
      "y": 3,
      "z": 9,
      "name": "Rock_Stone"
    },
    {
      "x": -7,
      "y": 4,
      "z": 9,
      "name": "Wood_Softwood_Planks"
    },
    {
      "x": -7,
      "y": 5,
      "z": 9,
      "name": "Empty"
    },
    {
      "x": -7,
      "y": 6,
      "z": 9,
      "name": "Empty"
    },
    {
      "x": -7,
      "y": 7,
      "z": 9,
      "name": "Empty"
    },
    {
      "x": -7,
      "y": 8,
      "z": 9,
      "name": "Empty"
    },
    {
      "x": -7,
      "y": 9,
      "z": 9,
      "name": "Empty"
    },
    {
      "x": -7,
      "y": 10,
      "z": 9,
      "name": "Empty"
    },
    {
      "x": -7,
      "y": 11,
      "z": 9,
      "name": "Empty"
    },
    {
      "x": -7,
      "y": 12,
      "z": 9,
      "name": "Rock_Stone"
    },
    {
      "x": -7,
      "y": 13,
      "z": 9,
      "name": "Rock_Stone"
    },
    {
      "x": -7,
      "y": 14,
      "z": 9,
      "name": "Rock_Stone"
    },
    {
      "x": -7,
      "y": -1,
      "z": 10,
      "name": "Rock_Stone"
    },
    {
      "x": -7,
      "y": 0,
      "z": 10,
      "name": "Rock_Stone"
    },
    {
      "x": -7,
      "y": 1,
      "z": 10,
      "name": "Rock_Stone"
    },
    {
      "x": -7,
      "y": 2,
      "z": 10,
      "name": "Rock_Stone"
    },
    {
      "x": -7,
      "y": 3,
      "z": 10,
      "name": "Rock_Stone"
    },
    {
      "x": -7,
      "y": 4,
      "z": 10,
      "name": "Wood_Softwood_Stairs"
    },
    {
      "x": -7,
      "y": 5,
      "z": 10,
      "name": "Empty"
    },
    {
      "x": -7,
      "y": 6,
      "z": 10,
      "name": "Empty"
    },
    {
      "x": -7,
      "y": 7,
      "z": 10,
      "name": "Empty"
    },
    {
      "x": -7,
      "y": 8,
      "z": 10,
      "name": "Empty"
    },
    {
      "x": -7,
      "y": 9,
      "z": 10,
      "name": "Empty"
    },
    {
      "x": -7,
      "y": 10,
      "z": 10,
      "name": "Empty"
    },
    {
      "x": -7,
      "y": 11,
      "z": 10,
      "name": "Empty"
    },
    {
      "x": -7,
      "y": 12,
      "z": 10,
      "name": "Rock_Stone"
    },
    {
      "x": -7,
      "y": 13,
      "z": 10,
      "name": "Rock_Stone"
    },
    {
      "x": -7,
      "y": 14,
      "z": 10,
      "name": "Rock_Stone"
    },
    {
      "x": -7,
      "y": -1,
      "z": 11,
      "name": "Rock_Stone"
    },
    {
      "x": -7,
      "y": 0,
      "z": 11,
      "name": "Rock_Stone"
    },
    {
      "x": -7,
      "y": 1,
      "z": 11,
      "name": "Rock_Stone"
    },
    {
      "x": -7,
      "y": 2,
      "z": 11,
      "name": "Rock_Stone"
    },
    {
      "x": -7,
      "y": 3,
      "z": 11,
      "name": "Rock_Stone"
    },
    {
      "x": -7,
      "y": 4,
      "z": 11,
      "name": "Empty"
    },
    {
      "x": -7,
