{
  "version": 8,
  "blockIdVersion": 8,
  "anchorX": 0,
  "anchorY": 0,
  "anchorZ": 0,
  "blocks": [
    {
      "x": -23,
      "y": 0,
      "z": -3,
      "name": "Soil_Dirt"
    },
    {
      "x": -23,
      "y": 1,
      "z": -3,
      "name": "Empty"
    },
    {
      "x": -23,
      "y": 2,
      "z": -3,
      "name": "Empty"
    },
    {
      "x": -23,
      "y": 0,
      "z": -2,
      "name": "Soil_Dirt"
    },
    {
      "x": -23,
      "y": 1,
      "z": -2,
      "name": "Survival_Trap_Spike_Wood"
    },
    {
      "x": -23,
      "y": 2,
      "z": -2,
      "name": "Empty"
    },
    {
      "x": -23,
      "y": 3,
      "z": -2,
      "name": "Empty"
    },
    {
      "x": -23,
      "y": 4,
      "z": -2,
      "name": "Empty"
    },
    {
      "x": -23,
      "y": 5,
      "z": -2,
      "name": "Rock_Stone"
    },
    {
      "x": -23,
      "y": 0,
      "z": -1,
      "name": "Soil_Dirt"
    },
    {
      "x": -23,
      "y": 1,
      "z": -1,
      "name": "Empty"
    },
    {
      "x": -23,
      "y": 2,
      "z": -1,
      "name": "Empty"
    },
    {
      "x": -23,
      "y": 3,
      "z": -1,
      "name": "Empty"
    },
    {
      "x": -23,
      "y": 4,
      "z": -1,
      "name": "Empty"
    },
    {
      "x": -23,
      "y": 5,
      "z": -1,
      "name": "Empty"
    },
    {
      "x": -23,
      "y": 6,
      "z": -1,
      "name": "Rock_Stone"
    },
    {
      "x": -23,
      "y": 0,
      "z": 0,
      "name": "Soil_Pathway"
    },
    {
      "x": -23,
      "y": 1,
      "z": 0,
      "name": "Survival_Trap_Spike_Wood"
    },
    {
      "x": -23,
      "y": 2,
      "z": 0,
      "name": "Empty"
    },
    {
      "x": -23,
      "y": 3,
      "z": 0,
      "name": "Empty"
    },
    {
      "x": -23,
      "y": 4,
      "z": 0,
      "name": "Empty"
    },
    {
      "x": -23,
      "y": 5,
      "z": 0,
      "name": "Empty"
    },
    {
      "x": -23,
      "y": 6,
      "z": 0,
      "name": "Empty"
    },
    {
      "x": -23,
      "y": 7,
      "z": 0,
      "name": "Rock_Stone"
    },
    {
      "x": -23,
      "y": 0,
      "z": 1,
      "name": "Soil_Pathway"
    },
    {
      "x": -23,
      "y": 1,
      "z": 1,
      "name": "Empty"
    },
    {
      "x": -23,
      "y": 2,
      "z": 1,
      "name": "Empty"
    },
    {
      "x": -23,
      "y": 3,
      "z": 1,
      "name": "Empty"
    },
    {
      "x": -23,
      "y": 4,
      "z": 1,
      "name": "Empty"
    },
    {
      "x": -23,
      "y": 5,
      "z": 1,
      "name": "Empty"
    },
    {
      "x": -23,
      "y": 6,
      "z": 1,
      "name": "Empty"
    },
    {
      "x": -23,
      "y": 7,
      "z": 1,
      "name": "Rock_Stone"
    },
    {
      "x": -23,
      "y": 0,
      "z": 2,
      "name": "Soil_Dirt"
    },
    {
      "x": -23,
      "y": 1,
      "z": 2,
      "name": "Empty"
    },
    {
      "x": -23,
      "y": 2,
      "z": 2,
      "name": "Empty"
    },
    {
      "x": -23,
      "y": 3,
      "z": 2,
      "name": "Empty"
    },
    {
      "x": -23,
      "y": 4,
      "z": 2,
      "name": "Empty"
    },
    {
      "x": -23,
      "y": 5,
      "z": 2,
      "name": "Empty"
    },
    {
      "x": -23,
      "y": 6,
      "z": 2,
      "name": "Empty"
    },
    {
      "x": -23,
      "y": 7,
      "z": 2,
      "name": "Rock_Stone"
    },
    {
      "x": -23,
      "y": 4,
      "z": 3,
      "name": "Rock_Stone"
    },
    {
      "x": -23,
      "y": 5,
      "z": 3,
      "name": "Rock_Stone"
    },
    {
      "x": -23,
      "y": 6,
      "z": 3,
      "name": "Rock_Stone"
    },
    {
      "x": -22,
      "y": 1,
      "z": -4,
      "name": "Rock_Stone"
    },
    {
      "x": -22,
      "y": 2,
      "z": -4,
      "name": "Rock_Stone"
    },
    {
      "x": -22,
      "y": 0,
      "z": -3,
      "name": "Rock_Stone"
    },
    {
      "x": -22,
      "y": 1,
      "z": -3,
      "name": "Rock_Stone"
    },
    {
      "x": -22,
      "y": 2,
      "z": -3,
      "name": "Rock_Stone"
    },
    {
      "x": -22,
      "y": 3,
      "z": -3,
      "name": "Rock_Stone"
    },
    {
      "x": -22,
      "y": 4,
      "z": -3,
      "name": "Rock_Stone"
    },
    {
      "x": -22,
      "y": 5,
      "z": -3,
      "name": "Rock_Stone"
    },
    {
      "x": -22,
      "y": 6,
      "z": -3,
      "name": "Rock_Stone"
    },
    {
      "x": -22,
      "y": 0,
      "z": -2,
      "name": "Soil_Dirt"
    },
    {
      "x": -22,
      "y": 1,
      "z": -2,
      "name": "Plant_Crop_Mushroom_Cap_Brown",
      "components": {
        "Components": {
          "FarmingBlock": {
            "LastTickGameTime": "0001-01-01T12:00:00Z"
          }
        }
      }
    },
    {
      "x": -22,
      "y": 2,
      "z": -2,
      "name": "Empty"
    },
    {
      "x": -22,
      "y": 3,
      "z": -2,
      "name": "Empty"
    },
    {
      "x": -22,
      "y": 4,
      "z": -2,
      "name": "Rock_Stone_Stalactite_Small",
      "rotation": 8
    },
    {
      "x": -22,
      "y": 5,
      "z": -2,
      "name": "Rock_Stone"
    },
    {
      "x": -22,
      "y": 6,
      "z": -2,
      "name": "Rock_Stone"
    },
    {
      "x": -22,
      "y": 7,
      "z": -2,
      "name": "Rock_Stone"
    },
    {
      "x": -22,
      "y": 8,
      "z": -2,
      "name": "Empty"
    },
    {
      "x": -22,
      "y": 0,
      "z": -1,
      "name": "Soil_Pathway"
    },
    {
      "x": -22,
      "y": 1,
      "z": -1,
      "name": "Empty"
    },
    {
      "x": -22,
      "y": 2,
      "z": -1,
      "name": "Empty"
    },
    {
      "x": -22,
      "y": 3,
      "z": -1,
      "name": "Empty"
    },
    {
      "x": -22,
      "y": 4,
      "z": -1,
      "name": "Empty"
    },
    {
      "x": -22,
      "y": 5,
      "z": -1,
      "name": "Empty"
    },
    {
      "x": -22,
      "y": 6,
      "z": -1,
      "name": "Rock_Stone"
    },
    {
      "x": -22,
      "y": 7,
      "z": -1,
      "name": "Rock_Stone"
    },
    {
      "x": -22,
      "y": 8,
      "z": -1,
      "name": "Empty"
    },
    {
      "x": -22,
      "y": 9,
      "z": -1,
      "name": "Empty"
    },
    {
      "x": -22,
      "y": 0,
      "z": 0,
      "name": "Soil_Pathway"
    },
    {
      "x": -22,
      "y": 1,
      "z": 0,
      "name": "Survival_Trap_Spike_Wood"
    },
    {
      "x": -22,
      "y": 2,
      "z": 0,
      "name": "Empty"
    },
    {
      "x": -22,
      "y": 3,
      "z": 0,
      "name": "Empty"
    },
    {
      "x": -22,
      "y": 4,
      "z": 0,
      "name": "Empty"
    },
    {
      "x": -22,
      "y": 5,
      "z": 0,
      "name": "Empty"
    },
    {
      "x": -22,
      "y": 6,
      "z": 0,
      "name": "Empty"
    },
    {
      "x": -22,
      "y": 7,
      "z": 0,
      "name": "Rock_Stone"
    },
    {
      "x": -22,
      "y": 8,
      "z": 0,
      "name": "Empty"
    },
    {
      "x": -22,
      "y": 9,
      "z": 0,
      "name": "Empty"
    },
    {
      "x": -22,
      "y": 10,
      "z": 0,
      "name": "Empty"
    },
    {
      "x": -22,
      "y": 0,
      "z": 1,
      "name": "Soil_Pathway"
    },
    {
      "x": -22,
      "y": 1,
      "z": 1,
      "name": "Survival_Trap_Spike_Wood"
    },
    {
      "x": -22,
      "y": 2,
      "z": 1,
      "name": "Empty"
    },
    {
      "x": -22,
      "y": 3,
      "z": 1,
      "name": "Empty"
    },
    {
      "x": -22,
      "y": 4,
      "z": 1,
      "name": "Empty"
    },
    {
      "x": -22,
      "y": 5,
      "z": 1,
      "name": "Empty"
    },
    {
      "x": -22,
      "y": 6,
      "z": 1,
      "name": "Empty"
    },
    {
      "x": -22,
      "y": 7,
      "z": 1,
      "name": "Rock_Stone"
    },
    {
      "x": -22,
      "y": 8,
      "z": 1,
      "name": "Plant_Moss_Rug_Green"
    },
    {
      "x": -22,
      "y": 9,
      "z": 1,
      "name": "Empty"
    },
    {
      "x": -22,
      "y": 10,
      "z": 1,
      "name": "Empty"
    },
    {
      "x": -22,
      "y": 0,
      "z": 2,
      "name": "Soil_Dirt"
    },
    {
      "x": -22,
      "y": 1,
      "z": 2,
      "name": "Survival_Trap_Spike_Wood"
    },
    {
      "x": -22,
      "y": 2,
      "z": 2,
      "name": "Empty"
    },
    {
      "x": -22,
      "y": 3,
      "z": 2,
      "name": "Empty"
    },
    {
      "x": -22,
      "y": 4,
      "z": 2,
      "name": "Empty"
    },
    {
      "x": -22,
      "y": 5,
      "z": 2,
      "name": "Rock_Stone"
    },
    {
      "x": -22,
      "y": 6,
      "z": 2,
      "name": "Rock_Stone"
    },
    {
      "x": -22,
      "y": 7,
      "z": 2,
      "name": "Rock_Stone"
    },
    {
      "x": -22,
      "y": 8,
      "z": 2,
      "name": "Plant_Moss_Rug_Green"
    },
    {
      "x": -22,
      "y": 9,
      "z": 2,
      "name": "Empty"
    },
    {
      "x": -22,
      "y": 10,
      "z": 2,
      "name": "Empty"
    },
    {
      "x": -22,
      "y": 2,
      "z": 3,
      "name": "Rock_Stone"
    },
    {
      "x": -22,
      "y": 3,
      "z": 3,
      "name": "Rock_Stone"
    },
    {
      "x": -22,
      "y": 4,
      "z": 3,
      "name": "Rock_Stone"
    },
    {
      "x": -22,
      "y": 5,
      "z": 3,
      "name": "Rock_Stone"
    },
    {
      "x": -22,
      "y": 6,
      "z": 3,
      "name": "Rock_Stone"
    },
    {
      "x": -22,
      "y": 7,
      "z": 3,
      "name": "Rock_Stone"
    },
    {
      "x": -22,
      "y": 8,
      "z": 3,
      "name": "Rock_Stone"
    },
    {
      "x": -22,
      "y": 3,
      "z": 4,
      "name": "Rock_Stone"
    },
    {
      "x": -22,
      "y": 4,
      "z": 4,
      "name": "Rock_Stone"
    },
    {
      "x": -22,
      "y": 5,
      "z": 4,
      "name": "Rock_Stone"
    },
    {
      "x": -22,
      "y": 6,
      "z": 4,
      "name": "Rock_Stone"
    },
    {
      "x": -22,
      "y": 7,
      "z": 4,
      "name": "Rock_Stone"
    },
    {
      "x": -22,
      "y": 5,
      "z": 5,
      "name": "Rock_Stone"
    },
    {
      "x": -21,
      "y": 1,
      "z": -5,
      "name": "Rock_Stone"
    },
    {
      "x": -21,
      "y": 2,
      "z": -5,
      "name": "Rock_Stone"
    },
    {
      "x": -21,
      "y": 3,
      "z": -5,
      "name": "Rock_Stone"
    },
    {
      "x": -21,
      "y": 0,
      "z": -4,
      "name": "Rock_Stone"
    },
    {
      "x": -21,
      "y": 1,
      "z": -4,
      "name": "Rock_Stone"
    },
    {
      "x": -21,
      "y": 2,
      "z": -4,
      "name": "Rock_Stone"
    },
    {
      "x": -21,
      "y": 3,
      "z": -4,
      "name": "Rock_Stone"
    },
    {
      "x": -21,
      "y": 4,
      "z": -4,
      "name": "Rock_Stone"
    },
    {
      "x": -21,
      "y": 5,
      "z": -4,
      "name": "Rock_Stone"
    },
    {
      "x": -21,
      "y": 0,
      "z": -3,
      "name": "Rock_Stone"
    },
    {
      "x": -21,
      "y": 1,
      "z": -3,
      "name": "Rock_Stone"
    },
    {
      "x": -21,
      "y": 2,
      "z": -3,
      "name": "Rock_Stone"
    },
    {
      "x": -21,
      "y": 3,
      "z": -3,
      "name": "Rock_Stone"
    },
    {
      "x": -21,
      "y": 4,
      "z": -3,
      "name": "Rock_Stone"
    },
    {
      "x": -21,
      "y": 5,
      "z": -3,
      "name": "Rock_Stone"
    },
    {
      "x": -21,
      "y": 6,
      "z": -3,
      "name": "Rock_Stone"
    },
    {
      "x": -21,
      "y": 7,
      "z": -3,
      "name": "Rock_Stone"
    },
    {
      "x": -21,
      "y": -1,
      "z": -2,
      "name": "Rock_Stone"
    },
    {
      "x": -21,
      "y": 0,
      "z": -2,
      "name": "Soil_Pathway"
    },
    {
      "x": -21,
      "y": 1,
      "z": -2,
      "name": "Empty"
    },
    {
      "x": -21,
      "y": 2,
      "z": -2,
      "name": "Empty"
    },
    {
      "x": -21,
      "y": 3,
      "z": -2,
      "name": "Empty"
    },
    {
      "x": -21,
      "y": 4,
      "z": -2,
      "name": "Empty"
    },
    {
      "x": -21,
      "y": 5,
      "z": -2,
      "name": "Rock_Stone"
    },
    {
      "x": -21,
      "y": 6,
      "z": -2,
      "name": "Rock_Stone"
    },
    {
      "x": -21,
      "y": 7,
      "z": -2,
      "name": "Rock_Stone"
    },
    {
      "x": -21,
      "y": 8,
      "z": -2,
      "name": "Empty"
    },
    {
      "x": -21,
      "y": 9,
      "z": -2,
      "name": "Empty"
    },
    {
      "x": -21,
      "y": 10,
      "z": -2,
      "name": "Empty"
    },
    {
      "x": -21,
      "y": -1,
      "z": -1,
      "name": "Rock_Stone"
    },
    {
      "x": -21,
      "y": 0,
      "z": -1,
      "name": "Soil_Pathway"
    },
    {
      "x": -21,
      "y": 1,
      "z": -1,
      "name": "Soil_Pathway_Half"
    },
    {
      "x": -21,
      "y": 2,
      "z": -1,
      "name": "Empty"
    },
    {
      "x": -21,
      "y": 3,
      "z": -1,
      "name": "Empty"
    },
    {
      "x": -21,
      "y": 4,
      "z": -1,
      "name": "Empty"
    },
    {
      "x": -21,
      "y": 5,
      "z": -1,
      "name": "Empty"
    },
    {
      "x": -21,
      "y": 6,
      "z": -1,
      "name": "Rock_Stone"
    },
    {
      "x": -21,
      "y": 7,
      "z": -1,
      "name": "Rock_Stone"
    },
    {
      "x": -21,
      "y": 8,
      "z": -1,
      "name": "Empty"
    },
    {
      "x": -21,
      "y": 9,
      "z": -1,
      "name": "Empty"
    },
    {
      "x": -21,
      "y": 10,
      "z": -1,
      "name": "Empty"
    },
    {
      "x": -21,
      "y": 11,
      "z": -1,
      "name": "Empty"
    },
    {
      "x": -21,
      "y": -1,
      "z": 0,
      "name": "Rock_Stone"
    },
    {
      "x": -21,
      "y": 0,
      "z": 0,
      "name": "Soil_Pathway"
    },
    {
      "x": -21,
      "y": 1,
      "z": 0,
      "name": "Soil_Pathway_Half"
    },
    {
      "x": -21,
      "y": 2,
      "z": 0,
      "name": "Empty"
    },
    {
      "x": -21,
      "y": 3,
      "z": 0,
      "name": "Empty"
    },
    {
      "x": -21,
      "y": 4,
      "z": 0,
      "name": "Empty"
    },
    {
      "x": -21,
      "y": 5,
      "z": 0,
      "name": "Empty"
    },
    {
      "x": -21,
      "y": 6,
      "z": 0,
      "name": "Empty"
    },
    {
      "x": -21,
      "y": 7,
      "z": 0,
      "name": "Rock_Stone"
    },
    {
      "x": -21,
      "y": 8,
      "z": 0,
      "name": "Empty"
    },
    {
      "x": -21,
      "y": 9,
      "z": 0,
      "name": "Empty"
    },
    {
      "x": -21,
      "y": 10,
      "z": 0,
      "name": "Empty"
    },
    {
      "x": -21,
      "y": 11,
      "z": 0,
      "name": "Empty"
    },
    {
      "x": -21,
      "y": 0,
      "z": 1,
      "name": "Soil_Pathway"
    },
    {
      "x": -21,
      "y": 1,
      "z": 1,
      "name": "Soil_Pathway_Half"
    },
    {
      "x": -21,
      "y": 2,
      "z": 1,
      "name": "Empty"
    },
    {
      "x": -21,
      "y": 3,
      "z": 1,
      "name": "Empty"
    },
    {
      "x": -21,
      "y": 4,
      "z": 1,
      "name": "Empty"
    },
    {
      "x": -21,
      "y": 5,
      "z": 1,
      "name": "Rock_Stone_Stalactite_Large",
      "filler": 31744,
      "rotation": 8
    },
    {
      "x": -21,
      "y": 6,
      "z": 1,
      "name": "Rock_Stone_Stalactite_Large",
      "rotation": 8
    },
    {
      "x": -21,
      "y": 7,
      "z": 1,
      "name": "Plant_Moss_Block_Green"
    },
    {
      "x": -21,
      "y": 8,
      "z": 1,
      "name": "Plant_Moss_Short_Green"
    },
    {
      "x": -21,
      "y": 9,
      "z": 1,
      "name": "Empty"
    },
    {
      "x": -21,
      "y": 10,
      "z": 1,
      "name": "Empty"
    },
    {
      "x": -21,
      "y": 11,
      "z": 1,
      "name": "Empty"
    },
    {
      "x": -21,
      "y": 0,
      "z": 2,
      "name": "Soil_Pathway"
    },
    {
      "x": -21,
      "y": 1,
      "z": 2,
      "name": "Soil_Pathway_Half"
    },
    {
      "x": -21,
      "y": 2,
      "z": 2,
      "name": "Empty"
    },
    {
      "x": -21,
      "y": 3,
      "z": 2,
      "name": "Empty"
    },
    {
      "x": -21,
      "y": 4,
      "z": 2,
      "name": "Empty"
    },
    {
      "x": -21,
      "y": 5,
      "z": 2,
      "name": "Empty"
    },
    {
      "x": -21,
      "y": 6,
      "z": 2,
      "name": "Plant_Moss_Wall_Green",
      "rotation": 1
    },
    {
      "x": -21,
      "y": 7,
      "z": 2,
      "name": "Plant_Moss_Wall_Green",
      "rotation": 1
    },
    {
      "x": -21,
      "y": 8,
      "z": 2,
      "name": "Empty"
    },
    {
      "x": -21,
      "y": 9,
      "z": 2,
      "name": "Empty"
    },
    {
      "x": -21,
      "y": 10,
      "z": 2,
      "name": "Empty"
    },
    {
      "x": -21,
      "y": 1,
      "z": 3,
      "name": "Rock_Stone"
    },
    {
      "x": -21,
      "y": 2,
      "z": 3,
      "name": "Rock_Stone"
    },
    {
      "x": -21,
      "y": 3,
      "z": 3,
      "name": "Rock_Stone"
    },
    {
      "x": -21,
      "y": 4,
      "z": 3,
      "name": "Rock_Stone"
    },
    {
      "x": -21,
      "y": 5,
      "z": 3,
      "name": "Rock_Stone"
    },
    {
      "x": -21,
      "y": 6,
      "z": 3,
      "name": "Rock_Stone"
    },
    {
      "x": -21,
      "y": 7,
      "z": 3,
      "name": "Rock_Stone"
    },
    {
      "x": -21,
      "y": 8,
      "z": 3,
      "name": "Rock_Stone"
    },
    {
      "x": -21,
      "y": 9,
      "z": 3,
      "name": "Rock_Stone"
    },
    {
      "x": -21,
      "y": 2,
      "z": 4,
      "name": "Rock_Stone"
    },
    {
      "x": -21,
      "y": 3,
      "z": 4,
      "name": "Rock_Stone"
    },
    {
      "x": -21,
      "y": 4,
      "z": 4,
      "name": "Rock_Stone"
    },
    {
      "x": -21,
      "y": 5,
      "z": 4,
      "name": "Rock_Stone"
    },
    {
      "x": -21,
      "y": 6,
      "z": 4,
      "name": "Rock_Stone"
    },
    {
      "x": -21,
      "y": 7,
      "z": 4,
      "name": "Rock_Stone"
    },
    {
      "x": -21,
      "y": 8,
      "z": 4,
      "name": "Rock_Stone"
    },
    {
      "x": -21,
      "y": 3,
      "z": 5,
      "name": "Rock_Stone"
    },
    {
      "x": -21,
      "y": 4,
      "z": 5,
      "name": "Rock_Stone"
    },
    {
      "x": -21,
      "y": 5,
      "z": 5,
      "name": "Rock_Stone"
    },
    {
      "x": -21,
      "y": 6,
      "z": 5,
      "name": "Rock_Stone"
    },
    {
      "x": -21,
      "y": 7,
      "z": 5,
      "name": "Rock_Stone"
    },
    {
      "x": -21,
      "y": 8,
      "z": 5,
      "name": "Rock_Stone"
    },
    {
      "x": -21,
      "y": 5,
      "z": 6,
      "name": "Rock_Stone"
    },
    {
      "x": -20,
      "y": 1,
      "z": -5,
      "name": "Rock_Stone"
    },
    {
      "x": -20,
      "y": 2,
      "z": -5,
      "name": "Rock_Stone"
    },
    {
      "x": -20,
      "y": 3,
      "z": -5,
      "name": "Rock_Stone"
    },
    {
      "x": -20,
      "y": 0,
      "z": -4,
      "name": "Rock_Stone"
    },
    {
      "x": -20,
      "y": 1,
      "z": -4,
      "name": "Rock_Stone"
    },
    {
      "x": -20,
      "y": 2,
      "z": -4,
      "name": "Rock_Stone"
    },
    {
      "x": -20,
      "y": 3,
      "z": -4,
      "name": "Rock_Stone"
    },
    {
      "x": -20,
      "y": 4,
      "z": -4,
      "name": "Rock_Stone"
    },
    {
      "x": -20,
      "y": 5,
      "z": -4,
      "name": "Rock_Stone"
    },
    {
      "x": -20,
      "y": 0,
      "z": -3,
      "name": "Rock_Stone"
    },
    {
      "x": -20,
      "y": 1,
      "z": -3,
      "name": "Rock_Stone"
    },
    {
      "x": -20,
      "y": 2,
      "z": -3,
      "name": "Rock_Stone"
    },
    {
      "x": -20,
      "y": 3,
      "z": -3,
      "name": "Rock_Stone"
    },
    {
      "x": -20,
      "y": 4,
      "z": -3,
      "name": "Rock_Stone"
    },
    {
      "x": -20,
      "y": 5,
      "z": -3,
      "name": "Rock_Stone"
    },
    {
      "x": -20,
      "y": 6,
      "z": -3,
      "name": "Rock_Stone"
    },
    {
      "x": -20,
      "y": 7,
      "z": -3,
      "name": "Rock_Stone"
    },
    {
      "x": -20,
      "y": 8,
      "z": -3,
      "name": "Deco_Pot_Clay_Broken"
    },
    {
      "x": -20,
      "y": 9,
      "z": -3,
      "name": "Empty"
    },
    {
      "x": -20,
      "y": -1,
      "z": -2,
      "name": "Rock_Stone"
    },
    {
      "x": -20,
      "y": 0,
      "z": -2,
      "name": "Soil_Pathway"
    },
    {
      "x": -20,
      "y": 1,
      "z": -2,
      "name": "Soil_Pathway_Half"
    },
    {
      "x": -20,
      "y": 2,
      "z": -2,
      "name": "Empty"
    },
    {
      "x": -20,
      "y": 3,
      "z": -2,
      "name": "Empty"
    },
    {
      "x": -20,
      "y": 4,
      "z": -2,
      "name": "Rock_Stone"
    },
    {
      "x": -20,
      "y": 5,
      "z": -2,
      "name": "Rock_Stone"
    },
    {
      "x": -20,
      "y": 6,
      "z": -2,
      "name": "Rock_Stone"
    },
    {
      "x": -20,
      "y": 7,
      "z": -2,
      "name": "Plant_Moss_Block_Green"
    },
    {
      "x": -20,
      "y": 8,
      "z": -2,
      "name": "Plant_Moss_Short_Green"
    },
    {
      "x": -20,
      "y": 9,
      "z": -2,
      "name": "Empty"
    },
    {
      "x": -20,
      "y": 10,
      "z": -2,
      "name": "Empty"
    },
    {
      "x": -20,
      "y": 11,
      "z": -2,
      "name": "Empty"
    },
    {
      "x": -20,
      "y": 0,
      "z": -1,
      "name": "Soil_Pathway"
    },
    {
      "x": -20,
      "y": 1,
      "z": -1,
      "name": "Soil_Pathway_Half"
    },
    {
      "x": -20,
      "y": 2,
      "z": -1,
      "name": "Empty"
    },
    {
      "x": -20,
      "y": 3,
      "z": -1,
      "name": "Empty"
    },
    {
      "x": -20,
      "y": 4,
      "z": -1,
      "name": "Empty"
    },
    {
      "x": -20,
      "y": 5,
      "z": -1,
      "name": "Empty"
    },
    {
      "x": -20,
      "y": 6,
      "z": -1,
      "name": "Empty"
    },
    {
      "x": -20,
      "y": 7,
      "z": -1,
      "name": "Rock_Stone"
    },
    {
      "x": -20,
      "y": 8,
      "z": -1,
      "name": "Empty"
    },
    {
      "x": -20,
      "y": 9,
      "z": -1,
      "name": "Empty"
    },
    {
      "x": -20,
      "y": 10,
      "z": -1,
      "name": "Empty"
    },
    {
      "x": -20,
      "y": 11,
      "z": -1,
      "name": "Empty"
    },
    {
      "x": -20,
      "y": 0,
      "z": 0,
      "name": "Soil_Pathway"
    },
    {
      "x": -20,
      "y": 1,
      "z": 0,
      "name": "Soil_Pathway_Half"
    },
    {
      "x": -20,
      "y": 2,
      "z": 0,
      "name": "Empty"
    },
    {
      "x": -20,
      "y": 3,
      "z": 0,
      "name": "Empty"
    },
    {
      "x": -20,
      "y": 4,
      "z": 0,
      "name": "Empty"
    },
    {
      "x": -20,
      "y": 5,
      "z": 0,
      "name": "Empty"
    },
    {
      "x": -20,
      "y": 6,
      "z": 0,
      "name": "Rock_Stone_Stalactite_Small",
      "rotation": 8
    },
    {
      "x": -20,
      "y": 7,
      "z": 0,
      "name": "Plant_Moss_Block_Green"
    },
    {
      "x": -20,
      "y": 8,
      "z": 0,
      "name": "Plant_Moss_Rug_Green"
    },
    {
      "x": -20,
      "y": 9,
      "z": 0,
      "name": "Empty"
    },
    {
      "x": -20,
      "y": 10,
      "z": 0,
      "name": "Empty"
    },
    {
      "x": -20,
      "y": 11,
      "z": 0,
      "name": "Empty"
    },
    {
      "x": -20,
      "y": 0,
      "z": 1,
      "name": "Rock_Stone"
    },
    {
      "x": -20,
      "y": 1,
      "z": 1,
      "name": "Soil_Pathway"
    },
    {
      "x": -20,
      "y": 2,
      "z": 1,
      "name": "Empty"
    },
    {
      "x": -20,
      "y": 3,
      "z": 1,
      "name": "Empty"
    },
    {
      "x": -20,
      "y": 4,
      "z": 1,
      "name": "Empty"
    },
    {
      "x": -20,
      "y": 5,
      "z": 1,
      "name": "Empty"
    },
    {
      "x": -20,
      "y": 6,
      "z": 1,
      "name": "Empty"
    },
    {
      "x": -20,
      "y": 7,
      "z": 1,
      "name": "Plant_Moss_Wall_Green",
      "rotation": 1
    },
    {
      "x": -20,
      "y": 8,
      "z": 1,
      "name": "Empty"
    },
    {
      "x": -20,
      "y": 9,
      "z": 1,
      "name": "Empty"
    },
    {
      "x": -20,
      "y": 10,
      "z": 1,
      "name": "Empty"
    },
    {
      "x": -20,
      "y": 11,
      "z": 1,
      "name": "Empty"
    },
    {
      "x": -20,
      "y": 1,
      "z": 2,
      "name": "Soil_Pathway"
    },
    {
      "x": -20,
      "y": 2,
      "z": 2,
      "name": "Empty"
    },
    {
      "x": -20,
      "y": 3,
      "z": 2,
      "name": "Empty"
    },
    {
      "x": -20,
      "y": 4,
      "z": 2,
      "name": "Empty"
    },
    {
      "x": -20,
      "y": 5,
      "z": 2,
      "name": "Empty"
    },
    {
      "x": -20,
      "y": 6,
      "z": 2,
      "name": "Empty"
    },
    {
      "x": -20,
      "y": 7,
      "z": 2,
      "name": "Empty"
    },
    {
      "x": -20,
      "y": 8,
      "z": 2,
      "name": "Rock_Stone"
    },
    {
      "x": -20,
      "y": 9,
      "z": 2,
      "name": "Rock_Stone"
    },
    {
      "x": -20,
      "y": 10,
      "z": 2,
      "name": "Rock_Stone"
    },
    {
      "x": -20,
      "y": 1,
      "z": 3,
      "name": "Rock_Stone"
    },
    {
      "x": -20,
      "y": 2,
      "z": 3,
      "name": "Rock_Stone"
    },
    {
      "x": -20,
      "y": 3,
      "z": 3,
      "name": "Rock_Stone"
    },
    {
      "x": -20,
      "y": 4,
      "z": 3,
      "name": "Rock_Stone"
    },
    {
      "x": -20,
      "y": 5,
      "z": 3,
      "name": "Rock_Stone"
    },
    {
      "x": -20,
      "y": 6,
      "z": 3,
      "name": "Rock_Stone"
    },
    {
      "x": -20,
      "y": 7,
      "z": 3,
      "name": "Rock_Stone"
    },
    {
      "x": -20,
      "y": 8,
      "z": 3,
      "name": "Rock_Stone"
    },
    {
      "x": -20,
      "y": 9,
      "z": 3,
      "name": "Rock_Stone"
    },
    {
      "x": -20,
      "y": 10,
      "z": 3,
      "name": "Rock_Stone"
    },
    {
      "x": -20,
      "y": 2,
      "z": 4,
      "name": "Rock_Stone"
    },
    {
      "x": -20,
      "y": 3,
      "z": 4,
      "name": "Rock_Stone"
    },
    {
      "x": -20,
      "y": 4,
      "z": 4,
      "name": "Rock_Stone"
    },
    {
      "x": -20,
      "y": 5,
      "z": 4,
      "name": "Rock_Stone"
    },
    {
      "x": -20,
      "y": 6,
      "z": 4,
      "name": "Rock_Stone"
    },
    {
      "x": -20,
      "y": 7,
      "z": 4,
      "name": "Rock_Stone"
    },
    {
      "x": -20,
      "y": 8,
      "z": 4,
      "name": "Rock_Stone"
    },
    {
      "x": -20,
      "y": 9,
      "z": 4,
      "name": "Rock_Stone"
    },
    {
      "x": -20,
      "y": 3,
      "z": 5,
      "name": "Rock_Stone"
    },
    {
      "x": -20,
      "y": 4,
      "z": 5,
      "name": "Rock_Stone"
    },
    {
      "x": -20,
      "y": 5,
      "z": 5,
      "name": "Rock_Stone"
    },
    {
      "x": -20,
      "y": 6,
      "z": 5,
      "name": "Rock_Stone"
    },
    {
      "x": -20,
      "y": 7,
      "z": 5,
      "name": "Rock_Stone"
    },
    {
      "x": -20,
      "y": 8,
      "z": 5,
      "name": "Rock_Stone"
    },
    {
      "x": -20,
      "y": 9,
      "z": 5,
      "name": "Rock_Stone"
    },
    {
      "x": -20,
      "y": 4,
      "z": 6,
      "name": "Rock_Stone"
    },
    {
      "x": -20,
      "y": 5,
      "z": 6,
      "name": "Rock_Stone"
    },
    {
      "x": -20,
      "y": 6,
      "z": 6,
      "name": "Rock_Stone"
    },
    {
      "x": -20,
      "y": 7,
      "z": 6,
      "name": "Rock_Stone"
    },
    {
      "x": -20,
      "y": 8,
      "z": 6,
      "name": "Rock_Stone"
    },
    {
      "x": -20,
      "y": 4,
      "z": 7,
      "name": "Rock_Stone"
    },
    {
      "x": -20,
      "y": 5,
      "z": 7,
      "name": "Rock_Stone"
    },
    {
      "x": -20,
      "y": 6,
      "z": 7,
      "name": "Rock_Stone"
    },
    {
      "x": -20,
      "y": 7,
      "z": 7,
      "name": "Rock_Stone"
    },
    {
      "x": -20,
      "y": 8,
      "z": 7,
      "name": "Rock_Stone"
    },
    {
      "x": -19,
      "y": 0,
      "z": -5,
      "name": "Rock_Stone"
    },
    {
      "x": -19,
      "y": 1,
      "z": -5,
      "name": "Rock_Stone"
    },
    {
      "x": -19,
      "y": 2,
      "z": -5,
      "name": "Rock_Stone"
    },
    {
      "x": -19,
      "y": 3,
      "z": -5,
      "name": "Rock_Stone"
    },
    {
      "x": -19,
      "y": 4,
      "z": -5,
      "name": "Rock_Stone"
    },
    {
      "x": -19,
      "y": 0,
      "z": -4,
      "name": "Rock_Stone"
    },
    {
      "x": -19,
      "y": 1,
      "z": -4,
      "name": "Rock_Stone"
    },
    {
      "x": -19,
      "y": 2,
      "z": -4,
      "name": "Rock_Stone"
    },
    {
      "x": -19,
      "y": 3,
      "z": -4,
      "name": "Rock_Stone"
    },
    {
      "x": -19,
      "y": 4,
      "z": -4,
      "name": "Rock_Stone"
    },
    {
      "x": -19,
      "y": 5,
      "z": -4,
      "name": "Rock_Stone"
    },
    {
      "x": -19,
      "y": 6,
      "z": -4,
      "name": "Rock_Stone"
    },
    {
      "x": -19,
      "y": 7,
      "z": -4,
      "name": "Rock_Stone"
    },
    {
      "x": -19,
      "y": 8,
      "z": -4,
      "name": "Furniture_Human_Ruins_Pot"
    },
    {
      "x": -19,
      "y": 9,
      "z": -4,
      "name": "Empty"
    },
    {
      "x": -19,
      "y": -1,
      "z": -3,
      "name": "Rock_Stone"
    },
    {
      "x": -19,
      "y": 0,
      "z": -3,
      "name": "Rock_Stone"
    },
    {
      "x": -19,
      "y": 1,
      "z": -3,
      "name": "Rock_Stone"
    },
    {
      "x": -19,
      "y": 2,
      "z": -3,
      "name": "Rock_Stone"
    },
    {
      "x": -19,
      "y": 3,
      "z": -3,
      "name": "Rock_Stone"
    },
    {
      "x": -19,
      "y": 4,
      "z": -3,
      "name": "Rock_Stone"
    },
    {
      "x": -19,
      "y": 5,
      "z": -3,
      "name": "Rock_Stone"
    },
    {
      "x": -19,
      "y": 6,
      "z": -3,
      "name": "Rock_Stone"
    },
    {
      "x": -19,
      "y": 7,
      "z": -3,
      "name": "Rock_Stone"
    },
    {
      "x": -19,
      "y": 8,
      "z": -3,
      "name": "Empty"
    },
    {
      "x": -19,
      "y": 9,
      "z": -3,
      "name": "Empty"
    },
    {
      "x": -19,
      "y": 10,
      "z": -3,
      "name": "Empty"
    },
    {
      "x": -19,
      "y": -1,
      "z": -2,
      "name": "Rock_Stone"
    },
    {
      "x": -19,
      "y": 0,
      "z": -2,
      "name": "Soil_Pathway"
    },
    {
      "x": -19,
      "y": 1,
      "z": -2,
      "name": "Soil_Pathway"
    },
    {
      "x": -19,
      "y": 2,
      "z": -2,
      "name": "Wood_Softwood_Fence",
      "rotation": 3
    },
    {
      "x": -19,
      "y": 3,
      "z": -2,
      "name": "Wood_Softwood_Fence",
      "rotation": 3
    },
    {
      "x": -19,
      "y": 4,
      "z": -2,
      "name": "Empty"
    },
    {
      "x": -19,
      "y": 5,
      "z": -2,
      "name": "Rock_Stone"
    },
    {
      "x": -19,
      "y": 6,
      "z": -2,
      "name": "Rock_Stone"
    },
    {
      "x": -19,
      "y": 7,
      "z": -2,
      "name": "Plant_Moss_Block_Green"
    },
    {
      "x": -19,
      "y": 8,
      "z": -2,
      "name": "Plant_Moss_Green"
    },
    {
      "x": -19,
      "y": 9,
      "z": -2,
      "name": "Empty"
    },
    {
      "x": -19,
      "y": 10,
      "z": -2,
      "name": "Empty"
    },
    {
      "x": -19,
      "y": 11,
      "z": -2,
      "name": "Empty"
    },
    {
      "x": -19,
      "y": 0,
      "z": -1,
      "name": "Rock_Stone"
    },
    {
      "x": -19,
      "y": 1,
      "z": -1,
      "name": "Soil_Pathway"
    },
    {
      "x": -19,
      "y": 2,
      "z": -1,
      "name": "Wood_Softwood_Fence",
      "rotation": 3
    },
    {
      "x": -19,
      "y": 3,
      "z": -1,
      "name": "Empty"
    },
    {
      "x": -19,
      "y": 4,
      "z": -1,
      "name": "Empty"
    },
    {
      "x": -19,
      "y": 5,
      "z": -1,
      "name": "Empty"
    },
    {
      "x": -19,
      "y": 6,
      "z": -1,
      "name": "Plant_Moss_Cave_Green",
      "rotation": 8
    },
    {
      "x": -19,
      "y": 7,
      "z": -1,
      "name": "Plant_Moss_Block_Green"
    },
    {
      "x": -19,
      "y": 8,
      "z": -1,
      "name": "Plant_Moss_Short_Green"
    },
    {
      "x": -19,
      "y": 9,
      "z": -1,
      "name": "Empty"
    },
    {
      "x": -19,
      "y": 10,
      "z": -1,
      "name": "Empty"
    },
    {
      "x": -19,
      "y": 11,
      "z": -1,
      "name": "Empty"
    },
    {
      "x": -19,
      "y": 0,
      "z": 0,
      "name": "Rock_Stone"
    },
    {
      "x": -19,
      "y": 1,
      "z": 0,
      "name": "Soil_Pathway"
    },
    {
      "x": -19,
      "y": 2,
      "z": 0,
      "name": "Wood_Softwood_Fence",
      "rotation": 3
    },
    {
      "x": -19,
      "y": 3,
      "z": 0,
      "name": "Empty"
    },
    {
      "x": -19,
      "y": 4,
      "z": 0,
      "name": "Empty"
    },
    {
      "x": -19,
      "y": 5,
      "z": 0,
      "name": "Empty"
    },
    {
      "x": -19,
      "y": 6,
      "z": 0,
      "name": "Empty"
    },
    {
      "x": -19,
      "y": 7,
      "z": 0,
      "name": "Plant_Moss_Wall_Green"
    },
    {
      "x": -19,
      "y": 8,
      "z": 0,
      "name": "Empty"
    },
    {
      "x": -19,
      "y": 9,
      "z": 0,
      "name": "Empty"
    },
    {
      "x": -19,
      "y": 10,
      "z": 0,
      "name": "Empty"
    },
    {
      "x": -19,
      "y": 11,
      "z": 0,
      "name": "Empty"
    },
    {
      "x": -19,
      "y": 0,
      "z": 1,
      "name": "Rock_Stone"
    },
    {
      "x": -19,
      "y": 1,
      "z": 1,
      "name": "Soil_Pathway"
    },
    {
      "x": -19,
      "y": 2,
      "z": 1,
      "name": "Wood_Softwood_Fence",
      "rotation": 3
    },
    {
      "x": -19,
      "y": 3,
      "z": 1,
      "name": "Wood_Softwood_Fence",
      "rotation": 3
    },
    {
      "x": -19,
      "y": 4,
      "z": 1,
      "name": "Empty"
    },
    {
      "x": -19,
      "y": 5,
      "z": 1,
      "name": "Empty"
    },
    {
      "x": -19,
      "y": 6,
      "z": 1,
      "name": "Empty"
    },
    {
      "x": -19,
      "y": 7,
      "z": 1,
      "name": "Empty"
    },
    {
      "x": -19,
      "y": 8,
      "z": 1,
      "name": "Empty"
    },
    {
      "x": -19,
      "y": 9,
      "z": 1,
      "name": "Rock_Stone"
    },
    {
      "x": -19,
      "y": 10,
      "z": 1,
      "name": "Rock_Stone"
    },
    {
      "x": -19,
      "y": 11,
      "z": 1,
      "name": "Rock_Stone"
    },
    {
      "x": -19,
      "y": 1,
      "z": 2,
      "name": "Soil_Pathway"
    },
    {
      "x": -19,
      "y": 2,
      "z": 2,
      "name": "Wood_Softwood_Fence",
      "rotation": 3
    },
    {
      "x": -19,
      "y": 3,
      "z": 2,
      "name": "Wood_Softwood_Fence",
      "rotation": 3
    },
    {
      "x": -19,
      "y": 4,
      "z": 2,
      "name": "Empty"
    },
    {
      "x": -19,
      "y": 5,
      "z": 2,
      "name": "Empty"
    },
    {
      "x": -19,
      "y": 6,
      "z": 2,
      "name": "Empty"
    },
    {
      "x": -19,
      "y": 7,
      "z": 2,
      "name": "Rock_Stone"
    },
    {
      "x": -19,
      "y": 8,
      "z": 2,
      "name": "Rock_Stone"
    },
    {
      "x": -19,
      "y": 9,
      "z": 2,
      "name": "Rock_Stone"
    },
    {
      "x": -19,
      "y": 10,
      "z": 2,
      "name": "Rock_Stone"
    },
    {
      "x": -19,
      "y": 11,
      "z": 2,
      "name": "Rock_Stone"
    },
    {
      "x": -19,
      "y": 1,
      "z": 3,
      "name": "Rock_Stone"
    },
    {
      "x": -19,
      "y": 2,
      "z": 3,
      "name": "Rock_Stone"
    },
    {
      "x": -19,
      "y": 3,
      "z": 3,
      "name": "Rock_Stone"
    },
    {
      "x": -19,
      "y": 4,
      "z": 3,
      "name": "Rock_Stone"
    },
    {
      "x": -19,
      "y": 5,
      "z": 3,
      "name": "Rock_Stone"
    },
    {
      "x": -19,
      "y": 6,
      "z": 3,
      "name": "Rock_Stone"
    },
    {
      "x": -19,
      "y": 7,
      "z": 3,
      "name": "Rock_Stone"
    },
    {
      "x": -19,
      "y": 8,
      "z": 3,
      "name": "Rock_Stone"
    },
    {
      "x": -19,
      "y": 9,
      "z": 3,
      "name": "Rock_Stone"
    },
    {
      "x": -19,
      "y": 10,
      "z": 3,
      "name": "Rock_Stone"
    },
    {
      "x": -19,
      "y": 11,
      "z": 3,
      "name": "Rock_Stone"
    },
    {
      "x": -19,
      "y": 1,
      "z": 4,
      "name": "Rock_Stone"
    },
    {
      "x": -19,
      "y": 2,
      "z": 4,
      "name": "Rock_Stone"
    },
    {
      "x": -19,
      "y": 3,
      "z": 4,
      "name": "Rock_Stone"
    },
    {
      "x": -19,
      "y": 4,
      "z": 4,
      "name": "Rock_Stone"
    },
    {
      "x": -19,
      "y": 5,
      "z": 4,
      "name": "Rock_Stone"
    },
    {
      "x": -19,
      "y": 6,
      "z": 4,
      "name": "Rock_Stone"
    },
    {
      "x": -19,
      "y": 7,
      "z": 4,
      "name": "Rock_Stone"
    },
    {
      "x": -19,
      "y": 8,
      "z": 4,
      "name": "Rock_Stone"
    },
    {
      "x": -19,
      "y": 9,
      "z": 4,
      "name": "Rock_Stone"
    },
    {
      "x": -19,
      "y": 10,
      "z": 4,
      "name": "Rock_Stone"
    },
    {
      "x": -19,
      "y": 2,
      "z": 5,
      "name": "Rock_Stone"
    },
    {
      "x": -19,
      "y": 3,
      "z": 5,
      "name": "Rock_Stone"
    },
    {
      "x": -19,
      "y": 4,
      "z": 5,
      "name": "Rock_Stone"
    },
    {
      "x": -19,
      "y": 5,
      "z": 5,
      "name": "Rock_Stone"
    },
    {
      "x": -19,
      "y": 6,
      "z": 5,
      "name": "Rock_Stone"
    },
    {
      "x": -19,
      "y": 7,
      "z": 5,
      "name": "Rock_Stone"
    },
    {
      "x": -19,
      "y": 8,
      "z": 5,
      "name": "Rock_Stone"
    },
    {
      "x": -19,
      "y": 9,
      "z": 5,
      "name": "Rock_Stone"
    },
    {
      "x": -19,
      "y": 10,
      "z": 5,
      "name": "Rock_Stone"
    },
    {
      "x": -19,
      "y": 3,
      "z": 6,
      "name": "Rock_Stone"
    },
    {
      "x": -19,
      "y": 4,
      "z": 6,
      "name": "Rock_Stone"
    },
    {
      "x": -19,
      "y": 5,
      "z": 6,
      "name": "Rock_Stone"
    },
    {
      "x": -19,
      "y": 6,
      "z": 6,
      "name": "Rock_Stone"
    },
    {
      "x": -19,
      "y": 7,
      "z": 6,
      "name": "Rock_Stone"
    },
    {
      "x": -19,
      "y": 8,
      "z": 6,
      "name": "Rock_Stone"
    },
    {
      "x": -19,
      "y": 9,
      "z": 6,
      "name": "Rock_Stone"
    },
    {
      "x": -19,
      "y": 3,
      "z": 7,
      "name": "Rock_Stone"
    },
    {
      "x": -19,
      "y": 4,
      "z": 7,
      "name": "Rock_Stone"
    },
    {
      "x": -19,
      "y": 5,
      "z": 7,
      "name": "Rock_Stone"
    },
    {
      "x": -19,
      "y": 6,
      "z": 7,
      "name": "Rock_Stone"
    },
    {
      "x": -19,
      "y": 7,
      "z": 7,
      "name": "Rock_Stone"
    },
    {
      "x": -19,
      "y": 8,
      "z": 7,
      "name": "Rock_Stone"
    },
    {
      "x": -18,
      "y": 0,
      "z": -5,
      "name": "Soil_Dirt"
    },
    {
      "x": -18,
      "y": 1,
      "z": -5,
      "name": "Empty"
    },
    {
      "x": -18,
      "y": 2,
      "z": -5,
      "name": "Empty"
    },
    {
      "x": -18,
      "y": 3,
      "z": -5,
      "name": "Rock_Stone"
    },
    {
      "x": -18,
      "y": 4,
      "z": -5,
      "name": "Rock_Stone"
    },
    {
      "x": -18,
      "y": 5,
      "z": -5,
      "name": "Rock_Stone"
    },
    {
      "x": -18,
      "y": -1,
      "z": -4,
      "name": "Rock_Stone"
    },
    {
      "x": -18,
      "y": 0,
      "z": -4,
      "name": "Soil_Dirt"
    },
    {
      "x": -18,
      "y": 1,
      "z": -4,
      "name": "Empty"
    },
    {
      "x": -18,
      "y": 2,
      "z": -4,
      "name": "Empty"
    },
    {
      "x": -18,
      "y": 3,
      "z": -4,
      "name": "Rock_Stone"
    },
    {
      "x": -18,
      "y": 4,
      "z": -4,
      "name": "Rock_Stone"
    },
    {
      "x": -18,
      "y": 5,
      "z": -4,
      "name": "Rock_Stone"
    },
    {
      "x": -18,
      "y": 6,
      "z": -4,
      "name": "Rock_Stone"
    },
    {
      "x": -18,
      "y": 7,
      "z": -4,
      "name": "Rock_Stone"
    },
    {
      "x": -18,
      "y": 8,
      "z": -4,
      "name": "Block_Spawner_Block",
      "components": {
        "Components": {
          "BlockSpawner": {
            "BlockSpawnerId": "Zone1_Goblin_Tier3"
          }
        }
      }
    },
    {
      "x": -18,
      "y": 9,
      "z": -4,
      "name": "Empty"
    },
    {
      "x": -18,
      "y": 10,
      "z": -4,
      "name": "Empty"
    },
    {
      "x": -18,
      "y": -1,
      "z": -3,
      "name": "Rock_Stone"
    },
    {
      "x": -18,
      "y": 0,
      "z": -3,
      "name": "Soil_Pathway"
    },
    {
      "x": -18,
      "y": 1,
      "z": -3,
      "name": "Soil_Pathway_Half"
    },
    {
      "x": -18,
      "y": 2,
      "z": -3,
      "name": "Empty"
    },
    {
      "x": -18,
      "y": 3,
      "z": -3,
      "name": "Empty"
    },
    {
      "x": -18,
      "y": 4,
      "z": -3,
      "name": "Empty"
    },
    {
      "x": -18,
      "y": 5,
      "z": -3,
      "name": "Rock_Stone"
    },
    {
      "x": -18,
      "y": 6,
      "z": -3,
      "name": "Rock_Stone"
    },
    {
      "x": -18,
      "y": 7,
      "z": -3,
      "name": "Plant_Moss_Block_Green"
    },
    {
      "x": -18,
      "y": 8,
      "z": -3,
      "name": "Plant_Moss_Rug_Green"
    },
    {
      "x": -18,
      "y": 9,
      "z": -3,
      "name": "Empty"
    },
    {
      "x": -18,
      "y": 10,
      "z": -3,
      "name": "Empty"
    },
    {
      "x": -18,
      "y": 0,
      "z": -2,
      "name": "Soil_Pathway"
    },
    {
      "x": -18,
      "y": 1,
      "z": -2,
      "name": "Soil_Pathway_Half"
    },
    {
      "x": -18,
      "y": 2,
      "z": -2,
      "name": "Empty"
    },
    {
      "x": -18,
      "y": 3,
      "z": -2,
      "name": "Empty"
    },
    {
      "x": -18,
      "y": 4,
      "z": -2,
      "name": "Empty"
    },
    {
      "x": -18,
      "y": 5,
      "z": -2,
      "name": "Empty"
    },
    {
      "x": -18,
      "y": 6,
      "z": -2,
      "name": "Rock_Stone"
    },
    {
      "x": -18,
      "y": 7,
      "z": -2,
      "name": "Plant_Moss_Block_Green"
    },
    {
      "x": -18,
      "y": 8,
      "z": -2,
      "name": "Plant_Moss_Rug_Green"
    },
    {
      "x": -18,
      "y": 9,
      "z": -2,
      "name": "Empty"
    },
    {
      "x": -18,
      "y": 10,
      "z": -2,
      "name": "Empty"
    },
    {
      "x": -18,
      "y": 11,
      "z": -2,
      "name": "Rock_Stone"
    },
    {
      "x": -18,
      "y": 0,
      "z": -1,
      "name": "Rock_Stone"
    },
    {
      "x": -18,
      "y": 1,
      "z": -1,
      "name": "Soil_Pathway"
    },
    {
      "x": -18,
      "y": 2,
      "z": -1,
      "name": "Empty"
    },
    {
      "x": -18,
      "y": 3,
      "z": -1,
      "name": "Empty"
    },
    {
      "x": -18,
      "y": 4,
      "z": -1,
      "name": "Empty"
    },
    {
      "x": -18,
      "y": 5,
      "z": -1,
      "name": "Empty"
    },
    {
      "x": -18,
      "y": 6,
      "z": -1,
      "name": "Empty"
    },
    {
      "x": -18,
      "y": 7,
      "z": -1,
      "name": "Plant_Moss_Wall_Green",
      "rotation": 1
    },
    {
      "x": -18,
      "y": 8,
      "z": -1,
      "name": "Empty"
    },
    {
      "x": -18,
      "y": 9,
      "z": -1,
      "name": "Empty"
    },
    {
      "x": -18,
      "y": 10,
      "z": -1,
      "name": "Empty"
    },
    {
      "x": -18,
      "y": 11,
      "z": -1,
      "name": "Rock_Stone"
    },
    {
      "x": -18,
      "y": 1,
      "z": 0,
      "name": "Soil_Pathway"
    },
    {
      "x": -18,
      "y": 2,
      "z": 0,
      "name": "Empty"
    },
    {
      "x": -18,
      "y": 3,
      "z": 0,
      "name": "Empty"
    },
    {
      "x": -18,
      "y": 4,
      "z": 0,
      "name": "Empty"
    },
    {
      "x": -18,
      "y": 5,
      "z": 0,
      "name": "Empty"
    },
    {
      "x": -18,
      "y": 6,
      "z": 0,
      "name": "Empty"
    },
    {
      "x": -18,
      "y": 7,
      "z": 0,
      "name": "Empty"
    },
    {
      "x": -18,
      "y": 8,
      "z": 0,
      "name": "Empty"
    },
    {
      "x": -18,
      "y": 9,
      "z": 0,
      "name": "Empty"
    },
    {
      "x": -18,
      "y": 10,
      "z": 0,
      "name": "Rock_Stone"
    },
    {
      "x": -18,
      "y": 11,
      "z": 0,
      "name": "Rock_Stone"
    },
    {
      "x": -18,
      "y": 1,
      "z": 1,
      "name": "Soil_Pathway"
    },
    {
      "x": -18,
      "y": 2,
      "z": 1,
      "name": "Empty"
    },
    {
      "x": -18,
      "y": 3,
      "z": 1,
      "name": "Empty"
    },
    {
      "x": -18,
      "y": 4,
      "z": 1,
      "name": "Empty"
    },
    {
      "x": -18,
      "y": 5,
      "z": 1,
      "name": "Empty"
    },
    {
      "x": -18,
      "y": 6,
      "z": 1,
      "name": "Empty"
    },
    {
      "x": -18,
      "y": 7,
      "z": 1,
      "name": "Rock_Stone"
    },
    {
      "x": -18,
      "y": 8,
      "z": 1,
      "name": "Rock_Stone"
    },
    {
      "x": -18,
      "y": 9,
      "z": 1,
      "name": "Rock_Stone"
    },
    {
      "x": -18,
      "y": 10,
      "z": 1,
      "name": "Rock_Stone"
    },
    {
      "x": -18,
      "y": 11,
      "z": 1,
      "name": "Rock_Stone"
    },
    {
      "x": -18,
      "y": 1,
      "z": 2,
      "name": "Soil_Pathway"
    },
    {
      "x": -18,
      "y": 2,
      "z": 2,
      "name": "Empty"
    },
    {
      "x": -18,
      "y": 3,
      "z": 2,
      "name": "Empty"
    },
    {
      "x": -18,
      "y": 4,
      "z": 2,
      "name": "Empty"
    },
    {
      "x": -18,
      "y": 5,
      "z": 2,
      "name": "Empty"
    },
    {
      "x": -18,
      "y": 6,
      "z": 2,
      "name": "Rock_Stone"
    },
    {
      "x": -18,
      "y": 7,
      "z": 2,
      "name": "Rock_Stone"
    },
    {
      "x": -18,
      "y": 8,
      "z": 2,
      "name": "Rock_Stone"
    },
    {
      "x": -18,
      "y": 9,
      "z": 2,
      "name": "Rock_Stone"
    },
    {
      "x": -18,
      "y": 10,
      "z": 2,
      "name": "Rock_Stone"
    },
    {
      "x": -18,
      "y": 11,
      "z": 2,
      "name": "Rock_Stone"
    },
    {
      "x": -18,
      "y": 1,
      "z": 3,
      "name": "Rock_Stone"
    },
    {
      "x": -18,
      "y": 2,
      "z": 3,
      "name": "Rock_Stone"
    },
    {
      "x": -18,
      "y": 3,
      "z": 3,
      "name": "Rock_Stone"
    },
    {
      "x": -18,
      "y": 4,
      "z": 3,
      "name": "Rock_Stone"
    },
    {
      "x": -18,
      "y": 5,
      "z": 3,
      "name": "Rock_Stone"
    },
    {
      "x": -18,
      "y": 6,
      "z": 3,
      "name": "Rock_Stone"
    },
    {
      "x": -18,
      "y": 7,
      "z": 3,
      "name": "Rock_Stone"
    },
    {
      "x": -18,
      "y": 8,
      "z": 3,
      "name": "Rock_Stone"
    },
    {
      "x": -18,
      "y": 9,
      "z": 3,
      "name": "Rock_Stone"
    },
    {
      "x": -18,
      "y": 10,
      "z": 3,
      "name": "Rock_Stone"
    },
    {
      "x": -18,
      "y": 11,
      "z": 3,
      "name": "Rock_Stone"
    },
    {
      "x": -18,
      "y": 1,
      "z": 4,
      "name": "Rock_Stone"
    },
    {
      "x": -18,
      "y": 2,
      "z": 4,
      "name": "Rock_Stone"
    },
    {
      "x": -18,
      "y": 3,
      "z": 4,
      "name": "Rock_Stone"
    },
    {
      "x": -18,
      "y": 4,
      "z": 4,
      "name": "Rock_Stone"
    },
    {
      "x": -18,
      "y": 5,
      "z": 4,
      "name": "Rock_Stone"
    },
    {
      "x": -18,
      "y": 6,
      "z": 4,
      "name": "Rock_Stone"
    },
    {
      "x": -18,
      "y": 7,
      "z": 4,
      "name": "Rock_Stone"
    },
    {
      "x": -18,
      "y": 8,
      "z": 4,
      "name": "Rock_Stone"
    },
    {
      "x": -18,
      "y": 9,
      "z": 4,
      "name": "Rock_Stone"
    },
    {
      "x": -18,
      "y": 10,
      "z": 4,
      "name": "Rock_Stone"
    },
    {
      "x": -18,
      "y": 11,
      "z": 4,
      "name": "Rock_Stone"
    },
    {
      "x": -18,
      "y": 1,
      "z": 5,
      "name": "Rock_Stone"
    },
    {
      "x": -18,
      "y": 2,
      "z": 5,
      "name": "Rock_Stone"
    },
    {
      "x": -18,
      "y": 3,
      "z": 5,
      "name": "Rock_Stone"
    },
    {
      "x": -18,
      "y": 4,
      "z": 5,
      "name": "Rock_Stone"
    },
    {
      "x": -18,
      "y": 5,
      "z": 5,
      "name": "Rock_Stone"
    },
    {
      "x": -18,
      "y": 6,
      "z": 5,
      "name": "Rock_Stone"
    },
    {
      "x": -18,
      "y": 7,
      "z": 5,
      "name": "Rock_Stone"
    },
    {
      "x": -18,
      "y": 8,
      "z": 5,
      "name": "Rock_Stone"
    },
    {
      "x": -18,
      "y": 9,
      "z": 5,
      "name": "Rock_Stone"
    },
    {
      "x": -18,
      "y": 10,
      "z": 5,
      "name": "Rock_Stone"
    },
    {
      "x": -18,
      "y": 2,
      "z": 6,
      "name": "Rock_Stone"
    },
    {
      "x": -18,
      "y": 3,
      "z": 6,
      "name": "Rock_Stone"
    },
    {
      "x": -18,
      "y": 4,
      "z": 6,
      "name": "Rock_Stone"
    },
    {
      "x": -18,
      "y": 5,
      "z": 6,
      "name": "Rock_Stone"
    },
    {
      "x": -18,
      "y": 6,
      "z": 6,
      "name": "Rock_Stone"
    },
    {
      "x": -18,
      "y": 7,
      "z": 6,
      "name": "Rock_Stone"
    },
    {
      "x": -18,
      "y": 8,
      "z": 6,
      "name": "Rock_Stone"
    },
    {
      "x": -18,
      "y": 9,
      "z": 6,
      "name": "Rock_Stone"
    },
    {
      "x": -18,
      "y": 10,
      "z": 6,
      "name": "Rock_Stone"
    },
    {
      "x": -18,
      "y": 3,
      "z": 7,
      "name": "Rock_Stone"
    },
    {
      "x": -18,
      "y": 4,
      "z": 7,
      "name": "Rock_Stone"
    },
    {
      "x": -18,
      "y": 5,
      "z": 7,
      "name": "Rock_Stone"
    },
    {
      "x": -18,
      "y": 6,
      "z": 7,
      "name": "Rock_Stone"
    },
    {
      "x": -18,
      "y": 7,
      "z": 7,
      "name": "Rock_Stone"
    },
    {
      "x": -18,
      "y": 8,
      "z": 7,
      "name": "Rock_Stone"
    },
    {
      "x": -18,
      "y": 9,
      "z": 7,
      "name": "Rock_Stone"
    },
    {
      "x": -18,
      "y": 4,
      "z": 8,
      "name": "Rock_Stone"
    },
    {
      "x": -18,
      "y": 5,
      "z": 8,
      "name": "Rock_Stone"
    },
    {
      "x": -18,
      "y": 6,
      "z": 8,
      "name": "Rock_Stone"
    },
    {
      "x": -18,
      "y": 7,
      "z": 8,
      "name": "Rock_Stone"
    },
    {
      "x": -18,
      "y": 8,
      "z": 8,
      "name": "Rock_Stone"
    },
    {
      "x": -17,
      "y": 0,
      "z": -6,
      "name": "Soil_Dirt"
    },
    {
      "x": -17,
      "y": 1,
      "z": -6,
      "name": "Empty"
    },
    {
      "x": -17,
      "y": 2,
      "z": -6,
      "name": "Empty"
    },
    {
      "x": -17,
      "y": -1,
      "z": -5,
      "name": "Rock_Stone"
    },
    {
      "x": -17,
      "y": 0,
      "z": -5,
      "name": "Soil_Dirt"
    },
    {
      "x": -17,
      "y": 1,
      "z": -5,
      "name": "Empty"
    },
    {
      "x": -17,
      "y": 2,
      "z": -5,
      "name": "Empty"
    },
    {
      "x": -17,
      "y": 3,
      "z": -5,
      "name": "Rock_Stone"
    },
    {
      "x": -17,
      "y": 4,
      "z": -5,
      "name": "Rock_Stone"
    },
    {
      "x": -17,
      "y": 5,
      "z": -5,
      "name": "Rock_Stone"
    },
    {
      "x": -17,
      "y": 6,
      "z": -5,
      "name": "Rock_Stone"
    },
    {
      "x": -17,
      "y": 7,
      "z": -5,
      "name": "Rock_Stone"
    },
    {
      "x": -17,
      "y": -1,
      "z": -4,
      "name": "Rock_Stone"
    },
    {
      "x": -17,
      "y": 0,
      "z": -4,
      "name": "Soil_Pathway"
    },
    {
      "x": -17,
      "y": 1,
      "z": -4,
      "name": "Empty"
    },
    {
      "x": -17,
      "y": 2,
      "z": -4,
      "name": "Empty"
    },
    {
      "x": -17,
      "y": 3,
      "z": -4,
      "name": "Empty"
    },
    {
      "x": -17,
      "y": 4,
      "z": -4,
      "name": "Rock_Stone"
    },
    {
      "x": -17,
      "y": 5,
      "z": -4,
      "name": "Rock_Stone"
    },
    {
      "x": -17,
      "y": 6,
      "z": -4,
      "name": "Rock_Stone"
    },
    {
      "x": -17,
      "y": 7,
      "z": -4,
      "name": "Rock_Stone"
    },
    {
      "x": -17,
      "y": 8,
      "z": -4,
      "name": "Plant_Moss_Rug_Green"
    },
    {
      "x": -17,
      "y": 9,
      "z": -4,
      "name": "Empty"
    },
    {
      "x": -17,
      "y": 10,
      "z": -4,
      "name": "Empty"
    },
    {
      "x": -17,
      "y": -1,
      "z": -3,
      "name": "Rock_Stone"
    },
    {
      "x": -17,
      "y": 0,
      "z": -3,
      "name": "Soil_Pathway"
    },
    {
      "x": -17,
      "y": 1,
      "z": -3,
      "name": "Soil_Pathway_Half"
    },
    {
      "x": -17,
      "y": 2,
      "z": -3,
      "name": "Empty"
    },
    {
      "x": -17,
      "y": 3,
      "z": -3,
      "name": "Empty"
    },
    {
      "x": -17,
      "y": 4,
      "z": -3,
      "name": "Empty"
    },
    {
      "x": -17,
      "y": 5,
      "z": -3,
      "name": "Empty"
    },
    {
      "x": -17,
      "y": 6,
      "z": -3,
      "name": "Rock_Stone"
    },
    {
      "x": -17,
      "y": 7,
      "z": -3,
      "name": "Plant_Moss_Block_Green"
    },
    {
      "x": -17,
      "y": 8,
      "z": -3,
      "name": "Plant_Moss_Rug_Green"
    },
    {
      "x": -17,
      "y": 9,
      "z": -3,
      "name": "Empty"
    },
    {
      "x": -17,
      "y": 10,
      "z": -3,
      "name": "Empty"
    },
    {
      "x": -17,
      "y": 0,
      "z": -2,
      "name": "Soil_Pathway"
    },
    {
      "x": -17,
      "y": 1,
      "z": -2,
      "name": "Soil_Pathway_Half"
    },
    {
      "x": -17,
      "y": 2,
      "z": -2,
      "name": "Empty"
    },
    {
      "x": -17,
      "y": 3,
      "z": -2,
      "name": "Empty"
    },
    {
      "x": -17,
      "y": 4,
      "z": -2,
      "name": "Empty"
    },
    {
      "x": -17,
      "y": 5,
      "z": -2,
      "name": "Empty"
    },
    {
      "x": -17,
      "y": 6,
      "z": -2,
      "name": "Empty"
    },
    {
      "x": -17,
      "y": 7,
      "z": -2,
      "name": "Plant_Moss_Block_Green"
    },
    {
      "x": -17,
      "y": 8,
      "z": -2,
      "name": "Plant_Moss_Rug_Green"
    },
    {
      "x": -17,
      "y": 9,
      "z": -2,
      "name": "Empty"
    },
    {
      "x": -17,
      "y": 10,
      "z": -2,
      "name": "Rock_Stone"
    },
    {
      "x": -17,
      "y": 11,
      "z": -2,
      "name": "Rock_Stone"
    },
    {
      "x": -17,
      "y": 0,
      "z": -1,
      "name": "Soil_Pathway"
    },
    {
      "x": -17,
      "y": 1,
      "z": -1,
      "name": "Soil_Pathway_Half"
    },
    {
      "x": -17,
      "y": 2,
      "z": -1,
      "name": "Empty"
    },
    {
      "x": -17,
      "y": 3,
      "z": -1,
      "name": "Empty"
    },
    {
      "x": -17,
      "y": 4,
      "z": -1,
      "name": "Empty"
    },
    {
      "x": -17,
      "y": 5,
      "z": -1,
      "name": "Empty"
    },
    {
      "x": -17,
      "y": 6,
      "z": -1,
      "name": "Empty"
    },
    {
      "x": -17,
      "y": 7,
      "z": -1,
      "name": "Empty"
    },
    {
      "x": -17,
      "y": 8,
      "z": -1,
      "name": "Empty"
    },
    {
      "x": -17,
      "y": 9,
      "z": -1,
      "name": "Empty"
    },
    {
      "x": -17,
      "y": 10,
      "z": -1,
      "name": "Rock_Stone"
    },
    {
      "x": -17,
      "y": 11,
      "z": -1,
      "name": "Rock_Stone"
    },
    {
      "x": -17,
      "y": 1,
      "z": 0,
      "name": "Soil_Pathway"
    },
    {
      "x": -17,
      "y": 2,
      "z": 0,
      "name": "Empty"
    },
    {
      "x": -17,
      "y": 3,
      "z": 0,
      "name": "Empty"
    },
    {
      "x": -17,
      "y": 4,
      "z": 0,
      "name": "Empty"
    },
    {
      "x": -17,
      "y": 5,
      "z": 0,
      "name": "Empty"
    },
    {
      "x": -17,
      "y": 6,
      "z": 0,
      "name": "Empty"
    },
    {
      "x": -17,
      "y": 7,
      "z": 0,
      "name": "Empty"
    },
    {
      "x": -17,
      "y": 8,
      "z": 0,
      "name": "Empty"
    },
    {
      "x": -17,
      "y": 9,
      "z": 0,
      "name": "Rock_Stone"
    },
    {
      "x": -17,
      "y": 10,
      "z": 0,
      "name": "Rock_Stone"
    },
    {
      "x": -17,
      "y": 11,
      "z": 0,
      "name": "Rock_Stone"
    },
    {
      "x": -17,
      "y": 1,
      "z": 1,
      "name": "Soil_Pathway"
    },
    {
      "x": -17,
      "y": 2,
      "z": 1,
      "name": "Wood_Deadwood_Beam"
    },
    {
      "x": -17,
      "y": 3,
      "z": 1,
      "name": "*Furniture_Ancient_Torch_State_Definitions_Off",
      "rotation": 1
    },
    {
      "x": -17,
      "y": 4,
      "z": 1,
      "name": "Empty"
    },
    {
      "x": -17,
      "y": 5,
      "z": 1,
      "name": "Empty"
    },
    {
      "x": -17,
      "y": 6,
      "z": 1,
      "name": "Empty"
    },
    {
      "x": -17,
      "y": 7,
      "z": 1,
      "name": "Rock_Stone"
    },
    {
      "x": -17,
      "y": 8,
      "z": 1,
      "name": "Rock_Stone"
    },
    {
      "x": -17,
      "y": 9,
      "z": 1,
      "name": "Rock_Stone"
    },
    {
      "x": -17,
      "y": 10,
      "z": 1,
      "name": "Rock_Stone"
    },
    {
      "x": -17,
      "y": 11,
      "z": 1,
      "name": "Rock_Stone"
    },
    {
      "x": -17,
      "y": 1,
      "z": 2,
      "name": "Soil_Pathway"
    },
    {
      "x": -17,
      "y": 2,
      "z": 2,
      "name": "Rubble_Stone_Medium"
    },
    {
      "x": -17,
      "y": 3,
      "z": 2,
      "name": "Empty"
    },
    {
      "x": -17,
      "y": 4,
      "z": 2,
      "name": "Empty"
    },
    {
      "x": -17,
      "y": 5,
      "z": 2,
      "name": "Rock_Stone"
    },
    {
      "x": -17,
      "y": 6,
      "z": 2,
      "name": "Rock_Stone"
    },
    {
      "x": -17,
      "y": 7,
      "z": 2,
      "name": "Rock_Stone"
    },
    {
      "x": -17,
      "y": 8,
      "z": 2,
      "name": "Rock_Stone"
    },
    {
      "x": -17,
      "y": 9,
      "z": 2,
      "name": "Rock_Stone"
    },
    {
      "x": -17,
      "y": 10,
      "z": 2,
      "name": "Rock_Stone"
    },
    {
      "x": -17,
      "y": 11,
      "z": 2,
      "name": "Rock_Stone"
    },
    {
      "x": -17,
      "y": 1,
      "z": 3,
      "name": "Rock_Stone"
    },
    {
      "x": -17,
      "y": 2,
      "z": 3,
      "name": "Rock_Stone"
    },
    {
      "x": -17,
      "y": 3,
      "z": 3,
      "name": "Rock_Stone"
    },
    {
      "x": -17,
      "y": 4,
      "z": 3,
      "name": "Rock_Stone"
    },
    {
      "x": -17,
      "y": 5,
      "z": 3,
      "name": "Rock_Stone"
    },
    {
      "x": -17,
      "y": 6,
      "z": 3,
      "name": "Rock_Stone"
    },
    {
      "x": -17,
      "y": 7,
      "z": 3,
      "name": "Rock_Stone"
    },
    {
      "x": -17,
      "y": 8,
      "z": 3,
      "name": "Rock_Stone"
    },
    {
      "x": -17,
      "y": 9,
      "z": 3,
      "name": "Rock_Stone"
    },
    {
      "x": -17,
      "y": 10,
      "z": 3,
      "name": "Rock_Stone"
    },
    {
      "x": -17,
      "y": 11,
      "z": 3,
      "name": "Rock_Stone"
    },
    {
      "x": -17,
      "y": 12,
      "z": 3,
      "name": "Rock_Stone"
    },
    {
      "x": -17,
      "y": 1,
      "z": 4,
      "name": "Rock_Stone"
    },
    {
      "x": -17,
      "y": 2,
      "z": 4,
      "name": "Rock_Stone"
    },
    {
      "x": -17,
      "y": 3,
      "z": 4,
      "name": "Rock_Stone"
    },
    {
      "x": -17,
      "y": 4,
      "z": 4,
      "name": "Rock_Stone"
    },
    {
      "x": -17,
      "y": 5,
      "z": 4,
      "name": "Rock_Stone"
    },
    {
      "x": -17,
      "y": 6,
      "z": 4,
      "name": "Rock_Stone"
    },
    {
      "x": -17,
      "y": 7,
      "z": 4,
      "name": "Rock_Stone"
    },
    {
      "x": -17,
      "y": 8,
      "z": 4,
      "name": "Rock_Stone"
    },
    {
      "x": -17,
      "y": 9,
      "z": 4,
      "name": "Rock_Stone"
    },
    {
      "x": -17,
      "y": 10,
      "z": 4,
      "name": "Rock_Stone"
    },
    {
      "x": -17,
      "y": 11,
      "z": 4,
      "name": "Rock_Stone"
    },
    {
      "x": -17,
      "y": 1,
      "z": 5,
      "name": "Rock_Stone"
    },
    {
      "x": -17,
      "y": 2,
      "z": 5,
      "name": "Rock_Stone"
    },
    {
      "x": -17,
      "y": 3,
      "z": 5,
      "name": "Rock_Stone"
    },
    {
      "x": -17,
      "y": 4,
      "z": 5,
      "name": "Rock_Stone"
    },
    {
      "x": -17,
      "y": 5,
      "z": 5,
      "name": "Rock_Stone"
    },
    {
      "x": -17,
      "y": 6,
      "z": 5,
      "name": "Rock_Stone"
    },
    {
      "x": -17,
      "y": 7,
      "z": 5,
      "name": "Rock_Stone"
    },
    {
      "x": -17,
      "y": 8,
      "z": 5,
      "name": "Rock_Stone"
    },
    {
      "x": -17,
      "y": 9,
      "z": 5,
      "name": "Rock_Stone"
    },
    {
      "x": -17,
      "y": 10,
      "z": 5,
      "name": "Rock_Stone"
    },
    {
      "x": -17,
      "y": 11,
      "z": 5,
      "name": "Rock_Stone"
    },
    {
      "x": -17,
      "y": 2,
      "z": 6,
      "name": "Rock_Stone"
    },
    {
      "x": -17,
      "y": 3,
      "z": 6,
      "name": "Rock_Stone"
    },
    {
      "x": -17,
      "y": 4,
      "z": 6,
      "name": "Rock_Stone"
    },
    {
      "x": -17,
      "y": 5,
      "z": 6,
      "name": "Rock_Stone"
    },
    {
      "x": -17,
      "y": 6,
      "z": 6,
      "name": "Rock_Stone"
    },
    {
      "x": -17,
      "y": 7,
      "z": 6,
      "name": "Rock_Stone"
    },
    {
      "x": -17,
      "y": 8,
      "z": 6,
      "name": "Rock_Stone"
    },
    {
      "x": -17,
      "y": 9,
      "z": 6,
      "name": "Rock_Stone"
    },
    {
      "x": -17,
      "y": 10,
      "z": 6,
      "name": "Rock_Stone"
    },
    {
      "x": -17,
      "y": 11,
      "z": 6,
      "name": "Rock_Stone"
    },
    {
      "x": -17,
      "y": 2,
      "z": 7,
      "name": "Rock_Stone"
    },
    {
      "x": -17,
      "y": 3,
      "z": 7,
      "name": "Rock_Stone"
    },
    {
      "x": -17,
      "y": 4,
      "z": 7,
      "name": "Rock_Stone"
    },
    {
      "x": -17,
      "y": 5,
      "z": 7,
      "name": "Rock_Stone"
    },
    {
      "x": -17,
      "y": 6,
      "z": 7,
      "name": "Rock_Stone"
    },
    {
      "x": -17,
      "y": 7,
      "z": 7,
      "name": "Rock_Stone"
    },
    {
      "x": -17,
      "y": 8,
      "z": 7,
      "name": "Rock_Stone"
    },
    {
      "x": -17,
      "y": 9,
      "z": 7,
      "name": "Rock_Stone"
    },
    {
      "x": -17,
      "y": 10,
      "z": 7,
      "name": "Rock_Stone"
    },
    {
      "x": -17,
      "y": 3,
      "z": 8,
      "name": "Rock_Stone"
    },
    {
      "x": -17,
      "y": 4,
      "z": 8,
      "name": "Rock_Stone"
    },
    {
      "x": -17,
      "y": 5,
      "z": 8,
      "name": "Rock_Stone"
    },
    {
      "x": -17,
      "y": 6,
      "z": 8,
      "name": "Rock_Stone"
    },
    {
      "x": -17,
      "y": 7,
      "z": 8,
      "name": "Rock_Stone"
    },
    {
      "x": -17,
      "y": 8,
      "z": 8,
      "name": "Rock_Stone"
    },
    {
      "x": -16,
      "y": 0,
      "z": -7,
      "name": "Soil_Dirt"
    },
    {
      "x": -16,
      "y": 1,
      "z": -7,
      "name": "Empty"
    },
    {
      "x": -16,
      "y": 2,
      "z": -7,
      "name": "Empty"
    },
    {
      "x": -16,
      "y": 3,
      "z": -7,
      "name": "Empty"
    },
    {
      "x": -16,
      "y": 0,
      "z": -6,
      "name": "Soil_Dirt"
    },
    {
      "x": -16,
      "y": 1,
      "z": -6,
      "name": "Empty"
    },
    {
      "x": -16,
      "y": 2,
      "z": -6,
      "name": "Empty"
    },
    {
      "x": -16,
      "y": 3,
      "z": -6,
      "name": "Empty"
    },
    {
      "x": -16,
      "y": 4,
      "z": -6,
      "name": "Empty"
    },
    {
      "x": -16,
      "y": 0,
      "z": -5,
      "name": "Soil_Pathway"
    },
    {
      "x": -16,
      "y": 1,
      "z": -5,
      "name": "Empty"
    },
    {
      "x": -16,
      "y": 2,
      "z": -5,
      "name": "Empty"
    },
    {
      "x": -16,
      "y": 3,
      "z": -5,
      "name": "Empty"
    },
    {
      "x": -16,
      "y": 4,
      "z": -5,
      "name": "Empty"
    },
    {
      "x": -16,
      "y": 5,
      "z": -5,
      "name": "Rock_Stone"
    },
    {
      "x": -16,
      "y": 6,
      "z": -5,
      "name": "Rock_Stone"
    },
    {
      "x": -16,
      "y": 7,
      "z": -5,
      "name": "Rock_Stone"
    },
    {
      "x": -16,
      "y": -1,
      "z": -4,
      "name": "Rock_Stone"
    },
    {
      "x": -16,
      "y": 0,
      "z": -4,
      "name": "Soil_Pathway"
    },
    {
      "x": -16,
      "y": 1,
      "z": -4,
      "name": "Empty"
    },
    {
      "x": -16,
      "y": 2,
      "z": -4,
      "name": "Empty"
    },
    {
      "x": -16,
      "y": 3,
      "z": -4,
      "name": "Empty"
    },
    {
      "x": -16,
      "y": 4,
      "z": -4,
      "name": "Empty"
    },
    {
      "x": -16,
      "y": 5,
      "z": -4,
      "name": "Rock_Stone"
    },
    {
      "x": -16,
      "y": 6,
      "z": -4,
      "name": "Rock_Stone"
    },
    {
      "x": -16,
      "y": 7,
      "z": -4,
      "name": "Rock_Stone"
    },
    {
      "x": -16,
      "y": 8,
      "z": -4,
      "name": "Rock_Stone"
    },
    {
      "x": -16,
      "y": 9,
      "z": -4,
      "name": "Rock_Stone"
    },
    {
      "x": -16,
      "y": -1,
      "z": -3,
      "name": "Rock_Stone"
    },
    {
      "x": -16,
      "y": 0,
      "z": -3,
      "name": "Soil_Pathway"
    },
    {
      "x": -16,
      "y": 1,
      "z": -3,
      "name": "Empty"
    },
    {
      "x": -16,
      "y": 2,
      "z": -3,
      "name": "Empty"
    },
    {
      "x": -16,
      "y": 3,
      "z": -3,
      "name": "Empty"
    },
    {
      "x": -16,
      "y": 4,
      "z": -3,
      "name": "Empty"
    },
    {
      "x": -16,
      "y": 5,
      "z": -3,
      "name": "Empty"
    },
    {
      "x": -16,
      "y": 6,
      "z": -3,
      "name": "Empty"
    },
    {
      "x": -16,
      "y": 7,
      "z": -3,
      "name": "Rock_Stone"
    },
    {
      "x": -16,
      "y": 8,
      "z": -3,
      "name": "Plant_Moss_Rug_Green"
    },
    {
      "x": -16,
      "y": 9,
      "z": -3,
      "name": "Rock_Stone"
    },
    {
      "x": -16,
      "y": 10,
      "z": -3,
      "name": "Rock_Stone"
    },
    {
      "x": -16,
      "y": 0,
      "z": -2,
      "name": "Soil_Pathway"
    },
    {
      "x": -16,
      "y": 1,
      "z": -2,
      "name": "Empty"
    },
    {
      "x": -16,
      "y": 2,
      "z": -2,
      "name": "Empty"
    },
    {
      "x": -16,
      "y": 3,
      "z": -2,
      "name": "Empty"
    },
    {
      "x": -16,
      "y": 4,
      "z": -2,
      "name": "Empty"
    },
    {
      "x": -16,
      "y": 5,
      "z": -2,
      "name": "Empty"
    },
    {
      "x": -16,
      "y": 6,
      "z": -2,
      "name": "Empty"
    },
    {
      "x": -16,
      "y": 7,
      "z": -2,
      "name": "Plant_Moss_Wall_Green",
      "rotation": 1
    },
    {
      "x": -16,
      "y": 8,
      "z": -2,
      "name": "Empty"
    },
    {
      "x": -16,
      "y": 9,
      "z": -2,
      "name": "Rock_Stone"
    },
    {
      "x": -16,
      "y": 10,
      "z": -2,
      "name": "Rock_Stone"
    },
    {
      "x": -16,
      "y": 11,
      "z": -2,
      "name": "Rock_Stone"
    },
    {
      "x": -16,
      "y": 0,
      "z": -1,
      "name": "Soil_Pathway"
    },
    {
      "x": -16,
      "y": 1,
      "z": -1,
      "name": "Soil_Pathway_Half"
    },
    {
      "x": -16,
      "y": 2,
      "z": -1,
      "name": "Empty"
    },
    {
      "x": -16,
      "y": 3,
      "z": -1,
      "name": "Empty"
    },
    {
      "x": -16,
      "y": 4,
      "z": -1,
      "name": "Empty"
    },
    {
      "x": -16,
      "y": 5,
      "z": -1,
      "name": "Empty"
    },
    {
      "x": -16,
      "y": 6,
      "z": -1,
      "name": "Empty"
    },
    {
      "x": -16,
      "y": 7,
      "z": -1,
      "name": "Empty"
    },
    {
      "x": -16,
      "y": 8,
      "z": -1,
      "name": "Empty"
    },
    {
      "x": -16,
      "y": 9,
      "z": -1,
      "name": "Empty"
    },
    {
      "x": -16,
      "y": 10,
      "z": -1,
      "name": "Rock_Stone"
    },
    {
      "x": -16,
      "y": 11,
      "z": -1,
      "name": "Rock_Stone"
    },
    {
      "x": -16,
      "y": 0,
      "z": 0,
      "name": "Soil_Pathway"
    },
    {
      "x": -16,
      "y": 1,
      "z": 0,
      "name": "Soil_Pathway_Half"
    },
    {
      "x": -16,
      "y": 2,
      "z": 0,
      "name": "Empty"
    },
    {
      "x": -16,
      "y": 3,
      "z": 0,
      "name": "Empty"
    },
    {
      "x": -16,
      "y": 4,
      "z": 0,
      "name": "Empty"
    },
    {
      "x": -16,
      "y": 5,
      "z": 0,
      "name": "Empty"
    },
    {
      "x": -16,
      "y": 6,
      "z": 0,
      "name": "Rock_Stone_Stalactite_Small",
      "rotation": 8
    },
    {
      "x": -16,
      "y": 7,
      "z": 0,
      "name": "Rock_Stone"
    },
    {
      "x": -16,
      "y": 8,
      "z": 0,
      "name": "Rock_Stone"
    },
    {
      "x": -16,
      "y": 9,
      "z": 0,
      "name": "Rock_Stone"
    },
    {
      "x": -16,
      "y": 10,
      "z": 0,
      "name": "Rock_Stone"
    },
    {
      "x": -16,
      "y": 11,
      "z": 0,
      "name": "Rock_Stone"
    },
    {
      "x": -16,
      "y": 12,
      "z": 0,
      "name": "Rock_Stone"
    },
    {
      "x": -16,
      "y": 0,
      "z": 1,
      "name": "Soil_Dirt"
    },
    {
      "x": -16,
      "y": 1,
      "z": 1,
      "name": "Soil_Pathway"
    },
    {
      "x": -16,
      "y": 2,
      "z": 1,
      "name": "Rubble_Stone"
    },
    {
      "x": -16,
      "y": 3,
      "z": 1,
      "name": "Empty"
    },
    {
      "x": -16,
      "y": 4,
      "z": 1,
      "name": "Empty"
    },
    {
      "x": -16,
      "y": 5,
      "z": 1,
      "name": "Empty"
    },
    {
      "x": -16,
      "y": 6,
      "z": 1,
      "name": "Empty"
    },
    {
      "x": -16,
      "y": 7,
      "z": 1,
      "name": "Rock_Stone"
    },
    {
      "x": -16,
      "y": 8,
      "z": 1,
      "name": "Rock_Stone"
    },
    {
      "x": -16,
      "y": 9,
      "z": 1,
      "name": "Rock_Stone"
    },
    {
      "x": -16,
      "y": 10,
      "z": 1,
      "name": "Rock_Stone"
    },
    {
      "x": -16,
      "y": 11,
      "z": 1,
      "name": "Rock_Stone"
    },
    {
      "x": -16,
      "y": 12,
      "z": 1,
      "name": "Rock_Stone"
    },
    {
      "x": -16,
      "y": 1,
      "z": 2,
      "name": "Rock_Stone"
    },
    {
      "x": -16,
      "y": 2,
      "z": 2,
      "name": "Rock_Stone"
    },
    {
      "x": -16,
      "y": 3,
      "z": 2,
      "name": "Rock_Stone"
    },
    {
      "x": -16,
      "y": 4,
      "z": 2,
      "name": "Rock_Stone"
    },
    {
      "x": -16,
      "y": 5,
      "z": 2,
      "name": "Rock_Stone"
    },
    {
      "x": -16,
      "y": 6,
      "z": 2,
      "name": "Rock_Stone"
    },
    {
      "x": -16,
      "y": 7,
      "z": 2,
      "name": "Rock_Stone"
    },
    {
      "x": -16,
      "y": 8,
      "z": 2,
      "name": "Rock_Stone"
    },
    {
      "x": -16,
      "y": 9,
      "z": 2,
      "name": "Rock_Stone"
    },
    {
      "x": -16,
      "y": 10,
      "z": 2,
      "name": "Rock_Stone"
    },
    {
      "x": -16,
      "y": 11,
      "z": 2,
      "name": "Rock_Stone"
    },
    {
      "x": -16,
      "y": 12,
      "z": 2,
      "name": "Rock_Stone"
    },
    {
      "x": -16,
      "y": 0,
      "z": 3,
      "name": "Rock_Stone"
    },
    {
      "x": -16,
      "y": 1,
      "z": 3,
      "name": "Rock_Stone"
    },
    {
      "x": -16,
      "y": 2,
      "z": 3,
      "name": "Rock_Stone"
    },
    {
      "x": -16,
      "y": 3,
      "z": 3,
      "name": "Rock_Stone"
    },
    {
      "x": -16,
      "y": 4,
      "z": 3,
      "name": "Rock_Stone"
    },
    {
      "x": -16,
      "y": 5,
      "z": 3,
      "name": "Rock_Stone"
    },
    {
      "x": -16,
      "y": 6,
      "z": 3,
      "name": "Rock_Stone"
    },
    {
      "x": -16,
      "y": 7,
      "z": 3,
      "name": "Rock_Stone"
    },
    {
      "x": -16,
      "y": 8,
      "z": 3,
      "name": "Rock_Stone"
    },
    {
      "x": -16,
      "y": 9,
      "z": 3,
      "name": "Rock_Stone"
    },
    {
      "x": -16,
      "y": 10,
      "z": 3,
      "name": "Rock_Stone"
    },
    {
      "x": -16,
      "y": 11,
      "z": 3,
      "name": "Rock_Stone"
    },
    {
      "x": -16,
      "y": 12,
      "z": 3,
      "name": "Rock_Stone"
    },
    {
      "x": -16,
      "y": 0,
      "z": 4,
      "name": "Rock_Stone"
    },
    {
      "x": -16,
      "y": 1,
      "z": 4,
      "name": "Rock_Stone"
    },
    {
      "x": -16,
      "y": 2,
      "z": 4,
      "name": "Rock_Stone"
    },
    {
      "x": -16,
      "y": 3,
      "z": 4,
      "name": "Rock_Stone"
    },
    {
      "x": -16,
      "y": 4,
      "z": 4,
      "name": "Rock_Stone"
    },
    {
      "x": -16,
      "y": 5,
      "z": 4,
      "name": "Rock_Stone"
    },
    {
      "x": -16,
      "y": 6,
      "z": 4,
      "name": "Rock_Stone"
    },
    {
      "x": -16,
      "y": 7,
      "z": 4,
      "name": "Rock_Stone"
    },
    {
      "x": -16,
      "y": 8,
      "z": 4,
      "name": "Rock_Stone"
    },
    {
      "x": -16,
      "y": 9,
      "z": 4,
      "name": "Rock_Stone"
    },
    {
      "x": -16,
      "y": 10,
      "z": 4,
      "name": "Rock_Stone"
    },
    {
      "x": -16,
      "y": 11,
      "z": 4,
      "name": "Rock_Stone"
    },
    {
      "x": -16,
      "y": 0,
      "z": 5,
      "name": "Rock_Stone"
    },
    {
      "x": -16,
      "y": 1,
      "z": 5,
      "name": "Rock_Stone"
    },
    {
      "x": -16,
      "y": 2,
      "z": 5,
      "name": "Rock_Stone"
    },
    {
      "x": -16,
      "y": 3,
      "z": 5,
      "name": "Rock_Stone"
    },
    {
      "x": -16,
      "y": 4,
      "z": 5,
      "name": "Rock_Stone"
    },
    {
      "x": -16,
      "y": 5,
      "z": 5,
      "name": "Rock_Stone"
    },
    {
      "x": -16,
      "y": 6,
      "z": 5,
      "name": "Rock_Stone"
    },
    {
      "x": -16,
      "y": 7,
      "z": 5,
      "name": "Rock_Stone"
    },
    {
      "x": -16,
      "y": 8,
      "z": 5,
      "name": "Rock_Stone"
    },
    {
      "x": -16,
      "y": 9,
      "z": 5,
      "name": "Rock_Stone"
    },
    {
      "x": -16,
      "y": 10,
      "z": 5,
      "name": "Rock_Stone"
    },
    {
      "x": -16,
      "y": 11,
      "z": 5,
      "name": "Rock_Stone"
    },
    {
      "x": -16,
      "y": 12,
      "z": 5,
      "name": "Rock_Stone"
    },
    {
      "x": -16,
      "y": 1,
      "z": 6,
      "name": "Rock_Stone"
    },
    {
      "x": -16,
      "y": 2,
      "z": 6,
      "name": "Rock_Stone"
    },
    {
      "x": -16,
      "y": 3,
      "z": 6,
      "name": "Rock_Stone"
    },
    {
      "x": -16,
      "y": 4,
      "z": 6,
      "name": "Rock_Stone"
    },
    {
      "x": -16,
      "y": 5,
      "z": 6,
      "name": "Rock_Stone"
    },
    {
      "x": -16,
      "y": 6,
      "z": 6,
      "name": "Rock_Stone"
    },
    {
      "x": -16,
      "y": 7,
      "z": 6,
      "name": "Rock_Stone"
    },
    {
      "x": -16,
      "y": 8,
      "z": 6,
      "name": "Rock_Stone"
    },
    {
      "x": -16,
      "y": 9,
      "z": 6,
      "name": "Rock_Stone"
    },
    {
      "x": -16,
      "y": 10,
      "z": 6,
      "name": "Rock_Stone"
    },
    {
      "x": -16,
      "y": 11,
      "z": 6,
      "name": "Rock_Stone"
    },
    {
      "x": -16,
      "y": 1,
      "z": 7,
      "name": "Rock_Stone"
    },
    {
      "x": -16,
      "y": 2,
      "z": 7,
      "name": "Rock_Stone"
    },
    {
      "x": -16,
      "y": 3,
      "z": 7,
      "name": "Rock_Stone"
    },
    {
      "x": -16,
      "y": 4,
      "z": 7,
      "name": "Rock_Stone"
    },
    {
      "x": -16,
      "y": 5,
      "z": 7,
      "name": "Rock_Stone"
    },
    {
      "x": -16,
      "y": 6,
      "z": 7,
      "name": "Rock_Stone"
    },
    {
      "x": -16,
      "y": 7,
      "z": 7,
      "name": "Rock_Stone"
    },
    {
      "x": -16,
      "y": 8,
      "z": 7,
      "name": "Rock_Stone"
    },
    {
      "x": -16,
      "y": 9,
      "z": 7,
      "name": "Rock_Stone"
    },
    {
      "x": -16,
      "y": 10,
      "z": 7,
      "name": "Rock_Stone"
    },
    {
      "x": -16,
      "y": 2,
      "z": 8,
      "name": "Rock_Stone"
    },
    {
      "x": -16,
      "y": 3,
      "z": 8,
      "name": "Rock_Stone"
    },
    {
      "x": -16,
      "y": 4,
      "z": 8,
      "name": "Rock_Stone"
    },
    {
      "x": -16,
      "y": 5,
      "z": 8,
      "name": "Rock_Stone"
    },
    {
      "x": -16,
      "y": 6,
      "z": 8,
      "name": "Rock_Stone"
    },
    {
      "x": -16,
      "y": 7,
      "z": 8,
      "name": "Rock_Stone"
    },
    {
      "x": -16,
      "y": 8,
      "z": 8,
      "name": "Rock_Stone"
    },
    {
      "x": -16,
      "y": 9,
      "z": 8,
      "name": "Rock_Stone"
    },
    {
      "x": -16,
      "y": 4,
      "z": 9,
      "name": "Rock_Stone"
    },
    {
      "x": -16,
      "y": 5,
      "z": 9,
      "name": "Rock_Stone"
    },
    {
      "x": -16,
      "y": 6,
      "z": 9,
      "name": "Rock_Stone"
    },
    {
      "x": -15,
      "y": 1,
      "z": -9,
      "name": "Soil_Clay"
    },
    {
      "x": -15,
      "y": 2,
      "z": -9,
      "name": "Soil_Clay"
    },
    {
      "x": -15,
      "y": 3,
      "z": -9,
      "name": "Soil_Clay"
    },
    {
      "x": -15,
      "y": 0,
      "z": -8,
      "name": "Soil_Dirt"
    },
    {
      "x": -15,
      "y": 1,
      "z": -8,
      "name": "Empty"
    },
    {
      "x": -15,
      "y": 2,
      "z": -8,
      "name": "Empty"
    },
    {
      "x": -15,
      "y": 0,
      "z": -7,
      "name": "Soil_Dirt"
    },
    {
      "x": -15,
      "y": 1,
      "z": -7,
      "name": "Furniture_Human_Ruins_Pot_Small"
    },
    {
      "x": -15,
      "y": 2,
      "z": -7,
      "name": "Empty"
    },
    {
      "x": -15,
      "y": 3,
      "z": -7,
      "name": "Empty"
    },
    {
      "x": -15,
      "y": 4,
      "z": -7,
      "name": "Empty"
    },
    {
      "x": -15,
      "y": 0,
      "z": -6,
      "name": "Soil_Pathway"
    },
    {
      "x": -15,
      "y": 1,
      "z": -6,
      "name": "Empty"
    },
    {
      "x": -15,
      "y": 2,
      "z": -6,
      "name": "Empty"
    },
    {
      "x": -15,
      "y": 3,
      "z": -6,
      "name": "Empty"
    },
    {
      "x": -15,
      "y": 4,
      "z": -6,
      "name": "Empty"
    },
    {
      "x": -15,
      "y": -1,
      "z": -5,
      "name": "Rock_Stone"
    },
    {
      "x": -15,
      "y": 0,
      "z": -5,
      "name": "Soil_Pathway"
    },
    {
      "x": -15,
      "y": 1,
      "z": -5,
      "name": "Empty"
    },
    {
      "x": -15,
      "y": 2,
      "z": -5,
      "name": "Empty"
    },
    {
      "x": -15,
      "y": 3,
      "z": -5,
      "name": "Empty"
    },
    {
      "x": -15,
      "y": 4,
      "z": -5,
      "name": "Empty"
    },
    {
      "x": -15,
      "y": 5,
      "z": -5,
      "name": "Rock_Stone"
    },
    {
      "x": -15,
      "y": 6,
      "z": -5,
      "name": "Rock_Stone"
    },
    {
      "x": -15,
      "y": 7,
      "z": -5,
      "name": "Rock_Stone"
    },
    {
      "x": -15,
      "y": -1,
      "z": -4,
      "name": "Rock_Stone"
    },
    {
      "x": -15,
      "y": 0,
      "z": -4,
      "name": "Soil_Pathway"
    },
    {
      "x": -15,
      "y": 1,
      "z": -4,
      "name": "Empty"
    },
    {
      "x": -15,
      "y": 2,
      "z": -4,
      "name": "Empty"
    },
    {
      "x": -15,
      "y": 3,
      "z": -4,
      "name": "Empty"
    },
    {
      "x": -15,
      "y": 4,
      "z": -4,
      "name": "Empty"
    },
    {
      "x": -15,
      "y": 5,
      "z": -4,
      "name": "Rock_Stone"
    },
    {
      "x": -15,
      "y": 6,
      "z": -4,
      "name": "Rock_Stone"
    },
    {
      "x": -15,
      "y": 7,
      "z": -4,
      "name": "Rock_Stone"
    },
    {
      "x": -15,
      "y": 8,
      "z": -4,
      "name": "Rock_Stone"
    },
    {
      "x": -15,
      "y": 9,
      "z": -4,
      "name": "Rock_Stone"
    },
    {
      "x": -15,
      "y": -1,
      "z": -3,
      "name": "Rock_Stone"
    },
    {
      "x": -15,
      "y": 0,
      "z": -3,
      "name": "Soil_Pathway"
    },
    {
      "x": -15,
      "y": 1,
      "z": -3,
      "name": "Empty"
    },
    {
      "x": -15,
      "y": 2,
      "z": -3,
      "name": "Empty"
    },
    {
      "x": -15,
      "y": 3,
      "z": -3,
      "name": "Empty"
    },
    {
      "x": -15,
      "y": 4,
      "z": -3,
      "name": "Empty"
    },
    {
      "x": -15,
      "y": 5,
      "z": -3,
      "name": "Empty"
    },
    {
      "x": -15,
      "y": 6,
      "z": -3,
      "name": "Empty"
    },
    {
      "x": -15,
      "y": 7,
      "z": -3,
      "name": "Empty"
    },
    {
      "x": -15,
      "y": 8,
      "z": -3,
      "name": "Rock_Stone"
    },
    {
      "x": -15,
      "y": 9,
      "z": -3,
      "name": "Rock_Stone"
    },
    {
      "x": -15,
      "y": 10,
      "z": -3,
      "name": "Rock_Stone"
    },
    {
      "x": -15,
      "y": -1,
      "z": -2,
      "name": "Rock_Stone"
    },
    {
      "x": -15,
      "y": 0,
      "z": -2,
      "name": "Soil_Pathway"
    },
    {
      "x": -15,
      "y": 1,
      "z": -2,
      "name": "Empty"
    },
    {
      "x": -15,
      "y": 2,
      "z": -2,
      "name": "Empty"
    },
    {
      "x": -15,
      "y": 3,
      "z": -2,
      "name": "Empty"
    },
    {
      "x": -15,
      "y": 4,
      "z": -2,
      "name": "Empty"
    },
    {
      "x": -15,
      "y": 5,
      "z": -2,
      "name": "Empty"
    },
    {
      "x": -15,
      "y": 6,
      "z": -2,
      "name": "Empty"
    },
    {
      "x": -15,
      "y": 7,
      "z": -2,
      "name": "Empty"
    },
    {
      "x": -15,
      "y": 8,
      "z": -2,
      "name": "Empty"
    },
    {
      "x": -15,
      "y": 9,
      "z": -2,
      "name": "Rock_Stone"
    },
    {
      "x": -15,
      "y": 10,
      "z": -2,
      "name": "Rock_Stone"
    },
    {
      "x": -15,
      "y": 11,
      "z": -2,
      "name": "Rock_Stone"
    },
    {
      "x": -15,
      "y": 0,
      "z": -1,
      "name": "Plant_Moss_Block_Green"
    },
    {
      "x": -15,
      "y": 1,
      "z": -1,
      "name": "Plant_Moss_Short_Green"
    },
    {
      "x": -15,
      "y": 2,
      "z": -1,
      "name": "Empty"
    },
    {
      "x": -15,
      "y": 3,
      "z": -1,
      "name": "Empty"
    },
    {
      "x": -15,
      "y": 4,
      "z": -1,
      "name": "Empty"
    },
    {
      "x": -15,
      "y": 5,
      "z": -1,
      "name": "Empty"
    },
    {
      "x": -15,
      "y": 6,
      "z": -1,
      "name": "Empty"
    },
    {
      "x": -15,
      "y": 7,
      "z": -1,
      "name": "Empty"
    },
    {
      "x": -15,
      "y": 8,
      "z": -1,
      "name": "Empty"
    },
    {
      "x": -15,
      "y": 9,
      "z": -1,
      "name": "Empty"
    },
    {
      "x": -15,
      "y": 10,
      "z": -1,
      "name": "Empty"
    },
    {
      "x": -15,
      "y": 11,
      "z": -1,
      "name": "Empty"
    },
    {
      "x": -15,
      "y": 12,
      "z": -1,
      "name": "Empty"
    },
    {
      "x": -15,
      "y": 0,
      "z": 0,
      "name": "Soil_Dirt"
    },
    {
      "x": -15,
      "y": 1,
      "z": 0,
      "name": "Deco_Bone_Skulls"
    },
    {
      "x": -15,
      "y": 2,
      "z": 0,
      "name": "Plant_Crop_Mushroom_Block_Green_Mycelium",
      "rotation": 8
    },
    {
      "x": -15,
      "y": 3,
      "z": 0,
      "name": "Plant_Crop_Mushroom_Block_Green"
    },
    {
      "x": -15,
      "y": 4,
      "z": 0,
      "name": "Plant_Crop_Mushroom_Shelve_Green"
    },
    {
      "x": -15,
      "y": 5,
      "z": 0,
      "name": "Empty"
    },
    {
      "x": -15,
      "y": 6,
      "z": 0,
      "name": "Empty"
    },
    {
      "x": -15,
      "y": 7,
      "z": 0,
      "name": "Empty"
    },
    {
      "x": -15,
      "y": 8,
      "z": 0,
      "name": "Rock_Stone"
    },
    {
      "x": -15,
      "y": 9,
      "z": 0,
      "name": "Rock_Stone"
    },
    {
      "x": -15,
      "y": 10,
      "z": 0,
      "name": "Rock_Stone"
    },
    {
      "x": -15,
      "y": 11,
      "z": 0,
      "name": "Rock_Stone"
    },
    {
      "x": -15,
      "y": 12,
      "z": 0,
      "name": "Rock_Stone"
    },
    {
      "x": -15,
      "y": 0,
      "z": 1,
      "name": "Rock_Stone"
    },
    {
      "x": -15,
      "y": 1,
      "z": 1,
      "name": "Rock_Stone"
    },
    {
      "x": -15,
      "y": 2,
      "z": 1,
      "name": "Rock_Stone"
    },
    {
      "x": -15,
      "y": 3,
      "z": 1,
      "name": "Rock_Stone"
    },
    {
      "x": -15,
      "y": 4,
      "z": 1,
      "name": "Rock_Stone"
    },
    {
      "x": -15,
      "y": 5,
      "z": 1,
      "name": "Rock_Stone"
    },
    {
      "x": -15,
      "y": 6,
      "z": 1,
      "name": "Rock_Stone"
    },
    {
      "x": -15,
      "y": 7,
      "z": 1,
      "name": "Rock_Stone"
    },
    {
      "x": -15,
      "y": 8,
      "z": 1,
      "name": "Rock_Stone"
    },
    {
      "x": -15,
      "y": 9,
      "z": 1,
      "name": "Rock_Stone"
    },
    {
      "x": -15,
      "y": 10,
      "z": 1,
      "name": "Rock_Stone"
    },
    {
      "x": -15,
      "y": 11,
      "z": 1,
      "name": "Rock_Stone"
    },
    {
      "x": -15,
      "y": 12,
      "z": 1,
      "name": "Rock_Stone"
    },
    {
      "x": -15,
      "y": 0,
      "z": 2,
      "name": "Rock_Stone"
    },
    {
      "x": -15,
      "y": 1,
      "z": 2,
      "name": "Rock_Stone"
    },
    {
      "x": -15,
      "y": 2,
      "z": 2,
      "name": "Rock_Stone"
    },
    {
      "x": -15,
      "y": 3,
      "z": 2,
      "name": "Rock_Stone"
    },
    {
      "x": -15,
      "y": 4,
      "z": 2,
      "name": "Rock_Stone"
    },
    {
      "x": -15,
      "y": 5,
      "z": 2,
      "name": "Rock_Stone"
    },
    {
      "x": -15,
      "y": 6,
      "z": 2,
      "name": "Rock_Stone"
    },
    {
      "x": -15,
      "y": 7,
      "z": 2,
      "name": "Rock_Stone"
    },
    {
      "x": -15,
      "y": 8,
      "z": 2,
      "name": "Rock_Stone"
    },
    {
      "x": -15,
      "y": 9,
      "z": 2,
      "name": "Rock_Stone"
    },
    {
      "x": -15,
      "y": 10,
      "z": 2,
      "name": "Rock_Stone"
    },
    {
      "x": -15,
      "y": 11,
      "z": 2,
      "name": "Rock_Stone"
    },
    {
      "x": -15,
      "y": 12,
      "z": 2,
      "name": "Rock_Stone"
    },
    {
      "x": -15,
      "y": 0,
      "z": 3,
      "name": "Rock_Stone"
    },
    {
      "x": -15,
      "y": 1,
      "z": 3,
      "name": "Rock_Stone"
    },
    {
      "x": -15,
      "y": 2,
      "z": 3,
      "name": "Rock_Stone"
    },
    {
      "x": -15,
      "y": 3,
      "z": 3,
      "name": "Rock_Stone"
    },
    {
      "x": -15,
      "y": 4,
      "z": 3,
      "name": "Rock_Stone"
    },
    {
      "x": -15,
      "y": 5,
      "z": 3,
      "name": "Rock_Stone"
    },
    {
      "x": -15,
      "y": 6,
      "z": 3,
      "name": "Rock_Stone"
    },
    {
      "x": -15,
      "y": 7,
      "z": 3,
      "name": "Rock_Stone"
    },
    {
      "x": -15,
      "y": 8,
      "z": 3,
      "name": "Rock_Stone"
    },
    {
      "x": -15,
      "y": 9,
      "z": 3,
      "name": "Rock_Stone"
    },
    {
      "x": -15,
      "y": 10,
      "z": 3,
      "name": "Rock_Stone"
    },
    {
      "x": -15,
      "y": 11,
      "z": 3,
      "name": "Rock_Stone"
    },
    {
      "x": -15,
      "y": 12,
      "z": 3,
      "name": "Rock_Stone"
    },
    {
      "x": -15,
      "y": 0,
      "z": 4,
      "name": "Rock_Stone"
    },
    {
      "x": -15,
      "y": 1,
      "z": 4,
      "name": "Rock_Stone"
    },
    {
      "x": -15,
      "y": 2,
      "z": 4,
      "name": "Rock_Stone"
    },
    {
      "x": -15,
      "y": 3,
      "z": 4,
      "name": "Rock_Stone"
    },
    {
      "x": -15,
      "y": 4,
      "z": 4,
      "name": "Rock_Stone"
    },
    {
      "x": -15,
      "y": 5,
      "z": 4,
      "name": "Rock_Stone"
    },
    {
      "x": -15,
      "y": 6,
      "z": 4,
      "name": "Rock_Stone"
    },
    {
      "x": -15,
      "y": 7,
      "z": 4,
      "name": "Rock_Stone"
    },
    {
      "x": -15,
      "y": 8,
      "z": 4,
      "name": "Rock_Stone"
    },
    {
      "x": -15,
      "y": 9,
      "z": 4,
      "name": "Rock_Stone"
    },
    {
      "x": -15,
      "y": 10,
      "z": 4,
      "name": "Rock_Stone"
    },
    {
      "x": -15,
      "y": 11,
      "z": 4,
      "name": "Rock_Stone"
    },
    {
      "x": -15,
      "y": 12,
      "z": 4,
      "name": "Rock_Stone"
    },
    {
      "x": -15,
      "y": 0,
      "z": 5,
      "name": "Rock_Stone"
    },
    {
      "x": -15,
      "y": 1,
      "z": 5,
      "name": "Rock_Stone"
    },
    {
      "x": -15,
      "y": 2,
      "z": 5,
      "name": "Rock_Stone"
    },
    {
      "x": -15,
      "y": 3,
      "z": 5,
      "name": "Rock_Stone"
    },
    {
      "x": -15,
      "y": 4,
      "z": 5,
      "name": "Rock_Stone"
    },
    {
      "x": -15,
      "y": 5,
      "z": 5,
      "name": "Rock_Stone"
    },
    {
      "x": -15,
      "y": 6,
      "z": 5,
      "name": "Rock_Stone"
    },
    {
      "x": -15,
      "y": 7,
      "z": 5,
      "name": "Rock_Stone"
    },
    {
      "x": -15,
      "y": 8,
      "z": 5,
      "name": "Rock_Stone"
    },
    {
      "x": -15,
      "y": 9,
      "z": 5,
      "name": "Rock_Stone"
    },
    {
      "x": -15,
      "y": 10,
      "z": 5,
      "name": "Rock_Stone"
    },
    {
      "x": -15,
      "y": 11,
      "z": 5,
      "name": "Rock_Stone"
    },
    {
      "x": -15,
      "y": 12,
      "z": 5,
      "name": "Rock_Stone"
    },
    {
      "x": -15,
      "y": 0,
      "z": 6,
      "name": "Rock_Stone"
    },
    {
      "x": -15,
      "y": 1,
      "z": 6,
      "name": "Rock_Stone"
    },
    {
      "x": -15,
      "y": 2,
      "z": 6,
      "name": "Rock_Stone"
    },
    {
      "x": -15,
      "y": 3,
      "z": 6,
      "name": "Rock_Stone"
    },
    {
      "x": -15,
      "y": 4,
      "z": 6,
      "name": "Rock_Stone"
    },
    {
      "x": -15,
      "y": 5,
      "z": 6,
      "name": "Rock_Stone"
    },
    {
      "x": -15,
      "y": 6,
      "z": 6,
      "name": "Rock_Stone"
    },
    {
      "x": -15,
      "y": 7,
      "z": 6,
      "name": "Rock_Stone"
    },
    {
      "x": -15,
      "y": 8,
      "z": 6,
      "name": "Rock_Stone"
    },
    {
      "x": -15,
      "y": 9,
      "z": 6,
      "name": "Rock_Stone"
    },
    {
      "x": -15,
      "y": 10,
      "z": 6,
      "name": "Rock_Stone"
    },
    {
      "x": -15,
      "y": 11,
      "z": 6,
      "name": "Rock_Stone"
    },
    {
      "x": -15,
      "y": 1,
      "z": 7,
      "name": "Rock_Stone"
    },
    {
      "x": -15,
      "y": 2,
      "z": 7,
      "name": "Rock_Stone"
    },
    {
      "x": -15,
      "y": 3,
      "z": 7,
      "name": "Rock_Stone"
    },
    {
      "x": -15,
      "y": 4,
      "z": 7,
      "name": "Rock_Stone"
    },
    {
      "x": -15,
      "y": 5,
      "z": 7,
      "name": "Rock_Stone"
    },
    {
      "x": -15,
      "y": 6,
      "z": 7,
      "name": "Rock_Stone"
    },
    {
      "x": -15,
      "y": 7,
      "z": 7,
      "name": "Rock_Stone"
    },
    {
      "x": -15,
      "y": 8,
      "z": 7,
      "name": "Rock_Stone"
    },
    {
      "x": -15,
      "y": 9,
      "z": 7,
      "name": "Rock_Stone"
    },
    {
      "x": -15,
      "y": 10,
      "z": 7,
      "name": "Rock_Stone"
    },
    {
      "x": -15,
      "y": 2,
      "z": 8,
      "name": "Rock_Stone"
    },
    {
      "x": -15,
      "y": 3,
      "z": 8,
      "name": "Rock_Stone"
    },
    {
      "x": -15,
      "y": 4,
      "z": 8,
      "name": "Rock_Stone"
    },
    {
      "x": -15,
      "y": 5,
      "z": 8,
      "name": "Rock_Stone"
    },
    {
      "x": -15,
      "y": 6,
      "z": 8,
      "name": "Rock_Stone"
    },
    {
      "x": -15,
      "y": 7,
      "z": 8,
      "name": "Rock_Stone"
    },
    {
      "x": -15,
      "y": 8,
      "z": 8,
      "name": "Rock_Stone"
    },
    {
      "x": -15,
      "y": 9,
      "z": 8,
      "name": "Rock_Stone"
    },
    {
      "x": -15,
      "y": 2,
      "z": 9,
      "name": "Rock_Stone"
    },
    {
      "x": -15,
      "y": 3,
      "z": 9,
      "name": "Rock_Stone"
    },
    {
      "x": -15,
      "y": 4,
      "z": 9,
      "name": "Rock_Stone"
    },
    {
      "x": -15,
      "y": 5,
      "z": 9,
      "name": "Rock_Stone"
    },
    {
      "x": -15,
      "y": 6,
      "z": 9,
      "name": "Rock_Stone"
    },
    {
      "x": -15,
      "y": 7,
      "z": 9,
      "name": "Rock_Stone"
    },
    {
      "x": -14,
      "y": 0,
      "z": -9,
      "name": "Soil_Clay"
    },
    {
      "x": -14,
      "y": 1,
      "z": -9,
      "name": "Soil_Clay"
    },
    {
      "x": -14,
      "y": 2,
      "z": -9,
      "name": "Soil_Clay"
    },
    {
      "x": -14,
      "y": 3,
      "z": -9,
      "name": "Soil_Clay"
    },
    {
      "x": -14,
      "y": 4,
      "z": -9,
      "name": "Soil_Clay"
    },
    {
      "x": -14,
      "y": 0,
      "z": -8,
      "name": "Soil_Dirt"
    },
    {
      "x": -14,
      "y": 1,
      "z": -8,
      "name": "Empty"
    },
    {
      "x": -14,
      "y": 2,
      "z": -8,
      "name": "Empty"
    },
    {
      "x": -14,
      "y": 3,
      "z": -8,
      "name": "Empty"
    },
    {
      "x": -14,
      "y": 4,
      "z": -8,
      "name": "Empty"
    },
    {
      "x": -14,
      "y": 0,
      "z": -7,
      "name": "Soil_Pathway"
    },
    {
      "x": -14,
      "y": 1,
      "z": -7,
      "name": "Empty"
    },
    {
      "x": -14,
      "y": 2,
      "z": -7,
      "name": "Empty"
    },
    {
      "x": -14,
      "y": 3,
      "z": -7,
      "name": "Empty"
    },
    {
      "x": -14,
      "y": 4,
      "z": -7,
      "name": "Empty"
    },
    {
      "x": -14,
      "y": 0,
      "z": -6,
      "name": "Soil_Pathway"
    },
    {
      "x": -14,
      "y": 1,
      "z": -6,
      "name": "Empty"
    },
    {
      "x": -14,
      "y": 2,
      "z": -6,
      "name": "Empty"
    },
    {
      "x": -14,
      "y": 3,
      "z": -6,
      "name": "Empty"
    },
    {
      "x": -14,
      "y": 4,
      "z": -6,
      "name": "Empty"
    },
    {
      "x": -14,
      "y": -1,
      "z": -5,
      "name": "Rock_Stone"
    },
    {
      "x": -14,
      "y": 0,
      "z": -5,
      "name": "Soil_Pathway"
    },
    {
      "x": -14,
      "y": 1,
      "z": -5,
      "name": "Empty"
    },
    {
      "x": -14,
      "y": 2,
      "z": -5,
      "name": "Empty"
    },
    {
      "x": -14,
      "y": 3,
      "z": -5,
      "name": "Empty"
    },
    {
      "x": -14,
      "y": 4,
      "z": -5,
      "name": "Empty"
    },
    {
      "x": -14,
      "y": 5,
      "z": -5,
      "name": "Rock_Stone"
    },
    {
      "x": -14,
      "y": 6,
      "z": -5,
      "name": "Rock_Stone"
    },
    {
      "x": -14,
      "y": 7,
      "z": -5,
      "name": "Rock_Stone"
    },
    {
      "x": -14,
      "y": 8,
      "z": -5,
      "name": "Rock_Stone"
    },
    {
      "x": -14,
      "y": -1,
      "z": -4,
      "name": "Rock_Stone"
    },
    {
      "x": -14,
      "y": 0,
      "z": -4,
      "name": "Soil_Pathway"
    },
    {
      "x": -14,
      "y": 1,
      "z": -4,
      "name": "Empty"
    },
    {
      "x": -14,
      "y": 2,
      "z": -4,
      "name": "Empty"
    },
    {
      "x": -14,
      "y": 3,
      "z": -4,
      "name": "Empty"
    },
    {
      "x": -14,
      "y": 4,
      "z": -4,
      "name": "Empty"
    },
    {
      "x": -14,
      "y": 5,
      "z": -4,
      "name": "Rock_Stone"
    },
    {
      "x": -14,
      "y": 6,
      "z": -4,
      "name": "Rock_Stone"
    },
    {
      "x": -14,
      "y": 7,
      "z": -4,
      "name": "Rock_Stone"
    },
    {
      "x": -14,
      "y": 8,
      "z": -4,
      "name": "Rock_Stone"
    },
    {
      "x": -14,
      "y": 9,
      "z": -4,
      "name": "Rock_Stone"
    },
    {
      "x": -14,
      "y": -1,
      "z": -3,
      "name": "Rock_Stone"
    },
    {
      "x": -14,
      "y": 0,
      "z": -3,
      "name": "Plant_Moss_Block_Green"
    },
    {
      "x": -14,
      "y": 1,
      "z": -3,
      "name": "Plant_Moss_Rug_Green"
    },
    {
      "x": -14,
      "y": 2,
      "z": -3,
      "name": "Plant_Moss_Wall_Green",
      "rotation": 3
    },
    {
      "x": -14,
      "y": 3,
      "z": -3,
      "name": "Empty"
    },
    {
      "x": -14,
      "y": 4,
      "z": -3,
      "name": "Empty"
    },
    {
      "x": -14,
      "y": 5,
      "z": -3,
      "name": "Empty"
    },
    {
      "x": -14,
      "y": 6,
      "z": -3,
      "name": "Rock_Stone"
    },
    {
      "x": -14,
      "y": 7,
      "z": -3,
      "name": "Rock_Stone"
    },
    {
      "x": -14,
      "y": 8,
      "z": -3,
      "name": "Rock_Stone"
    },
    {
      "x": -14,
      "y": 9,
      "z": -3,
      "name": "Rock_Stone"
    },
    {
      "x": -14,
      "y": 10,
      "z": -3,
      "name": "Rock_Stone"
    },
    {
      "x": -14,
      "y": -1,
      "z": -2,
      "name": "Rock_Stone"
    },
    {
      "x": -14,
      "y": 0,
      "z": -2,
      "name": "Plant_Moss_Block_Green"
    },
    {
      "x": -14,
      "y": 1,
      "z": -2,
      "name": "Deco_Bone_Pile"
    },
    {
      "x": -14,
      "y": 2,
      "z": -2,
      "name": "Plant_Moss_Wall_Green",
      "rotation": 3
    },
    {
      "x": -14,
      "y": 3,
      "z": -2,
      "name": "Empty"
    },
    {
      "x": -14,
      "y": 4,
      "z": -2,
      "name": "Empty"
    },
    {
      "x": -14,
      "y": 5,
      "z": -2,
      "name": "Empty"
    },
    {
      "x": -14,
      "y": 6,
      "z": -2,
      "name": "Empty"
    },
    {
      "x": -14,
      "y": 7,
      "z": -2,
      "name": "Empty"
    },
    {
      "x": -14,
      "y": 8,
      "z": -2,
      "name": "Empty"
    },
    {
      "x": -14,
      "y": 9,
      "z": -2,
      "name": "Empty"
    },
    {
      "x": -14,
      "y": 10,
      "z": -2,
      "name": "Rock_Stone"
    },
    {
      "x": -14,
      "y": 11,
      "z": -2,
      "name": "Rock_Stone"
    },
    {
      "x": -14,
      "y": -1,
      "z": -1,
      "name": "Rock_Stone"
    },
    {
      "x": -14,
      "y": 0,
      "z": -1,
      "name": "Plant_Moss_Block_Green"
    },
    {
