{
  "version": 8,
  "blockIdVersion": 8,
  "anchorX": 0,
  "anchorY": 1,
  "anchorZ": -13,
  "blocks": [
    {
      "x": -13,
      "y": 0,
      "z": -13,
      "name": "Rock_Sandstone"
    },
    {
      "x": -13,
      "y": 1,
      "z": -13,
      "name": "Rock_Sandstone_Brick"
    },
    {
      "x": -13,
      "y": 2,
      "z": -13,
      "name": "Rock_Sandstone_Brick"
    },
    {
      "x": -13,
      "y": 3,
      "z": -13,
      "name": "Rock_Sandstone_Brick"
    },
    {
      "x": -13,
      "y": 4,
      "z": -13,
      "name": "Rock_Sandstone_Brick"
    },
    {
      "x": -13,
      "y": 5,
      "z": -13,
      "name": "Rock_Sandstone_Brick"
    },
    {
      "x": -13,
      "y": 6,
      "z": -13,
      "name": "Rock_Sandstone_Brick"
    },
    {
      "x": -13,
      "y": 7,
      "z": -13,
      "name": "Rock_Sandstone_Brick"
    },
    {
      "x": -13,
      "y": 8,
      "z": -13,
      "name": "Rock_Sandstone_Brick"
    },
    {
      "x": -13,
      "y": 9,
      "z": -13,
      "name": "Rock_Sandstone_Brick"
    },
    {
      "x": -13,
      "y": 10,
      "z": -13,
      "name": "Rock_Sandstone_Brick"
    },
    {
      "x": -13,
      "y": 11,
      "z": -13,
      "name": "Rock_Sandstone_Brick"
    },
    {
      "x": -13,
      "y": 12,
      "z": -13,
      "name": "Rock_Sandstone"
    },
    {
      "x": -13,
      "y": 13,
      "z": -13,
      "name": "Rock_Sandstone"
    },
    {
      "x": -13,
      "y": 14,
      "z": -13,
      "name": "Rock_Sandstone"
    },
    {
      "x": -13,
      "y": 15,
      "z": -13,
      "name": "Rock_Sandstone"
    },
    {
      "x": -13,
      "y": 0,
      "z": -12,
      "name": "Rock_Sandstone"
    },
    {
      "x": -13,
      "y": 1,
      "z": -12,
      "name": "Rock_Sandstone_Brick"
    },
    {
      "x": -13,
      "y": 2,
      "z": -12,
      "name": "Rock_Sandstone_Brick"
    },
    {
      "x": -13,
      "y": 3,
      "z": -12,
      "name": "Rock_Sandstone_Brick"
    },
    {
      "x": -13,
      "y": 4,
      "z": -12,
      "name": "Rock_Sandstone_Brick"
    },
    {
      "x": -13,
      "y": 5,
      "z": -12,
      "name": "Rock_Sandstone_Brick"
    },
    {
      "x": -13,
      "y": 6,
      "z": -12,
      "name": "Rock_Sandstone_Brick"
    },
    {
      "x": -13,
      "y": 7,
      "z": -12,
      "name": "Rock_Sandstone_Brick"
    },
    {
      "x": -13,
      "y": 8,
      "z": -12,
      "name": "Rock_Sandstone_Brick"
    },
    {
      "x": -13,
      "y": 9,
      "z": -12,
      "name": "Rock_Sandstone_Brick"
    },
    {
      "x": -13,
      "y": 10,
      "z": -12,
      "name": "Rock_Sandstone_Brick"
    },
    {
      "x": -13,
      "y": 11,
      "z": -12,
      "name": "Rock_Sandstone_Brick"
    },
    {
      "x": -13,
      "y": 12,
      "z": -12,
      "name": "Rock_Sandstone"
    },
    {
      "x": -13,
      "y": 13,
      "z": -12,
      "name": "Rock_Sandstone"
    },
    {
      "x": -13,
      "y": 14,
      "z": -12,
      "name": "Rock_Sandstone"
    },
    {
      "x": -13,
      "y": 15,
      "z": -12,
      "name": "Rock_Sandstone"
    },
    {
      "x": -13,
      "y": 0,
      "z": -11,
      "name": "Rock_Sandstone"
    },
    {
      "x": -13,
      "y": 1,
      "z": -11,
      "name": "Rock_Sandstone_Brick"
    },
    {
      "x": -13,
      "y": 2,
      "z": -11,
      "name": "Rock_Sandstone_Brick"
    },
    {
      "x": -13,
      "y": 3,
      "z": -11,
      "name": "Rock_Sandstone_Brick"
    },
    {
      "x": -13,
      "y": 4,
      "z": -11,
      "name": "Rock_Sandstone_Brick"
    },
    {
      "x": -13,
      "y": 5,
      "z": -11,
      "name": "Rock_Sandstone_Brick"
    },
    {
      "x": -13,
      "y": 6,
      "z": -11,
      "name": "Rock_Sandstone_Brick"
    },
    {
      "x": -13,
      "y": 7,
      "z": -11,
      "name": "Rock_Sandstone_Brick"
    },
    {
      "x": -13,
      "y": 8,
      "z": -11,
      "name": "Rock_Sandstone_Brick"
    },
    {
      "x": -13,
      "y": 9,
      "z": -11,
      "name": "Rock_Sandstone_Brick"
    },
    {
      "x": -13,
      "y": 10,
      "z": -11,
      "name": "Rock_Sandstone_Brick"
    },
    {
      "x": -13,
      "y": 11,
      "z": -11,
      "name": "Rock_Sandstone_Brick"
    },
    {
      "x": -13,
      "y": 12,
      "z": -11,
      "name": "Rock_Sandstone"
    },
    {
      "x": -13,
      "y": 13,
      "z": -11,
      "name": "Rock_Sandstone"
    },
    {
      "x": -13,
      "y": 14,
      "z": -11,
      "name": "Rock_Sandstone"
    },
    {
      "x": -13,
      "y": 15,
      "z": -11,
      "name": "Rock_Sandstone"
    },
    {
      "x": -13,
      "y": 0,
      "z": -10,
      "name": "Rock_Sandstone"
    },
    {
      "x": -13,
      "y": 1,
      "z": -10,
      "name": "Rock_Sandstone_Brick"
    },
    {
      "x": -13,
      "y": 2,
      "z": -10,
      "name": "Rock_Sandstone_Brick"
    },
    {
      "x": -13,
      "y": 3,
      "z": -10,
      "name": "Rock_Sandstone_Brick"
    },
    {
      "x": -13,
      "y": 4,
      "z": -10,
      "name": "Rock_Sandstone_Brick"
    },
    {
      "x": -13,
      "y": 5,
      "z": -10,
      "name": "Rock_Sandstone_Brick"
    },
    {
      "x": -13,
      "y": 6,
      "z": -10,
      "name": "Rock_Sandstone_Brick"
    },
    {
      "x": -13,
      "y": 7,
      "z": -10,
      "name": "Rock_Sandstone_Brick"
    },
    {
      "x": -13,
      "y": 8,
      "z": -10,
      "name": "Rock_Sandstone_Brick"
    },
    {
      "x": -13,
      "y": 9,
      "z": -10,
      "name": "Rock_Sandstone_Brick"
    },
    {
      "x": -13,
      "y": 10,
      "z": -10,
      "name": "Rock_Sandstone_Brick"
    },
    {
      "x": -13,
      "y": 11,
      "z": -10,
      "name": "Rock_Sandstone_Brick"
    },
    {
      "x": -13,
      "y": 12,
      "z": -10,
      "name": "Rock_Sandstone"
    },
    {
      "x": -13,
      "y": 13,
      "z": -10,
      "name": "Rock_Sandstone"
    },
    {
      "x": -13,
      "y": 14,
      "z": -10,
      "name": "Rock_Sandstone"
    },
    {
      "x": -13,
      "y": 15,
      "z": -10,
      "name": "Rock_Sandstone"
    },
    {
      "x": -13,
      "y": 0,
      "z": -9,
      "name": "Rock_Sandstone"
    },
    {
      "x": -13,
      "y": 1,
      "z": -9,
      "name": "Rock_Sandstone_Brick"
    },
    {
      "x": -13,
      "y": 2,
      "z": -9,
      "name": "Rock_Sandstone_Brick"
    },
    {
      "x": -13,
      "y": 3,
      "z": -9,
      "name": "Rock_Sandstone_Brick"
    },
    {
      "x": -13,
      "y": 4,
      "z": -9,
      "name": "Rock_Sandstone_Brick"
    },
    {
      "x": -13,
      "y": 5,
      "z": -9,
      "name": "Rock_Sandstone_Brick"
    },
    {
      "x": -13,
      "y": 6,
      "z": -9,
      "name": "Rock_Sandstone_Brick"
    },
    {
      "x": -13,
      "y": 7,
      "z": -9,
      "name": "Rock_Sandstone_Brick"
    },
    {
      "x": -13,
      "y": 8,
      "z": -9,
      "name": "Rock_Sandstone_Brick"
    },
    {
      "x": -13,
      "y": 9,
      "z": -9,
      "name": "Rock_Sandstone_Brick"
    },
    {
      "x": -13,
      "y": 10,
      "z": -9,
      "name": "Rock_Sandstone_Brick"
    },
    {
      "x": -13,
      "y": 11,
      "z": -9,
      "name": "Rock_Sandstone_Brick"
    },
    {
      "x": -13,
      "y": 12,
      "z": -9,
      "name": "Rock_Sandstone"
    },
    {
      "x": -13,
      "y": 13,
      "z": -9,
      "name": "Rock_Sandstone"
    },
    {
      "x": -13,
      "y": 14,
      "z": -9,
      "name": "Rock_Sandstone"
    },
    {
      "x": -13,
      "y": 15,
      "z": -9,
      "name": "Rock_Sandstone"
    },
    {
      "x": -13,
      "y": 0,
      "z": -8,
      "name": "Rock_Sandstone"
    },
    {
      "x": -13,
      "y": 1,
      "z": -8,
      "name": "Rock_Sandstone_Brick"
    },
    {
      "x": -13,
      "y": 2,
      "z": -8,
      "name": "Rock_Sandstone_Brick"
    },
    {
      "x": -13,
      "y": 3,
      "z": -8,
      "name": "Rock_Sandstone_Brick"
    },
    {
      "x": -13,
      "y": 4,
      "z": -8,
      "name": "Rock_Sandstone_Brick"
    },
    {
      "x": -13,
      "y": 5,
      "z": -8,
      "name": "Rock_Sandstone_Brick"
    },
    {
      "x": -13,
      "y": 6,
      "z": -8,
      "name": "Rock_Sandstone_Brick"
    },
    {
      "x": -13,
      "y": 7,
      "z": -8,
      "name": "Rock_Sandstone_Brick"
    },
    {
      "x": -13,
      "y": 8,
      "z": -8,
      "name": "Rock_Sandstone_Brick"
    },
    {
      "x": -13,
      "y": 9,
      "z": -8,
      "name": "Rock_Sandstone_Brick"
    },
    {
      "x": -13,
      "y": 10,
      "z": -8,
      "name": "Rock_Sandstone_Brick"
    },
    {
      "x": -13,
      "y": 11,
      "z": -8,
      "name": "Rock_Sandstone_Brick"
    },
    {
      "x": -13,
      "y": 12,
      "z": -8,
      "name": "Rock_Sandstone"
    },
    {
      "x": -13,
      "y": 13,
      "z": -8,
      "name": "Rock_Sandstone"
    },
    {
      "x": -13,
      "y": 14,
      "z": -8,
      "name": "Rock_Sandstone"
    },
    {
      "x": -13,
      "y": 15,
      "z": -8,
      "name": "Rock_Sandstone"
    },
    {
      "x": -13,
      "y": 0,
      "z": -7,
      "name": "Rock_Sandstone"
    },
    {
      "x": -13,
      "y": 1,
      "z": -7,
      "name": "Rock_Sandstone_Brick"
    },
    {
      "x": -13,
      "y": 2,
      "z": -7,
      "name": "Rock_Sandstone_Brick"
    },
    {
      "x": -13,
      "y": 3,
      "z": -7,
      "name": "Rock_Sandstone_Brick"
    },
    {
      "x": -13,
      "y": 4,
      "z": -7,
      "name": "Rock_Sandstone_Brick"
    },
    {
      "x": -13,
      "y": 5,
      "z": -7,
      "name": "Rock_Sandstone_Brick"
    },
    {
      "x": -13,
      "y": 6,
      "z": -7,
      "name": "Rock_Sandstone_Brick"
    },
    {
      "x": -13,
      "y": 7,
      "z": -7,
      "name": "Rock_Sandstone_Brick"
    },
    {
      "x": -13,
      "y": 8,
      "z": -7,
      "name": "Rock_Sandstone_Brick"
    },
    {
      "x": -13,
      "y": 9,
      "z": -7,
      "name": "Rock_Sandstone_Brick"
    },
    {
      "x": -13,
      "y": 10,
      "z": -7,
      "name": "Rock_Sandstone_Brick"
    },
    {
      "x": -13,
      "y": 11,
      "z": -7,
      "name": "Rock_Sandstone_Brick"
    },
    {
      "x": -13,
      "y": 12,
      "z": -7,
      "name": "Rock_Sandstone"
    },
    {
      "x": -13,
      "y": 13,
      "z": -7,
      "name": "Rock_Sandstone"
    },
    {
      "x": -13,
      "y": 14,
      "z": -7,
      "name": "Rock_Sandstone"
    },
    {
      "x": -13,
      "y": 15,
      "z": -7,
      "name": "Rock_Sandstone"
    },
    {
      "x": -13,
      "y": 0,
      "z": -6,
      "name": "Rock_Sandstone"
    },
    {
      "x": -13,
      "y": 1,
      "z": -6,
      "name": "Rock_Sandstone_Brick"
    },
    {
      "x": -13,
      "y": 2,
      "z": -6,
      "name": "Rock_Sandstone_Brick"
    },
    {
      "x": -13,
      "y": 3,
      "z": -6,
      "name": "Rock_Sandstone_Brick"
    },
    {
      "x": -13,
      "y": 4,
      "z": -6,
      "name": "Rock_Sandstone_Brick"
    },
    {
      "x": -13,
      "y": 5,
      "z": -6,
      "name": "Rock_Sandstone_Brick"
    },
    {
      "x": -13,
      "y": 6,
      "z": -6,
      "name": "Rock_Sandstone_Brick"
    },
    {
      "x": -13,
      "y": 7,
      "z": -6,
      "name": "Rock_Sandstone_Brick"
    },
    {
      "x": -13,
      "y": 8,
      "z": -6,
      "name": "Rock_Sandstone_Brick"
    },
    {
      "x": -13,
      "y": 9,
      "z": -6,
      "name": "Rock_Sandstone_Brick"
    },
    {
      "x": -13,
      "y": 10,
      "z": -6,
      "name": "Rock_Sandstone_Brick"
    },
    {
      "x": -13,
      "y": 11,
      "z": -6,
      "name": "Rock_Sandstone_Brick"
    },
    {
      "x": -13,
      "y": 12,
      "z": -6,
      "name": "Rock_Sandstone"
    },
    {
      "x": -13,
      "y": 13,
      "z": -6,
      "name": "Rock_Sandstone"
    },
    {
      "x": -13,
      "y": 14,
      "z": -6,
      "name": "Rock_Sandstone"
    },
    {
      "x": -13,
      "y": 15,
      "z": -6,
      "name": "Rock_Sandstone"
    },
    {
      "x": -13,
      "y": 0,
      "z": -5,
      "name": "Rock_Sandstone"
    },
    {
      "x": -13,
      "y": 1,
      "z": -5,
      "name": "Rock_Sandstone_Brick"
    },
    {
      "x": -13,
      "y": 2,
      "z": -5,
      "name": "Rock_Sandstone_Brick"
    },
    {
      "x": -13,
      "y": 3,
      "z": -5,
      "name": "Rock_Sandstone_Brick"
    },
    {
      "x": -13,
      "y": 4,
      "z": -5,
      "name": "Rock_Sandstone_Brick"
    },
    {
      "x": -13,
      "y": 5,
      "z": -5,
      "name": "Rock_Sandstone_Brick"
    },
    {
      "x": -13,
      "y": 6,
      "z": -5,
      "name": "Rock_Sandstone_Brick"
    },
    {
      "x": -13,
      "y": 7,
      "z": -5,
      "name": "Rock_Sandstone_Brick"
    },
    {
      "x": -13,
      "y": 8,
      "z": -5,
      "name": "Rock_Sandstone_Brick"
    },
    {
      "x": -13,
      "y": 9,
      "z": -5,
      "name": "Rock_Sandstone_Brick"
    },
    {
      "x": -13,
      "y": 10,
      "z": -5,
      "name": "Rock_Sandstone_Brick"
    },
    {
      "x": -13,
      "y": 11,
      "z": -5,
      "name": "Rock_Sandstone_Brick"
    },
    {
      "x": -13,
      "y": 12,
      "z": -5,
      "name": "Rock_Sandstone"
    },
    {
      "x": -13,
      "y": 13,
      "z": -5,
      "name": "Rock_Sandstone"
    },
    {
      "x": -13,
      "y": 14,
      "z": -5,
      "name": "Rock_Sandstone"
    },
    {
      "x": -13,
      "y": 15,
      "z": -5,
      "name": "Rock_Sandstone"
    },
    {
      "x": -13,
      "y": 0,
      "z": -4,
      "name": "Rock_Sandstone"
    },
    {
      "x": -13,
      "y": 1,
      "z": -4,
      "name": "Rock_Sandstone_Brick"
    },
    {
      "x": -13,
      "y": 2,
      "z": -4,
      "name": "Rock_Sandstone_Brick"
    },
    {
      "x": -13,
      "y": 3,
      "z": -4,
      "name": "Rock_Sandstone_Brick"
    },
    {
      "x": -13,
      "y": 4,
      "z": -4,
      "name": "Rock_Sandstone_Brick"
    },
    {
      "x": -13,
      "y": 5,
      "z": -4,
      "name": "Rock_Sandstone_Brick"
    },
    {
      "x": -13,
      "y": 6,
      "z": -4,
      "name": "Rock_Sandstone_Brick"
    },
    {
      "x": -13,
      "y": 7,
      "z": -4,
      "name": "Rock_Sandstone_Brick"
    },
    {
      "x": -13,
      "y": 8,
      "z": -4,
      "name": "Rock_Sandstone_Brick"
    },
    {
      "x": -13,
      "y": 9,
      "z": -4,
      "name": "Rock_Sandstone_Brick"
    },
    {
      "x": -13,
      "y": 10,
      "z": -4,
      "name": "Rock_Sandstone_Brick"
    },
    {
      "x": -13,
      "y": 11,
      "z": -4,
      "name": "Rock_Sandstone_Brick"
    },
    {
      "x": -13,
      "y": 12,
      "z": -4,
      "name": "Rock_Sandstone"
    },
    {
      "x": -13,
      "y": 13,
      "z": -4,
      "name": "Rock_Sandstone"
    },
    {
      "x": -13,
      "y": 14,
      "z": -4,
      "name": "Rock_Sandstone"
    },
    {
      "x": -13,
      "y": 15,
      "z": -4,
      "name": "Rock_Sandstone"
    },
    {
      "x": -13,
      "y": 0,
      "z": -3,
      "name": "Rock_Sandstone"
    },
    {
      "x": -13,
      "y": 1,
      "z": -3,
      "name": "Rock_Sandstone_Brick"
    },
    {
      "x": -13,
      "y": 2,
      "z": -3,
      "name": "Rock_Sandstone_Brick"
    },
    {
      "x": -13,
      "y": 3,
      "z": -3,
      "name": "Rock_Sandstone_Brick"
    },
    {
      "x": -13,
      "y": 4,
      "z": -3,
      "name": "Rock_Sandstone_Brick"
    },
    {
      "x": -13,
      "y": 5,
      "z": -3,
      "name": "Rock_Sandstone_Brick"
    },
    {
      "x": -13,
      "y": 6,
      "z": -3,
      "name": "Rock_Sandstone_Brick"
    },
    {
      "x": -13,
      "y": 7,
      "z": -3,
      "name": "Rock_Sandstone_Brick"
    },
    {
      "x": -13,
      "y": 8,
      "z": -3,
      "name": "Rock_Sandstone_Brick"
    },
    {
      "x": -13,
      "y": 9,
      "z": -3,
      "name": "Rock_Sandstone_Brick"
    },
    {
      "x": -13,
      "y": 10,
      "z": -3,
      "name": "Rock_Sandstone_Brick"
    },
    {
      "x": -13,
      "y": 11,
      "z": -3,
      "name": "Rock_Sandstone_Brick"
    },
    {
      "x": -13,
      "y": 12,
      "z": -3,
      "name": "Rock_Sandstone"
    },
    {
      "x": -13,
      "y": 13,
      "z": -3,
      "name": "Rock_Sandstone"
    },
    {
      "x": -13,
      "y": 14,
      "z": -3,
      "name": "Rock_Sandstone"
    },
    {
      "x": -13,
      "y": 15,
      "z": -3,
      "name": "Rock_Sandstone"
    },
    {
      "x": -13,
      "y": 0,
      "z": -2,
      "name": "Rock_Sandstone"
    },
    {
      "x": -13,
      "y": 1,
      "z": -2,
      "name": "Rock_Sandstone_Brick"
    },
    {
      "x": -13,
      "y": 2,
      "z": -2,
      "name": "Rock_Sandstone_Brick"
    },
    {
      "x": -13,
      "y": 3,
      "z": -2,
      "name": "Rock_Sandstone_Brick"
    },
    {
      "x": -13,
      "y": 4,
      "z": -2,
      "name": "Rock_Sandstone_Brick"
    },
    {
      "x": -13,
      "y": 5,
      "z": -2,
      "name": "Rock_Sandstone_Brick"
    },
    {
      "x": -13,
      "y": 6,
      "z": -2,
      "name": "Rock_Sandstone_Brick"
    },
    {
      "x": -13,
      "y": 7,
      "z": -2,
      "name": "Rock_Sandstone_Brick"
    },
    {
      "x": -13,
      "y": 8,
      "z": -2,
      "name": "Rock_Sandstone_Brick"
    },
    {
      "x": -13,
      "y": 9,
      "z": -2,
      "name": "Rock_Sandstone_Brick"
    },
    {
      "x": -13,
      "y": 10,
      "z": -2,
      "name": "Rock_Sandstone_Brick"
    },
    {
      "x": -13,
      "y": 11,
      "z": -2,
      "name": "Rock_Sandstone_Brick"
    },
    {
      "x": -13,
      "y": 12,
      "z": -2,
      "name": "Rock_Sandstone"
    },
    {
      "x": -13,
      "y": 13,
      "z": -2,
      "name": "Rock_Sandstone"
    },
    {
      "x": -13,
      "y": 14,
      "z": -2,
      "name": "Rock_Sandstone"
    },
    {
      "x": -13,
      "y": 15,
      "z": -2,
      "name": "Rock_Sandstone"
    },
    {
      "x": -13,
      "y": 0,
      "z": -1,
      "name": "Rock_Sandstone"
    },
    {
      "x": -13,
      "y": 1,
      "z": -1,
      "name": "Soil_Gravel_Sand"
    },
    {
      "x": -13,
      "y": 2,
      "z": -1,
      "name": "Empty"
    },
    {
      "x": -13,
      "y": 3,
      "z": -1,
      "name": "Empty"
    },
    {
      "x": -13,
      "y": 4,
      "z": -1,
      "name": "Empty"
    },
    {
      "x": -13,
      "y": 5,
      "z": -1,
      "name": "Empty"
    },
    {
      "x": -13,
      "y": 6,
      "z": -1,
      "name": "Empty"
    },
    {
      "x": -13,
      "y": 7,
      "z": -1,
      "name": "Empty"
    },
    {
      "x": -13,
      "y": 8,
      "z": -1,
      "name": "Empty"
    },
    {
      "x": -13,
      "y": 9,
      "z": -1,
      "name": "Empty"
    },
    {
      "x": -13,
      "y": 10,
      "z": -1,
      "name": "Empty"
    },
    {
      "x": -13,
      "y": 11,
      "z": -1,
      "name": "Empty"
    },
    {
      "x": -13,
      "y": 12,
      "z": -1,
      "name": "Rock_Sandstone"
    },
    {
      "x": -13,
      "y": 13,
      "z": -1,
      "name": "Rock_Sandstone"
    },
    {
      "x": -13,
      "y": 14,
      "z": -1,
      "name": "Rock_Sandstone"
    },
    {
      "x": -13,
      "y": 15,
      "z": -1,
      "name": "Rock_Sandstone"
    },
    {
      "x": -13,
      "y": 0,
      "z": 0,
      "name": "Rock_Sandstone"
    },
    {
      "x": -13,
      "y": 1,
      "z": 0,
      "name": "Soil_Gravel_Sand"
    },
    {
      "x": -13,
      "y": 2,
      "z": 0,
      "name": "Empty"
    },
    {
      "x": -13,
      "y": 3,
      "z": 0,
      "name": "Empty"
    },
    {
      "x": -13,
      "y": 4,
      "z": 0,
      "name": "Empty"
    },
    {
      "x": -13,
      "y": 5,
      "z": 0,
      "name": "Empty"
    },
    {
      "x": -13,
      "y": 6,
      "z": 0,
      "name": "Empty"
    },
    {
      "x": -13,
      "y": 7,
      "z": 0,
      "name": "Empty"
    },
    {
      "x": -13,
      "y": 8,
      "z": 0,
      "name": "Empty"
    },
    {
      "x": -13,
      "y": 9,
      "z": 0,
      "name": "Empty"
    },
    {
      "x": -13,
      "y": 10,
      "z": 0,
      "name": "Empty"
    },
    {
      "x": -13,
      "y": 11,
      "z": 0,
      "name": "Empty"
    },
    {
      "x": -13,
      "y": 12,
      "z": 0,
      "name": "Rock_Sandstone"
    },
    {
      "x": -13,
      "y": 13,
      "z": 0,
      "name": "Rock_Sandstone"
    },
    {
      "x": -13,
      "y": 14,
      "z": 0,
      "name": "Rock_Sandstone"
    },
    {
      "x": -13,
      "y": 15,
      "z": 0,
      "name": "Rock_Sandstone"
    },
    {
      "x": -13,
      "y": 0,
      "z": 1,
      "name": "Rock_Sandstone"
    },
    {
      "x": -13,
      "y": 1,
      "z": 1,
      "name": "Soil_Gravel_Sand"
    },
    {
      "x": -13,
      "y": 2,
      "z": 1,
      "name": "Empty"
    },
    {
      "x": -13,
      "y": 3,
      "z": 1,
      "name": "Empty"
    },
    {
      "x": -13,
      "y": 4,
      "z": 1,
      "name": "Empty"
    },
    {
      "x": -13,
      "y": 5,
      "z": 1,
      "name": "Empty"
    },
    {
      "x": -13,
      "y": 6,
      "z": 1,
      "name": "Empty"
    },
    {
      "x": -13,
      "y": 7,
      "z": 1,
      "name": "Empty"
    },
    {
      "x": -13,
      "y": 8,
      "z": 1,
      "name": "Empty"
    },
    {
      "x": -13,
      "y": 9,
      "z": 1,
      "name": "Empty"
    },
    {
      "x": -13,
      "y": 10,
      "z": 1,
      "name": "Empty"
    },
    {
      "x": -13,
      "y": 11,
      "z": 1,
      "name": "Empty"
    },
    {
      "x": -13,
      "y": 12,
      "z": 1,
      "name": "Rock_Sandstone"
    },
    {
      "x": -13,
      "y": 13,
      "z": 1,
      "name": "Rock_Sandstone"
    },
    {
      "x": -13,
      "y": 14,
      "z": 1,
      "name": "Rock_Sandstone"
    },
    {
      "x": -13,
      "y": 15,
      "z": 1,
      "name": "Rock_Sandstone"
    },
    {
      "x": -13,
      "y": 0,
      "z": 2,
      "name": "Rock_Sandstone"
    },
    {
      "x": -13,
      "y": 1,
      "z": 2,
      "name": "Rock_Sandstone_Brick"
    },
    {
      "x": -13,
      "y": 2,
      "z": 2,
      "name": "Rock_Sandstone_Brick"
    },
    {
      "x": -13,
      "y": 3,
      "z": 2,
      "name": "Rock_Sandstone_Brick"
    },
    {
      "x": -13,
      "y": 4,
      "z": 2,
      "name": "Rock_Sandstone_Brick"
    },
    {
      "x": -13,
      "y": 5,
      "z": 2,
      "name": "Rock_Sandstone_Brick"
    },
    {
      "x": -13,
      "y": 6,
      "z": 2,
      "name": "Rock_Sandstone_Brick"
    },
    {
      "x": -13,
      "y": 7,
      "z": 2,
      "name": "Rock_Sandstone_Brick"
    },
    {
      "x": -13,
      "y": 8,
      "z": 2,
      "name": "Rock_Sandstone_Brick"
    },
    {
      "x": -13,
      "y": 9,
      "z": 2,
      "name": "Rock_Sandstone_Brick"
    },
    {
      "x": -13,
      "y": 10,
      "z": 2,
      "name": "Rock_Sandstone_Brick"
    },
    {
      "x": -13,
      "y": 11,
      "z": 2,
      "name": "Rock_Sandstone_Brick"
    },
    {
      "x": -13,
      "y": 12,
      "z": 2,
      "name": "Rock_Sandstone"
    },
    {
      "x": -13,
      "y": 13,
      "z": 2,
      "name": "Rock_Sandstone"
    },
    {
      "x": -13,
      "y": 14,
      "z": 2,
      "name": "Rock_Sandstone"
    },
    {
      "x": -13,
      "y": 15,
      "z": 2,
      "name": "Rock_Sandstone"
    },
    {
      "x": -13,
      "y": 0,
      "z": 3,
      "name": "Rock_Sandstone"
    },
    {
      "x": -13,
      "y": 1,
      "z": 3,
      "name": "Rock_Sandstone_Brick"
    },
    {
      "x": -13,
      "y": 2,
      "z": 3,
      "name": "Rock_Sandstone_Brick"
    },
    {
      "x": -13,
      "y": 3,
      "z": 3,
      "name": "Rock_Sandstone_Brick"
    },
    {
      "x": -13,
      "y": 4,
      "z": 3,
      "name": "Rock_Sandstone_Brick"
    },
    {
      "x": -13,
      "y": 5,
      "z": 3,
      "name": "Rock_Sandstone_Brick"
    },
    {
      "x": -13,
      "y": 6,
      "z": 3,
      "name": "Rock_Sandstone_Brick"
    },
    {
      "x": -13,
      "y": 7,
      "z": 3,
      "name": "Rock_Sandstone_Brick"
    },
    {
      "x": -13,
      "y": 8,
      "z": 3,
      "name": "Rock_Sandstone_Brick"
    },
    {
      "x": -13,
      "y": 9,
      "z": 3,
      "name": "Rock_Sandstone_Brick"
    },
    {
      "x": -13,
      "y": 10,
      "z": 3,
      "name": "Rock_Sandstone_Brick"
    },
    {
      "x": -13,
      "y": 11,
      "z": 3,
      "name": "Rock_Sandstone_Brick"
    },
    {
      "x": -13,
      "y": 12,
      "z": 3,
      "name": "Rock_Sandstone"
    },
    {
      "x": -13,
      "y": 13,
      "z": 3,
      "name": "Rock_Sandstone"
    },
    {
      "x": -13,
      "y": 14,
      "z": 3,
      "name": "Rock_Sandstone"
    },
    {
      "x": -13,
      "y": 15,
      "z": 3,
      "name": "Rock_Sandstone"
    },
    {
      "x": -13,
      "y": 0,
      "z": 4,
      "name": "Rock_Sandstone"
    },
    {
      "x": -13,
      "y": 1,
      "z": 4,
      "name": "Rock_Sandstone_Brick"
    },
    {
      "x": -13,
      "y": 2,
      "z": 4,
      "name": "Rock_Sandstone_Brick"
    },
    {
      "x": -13,
      "y": 3,
      "z": 4,
      "name": "Rock_Sandstone_Brick"
    },
    {
      "x": -13,
      "y": 4,
      "z": 4,
      "name": "Rock_Sandstone_Brick"
    },
    {
      "x": -13,
      "y": 5,
      "z": 4,
      "name": "Rock_Sandstone_Brick"
    },
    {
      "x": -13,
      "y": 6,
      "z": 4,
      "name": "Rock_Sandstone_Brick"
    },
    {
      "x": -13,
      "y": 7,
      "z": 4,
      "name": "Rock_Sandstone_Brick"
    },
    {
      "x": -13,
      "y": 8,
      "z": 4,
      "name": "Rock_Sandstone_Brick"
    },
    {
      "x": -13,
      "y": 9,
      "z": 4,
      "name": "Rock_Sandstone_Brick"
    },
    {
      "x": -13,
      "y": 10,
      "z": 4,
      "name": "Rock_Sandstone_Brick"
    },
    {
      "x": -13,
      "y": 11,
      "z": 4,
      "name": "Rock_Sandstone_Brick"
    },
    {
      "x": -13,
      "y": 12,
      "z": 4,
      "name": "Rock_Sandstone"
    },
    {
      "x": -13,
      "y": 13,
      "z": 4,
      "name": "Rock_Sandstone"
    },
    {
      "x": -13,
      "y": 14,
      "z": 4,
      "name": "Rock_Sandstone"
    },
    {
      "x": -13,
      "y": 15,
      "z": 4,
      "name": "Rock_Sandstone"
    },
    {
      "x": -13,
      "y": 0,
      "z": 5,
      "name": "Rock_Sandstone"
    },
    {
      "x": -13,
      "y": 1,
      "z": 5,
      "name": "Rock_Sandstone_Brick"
    },
    {
      "x": -13,
      "y": 2,
      "z": 5,
      "name": "Rock_Sandstone_Brick"
    },
    {
      "x": -13,
      "y": 3,
      "z": 5,
      "name": "Rock_Sandstone_Brick"
    },
    {
      "x": -13,
      "y": 4,
      "z": 5,
      "name": "Rock_Sandstone_Brick"
    },
    {
      "x": -13,
      "y": 5,
      "z": 5,
      "name": "Rock_Sandstone_Brick"
    },
    {
      "x": -13,
      "y": 6,
      "z": 5,
      "name": "Rock_Sandstone_Brick"
    },
    {
      "x": -13,
      "y": 7,
      "z": 5,
      "name": "Rock_Sandstone_Brick"
    },
    {
      "x": -13,
      "y": 8,
      "z": 5,
      "name": "Rock_Sandstone_Brick"
    },
    {
      "x": -13,
      "y": 9,
      "z": 5,
      "name": "Rock_Sandstone_Brick"
    },
    {
      "x": -13,
      "y": 10,
      "z": 5,
      "name": "Rock_Sandstone_Brick"
    },
    {
      "x": -13,
      "y": 11,
      "z": 5,
      "name": "Rock_Sandstone_Brick"
    },
    {
      "x": -13,
      "y": 12,
      "z": 5,
      "name": "Rock_Sandstone"
    },
    {
      "x": -13,
      "y": 13,
      "z": 5,
      "name": "Rock_Sandstone"
    },
    {
      "x": -13,
      "y": 14,
      "z": 5,
      "name": "Rock_Sandstone"
    },
    {
      "x": -13,
      "y": 15,
      "z": 5,
      "name": "Rock_Sandstone"
    },
    {
      "x": -13,
      "y": 0,
      "z": 6,
      "name": "Rock_Sandstone"
    },
    {
      "x": -13,
      "y": 1,
      "z": 6,
      "name": "Rock_Sandstone_Brick"
    },
    {
      "x": -13,
      "y": 2,
      "z": 6,
      "name": "Rock_Sandstone_Brick"
    },
    {
      "x": -13,
      "y": 3,
      "z": 6,
      "name": "Rock_Sandstone_Brick"
    },
    {
      "x": -13,
      "y": 4,
      "z": 6,
      "name": "Rock_Sandstone_Brick"
    },
    {
      "x": -13,
      "y": 5,
      "z": 6,
      "name": "Rock_Sandstone_Brick"
    },
    {
      "x": -13,
      "y": 6,
      "z": 6,
      "name": "Rock_Sandstone_Brick"
    },
    {
      "x": -13,
      "y": 7,
      "z": 6,
      "name": "Rock_Sandstone_Brick"
    },
    {
      "x": -13,
      "y": 8,
      "z": 6,
      "name": "Rock_Sandstone_Brick"
    },
    {
      "x": -13,
      "y": 9,
      "z": 6,
      "name": "Rock_Sandstone_Brick"
    },
    {
      "x": -13,
      "y": 10,
      "z": 6,
      "name": "Rock_Sandstone_Brick"
    },
    {
      "x": -13,
      "y": 11,
      "z": 6,
      "name": "Rock_Sandstone_Brick"
    },
    {
      "x": -13,
      "y": 12,
      "z": 6,
      "name": "Rock_Sandstone"
    },
    {
      "x": -13,
      "y": 13,
      "z": 6,
      "name": "Rock_Sandstone"
    },
    {
      "x": -13,
      "y": 14,
      "z": 6,
      "name": "Rock_Sandstone"
    },
    {
      "x": -13,
      "y": 15,
      "z": 6,
      "name": "Rock_Sandstone"
    },
    {
      "x": -13,
      "y": 0,
      "z": 7,
      "name": "Rock_Sandstone"
    },
    {
      "x": -13,
      "y": 1,
      "z": 7,
      "name": "Rock_Sandstone_Brick"
    },
    {
      "x": -13,
      "y": 2,
      "z": 7,
      "name": "Rock_Sandstone_Brick"
    },
    {
      "x": -13,
      "y": 3,
      "z": 7,
      "name": "Rock_Sandstone_Brick"
    },
    {
      "x": -13,
      "y": 4,
      "z": 7,
      "name": "Rock_Sandstone_Brick"
    },
    {
      "x": -13,
      "y": 5,
      "z": 7,
      "name": "Rock_Sandstone_Brick"
    },
    {
      "x": -13,
      "y": 6,
      "z": 7,
      "name": "Rock_Sandstone_Brick"
    },
    {
      "x": -13,
      "y": 7,
      "z": 7,
      "name": "Rock_Sandstone_Brick"
    },
    {
      "x": -13,
      "y": 8,
      "z": 7,
      "name": "Rock_Sandstone_Brick"
    },
    {
      "x": -13,
      "y": 9,
      "z": 7,
      "name": "Rock_Sandstone_Brick"
    },
    {
      "x": -13,
      "y": 10,
      "z": 7,
      "name": "Rock_Sandstone_Brick"
    },
    {
      "x": -13,
      "y": 11,
      "z": 7,
      "name": "Rock_Sandstone_Brick"
    },
    {
      "x": -13,
      "y": 12,
      "z": 7,
      "name": "Rock_Sandstone"
    },
    {
      "x": -13,
      "y": 13,
      "z": 7,
      "name": "Rock_Sandstone"
    },
    {
      "x": -13,
      "y": 14,
      "z": 7,
      "name": "Rock_Sandstone"
    },
    {
      "x": -13,
      "y": 15,
      "z": 7,
      "name": "Rock_Sandstone"
    },
    {
      "x": -13,
      "y": 0,
      "z": 8,
      "name": "Rock_Sandstone"
    },
    {
      "x": -13,
      "y": 1,
      "z": 8,
      "name": "Rock_Sandstone_Brick"
    },
    {
      "x": -13,
      "y": 2,
      "z": 8,
      "name": "Rock_Sandstone_Brick"
    },
    {
      "x": -13,
      "y": 3,
      "z": 8,
      "name": "Rock_Sandstone_Brick"
    },
    {
      "x": -13,
      "y": 4,
      "z": 8,
      "name": "Rock_Sandstone_Brick"
    },
    {
      "x": -13,
      "y": 5,
      "z": 8,
      "name": "Rock_Sandstone_Brick"
    },
    {
      "x": -13,
      "y": 6,
      "z": 8,
      "name": "Rock_Sandstone_Brick"
    },
    {
      "x": -13,
      "y": 7,
      "z": 8,
      "name": "Rock_Sandstone_Brick"
    },
    {
      "x": -13,
      "y": 8,
      "z": 8,
      "name": "Rock_Sandstone_Brick"
    },
    {
      "x": -13,
      "y": 9,
      "z": 8,
      "name": "Rock_Sandstone_Brick"
    },
    {
      "x": -13,
      "y": 10,
      "z": 8,
      "name": "Rock_Sandstone_Brick"
    },
    {
      "x": -13,
      "y": 11,
      "z": 8,
      "name": "Rock_Sandstone_Brick"
    },
    {
      "x": -13,
      "y": 12,
      "z": 8,
      "name": "Rock_Sandstone"
    },
    {
      "x": -13,
      "y": 13,
      "z": 8,
      "name": "Rock_Sandstone"
    },
    {
      "x": -13,
      "y": 14,
      "z": 8,
      "name": "Rock_Sandstone"
    },
    {
      "x": -13,
      "y": 15,
      "z": 8,
      "name": "Rock_Sandstone"
    },
    {
      "x": -13,
      "y": 0,
      "z": 9,
      "name": "Rock_Sandstone"
    },
    {
      "x": -13,
      "y": 1,
      "z": 9,
      "name": "Rock_Sandstone_Brick"
    },
    {
      "x": -13,
      "y": 2,
      "z": 9,
      "name": "Rock_Sandstone_Brick"
    },
    {
      "x": -13,
      "y": 3,
      "z": 9,
      "name": "Rock_Sandstone_Brick"
    },
    {
      "x": -13,
      "y": 4,
      "z": 9,
      "name": "Rock_Sandstone_Brick"
    },
    {
      "x": -13,
      "y": 5,
      "z": 9,
      "name": "Rock_Sandstone_Brick"
    },
    {
      "x": -13,
      "y": 6,
      "z": 9,
      "name": "Rock_Sandstone_Brick"
    },
    {
      "x": -13,
      "y": 7,
      "z": 9,
      "name": "Rock_Sandstone_Brick"
    },
    {
      "x": -13,
      "y": 8,
      "z": 9,
      "name": "Rock_Sandstone_Brick"
    },
    {
      "x": -13,
      "y": 9,
      "z": 9,
      "name": "Rock_Sandstone_Brick"
    },
    {
      "x": -13,
      "y": 10,
      "z": 9,
      "name": "Rock_Sandstone_Brick"
    },
    {
      "x": -13,
      "y": 11,
      "z": 9,
      "name": "Rock_Sandstone_Brick"
    },
    {
      "x": -13,
      "y": 12,
      "z": 9,
      "name": "Rock_Sandstone"
    },
    {
      "x": -13,
      "y": 13,
      "z": 9,
      "name": "Rock_Sandstone"
    },
    {
      "x": -13,
      "y": 14,
      "z": 9,
      "name": "Rock_Sandstone"
    },
    {
      "x": -13,
      "y": 15,
      "z": 9,
      "name": "Rock_Sandstone"
    },
    {
      "x": -13,
      "y": 0,
      "z": 10,
      "name": "Rock_Sandstone"
    },
    {
      "x": -13,
      "y": 1,
      "z": 10,
      "name": "Rock_Sandstone_Brick"
    },
    {
      "x": -13,
      "y": 2,
      "z": 10,
      "name": "Rock_Sandstone_Brick"
    },
    {
      "x": -13,
      "y": 3,
      "z": 10,
      "name": "Rock_Sandstone_Brick"
    },
    {
      "x": -13,
      "y": 4,
      "z": 10,
      "name": "Rock_Sandstone_Brick"
    },
    {
      "x": -13,
      "y": 5,
      "z": 10,
      "name": "Rock_Sandstone_Brick"
    },
    {
      "x": -13,
      "y": 6,
      "z": 10,
      "name": "Rock_Sandstone_Brick"
    },
    {
      "x": -13,
      "y": 7,
      "z": 10,
      "name": "Rock_Sandstone_Brick"
    },
    {
      "x": -13,
      "y": 8,
      "z": 10,
      "name": "Rock_Sandstone_Brick"
    },
    {
      "x": -13,
      "y": 9,
      "z": 10,
      "name": "Rock_Sandstone_Brick"
    },
    {
      "x": -13,
      "y": 10,
      "z": 10,
      "name": "Rock_Sandstone_Brick"
    },
    {
      "x": -13,
      "y": 11,
      "z": 10,
      "name": "Rock_Sandstone_Brick"
    },
    {
      "x": -13,
      "y": 12,
      "z": 10,
      "name": "Rock_Sandstone"
    },
    {
      "x": -13,
      "y": 13,
      "z": 10,
      "name": "Rock_Sandstone"
    },
    {
      "x": -13,
      "y": 14,
      "z": 10,
      "name": "Rock_Sandstone"
    },
    {
      "x": -13,
      "y": 15,
      "z": 10,
      "name": "Rock_Sandstone"
    },
    {
      "x": -13,
      "y": 0,
      "z": 11,
      "name": "Rock_Sandstone"
    },
    {
      "x": -13,
      "y": 1,
      "z": 11,
      "name": "Rock_Sandstone_Brick"
    },
    {
      "x": -13,
      "y": 2,
      "z": 11,
      "name": "Rock_Sandstone_Brick"
    },
    {
      "x": -13,
      "y": 3,
      "z": 11,
      "name": "Rock_Sandstone_Brick"
    },
    {
      "x": -13,
      "y": 4,
      "z": 11,
      "name": "Rock_Sandstone_Brick"
    },
    {
      "x": -13,
      "y": 5,
      "z": 11,
      "name": "Rock_Sandstone_Brick"
    },
    {
      "x": -13,
      "y": 6,
      "z": 11,
      "name": "Rock_Sandstone_Brick"
    },
    {
      "x": -13,
      "y": 7,
      "z": 11,
      "name": "Rock_Sandstone_Brick"
    },
    {
      "x": -13,
      "y": 8,
      "z": 11,
      "name": "Rock_Sandstone_Brick"
    },
    {
      "x": -13,
      "y": 9,
      "z": 11,
      "name": "Rock_Sandstone_Brick"
    },
    {
      "x": -13,
      "y": 10,
      "z": 11,
      "name": "Rock_Sandstone_Brick"
    },
    {
      "x": -13,
      "y": 11,
      "z": 11,
      "name": "Rock_Sandstone_Brick"
    },
    {
      "x": -13,
      "y": 12,
      "z": 11,
      "name": "Rock_Sandstone"
    },
    {
      "x": -13,
      "y": 13,
      "z": 11,
      "name": "Rock_Sandstone"
    },
    {
      "x": -13,
      "y": 14,
      "z": 11,
      "name": "Rock_Sandstone"
    },
    {
      "x": -13,
      "y": 15,
      "z": 11,
      "name": "Rock_Sandstone"
    },
    {
      "x": -13,
      "y": 0,
      "z": 12,
      "name": "Rock_Sandstone"
    },
    {
      "x": -13,
      "y": 1,
      "z": 12,
      "name": "Rock_Sandstone_Brick"
    },
    {
      "x": -13,
      "y": 2,
      "z": 12,
      "name": "Rock_Sandstone_Brick"
    },
    {
      "x": -13,
      "y": 3,
      "z": 12,
      "name": "Rock_Sandstone_Brick"
    },
    {
      "x": -13,
      "y": 4,
      "z": 12,
      "name": "Rock_Sandstone_Brick"
    },
    {
      "x": -13,
      "y": 5,
      "z": 12,
      "name": "Rock_Sandstone_Brick"
    },
    {
      "x": -13,
      "y": 6,
      "z": 12,
      "name": "Rock_Sandstone_Brick"
    },
    {
      "x": -13,
      "y": 7,
      "z": 12,
      "name": "Rock_Sandstone_Brick"
    },
    {
      "x": -13,
      "y": 8,
      "z": 12,
      "name": "Rock_Sandstone_Brick"
    },
    {
      "x": -13,
      "y": 9,
      "z": 12,
      "name": "Rock_Sandstone_Brick"
    },
    {
      "x": -13,
      "y": 10,
      "z": 12,
      "name": "Rock_Sandstone_Brick"
    },
    {
      "x": -13,
      "y": 11,
      "z": 12,
      "name": "Rock_Sandstone_Brick"
    },
    {
      "x": -13,
      "y": 12,
      "z": 12,
      "name": "Rock_Sandstone"
    },
    {
      "x": -13,
      "y": 13,
      "z": 12,
      "name": "Rock_Sandstone"
    },
    {
      "x": -13,
      "y": 14,
      "z": 12,
      "name": "Rock_Sandstone"
    },
    {
      "x": -13,
      "y": 15,
      "z": 12,
      "name": "Rock_Sandstone"
    },
    {
      "x": -13,
      "y": 0,
      "z": 13,
      "name": "Rock_Sandstone"
    },
    {
      "x": -13,
      "y": 1,
      "z": 13,
      "name": "Rock_Sandstone_Brick"
    },
    {
      "x": -13,
      "y": 2,
      "z": 13,
      "name": "Rock_Sandstone_Brick"
    },
    {
      "x": -13,
      "y": 3,
      "z": 13,
      "name": "Rock_Sandstone_Brick"
    },
    {
      "x": -13,
      "y": 4,
      "z": 13,
      "name": "Rock_Sandstone_Brick"
    },
    {
      "x": -13,
      "y": 5,
      "z": 13,
      "name": "Rock_Sandstone_Brick"
    },
    {
      "x": -13,
      "y": 6,
      "z": 13,
      "name": "Rock_Sandstone_Brick"
    },
    {
      "x": -13,
      "y": 7,
      "z": 13,
      "name": "Rock_Sandstone_Brick"
    },
    {
      "x": -13,
      "y": 8,
      "z": 13,
      "name": "Rock_Sandstone_Brick"
    },
    {
      "x": -13,
      "y": 9,
      "z": 13,
      "name": "Rock_Sandstone_Brick"
    },
    {
      "x": -13,
      "y": 10,
      "z": 13,
      "name": "Rock_Sandstone_Brick"
    },
    {
      "x": -13,
      "y": 11,
      "z": 13,
      "name": "Rock_Sandstone_Brick"
    },
    {
      "x": -13,
      "y": 12,
      "z": 13,
      "name": "Rock_Sandstone"
    },
    {
      "x": -13,
      "y": 13,
      "z": 13,
      "name": "Rock_Sandstone"
    },
    {
      "x": -13,
      "y": 14,
      "z": 13,
      "name": "Rock_Sandstone"
    },
    {
      "x": -13,
      "y": 15,
      "z": 13,
      "name": "Rock_Sandstone"
    },
    {
      "x": -12,
      "y": 0,
      "z": -13,
      "name": "Rock_Sandstone"
    },
    {
      "x": -12,
      "y": 1,
      "z": -13,
      "name": "Rock_Sandstone_Brick"
    },
    {
      "x": -12,
      "y": 2,
      "z": -13,
      "name": "Rock_Sandstone_Brick"
    },
    {
      "x": -12,
      "y": 3,
      "z": -13,
      "name": "Rock_Sandstone_Brick"
    },
    {
      "x": -12,
      "y": 4,
      "z": -13,
      "name": "Rock_Sandstone_Brick"
    },
    {
      "x": -12,
      "y": 5,
      "z": -13,
      "name": "Rock_Sandstone_Brick"
    },
    {
      "x": -12,
      "y": 6,
      "z": -13,
      "name": "Rock_Sandstone_Brick"
    },
    {
      "x": -12,
      "y": 7,
      "z": -13,
      "name": "Rock_Sandstone_Brick"
    },
    {
      "x": -12,
      "y": 8,
      "z": -13,
      "name": "Rock_Sandstone_Brick"
    },
    {
      "x": -12,
      "y": 9,
      "z": -13,
      "name": "Rock_Sandstone_Brick"
    },
    {
      "x": -12,
      "y": 10,
      "z": -13,
      "name": "Rock_Sandstone_Brick"
    },
    {
      "x": -12,
      "y": 11,
      "z": -13,
      "name": "Rock_Sandstone_Brick"
    },
    {
      "x": -12,
      "y": 12,
      "z": -13,
      "name": "Rock_Sandstone"
    },
    {
      "x": -12,
      "y": 13,
      "z": -13,
      "name": "Rock_Sandstone"
    },
    {
      "x": -12,
      "y": 14,
      "z": -13,
      "name": "Rock_Sandstone"
    },
    {
      "x": -12,
      "y": 15,
      "z": -13,
      "name": "Rock_Sandstone"
    },
    {
      "x": -12,
      "y": 0,
      "z": -12,
      "name": "Rock_Sandstone"
    },
    {
      "x": -12,
      "y": 1,
      "z": -12,
      "name": "Rock_Sandstone_Brick"
    },
    {
      "x": -12,
      "y": 2,
      "z": -12,
      "name": "Rock_Sandstone_Brick"
    },
    {
      "x": -12,
      "y": 3,
      "z": -12,
      "name": "Rock_Sandstone_Brick"
    },
    {
      "x": -12,
      "y": 4,
      "z": -12,
      "name": "Rock_Sandstone_Brick"
    },
    {
      "x": -12,
      "y": 5,
      "z": -12,
      "name": "Rock_Sandstone_Brick"
    },
    {
      "x": -12,
      "y": 6,
      "z": -12,
      "name": "Rock_Sandstone_Brick"
    },
    {
      "x": -12,
      "y": 7,
      "z": -12,
      "name": "Rock_Sandstone_Brick"
    },
    {
      "x": -12,
      "y": 8,
      "z": -12,
      "name": "Rock_Sandstone_Brick"
    },
    {
      "x": -12,
      "y": 9,
      "z": -12,
      "name": "Rock_Sandstone_Brick"
    },
    {
      "x": -12,
      "y": 10,
      "z": -12,
      "name": "Rock_Sandstone_Brick"
    },
    {
      "x": -12,
      "y": 11,
      "z": -12,
      "name": "Rock_Sandstone_Brick"
    },
    {
      "x": -12,
      "y": 12,
      "z": -12,
      "name": "Rock_Sandstone"
    },
    {
      "x": -12,
      "y": 13,
      "z": -12,
      "name": "Rock_Sandstone"
    },
    {
      "x": -12,
      "y": 14,
      "z": -12,
      "name": "Rock_Sandstone"
    },
    {
      "x": -12,
      "y": 15,
      "z": -12,
      "name": "Rock_Sandstone"
    },
    {
      "x": -12,
      "y": 0,
      "z": -11,
      "name": "Rock_Sandstone"
    },
    {
      "x": -12,
      "y": 1,
      "z": -11,
      "name": "Rock_Sandstone_Brick"
    },
    {
      "x": -12,
      "y": 2,
      "z": -11,
      "name": "Rock_Sandstone_Brick"
    },
    {
      "x": -12,
      "y": 3,
      "z": -11,
      "name": "Rock_Sandstone_Brick"
    },
    {
      "x": -12,
      "y": 4,
      "z": -11,
      "name": "Rock_Sandstone_Brick"
    },
    {
      "x": -12,
      "y": 5,
      "z": -11,
      "name": "Rock_Sandstone_Brick"
    },
    {
      "x": -12,
      "y": 6,
      "z": -11,
      "name": "Rock_Sandstone_Brick"
    },
    {
      "x": -12,
      "y": 7,
      "z": -11,
      "name": "Rock_Sandstone_Brick"
    },
    {
      "x": -12,
      "y": 8,
      "z": -11,
      "name": "Rock_Sandstone_Brick"
    },
    {
      "x": -12,
      "y": 9,
      "z": -11,
      "name": "Rock_Sandstone_Brick"
    },
    {
      "x": -12,
      "y": 10,
      "z": -11,
      "name": "Rock_Sandstone_Brick"
    },
    {
      "x": -12,
      "y": 11,
      "z": -11,
      "name": "Rock_Sandstone_Brick"
    },
    {
      "x": -12,
      "y": 12,
      "z": -11,
      "name": "Rock_Sandstone"
    },
    {
      "x": -12,
      "y": 13,
      "z": -11,
      "name": "Rock_Sandstone"
    },
    {
      "x": -12,
      "y": 14,
      "z": -11,
      "name": "Rock_Sandstone"
    },
    {
      "x": -12,
      "y": 15,
      "z": -11,
      "name": "Rock_Sandstone"
    },
    {
      "x": -12,
      "y": 0,
      "z": -10,
      "name": "Rock_Sandstone"
    },
    {
      "x": -12,
      "y": 1,
      "z": -10,
      "name": "Rock_Sandstone_Brick"
    },
    {
      "x": -12,
      "y": 2,
      "z": -10,
      "name": "Rock_Sandstone_Brick"
    },
    {
      "x": -12,
      "y": 3,
      "z": -10,
      "name": "Rock_Sandstone_Brick"
    },
    {
      "x": -12,
      "y": 4,
      "z": -10,
      "name": "Rock_Sandstone_Brick"
    },
    {
      "x": -12,
      "y": 5,
      "z": -10,
      "name": "Rock_Sandstone_Brick"
    },
    {
      "x": -12,
      "y": 6,
      "z": -10,
      "name": "Rock_Sandstone_Brick"
    },
    {
      "x": -12,
      "y": 7,
      "z": -10,
      "name": "Rock_Sandstone_Brick"
    },
    {
      "x": -12,
      "y": 8,
      "z": -10,
      "name": "Rock_Sandstone_Brick"
    },
    {
      "x": -12,
      "y": 9,
      "z": -10,
      "name": "Rock_Sandstone_Red_Brick"
    },
    {
      "x": -12,
      "y": 10,
      "z": -10,
      "name": "Rock_Sandstone_Brick"
    },
    {
      "x": -12,
      "y": 11,
      "z": -10,
      "name": "Rock_Sandstone_Brick"
    },
    {
      "x": -12,
      "y": 12,
      "z": -10,
      "name": "Rock_Sandstone"
    },
    {
      "x": -12,
      "y": 13,
      "z": -10,
      "name": "Rock_Sandstone"
    },
    {
      "x": -12,
      "y": 14,
      "z": -10,
      "name": "Rock_Sandstone"
    },
    {
      "x": -12,
      "y": 15,
      "z": -10,
      "name": "Rock_Sandstone"
    },
    {
      "x": -12,
      "y": 0,
      "z": -9,
      "name": "Rock_Sandstone"
    },
    {
      "x": -12,
      "y": 1,
      "z": -9,
      "name": "Rock_Sandstone_Brick"
    },
    {
      "x": -12,
      "y": 2,
      "z": -9,
      "name": "Rock_Sandstone_Brick"
    },
    {
      "x": -12,
      "y": 3,
      "z": -9,
      "name": "Rock_Sandstone_Brick"
    },
    {
      "x": -12,
      "y": 4,
      "z": -9,
      "name": "Rock_Sandstone_Brick"
    },
    {
      "x": -12,
      "y": 5,
      "z": -9,
      "name": "Rock_Sandstone_Brick"
    },
    {
      "x": -12,
      "y": 6,
      "z": -9,
      "name": "Rock_Sandstone_Brick"
    },
    {
      "x": -12,
      "y": 7,
      "z": -9,
      "name": "Rock_Sandstone_Brick"
    },
    {
      "x": -12,
      "y": 8,
      "z": -9,
      "name": "Rock_Sandstone_Brick"
    },
    {
      "x": -12,
      "y": 9,
      "z": -9,
      "name": "Rock_Sandstone_Red_Brick"
    },
    {
      "x": -12,
      "y": 10,
      "z": -9,
      "name": "Rock_Sandstone_Brick"
    },
    {
      "x": -12,
      "y": 11,
      "z": -9,
      "name": "Rock_Sandstone_Brick"
    },
    {
      "x": -12,
      "y": 12,
      "z": -9,
      "name": "Rock_Sandstone"
    },
    {
      "x": -12,
      "y": 13,
      "z": -9,
      "name": "Rock_Sandstone"
    },
    {
      "x": -12,
      "y": 14,
      "z": -9,
      "name": "Rock_Sandstone"
    },
    {
      "x": -12,
      "y": 15,
      "z": -9,
      "name": "Rock_Sandstone"
    },
    {
      "x": -12,
      "y": 0,
      "z": -8,
      "name": "Rock_Sandstone"
    },
    {
      "x": -12,
      "y": 1,
      "z": -8,
      "name": "Rock_Sandstone_Brick"
    },
    {
      "x": -12,
      "y": 2,
      "z": -8,
      "name": "Rock_Sandstone_Brick"
    },
    {
      "x": -12,
      "y": 3,
      "z": -8,
      "name": "Rock_Sandstone_Brick_Stairs",
      "rotation": 1
    },
    {
      "x": -12,
      "y": 4,
      "z": -8,
      "name": "Rock_Sandstone_Brick"
    },
    {
      "x": -12,
      "y": 5,
      "z": -8,
      "name": "Rock_Sandstone_Brick"
    },
    {
      "x": -12,
      "y": 6,
      "z": -8,
      "name": "Rock_Sandstone_Brick"
    },
    {
      "x": -12,
      "y": 7,
      "z": -8,
      "name": "Rock_Sandstone_Brick"
    },
    {
      "x": -12,
      "y": 8,
      "z": -8,
      "name": "Rock_Sandstone_Brick"
    },
    {
      "x": -12,
      "y": 9,
      "z": -8,
      "name": "Rock_Sandstone_Red_Brick"
    },
    {
      "x": -12,
      "y": 10,
      "z": -8,
      "name": "Rock_Sandstone_Brick"
    },
    {
      "x": -12,
      "y": 11,
      "z": -8,
      "name": "Rock_Sandstone_Brick"
    },
    {
      "x": -12,
      "y": 12,
      "z": -8,
      "name": "Rock_Sandstone"
    },
    {
      "x": -12,
      "y": 13,
      "z": -8,
      "name": "Rock_Sandstone"
    },
    {
      "x": -12,
      "y": 14,
      "z": -8,
      "name": "Rock_Sandstone"
    },
    {
      "x": -12,
      "y": 15,
      "z": -8,
      "name": "Rock_Sandstone"
    },
    {
      "x": -12,
      "y": 0,
      "z": -7,
      "name": "Rock_Sandstone"
    },
    {
      "x": -12,
      "y": 1,
      "z": -7,
      "name": "Rock_Sandstone_Brick"
    },
    {
      "x": -12,
      "y": 2,
      "z": -7,
      "name": "Rock_Sandstone_Brick"
    },
    {
      "x": -12,
      "y": 3,
      "z": -7,
      "name": "Rock_Sandstone_Brick_Stairs",
      "rotation": 1
    },
    {
      "x": -12,
      "y": 4,
      "z": -7,
      "name": "Rock_Sandstone_Brick"
    },
    {
      "x": -12,
      "y": 5,
      "z": -7,
      "name": "Rock_Sandstone_Brick"
    },
    {
      "x": -12,
      "y": 6,
      "z": -7,
      "name": "Rock_Sandstone_Brick"
    },
    {
      "x": -12,
      "y": 7,
      "z": -7,
      "name": "Rock_Sandstone_Brick"
    },
    {
      "x": -12,
      "y": 8,
      "z": -7,
      "name": "Rock_Sandstone_Brick"
    },
    {
      "x": -12,
      "y": 9,
      "z": -7,
      "name": "Rock_Sandstone_Red_Brick"
    },
    {
      "x": -12,
      "y": 10,
      "z": -7,
      "name": "Rock_Sandstone_Brick"
    },
    {
      "x": -12,
      "y": 11,
      "z": -7,
      "name": "Rock_Sandstone_Brick"
    },
    {
      "x": -12,
      "y": 12,
      "z": -7,
      "name": "Rock_Sandstone"
    },
    {
      "x": -12,
      "y": 13,
      "z": -7,
      "name": "Rock_Sandstone"
    },
    {
      "x": -12,
      "y": 14,
      "z": -7,
      "name": "Rock_Sandstone"
    },
    {
      "x": -12,
      "y": 15,
      "z": -7,
      "name": "Rock_Sandstone"
    },
    {
      "x": -12,
      "y": 0,
      "z": -6,
      "name": "Rock_Sandstone"
    },
    {
      "x": -12,
      "y": 1,
      "z": -6,
      "name": "Rock_Sandstone_Brick"
    },
    {
      "x": -12,
      "y": 2,
      "z": -6,
      "name": "Rock_Sandstone_Brick"
    },
    {
      "x": -12,
      "y": 3,
      "z": -6,
      "name": "Rock_Sandstone_Brick_Stairs",
      "rotation": 1
    },
    {
      "x": -12,
      "y": 4,
      "z": -6,
      "name": "Rock_Sandstone_Brick"
    },
    {
      "x": -12,
      "y": 5,
      "z": -6,
      "name": "Rock_Sandstone_Brick"
    },
    {
      "x": -12,
      "y": 6,
      "z": -6,
      "name": "Rock_Sandstone_Brick"
    },
    {
      "x": -12,
      "y": 7,
      "z": -6,
      "name": "Rock_Sandstone_Brick"
    },
    {
      "x": -12,
      "y": 8,
      "z": -6,
      "name": "Rock_Sandstone_Brick"
    },
    {
      "x": -12,
      "y": 9,
      "z": -6,
      "name": "Rock_Sandstone_Red_Brick"
    },
    {
      "x": -12,
      "y": 10,
      "z": -6,
      "name": "Rock_Sandstone_Brick"
    },
    {
      "x": -12,
      "y": 11,
      "z": -6,
      "name": "Rock_Sandstone_Brick"
    },
    {
      "x": -12,
      "y": 12,
      "z": -6,
      "name": "Rock_Sandstone"
    },
    {
      "x": -12,
      "y": 13,
      "z": -6,
      "name": "Rock_Sandstone"
    },
    {
      "x": -12,
      "y": 14,
      "z": -6,
      "name": "Rock_Sandstone"
    },
    {
      "x": -12,
      "y": 15,
      "z": -6,
      "name": "Rock_Sandstone"
    },
    {
      "x": -12,
      "y": 0,
      "z": -5,
      "name": "Rock_Sandstone"
    },
    {
      "x": -12,
      "y": 1,
      "z": -5,
      "name": "Rock_Sandstone_Brick"
    },
    {
      "x": -12,
      "y": 2,
      "z": -5,
      "name": "Rock_Sandstone_Brick"
    },
    {
      "x": -12,
      "y": 3,
      "z": -5,
      "name": "Rock_Sandstone_Brick_Stairs",
      "rotation": 1
    },
    {
      "x": -12,
      "y": 4,
      "z": -5,
      "name": "Rock_Sandstone_Brick"
    },
    {
      "x": -12,
      "y": 5,
      "z": -5,
      "name": "Rock_Sandstone_Brick"
    },
    {
      "x": -12,
      "y": 6,
      "z": -5,
      "name": "Rock_Sandstone_Brick"
    },
    {
      "x": -12,
      "y": 7,
      "z": -5,
      "name": "Rock_Sandstone_Brick"
    },
    {
      "x": -12,
      "y": 8,
      "z": -5,
      "name": "Rock_Sandstone_Brick"
    },
    {
      "x": -12,
      "y": 9,
      "z": -5,
      "name": "Rock_Sandstone_Red_Brick"
    },
    {
      "x": -12,
      "y": 10,
      "z": -5,
      "name": "Rock_Sandstone_Brick"
    },
    {
      "x": -12,
      "y": 11,
      "z": -5,
      "name": "Rock_Sandstone_Brick"
    },
    {
      "x": -12,
      "y": 12,
      "z": -5,
      "name": "Rock_Sandstone"
    },
    {
      "x": -12,
      "y": 13,
      "z": -5,
      "name": "Rock_Sandstone"
    },
    {
      "x": -12,
      "y": 14,
      "z": -5,
      "name": "Rock_Sandstone"
    },
    {
      "x": -12,
      "y": 15,
      "z": -5,
      "name": "Rock_Sandstone"
    },
    {
      "x": -12,
      "y": 0,
      "z": -4,
      "name": "Rock_Sandstone"
    },
    {
      "x": -12,
      "y": 1,
      "z": -4,
      "name": "Rock_Sandstone_Brick"
    },
    {
      "x": -12,
      "y": 2,
      "z": -4,
      "name": "Rock_Sandstone_Brick"
    },
    {
      "x": -12,
      "y": 3,
      "z": -4,
      "name": "Rock_Sandstone_Brick_Stairs",
      "rotation": 1
    },
    {
      "x": -12,
      "y": 4,
      "z": -4,
      "name": "Rock_Sandstone_Brick"
    },
    {
      "x": -12,
      "y": 5,
      "z": -4,
      "name": "Rock_Sandstone_Brick"
    },
    {
      "x": -12,
      "y": 6,
      "z": -4,
      "name": "Rock_Sandstone_Brick"
    },
    {
      "x": -12,
      "y": 7,
      "z": -4,
      "name": "Rock_Sandstone_Brick"
    },
    {
      "x": -12,
      "y": 8,
      "z": -4,
      "name": "Rock_Sandstone_Brick"
    },
    {
      "x": -12,
      "y": 9,
      "z": -4,
      "name": "Rock_Sandstone_Red_Brick"
    },
    {
      "x": -12,
      "y": 10,
      "z": -4,
      "name": "Rock_Sandstone_Brick"
    },
    {
      "x": -12,
      "y": 11,
      "z": -4,
      "name": "Rock_Sandstone_Brick"
    },
    {
      "x": -12,
      "y": 12,
      "z": -4,
      "name": "Rock_Sandstone"
    },
    {
      "x": -12,
      "y": 13,
      "z": -4,
      "name": "Rock_Sandstone"
    },
    {
      "x": -12,
      "y": 14,
      "z": -4,
      "name": "Rock_Sandstone"
    },
    {
      "x": -12,
      "y": 15,
      "z": -4,
      "name": "Rock_Sandstone"
    },
    {
      "x": -12,
      "y": 0,
      "z": -3,
      "name": "Rock_Sandstone"
    },
    {
      "x": -12,
      "y": 1,
      "z": -3,
      "name": "Rock_Sandstone_Brick"
    },
    {
      "x": -12,
      "y": 2,
      "z": -3,
      "name": "Rock_Sandstone_Brick"
    },
    {
      "x": -12,
      "y": 3,
      "z": -3,
      "name": "Rock_Sandstone_Brick_Stairs",
      "rotation": 1
    },
    {
      "x": -12,
      "y": 4,
      "z": -3,
      "name": "Rock_Sandstone_Brick"
    },
    {
      "x": -12,
      "y": 5,
      "z": -3,
      "name": "Rock_Sandstone_Brick"
    },
    {
      "x": -12,
      "y": 6,
      "z": -3,
      "name": "Rock_Sandstone_Brick"
    },
    {
      "x": -12,
      "y": 7,
      "z": -3,
      "name": "Rock_Sandstone_Brick"
    },
    {
      "x": -12,
      "y": 8,
      "z": -3,
      "name": "Rock_Sandstone_Brick"
    },
    {
      "x": -12,
      "y": 9,
      "z": -3,
      "name": "Rock_Sandstone_Red_Brick"
    },
    {
      "x": -12,
      "y": 10,
      "z": -3,
      "name": "Rock_Sandstone_Brick"
    },
    {
      "x": -12,
      "y": 11,
      "z": -3,
      "name": "Rock_Sandstone_Brick"
    },
    {
      "x": -12,
      "y": 12,
      "z": -3,
      "name": "Rock_Sandstone"
    },
    {
      "x": -12,
      "y": 13,
      "z": -3,
      "name": "Rock_Sandstone"
    },
    {
      "x": -12,
      "y": 14,
      "z": -3,
      "name": "Rock_Sandstone"
    },
    {
      "x": -12,
      "y": 15,
      "z": -3,
      "name": "Rock_Sandstone"
    },
    {
      "x": -12,
      "y": 0,
      "z": -2,
      "name": "Rock_Sandstone"
    },
    {
      "x": -12,
      "y": 1,
      "z": -2,
      "name": "Rock_Sandstone_Brick"
    },
    {
      "x": -12,
      "y": 2,
      "z": -2,
      "name": "Rock_Sandstone_Brick"
    },
    {
      "x": -12,
      "y": 3,
      "z": -2,
      "name": "Rock_Sandstone_Brick_Stairs",
      "rotation": 1
    },
    {
      "x": -12,
      "y": 4,
      "z": -2,
      "name": "Rock_Sandstone_Brick"
    },
    {
      "x": -12,
      "y": 5,
      "z": -2,
      "name": "Rock_Sandstone_Brick"
    },
    {
      "x": -12,
      "y": 6,
      "z": -2,
      "name": "Rock_Sandstone_Brick"
    },
    {
      "x": -12,
      "y": 7,
      "z": -2,
      "name": "Rock_Sandstone_Brick"
    },
    {
      "x": -12,
      "y": 8,
      "z": -2,
      "name": "Rock_Sandstone_Brick"
    },
    {
      "x": -12,
      "y": 9,
      "z": -2,
      "name": "Rock_Sandstone_Red_Brick"
    },
    {
      "x": -12,
      "y": 10,
      "z": -2,
      "name": "Rock_Sandstone_Brick"
    },
    {
      "x": -12,
      "y": 11,
      "z": -2,
      "name": "Rock_Sandstone_Brick"
    },
    {
      "x": -12,
      "y": 12,
      "z": -2,
      "name": "Rock_Sandstone"
    },
    {
      "x": -12,
      "y": 13,
      "z": -2,
      "name": "Rock_Sandstone"
    },
    {
      "x": -12,
      "y": 14,
      "z": -2,
      "name": "Rock_Sandstone"
    },
    {
      "x": -12,
      "y": 15,
      "z": -2,
      "name": "Rock_Sandstone"
    },
    {
      "x": -12,
      "y": 0,
      "z": -1,
      "name": "Rock_Sandstone"
    },
    {
      "x": -12,
      "y": 1,
      "z": -1,
      "name": "Soil_Gravel_Sand"
    },
    {
      "x": -12,
      "y": 2,
      "z": -1,
      "name": "Empty"
    },
    {
      "x": -12,
      "y": 3,
      "z": -1,
      "name": "Empty"
    },
    {
      "x": -12,
      "y": 4,
      "z": -1,
      "name": "Empty"
    },
    {
      "x": -12,
      "y": 5,
      "z": -1,
      "name": "Empty"
    },
    {
      "x": -12,
      "y": 6,
      "z": -1,
      "name": "Empty"
    },
    {
      "x": -12,
      "y": 7,
      "z": -1,
      "name": "Empty"
    },
    {
      "x": -12,
      "y": 8,
      "z": -1,
      "name": "Empty"
    },
    {
      "x": -12,
      "y": 9,
      "z": -1,
      "name": "Empty"
    },
    {
      "x": -12,
      "y": 10,
      "z": -1,
      "name": "Empty"
    },
    {
      "x": -12,
      "y": 11,
      "z": -1,
      "name": "Empty"
    },
    {
      "x": -12,
      "y": 12,
      "z": -1,
      "name": "Rock_Sandstone"
    },
    {
      "x": -12,
      "y": 13,
      "z": -1,
      "name": "Rock_Sandstone"
    },
    {
      "x": -12,
      "y": 14,
      "z": -1,
      "name": "Rock_Sandstone"
    },
    {
      "x": -12,
      "y": 15,
      "z": -1,
      "name": "Rock_Sandstone"
    },
    {
      "x": -12,
      "y": 0,
      "z": 0,
      "name": "Rock_Sandstone"
    },
    {
      "x": -12,
      "y": 1,
      "z": 0,
      "name": "Soil_Gravel_Sand"
    },
    {
      "x": -12,
      "y": 2,
      "z": 0,
      "name": "Empty"
    },
    {
      "x": -12,
      "y": 3,
      "z": 0,
      "name": "Empty"
    },
    {
      "x": -12,
      "y": 4,
      "z": 0,
      "name": "Empty"
    },
    {
      "x": -12,
      "y": 5,
      "z": 0,
      "name": "Empty"
    },
    {
      "x": -12,
      "y": 6,
      "z": 0,
      "name": "Empty"
    },
    {
      "x": -12,
      "y": 7,
      "z": 0,
      "name": "Empty"
    },
    {
      "x": -12,
      "y": 8,
      "z": 0,
      "name": "Empty"
    },
    {
      "x": -12,
      "y": 9,
      "z": 0,
      "name": "Empty"
    },
    {
      "x": -12,
      "y": 10,
      "z": 0,
      "name": "Empty"
    },
    {
      "x": -12,
      "y": 11,
      "z": 0,
      "name": "Empty"
    },
    {
      "x": -12,
      "y": 12,
      "z": 0,
      "name": "Rock_Sandstone"
    },
    {
      "x": -12,
      "y": 13,
      "z": 0,
      "name": "Rock_Sandstone"
    },
    {
      "x": -12,
      "y": 14,
      "z": 0,
      "name": "Rock_Sandstone"
    },
    {
      "x": -12,
      "y": 15,
      "z": 0,
      "name": "Rock_Sandstone"
    },
    {
      "x": -12,
      "y": 0,
      "z": 1,
      "name": "Rock_Sandstone"
    },
    {
      "x": -12,
      "y": 1,
      "z": 1,
      "name": "Soil_Gravel_Sand"
    },
    {
      "x": -12,
      "y": 2,
      "z": 1,
      "name": "Empty"
    },
    {
      "x": -12,
      "y": 3,
      "z": 1,
      "name": "Empty"
    },
    {
      "x": -12,
      "y": 4,
      "z": 1,
      "name": "Empty"
    },
    {
      "x": -12,
      "y": 5,
      "z": 1,
      "name": "Empty"
    },
    {
      "x": -12,
      "y": 6,
      "z": 1,
      "name": "Empty"
    },
    {
      "x": -12,
      "y": 7,
      "z": 1,
      "name": "Empty"
    },
    {
      "x": -12,
      "y": 8,
      "z": 1,
      "name": "Empty"
    },
    {
      "x": -12,
      "y": 9,
      "z": 1,
      "name": "Empty"
    },
    {
      "x": -12,
      "y": 10,
      "z": 1,
      "name": "Empty"
    },
    {
      "x": -12,
      "y": 11,
      "z": 1,
      "name": "Empty"
    },
    {
      "x": -12,
      "y": 12,
      "z": 1,
      "name": "Rock_Sandstone"
    },
    {
      "x": -12,
      "y": 13,
      "z": 1,
      "name": "Rock_Sandstone"
    },
    {
      "x": -12,
      "y": 14,
      "z": 1,
      "name": "Rock_Sandstone"
    },
    {
      "x": -12,
      "y": 15,
      "z": 1,
      "name": "Rock_Sandstone"
    },
    {
      "x": -12,
      "y": 0,
      "z": 2,
      "name": "Rock_Sandstone"
    },
    {
      "x": -12,
      "y": 1,
      "z": 2,
      "name": "Rock_Sandstone_Brick"
    },
    {
      "x": -12,
      "y": 2,
      "z": 2,
      "name": "Rock_Sandstone_Brick"
    },
    {
      "x": -12,
      "y": 3,
      "z": 2,
      "name": "Rock_Sandstone_Brick_Stairs",
      "rotation": 1
    },
    {
      "x": -12,
      "y": 4,
      "z": 2,
      "name": "Rock_Sandstone_Brick"
    },
    {
      "x": -12,
      "y": 5,
      "z": 2,
      "name": "Rock_Sandstone_Brick"
    },
    {
      "x": -12,
      "y": 6,
      "z": 2,
      "name": "Rock_Sandstone_Brick"
    },
    {
      "x": -12,
      "y": 7,
      "z": 2,
      "name": "Rock_Sandstone_Brick"
    },
    {
      "x": -12,
      "y": 8,
      "z": 2,
      "name": "Rock_Sandstone_Brick"
    },
    {
      "x": -12,
      "y": 9,
      "z": 2,
      "name": "Rock_Sandstone_Red_Brick"
    },
    {
      "x": -12,
      "y": 10,
      "z": 2,
      "name": "Rock_Sandstone_Brick"
    },
    {
      "x": -12,
      "y": 11,
      "z": 2,
      "name": "Rock_Sandstone_Brick"
    },
    {
      "x": -12,
      "y": 12,
      "z": 2,
      "name": "Rock_Sandstone"
    },
    {
      "x": -12,
      "y": 13,
      "z": 2,
      "name": "Rock_Sandstone"
    },
    {
      "x": -12,
      "y": 14,
      "z": 2,
      "name": "Rock_Sandstone"
    },
    {
      "x": -12,
      "y": 15,
      "z": 2,
      "name": "Rock_Sandstone"
    },
    {
      "x": -12,
      "y": 0,
      "z": 3,
      "name": "Rock_Sandstone"
    },
    {
      "x": -12,
      "y": 1,
      "z": 3,
      "name": "Rock_Sandstone_Brick"
    },
    {
      "x": -12,
      "y": 2,
      "z": 3,
      "name": "Rock_Sandstone_Brick"
    },
    {
      "x": -12,
      "y": 3,
      "z": 3,
      "name": "Rock_Sandstone_Brick_Stairs",
      "rotation": 1
    },
    {
      "x": -12,
      "y": 4,
      "z": 3,
      "name": "Rock_Sandstone_Brick"
    },
    {
      "x": -12,
      "y": 5,
      "z": 3,
      "name": "Rock_Sandstone_Brick"
    },
    {
      "x": -12,
      "y": 6,
      "z": 3,
      "name": "Rock_Sandstone_Brick"
    },
    {
      "x": -12,
      "y": 7,
      "z": 3,
      "name": "Rock_Sandstone_Brick"
    },
    {
      "x": -12,
      "y": 8,
      "z": 3,
      "name": "Rock_Sandstone_Brick"
    },
    {
      "x": -12,
      "y": 9,
      "z": 3,
      "name": "Rock_Sandstone_Red_Brick"
    },
    {
      "x": -12,
      "y": 10,
      "z": 3,
      "name": "Rock_Sandstone_Brick"
    },
    {
      "x": -12,
      "y": 11,
      "z": 3,
      "name": "Rock_Sandstone_Brick"
    },
    {
      "x": -12,
      "y": 12,
      "z": 3,
      "name": "Rock_Sandstone"
    },
    {
      "x": -12,
      "y": 13,
      "z": 3,
      "name": "Rock_Sandstone"
    },
    {
      "x": -12,
      "y": 14,
      "z": 3,
      "name": "Rock_Sandstone"
    },
    {
      "x": -12,
      "y": 15,
      "z": 3,
      "name": "Rock_Sandstone"
    },
    {
      "x": -12,
      "y": 0,
      "z": 4,
      "name": "Rock_Sandstone"
    },
    {
      "x": -12,
      "y": 1,
      "z": 4,
      "name": "Rock_Sandstone_Brick"
    },
    {
      "x": -12,
      "y": 2,
      "z": 4,
      "name": "Rock_Sandstone_Brick"
    },
    {
      "x": -12,
      "y": 3,
      "z": 4,
      "name": "Rock_Sandstone_Brick_Stairs",
      "rotation": 1
    },
    {
      "x": -12,
      "y": 4,
      "z": 4,
      "name": "Rock_Sandstone_Brick"
    },
    {
      "x": -12,
      "y": 5,
      "z": 4,
      "name": "Rock_Sandstone_Brick"
    },
    {
      "x": -12,
      "y": 6,
      "z": 4,
      "name": "Rock_Sandstone_Brick"
    },
    {
      "x": -12,
      "y": 7,
      "z": 4,
      "name": "Rock_Sandstone_Brick"
    },
    {
      "x": -12,
      "y": 8,
      "z": 4,
      "name": "Rock_Sandstone_Brick"
    },
    {
      "x": -12,
      "y": 9,
      "z": 4,
      "name": "Rock_Sandstone_Red_Brick"
    },
    {
      "x": -12,
      "y": 10,
      "z": 4,
      "name": "Rock_Sandstone_Brick"
    },
    {
      "x": -12,
      "y": 11,
      "z": 4,
      "name": "Rock_Sandstone_Brick"
    },
    {
      "x": -12,
      "y": 12,
      "z": 4,
      "name": "Rock_Sandstone"
    },
    {
      "x": -12,
      "y": 13,
      "z": 4,
      "name": "Rock_Sandstone"
    },
    {
      "x": -12,
      "y": 14,
      "z": 4,
      "name": "Rock_Sandstone"
    },
    {
      "x": -12,
      "y": 15,
      "z": 4,
      "name": "Rock_Sandstone"
    },
    {
      "x": -12,
      "y": 0,
      "z": 5,
      "name": "Rock_Sandstone"
    },
    {
      "x": -12,
      "y": 1,
      "z": 5,
      "name": "Rock_Sandstone_Brick"
    },
    {
      "x": -12,
      "y": 2,
      "z": 5,
      "name": "Rock_Sandstone_Brick"
    },
    {
      "x": -12,
      "y": 3,
      "z": 5,
      "name": "Rock_Sandstone_Brick"
    },
    {
      "x": -12,
      "y": 4,
      "z": 5,
      "name": "Rock_Sandstone_Brick"
    },
    {
      "x": -12,
      "y": 5,
      "z": 5,
      "name": "Rock_Sandstone_Brick"
    },
    {
      "x": -12,
      "y": 6,
      "z": 5,
      "name": "Rock_Sandstone_Brick"
    },
    {
      "x": -12,
      "y": 7,
      "z": 5,
      "name": "Rock_Sandstone_Brick"
    },
    {
      "x": -12,
      "y": 8,
      "z": 5,
      "name": "Rock_Sandstone_Brick"
    },
    {
      "x": -12,
      "y": 9,
      "z": 5,
      "name": "Rock_Sandstone_Red_Brick"
    },
    {
      "x": -12,
      "y": 10,
      "z": 5,
      "name": "Rock_Sandstone_Brick"
    },
    {
      "x": -12,
      "y": 11,
      "z": 5,
      "name": "Rock_Sandstone_Brick"
    },
    {
      "x": -12,
      "y": 12,
      "z": 5,
      "name": "Rock_Sandstone"
    },
    {
      "x": -12,
      "y": 13,
      "z": 5,
      "name": "Rock_Sandstone"
    },
    {
      "x": -12,
      "y": 14,
      "z": 5,
      "name": "Rock_Sandstone"
    },
    {
      "x": -12,
      "y": 15,
      "z": 5,
      "name": "Rock_Sandstone"
    },
    {
      "x": -12,
      "y": 0,
      "z": 6,
      "name": "Rock_Sandstone"
    },
    {
      "x": -12,
      "y": 1,
      "z": 6,
      "name": "Rock_Sandstone_Brick"
    },
    {
      "x": -12,
      "y": 2,
      "z": 6,
      "name": "Rock_Sandstone_Brick"
    },
    {
      "x": -12,
      "y": 3,
      "z": 6,
      "name": "Rock_Sandstone_Brick"
    },
    {
      "x": -12,
      "y": 4,
      "z": 6,
      "name": "Rock_Sandstone_Brick"
    },
    {
      "x": -12,
      "y": 5,
      "z": 6,
      "name": "Rock_Sandstone_Brick"
    },
    {
      "x": -12,
      "y": 6,
      "z": 6,
      "name": "Rock_Sandstone_Brick"
    },
    {
      "x": -12,
      "y": 7,
      "z": 6,
      "name": "Rock_Sandstone_Brick"
    },
    {
      "x": -12,
      "y": 8,
      "z": 6,
      "name": "Rock_Sandstone_Brick"
    },
    {
      "x": -12,
      "y": 9,
      "z": 6,
      "name": "Rock_Sandstone_Red_Brick"
    },
    {
      "x": -12,
      "y": 10,
      "z": 6,
      "name": "Rock_Sandstone_Brick"
    },
    {
      "x": -12,
      "y": 11,
      "z": 6,
      "name": "Rock_Sandstone_Brick"
    },
    {
      "x": -12,
      "y": 12,
      "z": 6,
      "name": "Rock_Sandstone"
    },
    {
      "x": -12,
      "y": 13,
      "z": 6,
      "name": "Rock_Sandstone"
    },
    {
      "x": -12,
      "y": 14,
      "z": 6,
      "name": "Rock_Sandstone"
    },
    {
      "x": -12,
      "y": 15,
      "z": 6,
      "name": "Rock_Sandstone"
    },
    {
      "x": -12,
      "y": 0,
      "z": 7,
      "name": "Rock_Sandstone"
    },
    {
      "x": -12,
      "y": 1,
      "z": 7,
      "name": "Rock_Sandstone_Brick"
    },
    {
      "x": -12,
      "y": 2,
      "z": 7,
      "name": "Rock_Sandstone_Brick"
    },
    {
      "x": -12,
      "y": 3,
      "z": 7,
      "name": "Rock_Sandstone_Brick"
    },
    {
      "x": -12,
      "y": 4,
      "z": 7,
      "name": "Rock_Sandstone_Brick"
    },
    {
      "x": -12,
      "y": 5,
      "z": 7,
      "name": "Rock_Sandstone_Brick"
    },
    {
      "x": -12,
      "y": 6,
      "z": 7,
      "name": "Rock_Sandstone_Brick"
    },
    {
      "x": -12,
      "y": 7,
      "z": 7,
      "name": "Rock_Sandstone_Brick"
    },
    {
      "x": -12,
      "y": 8,
      "z": 7,
      "name": "Rock_Sandstone_Brick"
    },
    {
      "x": -12,
      "y": 9,
      "z": 7,
      "name": "Rock_Sandstone_Red_Brick"
    },
    {
      "x": -12,
      "y": 10,
      "z": 7,
      "name": "Rock_Sandstone_Brick"
    },
    {
      "x": -12,
      "y": 11,
      "z": 7,
      "name": "Rock_Sandstone_Brick"
    },
    {
      "x": -12,
      "y": 12,
      "z": 7,
      "name": "Rock_Sandstone"
    },
    {
      "x": -12,
      "y": 13,
      "z": 7,
      "name": "Rock_Sandstone"
    },
    {
      "x": -12,
      "y": 14,
      "z": 7,
      "name": "Rock_Sandstone"
    },
    {
      "x": -12,
      "y": 15,
      "z": 7,
      "name": "Rock_Sandstone"
    },
    {
      "x": -12,
      "y": 0,
      "z": 8,
      "name": "Rock_Sandstone"
    },
    {
      "x": -12,
      "y": 1,
      "z": 8,
      "name": "Rock_Sandstone_Brick"
    },
    {
      "x": -12,
      "y": 2,
      "z": 8,
      "name": "Rock_Sandstone_Brick"
    },
    {
      "x": -12,
      "y": 3,
      "z": 8,
      "name": "Rock_Sandstone_Brick"
    },
    {
      "x": -12,
      "y": 4,
      "z": 8,
      "name": "Rock_Sandstone_Brick"
    },
    {
      "x": -12,
      "y": 5,
      "z": 8,
      "name": "Rock_Sandstone_Brick"
    },
    {
      "x": -12,
      "y": 6,
      "z": 8,
      "name": "Rock_Sandstone_Brick"
    },
    {
      "x": -12,
      "y": 7,
      "z": 8,
      "name": "Rock_Sandstone_Brick"
    },
    {
      "x": -12,
      "y": 8,
      "z": 8,
      "name": "Rock_Sandstone_Brick"
    },
    {
      "x": -12,
      "y": 9,
      "z": 8,
      "name": "Rock_Sandstone_Red_Brick"
    },
    {
      "x": -12,
      "y": 10,
      "z": 8,
      "name": "Rock_Sandstone_Brick"
    },
    {
      "x": -12,
      "y": 11,
      "z": 8,
      "name": "Rock_Sandstone_Brick"
    },
    {
      "x": -12,
      "y": 12,
      "z": 8,
      "name": "Rock_Sandstone"
    },
    {
      "x": -12,
      "y": 13,
      "z": 8,
      "name": "Rock_Sandstone"
    },
    {
      "x": -12,
      "y": 14,
      "z": 8,
      "name": "Rock_Sandstone"
    },
    {
      "x": -12,
      "y": 15,
      "z": 8,
      "name": "Rock_Sandstone"
    },
    {
      "x": -12,
      "y": 0,
      "z": 9,
      "name": "Rock_Sandstone"
    },
    {
      "x": -12,
      "y": 1,
      "z": 9,
      "name": "Rock_Sandstone_Brick"
    },
    {
      "x": -12,
      "y": 2,
      "z": 9,
      "name": "Rock_Sandstone_Brick"
    },
    {
      "x": -12,
      "y": 3,
      "z": 9,
      "name": "Rock_Sandstone_Brick"
    },
    {
      "x": -12,
      "y": 4,
      "z": 9,
      "name": "Rock_Sandstone_Brick"
    },
    {
      "x": -12,
      "y": 5,
      "z": 9,
      "name": "Rock_Sandstone_Brick"
    },
    {
      "x": -12,
      "y": 6,
      "z": 9,
      "name": "Rock_Sandstone_Brick"
    },
    {
      "x": -12,
      "y": 7,
      "z": 9,
      "name": "Rock_Sandstone_Brick"
    },
    {
      "x": -12,
      "y": 8,
      "z": 9,
      "name": "Rock_Sandstone_Brick"
    },
    {
      "x": -12,
      "y": 9,
      "z": 9,
      "name": "Rock_Sandstone_Red_Brick"
    },
    {
      "x": -12,
      "y": 10,
      "z": 9,
      "name": "Rock_Sandstone_Brick"
    },
    {
      "x": -12,
      "y": 11,
      "z": 9,
      "name": "Rock_Sandstone_Brick"
    },
    {
      "x": -12,
      "y": 12,
      "z": 9,
      "name": "Rock_Sandstone"
    },
    {
      "x": -12,
      "y": 13,
      "z": 9,
      "name": "Rock_Sandstone"
    },
    {
      "x": -12,
      "y": 14,
      "z": 9,
      "name": "Rock_Sandstone"
    },
    {
      "x": -12,
      "y": 15,
      "z": 9,
      "name": "Rock_Sandstone"
    },
    {
      "x": -12,
      "y": 0,
      "z": 10,
      "name": "Rock_Sandstone"
    },
    {
      "x": -12,
      "y": 1,
      "z": 10,
      "name": "Rock_Sandstone_Brick"
    },
    {
      "x": -12,
      "y": 2,
      "z": 10,
      "name": "Rock_Sandstone_Brick"
    },
    {
      "x": -12,
      "y": 3,
      "z": 10,
      "name": "Rock_Sandstone_Brick"
    },
    {
      "x": -12,
      "y": 4,
      "z": 10,
      "name": "Rock_Sandstone_Brick"
    },
    {
      "x": -12,
      "y": 5,
      "z": 10,
      "name": "Rock_Sandstone_Brick"
    },
    {
      "x": -12,
      "y": 6,
      "z": 10,
      "name": "Rock_Sandstone_Brick"
    },
    {
      "x": -12,
      "y": 7,
      "z": 10,
      "name": "Rock_Sandstone_Brick"
    },
    {
      "x": -12,
      "y": 8,
      "z": 10,
      "name": "Rock_Sandstone_Brick"
    },
    {
      "x": -12,
      "y": 9,
      "z": 10,
      "name": "Rock_Sandstone_Red_Brick"
    },
    {
      "x": -12,
      "y": 10,
      "z": 10,
      "name": "Rock_Sandstone_Brick"
    },
    {
      "x": -12,
      "y": 11,
      "z": 10,
      "name": "Rock_Sandstone_Brick"
    },
    {
      "x": -12,
      "y": 12,
      "z": 10,
      "name": "Rock_Sandstone"
    },
    {
      "x": -12,
      "y": 13,
      "z": 10,
      "name": "Rock_Sandstone"
    },
    {
      "x": -12,
      "y": 14,
      "z": 10,
      "name": "Rock_Sandstone"
    },
    {
      "x": -12,
      "y": 15,
      "z": 10,
      "name": "Rock_Sandstone"
    },
    {
      "x": -12,
      "y": 0,
      "z": 11,
      "name": "Rock_Sandstone"
    },
    {
      "x": -12,
      "y": 1,
      "z": 11,
      "name": "Rock_Sandstone_Brick"
    },
    {
      "x": -12,
      "y": 2,
      "z": 11,
      "name": "Rock_Sandstone_Brick"
    },
    {
      "x": -12,
      "y": 3,
      "z": 11,
      "name": "Rock_Sandstone_Brick"
    },
    {
      "x": -12,
      "y": 4,
      "z": 11,
      "name": "Rock_Sandstone_Brick"
    },
    {
      "x": -12,
      "y": 5,
      "z": 11,
      "name": "Rock_Sandstone_Brick"
    },
    {
      "x": -12,
      "y": 6,
      "z": 11,
      "name": "Rock_Sandstone_Brick"
    },
    {
      "x": -12,
      "y": 7,
      "z": 11,
      "name": "Rock_Sandstone_Brick"
    },
    {
      "x": -12,
      "y": 8,
      "z": 11,
      "name": "Rock_Sandstone_Brick"
    },
    {
      "x": -12,
      "y": 9,
      "z": 11,
      "name": "Rock_Sandstone_Red_Brick"
    },
    {
      "x": -12,
      "y": 10,
      "z": 11,
      "name": "Rock_Sandstone_Brick"
    },
    {
      "x": -12,
      "y": 11,
      "z": 11,
      "name": "Rock_Sandstone_Brick"
    },
    {
      "x": -12,
      "y": 12,
      "z": 11,
      "name": "Rock_Sandstone"
    },
    {
      "x": -12,
      "y": 13,
      "z": 11,
      "name": "Rock_Sandstone"
    },
    {
      "x": -12,
      "y": 14,
      "z": 11,
      "name": "Rock_Sandstone"
    },
    {
      "x": -12,
      "y": 15,
      "z": 11,
      "name": "Rock_Sandstone"
    },
    {
      "x": -12,
      "y": 0,
      "z": 12,
      "name": "Rock_Sandstone"
    },
    {
      "x": -12,
      "y": 1,
      "z": 12,
      "name": "Rock_Sandstone_Brick"
    },
    {
      "x": -12,
      "y": 2,
      "z": 12,
      "name": "Rock_Sandstone_Brick"
    },
    {
      "x": -12,
      "y": 3,
      "z": 12,
      "name": "Rock_Sandstone_Brick"
    },
    {
      "x": -12,
      "y": 4,
      "z": 12,
      "name": "Rock_Sandstone_Brick"
    },
    {
      "x": -12,
      "y": 5,
      "z": 12,
      "name": "Rock_Sandstone_Brick"
    },
    {
      "x": -12,
      "y": 6,
      "z": 12,
      "name": "Rock_Sandstone_Brick"
    },
    {
      "x": -12,
      "y": 7,
      "z": 12,
      "name": "Rock_Sandstone_Brick"
    },
    {
      "x": -12,
      "y": 8,
      "z": 12,
      "name": "Rock_Sandstone_Brick"
    },
    {
      "x": -12,
      "y": 9,
      "z": 12,
      "name": "Rock_Sandstone_Brick"
    },
    {
      "x": -12,
      "y": 10,
      "z": 12,
      "name": "Rock_Sandstone_Brick"
    },
    {
      "x": -12,
      "y": 11,
      "z": 12,
      "name": "Rock_Sandstone_Brick"
    },
    {
      "x": -12,
      "y": 12,
      "z": 12,
      "name": "Rock_Sandstone"
    },
    {
      "x": -12,
      "y": 13,
      "z": 12,
      "name": "Rock_Sandstone"
    },
    {
      "x": -12,
      "y": 14,
      "z": 12,
      "name": "Rock_Sandstone"
    },
    {
      "x": -12,
      "y": 15,
      "z": 12,
      "name": "Rock_Sandstone"
    },
    {
      "x": -12,
      "y": 0,
      "z": 13,
      "name": "Rock_Sandstone"
    },
    {
      "x": -12,
      "y": 1,
      "z": 13,
      "name": "Rock_Sandstone_Brick"
    },
    {
      "x": -12,
      "y": 2,
      "z": 13,
      "name": "Rock_Sandstone_Brick"
    },
    {
      "x": -12,
      "y": 3,
      "z": 13,
      "name": "Rock_Sandstone_Brick"
    },
    {
      "x": -12,
      "y": 4,
      "z": 13,
      "name": "Rock_Sandstone_Brick"
    },
    {
      "x": -12,
      "y": 5,
      "z": 13,
      "name": "Rock_Sandstone_Brick"
    },
    {
      "x": -12,
      "y": 6,
      "z": 13,
      "name": "Rock_Sandstone_Brick"
    },
    {
      "x": -12,
      "y": 7,
      "z": 13,
      "name": "Rock_Sandstone_Brick"
    },
    {
      "x": -12,
      "y": 8,
      "z": 13,
      "name": "Rock_Sandstone_Brick"
    },
    {
      "x": -12,
      "y": 9,
      "z": 13,
      "name": "Rock_Sandstone_Brick"
    },
    {
      "x": -12,
      "y": 10,
      "z": 13,
      "name": "Rock_Sandstone_Brick"
    },
    {
      "x": -12,
      "y": 11,
      "z": 13,
      "name": "Rock_Sandstone_Brick"
    },
    {
      "x": -12,
      "y": 12,
      "z": 13,
      "name": "Rock_Sandstone"
    },
    {
      "x": -12,
      "y": 13,
      "z": 13,
      "name": "Rock_Sandstone"
    },
    {
      "x": -12,
      "y": 14,
      "z": 13,
      "name": "Rock_Sandstone"
    },
    {
      "x": -12,
      "y": 15,
      "z": 13,
      "name": "Rock_Sandstone"
    },
    {
      "x": -11,
      "y": 0,
      "z": -13,
      "name": "Rock_Sandstone"
    },
    {
      "x": -11,
      "y": 1,
      "z": -13,
      "name": "Rock_Sandstone_Brick"
    },
    {
      "x": -11,
      "y": 2,
      "z": -13,
      "name": "Rock_Sandstone_Brick"
    },
    {
      "x": -11,
      "y": 3,
      "z": -13,
      "name": "Rock_Sandstone_Brick"
    },
    {
      "x": -11,
      "y": 4,
      "z": -13,
      "name": "Rock_Sandstone_Brick"
    },
    {
      "x": -11,
      "y": 5,
      "z": -13,
      "name": "Rock_Sandstone_Brick"
    },
    {
      "x": -11,
      "y": 6,
      "z": -13,
      "name": "Rock_Sandstone_Brick"
    },
    {
      "x": -11,
      "y": 7,
      "z": -13,
      "name": "Rock_Sandstone_Brick"
    },
    {
      "x": -11,
      "y": 8,
      "z": -13,
      "name": "Rock_Sandstone_Brick"
    },
    {
      "x": -11,
      "y": 9,
      "z": -13,
      "name": "Rock_Sandstone_Brick"
    },
    {
      "x": -11,
      "y": 10,
      "z": -13,
      "name": "Rock_Sandstone_Brick"
    },
    {
      "x": -11,
      "y": 11,
      "z": -13,
      "name": "Rock_Sandstone_Brick"
    },
    {
      "x": -11,
      "y": 12,
      "z": -13,
      "name": "Rock_Sandstone"
    },
    {
      "x": -11,
      "y": 13,
      "z": -13,
      "name": "Rock_Sandstone"
    },
    {
      "x": -11,
      "y": 14,
      "z": -13,
      "name": "Rock_Sandstone"
    },
    {
      "x": -11,
      "y": 15,
      "z": -13,
      "name": "Rock_Sandstone"
    },
    {
      "x": -11,
      "y": 0,
      "z": -12,
      "name": "Rock_Sandstone"
    },
    {
      "x": -11,
      "y": 1,
      "z": -12,
      "name": "Rock_Sandstone_Brick"
    },
    {
      "x": -11,
      "y": 2,
      "z": -12,
      "name": "Rock_Sandstone_Brick"
    },
    {
      "x": -11,
      "y": 3,
      "z": -12,
      "name": "Rock_Sandstone_Brick"
    },
    {
      "x": -11,
      "y": 4,
      "z": -12,
      "name": "Rock_Sandstone_Brick"
    },
    {
      "x": -11,
      "y": 5,
      "z": -12,
      "name": "Rock_Sandstone_Brick"
    },
    {
      "x": -11,
      "y": 6,
      "z": -12,
      "name": "Rock_Sandstone_Brick"
    },
    {
      "x": -11,
      "y": 7,
      "z": -12,
      "name": "Rock_Sandstone_Brick"
    },
    {
      "x": -11,
      "y": 8,
      "z": -12,
      "name": "Rock_Sandstone_Brick"
    },
    {
      "x": -11,
      "y": 9,
      "z": -12,
      "name": "Rock_Sandstone_Brick"
    },
    {
      "x": -11,
      "y": 10,
      "z": -12,
      "name": "Rock_Sandstone_Brick"
    },
    {
      "x": -11,
      "y": 11,
      "z": -12,
      "name": "Rock_Sandstone_Brick"
    },
    {
      "x": -11,
      "y": 12,
      "z": -12,
      "name": "Rock_Sandstone"
    },
    {
      "x": -11,
      "y": 13,
      "z": -12,
      "name": "Rock_Sandstone"
    },
    {
      "x": -11,
      "y": 14,
      "z": -12,
      "name": "Rock_Sandstone"
    },
    {
      "x": -11,
      "y": 15,
      "z": -12,
      "name": "Rock_Sandstone"
    },
    {
      "x": -11,
      "y": 0,
      "z": -11,
      "name": "Rock_Sandstone"
    },
    {
      "x": -11,
      "y": 1,
      "z": -11,
      "name": "Rock_Sandstone_Brick"
    },
    {
      "x": -11,
      "y": 2,
      "z": -11,
      "name": "Rock_Sandstone_Brick"
    },
    {
      "x": -11,
      "y": 3,
      "z": -11,
      "name": "Rock_Sandstone_Brick"
    },
    {
      "x": -11,
      "y": 4,
      "z": -11,
      "name": "Rock_Sandstone_Brick"
    },
    {
      "x": -11,
      "y": 5,
      "z": -11,
      "name": "Rock_Sandstone_Brick"
    },
    {
      "x": -11,
      "y": 6,
      "z": -11,
      "name": "Rock_Sandstone_Brick"
    },
    {
      "x": -11,
      "y": 7,
      "z": -11,
      "name": "Rock_Sandstone_Brick"
    },
    {
      "x": -11,
      "y": 8,
      "z": -11,
      "name": "Rock_Sandstone_Brick"
    },
    {
      "x": -11,
      "y": 9,
      "z": -11,
      "name": "Rock_Sandstone_Brick"
    },
    {
      "x": -11,
      "y": 10,
      "z": -11,
      "name": "Rock_Sandstone_Brick"
    },
    {
      "x": -11,
      "y": 11,
      "z": -11,
      "name": "Rock_Sandstone_Brick"
    },
    {
      "x": -11,
      "y": 12,
      "z": -11,
      "name": "Rock_Sandstone"
    },
    {
      "x": -11,
      "y": 13,
      "z": -11,
      "name": "Rock_Sandstone"
    },
    {
      "x": -11,
      "y": 14,
      "z": -11,
      "name": "Rock_Sandstone"
    },
    {
      "x": -11,
      "y": 15,
      "z": -11,
      "name": "Rock_Sandstone"
    },
    {
      "x": -11,
      "y": 0,
      "z": -10,
      "name": "Rock_Sandstone"
    },
    {
      "x": -11,
      "y": 1,
      "z": -10,
      "name": "Rock_Sandstone_Brick"
    },
    {
      "x": -11,
      "y": 2,
      "z": -10,
      "name": "Rock_Sandstone_Brick"
    },
    {
      "x": -11,
      "y": 3,
      "z": -10,
      "name": "Rock_Sandstone_Brick"
    },
    {
      "x": -11,
      "y": 4,
      "z": -10,
      "name": "Rock_Sandstone_Brick"
    },
    {
      "x": -11,
      "y": 5,
      "z": -10,
      "name": "Rock_Sandstone_Brick"
    },
    {
      "x": -11,
      "y": 6,
      "z": -10,
      "name": "Rock_Sandstone_Brick_Stairs"
    },
    {
      "x": -11,
      "y": 7,
      "z": -10,
      "name": "Empty"
    },
    {
      "x": -11,
      "y": 8,
      "z": -10,
      "name": "Empty"
    },
    {
      "x": -11,
      "y": 9,
      "z": -10,
      "name": "Empty"
    },
    {
      "x": -11,
      "y": 10,
      "z": -10,
      "name": "Rock_Sandstone_Brick_Stairs",
      "rotation": 11
    },
    {
      "x": -11,
      "y": 11,
      "z": -10,
      "name": "Rock_Sandstone_Brick"
    },
    {
      "x": -11,
      "y": 12,
      "z": -10,
      "name": "Rock_Sandstone"
    },
    {
      "x": -11,
      "y": 13,
      "z": -10,
      "name": "Rock_Sandstone"
    },
    {
      "x": -11,
      "y": 14,
      "z": -10,
      "name": "Rock_Sandstone"
    },
    {
      "x": -11,
      "y": 15,
      "z": -10,
      "name": "Rock_Sandstone"
    },
    {
      "x": -11,
      "y": 0,
      "z": -9,
      "name": "Rock_Sandstone"
    },
    {
      "x": -11,
      "y": 1,
      "z": -9,
      "name": "Rock_Sandstone_Brick"
    },
    {
      "x": -11,
      "y": 2,
      "z": -9,
      "name": "Rock_Sandstone_Brick"
    },
    {
      "x": -11,
      "y": 3,
      "z": -9,
      "name": "Rock_Sandstone_Brick"
    },
    {
      "x": -11,
      "y": 4,
      "z": -9,
      "name": "Rock_Sandstone_Brick"
    },
    {
      "x": -11,
      "y": 5,
      "z": -9,
      "name": "Rock_Sandstone_Brick_Stairs"
    },
    {
      "x": -11,
      "y": 6,
      "z": -9,
      "name": "Empty"
    },
    {
      "x": -11,
      "y": 7,
      "z": -9,
      "name": "Empty"
    },
    {
      "x": -11,
      "y": 8,
      "z": -9,
      "name": "Empty"
    },
    {
      "x": -11,
      "y": 9,
      "z": -9,
      "name": "Empty"
    },
    {
      "x": -11,
      "y": 10,
      "z": -9,
      "name": "Rock_Sandstone_Brick_Stairs",
      "rotation": 11
    },
    {
      "x": -11,
      "y": 11,
      "z": -9,
      "name": "Rock_Sandstone_Brick"
    },
    {
      "x": -11,
      "y": 12,
      "z": -9,
      "name": "Rock_Sandstone"
    },
    {
      "x": -11,
      "y": 13,
      "z": -9,
      "name": "Rock_Sandstone"
    },
    {
      "x": -11,
      "y": 14,
      "z": -9,
      "name": "Rock_Sandstone"
    },
    {
      "x": -11,
      "y": 15,
      "z": -9,
      "name": "Rock_Sandstone"
    },
    {
      "x": -11,
      "y": 0,
      "z": -8,
      "name": "Rock_Sandstone"
    },
    {
      "x": -11,
      "y": 1,
      "z": -8,
      "name": "Soil_Gravel_Sand"
    },
    {
      "x": -11,
      "y": 2,
      "z": -8,
      "name": "Empty"
    },
    {
      "x": -11,
      "y": 3,
      "z": -8,
      "name": "Empty"
    },
    {
      "x": -11,
      "y": 4,
      "z": -8,
      "name": "Empty"
    },
    {
      "x": -11,
      "y": 5,
      "z": -8,
      "name": "Empty"
    },
    {
      "x": -11,
      "y": 6,
      "z": -8,
      "name": "Empty"
    },
    {
      "x": -11,
      "y": 7,
      "z": -8,
      "name": "Empty"
    },
    {
      "x": -11,
      "y": 8,
      "z": -8,
      "name": "Empty"
    },
    {
      "x": -11,
      "y": 9,
      "z": -8,
      "name": "Empty"
    },
    {
      "x": -11,
      "y": 10,
      "z": -8,
      "name": "Rock_Sandstone_Brick_Stairs",
      "rotation": 11
    },
    {
      "x": -11,
      "y": 11,
      "z": -8,
      "name": "Rock_Sandstone_Brick"
    },
    {
      "x": -11,
      "y": 12,
      "z": -8,
      "name": "Rock_Sandstone"
    },
    {
      "x": -11,
      "y": 13,
      "z": -8,
      "name": "Rock_Sandstone"
    },
    {
      "x": -11,
      "y": 14,
      "z": -8,
      "name": "Rock_Sandstone"
    },
    {
      "x": -11,
      "y": 15,
      "z": -8,
      "name": "Rock_Sandstone"
    },
    {
      "x": -11,
      "y": 0,
      "z": -7,
      "name": "Rock_Sandstone"
    },
    {
      "x": -11,
      "y": 1,
      "z": -7,
      "name": "Soil_Gravel_Sand"
    },
    {
      "x": -11,
      "y": 2,
      "z": -7,
      "name": "Empty"
    },
    {
      "x": -11,
      "y": 3,
      "z": -7,
      "name": "Empty"
    },
    {
      "x": -11,
      "y": 4,
      "z": -7,
      "name": "Empty"
    },
    {
      "x": -11,
      "y": 5,
      "z": -7,
      "name": "Empty"
    },
    {
      "x": -11,
      "y": 6,
      "z": -7,
      "name": "Empty"
    },
    {
      "x": -11,
      "y": 7,
      "z": -7,
      "name": "Empty"
    },
    {
      "x": -11,
      "y": 8,
      "z": -7,
      "name": "Empty"
    },
    {
      "x": -11,
      "y": 9,
      "z": -7,
      "name": "Empty"
    },
    {
      "x": -11,
      "y": 10,
      "z": -7,
      "name": "Rock_Sandstone_Brick_Stairs",
      "rotation": 11
    },
    {
      "x": -11,
      "y": 11,
      "z": -7,
      "name": "Rock_Sandstone_Brick"
    },
    {
      "x": -11,
      "y": 12,
      "z": -7,
      "name": "Rock_Sandstone"
    },
    {
      "x": -11,
      "y": 13,
      "z": -7,
      "name": "Rock_Sandstone"
    },
    {
      "x": -11,
      "y": 14,
      "z": -7,
      "name": "Rock_Sandstone"
    },
    {
      "x": -11,
      "y": 15,
      "z": -7,
      "name": "Rock_Sandstone"
    },
    {
      "x": -11,
      "y": 0,
      "z": -6,
      "name": "Rock_Sandstone"
    },
    {
      "x": -11,
      "y": 1,
      "z": -6,
      "name": "Soil_Gravel_Sand"
    },
    {
      "x": -11,
      "y": 2,
      "z": -6,
      "name": "Furniture_Temple_Wind_Pot"
    },
    {
      "x": -11,
      "y": 3,
      "z": -6,
      "name": "Furniture_Temple_Wind_Pot",
      "filler": 1024
    },
    {
      "x": -11,
      "y": 4,
      "z": -6,
      "name": "Empty"
    },
    {
      "x": -11,
      "y": 5,
      "z": -6,
      "name": "Empty"
    },
    {
      "x": -11,
      "y": 6,
      "z": -6,
      "name": "Empty"
    },
    {
      "x": -11,
      "y": 7,
      "z": -6,
      "name": "Empty"
    },
    {
      "x": -11,
      "y": 8,
      "z": -6,
      "name": "Empty"
    },
    {
      "x": -11,
      "y": 9,
      "z": -6,
      "name": "Empty"
    },
    {
      "x": -11,
      "y": 10,
      "z": -6,
      "name": "Rock_Sandstone_Brick_Stairs",
      "rotation": 11
    },
    {
      "x": -11,
      "y": 11,
      "z": -6,
      "name": "Rock_Sandstone_Brick"
    },
    {
      "x": -11,
      "y": 12,
      "z": -6,
      "name": "Rock_Sandstone"
    },
    {
      "x": -11,
      "y": 13,
      "z": -6,
      "name": "Rock_Sandstone"
    },
    {
      "x": -11,
      "y": 14,
      "z": -6,
      "name": "Rock_Sandstone"
    },
    {
      "x": -11,
      "y": 15,
      "z": -6,
      "name": "Rock_Sandstone"
    },
    {
      "x": -11,
      "y": 0,
      "z": -5,
      "name": "Rock_Sandstone"
    },
    {
      "x": -11,
      "y": 1,
      "z": -5,
      "name": "Soil_Gravel_Sand"
    },
    {
      "x": -11,
      "y": 2,
      "z": -5,
      "name": "Empty"
    },
    {
      "x": -11,
      "y": 3,
      "z": -5,
      "name": "Empty"
    },
    {
      "x": -11,
      "y": 4,
      "z": -5,
      "name": "Empty"
    },
    {
      "x": -11,
      "y": 5,
      "z": -5,
      "name": "Empty"
    },
    {
      "x": -11,
      "y": 6,
      "z": -5,
      "name": "Empty"
    },
    {
      "x": -11,
      "y": 7,
      "z": -5,
      "name": "Empty"
    },
    {
      "x": -11,
      "y": 8,
      "z": -5,
      "name": "Empty"
    },
    {
      "x": -11,
      "y": 9,
      "z": -5,
      "name": "Empty"
    },
    {
      "x": -11,
      "y": 10,
      "z": -5,
      "name": "Rock_Sandstone_Brick_Stairs",
      "rotation": 11
    },
    {
      "x": -11,
      "y": 11,
      "z": -5,
      "name": "Rock_Sandstone_Brick"
    },
    {
      "x": -11,
      "y": 12,
      "z": -5,
      "name": "Rock_Sandstone"
    },
    {
      "x": -11,
      "y": 13,
      "z": -5,
      "name": "Rock_Sandstone"
    },
    {
      "x": -11,
      "y": 14,
      "z": -5,
      "name": "Rock_Sandstone"
    },
    {
      "x": -11,
      "y": 15,
      "z": -5,
      "name": "Rock_Sandstone"
    },
    {
      "x": -11,
      "y": 0,
      "z": -4,
      "name": "Rock_Sandstone"
    },
    {
      "x": -11,
      "y": 1,
      "z": -4,
      "name": "Soil_Gravel_Sand"
    },
    {
      "x": -11,
      "y": 2,
      "z": -4,
      "name": "*Furniture_Desert_Torch_State_Definitions_Off"
    },
    {
      "x": -11,
      "y": 3,
      "z": -4,
      "name": "*Furniture_Desert_Torch_State_Definitions_Off",
      "filler": 1024
    },
    {
      "x": -11,
      "y": 4,
      "z": -4,
      "name": "Empty"
    },
    {
      "x": -11,
      "y": 5,
      "z": -4,
      "name": "Empty"
    },
    {
      "x": -11,
      "y": 6,
      "z": -4,
      "name": "Empty"
    },
    {
      "x": -11,
      "y": 7,
      "z": -4,
      "name": "Empty"
    },
    {
      "x": -11,
      "y": 8,
      "z": -4,
      "name": "Empty"
    },
    {
      "x": -11,
      "y": 9,
      "z": -4,
      "name": "Empty"
    },
    {
      "x": -11,
      "y": 10,
      "z": -4,
      "name": "Rock_Sandstone_Brick_Stairs",
      "rotation": 11
    },
    {
      "x": -11,
      "y": 11,
      "z": -4,
      "name": "Rock_Sandstone_Brick"
    },
    {
      "x": -11,
      "y": 12,
      "z": -4,
      "name": "Rock_Sandstone"
    },
    {
      "x": -11,
      "y": 13,
      "z": -4,
      "name": "Rock_Sandstone"
    },
    {
      "x": -11,
      "y": 14,
      "z": -4,
      "name": "Rock_Sandstone"
    },
    {
      "x": -11,
      "y": 15,
      "z": -4,
      "name": "Rock_Sandstone"
    },
    {
      "x": -11,
      "y": 0,
      "z": -3,
      "name": "Rock_Sandstone"
    },
    {
      "x": -11,
      "y": 1,
      "z": -3,
      "name": "Soil_Gravel_Sand"
    },
    {
      "x": -11,
      "y": 2,
      "z": -3,
      "name": "Empty"
    },
    {
      "x": -11,
      "y": 3,
      "z": -3,
      "name": "Empty"
    },
    {
      "x": -11,
      "y": 4,
      "z": -3,
      "name": "Empty"
    },
    {
      "x": -11,
      "y": 5,
      "z": -3,
      "name": "Empty"
    },
    {
      "x": -11,
      "y": 6,
      "z": -3,
      "name": "Empty"
    },
    {
      "x": -11,
      "y": 7,
      "z": -3,
      "name": "Empty"
    },
    {
      "x": -11,
      "y": 8,
      "z": -3,
      "name": "Empty"
    },
    {
      "x": -11,
      "y": 9,
      "z": -3,
      "name": "Empty"
    },
    {
      "x": -11,
      "y": 10,
      "z": -3,
      "name": "Rock_Sandstone_Brick_Stairs",
      "rotation": 11
    },
    {
      "x": -11,
      "y": 11,
      "z": -3,
      "name": "Rock_Sandstone_Brick"
    },
    {
      "x": -11,
      "y": 12,
      "z": -3,
      "name": "Rock_Sandstone"
    },
    {
      "x": -11,
      "y": 13,
      "z": -3,
      "name": "Rock_Sandstone"
    },
    {
      "x": -11,
      "y": 14,
      "z": -3,
      "name": "Rock_Sandstone"
    },
    {
      "x": -11,
      "y": 15,
      "z": -3,
      "name": "Rock_Sandstone"
    },
    {
      "x": -11,
      "y": 0,
      "z": -2,
      "name": "Rock_Sandstone"
    },
    {
      "x": -11,
      "y": 1,
      "z": -2,
      "name": "Soil_Gravel_Sand"
    },
    {
      "x": -11,
      "y": 2,
      "z": -2,
      "name": "Empty"
    },
    {
      "x": -11,
      "y": 3,
      "z": -2,
      "name": "Empty"
    },
    {
      "x": -11,
      "y": 4,
      "z": -2,
      "name": "Empty"
    },
    {
      "x": -11,
      "y": 5,
      "z": -2,
      "name": "Empty"
    },
    {
      "x": -11,
      "y": 6,
      "z": -2,
      "name": "Empty"
    },
    {
      "x": -11,
      "y": 7,
      "z": -2,
      "name": "Empty"
    },
    {
      "x": -11,
      "y": 8,
      "z": -2,
      "name": "Empty"
    },
    {
      "x": -11,
      "y": 9,
      "z": -2,
      "name": "Empty"
    },
    {
      "x": -11,
      "y": 10,
      "z": -2,
      "name": "Rock_Sandstone_Brick_Stairs",
      "rotation": 11
    },
    {
      "x": -11,
      "y": 11,
      "z": -2,
      "name": "Rock_Sandstone_Brick"
    },
    {
      "x": -11,
      "y": 12,
      "z": -2,
      "name": "Rock_Sandstone"
    },
    {
      "x": -11,
      "y": 13,
      "z": -2,
      "name": "Rock_Sandstone"
    },
    {
      "x": -11,
      "y": 14,
      "z": -2,
      "name": "Rock_Sandstone"
    },
    {
      "x": -11,
      "y": 15,
      "z": -2,
      "name": "Rock_Sandstone"
    },
    {
      "x": -11,
      "y": 0,
      "z": -1,
      "name": "Rock_Sandstone"
    },
    {
      "x": -11,
      "y": 1,
      "z": -1,
      "name": "Soil_Gravel_Sand"
    },
    {
      "x": -11,
      "y": 2,
      "z": -1,
      "name": "Empty"
    },
    {
      "x": -11,
      "y": 3,
      "z": -1,
      "name": "Empty"
    },
    {
      "x": -11,
      "y": 4,
      "z": -1,
      "name": "Empty"
    },
    {
      "x": -11,
      "y": 5,
      "z": -1,
      "name": "Empty"
    },
    {
      "x": -11,
      "y": 6,
      "z": -1,
      "name": "Empty"
    },
    {
      "x": -11,
      "y": 7,
      "z": -1,
      "name": "Empty"
    },
    {
      "x": -11,
      "y": 8,
      "z": -1,
      "name": "Empty"
    },
    {
      "x": -11,
      "y": 9,
      "z": -1,
      "name": "Empty"
    },
    {
      "x": -11,
      "y": 10,
      "z": -1,
      "name": "Empty"
    },
    {
      "x": -11,
      "y": 11,
      "z": -1,
      "name": "Empty"
    },
    {
      "x": -11,
      "y": 12,
      "z": -1,
      "name": "Rock_Sandstone"
    },
    {
      "x": -11,
      "y": 13,
      "z": -1,
      "name": "Rock_Sandstone"
    },
    {
      "x": -11,
      "y": 14,
      "z": -1,
      "name": "Rock_Sandstone"
    },
    {
      "x": -11,
      "y": 15,
      "z": -1,
      "name": "Rock_Sandstone"
    },
    {
      "x": -11,
      "y": 0,
      "z": 0,
      "name": "Rock_Sandstone"
    },
    {
      "x": -11,
      "y": 1,
      "z": 0,
      "name": "Soil_Gravel_Sand"
    },
    {
      "x": -11,
      "y": 2,
      "z": 0,
      "name": "Empty"
    },
    {
      "x": -11,
      "y": 3,
      "z": 0,
      "name": "Empty"
    },
    {
      "x": -11,
      "y": 4,
      "z": 0,
      "name": "Empty"
    },
    {
      "x": -11,
      "y": 5,
      "z": 0,
      "name": "Empty"
    },
    {
      "x": -11,
      "y": 6,
      "z": 0,
      "name": "Empty"
    },
    {
      "x": -11,
      "y": 7,
      "z": 0,
      "name": "Empty"
    },
    {
      "x": -11,
      "y": 8,
      "z": 0,
      "name": "Empty"
    },
    {
      "x": -11,
      "y": 9,
      "z": 0,
      "name": "Empty"
    },
    {
      "x": -11,
      "y": 10,
      "z": 0,
      "name": "Empty"
    },
    {
      "x": -11,
      "y": 11,
      "z": 0,
      "name": "Empty"
    },
    {
      "x": -11,
      "y": 12,
      "z": 0,
