{
  "version": 8,
  "blockIdVersion": 8,
  "anchorX": 0,
  "anchorY": 4,
  "anchorZ": 0,
  "blocks": [
    {
      "x": -3,
      "y": 16,
      "z": -1,
      "name": "Plant_Leaves_Cedar"
    },
    {
      "x": -3,
      "y": 16,
      "z": 0,
      "name": "Plant_Leaves_Cedar"
    },
    {
      "x": -2,
      "y": 16,
      "z": -1,
      "name": "Plant_Leaves_Cedar"
    },
    {
      "x": -2,
      "y": 17,
      "z": -1,
      "name": "Plant_Leaves_Cedar"
    },
    {
      "x": -2,
      "y": 20,
      "z": -1,
      "name": "Plant_Leaves_Cedar"
    },
    {
      "x": -2,
      "y": 15,
      "z": 0,
      "name": "Plant_Leaves_Cedar"
    },
    {
      "x": -2,
      "y": 16,
      "z": 0,
      "name": "Plant_Leaves_Cedar"
    },
    {
      "x": -2,
      "y": 17,
      "z": 0,
      "name": "Plant_Leaves_Cedar"
    },
    {
      "x": -2,
      "y": 20,
      "z": 0,
      "name": "Plant_Leaves_Cedar"
    },
    {
      "x": -2,
      "y": 21,
      "z": 0,
      "name": "Plant_Leaves_Cedar"
    },
    {
      "x": -2,
      "y": 15,
      "z": 1,
      "name": "Plant_Leaves_Cedar"
    },
    {
      "x": -2,
      "y": 16,
      "z": 1,
      "name": "Plant_Leaves_Cedar"
    },
    {
      "x": -2,
      "y": 20,
      "z": 1,
      "name": "Plant_Leaves_Cedar"
    },
    {
      "x": -2,
      "y": 16,
      "z": 2,
      "name": "Plant_Leaves_Cedar"
    },
    {
      "x": -1,
      "y": 16,
      "z": -3,
      "name": "Plant_Leaves_Cedar"
    },
    {
      "x": -1,
      "y": 16,
      "z": -1,
      "name": "Plant_Leaves_Cedar"
    },
    {
      "x": -1,
      "y": 17,
      "z": -1,
      "name": "Plant_Leaves_Cedar"
    },
    {
      "x": -1,
      "y": 20,
      "z": -1,
      "name": "Plant_Leaves_Cedar"
    },
    {
      "x": -1,
      "y": 24,
      "z": -1,
      "name": "Plant_Leaves_Cedar"
    },
    {
      "x": -1,
      "y": 25,
      "z": -1,
      "name": "Plant_Leaves_Cedar"
    },
    {
      "x": -1,
      "y": 9,
      "z": 0,
      "name": "Wood_Cedar_Branch_Long",
      "rotation": 5
    },
    {
      "x": -1,
      "y": 13,
      "z": 0,
      "name": "Wood_Cedar_Branch_Long",
      "rotation": 5
    },
    {
      "x": -1,
      "y": 16,
      "z": 0,
      "name": "Wood_Cedar_Branch_Long",
      "rotation": 5
    },
    {
      "x": -1,
      "y": 17,
      "z": 0,
      "name": "Plant_Leaves_Cedar"
    },
    {
      "x": -1,
      "y": 18,
      "z": 0,
      "name": "Plant_Leaves_Cedar"
    },
    {
      "x": -1,
      "y": 20,
      "z": 0,
      "name": "Wood_Cedar_Branch_Long",
      "rotation": 5
    },
    {
      "x": -1,
      "y": 21,
      "z": 0,
      "name": "Plant_Leaves_Cedar"
    },
    {
      "x": -1,
      "y": 22,
      "z": 0,
      "name": "Plant_Leaves_Cedar"
    },
    {
      "x": -1,
      "y": 24,
      "z": 0,
      "name": "Plant_Leaves_Cedar"
    },
    {
      "x": -1,
      "y": 25,
      "z": 0,
      "name": "Plant_Leaves_Cedar"
    },
    {
      "x": -1,
      "y": 27,
      "z": 0,
      "name": "Plant_Leaves_Cedar"
    },
    {
      "x": -1,
      "y": 28,
      "z": 0,
      "name": "Plant_Leaves_Cedar"
    },
    {
      "x": -1,
      "y": 15,
      "z": 1,
      "name": "Plant_Leaves_Cedar"
    },
    {
      "x": -1,
      "y": 16,
      "z": 1,
      "name": "Plant_Leaves_Cedar"
    },
    {
      "x": -1,
      "y": 20,
      "z": 1,
      "name": "Plant_Leaves_Cedar"
    },
    {
      "x": -1,
      "y": 21,
      "z": 1,
      "name": "Plant_Leaves_Cedar"
    },
    {
      "x": -1,
      "y": 24,
      "z": 1,
      "name": "Plant_Leaves_Cedar"
    },
    {
      "x": -1,
      "y": 25,
      "z": 1,
      "name": "Plant_Leaves_Cedar"
    },
    {
      "x": -1,
      "y": 26,
      "z": 1,
      "name": "Plant_Leaves_Cedar"
    },
    {
      "x": -1,
      "y": 20,
      "z": 2,
      "name": "Plant_Leaves_Cedar"
    },
    {
      "x": -1,
      "y": 16,
      "z": 3,
      "name": "Plant_Leaves_Cedar"
    },
    {
      "x": 0,
      "y": 16,
      "z": -3,
      "name": "Plant_Leaves_Cedar"
    },
    {
      "x": 0,
      "y": 17,
      "z": -3,
      "name": "Plant_Leaves_Cedar"
    },
    {
      "x": 0,
      "y": 16,
      "z": -2,
      "name": "Plant_Leaves_Cedar"
    },
    {
      "x": 0,
      "y": 17,
      "z": -2,
      "name": "Plant_Leaves_Cedar"
    },
    {
      "x": 0,
      "y": 18,
      "z": -2,
      "name": "Plant_Leaves_Cedar"
    },
    {
      "x": 0,
      "y": 20,
      "z": -2,
      "name": "Plant_Leaves_Cedar"
    },
    {
      "x": 0,
      "y": 21,
      "z": -2,
      "name": "Plant_Leaves_Cedar"
    },
    {
      "x": 0,
      "y": 8,
      "z": -1,
      "name": "Wood_Cedar_Branch_Long",
      "rotation": 4
    },
    {
      "x": 0,
      "y": 12,
      "z": -1,
      "name": "Wood_Cedar_Branch_Long",
      "rotation": 4
    },
    {
      "x": 0,
      "y": 16,
      "z": -1,
      "name": "Plant_Leaves_Cedar"
    },
    {
      "x": 0,
      "y": 17,
      "z": -1,
      "name": "Wood_Cedar_Branch_Long",
      "rotation": 4
    },
    {
      "x": 0,
      "y": 18,
      "z": -1,
      "name": "Wood_Cedar_Branch_Short",
      "rotation": 2
    },
    {
      "x": 0,
      "y": 21,
      "z": -1,
      "name": "Wood_Cedar_Branch_Long",
      "rotation": 4
    },
    {
      "x": 0,
      "y": 22,
      "z": -1,
      "name": "Plant_Leaves_Cedar"
    },
    {
      "x": 0,
      "y": 23,
      "z": -1,
      "name": "Plant_Leaves_Cedar"
    },
    {
      "x": 0,
      "y": 24,
      "z": -1,
      "name": "Plant_Leaves_Cedar"
    },
    {
      "x": 0,
      "y": 25,
      "z": -1,
      "name": "Plant_Leaves_Cedar"
    },
    {
      "x": 0,
      "y": 26,
      "z": -1,
      "name": "Plant_Leaves_Cedar"
    },
    {
      "x": 0,
      "y": 27,
      "z": -1,
      "name": "Plant_Leaves_Cedar"
    },
    {
      "x": 0,
      "y": 28,
      "z": -1,
      "name": "Plant_Leaves_Cedar"
    },
    {
      "x": 0,
      "y": 29,
      "z": -1,
      "name": "Plant_Leaves_Cedar"
    },
    {
      "x": 0,
      "y": 1,
      "z": 0,
      "name": "Wood_Cedar_Roots"
    },
    {
      "x": 0,
      "y": 2,
      "z": 0,
      "name": "Wood_Cedar_Trunk"
    },
    {
      "x": 0,
      "y": 3,
      "z": 0,
      "name": "Wood_Cedar_Trunk"
    },
    {
      "x": 0,
      "y": 4,
      "z": 0,
      "name": "Wood_Cedar_Trunk_Full"
    },
    {
      "x": 0,
      "y": 5,
      "z": 0,
      "name": "Wood_Cedar_Trunk"
    },
    {
      "x": 0,
      "y": 6,
      "z": 0,
      "name": "Wood_Cedar_Trunk"
    },
    {
      "x": 0,
      "y": 7,
      "z": 0,
      "name": "Wood_Cedar_Trunk"
    },
    {
      "x": 0,
      "y": 8,
      "z": 0,
      "name": "Wood_Cedar_Trunk"
    },
    {
      "x": 0,
      "y": 9,
      "z": 0,
      "name": "Wood_Cedar_Trunk"
    },
    {
      "x": 0,
      "y": 10,
      "z": 0,
      "name": "Wood_Cedar_Trunk"
    },
    {
      "x": 0,
      "y": 11,
      "z": 0,
      "name": "Wood_Cedar_Trunk"
    },
    {
      "x": 0,
      "y": 12,
      "z": 0,
      "name": "Wood_Cedar_Trunk"
    },
    {
      "x": 0,
      "y": 13,
      "z": 0,
      "name": "Wood_Cedar_Trunk"
    },
    {
      "x": 0,
      "y": 14,
      "z": 0,
      "name": "Wood_Cedar_Trunk"
    },
    {
      "x": 0,
      "y": 15,
      "z": 0,
      "name": "Wood_Cedar_Trunk"
    },
    {
      "x": 0,
      "y": 16,
      "z": 0,
      "name": "Wood_Cedar_Trunk"
    },
    {
      "x": 0,
      "y": 17,
      "z": 0,
      "name": "Wood_Cedar_Trunk"
    },
    {
      "x": 0,
      "y": 18,
      "z": 0,
      "name": "Wood_Cedar_Trunk"
    },
    {
      "x": 0,
      "y": 19,
      "z": 0,
      "name": "Wood_Cedar_Trunk"
    },
    {
      "x": 0,
      "y": 20,
      "z": 0,
      "name": "Wood_Cedar_Trunk"
    },
    {
      "x": 0,
      "y": 21,
      "z": 0,
      "name": "Wood_Cedar_Trunk"
    },
    {
      "x": 0,
      "y": 22,
      "z": 0,
      "name": "Wood_Cedar_Trunk"
    },
    {
      "x": 0,
      "y": 23,
      "z": 0,
      "name": "Wood_Cedar_Trunk"
    },
    {
      "x": 0,
      "y": 24,
      "z": 0,
      "name": "Wood_Cedar_Trunk"
    },
    {
      "x": 0,
      "y": 25,
      "z": 0,
      "name": "Wood_Cedar_Branch_Long"
    },
    {
      "x": 0,
      "y": 26,
      "z": 0,
      "name": "Wood_Cedar_Branch_Long"
    },
    {
      "x": 0,
      "y": 27,
      "z": 0,
      "name": "Wood_Cedar_Branch_Long"
    },
    {
      "x": 0,
      "y": 28,
      "z": 0,
      "name": "Plant_Leaves_Cedar"
    },
    {
      "x": 0,
      "y": 29,
      "z": 0,
      "name": "Plant_Leaves_Cedar"
    },
    {
      "x": 0,
      "y": 30,
      "z": 0,
      "name": "Plant_Leaves_Cedar"
    },
    {
      "x": 0,
      "y": 0,
      "z": 1,
      "name": "Wood_Cedar_Roots"
    },
    {
      "x": 0,
      "y": 1,
      "z": 1,
      "name": "Wood_Cedar_Trunk"
    },
    {
      "x": 0,
      "y": 2,
      "z": 1,
      "name": "Wood_Cedar_Trunk"
    },
    {
      "x": 0,
      "y": 3,
      "z": 1,
      "name": "Wood_Cedar_Trunk"
    },
    {
      "x": 0,
      "y": 4,
      "z": 1,
      "name": "Wood_Cedar_Trunk_Full"
    },
    {
      "x": 0,
      "y": 9,
      "z": 1,
      "name": "Wood_Cedar_Branch_Long",
      "rotation": 4
    },
    {
      "x": 0,
      "y": 13,
      "z": 1,
      "name": "Wood_Cedar_Branch_Long",
      "rotation": 4
    },
    {
      "x": 0,
      "y": 16,
      "z": 1,
      "name": "Wood_Cedar_Branch_Long",
      "rotation": 4
    },
    {
      "x": 0,
      "y": 18,
      "z": 1,
      "name": "Plant_Leaves_Cedar"
    },
    {
      "x": 0,
      "y": 20,
      "z": 1,
      "name": "Wood_Cedar_Branch_Long",
      "rotation": 4
    },
    {
      "x": 0,
      "y": 21,
      "z": 1,
      "name": "Plant_Leaves_Cedar"
    },
    {
      "x": 0,
      "y": 22,
      "z": 1,
      "name": "Plant_Leaves_Cedar"
    },
    {
      "x": 0,
      "y": 24,
      "z": 1,
      "name": "Plant_Leaves_Cedar"
    },
    {
      "x": 0,
      "y": 25,
      "z": 1,
      "name": "Plant_Leaves_Cedar"
    },
    {
      "x": 0,
      "y": 15,
      "z": 2,
      "name": "Plant_Leaves_Cedar"
    },
    {
      "x": 0,
      "y": 16,
      "z": 2,
      "name": "Plant_Leaves_Cedar"
    },
    {
      "x": 0,
      "y": 17,
      "z": 2,
      "name": "Plant_Leaves_Cedar"
    },
    {
      "x": 0,
      "y": 20,
      "z": 2,
      "name": "Plant_Leaves_Cedar"
    },
    {
      "x": 0,
      "y": 21,
      "z": 2,
      "name": "Plant_Leaves_Cedar"
    },
    {
      "x": 0,
      "y": 16,
      "z": 3,
      "name": "Plant_Leaves_Cedar"
    },
    {
      "x": 0,
      "y": 17,
      "z": 3,
      "name": "Plant_Leaves_Cedar"
    },
    {
      "x": 1,
      "y": 16,
      "z": -3,
      "name": "Plant_Leaves_Cedar"
    },
    {
      "x": 1,
      "y": 16,
      "z": -2,
      "name": "Plant_Leaves_Cedar"
    },
    {
      "x": 1,
      "y": 17,
      "z": -2,
      "name": "Plant_Leaves_Cedar"
    },
    {
      "x": 1,
      "y": 20,
      "z": -2,
      "name": "Plant_Leaves_Cedar"
    },
    {
      "x": 1,
      "y": 21,
      "z": -2,
      "name": "Plant_Leaves_Cedar"
    },
    {
      "x": 1,
      "y": 18,
      "z": -1,
      "name": "Plant_Leaves_Cedar"
    },
    {
      "x": 1,
      "y": 21,
      "z": -1,
      "name": "Plant_Leaves_Cedar"
    },
    {
      "x": 1,
      "y": 25,
      "z": -1,
      "name": "Plant_Leaves_Cedar"
    },
    {
      "x": 1,
      "y": 26,
      "z": -1,
      "name": "Plant_Leaves_Cedar"
    },
    {
      "x": 1,
      "y": 7,
      "z": 0,
      "name": "Wood_Cedar_Branch_Short",
      "rotation": 1
    },
    {
      "x": 1,
      "y": 9,
      "z": 0,
      "name": "Wood_Cedar_Branch_Long",
      "rotation": 5
    },
    {
      "x": 1,
      "y": 12,
      "z": 0,
      "name": "Wood_Cedar_Branch_Long",
      "rotation": 5
    },
    {
      "x": 1,
      "y": 17,
      "z": 0,
      "name": "Wood_Cedar_Branch_Long",
      "rotation": 5
    },
    {
      "x": 1,
      "y": 18,
      "z": 0,
      "name": "Plant_Leaves_Cedar"
    },
    {
      "x": 1,
      "y": 20,
      "z": 0,
      "name": "Plant_Leaves_Cedar"
    },
    {
      "x": 1,
      "y": 21,
      "z": 0,
      "name": "Plant_Leaves_Cedar"
    },
    {
      "x": 1,
      "y": 22,
      "z": 0,
      "name": "Plant_Leaves_Cedar"
    },
    {
      "x": 1,
      "y": 24,
      "z": 0,
      "name": "Plant_Leaves_Cedar"
    },
    {
      "x": 1,
      "y": 25,
      "z": 0,
      "name": "Plant_Leaves_Cedar"
    },
    {
      "x": 1,
      "y": 26,
      "z": 0,
      "name": "Plant_Leaves_Cedar"
    },
    {
      "x": 1,
      "y": 27,
      "z": 0,
      "name": "Plant_Leaves_Cedar"
    },
    {
      "x": 1,
      "y": 18,
      "z": 1,
      "name": "Plant_Leaves_Cedar"
    },
    {
      "x": 1,
      "y": 21,
      "z": 1,
      "name": "Plant_Leaves_Cedar"
    },
    {
      "x": 1,
      "y": 24,
      "z": 1,
      "name": "Plant_Leaves_Cedar"
    },
    {
      "x": 1,
      "y": 16,
      "z": 3,
      "name": "Plant_Leaves_Cedar"
    },
    {
      "x": 2,
      "y": 16,
      "z": -1,
      "name": "Plant_Leaves_Cedar"
    },
    {
      "x": 2,
      "y": 20,
      "z": -1,
      "name": "Plant_Leaves_Cedar"
    },
    {
      "x": 2,
      "y": 16,
      "z": 0,
      "name": "Plant_Leaves_Cedar"
    },
    {
      "x": 2,
      "y": 17,
      "z": 0,
      "name": "Plant_Leaves_Cedar"
    },
    {
      "x": 2,
      "y": 17,
      "z": 1,
      "name": "Plant_Leaves_Cedar"
    }
  ]
}