{
  "version": 8,
  "blockIdVersion": 8,
  "anchorX": 1,
  "anchorY": 7,
  "anchorZ": -5,
  "blocks": [
    {
      "x": -5,
      "y": 6,
      "z": -5,
      "name": "Rock_Basalt_Cobble"
    },
    {
      "x": -5,
      "y": 7,
      "z": -5,
      "name": "Rock_Basalt_Cobble"
    },
    {
      "x": -5,
      "y": 8,
      "z": -5,
      "name": "Rock_Basalt_Cobble"
    },
    {
      "x": -5,
      "y": 9,
      "z": -5,
      "name": "Rock_Basalt_Cobble"
    },
    {
      "x": -5,
      "y": 10,
      "z": -5,
      "name": "Rock_Basalt_Cobble"
    },
    {
      "x": -5,
      "y": 11,
      "z": -5,
      "name": "Rock_Basalt_Cobble"
    },
    {
      "x": -5,
      "y": 12,
      "z": -5,
      "name": "Rock_Basalt_Cobble"
    },
    {
      "x": -5,
      "y": 6,
      "z": -4,
      "name": "Rock_Basalt_Cobble"
    },
    {
      "x": -5,
      "y": 7,
      "z": -4,
      "name": "Rock_Basalt_Cobble"
    },
    {
      "x": -5,
      "y": 8,
      "z": -4,
      "name": "Rock_Basalt_Cobble"
    },
    {
      "x": -5,
      "y": 9,
      "z": -4,
      "name": "Rock_Basalt_Cobble"
    },
    {
      "x": -5,
      "y": 10,
      "z": -4,
      "name": "Rock_Basalt_Cobble"
    },
    {
      "x": -5,
      "y": 11,
      "z": -4,
      "name": "Rock_Basalt_Cobble"
    },
    {
      "x": -5,
      "y": 12,
      "z": -4,
      "name": "Rock_Basalt_Cobble"
    },
    {
      "x": -5,
      "y": 6,
      "z": -3,
      "name": "Rock_Basalt_Cobble"
    },
    {
      "x": -5,
      "y": 7,
      "z": -3,
      "name": "Rock_Basalt_Cobble"
    },
    {
      "x": -5,
      "y": 8,
      "z": -3,
      "name": "Rock_Basalt_Cobble"
    },
    {
      "x": -5,
      "y": 9,
      "z": -3,
      "name": "Rock_Basalt_Cobble"
    },
    {
      "x": -5,
      "y": 10,
      "z": -3,
      "name": "Rock_Basalt_Cobble"
    },
    {
      "x": -5,
      "y": 11,
      "z": -3,
      "name": "Rock_Basalt_Cobble"
    },
    {
      "x": -5,
      "y": 12,
      "z": -3,
      "name": "Rock_Basalt_Cobble"
    },
    {
      "x": -5,
      "y": 6,
      "z": -2,
      "name": "Rock_Basalt_Cobble"
    },
    {
      "x": -5,
      "y": 7,
      "z": -2,
      "name": "Rock_Basalt_Cobble"
    },
    {
      "x": -5,
      "y": 8,
      "z": -2,
      "name": "Rock_Basalt_Cobble"
    },
    {
      "x": -5,
      "y": 9,
      "z": -2,
      "name": "Rock_Basalt_Cobble"
    },
    {
      "x": -5,
      "y": 10,
      "z": -2,
      "name": "Rock_Basalt_Cobble"
    },
    {
      "x": -5,
      "y": 11,
      "z": -2,
      "name": "Rock_Basalt_Cobble"
    },
    {
      "x": -5,
      "y": 12,
      "z": -2,
      "name": "Rock_Basalt_Cobble"
    },
    {
      "x": -5,
      "y": 6,
      "z": -1,
      "name": "Rock_Basalt_Cobble"
    },
    {
      "x": -5,
      "y": 7,
      "z": -1,
      "name": "Rock_Basalt_Cobble"
    },
    {
      "x": -5,
      "y": 8,
      "z": -1,
      "name": "Rock_Basalt_Cobble"
    },
    {
      "x": -5,
      "y": 9,
      "z": -1,
      "name": "Rock_Basalt_Cobble"
    },
    {
      "x": -5,
      "y": 10,
      "z": -1,
      "name": "Rock_Basalt_Cobble"
    },
    {
      "x": -5,
      "y": 11,
      "z": -1,
      "name": "Rock_Basalt_Cobble"
    },
    {
      "x": -5,
      "y": 12,
      "z": -1,
      "name": "Rock_Basalt_Cobble"
    },
    {
      "x": -5,
      "y": 6,
      "z": 0,
      "name": "Rock_Basalt_Cobble"
    },
    {
      "x": -5,
      "y": 7,
      "z": 0,
      "name": "Rock_Basalt_Cobble"
    },
    {
      "x": -5,
      "y": 8,
      "z": 0,
      "name": "Rock_Basalt_Cobble"
    },
    {
      "x": -5,
      "y": 9,
      "z": 0,
      "name": "Rock_Basalt_Cobble"
    },
    {
      "x": -5,
      "y": 10,
      "z": 0,
      "name": "Rock_Basalt_Cobble"
    },
    {
      "x": -5,
      "y": 11,
      "z": 0,
      "name": "Rock_Basalt_Cobble"
    },
    {
      "x": -5,
      "y": 12,
      "z": 0,
      "name": "Rock_Basalt_Cobble"
    },
    {
      "x": -5,
      "y": 6,
      "z": 1,
      "name": "Rock_Basalt_Cobble"
    },
    {
      "x": -5,
      "y": 7,
      "z": 1,
      "name": "Rock_Basalt_Cobble"
    },
    {
      "x": -5,
      "y": 8,
      "z": 1,
      "name": "Rock_Basalt_Cobble"
    },
    {
      "x": -5,
      "y": 9,
      "z": 1,
      "name": "Rock_Basalt_Cobble"
    },
    {
      "x": -5,
      "y": 10,
      "z": 1,
      "name": "Rock_Basalt_Cobble"
    },
    {
      "x": -5,
      "y": 11,
      "z": 1,
      "name": "Rock_Basalt_Cobble"
    },
    {
      "x": -5,
      "y": 12,
      "z": 1,
      "name": "Rock_Basalt_Cobble"
    },
    {
      "x": -5,
      "y": 6,
      "z": 2,
      "name": "Rock_Basalt_Cobble"
    },
    {
      "x": -5,
      "y": 7,
      "z": 2,
      "name": "Rock_Basalt_Cobble"
    },
    {
      "x": -5,
      "y": 8,
      "z": 2,
      "name": "Rock_Basalt_Cobble"
    },
    {
      "x": -5,
      "y": 9,
      "z": 2,
      "name": "Rock_Basalt_Cobble"
    },
    {
      "x": -5,
      "y": 10,
      "z": 2,
      "name": "Rock_Basalt_Cobble"
    },
    {
      "x": -5,
      "y": 11,
      "z": 2,
      "name": "Rock_Basalt_Cobble"
    },
    {
      "x": -5,
      "y": 12,
      "z": 2,
      "name": "Rock_Basalt_Cobble"
    },
    {
      "x": -5,
      "y": 6,
      "z": 3,
      "name": "Rock_Basalt_Cobble"
    },
    {
      "x": -5,
      "y": 7,
      "z": 3,
      "name": "Rock_Basalt_Cobble"
    },
    {
      "x": -5,
      "y": 8,
      "z": 3,
      "name": "Rock_Basalt_Cobble"
    },
    {
      "x": -5,
      "y": 9,
      "z": 3,
      "name": "Rock_Basalt_Cobble"
    },
    {
      "x": -5,
      "y": 10,
      "z": 3,
      "name": "Rock_Basalt_Cobble"
    },
    {
      "x": -5,
      "y": 11,
      "z": 3,
      "name": "Rock_Basalt_Cobble"
    },
    {
      "x": -5,
      "y": 12,
      "z": 3,
      "name": "Rock_Basalt_Cobble"
    },
    {
      "x": -5,
      "y": 6,
      "z": 4,
      "name": "Rock_Basalt_Cobble"
    },
    {
      "x": -5,
      "y": 7,
      "z": 4,
      "name": "Rock_Basalt_Cobble"
    },
    {
      "x": -5,
      "y": 8,
      "z": 4,
      "name": "Rock_Basalt_Cobble"
    },
    {
      "x": -5,
      "y": 9,
      "z": 4,
      "name": "Rock_Basalt_Cobble"
    },
    {
      "x": -5,
      "y": 10,
      "z": 4,
      "name": "Rock_Basalt_Cobble"
    },
    {
      "x": -5,
      "y": 11,
      "z": 4,
      "name": "Rock_Basalt_Cobble"
    },
    {
      "x": -5,
      "y": 12,
      "z": 4,
      "name": "Rock_Basalt_Cobble"
    },
    {
      "x": -5,
      "y": 6,
      "z": 5,
      "name": "Rock_Basalt_Cobble"
    },
    {
      "x": -5,
      "y": 7,
      "z": 5,
      "name": "Rock_Basalt_Cobble"
    },
    {
      "x": -5,
      "y": 8,
      "z": 5,
      "name": "Rock_Basalt_Cobble"
    },
    {
      "x": -5,
      "y": 9,
      "z": 5,
      "name": "Rock_Basalt_Cobble"
    },
    {
      "x": -5,
      "y": 10,
      "z": 5,
      "name": "Rock_Basalt_Cobble"
    },
    {
      "x": -5,
      "y": 11,
      "z": 5,
      "name": "Rock_Basalt_Cobble"
    },
    {
      "x": -5,
      "y": 12,
      "z": 5,
      "name": "Rock_Basalt_Cobble"
    },
    {
      "x": -5,
      "y": 6,
      "z": 6,
      "name": "Rock_Basalt_Cobble"
    },
    {
      "x": -5,
      "y": 7,
      "z": 6,
      "name": "Rock_Basalt_Cobble"
    },
    {
      "x": -5,
      "y": 8,
      "z": 6,
      "name": "Rock_Basalt_Cobble"
    },
    {
      "x": -5,
      "y": 9,
      "z": 6,
      "name": "Rock_Basalt_Cobble"
    },
    {
      "x": -5,
      "y": 10,
      "z": 6,
      "name": "Rock_Basalt_Cobble"
    },
    {
      "x": -5,
      "y": 11,
      "z": 6,
      "name": "Rock_Basalt_Cobble"
    },
    {
      "x": -5,
      "y": 12,
      "z": 6,
      "name": "Rock_Basalt_Cobble"
    },
    {
      "x": -4,
      "y": 5,
      "z": -5,
      "name": "Rock_Basalt_Cobble"
    },
    {
      "x": -4,
      "y": 6,
      "z": -5,
      "name": "Rock_Basalt_Cobble"
    },
    {
      "x": -4,
      "y": 7,
      "z": -5,
      "name": "Rock_Basalt_Brick"
    },
    {
      "x": -4,
      "y": 8,
      "z": -5,
      "name": "Rock_Basalt_Brick"
    },
    {
      "x": -4,
      "y": 9,
      "z": -5,
      "name": "Rock_Basalt_Brick"
    },
    {
      "x": -4,
      "y": 10,
      "z": -5,
      "name": "Rock_Basalt_Brick"
    },
    {
      "x": -4,
      "y": 11,
      "z": -5,
      "name": "Rock_Basalt_Brick"
    },
    {
      "x": -4,
      "y": 12,
      "z": -5,
      "name": "Rock_Basalt_Brick"
    },
    {
      "x": -4,
      "y": 13,
      "z": -5,
      "name": "Rock_Basalt_Cobble"
    },
    {
      "x": -4,
      "y": 5,
      "z": -4,
      "name": "Rock_Basalt_Cobble"
    },
    {
      "x": -4,
      "y": 6,
      "z": -4,
      "name": "Rock_Basalt_Cobble"
    },
    {
      "x": -4,
      "y": 7,
      "z": -4,
      "name": "Rock_Basalt_Brick"
    },
    {
      "x": -4,
      "y": 8,
      "z": -4,
      "name": "Rock_Basalt_Brick"
    },
    {
      "x": -4,
      "y": 9,
      "z": -4,
      "name": "Furniture_Ancient_Crate",
      "components": {
        "Components": {
          "container": {
            "Custom": false,
            "AllowViewing": true,
            "ItemContainer": {
              "Capacity": 20,
              "Items": {}
            }
          }
        }
      },
      "rotation": 1
    },
    {
      "x": -4,
      "y": 10,
      "z": -4,
      "name": "Furniture_Ancient_Barrel"
    },
    {
      "x": -4,
      "y": 11,
      "z": -4,
      "name": "Plant_Vine_Wall_Poisoned"
    },
    {
      "x": -4,
      "y": 12,
      "z": -4,
      "name": "Rock_Basalt_Cobble_Half",
      "rotation": 5
    },
    {
      "x": -4,
      "y": 13,
      "z": -4,
      "name": "Rock_Basalt_Cobble"
    },
    {
      "x": -4,
      "y": 5,
      "z": -3,
      "name": "Rock_Basalt_Cobble"
    },
    {
      "x": -4,
      "y": 6,
      "z": -3,
      "name": "Rock_Basalt_Cobble"
    },
    {
      "x": -4,
      "y": 7,
      "z": -3,
      "name": "Rock_Basalt_Brick"
    },
    {
      "x": -4,
      "y": 8,
      "z": -3,
      "name": "Rock_Basalt_Brick"
    },
    {
      "x": -4,
      "y": 9,
      "z": -3,
      "name": "Furniture_Ancient_Barrel"
    },
    {
      "x": -4,
      "y": 10,
      "z": -3,
      "name": "Empty"
    },
    {
      "x": -4,
      "y": 11,
      "z": -3,
      "name": "Empty"
    },
    {
      "x": -4,
      "y": 12,
      "z": -3,
      "name": "Rock_Basalt_Cobble_Half",
      "rotation": 5
    },
    {
      "x": -4,
      "y": 13,
      "z": -3,
      "name": "Rock_Basalt_Cobble"
    },
    {
      "x": -4,
      "y": 5,
      "z": -2,
      "name": "Rock_Basalt_Cobble"
    },
    {
      "x": -4,
      "y": 6,
      "z": -2,
      "name": "Rock_Basalt_Cobble"
    },
    {
      "x": -4,
      "y": 7,
      "z": -2,
      "name": "Rock_Basalt_Brick"
    },
    {
      "x": -4,
      "y": 8,
      "z": -2,
      "name": "Rock_Basalt_Brick"
    },
    {
      "x": -4,
      "y": 9,
      "z": -2,
      "name": "Rock_Basalt_Brick"
    },
    {
      "x": -4,
      "y": 10,
      "z": -2,
      "name": "Rock_Basalt_Brick"
    },
    {
      "x": -4,
      "y": 11,
      "z": -2,
      "name": "Rock_Basalt_Brick"
    },
    {
      "x": -4,
      "y": 12,
      "z": -2,
      "name": "Rock_Basalt_Brick"
    },
    {
      "x": -4,
      "y": 13,
      "z": -2,
      "name": "Rock_Basalt_Cobble"
    },
    {
      "x": -4,
      "y": 5,
      "z": -1,
      "name": "Rock_Basalt_Cobble"
    },
    {
      "x": -4,
      "y": 6,
      "z": -1,
      "name": "Rock_Basalt_Cobble"
    },
    {
      "x": -4,
      "y": 7,
      "z": -1,
      "name": "Rock_Basalt_Brick"
    },
    {
      "x": -4,
      "y": 8,
      "z": -1,
      "name": "Rock_Basalt_Brick"
    },
    {
      "x": -4,
      "y": 9,
      "z": -1,
      "name": "Furniture_Ancient_Coffin",
      "filler": 992,
      "rotation": 1
    },
    {
      "x": -4,
      "y": 10,
      "z": -1,
      "name": "Deco_Iron_Bars_Platforms",
      "rotation": 1
    },
    {
      "x": -4,
      "y": 11,
      "z": -1,
      "name": "Furniture_Ancient_Coffin",
      "filler": 992,
      "rotation": 1
    },
    {
      "x": -4,
      "y": 12,
      "z": -1,
      "name": "Rock_Basalt_Cobble_Half",
      "rotation": 5
    },
    {
      "x": -4,
      "y": 13,
      "z": -1,
      "name": "Rock_Basalt_Cobble"
    },
    {
      "x": -4,
      "y": 5,
      "z": 0,
      "name": "Rock_Basalt_Cobble"
    },
    {
      "x": -4,
      "y": 6,
      "z": 0,
      "name": "Rock_Basalt_Cobble"
    },
    {
      "x": -4,
      "y": 7,
      "z": 0,
      "name": "Rock_Basalt_Brick"
    },
    {
      "x": -4,
      "y": 8,
      "z": 0,
      "name": "Rock_Basalt_Brick"
    },
    {
      "x": -4,
      "y": 9,
      "z": 0,
      "name": "Furniture_Ancient_Coffin",
      "rotation": 1
    },
    {
      "x": -4,
      "y": 10,
      "z": 0,
      "name": "Deco_Iron_Bars_Platforms",
      "rotation": 1
    },
    {
      "x": -4,
      "y": 11,
      "z": 0,
      "name": "Furniture_Ancient_Coffin",
      "rotation": 1
    },
    {
      "x": -4,
      "y": 12,
      "z": 0,
      "name": "Rock_Basalt_Cobble_Half",
      "rotation": 5
    },
    {
      "x": -4,
      "y": 13,
      "z": 0,
      "name": "Rock_Basalt_Cobble"
    },
    {
      "x": -4,
      "y": 5,
      "z": 1,
      "name": "Rock_Basalt_Cobble"
    },
    {
      "x": -4,
      "y": 6,
      "z": 1,
      "name": "Rock_Basalt_Cobble"
    },
    {
      "x": -4,
      "y": 7,
      "z": 1,
      "name": "Rock_Basalt_Brick"
    },
    {
      "x": -4,
      "y": 8,
      "z": 1,
      "name": "Rock_Basalt_Brick"
    },
    {
      "x": -4,
      "y": 10,
      "z": 1,
      "name": "Deco_Iron_Bars_Platforms",
      "rotation": 1
    },
    {
      "x": -4,
      "y": 11,
      "z": 1,
      "name": "Empty"
    },
    {
      "x": -4,
      "y": 12,
      "z": 1,
      "name": "Rock_Basalt_Cobble_Half",
      "rotation": 5
    },
    {
      "x": -4,
      "y": 13,
      "z": 1,
      "name": "Rock_Basalt_Cobble"
    },
    {
      "x": -4,
      "y": 5,
      "z": 2,
      "name": "Rock_Basalt_Cobble"
    },
    {
      "x": -4,
      "y": 6,
      "z": 2,
      "name": "Rock_Basalt_Cobble"
    },
    {
      "x": -4,
      "y": 7,
      "z": 2,
      "name": "Rock_Basalt_Brick"
    },
    {
      "x": -4,
      "y": 8,
      "z": 2,
      "name": "Rock_Basalt_Brick"
    },
    {
      "x": -4,
      "y": 9,
      "z": 2,
      "name": "Furniture_Ancient_Coffin",
      "filler": 992,
      "rotation": 1
    },
    {
      "x": -4,
      "y": 10,
      "z": 2,
      "name": "Deco_Iron_Bars_Platforms",
      "rotation": 1
    },
    {
      "x": -4,
      "y": 11,
      "z": 2,
      "name": "Furniture_Ancient_Coffin",
      "filler": 992,
      "rotation": 1
    },
    {
      "x": -4,
      "y": 12,
      "z": 2,
      "name": "Rock_Basalt_Cobble_Half",
      "rotation": 5
    },
    {
      "x": -4,
      "y": 13,
      "z": 2,
      "name": "Rock_Basalt_Cobble"
    },
    {
      "x": -4,
      "y": 5,
      "z": 3,
      "name": "Rock_Basalt_Cobble"
    },
    {
      "x": -4,
      "y": 6,
      "z": 3,
      "name": "Rock_Basalt_Cobble"
    },
    {
      "x": -4,
      "y": 7,
      "z": 3,
      "name": "Rock_Basalt_Brick"
    },
    {
      "x": -4,
      "y": 8,
      "z": 3,
      "name": "Rock_Basalt_Brick"
    },
    {
      "x": -4,
      "y": 9,
      "z": 3,
      "name": "Furniture_Ancient_Coffin",
      "rotation": 1
    },
    {
      "x": -4,
      "y": 10,
      "z": 3,
      "name": "Deco_Iron_Bars_Platforms",
      "rotation": 1
    },
    {
      "x": -4,
      "y": 11,
      "z": 3,
      "name": "Furniture_Ancient_Coffin",
      "rotation": 1
    },
    {
      "x": -4,
      "y": 12,
      "z": 3,
      "name": "Rock_Basalt_Cobble_Half",
      "rotation": 5
    },
    {
      "x": -4,
      "y": 13,
      "z": 3,
      "name": "Rock_Basalt_Cobble"
    },
    {
      "x": -4,
      "y": 5,
      "z": 4,
      "name": "Rock_Basalt_Cobble"
    },
    {
      "x": -4,
      "y": 6,
      "z": 4,
      "name": "Rock_Basalt_Cobble"
    },
    {
      "x": -4,
      "y": 7,
      "z": 4,
      "name": "Rock_Basalt_Brick"
    },
    {
      "x": -4,
      "y": 8,
      "z": 4,
      "name": "Rock_Basalt_Brick"
    },
    {
      "x": -4,
      "y": 9,
      "z": 4,
      "name": "Rock_Basalt_Brick"
    },
    {
      "x": -4,
      "y": 10,
      "z": 4,
      "name": "Rock_Basalt_Brick"
    },
    {
      "x": -4,
      "y": 11,
      "z": 4,
      "name": "Rock_Basalt_Brick"
    },
    {
      "x": -4,
      "y": 12,
      "z": 4,
      "name": "Rock_Basalt_Brick"
    },
    {
      "x": -4,
      "y": 13,
      "z": 4,
      "name": "Rock_Basalt_Cobble"
    },
    {
      "x": -4,
      "y": 5,
      "z": 5,
      "name": "Rock_Basalt_Cobble"
    },
    {
      "x": -4,
      "y": 6,
      "z": 5,
      "name": "Rock_Basalt_Cobble"
    },
    {
      "x": -4,
      "y": 7,
      "z": 5,
      "name": "Rock_Basalt_Brick"
    },
    {
      "x": -4,
      "y": 8,
      "z": 5,
      "name": "Rock_Basalt_Brick"
    },
    {
      "x": -4,
      "y": 9,
      "z": 5,
      "name": "Furniture_Ancient_Crate",
      "components": {
        "Components": {
          "container": {
            "Custom": false,
            "AllowViewing": true,
            "ItemContainer": {
              "Capacity": 20,
              "Items": {}
            }
          }
        }
      },
      "rotation": 1
    },
    {
      "x": -4,
      "y": 10,
      "z": 5,
      "name": "Furniture_Ancient_Barrel"
    },
    {
      "x": -4,
      "y": 11,
      "z": 5,
      "name": "Plant_Vine_Wall_Poisoned",
      "rotation": 2
    },
    {
      "x": -4,
      "y": 12,
      "z": 5,
      "name": "Rock_Basalt_Cobble_Half",
      "rotation": 5
    },
    {
      "x": -4,
      "y": 13,
      "z": 5,
      "name": "Rock_Basalt_Cobble"
    },
    {
      "x": -4,
      "y": 5,
      "z": 6,
      "name": "Rock_Basalt_Cobble"
    },
    {
      "x": -4,
      "y": 6,
      "z": 6,
      "name": "Rock_Basalt_Cobble"
    },
    {
      "x": -4,
      "y": 7,
      "z": 6,
      "name": "Rock_Basalt_Brick"
    },
    {
      "x": -4,
      "y": 8,
      "z": 6,
      "name": "Rock_Basalt_Brick"
    },
    {
      "x": -4,
      "y": 9,
      "z": 6,
      "name": "Rock_Basalt_Brick"
    },
    {
      "x": -4,
      "y": 10,
      "z": 6,
      "name": "Rock_Basalt_Brick"
    },
    {
      "x": -4,
      "y": 11,
      "z": 6,
      "name": "Rock_Basalt_Brick"
    },
    {
      "x": -4,
      "y": 12,
      "z": 6,
      "name": "Rock_Basalt_Brick"
    },
    {
      "x": -4,
      "y": 13,
      "z": 6,
      "name": "Rock_Basalt_Cobble"
    },
    {
      "x": -3,
      "y": 5,
      "z": -5,
      "name": "Rock_Basalt_Cobble"
    },
    {
      "x": -3,
      "y": 6,
      "z": -5,
      "name": "Rock_Basalt_Cobble"
    },
    {
      "x": -3,
      "y": 7,
      "z": -5,
      "name": "Rock_Basalt_Brick"
    },
    {
      "x": -3,
      "y": 8,
      "z": -5,
      "name": "Rock_Basalt_Brick"
    },
    {
      "x": -3,
      "y": 9,
      "z": -5,
      "name": "*Rail_State_Definitions_Corner_Left",
      "rotation": 2
    },
    {
      "x": -3,
      "y": 10,
      "z": -5,
      "name": "Empty"
    },
    {
      "x": -3,
      "y": 11,
      "z": -5,
      "name": "Rock_Basalt_Brick_Half",
      "rotation": 5
    },
    {
      "x": -3,
      "y": 12,
      "z": -5,
      "name": "Rock_Basalt_Brick"
    },
    {
      "x": -3,
      "y": 13,
      "z": -5,
      "name": "Rock_Basalt_Brick"
    },
    {
      "x": -3,
      "y": 14,
      "z": -5,
      "name": "Rock_Basalt_Cobble"
    },
    {
      "x": -3,
      "y": 5,
      "z": -4,
      "name": "Rock_Basalt_Cobble"
    },
    {
      "x": -3,
      "y": 6,
      "z": -4,
      "name": "Rock_Basalt_Cobble"
    },
    {
      "x": -3,
      "y": 7,
      "z": -4,
      "name": "Rock_Basalt_Brick"
    },
    {
      "x": -3,
      "y": 8,
      "z": -4,
      "name": "Rock_Basalt_Brick"
    },
    {
      "x": -3,
      "y": 9,
      "z": -4,
      "name": "Furniture_Ancient_Barrel"
    },
    {
      "x": -3,
      "y": 10,
      "z": -4,
      "name": "Empty"
    },
    {
      "x": -3,
      "y": 11,
      "z": -4,
      "name": "Empty"
    },
    {
      "x": -3,
      "y": 12,
      "z": -4,
      "name": "Empty"
    },
    {
      "x": -3,
      "y": 13,
      "z": -4,
      "name": "Rock_Basalt_Cobble_Half",
      "rotation": 8
    },
    {
      "x": -3,
      "y": 14,
      "z": -4,
      "name": "Rock_Basalt_Cobble"
    },
    {
      "x": -3,
      "y": 5,
      "z": -3,
      "name": "Rock_Basalt_Cobble"
    },
    {
      "x": -3,
      "y": 6,
      "z": -3,
      "name": "Rock_Basalt_Cobble"
    },
    {
      "x": -3,
      "y": 7,
      "z": -3,
      "name": "Rock_Basalt_Brick"
    },
    {
      "x": -3,
      "y": 8,
      "z": -3,
      "name": "Rock_Basalt_Brick"
    },
    {
      "x": -3,
      "y": 9,
      "z": -3,
      "name": "Furniture_Ancient_Barrel"
    },
    {
      "x": -3,
      "y": 10,
      "z": -3,
      "name": "Empty"
    },
    {
      "x": -3,
      "y": 11,
      "z": -3,
      "name": "Empty"
    },
    {
      "x": -3,
      "y": 12,
      "z": -3,
      "name": "Empty"
    },
    {
      "x": -3,
      "y": 13,
      "z": -3,
      "name": "Rock_Basalt_Cobble_Half",
      "rotation": 8
    },
    {
      "x": -3,
      "y": 14,
      "z": -3,
      "name": "Rock_Basalt_Cobble"
    },
    {
      "x": -3,
      "y": 5,
      "z": -2,
      "name": "Rock_Basalt_Cobble"
    },
    {
      "x": -3,
      "y": 6,
      "z": -2,
      "name": "Rock_Basalt_Cobble"
    },
    {
      "x": -3,
      "y": 7,
      "z": -2,
      "name": "Rock_Basalt_Brick"
    },
    {
      "x": -3,
      "y": 8,
      "z": -2,
      "name": "Rock_Basalt_Brick"
    },
    {
      "x": -3,
      "y": 9,
      "z": -2,
      "name": "*Rail_State_Definitions_Corner_Left",
      "rotation": 1
    },
    {
      "x": -3,
      "y": 10,
      "z": -2,
      "name": "Empty"
    },
    {
      "x": -3,
      "y": 11,
      "z": -2,
      "name": "Empty"
    },
    {
      "x": -3,
      "y": 12,
      "z": -2,
      "name": "Empty"
    },
    {
      "x": -3,
      "y": 13,
      "z": -2,
      "name": "Rock_Basalt_Cobble_Half",
      "rotation": 8
    },
    {
      "x": -3,
      "y": 14,
      "z": -2,
      "name": "Rock_Basalt_Cobble"
    },
    {
      "x": -3,
      "y": 5,
      "z": -1,
      "name": "Rock_Basalt_Cobble"
    },
    {
      "x": -3,
      "y": 6,
      "z": -1,
      "name": "Rock_Basalt_Cobble"
    },
    {
      "x": -3,
      "y": 7,
      "z": -1,
      "name": "Rock_Basalt_Brick"
    },
    {
      "x": -3,
      "y": 8,
      "z": -1,
      "name": "Rock_Basalt_Brick"
    },
    {
      "x": -3,
      "y": 9,
      "z": -1,
      "name": "Rail"
    },
    {
      "x": -3,
      "y": 10,
      "z": -1,
      "name": "Empty"
    },
    {
      "x": -3,
      "y": 11,
      "z": -1,
      "name": "Empty"
    },
    {
      "x": -3,
      "y": 12,
      "z": -1,
      "name": "Empty"
    },
    {
      "x": -3,
      "y": 13,
      "z": -1,
      "name": "Rock_Basalt_Cobble_Half",
      "rotation": 8
    },
    {
      "x": -3,
      "y": 14,
      "z": -1,
      "name": "Rock_Basalt_Cobble"
    },
    {
      "x": -3,
      "y": 5,
      "z": 0,
      "name": "Rock_Basalt_Cobble"
    },
    {
      "x": -3,
      "y": 6,
      "z": 0,
      "name": "Rock_Basalt_Cobble"
    },
    {
      "x": -3,
      "y": 7,
      "z": 0,
      "name": "Rock_Basalt_Brick"
    },
    {
      "x": -3,
      "y": 8,
      "z": 0,
      "name": "Rock_Basalt_Brick"
    },
    {
      "x": -3,
      "y": 9,
      "z": 0,
      "name": "Rail"
    },
    {
      "x": -3,
      "y": 10,
      "z": 0,
      "name": "Empty"
    },
    {
      "x": -3,
      "y": 11,
      "z": 0,
      "name": "Empty"
    },
    {
      "x": -3,
      "y": 12,
      "z": 0,
      "name": "Empty"
    },
    {
      "x": -3,
      "y": 13,
      "z": 0,
      "name": "Rock_Basalt_Cobble_Half",
      "rotation": 8
    },
    {
      "x": -3,
      "y": 14,
      "z": 0,
      "name": "Rock_Basalt_Cobble"
    },
    {
      "x": -3,
      "y": 5,
      "z": 1,
      "name": "Rock_Basalt_Cobble"
    },
    {
      "x": -3,
      "y": 6,
      "z": 1,
      "name": "Rock_Basalt_Cobble"
    },
    {
      "x": -3,
      "y": 7,
      "z": 1,
      "name": "Rock_Basalt_Brick"
    },
    {
      "x": -3,
      "y": 8,
      "z": 1,
      "name": "Rock_Basalt_Brick"
    },
    {
      "x": -3,
      "y": 9,
      "z": 1,
      "name": "Rail"
    },
    {
      "x": -3,
      "y": 10,
      "z": 1,
      "name": "Empty"
    },
    {
      "x": -3,
      "y": 11,
      "z": 1,
      "name": "Empty"
    },
    {
      "x": -3,
      "y": 12,
      "z": 1,
      "name": "Empty"
    },
    {
      "x": -3,
      "y": 13,
      "z": 1,
      "name": "Rock_Basalt_Cobble_Half",
      "rotation": 8
    },
    {
      "x": -3,
      "y": 14,
      "z": 1,
      "name": "Rock_Basalt_Cobble"
    },
    {
      "x": -3,
      "y": 5,
      "z": 2,
      "name": "Rock_Basalt_Cobble"
    },
    {
      "x": -3,
      "y": 6,
      "z": 2,
      "name": "Rock_Basalt_Cobble"
    },
    {
      "x": -3,
      "y": 7,
      "z": 2,
      "name": "Rock_Basalt_Brick"
    },
    {
      "x": -3,
      "y": 8,
      "z": 2,
      "name": "Rock_Basalt_Brick"
    },
    {
      "x": -3,
      "y": 9,
      "z": 2,
      "name": "Empty"
    },
    {
      "x": -3,
      "y": 10,
      "z": 2,
      "name": "Empty"
    },
    {
      "x": -3,
      "y": 11,
      "z": 2,
      "name": "Empty"
    },
    {
      "x": -3,
      "y": 12,
      "z": 2,
      "name": "Empty"
    },
    {
      "x": -3,
      "y": 13,
      "z": 2,
      "name": "Rock_Basalt_Cobble_Half",
      "rotation": 8
    },
    {
      "x": -3,
      "y": 14,
      "z": 2,
      "name": "Rock_Basalt_Cobble"
    },
    {
      "x": -3,
      "y": 5,
      "z": 3,
      "name": "Rock_Basalt_Cobble"
    },
    {
      "x": -3,
      "y": 6,
      "z": 3,
      "name": "Rock_Basalt_Cobble"
    },
    {
      "x": -3,
      "y": 7,
      "z": 3,
      "name": "Rock_Basalt_Brick"
    },
    {
      "x": -3,
      "y": 8,
      "z": 3,
      "name": "Rock_Basalt_Brick"
    },
    {
      "x": -3,
      "y": 9,
      "z": 3,
      "name": "Empty"
    },
    {
      "x": -3,
      "y": 10,
      "z": 3,
      "name": "Empty"
    },
    {
      "x": -3,
      "y": 11,
      "z": 3,
      "name": "Empty"
    },
    {
      "x": -3,
      "y": 12,
      "z": 3,
      "name": "Empty"
    },
    {
      "x": -3,
      "y": 13,
      "z": 3,
      "name": "Rock_Basalt_Cobble_Half",
      "rotation": 8
    },
    {
      "x": -3,
      "y": 14,
      "z": 3,
      "name": "Rock_Basalt_Cobble"
    },
    {
      "x": -3,
      "y": 5,
      "z": 4,
      "name": "Rock_Basalt_Cobble"
    },
    {
      "x": -3,
      "y": 6,
      "z": 4,
      "name": "Rock_Basalt_Cobble"
    },
    {
      "x": -3,
      "y": 7,
      "z": 4,
      "name": "Rock_Basalt_Brick"
    },
    {
      "x": -3,
      "y": 8,
      "z": 4,
      "name": "Rock_Basalt_Brick"
    },
    {
      "x": -3,
      "y": 9,
      "z": 4,
      "name": "*Rail_State_Definitions_Corner_Left",
      "rotation": 1
    },
    {
      "x": -3,
      "y": 10,
      "z": 4,
      "name": "Empty"
    },
    {
      "x": -3,
      "y": 11,
      "z": 4,
      "name": "Empty"
    },
    {
      "x": -3,
      "y": 12,
      "z": 4,
      "name": "Empty"
    },
    {
      "x": -3,
      "y": 13,
      "z": 4,
      "name": "Rock_Basalt_Cobble_Half",
      "rotation": 8
    },
    {
      "x": -3,
      "y": 14,
      "z": 4,
      "name": "Rock_Basalt_Cobble"
    },
    {
      "x": -3,
      "y": 5,
      "z": 5,
      "name": "Rock_Basalt_Cobble"
    },
    {
      "x": -3,
      "y": 6,
      "z": 5,
      "name": "Rock_Basalt_Cobble"
    },
    {
      "x": -3,
      "y": 7,
      "z": 5,
      "name": "Rock_Basalt_Brick"
    },
    {
      "x": -3,
      "y": 8,
      "z": 5,
      "name": "Rock_Basalt_Brick"
    },
    {
      "x": -3,
      "y": 9,
      "z": 5,
      "name": "Rail"
    },
    {
      "x": -3,
      "y": 10,
      "z": 5,
      "name": "Empty"
    },
    {
      "x": -3,
      "y": 11,
      "z": 5,
      "name": "Empty"
    },
    {
      "x": -3,
      "y": 12,
      "z": 5,
      "name": "Empty"
    },
    {
      "x": -3,
      "y": 13,
      "z": 5,
      "name": "Rock_Basalt_Cobble_Half",
      "rotation": 8
    },
    {
      "x": -3,
      "y": 14,
      "z": 5,
      "name": "Rock_Basalt_Cobble"
    },
    {
      "x": -3,
      "y": 5,
      "z": 6,
      "name": "Rock_Basalt_Cobble"
    },
    {
      "x": -3,
      "y": 6,
      "z": 6,
      "name": "Rock_Basalt_Cobble"
    },
    {
      "x": -3,
      "y": 7,
      "z": 6,
      "name": "Rock_Basalt_Brick"
    },
    {
      "x": -3,
      "y": 8,
      "z": 6,
      "name": "Rock_Basalt_Brick"
    },
    {
      "x": -3,
      "y": 9,
      "z": 6,
      "name": "Rail"
    },
    {
      "x": -3,
      "y": 10,
      "z": 6,
      "name": "Empty"
    },
    {
      "x": -3,
      "y": 11,
      "z": 6,
      "name": "Rock_Basalt_Brick_Half",
      "rotation": 5
    },
    {
      "x": -3,
      "y": 12,
      "z": 6,
      "name": "Rock_Basalt_Brick"
    },
    {
      "x": -3,
      "y": 13,
      "z": 6,
      "name": "Rock_Basalt_Brick"
    },
    {
      "x": -3,
      "y": 14,
      "z": 6,
      "name": "Rock_Basalt_Cobble"
    },
    {
      "x": -2,
      "y": 4,
      "z": -5,
      "name": "Rock_Basalt_Cobble"
    },
    {
      "x": -2,
      "y": 5,
      "z": -5,
      "name": "Rock_Basalt_Cobble"
    },
    {
      "x": -2,
      "y": 6,
      "z": -5,
      "name": "Rock_Basalt_Cobble"
    },
    {
      "x": -2,
      "y": 7,
      "z": -5,
      "name": "Rock_Basalt_Brick"
    },
    {
      "x": -2,
      "y": 8,
      "z": -5,
      "name": "Rock_Basalt_Brick"
    },
    {
      "x": -2,
      "y": 9,
      "z": -5,
      "name": "*Rail_State_Definitions_Corner_Left"
    },
    {
      "x": -2,
      "y": 10,
      "z": -5,
      "name": "Empty"
    },
    {
      "x": -2,
      "y": 11,
      "z": -5,
      "name": "Empty"
    },
    {
      "x": -2,
      "y": 12,
      "z": -5,
      "name": "Rock_Basalt_Brick_Half",
      "rotation": 8
    },
    {
      "x": -2,
      "y": 13,
      "z": -5,
      "name": "Rock_Basalt_Brick"
    },
    {
      "x": -2,
      "y": 14,
      "z": -5,
      "name": "Rock_Basalt_Cobble"
    },
    {
      "x": -2,
      "y": 4,
      "z": -4,
      "name": "Rock_Basalt_Cobble"
    },
    {
      "x": -2,
      "y": 5,
      "z": -4,
      "name": "Rock_Basalt_Cobble"
    },
    {
      "x": -2,
      "y": 6,
      "z": -4,
      "name": "Rock_Basalt_Cobble"
    },
    {
      "x": -2,
      "y": 7,
      "z": -4,
      "name": "Rock_Basalt_Brick"
    },
    {
      "x": -2,
      "y": 8,
      "z": -4,
      "name": "Rock_Basalt_Brick"
    },
    {
      "x": -2,
      "y": 9,
      "z": -4,
      "name": "Empty"
    },
    {
      "x": -2,
      "y": 10,
      "z": -4,
      "name": "Empty"
    },
    {
      "x": -2,
      "y": 11,
      "z": -4,
      "name": "Empty"
    },
    {
      "x": -2,
      "y": 12,
      "z": -4,
      "name": "Empty"
    },
    {
      "x": -2,
      "y": 13,
      "z": -4,
      "name": "Empty"
    },
    {
      "x": -2,
      "y": 14,
      "z": -4,
      "name": "Rock_Basalt_Cobble"
    },
    {
      "x": -2,
      "y": 4,
      "z": -3,
      "name": "Rock_Basalt_Cobble"
    },
    {
      "x": -2,
      "y": 5,
      "z": -3,
      "name": "Rock_Basalt_Cobble"
    },
    {
      "x": -2,
      "y": 6,
      "z": -3,
      "name": "Rock_Basalt_Cobble"
    },
    {
      "x": -2,
      "y": 7,
      "z": -3,
      "name": "Rock_Basalt_Brick"
    },
    {
      "x": -2,
      "y": 8,
      "z": -3,
      "name": "Rock_Basalt_Brick"
    },
    {
      "x": -2,
      "y": 9,
      "z": -3,
      "name": "Rail"
    },
    {
      "x": -2,
      "y": 10,
      "z": -3,
      "name": "Empty"
    },
    {
      "x": -2,
      "y": 11,
      "z": -3,
      "name": "Empty"
    },
    {
      "x": -2,
      "y": 12,
      "z": -3,
      "name": "Empty"
    },
    {
      "x": -2,
      "y": 13,
      "z": -3,
      "name": "Empty"
    },
    {
      "x": -2,
      "y": 14,
      "z": -3,
      "name": "Rock_Basalt_Cobble"
    },
    {
      "x": -2,
      "y": 4,
      "z": -2,
      "name": "Rock_Basalt_Cobble"
    },
    {
      "x": -2,
      "y": 5,
      "z": -2,
      "name": "Rock_Basalt_Cobble"
    },
    {
      "x": -2,
      "y": 6,
      "z": -2,
      "name": "Rock_Basalt_Cobble"
    },
    {
      "x": -2,
      "y": 7,
      "z": -2,
      "name": "Rock_Basalt_Brick"
    },
    {
      "x": -2,
      "y": 8,
      "z": -2,
      "name": "Rock_Basalt_Brick"
    },
    {
      "x": -2,
      "y": 9,
      "z": -2,
      "name": "*Rail_State_Definitions_Corner_Left",
      "rotation": 3
    },
    {
      "x": -2,
      "y": 10,
      "z": -2,
      "name": "Empty"
    },
    {
      "x": -2,
      "y": 11,
      "z": -2,
      "name": "Empty"
    },
    {
      "x": -2,
      "y": 12,
      "z": -2,
      "name": "Empty"
    },
    {
      "x": -2,
      "y": 13,
      "z": -2,
      "name": "Empty"
    },
    {
      "x": -2,
      "y": 14,
      "z": -2,
      "name": "Rock_Basalt_Cobble"
    },
    {
      "x": -2,
      "y": 4,
      "z": -1,
      "name": "Rock_Basalt_Cobble"
    },
    {
      "x": -2,
      "y": 5,
      "z": -1,
      "name": "Rock_Basalt_Cobble"
    },
    {
      "x": -2,
      "y": 6,
      "z": -1,
      "name": "Rock_Basalt_Cobble"
    },
    {
      "x": -2,
      "y": 7,
      "z": -1,
      "name": "Rock_Basalt_Brick"
    },
    {
      "x": -2,
      "y": 8,
      "z": -1,
      "name": "Rock_Basalt_Brick"
    },
    {
      "x": -2,
      "y": 9,
      "z": -1,
      "name": "Empty"
    },
    {
      "x": -2,
      "y": 10,
      "z": -1,
      "name": "Empty"
    },
    {
      "x": -2,
      "y": 11,
      "z": -1,
      "name": "Empty"
    },
    {
      "x": -2,
      "y": 12,
      "z": -1,
      "name": "Empty"
    },
    {
      "x": -2,
      "y": 13,
      "z": -1,
      "name": "Empty"
    },
    {
      "x": -2,
      "y": 14,
      "z": -1,
      "name": "Rock_Basalt_Cobble"
    },
    {
      "x": -2,
      "y": 4,
      "z": 0,
      "name": "Rock_Basalt_Cobble"
    },
    {
      "x": -2,
      "y": 5,
      "z": 0,
      "name": "Rock_Basalt_Cobble"
    },
    {
      "x": -2,
      "y": 6,
      "z": 0,
      "name": "Rock_Basalt_Cobble"
    },
    {
      "x": -2,
      "y": 7,
      "z": 0,
      "name": "Rock_Basalt_Brick"
    },
    {
      "x": -2,
      "y": 8,
      "z": 0,
      "name": "Rock_Basalt_Brick"
    },
    {
      "x": -2,
      "y": 9,
      "z": 0,
      "name": "Empty"
    },
    {
      "x": -2,
      "y": 10,
      "z": 0,
      "name": "Empty"
    },
    {
      "x": -2,
      "y": 11,
      "z": 0,
      "name": "Empty"
    },
    {
      "x": -2,
      "y": 12,
      "z": 0,
      "name": "Empty"
    },
    {
      "x": -2,
      "y": 13,
      "z": 0,
      "name": "Empty"
    },
    {
      "x": -2,
      "y": 14,
      "z": 0,
      "name": "Rock_Basalt_Cobble"
    },
    {
      "x": -2,
      "y": 4,
      "z": 1,
      "name": "Rock_Basalt_Cobble"
    },
    {
      "x": -2,
      "y": 5,
      "z": 1,
      "name": "Rock_Basalt_Cobble"
    },
    {
      "x": -2,
      "y": 6,
      "z": 1,
      "name": "Rock_Basalt_Cobble"
    },
    {
      "x": -2,
      "y": 7,
      "z": 1,
      "name": "Rock_Basalt_Brick"
    },
    {
      "x": -2,
      "y": 8,
      "z": 1,
      "name": "Rock_Basalt_Brick"
    },
    {
      "x": -2,
      "y": 9,
      "z": 1,
      "name": "Empty"
    },
    {
      "x": -2,
      "y": 10,
      "z": 1,
      "name": "Empty"
    },
    {
      "x": -2,
      "y": 11,
      "z": 1,
      "name": "Empty"
    },
    {
      "x": -2,
      "y": 12,
      "z": 1,
      "name": "Empty"
    },
    {
      "x": -2,
      "y": 13,
      "z": 1,
      "name": "Empty"
    },
    {
      "x": -2,
      "y": 14,
      "z": 1,
      "name": "Rock_Basalt_Cobble"
    },
    {
      "x": -2,
      "y": 4,
      "z": 2,
      "name": "Rock_Basalt_Cobble"
    },
    {
      "x": -2,
      "y": 5,
      "z": 2,
      "name": "Rock_Basalt_Cobble"
    },
    {
      "x": -2,
      "y": 6,
      "z": 2,
      "name": "Rock_Basalt_Cobble"
    },
    {
      "x": -2,
      "y": 7,
      "z": 2,
      "name": "Rock_Basalt_Brick"
    },
    {
      "x": -2,
      "y": 8,
      "z": 2,
      "name": "Rock_Basalt_Brick"
    },
    {
      "x": -2,
      "y": 9,
      "z": 2,
      "name": "Empty"
    },
    {
      "x": -2,
      "y": 10,
      "z": 2,
      "name": "Empty"
    },
    {
      "x": -2,
      "y": 11,
      "z": 2,
      "name": "Empty"
    },
    {
      "x": -2,
      "y": 12,
      "z": 2,
      "name": "Empty"
    },
    {
      "x": -2,
      "y": 13,
      "z": 2,
      "name": "Empty"
    },
    {
      "x": -2,
      "y": 14,
      "z": 2,
      "name": "Rock_Basalt_Cobble"
    },
    {
      "x": -2,
      "y": 4,
      "z": 3,
      "name": "Rock_Basalt_Cobble"
    },
    {
      "x": -2,
      "y": 5,
      "z": 3,
      "name": "Rock_Basalt_Cobble"
    },
    {
      "x": -2,
      "y": 6,
      "z": 3,
      "name": "Rock_Basalt_Cobble"
    },
    {
      "x": -2,
      "y": 7,
      "z": 3,
      "name": "Rock_Basalt_Brick"
    },
    {
      "x": -2,
      "y": 8,
      "z": 3,
      "name": "Rock_Basalt_Brick"
    },
    {
      "x": -2,
      "y": 9,
      "z": 3,
      "name": "Empty"
    },
    {
      "x": -2,
      "y": 10,
      "z": 3,
      "name": "Empty"
    },
    {
      "x": -2,
      "y": 11,
      "z": 3,
      "name": "Empty"
    },
    {
      "x": -2,
      "y": 12,
      "z": 3,
      "name": "Empty"
    },
    {
      "x": -2,
      "y": 13,
      "z": 3,
      "name": "Empty"
    },
    {
      "x": -2,
      "y": 14,
      "z": 3,
      "name": "Rock_Basalt_Cobble"
    },
    {
      "x": -2,
      "y": 4,
      "z": 4,
      "name": "Rock_Basalt_Cobble"
    },
    {
      "x": -2,
      "y": 5,
      "z": 4,
      "name": "Rock_Basalt_Cobble"
    },
    {
      "x": -2,
      "y": 6,
      "z": 4,
      "name": "Rock_Basalt_Cobble"
    },
    {
      "x": -2,
      "y": 7,
      "z": 4,
      "name": "Rock_Basalt_Brick"
    },
    {
      "x": -2,
      "y": 8,
      "z": 4,
      "name": "Rock_Basalt_Brick"
    },
    {
      "x": -2,
      "y": 9,
      "z": 4,
      "name": "*Rail_State_Definitions_Corner_Left",
      "rotation": 3
    },
    {
      "x": -2,
      "y": 10,
      "z": 4,
      "name": "Empty"
    },
    {
      "x": -2,
      "y": 11,
      "z": 4,
      "name": "Empty"
    },
    {
      "x": -2,
      "y": 12,
      "z": 4,
      "name": "Empty"
    },
    {
      "x": -2,
      "y": 13,
      "z": 4,
      "name": "Empty"
    },
    {
      "x": -2,
      "y": 14,
      "z": 4,
      "name": "Rock_Basalt_Cobble"
    },
    {
      "x": -2,
      "y": 4,
      "z": 5,
      "name": "Rock_Basalt_Cobble"
    },
    {
      "x": -2,
      "y": 5,
      "z": 5,
      "name": "Rock_Basalt_Cobble"
    },
    {
      "x": -2,
      "y": 6,
      "z": 5,
      "name": "Rock_Basalt_Cobble"
    },
    {
      "x": -2,
      "y": 7,
      "z": 5,
      "name": "Rock_Basalt_Brick"
    },
    {
      "x": -2,
      "y": 8,
      "z": 5,
      "name": "Rock_Basalt_Brick"
    },
    {
      "x": -2,
      "y": 9,
      "z": 5,
      "name": "Empty"
    },
    {
      "x": -2,
      "y": 10,
      "z": 5,
      "name": "Empty"
    },
    {
      "x": -2,
      "y": 11,
      "z": 5,
      "name": "Empty"
    },
    {
      "x": -2,
      "y": 12,
      "z": 5,
      "name": "Empty"
    },
    {
      "x": -2,
      "y": 13,
      "z": 5,
      "name": "Empty"
    },
    {
      "x": -2,
      "y": 14,
      "z": 5,
      "name": "Rock_Basalt_Cobble"
    },
    {
      "x": -2,
      "y": 4,
      "z": 6,
      "name": "Rock_Basalt_Cobble"
    },
    {
      "x": -2,
      "y": 5,
      "z": 6,
      "name": "Rock_Basalt_Cobble"
    },
    {
      "x": -2,
      "y": 6,
      "z": 6,
      "name": "Rock_Basalt_Cobble"
    },
    {
      "x": -2,
      "y": 7,
      "z": 6,
      "name": "Rock_Basalt_Brick"
    },
    {
      "x": -2,
      "y": 8,
      "z": 6,
      "name": "Rock_Basalt_Brick"
    },
    {
      "x": -2,
      "y": 9,
      "z": 6,
      "name": "Empty"
    },
    {
      "x": -2,
      "y": 10,
      "z": 6,
      "name": "Empty"
    },
    {
      "x": -2,
      "y": 11,
      "z": 6,
      "name": "Empty"
    },
    {
      "x": -2,
      "y": 12,
      "z": 6,
      "name": "Rock_Basalt_Brick_Half",
      "rotation": 8
    },
    {
      "x": -2,
      "y": 13,
      "z": 6,
      "name": "Rock_Basalt_Brick"
    },
    {
      "x": -2,
      "y": 14,
      "z": 6,
      "name": "Rock_Basalt_Cobble"
    },
    {
      "x": -1,
      "y": 4,
      "z": -5,
      "name": "Rock_Basalt_Cobble"
    },
    {
      "x": -1,
      "y": 5,
      "z": -5,
      "name": "Soil_Dirt_Poisoned"
    },
    {
      "x": -1,
      "y": 9,
      "z": -5,
      "name": "Empty"
    },
    {
      "x": -1,
      "y": 10,
      "z": -5,
      "name": "Empty"
    },
    {
      "x": -1,
      "y": 11,
      "z": -5,
      "name": "Empty"
    },
    {
      "x": -1,
      "y": 12,
      "z": -5,
      "name": "Empty"
    },
    {
      "x": -1,
      "y": 13,
      "z": -5,
      "name": "Rock_Basalt_Brick"
    },
    {
      "x": -1,
      "y": 14,
      "z": -5,
      "name": "Rock_Basalt_Brick"
    },
    {
      "x": -1,
      "y": 4,
      "z": -4,
      "name": "Rock_Basalt_Cobble"
    },
    {
      "x": -1,
      "y": 5,
      "z": -4,
      "name": "Soil_Dirt_Poisoned"
    },
    {
      "x": -1,
      "y": 9,
      "z": -4,
      "name": "Empty"
    },
    {
      "x": -1,
      "y": 10,
      "z": -4,
      "name": "Empty"
    },
    {
      "x": -1,
      "y": 11,
      "z": -4,
      "name": "Empty"
    },
    {
      "x": -1,
      "y": 12,
      "z": -4,
      "name": "Empty"
    },
    {
      "x": -1,
      "y": 13,
      "z": -4,
      "name": "Empty"
    },
    {
      "x": -1,
      "y": 14,
      "z": -4,
      "name": "Rock_Basalt_Brick"
    },
    {
      "x": -1,
      "y": 4,
      "z": -3,
      "name": "Rock_Basalt_Cobble"
    },
    {
      "x": -1,
      "y": 5,
      "z": -3,
      "name": "Soil_Dirt_Poisoned"
    },
    {
      "x": -1,
      "y": 9,
      "z": -3,
      "name": "Empty"
    },
    {
      "x": -1,
      "y": 10,
      "z": -3,
      "name": "Empty"
    },
    {
      "x": -1,
      "y": 11,
      "z": -3,
      "name": "Empty"
    },
    {
      "x": -1,
      "y": 12,
      "z": -3,
      "name": "Empty"
    },
    {
      "x": -1,
      "y": 13,
      "z": -3,
      "name": "Empty"
    },
    {
      "x": -1,
      "y": 14,
      "z": -3,
      "name": "Rock_Basalt_Brick"
    },
    {
      "x": -1,
      "y": 4,
      "z": -2,
      "name": "Rock_Basalt_Cobble"
    },
    {
      "x": -1,
      "y": 5,
      "z": -2,
      "name": "Soil_Dirt_Poisoned"
    },
    {
      "x": -1,
      "y": 6,
      "z": -2,
      "name": "Soil_Dirt_Poisoned"
    },
    {
      "x": -1,
      "y": 9,
      "z": -2,
      "name": "Empty"
    },
    {
      "x": -1,
      "y": 10,
      "z": -2,
      "name": "Empty"
    },
    {
      "x": -1,
      "y": 11,
      "z": -2,
      "name": "Empty"
    },
    {
      "x": -1,
      "y": 12,
      "z": -2,
      "name": "Empty"
    },
    {
      "x": -1,
      "y": 13,
      "z": -2,
      "name": "Empty"
    },
    {
      "x": -1,
      "y": 14,
      "z": -2,
      "name": "Rock_Basalt_Brick"
    },
    {
      "x": -1,
      "y": 4,
      "z": -1,
      "name": "Rock_Basalt_Cobble"
    },
    {
      "x": -1,
      "y": 5,
      "z": -1,
      "name": "Soil_Dirt_Poisoned"
    },
    {
      "x": -1,
      "y": 6,
      "z": -1,
      "name": "Soil_Dirt_Poisoned"
    },
    {
      "x": -1,
      "y": 9,
      "z": -1,
      "name": "Empty"
    },
    {
      "x": -1,
      "y": 10,
      "z": -1,
      "name": "Empty"
    },
    {
      "x": -1,
      "y": 11,
      "z": -1,
      "name": "Empty"
    },
    {
      "x": -1,
      "y": 12,
      "z": -1,
      "name": "Empty"
    },
    {
      "x": -1,
      "y": 13,
      "z": -1,
      "name": "Empty"
    },
    {
      "x": -1,
      "y": 14,
      "z": -1,
      "name": "Rock_Basalt_Brick"
    },
    {
      "x": -1,
      "y": 4,
      "z": 0,
      "name": "Rock_Basalt_Cobble"
    },
    {
      "x": -1,
      "y": 5,
      "z": 0,
      "name": "Soil_Dirt_Poisoned"
    },
    {
      "x": -1,
      "y": 6,
      "z": 0,
      "name": "Soil_Dirt_Poisoned"
    },
    {
      "x": -1,
      "y": 9,
      "z": 0,
      "name": "Empty"
    },
    {
      "x": -1,
      "y": 10,
      "z": 0,
      "name": "Empty"
    },
    {
      "x": -1,
      "y": 11,
      "z": 0,
      "name": "Empty"
    },
    {
      "x": -1,
      "y": 12,
      "z": 0,
      "name": "Empty"
    },
    {
      "x": -1,
      "y": 13,
      "z": 0,
      "name": "Empty"
    },
    {
      "x": -1,
      "y": 14,
      "z": 0,
      "name": "Rock_Basalt_Brick"
    },
    {
      "x": -1,
      "y": 4,
      "z": 1,
      "name": "Rock_Basalt_Cobble"
    },
    {
      "x": -1,
      "y": 5,
      "z": 1,
      "name": "Soil_Dirt_Poisoned"
    },
    {
      "x": -1,
      "y": 6,
      "z": 1,
      "name": "Soil_Dirt_Poisoned"
    },
    {
      "x": -1,
      "y": 9,
      "z": 1,
      "name": "Empty"
    },
    {
      "x": -1,
      "y": 10,
      "z": 1,
      "name": "Empty"
    },
    {
      "x": -1,
      "y": 11,
      "z": 1,
      "name": "Empty"
    },
    {
      "x": -1,
      "y": 12,
      "z": 1,
      "name": "Empty"
    },
    {
      "x": -1,
      "y": 13,
      "z": 1,
      "name": "Empty"
    },
    {
      "x": -1,
      "y": 14,
      "z": 1,
      "name": "Rock_Basalt_Brick"
    },
    {
      "x": -1,
      "y": 4,
      "z": 2,
      "name": "Rock_Basalt_Cobble"
    },
    {
      "x": -1,
      "y": 5,
      "z": 2,
      "name": "Soil_Dirt_Poisoned"
    },
    {
      "x": -1,
      "y": 6,
      "z": 2,
      "name": "Soil_Dirt_Poisoned"
    },
    {
      "x": -1,
      "y": 7,
      "z": 2,
      "name": "Plant_Reeds_Poison"
    },
    {
      "x": -1,
      "y": 9,
      "z": 2,
      "name": "Empty"
    },
    {
      "x": -1,
      "y": 10,
      "z": 2,
      "name": "Empty"
    },
    {
      "x": -1,
      "y": 11,
      "z": 2,
      "name": "Empty"
    },
    {
      "x": -1,
      "y": 12,
      "z": 2,
      "name": "Empty"
    },
    {
      "x": -1,
      "y": 13,
      "z": 2,
      "name": "Empty"
    },
    {
      "x": -1,
      "y": 14,
      "z": 2,
      "name": "Rock_Basalt_Brick"
    },
    {
      "x": -1,
      "y": 4,
      "z": 3,
      "name": "Rock_Basalt_Cobble"
    },
    {
      "x": -1,
      "y": 5,
      "z": 3,
      "name": "Soil_Dirt_Poisoned"
    },
    {
      "x": -1,
      "y": 6,
      "z": 3,
      "name": "Soil_Dirt_Poisoned"
    },
    {
      "x": -1,
      "y": 7,
      "z": 3,
      "name": "Plant_Reeds_Poison"
    },
    {
      "x": -1,
      "y": 9,
      "z": 3,
      "name": "Empty"
    },
    {
      "x": -1,
      "y": 10,
      "z": 3,
      "name": "Empty"
    },
    {
      "x": -1,
      "y": 11,
      "z": 3,
      "name": "Empty"
    },
    {
      "x": -1,
      "y": 12,
      "z": 3,
      "name": "Empty"
    },
    {
      "x": -1,
      "y": 13,
      "z": 3,
      "name": "Empty"
    },
    {
      "x": -1,
      "y": 14,
      "z": 3,
      "name": "Rock_Basalt_Brick"
    },
    {
      "x": -1,
      "y": 4,
      "z": 4,
      "name": "Rock_Basalt_Cobble"
    },
    {
      "x": -1,
      "y": 5,
      "z": 4,
      "name": "Soil_Dirt_Poisoned"
    },
    {
      "x": -1,
      "y": 6,
      "z": 4,
      "name": "Soil_Dirt_Poisoned"
    },
    {
      "x": -1,
      "y": 7,
      "z": 4,
      "name": "Plant_Seaweed_Grass_Bulbs"
    },
    {
      "x": -1,
      "y": 8,
      "z": 4,
      "name": "Plant_Seaweed_Grass_Bulbs",
      "filler": 1024
    },
    {
      "x": -1,
      "y": 9,
      "z": 4,
      "name": "Empty"
    },
    {
      "x": -1,
      "y": 10,
      "z": 4,
      "name": "Empty"
    },
    {
      "x": -1,
      "y": 11,
      "z": 4,
      "name": "Empty"
    },
    {
      "x": -1,
      "y": 12,
      "z": 4,
      "name": "Empty"
    },
    {
      "x": -1,
      "y": 13,
      "z": 4,
      "name": "Empty"
    },
    {
      "x": -1,
      "y": 14,
      "z": 4,
      "name": "Rock_Basalt_Brick"
    },
    {
      "x": -1,
      "y": 4,
      "z": 5,
      "name": "Rock_Basalt_Cobble"
    },
    {
      "x": -1,
      "y": 5,
      "z": 5,
      "name": "Soil_Dirt_Poisoned"
    },
    {
      "x": -1,
      "y": 9,
      "z": 5,
      "name": "Empty"
    },
    {
      "x": -1,
      "y": 10,
      "z": 5,
      "name": "Empty"
    },
    {
      "x": -1,
      "y": 11,
      "z": 5,
      "name": "Empty"
    },
    {
      "x": -1,
      "y": 12,
      "z": 5,
      "name": "Empty"
    },
    {
      "x": -1,
      "y": 13,
      "z": 5,
      "name": "Plant_Vine_Wall_Poisoned",
      "rotation": 2
    },
    {
      "x": -1,
      "y": 14,
      "z": 5,
      "name": "Rock_Basalt_Brick"
    },
    {
      "x": -1,
      "y": 4,
      "z": 6,
      "name": "Rock_Basalt_Cobble"
    },
    {
      "x": -1,
      "y": 5,
      "z": 6,
      "name": "Soil_Dirt_Poisoned"
    },
    {
      "x": -1,
      "y": 9,
      "z": 6,
      "name": "Empty"
    },
    {
      "x": -1,
      "y": 10,
      "z": 6,
      "name": "Empty"
    },
    {
      "x": -1,
      "y": 11,
      "z": 6,
      "name": "Empty"
    },
    {
      "x": -1,
      "y": 12,
      "z": 6,
      "name": "Empty"
    },
    {
      "x": -1,
      "y": 13,
      "z": 6,
      "name": "Rock_Basalt_Brick"
    },
    {
      "x": -1,
      "y": 14,
      "z": 6,
      "name": "Rock_Basalt_Brick"
    },
    {
      "x": 0,
      "y": 4,
      "z": -5,
      "name": "Rock_Basalt_Cobble"
    },
    {
      "x": 0,
      "y": 5,
      "z": -5,
      "name": "Soil_Dirt_Poisoned"
    },
    {
      "x": 0,
      "y": 9,
      "z": -5,
      "name": "Empty"
    },
    {
      "x": 0,
      "y": 10,
      "z": -5,
      "name": "Empty"
    },
    {
      "x": 0,
      "y": 11,
      "z": -5,
      "name": "Empty"
    },
    {
      "x": 0,
      "y": 12,
      "z": -5,
      "name": "Empty"
    },
    {
      "x": 0,
      "y": 13,
      "z": -5,
      "name": "Rock_Basalt_Brick_Half",
      "rotation": 8
    },
    {
      "x": 0,
      "y": 14,
      "z": -5,
      "name": "Rock_Basalt_Brick"
    },
    {
      "x": 0,
      "y": 4,
      "z": -4,
      "name": "Rock_Basalt_Cobble"
    },
    {
      "x": 0,
      "y": 5,
      "z": -4,
      "name": "Soil_Dirt_Poisoned"
    },
    {
      "x": 0,
      "y": 9,
      "z": -4,
      "name": "Empty"
    },
    {
      "x": 0,
      "y": 10,
      "z": -4,
      "name": "Empty"
    },
    {
      "x": 0,
      "y": 11,
      "z": -4,
      "name": "Empty"
    },
    {
      "x": 0,
      "y": 12,
      "z": -4,
      "name": "Empty"
    },
    {
      "x": 0,
      "y": 13,
      "z": -4,
      "name": "Rock_Basalt_Brick_Half",
      "rotation": 8
    },
    {
      "x": 0,
      "y": 14,
      "z": -4,
      "name": "Rock_Basalt_Brick"
    },
    {
      "x": 0,
      "y": 4,
      "z": -3,
      "name": "Rock_Basalt_Cobble"
    },
    {
      "x": 0,
      "y": 5,
      "z": -3,
      "name": "Soil_Dirt_Poisoned"
    },
    {
      "x": 0,
      "y": 9,
      "z": -3,
      "name": "Empty"
    },
    {
      "x": 0,
      "y": 10,
      "z": -3,
      "name": "Empty"
    },
    {
      "x": 0,
      "y": 11,
      "z": -3,
      "name": "Empty"
    },
    {
      "x": 0,
      "y": 12,
      "z": -3,
      "name": "Empty"
    },
    {
      "x": 0,
      "y": 13,
      "z": -3,
      "name": "Empty"
    },
    {
      "x": 0,
      "y": 14,
      "z": -3,
      "name": "Rock_Basalt_Brick"
    },
    {
      "x": 0,
      "y": 4,
      "z": -2,
      "name": "Rock_Basalt_Cobble"
    },
    {
      "x": 0,
      "y": 5,
      "z": -2,
      "name": "Soil_Dirt_Poisoned"
    },
    {
      "x": 0,
      "y": 6,
      "z": -2,
      "name": "Soil_Dirt_Poisoned"
    },
    {
      "x": 0,
      "y": 9,
      "z": -2,
      "name": "Empty"
    },
    {
      "x": 0,
      "y": 10,
      "z": -2,
      "name": "Empty"
    },
    {
      "x": 0,
      "y": 11,
      "z": -2,
      "name": "Empty"
    },
    {
      "x": 0,
      "y": 12,
      "z": -2,
      "name": "Empty"
    },
    {
      "x": 0,
      "y": 13,
      "z": -2,
      "name": "Empty"
    },
    {
      "x": 0,
      "y": 14,
      "z": -2,
      "name": "Rock_Basalt_Brick"
    },
    {
      "x": 0,
      "y": 4,
      "z": -1,
      "name": "Rock_Basalt_Cobble"
    },
    {
      "x": 0,
      "y": 5,
      "z": -1,
      "name": "Soil_Dirt_Poisoned"
    },
    {
      "x": 0,
      "y": 6,
      "z": -1,
      "name": "Soil_Dirt_Poisoned"
    },
    {
      "x": 0,
      "y": 9,
      "z": -1,
      "name": "Empty"
    },
    {
      "x": 0,
      "y": 10,
      "z": -1,
      "name": "Empty"
    },
    {
      "x": 0,
      "y": 11,
      "z": -1,
      "name": "Empty"
    },
    {
      "x": 0,
      "y": 12,
      "z": -1,
      "name": "Empty"
    },
    {
      "x": 0,
      "y": 13,
      "z": -1,
      "name": "Empty"
    },
    {
      "x": 0,
      "y": 14,
      "z": -1,
      "name": "Rock_Basalt_Brick"
    },
    {
      "x": 0,
      "y": 4,
      "z": 0,
      "name": "Rock_Basalt_Cobble"
    },
    {
      "x": 0,
      "y": 5,
      "z": 0,
      "name": "Soil_Dirt_Poisoned"
    },
    {
      "x": 0,
      "y": 6,
      "z": 0,
      "name": "Soil_Dirt_Poisoned"
    },
    {
      "x": 0,
      "y": 9,
      "z": 0,
      "name": "Empty"
    },
    {
      "x": 0,
      "y": 10,
      "z": 0,
      "name": "Empty"
    },
    {
      "x": 0,
      "y": 11,
      "z": 0,
      "name": "Empty"
    },
    {
      "x": 0,
      "y": 12,
      "z": 0,
      "name": "Empty"
    },
    {
      "x": 0,
      "y": 13,
      "z": 0,
      "name": "Empty"
    },
    {
      "x": 0,
      "y": 14,
      "z": 0,
      "name": "Rock_Basalt_Brick"
    },
    {
      "x": 0,
      "y": 4,
      "z": 1,
      "name": "Rock_Basalt_Cobble"
    },
    {
      "x": 0,
      "y": 5,
      "z": 1,
      "name": "Soil_Dirt_Poisoned"
    },
    {
      "x": 0,
      "y": 6,
      "z": 1,
      "name": "Soil_Dirt_Poisoned"
    },
    {
      "x": 0,
      "y": 9,
      "z": 1,
      "name": "Empty"
    },
    {
      "x": 0,
      "y": 10,
      "z": 1,
      "name": "Empty"
    },
    {
      "x": 0,
      "y": 11,
      "z": 1,
      "name": "Empty"
    },
    {
      "x": 0,
      "y": 12,
      "z": 1,
      "name": "Empty"
    },
    {
      "x": 0,
      "y": 13,
      "z": 1,
      "name": "Empty"
    },
    {
      "x": 0,
      "y": 14,
      "z": 1,
      "name": "Rock_Basalt_Brick"
    },
    {
      "x": 0,
      "y": 4,
      "z": 2,
      "name": "Rock_Basalt_Cobble"
    },
    {
      "x": 0,
      "y": 5,
      "z": 2,
      "name": "Soil_Dirt_Poisoned"
    },
    {
      "x": 0,
      "y": 6,
      "z": 2,
      "name": "Soil_Dirt_Poisoned"
    },
    {
      "x": 0,
      "y": 7,
      "z": 2,
      "name": "Plant_Reeds_Poison"
    },
    {
      "x": 0,
      "y": 9,
      "z": 2,
      "name": "Empty"
    },
    {
      "x": 0,
      "y": 10,
      "z": 2,
      "name": "Empty"
    },
    {
      "x": 0,
      "y": 11,
      "z": 2,
      "name": "Empty"
    },
    {
      "x": 0,
      "y": 12,
      "z": 2,
      "name": "Empty"
    },
    {
      "x": 0,
      "y": 13,
      "z": 2,
      "name": "Empty"
    },
    {
      "x": 0,
      "y": 14,
      "z": 2,
      "name": "Rock_Basalt_Brick"
    },
    {
      "x": 0,
      "y": 4,
      "z": 3,
      "name": "Rock_Basalt_Cobble"
    },
    {
      "x": 0,
      "y": 5,
      "z": 3,
      "name": "Soil_Dirt_Poisoned"
    },
    {
      "x": 0,
      "y": 6,
      "z": 3,
      "name": "Soil_Dirt_Poisoned"
    },
    {
      "x": 0,
      "y": 9,
      "z": 3,
      "name": "Empty"
    },
    {
      "x": 0,
      "y": 10,
      "z": 3,
      "name": "Empty"
    },
    {
      "x": 0,
      "y": 11,
      "z": 3,
      "name": "Empty"
    },
    {
      "x": 0,
      "y": 12,
      "z": 3,
      "name": "Empty"
    },
    {
      "x": 0,
      "y": 13,
      "z": 3,
      "name": "Empty"
    },
    {
      "x": 0,
      "y": 14,
      "z": 3,
      "name": "Rock_Basalt_Brick"
    },
    {
      "x": 0,
      "y": 4,
      "z": 4,
      "name": "Rock_Basalt_Cobble"
    },
    {
      "x": 0,
      "y": 5,
      "z": 4,
      "name": "Soil_Dirt_Poisoned"
    },
    {
      "x": 0,
      "y": 9,
      "z": 4,
      "name": "Empty"
    },
    {
      "x": 0,
      "y": 10,
      "z": 4,
      "name": "Empty"
    },
    {
      "x": 0,
      "y": 11,
      "z": 4,
      "name": "Empty"
    },
    {
      "x": 0,
      "y": 12,
      "z": 4,
      "name": "Empty"
    },
    {
      "x": 0,
      "y": 13,
      "z": 4,
      "name": "Empty"
    },
    {
      "x": 0,
      "y": 14,
      "z": 4,
      "name": "Rock_Basalt_Brick"
    },
    {
      "x": 0,
      "y": 4,
      "z": 5,
      "name": "Rock_Basalt_Cobble"
    },
    {
      "x": 0,
      "y": 5,
      "z": 5,
      "name": "Soil_Dirt_Poisoned"
    },
    {
      "x": 0,
      "y": 9,
      "z": 5,
      "name": "Empty"
    },
    {
      "x": 0,
      "y": 10,
      "z": 5,
      "name": "Empty"
    },
    {
      "x": 0,
      "y": 11,
      "z": 5,
      "name": "Empty"
    },
    {
      "x": 0,
      "y": 12,
      "z": 5,
      "name": "Empty"
    },
    {
      "x": 0,
      "y": 13,
      "z": 5,
      "name": "Rock_Basalt_Brick_Half",
      "rotation": 8
    },
    {
      "x": 0,
      "y": 14,
      "z": 5,
      "name": "Rock_Basalt_Brick"
    },
    {
      "x": 0,
      "y": 4,
      "z": 6,
      "name": "Rock_Basalt_Cobble"
    },
    {
      "x": 0,
      "y": 5,
      "z": 6,
      "name": "Soil_Dirt_Poisoned"
    },
    {
      "x": 0,
      "y": 9,
      "z": 6,
      "name": "Empty"
    },
    {
      "x": 0,
      "y": 10,
      "z": 6,
      "name": "Empty"
    },
    {
      "x": 0,
      "y": 11,
      "z": 6,
      "name": "Empty"
    },
    {
      "x": 0,
      "y": 12,
      "z": 6,
      "name": "Empty"
    },
    {
      "x": 0,
      "y": 13,
      "z": 6,
      "name": "Rock_Basalt_Brick_Half",
      "rotation": 8
    },
    {
      "x": 0,
      "y": 14,
      "z": 6,
      "name": "Rock_Basalt_Brick"
    },
    {
      "x": 1,
      "y": 4,
      "z": -5,
      "name": "Rock_Basalt_Cobble"
    },
    {
      "x": 1,
      "y": 5,
      "z": -5,
      "name": "Soil_Dirt_Poisoned"
    },
    {
      "x": 1,
      "y": 9,
      "z": -5,
      "name": "Empty"
    },
    {
      "x": 1,
      "y": 10,
      "z": -5,
      "name": "Empty"
    },
    {
      "x": 1,
      "y": 11,
      "z": -5,
      "name": "Empty"
    },
    {
      "x": 1,
      "y": 12,
      "z": -5,
      "name": "Empty"
    },
    {
      "x": 1,
      "y": 13,
      "z": -5,
      "name": "Rock_Basalt_Brick_Half",
      "rotation": 8
    },
    {
      "x": 1,
      "y": 14,
      "z": -5,
      "name": "Rock_Basalt_Brick"
    },
    {
      "x": 1,
      "y": 4,
      "z": -4,
      "name": "Rock_Basalt_Cobble"
    },
    {
      "x": 1,
      "y": 5,
      "z": -4,
      "name": "Soil_Dirt_Poisoned"
    },
    {
      "x": 1,
      "y": 9,
      "z": -4,
      "name": "Empty"
    },
    {
      "x": 1,
      "y": 10,
      "z": -4,
      "name": "Empty"
    },
    {
      "x": 1,
      "y": 11,
      "z": -4,
      "name": "Empty"
    },
    {
      "x": 1,
      "y": 12,
      "z": -4,
      "name": "Empty"
    },
    {
      "x": 1,
      "y": 13,
      "z": -4,
      "name": "Rock_Basalt_Brick_Half",
      "rotation": 8
    },
    {
      "x": 1,
      "y": 14,
      "z": -4,
      "name": "Rock_Basalt_Brick"
    },
    {
      "x": 1,
      "y": 4,
      "z": -3,
      "name": "Rock_Basalt_Cobble"
    },
    {
      "x": 1,
      "y": 5,
      "z": -3,
      "name": "Soil_Dirt_Poisoned"
    },
    {
      "x": 1,
      "y": 9,
      "z": -3,
      "name": "Empty"
    },
    {
      "x": 1,
      "y": 10,
      "z": -3,
      "name": "Empty"
    },
    {
      "x": 1,
      "y": 11,
      "z": -3,
      "name": "Empty"
    },
    {
      "x": 1,
      "y": 12,
      "z": -3,
      "name": "Empty"
    },
    {
      "x": 1,
      "y": 13,
      "z": -3,
      "name": "Rock_Basalt_Brick_Half",
      "rotation": 8
    },
    {
      "x": 1,
      "y": 14,
      "z": -3,
      "name": "Rock_Basalt_Brick"
    },
    {
      "x": 1,
      "y": 4,
      "z": -2,
      "name": "Rock_Basalt_Cobble"
    },
    {
      "x": 1,
      "y": 5,
      "z": -2,
      "name": "Soil_Dirt_Poisoned"
    },
    {
      "x": 1,
      "y": 9,
      "z": -2,
      "name": "Empty"
    },
    {
      "x": 1,
      "y": 10,
      "z": -2,
      "name": "Empty"
    },
    {
      "x": 1,
      "y": 11,
      "z": -2,
      "name": "Empty"
    },
    {
      "x": 1,
      "y": 12,
      "z": -2,
      "name": "Empty"
    },
    {
      "x": 1,
      "y": 13,
      "z": -2,
      "name": "Empty"
    },
    {
      "x": 1,
      "y": 14,
      "z": -2,
      "name": "Rock_Basalt_Brick"
    },
    {
      "x": 1,
      "y": 4,
      "z": -1,
      "name": "Rock_Basalt_Cobble"
    },
    {
      "x": 1,
      "y": 5,
      "z": -1,
      "name": "Soil_Dirt_Poisoned"
    },
    {
      "x": 1,
      "y": 6,
      "z": -1,
      "name": "Soil_Dirt_Poisoned"
    },
    {
      "x": 1,
      "y": 9,
      "z": -1,
      "name": "Empty"
    },
    {
      "x": 1,
      "y": 10,
      "z": -1,
      "name": "Empty"
    },
    {
      "x": 1,
      "y": 11,
      "z": -1,
      "name": "Empty"
    },
    {
      "x": 1,
      "y": 12,
      "z": -1,
      "name": "Empty"
    },
    {
      "x": 1,
      "y": 13,
      "z": -1,
      "name": "Empty"
    },
    {
      "x": 1,
      "y": 14,
      "z": -1,
      "name": "Rock_Basalt_Brick"
    },
    {
      "x": 1,
      "y": 4,
      "z": 0,
      "name": "Rock_Basalt_Cobble"
    },
    {
      "x": 1,
      "y": 5,
      "z": 0,
      "name": "Soil_Dirt_Poisoned"
    },
    {
      "x": 1,
      "y": 6,
      "z": 0,
      "name": "Soil_Dirt_Poisoned"
    },
    {
      "x": 1,
      "y": 9,
      "z": 0,
      "name": "Empty"
    },
    {
      "x": 1,
      "y": 10,
      "z": 0,
      "name": "Empty"
    },
    {
      "x": 1,
      "y": 11,
      "z": 0,
      "name": "Empty"
    },
    {
      "x": 1,
      "y": 12,
      "z": 0,
      "name": "Empty"
    },
    {
      "x": 1,
      "y": 13,
      "z": 0,
      "name": "Empty"
    },
    {
      "x": 1,
      "y": 14,
      "z": 0,
      "name": "Rock_Basalt_Brick"
    },
    {
      "x": 1,
      "y": 4,
      "z": 1,
      "name": "Rock_Basalt_Cobble"
    },
    {
      "x": 1,
      "y": 5,
      "z": 1,
      "name": "Soil_Dirt_Poisoned"
    },
    {
      "x": 1,
      "y": 6,
      "z": 1,
      "name": "Soil_Dirt_Poisoned"
    },
    {
      "x": 1,
      "y": 9,
      "z": 1,
      "name": "Empty"
    },
    {
      "x": 1,
      "y": 10,
      "z": 1,
      "name": "Empty"
    },
    {
      "x": 1,
      "y": 11,
      "z": 1,
      "name": "Empty"
    },
    {
      "x": 1,
      "y": 12,
      "z": 1,
      "name": "Empty"
    },
    {
      "x": 1,
      "y": 13,
      "z": 1,
      "name": "Empty"
    },
    {
      "x": 1,
      "y": 14,
      "z": 1,
      "name": "Rock_Basalt_Brick"
    },
    {
      "x": 1,
      "y": 4,
      "z": 2,
      "name": "Rock_Basalt_Cobble"
    },
    {
      "x": 1,
      "y": 5,
      "z": 2,
      "name": "Soil_Dirt_Poisoned"
    },
    {
      "x": 1,
      "y": 6,
      "z": 2,
      "name": "Soil_Dirt_Poisoned"
    },
    {
      "x": 1,
      "y": 9,
      "z": 2,
      "name": "Empty"
    },
    {
      "x": 1,
      "y": 10,
      "z": 2,
      "name": "Empty"
    },
    {
      "x": 1,
      "y": 11,
      "z": 2,
      "name": "Empty"
    },
    {
      "x": 1,
      "y": 12,
      "z": 2,
      "name": "Empty"
    },
    {
      "x": 1,
      "y": 13,
      "z": 2,
      "name": "Empty"
    },
    {
      "x": 1,
      "y": 14,
      "z": 2,
      "name": "Rock_Basalt_Brick"
    },
    {
      "x": 1,
      "y": 4,
      "z": 3,
      "name": "Rock_Basalt_Cobble"
    },
    {
      "x": 1,
      "y": 5,
      "z": 3,
      "name": "Soil_Dirt_Poisoned"
    },
    {
      "x": 1,
      "y": 6,
      "z": 3,
      "name": "Soil_Dirt_Poisoned"
    },
    {
      "x": 1,
      "y": 9,
      "z": 3,
      "name": "Empty"
    },
    {
      "x": 1,
      "y": 10,
      "z": 3,
      "name": "Empty"
    },
    {
      "x": 1,
      "y": 11,
      "z": 3,
      "name": "Empty"
    },
    {
      "x": 1,
      "y": 12,
      "z": 3,
      "name": "Empty"
    },
    {
      "x": 1,
      "y": 13,
      "z": 3,
      "name": "Empty"
    },
    {
      "x": 1,
      "y": 14,
      "z": 3,
      "name": "Rock_Basalt_Brick"
    },
    {
      "x": 1,
      "y": 4,
      "z": 4,
      "name": "Rock_Basalt_Cobble"
    },
    {
      "x": 1,
      "y": 5,
      "z": 4,
      "name": "Soil_Dirt_Poisoned"
    },
    {
      "x": 1,
      "y": 9,
      "z": 4,
      "name": "Empty"
    },
    {
      "x": 1,
      "y": 10,
      "z": 4,
      "name": "Empty"
    },
    {
      "x": 1,
      "y": 11,
      "z": 4,
      "name": "Empty"
    },
    {
      "x": 1,
      "y": 12,
      "z": 4,
      "name": "Empty"
    },
    {
      "x": 1,
      "y": 13,
      "z": 4,
      "name": "Rock_Basalt_Brick_Half",
      "rotation": 8
    },
    {
      "x": 1,
      "y": 14,
      "z": 4,
      "name": "Rock_Basalt_Brick"
    },
    {
      "x": 1,
      "y": 4,
      "z": 5,
      "name": "Rock_Basalt_Cobble"
    },
    {
      "x": 1,
      "y": 5,
      "z": 5,
      "name": "Soil_Dirt_Poisoned"
    },
    {
      "x": 1,
      "y": 9,
      "z": 5,
      "name": "Empty"
    },
    {
      "x": 1,
      "y": 10,
      "z": 5,
      "name": "Empty"
    },
    {
      "x": 1,
      "y": 11,
      "z": 5,
      "name": "Empty"
    },
    {
      "x": 1,
      "y": 12,
      "z": 5,
      "name": "Empty"
    },
    {
      "x": 1,
      "y": 13,
      "z": 5,
      "name": "Rock_Basalt_Brick_Half",
      "rotation": 8
    },
    {
      "x": 1,
      "y": 14,
      "z": 5,
      "name": "Rock_Basalt_Brick"
    },
    {
      "x": 1,
      "y": 4,
      "z": 6,
      "name": "Rock_Basalt_Cobble"
    },
    {
      "x": 1,
      "y": 5,
      "z": 6,
      "name": "Soil_Dirt_Poisoned"
    },
    {
      "x": 1,
      "y": 9,
      "z": 6,
      "name": "Empty"
    },
    {
      "x": 1,
      "y": 10,
      "z": 6,
      "name": "Empty"
    },
    {
      "x": 1,
      "y": 11,
      "z": 6,
      "name": "Empty"
    },
    {
      "x": 1,
      "y": 12,
      "z": 6,
      "name": "Empty"
    },
    {
      "x": 1,
      "y": 13,
      "z": 6,
      "name": "Rock_Basalt_Brick_Half",
      "rotation": 8
    },
    {
      "x": 1,
      "y": 14,
      "z": 6,
      "name": "Rock_Basalt_Brick"
    },
    {
      "x": 2,
      "y": 4,
      "z": -5,
      "name": "Rock_Basalt_Cobble"
    },
    {
      "x": 2,
      "y": 5,
      "z": -5,
      "name": "Soil_Dirt_Poisoned"
    },
    {
      "x": 2,
      "y": 9,
      "z": -5,
      "name": "Empty"
    },
    {
      "x": 2,
      "y": 10,
      "z": -5,
      "name": "Empty"
    },
    {
      "x": 2,
      "y": 11,
      "z": -5,
      "name": "Empty"
    },
    {
      "x": 2,
      "y": 12,
      "z": -5,
      "name": "Empty"
    },
    {
      "x": 2,
      "y": 13,
      "z": -5,
      "name": "Rock_Basalt_Brick_Half",
      "rotation": 8
    },
    {
      "x": 2,
      "y": 14,
      "z": -5,
      "name": "Rock_Basalt_Brick"
    },
    {
      "x": 2,
      "y": 4,
      "z": -4,
      "name": "Rock_Basalt_Cobble"
    },
    {
      "x": 2,
      "y": 5,
      "z": -4,
      "name": "Soil_Dirt_Poisoned"
    },
    {
      "x": 2,
      "y": 9,
      "z": -4,
      "name": "Empty"
    },
    {
      "x": 2,
      "y": 10,
      "z": -4,
      "name": "Empty"
    },
    {
      "x": 2,
      "y": 11,
      "z": -4,
      "name": "Empty"
    },
    {
      "x": 2,
      "y": 12,
      "z": -4,
      "name": "Empty"
    },
    {
      "x": 2,
      "y": 13,
      "z": -4,
      "name": "Rock_Basalt_Brick_Half",
      "rotation": 8
    },
    {
      "x": 2,
      "y": 14,
      "z": -4,
      "name": "Rock_Basalt_Brick"
    },
    {
      "x": 2,
      "y": 4,
      "z": -3,
      "name": "Rock_Basalt_Cobble"
    },
    {
      "x": 2,
      "y": 5,
      "z": -3,
      "name": "Soil_Dirt_Poisoned"
    },
    {
      "x": 2,
      "y": 6,
      "z": -3,
      "name": "Plant_Seaweed_Grass_Bulbs"
    },
    {
      "x": 2,
      "y": 7,
      "z": -3,
      "name": "Plant_Seaweed_Grass_Bulbs",
      "filler": 1024
    },
    {
      "x": 2,
      "y": 9,
      "z": -3,
      "name": "Plant_Moss_Rug_Green"
    },
    {
      "x": 2,
      "y": 10,
      "z": -3,
      "name": "Empty"
    },
    {
      "x": 2,
      "y": 11,
      "z": -3,
      "name": "Empty"
    },
    {
      "x": 2,
      "y": 12,
      "z": -3,
      "name": "Empty"
    },
    {
      "x": 2,
      "y": 13,
      "z": -3,
      "name": "Empty"
    },
    {
      "x": 2,
      "y": 14,
      "z": -3,
      "name": "Rock_Basalt_Brick"
    },
    {
      "x": 2,
      "y": 4,
      "z": -2,
      "name": "Rock_Basalt_Cobble"
    },
    {
      "x": 2,
      "y": 5,
      "z": -2,
      "name": "Soil_Dirt_Poisoned"
    },
    {
      "x": 2,
      "y": 9,
      "z": -2,
      "name": "Empty"
    },
    {
      "x": 2,
      "y": 10,
      "z": -2,
      "name": "Empty"
    },
    {
      "x": 2,
      "y": 11,
      "z": -2,
      "name": "Empty"
    },
    {
      "x": 2,
      "y": 12,
      "z": -2,
      "name": "Empty"
    },
    {
      "x": 2,
      "y": 13,
      "z": -2,
      "name": "Empty"
    },
    {
      "x": 2,
      "y": 14,
      "z": -2,
      "name": "Rock_Basalt_Brick"
    },
    {
      "x": 2,
      "y": 4,
      "z": -1,
      "name": "Rock_Basalt_Cobble"
    },
    {
      "x": 2,
      "y": 5,
      "z": -1,
      "name": "Soil_Dirt_Poisoned"
    },
    {
      "x": 2,
      "y": 9,
      "z": -1,
      "name": "Empty"
    },
    {
      "x": 2,
      "y": 10,
      "z": -1,
      "name": "Empty"
    },
    {
      "x": 2,
      "y": 11,
      "z": -1,
      "name": "Empty"
    },
    {
      "x": 2,
      "y": 12,
      "z": -1,
      "name": "Empty"
    },
    {
      "x": 2,
      "y": 13,
      "z": -1,
      "name": "Empty"
    },
    {
      "x": 2,
      "y": 14,
      "z": -1,
      "name": "Rock_Basalt_Brick"
    },
    {
      "x": 2,
      "y": 4,
      "z": 0,
      "name": "Rock_Basalt_Cobble"
    },
    {
      "x": 2,
      "y": 5,
      "z": 0,
      "name": "Soil_Dirt_Poisoned"
    },
    {
      "x": 2,
      "y": 9,
      "z": 0,
      "name": "Empty"
    },
    {
      "x": 2,
      "y": 10,
      "z": 0,
      "name": "Empty"
    },
    {
      "x": 2,
      "y": 11,
      "z": 0,
      "name": "Empty"
    },
    {
      "x": 2,
      "y": 12,
      "z": 0,
      "name": "Empty"
    },
    {
      "x": 2,
      "y": 13,
      "z": 0,
      "name": "Empty"
    },
    {
      "x": 2,
      "y": 14,
      "z": 0,
      "name": "Rock_Basalt_Brick"
    },
    {
      "x": 2,
      "y": 4,
      "z": 1,
      "name": "Rock_Basalt_Cobble"
    },
    {
      "x": 2,
      "y": 5,
      "z": 1,
      "name": "Soil_Dirt_Poisoned"
    },
    {
      "x": 2,
      "y": 9,
      "z": 1,
      "name": "Empty"
    },
    {
      "x": 2,
      "y": 10,
      "z": 1,
      "name": "Empty"
    },
    {
      "x": 2,
      "y": 11,
      "z": 1,
      "name": "Empty"
    },
    {
      "x": 2,
      "y": 12,
      "z": 1,
      "name": "Empty"
    },
    {
      "x": 2,
      "y": 13,
      "z": 1,
      "name": "Empty"
    },
    {
      "x": 2,
      "y": 14,
      "z": 1,
      "name": "Rock_Basalt_Brick"
    },
    {
      "x": 2,
      "y": 4,
      "z": 2,
      "name": "Rock_Basalt_Cobble"
    },
    {
      "x": 2,
      "y": 5,
      "z": 2,
      "name": "Soil_Dirt_Poisoned"
    },
    {
      "x": 2,
      "y": 9,
      "z": 2,
      "name": "Empty"
    },
    {
      "x": 2,
      "y": 10,
      "z": 2,
      "name": "Empty"
    },
    {
      "x": 2,
      "y": 11,
      "z": 2,
      "name": "Empty"
    },
    {
      "x": 2,
      "y": 12,
      "z": 2,
      "name": "Empty"
    },
    {
      "x": 2,
      "y": 13,
      "z": 2,
      "name": "Empty"
    },
    {
      "x": 2,
      "y": 14,
      "z": 2,
      "name": "Rock_Basalt_Brick"
    },
    {
      "x": 2,
      "y": 4,
      "z": 3,
      "name": "Rock_Basalt_Cobble"
    },
    {
      "x": 2,
      "y": 5,
      "z": 3,
      "name": "Soil_Dirt_Poisoned"
    },
    {
      "x": 2,
      "y": 9,
      "z": 3,
      "name": "Empty"
    },
    {
      "x": 2,
      "y": 10,
      "z": 3,
      "name": "Empty"
    },
    {
      "x": 2,
      "y": 11,
      "z": 3,
      "name": "Empty"
    },
    {
      "x": 2,
      "y": 12,
      "z": 3,
      "name": "Empty"
    },
    {
      "x": 2,
      "y": 13,
      "z": 3,
      "name": "Empty"
    },
    {
      "x": 2,
      "y": 14,
      "z": 3,
      "name": "Rock_Basalt_Brick"
    },
    {
      "x": 2,
      "y": 4,
      "z": 4,
      "name": "Rock_Basalt_Cobble"
    },
    {
      "x": 2,
      "y": 5,
      "z": 4,
      "name": "Soil_Dirt_Poisoned"
    },
    {
      "x": 2,
      "y": 9,
      "z": 4,
      "name": "Empty"
    },
    {
      "x": 2,
      "y": 10,
      "z": 4,
      "name": "Empty"
    },
    {
      "x": 2,
      "y": 11,
      "z": 4,
      "name": "Empty"
    },
    {
      "x": 2,
      "y": 12,
      "z": 4,
      "name": "Empty"
    },
    {
      "x": 2,
      "y": 13,
      "z": 4,
      "name": "Empty"
    },
    {
      "x": 2,
      "y": 14,
      "z": 4,
      "name": "Rock_Basalt_Brick"
    },
    {
      "x": 2,
      "y": 4,
      "z": 5,
      "name": "Rock_Basalt_Cobble"
    },
    {
      "x": 2,
      "y": 5,
      "z": 5,
      "name": "Soil_Dirt_Poisoned"
    },
    {
      "x": 2,
      "y": 9,
      "z": 5,
      "name": "Empty"
    },
    {
      "x": 2,
      "y": 10,
      "z": 5,
      "name": "Empty"
    },
    {
      "x": 2,
      "y": 11,
      "z": 5,
      "name": "Empty"
    },
    {
      "x": 2,
      "y": 12,
      "z": 5,
      "name": "Empty"
    },
    {
      "x": 2,
      "y": 13,
      "z": 5,
      "name": "Rock_Basalt_Brick_Half",
      "rotation": 8
    },
    {
      "x": 2,
      "y": 14,
      "z": 5,
      "name": "Rock_Basalt_Brick"
    },
    {
      "x": 2,
      "y": 4,
      "z": 6,
      "name": "Rock_Basalt_Cobble"
    },
    {
      "x": 2,
      "y": 5,
      "z": 6,
      "name": "Soil_Dirt_Poisoned"
    },
    {
      "x": 2,
      "y": 9,
      "z": 6,
      "name": "Empty"
    },
    {
      "x": 2,
      "y": 10,
      "z": 6,
      "name": "Empty"
    },
    {
      "x": 2,
      "y": 11,
      "z": 6,
      "name": "Empty"
    },
    {
      "x": 2,
      "y": 12,
      "z": 6,
      "name": "Empty"
    },
    {
      "x": 2,
      "y": 13,
      "z": 6,
      "name": "Rock_Basalt_Brick_Half",
      "rotation": 8
    },
    {
      "x": 2,
      "y": 14,
      "z": 6,
      "name": "Rock_Basalt_Brick"
    },
    {
      "x": 3,
      "y": 4,
      "z": -5,
      "name": "Rock_Basalt_Cobble"
    },
    {
      "x": 3,
      "y": 5,
      "z": -5,
      "name": "Soil_Dirt_Poisoned"
    },
    {
      "x": 3,
      "y": 9,
      "z": -5,
      "name": "Plant_Moss_Rug_Green"
    },
    {
      "x": 3,
      "y": 10,
      "z": -5,
      "name": "Empty"
    },
    {
      "x": 3,
      "y": 11,
      "z": -5,
      "name": "Empty"
    },
    {
      "x": 3,
      "y": 12,
      "z": -5,
      "name": "Empty"
    },
    {
      "x": 3,
      "y": 13,
      "z": -5,
      "name": "Rock_Basalt_Brick"
    },
    {
      "x": 3,
      "y": 14,
      "z": -5,
      "name": "Rock_Basalt_Brick"
    },
    {
      "x": 3,
      "y": 4,
      "z": -4,
      "name": "Rock_Basalt_Cobble"
    },
    {
      "x": 3,
      "y": 5,
      "z": -4,
      "name": "Soil_Dirt_Poisoned"
    },
    {
      "x": 3,
      "y": 6,
      "z": -4,
      "name": "Plant_Reeds_Poison"
    },
    {
      "x": 3,
      "y": 9,
      "z": -4,
      "name": "Plant_Moss_Rug_Green"
    },
    {
      "x": 3,
      "y": 10,
      "z": -4,
      "name": "Empty"
    },
    {
      "x": 3,
      "y": 11,
      "z": -4,
      "name": "Empty"
    },
    {
      "x": 3,
      "y": 12,
      "z": -4,
      "name": "Empty"
    },
    {
      "x": 3,
      "y": 13,
      "z": -4,
      "name": "Empty"
    },
    {
      "x": 3,
      "y": 14,
      "z": -4,
      "name": "Rock_Basalt_Brick"
    },
    {
      "x": 3,
      "y": 4,
      "z": -3,
      "name": "Rock_Basalt_Cobble"
    },
    {
      "x": 3,
      "y": 5,
      "z": -3,
      "name": "Soil_Dirt_Poisoned"
    },
    {
      "x": 3,
      "y": 6,
      "z": -3,
      "name": "Plant_Seaweed_Grass_Bulbs"
    },
    {
      "x": 3,
      "y": 7,
      "z": -3,
      "name": "Plant_Seaweed_Grass_Bulbs",
      "filler": 1024
    },
    {
      "x": 3,
      "y": 9,
      "z": -3,
      "name": "Plant_Moss_Rug_Green"
    },
    {
      "x": 3,
      "y": 10,
      "z": -3,
      "name": "Empty"
    },
    {
      "x": 3,
      "y": 11,
      "z": -3,
      "name": "Empty"
    },
    {
      "x": 3,
      "y": 12,
      "z": -3,
      "name": "Empty"
    },
    {
      "x": 3,
      "y": 13,
      "z": -3,
      "name": "Plant_Moss_Wall_Green",
      "rotation": 3
    },
    {
      "x": 3,
      "y": 14,
      "z": -3,
      "name": "Plant_Moss_Block_Green"
    },
    {
      "x": 3,
      "y": 4,
      "z": -2,
      "name": "Rock_Basalt_Cobble"
    },
    {
      "x": 3,
      "y": 5,
      "z": -2,
      "name": "Soil_Dirt_Poisoned"
    },
    {
      "x": 3,
      "y": 6,
      "z": -2,
      "name": "Plant_Reeds_Poison"
    },
    {
      "x": 3,
      "y": 9,
      "z": -2,
      "name": "Plant_Moss_Rug_Green"
    },
    {
      "x": 3,
      "y": 10,
      "z": -2,
      "name": "Empty"
    },
    {
      "x": 3,
      "y": 11,
      "z": -2,
      "name": "Empty"
    },
    {
      "x": 3,
      "y": 12,
      "z": -2,
      "name": "Empty"
    },
    {
      "x": 3,
      "y": 13,
      "z": -2,
      "name": "Plant_Moss_Wall_Green",
      "rotation": 3
    },
    {
      "x": 3,
      "y": 14,
      "z": -2,
      "name": "Plant_Moss_Block_Green"
    },
    {
      "x": 3,
      "y": 4,
      "z": -1,
      "name": "Rock_Basalt_Cobble"
    },
    {
      "x": 3,
      "y": 5,
      "z": -1,
      "name": "Soil_Dirt_Poisoned"
    },
    {
      "x": 3,
      "y": 9,
      "z": -1,
      "name": "Empty"
    },
    {
      "x": 3,
      "y": 10,
      "z": -1,
      "name": "Empty"
    },
    {
      "x": 3,
      "y": 11,
      "z": -1,
      "name": "Empty"
    },
    {
      "x": 3,
      "y": 12,
      "z": -1,
      "name": "Empty"
    },
    {
      "x": 3,
      "y": 13,
      "z": -1,
      "name": "Empty"
    },
    {
      "x": 3,
      "y": 14,
      "z": -1,
      "name": "Rock_Basalt_Brick"
    },
    {
      "x": 3,
      "y": 4,
      "z": 0,
      "name": "Rock_Basalt_Cobble"
    },
    {
      "x": 3,
      "y": 5,
      "z": 0,
      "name": "Soil_Dirt_Poisoned"
    },
    {
      "x": 3,
      "y": 9,
      "z": 0,
      "name": "Empty"
    },
    {
      "x": 3,
      "y": 10,
      "z": 0,
      "name": "Empty"
    },
    {
      "x": 3,
      "y": 11,
      "z": 0,
      "name": "Empty"
    },
    {
      "x": 3,
      "y": 12,
      "z": 0,
      "name": "Empty"
    },
    {
      "x": 3,
      "y": 13,
      "z": 0,
      "name": "Empty"
    },
    {
      "x": 3,
      "y": 14,
      "z": 0,
      "name": "Rock_Basalt_Brick"
    },
    {
      "x": 3,
      "y": 4,
      "z": 1,
      "name": "Rock_Basalt_Cobble"
    },
    {
      "x": 3,
      "y": 5,
      "z": 1,
      "name": "Soil_Dirt_Poisoned"
    },
    {
      "x": 3,
      "y": 9,
      "z": 1,
      "name": "Empty"
    },
    {
      "x": 3,
      "y": 10,
      "z": 1,
      "name": "Empty"
    },
    {
      "x": 3,
      "y": 11,
      "z": 1,
      "name": "Empty"
    },
    {
      "x": 3,
      "y": 12,
      "z": 1,
      "name": "Empty"
    },
    {
      "x": 3,
      "y": 13,
      "z": 1,
      "name": "Empty"
    },
    {
      "x": 3,
      "y": 14,
      "z": 1,
      "name": "Rock_Basalt_Brick"
    },
    {
      "x": 3,
      "y": 4,
      "z": 2,
      "name": "Rock_Basalt_Cobble"
    },
    {
      "x": 3,
      "y": 5,
      "z": 2,
      "name": "Soil_Dirt_Poisoned"
    },
    {
      "x": 3,
      "y": 6,
      "z": 2,
      "name": "Plant_Reeds_Poison"
    },
    {
      "x": 3,
      "y": 9,
      "z": 2,
      "name": "Empty"
    },
    {
      "x": 3,
      "y": 10,
      "z": 2,
      "name": "Empty"
    },
    {
      "x": 3,
      "y": 11,
      "z": 2,
      "name": "Empty"
    },
    {
      "x": 3,
      "y": 12,
      "z": 2,
      "name": "Empty"
    },
    {
      "x": 3,
      "y": 13,
      "z": 2,
      "name": "Empty"
    },
    {
      "x": 3,
      "y": 14,
      "z": 2,
      "name": "Rock_Basalt_Brick"
    },
    {
      "x": 3,
      "y": 4,
      "z": 3,
      "name": "Rock_Basalt_Cobble"
    },
    {
      "x": 3,
      "y": 5,
      "z": 3,
      "name": "Soil_Dirt_Poisoned"
    },
    {
      "x": 3,
      "y": 6,
      "z": 3,
      "name": "Soil_Dirt_Poisoned"
    },
    {
      "x": 3,
      "y": 9,
      "z": 3,
      "name": "Empty"
    },
    {
      "x": 3,
      "y": 10,
      "z": 3,
      "name": "Empty"
    },
    {
      "x": 3,
      "y": 11,
      "z": 3,
      "name": "Empty"
    },
    {
      "x": 3,
      "y": 12,
      "z": 3,
      "name": "Empty"
    },
    {
      "x": 3,
      "y": 13,
      "z": 3,
      "name": "Empty"
    },
    {
      "x": 3,
      "y": 14,
      "z": 3,
      "name": "Rock_Basalt_Brick"
    },
    {
      "x": 3,
      "y": 4,
      "z": 4,
      "name": "Rock_Basalt_Cobble"
    },
    {
      "x": 3,
      "y": 5,
      "z": 4,
      "name": "Soil_Dirt_Poisoned"
    },
    {
      "x": 3,
      "y": 6,
      "z": 4,
      "name": "Soil_Dirt_Poisoned"
    },
    {
      "x": 3,
      "y": 9,
      "z": 4,
      "name": "Empty"
    },
    {
      "x": 3,
      "y": 10,
      "z": 4,
      "name": "Empty"
    },
    {
      "x": 3,
      "y": 11,
      "z": 4,
      "name": "Empty"
    },
    {
      "x": 3,
      "y": 12,
      "z": 4,
      "name": "Empty"
    },
    {
      "x": 3,
      "y": 13,
      "z": 4,
      "name": "Empty"
    },
    {
      "x": 3,
      "y": 14,
      "z": 4,
      "name": "Rock_Basalt_Brick"
    },
    {
      "x": 3,
      "y": 4,
      "z": 5,
      "name": "Rock_Basalt_Cobble"
    },
    {
      "x": 3,
      "y": 5,
      "z": 5,
      "name": "Soil_Dirt_Poisoned"
    },
    {
      "x": 3,
      "y": 9,
      "z": 5,
      "name": "Empty"
    },
    {
      "x": 3,
      "y": 10,
      "z": 5,
      "name": "Empty"
    },
    {
      "x": 3,
      "y": 11,
      "z": 5,
      "name": "Empty"
    },
    {
      "x": 3,
      "y": 12,
      "z": 5,
      "name": "Empty"
    },
    {
      "x": 3,
      "y": 13,
      "z": 5,
      "name": "Plant_Vine_Wall_Poisoned",
      "rotation": 2
    },
    {
      "x": 3,
      "y": 14,
      "z": 5,
      "name": "Rock_Basalt_Brick"
    },
    {
      "x": 3,
      "y": 4,
      "z": 6,
      "name": "Rock_Basalt_Cobble"
    },
    {
      "x": 3,
      "y": 5,
      "z": 6,
      "name": "Soil_Dirt_Poisoned"
    },
    {
      "x": 3,
      "y": 9,
      "z": 6,
      "name": "Empty"
    },
    {
      "x": 3,
      "y": 10,
      "z": 6,
      "name": "Empty"
    },
    {
      "x": 3,
      "y": 11,
      "z": 6,
      "name": "Empty"
    },
    {
      "x": 3,
      "y": 12,
      "z": 6,
      "name": "Empty"
    },
    {
      "x": 3,
      "y": 13,
      "z": 6,
      "name": "Rock_Basalt_Brick"
    },
    {
      "x": 3,
      "y": 14,
      "z": 6,
      "name": "Rock_Basalt_Brick"
    },
    {
      "x": 4,
      "y": 4,
      "z": -5,
      "name": "Rock_Basalt_Cobble"
    },
    {
      "x": 4,
      "y": 5,
      "z": -5,
      "name": "Rock_Basalt_Cobble"
    },
    {
      "x": 4,
      "y": 6,
      "z": -5,
      "name": "Rock_Basalt_Cobble"
    },
    {
      "x": 4,
      "y": 7,
      "z": -5,
      "name": "Rock_Basalt_Brick"
    },
    {
      "x": 4,
      "y": 8,
      "z": -5,
      "name": "Rock_Basalt_Brick"
    },
    {
      "x": 4,
      "y": 9,
      "z": -5,
      "name": "Plant_Moss_Rug_Green"
    },
    {
      "x": 4,
      "y": 10,
      "z": -5,
      "name": "Empty"
    },
    {
      "x": 4,
      "y": 11,
      "z": -5,
      "name": "Empty"
    },
    {
      "x": 4,
      "y": 12,
      "z": -5,
      "name": "Rock_Basalt_Brick_Half",
      "rotation": 8
    },
    {
      "x": 4,
      "y": 13,
      "z": -5,
      "name": "Rock_Basalt_Brick"
    },
    {
      "x": 4,
      "y": 14,
      "z": -5,
      "name": "Rock_Basalt_Cobble"
    },
    {
      "x": 4,
      "y": 4,
      "z": -4,
      "name": "Rock_Basalt_Cobble"
    },
    {
      "x": 4,
      "y": 5,
      "z": -4,
      "name": "Rock_Basalt_Cobble"
    },
    {
      "x": 4,
      "y": 6,
      "z": -4,
      "name": "Rock_Basalt_Cobble"
    },
    {
      "x": 4,
      "y": 7,
      "z": -4,
      "name": "Rock_Basalt_Brick"
    },
    {
      "x": 4,
      "y": 8,
      "z": -4,
      "name": "Rock_Basalt_Brick"
    },
    {
      "x": 4,
      "y": 9,
      "z": -4,
      "name": "Plant_Moss_Rug_Green"
    },
    {
      "x": 4,
      "y": 10,
      "z": -4,
      "name": "Empty"
    },
    {
      "x": 4,
      "y": 11,
      "z": -4,
      "name": "Empty"
    },
    {
      "x": 4,
      "y": 12,
      "z": -4,
      "name": "Empty"
    },
    {
      "x": 4,
      "y": 13,
      "z": -4,
      "name": "Empty"
    },
    {
      "x": 4,
      "y": 14,
      "z": -4,
      "name": "Rock_Basalt_Cobble"
    },
    {
      "x": 4,
      "y": 4,
      "z": -3,
      "name": "Rock_Basalt_Cobble"
    },
    {
      "x": 4,
      "y": 5,
      "z": -3,
      "name": "Rock_Basalt_Cobble"
    },
    {
      "x": 4,
      "y": 6,
      "z": -3,
      "name": "Rock_Basalt_Cobble"
    },
    {
      "x": 4,
      "y": 7,
      "z": -3,
      "name": "Rock_Basalt_Brick"
    },
    {
      "x": 4,
      "y": 8,
      "z": -3,
      "name": "Rock_Basalt_Brick"
    },
    {
      "x": 4,
      "y": 9,
      "z": -3,
      "name": "Plant_Moss_Rug_Green"
    },
    {
      "x": 4,
      "y": 10,
      "z": -3,
      "name": "Empty"
    },
    {
      "x": 4,
      "y": 11,
      "z": -3,
      "name": "Empty"
    },
    {
      "x": 4,
      "y": 12,
      "z": -3,
      "name": "Plant_Moss_Cave_Green",
      "rotation": 8
    },
    {
      "x": 4,
      "y": 13,
      "z": -3,
      "name": "Plant_Moss_Block_Green"
    },
    {
      "x": 4,
      "y": 14,
      "z": -3,
      "name": "Plant_Moss_Block_Green"
    },
    {
      "x": 4,
      "y": 4,
      "z": -2,
      "name": "Rock_Basalt_Cobble"
    },
    {
      "x": 4,
      "y": 5,
      "z": -2,
      "name": "Rock_Basalt_Cobble"
    },
    {
      "x": 4,
      "y": 6,
      "z": -2,
      "name": "Rock_Basalt_Cobble"
    },
    {
      "x": 4,
      "y": 7,
      "z": -2,
      "name": "Rock_Basalt_Brick"
    },
    {
      "x": 4,
      "y": 8,
      "z": -2,
      "name": "Plant_Moss_Block_Green"
    },
    {
      "x": 4,
      "y": 9,
      "z": -2,
      "name": "Plant_Moss_Rug_Green"
    },
    {
      "x": 4,
      "y": 10,
      "z": -2,
      "name": "Empty"
    },
    {
      "x": 4,
      "y": 11,
      "z": -2,
      "name": "Empty"
    },
    {
      "x": 4,
      "y": 12,
      "z": -2,
      "name": "Plant_Moss_Cave_Green",
      "rotation": 8
    },
    {
      "x": 4,
      "y": 13,
      "z": -2,
      "name": "Plant_Moss_Block_Green"
    },
    {
      "x": 4,
      "y": 14,
      "z": -2,
      "name": "Plant_Moss_Block_Green"
    },
    {
      "x": 4,
      "y": 4,
      "z": -1,
      "name": "Rock_Basalt_Cobble"
    },
    {
      "x": 4,
      "y": 5,
      "z": -1,
      "name": "Rock_Basalt_Cobble"
    },
    {
      "x": 4,
      "y": 6,
      "z": -1,
      "name": "Rock_Basalt_Cobble"
    },
    {
      "x": 4,
      "y": 7,
      "z": -1,
      "name": "Rock_Basalt_Brick"
    },
    {
      "x": 4,
      "y": 8,
      "z": -1,
      "name": "Rock_Basalt_Brick"
    },
    {
      "x": 4,
      "y": 9,
      "z": -1,
      "name": "Empty"
    },
    {
      "x": 4,
      "y": 10,
      "z": -1,
      "name": "Empty"
    },
    {
      "x": 4,
      "y": 11,
      "z": -1,
      "name": "Empty"
    },
    {
      "x": 4,
      "y": 12,
      "z": -1,
      "name": "Empty"
    },
    {
      "x": 4,
      "y": 13,
      "z": -1,
      "name": "Plant_Moss_Wall_Green"
    },
    {
      "x": 4,
      "y": 14,
      "z": -1,
      "name": "Rock_Basalt_Cobble"
    },
    {
      "x": 4,
      "y": 4,
      "z": 0,
      "name": "Rock_Basalt_Cobble"
    },
    {
      "x": 4,
      "y": 5,
      "z": 0,
      "name": "Rock_Basalt_Cobble"
    },
    {
      "x": 4,
      "y": 6,
      "z": 0,
      "name": "Rock_Basalt_Cobble"
    },
    {
      "x": 4,
      "y": 7,
      "z": 0,
      "name": "Rock_Basalt_Brick"
    },
    {
      "x": 4,
      "y": 8,
      "z": 0,
      "name": "Rock_Basalt_Brick"
    },
    {
      "x": 4,
      "y": 9,
      "z": 0,
      "name": "Empty"
    },
    {
      "x": 4,
      "y": 10,
      "z": 0,
      "name": "Empty"
    },
    {
      "x": 4,
      "y": 11,
      "z": 0,
      "name": "Empty"
    },
    {
      "x": 4,
      "y": 12,
      "z": 0,
      "name": "Empty"
    },
    {
      "x": 4,
      "y": 13,
      "z": 0,
      "name": "Empty"
    },
    {
      "x": 4,
      "y": 14,
      "z": 0,
      "name": "Rock_Basalt_Cobble"
    },
    {
      "x": 4,
      "y": 4,
      "z": 1,
      "name": "Rock_Basalt_Cobble"
    },
    {
      "x": 4,
      "y": 5,
      "z": 1,
      "name": "Rock_Basalt_Cobble"
    },
    {
      "x": 4,
      "y": 6,
      "z": 1,
      "name": "Rock_Basalt_Cobble"
    },
    {
      "x": 4,
      "y": 7,
      "z": 1,
      "name": "Rock_Basalt_Brick"
    },
    {
      "x": 4,
      "y": 8,
      "z": 1,
      "name": "Rock_Basalt_Brick"
    },
    {
      "x": 4,
      "y": 9,
      "z": 1,
      "name": "Empty"
    },
    {
      "x": 4,
      "y": 10,
      "z": 1,
      "name": "Empty"
    },
    {
      "x": 4,
      "y": 11,
      "z": 1,
      "name": "Empty"
    },
    {
      "x": 4,
      "y": 12,
      "z": 1,
      "name": "Empty"
    },
    {
      "x": 4,
      "y": 13,
      "z": 1,
      "name": "Empty"
    },
    {
      "x": 4,
      "y": 14,
      "z": 1,
      "name": "Rock_Basalt_Cobble"
    },
    {
      "x": 4,
      "y": 4,
      "z": 2,
      "name": "Rock_Basalt_Cobble"
    },
    {
      "x": 4,
      "y": 5,
      "z": 2,
      "name": "Rock_Basalt_Cobble"
    },
    {
      "x": 4,
      "y": 6,
      "z": 2,
      "name": "Rock_Basalt_Cobble"
    },
    {
      "x": 4,
      "y": 7,
      "z": 2,
      "name": "Rock_Basalt_Brick"
    },
    {
      "x": 4,
      "y": 8,
      "z": 2,
      "name": "Rock_Basalt_Brick"
    },
    {
      "x": 4,
      "y": 9,
      "z": 2,
      "name": "Empty"
    },
    {
      "x": 4,
      "y": 10,
      "z": 2,
      "name": "Empty"
    },
    {
      "x": 4,
      "y": 11,
      "z": 2,
      "name": "Empty"
    },
    {
      "x": 4,
      "y": 12,
      "z": 2,
      "name": "Empty"
    },
    {
      "x": 4,
      "y": 13,
      "z": 2,
      "name": "Empty"
    },
    {
      "x": 4,
      "y": 14,
      "z": 2,
      "name": "Rock_Basalt_Cobble"
    },
    {
      "x": 4,
      "y": 4,
      "z": 3,
      "name": "Rock_Basalt_Cobble"
    },
    {
      "x": 4,
      "y": 5,
      "z": 3,
      "name": "Rock_Basalt_Cobble"
    },
    {
      "x": 4,
      "y": 6,
      "z": 3,
      "name": "Rock_Basalt_Cobble"
    },
    {
      "x": 4,
      "y": 7,
      "z": 3,
      "name": "Rock_Basalt_Brick"
    },
    {
      "x": 4,
      "y": 8,
      "z": 3,
      "name": "Rock_Basalt_Brick"
    },
    {
      "x": 4,
      "y": 9,
      "z": 3,
      "name": "Empty"
    },
    {
      "x": 4,
      "y": 10,
      "z": 3,
      "name": "Empty"
    },
    {
      "x": 4,
      "y": 11,
      "z": 3,
      "name": "Empty"
    },
    {
      "x": 4,
      "y": 12,
      "z": 3,
      "name": "Empty"
    },
    {
      "x": 4,
      "y": 13,
      "z": 3,
      "name": "Empty"
    },
    {
      "x": 4,
      "y": 14,
      "z": 3,
      "name": "Rock_Basalt_Cobble"
    },
    {
      "x": 4,
      "y": 4,
      "z": 4,
      "name": "Rock_Basalt_Cobble"
    },
    {
      "x": 4,
      "y": 5,
      "z": 4,
      "name": "Rock_Basalt_Cobble"
    },
    {
      "x": 4,
      "y": 6,
      "z": 4,
      "name": "Rock_Basalt_Cobble"
    },
    {
      "x": 4,
      "y": 7,
      "z": 4,
      "name": "Rock_Basalt_Brick"
    },
    {
      "x": 4,
      "y": 8,
      "z": 4,
      "name": "Rock_Basalt_Brick"
    },
    {
      "x": 4,
      "y": 9,
      "z": 4,
      "name": "Empty"
    },
    {
      "x": 4,
      "y": 10,
      "z": 4,
      "name": "Empty"
    },
    {
      "x": 4,
      "y": 11,
      "z": 4,
      "name": "Empty"
    },
    {
      "x": 4,
      "y": 12,
      "z": 4,
      "name": "Empty"
    },
    {
      "x": 4,
      "y": 13,
      "z": 4,
      "name": "Empty"
    },
    {
      "x": 4,
      "y": 14,
      "z": 4,
      "name": "Rock_Basalt_Cobble"
    },
    {
      "x": 4,
      "y": 4,
      "z": 5,
      "name": "Rock_Basalt_Cobble"
    },
    {
      "x": 4,
      "y": 5,
      "z": 5,
      "name": "Rock_Basalt_Cobble"
    },
    {
      "x": 4,
      "y": 6,
      "z": 5,
      "name": "Rock_Basalt_Cobble"
    },
    {
      "x": 4,
      "y": 7,
      "z": 5,
      "name": "Rock_Basalt_Brick"
    },
    {
      "x": 4,
      "y": 8,
      "z": 5,
      "name": "Rock_Basalt_Brick"
    },
    {
      "x": 4,
      "y": 9,
      "z": 5,
      "name": "Empty"
    },
    {
      "x": 4,
      "y": 10,
      "z": 5,
      "name": "Empty"
    },
    {
      "x": 4,
      "y": 11,
      "z": 5,
      "name": "Empty"
    },
    {
      "x": 4,
      "y": 12,
      "z": 5,
      "name": "Plant_Vine_Wall_Poisoned",
      "rotation": 2
    },
    {
      "x": 4,
      "y": 13,
      "z": 5,
      "name": "Plant_Vine_Wall_Poisoned",
      "rotation": 2
    },
    {
      "x": 4,
      "y": 14,
      "z": 5,
      "name": "Rock_Basalt_Cobble"
    },
    {
      "x": 4,
      "y": 4,
      "z": 6,
      "name": "Rock_Basalt_Cobble"
    },
    {
      "x": 4,
      "y": 5,
      "z": 6,
      "name": "Rock_Basalt_Cobble"
    },
    {
      "x": 4,
      "y": 6,
      "z": 6,
      "name": "Rock_Basalt_Cobble"
    },
    {
      "x": 4,
      "y": 7,
      "z": 6,
      "name": "Rock_Basalt_Brick"
    },
    {
      "x": 4,
      "y": 8,
      "z": 6,
      "name": "Rock_Basalt_Brick"
    },
    {
      "x": 4,
      "y": 9,
      "z": 6,
      "name": "Empty"
    },
    {
      "x": 4,
      "y": 10,
      "z": 6,
      "name": "Empty"
    },
    {
      "x": 4,
      "y": 11,
      "z": 6,
      "name": "Empty"
    },
    {
      "x": 4,
      "y": 12,
      "z": 6,
      "name": "Rock_Basalt_Brick_Half",
      "rotation": 8
    },
    {
      "x": 4,
      "y": 13,
      "z": 6,
      "name": "Rock_Basalt_Brick"
    },
    {
      "x": 4,
      "y": 14,
      "z": 6,
      "name": "Rock_Basalt_Cobble"
    },
    {
      "x": 5,
      "y": 5,
      "z": -5,
      "name": "Rock_Basalt_Cobble"
    },
    {
      "x": 5,
      "y": 6,
      "z": -5,
      "name": "Rock_Basalt_Cobble"
    },
    {
      "x": 5,
      "y": 7,
      "z": -5,
      "name": "Rock_Basalt_Brick"
    },
    {
      "x": 5,
      "y": 8,
      "z": -5,
      "name": "Rock_Basalt_Brick"
    },
    {
      "x": 5,
      "y": 9,
      "z": -5,
      "name": "Empty"
    },
    {
      "x": 5,
      "y": 10,
      "z": -5,
      "name": "Empty"
    },
    {
      "x": 5,
      "y": 11,
      "z": -5,
      "name": "Rock_Basalt_Brick_Half",
      "rotation": 7
    },
    {
      "x": 5,
      "y": 12,
      "z": -5,
      "name": "Rock_Basalt_Brick"
    },
    {
      "x": 5,
      "y": 13,
      "z": -5,
      "name": "Rock_Basalt_Brick"
    },
    {
      "x": 5,
      "y": 14,
      "z": -5,
      "name": "Rock_Basalt_Cobble"
    },
    {
      "x": 5,
      "y": 5,
      "z": -4,
      "name": "Rock_Basalt_Cobble"
    },
    {
      "x": 5,
      "y": 6,
      "z": -4,
      "name": "Rock_Basalt_Cobble"
    },
    {
      "x": 5,
      "y": 7,
      "z": -4,
      "name": "Rock_Basalt_Brick"
    },
    {
      "x": 5,
      "y": 8,
      "z": -4,
      "name": "Rock_Basalt_Brick"
    },
    {
      "x": 5,
      "y": 9,
      "z": -4,
      "name": "Plant_Moss_Rug_Green"
    },
    {
      "x": 5,
      "y": 10,
      "z": -4,
      "name": "Empty"
    },
    {
      "x": 5,
      "y": 11,
      "z": -4,
      "name": "Empty"
    },
    {
      "x": 5,
      "y": 12,
      "z": -4,
      "name": "Plant_Moss_Cave_Green",
      "rotation": 8
    },
    {
      "x": 5,
      "y": 13,
      "z": -4,
      "name": "Plant_Moss_Block_Green"
    },
    {
      "x": 5,
      "y": 14,
      "z": -4,
      "name": "Rock_Basalt_Cobble"
    },
    {
      "x": 5,
      "y": 5,
      "z": -3,
      "name": "Rock_Basalt_Cobble"
    },
    {
      "x": 5,
      "y": 6,
      "z": -3,
      "name": "Rock_Basalt_Cobble"
    },
    {
      "x": 5,
      "y": 7,
      "z": -3,
      "name": "Rock_Basalt_Brick"
    },
    {
      "x": 5,
      "y": 8,
      "z": -3,
      "name": "Plant_Moss_Block_Green"
    },
    {
      "x": 5,
      "y": 9,
      "z": -3,
      "name": "Plant_Moss_Green"
    },
    {
      "x": 5,
      "y": 10,
      "z": -3,
      "name": "Empty"
    },
    {
      "x": 5,
      "y": 11,
      "z": -3,
      "name": "Empty"
    },
    {
      "x": 5,
      "y": 12,
      "z": -3,
      "name": "Plant_Moss_Wall_Green",
      "rotation": 3
    },
    {
      "x": 5,
      "y": 13,
      "z": -3,
      "name": "Plant_Moss_Block_Green"
    },
    {
      "x": 5,
      "y": 14,
      "z": -3,
      "name": "Rock_Basalt_Cobble"
    },
    {
      "x": 5,
      "y": 5,
      "z": -2,
      "name": "Rock_Basalt_Cobble"
    },
    {
      "x": 5,
      "y": 6,
      "z": -2,
      "name": "Rock_Basalt_Cobble"
    },
    {
      "x": 5,
      "y": 7,
      "z": -2,
      "name": "Rock_Basalt_Brick"
    },
    {
      "x": 5,
      "y": 8,
      "z": -2,
      "name": "Plant_Moss_Block_Green"
    },
    {
      "x": 5,
      "y": 9,
      "z": -2,
      "name": "Plant_Moss_Wall_Green",
      "rotation": 3
    },
    {
      "x": 5,
      "y": 10,
      "z": -2,
      "name": "Plant_Moss_Wall_Green",
      "rotation": 3
    },
    {
      "x": 5,
      "y": 11,
      "z": -2,
      "name": "Empty"
    },
    {
