{
  "version": 8,
  "blockIdVersion": 8,
  "anchorX": 6,
  "anchorY": 5,
  "anchorZ": 5,
  "blocks": [
    {
      "x": 3,
      "y": 5,
      "z": 2,
      "name": "Rock_Volcanic"
    },
    {
      "x": 3,
      "y": 6,
      "z": 2,
      "name": "Rubble_Volcanic"
    },
    {
      "x": 3,
      "y": 4,
      "z": 3,
      "name": "Rock_Volcanic"
    },
    {
      "x": 3,
      "y": 5,
      "z": 3,
      "name": "Rock_Volcanic"
    },
    {
      "x": 4,
      "y": 5,
      "z": 1,
      "name": "Rock_Volcanic"
    },
    {
      "x": 4,
      "y": 3,
      "z": 2,
      "name": "Rock_Volcanic"
    },
    {
      "x": 4,
      "y": 4,
      "z": 2,
      "name": "Rock_Volcanic"
    },
    {
      "x": 4,
      "y": 5,
      "z": 2,
      "name": "Rock_Volcanic"
    },
    {
      "x": 4,
      "y": 6,
      "z": 2,
      "name": "Rock_Volcanic"
    },
    {
      "x": 4,
      "y": 3,
      "z": 3,
      "name": "Rock_Volcanic"
    },
    {
      "x": 4,
      "y": 4,
      "z": 3,
      "name": "Rock_Volcanic"
    },
    {
      "x": 4,
      "y": 5,
      "z": 3,
      "name": "Rock_Volcanic"
    },
    {
      "x": 4,
      "y": 6,
      "z": 3,
      "name": "Rock_Volcanic"
    },
    {
      "x": 4,
      "y": 4,
      "z": 4,
      "name": "Rock_Volcanic"
    },
    {
      "x": 4,
      "y": 5,
      "z": 4,
      "name": "Rock_Volcanic"
    },
    {
      "x": 5,
      "y": 4,
      "z": 1,
      "name": "Rock_Volcanic"
    },
    {
      "x": 5,
      "y": 5,
      "z": 1,
      "name": "Rock_Volcanic"
    },
    {
      "x": 5,
      "y": 6,
      "z": 1,
      "name": "Rock_Volcanic"
    },
    {
      "x": 5,
      "y": 2,
      "z": 2,
      "name": "Rock_Volcanic"
    },
    {
      "x": 5,
      "y": 3,
      "z": 2,
      "name": "Rock_Volcanic"
    },
    {
      "x": 5,
      "y": 4,
      "z": 2,
      "name": "Rock_Volcanic"
    },
    {
      "x": 5,
      "y": 5,
      "z": 2,
      "name": "Rock_Volcanic"
    },
    {
      "x": 5,
      "y": 6,
      "z": 2,
      "name": "Rock_Volcanic"
    },
    {
      "x": 5,
      "y": 2,
      "z": 3,
      "name": "Rock_Volcanic"
    },
    {
      "x": 5,
      "y": 3,
      "z": 3,
      "name": "Rock_Volcanic"
    },
    {
      "x": 5,
      "y": 4,
      "z": 3,
      "name": "Rock_Volcanic"
    },
    {
      "x": 5,
      "y": 5,
      "z": 3,
      "name": "Rock_Volcanic"
    },
    {
      "x": 5,
      "y": 6,
      "z": 3,
      "name": "Rock_Volcanic"
    },
    {
      "x": 5,
      "y": 3,
      "z": 4,
      "name": "Rock_Volcanic"
    },
    {
      "x": 5,
      "y": 4,
      "z": 4,
      "name": "Rock_Volcanic"
    },
    {
      "x": 5,
      "y": 5,
      "z": 4,
      "name": "Rock_Volcanic"
    },
    {
      "x": 5,
      "y": 6,
      "z": 4,
      "name": "Rock_Volcanic"
    },
    {
      "x": 5,
      "y": 5,
      "z": 5,
      "name": "Rock_Volcanic"
    },
    {
      "x": 6,
      "y": 2,
      "z": 2,
      "name": "Rock_Volcanic"
    },
    {
      "x": 6,
      "y": 3,
      "z": 2,
      "name": "Rock_Volcanic"
    },
    {
      "x": 6,
      "y": 4,
      "z": 2,
      "name": "Rock_Volcanic"
    },
    {
      "x": 6,
      "y": 5,
      "z": 2,
      "name": "Rock_Volcanic"
    },
    {
      "x": 6,
      "y": 6,
      "z": 2,
      "name": "Rock_Volcanic"
    },
    {
      "x": 6,
      "y": 2,
      "z": 3,
      "name": "Rock_Volcanic"
    },
    {
      "x": 6,
      "y": 3,
      "z": 3,
      "name": "Rock_Volcanic"
    },
    {
      "x": 6,
      "y": 4,
      "z": 3,
      "name": "Rock_Volcanic"
    },
    {
      "x": 6,
      "y": 5,
      "z": 3,
      "name": "Rock_Volcanic"
    },
    {
      "x": 6,
      "y": 6,
      "z": 3,
      "name": "Rock_Volcanic_Cracked_Lava"
    },
    {
      "x": 6,
      "y": 7,
      "z": 3,
      "name": "Rubble_Volcanic"
    },
    {
      "x": 6,
      "y": 2,
      "z": 4,
      "name": "Rock_Volcanic"
    },
    {
      "x": 6,
      "y": 3,
      "z": 4,
      "name": "Rock_Volcanic"
    },
    {
      "x": 6,
      "y": 4,
      "z": 4,
      "name": "Rock_Volcanic"
    },
    {
      "x": 6,
      "y": 5,
      "z": 4,
      "name": "Rock_Volcanic"
    },
    {
      "x": 6,
      "y": 6,
      "z": 4,
      "name": "Rock_Volcanic_Cracked_Lava"
    },
    {
      "x": 6,
      "y": 7,
      "z": 4,
      "name": "Rock_Volcanic_Cracked_Lava"
    },
    {
      "x": 6,
      "y": 3,
      "z": 5,
      "name": "Rock_Volcanic"
    },
    {
      "x": 6,
      "y": 4,
      "z": 5,
      "name": "Rock_Volcanic"
    },
    {
      "x": 6,
      "y": 5,
      "z": 5,
      "name": "Rock_Volcanic"
    },
    {
      "x": 6,
      "y": 6,
      "z": 5,
      "name": "Rock_Volcanic_Cracked_Lava"
    },
    {
      "x": 6,
      "y": 7,
      "z": 5,
      "name": "Rock_Volcanic_Cracked_Lava"
    },
    {
      "x": 6,
      "y": 4,
      "z": 6,
      "name": "Rock_Volcanic"
    },
    {
      "x": 6,
      "y": 5,
      "z": 6,
      "name": "Rock_Volcanic"
    },
    {
      "x": 6,
      "y": 6,
      "z": 6,
      "name": "Rock_Volcanic"
    },
    {
      "x": 7,
      "y": 3,
      "z": 2,
      "name": "Rock_Volcanic"
    },
    {
      "x": 7,
      "y": 4,
      "z": 2,
      "name": "Rock_Volcanic"
    },
    {
      "x": 7,
      "y": 5,
      "z": 2,
      "name": "Rock_Volcanic"
    },
    {
      "x": 7,
      "y": 2,
      "z": 3,
      "name": "Rock_Volcanic"
    },
    {
      "x": 7,
      "y": 3,
      "z": 3,
      "name": "Rock_Volcanic"
    },
    {
      "x": 7,
      "y": 4,
      "z": 3,
      "name": "Rock_Volcanic"
    },
    {
      "x": 7,
      "y": 5,
      "z": 3,
      "name": "Rock_Volcanic"
    },
    {
      "x": 7,
      "y": 6,
      "z": 3,
      "name": "Rock_Volcanic"
    },
    {
      "x": 7,
      "y": 1,
      "z": 4,
      "name": "Rock_Volcanic"
    },
    {
      "x": 7,
      "y": 2,
      "z": 4,
      "name": "Rock_Volcanic"
    },
    {
      "x": 7,
      "y": 3,
      "z": 4,
      "name": "Rock_Volcanic"
    },
    {
      "x": 7,
      "y": 4,
      "z": 4,
      "name": "Rock_Volcanic"
    },
    {
      "x": 7,
      "y": 5,
      "z": 4,
      "name": "Rock_Volcanic"
    },
    {
      "x": 7,
      "y": 6,
      "z": 4,
      "name": "Rock_Volcanic_Cracked_Lava"
    },
    {
      "x": 7,
      "y": 7,
      "z": 4,
      "name": "Rubble_Volcanic"
    },
    {
      "x": 7,
      "y": 1,
      "z": 5,
      "name": "Rock_Volcanic"
    },
    {
      "x": 7,
      "y": 2,
      "z": 5,
      "name": "Rock_Volcanic"
    },
    {
      "x": 7,
      "y": 3,
      "z": 5,
      "name": "Rock_Volcanic"
    },
    {
      "x": 7,
      "y": 4,
      "z": 5,
      "name": "Rock_Volcanic"
    },
    {
      "x": 7,
      "y": 5,
      "z": 5,
      "name": "Rock_Volcanic"
    },
    {
      "x": 7,
      "y": 6,
      "z": 5,
      "name": "Rock_Volcanic"
    },
    {
      "x": 7,
      "y": 7,
      "z": 5,
      "name": "Rock_Volcanic"
    },
    {
      "x": 7,
      "y": 8,
      "z": 5,
      "name": "Rubble_Volcanic"
    },
    {
      "x": 7,
      "y": 1,
      "z": 6,
      "name": "Rock_Volcanic"
    },
    {
      "x": 7,
      "y": 2,
      "z": 6,
      "name": "Rock_Volcanic"
    },
    {
      "x": 7,
      "y": 3,
      "z": 6,
      "name": "Rock_Volcanic"
    },
    {
      "x": 7,
      "y": 4,
      "z": 6,
      "name": "Rock_Volcanic"
    },
    {
      "x": 7,
      "y": 5,
      "z": 6,
      "name": "Rock_Volcanic"
    },
    {
      "x": 7,
      "y": 6,
      "z": 6,
      "name": "Rock_Volcanic"
    },
    {
      "x": 7,
      "y": 7,
      "z": 6,
      "name": "Rock_Volcanic"
    },
    {
      "x": 7,
      "y": 3,
      "z": 7,
      "name": "Rock_Volcanic"
    },
    {
      "x": 7,
      "y": 4,
      "z": 7,
      "name": "Rock_Volcanic"
    },
    {
      "x": 7,
      "y": 5,
      "z": 7,
      "name": "Rock_Volcanic"
    },
    {
      "x": 7,
      "y": 6,
      "z": 7,
      "name": "Rock_Volcanic"
    },
    {
      "x": 8,
      "y": 3,
      "z": 4,
      "name": "Rock_Volcanic"
    },
    {
      "x": 8,
      "y": 4,
      "z": 4,
      "name": "Rock_Volcanic"
    },
    {
      "x": 8,
      "y": 5,
      "z": 4,
      "name": "Rock_Volcanic"
    },
    {
      "x": 8,
      "y": 6,
      "z": 4,
      "name": "Rock_Volcanic"
    },
    {
      "x": 8,
      "y": 7,
      "z": 4,
      "name": "Rubble_Volcanic"
    },
    {
      "x": 8,
      "y": 1,
      "z": 5,
      "name": "Rock_Volcanic"
    },
    {
      "x": 8,
      "y": 2,
      "z": 5,
      "name": "Rock_Volcanic"
    },
    {
      "x": 8,
      "y": 3,
      "z": 5,
      "name": "Rock_Volcanic"
    },
    {
      "x": 8,
      "y": 4,
      "z": 5,
      "name": "Rock_Volcanic"
    },
    {
      "x": 8,
      "y": 5,
      "z": 5,
      "name": "Rock_Volcanic"
    },
    {
      "x": 8,
      "y": 6,
      "z": 5,
      "name": "Rock_Volcanic_Cracked_Lava"
    },
    {
      "x": 8,
      "y": 7,
      "z": 5,
      "name": "Rock_Volcanic_Cracked_Lava"
    },
    {
      "x": 8,
      "y": 1,
      "z": 6,
      "name": "Rock_Volcanic"
    },
    {
      "x": 8,
      "y": 2,
      "z": 6,
      "name": "Rock_Volcanic"
    },
    {
      "x": 8,
      "y": 3,
      "z": 6,
      "name": "Rock_Volcanic"
    },
    {
      "x": 8,
      "y": 4,
      "z": 6,
      "name": "Rock_Volcanic"
    },
    {
      "x": 8,
      "y": 5,
      "z": 6,
      "name": "Rock_Volcanic"
    },
    {
      "x": 8,
      "y": 6,
      "z": 6,
      "name": "Rock_Volcanic"
    },
    {
      "x": 8,
      "y": 7,
      "z": 6,
      "name": "Rock_Volcanic"
    },
    {
      "x": 8,
      "y": 2,
      "z": 7,
      "name": "Rock_Volcanic"
    },
    {
      "x": 8,
      "y": 3,
      "z": 7,
      "name": "Rock_Volcanic"
    },
    {
      "x": 8,
      "y": 4,
      "z": 7,
      "name": "Rock_Volcanic"
    },
    {
      "x": 8,
      "y": 5,
      "z": 7,
      "name": "Rock_Volcanic_Cracked_Lava"
    },
    {
      "x": 9,
      "y": 4,
      "z": 4,
      "name": "Rock_Volcanic"
    },
    {
      "x": 9,
      "y": 5,
      "z": 4,
      "name": "Rock_Volcanic"
    },
    {
      "x": 9,
      "y": 3,
      "z": 5,
      "name": "Rock_Volcanic"
    },
    {
      "x": 9,
      "y": 4,
      "z": 5,
      "name": "Rock_Volcanic"
    },
    {
      "x": 9,
      "y": 5,
      "z": 5,
      "name": "Rock_Volcanic"
    },
    {
      "x": 9,
      "y": 6,
      "z": 5,
      "name": "Rock_Volcanic"
    },
    {
      "x": 9,
      "y": 2,
      "z": 6,
      "name": "Rock_Volcanic"
    },
    {
      "x": 9,
      "y": 3,
      "z": 6,
      "name": "Rock_Volcanic"
    },
    {
      "x": 9,
      "y": 4,
      "z": 6,
      "name": "Rock_Volcanic"
    },
    {
      "x": 9,
      "y": 5,
      "z": 6,
      "name": "Rock_Volcanic"
    },
    {
      "x": 9,
      "y": 6,
      "z": 6,
      "name": "Rock_Volcanic_Cracked_Lava"
    },
    {
      "x": 9,
      "y": 5,
      "z": 7,
      "name": "Rock_Volcanic"
    },
    {
      "x": 10,
      "y": 4,
      "z": 5,
      "name": "Rock_Volcanic"
    },
    {
      "x": 10,
      "y": 5,
      "z": 5,
      "name": "Rock_Volcanic"
    },
    {
      "x": 10,
      "y": 3,
      "z": 6,
      "name": "Rock_Volcanic"
    },
    {
      "x": 10,
      "y": 4,
      "z": 6,
      "name": "Rock_Volcanic"
    },
    {
      "x": 10,
      "y": 5,
      "z": 6,
      "name": "Rock_Volcanic"
    }
  ]
}