{
  "version": 8,
  "blockIdVersion": 8,
  "anchorX": 5,
  "anchorY": 4,
  "anchorZ": 8,
  "blocks": [
    {
      "x": 1,
      "y": 15,
      "z": 9,
      "name": "Plant_Leaves_Birch"
    },
    {
      "x": 2,
      "y": 14,
      "z": 7,
      "name": "Plant_Leaves_Birch"
    },
    {
      "x": 2,
      "y": 15,
      "z": 7,
      "name": "Plant_Leaves_Birch"
    },
    {
      "x": 2,
      "y": 17,
      "z": 7,
      "name": "Plant_Leaves_Birch"
    },
    {
      "x": 2,
      "y": 12,
      "z": 8,
      "name": "Plant_Leaves_Birch"
    },
    {
      "x": 2,
      "y": 13,
      "z": 8,
      "name": "Plant_Leaves_Birch"
    },
    {
      "x": 2,
      "y": 14,
      "z": 8,
      "name": "Plant_Leaves_Birch"
    },
    {
      "x": 2,
      "y": 15,
      "z": 8,
      "name": "Plant_Leaves_Birch"
    },
    {
      "x": 2,
      "y": 16,
      "z": 8,
      "name": "Plant_Leaves_Birch"
    },
    {
      "x": 2,
      "y": 17,
      "z": 8,
      "name": "Plant_Leaves_Birch"
    },
    {
      "x": 2,
      "y": 18,
      "z": 8,
      "name": "Plant_Leaves_Birch"
    },
    {
      "x": 2,
      "y": 13,
      "z": 9,
      "name": "Plant_Leaves_Birch"
    },
    {
      "x": 2,
      "y": 14,
      "z": 9,
      "name": "Plant_Leaves_Birch"
    },
    {
      "x": 2,
      "y": 15,
      "z": 9,
      "name": "Plant_Leaves_Birch"
    },
    {
      "x": 2,
      "y": 17,
      "z": 9,
      "name": "Plant_Leaves_Birch"
    },
    {
      "x": 2,
      "y": 18,
      "z": 9,
      "name": "Plant_Leaves_Birch"
    },
    {
      "x": 2,
      "y": 19,
      "z": 9,
      "name": "Plant_Leaves_Birch"
    },
    {
      "x": 2,
      "y": 11,
      "z": 10,
      "name": "Plant_Leaves_Birch"
    },
    {
      "x": 2,
      "y": 12,
      "z": 10,
      "name": "Plant_Leaves_Birch"
    },
    {
      "x": 2,
      "y": 13,
      "z": 10,
      "name": "Plant_Leaves_Birch"
    },
    {
      "x": 2,
      "y": 15,
      "z": 10,
      "name": "Plant_Leaves_Birch"
    },
    {
      "x": 2,
      "y": 17,
      "z": 10,
      "name": "Plant_Leaves_Birch"
    },
    {
      "x": 2,
      "y": 13,
      "z": 11,
      "name": "Plant_Leaves_Birch"
    },
    {
      "x": 2,
      "y": 18,
      "z": 11,
      "name": "Plant_Leaves_Birch"
    },
    {
      "x": 3,
      "y": 12,
      "z": 5,
      "name": "Plant_Leaves_Birch"
    },
    {
      "x": 3,
      "y": 13,
      "z": 5,
      "name": "Plant_Leaves_Birch"
    },
    {
      "x": 3,
      "y": 14,
      "z": 5,
      "name": "Plant_Leaves_Birch"
    },
    {
      "x": 3,
      "y": 11,
      "z": 6,
      "name": "Plant_Leaves_Birch"
    },
    {
      "x": 3,
      "y": 14,
      "z": 6,
      "name": "Plant_Leaves_Birch"
    },
    {
      "x": 3,
      "y": 15,
      "z": 6,
      "name": "Plant_Leaves_Birch"
    },
    {
      "x": 3,
      "y": 16,
      "z": 6,
      "name": "Plant_Leaves_Birch"
    },
    {
      "x": 3,
      "y": 17,
      "z": 6,
      "name": "Plant_Leaves_Birch"
    },
    {
      "x": 3,
      "y": 10,
      "z": 7,
      "name": "Plant_Leaves_Birch"
    },
    {
      "x": 3,
      "y": 11,
      "z": 7,
      "name": "Plant_Leaves_Birch"
    },
    {
      "x": 3,
      "y": 12,
      "z": 7,
      "name": "Plant_Leaves_Birch"
    },
    {
      "x": 3,
      "y": 13,
      "z": 7,
      "name": "Plant_Leaves_Birch"
    },
    {
      "x": 3,
      "y": 14,
      "z": 7,
      "name": "Plant_Leaves_Birch"
    },
    {
      "x": 3,
      "y": 15,
      "z": 7,
      "name": "Plant_Leaves_Birch"
    },
    {
      "x": 3,
      "y": 17,
      "z": 7,
      "name": "Plant_Leaves_Birch"
    },
    {
      "x": 3,
      "y": 18,
      "z": 7,
      "name": "Plant_Leaves_Birch"
    },
    {
      "x": 3,
      "y": 11,
      "z": 8,
      "name": "Plant_Leaves_Birch"
    },
    {
      "x": 3,
      "y": 12,
      "z": 8,
      "name": "Plant_Leaves_Birch"
    },
    {
      "x": 3,
      "y": 15,
      "z": 8,
      "name": "Plant_Leaves_Birch"
    },
    {
      "x": 3,
      "y": 16,
      "z": 8,
      "name": "Plant_Leaves_Birch"
    },
    {
      "x": 3,
      "y": 17,
      "z": 8,
      "name": "Plant_Leaves_Birch"
    },
    {
      "x": 3,
      "y": 18,
      "z": 8,
      "name": "Plant_Leaves_Birch"
    },
    {
      "x": 3,
      "y": 19,
      "z": 8,
      "name": "Plant_Leaves_Birch"
    },
    {
      "x": 3,
      "y": 12,
      "z": 9,
      "name": "Plant_Leaves_Birch"
    },
    {
      "x": 3,
      "y": 14,
      "z": 9,
      "name": "Plant_Leaves_Birch"
    },
    {
      "x": 3,
      "y": 17,
      "z": 9,
      "name": "Wood_Birch_Branch_Long",
      "rotation": 5
    },
    {
      "x": 3,
      "y": 19,
      "z": 9,
      "name": "Plant_Leaves_Birch"
    },
    {
      "x": 3,
      "y": 20,
      "z": 9,
      "name": "Plant_Leaves_Birch"
    },
    {
      "x": 3,
      "y": 21,
      "z": 9,
      "name": "Plant_Leaves_Birch"
    },
    {
      "x": 3,
      "y": 22,
      "z": 9,
      "name": "Plant_Leaves_Birch"
    },
    {
      "x": 3,
      "y": 24,
      "z": 9,
      "name": "Plant_Leaves_Birch"
    },
    {
      "x": 3,
      "y": 25,
      "z": 9,
      "name": "Plant_Leaves_Birch"
    },
    {
      "x": 3,
      "y": 13,
      "z": 10,
      "name": "Plant_Leaves_Birch"
    },
    {
      "x": 3,
      "y": 14,
      "z": 10,
      "name": "Plant_Leaves_Birch"
    },
    {
      "x": 3,
      "y": 15,
      "z": 10,
      "name": "Plant_Leaves_Birch"
    },
    {
      "x": 3,
      "y": 17,
      "z": 10,
      "name": "Plant_Leaves_Birch"
    },
    {
      "x": 3,
      "y": 18,
      "z": 10,
      "name": "Plant_Leaves_Birch"
    },
    {
      "x": 3,
      "y": 19,
      "z": 10,
      "name": "Plant_Leaves_Birch"
    },
    {
      "x": 3,
      "y": 20,
      "z": 10,
      "name": "Plant_Leaves_Birch"
    },
    {
      "x": 3,
      "y": 21,
      "z": 10,
      "name": "Plant_Leaves_Birch"
    },
    {
      "x": 3,
      "y": 22,
      "z": 10,
      "name": "Plant_Leaves_Birch"
    },
    {
      "x": 3,
      "y": 23,
      "z": 10,
      "name": "Plant_Leaves_Birch"
    },
    {
      "x": 3,
      "y": 24,
      "z": 10,
      "name": "Plant_Leaves_Birch"
    },
    {
      "x": 3,
      "y": 25,
      "z": 10,
      "name": "Plant_Leaves_Birch"
    },
    {
      "x": 3,
      "y": 26,
      "z": 10,
      "name": "Plant_Leaves_Birch"
    },
    {
      "x": 3,
      "y": 10,
      "z": 11,
      "name": "Plant_Leaves_Birch"
    },
    {
      "x": 3,
      "y": 11,
      "z": 11,
      "name": "Plant_Leaves_Birch"
    },
    {
      "x": 3,
      "y": 12,
      "z": 11,
      "name": "Plant_Leaves_Birch"
    },
    {
      "x": 3,
      "y": 13,
      "z": 11,
      "name": "Plant_Leaves_Birch"
    },
    {
      "x": 3,
      "y": 14,
      "z": 11,
      "name": "Plant_Leaves_Birch"
    },
    {
      "x": 3,
      "y": 15,
      "z": 11,
      "name": "Plant_Leaves_Birch"
    },
    {
      "x": 3,
      "y": 16,
      "z": 11,
      "name": "Plant_Leaves_Birch"
    },
    {
      "x": 3,
      "y": 18,
      "z": 11,
      "name": "Plant_Leaves_Birch"
    },
    {
      "x": 3,
      "y": 22,
      "z": 11,
      "name": "Plant_Leaves_Birch"
    },
    {
      "x": 3,
      "y": 23,
      "z": 11,
      "name": "Plant_Leaves_Birch"
    },
    {
      "x": 3,
      "y": 24,
      "z": 11,
      "name": "Plant_Leaves_Birch"
    },
    {
      "x": 3,
      "y": 25,
      "z": 11,
      "name": "Plant_Leaves_Birch"
    },
    {
      "x": 3,
      "y": 14,
      "z": 12,
      "name": "Plant_Leaves_Birch"
    },
    {
      "x": 3,
      "y": 15,
      "z": 12,
      "name": "Plant_Leaves_Birch"
    },
    {
      "x": 3,
      "y": 16,
      "z": 12,
      "name": "Plant_Leaves_Birch"
    },
    {
      "x": 3,
      "y": 17,
      "z": 12,
      "name": "Plant_Leaves_Birch"
    },
    {
      "x": 3,
      "y": 18,
      "z": 12,
      "name": "Plant_Leaves_Birch"
    },
    {
      "x": 3,
      "y": 19,
      "z": 12,
      "name": "Plant_Leaves_Birch"
    },
    {
      "x": 3,
      "y": 20,
      "z": 12,
      "name": "Plant_Leaves_Birch"
    },
    {
      "x": 3,
      "y": 14,
      "z": 13,
      "name": "Plant_Leaves_Birch"
    },
    {
      "x": 4,
      "y": 10,
      "z": 5,
      "name": "Plant_Leaves_Birch"
    },
    {
      "x": 4,
      "y": 11,
      "z": 5,
      "name": "Plant_Leaves_Birch"
    },
    {
      "x": 4,
      "y": 12,
      "z": 5,
      "name": "Plant_Leaves_Birch"
    },
    {
      "x": 4,
      "y": 13,
      "z": 5,
      "name": "Plant_Leaves_Birch"
    },
    {
      "x": 4,
      "y": 14,
      "z": 5,
      "name": "Plant_Leaves_Birch"
    },
    {
      "x": 4,
      "y": 15,
      "z": 5,
      "name": "Plant_Leaves_Birch"
    },
    {
      "x": 4,
      "y": 16,
      "z": 5,
      "name": "Plant_Leaves_Birch"
    },
    {
      "x": 4,
      "y": 11,
      "z": 6,
      "name": "Plant_Leaves_Birch"
    },
    {
      "x": 4,
      "y": 12,
      "z": 6,
      "name": "Wood_Birch_Branch_Corner",
      "rotation": 3
    },
    {
      "x": 4,
      "y": 13,
      "z": 6,
      "name": "Plant_Leaves_Birch"
    },
    {
      "x": 4,
      "y": 14,
      "z": 6,
      "name": "Wood_Birch_Branch_Long"
    },
    {
      "x": 4,
      "y": 15,
      "z": 6,
      "name": "Plant_Leaves_Birch"
    },
    {
      "x": 4,
      "y": 16,
      "z": 6,
      "name": "Plant_Leaves_Birch"
    },
    {
      "x": 4,
      "y": 17,
      "z": 6,
      "name": "Plant_Leaves_Birch"
    },
    {
      "x": 4,
      "y": 18,
      "z": 7,
      "name": "Plant_Leaves_Birch"
    },
    {
      "x": 4,
      "y": 19,
      "z": 7,
      "name": "Plant_Leaves_Birch"
    },
    {
      "x": 4,
      "y": 1,
      "z": 8,
      "name": "Wood_Birch_Trunk"
    },
    {
      "x": 4,
      "y": 2,
      "z": 8,
      "name": "Wood_Birch_Trunk"
    },
    {
      "x": 4,
      "y": 3,
      "z": 8,
      "name": "Wood_Birch_Trunk"
    },
    {
      "x": 4,
      "y": 4,
      "z": 8,
      "name": "Wood_Birch_Trunk"
    },
    {
      "x": 4,
      "y": 5,
      "z": 8,
      "name": "Wood_Birch_Trunk_Full"
    },
    {
      "x": 4,
      "y": 12,
      "z": 8,
      "name": "Wood_Birch_Trunk_Full"
    },
    {
      "x": 4,
      "y": 13,
      "z": 8,
      "name": "Wood_Birch_Branch_Long"
    },
    {
      "x": 4,
      "y": 14,
      "z": 8,
      "name": "Wood_Birch_Branch_Long"
    },
    {
      "x": 4,
      "y": 15,
      "z": 8,
      "name": "Wood_Birch_Branch_Long"
    },
    {
      "x": 4,
      "y": 16,
      "z": 8,
      "name": "Wood_Birch_Branch_Long"
    },
    {
      "x": 4,
      "y": 18,
      "z": 8,
      "name": "Plant_Leaves_Birch"
    },
    {
      "x": 4,
      "y": 19,
      "z": 8,
      "name": "Plant_Leaves_Birch"
    },
    {
      "x": 4,
      "y": 20,
      "z": 8,
      "name": "Plant_Leaves_Birch"
    },
    {
      "x": 4,
      "y": 21,
      "z": 8,
      "name": "Plant_Leaves_Birch"
    },
    {
      "x": 4,
      "y": 22,
      "z": 8,
      "name": "Plant_Leaves_Birch"
    },
    {
      "x": 4,
      "y": 23,
      "z": 8,
      "name": "Plant_Leaves_Birch"
    },
    {
      "x": 4,
      "y": 24,
      "z": 8,
      "name": "Plant_Leaves_Birch"
    },
    {
      "x": 4,
      "y": 17,
      "z": 9,
      "name": "Wood_Birch_Branch_Long",
      "rotation": 5
    },
    {
      "x": 4,
      "y": 26,
      "z": 9,
      "name": "Plant_Leaves_Birch"
    },
    {
      "x": 4,
      "y": 27,
      "z": 9,
      "name": "Plant_Leaves_Birch"
    },
    {
      "x": 4,
      "y": 20,
      "z": 10,
      "name": "Wood_Birch_Branch_Long",
      "rotation": 5
    },
    {
      "x": 4,
      "y": 22,
      "z": 10,
      "name": "Wood_Birch_Branch_Corner",
      "rotation": 3
    },
    {
      "x": 4,
      "y": 23,
      "z": 10,
      "name": "Wood_Birch_Branch_Long"
    },
    {
      "x": 4,
      "y": 24,
      "z": 10,
      "name": "Wood_Birch_Branch_Long"
    },
    {
      "x": 4,
      "y": 25,
      "z": 10,
      "name": "Wood_Birch_Branch_Long"
    },
    {
      "x": 4,
      "y": 26,
      "z": 10,
      "name": "Plant_Leaves_Birch"
    },
    {
      "x": 4,
      "y": 27,
      "z": 10,
      "name": "Plant_Leaves_Birch"
    },
    {
      "x": 4,
      "y": 13,
      "z": 11,
      "name": "Plant_Leaves_Birch"
    },
    {
      "x": 4,
      "y": 14,
      "z": 11,
      "name": "Wood_Birch_Branch_Corner",
      "rotation": 3
    },
    {
      "x": 4,
      "y": 15,
      "z": 11,
      "name": "Wood_Birch_Branch_Long"
    },
    {
      "x": 4,
      "y": 16,
      "z": 11,
      "name": "Wood_Birch_Branch_Long"
    },
    {
      "x": 4,
      "y": 17,
      "z": 11,
      "name": "Plant_Leaves_Birch"
    },
    {
      "x": 4,
      "y": 18,
      "z": 11,
      "name": "Plant_Leaves_Birch"
    },
    {
      "x": 4,
      "y": 19,
      "z": 11,
      "name": "Plant_Leaves_Birch"
    },
    {
      "x": 4,
      "y": 20,
      "z": 11,
      "name": "Plant_Leaves_Birch"
    },
    {
      "x": 4,
      "y": 23,
      "z": 11,
      "name": "Plant_Leaves_Birch"
    },
    {
      "x": 4,
      "y": 26,
      "z": 11,
      "name": "Plant_Leaves_Birch"
    },
    {
      "x": 4,
      "y": 12,
      "z": 12,
      "name": "Plant_Leaves_Birch"
    },
    {
      "x": 4,
      "y": 13,
      "z": 12,
      "name": "Plant_Leaves_Birch"
    },
    {
      "x": 4,
      "y": 17,
      "z": 12,
      "name": "Plant_Leaves_Birch"
    },
    {
      "x": 4,
      "y": 18,
      "z": 12,
      "name": "Plant_Leaves_Birch"
    },
    {
      "x": 4,
      "y": 19,
      "z": 12,
      "name": "Plant_Leaves_Birch"
    },
    {
      "x": 4,
      "y": 20,
      "z": 12,
      "name": "Plant_Leaves_Birch"
    },
    {
      "x": 4,
      "y": 21,
      "z": 12,
      "name": "Plant_Leaves_Birch"
    },
    {
      "x": 4,
      "y": 22,
      "z": 12,
      "name": "Plant_Leaves_Birch"
    },
    {
      "x": 4,
      "y": 23,
      "z": 12,
      "name": "Plant_Leaves_Birch"
    },
    {
      "x": 4,
      "y": 24,
      "z": 12,
      "name": "Plant_Leaves_Birch"
    },
    {
      "x": 4,
      "y": 14,
      "z": 13,
      "name": "Plant_Leaves_Birch"
    },
    {
      "x": 4,
      "y": 15,
      "z": 13,
      "name": "Plant_Leaves_Birch"
    },
    {
      "x": 4,
      "y": 16,
      "z": 13,
      "name": "Plant_Leaves_Birch"
    },
    {
      "x": 4,
      "y": 17,
      "z": 13,
      "name": "Plant_Leaves_Birch"
    },
    {
      "x": 4,
      "y": 18,
      "z": 13,
      "name": "Plant_Leaves_Birch"
    },
    {
      "x": 4,
      "y": 19,
      "z": 13,
      "name": "Plant_Leaves_Birch"
    },
    {
      "x": 4,
      "y": 20,
      "z": 13,
      "name": "Plant_Leaves_Birch"
    },
    {
      "x": 5,
      "y": 14,
      "z": 4,
      "name": "Plant_Leaves_Birch"
    },
    {
      "x": 5,
      "y": 10,
      "z": 5,
      "name": "Plant_Leaves_Birch"
    },
    {
      "x": 5,
      "y": 11,
      "z": 5,
      "name": "Plant_Leaves_Birch"
    },
    {
      "x": 5,
      "y": 12,
      "z": 5,
      "name": "Plant_Leaves_Birch"
    },
    {
      "x": 5,
      "y": 13,
      "z": 5,
      "name": "Plant_Leaves_Birch"
    },
    {
      "x": 5,
      "y": 14,
      "z": 5,
      "name": "Plant_Leaves_Birch"
    },
    {
      "x": 5,
      "y": 15,
      "z": 5,
      "name": "Plant_Leaves_Birch"
    },
    {
      "x": 5,
      "y": 16,
      "z": 5,
      "name": "Plant_Leaves_Birch"
    },
    {
      "x": 5,
      "y": 9,
      "z": 6,
      "name": "Plant_Leaves_Birch"
    },
    {
      "x": 5,
      "y": 10,
      "z": 6,
      "name": "Plant_Leaves_Birch"
    },
    {
      "x": 5,
      "y": 11,
      "z": 6,
      "name": "Wood_Birch_Trunk_Full"
    },
    {
      "x": 5,
      "y": 12,
      "z": 6,
      "name": "Wood_Birch_Trunk_Full"
    },
    {
      "x": 5,
      "y": 13,
      "z": 6,
      "name": "Wood_Birch_Branch_Long"
    },
    {
      "x": 5,
      "y": 14,
      "z": 6,
      "name": "Wood_Birch_Branch_Long"
    },
    {
      "x": 5,
      "y": 15,
      "z": 6,
      "name": "Wood_Birch_Branch_Long"
    },
    {
      "x": 5,
      "y": 16,
      "z": 6,
      "name": "Plant_Leaves_Birch"
    },
    {
      "x": 5,
      "y": 17,
      "z": 6,
      "name": "Plant_Leaves_Birch"
    },
    {
      "x": 5,
      "y": 18,
      "z": 6,
      "name": "Plant_Leaves_Birch"
    },
    {
      "x": 5,
      "y": 0,
      "z": 7,
      "name": "Wood_Birch_Trunk"
    },
    {
      "x": 5,
      "y": 1,
      "z": 7,
      "name": "Wood_Birch_Trunk"
    },
    {
      "x": 5,
      "y": 2,
      "z": 7,
      "name": "Wood_Birch_Trunk"
    },
    {
      "x": 5,
      "y": 3,
      "z": 7,
      "name": "Wood_Birch_Trunk"
    },
    {
      "x": 5,
      "y": 4,
      "z": 7,
      "name": "Wood_Birch_Trunk"
    },
    {
      "x": 5,
      "y": 5,
      "z": 7,
      "name": "Wood_Birch_Trunk"
    },
    {
      "x": 5,
      "y": 6,
      "z": 7,
      "name": "Wood_Birch_Trunk_Full"
    },
    {
      "x": 5,
      "y": 11,
      "z": 7,
      "name": "Wood_Birch_Trunk_Full"
    },
    {
      "x": 5,
      "y": 18,
      "z": 7,
      "name": "Plant_Leaves_Birch"
    },
    {
      "x": 5,
      "y": 19,
      "z": 7,
      "name": "Plant_Leaves_Birch"
    },
    {
      "x": 5,
      "y": 20,
      "z": 7,
      "name": "Plant_Leaves_Birch"
    },
    {
      "x": 5,
      "y": 21,
      "z": 7,
      "name": "Plant_Leaves_Birch"
    },
    {
      "x": 5,
      "y": 0,
      "z": 8,
      "name": "Wood_Birch_Trunk"
    },
    {
      "x": 5,
      "y": 1,
      "z": 8,
      "name": "Wood_Birch_Trunk"
    },
    {
      "x": 5,
      "y": 2,
      "z": 8,
      "name": "Wood_Birch_Trunk"
    },
    {
      "x": 5,
      "y": 3,
      "z": 8,
      "name": "Wood_Birch_Trunk"
    },
    {
      "x": 5,
      "y": 4,
      "z": 8,
      "name": "Wood_Birch_Trunk"
    },
    {
      "x": 5,
      "y": 5,
      "z": 8,
      "name": "Wood_Birch_Trunk"
    },
    {
      "x": 5,
      "y": 6,
      "z": 8,
      "name": "Wood_Birch_Trunk"
    },
    {
      "x": 5,
      "y": 7,
      "z": 8,
      "name": "Wood_Birch_Trunk"
    },
    {
      "x": 5,
      "y": 8,
      "z": 8,
      "name": "Wood_Birch_Trunk"
    },
    {
      "x": 5,
      "y": 9,
      "z": 8,
      "name": "Wood_Birch_Trunk"
    },
    {
      "x": 5,
      "y": 10,
      "z": 8,
      "name": "Wood_Birch_Trunk"
    },
    {
      "x": 5,
      "y": 11,
      "z": 8,
      "name": "Wood_Birch_Trunk"
    },
    {
      "x": 5,
      "y": 12,
      "z": 8,
      "name": "Wood_Birch_Trunk"
    },
    {
      "x": 5,
      "y": 13,
      "z": 8,
      "name": "Wood_Birch_Trunk_Full"
    },
    {
      "x": 5,
      "y": 14,
      "z": 8,
      "name": "Deco_Nest"
    },
    {
      "x": 5,
      "y": 19,
      "z": 8,
      "name": "Plant_Leaves_Birch"
    },
    {
      "x": 5,
      "y": 20,
      "z": 8,
      "name": "Plant_Leaves_Birch"
    },
    {
      "x": 5,
      "y": 21,
      "z": 8,
      "name": "Plant_Leaves_Birch"
    },
    {
      "x": 5,
      "y": 22,
      "z": 8,
      "name": "Plant_Leaves_Birch"
    },
    {
      "x": 5,
      "y": 23,
      "z": 8,
      "name": "Plant_Leaves_Birch"
    },
    {
      "x": 5,
      "y": 24,
      "z": 8,
      "name": "Plant_Leaves_Birch"
    },
    {
      "x": 5,
      "y": 25,
      "z": 8,
      "name": "Plant_Leaves_Birch"
    },
    {
      "x": 5,
      "y": 26,
      "z": 8,
      "name": "Plant_Leaves_Birch"
    },
    {
      "x": 5,
      "y": 1,
      "z": 9,
      "name": "Wood_Birch_Trunk"
    },
    {
      "x": 5,
      "y": 2,
      "z": 9,
      "name": "Wood_Birch_Trunk"
    },
    {
      "x": 5,
      "y": 3,
      "z": 9,
      "name": "Wood_Birch_Trunk"
    },
    {
      "x": 5,
      "y": 4,
      "z": 9,
      "name": "Wood_Birch_Trunk"
    },
    {
      "x": 5,
      "y": 5,
      "z": 9,
      "name": "Wood_Birch_Trunk_Full"
    },
    {
      "x": 5,
      "y": 11,
      "z": 9,
      "name": "Wood_Birch_Trunk_Full"
    },
    {
      "x": 5,
      "y": 12,
      "z": 9,
      "name": "Wood_Birch_Trunk"
    },
    {
      "x": 5,
      "y": 13,
      "z": 9,
      "name": "Wood_Birch_Trunk"
    },
    {
      "x": 5,
      "y": 14,
      "z": 9,
      "name": "Wood_Birch_Trunk"
    },
    {
      "x": 5,
      "y": 15,
      "z": 9,
      "name": "Wood_Birch_Trunk"
    },
    {
      "x": 5,
      "y": 16,
      "z": 9,
      "name": "Wood_Birch_Trunk"
    },
    {
      "x": 5,
      "y": 17,
      "z": 9,
      "name": "Wood_Birch_Trunk_Full"
    },
    {
      "x": 5,
      "y": 19,
      "z": 9,
      "name": "Wood_Birch_Branch_Long",
      "rotation": 4
    },
    {
      "x": 5,
      "y": 25,
      "z": 9,
      "name": "Plant_Leaves_Birch"
    },
    {
      "x": 5,
      "y": 26,
      "z": 9,
      "name": "Plant_Leaves_Birch"
    },
    {
      "x": 5,
      "y": 27,
      "z": 9,
      "name": "Plant_Leaves_Birch"
    },
    {
      "x": 5,
      "y": 28,
      "z": 9,
      "name": "Plant_Leaves_Birch"
    },
    {
      "x": 5,
      "y": 14,
      "z": 10,
      "name": "Wood_Birch_Trunk_Full"
    },
    {
      "x": 5,
      "y": 17,
      "z": 10,
      "name": "Wood_Birch_Trunk_Full"
    },
    {
      "x": 5,
      "y": 18,
      "z": 10,
      "name": "Wood_Birch_Trunk"
    },
    {
      "x": 5,
      "y": 19,
      "z": 10,
      "name": "Wood_Birch_Trunk"
    },
    {
      "x": 5,
      "y": 20,
      "z": 10,
      "name": "Wood_Birch_Trunk"
    },
    {
      "x": 5,
      "y": 21,
      "z": 10,
      "name": "Wood_Birch_Trunk_Full"
    },
    {
      "x": 5,
      "y": 22,
      "z": 10,
      "name": "Wood_Birch_Trunk_Full"
    },
    {
      "x": 5,
      "y": 23,
      "z": 10,
      "name": "Wood_Birch_Branch_Long"
    },
    {
      "x": 5,
      "y": 24,
      "z": 10,
      "name": "Wood_Birch_Branch_Long"
    },
    {
      "x": 5,
      "y": 25,
      "z": 10,
      "name": "Wood_Birch_Branch_Long"
    },
    {
      "x": 5,
      "y": 26,
      "z": 10,
      "name": "Wood_Birch_Branch_Long"
    },
    {
      "x": 5,
      "y": 27,
      "z": 10,
      "name": "Wood_Birch_Branch_Long"
    },
    {
      "x": 5,
      "y": 28,
      "z": 10,
      "name": "Plant_Leaves_Birch"
    },
    {
      "x": 5,
      "y": 13,
      "z": 11,
      "name": "Plant_Leaves_Birch"
    },
    {
      "x": 5,
      "y": 14,
      "z": 11,
      "name": "Wood_Birch_Trunk_Full"
    },
    {
      "x": 5,
      "y": 15,
      "z": 11,
      "name": "Wood_Birch_Branch_Long"
    },
    {
      "x": 5,
      "y": 16,
      "z": 11,
      "name": "Wood_Birch_Branch_Long"
    },
    {
      "x": 5,
      "y": 17,
      "z": 11,
      "name": "Wood_Birch_Branch_Long"
    },
    {
      "x": 5,
      "y": 18,
      "z": 11,
      "name": "Wood_Birch_Branch_Long"
    },
    {
      "x": 5,
      "y": 19,
      "z": 11,
      "name": "Plant_Leaves_Birch"
    },
    {
      "x": 5,
      "y": 20,
      "z": 11,
      "name": "Plant_Leaves_Birch"
    },
    {
      "x": 5,
      "y": 21,
      "z": 11,
      "name": "Plant_Leaves_Birch"
    },
    {
      "x": 5,
      "y": 22,
      "z": 11,
      "name": "Plant_Leaves_Birch"
    },
    {
      "x": 5,
      "y": 26,
      "z": 11,
      "name": "Plant_Leaves_Birch"
    },
    {
      "x": 5,
      "y": 27,
      "z": 11,
      "name": "Plant_Leaves_Birch"
    },
    {
      "x": 5,
      "y": 11,
      "z": 12,
      "name": "Plant_Leaves_Birch"
    },
    {
      "x": 5,
      "y": 12,
      "z": 12,
      "name": "Plant_Leaves_Birch"
    },
    {
      "x": 5,
      "y": 13,
      "z": 12,
      "name": "Plant_Leaves_Birch"
    },
    {
      "x": 5,
      "y": 14,
      "z": 12,
      "name": "Wood_Birch_Branch_Corner"
    },
    {
      "x": 5,
      "y": 15,
      "z": 12,
      "name": "Wood_Birch_Branch_Long"
    },
    {
      "x": 5,
      "y": 16,
      "z": 12,
      "name": "Wood_Birch_Branch_Long"
    },
    {
      "x": 5,
      "y": 18,
      "z": 12,
      "name": "Plant_Leaves_Birch"
    },
    {
      "x": 5,
      "y": 19,
      "z": 12,
      "name": "Plant_Leaves_Birch"
    },
    {
      "x": 5,
      "y": 20,
      "z": 12,
      "name": "Plant_Leaves_Birch"
    },
    {
      "x": 5,
      "y": 21,
      "z": 12,
      "name": "Plant_Leaves_Birch"
    },
    {
      "x": 5,
      "y": 22,
      "z": 12,
      "name": "Plant_Leaves_Birch"
    },
    {
      "x": 5,
      "y": 23,
      "z": 12,
      "name": "Plant_Leaves_Birch"
    },
    {
      "x": 5,
      "y": 24,
      "z": 12,
      "name": "Plant_Leaves_Birch"
    },
    {
      "x": 5,
      "y": 25,
      "z": 12,
      "name": "Plant_Leaves_Birch"
    },
    {
      "x": 5,
      "y": 13,
      "z": 13,
      "name": "Plant_Leaves_Birch"
    },
    {
      "x": 5,
      "y": 14,
      "z": 13,
      "name": "Plant_Leaves_Birch"
    },
    {
      "x": 5,
      "y": 15,
      "z": 13,
      "name": "Plant_Leaves_Birch"
    },
    {
      "x": 5,
      "y": 16,
      "z": 13,
      "name": "Plant_Leaves_Birch"
    },
    {
      "x": 5,
      "y": 17,
      "z": 13,
      "name": "Plant_Leaves_Birch"
    },
    {
      "x": 5,
      "y": 18,
      "z": 13,
      "name": "Plant_Leaves_Birch"
    },
    {
      "x": 5,
      "y": 20,
      "z": 13,
      "name": "Plant_Leaves_Birch"
    },
    {
      "x": 5,
      "y": 21,
      "z": 13,
      "name": "Plant_Leaves_Birch"
    },
    {
      "x": 5,
      "y": 22,
      "z": 13,
      "name": "Plant_Leaves_Birch"
    },
    {
      "x": 5,
      "y": 15,
      "z": 14,
      "name": "Plant_Leaves_Birch"
    },
    {
      "x": 6,
      "y": 11,
      "z": 4,
      "name": "Plant_Leaves_Birch"
    },
    {
      "x": 6,
      "y": 9,
      "z": 5,
      "name": "Plant_Leaves_Birch"
    },
    {
      "x": 6,
      "y": 10,
      "z": 5,
      "name": "Plant_Leaves_Birch"
    },
    {
      "x": 6,
      "y": 11,
      "z": 5,
      "name": "Plant_Leaves_Birch"
    },
    {
      "x": 6,
      "y": 13,
      "z": 5,
      "name": "Plant_Leaves_Birch"
    },
    {
      "x": 6,
      "y": 10,
      "z": 6,
      "name": "Plant_Leaves_Birch"
    },
    {
      "x": 6,
      "y": 11,
      "z": 6,
      "name": "Plant_Leaves_Birch"
    },
    {
      "x": 6,
      "y": 12,
      "z": 6,
      "name": "Plant_Leaves_Birch"
    },
    {
      "x": 6,
      "y": 13,
      "z": 6,
      "name": "Plant_Leaves_Birch"
    },
    {
      "x": 6,
      "y": 11,
      "z": 7,
      "name": "Wood_Birch_Branch_Corner",
      "rotation": 1
    },
    {
      "x": 6,
      "y": 12,
      "z": 7,
      "name": "Wood_Birch_Branch_Long"
    },
    {
      "x": 6,
      "y": 13,
      "z": 7,
      "name": "Wood_Birch_Branch_Long"
    },
    {
      "x": 6,
      "y": 14,
      "z": 7,
      "name": "Wood_Birch_Branch_Long"
    },
    {
      "x": 6,
      "y": 15,
      "z": 7,
      "name": "Plant_Leaves_Birch"
    },
    {
      "x": 6,
      "y": 16,
      "z": 7,
      "name": "Plant_Leaves_Birch"
    },
    {
      "x": 6,
      "y": 20,
      "z": 7,
      "name": "Plant_Leaves_Birch"
    },
    {
      "x": 6,
      "y": 19,
      "z": 8,
      "name": "Plant_Leaves_Birch"
    },
    {
      "x": 6,
      "y": 21,
      "z": 8,
      "name": "Plant_Leaves_Birch"
    },
    {
      "x": 6,
      "y": 22,
      "z": 8,
      "name": "Plant_Leaves_Birch"
    },
    {
      "x": 6,
      "y": 24,
      "z": 8,
      "name": "Plant_Leaves_Birch"
    },
    {
      "x": 6,
      "y": 25,
      "z": 8,
      "name": "Plant_Leaves_Birch"
    },
    {
      "x": 6,
      "y": 13,
      "z": 9,
      "name": "Wood_Birch_Trunk_Full"
    },
    {
      "x": 6,
      "y": 25,
      "z": 9,
      "name": "Plant_Leaves_Birch"
    },
    {
      "x": 6,
      "y": 26,
      "z": 9,
      "name": "Plant_Leaves_Birch"
    },
    {
      "x": 6,
      "y": 27,
      "z": 9,
      "name": "Plant_Leaves_Birch"
    },
    {
      "x": 6,
      "y": 13,
      "z": 10,
      "name": "Wood_Birch_Branch_Corner"
    },
    {
      "x": 6,
      "y": 14,
      "z": 10,
      "name": "Wood_Birch_Branch_Long"
    },
    {
      "x": 6,
      "y": 15,
      "z": 10,
      "name": "Wood_Birch_Branch_Long"
    },
    {
      "x": 6,
      "y": 16,
      "z": 10,
      "name": "Wood_Birch_Branch_Long"
    },
    {
      "x": 6,
      "y": 17,
      "z": 10,
      "name": "Plant_Leaves_Birch"
    },
    {
      "x": 6,
      "y": 18,
      "z": 10,
      "name": "Plant_Leaves_Birch"
    },
    {
      "x": 6,
      "y": 21,
      "z": 10,
      "name": "Wood_Birch_Branch_Corner",
      "rotation": 1
    },
    {
      "x": 6,
      "y": 22,
      "z": 10,
      "name": "Wood_Birch_Branch_Long"
    },
    {
      "x": 6,
      "y": 23,
      "z": 10,
      "name": "Wood_Birch_Branch_Long"
    },
    {
      "x": 6,
      "y": 24,
      "z": 10,
      "name": "Wood_Birch_Branch_Long"
    },
    {
      "x": 6,
      "y": 25,
      "z": 10,
      "name": "Plant_Leaves_Birch"
    },
    {
      "x": 6,
      "y": 26,
      "z": 10,
      "name": "Plant_Leaves_Birch"
    },
    {
      "x": 6,
      "y": 27,
      "z": 10,
      "name": "Plant_Leaves_Birch"
    },
    {
      "x": 6,
      "y": 28,
      "z": 10,
      "name": "Plant_Leaves_Birch"
    },
    {
      "x": 6,
      "y": 11,
      "z": 11,
      "name": "Plant_Leaves_Birch"
    },
    {
      "x": 6,
      "y": 12,
      "z": 11,
      "name": "Plant_Leaves_Birch"
    },
    {
      "x": 6,
      "y": 13,
      "z": 11,
      "name": "Plant_Leaves_Birch"
    },
    {
      "x": 6,
      "y": 14,
      "z": 11,
      "name": "Plant_Leaves_Birch"
    },
    {
      "x": 6,
      "y": 15,
      "z": 11,
      "name": "Plant_Leaves_Birch"
    },
    {
      "x": 6,
      "y": 16,
      "z": 11,
      "name": "Plant_Leaves_Birch"
    },
    {
      "x": 6,
      "y": 17,
      "z": 11,
      "name": "Plant_Leaves_Birch"
    },
    {
      "x": 6,
      "y": 19,
      "z": 11,
      "name": "Plant_Leaves_Birch"
    },
    {
      "x": 6,
      "y": 20,
      "z": 11,
      "name": "Plant_Leaves_Birch"
    },
    {
      "x": 6,
      "y": 24,
      "z": 11,
      "name": "Plant_Leaves_Birch"
    },
    {
      "x": 6,
      "y": 26,
      "z": 11,
      "name": "Plant_Leaves_Birch"
    },
    {
      "x": 6,
      "y": 27,
      "z": 11,
      "name": "Plant_Leaves_Birch"
    },
    {
      "x": 6,
      "y": 16,
      "z": 12,
      "name": "Plant_Leaves_Birch"
    },
    {
      "x": 6,
      "y": 17,
      "z": 12,
      "name": "Plant_Leaves_Birch"
    },
    {
      "x": 6,
      "y": 18,
      "z": 12,
      "name": "Plant_Leaves_Birch"
    },
    {
      "x": 6,
      "y": 22,
      "z": 12,
      "name": "Plant_Leaves_Birch"
    },
    {
      "x": 6,
      "y": 23,
      "z": 12,
      "name": "Plant_Leaves_Birch"
    },
    {
      "x": 6,
      "y": 24,
      "z": 12,
      "name": "Plant_Leaves_Birch"
    },
    {
      "x": 6,
      "y": 13,
      "z": 13,
      "name": "Plant_Leaves_Birch"
    },
    {
      "x": 6,
      "y": 14,
      "z": 13,
      "name": "Plant_Leaves_Birch"
    },
    {
      "x": 6,
      "y": 23,
      "z": 13,
      "name": "Plant_Leaves_Birch"
    },
    {
      "x": 7,
      "y": 10,
      "z": 6,
      "name": "Plant_Leaves_Birch"
    },
    {
      "x": 7,
      "y": 11,
      "z": 6,
      "name": "Plant_Leaves_Birch"
    },
    {
      "x": 7,
      "y": 8,
      "z": 7,
      "name": "Plant_Leaves_Birch"
    },
    {
      "x": 7,
      "y": 9,
      "z": 7,
      "name": "Plant_Leaves_Birch"
    },
    {
      "x": 7,
      "y": 10,
      "z": 7,
      "name": "Plant_Leaves_Birch"
    },
    {
      "x": 7,
      "y": 11,
      "z": 7,
      "name": "Plant_Leaves_Birch"
    },
    {
      "x": 7,
      "y": 12,
      "z": 7,
      "name": "Plant_Leaves_Birch"
    },
    {
      "x": 7,
      "y": 13,
      "z": 7,
      "name": "Plant_Leaves_Birch"
    },
    {
      "x": 7,
      "y": 14,
      "z": 7,
      "name": "Plant_Leaves_Birch"
    },
    {
      "x": 7,
      "y": 15,
      "z": 7,
      "name": "Plant_Leaves_Birch"
    },
    {
      "x": 7,
      "y": 17,
      "z": 7,
      "name": "Plant_Leaves_Birch"
    },
    {
      "x": 7,
      "y": 18,
      "z": 7,
      "name": "Plant_Leaves_Birch"
    },
    {
      "x": 7,
      "y": 11,
      "z": 8,
      "name": "Plant_Leaves_Birch"
    },
    {
      "x": 7,
      "y": 12,
      "z": 8,
      "name": "Plant_Leaves_Birch"
    },
    {
      "x": 7,
      "y": 13,
      "z": 8,
      "name": "Plant_Leaves_Birch"
    },
    {
      "x": 7,
      "y": 14,
      "z": 8,
      "name": "Wood_Birch_Branch_Corner",
      "rotation": 2
    },
    {
      "x": 7,
      "y": 15,
      "z": 8,
      "name": "Wood_Birch_Branch_Long"
    },
    {
      "x": 7,
      "y": 16,
      "z": 8,
      "name": "Wood_Birch_Branch_Long"
    },
    {
      "x": 7,
      "y": 17,
      "z": 8,
      "name": "Plant_Leaves_Birch"
    },
    {
      "x": 7,
      "y": 18,
      "z": 8,
      "name": "Plant_Leaves_Birch"
    },
    {
      "x": 7,
      "y": 19,
      "z": 8,
      "name": "Plant_Leaves_Birch"
    },
    {
      "x": 7,
      "y": 22,
      "z": 8,
      "name": "Plant_Leaves_Birch"
    },
    {
      "x": 7,
      "y": 24,
      "z": 8,
      "name": "Plant_Leaves_Birch"
    },
    {
      "x": 7,
      "y": 9,
      "z": 9,
      "name": "Plant_Leaves_Birch"
    },
    {
      "x": 7,
      "y": 10,
      "z": 9,
      "name": "Plant_Leaves_Birch"
    },
    {
      "x": 7,
      "y": 11,
      "z": 9,
      "name": "Plant_Leaves_Birch"
    },
    {
      "x": 7,
      "y": 12,
      "z": 9,
      "name": "Plant_Leaves_Birch"
    },
    {
      "x": 7,
      "y": 13,
      "z": 9,
      "name": "Wood_Birch_Trunk_Full"
    },
    {
      "x": 7,
      "y": 14,
      "z": 9,
      "name": "Wood_Birch_Trunk_Full"
    },
    {
      "x": 7,
      "y": 15,
      "z": 9,
      "name": "Wood_Birch_Branch_Long"
    },
    {
      "x": 7,
      "y": 16,
      "z": 9,
      "name": "Wood_Birch_Branch_Long"
    },
    {
      "x": 7,
      "y": 17,
      "z": 9,
      "name": "Wood_Birch_Branch_Long"
    },
    {
      "x": 7,
      "y": 18,
      "z": 9,
      "name": "Plant_Leaves_Birch"
    },
    {
      "x": 7,
      "y": 19,
      "z": 9,
      "name": "Plant_Leaves_Birch"
    },
    {
      "x": 7,
      "y": 20,
      "z": 9,
      "name": "Plant_Leaves_Birch"
    },
    {
      "x": 7,
      "y": 24,
      "z": 9,
      "name": "Plant_Leaves_Birch"
    },
    {
      "x": 7,
      "y": 25,
      "z": 9,
      "name": "Plant_Leaves_Birch"
    },
    {
      "x": 7,
      "y": 11,
      "z": 10,
      "name": "Plant_Leaves_Birch"
    },
    {
      "x": 7,
      "y": 12,
      "z": 10,
      "name": "Plant_Leaves_Birch"
    },
    {
      "x": 7,
      "y": 13,
      "z": 10,
      "name": "Plant_Leaves_Birch"
    },
    {
      "x": 7,
      "y": 14,
      "z": 10,
      "name": "Plant_Leaves_Birch"
    },
    {
      "x": 7,
      "y": 15,
      "z": 10,
      "name": "Plant_Leaves_Birch"
    },
    {
      "x": 7,
      "y": 16,
      "z": 10,
      "name": "Plant_Leaves_Birch"
    },
    {
      "x": 7,
      "y": 17,
      "z": 10,
      "name": "Plant_Leaves_Birch"
    },
    {
      "x": 7,
      "y": 18,
      "z": 10,
      "name": "Plant_Leaves_Birch"
    },
    {
      "x": 7,
      "y": 19,
      "z": 10,
      "name": "Plant_Leaves_Birch"
    },
    {
      "x": 7,
      "y": 23,
      "z": 10,
      "name": "Plant_Leaves_Birch"
    },
    {
      "x": 7,
      "y": 24,
      "z": 10,
      "name": "Plant_Leaves_Birch"
    },
    {
      "x": 7,
      "y": 25,
      "z": 10,
      "name": "Plant_Leaves_Birch"
    },
    {
      "x": 7,
      "y": 26,
      "z": 10,
      "name": "Plant_Leaves_Birch"
    },
    {
      "x": 7,
      "y": 12,
      "z": 11,
      "name": "Plant_Leaves_Birch"
    },
    {
      "x": 7,
      "y": 13,
      "z": 11,
      "name": "Plant_Leaves_Birch"
    },
    {
      "x": 7,
      "y": 14,
      "z": 11,
      "name": "Plant_Leaves_Birch"
    },
    {
      "x": 7,
      "y": 16,
      "z": 11,
      "name": "Plant_Leaves_Birch"
    },
    {
      "x": 7,
      "y": 23,
      "z": 11,
      "name": "Plant_Leaves_Birch"
    },
    {
      "x": 7,
      "y": 24,
      "z": 11,
      "name": "Plant_Leaves_Birch"
    },
    {
      "x": 7,
      "y": 25,
      "z": 11,
      "name": "Plant_Leaves_Birch"
    },
    {
      "x": 7,
      "y": 15,
      "z": 12,
      "name": "Plant_Leaves_Birch"
    },
    {
      "x": 7,
      "y": 16,
      "z": 12,
      "name": "Plant_Leaves_Birch"
    },
    {
      "x": 8,
      "y": 14,
      "z": 7,
      "name": "Plant_Leaves_Birch"
    },
    {
      "x": 8,
      "y": 15,
      "z": 7,
      "name": "Plant_Leaves_Birch"
    },
    {
      "x": 8,
      "y": 16,
      "z": 7,
      "name": "Plant_Leaves_Birch"
    },
    {
      "x": 8,
      "y": 11,
      "z": 8,
      "name": "Plant_Leaves_Birch"
    },
    {
      "x": 8,
      "y": 12,
      "z": 8,
      "name": "Plant_Leaves_Birch"
    },
    {
      "x": 8,
      "y": 13,
      "z": 8,
      "name": "Plant_Leaves_Birch"
    },
    {
      "x": 8,
      "y": 14,
      "z": 8,
      "name": "Plant_Leaves_Birch"
    },
    {
      "x": 8,
      "y": 15,
      "z": 8,
      "name": "Plant_Leaves_Birch"
    },
    {
      "x": 8,
      "y": 16,
      "z": 8,
      "name": "Plant_Leaves_Birch"
    },
    {
      "x": 8,
      "y": 17,
      "z": 8,
      "name": "Plant_Leaves_Birch"
    },
    {
      "x": 8,
      "y": 18,
      "z": 8,
      "name": "Plant_Leaves_Birch"
    },
    {
      "x": 8,
      "y": 11,
      "z": 9,
      "name": "Plant_Leaves_Birch"
    },
    {
      "x": 8,
      "y": 12,
      "z": 9,
      "name": "Plant_Leaves_Birch"
    },
    {
      "x": 8,
      "y": 13,
      "z": 9,
      "name": "Plant_Leaves_Birch"
    },
    {
      "x": 8,
      "y": 14,
      "z": 9,
      "name": "Plant_Leaves_Birch"
    },
    {
      "x": 8,
      "y": 15,
      "z": 9,
      "name": "Plant_Leaves_Birch"
    },
    {
      "x": 8,
      "y": 16,
      "z": 9,
      "name": "Plant_Leaves_Birch"
    },
    {
      "x": 8,
      "y": 17,
      "z": 9,
      "name": "Plant_Leaves_Birch"
    },
    {
      "x": 8,
      "y": 18,
      "z": 9,
      "name": "Plant_Leaves_Birch"
    },
    {
      "x": 8,
      "y": 22,
      "z": 9,
      "name": "Plant_Leaves_Birch"
    },
    {
      "x": 8,
      "y": 11,
      "z": 10,
      "name": "Plant_Leaves_Birch"
    },
    {
      "x": 8,
      "y": 12,
      "z": 10,
      "name": "Plant_Leaves_Birch"
    },
    {
      "x": 8,
      "y": 13,
      "z": 10,
      "name": "Plant_Leaves_Birch"
    },
    {
      "x": 8,
      "y": 15,
      "z": 10,
      "name": "Plant_Leaves_Birch"
    },
    {
      "x": 8,
      "y": 22,
      "z": 10,
      "name": "Plant_Leaves_Birch"
    },
    {
      "x": 8,
      "y": 23,
      "z": 10,
      "name": "Plant_Leaves_Birch"
    },
    {
      "x": 8,
      "y": 22,
      "z": 11,
      "name": "Plant_Leaves_Birch"
    },
    {
      "x": 9,
      "y": 16,
      "z": 9,
      "name": "Plant_Leaves_Birch"
    },
    {
      "x": 9,
      "y": 13,
      "z": 10,
      "name": "Plant_Leaves_Birch"
    }
  ]
}