{
  "version": 8,
  "blockIdVersion": 8,
  "anchorX": 0,
  "anchorY": 4,
  "anchorZ": 0,
  "blocks": [
    {
      "x": -5,
      "y": 10,
      "z": -2,
      "name": "Wood_Fir_Trunk",
      "support": 15,
      "rotation": 4
    },
    {
      "x": -5,
      "y": 10,
      "z": -1,
      "name": "Wood_Fir_Trunk",
      "support": 15,
      "rotation": 4
    },
    {
      "x": -5,
      "y": 11,
      "z": -1,
      "name": "Wood_Deadwood_Stairs",
      "rotation": 2
    },
    {
      "x": -5,
      "y": 9,
      "z": 0,
      "name": "Wood_Deadwood_Stairs",
      "rotation": 9
    },
    {
      "x": -5,
      "y": 10,
      "z": 0,
      "name": "Wood_Fir_Trunk",
      "support": 15,
      "rotation": 4
    },
    {
      "x": -5,
      "y": 11,
      "z": 0,
      "name": "Wood_Deadwood_Planks"
    },
    {
      "x": -5,
      "y": 12,
      "z": 0,
      "name": "Wood_Deadwood_Stairs",
      "rotation": 2
    },
    {
      "x": -5,
      "y": 13,
      "z": 0,
      "name": "Wood_Deadwood_Stairs"
    },
    {
      "x": -5,
      "y": 9,
      "z": 1,
      "name": "Wood_Deadwood_Stairs",
      "rotation": 9
    },
    {
      "x": -5,
      "y": 10,
      "z": 1,
      "name": "Wood_Fir_Trunk",
      "support": 15,
      "rotation": 4
    },
    {
      "x": -5,
      "y": 11,
      "z": 1,
      "name": "Wood_Deadwood_Planks"
    },
    {
      "x": -5,
      "y": 12,
      "z": 1,
      "name": "Wood_Deadwood_Stairs"
    },
    {
      "x": -5,
      "y": 13,
      "z": 1,
      "name": "Wood_Deadwood_Stairs",
      "rotation": 2
    },
    {
      "x": -5,
      "y": 10,
      "z": 2,
      "name": "Wood_Fir_Trunk",
      "support": 15,
      "rotation": 4
    },
    {
      "x": -5,
      "y": 11,
      "z": 2,
      "name": "Wood_Deadwood_Stairs"
    },
    {
      "x": -5,
      "y": 10,
      "z": 3,
      "name": "Wood_Fir_Branch_Long",
      "support": 15,
      "rotation": 4
    },
    {
      "x": -5,
      "y": 10,
      "z": 4,
      "name": "Wood_Deadwood_Beam",
      "rotation": 4
    },
    {
      "x": -4,
      "y": 7,
      "z": -1,
      "name": "Deco_Iron_Chain_Small"
    },
    {
      "x": -4,
      "y": 8,
      "z": -1,
      "name": "Deco_Iron_Chain_Small"
    },
    {
      "x": -4,
      "y": 9,
      "z": -1,
      "name": "Wood_Deadwood_Beam"
    },
    {
      "x": -4,
      "y": 10,
      "z": -1,
      "name": "Wood_Fir_Trunk",
      "support": 15,
      "rotation": 4
    },
    {
      "x": -4,
      "y": 11,
      "z": -1,
      "name": "Wood_Deadwood_Roof",
      "rotation": 2
    },
    {
      "x": -4,
      "y": 0,
      "z": 0,
      "name": "Wood_Fir_Trunk",
      "support": 15
    },
    {
      "x": -4,
      "y": 1,
      "z": 0,
      "name": "Wood_Fir_Trunk",
      "support": 15
    },
    {
      "x": -4,
      "y": 2,
      "z": 0,
      "name": "Wood_Fir_Trunk",
      "support": 15
    },
    {
      "x": -4,
      "y": 3,
      "z": 0,
      "name": "Wood_Fir_Trunk",
      "support": 15
    },
    {
      "x": -4,
      "y": 4,
      "z": 0,
      "name": "Wood_Fir_Trunk",
      "support": 15
    },
    {
      "x": -4,
      "y": 5,
      "z": 0,
      "name": "Wood_Fir_Trunk",
      "support": 15
    },
    {
      "x": -4,
      "y": 6,
      "z": 0,
      "name": "Wood_Fir_Trunk",
      "support": 15
    },
    {
      "x": -4,
      "y": 7,
      "z": 0,
      "name": "Wood_Fir_Trunk",
      "support": 15
    },
    {
      "x": -4,
      "y": 8,
      "z": 0,
      "name": "Wood_Fir_Trunk",
      "support": 15
    },
    {
      "x": -4,
      "y": 9,
      "z": 0,
      "name": "Wood_Fir_Trunk",
      "support": 15
    },
    {
      "x": -4,
      "y": 10,
      "z": 0,
      "name": "Wood_Fir_Trunk",
      "support": 15,
      "rotation": 4
    },
    {
      "x": -4,
      "y": 11,
      "z": 0,
      "name": "Wood_Deadwood_Planks"
    },
    {
      "x": -4,
      "y": 12,
      "z": 0,
      "name": "Wood_Deadwood_Roof",
      "rotation": 2
    },
    {
      "x": -4,
      "y": 0,
      "z": 1,
      "name": "Wood_Fir_Trunk",
      "support": 15
    },
    {
      "x": -4,
      "y": 1,
      "z": 1,
      "name": "Wood_Fir_Trunk",
      "support": 15
    },
    {
      "x": -4,
      "y": 2,
      "z": 1,
      "name": "Wood_Fir_Trunk",
      "support": 15
    },
    {
      "x": -4,
      "y": 3,
      "z": 1,
      "name": "Wood_Fir_Trunk",
      "support": 15
    },
    {
      "x": -4,
      "y": 4,
      "z": 1,
      "name": "Wood_Fir_Trunk",
      "support": 15
    },
    {
      "x": -4,
      "y": 5,
      "z": 1,
      "name": "Wood_Fir_Trunk",
      "support": 15
    },
    {
      "x": -4,
      "y": 6,
      "z": 1,
      "name": "Wood_Fir_Trunk",
      "support": 15
    },
    {
      "x": -4,
      "y": 7,
      "z": 1,
      "name": "Wood_Fir_Trunk",
      "support": 15
    },
    {
      "x": -4,
      "y": 8,
      "z": 1,
      "name": "Wood_Fir_Trunk",
      "support": 15
    },
    {
      "x": -4,
      "y": 9,
      "z": 1,
      "name": "Wood_Fir_Trunk",
      "support": 15
    },
    {
      "x": -4,
      "y": 10,
      "z": 1,
      "name": "Wood_Fir_Trunk",
      "support": 15,
      "rotation": 4
    },
    {
      "x": -4,
      "y": 11,
      "z": 1,
      "name": "Wood_Deadwood_Planks"
    },
    {
      "x": -4,
      "y": 12,
      "z": 1,
      "name": "Wood_Deadwood_Roof"
    },
    {
      "x": -4,
      "y": 7,
      "z": 2,
      "name": "Deco_Bone_Ribs",
      "rotation": 1
    },
    {
      "x": -4,
      "y": 8,
      "z": 2,
      "name": "Deco_Iron_Chain_Small"
    },
    {
      "x": -4,
      "y": 9,
      "z": 2,
      "name": "Deco_Iron_Chain_Small"
    },
    {
      "x": -4,
      "y": 10,
      "z": 2,
      "name": "Wood_Fir_Trunk",
      "support": 15,
      "rotation": 4
    },
    {
      "x": -4,
      "y": 11,
      "z": 2,
      "name": "Wood_Deadwood_Roof"
    },
    {
      "x": -3,
      "y": 7,
      "z": -1,
      "name": "Wood_Torch_Wall",
      "rotation": 2
    },
    {
      "x": -3,
      "y": 10,
      "z": -1,
      "name": "Wood_Fir_Branch_Long",
      "support": 15,
      "rotation": 5
    },
    {
      "x": -3,
      "y": 11,
      "z": -1,
      "name": "Wood_Deadwood_Roof",
      "rotation": 2
    },
    {
      "x": -3,
      "y": 0,
      "z": 0,
      "name": "Wood_Fir_Trunk",
      "support": 15
    },
    {
      "x": -3,
      "y": 1,
      "z": 0,
      "name": "Wood_Fir_Trunk",
      "support": 15
    },
    {
      "x": -3,
      "y": 2,
      "z": 0,
      "name": "Wood_Fir_Trunk",
      "support": 15
    },
    {
      "x": -3,
      "y": 3,
      "z": 0,
      "name": "Wood_Fir_Trunk",
      "support": 15
    },
    {
      "x": -3,
      "y": 4,
      "z": 0,
      "name": "Wood_Fir_Trunk",
      "support": 15
    },
    {
      "x": -3,
      "y": 5,
      "z": 0,
      "name": "Wood_Fir_Trunk",
      "support": 15
    },
    {
      "x": -3,
      "y": 6,
      "z": 0,
      "name": "Wood_Fir_Trunk",
      "support": 15
    },
    {
      "x": -3,
      "y": 7,
      "z": 0,
      "name": "Wood_Fir_Trunk",
      "support": 15
    },
    {
      "x": -3,
      "y": 8,
      "z": 0,
      "name": "Wood_Fir_Trunk",
      "support": 15
    },
    {
      "x": -3,
      "y": 9,
      "z": 0,
      "name": "Wood_Fir_Trunk",
      "support": 15
    },
    {
      "x": -3,
      "y": 10,
      "z": 0,
      "name": "Wood_Fir_Trunk",
      "support": 15,
      "rotation": 5
    },
    {
      "x": -3,
      "y": 11,
      "z": 0,
      "name": "Wood_Deadwood_Planks"
    },
    {
      "x": -3,
      "y": 12,
      "z": 0,
      "name": "Wood_Deadwood_Roof",
      "rotation": 2
    },
    {
      "x": -3,
      "y": 0,
      "z": 1,
      "name": "Wood_Fir_Trunk",
      "support": 15
    },
    {
      "x": -3,
      "y": 1,
      "z": 1,
      "name": "Wood_Fir_Trunk",
      "support": 15
    },
    {
      "x": -3,
      "y": 2,
      "z": 1,
      "name": "Wood_Fir_Trunk",
      "support": 15
    },
    {
      "x": -3,
      "y": 3,
      "z": 1,
      "name": "Wood_Fir_Trunk",
      "support": 15
    },
    {
      "x": -3,
      "y": 4,
      "z": 1,
      "name": "Wood_Fir_Trunk",
      "support": 15
    },
    {
      "x": -3,
      "y": 5,
      "z": 1,
      "name": "Wood_Fir_Trunk",
      "support": 15
    },
    {
      "x": -3,
      "y": 6,
      "z": 1,
      "name": "Wood_Fir_Trunk",
      "support": 15
    },
    {
      "x": -3,
      "y": 7,
      "z": 1,
      "name": "Wood_Fir_Trunk",
      "support": 15
    },
    {
      "x": -3,
      "y": 8,
      "z": 1,
      "name": "Wood_Fir_Trunk",
      "support": 15
    },
    {
      "x": -3,
      "y": 9,
      "z": 1,
      "name": "Wood_Fir_Trunk",
      "support": 15
    },
    {
      "x": -3,
      "y": 10,
      "z": 1,
      "name": "Wood_Fir_Trunk",
      "support": 15,
      "rotation": 5
    },
    {
      "x": -3,
      "y": 11,
      "z": 1,
      "name": "Wood_Deadwood_Planks"
    },
    {
      "x": -3,
      "y": 12,
      "z": 1,
      "name": "Wood_Deadwood_Roof"
    },
    {
      "x": -3,
      "y": 7,
      "z": 2,
      "name": "Wood_Torch_Wall"
    },
    {
      "x": -3,
      "y": 10,
      "z": 2,
      "name": "Wood_Fir_Branch_Long",
      "support": 15,
      "rotation": 5
    },
    {
      "x": -3,
      "y": 11,
      "z": 2,
      "name": "Wood_Deadwood_Roof"
    },
    {
      "x": -2,
      "y": 5,
      "z": -1,
      "name": "Empty"
    },
    {
      "x": -2,
      "y": 6,
      "z": -1,
      "name": "Empty"
    },
    {
      "x": -2,
      "y": 7,
      "z": -1,
      "name": "Empty"
    },
    {
      "x": -2,
      "y": 8,
      "z": -1,
      "name": "Empty"
    },
    {
      "x": -2,
      "y": 9,
      "z": -1,
      "name": "Empty"
    },
    {
      "x": -2,
      "y": 10,
      "z": -1,
      "name": "Wood_Fir_Branch_Long",
      "support": 15,
      "rotation": 5
    },
    {
      "x": -2,
      "y": 11,
      "z": -1,
      "name": "Wood_Deadwood_Roof",
      "rotation": 2
    },
    {
      "x": -2,
      "y": 5,
      "z": 0,
      "name": "Empty"
    },
    {
      "x": -2,
      "y": 6,
      "z": 0,
      "name": "Empty"
    },
    {
      "x": -2,
      "y": 7,
      "z": 0,
      "name": "Empty"
    },
    {
      "x": -2,
      "y": 8,
      "z": 0,
      "name": "Empty"
    },
    {
      "x": -2,
      "y": 9,
      "z": 0,
      "name": "Wood_Deadwood_Stairs",
      "rotation": 11
    },
    {
      "x": -2,
      "y": 10,
      "z": 0,
      "name": "Wood_Fir_Trunk",
      "support": 15,
      "rotation": 5
    },
    {
      "x": -2,
      "y": 11,
      "z": 0,
      "name": "Wood_Deadwood_Planks"
    },
    {
      "x": -2,
      "y": 12,
      "z": 0,
      "name": "Wood_Deadwood_Roof",
      "rotation": 2
    },
    {
      "x": -2,
      "y": 5,
      "z": 1,
      "name": "Empty"
    },
    {
      "x": -2,
      "y": 6,
      "z": 1,
      "name": "Empty"
    },
    {
      "x": -2,
      "y": 7,
      "z": 1,
      "name": "Empty"
    },
    {
      "x": -2,
      "y": 8,
      "z": 1,
      "name": "Empty"
    },
    {
      "x": -2,
      "y": 9,
      "z": 1,
      "name": "Wood_Deadwood_Stairs",
      "rotation": 11
    },
    {
      "x": -2,
      "y": 10,
      "z": 1,
      "name": "Wood_Fir_Trunk",
      "support": 15,
      "rotation": 5
    },
    {
      "x": -2,
      "y": 11,
      "z": 1,
      "name": "Wood_Deadwood_Planks"
    },
    {
      "x": -2,
      "y": 12,
      "z": 1,
      "name": "Wood_Deadwood_Roof"
    },
    {
      "x": -2,
      "y": 5,
      "z": 2,
      "name": "Empty"
    },
    {
      "x": -2,
      "y": 6,
      "z": 2,
      "name": "Empty"
    },
    {
      "x": -2,
      "y": 7,
      "z": 2,
      "name": "Empty"
    },
    {
      "x": -2,
      "y": 8,
      "z": 2,
      "name": "Empty"
    },
    {
      "x": -2,
      "y": 9,
      "z": 2,
      "name": "Empty"
    },
    {
      "x": -2,
      "y": 10,
      "z": 2,
      "name": "Deco_Iron_Chain_Small",
      "rotation": 5
    },
    {
      "x": -2,
      "y": 11,
      "z": 2,
      "name": "Wood_Deadwood_Roof"
    },
    {
      "x": -1,
      "y": 5,
      "z": -1,
      "name": "Empty"
    },
    {
      "x": -1,
      "y": 6,
      "z": -1,
      "name": "Empty"
    },
    {
      "x": -1,
      "y": 7,
      "z": -1,
      "name": "Empty"
    },
    {
      "x": -1,
      "y": 8,
      "z": -1,
      "name": "Empty"
    },
    {
      "x": -1,
      "y": 9,
      "z": -1,
      "name": "Empty"
    },
    {
      "x": -1,
      "y": 10,
      "z": -1,
      "name": "Deco_Iron_Chain_Small",
      "rotation": 5
    },
    {
      "x": -1,
      "y": 11,
      "z": -1,
      "name": "Wood_Deadwood_Roof",
      "rotation": 2
    },
    {
      "x": -1,
      "y": 5,
      "z": 0,
      "name": "Empty"
    },
    {
      "x": -1,
      "y": 6,
      "z": 0,
      "name": "Empty"
    },
    {
      "x": -1,
      "y": 7,
      "z": 0,
      "name": "Empty"
    },
    {
      "x": -1,
      "y": 8,
      "z": 0,
      "name": "Empty"
    },
    {
      "x": -1,
      "y": 9,
      "z": 0,
      "name": "Empty"
    },
    {
      "x": -1,
      "y": 10,
      "z": 0,
      "name": "Wood_Fir_Trunk",
      "support": 15,
      "rotation": 5
    },
    {
      "x": -1,
      "y": 11,
      "z": 0,
      "name": "Wood_Deadwood_Planks"
    },
    {
      "x": -1,
      "y": 12,
      "z": 0,
      "name": "Wood_Deadwood_Roof",
      "rotation": 2
    },
    {
      "x": -1,
      "y": 5,
      "z": 1,
      "name": "Empty"
    },
    {
      "x": -1,
      "y": 6,
      "z": 1,
      "name": "Empty"
    },
    {
      "x": -1,
      "y": 7,
      "z": 1,
      "name": "Empty"
    },
    {
      "x": -1,
      "y": 8,
      "z": 1,
      "name": "Empty"
    },
    {
      "x": -1,
      "y": 9,
      "z": 1,
      "name": "Empty"
    },
    {
      "x": -1,
      "y": 10,
      "z": 1,
      "name": "Wood_Fir_Trunk",
      "support": 15,
      "rotation": 5
    },
    {
      "x": -1,
      "y": 11,
      "z": 1,
      "name": "Wood_Deadwood_Planks"
    },
    {
      "x": -1,
      "y": 12,
      "z": 1,
      "name": "Wood_Deadwood_Roof"
    },
    {
      "x": -1,
      "y": 5,
      "z": 2,
      "name": "Empty"
    },
    {
      "x": -1,
      "y": 6,
      "z": 2,
      "name": "Empty"
    },
    {
      "x": -1,
      "y": 7,
      "z": 2,
      "name": "Empty"
    },
    {
      "x": -1,
      "y": 8,
      "z": 2,
      "name": "Empty"
    },
    {
      "x": -1,
      "y": 9,
      "z": 2,
      "name": "Empty"
    },
    {
      "x": -1,
      "y": 10,
      "z": 2,
      "name": "Deco_Iron_Chain_Small",
      "rotation": 5
    },
    {
      "x": -1,
      "y": 11,
      "z": 2,
      "name": "Wood_Deadwood_Roof"
    },
    {
      "x": 0,
      "y": 5,
      "z": -1,
      "name": "Empty"
    },
    {
      "x": 0,
      "y": 6,
      "z": -1,
      "name": "Empty"
    },
    {
      "x": 0,
      "y": 7,
      "z": -1,
      "name": "Empty"
    },
    {
      "x": 0,
      "y": 8,
      "z": -1,
      "name": "Empty"
    },
    {
      "x": 0,
      "y": 9,
      "z": -1,
      "name": "Empty"
    },
    {
      "x": 0,
      "y": 10,
      "z": -1,
      "name": "Deco_Iron_Chain_Small",
      "rotation": 5
    },
    {
      "x": 0,
      "y": 11,
      "z": -1,
      "name": "Wood_Deadwood_Roof",
      "rotation": 2
    },
    {
      "x": 0,
      "y": 4,
      "z": 0,
      "name": "Empty"
    },
    {
      "x": 0,
      "y": 5,
      "z": 0,
      "name": "Empty"
    },
    {
      "x": 0,
      "y": 6,
      "z": 0,
      "name": "Empty"
    },
    {
      "x": 0,
      "y": 7,
      "z": 0,
      "name": "Empty"
    },
    {
      "x": 0,
      "y": 8,
      "z": 0,
      "name": "Empty"
    },
    {
      "x": 0,
      "y": 9,
      "z": 0,
      "name": "Empty"
    },
    {
      "x": 0,
      "y": 10,
      "z": 0,
      "name": "Wood_Fir_Trunk",
      "support": 15,
      "rotation": 5
    },
    {
      "x": 0,
      "y": 11,
      "z": 0,
      "name": "Wood_Deadwood_Planks"
    },
    {
      "x": 0,
      "y": 12,
      "z": 0,
      "name": "Wood_Deadwood_Roof",
      "rotation": 2
    },
    {
      "x": 0,
      "y": 5,
      "z": 1,
      "name": "Empty"
    },
    {
      "x": 0,
      "y": 6,
      "z": 1,
      "name": "Empty"
    },
    {
      "x": 0,
      "y": 7,
      "z": 1,
      "name": "Empty"
    },
    {
      "x": 0,
      "y": 8,
      "z": 1,
      "name": "Empty"
    },
    {
      "x": 0,
      "y": 9,
      "z": 1,
      "name": "Empty"
    },
    {
      "x": 0,
      "y": 10,
      "z": 1,
      "name": "Wood_Fir_Trunk",
      "support": 15,
      "rotation": 5
    },
    {
      "x": 0,
      "y": 11,
      "z": 1,
      "name": "Wood_Deadwood_Planks"
    },
    {
      "x": 0,
      "y": 12,
      "z": 1,
      "name": "Wood_Deadwood_Roof"
    },
    {
      "x": 0,
      "y": 5,
      "z": 2,
      "name": "Empty"
    },
    {
      "x": 0,
      "y": 6,
      "z": 2,
      "name": "Empty"
    },
    {
      "x": 0,
      "y": 7,
      "z": 2,
      "name": "Empty"
    },
    {
      "x": 0,
      "y": 8,
      "z": 2,
      "name": "Empty"
    },
    {
      "x": 0,
      "y": 9,
      "z": 2,
      "name": "Empty"
    },
    {
      "x": 0,
      "y": 10,
      "z": 2,
      "name": "Deco_Iron_Chain_Small",
      "rotation": 5
    },
    {
      "x": 0,
      "y": 11,
      "z": 2,
      "name": "Wood_Deadwood_Roof"
    },
    {
      "x": 1,
      "y": 5,
      "z": -1,
      "name": "Empty"
    },
    {
      "x": 1,
      "y": 6,
      "z": -1,
      "name": "Empty"
    },
    {
      "x": 1,
      "y": 7,
      "z": -1,
      "name": "Empty"
    },
    {
      "x": 1,
      "y": 8,
      "z": -1,
      "name": "Empty"
    },
    {
      "x": 1,
      "y": 9,
      "z": -1,
      "name": "Empty"
    },
    {
      "x": 1,
      "y": 10,
      "z": -1,
      "name": "Deco_Iron_Chain_Small",
      "rotation": 5
    },
    {
      "x": 1,
      "y": 11,
      "z": -1,
      "name": "Wood_Deadwood_Roof",
      "rotation": 2
    },
    {
      "x": 1,
      "y": 5,
      "z": 0,
      "name": "Empty"
    },
    {
      "x": 1,
      "y": 6,
      "z": 0,
      "name": "Empty"
    },
    {
      "x": 1,
      "y": 7,
      "z": 0,
      "name": "Empty"
    },
    {
      "x": 1,
      "y": 8,
      "z": 0,
      "name": "Empty"
    },
    {
      "x": 1,
      "y": 9,
      "z": 0,
      "name": "Empty"
    },
    {
      "x": 1,
      "y": 10,
      "z": 0,
      "name": "Wood_Fir_Trunk",
      "support": 15,
      "rotation": 5
    },
    {
      "x": 1,
      "y": 11,
      "z": 0,
      "name": "Wood_Deadwood_Planks"
    },
    {
      "x": 1,
      "y": 12,
      "z": 0,
      "name": "Wood_Deadwood_Roof",
      "rotation": 2
    },
    {
      "x": 1,
      "y": 5,
      "z": 1,
      "name": "Empty"
    },
    {
      "x": 1,
      "y": 6,
      "z": 1,
      "name": "Empty"
    },
    {
      "x": 1,
      "y": 7,
      "z": 1,
      "name": "Empty"
    },
    {
      "x": 1,
      "y": 8,
      "z": 1,
      "name": "Empty"
    },
    {
      "x": 1,
      "y": 9,
      "z": 1,
      "name": "Empty"
    },
    {
      "x": 1,
      "y": 10,
      "z": 1,
      "name": "Wood_Fir_Trunk",
      "support": 15,
      "rotation": 5
    },
    {
      "x": 1,
      "y": 11,
      "z": 1,
      "name": "Wood_Deadwood_Planks"
    },
    {
      "x": 1,
      "y": 12,
      "z": 1,
      "name": "Wood_Deadwood_Roof"
    },
    {
      "x": 1,
      "y": 5,
      "z": 2,
      "name": "Empty"
    },
    {
      "x": 1,
      "y": 6,
      "z": 2,
      "name": "Empty"
    },
    {
      "x": 1,
      "y": 7,
      "z": 2,
      "name": "Empty"
    },
    {
      "x": 1,
      "y": 8,
      "z": 2,
      "name": "Empty"
    },
    {
      "x": 1,
      "y": 9,
      "z": 2,
      "name": "Empty"
    },
    {
      "x": 1,
      "y": 10,
      "z": 2,
      "name": "Deco_Iron_Chain_Small",
      "rotation": 5
    },
    {
      "x": 1,
      "y": 11,
      "z": 2,
      "name": "Wood_Deadwood_Roof"
    },
    {
      "x": 2,
      "y": 5,
      "z": -1,
      "name": "Empty"
    },
    {
      "x": 2,
      "y": 6,
      "z": -1,
      "name": "Empty"
    },
    {
      "x": 2,
      "y": 7,
      "z": -1,
      "name": "Empty"
    },
    {
      "x": 2,
      "y": 8,
      "z": -1,
      "name": "Empty"
    },
    {
      "x": 2,
      "y": 9,
      "z": -1,
      "name": "Empty"
    },
    {
      "x": 2,
      "y": 10,
      "z": -1,
      "name": "Deco_Iron_Chain_Small",
      "rotation": 5
    },
    {
      "x": 2,
      "y": 11,
      "z": -1,
      "name": "Wood_Deadwood_Roof",
      "rotation": 2
    },
    {
      "x": 2,
      "y": 5,
      "z": 0,
      "name": "Empty"
    },
    {
      "x": 2,
      "y": 6,
      "z": 0,
      "name": "Empty"
    },
    {
      "x": 2,
      "y": 7,
      "z": 0,
      "name": "Empty"
    },
    {
      "x": 2,
      "y": 8,
      "z": 0,
      "name": "Empty"
    },
    {
      "x": 2,
      "y": 9,
      "z": 0,
      "name": "Wood_Deadwood_Stairs",
      "rotation": 9
    },
    {
      "x": 2,
      "y": 10,
      "z": 0,
      "name": "Wood_Fir_Trunk",
      "support": 15,
      "rotation": 5
    },
    {
      "x": 2,
      "y": 11,
      "z": 0,
      "name": "Wood_Deadwood_Planks"
    },
    {
      "x": 2,
      "y": 12,
      "z": 0,
      "name": "Wood_Deadwood_Roof",
      "rotation": 2
    },
    {
      "x": 2,
      "y": 5,
      "z": 1,
      "name": "Empty"
    },
    {
      "x": 2,
      "y": 6,
      "z": 1,
      "name": "Empty"
    },
    {
      "x": 2,
      "y": 7,
      "z": 1,
      "name": "Empty"
    },
    {
      "x": 2,
      "y": 8,
      "z": 1,
      "name": "Empty"
    },
    {
      "x": 2,
      "y": 9,
      "z": 1,
      "name": "Wood_Deadwood_Stairs",
      "rotation": 9
    },
    {
      "x": 2,
      "y": 10,
      "z": 1,
      "name": "Wood_Fir_Trunk",
      "support": 15,
      "rotation": 5
    },
    {
      "x": 2,
      "y": 11,
      "z": 1,
      "name": "Wood_Deadwood_Planks"
    },
    {
      "x": 2,
      "y": 12,
      "z": 1,
      "name": "Wood_Deadwood_Roof"
    },
    {
      "x": 2,
      "y": 5,
      "z": 2,
      "name": "Empty"
    },
    {
      "x": 2,
      "y": 6,
      "z": 2,
      "name": "Empty"
    },
    {
      "x": 2,
      "y": 7,
      "z": 2,
      "name": "Empty"
    },
    {
      "x": 2,
      "y": 8,
      "z": 2,
      "name": "Empty"
    },
    {
      "x": 2,
      "y": 9,
      "z": 2,
      "name": "Empty"
    },
    {
      "x": 2,
      "y": 10,
      "z": 2,
      "name": "Deco_Iron_Chain_Small",
      "rotation": 5
    },
    {
      "x": 2,
      "y": 11,
      "z": 2,
      "name": "Wood_Deadwood_Roof"
    },
    {
      "x": 3,
      "y": 7,
      "z": -1,
      "name": "Wood_Torch_Wall",
      "rotation": 2
    },
    {
      "x": 3,
      "y": 10,
      "z": -1,
      "name": "Wood_Fir_Branch_Long",
      "support": 15,
      "rotation": 5
    },
    {
      "x": 3,
      "y": 11,
      "z": -1,
      "name": "Wood_Deadwood_Roof",
      "rotation": 2
    },
    {
      "x": 3,
      "y": 0,
      "z": 0,
      "name": "Wood_Fir_Trunk",
      "support": 15
    },
    {
      "x": 3,
      "y": 1,
      "z": 0,
      "name": "Wood_Fir_Trunk",
      "support": 15
    },
    {
      "x": 3,
      "y": 2,
      "z": 0,
      "name": "Wood_Fir_Trunk",
      "support": 15
    },
    {
      "x": 3,
      "y": 3,
      "z": 0,
      "name": "Wood_Fir_Trunk",
      "support": 15
    },
    {
      "x": 3,
      "y": 4,
      "z": 0,
      "name": "Wood_Fir_Trunk",
      "support": 15
    },
    {
      "x": 3,
      "y": 5,
      "z": 0,
      "name": "Wood_Fir_Trunk",
      "support": 15
    },
    {
      "x": 3,
      "y": 6,
      "z": 0,
      "name": "Wood_Fir_Trunk",
      "support": 15
    },
    {
      "x": 3,
      "y": 7,
      "z": 0,
      "name": "Wood_Fir_Trunk",
      "support": 15
    },
    {
      "x": 3,
      "y": 8,
      "z": 0,
      "name": "Wood_Fir_Trunk",
      "support": 15
    },
    {
      "x": 3,
      "y": 9,
      "z": 0,
      "name": "Wood_Fir_Trunk",
      "support": 15
    },
    {
      "x": 3,
      "y": 10,
      "z": 0,
      "name": "Wood_Fir_Trunk",
      "support": 15,
      "rotation": 5
    },
    {
      "x": 3,
      "y": 11,
      "z": 0,
      "name": "Wood_Deadwood_Planks"
    },
    {
      "x": 3,
      "y": 12,
      "z": 0,
      "name": "Wood_Deadwood_Roof",
      "rotation": 2
    },
    {
      "x": 3,
      "y": 0,
      "z": 1,
      "name": "Wood_Fir_Trunk",
      "support": 15
    },
    {
      "x": 3,
      "y": 1,
      "z": 1,
      "name": "Wood_Fir_Trunk",
      "support": 15
    },
    {
      "x": 3,
      "y": 2,
      "z": 1,
      "name": "Wood_Fir_Trunk",
      "support": 15
    },
    {
      "x": 3,
      "y": 3,
      "z": 1,
      "name": "Wood_Fir_Trunk",
      "support": 15
    },
    {
      "x": 3,
      "y": 4,
      "z": 1,
      "name": "Wood_Fir_Trunk",
      "support": 15
    },
    {
      "x": 3,
      "y": 5,
      "z": 1,
      "name": "Wood_Fir_Trunk",
      "support": 15
    },
    {
      "x": 3,
      "y": 6,
      "z": 1,
      "name": "Wood_Fir_Trunk",
      "support": 15
    },
    {
      "x": 3,
      "y": 7,
      "z": 1,
      "name": "Wood_Fir_Trunk",
      "support": 15
    },
    {
      "x": 3,
      "y": 8,
      "z": 1,
      "name": "Wood_Fir_Trunk",
      "support": 15
    },
    {
      "x": 3,
      "y": 9,
      "z": 1,
      "name": "Wood_Fir_Trunk",
      "support": 15
    },
    {
      "x": 3,
      "y": 10,
      "z": 1,
      "name": "Wood_Fir_Trunk",
      "support": 15,
      "rotation": 5
    },
    {
      "x": 3,
      "y": 11,
      "z": 1,
      "name": "Wood_Deadwood_Planks"
    },
    {
      "x": 3,
      "y": 12,
      "z": 1,
      "name": "Wood_Deadwood_Roof"
    },
    {
      "x": 3,
      "y": 7,
      "z": 2,
      "name": "Wood_Torch_Wall"
    },
    {
      "x": 3,
      "y": 10,
      "z": 2,
      "name": "Wood_Fir_Branch_Long",
      "support": 15,
      "rotation": 5
    },
    {
      "x": 3,
      "y": 11,
      "z": 2,
      "name": "Wood_Deadwood_Roof"
    },
    {
      "x": 4,
      "y": 10,
      "z": -3,
      "name": "Wood_Deadwood_Beam",
      "rotation": 4
    },
    {
      "x": 4,
      "y": 10,
      "z": -2,
      "name": "Wood_Fir_Branch_Long",
      "support": 15,
      "rotation": 4
    },
    {
      "x": 4,
      "y": 8,
      "z": -1,
      "name": "Deco_Iron_Chain_Small"
    },
    {
      "x": 4,
      "y": 9,
      "z": -1,
      "name": "Wood_Fir_Branch_Long",
      "support": 15
    },
    {
      "x": 4,
      "y": 10,
      "z": -1,
      "name": "Wood_Fir_Trunk",
      "support": 15,
      "rotation": 4
    },
    {
      "x": 4,
      "y": 11,
      "z": -1,
      "name": "Wood_Deadwood_Roof",
      "rotation": 2
    },
    {
      "x": 4,
      "y": 0,
      "z": 0,
      "name": "Wood_Fir_Trunk",
      "support": 15
    },
    {
      "x": 4,
      "y": 1,
      "z": 0,
      "name": "Wood_Fir_Trunk",
      "support": 15
    },
    {
      "x": 4,
      "y": 2,
      "z": 0,
      "name": "Wood_Fir_Trunk",
      "support": 15
    },
    {
      "x": 4,
      "y": 3,
      "z": 0,
      "name": "Wood_Fir_Trunk",
      "support": 15
    },
    {
      "x": 4,
      "y": 4,
      "z": 0,
      "name": "Wood_Fir_Trunk",
      "support": 15
    },
    {
      "x": 4,
      "y": 5,
      "z": 0,
      "name": "Wood_Fir_Trunk",
      "support": 15
    },
    {
      "x": 4,
      "y": 6,
      "z": 0,
      "name": "Wood_Fir_Trunk",
      "support": 15
    },
    {
      "x": 4,
      "y": 7,
      "z": 0,
      "name": "Wood_Fir_Trunk",
      "support": 15
    },
    {
      "x": 4,
      "y": 8,
      "z": 0,
      "name": "Wood_Fir_Trunk",
      "support": 15
    },
    {
      "x": 4,
      "y": 9,
      "z": 0,
      "name": "Wood_Fir_Trunk",
      "support": 15
    },
    {
      "x": 4,
      "y": 10,
      "z": 0,
      "name": "Wood_Fir_Trunk",
      "support": 15,
      "rotation": 4
    },
    {
      "x": 4,
      "y": 11,
      "z": 0,
      "name": "Wood_Deadwood_Planks"
    },
    {
      "x": 4,
      "y": 12,
      "z": 0,
      "name": "Wood_Deadwood_Roof",
      "rotation": 2
    },
    {
      "x": 4,
      "y": 0,
      "z": 1,
      "name": "Wood_Fir_Trunk",
      "support": 15
    },
    {
      "x": 4,
      "y": 1,
      "z": 1,
      "name": "Wood_Fir_Trunk",
      "support": 15
    },
    {
      "x": 4,
      "y": 2,
      "z": 1,
      "name": "Wood_Fir_Trunk",
      "support": 15
    },
    {
      "x": 4,
      "y": 3,
      "z": 1,
      "name": "Wood_Fir_Trunk",
      "support": 15
    },
    {
      "x": 4,
      "y": 4,
      "z": 1,
      "name": "Wood_Fir_Trunk",
      "support": 15
    },
    {
      "x": 4,
      "y": 5,
      "z": 1,
      "name": "Wood_Fir_Trunk",
      "support": 15
    },
    {
      "x": 4,
      "y": 6,
      "z": 1,
      "name": "Wood_Fir_Trunk",
      "support": 15
    },
    {
      "x": 4,
      "y": 7,
      "z": 1,
      "name": "Wood_Fir_Trunk",
      "support": 15
    },
    {
      "x": 4,
      "y": 8,
      "z": 1,
      "name": "Wood_Fir_Trunk",
      "support": 15
    },
    {
      "x": 4,
      "y": 9,
      "z": 1,
      "name": "Wood_Fir_Trunk",
      "support": 15
    },
    {
      "x": 4,
      "y": 10,
      "z": 1,
      "name": "Wood_Fir_Trunk",
      "support": 15,
      "rotation": 4
    },
    {
      "x": 4,
      "y": 11,
      "z": 1,
      "name": "Wood_Deadwood_Planks"
    },
    {
      "x": 4,
      "y": 12,
      "z": 1,
      "name": "Wood_Deadwood_Roof"
    },
    {
      "x": 4,
      "y": 8,
      "z": 2,
      "name": "Deco_Bone_Spine",
      "rotation": 1
    },
    {
      "x": 4,
      "y": 9,
      "z": 2,
      "name": "Deco_Iron_Chain_Small"
    },
    {
      "x": 4,
      "y": 10,
      "z": 2,
      "name": "Wood_Fir_Trunk",
      "support": 15,
      "rotation": 4
    },
    {
      "x": 4,
      "y": 11,
      "z": 2,
      "name": "Wood_Deadwood_Roof"
    },
    {
      "x": 5,
      "y": 10,
      "z": -1,
      "name": "Wood_Fir_Trunk",
      "support": 15,
      "rotation": 4
    },
    {
      "x": 5,
      "y": 11,
      "z": -1,
      "name": "Wood_Deadwood_Stairs",
      "rotation": 2
    },
    {
      "x": 5,
      "y": 9,
      "z": 0,
      "name": "Wood_Deadwood_Stairs",
      "rotation": 11
    },
    {
      "x": 5,
      "y": 10,
      "z": 0,
      "name": "Wood_Fir_Trunk",
      "support": 15,
      "rotation": 4
    },
    {
      "x": 5,
      "y": 11,
      "z": 0,
      "name": "Wood_Deadwood_Planks"
    },
    {
      "x": 5,
      "y": 12,
      "z": 0,
      "name": "Wood_Deadwood_Stairs",
      "rotation": 2
    },
    {
      "x": 5,
      "y": 13,
      "z": 0,
      "name": "Wood_Deadwood_Stairs"
    },
    {
      "x": 5,
      "y": 9,
      "z": 1,
      "name": "Wood_Deadwood_Stairs",
      "rotation": 11
    },
    {
      "x": 5,
      "y": 10,
      "z": 1,
      "name": "Wood_Fir_Trunk",
      "support": 15,
      "rotation": 4
    },
    {
      "x": 5,
      "y": 11,
      "z": 1,
      "name": "Wood_Deadwood_Planks"
    },
    {
      "x": 5,
      "y": 12,
      "z": 1,
      "name": "Wood_Deadwood_Stairs"
    },
    {
      "x": 5,
      "y": 13,
      "z": 1,
      "name": "Wood_Deadwood_Stairs",
      "rotation": 2
    },
    {
      "x": 5,
      "y": 10,
      "z": 2,
      "name": "Wood_Fir_Trunk",
      "support": 15,
      "rotation": 4
    },
    {
      "x": 5,
      "y": 11,
      "z": 2,
      "name": "Wood_Deadwood_Stairs"
    },
    {
      "x": 5,
      "y": 10,
      "z": 3,
      "name": "Wood_Fir_Trunk",
      "support": 15,
      "rotation": 4
    },
    {
      "x": 5,
      "y": 10,
      "z": 4,
      "name": "Wood_Deadwood_Beam",
      "rotation": 4
    }
  ]
}