{
  "version": 8,
  "blockIdVersion": 8,
  "anchorX": 0,
  "anchorY": 0,
  "anchorZ": 0,
  "blocks": [
    {
      "x": -4,
      "y": -7,
      "z": 1,
      "name": "Rock_Stone"
    },
    {
      "x": -4,
      "y": -6,
      "z": 1,
      "name": "Rock_Stone"
    },
    {
      "x": -4,
      "y": -5,
      "z": 1,
      "name": "Rock_Stone"
    },
    {
      "x": -4,
      "y": -8,
      "z": 2,
      "name": "Rock_Stone"
    },
    {
      "x": -4,
      "y": -7,
      "z": 2,
      "name": "Rock_Stone"
    },
    {
      "x": -4,
      "y": -6,
      "z": 2,
      "name": "Rock_Stone"
    },
    {
      "x": -4,
      "y": -5,
      "z": 2,
      "name": "Rock_Stone"
    },
    {
      "x": -4,
      "y": -4,
      "z": 2,
      "name": "Rock_Stone"
    },
    {
      "x": -4,
      "y": -3,
      "z": 2,
      "name": "Rock_Stone"
    },
    {
      "x": -4,
      "y": -7,
      "z": 3,
      "name": "Rock_Stone"
    },
    {
      "x": -4,
      "y": -6,
      "z": 3,
      "name": "Rock_Stone"
    },
    {
      "x": -4,
      "y": -5,
      "z": 3,
      "name": "Rock_Stone"
    },
    {
      "x": -4,
      "y": -4,
      "z": 3,
      "name": "Rock_Stone"
    },
    {
      "x": -3,
      "y": -7,
      "z": -1,
      "name": "Rock_Stone"
    },
    {
      "x": -3,
      "y": -6,
      "z": -1,
      "name": "Rock_Stone"
    },
    {
      "x": -3,
      "y": -8,
      "z": 0,
      "name": "Rock_Stone"
    },
    {
      "x": -3,
      "y": -7,
      "z": 0,
      "name": "Rock_Stone"
    },
    {
      "x": -3,
      "y": -6,
      "z": 0,
      "name": "Rock_Stone"
    },
    {
      "x": -3,
      "y": -5,
      "z": 0,
      "name": "Rock_Stone"
    },
    {
      "x": -3,
      "y": -4,
      "z": 0,
      "name": "Rock_Stone"
    },
    {
      "x": -3,
      "y": -8,
      "z": 1,
      "name": "Rock_Stone"
    },
    {
      "x": -3,
      "y": -7,
      "z": 1,
      "name": "Rock_Stone"
    },
    {
      "x": -3,
      "y": -6,
      "z": 1,
      "name": "Rock_Stone"
    },
    {
      "x": -3,
      "y": -5,
      "z": 1,
      "name": "Rock_Stone"
    },
    {
      "x": -3,
      "y": -4,
      "z": 1,
      "name": "Rock_Stone"
    },
    {
      "x": -3,
      "y": -3,
      "z": 1,
      "name": "Rock_Stone"
    },
    {
      "x": -3,
      "y": -8,
      "z": 2,
      "name": "Rock_Stone"
    },
    {
      "x": -3,
      "y": -7,
      "z": 2,
      "name": "Rock_Stone"
    },
    {
      "x": -3,
      "y": -6,
      "z": 2,
      "name": "Rock_Stone"
    },
    {
      "x": -3,
      "y": -5,
      "z": 2,
      "name": "Rock_Stone"
    },
    {
      "x": -3,
      "y": -4,
      "z": 2,
      "name": "Rock_Stone"
    },
    {
      "x": -3,
      "y": -3,
      "z": 2,
      "name": "Rock_Stone"
    },
    {
      "x": -3,
      "y": -2,
      "z": 2,
      "name": "Rock_Stone_Cobble_Mossy"
    },
    {
      "x": -3,
      "y": -1,
      "z": 2,
      "name": "Rock_Stone_Cobble_Mossy"
    },
    {
      "x": -3,
      "y": 0,
      "z": 2,
      "name": "Rock_Stone_Brick_Stairs",
      "rotation": 3
    },
    {
      "x": -3,
      "y": -8,
      "z": 3,
      "name": "Rock_Stone"
    },
    {
      "x": -3,
      "y": -7,
      "z": 3,
      "name": "Rock_Stone"
    },
    {
      "x": -3,
      "y": -6,
      "z": 3,
      "name": "Rock_Stone"
    },
    {
      "x": -3,
      "y": -5,
      "z": 3,
      "name": "Rock_Stone"
    },
    {
      "x": -3,
      "y": -4,
      "z": 3,
      "name": "Rock_Stone"
    },
    {
      "x": -3,
      "y": -3,
      "z": 3,
      "name": "Rock_Stone"
    },
    {
      "x": -3,
      "y": -2,
      "z": 3,
      "name": "Rock_Stone_Cobble_Mossy"
    },
    {
      "x": -3,
      "y": -1,
      "z": 3,
      "name": "Rock_Stone_Brick_Mossy"
    },
    {
      "x": -3,
      "y": 0,
      "z": 3,
      "name": "Rock_Stone_Brick_Stairs",
      "rotation": 3
    },
    {
      "x": -3,
      "y": -8,
      "z": 4,
      "name": "Rock_Stone"
    },
    {
      "x": -3,
      "y": -7,
      "z": 4,
      "name": "Rock_Stone"
    },
    {
      "x": -3,
      "y": -6,
      "z": 4,
      "name": "Rock_Stone"
    },
    {
      "x": -3,
      "y": -5,
      "z": 4,
      "name": "Rock_Stone"
    },
    {
      "x": -3,
      "y": -4,
      "z": 4,
      "name": "Rock_Stone"
    },
    {
      "x": -3,
      "y": -3,
      "z": 4,
      "name": "Rock_Stone"
    },
    {
      "x": -3,
      "y": -7,
      "z": 5,
      "name": "Rock_Stone"
    },
    {
      "x": -3,
      "y": -6,
      "z": 5,
      "name": "Rock_Stone"
    },
    {
      "x": -2,
      "y": -8,
      "z": -1,
      "name": "Rock_Stone"
    },
    {
      "x": -2,
      "y": -7,
      "z": -1,
      "name": "Rock_Stone"
    },
    {
      "x": -2,
      "y": -6,
      "z": -1,
      "name": "Rock_Stone"
    },
    {
      "x": -2,
      "y": -5,
      "z": -1,
      "name": "Rock_Stone"
    },
    {
      "x": -2,
      "y": -4,
      "z": -1,
      "name": "Rock_Stone"
    },
    {
      "x": -2,
      "y": -3,
      "z": -1,
      "name": "Rock_Stone"
    },
    {
      "x": -2,
      "y": -8,
      "z": 0,
      "name": "Rock_Stone"
    },
    {
      "x": -2,
      "y": -7,
      "z": 0,
      "name": "Rock_Stone"
    },
    {
      "x": -2,
      "y": -6,
      "z": 0,
      "name": "Rock_Stone_Cobble"
    },
    {
      "x": -2,
      "y": -5,
      "z": 0,
      "name": "Rock_Stone_Cobble"
    },
    {
      "x": -2,
      "y": -4,
      "z": 0,
      "name": "Rock_Stone_Cobble"
    },
    {
      "x": -2,
      "y": -3,
      "z": 0,
      "name": "Rock_Stone_Cobble"
    },
    {
      "x": -2,
      "y": -2,
      "z": 0,
      "name": "Rock_Stone_Cobble_Mossy"
    },
    {
      "x": -2,
      "y": -1,
      "z": 0,
      "name": "Rock_Stone_Cobble_Mossy"
    },
    {
      "x": -2,
      "y": 0,
      "z": 0,
      "name": "Rock_Stone_Cobble_Mossy"
    },
    {
      "x": -2,
      "y": 1,
      "z": 0,
      "name": "Rock_Stone_Brick_Pillar_Base"
    },
    {
      "x": -2,
      "y": -8,
      "z": 1,
      "name": "Rock_Stone"
    },
    {
      "x": -2,
      "y": -7,
      "z": 1,
      "name": "Rock_Stone"
    },
    {
      "x": -2,
      "y": -6,
      "z": 1,
      "name": "Rock_Stone_Cobble"
    },
    {
      "x": -2,
      "y": -5,
      "z": 1,
      "name": "Rock_Stone_Cobble"
    },
    {
      "x": -2,
      "y": -4,
      "z": 1,
      "name": "Rock_Stone_Cobble"
    },
    {
      "x": -2,
      "y": -3,
      "z": 1,
      "name": "Rock_Stone_Cobble"
    },
    {
      "x": -2,
      "y": -2,
      "z": 1,
      "name": "Rock_Stone_Cobble_Mossy"
    },
    {
      "x": -2,
      "y": -1,
      "z": 1,
      "name": "Rock_Stone_Cobble_Mossy"
    },
    {
      "x": -2,
      "y": 0,
      "z": 1,
      "name": "Rock_Stone_Brick_Mossy"
    },
    {
      "x": -2,
      "y": 1,
      "z": 1,
      "name": "Rock_Stone_Brick_Pillar_Base"
    },
    {
      "x": -2,
      "y": 2,
      "z": 1,
      "name": "Rock_Stone_Brick_Pillar_Middle"
    },
    {
      "x": -2,
      "y": 3,
      "z": 1,
      "name": "Rock_Stone_Brick_Pillar_Base",
      "rotation": 8
    },
    {
      "x": -2,
      "y": -8,
      "z": 2,
      "name": "Rock_Stone"
    },
    {
      "x": -2,
      "y": -7,
      "z": 2,
      "name": "Rock_Stone"
    },
    {
      "x": -2,
      "y": -6,
      "z": 2,
      "name": "Rock_Stone_Cobble"
    },
    {
      "x": -2,
      "y": -5,
      "z": 2,
      "name": "Rock_Stone_Cobble"
    },
    {
      "x": -2,
      "y": -4,
      "z": 2,
      "name": "Rock_Stone_Cobble"
    },
    {
      "x": -2,
      "y": -3,
      "z": 2,
      "name": "Rock_Stone_Cobble"
    },
    {
      "x": -2,
      "y": -2,
      "z": 2,
      "name": "Rock_Stone_Cobble"
    },
    {
      "x": -2,
      "y": -1,
      "z": 2,
      "name": "Rock_Stone_Cobble"
    },
    {
      "x": -2,
      "y": 0,
      "z": 2,
      "name": "Rock_Stone_Brick"
    },
    {
      "x": -2,
      "y": 1,
      "z": 2,
      "name": "Rock_Stone_Brick"
    },
    {
      "x": -2,
      "y": 2,
      "z": 2,
      "name": "Rock_Stone_Brick"
    },
    {
      "x": -2,
      "y": 3,
      "z": 2,
      "name": "Rock_Stone_Brick_Half",
      "rotation": 7
    },
    {
      "x": -2,
      "y": 4,
      "z": 2,
      "name": "Rock_Stone_Brick_Roof",
      "rotation": 3
    },
    {
      "x": -2,
      "y": -8,
      "z": 3,
      "name": "Rock_Stone"
    },
    {
      "x": -2,
      "y": -7,
      "z": 3,
      "name": "Rock_Stone"
    },
    {
      "x": -2,
      "y": -6,
      "z": 3,
      "name": "Rock_Stone_Cobble"
    },
    {
      "x": -2,
      "y": -5,
      "z": 3,
      "name": "Rock_Stone_Cobble"
    },
    {
      "x": -2,
      "y": -4,
      "z": 3,
      "name": "Rock_Stone_Cobble"
    },
    {
      "x": -2,
      "y": -3,
      "z": 3,
      "name": "Rock_Stone_Cobble"
    },
    {
      "x": -2,
      "y": -2,
      "z": 3,
      "name": "Rock_Stone_Cobble"
    },
    {
      "x": -2,
      "y": -1,
      "z": 3,
      "name": "Rock_Stone_Brick"
    },
    {
      "x": -2,
      "y": 0,
      "z": 3,
      "name": "Rock_Stone_Brick"
    },
    {
      "x": -2,
      "y": 1,
      "z": 3,
      "name": "Rock_Stone_Brick"
    },
    {
      "x": -2,
      "y": 2,
      "z": 3,
      "name": "Rock_Stone_Brick_Half",
      "rotation": 7
    },
    {
      "x": -2,
      "y": 3,
      "z": 3,
      "name": "Rock_Stone_Brick_Half",
      "rotation": 7
    },
    {
      "x": -2,
      "y": 4,
      "z": 3,
      "name": "Rock_Stone_Brick_Roof",
      "rotation": 3
    },
    {
      "x": -2,
      "y": -8,
      "z": 4,
      "name": "Rock_Stone"
    },
    {
      "x": -2,
      "y": -7,
      "z": 4,
      "name": "Rock_Stone"
    },
    {
      "x": -2,
      "y": -6,
      "z": 4,
      "name": "Rock_Stone_Cobble"
    },
    {
      "x": -2,
      "y": -5,
      "z": 4,
      "name": "Rock_Stone_Cobble"
    },
    {
      "x": -2,
      "y": -4,
      "z": 4,
      "name": "Rock_Stone_Cobble"
    },
    {
      "x": -2,
      "y": -3,
      "z": 4,
      "name": "Rock_Stone_Cobble_Mossy"
    },
    {
      "x": -2,
      "y": -2,
      "z": 4,
      "name": "Rock_Stone_Cobble_Mossy"
    },
    {
      "x": -2,
      "y": -1,
      "z": 4,
      "name": "Rock_Stone_Brick_Mossy"
    },
    {
      "x": -2,
      "y": 0,
      "z": 4,
      "name": "Rock_Stone_Brick_Mossy"
    },
    {
      "x": -2,
      "y": 1,
      "z": 4,
      "name": "Rock_Stone_Brick_Pillar_Base"
    },
    {
      "x": -2,
      "y": 2,
      "z": 4,
      "name": "Rock_Stone_Brick_Pillar_Middle"
    },
    {
      "x": -2,
      "y": 3,
      "z": 4,
      "name": "Rock_Stone_Brick_Pillar_Base",
      "rotation": 8
    },
    {
      "x": -2,
      "y": 4,
      "z": 4,
      "name": "Plant_Moss_Rug_Green_Dark"
    },
    {
      "x": -2,
      "y": -8,
      "z": 5,
      "name": "Rock_Stone"
    },
    {
      "x": -2,
      "y": -7,
      "z": 5,
      "name": "Rock_Stone"
    },
    {
      "x": -2,
      "y": -6,
      "z": 5,
      "name": "Rock_Stone"
    },
    {
      "x": -2,
      "y": -5,
      "z": 5,
      "name": "Rock_Stone"
    },
    {
      "x": -2,
      "y": -4,
      "z": 5,
      "name": "Rock_Stone"
    },
    {
      "x": -1,
      "y": -6,
      "z": -3,
      "name": "Rock_Stone_Brick"
    },
    {
      "x": -1,
      "y": -5,
      "z": -3,
      "name": "Rock_Stone_Brick"
    },
    {
      "x": -1,
      "y": -4,
      "z": -3,
      "name": "Rock_Stone_Brick_Stairs",
      "rotation": 2
    },
    {
      "x": -1,
      "y": -7,
      "z": -2,
      "name": "Rock_Stone"
    },
    {
      "x": -1,
      "y": -6,
      "z": -2,
      "name": "Rock_Stone_Brick"
    },
    {
      "x": -1,
      "y": -5,
      "z": -2,
      "name": "Rock_Stone_Brick"
    },
    {
      "x": -1,
      "y": -4,
      "z": -2,
      "name": "Rock_Stone_Brick_Mossy"
    },
    {
      "x": -1,
      "y": -3,
      "z": -2,
      "name": "Rock_Stone_Brick_Mossy"
    },
    {
      "x": -1,
      "y": -8,
      "z": -1,
      "name": "Rock_Stone"
    },
    {
      "x": -1,
      "y": -7,
      "z": -1,
      "name": "Rock_Stone"
    },
    {
      "x": -1,
      "y": -6,
      "z": -1,
      "name": "Rock_Stone_Brick"
    },
    {
      "x": -1,
      "y": -5,
      "z": -1,
      "name": "Rock_Stone_Brick"
    },
    {
      "x": -1,
      "y": -4,
      "z": -1,
      "name": "Rock_Stone_Brick"
    },
    {
      "x": -1,
      "y": -3,
      "z": -1,
      "name": "Rock_Stone_Brick"
    },
    {
      "x": -1,
      "y": -2,
      "z": -1,
      "name": "Rock_Stone_Brick_Mossy"
    },
    {
      "x": -1,
      "y": -1,
      "z": -1,
      "name": "Rock_Stone_Brick_Mossy"
    },
    {
      "x": -1,
      "y": 0,
      "z": -1,
      "name": "Rock_Stone_Brick_Stairs",
      "rotation": 2
    },
    {
      "x": -1,
      "y": -8,
      "z": 0,
      "name": "Rock_Stone"
    },
    {
      "x": -1,
      "y": -7,
      "z": 0,
      "name": "Rock_Stone"
    },
    {
      "x": -1,
      "y": -6,
      "z": 0,
      "name": "Rock_Stone_Brick"
    },
    {
      "x": -1,
      "y": -5,
      "z": 0,
      "name": "Rock_Stone_Brick"
    },
    {
      "x": -1,
      "y": -4,
      "z": 0,
      "name": "Rock_Stone_Brick"
    },
    {
      "x": -1,
      "y": -3,
      "z": 0,
      "name": "Rock_Stone_Brick"
    },
    {
      "x": -1,
      "y": -2,
      "z": 0,
      "name": "Rock_Stone_Brick"
    },
    {
      "x": -1,
      "y": -1,
      "z": 0,
      "name": "Rock_Stone_Brick"
    },
    {
      "x": -1,
      "y": 0,
      "z": 0,
      "name": "Rock_Stone_Brick"
    },
    {
      "x": -1,
      "y": 1,
      "z": 0,
      "name": "Rock_Stone_Brick_Stairs",
      "rotation": 2
    },
    {
      "x": -1,
      "y": -8,
      "z": 1,
      "name": "Rock_Stone"
    },
    {
      "x": -1,
      "y": -7,
      "z": 1,
      "name": "Rock_Stone"
    },
    {
      "x": -1,
      "y": -6,
      "z": 1,
      "name": "Rock_Stone_Brick"
    },
    {
      "x": -1,
      "y": -5,
      "z": 1,
      "name": "Rock_Stone_Brick"
    },
    {
      "x": -1,
      "y": -4,
      "z": 1,
      "name": "Rock_Stone_Brick"
    },
    {
      "x": -1,
      "y": -3,
      "z": 1,
      "name": "Rock_Stone_Brick"
    },
    {
      "x": -1,
      "y": -2,
      "z": 1,
      "name": "Rock_Stone_Brick"
    },
    {
      "x": -1,
      "y": -1,
      "z": 1,
      "name": "Rock_Stone_Brick"
    },
    {
      "x": -1,
      "y": 0,
      "z": 1,
      "name": "Rock_Stone_Brick"
    },
    {
      "x": -1,
      "y": 1,
      "z": 1,
      "name": "Rock_Stone_Brick"
    },
    {
      "x": -1,
      "y": 2,
      "z": 1,
      "name": "*Rock_Stone_Brick_Wall_State_Definitions_Corner",
      "rotation": 1
    },
    {
      "x": -1,
      "y": 3,
      "z": 1,
      "name": "Empty"
    },
    {
      "x": -1,
      "y": 4,
      "z": 1,
      "name": "Empty"
    },
    {
      "x": -1,
      "y": -8,
      "z": 2,
      "name": "Rock_Stone"
    },
    {
      "x": -1,
      "y": -7,
      "z": 2,
      "name": "Rock_Stone"
    },
    {
      "x": -1,
      "y": -6,
      "z": 2,
      "name": "Rock_Stone_Brick"
    },
    {
      "x": -1,
      "y": -5,
      "z": 2,
      "name": "Rock_Stone_Brick"
    },
    {
      "x": -1,
      "y": -4,
      "z": 2,
      "name": "Rock_Stone_Brick"
    },
    {
      "x": -1,
      "y": -3,
      "z": 2,
      "name": "Rock_Stone_Brick"
    },
    {
      "x": -1,
      "y": -2,
      "z": 2,
      "name": "Rock_Stone_Brick"
    },
    {
      "x": -1,
      "y": -1,
      "z": 2,
      "name": "Rock_Stone_Brick_Smooth"
    },
    {
      "x": -1,
      "y": 0,
      "z": 2,
      "name": "Furniture_Human_Ruins_Coffin",
      "filler": 992,
      "rotation": 1
    },
    {
      "x": -1,
      "y": 1,
      "z": 2,
      "name": "Empty"
    },
    {
      "x": -1,
      "y": 2,
      "z": 2,
      "name": "Rock_Stone_Brick_Smooth"
    },
    {
      "x": -1,
      "y": 3,
      "z": 2,
      "name": "Rock_Stone_Brick_Smooth"
    },
    {
      "x": -1,
      "y": 4,
      "z": 2,
      "name": "Rock_Stone_Brick_Smooth"
    },
    {
      "x": -1,
      "y": 5,
      "z": 2,
      "name": "Rock_Stone_Brick_Half"
    },
    {
      "x": -1,
      "y": -8,
      "z": 3,
      "name": "Rock_Stone"
    },
    {
      "x": -1,
      "y": -7,
      "z": 3,
      "name": "Rock_Stone"
    },
    {
      "x": -1,
      "y": -6,
      "z": 3,
      "name": "Rock_Stone_Brick"
    },
    {
      "x": -1,
      "y": -5,
      "z": 3,
      "name": "Rock_Stone_Brick"
    },
    {
      "x": -1,
      "y": -4,
      "z": 3,
      "name": "Rock_Stone_Brick"
    },
    {
      "x": -1,
      "y": -3,
      "z": 3,
      "name": "Rock_Stone_Brick"
    },
    {
      "x": -1,
      "y": -2,
      "z": 3,
      "name": "Rock_Stone_Brick"
    },
    {
      "x": -1,
      "y": -1,
      "z": 3,
      "name": "Rock_Stone_Brick_Smooth"
    },
    {
      "x": -1,
      "y": 0,
      "z": 3,
      "name": "Furniture_Human_Ruins_Coffin",
      "rotation": 1
    },
    {
      "x": -1,
      "y": 1,
      "z": 3,
      "name": "Empty"
    },
    {
      "x": -1,
      "y": 2,
      "z": 3,
      "name": "Rock_Stone_Brick_Smooth"
    },
    {
      "x": -1,
      "y": 3,
      "z": 3,
      "name": "Rock_Stone_Brick_Smooth_Half",
      "rotation": 4
    },
    {
      "x": -1,
      "y": 4,
      "z": 3,
      "name": "Rock_Stone_Brick_Smooth_Half",
      "rotation": 4
    },
    {
      "x": -1,
      "y": 5,
      "z": 3,
      "name": "Rock_Stone_Brick_Half"
    },
    {
      "x": -1,
      "y": -8,
      "z": 4,
      "name": "Rock_Stone"
    },
    {
      "x": -1,
      "y": -7,
      "z": 4,
      "name": "Rock_Stone"
    },
    {
      "x": -1,
      "y": -6,
      "z": 4,
      "name": "Rock_Stone_Cobble"
    },
    {
      "x": -1,
      "y": -5,
      "z": 4,
      "name": "Rock_Stone_Cobble"
    },
    {
      "x": -1,
      "y": -4,
      "z": 4,
      "name": "Rock_Stone_Cobble"
    },
    {
      "x": -1,
      "y": -3,
      "z": 4,
      "name": "Rock_Stone_Cobble"
    },
    {
      "x": -1,
      "y": -2,
      "z": 4,
      "name": "Rock_Stone_Cobble_Mossy"
    },
    {
      "x": -1,
      "y": -1,
      "z": 4,
      "name": "Rock_Stone_Cobble_Mossy"
    },
    {
      "x": -1,
      "y": 0,
      "z": 4,
      "name": "Rock_Stone_Brick_Mossy"
    },
    {
      "x": -1,
      "y": 1,
      "z": 4,
      "name": "Rock_Stone_Brick"
    },
    {
      "x": -1,
      "y": 2,
      "z": 4,
      "name": "Plant_Moss_Rug_Green_Dark"
    },
    {
      "x": -1,
      "y": -8,
      "z": 5,
      "name": "Rock_Stone"
    },
    {
      "x": -1,
      "y": -7,
      "z": 5,
      "name": "Rock_Stone"
    },
    {
      "x": -1,
      "y": -6,
      "z": 5,
      "name": "Rock_Stone"
    },
    {
      "x": -1,
      "y": -5,
      "z": 5,
      "name": "Rock_Stone"
    },
    {
      "x": -1,
      "y": -4,
      "z": 5,
      "name": "Rock_Stone"
    },
    {
      "x": -1,
      "y": -3,
      "z": 5,
      "name": "Rock_Stone"
    },
    {
      "x": -1,
      "y": 1,
      "z": 5,
      "name": "Plant_Vine_Wall"
    },
    {
      "x": -1,
      "y": -7,
      "z": 6,
      "name": "Rock_Stone"
    },
    {
      "x": -1,
      "y": -6,
      "z": 6,
      "name": "Rock_Stone"
    },
    {
      "x": -1,
      "y": -5,
      "z": 6,
      "name": "Rock_Stone"
    },
    {
      "x": -1,
      "y": -4,
      "z": 6,
      "name": "Rock_Stone"
    },
    {
      "x": 0,
      "y": -6,
      "z": -3,
      "name": "Rock_Stone_Brick"
    },
    {
      "x": 0,
      "y": -5,
      "z": -3,
      "name": "Rock_Stone_Brick_Stairs",
      "rotation": 2
    },
    {
      "x": 0,
      "y": -8,
      "z": -2,
      "name": "Rock_Stone"
    },
    {
      "x": 0,
      "y": -7,
      "z": -2,
      "name": "Rock_Stone"
    },
    {
      "x": 0,
      "y": -6,
      "z": -2,
      "name": "Rock_Stone_Brick"
    },
    {
      "x": 0,
      "y": -5,
      "z": -2,
      "name": "Rock_Stone_Brick"
    },
    {
      "x": 0,
      "y": -4,
      "z": -2,
      "name": "Rock_Stone_Brick_Mossy"
    },
    {
      "x": 0,
      "y": -3,
      "z": -2,
      "name": "Rock_Stone_Brick_Stairs",
      "rotation": 2
    },
    {
      "x": 0,
      "y": -8,
      "z": -1,
      "name": "Rock_Stone"
    },
    {
      "x": 0,
      "y": -7,
      "z": -1,
      "name": "Rock_Stone"
    },
    {
      "x": 0,
      "y": -6,
      "z": -1,
      "name": "Rock_Stone_Brick"
    },
    {
      "x": 0,
      "y": -5,
      "z": -1,
      "name": "Rock_Stone_Brick"
    },
    {
      "x": 0,
      "y": -4,
      "z": -1,
      "name": "Rock_Stone_Brick"
    },
    {
      "x": 0,
      "y": -3,
      "z": -1,
      "name": "Rock_Stone_Brick"
    },
    {
      "x": 0,
      "y": -2,
      "z": -1,
      "name": "Rock_Stone_Brick_Mossy"
    },
    {
      "x": 0,
      "y": -1,
      "z": -1,
      "name": "Rock_Stone_Brick_Mossy"
    },
    {
      "x": 0,
      "y": 0,
      "z": -1,
      "name": "Rock_Stone_Brick_Stairs",
      "rotation": 2
    },
    {
      "x": 0,
      "y": -8,
      "z": 0,
      "name": "Rock_Stone"
    },
    {
      "x": 0,
      "y": -7,
      "z": 0,
      "name": "Rock_Stone"
    },
    {
      "x": 0,
      "y": -6,
      "z": 0,
      "name": "Rock_Stone_Brick"
    },
    {
      "x": 0,
      "y": -5,
      "z": 0,
      "name": "Rock_Stone_Brick"
    },
    {
      "x": 0,
      "y": -4,
      "z": 0,
      "name": "Rock_Stone_Brick"
    },
    {
      "x": 0,
      "y": -3,
      "z": 0,
      "name": "Rock_Stone_Brick"
    },
    {
      "x": 0,
      "y": -2,
      "z": 0,
      "name": "Rock_Stone_Brick"
    },
    {
      "x": 0,
      "y": -1,
      "z": 0,
      "name": "Rock_Stone_Brick"
    },
    {
      "x": 0,
      "y": 0,
      "z": 0,
      "name": "Rock_Stone_Brick"
    },
    {
      "x": 0,
      "y": 1,
      "z": 0,
      "name": "Rock_Stone_Brick_Stairs",
      "rotation": 2
    },
    {
      "x": 0,
      "y": -8,
      "z": 1,
      "name": "Rock_Stone"
    },
    {
      "x": 0,
      "y": -7,
      "z": 1,
      "name": "Rock_Stone"
    },
    {
      "x": 0,
      "y": -6,
      "z": 1,
      "name": "Rock_Stone_Brick"
    },
    {
      "x": 0,
      "y": -5,
      "z": 1,
      "name": "Rock_Stone_Brick"
    },
    {
      "x": 0,
      "y": -4,
      "z": 1,
      "name": "Rock_Stone_Brick"
    },
    {
      "x": 0,
      "y": -3,
      "z": 1,
      "name": "Rock_Stone_Brick"
    },
    {
      "x": 0,
      "y": -2,
      "z": 1,
      "name": "Rock_Stone_Brick"
    },
    {
      "x": 0,
      "y": -1,
      "z": 1,
      "name": "Rock_Stone_Brick"
    },
    {
      "x": 0,
      "y": 0,
      "z": 1,
      "name": "Rock_Stone_Brick"
    },
    {
      "x": 0,
      "y": 1,
      "z": 1,
      "name": "Rock_Stone_Brick"
    },
    {
      "x": 0,
      "y": 2,
      "z": 1,
      "name": "Furniture_Village_Tombstone",
      "rotation": 2
    },
    {
      "x": 0,
      "y": 3,
      "z": 1,
      "name": "Furniture_Village_Tombstone",
      "filler": 1024,
      "rotation": 2
    },
    {
      "x": 0,
      "y": 4,
      "z": 1,
      "name": "Empty"
    },
    {
      "x": 0,
      "y": -8,
      "z": 2,
      "name": "Rock_Stone"
    },
    {
      "x": 0,
      "y": -7,
      "z": 2,
      "name": "Rock_Stone"
    },
    {
      "x": 0,
      "y": -6,
      "z": 2,
      "name": "Rock_Stone_Brick"
    },
    {
      "x": 0,
      "y": -5,
      "z": 2,
      "name": "Rock_Stone_Brick"
    },
    {
      "x": 0,
      "y": -4,
      "z": 2,
      "name": "Rock_Stone_Brick"
    },
    {
      "x": 0,
      "y": -3,
      "z": 2,
      "name": "Rock_Stone_Brick"
    },
    {
      "x": 0,
      "y": -2,
      "z": 2,
      "name": "Rock_Stone_Brick"
    },
    {
      "x": 0,
      "y": -1,
      "z": 2,
      "name": "Rock_Stone_Brick_Smooth"
    },
    {
      "x": 0,
      "y": 0,
      "z": 2,
      "name": "Empty"
    },
    {
      "x": 0,
      "y": 1,
      "z": 2,
      "name": "Empty"
    },
    {
      "x": 0,
      "y": 2,
      "z": 2,
      "name": "Rock_Stone_Brick_Smooth"
    },
    {
      "x": 0,
      "y": 3,
      "z": 2,
      "name": "Rock_Stone_Brick_Smooth"
    },
    {
      "x": 0,
      "y": 4,
      "z": 2,
      "name": "Rock_Stone_Brick_Smooth"
    },
    {
      "x": 0,
      "y": 5,
      "z": 2,
      "name": "Rock_Stone_Brick"
    },
    {
      "x": 0,
      "y": 6,
      "z": 2,
      "name": "Plant_Moss_Rug_Green_Dark"
    },
    {
      "x": 0,
      "y": -8,
      "z": 3,
      "name": "Rock_Stone"
    },
    {
      "x": 0,
      "y": -7,
      "z": 3,
      "name": "Rock_Stone"
    },
    {
      "x": 0,
      "y": -6,
      "z": 3,
      "name": "Rock_Stone_Brick"
    },
    {
      "x": 0,
      "y": -5,
      "z": 3,
      "name": "Rock_Stone_Brick"
    },
    {
      "x": 0,
      "y": -4,
      "z": 3,
      "name": "Rock_Stone_Brick"
    },
    {
      "x": 0,
      "y": -3,
      "z": 3,
      "name": "Rock_Stone_Brick"
    },
    {
      "x": 0,
      "y": -2,
      "z": 3,
      "name": "Rock_Stone_Brick"
    },
    {
      "x": 0,
      "y": -1,
      "z": 3,
      "name": "Rock_Stone_Brick_Smooth"
    },
    {
      "x": 0,
      "y": 0,
      "z": 3,
      "name": "Plant_Crop_Health1"
    },
    {
      "x": 0,
      "y": 1,
      "z": 3,
      "name": "Empty"
    },
    {
      "x": 0,
      "y": 2,
      "z": 3,
      "name": "Rock_Stone_Brick_Smooth"
    },
    {
      "x": 0,
      "y": 3,
      "z": 3,
      "name": "Rock_Stone_Brick_Smooth"
    },
    {
      "x": 0,
      "y": 4,
      "z": 3,
      "name": "Rock_Stone_Brick_Smooth_Half",
      "rotation": 4
    },
    {
      "x": 0,
      "y": 5,
      "z": 3,
      "name": "Rock_Stone_Brick"
    },
    {
      "x": 0,
      "y": 6,
      "z": 3,
      "name": "Plant_Moss_Short_Green_Dark"
    },
    {
      "x": 0,
      "y": -8,
      "z": 4,
      "name": "Rock_Stone"
    },
    {
      "x": 0,
      "y": -7,
      "z": 4,
      "name": "Rock_Stone"
    },
    {
      "x": 0,
      "y": -6,
      "z": 4,
      "name": "Rock_Stone_Cobble"
    },
    {
      "x": 0,
      "y": -5,
      "z": 4,
      "name": "Rock_Stone_Cobble"
    },
    {
      "x": 0,
      "y": -4,
      "z": 4,
      "name": "Rock_Stone_Cobble"
    },
    {
      "x": 0,
      "y": -3,
      "z": 4,
      "name": "Rock_Stone_Cobble"
    },
    {
      "x": 0,
      "y": -2,
      "z": 4,
      "name": "Rock_Stone_Cobble_Mossy"
    },
    {
      "x": 0,
      "y": -1,
      "z": 4,
      "name": "Rock_Stone_Cobble_Mossy"
    },
    {
      "x": 0,
      "y": 0,
      "z": 4,
      "name": "Rock_Stone_Brick_Mossy"
    },
    {
      "x": 0,
      "y": 1,
      "z": 4,
      "name": "Rock_Stone_Brick_Mossy"
    },
    {
      "x": 0,
      "y": 2,
      "z": 4,
      "name": "Plant_Crop_Mushroom_Shelve_Green"
    },
    {
      "x": 0,
      "y": -8,
      "z": 5,
      "name": "Rock_Stone"
    },
    {
      "x": 0,
      "y": -7,
      "z": 5,
      "name": "Rock_Stone"
    },
    {
      "x": 0,
      "y": -6,
      "z": 5,
      "name": "Rock_Stone"
    },
    {
      "x": 0,
      "y": -5,
      "z": 5,
      "name": "Rock_Stone"
    },
    {
      "x": 0,
      "y": -4,
      "z": 5,
      "name": "Rock_Stone"
    },
    {
      "x": 0,
      "y": -3,
      "z": 5,
      "name": "Rock_Stone"
    },
    {
      "x": 0,
      "y": 1,
      "z": 5,
      "name": "Plant_Vine_Wall"
    },
    {
      "x": 0,
      "y": -8,
      "z": 6,
      "name": "Rock_Stone"
    },
    {
      "x": 0,
      "y": -7,
      "z": 6,
      "name": "Rock_Stone"
    },
    {
      "x": 0,
      "y": -6,
      "z": 6,
      "name": "Rock_Stone"
    },
    {
      "x": 0,
      "y": -5,
      "z": 6,
      "name": "Rock_Stone"
    },
    {
      "x": 0,
      "y": -4,
      "z": 6,
      "name": "Rock_Stone"
    },
    {
      "x": 1,
      "y": -7,
      "z": -2,
      "name": "Rock_Stone"
    },
    {
      "x": 1,
      "y": -6,
      "z": -2,
      "name": "Rock_Stone_Brick"
    },
    {
      "x": 1,
      "y": -5,
      "z": -2,
      "name": "Rock_Stone_Brick"
    },
    {
      "x": 1,
      "y": -4,
      "z": -2,
      "name": "Rock_Stone_Brick_Mossy"
    },
    {
      "x": 1,
      "y": -3,
      "z": -2,
      "name": "Rock_Stone_Brick_Stairs",
      "rotation": 2
    },
    {
      "x": 1,
      "y": -8,
      "z": -1,
      "name": "Rock_Stone"
    },
    {
      "x": 1,
      "y": -7,
      "z": -1,
      "name": "Rock_Stone"
    },
    {
      "x": 1,
      "y": -6,
      "z": -1,
      "name": "Rock_Stone_Brick"
    },
    {
      "x": 1,
      "y": -5,
      "z": -1,
      "name": "Rock_Stone_Brick"
    },
    {
      "x": 1,
      "y": -4,
      "z": -1,
      "name": "Rock_Stone_Brick"
    },
    {
      "x": 1,
      "y": -3,
      "z": -1,
      "name": "Rock_Stone_Brick_Mossy"
    },
    {
      "x": 1,
      "y": -2,
      "z": -1,
      "name": "Rock_Stone_Brick_Mossy"
    },
    {
      "x": 1,
      "y": -1,
      "z": -1,
      "name": "Furniture_Village_Tombstone",
      "rotation": 1
    },
    {
      "x": 1,
      "y": 0,
      "z": -1,
      "name": "Furniture_Village_Tombstone",
      "filler": 1024,
      "rotation": 1
    },
    {
      "x": 1,
      "y": -8,
      "z": 0,
      "name": "Rock_Stone"
    },
    {
      "x": 1,
      "y": -7,
      "z": 0,
      "name": "Rock_Stone"
    },
    {
      "x": 1,
      "y": -6,
      "z": 0,
      "name": "Rock_Stone_Brick"
    },
    {
      "x": 1,
      "y": -5,
      "z": 0,
      "name": "Rock_Stone_Brick"
    },
    {
      "x": 1,
      "y": -4,
      "z": 0,
      "name": "Rock_Stone_Brick"
    },
    {
      "x": 1,
      "y": -3,
      "z": 0,
      "name": "Rock_Stone_Brick"
    },
    {
      "x": 1,
      "y": -2,
      "z": 0,
      "name": "Rock_Stone_Brick"
    },
    {
      "x": 1,
      "y": -1,
      "z": 0,
      "name": "Rock_Stone_Brick"
    },
    {
      "x": 1,
      "y": 0,
      "z": 0,
      "name": "Rock_Stone_Brick"
    },
    {
      "x": 1,
      "y": 1,
      "z": 0,
      "name": "Rock_Stone_Brick_Stairs",
      "rotation": 2
    },
    {
      "x": 1,
      "y": -8,
      "z": 1,
      "name": "Rock_Stone"
    },
    {
      "x": 1,
      "y": -7,
      "z": 1,
      "name": "Rock_Stone"
    },
    {
      "x": 1,
      "y": -6,
      "z": 1,
      "name": "Rock_Stone_Brick"
    },
    {
      "x": 1,
      "y": -5,
      "z": 1,
      "name": "Rock_Stone_Brick"
    },
    {
      "x": 1,
      "y": -4,
      "z": 1,
      "name": "Rock_Stone_Brick"
    },
    {
      "x": 1,
      "y": -3,
      "z": 1,
      "name": "Rock_Stone_Brick"
    },
    {
      "x": 1,
      "y": -2,
      "z": 1,
      "name": "Rock_Stone_Brick"
    },
    {
      "x": 1,
      "y": -1,
      "z": 1,
      "name": "Rock_Stone_Brick"
    },
    {
      "x": 1,
      "y": 0,
      "z": 1,
      "name": "Rock_Stone_Brick"
    },
    {
      "x": 1,
      "y": 1,
      "z": 1,
      "name": "Rock_Stone_Brick"
    },
    {
      "x": 1,
      "y": 2,
      "z": 1,
      "name": "Plant_Crop_Mushroom_Cap_Brown",
      "components": {
        "Components": {
          "FarmingBlock": {}
        }
      }
    },
    {
      "x": 1,
      "y": 3,
      "z": 1,
      "name": "Empty"
    },
    {
      "x": 1,
      "y": 4,
      "z": 1,
      "name": "Empty"
    },
    {
      "x": 1,
      "y": 5,
      "z": 1,
      "name": "Rock_Stone_Brick_Stairs",
      "rotation": 9
    },
    {
      "x": 1,
      "y": 6,
      "z": 1,
      "name": "Plant_Moss_Rug_Green_Dark"
    },
    {
      "x": 1,
      "y": -8,
      "z": 2,
      "name": "Rock_Stone"
    },
    {
      "x": 1,
      "y": -7,
      "z": 2,
      "name": "Rock_Stone"
    },
    {
      "x": 1,
      "y": -6,
      "z": 2,
      "name": "Rock_Stone_Brick"
    },
    {
      "x": 1,
      "y": -5,
      "z": 2,
      "name": "Rock_Stone_Brick"
    },
    {
      "x": 1,
      "y": -4,
      "z": 2,
      "name": "Rock_Stone_Brick"
    },
    {
      "x": 1,
      "y": -3,
      "z": 2,
      "name": "Rock_Stone_Brick"
    },
    {
      "x": 1,
      "y": -2,
      "z": 2,
      "name": "Rock_Stone_Brick"
    },
    {
      "x": 1,
      "y": -1,
      "z": 2,
      "name": "Rock_Stone_Brick_Smooth"
    },
    {
      "x": 1,
      "y": 0,
      "z": 2,
      "name": "Furniture_Human_Ruins_Coffin",
      "filler": 992,
      "rotation": 1
    },
    {
      "x": 1,
      "y": 1,
      "z": 2,
      "name": "Empty"
    },
    {
      "x": 1,
      "y": 2,
      "z": 2,
      "name": "Rock_Stone_Brick_Smooth"
    },
    {
      "x": 1,
      "y": 3,
      "z": 2,
      "name": "Rock_Stone_Brick_Smooth"
    },
    {
      "x": 1,
      "y": 4,
      "z": 2,
      "name": "Rock_Stone_Brick_Smooth"
    },
    {
      "x": 1,
      "y": 5,
      "z": 2,
      "name": "Rock_Stone_Brick"
    },
    {
      "x": 1,
      "y": 6,
      "z": 2,
      "name": "Plant_Moss_Rug_Green_Dark"
    },
    {
      "x": 1,
      "y": -8,
      "z": 3,
      "name": "Rock_Stone"
    },
    {
      "x": 1,
      "y": -7,
      "z": 3,
      "name": "Rock_Stone"
    },
    {
      "x": 1,
      "y": -6,
      "z": 3,
      "name": "Rock_Stone_Brick"
    },
    {
      "x": 1,
      "y": -5,
      "z": 3,
      "name": "Rock_Stone_Brick"
    },
    {
      "x": 1,
      "y": -4,
      "z": 3,
      "name": "Rock_Stone_Brick"
    },
    {
      "x": 1,
      "y": -3,
      "z": 3,
      "name": "Rock_Stone_Brick"
    },
    {
      "x": 1,
      "y": -2,
      "z": 3,
      "name": "Rock_Stone_Brick"
    },
    {
      "x": 1,
      "y": -1,
      "z": 3,
      "name": "Rock_Stone_Brick_Smooth"
    },
    {
      "x": 1,
      "y": 0,
      "z": 3,
      "name": "Furniture_Human_Ruins_Coffin",
      "rotation": 1
    },
    {
      "x": 1,
      "y": 1,
      "z": 3,
      "name": "Empty"
    },
    {
      "x": 1,
      "y": 2,
      "z": 3,
      "name": "Rock_Stone_Brick_Smooth"
    },
    {
      "x": 1,
      "y": 3,
      "z": 3,
      "name": "Rock_Stone_Brick_Smooth"
    },
    {
      "x": 1,
      "y": 4,
      "z": 3,
      "name": "Rock_Stone_Brick_Smooth"
    },
    {
      "x": 1,
      "y": 5,
      "z": 3,
      "name": "Rock_Stone_Brick"
    },
    {
      "x": 1,
      "y": -8,
      "z": 4,
      "name": "Rock_Stone"
    },
    {
      "x": 1,
      "y": -7,
      "z": 4,
      "name": "Rock_Stone"
    },
    {
      "x": 1,
      "y": -6,
      "z": 4,
      "name": "Rock_Stone_Cobble"
    },
    {
      "x": 1,
      "y": -5,
      "z": 4,
      "name": "Rock_Stone_Cobble"
    },
    {
      "x": 1,
      "y": -4,
      "z": 4,
      "name": "Rock_Stone_Cobble"
    },
    {
      "x": 1,
      "y": -3,
      "z": 4,
      "name": "Rock_Stone_Cobble"
    },
    {
      "x": 1,
      "y": -2,
      "z": 4,
      "name": "Rock_Stone_Cobble_Mossy"
    },
    {
      "x": 1,
      "y": -1,
      "z": 4,
      "name": "Rock_Stone_Cobble_Mossy"
    },
    {
      "x": 1,
      "y": 0,
      "z": 4,
      "name": "Rock_Stone_Brick_Mossy"
    },
    {
      "x": 1,
      "y": 1,
      "z": 4,
      "name": "Rock_Stone_Brick_Mossy"
    },
    {
      "x": 1,
      "y": 2,
      "z": 4,
      "name": "Rock_Stone_Brick_Half",
      "rotation": 7
    },
    {
      "x": 1,
      "y": 3,
      "z": 4,
      "name": "Rock_Stone_Brick_Half",
      "rotation": 7
    },
    {
      "x": 1,
      "y": 4,
      "z": 4,
      "name": "Rock_Stone_Brick_Decorative"
    },
    {
      "x": 1,
      "y": 5,
      "z": 4,
      "name": "Rock_Stone_Brick_Half"
    },
    {
      "x": 1,
      "y": -8,
      "z": 5,
      "name": "Rock_Stone"
    },
    {
      "x": 1,
      "y": -7,
      "z": 5,
      "name": "Rock_Stone"
    },
    {
      "x": 1,
      "y": -6,
      "z": 5,
      "name": "Rock_Stone"
    },
    {
      "x": 1,
      "y": -5,
      "z": 5,
      "name": "Rock_Stone"
    },
    {
      "x": 1,
      "y": -4,
      "z": 5,
      "name": "Rock_Stone"
    },
    {
      "x": 1,
      "y": -3,
      "z": 5,
      "name": "Rock_Stone"
    },
    {
      "x": 1,
      "y": -7,
      "z": 6,
      "name": "Rock_Stone"
    },
    {
      "x": 1,
      "y": -6,
      "z": 6,
      "name": "Rock_Stone"
    },
    {
      "x": 1,
      "y": -5,
      "z": 6,
      "name": "Rock_Stone"
    },
    {
      "x": 2,
      "y": -8,
      "z": -1,
      "name": "Rock_Stone"
    },
    {
      "x": 2,
      "y": -7,
      "z": -1,
      "name": "Rock_Stone"
    },
    {
      "x": 2,
      "y": -6,
      "z": -1,
      "name": "Rock_Stone"
    },
    {
      "x": 2,
      "y": -5,
      "z": -1,
      "name": "Rock_Stone"
    },
    {
      "x": 2,
      "y": -4,
      "z": -1,
      "name": "Rock_Stone"
    },
    {
      "x": 2,
      "y": -8,
      "z": 0,
      "name": "Rock_Stone"
    },
    {
      "x": 2,
      "y": -7,
      "z": 0,
      "name": "Rock_Stone"
    },
    {
      "x": 2,
      "y": -6,
      "z": 0,
      "name": "Rock_Stone_Cobble"
    },
    {
      "x": 2,
      "y": -5,
      "z": 0,
      "name": "Rock_Stone_Cobble"
    },
    {
      "x": 2,
      "y": -4,
      "z": 0,
      "name": "Rock_Stone_Cobble"
    },
    {
      "x": 2,
      "y": -3,
      "z": 0,
      "name": "Rock_Stone_Cobble"
    },
    {
      "x": 2,
      "y": -2,
      "z": 0,
      "name": "Rock_Stone_Cobble"
    },
    {
      "x": 2,
      "y": -1,
      "z": 0,
      "name": "Rock_Stone_Cobble_Mossy"
    },
    {
      "x": 2,
      "y": 0,
      "z": 0,
      "name": "Rock_Stone_Brick_Pillar_Base",
      "rotation": 8
    },
    {
      "x": 2,
      "y": 1,
      "z": 0,
      "name": "Rock_Stone_Brick_Pillar_Base"
    },
    {
      "x": 2,
      "y": 2,
      "z": 0,
      "name": "Rock_Stone_Brick_Pillar_Base",
      "rotation": 8
    },
    {
      "x": 2,
      "y": -8,
      "z": 1,
      "name": "Rock_Stone"
    },
    {
      "x": 2,
      "y": -7,
      "z": 1,
      "name": "Rock_Stone"
    },
    {
      "x": 2,
      "y": -6,
      "z": 1,
      "name": "Rock_Stone_Cobble"
    },
    {
      "x": 2,
      "y": -5,
      "z": 1,
      "name": "Rock_Stone_Cobble"
    },
    {
      "x": 2,
      "y": -4,
      "z": 1,
      "name": "Rock_Stone_Cobble"
    },
    {
      "x": 2,
      "y": -3,
      "z": 1,
      "name": "Rock_Stone_Cobble"
    },
    {
      "x": 2,
      "y": -2,
      "z": 1,
      "name": "Rock_Stone_Cobble_Mossy"
    },
    {
      "x": 2,
      "y": -1,
      "z": 1,
      "name": "Rock_Stone_Cobble"
    },
    {
      "x": 2,
      "y": 0,
      "z": 1,
      "name": "Rock_Stone_Cobble"
    },
    {
      "x": 2,
      "y": 1,
      "z": 1,
      "name": "Rock_Stone_Brick_Pillar_Base"
    },
    {
      "x": 2,
      "y": 2,
      "z": 1,
      "name": "Rock_Stone_Brick_Pillar_Middle"
    },
    {
      "x": 2,
      "y": 3,
      "z": 1,
      "name": "Rock_Stone_Brick_Pillar_Base",
      "rotation": 8
    },
    {
      "x": 2,
      "y": 4,
      "z": 1,
      "name": "Rock_Stone_Brick_Decorative"
    },
    {
      "x": 2,
      "y": 5,
      "z": 1,
      "name": "Rock_Stone_Brick_Roof",
      "rotation": 1
    },
    {
      "x": 2,
      "y": -8,
      "z": 2,
      "name": "Rock_Stone"
    },
    {
      "x": 2,
      "y": -7,
      "z": 2,
      "name": "Rock_Stone"
    },
    {
      "x": 2,
      "y": -6,
      "z": 2,
      "name": "Rock_Stone_Cobble"
    },
    {
      "x": 2,
      "y": -5,
      "z": 2,
      "name": "Rock_Stone_Cobble"
    },
    {
      "x": 2,
      "y": -4,
      "z": 2,
      "name": "Rock_Stone_Cobble"
    },
    {
      "x": 2,
      "y": -3,
      "z": 2,
      "name": "Rock_Stone_Cobble"
    },
    {
      "x": 2,
      "y": -2,
      "z": 2,
      "name": "Rock_Stone_Cobble"
    },
    {
      "x": 2,
      "y": -1,
      "z": 2,
      "name": "Rock_Stone_Cobble"
    },
    {
      "x": 2,
      "y": 0,
      "z": 2,
      "name": "Rock_Stone_Cobble"
    },
    {
      "x": 2,
      "y": 1,
      "z": 2,
      "name": "Rock_Stone_Brick"
    },
    {
      "x": 2,
      "y": 2,
      "z": 2,
      "name": "Rock_Stone_Brick"
    },
    {
      "x": 2,
      "y": 3,
      "z": 2,
      "name": "Rock_Stone_Brick_Mossy"
    },
    {
      "x": 2,
      "y": 4,
      "z": 2,
      "name": "Rock_Stone_Brick_Decorative"
    },
    {
      "x": 2,
      "y": 5,
      "z": 2,
      "name": "Rock_Stone_Brick_Roof",
      "rotation": 1
    },
    {
      "x": 2,
      "y": -8,
      "z": 3,
      "name": "Rock_Stone"
    },
    {
      "x": 2,
      "y": -7,
      "z": 3,
      "name": "Rock_Stone"
    },
    {
      "x": 2,
      "y": -6,
      "z": 3,
      "name": "Rock_Stone_Cobble"
    },
    {
      "x": 2,
      "y": -5,
      "z": 3,
      "name": "Rock_Stone_Cobble"
    },
    {
      "x": 2,
      "y": -4,
      "z": 3,
      "name": "Rock_Stone_Cobble"
    },
    {
      "x": 2,
      "y": -3,
      "z": 3,
      "name": "Rock_Stone_Cobble"
    },
    {
      "x": 2,
      "y": -2,
      "z": 3,
      "name": "Rock_Stone_Cobble"
    },
    {
      "x": 2,
      "y": -1,
      "z": 3,
      "name": "Rock_Stone_Cobble"
    },
    {
      "x": 2,
      "y": 0,
      "z": 3,
      "name": "Rock_Stone_Cobble"
    },
    {
      "x": 2,
      "y": 1,
      "z": 3,
      "name": "Rock_Stone_Cobble"
    },
    {
      "x": 2,
      "y": 2,
      "z": 3,
      "name": "Rock_Stone_Brick"
    },
    {
      "x": 2,
      "y": 3,
      "z": 3,
      "name": "Rock_Stone_Brick_Mossy"
    },
    {
      "x": 2,
      "y": 4,
      "z": 3,
      "name": "Rock_Stone_Brick_Decorative"
    },
    {
      "x": 2,
      "y": 5,
      "z": 3,
      "name": "Rock_Stone_Brick_Half"
    },
    {
      "x": 2,
      "y": -8,
      "z": 4,
      "name": "Rock_Stone"
    },
    {
      "x": 2,
      "y": -7,
      "z": 4,
      "name": "Rock_Stone"
    },
    {
      "x": 2,
      "y": -6,
      "z": 4,
      "name": "Rock_Stone_Cobble"
    },
    {
      "x": 2,
      "y": -5,
      "z": 4,
      "name": "Rock_Stone_Cobble"
    },
    {
      "x": 2,
      "y": -4,
      "z": 4,
      "name": "Rock_Stone_Cobble"
    },
    {
      "x": 2,
      "y": -3,
      "z": 4,
      "name": "Rock_Stone_Cobble"
    },
    {
      "x": 2,
      "y": -2,
      "z": 4,
      "name": "Rock_Stone_Cobble_Mossy"
    },
    {
      "x": 2,
      "y": -1,
      "z": 4,
      "name": "Rock_Stone_Cobble_Mossy"
    },
    {
      "x": 2,
      "y": 0,
      "z": 4,
      "name": "Rock_Stone_Cobble_Mossy"
    },
    {
      "x": 2,
      "y": 1,
      "z": 4,
      "name": "Rock_Stone_Brick_Pillar_Base"
    },
    {
      "x": 2,
      "y": 2,
      "z": 4,
      "name": "Rock_Stone_Brick_Pillar_Middle"
    },
    {
      "x": 2,
      "y": 3,
      "z": 4,
      "name": "Rock_Stone_Brick_Pillar_Base",
      "rotation": 8
    },
    {
      "x": 2,
      "y": 4,
      "z": 4,
      "name": "Rock_Stone_Brick_Decorative"
    },
    {
      "x": 2,
      "y": -8,
      "z": 5,
      "name": "Rock_Stone"
    },
    {
      "x": 2,
      "y": -7,
      "z": 5,
      "name": "Rock_Stone"
    },
    {
      "x": 2,
      "y": -6,
      "z": 5,
      "name": "Rock_Stone"
    },
    {
      "x": 2,
      "y": -5,
      "z": 5,
      "name": "Rock_Stone"
    },
    {
      "x": 2,
      "y": -4,
      "z": 5,
      "name": "Rock_Stone"
    },
    {
      "x": 2,
      "y": -2,
      "z": 5,
      "name": "Plant_Vine_Wall"
    },
    {
      "x": 2,
      "y": -1,
      "z": 5,
      "name": "Plant_Vine_Wall"
    },
    {
      "x": 3,
      "y": -7,
      "z": -1,
      "name": "Rock_Stone"
    },
    {
      "x": 3,
      "y": -6,
      "z": -1,
      "name": "Rock_Stone"
    },
    {
      "x": 3,
      "y": -5,
      "z": -1,
      "name": "Rock_Stone"
    },
    {
      "x": 3,
      "y": -8,
      "z": 0,
      "name": "Rock_Stone"
    },
    {
      "x": 3,
      "y": -7,
      "z": 0,
      "name": "Rock_Stone"
    },
    {
      "x": 3,
      "y": -6,
      "z": 0,
      "name": "Rock_Stone"
    },
    {
      "x": 3,
      "y": -5,
      "z": 0,
      "name": "Rock_Stone"
    },
    {
      "x": 3,
      "y": -4,
      "z": 0,
      "name": "Rock_Stone"
    },
    {
      "x": 3,
      "y": -8,
      "z": 1,
      "name": "Rock_Stone"
    },
    {
      "x": 3,
      "y": -7,
      "z": 1,
      "name": "Rock_Stone"
    },
    {
      "x": 3,
      "y": -6,
      "z": 1,
      "name": "Rock_Stone"
    },
    {
      "x": 3,
      "y": -5,
      "z": 1,
      "name": "Rock_Stone"
    },
    {
      "x": 3,
      "y": -4,
      "z": 1,
      "name": "Rock_Stone"
    },
    {
      "x": 3,
      "y": -3,
      "z": 1,
      "name": "Rock_Stone"
    },
    {
      "x": 3,
      "y": -1,
      "z": 1,
      "name": "Plant_Vine",
      "rotation": 1
    },
    {
      "x": 3,
      "y": 0,
      "z": 1,
      "name": "Plant_Vine",
      "rotation": 1
    },
    {
      "x": 3,
      "y": 1,
      "z": 1,
      "name": "Plant_Vine_Wall",
      "rotation": 1
    },
    {
      "x": 3,
      "y": -8,
      "z": 2,
      "name": "Rock_Stone"
    },
    {
      "x": 3,
      "y": -7,
      "z": 2,
      "name": "Rock_Stone"
    },
    {
      "x": 3,
      "y": -6,
      "z": 2,
      "name": "Rock_Stone"
    },
    {
      "x": 3,
      "y": -5,
      "z": 2,
      "name": "Rock_Stone"
    },
    {
      "x": 3,
      "y": -4,
      "z": 2,
      "name": "Rock_Stone"
    },
    {
      "x": 3,
      "y": -3,
      "z": 2,
      "name": "Rock_Stone"
    },
    {
      "x": 3,
      "y": -2,
      "z": 2,
      "name": "Plant_Vine",
      "rotation": 1
    },
    {
      "x": 3,
      "y": -1,
      "z": 2,
      "name": "Plant_Vine",
      "rotation": 1
    },
    {
      "x": 3,
      "y": 0,
      "z": 2,
      "name": "Plant_Vine",
      "rotation": 1
    },
    {
      "x": 3,
      "y": 1,
      "z": 2,
      "name": "Plant_Vine",
      "rotation": 1
    },
    {
      "x": 3,
      "y": 2,
      "z": 2,
      "name": "Plant_Vine_Wall",
      "rotation": 1
    },
    {
      "x": 3,
      "y": -8,
      "z": 3,
      "name": "Rock_Stone"
    },
    {
      "x": 3,
      "y": -7,
      "z": 3,
      "name": "Rock_Stone"
    },
    {
      "x": 3,
      "y": -6,
      "z": 3,
      "name": "Rock_Stone"
    },
    {
      "x": 3,
      "y": -5,
      "z": 3,
      "name": "Rock_Stone"
    },
    {
      "x": 3,
      "y": -4,
      "z": 3,
      "name": "Rock_Stone"
    },
    {
      "x": 3,
      "y": -3,
      "z": 3,
      "name": "Rock_Stone"
    },
    {
      "x": 3,
      "y": -2,
      "z": 3,
      "name": "Plant_Vine_Wall",
      "rotation": 1
    },
    {
      "x": 3,
      "y": -1,
      "z": 3,
      "name": "Plant_Vine_Wall",
      "rotation": 1
    },
    {
      "x": 3,
      "y": 0,
      "z": 3,
      "name": "Plant_Vine_Wall",
      "rotation": 1
    },
    {
      "x": 3,
      "y": 1,
      "z": 3,
      "name": "Plant_Vine",
      "rotation": 1
    },
    {
      "x": 3,
      "y": 2,
      "z": 3,
      "name": "Plant_Vine_Wall",
      "rotation": 1
    },
    {
      "x": 3,
      "y": -8,
      "z": 4,
      "name": "Rock_Stone"
    },
    {
      "x": 3,
      "y": -7,
      "z": 4,
      "name": "Rock_Stone"
    },
    {
      "x": 3,
      "y": -6,
      "z": 4,
      "name": "Rock_Stone"
    },
    {
      "x": 3,
      "y": -5,
      "z": 4,
      "name": "Rock_Stone"
    },
    {
      "x": 3,
      "y": -4,
      "z": 4,
      "name": "Rock_Stone"
    },
    {
      "x": 3,
      "y": -1,
      "z": 4,
      "name": "Plant_Vine_Wall",
      "rotation": 1
    },
    {
      "x": 3,
      "y": 0,
      "z": 4,
      "name": "Plant_Vine_Wall",
      "rotation": 1
    },
    {
      "x": 3,
      "y": -7,
      "z": 5,
      "name": "Rock_Stone"
    },
    {
      "x": 3,
      "y": -6,
      "z": 5,
      "name": "Rock_Stone"
    },
    {
      "x": 3,
      "y": -5,
      "z": 5,
      "name": "Rock_Stone"
    },
    {
      "x": 4,
      "y": -7,
      "z": 1,
      "name": "Rock_Stone"
    },
    {
      "x": 4,
      "y": -6,
      "z": 1,
      "name": "Rock_Stone"
    },
    {
      "x": 4,
      "y": -5,
      "z": 1,
      "name": "Rock_Stone"
    },
    {
      "x": 4,
      "y": -4,
      "z": 1,
      "name": "Rock_Stone"
    },
    {
      "x": 4,
      "y": -8,
      "z": 2,
      "name": "Rock_Stone"
    },
    {
      "x": 4,
      "y": -7,
      "z": 2,
      "name": "Rock_Stone"
    },
    {
      "x": 4,
      "y": -6,
      "z": 2,
      "name": "Rock_Stone"
    },
    {
      "x": 4,
      "y": -5,
      "z": 2,
      "name": "Rock_Stone"
    },
    {
      "x": 4,
      "y": -4,
      "z": 2,
      "name": "Rock_Stone"
    },
    {
      "x": 4,
      "y": -7,
      "z": 3,
      "name": "Rock_Stone"
    },
    {
      "x": 4,
      "y": -6,
      "z": 3,
      "name": "Rock_Stone"
    },
    {
      "x": 4,
      "y": -5,
      "z": 3,
      "name": "Rock_Stone"
    },
    {
      "x": 4,
      "y": -4,
      "z": 3,
      "name": "Rock_Stone"
    }
  ]
}
