{
  "version": 8,
  "blockIdVersion": 8,
  "anchorX": 1,
  "anchorY": 3,
  "anchorZ": -1,
  "blocks": [
    {
      "x": -1,
      "y": 7,
      "z": -2,
      "name": "Plant_Crop_Mushroom_Block_White_Mycelium",
      "rotation": 8
    },
    {
      "x": -1,
      "y": 8,
      "z": -2,
      "name": "Plant_Crop_Mushroom_Block_White"
    },
    {
      "x": -1,
      "y": 7,
      "z": -1,
      "name": "Plant_Crop_Mushroom_Block_White_Mycelium",
      "rotation": 8
    },
    {
      "x": -1,
      "y": 8,
      "z": -1,
      "name": "Plant_Crop_Mushroom_Block_White"
    },
    {
      "x": -1,
      "y": 8,
      "z": 0,
      "name": "Plant_Crop_Mushroom_Block_White"
    },
    {
      "x": 0,
      "y": 8,
      "z": -3,
      "name": "Plant_Crop_Mushroom_Block_White"
    },
    {
      "x": 0,
      "y": 7,
      "z": -2,
      "name": "Plant_Crop_Mushroom_Block_White_Mycelium",
      "rotation": 8
    },
    {
      "x": 0,
      "y": 8,
      "z": -2,
      "name": "Plant_Crop_Mushroom_Block_White"
    },
    {
      "x": 0,
      "y": 9,
      "z": -2,
      "name": "Plant_Crop_Mushroom_Block_White_Mycelium"
    },
    {
      "x": 0,
      "y": 7,
      "z": -1,
      "name": "Plant_Crop_Mushroom_Block_White_Mycelium",
      "rotation": 8
    },
    {
      "x": 0,
      "y": 8,
      "z": -1,
      "name": "Plant_Crop_Mushroom_Block_White"
    },
    {
      "x": 0,
      "y": 9,
      "z": -1,
      "name": "Plant_Crop_Mushroom_Block_White_Mycelium"
    },
    {
      "x": 0,
      "y": 7,
      "z": 0,
      "name": "Plant_Crop_Mushroom_Block_White_Mycelium",
      "rotation": 8
    },
    {
      "x": 0,
      "y": 8,
      "z": 0,
      "name": "Plant_Crop_Mushroom_Block_White"
    },
    {
      "x": 0,
      "y": 8,
      "z": 1,
      "name": "Plant_Crop_Mushroom_Block_White"
    },
    {
      "x": 1,
      "y": 8,
      "z": -3,
      "name": "Plant_Crop_Mushroom_Block_White"
    },
    {
      "x": 1,
      "y": 8,
      "z": -2,
      "name": "Plant_Crop_Mushroom_Block_White"
    },
    {
      "x": 1,
      "y": 9,
      "z": -2,
      "name": "Plant_Crop_Mushroom_Block_White_Mycelium"
    },
    {
      "x": 1,
      "y": 3,
      "z": -1,
      "name": "Plant_Crop_Mushroom_Block_White_Branch"
    },
    {
      "x": 1,
      "y": 4,
      "z": -1,
      "name": "Plant_Crop_Mushroom_Block_White_Branch"
    },
    {
      "x": 1,
      "y": 5,
      "z": -1,
      "name": "Plant_Crop_Mushroom_Block_White_Branch"
    },
    {
      "x": 1,
      "y": 6,
      "z": -1,
      "name": "Plant_Crop_Mushroom_Block_White_Branch"
    },
    {
      "x": 1,
      "y": 7,
      "z": -1,
      "name": "Plant_Crop_Mushroom_Block_White_Branch"
    },
    {
      "x": 1,
      "y": 8,
      "z": -1,
      "name": "Plant_Crop_Mushroom_Block_White"
    },
    {
      "x": 1,
      "y": 7,
      "z": 0,
      "name": "Plant_Crop_Mushroom_Block_White_Mycelium",
      "rotation": 8
    },
    {
      "x": 1,
      "y": 8,
      "z": 0,
      "name": "Plant_Crop_Mushroom_Block_White"
    },
    {
      "x": 1,
      "y": 8,
      "z": 1,
      "name": "Plant_Crop_Mushroom_Block_White"
    },
    {
      "x": 2,
      "y": 7,
      "z": -3,
      "name": "Plant_Crop_Mushroom_Block_White_Mycelium",
      "rotation": 8
    },
    {
      "x": 2,
      "y": 8,
      "z": -3,
      "name": "Plant_Crop_Mushroom_Block_White"
    },
    {
      "x": 2,
      "y": 7,
      "z": -2,
      "name": "Plant_Crop_Mushroom_Block_White_Mycelium",
      "rotation": 8
    },
    {
      "x": 2,
      "y": 8,
      "z": -2,
      "name": "Plant_Crop_Mushroom_Block_White"
    },
    {
      "x": 2,
      "y": 7,
      "z": -1,
      "name": "Plant_Crop_Mushroom_Block_White_Mycelium",
      "rotation": 8
    },
    {
      "x": 2,
      "y": 8,
      "z": -1,
      "name": "Plant_Crop_Mushroom_Block_White"
    },
    {
      "x": 2,
      "y": 7,
      "z": 0,
      "name": "Plant_Crop_Mushroom_Block_White_Mycelium",
      "rotation": 8
    },
    {
      "x": 2,
      "y": 8,
      "z": 0,
      "name": "Plant_Crop_Mushroom_Block_White"
    },
    {
      "x": 2,
      "y": 7,
      "z": 1,
      "name": "Plant_Crop_Mushroom_Block_White_Mycelium",
      "rotation": 8
    },
    {
      "x": 2,
      "y": 8,
      "z": 1,
      "name": "Plant_Crop_Mushroom_Block_White"
    },
    {
      "x": 3,
      "y": 7,
      "z": -2,
      "name": "Plant_Crop_Mushroom_Block_White_Mycelium",
      "rotation": 8
    },
    {
      "x": 3,
      "y": 8,
      "z": -2,
      "name": "Plant_Crop_Mushroom_Block_White"
    },
    {
      "x": 3,
      "y": 8,
      "z": -1,
      "name": "Plant_Crop_Mushroom_Block_White"
    },
    {
      "x": 3,
      "y": 7,
      "z": 0,
      "name": "Plant_Crop_Mushroom_Block_White_Mycelium",
      "rotation": 8
    },
    {
      "x": 3,
      "y": 8,
      "z": 0,
      "name": "Plant_Crop_Mushroom_Block_White"
    }
  ]
}