{
  "version": 8,
  "blockIdVersion": 8,
  "anchorX": 0,
  "anchorY": 11,
  "anchorZ": 0,
  "blocks": [
    {
      "x": -3,
      "y": 6,
      "z": -1,
      "name": "Wood_Fir_Roots"
    },
    {
      "x": -3,
      "y": 7,
      "z": -1,
      "name": "Wood_Fir_Trunk_Full"
    },
    {
      "x": -3,
      "y": 18,
      "z": 0,
      "name": "Plant_Leaves_Dead"
    },
    {
      "x": -2,
      "y": 8,
      "z": 0,
      "name": "Wood_Fir_Trunk"
    },
    {
      "x": -2,
      "y": 9,
      "z": 0,
      "name": "Wood_Fir_Trunk"
    },
    {
      "x": -2,
      "y": 10,
      "z": 0,
      "name": "Wood_Fir_Trunk_Full"
    },
    {
      "x": -2,
      "y": 18,
      "z": 0,
      "name": "Plant_Leaves_Dead"
    },
    {
      "x": -2,
      "y": 20,
      "z": 0,
      "name": "Plant_Leaves_Dead"
    },
    {
      "x": -2,
      "y": 21,
      "z": 0,
      "name": "Plant_Leaves_Dead"
    },
    {
      "x": -2,
      "y": 18,
      "z": 1,
      "name": "Plant_Leaves_Dead"
    },
    {
      "x": -1,
      "y": 20,
      "z": -2,
      "name": "Plant_Leaves_Dead"
    },
    {
      "x": -1,
      "y": 18,
      "z": -1,
      "name": "Plant_Leaves_Dead"
    },
    {
      "x": -1,
      "y": 20,
      "z": -1,
      "name": "Plant_Leaves_Dead"
    },
    {
      "x": -1,
      "y": 22,
      "z": -1,
      "name": "Plant_Leaves_Dead"
    },
    {
      "x": -1,
      "y": 10,
      "z": 0,
      "name": "Wood_Fir_Trunk"
    },
    {
      "x": -1,
      "y": 11,
      "z": 0,
      "name": "Wood_Fir_Trunk"
    },
    {
      "x": -1,
      "y": 12,
      "z": 0,
      "name": "Wood_Fir_Trunk_Full"
    },
    {
      "x": -1,
      "y": 18,
      "z": 0,
      "name": "Wood_Fir_Branch_Long",
      "rotation": 5
    },
    {
      "x": -1,
      "y": 20,
      "z": 0,
      "name": "Wood_Fir_Branch_Corner",
      "rotation": 3
    },
    {
      "x": -1,
      "y": 23,
      "z": 0,
      "name": "Plant_Leaves_Dead"
    },
    {
      "x": -1,
      "y": 24,
      "z": 0,
      "name": "Plant_Leaves_Dead"
    },
    {
      "x": -1,
      "y": 25,
      "z": 0,
      "name": "Plant_Leaves_Dead"
    },
    {
      "x": -1,
      "y": 17,
      "z": 1,
      "name": "Plant_Leaves_Dead"
    },
    {
      "x": -1,
      "y": 18,
      "z": 1,
      "name": "Plant_Leaves_Dead"
    },
    {
      "x": -1,
      "y": 20,
      "z": 1,
      "name": "Plant_Leaves_Dead"
    },
    {
      "x": -1,
      "y": 22,
      "z": 1,
      "name": "Plant_Leaves_Dead"
    },
    {
      "x": -1,
      "y": 7,
      "z": 2,
      "name": "Wood_Fir_Roots"
    },
    {
      "x": -1,
      "y": 8,
      "z": 2,
      "name": "Wood_Fir_Trunk"
    },
    {
      "x": -1,
      "y": 9,
      "z": 2,
      "name": "Wood_Fir_Trunk_Full"
    },
    {
      "x": 0,
      "y": 21,
      "z": -3,
      "name": "Plant_Leaves_Dead"
    },
    {
      "x": 0,
      "y": 8,
      "z": -2,
      "name": "Wood_Fir_Roots"
    },
    {
      "x": 0,
      "y": 9,
      "z": -2,
      "name": "Wood_Fir_Trunk_Full"
    },
    {
      "x": 0,
      "y": 20,
      "z": -2,
      "name": "Plant_Leaves_Dead"
    },
    {
      "x": 0,
      "y": 22,
      "z": -2,
      "name": "Plant_Leaves_Dead"
    },
    {
      "x": 0,
      "y": 23,
      "z": -2,
      "name": "Plant_Leaves_Dead"
    },
    {
      "x": 0,
      "y": 10,
      "z": -1,
      "name": "Wood_Fir_Trunk"
    },
    {
      "x": 0,
      "y": 11,
      "z": -1,
      "name": "Wood_Fir_Trunk"
    },
    {
      "x": 0,
      "y": 12,
      "z": -1,
      "name": "Wood_Fir_Trunk"
    },
    {
      "x": 0,
      "y": 13,
      "z": -1,
      "name": "Wood_Fir_Trunk_Full"
    },
    {
      "x": 0,
      "y": 20,
      "z": -1,
      "name": "Wood_Fir_Branch_Corner",
      "rotation": 2
    },
    {
      "x": 0,
      "y": 22,
      "z": -1,
      "name": "Wood_Fir_Branch_Long",
      "rotation": 4
    },
    {
      "x": 0,
      "y": 24,
      "z": -1,
      "name": "Plant_Leaves_Dead"
    },
    {
      "x": 0,
      "y": 25,
      "z": -1,
      "name": "Plant_Leaves_Dead"
    },
    {
      "x": 0,
      "y": 26,
      "z": -1,
      "name": "Plant_Leaves_Dead"
    },
    {
      "x": 0,
      "y": 11,
      "z": 0,
      "name": "Wood_Fir_Trunk_Full"
    },
    {
      "x": 0,
      "y": 12,
      "z": 0,
      "name": "Wood_Fir_Trunk"
    },
    {
      "x": 0,
      "y": 13,
      "z": 0,
      "name": "Wood_Fir_Trunk"
    },
    {
      "x": 0,
      "y": 14,
      "z": 0,
      "name": "Wood_Fir_Trunk"
    },
    {
      "x": 0,
      "y": 15,
      "z": 0,
      "name": "Wood_Fir_Trunk"
    },
    {
      "x": 0,
      "y": 16,
      "z": 0,
      "name": "Wood_Fir_Trunk"
    },
    {
      "x": 0,
      "y": 17,
      "z": 0,
      "name": "Wood_Fir_Trunk"
    },
    {
      "x": 0,
      "y": 18,
      "z": 0,
      "name": "Wood_Fir_Trunk"
    },
    {
      "x": 0,
      "y": 19,
      "z": 0,
      "name": "Wood_Fir_Trunk"
    },
    {
      "x": 0,
      "y": 20,
      "z": 0,
      "name": "Wood_Fir_Trunk"
    },
    {
      "x": 0,
      "y": 21,
      "z": 0,
      "name": "Wood_Fir_Trunk"
    },
    {
      "x": 0,
      "y": 22,
      "z": 0,
      "name": "Wood_Fir_Trunk"
    },
    {
      "x": 0,
      "y": 23,
      "z": 0,
      "name": "Wood_Fir_Trunk"
    },
    {
      "x": 0,
      "y": 24,
      "z": 0,
      "name": "Wood_Fir_Trunk"
    },
    {
      "x": 0,
      "y": 25,
      "z": 0,
      "name": "Plant_Leaves_Dead"
    },
    {
      "x": 0,
      "y": 26,
      "z": 0,
      "name": "Plant_Leaves_Dead"
    },
    {
      "x": 0,
      "y": 27,
      "z": 0,
      "name": "Plant_Leaves_Dead"
    },
    {
      "x": 0,
      "y": 28,
      "z": 0,
      "name": "Plant_Leaves_Dead"
    },
    {
      "x": 0,
      "y": 9,
      "z": 1,
      "name": "Wood_Fir_Trunk"
    },
    {
      "x": 0,
      "y": 10,
      "z": 1,
      "name": "Wood_Fir_Trunk"
    },
    {
      "x": 0,
      "y": 11,
      "z": 1,
      "name": "Wood_Fir_Trunk_Full"
    },
    {
      "x": 0,
      "y": 17,
      "z": 1,
      "name": "Wood_Fir_Branch_Corner"
    },
    {
      "x": 0,
      "y": 20,
      "z": 1,
      "name": "Wood_Fir_Branch_Long",
      "rotation": 4
    },
    {
      "x": 0,
      "y": 22,
      "z": 1,
      "name": "Wood_Fir_Branch_Corner"
    },
    {
      "x": 0,
      "y": 24,
      "z": 1,
      "name": "Plant_Leaves_Dead"
    },
    {
      "x": 0,
      "y": 25,
      "z": 1,
      "name": "Plant_Leaves_Dead"
    },
    {
      "x": 0,
      "y": 9,
      "z": 2,
      "name": "Wood_Fir_Trunk_Full"
    },
    {
      "x": 0,
      "y": 17,
      "z": 2,
      "name": "Plant_Leaves_Dead"
    },
    {
      "x": 0,
      "y": 20,
      "z": 2,
      "name": "Plant_Leaves_Dead"
    },
    {
      "x": 0,
      "y": 22,
      "z": 2,
      "name": "Plant_Leaves_Dead"
    },
    {
      "x": 0,
      "y": 23,
      "z": 2,
      "name": "Plant_Leaves_Dead"
    },
    {
      "x": 0,
      "y": 17,
      "z": 3,
      "name": "Plant_Leaves_Dead"
    },
    {
      "x": 1,
      "y": 11,
      "z": -1,
      "name": "Wood_Fir_Trunk"
    },
    {
      "x": 1,
      "y": 12,
      "z": -1,
      "name": "Wood_Fir_Trunk_Full"
    },
    {
      "x": 1,
      "y": 18,
      "z": -1,
      "name": "Plant_Leaves_Dead"
    },
    {
      "x": 1,
      "y": 20,
      "z": -1,
      "name": "Plant_Leaves_Dead"
    },
    {
      "x": 1,
      "y": 22,
      "z": -1,
      "name": "Plant_Leaves_Dead"
    },
    {
      "x": 1,
      "y": 10,
      "z": 0,
      "name": "Wood_Fir_Trunk"
    },
    {
      "x": 1,
      "y": 11,
      "z": 0,
      "name": "Wood_Fir_Trunk"
    },
    {
      "x": 1,
      "y": 12,
      "z": 0,
      "name": "Wood_Fir_Trunk"
    },
    {
      "x": 1,
      "y": 13,
      "z": 0,
      "name": "Wood_Fir_Trunk"
    },
    {
      "x": 1,
      "y": 14,
      "z": 0,
      "name": "Wood_Fir_Trunk_Full"
    },
    {
      "x": 1,
      "y": 18,
      "z": 0,
      "name": "Wood_Fir_Branch_Long",
      "rotation": 5
    },
    {
      "x": 1,
      "y": 23,
      "z": 0,
      "name": "Plant_Leaves_Dead"
    },
    {
      "x": 1,
      "y": 24,
      "z": 0,
      "name": "Plant_Leaves_Dead"
    },
    {
      "x": 1,
      "y": 17,
      "z": 1,
      "name": "Plant_Leaves_Dead"
    },
    {
      "x": 1,
      "y": 18,
      "z": 1,
      "name": "Plant_Leaves_Dead"
    },
    {
      "x": 1,
      "y": 20,
      "z": 1,
      "name": "Plant_Leaves_Dead"
    },
    {
      "x": 1,
      "y": 22,
      "z": 1,
      "name": "Plant_Leaves_Dead"
    },
    {
      "x": 1,
      "y": 17,
      "z": 2,
      "name": "Plant_Leaves_Dead"
    },
    {
      "x": 1,
      "y": 20,
      "z": 2,
      "name": "Plant_Leaves_Dead"
    },
    {
      "x": 2,
      "y": 18,
      "z": -1,
      "name": "Plant_Leaves_Dead"
    },
    {
      "x": 2,
      "y": 7,
      "z": 0,
      "name": "Wood_Fir_Roots"
    },
    {
      "x": 2,
      "y": 8,
      "z": 0,
      "name": "Wood_Fir_Trunk"
    },
    {
      "x": 2,
      "y": 9,
      "z": 0,
      "name": "Wood_Fir_Trunk"
    },
    {
      "x": 2,
      "y": 10,
      "z": 0,
      "name": "Wood_Fir_Trunk_Full"
    },
    {
      "x": 2,
      "y": 18,
      "z": 0,
      "name": "Plant_Leaves_Dead"
    },
    {
      "x": 2,
      "y": 6,
      "z": 1,
      "name": "Wood_Fir_Roots"
    },
    {
      "x": 2,
      "y": 7,
      "z": 1,
      "name": "Wood_Fir_Trunk"
    },
    {
      "x": 2,
      "y": 8,
      "z": 1,
      "name": "Wood_Fir_Trunk_Full"
    },
    {
      "x": 3,
      "y": 18,
      "z": 0,
      "name": "Plant_Leaves_Dead"
    }
  ]
}