{
  "version": 8,
  "blockIdVersion": 8,
  "anchorX": -1,
  "anchorY": 10,
  "anchorZ": 1,
  "blocks": [
    {
      "x": -7,
      "y": 11,
      "z": -5,
      "name": "*Wood_Hardwood_Fence_State_Definitions_Corner",
      "rotation": 1
    },
    {
      "x": -7,
      "y": 12,
      "z": -5,
      "name": "Empty"
    },
    {
      "x": -7,
      "y": 13,
      "z": -5,
      "name": "Empty"
    },
    {
      "x": -7,
      "y": 8,
      "z": -4,
      "name": "Soil_Dirt"
    },
    {
      "x": -7,
      "y": 9,
      "z": -4,
      "name": "Soil_Dirt"
    },
    {
      "x": -7,
      "y": 10,
      "z": -4,
      "name": "Soil_Leaves"
    },
    {
      "x": -7,
      "y": 11,
      "z": -4,
      "name": "Wood_Hardwood_Fence",
      "rotation": 3
    },
    {
      "x": -7,
      "y": 12,
      "z": -4,
      "name": "Empty"
    },
    {
      "x": -7,
      "y": 13,
      "z": -4,
      "name": "Empty"
    },
    {
      "x": -7,
      "y": 7,
      "z": -3,
      "name": "Soil_Dirt"
    },
    {
      "x": -7,
      "y": 8,
      "z": -3,
      "name": "Soil_Dirt"
    },
    {
      "x": -7,
      "y": 9,
      "z": -3,
      "name": "Soil_Dirt"
    },
    {
      "x": -7,
      "y": 10,
      "z": -3,
      "name": "Soil_Leaves"
    },
    {
      "x": -7,
      "y": 11,
      "z": -3,
      "name": "Wood_Hardwood_Fence",
      "rotation": 3
    },
    {
      "x": -7,
      "y": 12,
      "z": -3,
      "name": "Empty"
    },
    {
      "x": -7,
      "y": 13,
      "z": -3,
      "name": "Empty"
    },
    {
      "x": -7,
      "y": 7,
      "z": -2,
      "name": "Soil_Dirt"
    },
    {
      "x": -7,
      "y": 8,
      "z": -2,
      "name": "Soil_Dirt"
    },
    {
      "x": -7,
      "y": 9,
      "z": -2,
      "name": "Soil_Dirt"
    },
    {
      "x": -7,
      "y": 10,
      "z": -2,
      "name": "Soil_Grass_Deep"
    },
    {
      "x": -7,
      "y": 11,
      "z": -2,
      "name": "Wood_Hardwood_Fence",
      "rotation": 3
    },
    {
      "x": -7,
      "y": 12,
      "z": -2,
      "name": "Empty"
    },
    {
      "x": -7,
      "y": 13,
      "z": -2,
      "name": "Empty"
    },
    {
      "x": -7,
      "y": 6,
      "z": -1,
      "name": "Soil_Dirt"
    },
    {
      "x": -7,
      "y": 7,
      "z": -1,
      "name": "Soil_Dirt"
    },
    {
      "x": -7,
      "y": 8,
      "z": -1,
      "name": "Soil_Dirt"
    },
    {
      "x": -7,
      "y": 9,
      "z": -1,
      "name": "Soil_Dirt"
    },
    {
      "x": -7,
      "y": 10,
      "z": -1,
      "name": "Soil_Dirt"
    },
    {
      "x": -7,
      "y": 11,
      "z": -1,
      "name": "Wood_Hardwood_Fence",
      "rotation": 3
    },
    {
      "x": -7,
      "y": 12,
      "z": -1,
      "name": "Empty"
    },
    {
      "x": -7,
      "y": 13,
      "z": -1,
      "name": "Empty"
    },
    {
      "x": -7,
      "y": 6,
      "z": 0,
      "name": "Soil_Dirt"
    },
    {
      "x": -7,
      "y": 7,
      "z": 0,
      "name": "Soil_Dirt"
    },
    {
      "x": -7,
      "y": 8,
      "z": 0,
      "name": "Soil_Dirt"
    },
    {
      "x": -7,
      "y": 9,
      "z": 0,
      "name": "Soil_Dirt"
    },
    {
      "x": -7,
      "y": 10,
      "z": 0,
      "name": "Soil_Dirt"
    },
    {
      "x": -7,
      "y": 11,
      "z": 0,
      "name": "Wood_Hardwood_Fence",
      "rotation": 3
    },
    {
      "x": -7,
      "y": 12,
      "z": 0,
      "name": "Empty"
    },
    {
      "x": -7,
      "y": 13,
      "z": 0,
      "name": "Empty"
    },
    {
      "x": -7,
      "y": 6,
      "z": 1,
      "name": "Soil_Dirt"
    },
    {
      "x": -7,
      "y": 7,
      "z": 1,
      "name": "Soil_Dirt"
    },
    {
      "x": -7,
      "y": 8,
      "z": 1,
      "name": "Soil_Dirt"
    },
    {
      "x": -7,
      "y": 9,
      "z": 1,
      "name": "Soil_Dirt"
    },
    {
      "x": -7,
      "y": 10,
      "z": 1,
      "name": "Soil_Grass_Deep"
    },
    {
      "x": -7,
      "y": 11,
      "z": 1,
      "name": "Wood_Hardwood_Fence",
      "rotation": 3
    },
    {
      "x": -7,
      "y": 12,
      "z": 1,
      "name": "Empty"
    },
    {
      "x": -7,
      "y": 13,
      "z": 1,
      "name": "Empty"
    },
    {
      "x": -7,
      "y": 7,
      "z": 2,
      "name": "Soil_Dirt"
    },
    {
      "x": -7,
      "y": 8,
      "z": 2,
      "name": "Soil_Dirt"
    },
    {
      "x": -7,
      "y": 9,
      "z": 2,
      "name": "Soil_Dirt"
    },
    {
      "x": -7,
      "y": 10,
      "z": 2,
      "name": "Soil_Grass_Deep"
    },
    {
      "x": -7,
      "y": 11,
      "z": 2,
      "name": "*Wood_Hardwood_Fence_State_Definitions_Corner",
      "rotation": 2
    },
    {
      "x": -7,
      "y": 12,
      "z": 2,
      "name": "Empty"
    },
    {
      "x": -7,
      "y": 13,
      "z": 2,
      "name": "Empty"
    },
    {
      "x": -6,
      "y": 9,
      "z": -5,
      "name": "Soil_Dirt"
    },
    {
      "x": -6,
      "y": 10,
      "z": -5,
      "name": "Soil_Grass_Deep"
    },
    {
      "x": -6,
      "y": 11,
      "z": -5,
      "name": "Wood_Hardwood_Fence",
      "rotation": 2
    },
    {
      "x": -6,
      "y": 12,
      "z": -5,
      "name": "Empty"
    },
    {
      "x": -6,
      "y": 13,
      "z": -5,
      "name": "Empty"
    },
    {
      "x": -6,
      "y": 7,
      "z": -4,
      "name": "Soil_Dirt"
    },
    {
      "x": -6,
      "y": 8,
      "z": -4,
      "name": "Soil_Dirt"
    },
    {
      "x": -6,
      "y": 9,
      "z": -4,
      "name": "Soil_Dirt"
    },
    {
      "x": -6,
      "y": 10,
      "z": -4,
      "name": "Soil_Leaves"
    },
    {
      "x": -6,
      "y": 11,
      "z": -4,
      "name": "Plant_Grass_Lush"
    },
    {
      "x": -6,
      "y": 12,
      "z": -4,
      "name": "Empty"
    },
    {
      "x": -6,
      "y": 13,
      "z": -4,
      "name": "Empty"
    },
    {
      "x": -6,
      "y": 6,
      "z": -3,
      "name": "Soil_Dirt"
    },
    {
      "x": -6,
      "y": 7,
      "z": -3,
      "name": "Soil_Dirt"
    },
    {
      "x": -6,
      "y": 8,
      "z": -3,
      "name": "Soil_Dirt"
    },
    {
      "x": -6,
      "y": 9,
      "z": -3,
      "name": "Soil_Dirt"
    },
    {
      "x": -6,
      "y": 10,
      "z": -3,
      "name": "Soil_Grass_Deep"
    },
    {
      "x": -6,
      "y": 11,
      "z": -3,
      "name": "Empty"
    },
    {
      "x": -6,
      "y": 12,
      "z": -3,
      "name": "Empty"
    },
    {
      "x": -6,
      "y": 13,
      "z": -3,
      "name": "Empty"
    },
    {
      "x": -6,
      "y": 6,
      "z": -2,
      "name": "Soil_Dirt"
    },
    {
      "x": -6,
      "y": 7,
      "z": -2,
      "name": "Soil_Dirt"
    },
    {
      "x": -6,
      "y": 8,
      "z": -2,
      "name": "Soil_Dirt"
    },
    {
      "x": -6,
      "y": 9,
      "z": -2,
      "name": "Soil_Dirt"
    },
    {
      "x": -6,
      "y": 10,
      "z": -2,
      "name": "Soil_Dirt"
    },
    {
      "x": -6,
      "y": 11,
      "z": -2,
      "name": "Empty"
    },
    {
      "x": -6,
      "y": 12,
      "z": -2,
      "name": "Empty"
    },
    {
      "x": -6,
      "y": 13,
      "z": -2,
      "name": "Empty"
    },
    {
      "x": -6,
      "y": 5,
      "z": -1,
      "name": "Soil_Dirt"
    },
    {
      "x": -6,
      "y": 6,
      "z": -1,
      "name": "Soil_Dirt"
    },
    {
      "x": -6,
      "y": 7,
      "z": -1,
      "name": "Soil_Dirt"
    },
    {
      "x": -6,
      "y": 8,
      "z": -1,
      "name": "Soil_Dirt"
    },
    {
      "x": -6,
      "y": 9,
      "z": -1,
      "name": "Soil_Dirt"
    },
    {
      "x": -6,
      "y": 10,
      "z": -1,
      "name": "Soil_Dirt"
    },
    {
      "x": -6,
      "y": 11,
      "z": -1,
      "name": "Empty"
    },
    {
      "x": -6,
      "y": 12,
      "z": -1,
      "name": "Empty"
    },
    {
      "x": -6,
      "y": 13,
      "z": -1,
      "name": "Empty"
    },
    {
      "x": -6,
      "y": 5,
      "z": 0,
      "name": "Soil_Dirt"
    },
    {
      "x": -6,
      "y": 6,
      "z": 0,
      "name": "Soil_Dirt"
    },
    {
      "x": -6,
      "y": 7,
      "z": 0,
      "name": "Soil_Dirt"
    },
    {
      "x": -6,
      "y": 8,
      "z": 0,
      "name": "Soil_Dirt"
    },
    {
      "x": -6,
      "y": 9,
      "z": 0,
      "name": "Soil_Dirt"
    },
    {
      "x": -6,
      "y": 10,
      "z": 0,
      "name": "Soil_Dirt"
    },
    {
      "x": -6,
      "y": 11,
      "z": 0,
      "name": "Empty"
    },
    {
      "x": -6,
      "y": 12,
      "z": 0,
      "name": "Empty"
    },
    {
      "x": -6,
      "y": 13,
      "z": 0,
      "name": "Empty"
    },
    {
      "x": -6,
      "y": 5,
      "z": 1,
      "name": "Soil_Dirt"
    },
    {
      "x": -6,
      "y": 6,
      "z": 1,
      "name": "Soil_Dirt"
    },
    {
      "x": -6,
      "y": 7,
      "z": 1,
      "name": "Soil_Dirt"
    },
    {
      "x": -6,
      "y": 8,
      "z": 1,
      "name": "Soil_Dirt"
    },
    {
      "x": -6,
      "y": 9,
      "z": 1,
      "name": "Soil_Dirt"
    },
    {
      "x": -6,
      "y": 10,
      "z": 1,
      "name": "Soil_Grass_Deep"
    },
    {
      "x": -6,
      "y": 11,
      "z": 1,
      "name": "Plant_Grass_Sharp_Tall"
    },
    {
      "x": -6,
      "y": 12,
      "z": 1,
      "name": "Plant_Grass_Sharp_Tall",
      "filler": 1024
    },
    {
      "x": -6,
      "y": 13,
      "z": 1,
      "name": "Empty"
    },
    {
      "x": -6,
      "y": 7,
      "z": 2,
      "name": "Soil_Dirt"
    },
    {
      "x": -6,
      "y": 8,
      "z": 2,
      "name": "Soil_Dirt"
    },
    {
      "x": -6,
      "y": 9,
      "z": 2,
      "name": "Soil_Dirt"
    },
    {
      "x": -6,
      "y": 10,
      "z": 2,
      "name": "Soil_Grass_Deep"
    },
    {
      "x": -6,
      "y": 11,
      "z": 2,
      "name": "*Wood_Hardwood_Fence_State_Definitions_Corner"
    },
    {
      "x": -6,
      "y": 12,
      "z": 2,
      "name": "Empty"
    },
    {
      "x": -6,
      "y": 13,
      "z": 2,
      "name": "Empty"
    },
    {
      "x": -6,
      "y": 9,
      "z": 3,
      "name": "Soil_Dirt"
    },
    {
      "x": -6,
      "y": 10,
      "z": 3,
      "name": "Soil_Leaves"
    },
    {
      "x": -6,
      "y": 11,
      "z": 3,
      "name": "*Wood_Hardwood_Fence_State_Definitions_Corner",
      "rotation": 2
    },
    {
      "x": -6,
      "y": 12,
      "z": 3,
      "name": "Empty"
    },
    {
      "x": -6,
      "y": 13,
      "z": 3,
      "name": "Empty"
    },
    {
      "x": -5,
      "y": 8,
      "z": -5,
      "name": "Soil_Dirt"
    },
    {
      "x": -5,
      "y": 9,
      "z": -5,
      "name": "Soil_Dirt"
    },
    {
      "x": -5,
      "y": 10,
      "z": -5,
      "name": "Soil_Grass_Deep"
    },
    {
      "x": -5,
      "y": 11,
      "z": -5,
      "name": "Wood_Hardwood_Fence",
      "rotation": 2
    },
    {
      "x": -5,
      "y": 12,
      "z": -5,
      "name": "Empty"
    },
    {
      "x": -5,
      "y": 13,
      "z": -5,
      "name": "Empty"
    },
    {
      "x": -5,
      "y": 7,
      "z": -4,
      "name": "Soil_Dirt"
    },
    {
      "x": -5,
      "y": 8,
      "z": -4,
      "name": "Soil_Dirt"
    },
    {
      "x": -5,
      "y": 9,
      "z": -4,
      "name": "Soil_Dirt"
    },
    {
      "x": -5,
      "y": 10,
      "z": -4,
      "name": "Soil_Leaves"
    },
    {
      "x": -5,
      "y": 11,
      "z": -4,
      "name": "Coop_Chicken",
      "filler": 1023
    },
    {
      "x": -5,
      "y": 12,
      "z": -4,
      "name": "Coop_Chicken",
      "filler": 2047
    },
    {
      "x": -5,
      "y": 13,
      "z": -4,
      "name": "Coop_Chicken",
      "filler": 3071
    },
    {
      "x": -5,
      "y": 5,
      "z": -3,
      "name": "Soil_Dirt"
    },
    {
      "x": -5,
      "y": 6,
      "z": -3,
      "name": "Soil_Dirt"
    },
    {
      "x": -5,
      "y": 7,
      "z": -3,
      "name": "Soil_Dirt"
    },
    {
      "x": -5,
      "y": 8,
      "z": -3,
      "name": "Soil_Dirt"
    },
    {
      "x": -5,
      "y": 9,
      "z": -3,
      "name": "Soil_Dirt"
    },
    {
      "x": -5,
      "y": 10,
      "z": -3,
      "name": "Soil_Dirt"
    },
    {
      "x": -5,
      "y": 11,
      "z": -3,
      "name": "Coop_Chicken",
      "filler": 31
    },
    {
      "x": -5,
      "y": 12,
      "z": -3,
      "name": "Coop_Chicken",
      "filler": 1055
    },
    {
      "x": -5,
      "y": 13,
      "z": -3,
      "name": "Coop_Chicken",
      "filler": 2079
    },
    {
      "x": -5,
      "y": 5,
      "z": -2,
      "name": "Soil_Dirt"
    },
    {
      "x": -5,
      "y": 6,
      "z": -2,
      "name": "Soil_Dirt"
    },
    {
      "x": -5,
      "y": 7,
      "z": -2,
      "name": "Soil_Dirt"
    },
    {
      "x": -5,
      "y": 8,
      "z": -2,
      "name": "Soil_Dirt"
    },
    {
      "x": -5,
      "y": 9,
      "z": -2,
      "name": "Soil_Dirt"
    },
    {
      "x": -5,
      "y": 10,
      "z": -2,
      "name": "Soil_Dirt"
    },
    {
      "x": -5,
      "y": 11,
      "z": -2,
      "name": "Empty"
    },
    {
      "x": -5,
      "y": 12,
      "z": -2,
      "name": "Empty"
    },
    {
      "x": -5,
      "y": 13,
      "z": -2,
      "name": "Empty"
    },
    {
      "x": -5,
      "y": 5,
      "z": -1,
      "name": "Soil_Dirt"
    },
    {
      "x": -5,
      "y": 6,
      "z": -1,
      "name": "Soil_Dirt"
    },
    {
      "x": -5,
      "y": 7,
      "z": -1,
      "name": "Soil_Dirt"
    },
    {
      "x": -5,
      "y": 8,
      "z": -1,
      "name": "Soil_Dirt"
    },
    {
      "x": -5,
      "y": 9,
      "z": -1,
      "name": "Soil_Dirt"
    },
    {
      "x": -5,
      "y": 10,
      "z": -1,
      "name": "Soil_Mud_Dry"
    },
    {
      "x": -5,
      "y": 11,
      "z": -1,
      "name": "Empty"
    },
    {
      "x": -5,
      "y": 12,
      "z": -1,
      "name": "Empty"
    },
    {
      "x": -5,
      "y": 13,
      "z": -1,
      "name": "Empty"
    },
    {
      "x": -5,
      "y": 5,
      "z": 0,
      "name": "Soil_Dirt"
    },
    {
      "x": -5,
      "y": 6,
      "z": 0,
      "name": "Soil_Dirt"
    },
    {
      "x": -5,
      "y": 7,
      "z": 0,
      "name": "Soil_Dirt"
    },
    {
      "x": -5,
      "y": 8,
      "z": 0,
      "name": "Soil_Dirt"
    },
    {
      "x": -5,
      "y": 9,
      "z": 0,
      "name": "Soil_Dirt"
    },
    {
      "x": -5,
      "y": 10,
      "z": 0,
      "name": "Soil_Mud_Dry"
    },
    {
      "x": -5,
      "y": 11,
      "z": 0,
      "name": "Empty"
    },
    {
      "x": -5,
      "y": 12,
      "z": 0,
      "name": "Empty"
    },
    {
      "x": -5,
      "y": 13,
      "z": 0,
      "name": "Empty"
    },
    {
      "x": -5,
      "y": 5,
      "z": 1,
      "name": "Soil_Dirt"
    },
    {
      "x": -5,
      "y": 6,
      "z": 1,
      "name": "Soil_Dirt"
    },
    {
      "x": -5,
      "y": 7,
      "z": 1,
      "name": "Soil_Dirt"
    },
    {
      "x": -5,
      "y": 8,
      "z": 1,
      "name": "Soil_Dirt"
    },
    {
      "x": -5,
      "y": 9,
      "z": 1,
      "name": "Soil_Dirt"
    },
    {
      "x": -5,
      "y": 10,
      "z": 1,
      "name": "Soil_Grass_Deep"
    },
    {
      "x": -5,
      "y": 11,
      "z": 1,
      "name": "Plant_Grass_Sharp_Tall"
    },
    {
      "x": -5,
      "y": 12,
      "z": 1,
      "name": "Plant_Grass_Sharp_Tall",
      "filler": 1024
    },
    {
      "x": -5,
      "y": 13,
      "z": 1,
      "name": "Empty"
    },
    {
      "x": -5,
      "y": 6,
      "z": 2,
      "name": "Soil_Dirt"
    },
    {
      "x": -5,
      "y": 7,
      "z": 2,
      "name": "Soil_Dirt"
    },
    {
      "x": -5,
      "y": 8,
      "z": 2,
      "name": "Soil_Dirt"
    },
    {
      "x": -5,
      "y": 9,
      "z": 2,
      "name": "Soil_Dirt"
    },
    {
      "x": -5,
      "y": 10,
      "z": 2,
      "name": "Soil_Leaves"
    },
    {
      "x": -5,
      "y": 11,
      "z": 2,
      "name": "Plant_Grass_Lush"
    },
    {
      "x": -5,
      "y": 12,
      "z": 2,
      "name": "Empty"
    },
    {
      "x": -5,
      "y": 13,
      "z": 2,
      "name": "Empty"
    },
    {
      "x": -5,
      "y": 7,
      "z": 3,
      "name": "Soil_Dirt"
    },
    {
      "x": -5,
      "y": 8,
      "z": 3,
      "name": "Soil_Dirt"
    },
    {
      "x": -5,
      "y": 9,
      "z": 3,
      "name": "Soil_Dirt"
    },
    {
      "x": -5,
      "y": 10,
      "z": 3,
      "name": "Soil_Leaves"
    },
    {
      "x": -5,
      "y": 11,
      "z": 3,
      "name": "Wood_Hardwood_Fence"
    },
    {
      "x": -5,
      "y": 12,
      "z": 3,
      "name": "Empty"
    },
    {
      "x": -5,
      "y": 13,
      "z": 3,
      "name": "Empty"
    },
    {
      "x": -4,
      "y": 7,
      "z": -5,
      "name": "Soil_Dirt"
    },
    {
      "x": -4,
      "y": 8,
      "z": -5,
      "name": "Soil_Dirt"
    },
    {
      "x": -4,
      "y": 9,
      "z": -5,
      "name": "Soil_Dirt"
    },
    {
      "x": -4,
      "y": 10,
      "z": -5,
      "name": "Soil_Dirt"
    },
    {
      "x": -4,
      "y": 11,
      "z": -5,
      "name": "Wood_Hardwood_Fence",
      "rotation": 2
    },
    {
      "x": -4,
      "y": 12,
      "z": -5,
      "name": "Empty"
    },
    {
      "x": -4,
      "y": 13,
      "z": -5,
      "name": "Empty"
    },
    {
      "x": -4,
      "y": 6,
      "z": -4,
      "name": "Soil_Dirt"
    },
    {
      "x": -4,
      "y": 7,
      "z": -4,
      "name": "Soil_Dirt"
    },
    {
      "x": -4,
      "y": 8,
      "z": -4,
      "name": "Soil_Dirt"
    },
    {
      "x": -4,
      "y": 9,
      "z": -4,
      "name": "Soil_Dirt"
    },
    {
      "x": -4,
      "y": 10,
      "z": -4,
      "name": "Soil_Dirt"
    },
    {
      "x": -4,
      "y": 11,
      "z": -4,
      "name": "Coop_Chicken",
      "filler": 992
    },
    {
      "x": -4,
      "y": 12,
      "z": -4,
      "name": "Coop_Chicken",
      "filler": 2016
    },
    {
      "x": -4,
      "y": 13,
      "z": -4,
      "name": "Coop_Chicken",
      "filler": 3040
    },
    {
      "x": -4,
      "y": 5,
      "z": -3,
      "name": "Soil_Dirt"
    },
    {
      "x": -4,
      "y": 6,
      "z": -3,
      "name": "Soil_Dirt"
    },
    {
      "x": -4,
      "y": 7,
      "z": -3,
      "name": "Soil_Dirt"
    },
    {
      "x": -4,
      "y": 8,
      "z": -3,
      "name": "Soil_Dirt"
    },
    {
      "x": -4,
      "y": 9,
      "z": -3,
      "name": "Soil_Dirt"
    },
    {
      "x": -4,
      "y": 10,
      "z": -3,
      "name": "Soil_Mud_Dry"
    },
    {
      "x": -4,
      "y": 11,
      "z": -3,
      "name": "Coop_Chicken"
    },
    {
      "x": -4,
      "y": 12,
      "z": -3,
      "name": "Coop_Chicken",
      "filler": 1024
    },
    {
      "x": -4,
      "y": 13,
      "z": -3,
      "name": "Coop_Chicken",
      "filler": 2048
    },
    {
      "x": -4,
      "y": 5,
      "z": -2,
      "name": "Soil_Dirt"
    },
    {
      "x": -4,
      "y": 6,
      "z": -2,
      "name": "Soil_Dirt"
    },
    {
      "x": -4,
      "y": 7,
      "z": -2,
      "name": "Soil_Dirt"
    },
    {
      "x": -4,
      "y": 8,
      "z": -2,
      "name": "Soil_Dirt"
    },
    {
      "x": -4,
      "y": 9,
      "z": -2,
      "name": "Soil_Dirt"
    },
    {
      "x": -4,
      "y": 10,
      "z": -2,
      "name": "Soil_Mud_Dry"
    },
    {
      "x": -4,
      "y": 11,
      "z": -2,
      "name": "Empty"
    },
    {
      "x": -4,
      "y": 12,
      "z": -2,
      "name": "Empty"
    },
    {
      "x": -4,
      "y": 13,
      "z": -2,
      "name": "Empty"
    },
    {
      "x": -4,
      "y": 5,
      "z": -1,
      "name": "Soil_Dirt"
    },
    {
      "x": -4,
      "y": 6,
      "z": -1,
      "name": "Soil_Dirt"
    },
    {
      "x": -4,
      "y": 7,
      "z": -1,
      "name": "Soil_Dirt"
    },
    {
      "x": -4,
      "y": 8,
      "z": -1,
      "name": "Soil_Dirt"
    },
    {
      "x": -4,
      "y": 9,
      "z": -1,
      "name": "Soil_Dirt"
    },
    {
      "x": -4,
      "y": 10,
      "z": -1,
      "name": "Soil_Mud_Dry"
    },
    {
      "x": -4,
      "y": 11,
      "z": -1,
      "name": "Empty"
    },
    {
      "x": -4,
      "y": 12,
      "z": -1,
      "name": "Empty"
    },
    {
      "x": -4,
      "y": 13,
      "z": -1,
      "name": "Empty"
    },
    {
      "x": -4,
      "y": 5,
      "z": 0,
      "name": "Soil_Dirt"
    },
    {
      "x": -4,
      "y": 6,
      "z": 0,
      "name": "Soil_Dirt"
    },
    {
      "x": -4,
      "y": 7,
      "z": 0,
      "name": "Soil_Dirt"
    },
    {
      "x": -4,
      "y": 8,
      "z": 0,
      "name": "Soil_Dirt"
    },
    {
      "x": -4,
      "y": 9,
      "z": 0,
      "name": "Soil_Dirt"
    },
    {
      "x": -4,
      "y": 10,
      "z": 0,
      "name": "Soil_Mud_Dry"
    },
    {
      "x": -4,
      "y": 11,
      "z": 0,
      "name": "Empty"
    },
    {
      "x": -4,
      "y": 12,
      "z": 0,
      "name": "Empty"
    },
    {
      "x": -4,
      "y": 13,
      "z": 0,
      "name": "Empty"
    },
    {
      "x": -4,
      "y": 5,
      "z": 1,
      "name": "Soil_Dirt"
    },
    {
      "x": -4,
      "y": 6,
      "z": 1,
      "name": "Soil_Dirt"
    },
    {
      "x": -4,
      "y": 7,
      "z": 1,
      "name": "Soil_Dirt"
    },
    {
      "x": -4,
      "y": 8,
      "z": 1,
      "name": "Soil_Dirt"
    },
    {
      "x": -4,
      "y": 9,
      "z": 1,
      "name": "Soil_Dirt"
    },
    {
      "x": -4,
      "y": 10,
      "z": 1,
      "name": "Soil_Dirt"
    },
    {
      "x": -4,
      "y": 11,
      "z": 1,
      "name": "Empty"
    },
    {
      "x": -4,
      "y": 12,
      "z": 1,
      "name": "Empty"
    },
    {
      "x": -4,
      "y": 13,
      "z": 1,
      "name": "Empty"
    },
    {
      "x": -4,
      "y": 5,
      "z": 2,
      "name": "Soil_Dirt"
    },
    {
      "x": -4,
      "y": 6,
      "z": 2,
      "name": "Soil_Dirt"
    },
    {
      "x": -4,
      "y": 7,
      "z": 2,
      "name": "Soil_Dirt"
    },
    {
      "x": -4,
      "y": 8,
      "z": 2,
      "name": "Soil_Dirt"
    },
    {
      "x": -4,
      "y": 9,
      "z": 2,
      "name": "Soil_Dirt"
    },
    {
      "x": -4,
      "y": 10,
      "z": 2,
      "name": "Soil_Grass_Deep"
    },
    {
      "x": -4,
      "y": 11,
      "z": 2,
      "name": "Empty"
    },
    {
      "x": -4,
      "y": 12,
      "z": 2,
      "name": "Empty"
    },
    {
      "x": -4,
      "y": 13,
      "z": 2,
      "name": "Empty"
    },
    {
      "x": -4,
      "y": 6,
      "z": 3,
      "name": "Soil_Dirt"
    },
    {
      "x": -4,
      "y": 7,
      "z": 3,
      "name": "Soil_Dirt"
    },
    {
      "x": -4,
      "y": 8,
      "z": 3,
      "name": "Soil_Dirt"
    },
    {
      "x": -4,
      "y": 9,
      "z": 3,
      "name": "Soil_Dirt"
    },
    {
      "x": -4,
      "y": 10,
      "z": 3,
      "name": "Soil_Grass_Deep"
    },
    {
      "x": -4,
      "y": 11,
      "z": 3,
      "name": "Wood_Hardwood_Fence"
    },
    {
      "x": -4,
      "y": 12,
      "z": 3,
      "name": "Empty"
    },
    {
      "x": -4,
      "y": 13,
      "z": 3,
      "name": "Empty"
    },
    {
      "x": -3,
      "y": 6,
      "z": -5,
      "name": "Soil_Dirt"
    },
    {
      "x": -3,
      "y": 7,
      "z": -5,
      "name": "Soil_Dirt"
    },
    {
      "x": -3,
      "y": 8,
      "z": -5,
      "name": "Soil_Dirt"
    },
    {
      "x": -3,
      "y": 9,
      "z": -5,
      "name": "Soil_Dirt"
    },
    {
      "x": -3,
      "y": 10,
      "z": -5,
      "name": "Soil_Dirt"
    },
    {
      "x": -3,
      "y": 11,
      "z": -5,
      "name": "Wood_Hardwood_Fence",
      "rotation": 2
    },
    {
      "x": -3,
      "y": 12,
      "z": -5,
      "name": "Empty"
    },
    {
      "x": -3,
      "y": 13,
      "z": -5,
      "name": "Empty"
    },
    {
      "x": -3,
      "y": 5,
      "z": -4,
      "name": "Soil_Dirt"
    },
    {
      "x": -3,
      "y": 6,
      "z": -4,
      "name": "Soil_Dirt"
    },
    {
      "x": -3,
      "y": 7,
      "z": -4,
      "name": "Soil_Dirt"
    },
    {
      "x": -3,
      "y": 8,
      "z": -4,
      "name": "Soil_Dirt"
    },
    {
      "x": -3,
      "y": 9,
      "z": -4,
      "name": "Soil_Dirt"
    },
    {
      "x": -3,
      "y": 10,
      "z": -4,
      "name": "Soil_Dirt_Tilled"
    },
    {
      "x": -3,
      "y": 11,
      "z": -4,
      "name": "Coop_Chicken",
      "filler": 993
    },
    {
      "x": -3,
      "y": 12,
      "z": -4,
      "name": "Coop_Chicken",
      "filler": 2017
    },
    {
      "x": -3,
      "y": 13,
      "z": -4,
      "name": "Coop_Chicken",
      "filler": 3041
    },
    {
      "x": -3,
      "y": 5,
      "z": -3,
      "name": "Soil_Dirt"
    },
    {
      "x": -3,
      "y": 6,
      "z": -3,
      "name": "Soil_Dirt"
    },
    {
      "x": -3,
      "y": 7,
      "z": -3,
      "name": "Soil_Dirt"
    },
    {
      "x": -3,
      "y": 8,
      "z": -3,
      "name": "Soil_Dirt"
    },
    {
      "x": -3,
      "y": 9,
      "z": -3,
      "name": "Soil_Dirt"
    },
    {
      "x": -3,
      "y": 10,
      "z": -3,
      "name": "Soil_Mud_Dry"
    },
    {
      "x": -3,
      "y": 11,
      "z": -3,
      "name": "Coop_Chicken",
      "filler": 1
    },
    {
      "x": -3,
      "y": 12,
      "z": -3,
      "name": "Coop_Chicken",
      "filler": 1025
    },
    {
      "x": -3,
      "y": 13,
      "z": -3,
      "name": "Coop_Chicken",
      "filler": 2049
    },
    {
      "x": -3,
      "y": 5,
      "z": -2,
      "name": "Soil_Dirt"
    },
    {
      "x": -3,
      "y": 6,
      "z": -2,
      "name": "Soil_Dirt"
    },
    {
      "x": -3,
      "y": 7,
      "z": -2,
      "name": "Soil_Dirt"
    },
    {
      "x": -3,
      "y": 8,
      "z": -2,
      "name": "Soil_Dirt"
    },
    {
      "x": -3,
      "y": 9,
      "z": -2,
      "name": "Soil_Dirt"
    },
    {
      "x": -3,
      "y": 10,
      "z": -2,
      "name": "Soil_Mud_Dry"
    },
    {
      "x": -3,
      "y": 11,
      "z": -2,
      "name": "Empty"
    },
    {
      "x": -3,
      "y": 12,
      "z": -2,
      "name": "Empty"
    },
    {
      "x": -3,
      "y": 13,
      "z": -2,
      "name": "Empty"
    },
    {
      "x": -3,
      "y": 5,
      "z": -1,
      "name": "Soil_Dirt"
    },
    {
      "x": -3,
      "y": 6,
      "z": -1,
      "name": "Soil_Dirt"
    },
    {
      "x": -3,
      "y": 7,
      "z": -1,
      "name": "Soil_Dirt"
    },
    {
      "x": -3,
      "y": 8,
      "z": -1,
      "name": "Soil_Dirt"
    },
    {
      "x": -3,
      "y": 9,
      "z": -1,
      "name": "Soil_Dirt"
    },
    {
      "x": -3,
      "y": 10,
      "z": -1,
      "name": "Soil_Mud_Dry"
    },
    {
      "x": -3,
      "y": 11,
      "z": -1,
      "name": "Empty"
    },
    {
      "x": -3,
      "y": 12,
      "z": -1,
      "name": "Empty"
    },
    {
      "x": -3,
      "y": 13,
      "z": -1,
      "name": "Empty"
    },
    {
      "x": -3,
      "y": 5,
      "z": 0,
      "name": "Soil_Dirt"
    },
    {
      "x": -3,
      "y": 6,
      "z": 0,
      "name": "Soil_Dirt"
    },
    {
      "x": -3,
      "y": 7,
      "z": 0,
      "name": "Soil_Dirt"
    },
    {
      "x": -3,
      "y": 8,
      "z": 0,
      "name": "Soil_Dirt"
    },
    {
      "x": -3,
      "y": 9,
      "z": 0,
      "name": "Soil_Dirt"
    },
    {
      "x": -3,
      "y": 10,
      "z": 0,
      "name": "Soil_Mud_Dry"
    },
    {
      "x": -3,
      "y": 11,
      "z": 0,
      "name": "Empty"
    },
    {
      "x": -3,
      "y": 12,
      "z": 0,
      "name": "Empty"
    },
    {
      "x": -3,
      "y": 13,
      "z": 0,
      "name": "Empty"
    },
    {
      "x": -3,
      "y": 5,
      "z": 1,
      "name": "Soil_Dirt"
    },
    {
      "x": -3,
      "y": 6,
      "z": 1,
      "name": "Soil_Dirt"
    },
    {
      "x": -3,
      "y": 7,
      "z": 1,
      "name": "Soil_Dirt"
    },
    {
      "x": -3,
      "y": 8,
      "z": 1,
      "name": "Soil_Dirt"
    },
    {
      "x": -3,
      "y": 9,
      "z": 1,
      "name": "Soil_Dirt"
    },
    {
      "x": -3,
      "y": 10,
      "z": 1,
      "name": "Soil_Dirt"
    },
    {
      "x": -3,
      "y": 11,
      "z": 1,
      "name": "Empty"
    },
    {
      "x": -3,
      "y": 12,
      "z": 1,
      "name": "Empty"
    },
    {
      "x": -3,
      "y": 13,
      "z": 1,
      "name": "Empty"
    },
    {
      "x": -3,
      "y": 5,
      "z": 2,
      "name": "Soil_Dirt"
    },
    {
      "x": -3,
      "y": 6,
      "z": 2,
      "name": "Soil_Dirt"
    },
    {
      "x": -3,
      "y": 7,
      "z": 2,
      "name": "Soil_Dirt"
    },
    {
      "x": -3,
      "y": 8,
      "z": 2,
      "name": "Soil_Dirt"
    },
    {
      "x": -3,
      "y": 9,
      "z": 2,
      "name": "Soil_Dirt"
    },
    {
      "x": -3,
      "y": 10,
      "z": 2,
      "name": "Soil_Dirt"
    },
    {
      "x": -3,
      "y": 11,
      "z": 2,
      "name": "Empty"
    },
    {
      "x": -3,
      "y": 12,
      "z": 2,
      "name": "Empty"
    },
    {
      "x": -3,
      "y": 13,
      "z": 2,
      "name": "Empty"
    },
    {
      "x": -3,
      "y": 6,
      "z": 3,
      "name": "Soil_Dirt"
    },
    {
      "x": -3,
      "y": 7,
      "z": 3,
      "name": "Soil_Dirt"
    },
    {
      "x": -3,
      "y": 8,
      "z": 3,
      "name": "Soil_Dirt"
    },
    {
      "x": -3,
      "y": 9,
      "z": 3,
      "name": "Soil_Dirt"
    },
    {
      "x": -3,
      "y": 10,
      "z": 3,
      "name": "Soil_Dirt"
    },
    {
      "x": -3,
      "y": 11,
      "z": 3,
      "name": "Wood_Hardwood_Fence"
    },
    {
      "x": -3,
      "y": 12,
      "z": 3,
      "name": "Empty"
    },
    {
      "x": -3,
      "y": 13,
      "z": 3,
      "name": "Empty"
    },
    {
      "x": -2,
      "y": 8,
      "z": -6,
      "name": "Soil_Dirt"
    },
    {
      "x": -2,
      "y": 9,
      "z": -6,
      "name": "Soil_Dirt"
    },
    {
      "x": -2,
      "y": 10,
      "z": -6,
      "name": "Soil_Dirt_Tilled"
    },
    {
      "x": -2,
      "y": 6,
      "z": -5,
      "name": "Soil_Dirt"
    },
    {
      "x": -2,
      "y": 7,
      "z": -5,
      "name": "Soil_Dirt"
    },
    {
      "x": -2,
      "y": 8,
      "z": -5,
      "name": "Soil_Dirt"
    },
    {
      "x": -2,
      "y": 9,
      "z": -5,
      "name": "Soil_Dirt"
    },
    {
      "x": -2,
      "y": 10,
      "z": -5,
      "name": "Soil_Dirt_Tilled"
    },
    {
      "x": -2,
      "y": 11,
      "z": -5,
      "name": "Wood_Hardwood_Fence",
      "rotation": 2
    },
    {
      "x": -2,
      "y": 12,
      "z": -5,
      "name": "Empty"
    },
    {
      "x": -2,
      "y": 13,
      "z": -5,
      "name": "Empty"
    },
    {
      "x": -2,
      "y": 5,
      "z": -4,
      "name": "Soil_Dirt"
    },
    {
      "x": -2,
      "y": 6,
      "z": -4,
      "name": "Soil_Dirt"
    },
    {
      "x": -2,
      "y": 7,
      "z": -4,
      "name": "Soil_Dirt"
    },
    {
      "x": -2,
      "y": 8,
      "z": -4,
      "name": "Soil_Dirt"
    },
    {
      "x": -2,
      "y": 9,
      "z": -4,
      "name": "Soil_Dirt"
    },
    {
      "x": -2,
      "y": 10,
      "z": -4,
      "name": "Soil_Dirt_Tilled"
    },
    {
      "x": -2,
      "y": 11,
      "z": -4,
      "name": "Empty"
    },
    {
      "x": -2,
      "y": 12,
      "z": -4,
      "name": "Empty"
    },
    {
      "x": -2,
      "y": 13,
      "z": -4,
      "name": "Empty"
    },
    {
      "x": -2,
      "y": 5,
      "z": -3,
      "name": "Soil_Dirt"
    },
    {
      "x": -2,
      "y": 6,
      "z": -3,
      "name": "Soil_Dirt"
    },
    {
      "x": -2,
      "y": 7,
      "z": -3,
      "name": "Soil_Dirt"
    },
    {
      "x": -2,
      "y": 8,
      "z": -3,
      "name": "Soil_Dirt"
    },
    {
      "x": -2,
      "y": 9,
      "z": -3,
      "name": "Soil_Dirt"
    },
    {
      "x": -2,
      "y": 10,
      "z": -3,
      "name": "Soil_Mud_Dry"
    },
    {
      "x": -2,
      "y": 11,
      "z": -3,
      "name": "Empty"
    },
    {
      "x": -2,
      "y": 12,
      "z": -3,
      "name": "Empty"
    },
    {
      "x": -2,
      "y": 13,
      "z": -3,
      "name": "Empty"
    },
    {
      "x": -2,
      "y": 5,
      "z": -2,
      "name": "Soil_Dirt"
    },
    {
      "x": -2,
      "y": 6,
      "z": -2,
      "name": "Soil_Dirt"
    },
    {
      "x": -2,
      "y": 7,
      "z": -2,
      "name": "Soil_Dirt"
    },
    {
      "x": -2,
      "y": 8,
      "z": -2,
      "name": "Soil_Dirt"
    },
    {
      "x": -2,
      "y": 9,
      "z": -2,
      "name": "Soil_Dirt"
    },
    {
      "x": -2,
      "y": 10,
      "z": -2,
      "name": "Soil_Mud_Dry"
    },
    {
      "x": -2,
      "y": 11,
      "z": -2,
      "name": "Empty"
    },
    {
      "x": -2,
      "y": 12,
      "z": -2,
      "name": "Empty"
    },
    {
      "x": -2,
      "y": 13,
      "z": -2,
      "name": "Empty"
    },
    {
      "x": -2,
      "y": 5,
      "z": -1,
      "name": "Soil_Dirt"
    },
    {
      "x": -2,
      "y": 6,
      "z": -1,
      "name": "Soil_Dirt"
    },
    {
      "x": -2,
      "y": 7,
      "z": -1,
      "name": "Soil_Dirt"
    },
    {
      "x": -2,
      "y": 8,
      "z": -1,
      "name": "Soil_Dirt"
    },
    {
      "x": -2,
      "y": 9,
      "z": -1,
      "name": "Soil_Dirt"
    },
    {
      "x": -2,
      "y": 10,
      "z": -1,
      "name": "Soil_Mud_Dry"
    },
    {
      "x": -2,
      "y": 11,
      "z": -1,
      "name": "Empty"
    },
    {
      "x": -2,
      "y": 12,
      "z": -1,
      "name": "Empty"
    },
    {
      "x": -2,
      "y": 13,
      "z": -1,
      "name": "Empty"
    },
    {
      "x": -2,
      "y": 5,
      "z": 0,
      "name": "Soil_Dirt"
    },
    {
      "x": -2,
      "y": 6,
      "z": 0,
      "name": "Soil_Dirt"
    },
    {
      "x": -2,
      "y": 7,
      "z": 0,
      "name": "Soil_Dirt"
    },
    {
      "x": -2,
      "y": 8,
      "z": 0,
      "name": "Soil_Dirt"
    },
    {
      "x": -2,
      "y": 9,
      "z": 0,
      "name": "Soil_Dirt"
    },
    {
      "x": -2,
      "y": 10,
      "z": 0,
      "name": "Soil_Mud_Dry"
    },
    {
      "x": -2,
      "y": 11,
      "z": 0,
      "name": "Empty"
    },
    {
      "x": -2,
      "y": 12,
      "z": 0,
      "name": "Empty"
    },
    {
      "x": -2,
      "y": 13,
      "z": 0,
      "name": "Empty"
    },
    {
      "x": -2,
      "y": 5,
      "z": 1,
      "name": "Soil_Dirt"
    },
    {
      "x": -2,
      "y": 6,
      "z": 1,
      "name": "Soil_Dirt"
    },
    {
      "x": -2,
      "y": 7,
      "z": 1,
      "name": "Soil_Dirt"
    },
    {
      "x": -2,
      "y": 8,
      "z": 1,
      "name": "Soil_Dirt"
    },
    {
      "x": -2,
      "y": 9,
      "z": 1,
      "name": "Soil_Dirt"
    },
    {
      "x": -2,
      "y": 10,
      "z": 1,
      "name": "Soil_Mud_Dry"
    },
    {
      "x": -2,
      "y": 11,
      "z": 1,
      "name": "Empty"
    },
    {
      "x": -2,
      "y": 12,
      "z": 1,
      "name": "Empty"
    },
    {
      "x": -2,
      "y": 13,
      "z": 1,
      "name": "Empty"
    },
    {
      "x": -2,
      "y": 5,
      "z": 2,
      "name": "Soil_Dirt"
    },
    {
      "x": -2,
      "y": 6,
      "z": 2,
      "name": "Soil_Dirt"
    },
    {
      "x": -2,
      "y": 7,
      "z": 2,
      "name": "Soil_Dirt"
    },
    {
      "x": -2,
      "y": 8,
      "z": 2,
      "name": "Soil_Dirt"
    },
    {
      "x": -2,
      "y": 9,
      "z": 2,
      "name": "Soil_Dirt"
    },
    {
      "x": -2,
      "y": 10,
      "z": 2,
      "name": "Soil_Dirt"
    },
    {
      "x": -2,
      "y": 11,
      "z": 2,
      "name": "Empty"
    },
    {
      "x": -2,
      "y": 12,
      "z": 2,
      "name": "Empty"
    },
    {
      "x": -2,
      "y": 13,
      "z": 2,
      "name": "Empty"
    },
    {
      "x": -2,
      "y": 5,
      "z": 3,
      "name": "Soil_Dirt"
    },
    {
      "x": -2,
      "y": 6,
      "z": 3,
      "name": "Soil_Dirt"
    },
    {
      "x": -2,
      "y": 7,
      "z": 3,
      "name": "Soil_Dirt"
    },
    {
      "x": -2,
      "y": 8,
      "z": 3,
      "name": "Soil_Dirt"
    },
    {
      "x": -2,
      "y": 9,
      "z": 3,
      "name": "Soil_Dirt"
    },
    {
      "x": -2,
      "y": 10,
      "z": 3,
      "name": "Soil_Dirt_Tilled"
    },
    {
      "x": -2,
      "y": 11,
      "z": 3,
      "name": "*Wood_Hardwood_Fence_State_Definitions_Corner"
    },
    {
      "x": -2,
      "y": 12,
      "z": 3,
      "name": "Empty"
    },
    {
      "x": -2,
      "y": 13,
      "z": 3,
      "name": "Empty"
    },
    {
      "x": -2,
      "y": 5,
      "z": 4,
      "name": "Soil_Dirt"
    },
    {
      "x": -2,
      "y": 6,
      "z": 4,
      "name": "Soil_Dirt"
    },
    {
      "x": -2,
      "y": 7,
      "z": 4,
      "name": "Soil_Dirt"
    },
    {
      "x": -2,
      "y": 8,
      "z": 4,
      "name": "Soil_Dirt"
    },
    {
      "x": -2,
      "y": 9,
      "z": 4,
      "name": "Soil_Dirt"
    },
    {
      "x": -2,
      "y": 10,
      "z": 4,
      "name": "Soil_Dirt_Tilled"
    },
    {
      "x": -2,
      "y": 11,
      "z": 4,
      "name": "Wood_Hardwood_Fence",
      "rotation": 3
    },
    {
      "x": -2,
      "y": 12,
      "z": 4,
      "name": "Empty"
    },
    {
      "x": -2,
      "y": 13,
      "z": 4,
      "name": "Empty"
    },
    {
      "x": -2,
      "y": 6,
      "z": 5,
      "name": "Soil_Dirt"
    },
    {
      "x": -2,
      "y": 7,
      "z": 5,
      "name": "Soil_Dirt"
    },
    {
      "x": -2,
      "y": 8,
      "z": 5,
      "name": "Soil_Dirt"
    },
    {
      "x": -2,
      "y": 9,
      "z": 5,
      "name": "Soil_Dirt"
    },
    {
      "x": -2,
      "y": 10,
      "z": 5,
      "name": "Soil_Dirt_Tilled"
    },
    {
      "x": -2,
      "y": 11,
      "z": 5,
      "name": "Wood_Hardwood_Fence",
      "rotation": 3
    },
    {
      "x": -2,
      "y": 12,
      "z": 5,
      "name": "Empty"
    },
    {
      "x": -2,
      "y": 13,
      "z": 5,
      "name": "Empty"
    },
    {
      "x": -2,
      "y": 7,
      "z": 6,
      "name": "Soil_Dirt"
    },
    {
      "x": -2,
      "y": 8,
      "z": 6,
      "name": "Soil_Dirt"
    },
    {
      "x": -2,
      "y": 9,
      "z": 6,
      "name": "Soil_Dirt"
    },
    {
      "x": -2,
      "y": 10,
      "z": 6,
      "name": "Soil_Dirt_Tilled"
    },
    {
      "x": -2,
      "y": 11,
      "z": 6,
      "name": "Wood_Hardwood_Fence",
      "rotation": 3
    },
    {
      "x": -2,
      "y": 12,
      "z": 6,
      "name": "Empty"
    },
    {
      "x": -2,
      "y": 13,
      "z": 6,
      "name": "Empty"
    },
    {
      "x": -2,
      "y": 8,
      "z": 7,
      "name": "Soil_Dirt"
    },
    {
      "x": -2,
      "y": 9,
      "z": 7,
      "name": "Soil_Dirt"
    },
    {
      "x": -2,
      "y": 10,
      "z": 7,
      "name": "Soil_Dirt"
    },
    {
      "x": -2,
      "y": 11,
      "z": 7,
      "name": "*Wood_Hardwood_Fence_State_Definitions_Corner",
      "rotation": 2
    },
    {
      "x": -2,
      "y": 12,
      "z": 7,
      "name": "Empty"
    },
    {
      "x": -2,
      "y": 13,
      "z": 7,
      "name": "Empty"
    },
    {
      "x": -1,
      "y": 7,
      "z": -6,
      "name": "Soil_Dirt"
    },
    {
      "x": -1,
      "y": 8,
      "z": -6,
      "name": "Soil_Dirt"
    },
    {
      "x": -1,
      "y": 9,
      "z": -6,
      "name": "Soil_Dirt"
    },
    {
      "x": -1,
      "y": 10,
      "z": -6,
      "name": "Soil_Dirt_Tilled"
    },
    {
      "x": -1,
      "y": 7,
      "z": -5,
      "name": "Soil_Dirt"
    },
    {
      "x": -1,
      "y": 8,
      "z": -5,
      "name": "Soil_Dirt"
    },
    {
      "x": -1,
      "y": 9,
      "z": -5,
      "name": "Soil_Dirt"
    },
    {
      "x": -1,
      "y": 10,
      "z": -5,
      "name": "Soil_Dirt_Tilled"
    },
    {
      "x": -1,
      "y": 11,
      "z": -5,
      "name": "Wood_Hardwood_Fence",
      "rotation": 2
    },
    {
      "x": -1,
      "y": 12,
      "z": -5,
      "name": "Empty"
    },
    {
      "x": -1,
      "y": 13,
      "z": -5,
      "name": "Empty"
    },
    {
      "x": -1,
      "y": 6,
      "z": -4,
      "name": "Soil_Dirt"
    },
    {
      "x": -1,
      "y": 7,
      "z": -4,
      "name": "Soil_Dirt"
    },
    {
      "x": -1,
      "y": 8,
      "z": -4,
      "name": "Soil_Dirt"
    },
    {
      "x": -1,
      "y": 9,
      "z": -4,
      "name": "Soil_Dirt"
    },
    {
      "x": -1,
      "y": 10,
      "z": -4,
      "name": "Soil_Dirt_Tilled"
    },
    {
      "x": -1,
      "y": 11,
      "z": -4,
      "name": "*Plant_Crop_Carrot_Block_State_Definitions_Stage1",
      "components": {
        "Components": {
          "FarmingBlock": {}
        }
      }
    },
    {
      "x": -1,
      "y": 12,
      "z": -4,
      "name": "Empty"
    },
    {
      "x": -1,
      "y": 13,
      "z": -4,
      "name": "Empty"
    },
    {
      "x": -1,
      "y": 5,
      "z": -3,
      "name": "Soil_Dirt"
    },
    {
      "x": -1,
      "y": 6,
      "z": -3,
      "name": "Soil_Dirt"
    },
    {
      "x": -1,
      "y": 7,
      "z": -3,
      "name": "Soil_Dirt"
    },
    {
      "x": -1,
      "y": 8,
      "z": -3,
      "name": "Soil_Dirt"
    },
    {
      "x": -1,
      "y": 9,
      "z": -3,
      "name": "Soil_Dirt"
    },
    {
      "x": -1,
      "y": 10,
      "z": -3,
      "name": "Soil_Dirt_Tilled"
    },
    {
      "x": -1,
      "y": 11,
      "z": -3,
      "name": "Empty"
    },
    {
      "x": -1,
      "y": 12,
      "z": -3,
      "name": "Empty"
    },
    {
      "x": -1,
      "y": 13,
      "z": -3,
      "name": "Empty"
    },
    {
      "x": -1,
      "y": 5,
      "z": -2,
      "name": "Soil_Dirt"
    },
    {
      "x": -1,
      "y": 6,
      "z": -2,
      "name": "Soil_Dirt"
    },
    {
      "x": -1,
      "y": 7,
      "z": -2,
      "name": "Soil_Dirt"
    },
    {
      "x": -1,
      "y": 8,
      "z": -2,
      "name": "Soil_Dirt"
    },
    {
      "x": -1,
      "y": 9,
      "z": -2,
      "name": "Soil_Dirt"
    },
    {
      "x": -1,
      "y": 10,
      "z": -2,
      "name": "Soil_Dirt_Tilled"
    },
    {
      "x": -1,
      "y": 11,
      "z": -2,
      "name": "*Plant_Crop_Carrot_Block_State_Definitions_Stage1",
      "components": {
        "Components": {
          "FarmingBlock": {}
        }
      }
    },
    {
      "x": -1,
      "y": 12,
      "z": -2,
      "name": "Empty"
    },
    {
      "x": -1,
      "y": 13,
      "z": -2,
      "name": "Empty"
    },
    {
      "x": -1,
      "y": 5,
      "z": -1,
      "name": "Soil_Dirt"
    },
    {
      "x": -1,
      "y": 6,
      "z": -1,
      "name": "Soil_Dirt"
    },
    {
      "x": -1,
      "y": 7,
      "z": -1,
      "name": "Soil_Dirt"
    },
    {
      "x": -1,
      "y": 8,
      "z": -1,
      "name": "Soil_Dirt"
    },
    {
      "x": -1,
      "y": 9,
      "z": -1,
      "name": "Soil_Dirt"
    },
    {
      "x": -1,
      "y": 10,
      "z": -1,
      "name": "Soil_Mud_Dry"
    },
    {
      "x": -1,
      "y": 11,
      "z": -1,
      "name": "Empty"
    },
    {
      "x": -1,
      "y": 12,
      "z": -1,
      "name": "Empty"
    },
    {
      "x": -1,
      "y": 13,
      "z": -1,
      "name": "Empty"
    },
    {
      "x": -1,
      "y": 5,
      "z": 0,
      "name": "Soil_Dirt"
    },
    {
      "x": -1,
      "y": 6,
      "z": 0,
      "name": "Soil_Dirt"
    },
    {
      "x": -1,
      "y": 7,
      "z": 0,
      "name": "Soil_Dirt"
    },
    {
      "x": -1,
      "y": 8,
      "z": 0,
      "name": "Soil_Dirt"
    },
    {
      "x": -1,
      "y": 9,
      "z": 0,
      "name": "Soil_Dirt"
    },
    {
      "x": -1,
      "y": 10,
      "z": 0,
      "name": "Soil_Mud_Dry"
    },
    {
      "x": -1,
      "y": 11,
      "z": 0,
      "name": "Empty"
    },
    {
      "x": -1,
      "y": 12,
      "z": 0,
      "name": "Empty"
    },
    {
      "x": -1,
      "y": 13,
      "z": 0,
      "name": "Empty"
    },
    {
      "x": -1,
      "y": 5,
      "z": 1,
      "name": "Soil_Dirt"
    },
    {
      "x": -1,
      "y": 6,
      "z": 1,
      "name": "Soil_Dirt"
    },
    {
      "x": -1,
      "y": 7,
      "z": 1,
      "name": "Soil_Dirt"
    },
    {
      "x": -1,
      "y": 8,
      "z": 1,
      "name": "Soil_Dirt"
    },
    {
      "x": -1,
      "y": 9,
      "z": 1,
      "name": "Soil_Dirt"
    },
    {
      "x": -1,
      "y": 10,
      "z": 1,
      "name": "Soil_Dirt"
    },
    {
      "x": -1,
      "y": 11,
      "z": 1,
      "name": "Empty"
    },
    {
      "x": -1,
      "y": 12,
      "z": 1,
      "name": "Empty"
    },
    {
      "x": -1,
      "y": 13,
      "z": 1,
      "name": "Empty"
    },
    {
      "x": -1,
      "y": 5,
      "z": 2,
      "name": "Soil_Dirt"
    },
    {
      "x": -1,
      "y": 6,
      "z": 2,
      "name": "Soil_Dirt"
    },
    {
      "x": -1,
      "y": 7,
      "z": 2,
      "name": "Soil_Dirt"
    },
    {
      "x": -1,
      "y": 8,
      "z": 2,
      "name": "Soil_Dirt"
    },
    {
      "x": -1,
      "y": 9,
      "z": 2,
      "name": "Soil_Dirt"
    },
    {
      "x": -1,
      "y": 10,
      "z": 2,
      "name": "Soil_Dirt"
    },
    {
      "x": -1,
      "y": 11,
      "z": 2,
      "name": "Empty"
    },
    {
      "x": -1,
      "y": 12,
      "z": 2,
      "name": "Empty"
    },
    {
      "x": -1,
      "y": 13,
      "z": 2,
      "name": "Empty"
    },
    {
      "x": -1,
      "y": 5,
      "z": 3,
      "name": "Soil_Dirt"
    },
    {
      "x": -1,
      "y": 6,
      "z": 3,
      "name": "Soil_Dirt"
    },
    {
      "x": -1,
      "y": 7,
      "z": 3,
      "name": "Soil_Dirt"
    },
    {
      "x": -1,
      "y": 8,
      "z": 3,
      "name": "Soil_Dirt"
    },
    {
      "x": -1,
      "y": 9,
      "z": 3,
      "name": "Soil_Dirt"
    },
    {
      "x": -1,
      "y": 10,
      "z": 3,
      "name": "Soil_Dirt_Tilled"
    },
    {
      "x": -1,
      "y": 11,
      "z": 3,
      "name": "Empty"
    },
    {
      "x": -1,
      "y": 12,
      "z": 3,
      "name": "Empty"
    },
    {
      "x": -1,
      "y": 13,
      "z": 3,
      "name": "Empty"
    },
    {
      "x": -1,
      "y": 5,
      "z": 4,
      "name": "Soil_Dirt"
    },
    {
      "x": -1,
      "y": 6,
      "z": 4,
      "name": "Soil_Dirt"
    },
    {
      "x": -1,
      "y": 7,
      "z": 4,
      "name": "Soil_Dirt"
    },
    {
      "x": -1,
      "y": 8,
      "z": 4,
      "name": "Soil_Dirt"
    },
    {
      "x": -1,
      "y": 9,
      "z": 4,
      "name": "Soil_Dirt"
    },
    {
      "x": -1,
      "y": 10,
      "z": 4,
      "name": "Soil_Dirt_Tilled"
    },
    {
      "x": -1,
      "y": 11,
      "z": 4,
      "name": "*Plant_Crop_Carrot_Block_State_Definitions_Stage2",
      "components": {
        "Components": {
          "FarmingBlock": {}
        }
      }
    },
    {
      "x": -1,
      "y": 12,
      "z": 4,
      "name": "Empty"
    },
    {
      "x": -1,
      "y": 13,
      "z": 4,
      "name": "Empty"
    },
    {
      "x": -1,
      "y": 5,
      "z": 5,
      "name": "Soil_Dirt"
    },
    {
      "x": -1,
      "y": 6,
      "z": 5,
      "name": "Soil_Dirt"
    },
    {
      "x": -1,
      "y": 7,
      "z": 5,
      "name": "Soil_Dirt"
    },
    {
      "x": -1,
      "y": 8,
      "z": 5,
      "name": "Soil_Dirt"
    },
    {
      "x": -1,
      "y": 9,
      "z": 5,
      "name": "Soil_Dirt"
    },
    {
      "x": -1,
      "y": 10,
      "z": 5,
      "name": "Soil_Dirt_Tilled"
    },
    {
      "x": -1,
      "y": 11,
      "z": 5,
      "name": "*Plant_Crop_Carrot_Block_State_Definitions_StageFinal",
      "components": {
        "Components": {
          "FarmingBlock": {}
        }
      }
    },
    {
      "x": -1,
      "y": 12,
      "z": 5,
      "name": "Empty"
    },
    {
      "x": -1,
      "y": 13,
      "z": 5,
      "name": "Empty"
    },
    {
      "x": -1,
      "y": 6,
      "z": 6,
      "name": "Soil_Dirt"
    },
    {
      "x": -1,
      "y": 7,
      "z": 6,
      "name": "Soil_Dirt"
    },
    {
      "x": -1,
      "y": 8,
      "z": 6,
      "name": "Soil_Dirt"
    },
    {
      "x": -1,
      "y": 9,
      "z": 6,
      "name": "Soil_Dirt"
    },
    {
      "x": -1,
      "y": 10,
      "z": 6,
      "name": "Soil_Dirt"
    },
    {
      "x": -1,
      "y": 11,
      "z": 6,
      "name": "Empty"
    },
    {
      "x": -1,
      "y": 12,
      "z": 6,
      "name": "Empty"
    },
    {
      "x": -1,
      "y": 13,
      "z": 6,
      "name": "Empty"
    },
    {
      "x": -1,
      "y": 8,
      "z": 7,
      "name": "Soil_Dirt"
    },
    {
      "x": -1,
      "y": 9,
      "z": 7,
      "name": "Soil_Dirt"
    },
    {
      "x": -1,
      "y": 10,
      "z": 7,
      "name": "Soil_Dirt"
    },
    {
      "x": -1,
      "y": 11,
      "z": 7,
      "name": "Wood_Hardwood_Fence"
    },
    {
      "x": -1,
      "y": 12,
      "z": 7,
      "name": "Empty"
    },
    {
      "x": -1,
      "y": 13,
      "z": 7,
      "name": "Empty"
    },
    {
      "x": 0,
      "y": 7,
      "z": -5,
      "name": "Soil_Dirt"
    },
    {
      "x": 0,
      "y": 8,
      "z": -5,
      "name": "Soil_Dirt"
    },
    {
      "x": 0,
      "y": 9,
      "z": -5,
      "name": "Soil_Dirt"
    },
    {
      "x": 0,
      "y": 10,
      "z": -5,
      "name": "Soil_Dirt_Tilled"
    },
    {
      "x": 0,
      "y": 11,
      "z": -5,
      "name": "Wood_Hardwood_Fence",
      "rotation": 2
    },
    {
      "x": 0,
      "y": 12,
      "z": -5,
      "name": "Empty"
    },
    {
      "x": 0,
      "y": 13,
      "z": -5,
      "name": "Empty"
    },
    {
      "x": 0,
      "y": 6,
      "z": -4,
      "name": "Soil_Dirt"
    },
    {
      "x": 0,
      "y": 7,
      "z": -4,
      "name": "Soil_Dirt"
    },
    {
      "x": 0,
      "y": 8,
      "z": -4,
      "name": "Soil_Dirt"
    },
    {
      "x": 0,
      "y": 9,
      "z": -4,
      "name": "Soil_Dirt"
    },
    {
      "x": 0,
      "y": 10,
      "z": -4,
      "name": "Soil_Dirt_Tilled"
    },
    {
      "x": 0,
      "y": 11,
      "z": -4,
      "name": "*Plant_Crop_Carrot_Block_State_Definitions_StageFinal",
      "components": {
        "Components": {
          "FarmingBlock": {}
        }
      }
    },
    {
      "x": 0,
      "y": 12,
      "z": -4,
      "name": "Empty"
    },
    {
      "x": 0,
      "y": 13,
      "z": -4,
      "name": "Empty"
    },
    {
      "x": 0,
      "y": 5,
      "z": -3,
      "name": "Soil_Dirt"
    },
    {
      "x": 0,
      "y": 6,
      "z": -3,
      "name": "Soil_Dirt"
    },
    {
      "x": 0,
      "y": 7,
      "z": -3,
      "name": "Soil_Dirt"
    },
    {
      "x": 0,
      "y": 8,
      "z": -3,
      "name": "Soil_Dirt"
    },
    {
      "x": 0,
      "y": 9,
      "z": -3,
      "name": "Soil_Dirt"
    },
    {
      "x": 0,
      "y": 10,
      "z": -3,
      "name": "Soil_Dirt_Tilled"
    },
    {
      "x": 0,
      "y": 11,
      "z": -3,
      "name": "*Plant_Crop_Carrot_Block_State_Definitions_StageFinal",
      "components": {
        "Components": {
          "FarmingBlock": {}
        }
      }
    },
    {
      "x": 0,
      "y": 12,
      "z": -3,
      "name": "Empty"
    },
    {
      "x": 0,
      "y": 13,
      "z": -3,
      "name": "Empty"
    },
    {
      "x": 0,
      "y": 5,
      "z": -2,
      "name": "Soil_Dirt"
    },
    {
      "x": 0,
      "y": 6,
      "z": -2,
      "name": "Soil_Dirt"
    },
    {
      "x": 0,
      "y": 7,
      "z": -2,
      "name": "Soil_Dirt"
    },
    {
      "x": 0,
      "y": 8,
      "z": -2,
      "name": "Soil_Dirt"
    },
    {
      "x": 0,
      "y": 9,
      "z": -2,
      "name": "Soil_Dirt"
    },
    {
      "x": 0,
      "y": 10,
      "z": -2,
      "name": "Soil_Dirt_Tilled"
    },
    {
      "x": 0,
      "y": 11,
      "z": -2,
      "name": "Empty"
    },
    {
      "x": 0,
      "y": 12,
      "z": -2,
      "name": "Empty"
    },
    {
      "x": 0,
      "y": 13,
      "z": -2,
      "name": "Empty"
    },
    {
      "x": 0,
      "y": 5,
      "z": -1,
      "name": "Soil_Dirt"
    },
    {
      "x": 0,
      "y": 6,
      "z": -1,
      "name": "Soil_Dirt"
    },
    {
      "x": 0,
      "y": 7,
      "z": -1,
      "name": "Soil_Dirt"
    },
    {
      "x": 0,
      "y": 8,
      "z": -1,
      "name": "Soil_Dirt"
    },
    {
      "x": 0,
      "y": 9,
      "z": -1,
      "name": "Soil_Dirt"
    },
    {
      "x": 0,
      "y": 10,
      "z": -1,
      "name": "Soil_Mud_Dry"
    },
    {
      "x": 0,
      "y": 11,
      "z": -1,
      "name": "Empty"
    },
    {
      "x": 0,
      "y": 12,
      "z": -1,
      "name": "Empty"
    },
    {
      "x": 0,
      "y": 13,
      "z": -1,
      "name": "Empty"
    },
    {
      "x": 0,
      "y": 5,
      "z": 0,
      "name": "Soil_Dirt"
    },
    {
      "x": 0,
      "y": 6,
      "z": 0,
      "name": "Soil_Dirt"
    },
    {
      "x": 0,
      "y": 7,
      "z": 0,
      "name": "Soil_Dirt"
    },
    {
      "x": 0,
      "y": 8,
      "z": 0,
      "name": "Soil_Dirt"
    },
    {
      "x": 0,
      "y": 9,
      "z": 0,
      "name": "Soil_Dirt"
    },
    {
      "x": 0,
      "y": 10,
      "z": 0,
      "name": "Soil_Mud_Dry"
    },
    {
      "x": 0,
      "y": 11,
      "z": 0,
      "name": "Empty"
    },
    {
      "x": 0,
      "y": 12,
      "z": 0,
      "name": "Empty"
    },
    {
      "x": 0,
      "y": 13,
      "z": 0,
      "name": "Empty"
    },
    {
      "x": 0,
      "y": 5,
      "z": 1,
      "name": "Soil_Dirt"
    },
    {
      "x": 0,
      "y": 6,
      "z": 1,
      "name": "Soil_Dirt"
    },
    {
      "x": 0,
      "y": 7,
      "z": 1,
      "name": "Soil_Dirt"
    },
    {
      "x": 0,
      "y": 8,
      "z": 1,
      "name": "Soil_Dirt"
    },
    {
      "x": 0,
      "y": 9,
      "z": 1,
      "name": "Soil_Dirt"
    },
    {
      "x": 0,
      "y": 10,
      "z": 1,
      "name": "Soil_Dirt"
    },
    {
      "x": 0,
      "y": 11,
      "z": 1,
      "name": "Empty"
    },
    {
      "x": 0,
      "y": 12,
      "z": 1,
      "name": "Empty"
    },
    {
      "x": 0,
      "y": 13,
      "z": 1,
      "name": "Empty"
    },
    {
      "x": 0,
      "y": 5,
      "z": 2,
      "name": "Soil_Dirt"
    },
    {
      "x": 0,
      "y": 6,
      "z": 2,
      "name": "Soil_Dirt"
    },
    {
      "x": 0,
      "y": 7,
      "z": 2,
      "name": "Soil_Dirt"
    },
    {
      "x": 0,
      "y": 8,
      "z": 2,
      "name": "Soil_Dirt"
    },
    {
      "x": 0,
      "y": 9,
      "z": 2,
      "name": "Soil_Dirt"
    },
    {
      "x": 0,
      "y": 10,
      "z": 2,
      "name": "Soil_Dirt"
    },
    {
      "x": 0,
      "y": 11,
      "z": 2,
      "name": "Empty"
    },
    {
      "x": 0,
      "y": 12,
      "z": 2,
      "name": "Empty"
    },
    {
      "x": 0,
      "y": 13,
      "z": 2,
      "name": "Empty"
    },
    {
      "x": 0,
      "y": 5,
      "z": 3,
      "name": "Soil_Dirt"
    },
    {
      "x": 0,
      "y": 6,
      "z": 3,
      "name": "Soil_Dirt"
    },
    {
      "x": 0,
      "y": 7,
      "z": 3,
      "name": "Soil_Dirt"
    },
    {
      "x": 0,
      "y": 8,
      "z": 3,
      "name": "Soil_Dirt"
    },
    {
      "x": 0,
      "y": 9,
      "z": 3,
      "name": "Soil_Dirt"
    },
    {
      "x": 0,
      "y": 10,
      "z": 3,
      "name": "Soil_Dirt"
    },
    {
      "x": 0,
      "y": 11,
      "z": 3,
      "name": "Empty"
    },
    {
      "x": 0,
      "y": 12,
      "z": 3,
      "name": "Empty"
    },
    {
      "x": 0,
      "y": 13,
      "z": 3,
      "name": "Empty"
    },
    {
      "x": 0,
      "y": 5,
      "z": 4,
      "name": "Soil_Dirt"
    },
    {
      "x": 0,
      "y": 6,
      "z": 4,
      "name": "Soil_Dirt"
    },
    {
      "x": 0,
      "y": 7,
      "z": 4,
      "name": "Soil_Dirt"
    },
    {
      "x": 0,
      "y": 8,
      "z": 4,
      "name": "Soil_Dirt"
    },
    {
      "x": 0,
      "y": 9,
      "z": 4,
      "name": "Soil_Dirt"
    },
    {
      "x": 0,
      "y": 10,
      "z": 4,
      "name": "Soil_Dirt_Tilled"
    },
    {
      "x": 0,
      "y": 11,
      "z": 4,
      "name": "Empty"
    },
    {
      "x": 0,
      "y": 12,
      "z": 4,
      "name": "Empty"
    },
    {
      "x": 0,
      "y": 13,
      "z": 4,
      "name": "Empty"
    },
    {
      "x": 0,
      "y": 5,
      "z": 5,
      "name": "Soil_Dirt"
    },
    {
      "x": 0,
      "y": 6,
      "z": 5,
      "name": "Soil_Dirt"
    },
    {
      "x": 0,
      "y": 7,
      "z": 5,
      "name": "Soil_Dirt"
    },
    {
      "x": 0,
      "y": 8,
      "z": 5,
      "name": "Soil_Dirt"
    },
    {
      "x": 0,
      "y": 9,
      "z": 5,
      "name": "Soil_Dirt"
    },
    {
      "x": 0,
      "y": 10,
      "z": 5,
      "name": "Soil_Dirt_Tilled"
    },
    {
      "x": 0,
      "y": 11,
      "z": 5,
      "name": "Coop_Chicken",
      "filler": 31,
      "rotation": 2
    },
    {
      "x": 0,
      "y": 12,
      "z": 5,
      "name": "Coop_Chicken",
      "filler": 1055,
      "rotation": 2
    },
    {
      "x": 0,
      "y": 13,
      "z": 5,
      "name": "Coop_Chicken",
      "filler": 2079,
      "rotation": 2
    },
    {
      "x": 0,
      "y": 6,
      "z": 6,
      "name": "Soil_Dirt"
    },
    {
      "x": 0,
      "y": 7,
      "z": 6,
      "name": "Soil_Dirt"
    },
    {
      "x": 0,
      "y": 8,
      "z": 6,
      "name": "Soil_Dirt"
    },
    {
      "x": 0,
      "y": 9,
      "z": 6,
      "name": "Soil_Dirt"
    },
    {
      "x": 0,
      "y": 10,
      "z": 6,
      "name": "Soil_Mud_Dry"
    },
    {
      "x": 0,
      "y": 11,
      "z": 6,
      "name": "Coop_Chicken",
      "filler": 63,
      "rotation": 2
    },
    {
      "x": 0,
      "y": 12,
      "z": 6,
      "name": "Coop_Chicken",
      "filler": 1087,
      "rotation": 2
    },
    {
      "x": 0,
      "y": 13,
      "z": 6,
      "name": "Coop_Chicken",
      "filler": 2111,
      "rotation": 2
    },
    {
      "x": 0,
      "y": 7,
      "z": 7,
      "name": "Soil_Dirt"
    },
    {
      "x": 0,
      "y": 8,
      "z": 7,
      "name": "Soil_Dirt"
    },
    {
      "x": 0,
      "y": 9,
      "z": 7,
      "name": "Soil_Dirt"
    },
    {
      "x": 0,
      "y": 10,
      "z": 7,
      "name": "Soil_Mud_Dry"
    },
    {
      "x": 0,
      "y": 11,
      "z": 7,
      "name": "Wood_Hardwood_Fence"
    },
    {
      "x": 0,
      "y": 12,
      "z": 7,
      "name": "Empty"
    },
    {
      "x": 0,
      "y": 13,
      "z": 7,
      "name": "Empty"
    },
    {
      "x": 1,
      "y": 7,
      "z": -5,
      "name": "Soil_Dirt"
    },
    {
      "x": 1,
      "y": 8,
      "z": -5,
      "name": "Soil_Dirt"
    },
    {
      "x": 1,
      "y": 9,
      "z": -5,
      "name": "Soil_Dirt"
    },
    {
      "x": 1,
      "y": 10,
      "z": -5,
      "name": "Soil_Dirt"
    },
    {
      "x": 1,
      "y": 11,
      "z": -5,
      "name": "*Wood_Hardwood_Fence_State_Definitions_Corner"
    },
    {
      "x": 1,
      "y": 12,
      "z": -5,
      "name": "Empty"
    },
    {
      "x": 1,
      "y": 13,
      "z": -5,
      "name": "Empty"
    },
    {
      "x": 1,
      "y": 6,
      "z": -4,
      "name": "Soil_Dirt"
    },
    {
      "x": 1,
      "y": 7,
      "z": -4,
      "name": "Soil_Dirt"
    },
    {
      "x": 1,
      "y": 8,
      "z": -4,
      "name": "Soil_Dirt"
    },
    {
      "x": 1,
      "y": 9,
      "z": -4,
      "name": "Soil_Dirt"
    },
    {
      "x": 1,
      "y": 10,
      "z": -4,
      "name": "Soil_Dirt_Tilled"
    },
    {
      "x": 1,
      "y": 11,
      "z": -4,
      "name": "*Wood_Hardwood_Fence_State_Definitions_Corner",
      "rotation": 2
    },
    {
      "x": 1,
      "y": 12,
      "z": -4,
      "name": "Empty"
    },
    {
      "x": 1,
      "y": 13,
      "z": -4,
      "name": "Empty"
    },
    {
      "x": 1,
      "y": 5,
      "z": -3,
      "name": "Soil_Dirt"
    },
    {
      "x": 1,
      "y": 6,
      "z": -3,
      "name": "Soil_Dirt"
    },
    {
      "x": 1,
      "y": 7,
      "z": -3,
      "name": "Soil_Dirt"
    },
    {
      "x": 1,
      "y": 8,
      "z": -3,
      "name": "Soil_Dirt"
    },
    {
      "x": 1,
      "y": 9,
      "z": -3,
      "name": "Soil_Dirt"
    },
    {
      "x": 1,
      "y": 10,
      "z": -3,
      "name": "Soil_Dirt_Tilled"
    },
    {
      "x": 1,
      "y": 11,
      "z": -3,
      "name": "*Plant_Crop_Carrot_Block_State_Definitions_Stage1",
      "components": {
        "Components": {
          "FarmingBlock": {}
        }
      }
    },
    {
      "x": 1,
      "y": 12,
      "z": -3,
      "name": "Empty"
    },
    {
      "x": 1,
      "y": 13,
      "z": -3,
      "name": "Empty"
    },
    {
      "x": 1,
      "y": 5,
      "z": -2,
      "name": "Soil_Dirt"
    },
    {
      "x": 1,
      "y": 6,
      "z": -2,
      "name": "Soil_Dirt"
    },
    {
      "x": 1,
      "y": 7,
      "z": -2,
      "name": "Soil_Dirt"
    },
    {
      "x": 1,
      "y": 8,
      "z": -2,
      "name": "Soil_Dirt"
    },
    {
      "x": 1,
      "y": 9,
      "z": -2,
      "name": "Soil_Dirt"
    },
    {
      "x": 1,
      "y": 10,
      "z": -2,
      "name": "Soil_Dirt_Tilled"
    },
    {
      "x": 1,
      "y": 11,
      "z": -2,
      "name": "Empty"
    },
    {
      "x": 1,
      "y": 12,
      "z": -2,
      "name": "Empty"
    },
    {
      "x": 1,
      "y": 13,
      "z": -2,
      "name": "Empty"
    },
    {
      "x": 1,
      "y": 5,
      "z": -1,
      "name": "Soil_Dirt"
    },
    {
      "x": 1,
      "y": 6,
      "z": -1,
      "name": "Soil_Dirt"
    },
    {
      "x": 1,
      "y": 7,
      "z": -1,
      "name": "Soil_Dirt"
    },
    {
      "x": 1,
      "y": 8,
      "z": -1,
      "name": "Soil_Dirt"
    },
    {
      "x": 1,
      "y": 9,
      "z": -1,
      "name": "Soil_Dirt"
    },
    {
      "x": 1,
      "y": 10,
      "z": -1,
      "name": "Soil_Dirt_Tilled"
    },
    {
      "x": 1,
      "y": 11,
      "z": -1,
      "name": "Empty"
    },
    {
      "x": 1,
      "y": 12,
      "z": -1,
      "name": "Empty"
    },
    {
      "x": 1,
      "y": 13,
      "z": -1,
      "name": "Empty"
    },
    {
      "x": 1,
      "y": 5,
      "z": 0,
      "name": "Soil_Dirt"
    },
    {
      "x": 1,
      "y": 6,
      "z": 0,
      "name": "Soil_Dirt"
    },
    {
      "x": 1,
      "y": 7,
      "z": 0,
      "name": "Soil_Dirt"
    },
    {
      "x": 1,
      "y": 8,
      "z": 0,
      "name": "Soil_Dirt"
    },
    {
      "x": 1,
      "y": 9,
      "z": 0,
      "name": "Soil_Dirt"
    },
    {
      "x": 1,
      "y": 10,
      "z": 0,
      "name": "Soil_Dirt"
    },
    {
      "x": 1,
      "y": 11,
      "z": 0,
      "name": "Empty"
    },
    {
      "x": 1,
      "y": 12,
      "z": 0,
      "name": "Empty"
    },
    {
      "x": 1,
      "y": 13,
      "z": 0,
      "name": "Empty"
    },
    {
      "x": 1,
      "y": 5,
      "z": 1,
      "name": "Soil_Dirt"
    },
    {
      "x": 1,
      "y": 6,
      "z": 1,
      "name": "Soil_Dirt"
    },
    {
      "x": 1,
      "y": 7,
      "z": 1,
      "name": "Soil_Dirt"
    },
    {
      "x": 1,
      "y": 8,
      "z": 1,
      "name": "Soil_Dirt"
    },
    {
      "x": 1,
      "y": 9,
      "z": 1,
      "name": "Soil_Dirt"
    },
    {
      "x": 1,
      "y": 10,
      "z": 1,
      "name": "Soil_Dirt"
    },
    {
      "x": 1,
      "y": 11,
      "z": 1,
      "name": "Empty"
    },
    {
      "x": 1,
      "y": 12,
      "z": 1,
      "name": "Empty"
    },
    {
      "x": 1,
      "y": 13,
      "z": 1,
      "name": "Empty"
    },
    {
      "x": 1,
      "y": 5,
      "z": 2,
      "name": "Soil_Dirt"
    },
    {
      "x": 1,
      "y": 6,
      "z": 2,
      "name": "Soil_Dirt"
    },
    {
      "x": 1,
      "y": 7,
      "z": 2,
      "name": "Soil_Dirt"
    },
    {
      "x": 1,
      "y": 8,
      "z": 2,
      "name": "Soil_Dirt"
    },
    {
      "x": 1,
      "y": 9,
      "z": 2,
      "name": "Soil_Dirt"
    },
    {
      "x": 1,
      "y": 10,
      "z": 2,
      "name": "Soil_Dirt"
    },
    {
      "x": 1,
      "y": 11,
      "z": 2,
      "name": "Empty"
    },
    {
      "x": 1,
      "y": 12,
      "z": 2,
      "name": "Empty"
    },
    {
      "x": 1,
      "y": 13,
      "z": 2,
      "name": "Empty"
    },
    {
      "x": 1,
      "y": 5,
      "z": 3,
      "name": "Soil_Dirt"
    },
    {
      "x": 1,
      "y": 6,
      "z": 3,
      "name": "Soil_Dirt"
    },
    {
      "x": 1,
      "y": 7,
      "z": 3,
      "name": "Soil_Dirt"
    },
    {
      "x": 1,
      "y": 8,
      "z": 3,
      "name": "Soil_Dirt"
    },
    {
      "x": 1,
      "y": 9,
      "z": 3,
      "name": "Soil_Dirt"
    },
    {
      "x": 1,
      "y": 10,
      "z": 3,
      "name": "Soil_Dirt"
    },
    {
      "x": 1,
      "y": 11,
      "z": 3,
      "name": "Empty"
    },
    {
      "x": 1,
      "y": 12,
      "z": 3,
      "name": "Empty"
    },
    {
      "x": 1,
      "y": 13,
      "z": 3,
      "name": "Empty"
    },
    {
      "x": 1,
      "y": 5,
      "z": 4,
      "name": "Soil_Dirt"
    },
    {
      "x": 1,
      "y": 6,
      "z": 4,
      "name": "Soil_Dirt"
    },
    {
      "x": 1,
      "y": 7,
      "z": 4,
      "name": "Soil_Dirt"
    },
    {
      "x": 1,
      "y": 8,
      "z": 4,
      "name": "Soil_Dirt"
    },
    {
      "x": 1,
      "y": 9,
      "z": 4,
      "name": "Soil_Dirt"
    },
    {
      "x": 1,
      "y": 10,
      "z": 4,
      "name": "Soil_Mud_Dry"
    },
    {
      "x": 1,
      "y": 11,
      "z": 4,
      "name": "Empty"
    },
    {
      "x": 1,
      "y": 12,
      "z": 4,
      "name": "Empty"
    },
    {
      "x": 1,
      "y": 13,
      "z": 4,
      "name": "Empty"
    },
    {
      "x": 1,
      "y": 5,
      "z": 5,
      "name": "Soil_Dirt"
    },
    {
      "x": 1,
      "y": 6,
      "z": 5,
      "name": "Soil_Dirt"
    },
    {
      "x": 1,
      "y": 7,
      "z": 5,
      "name": "Soil_Dirt"
    },
    {
      "x": 1,
      "y": 8,
      "z": 5,
      "name": "Soil_Dirt"
    },
    {
      "x": 1,
      "y": 9,
      "z": 5,
      "name": "Soil_Dirt"
    },
    {
      "x": 1,
      "y": 10,
      "z": 5,
      "name": "Soil_Mud_Dry"
    },
    {
      "x": 1,
      "y": 11,
      "z": 5,
      "name": "Coop_Chicken",
      "rotation": 2
    },
    {
      "x": 1,
      "y": 12,
      "z": 5,
      "name": "Coop_Chicken",
      "filler": 1024,
      "rotation": 2
    },
    {
      "x": 1,
      "y": 13,
      "z": 5,
      "name": "Coop_Chicken",
      "filler": 2048,
      "rotation": 2
    },
    {
      "x": 1,
      "y": 6,
      "z": 6,
      "name": "Soil_Dirt"
    },
    {
      "x": 1,
      "y": 7,
      "z": 6,
      "name": "Soil_Dirt"
    },
    {
      "x": 1,
      "y": 8,
      "z": 6,
      "name": "Soil_Dirt"
    },
    {
      "x": 1,
      "y": 9,
      "z": 6,
      "name": "Soil_Dirt"
    },
    {
      "x": 1,
      "y": 10,
      "z": 6,
      "name": "Soil_Mud_Dry"
    },
    {
      "x": 1,
      "y": 11,
      "z": 6,
      "name": "Coop_Chicken",
      "filler": 32,
      "rotation": 2
    },
    {
      "x": 1,
      "y": 12,
      "z": 6,
      "name": "Coop_Chicken",
      "filler": 1056,
      "rotation": 2
    },
    {
      "x": 1,
      "y": 13,
      "z": 6,
      "name": "Coop_Chicken",
      "filler": 2080,
      "rotation": 2
    },
    {
      "x": 1,
      "y": 7,
      "z": 7,
      "name": "Soil_Dirt"
    },
    {
      "x": 1,
      "y": 8,
      "z": 7,
      "name": "Soil_Dirt"
    },
    {
      "x": 1,
      "y": 9,
      "z": 7,
      "name": "Soil_Dirt"
    },
    {
      "x": 1,
      "y": 10,
      "z": 7,
      "name": "Soil_Mud_Dry"
    },
    {
      "x": 1,
      "y": 11,
      "z": 7,
      "name": "Wood_Hardwood_Fence"
    },
    {
      "x": 1,
      "y": 12,
      "z": 7,
      "name": "Empty"
    },
    {
      "x": 1,
      "y": 13,
      "z": 7,
      "name": "Empty"
    },
    {
      "x": 2,
      "y": 7,
      "z": -4,
      "name": "Soil_Dirt"
    },
    {
      "x": 2,
      "y": 8,
      "z": -4,
      "name": "Soil_Dirt"
    },
    {
      "x": 2,
      "y": 9,
      "z": -4,
      "name": "Soil_Dirt"
    },
    {
      "x": 2,
      "y": 10,
      "z": -4,
      "name": "Soil_Dirt_Tilled"
    },
    {
      "x": 2,
      "y": 11,
      "z": -4,
      "name": "Wood_Hardwood_Fence",
      "rotation": 2
    },
    {
      "x": 2,
      "y": 12,
      "z": -4,
      "name": "Empty"
    },
    {
      "x": 2,
      "y": 13,
      "z": -4,
      "name": "Empty"
    },
    {
      "x": 2,
      "y": 6,
      "z": -3,
      "name": "Soil_Dirt"
    },
    {
      "x": 2,
      "y": 7,
      "z": -3,
      "name": "Soil_Dirt"
    },
    {
      "x": 2,
      "y": 8,
      "z": -3,
      "name": "Soil_Dirt"
    },
    {
      "x": 2,
      "y": 9,
      "z": -3,
      "name": "Soil_Dirt"
    },
    {
      "x": 2,
      "y": 10,
      "z": -3,
      "name": "Soil_Dirt_Tilled"
    },
    {
      "x": 2,
      "y": 11,
      "z": -3,
      "name": "Empty"
    },
    {
      "x": 2,
      "y": 12,
      "z": -3,
      "name": "Empty"
    },
    {
      "x": 2,
      "y": 13,
      "z": -3,
      "name": "Empty"
    },
    {
      "x": 2,
      "y": 5,
      "z": -2,
      "name": "Soil_Dirt"
    },
    {
      "x": 2,
      "y": 6,
      "z": -2,
      "name": "Soil_Dirt"
    },
    {
      "x": 2,
      "y": 7,
      "z": -2,
      "name": "Soil_Dirt"
    },
    {
      "x": 2,
      "y": 8,
      "z": -2,
      "name": "Soil_Dirt"
    },
    {
      "x": 2,
      "y": 9,
      "z": -2,
      "name": "Soil_Dirt"
    },
    {
      "x": 2,
      "y": 10,
      "z": -2,
      "name": "Soil_Mud_Dry"
    },
    {
      "x": 2,
      "y": 11,
      "z": -2,
      "name": "Empty"
    },
    {
      "x": 2,
      "y": 12,
      "z": -2,
      "name": "Empty"
    },
    {
      "x": 2,
      "y": 13,
      "z": -2,
      "name": "Empty"
    },
    {
      "x": 2,
      "y": 5,
      "z": -1,
      "name": "Soil_Dirt"
    },
    {
      "x": 2,
      "y": 6,
      "z": -1,
      "name": "Soil_Dirt"
    },
    {
      "x": 2,
      "y": 7,
      "z": -1,
      "name": "Soil_Dirt"
    },
    {
      "x": 2,
      "y": 8,
      "z": -1,
      "name": "Soil_Dirt"
    },
    {
      "x": 2,
      "y": 9,
      "z": -1,
      "name": "Soil_Dirt"
    },
    {
      "x": 2,
      "y": 10,
      "z": -1,
      "name": "Soil_Mud_Dry"
    },
    {
      "x": 2,
      "y": 11,
      "z": -1,
      "name": "Empty"
    },
    {
      "x": 2,
      "y": 12,
      "z": -1,
      "name": "Empty"
    },
    {
      "x": 2,
      "y": 13,
      "z": -1,
      "name": "Empty"
    },
    {
      "x": 2,
      "y": 5,
      "z": 0,
      "name": "Soil_Dirt"
    },
    {
      "x": 2,
      "y": 6,
      "z": 0,
      "name": "Soil_Dirt"
    },
    {
      "x": 2,
      "y": 7,
      "z": 0,
      "name": "Soil_Dirt"
    },
    {
      "x": 2,
      "y": 8,
      "z": 0,
      "name": "Soil_Dirt"
    },
    {
      "x": 2,
      "y": 9,
      "z": 0,
      "name": "Soil_Dirt"
    },
    {
      "x": 2,
      "y": 10,
      "z": 0,
      "name": "Soil_Dirt"
    },
    {
      "x": 2,
      "y": 11,
      "z": 0,
      "name": "Empty"
    },
    {
      "x": 2,
      "y": 12,
      "z": 0,
      "name": "Empty"
    },
    {
      "x": 2,
      "y": 13,
      "z": 0,
      "name": "Empty"
    },
    {
      "x": 2,
      "y": 5,
      "z": 1,
      "name": "Soil_Dirt"
    },
    {
      "x": 2,
      "y": 6,
      "z": 1,
      "name": "Soil_Dirt"
    },
    {
      "x": 2,
      "y": 7,
      "z": 1,
      "name": "Soil_Dirt"
    },
    {
      "x": 2,
      "y": 8,
      "z": 1,
      "name": "Soil_Dirt"
    },
    {
      "x": 2,
      "y": 9,
      "z": 1,
      "name": "Soil_Dirt"
    },
    {
      "x": 2,
      "y": 10,
      "z": 1,
      "name": "Soil_Dirt"
    },
    {
      "x": 2,
      "y": 11,
      "z": 1,
      "name": "Empty"
    },
    {
      "x": 2,
      "y": 12,
      "z": 1,
      "name": "Empty"
    },
    {
      "x": 2,
      "y": 13,
      "z": 1,
      "name": "Empty"
    },
    {
      "x": 2,
      "y": 5,
      "z": 2,
      "name": "Soil_Dirt"
    },
    {
      "x": 2,
      "y": 6,
      "z": 2,
      "name": "Soil_Dirt"
    },
    {
      "x": 2,
      "y": 7,
      "z": 2,
      "name": "Soil_Dirt"
    },
    {
      "x": 2,
      "y": 8,
      "z": 2,
      "name": "Soil_Dirt"
    },
    {
      "x": 2,
      "y": 9,
      "z": 2,
      "name": "Soil_Dirt"
    },
    {
      "x": 2,
      "y": 10,
      "z": 2,
      "name": "Soil_Mud_Dry"
    },
    {
      "x": 2,
      "y": 11,
      "z": 2,
      "name": "Empty"
    },
    {
      "x": 2,
      "y": 12,
      "z": 2,
      "name": "Empty"
    },
    {
      "x": 2,
      "y": 13,
      "z": 2,
      "name": "Empty"
    },
    {
      "x": 2,
      "y": 5,
      "z": 3,
      "name": "Soil_Dirt"
    },
    {
      "x": 2,
      "y": 6,
      "z": 3,
      "name": "Soil_Dirt"
    },
    {
      "x": 2,
      "y": 7,
      "z": 3,
      "name": "Soil_Dirt"
    },
    {
      "x": 2,
      "y": 8,
      "z": 3,
      "name": "Soil_Dirt"
    },
    {
      "x": 2,
      "y": 9,
      "z": 3,
      "name": "Soil_Dirt"
    },
    {
      "x": 2,
      "y": 10,
      "z": 3,
      "name": "Soil_Mud_Dry"
    },
    {
      "x": 2,
      "y": 11,
      "z": 3,
      "name": "Empty"
    },
    {
      "x": 2,
      "y": 12,
      "z": 3,
      "name": "Empty"
    },
    {
      "x": 2,
      "y": 13,
      "z": 3,
      "name": "Empty"
    },
    {
      "x": 2,
      "y": 5,
      "z": 4,
      "name": "Soil_Dirt"
    },
    {
      "x": 2,
      "y": 6,
      "z": 4,
      "name": "Soil_Dirt"
    },
    {
      "x": 2,
      "y": 7,
      "z": 4,
      "name": "Soil_Dirt"
    },
    {
      "x": 2,
      "y": 8,
      "z": 4,
      "name": "Soil_Dirt"
    },
    {
      "x": 2,
      "y": 9,
      "z": 4,
      "name": "Soil_Dirt"
    },
    {
      "x": 2,
      "y": 10,
      "z": 4,
      "name": "Soil_Mud_Dry"
    },
    {
      "x": 2,
      "y": 11,
      "z": 4,
      "name": "Empty"
    },
    {
      "x": 2,
      "y": 12,
      "z": 4,
      "name": "Empty"
    },
    {
      "x": 2,
      "y": 13,
      "z": 4,
      "name": "Empty"
    },
    {
      "x": 2,
      "y": 5,
      "z": 5,
      "name": "Soil_Dirt"
    },
    {
      "x": 2,
      "y": 6,
      "z": 5,
      "name": "Soil_Dirt"
    },
    {
      "x": 2,
      "y": 7,
      "z": 5,
      "name": "Soil_Dirt"
    },
    {
      "x": 2,
      "y": 8,
      "z": 5,
      "name": "Soil_Dirt"
    },
    {
      "x": 2,
      "y": 9,
      "z": 5,
      "name": "Soil_Dirt"
    },
    {
      "x": 2,
      "y": 10,
      "z": 5,
      "name": "Soil_Mud_Dry"
    },
    {
      "x": 2,
      "y": 11,
      "z": 5,
      "name": "Coop_Chicken",
      "filler": 1,
      "rotation": 2
    },
    {
      "x": 2,
      "y": 12,
      "z": 5,
      "name": "Coop_Chicken",
      "filler": 1025,
      "rotation": 2
    },
    {
      "x": 2,
      "y": 13,
      "z": 5,
      "name": "Coop_Chicken",
      "filler": 2049,
      "rotation": 2
    },
    {
      "x": 2,
      "y": 6,
      "z": 6,
      "name": "Soil_Dirt"
    },
    {
      "x": 2,
      "y": 7,
      "z": 6,
      "name": "Soil_Dirt"
    },
    {
      "x": 2,
      "y": 8,
      "z": 6,
      "name": "Soil_Dirt"
    },
    {
      "x": 2,
      "y": 9,
      "z": 6,
      "name": "Soil_Dirt"
    },
    {
      "x": 2,
      "y": 10,
      "z": 6,
      "name": "Soil_Mud_Dry"
    },
    {
      "x": 2,
      "y": 11,
      "z": 6,
      "name": "Coop_Chicken",
      "filler": 33,
      "rotation": 2
    },
    {
      "x": 2,
      "y": 12,
      "z": 6,
      "name": "Coop_Chicken",
      "filler": 1057,
      "rotation": 2
    },
    {
      "x": 2,
      "y": 13,
      "z": 6,
      "name": "Coop_Chicken",
      "filler": 2081,
      "rotation": 2
    },
    {
      "x": 2,
      "y": 6,
      "z": 7,
      "name": "Soil_Dirt"
    },
    {
      "x": 2,
      "y": 7,
      "z": 7,
      "name": "Soil_Dirt"
    },
    {
      "x": 2,
      "y": 8,
      "z": 7,
      "name": "Soil_Dirt"
    },
    {
      "x": 2,
      "y": 9,
      "z": 7,
      "name": "Soil_Dirt"
    },
    {
      "x": 2,
      "y": 10,
      "z": 7,
      "name": "Soil_Dirt"
    },
    {
      "x": 2,
      "y": 11,
      "z": 7,
      "name": "Wood_Hardwood_Fence"
    },
    {
      "x": 2,
      "y": 12,
      "z": 7,
      "name": "Empty"
    },
    {
      "x": 2,
      "y": 13,
      "z": 7,
      "name": "Empty"
    },
    {
      "x": 3,
      "y": 7,
      "z": -4,
      "name": "Soil_Dirt"
    },
    {
      "x": 3,
      "y": 8,
      "z": -4,
      "name": "Soil_Dirt"
    },
    {
      "x": 3,
      "y": 9,
      "z": -4,
      "name": "Soil_Dirt"
    },
    {
      "x": 3,
      "y": 10,
      "z": -4,
      "name": "Soil_Dirt"
    },
    {
      "x": 3,
      "y": 11,
      "z": -4,
      "name": "Wood_Hardwood_Fence",
      "rotation": 2
    },
    {
      "x": 3,
      "y": 12,
      "z": -4,
      "name": "Empty"
    },
    {
      "x": 3,
      "y": 13,
      "z": -4,
      "name": "Empty"
    },
    {
      "x": 3,
      "y": 6,
      "z": -3,
      "name": "Soil_Dirt"
    },
    {
      "x": 3,
      "y": 7,
      "z": -3,
      "name": "Soil_Dirt"
    },
    {
      "x": 3,
      "y": 8,
      "z": -3,
      "name": "Soil_Dirt"
    },
    {
      "x": 3,
      "y": 9,
      "z": -3,
      "name": "Soil_Dirt"
    },
    {
      "x": 3,
      "y": 10,
      "z": -3,
      "name": "Soil_Dirt_Tilled"
    },
    {
      "x": 3,
      "y": 11,
      "z": -3,
      "name": "*Plant_Crop_Carrot_Block_State_Definitions_Stage1",
      "components": {
        "Components": {
          "FarmingBlock": {}
        }
      }
    },
    {
      "x": 3,
      "y": 12,
      "z": -3,
      "name": "Empty"
    },
    {
      "x": 3,
      "y": 13,
      "z": -3,
      "name": "Empty"
    },
    {
      "x": 3,
      "y": 5,
      "z": -2,
      "name": "Soil_Dirt"
    },
    {
      "x": 3,
      "y": 6,
      "z": -2,
      "name": "Soil_Dirt"
    },
    {
      "x": 3,
      "y": 7,
      "z": -2,
      "name": "Soil_Dirt"
    },
    {
      "x": 3,
      "y": 8,
      "z": -2,
      "name": "Soil_Dirt"
    },
    {
      "x": 3,
      "y": 9,
      "z": -2,
      "name": "Soil_Dirt"
    },
    {
      "x": 3,
      "y": 10,
      "z": -2,
      "name": "Soil_Mud_Dry"
    },
    {
      "x": 3,
      "y": 11,
      "z": -2,
      "name": "Empty"
    },
    {
      "x": 3,
      "y": 12,
      "z": -2,
      "name": "Empty"
    },
    {
      "x": 3,
      "y": 13,
      "z": -2,
      "name": "Empty"
    },
    {
      "x": 3,
      "y": 5,
      "z": -1,
      "name": "Soil_Dirt"
    },
    {
      "x": 3,
      "y": 6,
      "z": -1,
      "name": "Soil_Dirt"
    },
    {
      "x": 3,
      "y": 7,
      "z": -1,
      "name": "Soil_Dirt"
    },
    {
      "x": 3,
      "y": 8,
      "z": -1,
      "name": "Soil_Dirt"
    },
    {
      "x": 3,
      "y": 9,
      "z": -1,
      "name": "Soil_Dirt"
    },
    {
      "x": 3,
      "y": 10,
      "z": -1,
      "name": "Soil_Mud_Dry"
    },
    {
      "x": 3,
      "y": 11,
      "z": -1,
      "name": "Empty"
    },
    {
      "x": 3,
      "y": 12,
      "z": -1,
      "name": "Empty"
    },
    {
      "x": 3,
      "y": 13,
      "z": -1,
      "name": "Empty"
    },
    {
      "x": 3,
      "y": 5,
      "z": 0,
      "name": "Soil_Dirt"
    },
    {
      "x": 3,
      "y": 6,
      "z": 0,
      "name": "Soil_Dirt"
    },
    {
      "x": 3,
      "y": 7,
      "z": 0,
      "name": "Soil_Dirt"
    },
    {
      "x": 3,
      "y": 8,
      "z": 0,
      "name": "Soil_Dirt"
    },
    {
      "x": 3,
      "y": 9,
      "z": 0,
      "name": "Soil_Dirt"
    },
    {
      "x": 3,
      "y": 10,
      "z": 0,
      "name": "Soil_Mud_Dry"
    },
    {
      "x": 3,
      "y": 11,
      "z": 0,
      "name": "Empty"
    },
    {
      "x": 3,
      "y": 12,
      "z": 0,
      "name": "Empty"
    },
    {
      "x": 3,
      "y": 13,
      "z": 0,
      "name": "Empty"
    },
    {
      "x": 3,
      "y": 5,
      "z": 1,
      "name": "Soil_Dirt"
    },
    {
      "x": 3,
      "y": 6,
      "z": 1,
      "name": "Soil_Dirt"
    },
    {
      "x": 3,
      "y": 7,
      "z": 1,
      "name": "Soil_Dirt"
    },
    {
      "x": 3,
      "y": 8,
      "z": 1,
      "name": "Soil_Dirt"
    },
    {
      "x": 3,
      "y": 9,
      "z": 1,
      "name": "Soil_Dirt"
    },
    {
      "x": 3,
      "y": 10,
      "z": 1,
      "name": "Soil_Mud_Dry"
    },
    {
      "x": 3,
      "y": 11,
      "z": 1,
      "name": "Empty"
    },
    {
      "x": 3,
      "y": 12,
      "z": 1,
      "name": "Empty"
    },
    {
      "x": 3,
      "y": 13,
      "z": 1,
      "name": "Empty"
    },
    {
      "x": 3,
      "y": 5,
      "z": 2,
      "name": "Soil_Dirt"
    },
    {
      "x": 3,
      "y": 6,
      "z": 2,
      "name": "Soil_Dirt"
    },
    {
      "x": 3,
      "y": 7,
      "z": 2,
      "name": "Soil_Dirt"
    },
    {
      "x": 3,
      "y": 8,
      "z": 2,
      "name": "Soil_Dirt"
    },
    {
      "x": 3,
      "y": 9,
      "z": 2,
      "name": "Soil_Dirt"
    },
    {
      "x": 3,
      "y": 10,
      "z": 2,
      "name": "Soil_Mud_Dry"
    },
    {
      "x": 3,
      "y": 11,
      "z": 2,
      "name": "Empty"
    },
    {
      "x": 3,
      "y": 12,
      "z": 2,
      "name": "Empty"
    },
    {
      "x": 3,
      "y": 13,
      "z": 2,
      "name": "Empty"
    },
    {
      "x": 3,
      "y": 5,
      "z": 3,
      "name": "Soil_Dirt"
    },
    {
      "x": 3,
      "y": 6,
      "z": 3,
      "name": "Soil_Dirt"
    },
    {
      "x": 3,
      "y": 7,
      "z": 3,
      "name": "Soil_Dirt"
    },
    {
      "x": 3,
      "y": 8,
      "z": 3,
      "name": "Soil_Dirt"
    },
    {
      "x": 3,
      "y": 9,
      "z": 3,
      "name": "Soil_Dirt"
    },
    {
      "x": 3,
      "y": 10,
      "z": 3,
      "name": "Soil_Mud_Dry"
    },
    {
      "x": 3,
      "y": 11,
      "z": 3,
      "name": "Empty"
    },
    {
      "x": 3,
      "y": 12,
      "z": 3,
      "name": "Empty"
    },
    {
      "x": 3,
      "y": 13,
      "z": 3,
      "name": "Empty"
    },
    {
      "x": 3,
      "y": 6,
      "z": 4,
      "name": "Soil_Dirt"
    },
    {
      "x": 3,
      "y": 7,
      "z": 4,
      "name": "Soil_Dirt"
    },
    {
      "x": 3,
      "y": 8,
      "z": 4,
      "name": "Soil_Dirt"
    },
    {
      "x": 3,
      "y": 9,
      "z": 4,
      "name": "Soil_Dirt"
    },
    {
      "x": 3,
      "y": 10,
      "z": 4,
      "name": "Soil_Mud_Dry"
    },
    {
      "x": 3,
      "y": 11,
      "z": 4,
      "name": "Empty"
    },
    {
      "x": 3,
      "y": 12,
      "z": 4,
      "name": "Empty"
    },
    {
      "x": 3,
      "y": 13,
      "z": 4,
      "name": "Empty"
    },
    {
      "x": 3,
      "y": 6,
      "z": 5,
      "name": "Soil_Dirt"
    },
    {
      "x": 3,
      "y": 7,
      "z": 5,
      "name": "Soil_Dirt"
    },
    {
      "x": 3,
      "y": 8,
      "z": 5,
      "name": "Soil_Dirt"
    },
    {
      "x": 3,
      "y": 9,
      "z": 5,
      "name": "Soil_Dirt"
    },
    {
      "x": 3,
      "y": 10,
      "z": 5,
      "name": "Soil_Mud_Dry"
    },
    {
      "x": 3,
      "y": 11,
      "z": 5,
      "name": "Empty"
    },
    {
      "x": 3,
      "y": 12,
      "z": 5,
      "name": "Empty"
    },
    {
      "x": 3,
      "y": 13,
      "z": 5,
      "name": "Empty"
    },
    {
      "x": 3,
      "y": 6,
      "z": 6,
      "name": "Soil_Dirt"
    },
    {
      "x": 3,
      "y": 7,
      "z": 6,
      "name": "Soil_Dirt"
    },
    {
      "x": 3,
      "y": 8,
      "z": 6,
      "name": "Soil_Dirt"
    },
    {
      "x": 3,
      "y": 9,
      "z": 6,
      "name": "Soil_Dirt"
    },
    {
      "x": 3,
      "y": 10,
      "z": 6,
      "name": "Soil_Grass_Deep"
    },
    {
      "x": 3,
      "y": 11,
      "z": 6,
      "name": "Plant_Grass_Lush"
    },
    {
      "x": 3,
      "y": 12,
      "z": 6,
      "name": "Empty"
    },
    {
      "x": 3,
      "y": 13,
      "z": 6,
      "name": "Empty"
    },
    {
      "x": 3,
      "y": 7,
      "z": 7,
      "name": "Soil_Dirt"
    },
    {
      "x": 3,
      "y": 8,
      "z": 7,
      "name": "Soil_Dirt"
    },
    {
      "x": 3,
      "y": 9,
      "z": 7,
      "name": "Soil_Dirt"
    },
    {
      "x": 3,
      "y": 10,
      "z": 7,
      "name": "Soil_Grass_Deep"
    },
    {
      "x": 3,
      "y": 11,
      "z": 7,
      "name": "Wood_Hardwood_Fence"
    },
    {
      "x": 3,
      "y": 12,
      "z": 7,
      "name": "Empty"
    },
    {
      "x": 3,
      "y": 13,
      "z": 7,
      "name": "Empty"
    },
    {
      "x": 4,
      "y": 8,
      "z": -4,
      "name": "Soil_Dirt"
    },
    {
      "x": 4,
      "y": 9,
      "z": -4,
      "name": "Soil_Dirt"
    },
    {
      "x": 4,
      "y": 10,
      "z": -4,
      "name": "Soil_Leaves"
    },
    {
      "x": 4,
      "y": 11,
      "z": -4,
      "name": "Wood_Hardwood_Fence",
      "rotation": 2
    },
    {
      "x": 4,
      "y": 12,
      "z": -4,
      "name": "Empty"
    },
    {
      "x": 4,
      "y": 13,
      "z": -4,
      "name": "Empty"
    },
    {
      "x": 4,
      "y": 6,
      "z": -3,
      "name": "Soil_Dirt"
    },
    {
      "x": 4,
      "y": 7,
      "z": -3,
      "name": "Soil_Dirt"
    },
    {
      "x": 4,
      "y": 8,
      "z": -3,
      "name": "Soil_Dirt"
    },
    {
      "x": 4,
      "y": 9,
      "z": -3,
      "name": "Soil_Dirt"
    },
    {
      "x": 4,
      "y": 10,
      "z": -3,
      "name": "Soil_Leaves"
    },
    {
      "x": 4,
      "y": 11,
      "z": -3,
      "name": "Plant_Grass_Sharp_Tall"
    },
    {
      "x": 4,
      "y": 12,
      "z": -3,
      "name": "Plant_Grass_Sharp_Tall",
      "filler": 1024
    },
    {
      "x": 4,
      "y": 13,
      "z": -3,
      "name": "Empty"
    },
    {
      "x": 4,
      "y": 6,
      "z": -2,
      "name": "Soil_Dirt"
    },
    {
      "x": 4,
      "y": 7,
      "z": -2,
      "name": "Soil_Dirt"
    },
    {
      "x": 4,
      "y": 8,
      "z": -2,
      "name": "Soil_Dirt"
    },
    {
      "x": 4,
      "y": 9,
      "z": -2,
      "name": "Soil_Dirt"
    },
    {
      "x": 4,
      "y": 10,
      "z": -2,
      "name": "Soil_Dirt"
    },
    {
      "x": 4,
      "y": 11,
      "z": -2,
      "name": "Empty"
    },
    {
      "x": 4,
      "y": 12,
      "z": -2,
      "name": "Empty"
    },
    {
      "x": 4,
      "y": 13,
      "z": -2,
      "name": "Empty"
    },
    {
      "x": 4,
      "y": 6,
      "z": -1,
      "name": "Soil_Dirt"
    },
    {
      "x": 4,
      "y": 7,
      "z": -1,
      "name": "Soil_Dirt"
    },
    {
      "x": 4,
      "y": 8,
      "z": -1,
      "name": "Soil_Dirt"
    },
    {
      "x": 4,
      "y": 9,
      "z": -1,
      "name": "Soil_Dirt"
    },
    {
      "x": 4,
      "y": 10,
      "z": -1,
      "name": "Soil_Mud_Dry"
    },
    {
      "x": 4,
      "y": 11,
      "z": -1,
      "name": "Empty"
    },
    {
      "x": 4,
      "y": 12,
      "z": -1,
      "name": "Empty"
    },
    {
      "x": 4,
      "y": 13,
      "z": -1,
      "name": "Empty"
    },
    {
      "x": 4,
      "y": 6,
      "z": 0,
      "name": "Soil_Dirt"
    },
    {
      "x": 4,
      "y": 7,
      "z": 0,
      "name": "Soil_Dirt"
    },
    {
      "x": 4,
      "y": 8,
      "z": 0,
      "name": "Soil_Dirt"
    },
    {
      "x": 4,
      "y": 9,
      "z": 0,
      "name": "Soil_Dirt"
    },
    {
      "x": 4,
      "y": 10,
      "z": 0,
      "name": "Soil_Mud_Dry"
    },
    {
      "x": 4,
      "y": 11,
      "z": 0,
      "name": "Empty"
    },
    {
      "x": 4,
      "y": 12,
      "z": 0,
      "name": "Empty"
    },
    {
      "x": 4,
      "y": 13,
      "z": 0,
      "name": "Empty"
    },
    {
      "x": 4,
      "y": 6,
      "z": 1,
      "name": "Soil_Dirt"
    },
    {
      "x": 4,
      "y": 7,
      "z": 1,
      "name": "Soil_Dirt"
    },
    {
      "x": 4,
      "y": 8,
      "z": 1,
      "name": "Soil_Dirt"
    },
    {
      "x": 4,
      "y": 9,
      "z": 1,
      "name": "Soil_Dirt"
    },
    {
      "x": 4,
      "y": 10,
      "z": 1,
      "name": "Soil_Mud_Dry"
    },
    {
      "x": 4,
      "y": 11,
      "z": 1,
      "name": "*Wood_Hardwood_Fence_State_Definitions_Corner",
      "rotation": 1
    },
    {
      "x": 4,
      "y": 12,
      "z": 1,
      "name": "Empty"
    },
    {
      "x": 4,
      "y": 13,
      "z": 1,
      "name": "Empty"
    },
    {
      "x": 4,
      "y": 6,
      "z": 2,
      "name": "Soil_Dirt"
    },
    {
      "x": 4,
      "y": 7,
      "z": 2,
      "name": "Soil_Dirt"
    },
    {
      "x": 4,
      "y": 8,
      "z": 2,
      "name": "Soil_Dirt"
    },
    {
      "x": 4,
      "y": 9,
      "z": 2,
      "name": "Soil_Dirt"
    },
    {
      "x": 4,
      "y": 10,
      "z": 2,
      "name": "Soil_Mud_Dry"
    },
    {
      "x": 4,
      "y": 11,
      "z": 2,
      "name": "Wood_Hardwood_Fence",
      "rotation": 1
    },
    {
      "x": 4,
      "y": 12,
      "z": 2,
      "name": "Empty"
    },
    {
      "x": 4,
      "y": 13,
      "z": 2,
      "name": "Empty"
    },
    {
      "x": 4,
      "y": 6,
      "z": 3,
      "name": "Soil_Dirt"
    },
    {
      "x": 4,
      "y": 7,
      "z": 3,
      "name": "Soil_Dirt"
    },
    {
      "x": 4,
      "y": 8,
      "z": 3,
      "name": "Soil_Dirt"
    },
    {
      "x": 4,
      "y": 9,
      "z": 3,
      "name": "Soil_Dirt"
    },
    {
      "x": 4,
      "y": 10,
      "z": 3,
      "name": "Soil_Mud_Dry"
    },
    {
      "x": 4,
      "y": 11,
      "z": 3,
      "name": "Wood_Hardwood_Fence",
      "rotation": 1
    },
    {
      "x": 4,
      "y": 12,
      "z": 3,
      "name": "Empty"
    },
    {
      "x": 4,
      "y": 13,
      "z": 3,
      "name": "Empty"
    },
    {
      "x": 4,
      "y": 7,
      "z": 4,
      "name": "Soil_Dirt"
    },
    {
      "x": 4,
      "y": 8,
      "z": 4,
      "name": "Soil_Dirt"
    },
    {
      "x": 4,
      "y": 9,
      "z": 4,
      "name": "Soil_Dirt"
    },
    {
      "x": 4,
      "y": 10,
      "z": 4,
      "name": "Soil_Mud_Dry"
    },
    {
      "x": 4,
      "y": 11,
      "z": 4,
      "name": "Wood_Hardwood_Fence",
      "rotation": 1
    },
    {
      "x": 4,
      "y": 12,
      "z": 4,
      "name": "Empty"
    },
    {
      "x": 4,
      "y": 13,
      "z": 4,
      "name": "Empty"
    },
    {
      "x": 4,
      "y": 7,
      "z": 5,
      "name": "Soil_Dirt"
    },
    {
      "x": 4,
      "y": 8,
      "z": 5,
      "name": "Soil_Dirt"
    },
    {
      "x": 4,
      "y": 9,
      "z": 5,
      "name": "Soil_Dirt"
    },
    {
      "x": 4,
      "y": 10,
      "z": 5,
      "name": "Soil_Grass_Deep"
    },
    {
      "x": 4,
      "y": 11,
      "z": 5,
      "name": "Wood_Hardwood_Fence",
      "rotation": 1
    },
    {
      "x": 4,
      "y": 12,
      "z": 5,
      "name": "Empty"
    },
    {
      "x": 4,
      "y": 13,
      "z": 5,
      "name": "Empty"
    },
    {
      "x": 4,
      "y": 8,
      "z": 6,
      "name": "Soil_Dirt"
    },
    {
      "x": 4,
      "y": 9,
      "z": 6,
      "name": "Soil_Dirt"
    },
    {
      "x": 4,
      "y": 10,
      "z": 6,
      "name": "Soil_Grass_Deep"
    },
    {
      "x": 4,
      "y": 11,
      "z": 6,
      "name": "Wood_Hardwood_Fence",
      "rotation": 1
    },
    {
      "x": 4,
      "y": 12,
      "z": 6,
      "name": "Empty"
    },
    {
      "x": 4,
      "y": 13,
      "z": 6,
      "name": "Empty"
    },
    {
      "x": 4,
      "y": 10,
      "z": 7,
      "name": "Soil_Grass_Deep"
    },
    {
      "x": 4,
      "y": 11,
      "z": 7,
      "name": "*Wood_Hardwood_Fence_State_Definitions_Corner",
      "rotation": 3
    },
    {
      "x": 4,
      "y": 12,
      "z": 7,
      "name": "Empty"
    },
    {
      "x": 4,
      "y": 13,
      "z": 7,
      "name": "Empty"
    },
    {
      "x": 5,
      "y": 9,
      "z": -4,
      "name": "Soil_Dirt"
    },
    {
      "x": 5,
      "y": 10,
      "z": -4,
      "name": "Soil_Leaves"
    },
    {
      "x": 5,
      "y": 11,
      "z": -4,
      "name": "*Wood_Hardwood_Fence_State_Definitions_Corner"
    },
    {
      "x": 5,
      "y": 12,
      "z": -4,
      "name": "Empty"
    },
    {
      "x": 5,
      "y": 13,
      "z": -4,
      "name": "Empty"
    },
    {
      "x": 5,
      "y": 8,
      "z": -3,
      "name": "Soil_Dirt"
    },
    {
      "x": 5,
      "y": 9,
      "z": -3,
      "name": "Soil_Dirt"
    },
    {
      "x": 5,
      "y": 10,
      "z": -3,
      "name": "Soil_Leaves"
    },
    {
      "x": 5,
      "y": 11,
      "z": -3,
      "name": "Wood_Hardwood_Fence",
      "rotation": 1
    },
    {
      "x": 5,
      "y": 12,
      "z": -3,
      "name": "Empty"
    },
    {
      "x": 5,
      "y": 13,
      "z": -3,
      "name": "Empty"
    },
    {
      "x": 5,
      "y": 7,
      "z": -2,
      "name": "Soil_Dirt"
    },
    {
      "x": 5,
      "y": 8,
      "z": -2,
      "name": "Soil_Dirt"
    },
    {
      "x": 5,
      "y": 9,
      "z": -2,
      "name": "Soil_Dirt"
    },
    {
      "x": 5,
      "y": 10,
      "z": -2,
      "name": "Soil_Grass_Deep"
    },
    {
      "x": 5,
      "y": 11,
      "z": -2,
      "name": "Wood_Hardwood_Fence",
      "rotation": 1
    },
    {
      "x": 5,
      "y": 12,
      "z": -2,
      "name": "Empty"
    },
    {
      "x": 5,
      "y": 13,
      "z": -2,
      "name": "Empty"
    },
    {
      "x": 5,
      "y": 8,
      "z": -1,
      "name": "Soil_Dirt"
    },
    {
      "x": 5,
      "y": 9,
      "z": -1,
      "name": "Soil_Dirt"
    },
    {
      "x": 5,
      "y": 10,
      "z": -1,
      "name": "Soil_Mud_Dry"
    },
    {
      "x": 5,
      "y": 11,
      "z": -1,
      "name": "Wood_Hardwood_Fence",
      "rotation": 1
    },
    {
      "x": 5,
      "y": 12,
      "z": -1,
      "name": "Empty"
    },
    {
      "x": 5,
      "y": 13,
      "z": -1,
      "name": "Empty"
    },
    {
      "x": 5,
      "y": 8,
      "z": 0,
      "name": "Soil_Dirt"
    },
    {
      "x": 5,
      "y": 9,
      "z": 0,
      "name": "Soil_Dirt"
    },
    {
      "x": 5,
      "y": 10,
      "z": 0,
      "name": "Soil_Mud_Dry"
    },
    {
      "x": 5,
      "y": 11,
      "z": 0,
      "name": "Wood_Hardwood_Fence",
      "rotation": 1
    },
    {
      "x": 5,
      "y": 12,
      "z": 0,
      "name": "Empty"
    },
    {
      "x": 5,
      "y": 13,
      "z": 0,
      "name": "Empty"
    },
    {
      "x": 5,
      "y": 9,
      "z": 1,
      "name": "Soil_Dirt"
    },
    {
      "x": 5,
      "y": 10,
      "z": 1,
      "name": "Soil_Mud_Dry"
    },
    {
      "x": 5,
      "y": 11,
      "z": 1,
      "name": "*Wood_Hardwood_Fence_State_Definitions_Corner",
      "rotation": 3
    },
    {
      "x": 5,
      "y": 12,
      "z": 1,
      "name": "Empty"
    },
    {
      "x": 5,
      "y": 13,
      "z": 1,
      "name": "Empty"
    }
  ],
  "entities": [
    {
      "Components": {
        "Nameplate": {
          "Text": "Kweebec_Rabbit"
        },
        "HiddenFromAdventurePlayer": {},
        "SpawnMarkerComponent": {
          "SpawnMarker": "Kweebec_Rabbit",
          "RespawnTime": 0.0,
          "SpawnCount": 0
        },
        "Transform": {
          "Position": {
            "X": 1.3345489501953125,
            "Y": 11.174522399902344,
            "Z": -0.298004150390625
          },
          "Rotation": {
            "Pitch": 0.0,
            "Yaw": -1.7172925472259521,
            "Roll": 0.0
          }
        },
        "Model": {
          "Model": {
            "Id": "NPC_Spawn_Marker",
            "Scale": 1.0
          }
        },
        "UUID": {
          "UUID": {
            "$binary": "Lrp/FUijPU2tKB3zqFmJAg==",
            "$type": "04"
          }
        },
        "HeadRotation": {
          "Rotation": {
            "Pitch": 0.0,
            "Yaw": 1.424300193786621,
            "Roll": 0.0
          }
        }
      }
    },
    {
      "Components": {
        "Nameplate": {
          "Text": "Kweebec_Rabbit"
        },
        "HiddenFromAdventurePlayer": {},
        "SpawnMarkerComponent": {
          "SpawnMarker": "Kweebec_Rabbit",
          "RespawnTime": 0.0,
          "SpawnCount": 0
        },
        "Transform": {
          "Position": {
            "X": -2.5232467651367188,
            "Y": 11.175048828125,
            "Z": 1.16461181640625
          },
          "Rotation": {
            "Pitch": 0.0,
            "Yaw": -1.0235412120819092,
            "Roll": 0.0
          }
        },
        "Model": {
          "Model": {
            "Id": "NPC_Spawn_Marker",
            "Scale": 1.0
          }
        },
        "UUID": {
          "UUID": {
            "$binary": "t4OMACEgNpqwHHCUYZO7kg==",
            "$type": "04"
          }
        },
        "HeadRotation": {
          "Rotation": {
            "Pitch": 0.0,
            "Yaw": 2.118051528930664,
            "Roll": 0.0
          }
        }
      }
    }
  ]
}