{
  "version": 8,
  "blockIdVersion": 8,
  "anchorX": 0,
  "anchorY": 0,
  "anchorZ": 0,
  "blocks": [
    {
      "x": -19,
      "y": -22,
      "z": 0,
      "name": "Rock_Basalt"
    },
    {
      "x": -19,
      "y": -21,
      "z": 0,
      "name": "Rock_Basalt"
    },
    {
      "x": -19,
      "y": -20,
      "z": 0,
      "name": "Rock_Basalt"
    },
    {
      "x": -19,
      "y": -19,
      "z": 0,
      "name": "Rock_Basalt"
    },
    {
      "x": -19,
      "y": -18,
      "z": 0,
      "name": "Rock_Basalt"
    },
    {
      "x": -19,
      "y": -17,
      "z": 0,
      "name": "Rock_Basalt"
    },
    {
      "x": -19,
      "y": -16,
      "z": 0,
      "name": "Rock_Basalt"
    },
    {
      "x": -19,
      "y": -15,
      "z": 0,
      "name": "Rock_Basalt"
    },
    {
      "x": -19,
      "y": -14,
      "z": 0,
      "name": "Rock_Basalt"
    },
    {
      "x": -19,
      "y": -13,
      "z": 0,
      "name": "Rock_Basalt"
    },
    {
      "x": -19,
      "y": -22,
      "z": 1,
      "name": "Rock_Basalt"
    },
    {
      "x": -19,
      "y": -21,
      "z": 1,
      "name": "Rock_Basalt"
    },
    {
      "x": -19,
      "y": -20,
      "z": 1,
      "name": "Rock_Basalt"
    },
    {
      "x": -19,
      "y": -19,
      "z": 1,
      "name": "Rock_Basalt"
    },
    {
      "x": -19,
      "y": -18,
      "z": 1,
      "name": "Rock_Basalt"
    },
    {
      "x": -19,
      "y": -17,
      "z": 1,
      "name": "Rock_Basalt"
    },
    {
      "x": -19,
      "y": -16,
      "z": 1,
      "name": "Rock_Basalt"
    },
    {
      "x": -19,
      "y": -15,
      "z": 1,
      "name": "Rock_Basalt"
    },
    {
      "x": -19,
      "y": -14,
      "z": 1,
      "name": "Rock_Basalt"
    },
    {
      "x": -19,
      "y": -13,
      "z": 1,
      "name": "Rock_Basalt"
    },
    {
      "x": -19,
      "y": -12,
      "z": 1,
      "name": "Rock_Basalt"
    },
    {
      "x": -19,
      "y": -22,
      "z": 2,
      "name": "Rock_Basalt"
    },
    {
      "x": -19,
      "y": -21,
      "z": 2,
      "name": "Rock_Basalt"
    },
    {
      "x": -19,
      "y": -20,
      "z": 2,
      "name": "Rock_Basalt"
    },
    {
      "x": -19,
      "y": -19,
      "z": 2,
      "name": "Rock_Basalt"
    },
    {
      "x": -19,
      "y": -18,
      "z": 2,
      "name": "Rock_Basalt"
    },
    {
      "x": -19,
      "y": -17,
      "z": 2,
      "name": "Rock_Basalt"
    },
    {
      "x": -19,
      "y": -16,
      "z": 2,
      "name": "Rock_Basalt"
    },
    {
      "x": -19,
      "y": -15,
      "z": 2,
      "name": "Rock_Basalt"
    },
    {
      "x": -19,
      "y": -14,
      "z": 2,
      "name": "Rock_Basalt"
    },
    {
      "x": -19,
      "y": -13,
      "z": 2,
      "name": "Rock_Basalt"
    },
    {
      "x": -18,
      "y": -22,
      "z": -1,
      "name": "Rock_Basalt"
    },
    {
      "x": -18,
      "y": -21,
      "z": -1,
      "name": "Rock_Basalt"
    },
    {
      "x": -18,
      "y": -20,
      "z": -1,
      "name": "Rock_Basalt"
    },
    {
      "x": -18,
      "y": -19,
      "z": -1,
      "name": "Rock_Basalt"
    },
    {
      "x": -18,
      "y": -18,
      "z": -1,
      "name": "Rock_Basalt"
    },
    {
      "x": -18,
      "y": -17,
      "z": -1,
      "name": "Rock_Basalt"
    },
    {
      "x": -18,
      "y": -16,
      "z": -1,
      "name": "Rock_Basalt"
    },
    {
      "x": -18,
      "y": -15,
      "z": -1,
      "name": "Rock_Basalt"
    },
    {
      "x": -18,
      "y": -14,
      "z": -1,
      "name": "Rock_Basalt"
    },
    {
      "x": -18,
      "y": -13,
      "z": -1,
      "name": "Rock_Basalt"
    },
    {
      "x": -18,
      "y": -12,
      "z": -1,
      "name": "Rock_Basalt"
    },
    {
      "x": -18,
      "y": -11,
      "z": -1,
      "name": "Rock_Basalt"
    },
    {
      "x": -18,
      "y": -10,
      "z": -1,
      "name": "Rock_Basalt"
    },
    {
      "x": -18,
      "y": -9,
      "z": -1,
      "name": "Rock_Basalt"
    },
    {
      "x": -18,
      "y": -8,
      "z": -1,
      "name": "Soil_Dirt_Cold"
    },
    {
      "x": -18,
      "y": -7,
      "z": -1,
      "name": "Soil_Dirt_Cold"
    },
    {
      "x": -18,
      "y": -22,
      "z": 0,
      "name": "Rock_Basalt"
    },
    {
      "x": -18,
      "y": -21,
      "z": 0,
      "name": "Rock_Basalt"
    },
    {
      "x": -18,
      "y": -20,
      "z": 0,
      "name": "Rock_Basalt"
    },
    {
      "x": -18,
      "y": -19,
      "z": 0,
      "name": "Rock_Basalt"
    },
    {
      "x": -18,
      "y": -18,
      "z": 0,
      "name": "Rock_Basalt"
    },
    {
      "x": -18,
      "y": -17,
      "z": 0,
      "name": "Rock_Basalt"
    },
    {
      "x": -18,
      "y": -16,
      "z": 0,
      "name": "Rock_Basalt"
    },
    {
      "x": -18,
      "y": -15,
      "z": 0,
      "name": "Rock_Basalt"
    },
    {
      "x": -18,
      "y": -14,
      "z": 0,
      "name": "Rock_Basalt"
    },
    {
      "x": -18,
      "y": -13,
      "z": 0,
      "name": "Rock_Basalt"
    },
    {
      "x": -18,
      "y": -12,
      "z": 0,
      "name": "Rock_Basalt"
    },
    {
      "x": -18,
      "y": -11,
      "z": 0,
      "name": "Rock_Basalt"
    },
    {
      "x": -18,
      "y": -10,
      "z": 0,
      "name": "Rock_Basalt"
    },
    {
      "x": -18,
      "y": -9,
      "z": 0,
      "name": "Rock_Basalt"
    },
    {
      "x": -18,
      "y": -8,
      "z": 0,
      "name": "Rock_Basalt"
    },
    {
      "x": -18,
      "y": -7,
      "z": 0,
      "name": "Soil_Dirt_Cold"
    },
    {
      "x": -18,
      "y": -6,
      "z": 0,
      "name": "Soil_Dirt_Cold"
    },
    {
      "x": -18,
      "y": 1,
      "z": 0,
      "name": "Rock_Shale"
    },
    {
      "x": -18,
      "y": 2,
      "z": 0,
      "name": "Rock_Shale"
    },
    {
      "x": -18,
      "y": 3,
      "z": 0,
      "name": "Rock_Shale_Brick_Smooth_Half",
      "rotation": 7
    },
    {
      "x": -18,
      "y": -22,
      "z": 1,
      "name": "Rock_Basalt"
    },
    {
      "x": -18,
      "y": -21,
      "z": 1,
      "name": "Rock_Basalt"
    },
    {
      "x": -18,
      "y": -20,
      "z": 1,
      "name": "Rock_Basalt"
    },
    {
      "x": -18,
      "y": -19,
      "z": 1,
      "name": "Rock_Basalt"
    },
    {
      "x": -18,
      "y": -18,
      "z": 1,
      "name": "Rock_Basalt"
    },
    {
      "x": -18,
      "y": -17,
      "z": 1,
      "name": "Rock_Basalt"
    },
    {
      "x": -18,
      "y": -16,
      "z": 1,
      "name": "Rock_Basalt"
    },
    {
      "x": -18,
      "y": -15,
      "z": 1,
      "name": "Rock_Basalt"
    },
    {
      "x": -18,
      "y": -14,
      "z": 1,
      "name": "Rock_Basalt"
    },
    {
      "x": -18,
      "y": -13,
      "z": 1,
      "name": "Rock_Basalt"
    },
    {
      "x": -18,
      "y": -12,
      "z": 1,
      "name": "Rock_Basalt"
    },
    {
      "x": -18,
      "y": -11,
      "z": 1,
      "name": "Rock_Basalt"
    },
    {
      "x": -18,
      "y": -10,
      "z": 1,
      "name": "Rock_Basalt"
    },
    {
      "x": -18,
      "y": -9,
      "z": 1,
      "name": "Rock_Basalt"
    },
    {
      "x": -18,
      "y": -8,
      "z": 1,
      "name": "Rock_Basalt"
    },
    {
      "x": -18,
      "y": -7,
      "z": 1,
      "name": "Soil_Dirt_Cold"
    },
    {
      "x": -18,
      "y": -6,
      "z": 1,
      "name": "Soil_Dirt_Cold"
    },
    {
      "x": -18,
      "y": -1,
      "z": 1,
      "name": "Rock_Shale"
    },
    {
      "x": -18,
      "y": 0,
      "z": 1,
      "name": "Rock_Shale"
    },
    {
      "x": -18,
      "y": 1,
      "z": 1,
      "name": "Rock_Shale"
    },
    {
      "x": -18,
      "y": 2,
      "z": 1,
      "name": "Rock_Shale"
    },
    {
      "x": -18,
      "y": 3,
      "z": 1,
      "name": "Rock_Shale_Brick_Smooth_Half",
      "rotation": 7
    },
    {
      "x": -18,
      "y": -22,
      "z": 2,
      "name": "Rock_Basalt"
    },
    {
      "x": -18,
      "y": -21,
      "z": 2,
      "name": "Rock_Basalt"
    },
    {
      "x": -18,
      "y": -20,
      "z": 2,
      "name": "Rock_Basalt"
    },
    {
      "x": -18,
      "y": -19,
      "z": 2,
      "name": "Rock_Basalt"
    },
    {
      "x": -18,
      "y": -18,
      "z": 2,
      "name": "Rock_Basalt"
    },
    {
      "x": -18,
      "y": -17,
      "z": 2,
      "name": "Rock_Basalt"
    },
    {
      "x": -18,
      "y": -16,
      "z": 2,
      "name": "Rock_Basalt"
    },
    {
      "x": -18,
      "y": -15,
      "z": 2,
      "name": "Rock_Basalt"
    },
    {
      "x": -18,
      "y": -14,
      "z": 2,
      "name": "Rock_Basalt"
    },
    {
      "x": -18,
      "y": -13,
      "z": 2,
      "name": "Rock_Basalt"
    },
    {
      "x": -18,
      "y": -12,
      "z": 2,
      "name": "Rock_Basalt"
    },
    {
      "x": -18,
      "y": -11,
      "z": 2,
      "name": "Rock_Basalt"
    },
    {
      "x": -18,
      "y": -10,
      "z": 2,
      "name": "Rock_Basalt"
    },
    {
      "x": -18,
      "y": -9,
      "z": 2,
      "name": "Rock_Basalt"
    },
    {
      "x": -18,
      "y": -8,
      "z": 2,
      "name": "Soil_Dirt_Cold"
    },
    {
      "x": -18,
      "y": -7,
      "z": 2,
      "name": "Soil_Dirt_Cold"
    },
    {
      "x": -18,
      "y": -1,
      "z": 2,
      "name": "Rock_Shale"
    },
    {
      "x": -18,
      "y": 0,
      "z": 2,
      "name": "Rock_Shale"
    },
    {
      "x": -18,
      "y": 1,
      "z": 2,
      "name": "Rock_Shale"
    },
    {
      "x": -18,
      "y": 2,
      "z": 2,
      "name": "Rock_Shale"
    },
    {
      "x": -18,
      "y": 3,
      "z": 2,
      "name": "Rock_Shale_Brick_Smooth_Half",
      "rotation": 7
    },
    {
      "x": -18,
      "y": -22,
      "z": 3,
      "name": "Rock_Basalt"
    },
    {
      "x": -18,
      "y": -21,
      "z": 3,
      "name": "Rock_Basalt"
    },
    {
      "x": -18,
      "y": -20,
      "z": 3,
      "name": "Rock_Basalt"
    },
    {
      "x": -18,
      "y": -19,
      "z": 3,
      "name": "Rock_Basalt"
    },
    {
      "x": -18,
      "y": -18,
      "z": 3,
      "name": "Rock_Basalt"
    },
    {
      "x": -18,
      "y": -17,
      "z": 3,
      "name": "Rock_Basalt"
    },
    {
      "x": -18,
      "y": -16,
      "z": 3,
      "name": "Rock_Basalt"
    },
    {
      "x": -18,
      "y": -15,
      "z": 3,
      "name": "Rock_Basalt"
    },
    {
      "x": -18,
      "y": -14,
      "z": 3,
      "name": "Rock_Basalt"
    },
    {
      "x": -18,
      "y": -13,
      "z": 3,
      "name": "Rock_Basalt"
    },
    {
      "x": -18,
      "y": -12,
      "z": 3,
      "name": "Rock_Basalt"
    },
    {
      "x": -18,
      "y": -11,
      "z": 3,
      "name": "Rock_Basalt"
    },
    {
      "x": -18,
      "y": -10,
      "z": 3,
      "name": "Soil_Dirt_Cold"
    },
    {
      "x": -17,
      "y": -12,
      "z": -6,
      "name": "Rock_Basalt"
    },
    {
      "x": -17,
      "y": -11,
      "z": -6,
      "name": "Rock_Basalt"
    },
    {
      "x": -17,
      "y": -10,
      "z": -6,
      "name": "Rock_Basalt"
    },
    {
      "x": -17,
      "y": -9,
      "z": -6,
      "name": "Rock_Basalt"
    },
    {
      "x": -17,
      "y": -8,
      "z": -6,
      "name": "Rock_Basalt"
    },
    {
      "x": -17,
      "y": -7,
      "z": -6,
      "name": "Rock_Basalt"
    },
    {
      "x": -17,
      "y": -6,
      "z": -6,
      "name": "Rock_Basalt"
    },
    {
      "x": -17,
      "y": -5,
      "z": -6,
      "name": "Rock_Basalt"
    },
    {
      "x": -17,
      "y": -4,
      "z": -6,
      "name": "Rock_Basalt"
    },
    {
      "x": -17,
      "y": -3,
      "z": -6,
      "name": "Rock_Basalt"
    },
    {
      "x": -17,
      "y": -2,
      "z": -6,
      "name": "Rock_Basalt"
    },
    {
      "x": -17,
      "y": -1,
      "z": -6,
      "name": "Rock_Basalt"
    },
    {
      "x": -17,
      "y": 0,
      "z": -6,
      "name": "Rock_Basalt"
    },
    {
      "x": -17,
      "y": 1,
      "z": -6,
      "name": "Rock_Basalt"
    },
    {
      "x": -17,
      "y": 2,
      "z": -6,
      "name": "Rock_Basalt"
    },
    {
      "x": -17,
      "y": 3,
      "z": -6,
      "name": "Rock_Basalt"
    },
    {
      "x": -17,
      "y": 4,
      "z": -6,
      "name": "Rock_Basalt"
    },
    {
      "x": -17,
      "y": 5,
      "z": -6,
      "name": "Soil_Dirt_Cold"
    },
    {
      "x": -17,
      "y": 6,
      "z": -6,
      "name": "Soil_Snow"
    },
    {
      "x": -17,
      "y": -12,
      "z": -5,
      "name": "Rock_Basalt"
    },
    {
      "x": -17,
      "y": -11,
      "z": -5,
      "name": "Rock_Basalt"
    },
    {
      "x": -17,
      "y": -10,
      "z": -5,
      "name": "Rock_Basalt"
    },
    {
      "x": -17,
      "y": -9,
      "z": -5,
      "name": "Rock_Basalt"
    },
    {
      "x": -17,
      "y": -8,
      "z": -5,
      "name": "Rock_Basalt"
    },
    {
      "x": -17,
      "y": -7,
      "z": -5,
      "name": "Rock_Basalt"
    },
    {
      "x": -17,
      "y": -6,
      "z": -5,
      "name": "Rock_Basalt"
    },
    {
      "x": -17,
      "y": -5,
      "z": -5,
      "name": "Rock_Basalt"
    },
    {
      "x": -17,
      "y": -4,
      "z": -5,
      "name": "Rock_Basalt"
    },
    {
      "x": -17,
      "y": -3,
      "z": -5,
      "name": "Rock_Basalt"
    },
    {
      "x": -17,
      "y": -2,
      "z": -5,
      "name": "Rock_Basalt"
    },
    {
      "x": -17,
      "y": -1,
      "z": -5,
      "name": "Rock_Basalt"
    },
    {
      "x": -17,
      "y": 0,
      "z": -5,
      "name": "Rock_Basalt"
    },
    {
      "x": -17,
      "y": 1,
      "z": -5,
      "name": "Rock_Basalt"
    },
    {
      "x": -17,
      "y": 2,
      "z": -5,
      "name": "Rock_Basalt"
    },
    {
      "x": -17,
      "y": 3,
      "z": -5,
      "name": "Rock_Basalt"
    },
    {
      "x": -17,
      "y": 4,
      "z": -5,
      "name": "Rock_Basalt"
    },
    {
      "x": -17,
      "y": 5,
      "z": -5,
      "name": "Soil_Dirt_Cold"
    },
    {
      "x": -17,
      "y": 6,
      "z": -5,
      "name": "Soil_Snow"
    },
    {
      "x": -17,
      "y": -22,
      "z": -4,
      "name": "Rock_Basalt"
    },
    {
      "x": -17,
      "y": -21,
      "z": -4,
      "name": "Rock_Basalt"
    },
    {
      "x": -17,
      "y": -20,
      "z": -4,
      "name": "Rock_Basalt"
    },
    {
      "x": -17,
      "y": -19,
      "z": -4,
      "name": "Rock_Basalt"
    },
    {
      "x": -17,
      "y": -18,
      "z": -4,
      "name": "Rock_Basalt"
    },
    {
      "x": -17,
      "y": -17,
      "z": -4,
      "name": "Rock_Basalt"
    },
    {
      "x": -17,
      "y": -16,
      "z": -4,
      "name": "Rock_Basalt"
    },
    {
      "x": -17,
      "y": -15,
      "z": -4,
      "name": "Rock_Basalt"
    },
    {
      "x": -17,
      "y": -14,
      "z": -4,
      "name": "Rock_Basalt"
    },
    {
      "x": -17,
      "y": -13,
      "z": -4,
      "name": "Rock_Basalt"
    },
    {
      "x": -17,
      "y": -12,
      "z": -4,
      "name": "Rock_Basalt"
    },
    {
      "x": -17,
      "y": -11,
      "z": -4,
      "name": "Rock_Basalt"
    },
    {
      "x": -17,
      "y": -10,
      "z": -4,
      "name": "Rock_Basalt"
    },
    {
      "x": -17,
      "y": -9,
      "z": -4,
      "name": "Rock_Basalt"
    },
    {
      "x": -17,
      "y": -8,
      "z": -4,
      "name": "Rock_Basalt"
    },
    {
      "x": -17,
      "y": -7,
      "z": -4,
      "name": "Rock_Basalt"
    },
    {
      "x": -17,
      "y": -6,
      "z": -4,
      "name": "Rock_Basalt"
    },
    {
      "x": -17,
      "y": -5,
      "z": -4,
      "name": "Rock_Basalt"
    },
    {
      "x": -17,
      "y": -4,
      "z": -4,
      "name": "Rock_Basalt"
    },
    {
      "x": -17,
      "y": -3,
      "z": -4,
      "name": "Rock_Basalt"
    },
    {
      "x": -17,
      "y": -2,
      "z": -4,
      "name": "Rock_Basalt"
    },
    {
      "x": -17,
      "y": -1,
      "z": -4,
      "name": "Rock_Basalt"
    },
    {
      "x": -17,
      "y": 0,
      "z": -4,
      "name": "Rock_Basalt"
    },
    {
      "x": -17,
      "y": 1,
      "z": -4,
      "name": "Rock_Basalt"
    },
    {
      "x": -17,
      "y": 2,
      "z": -4,
      "name": "Rock_Basalt"
    },
    {
      "x": -17,
      "y": 3,
      "z": -4,
      "name": "Rock_Basalt"
    },
    {
      "x": -17,
      "y": 4,
      "z": -4,
      "name": "Rock_Basalt"
    },
    {
      "x": -17,
      "y": 5,
      "z": -4,
      "name": "Soil_Dirt_Cold"
    },
    {
      "x": -17,
      "y": 6,
      "z": -4,
      "name": "Soil_Snow"
    },
    {
      "x": -17,
      "y": -22,
      "z": -3,
      "name": "Rock_Basalt"
    },
    {
      "x": -17,
      "y": -21,
      "z": -3,
      "name": "Rock_Basalt"
    },
    {
      "x": -17,
      "y": -20,
      "z": -3,
      "name": "Rock_Basalt"
    },
    {
      "x": -17,
      "y": -19,
      "z": -3,
      "name": "Rock_Basalt"
    },
    {
      "x": -17,
      "y": -18,
      "z": -3,
      "name": "Rock_Basalt"
    },
    {
      "x": -17,
      "y": -17,
      "z": -3,
      "name": "Rock_Basalt"
    },
    {
      "x": -17,
      "y": -16,
      "z": -3,
      "name": "Rock_Basalt"
    },
    {
      "x": -17,
      "y": -15,
      "z": -3,
      "name": "Rock_Basalt"
    },
    {
      "x": -17,
      "y": -14,
      "z": -3,
      "name": "Rock_Basalt"
    },
    {
      "x": -17,
      "y": -13,
      "z": -3,
      "name": "Rock_Basalt"
    },
    {
      "x": -17,
      "y": -12,
      "z": -3,
      "name": "Rock_Basalt"
    },
    {
      "x": -17,
      "y": -11,
      "z": -3,
      "name": "Rock_Basalt"
    },
    {
      "x": -17,
      "y": -10,
      "z": -3,
      "name": "Rock_Basalt"
    },
    {
      "x": -17,
      "y": -9,
      "z": -3,
      "name": "Rock_Basalt"
    },
    {
      "x": -17,
      "y": -8,
      "z": -3,
      "name": "Rock_Basalt"
    },
    {
      "x": -17,
      "y": -7,
      "z": -3,
      "name": "Rock_Basalt"
    },
    {
      "x": -17,
      "y": -6,
      "z": -3,
      "name": "Rock_Basalt"
    },
    {
      "x": -17,
      "y": -5,
      "z": -3,
      "name": "Rock_Shale"
    },
    {
      "x": -17,
      "y": -4,
      "z": -3,
      "name": "Rock_Shale"
    },
    {
      "x": -17,
      "y": -3,
      "z": -3,
      "name": "Rock_Shale"
    },
    {
      "x": -17,
      "y": -2,
      "z": -3,
      "name": "Rock_Shale"
    },
    {
      "x": -17,
      "y": -1,
      "z": -3,
      "name": "Rock_Shale"
    },
    {
      "x": -17,
      "y": 0,
      "z": -3,
      "name": "Rock_Shale"
    },
    {
      "x": -17,
      "y": 1,
      "z": -3,
      "name": "Rock_Shale"
    },
    {
      "x": -17,
      "y": 2,
      "z": -3,
      "name": "Soil_Dirt_Cold"
    },
    {
      "x": -17,
      "y": 3,
      "z": -3,
      "name": "Soil_Snow"
    },
    {
      "x": -17,
      "y": 4,
      "z": -3,
      "name": "Soil_Snow_Half"
    },
    {
      "x": -17,
      "y": -22,
      "z": -2,
      "name": "Rock_Basalt"
    },
    {
      "x": -17,
      "y": -21,
      "z": -2,
      "name": "Rock_Basalt"
    },
    {
      "x": -17,
      "y": -20,
      "z": -2,
      "name": "Rock_Basalt"
    },
    {
      "x": -17,
      "y": -19,
      "z": -2,
      "name": "Rock_Basalt"
    },
    {
      "x": -17,
      "y": -18,
      "z": -2,
      "name": "Rock_Basalt"
    },
    {
      "x": -17,
      "y": -17,
      "z": -2,
      "name": "Rock_Basalt"
    },
    {
      "x": -17,
      "y": -16,
      "z": -2,
      "name": "Rock_Basalt"
    },
    {
      "x": -17,
      "y": -15,
      "z": -2,
      "name": "Rock_Basalt"
    },
    {
      "x": -17,
      "y": -14,
      "z": -2,
      "name": "Rock_Basalt"
    },
    {
      "x": -17,
      "y": -13,
      "z": -2,
      "name": "Rock_Basalt"
    },
    {
      "x": -17,
      "y": -12,
      "z": -2,
      "name": "Rock_Basalt"
    },
    {
      "x": -17,
      "y": -11,
      "z": -2,
      "name": "Rock_Basalt"
    },
    {
      "x": -17,
      "y": -10,
      "z": -2,
      "name": "Rock_Basalt"
    },
    {
      "x": -17,
      "y": -9,
      "z": -2,
      "name": "Rock_Basalt"
    },
    {
      "x": -17,
      "y": -8,
      "z": -2,
      "name": "Rock_Basalt"
    },
    {
      "x": -17,
      "y": -7,
      "z": -2,
      "name": "Rock_Basalt"
    },
    {
      "x": -17,
      "y": -6,
      "z": -2,
      "name": "Rock_Shale"
    },
    {
      "x": -17,
      "y": -5,
      "z": -2,
      "name": "Rock_Shale"
    },
    {
      "x": -17,
      "y": -4,
      "z": -2,
      "name": "Rock_Shale"
    },
    {
      "x": -17,
      "y": -3,
      "z": -2,
      "name": "Rock_Shale"
    },
    {
      "x": -17,
      "y": -2,
      "z": -2,
      "name": "Rock_Shale"
    },
    {
      "x": -17,
      "y": -1,
      "z": -2,
      "name": "Rock_Shale"
    },
    {
      "x": -17,
      "y": 0,
      "z": -2,
      "name": "Rock_Shale"
    },
    {
      "x": -17,
      "y": 1,
      "z": -2,
      "name": "Rock_Shale"
    },
    {
      "x": -17,
      "y": 2,
      "z": -2,
      "name": "Soil_Dirt_Cold"
    },
    {
      "x": -17,
      "y": 3,
      "z": -2,
      "name": "Soil_Snow"
    },
    {
      "x": -17,
      "y": 4,
      "z": -2,
      "name": "Soil_Snow_Half"
    },
    {
      "x": -17,
      "y": -22,
      "z": -1,
      "name": "Rock_Basalt"
    },
    {
      "x": -17,
      "y": -21,
      "z": -1,
      "name": "Rock_Basalt"
    },
    {
      "x": -17,
      "y": -20,
      "z": -1,
      "name": "Rock_Basalt"
    },
    {
      "x": -17,
      "y": -19,
      "z": -1,
      "name": "Rock_Basalt"
    },
    {
      "x": -17,
      "y": -18,
      "z": -1,
      "name": "Rock_Basalt"
    },
    {
      "x": -17,
      "y": -17,
      "z": -1,
      "name": "Rock_Basalt"
    },
    {
      "x": -17,
      "y": -16,
      "z": -1,
      "name": "Rock_Basalt"
    },
    {
      "x": -17,
      "y": -15,
      "z": -1,
      "name": "Rock_Basalt"
    },
    {
      "x": -17,
      "y": -14,
      "z": -1,
      "name": "Rock_Basalt"
    },
    {
      "x": -17,
      "y": -13,
      "z": -1,
      "name": "Rock_Basalt"
    },
    {
      "x": -17,
      "y": -12,
      "z": -1,
      "name": "Rock_Basalt"
    },
    {
      "x": -17,
      "y": -11,
      "z": -1,
      "name": "Rock_Basalt"
    },
    {
      "x": -17,
      "y": -10,
      "z": -1,
      "name": "Rock_Basalt"
    },
    {
      "x": -17,
      "y": -9,
      "z": -1,
      "name": "Rock_Basalt"
    },
    {
      "x": -17,
      "y": -8,
      "z": -1,
      "name": "Rock_Basalt"
    },
    {
      "x": -17,
      "y": -7,
      "z": -1,
      "name": "Rock_Basalt"
    },
    {
      "x": -17,
      "y": -6,
      "z": -1,
      "name": "Rock_Shale"
    },
    {
      "x": -17,
      "y": -5,
      "z": -1,
      "name": "Rock_Shale"
    },
    {
      "x": -17,
      "y": -4,
      "z": -1,
      "name": "Rock_Shale"
    },
    {
      "x": -17,
      "y": -3,
      "z": -1,
      "name": "Rock_Shale"
    },
    {
      "x": -17,
      "y": -2,
      "z": -1,
      "name": "Rock_Shale"
    },
    {
      "x": -17,
      "y": -1,
      "z": -1,
      "name": "Rock_Shale"
    },
    {
      "x": -17,
      "y": 0,
      "z": -1,
      "name": "Rock_Shale"
    },
    {
      "x": -17,
      "y": 1,
      "z": -1,
      "name": "Rock_Shale"
    },
    {
      "x": -17,
      "y": 2,
      "z": -1,
      "name": "Soil_Dirt_Cold"
    },
    {
      "x": -17,
      "y": 3,
      "z": -1,
      "name": "Soil_Snow"
    },
    {
      "x": -17,
      "y": -22,
      "z": 0,
      "name": "Rock_Basalt"
    },
    {
      "x": -17,
      "y": -21,
      "z": 0,
      "name": "Rock_Basalt"
    },
    {
      "x": -17,
      "y": -20,
      "z": 0,
      "name": "Rock_Basalt"
    },
    {
      "x": -17,
      "y": -19,
      "z": 0,
      "name": "Rock_Basalt"
    },
    {
      "x": -17,
      "y": -18,
      "z": 0,
      "name": "Rock_Basalt"
    },
    {
      "x": -17,
      "y": -17,
      "z": 0,
      "name": "Rock_Basalt"
    },
    {
      "x": -17,
      "y": -16,
      "z": 0,
      "name": "Rock_Basalt"
    },
    {
      "x": -17,
      "y": -15,
      "z": 0,
      "name": "Rock_Basalt"
    },
    {
      "x": -17,
      "y": -14,
      "z": 0,
      "name": "Rock_Basalt"
    },
    {
      "x": -17,
      "y": -13,
      "z": 0,
      "name": "Rock_Basalt"
    },
    {
      "x": -17,
      "y": -12,
      "z": 0,
      "name": "Rock_Basalt"
    },
    {
      "x": -17,
      "y": -11,
      "z": 0,
      "name": "Rock_Basalt"
    },
    {
      "x": -17,
      "y": -10,
      "z": 0,
      "name": "Rock_Basalt"
    },
    {
      "x": -17,
      "y": -9,
      "z": 0,
      "name": "Rock_Basalt"
    },
    {
      "x": -17,
      "y": -8,
      "z": 0,
      "name": "Rock_Basalt"
    },
    {
      "x": -17,
      "y": -7,
      "z": 0,
      "name": "Soil_Dirt_Cold"
    },
    {
      "x": -17,
      "y": -6,
      "z": 0,
      "name": "Soil_Dirt_Cold"
    },
    {
      "x": -17,
      "y": -2,
      "z": 0,
      "name": "Rock_Shale"
    },
    {
      "x": -17,
      "y": -1,
      "z": 0,
      "name": "Rock_Shale"
    },
    {
      "x": -17,
      "y": 0,
      "z": 0,
      "name": "Rock_Shale"
    },
    {
      "x": -17,
      "y": 1,
      "z": 0,
      "name": "Rock_Shale"
    },
    {
      "x": -17,
      "y": 2,
      "z": 0,
      "name": "Rock_Shale"
    },
    {
      "x": -17,
      "y": 3,
      "z": 0,
      "name": "Rock_Shale_Brick_Smooth"
    },
    {
      "x": -17,
      "y": 4,
      "z": 0,
      "name": "Rock_Shale_Brick_Smooth"
    },
    {
      "x": -17,
      "y": 5,
      "z": 0,
      "name": "Rock_Shale_Brick_Smooth_Half",
      "rotation": 7
    },
    {
      "x": -17,
      "y": -22,
      "z": 1,
      "name": "Rock_Basalt"
    },
    {
      "x": -17,
      "y": -21,
      "z": 1,
      "name": "Rock_Basalt"
    },
    {
      "x": -17,
      "y": -20,
      "z": 1,
      "name": "Rock_Basalt"
    },
    {
      "x": -17,
      "y": -19,
      "z": 1,
      "name": "Rock_Basalt"
    },
    {
      "x": -17,
      "y": -18,
      "z": 1,
      "name": "Rock_Basalt"
    },
    {
      "x": -17,
      "y": -17,
      "z": 1,
      "name": "Rock_Basalt"
    },
    {
      "x": -17,
      "y": -16,
      "z": 1,
      "name": "Rock_Basalt"
    },
    {
      "x": -17,
      "y": -15,
      "z": 1,
      "name": "Rock_Basalt"
    },
    {
      "x": -17,
      "y": -14,
      "z": 1,
      "name": "Rock_Basalt"
    },
    {
      "x": -17,
      "y": -13,
      "z": 1,
      "name": "Rock_Basalt"
    },
    {
      "x": -17,
      "y": -12,
      "z": 1,
      "name": "Rock_Basalt"
    },
    {
      "x": -17,
      "y": -11,
      "z": 1,
      "name": "Rock_Basalt"
    },
    {
      "x": -17,
      "y": -10,
      "z": 1,
      "name": "Rock_Basalt"
    },
    {
      "x": -17,
      "y": -9,
      "z": 1,
      "name": "Rock_Basalt"
    },
    {
      "x": -17,
      "y": -8,
      "z": 1,
      "name": "Rock_Basalt"
    },
    {
      "x": -17,
      "y": -7,
      "z": 1,
      "name": "Soil_Dirt_Cold"
    },
    {
      "x": -17,
      "y": -6,
      "z": 1,
      "name": "Soil_Dirt_Cold"
    },
    {
      "x": -17,
      "y": -2,
      "z": 1,
      "name": "Rock_Shale"
    },
    {
      "x": -17,
      "y": -1,
      "z": 1,
      "name": "Rock_Shale"
    },
    {
      "x": -17,
      "y": 0,
      "z": 1,
      "name": "Rock_Shale"
    },
    {
      "x": -17,
      "y": 1,
      "z": 1,
      "name": "Rock_Shale"
    },
    {
      "x": -17,
      "y": 2,
      "z": 1,
      "name": "Rock_Shale"
    },
    {
      "x": -17,
      "y": 3,
      "z": 1,
      "name": "Rock_Shale_Brick_Smooth"
    },
    {
      "x": -17,
      "y": 4,
      "z": 1,
      "name": "Rock_Shale_Brick_Smooth"
    },
    {
      "x": -17,
      "y": 5,
      "z": 1,
      "name": "Rock_Shale_Brick_Smooth_Half",
      "rotation": 7
    },
    {
      "x": -17,
      "y": -22,
      "z": 2,
      "name": "Rock_Basalt"
    },
    {
      "x": -17,
      "y": -21,
      "z": 2,
      "name": "Rock_Basalt"
    },
    {
      "x": -17,
      "y": -20,
      "z": 2,
      "name": "Rock_Basalt"
    },
    {
      "x": -17,
      "y": -19,
      "z": 2,
      "name": "Rock_Basalt"
    },
    {
      "x": -17,
      "y": -18,
      "z": 2,
      "name": "Rock_Basalt"
    },
    {
      "x": -17,
      "y": -17,
      "z": 2,
      "name": "Rock_Basalt"
    },
    {
      "x": -17,
      "y": -16,
      "z": 2,
      "name": "Rock_Basalt"
    },
    {
      "x": -17,
      "y": -15,
      "z": 2,
      "name": "Rock_Basalt"
    },
    {
      "x": -17,
      "y": -14,
      "z": 2,
      "name": "Rock_Basalt"
    },
    {
      "x": -17,
      "y": -13,
      "z": 2,
      "name": "Rock_Basalt"
    },
    {
      "x": -17,
      "y": -12,
      "z": 2,
      "name": "Rock_Basalt"
    },
    {
      "x": -17,
      "y": -11,
      "z": 2,
      "name": "Rock_Basalt"
    },
    {
      "x": -17,
      "y": -10,
      "z": 2,
      "name": "Rock_Basalt"
    },
    {
      "x": -17,
      "y": -9,
      "z": 2,
      "name": "Rock_Basalt"
    },
    {
      "x": -17,
      "y": -8,
      "z": 2,
      "name": "Rock_Basalt"
    },
    {
      "x": -17,
      "y": -7,
      "z": 2,
      "name": "Soil_Dirt_Cold"
    },
    {
      "x": -17,
      "y": -6,
      "z": 2,
      "name": "Soil_Dirt_Cold"
    },
    {
      "x": -17,
      "y": -2,
      "z": 2,
      "name": "Rock_Shale"
    },
    {
      "x": -17,
      "y": -1,
      "z": 2,
      "name": "Rock_Shale"
    },
    {
      "x": -17,
      "y": 0,
      "z": 2,
      "name": "Rock_Shale"
    },
    {
      "x": -17,
      "y": 1,
      "z": 2,
      "name": "Rock_Shale"
    },
    {
      "x": -17,
      "y": 2,
      "z": 2,
      "name": "Rock_Shale"
    },
    {
      "x": -17,
      "y": 3,
      "z": 2,
      "name": "Rock_Shale_Brick_Smooth"
    },
    {
      "x": -17,
      "y": 4,
      "z": 2,
      "name": "Rock_Shale_Brick_Smooth"
    },
    {
      "x": -17,
      "y": 5,
      "z": 2,
      "name": "Rock_Shale_Brick_Smooth_Half",
      "rotation": 7
    },
    {
      "x": -17,
      "y": -22,
      "z": 3,
      "name": "Rock_Basalt"
    },
    {
      "x": -17,
      "y": -21,
      "z": 3,
      "name": "Rock_Basalt"
    },
    {
      "x": -17,
      "y": -20,
      "z": 3,
      "name": "Rock_Basalt"
    },
    {
      "x": -17,
      "y": -19,
      "z": 3,
      "name": "Rock_Basalt"
    },
    {
      "x": -17,
      "y": -18,
      "z": 3,
      "name": "Rock_Basalt"
    },
    {
      "x": -17,
      "y": -17,
      "z": 3,
      "name": "Rock_Basalt"
    },
    {
      "x": -17,
      "y": -16,
      "z": 3,
      "name": "Rock_Basalt"
    },
    {
      "x": -17,
      "y": -15,
      "z": 3,
      "name": "Rock_Basalt"
    },
    {
      "x": -17,
      "y": -14,
      "z": 3,
      "name": "Rock_Basalt"
    },
    {
      "x": -17,
      "y": -13,
      "z": 3,
      "name": "Rock_Basalt"
    },
    {
      "x": -17,
      "y": -12,
      "z": 3,
      "name": "Rock_Basalt"
    },
    {
      "x": -17,
      "y": -11,
      "z": 3,
      "name": "Rock_Basalt"
    },
    {
      "x": -17,
      "y": -10,
      "z": 3,
      "name": "Rock_Basalt"
    },
    {
      "x": -17,
      "y": -9,
      "z": 3,
      "name": "Rock_Basalt"
    },
    {
      "x": -17,
      "y": -8,
      "z": 3,
      "name": "Rock_Basalt"
    },
    {
      "x": -17,
      "y": -7,
      "z": 3,
      "name": "Soil_Dirt_Cold"
    },
    {
      "x": -17,
      "y": -6,
      "z": 3,
      "name": "Soil_Dirt_Cold"
    },
    {
      "x": -17,
      "y": -22,
      "z": 4,
      "name": "Rock_Basalt"
    },
    {
      "x": -17,
      "y": -21,
      "z": 4,
      "name": "Rock_Basalt"
    },
    {
      "x": -17,
      "y": -20,
      "z": 4,
      "name": "Rock_Basalt"
    },
    {
      "x": -17,
      "y": -19,
      "z": 4,
      "name": "Rock_Basalt"
    },
    {
      "x": -17,
      "y": -18,
      "z": 4,
      "name": "Rock_Basalt"
    },
    {
      "x": -17,
      "y": -17,
      "z": 4,
      "name": "Rock_Basalt"
    },
    {
      "x": -17,
      "y": -16,
      "z": 4,
      "name": "Rock_Basalt"
    },
    {
      "x": -17,
      "y": -15,
      "z": 4,
      "name": "Rock_Basalt"
    },
    {
      "x": -17,
      "y": -14,
      "z": 4,
      "name": "Rock_Basalt"
    },
    {
      "x": -17,
      "y": -13,
      "z": 4,
      "name": "Rock_Basalt"
    },
    {
      "x": -17,
      "y": -12,
      "z": 4,
      "name": "Rock_Basalt"
    },
    {
      "x": -17,
      "y": -11,
      "z": 4,
      "name": "Rock_Basalt"
    },
    {
      "x": -17,
      "y": -10,
      "z": 4,
      "name": "Rock_Basalt"
    },
    {
      "x": -17,
      "y": -9,
      "z": 4,
      "name": "Soil_Dirt_Cold"
    },
    {
      "x": -17,
      "y": -8,
      "z": 4,
      "name": "Soil_Dirt_Cold"
    },
    {
      "x": -16,
      "y": -22,
      "z": -8,
      "name": "Rock_Basalt"
    },
    {
      "x": -16,
      "y": -21,
      "z": -8,
      "name": "Rock_Basalt"
    },
    {
      "x": -16,
      "y": -20,
      "z": -8,
      "name": "Rock_Basalt"
    },
    {
      "x": -16,
      "y": -19,
      "z": -8,
      "name": "Rock_Basalt"
    },
    {
      "x": -16,
      "y": -18,
      "z": -8,
      "name": "Rock_Basalt"
    },
    {
      "x": -16,
      "y": -17,
      "z": -8,
      "name": "Rock_Basalt"
    },
    {
      "x": -16,
      "y": -16,
      "z": -8,
      "name": "Rock_Basalt"
    },
    {
      "x": -16,
      "y": -15,
      "z": -8,
      "name": "Rock_Basalt"
    },
    {
      "x": -16,
      "y": -14,
      "z": -8,
      "name": "Rock_Basalt"
    },
    {
      "x": -16,
      "y": -13,
      "z": -8,
      "name": "Rock_Basalt"
    },
    {
      "x": -16,
      "y": -12,
      "z": -8,
      "name": "Rock_Shale"
    },
    {
      "x": -16,
      "y": -11,
      "z": -8,
      "name": "Rock_Shale"
    },
    {
      "x": -16,
      "y": -10,
      "z": -8,
      "name": "Rock_Shale"
    },
    {
      "x": -16,
      "y": -9,
      "z": -8,
      "name": "Rock_Shale"
    },
    {
      "x": -16,
      "y": -8,
      "z": -8,
      "name": "Rock_Shale"
    },
    {
      "x": -16,
      "y": -7,
      "z": -8,
      "name": "Rock_Shale"
    },
    {
      "x": -16,
      "y": -6,
      "z": -8,
      "name": "Rock_Shale"
    },
    {
      "x": -16,
      "y": -22,
      "z": -7,
      "name": "Rock_Basalt"
    },
    {
      "x": -16,
      "y": -21,
      "z": -7,
      "name": "Rock_Basalt"
    },
    {
      "x": -16,
      "y": -20,
      "z": -7,
      "name": "Rock_Basalt"
    },
    {
      "x": -16,
      "y": -19,
      "z": -7,
      "name": "Rock_Basalt"
    },
    {
      "x": -16,
      "y": -18,
      "z": -7,
      "name": "Rock_Basalt"
    },
    {
      "x": -16,
      "y": -17,
      "z": -7,
      "name": "Rock_Basalt"
    },
    {
      "x": -16,
      "y": -16,
      "z": -7,
      "name": "Rock_Basalt"
    },
    {
      "x": -16,
      "y": -15,
      "z": -7,
      "name": "Rock_Basalt"
    },
    {
      "x": -16,
      "y": -14,
      "z": -7,
      "name": "Rock_Basalt"
    },
    {
      "x": -16,
      "y": -13,
      "z": -7,
      "name": "Rock_Basalt"
    },
    {
      "x": -16,
      "y": -12,
      "z": -7,
      "name": "Rock_Shale"
    },
    {
      "x": -16,
      "y": -11,
      "z": -7,
      "name": "Rock_Shale"
    },
    {
      "x": -16,
      "y": -10,
      "z": -7,
      "name": "Rock_Shale"
    },
    {
      "x": -16,
      "y": -9,
      "z": -7,
      "name": "Rock_Shale"
    },
    {
      "x": -16,
      "y": -8,
      "z": -7,
      "name": "Rock_Shale"
    },
    {
      "x": -16,
      "y": -7,
      "z": -7,
      "name": "Rock_Shale"
    },
    {
      "x": -16,
      "y": -6,
      "z": -7,
      "name": "Rock_Shale"
    },
    {
      "x": -16,
      "y": -5,
      "z": -7,
      "name": "Rock_Shale"
    },
    {
      "x": -16,
      "y": -4,
      "z": -7,
      "name": "Rock_Shale"
    },
    {
      "x": -16,
      "y": -3,
      "z": -7,
      "name": "Rock_Shale"
    },
    {
      "x": -16,
      "y": -2,
      "z": -7,
      "name": "Rock_Shale"
    },
    {
      "x": -16,
      "y": -1,
      "z": -7,
      "name": "Rock_Shale"
    },
    {
      "x": -16,
      "y": 0,
      "z": -7,
      "name": "Rock_Shale"
    },
    {
      "x": -16,
      "y": 1,
      "z": -7,
      "name": "Rock_Shale"
    },
    {
      "x": -16,
      "y": 2,
      "z": -7,
      "name": "Rock_Shale"
    },
    {
      "x": -16,
      "y": 3,
      "z": -7,
      "name": "Rock_Basalt"
    },
    {
      "x": -16,
      "y": 4,
      "z": -7,
      "name": "Soil_Snow"
    },
    {
      "x": -16,
      "y": -22,
      "z": -6,
      "name": "Rock_Basalt"
    },
    {
      "x": -16,
      "y": -21,
      "z": -6,
      "name": "Rock_Basalt"
    },
    {
      "x": -16,
      "y": -20,
      "z": -6,
      "name": "Rock_Basalt"
    },
    {
      "x": -16,
      "y": -19,
      "z": -6,
      "name": "Rock_Basalt"
    },
    {
      "x": -16,
      "y": -18,
      "z": -6,
      "name": "Rock_Basalt"
    },
    {
      "x": -16,
      "y": -17,
      "z": -6,
      "name": "Rock_Basalt"
    },
    {
      "x": -16,
      "y": -16,
      "z": -6,
      "name": "Rock_Basalt"
    },
    {
      "x": -16,
      "y": -15,
      "z": -6,
      "name": "Rock_Basalt"
    },
    {
      "x": -16,
      "y": -14,
      "z": -6,
      "name": "Rock_Basalt"
    },
    {
      "x": -16,
      "y": -13,
      "z": -6,
      "name": "Rock_Basalt"
    },
    {
      "x": -16,
      "y": -12,
      "z": -6,
      "name": "Rock_Basalt"
    },
    {
      "x": -16,
      "y": -11,
      "z": -6,
      "name": "Rock_Shale"
    },
    {
      "x": -16,
      "y": -10,
      "z": -6,
      "name": "Rock_Shale"
    },
    {
      "x": -16,
      "y": -9,
      "z": -6,
      "name": "Rock_Shale"
    },
    {
      "x": -16,
      "y": -8,
      "z": -6,
      "name": "Rock_Shale"
    },
    {
      "x": -16,
      "y": -7,
      "z": -6,
      "name": "Rock_Shale"
    },
    {
      "x": -16,
      "y": -6,
      "z": -6,
      "name": "Rock_Shale"
    },
    {
      "x": -16,
      "y": -5,
      "z": -6,
      "name": "Rock_Shale"
    },
    {
      "x": -16,
      "y": -4,
      "z": -6,
      "name": "Rock_Shale"
    },
    {
      "x": -16,
      "y": -3,
      "z": -6,
      "name": "Rock_Shale"
    },
    {
      "x": -16,
      "y": -2,
      "z": -6,
      "name": "Rock_Shale"
    },
    {
      "x": -16,
      "y": -1,
      "z": -6,
      "name": "Rock_Shale"
    },
    {
      "x": -16,
      "y": 0,
      "z": -6,
      "name": "Rock_Shale"
    },
    {
      "x": -16,
      "y": 1,
      "z": -6,
      "name": "Rock_Shale"
    },
    {
      "x": -16,
      "y": 2,
      "z": -6,
      "name": "Rock_Shale"
    },
    {
      "x": -16,
      "y": 3,
      "z": -6,
      "name": "Rock_Basalt"
    },
    {
      "x": -16,
      "y": 4,
      "z": -6,
      "name": "Rock_Basalt"
    },
    {
      "x": -16,
      "y": 5,
      "z": -6,
      "name": "Soil_Dirt_Cold"
    },
    {
      "x": -16,
      "y": 6,
      "z": -6,
      "name": "Soil_Snow"
    },
    {
      "x": -16,
      "y": -22,
      "z": -5,
      "name": "Rock_Basalt"
    },
    {
      "x": -16,
      "y": -21,
      "z": -5,
      "name": "Rock_Basalt"
    },
    {
      "x": -16,
      "y": -20,
      "z": -5,
      "name": "Rock_Basalt"
    },
    {
      "x": -16,
      "y": -19,
      "z": -5,
      "name": "Rock_Basalt"
    },
    {
      "x": -16,
      "y": -18,
      "z": -5,
      "name": "Rock_Basalt"
    },
    {
      "x": -16,
      "y": -17,
      "z": -5,
      "name": "Rock_Basalt"
    },
    {
      "x": -16,
      "y": -16,
      "z": -5,
      "name": "Rock_Basalt"
    },
    {
      "x": -16,
      "y": -15,
      "z": -5,
      "name": "Rock_Basalt"
    },
    {
      "x": -16,
      "y": -14,
      "z": -5,
      "name": "Rock_Basalt"
    },
    {
      "x": -16,
      "y": -13,
      "z": -5,
      "name": "Rock_Basalt"
    },
    {
      "x": -16,
      "y": -12,
      "z": -5,
      "name": "Rock_Basalt"
    },
    {
      "x": -16,
      "y": -11,
      "z": -5,
      "name": "Rock_Basalt"
    },
    {
      "x": -16,
      "y": -10,
      "z": -5,
      "name": "Rock_Basalt"
    },
    {
      "x": -16,
      "y": -9,
      "z": -5,
      "name": "Rock_Basalt"
    },
    {
      "x": -16,
      "y": -8,
      "z": -5,
      "name": "Rock_Basalt"
    },
    {
      "x": -16,
      "y": -7,
      "z": -5,
      "name": "Rock_Basalt"
    },
    {
      "x": -16,
      "y": -6,
      "z": -5,
      "name": "Rock_Basalt"
    },
    {
      "x": -16,
      "y": -5,
      "z": -5,
      "name": "Rock_Shale"
    },
    {
      "x": -16,
      "y": -4,
      "z": -5,
      "name": "Rock_Shale"
    },
    {
      "x": -16,
      "y": -3,
      "z": -5,
      "name": "Rock_Shale"
    },
    {
      "x": -16,
      "y": -2,
      "z": -5,
      "name": "Rock_Basalt"
    },
    {
      "x": -16,
      "y": -1,
      "z": -5,
      "name": "Rock_Shale"
    },
    {
      "x": -16,
      "y": 0,
      "z": -5,
      "name": "Rock_Shale"
    },
    {
      "x": -16,
      "y": 1,
      "z": -5,
      "name": "Rock_Shale"
    },
    {
      "x": -16,
      "y": 2,
      "z": -5,
      "name": "Rock_Basalt"
    },
    {
      "x": -16,
      "y": 3,
      "z": -5,
      "name": "Rock_Basalt"
    },
    {
      "x": -16,
      "y": 4,
      "z": -5,
      "name": "Rock_Basalt"
    },
    {
      "x": -16,
      "y": 5,
      "z": -5,
      "name": "Soil_Dirt_Cold"
    },
    {
      "x": -16,
      "y": 6,
      "z": -5,
      "name": "Soil_Snow"
    },
    {
      "x": -16,
      "y": 7,
      "z": -5,
      "name": "Plant_Flower_Orchid_Purple"
    },
    {
      "x": -16,
      "y": -22,
      "z": -4,
      "name": "Rock_Basalt"
    },
    {
      "x": -16,
      "y": -21,
      "z": -4,
      "name": "Rock_Basalt"
    },
    {
      "x": -16,
      "y": -20,
      "z": -4,
      "name": "Rock_Basalt"
    },
    {
      "x": -16,
      "y": -19,
      "z": -4,
      "name": "Rock_Basalt"
    },
    {
      "x": -16,
      "y": -18,
      "z": -4,
      "name": "Rock_Basalt"
    },
    {
      "x": -16,
      "y": -17,
      "z": -4,
      "name": "Rock_Basalt"
    },
    {
      "x": -16,
      "y": -16,
      "z": -4,
      "name": "Rock_Basalt"
    },
    {
      "x": -16,
      "y": -15,
      "z": -4,
      "name": "Rock_Basalt"
    },
    {
      "x": -16,
      "y": -14,
      "z": -4,
      "name": "Rock_Basalt"
    },
    {
      "x": -16,
      "y": -13,
      "z": -4,
      "name": "Rock_Basalt"
    },
    {
      "x": -16,
      "y": -12,
      "z": -4,
      "name": "Rock_Basalt"
    },
    {
      "x": -16,
      "y": -11,
      "z": -4,
      "name": "Rock_Basalt"
    },
    {
      "x": -16,
      "y": -10,
      "z": -4,
      "name": "Rock_Basalt"
    },
    {
      "x": -16,
      "y": -9,
      "z": -4,
      "name": "Rock_Basalt"
    },
    {
      "x": -16,
      "y": -8,
      "z": -4,
      "name": "Rock_Basalt"
    },
    {
      "x": -16,
      "y": -7,
      "z": -4,
      "name": "Rock_Basalt"
    },
    {
      "x": -16,
      "y": -6,
      "z": -4,
      "name": "Rock_Basalt"
    },
    {
      "x": -16,
      "y": -5,
      "z": -4,
      "name": "Rock_Basalt"
    },
    {
      "x": -16,
      "y": -4,
      "z": -4,
      "name": "Rock_Basalt"
    },
    {
      "x": -16,
      "y": -3,
      "z": -4,
      "name": "Rock_Basalt"
    },
    {
      "x": -16,
      "y": -2,
      "z": -4,
      "name": "Rock_Basalt"
    },
    {
      "x": -16,
      "y": -1,
      "z": -4,
      "name": "Rock_Basalt"
    },
    {
      "x": -16,
      "y": 0,
      "z": -4,
      "name": "Rock_Shale"
    },
    {
      "x": -16,
      "y": 1,
      "z": -4,
      "name": "Rock_Basalt"
    },
    {
      "x": -16,
      "y": 2,
      "z": -4,
      "name": "Rock_Basalt"
    },
    {
      "x": -16,
      "y": 3,
      "z": -4,
      "name": "Rock_Basalt"
    },
    {
      "x": -16,
      "y": 4,
      "z": -4,
      "name": "Rock_Basalt"
    },
    {
      "x": -16,
      "y": 5,
      "z": -4,
      "name": "Soil_Dirt_Cold"
    },
    {
      "x": -16,
      "y": 6,
      "z": -4,
      "name": "Soil_Snow"
    },
    {
      "x": -16,
      "y": 7,
      "z": -4,
      "name": "Plant_Grass_Snowy_Short"
    },
    {
      "x": -16,
      "y": -22,
      "z": -3,
      "name": "Rock_Basalt"
    },
    {
      "x": -16,
      "y": -21,
      "z": -3,
      "name": "Rock_Basalt"
    },
    {
      "x": -16,
      "y": -20,
      "z": -3,
      "name": "Rock_Basalt"
    },
    {
      "x": -16,
      "y": -19,
      "z": -3,
      "name": "Rock_Basalt"
    },
    {
      "x": -16,
      "y": -18,
      "z": -3,
      "name": "Rock_Basalt"
    },
    {
      "x": -16,
      "y": -17,
      "z": -3,
      "name": "Rock_Basalt"
    },
    {
      "x": -16,
      "y": -16,
      "z": -3,
      "name": "Rock_Basalt"
    },
    {
      "x": -16,
      "y": -15,
      "z": -3,
      "name": "Rock_Basalt"
    },
    {
      "x": -16,
      "y": -14,
      "z": -3,
      "name": "Rock_Basalt"
    },
    {
      "x": -16,
      "y": -13,
      "z": -3,
      "name": "Rock_Basalt"
    },
    {
      "x": -16,
      "y": -12,
      "z": -3,
      "name": "Rock_Basalt"
    },
    {
      "x": -16,
      "y": -11,
      "z": -3,
      "name": "Rock_Basalt"
    },
    {
      "x": -16,
      "y": -10,
      "z": -3,
      "name": "Rock_Basalt"
    },
    {
      "x": -16,
      "y": -9,
      "z": -3,
      "name": "Rock_Basalt"
    },
    {
      "x": -16,
      "y": -8,
      "z": -3,
      "name": "Rock_Basalt"
    },
    {
      "x": -16,
      "y": -7,
      "z": -3,
      "name": "Rock_Basalt"
    },
    {
      "x": -16,
      "y": -6,
      "z": -3,
      "name": "Rock_Basalt"
    },
    {
      "x": -16,
      "y": -5,
      "z": -3,
      "name": "Rock_Basalt"
    },
    {
      "x": -16,
      "y": -4,
      "z": -3,
      "name": "Rock_Shale"
    },
    {
      "x": -16,
      "y": -3,
      "z": -3,
      "name": "Rock_Basalt"
    },
    {
      "x": -16,
      "y": -2,
      "z": -3,
      "name": "Rock_Basalt"
    },
    {
      "x": -16,
      "y": -1,
      "z": -3,
      "name": "Rock_Shale"
    },
    {
      "x": -16,
      "y": 0,
      "z": -3,
      "name": "Rock_Shale"
    },
    {
      "x": -16,
      "y": 1,
      "z": -3,
      "name": "Rock_Shale"
    },
    {
      "x": -16,
      "y": 2,
      "z": -3,
      "name": "Rock_Basalt"
    },
    {
      "x": -16,
      "y": 3,
      "z": -3,
      "name": "Rock_Basalt"
    },
    {
      "x": -16,
      "y": 4,
      "z": -3,
      "name": "Rock_Basalt"
    },
    {
      "x": -16,
      "y": 5,
      "z": -3,
      "name": "Soil_Dirt_Cold"
    },
    {
      "x": -16,
      "y": 6,
      "z": -3,
      "name": "Soil_Snow"
    },
    {
      "x": -16,
      "y": -22,
      "z": -2,
      "name": "Rock_Basalt"
    },
    {
      "x": -16,
      "y": -21,
      "z": -2,
      "name": "Rock_Basalt"
    },
    {
      "x": -16,
      "y": -20,
      "z": -2,
      "name": "Rock_Basalt"
    },
    {
      "x": -16,
      "y": -19,
      "z": -2,
      "name": "Rock_Basalt"
    },
    {
      "x": -16,
      "y": -18,
      "z": -2,
      "name": "Rock_Basalt"
    },
    {
      "x": -16,
      "y": -17,
      "z": -2,
      "name": "Rock_Basalt"
    },
    {
      "x": -16,
      "y": -16,
      "z": -2,
      "name": "Rock_Basalt"
    },
    {
      "x": -16,
      "y": -15,
      "z": -2,
      "name": "Rock_Basalt"
    },
    {
      "x": -16,
      "y": -14,
      "z": -2,
      "name": "Rock_Basalt"
    },
    {
      "x": -16,
      "y": -13,
      "z": -2,
      "name": "Rock_Basalt"
    },
    {
      "x": -16,
      "y": -12,
      "z": -2,
      "name": "Rock_Basalt"
    },
    {
      "x": -16,
      "y": -11,
      "z": -2,
      "name": "Rock_Basalt"
    },
    {
      "x": -16,
      "y": -10,
      "z": -2,
      "name": "Rock_Basalt"
    },
    {
      "x": -16,
      "y": -9,
      "z": -2,
      "name": "Rock_Basalt"
    },
    {
      "x": -16,
      "y": -8,
      "z": -2,
      "name": "Rock_Basalt"
    },
    {
      "x": -16,
      "y": -7,
      "z": -2,
      "name": "Rock_Basalt"
    },
    {
      "x": -16,
      "y": -6,
      "z": -2,
      "name": "Rock_Basalt"
    },
    {
      "x": -16,
      "y": -5,
      "z": -2,
      "name": "Rock_Shale"
    },
    {
      "x": -16,
      "y": -4,
      "z": -2,
      "name": "Rock_Shale"
    },
    {
      "x": -16,
      "y": -3,
      "z": -2,
      "name": "Rock_Shale"
    },
    {
      "x": -16,
      "y": -2,
      "z": -2,
      "name": "Rock_Shale"
    },
    {
      "x": -16,
      "y": -1,
      "z": -2,
      "name": "Rock_Shale"
    },
    {
      "x": -16,
      "y": 0,
      "z": -2,
      "name": "Rock_Shale"
    },
    {
      "x": -16,
      "y": 1,
      "z": -2,
      "name": "Rock_Shale"
    },
    {
      "x": -16,
      "y": 2,
      "z": -2,
      "name": "Soil_Dirt_Cold"
    },
    {
      "x": -16,
      "y": 3,
      "z": -2,
      "name": "Soil_Snow"
    },
    {
      "x": -16,
      "y": 4,
      "z": -2,
      "name": "Soil_Snow_Half"
    },
    {
      "x": -16,
      "y": -22,
      "z": -1,
      "name": "Rock_Basalt"
    },
    {
      "x": -16,
      "y": -21,
      "z": -1,
      "name": "Rock_Basalt"
    },
    {
      "x": -16,
      "y": -20,
      "z": -1,
      "name": "Rock_Basalt"
    },
    {
      "x": -16,
      "y": -19,
      "z": -1,
      "name": "Rock_Basalt"
    },
    {
      "x": -16,
      "y": -18,
      "z": -1,
      "name": "Rock_Basalt"
    },
    {
      "x": -16,
      "y": -17,
      "z": -1,
      "name": "Rock_Basalt"
    },
    {
      "x": -16,
      "y": -16,
      "z": -1,
      "name": "Rock_Basalt"
    },
    {
      "x": -16,
      "y": -15,
      "z": -1,
      "name": "Rock_Basalt"
    },
    {
      "x": -16,
      "y": -14,
      "z": -1,
      "name": "Rock_Basalt"
    },
    {
      "x": -16,
      "y": -13,
      "z": -1,
      "name": "Rock_Basalt"
    },
    {
      "x": -16,
      "y": -12,
      "z": -1,
      "name": "Rock_Basalt"
    },
    {
      "x": -16,
      "y": -11,
      "z": -1,
      "name": "Rock_Basalt"
    },
    {
      "x": -16,
      "y": -10,
      "z": -1,
      "name": "Rock_Basalt"
    },
    {
      "x": -16,
      "y": -9,
      "z": -1,
      "name": "Rock_Basalt"
    },
    {
      "x": -16,
      "y": -8,
      "z": -1,
      "name": "Rock_Basalt"
    },
    {
      "x": -16,
      "y": -7,
      "z": -1,
      "name": "Rock_Basalt"
    },
    {
      "x": -16,
      "y": -6,
      "z": -1,
      "name": "Rock_Shale"
    },
    {
      "x": -16,
      "y": -5,
      "z": -1,
      "name": "Rock_Shale"
    },
    {
      "x": -16,
      "y": -4,
      "z": -1,
      "name": "Rock_Shale"
    },
    {
      "x": -16,
      "y": -3,
      "z": -1,
      "name": "Rock_Shale"
    },
    {
      "x": -16,
      "y": -2,
      "z": -1,
      "name": "Rock_Shale"
    },
    {
      "x": -16,
      "y": -1,
      "z": -1,
      "name": "Rock_Shale"
    },
    {
      "x": -16,
      "y": 0,
      "z": -1,
      "name": "Rock_Shale"
    },
    {
      "x": -16,
      "y": 1,
      "z": -1,
      "name": "Rock_Shale"
    },
    {
      "x": -16,
      "y": 2,
      "z": -1,
      "name": "Soil_Dirt_Cold"
    },
    {
      "x": -16,
      "y": 3,
      "z": -1,
      "name": "Soil_Snow"
    },
    {
      "x": -16,
      "y": 4,
      "z": -1,
      "name": "Soil_Snow_Half"
    },
    {
      "x": -16,
      "y": -22,
      "z": 0,
      "name": "Rock_Basalt"
    },
    {
      "x": -16,
      "y": -21,
      "z": 0,
      "name": "Rock_Basalt"
    },
    {
      "x": -16,
      "y": -20,
      "z": 0,
      "name": "Rock_Basalt"
    },
    {
      "x": -16,
      "y": -19,
      "z": 0,
      "name": "Rock_Basalt"
    },
    {
      "x": -16,
      "y": -18,
      "z": 0,
      "name": "Rock_Basalt"
    },
    {
      "x": -16,
      "y": -17,
      "z": 0,
      "name": "Rock_Basalt"
    },
    {
      "x": -16,
      "y": -16,
      "z": 0,
      "name": "Rock_Basalt"
    },
    {
      "x": -16,
      "y": -15,
      "z": 0,
      "name": "Rock_Basalt"
    },
    {
      "x": -16,
      "y": -14,
      "z": 0,
      "name": "Rock_Basalt"
    },
    {
      "x": -16,
      "y": -13,
      "z": 0,
      "name": "Rock_Basalt"
    },
    {
      "x": -16,
      "y": -12,
      "z": 0,
      "name": "Rock_Basalt"
    },
    {
      "x": -16,
      "y": -11,
      "z": 0,
      "name": "Rock_Basalt"
    },
    {
      "x": -16,
      "y": -10,
      "z": 0,
      "name": "Rock_Basalt"
    },
    {
      "x": -16,
      "y": -9,
      "z": 0,
      "name": "Rock_Basalt"
    },
    {
      "x": -16,
      "y": -8,
      "z": 0,
      "name": "Rock_Basalt"
    },
    {
      "x": -16,
      "y": -7,
      "z": 0,
      "name": "Rock_Basalt"
    },
    {
      "x": -16,
      "y": -6,
      "z": 0,
      "name": "Rock_Basalt"
    },
    {
      "x": -16,
      "y": -5,
      "z": 0,
      "name": "Rock_Shale"
    },
    {
      "x": -16,
      "y": -4,
      "z": 0,
      "name": "Rock_Shale"
    },
    {
      "x": -16,
      "y": -3,
      "z": 0,
      "name": "Rock_Shale"
    },
    {
      "x": -16,
      "y": -2,
      "z": 0,
      "name": "Rock_Shale"
    },
    {
      "x": -16,
      "y": -1,
      "z": 0,
      "name": "Rock_Shale"
    },
    {
      "x": -16,
      "y": 0,
      "z": 0,
      "name": "Rock_Shale"
    },
    {
      "x": -16,
      "y": 1,
      "z": 0,
      "name": "Rock_Shale"
    },
    {
      "x": -16,
      "y": 2,
      "z": 0,
      "name": "Rock_Shale"
    },
    {
      "x": -16,
      "y": 3,
      "z": 0,
      "name": "Rock_Basalt"
    },
    {
      "x": -16,
      "y": 4,
      "z": 0,
      "name": "Rock_Shale_Brick"
    },
    {
      "x": -16,
      "y": 5,
      "z": 0,
      "name": "Rock_Shale_Brick"
    },
    {
      "x": -16,
      "y": 6,
      "z": 0,
      "name": "Rock_Shale_Brick_Smooth"
    },
    {
      "x": -16,
      "y": 7,
      "z": 0,
      "name": "Rock_Shale_Brick_Smooth_Half",
      "rotation": 7
    },
    {
      "x": -16,
      "y": -22,
      "z": 1,
      "name": "Rock_Basalt"
    },
    {
      "x": -16,
      "y": -21,
      "z": 1,
      "name": "Rock_Basalt"
    },
    {
      "x": -16,
      "y": -20,
      "z": 1,
      "name": "Rock_Basalt"
    },
    {
      "x": -16,
      "y": -19,
      "z": 1,
      "name": "Rock_Basalt"
    },
    {
      "x": -16,
      "y": -18,
      "z": 1,
      "name": "Rock_Basalt"
    },
    {
      "x": -16,
      "y": -17,
      "z": 1,
      "name": "Rock_Basalt"
    },
    {
      "x": -16,
      "y": -16,
      "z": 1,
      "name": "Rock_Basalt"
    },
    {
      "x": -16,
      "y": -15,
      "z": 1,
      "name": "Rock_Basalt"
    },
    {
      "x": -16,
      "y": -14,
      "z": 1,
      "name": "Rock_Basalt"
    },
    {
      "x": -16,
      "y": -13,
      "z": 1,
      "name": "Rock_Basalt"
    },
    {
      "x": -16,
      "y": -12,
      "z": 1,
      "name": "Rock_Basalt"
    },
    {
      "x": -16,
      "y": -11,
      "z": 1,
      "name": "Rock_Basalt"
    },
    {
      "x": -16,
      "y": -10,
      "z": 1,
      "name": "Rock_Basalt"
    },
    {
      "x": -16,
      "y": -9,
      "z": 1,
      "name": "Rock_Basalt"
    },
    {
      "x": -16,
      "y": -8,
      "z": 1,
      "name": "Rock_Basalt"
    },
    {
      "x": -16,
      "y": -7,
      "z": 1,
      "name": "Rock_Basalt"
    },
    {
      "x": -16,
      "y": -6,
      "z": 1,
      "name": "Rock_Basalt"
    },
    {
      "x": -16,
      "y": -5,
      "z": 1,
      "name": "Rock_Shale"
    },
    {
      "x": -16,
      "y": -4,
      "z": 1,
      "name": "Rock_Shale"
    },
    {
      "x": -16,
      "y": -3,
      "z": 1,
      "name": "Rock_Shale"
    },
    {
      "x": -16,
      "y": -2,
      "z": 1,
      "name": "Rock_Shale"
    },
    {
      "x": -16,
      "y": -1,
      "z": 1,
      "name": "Rock_Shale"
    },
    {
      "x": -16,
      "y": 0,
      "z": 1,
      "name": "Rock_Shale"
    },
    {
      "x": -16,
      "y": 1,
      "z": 1,
      "name": "Rock_Shale"
    },
    {
      "x": -16,
      "y": 2,
      "z": 1,
      "name": "Rock_Shale"
    },
    {
      "x": -16,
      "y": 3,
      "z": 1,
      "name": "Rock_Shale_Brick"
    },
    {
      "x": -16,
      "y": 4,
      "z": 1,
      "name": "Rock_Shale_Brick"
    },
    {
      "x": -16,
      "y": 5,
      "z": 1,
      "name": "Rock_Shale_Brick"
    },
    {
      "x": -16,
      "y": 6,
      "z": 1,
      "name": "Rock_Shale_Brick_Smooth"
    },
    {
      "x": -16,
      "y": 7,
      "z": 1,
      "name": "Rock_Shale_Brick_Smooth_Half",
      "rotation": 7
    },
    {
      "x": -16,
      "y": -22,
      "z": 2,
      "name": "Rock_Basalt"
    },
    {
      "x": -16,
      "y": -21,
      "z": 2,
      "name": "Rock_Basalt"
    },
    {
      "x": -16,
      "y": -20,
      "z": 2,
      "name": "Rock_Basalt"
    },
    {
      "x": -16,
      "y": -19,
      "z": 2,
      "name": "Rock_Basalt"
    },
    {
      "x": -16,
      "y": -18,
      "z": 2,
      "name": "Rock_Basalt"
    },
    {
      "x": -16,
      "y": -17,
      "z": 2,
      "name": "Rock_Basalt"
    },
    {
      "x": -16,
      "y": -16,
      "z": 2,
      "name": "Rock_Basalt"
    },
    {
      "x": -16,
      "y": -15,
      "z": 2,
      "name": "Rock_Basalt"
    },
    {
      "x": -16,
      "y": -14,
      "z": 2,
      "name": "Rock_Basalt"
    },
    {
      "x": -16,
      "y": -13,
      "z": 2,
      "name": "Rock_Basalt"
    },
    {
      "x": -16,
      "y": -12,
      "z": 2,
      "name": "Rock_Basalt"
    },
    {
      "x": -16,
      "y": -11,
      "z": 2,
      "name": "Rock_Basalt"
    },
    {
      "x": -16,
      "y": -10,
      "z": 2,
      "name": "Rock_Basalt"
    },
    {
      "x": -16,
      "y": -9,
      "z": 2,
      "name": "Rock_Basalt"
    },
    {
      "x": -16,
      "y": -8,
      "z": 2,
      "name": "Rock_Basalt"
    },
    {
      "x": -16,
      "y": -7,
      "z": 2,
      "name": "Rock_Basalt"
    },
    {
      "x": -16,
      "y": -6,
      "z": 2,
      "name": "Rock_Basalt"
    },
    {
      "x": -16,
      "y": -5,
      "z": 2,
      "name": "Rock_Shale"
    },
    {
      "x": -16,
      "y": -4,
      "z": 2,
      "name": "Rock_Shale"
    },
    {
      "x": -16,
      "y": -3,
      "z": 2,
      "name": "Rock_Shale"
    },
    {
      "x": -16,
      "y": -2,
      "z": 2,
      "name": "Rock_Shale"
    },
    {
      "x": -16,
      "y": -1,
      "z": 2,
      "name": "Rock_Shale"
    },
    {
      "x": -16,
      "y": 0,
      "z": 2,
      "name": "Rock_Shale"
    },
    {
      "x": -16,
      "y": 1,
      "z": 2,
      "name": "Rock_Shale"
    },
    {
      "x": -16,
      "y": 2,
      "z": 2,
      "name": "Rock_Shale"
    },
    {
      "x": -16,
      "y": 3,
      "z": 2,
      "name": "Rock_Shale_Brick"
    },
    {
      "x": -16,
      "y": 4,
      "z": 2,
      "name": "Rock_Shale_Brick"
    },
    {
      "x": -16,
      "y": 5,
      "z": 2,
      "name": "Rock_Shale_Brick"
    },
    {
      "x": -16,
      "y": 6,
      "z": 2,
      "name": "Rock_Shale_Brick_Smooth"
    },
    {
      "x": -16,
      "y": 7,
      "z": 2,
      "name": "Rock_Shale_Brick_Smooth_Half",
      "rotation": 7
    },
    {
      "x": -16,
      "y": -22,
      "z": 3,
      "name": "Rock_Basalt"
    },
    {
      "x": -16,
      "y": -21,
      "z": 3,
      "name": "Rock_Basalt"
    },
    {
      "x": -16,
      "y": -20,
      "z": 3,
      "name": "Rock_Basalt"
    },
    {
      "x": -16,
      "y": -19,
      "z": 3,
      "name": "Rock_Basalt"
    },
    {
      "x": -16,
      "y": -18,
      "z": 3,
      "name": "Rock_Basalt"
    },
    {
      "x": -16,
      "y": -17,
      "z": 3,
      "name": "Rock_Basalt"
    },
    {
      "x": -16,
      "y": -16,
      "z": 3,
      "name": "Rock_Basalt"
    },
    {
      "x": -16,
      "y": -15,
      "z": 3,
      "name": "Rock_Basalt"
    },
    {
      "x": -16,
      "y": -14,
      "z": 3,
      "name": "Rock_Basalt"
    },
    {
      "x": -16,
      "y": -13,
      "z": 3,
      "name": "Rock_Basalt"
    },
    {
      "x": -16,
      "y": -12,
      "z": 3,
      "name": "Rock_Basalt"
    },
    {
      "x": -16,
      "y": -11,
      "z": 3,
      "name": "Rock_Basalt"
    },
    {
      "x": -16,
      "y": -10,
      "z": 3,
      "name": "Rock_Basalt"
    },
    {
      "x": -16,
      "y": -9,
      "z": 3,
      "name": "Rock_Basalt"
    },
    {
      "x": -16,
      "y": -8,
      "z": 3,
      "name": "Rock_Basalt"
    },
    {
      "x": -16,
      "y": -7,
      "z": 3,
      "name": "Rock_Basalt"
    },
    {
      "x": -16,
      "y": -6,
      "z": 3,
      "name": "Rock_Basalt"
    },
    {
      "x": -16,
      "y": -5,
      "z": 3,
      "name": "Rock_Shale"
    },
    {
      "x": -16,
      "y": -4,
      "z": 3,
      "name": "Rock_Shale"
    },
    {
      "x": -16,
      "y": -3,
      "z": 3,
      "name": "Rock_Shale"
    },
    {
      "x": -16,
      "y": -2,
      "z": 3,
      "name": "Rock_Shale"
    },
    {
      "x": -16,
      "y": -1,
      "z": 3,
      "name": "Rock_Shale"
    },
    {
      "x": -16,
      "y": 0,
      "z": 3,
      "name": "Rock_Shale"
    },
    {
      "x": -16,
      "y": 1,
      "z": 3,
      "name": "Rock_Shale"
    },
    {
      "x": -16,
      "y": 2,
      "z": 3,
      "name": "Rock_Shale"
    },
    {
      "x": -16,
      "y": 3,
      "z": 3,
      "name": "Rock_Shale_Brick"
    },
    {
      "x": -16,
      "y": 4,
      "z": 3,
      "name": "Rock_Shale_Brick"
    },
    {
      "x": -16,
      "y": 5,
      "z": 3,
      "name": "Rock_Shale_Brick"
    },
    {
      "x": -16,
      "y": -22,
      "z": 4,
      "name": "Rock_Basalt"
    },
    {
      "x": -16,
      "y": -21,
      "z": 4,
      "name": "Rock_Basalt"
    },
    {
      "x": -16,
      "y": -20,
      "z": 4,
      "name": "Rock_Basalt"
    },
    {
      "x": -16,
      "y": -19,
      "z": 4,
      "name": "Rock_Basalt"
    },
    {
      "x": -16,
      "y": -18,
      "z": 4,
      "name": "Rock_Basalt"
    },
    {
      "x": -16,
      "y": -17,
      "z": 4,
      "name": "Rock_Basalt"
    },
    {
      "x": -16,
      "y": -16,
      "z": 4,
      "name": "Rock_Basalt"
    },
    {
      "x": -16,
      "y": -15,
      "z": 4,
      "name": "Rock_Basalt"
    },
    {
      "x": -16,
      "y": -14,
      "z": 4,
      "name": "Rock_Basalt"
    },
    {
      "x": -16,
      "y": -13,
      "z": 4,
      "name": "Rock_Basalt"
    },
    {
      "x": -16,
      "y": -12,
      "z": 4,
      "name": "Rock_Basalt"
    },
    {
      "x": -16,
      "y": -11,
      "z": 4,
      "name": "Rock_Basalt"
    },
    {
      "x": -16,
      "y": -10,
      "z": 4,
      "name": "Rock_Basalt"
    },
    {
      "x": -16,
      "y": -9,
      "z": 4,
      "name": "Rock_Basalt"
    },
    {
      "x": -16,
      "y": -8,
      "z": 4,
      "name": "Rock_Basalt"
    },
    {
      "x": -16,
      "y": -7,
      "z": 4,
      "name": "Soil_Dirt_Cold"
    },
    {
      "x": -16,
      "y": -6,
      "z": 4,
      "name": "Soil_Dirt_Cold"
    },
    {
      "x": -16,
      "y": -11,
      "z": 5,
      "name": "Rock_Basalt"
    },
    {
      "x": -16,
      "y": -10,
      "z": 5,
      "name": "Rock_Basalt"
    },
    {
      "x": -16,
      "y": -9,
      "z": 5,
      "name": "Soil_Dirt_Cold"
    },
    {
      "x": -16,
      "y": -8,
      "z": 5,
      "name": "Soil_Dirt_Cold"
    },
    {
      "x": -16,
      "y": -22,
      "z": 8,
      "name": "Rock_Basalt"
    },
    {
      "x": -16,
      "y": -21,
      "z": 8,
      "name": "Rock_Basalt"
    },
    {
      "x": -16,
      "y": -20,
      "z": 8,
      "name": "Rock_Basalt"
    },
    {
      "x": -16,
      "y": -19,
      "z": 8,
      "name": "Rock_Basalt"
    },
    {
      "x": -16,
      "y": -18,
      "z": 8,
      "name": "Rock_Basalt"
    },
    {
      "x": -16,
      "y": -17,
      "z": 8,
      "name": "Rock_Basalt"
    },
    {
      "x": -16,
      "y": -16,
      "z": 8,
      "name": "Rock_Basalt"
    },
    {
      "x": -16,
      "y": -15,
      "z": 8,
      "name": "Rock_Basalt"
    },
    {
      "x": -16,
      "y": -14,
      "z": 8,
      "name": "Rock_Basalt"
    },
    {
      "x": -16,
      "y": -13,
      "z": 8,
      "name": "Rock_Basalt"
    },
    {
      "x": -16,
      "y": -12,
      "z": 8,
      "name": "Rock_Basalt"
    },
    {
      "x": -16,
      "y": -11,
      "z": 8,
      "name": "Rock_Basalt"
    },
    {
      "x": -16,
      "y": -10,
      "z": 8,
      "name": "Rock_Basalt"
    },
    {
      "x": -16,
      "y": -9,
      "z": 8,
      "name": "Rock_Basalt"
    },
    {
      "x": -16,
      "y": -8,
      "z": 8,
      "name": "Rock_Basalt"
    },
    {
      "x": -16,
      "y": -7,
      "z": 8,
      "name": "Rock_Basalt"
    },
    {
      "x": -16,
      "y": -6,
      "z": 8,
      "name": "Rock_Basalt"
    },
    {
      "x": -16,
      "y": -5,
      "z": 8,
      "name": "Rock_Slate"
    },
    {
      "x": -16,
      "y": -4,
      "z": 8,
      "name": "Rock_Slate"
    },
    {
      "x": -16,
      "y": -3,
      "z": 8,
      "name": "Rock_Slate"
    },
    {
      "x": -16,
      "y": -2,
      "z": 8,
      "name": "Rock_Shale"
    },
    {
      "x": -16,
      "y": -1,
      "z": 8,
      "name": "Rock_Shale"
    },
    {
      "x": -16,
      "y": 0,
      "z": 8,
      "name": "Rock_Slate"
    },
    {
      "x": -16,
      "y": 1,
      "z": 8,
      "name": "Rock_Slate"
    },
    {
      "x": -16,
      "y": 2,
      "z": 8,
      "name": "Rock_Slate"
    },
    {
      "x": -16,
      "y": 3,
      "z": 8,
      "name": "Rock_Slate"
    },
    {
      "x": -16,
      "y": 4,
      "z": 8,
      "name": "Rock_Slate"
    },
    {
      "x": -16,
      "y": 5,
      "z": 8,
      "name": "Rock_Slate"
    },
    {
      "x": -16,
      "y": 6,
      "z": 8,
      "name": "Soil_Dirt_Cold"
    },
    {
      "x": -16,
      "y": 7,
      "z": 8,
      "name": "Soil_Dirt_Cold"
    },
    {
      "x": -16,
      "y": 8,
      "z": 8,
      "name": "Soil_Snow"
    },
    {
      "x": -16,
      "y": -22,
      "z": 9,
      "name": "Rock_Basalt"
    },
    {
      "x": -16,
      "y": -21,
      "z": 9,
      "name": "Rock_Basalt"
    },
    {
      "x": -16,
      "y": -20,
      "z": 9,
      "name": "Rock_Basalt"
    },
    {
      "x": -16,
      "y": -19,
      "z": 9,
      "name": "Rock_Basalt"
    },
    {
      "x": -16,
      "y": -18,
      "z": 9,
      "name": "Rock_Basalt"
    },
    {
      "x": -16,
      "y": -17,
      "z": 9,
      "name": "Rock_Basalt"
    },
    {
      "x": -16,
      "y": -16,
      "z": 9,
      "name": "Rock_Basalt"
    },
    {
      "x": -16,
      "y": -15,
      "z": 9,
      "name": "Rock_Basalt"
    },
    {
      "x": -16,
      "y": -14,
      "z": 9,
      "name": "Rock_Basalt"
    },
    {
      "x": -16,
      "y": -13,
      "z": 9,
      "name": "Rock_Basalt"
    },
    {
      "x": -16,
      "y": -12,
      "z": 9,
      "name": "Rock_Basalt"
    },
    {
      "x": -16,
      "y": -11,
      "z": 9,
      "name": "Rock_Basalt"
    },
    {
      "x": -16,
      "y": -10,
      "z": 9,
      "name": "Rock_Basalt"
    },
    {
      "x": -16,
      "y": -9,
      "z": 9,
      "name": "Rock_Basalt"
    },
    {
      "x": -16,
      "y": -8,
      "z": 9,
      "name": "Rock_Basalt"
    },
    {
      "x": -16,
      "y": -7,
      "z": 9,
      "name": "Rock_Basalt"
    },
    {
      "x": -16,
      "y": -6,
      "z": 9,
      "name": "Rock_Slate"
    },
    {
      "x": -16,
      "y": -5,
      "z": 9,
      "name": "Rock_Slate"
    },
    {
      "x": -16,
      "y": -4,
      "z": 9,
      "name": "Rock_Slate"
    },
    {
      "x": -16,
      "y": -3,
      "z": 9,
      "name": "Rock_Shale"
    },
    {
      "x": -16,
      "y": -2,
      "z": 9,
      "name": "Rock_Shale"
    },
    {
      "x": -16,
      "y": -1,
      "z": 9,
      "name": "Rock_Shale"
    },
    {
      "x": -16,
      "y": 0,
      "z": 9,
      "name": "Rock_Slate"
    },
    {
      "x": -16,
      "y": 1,
      "z": 9,
      "name": "Rock_Slate"
    },
    {
      "x": -16,
      "y": 2,
      "z": 9,
      "name": "Rock_Slate"
    },
    {
      "x": -16,
      "y": 3,
      "z": 9,
      "name": "Rock_Slate"
    },
    {
      "x": -16,
      "y": 4,
      "z": 9,
      "name": "Rock_Slate"
    },
    {
      "x": -16,
      "y": 5,
      "z": 9,
      "name": "Rock_Slate"
    },
    {
      "x": -16,
      "y": 6,
      "z": 9,
      "name": "Rock_Slate"
    },
    {
      "x": -16,
      "y": 7,
      "z": 9,
      "name": "Soil_Snow"
    },
    {
      "x": -16,
      "y": 8,
      "z": 9,
      "name": "Soil_Snow_Half"
    },
    {
      "x": -15,
      "y": -22,
      "z": -9,
      "name": "Rock_Basalt"
    },
    {
      "x": -15,
      "y": -21,
      "z": -9,
      "name": "Rock_Basalt"
    },
    {
      "x": -15,
      "y": -20,
      "z": -9,
      "name": "Rock_Basalt"
    },
    {
      "x": -15,
      "y": -19,
      "z": -9,
      "name": "Rock_Basalt"
    },
    {
      "x": -15,
      "y": -18,
      "z": -9,
      "name": "Rock_Basalt"
    },
    {
      "x": -15,
      "y": -17,
      "z": -9,
      "name": "Rock_Basalt"
    },
    {
      "x": -15,
      "y": -16,
      "z": -9,
      "name": "Rock_Basalt"
    },
    {
      "x": -15,
      "y": -15,
      "z": -9,
      "name": "Rock_Basalt"
    },
    {
      "x": -15,
      "y": -14,
      "z": -9,
      "name": "Rock_Basalt"
    },
    {
      "x": -15,
      "y": -13,
      "z": -9,
      "name": "Rock_Basalt"
    },
    {
      "x": -15,
      "y": -12,
      "z": -9,
      "name": "Rock_Basalt"
    },
    {
      "x": -15,
      "y": -11,
      "z": -9,
      "name": "Rock_Shale"
    },
    {
      "x": -15,
      "y": -10,
      "z": -9,
      "name": "Rock_Shale"
    },
    {
      "x": -15,
      "y": -9,
      "z": -9,
      "name": "Rock_Shale"
    },
    {
      "x": -15,
      "y": -8,
      "z": -9,
      "name": "Rock_Shale"
    },
    {
      "x": -15,
      "y": -7,
      "z": -9,
      "name": "Rock_Shale"
    },
    {
      "x": -15,
      "y": -6,
      "z": -9,
      "name": "Rock_Shale"
    },
    {
      "x": -15,
      "y": -5,
      "z": -9,
      "name": "Rock_Shale"
    },
    {
      "x": -15,
      "y": -4,
      "z": -9,
      "name": "Rock_Shale"
    },
    {
      "x": -15,
      "y": -22,
      "z": -8,
      "name": "Rock_Basalt"
    },
    {
      "x": -15,
      "y": -21,
      "z": -8,
      "name": "Rock_Basalt"
    },
    {
      "x": -15,
      "y": -20,
      "z": -8,
      "name": "Rock_Basalt"
    },
    {
      "x": -15,
      "y": -19,
      "z": -8,
      "name": "Rock_Basalt"
    },
    {
      "x": -15,
      "y": -18,
      "z": -8,
      "name": "Rock_Basalt"
    },
    {
      "x": -15,
      "y": -17,
      "z": -8,
      "name": "Rock_Basalt"
    },
    {
      "x": -15,
      "y": -16,
      "z": -8,
      "name": "Rock_Basalt"
    },
    {
      "x": -15,
      "y": -15,
      "z": -8,
      "name": "Rock_Basalt"
    },
    {
      "x": -15,
      "y": -14,
      "z": -8,
      "name": "Rock_Basalt"
    },
    {
      "x": -15,
      "y": -13,
      "z": -8,
      "name": "Rock_Basalt"
    },
    {
      "x": -15,
      "y": -12,
      "z": -8,
      "name": "Rock_Shale"
    },
    {
      "x": -15,
      "y": -11,
      "z": -8,
      "name": "Rock_Shale"
    },
    {
      "x": -15,
      "y": -10,
      "z": -8,
      "name": "Rock_Shale"
    },
    {
      "x": -15,
      "y": -9,
      "z": -8,
      "name": "Rock_Shale"
    },
    {
      "x": -15,
      "y": -8,
      "z": -8,
      "name": "Rock_Shale"
    },
    {
      "x": -15,
      "y": -7,
      "z": -8,
      "name": "Rock_Shale"
    },
    {
      "x": -15,
      "y": -6,
      "z": -8,
      "name": "Rock_Shale"
    },
    {
      "x": -15,
      "y": -5,
      "z": -8,
      "name": "Rock_Shale"
    },
    {
      "x": -15,
      "y": -4,
      "z": -8,
      "name": "Rock_Shale"
    },
    {
      "x": -15,
      "y": -3,
      "z": -8,
      "name": "Rock_Shale"
    },
    {
      "x": -15,
      "y": -2,
      "z": -8,
      "name": "Rock_Shale"
    },
    {
      "x": -15,
      "y": -1,
      "z": -8,
      "name": "Rock_Shale"
    },
    {
      "x": -15,
      "y": 0,
      "z": -8,
      "name": "Rock_Shale"
    },
    {
      "x": -15,
      "y": 1,
      "z": -8,
      "name": "Rock_Shale"
    },
    {
      "x": -15,
      "y": 2,
      "z": -8,
      "name": "Rock_Basalt"
    },
    {
      "x": -15,
      "y": 3,
      "z": -8,
      "name": "Rock_Basalt"
    },
    {
      "x": -15,
      "y": 4,
      "z": -8,
      "name": "Soil_Snow"
    },
    {
      "x": -15,
      "y": -22,
      "z": -7,
      "name": "Rock_Basalt"
    },
    {
      "x": -15,
      "y": -21,
      "z": -7,
      "name": "Rock_Basalt"
    },
    {
      "x": -15,
      "y": -20,
      "z": -7,
      "name": "Rock_Basalt"
    },
    {
      "x": -15,
      "y": -19,
      "z": -7,
      "name": "Rock_Basalt"
    },
    {
      "x": -15,
      "y": -18,
      "z": -7,
      "name": "Rock_Basalt"
    },
    {
      "x": -15,
      "y": -17,
      "z": -7,
      "name": "Rock_Basalt"
    },
    {
      "x": -15,
      "y": -16,
      "z": -7,
      "name": "Rock_Basalt"
    },
    {
      "x": -15,
      "y": -15,
      "z": -7,
      "name": "Rock_Basalt"
    },
    {
      "x": -15,
      "y": -14,
      "z": -7,
      "name": "Rock_Basalt"
    },
    {
      "x": -15,
      "y": -13,
      "z": -7,
      "name": "Rock_Basalt"
    },
    {
      "x": -15,
      "y": -12,
      "z": -7,
      "name": "Rock_Basalt"
    },
    {
      "x": -15,
      "y": -11,
      "z": -7,
      "name": "Rock_Shale"
    },
    {
      "x": -15,
      "y": -10,
      "z": -7,
      "name": "Rock_Shale"
    },
    {
      "x": -15,
      "y": -9,
      "z": -7,
      "name": "Rock_Shale"
    },
    {
      "x": -15,
      "y": -8,
      "z": -7,
      "name": "Rock_Shale"
    },
    {
      "x": -15,
      "y": -7,
      "z": -7,
      "name": "Rock_Shale"
    },
    {
      "x": -15,
      "y": -6,
      "z": -7,
      "name": "Rock_Shale"
    },
    {
      "x": -15,
      "y": -5,
      "z": -7,
      "name": "Rock_Shale"
    },
    {
      "x": -15,
      "y": -4,
      "z": -7,
      "name": "Rock_Shale"
    },
    {
      "x": -15,
      "y": -3,
      "z": -7,
      "name": "Rock_Shale"
    },
    {
      "x": -15,
      "y": -2,
      "z": -7,
      "name": "Rock_Shale"
    },
    {
      "x": -15,
      "y": -1,
      "z": -7,
      "name": "Rock_Shale"
    },
    {
      "x": -15,
      "y": 0,
      "z": -7,
      "name": "Rock_Shale"
    },
    {
      "x": -15,
      "y": 1,
      "z": -7,
      "name": "Rock_Shale"
    },
    {
      "x": -15,
      "y": 2,
      "z": -7,
      "name": "Rock_Shale"
    },
    {
      "x": -15,
      "y": 3,
      "z": -7,
      "name": "Rock_Basalt"
    },
    {
      "x": -15,
      "y": 4,
      "z": -7,
      "name": "Soil_Dirt_Cold"
    },
    {
      "x": -15,
      "y": 5,
      "z": -7,
      "name": "Soil_Snow"
    },
    {
      "x": -15,
      "y": -22,
      "z": -6,
      "name": "Rock_Basalt"
    },
    {
      "x": -15,
      "y": -21,
      "z": -6,
      "name": "Rock_Basalt"
    },
    {
      "x": -15,
      "y": -20,
      "z": -6,
      "name": "Rock_Basalt"
    },
    {
      "x": -15,
      "y": -19,
      "z": -6,
      "name": "Rock_Basalt"
    },
    {
      "x": -15,
      "y": -18,
      "z": -6,
      "name": "Rock_Basalt"
    },
    {
      "x": -15,
      "y": -17,
      "z": -6,
      "name": "Rock_Basalt"
    },
    {
      "x": -15,
      "y": -16,
      "z": -6,
      "name": "Rock_Basalt"
    },
    {
      "x": -15,
      "y": -15,
      "z": -6,
      "name": "Rock_Basalt"
    },
    {
      "x": -15,
      "y": -14,
      "z": -6,
      "name": "Rock_Basalt"
    },
    {
      "x": -15,
      "y": -13,
      "z": -6,
      "name": "Rock_Basalt"
    },
    {
      "x": -15,
      "y": -12,
      "z": -6,
      "name": "Rock_Basalt"
    },
    {
      "x": -15,
      "y": -11,
      "z": -6,
      "name": "Rock_Basalt"
    },
    {
      "x": -15,
      "y": -10,
      "z": -6,
      "name": "Rock_Shale"
    },
    {
      "x": -15,
      "y": -9,
      "z": -6,
      "name": "Rock_Basalt"
    },
    {
      "x": -15,
      "y": -8,
      "z": -6,
      "name": "Rock_Basalt"
    },
    {
      "x": -15,
      "y": -7,
      "z": -6,
      "name": "Rock_Shale"
    },
    {
      "x": -15,
      "y": -6,
      "z": -6,
      "name": "Rock_Basalt"
    },
    {
      "x": -15,
      "y": -5,
      "z": -6,
      "name": "Rock_Shale"
    },
    {
      "x": -15,
      "y": -4,
      "z": -6,
      "name": "Rock_Shale"
    },
    {
      "x": -15,
      "y": -3,
      "z": -6,
      "name": "Rock_Shale"
    },
    {
      "x": -15,
      "y": -2,
      "z": -6,
      "name": "Rock_Shale"
    },
    {
      "x": -15,
      "y": -1,
      "z": -6,
      "name": "Rock_Shale"
    },
    {
      "x": -15,
      "y": 0,
      "z": -6,
      "name": "Rock_Shale"
    },
    {
      "x": -15,
      "y": 1,
      "z": -6,
      "name": "Rock_Shale"
    },
    {
      "x": -15,
      "y": 2,
      "z": -6,
      "name": "Rock_Basalt"
    },
    {
      "x": -15,
      "y": 3,
      "z": -6,
      "name": "Rock_Basalt"
    },
    {
      "x": -15,
      "y": 4,
      "z": -6,
      "name": "Rock_Basalt"
    },
    {
      "x": -15,
      "y": 5,
      "z": -6,
      "name": "Soil_Dirt_Cold"
    },
    {
      "x": -15,
      "y": 6,
      "z": -6,
      "name": "Soil_Snow"
    },
    {
      "x": -15,
      "y": -22,
      "z": -5,
      "name": "Rock_Basalt"
    },
    {
      "x": -15,
      "y": -21,
      "z": -5,
      "name": "Rock_Basalt"
    },
    {
      "x": -15,
      "y": -20,
      "z": -5,
      "name": "Rock_Basalt"
    },
    {
      "x": -15,
      "y": -19,
      "z": -5,
      "name": "Rock_Basalt"
    },
    {
      "x": -15,
      "y": -18,
      "z": -5,
      "name": "Rock_Basalt"
    },
    {
      "x": -15,
      "y": -17,
      "z": -5,
      "name": "Rock_Basalt"
    },
    {
      "x": -15,
      "y": -16,
      "z": -5,
      "name": "Rock_Basalt"
    },
    {
      "x": -15,
      "y": -15,
      "z": -5,
      "name": "Rock_Basalt"
    },
    {
      "x": -15,
      "y": -14,
      "z": -5,
      "name": "Rock_Basalt"
    },
    {
      "x": -15,
      "y": -13,
      "z": -5,
      "name": "Rock_Basalt"
    },
    {
      "x": -15,
      "y": -12,
      "z": -5,
      "name": "Rock_Basalt"
    },
    {
      "x": -15,
      "y": -11,
      "z": -5,
      "name": "Rock_Basalt"
    },
    {
      "x": -15,
      "y": -10,
      "z": -5,
      "name": "Rock_Basalt"
    },
    {
      "x": -15,
      "y": -9,
      "z": -5,
      "name": "Rock_Basalt"
    },
    {
      "x": -15,
      "y": -8,
      "z": -5,
      "name": "Rock_Basalt"
    },
    {
      "x": -15,
      "y": -7,
      "z": -5,
      "name": "Rock_Basalt"
    },
    {
      "x": -15,
      "y": -6,
      "z": -5,
      "name": "Rock_Basalt"
    },
    {
      "x": -15,
      "y": -5,
      "z": -5,
      "name": "Rock_Basalt"
    },
    {
      "x": -15,
      "y": -4,
      "z": -5,
      "name": "Rock_Shale"
    },
    {
      "x": -15,
      "y": -3,
      "z": -5,
      "name": "Rock_Basalt"
    },
    {
      "x": -15,
      "y": -2,
      "z": -5,
      "name": "Rock_Basalt"
    },
    {
      "x": -15,
      "y": -1,
      "z": -5,
      "name": "Rock_Basalt"
    },
    {
      "x": -15,
      "y": 0,
      "z": -5,
      "name": "Rock_Shale"
    },
    {
      "x": -15,
      "y": 1,
      "z": -5,
      "name": "Rock_Basalt"
    },
    {
      "x": -15,
      "y": 2,
      "z": -5,
      "name": "Rock_Basalt"
    },
    {
      "x": -15,
      "y": 3,
      "z": -5,
      "name": "Rock_Basalt"
    },
    {
      "x": -15,
      "y": 4,
      "z": -5,
      "name": "Rock_Basalt"
    },
    {
      "x": -15,
      "y": 5,
      "z": -5,
      "name": "Soil_Dirt_Cold"
    },
    {
      "x": -15,
      "y": 6,
      "z": -5,
      "name": "Soil_Snow"
    },
    {
      "x": -15,
      "y": -22,
      "z": -4,
      "name": "Rock_Basalt"
    },
    {
      "x": -15,
      "y": -21,
      "z": -4,
      "name": "Rock_Basalt"
    },
    {
      "x": -15,
      "y": -20,
      "z": -4,
      "name": "Rock_Basalt"
    },
    {
      "x": -15,
      "y": -19,
      "z": -4,
      "name": "Rock_Basalt"
    },
    {
      "x": -15,
      "y": -18,
      "z": -4,
      "name": "Rock_Basalt"
    },
    {
      "x": -15,
      "y": -17,
      "z": -4,
      "name": "Rock_Basalt"
    },
    {
      "x": -15,
      "y": -16,
      "z": -4,
      "name": "Rock_Basalt"
    },
    {
      "x": -15,
      "y": -15,
      "z": -4,
      "name": "Rock_Basalt"
    },
    {
      "x": -15,
      "y": -14,
      "z": -4,
      "name": "Rock_Basalt"
    },
    {
      "x": -15,
      "y": -13,
      "z": -4,
      "name": "Rock_Basalt"
    },
    {
      "x": -15,
      "y": -12,
      "z": -4,
      "name": "Rock_Basalt"
    },
    {
      "x": -15,
      "y": -11,
      "z": -4,
      "name": "Rock_Basalt"
    },
    {
      "x": -15,
      "y": -10,
      "z": -4,
      "name": "Rock_Basalt"
    },
    {
      "x": -15,
      "y": -9,
      "z": -4,
      "name": "Rock_Basalt"
    },
    {
      "x": -15,
      "y": -8,
      "z": -4,
      "name": "Rock_Basalt"
    },
    {
      "x": -15,
      "y": -7,
      "z": -4,
      "name": "Rock_Basalt"
    },
    {
      "x": -15,
      "y": -6,
      "z": -4,
      "name": "Rock_Basalt"
    },
    {
      "x": -15,
      "y": -5,
      "z": -4,
      "name": "Rock_Basalt"
    },
    {
      "x": -15,
      "y": -4,
      "z": -4,
      "name": "Rock_Basalt"
    },
    {
      "x": -15,
      "y": -3,
      "z": -4,
      "name": "Rock_Basalt"
    },
    {
      "x": -15,
      "y": -2,
      "z": -4,
      "name": "Rock_Basalt"
    },
    {
      "x": -15,
      "y": -1,
      "z": -4,
      "name": "Rock_Basalt"
    },
    {
      "x": -15,
      "y": 0,
      "z": -4,
      "name": "Rock_Basalt"
    },
    {
      "x": -15,
      "y": 1,
      "z": -4,
      "name": "Rock_Basalt"
    },
    {
      "x": -15,
      "y": 2,
      "z": -4,
      "name": "Rock_Basalt"
    },
    {
      "x": -15,
      "y": 3,
      "z": -4,
      "name": "Rock_Basalt"
    },
    {
      "x": -15,
      "y": 4,
      "z": -4,
      "name": "Rock_Basalt"
    },
    {
      "x": -15,
      "y": 5,
      "z": -4,
      "name": "Soil_Dirt_Cold"
    },
    {
      "x": -15,
      "y": 6,
      "z": -4,
      "name": "Soil_Snow"
    },
    {
      "x": -15,
      "y": 7,
      "z": -4,
      "name": "Plant_Flower_Orchid_Purple"
    },
    {
      "x": -15,
      "y": -22,
      "z": -3,
      "name": "Rock_Basalt"
    },
    {
      "x": -15,
      "y": -21,
      "z": -3,
      "name": "Rock_Basalt"
    },
    {
      "x": -15,
      "y": -20,
      "z": -3,
      "name": "Rock_Basalt"
    },
    {
      "x": -15,
      "y": -19,
      "z": -3,
      "name": "Rock_Basalt"
    },
    {
      "x": -15,
      "y": -18,
      "z": -3,
      "name": "Rock_Basalt"
    },
    {
      "x": -15,
      "y": -17,
      "z": -3,
      "name": "Rock_Basalt"
    },
    {
      "x": -15,
      "y": -16,
      "z": -3,
      "name": "Rock_Basalt"
    },
    {
      "x": -15,
      "y": -15,
      "z": -3,
      "name": "Rock_Basalt"
    },
    {
      "x": -15,
      "y": -14,
      "z": -3,
      "name": "Rock_Basalt"
    },
    {
      "x": -15,
      "y": -13,
      "z": -3,
      "name": "Rock_Basalt"
    },
    {
      "x": -15,
      "y": -12,
      "z": -3,
      "name": "Rock_Basalt"
    },
    {
      "x": -15,
      "y": -11,
      "z": -3,
      "name": "Rock_Basalt"
    },
    {
      "x": -15,
      "y": -10,
      "z": -3,
      "name": "Rock_Basalt"
    },
    {
      "x": -15,
      "y": -9,
      "z": -3,
      "name": "Rock_Basalt"
    },
    {
      "x": -15,
      "y": -8,
      "z": -3,
      "name": "Rock_Basalt"
    },
    {
      "x": -15,
      "y": -7,
      "z": -3,
      "name": "Rock_Basalt"
    },
    {
      "x": -15,
      "y": -6,
      "z": -3,
      "name": "Rock_Basalt"
    },
    {
      "x": -15,
      "y": -5,
      "z": -3,
      "name": "Rock_Basalt"
    },
    {
      "x": -15,
      "y": -4,
      "z": -3,
      "name": "Rock_Basalt"
    },
    {
      "x": -15,
      "y": -3,
      "z": -3,
      "name": "Rock_Basalt"
    },
    {
      "x": -15,
      "y": -2,
      "z": -3,
      "name": "Rock_Basalt"
    },
    {
      "x": -15,
      "y": -1,
      "z": -3,
      "name": "Rock_Basalt"
    },
    {
      "x": -15,
      "y": 0,
      "z": -3,
      "name": "Rock_Shale"
    },
    {
      "x": -15,
      "y": 1,
      "z": -3,
      "name": "Rock_Basalt"
    },
    {
      "x": -15,
      "y": 2,
      "z": -3,
      "name": "Rock_Basalt"
    },
    {
      "x": -15,
      "y": 3,
      "z": -3,
      "name": "Rock_Basalt"
    },
    {
      "x": -15,
      "y": 4,
      "z": -3,
      "name": "Rock_Basalt"
    },
    {
      "x": -15,
      "y": 5,
      "z": -3,
      "name": "Soil_Dirt_Cold"
    },
    {
      "x": -15,
      "y": 6,
      "z": -3,
      "name": "Soil_Snow"
    },
    {
      "x": -15,
      "y": 7,
      "z": -3,
      "name": "Plant_Grass_Snowy_Short"
    },
    {
      "x": -15,
      "y": -22,
      "z": -2,
      "name": "Rock_Basalt"
    },
    {
      "x": -15,
      "y": -21,
      "z": -2,
      "name": "Rock_Basalt"
    },
    {
      "x": -15,
      "y": -20,
      "z": -2,
      "name": "Rock_Basalt"
    },
    {
      "x": -15,
      "y": -19,
      "z": -2,
      "name": "Rock_Basalt"
    },
    {
      "x": -15,
      "y": -18,
      "z": -2,
      "name": "Rock_Basalt"
    },
    {
      "x": -15,
      "y": -17,
      "z": -2,
      "name": "Rock_Basalt"
    },
    {
      "x": -15,
      "y": -16,
      "z": -2,
      "name": "Rock_Basalt"
    },
    {
      "x": -15,
      "y": -15,
      "z": -2,
      "name": "Rock_Basalt"
    },
    {
      "x": -15,
      "y": -14,
      "z": -2,
      "name": "Rock_Basalt"
    },
    {
      "x": -15,
      "y": -13,
      "z": -2,
      "name": "Rock_Basalt"
    },
    {
      "x": -15,
      "y": -12,
      "z": -2,
      "name": "Rock_Basalt"
    },
    {
      "x": -15,
      "y": -11,
      "z": -2,
      "name": "Rock_Basalt"
    },
    {
      "x": -15,
      "y": -10,
      "z": -2,
      "name": "Rock_Basalt"
    },
    {
      "x": -15,
      "y": -9,
      "z": -2,
      "name": "Rock_Basalt"
    },
    {
      "x": -15,
      "y": -8,
      "z": -2,
      "name": "Rock_Basalt"
    },
    {
      "x": -15,
      "y": -7,
      "z": -2,
      "name": "Rock_Basalt"
    },
    {
      "x": -15,
      "y": -6,
      "z": -2,
      "name": "Rock_Basalt"
    },
    {
      "x": -15,
      "y": -5,
      "z": -2,
      "name": "Rock_Basalt"
    },
    {
      "x": -15,
      "y": -4,
      "z": -2,
      "name": "Rock_Shale"
    },
    {
      "x": -15,
      "y": -3,
      "z": -2,
      "name": "Rock_Basalt"
    },
    {
      "x": -15,
      "y": -2,
      "z": -2,
      "name": "Rock_Basalt"
    },
    {
      "x": -15,
      "y": -1,
      "z": -2,
      "name": "Rock_Shale"
    },
    {
      "x": -15,
      "y": 0,
      "z": -2,
      "name": "Rock_Shale"
    },
    {
      "x": -15,
      "y": 1,
      "z": -2,
      "name": "Rock_Shale"
    },
    {
      "x": -15,
      "y": 2,
      "z": -2,
      "name": "Rock_Basalt"
    },
    {
      "x": -15,
      "y": 3,
      "z": -2,
      "name": "Rock_Basalt"
    },
    {
      "x": -15,
      "y": 4,
      "z": -2,
      "name": "Rock_Basalt"
    },
    {
      "x": -15,
      "y": 5,
      "z": -2,
      "name": "Soil_Dirt_Cold"
    },
    {
      "x": -15,
      "y": 6,
      "z": -2,
      "name": "Soil_Snow"
    },
    {
      "x": -15,
      "y": -22,
      "z": -1,
      "name": "Rock_Basalt"
    },
    {
      "x": -15,
      "y": -21,
      "z": -1,
      "name": "Rock_Basalt"
    },
    {
      "x": -15,
      "y": -20,
      "z": -1,
      "name": "Rock_Basalt"
    },
    {
      "x": -15,
      "y": -19,
      "z": -1,
      "name": "Rock_Basalt"
    },
    {
      "x": -15,
      "y": -18,
      "z": -1,
      "name": "Rock_Basalt"
    },
    {
      "x": -15,
      "y": -17,
      "z": -1,
      "name": "Rock_Basalt"
    },
    {
      "x": -15,
      "y": -16,
      "z": -1,
      "name": "Rock_Basalt"
    },
    {
      "x": -15,
      "y": -15,
      "z": -1,
      "name": "Rock_Basalt"
    },
    {
      "x": -15,
      "y": -14,
      "z": -1,
      "name": "Rock_Basalt"
    },
    {
      "x": -15,
      "y": -13,
      "z": -1,
      "name": "Rock_Basalt"
    },
    {
      "x": -15,
      "y": -12,
      "z": -1,
      "name": "Rock_Basalt"
    },
    {
      "x": -15,
      "y": -11,
      "z": -1,
      "name": "Rock_Basalt"
    },
    {
      "x": -15,
      "y": -10,
      "z": -1,
      "name": "Rock_Basalt"
    },
    {
      "x": -15,
      "y": -9,
      "z": -1,
      "name": "Rock_Basalt"
    },
    {
      "x": -15,
      "y": -8,
      "z": -1,
      "name": "Rock_Basalt"
    },
    {
      "x": -15,
      "y": -7,
      "z": -1,
      "name": "Rock_Basalt"
    },
    {
      "x": -15,
      "y": -6,
      "z": -1,
      "name": "Rock_Basalt"
    },
    {
      "x": -15,
      "y": -5,
      "z": -1,
      "name": "Rock_Shale"
    },
    {
      "x": -15,
      "y": -4,
      "z": -1,
      "name": "Rock_Shale"
    },
    {
      "x": -15,
      "y": -3,
      "z": -1,
      "name": "Rock_Shale"
    },
    {
      "x": -15,
      "y": -2,
      "z": -1,
      "name": "Rock_Shale"
    },
    {
      "x": -15,
      "y": -1,
      "z": -1,
      "name": "Rock_Shale"
    },
    {
      "x": -15,
      "y": 0,
      "z": -1,
      "name": "Rock_Shale"
    },
    {
      "x": -15,
      "y": 1,
      "z": -1,
      "name": "Rock_Shale"
    },
    {
      "x": -15,
      "y": 2,
      "z": -1,
      "name": "Rock_Basalt"
    },
    {
      "x": -15,
      "y": 3,
      "z": -1,
      "name": "Rock_Basalt"
    },
    {
      "x": -15,
      "y": 4,
      "z": -1,
      "name": "Rock_Basalt"
    },
    {
      "x": -15,
      "y": 5,
      "z": -1,
      "name": "Soil_Dirt_Cold"
    },
    {
      "x": -15,
      "y": 6,
      "z": -1,
      "name": "Soil_Snow"
    },
    {
      "x": -15,
      "y": 7,
      "z": -1,
      "name": "Soil_Snow_Half"
    },
    {
      "x": -15,
      "y": -22,
      "z": 0,
      "name": "Rock_Basalt"
    },
    {
      "x": -15,
      "y": -21,
      "z": 0,
      "name": "Rock_Basalt"
    },
    {
      "x": -15,
      "y": -20,
      "z": 0,
      "name": "Rock_Basalt"
    },
    {
      "x": -15,
      "y": -19,
      "z": 0,
      "name": "Rock_Basalt"
    },
    {
      "x": -15,
      "y": -18,
      "z": 0,
      "name": "Rock_Basalt"
    },
    {
      "x": -15,
      "y": -17,
      "z": 0,
      "name": "Rock_Basalt"
    },
    {
      "x": -15,
      "y": -16,
      "z": 0,
      "name": "Rock_Basalt"
    },
    {
      "x": -15,
      "y": -15,
      "z": 0,
      "name": "Rock_Basalt"
    },
    {
      "x": -15,
      "y": -14,
      "z": 0,
      "name": "Rock_Basalt"
    },
    {
      "x": -15,
      "y": -13,
      "z": 0,
      "name": "Rock_Basalt"
    },
    {
      "x": -15,
      "y": -12,
      "z": 0,
      "name": "Rock_Basalt"
    },
    {
      "x": -15,
      "y": -11,
      "z": 0,
      "name": "Rock_Basalt"
    },
    {
      "x": -15,
      "y": -10,
      "z": 0,
      "name": "Rock_Basalt"
    },
    {
      "x": -15,
      "y": -9,
      "z": 0,
      "name": "Rock_Basalt"
    },
    {
      "x": -15,
      "y": -8,
      "z": 0,
      "name": "Rock_Basalt"
    },
    {
      "x": -15,
      "y": -7,
      "z": 0,
      "name": "Rock_Basalt"
    },
    {
      "x": -15,
      "y": -6,
      "z": 0,
      "name": "Rock_Basalt"
    },
    {
      "x": -15,
      "y": -5,
      "z": 0,
      "name": "Rock_Basalt"
    },
    {
      "x": -15,
      "y": -4,
      "z": 0,
      "name": "Rock_Shale"
    },
    {
      "x": -15,
      "y": -3,
      "z": 0,
      "name": "Rock_Shale"
    },
    {
      "x": -15,
      "y": -2,
      "z": 0,
      "name": "Rock_Shale"
    },
    {
      "x": -15,
      "y": -1,
      "z": 0,
      "name": "Rock_Shale"
    },
    {
      "x": -15,
      "y": 0,
      "z": 0,
      "name": "Rock_Shale"
    },
    {
      "x": -15,
      "y": 1,
      "z": 0,
      "name": "Rock_Shale"
    },
    {
      "x": -15,
      "y": 2,
      "z": 0,
      "name": "Rock_Shale"
    },
    {
      "x": -15,
      "y": 3,
      "z": 0,
      "name": "Rock_Basalt"
    },
    {
      "x": -15,
      "y": 4,
      "z": 0,
      "name": "Rock_Basalt"
    },
    {
      "x": -15,
      "y": 5,
      "z": 0,
      "name": "Rock_Basalt"
    },
    {
      "x": -15,
      "y": 6,
      "z": 0,
      "name": "Rock_Basalt"
    },
    {
      "x": -15,
      "y": 7,
      "z": 0,
      "name": "Rock_Shale_Brick_Smooth"
    },
    {
      "x": -15,
      "y": 8,
      "z": 0,
      "name": "Rock_Shale_Brick_Smooth"
    },
    {
      "x": -15,
      "y": 9,
      "z": 0,
      "name": "Rock_Shale_Brick_Smooth_Half",
      "rotation": 7
    },
    {
      "x": -15,
      "y": -22,
      "z": 1,
      "name": "Rock_Basalt"
    },
    {
      "x": -15,
      "y": -21,
      "z": 1,
      "name": "Rock_Basalt"
    },
    {
      "x": -15,
      "y": -20,
      "z": 1,
      "name": "Rock_Basalt"
    },
    {
      "x": -15,
      "y": -19,
      "z": 1,
      "name": "Rock_Basalt"
    },
    {
      "x": -15,
      "y": -18,
      "z": 1,
      "name": "Rock_Basalt"
    },
    {
      "x": -15,
      "y": -17,
      "z": 1,
      "name": "Rock_Basalt"
    },
    {
      "x": -15,
      "y": -16,
      "z": 1,
      "name": "Rock_Basalt"
    },
    {
      "x": -15,
      "y": -15,
      "z": 1,
      "name": "Rock_Basalt"
    },
    {
      "x": -15,
      "y": -14,
      "z": 1,
      "name": "Rock_Basalt"
    },
    {
      "x": -15,
      "y": -13,
      "z": 1,
      "name": "Rock_Basalt"
    },
    {
      "x": -15,
      "y": -12,
      "z": 1,
      "name": "Rock_Basalt"
    },
    {
      "x": -15,
      "y": -11,
      "z": 1,
      "name": "Rock_Basalt"
    },
    {
      "x": -15,
      "y": -10,
      "z": 1,
      "name": "Rock_Basalt"
    },
    {
      "x": -15,
      "y": -9,
      "z": 1,
      "name": "Rock_Basalt"
    },
    {
      "x": -15,
      "y": -8,
      "z": 1,
      "name": "Rock_Basalt"
    },
    {
      "x": -15,
      "y": -7,
      "z": 1,
      "name": "Rock_Basalt"
    },
    {
      "x": -15,
      "y": -6,
      "z": 1,
      "name": "Rock_Basalt"
    },
    {
      "x": -15,
      "y": -5,
      "z": 1,
      "name": "Rock_Basalt"
    },
    {
      "x": -15,
      "y": -4,
      "z": 1,
      "name": "Rock_Shale"
    },
    {
      "x": -15,
      "y": -3,
      "z": 1,
      "name": "Rock_Shale"
    },
    {
      "x": -15,
      "y": -2,
      "z": 1,
      "name": "Rock_Shale"
    },
    {
      "x": -15,
      "y": -1,
      "z": 1,
      "name": "Rock_Shale"
    },
    {
      "x": -15,
      "y": 0,
      "z": 1,
      "name": "Rock_Shale"
    },
    {
      "x": -15,
      "y": 1,
      "z": 1,
      "name": "Rock_Shale"
    },
    {
      "x": -15,
      "y": 2,
      "z": 1,
      "name": "Rock_Shale"
    },
    {
      "x": -15,
      "y": 3,
      "z": 1,
      "name": "Rock_Basalt"
    },
    {
      "x": -15,
      "y": 4,
      "z": 1,
      "name": "Rock_Basalt"
    },
    {
      "x": -15,
      "y": 5,
      "z": 1,
      "name": "Rock_Basalt"
    },
    {
      "x": -15,
      "y": 6,
      "z": 1,
      "name": "Rock_Basalt"
    },
    {
      "x": -15,
      "y": 7,
      "z": 1,
      "name": "Rock_Shale_Brick_Smooth"
    },
    {
      "x": -15,
      "y": 8,
      "z": 1,
      "name": "Rock_Shale_Brick_Smooth"
    },
    {
      "x": -15,
      "y": 9,
      "z": 1,
      "name": "Rock_Shale_Brick_Smooth_Half",
      "rotation": 7
    },
    {
      "x": -15,
      "y": -22,
      "z": 2,
      "name": "Rock_Basalt"
    },
    {
      "x": -15,
      "y": -21,
      "z": 2,
      "name": "Rock_Basalt"
    },
    {
      "x": -15,
      "y": -20,
      "z": 2,
      "name": "Rock_Basalt"
    },
    {
      "x": -15,
      "y": -19,
      "z": 2,
      "name": "Rock_Basalt"
    },
    {
      "x": -15,
      "y": -18,
      "z": 2,
      "name": "Rock_Basalt"
    },
    {
      "x": -15,
      "y": -17,
      "z": 2,
      "name": "Rock_Basalt"
    },
    {
      "x": -15,
      "y": -16,
      "z": 2,
      "name": "Rock_Basalt"
    },
    {
      "x": -15,
      "y": -15,
      "z": 2,
      "name": "Rock_Basalt"
    },
    {
      "x": -15,
      "y": -14,
      "z": 2,
      "name": "Rock_Basalt"
    },
    {
      "x": -15,
      "y": -13,
      "z": 2,
      "name": "Rock_Basalt"
    },
    {
      "x": -15,
      "y": -12,
      "z": 2,
      "name": "Rock_Basalt"
    },
    {
      "x": -15,
      "y": -11,
      "z": 2,
      "name": "Rock_Basalt"
    },
    {
      "x": -15,
      "y": -10,
      "z": 2,
      "name": "Rock_Basalt"
    },
    {
      "x": -15,
      "y": -9,
      "z": 2,
      "name": "Rock_Basalt"
    },
    {
      "x": -15,
      "y": -8,
      "z": 2,
      "name": "Rock_Basalt"
    },
    {
      "x": -15,
      "y": -7,
      "z": 2,
      "name": "Soil_Dirt_Cold"
    },
    {
      "x": -15,
      "y": -6,
      "z": 2,
      "name": "Soil_Dirt_Cold"
    },
    {
      "x": -15,
      "y": 4,
      "z": 2,
      "name": "Rock_Basalt"
    },
    {
      "x": -15,
      "y": 5,
      "z": 2,
      "name": "Rock_Basalt"
    },
    {
      "x": -15,
      "y": 6,
      "z": 2,
      "name": "Rock_Basalt"
    },
    {
      "x": -15,
      "y": 7,
      "z": 2,
      "name": "Rock_Shale_Brick_Smooth"
    },
    {
      "x": -15,
      "y": 8,
      "z": 2,
      "name": "Rock_Shale_Brick_Smooth"
    },
    {
      "x": -15,
      "y": 9,
      "z": 2,
      "name": "Rock_Shale_Brick_Smooth_Half",
      "rotation": 7
    },
    {
      "x": -15,
      "y": -22,
      "z": 3,
      "name": "Rock_Basalt"
    },
    {
      "x": -15,
      "y": -21,
      "z": 3,
      "name": "Rock_Basalt"
    },
    {
      "x": -15,
      "y": -20,
      "z": 3,
      "name": "Rock_Basalt"
    },
    {
      "x": -15,
      "y": -19,
      "z": 3,
      "name": "Rock_Basalt"
    },
    {
      "x": -15,
      "y": -18,
      "z": 3,
      "name": "Rock_Basalt"
    },
    {
      "x": -15,
      "y": -17,
      "z": 3,
      "name": "Rock_Basalt"
    },
    {
      "x": -15,
      "y": -16,
      "z": 3,
      "name": "Rock_Basalt"
    },
    {
      "x": -15,
      "y": -15,
      "z": 3,
      "name": "Rock_Basalt"
    },
    {
      "x": -15,
      "y": -14,
      "z": 3,
      "name": "Rock_Basalt"
    },
    {
      "x": -15,
      "y": -13,
      "z": 3,
      "name": "Rock_Basalt"
    },
    {
      "x": -15,
      "y": -12,
      "z": 3,
      "name": "Rock_Basalt"
    },
    {
