{
  "version": 8,
  "blockIdVersion": 8,
  "anchorX": 18,
  "anchorY": 15,
  "anchorZ": 8,
  "blocks": [
    {
      "x": 13,
      "y": 34,
      "z": 3,
      "name": "Soil_Ash"
    },
    {
      "x": 13,
      "y": 35,
      "z": 3,
      "name": "Rock_Slate"
    },
    {
      "x": 13,
      "y": 36,
      "z": 3,
      "name": "Rock_Slate"
    },
    {
      "x": 13,
      "y": 33,
      "z": 4,
      "name": "Soil_Ash"
    },
    {
      "x": 13,
      "y": 34,
      "z": 4,
      "name": "Soil_Ash"
    },
    {
      "x": 13,
      "y": 35,
      "z": 4,
      "name": "Rock_Slate"
    },
    {
      "x": 13,
      "y": 36,
      "z": 4,
      "name": "Rock_Slate"
    },
    {
      "x": 13,
      "y": 37,
      "z": 4,
      "name": "Rock_Slate"
    },
    {
      "x": 13,
      "y": 38,
      "z": 4,
      "name": "Rock_Slate"
    },
    {
      "x": 13,
      "y": 39,
      "z": 4,
      "name": "Rock_Slate"
    },
    {
      "x": 13,
      "y": 14,
      "z": 5,
      "name": "Rock_Slate"
    },
    {
      "x": 13,
      "y": 15,
      "z": 5,
      "name": "Rock_Slate"
    },
    {
      "x": 13,
      "y": 16,
      "z": 5,
      "name": "Rock_Slate"
    },
    {
      "x": 13,
      "y": 17,
      "z": 5,
      "name": "Rock_Volcanic"
    },
    {
      "x": 13,
      "y": 18,
      "z": 5,
      "name": "Rock_Volcanic"
    },
    {
      "x": 13,
      "y": 19,
      "z": 5,
      "name": "Rock_Volcanic"
    },
    {
      "x": 13,
      "y": 20,
      "z": 5,
      "name": "Soil_Ash"
    },
    {
      "x": 13,
      "y": 33,
      "z": 5,
      "name": "Soil_Ash"
    },
    {
      "x": 13,
      "y": 34,
      "z": 5,
      "name": "Soil_Ash"
    },
    {
      "x": 13,
      "y": 35,
      "z": 5,
      "name": "Rock_Slate"
    },
    {
      "x": 13,
      "y": 36,
      "z": 5,
      "name": "Rock_Slate"
    },
    {
      "x": 13,
      "y": 37,
      "z": 5,
      "name": "Rock_Slate"
    },
    {
      "x": 13,
      "y": 38,
      "z": 5,
      "name": "Rock_Slate"
    },
    {
      "x": 13,
      "y": 39,
      "z": 5,
      "name": "Rock_Slate"
    },
    {
      "x": 13,
      "y": 14,
      "z": 6,
      "name": "Rock_Slate"
    },
    {
      "x": 13,
      "y": 15,
      "z": 6,
      "name": "Rock_Slate"
    },
    {
      "x": 13,
      "y": 16,
      "z": 6,
      "name": "Rock_Slate"
    },
    {
      "x": 13,
      "y": 17,
      "z": 6,
      "name": "Rock_Volcanic"
    },
    {
      "x": 13,
      "y": 18,
      "z": 6,
      "name": "Rock_Volcanic"
    },
    {
      "x": 13,
      "y": 19,
      "z": 6,
      "name": "Rock_Volcanic"
    },
    {
      "x": 13,
      "y": 20,
      "z": 6,
      "name": "Soil_Ash"
    },
    {
      "x": 13,
      "y": 33,
      "z": 6,
      "name": "Soil_Ash"
    },
    {
      "x": 13,
      "y": 34,
      "z": 6,
      "name": "Soil_Ash"
    },
    {
      "x": 13,
      "y": 35,
      "z": 6,
      "name": "Rock_Slate"
    },
    {
      "x": 13,
      "y": 36,
      "z": 6,
      "name": "Rock_Slate"
    },
    {
      "x": 13,
      "y": 37,
      "z": 6,
      "name": "Rock_Slate"
    },
    {
      "x": 13,
      "y": 38,
      "z": 6,
      "name": "Rock_Slate"
    },
    {
      "x": 13,
      "y": 39,
      "z": 6,
      "name": "Rock_Slate"
    },
    {
      "x": 13,
      "y": 14,
      "z": 7,
      "name": "Soil_Ash"
    },
    {
      "x": 13,
      "y": 15,
      "z": 7,
      "name": "Rock_Slate"
    },
    {
      "x": 13,
      "y": 16,
      "z": 7,
      "name": "Rock_Slate"
    },
    {
      "x": 13,
      "y": 17,
      "z": 7,
      "name": "Rock_Slate"
    },
    {
      "x": 13,
      "y": 18,
      "z": 7,
      "name": "Rock_Volcanic"
    },
    {
      "x": 13,
      "y": 19,
      "z": 7,
      "name": "Rock_Volcanic"
    },
    {
      "x": 13,
      "y": 20,
      "z": 7,
      "name": "Rock_Volcanic"
    },
    {
      "x": 13,
      "y": 21,
      "z": 7,
      "name": "Soil_Ash"
    },
    {
      "x": 13,
      "y": 22,
      "z": 7,
      "name": "Soil_Ash"
    },
    {
      "x": 13,
      "y": 35,
      "z": 7,
      "name": "Rock_Slate"
    },
    {
      "x": 13,
      "y": 36,
      "z": 7,
      "name": "Rock_Slate"
    },
    {
      "x": 13,
      "y": 37,
      "z": 7,
      "name": "Rock_Slate"
    },
    {
      "x": 13,
      "y": 38,
      "z": 7,
      "name": "Rock_Slate"
    },
    {
      "x": 13,
      "y": 39,
      "z": 7,
      "name": "Rock_Slate"
    },
    {
      "x": 13,
      "y": 14,
      "z": 8,
      "name": "Soil_Ash"
    },
    {
      "x": 13,
      "y": 15,
      "z": 8,
      "name": "Soil_Ash"
    },
    {
      "x": 13,
      "y": 16,
      "z": 8,
      "name": "Rock_Slate"
    },
    {
      "x": 13,
      "y": 17,
      "z": 8,
      "name": "Rock_Slate"
    },
    {
      "x": 13,
      "y": 18,
      "z": 8,
      "name": "Rock_Volcanic"
    },
    {
      "x": 13,
      "y": 19,
      "z": 8,
      "name": "Rock_Volcanic"
    },
    {
      "x": 13,
      "y": 20,
      "z": 8,
      "name": "Rock_Volcanic"
    },
    {
      "x": 13,
      "y": 21,
      "z": 8,
      "name": "Soil_Ash"
    },
    {
      "x": 13,
      "y": 22,
      "z": 8,
      "name": "Soil_Ash"
    },
    {
      "x": 13,
      "y": 36,
      "z": 8,
      "name": "Rock_Slate"
    },
    {
      "x": 13,
      "y": 37,
      "z": 8,
      "name": "Rock_Slate"
    },
    {
      "x": 13,
      "y": 38,
      "z": 8,
      "name": "Rock_Slate"
    },
    {
      "x": 13,
      "y": 39,
      "z": 8,
      "name": "Rock_Slate"
    },
    {
      "x": 13,
      "y": 14,
      "z": 9,
      "name": "Soil_Ash"
    },
    {
      "x": 13,
      "y": 15,
      "z": 9,
      "name": "Soil_Ash"
    },
    {
      "x": 13,
      "y": 16,
      "z": 9,
      "name": "Soil_Ash"
    },
    {
      "x": 13,
      "y": 17,
      "z": 9,
      "name": "Rock_Slate"
    },
    {
      "x": 13,
      "y": 18,
      "z": 9,
      "name": "Rock_Volcanic"
    },
    {
      "x": 13,
      "y": 19,
      "z": 9,
      "name": "Rock_Volcanic"
    },
    {
      "x": 13,
      "y": 20,
      "z": 9,
      "name": "Soil_Ash"
    },
    {
      "x": 13,
      "y": 21,
      "z": 9,
      "name": "Soil_Ash"
    },
    {
      "x": 13,
      "y": 22,
      "z": 9,
      "name": "Soil_Ash"
    },
    {
      "x": 13,
      "y": 23,
      "z": 9,
      "name": "Soil_Ash"
    },
    {
      "x": 13,
      "y": 36,
      "z": 9,
      "name": "Rock_Slate"
    },
    {
      "x": 13,
      "y": 37,
      "z": 9,
      "name": "Rock_Slate"
    },
    {
      "x": 13,
      "y": 38,
      "z": 9,
      "name": "Rock_Slate"
    },
    {
      "x": 13,
      "y": 39,
      "z": 9,
      "name": "Rock_Slate"
    },
    {
      "x": 13,
      "y": 15,
      "z": 10,
      "name": "Soil_Ash"
    },
    {
      "x": 13,
      "y": 16,
      "z": 10,
      "name": "Soil_Ash"
    },
    {
      "x": 13,
      "y": 17,
      "z": 10,
      "name": "Rock_Slate"
    },
    {
      "x": 13,
      "y": 18,
      "z": 10,
      "name": "Rock_Volcanic"
    },
    {
      "x": 13,
      "y": 19,
      "z": 10,
      "name": "Rock_Volcanic"
    },
    {
      "x": 13,
      "y": 20,
      "z": 10,
      "name": "Soil_Ash"
    },
    {
      "x": 13,
      "y": 21,
      "z": 10,
      "name": "Soil_Ash"
    },
    {
      "x": 13,
      "y": 22,
      "z": 10,
      "name": "Soil_Ash"
    },
    {
      "x": 13,
      "y": 23,
      "z": 10,
      "name": "Soil_Ash"
    },
    {
      "x": 13,
      "y": 36,
      "z": 10,
      "name": "Rock_Slate"
    },
    {
      "x": 13,
      "y": 37,
      "z": 10,
      "name": "Rock_Slate"
    },
    {
      "x": 13,
      "y": 38,
      "z": 10,
      "name": "Rock_Slate"
    },
    {
      "x": 13,
      "y": 15,
      "z": 11,
      "name": "Soil_Ash"
    },
    {
      "x": 13,
      "y": 16,
      "z": 11,
      "name": "Soil_Ash"
    },
    {
      "x": 13,
      "y": 17,
      "z": 11,
      "name": "Rock_Slate"
    },
    {
      "x": 13,
      "y": 18,
      "z": 11,
      "name": "Rock_Slate"
    },
    {
      "x": 13,
      "y": 19,
      "z": 11,
      "name": "Soil_Ash"
    },
    {
      "x": 13,
      "y": 20,
      "z": 11,
      "name": "Soil_Ash"
    },
    {
      "x": 13,
      "y": 21,
      "z": 11,
      "name": "Soil_Ash"
    },
    {
      "x": 13,
      "y": 22,
      "z": 11,
      "name": "Soil_Ash"
    },
    {
      "x": 13,
      "y": 23,
      "z": 11,
      "name": "Soil_Ash"
    },
    {
      "x": 13,
      "y": 15,
      "z": 12,
      "name": "Soil_Ash"
    },
    {
      "x": 13,
      "y": 16,
      "z": 12,
      "name": "Rock_Slate"
    },
    {
      "x": 13,
      "y": 17,
      "z": 12,
      "name": "Rock_Slate"
    },
    {
      "x": 13,
      "y": 18,
      "z": 12,
      "name": "Rock_Slate"
    },
    {
      "x": 13,
      "y": 19,
      "z": 12,
      "name": "Soil_Ash"
    },
    {
      "x": 13,
      "y": 20,
      "z": 12,
      "name": "Soil_Ash"
    },
    {
      "x": 13,
      "y": 21,
      "z": 12,
      "name": "Soil_Ash"
    },
    {
      "x": 13,
      "y": 22,
      "z": 12,
      "name": "Soil_Ash"
    },
    {
      "x": 13,
      "y": 23,
      "z": 12,
      "name": "Soil_Ash"
    },
    {
      "x": 14,
      "y": 29,
      "z": 2,
      "name": "Rock_Slate"
    },
    {
      "x": 14,
      "y": 30,
      "z": 2,
      "name": "Rock_Slate"
    },
    {
      "x": 14,
      "y": 31,
      "z": 2,
      "name": "Soil_Ash"
    },
    {
      "x": 14,
      "y": 32,
      "z": 2,
      "name": "Soil_Ash"
    },
    {
      "x": 14,
      "y": 33,
      "z": 2,
      "name": "Soil_Ash"
    },
    {
      "x": 14,
      "y": 34,
      "z": 2,
      "name": "Rock_Slate"
    },
    {
      "x": 14,
      "y": 19,
      "z": 3,
      "name": "Rock_Volcanic"
    },
    {
      "x": 14,
      "y": 20,
      "z": 3,
      "name": "Soil_Ash"
    },
    {
      "x": 14,
      "y": 21,
      "z": 3,
      "name": "Soil_Ash"
    },
    {
      "x": 14,
      "y": 22,
      "z": 3,
      "name": "Rock_Slate"
    },
    {
      "x": 14,
      "y": 23,
      "z": 3,
      "name": "Soil_Ash"
    },
    {
      "x": 14,
      "y": 24,
      "z": 3,
      "name": "Soil_Ash"
    },
    {
      "x": 14,
      "y": 25,
      "z": 3,
      "name": "Soil_Ash"
    },
    {
      "x": 14,
      "y": 26,
      "z": 3,
      "name": "Soil_Ash"
    },
    {
      "x": 14,
      "y": 27,
      "z": 3,
      "name": "Soil_Ash"
    },
    {
      "x": 14,
      "y": 28,
      "z": 3,
      "name": "Soil_Ash"
    },
    {
      "x": 14,
      "y": 29,
      "z": 3,
      "name": "Rock_Slate"
    },
    {
      "x": 14,
      "y": 30,
      "z": 3,
      "name": "Rock_Slate"
    },
    {
      "x": 14,
      "y": 31,
      "z": 3,
      "name": "Soil_Ash"
    },
    {
      "x": 14,
      "y": 32,
      "z": 3,
      "name": "Soil_Ash"
    },
    {
      "x": 14,
      "y": 33,
      "z": 3,
      "name": "Soil_Ash"
    },
    {
      "x": 14,
      "y": 34,
      "z": 3,
      "name": "Soil_Ash"
    },
    {
      "x": 14,
      "y": 35,
      "z": 3,
      "name": "Rock_Slate"
    },
    {
      "x": 14,
      "y": 36,
      "z": 3,
      "name": "Rock_Slate"
    },
    {
      "x": 14,
      "y": 37,
      "z": 3,
      "name": "Rock_Slate"
    },
    {
      "x": 14,
      "y": 38,
      "z": 3,
      "name": "Rock_Slate"
    },
    {
      "x": 14,
      "y": 17,
      "z": 4,
      "name": "Rock_Volcanic"
    },
    {
      "x": 14,
      "y": 18,
      "z": 4,
      "name": "Rock_Volcanic"
    },
    {
      "x": 14,
      "y": 19,
      "z": 4,
      "name": "Rock_Volcanic"
    },
    {
      "x": 14,
      "y": 20,
      "z": 4,
      "name": "Soil_Ash"
    },
    {
      "x": 14,
      "y": 21,
      "z": 4,
      "name": "Soil_Ash"
    },
    {
      "x": 14,
      "y": 22,
      "z": 4,
      "name": "Rock_Slate"
    },
    {
      "x": 14,
      "y": 23,
      "z": 4,
      "name": "Soil_Ash"
    },
    {
      "x": 14,
      "y": 24,
      "z": 4,
      "name": "Soil_Ash"
    },
    {
      "x": 14,
      "y": 25,
      "z": 4,
      "name": "Soil_Ash"
    },
    {
      "x": 14,
      "y": 26,
      "z": 4,
      "name": "Soil_Ash"
    },
    {
      "x": 14,
      "y": 27,
      "z": 4,
      "name": "Soil_Ash"
    },
    {
      "x": 14,
      "y": 28,
      "z": 4,
      "name": "Soil_Ash"
    },
    {
      "x": 14,
      "y": 29,
      "z": 4,
      "name": "Rock_Slate"
    },
    {
      "x": 14,
      "y": 30,
      "z": 4,
      "name": "Rock_Slate"
    },
    {
      "x": 14,
      "y": 31,
      "z": 4,
      "name": "Rock_Slate"
    },
    {
      "x": 14,
      "y": 32,
      "z": 4,
      "name": "Soil_Ash"
    },
    {
      "x": 14,
      "y": 33,
      "z": 4,
      "name": "Soil_Ash"
    },
    {
      "x": 14,
      "y": 34,
      "z": 4,
      "name": "Soil_Ash"
    },
    {
      "x": 14,
      "y": 35,
      "z": 4,
      "name": "Rock_Slate"
    },
    {
      "x": 14,
      "y": 36,
      "z": 4,
      "name": "Rock_Slate"
    },
    {
      "x": 14,
      "y": 37,
      "z": 4,
      "name": "Rock_Slate"
    },
    {
      "x": 14,
      "y": 38,
      "z": 4,
      "name": "Rock_Slate"
    },
    {
      "x": 14,
      "y": 39,
      "z": 4,
      "name": "Rock_Slate"
    },
    {
      "x": 14,
      "y": 14,
      "z": 5,
      "name": "Rock_Slate"
    },
    {
      "x": 14,
      "y": 15,
      "z": 5,
      "name": "Rock_Slate"
    },
    {
      "x": 14,
      "y": 16,
      "z": 5,
      "name": "Rock_Slate"
    },
    {
      "x": 14,
      "y": 17,
      "z": 5,
      "name": "Rock_Volcanic"
    },
    {
      "x": 14,
      "y": 18,
      "z": 5,
      "name": "Rock_Volcanic"
    },
    {
      "x": 14,
      "y": 19,
      "z": 5,
      "name": "Rock_Volcanic"
    },
    {
      "x": 14,
      "y": 20,
      "z": 5,
      "name": "Soil_Ash"
    },
    {
      "x": 14,
      "y": 21,
      "z": 5,
      "name": "Soil_Ash"
    },
    {
      "x": 14,
      "y": 22,
      "z": 5,
      "name": "Rock_Slate"
    },
    {
      "x": 14,
      "y": 23,
      "z": 5,
      "name": "Soil_Ash"
    },
    {
      "x": 14,
      "y": 24,
      "z": 5,
      "name": "Soil_Ash"
    },
    {
      "x": 14,
      "y": 25,
      "z": 5,
      "name": "Soil_Ash"
    },
    {
      "x": 14,
      "y": 26,
      "z": 5,
      "name": "Soil_Ash"
    },
    {
      "x": 14,
      "y": 27,
      "z": 5,
      "name": "Soil_Ash"
    },
    {
      "x": 14,
      "y": 31,
      "z": 5,
      "name": "Rock_Slate"
    },
    {
      "x": 14,
      "y": 32,
      "z": 5,
      "name": "Soil_Ash"
    },
    {
      "x": 14,
      "y": 33,
      "z": 5,
      "name": "Soil_Ash"
    },
    {
      "x": 14,
      "y": 34,
      "z": 5,
      "name": "Soil_Ash"
    },
    {
      "x": 14,
      "y": 35,
      "z": 5,
      "name": "Rock_Slate"
    },
    {
      "x": 14,
      "y": 36,
      "z": 5,
      "name": "Rock_Slate"
    },
    {
      "x": 14,
      "y": 37,
      "z": 5,
      "name": "Rock_Slate"
    },
    {
      "x": 14,
      "y": 38,
      "z": 5,
      "name": "Rock_Slate"
    },
    {
      "x": 14,
      "y": 39,
      "z": 5,
      "name": "Rock_Slate"
    },
    {
      "x": 14,
      "y": 12,
      "z": 6,
      "name": "Soil_Ash"
    },
    {
      "x": 14,
      "y": 13,
      "z": 6,
      "name": "Soil_Ash"
    },
    {
      "x": 14,
      "y": 14,
      "z": 6,
      "name": "Rock_Slate"
    },
    {
      "x": 14,
      "y": 15,
      "z": 6,
      "name": "Rock_Slate"
    },
    {
      "x": 14,
      "y": 16,
      "z": 6,
      "name": "Rock_Slate"
    },
    {
      "x": 14,
      "y": 17,
      "z": 6,
      "name": "Rock_Volcanic"
    },
    {
      "x": 14,
      "y": 18,
      "z": 6,
      "name": "Rock_Volcanic"
    },
    {
      "x": 14,
      "y": 19,
      "z": 6,
      "name": "Rock_Volcanic"
    },
    {
      "x": 14,
      "y": 20,
      "z": 6,
      "name": "Rock_Volcanic"
    },
    {
      "x": 14,
      "y": 21,
      "z": 6,
      "name": "Soil_Ash"
    },
    {
      "x": 14,
      "y": 22,
      "z": 6,
      "name": "Rock_Slate"
    },
    {
      "x": 14,
      "y": 23,
      "z": 6,
      "name": "Rock_Slate"
    },
    {
      "x": 14,
      "y": 33,
      "z": 6,
      "name": "Soil_Ash"
    },
    {
      "x": 14,
      "y": 34,
      "z": 6,
      "name": "Soil_Ash"
    },
    {
      "x": 14,
      "y": 35,
      "z": 6,
      "name": "Soil_Ash"
    },
    {
      "x": 14,
      "y": 36,
      "z": 6,
      "name": "Rock_Slate"
    },
    {
      "x": 14,
      "y": 37,
      "z": 6,
      "name": "Rock_Slate"
    },
    {
      "x": 14,
      "y": 38,
      "z": 6,
      "name": "Rock_Slate"
    },
    {
      "x": 14,
      "y": 39,
      "z": 6,
      "name": "Rock_Slate"
    },
    {
      "x": 14,
      "y": 12,
      "z": 7,
      "name": "Soil_Ash"
    },
    {
      "x": 14,
      "y": 13,
      "z": 7,
      "name": "Soil_Ash"
    },
    {
      "x": 14,
      "y": 14,
      "z": 7,
      "name": "Soil_Ash"
    },
    {
      "x": 14,
      "y": 15,
      "z": 7,
      "name": "Soil_Ash"
    },
    {
      "x": 14,
      "y": 16,
      "z": 7,
      "name": "Rock_Slate"
    },
    {
      "x": 14,
      "y": 17,
      "z": 7,
      "name": "Rock_Volcanic"
    },
    {
      "x": 14,
      "y": 18,
      "z": 7,
      "name": "Rock_Volcanic"
    },
    {
      "x": 14,
      "y": 19,
      "z": 7,
      "name": "Rock_Volcanic"
    },
    {
      "x": 14,
      "y": 20,
      "z": 7,
      "name": "Rock_Volcanic"
    },
    {
      "x": 14,
      "y": 21,
      "z": 7,
      "name": "Soil_Ash"
    },
    {
      "x": 14,
      "y": 22,
      "z": 7,
      "name": "Rock_Slate"
    },
    {
      "x": 14,
      "y": 35,
      "z": 7,
      "name": "Soil_Ash"
    },
    {
      "x": 14,
      "y": 36,
      "z": 7,
      "name": "Rock_Slate"
    },
    {
      "x": 14,
      "y": 37,
      "z": 7,
      "name": "Rock_Slate"
    },
    {
      "x": 14,
      "y": 38,
      "z": 7,
      "name": "Rock_Slate"
    },
    {
      "x": 14,
      "y": 39,
      "z": 7,
      "name": "Rock_Slate"
    },
    {
      "x": 14,
      "y": 12,
      "z": 8,
      "name": "Soil_Ash"
    },
    {
      "x": 14,
      "y": 13,
      "z": 8,
      "name": "Soil_Ash"
    },
    {
      "x": 14,
      "y": 14,
      "z": 8,
      "name": "Soil_Ash"
    },
    {
      "x": 14,
      "y": 15,
      "z": 8,
      "name": "Soil_Ash"
    },
    {
      "x": 14,
      "y": 16,
      "z": 8,
      "name": "Rock_Slate"
    },
    {
      "x": 14,
      "y": 17,
      "z": 8,
      "name": "Rock_Slate"
    },
    {
      "x": 14,
      "y": 18,
      "z": 8,
      "name": "Rock_Volcanic"
    },
    {
      "x": 14,
      "y": 19,
      "z": 8,
      "name": "Rock_Volcanic"
    },
    {
      "x": 14,
      "y": 20,
      "z": 8,
      "name": "Rock_Volcanic"
    },
    {
      "x": 14,
      "y": 21,
      "z": 8,
      "name": "Soil_Ash"
    },
    {
      "x": 14,
      "y": 22,
      "z": 8,
      "name": "Soil_Ash"
    },
    {
      "x": 14,
      "y": 35,
      "z": 8,
      "name": "Soil_Ash"
    },
    {
      "x": 14,
      "y": 36,
      "z": 8,
      "name": "Rock_Slate"
    },
    {
      "x": 14,
      "y": 37,
      "z": 8,
      "name": "Rock_Slate"
    },
    {
      "x": 14,
      "y": 38,
      "z": 8,
      "name": "Rock_Slate"
    },
    {
      "x": 14,
      "y": 39,
      "z": 8,
      "name": "Rock_Slate"
    },
    {
      "x": 14,
      "y": 11,
      "z": 9,
      "name": "Soil_Ash"
    },
    {
      "x": 14,
      "y": 12,
      "z": 9,
      "name": "Soil_Ash"
    },
    {
      "x": 14,
      "y": 13,
      "z": 9,
      "name": "Soil_Ash"
    },
    {
      "x": 14,
      "y": 14,
      "z": 9,
      "name": "Soil_Ash"
    },
    {
      "x": 14,
      "y": 15,
      "z": 9,
      "name": "Soil_Ash"
    },
    {
      "x": 14,
      "y": 16,
      "z": 9,
      "name": "Soil_Ash"
    },
    {
      "x": 14,
      "y": 17,
      "z": 9,
      "name": "Rock_Slate"
    },
    {
      "x": 14,
      "y": 18,
      "z": 9,
      "name": "Rock_Volcanic"
    },
    {
      "x": 14,
      "y": 19,
      "z": 9,
      "name": "Rock_Volcanic"
    },
    {
      "x": 14,
      "y": 20,
      "z": 9,
      "name": "Rock_Volcanic"
    },
    {
      "x": 14,
      "y": 21,
      "z": 9,
      "name": "Soil_Ash"
    },
    {
      "x": 14,
      "y": 22,
      "z": 9,
      "name": "Soil_Ash"
    },
    {
      "x": 14,
      "y": 23,
      "z": 9,
      "name": "Soil_Ash"
    },
    {
      "x": 14,
      "y": 24,
      "z": 9,
      "name": "Soil_Ash"
    },
    {
      "x": 14,
      "y": 34,
      "z": 9,
      "name": "Soil_Ash"
    },
    {
      "x": 14,
      "y": 35,
      "z": 9,
      "name": "Soil_Ash"
    },
    {
      "x": 14,
      "y": 36,
      "z": 9,
      "name": "Rock_Slate"
    },
    {
      "x": 14,
      "y": 37,
      "z": 9,
      "name": "Rock_Slate"
    },
    {
      "x": 14,
      "y": 38,
      "z": 9,
      "name": "Rock_Slate"
    },
    {
      "x": 14,
      "y": 39,
      "z": 9,
      "name": "Rock_Slate"
    },
    {
      "x": 14,
      "y": 11,
      "z": 10,
      "name": "Soil_Ash"
    },
    {
      "x": 14,
      "y": 12,
      "z": 10,
      "name": "Soil_Ash"
    },
    {
      "x": 14,
      "y": 13,
      "z": 10,
      "name": "Soil_Ash"
    },
    {
      "x": 14,
      "y": 14,
      "z": 10,
      "name": "Soil_Ash"
    },
    {
      "x": 14,
      "y": 15,
      "z": 10,
      "name": "Soil_Ash"
    },
    {
      "x": 14,
      "y": 16,
      "z": 10,
      "name": "Soil_Ash"
    },
    {
      "x": 14,
      "y": 17,
      "z": 10,
      "name": "Rock_Slate"
    },
    {
      "x": 14,
      "y": 18,
      "z": 10,
      "name": "Rock_Slate"
    },
    {
      "x": 14,
      "y": 19,
      "z": 10,
      "name": "Rock_Volcanic"
    },
    {
      "x": 14,
      "y": 20,
      "z": 10,
      "name": "Soil_Ash"
    },
    {
      "x": 14,
      "y": 21,
      "z": 10,
      "name": "Soil_Ash"
    },
    {
      "x": 14,
      "y": 22,
      "z": 10,
      "name": "Soil_Ash"
    },
    {
      "x": 14,
      "y": 23,
      "z": 10,
      "name": "Soil_Ash"
    },
    {
      "x": 14,
      "y": 24,
      "z": 10,
      "name": "Soil_Ash"
    },
    {
      "x": 14,
      "y": 25,
      "z": 10,
      "name": "Soil_Ash"
    },
    {
      "x": 14,
      "y": 33,
      "z": 10,
      "name": "Soil_Ash"
    },
    {
      "x": 14,
      "y": 34,
      "z": 10,
      "name": "Soil_Ash"
    },
    {
      "x": 14,
      "y": 35,
      "z": 10,
      "name": "Soil_Ash"
    },
    {
      "x": 14,
      "y": 36,
      "z": 10,
      "name": "Rock_Slate"
    },
    {
      "x": 14,
      "y": 37,
      "z": 10,
      "name": "Rock_Slate"
    },
    {
      "x": 14,
      "y": 38,
      "z": 10,
      "name": "Rock_Slate"
    },
    {
      "x": 14,
      "y": 39,
      "z": 10,
      "name": "Rock_Slate"
    },
    {
      "x": 14,
      "y": 11,
      "z": 11,
      "name": "Soil_Ash"
    },
    {
      "x": 14,
      "y": 12,
      "z": 11,
      "name": "Soil_Ash"
    },
    {
      "x": 14,
      "y": 13,
      "z": 11,
      "name": "Soil_Ash"
    },
    {
      "x": 14,
      "y": 14,
      "z": 11,
      "name": "Soil_Ash"
    },
    {
      "x": 14,
      "y": 15,
      "z": 11,
      "name": "Soil_Ash"
    },
    {
      "x": 14,
      "y": 16,
      "z": 11,
      "name": "Soil_Ash"
    },
    {
      "x": 14,
      "y": 17,
      "z": 11,
      "name": "Rock_Slate"
    },
    {
      "x": 14,
      "y": 18,
      "z": 11,
      "name": "Rock_Slate"
    },
    {
      "x": 14,
      "y": 19,
      "z": 11,
      "name": "Soil_Ash"
    },
    {
      "x": 14,
      "y": 20,
      "z": 11,
      "name": "Soil_Ash"
    },
    {
      "x": 14,
      "y": 21,
      "z": 11,
      "name": "Soil_Ash"
    },
    {
      "x": 14,
      "y": 22,
      "z": 11,
      "name": "Soil_Ash"
    },
    {
      "x": 14,
      "y": 23,
      "z": 11,
      "name": "Soil_Ash"
    },
    {
      "x": 14,
      "y": 24,
      "z": 11,
      "name": "Soil_Ash"
    },
    {
      "x": 14,
      "y": 25,
      "z": 11,
      "name": "Soil_Ash"
    },
    {
      "x": 14,
      "y": 13,
      "z": 12,
      "name": "Soil_Ash"
    },
    {
      "x": 14,
      "y": 14,
      "z": 12,
      "name": "Soil_Ash"
    },
    {
      "x": 14,
      "y": 15,
      "z": 12,
      "name": "Soil_Ash"
    },
    {
      "x": 14,
      "y": 16,
      "z": 12,
      "name": "Rock_Slate"
    },
    {
      "x": 14,
      "y": 17,
      "z": 12,
      "name": "Rock_Slate"
    },
    {
      "x": 14,
      "y": 18,
      "z": 12,
      "name": "Rock_Slate"
    },
    {
      "x": 14,
      "y": 19,
      "z": 12,
      "name": "Soil_Ash"
    },
    {
      "x": 14,
      "y": 20,
      "z": 12,
      "name": "Soil_Ash"
    },
    {
      "x": 14,
      "y": 21,
      "z": 12,
      "name": "Soil_Ash"
    },
    {
      "x": 14,
      "y": 22,
      "z": 12,
      "name": "Soil_Ash"
    },
    {
      "x": 14,
      "y": 23,
      "z": 12,
      "name": "Soil_Ash"
    },
    {
      "x": 14,
      "y": 24,
      "z": 12,
      "name": "Soil_Ash"
    },
    {
      "x": 14,
      "y": 25,
      "z": 12,
      "name": "Soil_Ash"
    },
    {
      "x": 14,
      "y": 16,
      "z": 13,
      "name": "Rock_Slate"
    },
    {
      "x": 14,
      "y": 17,
      "z": 13,
      "name": "Rock_Slate"
    },
    {
      "x": 14,
      "y": 18,
      "z": 13,
      "name": "Rock_Slate"
    },
    {
      "x": 14,
      "y": 19,
      "z": 13,
      "name": "Soil_Ash"
    },
    {
      "x": 14,
      "y": 20,
      "z": 13,
      "name": "Soil_Ash"
    },
    {
      "x": 14,
      "y": 21,
      "z": 13,
      "name": "Soil_Ash"
    },
    {
      "x": 14,
      "y": 22,
      "z": 13,
      "name": "Soil_Ash"
    },
    {
      "x": 15,
      "y": 28,
      "z": 2,
      "name": "Soil_Ash"
    },
    {
      "x": 15,
      "y": 29,
      "z": 2,
      "name": "Rock_Slate"
    },
    {
      "x": 15,
      "y": 30,
      "z": 2,
      "name": "Rock_Slate"
    },
    {
      "x": 15,
      "y": 31,
      "z": 2,
      "name": "Soil_Ash"
    },
    {
      "x": 15,
      "y": 32,
      "z": 2,
      "name": "Soil_Ash"
    },
    {
      "x": 15,
      "y": 33,
      "z": 2,
      "name": "Soil_Ash"
    },
    {
      "x": 15,
      "y": 34,
      "z": 2,
      "name": "Rock_Slate"
    },
    {
      "x": 15,
      "y": 18,
      "z": 3,
      "name": "Rock_Volcanic"
    },
    {
      "x": 15,
      "y": 19,
      "z": 3,
      "name": "Rock_Volcanic"
    },
    {
      "x": 15,
      "y": 20,
      "z": 3,
      "name": "Soil_Ash"
    },
    {
      "x": 15,
      "y": 21,
      "z": 3,
      "name": "Rock_Slate"
    },
    {
      "x": 15,
      "y": 22,
      "z": 3,
      "name": "Rock_Slate"
    },
    {
      "x": 15,
      "y": 23,
      "z": 3,
      "name": "Soil_Ash"
    },
    {
      "x": 15,
      "y": 24,
      "z": 3,
      "name": "Soil_Ash"
    },
    {
      "x": 15,
      "y": 25,
      "z": 3,
      "name": "Soil_Ash"
    },
    {
      "x": 15,
      "y": 26,
      "z": 3,
      "name": "Soil_Ash"
    },
    {
      "x": 15,
      "y": 27,
      "z": 3,
      "name": "Soil_Ash"
    },
    {
      "x": 15,
      "y": 28,
      "z": 3,
      "name": "Soil_Ash"
    },
    {
      "x": 15,
      "y": 29,
      "z": 3,
      "name": "Rock_Slate"
    },
    {
      "x": 15,
      "y": 30,
      "z": 3,
      "name": "Rock_Slate"
    },
    {
      "x": 15,
      "y": 31,
      "z": 3,
      "name": "Soil_Ash"
    },
    {
      "x": 15,
      "y": 32,
      "z": 3,
      "name": "Soil_Ash"
    },
    {
      "x": 15,
      "y": 33,
      "z": 3,
      "name": "Soil_Ash"
    },
    {
      "x": 15,
      "y": 34,
      "z": 3,
      "name": "Rock_Slate"
    },
    {
      "x": 15,
      "y": 35,
      "z": 3,
      "name": "Rock_Slate"
    },
    {
      "x": 15,
      "y": 36,
      "z": 3,
      "name": "Rock_Slate"
    },
    {
      "x": 15,
      "y": 37,
      "z": 3,
      "name": "Rock_Slate"
    },
    {
      "x": 15,
      "y": 38,
      "z": 3,
      "name": "Rock_Slate"
    },
    {
      "x": 15,
      "y": 39,
      "z": 3,
      "name": "Rock_Slate"
    },
    {
      "x": 15,
      "y": 10,
      "z": 4,
      "name": "Soil_Ash"
    },
    {
      "x": 15,
      "y": 11,
      "z": 4,
      "name": "Soil_Ash"
    },
    {
      "x": 15,
      "y": 12,
      "z": 4,
      "name": "Soil_Ash"
    },
    {
      "x": 15,
      "y": 13,
      "z": 4,
      "name": "Rock_Slate"
    },
    {
      "x": 15,
      "y": 14,
      "z": 4,
      "name": "Rock_Slate"
    },
    {
      "x": 15,
      "y": 15,
      "z": 4,
      "name": "Rock_Slate"
    },
    {
      "x": 15,
      "y": 16,
      "z": 4,
      "name": "Rock_Volcanic"
    },
    {
      "x": 15,
      "y": 17,
      "z": 4,
      "name": "Rock_Volcanic"
    },
    {
      "x": 15,
      "y": 18,
      "z": 4,
      "name": "Rock_Volcanic"
    },
    {
      "x": 15,
      "y": 19,
      "z": 4,
      "name": "Rock_Volcanic"
    },
    {
      "x": 15,
      "y": 20,
      "z": 4,
      "name": "Soil_Ash"
    },
    {
      "x": 15,
      "y": 21,
      "z": 4,
      "name": "Soil_Ash"
    },
    {
      "x": 15,
      "y": 22,
      "z": 4,
      "name": "Rock_Slate"
    },
    {
      "x": 15,
      "y": 23,
      "z": 4,
      "name": "Soil_Ash"
    },
    {
      "x": 15,
      "y": 24,
      "z": 4,
      "name": "Soil_Ash"
    },
    {
      "x": 15,
      "y": 25,
      "z": 4,
      "name": "Soil_Ash"
    },
    {
      "x": 15,
      "y": 26,
      "z": 4,
      "name": "Soil_Ash"
    },
    {
      "x": 15,
      "y": 27,
      "z": 4,
      "name": "Soil_Ash"
    },
    {
      "x": 15,
      "y": 28,
      "z": 4,
      "name": "Soil_Ash"
    },
    {
      "x": 15,
      "y": 29,
      "z": 4,
      "name": "Soil_Ash"
    },
    {
      "x": 15,
      "y": 30,
      "z": 4,
      "name": "Rock_Slate"
    },
    {
      "x": 15,
      "y": 31,
      "z": 4,
      "name": "Rock_Slate"
    },
    {
      "x": 15,
      "y": 32,
      "z": 4,
      "name": "Soil_Ash"
    },
    {
      "x": 15,
      "y": 33,
      "z": 4,
      "name": "Soil_Ash"
    },
    {
      "x": 15,
      "y": 34,
      "z": 4,
      "name": "Rock_Slate"
    },
    {
      "x": 15,
      "y": 35,
      "z": 4,
      "name": "Rock_Slate"
    },
    {
      "x": 15,
      "y": 36,
      "z": 4,
      "name": "Rock_Slate"
    },
    {
      "x": 15,
      "y": 37,
      "z": 4,
      "name": "Rock_Slate"
    },
    {
      "x": 15,
      "y": 38,
      "z": 4,
      "name": "Rock_Slate"
    },
    {
      "x": 15,
      "y": 39,
      "z": 4,
      "name": "Rock_Slate"
    },
    {
      "x": 15,
      "y": 10,
      "z": 5,
      "name": "Soil_Ash"
    },
    {
      "x": 15,
      "y": 11,
      "z": 5,
      "name": "Soil_Ash"
    },
    {
      "x": 15,
      "y": 12,
      "z": 5,
      "name": "Soil_Ash"
    },
    {
      "x": 15,
      "y": 13,
      "z": 5,
      "name": "Soil_Ash"
    },
    {
      "x": 15,
      "y": 14,
      "z": 5,
      "name": "Rock_Slate"
    },
    {
      "x": 15,
      "y": 15,
      "z": 5,
      "name": "Rock_Slate"
    },
    {
      "x": 15,
      "y": 16,
      "z": 5,
      "name": "Rock_Volcanic"
    },
    {
      "x": 15,
      "y": 17,
      "z": 5,
      "name": "Rock_Volcanic"
    },
    {
      "x": 15,
      "y": 18,
      "z": 5,
      "name": "Rock_Volcanic"
    },
    {
      "x": 15,
      "y": 19,
      "z": 5,
      "name": "Rock_Volcanic"
    },
    {
      "x": 15,
      "y": 20,
      "z": 5,
      "name": "Rock_Volcanic"
    },
    {
      "x": 15,
      "y": 21,
      "z": 5,
      "name": "Rock_Slate"
    },
    {
      "x": 15,
      "y": 22,
      "z": 5,
      "name": "Rock_Slate"
    },
    {
      "x": 15,
      "y": 23,
      "z": 5,
      "name": "Soil_Ash"
    },
    {
      "x": 15,
      "y": 24,
      "z": 5,
      "name": "Soil_Ash"
    },
    {
      "x": 15,
      "y": 25,
      "z": 5,
      "name": "Soil_Ash"
    },
    {
      "x": 15,
      "y": 26,
      "z": 5,
      "name": "Soil_Ash"
    },
    {
      "x": 15,
      "y": 27,
      "z": 5,
      "name": "Soil_Ash"
    },
    {
      "x": 15,
      "y": 28,
      "z": 5,
      "name": "Soil_Ash"
    },
    {
      "x": 15,
      "y": 29,
      "z": 5,
      "name": "Soil_Ash"
    },
    {
      "x": 15,
      "y": 30,
      "z": 5,
      "name": "Rock_Slate"
    },
    {
      "x": 15,
      "y": 31,
      "z": 5,
      "name": "Rock_Slate"
    },
    {
      "x": 15,
      "y": 32,
      "z": 5,
      "name": "Rock_Slate"
    },
    {
      "x": 15,
      "y": 33,
      "z": 5,
      "name": "Soil_Ash"
    },
    {
      "x": 15,
      "y": 34,
      "z": 5,
      "name": "Soil_Ash"
    },
    {
      "x": 15,
      "y": 35,
      "z": 5,
      "name": "Rock_Slate"
    },
    {
      "x": 15,
      "y": 36,
      "z": 5,
      "name": "Rock_Slate"
    },
    {
      "x": 15,
      "y": 37,
      "z": 5,
      "name": "Rock_Slate"
    },
    {
      "x": 15,
      "y": 38,
      "z": 5,
      "name": "Rock_Slate"
    },
    {
      "x": 15,
      "y": 39,
      "z": 5,
      "name": "Soil_Ash"
    },
    {
      "x": 15,
      "y": 10,
      "z": 6,
      "name": "Soil_Ash"
    },
    {
      "x": 15,
      "y": 11,
      "z": 6,
      "name": "Soil_Ash"
    },
    {
      "x": 15,
      "y": 12,
      "z": 6,
      "name": "Soil_Ash"
    },
    {
      "x": 15,
      "y": 13,
      "z": 6,
      "name": "Soil_Ash"
    },
    {
      "x": 15,
      "y": 14,
      "z": 6,
      "name": "Rock_Slate"
    },
    {
      "x": 15,
      "y": 15,
      "z": 6,
      "name": "Rock_Slate"
    },
    {
      "x": 15,
      "y": 16,
      "z": 6,
      "name": "Rock_Volcanic"
    },
    {
      "x": 15,
      "y": 17,
      "z": 6,
      "name": "Rock_Volcanic"
    },
    {
      "x": 15,
      "y": 18,
      "z": 6,
      "name": "Rock_Volcanic"
    },
    {
      "x": 15,
      "y": 19,
      "z": 6,
      "name": "Rock_Volcanic"
    },
    {
      "x": 15,
      "y": 20,
      "z": 6,
      "name": "Rock_Volcanic"
    },
    {
      "x": 15,
      "y": 21,
      "z": 6,
      "name": "Soil_Ash"
    },
    {
      "x": 15,
      "y": 22,
      "z": 6,
      "name": "Rock_Slate"
    },
    {
      "x": 15,
      "y": 23,
      "z": 6,
      "name": "Rock_Slate"
    },
    {
      "x": 15,
      "y": 24,
      "z": 6,
      "name": "Soil_Ash"
    },
    {
      "x": 15,
      "y": 25,
      "z": 6,
      "name": "Soil_Ash"
    },
    {
      "x": 15,
      "y": 32,
      "z": 6,
      "name": "Rock_Slate"
    },
    {
      "x": 15,
      "y": 33,
      "z": 6,
      "name": "Soil_Ash"
    },
    {
      "x": 15,
      "y": 34,
      "z": 6,
      "name": "Soil_Ash"
    },
    {
      "x": 15,
      "y": 35,
      "z": 6,
      "name": "Soil_Ash"
    },
    {
      "x": 15,
      "y": 36,
      "z": 6,
      "name": "Rock_Slate"
    },
    {
      "x": 15,
      "y": 37,
      "z": 6,
      "name": "Rock_Slate"
    },
    {
      "x": 15,
      "y": 38,
      "z": 6,
      "name": "Soil_Ash"
    },
    {
      "x": 15,
      "y": 39,
      "z": 6,
      "name": "Soil_Ash"
    },
    {
      "x": 15,
      "y": 10,
      "z": 7,
      "name": "Soil_Ash"
    },
    {
      "x": 15,
      "y": 11,
      "z": 7,
      "name": "Soil_Ash"
    },
    {
      "x": 15,
      "y": 12,
      "z": 7,
      "name": "Soil_Ash"
    },
    {
      "x": 15,
      "y": 13,
      "z": 7,
      "name": "Soil_Ash"
    },
    {
      "x": 15,
      "y": 14,
      "z": 7,
      "name": "Soil_Ash"
    },
    {
      "x": 15,
      "y": 15,
      "z": 7,
      "name": "Rock_Slate"
    },
    {
      "x": 15,
      "y": 16,
      "z": 7,
      "name": "Rock_Slate"
    },
    {
      "x": 15,
      "y": 17,
      "z": 7,
      "name": "Rock_Volcanic"
    },
    {
      "x": 15,
      "y": 18,
      "z": 7,
      "name": "Rock_Volcanic"
    },
    {
      "x": 15,
      "y": 19,
      "z": 7,
      "name": "Rock_Volcanic"
    },
    {
      "x": 15,
      "y": 20,
      "z": 7,
      "name": "Rock_Volcanic"
    },
    {
      "x": 15,
      "y": 21,
      "z": 7,
      "name": "Rock_Slate"
    },
    {
      "x": 15,
      "y": 22,
      "z": 7,
      "name": "Rock_Slate"
    },
    {
      "x": 15,
      "y": 23,
      "z": 7,
      "name": "Rock_Slate"
    },
    {
      "x": 15,
      "y": 24,
      "z": 7,
      "name": "Soil_Ash"
    },
    {
      "x": 15,
      "y": 25,
      "z": 7,
      "name": "Soil_Ash"
    },
    {
      "x": 15,
      "y": 34,
      "z": 7,
      "name": "Soil_Ash"
    },
    {
      "x": 15,
      "y": 35,
      "z": 7,
      "name": "Soil_Ash"
    },
    {
      "x": 15,
      "y": 36,
      "z": 7,
      "name": "Rock_Slate"
    },
    {
      "x": 15,
      "y": 37,
      "z": 7,
      "name": "Rock_Slate"
    },
    {
      "x": 15,
      "y": 38,
      "z": 7,
      "name": "Rock_Slate"
    },
    {
      "x": 15,
      "y": 39,
      "z": 7,
      "name": "Soil_Ash"
    },
    {
      "x": 15,
      "y": 10,
      "z": 8,
      "name": "Soil_Ash"
    },
    {
      "x": 15,
      "y": 11,
      "z": 8,
      "name": "Soil_Ash"
    },
    {
      "x": 15,
      "y": 12,
      "z": 8,
      "name": "Soil_Ash"
    },
    {
      "x": 15,
      "y": 13,
      "z": 8,
      "name": "Soil_Ash"
    },
    {
      "x": 15,
      "y": 14,
      "z": 8,
      "name": "Soil_Ash"
    },
    {
      "x": 15,
      "y": 15,
      "z": 8,
      "name": "Soil_Ash"
    },
    {
      "x": 15,
      "y": 16,
      "z": 8,
      "name": "Rock_Slate"
    },
    {
      "x": 15,
      "y": 17,
      "z": 8,
      "name": "Rock_Slate"
    },
    {
      "x": 15,
      "y": 18,
      "z": 8,
      "name": "Rock_Volcanic"
    },
    {
      "x": 15,
      "y": 19,
      "z": 8,
      "name": "Rock_Volcanic"
    },
    {
      "x": 15,
      "y": 20,
      "z": 8,
      "name": "Rock_Volcanic"
    },
    {
      "x": 15,
      "y": 21,
      "z": 8,
      "name": "Rock_Volcanic"
    },
    {
      "x": 15,
      "y": 22,
      "z": 8,
      "name": "Rock_Slate"
    },
    {
      "x": 15,
      "y": 23,
      "z": 8,
      "name": "Rock_Slate"
    },
    {
      "x": 15,
      "y": 24,
      "z": 8,
      "name": "Soil_Ash"
    },
    {
      "x": 15,
      "y": 34,
      "z": 8,
      "name": "Soil_Ash"
    },
    {
      "x": 15,
      "y": 35,
      "z": 8,
      "name": "Soil_Ash"
    },
    {
      "x": 15,
      "y": 36,
      "z": 8,
      "name": "Rock_Slate"
    },
    {
      "x": 15,
      "y": 37,
      "z": 8,
      "name": "Rock_Slate"
    },
    {
      "x": 15,
      "y": 38,
      "z": 8,
      "name": "Rock_Slate"
    },
    {
      "x": 15,
      "y": 39,
      "z": 8,
      "name": "Rock_Slate"
    },
    {
      "x": 15,
      "y": 10,
      "z": 9,
      "name": "Soil_Ash"
    },
    {
      "x": 15,
      "y": 11,
      "z": 9,
      "name": "Soil_Ash"
    },
    {
      "x": 15,
      "y": 12,
      "z": 9,
      "name": "Soil_Ash"
    },
    {
      "x": 15,
      "y": 13,
      "z": 9,
      "name": "Soil_Ash"
    },
    {
      "x": 15,
      "y": 14,
      "z": 9,
      "name": "Soil_Ash"
    },
    {
      "x": 15,
      "y": 15,
      "z": 9,
      "name": "Soil_Ash"
    },
    {
      "x": 15,
      "y": 16,
      "z": 9,
      "name": "Soil_Ash"
    },
    {
      "x": 15,
      "y": 17,
      "z": 9,
      "name": "Rock_Slate"
    },
    {
      "x": 15,
      "y": 18,
      "z": 9,
      "name": "Rock_Volcanic"
    },
    {
      "x": 15,
      "y": 19,
      "z": 9,
      "name": "Rock_Volcanic"
    },
    {
      "x": 15,
      "y": 20,
      "z": 9,
      "name": "Rock_Volcanic"
    },
    {
      "x": 15,
      "y": 21,
      "z": 9,
      "name": "Rock_Volcanic"
    },
    {
      "x": 15,
      "y": 22,
      "z": 9,
      "name": "Soil_Ash"
    },
    {
      "x": 15,
      "y": 23,
      "z": 9,
      "name": "Soil_Ash"
    },
    {
      "x": 15,
      "y": 24,
      "z": 9,
      "name": "Soil_Ash"
    },
    {
      "x": 15,
      "y": 31,
      "z": 9,
      "name": "Rock_Slate"
    },
    {
      "x": 15,
      "y": 32,
      "z": 9,
      "name": "Rock_Slate"
    },
    {
      "x": 15,
      "y": 33,
      "z": 9,
      "name": "Soil_Ash"
    },
    {
      "x": 15,
      "y": 34,
      "z": 9,
      "name": "Soil_Ash"
    },
    {
      "x": 15,
      "y": 35,
      "z": 9,
      "name": "Soil_Ash"
    },
    {
      "x": 15,
      "y": 36,
      "z": 9,
      "name": "Rock_Slate"
    },
    {
      "x": 15,
      "y": 37,
      "z": 9,
      "name": "Rock_Slate"
    },
    {
      "x": 15,
      "y": 38,
      "z": 9,
      "name": "Rock_Slate"
    },
    {
      "x": 15,
      "y": 39,
      "z": 9,
      "name": "Rock_Slate"
    },
    {
      "x": 15,
      "y": 40,
      "z": 9,
      "name": "Rock_Slate"
    },
    {
      "x": 15,
      "y": 11,
      "z": 10,
      "name": "Soil_Ash"
    },
    {
      "x": 15,
      "y": 12,
      "z": 10,
      "name": "Soil_Ash"
    },
    {
      "x": 15,
      "y": 13,
      "z": 10,
      "name": "Soil_Ash"
    },
    {
      "x": 15,
      "y": 14,
      "z": 10,
      "name": "Soil_Ash"
    },
    {
      "x": 15,
      "y": 15,
      "z": 10,
      "name": "Soil_Ash"
    },
    {
      "x": 15,
      "y": 16,
      "z": 10,
      "name": "Soil_Ash"
    },
    {
      "x": 15,
      "y": 17,
      "z": 10,
      "name": "Rock_Slate"
    },
    {
      "x": 15,
      "y": 18,
      "z": 10,
      "name": "Rock_Slate"
    },
    {
      "x": 15,
      "y": 19,
      "z": 10,
      "name": "Rock_Volcanic"
    },
    {
      "x": 15,
      "y": 20,
      "z": 10,
      "name": "Soil_Ash"
    },
    {
      "x": 15,
      "y": 21,
      "z": 10,
      "name": "Soil_Ash"
    },
    {
      "x": 15,
      "y": 22,
      "z": 10,
      "name": "Soil_Ash"
    },
    {
      "x": 15,
      "y": 23,
      "z": 10,
      "name": "Soil_Ash"
    },
    {
      "x": 15,
      "y": 24,
      "z": 10,
      "name": "Soil_Ash"
    },
    {
      "x": 15,
      "y": 25,
      "z": 10,
      "name": "Soil_Ash"
    },
    {
      "x": 15,
      "y": 26,
      "z": 10,
      "name": "Soil_Ash"
    },
    {
      "x": 15,
      "y": 27,
      "z": 10,
      "name": "Soil_Ash"
    },
    {
      "x": 15,
      "y": 28,
      "z": 10,
      "name": "Soil_Ash"
    },
    {
      "x": 15,
      "y": 29,
      "z": 10,
      "name": "Soil_Ash"
    },
    {
      "x": 15,
      "y": 30,
      "z": 10,
      "name": "Soil_Ash"
    },
    {
      "x": 15,
      "y": 31,
      "z": 10,
      "name": "Rock_Slate"
    },
    {
      "x": 15,
      "y": 32,
      "z": 10,
      "name": "Rock_Slate"
    },
    {
      "x": 15,
      "y": 33,
      "z": 10,
      "name": "Soil_Ash"
    },
    {
      "x": 15,
      "y": 34,
      "z": 10,
      "name": "Soil_Ash"
    },
    {
      "x": 15,
      "y": 35,
      "z": 10,
      "name": "Soil_Ash"
    },
    {
      "x": 15,
      "y": 36,
      "z": 10,
      "name": "Rock_Slate"
    },
    {
      "x": 15,
      "y": 37,
      "z": 10,
      "name": "Rock_Slate"
    },
    {
      "x": 15,
      "y": 38,
      "z": 10,
      "name": "Rock_Slate"
    },
    {
      "x": 15,
      "y": 39,
      "z": 10,
      "name": "Rock_Slate"
    },
    {
      "x": 15,
      "y": 40,
      "z": 10,
      "name": "Rock_Slate"
    },
    {
      "x": 15,
      "y": 11,
      "z": 11,
      "name": "Soil_Ash"
    },
    {
      "x": 15,
      "y": 12,
      "z": 11,
      "name": "Soil_Ash"
    },
    {
      "x": 15,
      "y": 13,
      "z": 11,
      "name": "Soil_Ash"
    },
    {
      "x": 15,
      "y": 14,
      "z": 11,
      "name": "Soil_Ash"
    },
    {
      "x": 15,
      "y": 15,
      "z": 11,
      "name": "Soil_Ash"
    },
    {
      "x": 15,
      "y": 16,
      "z": 11,
      "name": "Soil_Ash"
    },
    {
      "x": 15,
      "y": 17,
      "z": 11,
      "name": "Rock_Slate"
    },
    {
      "x": 15,
      "y": 18,
      "z": 11,
      "name": "Rock_Slate"
    },
    {
      "x": 15,
      "y": 19,
      "z": 11,
      "name": "Rock_Volcanic"
    },
    {
      "x": 15,
      "y": 20,
      "z": 11,
      "name": "Soil_Ash"
    },
    {
      "x": 15,
      "y": 21,
      "z": 11,
      "name": "Soil_Ash"
    },
    {
      "x": 15,
      "y": 22,
      "z": 11,
      "name": "Soil_Ash"
    },
    {
      "x": 15,
      "y": 23,
      "z": 11,
      "name": "Soil_Ash"
    },
    {
      "x": 15,
      "y": 24,
      "z": 11,
      "name": "Soil_Ash"
    },
    {
      "x": 15,
      "y": 25,
      "z": 11,
      "name": "Soil_Ash"
    },
    {
      "x": 15,
      "y": 26,
      "z": 11,
      "name": "Rock_Slate"
    },
    {
      "x": 15,
      "y": 27,
      "z": 11,
      "name": "Soil_Ash"
    },
    {
      "x": 15,
      "y": 28,
      "z": 11,
      "name": "Soil_Ash"
    },
    {
      "x": 15,
      "y": 29,
      "z": 11,
      "name": "Soil_Ash"
    },
    {
      "x": 15,
      "y": 30,
      "z": 11,
      "name": "Soil_Ash"
    },
    {
      "x": 15,
      "y": 31,
      "z": 11,
      "name": "Rock_Slate"
    },
    {
      "x": 15,
      "y": 35,
      "z": 11,
      "name": "Soil_Ash"
    },
    {
      "x": 15,
      "y": 36,
      "z": 11,
      "name": "Rock_Slate"
    },
    {
      "x": 15,
      "y": 37,
      "z": 11,
      "name": "Rock_Slate"
    },
    {
      "x": 15,
      "y": 38,
      "z": 11,
      "name": "Rock_Slate"
    },
    {
      "x": 15,
      "y": 39,
      "z": 11,
      "name": "Rock_Slate"
    },
    {
      "x": 15,
      "y": 13,
      "z": 12,
      "name": "Soil_Ash"
    },
    {
      "x": 15,
      "y": 14,
      "z": 12,
      "name": "Soil_Ash"
    },
    {
      "x": 15,
      "y": 15,
      "z": 12,
      "name": "Soil_Ash"
    },
    {
      "x": 15,
      "y": 16,
      "z": 12,
      "name": "Rock_Slate"
    },
    {
      "x": 15,
      "y": 17,
      "z": 12,
      "name": "Rock_Slate"
    },
    {
      "x": 15,
      "y": 18,
      "z": 12,
      "name": "Rock_Slate"
    },
    {
      "x": 15,
      "y": 19,
      "z": 12,
      "name": "Rock_Volcanic"
    },
    {
      "x": 15,
      "y": 20,
      "z": 12,
      "name": "Soil_Ash"
    },
    {
      "x": 15,
      "y": 21,
      "z": 12,
      "name": "Soil_Ash"
    },
    {
      "x": 15,
      "y": 22,
      "z": 12,
      "name": "Soil_Ash"
    },
    {
      "x": 15,
      "y": 23,
      "z": 12,
      "name": "Soil_Ash"
    },
    {
      "x": 15,
      "y": 24,
      "z": 12,
      "name": "Soil_Ash"
    },
    {
      "x": 15,
      "y": 25,
      "z": 12,
      "name": "Rock_Slate"
    },
    {
      "x": 15,
      "y": 36,
      "z": 12,
      "name": "Rock_Slate"
    },
    {
      "x": 15,
      "y": 37,
      "z": 12,
      "name": "Rock_Slate"
    },
    {
      "x": 15,
      "y": 38,
      "z": 12,
      "name": "Rock_Slate"
    },
    {
      "x": 15,
      "y": 15,
      "z": 13,
      "name": "Rock_Slate"
    },
    {
      "x": 15,
      "y": 16,
      "z": 13,
      "name": "Rock_Slate"
    },
    {
      "x": 15,
      "y": 17,
      "z": 13,
      "name": "Rock_Slate"
    },
    {
      "x": 15,
      "y": 18,
      "z": 13,
      "name": "Rock_Slate"
    },
    {
      "x": 15,
      "y": 19,
      "z": 13,
      "name": "Rock_Slate"
    },
    {
      "x": 15,
      "y": 20,
      "z": 13,
      "name": "Soil_Ash"
    },
    {
      "x": 15,
      "y": 21,
      "z": 13,
      "name": "Soil_Ash"
    },
    {
      "x": 15,
      "y": 22,
      "z": 13,
      "name": "Soil_Ash"
    },
    {
      "x": 15,
      "y": 23,
      "z": 13,
      "name": "Soil_Ash"
    },
    {
      "x": 15,
      "y": 24,
      "z": 13,
      "name": "Soil_Ash"
    },
    {
      "x": 15,
      "y": 25,
      "z": 13,
      "name": "Rock_Slate"
    },
    {
      "x": 15,
      "y": 19,
      "z": 14,
      "name": "Rock_Slate"
    },
    {
      "x": 15,
      "y": 20,
      "z": 14,
      "name": "Soil_Ash"
    },
    {
      "x": 15,
      "y": 21,
      "z": 14,
      "name": "Soil_Ash"
    },
    {
      "x": 16,
      "y": 28,
      "z": 2,
      "name": "Soil_Ash"
    },
    {
      "x": 16,
      "y": 29,
      "z": 2,
      "name": "Rock_Slate"
    },
    {
      "x": 16,
      "y": 30,
      "z": 2,
      "name": "Rock_Slate"
    },
    {
      "x": 16,
      "y": 31,
      "z": 2,
      "name": "Soil_Ash"
    },
    {
      "x": 16,
      "y": 32,
      "z": 2,
      "name": "Soil_Ash"
    },
    {
      "x": 16,
      "y": 33,
      "z": 2,
      "name": "Soil_Ash"
    },
    {
      "x": 16,
      "y": 34,
      "z": 2,
      "name": "Soil_Ash"
    },
    {
      "x": 16,
      "y": 11,
      "z": 3,
      "name": "Soil_Ash"
    },
    {
      "x": 16,
      "y": 12,
      "z": 3,
      "name": "Rock_Slate"
    },
    {
      "x": 16,
      "y": 13,
      "z": 3,
      "name": "Rock_Slate"
    },
    {
      "x": 16,
      "y": 14,
      "z": 3,
      "name": "Rock_Slate"
    },
    {
      "x": 16,
      "y": 18,
      "z": 3,
      "name": "Rock_Volcanic"
    },
    {
      "x": 16,
      "y": 19,
      "z": 3,
      "name": "Soil_Ash"
    },
    {
      "x": 16,
      "y": 20,
      "z": 3,
      "name": "Soil_Ash"
    },
    {
      "x": 16,
      "y": 21,
      "z": 3,
      "name": "Rock_Slate"
    },
    {
      "x": 16,
      "y": 22,
      "z": 3,
      "name": "Soil_Ash"
    },
    {
      "x": 16,
      "y": 23,
      "z": 3,
      "name": "Soil_Ash"
    },
    {
      "x": 16,
      "y": 24,
      "z": 3,
      "name": "Soil_Ash"
    },
    {
      "x": 16,
      "y": 25,
      "z": 3,
      "name": "Soil_Ash"
    },
    {
      "x": 16,
      "y": 26,
      "z": 3,
      "name": "Soil_Ash"
    },
    {
      "x": 16,
      "y": 27,
      "z": 3,
      "name": "Soil_Ash"
    },
    {
      "x": 16,
      "y": 28,
      "z": 3,
      "name": "Soil_Ash"
    },
    {
      "x": 16,
      "y": 29,
      "z": 3,
      "name": "Soil_Ash"
    },
    {
      "x": 16,
      "y": 30,
      "z": 3,
      "name": "Rock_Slate"
    },
    {
      "x": 16,
      "y": 31,
      "z": 3,
      "name": "Soil_Ash"
    },
    {
      "x": 16,
      "y": 32,
      "z": 3,
      "name": "Soil_Ash"
    },
    {
      "x": 16,
      "y": 33,
      "z": 3,
      "name": "Soil_Ash"
    },
    {
      "x": 16,
      "y": 34,
      "z": 3,
      "name": "Soil_Ash"
    },
    {
      "x": 16,
      "y": 35,
      "z": 3,
      "name": "Rock_Slate"
    },
    {
      "x": 16,
      "y": 36,
      "z": 3,
      "name": "Soil_Ash"
    },
    {
      "x": 16,
      "y": 37,
      "z": 3,
      "name": "Rock_Slate"
    },
    {
      "x": 16,
      "y": 38,
      "z": 3,
      "name": "Rock_Slate"
    },
    {
      "x": 16,
      "y": 39,
      "z": 3,
      "name": "Rock_Slate"
    },
    {
      "x": 16,
      "y": 10,
      "z": 4,
      "name": "Soil_Ash"
    },
    {
      "x": 16,
      "y": 11,
      "z": 4,
      "name": "Soil_Ash"
    },
    {
      "x": 16,
      "y": 12,
      "z": 4,
      "name": "Soil_Ash"
    },
    {
      "x": 16,
      "y": 13,
      "z": 4,
      "name": "Rock_Slate"
    },
    {
      "x": 16,
      "y": 14,
      "z": 4,
      "name": "Rock_Slate"
    },
    {
      "x": 16,
      "y": 15,
      "z": 4,
      "name": "Rock_Slate"
    },
    {
      "x": 16,
      "y": 16,
      "z": 4,
      "name": "Rock_Volcanic"
    },
    {
      "x": 16,
      "y": 17,
      "z": 4,
      "name": "Rock_Volcanic"
    },
    {
      "x": 16,
      "y": 18,
      "z": 4,
      "name": "Rock_Volcanic"
    },
    {
      "x": 16,
      "y": 19,
      "z": 4,
      "name": "Rock_Volcanic"
    },
    {
      "x": 16,
      "y": 20,
      "z": 4,
      "name": "Rock_Slate"
    },
    {
      "x": 16,
      "y": 21,
      "z": 4,
      "name": "Rock_Slate"
    },
    {
      "x": 16,
      "y": 22,
      "z": 4,
      "name": "Soil_Ash"
    },
    {
      "x": 16,
      "y": 23,
      "z": 4,
      "name": "Soil_Ash"
    },
    {
      "x": 16,
      "y": 24,
      "z": 4,
      "name": "Soil_Ash"
    },
    {
      "x": 16,
      "y": 25,
      "z": 4,
      "name": "Soil_Ash"
    },
    {
      "x": 16,
      "y": 26,
      "z": 4,
      "name": "Soil_Ash"
    },
    {
      "x": 16,
      "y": 27,
      "z": 4,
      "name": "Soil_Ash"
    },
    {
      "x": 16,
      "y": 28,
      "z": 4,
      "name": "Soil_Ash"
    },
    {
      "x": 16,
      "y": 29,
      "z": 4,
      "name": "Soil_Ash"
    },
    {
      "x": 16,
      "y": 30,
      "z": 4,
      "name": "Rock_Slate"
    },
    {
      "x": 16,
      "y": 31,
      "z": 4,
      "name": "Rock_Slate"
    },
    {
      "x": 16,
      "y": 32,
      "z": 4,
      "name": "Soil_Ash"
    },
    {
      "x": 16,
      "y": 33,
      "z": 4,
      "name": "Soil_Ash"
    },
    {
      "x": 16,
      "y": 34,
      "z": 4,
      "name": "Soil_Ash"
    },
    {
      "x": 16,
      "y": 35,
      "z": 4,
      "name": "Soil_Ash"
    },
    {
      "x": 16,
      "y": 36,
      "z": 4,
      "name": "Soil_Ash"
    },
    {
      "x": 16,
      "y": 37,
      "z": 4,
      "name": "Soil_Ash"
    },
    {
      "x": 16,
      "y": 38,
      "z": 4,
      "name": "Soil_Ash"
    },
    {
      "x": 16,
      "y": 39,
      "z": 4,
      "name": "Soil_Ash"
    },
    {
      "x": 16,
      "y": 9,
      "z": 5,
      "name": "Soil_Ash"
    },
    {
      "x": 16,
      "y": 10,
      "z": 5,
      "name": "Soil_Ash"
    },
    {
      "x": 16,
      "y": 11,
      "z": 5,
      "name": "Soil_Ash"
    },
    {
      "x": 16,
      "y": 12,
      "z": 5,
      "name": "Soil_Ash"
    },
    {
      "x": 16,
      "y": 13,
      "z": 5,
      "name": "Soil_Ash"
    },
    {
      "x": 16,
      "y": 14,
      "z": 5,
      "name": "Rock_Slate"
    },
    {
      "x": 16,
      "y": 15,
      "z": 5,
      "name": "Rock_Slate"
    },
    {
      "x": 16,
      "y": 16,
      "z": 5,
      "name": "Rock_Volcanic"
    },
    {
      "x": 16,
      "y": 17,
      "z": 5,
      "name": "Rock_Volcanic"
    },
    {
      "x": 16,
      "y": 18,
      "z": 5,
      "name": "Rock_Volcanic"
    },
    {
      "x": 16,
      "y": 19,
      "z": 5,
      "name": "Rock_Volcanic"
    },
    {
      "x": 16,
      "y": 20,
      "z": 5,
      "name": "Rock_Slate"
    },
    {
      "x": 16,
      "y": 21,
      "z": 5,
      "name": "Rock_Slate"
    },
    {
      "x": 16,
      "y": 22,
      "z": 5,
      "name": "Rock_Slate"
    },
    {
      "x": 16,
      "y": 23,
      "z": 5,
      "name": "Soil_Ash"
    },
    {
      "x": 16,
      "y": 24,
      "z": 5,
      "name": "Soil_Ash"
    },
    {
      "x": 16,
      "y": 25,
      "z": 5,
      "name": "Soil_Ash"
    },
    {
      "x": 16,
      "y": 26,
      "z": 5,
      "name": "Soil_Ash"
    },
    {
      "x": 16,
      "y": 27,
      "z": 5,
      "name": "Soil_Ash"
    },
    {
      "x": 16,
      "y": 28,
      "z": 5,
      "name": "Soil_Ash"
    },
    {
      "x": 16,
      "y": 29,
      "z": 5,
      "name": "Soil_Ash"
    },
    {
      "x": 16,
      "y": 30,
      "z": 5,
      "name": "Rock_Slate"
    },
    {
      "x": 16,
      "y": 31,
      "z": 5,
      "name": "Rock_Slate"
    },
    {
      "x": 16,
      "y": 32,
      "z": 5,
      "name": "Rock_Slate"
    },
    {
      "x": 16,
      "y": 33,
      "z": 5,
      "name": "Soil_Ash"
    },
    {
      "x": 16,
      "y": 34,
      "z": 5,
      "name": "Soil_Ash"
    },
    {
      "x": 16,
      "y": 35,
      "z": 5,
      "name": "Rock_Slate"
    },
    {
      "x": 16,
      "y": 36,
      "z": 5,
      "name": "Soil_Ash"
    },
    {
      "x": 16,
      "y": 37,
      "z": 5,
      "name": "Soil_Ash"
    },
    {
      "x": 16,
      "y": 38,
      "z": 5,
      "name": "Soil_Ash"
    },
    {
      "x": 16,
      "y": 39,
      "z": 5,
      "name": "Soil_Ash"
    },
    {
      "x": 16,
      "y": 9,
      "z": 6,
      "name": "Soil_Ash"
    },
    {
      "x": 16,
      "y": 10,
      "z": 6,
      "name": "Soil_Ash"
    },
    {
      "x": 16,
      "y": 11,
      "z": 6,
      "name": "Soil_Ash"
    },
    {
      "x": 16,
      "y": 12,
      "z": 6,
      "name": "Soil_Ash"
    },
    {
      "x": 16,
      "y": 13,
      "z": 6,
      "name": "Soil_Ash"
    },
    {
      "x": 16,
      "y": 14,
      "z": 6,
      "name": "Rock_Slate"
    },
    {
      "x": 16,
      "y": 15,
      "z": 6,
      "name": "Rock_Slate"
    },
    {
      "x": 16,
      "y": 16,
      "z": 6,
      "name": "Rock_Volcanic"
    },
    {
      "x": 16,
      "y": 17,
      "z": 6,
      "name": "Rock_Volcanic"
    },
    {
      "x": 16,
      "y": 18,
      "z": 6,
      "name": "Rock_Volcanic"
    },
    {
      "x": 16,
      "y": 19,
      "z": 6,
      "name": "Rock_Volcanic"
    },
    {
      "x": 16,
      "y": 20,
      "z": 6,
      "name": "Rock_Slate"
    },
    {
      "x": 16,
      "y": 21,
      "z": 6,
      "name": "Rock_Slate"
    },
    {
      "x": 16,
      "y": 22,
      "z": 6,
      "name": "Rock_Slate"
    },
    {
      "x": 16,
      "y": 23,
      "z": 6,
      "name": "Rock_Slate"
    },
    {
      "x": 16,
      "y": 24,
      "z": 6,
      "name": "Soil_Ash"
    },
    {
      "x": 16,
      "y": 25,
      "z": 6,
      "name": "Soil_Ash"
    },
    {
      "x": 16,
      "y": 31,
      "z": 6,
      "name": "Rock_Slate"
    },
    {
      "x": 16,
      "y": 32,
      "z": 6,
      "name": "Rock_Slate"
    },
    {
      "x": 16,
      "y": 33,
      "z": 6,
      "name": "Soil_Ash"
    },
    {
      "x": 16,
      "y": 34,
      "z": 6,
      "name": "Soil_Ash"
    },
    {
      "x": 16,
      "y": 35,
      "z": 6,
      "name": "Soil_Ash"
    },
    {
      "x": 16,
      "y": 36,
      "z": 6,
      "name": "Rock_Slate"
    },
    {
      "x": 16,
      "y": 37,
      "z": 6,
      "name": "Rock_Slate"
    },
    {
      "x": 16,
      "y": 38,
      "z": 6,
      "name": "Soil_Ash"
    },
    {
      "x": 16,
      "y": 39,
      "z": 6,
      "name": "Soil_Ash"
    },
    {
      "x": 16,
      "y": 9,
      "z": 7,
      "name": "Soil_Ash"
    },
    {
      "x": 16,
      "y": 10,
      "z": 7,
      "name": "Soil_Ash"
    },
    {
      "x": 16,
      "y": 11,
      "z": 7,
      "name": "Soil_Ash"
    },
    {
      "x": 16,
      "y": 12,
      "z": 7,
      "name": "Soil_Ash"
    },
    {
      "x": 16,
      "y": 13,
      "z": 7,
      "name": "Soil_Ash"
    },
    {
      "x": 16,
      "y": 14,
      "z": 7,
      "name": "Rock_Slate"
    },
    {
      "x": 16,
      "y": 15,
      "z": 7,
      "name": "Rock_Slate"
    },
    {
      "x": 16,
      "y": 16,
      "z": 7,
      "name": "Rock_Slate"
    },
    {
      "x": 16,
      "y": 17,
      "z": 7,
      "name": "Rock_Volcanic"
    },
    {
      "x": 16,
      "y": 18,
      "z": 7,
      "name": "Rock_Volcanic"
    },
    {
      "x": 16,
      "y": 19,
      "z": 7,
      "name": "Rock_Volcanic"
    },
    {
      "x": 16,
      "y": 20,
      "z": 7,
      "name": "Rock_Volcanic"
    },
    {
      "x": 16,
      "y": 21,
      "z": 7,
      "name": "Rock_Slate"
    },
    {
      "x": 16,
      "y": 22,
      "z": 7,
      "name": "Rock_Slate"
    },
    {
      "x": 16,
      "y": 23,
      "z": 7,
      "name": "Rock_Slate"
    },
    {
      "x": 16,
      "y": 24,
      "z": 7,
      "name": "Soil_Ash"
    },
    {
      "x": 16,
      "y": 25,
      "z": 7,
      "name": "Soil_Ash"
    },
    {
      "x": 16,
      "y": 34,
      "z": 7,
      "name": "Soil_Ash"
    },
    {
      "x": 16,
      "y": 35,
      "z": 7,
      "name": "Soil_Ash"
    },
    {
      "x": 16,
      "y": 36,
      "z": 7,
      "name": "Rock_Slate"
    },
    {
      "x": 16,
      "y": 37,
      "z": 7,
      "name": "Rock_Slate"
    },
    {
      "x": 16,
      "y": 38,
      "z": 7,
      "name": "Soil_Ash"
    },
    {
      "x": 16,
      "y": 39,
      "z": 7,
      "name": "Soil_Ash"
    },
    {
      "x": 16,
      "y": 9,
      "z": 8,
      "name": "Rock_Slate"
    },
    {
      "x": 16,
      "y": 10,
      "z": 8,
      "name": "Soil_Ash"
    },
    {
      "x": 16,
      "y": 11,
      "z": 8,
      "name": "Soil_Ash"
    },
    {
      "x": 16,
      "y": 12,
      "z": 8,
      "name": "Soil_Ash"
    },
    {
      "x": 16,
      "y": 13,
      "z": 8,
      "name": "Soil_Ash"
    },
    {
      "x": 16,
      "y": 14,
      "z": 8,
      "name": "Soil_Ash"
    },
    {
      "x": 16,
      "y": 15,
      "z": 8,
      "name": "Soil_Ash"
    },
    {
      "x": 16,
      "y": 16,
      "z": 8,
      "name": "Rock_Slate"
    },
    {
      "x": 16,
      "y": 17,
      "z": 8,
      "name": "Rock_Volcanic"
    },
    {
      "x": 16,
      "y": 18,
      "z": 8,
      "name": "Rock_Slate"
    },
    {
      "x": 16,
      "y": 19,
      "z": 8,
      "name": "Rock_Volcanic"
    },
    {
      "x": 16,
      "y": 20,
      "z": 8,
      "name": "Rock_Volcanic"
    },
    {
      "x": 16,
      "y": 21,
      "z": 8,
      "name": "Rock_Slate"
    },
    {
      "x": 16,
      "y": 22,
      "z": 8,
      "name": "Rock_Slate"
    },
    {
      "x": 16,
      "y": 23,
      "z": 8,
      "name": "Rock_Slate"
    },
    {
      "x": 16,
      "y": 24,
      "z": 8,
      "name": "Soil_Ash"
    },
    {
      "x": 16,
      "y": 34,
      "z": 8,
      "name": "Soil_Ash"
    },
    {
      "x": 16,
      "y": 35,
      "z": 8,
      "name": "Soil_Ash"
    },
    {
      "x": 16,
      "y": 36,
      "z": 8,
      "name": "Rock_Slate"
    },
    {
      "x": 16,
      "y": 37,
      "z": 8,
      "name": "Rock_Slate"
    },
    {
      "x": 16,
      "y": 38,
      "z": 8,
      "name": "Soil_Ash"
    },
    {
      "x": 16,
      "y": 39,
      "z": 8,
      "name": "Soil_Ash"
    },
    {
      "x": 16,
      "y": 40,
      "z": 8,
      "name": "Soil_Ash"
    },
    {
      "x": 16,
      "y": 10,
      "z": 9,
      "name": "Rock_Slate"
    },
    {
      "x": 16,
      "y": 11,
      "z": 9,
      "name": "Soil_Ash"
    },
    {
      "x": 16,
      "y": 12,
      "z": 9,
      "name": "Soil_Ash"
    },
    {
      "x": 16,
      "y": 13,
      "z": 9,
      "name": "Soil_Ash"
    },
    {
      "x": 16,
      "y": 14,
      "z": 9,
      "name": "Soil_Ash"
    },
    {
      "x": 16,
      "y": 15,
      "z": 9,
      "name": "Soil_Ash"
    },
    {
      "x": 16,
      "y": 16,
      "z": 9,
      "name": "Rock_Slate"
    },
    {
      "x": 16,
      "y": 17,
      "z": 9,
      "name": "Rock_Slate"
    },
    {
      "x": 16,
      "y": 18,
      "z": 9,
      "name": "Rock_Slate"
    },
    {
      "x": 16,
      "y": 19,
      "z": 9,
      "name": "Rock_Volcanic"
    },
    {
      "x": 16,
      "y": 20,
      "z": 9,
      "name": "Rock_Volcanic"
    },
    {
      "x": 16,
      "y": 21,
      "z": 9,
      "name": "Rock_Slate"
    },
    {
      "x": 16,
      "y": 22,
      "z": 9,
      "name": "Rock_Volcanic"
    },
    {
      "x": 16,
      "y": 23,
      "z": 9,
      "name": "Rock_Slate"
    },
    {
      "x": 16,
      "y": 24,
      "z": 9,
      "name": "Soil_Ash"
    },
    {
      "x": 16,
      "y": 30,
      "z": 9,
      "name": "Soil_Ash"
    },
    {
      "x": 16,
      "y": 31,
      "z": 9,
      "name": "Rock_Slate"
    },
    {
      "x": 16,
      "y": 32,
      "z": 9,
      "name": "Rock_Slate"
    },
    {
      "x": 16,
      "y": 33,
      "z": 9,
      "name": "Rock_Slate"
    },
    {
      "x": 16,
      "y": 34,
      "z": 9,
      "name": "Soil_Ash"
    },
    {
      "x": 16,
      "y": 35,
      "z": 9,
      "name": "Rock_Slate"
    },
    {
      "x": 16,
      "y": 36,
      "z": 9,
      "name": "Rock_Slate"
    },
    {
      "x": 16,
      "y": 37,
      "z": 9,
      "name": "Rock_Slate"
    },
    {
      "x": 16,
      "y": 38,
      "z": 9,
      "name": "Rock_Slate"
    },
    {
      "x": 16,
      "y": 39,
      "z": 9,
      "name": "Rock_Slate"
    },
    {
      "x": 16,
      "y": 40,
      "z": 9,
      "name": "Rock_Slate"
    },
    {
      "x": 16,
      "y": 11,
      "z": 10,
      "name": "Soil_Ash"
    },
    {
      "x": 16,
      "y": 12,
      "z": 10,
      "name": "Soil_Ash"
    },
    {
      "x": 16,
      "y": 13,
      "z": 10,
      "name": "Soil_Ash"
    },
    {
      "x": 16,
      "y": 14,
      "z": 10,
      "name": "Soil_Ash"
    },
    {
      "x": 16,
      "y": 15,
      "z": 10,
      "name": "Soil_Ash"
    },
    {
      "x": 16,
      "y": 16,
      "z": 10,
      "name": "Rock_Slate"
    },
    {
      "x": 16,
      "y": 17,
      "z": 10,
      "name": "Rock_Slate"
    },
    {
      "x": 16,
      "y": 18,
      "z": 10,
      "name": "Rock_Slate"
    },
    {
      "x": 16,
      "y": 19,
      "z": 10,
      "name": "Rock_Volcanic"
    },
    {
      "x": 16,
      "y": 20,
      "z": 10,
      "name": "Rock_Volcanic"
    },
    {
      "x": 16,
      "y": 21,
      "z": 10,
      "name": "Rock_Volcanic"
    },
    {
      "x": 16,
      "y": 22,
      "z": 10,
      "name": "Rock_Volcanic"
    },
    {
      "x": 16,
      "y": 23,
      "z": 10,
      "name": "Soil_Ash"
    },
    {
      "x": 16,
      "y": 24,
      "z": 10,
      "name": "Soil_Ash"
    },
    {
      "x": 16,
      "y": 25,
      "z": 10,
      "name": "Soil_Ash"
    },
    {
      "x": 16,
      "y": 26,
      "z": 10,
      "name": "Soil_Ash"
    },
    {
      "x": 16,
      "y": 27,
      "z": 10,
      "name": "Soil_Ash"
    },
    {
      "x": 16,
      "y": 28,
      "z": 10,
      "name": "Soil_Ash"
    },
    {
      "x": 16,
      "y": 29,
      "z": 10,
      "name": "Soil_Ash"
    },
    {
      "x": 16,
      "y": 30,
      "z": 10,
      "name": "Soil_Ash"
    },
    {
      "x": 16,
      "y": 31,
      "z": 10,
      "name": "Rock_Slate"
    },
    {
      "x": 16,
      "y": 32,
      "z": 10,
      "name": "Rock_Slate"
    },
    {
      "x": 16,
      "y": 33,
      "z": 10,
      "name": "Rock_Slate"
    },
    {
      "x": 16,
      "y": 34,
      "z": 10,
      "name": "Soil_Ash"
    },
    {
      "x": 16,
      "y": 35,
      "z": 10,
      "name": "Rock_Slate"
    },
    {
      "x": 16,
      "y": 36,
      "z": 10,
      "name": "Rock_Slate"
    },
    {
      "x": 16,
      "y": 37,
      "z": 10,
      "name": "Rock_Slate"
    },
    {
      "x": 16,
      "y": 38,
      "z": 10,
      "name": "Rock_Slate"
    },
    {
      "x": 16,
      "y": 39,
      "z": 10,
      "name": "Rock_Slate"
    },
    {
      "x": 16,
      "y": 40,
      "z": 10,
      "name": "Rock_Slate"
    },
    {
      "x": 16,
      "y": 11,
      "z": 11,
      "name": "Soil_Ash"
    },
    {
      "x": 16,
      "y": 12,
      "z": 11,
      "name": "Soil_Ash"
    },
    {
      "x": 16,
      "y": 13,
      "z": 11,
      "name": "Soil_Ash"
    },
    {
      "x": 16,
      "y": 14,
      "z": 11,
      "name": "Soil_Ash"
    },
    {
      "x": 16,
      "y": 15,
      "z": 11,
      "name": "Soil_Ash"
    },
    {
      "x": 16,
      "y": 16,
      "z": 11,
      "name": "Rock_Slate"
    },
    {
      "x": 16,
      "y": 17,
      "z": 11,
      "name": "Rock_Slate"
    },
    {
      "x": 16,
      "y": 18,
      "z": 11,
      "name": "Rock_Slate"
    },
    {
      "x": 16,
      "y": 19,
      "z": 11,
      "name": "Rock_Slate"
    },
    {
      "x": 16,
      "y": 20,
      "z": 11,
      "name": "Rock_Volcanic"
    },
    {
      "x": 16,
      "y": 21,
      "z": 11,
      "name": "Soil_Ash"
    },
    {
      "x": 16,
      "y": 22,
      "z": 11,
      "name": "Soil_Ash"
    },
    {
      "x": 16,
      "y": 23,
      "z": 11,
      "name": "Soil_Ash"
    },
    {
      "x": 16,
      "y": 24,
      "z": 11,
      "name": "Soil_Ash"
    },
    {
      "x": 16,
      "y": 25,
      "z": 11,
      "name": "Soil_Ash"
    },
    {
      "x": 16,
      "y": 26,
      "z": 11,
      "name": "Soil_Ash"
    },
    {
      "x": 16,
      "y": 27,
      "z": 11,
      "name": "Soil_Ash"
    },
    {
      "x": 16,
      "y": 28,
      "z": 11,
      "name": "Soil_Ash"
    },
    {
      "x": 16,
      "y": 29,
      "z": 11,
      "name": "Soil_Ash"
    },
    {
      "x": 16,
      "y": 30,
      "z": 11,
      "name": "Soil_Ash"
    },
    {
      "x": 16,
      "y": 31,
      "z": 11,
      "name": "Soil_Ash"
    },
    {
      "x": 16,
      "y": 32,
      "z": 11,
      "name": "Rock_Slate"
    },
    {
      "x": 16,
      "y": 33,
      "z": 11,
      "name": "Rock_Slate"
    },
    {
      "x": 16,
      "y": 34,
      "z": 11,
      "name": "Soil_Ash"
    },
    {
      "x": 16,
      "y": 35,
      "z": 11,
      "name": "Soil_Ash"
    },
    {
      "x": 16,
      "y": 36,
      "z": 11,
      "name": "Rock_Slate"
    },
    {
      "x": 16,
      "y": 37,
      "z": 11,
      "name": "Rock_Slate"
    },
    {
      "x": 16,
      "y": 38,
      "z": 11,
      "name": "Rock_Slate"
    },
    {
      "x": 16,
      "y": 39,
      "z": 11,
      "name": "Rock_Slate"
    },
    {
      "x": 16,
      "y": 12,
      "z": 12,
      "name": "Rock_Slate"
    },
    {
      "x": 16,
      "y": 13,
      "z": 12,
      "name": "Soil_Ash"
    },
    {
      "x": 16,
      "y": 14,
      "z": 12,
      "name": "Soil_Ash"
    },
    {
      "x": 16,
      "y": 15,
      "z": 12,
      "name": "Soil_Ash"
    },
    {
      "x": 16,
      "y": 16,
      "z": 12,
      "name": "Rock_Slate"
    },
    {
      "x": 16,
      "y": 17,
      "z": 12,
      "name": "Rock_Slate"
    },
    {
      "x": 16,
      "y": 18,
      "z": 12,
      "name": "Rock_Slate"
    },
    {
      "x": 16,
      "y": 19,
      "z": 12,
      "name": "Rock_Slate"
    },
    {
      "x": 16,
      "y": 20,
      "z": 12,
      "name": "Soil_Ash"
    },
    {
      "x": 16,
      "y": 21,
      "z": 12,
      "name": "Soil_Ash"
    },
    {
      "x": 16,
      "y": 22,
      "z": 12,
      "name": "Soil_Ash"
    },
    {
      "x": 16,
      "y": 23,
      "z": 12,
      "name": "Soil_Ash"
    },
    {
      "x": 16,
      "y": 24,
      "z": 12,
      "name": "Rock_Slate"
    },
    {
      "x": 16,
      "y": 25,
      "z": 12,
      "name": "Soil_Ash"
    },
    {
      "x": 16,
      "y": 26,
      "z": 12,
      "name": "Rock_Slate"
    },
    {
      "x": 16,
      "y": 27,
      "z": 12,
      "name": "Soil_Ash"
    },
    {
      "x": 16,
      "y": 28,
      "z": 12,
      "name": "Soil_Ash"
    },
    {
      "x": 16,
      "y": 29,
      "z": 12,
      "name": "Soil_Ash"
    },
    {
      "x": 16,
      "y": 36,
      "z": 12,
      "name": "Soil_Ash"
    },
    {
      "x": 16,
      "y": 37,
      "z": 12,
      "name": "Rock_Slate"
    },
    {
      "x": 16,
      "y": 38,
      "z": 12,
      "name": "Rock_Slate"
    },
    {
      "x": 16,
      "y": 15,
      "z": 13,
      "name": "Rock_Slate"
    },
    {
      "x": 16,
      "y": 16,
      "z": 13,
      "name": "Rock_Slate"
    },
    {
      "x": 16,
      "y": 17,
      "z": 13,
      "name": "Rock_Slate"
    },
    {
      "x": 16,
      "y": 18,
      "z": 13,
      "name": "Rock_Slate"
    },
    {
      "x": 16,
      "y": 19,
      "z": 13,
      "name": "Rock_Slate"
    },
    {
      "x": 16,
      "y": 20,
      "z": 13,
      "name": "Rock_Volcanic"
    },
    {
      "x": 16,
      "y": 21,
      "z": 13,
      "name": "Soil_Ash"
    },
    {
      "x": 16,
      "y": 22,
      "z": 13,
      "name": "Soil_Ash"
    },
    {
      "x": 16,
      "y": 23,
      "z": 13,
      "name": "Soil_Ash"
    },
    {
      "x": 16,
      "y": 24,
      "z": 13,
      "name": "Rock_Slate"
    },
    {
      "x": 16,
      "y": 25,
      "z": 13,
      "name": "Rock_Slate"
    },
    {
      "x": 16,
      "y": 26,
      "z": 13,
      "name": "Rock_Slate"
    },
    {
      "x": 16,
      "y": 18,
      "z": 14,
      "name": "Rock_Slate"
    },
    {
      "x": 16,
      "y": 19,
      "z": 14,
      "name": "Rock_Slate"
    },
    {
      "x": 16,
      "y": 20,
      "z": 14,
      "name": "Rock_Volcanic"
    },
    {
      "x": 16,
      "y": 21,
      "z": 14,
      "name": "Rock_Volcanic"
    },
    {
      "x": 16,
      "y": 22,
      "z": 14,
      "name": "Soil_Ash"
    },
    {
      "x": 17,
      "y": 10,
      "z": 3,
      "name": "Rock_Slate"
    },
    {
      "x": 17,
      "y": 11,
      "z": 3,
      "name": "Rock_Slate"
    },
    {
      "x": 17,
      "y": 12,
      "z": 3,
      "name": "Rock_Slate"
    },
    {
      "x": 17,
      "y": 13,
      "z": 3,
      "name": "Rock_Slate"
    },
    {
      "x": 17,
      "y": 14,
      "z": 3,
      "name": "Rock_Slate"
    },
    {
      "x": 17,
      "y": 15,
      "z": 3,
      "name": "Rock_Slate"
    },
    {
      "x": 17,
      "y": 18,
      "z": 3,
      "name": "Rock_Volcanic"
    },
    {
      "x": 17,
      "y": 19,
      "z": 3,
      "name": "Soil_Ash"
    },
    {
      "x": 17,
      "y": 20,
      "z": 3,
      "name": "Soil_Ash"
    },
    {
      "x": 17,
      "y": 21,
      "z": 3,
      "name": "Rock_Slate"
    },
    {
      "x": 17,
      "y": 22,
      "z": 3,
      "name": "Soil_Ash"
    },
    {
      "x": 17,
      "y": 23,
      "z": 3,
      "name": "Soil_Ash"
    },
    {
      "x": 17,
      "y": 24,
      "z": 3,
      "name": "Soil_Ash"
    },
    {
      "x": 17,
      "y": 25,
      "z": 3,
      "name": "Soil_Ash"
    },
    {
      "x": 17,
      "y": 26,
      "z": 3,
      "name": "Soil_Ash"
    },
    {
      "x": 17,
      "y": 27,
      "z": 3,
      "name": "Soil_Ash"
    },
    {
      "x": 17,
      "y": 28,
      "z": 3,
      "name": "Soil_Ash"
    },
    {
      "x": 17,
      "y": 29,
      "z": 3,
      "name": "Soil_Ash"
    },
    {
      "x": 17,
      "y": 30,
      "z": 3,
      "name": "Rock_Slate"
    },
    {
      "x": 17,
      "y": 31,
      "z": 3,
      "name": "Rock_Slate"
    },
    {
      "x": 17,
      "y": 32,
      "z": 3,
      "name": "Soil_Ash"
    },
    {
      "x": 17,
      "y": 33,
      "z": 3,
      "name": "Soil_Ash"
    },
    {
      "x": 17,
      "y": 34,
      "z": 3,
      "name": "Soil_Ash"
    },
    {
      "x": 17,
      "y": 35,
      "z": 3,
      "name": "Soil_Ash"
    },
    {
      "x": 17,
      "y": 36,
      "z": 3,
      "name": "Soil_Ash"
    },
    {
      "x": 17,
      "y": 37,
      "z": 3,
      "name": "Soil_Ash"
    },
    {
      "x": 17,
      "y": 38,
      "z": 3,
      "name": "Soil_Ash"
    },
    {
      "x": 17,
      "y": 10,
      "z": 4,
      "name": "Soil_Ash"
    },
    {
      "x": 17,
      "y": 11,
      "z": 4,
      "name": "Soil_Ash"
    },
    {
      "x": 17,
      "y": 12,
      "z": 4,
      "name": "Soil_Ash"
    },
    {
      "x": 17,
      "y": 13,
      "z": 4,
      "name": "Rock_Slate"
    },
    {
      "x": 17,
      "y": 14,
      "z": 4,
      "name": "Rock_Slate"
    },
    {
      "x": 17,
      "y": 15,
      "z": 4,
      "name": "Rock_Slate"
    },
    {
      "x": 17,
      "y": 16,
      "z": 4,
      "name": "Rock_Volcanic"
    },
    {
      "x": 17,
      "y": 17,
      "z": 4,
      "name": "Rock_Volcanic"
    },
    {
      "x": 17,
      "y": 18,
      "z": 4,
      "name": "Rock_Volcanic"
    },
    {
      "x": 17,
      "y": 19,
      "z": 4,
      "name": "Soil_Ash"
    },
    {
      "x": 17,
      "y": 20,
      "z": 4,
      "name": "Rock_Slate"
    },
    {
      "x": 17,
      "y": 21,
      "z": 4,
      "name": "Rock_Slate"
    },
    {
      "x": 17,
      "y": 22,
      "z": 4,
      "name": "Soil_Ash"
    },
    {
      "x": 17,
      "y": 23,
      "z": 4,
      "name": "Soil_Ash"
    },
    {
      "x": 17,
      "y": 24,
      "z": 4,
      "name": "Soil_Ash"
    },
    {
      "x": 17,
      "y": 25,
      "z": 4,
      "name": "Soil_Ash"
    },
    {
      "x": 17,
      "y": 26,
      "z": 4,
      "name": "Soil_Ash"
    },
    {
      "x": 17,
      "y": 27,
      "z": 4,
      "name": "Soil_Ash"
    },
    {
      "x": 17,
      "y": 28,
      "z": 4,
      "name": "Soil_Ash"
    },
    {
      "x": 17,
      "y": 29,
      "z": 4,
      "name": "Soil_Ash"
    },
    {
      "x": 17,
      "y": 30,
      "z": 4,
      "name": "Rock_Slate"
    },
    {
      "x": 17,
      "y": 31,
      "z": 4,
      "name": "Rock_Slate"
    },
    {
      "x": 17,
      "y": 32,
      "z": 4,
      "name": "Soil_Ash"
    },
    {
      "x": 17,
      "y": 33,
      "z": 4,
      "name": "Soil_Ash"
    },
    {
      "x": 17,
      "y": 34,
      "z": 4,
      "name": "Soil_Ash"
    },
    {
      "x": 17,
      "y": 35,
      "z": 4,
      "name": "Soil_Ash"
    },
    {
      "x": 17,
      "y": 36,
      "z": 4,
      "name": "Soil_Ash"
    },
    {
      "x": 17,
      "y": 37,
      "z": 4,
      "name": "Soil_Ash"
    },
    {
      "x": 17,
      "y": 38,
      "z": 4,
      "name": "Soil_Ash"
    },
    {
      "x": 17,
      "y": 39,
      "z": 4,
      "name": "Soil_Ash"
    },
    {
      "x": 17,
      "y": 8,
      "z": 5,
      "name": "Rock_Slate"
    },
    {
      "x": 17,
      "y": 9,
      "z": 5,
      "name": "Rock_Slate"
    },
    {
      "x": 17,
      "y": 10,
      "z": 5,
      "name": "Soil_Ash"
    },
    {
      "x": 17,
      "y": 11,
      "z": 5,
      "name": "Soil_Ash"
    },
    {
      "x": 17,
      "y": 12,
      "z": 5,
      "name": "Soil_Ash"
    },
    {
      "x": 17,
      "y": 13,
      "z": 5,
      "name": "Rock_Slate"
    },
    {
      "x": 17,
      "y": 14,
      "z": 5,
      "name": "Rock_Slate"
    },
    {
      "x": 17,
      "y": 15,
      "z": 5,
      "name": "Rock_Slate"
    },
    {
      "x": 17,
      "y": 16,
      "z": 5,
      "name": "Rock_Volcanic"
    },
    {
      "x": 17,
      "y": 17,
      "z": 5,
      "name": "Rock_Volcanic"
    },
    {
      "x": 17,
      "y": 18,
      "z": 5,
      "name": "Rock_Volcanic"
    },
    {
      "x": 17,
      "y": 19,
      "z": 5,
      "name": "Rock_Slate"
    },
    {
      "x": 17,
      "y": 20,
      "z": 5,
      "name": "Rock_Slate"
    },
    {
      "x": 17,
      "y": 21,
      "z": 5,
      "name": "Rock_Slate"
    },
    {
      "x": 17,
      "y": 22,
      "z": 5,
      "name": "Soil_Ash"
    },
    {
      "x": 17,
      "y": 23,
      "z": 5,
      "name": "Soil_Ash"
    },
    {
      "x": 17,
      "y": 24,
      "z": 5,
      "name": "Soil_Ash"
    },
    {
      "x": 17,
      "y": 25,
      "z": 5,
      "name": "Soil_Ash"
    },
    {
      "x": 17,
      "y": 26,
      "z": 5,
      "name": "Soil_Ash"
    },
    {
      "x": 17,
      "y": 27,
      "z": 5,
      "name": "Soil_Ash"
    },
    {
      "x": 17,
      "y": 28,
      "z": 5,
      "name": "Soil_Ash"
    },
    {
      "x": 17,
      "y": 29,
      "z": 5,
      "name": "Soil_Ash"
    },
    {
      "x": 17,
      "y": 30,
      "z": 5,
      "name": "Rock_Slate"
    },
    {
      "x": 17,
      "y": 31,
      "z": 5,
      "name": "Rock_Slate"
    },
    {
      "x": 17,
      "y": 32,
      "z": 5,
      "name": "Rock_Slate"
    },
    {
      "x": 17,
      "y": 33,
      "z": 5,
      "name": "Soil_Ash"
    },
    {
      "x": 17,
      "y": 34,
      "z": 5,
      "name": "Rock_Slate"
    },
    {
      "x": 17,
      "y": 35,
      "z": 5,
      "name": "Soil_Ash"
    },
    {
      "x": 17,
      "y": 36,
      "z": 5,
      "name": "Soil_Ash"
    },
    {
      "x": 17,
      "y": 37,
      "z": 5,
      "name": "Soil_Ash"
    },
    {
      "x": 17,
      "y": 38,
      "z": 5,
      "name": "Soil_Ash"
    },
    {
      "x": 17,
      "y": 39,
      "z": 5,
      "name": "Soil_Ash"
    },
    {
      "x": 17,
      "y": 8,
      "z": 6,
      "name": "Rock_Slate"
    },
    {
      "x": 17,
      "y": 9,
      "z": 6,
      "name": "Rock_Slate"
    },
    {
      "x": 17,
      "y": 10,
      "z": 6,
      "name": "Soil_Ash"
    },
    {
      "x": 17,
      "y": 11,
      "z": 6,
      "name": "Soil_Ash"
    },
    {
      "x": 17,
      "y": 12,
      "z": 6,
      "name": "Soil_Ash"
    },
    {
      "x": 17,
      "y": 13,
      "z": 6,
      "name": "Rock_Slate"
    },
    {
      "x": 17,
      "y": 14,
      "z": 6,
      "name": "Rock_Slate"
    },
    {
      "x": 17,
      "y": 15,
      "z": 6,
      "name": "Rock_Slate"
    },
    {
      "x": 17,
      "y": 16,
      "z": 6,
      "name": "Rock_Volcanic"
    },
    {
      "x": 17,
      "y": 17,
      "z": 6,
      "name": "Rock_Volcanic"
    },
    {
      "x": 17,
      "y": 18,
      "z": 6,
      "name": "Rock_Volcanic"
    },
    {
      "x": 17,
      "y": 19,
      "z": 6,
      "name": "Rock_Volcanic"
    },
    {
      "x": 17,
      "y": 20,
      "z": 6,
      "name": "Rock_Slate"
    },
    {
      "x": 17,
      "y": 21,
      "z": 6,
      "name": "Rock_Slate"
    },
    {
      "x": 17,
      "y": 22,
      "z": 6,
      "name": "Rock_Slate"
    },
    {
      "x": 17,
      "y": 23,
      "z": 6,
      "name": "Soil_Ash"
    },
    {
      "x": 17,
      "y": 24,
      "z": 6,
      "name": "Soil_Ash"
    },
    {
      "x": 17,
      "y": 25,
      "z": 6,
      "name": "Soil_Ash"
    },
    {
      "x": 17,
      "y": 30,
      "z": 6,
      "name": "Rock_Slate"
    },
    {
      "x": 17,
      "y": 31,
      "z": 6,
      "name": "Rock_Slate"
    },
    {
      "x": 17,
      "y": 32,
      "z": 6,
      "name": "Soil_Ash"
    },
    {
      "x": 17,
      "y": 33,
      "z": 6,
      "name": "Soil_Ash"
    },
    {
      "x": 17,
      "y": 34,
      "z": 6,
      "name": "Soil_Ash"
    },
    {
      "x": 17,
      "y": 35,
      "z": 6,
      "name": "Soil_Ash"
    },
    {
      "x": 17,
      "y": 36,
      "z": 6,
      "name": "Soil_Ash"
    },
    {
      "x": 17,
      "y": 37,
      "z": 6,
      "name": "Soil_Ash"
    },
    {
      "x": 17,
      "y": 38,
      "z": 6,
      "name": "Soil_Ash"
    },
    {
      "x": 17,
      "y": 39,
      "z": 6,
      "name": "Soil_Ash"
    },
    {
      "x": 17,
      "y": 8,
      "z": 7,
      "name": "Rock_Slate"
    },
    {
      "x": 17,
      "y": 9,
      "z": 7,
      "name": "Rock_Slate"
    },
    {
      "x": 17,
      "y": 10,
      "z": 7,
      "name": "Soil_Ash"
    },
    {
      "x": 17,
      "y": 11,
      "z": 7,
      "name": "Soil_Ash"
    },
    {
      "x": 17,
      "y": 12,
      "z": 7,
      "name": "Soil_Ash"
    },
    {
      "x": 17,
      "y": 13,
      "z": 7,
      "name": "Rock_Slate"
    },
    {
      "x": 17,
      "y": 14,
      "z": 7,
      "name": "Rock_Slate"
    },
    {
      "x": 17,
      "y": 15,
      "z": 7,
      "name": "Rock_Slate"
    },
    {
      "x": 17,
      "y": 16,
      "z": 7,
      "name": "Rock_Volcanic"
    },
    {
      "x": 17,
      "y": 17,
      "z": 7,
      "name": "Rock_Volcanic"
    },
    {
      "x": 17,
      "y": 18,
      "z": 7,
      "name": "Rock_Volcanic"
    },
    {
      "x": 17,
      "y": 19,
      "z": 7,
      "name": "Rock_Volcanic"
    },
    {
      "x": 17,
      "y": 20,
      "z": 7,
      "name": "Rock_Slate"
    },
    {
      "x": 17,
      "y": 21,
      "z": 7,
      "name": "Rock_Slate"
    },
    {
      "x": 17,
      "y": 22,
      "z": 7,
      "name": "Rock_Slate"
    },
    {
      "x": 17,
      "y": 23,
      "z": 7,
      "name": "Rock_Slate"
    },
    {
      "x": 17,
      "y": 24,
      "z": 7,
      "name": "Soil_Ash"
    },
    {
      "x": 17,
      "y": 25,
      "z": 7,
      "name": "Soil_Ash"
    },
    {
      "x": 17,
      "y": 33,
      "z": 7,
      "name": "Soil_Ash"
    },
    {
      "x": 17,
      "y": 34,
      "z": 7,
      "name": "Soil_Ash"
    },
    {
      "x": 17,
      "y": 35,
      "z": 7,
      "name": "Rock_Slate"
    },
    {
      "x": 17,
      "y": 36,
      "z": 7,
      "name": "Rock_Slate"
    },
    {
      "x": 17,
      "y": 37,
      "z": 7,
      "name": "Soil_Ash"
    },
    {
      "x": 17,
      "y": 38,
      "z": 7,
      "name": "Soil_Ash"
    },
    {
      "x": 17,
      "y": 39,
      "z": 7,
      "name": "Soil_Ash"
    },
    {
      "x": 17,
      "y": 9,
      "z": 8,
      "name": "Rock_Slate"
    },
    {
      "x": 17,
      "y": 10,
      "z": 8,
      "name": "Soil_Ash"
    },
    {
      "x": 17,
      "y": 11,
      "z": 8,
      "name": "Soil_Ash"
    },
    {
      "x": 17,
      "y": 12,
      "z": 8,
      "name": "Soil_Ash"
    },
    {
      "x": 17,
      "y": 13,
      "z": 8,
      "name": "Rock_Slate"
    },
    {
      "x": 17,
      "y": 14,
      "z": 8,
      "name": "Rock_Slate"
    },
    {
      "x": 17,
      "y": 15,
      "z": 8,
      "name": "Rock_Slate"
    },
    {
      "x": 17,
      "y": 16,
      "z": 8,
      "name": "Rock_Slate"
    },
    {
      "x": 17,
      "y": 17,
      "z": 8,
      "name": "Rock_Volcanic"
    },
    {
      "x": 17,
      "y": 18,
      "z": 8,
      "name": "Rock_Slate"
    },
    {
      "x": 17,
      "y": 19,
      "z": 8,
      "name": "Rock_Volcanic"
    },
    {
      "x": 17,
      "y": 20,
      "z": 8,
      "name": "Rock_Slate"
    },
    {
      "x": 17,
      "y": 21,
      "z": 8,
      "name": "Rock_Slate"
    },
    {
      "x": 17,
      "y": 22,
      "z": 8,
      "name": "Rock_Slate"
    },
    {
      "x": 17,
      "y": 23,
      "z": 8,
      "name": "Rock_Slate"
    },
    {
      "x": 17,
      "y": 24,
      "z": 8,
      "name": "Soil_Ash"
    },
    {
      "x": 17,
      "y": 25,
      "z": 8,
      "name": "Soil_Ash"
    },
    {
      "x": 17,
      "y": 34,
      "z": 8,
      "name": "Soil_Ash"
    },
    {
      "x": 17,
      "y": 35,
      "z": 8,
      "name": "Rock_Slate"
    },
    {
      "x": 17,
      "y": 36,
      "z": 8,
      "name": "Rock_Slate"
    },
    {
      "x": 17,
      "y": 37,
      "z": 8,
      "name": "Rock_Slate"
    },
    {
      "x": 17,
      "y": 38,
      "z": 8,
      "name": "Soil_Ash"
    },
    {
      "x": 17,
      "y": 39,
      "z": 8,
      "name": "Soil_Ash"
    },
    {
      "x": 17,
      "y": 40,
      "z": 8,
      "name": "Soil_Ash"
    },
    {
      "x": 17,
      "y": 9,
      "z": 9,
      "name": "Rock_Slate"
    },
    {
      "x": 17,
      "y": 10,
      "z": 9,
      "name": "Rock_Slate"
    },
    {
      "x": 17,
      "y": 11,
      "z": 9,
      "name": "Soil_Ash"
    },
    {
      "x": 17,
      "y": 12,
      "z": 9,
      "name": "Soil_Ash"
    },
    {
      "x": 17,
      "y": 13,
      "z": 9,
      "name": "Soil_Ash"
    },
    {
      "x": 17,
      "y": 14,
      "z": 9,
      "name": "Soil_Ash"
    },
    {
      "x": 17,
      "y": 15,
      "z": 9,
      "name": "Rock_Slate"
    },
    {
      "x": 17,
      "y": 16,
      "z": 9,
      "name": "Rock_Slate"
    },
    {
      "x": 17,
      "y": 17,
      "z": 9,
      "name": "Rock_Slate"
    },
    {
      "x": 17,
      "y": 18,
      "z": 9,
      "name": "Rock_Volcanic"
    },
    {
      "x": 17,
      "y": 19,
      "z": 9,
      "name": "Rock_Slate"
    },
    {
      "x": 17,
      "y": 20,
      "z": 9,
      "name": "Rock_Volcanic"
    },
    {
      "x": 17,
      "y": 21,
      "z": 9,
      "name": "Rock_Slate"
    },
    {
      "x": 17,
      "y": 22,
      "z": 9,
      "name": "Rock_Slate"
    },
    {
      "x": 17,
      "y": 23,
      "z": 9,
      "name": "Rock_Slate"
    },
    {
      "x": 17,
      "y": 24,
      "z": 9,
      "name": "Soil_Ash"
    },
    {
      "x": 17,
      "y": 25,
      "z": 9,
      "name": "Soil_Ash"
    },
    {
      "x": 17,
      "y": 30,
      "z": 9,
      "name": "Soil_Ash"
    },
    {
      "x": 17,
      "y": 31,
      "z": 9,
      "name": "Rock_Slate"
    },
    {
      "x": 17,
      "y": 32,
      "z": 9,
      "name": "Rock_Slate"
    },
    {
      "x": 17,
      "y": 33,
      "z": 9,
      "name": "Soil_Ash"
    },
    {
      "x": 17,
      "y": 34,
      "z": 9,
      "name": "Rock_Slate"
    },
    {
      "x": 17,
      "y": 35,
      "z": 9,
      "name": "Rock_Slate"
    },
    {
      "x": 17,
      "y": 36,
      "z": 9,
      "name": "Rock_Slate"
    },
    {
      "x": 17,
      "y": 37,
      "z": 9,
      "name": "Rock_Slate"
    },
    {
      "x": 17,
      "y": 38,
      "z": 9,
      "name": "Rock_Slate"
    },
    {
      "x": 17,
      "y": 39,
      "z": 9,
      "name": "Soil_Ash"
    },
    {
      "x": 17,
      "y": 40,
      "z": 9,
      "name": "Rock_Slate"
    },
    {
      "x": 17,
      "y": 11,
      "z": 10,
      "name": "Rock_Slate"
    },
    {
      "x": 17,
      "y": 12,
      "z": 10,
      "name": "Soil_Ash"
    },
    {
      "x": 17,
      "y": 13,
      "z": 10,
      "name": "Soil_Ash"
    },
    {
      "x": 17,
      "y": 14,
      "z": 10,
      "name": "Soil_Ash"
    },
    {
      "x": 17,
      "y": 15,
      "z": 10,
      "name": "Soil_Ash"
    },
    {
      "x": 17,
      "y": 16,
      "z": 10,
      "name": "Rock_Slate"
    },
    {
      "x": 17,
      "y": 17,
      "z": 10,
      "name": "Rock_Slate"
    },
    {
      "x": 17,
      "y": 18,
      "z": 10,
      "name": "Rock_Volcanic"
    },
    {
      "x": 17,
      "y": 19,
      "z": 10,
      "name": "Rock_Slate"
    },
    {
      "x": 17,
      "y": 20,
      "z": 10,
      "name": "Rock_Volcanic"
    },
    {
      "x": 17,
      "y": 21,
      "z": 10,
      "name": "Rock_Volcanic"
    },
    {
      "x": 17,
      "y": 22,
      "z": 10,
      "name": "Rock_Volcanic"
    },
    {
      "x": 17,
      "y": 23,
      "z": 10,
      "name": "Rock_Slate"
    },
    {
      "x": 17,
      "y": 24,
      "z": 10,
      "name": "Soil_Ash"
    },
    {
      "x": 17,
      "y": 25,
      "z": 10,
      "name": "Soil_Ash"
    },
    {
      "x": 17,
      "y": 26,
      "z": 10,
      "name": "Soil_Ash"
    },
    {
      "x": 17,
      "y": 27,
      "z": 10,
      "name": "Soil_Ash"
    },
    {
      "x": 17,
      "y": 28,
      "z": 10,
      "name": "Soil_Ash"
    },
    {
      "x": 17,
      "y": 29,
      "z": 10,
      "name": "Soil_Ash"
    },
    {
      "x": 17,
      "y": 30,
      "z": 10,
      "name": "Soil_Ash"
    },
    {
      "x": 17,
      "y": 31,
      "z": 10,
      "name": "Rock_Slate"
    },
    {
      "x": 17,
      "y": 32,
      "z": 10,
      "name": "Rock_Slate"
    },
    {
      "x": 17,
      "y": 33,
      "z": 10,
      "name": "Rock_Slate"
    },
    {
      "x": 17,
      "y": 34,
      "z": 10,
      "name": "Rock_Slate"
    },
    {
      "x": 17,
      "y": 35,
      "z": 10,
      "name": "Rock_Slate"
    },
    {
      "x": 17,
      "y": 36,
      "z": 10,
      "name": "Rock_Slate"
    },
    {
      "x": 17,
      "y": 37,
      "z": 10,
      "name": "Rock_Slate"
    },
    {
      "x": 17,
      "y": 38,
      "z": 10,
      "name": "Rock_Slate"
    },
    {
      "x": 17,
      "y": 39,
      "z": 10,
      "name": "Rock_Slate"
    },
    {
      "x": 17,
      "y": 40,
      "z": 10,
      "name": "Rock_Slate"
    },
    {
      "x": 17,
      "y": 11,
      "z": 11,
      "name": "Rock_Slate"
    },
    {
      "x": 17,
      "y": 12,
      "z": 11,
      "name": "Rock_Slate"
    },
    {
      "x": 17,
      "y": 13,
      "z": 11,
      "name": "Rock_Slate"
    },
    {
      "x": 17,
      "y": 14,
      "z": 11,
      "name": "Soil_Ash"
    },
    {
      "x": 17,
      "y": 15,
      "z": 11,
      "name": "Rock_Slate"
    },
    {
      "x": 17,
      "y": 16,
      "z": 11,
      "name": "Rock_Slate"
    },
    {
      "x": 17,
      "y": 17,
      "z": 11,
      "name": "Rock_Slate"
    },
    {
      "x": 17,
      "y": 18,
      "z": 11,
      "name": "Rock_Volcanic"
    },
    {
      "x": 17,
      "y": 19,
      "z": 11,
      "name": "Rock_Slate"
    },
    {
      "x": 17,
      "y": 20,
      "z": 11,
      "name": "Rock_Volcanic"
    },
    {
      "x": 17,
      "y": 21,
      "z": 11,
      "name": "Rock_Volcanic"
    },
    {
      "x": 17,
      "y": 22,
      "z": 11,
      "name": "Rock_Volcanic"
    },
    {
      "x": 17,
      "y": 23,
      "z": 11,
      "name": "Rock_Volcanic"
    },
    {
      "x": 17,
      "y": 24,
      "z": 11,
      "name": "Soil_Ash"
    },
    {
      "x": 17,
      "y": 25,
      "z": 11,
      "name": "Soil_Ash"
    },
    {
      "x": 17,
      "y": 26,
      "z": 11,
      "name": "Soil_Ash"
    },
    {
      "x": 17,
      "y": 27,
      "z": 11,
      "name": "Soil_Ash"
    },
    {
      "x": 17,
      "y": 28,
      "z": 11,
      "name": "Soil_Ash"
    },
    {
      "x": 17,
      "y": 29,
      "z": 11,
      "name": "Soil_Ash"
    },
    {
      "x": 17,
      "y": 30,
      "z": 11,
      "name": "Soil_Ash"
    },
    {
      "x": 17,
      "y": 31,
      "z": 11,
      "name": "Soil_Ash"
    },
    {
      "x": 17,
      "y": 32,
      "z": 11,
      "name": "Rock_Slate"
    },
    {
      "x": 17,
      "y": 33,
      "z": 11,
      "name": "Rock_Slate"
    },
    {
      "x": 17,
      "y": 34,
      "z": 11,
      "name": "Rock_Slate"
    },
    {
      "x": 17,
      "y": 35,
      "z": 11,
      "name": "Soil_Ash"
    },
    {
      "x": 17,
      "y": 36,
      "z": 11,
      "name": "Soil_Ash"
    },
    {
      "x": 17,
      "y": 37,
      "z": 11,
      "name": "Rock_Slate"
    },
    {
      "x": 17,
      "y": 38,
      "z": 11,
      "name": "Rock_Slate"
    },
    {
      "x": 17,
      "y": 39,
      "z": 11,
      "name": "Rock_Slate"
    },
    {
      "x": 17,
      "y": 12,
      "z": 12,
      "name": "Rock_Slate"
    },
    {
      "x": 17,
      "y": 13,
      "z": 12,
      "name": "Rock_Slate"
    },
    {
      "x": 17,
      "y": 14,
      "z": 12,
      "name": "Rock_Slate"
    },
    {
      "x": 17,
      "y": 15,
      "z": 12,
      "name": "Rock_Slate"
    },
    {
      "x": 17,
      "y": 16,
      "z": 12,
      "name": "Rock_Slate"
    },
    {
      "x": 17,
      "y": 17,
      "z": 12,
      "name": "Rock_Slate"
    },
    {
      "x": 17,
      "y": 18,
      "z": 12,
      "name": "Rock_Slate"
    },
    {
      "x": 17,
      "y": 19,
      "z": 12,
      "name": "Rock_Slate"
    },
    {
      "x": 17,
      "y": 20,
      "z": 12,
      "name": "Rock_Volcanic"
    },
    {
      "x": 17,
      "y": 21,
      "z": 12,
      "name": "Rock_Volcanic"
    },
    {
      "x": 17,
      "y": 22,
      "z": 12,
      "name": "Rock_Volcanic"
    },
    {
      "x": 17,
      "y": 23,
      "z": 12,
      "name": "Soil_Ash"
    },
    {
      "x": 17,
      "y": 24,
      "z": 12,
      "name": "Rock_Slate"
    },
    {
      "x": 17,
      "y": 25,
      "z": 12,
      "name": "Soil_Ash"
    },
    {
      "x": 17,
      "y": 26,
      "z": 12,
      "name": "Rock_Slate"
    },
    {
      "x": 17,
      "y": 27,
      "z": 12,
      "name": "Soil_Ash"
    },
    {
      "x": 17,
      "y": 28,
      "z": 12,
      "name": "Soil_Ash"
    },
    {
      "x": 17,
      "y": 29,
      "z": 12,
      "name": "Soil_Ash"
    },
    {
      "x": 17,
      "y": 30,
      "z": 12,
      "name": "Soil_Ash"
    },
    {
      "x": 17,
      "y": 31,
      "z": 12,
      "name": "Soil_Ash"
    },
    {
      "x": 17,
      "y": 32,
      "z": 12,
      "name": "Rock_Slate"
    },
    {
      "x": 17,
      "y": 33,
      "z": 12,
      "name": "Rock_Slate"
    },
    {
      "x": 17,
      "y": 34,
      "z": 12,
      "name": "Soil_Ash"
    },
    {
      "x": 17,
      "y": 35,
      "z": 12,
      "name": "Soil_Ash"
    },
    {
      "x": 17,
      "y": 36,
      "z": 12,
      "name": "Soil_Ash"
    },
    {
      "x": 17,
      "y": 37,
      "z": 12,
      "name": "Soil_Ash"
    },
    {
      "x": 17,
      "y": 38,
      "z": 12,
      "name": "Rock_Slate"
    },
    {
      "x": 17,
      "y": 39,
      "z": 12,
      "name": "Rock_Slate"
    },
    {
      "x": 17,
      "y": 15,
      "z": 13,
      "name": "Rock_Slate"
    },
    {
      "x": 17,
      "y": 16,
      "z": 13,
      "name": "Rock_Slate"
    },
    {
      "x": 17,
      "y": 17,
      "z": 13,
      "name": "Rock_Slate"
    },
    {
      "x": 17,
      "y": 18,
      "z": 13,
      "name": "Rock_Slate"
    },
    {
      "x": 17,
      "y": 19,
      "z": 13,
      "name": "Rock_Slate"
    },
    {
      "x": 17,
      "y": 20,
      "z": 13,
      "name": "Rock_Volcanic"
    },
    {
      "x": 17,
      "y": 21,
      "z": 13,
      "name": "Rock_Volcanic"
    },
    {
      "x": 17,
      "y": 22,
      "z": 13,
      "name": "Rock_Volcanic"
    },
    {
      "x": 17,
      "y": 23,
      "z": 13,
      "name": "Soil_Ash"
    },
    {
      "x": 17,
      "y": 24,
      "z": 13,
      "name": "Rock_Slate"
    },
    {
      "x": 17,
      "y": 25,
      "z": 13,
      "name": "Rock_Slate"
    },
    {
      "x": 17,
      "y": 26,
      "z": 13,
      "name": "Rock_Slate"
    },
    {
      "x": 17,
      "y": 27,
      "z": 13,
      "name": "Soil_Ash"
    },
    {
      "x": 17,
      "y": 28,
      "z": 13,
      "name": "Soil_Ash"
    },
    {
      "x": 17,
      "y": 29,
      "z": 13,
      "name": "Soil_Ash"
    },
    {
      "x": 17,
      "y": 30,
      "z": 13,
      "name": "Soil_Ash"
    },
    {
      "x": 17,
      "y": 31,
      "z": 13,
      "name": "Soil_Ash"
    },
    {
      "x": 17,
      "y": 32,
      "z": 13,
      "name": "Rock_Slate"
    },
    {
      "x": 17,
      "y": 33,
      "z": 13,
      "name": "Rock_Slate"
    },
    {
      "x": 17,
      "y": 34,
      "z": 13,
      "name": "Soil_Ash"
    },
    {
      "x": 17,
      "y": 35,
      "z": 13,
      "name": "Soil_Ash"
    },
    {
      "x": 17,
      "y": 36,
      "z": 13,
      "name": "Soil_Ash"
    },
    {
      "x": 17,
      "y": 18,
      "z": 14,
      "name": "Rock_Slate"
    },
    {
      "x": 17,
      "y": 19,
      "z": 14,
      "name": "Rock_Slate"
    },
    {
      "x": 17,
      "y": 20,
      "z": 14,
      "name": "Rock_Volcanic"
    },
    {
      "x": 17,
      "y": 21,
      "z": 14,
      "name": "Rock_Volcanic"
    },
    {
      "x": 17,
      "y": 22,
      "z": 14,
      "name": "Soil_Ash"
    },
    {
      "x": 18,
      "y": 10,
      "z": 3,
      "name": "Rock_Slate"
    },
    {
      "x": 18,
      "y": 11,
      "z": 3,
      "name": "Rock_Slate"
    },
    {
      "x": 18,
      "y": 12,
      "z": 3,
      "name": "Rock_Slate"
    },
    {
      "x": 18,
      "y": 13,
      "z": 3,
      "name": "Rock_Slate"
    },
    {
      "x": 18,
      "y": 14,
      "z": 3,
      "name": "Rock_Slate"
    },
    {
      "x": 18,
      "y": 15,
      "z": 3,
      "name": "Rock_Slate"
    },
    {
      "x": 18,
      "y": 20,
      "z": 3,
      "name": "Soil_Ash"
    },
    {
      "x": 18,
      "y": 21,
      "z": 3,
      "name": "Rock_Slate"
    },
    {
      "x": 18,
      "y": 22,
      "z": 3,
      "name": "Soil_Ash"
    },
    {
      "x": 18,
      "y": 23,
      "z": 3,
      "name": "Soil_Ash"
    },
    {
      "x": 18,
      "y": 24,
      "z": 3,
      "name": "Soil_Ash"
    },
    {
      "x": 18,
      "y": 25,
      "z": 3,
      "name": "Soil_Ash"
    },
    {
      "x": 18,
      "y": 26,
      "z": 3,
      "name": "Soil_Ash"
    },
    {
      "x": 18,
      "y": 32,
      "z": 3,
      "name": "Soil_Ash"
    },
    {
      "x": 18,
      "y": 33,
      "z": 3,
      "name": "Soil_Ash"
    },
    {
      "x": 18,
      "y": 34,
      "z": 3,
      "name": "Soil_Ash"
    },
    {
      "x": 18,
      "y": 35,
      "z": 3,
      "name": "Soil_Ash"
    },
    {
      "x": 18,
      "y": 10,
      "z": 4,
      "name": "Rock_Slate"
    },
    {
      "x": 18,
      "y": 11,
      "z": 4,
      "name": "Rock_Slate"
    },
    {
      "x": 18,
      "y": 12,
      "z": 4,
      "name": "Rock_Slate"
    },
    {
      "x": 18,
      "y": 13,
      "z": 4,
      "name": "Rock_Slate"
