{
  "version": 8,
  "blockIdVersion": 8,
  "anchorX": 0,
  "anchorY": 0,
  "anchorZ": 0,
  "blocks": [
    {
      "x": -6,
      "y": 0,
      "z": 0,
      "name": "Rock_Stone"
    },
    {
      "x": -6,
      "y": 1,
      "z": 0,
      "name": "Rock_Stone_Stalactite_Small"
    },
    {
      "x": -6,
      "y": 0,
      "z": 1,
      "name": "Rock_Stone"
    },
    {
      "x": -6,
      "y": 1,
      "z": 1,
      "name": "Rock_Stone"
    },
    {
      "x": -6,
      "y": 0,
      "z": 2,
      "name": "Rock_Stone"
    },
    {
      "x": -5,
      "y": 0,
      "z": -3,
      "name": "Soil_Gravel"
    },
    {
      "x": -5,
      "y": 0,
      "z": -2,
      "name": "Soil_Gravel"
    },
    {
      "x": -5,
      "y": 4,
      "z": -2,
      "name": "Wood_Deadwood_Planks_Half",
      "rotation": 7
    },
    {
      "x": -5,
      "y": 0,
      "z": -1,
      "name": "Rock_Stone"
    },
    {
      "x": -5,
      "y": 0,
      "z": 0,
      "name": "Rock_Stone"
    },
    {
      "x": -5,
      "y": 1,
      "z": 0,
      "name": "Rock_Stone"
    },
    {
      "x": -5,
      "y": 2,
      "z": 0,
      "name": "Plant_Moss_Rug_Green"
    },
    {
      "x": -5,
      "y": 0,
      "z": 1,
      "name": "Rock_Stone"
    },
    {
      "x": -5,
      "y": 1,
      "z": 1,
      "name": "Rock_Stone"
    },
    {
      "x": -5,
      "y": 2,
      "z": 1,
      "name": "Rock_Stone"
    },
    {
      "x": -5,
      "y": 3,
      "z": 1,
      "name": "Rock_Stone_Stalactite_Small"
    },
    {
      "x": -5,
      "y": 4,
      "z": 1,
      "name": "Cloth_Roof_Hide_Flap",
      "rotation": 3
    },
    {
      "x": -5,
      "y": 0,
      "z": 2,
      "name": "Rock_Stone"
    },
    {
      "x": -5,
      "y": 1,
      "z": 2,
      "name": "Rock_Stone"
    },
    {
      "x": -5,
      "y": 2,
      "z": 2,
      "name": "Rock_Stone_Stalactite_Large"
    },
    {
      "x": -5,
      "y": 3,
      "z": 2,
      "name": "Rock_Stone_Stalactite_Large",
      "filler": 1024
    },
    {
      "x": -5,
      "y": 4,
      "z": 2,
      "name": "Cloth_Roof_Hide_Flap",
      "rotation": 3
    },
    {
      "x": -5,
      "y": 0,
      "z": 3,
      "name": "Rock_Stone"
    },
    {
      "x": -5,
      "y": 1,
      "z": 3,
      "name": "Rubble_Stone"
    },
    {
      "x": -4,
      "y": 0,
      "z": -3,
      "name": "Soil_Gravel"
    },
    {
      "x": -4,
      "y": 4,
      "z": -3,
      "name": "Cloth_Roof_Hide_Flap",
      "rotation": 2
    },
    {
      "x": -4,
      "y": 0,
      "z": -2,
      "name": "Rock_Stone"
    },
    {
      "x": -4,
      "y": 1,
      "z": -2,
      "name": "Wood_Softwood_Planks"
    },
    {
      "x": -4,
      "y": 2,
      "z": -2,
      "name": "Plant_Moss_Rug_Green"
    },
    {
      "x": -4,
      "y": 3,
      "z": -2,
      "name": "Empty"
    },
    {
      "x": -4,
      "y": 4,
      "z": -2,
      "name": "Wood_Deadwood_Planks"
    },
    {
      "x": -4,
      "y": 5,
      "z": -2,
      "name": "*Cloth_Roof_Hide_State_Definitions_Corner_Right",
      "rotation": 3
    },
    {
      "x": -4,
      "y": 0,
      "z": -1,
      "name": "Rock_Stone"
    },
    {
      "x": -4,
      "y": 1,
      "z": -1,
      "name": "Empty"
    },
    {
      "x": -4,
      "y": 2,
      "z": -1,
      "name": "Empty"
    },
    {
      "x": -4,
      "y": 3,
      "z": -1,
      "name": "Empty"
    },
    {
      "x": -4,
      "y": 4,
      "z": -1,
      "name": "*Wood_Softwood_Planks_Half_State_Definitions_Block",
      "rotation": 8
    },
    {
      "x": -4,
      "y": 5,
      "z": -1,
      "name": "Block_Spawner_Block",
      "components": {
        "Components": {
          "BlockSpawner": {
            "BlockSpawnerId": "Zone1_Goblin_Tier3"
          }
        }
      },
      "rotation": 2
    },
    {
      "x": -4,
      "y": 0,
      "z": 0,
      "name": "Rock_Stone"
    },
    {
      "x": -4,
      "y": 1,
      "z": 0,
      "name": "Furniture_Crude_Stool"
    },
    {
      "x": -4,
      "y": 2,
      "z": 0,
      "name": "Empty"
    },
    {
      "x": -4,
      "y": 3,
      "z": 0,
      "name": "Empty"
    },
    {
      "x": -4,
      "y": 4,
      "z": 0,
      "name": "Wood_Softwood_Planks_Half",
      "rotation": 8
    },
    {
      "x": -4,
      "y": 5,
      "z": 0,
      "name": "Furniture_Village_Pot"
    },
    {
      "x": -4,
      "y": 0,
      "z": 1,
      "name": "Rock_Stone"
    },
    {
      "x": -4,
      "y": 1,
      "z": 1,
      "name": "Wood_Deadwood_Planks"
    },
    {
      "x": -4,
      "y": 2,
      "z": 1,
      "name": "Wood_Deadwood_Beam"
    },
    {
      "x": -4,
      "y": 3,
      "z": 1,
      "name": "Wood_Deadwood_Beam"
    },
    {
      "x": -4,
      "y": 4,
      "z": 1,
      "name": "Wood_Deadwood_Planks"
    },
    {
      "x": -4,
      "y": 5,
      "z": 1,
      "name": "Cloth_Roof_Hide",
      "rotation": 3
    },
    {
      "x": -4,
      "y": 0,
      "z": 2,
      "name": "Rock_Stone"
    },
    {
      "x": -4,
      "y": 1,
      "z": 2,
      "name": "Wood_Softwood_Fence",
      "rotation": 2
    },
    {
      "x": -4,
      "y": 2,
      "z": 2,
      "name": "Wood_Softwood_Fence",
      "rotation": 2
    },
    {
      "x": -4,
      "y": 3,
      "z": 2,
      "name": "Wood_Deadwood_Planks"
    },
    {
      "x": -4,
      "y": 4,
      "z": 2,
      "name": "Wood_Deadwood_Planks"
    },
    {
      "x": -4,
      "y": 5,
      "z": 2,
      "name": "*Cloth_Roof_Hide_State_Definitions_Corner_Right"
    },
    {
      "x": -4,
      "y": 0,
      "z": 3,
      "name": "Rock_Stone"
    },
    {
      "x": -4,
      "y": 1,
      "z": 3,
      "name": "Rock_Stone_Stalactite_Large"
    },
    {
      "x": -4,
      "y": 2,
      "z": 3,
      "name": "Rock_Stone_Stalactite_Large",
      "filler": 1024
    },
    {
      "x": -4,
      "y": 4,
      "z": 3,
      "name": "Cloth_Roof_Hide_Flap"
    },
    {
      "x": -3,
      "y": 0,
      "z": -3,
      "name": "Rock_Stone"
    },
    {
      "x": -3,
      "y": 2,
      "z": -3,
      "name": "Plant_Moss_Wall_Green",
      "rotation": 2
    },
    {
      "x": -3,
      "y": 3,
      "z": -3,
      "name": "Plant_Moss_Wall_Green",
      "rotation": 2
    },
    {
      "x": -3,
      "y": 4,
      "z": -3,
      "name": "Cloth_Roof_Hide_Flap",
      "rotation": 2
    },
    {
      "x": -3,
      "y": 0,
      "z": -2,
      "name": "Rock_Stone"
    },
    {
      "x": -3,
      "y": 1,
      "z": -2,
      "name": "Wood_Softwood_Planks"
    },
    {
      "x": -3,
      "y": 2,
      "z": -2,
      "name": "Wood_Softwood_Planks"
    },
    {
      "x": -3,
      "y": 3,
      "z": -2,
      "name": "Wood_Deadwood_Beam"
    },
    {
      "x": -3,
      "y": 4,
      "z": -2,
      "name": "Wood_Deadwood_Planks"
    },
    {
      "x": -3,
      "y": 5,
      "z": -2,
      "name": "Cloth_Roof_Hide",
      "rotation": 2
    },
    {
      "x": -3,
      "y": 0,
      "z": -1,
      "name": "Soil_Gravel_Mossy"
    },
    {
      "x": -3,
      "y": 1,
      "z": -1,
      "name": "Plant_Moss_Short_Green"
    },
    {
      "x": -3,
      "y": 2,
      "z": -1,
      "name": "Empty"
    },
    {
      "x": -3,
      "y": 3,
      "z": -1,
      "name": "Empty"
    },
    {
      "x": -3,
      "y": 4,
      "z": -1,
      "name": "Wood_Deadwood_Beam",
      "rotation": 5
    },
    {
      "x": -3,
      "y": 0,
      "z": 0,
      "name": "Soil_Gravel_Mossy"
    },
    {
      "x": -3,
      "y": 1,
      "z": 0,
      "name": "Empty"
    },
    {
      "x": -3,
      "y": 2,
      "z": 0,
      "name": "Empty"
    },
    {
      "x": -3,
      "y": 3,
      "z": 0,
      "name": "Empty"
    },
    {
      "x": -3,
      "y": 4,
      "z": 0,
      "name": "Empty"
    },
    {
      "x": -3,
      "y": 5,
      "z": 0,
      "name": "Empty"
    },
    {
      "x": -3,
      "y": 6,
      "z": 0,
      "name": "Cloth_Roof_Hide_Flat"
    },
    {
      "x": -3,
      "y": 0,
      "z": 1,
      "name": "Rock_Stone"
    },
    {
      "x": -3,
      "y": 1,
      "z": 1,
      "name": "Furniture_Village_Counter",
      "rotation": 2
    },
    {
      "x": -3,
      "y": 2,
      "z": 1,
      "name": "Plant_Moss_Rug_Green"
    },
    {
      "x": -3,
      "y": 3,
      "z": 1,
      "name": "Empty"
    },
    {
      "x": -3,
      "y": 4,
      "z": 1,
      "name": "Empty"
    },
    {
      "x": -3,
      "y": 5,
      "z": 1,
      "name": "Plant_Moss_Cave_Green",
      "rotation": 8
    },
    {
      "x": -3,
      "y": 6,
      "z": 1,
      "name": "Plant_Moss_Rug_Green"
    },
    {
      "x": -3,
      "y": 0,
      "z": 2,
      "name": "Rock_Stone"
    },
    {
      "x": -3,
      "y": 1,
      "z": 2,
      "name": "Wood_Deadwood_Planks"
    },
    {
      "x": -3,
      "y": 2,
      "z": 2,
      "name": "Wood_Softwood_Fence"
    },
    {
      "x": -3,
      "y": 3,
      "z": 2,
      "name": "Wood_Softwood_Fence"
    },
    {
      "x": -3,
      "y": 4,
      "z": 2,
      "name": "Wood_Deadwood_Beam",
      "rotation": 5
    },
    {
      "x": -3,
      "y": 5,
      "z": 2,
      "name": "Cloth_Roof_Hide"
    },
    {
      "x": -3,
      "y": 0,
      "z": 3,
      "name": "Soil_Gravel"
    },
    {
      "x": -3,
      "y": 4,
      "z": 3,
      "name": "Cloth_Roof_Hide_Flap"
    },
    {
      "x": -2,
      "y": 0,
      "z": -3,
      "name": "Rock_Stone"
    },
    {
      "x": -2,
      "y": 1,
      "z": -3,
      "name": "Plant_Crop_Mushroom_Cap_Green",
      "components": {
        "Components": {
          "FarmingBlock": {}
        }
      }
    },
    {
      "x": -2,
      "y": 3,
      "z": -3,
      "name": "Plant_Moss_Wall_Green",
      "rotation": 2
    },
    {
      "x": -2,
      "y": 4,
      "z": -3,
      "name": "Plant_Moss_Wall_Green",
      "rotation": 2
    },
    {
      "x": -2,
      "y": 0,
      "z": -2,
      "name": "Rock_Stone"
    },
    {
      "x": -2,
      "y": 1,
      "z": -2,
      "name": "Wood_Softwood_Planks"
    },
    {
      "x": -2,
      "y": 2,
      "z": -2,
      "name": "Wood_Softwood_Planks_Half",
      "rotation": 4
    },
    {
      "x": -2,
      "y": 3,
      "z": -2,
      "name": "*Wood_Deadwood_Planks_Half_State_Definitions_Block",
      "rotation": 7
    },
    {
      "x": -2,
      "y": 4,
      "z": -2,
      "name": "Wood_Deadwood_Planks"
    },
    {
      "x": -2,
      "y": 5,
      "z": -2,
      "name": "Cloth_Roof_Hide",
      "rotation": 2
    },
    {
      "x": -2,
      "y": 0,
      "z": -1,
      "name": "Soil_Gravel_Mossy"
    },
    {
      "x": -2,
      "y": 1,
      "z": -1,
      "name": "Empty"
    },
    {
      "x": -2,
      "y": 2,
      "z": -1,
      "name": "Empty"
    },
    {
      "x": -2,
      "y": 3,
      "z": -1,
      "name": "Empty"
    },
    {
      "x": -2,
      "y": 4,
      "z": -1,
      "name": "Wood_Deadwood_Beam",
      "rotation": 5
    },
    {
      "x": -2,
      "y": 6,
      "z": -1,
      "name": "Cloth_Roof_Hide_Flat"
    },
    {
      "x": -2,
      "y": 0,
      "z": 0,
      "name": "Soil_Gravel_Mossy"
    },
    {
      "x": -2,
      "y": 1,
      "z": 0,
      "name": "Plant_Crop_Mushroom_Glowing_Green"
    },
    {
      "x": -2,
      "y": 2,
      "z": 0,
      "name": "Empty"
    },
    {
      "x": -2,
      "y": 3,
      "z": 0,
      "name": "Empty"
    },
    {
      "x": -2,
      "y": 4,
      "z": 0,
      "name": "Empty"
    },
    {
      "x": -2,
      "y": 5,
      "z": 0,
      "name": "Plant_Moss_Cave_Green",
      "rotation": 8
    },
    {
      "x": -2,
      "y": 6,
      "z": 0,
      "name": "Plant_Moss_Rug_Green"
    },
    {
      "x": -2,
      "y": 0,
      "z": 1,
      "name": "Soil_Gravel_Mossy"
    },
    {
      "x": -2,
      "y": 1,
      "z": 1,
      "name": "Furniture_Village_Counter",
      "filler": 1,
      "rotation": 2
    },
    {
      "x": -2,
      "y": 2,
      "z": 1,
      "name": "Plant_Moss_Rug_Green"
    },
    {
      "x": -2,
      "y": 3,
      "z": 1,
      "name": "Empty"
    },
    {
      "x": -2,
      "y": 4,
      "z": 1,
      "name": "Plant_Moss_Wall_Green",
      "rotation": 2
    },
    {
      "x": -2,
      "y": 5,
      "z": 1,
      "name": "Plant_Moss_Cave_Green",
      "rotation": 8
    },
    {
      "x": -2,
      "y": 6,
      "z": 1,
      "name": "Plant_Moss_Rug_Green"
    },
    {
      "x": -2,
      "y": 0,
      "z": 2,
      "name": "Rock_Stone"
    },
    {
      "x": -2,
      "y": 1,
      "z": 2,
      "name": "Wood_Deadwood_Planks"
    },
    {
      "x": -2,
      "y": 2,
      "z": 2,
      "name": "Plant_Moss_Rug_Green"
    },
    {
      "x": -2,
      "y": 4,
      "z": 2,
      "name": "Wood_Deadwood_Beam",
      "rotation": 5
    },
    {
      "x": -2,
      "y": 5,
      "z": 2,
      "name": "Plant_Moss_Rug_Green"
    },
    {
      "x": -2,
      "y": 0,
      "z": 3,
      "name": "Soil_Gravel"
    },
    {
      "x": -2,
      "y": 4,
      "z": 3,
      "name": "Plant_Moss_Wall_Green"
    },
    {
      "x": -1,
      "y": 0,
      "z": -3,
      "name": "Rock_Stone"
    },
    {
      "x": -1,
      "y": 3,
      "z": -3,
      "name": "Wood_Deadwood_Planks_Half",
      "rotation": 6
    },
    {
      "x": -1,
      "y": 4,
      "z": -3,
      "name": "Wood_Deadwood_Planks_Half",
      "rotation": 6
    },
    {
      "x": -1,
      "y": 0,
      "z": -2,
      "name": "Rock_Stone"
    },
    {
      "x": -1,
      "y": 1,
      "z": -2,
      "name": "Wood_Deadwood_Planks"
    },
    {
      "x": -1,
      "y": 2,
      "z": -2,
      "name": "Wood_Deadwood_Planks"
    },
    {
      "x": -1,
      "y": 3,
      "z": -2,
      "name": "Wood_Deadwood_Planks"
    },
    {
      "x": -1,
      "y": 4,
      "z": -2,
      "name": "Wood_Deadwood_Planks"
    },
    {
      "x": -1,
      "y": 5,
      "z": -2,
      "name": "*Cloth_Roof_Hide_State_Definitions_Corner_Right",
      "rotation": 2
    },
    {
      "x": -1,
      "y": 0,
      "z": -1,
      "name": "Soil_Gravel_Mossy"
    },
    {
      "x": -1,
      "y": 1,
      "z": -1,
      "name": "Furniture_Crude_Door",
      "rotation": 1
    },
    {
      "x": -1,
      "y": 2,
      "z": -1,
      "name": "Furniture_Crude_Door",
      "filler": 1024,
      "rotation": 1
    },
    {
      "x": -1,
      "y": 3,
      "z": -1,
      "name": "Wood_Softwood_Fence",
      "rotation": 1
    },
    {
      "x": -1,
      "y": 4,
      "z": -1,
      "name": "Wood_Deadwood_Planks"
    },
    {
      "x": -1,
      "y": 5,
      "z": -1,
      "name": "Cloth_Roof_Hide",
      "rotation": 1
    },
    {
      "x": -1,
      "y": 0,
      "z": 0,
      "name": "Rock_Stone"
    },
    {
      "x": -1,
      "y": 1,
      "z": 0,
      "name": "Wood_Softwood_Planks"
    },
    {
      "x": -1,
      "y": 2,
      "z": 0,
      "name": "Furniture_Crude_Window",
      "rotation": 1
    },
    {
      "x": -1,
      "y": 3,
      "z": 0,
      "name": "Wood_Softwood_Fence",
      "rotation": 1
    },
    {
      "x": -1,
      "y": 4,
      "z": 0,
      "name": "Wood_Deadwood_Planks"
    },
    {
      "x": -1,
      "y": 5,
      "z": 0,
      "name": "Cloth_Roof_Hide",
      "rotation": 1
    },
    {
      "x": -1,
      "y": 0,
      "z": 1,
      "name": "Rock_Stone"
    },
    {
      "x": -1,
      "y": 1,
      "z": 1,
      "name": "Wood_Softwood_Planks"
    },
    {
      "x": -1,
      "y": 2,
      "z": 1,
      "name": "Wood_Softwood_Fence",
      "rotation": 1
    },
    {
      "x": -1,
      "y": 3,
      "z": 1,
      "name": "Furniture_Crude_Window",
      "rotation": 1
    },
    {
      "x": -1,
      "y": 4,
      "z": 1,
      "name": "Wood_Deadwood_Planks"
    },
    {
      "x": -1,
      "y": 5,
      "z": 1,
      "name": "Plant_Moss_Rug_Green"
    },
    {
      "x": -1,
      "y": 0,
      "z": 2,
      "name": "Rock_Stone"
    },
    {
      "x": -1,
      "y": 1,
      "z": 2,
      "name": "Wood_Softwood_Planks_Half",
      "rotation": 4
    },
    {
      "x": -1,
      "y": 2,
      "z": 2,
      "name": "Wood_Softwood_Planks_Half",
      "rotation": 4
    },
    {
      "x": -1,
      "y": 3,
      "z": 2,
      "name": "Wood_Deadwood_Planks"
    },
    {
      "x": -1,
      "y": 4,
      "z": 2,
      "name": "Wood_Deadwood_Planks"
    },
    {
      "x": -1,
      "y": 5,
      "z": 2,
      "name": "Plant_Moss_Rug_Green"
    },
    {
      "x": -1,
      "y": 0,
      "z": 3,
      "name": "Rock_Stone"
    },
    {
      "x": -1,
      "y": 3,
      "z": 3,
      "name": "Plant_Moss_Wall_Green"
    },
    {
      "x": -1,
      "y": 4,
      "z": 3,
      "name": "Plant_Moss_Wall_Green"
    },
    {
      "x": 0,
      "y": 0,
      "z": -3,
      "name": "Rock_Stone"
    },
    {
      "x": 0,
      "y": 0,
      "z": -2,
      "name": "Soil_Gravel"
    },
    {
      "x": 0,
      "y": 4,
      "z": -2,
      "name": "Wood_Deadwood_Planks_Half",
      "rotation": 5
    },
    {
      "x": 0,
      "y": 0,
      "z": -1,
      "name": "Soil_Gravel"
    },
    {
      "x": 0,
      "y": 4,
      "z": -1,
      "name": "Cloth_Roof_Hide_Flap",
      "rotation": 1
    },
    {
      "x": 0,
      "y": 0,
      "z": 0,
      "name": "Rock_Stone"
    },
    {
      "x": 0,
      "y": 4,
      "z": 0,
      "name": "Wood_Deadwood_Planks_Half",
      "rotation": 5
    },
    {
      "x": 0,
      "y": 0,
      "z": 1,
      "name": "Rock_Stone"
    },
    {
      "x": 0,
      "y": 4,
      "z": 1,
      "name": "Plant_Moss_Wall_Green",
      "rotation": 1
    },
    {
      "x": 0,
      "y": 0,
      "z": 2,
      "name": "Rock_Stone"
    },
    {
      "x": 0,
      "y": 1,
      "z": 2,
      "name": "Rubble_Stone"
    },
    {
      "x": 0,
      "y": 3,
      "z": 2,
      "name": "Plant_Moss_Wall_Green",
      "rotation": 1
    },
    {
      "x": 0,
      "y": 4,
      "z": 2,
      "name": "Plant_Moss_Wall_Green",
      "rotation": 1
    },
    {
      "x": 0,
      "y": 0,
      "z": 3,
      "name": "Rock_Stone"
    }
  ]
}
