{
  "version": 8,
  "blockIdVersion": 8,
  "anchorX": 2,
  "anchorY": 8,
  "anchorZ": -2,
  "blocks": [
    {
      "x": -4,
      "y": 5,
      "z": -3,
      "name": "Rock_Sandstone_White"
    },
    {
      "x": -4,
      "y": 6,
      "z": -3,
      "name": "Soil_Sand_White"
    },
    {
      "x": -4,
      "y": 5,
      "z": -2,
      "name": "Rock_Sandstone_White"
    },
    {
      "x": -4,
      "y": 6,
      "z": -2,
      "name": "Rock_Sandstone_White"
    },
    {
      "x": -4,
      "y": 7,
      "z": -2,
      "name": "Rock_Sandstone_White"
    },
    {
      "x": -4,
      "y": 8,
      "z": -2,
      "name": "Soil_Sand_White"
    },
    {
      "x": -4,
      "y": 9,
      "z": -2,
      "name": "Wood_Drywood_Planks_Half"
    },
    {
      "x": -4,
      "y": 4,
      "z": -1,
      "name": "Rock_Sandstone_White"
    },
    {
      "x": -4,
      "y": 5,
      "z": -1,
      "name": "Rock_Sandstone_White"
    },
    {
      "x": -4,
      "y": 6,
      "z": -1,
      "name": "Rock_Sandstone_White"
    },
    {
      "x": -4,
      "y": 7,
      "z": -1,
      "name": "Soil_Sand_White"
    },
    {
      "x": -4,
      "y": 8,
      "z": -1,
      "name": "Furniture_Village_Pot"
    },
    {
      "x": -4,
      "y": 9,
      "z": -1,
      "name": "Empty"
    },
    {
      "x": -4,
      "y": 10,
      "z": -1,
      "name": "Empty"
    },
    {
      "x": -4,
      "y": 4,
      "z": 0,
      "name": "Rock_Sandstone_White"
    },
    {
      "x": -4,
      "y": 5,
      "z": 0,
      "name": "Rock_Sandstone_White"
    },
    {
      "x": -4,
      "y": 6,
      "z": 0,
      "name": "Rock_Sandstone_White"
    },
    {
      "x": -4,
      "y": 7,
      "z": 0,
      "name": "Rock_Sandstone_White"
    },
    {
      "x": -4,
      "y": 8,
      "z": 0,
      "name": "Empty"
    },
    {
      "x": -4,
      "y": 9,
      "z": 0,
      "name": "Empty"
    },
    {
      "x": -4,
      "y": 10,
      "z": 0,
      "name": "Empty"
    },
    {
      "x": -4,
      "y": 5,
      "z": 1,
      "name": "Rock_Sandstone_White"
    },
    {
      "x": -4,
      "y": 6,
      "z": 1,
      "name": "Rock_Sandstone_White"
    },
    {
      "x": -4,
      "y": 7,
      "z": 1,
      "name": "Soil_Sand_White"
    },
    {
      "x": -4,
      "y": 8,
      "z": 1,
      "name": "Empty"
    },
    {
      "x": -4,
      "y": 9,
      "z": 1,
      "name": "Empty"
    },
    {
      "x": -4,
      "y": 5,
      "z": 2,
      "name": "Rock_Sandstone_White"
    },
    {
      "x": -4,
      "y": 6,
      "z": 2,
      "name": "Soil_Sand_White"
    },
    {
      "x": -4,
      "y": 7,
      "z": 2,
      "name": "Rock_Sandstone_White"
    },
    {
      "x": -4,
      "y": 8,
      "z": 2,
      "name": "Empty"
    },
    {
      "x": -4,
      "y": 6,
      "z": 3,
      "name": "Rock_Sandstone_White"
    },
    {
      "x": -3,
      "y": 4,
      "z": -3,
      "name": "Rock_Sandstone_White"
    },
    {
      "x": -3,
      "y": 5,
      "z": -3,
      "name": "Rock_Sandstone_White"
    },
    {
      "x": -3,
      "y": 6,
      "z": -3,
      "name": "Rock_Sandstone_White"
    },
    {
      "x": -3,
      "y": 7,
      "z": -3,
      "name": "Soil_Sand_White"
    },
    {
      "x": -3,
      "y": 4,
      "z": -2,
      "name": "Rock_Sandstone_White"
    },
    {
      "x": -3,
      "y": 5,
      "z": -2,
      "name": "Rock_Sandstone_White"
    },
    {
      "x": -3,
      "y": 6,
      "z": -2,
      "name": "Rock_Sandstone_White"
    },
    {
      "x": -3,
      "y": 7,
      "z": -2,
      "name": "Rock_Sandstone_White"
    },
    {
      "x": -3,
      "y": 8,
      "z": -2,
      "name": "Soil_Sand_White"
    },
    {
      "x": -3,
      "y": 9,
      "z": -2,
      "name": "Soil_Sand_White"
    },
    {
      "x": -3,
      "y": 10,
      "z": -2,
      "name": "Wood_Drywood_Stairs",
      "rotation": 3
    },
    {
      "x": -3,
      "y": 11,
      "z": -2,
      "name": "Wood_Dry_Branch_Long",
      "rotation": 5
    },
    {
      "x": -3,
      "y": 4,
      "z": -1,
      "name": "Rock_Sandstone_White"
    },
    {
      "x": -3,
      "y": 5,
      "z": -1,
      "name": "Rock_Sandstone_White"
    },
    {
      "x": -3,
      "y": 6,
      "z": -1,
      "name": "Rock_Sandstone_White"
    },
    {
      "x": -3,
      "y": 7,
      "z": -1,
      "name": "Soil_Sand_White"
    },
    {
      "x": -3,
      "y": 8,
      "z": -1,
      "name": "Block_Spawner_Block",
      "components": {
        "Components": {
          "PlacedByInteraction": {
            "WhoPlacedUuid": {
              "$binary": "qA/t28wKPUewuu66t1XEYQ==",
              "$type": "04"
            }
          },
          "BlockSpawner": {
            "BlockSpawnerId": "Zone2_Encounters_Tier1"
          }
        }
      }
    },
    {
      "x": -3,
      "y": 9,
      "z": -1,
      "name": "Empty"
    },
    {
      "x": -3,
      "y": 10,
      "z": -1,
      "name": "Empty"
    },
    {
      "x": -3,
      "y": 3,
      "z": 0,
      "name": "Rock_Sandstone_White"
    },
    {
      "x": -3,
      "y": 4,
      "z": 0,
      "name": "Rock_Sandstone_White"
    },
    {
      "x": -3,
      "y": 5,
      "z": 0,
      "name": "Rock_Sandstone_White"
    },
    {
      "x": -3,
      "y": 6,
      "z": 0,
      "name": "Rock_Sandstone_White"
    },
    {
      "x": -3,
      "y": 7,
      "z": 0,
      "name": "Soil_Sand_White"
    },
    {
      "x": -3,
      "y": 8,
      "z": 0,
      "name": "Empty"
    },
    {
      "x": -3,
      "y": 9,
      "z": 0,
      "name": "Empty"
    },
    {
      "x": -3,
      "y": 10,
      "z": 0,
      "name": "Empty"
    },
    {
      "x": -3,
      "y": 3,
      "z": 1,
      "name": "Rock_Sandstone_White"
    },
    {
      "x": -3,
      "y": 4,
      "z": 1,
      "name": "Rock_Sandstone_White"
    },
    {
      "x": -3,
      "y": 5,
      "z": 1,
      "name": "Rock_Sandstone_White"
    },
    {
      "x": -3,
      "y": 6,
      "z": 1,
      "name": "Rock_Sandstone_White"
    },
    {
      "x": -3,
      "y": 7,
      "z": 1,
      "name": "Rock_Sandstone_White"
    },
    {
      "x": -3,
      "y": 8,
      "z": 1,
      "name": "Empty"
    },
    {
      "x": -3,
      "y": 9,
      "z": 1,
      "name": "Empty"
    },
    {
      "x": -3,
      "y": 3,
      "z": 2,
      "name": "Rock_Sandstone_White"
    },
    {
      "x": -3,
      "y": 4,
      "z": 2,
      "name": "Rock_Sandstone_White"
    },
    {
      "x": -3,
      "y": 5,
      "z": 2,
      "name": "Rock_Sandstone_White"
    },
    {
      "x": -3,
      "y": 6,
      "z": 2,
      "name": "Rock_Sandstone_White"
    },
    {
      "x": -3,
      "y": 7,
      "z": 2,
      "name": "Rock_Sandstone_White"
    },
    {
      "x": -3,
      "y": 8,
      "z": 2,
      "name": "Empty"
    },
    {
      "x": -3,
      "y": 9,
      "z": 2,
      "name": "Empty"
    },
    {
      "x": -3,
      "y": 4,
      "z": 3,
      "name": "Rock_Sandstone_White"
    },
    {
      "x": -3,
      "y": 5,
      "z": 3,
      "name": "Rock_Sandstone_White"
    },
    {
      "x": -3,
      "y": 6,
      "z": 3,
      "name": "Rock_Sandstone_White"
    },
    {
      "x": -3,
      "y": 7,
      "z": 3,
      "name": "Rock_Sandstone_White"
    },
    {
      "x": -3,
      "y": 5,
      "z": 4,
      "name": "Rock_Sandstone_White"
    },
    {
      "x": -3,
      "y": 6,
      "z": 4,
      "name": "Soil_Sand_White"
    },
    {
      "x": -2,
      "y": 4,
      "z": -3,
      "name": "Rock_Sandstone_White"
    },
    {
      "x": -2,
      "y": 5,
      "z": -3,
      "name": "Rock_Sandstone_White"
    },
    {
      "x": -2,
      "y": 6,
      "z": -3,
      "name": "Rock_Sandstone_White"
    },
    {
      "x": -2,
      "y": 7,
      "z": -3,
      "name": "Soil_Sand_White"
    },
    {
      "x": -2,
      "y": 11,
      "z": -3,
      "name": "Wood_Dry_Branch_Short",
      "rotation": 2
    },
    {
      "x": -2,
      "y": 3,
      "z": -2,
      "name": "Rock_Sandstone_White"
    },
    {
      "x": -2,
      "y": 4,
      "z": -2,
      "name": "Rock_Sandstone_White"
    },
    {
      "x": -2,
      "y": 5,
      "z": -2,
      "name": "Rock_Sandstone_White"
    },
    {
      "x": -2,
      "y": 6,
      "z": -2,
      "name": "Rock_Sandstone_White"
    },
    {
      "x": -2,
      "y": 7,
      "z": -2,
      "name": "Wood_Dry_Trunk"
    },
    {
      "x": -2,
      "y": 8,
      "z": -2,
      "name": "Wood_Dry_Trunk"
    },
    {
      "x": -2,
      "y": 9,
      "z": -2,
      "name": "Wood_Dry_Trunk"
    },
    {
      "x": -2,
      "y": 10,
      "z": -2,
      "name": "Wood_Dry_Trunk"
    },
    {
      "x": -2,
      "y": 11,
      "z": -2,
      "name": "Wood_Dry_Trunk"
    },
    {
      "x": -2,
      "y": 12,
      "z": -2,
      "name": "Rock_Sandstone_Cobble_Roof",
      "rotation": 1
    },
    {
      "x": -2,
      "y": 3,
      "z": -1,
      "name": "Rock_Sandstone_White"
    },
    {
      "x": -2,
      "y": 4,
      "z": -1,
      "name": "Rock_Sandstone_White"
    },
    {
      "x": -2,
      "y": 5,
      "z": -1,
      "name": "Rock_Sandstone_White"
    },
    {
      "x": -2,
      "y": 6,
      "z": -1,
      "name": "Rock_Sandstone_White"
    },
    {
      "x": -2,
      "y": 7,
      "z": -1,
      "name": "Rock_Sandstone_White"
    },
    {
      "x": -2,
      "y": 8,
      "z": -1,
      "name": "Soil_Sand_White"
    },
    {
      "x": -2,
      "y": 9,
      "z": -1,
      "name": "Soil_Sand_White"
    },
    {
      "x": -2,
      "y": 10,
      "z": -1,
      "name": "Wood_Drywood_Planks"
    },
    {
      "x": -2,
      "y": 11,
      "z": -1,
      "name": "Wood_Dry_Branch_Long",
      "rotation": 4
    },
    {
      "x": -2,
      "y": 2,
      "z": 0,
      "name": "Rock_Sandstone_White"
    },
    {
      "x": -2,
      "y": 3,
      "z": 0,
      "name": "Rock_Sandstone_White"
    },
    {
      "x": -2,
      "y": 4,
      "z": 0,
      "name": "Rock_Sandstone_White"
    },
    {
      "x": -2,
      "y": 5,
      "z": 0,
      "name": "Rock_Sandstone_White"
    },
    {
      "x": -2,
      "y": 6,
      "z": 0,
      "name": "Rock_Sandstone_White"
    },
    {
      "x": -2,
      "y": 7,
      "z": 0,
      "name": "Rock_Sandstone_White"
    },
    {
      "x": -2,
      "y": 8,
      "z": 0,
      "name": "Soil_Sand_White"
    },
    {
      "x": -2,
      "y": 9,
      "z": 0,
      "name": "Empty"
    },
    {
      "x": -2,
      "y": 11,
      "z": 0,
      "name": "Wood_Dry_Branch_Long",
      "rotation": 4
    },
    {
      "x": -2,
      "y": 2,
      "z": 1,
      "name": "Rock_Sandstone_White"
    },
    {
      "x": -2,
      "y": 3,
      "z": 1,
      "name": "Rock_Sandstone_White"
    },
    {
      "x": -2,
      "y": 4,
      "z": 1,
      "name": "Rock_Sandstone_White"
    },
    {
      "x": -2,
      "y": 5,
      "z": 1,
      "name": "Rock_Sandstone_White"
    },
    {
      "x": -2,
      "y": 6,
      "z": 1,
      "name": "Rock_Sandstone_White"
    },
    {
      "x": -2,
      "y": 7,
      "z": 1,
      "name": "Rock_Sandstone_White"
    },
    {
      "x": -2,
      "y": 8,
      "z": 1,
      "name": "Wood_Drywood_Planks"
    },
    {
      "x": -2,
      "y": 9,
      "z": 1,
      "name": "Wood_Drywood_Planks"
    },
    {
      "x": -2,
      "y": 10,
      "z": 1,
      "name": "Wood_Drywood_Planks_Half"
    },
    {
      "x": -2,
      "y": 3,
      "z": 2,
      "name": "Rock_Sandstone_White"
    },
    {
      "x": -2,
      "y": 4,
      "z": 2,
      "name": "Rock_Sandstone_White"
    },
    {
      "x": -2,
      "y": 5,
      "z": 2,
      "name": "Rock_Sandstone_White"
    },
    {
      "x": -2,
      "y": 6,
      "z": 2,
      "name": "Rock_Sandstone_White"
    },
    {
      "x": -2,
      "y": 7,
      "z": 2,
      "name": "Wood_Drywood_Planks"
    },
    {
      "x": -2,
      "y": 8,
      "z": 2,
      "name": "Soil_Sand_White"
    },
    {
      "x": -2,
      "y": 9,
      "z": 2,
      "name": "Wood_Drywood_Stairs"
    },
    {
      "x": -2,
      "y": 3,
      "z": 3,
      "name": "Rock_Sandstone_White"
    },
    {
      "x": -2,
      "y": 4,
      "z": 3,
      "name": "Rock_Sandstone_White"
    },
    {
      "x": -2,
      "y": 5,
      "z": 3,
      "name": "Rock_Sandstone_White"
    },
    {
      "x": -2,
      "y": 6,
      "z": 3,
      "name": "Rock_Sandstone_White"
    },
    {
      "x": -2,
      "y": 7,
      "z": 3,
      "name": "Soil_Sand_White"
    },
    {
      "x": -2,
      "y": 8,
      "z": 3,
      "name": "Wood_Drywood_Planks"
    },
    {
      "x": -2,
      "y": 9,
      "z": 3,
      "name": "Wood_Drywood_Planks_Half",
      "rotation": 6
    },
    {
      "x": -2,
      "y": 4,
      "z": 4,
      "name": "Rock_Sandstone_White"
    },
    {
      "x": -2,
      "y": 5,
      "z": 4,
      "name": "Rock_Sandstone_White"
    },
    {
      "x": -2,
      "y": 6,
      "z": 4,
      "name": "Rock_Sandstone_White"
    },
    {
      "x": -2,
      "y": 7,
      "z": 4,
      "name": "Wood_Dry_Trunk"
    },
    {
      "x": -2,
      "y": 8,
      "z": 4,
      "name": "Wood_Dry_Trunk"
    },
    {
      "x": -2,
      "y": 9,
      "z": 4,
      "name": "Wood_Dry_Trunk"
    },
    {
      "x": -2,
      "y": 10,
      "z": 4,
      "name": "Wood_Dry_Trunk"
    },
    {
      "x": -2,
      "y": 11,
      "z": 4,
      "name": "Wood_Dry_Branch_Long"
    },
    {
      "x": -1,
      "y": 4,
      "z": -3,
      "name": "Rock_Sandstone_White"
    },
    {
      "x": -1,
      "y": 5,
      "z": -3,
      "name": "Rock_Sandstone_White"
    },
    {
      "x": -1,
      "y": 6,
      "z": -3,
      "name": "Rock_Sandstone_White"
    },
    {
      "x": -1,
      "y": 7,
      "z": -3,
      "name": "Rock_Sandstone_White"
    },
    {
      "x": -1,
      "y": 3,
      "z": -2,
      "name": "Rock_Sandstone_White"
    },
    {
      "x": -1,
      "y": 4,
      "z": -2,
      "name": "Rock_Sandstone_White"
    },
    {
      "x": -1,
      "y": 5,
      "z": -2,
      "name": "Rock_Sandstone_White"
    },
    {
      "x": -1,
      "y": 6,
      "z": -2,
      "name": "Rock_Sandstone_White"
    },
    {
      "x": -1,
      "y": 7,
      "z": -2,
      "name": "Soil_Sand_White"
    },
    {
      "x": -1,
      "y": 11,
      "z": -2,
      "name": "Wood_Dry_Branch_Short",
      "rotation": 1
    },
    {
      "x": -1,
      "y": 2,
      "z": -1,
      "name": "Rock_Sandstone_White"
    },
    {
      "x": -1,
      "y": 3,
      "z": -1,
      "name": "Rock_Sandstone_White"
    },
    {
      "x": -1,
      "y": 4,
      "z": -1,
      "name": "Rock_Sandstone_White"
    },
    {
      "x": -1,
      "y": 5,
      "z": -1,
      "name": "Rock_Sandstone_White"
    },
    {
      "x": -1,
      "y": 6,
      "z": -1,
      "name": "Rock_Sandstone_White"
    },
    {
      "x": -1,
      "y": 7,
      "z": -1,
      "name": "Soil_Sand_White"
    },
    {
      "x": -1,
      "y": 2,
      "z": 0,
      "name": "Rock_Sandstone_White"
    },
    {
      "x": -1,
      "y": 3,
      "z": 0,
      "name": "Rock_Sandstone_White"
    },
    {
      "x": -1,
      "y": 4,
      "z": 0,
      "name": "Rock_Sandstone_White"
    },
    {
      "x": -1,
      "y": 5,
      "z": 0,
      "name": "Rock_Sandstone_White"
    },
    {
      "x": -1,
      "y": 6,
      "z": 0,
      "name": "Rock_Sandstone_White"
    },
    {
      "x": -1,
      "y": 7,
      "z": 0,
      "name": "Soil_Sand_White"
    },
    {
      "x": -1,
      "y": 2,
      "z": 1,
      "name": "Rock_Sandstone_White"
    },
    {
      "x": -1,
      "y": 3,
      "z": 1,
      "name": "Rock_Sandstone_White"
    },
    {
      "x": -1,
      "y": 4,
      "z": 1,
      "name": "Rock_Sandstone_White"
    },
    {
      "x": -1,
      "y": 5,
      "z": 1,
      "name": "Rock_Sandstone_White"
    },
    {
      "x": -1,
      "y": 6,
      "z": 1,
      "name": "Rock_Sandstone_White"
    },
    {
      "x": -1,
      "y": 3,
      "z": 2,
      "name": "Rock_Sandstone_White"
    },
    {
      "x": -1,
      "y": 4,
      "z": 2,
      "name": "Rock_Sandstone_White"
    },
    {
      "x": -1,
      "y": 5,
      "z": 2,
      "name": "Rock_Sandstone_White"
    },
    {
      "x": -1,
      "y": 6,
      "z": 2,
      "name": "Soil_Sand_White"
    },
    {
      "x": -1,
      "y": 4,
      "z": 3,
      "name": "Rock_Sandstone_White"
    },
    {
      "x": -1,
      "y": 5,
      "z": 3,
      "name": "Rock_Sandstone_White"
    },
    {
      "x": -1,
      "y": 6,
      "z": 3,
      "name": "Soil_Sand_White"
    },
    {
      "x": 0,
      "y": 5,
      "z": -3,
      "name": "Rock_Sandstone_White"
    },
    {
      "x": 0,
      "y": 6,
      "z": -3,
      "name": "Rock_Sandstone_White"
    },
    {
      "x": 0,
      "y": 7,
      "z": -3,
      "name": "Soil_Sand_White"
    },
    {
      "x": 0,
      "y": 3,
      "z": -2,
      "name": "Rock_Sandstone_White"
    },
    {
      "x": 0,
      "y": 4,
      "z": -2,
      "name": "Rock_Sandstone_White"
    },
    {
      "x": 0,
      "y": 5,
      "z": -2,
      "name": "Rock_Sandstone_White"
    },
    {
      "x": 0,
      "y": 6,
      "z": -2,
      "name": "Rock_Sandstone_White"
    },
    {
      "x": 0,
      "y": 7,
      "z": -2,
      "name": "Rock_Sandstone_White"
    },
    {
      "x": 0,
      "y": 2,
      "z": -1,
      "name": "Rock_Sandstone_White"
    },
    {
      "x": 0,
      "y": 3,
      "z": -1,
      "name": "Rock_Sandstone_White"
    },
    {
      "x": 0,
      "y": 4,
      "z": -1,
      "name": "Rock_Sandstone_White"
    },
    {
      "x": 0,
      "y": 5,
      "z": -1,
      "name": "Rock_Sandstone_White"
    },
    {
      "x": 0,
      "y": 6,
      "z": -1,
      "name": "Rock_Sandstone_White"
    },
    {
      "x": 0,
      "y": 7,
      "z": -1,
      "name": "Soil_Sand_White"
    },
    {
      "x": 0,
      "y": 2,
      "z": 0,
      "name": "Rock_Sandstone_White"
    },
    {
      "x": 0,
      "y": 3,
      "z": 0,
      "name": "Rock_Sandstone_White"
    },
    {
      "x": 0,
      "y": 4,
      "z": 0,
      "name": "Rock_Sandstone_White"
    },
    {
      "x": 0,
      "y": 5,
      "z": 0,
      "name": "Rock_Sandstone_White"
    },
    {
      "x": 0,
      "y": 6,
      "z": 0,
      "name": "Rock_Sandstone_White"
    },
    {
      "x": 0,
      "y": 7,
      "z": 0,
      "name": "Rock_Sandstone_White"
    },
    {
      "x": 0,
      "y": 3,
      "z": 1,
      "name": "Rock_Sandstone_White"
    },
    {
      "x": 0,
      "y": 4,
      "z": 1,
      "name": "Rock_Sandstone_White"
    },
    {
      "x": 0,
      "y": 5,
      "z": 1,
      "name": "Rock_Sandstone_White"
    },
    {
      "x": 0,
      "y": 6,
      "z": 1,
      "name": "Soil_Sand_White"
    },
    {
      "x": 0,
      "y": 4,
      "z": 2,
      "name": "Rock_Sandstone_White"
    },
    {
      "x": 0,
      "y": 5,
      "z": 2,
      "name": "Rock_Sandstone_White"
    },
    {
      "x": 0,
      "y": 6,
      "z": 2,
      "name": "Soil_Sand_White"
    },
    {
      "x": 1,
      "y": 1,
      "z": -3,
      "name": "Rock_Sandstone_Cobble"
    },
    {
      "x": 1,
      "y": 2,
      "z": -3,
      "name": "Rock_Sandstone_Cobble"
    },
    {
      "x": 1,
      "y": 6,
      "z": -3,
      "name": "Rock_Sandstone_White"
    },
    {
      "x": 1,
      "y": 7,
      "z": -3,
      "name": "Rock_Sandstone_White"
    },
    {
      "x": 1,
      "y": 8,
      "z": -3,
      "name": "Rock_Sandstone_White"
    },
    {
      "x": 1,
      "y": 9,
      "z": -3,
      "name": "Container_Bucket"
    },
    {
      "x": 1,
      "y": 1,
      "z": -2,
      "name": "Rock_Sandstone_Cobble"
    },
    {
      "x": 1,
      "y": 2,
      "z": -2,
      "name": "Rock_Sandstone_Cobble"
    },
    {
      "x": 1,
      "y": 3,
      "z": -2,
      "name": "Rock_Sandstone_White"
    },
    {
      "x": 1,
      "y": 4,
      "z": -2,
      "name": "Rock_Sandstone_White"
    },
    {
      "x": 1,
      "y": 5,
      "z": -2,
      "name": "Rock_Sandstone_White"
    },
    {
      "x": 1,
      "y": 6,
      "z": -2,
      "name": "Rock_Sandstone_White"
    },
    {
      "x": 1,
      "y": 7,
      "z": -2,
      "name": "Rock_Sandstone_White"
    },
    {
      "x": 1,
      "y": 8,
      "z": -2,
      "name": "Rock_Sandstone_White"
    },
    {
      "x": 1,
      "y": 9,
      "z": -2,
      "name": "Empty"
    },
    {
      "x": 1,
      "y": 12,
      "z": -2,
      "name": "Plant_Moss_Wall_Yellow",
      "rotation": 3
    },
    {
      "x": 1,
      "y": 2,
      "z": -1,
      "name": "Rock_Sandstone_White"
    },
    {
      "x": 1,
      "y": 3,
      "z": -1,
      "name": "Rock_Sandstone_White"
    },
    {
      "x": 1,
      "y": 4,
      "z": -1,
      "name": "Rock_Sandstone_White"
    },
    {
      "x": 1,
      "y": 5,
      "z": -1,
      "name": "Rock_Sandstone_White"
    },
    {
      "x": 1,
      "y": 6,
      "z": -1,
      "name": "Rock_Sandstone_White"
    },
    {
      "x": 1,
      "y": 7,
      "z": -1,
      "name": "Soil_Sand_White"
    },
    {
      "x": 1,
      "y": 3,
      "z": 0,
      "name": "Rock_Sandstone_White"
    },
    {
      "x": 1,
      "y": 4,
      "z": 0,
      "name": "Rock_Sandstone_White"
    },
    {
      "x": 1,
      "y": 5,
      "z": 0,
      "name": "Rock_Sandstone_White"
    },
    {
      "x": 1,
      "y": 6,
      "z": 0,
      "name": "Soil_Sand_White"
    },
    {
      "x": 2,
      "y": 1,
      "z": -4,
      "name": "Rock_Sandstone_Cobble"
    },
    {
      "x": 2,
      "y": 2,
      "z": -4,
      "name": "Rock_Sandstone_Cobble"
    },
    {
      "x": 2,
      "y": 3,
      "z": -4,
      "name": "Rock_Sandstone_Cobble"
    },
    {
      "x": 2,
      "y": 7,
      "z": -4,
      "name": "Rock_Sandstone_White"
    },
    {
      "x": 2,
      "y": 8,
      "z": -4,
      "name": "Rock_Sandstone_White"
    },
    {
      "x": 2,
      "y": 9,
      "z": -4,
      "name": "Empty"
    },
    {
      "x": 2,
      "y": 0,
      "z": -3,
      "name": "Rock_Sandstone_Cobble"
    },
    {
      "x": 2,
      "y": 1,
      "z": -3,
      "name": "Furniture_Village_Pot"
    },
    {
      "x": 2,
      "y": 2,
      "z": -3,
      "name": "Empty"
    },
    {
      "x": 2,
      "y": 3,
      "z": -3,
      "name": "Empty"
    },
    {
      "x": 2,
      "y": 4,
      "z": -3,
      "name": "Empty"
    },
    {
      "x": 2,
      "y": 5,
      "z": -3,
      "name": "Empty"
    },
    {
      "x": 2,
      "y": 6,
      "z": -3,
      "name": "Empty"
    },
    {
      "x": 2,
      "y": 7,
      "z": -3,
      "name": "Rock_Sandstone_Cobble"
    },
    {
      "x": 2,
      "y": 8,
      "z": -3,
      "name": "Rock_Sandstone_White"
    },
    {
      "x": 2,
      "y": 9,
      "z": -3,
      "name": "Wood_Drywood_Planks_Half",
      "rotation": 7
    },
    {
      "x": 2,
      "y": 10,
      "z": -3,
      "name": "Empty"
    },
    {
      "x": 2,
      "y": 11,
      "z": -3,
      "name": "Empty"
    },
    {
      "x": 2,
      "y": 12,
      "z": -3,
      "name": "Wood_Dry_Branch_Short",
      "rotation": 2
    },
    {
      "x": 2,
      "y": 0,
      "z": -2,
      "name": "Rock_Sandstone_Cobble"
    },
    {
      "x": 2,
      "y": 1,
      "z": -2,
      "name": "Empty"
    },
    {
      "x": 2,
      "y": 2,
      "z": -2,
      "name": "Empty"
    },
    {
      "x": 2,
      "y": 3,
      "z": -2,
      "name": "Empty"
    },
    {
      "x": 2,
      "y": 4,
      "z": -2,
      "name": "Empty"
    },
    {
      "x": 2,
      "y": 5,
      "z": -2,
      "name": "Plant_Moss_Wall_Yellow",
      "rotation": 2
    },
    {
      "x": 2,
      "y": 6,
      "z": -2,
      "name": "Rock_Sandstone_Cobble"
    },
    {
      "x": 2,
      "y": 7,
      "z": -2,
      "name": "Rock_Sandstone_Cobble"
    },
    {
      "x": 2,
      "y": 8,
      "z": -2,
      "name": "Rock_Sandstone_White"
    },
    {
      "x": 2,
      "y": 9,
      "z": -2,
      "name": "Wood_Dry_Trunk"
    },
    {
      "x": 2,
      "y": 10,
      "z": -2,
      "name": "Wood_Dry_Branch_Long"
    },
    {
      "x": 2,
      "y": 11,
      "z": -2,
      "name": "Wood_Dry_Branch_Long"
    },
    {
      "x": 2,
      "y": 12,
      "z": -2,
      "name": "Wood_Dry_Trunk",
      "rotation": 5
    },
    {
      "x": 2,
      "y": 1,
      "z": -1,
      "name": "Rock_Sandstone_Cobble"
    },
    {
      "x": 2,
      "y": 2,
      "z": -1,
      "name": "Rock_Sandstone_Cobble"
    },
    {
      "x": 2,
      "y": 5,
      "z": -1,
      "name": "Rock_Sandstone_Cobble"
    },
    {
      "x": 2,
      "y": 6,
      "z": -1,
      "name": "Rock_Sandstone_Cobble"
    },
    {
      "x": 2,
      "y": 7,
      "z": -1,
      "name": "Rock_Sandstone_Cobble"
    },
    {
      "x": 2,
      "y": 8,
      "z": -1,
      "name": "Rock_Sandstone_White"
    },
    {
      "x": 2,
      "y": 9,
      "z": -1,
      "name": "Wood_Drywood_Planks_Half",
      "rotation": 7
    },
    {
      "x": 2,
      "y": 10,
      "z": -1,
      "name": "Empty"
    },
    {
      "x": 2,
      "y": 11,
      "z": -1,
      "name": "Empty"
    },
    {
      "x": 2,
      "y": 12,
      "z": -1,
      "name": "Wood_Dry_Branch_Short"
    },
    {
      "x": 2,
      "y": 7,
      "z": 0,
      "name": "Rock_Sandstone_White"
    },
    {
      "x": 2,
      "y": 8,
      "z": 0,
      "name": "Soil_Sand_White"
    },
    {
      "x": 3,
      "y": 1,
      "z": -4,
      "name": "Rock_Sandstone_Cobble"
    },
    {
      "x": 3,
      "y": 2,
      "z": -4,
      "name": "Rock_Sandstone_Cobble"
    },
    {
      "x": 3,
      "y": 3,
      "z": -4,
      "name": "Rock_Sandstone_Cobble"
    },
    {
      "x": 3,
      "y": 6,
      "z": -4,
      "name": "Rock_Sandstone_Cobble"
    },
    {
      "x": 3,
      "y": 7,
      "z": -4,
      "name": "Rock_Sandstone_Cobble"
    },
    {
      "x": 3,
      "y": 8,
      "z": -4,
      "name": "Rock_Sandstone_White"
    },
    {
      "x": 3,
      "y": 9,
      "z": -4,
      "name": "Wood_Drywood_Planks_Half",
      "rotation": 6
    },
    {
      "x": 3,
      "y": 10,
      "z": -4,
      "name": "Empty"
    },
    {
      "x": 3,
      "y": 0,
      "z": -3,
      "name": "Rock_Sandstone_Cobble"
    },
    {
      "x": 3,
      "y": 1,
      "z": -3,
      "name": "Empty"
    },
    {
      "x": 3,
      "y": 2,
      "z": -3,
      "name": "Empty"
    },
    {
      "x": 3,
      "y": 3,
      "z": -3,
      "name": "Empty"
    },
    {
      "x": 3,
      "y": 4,
      "z": -3,
      "name": "Empty"
    },
    {
      "x": 3,
      "y": 5,
      "z": -3,
      "name": "Empty"
    },
    {
      "x": 3,
      "y": 6,
      "z": -3,
      "name": "Empty"
    },
    {
      "x": 3,
      "y": 7,
      "z": -3,
      "name": "Empty"
    },
    {
      "x": 3,
      "y": 8,
      "z": -3,
      "name": "Empty"
    },
    {
      "x": 3,
      "y": 9,
      "z": -3,
      "name": "Empty"
    },
    {
      "x": 3,
      "y": 10,
      "z": -3,
      "name": "Empty"
    },
    {
      "x": 3,
      "y": 11,
      "z": -3,
      "name": "Empty"
    },
    {
      "x": 3,
      "y": 12,
      "z": -3,
      "name": "Empty"
    },
    {
      "x": 3,
      "y": 0,
      "z": -2,
      "name": "Rock_Sandstone_Cobble"
    },
    {
      "x": 3,
      "y": 1,
      "z": -2,
      "name": "Empty"
    },
    {
      "x": 3,
      "y": 2,
      "z": -2,
      "name": "Deco_Rope"
    },
    {
      "x": 3,
      "y": 3,
      "z": -2,
      "name": "Deco_Rope"
    },
    {
      "x": 3,
      "y": 4,
      "z": -2,
      "name": "Deco_Rope"
    },
    {
      "x": 3,
      "y": 5,
      "z": -2,
      "name": "Deco_Rope"
    },
    {
      "x": 3,
      "y": 6,
      "z": -2,
      "name": "Deco_Rope"
    },
    {
      "x": 3,
      "y": 7,
      "z": -2,
      "name": "Deco_Rope"
    },
    {
      "x": 3,
      "y": 8,
      "z": -2,
      "name": "Deco_Rope"
    },
    {
      "x": 3,
      "y": 9,
      "z": -2,
      "name": "Deco_Rope"
    },
    {
      "x": 3,
      "y": 10,
      "z": -2,
      "name": "Deco_Rope"
    },
    {
      "x": 3,
      "y": 11,
      "z": -2,
      "name": "Deco_Rope"
    },
    {
      "x": 3,
      "y": 12,
      "z": -2,
      "name": "Wood_Dry_Trunk",
      "rotation": 5
    },
    {
      "x": 3,
      "y": 0,
      "z": -1,
      "name": "Rock_Sandstone_Cobble"
    },
    {
      "x": 3,
      "y": 1,
      "z": -1,
      "name": "Plant_Reeds_Water"
    },
    {
      "x": 3,
      "y": 2,
      "z": -1,
      "name": "Plant_Reeds_Water",
      "filler": 1024
    },
    {
      "x": 3,
      "y": 3,
      "z": -1,
      "name": "Empty"
    },
    {
      "x": 3,
      "y": 4,
      "z": -1,
      "name": "Empty"
    },
    {
      "x": 3,
      "y": 5,
      "z": -1,
      "name": "Empty"
    },
    {
      "x": 3,
      "y": 6,
      "z": -1,
      "name": "Empty"
    },
    {
      "x": 3,
      "y": 7,
      "z": -1,
      "name": "Empty"
    },
    {
      "x": 3,
      "y": 8,
      "z": -1,
      "name": "Empty"
    },
    {
      "x": 3,
      "y": 9,
      "z": -1,
      "name": "Empty"
    },
    {
      "x": 3,
      "y": 10,
      "z": -1,
      "name": "Empty"
    },
    {
      "x": 3,
      "y": 11,
      "z": -1,
      "name": "Empty"
    },
    {
      "x": 3,
      "y": 12,
      "z": -1,
      "name": "Empty"
    },
    {
      "x": 3,
      "y": 1,
      "z": 0,
      "name": "Rock_Sandstone_Cobble"
    },
    {
      "x": 3,
      "y": 2,
      "z": 0,
      "name": "Rock_Sandstone_Cobble"
    },
    {
      "x": 3,
      "y": 6,
      "z": 0,
      "name": "Rock_Sandstone_Cobble"
    },
    {
      "x": 3,
      "y": 7,
      "z": 0,
      "name": "Rock_Sandstone_Cobble"
    },
    {
      "x": 3,
      "y": 8,
      "z": 0,
      "name": "Rock_Sandstone_White"
    },
    {
      "x": 3,
      "y": 9,
      "z": 0,
      "name": "Wood_Drywood_Planks_Half",
      "rotation": 4
    },
    {
      "x": 3,
      "y": 10,
      "z": 0,
      "name": "Empty"
    },
    {
      "x": 3,
      "y": 11,
      "z": 0,
      "name": "Empty"
    },
    {
      "x": 4,
      "y": 1,
      "z": -4,
      "name": "Rock_Sandstone_Cobble"
    },
    {
      "x": 4,
      "y": 2,
      "z": -4,
      "name": "Rock_Sandstone_Cobble"
    },
    {
      "x": 4,
      "y": 7,
      "z": -4,
      "name": "Rock_Sandstone_White"
    },
    {
      "x": 4,
      "y": 8,
      "z": -4,
      "name": "Rock_Sandstone_White"
    },
    {
      "x": 4,
      "y": 9,
      "z": -4,
      "name": "Empty"
    },
    {
      "x": 4,
      "y": 0,
      "z": -3,
      "name": "Rock_Sandstone_Cobble"
    },
    {
      "x": 4,
      "y": 1,
      "z": -3,
      "name": "Empty"
    },
    {
      "x": 4,
      "y": 2,
      "z": -3,
      "name": "Empty"
    },
    {
      "x": 4,
      "y": 3,
      "z": -3,
      "name": "Empty"
    },
    {
      "x": 4,
      "y": 4,
      "z": -3,
      "name": "Empty"
    },
    {
      "x": 4,
      "y": 5,
      "z": -3,
      "name": "Empty"
    },
    {
      "x": 4,
      "y": 6,
      "z": -3,
      "name": "Empty"
    },
    {
      "x": 4,
      "y": 7,
      "z": -3,
      "name": "Rock_Sandstone_Cobble"
    },
    {
      "x": 4,
      "y": 8,
      "z": -3,
      "name": "Rock_Sandstone_White"
    },
    {
      "x": 4,
      "y": 9,
      "z": -3,
      "name": "Wood_Drywood_Planks_Half",
      "rotation": 5
    },
    {
      "x": 4,
      "y": 10,
      "z": -3,
      "name": "Empty"
    },
    {
      "x": 4,
      "y": 11,
      "z": -3,
      "name": "Empty"
    },
    {
      "x": 4,
      "y": 12,
      "z": -3,
      "name": "Wood_Dry_Branch_Short",
      "rotation": 2
    },
    {
      "x": 4,
      "y": 0,
      "z": -2,
      "name": "Rock_Sandstone_Cobble"
    },
    {
      "x": 4,
      "y": 1,
      "z": -2,
      "name": "Deco_Pot_Clay_Broken"
    },
    {
      "x": 4,
      "y": 2,
      "z": -2,
      "name": "Empty"
    },
    {
      "x": 4,
      "y": 3,
      "z": -2,
      "name": "Plant_Moss_Wall_Yellow",
      "rotation": 3
    },
    {
      "x": 4,
      "y": 4,
      "z": -2,
      "name": "Empty"
    },
    {
      "x": 4,
      "y": 5,
      "z": -2,
      "name": "Empty"
    },
    {
      "x": 4,
      "y": 6,
      "z": -2,
      "name": "Rock_Sandstone_Cobble"
    },
    {
      "x": 4,
      "y": 7,
      "z": -2,
      "name": "Rock_Sandstone_Cobble"
    },
    {
      "x": 4,
      "y": 8,
      "z": -2,
      "name": "Rock_Sandstone_Cobble"
    },
    {
      "x": 4,
      "y": 9,
      "z": -2,
      "name": "Wood_Dry_Trunk"
    },
    {
      "x": 4,
      "y": 10,
      "z": -2,
      "name": "Wood_Dry_Branch_Long"
    },
    {
      "x": 4,
      "y": 11,
      "z": -2,
      "name": "Wood_Dry_Branch_Long"
    },
    {
      "x": 4,
      "y": 12,
      "z": -2,
      "name": "Wood_Dry_Trunk",
      "rotation": 5
    },
    {
      "x": 4,
      "y": 0,
      "z": -1,
      "name": "Rock_Sandstone_Cobble"
    },
    {
      "x": 4,
      "y": 1,
      "z": -1,
      "name": "Empty"
    },
    {
      "x": 4,
      "y": 2,
      "z": -1,
      "name": "Empty"
    },
    {
      "x": 4,
      "y": 3,
      "z": -1,
      "name": "Empty"
    },
    {
      "x": 4,
      "y": 4,
      "z": -1,
      "name": "Empty"
    },
    {
      "x": 4,
      "y": 5,
      "z": -1,
      "name": "Empty"
    },
    {
      "x": 4,
      "y": 6,
      "z": -1,
      "name": "Empty"
    },
    {
      "x": 4,
      "y": 7,
      "z": -1,
      "name": "Rock_Sandstone_Cobble"
    },
    {
      "x": 4,
      "y": 8,
      "z": -1,
      "name": "Rock_Sandstone_White"
    },
    {
      "x": 4,
      "y": 9,
      "z": -1,
      "name": "Wood_Drywood_Planks_Half",
      "rotation": 5
    },
    {
      "x": 4,
      "y": 10,
      "z": -1,
      "name": "Empty"
    },
    {
      "x": 4,
      "y": 12,
      "z": -1,
      "name": "Wood_Dry_Branch_Short"
    },
    {
      "x": 4,
      "y": 1,
      "z": 0,
      "name": "Rock_Sandstone_Cobble"
    },
    {
      "x": 4,
      "y": 2,
      "z": 0,
      "name": "Rock_Sandstone_Cobble"
    },
    {
      "x": 4,
      "y": 7,
      "z": 0,
      "name": "Rock_Sandstone_White"
    },
    {
      "x": 4,
      "y": 8,
      "z": 0,
      "name": "Soil_Sand_White"
    },
    {
      "x": 5,
      "y": 1,
      "z": -3,
      "name": "Rock_Sandstone_Cobble"
    },
    {
      "x": 5,
      "y": 2,
      "z": -3,
      "name": "Rock_Sandstone_Cobble"
    },
    {
      "x": 5,
      "y": 3,
      "z": -3,
      "name": "Rock_Sandstone_Cobble"
    },
    {
      "x": 5,
      "y": 7,
      "z": -3,
      "name": "Rock_Sandstone_White"
    },
    {
      "x": 5,
      "y": 1,
      "z": -2,
      "name": "Rock_Sandstone_Cobble"
    },
    {
      "x": 5,
      "y": 2,
      "z": -2,
      "name": "Rock_Sandstone_Cobble"
    },
    {
      "x": 5,
      "y": 3,
      "z": -2,
      "name": "Rock_Sandstone_Cobble"
    },
    {
      "x": 5,
      "y": 6,
      "z": -2,
      "name": "Rock_Sandstone_White"
    },
    {
      "x": 5,
      "y": 7,
      "z": -2,
      "name": "Rock_Sandstone_White"
    },
    {
      "x": 5,
      "y": 8,
      "z": -2,
      "name": "Rock_Sandstone_White"
    },
    {
      "x": 5,
      "y": 9,
      "z": -2,
      "name": "Plant_Bush_Arid_Sharp"
    },
    {
      "x": 5,
      "y": 1,
      "z": -1,
      "name": "Rock_Sandstone_Cobble"
    },
    {
      "x": 5,
      "y": 2,
      "z": -1,
      "name": "Rock_Sandstone_Cobble"
    },
    {
      "x": 5,
      "y": 3,
      "z": -1,
      "name": "Rock_Sandstone_Cobble"
    },
    {
      "x": 5,
      "y": 7,
      "z": -1,
      "name": "Rock_Sandstone_White"
    },
    {
      "x": 5,
      "y": 8,
      "z": -1,
      "name": "Soil_Sand_White"
    }
  ]
}