{
  "version": 8,
  "blockIdVersion": 8,
  "anchorX": 3,
  "anchorY": 1,
  "anchorZ": -5,
  "blocks": [
    {
      "x": -3,
      "y": 0,
      "z": 1,
      "name": "Rock_Basalt_Brick"
    },
    {
      "x": -3,
      "y": 1,
      "z": 1,
      "name": "Rock_Basalt_Brick"
    },
    {
      "x": -3,
      "y": 2,
      "z": 1,
      "name": "Rock_Basalt_Brick"
    },
    {
      "x": -3,
      "y": 3,
      "z": 1,
      "name": "Rock_Basalt_Brick"
    },
    {
      "x": -3,
      "y": 0,
      "z": 2,
      "name": "Rock_Basalt_Brick"
    },
    {
      "x": -3,
      "y": 1,
      "z": 2,
      "name": "Plant_Moss_Green"
    },
    {
      "x": -3,
      "y": 2,
      "z": 2,
      "name": "Empty"
    },
    {
      "x": -3,
      "y": 3,
      "z": 2,
      "name": "Rock_Basalt_Brick"
    },
    {
      "x": -3,
      "y": 0,
      "z": 3,
      "name": "Rock_Basalt_Brick"
    },
    {
      "x": -3,
      "y": 1,
      "z": 3,
      "name": "Furniture_Ancient_Coffin"
    },
    {
      "x": -3,
      "y": 2,
      "z": 3,
      "name": "Empty"
    },
    {
      "x": -3,
      "y": 3,
      "z": 3,
      "name": "Rock_Basalt_Brick"
    },
    {
      "x": -3,
      "y": 0,
      "z": 4,
      "name": "Rock_Basalt_Brick"
    },
    {
      "x": -3,
      "y": 1,
      "z": 4,
      "name": "Rock_Basalt_Brick"
    },
    {
      "x": -3,
      "y": 2,
      "z": 4,
      "name": "Rock_Basalt_Brick"
    },
    {
      "x": -3,
      "y": 3,
      "z": 4,
      "name": "Rock_Basalt_Brick"
    },
    {
      "x": -2,
      "y": 0,
      "z": 1,
      "name": "Rock_Basalt_Brick"
    },
    {
      "x": -2,
      "y": 1,
      "z": 1,
      "name": "Rock_Basalt_Brick"
    },
    {
      "x": -2,
      "y": 2,
      "z": 1,
      "name": "Rock_Basalt_Brick"
    },
    {
      "x": -2,
      "y": 3,
      "z": 1,
      "name": "Rock_Basalt_Brick"
    },
    {
      "x": -2,
      "y": 0,
      "z": 2,
      "name": "Rock_Basalt_Brick"
    },
    {
      "x": -2,
      "y": 1,
      "z": 2,
      "name": "Empty"
    },
    {
      "x": -2,
      "y": 2,
      "z": 2,
      "name": "Empty"
    },
    {
      "x": -2,
      "y": 3,
      "z": 2,
      "name": "Rock_Basalt_Brick"
    },
    {
      "x": -2,
      "y": 0,
      "z": 3,
      "name": "Rock_Basalt_Brick"
    },
    {
      "x": -2,
      "y": 1,
      "z": 3,
      "name": "Furniture_Ancient_Coffin",
      "filler": 1
    },
    {
      "x": -2,
      "y": 2,
      "z": 3,
      "name": "Empty"
    },
    {
      "x": -2,
      "y": 3,
      "z": 3,
      "name": "Rock_Basalt_Brick"
    },
    {
      "x": -2,
      "y": 0,
      "z": 4,
      "name": "Rock_Basalt_Brick"
    },
    {
      "x": -2,
      "y": 1,
      "z": 4,
      "name": "Rock_Basalt_Brick"
    },
    {
      "x": -2,
      "y": 2,
      "z": 4,
      "name": "Rock_Basalt_Brick"
    },
    {
      "x": -2,
      "y": 3,
      "z": 4,
      "name": "Rock_Basalt_Brick"
    },
    {
      "x": -2,
      "y": 0,
      "z": 5,
      "name": "Rock_Basalt_Brick"
    },
    {
      "x": -2,
      "y": 1,
      "z": 5,
      "name": "Rock_Basalt_Brick"
    },
    {
      "x": -2,
      "y": 2,
      "z": 5,
      "name": "Rock_Basalt_Brick"
    },
    {
      "x": -2,
      "y": 3,
      "z": 5,
      "name": "Rock_Basalt_Brick"
    },
    {
      "x": -2,
      "y": 0,
      "z": 6,
      "name": "Rock_Basalt_Brick"
    },
    {
      "x": -2,
      "y": 1,
      "z": 6,
      "name": "Rock_Basalt_Brick"
    },
    {
      "x": -2,
      "y": 2,
      "z": 6,
      "name": "Rock_Basalt_Brick"
    },
    {
      "x": -2,
      "y": 3,
      "z": 6,
      "name": "Rock_Basalt_Brick"
    },
    {
      "x": -1,
      "y": 0,
      "z": 1,
      "name": "Rock_Basalt_Brick"
    },
    {
      "x": -1,
      "y": 1,
      "z": 1,
      "name": "Rock_Basalt_Brick"
    },
    {
      "x": -1,
      "y": 2,
      "z": 1,
      "name": "Rock_Basalt_Brick"
    },
    {
      "x": -1,
      "y": 3,
      "z": 1,
      "name": "Rock_Basalt_Brick"
    },
    {
      "x": -1,
      "y": 0,
      "z": 2,
      "name": "Rock_Basalt_Brick"
    },
    {
      "x": -1,
      "y": 1,
      "z": 2,
      "name": "Plant_Seaweed_Grass_Bulbs"
    },
    {
      "x": -1,
      "y": 2,
      "z": 2,
      "name": "Plant_Seaweed_Grass_Bulbs",
      "filler": 1024
    },
    {
      "x": -1,
      "y": 3,
      "z": 2,
      "name": "Rock_Basalt_Brick"
    },
    {
      "x": -1,
      "y": 0,
      "z": 3,
      "name": "Rock_Basalt_Brick"
    },
    {
      "x": -1,
      "y": 1,
      "z": 3,
      "name": "Empty"
    },
    {
      "x": -1,
      "y": 2,
      "z": 3,
      "name": "Empty"
    },
    {
      "x": -1,
      "y": 3,
      "z": 3,
      "name": "Rock_Basalt_Brick"
    },
    {
      "x": -1,
      "y": 0,
      "z": 4,
      "name": "Rock_Basalt_Brick"
    },
    {
      "x": -1,
      "y": 1,
      "z": 4,
      "name": "Plant_Moss_Rug_Green"
    },
    {
      "x": -1,
      "y": 2,
      "z": 4,
      "name": "Empty"
    },
    {
      "x": -1,
      "y": 3,
      "z": 4,
      "name": "Rock_Basalt_Brick"
    },
    {
      "x": -1,
      "y": 0,
      "z": 5,
      "name": "Rock_Basalt_Brick"
    },
    {
      "x": -1,
      "y": 1,
      "z": 5,
      "name": "Plant_Moss_Rug_Green"
    },
    {
      "x": -1,
      "y": 2,
      "z": 5,
      "name": "Empty"
    },
    {
      "x": -1,
      "y": 3,
      "z": 5,
      "name": "Rock_Basalt_Brick"
    },
    {
      "x": -1,
      "y": 0,
      "z": 6,
      "name": "Rock_Basalt_Brick"
    },
    {
      "x": -1,
      "y": 1,
      "z": 6,
      "name": "Rock_Basalt_Brick"
    },
    {
      "x": -1,
      "y": 2,
      "z": 6,
      "name": "Rock_Basalt_Brick"
    },
    {
      "x": -1,
      "y": 3,
      "z": 6,
      "name": "Rock_Basalt_Brick"
    },
    {
      "x": 0,
      "y": 0,
      "z": 1,
      "name": "Rock_Basalt_Brick"
    },
    {
      "x": 0,
      "y": 1,
      "z": 1,
      "name": "Rock_Basalt_Brick"
    },
    {
      "x": 0,
      "y": 2,
      "z": 1,
      "name": "Rock_Basalt_Brick"
    },
    {
      "x": 0,
      "y": 3,
      "z": 1,
      "name": "Rock_Basalt_Brick"
    },
    {
      "x": 0,
      "y": 0,
      "z": 2,
      "name": "Rock_Basalt_Brick"
    },
    {
      "x": 0,
      "y": 1,
      "z": 2,
      "name": "Plant_Reeds_Poison"
    },
    {
      "x": 0,
      "y": 2,
      "z": 2,
      "name": "Empty"
    },
    {
      "x": 0,
      "y": 3,
      "z": 2,
      "name": "Rock_Basalt_Brick"
    },
    {
      "x": 0,
      "y": 0,
      "z": 3,
      "name": "Rock_Basalt_Brick"
    },
    {
      "x": 0,
      "y": 1,
      "z": 3,
      "name": "Plant_Moss_Rug_Green"
    },
    {
      "x": 0,
      "y": 2,
      "z": 3,
      "name": "Empty"
    },
    {
      "x": 0,
      "y": 3,
      "z": 3,
      "name": "Rock_Basalt_Brick"
    },
    {
      "x": 0,
      "y": 0,
      "z": 4,
      "name": "Rock_Basalt_Brick"
    },
    {
      "x": 0,
      "y": 1,
      "z": 4,
      "name": "Plant_Moss_Rug_Green"
    },
    {
      "x": 0,
      "y": 2,
      "z": 4,
      "name": "Empty"
    },
    {
      "x": 0,
      "y": 3,
      "z": 4,
      "name": "Rock_Basalt_Brick"
    },
    {
      "x": 0,
      "y": 0,
      "z": 5,
      "name": "Rock_Basalt_Brick"
    },
    {
      "x": 0,
      "y": 1,
      "z": 5,
      "name": "Plant_Moss_Rug_Green"
    },
    {
      "x": 0,
      "y": 2,
      "z": 5,
      "name": "Empty"
    },
    {
      "x": 0,
      "y": 3,
      "z": 5,
      "name": "Rock_Basalt_Brick"
    },
    {
      "x": 0,
      "y": 0,
      "z": 6,
      "name": "Rock_Basalt_Brick"
    },
    {
      "x": 0,
      "y": 1,
      "z": 6,
      "name": "Rock_Basalt_Brick"
    },
    {
      "x": 0,
      "y": 2,
      "z": 6,
      "name": "Rock_Basalt_Brick"
    },
    {
      "x": 0,
      "y": 3,
      "z": 6,
      "name": "Rock_Basalt_Brick"
    },
    {
      "x": 1,
      "y": 0,
      "z": 1,
      "name": "Rock_Basalt_Brick"
    },
    {
      "x": 1,
      "y": 1,
      "z": 1,
      "name": "Rock_Basalt_Brick"
    },
    {
      "x": 1,
      "y": 2,
      "z": 1,
      "name": "Rock_Basalt_Brick"
    },
    {
      "x": 1,
      "y": 3,
      "z": 1,
      "name": "Rock_Basalt_Brick"
    },
    {
      "x": 1,
      "y": 0,
      "z": 2,
      "name": "Rock_Basalt_Brick"
    },
    {
      "x": 1,
      "y": 1,
      "z": 2,
      "name": "Empty"
    },
    {
      "x": 1,
      "y": 2,
      "z": 2,
      "name": "Empty"
    },
    {
      "x": 1,
      "y": 3,
      "z": 2,
      "name": "Rock_Basalt_Brick"
    },
    {
      "x": 1,
      "y": 0,
      "z": 3,
      "name": "Rock_Basalt_Brick"
    },
    {
      "x": 1,
      "y": 1,
      "z": 3,
      "name": "Empty"
    },
    {
      "x": 1,
      "y": 2,
      "z": 3,
      "name": "Empty"
    },
    {
      "x": 1,
      "y": 3,
      "z": 3,
      "name": "Rock_Basalt_Brick"
    },
    {
      "x": 1,
      "y": 0,
      "z": 4,
      "name": "Rock_Basalt_Brick"
    },
    {
      "x": 1,
      "y": 1,
      "z": 4,
      "name": "Empty"
    },
    {
      "x": 1,
      "y": 2,
      "z": 4,
      "name": "Empty"
    },
    {
      "x": 1,
      "y": 3,
      "z": 4,
      "name": "Rock_Basalt_Brick"
    },
    {
      "x": 1,
      "y": 0,
      "z": 5,
      "name": "Rock_Basalt_Brick"
    },
    {
      "x": 1,
      "y": 1,
      "z": 5,
      "name": "Plant_Moss_Green"
    },
    {
      "x": 1,
      "y": 2,
      "z": 5,
      "name": "Empty"
    },
    {
      "x": 1,
      "y": 3,
      "z": 5,
      "name": "Rock_Basalt_Brick"
    },
    {
      "x": 1,
      "y": 0,
      "z": 6,
      "name": "Rock_Basalt_Brick"
    },
    {
      "x": 1,
      "y": 1,
      "z": 6,
      "name": "Rock_Basalt_Brick"
    },
    {
      "x": 1,
      "y": 2,
      "z": 6,
      "name": "Rock_Basalt_Brick"
    },
    {
      "x": 1,
      "y": 3,
      "z": 6,
      "name": "Rock_Basalt_Brick"
    },
    {
      "x": 2,
      "y": 0,
      "z": -4,
      "name": "Rock_Basalt_Brick"
    },
    {
      "x": 2,
      "y": 1,
      "z": -4,
      "name": "Rock_Basalt_Brick"
    },
    {
      "x": 2,
      "y": 2,
      "z": -4,
      "name": "Rock_Basalt_Brick"
    },
    {
      "x": 2,
      "y": 3,
      "z": -4,
      "name": "Rock_Basalt_Brick"
    },
    {
      "x": 2,
      "y": 0,
      "z": -3,
      "name": "Rock_Basalt_Brick"
    },
    {
      "x": 2,
      "y": 1,
      "z": -3,
      "name": "Rock_Basalt_Brick"
    },
    {
      "x": 2,
      "y": 2,
      "z": -3,
      "name": "Rock_Basalt_Brick"
    },
    {
      "x": 2,
      "y": 3,
      "z": -3,
      "name": "Rock_Basalt_Brick"
    },
    {
      "x": 2,
      "y": 0,
      "z": -2,
      "name": "Rock_Basalt_Brick"
    },
    {
      "x": 2,
      "y": 1,
      "z": -2,
      "name": "Rock_Basalt_Brick"
    },
    {
      "x": 2,
      "y": 2,
      "z": -2,
      "name": "Rock_Basalt_Brick"
    },
    {
      "x": 2,
      "y": 3,
      "z": -2,
      "name": "Rock_Basalt_Brick"
    },
    {
      "x": 2,
      "y": 0,
      "z": -1,
      "name": "Rock_Basalt_Brick"
    },
    {
      "x": 2,
      "y": 1,
      "z": -1,
      "name": "Rock_Basalt_Brick"
    },
    {
      "x": 2,
      "y": 2,
      "z": -1,
      "name": "Rock_Basalt_Brick"
    },
    {
      "x": 2,
      "y": 3,
      "z": -1,
      "name": "Rock_Basalt_Brick"
    },
    {
      "x": 2,
      "y": 0,
      "z": 0,
      "name": "Rock_Basalt_Brick"
    },
    {
      "x": 2,
      "y": 1,
      "z": 0,
      "name": "Rock_Basalt_Brick"
    },
    {
      "x": 2,
      "y": 2,
      "z": 0,
      "name": "Rock_Basalt_Brick"
    },
    {
      "x": 2,
      "y": 3,
      "z": 0,
      "name": "Rock_Basalt_Brick"
    },
    {
      "x": 2,
      "y": 0,
      "z": 1,
      "name": "Rock_Basalt_Brick"
    },
    {
      "x": 2,
      "y": 1,
      "z": 1,
      "name": "Rock_Basalt_Brick"
    },
    {
      "x": 2,
      "y": 2,
      "z": 1,
      "name": "Rock_Basalt_Brick"
    },
    {
      "x": 2,
      "y": 3,
      "z": 1,
      "name": "Rock_Basalt_Brick"
    },
    {
      "x": 2,
      "y": 0,
      "z": 2,
      "name": "Rock_Basalt_Brick"
    },
    {
      "x": 2,
      "y": 1,
      "z": 2,
      "name": "Empty"
    },
    {
      "x": 2,
      "y": 2,
      "z": 2,
      "name": "Empty"
    },
    {
      "x": 2,
      "y": 3,
      "z": 2,
      "name": "Rock_Basalt_Brick"
    },
    {
      "x": 2,
      "y": 0,
      "z": 3,
      "name": "Rock_Basalt_Brick"
    },
    {
      "x": 2,
      "y": 1,
      "z": 3,
      "name": "Plant_Moss_Rug_Green"
    },
    {
      "x": 2,
      "y": 2,
      "z": 3,
      "name": "Empty"
    },
    {
      "x": 2,
      "y": 3,
      "z": 3,
      "name": "Rock_Basalt_Brick"
    },
    {
      "x": 2,
      "y": 0,
      "z": 4,
      "name": "Rock_Basalt_Brick"
    },
    {
      "x": 2,
      "y": 1,
      "z": 4,
      "name": "Plant_Reeds_Poison"
    },
    {
      "x": 2,
      "y": 2,
      "z": 4,
      "name": "Empty"
    },
    {
      "x": 2,
      "y": 3,
      "z": 4,
      "name": "Rock_Basalt_Brick"
    },
    {
      "x": 2,
      "y": 0,
      "z": 5,
      "name": "Rock_Basalt_Brick"
    },
    {
      "x": 2,
      "y": 1,
      "z": 5,
      "name": "Plant_Reeds_Poison"
    },
    {
      "x": 2,
      "y": 2,
      "z": 5,
      "name": "Empty"
    },
    {
      "x": 2,
      "y": 3,
      "z": 5,
      "name": "Rock_Basalt_Brick"
    },
    {
      "x": 2,
      "y": 0,
      "z": 6,
      "name": "Rock_Basalt_Brick"
    },
    {
      "x": 2,
      "y": 1,
      "z": 6,
      "name": "Rock_Basalt_Brick"
    },
    {
      "x": 2,
      "y": 2,
      "z": 6,
      "name": "Rock_Basalt_Brick"
    },
    {
      "x": 2,
      "y": 3,
      "z": 6,
      "name": "Rock_Basalt_Brick"
    },
    {
      "x": 2,
      "y": 0,
      "z": 7,
      "name": "Rock_Basalt_Brick"
    },
    {
      "x": 2,
      "y": 1,
      "z": 7,
      "name": "Rock_Basalt_Brick"
    },
    {
      "x": 2,
      "y": 2,
      "z": 7,
      "name": "Rock_Basalt_Brick"
    },
    {
      "x": 2,
      "y": 3,
      "z": 7,
      "name": "Rock_Basalt_Brick"
    },
    {
      "x": 3,
      "y": 1,
      "z": -5,
      "name": "Empty"
    },
    {
      "x": 3,
      "y": 0,
      "z": -4,
      "name": "Rock_Basalt_Brick"
    },
    {
      "x": 3,
      "y": 1,
      "z": -4,
      "name": "Empty"
    },
    {
      "x": 3,
      "y": 2,
      "z": -4,
      "name": "Empty"
    },
    {
      "x": 3,
      "y": 3,
      "z": -4,
      "name": "Rock_Basalt_Brick"
    },
    {
      "x": 3,
      "y": 0,
      "z": -3,
      "name": "Rock_Basalt_Brick"
    },
    {
      "x": 3,
      "y": 1,
      "z": -3,
      "name": "Empty"
    },
    {
      "x": 3,
      "y": 2,
      "z": -3,
      "name": "Empty"
    },
    {
      "x": 3,
      "y": 3,
      "z": -3,
      "name": "Rock_Basalt_Brick"
    },
    {
      "x": 3,
      "y": 0,
      "z": -2,
      "name": "Rock_Basalt_Brick"
    },
    {
      "x": 3,
      "y": 1,
      "z": -2,
      "name": "Plant_Reeds_Poison"
    },
    {
      "x": 3,
      "y": 2,
      "z": -2,
      "name": "Empty"
    },
    {
      "x": 3,
      "y": 3,
      "z": -2,
      "name": "Rock_Basalt_Brick"
    },
    {
      "x": 3,
      "y": 0,
      "z": -1,
      "name": "Rock_Basalt_Brick"
    },
    {
      "x": 3,
      "y": 1,
      "z": -1,
      "name": "Plant_Reeds_Poison"
    },
    {
      "x": 3,
      "y": 2,
      "z": -1,
      "name": "Empty"
    },
    {
      "x": 3,
      "y": 3,
      "z": -1,
      "name": "Rock_Basalt_Brick"
    },
    {
      "x": 3,
      "y": 0,
      "z": 0,
      "name": "Rock_Basalt_Brick"
    },
    {
      "x": 3,
      "y": 1,
      "z": 0,
      "name": "Plant_Seaweed_Grass_Bulbs"
    },
    {
      "x": 3,
      "y": 2,
      "z": 0,
      "name": "Plant_Seaweed_Grass_Bulbs",
      "filler": 1024
    },
    {
      "x": 3,
      "y": 3,
      "z": 0,
      "name": "Rock_Basalt_Brick"
    },
    {
      "x": 3,
      "y": 0,
      "z": 1,
      "name": "Rock_Basalt_Brick"
    },
    {
      "x": 3,
      "y": 1,
      "z": 1,
      "name": "Plant_Moss_Rug_Green"
    },
    {
      "x": 3,
      "y": 2,
      "z": 1,
      "name": "Empty"
    },
    {
      "x": 3,
      "y": 3,
      "z": 1,
      "name": "Rock_Basalt_Brick"
    },
    {
      "x": 3,
      "y": 0,
      "z": 2,
      "name": "Rock_Basalt_Brick"
    },
    {
      "x": 3,
      "y": 1,
      "z": 2,
      "name": "Plant_Moss_Green"
    },
    {
      "x": 3,
      "y": 2,
      "z": 2,
      "name": "Empty"
    },
    {
      "x": 3,
      "y": 3,
      "z": 2,
      "name": "Rock_Basalt_Brick"
    },
    {
      "x": 3,
      "y": 0,
      "z": 3,
      "name": "Rock_Basalt_Brick"
    },
    {
      "x": 3,
      "y": 1,
      "z": 3,
      "name": "Plant_Moss_Rug_Green"
    },
    {
      "x": 3,
      "y": 2,
      "z": 3,
      "name": "Empty"
    },
    {
      "x": 3,
      "y": 3,
      "z": 3,
      "name": "Rock_Basalt_Brick"
    },
    {
      "x": 3,
      "y": 0,
      "z": 4,
      "name": "Rock_Basalt_Brick"
    },
    {
      "x": 3,
      "y": 1,
      "z": 4,
      "name": "Plant_Moss_Rug_Green"
    },
    {
      "x": 3,
      "y": 2,
      "z": 4,
      "name": "Empty"
    },
    {
      "x": 3,
      "y": 3,
      "z": 4,
      "name": "Rock_Basalt_Brick"
    },
    {
      "x": 3,
      "y": 0,
      "z": 5,
      "name": "Rock_Basalt_Brick"
    },
    {
      "x": 3,
      "y": 1,
      "z": 5,
      "name": "Plant_Seaweed_Grass_Bulbs"
    },
    {
      "x": 3,
      "y": 2,
      "z": 5,
      "name": "Plant_Seaweed_Grass_Bulbs",
      "filler": 1024
    },
    {
      "x": 3,
      "y": 3,
      "z": 5,
      "name": "Rock_Basalt_Brick"
    },
    {
      "x": 3,
      "y": 0,
      "z": 6,
      "name": "Rock_Basalt_Brick"
    },
    {
      "x": 3,
      "y": 1,
      "z": 6,
      "name": "Plant_Seaweed_Grass_Bulbs"
    },
    {
      "x": 3,
      "y": 2,
      "z": 6,
      "name": "Plant_Seaweed_Grass_Bulbs",
      "filler": 1024
    },
    {
      "x": 3,
      "y": 3,
      "z": 6,
      "name": "Rock_Basalt_Brick"
    },
    {
      "x": 3,
      "y": 0,
      "z": 7,
      "name": "Rock_Basalt_Brick"
    },
    {
      "x": 3,
      "y": 1,
      "z": 7,
      "name": "Plant_Seaweed_Grass_Bulbs"
    },
    {
      "x": 3,
      "y": 2,
      "z": 7,
      "name": "Plant_Seaweed_Grass_Bulbs",
      "filler": 1024
    },
    {
      "x": 3,
      "y": 3,
      "z": 7,
      "name": "Rock_Basalt_Brick"
    },
    {
      "x": 4,
      "y": 0,
      "z": -4,
      "name": "Rock_Basalt_Brick"
    },
    {
      "x": 4,
      "y": 1,
      "z": -4,
      "name": "Empty"
    },
    {
      "x": 4,
      "y": 2,
      "z": -4,
      "name": "Empty"
    },
    {
      "x": 4,
      "y": 3,
      "z": -4,
      "name": "Rock_Basalt_Brick"
    },
    {
      "x": 4,
      "y": 0,
      "z": -3,
      "name": "Rock_Basalt_Brick"
    },
    {
      "x": 4,
      "y": 1,
      "z": -3,
      "name": "Empty"
    },
    {
      "x": 4,
      "y": 2,
      "z": -3,
      "name": "Empty"
    },
    {
      "x": 4,
      "y": 3,
      "z": -3,
      "name": "Rock_Basalt_Brick"
    },
    {
      "x": 4,
      "y": 0,
      "z": -2,
      "name": "Rock_Basalt_Brick"
    },
    {
      "x": 4,
      "y": 1,
      "z": -2,
      "name": "Empty"
    },
    {
      "x": 4,
      "y": 2,
      "z": -2,
      "name": "Empty"
    },
    {
      "x": 4,
      "y": 3,
      "z": -2,
      "name": "Rock_Basalt_Brick"
    },
    {
      "x": 4,
      "y": 0,
      "z": -1,
      "name": "Rock_Basalt_Brick"
    },
    {
      "x": 4,
      "y": 1,
      "z": -1,
      "name": "Plant_Seaweed_Grass_Bulbs"
    },
    {
      "x": 4,
      "y": 2,
      "z": -1,
      "name": "Plant_Seaweed_Grass_Bulbs",
      "filler": 1024
    },
    {
      "x": 4,
      "y": 3,
      "z": -1,
      "name": "Rock_Basalt_Brick"
    },
    {
      "x": 4,
      "y": 0,
      "z": 0,
      "name": "Rock_Basalt_Brick"
    },
    {
      "x": 4,
      "y": 1,
      "z": 0,
      "name": "Plant_Moss_Rug_Green"
    },
    {
      "x": 4,
      "y": 2,
      "z": 0,
      "name": "Empty"
    },
    {
      "x": 4,
      "y": 3,
      "z": 0,
      "name": "Rock_Basalt_Brick"
    },
    {
      "x": 4,
      "y": 0,
      "z": 1,
      "name": "Rock_Basalt_Brick"
    },
    {
      "x": 4,
      "y": 1,
      "z": 1,
      "name": "Plant_Moss_Rug_Green"
    },
    {
      "x": 4,
      "y": 2,
      "z": 1,
      "name": "Empty"
    },
    {
      "x": 4,
      "y": 3,
      "z": 1,
      "name": "Rock_Basalt_Brick"
    },
    {
      "x": 4,
      "y": 0,
      "z": 2,
      "name": "Rock_Basalt_Brick"
    },
    {
      "x": 4,
      "y": 1,
      "z": 2,
      "name": "Plant_Moss_Green"
    },
    {
      "x": 4,
      "y": 2,
      "z": 2,
      "name": "Empty"
    },
    {
      "x": 4,
      "y": 3,
      "z": 2,
      "name": "Rock_Basalt_Brick"
    },
    {
      "x": 4,
      "y": 0,
      "z": 3,
      "name": "Rock_Basalt_Brick"
    },
    {
      "x": 4,
      "y": 1,
      "z": 3,
      "name": "Empty"
    },
    {
      "x": 4,
      "y": 2,
      "z": 3,
      "name": "Empty"
    },
    {
      "x": 4,
      "y": 3,
      "z": 3,
      "name": "Rock_Basalt_Brick"
    },
    {
      "x": 4,
      "y": 0,
      "z": 4,
      "name": "Rock_Basalt_Brick"
    },
    {
      "x": 4,
      "y": 1,
      "z": 4,
      "name": "Plant_Moss_Rug_Green"
    },
    {
      "x": 4,
      "y": 2,
      "z": 4,
      "name": "Empty"
    },
    {
      "x": 4,
      "y": 3,
      "z": 4,
      "name": "Rock_Basalt_Brick"
    },
    {
      "x": 4,
      "y": 0,
      "z": 5,
      "name": "Rock_Basalt_Brick"
    },
    {
      "x": 4,
      "y": 1,
      "z": 5,
      "name": "Plant_Reeds_Poison"
    },
    {
      "x": 4,
      "y": 2,
      "z": 5,
      "name": "Empty"
    },
    {
      "x": 4,
      "y": 3,
      "z": 5,
      "name": "Rock_Basalt_Brick"
    },
    {
      "x": 4,
      "y": 0,
      "z": 6,
      "name": "Rock_Basalt_Brick"
    },
    {
      "x": 4,
      "y": 1,
      "z": 6,
      "name": "Plant_Reeds_Poison"
    },
    {
      "x": 4,
      "y": 2,
      "z": 6,
      "name": "Empty"
    },
    {
      "x": 4,
      "y": 3,
      "z": 6,
      "name": "Rock_Basalt_Brick"
    },
    {
      "x": 4,
      "y": 0,
      "z": 7,
      "name": "Rock_Basalt_Brick"
    },
    {
      "x": 4,
      "y": 1,
      "z": 7,
      "name": "Empty"
    },
    {
      "x": 4,
      "y": 2,
      "z": 7,
      "name": "Empty"
    },
    {
      "x": 4,
      "y": 3,
      "z": 7,
      "name": "Rock_Basalt_Brick"
    },
    {
      "x": 5,
      "y": 0,
      "z": -4,
      "name": "Rock_Basalt_Brick"
    },
    {
      "x": 5,
      "y": 1,
      "z": -4,
      "name": "Rock_Basalt_Brick"
    },
    {
      "x": 5,
      "y": 2,
      "z": -4,
      "name": "Rock_Basalt_Brick"
    },
    {
      "x": 5,
      "y": 3,
      "z": -4,
      "name": "Rock_Basalt_Brick"
    },
    {
      "x": 5,
      "y": 0,
      "z": -3,
      "name": "Rock_Basalt_Brick"
    },
    {
      "x": 5,
      "y": 1,
      "z": -3,
      "name": "Rock_Basalt_Brick"
    },
    {
      "x": 5,
      "y": 2,
      "z": -3,
      "name": "Rock_Basalt_Brick"
    },
    {
      "x": 5,
      "y": 3,
      "z": -3,
      "name": "Rock_Basalt_Brick"
    },
    {
      "x": 5,
      "y": 0,
      "z": -2,
      "name": "Rock_Basalt_Brick"
    },
    {
      "x": 5,
      "y": 1,
      "z": -2,
      "name": "Rock_Basalt_Brick"
    },
    {
      "x": 5,
      "y": 2,
      "z": -2,
      "name": "Rock_Basalt_Brick"
    },
    {
      "x": 5,
      "y": 3,
      "z": -2,
      "name": "Rock_Basalt_Brick"
    },
    {
      "x": 5,
      "y": 0,
      "z": -1,
      "name": "Rock_Basalt_Brick"
    },
    {
      "x": 5,
      "y": 1,
      "z": -1,
      "name": "Rock_Basalt_Brick"
    },
    {
      "x": 5,
      "y": 2,
      "z": -1,
      "name": "Rock_Basalt_Brick"
    },
    {
      "x": 5,
      "y": 3,
      "z": -1,
      "name": "Rock_Basalt_Brick"
    },
    {
      "x": 5,
      "y": 0,
      "z": 0,
      "name": "Rock_Basalt_Brick"
    },
    {
      "x": 5,
      "y": 1,
      "z": 0,
      "name": "Rock_Basalt_Brick"
    },
    {
      "x": 5,
      "y": 2,
      "z": 0,
      "name": "Rock_Basalt_Brick"
    },
    {
      "x": 5,
      "y": 3,
      "z": 0,
      "name": "Rock_Basalt_Brick"
    },
    {
      "x": 5,
      "y": 0,
      "z": 1,
      "name": "Rock_Basalt_Brick"
    },
    {
      "x": 5,
      "y": 1,
      "z": 1,
      "name": "Rock_Basalt_Brick"
    },
    {
      "x": 5,
      "y": 2,
      "z": 1,
      "name": "Rock_Basalt_Brick"
    },
    {
      "x": 5,
      "y": 3,
      "z": 1,
      "name": "Rock_Basalt_Brick"
    },
    {
      "x": 5,
      "y": 0,
      "z": 2,
      "name": "Rock_Basalt_Brick"
    },
    {
      "x": 5,
      "y": 1,
      "z": 2,
      "name": "Rock_Basalt_Brick"
    },
    {
      "x": 5,
      "y": 2,
      "z": 2,
      "name": "Rock_Basalt_Brick"
    },
    {
      "x": 5,
      "y": 3,
      "z": 2,
      "name": "Rock_Basalt_Brick"
    },
    {
      "x": 5,
      "y": 0,
      "z": 3,
      "name": "Rock_Basalt_Brick"
    },
    {
      "x": 5,
      "y": 1,
      "z": 3,
      "name": "Rock_Basalt_Brick"
    },
    {
      "x": 5,
      "y": 2,
      "z": 3,
      "name": "Rock_Basalt_Brick"
    },
    {
      "x": 5,
      "y": 3,
      "z": 3,
      "name": "Rock_Basalt_Brick"
    },
    {
      "x": 5,
      "y": 0,
      "z": 4,
      "name": "Rock_Basalt_Brick"
    },
    {
      "x": 5,
      "y": 1,
      "z": 4,
      "name": "Rock_Basalt_Brick"
    },
    {
      "x": 5,
      "y": 2,
      "z": 4,
      "name": "Rock_Basalt_Brick"
    },
    {
      "x": 5,
      "y": 3,
      "z": 4,
      "name": "Rock_Basalt_Brick"
    },
    {
      "x": 5,
      "y": 0,
      "z": 5,
      "name": "Rock_Basalt_Brick"
    },
    {
      "x": 5,
      "y": 1,
      "z": 5,
      "name": "Rock_Basalt_Brick"
    },
    {
      "x": 5,
      "y": 2,
      "z": 5,
      "name": "Rock_Basalt_Brick"
    },
    {
      "x": 5,
      "y": 3,
      "z": 5,
      "name": "Rock_Basalt_Brick"
    },
    {
      "x": 5,
      "y": 0,
      "z": 6,
      "name": "Rock_Basalt_Brick"
    },
    {
      "x": 5,
      "y": 1,
      "z": 6,
      "name": "Rock_Basalt_Brick"
    },
    {
      "x": 5,
      "y": 2,
      "z": 6,
      "name": "Rock_Basalt_Brick"
    },
    {
      "x": 5,
      "y": 3,
      "z": 6,
      "name": "Rock_Basalt_Brick"
    },
    {
      "x": 5,
      "y": 0,
      "z": 7,
      "name": "Rock_Basalt_Brick"
    },
    {
      "x": 5,
      "y": 1,
      "z": 7,
      "name": "Rock_Basalt_Brick"
    },
    {
      "x": 5,
      "y": 2,
      "z": 7,
      "name": "Rock_Basalt_Brick"
    },
    {
      "x": 5,
      "y": 3,
      "z": 7,
      "name": "Rock_Basalt_Brick"
    }
  ]
}
