{
  "version": 8,
  "blockIdVersion": 8,
  "anchorX": 1,
  "anchorY": 15,
  "anchorZ": -2,
  "blocks": [
    {
      "x": -10,
      "y": 7,
      "z": -1,
      "name": "Rock_Basalt"
    },
    {
      "x": -10,
      "y": 8,
      "z": -1,
      "name": "Rock_Basalt"
    },
    {
      "x": -10,
      "y": 9,
      "z": -1,
      "name": "Rock_Basalt"
    },
    {
      "x": -10,
      "y": 10,
      "z": -1,
      "name": "Rock_Basalt"
    },
    {
      "x": -10,
      "y": 11,
      "z": -1,
      "name": "Rock_Stone"
    },
    {
      "x": -10,
      "y": 12,
      "z": -1,
      "name": "Rock_Stone_Mossy"
    },
    {
      "x": -10,
      "y": 7,
      "z": 0,
      "name": "Rock_Basalt"
    },
    {
      "x": -10,
      "y": 8,
      "z": 0,
      "name": "Rock_Basalt"
    },
    {
      "x": -10,
      "y": 9,
      "z": 0,
      "name": "Rock_Basalt"
    },
    {
      "x": -10,
      "y": 10,
      "z": 0,
      "name": "Rock_Basalt"
    },
    {
      "x": -10,
      "y": 11,
      "z": 0,
      "name": "Rock_Stone"
    },
    {
      "x": -10,
      "y": 12,
      "z": 0,
      "name": "Rock_Stone_Mossy"
    },
    {
      "x": -10,
      "y": 7,
      "z": 1,
      "name": "Rock_Basalt"
    },
    {
      "x": -10,
      "y": 8,
      "z": 1,
      "name": "Rock_Basalt"
    },
    {
      "x": -10,
      "y": 9,
      "z": 1,
      "name": "Rock_Basalt"
    },
    {
      "x": -10,
      "y": 10,
      "z": 1,
      "name": "Rock_Basalt"
    },
    {
      "x": -10,
      "y": 11,
      "z": 1,
      "name": "Rock_Basalt"
    },
    {
      "x": -10,
      "y": 12,
      "z": 1,
      "name": "Rock_Stone"
    },
    {
      "x": -10,
      "y": 13,
      "z": 1,
      "name": "Plant_Crop_Mushroom_Block_Green"
    },
    {
      "x": -10,
      "y": 7,
      "z": 2,
      "name": "Rock_Basalt"
    },
    {
      "x": -10,
      "y": 8,
      "z": 2,
      "name": "Rock_Basalt"
    },
    {
      "x": -10,
      "y": 9,
      "z": 2,
      "name": "Rock_Basalt"
    },
    {
      "x": -10,
      "y": 10,
      "z": 2,
      "name": "Rock_Basalt"
    },
    {
      "x": -10,
      "y": 11,
      "z": 2,
      "name": "Rock_Basalt"
    },
    {
      "x": -10,
      "y": 12,
      "z": 2,
      "name": "Rock_Stone"
    },
    {
      "x": -10,
      "y": 13,
      "z": 2,
      "name": "Plant_Crop_Mushroom_Block_Green"
    },
    {
      "x": -10,
      "y": 8,
      "z": 3,
      "name": "Rock_Basalt"
    },
    {
      "x": -10,
      "y": 9,
      "z": 3,
      "name": "Rock_Basalt"
    },
    {
      "x": -10,
      "y": 10,
      "z": 3,
      "name": "Rock_Basalt"
    },
    {
      "x": -10,
      "y": 11,
      "z": 3,
      "name": "Rock_Basalt"
    },
    {
      "x": -10,
      "y": 12,
      "z": 3,
      "name": "Rock_Basalt"
    },
    {
      "x": -9,
      "y": 6,
      "z": -3,
      "name": "Rock_Basalt"
    },
    {
      "x": -9,
      "y": 7,
      "z": -3,
      "name": "Rock_Basalt"
    },
    {
      "x": -9,
      "y": 8,
      "z": -3,
      "name": "Rock_Basalt"
    },
    {
      "x": -9,
      "y": 9,
      "z": -3,
      "name": "Rock_Basalt"
    },
    {
      "x": -9,
      "y": 10,
      "z": -3,
      "name": "Rock_Basalt"
    },
    {
      "x": -9,
      "y": 11,
      "z": -3,
      "name": "Rock_Stone"
    },
    {
      "x": -9,
      "y": 12,
      "z": -3,
      "name": "Rock_Stone_Mossy"
    },
    {
      "x": -9,
      "y": 6,
      "z": -2,
      "name": "Rock_Basalt"
    },
    {
      "x": -9,
      "y": 7,
      "z": -2,
      "name": "Rock_Basalt"
    },
    {
      "x": -9,
      "y": 8,
      "z": -2,
      "name": "Rock_Basalt"
    },
    {
      "x": -9,
      "y": 9,
      "z": -2,
      "name": "Rock_Basalt"
    },
    {
      "x": -9,
      "y": 10,
      "z": -2,
      "name": "Rock_Basalt"
    },
    {
      "x": -9,
      "y": 11,
      "z": -2,
      "name": "Rock_Stone"
    },
    {
      "x": -9,
      "y": 12,
      "z": -2,
      "name": "Rock_Stone_Mossy"
    },
    {
      "x": -9,
      "y": 13,
      "z": -2,
      "name": "Rock_Stone"
    },
    {
      "x": -9,
      "y": 14,
      "z": -2,
      "name": "Rock_Stone"
    },
    {
      "x": -9,
      "y": 15,
      "z": -2,
      "name": "Rock_Stone"
    },
    {
      "x": -9,
      "y": 16,
      "z": -2,
      "name": "Plant_Moss_Rug_Green_Dark"
    },
    {
      "x": -9,
      "y": 6,
      "z": -1,
      "name": "Rock_Basalt"
    },
    {
      "x": -9,
      "y": 7,
      "z": -1,
      "name": "Rock_Basalt"
    },
    {
      "x": -9,
      "y": 8,
      "z": -1,
      "name": "Rock_Basalt"
    },
    {
      "x": -9,
      "y": 9,
      "z": -1,
      "name": "Rock_Basalt"
    },
    {
      "x": -9,
      "y": 10,
      "z": -1,
      "name": "Rock_Basalt"
    },
    {
      "x": -9,
      "y": 11,
      "z": -1,
      "name": "Rock_Stone"
    },
    {
      "x": -9,
      "y": 12,
      "z": -1,
      "name": "Rock_Stone"
    },
    {
      "x": -9,
      "y": 13,
      "z": -1,
      "name": "Rock_Stone"
    },
    {
      "x": -9,
      "y": 14,
      "z": -1,
      "name": "Rock_Stone"
    },
    {
      "x": -9,
      "y": 15,
      "z": -1,
      "name": "Plant_Moss_Wall_Green_Dark"
    },
    {
      "x": -9,
      "y": 6,
      "z": 0,
      "name": "Rock_Basalt"
    },
    {
      "x": -9,
      "y": 7,
      "z": 0,
      "name": "Rock_Basalt"
    },
    {
      "x": -9,
      "y": 8,
      "z": 0,
      "name": "Rock_Basalt"
    },
    {
      "x": -9,
      "y": 9,
      "z": 0,
      "name": "Rock_Basalt"
    },
    {
      "x": -9,
      "y": 10,
      "z": 0,
      "name": "Rock_Basalt"
    },
    {
      "x": -9,
      "y": 11,
      "z": 0,
      "name": "Rock_Stone"
    },
    {
      "x": -9,
      "y": 12,
      "z": 0,
      "name": "Rock_Stone"
    },
    {
      "x": -9,
      "y": 13,
      "z": 0,
      "name": "Plant_Crop_Mushroom_Block_Green"
    },
    {
      "x": -9,
      "y": 14,
      "z": 0,
      "name": "Plant_Moss_Rug_Green_Dark"
    },
    {
      "x": -9,
      "y": 6,
      "z": 1,
      "name": "Rock_Basalt"
    },
    {
      "x": -9,
      "y": 7,
      "z": 1,
      "name": "Rock_Basalt"
    },
    {
      "x": -9,
      "y": 8,
      "z": 1,
      "name": "Rock_Basalt"
    },
    {
      "x": -9,
      "y": 9,
      "z": 1,
      "name": "Rock_Basalt"
    },
    {
      "x": -9,
      "y": 10,
      "z": 1,
      "name": "Rock_Basalt"
    },
    {
      "x": -9,
      "y": 11,
      "z": 1,
      "name": "Rock_Basalt"
    },
    {
      "x": -9,
      "y": 12,
      "z": 1,
      "name": "Rock_Stone"
    },
    {
      "x": -9,
      "y": 13,
      "z": 1,
      "name": "Plant_Crop_Mushroom_Block_Green"
    },
    {
      "x": -9,
      "y": 5,
      "z": 2,
      "name": "Rock_Basalt"
    },
    {
      "x": -9,
      "y": 6,
      "z": 2,
      "name": "Rock_Basalt"
    },
    {
      "x": -9,
      "y": 7,
      "z": 2,
      "name": "Rock_Basalt"
    },
    {
      "x": -9,
      "y": 8,
      "z": 2,
      "name": "Rock_Basalt"
    },
    {
      "x": -9,
      "y": 9,
      "z": 2,
      "name": "Rock_Basalt"
    },
    {
      "x": -9,
      "y": 10,
      "z": 2,
      "name": "Rock_Basalt"
    },
    {
      "x": -9,
      "y": 11,
      "z": 2,
      "name": "Rock_Basalt"
    },
    {
      "x": -9,
      "y": 12,
      "z": 2,
      "name": "Rock_Stone"
    },
    {
      "x": -9,
      "y": 13,
      "z": 2,
      "name": "Plant_Crop_Mushroom_Block_Green"
    },
    {
      "x": -9,
      "y": 6,
      "z": 3,
      "name": "Rock_Basalt"
    },
    {
      "x": -9,
      "y": 8,
      "z": 3,
      "name": "Rock_Basalt"
    },
    {
      "x": -9,
      "y": 9,
      "z": 3,
      "name": "Rock_Basalt"
    },
    {
      "x": -9,
      "y": 10,
      "z": 3,
      "name": "Rock_Basalt"
    },
    {
      "x": -9,
      "y": 11,
      "z": 3,
      "name": "Rock_Basalt"
    },
    {
      "x": -9,
      "y": 12,
      "z": 3,
      "name": "Rock_Basalt"
    },
    {
      "x": -9,
      "y": 13,
      "z": 3,
      "name": "Plant_Crop_Mushroom_Block_Green"
    },
    {
      "x": -9,
      "y": 9,
      "z": 4,
      "name": "Rock_Basalt"
    },
    {
      "x": -9,
      "y": 10,
      "z": 4,
      "name": "Rock_Basalt"
    },
    {
      "x": -9,
      "y": 11,
      "z": 4,
      "name": "Rock_Basalt"
    },
    {
      "x": -9,
      "y": 12,
      "z": 4,
      "name": "Rock_Basalt"
    },
    {
      "x": -8,
      "y": 7,
      "z": -4,
      "name": "Rock_Basalt"
    },
    {
      "x": -8,
      "y": 8,
      "z": -4,
      "name": "Rock_Basalt"
    },
    {
      "x": -8,
      "y": 9,
      "z": -4,
      "name": "Rock_Basalt"
    },
    {
      "x": -8,
      "y": 10,
      "z": -4,
      "name": "Rock_Basalt"
    },
    {
      "x": -8,
      "y": 11,
      "z": -4,
      "name": "Rock_Stone"
    },
    {
      "x": -8,
      "y": 12,
      "z": -4,
      "name": "Rock_Stone"
    },
    {
      "x": -8,
      "y": 13,
      "z": -4,
      "name": "Rock_Stone"
    },
    {
      "x": -8,
      "y": 14,
      "z": -4,
      "name": "Rock_Stone"
    },
    {
      "x": -8,
      "y": 15,
      "z": -4,
      "name": "Rock_Stone"
    },
    {
      "x": -8,
      "y": 16,
      "z": -4,
      "name": "Rock_Stone"
    },
    {
      "x": -8,
      "y": 2,
      "z": -3,
      "name": "Rock_Basalt"
    },
    {
      "x": -8,
      "y": 3,
      "z": -3,
      "name": "Rock_Basalt"
    },
    {
      "x": -8,
      "y": 4,
      "z": -3,
      "name": "Rock_Basalt"
    },
    {
      "x": -8,
      "y": 5,
      "z": -3,
      "name": "Rock_Basalt"
    },
    {
      "x": -8,
      "y": 6,
      "z": -3,
      "name": "Rock_Basalt"
    },
    {
      "x": -8,
      "y": 7,
      "z": -3,
      "name": "Rock_Basalt"
    },
    {
      "x": -8,
      "y": 8,
      "z": -3,
      "name": "Rock_Basalt"
    },
    {
      "x": -8,
      "y": 9,
      "z": -3,
      "name": "Rock_Basalt"
    },
    {
      "x": -8,
      "y": 10,
      "z": -3,
      "name": "Rock_Basalt"
    },
    {
      "x": -8,
      "y": 11,
      "z": -3,
      "name": "Rock_Stone"
    },
    {
      "x": -8,
      "y": 12,
      "z": -3,
      "name": "Rock_Stone"
    },
    {
      "x": -8,
      "y": 13,
      "z": -3,
      "name": "Rock_Stone"
    },
    {
      "x": -8,
      "y": 14,
      "z": -3,
      "name": "Rock_Stone"
    },
    {
      "x": -8,
      "y": 15,
      "z": -3,
      "name": "Rock_Stone"
    },
    {
      "x": -8,
      "y": 16,
      "z": -3,
      "name": "Empty"
    },
    {
      "x": -8,
      "y": 17,
      "z": -3,
      "name": "Plant_Moss_Wall_Green_Dark",
      "rotation": 3
    },
    {
      "x": -8,
      "y": 2,
      "z": -2,
      "name": "Rock_Basalt"
    },
    {
      "x": -8,
      "y": 3,
      "z": -2,
      "name": "Rock_Basalt"
    },
    {
      "x": -8,
      "y": 4,
      "z": -2,
      "name": "Rock_Basalt"
    },
    {
      "x": -8,
      "y": 5,
      "z": -2,
      "name": "Rock_Basalt"
    },
    {
      "x": -8,
      "y": 6,
      "z": -2,
      "name": "Rock_Basalt"
    },
    {
      "x": -8,
      "y": 7,
      "z": -2,
      "name": "Rock_Basalt"
    },
    {
      "x": -8,
      "y": 8,
      "z": -2,
      "name": "Rock_Basalt"
    },
    {
      "x": -8,
      "y": 9,
      "z": -2,
      "name": "Rock_Basalt"
    },
    {
      "x": -8,
      "y": 10,
      "z": -2,
      "name": "Rock_Basalt"
    },
    {
      "x": -8,
      "y": 11,
      "z": -2,
      "name": "Rock_Stone"
    },
    {
      "x": -8,
      "y": 12,
      "z": -2,
      "name": "Soil_Dirt_Burnt"
    },
    {
      "x": -8,
      "y": 13,
      "z": -2,
      "name": "Plant_Crop_Mushroom_Block_Green"
    },
    {
      "x": -8,
      "y": 14,
      "z": -2,
      "name": "Empty"
    },
    {
      "x": -8,
      "y": 15,
      "z": -2,
      "name": "Plant_Moss_Wall_Green_Dark",
      "rotation": 1
    },
    {
      "x": -8,
      "y": 16,
      "z": -2,
      "name": "Empty"
    },
    {
      "x": -8,
      "y": 17,
      "z": -2,
      "name": "Empty"
    },
    {
      "x": -8,
      "y": 2,
      "z": -1,
      "name": "Rock_Basalt"
    },
    {
      "x": -8,
      "y": 3,
      "z": -1,
      "name": "Rock_Basalt"
    },
    {
      "x": -8,
      "y": 4,
      "z": -1,
      "name": "Rock_Basalt"
    },
    {
      "x": -8,
      "y": 5,
      "z": -1,
      "name": "Rock_Basalt"
    },
    {
      "x": -8,
      "y": 6,
      "z": -1,
      "name": "Rock_Basalt"
    },
    {
      "x": -8,
      "y": 7,
      "z": -1,
      "name": "Rock_Basalt"
    },
    {
      "x": -8,
      "y": 8,
      "z": -1,
      "name": "Rock_Basalt"
    },
    {
      "x": -8,
      "y": 9,
      "z": -1,
      "name": "Rock_Basalt"
    },
    {
      "x": -8,
      "y": 10,
      "z": -1,
      "name": "Rock_Basalt"
    },
    {
      "x": -8,
      "y": 11,
      "z": -1,
      "name": "Soil_Dirt_Burnt"
    },
    {
      "x": -8,
      "y": 12,
      "z": -1,
      "name": "Soil_Dirt_Burnt"
    },
    {
      "x": -8,
      "y": 14,
      "z": -1,
      "name": "Empty"
    },
    {
      "x": -8,
      "y": 15,
      "z": -1,
      "name": "Empty"
    },
    {
      "x": -8,
      "y": 16,
      "z": -1,
      "name": "Empty"
    },
    {
      "x": -8,
      "y": 17,
      "z": -1,
      "name": "Empty"
    },
    {
      "x": -8,
      "y": 3,
      "z": 0,
      "name": "Rock_Basalt"
    },
    {
      "x": -8,
      "y": 4,
      "z": 0,
      "name": "Rock_Basalt"
    },
    {
      "x": -8,
      "y": 5,
      "z": 0,
      "name": "Rock_Basalt"
    },
    {
      "x": -8,
      "y": 6,
      "z": 0,
      "name": "Rock_Basalt"
    },
    {
      "x": -8,
      "y": 7,
      "z": 0,
      "name": "Rock_Basalt"
    },
    {
      "x": -8,
      "y": 8,
      "z": 0,
      "name": "Rock_Basalt"
    },
    {
      "x": -8,
      "y": 9,
      "z": 0,
      "name": "Rock_Basalt"
    },
    {
      "x": -8,
      "y": 10,
      "z": 0,
      "name": "Rock_Basalt"
    },
    {
      "x": -8,
      "y": 11,
      "z": 0,
      "name": "Soil_Dirt_Burnt"
    },
    {
      "x": -8,
      "y": 12,
      "z": 0,
      "name": "Soil_Dirt_Burnt"
    },
    {
      "x": -8,
      "y": 14,
      "z": 0,
      "name": "Empty"
    },
    {
      "x": -8,
      "y": 15,
      "z": 0,
      "name": "Empty"
    },
    {
      "x": -8,
      "y": 16,
      "z": 0,
      "name": "Empty"
    },
    {
      "x": -8,
      "y": 17,
      "z": 0,
      "name": "Empty"
    },
    {
      "x": -8,
      "y": 3,
      "z": 1,
      "name": "Rock_Basalt"
    },
    {
      "x": -8,
      "y": 4,
      "z": 1,
      "name": "Rock_Basalt"
    },
    {
      "x": -8,
      "y": 5,
      "z": 1,
      "name": "Rock_Basalt"
    },
    {
      "x": -8,
      "y": 6,
      "z": 1,
      "name": "Rock_Basalt"
    },
    {
      "x": -8,
      "y": 7,
      "z": 1,
      "name": "Rock_Basalt"
    },
    {
      "x": -8,
      "y": 8,
      "z": 1,
      "name": "Rock_Basalt"
    },
    {
      "x": -8,
      "y": 9,
      "z": 1,
      "name": "Rock_Basalt"
    },
    {
      "x": -8,
      "y": 10,
      "z": 1,
      "name": "Rock_Basalt"
    },
    {
      "x": -8,
      "y": 11,
      "z": 1,
      "name": "Soil_Dirt_Burnt"
    },
    {
      "x": -8,
      "y": 12,
      "z": 1,
      "name": "Soil_Dirt_Burnt"
    },
    {
      "x": -8,
      "y": 14,
      "z": 1,
      "name": "Empty"
    },
    {
      "x": -8,
      "y": 15,
      "z": 1,
      "name": "Empty"
    },
    {
      "x": -8,
      "y": 16,
      "z": 1,
      "name": "Empty"
    },
    {
      "x": -8,
      "y": 4,
      "z": 2,
      "name": "Rock_Basalt"
    },
    {
      "x": -8,
      "y": 5,
      "z": 2,
      "name": "Rock_Basalt"
    },
    {
      "x": -8,
      "y": 6,
      "z": 2,
      "name": "Rock_Basalt"
    },
    {
      "x": -8,
      "y": 7,
      "z": 2,
      "name": "Rock_Basalt"
    },
    {
      "x": -8,
      "y": 8,
      "z": 2,
      "name": "Rock_Basalt"
    },
    {
      "x": -8,
      "y": 9,
      "z": 2,
      "name": "Rock_Basalt"
    },
    {
      "x": -8,
      "y": 10,
      "z": 2,
      "name": "Rock_Basalt"
    },
    {
      "x": -8,
      "y": 11,
      "z": 2,
      "name": "Rock_Basalt"
    },
    {
      "x": -8,
      "y": 12,
      "z": 2,
      "name": "Soil_Dirt_Burnt"
    },
    {
      "x": -8,
      "y": 13,
      "z": 2,
      "name": "Plant_Crop_Mushroom_Block_Green"
    },
    {
      "x": -8,
      "y": 14,
      "z": 2,
      "name": "Plant_Moss_Rug_Green_Dark"
    },
    {
      "x": -8,
      "y": 5,
      "z": 3,
      "name": "Rock_Basalt"
    },
    {
      "x": -8,
      "y": 6,
      "z": 3,
      "name": "Rock_Basalt"
    },
    {
      "x": -8,
      "y": 7,
      "z": 3,
      "name": "Rock_Basalt"
    },
    {
      "x": -8,
      "y": 8,
      "z": 3,
      "name": "Rock_Basalt"
    },
    {
      "x": -8,
      "y": 9,
      "z": 3,
      "name": "Rock_Basalt"
    },
    {
      "x": -8,
      "y": 10,
      "z": 3,
      "name": "Rock_Basalt"
    },
    {
      "x": -8,
      "y": 11,
      "z": 3,
      "name": "Rock_Basalt"
    },
    {
      "x": -8,
      "y": 12,
      "z": 3,
      "name": "Rock_Basalt"
    },
    {
      "x": -8,
      "y": 13,
      "z": 3,
      "name": "Plant_Crop_Mushroom_Block_Green"
    },
    {
      "x": -8,
      "y": 14,
      "z": 3,
      "name": "Plant_Moss_Rug_Green_Dark"
    },
    {
      "x": -8,
      "y": 7,
      "z": 4,
      "name": "Rock_Basalt"
    },
    {
      "x": -8,
      "y": 8,
      "z": 4,
      "name": "Rock_Basalt"
    },
    {
      "x": -8,
      "y": 9,
      "z": 4,
      "name": "Rock_Basalt"
    },
    {
      "x": -8,
      "y": 10,
      "z": 4,
      "name": "Rock_Basalt"
    },
    {
      "x": -8,
      "y": 11,
      "z": 4,
      "name": "Rock_Basalt"
    },
    {
      "x": -8,
      "y": 12,
      "z": 4,
      "name": "Rock_Basalt"
    },
    {
      "x": -8,
      "y": 13,
      "z": 4,
      "name": "Plant_Crop_Mushroom_Block_Green"
    },
    {
      "x": -8,
      "y": 12,
      "z": 5,
      "name": "Rock_Basalt"
    },
    {
      "x": -7,
      "y": 7,
      "z": -6,
      "name": "Rock_Basalt"
    },
    {
      "x": -7,
      "y": 8,
      "z": -6,
      "name": "Rock_Basalt"
    },
    {
      "x": -7,
      "y": 9,
      "z": -6,
      "name": "Rock_Basalt"
    },
    {
      "x": -7,
      "y": 10,
      "z": -6,
      "name": "Rock_Basalt"
    },
    {
      "x": -7,
      "y": 11,
      "z": -6,
      "name": "Rock_Basalt"
    },
    {
      "x": -7,
      "y": 12,
      "z": -6,
      "name": "Rock_Stone"
    },
    {
      "x": -7,
      "y": 13,
      "z": -6,
      "name": "Rock_Stone"
    },
    {
      "x": -7,
      "y": 14,
      "z": -6,
      "name": "Rock_Stone"
    },
    {
      "x": -7,
      "y": 15,
      "z": -6,
      "name": "Rock_Stone"
    },
    {
      "x": -7,
      "y": 4,
      "z": -5,
      "name": "Rock_Basalt"
    },
    {
      "x": -7,
      "y": 5,
      "z": -5,
      "name": "Rock_Basalt"
    },
    {
      "x": -7,
      "y": 6,
      "z": -5,
      "name": "Rock_Basalt"
    },
    {
      "x": -7,
      "y": 7,
      "z": -5,
      "name": "Rock_Basalt"
    },
    {
      "x": -7,
      "y": 8,
      "z": -5,
      "name": "Rock_Basalt"
    },
    {
      "x": -7,
      "y": 9,
      "z": -5,
      "name": "Rock_Basalt"
    },
    {
      "x": -7,
      "y": 10,
      "z": -5,
      "name": "Rock_Basalt"
    },
    {
      "x": -7,
      "y": 11,
      "z": -5,
      "name": "Rock_Basalt"
    },
    {
      "x": -7,
      "y": 12,
      "z": -5,
      "name": "Rock_Stone"
    },
    {
      "x": -7,
      "y": 13,
      "z": -5,
      "name": "Rock_Stone"
    },
    {
      "x": -7,
      "y": 14,
      "z": -5,
      "name": "Rock_Stone"
    },
    {
      "x": -7,
      "y": 15,
      "z": -5,
      "name": "Rock_Stone"
    },
    {
      "x": -7,
      "y": 16,
      "z": -5,
      "name": "Rock_Stone"
    },
    {
      "x": -7,
      "y": 17,
      "z": -5,
      "name": "Rock_Stone"
    },
    {
      "x": -7,
      "y": 2,
      "z": -4,
      "name": "Rock_Basalt"
    },
    {
      "x": -7,
      "y": 3,
      "z": -4,
      "name": "Rock_Basalt"
    },
    {
      "x": -7,
      "y": 4,
      "z": -4,
      "name": "Rock_Basalt"
    },
    {
      "x": -7,
      "y": 5,
      "z": -4,
      "name": "Rock_Basalt"
    },
    {
      "x": -7,
      "y": 6,
      "z": -4,
      "name": "Rock_Basalt"
    },
    {
      "x": -7,
      "y": 7,
      "z": -4,
      "name": "Rock_Basalt"
    },
    {
      "x": -7,
      "y": 8,
      "z": -4,
      "name": "Rock_Basalt"
    },
    {
      "x": -7,
      "y": 9,
      "z": -4,
      "name": "Rock_Basalt"
    },
    {
      "x": -7,
      "y": 10,
      "z": -4,
      "name": "Rock_Basalt"
    },
    {
      "x": -7,
      "y": 11,
      "z": -4,
      "name": "Rock_Stone"
    },
    {
      "x": -7,
      "y": 12,
      "z": -4,
      "name": "Rock_Stone"
    },
    {
      "x": -7,
      "y": 13,
      "z": -4,
      "name": "Plant_Crop_Mushroom_Block_Green"
    },
    {
      "x": -7,
      "y": 14,
      "z": -4,
      "name": "Soil_Grass_Deep"
    },
    {
      "x": -7,
      "y": 15,
      "z": -4,
      "name": "Plant_Bush_Jungle"
    },
    {
      "x": -7,
      "y": 16,
      "z": -4,
      "name": "Empty"
    },
    {
      "x": -7,
      "y": 17,
      "z": -4,
      "name": "Rock_Stone"
    },
    {
      "x": -7,
      "y": 18,
      "z": -4,
      "name": "Rock_Stone"
    },
    {
      "x": -7,
      "y": 2,
      "z": -3,
      "name": "Rock_Basalt"
    },
    {
      "x": -7,
      "y": 3,
      "z": -3,
      "name": "Rock_Basalt"
    },
    {
      "x": -7,
      "y": 4,
      "z": -3,
      "name": "Rock_Basalt"
    },
    {
      "x": -7,
      "y": 5,
      "z": -3,
      "name": "Rock_Basalt"
    },
    {
      "x": -7,
      "y": 6,
      "z": -3,
      "name": "Rock_Basalt"
    },
    {
      "x": -7,
      "y": 7,
      "z": -3,
      "name": "Rock_Basalt"
    },
    {
      "x": -7,
      "y": 8,
      "z": -3,
      "name": "Rock_Basalt"
    },
    {
      "x": -7,
      "y": 9,
      "z": -3,
      "name": "Rock_Basalt"
    },
    {
      "x": -7,
      "y": 10,
      "z": -3,
      "name": "Rock_Basalt"
    },
    {
      "x": -7,
      "y": 11,
      "z": -3,
      "name": "Rock_Stone"
    },
    {
      "x": -7,
      "y": 12,
      "z": -3,
      "name": "Soil_Dirt_Burnt"
    },
    {
      "x": -7,
      "y": 14,
      "z": -3,
      "name": "Empty"
    },
    {
      "x": -7,
      "y": 15,
      "z": -3,
      "name": "Empty"
    },
    {
      "x": -7,
      "y": 16,
      "z": -3,
      "name": "Plant_Moss_Cave_Green_Dark",
      "rotation": 8
    },
    {
      "x": -7,
      "y": 17,
      "z": -3,
      "name": "Rock_Stone"
    },
    {
      "x": -7,
      "y": 18,
      "z": -3,
      "name": "Plant_Moss_Rug_Green_Dark"
    },
    {
      "x": -7,
      "y": 2,
      "z": -2,
      "name": "Rock_Basalt"
    },
    {
      "x": -7,
      "y": 3,
      "z": -2,
      "name": "Rock_Basalt"
    },
    {
      "x": -7,
      "y": 4,
      "z": -2,
      "name": "Rock_Basalt"
    },
    {
      "x": -7,
      "y": 5,
      "z": -2,
      "name": "Rock_Basalt"
    },
    {
      "x": -7,
      "y": 6,
      "z": -2,
      "name": "Rock_Basalt"
    },
    {
      "x": -7,
      "y": 7,
      "z": -2,
      "name": "Rock_Basalt"
    },
    {
      "x": -7,
      "y": 8,
      "z": -2,
      "name": "Rock_Basalt"
    },
    {
      "x": -7,
      "y": 9,
      "z": -2,
      "name": "Rock_Basalt"
    },
    {
      "x": -7,
      "y": 10,
      "z": -2,
      "name": "Rock_Basalt"
    },
    {
      "x": -7,
      "y": 11,
      "z": -2,
      "name": "Soil_Dirt_Burnt"
    },
    {
      "x": -7,
      "y": 12,
      "z": -2,
      "name": "Soil_Dirt_Burnt"
    },
    {
      "x": -7,
      "y": 14,
      "z": -2,
      "name": "Empty"
    },
    {
      "x": -7,
      "y": 15,
      "z": -2,
      "name": "Empty"
    },
    {
      "x": -7,
      "y": 16,
      "z": -2,
      "name": "Empty"
    },
    {
      "x": -7,
      "y": 17,
      "z": -2,
      "name": "Plant_Moss_Wall_Green_Dark"
    },
    {
      "x": -7,
      "y": 18,
      "z": -2,
      "name": "Empty"
    },
    {
      "x": -7,
      "y": 2,
      "z": -1,
      "name": "Rock_Basalt"
    },
    {
      "x": -7,
      "y": 3,
      "z": -1,
      "name": "Rock_Basalt"
    },
    {
      "x": -7,
      "y": 4,
      "z": -1,
      "name": "Rock_Basalt"
    },
    {
      "x": -7,
      "y": 5,
      "z": -1,
      "name": "Rock_Basalt"
    },
    {
      "x": -7,
      "y": 6,
      "z": -1,
      "name": "Rock_Basalt"
    },
    {
      "x": -7,
      "y": 7,
      "z": -1,
      "name": "Rock_Basalt"
    },
    {
      "x": -7,
      "y": 8,
      "z": -1,
      "name": "Rock_Basalt"
    },
    {
      "x": -7,
      "y": 9,
      "z": -1,
      "name": "Rock_Basalt"
    },
    {
      "x": -7,
      "y": 10,
      "z": -1,
      "name": "Soil_Dirt_Burnt"
    },
    {
      "x": -7,
      "y": 11,
      "z": -1,
      "name": "Soil_Dirt_Burnt"
    },
    {
      "x": -7,
      "y": 12,
      "z": -1,
      "name": "Soil_Dirt_Burnt"
    },
    {
      "x": -7,
      "y": 14,
      "z": -1,
      "name": "Empty"
    },
    {
      "x": -7,
      "y": 15,
      "z": -1,
      "name": "Empty"
    },
    {
      "x": -7,
      "y": 16,
      "z": -1,
      "name": "Empty"
    },
    {
      "x": -7,
      "y": 17,
      "z": -1,
      "name": "Empty"
    },
    {
      "x": -7,
      "y": 18,
      "z": -1,
      "name": "Empty"
    },
    {
      "x": -7,
      "y": 2,
      "z": 0,
      "name": "Rock_Basalt"
    },
    {
      "x": -7,
      "y": 3,
      "z": 0,
      "name": "Rock_Basalt"
    },
    {
      "x": -7,
      "y": 4,
      "z": 0,
      "name": "Rock_Basalt"
    },
    {
      "x": -7,
      "y": 5,
      "z": 0,
      "name": "Rock_Basalt"
    },
    {
      "x": -7,
      "y": 6,
      "z": 0,
      "name": "Rock_Basalt"
    },
    {
      "x": -7,
      "y": 7,
      "z": 0,
      "name": "Rock_Basalt"
    },
    {
      "x": -7,
      "y": 8,
      "z": 0,
      "name": "Rock_Basalt"
    },
    {
      "x": -7,
      "y": 9,
      "z": 0,
      "name": "Rock_Basalt"
    },
    {
      "x": -7,
      "y": 10,
      "z": 0,
      "name": "Soil_Dirt_Burnt"
    },
    {
      "x": -7,
      "y": 11,
      "z": 0,
      "name": "Soil_Dirt_Burnt"
    },
    {
      "x": -7,
      "y": 12,
      "z": 0,
      "name": "Soil_Dirt_Burnt"
    },
    {
      "x": -7,
      "y": 14,
      "z": 0,
      "name": "Empty"
    },
    {
      "x": -7,
      "y": 15,
      "z": 0,
      "name": "Empty"
    },
    {
      "x": -7,
      "y": 16,
      "z": 0,
      "name": "Empty"
    },
    {
      "x": -7,
      "y": 17,
      "z": 0,
      "name": "Empty"
    },
    {
      "x": -7,
      "y": 18,
      "z": 0,
      "name": "Empty"
    },
    {
      "x": -7,
      "y": 2,
      "z": 1,
      "name": "Rock_Basalt"
    },
    {
      "x": -7,
      "y": 3,
      "z": 1,
      "name": "Rock_Basalt"
    },
    {
      "x": -7,
      "y": 4,
      "z": 1,
      "name": "Rock_Basalt"
    },
    {
      "x": -7,
      "y": 5,
      "z": 1,
      "name": "Rock_Basalt"
    },
    {
      "x": -7,
      "y": 6,
      "z": 1,
      "name": "Rock_Basalt"
    },
    {
      "x": -7,
      "y": 7,
      "z": 1,
      "name": "Rock_Basalt"
    },
    {
      "x": -7,
      "y": 8,
      "z": 1,
      "name": "Rock_Basalt"
    },
    {
      "x": -7,
      "y": 9,
      "z": 1,
      "name": "Rock_Basalt"
    },
    {
      "x": -7,
      "y": 10,
      "z": 1,
      "name": "Soil_Dirt_Burnt"
    },
    {
      "x": -7,
      "y": 11,
      "z": 1,
      "name": "Soil_Dirt_Burnt"
    },
    {
      "x": -7,
      "y": 12,
      "z": 1,
      "name": "Soil_Dirt_Burnt"
    },
    {
      "x": -7,
      "y": 14,
      "z": 1,
      "name": "Empty"
    },
    {
      "x": -7,
      "y": 15,
      "z": 1,
      "name": "Empty"
    },
    {
      "x": -7,
      "y": 16,
      "z": 1,
      "name": "Empty"
    },
    {
      "x": -7,
      "y": 17,
      "z": 1,
      "name": "Empty"
    },
    {
      "x": -7,
      "y": 3,
      "z": 2,
      "name": "Rock_Basalt"
    },
    {
      "x": -7,
      "y": 4,
      "z": 2,
      "name": "Rock_Basalt"
    },
    {
      "x": -7,
      "y": 5,
      "z": 2,
      "name": "Rock_Basalt"
    },
    {
      "x": -7,
      "y": 6,
      "z": 2,
      "name": "Rock_Basalt"
    },
    {
      "x": -7,
      "y": 7,
      "z": 2,
      "name": "Rock_Basalt"
    },
    {
      "x": -7,
      "y": 8,
      "z": 2,
      "name": "Rock_Basalt"
    },
    {
      "x": -7,
      "y": 9,
      "z": 2,
      "name": "Rock_Basalt"
    },
    {
      "x": -7,
      "y": 10,
      "z": 2,
      "name": "Rock_Basalt"
    },
    {
      "x": -7,
      "y": 11,
      "z": 2,
      "name": "Soil_Dirt_Burnt"
    },
    {
      "x": -7,
      "y": 12,
      "z": 2,
      "name": "Soil_Dirt_Burnt"
    },
    {
      "x": -7,
      "y": 14,
      "z": 2,
      "name": "Empty"
    },
    {
      "x": -7,
      "y": 15,
      "z": 2,
      "name": "Empty"
    },
    {
      "x": -7,
      "y": 16,
      "z": 2,
      "name": "Empty"
    },
    {
      "x": -7,
      "y": 4,
      "z": 3,
      "name": "Rock_Basalt"
    },
    {
      "x": -7,
      "y": 5,
      "z": 3,
      "name": "Rock_Basalt"
    },
    {
      "x": -7,
      "y": 6,
      "z": 3,
      "name": "Rock_Basalt"
    },
    {
      "x": -7,
      "y": 7,
      "z": 3,
      "name": "Rock_Basalt"
    },
    {
      "x": -7,
      "y": 8,
      "z": 3,
      "name": "Rock_Basalt"
    },
    {
      "x": -7,
      "y": 9,
      "z": 3,
      "name": "Rock_Basalt"
    },
    {
      "x": -7,
      "y": 10,
      "z": 3,
      "name": "Rock_Basalt"
    },
    {
      "x": -7,
      "y": 11,
      "z": 3,
      "name": "Rock_Basalt"
    },
    {
      "x": -7,
      "y": 12,
      "z": 3,
      "name": "Soil_Dirt_Burnt"
    },
    {
      "x": -7,
      "y": 14,
      "z": 3,
      "name": "Empty"
    },
    {
      "x": -7,
      "y": 15,
      "z": 3,
      "name": "Empty"
    },
    {
      "x": -7,
      "y": 16,
      "z": 3,
      "name": "Empty"
    },
    {
      "x": -7,
      "y": 17,
      "z": 3,
      "name": "Empty"
    },
    {
      "x": -7,
      "y": 4,
      "z": 4,
      "name": "Rock_Basalt"
    },
    {
      "x": -7,
      "y": 5,
      "z": 4,
      "name": "Rock_Basalt"
    },
    {
      "x": -7,
      "y": 6,
      "z": 4,
      "name": "Rock_Basalt"
    },
    {
      "x": -7,
      "y": 7,
      "z": 4,
      "name": "Rock_Basalt"
    },
    {
      "x": -7,
      "y": 8,
      "z": 4,
      "name": "Rock_Basalt"
    },
    {
      "x": -7,
      "y": 9,
      "z": 4,
      "name": "Rock_Basalt"
    },
    {
      "x": -7,
      "y": 10,
      "z": 4,
      "name": "Rock_Basalt"
    },
    {
      "x": -7,
      "y": 11,
      "z": 4,
      "name": "Rock_Basalt"
    },
    {
      "x": -7,
      "y": 12,
      "z": 4,
      "name": "Rock_Basalt"
    },
    {
      "x": -7,
      "y": 13,
      "z": 4,
      "name": "Plant_Crop_Mushroom_Block_Green"
    },
    {
      "x": -7,
      "y": 14,
      "z": 4,
      "name": "Plant_Moss_Rug_Green_Dark"
    },
    {
      "x": -7,
      "y": 15,
      "z": 4,
      "name": "Empty"
    },
    {
      "x": -7,
      "y": 10,
      "z": 5,
      "name": "Rock_Basalt"
    },
    {
      "x": -7,
      "y": 11,
      "z": 5,
      "name": "Rock_Basalt"
    },
    {
      "x": -7,
      "y": 12,
      "z": 5,
      "name": "Rock_Basalt"
    },
    {
      "x": -6,
      "y": 7,
      "z": -6,
      "name": "Rock_Basalt"
    },
    {
      "x": -6,
      "y": 8,
      "z": -6,
      "name": "Rock_Basalt"
    },
    {
      "x": -6,
      "y": 9,
      "z": -6,
      "name": "Rock_Basalt"
    },
    {
      "x": -6,
      "y": 10,
      "z": -6,
      "name": "Rock_Basalt"
    },
    {
      "x": -6,
      "y": 11,
      "z": -6,
      "name": "Rock_Basalt"
    },
    {
      "x": -6,
      "y": 12,
      "z": -6,
      "name": "Rock_Stone"
    },
    {
      "x": -6,
      "y": 13,
      "z": -6,
      "name": "Rock_Stone"
    },
    {
      "x": -6,
      "y": 14,
      "z": -6,
      "name": "Rock_Stone"
    },
    {
      "x": -6,
      "y": 15,
      "z": -6,
      "name": "Rock_Stone"
    },
    {
      "x": -6,
      "y": 16,
      "z": -6,
      "name": "Rock_Stone"
    },
    {
      "x": -6,
      "y": 17,
      "z": -6,
      "name": "Rock_Stone"
    },
    {
      "x": -6,
      "y": 2,
      "z": -5,
      "name": "Rock_Basalt"
    },
    {
      "x": -6,
      "y": 3,
      "z": -5,
      "name": "Rock_Basalt"
    },
    {
      "x": -6,
      "y": 4,
      "z": -5,
      "name": "Rock_Basalt"
    },
    {
      "x": -6,
      "y": 5,
      "z": -5,
      "name": "Rock_Basalt"
    },
    {
      "x": -6,
      "y": 6,
      "z": -5,
      "name": "Rock_Basalt"
    },
    {
      "x": -6,
      "y": 7,
      "z": -5,
      "name": "Rock_Basalt"
    },
    {
      "x": -6,
      "y": 8,
      "z": -5,
      "name": "Rock_Basalt"
    },
    {
      "x": -6,
      "y": 9,
      "z": -5,
      "name": "Rock_Basalt"
    },
    {
      "x": -6,
      "y": 10,
      "z": -5,
      "name": "Rock_Basalt"
    },
    {
      "x": -6,
      "y": 11,
      "z": -5,
      "name": "Rock_Basalt"
    },
    {
      "x": -6,
      "y": 12,
      "z": -5,
      "name": "Rock_Stone"
    },
    {
      "x": -6,
      "y": 13,
      "z": -5,
      "name": "Plant_Crop_Mushroom_Block_Green"
    },
    {
      "x": -6,
      "y": 14,
      "z": -5,
      "name": "Soil_Grass_Deep"
    },
    {
      "x": -6,
      "y": 15,
      "z": -5,
      "name": "Plant_Bush_Jungle"
    },
    {
      "x": -6,
      "y": 16,
      "z": -5,
      "name": "Rock_Stone"
    },
    {
      "x": -6,
      "y": 17,
      "z": -5,
      "name": "Rock_Stone"
    },
    {
      "x": -6,
      "y": 18,
      "z": -5,
      "name": "Rock_Stone"
    },
    {
      "x": -6,
      "y": 2,
      "z": -4,
      "name": "Rock_Basalt"
    },
    {
      "x": -6,
      "y": 3,
      "z": -4,
      "name": "Rock_Basalt"
    },
    {
      "x": -6,
      "y": 4,
      "z": -4,
      "name": "Rock_Basalt"
    },
    {
      "x": -6,
      "y": 5,
      "z": -4,
      "name": "Rock_Basalt"
    },
    {
      "x": -6,
      "y": 6,
      "z": -4,
      "name": "Rock_Basalt"
    },
    {
      "x": -6,
      "y": 7,
      "z": -4,
      "name": "Rock_Basalt"
    },
    {
      "x": -6,
      "y": 8,
      "z": -4,
      "name": "Rock_Basalt"
    },
    {
      "x": -6,
      "y": 9,
      "z": -4,
      "name": "Rock_Basalt"
    },
    {
      "x": -6,
      "y": 10,
      "z": -4,
      "name": "Rock_Basalt"
    },
    {
      "x": -6,
      "y": 11,
      "z": -4,
      "name": "Rock_Stone"
    },
    {
      "x": -6,
      "y": 12,
      "z": -4,
      "name": "Rock_Stone"
    },
    {
      "x": -6,
      "y": 13,
      "z": -4,
      "name": "Plant_Crop_Mushroom_Block_Green"
    },
    {
      "x": -6,
      "y": 14,
      "z": -4,
      "name": "Soil_Grass_Deep"
    },
    {
      "x": -6,
      "y": 15,
      "z": -4,
      "name": "Plant_Bush_Jungle"
    },
    {
      "x": -6,
      "y": 16,
      "z": -4,
      "name": "Empty"
    },
    {
      "x": -6,
      "y": 17,
      "z": -4,
      "name": "Empty"
    },
    {
      "x": -6,
      "y": 18,
      "z": -4,
      "name": "Rock_Stone"
    },
    {
      "x": -6,
      "y": 2,
      "z": -3,
      "name": "Rock_Basalt"
    },
    {
      "x": -6,
      "y": 3,
      "z": -3,
      "name": "Rock_Basalt"
    },
    {
      "x": -6,
      "y": 4,
      "z": -3,
      "name": "Rock_Basalt"
    },
    {
      "x": -6,
      "y": 5,
      "z": -3,
      "name": "Rock_Basalt"
    },
    {
      "x": -6,
      "y": 6,
      "z": -3,
      "name": "Rock_Basalt"
    },
    {
      "x": -6,
      "y": 7,
      "z": -3,
      "name": "Rock_Basalt"
    },
    {
      "x": -6,
      "y": 8,
      "z": -3,
      "name": "Rock_Basalt"
    },
    {
      "x": -6,
      "y": 9,
      "z": -3,
      "name": "Rock_Basalt"
    },
    {
      "x": -6,
      "y": 10,
      "z": -3,
      "name": "Rock_Basalt"
    },
    {
      "x": -6,
      "y": 11,
      "z": -3,
      "name": "Soil_Dirt_Burnt"
    },
    {
      "x": -6,
      "y": 12,
      "z": -3,
      "name": "Soil_Dirt_Burnt"
    },
    {
      "x": -6,
      "y": 14,
      "z": -3,
      "name": "Plant_Moss_Rug_Blue"
    },
    {
      "x": -6,
      "y": 15,
      "z": -3,
      "name": "Empty"
    },
    {
      "x": -6,
      "y": 16,
      "z": -3,
      "name": "Empty"
    },
    {
      "x": -6,
      "y": 17,
      "z": -3,
      "name": "Empty"
    },
    {
      "x": -6,
      "y": 18,
      "z": -3,
      "name": "Rock_Stone"
    },
    {
      "x": -6,
      "y": 19,
      "z": -3,
      "name": "Plant_Moss_Rug_Green_Dark"
    },
    {
      "x": -6,
      "y": 2,
      "z": -2,
      "name": "Rock_Basalt"
    },
    {
      "x": -6,
      "y": 3,
      "z": -2,
      "name": "Rock_Basalt"
    },
    {
      "x": -6,
      "y": 4,
      "z": -2,
      "name": "Rock_Basalt"
    },
    {
      "x": -6,
      "y": 5,
      "z": -2,
      "name": "Rock_Basalt"
    },
    {
      "x": -6,
      "y": 6,
      "z": -2,
      "name": "Rock_Basalt"
    },
    {
      "x": -6,
      "y": 7,
      "z": -2,
      "name": "Rock_Basalt"
    },
    {
      "x": -6,
      "y": 8,
      "z": -2,
      "name": "Rock_Basalt"
    },
    {
      "x": -6,
      "y": 9,
      "z": -2,
      "name": "Rock_Basalt"
    },
    {
      "x": -6,
      "y": 10,
      "z": -2,
      "name": "Soil_Dirt_Burnt"
    },
    {
      "x": -6,
      "y": 11,
      "z": -2,
      "name": "Soil_Dirt_Burnt"
    },
    {
      "x": -6,
      "y": 12,
      "z": -2,
      "name": "Soil_Dirt_Burnt"
    },
    {
      "x": -6,
      "y": 14,
      "z": -2,
      "name": "Empty"
    },
    {
      "x": -6,
      "y": 15,
      "z": -2,
      "name": "Empty"
    },
    {
      "x": -6,
      "y": 16,
      "z": -2,
      "name": "Empty"
    },
    {
      "x": -6,
      "y": 17,
      "z": -2,
      "name": "Empty"
    },
    {
      "x": -6,
      "y": 18,
      "z": -2,
      "name": "Plant_Moss_Wall_Green_Dark"
    },
    {
      "x": -6,
      "y": 19,
      "z": -2,
      "name": "Empty"
    },
    {
      "x": -6,
      "y": 2,
      "z": -1,
      "name": "Rock_Basalt"
    },
    {
      "x": -6,
      "y": 3,
      "z": -1,
      "name": "Rock_Basalt"
    },
    {
      "x": -6,
      "y": 4,
      "z": -1,
      "name": "Rock_Basalt"
    },
    {
      "x": -6,
      "y": 5,
      "z": -1,
      "name": "Rock_Basalt"
    },
    {
      "x": -6,
      "y": 6,
      "z": -1,
      "name": "Rock_Basalt"
    },
    {
      "x": -6,
      "y": 7,
      "z": -1,
      "name": "Rock_Basalt"
    },
    {
      "x": -6,
      "y": 8,
      "z": -1,
      "name": "Rock_Basalt"
    },
    {
      "x": -6,
      "y": 9,
      "z": -1,
      "name": "Rock_Basalt"
    },
    {
      "x": -6,
      "y": 10,
      "z": -1,
      "name": "Soil_Dirt_Burnt"
    },
    {
      "x": -6,
      "y": 11,
      "z": -1,
      "name": "Soil_Dirt_Burnt"
    },
    {
      "x": -6,
      "y": 12,
      "z": -1,
      "name": "Soil_Dirt_Burnt"
    },
    {
      "x": -6,
      "y": 14,
      "z": -1,
      "name": "Empty"
    },
    {
      "x": -6,
      "y": 15,
      "z": -1,
      "name": "Empty"
    },
    {
      "x": -6,
      "y": 16,
      "z": -1,
      "name": "Empty"
    },
    {
      "x": -6,
      "y": 17,
      "z": -1,
      "name": "Empty"
    },
    {
      "x": -6,
      "y": 18,
      "z": -1,
      "name": "Empty"
    },
    {
      "x": -6,
      "y": 2,
      "z": 0,
      "name": "Rock_Basalt"
    },
    {
      "x": -6,
      "y": 3,
      "z": 0,
      "name": "Rock_Basalt"
    },
    {
      "x": -6,
      "y": 4,
      "z": 0,
      "name": "Rock_Basalt"
    },
    {
      "x": -6,
      "y": 5,
      "z": 0,
      "name": "Rock_Basalt"
    },
    {
      "x": -6,
      "y": 6,
      "z": 0,
      "name": "Rock_Basalt"
    },
    {
      "x": -6,
      "y": 7,
      "z": 0,
      "name": "Rock_Basalt"
    },
    {
      "x": -6,
      "y": 8,
      "z": 0,
      "name": "Rock_Basalt"
    },
    {
      "x": -6,
      "y": 9,
      "z": 0,
      "name": "Rock_Basalt"
    },
    {
      "x": -6,
      "y": 10,
      "z": 0,
      "name": "Soil_Dirt_Burnt"
    },
    {
      "x": -6,
      "y": 11,
      "z": 0,
      "name": "Soil_Dirt_Burnt"
    },
    {
      "x": -6,
      "y": 12,
      "z": 0,
      "name": "Soil_Dirt_Burnt"
    },
    {
      "x": -6,
      "y": 14,
      "z": 0,
      "name": "Empty"
    },
    {
      "x": -6,
      "y": 15,
      "z": 0,
      "name": "Empty"
    },
    {
      "x": -6,
      "y": 16,
      "z": 0,
      "name": "Empty"
    },
    {
      "x": -6,
      "y": 17,
      "z": 0,
      "name": "Empty"
    },
    {
      "x": -6,
      "y": 18,
      "z": 0,
      "name": "Empty"
    },
    {
      "x": -6,
      "y": 2,
      "z": 1,
      "name": "Rock_Basalt"
    },
    {
      "x": -6,
      "y": 3,
      "z": 1,
      "name": "Rock_Basalt"
    },
    {
      "x": -6,
      "y": 4,
      "z": 1,
      "name": "Rock_Basalt"
    },
    {
      "x": -6,
      "y": 5,
      "z": 1,
      "name": "Rock_Basalt"
    },
    {
      "x": -6,
      "y": 6,
      "z": 1,
      "name": "Rock_Basalt"
    },
    {
      "x": -6,
      "y": 7,
      "z": 1,
      "name": "Rock_Basalt"
    },
    {
      "x": -6,
      "y": 8,
      "z": 1,
      "name": "Rock_Basalt"
    },
    {
      "x": -6,
      "y": 9,
      "z": 1,
      "name": "Rock_Basalt"
    },
    {
      "x": -6,
      "y": 10,
      "z": 1,
      "name": "Soil_Dirt_Burnt"
    },
    {
      "x": -6,
      "y": 11,
      "z": 1,
      "name": "Soil_Dirt_Burnt"
    },
    {
      "x": -6,
      "y": 12,
      "z": 1,
      "name": "Soil_Dirt_Burnt"
    },
    {
      "x": -6,
      "y": 14,
      "z": 1,
      "name": "Empty"
    },
    {
      "x": -6,
      "y": 15,
      "z": 1,
      "name": "Empty"
    },
    {
      "x": -6,
      "y": 16,
      "z": 1,
      "name": "Empty"
    },
    {
      "x": -6,
      "y": 17,
      "z": 1,
      "name": "Empty"
    },
    {
      "x": -6,
      "y": 18,
      "z": 1,
      "name": "Empty"
    },
    {
      "x": -6,
      "y": 2,
      "z": 2,
      "name": "Rock_Basalt"
    },
    {
      "x": -6,
      "y": 3,
      "z": 2,
      "name": "Rock_Basalt"
    },
    {
      "x": -6,
      "y": 4,
      "z": 2,
      "name": "Rock_Basalt"
    },
    {
      "x": -6,
      "y": 5,
      "z": 2,
      "name": "Rock_Basalt"
    },
    {
      "x": -6,
      "y": 6,
      "z": 2,
      "name": "Rock_Basalt"
    },
    {
      "x": -6,
      "y": 7,
      "z": 2,
      "name": "Rock_Basalt"
    },
    {
      "x": -6,
      "y": 8,
      "z": 2,
      "name": "Rock_Basalt"
    },
    {
      "x": -6,
      "y": 9,
      "z": 2,
      "name": "Rock_Basalt"
    },
    {
      "x": -6,
      "y": 10,
      "z": 2,
      "name": "Soil_Dirt_Burnt"
    },
    {
      "x": -6,
      "y": 11,
      "z": 2,
      "name": "Soil_Dirt_Burnt"
    },
    {
      "x": -6,
      "y": 12,
      "z": 2,
      "name": "Soil_Dirt_Burnt"
    },
    {
      "x": -6,
      "y": 14,
      "z": 2,
      "name": "Empty"
    },
    {
      "x": -6,
      "y": 15,
      "z": 2,
      "name": "Empty"
    },
    {
      "x": -6,
      "y": 16,
      "z": 2,
      "name": "Empty"
    },
    {
      "x": -6,
      "y": 17,
      "z": 2,
      "name": "Empty"
    },
    {
      "x": -6,
      "y": 18,
      "z": 2,
      "name": "Empty"
    },
    {
      "x": -6,
      "y": 3,
      "z": 3,
      "name": "Rock_Basalt"
    },
    {
      "x": -6,
      "y": 4,
      "z": 3,
      "name": "Rock_Basalt"
    },
    {
      "x": -6,
      "y": 5,
      "z": 3,
      "name": "Rock_Basalt"
    },
    {
      "x": -6,
      "y": 6,
      "z": 3,
      "name": "Rock_Basalt"
    },
    {
      "x": -6,
      "y": 7,
      "z": 3,
      "name": "Rock_Basalt"
    },
    {
      "x": -6,
      "y": 8,
      "z": 3,
      "name": "Rock_Basalt"
    },
    {
      "x": -6,
      "y": 9,
      "z": 3,
      "name": "Rock_Basalt"
    },
    {
      "x": -6,
      "y": 10,
      "z": 3,
      "name": "Rock_Basalt"
    },
    {
      "x": -6,
      "y": 11,
      "z": 3,
      "name": "Soil_Dirt_Burnt"
    },
    {
      "x": -6,
      "y": 12,
      "z": 3,
      "name": "Soil_Dirt_Burnt"
    },
    {
      "x": -6,
      "y": 14,
      "z": 3,
      "name": "Empty"
    },
    {
      "x": -6,
      "y": 15,
      "z": 3,
      "name": "Empty"
    },
    {
      "x": -6,
      "y": 16,
      "z": 3,
      "name": "Empty"
    },
    {
      "x": -6,
      "y": 17,
      "z": 3,
      "name": "Empty"
    },
    {
      "x": -6,
      "y": 18,
      "z": 3,
      "name": "Empty"
    },
    {
      "x": -6,
      "y": 3,
      "z": 4,
      "name": "Rock_Basalt"
    },
    {
      "x": -6,
      "y": 4,
      "z": 4,
      "name": "Rock_Basalt"
    },
    {
      "x": -6,
      "y": 5,
      "z": 4,
      "name": "Rock_Basalt"
    },
    {
      "x": -6,
      "y": 6,
      "z": 4,
      "name": "Rock_Basalt"
    },
    {
      "x": -6,
      "y": 7,
      "z": 4,
      "name": "Rock_Basalt"
    },
    {
      "x": -6,
      "y": 8,
      "z": 4,
      "name": "Rock_Basalt"
    },
    {
      "x": -6,
      "y": 9,
      "z": 4,
      "name": "Rock_Basalt"
    },
    {
      "x": -6,
      "y": 10,
      "z": 4,
      "name": "Rock_Basalt"
    },
    {
      "x": -6,
      "y": 11,
      "z": 4,
      "name": "Rock_Basalt"
    },
    {
      "x": -6,
      "y": 12,
      "z": 4,
      "name": "Rock_Basalt"
    },
    {
      "x": -6,
      "y": 13,
      "z": 4,
      "name": "Rock_Basalt"
    },
    {
      "x": -6,
      "y": 14,
      "z": 4,
      "name": "Rock_Basalt"
    },
    {
      "x": -6,
      "y": 15,
      "z": 4,
      "name": "Empty"
    },
    {
      "x": -6,
      "y": 16,
      "z": 4,
      "name": "Empty"
    },
    {
      "x": -6,
      "y": 17,
      "z": 4,
      "name": "Empty"
    },
    {
      "x": -6,
      "y": 18,
      "z": 4,
      "name": "Empty"
    },
    {
      "x": -6,
      "y": 4,
      "z": 5,
      "name": "Rock_Basalt"
    },
    {
      "x": -6,
      "y": 5,
      "z": 5,
      "name": "Rock_Basalt"
    },
    {
      "x": -6,
      "y": 6,
      "z": 5,
      "name": "Rock_Basalt"
    },
    {
      "x": -6,
      "y": 7,
      "z": 5,
      "name": "Rock_Basalt"
    },
    {
      "x": -6,
      "y": 8,
      "z": 5,
      "name": "Rock_Basalt"
    },
    {
      "x": -6,
      "y": 9,
      "z": 5,
      "name": "Rock_Basalt"
    },
    {
      "x": -6,
      "y": 10,
      "z": 5,
      "name": "Rock_Basalt"
    },
    {
      "x": -6,
      "y": 11,
      "z": 5,
      "name": "Rock_Basalt"
    },
    {
      "x": -6,
      "y": 12,
      "z": 5,
      "name": "Rock_Basalt"
    },
    {
      "x": -6,
      "y": 13,
      "z": 5,
      "name": "Rock_Basalt"
    },
    {
      "x": -6,
      "y": 14,
      "z": 5,
      "name": "Rock_Basalt"
    },
    {
      "x": -6,
      "y": 15,
      "z": 5,
      "name": "Empty"
    },
    {
      "x": -6,
      "y": 16,
      "z": 5,
      "name": "Empty"
    },
    {
      "x": -6,
      "y": 17,
      "z": 5,
      "name": "Empty"
    },
    {
      "x": -6,
      "y": 18,
      "z": 5,
      "name": "Empty"
    },
    {
      "x": -5,
      "y": 8,
      "z": -7,
      "name": "Rock_Basalt"
    },
    {
      "x": -5,
      "y": 9,
      "z": -7,
      "name": "Rock_Basalt"
    },
    {
      "x": -5,
      "y": 10,
      "z": -7,
      "name": "Rock_Basalt"
    },
    {
      "x": -5,
      "y": 11,
      "z": -7,
      "name": "Rock_Basalt"
    },
    {
      "x": -5,
      "y": 12,
      "z": -7,
      "name": "Rock_Basalt"
    },
    {
      "x": -5,
      "y": 13,
      "z": -7,
      "name": "Rock_Basalt"
    },
    {
      "x": -5,
      "y": 14,
      "z": -7,
      "name": "Rock_Basalt"
    },
    {
      "x": -5,
      "y": 5,
      "z": -6,
      "name": "Rock_Basalt"
    },
    {
      "x": -5,
      "y": 6,
      "z": -6,
      "name": "Rock_Basalt"
    },
    {
      "x": -5,
      "y": 7,
      "z": -6,
      "name": "Rock_Basalt"
    },
    {
      "x": -5,
      "y": 8,
      "z": -6,
      "name": "Rock_Basalt"
    },
    {
      "x": -5,
      "y": 9,
      "z": -6,
      "name": "Rock_Basalt"
    },
    {
      "x": -5,
      "y": 10,
      "z": -6,
      "name": "Rock_Basalt"
    },
    {
      "x": -5,
      "y": 11,
      "z": -6,
      "name": "Rock_Basalt"
    },
    {
      "x": -5,
      "y": 12,
      "z": -6,
      "name": "Rock_Basalt"
    },
    {
      "x": -5,
      "y": 13,
      "z": -6,
      "name": "Rock_Stone"
    },
    {
      "x": -5,
      "y": 14,
      "z": -6,
      "name": "Rock_Stone"
    },
    {
      "x": -5,
      "y": 15,
      "z": -6,
      "name": "Rock_Stone"
    },
    {
      "x": -5,
      "y": 16,
      "z": -6,
      "name": "Rock_Stone"
    },
    {
      "x": -5,
      "y": 17,
      "z": -6,
      "name": "Rock_Stone"
    },
    {
      "x": -5,
      "y": 18,
      "z": -6,
      "name": "Rock_Stone"
    },
    {
      "x": -5,
      "y": 2,
      "z": -5,
      "name": "Rock_Basalt"
    },
    {
      "x": -5,
      "y": 3,
      "z": -5,
      "name": "Rock_Basalt"
    },
    {
      "x": -5,
      "y": 4,
      "z": -5,
      "name": "Rock_Basalt"
    },
    {
      "x": -5,
      "y": 5,
      "z": -5,
      "name": "Rock_Basalt"
    },
    {
      "x": -5,
      "y": 6,
      "z": -5,
      "name": "Rock_Basalt"
    },
    {
      "x": -5,
      "y": 7,
      "z": -5,
      "name": "Rock_Basalt"
    },
    {
      "x": -5,
      "y": 8,
      "z": -5,
      "name": "Rock_Basalt"
    },
    {
      "x": -5,
      "y": 9,
      "z": -5,
      "name": "Rock_Basalt"
    },
    {
      "x": -5,
      "y": 10,
      "z": -5,
      "name": "Rock_Basalt"
    },
    {
      "x": -5,
      "y": 11,
      "z": -5,
      "name": "Rock_Basalt"
    },
    {
      "x": -5,
      "y": 12,
      "z": -5,
      "name": "Rock_Stone"
    },
    {
      "x": -5,
      "y": 13,
      "z": -5,
      "name": "Plant_Crop_Mushroom_Block_Green"
    },
    {
      "x": -5,
      "y": 14,
      "z": -5,
      "name": "Soil_Grass_Deep"
    },
    {
      "x": -5,
      "y": 15,
      "z": -5,
      "name": "Plant_Grass_Jungle_Tall"
    },
    {
      "x": -5,
      "y": 16,
      "z": -5,
      "name": "Empty"
    },
    {
      "x": -5,
      "y": 17,
      "z": -5,
      "name": "Rock_Stone"
    },
    {
      "x": -5,
      "y": 18,
      "z": -5,
      "name": "Rock_Stone"
    },
    {
      "x": -5,
      "y": 2,
      "z": -4,
      "name": "Rock_Basalt"
    },
    {
      "x": -5,
      "y": 3,
      "z": -4,
      "name": "Rock_Basalt"
    },
    {
      "x": -5,
      "y": 4,
      "z": -4,
      "name": "Rock_Basalt"
    },
    {
      "x": -5,
      "y": 5,
      "z": -4,
      "name": "Rock_Basalt"
    },
    {
      "x": -5,
      "y": 6,
      "z": -4,
      "name": "Rock_Basalt"
    },
    {
      "x": -5,
      "y": 7,
      "z": -4,
      "name": "Rock_Basalt"
    },
    {
      "x": -5,
      "y": 8,
      "z": -4,
      "name": "Rock_Basalt"
    },
    {
      "x": -5,
      "y": 9,
      "z": -4,
      "name": "Rock_Basalt"
    },
    {
      "x": -5,
      "y": 10,
      "z": -4,
      "name": "Rock_Basalt"
    },
    {
      "x": -5,
      "y": 11,
      "z": -4,
      "name": "Rock_Basalt"
    },
    {
      "x": -5,
      "y": 12,
      "z": -4,
      "name": "Rock_Stone"
    },
    {
      "x": -5,
      "y": 13,
      "z": -4,
      "name": "Soil_Grass_Deep"
    },
    {
      "x": -5,
      "y": 14,
      "z": -4,
      "name": "Plant_Grass_Jungle_Tall"
    },
    {
      "x": -5,
      "y": 15,
      "z": -4,
      "name": "Empty"
    },
    {
      "x": -5,
      "y": 16,
      "z": -4,
      "name": "Empty"
    },
    {
      "x": -5,
      "y": 17,
      "z": -4,
      "name": "Empty"
    },
    {
      "x": -5,
      "y": 18,
      "z": -4,
      "name": "Rock_Stone"
    },
    {
      "x": -5,
      "y": 19,
      "z": -4,
      "name": "Plant_Moss_Rug_Green_Dark"
    },
    {
      "x": -5,
      "y": 2,
      "z": -3,
      "name": "Rock_Basalt"
    },
    {
      "x": -5,
      "y": 3,
      "z": -3,
      "name": "Rock_Basalt"
    },
    {
      "x": -5,
      "y": 4,
      "z": -3,
      "name": "Rock_Basalt"
    },
    {
      "x": -5,
      "y": 5,
      "z": -3,
      "name": "Rock_Basalt"
    },
    {
      "x": -5,
      "y": 6,
      "z": -3,
      "name": "Rock_Basalt"
    },
    {
      "x": -5,
      "y": 7,
      "z": -3,
      "name": "Rock_Basalt"
    },
    {
      "x": -5,
      "y": 8,
      "z": -3,
      "name": "Rock_Basalt"
    },
    {
      "x": -5,
      "y": 9,
      "z": -3,
      "name": "Rock_Basalt"
    },
    {
      "x": -5,
      "y": 10,
      "z": -3,
      "name": "Rock_Basalt"
    },
    {
      "x": -5,
      "y": 11,
      "z": -3,
      "name": "Rock_Basalt"
    },
    {
      "x": -5,
      "y": 12,
      "z": -3,
      "name": "Soil_Dirt_Burnt"
    },
    {
      "x": -5,
      "y": 14,
      "z": -3,
      "name": "Plant_Moss_Rug_Blue"
    },
    {
      "x": -5,
      "y": 15,
      "z": -3,
      "name": "Empty"
    },
    {
      "x": -5,
      "y": 16,
      "z": -3,
      "name": "Empty"
    },
    {
      "x": -5,
      "y": 17,
      "z": -3,
      "name": "Empty"
    },
    {
      "x": -5,
      "y": 18,
      "z": -3,
      "name": "Empty"
    },
    {
      "x": -5,
      "y": 19,
      "z": -3,
      "name": "Empty"
    },
    {
      "x": -5,
      "y": 2,
      "z": -2,
      "name": "Rock_Basalt"
    },
    {
      "x": -5,
      "y": 3,
      "z": -2,
      "name": "Rock_Basalt"
    },
    {
      "x": -5,
      "y": 4,
      "z": -2,
      "name": "Rock_Basalt"
    },
    {
      "x": -5,
      "y": 5,
      "z": -2,
      "name": "Rock_Basalt"
    },
    {
      "x": -5,
      "y": 6,
      "z": -2,
      "name": "Rock_Basalt"
    },
    {
      "x": -5,
      "y": 7,
      "z": -2,
      "name": "Rock_Basalt"
    },
    {
      "x": -5,
      "y": 8,
      "z": -2,
      "name": "Rock_Basalt"
    },
    {
      "x": -5,
      "y": 9,
      "z": -2,
      "name": "Rock_Basalt"
    },
    {
      "x": -5,
      "y": 10,
      "z": -2,
      "name": "Rock_Basalt"
    },
    {
      "x": -5,
      "y": 11,
      "z": -2,
      "name": "Soil_Dirt_Burnt"
    },
    {
      "x": -5,
      "y": 12,
      "z": -2,
      "name": "Soil_Dirt_Burnt"
    },
    {
      "x": -5,
      "y": 14,
      "z": -2,
      "name": "Plant_Moss_Rug_Blue"
    },
    {
      "x": -5,
      "y": 15,
      "z": -2,
      "name": "Empty"
    },
    {
      "x": -5,
      "y": 16,
      "z": -2,
      "name": "Empty"
    },
    {
      "x": -5,
      "y": 17,
      "z": -2,
      "name": "Empty"
    },
    {
      "x": -5,
      "y": 18,
      "z": -2,
      "name": "Empty"
    },
    {
      "x": -5,
      "y": 19,
      "z": -2,
      "name": "Empty"
    },
    {
      "x": -5,
      "y": 2,
      "z": -1,
      "name": "Rock_Basalt"
    },
    {
      "x": -5,
      "y": 3,
      "z": -1,
      "name": "Rock_Basalt"
    },
    {
      "x": -5,
      "y": 4,
      "z": -1,
      "name": "Rock_Basalt"
    },
    {
      "x": -5,
      "y": 5,
      "z": -1,
      "name": "Rock_Basalt"
    },
    {
      "x": -5,
      "y": 6,
      "z": -1,
      "name": "Rock_Basalt"
    },
    {
      "x": -5,
      "y": 7,
      "z": -1,
      "name": "Rock_Basalt"
    },
    {
      "x": -5,
      "y": 8,
      "z": -1,
      "name": "Rock_Basalt"
    },
    {
      "x": -5,
      "y": 9,
      "z": -1,
      "name": "Rock_Basalt"
    },
    {
      "x": -5,
      "y": 10,
      "z": -1,
      "name": "Soil_Dirt_Burnt"
    },
    {
      "x": -5,
      "y": 11,
      "z": -1,
      "name": "Soil_Dirt_Burnt"
    },
    {
      "x": -5,
      "y": 12,
      "z": -1,
      "name": "Soil_Dirt_Burnt"
    },
    {
      "x": -5,
      "y": 14,
      "z": -1,
      "name": "Empty"
    },
    {
      "x": -5,
      "y": 15,
      "z": -1,
      "name": "Empty"
    },
    {
      "x": -5,
      "y": 16,
      "z": -1,
      "name": "Empty"
    },
    {
      "x": -5,
      "y": 17,
      "z": -1,
      "name": "Empty"
    },
    {
      "x": -5,
      "y": 18,
      "z": -1,
      "name": "Empty"
    },
    {
      "x": -5,
      "y": 19,
      "z": -1,
      "name": "Empty"
    },
    {
      "x": -5,
      "y": 2,
      "z": 0,
      "name": "Rock_Basalt"
    },
    {
      "x": -5,
      "y": 3,
      "z": 0,
      "name": "Rock_Basalt"
    },
    {
      "x": -5,
      "y": 4,
      "z": 0,
      "name": "Rock_Basalt"
    },
    {
      "x": -5,
      "y": 5,
      "z": 0,
      "name": "Rock_Basalt"
    },
    {
      "x": -5,
      "y": 6,
      "z": 0,
      "name": "Rock_Basalt"
    },
    {
      "x": -5,
      "y": 7,
      "z": 0,
      "name": "Rock_Basalt"
    },
    {
      "x": -5,
      "y": 8,
      "z": 0,
      "name": "Rock_Basalt"
    },
    {
      "x": -5,
      "y": 9,
      "z": 0,
      "name": "Rock_Basalt"
    },
    {
      "x": -5,
      "y": 10,
      "z": 0,
      "name": "Soil_Dirt_Burnt"
    },
    {
      "x": -5,
      "y": 11,
      "z": 0,
      "name": "Soil_Dirt_Burnt"
    },
    {
      "x": -5,
      "y": 12,
      "z": 0,
      "name": "Soil_Dirt_Burnt"
    },
    {
      "x": -5,
      "y": 14,
      "z": 0,
      "name": "Empty"
    },
    {
      "x": -5,
      "y": 15,
      "z": 0,
      "name": "Empty"
    },
    {
      "x": -5,
      "y": 16,
      "z": 0,
      "name": "Empty"
    },
    {
      "x": -5,
      "y": 17,
      "z": 0,
      "name": "Empty"
    },
    {
      "x": -5,
      "y": 18,
      "z": 0,
      "name": "Empty"
    },
    {
      "x": -5,
      "y": 1,
      "z": 1,
      "name": "Rock_Basalt"
    },
    {
      "x": -5,
      "y": 2,
      "z": 1,
      "name": "Rock_Basalt"
    },
    {
      "x": -5,
      "y": 3,
      "z": 1,
      "name": "Rock_Basalt"
    },
    {
      "x": -5,
      "y": 4,
      "z": 1,
      "name": "Rock_Basalt"
    },
    {
      "x": -5,
      "y": 5,
      "z": 1,
      "name": "Rock_Basalt"
    },
    {
      "x": -5,
      "y": 6,
      "z": 1,
      "name": "Rock_Basalt"
    },
    {
      "x": -5,
      "y": 7,
      "z": 1,
      "name": "Rock_Basalt"
    },
    {
      "x": -5,
      "y": 8,
      "z": 1,
      "name": "Rock_Basalt"
    },
    {
      "x": -5,
      "y": 9,
      "z": 1,
      "name": "Rock_Basalt"
    },
    {
      "x": -5,
      "y": 10,
      "z": 1,
      "name": "Soil_Dirt_Burnt"
    },
    {
      "x": -5,
      "y": 11,
      "z": 1,
      "name": "Soil_Dirt_Burnt"
    },
    {
      "x": -5,
      "y": 12,
      "z": 1,
      "name": "Soil_Dirt_Burnt"
    },
    {
      "x": -5,
      "y": 14,
      "z": 1,
      "name": "Empty"
    },
    {
      "x": -5,
      "y": 15,
      "z": 1,
      "name": "Empty"
    },
    {
      "x": -5,
      "y": 16,
      "z": 1,
      "name": "Empty"
    },
    {
      "x": -5,
      "y": 17,
      "z": 1,
      "name": "Empty"
    },
    {
      "x": -5,
      "y": 18,
      "z": 1,
      "name": "Empty"
    },
    {
      "x": -5,
      "y": 19,
      "z": 1,
      "name": "Empty"
    },
    {
      "x": -5,
      "y": 1,
      "z": 2,
      "name": "Rock_Basalt"
    },
    {
      "x": -5,
      "y": 2,
      "z": 2,
      "name": "Rock_Basalt"
    },
    {
      "x": -5,
      "y": 3,
      "z": 2,
      "name": "Rock_Basalt"
    },
    {
      "x": -5,
      "y": 4,
      "z": 2,
      "name": "Rock_Basalt"
    },
    {
      "x": -5,
      "y": 5,
      "z": 2,
      "name": "Rock_Basalt"
    },
    {
      "x": -5,
      "y": 6,
      "z": 2,
      "name": "Rock_Basalt"
    },
    {
      "x": -5,
      "y": 7,
      "z": 2,
      "name": "Rock_Basalt"
    },
    {
      "x": -5,
      "y": 8,
      "z": 2,
      "name": "Rock_Basalt"
    },
    {
      "x": -5,
      "y": 9,
      "z": 2,
      "name": "Rock_Basalt"
    },
    {
      "x": -5,
      "y": 10,
      "z": 2,
      "name": "Soil_Dirt_Burnt"
    },
    {
      "x": -5,
      "y": 11,
      "z": 2,
      "name": "Soil_Dirt_Burnt"
    },
    {
      "x": -5,
      "y": 12,
      "z": 2,
      "name": "Soil_Dirt_Burnt"
    },
    {
      "x": -5,
      "y": 14,
      "z": 2,
      "name": "Empty"
    },
    {
      "x": -5,
      "y": 15,
      "z": 2,
      "name": "Empty"
    },
    {
      "x": -5,
      "y": 16,
      "z": 2,
      "name": "Empty"
    },
    {
      "x": -5,
      "y": 17,
      "z": 2,
      "name": "Empty"
    },
    {
      "x": -5,
      "y": 18,
      "z": 2,
      "name": "Empty"
    },
    {
      "x": -5,
      "y": 19,
      "z": 2,
      "name": "Empty"
    },
    {
      "x": -5,
      "y": 2,
      "z": 3,
      "name": "Rock_Basalt"
    },
    {
      "x": -5,
      "y": 3,
      "z": 3,
      "name": "Rock_Basalt"
    },
    {
      "x": -5,
      "y": 4,
      "z": 3,
      "name": "Rock_Basalt"
    },
    {
      "x": -5,
      "y": 5,
      "z": 3,
      "name": "Rock_Basalt"
    },
    {
      "x": -5,
      "y": 6,
      "z": 3,
      "name": "Rock_Basalt"
    },
    {
      "x": -5,
      "y": 7,
      "z": 3,
      "name": "Rock_Basalt"
    },
    {
      "x": -5,
      "y": 8,
      "z": 3,
      "name": "Rock_Basalt"
    },
    {
      "x": -5,
      "y": 9,
      "z": 3,
      "name": "Rock_Basalt"
    },
    {
      "x": -5,
      "y": 10,
      "z": 3,
      "name": "Rock_Basalt"
    },
    {
      "x": -5,
      "y": 11,
      "z": 3,
      "name": "Soil_Dirt_Burnt"
    },
    {
      "x": -5,
      "y": 12,
      "z": 3,
      "name": "Soil_Dirt_Burnt"
    },
    {
      "x": -5,
      "y": 14,
      "z": 3,
      "name": "Empty"
    },
    {
      "x": -5,
      "y": 15,
      "z": 3,
      "name": "Empty"
    },
    {
      "x": -5,
      "y": 16,
      "z": 3,
      "name": "Empty"
    },
    {
      "x": -5,
      "y": 17,
      "z": 3,
      "name": "Empty"
    },
    {
      "x": -5,
      "y": 18,
      "z": 3,
      "name": "Empty"
    },
    {
      "x": -5,
      "y": 19,
      "z": 3,
      "name": "Empty"
    },
    {
      "x": -5,
      "y": 2,
      "z": 4,
      "name": "Rock_Basalt"
    },
    {
      "x": -5,
      "y": 3,
      "z": 4,
      "name": "Rock_Basalt"
    },
    {
      "x": -5,
      "y": 4,
      "z": 4,
      "name": "Rock_Basalt"
    },
    {
      "x": -5,
      "y": 5,
      "z": 4,
      "name": "Rock_Basalt"
    },
    {
      "x": -5,
      "y": 6,
      "z": 4,
      "name": "Rock_Basalt"
    },
    {
      "x": -5,
      "y": 7,
      "z": 4,
      "name": "Rock_Basalt"
    },
    {
      "x": -5,
      "y": 8,
      "z": 4,
      "name": "Rock_Basalt"
    },
    {
      "x": -5,
      "y": 9,
      "z": 4,
      "name": "Rock_Basalt"
    },
    {
      "x": -5,
      "y": 10,
      "z": 4,
      "name": "Rock_Basalt"
    },
    {
      "x": -5,
      "y": 11,
      "z": 4,
      "name": "Rock_Basalt"
    },
    {
      "x": -5,
      "y": 12,
      "z": 4,
      "name": "Soil_Dirt_Burnt"
    },
    {
      "x": -5,
      "y": 14,
      "z": 4,
      "name": "Empty"
    },
    {
      "x": -5,
      "y": 15,
      "z": 4,
      "name": "Empty"
    },
    {
      "x": -5,
      "y": 16,
      "z": 4,
      "name": "Empty"
    },
    {
      "x": -5,
      "y": 17,
      "z": 4,
      "name": "Empty"
    },
    {
      "x": -5,
      "y": 18,
      "z": 4,
      "name": "Empty"
    },
    {
      "x": -5,
      "y": 19,
      "z": 4,
      "name": "Empty"
    },
    {
      "x": -5,
      "y": 3,
      "z": 5,
      "name": "Rock_Basalt"
    },
    {
      "x": -5,
      "y": 4,
      "z": 5,
      "name": "Rock_Basalt"
    },
    {
      "x": -5,
      "y": 5,
      "z": 5,
      "name": "Rock_Basalt"
    },
    {
      "x": -5,
      "y": 6,
      "z": 5,
      "name": "Rock_Basalt"
    },
    {
      "x": -5,
      "y": 7,
      "z": 5,
      "name": "Rock_Basalt"
    },
    {
      "x": -5,
      "y": 8,
      "z": 5,
      "name": "Rock_Basalt"
    },
    {
      "x": -5,
      "y": 9,
      "z": 5,
      "name": "Rock_Basalt"
    },
    {
      "x": -5,
      "y": 10,
      "z": 5,
      "name": "Rock_Basalt"
    },
    {
      "x": -5,
      "y": 11,
      "z": 5,
      "name": "Rock_Basalt"
    },
    {
      "x": -5,
      "y": 12,
      "z": 5,
      "name": "Rock_Basalt"
    },
    {
      "x": -5,
      "y": 13,
      "z": 5,
      "name": "Rock_Basalt"
    },
    {
      "x": -5,
      "y": 14,
      "z": 5,
      "name": "Rock_Basalt"
    },
    {
      "x": -5,
      "y": 15,
      "z": 5,
      "name": "Rock_Basalt"
    },
    {
      "x": -5,
      "y": 16,
      "z": 5,
      "name": "Empty"
    },
    {
      "x": -5,
      "y": 17,
      "z": 5,
      "name": "Empty"
    },
    {
      "x": -5,
      "y": 18,
      "z": 5,
      "name": "Empty"
    },
    {
      "x": -5,
      "y": 19,
      "z": 5,
      "name": "Empty"
    },
    {
      "x": -5,
      "y": 5,
      "z": 6,
      "name": "Rock_Basalt"
    },
    {
      "x": -5,
      "y": 6,
      "z": 6,
      "name": "Rock_Basalt"
    },
    {
      "x": -5,
      "y": 7,
      "z": 6,
      "name": "Rock_Basalt"
    },
    {
      "x": -5,
      "y": 8,
      "z": 6,
      "name": "Rock_Basalt"
    },
    {
      "x": -5,
      "y": 9,
      "z": 6,
      "name": "Rock_Basalt"
    },
    {
      "x": -5,
      "y": 10,
      "z": 6,
      "name": "Rock_Basalt"
    },
    {
      "x": -5,
      "y": 11,
      "z": 6,
      "name": "Rock_Basalt"
    },
    {
      "x": -5,
      "y": 12,
      "z": 6,
      "name": "Rock_Basalt"
    },
    {
      "x": -5,
      "y": 13,
      "z": 6,
      "name": "Rock_Basalt"
    },
    {
      "x": -5,
      "y": 14,
      "z": 6,
      "name": "Rock_Basalt"
    },
    {
      "x": -5,
      "y": 15,
      "z": 6,
      "name": "Rock_Basalt"
    },
    {
      "x": -5,
      "y": 16,
      "z": 6,
      "name": "Empty"
    },
    {
      "x": -5,
      "y": 17,
      "z": 6,
      "name": "Empty"
    },
    {
      "x": -5,
      "y": 18,
      "z": 6,
      "name": "Empty"
    },
    {
      "x": -5,
      "y": 12,
      "z": 7,
      "name": "Rock_Basalt"
    },
    {
      "x": -4,
      "y": 9,
      "z": -8,
      "name": "Rock_Basalt"
    },
    {
      "x": -4,
      "y": 10,
      "z": -8,
      "name": "Rock_Basalt"
    },
    {
      "x": -4,
      "y": 11,
      "z": -8,
      "name": "Rock_Basalt"
    },
    {
      "x": -4,
      "y": 12,
      "z": -8,
      "name": "Rock_Basalt"
    },
    {
      "x": -4,
      "y": 13,
      "z": -8,
      "name": "Rock_Basalt"
    },
    {
      "x": -4,
      "y": 6,
      "z": -7,
      "name": "Rock_Basalt"
    },
    {
      "x": -4,
      "y": 7,
      "z": -7,
      "name": "Rock_Basalt"
    },
    {
      "x": -4,
      "y": 8,
      "z": -7,
      "name": "Rock_Basalt"
    },
    {
      "x": -4,
      "y": 9,
      "z": -7,
      "name": "Rock_Basalt"
    },
    {
      "x": -4,
      "y": 10,
      "z": -7,
      "name": "Rock_Basalt"
    },
    {
      "x": -4,
      "y": 11,
      "z": -7,
      "name": "Rock_Basalt"
    },
    {
      "x": -4,
      "y": 12,
      "z": -7,
      "name": "Rock_Basalt"
    },
    {
      "x": -4,
      "y": 13,
      "z": -7,
      "name": "Rock_Basalt"
    },
    {
      "x": -4,
      "y": 14,
      "z": -7,
      "name": "Rock_Basalt"
    },
    {
      "x": -4,
      "y": 15,
      "z": -7,
      "name": "Rock_Basalt"
    },
    {
      "x": -4,
      "y": 16,
      "z": -7,
      "name": "Rock_Basalt"
    },
    {
      "x": -4,
      "y": 3,
      "z": -6,
      "name": "Rock_Basalt"
    },
    {
      "x": -4,
      "y": 4,
      "z": -6,
      "name": "Rock_Basalt"
    },
    {
      "x": -4,
      "y": 5,
      "z": -6,
      "name": "Rock_Basalt"
    },
    {
      "x": -4,
      "y": 6,
      "z": -6,
      "name": "Rock_Basalt"
    },
    {
      "x": -4,
      "y": 7,
      "z": -6,
      "name": "Rock_Basalt"
    },
    {
      "x": -4,
      "y": 8,
      "z": -6,
      "name": "Rock_Basalt"
    },
    {
      "x": -4,
      "y": 9,
      "z": -6,
      "name": "Rock_Basalt"
    },
    {
      "x": -4,
      "y": 10,
      "z": -6,
      "name": "Rock_Basalt"
    },
    {
      "x": -4,
      "y": 11,
      "z": -6,
      "name": "Rock_Basalt"
    },
    {
      "x": -4,
      "y": 12,
      "z": -6,
      "name": "Rock_Basalt"
    },
    {
      "x": -4,
      "y": 13,
      "z": -6,
      "name": "Rock_Basalt"
    },
    {
      "x": -4,
      "y": 14,
      "z": -6,
      "name": "Rock_Basalt"
    },
    {
      "x": -4,
      "y": 15,
      "z": -6,
      "name": "Rock_Basalt"
    },
    {
      "x": -4,
      "y": 16,
      "z": -6,
      "name": "Rock_Basalt"
    },
    {
      "x": -4,
      "y": 17,
      "z": -6,
      "name": "Rock_Stone"
    },
    {
      "x": -4,
      "y": 18,
      "z": -6,
      "name": "Rock_Stone"
    },
    {
      "x": -4,
      "y": 2,
      "z": -5,
      "name": "Rock_Basalt"
    },
    {
      "x": -4,
      "y": 3,
      "z": -5,
      "name": "Rock_Basalt"
    },
    {
      "x": -4,
      "y": 4,
      "z": -5,
      "name": "Rock_Basalt"
    },
    {
      "x": -4,
      "y": 5,
      "z": -5,
      "name": "Rock_Basalt"
    },
    {
      "x": -4,
      "y": 6,
      "z": -5,
      "name": "Rock_Basalt"
    },
    {
      "x": -4,
      "y": 7,
      "z": -5,
      "name": "Rock_Basalt"
    },
    {
      "x": -4,
      "y": 8,
      "z": -5,
      "name": "Rock_Basalt"
    },
    {
      "x": -4,
      "y": 9,
      "z": -5,
      "name": "Rock_Basalt"
    },
    {
      "x": -4,
      "y": 10,
      "z": -5,
      "name": "Rock_Basalt"
    },
    {
      "x": -4,
      "y": 11,
      "z": -5,
      "name": "Rock_Basalt"
    },
    {
      "x": -4,
      "y": 12,
      "z": -5,
      "name": "Rock_Basalt"
    },
    {
      "x": -4,
      "y": 13,
      "z": -5,
      "name": "Plant_Crop_Mushroom_Block_Green"
    },
    {
      "x": -4,
      "y": 14,
      "z": -5,
      "name": "Rock_Basalt"
    },
    {
      "x": -4,
      "y": 15,
      "z": -5,
      "name": "Empty"
    },
    {
      "x": -4,
      "y": 16,
      "z": -5,
      "name": "Empty"
    },
    {
      "x": -4,
      "y": 17,
      "z": -5,
      "name": "Rock_Stone"
    },
    {
      "x": -4,
      "y": 18,
      "z": -5,
      "name": "Rock_Stone"
    },
    {
      "x": -4,
      "y": 2,
      "z": -4,
      "name": "Rock_Basalt"
    },
    {
      "x": -4,
      "y": 3,
      "z": -4,
      "name": "Rock_Basalt"
    },
    {
      "x": -4,
      "y": 4,
      "z": -4,
      "name": "Rock_Basalt"
    },
    {
      "x": -4,
      "y": 5,
      "z": -4,
      "name": "Rock_Basalt"
    },
    {
      "x": -4,
      "y": 6,
      "z": -4,
      "name": "Rock_Basalt"
    },
    {
      "x": -4,
      "y": 7,
      "z": -4,
      "name": "Rock_Basalt"
    },
    {
      "x": -4,
      "y": 8,
      "z": -4,
      "name": "Rock_Basalt"
    },
    {
      "x": -4,
      "y": 9,
      "z": -4,
      "name": "Rock_Basalt"
    },
    {
      "x": -4,
      "y": 10,
      "z": -4,
      "name": "Rock_Basalt"
    },
    {
      "x": -4,
      "y": 11,
      "z": -4,
      "name": "Rock_Basalt"
    },
    {
      "x": -4,
      "y": 12,
      "z": -4,
      "name": "Rock_Stone"
    },
    {
      "x": -4,
      "y": 13,
      "z": -4,
      "name": "Plant_Crop_Mushroom_Block_Green"
    },
    {
      "x": -4,
      "y": 14,
      "z": -4,
      "name": "Soil_Grass_Deep"
    },
    {
      "x": -4,
      "y": 15,
      "z": -4,
      "name": "Plant_Flower_Bushy_Green"
    },
    {
      "x": -4,
      "y": 16,
      "z": -4,
      "name": "Empty"
    },
    {
      "x": -4,
      "y": 17,
      "z": -4,
      "name": "Empty"
    },
    {
      "x": -4,
      "y": 18,
      "z": -4,
      "name": "Rock_Stone"
    },
    {
      "x": -4,
      "y": 19,
      "z": -4,
      "name": "Plant_Moss_Rug_Green_Dark"
    },
    {
      "x": -4,
      "y": 2,
      "z": -3,
      "name": "Rock_Basalt"
    },
    {
      "x": -4,
      "y": 3,
      "z": -3,
      "name": "Rock_Basalt"
    },
    {
      "x": -4,
      "y": 4,
      "z": -3,
      "name": "Rock_Basalt"
    },
    {
      "x": -4,
      "y": 5,
      "z": -3,
      "name": "Rock_Basalt"
    },
    {
      "x": -4,
      "y": 6,
      "z": -3,
      "name": "Rock_Basalt"
    },
    {
      "x": -4,
      "y": 7,
      "z": -3,
      "name": "Rock_Basalt"
    },
    {
      "x": -4,
      "y": 8,
      "z": -3,
      "name": "Rock_Basalt"
    },
    {
      "x": -4,
      "y": 9,
      "z": -3,
      "name": "Rock_Basalt"
    },
    {
      "x": -4,
      "y": 10,
      "z": -3,
      "name": "Rock_Basalt"
    },
    {
      "x": -4,
      "y": 11,
      "z": -3,
      "name": "Rock_Basalt"
    },
    {
      "x": -4,
      "y": 12,
      "z": -3,
      "name": "Rock_Stone"
    },
    {
      "x": -4,
      "y": 13,
      "z": -3,
      "name": "Plant_Crop_Mushroom_Block_Green"
    },
    {
      "x": -4,
      "y": 14,
      "z": -3,
      "name": "Soil_Grass_Deep"
    },
    {
      "x": -4,
      "y": 15,
      "z": -3,
      "name": "Plant_Grass_Jungle_Short"
    },
    {
      "x": -4,
      "y": 16,
      "z": -3,
      "name": "Empty"
    },
    {
      "x": -4,
      "y": 17,
      "z": -3,
      "name": "Empty"
    },
    {
      "x": -4,
      "y": 18,
      "z": -3,
      "name": "Plant_Moss_Wall_Green_Dark"
    },
    {
      "x": -4,
      "y": 19,
      "z": -3,
      "name": "Empty"
    },
    {
      "x": -4,
      "y": 2,
      "z": -2,
      "name": "Rock_Basalt"
    },
    {
      "x": -4,
      "y": 3,
      "z": -2,
      "name": "Rock_Basalt"
    },
    {
      "x": -4,
      "y": 4,
      "z": -2,
      "name": "Rock_Basalt"
    },
    {
      "x": -4,
      "y": 5,
      "z": -2,
      "name": "Rock_Basalt"
    },
    {
      "x": -4,
      "y": 6,
      "z": -2,
      "name": "Rock_Basalt"
    },
    {
      "x": -4,
      "y": 7,
      "z": -2,
      "name": "Rock_Basalt"
    },
    {
      "x": -4,
      "y": 8,
      "z": -2,
      "name": "Rock_Basalt"
    },
    {
      "x": -4,
      "y": 9,
      "z": -2,
      "name": "Rock_Basalt"
    },
    {
      "x": -4,
      "y": 10,
      "z": -2,
      "name": "Rock_Basalt"
    },
    {
      "x": -4,
      "y": 11,
      "z": -2,
      "name": "Rock_Basalt"
    },
    {
      "x": -4,
      "y": 12,
      "z": -2,
      "name": "Soil_Dirt_Burnt"
    },
    {
      "x": -4,
      "y": 13,
      "z": -2,
      "name": "Plant_Crop_Mushroom_Block_Green"
    },
    {
      "x": -4,
      "y": 14,
      "z": -2,
      "name": "Soil_Grass_Deep"
    },
    {
      "x": -4,
      "y": 15,
      "z": -2,
      "name": "Plant_Fern_Jungle_Trunk"
    },
    {
      "x": -4,
      "y": 16,
      "z": -2,
      "name": "Plant_Fern_Jungle"
    },
    {
      "x": -4,
      "y": 17,
      "z": -2,
      "name": "Plant_Fern_Jungle",
      "filler": 1024
    },
    {
      "x": -4,
      "y": 18,
      "z": -2,
      "name": "Plant_Moss_Wall_Green_Dark",
      "rotation": 3
    },
    {
      "x": -4,
      "y": 19,
      "z": -2,
      "name": "Empty"
    },
    {
      "x": -4,
      "y": 2,
      "z": -1,
      "name": "Rock_Basalt"
    },
    {
      "x": -4,
      "y": 3,
      "z": -1,
      "name": "Rock_Basalt"
    },
    {
      "x": -4,
      "y": 4,
      "z": -1,
      "name": "Rock_Basalt"
    },
    {
      "x": -4,
      "y": 5,
      "z": -1,
      "name": "Rock_Basalt"
    },
    {
      "x": -4,
      "y": 6,
      "z": -1,
      "name": "Rock_Basalt"
    },
    {
      "x": -4,
      "y": 7,
      "z": -1,
      "name": "Rock_Basalt"
    },
    {
      "x": -4,
      "y": 8,
      "z": -1,
      "name": "Rock_Basalt"
    },
    {
      "x": -4,
      "y": 9,
      "z": -1,
      "name": "Rock_Basalt"
    },
    {
      "x": -4,
      "y": 10,
      "z": -1,
      "name": "Rock_Basalt"
    },
    {
      "x": -4,
      "y": 11,
      "z": -1,
      "name": "Soil_Dirt_Burnt"
    },
    {
      "x": -4,
      "y": 12,
      "z": -1,
      "name": "Soil_Dirt_Burnt"
    },
    {
      "x": -4,
      "y": 13,
      "z": -1,
      "name": "Soil_Grass_Deep"
    },
    {
      "x": -4,
      "y": 14,
      "z": -1,
      "name": "Plant_Grass_Jungle"
    },
    {
      "x": -4,
      "y": 15,
      "z": -1,
      "name": "Empty"
    },
    {
      "x": -4,
      "y": 16,
      "z": -1,
      "name": "Empty"
    },
    {
      "x": -4,
      "y": 17,
      "z": -1,
      "name": "Empty"
    },
    {
      "x": -4,
      "y": 18,
      "z": -1,
      "name": "Empty"
    },
    {
      "x": -4,
      "y": 19,
      "z": -1,
      "name": "Empty"
    },
    {
      "x": -4,
      "y": 1,
      "z": 0,
      "name": "Rock_Basalt"
    },
    {
      "x": -4,
      "y": 2,
      "z": 0,
      "name": "Rock_Basalt"
    },
    {
      "x": -4,
      "y": 3,
      "z": 0,
      "name": "Rock_Basalt"
    },
    {
      "x": -4,
      "y": 4,
      "z": 0,
      "name": "Rock_Basalt"
    },
    {
      "x": -4,
      "y": 5,
      "z": 0,
      "name": "Rock_Basalt"
    },
    {
      "x": -4,
      "y": 6,
      "z": 0,
      "name": "Rock_Basalt"
    },
    {
      "x": -4,
      "y": 7,
      "z": 0,
      "name": "Rock_Basalt"
    },
    {
      "x": -4,
      "y": 8,
      "z": 0,
      "name": "Rock_Basalt"
    },
    {
      "x": -4,
      "y": 9,
      "z": 0,
      "name": "Rock_Basalt"
    },
    {
      "x": -4,
      "y": 10,
      "z": 0,
      "name": "Rock_Basalt"
    },
    {
      "x": -4,
      "y": 11,
      "z": 0,
      "name": "Soil_Dirt_Burnt"
    },
    {
      "x": -4,
      "y": 12,
      "z": 0,
      "name": "Soil_Dirt_Burnt"
    },
    {
      "x": -4,
      "y": 14,
      "z": 0,
      "name": "Empty"
    },
    {
      "x": -4,
      "y": 15,
      "z": 0,
      "name": "Empty"
    },
    {
      "x": -4,
      "y": 16,
      "z": 0,
      "name": "Empty"
    },
    {
      "x": -4,
      "y": 17,
      "z": 0,
      "name": "Empty"
    },
    {
      "x": -4,
      "y": 18,
      "z": 0,
      "name": "Empty"
    },
    {
      "x": -4,
      "y": 19,
      "z": 0,
      "name": "Empty"
    },
    {
      "x": -4,
      "y": 1,
      "z": 1,
      "name": "Rock_Basalt"
    },
    {
      "x": -4,
      "y": 2,
      "z": 1,
      "name": "Rock_Basalt"
    },
    {
      "x": -4,
      "y": 3,
      "z": 1,
      "name": "Rock_Basalt"
    },
    {
      "x": -4,
      "y": 4,
      "z": 1,
      "name": "Rock_Basalt"
    },
    {
      "x": -4,
      "y": 5,
      "z": 1,
      "name": "Rock_Basalt"
    },
    {
      "x": -4,
      "y": 6,
      "z": 1,
      "name": "Rock_Basalt"
    },
    {
      "x": -4,
      "y": 7,
      "z": 1,
      "name": "Rock_Basalt"
    },
    {
      "x": -4,
      "y": 8,
      "z": 1,
      "name": "Rock_Basalt"
    },
    {
      "x": -4,
      "y": 9,
      "z": 1,
      "name": "Rock_Basalt"
    },
    {
      "x": -4,
      "y": 10,
      "z": 1,
      "name": "Soil_Dirt_Burnt"
    },
    {
      "x": -4,
      "y": 11,
      "z": 1,
      "name": "Soil_Dirt_Burnt"
    },
    {
      "x": -4,
      "y": 12,
      "z": 1,
      "name": "Soil_Dirt_Burnt"
    },
    {
      "x": -4,
      "y": 14,
      "z": 1,
      "name": "Empty"
    },
    {
      "x": -4,
      "y": 15,
      "z": 1,
      "name": "Empty"
    },
    {
      "x": -4,
      "y": 16,
      "z": 1,
      "name": "Empty"
    },
    {
      "x": -4,
      "y": 17,
      "z": 1,
      "name": "Empty"
    },
    {
      "x": -4,
      "y": 18,
      "z": 1,
      "name": "Empty"
    },
    {
      "x": -4,
      "y": 19,
      "z": 1,
      "name": "Empty"
    },
    {
      "x": -4,
      "y": 1,
      "z": 2,
      "name": "Rock_Basalt"
    },
    {
      "x": -4,
      "y": 2,
      "z": 2,
      "name": "Rock_Basalt"
    },
    {
      "x": -4,
      "y": 3,
      "z": 2,
      "name": "Rock_Basalt"
    },
    {
      "x": -4,
      "y": 4,
      "z": 2,
      "name": "Rock_Basalt"
    },
    {
      "x": -4,
      "y": 5,
      "z": 2,
      "name": "Rock_Basalt"
    },
    {
      "x": -4,
      "y": 6,
      "z": 2,
      "name": "Rock_Basalt"
    },
    {
      "x": -4,
      "y": 7,
      "z": 2,
      "name": "Rock_Basalt"
    },
    {
      "x": -4,
      "y": 8,
      "z": 2,
      "name": "Rock_Basalt"
    },
    {
      "x": -4,
      "y": 9,
      "z": 2,
      "name": "Rock_Basalt"
    },
    {
      "x": -4,
      "y": 10,
      "z": 2,
      "name": "Rock_Basalt"
    },
    {
      "x": -4,
      "y": 11,
      "z": 2,
      "name": "Soil_Dirt_Burnt"
    },
    {
      "x": -4,
      "y": 12,
      "z": 2,
      "name": "Soil_Dirt_Burnt"
    },
    {
      "x": -4,
      "y": 14,
      "z": 2,
      "name": "Empty"
    },
    {
      "x": -4,
      "y": 15,
      "z": 2,
      "name": "Empty"
    },
    {
      "x": -4,
      "y": 16,
      "z": 2,
      "name": "Empty"
    },
    {
      "x": -4,
      "y": 17,
      "z": 2,
      "name": "Empty"
    },
    {
      "x": -4,
      "y": 18,
      "z": 2,
      "name": "Empty"
    },
    {
      "x": -4,
      "y": 19,
      "z": 2,
      "name": "Empty"
    },
    {
      "x": -4,
      "y": 1,
      "z": 3,
      "name": "Rock_Basalt"
    },
    {
      "x": -4,
      "y": 2,
      "z": 3,
      "name": "Rock_Basalt"
    },
    {
      "x": -4,
      "y": 3,
      "z": 3,
      "name": "Rock_Basalt"
    },
    {
      "x": -4,
      "y": 4,
      "z": 3,
      "name": "Rock_Basalt"
    },
    {
      "x": -4,
      "y": 5,
      "z": 3,
      "name": "Rock_Basalt"
    },
    {
      "x": -4,
      "y": 6,
      "z": 3,
      "name": "Rock_Basalt"
    },
    {
      "x": -4,
      "y": 7,
      "z": 3,
      "name": "Rock_Basalt"
    },
    {
      "x": -4,
      "y": 8,
      "z": 3,
      "name": "Rock_Basalt"
    },
    {
      "x": -4,
      "y": 9,
      "z": 3,
      "name": "Rock_Basalt"
    },
    {
      "x": -4,
      "y": 10,
      "z": 3,
      "name": "Rock_Basalt"
    },
    {
      "x": -4,
      "y": 11,
      "z": 3,
      "name": "Soil_Dirt_Burnt"
    },
    {
      "x": -4,
      "y": 12,
      "z": 3,
      "name": "Soil_Dirt_Burnt"
    },
    {
      "x": -4,
      "y": 14,
      "z": 3,
      "name": "Empty"
    },
    {
      "x": -4,
      "y": 15,
      "z": 3,
      "name": "Empty"
    },
    {
      "x": -4,
      "y": 16,
      "z": 3,
      "name": "Empty"
    },
    {
      "x": -4,
      "y": 17,
      "z": 3,
      "name": "Empty"
    },
    {
      "x": -4,
      "y": 18,
      "z": 3,
      "name": "Empty"
    },
    {
      "x": -4,
      "y": 19,
      "z": 3,
      "name": "Empty"
    },
    {
      "x": -4,
      "y": 20,
      "z": 3,
      "name": "Empty"
    },
    {
      "x": -4,
      "y": 1,
      "z": 4,
      "name": "Rock_Basalt"
    },
    {
      "x": -4,
      "y": 2,
      "z": 4,
      "name": "Rock_Basalt"
    },
    {
      "x": -4,
      "y": 3,
      "z": 4,
      "name": "Rock_Basalt"
    },
    {
      "x": -4,
      "y": 4,
      "z": 4,
      "name": "Rock_Basalt"
    },
    {
      "x": -4,
      "y": 5,
      "z": 4,
      "name": "Rock_Basalt"
    },
    {
      "x": -4,
      "y": 6,
      "z": 4,
      "name": "Rock_Basalt"
    },
    {
      "x": -4,
      "y": 7,
      "z": 4,
      "name": "Rock_Basalt"
    },
    {
      "x": -4,
      "y": 8,
      "z": 4,
      "name": "Rock_Basalt"
    },
    {
      "x": -4,
      "y": 9,
      "z": 4,
      "name": "Rock_Basalt"
    },
    {
      "x": -4,
      "y": 10,
      "z": 4,
      "name": "Rock_Basalt"
    },
    {
      "x": -4,
      "y": 11,
      "z": 4,
      "name": "Soil_Dirt_Burnt"
    },
    {
      "x": -4,
      "y": 12,
      "z": 4,
      "name": "Soil_Dirt_Burnt"
    },
    {
      "x": -4,
      "y": 14,
      "z": 4,
      "name": "Empty"
    },
    {
      "x": -4,
      "y": 15,
      "z": 4,
      "name": "Empty"
    },
    {
      "x": -4,
      "y": 16,
      "z": 4,
      "name": "Plant_Moss_Wall_Green_Dark",
      "rotation": 2
    },
    {
      "x": -4,
      "y": 17,
      "z": 4,
      "name": "Empty"
    },
    {
      "x": -4,
      "y": 18,
      "z": 4,
      "name": "Empty"
    },
    {
      "x": -4,
      "y": 19,
      "z": 4,
      "name": "Empty"
    },
    {
      "x": -4,
      "y": 2,
      "z": 5,
      "name": "Rock_Basalt"
    },
    {
      "x": -4,
      "y": 3,
      "z": 5,
      "name": "Rock_Basalt"
    },
    {
      "x": -4,
      "y": 4,
      "z": 5,
      "name": "Rock_Basalt"
    },
    {
      "x": -4,
      "y": 5,
      "z": 5,
      "name": "Rock_Basalt"
    },
    {
      "x": -4,
      "y": 6,
      "z": 5,
      "name": "Rock_Basalt"
    },
    {
      "x": -4,
      "y": 7,
      "z": 5,
      "name": "Rock_Basalt"
    },
    {
      "x": -4,
      "y": 8,
      "z": 5,
      "name": "Rock_Basalt"
    },
    {
      "x": -4,
      "y": 9,
      "z": 5,
      "name": "Rock_Basalt"
    },
    {
      "x": -4,
      "y": 10,
      "z": 5,
      "name": "Rock_Basalt"
    },
    {
      "x": -4,
      "y": 11,
      "z": 5,
      "name": "Rock_Basalt"
    },
    {
      "x": -4,
      "y": 12,
      "z": 5,
      "name": "Rock_Basalt"
    },
    {
      "x": -4,
      "y": 13,
      "z": 5,
      "name": "Rock_Basalt"
    },
    {
      "x": -4,
      "y": 14,
      "z": 5,
      "name": "Rock_Basalt"
    },
    {
      "x": -4,
      "y": 15,
      "z": 5,
      "name": "Rock_Basalt"
    },
    {
      "x": -4,
      "y": 16,
      "z": 5,
      "name": "Rock_Basalt"
    },
    {
      "x": -4,
      "y": 17,
      "z": 5,
      "name": "Plant_Moss_Rug_Green_Dark"
    },
    {
      "x": -4,
      "y": 18,
      "z": 5,
      "name": "Empty"
    },
    {
      "x": -4,
      "y": 19,
      "z": 5,
      "name": "Empty"
    },
    {
      "x": -4,
      "y": 4,
      "z": 6,
      "name": "Rock_Basalt"
    },
    {
      "x": -4,
      "y": 5,
      "z": 6,
      "name": "Rock_Basalt"
    },
    {
      "x": -4,
      "y": 6,
      "z": 6,
      "name": "Rock_Basalt"
    },
    {
      "x": -4,
      "y": 7,
      "z": 6,
      "name": "Rock_Basalt"
    },
    {
      "x": -4,
      "y": 8,
      "z": 6,
      "name": "Rock_Basalt"
    },
    {
      "x": -4,
      "y": 9,
      "z": 6,
      "name": "Rock_Basalt"
    },
    {
      "x": -4,
      "y": 10,
      "z": 6,
      "name": "Rock_Basalt"
    },
    {
      "x": -4,
      "y": 11,
      "z": 6,
      "name": "Rock_Basalt"
    },
    {
      "x": -4,
      "y": 12,
      "z": 6,
      "name": "Rock_Basalt"
    },
    {
      "x": -4,
      "y": 13,
      "z": 6,
      "name": "Rock_Basalt"
    },
    {
      "x": -4,
      "y": 14,
      "z": 6,
      "name": "Rock_Basalt"
    },
    {
      "x": -4,
      "y": 15,
      "z": 6,
      "name": "Rock_Basalt"
    },
    {
      "x": -4,
      "y": 16,
      "z": 6,
      "name": "Rock_Basalt"
    },
    {
      "x": -4,
      "y": 17,
      "z": 6,
      "name": "Empty"
    },
    {
      "x": -4,
      "y": 18,
      "z": 6,
      "name": "Empty"
    },
    {
      "x": -4,
      "y": 19,
      "z": 6,
      "name": "Empty"
    },
    {
      "x": -4,
      "y": 10,
      "z": 7,
      "name": "Rock_Basalt"
    },
    {
      "x": -4,
      "y": 11,
      "z": 7,
      "name": "Rock_Basalt"
    },
    {
      "x": -4,
      "y": 12,
      "z": 7,
      "name": "Rock_Basalt"
    },
    {
      "x": -4,
      "y": 13,
      "z": 7,
      "name": "Rock_Basalt"
    },
    {
      "x": -4,
      "y": 14,
      "z": 7,
      "name": "Rock_Basalt"
    },
    {
      "x": -3,
      "y": 9,
      "z": -9,
      "name": "Rock_Basalt"
    },
    {
      "x": -3,
      "y": 10,
      "z": -9,
      "name": "Rock_Basalt"
    },
    {
      "x": -3,
      "y": 11,
      "z": -9,
      "name": "Rock_Basalt"
    },
    {
      "x": -3,
      "y": 12,
      "z": -9,
      "name": "Rock_Basalt"
    },
    {
      "x": -3,
      "y": 13,
      "z": -9,
      "name": "Rock_Basalt"
    },
    {
      "x": -3,
      "y": 14,
      "z": -9,
      "name": "Rock_Basalt"
    },
    {
      "x": -3,
      "y": 6,
      "z": -8,
      "name": "Rock_Basalt"
    },
    {
      "x": -3,
      "y": 7,
      "z": -8,
      "name": "Rock_Basalt"
    },
    {
      "x": -3,
      "y": 8,
      "z": -8,
      "name": "Rock_Basalt"
    },
    {
      "x": -3,
      "y": 9,
      "z": -8,
      "name": "Rock_Basalt"
    },
    {
      "x": -3,
      "y": 10,
      "z": -8,
      "name": "Rock_Basalt"
    },
    {
      "x": -3,
      "y": 11,
      "z": -8,
      "name": "Rock_Basalt"
    },
    {
      "x": -3,
      "y": 12,
      "z": -8,
      "name": "Rock_Basalt"
    },
    {
      "x": -3,
      "y": 13,
      "z": -8,
      "name": "Rock_Basalt"
    },
    {
      "x": -3,
      "y": 14,
      "z": -8,
      "name": "Rock_Basalt"
    },
    {
      "x": -3,
      "y": 4,
      "z": -7,
      "name": "Rock_Basalt"
    },
    {
      "x": -3,
      "y": 5,
      "z": -7,
      "name": "Rock_Basalt"
    },
    {
      "x": -3,
      "y": 6,
      "z": -7,
      "name": "Rock_Basalt"
    },
    {
      "x": -3,
      "y": 7,
      "z": -7,
      "name": "Rock_Basalt"
    },
    {
      "x": -3,
      "y": 8,
      "z": -7,
      "name": "Rock_Basalt"
    },
    {
      "x": -3,
      "y": 9,
      "z": -7,
      "name": "Rock_Basalt"
    },
    {
      "x": -3,
      "y": 10,
      "z": -7,
      "name": "Rock_Basalt"
    },
    {
      "x": -3,
      "y": 11,
      "z": -7,
      "name": "Rock_Basalt"
    },
    {
      "x": -3,
      "y": 12,
      "z": -7,
      "name": "Rock_Basalt"
    },
    {
      "x": -3,
      "y": 13,
      "z": -7,
      "name": "Rock_Basalt"
    },
    {
      "x": -3,
      "y": 14,
      "z": -7,
      "name": "Rock_Basalt"
    },
    {
      "x": -3,
      "y": 15,
      "z": -7,
      "name": "Rock_Basalt"
    },
    {
      "x": -3,
      "y": 16,
      "z": -7,
      "name": "Rock_Stone"
    },
    {
      "x": -3,
      "y": 17,
      "z": -7,
      "name": "Rock_Stone"
    },
    {
      "x": -3,
      "y": 3,
      "z": -6,
      "name": "Rock_Basalt"
    },
    {
      "x": -3,
      "y": 4,
      "z": -6,
      "name": "Rock_Basalt"
    },
    {
      "x": -3,
      "y": 5,
      "z": -6,
      "name": "Rock_Basalt"
    },
    {
      "x": -3,
      "y": 6,
      "z": -6,
      "name": "Rock_Basalt"
    },
    {
      "x": -3,
      "y": 7,
      "z": -6,
      "name": "Rock_Basalt"
    },
    {
      "x": -3,
      "y": 8,
      "z": -6,
      "name": "Rock_Basalt"
    },
    {
      "x": -3,
      "y": 9,
      "z": -6,
      "name": "Rock_Basalt"
    },
    {
      "x": -3,
      "y": 10,
      "z": -6,
      "name": "Rock_Basalt"
    },
    {
      "x": -3,
      "y": 11,
      "z": -6,
      "name": "Rock_Basalt"
    },
    {
      "x": -3,
      "y": 12,
      "z": -6,
      "name": "Rock_Basalt"
    },
    {
      "x": -3,
      "y": 13,
      "z": -6,
      "name": "Rock_Basalt"
    },
    {
      "x": -3,
      "y": 14,
      "z": -6,
      "name": "Rock_Basalt"
    },
    {
      "x": -3,
      "y": 15,
      "z": -6,
      "name": "Rock_Basalt"
    },
    {
      "x": -3,
      "y": 16,
      "z": -6,
      "name": "Rock_Stone"
    },
    {
      "x": -3,
      "y": 17,
      "z": -6,
      "name": "Rock_Stone"
    },
    {
      "x": -3,
      "y": 2,
      "z": -5,
      "name": "Rock_Basalt"
    },
    {
      "x": -3,
      "y": 3,
      "z": -5,
      "name": "Rock_Basalt"
    },
    {
      "x": -3,
      "y": 4,
      "z": -5,
      "name": "Rock_Basalt"
    },
    {
      "x": -3,
      "y": 5,
      "z": -5,
      "name": "Rock_Basalt"
    },
    {
      "x": -3,
      "y": 6,
      "z": -5,
      "name": "Rock_Basalt"
    },
    {
      "x": -3,
      "y": 7,
      "z": -5,
      "name": "Rock_Basalt"
    },
    {
      "x": -3,
      "y": 8,
      "z": -5,
      "name": "Rock_Basalt"
    },
    {
      "x": -3,
      "y": 9,
      "z": -5,
      "name": "Rock_Basalt"
    },
    {
      "x": -3,
      "y": 10,
      "z": -5,
      "name": "Rock_Basalt"
    },
    {
      "x": -3,
      "y": 11,
      "z": -5,
      "name": "Rock_Basalt"
    },
    {
      "x": -3,
      "y": 12,
      "z": -5,
      "name": "Rock_Basalt"
    },
    {
      "x": -3,
      "y": 13,
      "z": -5,
      "name": "Rock_Basalt"
    },
    {
      "x": -3,
      "y": 14,
      "z": -5,
      "name": "Rock_Basalt"
    },
    {
      "x": -3,
      "y": 15,
      "z": -5,
      "name": "Rock_Basalt"
    },
    {
      "x": -3,
      "y": 16,
      "z": -5,
      "name": "Rock_Basalt"
    },
    {
      "x": -3,
      "y": 17,
      "z": -5,
      "name": "Rock_Stone"
    },
    {
      "x": -3,
      "y": 18,
      "z": -5,
      "name": "Rock_Stone"
    },
    {
      "x": -3,
      "y": 19,
      "z": -5,
      "name": "Plant_Moss_Rug_Green_Dark"
    },
    {
      "x": -3,
      "y": 2,
      "z": -4,
      "name": "Rock_Basalt"
    },
    {
      "x": -3,
      "y": 3,
      "z": -4,
      "name": "Rock_Basalt"
    },
    {
      "x": -3,
      "y": 4,
      "z": -4,
      "name": "Rock_Basalt"
    },
    {
      "x": -3,
      "y": 5,
      "z": -4,
      "name": "Rock_Basalt"
    },
    {
      "x": -3,
      "y": 6,
      "z": -4,
      "name": "Rock_Basalt"
    },
    {
      "x": -3,
      "y": 7,
      "z": -4,
      "name": "Rock_Basalt"
    },
    {
      "x": -3,
      "y": 8,
      "z": -4,
      "name": "Rock_Basalt"
    },
    {
      "x": -3,
      "y": 9,
      "z": -4,
      "name": "Rock_Basalt"
    },
    {
      "x": -3,
      "y": 10,
      "z": -4,
      "name": "Rock_Basalt"
    },
    {
      "x": -3,
      "y": 11,
      "z": -4,
      "name": "Rock_Basalt"
    },
    {
      "x": -3,
      "y": 12,
      "z": -4,
      "name": "Rock_Basalt"
    },
    {
      "x": -3,
      "y": 13,
      "z": -4,
      "name": "Rock_Stone"
    },
    {
      "x": -3,
      "y": 14,
      "z": -4,
      "name": "Rock_Basalt"
    },
    {
      "x": -3,
      "y": 15,
      "z": -4,
      "name": "Rock_Basalt"
    },
    {
      "x": -3,
      "y": 16,
      "z": -4,
      "name": "Rock_Basalt"
    },
    {
      "x": -3,
      "y": 17,
      "z": -4,
      "name": "Rock_Basalt"
    },
    {
      "x": -3,
      "y": 18,
      "z": -4,
      "name": "Rock_Stone"
    },
    {
      "x": -3,
      "y": 19,
      "z": -4,
      "name": "Plant_Moss_Rug_Green_Dark"
    },
    {
      "x": -3,
      "y": 2,
      "z": -3,
      "name": "Rock_Basalt"
    },
    {
      "x": -3,
      "y": 3,
      "z": -3,
      "name": "Rock_Basalt"
    },
    {
      "x": -3,
      "y": 4,
      "z": -3,
      "name": "Rock_Basalt"
    },
    {
      "x": -3,
      "y": 5,
      "z": -3,
      "name": "Rock_Basalt"
    },
    {
      "x": -3,
      "y": 6,
      "z": -3,
      "name": "Rock_Basalt"
    },
    {
      "x": -3,
      "y": 7,
      "z": -3,
      "name": "Rock_Basalt"
    },
    {
      "x": -3,
      "y": 8,
      "z": -3,
      "name": "Rock_Basalt"
    },
    {
      "x": -3,
      "y": 9,
      "z": -3,
      "name": "Rock_Basalt"
    },
    {
      "x": -3,
      "y": 10,
      "z": -3,
      "name": "Rock_Basalt"
    },
    {
      "x": -3,
      "y": 11,
      "z": -3,
      "name": "Rock_Basalt"
    },
    {
      "x": -3,
      "y": 12,
      "z": -3,
      "name": "Rock_Basalt"
    },
    {
      "x": -3,
      "y": 13,
      "z": -3,
      "name": "Rock_Stone"
    },
    {
      "x": -3,
      "y": 14,
      "z": -3,
      "name": "Soil_Grass_Deep"
    },
    {
      "x": -3,
      "y": 15,
      "z": -3,
      "name": "Plant_Grass_Jungle_Short"
    },
    {
      "x": -3,
      "y": 16,
      "z": -3,
      "name": "Empty"
    },
    {
      "x": -3,
      "y": 17,
      "z": -3,
      "name": "Rock_Basalt"
    },
    {
      "x": -3,
      "y": 18,
      "z": -3,
      "name": "Rock_Basalt"
    },
    {
      "x": -3,
      "y": 19,
      "z": -3,
      "name": "Plant_Moss_Rug_Green_Dark"
    },
    {
      "x": -3,
      "y": 2,
      "z": -2,
      "name": "Rock_Basalt"
    },
    {
      "x": -3,
      "y": 3,
      "z": -2,
      "name": "Rock_Basalt"
    },
    {
      "x": -3,
      "y": 4,
      "z": -2,
      "name": "Rock_Basalt"
    },
    {
      "x": -3,
      "y": 5,
      "z": -2,
      "name": "Rock_Basalt"
    },
    {
      "x": -3,
      "y": 6,
      "z": -2,
      "name": "Rock_Basalt"
    },
    {
      "x": -3,
      "y": 7,
      "z": -2,
      "name": "Rock_Basalt"
    },
    {
      "x": -3,
      "y": 8,
      "z": -2,
      "name": "Rock_Basalt"
    },
    {
      "x": -3,
      "y": 9,
      "z": -2,
      "name": "Rock_Basalt"
    },
    {
      "x": -3,
      "y": 10,
      "z": -2,
      "name": "Rock_Basalt"
    },
    {
      "x": -3,
      "y": 11,
      "z": -2,
      "name": "Rock_Basalt"
    },
    {
      "x": -3,
      "y": 12,
      "z": -2,
      "name": "Rock_Basalt"
    },
    {
      "x": -3,
      "y": 13,
      "z": -2,
      "name": "Rock_Stone"
    },
    {
      "x": -3,
      "y": 14,
      "z": -2,
      "name": "Soil_Grass_Deep"
    },
    {
      "x": -3,
      "y": 15,
      "z": -2,
      "name": "Plant_Bush_Jungle"
    },
    {
      "x": -3,
      "y": 16,
      "z": -2,
      "name": "Empty"
    },
    {
      "x": -3,
      "y": 17,
      "z": -2,
      "name": "Empty"
    },
    {
      "x": -3,
      "y": 18,
      "z": -2,
      "name": "Rock_Basalt"
    },
    {
      "x": -3,
      "y": 19,
      "z": -2,
      "name": "Plant_Moss_Rug_Green_Dark"
    },
    {
      "x": -3,
      "y": 0,
      "z": -1,
      "name": "Rock_Basalt"
    },
    {
      "x": -3,
      "y": 1,
      "z": -1,
      "name": "Rock_Basalt"
    },
    {
      "x": -3,
      "y": 2,
      "z": -1,
      "name": "Rock_Basalt"
    },
    {
      "x": -3,
      "y": 3,
      "z": -1,
      "name": "Rock_Basalt"
    },
    {
      "x": -3,
      "y": 4,
      "z": -1,
      "name": "Rock_Basalt"
    },
    {
      "x": -3,
      "y": 5,
      "z": -1,
      "name": "Rock_Basalt"
    },
    {
      "x": -3,
      "y": 6,
      "z": -1,
      "name": "Rock_Basalt"
    },
    {
      "x": -3,
      "y": 7,
      "z": -1,
      "name": "Rock_Basalt"
    },
    {
      "x": -3,
      "y": 8,
      "z": -1,
      "name": "Rock_Basalt"
    },
    {
      "x": -3,
      "y": 9,
      "z": -1,
      "name": "Rock_Basalt"
    },
    {
      "x": -3,
      "y": 10,
      "z": -1,
      "name": "Rock_Basalt"
    },
    {
      "x": -3,
      "y": 11,
      "z": -1,
      "name": "Rock_Basalt"
    },
    {
      "x": -3,
      "y": 12,
      "z": -1,
      "name": "Rock_Basalt"
    },
    {
      "x": -3,
      "y": 13,
      "z": -1,
      "name": "Rock_Stone"
    },
    {
      "x": -3,
      "y": 14,
      "z": -1,
      "name": "Soil_Grass_Deep"
    },
    {
      "x": -3,
      "y": 15,
      "z": -1,
      "name": "Plant_Bush_Jungle"
    },
    {
      "x": -3,
      "y": 16,
      "z": -1,
      "name": "Empty"
    },
    {
      "x": -3,
      "y": 17,
      "z": -1,
      "name": "Empty"
    },
    {
      "x": -3,
      "y": 18,
      "z": -1,
      "name": "Plant_Moss_Wall_Green_Dark"
    },
    {
      "x": -3,
      "y": 19,
      "z": -1,
      "name": "Plant_Moss_Wall_Green_Dark",
      "rotation": 3
    },
    {
      "x": -3,
      "y": 0,
      "z": 0,
      "name": "Rock_Basalt"
    },
    {
      "x": -3,
      "y": 1,
      "z": 0,
      "name": "Rock_Basalt"
    },
