{
  "version": 8,
  "blockIdVersion": 8,
  "anchorX": 0,
  "anchorY": 0,
  "anchorZ": 0,
  "blocks": [
    {
      "x": -6,
      "y": -1,
      "z": 2,
      "name": "Rock_Stone"
    },
    {
      "x": -6,
      "y": 0,
      "z": 2,
      "name": "Rock_Stone"
    },
    {
      "x": -6,
      "y": 1,
      "z": 2,
      "name": "Rock_Stone"
    },
    {
      "x": -6,
      "y": 2,
      "z": 2,
      "name": "Rock_Stone"
    },
    {
      "x": -6,
      "y": 3,
      "z": 2,
      "name": "Rock_Stone"
    },
    {
      "x": -6,
      "y": 4,
      "z": 2,
      "name": "Rock_Stone"
    },
    {
      "x": -6,
      "y": 5,
      "z": 2,
      "name": "Rock_Stone"
    },
    {
      "x": -6,
      "y": 6,
      "z": 2,
      "name": "Rock_Stone"
    },
    {
      "x": -6,
      "y": 7,
      "z": 2,
      "name": "Rock_Stone"
    },
    {
      "x": -6,
      "y": 8,
      "z": 2,
      "name": "Rock_Stone"
    },
    {
      "x": -6,
      "y": -1,
      "z": 3,
      "name": "Rock_Stone"
    },
    {
      "x": -6,
      "y": 0,
      "z": 3,
      "name": "Rock_Stone"
    },
    {
      "x": -6,
      "y": 1,
      "z": 3,
      "name": "Rock_Stone"
    },
    {
      "x": -6,
      "y": 2,
      "z": 3,
      "name": "Empty"
    },
    {
      "x": -6,
      "y": 3,
      "z": 3,
      "name": "Empty"
    },
    {
      "x": -6,
      "y": 4,
      "z": 3,
      "name": "Empty"
    },
    {
      "x": -6,
      "y": 5,
      "z": 3,
      "name": "Empty"
    },
    {
      "x": -6,
      "y": 6,
      "z": 3,
      "name": "Empty"
    },
    {
      "x": -6,
      "y": 7,
      "z": 3,
      "name": "Rock_Stone"
    },
    {
      "x": -6,
      "y": 8,
      "z": 3,
      "name": "Rock_Stone"
    },
    {
      "x": -6,
      "y": -1,
      "z": 4,
      "name": "Rock_Stone"
    },
    {
      "x": -6,
      "y": 0,
      "z": 4,
      "name": "Rock_Stone"
    },
    {
      "x": -6,
      "y": 1,
      "z": 4,
      "name": "Empty"
    },
    {
      "x": -6,
      "y": 2,
      "z": 4,
      "name": "Empty"
    },
    {
      "x": -6,
      "y": 3,
      "z": 4,
      "name": "Empty"
    },
    {
      "x": -6,
      "y": 4,
      "z": 4,
      "name": "Empty"
    },
    {
      "x": -6,
      "y": 5,
      "z": 4,
      "name": "Empty"
    },
    {
      "x": -6,
      "y": 6,
      "z": 4,
      "name": "Wood_Softwood_Planks_Half",
      "rotation": 7
    },
    {
      "x": -6,
      "y": 7,
      "z": 4,
      "name": "Empty"
    },
    {
      "x": -6,
      "y": 8,
      "z": 4,
      "name": "Rock_Stone"
    },
    {
      "x": -6,
      "y": -1,
      "z": 5,
      "name": "Rock_Stone"
    },
    {
      "x": -6,
      "y": 0,
      "z": 5,
      "name": "Soil_Gravel"
    },
    {
      "x": -6,
      "y": 1,
      "z": 5,
      "name": "Empty"
    },
    {
      "x": -6,
      "y": 2,
      "z": 5,
      "name": "Empty"
    },
    {
      "x": -6,
      "y": 3,
      "z": 5,
      "name": "Empty"
    },
    {
      "x": -6,
      "y": 4,
      "z": 5,
      "name": "Empty"
    },
    {
      "x": -6,
      "y": 5,
      "z": 5,
      "name": "Empty"
    },
    {
      "x": -6,
      "y": 6,
      "z": 5,
      "name": "Empty"
    },
    {
      "x": -6,
      "y": 7,
      "z": 5,
      "name": "Empty"
    },
    {
      "x": -6,
      "y": 8,
      "z": 5,
      "name": "Rock_Stone"
    },
    {
      "x": -6,
      "y": -1,
      "z": 6,
      "name": "Rock_Stone"
    },
    {
      "x": -6,
      "y": 0,
      "z": 6,
      "name": "Soil_Gravel"
    },
    {
      "x": -6,
      "y": 1,
      "z": 6,
      "name": "Rail",
      "rotation": 1
    },
    {
      "x": -6,
      "y": 2,
      "z": 6,
      "name": "Empty"
    },
    {
      "x": -6,
      "y": 3,
      "z": 6,
      "name": "Empty"
    },
    {
      "x": -6,
      "y": 4,
      "z": 6,
      "name": "Empty"
    },
    {
      "x": -6,
      "y": 5,
      "z": 6,
      "name": "Empty"
    },
    {
      "x": -6,
      "y": 6,
      "z": 6,
      "name": "Empty"
    },
    {
      "x": -6,
      "y": 7,
      "z": 6,
      "name": "Empty"
    },
    {
      "x": -6,
      "y": 8,
      "z": 6,
      "name": "Rock_Stone"
    },
    {
      "x": -6,
      "y": -1,
      "z": 7,
      "name": "Rock_Stone"
    },
    {
      "x": -6,
      "y": 0,
      "z": 7,
      "name": "Soil_Gravel"
    },
    {
      "x": -6,
      "y": 1,
      "z": 7,
      "name": "Empty"
    },
    {
      "x": -6,
      "y": 2,
      "z": 7,
      "name": "Empty"
    },
    {
      "x": -6,
      "y": 3,
      "z": 7,
      "name": "Empty"
    },
    {
      "x": -6,
      "y": 4,
      "z": 7,
      "name": "Empty"
    },
    {
      "x": -6,
      "y": 5,
      "z": 7,
      "name": "Empty"
    },
    {
      "x": -6,
      "y": 6,
      "z": 7,
      "name": "Empty"
    },
    {
      "x": -6,
      "y": 7,
      "z": 7,
      "name": "Empty"
    },
    {
      "x": -6,
      "y": 8,
      "z": 7,
      "name": "Rock_Stone"
    },
    {
      "x": -6,
      "y": -1,
      "z": 8,
      "name": "Rock_Stone"
    },
    {
      "x": -6,
      "y": 0,
      "z": 8,
      "name": "Rock_Stone"
    },
    {
      "x": -6,
      "y": 1,
      "z": 8,
      "name": "Empty"
    },
    {
      "x": -6,
      "y": 2,
      "z": 8,
      "name": "Empty"
    },
    {
      "x": -6,
      "y": 3,
      "z": 8,
      "name": "Empty"
    },
    {
      "x": -6,
      "y": 4,
      "z": 8,
      "name": "Empty"
    },
    {
      "x": -6,
      "y": 5,
      "z": 8,
      "name": "Empty"
    },
    {
      "x": -6,
      "y": 6,
      "z": 8,
      "name": "Empty"
    },
    {
      "x": -6,
      "y": 7,
      "z": 8,
      "name": "Rock_Stone"
    },
    {
      "x": -6,
      "y": 8,
      "z": 8,
      "name": "Rock_Stone"
    },
    {
      "x": -6,
      "y": -1,
      "z": 9,
      "name": "Rock_Stone"
    },
    {
      "x": -6,
      "y": 0,
      "z": 9,
      "name": "Rock_Stone"
    },
    {
      "x": -6,
      "y": 1,
      "z": 9,
      "name": "Empty"
    },
    {
      "x": -6,
      "y": 2,
      "z": 9,
      "name": "Empty"
    },
    {
      "x": -6,
      "y": 3,
      "z": 9,
      "name": "Empty"
    },
    {
      "x": -6,
      "y": 4,
      "z": 9,
      "name": "Empty"
    },
    {
      "x": -6,
      "y": 5,
      "z": 9,
      "name": "Empty"
    },
    {
      "x": -6,
      "y": 6,
      "z": 9,
      "name": "Wood_Softwood_Planks_Half",
      "rotation": 7
    },
    {
      "x": -6,
      "y": 7,
      "z": 9,
      "name": "Rock_Stone"
    },
    {
      "x": -6,
      "y": 8,
      "z": 9,
      "name": "Rock_Stone"
    },
    {
      "x": -6,
      "y": -1,
      "z": 10,
      "name": "Rock_Stone"
    },
    {
      "x": -6,
      "y": 0,
      "z": 10,
      "name": "Rock_Stone"
    },
    {
      "x": -6,
      "y": 1,
      "z": 10,
      "name": "Rock_Stone"
    },
    {
      "x": -6,
      "y": 2,
      "z": 10,
      "name": "Rock_Stone"
    },
    {
      "x": -6,
      "y": 3,
      "z": 10,
      "name": "Rock_Stone"
    },
    {
      "x": -6,
      "y": 4,
      "z": 10,
      "name": "Rock_Stone"
    },
    {
      "x": -6,
      "y": 5,
      "z": 10,
      "name": "Rock_Stone"
    },
    {
      "x": -6,
      "y": 6,
      "z": 10,
      "name": "Rock_Stone"
    },
    {
      "x": -6,
      "y": 7,
      "z": 10,
      "name": "Rock_Stone"
    },
    {
      "x": -6,
      "y": 8,
      "z": 10,
      "name": "Rock_Stone"
    },
    {
      "x": -5,
      "y": -1,
      "z": 2,
      "name": "Rock_Stone"
    },
    {
      "x": -5,
      "y": 0,
      "z": 2,
      "name": "Rock_Stone"
    },
    {
      "x": -5,
      "y": 1,
      "z": 2,
      "name": "Rock_Stone"
    },
    {
      "x": -5,
      "y": 2,
      "z": 2,
      "name": "Rock_Stone"
    },
    {
      "x": -5,
      "y": 3,
      "z": 2,
      "name": "Rock_Stone"
    },
    {
      "x": -5,
      "y": 4,
      "z": 2,
      "name": "Rock_Stone"
    },
    {
      "x": -5,
      "y": 5,
      "z": 2,
      "name": "Rock_Stone"
    },
    {
      "x": -5,
      "y": 6,
      "z": 2,
      "name": "Rock_Stone"
    },
    {
      "x": -5,
      "y": 7,
      "z": 2,
      "name": "Rock_Stone"
    },
    {
      "x": -5,
      "y": 8,
      "z": 2,
      "name": "Rock_Stone"
    },
    {
      "x": -5,
      "y": -1,
      "z": 3,
      "name": "Rock_Stone"
    },
    {
      "x": -5,
      "y": 0,
      "z": 3,
      "name": "Rock_Stone"
    },
    {
      "x": -5,
      "y": 1,
      "z": 3,
      "name": "Rock_Stone"
    },
    {
      "x": -5,
      "y": 2,
      "z": 3,
      "name": "Rock_Stone"
    },
    {
      "x": -5,
      "y": 3,
      "z": 3,
      "name": "Rock_Stone"
    },
    {
      "x": -5,
      "y": 4,
      "z": 3,
      "name": "Empty"
    },
    {
      "x": -5,
      "y": 5,
      "z": 3,
      "name": "Empty"
    },
    {
      "x": -5,
      "y": 6,
      "z": 3,
      "name": "Wood_Beech_Trunk",
      "rotation": 4
    },
    {
      "x": -5,
      "y": 7,
      "z": 3,
      "name": "Rock_Stone"
    },
    {
      "x": -5,
      "y": 8,
      "z": 3,
      "name": "Rock_Stone"
    },
    {
      "x": -5,
      "y": -1,
      "z": 4,
      "name": "Rock_Stone"
    },
    {
      "x": -5,
      "y": 0,
      "z": 4,
      "name": "Rock_Stone"
    },
    {
      "x": -5,
      "y": 1,
      "z": 4,
      "name": "Wood_Beech_Trunk"
    },
    {
      "x": -5,
      "y": 2,
      "z": 4,
      "name": "Wood_Beech_Trunk"
    },
    {
      "x": -5,
      "y": 3,
      "z": 4,
      "name": "Wood_Beech_Trunk"
    },
    {
      "x": -5,
      "y": 4,
      "z": 4,
      "name": "Wood_Beech_Trunk"
    },
    {
      "x": -5,
      "y": 5,
      "z": 4,
      "name": "Wood_Beech_Trunk"
    },
    {
      "x": -5,
      "y": 6,
      "z": 4,
      "name": "Wood_Beech_Trunk",
      "rotation": 4
    },
    {
      "x": -5,
      "y": 7,
      "z": 4,
      "name": "Empty"
    },
    {
      "x": -5,
      "y": 8,
      "z": 4,
      "name": "Rock_Stone"
    },
    {
      "x": -5,
      "y": -1,
      "z": 5,
      "name": "Rock_Stone"
    },
    {
      "x": -5,
      "y": 0,
      "z": 5,
      "name": "Rock_Stone"
    },
    {
      "x": -5,
      "y": 1,
      "z": 5,
      "name": "Empty"
    },
    {
      "x": -5,
      "y": 2,
      "z": 5,
      "name": "Empty"
    },
    {
      "x": -5,
      "y": 3,
      "z": 5,
      "name": "Empty"
    },
    {
      "x": -5,
      "y": 4,
      "z": 5,
      "name": "Empty"
    },
    {
      "x": -5,
      "y": 5,
      "z": 5,
      "name": "Empty"
    },
    {
      "x": -5,
      "y": 6,
      "z": 5,
      "name": "Wood_Beech_Trunk",
      "rotation": 4
    },
    {
      "x": -5,
      "y": 7,
      "z": 5,
      "name": "Empty"
    },
    {
      "x": -5,
      "y": 8,
      "z": 5,
      "name": "Rock_Stone"
    },
    {
      "x": -5,
      "y": -1,
      "z": 6,
      "name": "Rock_Stone"
    },
    {
      "x": -5,
      "y": 0,
      "z": 6,
      "name": "Soil_Gravel"
    },
    {
      "x": -5,
      "y": 1,
      "z": 6,
      "name": "Rail",
      "rotation": 1
    },
    {
      "x": -5,
      "y": 2,
      "z": 6,
      "name": "Empty"
    },
    {
      "x": -5,
      "y": 3,
      "z": 6,
      "name": "Empty"
    },
    {
      "x": -5,
      "y": 4,
      "z": 6,
      "name": "Empty"
    },
    {
      "x": -5,
      "y": 5,
      "z": 6,
      "name": "Empty"
    },
    {
      "x": -5,
      "y": 6,
      "z": 6,
      "name": "Wood_Beech_Trunk",
      "rotation": 4
    },
    {
      "x": -5,
      "y": 7,
      "z": 6,
      "name": "Empty"
    },
    {
      "x": -5,
      "y": 8,
      "z": 6,
      "name": "Rock_Stone"
    },
    {
      "x": -5,
      "y": -1,
      "z": 7,
      "name": "Rock_Stone"
    },
    {
      "x": -5,
      "y": 0,
      "z": 7,
      "name": "Soil_Gravel"
    },
    {
      "x": -5,
      "y": 1,
      "z": 7,
      "name": "Empty"
    },
    {
      "x": -5,
      "y": 2,
      "z": 7,
      "name": "Empty"
    },
    {
      "x": -5,
      "y": 3,
      "z": 7,
      "name": "Empty"
    },
    {
      "x": -5,
      "y": 4,
      "z": 7,
      "name": "Empty"
    },
    {
      "x": -5,
      "y": 5,
      "z": 7,
      "name": "Empty"
    },
    {
      "x": -5,
      "y": 6,
      "z": 7,
      "name": "Wood_Beech_Trunk",
      "rotation": 4
    },
    {
      "x": -5,
      "y": 7,
      "z": 7,
      "name": "Empty"
    },
    {
      "x": -5,
      "y": 8,
      "z": 7,
      "name": "Rock_Stone"
    },
    {
      "x": -5,
      "y": -1,
      "z": 8,
      "name": "Rock_Stone"
    },
    {
      "x": -5,
      "y": 0,
      "z": 8,
      "name": "Rock_Stone"
    },
    {
      "x": -5,
      "y": 1,
      "z": 8,
      "name": "Empty"
    },
    {
      "x": -5,
      "y": 2,
      "z": 8,
      "name": "Empty"
    },
    {
      "x": -5,
      "y": 3,
      "z": 8,
      "name": "Empty"
    },
    {
      "x": -5,
      "y": 4,
      "z": 8,
      "name": "Empty"
    },
    {
      "x": -5,
      "y": 5,
      "z": 8,
      "name": "Empty"
    },
    {
      "x": -5,
      "y": 6,
      "z": 8,
      "name": "Wood_Beech_Trunk",
      "rotation": 4
    },
    {
      "x": -5,
      "y": 7,
      "z": 8,
      "name": "Rock_Stone"
    },
    {
      "x": -5,
      "y": 8,
      "z": 8,
      "name": "Rock_Stone"
    },
    {
      "x": -5,
      "y": -1,
      "z": 9,
      "name": "Rock_Stone"
    },
    {
      "x": -5,
      "y": 0,
      "z": 9,
      "name": "Rock_Stone"
    },
    {
      "x": -5,
      "y": 1,
      "z": 9,
      "name": "Wood_Beech_Trunk"
    },
    {
      "x": -5,
      "y": 2,
      "z": 9,
      "name": "Wood_Beech_Trunk"
    },
    {
      "x": -5,
      "y": 3,
      "z": 9,
      "name": "Wood_Beech_Trunk"
    },
    {
      "x": -5,
      "y": 4,
      "z": 9,
      "name": "Wood_Beech_Trunk"
    },
    {
      "x": -5,
      "y": 5,
      "z": 9,
      "name": "Wood_Beech_Trunk"
    },
    {
      "x": -5,
      "y": 6,
      "z": 9,
      "name": "Wood_Beech_Trunk",
      "rotation": 4
    },
    {
      "x": -5,
      "y": 7,
      "z": 9,
      "name": "Rock_Stone"
    },
    {
      "x": -5,
      "y": 8,
      "z": 9,
      "name": "Rock_Stone"
    },
    {
      "x": -5,
      "y": -1,
      "z": 10,
      "name": "Rock_Stone"
    },
    {
      "x": -5,
      "y": 0,
      "z": 10,
      "name": "Rock_Stone"
    },
    {
      "x": -5,
      "y": 1,
      "z": 10,
      "name": "Rock_Stone"
    },
    {
      "x": -5,
      "y": 2,
      "z": 10,
      "name": "Rock_Stone"
    },
    {
      "x": -5,
      "y": 3,
      "z": 10,
      "name": "Rock_Stone"
    },
    {
      "x": -5,
      "y": 4,
      "z": 10,
      "name": "Rock_Stone"
    },
    {
      "x": -5,
      "y": 5,
      "z": 10,
      "name": "Rock_Stone"
    },
    {
      "x": -5,
      "y": 6,
      "z": 10,
      "name": "Rock_Stone"
    },
    {
      "x": -5,
      "y": 7,
      "z": 10,
      "name": "Rock_Stone"
    },
    {
      "x": -5,
      "y": 8,
      "z": 10,
      "name": "Rock_Stone"
    },
    {
      "x": -4,
      "y": -1,
      "z": 0,
      "name": "Rock_Stone"
    },
    {
      "x": -4,
      "y": 0,
      "z": 0,
      "name": "Rock_Stone"
    },
    {
      "x": -4,
      "y": 1,
      "z": 0,
      "name": "Rock_Stone"
    },
    {
      "x": -4,
      "y": 2,
      "z": 0,
      "name": "Rock_Stone"
    },
    {
      "x": -4,
      "y": 3,
      "z": 0,
      "name": "Rock_Stone"
    },
    {
      "x": -4,
      "y": 4,
      "z": 0,
      "name": "Rock_Stone"
    },
    {
      "x": -4,
      "y": 5,
      "z": 0,
      "name": "Rock_Stone"
    },
    {
      "x": -4,
      "y": 6,
      "z": 0,
      "name": "Rock_Stone"
    },
    {
      "x": -4,
      "y": 7,
      "z": 0,
      "name": "Rock_Stone"
    },
    {
      "x": -4,
      "y": 8,
      "z": 0,
      "name": "Rock_Stone"
    },
    {
      "x": -4,
      "y": -1,
      "z": 1,
      "name": "Rock_Stone"
    },
    {
      "x": -4,
      "y": 0,
      "z": 1,
      "name": "Rock_Stone"
    },
    {
      "x": -4,
      "y": 1,
      "z": 1,
      "name": "Rock_Stone"
    },
    {
      "x": -4,
      "y": 2,
      "z": 1,
      "name": "Rock_Stone"
    },
    {
      "x": -4,
      "y": 3,
      "z": 1,
      "name": "Rock_Stone"
    },
    {
      "x": -4,
      "y": 4,
      "z": 1,
      "name": "Rock_Stone"
    },
    {
      "x": -4,
      "y": 5,
      "z": 1,
      "name": "Rock_Stone"
    },
    {
      "x": -4,
      "y": 6,
      "z": 1,
      "name": "Rock_Stone"
    },
    {
      "x": -4,
      "y": 7,
      "z": 1,
      "name": "Rock_Stone"
    },
    {
      "x": -4,
      "y": 8,
      "z": 1,
      "name": "Rock_Stone"
    },
    {
      "x": -4,
      "y": -1,
      "z": 2,
      "name": "Rock_Stone"
    },
    {
      "x": -4,
      "y": 0,
      "z": 2,
      "name": "Rock_Stone"
    },
    {
      "x": -4,
      "y": 1,
      "z": 2,
      "name": "Rock_Stone"
    },
    {
      "x": -4,
      "y": 2,
      "z": 2,
      "name": "Rock_Stone"
    },
    {
      "x": -4,
      "y": 3,
      "z": 2,
      "name": "Rock_Stone"
    },
    {
      "x": -4,
      "y": 4,
      "z": 2,
      "name": "Rock_Stone"
    },
    {
      "x": -4,
      "y": 5,
      "z": 2,
      "name": "Rock_Stone"
    },
    {
      "x": -4,
      "y": 6,
      "z": 2,
      "name": "Rock_Stone"
    },
    {
      "x": -4,
      "y": 7,
      "z": 2,
      "name": "Rock_Stone"
    },
    {
      "x": -4,
      "y": 8,
      "z": 2,
      "name": "Rock_Stone"
    },
    {
      "x": -4,
      "y": -1,
      "z": 3,
      "name": "Rock_Stone"
    },
    {
      "x": -4,
      "y": 0,
      "z": 3,
      "name": "Rock_Stone"
    },
    {
      "x": -4,
      "y": 1,
      "z": 3,
      "name": "Rock_Stone_Cobble"
    },
    {
      "x": -4,
      "y": 2,
      "z": 3,
      "name": "Rock_Stone"
    },
    {
      "x": -4,
      "y": 3,
      "z": 3,
      "name": "Rock_Stone"
    },
    {
      "x": -4,
      "y": 4,
      "z": 3,
      "name": "Plant_Moss_Rug_Yellow"
    },
    {
      "x": -4,
      "y": 5,
      "z": 3,
      "name": "Empty"
    },
    {
      "x": -4,
      "y": 6,
      "z": 3,
      "name": "Empty"
    },
    {
      "x": -4,
      "y": 7,
      "z": 3,
      "name": "Rock_Stone"
    },
    {
      "x": -4,
      "y": 8,
      "z": 3,
      "name": "Rock_Stone"
    },
    {
      "x": -4,
      "y": -1,
      "z": 4,
      "name": "Rock_Stone"
    },
    {
      "x": -4,
      "y": 0,
      "z": 4,
      "name": "Rock_Stone"
    },
    {
      "x": -4,
      "y": 1,
      "z": 4,
      "name": "Rock_Stone_Cobble_Half",
      "rotation": 4
    },
    {
      "x": -4,
      "y": 2,
      "z": 4,
      "name": "Empty"
    },
    {
      "x": -4,
      "y": 3,
      "z": 4,
      "name": "Plant_Moss_Wall_Yellow"
    },
    {
      "x": -4,
      "y": 4,
      "z": 4,
      "name": "Empty"
    },
    {
      "x": -4,
      "y": 5,
      "z": 4,
      "name": "Empty"
    },
    {
      "x": -4,
      "y": 6,
      "z": 4,
      "name": "Wood_Softwood_Planks_Half",
      "rotation": 5
    },
    {
      "x": -4,
      "y": 7,
      "z": 4,
      "name": "Rock_Stone"
    },
    {
      "x": -4,
      "y": 8,
      "z": 4,
      "name": "Rock_Stone"
    },
    {
      "x": -4,
      "y": -1,
      "z": 5,
      "name": "Rock_Stone"
    },
    {
      "x": -4,
      "y": 0,
      "z": 5,
      "name": "Rock_Stone"
    },
    {
      "x": -4,
      "y": 1,
      "z": 5,
      "name": "Empty"
    },
    {
      "x": -4,
      "y": 2,
      "z": 5,
      "name": "Empty"
    },
    {
      "x": -4,
      "y": 3,
      "z": 5,
      "name": "Empty"
    },
    {
      "x": -4,
      "y": 4,
      "z": 5,
      "name": "Empty"
    },
    {
      "x": -4,
      "y": 5,
      "z": 5,
      "name": "Empty"
    },
    {
      "x": -4,
      "y": 6,
      "z": 5,
      "name": "Empty"
    },
    {
      "x": -4,
      "y": 7,
      "z": 5,
      "name": "Empty"
    },
    {
      "x": -4,
      "y": 8,
      "z": 5,
      "name": "Rock_Stone"
    },
    {
      "x": -4,
      "y": -1,
      "z": 6,
      "name": "Rock_Stone"
    },
    {
      "x": -4,
      "y": 0,
      "z": 6,
      "name": "Soil_Gravel"
    },
    {
      "x": -4,
      "y": 1,
      "z": 6,
      "name": "Rail",
      "rotation": 1
    },
    {
      "x": -4,
      "y": 2,
      "z": 6,
      "name": "Empty"
    },
    {
      "x": -4,
      "y": 3,
      "z": 6,
      "name": "Empty"
    },
    {
      "x": -4,
      "y": 4,
      "z": 6,
      "name": "Empty"
    },
    {
      "x": -4,
      "y": 5,
      "z": 6,
      "name": "Empty"
    },
    {
      "x": -4,
      "y": 6,
      "z": 6,
      "name": "Empty"
    },
    {
      "x": -4,
      "y": 7,
      "z": 6,
      "name": "Empty"
    },
    {
      "x": -4,
      "y": 8,
      "z": 6,
      "name": "Rock_Stone"
    },
    {
      "x": -4,
      "y": -1,
      "z": 7,
      "name": "Rock_Stone"
    },
    {
      "x": -4,
      "y": 0,
      "z": 7,
      "name": "Soil_Gravel"
    },
    {
      "x": -4,
      "y": 1,
      "z": 7,
      "name": "Empty"
    },
    {
      "x": -4,
      "y": 2,
      "z": 7,
      "name": "Empty"
    },
    {
      "x": -4,
      "y": 3,
      "z": 7,
      "name": "Empty"
    },
    {
      "x": -4,
      "y": 4,
      "z": 7,
      "name": "Empty"
    },
    {
      "x": -4,
      "y": 5,
      "z": 7,
      "name": "Empty"
    },
    {
      "x": -4,
      "y": 6,
      "z": 7,
      "name": "Empty"
    },
    {
      "x": -4,
      "y": 7,
      "z": 7,
      "name": "Empty"
    },
    {
      "x": -4,
      "y": 8,
      "z": 7,
      "name": "Rock_Stone"
    },
    {
      "x": -4,
      "y": -1,
      "z": 8,
      "name": "Rock_Stone"
    },
    {
      "x": -4,
      "y": 0,
      "z": 8,
      "name": "Rock_Stone"
    },
    {
      "x": -4,
      "y": 1,
      "z": 8,
      "name": "Empty"
    },
    {
      "x": -4,
      "y": 2,
      "z": 8,
      "name": "Empty"
    },
    {
      "x": -4,
      "y": 3,
      "z": 8,
      "name": "Empty"
    },
    {
      "x": -4,
      "y": 4,
      "z": 8,
      "name": "Empty"
    },
    {
      "x": -4,
      "y": 5,
      "z": 8,
      "name": "Empty"
    },
    {
      "x": -4,
      "y": 6,
      "z": 8,
      "name": "Empty"
    },
    {
      "x": -4,
      "y": 7,
      "z": 8,
      "name": "Rock_Stone"
    },
    {
      "x": -4,
      "y": 8,
      "z": 8,
      "name": "Rock_Stone"
    },
    {
      "x": -4,
      "y": -1,
      "z": 9,
      "name": "Rock_Stone"
    },
    {
      "x": -4,
      "y": 0,
      "z": 9,
      "name": "Rock_Stone"
    },
    {
      "x": -4,
      "y": 1,
      "z": 9,
      "name": "Empty"
    },
    {
      "x": -4,
      "y": 2,
      "z": 9,
      "name": "Empty"
    },
    {
      "x": -4,
      "y": 3,
      "z": 9,
      "name": "Empty"
    },
    {
      "x": -4,
      "y": 4,
      "z": 9,
      "name": "Empty"
    },
    {
      "x": -4,
      "y": 5,
      "z": 9,
      "name": "Empty"
    },
    {
      "x": -4,
      "y": 6,
      "z": 9,
      "name": "Wood_Softwood_Planks_Half",
      "rotation": 5
    },
    {
      "x": -4,
      "y": 7,
      "z": 9,
      "name": "Rock_Stone"
    },
    {
      "x": -4,
      "y": 8,
      "z": 9,
      "name": "Rock_Stone"
    },
    {
      "x": -4,
      "y": -1,
      "z": 10,
      "name": "Rock_Stone"
    },
    {
      "x": -4,
      "y": 0,
      "z": 10,
      "name": "Rock_Stone"
    },
    {
      "x": -4,
      "y": 1,
      "z": 10,
      "name": "Rock_Stone"
    },
    {
      "x": -4,
      "y": 2,
      "z": 10,
      "name": "Rock_Stone"
    },
    {
      "x": -4,
      "y": 3,
      "z": 10,
      "name": "Rock_Stone"
    },
    {
      "x": -4,
      "y": 4,
      "z": 10,
      "name": "Rock_Stone"
    },
    {
      "x": -4,
      "y": 5,
      "z": 10,
      "name": "Rock_Stone"
    },
    {
      "x": -4,
      "y": 6,
      "z": 10,
      "name": "Rock_Stone"
    },
    {
      "x": -4,
      "y": 7,
      "z": 10,
      "name": "Rock_Stone"
    },
    {
      "x": -4,
      "y": 8,
      "z": 10,
      "name": "Rock_Stone"
    },
    {
      "x": -3,
      "y": -1,
      "z": 0,
      "name": "Rock_Stone"
    },
    {
      "x": -3,
      "y": 0,
      "z": 0,
      "name": "Rock_Stone"
    },
    {
      "x": -3,
      "y": 1,
      "z": 0,
      "name": "Rock_Stone"
    },
    {
      "x": -3,
      "y": 2,
      "z": 0,
      "name": "Empty"
    },
    {
      "x": -3,
      "y": 3,
      "z": 0,
      "name": "Empty"
    },
    {
      "x": -3,
      "y": 4,
      "z": 0,
      "name": "Empty"
    },
    {
      "x": -3,
      "y": 5,
      "z": 0,
      "name": "Empty"
    },
    {
      "x": -3,
      "y": 6,
      "z": 0,
      "name": "Empty"
    },
    {
      "x": -3,
      "y": 7,
      "z": 0,
      "name": "Rock_Stone"
    },
    {
      "x": -3,
      "y": 8,
      "z": 0,
      "name": "Rock_Stone"
    },
    {
      "x": -3,
      "y": -1,
      "z": 1,
      "name": "Rock_Stone"
    },
    {
      "x": -3,
      "y": 0,
      "z": 1,
      "name": "Rock_Stone"
    },
    {
      "x": -3,
      "y": 1,
      "z": 1,
      "name": "Rock_Stone"
    },
    {
      "x": -3,
      "y": 2,
      "z": 1,
      "name": "Rock_Stone"
    },
    {
      "x": -3,
      "y": 3,
      "z": 1,
      "name": "Rock_Stone"
    },
    {
      "x": -3,
      "y": 4,
      "z": 1,
      "name": "Rock_Stone"
    },
    {
      "x": -3,
      "y": 5,
      "z": 1,
      "name": "Empty"
    },
    {
      "x": -3,
      "y": 6,
      "z": 1,
      "name": "Rock_Stone"
    },
    {
      "x": -3,
      "y": 7,
      "z": 1,
      "name": "Rock_Stone"
    },
    {
      "x": -3,
      "y": 8,
      "z": 1,
      "name": "Rock_Stone"
    },
    {
      "x": -3,
      "y": -1,
      "z": 2,
      "name": "Rock_Stone"
    },
    {
      "x": -3,
      "y": 0,
      "z": 2,
      "name": "Rock_Stone"
    },
    {
      "x": -3,
      "y": 1,
      "z": 2,
      "name": "Rock_Stone"
    },
    {
      "x": -3,
      "y": 2,
      "z": 2,
      "name": "Rock_Stone_Cobble"
    },
    {
      "x": -3,
      "y": 3,
      "z": 2,
      "name": "Rock_Stone"
    },
    {
      "x": -3,
      "y": 4,
      "z": 2,
      "name": "Rock_Stone"
    },
    {
      "x": -3,
      "y": 5,
      "z": 2,
      "name": "Rock_Stone"
    },
    {
      "x": -3,
      "y": 6,
      "z": 2,
      "name": "Rock_Stone"
    },
    {
      "x": -3,
      "y": 7,
      "z": 2,
      "name": "Rock_Stone"
    },
    {
      "x": -3,
      "y": 8,
      "z": 2,
      "name": "Rock_Stone"
    },
    {
      "x": -3,
      "y": -1,
      "z": 3,
      "name": "Rock_Stone"
    },
    {
      "x": -3,
      "y": 0,
      "z": 3,
      "name": "Rock_Stone"
    },
    {
      "x": -3,
      "y": 1,
      "z": 3,
      "name": "Rock_Stone_Cobble"
    },
    {
      "x": -3,
      "y": 2,
      "z": 3,
      "name": "Rock_Stone_Cobble"
    },
    {
      "x": -3,
      "y": 3,
      "z": 3,
      "name": "Plant_Moss_Yellow"
    },
    {
      "x": -3,
      "y": 4,
      "z": 3,
      "name": "Empty"
    },
    {
      "x": -3,
      "y": 5,
      "z": 3,
      "name": "Empty"
    },
    {
      "x": -3,
      "y": 6,
      "z": 3,
      "name": "Rock_Stone"
    },
    {
      "x": -3,
      "y": 7,
      "z": 3,
      "name": "Rock_Stone"
    },
    {
      "x": -3,
      "y": 8,
      "z": 3,
      "name": "Rock_Stone"
    },
    {
      "x": -3,
      "y": -1,
      "z": 4,
      "name": "Rock_Stone"
    },
    {
      "x": -3,
      "y": 0,
      "z": 4,
      "name": "Rock_Stone"
    },
    {
      "x": -3,
      "y": 1,
      "z": 4,
      "name": "Empty"
    },
    {
      "x": -3,
      "y": 2,
      "z": 4,
      "name": "Empty"
    },
    {
      "x": -3,
      "y": 3,
      "z": 4,
      "name": "Empty"
    },
    {
      "x": -3,
      "y": 4,
      "z": 4,
      "name": "Empty"
    },
    {
      "x": -3,
      "y": 5,
      "z": 4,
      "name": "Empty"
    },
    {
      "x": -3,
      "y": 6,
      "z": 4,
      "name": "Empty"
    },
    {
      "x": -3,
      "y": 7,
      "z": 4,
      "name": "Empty"
    },
    {
      "x": -3,
      "y": 8,
      "z": 4,
      "name": "Rock_Stone"
    },
    {
      "x": -3,
      "y": -1,
      "z": 5,
      "name": "Rock_Stone"
    },
    {
      "x": -3,
      "y": 0,
      "z": 5,
      "name": "Soil_Gravel"
    },
    {
      "x": -3,
      "y": 1,
      "z": 5,
      "name": "Empty"
    },
    {
      "x": -3,
      "y": 2,
      "z": 5,
      "name": "Empty"
    },
    {
      "x": -3,
      "y": 3,
      "z": 5,
      "name": "Empty"
    },
    {
      "x": -3,
      "y": 4,
      "z": 5,
      "name": "Empty"
    },
    {
      "x": -3,
      "y": 5,
      "z": 5,
      "name": "Empty"
    },
    {
      "x": -3,
      "y": 6,
      "z": 5,
      "name": "Empty"
    },
    {
      "x": -3,
      "y": 7,
      "z": 5,
      "name": "Empty"
    },
    {
      "x": -3,
      "y": 8,
      "z": 5,
      "name": "Rock_Stone"
    },
    {
      "x": -3,
      "y": -1,
      "z": 6,
      "name": "Rock_Stone"
    },
    {
      "x": -3,
      "y": 0,
      "z": 6,
      "name": "Soil_Gravel"
    },
    {
      "x": -3,
      "y": 1,
      "z": 6,
      "name": "Rail",
      "rotation": 1
    },
    {
      "x": -3,
      "y": 2,
      "z": 6,
      "name": "Empty"
    },
    {
      "x": -3,
      "y": 3,
      "z": 6,
      "name": "Empty"
    },
    {
      "x": -3,
      "y": 4,
      "z": 6,
      "name": "Empty"
    },
    {
      "x": -3,
      "y": 5,
      "z": 6,
      "name": "Empty"
    },
    {
      "x": -3,
      "y": 6,
      "z": 6,
      "name": "Empty"
    },
    {
      "x": -3,
      "y": 7,
      "z": 6,
      "name": "Empty"
    },
    {
      "x": -3,
      "y": 8,
      "z": 6,
      "name": "Rock_Stone"
    },
    {
      "x": -3,
      "y": -1,
      "z": 7,
      "name": "Rock_Stone"
    },
    {
      "x": -3,
      "y": 0,
      "z": 7,
      "name": "Soil_Gravel"
    },
    {
      "x": -3,
      "y": 1,
      "z": 7,
      "name": "Empty"
    },
    {
      "x": -3,
      "y": 2,
      "z": 7,
      "name": "Empty"
    },
    {
      "x": -3,
      "y": 3,
      "z": 7,
      "name": "Empty"
    },
    {
      "x": -3,
      "y": 4,
      "z": 7,
      "name": "Empty"
    },
    {
      "x": -3,
      "y": 5,
      "z": 7,
      "name": "Empty"
    },
    {
      "x": -3,
      "y": 6,
      "z": 7,
      "name": "Empty"
    },
    {
      "x": -3,
      "y": 7,
      "z": 7,
      "name": "Empty"
    },
    {
      "x": -3,
      "y": 8,
      "z": 7,
      "name": "Rock_Stone"
    },
    {
      "x": -3,
      "y": -1,
      "z": 8,
      "name": "Rock_Stone"
    },
    {
      "x": -3,
      "y": 0,
      "z": 8,
      "name": "Rock_Stone"
    },
    {
      "x": -3,
      "y": 1,
      "z": 8,
      "name": "Empty"
    },
    {
      "x": -3,
      "y": 2,
      "z": 8,
      "name": "Empty"
    },
    {
      "x": -3,
      "y": 3,
      "z": 8,
      "name": "Empty"
    },
    {
      "x": -3,
      "y": 4,
      "z": 8,
      "name": "Empty"
    },
    {
      "x": -3,
      "y": 5,
      "z": 8,
      "name": "Empty"
    },
    {
      "x": -3,
      "y": 6,
      "z": 8,
      "name": "Empty"
    },
    {
      "x": -3,
      "y": 7,
      "z": 8,
      "name": "Empty"
    },
    {
      "x": -3,
      "y": 8,
      "z": 8,
      "name": "Rock_Stone"
    },
    {
      "x": -3,
      "y": -1,
      "z": 9,
      "name": "Rock_Stone"
    },
    {
      "x": -3,
      "y": 0,
      "z": 9,
      "name": "Rock_Stone"
    },
    {
      "x": -3,
      "y": 1,
      "z": 9,
      "name": "Empty"
    },
    {
      "x": -3,
      "y": 2,
      "z": 9,
      "name": "Empty"
    },
    {
      "x": -3,
      "y": 3,
      "z": 9,
      "name": "Empty"
    },
    {
      "x": -3,
      "y": 4,
      "z": 9,
      "name": "Empty"
    },
    {
      "x": -3,
      "y": 5,
      "z": 9,
      "name": "Empty"
    },
    {
      "x": -3,
      "y": 6,
      "z": 9,
      "name": "Empty"
    },
    {
      "x": -3,
      "y": 7,
      "z": 9,
      "name": "Rock_Stone"
    },
    {
      "x": -3,
      "y": 8,
      "z": 9,
      "name": "Rock_Stone"
    },
    {
      "x": -3,
      "y": -1,
      "z": 10,
      "name": "Rock_Stone"
    },
    {
      "x": -3,
      "y": 0,
      "z": 10,
      "name": "Rock_Stone"
    },
    {
      "x": -3,
      "y": 1,
      "z": 10,
      "name": "Rock_Stone"
    },
    {
      "x": -3,
      "y": 2,
      "z": 10,
      "name": "Rock_Stone"
    },
    {
      "x": -3,
      "y": 3,
      "z": 10,
      "name": "Rock_Stone"
    },
    {
      "x": -3,
      "y": 4,
      "z": 10,
      "name": "Rock_Stone"
    },
    {
      "x": -3,
      "y": 5,
      "z": 10,
      "name": "Rock_Stone"
    },
    {
      "x": -3,
      "y": 6,
      "z": 10,
      "name": "Rock_Stone"
    },
    {
      "x": -3,
      "y": 7,
      "z": 10,
      "name": "Rock_Stone"
    },
    {
      "x": -3,
      "y": 8,
      "z": 10,
      "name": "Rock_Stone"
    },
    {
      "x": -2,
      "y": -1,
      "z": 0,
      "name": "Rock_Stone"
    },
    {
      "x": -2,
      "y": 0,
      "z": 0,
      "name": "Rock_Stone"
    },
    {
      "x": -2,
      "y": 1,
      "z": 0,
      "name": "Rubble_Stone"
    },
    {
      "x": -2,
      "y": 2,
      "z": 0,
      "name": "Empty"
    },
    {
      "x": -2,
      "y": 3,
      "z": 0,
      "name": "Empty"
    },
    {
      "x": -2,
      "y": 4,
      "z": 0,
      "name": "Empty"
    },
    {
      "x": -2,
      "y": 5,
      "z": 0,
      "name": "Empty"
    },
    {
      "x": -2,
      "y": 6,
      "z": 0,
      "name": "Empty"
    },
    {
      "x": -2,
      "y": 7,
      "z": 0,
      "name": "Rock_Stone"
    },
    {
      "x": -2,
      "y": 8,
      "z": 0,
      "name": "Rock_Stone"
    },
    {
      "x": -2,
      "y": -1,
      "z": 1,
      "name": "Rock_Stone"
    },
    {
      "x": -2,
      "y": 0,
      "z": 1,
      "name": "Rock_Stone"
    },
    {
      "x": -2,
      "y": 1,
      "z": 1,
      "name": "Rock_Stone"
    },
    {
      "x": -2,
      "y": 2,
      "z": 1,
      "name": "Rock_Stone"
    },
    {
      "x": -2,
      "y": 3,
      "z": 1,
      "name": "Empty"
    },
    {
      "x": -2,
      "y": 4,
      "z": 1,
      "name": "Empty"
    },
    {
      "x": -2,
      "y": 5,
      "z": 1,
      "name": "Empty"
    },
    {
      "x": -2,
      "y": 6,
      "z": 1,
      "name": "Empty"
    },
    {
      "x": -2,
      "y": 7,
      "z": 1,
      "name": "Rock_Stone"
    },
    {
      "x": -2,
      "y": 8,
      "z": 1,
      "name": "Rock_Stone"
    },
    {
      "x": -2,
      "y": -1,
      "z": 2,
      "name": "Rock_Stone"
    },
    {
      "x": -2,
      "y": 0,
      "z": 2,
      "name": "Rock_Stone"
    },
    {
      "x": -2,
      "y": 1,
      "z": 2,
      "name": "Rock_Stone"
    },
    {
      "x": -2,
      "y": 2,
      "z": 2,
      "name": "Rock_Stone_Cobble"
    },
    {
      "x": -2,
      "y": 3,
      "z": 2,
      "name": "Rock_Stone"
    },
    {
      "x": -2,
      "y": 4,
      "z": 2,
      "name": "Rock_Stone"
    },
    {
      "x": -2,
      "y": 5,
      "z": 2,
      "name": "Rock_Stone"
    },
    {
      "x": -2,
      "y": 6,
      "z": 2,
      "name": "Wood_Beech_Trunk",
      "rotation": 5
    },
    {
      "x": -2,
      "y": 7,
      "z": 2,
      "name": "Rock_Stone"
    },
    {
      "x": -2,
      "y": 8,
      "z": 2,
      "name": "Rock_Stone"
    },
    {
      "x": -2,
      "y": -1,
      "z": 3,
      "name": "Rock_Stone"
    },
    {
      "x": -2,
      "y": 0,
      "z": 3,
      "name": "Rock_Stone"
    },
    {
      "x": -2,
      "y": 1,
      "z": 3,
      "name": "Rock_Stone_Cobble"
    },
    {
      "x": -2,
      "y": 2,
      "z": 3,
      "name": "Rock_Stone_Cobble_Half"
    },
    {
      "x": -2,
      "y": 3,
      "z": 3,
      "name": "Empty"
    },
    {
      "x": -2,
      "y": 4,
      "z": 3,
      "name": "Empty"
    },
    {
      "x": -2,
      "y": 5,
      "z": 3,
      "name": "Empty"
    },
    {
      "x": -2,
      "y": 6,
      "z": 3,
      "name": "Rock_Stone"
    },
    {
      "x": -2,
      "y": 7,
      "z": 3,
      "name": "Rock_Stone"
    },
    {
      "x": -2,
      "y": 8,
      "z": 3,
      "name": "Rock_Stone"
    },
    {
      "x": -2,
      "y": -1,
      "z": 4,
      "name": "Rock_Stone"
    },
    {
      "x": -2,
      "y": 0,
      "z": 4,
      "name": "Rock_Stone"
    },
    {
      "x": -2,
      "y": 1,
      "z": 4,
      "name": "Empty"
    },
    {
      "x": -2,
      "y": 2,
      "z": 4,
      "name": "Empty"
    },
    {
      "x": -2,
      "y": 3,
      "z": 4,
      "name": "Empty"
    },
    {
      "x": -2,
      "y": 4,
      "z": 4,
      "name": "Empty"
    },
    {
      "x": -2,
      "y": 5,
      "z": 4,
      "name": "Empty"
    },
    {
      "x": -2,
      "y": 6,
      "z": 4,
      "name": "Empty"
    },
    {
      "x": -2,
      "y": 7,
      "z": 4,
      "name": "Empty"
    },
    {
      "x": -2,
      "y": 8,
      "z": 4,
      "name": "Rock_Stone"
    },
    {
      "x": -2,
      "y": -1,
      "z": 5,
      "name": "Rock_Stone"
    },
    {
      "x": -2,
      "y": 0,
      "z": 5,
      "name": "Soil_Gravel"
    },
    {
      "x": -2,
      "y": 1,
      "z": 5,
      "name": "Empty"
    },
    {
      "x": -2,
      "y": 2,
      "z": 5,
      "name": "Empty"
    },
    {
      "x": -2,
      "y": 3,
      "z": 5,
      "name": "Empty"
    },
    {
      "x": -2,
      "y": 4,
      "z": 5,
      "name": "Empty"
    },
    {
      "x": -2,
      "y": 5,
      "z": 5,
      "name": "Empty"
    },
    {
      "x": -2,
      "y": 6,
      "z": 5,
      "name": "Empty"
    },
    {
      "x": -2,
      "y": 7,
      "z": 5,
      "name": "Empty"
    },
    {
      "x": -2,
      "y": 8,
      "z": 5,
      "name": "Rock_Stone"
    },
    {
      "x": -2,
      "y": -1,
      "z": 6,
      "name": "Rock_Stone"
    },
    {
      "x": -2,
      "y": 0,
      "z": 6,
      "name": "Soil_Gravel"
    },
    {
      "x": -2,
      "y": 1,
      "z": 6,
      "name": "Rail",
      "rotation": 1
    },
    {
      "x": -2,
      "y": 2,
      "z": 6,
      "name": "Empty"
    },
    {
      "x": -2,
      "y": 3,
      "z": 6,
      "name": "Empty"
    },
    {
      "x": -2,
      "y": 4,
      "z": 6,
      "name": "Empty"
    },
    {
      "x": -2,
      "y": 5,
      "z": 6,
      "name": "Empty"
    },
    {
      "x": -2,
      "y": 6,
      "z": 6,
      "name": "Empty"
    },
    {
      "x": -2,
      "y": 7,
      "z": 6,
      "name": "Empty"
    },
    {
      "x": -2,
      "y": 8,
      "z": 6,
      "name": "Rock_Stone"
    },
    {
      "x": -2,
      "y": -1,
      "z": 7,
      "name": "Rock_Stone"
    },
    {
      "x": -2,
      "y": 0,
      "z": 7,
      "name": "Soil_Gravel"
    },
    {
      "x": -2,
      "y": 1,
      "z": 7,
      "name": "Empty"
    },
    {
      "x": -2,
      "y": 2,
      "z": 7,
      "name": "Empty"
    },
    {
      "x": -2,
      "y": 3,
      "z": 7,
      "name": "Empty"
    },
    {
      "x": -2,
      "y": 4,
      "z": 7,
      "name": "Empty"
    },
    {
      "x": -2,
      "y": 5,
      "z": 7,
      "name": "Empty"
    },
    {
      "x": -2,
      "y": 6,
      "z": 7,
      "name": "Empty"
    },
    {
      "x": -2,
      "y": 7,
      "z": 7,
      "name": "Empty"
    },
    {
      "x": -2,
      "y": 8,
      "z": 7,
      "name": "Rock_Stone"
    },
    {
      "x": -2,
      "y": -1,
      "z": 8,
      "name": "Rock_Stone"
    },
    {
      "x": -2,
      "y": 0,
      "z": 8,
      "name": "Rock_Stone"
    },
    {
      "x": -2,
      "y": 1,
      "z": 8,
      "name": "Wood_Softwood_Stairs",
      "rotation": 3
    },
    {
      "x": -2,
      "y": 2,
      "z": 8,
      "name": "Empty"
    },
    {
      "x": -2,
      "y": 3,
      "z": 8,
      "name": "Empty"
    },
    {
      "x": -2,
      "y": 4,
      "z": 8,
      "name": "Empty"
    },
    {
      "x": -2,
      "y": 5,
      "z": 8,
      "name": "Empty"
    },
    {
      "x": -2,
      "y": 6,
      "z": 8,
      "name": "Empty"
    },
    {
      "x": -2,
      "y": 7,
      "z": 8,
      "name": "Empty"
    },
    {
      "x": -2,
      "y": 8,
      "z": 8,
      "name": "Rock_Stone"
    },
    {
      "x": -2,
      "y": -1,
      "z": 9,
      "name": "Rock_Stone"
    },
    {
      "x": -2,
      "y": 0,
      "z": 9,
      "name": "Rock_Stone"
    },
    {
      "x": -2,
      "y": 1,
      "z": 9,
      "name": "Wood_Softwood_Stairs",
      "rotation": 3
    },
    {
      "x": -2,
      "y": 2,
      "z": 9,
      "name": "Empty"
    },
    {
      "x": -2,
      "y": 3,
      "z": 9,
      "name": "Empty"
    },
    {
      "x": -2,
      "y": 4,
      "z": 9,
      "name": "Empty"
    },
    {
      "x": -2,
      "y": 5,
      "z": 9,
      "name": "Empty"
    },
    {
      "x": -2,
      "y": 6,
      "z": 9,
      "name": "Empty"
    },
    {
      "x": -2,
      "y": 7,
      "z": 9,
      "name": "Empty"
    },
    {
      "x": -2,
      "y": 8,
      "z": 9,
      "name": "Rock_Stone"
    },
    {
      "x": -2,
      "y": -1,
      "z": 10,
      "name": "Rock_Stone"
    },
    {
      "x": -2,
      "y": 0,
      "z": 10,
      "name": "Rock_Stone"
    },
    {
      "x": -2,
      "y": 1,
      "z": 10,
      "name": "Rock_Stone"
    },
    {
      "x": -2,
      "y": 2,
      "z": 10,
      "name": "Rock_Stone"
    },
    {
      "x": -2,
      "y": 3,
      "z": 10,
      "name": "Rock_Stone"
    },
    {
      "x": -2,
      "y": 4,
      "z": 10,
      "name": "Rock_Stone"
    },
    {
      "x": -2,
      "y": 5,
      "z": 10,
      "name": "Rock_Stone"
    },
    {
      "x": -2,
      "y": 6,
      "z": 10,
      "name": "Rock_Stone"
    },
    {
      "x": -2,
      "y": 7,
      "z": 10,
      "name": "Rock_Stone"
    },
    {
      "x": -2,
      "y": 8,
      "z": 10,
      "name": "Rock_Stone"
    },
    {
      "x": -1,
      "y": -1,
      "z": 0,
      "name": "Rock_Stone"
    },
    {
      "x": -1,
      "y": 0,
      "z": 0,
      "name": "Rock_Stone"
    },
    {
      "x": -1,
      "y": 1,
      "z": 0,
      "name": "Empty"
    },
    {
      "x": -1,
      "y": 2,
      "z": 0,
      "name": "Empty"
    },
    {
      "x": -1,
      "y": 3,
      "z": 0,
      "name": "Empty"
    },
    {
      "x": -1,
      "y": 4,
      "z": 0,
      "name": "Empty"
    },
    {
      "x": -1,
      "y": 5,
      "z": 0,
      "name": "Empty"
    },
    {
      "x": -1,
      "y": 6,
      "z": 0,
      "name": "Empty"
    },
    {
      "x": -1,
      "y": 7,
      "z": 0,
      "name": "Empty"
    },
    {
      "x": -1,
      "y": 8,
      "z": 0,
      "name": "Rock_Stone"
    },
    {
      "x": -1,
      "y": -1,
      "z": 1,
      "name": "Rock_Stone"
    },
    {
      "x": -1,
      "y": 0,
      "z": 1,
      "name": "Rock_Stone"
    },
    {
      "x": -1,
      "y": 1,
      "z": 1,
      "name": "Empty"
    },
    {
      "x": -1,
      "y": 2,
      "z": 1,
      "name": "Empty"
    },
    {
      "x": -1,
      "y": 3,
      "z": 1,
      "name": "Empty"
    },
    {
      "x": -1,
      "y": 4,
      "z": 1,
      "name": "Empty"
    },
    {
      "x": -1,
      "y": 5,
      "z": 1,
      "name": "Empty"
    },
    {
      "x": -1,
      "y": 6,
      "z": 1,
      "name": "Wood_Softwood_Planks_Half",
      "rotation": 6
    },
    {
      "x": -1,
      "y": 7,
      "z": 1,
      "name": "Rock_Stone"
    },
    {
      "x": -1,
      "y": 8,
      "z": 1,
      "name": "Rock_Stone"
    },
    {
      "x": -1,
      "y": -1,
      "z": 2,
      "name": "Rock_Stone"
    },
    {
      "x": -1,
      "y": 0,
      "z": 2,
      "name": "Rock_Stone"
    },
    {
      "x": -1,
      "y": 1,
      "z": 2,
      "name": "Wood_Beech_Trunk"
    },
    {
      "x": -1,
      "y": 2,
      "z": 2,
      "name": "Wood_Beech_Trunk"
    },
    {
      "x": -1,
      "y": 3,
      "z": 2,
      "name": "Wood_Beech_Trunk"
    },
    {
      "x": -1,
      "y": 4,
      "z": 2,
      "name": "Wood_Beech_Trunk"
    },
    {
      "x": -1,
      "y": 5,
      "z": 2,
      "name": "Wood_Beech_Trunk"
    },
    {
      "x": -1,
      "y": 6,
      "z": 2,
      "name": "Wood_Beech_Trunk",
      "rotation": 5
    },
    {
      "x": -1,
      "y": 7,
      "z": 2,
      "name": "Rock_Stone"
    },
    {
      "x": -1,
      "y": 8,
      "z": 2,
      "name": "Rock_Stone"
    },
    {
      "x": -1,
      "y": -1,
      "z": 3,
      "name": "Rock_Stone"
    },
    {
      "x": -1,
      "y": 0,
      "z": 3,
      "name": "Rock_Stone"
    },
    {
      "x": -1,
      "y": 1,
      "z": 3,
      "name": "Empty"
    },
    {
      "x": -1,
      "y": 2,
      "z": 3,
      "name": "Empty"
    },
    {
      "x": -1,
      "y": 3,
      "z": 3,
      "name": "Empty"
    },
    {
      "x": -1,
      "y": 4,
      "z": 3,
      "name": "Empty"
    },
    {
      "x": -1,
      "y": 5,
      "z": 3,
      "name": "Empty"
    },
    {
      "x": -1,
      "y": 6,
      "z": 3,
      "name": "Wood_Softwood_Planks_Half",
      "rotation": 4
    },
    {
      "x": -1,
      "y": 7,
      "z": 3,
      "name": "Empty"
    },
    {
      "x": -1,
      "y": 8,
      "z": 3,
      "name": "Rock_Stone"
    },
    {
      "x": -1,
      "y": -1,
      "z": 4,
      "name": "Rock_Stone"
    },
    {
      "x": -1,
      "y": 0,
      "z": 4,
      "name": "Soil_Gravel"
    },
    {
      "x": -1,
      "y": 1,
      "z": 4,
      "name": "*Rail_State_Definitions_Corner_Left",
      "rotation": 1
    },
    {
      "x": -1,
      "y": 2,
      "z": 4,
      "name": "Empty"
    },
    {
      "x": -1,
      "y": 3,
      "z": 4,
      "name": "Empty"
    },
    {
      "x": -1,
      "y": 4,
      "z": 4,
      "name": "Empty"
    },
    {
      "x": -1,
      "y": 5,
      "z": 4,
      "name": "Empty"
    },
    {
      "x": -1,
      "y": 6,
      "z": 4,
      "name": "Empty"
    },
    {
      "x": -1,
      "y": 7,
      "z": 4,
      "name": "Empty"
    },
    {
      "x": -1,
      "y": 8,
      "z": 4,
      "name": "Rock_Stone"
    },
    {
      "x": -1,
      "y": -1,
      "z": 5,
      "name": "Rock_Stone"
    },
    {
      "x": -1,
      "y": 0,
      "z": 5,
      "name": "Soil_Gravel"
    },
    {
      "x": -1,
      "y": 1,
      "z": 5,
      "name": "Rail"
    },
    {
      "x": -1,
      "y": 2,
      "z": 5,
      "name": "Empty"
    },
    {
      "x": -1,
      "y": 3,
      "z": 5,
      "name": "Empty"
    },
    {
      "x": -1,
      "y": 4,
      "z": 5,
      "name": "Empty"
    },
    {
      "x": -1,
      "y": 5,
      "z": 5,
      "name": "Empty"
    },
    {
      "x": -1,
      "y": 6,
      "z": 5,
      "name": "Empty"
    },
    {
      "x": -1,
      "y": 7,
      "z": 5,
      "name": "Empty"
    },
    {
      "x": -1,
      "y": 8,
      "z": 5,
      "name": "Rock_Stone"
    },
    {
      "x": -1,
      "y": -1,
      "z": 6,
      "name": "Rock_Stone"
    },
    {
      "x": -1,
      "y": 0,
      "z": 6,
      "name": "Soil_Gravel"
    },
    {
      "x": -1,
      "y": 1,
      "z": 6,
      "name": "*Rail_State_Definitions_Corner_Left",
      "rotation": 3
    },
    {
      "x": -1,
      "y": 2,
      "z": 6,
      "name": "Empty"
    },
    {
      "x": -1,
      "y": 3,
      "z": 6,
      "name": "Empty"
    },
    {
      "x": -1,
      "y": 4,
      "z": 6,
      "name": "Empty"
    },
    {
      "x": -1,
      "y": 5,
      "z": 6,
      "name": "Empty"
    },
    {
      "x": -1,
      "y": 6,
      "z": 6,
      "name": "Empty"
    },
    {
      "x": -1,
      "y": 7,
      "z": 6,
      "name": "Empty"
    },
    {
      "x": -1,
      "y": 8,
      "z": 6,
      "name": "Rock_Stone"
    },
    {
      "x": -1,
      "y": -1,
      "z": 7,
      "name": "Rock_Stone"
    },
    {
      "x": -1,
      "y": 0,
      "z": 7,
      "name": "Rock_Stone"
    },
    {
      "x": -1,
      "y": 1,
      "z": 7,
      "name": "Empty"
    },
    {
      "x": -1,
      "y": 2,
      "z": 7,
      "name": "Empty"
    },
    {
      "x": -1,
      "y": 3,
      "z": 7,
      "name": "Empty"
    },
    {
      "x": -1,
      "y": 4,
      "z": 7,
      "name": "Empty"
    },
    {
      "x": -1,
      "y": 5,
      "z": 7,
      "name": "Empty"
    },
    {
      "x": -1,
      "y": 6,
      "z": 7,
      "name": "Empty"
    },
    {
      "x": -1,
      "y": 7,
      "z": 7,
      "name": "Empty"
    },
    {
      "x": -1,
      "y": 8,
      "z": 7,
      "name": "Rock_Stone"
    },
    {
      "x": -1,
      "y": -1,
      "z": 8,
      "name": "Rock_Stone"
    },
    {
      "x": -1,
      "y": 0,
      "z": 8,
      "name": "Rock_Stone"
    },
    {
      "x": -1,
      "y": 1,
      "z": 8,
      "name": "Rock_Stone"
    },
    {
      "x": -1,
      "y": 2,
      "z": 8,
      "name": "Wood_Softwood_Stairs",
      "rotation": 3
    },
    {
      "x": -1,
      "y": 3,
      "z": 8,
      "name": "Empty"
    },
    {
      "x": -1,
      "y": 4,
      "z": 8,
      "name": "Empty"
    },
    {
      "x": -1,
      "y": 5,
      "z": 8,
      "name": "Empty"
    },
    {
      "x": -1,
      "y": 6,
      "z": 8,
      "name": "Empty"
    },
    {
      "x": -1,
      "y": 7,
      "z": 8,
      "name": "Empty"
    },
    {
      "x": -1,
      "y": 8,
      "z": 8,
      "name": "Rock_Stone"
    },
    {
      "x": -1,
      "y": -1,
      "z": 9,
      "name": "Rock_Stone"
    },
    {
      "x": -1,
      "y": 0,
      "z": 9,
      "name": "Rock_Stone"
    },
    {
      "x": -1,
      "y": 1,
      "z": 9,
      "name": "Rock_Stone"
    },
    {
      "x": -1,
      "y": 2,
      "z": 9,
      "name": "Wood_Softwood_Stairs",
      "rotation": 3
    },
    {
      "x": -1,
      "y": 3,
      "z": 9,
      "name": "Empty"
    },
    {
      "x": -1,
      "y": 4,
      "z": 9,
      "name": "Empty"
    },
    {
      "x": -1,
      "y": 5,
      "z": 9,
      "name": "Empty"
    },
    {
      "x": -1,
      "y": 6,
      "z": 9,
      "name": "Empty"
    },
    {
      "x": -1,
      "y": 7,
      "z": 9,
      "name": "Empty"
    },
    {
      "x": -1,
      "y": 8,
      "z": 9,
      "name": "Rock_Stone"
    },
    {
      "x": -1,
      "y": -1,
      "z": 10,
      "name": "Rock_Stone"
    },
    {
      "x": -1,
      "y": 0,
      "z": 10,
      "name": "Rock_Stone"
    },
    {
      "x": -1,
      "y": 1,
      "z": 10,
      "name": "Rock_Stone"
    },
    {
      "x": -1,
      "y": 2,
      "z": 10,
      "name": "Rock_Stone"
    },
    {
      "x": -1,
      "y": 3,
      "z": 10,
      "name": "Rock_Stone"
    },
    {
      "x": -1,
      "y": 4,
      "z": 10,
      "name": "Rock_Stone"
    },
    {
      "x": -1,
      "y": 5,
      "z": 10,
      "name": "Rock_Stone"
    },
    {
      "x": -1,
      "y": 6,
      "z": 10,
      "name": "Rock_Stone"
    },
    {
      "x": -1,
      "y": 7,
      "z": 10,
      "name": "Rock_Stone"
    },
    {
      "x": -1,
      "y": 8,
      "z": 10,
      "name": "Rock_Stone"
    },
    {
      "x": 0,
      "y": -1,
      "z": 0,
      "name": "Rock_Stone"
    },
    {
      "x": 0,
      "y": 0,
      "z": 0,
      "name": "Rock_Stone"
    },
    {
      "x": 0,
      "y": 1,
      "z": 0,
      "name": "Rail"
    },
    {
      "x": 0,
      "y": 2,
      "z": 0,
      "name": "Empty"
    },
    {
      "x": 0,
      "y": 3,
      "z": 0,
      "name": "Empty"
    },
    {
      "x": 0,
      "y": 4,
      "z": 0,
      "name": "Empty"
    },
    {
      "x": 0,
      "y": 5,
      "z": 0,
      "name": "Empty"
    },
    {
      "x": 0,
      "y": 6,
      "z": 0,
      "name": "Empty"
    },
    {
      "x": 0,
      "y": 7,
      "z": 0,
      "name": "Empty"
    },
    {
      "x": 0,
      "y": 8,
      "z": 0,
      "name": "Rock_Stone"
    },
    {
      "x": 0,
      "y": -1,
      "z": 1,
      "name": "Rock_Stone"
    },
    {
      "x": 0,
      "y": 0,
      "z": 1,
      "name": "Rock_Stone"
    },
    {
      "x": 0,
      "y": 1,
      "z": 1,
      "name": "*Rail_State_Definitions_Corner_Left",
      "rotation": 2
    },
    {
      "x": 0,
      "y": 2,
      "z": 1,
      "name": "Empty"
    },
    {
      "x": 0,
      "y": 3,
      "z": 1,
      "name": "Empty"
    },
    {
      "x": 0,
      "y": 4,
      "z": 1,
      "name": "Empty"
    },
    {
      "x": 0,
      "y": 5,
      "z": 1,
      "name": "Empty"
    },
    {
      "x": 0,
      "y": 6,
      "z": 1,
      "name": "Empty"
    },
    {
      "x": 0,
      "y": 7,
      "z": 1,
      "name": "Empty"
    },
    {
      "x": 0,
      "y": 8,
      "z": 1,
      "name": "Rock_Stone"
    },
    {
      "x": 0,
      "y": -1,
      "z": 2,
      "name": "Rock_Stone"
    },
    {
      "x": 0,
      "y": 0,
      "z": 2,
      "name": "Soil_Gravel"
    },
    {
      "x": 0,
      "y": 1,
      "z": 2,
      "name": "Empty"
    },
    {
      "x": 0,
      "y": 2,
      "z": 2,
      "name": "Empty"
    },
    {
      "x": 0,
      "y": 3,
      "z": 2,
      "name": "Empty"
    },
    {
      "x": 0,
      "y": 4,
      "z": 2,
      "name": "Empty"
    },
    {
      "x": 0,
      "y": 5,
      "z": 2,
      "name": "Empty"
    },
    {
      "x": 0,
      "y": 6,
      "z": 2,
      "name": "Wood_Beech_Trunk",
      "rotation": 5
    },
    {
      "x": 0,
      "y": 7,
      "z": 2,
      "name": "Rock_Stone"
    },
    {
      "x": 0,
      "y": 8,
      "z": 2,
      "name": "Rock_Stone"
    },
    {
      "x": 0,
      "y": -1,
      "z": 3,
      "name": "Rock_Stone"
    },
    {
      "x": 0,
      "y": 0,
      "z": 3,
      "name": "Soil_Gravel"
    },
    {
      "x": 0,
      "y": 1,
      "z": 3,
      "name": "Empty"
    },
    {
      "x": 0,
      "y": 2,
      "z": 3,
      "name": "Empty"
    },
    {
      "x": 0,
      "y": 3,
      "z": 3,
      "name": "Empty"
    },
    {
      "x": 0,
      "y": 4,
      "z": 3,
      "name": "Empty"
    },
    {
      "x": 0,
      "y": 5,
      "z": 3,
      "name": "Empty"
    },
    {
      "x": 0,
      "y": 6,
      "z": 3,
      "name": "Empty"
    },
    {
      "x": 0,
      "y": 7,
      "z": 3,
      "name": "Empty"
    },
    {
      "x": 0,
      "y": 8,
      "z": 3,
      "name": "Rock_Stone"
    },
    {
      "x": 0,
      "y": -1,
      "z": 4,
      "name": "Rock_Stone"
    },
    {
      "x": 0,
      "y": 0,
      "z": 4,
      "name": "Soil_Gravel"
    },
    {
      "x": 0,
      "y": 1,
      "z": 4,
      "name": "Rail",
      "rotation": 1
    },
    {
      "x": 0,
      "y": 2,
      "z": 4,
      "name": "Empty"
    },
    {
      "x": 0,
      "y": 3,
      "z": 4,
      "name": "Empty"
    },
    {
      "x": 0,
      "y": 4,
      "z": 4,
      "name": "Empty"
    },
    {
      "x": 0,
      "y": 5,
      "z": 4,
      "name": "Empty"
    },
    {
      "x": 0,
      "y": 6,
      "z": 4,
      "name": "Empty"
    },
    {
      "x": 0,
      "y": 7,
      "z": 4,
      "name": "Empty"
    },
    {
      "x": 0,
      "y": 8,
      "z": 4,
      "name": "Rock_Stone"
    },
    {
      "x": 0,
      "y": -1,
      "z": 5,
      "name": "Rock_Stone"
    },
    {
      "x": 0,
      "y": 0,
      "z": 5,
      "name": "Soil_Gravel"
    },
    {
      "x": 0,
      "y": 1,
      "z": 5,
      "name": "Empty"
    },
    {
      "x": 0,
      "y": 2,
      "z": 5,
      "name": "Empty"
    },
    {
      "x": 0,
      "y": 3,
      "z": 5,
      "name": "Empty"
    },
    {
      "x": 0,
      "y": 4,
      "z": 5,
      "name": "Empty"
    },
    {
      "x": 0,
      "y": 5,
      "z": 5,
      "name": "Empty"
    },
    {
      "x": 0,
      "y": 6,
      "z": 5,
      "name": "Empty"
    },
    {
      "x": 0,
      "y": 7,
      "z": 5,
      "name": "Empty"
    },
    {
      "x": 0,
      "y": 8,
      "z": 5,
      "name": "Rock_Stone"
    },
    {
      "x": 0,
      "y": -1,
      "z": 6,
      "name": "Rock_Stone"
    },
    {
      "x": 0,
      "y": 0,
      "z": 6,
      "name": "Rock_Stone"
    },
    {
      "x": 0,
      "y": 1,
      "z": 6,
      "name": "Empty"
    },
    {
      "x": 0,
      "y": 2,
      "z": 6,
      "name": "Empty"
    },
    {
      "x": 0,
      "y": 3,
      "z": 6,
      "name": "Empty"
    },
    {
      "x": 0,
      "y": 4,
      "z": 6,
      "name": "Empty"
    },
    {
      "x": 0,
      "y": 5,
      "z": 6,
      "name": "Empty"
    },
    {
      "x": 0,
      "y": 6,
      "z": 6,
      "name": "Empty"
    },
    {
      "x": 0,
      "y": 7,
      "z": 6,
      "name": "Empty"
    },
    {
      "x": 0,
      "y": 8,
      "z": 6,
      "name": "Rock_Stone"
    },
    {
      "x": 0,
      "y": -1,
      "z": 7,
      "name": "Rock_Stone"
    },
    {
      "x": 0,
      "y": 0,
      "z": 7,
      "name": "Rock_Stone"
    },
    {
      "x": 0,
      "y": 1,
      "z": 7,
      "name": "Rock_Stone"
    },
    {
      "x": 0,
      "y": 2,
      "z": 7,
      "name": "Wood_Softwood_Planks"
    },
    {
      "x": 0,
      "y": 3,
      "z": 7,
      "name": "Empty"
    },
    {
      "x": 0,
      "y": 4,
      "z": 7,
      "name": "Empty"
    },
    {
      "x": 0,
      "y": 5,
      "z": 7,
      "name": "Empty"
    },
    {
      "x": 0,
      "y": 6,
      "z": 7,
      "name": "Empty"
    },
    {
      "x": 0,
      "y": 7,
      "z": 7,
      "name": "Empty"
    },
    {
      "x": 0,
      "y": 8,
      "z": 7,
      "name": "Rock_Stone"
    },
    {
      "x": 0,
      "y": -1,
      "z": 8,
      "name": "Rock_Stone"
    },
    {
      "x": 0,
      "y": 0,
      "z": 8,
      "name": "Rock_Stone"
    },
    {
      "x": 0,
      "y": 1,
      "z": 8,
      "name": "Rock_Stone"
    },
    {
      "x": 0,
      "y": 2,
      "z": 8,
      "name": "Wood_Softwood_Planks"
    },
    {
      "x": 0,
      "y": 3,
      "z": 8,
      "name": "Empty"
    },
    {
      "x": 0,
      "y": 4,
      "z": 8,
      "name": "Empty"
    },
    {
      "x": 0,
      "y": 5,
      "z": 8,
      "name": "Empty"
    },
    {
      "x": 0,
      "y": 6,
      "z": 8,
      "name": "Empty"
    },
    {
      "x": 0,
      "y": 7,
      "z": 8,
      "name": "Empty"
    },
    {
      "x": 0,
      "y": 8,
      "z": 8,
      "name": "Rock_Stone"
    },
    {
      "x": 0,
      "y": -1,
      "z": 9,
      "name": "Rock_Stone"
    },
    {
      "x": 0,
      "y": 0,
      "z": 9,
      "name": "Rock_Stone"
    },
    {
      "x": 0,
      "y": 1,
      "z": 9,
      "name": "Rock_Stone"
    },
    {
      "x": 0,
      "y": 2,
      "z": 9,
      "name": "Wood_Softwood_Planks"
    },
    {
      "x": 0,
      "y": 3,
      "z": 9,
      "name": "Empty"
    },
    {
      "x": 0,
      "y": 4,
      "z": 9,
      "name": "Empty"
    },
    {
      "x": 0,
      "y": 5,
      "z": 9,
      "name": "Empty"
    },
    {
      "x": 0,
      "y": 6,
      "z": 9,
      "name": "Empty"
    },
    {
      "x": 0,
      "y": 7,
      "z": 9,
      "name": "Empty"
    },
    {
      "x": 0,
      "y": 8,
      "z": 9,
      "name": "Rock_Stone"
    },
    {
      "x": 0,
      "y": -1,
      "z": 10,
      "name": "Rock_Stone"
    },
    {
      "x": 0,
      "y": 0,
      "z": 10,
      "name": "Rock_Stone"
    },
    {
      "x": 0,
      "y": 1,
      "z": 10,
      "name": "Rock_Stone"
    },
    {
      "x": 0,
      "y": 2,
      "z": 10,
      "name": "Rock_Stone"
    },
    {
      "x": 0,
      "y": 3,
      "z": 10,
      "name": "Rock_Stone"
    },
    {
      "x": 0,
      "y": 4,
      "z": 10,
      "name": "Rock_Stone"
    },
    {
      "x": 0,
      "y": 5,
      "z": 10,
      "name": "Rock_Stone"
    },
    {
      "x": 0,
      "y": 6,
      "z": 10,
      "name": "Rock_Stone"
    },
    {
      "x": 0,
      "y": 7,
      "z": 10,
      "name": "Rock_Stone"
    },
    {
      "x": 0,
      "y": 8,
      "z": 10,
      "name": "Rock_Stone"
    },
    {
      "x": 1,
      "y": -1,
      "z": 0,
      "name": "Rock_Stone"
    },
    {
      "x": 1,
      "y": 0,
      "z": 0,
      "name": "Soil_Gravel"
    },
    {
      "x": 1,
      "y": 1,
      "z": 0,
      "name": "Empty"
    },
    {
      "x": 1,
      "y": 2,
      "z": 0,
      "name": "Empty"
    },
    {
      "x": 1,
      "y": 3,
      "z": 0,
      "name": "Empty"
    },
    {
      "x": 1,
      "y": 4,
      "z": 0,
      "name": "Empty"
    },
    {
      "x": 1,
      "y": 5,
      "z": 0,
      "name": "Empty"
    },
    {
      "x": 1,
      "y": 6,
      "z": 0,
      "name": "Empty"
    },
    {
      "x": 1,
      "y": 7,
      "z": 0,
      "name": "Empty"
    },
    {
      "x": 1,
      "y": 8,
      "z": 0,
      "name": "Rock_Stone"
    },
    {
      "x": 1,
      "y": -1,
      "z": 1,
      "name": "Rock_Stone"
    },
    {
      "x": 1,
      "y": 0,
      "z": 1,
      "name": "Soil_Gravel"
    },
    {
      "x": 1,
      "y": 1,
      "z": 1,
      "name": "*Rail_State_Definitions_Corner_Left"
    },
    {
      "x": 1,
      "y": 2,
      "z": 1,
      "name": "Empty"
    },
    {
      "x": 1,
      "y": 3,
      "z": 1,
      "name": "Empty"
    },
    {
      "x": 1,
      "y": 4,
      "z": 1,
      "name": "Empty"
    },
    {
      "x": 1,
      "y": 5,
      "z": 1,
      "name": "Empty"
    },
    {
      "x": 1,
      "y": 6,
      "z": 1,
      "name": "Empty"
    },
    {
      "x": 1,
      "y": 7,
      "z": 1,
      "name": "Empty"
    },
    {
      "x": 1,
      "y": 8,
      "z": 1,
      "name": "Rock_Stone"
    },
    {
      "x": 1,
      "y": -1,
      "z": 2,
      "name": "Rock_Stone"
    },
    {
      "x": 1,
      "y": 0,
      "z": 2,
      "name": "Soil_Gravel"
    },
    {
      "x": 1,
      "y": 1,
      "z": 2,
      "name": "Rail"
    },
    {
      "x": 1,
      "y": 2,
      "z": 2,
      "name": "Empty"
    },
    {
      "x": 1,
      "y": 3,
      "z": 2,
      "name": "Empty"
    },
    {
      "x": 1,
      "y": 4,
      "z": 2,
      "name": "Empty"
    },
    {
      "x": 1,
      "y": 5,
      "z": 2,
      "name": "Empty"
    },
    {
      "x": 1,
      "y": 6,
      "z": 2,
      "name": "Wood_Beech_Trunk",
      "rotation": 5
    },
    {
      "x": 1,
      "y": 7,
      "z": 2,
      "name": "Empty"
    },
    {
      "x": 1,
      "y": 8,
      "z": 2,
      "name": "Rock_Stone"
    },
    {
      "x": 1,
      "y": -1,
      "z": 3,
      "name": "Rock_Stone"
    },
    {
      "x": 1,
      "y": 0,
      "z": 3,
      "name": "Soil_Gravel"
    },
    {
      "x": 1,
      "y": 1,
      "z": 3,
      "name": "Rail"
    },
    {
      "x": 1,
      "y": 2,
      "z": 3,
      "name": "Empty"
    },
    {
      "x": 1,
      "y": 3,
      "z": 3,
      "name": "Empty"
    },
    {
      "x": 1,
      "y": 4,
      "z": 3,
      "name": "Empty"
    },
    {
      "x": 1,
      "y": 5,
      "z": 3,
      "name": "Empty"
    },
    {
      "x": 1,
      "y": 6,
      "z": 3,
      "name": "Empty"
    },
    {
      "x": 1,
      "y": 7,
      "z": 3,
      "name": "Empty"
    },
    {
      "x": 1,
      "y": 8,
      "z": 3,
      "name": "Rock_Stone"
    },
    {
      "x": 1,
      "y": -1,
      "z": 4,
      "name": "Rock_Stone"
    },
    {
      "x": 1,
      "y": 0,
      "z": 4,
      "name": "Soil_Gravel"
    },
    {
      "x": 1,
      "y": 1,
      "z": 4,
      "name": "*Rail_State_Definitions_Corner_Left",
      "rotation": 3
    },
    {
      "x": 1,
      "y": 2,
      "z": 4,
      "name": "Empty"
    },
    {
      "x": 1,
      "y": 3,
      "z": 4,
      "name": "Empty"
    },
    {
      "x": 1,
      "y": 4,
      "z": 4,
      "name": "Empty"
    },
    {
      "x": 1,
      "y": 5,
      "z": 4,
      "name": "Empty"
    },
    {
      "x": 1,
      "y": 6,
      "z": 4,
      "name": "Empty"
    },
    {
      "x": 1,
      "y": 7,
      "z": 4,
      "name": "Empty"
    },
    {
      "x": 1,
      "y": 8,
      "z": 4,
      "name": "Rock_Stone"
    },
    {
      "x": 1,
      "y": -1,
      "z": 5,
      "name": "Rock_Stone"
    },
    {
      "x": 1,
      "y": 0,
      "z": 5,
      "name": "Rock_Stone"
    },
    {
      "x": 1,
      "y": 1,
      "z": 5,
      "name": "Empty"
    },
    {
      "x": 1,
      "y": 2,
      "z": 5,
      "name": "Empty"
    },
    {
      "x": 1,
      "y": 3,
      "z": 5,
      "name": "Empty"
    },
    {
      "x": 1,
      "y": 4,
      "z": 5,
      "name": "Empty"
    },
    {
      "x": 1,
      "y": 5,
      "z": 5,
      "name": "Empty"
    },
    {
      "x": 1,
      "y": 6,
      "z": 5,
      "name": "Empty"
    },
    {
      "x": 1,
      "y": 7,
      "z": 5,
      "name": "Empty"
    },
    {
      "x": 1,
      "y": 8,
      "z": 5,
      "name": "Rock_Stone"
    },
    {
      "x": 1,
      "y": -1,
      "z": 6,
      "name": "Rock_Stone"
    },
    {
      "x": 1,
      "y": 0,
      "z": 6,
      "name": "Rock_Stone"
    },
    {
      "x": 1,
      "y": 1,
      "z": 6,
      "name": "Wood_Beech_Branch_Long"
    },
    {
      "x": 1,
      "y": 2,
      "z": 6,
      "name": "Wood_Softwood_Planks"
    },
    {
      "x": 1,
      "y": 3,
      "z": 6,
      "name": "Wood_Softwood_Fence",
      "rotation": 2
    },
    {
      "x": 1,
      "y": 4,
      "z": 6,
      "name": "Empty"
    },
    {
      "x": 1,
      "y": 5,
      "z": 6,
      "name": "Empty"
    },
    {
      "x": 1,
      "y": 6,
      "z": 6,
      "name": "Empty"
    },
    {
      "x": 1,
      "y": 7,
      "z": 6,
      "name": "Empty"
    },
    {
      "x": 1,
      "y": 8,
      "z": 6,
      "name": "Rock_Stone"
    },
    {
      "x": 1,
      "y": -1,
      "z": 7,
      "name": "Rock_Stone"
    },
    {
      "x": 1,
      "y": 0,
      "z": 7,
      "name": "Rock_Stone"
    },
    {
      "x": 1,
      "y": 1,
      "z": 7,
      "name": "Rock_Stone"
    },
    {
      "x": 1,
      "y": 2,
      "z": 7,
      "name": "Wood_Softwood_Planks"
    },
    {
      "x": 1,
      "y": 3,
      "z": 7,
      "name": "Empty"
    },
    {
      "x": 1,
      "y": 4,
      "z": 7,
      "name": "Empty"
    },
    {
      "x": 1,
      "y": 5,
      "z": 7,
      "name": "Empty"
    },
    {
      "x": 1,
      "y": 6,
      "z": 7,
      "name": "Empty"
    },
    {
      "x": 1,
      "y": 7,
      "z": 7,
      "name": "Empty"
    },
    {
      "x": 1,
      "y": 8,
      "z": 7,
      "name": "Rock_Stone"
    },
    {
      "x": 1,
      "y": -1,
      "z": 8,
      "name": "Rock_Stone"
    },
    {
      "x": 1,
      "y": 0,
      "z": 8,
      "name": "Rock_Stone"
    },
    {
      "x": 1,
      "y": 1,
      "z": 8,
      "name": "Rock_Stone"
    },
    {
      "x": 1,
      "y": 2,
      "z": 8,
      "name": "Wood_Softwood_Planks"
    },
    {
      "x": 1,
      "y": 3,
      "z": 8,
      "name": "Empty"
    },
    {
      "x": 1,
      "y": 4,
      "z": 8,
      "name": "Empty"
    },
    {
      "x": 1,
      "y": 5,
      "z": 8,
      "name": "Empty"
    },
    {
      "x": 1,
      "y": 6,
      "z": 8,
      "name": "Empty"
    },
    {
      "x": 1,
      "y": 7,
      "z": 8,
      "name": "Empty"
    },
    {
      "x": 1,
      "y": 8,
      "z": 8,
      "name": "Rock_Stone"
    },
    {
      "x": 1,
      "y": -1,
      "z": 9,
      "name": "Rock_Stone"
    },
    {
      "x": 1,
      "y": 0,
      "z": 9,
      "name": "Rock_Stone"
    },
    {
      "x": 1,
      "y": 1,
      "z": 9,
      "name": "Rock_Stone"
    },
    {
      "x": 1,
      "y": 2,
      "z": 9,
      "name": "Wood_Softwood_Planks"
    },
    {
      "x": 1,
      "y": 3,
      "z": 9,
      "name": "Empty"
    },
    {
      "x": 1,
      "y": 4,
      "z": 9,
      "name": "Empty"
    },
    {
      "x": 1,
      "y": 5,
      "z": 9,
      "name": "Empty"
    },
    {
      "x": 1,
      "y": 6,
      "z": 9,
      "name": "Rock_Stone"
    },
    {
      "x": 1,
      "y": 7,
      "z": 9,
      "name": "Rock_Stone"
    },
    {
      "x": 1,
      "y": 8,
      "z": 9,
      "name": "Rock_Stone"
    },
    {
      "x": 1,
      "y": -1,
      "z": 10,
      "name": "Rock_Stone"
    },
    {
      "x": 1,
      "y": 0,
      "z": 10,
      "name": "Rock_Stone"
    },
    {
      "x": 1,
      "y": 1,
      "z": 10,
      "name": "Rock_Stone"
    },
    {
      "x": 1,
      "y": 2,
      "z": 10,
      "name": "Rock_Stone"
    },
    {
      "x": 1,
      "y": 3,
      "z": 10,
      "name": "Rock_Stone"
    },
    {
      "x": 1,
      "y": 4,
      "z": 10,
      "name": "Rock_Stone"
    },
    {
      "x": 1,
      "y": 5,
      "z": 10,
      "name": "Rock_Stone"
    },
    {
      "x": 1,
      "y": 6,
      "z": 10,
      "name": "Rock_Stone"
    },
    {
      "x": 1,
      "y": 7,
      "z": 10,
      "name": "Rock_Stone"
    },
    {
      "x": 1,
      "y": 8,
      "z": 10,
      "name": "Rock_Stone"
    },
    {
      "x": 2,
      "y": -1,
      "z": 0,
      "name": "Rock_Stone"
    },
    {
      "x": 2,
      "y": 0,
      "z": 0,
      "name": "Soil_Gravel"
    },
    {
      "x": 2,
      "y": 1,
      "z": 0,
      "name": "Empty"
    },
    {
      "x": 2,
      "y": 2,
      "z": 0,
      "name": "Empty"
    },
    {
      "x": 2,
      "y": 3,
      "z": 0,
      "name": "Empty"
    },
    {
      "x": 2,
      "y": 4,
      "z": 0,
      "name": "Empty"
    },
    {
      "x": 2,
      "y": 5,
      "z": 0,
      "name": "Empty"
    },
    {
      "x": 2,
      "y": 6,
      "z": 0,
      "name": "Empty"
    },
    {
      "x": 2,
      "y": 7,
      "z": 0,
      "name": "Empty"
    },
    {
      "x": 2,
      "y": 8,
      "z": 0,
      "name": "Rock_Stone"
    },
    {
      "x": 2,
      "y": -1,
      "z": 1,
      "name": "Rock_Stone"
    },
    {
      "x": 2,
      "y": 0,
      "z": 1,
      "name": "Soil_Gravel"
    },
    {
      "x": 2,
      "y": 1,
      "z": 1,
      "name": "Empty"
    },
    {
      "x": 2,
      "y": 2,
      "z": 1,
      "name": "Empty"
    },
    {
      "x": 2,
      "y": 3,
      "z": 1,
      "name": "Empty"
    },
    {
      "x": 2,
      "y": 4,
      "z": 1,
      "name": "Empty"
    },
    {
      "x": 2,
      "y": 5,
      "z": 1,
      "name": "Empty"
    },
    {
      "x": 2,
      "y": 6,
      "z": 1,
      "name": "Empty"
    },
    {
      "x": 2,
      "y": 7,
      "z": 1,
      "name": "Rock_Stone"
    },
    {
      "x": 2,
      "y": 8,
      "z": 1,
      "name": "Rock_Stone"
    },
    {
      "x": 2,
      "y": -1,
      "z": 2,
      "name": "Rock_Stone"
    },
    {
      "x": 2,
      "y": 0,
      "z": 2,
      "name": "Soil_Gravel"
    },
    {
      "x": 2,
      "y": 1,
      "z": 2,
      "name": "Empty"
    },
    {
      "x": 2,
      "y": 2,
      "z": 2,
      "name": "Empty"
    },
    {
      "x": 2,
      "y": 3,
      "z": 2,
      "name": "Empty"
    },
    {
      "x": 2,
      "y": 4,
      "z": 2,
      "name": "Empty"
    },
    {
      "x": 2,
      "y": 5,
      "z": 2,
      "name": "Empty"
    },
    {
      "x": 2,
      "y": 6,
      "z": 2,
      "name": "Wood_Beech_Trunk",
      "rotation": 5
    },
    {
      "x": 2,
      "y": 7,
      "z": 2,
      "name": "Rock_Stone"
    },
    {
      "x": 2,
      "y": 8,
      "z": 2,
      "name": "Rock_Stone"
    },
    {
      "x": 2,
      "y": -1,
      "z": 3,
      "name": "Rock_Stone"
    },
    {
      "x": 2,
      "y": 0,
      "z": 3,
      "name": "Soil_Gravel"
    },
    {
      "x": 2,
      "y": 1,
      "z": 3,
      "name": "Empty"
    },
    {
      "x": 2,
      "y": 2,
      "z": 3,
      "name": "Empty"
    },
    {
      "x": 2,
      "y": 3,
      "z": 3,
      "name": "Empty"
    },
    {
      "x": 2,
      "y": 4,
      "z": 3,
      "name": "Empty"
    },
    {
      "x": 2,
      "y": 5,
      "z": 3,
      "name": "Empty"
    },
    {
      "x": 2,
      "y": 6,
      "z": 3,
      "name": "Empty"
    },
    {
      "x": 2,
      "y": 7,
      "z": 3,
      "name": "Empty"
    },
    {
      "x": 2,
      "y": 8,
      "z": 3,
      "name": "Rock_Stone"
    },
    {
      "x": 2,
      "y": -1,
      "z": 4,
      "name": "Rock_Stone"
    },
    {
      "x": 2,
      "y": 0,
      "z": 4,
      "name": "Rock_Stone"
    },
    {
      "x": 2,
      "y": 1,
      "z": 4,
      "name": "Empty"
    },
    {
      "x": 2,
      "y": 2,
      "z": 4,
      "name": "Empty"
    },
    {
      "x": 2,
      "y": 3,
      "z": 4,
      "name": "Empty"
    },
    {
      "x": 2,
      "y": 4,
      "z": 4,
      "name": "Empty"
    },
    {
      "x": 2,
      "y": 5,
      "z": 4,
      "name": "Empty"
    },
    {
      "x": 2,
      "y": 6,
      "z": 4,
      "name": "Empty"
    },
    {
      "x": 2,
      "y": 7,
      "z": 4,
      "name": "Empty"
    },
    {
      "x": 2,
      "y": 8,
      "z": 4,
      "name": "Rock_Stone"
    },
    {
      "x": 2,
      "y": -1,
      "z": 5,
      "name": "Rock_Stone"
    },
    {
      "x": 2,
      "y": 0,
      "z": 5,
      "name": "Rock_Stone"
    },
    {
      "x": 2,
      "y": 1,
      "z": 5,
      "name": "Empty"
    },
    {
      "x": 2,
      "y": 2,
      "z": 5,
      "name": "Empty"
    },
    {
      "x": 2,
      "y": 3,
      "z": 5,
      "name": "Empty"
    },
    {
      "x": 2,
      "y": 4,
      "z": 5,
      "name": "Empty"
    },
    {
      "x": 2,
      "y": 5,
      "z": 5,
      "name": "Empty"
    },
    {
      "x": 2,
      "y": 6,
      "z": 5,
      "name": "Empty"
    },
    {
      "x": 2,
      "y": 7,
      "z": 5,
      "name": "Empty"
    },
    {
      "x": 2,
      "y": 8,
      "z": 5,
      "name": "Rock_Stone"
    },
    {
      "x": 2,
      "y": -1,
      "z": 6,
      "name": "Rock_Stone"
    },
    {
      "x": 2,
      "y": 0,
      "z": 6,
      "name": "Rock_Stone"
    },
    {
      "x": 2,
      "y": 1,
      "z": 6,
      "name": "Empty"
    },
    {
      "x": 2,
      "y": 2,
      "z": 6,
      "name": "Wood_Softwood_Planks"
    },
    {
      "x": 2,
      "y": 3,
      "z": 6,
      "name": "Wood_Softwood_Fence",
      "rotation": 2
    },
    {
      "x": 2,
      "y": 4,
      "z": 6,
      "name": "Empty"
    },
    {
      "x": 2,
      "y": 5,
      "z": 6,
      "name": "Empty"
    },
    {
      "x": 2,
      "y": 6,
      "z": 6,
      "name": "Empty"
    },
    {
      "x": 2,
      "y": 7,
      "z": 6,
      "name": "Empty"
    },
    {
      "x": 2,
      "y": 8,
      "z": 6,
      "name": "Rock_Stone"
    },
    {
      "x": 2,
      "y": -1,
      "z": 7,
      "name": "Rock_Stone"
    },
    {
      "x": 2,
      "y": 0,
      "z": 7,
      "name": "Rock_Stone"
    },
    {
      "x": 2,
      "y": 1,
      "z": 7,
      "name": "Rock_Stone"
    },
    {
      "x": 2,
      "y": 2,
      "z": 7,
      "name": "Wood_Softwood_Planks"
    },
    {
      "x": 2,
      "y": 3,
      "z": 7,
      "name": "Empty"
    },
    {
      "x": 2,
      "y": 4,
      "z": 7,
      "name": "Empty"
    },
    {
      "x": 2,
      "y": 5,
      "z": 7,
      "name": "Empty"
    },
    {
      "x": 2,
      "y": 6,
      "z": 7,
      "name": "Empty"
    },
    {
      "x": 2,
      "y": 7,
      "z": 7,
      "name": "Empty"
    },
    {
      "x": 2,
      "y": 8,
      "z": 7,
      "name": "Rock_Stone"
    },
    {
      "x": 2,
      "y": -1,
      "z": 8,
      "name": "Rock_Stone"
    },
    {
      "x": 2,
      "y": 0,
      "z": 8,
      "name": "Rock_Stone"
    },
    {
      "x": 2,
      "y": 1,
      "z": 8,
      "name": "Rock_Stone"
    },
    {
      "x": 2,
      "y": 2,
      "z": 8,
      "name": "Wood_Softwood_Planks"
    },
    {
      "x": 2,
      "y": 3,
      "z": 8,
      "name": "Furniture_Tavern_Barrel"
    },
    {
      "x": 2,
      "y": 4,
      "z": 8,
      "name": "Empty"
    },
    {
      "x": 2,
      "y": 5,
      "z": 8,
      "name": "Empty"
    },
    {
      "x": 2,
      "y": 6,
      "z": 8,
      "name": "Empty"
    },
    {
      "x": 2,
      "y": 7,
      "z": 8,
      "name": "Empty"
    },
    {
      "x": 2,
      "y": 8,
      "z": 8,
      "name": "Rock_Stone"
    },
    {
      "x": 2,
      "y": -1,
      "z": 9,
      "name": "Rock_Stone"
    },
    {
      "x": 2,
      "y": 0,
      "z": 9,
      "name": "Rock_Stone"
    },
    {
      "x": 2,
      "y": 1,
      "z": 9,
      "name": "Rock_Stone"
    },
    {
      "x": 2,
      "y": 2,
      "z": 9,
      "name": "Wood_Softwood_Planks"
    },
    {
      "x": 2,
      "y": 3,
      "z": 9,
      "name": "Empty"
    },
    {
      "x": 2,
      "y": 4,
      "z": 9,
      "name": "Rock_Stone"
    },
    {
      "x": 2,
      "y": 5,
      "z": 9,
      "name": "Rock_Stone"
    },
    {
      "x": 2,
      "y": 6,
      "z": 9,
      "name": "Rock_Stone"
    },
    {
      "x": 2,
      "y": 7,
      "z": 9,
      "name": "Rock_Stone"
    },
    {
      "x": 2,
      "y": 8,
      "z": 9,
      "name": "Rock_Stone"
    },
    {
      "x": 2,
      "y": -1,
      "z": 10,
      "name": "Rock_Stone"
    },
    {
      "x": 2,
      "y": 0,
      "z": 10,
      "name": "Rock_Stone"
    },
    {
      "x": 2,
      "y": 1,
      "z": 10,
      "name": "Rock_Stone"
    },
    {
      "x": 2,
      "y": 2,
      "z": 10,
      "name": "Rock_Stone"
    },
    {
      "x": 2,
      "y": 3,
      "z": 10,
      "name": "Rock_Stone"
    },
    {
      "x": 2,
      "y": 4,
      "z": 10,
      "name": "Rock_Stone"
    },
    {
      "x": 2,
      "y": 5,
      "z": 10,
      "name": "Rock_Stone"
    },
    {
      "x": 2,
      "y": 6,
      "z": 10,
      "name": "Rock_Stone"
    },
    {
      "x": 2,
      "y": 7,
      "z": 10,
      "name": "Rock_Stone"
    },
    {
      "x": 2,
      "y": 8,
      "z": 10,
      "name": "Rock_Stone"
    },
    {
      "x": 3,
      "y": -1,
      "z": 0,
      "name": "Rock_Stone"
    },
    {
      "x": 3,
      "y": 0,
      "z": 0,
      "name": "Rock_Stone"
    },
    {
      "x": 3,
      "y": 1,
      "z": 0,
      "name": "Empty"
    },
    {
      "x": 3,
      "y": 2,
      "z": 0,
      "name": "Empty"
    },
    {
      "x": 3,
      "y": 3,
      "z": 0,
      "name": "Empty"
    },
    {
      "x": 3,
      "y": 4,
      "z": 0,
      "name": "Empty"
    },
    {
      "x": 3,
      "y": 5,
      "z": 0,
      "name": "Empty"
    },
    {
      "x": 3,
      "y": 6,
      "z": 0,
      "name": "Empty"
    },
    {
      "x": 3,
      "y": 7,
      "z": 0,
      "name": "Rock_Stone"
    },
    {
      "x": 3,
      "y": 8,
      "z": 0,
      "name": "Rock_Stone"
    },
    {
      "x": 3,
      "y": -1,
      "z": 1,
      "name": "Rock_Stone"
    },
    {
      "x": 3,
      "y": 0,
      "z": 1,
      "name": "Rock_Stone"
    },
    {
      "x": 3,
      "y": 1,
      "z": 1,
      "name": "Empty"
    },
    {
      "x": 3,
      "y": 2,
      "z": 1,
      "name": "Empty"
    },
    {
      "x": 3,
      "y": 3,
      "z": 1,
      "name": "Empty"
    },
    {
      "x": 3,
      "y": 4,
      "z": 1,
      "name": "Empty"
    },
    {
      "x": 3,
      "y": 5,
      "z": 1,
      "name": "Empty"
    },
    {
      "x": 3,
      "y": 6,
      "z": 1,
      "name": "Rock_Stone"
    },
    {
      "x": 3,
      "y": 7,
      "z": 1,
      "name": "Rock_Stone"
    },
    {
      "x": 3,
      "y": 8,
      "z": 1,
      "name": "Rock_Stone"
    },
    {
      "x": 3,
      "y": -1,
      "z": 2,
      "name": "Rock_Stone"
    },
    {
      "x": 3,
      "y": 0,
      "z": 2,
      "name": "Rock_Stone"
    },
    {
      "x": 3,
      "y": 1,
      "z": 2,
      "name": "Wood_Beech_Trunk"
    },
    {
      "x": 3,
      "y": 2,
      "z": 2,
      "name": "Wood_Beech_Trunk"
    },
    {
      "x": 3,
      "y": 3,
      "z": 2,
      "name": "Wood_Beech_Trunk"
    },
    {
      "x": 3,
      "y": 4,
      "z": 2,
      "name": "Wood_Beech_Trunk"
    },
    {
      "x": 3,
      "y": 5,
      "z": 2,
      "name": "Wood_Beech_Trunk"
    },
    {
      "x": 3,
      "y": 6,
      "z": 2,
      "name": "Wood_Beech_Trunk",
      "rotation": 5
    },
    {
      "x": 3,
      "y": 7,
      "z": 2,
      "name": "Rock_Stone"
    },
    {
      "x": 3,
      "y": 8,
      "z": 2,
      "name": "Rock_Stone"
    },
    {
      "x": 3,
      "y": -1,
      "z": 3,
      "name": "Rock_Stone"
    },
    {
      "x": 3,
      "y": 0,
      "z": 3,
      "name": "Rock_Stone"
    },
    {
      "x": 3,
      "y": 1,
      "z": 3,
      "name": "Empty"
    },
    {
      "x": 3,
      "y": 2,
      "z": 3,
      "name": "Empty"
    },
    {
      "x": 3,
      "y": 3,
      "z": 3,
      "name": "Empty"
    },
    {
      "x": 3,
      "y": 4,
      "z": 3,
      "name": "Empty"
    },
    {
      "x": 3,
      "y": 5,
      "z": 3,
      "name": "Empty"
    },
    {
      "x": 3,
      "y": 6,
      "z": 3,
      "name": "Wood_Softwood_Planks_Half",
      "rotation": 4
    },
    {
      "x": 3,
      "y": 7,
      "z": 3,
      "name": "Rock_Stone"
    },
    {
      "x": 3,
      "y": 8,
      "z": 3,
      "name": "Rock_Stone"
    },
    {
      "x": 3,
      "y": -1,
      "z": 4,
      "name": "Rock_Stone"
    },
    {
      "x": 3,
      "y": 0,
      "z": 4,
      "name": "Rock_Stone"
    },
    {
      "x": 3,
      "y": 1,
      "z": 4,
      "name": "Wood_Softwood_Beam"
    },
    {
      "x": 3,
      "y": 2,
      "z": 4,
      "name": "*Furniture_Crude_Torch_State_Definitions_Off"
    },
    {
      "x": 3,
      "y": 3,
      "z": 4,
      "name": "Empty"
    },
    {
      "x": 3,
      "y": 4,
      "z": 4,
      "name": "Empty"
    },
    {
      "x": 3,
      "y": 5,
      "z": 4,
      "name": "Empty"
    },
    {
      "x": 3,
      "y": 6,
      "z": 4,
      "name": "Empty"
    },
    {
      "x": 3,
      "y": 7,
      "z": 4,
      "name": "Empty"
    },
    {
      "x": 3,
      "y": 8,
      "z": 4,
      "name": "Rock_Stone"
    },
    {
      "x": 3,
      "y": -1,
      "z": 5,
      "name": "Rock_Stone"
    },
    {
      "x": 3,
      "y": 0,
      "z": 5,
      "name": "Rock_Stone"
    },
    {
      "x": 3,
      "y": 1,
      "z": 5,
      "name": "Rubble_Stone_Medium"
    },
    {
      "x": 3,
      "y": 2,
      "z": 5,
      "name": "Empty"
    },
    {
      "x": 3,
      "y": 3,
      "z": 5,
      "name": "Empty"
    },
    {
      "x": 3,
      "y": 4,
      "z": 5,
      "name": "Empty"
    },
    {
      "x": 3,
      "y": 5,
      "z": 5,
      "name": "Empty"
    },
    {
      "x": 3,
      "y": 6,
      "z": 5,
      "name": "Empty"
    },
    {
      "x": 3,
      "y": 7,
      "z": 5,
      "name": "Empty"
    },
    {
      "x": 3,
      "y": 8,
      "z": 5,
      "name": "Rock_Stone"
    },
    {
      "x": 3,
      "y": -1,
      "z": 6,
      "name": "Rock_Stone"
    },
    {
      "x": 3,
      "y": 0,
      "z": 6,
      "name": "Rock_Stone"
    },
    {
      "x": 3,
      "y": 1,
      "z": 6,
      "name": "Wood_Beech_Branch_Long"
    },
    {
      "x": 3,
      "y": 2,
      "z": 6,
      "name": "Wood_Softwood_Planks"
    },
    {
      "x": 3,
      "y": 3,
      "z": 6,
      "name": "Wood_Softwood_Fence",
      "rotation": 2
    },
    {
      "x": 3,
      "y": 4,
      "z": 6,
      "name": "Empty"
    },
    {
      "x": 3,
      "y": 5,
      "z": 6,
      "name": "Empty"
    },
    {
      "x": 3,
      "y": 6,
      "z": 6,
      "name": "Empty"
    },
    {
      "x": 3,
      "y": 7,
      "z": 6,
      "name": "Rock_Stone"
    },
    {
      "x": 3,
      "y": 8,
      "z": 6,
      "name": "Rock_Stone"
    },
    {
      "x": 3,
      "y": -1,
      "z": 7,
      "name": "Rock_Stone"
    },
    {
      "x": 3,
      "y": 0,
      "z": 7,
      "name": "Rock_Stone"
    },
    {
      "x": 3,
      "y": 1,
      "z": 7,
      "name": "Rock_Stone"
    },
    {
      "x": 3,
      "y": 2,
      "z": 7,
      "name": "Wood_Softwood_Planks"
    },
    {
      "x": 3,
      "y": 3,
      "z": 7,
      "name": "Furniture_Village_Crate"
    },
    {
      "x": 3,
      "y": 4,
      "z": 7,
      "name": "Empty"
    },
    {
      "x": 3,
      "y": 5,
      "z": 7,
      "name": "Rock_Stone"
    },
    {
      "x": 3,
      "y": 6,
      "z": 7,
      "name": "Rock_Stone"
    },
    {
      "x": 3,
      "y": 7,
      "z": 7,
      "name": "Rock_Stone"
    },
    {
      "x": 3,
      "y": 8,
      "z": 7,
      "name": "Rock_Stone"
    },
    {
      "x": 3,
      "y": -1,
      "z": 8,
      "name": "Rock_Stone"
    },
    {
      "x": 3,
      "y": 0,
      "z": 8,
      "name": "Rock_Stone"
    },
    {
      "x": 3,
      "y": 1,
      "z": 8,
      "name": "Rock_Stone"
    },
    {
      "x": 3,
      "y": 2,
      "z": 8,
      "name": "Rock_Stone"
    },
    {
      "x": 3,
      "y": 3,
      "z": 8,
      "name": "Rock_Stone"
    },
    {
      "x": 3,
      "y": 4,
      "z": 8,
      "name": "Rock_Stone"
    },
    {
      "x": 3,
      "y": 5,
      "z": 8,
      "name": "Rock_Stone"
    },
    {
      "x": 3,
      "y": 6,
      "z": 8,
      "name": "Rock_Stone"
    },
    {
      "x": 3,
      "y": 7,
      "z": 8,
      "name": "Rock_Stone"
    },
    {
      "x": 3,
      "y": 8,
      "z": 8,
      "name": "Rock_Stone"
    },
    {
      "x": 3,
      "y": -1,
      "z": 9,
      "name": "Rock_Stone"
    },
    {
      "x": 3,
      "y": 0,
      "z": 9,
      "name": "Rock_Stone"
    },
    {
      "x": 3,
      "y": 1,
      "z": 9,
      "name": "Rock_Stone"
    },
    {
      "x": 3,
      "y": 2,
      "z": 9,
      "name": "Rock_Stone"
    },
    {
      "x": 3,
      "y": 3,
      "z": 9,
      "name": "Rock_Stone"
    },
    {
      "x": 3,
      "y": 4,
      "z": 9,
      "name": "Rock_Stone"
    },
    {
      "x": 3,
      "y": 5,
      "z": 9,
      "name": "Rock_Stone"
    },
    {
      "x": 3,
      "y": 6,
      "z": 9,
      "name": "Rock_Stone"
    },
    {
      "x": 3,
      "y": 7,
      "z": 9,
      "name": "Rock_Stone"
    },
    {
      "x": 3,
      "y": 8,
      "z": 9,
      "name": "Rock_Stone"
    },
    {
      "x": 3,
      "y": -1,
      "z": 10,
      "name": "Rock_Stone"
    },
    {
      "x": 3,
      "y": 0,
      "z": 10,
      "name": "Rock_Stone"
    },
    {
      "x": 3,
      "y": 1,
      "z": 10,
      "name": "Rock_Stone"
    },
    {
      "x": 3,
      "y": 2,
      "z": 10,
      "name": "Rock_Stone"
    },
    {
      "x": 3,
      "y": 3,
      "z": 10,
      "name": "Rock_Stone"
    },
    {
      "x": 3,
      "y": 4,
      "z": 10,
      "name": "Rock_Stone"
    },
    {
      "x": 3,
      "y": 5,
      "z": 10,
      "name": "Rock_Stone"
    },
    {
      "x": 3,
      "y": 6,
      "z": 10,
      "name": "Rock_Stone"
    },
    {
      "x": 3,
      "y": 7,
      "z": 10,
      "name": "Rock_Stone"
    },
    {
      "x": 3,
      "y": 8,
      "z": 10,
      "name": "Rock_Stone"
    },
    {
      "x": 4,
      "y": -1,
      "z": 0,
      "name": "Rock_Stone"
    },
    {
      "x": 4,
      "y": 0,
      "z": 0,
      "name": "Rock_Stone"
    },
    {
      "x": 4,
      "y": 1,
      "z": 0,
      "name": "Rock_Stone"
    },
    {
      "x": 4,
      "y": 2,
      "z": 0,
      "name": "Rock_Stone"
    },
    {
      "x": 4,
      "y": 3,
      "z": 0,
      "name": "Rock_Stone"
    },
    {
      "x": 4,
      "y": 4,
      "z": 0,
      "name": "Rock_Stone"
    },
    {
      "x": 4,
      "y": 5,
      "z": 0,
      "name": "Rock_Stone"
    },
    {
      "x": 4,
      "y": 6,
      "z": 0,
      "name": "Rock_Stone"
    },
    {
      "x": 4,
      "y": 7,
      "z": 0,
      "name": "Rock_Stone"
    },
    {
      "x": 4,
      "y": 8,
      "z": 0,
      "name": "Rock_Stone"
    },
    {
      "x": 4,
      "y": -1,
      "z": 1,
      "name": "Rock_Stone"
    },
    {
      "x": 4,
      "y": 0,
      "z": 1,
      "name": "Rock_Stone"
    },
    {
      "x": 4,
      "y": 1,
      "z": 1,
      "name": "Rock_Stone"
    },
    {
      "x": 4,
      "y": 2,
      "z": 1,
      "name": "Rock_Stone"
    },
    {
      "x": 4,
      "y": 3,
      "z": 1,
      "name": "Rock_Stone"
    },
    {
      "x": 4,
      "y": 4,
      "z": 1,
      "name": "Rock_Stone"
    },
    {
      "x": 4,
      "y": 5,
      "z": 1,
      "name": "Rock_Stone"
    },
    {
      "x": 4,
      "y": 6,
      "z": 1,
      "name": "Rock_Stone"
    },
    {
      "x": 4,
      "y": 7,
      "z": 1,
      "name": "Rock_Stone"
    },
    {
      "x": 4,
      "y": 8,
      "z": 1,
      "name": "Rock_Stone"
    },
    {
      "x": 4,
      "y": -1,
      "z": 2,
      "name": "Rock_Stone"
    },
    {
      "x": 4,
      "y": 0,
      "z": 2,
      "name": "Rock_Stone"
    },
    {
      "x": 4,
      "y": 1,
      "z": 2,
      "name": "Rock_Stone"
    },
    {
      "x": 4,
      "y": 2,
      "z": 2,
      "name": "Rock_Stone"
    },
    {
      "x": 4,
      "y": 3,
      "z": 2,
      "name": "Rock_Stone"
    },
    {
      "x": 4,
      "y": 4,
      "z": 2,
      "name": "Rock_Stone"
    },
    {
      "x": 4,
      "y": 5,
      "z": 2,
      "name": "Rock_Stone"
    },
    {
      "x": 4,
      "y": 6,
      "z": 2,
      "name": "Wood_Beech_Trunk",
      "rotation": 5
    },
    {
      "x": 4,
      "y": 7,
      "z": 2,
      "name": "Rock_Stone"
    },
    {
      "x": 4,
      "y": 8,
      "z": 2,
      "name": "Rock_Stone"
    },
    {
      "x": 4,
      "y": -1,
      "z": 3,
      "name": "Rock_Stone"
    },
    {
      "x": 4,
      "y": 0,
      "z": 3,
      "name": "Rock_Stone"
    },
    {
      "x": 4,
      "y": 1,
      "z": 3,
      "name": "Rock_Stone"
    },
    {
      "x": 4,
      "y": 2,
      "z": 3,
      "name": "Rock_Stone"
    },
    {
      "x": 4,
      "y": 3,
      "z": 3,
      "name": "Rock_Stone"
    },
    {
      "x": 4,
      "y": 4,
      "z": 3,
      "name": "Rock_Stone"
    },
    {
      "x": 4,
      "y": 5,
      "z": 3,
      "name": "Rock_Stone"
    },
    {
      "x": 4,
      "y": 6,
      "z": 3,
      "name": "Rock_Stone"
    },
    {
      "x": 4,
      "y": 7,
      "z": 3,
      "name": "Rock_Stone"
    },
    {
      "x": 4,
      "y": 8,
      "z": 3,
      "name": "Rock_Stone"
    },
    {
      "x": 4,
      "y": -1,
      "z": 4,
      "name": "Rock_Stone"
    },
    {
      "x": 4,
      "y": 0,
      "z": 4,
      "name": "Rock_Stone"
    },
    {
      "x": 4,
      "y": 1,
      "z": 4,
      "name": "Rock_Stone"
    },
    {
      "x": 4,
      "y": 2,
      "z": 4,
      "name": "Rock_Stone"
    },
    {
      "x": 4,
      "y": 3,
      "z": 4,
      "name": "Rock_Stone"
    },
    {
      "x": 4,
      "y": 4,
      "z": 4,
      "name": "Rock_Stone"
    },
    {
      "x": 4,
      "y": 5,
      "z": 4,
      "name": "Rock_Stone"
    },
    {
      "x": 4,
      "y": 6,
      "z": 4,
      "name": "Rock_Stone"
    },
    {
      "x": 4,
      "y": 7,
      "z": 4,
      "name": "Rock_Stone"
    },
    {
      "x": 4,
      "y": 8,
      "z": 4,
      "name": "Rock_Stone"
    },
    {
      "x": 4,
      "y": -1,
      "z": 5,
      "name": "Rock_Stone"
    },
    {
      "x": 4,
      "y": 0,
      "z": 5,
      "name": "Rock_Stone"
    },
    {
      "x": 4,
      "y": 1,
      "z": 5,
      "name": "Rock_Stone"
    },
    {
      "x": 4,
      "y": 2,
      "z": 5,
      "name": "Rock_Stone"
    },
    {
      "x": 4,
      "y": 3,
      "z": 5,
      "name": "Rock_Stone"
    },
    {
      "x": 4,
      "y": 4,
      "z": 5,
      "name": "Rock_Stone"
    },
    {
      "x": 4,
      "y": 5,
      "z": 5,
      "name": "Rock_Stone"
    },
    {
      "x": 4,
      "y": 6,
      "z": 5,
      "name": "Rock_Stone"
    },
    {
      "x": 4,
      "y": 7,
      "z": 5,
      "name": "Rock_Stone"
    },
    {
      "x": 4,
      "y": 8,
      "z": 5,
      "name": "Rock_Stone"
    },
    {
      "x": 4,
      "y": -1,
      "z": 6,
      "name": "Rock_Stone"
    },
    {
      "x": 4,
      "y": 0,
      "z": 6,
      "name": "Rock_Stone"
    },
    {
      "x": 4,
      "y": 1,
      "z": 6,
      "name": "Rock_Stone"
    },
    {
      "x": 4,
      "y": 2,
      "z": 6,
      "name": "Rock_Stone"
    },
    {
      "x": 4,
      "y": 3,
      "z": 6,
      "name": "Rock_Stone"
    },
    {
      "x": 4,
      "y": 4,
      "z": 6,
      "name": "Rock_Stone"
    },
    {
      "x": 4,
      "y": 5,
      "z": 6,
      "name": "Rock_Stone"
    },
    {
      "x": 4,
      "y": 6,
      "z": 6,
      "name": "Rock_Stone"
    },
    {
      "x": 4,
      "y": 7,
      "z": 6,
      "name": "Rock_Stone"
    },
    {
      "x": 4,
      "y": 8,
      "z": 6,
      "name": "Rock_Stone"
    },
    {
      "x": 4,
      "y": -1,
      "z": 7,
      "name": "Rock_Stone"
    },
    {
      "x": 4,
      "y": 0,
      "z": 7,
      "name": "Rock_Stone"
    },
    {
      "x": 4,
      "y": 1,
      "z": 7,
      "name": "Rock_Stone"
    },
    {
      "x": 4,
      "y": 2,
      "z": 7,
      "name": "Rock_Stone"
    },
    {
      "x": 4,
      "y": 3,
      "z": 7,
      "name": "Rock_Stone"
    },
    {
      "x": 4,
      "y": 4,
      "z": 7,
      "name": "Rock_Stone"
    },
    {
      "x": 4,
      "y": 5,
      "z": 7,
      "name": "Rock_Stone"
    },
    {
      "x": 4,
      "y": 6,
      "z": 7,
      "name": "Rock_Stone"
    },
    {
      "x": 4,
      "y": 7,
      "z": 7,
      "name": "Rock_Stone"
    },
    {
      "x": 4,
      "y": 8,
      "z": 7,
      "name": "Rock_Stone"
    },
    {
      "x": 4,
      "y": -1,
      "z": 8,
      "name": "Rock_Stone"
    },
    {
      "x": 4,
      "y": 0,
      "z": 8,
      "name": "Rock_Stone"
    },
    {
      "x": 4,
      "y": 1,
      "z": 8,
      "name": "Rock_Stone"
    },
    {
      "x": 4,
      "y": 2,
      "z": 8,
      "name": "Rock_Stone"
    },
    {
      "x": 4,
      "y": 3,
      "z": 8,
      "name": "Rock_Stone"
    },
    {
      "x": 4,
      "y": 4,
      "z": 8,
      "name": "Rock_Stone"
    },
    {
      "x": 4,
      "y": 5,
      "z": 8,
      "name": "Rock_Stone"
    },
    {
      "x": 4,
      "y": 6,
      "z": 8,
      "name": "Rock_Stone"
    },
    {
      "x": 4,
      "y": 7,
      "z": 8,
      "name": "Rock_Stone"
    },
    {
      "x": 4,
      "y": 8,
      "z": 8,
      "name": "Rock_Stone"
    },
    {
      "x": 4,
      "y": -1,
      "z": 9,
      "name": "Rock_Stone"
    },
    {
      "x": 4,
      "y": 0,
      "z": 9,
      "name": "Rock_Stone"
    },
    {
      "x": 4,
      "y": 1,
      "z": 9,
      "name": "Rock_Stone"
    },
    {
      "x": 4,
      "y": 2,
      "z": 9,
      "name": "Rock_Stone"
    },
    {
      "x": 4,
      "y": 3,
      "z": 9,
      "name": "Rock_Stone"
    },
    {
      "x": 4,
      "y": 4,
      "z": 9,
      "name": "Rock_Stone"
    },
    {
      "x": 4,
      "y": 5,
      "z": 9,
      "name": "Rock_Stone"
    },
    {
      "x": 4,
      "y": 6,
      "z": 9,
      "name": "Rock_Stone"
    },
    {
      "x": 4,
      "y": 7,
      "z": 9,
      "name": "Rock_Stone"
    },
    {
      "x": 4,
      "y": 8,
      "z": 9,
      "name": "Rock_Stone"
    },
    {
      "x": 4,
      "y": -1,
      "z": 10,
      "name": "Rock_Stone"
    },
    {
      "x": 4,
      "y": 0,
      "z": 10,
      "name": "Rock_Stone"
    },
    {
      "x": 4,
      "y": 1,
      "z": 10,
      "name": "Rock_Stone"
    },
    {
      "x": 4,
      "y": 2,
      "z": 10,
      "name": "Rock_Stone"
    },
    {
      "x": 4,
      "y": 3,
      "z": 10,
      "name": "Rock_Stone"
    },
    {
      "x": 4,
      "y": 4,
      "z": 10,
      "name": "Rock_Stone"
    },
    {
      "x": 4,
      "y": 5,
      "z": 10,
      "name": "Rock_Stone"
    },
    {
      "x": 4,
      "y": 6,
      "z": 10,
      "name": "Rock_Stone"
    },
    {
      "x": 4,
      "y": 7,
      "z": 10,
      "name": "Rock_Stone"
    },
    {
      "x": 4,
      "y": 8,
      "z": 10,
      "name": "Rock_Stone"
    }
  ]
}