{
  "version": 8,
  "blockIdVersion": 8,
  "anchorX": -2,
  "anchorY": 0,
  "anchorZ": 7,
  "blocks": [
    {
      "x": -7,
      "y": 0,
      "z": -7,
      "name": "Rock_Shale"
    },
    {
      "x": -7,
      "y": 1,
      "z": -7,
      "name": "Rock_Shale"
    },
    {
      "x": -7,
      "y": 2,
      "z": -7,
      "name": "Rock_Shale"
    },
    {
      "x": -7,
      "y": 3,
      "z": -7,
      "name": "Rock_Shale"
    },
    {
      "x": -7,
      "y": 4,
      "z": -7,
      "name": "Rock_Shale"
    },
    {
      "x": -7,
      "y": 5,
      "z": -7,
      "name": "Rock_Basalt"
    },
    {
      "x": -7,
      "y": 0,
      "z": -6,
      "name": "Rock_Shale"
    },
    {
      "x": -7,
      "y": 1,
      "z": -6,
      "name": "Rock_Shale"
    },
    {
      "x": -7,
      "y": 2,
      "z": -6,
      "name": "Rock_Shale"
    },
    {
      "x": -7,
      "y": 3,
      "z": -6,
      "name": "Rock_Shale"
    },
    {
      "x": -7,
      "y": 4,
      "z": -6,
      "name": "Rock_Shale"
    },
    {
      "x": -7,
      "y": 5,
      "z": -6,
      "name": "Rock_Basalt"
    },
    {
      "x": -7,
      "y": 0,
      "z": -5,
      "name": "Rock_Shale"
    },
    {
      "x": -7,
      "y": 1,
      "z": -5,
      "name": "Rock_Shale"
    },
    {
      "x": -7,
      "y": 2,
      "z": -5,
      "name": "Rock_Shale"
    },
    {
      "x": -7,
      "y": 3,
      "z": -5,
      "name": "Rock_Shale"
    },
    {
      "x": -7,
      "y": 4,
      "z": -5,
      "name": "Rock_Shale"
    },
    {
      "x": -7,
      "y": 5,
      "z": -5,
      "name": "Rock_Basalt"
    },
    {
      "x": -7,
      "y": 0,
      "z": -4,
      "name": "Rock_Shale"
    },
    {
      "x": -7,
      "y": 1,
      "z": -4,
      "name": "Rock_Shale"
    },
    {
      "x": -7,
      "y": 2,
      "z": -4,
      "name": "Rock_Shale"
    },
    {
      "x": -7,
      "y": 3,
      "z": -4,
      "name": "Rock_Shale"
    },
    {
      "x": -7,
      "y": 4,
      "z": -4,
      "name": "Rock_Shale"
    },
    {
      "x": -7,
      "y": 5,
      "z": -4,
      "name": "Rock_Basalt"
    },
    {
      "x": -7,
      "y": 0,
      "z": -3,
      "name": "Rock_Shale"
    },
    {
      "x": -7,
      "y": 1,
      "z": -3,
      "name": "Rock_Shale"
    },
    {
      "x": -7,
      "y": 2,
      "z": -3,
      "name": "Rock_Shale"
    },
    {
      "x": -7,
      "y": 3,
      "z": -3,
      "name": "Rock_Shale"
    },
    {
      "x": -7,
      "y": 4,
      "z": -3,
      "name": "Rock_Shale"
    },
    {
      "x": -7,
      "y": 5,
      "z": -3,
      "name": "Rock_Basalt"
    },
    {
      "x": -7,
      "y": 0,
      "z": -2,
      "name": "Rock_Shale"
    },
    {
      "x": -7,
      "y": 1,
      "z": -2,
      "name": "Rock_Shale"
    },
    {
      "x": -7,
      "y": 2,
      "z": -2,
      "name": "Rock_Shale"
    },
    {
      "x": -7,
      "y": 3,
      "z": -2,
      "name": "Rock_Shale"
    },
    {
      "x": -7,
      "y": 4,
      "z": -2,
      "name": "Rock_Shale"
    },
    {
      "x": -7,
      "y": 5,
      "z": -2,
      "name": "Rock_Basalt"
    },
    {
      "x": -7,
      "y": 0,
      "z": -1,
      "name": "Rock_Shale"
    },
    {
      "x": -7,
      "y": 1,
      "z": -1,
      "name": "Rock_Shale"
    },
    {
      "x": -7,
      "y": 2,
      "z": -1,
      "name": "Rock_Shale"
    },
    {
      "x": -7,
      "y": 3,
      "z": -1,
      "name": "Rock_Shale"
    },
    {
      "x": -7,
      "y": 4,
      "z": -1,
      "name": "Rock_Shale"
    },
    {
      "x": -7,
      "y": 5,
      "z": -1,
      "name": "Rock_Basalt"
    },
    {
      "x": -7,
      "y": 0,
      "z": 0,
      "name": "Rock_Shale"
    },
    {
      "x": -7,
      "y": 1,
      "z": 0,
      "name": "Rock_Shale"
    },
    {
      "x": -7,
      "y": 2,
      "z": 0,
      "name": "Rock_Shale"
    },
    {
      "x": -7,
      "y": 3,
      "z": 0,
      "name": "Rock_Shale"
    },
    {
      "x": -7,
      "y": 4,
      "z": 0,
      "name": "Rock_Shale"
    },
    {
      "x": -7,
      "y": 5,
      "z": 0,
      "name": "Rock_Basalt"
    },
    {
      "x": -7,
      "y": 0,
      "z": 1,
      "name": "Rock_Shale"
    },
    {
      "x": -7,
      "y": 1,
      "z": 1,
      "name": "Rock_Shale"
    },
    {
      "x": -7,
      "y": 2,
      "z": 1,
      "name": "Rock_Shale"
    },
    {
      "x": -7,
      "y": 3,
      "z": 1,
      "name": "Rock_Shale"
    },
    {
      "x": -7,
      "y": 4,
      "z": 1,
      "name": "Rock_Shale"
    },
    {
      "x": -7,
      "y": 5,
      "z": 1,
      "name": "Rock_Basalt"
    },
    {
      "x": -7,
      "y": 0,
      "z": 2,
      "name": "Rock_Shale"
    },
    {
      "x": -7,
      "y": 1,
      "z": 2,
      "name": "Rock_Shale"
    },
    {
      "x": -7,
      "y": 2,
      "z": 2,
      "name": "Rock_Shale"
    },
    {
      "x": -7,
      "y": 3,
      "z": 2,
      "name": "Rock_Shale"
    },
    {
      "x": -7,
      "y": 4,
      "z": 2,
      "name": "Rock_Shale"
    },
    {
      "x": -7,
      "y": 5,
      "z": 2,
      "name": "Rock_Basalt"
    },
    {
      "x": -7,
      "y": 0,
      "z": 3,
      "name": "Rock_Shale"
    },
    {
      "x": -7,
      "y": 1,
      "z": 3,
      "name": "Rock_Shale"
    },
    {
      "x": -7,
      "y": 2,
      "z": 3,
      "name": "Rock_Shale"
    },
    {
      "x": -7,
      "y": 3,
      "z": 3,
      "name": "Rock_Shale"
    },
    {
      "x": -7,
      "y": 4,
      "z": 3,
      "name": "Rock_Shale"
    },
    {
      "x": -7,
      "y": 5,
      "z": 3,
      "name": "Rock_Basalt"
    },
    {
      "x": -7,
      "y": 0,
      "z": 4,
      "name": "Rock_Shale"
    },
    {
      "x": -7,
      "y": 1,
      "z": 4,
      "name": "Rock_Shale"
    },
    {
      "x": -7,
      "y": 2,
      "z": 4,
      "name": "Rock_Shale"
    },
    {
      "x": -7,
      "y": 3,
      "z": 4,
      "name": "Rock_Shale"
    },
    {
      "x": -7,
      "y": 4,
      "z": 4,
      "name": "Rock_Shale"
    },
    {
      "x": -7,
      "y": 5,
      "z": 4,
      "name": "Rock_Basalt"
    },
    {
      "x": -7,
      "y": 0,
      "z": 5,
      "name": "Rock_Shale"
    },
    {
      "x": -7,
      "y": 1,
      "z": 5,
      "name": "Rock_Shale"
    },
    {
      "x": -7,
      "y": 2,
      "z": 5,
      "name": "Rock_Shale"
    },
    {
      "x": -7,
      "y": 3,
      "z": 5,
      "name": "Rock_Shale"
    },
    {
      "x": -7,
      "y": 4,
      "z": 5,
      "name": "Rock_Shale"
    },
    {
      "x": -7,
      "y": 5,
      "z": 5,
      "name": "Rock_Basalt"
    },
    {
      "x": -7,
      "y": 0,
      "z": 6,
      "name": "Rock_Shale"
    },
    {
      "x": -7,
      "y": 1,
      "z": 6,
      "name": "Rock_Shale"
    },
    {
      "x": -7,
      "y": 2,
      "z": 6,
      "name": "Rock_Shale"
    },
    {
      "x": -7,
      "y": 3,
      "z": 6,
      "name": "Rock_Shale"
    },
    {
      "x": -7,
      "y": 4,
      "z": 6,
      "name": "Rock_Shale"
    },
    {
      "x": -7,
      "y": 5,
      "z": 6,
      "name": "Rock_Basalt"
    },
    {
      "x": -7,
      "y": 0,
      "z": 7,
      "name": "Rock_Shale"
    },
    {
      "x": -7,
      "y": 1,
      "z": 7,
      "name": "Rock_Shale"
    },
    {
      "x": -7,
      "y": 2,
      "z": 7,
      "name": "Rock_Shale"
    },
    {
      "x": -7,
      "y": 3,
      "z": 7,
      "name": "Rock_Shale"
    },
    {
      "x": -7,
      "y": 4,
      "z": 7,
      "name": "Rock_Shale"
    },
    {
      "x": -7,
      "y": 5,
      "z": 7,
      "name": "Rock_Basalt"
    },
    {
      "x": -6,
      "y": 0,
      "z": -7,
      "name": "Rock_Shale"
    },
    {
      "x": -6,
      "y": 1,
      "z": -7,
      "name": "Rock_Shale"
    },
    {
      "x": -6,
      "y": 2,
      "z": -7,
      "name": "Rock_Shale"
    },
    {
      "x": -6,
      "y": 3,
      "z": -7,
      "name": "Rock_Shale"
    },
    {
      "x": -6,
      "y": 4,
      "z": -7,
      "name": "Rock_Shale"
    },
    {
      "x": -6,
      "y": 5,
      "z": -7,
      "name": "Rock_Basalt"
    },
    {
      "x": -6,
      "y": 0,
      "z": -6,
      "name": "Rock_Shale"
    },
    {
      "x": -6,
      "y": 1,
      "z": -6,
      "name": "Rock_Shale"
    },
    {
      "x": -6,
      "y": 2,
      "z": -6,
      "name": "Rock_Shale"
    },
    {
      "x": -6,
      "y": 3,
      "z": -6,
      "name": "Rock_Shale"
    },
    {
      "x": -6,
      "y": 4,
      "z": -6,
      "name": "Rock_Shale"
    },
    {
      "x": -6,
      "y": 5,
      "z": -6,
      "name": "Rock_Basalt"
    },
    {
      "x": -6,
      "y": 0,
      "z": -5,
      "name": "Rock_Shale"
    },
    {
      "x": -6,
      "y": 1,
      "z": -5,
      "name": "Rock_Shale"
    },
    {
      "x": -6,
      "y": 2,
      "z": -5,
      "name": "Rock_Shale"
    },
    {
      "x": -6,
      "y": 3,
      "z": -5,
      "name": "Rock_Shale"
    },
    {
      "x": -6,
      "y": 4,
      "z": -5,
      "name": "Rock_Shale"
    },
    {
      "x": -6,
      "y": 5,
      "z": -5,
      "name": "Rock_Basalt"
    },
    {
      "x": -6,
      "y": 0,
      "z": -4,
      "name": "Rock_Shale"
    },
    {
      "x": -6,
      "y": 1,
      "z": -4,
      "name": "Rock_Shale"
    },
    {
      "x": -6,
      "y": 2,
      "z": -4,
      "name": "Rock_Shale"
    },
    {
      "x": -6,
      "y": 3,
      "z": -4,
      "name": "Rock_Shale"
    },
    {
      "x": -6,
      "y": 4,
      "z": -4,
      "name": "Rock_Shale"
    },
    {
      "x": -6,
      "y": 5,
      "z": -4,
      "name": "Rock_Basalt"
    },
    {
      "x": -6,
      "y": 0,
      "z": -3,
      "name": "Rock_Shale"
    },
    {
      "x": -6,
      "y": 1,
      "z": -3,
      "name": "Rock_Shale"
    },
    {
      "x": -6,
      "y": 2,
      "z": -3,
      "name": "Rock_Shale"
    },
    {
      "x": -6,
      "y": 3,
      "z": -3,
      "name": "Rock_Shale"
    },
    {
      "x": -6,
      "y": 4,
      "z": -3,
      "name": "Rock_Shale"
    },
    {
      "x": -6,
      "y": 5,
      "z": -3,
      "name": "Rock_Basalt"
    },
    {
      "x": -6,
      "y": 0,
      "z": -2,
      "name": "Rock_Shale"
    },
    {
      "x": -6,
      "y": 1,
      "z": -2,
      "name": "Rock_Shale"
    },
    {
      "x": -6,
      "y": 2,
      "z": -2,
      "name": "Rock_Shale"
    },
    {
      "x": -6,
      "y": 3,
      "z": -2,
      "name": "Rock_Shale"
    },
    {
      "x": -6,
      "y": 4,
      "z": -2,
      "name": "Rock_Shale"
    },
    {
      "x": -6,
      "y": 5,
      "z": -2,
      "name": "Rock_Basalt"
    },
    {
      "x": -6,
      "y": 0,
      "z": -1,
      "name": "Rock_Shale"
    },
    {
      "x": -6,
      "y": 1,
      "z": -1,
      "name": "Rock_Shale"
    },
    {
      "x": -6,
      "y": 2,
      "z": -1,
      "name": "Rock_Shale"
    },
    {
      "x": -6,
      "y": 3,
      "z": -1,
      "name": "Rock_Shale"
    },
    {
      "x": -6,
      "y": 4,
      "z": -1,
      "name": "Rock_Shale"
    },
    {
      "x": -6,
      "y": 5,
      "z": -1,
      "name": "Rock_Basalt"
    },
    {
      "x": -6,
      "y": 0,
      "z": 0,
      "name": "Rock_Shale"
    },
    {
      "x": -6,
      "y": 1,
      "z": 0,
      "name": "Rock_Shale"
    },
    {
      "x": -6,
      "y": 2,
      "z": 0,
      "name": "Rock_Shale"
    },
    {
      "x": -6,
      "y": 3,
      "z": 0,
      "name": "Rock_Shale"
    },
    {
      "x": -6,
      "y": 4,
      "z": 0,
      "name": "Rock_Shale"
    },
    {
      "x": -6,
      "y": 5,
      "z": 0,
      "name": "Rock_Basalt"
    },
    {
      "x": -6,
      "y": 0,
      "z": 1,
      "name": "Rock_Shale"
    },
    {
      "x": -6,
      "y": 1,
      "z": 1,
      "name": "Rock_Shale"
    },
    {
      "x": -6,
      "y": 2,
      "z": 1,
      "name": "Rock_Shale"
    },
    {
      "x": -6,
      "y": 3,
      "z": 1,
      "name": "Rock_Shale"
    },
    {
      "x": -6,
      "y": 4,
      "z": 1,
      "name": "Rock_Shale"
    },
    {
      "x": -6,
      "y": 5,
      "z": 1,
      "name": "Rock_Basalt"
    },
    {
      "x": -6,
      "y": 0,
      "z": 2,
      "name": "Rock_Shale"
    },
    {
      "x": -6,
      "y": 1,
      "z": 2,
      "name": "Rock_Shale"
    },
    {
      "x": -6,
      "y": 2,
      "z": 2,
      "name": "Rock_Shale"
    },
    {
      "x": -6,
      "y": 3,
      "z": 2,
      "name": "Rock_Shale"
    },
    {
      "x": -6,
      "y": 4,
      "z": 2,
      "name": "Rock_Shale"
    },
    {
      "x": -6,
      "y": 5,
      "z": 2,
      "name": "Rock_Basalt"
    },
    {
      "x": -6,
      "y": 0,
      "z": 3,
      "name": "Rock_Shale"
    },
    {
      "x": -6,
      "y": 1,
      "z": 3,
      "name": "Rock_Shale"
    },
    {
      "x": -6,
      "y": 2,
      "z": 3,
      "name": "Rock_Shale"
    },
    {
      "x": -6,
      "y": 3,
      "z": 3,
      "name": "Rock_Shale"
    },
    {
      "x": -6,
      "y": 4,
      "z": 3,
      "name": "Rock_Shale"
    },
    {
      "x": -6,
      "y": 5,
      "z": 3,
      "name": "Rock_Basalt"
    },
    {
      "x": -6,
      "y": 0,
      "z": 4,
      "name": "Rock_Shale"
    },
    {
      "x": -6,
      "y": 1,
      "z": 4,
      "name": "Rock_Shale"
    },
    {
      "x": -6,
      "y": 2,
      "z": 4,
      "name": "Rock_Shale"
    },
    {
      "x": -6,
      "y": 3,
      "z": 4,
      "name": "Rock_Shale"
    },
    {
      "x": -6,
      "y": 4,
      "z": 4,
      "name": "Rock_Shale"
    },
    {
      "x": -6,
      "y": 5,
      "z": 4,
      "name": "Rock_Basalt"
    },
    {
      "x": -6,
      "y": 0,
      "z": 5,
      "name": "Rock_Shale"
    },
    {
      "x": -6,
      "y": 1,
      "z": 5,
      "name": "Rock_Shale"
    },
    {
      "x": -6,
      "y": 2,
      "z": 5,
      "name": "Rock_Shale"
    },
    {
      "x": -6,
      "y": 3,
      "z": 5,
      "name": "Rock_Shale"
    },
    {
      "x": -6,
      "y": 4,
      "z": 5,
      "name": "Rock_Shale"
    },
    {
      "x": -6,
      "y": 5,
      "z": 5,
      "name": "Rock_Basalt"
    },
    {
      "x": -6,
      "y": 0,
      "z": 6,
      "name": "Rock_Shale"
    },
    {
      "x": -6,
      "y": 1,
      "z": 6,
      "name": "Rock_Basalt"
    },
    {
      "x": -6,
      "y": 2,
      "z": 6,
      "name": "Rock_Basalt"
    },
    {
      "x": -6,
      "y": 3,
      "z": 6,
      "name": "Rock_Shale"
    },
    {
      "x": -6,
      "y": 4,
      "z": 6,
      "name": "Rock_Shale"
    },
    {
      "x": -6,
      "y": 5,
      "z": 6,
      "name": "Rock_Basalt"
    },
    {
      "x": -6,
      "y": 0,
      "z": 7,
      "name": "Rock_Shale_Brick_Smooth"
    },
    {
      "x": -6,
      "y": 1,
      "z": 7,
      "name": "Rock_Shale_Brick_Pillar_Base"
    },
    {
      "x": -6,
      "y": 2,
      "z": 7,
      "name": "Rock_Shale_Brick_Pillar_Middle"
    },
    {
      "x": -6,
      "y": 3,
      "z": 7,
      "name": "Rock_Shale_Brick_Pillar_Base",
      "rotation": 8
    },
    {
      "x": -6,
      "y": 4,
      "z": 7,
      "name": "Rock_Shale_Brick"
    },
    {
      "x": -6,
      "y": 5,
      "z": 7,
      "name": "Rock_Basalt"
    },
    {
      "x": -5,
      "y": 0,
      "z": -7,
      "name": "Rock_Shale"
    },
    {
      "x": -5,
      "y": 1,
      "z": -7,
      "name": "Rock_Shale"
    },
    {
      "x": -5,
      "y": 2,
      "z": -7,
      "name": "Rock_Shale"
    },
    {
      "x": -5,
      "y": 3,
      "z": -7,
      "name": "Rock_Shale"
    },
    {
      "x": -5,
      "y": 4,
      "z": -7,
      "name": "Rock_Shale"
    },
    {
      "x": -5,
      "y": 5,
      "z": -7,
      "name": "Rock_Basalt"
    },
    {
      "x": -5,
      "y": 0,
      "z": -6,
      "name": "Rock_Shale"
    },
    {
      "x": -5,
      "y": 1,
      "z": -6,
      "name": "Rock_Shale"
    },
    {
      "x": -5,
      "y": 2,
      "z": -6,
      "name": "Rock_Shale"
    },
    {
      "x": -5,
      "y": 3,
      "z": -6,
      "name": "Rock_Shale"
    },
    {
      "x": -5,
      "y": 4,
      "z": -6,
      "name": "Rock_Shale"
    },
    {
      "x": -5,
      "y": 5,
      "z": -6,
      "name": "Rock_Basalt"
    },
    {
      "x": -5,
      "y": 0,
      "z": -5,
      "name": "Rock_Shale"
    },
    {
      "x": -5,
      "y": 1,
      "z": -5,
      "name": "Rock_Shale"
    },
    {
      "x": -5,
      "y": 2,
      "z": -5,
      "name": "Rock_Shale"
    },
    {
      "x": -5,
      "y": 3,
      "z": -5,
      "name": "Rock_Shale"
    },
    {
      "x": -5,
      "y": 4,
      "z": -5,
      "name": "Rock_Shale"
    },
    {
      "x": -5,
      "y": 5,
      "z": -5,
      "name": "Rock_Basalt"
    },
    {
      "x": -5,
      "y": 0,
      "z": -4,
      "name": "Rock_Shale"
    },
    {
      "x": -5,
      "y": 1,
      "z": -4,
      "name": "Rock_Shale"
    },
    {
      "x": -5,
      "y": 2,
      "z": -4,
      "name": "Rock_Shale"
    },
    {
      "x": -5,
      "y": 3,
      "z": -4,
      "name": "Rock_Shale"
    },
    {
      "x": -5,
      "y": 4,
      "z": -4,
      "name": "Rock_Shale"
    },
    {
      "x": -5,
      "y": 5,
      "z": -4,
      "name": "Rock_Basalt"
    },
    {
      "x": -5,
      "y": 0,
      "z": -3,
      "name": "Rock_Shale"
    },
    {
      "x": -5,
      "y": 1,
      "z": -3,
      "name": "Rock_Shale"
    },
    {
      "x": -5,
      "y": 2,
      "z": -3,
      "name": "Rock_Shale"
    },
    {
      "x": -5,
      "y": 3,
      "z": -3,
      "name": "Rock_Shale"
    },
    {
      "x": -5,
      "y": 4,
      "z": -3,
      "name": "Rock_Shale"
    },
    {
      "x": -5,
      "y": 5,
      "z": -3,
      "name": "Rock_Basalt"
    },
    {
      "x": -5,
      "y": 0,
      "z": -2,
      "name": "Rock_Shale"
    },
    {
      "x": -5,
      "y": 1,
      "z": -2,
      "name": "Rock_Shale"
    },
    {
      "x": -5,
      "y": 2,
      "z": -2,
      "name": "Rock_Shale"
    },
    {
      "x": -5,
      "y": 3,
      "z": -2,
      "name": "Rock_Shale"
    },
    {
      "x": -5,
      "y": 4,
      "z": -2,
      "name": "Rock_Shale"
    },
    {
      "x": -5,
      "y": 5,
      "z": -2,
      "name": "Rock_Basalt"
    },
    {
      "x": -5,
      "y": 0,
      "z": -1,
      "name": "Rock_Shale"
    },
    {
      "x": -5,
      "y": 1,
      "z": -1,
      "name": "Rock_Shale"
    },
    {
      "x": -5,
      "y": 2,
      "z": -1,
      "name": "Rock_Shale"
    },
    {
      "x": -5,
      "y": 3,
      "z": -1,
      "name": "Rock_Shale"
    },
    {
      "x": -5,
      "y": 4,
      "z": -1,
      "name": "Rock_Shale"
    },
    {
      "x": -5,
      "y": 5,
      "z": -1,
      "name": "Rock_Basalt"
    },
    {
      "x": -5,
      "y": 0,
      "z": 0,
      "name": "Rock_Shale"
    },
    {
      "x": -5,
      "y": 1,
      "z": 0,
      "name": "Rock_Shale"
    },
    {
      "x": -5,
      "y": 2,
      "z": 0,
      "name": "Rock_Shale"
    },
    {
      "x": -5,
      "y": 3,
      "z": 0,
      "name": "Rock_Shale"
    },
    {
      "x": -5,
      "y": 4,
      "z": 0,
      "name": "Rock_Shale"
    },
    {
      "x": -5,
      "y": 5,
      "z": 0,
      "name": "Rock_Basalt"
    },
    {
      "x": -5,
      "y": 0,
      "z": 1,
      "name": "Rock_Shale"
    },
    {
      "x": -5,
      "y": 1,
      "z": 1,
      "name": "Rock_Shale"
    },
    {
      "x": -5,
      "y": 2,
      "z": 1,
      "name": "Rock_Shale"
    },
    {
      "x": -5,
      "y": 3,
      "z": 1,
      "name": "Rock_Shale"
    },
    {
      "x": -5,
      "y": 4,
      "z": 1,
      "name": "Rock_Shale"
    },
    {
      "x": -5,
      "y": 5,
      "z": 1,
      "name": "Rock_Basalt"
    },
    {
      "x": -5,
      "y": 0,
      "z": 2,
      "name": "Rock_Shale"
    },
    {
      "x": -5,
      "y": 1,
      "z": 2,
      "name": "Rock_Shale"
    },
    {
      "x": -5,
      "y": 2,
      "z": 2,
      "name": "Rock_Shale"
    },
    {
      "x": -5,
      "y": 3,
      "z": 2,
      "name": "Rock_Shale"
    },
    {
      "x": -5,
      "y": 4,
      "z": 2,
      "name": "Rock_Shale"
    },
    {
      "x": -5,
      "y": 5,
      "z": 2,
      "name": "Rock_Basalt"
    },
    {
      "x": -5,
      "y": 0,
      "z": 3,
      "name": "Rock_Shale"
    },
    {
      "x": -5,
      "y": 1,
      "z": 3,
      "name": "Rock_Shale"
    },
    {
      "x": -5,
      "y": 2,
      "z": 3,
      "name": "Rock_Shale"
    },
    {
      "x": -5,
      "y": 3,
      "z": 3,
      "name": "Rock_Shale"
    },
    {
      "x": -5,
      "y": 4,
      "z": 3,
      "name": "Rock_Shale"
    },
    {
      "x": -5,
      "y": 5,
      "z": 3,
      "name": "Rock_Basalt"
    },
    {
      "x": -5,
      "y": 0,
      "z": 4,
      "name": "Rock_Shale"
    },
    {
      "x": -5,
      "y": 1,
      "z": 4,
      "name": "Rock_Shale"
    },
    {
      "x": -5,
      "y": 2,
      "z": 4,
      "name": "Rock_Shale"
    },
    {
      "x": -5,
      "y": 3,
      "z": 4,
      "name": "Rock_Shale"
    },
    {
      "x": -5,
      "y": 4,
      "z": 4,
      "name": "Rock_Shale"
    },
    {
      "x": -5,
      "y": 5,
      "z": 4,
      "name": "Rock_Basalt"
    },
    {
      "x": -5,
      "y": 0,
      "z": 5,
      "name": "Rock_Shale"
    },
    {
      "x": -5,
      "y": 1,
      "z": 5,
      "name": "Rock_Basalt"
    },
    {
      "x": -5,
      "y": 2,
      "z": 5,
      "name": "Rock_Basalt"
    },
    {
      "x": -5,
      "y": 3,
      "z": 5,
      "name": "Rock_Basalt"
    },
    {
      "x": -5,
      "y": 4,
      "z": 5,
      "name": "Rock_Shale"
    },
    {
      "x": -5,
      "y": 5,
      "z": 5,
      "name": "Rock_Basalt"
    },
    {
      "x": -5,
      "y": 0,
      "z": 6,
      "name": "Rock_Basalt"
    },
    {
      "x": -5,
      "y": 1,
      "z": 6,
      "name": "Furniture_Ancient_Crate"
    },
    {
      "x": -5,
      "y": 2,
      "z": 6,
      "name": "Empty"
    },
    {
      "x": -5,
      "y": 3,
      "z": 6,
      "name": "Empty"
    },
    {
      "x": -5,
      "y": 4,
      "z": 6,
      "name": "Rock_Shale"
    },
    {
      "x": -5,
      "y": 5,
      "z": 6,
      "name": "Rock_Basalt"
    },
    {
      "x": -5,
      "y": 0,
      "z": 7,
      "name": "Rock_Basalt"
    },
    {
      "x": -5,
      "y": 1,
      "z": 7,
      "name": "Empty"
    },
    {
      "x": -5,
      "y": 2,
      "z": 7,
      "name": "Empty"
    },
    {
      "x": -5,
      "y": 3,
      "z": 7,
      "name": "Empty"
    },
    {
      "x": -5,
      "y": 4,
      "z": 7,
      "name": "Rock_Shale_Brick_Stairs",
      "rotation": 11
    },
    {
      "x": -5,
      "y": 5,
      "z": 7,
      "name": "Rock_Basalt"
    },
    {
      "x": -4,
      "y": 0,
      "z": -7,
      "name": "Rock_Shale"
    },
    {
      "x": -4,
      "y": 1,
      "z": -7,
      "name": "Rock_Shale"
    },
    {
      "x": -4,
      "y": 2,
      "z": -7,
      "name": "Rock_Shale"
    },
    {
      "x": -4,
      "y": 3,
      "z": -7,
      "name": "Rock_Shale"
    },
    {
      "x": -4,
      "y": 4,
      "z": -7,
      "name": "Rock_Shale"
    },
    {
      "x": -4,
      "y": 5,
      "z": -7,
      "name": "Rock_Basalt"
    },
    {
      "x": -4,
      "y": 0,
      "z": -6,
      "name": "Rock_Shale"
    },
    {
      "x": -4,
      "y": 1,
      "z": -6,
      "name": "Rock_Shale"
    },
    {
      "x": -4,
      "y": 2,
      "z": -6,
      "name": "Rock_Shale"
    },
    {
      "x": -4,
      "y": 3,
      "z": -6,
      "name": "Rock_Shale"
    },
    {
      "x": -4,
      "y": 4,
      "z": -6,
      "name": "Rock_Shale"
    },
    {
      "x": -4,
      "y": 5,
      "z": -6,
      "name": "Rock_Basalt"
    },
    {
      "x": -4,
      "y": 0,
      "z": -5,
      "name": "Rock_Shale"
    },
    {
      "x": -4,
      "y": 1,
      "z": -5,
      "name": "Rock_Shale"
    },
    {
      "x": -4,
      "y": 2,
      "z": -5,
      "name": "Rock_Shale"
    },
    {
      "x": -4,
      "y": 3,
      "z": -5,
      "name": "Rock_Shale"
    },
    {
      "x": -4,
      "y": 4,
      "z": -5,
      "name": "Rock_Shale"
    },
    {
      "x": -4,
      "y": 5,
      "z": -5,
      "name": "Rock_Basalt"
    },
    {
      "x": -4,
      "y": 0,
      "z": -4,
      "name": "Rock_Shale"
    },
    {
      "x": -4,
      "y": 1,
      "z": -4,
      "name": "Rock_Shale"
    },
    {
      "x": -4,
      "y": 2,
      "z": -4,
      "name": "Rock_Shale"
    },
    {
      "x": -4,
      "y": 3,
      "z": -4,
      "name": "Rock_Shale"
    },
    {
      "x": -4,
      "y": 4,
      "z": -4,
      "name": "Rock_Shale"
    },
    {
      "x": -4,
      "y": 5,
      "z": -4,
      "name": "Rock_Basalt"
    },
    {
      "x": -4,
      "y": 0,
      "z": -3,
      "name": "Rock_Shale"
    },
    {
      "x": -4,
      "y": 1,
      "z": -3,
      "name": "Rock_Shale"
    },
    {
      "x": -4,
      "y": 2,
      "z": -3,
      "name": "Rock_Shale"
    },
    {
      "x": -4,
      "y": 3,
      "z": -3,
      "name": "Rock_Shale"
    },
    {
      "x": -4,
      "y": 4,
      "z": -3,
      "name": "Rock_Shale"
    },
    {
      "x": -4,
      "y": 5,
      "z": -3,
      "name": "Rock_Basalt"
    },
    {
      "x": -4,
      "y": 0,
      "z": -2,
      "name": "Rock_Shale"
    },
    {
      "x": -4,
      "y": 1,
      "z": -2,
      "name": "Rock_Shale"
    },
    {
      "x": -4,
      "y": 2,
      "z": -2,
      "name": "Rock_Shale"
    },
    {
      "x": -4,
      "y": 3,
      "z": -2,
      "name": "Rock_Shale"
    },
    {
      "x": -4,
      "y": 4,
      "z": -2,
      "name": "Rock_Shale"
    },
    {
      "x": -4,
      "y": 5,
      "z": -2,
      "name": "Rock_Basalt"
    },
    {
      "x": -4,
      "y": 0,
      "z": -1,
      "name": "Rock_Shale"
    },
    {
      "x": -4,
      "y": 1,
      "z": -1,
      "name": "Rock_Shale"
    },
    {
      "x": -4,
      "y": 2,
      "z": -1,
      "name": "Rock_Shale"
    },
    {
      "x": -4,
      "y": 3,
      "z": -1,
      "name": "Rock_Shale"
    },
    {
      "x": -4,
      "y": 4,
      "z": -1,
      "name": "Rock_Shale"
    },
    {
      "x": -4,
      "y": 5,
      "z": -1,
      "name": "Rock_Basalt"
    },
    {
      "x": -4,
      "y": 0,
      "z": 0,
      "name": "Rock_Shale"
    },
    {
      "x": -4,
      "y": 1,
      "z": 0,
      "name": "Rock_Shale"
    },
    {
      "x": -4,
      "y": 2,
      "z": 0,
      "name": "Rock_Shale"
    },
    {
      "x": -4,
      "y": 3,
      "z": 0,
      "name": "Rock_Shale"
    },
    {
      "x": -4,
      "y": 4,
      "z": 0,
      "name": "Rock_Shale"
    },
    {
      "x": -4,
      "y": 5,
      "z": 0,
      "name": "Rock_Basalt"
    },
    {
      "x": -4,
      "y": 0,
      "z": 1,
      "name": "Rock_Shale"
    },
    {
      "x": -4,
      "y": 1,
      "z": 1,
      "name": "Rock_Shale"
    },
    {
      "x": -4,
      "y": 2,
      "z": 1,
      "name": "Rock_Shale"
    },
    {
      "x": -4,
      "y": 3,
      "z": 1,
      "name": "Rock_Shale"
    },
    {
      "x": -4,
      "y": 4,
      "z": 1,
      "name": "Rock_Shale"
    },
    {
      "x": -4,
      "y": 5,
      "z": 1,
      "name": "Rock_Basalt"
    },
    {
      "x": -4,
      "y": 0,
      "z": 2,
      "name": "Rock_Shale"
    },
    {
      "x": -4,
      "y": 1,
      "z": 2,
      "name": "Rock_Shale"
    },
    {
      "x": -4,
      "y": 2,
      "z": 2,
      "name": "Rock_Shale"
    },
    {
      "x": -4,
      "y": 3,
      "z": 2,
      "name": "Rock_Shale"
    },
    {
      "x": -4,
      "y": 4,
      "z": 2,
      "name": "Rock_Shale"
    },
    {
      "x": -4,
      "y": 5,
      "z": 2,
      "name": "Rock_Basalt"
    },
    {
      "x": -4,
      "y": 0,
      "z": 3,
      "name": "Rock_Shale"
    },
    {
      "x": -4,
      "y": 1,
      "z": 3,
      "name": "Rock_Shale"
    },
    {
      "x": -4,
      "y": 2,
      "z": 3,
      "name": "Rock_Shale"
    },
    {
      "x": -4,
      "y": 3,
      "z": 3,
      "name": "Rock_Shale"
    },
    {
      "x": -4,
      "y": 4,
      "z": 3,
      "name": "Rock_Shale"
    },
    {
      "x": -4,
      "y": 5,
      "z": 3,
      "name": "Rock_Basalt"
    },
    {
      "x": -4,
      "y": 0,
      "z": 4,
      "name": "Rock_Shale"
    },
    {
      "x": -4,
      "y": 1,
      "z": 4,
      "name": "Rock_Shale"
    },
    {
      "x": -4,
      "y": 2,
      "z": 4,
      "name": "Rock_Shale"
    },
    {
      "x": -4,
      "y": 3,
      "z": 4,
      "name": "Rock_Shale"
    },
    {
      "x": -4,
      "y": 4,
      "z": 4,
      "name": "Rock_Shale"
    },
    {
      "x": -4,
      "y": 5,
      "z": 4,
      "name": "Rock_Basalt"
    },
    {
      "x": -4,
      "y": 0,
      "z": 5,
      "name": "Rock_Shale"
    },
    {
      "x": -4,
      "y": 1,
      "z": 5,
      "name": "Rock_Basalt"
    },
    {
      "x": -4,
      "y": 2,
      "z": 5,
      "name": "Empty"
    },
    {
      "x": -4,
      "y": 3,
      "z": 5,
      "name": "Rock_Shale"
    },
    {
      "x": -4,
      "y": 4,
      "z": 5,
      "name": "Rock_Shale"
    },
    {
      "x": -4,
      "y": 5,
      "z": 5,
      "name": "Rock_Basalt"
    },
    {
      "x": -4,
      "y": 0,
      "z": 6,
      "name": "Soil_Dirt_Cold"
    },
    {
      "x": -4,
      "y": 1,
      "z": 6,
      "name": "Empty"
    },
    {
      "x": -4,
      "y": 2,
      "z": 6,
      "name": "Empty"
    },
    {
      "x": -4,
      "y": 3,
      "z": 6,
      "name": "Empty"
    },
    {
      "x": -4,
      "y": 4,
      "z": 6,
      "name": "Empty"
    },
    {
      "x": -4,
      "y": 5,
      "z": 6,
      "name": "Rock_Shale"
    },
    {
      "x": -4,
      "y": 0,
      "z": 7,
      "name": "Rock_Basalt"
    },
    {
      "x": -4,
      "y": 1,
      "z": 7,
      "name": "Empty"
    },
    {
      "x": -4,
      "y": 2,
      "z": 7,
      "name": "Empty"
    },
    {
      "x": -4,
      "y": 3,
      "z": 7,
      "name": "Empty"
    },
    {
      "x": -4,
      "y": 4,
      "z": 7,
      "name": "Empty"
    },
    {
      "x": -4,
      "y": 5,
      "z": 7,
      "name": "Rock_Basalt"
    },
    {
      "x": -3,
      "y": 0,
      "z": -7,
      "name": "Rock_Shale"
    },
    {
      "x": -3,
      "y": 1,
      "z": -7,
      "name": "Rock_Shale"
    },
    {
      "x": -3,
      "y": 2,
      "z": -7,
      "name": "Rock_Shale"
    },
    {
      "x": -3,
      "y": 3,
      "z": -7,
      "name": "Rock_Shale"
    },
    {
      "x": -3,
      "y": 4,
      "z": -7,
      "name": "Rock_Shale"
    },
    {
      "x": -3,
      "y": 5,
      "z": -7,
      "name": "Rock_Basalt"
    },
    {
      "x": -3,
      "y": 0,
      "z": -6,
      "name": "Rock_Shale"
    },
    {
      "x": -3,
      "y": 1,
      "z": -6,
      "name": "Rock_Shale"
    },
    {
      "x": -3,
      "y": 2,
      "z": -6,
      "name": "Rock_Shale"
    },
    {
      "x": -3,
      "y": 3,
      "z": -6,
      "name": "Rock_Shale"
    },
    {
      "x": -3,
      "y": 4,
      "z": -6,
      "name": "Rock_Shale"
    },
    {
      "x": -3,
      "y": 5,
      "z": -6,
      "name": "Rock_Basalt"
    },
    {
      "x": -3,
      "y": 0,
      "z": -5,
      "name": "Rock_Shale"
    },
    {
      "x": -3,
      "y": 1,
      "z": -5,
      "name": "Rock_Shale"
    },
    {
      "x": -3,
      "y": 2,
      "z": -5,
      "name": "Rock_Shale"
    },
    {
      "x": -3,
      "y": 3,
      "z": -5,
      "name": "Rock_Shale"
    },
    {
      "x": -3,
      "y": 4,
      "z": -5,
      "name": "Rock_Shale"
    },
    {
      "x": -3,
      "y": 5,
      "z": -5,
      "name": "Rock_Basalt"
    },
    {
      "x": -3,
      "y": 0,
      "z": -4,
      "name": "Rock_Shale"
    },
    {
      "x": -3,
      "y": 1,
      "z": -4,
      "name": "Rock_Shale"
    },
    {
      "x": -3,
      "y": 2,
      "z": -4,
      "name": "Rock_Shale"
    },
    {
      "x": -3,
      "y": 3,
      "z": -4,
      "name": "Rock_Shale"
    },
    {
      "x": -3,
      "y": 4,
      "z": -4,
      "name": "Rock_Shale"
    },
    {
      "x": -3,
      "y": 5,
      "z": -4,
      "name": "Rock_Basalt"
    },
    {
      "x": -3,
      "y": 0,
      "z": -3,
      "name": "Rock_Shale"
    },
    {
      "x": -3,
      "y": 1,
      "z": -3,
      "name": "Rock_Shale"
    },
    {
      "x": -3,
      "y": 2,
      "z": -3,
      "name": "Rock_Shale"
    },
    {
      "x": -3,
      "y": 3,
      "z": -3,
      "name": "Rock_Shale"
    },
    {
      "x": -3,
      "y": 4,
      "z": -3,
      "name": "Rock_Shale"
    },
    {
      "x": -3,
      "y": 5,
      "z": -3,
      "name": "Rock_Basalt"
    },
    {
      "x": -3,
      "y": 0,
      "z": -2,
      "name": "Rock_Shale"
    },
    {
      "x": -3,
      "y": 1,
      "z": -2,
      "name": "Rock_Shale"
    },
    {
      "x": -3,
      "y": 2,
      "z": -2,
      "name": "Rock_Shale"
    },
    {
      "x": -3,
      "y": 3,
      "z": -2,
      "name": "Rock_Shale"
    },
    {
      "x": -3,
      "y": 4,
      "z": -2,
      "name": "Rock_Shale"
    },
    {
      "x": -3,
      "y": 5,
      "z": -2,
      "name": "Rock_Basalt"
    },
    {
      "x": -3,
      "y": 0,
      "z": -1,
      "name": "Rock_Shale"
    },
    {
      "x": -3,
      "y": 1,
      "z": -1,
      "name": "Rock_Shale"
    },
    {
      "x": -3,
      "y": 2,
      "z": -1,
      "name": "Rock_Shale"
    },
    {
      "x": -3,
      "y": 3,
      "z": -1,
      "name": "Rock_Shale"
    },
    {
      "x": -3,
      "y": 4,
      "z": -1,
      "name": "Rock_Shale"
    },
    {
      "x": -3,
      "y": 5,
      "z": -1,
      "name": "Rock_Basalt"
    },
    {
      "x": -3,
      "y": 0,
      "z": 0,
      "name": "Rock_Shale"
    },
    {
      "x": -3,
      "y": 1,
      "z": 0,
      "name": "Rock_Shale"
    },
    {
      "x": -3,
      "y": 2,
      "z": 0,
      "name": "Rock_Shale"
    },
    {
      "x": -3,
      "y": 3,
      "z": 0,
      "name": "Rock_Shale"
    },
    {
      "x": -3,
      "y": 4,
      "z": 0,
      "name": "Rock_Shale"
    },
    {
      "x": -3,
      "y": 5,
      "z": 0,
      "name": "Rock_Basalt"
    },
    {
      "x": -3,
      "y": 0,
      "z": 1,
      "name": "Rock_Shale"
    },
    {
      "x": -3,
      "y": 1,
      "z": 1,
      "name": "Rock_Shale"
    },
    {
      "x": -3,
      "y": 2,
      "z": 1,
      "name": "Rock_Shale"
    },
    {
      "x": -3,
      "y": 3,
      "z": 1,
      "name": "Rock_Shale"
    },
    {
      "x": -3,
      "y": 4,
      "z": 1,
      "name": "Rock_Shale"
    },
    {
      "x": -3,
      "y": 5,
      "z": 1,
      "name": "Rock_Basalt"
    },
    {
      "x": -3,
      "y": 0,
      "z": 2,
      "name": "Rock_Shale"
    },
    {
      "x": -3,
      "y": 1,
      "z": 2,
      "name": "Rock_Shale"
    },
    {
      "x": -3,
      "y": 2,
      "z": 2,
      "name": "Rock_Shale"
    },
    {
      "x": -3,
      "y": 3,
      "z": 2,
      "name": "Rock_Shale"
    },
    {
      "x": -3,
      "y": 4,
      "z": 2,
      "name": "Rock_Shale"
    },
    {
      "x": -3,
      "y": 5,
      "z": 2,
      "name": "Rock_Basalt"
    },
    {
      "x": -3,
      "y": 0,
      "z": 3,
      "name": "Rock_Shale_Cobble"
    },
    {
      "x": -3,
      "y": 1,
      "z": 3,
      "name": "Empty"
    },
    {
      "x": -3,
      "y": 2,
      "z": 3,
      "name": "Empty"
    },
    {
      "x": -3,
      "y": 3,
      "z": 3,
      "name": "Empty"
    },
    {
      "x": -3,
      "y": 4,
      "z": 3,
      "name": "Empty"
    },
    {
      "x": -3,
      "y": 5,
      "z": 3,
      "name": "Rock_Shale"
    },
    {
      "x": -3,
      "y": 0,
      "z": 4,
      "name": "Rock_Shale"
    },
    {
      "x": -3,
      "y": 1,
      "z": 4,
      "name": "Rock_Shale"
    },
    {
      "x": -3,
      "y": 2,
      "z": 4,
      "name": "Rock_Shale"
    },
    {
      "x": -3,
      "y": 3,
      "z": 4,
      "name": "Empty"
    },
    {
      "x": -3,
      "y": 4,
      "z": 4,
      "name": "Plant_Bush_Dead_Hanging"
    },
    {
      "x": -3,
      "y": 5,
      "z": 4,
      "name": "Rock_Shale"
    },
    {
      "x": -3,
      "y": 0,
      "z": 5,
      "name": "Soil_Dirt_Cold"
    },
    {
      "x": -3,
      "y": 1,
      "z": 5,
      "name": "*Plant_Crop_Berry_Winter_Block_State_Definitions_StageFinal",
      "components": {
        "Components": {
          "FarmingBlock": {}
        }
      }
    },
    {
      "x": -3,
      "y": 2,
      "z": 5,
      "name": "Empty"
    },
    {
      "x": -3,
      "y": 3,
      "z": 5,
      "name": "Empty"
    },
    {
      "x": -3,
      "y": 4,
      "z": 5,
      "name": "Empty"
    },
    {
      "x": -3,
      "y": 5,
      "z": 5,
      "name": "Rock_Shale"
    },
    {
      "x": -3,
      "y": 0,
      "z": 6,
      "name": "Soil_Dirt_Cold"
    },
    {
      "x": -3,
      "y": 1,
      "z": 6,
      "name": "Empty"
    },
    {
      "x": -3,
      "y": 2,
      "z": 6,
      "name": "Empty"
    },
    {
      "x": -3,
      "y": 3,
      "z": 6,
      "name": "Empty"
    },
    {
      "x": -3,
      "y": 4,
      "z": 6,
      "name": "Empty"
    },
    {
      "x": -3,
      "y": 5,
      "z": 6,
      "name": "Rock_Shale"
    },
    {
      "x": -3,
      "y": 0,
      "z": 7,
      "name": "Rock_Shale_Brick_Smooth"
    },
    {
      "x": -3,
      "y": 1,
      "z": 7,
      "name": "Empty"
    },
    {
      "x": -3,
      "y": 2,
      "z": 7,
      "name": "Empty"
    },
    {
      "x": -3,
      "y": 3,
      "z": 7,
      "name": "Empty"
    },
    {
      "x": -3,
      "y": 4,
      "z": 7,
      "name": "Empty"
    },
    {
      "x": -3,
      "y": 5,
      "z": 7,
      "name": "Rock_Basalt"
    },
    {
      "x": -2,
      "y": 0,
      "z": -7,
      "name": "Rock_Shale"
    },
    {
      "x": -2,
      "y": 1,
      "z": -7,
      "name": "Rock_Shale"
    },
    {
      "x": -2,
      "y": 2,
      "z": -7,
      "name": "Rock_Shale"
    },
    {
      "x": -2,
      "y": 3,
      "z": -7,
      "name": "Rock_Shale"
    },
    {
      "x": -2,
      "y": 4,
      "z": -7,
      "name": "Rock_Shale"
    },
    {
      "x": -2,
      "y": 5,
      "z": -7,
      "name": "Rock_Basalt"
    },
    {
      "x": -2,
      "y": 0,
      "z": -6,
      "name": "Rock_Shale"
    },
    {
      "x": -2,
      "y": 1,
      "z": -6,
      "name": "Rock_Shale"
    },
    {
      "x": -2,
      "y": 2,
      "z": -6,
      "name": "Rock_Shale"
    },
    {
      "x": -2,
      "y": 3,
      "z": -6,
      "name": "Rock_Shale"
    },
    {
      "x": -2,
      "y": 4,
      "z": -6,
      "name": "Rock_Shale"
    },
    {
      "x": -2,
      "y": 5,
      "z": -6,
      "name": "Rock_Basalt"
    },
    {
      "x": -2,
      "y": 0,
      "z": -5,
      "name": "Rock_Shale"
    },
    {
      "x": -2,
      "y": 1,
      "z": -5,
      "name": "Rock_Shale"
    },
    {
      "x": -2,
      "y": 2,
      "z": -5,
      "name": "Rock_Shale"
    },
    {
      "x": -2,
      "y": 3,
      "z": -5,
      "name": "Rock_Shale"
    },
    {
      "x": -2,
      "y": 4,
      "z": -5,
      "name": "Rock_Shale"
    },
    {
      "x": -2,
      "y": 5,
      "z": -5,
      "name": "Rock_Basalt"
    },
    {
      "x": -2,
      "y": 0,
      "z": -4,
      "name": "Rock_Shale"
    },
    {
      "x": -2,
      "y": 1,
      "z": -4,
      "name": "Rock_Shale"
    },
    {
      "x": -2,
      "y": 2,
      "z": -4,
      "name": "Rock_Shale"
    },
    {
      "x": -2,
      "y": 3,
      "z": -4,
      "name": "Rock_Shale"
    },
    {
      "x": -2,
      "y": 4,
      "z": -4,
      "name": "Rock_Shale"
    },
    {
      "x": -2,
      "y": 5,
      "z": -4,
      "name": "Rock_Basalt"
    },
    {
      "x": -2,
      "y": 0,
      "z": -3,
      "name": "Rock_Shale"
    },
    {
      "x": -2,
      "y": 1,
      "z": -3,
      "name": "Rock_Shale"
    },
    {
      "x": -2,
      "y": 2,
      "z": -3,
      "name": "Rock_Shale"
    },
    {
      "x": -2,
      "y": 3,
      "z": -3,
      "name": "Rock_Shale"
    },
    {
      "x": -2,
      "y": 4,
      "z": -3,
      "name": "Rock_Shale"
    },
    {
      "x": -2,
      "y": 5,
      "z": -3,
      "name": "Rock_Basalt"
    },
    {
      "x": -2,
      "y": 0,
      "z": -2,
      "name": "Rock_Shale"
    },
    {
      "x": -2,
      "y": 1,
      "z": -2,
      "name": "Rock_Shale"
    },
    {
      "x": -2,
      "y": 2,
      "z": -2,
      "name": "Rock_Shale"
    },
    {
      "x": -2,
      "y": 3,
      "z": -2,
      "name": "Rock_Shale"
    },
    {
      "x": -2,
      "y": 4,
      "z": -2,
      "name": "Rock_Shale"
    },
    {
      "x": -2,
      "y": 5,
      "z": -2,
      "name": "Rock_Basalt"
    },
    {
      "x": -2,
      "y": 0,
      "z": -1,
      "name": "Rock_Shale"
    },
    {
      "x": -2,
      "y": 1,
      "z": -1,
      "name": "Rock_Shale"
    },
    {
      "x": -2,
      "y": 2,
      "z": -1,
      "name": "Rock_Shale"
    },
    {
      "x": -2,
      "y": 3,
      "z": -1,
      "name": "Rock_Shale"
    },
    {
      "x": -2,
      "y": 4,
      "z": -1,
      "name": "Rock_Shale"
    },
    {
      "x": -2,
      "y": 5,
      "z": -1,
      "name": "Rock_Basalt"
    },
    {
      "x": -2,
      "y": 0,
      "z": 0,
      "name": "Rock_Shale"
    },
    {
      "x": -2,
      "y": 1,
      "z": 0,
      "name": "Rock_Shale"
    },
    {
      "x": -2,
      "y": 2,
      "z": 0,
      "name": "Rock_Shale"
    },
    {
      "x": -2,
      "y": 3,
      "z": 0,
      "name": "Rock_Shale"
    },
    {
      "x": -2,
      "y": 4,
      "z": 0,
      "name": "Rock_Shale"
    },
    {
      "x": -2,
      "y": 5,
      "z": 0,
      "name": "Rock_Basalt"
    },
    {
      "x": -2,
      "y": 0,
      "z": 1,
      "name": "Rock_Shale"
    },
    {
      "x": -2,
      "y": 1,
      "z": 1,
      "name": "Rock_Shale"
    },
    {
      "x": -2,
      "y": 2,
      "z": 1,
      "name": "Rock_Shale"
    },
    {
      "x": -2,
      "y": 3,
      "z": 1,
      "name": "Rock_Shale"
    },
    {
      "x": -2,
      "y": 4,
      "z": 1,
      "name": "Rock_Shale"
    },
    {
      "x": -2,
      "y": 5,
      "z": 1,
      "name": "Rock_Basalt"
    },
    {
      "x": -2,
      "y": 0,
      "z": 2,
      "name": "Rock_Shale_Cobble"
    },
    {
      "x": -2,
      "y": 1,
      "z": 2,
      "name": "Empty"
    },
    {
      "x": -2,
      "y": 2,
      "z": 2,
      "name": "Empty"
    },
    {
      "x": -2,
      "y": 3,
      "z": 2,
      "name": "Empty"
    },
    {
      "x": -2,
      "y": 4,
      "z": 2,
      "name": "Empty"
    },
    {
      "x": -2,
      "y": 5,
      "z": 2,
      "name": "Rock_Shale"
    },
    {
      "x": -2,
      "y": 0,
      "z": 3,
      "name": "Rock_Shale_Cobble"
    },
    {
      "x": -2,
      "y": 1,
      "z": 3,
      "name": "Empty"
    },
    {
      "x": -2,
      "y": 2,
      "z": 3,
      "name": "Empty"
    },
    {
      "x": -2,
      "y": 3,
      "z": 3,
      "name": "Empty"
    },
    {
      "x": -2,
      "y": 4,
      "z": 3,
      "name": "Empty"
    },
    {
      "x": -2,
      "y": 5,
      "z": 3,
      "name": "Rock_Shale"
    },
    {
      "x": -2,
      "y": 0,
      "z": 4,
      "name": "Rock_Shale_Cobble"
    },
    {
      "x": -2,
      "y": 1,
      "z": 4,
      "name": "Rock_Shale_Brick_Beam"
    },
    {
      "x": -2,
      "y": 2,
      "z": 4,
      "name": "Furniture_Human_Ruins_Torch"
    },
    {
      "x": -2,
      "y": 3,
      "z": 4,
      "name": "Empty"
    },
    {
      "x": -2,
      "y": 4,
      "z": 4,
      "name": "Empty"
    },
    {
      "x": -2,
      "y": 5,
      "z": 4,
      "name": "Rock_Shale"
    },
    {
      "x": -2,
      "y": 0,
      "z": 5,
      "name": "Rock_Shale_Cobble"
    },
    {
      "x": -2,
      "y": 1,
      "z": 5,
      "name": "Deco_Bone_Skulls"
    },
    {
      "x": -2,
      "y": 2,
      "z": 5,
      "name": "Empty"
    },
    {
      "x": -2,
      "y": 3,
      "z": 5,
      "name": "Empty"
    },
    {
      "x": -2,
      "y": 4,
      "z": 5,
      "name": "Empty"
    },
    {
      "x": -2,
      "y": 5,
      "z": 5,
      "name": "Rock_Basalt"
    },
    {
      "x": -2,
      "y": 0,
      "z": 6,
      "name": "Soil_Dirt_Cold"
    },
    {
      "x": -2,
      "y": 1,
      "z": 6,
      "name": "Empty"
    },
    {
      "x": -2,
      "y": 2,
      "z": 6,
      "name": "Empty"
    },
    {
      "x": -2,
      "y": 3,
      "z": 6,
      "name": "Empty"
    },
    {
      "x": -2,
      "y": 4,
      "z": 6,
      "name": "Empty"
    },
    {
      "x": -2,
      "y": 5,
      "z": 6,
      "name": "Rock_Basalt"
    },
    {
      "x": -2,
      "y": 0,
      "z": 7,
      "name": "Soil_Dirt_Cold"
    },
    {
      "x": -2,
      "y": 1,
      "z": 7,
      "name": "Empty"
    },
    {
      "x": -2,
      "y": 2,
      "z": 7,
      "name": "Empty"
    },
    {
      "x": -2,
      "y": 3,
      "z": 7,
      "name": "Empty"
    },
    {
      "x": -2,
      "y": 4,
      "z": 7,
      "name": "Empty"
    },
    {
      "x": -2,
      "y": 5,
      "z": 7,
      "name": "Rock_Basalt"
    },
    {
      "x": -1,
      "y": 0,
      "z": -7,
      "name": "Rock_Shale"
    },
    {
      "x": -1,
      "y": 1,
      "z": -7,
      "name": "Rock_Shale"
    },
    {
      "x": -1,
      "y": 2,
      "z": -7,
      "name": "Rock_Shale"
    },
    {
      "x": -1,
      "y": 3,
      "z": -7,
      "name": "Rock_Shale"
    },
    {
      "x": -1,
      "y": 4,
      "z": -7,
      "name": "Rock_Shale"
    },
    {
      "x": -1,
      "y": 5,
      "z": -7,
      "name": "Rock_Basalt"
    },
    {
      "x": -1,
      "y": 0,
      "z": -6,
      "name": "Rock_Shale"
    },
    {
      "x": -1,
      "y": 1,
      "z": -6,
      "name": "Rock_Shale"
    },
    {
      "x": -1,
      "y": 2,
      "z": -6,
      "name": "Rock_Shale"
    },
    {
      "x": -1,
      "y": 3,
      "z": -6,
      "name": "Rock_Shale"
    },
    {
      "x": -1,
      "y": 4,
      "z": -6,
      "name": "Rock_Shale"
    },
    {
      "x": -1,
      "y": 5,
      "z": -6,
      "name": "Rock_Basalt"
    },
    {
      "x": -1,
      "y": 0,
      "z": -5,
      "name": "Rock_Shale"
    },
    {
      "x": -1,
      "y": 1,
      "z": -5,
      "name": "Rock_Shale"
    },
    {
      "x": -1,
      "y": 2,
      "z": -5,
      "name": "Rock_Shale"
    },
    {
      "x": -1,
      "y": 3,
      "z": -5,
      "name": "Rock_Shale"
    },
    {
      "x": -1,
      "y": 4,
      "z": -5,
      "name": "Rock_Shale"
    },
    {
      "x": -1,
      "y": 5,
      "z": -5,
      "name": "Rock_Basalt"
    },
    {
      "x": -1,
      "y": 0,
      "z": -4,
      "name": "Rock_Shale"
    },
    {
      "x": -1,
      "y": 1,
      "z": -4,
      "name": "Rock_Shale"
    },
    {
      "x": -1,
      "y": 2,
      "z": -4,
      "name": "Rock_Shale"
    },
    {
      "x": -1,
      "y": 3,
      "z": -4,
      "name": "Rock_Shale"
    },
    {
      "x": -1,
      "y": 4,
      "z": -4,
      "name": "Rock_Shale"
    },
    {
      "x": -1,
      "y": 5,
      "z": -4,
      "name": "Rock_Basalt"
    },
    {
      "x": -1,
      "y": 0,
      "z": -3,
      "name": "Rock_Shale"
    },
    {
      "x": -1,
      "y": 1,
      "z": -3,
      "name": "Rock_Shale"
    },
    {
      "x": -1,
      "y": 2,
      "z": -3,
      "name": "Rock_Shale"
    },
    {
      "x": -1,
      "y": 3,
      "z": -3,
      "name": "Rock_Shale"
    },
    {
      "x": -1,
      "y": 4,
      "z": -3,
      "name": "Rock_Shale"
    },
    {
      "x": -1,
      "y": 5,
      "z": -3,
      "name": "Rock_Basalt"
    },
    {
      "x": -1,
      "y": 0,
      "z": -2,
      "name": "Rock_Shale"
    },
    {
      "x": -1,
      "y": 1,
      "z": -2,
      "name": "Rock_Shale"
    },
    {
      "x": -1,
      "y": 2,
      "z": -2,
      "name": "Rock_Shale"
    },
    {
      "x": -1,
      "y": 3,
      "z": -2,
      "name": "Rock_Shale"
    },
    {
      "x": -1,
      "y": 4,
      "z": -2,
      "name": "Rock_Shale"
    },
    {
      "x": -1,
      "y": 5,
      "z": -2,
      "name": "Rock_Basalt"
    },
    {
      "x": -1,
      "y": 0,
      "z": -1,
      "name": "Rock_Shale"
    },
    {
      "x": -1,
      "y": 1,
      "z": -1,
      "name": "Rock_Shale"
    },
    {
      "x": -1,
      "y": 2,
      "z": -1,
      "name": "Rock_Shale"
    },
    {
      "x": -1,
      "y": 3,
      "z": -1,
      "name": "Rock_Shale"
    },
    {
      "x": -1,
      "y": 4,
      "z": -1,
      "name": "Rock_Shale"
    },
    {
      "x": -1,
      "y": 5,
      "z": -1,
      "name": "Rock_Basalt"
    },
    {
      "x": -1,
      "y": 0,
      "z": 0,
      "name": "Rock_Shale"
    },
    {
      "x": -1,
      "y": 1,
      "z": 0,
      "name": "Rock_Shale"
    },
    {
      "x": -1,
      "y": 2,
      "z": 0,
      "name": "Rock_Shale"
    },
    {
      "x": -1,
      "y": 3,
      "z": 0,
      "name": "Rock_Shale"
    },
    {
      "x": -1,
      "y": 4,
      "z": 0,
      "name": "Rock_Shale"
    },
    {
      "x": -1,
      "y": 5,
      "z": 0,
      "name": "Rock_Basalt"
    },
    {
      "x": -1,
      "y": 0,
      "z": 1,
      "name": "Rock_Shale"
    },
    {
      "x": -1,
      "y": 1,
      "z": 1,
      "name": "Empty"
    },
    {
      "x": -1,
      "y": 2,
      "z": 1,
      "name": "Rock_Shale_Stalactites_Large",
      "filler": 31744,
      "rotation": 8
    },
    {
      "x": -1,
      "y": 3,
      "z": 1,
      "name": "Rock_Shale_Stalactites_Large",
      "rotation": 8
    },
    {
      "x": -1,
      "y": 4,
      "z": 1,
      "name": "Rock_Shale"
    },
    {
      "x": -1,
      "y": 5,
      "z": 1,
      "name": "Rock_Basalt"
    },
    {
      "x": -1,
      "y": 0,
      "z": 2,
      "name": "Empty"
    },
    {
      "x": -1,
      "y": 1,
      "z": 2,
      "name": "Empty"
    },
    {
      "x": -1,
      "y": 2,
      "z": 2,
      "name": "Empty"
    },
    {
      "x": -1,
      "y": 3,
      "z": 2,
      "name": "Empty"
    },
    {
      "x": -1,
      "y": 4,
      "z": 2,
      "name": "Plant_Bush_Dead_Hanging"
    },
    {
      "x": -1,
      "y": 5,
      "z": 2,
      "name": "Rock_Basalt"
    },
    {
      "x": -1,
      "y": 0,
      "z": 3,
      "name": "Rock_Shale_Cobble_Half"
    },
    {
      "x": -1,
      "y": 1,
      "z": 3,
      "name": "Empty"
    },
    {
      "x": -1,
      "y": 2,
      "z": 3,
      "name": "Empty"
    },
    {
      "x": -1,
      "y": 3,
      "z": 3,
      "name": "Empty"
    },
    {
      "x": -1,
      "y": 4,
      "z": 3,
      "name": "Empty"
    },
    {
      "x": -1,
      "y": 5,
      "z": 3,
      "name": "Rock_Basalt"
    },
    {
      "x": -1,
      "y": 0,
      "z": 4,
      "name": "Rock_Shale_Cobble_Half"
    },
    {
      "x": -1,
      "y": 1,
      "z": 4,
      "name": "Empty"
    },
    {
      "x": -1,
      "y": 2,
      "z": 4,
      "name": "Empty"
    },
    {
      "x": -1,
      "y": 3,
      "z": 4,
      "name": "Empty"
    },
    {
      "x": -1,
      "y": 4,
      "z": 4,
      "name": "Empty"
    },
    {
      "x": -1,
      "y": 5,
      "z": 4,
      "name": "Rock_Basalt"
    },
    {
      "x": -1,
      "y": 0,
      "z": 5,
      "name": "Rock_Shale_Brick"
    },
    {
      "x": -1,
      "y": 1,
      "z": 5,
      "name": "Empty"
    },
    {
      "x": -1,
      "y": 2,
      "z": 5,
      "name": "Empty"
    },
    {
      "x": -1,
      "y": 3,
      "z": 5,
      "name": "Empty"
    },
    {
      "x": -1,
      "y": 4,
      "z": 5,
      "name": "Empty"
    },
    {
      "x": -1,
      "y": 5,
      "z": 5,
      "name": "Rock_Basalt"
    },
    {
      "x": -1,
      "y": 0,
      "z": 6,
      "name": "Soil_Dirt_Cold"
    },
    {
      "x": -1,
      "y": 1,
      "z": 6,
      "name": "Empty"
    },
    {
      "x": -1,
      "y": 2,
      "z": 6,
      "name": "Empty"
    },
    {
      "x": -1,
      "y": 3,
      "z": 6,
      "name": "Empty"
    },
    {
      "x": -1,
      "y": 4,
      "z": 6,
      "name": "Empty"
    },
    {
      "x": -1,
      "y": 5,
      "z": 6,
      "name": "Rock_Basalt"
    },
    {
      "x": -1,
      "y": 0,
      "z": 7,
      "name": "Rock_Shale_Brick_Smooth"
    },
    {
      "x": -1,
      "y": 1,
      "z": 7,
      "name": "Empty"
    },
    {
      "x": -1,
      "y": 2,
      "z": 7,
      "name": "Empty"
    },
    {
      "x": -1,
      "y": 3,
      "z": 7,
      "name": "Empty"
    },
    {
      "x": -1,
      "y": 4,
      "z": 7,
      "name": "Empty"
    },
    {
      "x": -1,
      "y": 5,
      "z": 7,
      "name": "Rock_Basalt"
    },
    {
      "x": 0,
      "y": 0,
      "z": -7,
      "name": "Rock_Shale"
    },
    {
      "x": 0,
      "y": 1,
      "z": -7,
      "name": "Rock_Shale"
    },
    {
      "x": 0,
      "y": 2,
      "z": -7,
      "name": "Rock_Shale"
    },
    {
      "x": 0,
      "y": 3,
      "z": -7,
      "name": "Rock_Shale"
    },
    {
      "x": 0,
      "y": 4,
      "z": -7,
      "name": "Rock_Shale"
    },
    {
      "x": 0,
      "y": 5,
      "z": -7,
      "name": "Rock_Basalt"
    },
    {
      "x": 0,
      "y": 0,
      "z": -6,
      "name": "Rock_Shale"
    },
    {
      "x": 0,
      "y": 1,
      "z": -6,
      "name": "Rock_Shale"
    },
    {
      "x": 0,
      "y": 2,
      "z": -6,
      "name": "Rock_Shale"
    },
    {
      "x": 0,
      "y": 3,
      "z": -6,
      "name": "Rock_Shale"
    },
    {
      "x": 0,
      "y": 4,
      "z": -6,
      "name": "Rock_Shale"
    },
    {
      "x": 0,
      "y": 5,
      "z": -6,
      "name": "Rock_Basalt"
    },
    {
      "x": 0,
      "y": 0,
      "z": -5,
      "name": "Rock_Shale"
    },
    {
      "x": 0,
      "y": 1,
      "z": -5,
      "name": "Rock_Shale"
    },
    {
      "x": 0,
      "y": 2,
      "z": -5,
      "name": "Rock_Shale"
    },
    {
      "x": 0,
      "y": 3,
      "z": -5,
      "name": "Rock_Shale"
    },
    {
      "x": 0,
      "y": 4,
      "z": -5,
      "name": "Rock_Shale"
    },
    {
      "x": 0,
      "y": 5,
      "z": -5,
      "name": "Rock_Basalt"
    },
    {
      "x": 0,
      "y": 0,
      "z": -4,
      "name": "Rock_Shale"
    },
    {
      "x": 0,
      "y": 1,
      "z": -4,
      "name": "Rock_Shale"
    },
    {
      "x": 0,
      "y": 2,
      "z": -4,
      "name": "Rock_Shale"
    },
    {
      "x": 0,
      "y": 3,
      "z": -4,
      "name": "Rock_Shale"
    },
    {
      "x": 0,
      "y": 4,
      "z": -4,
      "name": "Rock_Shale"
    },
    {
      "x": 0,
      "y": 5,
      "z": -4,
      "name": "Rock_Basalt"
    },
    {
      "x": 0,
      "y": 0,
      "z": -3,
      "name": "Rock_Shale"
    },
    {
      "x": 0,
      "y": 1,
      "z": -3,
      "name": "Rock_Shale"
    },
    {
      "x": 0,
      "y": 2,
      "z": -3,
      "name": "Rock_Shale"
    },
    {
      "x": 0,
      "y": 3,
      "z": -3,
      "name": "Rock_Shale"
    },
    {
      "x": 0,
      "y": 4,
      "z": -3,
      "name": "Rock_Shale"
    },
    {
      "x": 0,
      "y": 5,
      "z": -3,
      "name": "Rock_Basalt"
    },
    {
      "x": 0,
      "y": 0,
      "z": -2,
      "name": "Rock_Shale"
    },
    {
      "x": 0,
      "y": 1,
      "z": -2,
      "name": "Rock_Shale"
    },
    {
      "x": 0,
      "y": 2,
      "z": -2,
      "name": "Rock_Shale"
    },
    {
      "x": 0,
      "y": 3,
      "z": -2,
      "name": "Rock_Shale"
    },
    {
      "x": 0,
      "y": 4,
      "z": -2,
      "name": "Rock_Shale"
    },
    {
      "x": 0,
      "y": 5,
      "z": -2,
      "name": "Rock_Basalt"
    },
    {
      "x": 0,
      "y": 0,
      "z": -1,
      "name": "Empty"
    },
    {
      "x": 0,
      "y": 1,
      "z": -1,
      "name": "Empty"
    },
    {
      "x": 0,
      "y": 2,
      "z": -1,
      "name": "Empty"
    },
    {
      "x": 0,
      "y": 3,
      "z": -1,
      "name": "Rock_Shale"
    },
    {
      "x": 0,
      "y": 4,
      "z": -1,
      "name": "Rock_Shale"
    },
    {
      "x": 0,
      "y": 5,
      "z": -1,
      "name": "Rock_Basalt"
    },
    {
      "x": 0,
      "y": 0,
      "z": 0,
      "name": "Empty"
    },
    {
      "x": 0,
      "y": 1,
      "z": 0,
      "name": "Empty"
    },
    {
      "x": 0,
      "y": 2,
      "z": 0,
      "name": "Rock_Shale_Stalactites_Small",
      "rotation": 8
    },
    {
      "x": 0,
      "y": 3,
      "z": 0,
      "name": "Rock_Shale"
    },
    {
      "x": 0,
      "y": 4,
      "z": 0,
      "name": "Rock_Shale"
    },
    {
      "x": 0,
      "y": 5,
      "z": 0,
      "name": "Rock_Basalt"
    },
    {
      "x": 0,
      "y": 0,
      "z": 1,
      "name": "Plant_Bush_Dead_Twisted"
    },
    {
      "x": 0,
      "y": 1,
      "z": 1,
      "name": "Empty"
    },
    {
      "x": 0,
      "y": 2,
      "z": 1,
      "name": "Empty"
    },
    {
      "x": 0,
      "y": 3,
      "z": 1,
      "name": "Empty"
    },
    {
      "x": 0,
      "y": 4,
      "z": 1,
      "name": "Empty"
    },
    {
      "x": 0,
      "y": 5,
      "z": 1,
      "name": "Rock_Basalt"
    },
    {
      "x": 0,
      "y": 0,
      "z": 2,
      "name": "Empty"
    },
    {
      "x": 0,
      "y": 1,
      "z": 2,
      "name": "Empty"
    },
    {
      "x": 0,
      "y": 2,
      "z": 2,
      "name": "Empty"
    },
    {
      "x": 0,
      "y": 3,
      "z": 2,
      "name": "Empty"
    },
    {
      "x": 0,
      "y": 4,
      "z": 2,
      "name": "Empty"
    },
    {
      "x": 0,
      "y": 5,
      "z": 2,
      "name": "Rock_Basalt"
    },
    {
      "x": 0,
      "y": 0,
      "z": 3,
      "name": "Empty"
    },
    {
      "x": 0,
      "y": 1,
      "z": 3,
      "name": "Empty"
    },
    {
      "x": 0,
      "y": 2,
      "z": 3,
      "name": "Empty"
    },
    {
      "x": 0,
      "y": 3,
      "z": 3,
      "name": "Empty"
    },
    {
      "x": 0,
      "y": 4,
      "z": 3,
      "name": "Empty"
    },
    {
      "x": 0,
      "y": 5,
      "z": 3,
      "name": "Rock_Basalt"
    },
    {
      "x": 0,
      "y": 0,
      "z": 4,
      "name": "Rock_Shale_Brick_Half"
    },
    {
      "x": 0,
      "y": 1,
      "z": 4,
      "name": "Empty"
    },
    {
      "x": 0,
      "y": 2,
      "z": 4,
      "name": "Empty"
    },
    {
      "x": 0,
      "y": 3,
      "z": 4,
      "name": "Empty"
    },
    {
      "x": 0,
      "y": 4,
      "z": 4,
      "name": "Empty"
    },
    {
      "x": 0,
      "y": 5,
      "z": 4,
      "name": "Rock_Basalt"
    },
    {
      "x": 0,
      "y": 0,
      "z": 5,
      "name": "Rock_Shale_Brick"
    },
    {
      "x": 0,
      "y": 1,
      "z": 5,
      "name": "Empty"
    },
    {
      "x": 0,
      "y": 2,
      "z": 5,
      "name": "Empty"
    },
    {
      "x": 0,
      "y": 3,
      "z": 5,
      "name": "Empty"
    },
    {
      "x": 0,
      "y": 4,
      "z": 5,
      "name": "Empty"
    },
    {
      "x": 0,
      "y": 5,
      "z": 5,
      "name": "Rock_Basalt"
    },
    {
      "x": 0,
      "y": 0,
      "z": 6,
      "name": "Rock_Shale_Brick"
    },
    {
      "x": 0,
      "y": 1,
      "z": 6,
      "name": "Empty"
    },
    {
      "x": 0,
      "y": 2,
      "z": 6,
      "name": "Empty"
    },
    {
      "x": 0,
      "y": 3,
      "z": 6,
      "name": "Empty"
    },
    {
      "x": 0,
      "y": 4,
      "z": 6,
      "name": "Empty"
    },
    {
      "x": 0,
      "y": 5,
      "z": 6,
      "name": "Rock_Basalt"
    },
    {
      "x": 0,
      "y": 0,
      "z": 7,
      "name": "Rock_Shale_Brick_Smooth"
    },
    {
      "x": 0,
      "y": 1,
      "z": 7,
      "name": "Empty"
    },
    {
      "x": 0,
      "y": 2,
      "z": 7,
      "name": "Empty"
    },
    {
      "x": 0,
      "y": 3,
      "z": 7,
      "name": "Empty"
    },
    {
      "x": 0,
      "y": 4,
      "z": 7,
      "name": "Empty"
    },
    {
      "x": 0,
      "y": 5,
      "z": 7,
      "name": "Rock_Basalt"
    },
    {
      "x": 1,
      "y": 0,
      "z": -7,
      "name": "Rock_Shale"
    },
    {
      "x": 1,
      "y": 1,
      "z": -7,
      "name": "Rock_Shale"
    },
    {
      "x": 1,
      "y": 2,
      "z": -7,
      "name": "Rock_Shale"
    },
    {
      "x": 1,
      "y": 3,
      "z": -7,
      "name": "Rock_Shale"
    },
    {
      "x": 1,
      "y": 4,
      "z": -7,
      "name": "Rock_Shale"
    },
    {
      "x": 1,
      "y": 5,
      "z": -7,
      "name": "Rock_Basalt"
    },
    {
      "x": 1,
      "y": 0,
      "z": -6,
      "name": "Rock_Shale"
    },
    {
      "x": 1,
      "y": 1,
      "z": -6,
      "name": "Rock_Shale"
    },
    {
      "x": 1,
      "y": 2,
      "z": -6,
      "name": "Rock_Shale"
    },
    {
      "x": 1,
      "y": 3,
      "z": -6,
      "name": "Rock_Shale"
    },
    {
      "x": 1,
      "y": 4,
      "z": -6,
      "name": "Rock_Shale"
    },
    {
      "x": 1,
      "y": 5,
      "z": -6,
      "name": "Rock_Basalt"
    },
    {
      "x": 1,
      "y": 0,
      "z": -5,
      "name": "Rock_Shale"
    },
    {
      "x": 1,
      "y": 1,
      "z": -5,
      "name": "Rock_Shale"
    },
    {
      "x": 1,
      "y": 2,
      "z": -5,
      "name": "Rock_Shale"
    },
    {
      "x": 1,
      "y": 3,
      "z": -5,
      "name": "Rock_Shale"
    },
    {
      "x": 1,
      "y": 4,
      "z": -5,
      "name": "Rock_Shale"
    },
    {
      "x": 1,
      "y": 5,
      "z": -5,
      "name": "Rock_Basalt"
    },
    {
      "x": 1,
      "y": 0,
      "z": -4,
      "name": "Rock_Shale"
    },
    {
      "x": 1,
      "y": 1,
      "z": -4,
      "name": "Rock_Shale"
    },
    {
      "x": 1,
      "y": 2,
      "z": -4,
      "name": "Rock_Shale"
    },
    {
      "x": 1,
      "y": 3,
      "z": -4,
      "name": "Rock_Shale"
    },
    {
      "x": 1,
      "y": 4,
      "z": -4,
      "name": "Rock_Shale"
    },
    {
      "x": 1,
      "y": 5,
      "z": -4,
      "name": "Rock_Basalt"
    },
    {
      "x": 1,
      "y": 0,
      "z": -3,
      "name": "Rock_Shale"
    },
    {
      "x": 1,
      "y": 1,
      "z": -3,
      "name": "Rock_Shale"
    },
    {
      "x": 1,
      "y": 2,
      "z": -3,
      "name": "Rock_Shale"
    },
    {
      "x": 1,
      "y": 3,
      "z": -3,
      "name": "Empty"
    },
    {
      "x": 1,
      "y": 4,
      "z": -3,
      "name": "Empty"
    },
    {
      "x": 1,
      "y": 5,
      "z": -3,
      "name": "Rock_Shale"
    },
    {
      "x": 1,
      "y": 0,
      "z": -2,
      "name": "Rock_Shale"
    },
    {
      "x": 1,
      "y": 1,
      "z": -2,
      "name": "Rock_Shale"
    },
    {
      "x": 1,
      "y": 2,
      "z": -2,
      "name": "Empty"
    },
    {
      "x": 1,
      "y": 3,
      "z": -2,
      "name": "Empty"
    },
    {
      "x": 1,
      "y": 4,
      "z": -2,
      "name": "Empty"
    },
    {
      "x": 1,
      "y": 5,
      "z": -2,
      "name": "Rock_Basalt"
    },
    {
      "x": 1,
      "y": 0,
      "z": -1,
      "name": "Empty"
    },
    {
      "x": 1,
      "y": 1,
      "z": -1,
      "name": "Empty"
    },
    {
      "x": 1,
      "y": 2,
      "z": -1,
      "name": "Empty"
    },
    {
      "x": 1,
      "y": 3,
      "z": -1,
      "name": "Empty"
    },
    {
      "x": 1,
      "y": 4,
      "z": -1,
      "name": "Empty"
    },
    {
      "x": 1,
      "y": 5,
      "z": -1,
      "name": "Rock_Basalt"
    },
    {
      "x": 1,
      "y": 0,
      "z": 0,
      "name": "Empty"
    },
    {
      "x": 1,
      "y": 1,
      "z": 0,
      "name": "Empty"
    },
    {
      "x": 1,
      "y": 2,
      "z": 0,
      "name": "Empty"
    },
    {
      "x": 1,
      "y": 3,
      "z": 0,
      "name": "Empty"
    },
    {
      "x": 1,
      "y": 4,
      "z": 0,
      "name": "Empty"
    },
    {
      "x": 1,
      "y": 5,
      "z": 0,
      "name": "Rock_Basalt"
    },
    {
      "x": 1,
      "y": 0,
      "z": 1,
      "name": "Empty"
    },
    {
      "x": 1,
      "y": 1,
      "z": 1,
      "name": "Empty"
    },
    {
      "x": 1,
      "y": 2,
      "z": 1,
      "name": "Empty"
    },
    {
      "x": 1,
      "y": 3,
      "z": 1,
      "name": "Empty"
    },
    {
      "x": 1,
      "y": 4,
      "z": 1,
      "name": "Empty"
    },
    {
      "x": 1,
      "y": 5,
      "z": 1,
      "name": "Rock_Basalt"
    },
    {
      "x": 1,
      "y": 0,
      "z": 2,
      "name": "Empty"
    },
    {
      "x": 1,
      "y": 1,
      "z": 2,
      "name": "Empty"
    },
    {
      "x": 1,
      "y": 2,
      "z": 2,
      "name": "Empty"
    },
    {
      "x": 1,
      "y": 3,
      "z": 2,
      "name": "Empty"
    },
    {
      "x": 1,
      "y": 4,
      "z": 2,
      "name": "Empty"
    },
    {
      "x": 1,
      "y": 5,
      "z": 2,
      "name": "Rock_Basalt"
    },
    {
      "x": 1,
      "y": 0,
      "z": 3,
      "name": "Empty"
    },
    {
      "x": 1,
      "y": 1,
      "z": 3,
      "name": "Empty"
    },
    {
      "x": 1,
      "y": 2,
      "z": 3,
      "name": "Empty"
    },
    {
      "x": 1,
      "y": 3,
      "z": 3,
      "name": "Empty"
    },
    {
      "x": 1,
      "y": 4,
      "z": 3,
      "name": "Empty"
    },
    {
      "x": 1,
      "y": 5,
      "z": 3,
      "name": "Rock_Basalt"
    },
    {
      "x": 1,
      "y": 0,
      "z": 4,
      "name": "Rock_Shale_Brick_Half"
    },
    {
      "x": 1,
      "y": 1,
      "z": 4,
      "name": "Empty"
    },
    {
      "x": 1,
      "y": 2,
      "z": 4,
      "name": "Empty"
    },
    {
      "x": 1,
      "y": 3,
      "z": 4,
      "name": "Empty"
    },
    {
      "x": 1,
      "y": 4,
      "z": 4,
      "name": "Empty"
    },
    {
      "x": 1,
      "y": 5,
      "z": 4,
      "name": "Rock_Basalt"
    },
    {
      "x": 1,
      "y": 0,
      "z": 5,
      "name": "Rock_Shale_Brick_Half"
    },
    {
      "x": 1,
      "y": 1,
      "z": 5,
      "name": "Empty"
    },
    {
      "x": 1,
      "y": 2,
      "z": 5,
      "name": "Empty"
    },
    {
      "x": 1,
      "y": 3,
      "z": 5,
      "name": "Empty"
    },
    {
      "x": 1,
      "y": 4,
      "z": 5,
      "name": "Empty"
    },
    {
      "x": 1,
      "y": 5,
      "z": 5,
      "name": "Rock_Basalt"
    },
    {
      "x": 1,
      "y": 0,
      "z": 6,
      "name": "Rock_Basalt"
    },
    {
      "x": 1,
      "y": 1,
      "z": 6,
      "name": "Wood_Redwood_Branch_Long"
    },
    {
      "x": 1,
      "y": 2,
      "z": 6,
      "name": "Wood_Redwood_Branch_Long"
    },
    {
      "x": 1,
      "y": 3,
      "z": 6,
      "name": "Wood_Redwood_Branch_Long"
    },
    {
      "x": 1,
      "y": 4,
      "z": 6,
      "name": "Wood_Redwood_Branch_Long"
    },
    {
      "x": 1,
      "y": 5,
      "z": 6,
      "name": "Rock_Basalt"
    },
    {
      "x": 1,
      "y": 0,
      "z": 7,
      "name": "Rock_Basalt"
    },
    {
      "x": 1,
      "y": 1,
      "z": 7,
      "name": "Furniture_Ancient_Barrel"
    },
    {
      "x": 1,
      "y": 2,
      "z": 7,
      "name": "Empty"
    },
    {
      "x": 1,
      "y": 3,
      "z": 7,
      "name": "Empty"
    },
    {
      "x": 1,
      "y": 4,
      "z": 7,
      "name": "Rock_Shale_Brick_Stairs",
      "rotation": 9
    },
    {
      "x": 1,
      "y": 5,
      "z": 7,
      "name": "Rock_Basalt"
    },
    {
      "x": 2,
      "y": 0,
      "z": -7,
      "name": "Rock_Shale"
    },
    {
      "x": 2,
      "y": 1,
      "z": -7,
      "name": "Rock_Shale"
    },
    {
      "x": 2,
      "y": 2,
      "z": -7,
      "name": "Rock_Shale"
    },
    {
      "x": 2,
      "y": 3,
      "z": -7,
      "name": "Rock_Shale"
    },
    {
      "x": 2,
      "y": 4,
      "z": -7,
      "name": "Rock_Shale"
    },
    {
      "x": 2,
      "y": 5,
      "z": -7,
      "name": "Rock_Basalt"
    },
    {
      "x": 2,
      "y": 0,
      "z": -6,
      "name": "Rock_Shale"
    },
    {
      "x": 2,
      "y": 1,
      "z": -6,
      "name": "Rock_Shale"
    },
    {
      "x": 2,
      "y": 2,
      "z": -6,
      "name": "Rock_Shale"
    },
    {
      "x": 2,
      "y": 3,
      "z": -6,
      "name": "Rock_Shale"
    },
    {
      "x": 2,
      "y": 4,
      "z": -6,
      "name": "Rock_Shale"
    },
    {
      "x": 2,
      "y": 5,
      "z": -6,
      "name": "Rock_Basalt"
    },
    {
      "x": 2,
      "y": 0,
      "z": -5,
      "name": "Rock_Shale"
    },
    {
      "x": 2,
      "y": 1,
      "z": -5,
      "name": "Rock_Shale"
    },
    {
      "x": 2,
      "y": 2,
      "z": -5,
      "name": "Rock_Shale"
    },
    {
      "x": 2,
      "y": 3,
      "z": -5,
      "name": "Rock_Shale"
    },
    {
      "x": 2,
      "y": 4,
      "z": -5,
      "name": "Rock_Shale"
    },
    {
      "x": 2,
      "y": 5,
      "z": -5,
      "name": "Rock_Basalt"
    },
    {
      "x": 2,
      "y": 0,
      "z": -4,
      "name": "Rock_Shale"
    },
    {
      "x": 2,
      "y": 1,
      "z": -4,
      "name": "Rock_Shale"
    },
    {
      "x": 2,
      "y": 2,
      "z": -4,
      "name": "Rock_Shale"
    },
    {
      "x": 2,
      "y": 3,
      "z": -4,
      "name": "Rock_Shale"
    },
    {
      "x": 2,
      "y": 4,
      "z": -4,
      "name": "Rock_Shale"
    },
    {
      "x": 2,
      "y": 5,
      "z": -4,
      "name": "Rock_Basalt"
    },
    {
      "x": 2,
      "y": 0,
      "z": -3,
      "name": "Rock_Shale"
    },
    {
      "x": 2,
      "y": 1,
      "z": -3,
      "name": "Rock_Shale"
    },
    {
      "x": 2,
      "y": 2,
      "z": -3,
      "name": "Rock_Shale"
    },
    {
      "x": 2,
      "y": 3,
      "z": -3,
      "name": "Empty"
    },
    {
      "x": 2,
      "y": 4,
      "z": -3,
      "name": "Empty"
    },
    {
      "x": 2,
      "y": 5,
      "z": -3,
      "name": "Rock_Shale"
    },
    {
      "x": 2,
      "y": 0,
      "z": -2,
      "name": "Rock_Shale_Brick"
    },
    {
      "x": 2,
      "y": 1,
      "z": -2,
      "name": "Empty"
    },
    {
      "x": 2,
      "y": 2,
      "z": -2,
      "name": "Empty"
    },
    {
      "x": 2,
      "y": 3,
      "z": -2,
      "name": "Empty"
    },
    {
      "x": 2,
      "y": 4,
      "z": -2,
      "name": "Empty"
    },
    {
      "x": 2,
      "y": 5,
      "z": -2,
      "name": "Rock_Shale"
    },
    {
      "x": 2,
      "y": 0,
      "z": -1,
      "name": "Rock_Shale_Brick_Half"
    },
    {
      "x": 2,
      "y": 1,
      "z": -1,
      "name": "Empty"
    },
    {
      "x": 2,
      "y": 2,
      "z": -1,
      "name": "Empty"
    },
    {
      "x": 2,
      "y": 3,
      "z": -1,
      "name": "Empty"
    },
    {
      "x": 2,
      "y": 4,
      "z": -1,
      "name": "Empty"
    },
    {
      "x": 2,
      "y": 5,
      "z": -1,
      "name": "Rock_Basalt"
    },
    {
      "x": 2,
      "y": 0,
      "z": 0,
      "name": "Rock_Shale_Cobble_Half"
    },
    {
      "x": 2,
      "y": 1,
      "z": 0,
      "name": "Empty"
    },
    {
      "x": 2,
      "y": 2,
      "z": 0,
      "name": "Empty"
    },
    {
      "x": 2,
      "y": 3,
      "z": 0,
      "name": "Empty"
    },
    {
      "x": 2,
      "y": 4,
      "z": 0,
      "name": "Empty"
    },
    {
      "x": 2,
      "y": 5,
      "z": 0,
      "name": "Rock_Basalt"
    },
    {
      "x": 2,
      "y": 0,
      "z": 1,
      "name": "Empty"
    },
    {
      "x": 2,
      "y": 1,
      "z": 1,
      "name": "Empty"
    },
    {
      "x": 2,
      "y": 2,
      "z": 1,
      "name": "Empty"
    },
    {
      "x": 2,
      "y": 3,
      "z": 1,
      "name": "Empty"
    },
    {
      "x": 2,
      "y": 4,
      "z": 1,
      "name": "Empty"
    },
    {
      "x": 2,
      "y": 5,
      "z": 1,
      "name": "Rock_Basalt"
    },
    {
      "x": 2,
      "y": 0,
      "z": 2,
      "name": "Empty"
    },
    {
      "x": 2,
      "y": 1,
      "z": 2,
      "name": "Empty"
    },
    {
      "x": 2,
      "y": 2,
      "z": 2,
      "name": "Empty"
    },
    {
      "x": 2,
      "y": 3,
      "z": 2,
      "name": "Empty"
    },
    {
      "x": 2,
      "y": 4,
      "z": 2,
      "name": "Empty"
    },
    {
      "x": 2,
      "y": 5,
      "z": 2,
      "name": "Rock_Basalt"
    },
    {
      "x": 2,
      "y": 0,
      "z": 3,
      "name": "Empty"
    },
    {
      "x": 2,
      "y": 1,
      "z": 3,
      "name": "Empty"
    },
    {
      "x": 2,
      "y": 2,
      "z": 3,
      "name": "Empty"
    },
    {
      "x": 2,
      "y": 3,
      "z": 3,
      "name": "Empty"
    },
    {
      "x": 2,
      "y": 4,
      "z": 3,
      "name": "Empty"
    },
    {
      "x": 2,
      "y": 5,
      "z": 3,
      "name": "Rock_Basalt"
    },
    {
      "x": 2,
      "y": 0,
      "z": 4,
      "name": "Empty"
    },
    {
      "x": 2,
      "y": 1,
      "z": 4,
      "name": "Empty"
    },
    {
      "x": 2,
      "y": 2,
      "z": 4,
      "name": "Empty"
    },
    {
      "x": 2,
      "y": 3,
      "z": 4,
      "name": "Empty"
    },
    {
      "x": 2,
      "y": 4,
      "z": 4,
      "name": "Empty"
    },
    {
      "x": 2,
      "y": 5,
      "z": 4,
      "name": "Rock_Basalt"
    },
    {
      "x": 2,
      "y": 0,
      "z": 5,
      "name": "Empty"
    },
    {
      "x": 2,
      "y": 1,
      "z": 5,
      "name": "Empty"
    },
    {
      "x": 2,
      "y": 2,
      "z": 5,
      "name": "Empty"
    },
    {
      "x": 2,
      "y": 3,
      "z": 5,
      "name": "Empty"
    },
    {
      "x": 2,
      "y": 4,
      "z": 5,
      "name": "Empty"
    },
    {
      "x": 2,
      "y": 5,
      "z": 5,
      "name": "Rock_Shale"
    },
    {
      "x": 2,
      "y": 0,
      "z": 6,
      "name": "Rock_Basalt"
    },
    {
      "x": 2,
      "y": 1,
      "z": 6,
      "name": "Empty"
    },
    {
      "x": 2,
      "y": 2,
      "z": 6,
      "name": "Empty"
    },
    {
      "x": 2,
      "y": 3,
      "z": 6,
      "name": "Rock_Shale_Stalactites_Large",
      "filler": 31744,
      "rotation": 8
    },
    {
      "x": 2,
      "y": 4,
      "z": 6,
      "name": "Rock_Shale_Stalactites_Large",
      "rotation": 8
    },
    {
      "x": 2,
      "y": 5,
      "z": 6,
      "name": "Rock_Shale"
    },
    {
      "x": 2,
      "y": 0,
      "z": 7,
      "name": "Rock_Shale_Brick_Smooth"
    },
    {
      "x": 2,
      "y": 1,
      "z": 7,
      "name": "Rock_Shale_Brick_Pillar_Base"
    },
    {
      "x": 2,
      "y": 2,
      "z": 7,
      "name": "Rock_Shale_Brick_Pillar_Middle"
    },
    {
      "x": 2,
      "y": 3,
      "z": 7,
      "name": "Rock_Shale_Brick_Pillar_Base",
      "rotation": 8
    },
    {
      "x": 2,
      "y": 4,
      "z": 7,
      "name": "Rock_Shale_Brick"
    },
    {
      "x": 2,
      "y": 5,
      "z": 7,
      "name": "Rock_Basalt"
    },
    {
      "x": 3,
      "y": 0,
      "z": -7,
      "name": "Rock_Shale"
    },
    {
      "x": 3,
      "y": 1,
      "z": -7,
      "name": "Rock_Shale"
    },
    {
      "x": 3,
      "y": 2,
      "z": -7,
      "name": "Rock_Shale"
    },
    {
      "x": 3,
      "y": 3,
      "z": -7,
      "name": "Rock_Shale"
    },
    {
      "x": 3,
      "y": 4,
      "z": -7,
      "name": "Rock_Shale"
    },
    {
      "x": 3,
      "y": 5,
      "z": -7,
      "name": "Rock_Basalt"
    },
    {
      "x": 3,
      "y": 0,
      "z": -6,
      "name": "Rock_Shale"
    },
    {
      "x": 3,
      "y": 1,
      "z": -6,
      "name": "Rock_Shale"
    },
    {
      "x": 3,
      "y": 2,
      "z": -6,
      "name": "Rock_Shale"
    },
    {
      "x": 3,
      "y": 3,
      "z": -6,
      "name": "Rock_Shale"
    },
    {
      "x": 3,
      "y": 4,
      "z": -6,
      "name": "Rock_Shale"
    },
    {
      "x": 3,
      "y": 5,
      "z": -6,
      "name": "Rock_Basalt"
    },
    {
      "x": 3,
      "y": 0,
      "z": -5,
      "name": "Rock_Shale"
    },
    {
      "x": 3,
      "y": 1,
      "z": -5,
      "name": "Rock_Shale"
    },
    {
      "x": 3,
      "y": 2,
      "z": -5,
      "name": "Rock_Shale"
    },
    {
      "x": 3,
      "y": 3,
      "z": -5,
      "name": "Rock_Shale"
    },
    {
      "x": 3,
      "y": 4,
      "z": -5,
      "name": "Rock_Shale"
    },
    {
      "x": 3,
      "y": 5,
      "z": -5,
      "name": "Rock_Basalt"
    },
    {
      "x": 3,
      "y": 0,
      "z": -4,
      "name": "Rock_Shale"
    },
    {
      "x": 3,
      "y": 1,
      "z": -4,
      "name": "Empty"
    },
    {
      "x": 3,
      "y": 2,
      "z": -4,
      "name": "Empty"
    },
    {
      "x": 3,
      "y": 3,
      "z": -4,
      "name": "Rock_Shale"
    },
    {
      "x": 3,
      "y": 4,
      "z": -4,
      "name": "Rock_Shale"
    },
    {
      "x": 3,
      "y": 5,
      "z": -4,
      "name": "Rock_Basalt"
    },
    {
      "x": 3,
      "y": 0,
      "z": -3,
      "name": "Rock_Shale"
    },
    {
      "x": 3,
      "y": 1,
      "z": -3,
      "name": "Empty"
    },
    {
      "x": 3,
      "y": 2,
      "z": -3,
      "name": "Empty"
    },
    {
      "x": 3,
      "y": 3,
      "z": -3,
      "name": "Rock_Shale_Stalactites_Large",
      "filler": 31744,
      "rotation": 8
    },
    {
      "x": 3,
      "y": 4,
      "z": -3,
      "name": "Rock_Shale_Stalactites_Large",
      "rotation": 8
    },
    {
      "x": 3,
      "y": 5,
      "z": -3,
      "name": "Rock_Shale"
    },
    {
      "x": 3,
      "y": 0,
      "z": -2,
      "name": "Rock_Shale_Brick"
    },
    {
      "x": 3,
      "y": 1,
      "z": -2,
      "name": "Empty"
    },
    {
      "x": 3,
      "y": 2,
      "z": -2,
      "name": "Empty"
    },
    {
      "x": 3,
      "y": 3,
      "z": -2,
      "name": "Empty"
    },
    {
      "x": 3,
      "y": 4,
      "z": -2,
      "name": "Empty"
    },
    {
      "x": 3,
      "y": 5,
      "z": -2,
      "name": "Rock_Shale"
    },
    {
      "x": 3,
      "y": 0,
      "z": -1,
      "name": "Rock_Shale_Brick"
    },
    {
      "x": 3,
      "y": 1,
      "z": -1,
      "name": "Empty"
    },
    {
      "x": 3,
      "y": 2,
      "z": -1,
      "name": "Empty"
    },
    {
      "x": 3,
      "y": 3,
      "z": -1,
      "name": "Empty"
    },
    {
      "x": 3,
      "y": 4,
      "z": -1,
      "name": "Empty"
    },
    {
      "x": 3,
      "y": 5,
      "z": -1,
      "name": "Rock_Basalt"
    },
    {
      "x": 3,
      "y": 0,
      "z": 0,
      "name": "Rock_Shale_Cobble_Half"
    },
    {
      "x": 3,
      "y": 1,
      "z": 0,
      "name": "Empty"
    },
    {
      "x": 3,
      "y": 2,
      "z": 0,
      "name": "Empty"
    },
    {
      "x": 3,
      "y": 3,
      "z": 0,
      "name": "Empty"
    },
    {
      "x": 3,
      "y": 4,
      "z": 0,
      "name": "Empty"
    },
    {
      "x": 3,
      "y": 5,
      "z": 0,
      "name": "Rock_Basalt"
    },
    {
      "x": 3,
      "y": 0,
      "z": 1,
      "name": "Rock_Shale_Cobble_Half"
    },
    {
      "x": 3,
      "y": 1,
      "z": 1,
      "name": "Empty"
    },
    {
      "x": 3,
      "y": 2,
      "z": 1,
      "name": "Empty"
    },
    {
      "x": 3,
      "y": 3,
      "z": 1,
      "name": "Empty"
    },
    {
      "x": 3,
      "y": 4,
      "z": 1,
      "name": "Empty"
    },
    {
      "x": 3,
      "y": 5,
      "z": 1,
      "name": "Rock_Basalt"
    },
    {
      "x": 3,
      "y": 0,
      "z": 2,
      "name": "Rock_Shale_Brick_Half"
    },
    {
      "x": 3,
      "y": 1,
      "z": 2,
      "name": "Empty"
    },
    {
      "x": 3,
      "y": 2,
      "z": 2,
      "name": "Empty"
    },
    {
      "x": 3,
      "y": 3,
      "z": 2,
      "name": "Empty"
    },
    {
      "x": 3,
      "y": 4,
      "z": 2,
      "name": "Empty"
    },
    {
      "x": 3,
      "y": 5,
      "z": 2,
      "name": "Rock_Basalt"
    },
    {
      "x": 3,
      "y": 0,
      "z": 3,
      "name": "Deco_Bone_Pile"
    },
    {
      "x": 3,
      "y": 1,
      "z": 3,
      "name": "Empty"
    },
    {
      "x": 3,
      "y": 2,
      "z": 3,
      "name": "Empty"
    },
    {
      "x": 3,
      "y": 3,
      "z": 3,
      "name": "Empty"
    },
    {
      "x": 3,
      "y": 4,
      "z": 3,
      "name": "Empty"
    },
    {
      "x": 3,
      "y": 5,
      "z": 3,
      "name": "Rock_Basalt"
    },
    {
      "x": 3,
      "y": 0,
      "z": 4,
      "name": "Empty"
    },
    {
      "x": 3,
      "y": 1,
      "z": 4,
      "name": "Empty"
    },
    {
      "x": 3,
      "y": 2,
      "z": 4,
      "name": "Empty"
    },
    {
      "x": 3,
      "y": 3,
      "z": 4,
      "name": "Empty"
    },
    {
      "x": 3,
      "y": 4,
      "z": 4,
      "name": "Empty"
    },
    {
      "x": 3,
      "y": 5,
      "z": 4,
      "name": "Rock_Shale"
    },
    {
      "x": 3,
      "y": 0,
      "z": 5,
      "name": "Rock_Shale"
    },
    {
      "x": 3,
      "y": 1,
      "z": 5,
      "name": "Empty"
    },
    {
      "x": 3,
      "y": 2,
      "z": 5,
      "name": "Empty"
    },
    {
      "x": 3,
      "y": 3,
      "z": 5,
      "name": "Empty"
    },
    {
      "x": 3,
      "y": 4,
      "z": 5,
      "name": "Empty"
    },
    {
      "x": 3,
      "y": 5,
      "z": 5,
      "name": "Rock_Shale"
    },
    {
      "x": 3,
      "y": 0,
      "z": 6,
      "name": "Rock_Shale"
    },
    {
      "x": 3,
      "y": 1,
      "z": 6,
      "name": "Rock_Shale"
    },
    {
      "x": 3,
      "y": 2,
      "z": 6,
      "name": "Rock_Shale"
    },
    {
      "x": 3,
      "y": 3,
      "z": 6,
      "name": "Empty"
    },
    {
      "x": 3,
      "y": 4,
      "z": 6,
      "name": "Empty"
    },
    {
      "x": 3,
      "y": 5,
      "z": 6,
      "name": "Rock_Shale"
    },
    {
      "x": 3,
      "y": 0,
      "z": 7,
      "name": "Rock_Shale"
    },
    {
      "x": 3,
      "y": 1,
      "z": 7,
      "name": "Rock_Shale"
    },
    {
      "x": 3,
      "y": 2,
      "z": 7,
      "name": "Rock_Shale"
    },
    {
      "x": 3,
      "y": 3,
      "z": 7,
      "name": "Rock_Shale"
    },
    {
      "x": 3,
      "y": 4,
      "z": 7,
      "name": "Rock_Shale"
    },
    {
      "x": 3,
      "y": 5,
      "z": 7,
      "name": "Rock_Basalt"
    },
    {
      "x": 4,
      "y": 0,
      "z": -7,
      "name": "Rock_Shale"
    },
    {
      "x": 4,
      "y": 1,
      "z": -7,
      "name": "Rock_Shale"
    },
    {
      "x": 4,
      "y": 2,
      "z": -7,
      "name": "Rock_Shale"
    },
    {
      "x": 4,
      "y": 3,
      "z": -7,
      "name": "Rock_Shale"
    },
    {
      "x": 4,
      "y": 4,
      "z": -7,
      "name": "Rock_Shale"
    },
    {
      "x": 4,
      "y": 5,
      "z": -7,
      "name": "Rock_Basalt"
    },
    {
      "x": 4,
      "y": 0,
      "z": -6,
      "name": "Rock_Shale"
    },
    {
      "x": 4,
      "y": 1,
      "z": -6,
      "name": "Rock_Shale"
    },
    {
      "x": 4,
      "y": 2,
      "z": -6,
      "name": "Rock_Shale"
    },
    {
      "x": 4,
      "y": 3,
      "z": -6,
      "name": "Rock_Basalt"
    },
    {
      "x": 4,
      "y": 4,
      "z": -6,
      "name": "Rock_Shale"
    },
    {
      "x": 4,
      "y": 5,
      "z": -6,
      "name": "Rock_Basalt"
    },
    {
      "x": 4,
      "y": 0,
      "z": -5,
      "name": "Soil_Dirt_Cold"
    },
    {
      "x": 4,
      "y": 1,
      "z": -5,
      "name": "Furniture_Ancient_Crate"
    },
    {
      "x": 4,
      "y": 2,
      "z": -5,
      "name": "Empty"
    },
    {
      "x": 4,
      "y": 3,
      "z": -5,
      "name": "Empty"
    },
    {
      "x": 4,
      "y": 4,
      "z": -5,
      "name": "Rock_Basalt"
    },
    {
      "x": 4,
      "y": 5,
      "z": -5,
      "name": "Rock_Basalt"
    },
    {
      "x": 4,
      "y": 0,
      "z": -4,
      "name": "Rock_Shale"
    },
    {
      "x": 4,
      "y": 1,
      "z": -4,
      "name": "Wood_Redwood_Branch_Long"
    },
    {
      "x": 4,
      "y": 2,
      "z": -4,
      "name": "Wood_Redwood_Branch_Long"
    },
    {
      "x": 4,
      "y": 3,
      "z": -4,
      "name": "Wood_Redwood_Branch_Long"
    },
    {
      "x": 4,
      "y": 4,
      "z": -4,
      "name": "Wood_Redwood_Branch_Long"
    },
    {
      "x": 4,
      "y": 5,
      "z": -4,
      "name": "Rock_Shale"
    },
    {
      "x": 4,
      "y": 0,
      "z": -3,
      "name": "Rock_Shale"
    },
    {
      "x": 4,
      "y": 1,
      "z": -3,
      "name": "Deco_Bone_Pile"
    },
    {
      "x": 4,
      "y": 2,
      "z": -3,
      "name": "Empty"
    },
    {
      "x": 4,
      "y": 3,
      "z": -3,
      "name": "Empty"
    },
    {
      "x": 4,
      "y": 4,
      "z": -3,
      "name": "Empty"
    },
    {
      "x": 4,
      "y": 5,
      "z": -3,
      "name": "Rock_Shale"
    },
    {
      "x": 4,
      "y": 0,
      "z": -2,
      "name": "Rock_Shale"
    },
    {
      "x": 4,
      "y": 1,
      "z": -2,
      "name": "Empty"
    },
    {
      "x": 4,
      "y": 2,
      "z": -2,
      "name": "Empty"
    },
    {
      "x": 4,
      "y": 3,
      "z": -2,
      "name": "Empty"
    },
    {
      "x": 4,
      "y": 4,
      "z": -2,
      "name": "Empty"
    },
    {
      "x": 4,
      "y": 5,
      "z": -2,
      "name": "Rock_Shale"
    },
    {
      "x": 4,
      "y": 0,
      "z": -1,
      "name": "Rock_Shale"
    },
    {
      "x": 4,
      "y": 1,
      "z": -1,
      "name": "Empty"
    },
    {
      "x": 4,
      "y": 2,
      "z": -1,
      "name": "Empty"
    },
    {
      "x": 4,
      "y": 3,
      "z": -1,
      "name": "Empty"
    },
    {
      "x": 4,
      "y": 4,
      "z": -1,
      "name": "Empty"
    },
    {
      "x": 4,
      "y": 5,
      "z": -1,
      "name": "Rock_Basalt"
    },
    {
      "x": 4,
      "y": 0,
      "z": 0,
      "name": "Rock_Shale_Cobble"
    },
    {
      "x": 4,
      "y": 1,
      "z": 0,
      "name": "Empty"
    },
    {
      "x": 4,
      "y": 2,
      "z": 0,
      "name": "Empty"
    },
    {
      "x": 4,
      "y": 3,
      "z": 0,
      "name": "Empty"
    },
    {
      "x": 4,
      "y": 4,
      "z": 0,
      "name": "Empty"
    },
    {
      "x": 4,
      "y": 5,
      "z": 0,
      "name": "Rock_Basalt"
    },
    {
      "x": 4,
      "y": 0,
      "z": 1,
      "name": "Rock_Shale_Cobble"
    },
    {
      "x": 4,
      "y": 1,
      "z": 1,
      "name": "Empty"
    },
    {
      "x": 4,
      "y": 2,
      "z": 1,
      "name": "Empty"
    },
    {
      "x": 4,
      "y": 3,
      "z": 1,
      "name": "Empty"
    },
    {
      "x": 4,
      "y": 4,
      "z": 1,
      "name": "Empty"
    },
    {
      "x": 4,
      "y": 5,
      "z": 1,
      "name": "Rock_Basalt"
    },
    {
      "x": 4,
      "y": 0,
      "z": 2,
      "name": "Rock_Shale_Brick_Half"
    },
    {
      "x": 4,
      "y": 1,
      "z": 2,
      "name": "Empty"
    },
    {
      "x": 4,
      "y": 2,
      "z": 2,
      "name": "Empty"
    },
    {
      "x": 4,
      "y": 3,
      "z": 2,
      "name": "Empty"
    },
    {
      "x": 4,
      "y": 4,
      "z": 2,
      "name": "Plant_Bush_Dead_Hanging"
    },
    {
      "x": 4,
      "y": 5,
      "z": 2,
      "name": "Rock_Basalt"
    },
    {
      "x": 4,
      "y": 0,
      "z": 3,
      "name": "Rock_Shale_Brick_Half"
    },
    {
      "x": 4,
      "y": 1,
      "z": 3,
      "name": "Empty"
    },
    {
      "x": 4,
      "y": 2,
      "z": 3,
      "name": "Empty"
    },
    {
      "x": 4,
      "y": 3,
      "z": 3,
      "name": "Empty"
    },
    {
      "x": 4,
      "y": 4,
      "z": 3,
      "name": "Empty"
    },
    {
      "x": 4,
      "y": 5,
      "z": 3,
      "name": "Rock_Shale"
    },
    {
      "x": 4,
      "y": 0,
      "z": 4,
      "name": "Empty"
    },
    {
      "x": 4,
      "y": 1,
      "z": 4,
      "name": "Empty"
    },
    {
      "x": 4,
      "y": 2,
      "z": 4,
      "name": "Empty"
    },
    {
      "x": 4,
      "y": 3,
      "z": 4,
      "name": "Empty"
    },
    {
      "x": 4,
      "y": 4,
      "z": 4,
      "name": "Rock_Shale_Stalactites_Small",
      "rotation": 8
    },
    {
      "x": 4,
      "y": 5,
      "z": 4,
      "name": "Rock_Shale"
    },
    {
      "x": 4,
      "y": 0,
      "z": 5,
      "name": "Rock_Shale"
    },
    {
      "x": 4,
      "y": 1,
      "z": 5,
      "name": "Rock_Shale"
    },
    {
      "x": 4,
      "y": 2,
      "z": 5,
      "name": "Empty"
    },
    {
      "x": 4,
      "y": 3,
      "z": 5,
      "name": "Empty"
    },
    {
      "x": 4,
      "y": 4,
      "z": 5,
      "name": "Empty"
    },
    {
      "x": 4,
      "y": 5,
      "z": 5,
      "name": "Rock_Shale"
    },
    {
      "x": 4,
      "y": 0,
      "z": 6,
      "name": "Rock_Shale"
    },
    {
      "x": 4,
      "y": 1,
      "z": 6,
      "name": "Rock_Shale"
    },
    {
      "x": 4,
      "y": 2,
      "z": 6,
      "name": "Rock_Shale"
    },
    {
      "x": 4,
      "y": 3,
      "z": 6,
      "name": "Empty"
    },
    {
      "x": 4,
      "y": 4,
      "z": 6,
      "name": "Empty"
    },
    {
      "x": 4,
      "y": 5,
      "z": 6,
      "name": "Rock_Shale"
    },
    {
      "x": 4,
      "y": 0,
      "z": 7,
      "name": "Rock_Shale"
    },
    {
      "x": 4,
      "y": 1,
      "z": 7,
      "name": "Rock_Shale"
    },
    {
      "x": 4,
      "y": 2,
      "z": 7,
      "name": "Rock_Shale"
    },
    {
      "x": 4,
      "y": 3,
      "z": 7,
      "name": "Rock_Shale"
    },
    {
      "x": 4,
      "y": 4,
      "z": 7,
      "name": "Rock_Shale"
    },
    {
      "x": 4,
      "y": 5,
      "z": 7,
      "name": "Rock_Basalt"
    },
    {
      "x": 5,
      "y": 0,
      "z": -7,
      "name": "Rock_Shale"
    },
    {
      "x": 5,
      "y": 1,
      "z": -7,
      "name": "Rock_Shale"
    },
    {
      "x": 5,
      "y": 2,
      "z": -7,
      "name": "Rock_Basalt"
    },
    {
      "x": 5,
      "y": 3,
      "z": -7,
      "name": "Rock_Shale"
    },
    {
      "x": 5,
      "y": 4,
      "z": -7,
      "name": "Rock_Shale"
    },
    {
      "x": 5,
      "y": 5,
      "z": -7,
      "name": "Rock_Basalt"
    },
    {
      "x": 5,
      "y": 0,
      "z": -6,
      "name": "Soil_Dirt_Cold"
    },
    {
      "x": 5,
      "y": 1,
      "z": -6,
      "name": "Furniture_Ancient_Barrel"
    },
    {
      "x": 5,
      "y": 2,
      "z": -6,
      "name": "Empty"
    },
    {
      "x": 5,
      "y": 3,
      "z": -6,
      "name": "Rock_Basalt"
    },
    {
      "x": 5,
      "y": 4,
      "z": -6,
      "name": "Rock_Basalt"
    },
    {
      "x": 5,
      "y": 5,
      "z": -6,
      "name": "Rock_Basalt"
    },
    {
      "x": 5,
      "y": 0,
      "z": -5,
      "name": "Soil_Dirt_Cold"
    },
    {
      "x": 5,
      "y": 1,
      "z": -5,
      "name": "Empty"
    },
    {
      "x": 5,
      "y": 2,
      "z": -5,
      "name": "Empty"
    },
    {
      "x": 5,
      "y": 3,
      "z": -5,
      "name": "Empty"
    },
    {
      "x": 5,
      "y": 4,
      "z": -5,
      "name": "Rock_Basalt"
    },
    {
      "x": 5,
      "y": 5,
      "z": -5,
      "name": "Rock_Basalt"
    },
    {
      "x": 5,
      "y": 0,
      "z": -4,
      "name": "Soil_Dirt_Cold"
    },
    {
      "x": 5,
      "y": 1,
      "z": -4,
      "name": "Deco_Bone_Skulls"
    },
    {
      "x": 5,
      "y": 2,
      "z": -4,
      "name": "Empty"
    },
    {
      "x": 5,
      "y": 3,
      "z": -4,
      "name": "Empty"
    },
    {
      "x": 5,
      "y": 4,
      "z": -4,
      "name": "Empty"
    },
    {
      "x": 5,
      "y": 5,
      "z": -4,
      "name": "Rock_Basalt"
    },
    {
      "x": 5,
      "y": 0,
      "z": -3,
      "name": "Rock_Shale"
    },
    {
      "x": 5,
      "y": 1,
      "z": -3,
      "name": "Empty"
    },
    {
      "x": 5,
      "y": 2,
      "z": -3,
      "name": "Empty"
    },
    {
      "x": 5,
      "y": 3,
      "z": -3,
      "name": "Empty"
    },
    {
      "x": 5,
      "y": 4,
      "z": -3,
      "name": "Empty"
    },
    {
      "x": 5,
      "y": 5,
      "z": -3,
      "name": "Rock_Basalt"
    },
    {
      "x": 5,
      "y": 0,
      "z": -2,
      "name": "Rock_Shale"
    },
    {
      "x": 5,
      "y": 1,
      "z": -2,
      "name": "Empty"
    },
    {
      "x": 5,
      "y": 2,
      "z": -2,
      "name": "Empty"
    },
    {
      "x": 5,
      "y": 3,
      "z": -2,
      "name": "Empty"
    },
    {
      "x": 5,
      "y": 4,
      "z": -2,
      "name": "Empty"
    },
    {
      "x": 5,
      "y": 5,
      "z": -2,
      "name": "Rock_Basalt"
    },
    {
      "x": 5,
      "y": 0,
      "z": -1,
      "name": "Rock_Shale"
    },
    {
      "x": 5,
      "y": 1,
      "z": -1,
      "name": "Empty"
    },
    {
      "x": 5,
      "y": 2,
      "z": -1,
      "name": "Empty"
    },
    {
      "x": 5,
      "y": 3,
      "z": -1,
      "name": "Empty"
    },
    {
      "x": 5,
      "y": 4,
      "z": -1,
      "name": "Empty"
    },
    {
      "x": 5,
      "y": 5,
      "z": -1,
      "name": "Rock_Basalt"
    },
    {
      "x": 5,
      "y": 0,
      "z": 0,
      "name": "Soil_Dirt_Cold"
    },
    {
      "x": 5,
      "y": 1,
      "z": 0,
      "name": "Empty"
    },
    {
      "x": 5,
      "y": 2,
      "z": 0,
      "name": "Empty"
    },
    {
      "x": 5,
      "y": 3,
      "z": 0,
      "name": "Empty"
    },
    {
      "x": 5,
      "y": 4,
      "z": 0,
      "name": "Empty"
    },
    {
      "x": 5,
      "y": 5,
      "z": 0,
      "name": "Rock_Basalt"
    },
    {
      "x": 5,
      "y": 0,
      "z": 1,
      "name": "Rock_Shale_Brick_Smooth"
    },
    {
      "x": 5,
      "y": 1,
      "z": 1,
      "name": "Empty"
    },
    {
      "x": 5,
      "y": 2,
      "z": 1,
      "name": "Empty"
    },
    {
      "x": 5,
      "y": 3,
      "z": 1,
      "name": "Empty"
    },
    {
      "x": 5,
      "y": 4,
      "z": 1,
      "name": "Empty"
    },
    {
      "x": 5,
      "y": 5,
      "z": 1,
      "name": "Rock_Basalt"
    },
    {
      "x": 5,
      "y": 0,
      "z": 2,
      "name": "Rock_Shale_Brick"
    },
    {
      "x": 5,
      "y": 1,
      "z": 2,
      "name": "Rock_Shale_Brick_Beam"
    },
    {
      "x": 5,
      "y": 2,
      "z": 2,
      "name": "Furniture_Human_Ruins_Torch",
      "rotation": 1
    },
    {
      "x": 5,
      "y": 3,
      "z": 2,
      "name": "Empty"
    },
    {
      "x": 5,
      "y": 4,
      "z": 2,
      "name": "Empty"
    },
    {
      "x": 5,
      "y": 5,
      "z": 2,
      "name": "Rock_Basalt"
    },
    {
      "x": 5,
      "y": 0,
      "z": 3,
      "name": "Rock_Basalt"
    },
    {
      "x": 5,
      "y": 1,
      "z": 3,
      "name": "Empty"
    },
    {
      "x": 5,
      "y": 2,
      "z": 3,
      "name": "Empty"
    },
    {
      "x": 5,
      "y": 3,
      "z": 3,
      "name": "Empty"
    },
    {
      "x": 5,
      "y": 4,
      "z": 3,
      "name": "Rock_Basalt"
    },
    {
      "x": 5,
      "y": 5,
      "z": 3,
      "name": "Rock_Basalt"
    },
    {
      "x": 5,
      "y": 0,
      "z": 4,
      "name": "Rock_Basalt"
    },
    {
      "x": 5,
      "y": 1,
      "z": 4,
      "name": "Empty"
    },
    {
      "x": 5,
      "y": 2,
      "z": 4,
      "name": "Empty"
    },
    {
      "x": 5,
      "y": 3,
      "z": 4,
      "name": "Empty"
    },
    {
      "x": 5,
      "y": 4,
      "z": 4,
      "name": "Rock_Basalt"
    },
    {
      "x": 5,
      "y": 5,
      "z": 4,
      "name": "Rock_Basalt"
    },
    {
      "x": 5,
      "y": 0,
      "z": 5,
      "name": "Rock_Shale"
    },
    {
      "x": 5,
      "y": 1,
      "z": 5,
      "name": "Rock_Shale"
    },
    {
      "x": 5,
      "y": 2,
      "z": 5,
      "name": "Rock_Shale"
    },
    {
      "x": 5,
      "y": 3,
      "z": 5,
      "name": "Rock_Shale"
    },
    {
      "x": 5,
      "y": 4,
      "z": 5,
      "name": "Rock_Shale"
    },
    {
      "x": 5,
      "y": 5,
      "z": 5,
      "name": "Rock_Basalt"
    },
    {
      "x": 5,
      "y": 0,
      "z": 6,
      "name": "Rock_Shale"
    },
    {
      "x": 5,
      "y": 1,
      "z": 6,
      "name": "Rock_Shale"
    },
    {
      "x": 5,
      "y": 2,
      "z": 6,
      "name": "Rock_Shale"
    },
    {
      "x": 5,
      "y": 3,
      "z": 6,
      "name": "Rock_Shale"
    },
    {
      "x": 5,
      "y": 4,
      "z": 6,
      "name": "Rock_Shale"
    },
    {
      "x": 5,
      "y": 5,
      "z": 6,
      "name": "Rock_Basalt"
    },
    {
      "x": 6,
      "y": 0,
      "z": -7,
      "name": "Rock_Shale"
    },
    {
      "x": 6,
      "y": 1,
      "z": -7,
      "name": "Rock_Basalt"
    },
    {
      "x": 6,
      "y": 2,
      "z": -7,
      "name": "Rock_Basalt"
    },
    {
      "x": 6,
      "y": 3,
      "z": -7,
      "name": "Rock_Basalt"
    },
    {
      "x": 6,
      "y": 4,
      "z": -7,
      "name": "Rock_Shale"
    },
    {
      "x": 6,
      "y": 5,
      "z": -7,
      "name": "Rock_Basalt"
    },
    {
      "x": 6,
      "y": 0,
      "z": -6,
      "name": "Soil_Dirt_Cold"
    },
    {
      "x": 6,
      "y": 1,
      "z": -6,
      "name": "Furniture_Ancient_Barrel"
    },
    {
      "x": 6,
      "y": 2,
      "z": -6,
      "name": "Empty"
    },
    {
      "x": 6,
      "y": 3,
      "z": -6,
      "name": "Rock_Basalt"
    },
    {
      "x": 6,
      "y": 4,
      "z": -6,
      "name": "Rock_Basalt"
    },
    {
      "x": 6,
      "y": 5,
      "z": -6,
      "name": "Rock_Basalt"
    },
    {
      "x": 6,
      "y": 0,
      "z": -5,
      "name": "Soil_Dirt_Cold"
    },
    {
      "x": 6,
      "y": 1,
      "z": -5,
      "name": "Plant_Bush_Dead_Twisted"
    },
    {
      "x": 6,
      "y": 2,
      "z": -5,
      "name": "Empty"
    },
    {
      "x": 6,
      "y": 3,
      "z": -5,
      "name": "Rock_Basalt"
    },
    {
      "x": 6,
      "y": 4,
      "z": -5,
      "name": "Rock_Basalt"
    },
    {
      "x": 6,
      "y": 5,
      "z": -5,
      "name": "Rock_Basalt"
    },
    {
      "x": 6,
      "y": 0,
      "z": -4,
      "name": "Soil_Dirt_Cold"
    },
    {
      "x": 6,
      "y": 1,
      "z": -4,
      "name": "Empty"
    },
    {
      "x": 6,
      "y": 2,
      "z": -4,
      "name": "Empty"
    },
    {
      "x": 6,
      "y": 3,
      "z": -4,
      "name": "Empty"
    },
    {
      "x": 6,
      "y": 4,
      "z": -4,
      "name": "Empty"
    },
    {
      "x": 6,
      "y": 5,
      "z": -4,
      "name": "Rock_Basalt"
    },
    {
      "x": 6,
      "y": 0,
      "z": -3,
      "name": "Rock_Shale"
    },
    {
      "x": 6,
      "y": 1,
      "z": -3,
      "name": "Empty"
    },
    {
      "x": 6,
      "y": 2,
      "z": -3,
      "name": "Empty"
    },
    {
      "x": 6,
      "y": 3,
      "z": -3,
      "name": "Empty"
    },
    {
      "x": 6,
      "y": 4,
      "z": -3,
      "name": "Empty"
    },
    {
      "x": 6,
      "y": 5,
      "z": -3,
      "name": "Rock_Basalt"
    },
    {
      "x": 6,
      "y": 0,
      "z": -2,
      "name": "Rock_Shale"
    },
    {
      "x": 6,
      "y": 1,
      "z": -2,
      "name": "Empty"
    },
    {
      "x": 6,
      "y": 2,
      "z": -2,
      "name": "Empty"
    },
    {
      "x": 6,
      "y": 3,
      "z": -2,
      "name": "Empty"
    },
    {
      "x": 6,
      "y": 4,
      "z": -2,
      "name": "Empty"
    },
    {
      "x": 6,
      "y": 5,
      "z": -2,
      "name": "Rock_Basalt"
    },
    {
      "x": 6,
      "y": 0,
      "z": -1,
      "name": "Rock_Shale"
    },
    {
      "x": 6,
      "y": 1,
      "z": -1,
      "name": "Empty"
    },
    {
      "x": 6,
      "y": 2,
