{
  "version": 8,
  "blockIdVersion": 8,
  "anchorX": 2,
  "anchorY": 11,
  "anchorZ": -1,
  "blocks": [
    {
      "x": -6,
      "y": 11,
      "z": 1,
      "name": "Rock_Stone"
    },
    {
      "x": -6,
      "y": 12,
      "z": 1,
      "name": "Rock_Stone"
    },
    {
      "x": -6,
      "y": 13,
      "z": 1,
      "name": "Rock_Stone"
    },
    {
      "x": -6,
      "y": 14,
      "z": 1,
      "name": "Rock_Stone"
    },
    {
      "x": -6,
      "y": 15,
      "z": 1,
      "name": "Rock_Stone"
    },
    {
      "x": -6,
      "y": 29,
      "z": 1,
      "name": "Plant_Leaves_Birch",
      "support": 15
    },
    {
      "x": -6,
      "y": 12,
      "z": 2,
      "name": "Rock_Stone"
    },
    {
      "x": -6,
      "y": 13,
      "z": 2,
      "name": "Rock_Stone"
    },
    {
      "x": -6,
      "y": 14,
      "z": 2,
      "name": "Rock_Stone"
    },
    {
      "x": -6,
      "y": 28,
      "z": 2,
      "name": "Plant_Leaves_Birch",
      "support": 15
    },
    {
      "x": -6,
      "y": 29,
      "z": 2,
      "name": "Plant_Leaves_Birch",
      "support": 15
    },
    {
      "x": -6,
      "y": 30,
      "z": 2,
      "name": "Plant_Leaves_Birch",
      "support": 15
    },
    {
      "x": -6,
      "y": 33,
      "z": 2,
      "name": "Plant_Leaves_Birch",
      "support": 15
    },
    {
      "x": -6,
      "y": 29,
      "z": 3,
      "name": "Plant_Leaves_Birch",
      "support": 15
    },
    {
      "x": -6,
      "y": 30,
      "z": 3,
      "name": "Plant_Leaves_Birch",
      "support": 15
    },
    {
      "x": -6,
      "y": 28,
      "z": 4,
      "name": "Plant_Leaves_Birch",
      "support": 15
    },
    {
      "x": -6,
      "y": 27,
      "z": 5,
      "name": "Plant_Leaves_Birch",
      "support": 15
    },
    {
      "x": -6,
      "y": 28,
      "z": 5,
      "name": "Plant_Leaves_Birch",
      "support": 15
    },
    {
      "x": -6,
      "y": 27,
      "z": 6,
      "name": "Plant_Leaves_Birch",
      "support": 15
    },
    {
      "x": -6,
      "y": 28,
      "z": 6,
      "name": "Plant_Leaves_Birch",
      "support": 15
    },
    {
      "x": -6,
      "y": 29,
      "z": 6,
      "name": "Plant_Leaves_Birch",
      "support": 15
    },
    {
      "x": -5,
      "y": 13,
      "z": -1,
      "name": "Rock_Stone"
    },
    {
      "x": -5,
      "y": 14,
      "z": -1,
      "name": "Rock_Stone"
    },
    {
      "x": -5,
      "y": 15,
      "z": -1,
      "name": "Rock_Stone"
    },
    {
      "x": -5,
      "y": 16,
      "z": -1,
      "name": "Rock_Stone"
    },
    {
      "x": -5,
      "y": 12,
      "z": 0,
      "name": "Rock_Stone"
    },
    {
      "x": -5,
      "y": 13,
      "z": 0,
      "name": "Rock_Stone"
    },
    {
      "x": -5,
      "y": 14,
      "z": 0,
      "name": "Rock_Stone"
    },
    {
      "x": -5,
      "y": 15,
      "z": 0,
      "name": "Rock_Stone"
    },
    {
      "x": -5,
      "y": 16,
      "z": 0,
      "name": "Rock_Stone"
    },
    {
      "x": -5,
      "y": 17,
      "z": 0,
      "name": "Rock_Stone"
    },
    {
      "x": -5,
      "y": 18,
      "z": 0,
      "name": "Soil_Dirt"
    },
    {
      "x": -5,
      "y": 19,
      "z": 0,
      "name": "Soil_Grass"
    },
    {
      "x": -5,
      "y": 10,
      "z": 1,
      "name": "Rock_Stone"
    },
    {
      "x": -5,
      "y": 11,
      "z": 1,
      "name": "Rock_Stone"
    },
    {
      "x": -5,
      "y": 12,
      "z": 1,
      "name": "Rock_Stone"
    },
    {
      "x": -5,
      "y": 13,
      "z": 1,
      "name": "Rock_Stone"
    },
    {
      "x": -5,
      "y": 14,
      "z": 1,
      "name": "Rock_Stone"
    },
    {
      "x": -5,
      "y": 15,
      "z": 1,
      "name": "Soil_Dirt"
    },
    {
      "x": -5,
      "y": 16,
      "z": 1,
      "name": "Rock_Stone"
    },
    {
      "x": -5,
      "y": 17,
      "z": 1,
      "name": "Rock_Stone"
    },
    {
      "x": -5,
      "y": 18,
      "z": 1,
      "name": "Soil_Dirt"
    },
    {
      "x": -5,
      "y": 19,
      "z": 1,
      "name": "Soil_Grass"
    },
    {
      "x": -5,
      "y": 28,
      "z": 1,
      "name": "Plant_Leaves_Birch",
      "support": 15
    },
    {
      "x": -5,
      "y": 29,
      "z": 1,
      "name": "Plant_Leaves_Birch",
      "support": 15
    },
    {
      "x": -5,
      "y": 30,
      "z": 1,
      "name": "Plant_Leaves_Birch",
      "support": 15
    },
    {
      "x": -5,
      "y": 33,
      "z": 1,
      "name": "Plant_Leaves_Birch",
      "support": 15
    },
    {
      "x": -5,
      "y": 9,
      "z": 2,
      "name": "Rock_Stone"
    },
    {
      "x": -5,
      "y": 10,
      "z": 2,
      "name": "Rock_Stone"
    },
    {
      "x": -5,
      "y": 11,
      "z": 2,
      "name": "Rock_Stone"
    },
    {
      "x": -5,
      "y": 12,
      "z": 2,
      "name": "Rock_Stone"
    },
    {
      "x": -5,
      "y": 13,
      "z": 2,
      "name": "Rock_Stone"
    },
    {
      "x": -5,
      "y": 14,
      "z": 2,
      "name": "Rock_Stone"
    },
    {
      "x": -5,
      "y": 15,
      "z": 2,
      "name": "Rock_Stone"
    },
    {
      "x": -5,
      "y": 16,
      "z": 2,
      "name": "Rock_Stone"
    },
    {
      "x": -5,
      "y": 17,
      "z": 2,
      "name": "Rock_Stone"
    },
    {
      "x": -5,
      "y": 18,
      "z": 2,
      "name": "Soil_Grass"
    },
    {
      "x": -5,
      "y": 27,
      "z": 2,
      "name": "Plant_Leaves_Birch",
      "support": 15
    },
    {
      "x": -5,
      "y": 28,
      "z": 2,
      "name": "Plant_Leaves_Birch",
      "support": 15
    },
    {
      "x": -5,
      "y": 29,
      "z": 2,
      "name": "Plant_Leaves_Birch",
      "support": 15
    },
    {
      "x": -5,
      "y": 30,
      "z": 2,
      "name": "Plant_Leaves_Birch",
      "support": 15
    },
    {
      "x": -5,
      "y": 31,
      "z": 2,
      "name": "Plant_Leaves_Birch",
      "support": 15
    },
    {
      "x": -5,
      "y": 33,
      "z": 2,
      "name": "Plant_Leaves_Birch",
      "support": 15
    },
    {
      "x": -5,
      "y": 34,
      "z": 2,
      "name": "Plant_Leaves_Birch",
      "support": 15
    },
    {
      "x": -5,
      "y": 11,
      "z": 3,
      "name": "Rock_Stone"
    },
    {
      "x": -5,
      "y": 12,
      "z": 3,
      "name": "Rock_Stone"
    },
    {
      "x": -5,
      "y": 13,
      "z": 3,
      "name": "Rock_Stone"
    },
    {
      "x": -5,
      "y": 14,
      "z": 3,
      "name": "Rock_Stone"
    },
    {
      "x": -5,
      "y": 15,
      "z": 3,
      "name": "Rock_Stone"
    },
    {
      "x": -5,
      "y": 26,
      "z": 3,
      "name": "Plant_Leaves_Birch",
      "support": 15
    },
    {
      "x": -5,
      "y": 27,
      "z": 3,
      "name": "Plant_Leaves_Birch",
      "support": 15
    },
    {
      "x": -5,
      "y": 30,
      "z": 3,
      "name": "Wood_Birch_Branch_Corner",
      "support": 15,
      "rotation": 3
    },
    {
      "x": -5,
      "y": 31,
      "z": 3,
      "name": "Plant_Leaves_Birch",
      "support": 15
    },
    {
      "x": -5,
      "y": 34,
      "z": 3,
      "name": "Plant_Leaves_Birch",
      "support": 15
    },
    {
      "x": -5,
      "y": 24,
      "z": 4,
      "name": "Plant_Leaves_Birch",
      "support": 15
    },
    {
      "x": -5,
      "y": 25,
      "z": 4,
      "name": "Plant_Leaves_Birch",
      "support": 15
    },
    {
      "x": -5,
      "y": 29,
      "z": 4,
      "name": "Plant_Leaves_Birch",
      "support": 15
    },
    {
      "x": -5,
      "y": 32,
      "z": 4,
      "name": "Plant_Leaves_Birch",
      "support": 15
    },
    {
      "x": -5,
      "y": 28,
      "z": 5,
      "name": "Plant_Leaves_Birch",
      "support": 15
    },
    {
      "x": -5,
      "y": 29,
      "z": 5,
      "name": "Plant_Leaves_Birch",
      "support": 15
    },
    {
      "x": -5,
      "y": 31,
      "z": 5,
      "name": "Plant_Leaves_Birch",
      "support": 15
    },
    {
      "x": -5,
      "y": 32,
      "z": 5,
      "name": "Plant_Leaves_Birch",
      "support": 15
    },
    {
      "x": -5,
      "y": 33,
      "z": 5,
      "name": "Plant_Leaves_Birch",
      "support": 15
    },
    {
      "x": -5,
      "y": 27,
      "z": 6,
      "name": "Plant_Leaves_Birch",
      "support": 15
    },
    {
      "x": -5,
      "y": 28,
      "z": 6,
      "name": "Plant_Leaves_Birch",
      "support": 15
    },
    {
      "x": -5,
      "y": 29,
      "z": 6,
      "name": "Plant_Leaves_Birch",
      "support": 15
    },
    {
      "x": -5,
      "y": 31,
      "z": 6,
      "name": "Plant_Leaves_Birch",
      "support": 15
    },
    {
      "x": -5,
      "y": 32,
      "z": 6,
      "name": "Plant_Leaves_Birch",
      "support": 15
    },
    {
      "x": -5,
      "y": 27,
      "z": 7,
      "name": "Plant_Leaves_Birch",
      "support": 15
    },
    {
      "x": -5,
      "y": 28,
      "z": 7,
      "name": "Plant_Leaves_Birch",
      "support": 15
    },
    {
      "x": -4,
      "y": 12,
      "z": -1,
      "name": "Rock_Stone"
    },
    {
      "x": -4,
      "y": 13,
      "z": -1,
      "name": "Rock_Stone"
    },
    {
      "x": -4,
      "y": 14,
      "z": -1,
      "name": "Rock_Stone"
    },
    {
      "x": -4,
      "y": 15,
      "z": -1,
      "name": "Rock_Stone"
    },
    {
      "x": -4,
      "y": 16,
      "z": -1,
      "name": "Rock_Stone"
    },
    {
      "x": -4,
      "y": 17,
      "z": -1,
      "name": "Rock_Stone"
    },
    {
      "x": -4,
      "y": 18,
      "z": -1,
      "name": "Soil_Grass"
    },
    {
      "x": -4,
      "y": 10,
      "z": 0,
      "name": "Rock_Stone"
    },
    {
      "x": -4,
      "y": 11,
      "z": 0,
      "name": "Rock_Stone"
    },
    {
      "x": -4,
      "y": 12,
      "z": 0,
      "name": "Rock_Stone"
    },
    {
      "x": -4,
      "y": 13,
      "z": 0,
      "name": "Rock_Stone"
    },
    {
      "x": -4,
      "y": 14,
      "z": 0,
      "name": "Rock_Stone"
    },
    {
      "x": -4,
      "y": 15,
      "z": 0,
      "name": "Rock_Stone"
    },
    {
      "x": -4,
      "y": 16,
      "z": 0,
      "name": "Soil_Dirt"
    },
    {
      "x": -4,
      "y": 17,
      "z": 0,
      "name": "Rock_Stone"
    },
    {
      "x": -4,
      "y": 18,
      "z": 0,
      "name": "Soil_Dirt"
    },
    {
      "x": -4,
      "y": 19,
      "z": 0,
      "name": "Soil_Grass"
    },
    {
      "x": -4,
      "y": 29,
      "z": 0,
      "name": "Plant_Leaves_Birch",
      "support": 15
    },
    {
      "x": -4,
      "y": 32,
      "z": 0,
      "name": "Plant_Leaves_Birch",
      "support": 15
    },
    {
      "x": -4,
      "y": 33,
      "z": 0,
      "name": "Plant_Leaves_Birch",
      "support": 15
    },
    {
      "x": -4,
      "y": 8,
      "z": 1,
      "name": "Rock_Stone"
    },
    {
      "x": -4,
      "y": 9,
      "z": 1,
      "name": "Rock_Stone"
    },
    {
      "x": -4,
      "y": 10,
      "z": 1,
      "name": "Rock_Stone"
    },
    {
      "x": -4,
      "y": 11,
      "z": 1,
      "name": "Rock_Stone"
    },
    {
      "x": -4,
      "y": 12,
      "z": 1,
      "name": "Rock_Stone"
    },
    {
      "x": -4,
      "y": 13,
      "z": 1,
      "name": "Rock_Stone"
    },
    {
      "x": -4,
      "y": 14,
      "z": 1,
      "name": "Rock_Stone"
    },
    {
      "x": -4,
      "y": 15,
      "z": 1,
      "name": "Rock_Stone"
    },
    {
      "x": -4,
      "y": 16,
      "z": 1,
      "name": "Soil_Dirt"
    },
    {
      "x": -4,
      "y": 17,
      "z": 1,
      "name": "Rock_Stone"
    },
    {
      "x": -4,
      "y": 18,
      "z": 1,
      "name": "Soil_Dirt"
    },
    {
      "x": -4,
      "y": 19,
      "z": 1,
      "name": "Soil_Dirt"
    },
    {
      "x": -4,
      "y": 20,
      "z": 1,
      "name": "Soil_Grass"
    },
    {
      "x": -4,
      "y": 21,
      "z": 1,
      "name": "Plant_Grass_Sharp"
    },
    {
      "x": -4,
      "y": 27,
      "z": 1,
      "name": "Plant_Leaves_Birch",
      "support": 15
    },
    {
      "x": -4,
      "y": 28,
      "z": 1,
      "name": "Plant_Leaves_Birch",
      "support": 15
    },
    {
      "x": -4,
      "y": 29,
      "z": 1,
      "name": "Plant_Leaves_Birch",
      "support": 15
    },
    {
      "x": -4,
      "y": 30,
      "z": 1,
      "name": "Plant_Leaves_Birch",
      "support": 15
    },
    {
      "x": -4,
      "y": 33,
      "z": 1,
      "name": "Plant_Leaves_Birch",
      "support": 15
    },
    {
      "x": -4,
      "y": 8,
      "z": 2,
      "name": "Rock_Stone"
    },
    {
      "x": -4,
      "y": 9,
      "z": 2,
      "name": "Rock_Stone"
    },
    {
      "x": -4,
      "y": 10,
      "z": 2,
      "name": "Rock_Stone"
    },
    {
      "x": -4,
      "y": 11,
      "z": 2,
      "name": "Rock_Stone"
    },
    {
      "x": -4,
      "y": 12,
      "z": 2,
      "name": "Rock_Stone"
    },
    {
      "x": -4,
      "y": 13,
      "z": 2,
      "name": "Rock_Stone"
    },
    {
      "x": -4,
      "y": 14,
      "z": 2,
      "name": "Rock_Stone"
    },
    {
      "x": -4,
      "y": 15,
      "z": 2,
      "name": "Rock_Stone"
    },
    {
      "x": -4,
      "y": 16,
      "z": 2,
      "name": "Soil_Dirt"
    },
    {
      "x": -4,
      "y": 17,
      "z": 2,
      "name": "Rock_Stone"
    },
    {
      "x": -4,
      "y": 18,
      "z": 2,
      "name": "Soil_Dirt"
    },
    {
      "x": -4,
      "y": 19,
      "z": 2,
      "name": "Soil_Dirt"
    },
    {
      "x": -4,
      "y": 20,
      "z": 2,
      "name": "Soil_Grass"
    },
    {
      "x": -4,
      "y": 21,
      "z": 2,
      "name": "Plant_Grass_Sharp"
    },
    {
      "x": -4,
      "y": 25,
      "z": 2,
      "name": "Plant_Leaves_Birch",
      "support": 15
    },
    {
      "x": -4,
      "y": 33,
      "z": 2,
      "name": "Wood_Birch_Branch_Long",
      "support": 15,
      "rotation": 5
    },
    {
      "x": -4,
      "y": 34,
      "z": 2,
      "name": "Plant_Leaves_Birch",
      "support": 15
    },
    {
      "x": -4,
      "y": 8,
      "z": 3,
      "name": "Rock_Stone"
    },
    {
      "x": -4,
      "y": 9,
      "z": 3,
      "name": "Rock_Stone"
    },
    {
      "x": -4,
      "y": 10,
      "z": 3,
      "name": "Rock_Stone"
    },
    {
      "x": -4,
      "y": 11,
      "z": 3,
      "name": "Rock_Stone"
    },
    {
      "x": -4,
      "y": 12,
      "z": 3,
      "name": "Rock_Stone"
    },
    {
      "x": -4,
      "y": 13,
      "z": 3,
      "name": "Rock_Stone"
    },
    {
      "x": -4,
      "y": 14,
      "z": 3,
      "name": "Rock_Stone"
    },
    {
      "x": -4,
      "y": 15,
      "z": 3,
      "name": "Rock_Stone"
    },
    {
      "x": -4,
      "y": 16,
      "z": 3,
      "name": "Rock_Stone"
    },
    {
      "x": -4,
      "y": 17,
      "z": 3,
      "name": "Rock_Stone"
    },
    {
      "x": -4,
      "y": 18,
      "z": 3,
      "name": "Soil_Dirt"
    },
    {
      "x": -4,
      "y": 19,
      "z": 3,
      "name": "Soil_Grass"
    },
    {
      "x": -4,
      "y": 24,
      "z": 3,
      "name": "Plant_Leaves_Birch",
      "support": 15
    },
    {
      "x": -4,
      "y": 25,
      "z": 3,
      "name": "Plant_Leaves_Birch",
      "support": 15
    },
    {
      "x": -4,
      "y": 30,
      "z": 3,
      "name": "Wood_Birch_Trunk_Full",
      "support": 15
    },
    {
      "x": -4,
      "y": 34,
      "z": 3,
      "name": "Plant_Leaves_Birch",
      "support": 15
    },
    {
      "x": -4,
      "y": 36,
      "z": 3,
      "name": "Plant_Leaves_Birch",
      "support": 15
    },
    {
      "x": -4,
      "y": 25,
      "z": 4,
      "name": "Plant_Leaves_Birch",
      "support": 15
    },
    {
      "x": -4,
      "y": 26,
      "z": 4,
      "name": "Plant_Leaves_Birch",
      "support": 15
    },
    {
      "x": -4,
      "y": 28,
      "z": 4,
      "name": "Wood_Birch_Trunk_Full",
      "support": 15
    },
    {
      "x": -4,
      "y": 29,
      "z": 4,
      "name": "Wood_Birch_Trunk_Full",
      "support": 15
    },
    {
      "x": -4,
      "y": 30,
      "z": 4,
      "name": "Wood_Birch_Trunk_Full",
      "support": 15
    },
    {
      "x": -4,
      "y": 31,
      "z": 4,
      "name": "Wood_Birch_Trunk_Full",
      "support": 15
    },
    {
      "x": -4,
      "y": 32,
      "z": 4,
      "name": "Wood_Birch_Trunk_Full",
      "support": 15
    },
    {
      "x": -4,
      "y": 37,
      "z": 4,
      "name": "Plant_Leaves_Birch",
      "support": 15
    },
    {
      "x": -4,
      "y": 25,
      "z": 5,
      "name": "Plant_Leaves_Birch",
      "support": 15
    },
    {
      "x": -4,
      "y": 28,
      "z": 5,
      "name": "Wood_Birch_Trunk_Full",
      "support": 15
    },
    {
      "x": -4,
      "y": 32,
      "z": 5,
      "name": "Wood_Birch_Branch_Long",
      "support": 15,
      "rotation": 4
    },
    {
      "x": -4,
      "y": 35,
      "z": 5,
      "name": "Plant_Leaves_Birch",
      "support": 15
    },
    {
      "x": -4,
      "y": 37,
      "z": 5,
      "name": "Plant_Leaves_Birch",
      "support": 15
    },
    {
      "x": -4,
      "y": 28,
      "z": 6,
      "name": "Wood_Birch_Branch_Long",
      "support": 15,
      "rotation": 4
    },
    {
      "x": -4,
      "y": 29,
      "z": 6,
      "name": "Plant_Leaves_Birch",
      "support": 15
    },
    {
      "x": -4,
      "y": 32,
      "z": 6,
      "name": "Plant_Leaves_Birch",
      "support": 15
    },
    {
      "x": -4,
      "y": 33,
      "z": 6,
      "name": "Plant_Leaves_Birch",
      "support": 15
    },
    {
      "x": -4,
      "y": 35,
      "z": 6,
      "name": "Plant_Leaves_Birch",
      "support": 15
    },
    {
      "x": -4,
      "y": 26,
      "z": 7,
      "name": "Plant_Leaves_Birch",
      "support": 15
    },
    {
      "x": -4,
      "y": 27,
      "z": 7,
      "name": "Plant_Leaves_Birch",
      "support": 15
    },
    {
      "x": -4,
      "y": 28,
      "z": 7,
      "name": "Plant_Leaves_Birch",
      "support": 15
    },
    {
      "x": -4,
      "y": 29,
      "z": 7,
      "name": "Plant_Leaves_Birch",
      "support": 15
    },
    {
      "x": -4,
      "y": 32,
      "z": 7,
      "name": "Plant_Leaves_Birch",
      "support": 15
    },
    {
      "x": -4,
      "y": 34,
      "z": 7,
      "name": "Plant_Leaves_Birch",
      "support": 15
    },
    {
      "x": -4,
      "y": 27,
      "z": 8,
      "name": "Plant_Leaves_Birch",
      "support": 15
    },
    {
      "x": -4,
      "y": 28,
      "z": 8,
      "name": "Plant_Leaves_Birch",
      "support": 15
    },
    {
      "x": -3,
      "y": 14,
      "z": -1,
      "name": "Rock_Stone"
    },
    {
      "x": -3,
      "y": 15,
      "z": -1,
      "name": "Rock_Stone"
    },
    {
      "x": -3,
      "y": 16,
      "z": -1,
      "name": "Rock_Stone"
    },
    {
      "x": -3,
      "y": 17,
      "z": -1,
      "name": "Rock_Stone"
    },
    {
      "x": -3,
      "y": 18,
      "z": -1,
      "name": "Soil_Dirt"
    },
    {
      "x": -3,
      "y": 19,
      "z": -1,
      "name": "Soil_Dirt"
    },
    {
      "x": -3,
      "y": 20,
      "z": -1,
      "name": "Soil_Dirt"
    },
    {
      "x": -3,
      "y": 21,
      "z": -1,
      "name": "Soil_Grass"
    },
    {
      "x": -3,
      "y": 9,
      "z": 0,
      "name": "Rock_Stone"
    },
    {
      "x": -3,
      "y": 10,
      "z": 0,
      "name": "Rock_Stone"
    },
    {
      "x": -3,
      "y": 11,
      "z": 0,
      "name": "Rock_Stone"
    },
    {
      "x": -3,
      "y": 12,
      "z": 0,
      "name": "Rock_Stone"
    },
    {
      "x": -3,
      "y": 13,
      "z": 0,
      "name": "Rock_Stone"
    },
    {
      "x": -3,
      "y": 14,
      "z": 0,
      "name": "Rock_Stone"
    },
    {
      "x": -3,
      "y": 15,
      "z": 0,
      "name": "Rock_Stone"
    },
    {
      "x": -3,
      "y": 16,
      "z": 0,
      "name": "Soil_Dirt"
    },
    {
      "x": -3,
      "y": 17,
      "z": 0,
      "name": "Soil_Dirt"
    },
    {
      "x": -3,
      "y": 18,
      "z": 0,
      "name": "Soil_Dirt"
    },
    {
      "x": -3,
      "y": 19,
      "z": 0,
      "name": "Soil_Dirt"
    },
    {
      "x": -3,
      "y": 20,
      "z": 0,
      "name": "Soil_Dirt"
    },
    {
      "x": -3,
      "y": 21,
      "z": 0,
      "name": "Soil_Grass"
    },
    {
      "x": -3,
      "y": 31,
      "z": 0,
      "name": "Plant_Leaves_Birch",
      "support": 15
    },
    {
      "x": -3,
      "y": 32,
      "z": 0,
      "name": "Plant_Leaves_Birch",
      "support": 15
    },
    {
      "x": -3,
      "y": 33,
      "z": 0,
      "name": "Plant_Leaves_Birch",
      "support": 15
    },
    {
      "x": -3,
      "y": 7,
      "z": 1,
      "name": "Rock_Stone"
    },
    {
      "x": -3,
      "y": 8,
      "z": 1,
      "name": "Rock_Stone"
    },
    {
      "x": -3,
      "y": 9,
      "z": 1,
      "name": "Rock_Stone"
    },
    {
      "x": -3,
      "y": 10,
      "z": 1,
      "name": "Rock_Stone"
    },
    {
      "x": -3,
      "y": 11,
      "z": 1,
      "name": "Rock_Stone"
    },
    {
      "x": -3,
      "y": 12,
      "z": 1,
      "name": "Rock_Stone"
    },
    {
      "x": -3,
      "y": 13,
      "z": 1,
      "name": "Rock_Stone"
    },
    {
      "x": -3,
      "y": 14,
      "z": 1,
      "name": "Rock_Stone"
    },
    {
      "x": -3,
      "y": 15,
      "z": 1,
      "name": "Rock_Stone"
    },
    {
      "x": -3,
      "y": 16,
      "z": 1,
      "name": "Soil_Dirt"
    },
    {
      "x": -3,
      "y": 17,
      "z": 1,
      "name": "Soil_Dirt"
    },
    {
      "x": -3,
      "y": 18,
      "z": 1,
      "name": "Soil_Dirt"
    },
    {
      "x": -3,
      "y": 19,
      "z": 1,
      "name": "Soil_Dirt"
    },
    {
      "x": -3,
      "y": 20,
      "z": 1,
      "name": "Soil_Dirt"
    },
    {
      "x": -3,
      "y": 21,
      "z": 1,
      "name": "Soil_Grass"
    },
    {
      "x": -3,
      "y": 26,
      "z": 1,
      "name": "Plant_Leaves_Birch",
      "support": 15
    },
    {
      "x": -3,
      "y": 27,
      "z": 1,
      "name": "Plant_Leaves_Birch",
      "support": 15
    },
    {
      "x": -3,
      "y": 28,
      "z": 1,
      "name": "Plant_Leaves_Birch",
      "support": 15
    },
    {
      "x": -3,
      "y": 32,
      "z": 1,
      "name": "Wood_Birch_Branch_Corner",
      "support": 15,
      "rotation": 2
    },
    {
      "x": -3,
      "y": 33,
      "z": 1,
      "name": "Plant_Leaves_Birch",
      "support": 15
    },
    {
      "x": -3,
      "y": 35,
      "z": 1,
      "name": "Plant_Leaves_Birch",
      "support": 15
    },
    {
      "x": -3,
      "y": 7,
      "z": 2,
      "name": "Rock_Stone"
    },
    {
      "x": -3,
      "y": 8,
      "z": 2,
      "name": "Rock_Stone"
    },
    {
      "x": -3,
      "y": 9,
      "z": 2,
      "name": "Rock_Stone"
    },
    {
      "x": -3,
      "y": 10,
      "z": 2,
      "name": "Rock_Stone"
    },
    {
      "x": -3,
      "y": 11,
      "z": 2,
      "name": "Rock_Stone"
    },
    {
      "x": -3,
      "y": 12,
      "z": 2,
      "name": "Rock_Stone"
    },
    {
      "x": -3,
      "y": 13,
      "z": 2,
      "name": "Rock_Stone"
    },
    {
      "x": -3,
      "y": 14,
      "z": 2,
      "name": "Rock_Stone"
    },
    {
      "x": -3,
      "y": 15,
      "z": 2,
      "name": "Rock_Stone"
    },
    {
      "x": -3,
      "y": 16,
      "z": 2,
      "name": "Soil_Dirt"
    },
    {
      "x": -3,
      "y": 17,
      "z": 2,
      "name": "Soil_Dirt"
    },
    {
      "x": -3,
      "y": 18,
      "z": 2,
      "name": "Soil_Dirt"
    },
    {
      "x": -3,
      "y": 19,
      "z": 2,
      "name": "Soil_Dirt"
    },
    {
      "x": -3,
      "y": 20,
      "z": 2,
      "name": "Soil_Grass"
    },
    {
      "x": -3,
      "y": 21,
      "z": 2,
      "name": "Plant_Grass_Sharp_Tall"
    },
    {
      "x": -3,
      "y": 22,
      "z": 2,
      "name": "Plant_Grass_Sharp_Tall",
      "filler": 1024
    },
    {
      "x": -3,
      "y": 30,
      "z": 2,
      "name": "Wood_Birch_Trunk_Full",
      "support": 15
    },
    {
      "x": -3,
      "y": 31,
      "z": 2,
      "name": "Wood_Birch_Trunk_Full",
      "support": 15
    },
    {
      "x": -3,
      "y": 32,
      "z": 2,
      "name": "Wood_Birch_Trunk_Full",
      "support": 15
    },
    {
      "x": -3,
      "y": 33,
      "z": 2,
      "name": "Wood_Birch_Trunk_Full",
      "support": 15
    },
    {
      "x": -3,
      "y": 34,
      "z": 2,
      "name": "Wood_Birch_Trunk_Full",
      "support": 15
    },
    {
      "x": -3,
      "y": 36,
      "z": 2,
      "name": "Plant_Leaves_Birch",
      "support": 15
    },
    {
      "x": -3,
      "y": 37,
      "z": 2,
      "name": "Plant_Leaves_Birch",
      "support": 15
    },
    {
      "x": -3,
      "y": 7,
      "z": 3,
      "name": "Rock_Stone"
    },
    {
      "x": -3,
      "y": 8,
      "z": 3,
      "name": "Rock_Stone"
    },
    {
      "x": -3,
      "y": 9,
      "z": 3,
      "name": "Rock_Stone"
    },
    {
      "x": -3,
      "y": 10,
      "z": 3,
      "name": "Rock_Stone"
    },
    {
      "x": -3,
      "y": 11,
      "z": 3,
      "name": "Rock_Stone"
    },
    {
      "x": -3,
      "y": 12,
      "z": 3,
      "name": "Rock_Stone"
    },
    {
      "x": -3,
      "y": 13,
      "z": 3,
      "name": "Rock_Stone"
    },
    {
      "x": -3,
      "y": 14,
      "z": 3,
      "name": "Rock_Stone"
    },
    {
      "x": -3,
      "y": 15,
      "z": 3,
      "name": "Rock_Stone"
    },
    {
      "x": -3,
      "y": 16,
      "z": 3,
      "name": "Rock_Stone"
    },
    {
      "x": -3,
      "y": 17,
      "z": 3,
      "name": "Soil_Dirt"
    },
    {
      "x": -3,
      "y": 18,
      "z": 3,
      "name": "Wood_Birch_Trunk_Full",
      "support": 15
    },
    {
      "x": -3,
      "y": 19,
      "z": 3,
      "name": "Soil_Dirt"
    },
    {
      "x": -3,
      "y": 20,
      "z": 3,
      "name": "Soil_Grass"
    },
    {
      "x": -3,
      "y": 21,
      "z": 3,
      "name": "Plant_Grass_Sharp"
    },
    {
      "x": -3,
      "y": 9,
      "z": 4,
      "name": "Rock_Stone"
    },
    {
      "x": -3,
      "y": 10,
      "z": 4,
      "name": "Rock_Stone"
    },
    {
      "x": -3,
      "y": 11,
      "z": 4,
      "name": "Rock_Stone"
    },
    {
      "x": -3,
      "y": 17,
      "z": 4,
      "name": "Rock_Stone"
    },
    {
      "x": -3,
      "y": 18,
      "z": 4,
      "name": "Wood_Birch_Trunk_Full",
      "support": 15
    },
    {
      "x": -3,
      "y": 25,
      "z": 4,
      "name": "Wood_Birch_Trunk_Full",
      "support": 15
    },
    {
      "x": -3,
      "y": 27,
      "z": 4,
      "name": "Wood_Birch_Trunk_Full",
      "support": 15
    },
    {
      "x": -3,
      "y": 28,
      "z": 4,
      "name": "Wood_Birch_Trunk_Full",
      "support": 15
    },
    {
      "x": -3,
      "y": 37,
      "z": 4,
      "name": "Plant_Leaves_Birch",
      "support": 15
    },
    {
      "x": -3,
      "y": 38,
      "z": 4,
      "name": "Plant_Leaves_Birch",
      "support": 15
    },
    {
      "x": -3,
      "y": 37,
      "z": 5,
      "name": "Plant_Leaves_Birch",
      "support": 15
    },
    {
      "x": -3,
      "y": 35,
      "z": 6,
      "name": "Plant_Leaves_Birch",
      "support": 15
    },
    {
      "x": -3,
      "y": 30,
      "z": 7,
      "name": "Plant_Leaves_Birch",
      "support": 15
    },
    {
      "x": -3,
      "y": 34,
      "z": 7,
      "name": "Plant_Leaves_Birch",
      "support": 15
    },
    {
      "x": -3,
      "y": 35,
      "z": 7,
      "name": "Plant_Leaves_Birch",
      "support": 15
    },
    {
      "x": -3,
      "y": 27,
      "z": 8,
      "name": "Plant_Leaves_Birch",
      "support": 15
    },
    {
      "x": -3,
      "y": 30,
      "z": 8,
      "name": "Plant_Leaves_Birch",
      "support": 15
    },
    {
      "x": -3,
      "y": 31,
      "z": 8,
      "name": "Plant_Leaves_Birch",
      "support": 15
    },
    {
      "x": -3,
      "y": 34,
      "z": 8,
      "name": "Plant_Leaves_Birch",
      "support": 15
    },
    {
      "x": -2,
      "y": 18,
      "z": -2,
      "name": "Rock_Stone"
    },
    {
      "x": -2,
      "y": 19,
      "z": -2,
      "name": "Soil_Dirt"
    },
    {
      "x": -2,
      "y": 20,
      "z": -2,
      "name": "Soil_Grass"
    },
    {
      "x": -2,
      "y": 21,
      "z": -2,
      "name": "Plant_Grass_Sharp"
    },
    {
      "x": -2,
      "y": 17,
      "z": -1,
      "name": "Rock_Stone"
    },
    {
      "x": -2,
      "y": 18,
      "z": -1,
      "name": "Rock_Stone"
    },
    {
      "x": -2,
      "y": 19,
      "z": -1,
      "name": "Soil_Dirt"
    },
    {
      "x": -2,
      "y": 20,
      "z": -1,
      "name": "Soil_Dirt"
    },
    {
      "x": -2,
      "y": 21,
      "z": -1,
      "name": "Soil_Dirt"
    },
    {
      "x": -2,
      "y": 22,
      "z": -1,
      "name": "Soil_Grass"
    },
    {
      "x": -2,
      "y": 10,
      "z": 0,
      "name": "Rock_Stone"
    },
    {
      "x": -2,
      "y": 11,
      "z": 0,
      "name": "Rock_Stone"
    },
    {
      "x": -2,
      "y": 15,
      "z": 0,
      "name": "Rock_Stone"
    },
    {
      "x": -2,
      "y": 16,
      "z": 0,
      "name": "Rock_Stone"
    },
    {
      "x": -2,
      "y": 17,
      "z": 0,
      "name": "Rock_Stone"
    },
    {
      "x": -2,
      "y": 18,
      "z": 0,
      "name": "Soil_Dirt"
    },
    {
      "x": -2,
      "y": 19,
      "z": 0,
      "name": "Soil_Dirt"
    },
    {
      "x": -2,
      "y": 20,
      "z": 0,
      "name": "Soil_Dirt"
    },
    {
      "x": -2,
      "y": 21,
      "z": 0,
      "name": "Soil_Dirt"
    },
    {
      "x": -2,
      "y": 22,
      "z": 0,
      "name": "Soil_Grass"
    },
    {
      "x": -2,
      "y": 29,
      "z": 0,
      "name": "Plant_Leaves_Birch",
      "support": 15
    },
    {
      "x": -2,
      "y": 31,
      "z": 0,
      "name": "Plant_Leaves_Birch",
      "support": 15
    },
    {
      "x": -2,
      "y": 32,
      "z": 0,
      "name": "Plant_Leaves_Birch",
      "support": 15
    },
    {
      "x": -2,
      "y": 6,
      "z": 1,
      "name": "Rock_Stone"
    },
    {
      "x": -2,
      "y": 7,
      "z": 1,
      "name": "Rock_Stone"
    },
    {
      "x": -2,
      "y": 8,
      "z": 1,
      "name": "Rock_Stone"
    },
    {
      "x": -2,
      "y": 9,
      "z": 1,
      "name": "Rock_Stone"
    },
    {
      "x": -2,
      "y": 10,
      "z": 1,
      "name": "Rock_Stone"
    },
    {
      "x": -2,
      "y": 11,
      "z": 1,
      "name": "Rock_Stone"
    },
    {
      "x": -2,
      "y": 12,
      "z": 1,
      "name": "Rock_Stone"
    },
    {
      "x": -2,
      "y": 13,
      "z": 1,
      "name": "Rock_Stone"
    },
    {
      "x": -2,
      "y": 14,
      "z": 1,
      "name": "Rock_Stone"
    },
    {
      "x": -2,
      "y": 15,
      "z": 1,
      "name": "Rock_Stone"
    },
    {
      "x": -2,
      "y": 16,
      "z": 1,
      "name": "Rock_Stone"
    },
    {
      "x": -2,
      "y": 17,
      "z": 1,
      "name": "Rock_Stone"
    },
    {
      "x": -2,
      "y": 18,
      "z": 1,
      "name": "Soil_Dirt"
    },
    {
      "x": -2,
      "y": 19,
      "z": 1,
      "name": "Soil_Dirt"
    },
    {
      "x": -2,
      "y": 20,
      "z": 1,
      "name": "Soil_Dirt"
    },
    {
      "x": -2,
      "y": 21,
      "z": 1,
      "name": "Soil_Dirt"
    },
    {
      "x": -2,
      "y": 22,
      "z": 1,
      "name": "Soil_Grass"
    },
    {
      "x": -2,
      "y": 29,
      "z": 1,
      "name": "Plant_Leaves_Birch",
      "support": 15
    },
    {
      "x": -2,
      "y": 32,
      "z": 1,
      "name": "Plant_Leaves_Birch",
      "support": 15
    },
    {
      "x": -2,
      "y": 35,
      "z": 1,
      "name": "Plant_Leaves_Birch",
      "support": 15
    },
    {
      "x": -2,
      "y": 36,
      "z": 1,
      "name": "Plant_Leaves_Birch",
      "support": 15
    },
    {
      "x": -2,
      "y": 6,
      "z": 2,
      "name": "Rock_Stone"
    },
    {
      "x": -2,
      "y": 7,
      "z": 2,
      "name": "Rock_Stone"
    },
    {
      "x": -2,
      "y": 8,
      "z": 2,
      "name": "Rock_Stone"
    },
    {
      "x": -2,
      "y": 9,
      "z": 2,
      "name": "Rock_Stone"
    },
    {
      "x": -2,
      "y": 10,
      "z": 2,
      "name": "Rock_Stone"
    },
    {
      "x": -2,
      "y": 11,
      "z": 2,
      "name": "Rock_Stone"
    },
    {
      "x": -2,
      "y": 12,
      "z": 2,
      "name": "Rock_Stone"
    },
    {
      "x": -2,
      "y": 13,
      "z": 2,
      "name": "Rock_Stone"
    },
    {
      "x": -2,
      "y": 14,
      "z": 2,
      "name": "Rock_Stone"
    },
    {
      "x": -2,
      "y": 15,
      "z": 2,
      "name": "Rock_Stone"
    },
    {
      "x": -2,
      "y": 16,
      "z": 2,
      "name": "Rock_Stone"
    },
    {
      "x": -2,
      "y": 17,
      "z": 2,
      "name": "Rock_Stone"
    },
    {
      "x": -2,
      "y": 18,
      "z": 2,
      "name": "Soil_Dirt"
    },
    {
      "x": -2,
      "y": 19,
      "z": 2,
      "name": "Soil_Dirt"
    },
    {
      "x": -2,
      "y": 20,
      "z": 2,
      "name": "Soil_Dirt"
    },
    {
      "x": -2,
      "y": 21,
      "z": 2,
      "name": "Soil_Dirt"
    },
    {
      "x": -2,
      "y": 22,
      "z": 2,
      "name": "Soil_Grass"
    },
    {
      "x": -2,
      "y": 35,
      "z": 2,
      "name": "Plant_Leaves_Birch",
      "support": 15
    },
    {
      "x": -2,
      "y": 36,
      "z": 2,
      "name": "Plant_Leaves_Birch",
      "support": 15
    },
    {
      "x": -2,
      "y": 37,
      "z": 2,
      "name": "Plant_Leaves_Birch",
      "support": 15
    },
    {
      "x": -2,
      "y": 6,
      "z": 3,
      "name": "Rock_Stone"
    },
    {
      "x": -2,
      "y": 7,
      "z": 3,
      "name": "Rock_Stone"
    },
    {
      "x": -2,
      "y": 8,
      "z": 3,
      "name": "Rock_Stone"
    },
    {
      "x": -2,
      "y": 9,
      "z": 3,
      "name": "Rock_Stone"
    },
    {
      "x": -2,
      "y": 10,
      "z": 3,
      "name": "Rock_Stone"
    },
    {
      "x": -2,
      "y": 11,
      "z": 3,
      "name": "Rock_Stone"
    },
    {
      "x": -2,
      "y": 12,
      "z": 3,
      "name": "Rock_Stone"
    },
    {
      "x": -2,
      "y": 15,
      "z": 3,
      "name": "Rock_Stone"
    },
    {
      "x": -2,
      "y": 16,
      "z": 3,
      "name": "Rock_Stone"
    },
    {
      "x": -2,
      "y": 17,
      "z": 3,
      "name": "Rock_Stone"
    },
    {
      "x": -2,
      "y": 18,
      "z": 3,
      "name": "Soil_Dirt"
    },
    {
      "x": -2,
      "y": 19,
      "z": 3,
      "name": "Soil_Dirt"
    },
    {
      "x": -2,
      "y": 20,
      "z": 3,
      "name": "Soil_Dirt"
    },
    {
      "x": -2,
      "y": 21,
      "z": 3,
      "name": "Soil_Grass"
    },
    {
      "x": -2,
      "y": 27,
      "z": 3,
      "name": "Wood_Birch_Trunk_Full",
      "support": 15
    },
    {
      "x": -2,
      "y": 36,
      "z": 3,
      "name": "Wood_Birch_Branch_Long",
      "support": 15,
      "rotation": 4
    },
    {
      "x": -2,
      "y": 38,
      "z": 3,
      "name": "Plant_Leaves_Birch",
      "support": 15
    },
    {
      "x": -2,
      "y": 6,
      "z": 4,
      "name": "Rock_Stone"
    },
    {
      "x": -2,
      "y": 7,
      "z": 4,
      "name": "Rock_Stone"
    },
    {
      "x": -2,
      "y": 8,
      "z": 4,
      "name": "Rock_Stone"
    },
    {
      "x": -2,
      "y": 9,
      "z": 4,
      "name": "Rock_Stone"
    },
    {
      "x": -2,
      "y": 16,
      "z": 4,
      "name": "Rock_Stone"
    },
    {
      "x": -2,
      "y": 17,
      "z": 4,
      "name": "Rock_Stone"
    },
    {
      "x": -2,
      "y": 18,
      "z": 4,
      "name": "Wood_Birch_Trunk_Full",
      "support": 15
    },
    {
      "x": -2,
      "y": 19,
      "z": 4,
      "name": "Wood_Birch_Trunk",
      "support": 15
    },
    {
      "x": -2,
      "y": 20,
      "z": 4,
      "name": "Wood_Birch_Trunk",
      "support": 15
    },
    {
      "x": -2,
      "y": 21,
      "z": 4,
      "name": "Wood_Birch_Trunk",
      "support": 15
    },
    {
      "x": -2,
      "y": 22,
      "z": 4,
      "name": "Wood_Birch_Trunk",
      "support": 15
    },
    {
      "x": -2,
      "y": 23,
      "z": 4,
      "name": "Wood_Birch_Trunk",
      "support": 15
    },
    {
      "x": -2,
      "y": 24,
      "z": 4,
      "name": "Wood_Birch_Trunk",
      "support": 15
    },
    {
      "x": -2,
      "y": 25,
      "z": 4,
      "name": "Wood_Birch_Trunk",
      "support": 15
    },
    {
      "x": -2,
      "y": 26,
      "z": 4,
      "name": "Wood_Birch_Trunk",
      "support": 15
    },
    {
      "x": -2,
      "y": 27,
      "z": 4,
      "name": "Wood_Birch_Trunk",
      "support": 15
    },
    {
      "x": -2,
      "y": 28,
      "z": 4,
      "name": "Wood_Birch_Trunk",
      "support": 15
    },
    {
      "x": -2,
      "y": 29,
      "z": 4,
      "name": "Wood_Birch_Trunk",
      "support": 15
    },
    {
      "x": -2,
      "y": 30,
      "z": 4,
      "name": "Wood_Birch_Trunk",
      "support": 15
    },
    {
      "x": -2,
      "y": 31,
      "z": 4,
      "name": "Wood_Birch_Trunk",
      "support": 15
    },
    {
      "x": -2,
      "y": 32,
      "z": 4,
      "name": "Wood_Birch_Trunk",
      "support": 15
    },
    {
      "x": -2,
      "y": 33,
      "z": 4,
      "name": "Wood_Birch_Trunk",
      "support": 15
    },
    {
      "x": -2,
      "y": 34,
      "z": 4,
      "name": "Wood_Birch_Trunk",
      "support": 15
    },
    {
      "x": -2,
      "y": 35,
      "z": 4,
      "name": "Wood_Birch_Trunk",
      "support": 15
    },
    {
      "x": -2,
      "y": 36,
      "z": 4,
      "name": "Wood_Birch_Trunk",
      "support": 15
    },
    {
      "x": -2,
      "y": 37,
      "z": 4,
      "name": "Wood_Birch_Trunk_Full",
      "support": 15
    },
    {
      "x": -2,
      "y": 38,
      "z": 4,
      "name": "Plant_Leaves_Birch",
      "support": 15
    },
    {
      "x": -2,
      "y": 18,
      "z": 5,
      "name": "Rock_Stone"
    },
    {
      "x": -2,
      "y": 19,
      "z": 5,
      "name": "Soil_Grass"
    },
    {
      "x": -2,
      "y": 35,
      "z": 5,
      "name": "Wood_Birch_Branch_Long",
      "support": 15,
      "rotation": 4
    },
    {
      "x": -2,
      "y": 28,
      "z": 6,
      "name": "Plant_Leaves_Birch",
      "support": 15
    },
    {
      "x": -2,
      "y": 31,
      "z": 6,
      "name": "Wood_Birch_Trunk_Full",
      "support": 15
    },
    {
      "x": -2,
      "y": 32,
      "z": 6,
      "name": "Wood_Birch_Trunk_Full",
      "support": 15
    },
    {
      "x": -2,
      "y": 33,
      "z": 6,
      "name": "Wood_Birch_Trunk_Full",
      "support": 15
    },
    {
      "x": -2,
      "y": 35,
      "z": 6,
      "name": "Wood_Birch_Branch_Corner",
      "support": 15
    },
    {
      "x": -2,
      "y": 36,
      "z": 6,
      "name": "Plant_Leaves_Birch",
      "support": 15
    },
    {
      "x": -2,
      "y": 37,
      "z": 6,
      "name": "Plant_Leaves_Birch",
      "support": 15
    },
    {
      "x": -2,
      "y": 27,
      "z": 7,
      "name": "Plant_Leaves_Birch",
      "support": 15
    },
    {
      "x": -2,
      "y": 28,
      "z": 7,
      "name": "Plant_Leaves_Birch",
      "support": 15
    },
    {
      "x": -2,
      "y": 31,
      "z": 7,
      "name": "Wood_Birch_Branch_Corner",
      "support": 15
    },
    {
      "x": -2,
      "y": 32,
      "z": 7,
      "name": "Plant_Leaves_Birch",
      "support": 15
    },
    {
      "x": -2,
      "y": 34,
      "z": 7,
      "name": "Plant_Leaves_Birch",
      "support": 15
    },
    {
      "x": -2,
      "y": 35,
      "z": 7,
      "name": "Plant_Leaves_Birch",
      "support": 15
    },
    {
      "x": -2,
      "y": 36,
      "z": 7,
      "name": "Plant_Leaves_Birch",
      "support": 15
    },
    {
      "x": -2,
      "y": 30,
      "z": 8,
      "name": "Plant_Leaves_Birch",
      "support": 15
    },
    {
      "x": -2,
      "y": 31,
      "z": 8,
      "name": "Plant_Leaves_Birch",
      "support": 15
    },
    {
      "x": -2,
      "y": 32,
      "z": 8,
      "name": "Plant_Leaves_Birch",
      "support": 15
    },
    {
      "x": -2,
      "y": 34,
      "z": 8,
      "name": "Plant_Leaves_Birch",
      "support": 15
    },
    {
      "x": -2,
      "y": 31,
      "z": 9,
      "name": "Plant_Leaves_Birch",
      "support": 15
    },
    {
      "x": -1,
      "y": 17,
      "z": -2,
      "name": "Rock_Stone"
    },
    {
      "x": -1,
      "y": 18,
      "z": -2,
      "name": "Rock_Stone"
    },
    {
      "x": -1,
      "y": 19,
      "z": -2,
      "name": "Rock_Stone"
    },
    {
      "x": -1,
      "y": 20,
      "z": -2,
      "name": "Soil_Dirt"
    },
    {
      "x": -1,
      "y": 21,
      "z": -2,
      "name": "Soil_Grass"
    },
    {
      "x": -1,
      "y": 17,
      "z": -1,
      "name": "Rock_Stone"
    },
    {
      "x": -1,
      "y": 18,
      "z": -1,
      "name": "Rock_Stone"
    },
    {
      "x": -1,
      "y": 19,
      "z": -1,
      "name": "Soil_Dirt"
    },
    {
      "x": -1,
      "y": 20,
      "z": -1,
      "name": "Soil_Dirt"
    },
    {
      "x": -1,
      "y": 21,
      "z": -1,
      "name": "Soil_Dirt"
    },
    {
      "x": -1,
      "y": 22,
      "z": -1,
      "name": "Soil_Grass"
    },
    {
      "x": -1,
      "y": 16,
      "z": 0,
      "name": "Rock_Stone"
    },
    {
      "x": -1,
      "y": 17,
      "z": 0,
      "name": "Rock_Stone"
    },
    {
      "x": -1,
      "y": 18,
      "z": 0,
      "name": "Rock_Stone"
    },
    {
      "x": -1,
      "y": 19,
      "z": 0,
      "name": "Soil_Dirt"
    },
    {
      "x": -1,
      "y": 20,
      "z": 0,
      "name": "Soil_Dirt"
    },
    {
      "x": -1,
      "y": 21,
      "z": 0,
      "name": "Soil_Dirt"
    },
    {
      "x": -1,
      "y": 22,
      "z": 0,
      "name": "Soil_Grass"
    },
    {
      "x": -1,
      "y": 23,
      "z": 0,
      "name": "Plant_Grass_Sharp"
    },
    {
      "x": -1,
      "y": 27,
      "z": 0,
      "name": "Plant_Leaves_Birch",
      "support": 15
    },
    {
      "x": -1,
      "y": 28,
      "z": 0,
      "name": "Plant_Leaves_Birch",
      "support": 15
    },
    {
      "x": -1,
      "y": 29,
      "z": 0,
      "name": "Plant_Leaves_Birch",
      "support": 15
    },
    {
      "x": -1,
      "y": 30,
      "z": 0,
      "name": "Plant_Leaves_Birch",
      "support": 15
    },
    {
      "x": -1,
      "y": 6,
      "z": 1,
      "name": "Rock_Stone"
    },
    {
      "x": -1,
      "y": 7,
      "z": 1,
      "name": "Rock_Stone"
    },
    {
      "x": -1,
      "y": 8,
      "z": 1,
      "name": "Rock_Stone"
    },
    {
      "x": -1,
      "y": 9,
      "z": 1,
      "name": "Rock_Stone"
    },
    {
      "x": -1,
      "y": 16,
      "z": 1,
      "name": "Rock_Stone"
    },
    {
      "x": -1,
      "y": 17,
      "z": 1,
      "name": "Rock_Stone"
    },
    {
      "x": -1,
      "y": 18,
      "z": 1,
      "name": "Soil_Dirt"
    },
    {
      "x": -1,
      "y": 19,
      "z": 1,
      "name": "Soil_Dirt"
    },
    {
      "x": -1,
      "y": 20,
      "z": 1,
      "name": "Soil_Dirt"
    },
    {
      "x": -1,
      "y": 21,
      "z": 1,
      "name": "Soil_Dirt"
    },
    {
      "x": -1,
      "y": 22,
      "z": 1,
      "name": "Soil_Grass"
    },
    {
      "x": -1,
      "y": 29,
      "z": 1,
      "name": "Wood_Birch_Branch_Long",
      "support": 15,
      "rotation": 4
    },
    {
      "x": -1,
      "y": 30,
      "z": 1,
      "name": "Plant_Leaves_Birch",
      "support": 15
    },
    {
      "x": -1,
      "y": 32,
      "z": 1,
      "name": "Plant_Leaves_Birch",
      "support": 15
    },
    {
      "x": -1,
      "y": 34,
      "z": 1,
      "name": "Plant_Leaves_Birch",
      "support": 15
    },
    {
      "x": -1,
      "y": 36,
      "z": 1,
      "name": "Plant_Leaves_Birch",
      "support": 15
    },
    {
      "x": -1,
      "y": 5,
      "z": 2,
      "name": "Rock_Stone"
    },
    {
      "x": -1,
      "y": 6,
      "z": 2,
      "name": "Rock_Stone"
    },
    {
      "x": -1,
      "y": 7,
      "z": 2,
      "name": "Rock_Stone"
    },
    {
      "x": -1,
      "y": 8,
      "z": 2,
      "name": "Rock_Stone"
    },
    {
      "x": -1,
      "y": 9,
      "z": 2,
      "name": "Rock_Stone"
    },
    {
      "x": -1,
      "y": 10,
      "z": 2,
      "name": "Rock_Stone"
    },
    {
      "x": -1,
      "y": 11,
      "z": 2,
      "name": "Rock_Stone"
    },
    {
      "x": -1,
      "y": 16,
      "z": 2,
      "name": "Rock_Stone"
    },
    {
      "x": -1,
      "y": 17,
      "z": 2,
      "name": "Rock_Stone"
    },
    {
      "x": -1,
      "y": 18,
      "z": 2,
      "name": "Soil_Dirt"
    },
    {
      "x": -1,
      "y": 19,
      "z": 2,
      "name": "Soil_Dirt"
    },
    {
      "x": -1,
      "y": 20,
      "z": 2,
      "name": "Soil_Dirt"
    },
    {
      "x": -1,
      "y": 21,
      "z": 2,
      "name": "Soil_Dirt"
    },
    {
      "x": -1,
      "y": 22,
      "z": 2,
      "name": "Soil_Grass"
    },
    {
      "x": -1,
      "y": 29,
      "z": 2,
      "name": "Wood_Birch_Trunk_Full",
      "support": 15
    },
    {
      "x": -1,
      "y": 30,
      "z": 2,
      "name": "Wood_Birch_Trunk_Full",
      "support": 15
    },
    {
      "x": -1,
      "y": 31,
      "z": 2,
      "name": "Wood_Birch_Trunk_Full",
      "support": 15
    },
    {
      "x": -1,
      "y": 34,
      "z": 2,
      "name": "Plant_Leaves_Birch",
      "support": 15
    },
    {
      "x": -1,
      "y": 36,
      "z": 2,
      "name": "Plant_Leaves_Birch",
      "support": 15
    },
    {
      "x": -1,
      "y": 37,
      "z": 2,
      "name": "Plant_Leaves_Birch",
      "support": 15
    },
    {
      "x": -1,
      "y": 5,
      "z": 3,
      "name": "Rock_Stone"
    },
    {
      "x": -1,
      "y": 6,
      "z": 3,
      "name": "Rock_Stone"
    },
    {
      "x": -1,
      "y": 7,
      "z": 3,
      "name": "Rock_Stone"
    },
    {
      "x": -1,
      "y": 8,
      "z": 3,
      "name": "Rock_Stone"
    },
    {
      "x": -1,
      "y": 9,
      "z": 3,
      "name": "Rock_Stone"
    },
    {
      "x": -1,
      "y": 10,
      "z": 3,
      "name": "Rock_Stone"
    },
    {
      "x": -1,
      "y": 16,
      "z": 3,
      "name": "Rock_Stone"
    },
    {
      "x": -1,
      "y": 17,
      "z": 3,
      "name": "Rock_Stone"
    },
    {
      "x": -1,
      "y": 18,
      "z": 3,
      "name": "Soil_Dirt"
    },
    {
      "x": -1,
      "y": 19,
      "z": 3,
      "name": "Soil_Dirt"
    },
    {
      "x": -1,
      "y": 20,
      "z": 3,
      "name": "Soil_Dirt"
    },
    {
      "x": -1,
      "y": 21,
      "z": 3,
      "name": "Soil_Dirt"
    },
    {
      "x": -1,
      "y": 22,
      "z": 3,
      "name": "Soil_Grass"
    },
    {
      "x": -1,
      "y": 27,
      "z": 3,
      "name": "Wood_Birch_Trunk_Full",
      "support": 15
    },
    {
      "x": -1,
      "y": 28,
      "z": 3,
      "name": "Wood_Birch_Trunk_Full",
      "support": 15
    },
    {
      "x": -1,
      "y": 29,
      "z": 3,
      "name": "Wood_Birch_Trunk_Full",
      "support": 15
    },
    {
      "x": -1,
      "y": 33,
      "z": 3,
      "name": "Wood_Birch_Trunk_Full",
      "support": 15
    },
    {
      "x": -1,
      "y": 5,
      "z": 4,
      "name": "Rock_Stone"
    },
    {
      "x": -1,
      "y": 6,
      "z": 4,
      "name": "Rock_Stone"
    },
    {
      "x": -1,
      "y": 7,
      "z": 4,
      "name": "Rock_Stone"
    },
    {
      "x": -1,
      "y": 8,
      "z": 4,
      "name": "Rock_Stone"
    },
    {
      "x": -1,
      "y": 16,
      "z": 4,
      "name": "Rock_Stone"
    },
    {
      "x": -1,
      "y": 17,
      "z": 4,
      "name": "Rock_Stone"
    },
    {
      "x": -1,
      "y": 18,
      "z": 4,
      "name": "Wood_Birch_Trunk_Full",
      "support": 15
    },
    {
      "x": -1,
      "y": 19,
      "z": 4,
      "name": "Soil_Dirt"
    },
    {
      "x": -1,
      "y": 20,
      "z": 4,
      "name": "Soil_Dirt"
    },
    {
      "x": -1,
      "y": 21,
      "z": 4,
      "name": "Soil_Dirt"
    },
    {
      "x": -1,
      "y": 22,
      "z": 4,
      "name": "Soil_Grass"
    },
    {
      "x": -1,
      "y": 26,
      "z": 4,
      "name": "Wood_Birch_Trunk_Full",
      "support": 15
    },
    {
      "x": -1,
      "y": 27,
      "z": 4,
      "name": "Wood_Birch_Trunk_Full",
      "support": 15
    },
    {
      "x": -1,
      "y": 33,
      "z": 4,
      "name": "Wood_Birch_Trunk_Full",
      "support": 15
    },
    {
      "x": -1,
      "y": 36,
      "z": 4,
      "name": "Wood_Birch_Branch_Long",
      "support": 15,
      "rotation": 5
    },
    {
      "x": -1,
      "y": 38,
      "z": 4,
      "name": "Plant_Leaves_Birch",
      "support": 15
    },
    {
      "x": -1,
      "y": 7,
      "z": 5,
      "name": "Rock_Stone"
    },
    {
      "x": -1,
      "y": 18,
      "z": 5,
      "name": "Rock_Stone"
    },
    {
      "x": -1,
      "y": 19,
      "z": 5,
      "name": "Soil_Dirt"
    },
    {
      "x": -1,
      "y": 20,
      "z": 5,
      "name": "Soil_Grass"
    },
    {
      "x": -1,
      "y": 37,
      "z": 5,
      "name": "Plant_Leaves_Birch",
      "support": 15
    },
    {
      "x": -1,
      "y": 28,
      "z": 6,
      "name": "Plant_Leaves_Birch",
      "support": 15
    },
    {
      "x": -1,
      "y": 31,
      "z": 6,
      "name": "Wood_Birch_Trunk_Full",
      "support": 15
    },
    {
      "x": -1,
      "y": 35,
      "z": 6,
      "name": "Plant_Leaves_Birch",
      "support": 15
    },
    {
      "x": -1,
      "y": 26,
      "z": 7,
      "name": "Plant_Leaves_Birch",
      "support": 15
    },
    {
      "x": -1,
      "y": 27,
      "z": 7,
      "name": "Plant_Leaves_Birch",
      "support": 15
    },
    {
      "x": -1,
      "y": 28,
      "z": 7,
      "name": "Plant_Leaves_Birch",
      "support": 15
    },
    {
      "x": -1,
      "y": 29,
      "z": 7,
      "name": "Plant_Leaves_Birch",
      "support": 15
    },
    {
      "x": -1,
      "y": 31,
      "z": 7,
      "name": "Plant_Leaves_Birch",
      "support": 15
    },
    {
      "x": -1,
      "y": 34,
      "z": 7,
      "name": "Plant_Leaves_Birch",
      "support": 15
    },
    {
      "x": -1,
      "y": 35,
      "z": 7,
      "name": "Plant_Leaves_Birch",
      "support": 15
    },
    {
      "x": -1,
      "y": 26,
      "z": 8,
      "name": "Plant_Leaves_Birch",
      "support": 15
    },
    {
      "x": -1,
      "y": 27,
      "z": 8,
      "name": "Plant_Leaves_Birch",
      "support": 15
    },
    {
      "x": -1,
      "y": 28,
      "z": 8,
      "name": "Plant_Leaves_Birch",
      "support": 15
    },
    {
      "x": -1,
      "y": 30,
      "z": 8,
      "name": "Plant_Leaves_Birch",
      "support": 15
    },
    {
      "x": -1,
      "y": 31,
      "z": 8,
      "name": "Plant_Leaves_Birch",
      "support": 15
    },
    {
      "x": -1,
      "y": 32,
      "z": 8,
      "name": "Plant_Leaves_Birch",
      "support": 15
    },
    {
      "x": -1,
      "y": 30,
      "z": 9,
      "name": "Plant_Leaves_Birch",
      "support": 15
    },
    {
      "x": -1,
      "y": 31,
      "z": 9,
      "name": "Plant_Leaves_Birch",
      "support": 15
    },
    {
      "x": 0,
      "y": 19,
      "z": -3,
      "name": "Rock_Stone"
    },
    {
      "x": 0,
      "y": 20,
      "z": -3,
      "name": "Soil_Grass"
    },
    {
      "x": 0,
      "y": 18,
      "z": -2,
      "name": "Rock_Stone"
    },
    {
      "x": 0,
      "y": 19,
      "z": -2,
      "name": "Soil_Dirt"
    },
    {
      "x": 0,
      "y": 20,
      "z": -2,
      "name": "Soil_Dirt"
    },
    {
      "x": 0,
      "y": 21,
      "z": -2,
      "name": "Soil_Dirt"
    },
    {
      "x": 0,
      "y": 22,
      "z": -2,
      "name": "Soil_Grass"
    },
    {
      "x": 0,
      "y": 17,
      "z": -1,
      "name": "Rock_Stone"
    },
    {
      "x": 0,
      "y": 18,
      "z": -1,
      "name": "Rock_Stone"
    },
    {
      "x": 0,
      "y": 19,
      "z": -1,
      "name": "Rock_Stone"
    },
    {
      "x": 0,
      "y": 20,
      "z": -1,
      "name": "Soil_Dirt"
    },
    {
      "x": 0,
      "y": 21,
      "z": -1,
      "name": "Soil_Dirt"
    },
    {
      "x": 0,
      "y": 22,
      "z": -1,
      "name": "Soil_Grass"
    },
    {
      "x": 0,
      "y": 23,
      "z": -1,
      "name": "Plant_Grass_Sharp"
    },
    {
      "x": 0,
      "y": 17,
      "z": 0,
      "name": "Rock_Stone"
    },
    {
      "x": 0,
      "y": 18,
      "z": 0,
      "name": "Rock_Stone"
    },
    {
      "x": 0,
      "y": 19,
      "z": 0,
      "name": "Rock_Stone"
    },
    {
      "x": 0,
      "y": 20,
      "z": 0,
      "name": "Soil_Dirt"
    },
    {
      "x": 0,
      "y": 21,
      "z": 0,
      "name": "Soil_Dirt"
    },
    {
      "x": 0,
      "y": 22,
      "z": 0,
      "name": "Soil_Dirt"
    },
    {
      "x": 0,
      "y": 23,
      "z": 0,
      "name": "Soil_Grass"
    },
    {
      "x": 0,
      "y": 27,
      "z": 0,
      "name": "Plant_Leaves_Birch",
      "support": 15
    },
    {
      "x": 0,
      "y": 28,
      "z": 0,
      "name": "Plant_Leaves_Birch",
      "support": 15
    },
    {
      "x": 0,
      "y": 29,
      "z": 0,
      "name": "Plant_Leaves_Birch",
      "support": 15
    },
    {
      "x": 0,
      "y": 6,
      "z": 1,
      "name": "Rock_Stone"
    },
    {
      "x": 0,
      "y": 7,
      "z": 1,
      "name": "Rock_Stone"
    },
    {
      "x": 0,
      "y": 16,
      "z": 1,
      "name": "Rock_Stone"
    },
    {
      "x": 0,
      "y": 17,
      "z": 1,
      "name": "Rock_Stone"
    },
    {
      "x": 0,
      "y": 18,
      "z": 1,
      "name": "Rock_Stone"
    },
    {
      "x": 0,
      "y": 19,
      "z": 1,
      "name": "Rock_Stone"
    },
    {
      "x": 0,
      "y": 20,
      "z": 1,
      "name": "Soil_Dirt"
    },
    {
      "x": 0,
      "y": 21,
      "z": 1,
      "name": "Soil_Dirt"
    },
    {
      "x": 0,
      "y": 22,
      "z": 1,
      "name": "Soil_Dirt"
    },
    {
      "x": 0,
      "y": 23,
      "z": 1,
      "name": "Soil_Grass"
    },
    {
      "x": 0,
      "y": 26,
      "z": 1,
      "name": "Plant_Leaves_Birch",
      "support": 15
    },
    {
      "x": 0,
      "y": 29,
      "z": 1,
      "name": "Plant_Leaves_Birch",
      "support": 15
    },
    {
      "x": 0,
      "y": 30,
      "z": 1,
      "name": "Plant_Leaves_Birch",
      "support": 15
    },
    {
      "x": 0,
      "y": 33,
      "z": 1,
      "name": "Plant_Leaves_Birch",
      "support": 15
    },
    {
      "x": 0,
      "y": 5,
      "z": 2,
      "name": "Rock_Stone"
    },
    {
      "x": 0,
      "y": 6,
      "z": 2,
      "name": "Rock_Stone"
    },
    {
      "x": 0,
      "y": 7,
      "z": 2,
      "name": "Rock_Stone"
    },
    {
      "x": 0,
      "y": 8,
      "z": 2,
      "name": "Rock_Stone"
    },
    {
      "x": 0,
      "y": 16,
      "z": 2,
      "name": "Rock_Stone"
    },
    {
      "x": 0,
      "y": 17,
      "z": 2,
      "name": "Rock_Stone"
    },
    {
      "x": 0,
      "y": 18,
      "z": 2,
      "name": "Rock_Stone"
    },
    {
      "x": 0,
      "y": 19,
      "z": 2,
      "name": "Soil_Dirt"
    },
    {
      "x": 0,
      "y": 20,
      "z": 2,
      "name": "Soil_Dirt"
    },
    {
      "x": 0,
      "y": 21,
      "z": 2,
      "name": "Soil_Dirt"
    },
    {
      "x": 0,
      "y": 22,
      "z": 2,
      "name": "Soil_Grass"
    },
    {
      "x": 0,
      "y": 33,
      "z": 2,
      "name": "Plant_Leaves_Birch",
      "support": 15
    },
    {
      "x": 0,
      "y": 34,
      "z": 2,
      "name": "Plant_Leaves_Birch",
      "support": 15
    },
    {
      "x": 0,
      "y": 36,
      "z": 2,
      "name": "Plant_Leaves_Birch",
      "support": 15
    },
    {
      "x": 0,
      "y": 4,
      "z": 3,
      "name": "Rock_Stone"
    },
    {
      "x": 0,
      "y": 5,
      "z": 3,
      "name": "Rock_Stone"
    },
    {
      "x": 0,
      "y": 6,
      "z": 3,
      "name": "Rock_Stone"
    },
    {
      "x": 0,
      "y": 7,
      "z": 3,
      "name": "Rock_Stone"
    },
    {
      "x": 0,
      "y": 8,
      "z": 3,
      "name": "Rock_Stone"
    },
    {
      "x": 0,
      "y": 16,
      "z": 3,
      "name": "Rock_Stone"
    },
    {
      "x": 0,
      "y": 17,
      "z": 3,
      "name": "Rock_Stone"
    },
    {
      "x": 0,
      "y": 18,
      "z": 3,
      "name": "Rock_Stone"
    },
    {
      "x": 0,
      "y": 19,
      "z": 3,
      "name": "Soil_Dirt"
    },
    {
      "x": 0,
      "y": 20,
      "z": 3,
      "name": "Soil_Dirt"
    },
    {
      "x": 0,
      "y": 21,
      "z": 3,
      "name": "Soil_Dirt"
    },
    {
      "x": 0,
      "y": 22,
      "z": 3,
      "name": "Soil_Grass"
    },
    {
      "x": 0,
      "y": 33,
      "z": 3,
      "name": "Wood_Birch_Trunk_Full",
      "support": 15
    },
    {
      "x": 0,
      "y": 36,
      "z": 3,
      "name": "Plant_Leaves_Birch",
      "support": 15
    },
    {
      "x": 0,
      "y": 5,
      "z": 4,
      "name": "Rock_Stone"
    },
    {
      "x": 0,
      "y": 6,
      "z": 4,
      "name": "Rock_Stone"
    },
    {
      "x": 0,
      "y": 7,
      "z": 4,
      "name": "Rock_Stone"
    },
    {
      "x": 0,
      "y": 17,
      "z": 4,
      "name": "Rock_Stone"
    },
    {
      "x": 0,
      "y": 18,
      "z": 4,
      "name": "Rock_Stone"
    },
    {
      "x": 0,
      "y": 19,
      "z": 4,
      "name": "Soil_Dirt"
    },
    {
      "x": 0,
      "y": 20,
      "z": 4,
      "name": "Soil_Dirt"
    },
    {
      "x": 0,
      "y": 21,
      "z": 4,
      "name": "Soil_Dirt"
    },
    {
      "x": 0,
      "y": 22,
      "z": 4,
      "name": "Soil_Grass"
    },
    {
      "x": 0,
      "y": 27,
      "z": 4,
      "name": "Wood_Birch_Trunk_Full",
      "support": 15
    },
    {
      "x": 0,
      "y": 35,
      "z": 4,
      "name": "Plant_Leaves_Birch",
      "support": 15
    },
    {
      "x": 0,
      "y": 36,
      "z": 4,
      "name": "Plant_Leaves_Birch",
      "support": 15
    },
    {
      "x": 0,
      "y": 37,
      "z": 4,
      "name": "Plant_Leaves_Birch",
      "support": 15
    },
    {
      "x": 0,
      "y": 5,
      "z": 5,
      "name": "Rock_Stone"
    },
    {
      "x": 0,
      "y": 6,
      "z": 5,
      "name": "Rock_Stone"
    },
    {
      "x": 0,
      "y": 7,
      "z": 5,
      "name": "Rock_Stone"
    },
    {
      "x": 0,
      "y": 19,
      "z": 5,
      "name": "Rock_Stone"
    },
    {
      "x": 0,
      "y": 20,
      "z": 5,
      "name": "Soil_Grass"
    },
    {
      "x": 0,
      "y": 27,
      "z": 5,
      "name": "Wood_Birch_Trunk_Full",
      "support": 15
    },
    {
      "x": 0,
      "y": 28,
      "z": 5,
      "name": "Wood_Birch_Trunk_Full",
      "support": 15
    },
    {
      "x": 0,
      "y": 29,
      "z": 5,
      "name": "Wood_Birch_Trunk_Full",
      "support": 15
    },
    {
      "x": 0,
      "y": 30,
      "z": 5,
      "name": "Wood_Birch_Trunk_Full",
      "support": 15
    },
    {
      "x": 0,
      "y": 31,
      "z": 5,
      "name": "Wood_Birch_Trunk_Full",
      "support": 15
    },
    {
      "x": 0,
      "y": 32,
      "z": 5,
      "name": "Wood_Birch_Trunk_Full",
      "support": 15
    },
    {
      "x": 0,
      "y": 35,
      "z": 5,
      "name": "Plant_Leaves_Birch",
      "support": 15
    },
    {
      "x": 0,
      "y": 36,
      "z": 5,
      "name": "Plant_Leaves_Birch",
      "support": 15
    },
    {
      "x": 0,
      "y": 37,
      "z": 5,
      "name": "Plant_Leaves_Birch",
      "support": 15
    },
    {
      "x": 0,
      "y": 27,
      "z": 6,
      "name": "Wood_Birch_Branch_Corner",
      "support": 15
    },
    {
      "x": 0,
      "y": 28,
      "z": 6,
      "name": "Plant_Leaves_Birch",
      "support": 15
    },
    {
      "x": 0,
      "y": 31,
      "z": 6,
      "name": "Wood_Birch_Trunk_Full",
      "support": 15
    },
    {
      "x": 0,
      "y": 34,
      "z": 6,
      "name": "Plant_Leaves_Birch",
      "support": 15
    },
    {
      "x": 0,
      "y": 27,
      "z": 7,
      "name": "Plant_Leaves_Birch",
      "support": 15
    },
    {
      "x": 0,
      "y": 28,
      "z": 7,
      "name": "Plant_Leaves_Birch",
      "support": 15
    },
    {
      "x": 0,
      "y": 34,
      "z": 7,
      "name": "Plant_Leaves_Birch",
      "support": 15
    },
    {
      "x": 0,
      "y": 27,
      "z": 8,
      "name": "Plant_Leaves_Birch",
      "support": 15
    },
    {
      "x": 0,
      "y": 31,
      "z": 8,
      "name": "Plant_Leaves_Birch",
      "support": 15
    },
    {
      "x": 0,
      "y": 30,
      "z": 9,
      "name": "Plant_Leaves_Birch",
      "support": 15
    },
    {
      "x": 1,
      "y": 18,
      "z": -3,
      "name": "Rock_Stone"
    },
    {
      "x": 1,
      "y": 19,
      "z": -3,
      "name": "Rock_Stone"
    },
    {
      "x": 1,
      "y": 20,
      "z": -3,
      "name": "Soil_Grass"
    },
    {
      "x": 1,
      "y": 18,
      "z": -2,
      "name": "Rock_Stone"
    },
    {
      "x": 1,
      "y": 19,
      "z": -2,
      "name": "Rock_Stone"
    },
    {
      "x": 1,
      "y": 20,
      "z": -2,
      "name": "Soil_Dirt"
    },
    {
      "x": 1,
      "y": 21,
      "z": -2,
      "name": "Soil_Dirt"
    },
    {
      "x": 1,
      "y": 22,
      "z": -2,
      "name": "Soil_Grass"
    },
    {
      "x": 1,
      "y": 23,
      "z": -2,
      "name": "Plant_Grass_Sharp"
    },
    {
      "x": 1,
      "y": 17,
      "z": -1,
      "name": "Rock_Stone"
    },
    {
      "x": 1,
      "y": 18,
      "z": -1,
      "name": "Rock_Stone"
    },
    {
      "x": 1,
      "y": 19,
      "z": -1,
      "name": "Rock_Stone"
    },
    {
      "x": 1,
      "y": 20,
      "z": -1,
      "name": "Soil_Dirt"
    },
    {
      "x": 1,
      "y": 21,
      "z": -1,
      "name": "Soil_Dirt"
    },
    {
      "x": 1,
      "y": 22,
      "z": -1,
      "name": "Soil_Grass"
    },
    {
      "x": 1,
      "y": 23,
      "z": -1,
      "name": "Plant_Grass_Sharp_Tall"
    },
    {
      "x": 1,
      "y": 24,
      "z": -1,
      "name": "Plant_Grass_Sharp_Tall",
      "filler": 1024
    },
    {
      "x": 1,
      "y": 17,
      "z": 0,
      "name": "Rock_Stone"
    },
    {
      "x": 1,
      "y": 18,
      "z": 0,
      "name": "Rock_Stone"
    },
    {
      "x": 1,
      "y": 19,
      "z": 0,
      "name": "Rock_Stone"
    },
    {
      "x": 1,
      "y": 20,
      "z": 0,
      "name": "Soil_Dirt"
    },
    {
      "x": 1,
      "y": 21,
      "z": 0,
      "name": "Soil_Dirt"
    },
    {
      "x": 1,
      "y": 22,
      "z": 0,
      "name": "Soil_Dirt"
    },
    {
      "x": 1,
      "y": 23,
      "z": 0,
      "name": "Soil_Grass"
    },
    {
      "x": 1,
      "y": 28,
      "z": 0,
      "name": "Plant_Leaves_Birch",
      "support": 15
    },
    {
      "x": 1,
      "y": 17,
      "z": 1,
      "name": "Rock_Stone"
    },
    {
      "x": 1,
      "y": 18,
      "z": 1,
      "name": "Rock_Stone"
    },
    {
      "x": 1,
      "y": 19,
      "z": 1,
      "name": "Rock_Stone"
    },
    {
      "x": 1,
      "y": 20,
      "z": 1,
      "name": "Rock_Stone"
    },
    {
      "x": 1,
      "y": 21,
      "z": 1,
      "name": "Soil_Dirt"
    },
    {
      "x": 1,
      "y": 22,
      "z": 1,
      "name": "Soil_Dirt"
    },
    {
      "x": 1,
      "y": 23,
      "z": 1,
      "name": "Soil_Grass"
    },
    {
      "x": 1,
      "y": 27,
      "z": 1,
      "name": "Plant_Leaves_Birch",
      "support": 15
    },
    {
      "x": 1,
      "y": 28,
      "z": 1,
      "name": "Plant_Leaves_Birch",
      "support": 15
    },
    {
      "x": 1,
      "y": 29,
      "z": 1,
      "name": "Plant_Leaves_Birch",
      "support": 15
    },
    {
      "x": 1,
      "y": 32,
      "z": 1,
      "name": "Plant_Leaves_Birch",
      "support": 15
    },
    {
      "x": 1,
      "y": 5,
      "z": 2,
      "name": "Rock_Stone"
    },
    {
      "x": 1,
      "y": 6,
      "z": 2,
      "name": "Rock_Stone"
    },
    {
      "x": 1,
      "y": 7,
      "z": 2,
      "name": "Rock_Stone"
    },
    {
      "x": 1,
      "y": 16,
      "z": 2,
      "name": "Rock_Stone"
    },
    {
      "x": 1,
      "y": 17,
      "z": 2,
      "name": "Rock_Stone"
    },
    {
      "x": 1,
      "y": 18,
      "z": 2,
      "name": "Rock_Stone"
    },
    {
      "x": 1,
      "y": 19,
      "z": 2,
      "name": "Rock_Stone"
    },
    {
      "x": 1,
      "y": 20,
      "z": 2,
      "name": "Soil_Dirt"
    },
    {
      "x": 1,
      "y": 21,
      "z": 2,
      "name": "Soil_Dirt"
    },
    {
      "x": 1,
      "y": 22,
      "z": 2,
      "name": "Soil_Dirt"
    },
    {
      "x": 1,
      "y": 23,
      "z": 2,
      "name": "Soil_Grass"
    },
    {
      "x": 1,
      "y": 32,
      "z": 2,
      "name": "Plant_Leaves_Birch",
      "support": 15
    },
    {
      "x": 1,
      "y": 33,
      "z": 2,
      "name": "Plant_Leaves_Birch",
      "support": 15
    },
    {
      "x": 1,
      "y": 34,
      "z": 2,
      "name": "Plant_Leaves_Birch",
      "support": 15
    },
    {
      "x": 1,
      "y": 4,
      "z": 3,
      "name": "Rock_Stone"
    },
    {
      "x": 1,
      "y": 5,
      "z": 3,
      "name": "Rock_Stone"
    },
    {
      "x": 1,
      "y": 6,
      "z": 3,
      "name": "Rock_Stone"
    },
    {
      "x": 1,
      "y": 7,
      "z": 3,
      "name": "Rock_Stone"
    },
    {
      "x": 1,
      "y": 17,
      "z": 3,
      "name": "Rock_Stone"
    },
    {
      "x": 1,
      "y": 18,
      "z": 3,
      "name": "Rock_Stone"
    },
    {
      "x": 1,
      "y": 19,
      "z": 3,
      "name": "Rock_Stone"
    },
    {
      "x": 1,
      "y": 20,
      "z": 3,
      "name": "Soil_Dirt"
    },
    {
      "x": 1,
      "y": 21,
      "z": 3,
      "name": "Soil_Dirt"
    },
    {
      "x": 1,
      "y": 22,
      "z": 3,
      "name": "Soil_Dirt"
    },
    {
      "x": 1,
      "y": 23,
      "z": 3,
      "name": "Soil_Grass"
    },
    {
      "x": 1,
      "y": 27,
      "z": 3,
      "name": "Plant_Leaves_Birch",
      "support": 15
    },
    {
      "x": 1,
      "y": 28,
      "z": 3,
      "name": "Plant_Leaves_Birch",
      "support": 15
    },
    {
      "x": 1,
      "y": 31,
      "z": 3,
      "name": "Plant_Leaves_Birch",
      "support": 15
    },
    {
      "x": 1,
      "y": 32,
      "z": 3,
      "name": "Plant_Leaves_Birch",
      "support": 15
    },
    {
      "x": 1,
      "y": 33,
      "z": 3,
      "name": "Plant_Leaves_Birch",
      "support": 15
    },
    {
      "x": 1,
      "y": 34,
      "z": 3,
      "name": "Plant_Leaves_Birch",
      "support": 15
    },
    {
      "x": 1,
      "y": 36,
      "z": 3,
      "name": "Plant_Leaves_Birch",
      "support": 15
    },
    {
      "x": 1,
      "y": 4,
      "z": 4,
      "name": "Rock_Stone"
    },
    {
      "x": 1,
      "y": 5,
      "z": 4,
      "name": "Rock_Stone"
    },
    {
      "x": 1,
      "y": 6,
      "z": 4,
      "name": "Rock_Stone"
    },
    {
      "x": 1,
      "y": 7,
      "z": 4,
      "name": "Rock_Stone"
    },
    {
      "x": 1,
      "y": 18,
      "z": 4,
      "name": "Rock_Stone"
    },
    {
      "x": 1,
      "y": 19,
      "z": 4,
      "name": "Rock_Stone"
    },
    {
      "x": 1,
      "y": 20,
      "z": 4,
      "name": "Soil_Dirt"
    },
    {
      "x": 1,
      "y": 21,
      "z": 4,
      "name": "Soil_Dirt"
    },
    {
      "x": 1,
      "y": 22,
      "z": 4,
      "name": "Soil_Grass"
    },
    {
      "x": 1,
      "y": 23,
      "z": 4,
      "name": "Plant_Grass_Sharp"
    },
    {
      "x": 1,
      "y": 27,
      "z": 4,
      "name": "Wood_Birch_Branch_Long",
      "support": 15,
      "rotation": 5
    },
    {
      "x": 1,
      "y": 36,
      "z": 4,
      "name": "Plant_Leaves_Birch",
      "support": 15
    },
    {
      "x": 1,
      "y": 4,
      "z": 5,
      "name": "Rock_Stone"
    },
    {
      "x": 1,
      "y": 5,
      "z": 5,
      "name": "Rock_Stone"
    },
    {
      "x": 1,
      "y": 19,
      "z": 5,
      "name": "Rock_Stone"
    },
    {
      "x": 1,
      "y": 20,
      "z": 5,
      "name": "Soil_Dirt"
    },
    {
      "x": 1,
      "y": 21,
      "z": 5,
      "name": "Soil_Grass"
    },
    {
      "x": 1,
      "y": 31,
      "z": 5,
      "name": "Wood_Birch_Branch_Long",
      "support": 15,
      "rotation": 5
    },
    {
      "x": 1,
      "y": 35,
      "z": 5,
      "name": "Plant_Leaves_Birch",
      "support": 15
    },
    {
      "x": 1,
      "y": 36,
      "z": 5,
      "name": "Plant_Leaves_Birch",
      "support": 15
    },
    {
      "x": 1,
      "y": 25,
      "z": 6,
      "name": "Plant_Leaves_Birch",
      "support": 15
    },
    {
      "x": 1,
      "y": 26,
      "z": 6,
      "name": "Plant_Leaves_Birch",
      "support": 15
    },
    {
      "x": 1,
      "y": 27,
      "z": 6,
      "name": "Plant_Leaves_Birch",
      "support": 15
    },
    {
      "x": 1,
      "y": 32,
      "z": 6,
      "name": "Plant_Leaves_Birch",
      "support": 15
    },
    {
      "x": 1,
      "y": 27,
      "z": 7,
      "name": "Plant_Leaves_Birch",
      "support": 15
    },
    {
      "x": 1,
      "y": 31,
      "z": 7,
      "name": "Plant_Leaves_Birch",
      "support": 15
    },
    {
      "x": 1,
      "y": 32,
      "z": 7,
      "name": "Plant_Leaves_Birch",
      "support": 15
    },
    {
      "x": 2,
      "y": 18,
      "z": -3,
      "name": "Rock_Stone"
    },
    {
      "x": 2,
      "y": 19,
      "z": -3,
      "name": "Rock_Stone"
    },
    {
      "x": 2,
      "y": 20,
      "z": -3,
      "name": "Soil_Dirt"
    },
    {
      "x": 2,
      "y": 21,
      "z": -3,
      "name": "Soil_Grass"
    },
    {
      "x": 2,
      "y": 18,
      "z": -2,
      "name": "Rock_Stone"
    },
    {
      "x": 2,
      "y": 19,
      "z": -2,
      "name": "Rock_Stone"
    },
    {
      "x": 2,
      "y": 20,
      "z": -2,
      "name": "Soil_Dirt"
    },
    {
      "x": 2,
      "y": 21,
      "z": -2,
      "name": "Soil_Dirt"
    },
    {
      "x": 2,
      "y": 22,
      "z": -2,
      "name": "Soil_Dirt"
    },
    {
      "x": 2,
      "y": 23,
      "z": -2,
      "name": "Soil_Grass"
    },
    {
      "x": 2,
      "y": 18,
      "z": -1,
      "name": "Rock_Stone"
    },
    {
      "x": 2,
      "y": 19,
      "z": -1,
      "name": "Rock_Stone"
    },
    {
      "x": 2,
      "y": 20,
      "z": -1,
      "name": "Soil_Dirt"
    },
    {
      "x": 2,
      "y": 21,
      "z": -1,
      "name": "Soil_Dirt"
    },
    {
      "x": 2,
      "y": 22,
      "z": -1,
      "name": "Soil_Dirt"
    },
    {
      "x": 2,
      "y": 23,
      "z": -1,
      "name": "Soil_Grass"
    },
    {
      "x": 2,
      "y": 17,
      "z": 0,
      "name": "Rock_Stone"
    },
    {
      "x": 2,
      "y": 18,
      "z": 0,
      "name": "Rock_Stone"
    },
    {
      "x": 2,
      "y": 19,
      "z": 0,
      "name": "Rock_Stone"
    },
    {
      "x": 2,
      "y": 20,
      "z": 0,
      "name": "Rock_Stone"
    },
    {
      "x": 2,
      "y": 21,
      "z": 0,
      "name": "Soil_Dirt"
    },
    {
      "x": 2,
      "y": 22,
      "z": 0,
      "name": "Soil_Dirt"
    },
    {
      "x": 2,
      "y": 23,
      "z": 0,
      "name": "Soil_Grass"
    },
    {
      "x": 2,
      "y": 24,
      "z": 0,
      "name": "Plant_Grass_Sharp"
    },
    {
      "x": 2,
      "y": 17,
      "z": 1,
      "name": "Rock_Stone"
    },
    {
      "x": 2,
      "y": 18,
      "z": 1,
      "name": "Rock_Stone"
    },
    {
      "x": 2,
      "y": 19,
      "z": 1,
      "name": "Rock_Stone"
    },
    {
      "x": 2,
      "y": 20,
      "z": 1,
      "name": "Rock_Stone"
    },
    {
      "x": 2,
      "y": 21,
      "z": 1,
      "name": "Soil_Dirt"
    },
    {
      "x": 2,
      "y": 22,
      "z": 1,
      "name": "Soil_Dirt"
    },
    {
      "x": 2,
      "y": 23,
      "z": 1,
      "name": "Soil_Grass"
    },
    {
      "x": 2,
      "y": 24,
      "z": 1,
      "name": "Plant_Flower_Common_Red2"
    },
    {
      "x": 2,
      "y": 30,
      "z": 1,
      "name": "Plant_Leaves_Beech",
      "support": 15
    },
    {
      "x": 2,
      "y": 17,
      "z": 2,
      "name": "Rock_Stone"
    },
    {
      "x": 2,
      "y": 18,
      "z": 2,
      "name": "Rock_Stone"
    },
    {
      "x": 2,
      "y": 19,
      "z": 2,
      "name": "Rock_Stone"
    },
    {
      "x": 2,
      "y": 20,
      "z": 2,
      "name": "Soil_Dirt"
    },
    {
      "x": 2,
      "y": 21,
      "z": 2,
      "name": "Soil_Dirt"
    },
    {
      "x": 2,
      "y": 22,
      "z": 2,
      "name": "Soil_Dirt"
    },
    {
      "x": 2,
      "y": 23,
      "z": 2,
      "name": "Soil_Grass"
    },
    {
      "x": 2,
      "y": 24,
      "z": 2,
      "name": "Plant_Grass_Sharp"
    },
    {
      "x": 2,
      "y": 27,
      "z": 2,
      "name": "Plant_Leaves_Birch",
      "support": 15
    },
    {
      "x": 2,
      "y": 30,
      "z": 2,
      "name": "Plant_Leaves_Birch",
      "support": 15
    },
    {
      "x": 2,
      "y": 31,
      "z": 2,
      "name": "Plant_Leaves_Birch",
      "support": 15
    },
    {
      "x": 2,
      "y": 32,
      "z": 2,
      "name": "Plant_Leaves_Birch",
      "support": 15
    },
    {
      "x": 2,
      "y": 4,
      "z": 3,
      "name": "Rock_Stone"
    },
    {
      "x": 2,
      "y": 5,
      "z": 3,
      "name": "Rock_Stone"
    },
    {
      "x": 2,
      "y": 6,
      "z": 3,
      "name": "Rock_Stone"
    },
    {
      "x": 2,
      "y": 17,
      "z": 3,
      "name": "Rock_Stone"
    },
    {
      "x": 2,
      "y": 18,
      "z": 3,
      "name": "Rock_Stone"
    },
    {
      "x": 2,
      "y": 19,
      "z": 3,
      "name": "Rock_Stone"
    },
    {
      "x": 2,
      "y": 20,
      "z": 3,
      "name": "Soil_Dirt"
    },
    {
      "x": 2,
      "y": 21,
      "z": 3,
      "name": "Soil_Dirt"
    },
    {
      "x": 2,
      "y": 22,
      "z": 3,
      "name": "Soil_Dirt"
    },
    {
      "x": 2,
      "y": 23,
      "z": 3,
      "name": "Soil_Grass"
    },
    {
      "x": 2,
      "y": 26,
      "z": 3,
      "name": "Plant_Leaves_Birch",
      "support": 15
    },
    {
      "x": 2,
      "y": 27,
      "z": 3,
      "name": "Plant_Leaves_Birch",
      "support": 15
    },
    {
      "x": 2,
      "y": 28,
      "z": 3,
      "name": "Plant_Leaves_Birch",
      "support": 15
    },
    {
      "x": 2,
      "y": 30,
      "z": 3,
      "name": "Plant_Leaves_Beech",
      "support": 15
    },
    {
      "x": 2,
      "y": 32,
      "z": 3,
      "name": "Plant_Leaves_Birch",
      "support": 15
    },
    {
      "x": 2,
      "y": 33,
      "z": 3,
      "name": "Plant_Leaves_Birch",
      "support": 15
    },
    {
      "x": 2,
      "y": 5,
      "z": 4,
      "name": "Rock_Stone"
    },
    {
      "x": 2,
      "y": 18,
      "z": 4,
      "name": "Rock_Stone"
    },
    {
      "x": 2,
      "y": 19,
      "z": 4,
      "name": "Soil_Dirt"
    },
    {
      "x": 2,
      "y": 20,
      "z": 4,
      "name": "Soil_Dirt"
    },
    {
      "x": 2,
      "y": 21,
      "z": 4,
      "name": "Soil_Dirt"
    },
    {
      "x": 2,
      "y": 22,
      "z": 4,
      "name": "Soil_Grass"
    },
    {
      "x": 2,
      "y": 23,
      "z": 4,
      "name": "Plant_Grass_Sharp"
    },
    {
      "x": 2,
      "y": 24,
      "z": 4,
      "name": "Plant_Leaves_Birch",
      "support": 15
    },
    {
      "x": 2,
      "y": 25,
      "z": 4,
      "name": "Plant_Leaves_Birch",
      "support": 15
    },
    {
      "x": 2,
      "y": 26,
      "z": 4,
      "name": "Plant_Leaves_Birch",
      "support": 15
    },
    {
      "x": 2,
      "y": 27,
      "z": 4,
      "name": "Plant_Leaves_Birch",
      "support": 15
    },
    {
      "x": 2,
      "y": 29,
      "z": 4,
      "name": "Plant_Leaves_Birch",
      "support": 15
    },
    {
      "x": 2,
      "y": 30,
      "z": 4,
      "name": "Plant_Leaves_Birch",
      "support": 15
    },
    {
      "x": 2,
      "y": 31,
      "z": 4,
      "name": "Plant_Leaves_Birch",
      "support": 15
    },
    {
      "x": 2,
      "y": 5,
      "z": 5,
      "name": "Rock_Stone"
    },
    {
      "x": 2,
      "y": 18,
      "z": 5,
      "name": "Rock_Stone"
    },
    {
      "x": 2,
      "y": 19,
      "z": 5,
      "name": "Soil_Dirt"
    },
    {
      "x": 2,
      "y": 20,
      "z": 5,
      "name": "Soil_Dirt"
    },
    {
      "x": 2,
      "y": 21,
      "z": 5,
      "name": "Soil_Dirt"
    },
    {
      "x": 2,
      "y": 22,
      "z": 5,
      "name": "Soil_Grass"
    },
    {
      "x": 2,
      "y": 25,
      "z": 5,
      "name": "Plant_Leaves_Birch",
      "support": 15
    },
    {
      "x": 2,
      "y": 26,
      "z": 5,
      "name": "Plant_Leaves_Birch",
      "support": 15
    },
    {
      "x": 2,
      "y": 27,
      "z": 5,
      "name": "Plant_Leaves_Birch",
      "support": 15
    },
    {
      "x": 2,
      "y": 29,
      "z": 5,
      "name": "Plant_Leaves_Birch",
      "support": 15
    },
    {
      "x": 2,
      "y": 30,
      "z": 5,
      "name": "Plant_Leaves_Birch",
      "support": 15
    },
    {
      "x": 2,
      "y": 31,
      "z": 5,
      "name": "Plant_Leaves_Birch",
      "support": 15
    },
    {
      "x": 2,
      "y": 32,
      "z": 5,
      "name": "Plant_Leaves_Birch",
      "support": 15
    },
    {
      "x": 2,
      "y": 33,
      "z": 5,
      "name": "Plant_Leaves_Birch",
      "support": 15
    },
    {
      "x": 2,
      "y": 20,
      "z": 6,
      "name": "Soil_Dirt"
    },
    {
      "x": 2,
      "y": 21,
      "z": 6,
      "name": "Soil_Grass"
    },
    {
      "x": 2,
      "y": 30,
      "z": 6,
      "name": "Plant_Leaves_Birch",
      "support": 15
    },
    {
      "x": 2,
      "y": 31,
      "z": 6,
      "name": "Plant_Leaves_Birch",
      "support": 15
    },
    {
      "x": 2,
      "y": 32,
      "z": 6,
      "name": "Plant_Leaves_Birch",
      "support": 15
    },
    {
      "x": 2,
      "y": 31,
      "z": 7,
      "name": "Plant_Leaves_Birch",
      "support": 15
    },
    {
      "x": 2,
      "y": 32,
      "z": 7,
      "name": "Plant_Leaves_Birch",
      "support": 15
    },
    {
      "x": 3,
      "y": 19,
      "z": -3,
      "name": "Rock_Stone"
    },
    {
      "x": 3,
      "y": 20,
      "z": -3,
      "name": "Soil_Dirt"
    },
    {
      "x": 3,
      "y": 21,
      "z": -3,
      "name": "Soil_Grass"
    },
    {
      "x": 3,
      "y": 18,
      "z": -2,
      "name": "Rock_Stone"
    },
    {
      "x": 3,
      "y": 19,
      "z": -2,
      "name": "Rock_Stone"
    },
    {
      "x": 3,
      "y": 20,
      "z": -2,
      "name": "Soil_Dirt"
    },
    {
      "x": 3,
      "y": 21,
      "z": -2,
      "name": "Soil_Dirt"
    },
    {
      "x": 3,
      "y": 22,
      "z": -2,
      "name": "Soil_Grass"
    },
    {
      "x": 3,
      "y": 18,
      "z": -1,
      "name": "Rock_Stone"
    },
    {
      "x": 3,
      "y": 19,
      "z": -1,
      "name": "Rock_Stone"
    },
    {
      "x": 3,
      "y": 20,
      "z": -1,
      "name": "Soil_Dirt"
    },
    {
      "x": 3,
      "y": 21,
      "z": -1,
      "name": "Soil_Dirt"
    },
    {
      "x": 3,
      "y": 22,
      "z": -1,
      "name": "Soil_Dirt"
    },
    {
      "x": 3,
      "y": 23,
      "z": -1,
      "name": "Soil_Grass"
    },
    {
      "x": 3,
      "y": 17,
      "z": 0,
      "name": "Rock_Stone"
    },
    {
      "x": 3,
      "y": 18,
      "z": 0,
      "name": "Rock_Stone"
    },
    {
      "x": 3,
      "y": 19,
      "z": 0,
      "name": "Rock_Stone"
    },
    {
      "x": 3,
      "y": 20,
      "z": 0,
      "name": "Rock_Stone"
    },
    {
      "x": 3,
      "y": 21,
      "z": 0,
      "name": "Soil_Dirt"
    },
    {
      "x": 3,
      "y": 22,
      "z": 0,
      "name": "Soil_Dirt"
    },
    {
      "x": 3,
      "y": 23,
      "z": 0,
      "name": "Soil_Grass"
    },
    {
      "x": 3,
      "y": 24,
      "z": 0,
      "name": "Plant_Grass_Sharp"
    },
    {
      "x": 3,
      "y": 34,
      "z": 0,
      "name": "Plant_Leaves_Beech",
      "support": 15
    },
    {
      "x": 3,
      "y": 17,
      "z": 1,
      "name": "Rock_Stone"
    },
    {
      "x": 3,
      "y": 18,
      "z": 1,
      "name": "Rock_Stone"
    },
    {
      "x": 3,
      "y": 19,
      "z": 1,
      "name": "Rock_Stone"
    },
    {
      "x": 3,
      "y": 20,
      "z": 1,
      "name": "Rock_Stone"
    },
    {
      "x": 3,
      "y": 21,
      "z": 1,
      "name": "Soil_Dirt"
    },
    {
      "x": 3,
      "y": 22,
      "z": 1,
      "name": "Soil_Dirt"
    },
    {
      "x": 3,
      "y": 23,
      "z": 1,
      "name": "Soil_Grass"
    },
    {
      "x": 3,
      "y": 24,
      "z": 1,
      "name": "Plant_Grass_Sharp"
    },
    {
      "x": 3,
      "y": 31,
      "z": 1,
      "name": "Plant_Leaves_Beech",
      "support": 15
    },
    {
      "x": 3,
      "y": 32,
      "z": 1,
      "name": "Plant_Leaves_Beech",
      "support": 15
    },
    {
      "x": 3,
      "y": 34,
      "z": 1,
      "name": "Plant_Leaves_Beech",
      "support": 15
    },
    {
      "x": 3,
      "y": 35,
      "z": 1,
      "name": "Plant_Leaves_Beech",
      "support": 15
    },
    {
      "x": 3,
      "y": 17,
      "z": 2,
      "name": "Rock_Stone"
    },
    {
      "x": 3,
      "y": 18,
      "z": 2,
      "name": "Rock_Stone"
    },
    {
      "x": 3,
      "y": 19,
      "z": 2,
      "name": "Rock_Stone"
    },
    {
      "x": 3,
      "y": 20,
      "z": 2,
      "name": "Soil_Dirt"
    },
    {
      "x": 3,
      "y": 21,
      "z": 2,
      "name": "Soil_Dirt"
    },
    {
      "x": 3,
      "y": 22,
      "z": 2,
      "name": "Soil_Dirt"
    },
    {
      "x": 3,
      "y": 23,
      "z": 2,
      "name": "Soil_Grass"
    },
    {
      "x": 3,
      "y": 30,
      "z": 2,
      "name": "Plant_Leaves_Beech",
      "support": 15
    },
    {
      "x": 3,
      "y": 31,
      "z": 2,
      "name": "Wood_Beech_Branch_Corner",
      "support": 15,
      "rotation": 3
    },
    {
      "x": 3,
      "y": 32,
      "z": 2,
      "name": "Plant_Leaves_Beech",
      "support": 15
    },
    {
      "x": 3,
      "y": 17,
      "z": 3,
      "name": "Rock_Stone"
    },
    {
      "x": 3,
      "y": 18,
      "z": 3,
      "name": "Rock_Stone"
    },
    {
      "x": 3,
      "y": 19,
      "z": 3,
      "name": "Rock_Stone"
    },
    {
      "x": 3,
      "y": 20,
      "z": 3,
      "name": "Soil_Dirt"
    },
    {
      "x": 3,
      "y": 21,
      "z": 3,
      "name": "Soil_Dirt"
    },
    {
      "x": 3,
      "y": 22,
      "z": 3,
      "name": "Soil_Dirt"
    },
    {
      "x": 3,
      "y": 23,
      "z": 3,
      "name": "Soil_Grass"
    },
    {
      "x": 3,
      "y": 27,
      "z": 3,
      "name": "Plant_Leaves_Birch",
      "support": 15
    },
    {
      "x": 3,
      "y": 31,
      "z": 3,
      "name": "Plant_Leaves_Beech",
      "support": 15
    },
    {
      "x": 3,
      "y": 32,
      "z": 3,
      "name": "Plant_Leaves_Beech",
      "support": 15
    },
    {
      "x": 3,
      "y": 17,
      "z": 4,
      "name": "Rock_Stone"
    },
    {
      "x": 3,
      "y": 18,
      "z": 4,
      "name": "Rock_Stone"
    },
    {
      "x": 3,
      "y": 19,
      "z": 4,
      "name": "Rock_Stone"
    },
    {
      "x": 3,
      "y": 20,
      "z": 4,
      "name": "Soil_Dirt"
    },
    {
      "x": 3,
      "y": 21,
      "z": 4,
      "name": "Soil_Dirt"
    },
    {
      "x": 3,
      "y": 22,
      "z": 4,
      "name": "Soil_Grass"
    },
    {
      "x": 3,
      "y": 23,
      "z": 4,
      "name": "Plant_Grass_Sharp_Tall"
    },
    {
      "x": 3,
      "y": 24,
      "z": 4,
      "name": "Plant_Grass_Sharp_Tall",
      "filler": 1024
    },
    {
      "x": 3,
      "y": 26,
      "z": 4,
      "name": "Plant_Leaves_Birch",
      "support": 15
    },
    {
      "x": 3,
      "y": 18,
      "z": 5,
      "name": "Rock_Stone"
    },
    {
      "x": 3,
      "y": 19,
      "z": 5,
      "name": "Rock_Stone"
    },
    {
      "x": 3,
      "y": 20,
      "z": 5,
      "name": "Soil_Dirt"
    },
    {
      "x": 3,
      "y": 21,
      "z": 5,
      "name": "Soil_Dirt"
    },
    {
      "x": 3,
      "y": 22,
      "z": 5,
      "name": "Soil_Grass"
    },
    {
      "x": 3,
      "y": 23,
      "z": 5,
      "name": "Plant_Grass_Sharp"
    },
    {
      "x": 3,
      "y": 30,
      "z": 5,
      "name": "Plant_Leaves_Birch",
      "support": 15
    },
    {
      "x": 3,
      "y": 31,
      "z": 5,
      "name": "Plant_Leaves_Birch",
      "support": 15
    },
    {
      "x": 3,
      "y": 20,
      "z": 6,
      "name": "Soil_Dirt"
    },
    {
      "x": 3,
      "y": 21,
      "z": 6,
      "name": "Soil_Grass"
    },
    {
      "x": 3,
      "y": 32,
      "z": 6,
      "name": "Plant_Leaves_Birch",
      "support": 15
    },
    {
      "x": 4,
      "y": 19,
      "z": -3,
      "name": "Rock_Stone"
    },
    {
      "x": 4,
      "y": 20,
      "z": -3,
      "name": "Soil_Dirt"
    },
    {
      "x": 4,
      "y": 21,
      "z": -3,
      "name": "Soil_Grass"
    },
    {
      "x": 4,
      "y": 18,
      "z": -2,
      "name": "Rock_Stone"
    },
    {
      "x": 4,
      "y": 19,
      "z": -2,
      "name": "Rock_Stone"
    },
    {
      "x": 4,
      "y": 20,
      "z": -2,
      "name": "Soil_Dirt"
    },
    {
      "x": 4,
      "y": 21,
      "z": -2,
      "name": "Soil_Dirt"
    },
    {
      "x": 4,
      "y": 22,
      "z": -2,
      "name": "Soil_Grass"
    },
    {
      "x": 4,
      "y": 30,
      "z": -2,
      "name": "Plant_Leaves_Beech",
      "support": 15
    },
    {
      "x": 4,
      "y": 18,
      "z": -1,
      "name": "Rock_Stone"
    },
    {
      "x": 4,
      "y": 19,
      "z": -1,
      "name": "Rock_Stone"
    },
    {
      "x": 4,
      "y": 20,
      "z": -1,
      "name": "Soil_Dirt"
    },
    {
      "x": 4,
      "y": 21,
      "z": -1,
      "name": "Soil_Dirt"
    },
    {
      "x": 4,
      "y": 22,
      "z": -1,
      "name": "Soil_Dirt"
    },
    {
      "x": 4,
      "y": 23,
      "z": -1,
      "name": "Soil_Grass"
    },
    {
      "x": 4,
      "y": 34,
      "z": -1,
      "name": "Plant_Leaves_Beech",
      "support": 15
    },
    {
      "x": 4,
      "y": 17,
      "z": 0,
      "name": "Rock_Stone"
    },
    {
      "x": 4,
      "y": 18,
      "z": 0,
      "name": "Rock_Stone"
    },
    {
      "x": 4,
      "y": 19,
      "z": 0,
      "name": "Rock_Stone"
    },
    {
      "x": 4,
      "y": 20,
      "z": 0,
      "name": "Soil_Dirt"
    },
    {
      "x": 4,
      "y": 21,
      "z": 0,
      "name": "Soil_Dirt"
    },
    {
      "x": 4,
      "y": 22,
      "z": 0,
      "name": "Soil_Dirt"
    },
    {
      "x": 4,
      "y": 23,
      "z": 0,
      "name": "Soil_Grass"
    },
    {
      "x": 4,
      "y": 31,
      "z": 0,
      "name": "Plant_Leaves_Beech",
      "support": 15
    },
    {
      "x": 4,
      "y": 32,
      "z": 0,
      "name": "Plant_Leaves_Beech",
      "support": 15
    },
    {
      "x": 4,
      "y": 34,
      "z": 0,
      "name": "Plant_Leaves_Beech",
      "support": 15
    },
    {
      "x": 4,
      "y": 35,
      "z": 0,
      "name": "Plant_Leaves_Beech",
      "support": 15
    },
    {
      "x": 4,
      "y": 17,
      "z": 1,
      "name": "Rock_Stone"
    },
    {
      "x": 4,
      "y": 18,
      "z": 1,
      "name": "Rock_Stone"
    },
    {
      "x": 4,
      "y": 19,
      "z": 1,
      "name": "Rock_Stone"
    },
    {
      "x": 4,
      "y": 20,
      "z": 1,
      "name": "Rock_Stone"
    },
    {
      "x": 4,
      "y": 21,
      "z": 1,
      "name": "Soil_Dirt"
    },
    {
      "x": 4,
      "y": 22,
      "z": 1,
      "name": "Soil_Dirt"
    },
    {
      "x": 4,
      "y": 23,
      "z": 1,
      "name": "Soil_Grass"
    },
    {
      "x": 4,
      "y": 31,
      "z": 1,
      "name": "Plant_Leaves_Beech",
      "support": 15
    },
    {
      "x": 4,
      "y": 32,
      "z": 1,
      "name": "Plant_Leaves_Beech",
      "support": 15
    },
    {
      "x": 4,
      "y": 35,
      "z": 1,
      "name": "Wood_Beech_Branch_Long",
      "support": 15,
      "rotation": 5
    },
    {
      "x": 4,
      "y": 36,
      "z": 1,
      "name": "Plant_Leaves_Beech",
      "support": 15
    },
    {
      "x": 4,
      "y": 17,
      "z": 2,
      "name": "Rock_Stone"
    },
    {
      "x": 4,
      "y": 18,
      "z": 2,
      "name": "Rock_Stone"
    },
    {
      "x": 4,
      "y": 19,
      "z": 2,
      "name": "Rock_Stone"
    },
    {
      "x": 4,
      "y": 20,
      "z": 2,
      "name": "Rock_Stone"
    },
    {
      "x": 4,
      "y": 21,
      "z": 2,
      "name": "Soil_Dirt"
    },
    {
      "x": 4,
      "y": 22,
      "z": 2,
      "name": "Soil_Dirt"
    },
    {
      "x": 4,
      "y": 23,
      "z": 2,
      "name": "Soil_Grass"
    },
    {
      "x": 4,
      "y": 31,
      "z": 2,
      "name": "Wood_Beech_Trunk_Full",
      "support": 15
    },
    {
      "x": 4,
      "y": 32,
      "z": 2,
      "name": "Plant_Leaves_Beech",
      "support": 15
    },
    {
      "x": 4,
      "y": 35,
      "z": 2,
      "name": "Plant_Leaves_Beech",
      "support": 15
    },
    {
      "x": 4,
      "y": 17,
      "z": 3,
      "name": "Rock_Stone"
    },
    {
      "x": 4,
      "y": 18,
      "z": 3,
      "name": "Rock_Stone"
    },
    {
      "x": 4,
      "y": 19,
      "z": 3,
      "name": "Rock_Stone"
    },
    {
      "x": 4,
      "y": 20,
      "z": 3,
      "name": "Soil_Dirt"
    },
    {
      "x": 4,
      "y": 21,
      "z": 3,
      "name": "Soil_Dirt"
    },
    {
      "x": 4,
      "y": 22,
      "z": 3,
      "name": "Soil_Dirt"
    },
    {
      "x": 4,
      "y": 23,
      "z": 3,
      "name": "Soil_Grass"
    },
    {
      "x": 4,
      "y": 32,
      "z": 3,
      "name": "Plant_Leaves_Beech",
      "support": 15
    },
    {
      "x": 4,
      "y": 34,
      "z": 3,
      "name": "Plant_Leaves_Beech",
      "support": 15
    },
    {
      "x": 4,
      "y": 35,
      "z": 3,
      "name": "Plant_Leaves_Beech",
      "support": 15
    },
    {
      "x": 4,
      "y": 17,
      "z": 4,
      "name": "Rock_Stone"
    },
    {
      "x": 4,
      "y": 18,
      "z": 4,
      "name": "Rock_Stone"
    },
    {
      "x": 4,
      "y": 19,
      "z": 4,
      "name": "Rock_Stone"
    },
    {
      "x": 4,
      "y": 20,
      "z": 4,
      "name": "Soil_Dirt"
    },
    {
      "x": 4,
      "y": 21,
      "z": 4,
      "name": "Soil_Dirt"
    },
    {
      "x": 4,
      "y": 22,
      "z": 4,
      "name": "Soil_Grass"
    },
    {
      "x": 4,
      "y": 23,
      "z": 4,
      "name": "Plant_Grass_Sharp"
    },
    {
      "x": 4,
      "y": 31,
      "z": 4,
      "name": "Plant_Leaves_Beech",
      "support": 15
    },
    {
      "x": 4,
      "y": 34,
      "z": 4,
      "name": "Plant_Leaves_Beech",
      "support": 15
    },
    {
      "x": 4,
      "y": 17,
      "z": 5,
      "name": "Rock_Stone"
    },
    {
      "x": 4,
      "y": 18,
      "z": 5,
      "name": "Rock_Stone"
    },
    {
      "x": 4,
      "y": 19,
      "z": 5,
      "name": "Rock_Stone"
    },
    {
      "x": 4,
      "y": 20,
      "z": 5,
      "name": "Soil_Dirt"
    },
    {
      "x": 4,
      "y": 21,
      "z": 5,
      "name": "Soil_Dirt"
    },
    {
      "x": 4,
      "y": 22,
      "z": 5,
      "name": "Soil_Grass"
    },
    {
      "x": 4,
      "y": 19,
      "z": 6,
      "name": "Rock_Stone"
    },
    {
      "x": 4,
      "y": 20,
      "z": 6,
      "name": "Soil_Dirt"
    },
    {
      "x": 4,
      "y": 21,
      "z": 6,
      "name": "Soil_Grass"
    },
    {
      "x": 5,
      "y": 19,
      "z": -3,
      "name": "Rock_Stone"
    },
    {
      "x": 5,
      "y": 20,
      "z": -3,
      "name": "Soil_Dirt"
    },
    {
      "x": 5,
      "y": 30,
      "z": -3,
      "name": "Plant_Leaves_Beech",
      "support": 15
    },
    {
      "x": 5,
      "y": 18,
      "z": -2,
      "name": "Rock_Stone"
    },
    {
      "x": 5,
      "y": 19,
      "z": -2,
      "name": "Soil_Dirt"
    },
    {
      "x": 5,
      "y": 20,
      "z": -2,
      "name": "Soil_Dirt"
    },
    {
      "x": 5,
      "y": 21,
      "z": -2,
      "name": "Soil_Dirt"
    },
    {
      "x": 5,
      "y": 22,
      "z": -2,
      "name": "Soil_Grass"
    },
    {
      "x": 5,
      "y": 30,
      "z": -2,
      "name": "Plant_Leaves_Beech",
      "support": 15
    },
    {
      "x": 5,
      "y": 31,
      "z": -2,
      "name": "Plant_Leaves_Beech",
      "support": 15
    },
    {
      "x": 5,
      "y": 18,
      "z": -1,
      "name": "Rock_Stone"
    },
    {
      "x": 5,
      "y": 19,
      "z": -1,
      "name": "Rock_Stone"
    },
    {
      "x": 5,
      "y": 20,
      "z": -1,
      "name": "Soil_Dirt"
    },
    {
      "x": 5,
      "y": 21,
      "z": -1,
      "name": "Soil_Dirt"
    },
    {
      "x": 5,
      "y": 22,
      "z": -1,
      "name": "Soil_Grass"
    },
    {
      "x": 5,
      "y": 30,
      "z": -1,
      "name": "Plant_Leaves_Beech",
      "support": 15
    },
    {
      "x": 5,
      "y": 32,
      "z": -1,
      "name": "Plant_Leaves_Beech",
      "support": 15
    },
    {
      "x": 5,
      "y": 35,
      "z": -1,
      "name": "Plant_Leaves_Beech",
      "support": 15
    },
    {
      "x": 5,
      "y": 36,
      "z": -1,
      "name": "Plant_Leaves_Beech",
      "support": 15
    },
    {
      "x": 5,
      "y": 17,
      "z": 0,
      "name": "Rock_Stone"
    },
    {
      "x": 5,
      "y": 18,
      "z": 0,
      "name": "Rock_Stone"
    },
    {
      "x": 5,
      "y": 19,
      "z": 0,
      "name": "Rock_Stone"
    },
    {
      "x": 5,
      "y": 20,
      "z": 0,
      "name": "Soil_Dirt"
    },
    {
      "x": 5,
      "y": 21,
      "z": 0,
      "name": "Soil_Dirt"
    },
    {
      "x": 5,
      "y": 22,
      "z": 0,
      "name": "Soil_Dirt"
    },
    {
      "x": 5,
      "y": 23,
      "z": 0,
      "name": "Soil_Grass"
    },
    {
      "x": 5,
      "y": 35,
      "z": 0,
      "name": "Plant_Leaves_Beech",
      "support": 15
    },
    {
      "x": 5,
      "y": 37,
      "z": 0,
      "name": "Plant_Leaves_Beech",
      "support": 15
    },
    {
      "x": 5,
      "y": 38,
      "z": 0,
      "name": "Plant_Leaves_Beech",
      "support": 15
    },
    {
      "x": 5,
      "y": 17,
      "z": 1,
      "name": "Rock_Stone"
    },
    {
      "x": 5,
      "y": 18,
      "z": 1,
      "name": "Rock_Stone"
    },
    {
      "x": 5,
      "y": 19,
      "z": 1,
      "name": "Rock_Stone"
    },
    {
      "x": 5,
      "y": 20,
      "z": 1,
      "name": "Soil_Dirt"
    },
    {
      "x": 5,
      "y": 21,
      "z": 1,
      "name": "Soil_Dirt"
    },
    {
      "x": 5,
      "y": 22,
      "z": 1,
      "name": "Soil_Dirt"
    },
    {
      "x": 5,
      "y": 23,
      "z": 1,
      "name": "Soil_Grass"
    },
    {
      "x": 5,
      "y": 31,
      "z": 1,
      "name": "Wood_Beech_Trunk_Full",
      "support": 15
    },
    {
      "x": 5,
      "y": 35,
      "z": 1,
      "name": "Wood_Beech_Trunk_Full",
      "support": 15
    },
    {
      "x": 5,
      "y": 17,
      "z": 2,
      "name": "Rock_Stone"
    },
    {
      "x": 5,
      "y": 18,
      "z": 2,
      "name": "Rock_Stone"
    },
    {
      "x": 5,
      "y": 19,
      "z": 2,
      "name": "Rock_Stone"
    },
    {
      "x": 5,
      "y": 20,
      "z": 2,
      "name": "Soil_Dirt"
    },
    {
      "x": 5,
      "y": 21,
      "z": 2,
      "name": "Soil_Dirt"
    },
    {
      "x": 5,
      "y": 22,
      "z": 2,
      "name": "Soil_Dirt"
    },
    {
      "x": 5,
      "y": 23,
      "z": 2,
      "name": "Soil_Grass"
    },
    {
      "x": 5,
      "y": 31,
      "z": 2,
      "name": "Wood_Beech_Trunk_Full",
      "support": 15
    },
    {
      "x": 5,
      "y": 35,
      "z": 2,
      "name": "Wood_Beech_Trunk_Full",
      "support": 15
    },
    {
      "x": 5,
      "y": 36,
      "z": 2,
      "name": "Plant_Leaves_Beech",
      "support": 15
    },
    {
      "x": 5,
      "y": 17,
      "z": 3,
      "name": "Rock_Stone"
    },
    {
      "x": 5,
      "y": 18,
      "z": 3,
      "name": "Rock_Stone"
    },
    {
      "x": 5,
      "y": 19,
      "z": 3,
      "name": "Rock_Stone"
    },
    {
      "x": 5,
      "y": 20,
      "z": 3,
      "name": "Soil_Dirt"
    },
    {
      "x": 5,
      "y": 21,
      "z": 3,
      "name": "Soil_Dirt"
    },
    {
      "x": 5,
      "y": 22,
      "z": 3,
      "name": "Soil_Grass"
    },
    {
      "x": 5,
      "y": 34,
      "z": 3,
      "name": "Plant_Leaves_Beech",
      "support": 15
    },
    {
      "x": 5,
      "y": 35,
      "z": 3,
      "name": "Plant_Leaves_Beech",
      "support": 15
    },
    {
      "x": 5,
      "y": 17,
      "z": 4,
      "name": "Rock_Stone"
    },
    {
      "x": 5,
      "y": 18,
      "z": 4,
      "name": "Rock_Stone"
    },
    {
      "x": 5,
      "y": 19,
      "z": 4,
      "name": "Rock_Stone"
    },
    {
      "x": 5,
      "y": 20,
      "z": 4,
      "name": "Soil_Dirt"
    },
    {
      "x": 5,
      "y": 21,
      "z": 4,
      "name": "Soil_Dirt"
    },
    {
      "x": 5,
      "y": 22,
      "z": 4,
      "name": "Soil_Grass"
    },
    {
      "x": 5,
      "y": 23,
      "z": 4,
      "name": "Plant_Flower_Common_Yellow2"
    },
    {
      "x": 5,
      "y": 31,
      "z": 4,
      "name": "Plant_Leaves_Beech",
      "support": 15
    },
    {
      "x": 5,
      "y": 32,
      "z": 4,
      "name": "Plant_Leaves_Beech",
      "support": 15
    },
    {
      "x": 5,
      "y": 34,
      "z": 4,
      "name": "Plant_Leaves_Beech",
      "support": 15
    },
    {
      "x": 5,
      "y": 17,
      "z": 5,
      "name": "Rock_Stone"
    },
    {
      "x": 5,
      "y": 18,
      "z": 5,
      "name": "Rock_Stone"
    },
    {
      "x": 5,
      "y": 19,
      "z": 5,
      "name": "Rock_Stone"
    },
    {
      "x": 5,
      "y": 20,
      "z": 5,
      "name": "Rock_Stone"
    },
    {
      "x": 5,
      "y": 21,
      "z": 5,
      "name": "Soil_Grass"
    },
    {
      "x": 5,
      "y": 31,
      "z": 5,
      "name": "Plant_Leaves_Beech",
      "support": 15
    },
    {
      "x": 5,
      "y": 32,
      "z": 5,
      "name": "Plant_Leaves_Beech",
      "support": 15
    },
    {
      "x": 5,
      "y": 19,
      "z": 6,
      "name": "Rock_Stone"
    },
    {
      "x": 5,
      "y": 20,
      "z": 6,
      "name": "Soil_Grass"
    },
    {
      "x": 5,
      "y": 31,
      "z": 6,
      "name": "Plant_Leaves_Beech",
      "support": 15
    },
    {
      "x": 6,
      "y": 19,
      "z": -3,
      "name": "Rock_Stone"
    },
    {
      "x": 6,
      "y": 20,
      "z": -3,
      "name": "Soil_Grass"
    },
    {
      "x": 6,
      "y": 30,
      "z": -3,
      "name": "Plant_Leaves_Beech",
      "support": 15
    },
    {
      "x": 6,
      "y": 31,
      "z": -3,
      "name": "Plant_Leaves_Beech",
      "support": 15
    },
    {
      "x": 6,
      "y": 5,
