{
  "version": 8,
  "blockIdVersion": 8,
  "anchorX": -1,
  "anchorY": 8,
  "anchorZ": -9,
  "blocks": [
    {
      "x": -19,
      "y": 0,
      "z": -10,
      "name": "Rock_Stone"
    },
    {
      "x": -19,
      "y": 1,
      "z": -10,
      "name": "Rock_Stone"
    },
    {
      "x": -19,
      "y": 2,
      "z": -10,
      "name": "Rock_Stone"
    },
    {
      "x": -19,
      "y": 3,
      "z": -10,
      "name": "Rock_Stone"
    },
    {
      "x": -19,
      "y": 4,
      "z": -10,
      "name": "Rock_Stone"
    },
    {
      "x": -19,
      "y": 5,
      "z": -10,
      "name": "Rock_Stone"
    },
    {
      "x": -19,
      "y": 6,
      "z": -10,
      "name": "Rock_Stone"
    },
    {
      "x": -19,
      "y": 7,
      "z": -10,
      "name": "Rock_Stone"
    },
    {
      "x": -19,
      "y": 0,
      "z": -9,
      "name": "Rock_Stone"
    },
    {
      "x": -19,
      "y": 1,
      "z": -9,
      "name": "Rock_Stone"
    },
    {
      "x": -19,
      "y": 2,
      "z": -9,
      "name": "Rock_Stone"
    },
    {
      "x": -19,
      "y": 3,
      "z": -9,
      "name": "Rock_Stone"
    },
    {
      "x": -19,
      "y": 4,
      "z": -9,
      "name": "Rock_Stone"
    },
    {
      "x": -19,
      "y": 5,
      "z": -9,
      "name": "Rock_Stone"
    },
    {
      "x": -19,
      "y": 6,
      "z": -9,
      "name": "Rock_Stone"
    },
    {
      "x": -19,
      "y": 7,
      "z": -9,
      "name": "Rock_Stone"
    },
    {
      "x": -19,
      "y": 8,
      "z": -9,
      "name": "Rock_Stone"
    },
    {
      "x": -19,
      "y": 0,
      "z": -8,
      "name": "Rock_Stone"
    },
    {
      "x": -19,
      "y": 1,
      "z": -8,
      "name": "Rock_Stone"
    },
    {
      "x": -19,
      "y": 2,
      "z": -8,
      "name": "Rock_Stone"
    },
    {
      "x": -19,
      "y": 3,
      "z": -8,
      "name": "Rock_Stone"
    },
    {
      "x": -19,
      "y": 4,
      "z": -8,
      "name": "Rock_Stone"
    },
    {
      "x": -19,
      "y": 5,
      "z": -8,
      "name": "Rock_Stone"
    },
    {
      "x": -19,
      "y": 6,
      "z": -8,
      "name": "Rock_Stone"
    },
    {
      "x": -19,
      "y": 7,
      "z": -8,
      "name": "Rock_Stone"
    },
    {
      "x": -19,
      "y": 8,
      "z": -8,
      "name": "Rock_Stone"
    },
    {
      "x": -19,
      "y": 9,
      "z": -8,
      "name": "Rock_Stone"
    },
    {
      "x": -19,
      "y": 10,
      "z": -8,
      "name": "Rock_Stone"
    },
    {
      "x": -19,
      "y": 11,
      "z": -8,
      "name": "Rock_Stone"
    },
    {
      "x": -19,
      "y": 12,
      "z": -8,
      "name": "Rock_Stone"
    },
    {
      "x": -19,
      "y": 13,
      "z": -8,
      "name": "Rock_Stone"
    },
    {
      "x": -19,
      "y": 0,
      "z": -7,
      "name": "Rock_Stone"
    },
    {
      "x": -19,
      "y": 1,
      "z": -7,
      "name": "Rock_Stone"
    },
    {
      "x": -19,
      "y": 2,
      "z": -7,
      "name": "Rock_Stone"
    },
    {
      "x": -19,
      "y": 3,
      "z": -7,
      "name": "Rock_Stone"
    },
    {
      "x": -19,
      "y": 4,
      "z": -7,
      "name": "Rock_Stone"
    },
    {
      "x": -19,
      "y": 5,
      "z": -7,
      "name": "Rock_Stone"
    },
    {
      "x": -19,
      "y": 6,
      "z": -7,
      "name": "Rock_Stone"
    },
    {
      "x": -19,
      "y": 7,
      "z": -7,
      "name": "Rock_Stone"
    },
    {
      "x": -19,
      "y": 8,
      "z": -7,
      "name": "Rock_Stone"
    },
    {
      "x": -19,
      "y": 9,
      "z": -7,
      "name": "Rock_Stone"
    },
    {
      "x": -19,
      "y": 10,
      "z": -7,
      "name": "Rock_Stone"
    },
    {
      "x": -19,
      "y": 11,
      "z": -7,
      "name": "Rock_Stone"
    },
    {
      "x": -19,
      "y": 12,
      "z": -7,
      "name": "Rock_Stone"
    },
    {
      "x": -19,
      "y": 13,
      "z": -7,
      "name": "Rock_Stone"
    },
    {
      "x": -19,
      "y": 0,
      "z": -6,
      "name": "Rock_Stone"
    },
    {
      "x": -19,
      "y": 1,
      "z": -6,
      "name": "Rock_Stone"
    },
    {
      "x": -19,
      "y": 2,
      "z": -6,
      "name": "Rock_Stone"
    },
    {
      "x": -19,
      "y": 3,
      "z": -6,
      "name": "Rock_Stone"
    },
    {
      "x": -19,
      "y": 4,
      "z": -6,
      "name": "Rock_Stone"
    },
    {
      "x": -19,
      "y": 5,
      "z": -6,
      "name": "Rock_Stone"
    },
    {
      "x": -19,
      "y": 6,
      "z": -6,
      "name": "Rock_Stone"
    },
    {
      "x": -19,
      "y": 7,
      "z": -6,
      "name": "Rock_Stone"
    },
    {
      "x": -19,
      "y": 8,
      "z": -6,
      "name": "Rock_Stone"
    },
    {
      "x": -19,
      "y": 9,
      "z": -6,
      "name": "Rock_Stone"
    },
    {
      "x": -19,
      "y": 10,
      "z": -6,
      "name": "Rock_Stone"
    },
    {
      "x": -19,
      "y": 11,
      "z": -6,
      "name": "Rock_Stone"
    },
    {
      "x": -19,
      "y": 0,
      "z": -5,
      "name": "Rock_Stone"
    },
    {
      "x": -19,
      "y": 1,
      "z": -5,
      "name": "Rock_Stone"
    },
    {
      "x": -19,
      "y": 2,
      "z": -5,
      "name": "Rock_Stone"
    },
    {
      "x": -19,
      "y": 3,
      "z": -5,
      "name": "Rock_Stone"
    },
    {
      "x": -19,
      "y": 4,
      "z": -5,
      "name": "Rock_Stone"
    },
    {
      "x": -19,
      "y": 5,
      "z": -5,
      "name": "Rock_Stone"
    },
    {
      "x": -19,
      "y": 6,
      "z": -5,
      "name": "Rock_Stone"
    },
    {
      "x": -19,
      "y": 7,
      "z": -5,
      "name": "Rock_Stone"
    },
    {
      "x": -19,
      "y": 8,
      "z": -5,
      "name": "Rock_Stone"
    },
    {
      "x": -19,
      "y": 9,
      "z": -5,
      "name": "Rock_Stone"
    },
    {
      "x": -19,
      "y": 10,
      "z": -5,
      "name": "Rock_Stone"
    },
    {
      "x": -19,
      "y": 0,
      "z": -4,
      "name": "Rock_Stone"
    },
    {
      "x": -19,
      "y": 1,
      "z": -4,
      "name": "Rock_Stone"
    },
    {
      "x": -19,
      "y": 2,
      "z": -4,
      "name": "Rock_Stone"
    },
    {
      "x": -19,
      "y": 3,
      "z": -4,
      "name": "Rock_Stone"
    },
    {
      "x": -19,
      "y": 4,
      "z": -4,
      "name": "Rock_Stone"
    },
    {
      "x": -19,
      "y": 5,
      "z": -4,
      "name": "Rock_Stone"
    },
    {
      "x": -19,
      "y": 6,
      "z": -4,
      "name": "Rock_Stone"
    },
    {
      "x": -19,
      "y": 7,
      "z": -4,
      "name": "Rock_Stone"
    },
    {
      "x": -19,
      "y": 8,
      "z": -4,
      "name": "Rock_Stone"
    },
    {
      "x": -19,
      "y": 9,
      "z": -4,
      "name": "Rock_Stone"
    },
    {
      "x": -18,
      "y": 0,
      "z": -12,
      "name": "Rock_Stone"
    },
    {
      "x": -18,
      "y": 1,
      "z": -12,
      "name": "Rock_Stone"
    },
    {
      "x": -18,
      "y": 2,
      "z": -12,
      "name": "Rock_Stone"
    },
    {
      "x": -18,
      "y": 3,
      "z": -12,
      "name": "Rock_Stone"
    },
    {
      "x": -18,
      "y": 4,
      "z": -12,
      "name": "Rock_Stone"
    },
    {
      "x": -18,
      "y": 5,
      "z": -12,
      "name": "Rock_Stone"
    },
    {
      "x": -18,
      "y": 6,
      "z": -12,
      "name": "Rock_Stone"
    },
    {
      "x": -18,
      "y": 7,
      "z": -12,
      "name": "Rock_Stone"
    },
    {
      "x": -18,
      "y": 0,
      "z": -11,
      "name": "Rock_Stone"
    },
    {
      "x": -18,
      "y": 1,
      "z": -11,
      "name": "Rock_Stone"
    },
    {
      "x": -18,
      "y": 2,
      "z": -11,
      "name": "Rock_Stone"
    },
    {
      "x": -18,
      "y": 3,
      "z": -11,
      "name": "Rock_Stone"
    },
    {
      "x": -18,
      "y": 4,
      "z": -11,
      "name": "Rock_Stone"
    },
    {
      "x": -18,
      "y": 5,
      "z": -11,
      "name": "Rock_Stone"
    },
    {
      "x": -18,
      "y": 6,
      "z": -11,
      "name": "Rock_Stone"
    },
    {
      "x": -18,
      "y": 7,
      "z": -11,
      "name": "Rock_Stone"
    },
    {
      "x": -18,
      "y": 8,
      "z": -11,
      "name": "Rock_Stone"
    },
    {
      "x": -18,
      "y": 9,
      "z": -11,
      "name": "Rock_Stone"
    },
    {
      "x": -18,
      "y": 0,
      "z": -10,
      "name": "Rock_Stone"
    },
    {
      "x": -18,
      "y": 1,
      "z": -10,
      "name": "Rock_Stone"
    },
    {
      "x": -18,
      "y": 2,
      "z": -10,
      "name": "Rock_Stone"
    },
    {
      "x": -18,
      "y": 3,
      "z": -10,
      "name": "Rock_Stone"
    },
    {
      "x": -18,
      "y": 4,
      "z": -10,
      "name": "Rock_Stone"
    },
    {
      "x": -18,
      "y": 5,
      "z": -10,
      "name": "Rock_Stone"
    },
    {
      "x": -18,
      "y": 6,
      "z": -10,
      "name": "Rock_Stone"
    },
    {
      "x": -18,
      "y": 7,
      "z": -10,
      "name": "Rock_Stone"
    },
    {
      "x": -18,
      "y": 8,
      "z": -10,
      "name": "Rock_Stone"
    },
    {
      "x": -18,
      "y": 9,
      "z": -10,
      "name": "Rock_Stone"
    },
    {
      "x": -18,
      "y": 10,
      "z": -10,
      "name": "Rock_Stone"
    },
    {
      "x": -18,
      "y": 11,
      "z": -10,
      "name": "Rock_Stone"
    },
    {
      "x": -18,
      "y": 12,
      "z": -10,
      "name": "Rock_Stone"
    },
    {
      "x": -18,
      "y": 13,
      "z": -10,
      "name": "Rock_Stone"
    },
    {
      "x": -18,
      "y": 0,
      "z": -9,
      "name": "Rock_Stone"
    },
    {
      "x": -18,
      "y": 1,
      "z": -9,
      "name": "Rock_Stone"
    },
    {
      "x": -18,
      "y": 2,
      "z": -9,
      "name": "Rock_Stone"
    },
    {
      "x": -18,
      "y": 3,
      "z": -9,
      "name": "Rock_Stone"
    },
    {
      "x": -18,
      "y": 4,
      "z": -9,
      "name": "Rock_Stone"
    },
    {
      "x": -18,
      "y": 5,
      "z": -9,
      "name": "Rock_Stone"
    },
    {
      "x": -18,
      "y": 6,
      "z": -9,
      "name": "Rock_Stone"
    },
    {
      "x": -18,
      "y": 7,
      "z": -9,
      "name": "Rock_Stone"
    },
    {
      "x": -18,
      "y": 8,
      "z": -9,
      "name": "Rock_Stone"
    },
    {
      "x": -18,
      "y": 9,
      "z": -9,
      "name": "Rock_Stone"
    },
    {
      "x": -18,
      "y": 10,
      "z": -9,
      "name": "Rock_Stone"
    },
    {
      "x": -18,
      "y": 11,
      "z": -9,
      "name": "Rock_Stone"
    },
    {
      "x": -18,
      "y": 12,
      "z": -9,
      "name": "Rock_Stone"
    },
    {
      "x": -18,
      "y": 13,
      "z": -9,
      "name": "Rock_Stone"
    },
    {
      "x": -18,
      "y": 14,
      "z": -9,
      "name": "Rock_Stone"
    },
    {
      "x": -18,
      "y": 15,
      "z": -9,
      "name": "Rock_Stone"
    },
    {
      "x": -18,
      "y": 16,
      "z": -9,
      "name": "Soil_Grass"
    },
    {
      "x": -18,
      "y": 0,
      "z": -8,
      "name": "Rock_Stone"
    },
    {
      "x": -18,
      "y": 1,
      "z": -8,
      "name": "Rock_Stone"
    },
    {
      "x": -18,
      "y": 2,
      "z": -8,
      "name": "Rock_Stone"
    },
    {
      "x": -18,
      "y": 3,
      "z": -8,
      "name": "Rock_Stone"
    },
    {
      "x": -18,
      "y": 4,
      "z": -8,
      "name": "Rock_Stone"
    },
    {
      "x": -18,
      "y": 5,
      "z": -8,
      "name": "Rock_Stone"
    },
    {
      "x": -18,
      "y": 6,
      "z": -8,
      "name": "Rock_Stone"
    },
    {
      "x": -18,
      "y": 7,
      "z": -8,
      "name": "Rock_Stone"
    },
    {
      "x": -18,
      "y": 8,
      "z": -8,
      "name": "Rock_Stone"
    },
    {
      "x": -18,
      "y": 9,
      "z": -8,
      "name": "Rock_Stone"
    },
    {
      "x": -18,
      "y": 10,
      "z": -8,
      "name": "Rock_Stone"
    },
    {
      "x": -18,
      "y": 11,
      "z": -8,
      "name": "Rock_Stone"
    },
    {
      "x": -18,
      "y": 12,
      "z": -8,
      "name": "Rock_Stone"
    },
    {
      "x": -18,
      "y": 13,
      "z": -8,
      "name": "Rock_Stone"
    },
    {
      "x": -18,
      "y": 14,
      "z": -8,
      "name": "Rock_Stone"
    },
    {
      "x": -18,
      "y": 15,
      "z": -8,
      "name": "Rock_Stone"
    },
    {
      "x": -18,
      "y": 16,
      "z": -8,
      "name": "Soil_Grass"
    },
    {
      "x": -18,
      "y": 0,
      "z": -7,
      "name": "Rock_Stone"
    },
    {
      "x": -18,
      "y": 1,
      "z": -7,
      "name": "Rock_Stone"
    },
    {
      "x": -18,
      "y": 2,
      "z": -7,
      "name": "Rock_Stone"
    },
    {
      "x": -18,
      "y": 3,
      "z": -7,
      "name": "Rock_Stone"
    },
    {
      "x": -18,
      "y": 4,
      "z": -7,
      "name": "Rock_Stone"
    },
    {
      "x": -18,
      "y": 5,
      "z": -7,
      "name": "Rock_Stone"
    },
    {
      "x": -18,
      "y": 6,
      "z": -7,
      "name": "Rock_Stone"
    },
    {
      "x": -18,
      "y": 7,
      "z": -7,
      "name": "Rock_Stone"
    },
    {
      "x": -18,
      "y": 8,
      "z": -7,
      "name": "Rock_Stone"
    },
    {
      "x": -18,
      "y": 9,
      "z": -7,
      "name": "Rock_Stone"
    },
    {
      "x": -18,
      "y": 10,
      "z": -7,
      "name": "Rock_Stone"
    },
    {
      "x": -18,
      "y": 11,
      "z": -7,
      "name": "Rock_Stone"
    },
    {
      "x": -18,
      "y": 12,
      "z": -7,
      "name": "Rock_Stone"
    },
    {
      "x": -18,
      "y": 13,
      "z": -7,
      "name": "Rock_Stone"
    },
    {
      "x": -18,
      "y": 14,
      "z": -7,
      "name": "Rock_Stone"
    },
    {
      "x": -18,
      "y": 15,
      "z": -7,
      "name": "Rock_Stone"
    },
    {
      "x": -18,
      "y": 16,
      "z": -7,
      "name": "Soil_Dirt"
    },
    {
      "x": -18,
      "y": 17,
      "z": -7,
      "name": "Soil_Grass"
    },
    {
      "x": -18,
      "y": 0,
      "z": -6,
      "name": "Rock_Stone"
    },
    {
      "x": -18,
      "y": 1,
      "z": -6,
      "name": "Rock_Stone"
    },
    {
      "x": -18,
      "y": 2,
      "z": -6,
      "name": "Rock_Stone"
    },
    {
      "x": -18,
      "y": 3,
      "z": -6,
      "name": "Rock_Stone"
    },
    {
      "x": -18,
      "y": 4,
      "z": -6,
      "name": "Rock_Stone"
    },
    {
      "x": -18,
      "y": 5,
      "z": -6,
      "name": "Rock_Stone"
    },
    {
      "x": -18,
      "y": 6,
      "z": -6,
      "name": "Rock_Stone"
    },
    {
      "x": -18,
      "y": 7,
      "z": -6,
      "name": "Rock_Stone"
    },
    {
      "x": -18,
      "y": 8,
      "z": -6,
      "name": "Rock_Stone"
    },
    {
      "x": -18,
      "y": 9,
      "z": -6,
      "name": "Rock_Stone"
    },
    {
      "x": -18,
      "y": 10,
      "z": -6,
      "name": "Rock_Stone"
    },
    {
      "x": -18,
      "y": 11,
      "z": -6,
      "name": "Rock_Stone"
    },
    {
      "x": -18,
      "y": 12,
      "z": -6,
      "name": "Rock_Stone"
    },
    {
      "x": -18,
      "y": 13,
      "z": -6,
      "name": "Rock_Stone"
    },
    {
      "x": -18,
      "y": 14,
      "z": -6,
      "name": "Rock_Stone"
    },
    {
      "x": -18,
      "y": 15,
      "z": -6,
      "name": "Rock_Stone"
    },
    {
      "x": -18,
      "y": 16,
      "z": -6,
      "name": "Soil_Dirt"
    },
    {
      "x": -18,
      "y": 17,
      "z": -6,
      "name": "Soil_Grass"
    },
    {
      "x": -18,
      "y": 0,
      "z": -5,
      "name": "Rock_Stone"
    },
    {
      "x": -18,
      "y": 1,
      "z": -5,
      "name": "Rock_Stone"
    },
    {
      "x": -18,
      "y": 2,
      "z": -5,
      "name": "Rock_Stone"
    },
    {
      "x": -18,
      "y": 3,
      "z": -5,
      "name": "Rock_Stone"
    },
    {
      "x": -18,
      "y": 4,
      "z": -5,
      "name": "Rock_Stone"
    },
    {
      "x": -18,
      "y": 5,
      "z": -5,
      "name": "Rock_Stone"
    },
    {
      "x": -18,
      "y": 6,
      "z": -5,
      "name": "Rock_Stone"
    },
    {
      "x": -18,
      "y": 7,
      "z": -5,
      "name": "Rock_Stone"
    },
    {
      "x": -18,
      "y": 8,
      "z": -5,
      "name": "Rock_Stone"
    },
    {
      "x": -18,
      "y": 9,
      "z": -5,
      "name": "Rock_Stone"
    },
    {
      "x": -18,
      "y": 10,
      "z": -5,
      "name": "Rock_Stone"
    },
    {
      "x": -18,
      "y": 11,
      "z": -5,
      "name": "Rock_Stone"
    },
    {
      "x": -18,
      "y": 12,
      "z": -5,
      "name": "Rock_Stone"
    },
    {
      "x": -18,
      "y": 13,
      "z": -5,
      "name": "Rock_Stone"
    },
    {
      "x": -18,
      "y": 14,
      "z": -5,
      "name": "Rock_Stone"
    },
    {
      "x": -18,
      "y": 15,
      "z": -5,
      "name": "Rock_Stone"
    },
    {
      "x": -18,
      "y": 16,
      "z": -5,
      "name": "Soil_Dirt"
    },
    {
      "x": -18,
      "y": 17,
      "z": -5,
      "name": "Soil_Grass"
    },
    {
      "x": -18,
      "y": 0,
      "z": -4,
      "name": "Rock_Stone"
    },
    {
      "x": -18,
      "y": 1,
      "z": -4,
      "name": "Rock_Stone"
    },
    {
      "x": -18,
      "y": 2,
      "z": -4,
      "name": "Rock_Stone"
    },
    {
      "x": -18,
      "y": 3,
      "z": -4,
      "name": "Rock_Stone"
    },
    {
      "x": -18,
      "y": 4,
      "z": -4,
      "name": "Rock_Stone"
    },
    {
      "x": -18,
      "y": 5,
      "z": -4,
      "name": "Rock_Stone"
    },
    {
      "x": -18,
      "y": 6,
      "z": -4,
      "name": "Rock_Stone"
    },
    {
      "x": -18,
      "y": 7,
      "z": -4,
      "name": "Rock_Stone"
    },
    {
      "x": -18,
      "y": 8,
      "z": -4,
      "name": "Rock_Stone"
    },
    {
      "x": -18,
      "y": 9,
      "z": -4,
      "name": "Rock_Stone"
    },
    {
      "x": -18,
      "y": 10,
      "z": -4,
      "name": "Rock_Stone"
    },
    {
      "x": -18,
      "y": 11,
      "z": -4,
      "name": "Rock_Stone"
    },
    {
      "x": -18,
      "y": 12,
      "z": -4,
      "name": "Rock_Stone"
    },
    {
      "x": -18,
      "y": 13,
      "z": -4,
      "name": "Rock_Stone"
    },
    {
      "x": -18,
      "y": 14,
      "z": -4,
      "name": "Rock_Stone"
    },
    {
      "x": -18,
      "y": 15,
      "z": -4,
      "name": "Rock_Stone"
    },
    {
      "x": -18,
      "y": 0,
      "z": -3,
      "name": "Rock_Stone"
    },
    {
      "x": -18,
      "y": 1,
      "z": -3,
      "name": "Rock_Stone"
    },
    {
      "x": -18,
      "y": 2,
      "z": -3,
      "name": "Rock_Stone"
    },
    {
      "x": -18,
      "y": 3,
      "z": -3,
      "name": "Rock_Stone"
    },
    {
      "x": -18,
      "y": 4,
      "z": -3,
      "name": "Rock_Stone"
    },
    {
      "x": -18,
      "y": 5,
      "z": -3,
      "name": "Rock_Stone"
    },
    {
      "x": -18,
      "y": 6,
      "z": -3,
      "name": "Rock_Stone"
    },
    {
      "x": -18,
      "y": 7,
      "z": -3,
      "name": "Rock_Stone"
    },
    {
      "x": -18,
      "y": 8,
      "z": -3,
      "name": "Rock_Stone"
    },
    {
      "x": -18,
      "y": 9,
      "z": -3,
      "name": "Rock_Stone"
    },
    {
      "x": -18,
      "y": 10,
      "z": -3,
      "name": "Rock_Stone"
    },
    {
      "x": -18,
      "y": 11,
      "z": -3,
      "name": "Rock_Stone"
    },
    {
      "x": -18,
      "y": 12,
      "z": -3,
      "name": "Rock_Stone"
    },
    {
      "x": -18,
      "y": 13,
      "z": -3,
      "name": "Rock_Stone"
    },
    {
      "x": -18,
      "y": 0,
      "z": -2,
      "name": "Rock_Stone"
    },
    {
      "x": -18,
      "y": 1,
      "z": -2,
      "name": "Rock_Stone"
    },
    {
      "x": -18,
      "y": 2,
      "z": -2,
      "name": "Rock_Stone"
    },
    {
      "x": -18,
      "y": 3,
      "z": -2,
      "name": "Rock_Stone"
    },
    {
      "x": -18,
      "y": 4,
      "z": -2,
      "name": "Rock_Stone"
    },
    {
      "x": -18,
      "y": 5,
      "z": -2,
      "name": "Rock_Stone"
    },
    {
      "x": -18,
      "y": 6,
      "z": -2,
      "name": "Rock_Stone"
    },
    {
      "x": -18,
      "y": 7,
      "z": -2,
      "name": "Rock_Stone"
    },
    {
      "x": -18,
      "y": 8,
      "z": -2,
      "name": "Rock_Stone"
    },
    {
      "x": -18,
      "y": 9,
      "z": -2,
      "name": "Rock_Stone"
    },
    {
      "x": -18,
      "y": 10,
      "z": -2,
      "name": "Rock_Stone"
    },
    {
      "x": -17,
      "y": 0,
      "z": -12,
      "name": "Rock_Stone"
    },
    {
      "x": -17,
      "y": 1,
      "z": -12,
      "name": "Rock_Stone"
    },
    {
      "x": -17,
      "y": 2,
      "z": -12,
      "name": "Rock_Stone"
    },
    {
      "x": -17,
      "y": 3,
      "z": -12,
      "name": "Rock_Stone"
    },
    {
      "x": -17,
      "y": 4,
      "z": -12,
      "name": "Rock_Stone"
    },
    {
      "x": -17,
      "y": 5,
      "z": -12,
      "name": "Rock_Stone"
    },
    {
      "x": -17,
      "y": 6,
      "z": -12,
      "name": "Rock_Stone"
    },
    {
      "x": -17,
      "y": 7,
      "z": -12,
      "name": "Rock_Stone"
    },
    {
      "x": -17,
      "y": 8,
      "z": -12,
      "name": "Rock_Stone"
    },
    {
      "x": -17,
      "y": 9,
      "z": -12,
      "name": "Rock_Stone"
    },
    {
      "x": -17,
      "y": 0,
      "z": -11,
      "name": "Rock_Stone"
    },
    {
      "x": -17,
      "y": 1,
      "z": -11,
      "name": "Rock_Stone"
    },
    {
      "x": -17,
      "y": 2,
      "z": -11,
      "name": "Rock_Stone"
    },
    {
      "x": -17,
      "y": 3,
      "z": -11,
      "name": "Rock_Stone"
    },
    {
      "x": -17,
      "y": 4,
      "z": -11,
      "name": "Rock_Stone"
    },
    {
      "x": -17,
      "y": 5,
      "z": -11,
      "name": "Rock_Stone"
    },
    {
      "x": -17,
      "y": 6,
      "z": -11,
      "name": "Rock_Stone"
    },
    {
      "x": -17,
      "y": 7,
      "z": -11,
      "name": "Rock_Stone"
    },
    {
      "x": -17,
      "y": 8,
      "z": -11,
      "name": "Rock_Stone"
    },
    {
      "x": -17,
      "y": 9,
      "z": -11,
      "name": "Rock_Stone"
    },
    {
      "x": -17,
      "y": 10,
      "z": -11,
      "name": "Rock_Stone"
    },
    {
      "x": -17,
      "y": 11,
      "z": -11,
      "name": "Rock_Stone"
    },
    {
      "x": -17,
      "y": 12,
      "z": -11,
      "name": "Rock_Stone"
    },
    {
      "x": -17,
      "y": 13,
      "z": -11,
      "name": "Rock_Stone"
    },
    {
      "x": -17,
      "y": 0,
      "z": -10,
      "name": "Rock_Stone"
    },
    {
      "x": -17,
      "y": 1,
      "z": -10,
      "name": "Rock_Stone"
    },
    {
      "x": -17,
      "y": 2,
      "z": -10,
      "name": "Rock_Stone"
    },
    {
      "x": -17,
      "y": 3,
      "z": -10,
      "name": "Rock_Stone"
    },
    {
      "x": -17,
      "y": 4,
      "z": -10,
      "name": "Rock_Stone"
    },
    {
      "x": -17,
      "y": 5,
      "z": -10,
      "name": "Rock_Stone"
    },
    {
      "x": -17,
      "y": 6,
      "z": -10,
      "name": "Rock_Stone"
    },
    {
      "x": -17,
      "y": 7,
      "z": -10,
      "name": "Rock_Stone"
    },
    {
      "x": -17,
      "y": 8,
      "z": -10,
      "name": "Rock_Stone"
    },
    {
      "x": -17,
      "y": 9,
      "z": -10,
      "name": "Rock_Stone"
    },
    {
      "x": -17,
      "y": 10,
      "z": -10,
      "name": "Rock_Stone"
    },
    {
      "x": -17,
      "y": 11,
      "z": -10,
      "name": "Rock_Stone"
    },
    {
      "x": -17,
      "y": 12,
      "z": -10,
      "name": "Rock_Stone"
    },
    {
      "x": -17,
      "y": 13,
      "z": -10,
      "name": "Rock_Stone"
    },
    {
      "x": -17,
      "y": 14,
      "z": -10,
      "name": "Rock_Stone"
    },
    {
      "x": -17,
      "y": 15,
      "z": -10,
      "name": "Soil_Dirt"
    },
    {
      "x": -17,
      "y": 16,
      "z": -10,
      "name": "Soil_Grass"
    },
    {
      "x": -17,
      "y": 0,
      "z": -9,
      "name": "Rock_Stone"
    },
    {
      "x": -17,
      "y": 1,
      "z": -9,
      "name": "Rock_Stone"
    },
    {
      "x": -17,
      "y": 2,
      "z": -9,
      "name": "Rock_Stone"
    },
    {
      "x": -17,
      "y": 3,
      "z": -9,
      "name": "Rock_Stone"
    },
    {
      "x": -17,
      "y": 4,
      "z": -9,
      "name": "Rock_Stone"
    },
    {
      "x": -17,
      "y": 5,
      "z": -9,
      "name": "Rock_Stone"
    },
    {
      "x": -17,
      "y": 6,
      "z": -9,
      "name": "Rock_Stone"
    },
    {
      "x": -17,
      "y": 7,
      "z": -9,
      "name": "Rock_Stone"
    },
    {
      "x": -17,
      "y": 8,
      "z": -9,
      "name": "Rock_Stone"
    },
    {
      "x": -17,
      "y": 9,
      "z": -9,
      "name": "Rock_Stone"
    },
    {
      "x": -17,
      "y": 10,
      "z": -9,
      "name": "Rock_Stone"
    },
    {
      "x": -17,
      "y": 11,
      "z": -9,
      "name": "Rock_Stone"
    },
    {
      "x": -17,
      "y": 12,
      "z": -9,
      "name": "Rock_Stone"
    },
    {
      "x": -17,
      "y": 13,
      "z": -9,
      "name": "Rock_Stone"
    },
    {
      "x": -17,
      "y": 14,
      "z": -9,
      "name": "Rock_Stone"
    },
    {
      "x": -17,
      "y": 15,
      "z": -9,
      "name": "Rock_Stone"
    },
    {
      "x": -17,
      "y": 16,
      "z": -9,
      "name": "Soil_Grass"
    },
    {
      "x": -17,
      "y": 0,
      "z": -8,
      "name": "Rock_Stone"
    },
    {
      "x": -17,
      "y": 1,
      "z": -8,
      "name": "Rock_Stone"
    },
    {
      "x": -17,
      "y": 2,
      "z": -8,
      "name": "Rock_Stone"
    },
    {
      "x": -17,
      "y": 3,
      "z": -8,
      "name": "Rock_Stone"
    },
    {
      "x": -17,
      "y": 4,
      "z": -8,
      "name": "Rock_Stone"
    },
    {
      "x": -17,
      "y": 5,
      "z": -8,
      "name": "Rock_Stone"
    },
    {
      "x": -17,
      "y": 6,
      "z": -8,
      "name": "Rock_Stone"
    },
    {
      "x": -17,
      "y": 7,
      "z": -8,
      "name": "Rock_Stone"
    },
    {
      "x": -17,
      "y": 8,
      "z": -8,
      "name": "Rock_Stone"
    },
    {
      "x": -17,
      "y": 9,
      "z": -8,
      "name": "Rock_Stone"
    },
    {
      "x": -17,
      "y": 10,
      "z": -8,
      "name": "Rock_Stone"
    },
    {
      "x": -17,
      "y": 11,
      "z": -8,
      "name": "Rock_Stone"
    },
    {
      "x": -17,
      "y": 12,
      "z": -8,
      "name": "Rock_Stone"
    },
    {
      "x": -17,
      "y": 13,
      "z": -8,
      "name": "Rock_Stone"
    },
    {
      "x": -17,
      "y": 14,
      "z": -8,
      "name": "Rock_Stone"
    },
    {
      "x": -17,
      "y": 15,
      "z": -8,
      "name": "Rock_Stone"
    },
    {
      "x": -17,
      "y": 16,
      "z": -8,
      "name": "Rock_Stone"
    },
    {
      "x": -17,
      "y": 17,
      "z": -8,
      "name": "Soil_Grass"
    },
    {
      "x": -17,
      "y": 18,
      "z": -8,
      "name": "Plant_Grass_Sharp_Short"
    },
    {
      "x": -17,
      "y": 0,
      "z": -7,
      "name": "Rock_Stone"
    },
    {
      "x": -17,
      "y": 1,
      "z": -7,
      "name": "Rock_Stone"
    },
    {
      "x": -17,
      "y": 2,
      "z": -7,
      "name": "Rock_Stone"
    },
    {
      "x": -17,
      "y": 3,
      "z": -7,
      "name": "Rock_Stone"
    },
    {
      "x": -17,
      "y": 4,
      "z": -7,
      "name": "Rock_Stone"
    },
    {
      "x": -17,
      "y": 5,
      "z": -7,
      "name": "Rock_Stone"
    },
    {
      "x": -17,
      "y": 6,
      "z": -7,
      "name": "Rock_Stone"
    },
    {
      "x": -17,
      "y": 7,
      "z": -7,
      "name": "Rock_Stone"
    },
    {
      "x": -17,
      "y": 8,
      "z": -7,
      "name": "Rock_Stone"
    },
    {
      "x": -17,
      "y": 9,
      "z": -7,
      "name": "Rock_Stone"
    },
    {
      "x": -17,
      "y": 10,
      "z": -7,
      "name": "Rock_Stone"
    },
    {
      "x": -17,
      "y": 11,
      "z": -7,
      "name": "Rock_Stone"
    },
    {
      "x": -17,
      "y": 12,
      "z": -7,
      "name": "Rock_Stone"
    },
    {
      "x": -17,
      "y": 13,
      "z": -7,
      "name": "Rock_Stone"
    },
    {
      "x": -17,
      "y": 14,
      "z": -7,
      "name": "Rock_Stone"
    },
    {
      "x": -17,
      "y": 15,
      "z": -7,
      "name": "Rock_Stone"
    },
    {
      "x": -17,
      "y": 16,
      "z": -7,
      "name": "Rock_Stone"
    },
    {
      "x": -17,
      "y": 17,
      "z": -7,
      "name": "Soil_Dirt"
    },
    {
      "x": -17,
      "y": 18,
      "z": -7,
      "name": "Soil_Grass"
    },
    {
      "x": -17,
      "y": 0,
      "z": -6,
      "name": "Rock_Stone"
    },
    {
      "x": -17,
      "y": 1,
      "z": -6,
      "name": "Rock_Stone"
    },
    {
      "x": -17,
      "y": 2,
      "z": -6,
      "name": "Rock_Stone"
    },
    {
      "x": -17,
      "y": 3,
      "z": -6,
      "name": "Rock_Stone"
    },
    {
      "x": -17,
      "y": 4,
      "z": -6,
      "name": "Rock_Stone"
    },
    {
      "x": -17,
      "y": 5,
      "z": -6,
      "name": "Rock_Stone"
    },
    {
      "x": -17,
      "y": 6,
      "z": -6,
      "name": "Rock_Stone"
    },
    {
      "x": -17,
      "y": 7,
      "z": -6,
      "name": "Rock_Stone"
    },
    {
      "x": -17,
      "y": 8,
      "z": -6,
      "name": "Rock_Stone"
    },
    {
      "x": -17,
      "y": 9,
      "z": -6,
      "name": "Rock_Stone"
    },
    {
      "x": -17,
      "y": 10,
      "z": -6,
      "name": "Rock_Stone"
    },
    {
      "x": -17,
      "y": 11,
      "z": -6,
      "name": "Rock_Stone"
    },
    {
      "x": -17,
      "y": 12,
      "z": -6,
      "name": "Rock_Stone"
    },
    {
      "x": -17,
      "y": 13,
      "z": -6,
      "name": "Rock_Stone"
    },
    {
      "x": -17,
      "y": 14,
      "z": -6,
      "name": "Rock_Stone"
    },
    {
      "x": -17,
      "y": 15,
      "z": -6,
      "name": "Rock_Stone"
    },
    {
      "x": -17,
      "y": 16,
      "z": -6,
      "name": "Rock_Stone"
    },
    {
      "x": -17,
      "y": 17,
      "z": -6,
      "name": "Soil_Dirt"
    },
    {
      "x": -17,
      "y": 18,
      "z": -6,
      "name": "Soil_Grass"
    },
    {
      "x": -17,
      "y": 19,
      "z": -6,
      "name": "Plant_Grass_Sharp"
    },
    {
      "x": -17,
      "y": 0,
      "z": -5,
      "name": "Rock_Stone"
    },
    {
      "x": -17,
      "y": 1,
      "z": -5,
      "name": "Rock_Stone"
    },
    {
      "x": -17,
      "y": 2,
      "z": -5,
      "name": "Rock_Stone"
    },
    {
      "x": -17,
      "y": 3,
      "z": -5,
      "name": "Rock_Stone"
    },
    {
      "x": -17,
      "y": 4,
      "z": -5,
      "name": "Rock_Stone"
    },
    {
      "x": -17,
      "y": 5,
      "z": -5,
      "name": "Rock_Stone"
    },
    {
      "x": -17,
      "y": 6,
      "z": -5,
      "name": "Rock_Stone"
    },
    {
      "x": -17,
      "y": 7,
      "z": -5,
      "name": "Rock_Stone"
    },
    {
      "x": -17,
      "y": 8,
      "z": -5,
      "name": "Rock_Stone"
    },
    {
      "x": -17,
      "y": 9,
      "z": -5,
      "name": "Rock_Stone"
    },
    {
      "x": -17,
      "y": 10,
      "z": -5,
      "name": "Rock_Stone"
    },
    {
      "x": -17,
      "y": 11,
      "z": -5,
      "name": "Rock_Stone"
    },
    {
      "x": -17,
      "y": 12,
      "z": -5,
      "name": "Rock_Stone"
    },
    {
      "x": -17,
      "y": 13,
      "z": -5,
      "name": "Rock_Stone"
    },
    {
      "x": -17,
      "y": 14,
      "z": -5,
      "name": "Rock_Stone"
    },
    {
      "x": -17,
      "y": 15,
      "z": -5,
      "name": "Rock_Stone"
    },
    {
      "x": -17,
      "y": 16,
      "z": -5,
      "name": "Rock_Stone"
    },
    {
      "x": -17,
      "y": 17,
      "z": -5,
      "name": "Soil_Dirt"
    },
    {
      "x": -17,
      "y": 18,
      "z": -5,
      "name": "Soil_Grass"
    },
    {
      "x": -17,
      "y": 0,
      "z": -4,
      "name": "Rock_Stone"
    },
    {
      "x": -17,
      "y": 1,
      "z": -4,
      "name": "Rock_Stone"
    },
    {
      "x": -17,
      "y": 2,
      "z": -4,
      "name": "Rock_Stone"
    },
    {
      "x": -17,
      "y": 3,
      "z": -4,
      "name": "Rock_Stone"
    },
    {
      "x": -17,
      "y": 4,
      "z": -4,
      "name": "Rock_Stone"
    },
    {
      "x": -17,
      "y": 5,
      "z": -4,
      "name": "Rock_Stone"
    },
    {
      "x": -17,
      "y": 6,
      "z": -4,
      "name": "Rock_Stone"
    },
    {
      "x": -17,
      "y": 7,
      "z": -4,
      "name": "Rock_Stone"
    },
    {
      "x": -17,
      "y": 8,
      "z": -4,
      "name": "Rock_Stone"
    },
    {
      "x": -17,
      "y": 9,
      "z": -4,
      "name": "Rock_Stone"
    },
    {
      "x": -17,
      "y": 10,
      "z": -4,
      "name": "Rock_Stone"
    },
    {
      "x": -17,
      "y": 11,
      "z": -4,
      "name": "Rock_Stone"
    },
    {
      "x": -17,
      "y": 12,
      "z": -4,
      "name": "Rock_Stone"
    },
    {
      "x": -17,
      "y": 13,
      "z": -4,
      "name": "Rock_Stone"
    },
    {
      "x": -17,
      "y": 14,
      "z": -4,
      "name": "Rock_Stone"
    },
    {
      "x": -17,
      "y": 15,
      "z": -4,
      "name": "Rock_Stone"
    },
    {
      "x": -17,
      "y": 16,
      "z": -4,
      "name": "Rock_Stone"
    },
    {
      "x": -17,
      "y": 17,
      "z": -4,
      "name": "Soil_Dirt"
    },
    {
      "x": -17,
      "y": 18,
      "z": -4,
      "name": "Soil_Grass"
    },
    {
      "x": -17,
      "y": 19,
      "z": -4,
      "name": "Plant_Grass_Sharp_Short"
    },
    {
      "x": -17,
      "y": 0,
      "z": -3,
      "name": "Rock_Stone"
    },
    {
      "x": -17,
      "y": 1,
      "z": -3,
      "name": "Rock_Stone"
    },
    {
      "x": -17,
      "y": 2,
      "z": -3,
      "name": "Rock_Stone"
    },
    {
      "x": -17,
      "y": 3,
      "z": -3,
      "name": "Rock_Stone"
    },
    {
      "x": -17,
      "y": 4,
      "z": -3,
      "name": "Rock_Stone"
    },
    {
      "x": -17,
      "y": 5,
      "z": -3,
      "name": "Rock_Stone"
    },
    {
      "x": -17,
      "y": 6,
      "z": -3,
      "name": "Rock_Stone"
    },
    {
      "x": -17,
      "y": 7,
      "z": -3,
      "name": "Rock_Stone"
    },
    {
      "x": -17,
      "y": 8,
      "z": -3,
      "name": "Rock_Stone"
    },
    {
      "x": -17,
      "y": 9,
      "z": -3,
      "name": "Rock_Stone"
    },
    {
      "x": -17,
      "y": 10,
      "z": -3,
      "name": "Rock_Stone"
    },
    {
      "x": -17,
      "y": 11,
      "z": -3,
      "name": "Rock_Stone"
    },
    {
      "x": -17,
      "y": 12,
      "z": -3,
      "name": "Rock_Stone"
    },
    {
      "x": -17,
      "y": 13,
      "z": -3,
      "name": "Rock_Stone"
    },
    {
      "x": -17,
      "y": 14,
      "z": -3,
      "name": "Rock_Stone"
    },
    {
      "x": -17,
      "y": 15,
      "z": -3,
      "name": "Rock_Stone"
    },
    {
      "x": -17,
      "y": 16,
      "z": -3,
      "name": "Rock_Stone"
    },
    {
      "x": -17,
      "y": 17,
      "z": -3,
      "name": "Soil_Dirt"
    },
    {
      "x": -17,
      "y": 18,
      "z": -3,
      "name": "Soil_Grass"
    },
    {
      "x": -17,
      "y": 19,
      "z": -3,
      "name": "Plant_Grass_Sharp_Short"
    },
    {
      "x": -17,
      "y": 0,
      "z": -2,
      "name": "Rock_Stone"
    },
    {
      "x": -17,
      "y": 1,
      "z": -2,
      "name": "Rock_Stone"
    },
    {
      "x": -17,
      "y": 2,
      "z": -2,
      "name": "Rock_Stone"
    },
    {
      "x": -17,
      "y": 3,
      "z": -2,
      "name": "Rock_Stone"
    },
    {
      "x": -17,
      "y": 4,
      "z": -2,
      "name": "Rock_Stone"
    },
    {
      "x": -17,
      "y": 5,
      "z": -2,
      "name": "Rock_Stone"
    },
    {
      "x": -17,
      "y": 6,
      "z": -2,
      "name": "Rock_Stone"
    },
    {
      "x": -17,
      "y": 7,
      "z": -2,
      "name": "Rock_Stone"
    },
    {
      "x": -17,
      "y": 8,
      "z": -2,
      "name": "Rock_Stone"
    },
    {
      "x": -17,
      "y": 9,
      "z": -2,
      "name": "Rock_Stone"
    },
    {
      "x": -17,
      "y": 10,
      "z": -2,
      "name": "Rock_Stone"
    },
    {
      "x": -17,
      "y": 11,
      "z": -2,
      "name": "Rock_Stone"
    },
    {
      "x": -17,
      "y": 12,
      "z": -2,
      "name": "Rock_Stone"
    },
    {
      "x": -17,
      "y": 13,
      "z": -2,
      "name": "Rock_Stone"
    },
    {
      "x": -17,
      "y": 14,
      "z": -2,
      "name": "Rock_Stone"
    },
    {
      "x": -17,
      "y": 15,
      "z": -2,
      "name": "Rock_Stone"
    },
    {
      "x": -17,
      "y": 16,
      "z": -2,
      "name": "Soil_Dirt"
    },
    {
      "x": -17,
      "y": 17,
      "z": -2,
      "name": "Soil_Grass"
    },
    {
      "x": -17,
      "y": 0,
      "z": -1,
      "name": "Rock_Stone"
    },
    {
      "x": -17,
      "y": 1,
      "z": -1,
      "name": "Rock_Stone"
    },
    {
      "x": -17,
      "y": 2,
      "z": -1,
      "name": "Rock_Stone"
    },
    {
      "x": -17,
      "y": 3,
      "z": -1,
      "name": "Rock_Stone"
    },
    {
      "x": -17,
      "y": 4,
      "z": -1,
      "name": "Rock_Stone"
    },
    {
      "x": -17,
      "y": 5,
      "z": -1,
      "name": "Rock_Stone"
    },
    {
      "x": -17,
      "y": 6,
      "z": -1,
      "name": "Rock_Stone"
    },
    {
      "x": -17,
      "y": 7,
      "z": -1,
      "name": "Rock_Stone"
    },
    {
      "x": -17,
      "y": 8,
      "z": -1,
      "name": "Rock_Stone"
    },
    {
      "x": -17,
      "y": 9,
      "z": -1,
      "name": "Rock_Stone"
    },
    {
      "x": -17,
      "y": 10,
      "z": -1,
      "name": "Rock_Stone"
    },
    {
      "x": -17,
      "y": 11,
      "z": -1,
      "name": "Rock_Stone"
    },
    {
      "x": -16,
      "y": 0,
      "z": -13,
      "name": "Rock_Stone"
    },
    {
      "x": -16,
      "y": 1,
      "z": -13,
      "name": "Rock_Stone"
    },
    {
      "x": -16,
      "y": 2,
      "z": -13,
      "name": "Rock_Stone"
    },
    {
      "x": -16,
      "y": 3,
      "z": -13,
      "name": "Rock_Stone"
    },
    {
      "x": -16,
      "y": 4,
      "z": -13,
      "name": "Rock_Stone"
    },
    {
      "x": -16,
      "y": 5,
      "z": -13,
      "name": "Rock_Stone"
    },
    {
      "x": -16,
      "y": 6,
      "z": -13,
      "name": "Rock_Stone"
    },
    {
      "x": -16,
      "y": 0,
      "z": -12,
      "name": "Rock_Stone"
    },
    {
      "x": -16,
      "y": 1,
      "z": -12,
      "name": "Rock_Stone"
    },
    {
      "x": -16,
      "y": 2,
      "z": -12,
      "name": "Rock_Stone"
    },
    {
      "x": -16,
      "y": 3,
      "z": -12,
      "name": "Rock_Stone"
    },
    {
      "x": -16,
      "y": 4,
      "z": -12,
      "name": "Rock_Stone"
    },
    {
      "x": -16,
      "y": 5,
      "z": -12,
      "name": "Rock_Stone"
    },
    {
      "x": -16,
      "y": 6,
      "z": -12,
      "name": "Rock_Stone"
    },
    {
      "x": -16,
      "y": 7,
      "z": -12,
      "name": "Rock_Stone"
    },
    {
      "x": -16,
      "y": 8,
      "z": -12,
      "name": "Rock_Stone"
    },
    {
      "x": -16,
      "y": 9,
      "z": -12,
      "name": "Rock_Stone"
    },
    {
      "x": -16,
      "y": 10,
      "z": -12,
      "name": "Rock_Stone"
    },
    {
      "x": -16,
      "y": 11,
      "z": -12,
      "name": "Rock_Stone"
    },
    {
      "x": -16,
      "y": 12,
      "z": -12,
      "name": "Rock_Stone"
    },
    {
      "x": -16,
      "y": 13,
      "z": -12,
      "name": "Rock_Stone"
    },
    {
      "x": -16,
      "y": 14,
      "z": -12,
      "name": "Rock_Stone"
    },
    {
      "x": -16,
      "y": 0,
      "z": -11,
      "name": "Rock_Stone"
    },
    {
      "x": -16,
      "y": 1,
      "z": -11,
      "name": "Rock_Stone"
    },
    {
      "x": -16,
      "y": 2,
      "z": -11,
      "name": "Rock_Stone"
    },
    {
      "x": -16,
      "y": 3,
      "z": -11,
      "name": "Rock_Stone"
    },
    {
      "x": -16,
      "y": 4,
      "z": -11,
      "name": "Rock_Stone"
    },
    {
      "x": -16,
      "y": 5,
      "z": -11,
      "name": "Rock_Stone"
    },
    {
      "x": -16,
      "y": 6,
      "z": -11,
      "name": "Rock_Stone"
    },
    {
      "x": -16,
      "y": 7,
      "z": -11,
      "name": "Rock_Stone"
    },
    {
      "x": -16,
      "y": 8,
      "z": -11,
      "name": "Rock_Stone"
    },
    {
      "x": -16,
      "y": 9,
      "z": -11,
      "name": "Rock_Stone"
    },
    {
      "x": -16,
      "y": 10,
      "z": -11,
      "name": "Rock_Stone"
    },
    {
      "x": -16,
      "y": 11,
      "z": -11,
      "name": "Rock_Stone"
    },
    {
      "x": -16,
      "y": 12,
      "z": -11,
      "name": "Rock_Stone"
    },
    {
      "x": -16,
      "y": 13,
      "z": -11,
      "name": "Rock_Stone"
    },
    {
      "x": -16,
      "y": 14,
      "z": -11,
      "name": "Rock_Stone"
    },
    {
      "x": -16,
      "y": 15,
      "z": -11,
      "name": "Soil_Dirt"
    },
    {
      "x": -16,
      "y": 16,
      "z": -11,
      "name": "Soil_Grass"
    },
    {
      "x": -16,
      "y": 0,
      "z": -10,
      "name": "Rock_Stone"
    },
    {
      "x": -16,
      "y": 1,
      "z": -10,
      "name": "Rock_Stone"
    },
    {
      "x": -16,
      "y": 2,
      "z": -10,
      "name": "Rock_Stone"
    },
    {
      "x": -16,
      "y": 3,
      "z": -10,
      "name": "Rock_Stone"
    },
    {
      "x": -16,
      "y": 4,
      "z": -10,
      "name": "Rock_Stone"
    },
    {
      "x": -16,
      "y": 5,
      "z": -10,
      "name": "Rock_Stone"
    },
    {
      "x": -16,
      "y": 6,
      "z": -10,
      "name": "Rock_Stone"
    },
    {
      "x": -16,
      "y": 7,
      "z": -10,
      "name": "Rock_Stone"
    },
    {
      "x": -16,
      "y": 8,
      "z": -10,
      "name": "Rock_Stone"
    },
    {
      "x": -16,
      "y": 9,
      "z": -10,
      "name": "Rock_Stone"
    },
    {
      "x": -16,
      "y": 10,
      "z": -10,
      "name": "Rock_Stone"
    },
    {
      "x": -16,
      "y": 11,
      "z": -10,
      "name": "Rock_Stone"
    },
    {
      "x": -16,
      "y": 12,
      "z": -10,
      "name": "Rock_Stone"
    },
    {
      "x": -16,
      "y": 13,
      "z": -10,
      "name": "Rock_Stone"
    },
    {
      "x": -16,
      "y": 14,
      "z": -10,
      "name": "Rock_Stone"
    },
    {
      "x": -16,
      "y": 15,
      "z": -10,
      "name": "Soil_Dirt"
    },
    {
      "x": -16,
      "y": 16,
      "z": -10,
      "name": "Soil_Grass"
    },
    {
      "x": -16,
      "y": 0,
      "z": -9,
      "name": "Rock_Stone"
    },
    {
      "x": -16,
      "y": 1,
      "z": -9,
      "name": "Rock_Stone"
    },
    {
      "x": -16,
      "y": 2,
      "z": -9,
      "name": "Rock_Stone"
    },
    {
      "x": -16,
      "y": 3,
      "z": -9,
      "name": "Rock_Stone"
    },
    {
      "x": -16,
      "y": 4,
      "z": -9,
      "name": "Rock_Stone"
    },
    {
      "x": -16,
      "y": 5,
      "z": -9,
      "name": "Rock_Stone"
    },
    {
      "x": -16,
      "y": 6,
      "z": -9,
      "name": "Rock_Stone"
    },
    {
      "x": -16,
      "y": 7,
      "z": -9,
      "name": "Rock_Stone"
    },
    {
      "x": -16,
      "y": 8,
      "z": -9,
      "name": "Rock_Stone"
    },
    {
      "x": -16,
      "y": 9,
      "z": -9,
      "name": "Rock_Stone"
    },
    {
      "x": -16,
      "y": 10,
      "z": -9,
      "name": "Rock_Stone"
    },
    {
      "x": -16,
      "y": 11,
      "z": -9,
      "name": "Rock_Stone"
    },
    {
      "x": -16,
      "y": 12,
      "z": -9,
      "name": "Rock_Stone"
    },
    {
      "x": -16,
      "y": 13,
      "z": -9,
      "name": "Rock_Stone"
    },
    {
      "x": -16,
      "y": 14,
      "z": -9,
      "name": "Rock_Stone"
    },
    {
      "x": -16,
      "y": 15,
      "z": -9,
      "name": "Rock_Stone"
    },
    {
      "x": -16,
      "y": 16,
      "z": -9,
      "name": "Soil_Dirt"
    },
    {
      "x": -16,
      "y": 17,
      "z": -9,
      "name": "Soil_Grass"
    },
    {
      "x": -16,
      "y": 18,
      "z": -9,
      "name": "Plant_Grass_Sharp_Short"
    },
    {
      "x": -16,
      "y": 0,
      "z": -8,
      "name": "Rock_Stone"
    },
    {
      "x": -16,
      "y": 1,
      "z": -8,
      "name": "Rock_Stone"
    },
    {
      "x": -16,
      "y": 2,
      "z": -8,
      "name": "Rock_Stone"
    },
    {
      "x": -16,
      "y": 3,
      "z": -8,
      "name": "Rock_Stone"
    },
    {
      "x": -16,
      "y": 4,
      "z": -8,
      "name": "Rock_Stone"
    },
    {
      "x": -16,
      "y": 5,
      "z": -8,
      "name": "Rock_Stone"
    },
    {
      "x": -16,
      "y": 6,
      "z": -8,
      "name": "Rock_Stone"
    },
    {
      "x": -16,
      "y": 7,
      "z": -8,
      "name": "Rock_Stone"
    },
    {
      "x": -16,
      "y": 8,
      "z": -8,
      "name": "Rock_Stone"
    },
    {
      "x": -16,
      "y": 9,
      "z": -8,
      "name": "Rock_Stone"
    },
    {
      "x": -16,
      "y": 10,
      "z": -8,
      "name": "Rock_Stone"
    },
    {
      "x": -16,
      "y": 11,
      "z": -8,
      "name": "Rock_Stone"
    },
    {
      "x": -16,
      "y": 12,
      "z": -8,
      "name": "Rock_Stone"
    },
    {
      "x": -16,
      "y": 13,
      "z": -8,
      "name": "Rock_Stone"
    },
    {
      "x": -16,
      "y": 14,
      "z": -8,
      "name": "Rock_Stone"
    },
    {
      "x": -16,
      "y": 15,
      "z": -8,
      "name": "Rock_Stone"
    },
    {
      "x": -16,
      "y": 16,
      "z": -8,
      "name": "Soil_Dirt"
    },
    {
      "x": -16,
      "y": 17,
      "z": -8,
      "name": "Soil_Grass"
    },
    {
      "x": -16,
      "y": 0,
      "z": -7,
      "name": "Rock_Stone"
    },
    {
      "x": -16,
      "y": 1,
      "z": -7,
      "name": "Rock_Stone"
    },
    {
      "x": -16,
      "y": 2,
      "z": -7,
      "name": "Rock_Stone"
    },
    {
      "x": -16,
      "y": 3,
      "z": -7,
      "name": "Rock_Stone"
    },
    {
      "x": -16,
      "y": 4,
      "z": -7,
      "name": "Rock_Stone"
    },
    {
      "x": -16,
      "y": 5,
      "z": -7,
      "name": "Rock_Stone"
    },
    {
      "x": -16,
      "y": 6,
      "z": -7,
      "name": "Rock_Stone"
    },
    {
      "x": -16,
      "y": 7,
      "z": -7,
      "name": "Rock_Stone"
    },
    {
      "x": -16,
      "y": 8,
      "z": -7,
      "name": "Rock_Stone"
    },
    {
      "x": -16,
      "y": 9,
      "z": -7,
      "name": "Rock_Stone"
    },
    {
      "x": -16,
      "y": 10,
      "z": -7,
      "name": "Rock_Stone"
    },
    {
      "x": -16,
      "y": 11,
      "z": -7,
      "name": "Rock_Stone"
    },
    {
      "x": -16,
      "y": 12,
      "z": -7,
      "name": "Rock_Stone"
    },
    {
      "x": -16,
      "y": 13,
      "z": -7,
      "name": "Rock_Stone"
    },
    {
      "x": -16,
      "y": 14,
      "z": -7,
      "name": "Rock_Stone"
    },
    {
      "x": -16,
      "y": 15,
      "z": -7,
      "name": "Rock_Stone"
    },
    {
      "x": -16,
      "y": 16,
      "z": -7,
      "name": "Rock_Stone"
    },
    {
      "x": -16,
      "y": 17,
      "z": -7,
      "name": "Soil_Dirt"
    },
    {
      "x": -16,
      "y": 18,
      "z": -7,
      "name": "Soil_Grass"
    },
    {
      "x": -16,
      "y": 19,
      "z": -7,
      "name": "Plant_Grass_Sharp_Tall"
    },
    {
      "x": -16,
      "y": 20,
      "z": -7,
      "name": "Plant_Grass_Sharp_Tall",
      "filler": 1024
    },
    {
      "x": -16,
      "y": 0,
      "z": -6,
      "name": "Rock_Stone"
    },
    {
      "x": -16,
      "y": 1,
      "z": -6,
      "name": "Rock_Stone"
    },
    {
      "x": -16,
      "y": 2,
      "z": -6,
      "name": "Rock_Stone"
    },
    {
      "x": -16,
      "y": 3,
      "z": -6,
      "name": "Rock_Stone"
    },
    {
      "x": -16,
      "y": 4,
      "z": -6,
      "name": "Rock_Stone"
    },
    {
      "x": -16,
      "y": 5,
      "z": -6,
      "name": "Rock_Stone"
    },
    {
      "x": -16,
      "y": 6,
      "z": -6,
      "name": "Rock_Stone"
    },
    {
      "x": -16,
      "y": 7,
      "z": -6,
      "name": "Rock_Stone"
    },
    {
      "x": -16,
      "y": 8,
      "z": -6,
      "name": "Rock_Stone"
    },
    {
      "x": -16,
      "y": 9,
      "z": -6,
      "name": "Rock_Stone"
    },
    {
      "x": -16,
      "y": 10,
      "z": -6,
      "name": "Rock_Stone"
    },
    {
      "x": -16,
      "y": 11,
      "z": -6,
      "name": "Rock_Stone"
    },
    {
      "x": -16,
      "y": 12,
      "z": -6,
      "name": "Rock_Stone"
    },
    {
      "x": -16,
      "y": 13,
      "z": -6,
      "name": "Rock_Stone"
    },
    {
      "x": -16,
      "y": 14,
      "z": -6,
      "name": "Rock_Stone"
    },
    {
      "x": -16,
      "y": 15,
      "z": -6,
      "name": "Rock_Stone"
    },
    {
      "x": -16,
      "y": 16,
      "z": -6,
      "name": "Rock_Stone"
    },
    {
      "x": -16,
      "y": 17,
      "z": -6,
      "name": "Soil_Dirt"
    },
    {
      "x": -16,
      "y": 18,
      "z": -6,
      "name": "Soil_Grass"
    },
    {
      "x": -16,
      "y": 19,
      "z": -6,
      "name": "Plant_Grass_Sharp"
    },
    {
      "x": -16,
      "y": 0,
      "z": -5,
      "name": "Rock_Stone"
    },
    {
      "x": -16,
      "y": 1,
      "z": -5,
      "name": "Rock_Stone"
    },
    {
      "x": -16,
      "y": 2,
      "z": -5,
      "name": "Rock_Stone"
    },
    {
      "x": -16,
      "y": 3,
      "z": -5,
      "name": "Rock_Stone"
    },
    {
      "x": -16,
      "y": 4,
      "z": -5,
      "name": "Rock_Stone"
    },
    {
      "x": -16,
      "y": 5,
      "z": -5,
      "name": "Rock_Stone"
    },
    {
      "x": -16,
      "y": 6,
      "z": -5,
      "name": "Rock_Stone"
    },
    {
      "x": -16,
      "y": 7,
      "z": -5,
      "name": "Rock_Stone"
    },
    {
      "x": -16,
      "y": 8,
      "z": -5,
      "name": "Rock_Stone"
    },
    {
      "x": -16,
      "y": 9,
      "z": -5,
      "name": "Rock_Stone"
    },
    {
      "x": -16,
      "y": 10,
      "z": -5,
      "name": "Rock_Stone"
    },
    {
      "x": -16,
      "y": 11,
      "z": -5,
      "name": "Rock_Stone"
    },
    {
      "x": -16,
      "y": 12,
      "z": -5,
      "name": "Rock_Stone"
    },
    {
      "x": -16,
      "y": 13,
      "z": -5,
      "name": "Rock_Stone"
    },
    {
      "x": -16,
      "y": 14,
      "z": -5,
      "name": "Rock_Stone"
    },
    {
      "x": -16,
      "y": 15,
      "z": -5,
      "name": "Rock_Stone"
    },
    {
      "x": -16,
      "y": 16,
      "z": -5,
      "name": "Rock_Stone"
    },
    {
      "x": -16,
      "y": 17,
      "z": -5,
      "name": "Soil_Dirt"
    },
    {
      "x": -16,
      "y": 18,
      "z": -5,
      "name": "Soil_Grass"
    },
    {
      "x": -16,
      "y": 19,
      "z": -5,
      "name": "Plant_Grass_Sharp"
    },
    {
      "x": -16,
      "y": 0,
      "z": -4,
      "name": "Rock_Stone"
    },
    {
      "x": -16,
      "y": 1,
      "z": -4,
      "name": "Rock_Stone"
    },
    {
      "x": -16,
      "y": 2,
      "z": -4,
      "name": "Rock_Stone"
    },
    {
      "x": -16,
      "y": 3,
      "z": -4,
      "name": "Rock_Stone"
    },
    {
      "x": -16,
      "y": 4,
      "z": -4,
      "name": "Rock_Stone"
    },
    {
      "x": -16,
      "y": 5,
      "z": -4,
      "name": "Rock_Stone"
    },
    {
      "x": -16,
      "y": 6,
      "z": -4,
      "name": "Rock_Stone"
    },
    {
      "x": -16,
      "y": 7,
      "z": -4,
      "name": "Rock_Stone"
    },
    {
      "x": -16,
      "y": 8,
      "z": -4,
      "name": "Rock_Stone"
    },
    {
      "x": -16,
      "y": 9,
      "z": -4,
      "name": "Rock_Stone"
    },
    {
      "x": -16,
      "y": 10,
      "z": -4,
      "name": "Rock_Stone"
    },
    {
      "x": -16,
      "y": 11,
      "z": -4,
      "name": "Rock_Stone"
    },
    {
      "x": -16,
      "y": 12,
      "z": -4,
      "name": "Rock_Stone"
    },
    {
      "x": -16,
      "y": 13,
      "z": -4,
      "name": "Rock_Stone"
    },
    {
      "x": -16,
      "y": 14,
      "z": -4,
      "name": "Rock_Stone"
    },
    {
      "x": -16,
      "y": 15,
      "z": -4,
      "name": "Rock_Stone"
    },
    {
      "x": -16,
      "y": 16,
      "z": -4,
      "name": "Rock_Stone"
    },
    {
      "x": -16,
      "y": 17,
      "z": -4,
      "name": "Soil_Dirt"
    },
    {
      "x": -16,
      "y": 18,
      "z": -4,
      "name": "Soil_Grass"
    },
    {
      "x": -16,
      "y": 0,
      "z": -3,
      "name": "Rock_Stone"
    },
    {
      "x": -16,
      "y": 1,
      "z": -3,
      "name": "Rock_Stone"
    },
    {
      "x": -16,
      "y": 2,
      "z": -3,
      "name": "Rock_Stone"
    },
    {
      "x": -16,
      "y": 3,
      "z": -3,
      "name": "Rock_Stone"
    },
    {
      "x": -16,
      "y": 4,
      "z": -3,
      "name": "Rock_Stone"
    },
    {
      "x": -16,
      "y": 5,
      "z": -3,
      "name": "Rock_Stone"
    },
    {
      "x": -16,
      "y": 6,
      "z": -3,
      "name": "Rock_Stone"
    },
    {
      "x": -16,
      "y": 7,
      "z": -3,
      "name": "Rock_Stone"
    },
    {
      "x": -16,
      "y": 8,
      "z": -3,
      "name": "Rock_Stone"
    },
    {
      "x": -16,
      "y": 9,
      "z": -3,
      "name": "Rock_Stone"
    },
    {
      "x": -16,
      "y": 10,
      "z": -3,
      "name": "Rock_Stone"
    },
    {
      "x": -16,
      "y": 11,
      "z": -3,
      "name": "Rock_Stone"
    },
    {
      "x": -16,
      "y": 12,
      "z": -3,
      "name": "Rock_Stone"
    },
    {
      "x": -16,
      "y": 13,
      "z": -3,
      "name": "Rock_Stone"
    },
    {
      "x": -16,
      "y": 14,
      "z": -3,
      "name": "Rock_Stone"
    },
    {
      "x": -16,
      "y": 15,
      "z": -3,
      "name": "Rock_Stone"
    },
    {
      "x": -16,
      "y": 16,
      "z": -3,
      "name": "Rock_Stone"
    },
    {
      "x": -16,
      "y": 17,
      "z": -3,
      "name": "Soil_Dirt"
    },
    {
      "x": -16,
      "y": 18,
      "z": -3,
      "name": "Soil_Grass"
    },
    {
      "x": -16,
      "y": 0,
      "z": -2,
      "name": "Rock_Stone"
    },
    {
      "x": -16,
      "y": 1,
      "z": -2,
      "name": "Rock_Stone"
    },
    {
      "x": -16,
      "y": 2,
      "z": -2,
      "name": "Rock_Stone"
    },
    {
      "x": -16,
      "y": 3,
      "z": -2,
      "name": "Rock_Stone"
    },
    {
      "x": -16,
      "y": 4,
      "z": -2,
      "name": "Rock_Stone"
    },
    {
      "x": -16,
      "y": 5,
      "z": -2,
      "name": "Rock_Stone"
    },
    {
      "x": -16,
      "y": 6,
      "z": -2,
      "name": "Rock_Stone"
    },
    {
      "x": -16,
      "y": 7,
      "z": -2,
      "name": "Rock_Stone"
    },
    {
      "x": -16,
      "y": 8,
      "z": -2,
      "name": "Rock_Stone"
    },
    {
      "x": -16,
      "y": 9,
      "z": -2,
      "name": "Rock_Stone"
    },
    {
      "x": -16,
      "y": 10,
      "z": -2,
      "name": "Rock_Stone"
    },
    {
      "x": -16,
      "y": 11,
      "z": -2,
      "name": "Rock_Stone"
    },
    {
      "x": -16,
      "y": 12,
      "z": -2,
      "name": "Rock_Stone"
    },
    {
      "x": -16,
      "y": 13,
      "z": -2,
      "name": "Rock_Stone"
    },
    {
      "x": -16,
      "y": 14,
      "z": -2,
      "name": "Rock_Stone"
    },
    {
      "x": -16,
      "y": 15,
      "z": -2,
      "name": "Rock_Stone"
    },
    {
      "x": -16,
      "y": 16,
      "z": -2,
      "name": "Rock_Stone"
    },
    {
      "x": -16,
      "y": 17,
      "z": -2,
      "name": "Soil_Dirt"
    },
    {
      "x": -16,
      "y": 18,
      "z": -2,
      "name": "Soil_Grass"
    },
    {
      "x": -16,
      "y": 0,
      "z": -1,
      "name": "Rock_Stone"
    },
    {
      "x": -16,
      "y": 1,
      "z": -1,
      "name": "Rock_Stone"
    },
    {
      "x": -16,
      "y": 2,
      "z": -1,
      "name": "Rock_Stone"
    },
    {
      "x": -16,
      "y": 3,
      "z": -1,
      "name": "Rock_Stone"
    },
    {
      "x": -16,
      "y": 4,
      "z": -1,
      "name": "Rock_Stone"
    },
    {
      "x": -16,
      "y": 5,
      "z": -1,
      "name": "Rock_Stone"
    },
    {
      "x": -16,
      "y": 6,
      "z": -1,
      "name": "Rock_Stone"
    },
    {
      "x": -16,
      "y": 7,
      "z": -1,
      "name": "Rock_Stone"
    },
    {
      "x": -16,
      "y": 8,
      "z": -1,
      "name": "Rock_Stone"
    },
    {
      "x": -16,
      "y": 9,
      "z": -1,
      "name": "Rock_Stone"
    },
    {
      "x": -16,
      "y": 10,
      "z": -1,
      "name": "Rock_Stone"
    },
    {
      "x": -16,
      "y": 11,
      "z": -1,
      "name": "Rock_Stone"
    },
    {
      "x": -16,
      "y": 12,
      "z": -1,
      "name": "Rock_Stone"
    },
    {
      "x": -16,
      "y": 13,
      "z": -1,
      "name": "Rock_Stone"
    },
    {
      "x": -16,
      "y": 14,
      "z": -1,
      "name": "Rock_Stone"
    },
    {
      "x": -16,
      "y": 15,
      "z": -1,
      "name": "Rock_Stone"
    },
    {
      "x": -16,
      "y": 16,
      "z": -1,
      "name": "Soil_Dirt"
    },
    {
      "x": -16,
      "y": 17,
      "z": -1,
      "name": "Soil_Grass"
    },
    {
      "x": -16,
      "y": 18,
      "z": -1,
      "name": "Plant_Grass_Sharp_Short"
    },
    {
      "x": -16,
      "y": 0,
      "z": 0,
      "name": "Rock_Stone"
    },
    {
      "x": -16,
      "y": 1,
      "z": 0,
      "name": "Rock_Stone"
    },
    {
      "x": -16,
      "y": 2,
      "z": 0,
      "name": "Rock_Stone"
    },
    {
      "x": -16,
      "y": 3,
      "z": 0,
      "name": "Rock_Stone"
    },
    {
      "x": -16,
      "y": 4,
      "z": 0,
      "name": "Rock_Stone"
    },
    {
      "x": -16,
      "y": 5,
      "z": 0,
      "name": "Rock_Stone"
    },
    {
      "x": -16,
      "y": 6,
      "z": 0,
      "name": "Rock_Stone"
    },
    {
      "x": -16,
      "y": 7,
      "z": 0,
      "name": "Rock_Stone"
    },
    {
      "x": -16,
      "y": 8,
      "z": 0,
      "name": "Rock_Stone"
    },
    {
      "x": -16,
      "y": 9,
      "z": 0,
      "name": "Rock_Stone"
    },
    {
      "x": -16,
      "y": 10,
      "z": 0,
      "name": "Rock_Stone"
    },
    {
      "x": -16,
      "y": 11,
      "z": 0,
      "name": "Rock_Stone"
    },
    {
      "x": -16,
      "y": 12,
      "z": 0,
      "name": "Rock_Stone"
    },
    {
      "x": -16,
      "y": 13,
      "z": 0,
      "name": "Rock_Stone"
    },
    {
      "x": -16,
      "y": 0,
      "z": 6,
      "name": "Rock_Quartzite"
    },
    {
      "x": -16,
      "y": 1,
      "z": 6,
      "name": "Rock_Quartzite"
    },
    {
      "x": -16,
      "y": 2,
      "z": 6,
      "name": "Rock_Quartzite"
    },
    {
      "x": -16,
      "y": 3,
      "z": 6,
      "name": "Rock_Quartzite"
    },
    {
      "x": -16,
      "y": 4,
      "z": 6,
      "name": "Rock_Quartzite"
    },
    {
      "x": -16,
      "y": 5,
      "z": 6,
      "name": "Rock_Quartzite"
    },
    {
      "x": -16,
      "y": 6,
      "z": 6,
      "name": "Rock_Quartzite"
    },
    {
      "x": -16,
      "y": 7,
      "z": 6,
      "name": "Rock_Quartzite"
    },
    {
      "x": -16,
      "y": 8,
      "z": 6,
      "name": "Rock_Quartzite"
    },
    {
      "x": -16,
      "y": 9,
      "z": 6,
      "name": "Rock_Quartzite"
    },
    {
      "x": -16,
      "y": 10,
      "z": 6,
      "name": "Rock_Quartzite_Cobble"
    },
    {
      "x": -16,
      "y": 11,
      "z": 6,
      "name": "Rock_Quartzite_Cobble"
    },
    {
      "x": -16,
      "y": 0,
      "z": 7,
      "name": "Rock_Quartzite"
    },
    {
      "x": -16,
      "y": 1,
      "z": 7,
      "name": "Rock_Quartzite"
    },
    {
      "x": -16,
      "y": 2,
      "z": 7,
      "name": "Rock_Quartzite"
    },
    {
      "x": -16,
      "y": 3,
      "z": 7,
      "name": "Rock_Quartzite"
    },
    {
      "x": -16,
      "y": 4,
      "z": 7,
      "name": "Rock_Quartzite"
    },
    {
      "x": -16,
      "y": 5,
      "z": 7,
      "name": "Rock_Quartzite"
    },
    {
      "x": -16,
      "y": 6,
      "z": 7,
      "name": "Rock_Quartzite"
    },
    {
      "x": -16,
      "y": 7,
      "z": 7,
      "name": "Rock_Quartzite"
    },
    {
      "x": -16,
      "y": 8,
      "z": 7,
      "name": "Rock_Quartzite"
    },
    {
      "x": -16,
      "y": 9,
      "z": 7,
      "name": "Rock_Quartzite"
    },
    {
      "x": -16,
      "y": 10,
      "z": 7,
      "name": "Rock_Quartzite_Cobble"
    },
    {
      "x": -16,
      "y": 11,
      "z": 7,
      "name": "Rock_Quartzite_Cobble"
    },
    {
      "x": -15,
      "y": 0,
      "z": -14,
      "name": "Rock_Stone"
    },
    {
      "x": -15,
      "y": 1,
      "z": -14,
      "name": "Rock_Stone"
    },
    {
      "x": -15,
      "y": 2,
      "z": -14,
      "name": "Rock_Stone"
    },
    {
      "x": -15,
      "y": 3,
      "z": -14,
      "name": "Rock_Stone"
    },
    {
      "x": -15,
      "y": 4,
      "z": -14,
      "name": "Rock_Stone"
    },
    {
      "x": -15,
      "y": 5,
      "z": -14,
      "name": "Rock_Stone"
    },
    {
      "x": -15,
      "y": 6,
      "z": -14,
      "name": "Rock_Stone"
    },
    {
      "x": -15,
      "y": 7,
      "z": -14,
      "name": "Rock_Stone"
    },
    {
      "x": -15,
      "y": 8,
      "z": -14,
      "name": "Rock_Stone"
    },
    {
      "x": -15,
      "y": 0,
      "z": -13,
      "name": "Rock_Stone"
    },
    {
      "x": -15,
      "y": 1,
      "z": -13,
      "name": "Rock_Stone"
    },
    {
      "x": -15,
      "y": 2,
      "z": -13,
      "name": "Rock_Stone"
    },
    {
      "x": -15,
      "y": 3,
      "z": -13,
      "name": "Rock_Stone"
    },
    {
      "x": -15,
      "y": 4,
      "z": -13,
      "name": "Rock_Stone"
    },
    {
      "x": -15,
      "y": 5,
      "z": -13,
      "name": "Rock_Stone"
    },
    {
      "x": -15,
      "y": 6,
      "z": -13,
      "name": "Rock_Stone"
    },
    {
      "x": -15,
      "y": 7,
      "z": -13,
      "name": "Rock_Stone"
    },
    {
      "x": -15,
      "y": 8,
      "z": -13,
      "name": "Rock_Stone"
    },
    {
      "x": -15,
      "y": 9,
      "z": -13,
      "name": "Rock_Stone"
    },
    {
      "x": -15,
      "y": 10,
      "z": -13,
      "name": "Rock_Stone"
    },
    {
      "x": -15,
      "y": 11,
      "z": -13,
      "name": "Rock_Stone"
    },
    {
      "x": -15,
      "y": 0,
      "z": -12,
      "name": "Rock_Stone"
    },
    {
      "x": -15,
      "y": 1,
      "z": -12,
      "name": "Rock_Stone"
    },
    {
      "x": -15,
      "y": 2,
      "z": -12,
      "name": "Rock_Stone"
    },
    {
      "x": -15,
      "y": 3,
      "z": -12,
      "name": "Rock_Stone"
    },
    {
      "x": -15,
      "y": 4,
      "z": -12,
      "name": "Rock_Stone"
    },
    {
      "x": -15,
      "y": 5,
      "z": -12,
      "name": "Rock_Stone"
    },
    {
      "x": -15,
      "y": 6,
      "z": -12,
      "name": "Rock_Stone"
    },
    {
      "x": -15,
      "y": 7,
      "z": -12,
      "name": "Rock_Stone"
    },
    {
      "x": -15,
      "y": 8,
      "z": -12,
      "name": "Rock_Stone"
    },
    {
      "x": -15,
      "y": 9,
      "z": -12,
      "name": "Rock_Stone"
    },
    {
      "x": -15,
      "y": 10,
      "z": -12,
      "name": "Rock_Stone"
    },
    {
      "x": -15,
      "y": 11,
      "z": -12,
      "name": "Rock_Stone"
    },
    {
      "x": -15,
      "y": 12,
      "z": -12,
      "name": "Rock_Stone"
    },
    {
      "x": -15,
      "y": 13,
      "z": -12,
      "name": "Rock_Stone"
    },
    {
      "x": -15,
      "y": 14,
      "z": -12,
      "name": "Rock_Stone"
    },
    {
      "x": -15,
      "y": 15,
      "z": -12,
      "name": "Soil_Dirt"
    },
    {
      "x": -15,
      "y": 16,
      "z": -12,
      "name": "Soil_Grass"
    },
    {
      "x": -15,
      "y": 0,
      "z": -11,
      "name": "Rock_Stone"
    },
    {
      "x": -15,
      "y": 1,
      "z": -11,
      "name": "Rock_Stone"
    },
    {
      "x": -15,
      "y": 2,
      "z": -11,
      "name": "Rock_Stone"
    },
    {
      "x": -15,
      "y": 3,
      "z": -11,
      "name": "Rock_Stone"
    },
    {
      "x": -15,
      "y": 4,
      "z": -11,
      "name": "Rock_Stone"
    },
    {
      "x": -15,
      "y": 5,
      "z": -11,
      "name": "Rock_Stone"
    },
    {
      "x": -15,
      "y": 6,
      "z": -11,
      "name": "Rock_Stone"
    },
    {
      "x": -15,
      "y": 7,
      "z": -11,
      "name": "Rock_Stone"
    },
    {
      "x": -15,
      "y": 8,
      "z": -11,
      "name": "Rock_Stone"
    },
    {
      "x": -15,
      "y": 9,
      "z": -11,
      "name": "Rock_Stone"
    },
    {
      "x": -15,
      "y": 10,
      "z": -11,
      "name": "Rock_Stone"
    },
    {
      "x": -15,
      "y": 11,
      "z": -11,
      "name": "Rock_Stone"
    },
    {
      "x": -15,
      "y": 12,
      "z": -11,
      "name": "Rock_Stone"
    },
    {
      "x": -15,
      "y": 13,
      "z": -11,
      "name": "Rock_Stone"
    },
    {
      "x": -15,
      "y": 14,
      "z": -11,
      "name": "Rock_Stone"
    },
    {
      "x": -15,
      "y": 15,
      "z": -11,
      "name": "Soil_Dirt"
    },
    {
      "x": -15,
      "y": 16,
      "z": -11,
      "name": "Soil_Grass"
    },
    {
      "x": -15,
      "y": 0,
      "z": -10,
      "name": "Rock_Stone"
    },
    {
      "x": -15,
      "y": 1,
      "z": -10,
      "name": "Rock_Stone"
    },
    {
      "x": -15,
      "y": 2,
      "z": -10,
      "name": "Rock_Stone"
    },
    {
      "x": -15,
      "y": 3,
      "z": -10,
      "name": "Rock_Stone"
    },
    {
      "x": -15,
      "y": 4,
      "z": -10,
      "name": "Rock_Stone"
    },
    {
      "x": -15,
      "y": 5,
      "z": -10,
      "name": "Rock_Stone"
    },
    {
      "x": -15,
      "y": 6,
      "z": -10,
      "name": "Rock_Stone"
    },
    {
      "x": -15,
      "y": 7,
      "z": -10,
      "name": "Rock_Stone"
    },
    {
      "x": -15,
      "y": 8,
      "z": -10,
      "name": "Rock_Stone"
    },
    {
      "x": -15,
      "y": 9,
      "z": -10,
      "name": "Rock_Stone"
    },
    {
      "x": -15,
      "y": 10,
      "z": -10,
      "name": "Rock_Stone"
    },
    {
      "x": -15,
      "y": 11,
      "z": -10,
      "name": "Rock_Stone"
    },
    {
      "x": -15,
      "y": 12,
      "z": -10,
      "name": "Rock_Stone"
    },
    {
      "x": -15,
      "y": 13,
      "z": -10,
      "name": "Rock_Stone"
    },
    {
      "x": -15,
      "y": 14,
      "z": -10,
      "name": "Rock_Stone"
    },
    {
      "x": -15,
      "y": 15,
      "z": -10,
      "name": "Soil_Dirt"
    },
    {
      "x": -15,
      "y": 16,
      "z": -10,
      "name": "Soil_Grass"
    },
    {
      "x": -15,
      "y": 0,
      "z": -9,
      "name": "Rock_Stone"
    },
    {
      "x": -15,
      "y": 1,
      "z": -9,
      "name": "Rock_Stone"
    },
    {
      "x": -15,
      "y": 2,
      "z": -9,
      "name": "Rock_Stone"
    },
    {
      "x": -15,
      "y": 3,
      "z": -9,
      "name": "Rock_Stone"
    },
    {
      "x": -15,
      "y": 4,
      "z": -9,
      "name": "Rock_Stone"
    },
    {
      "x": -15,
      "y": 5,
      "z": -9,
      "name": "Rock_Stone"
    },
    {
      "x": -15,
      "y": 6,
      "z": -9,
      "name": "Rock_Stone"
    },
    {
      "x": -15,
      "y": 7,
      "z": -9,
      "name": "Rock_Stone"
    },
    {
      "x": -15,
      "y": 8,
      "z": -9,
      "name": "Rock_Stone"
    },
    {
      "x": -15,
      "y": 9,
      "z": -9,
      "name": "Rock_Stone"
    },
    {
      "x": -15,
      "y": 10,
      "z": -9,
      "name": "Rock_Stone"
    },
    {
      "x": -15,
      "y": 11,
      "z": -9,
      "name": "Rock_Stone"
    },
    {
      "x": -15,
      "y": 12,
      "z": -9,
      "name": "Rock_Stone"
    },
    {
      "x": -15,
      "y": 13,
      "z": -9,
      "name": "Rock_Stone"
    },
    {
      "x": -15,
      "y": 14,
      "z": -9,
      "name": "Rock_Stone"
    },
    {
      "x": -15,
      "y": 15,
      "z": -9,
      "name": "Rock_Stone"
    },
    {
      "x": -15,
      "y": 16,
      "z": -9,
      "name": "Soil_Dirt"
    },
    {
      "x": -15,
      "y": 17,
      "z": -9,
      "name": "Soil_Grass"
    },
    {
      "x": -15,
      "y": 0,
      "z": -8,
      "name": "Rock_Stone"
    },
    {
      "x": -15,
      "y": 1,
      "z": -8,
      "name": "Rock_Stone"
    },
    {
      "x": -15,
      "y": 2,
      "z": -8,
      "name": "Rock_Stone"
    },
    {
      "x": -15,
      "y": 3,
      "z": -8,
      "name": "Rock_Stone"
    },
    {
      "x": -15,
      "y": 4,
      "z": -8,
      "name": "Rock_Stone"
    },
    {
      "x": -15,
      "y": 5,
      "z": -8,
      "name": "Rock_Stone"
    },
    {
      "x": -15,
      "y": 6,
      "z": -8,
      "name": "Rock_Stone"
    },
    {
      "x": -15,
      "y": 7,
      "z": -8,
      "name": "Rock_Stone"
    },
    {
      "x": -15,
      "y": 8,
      "z": -8,
      "name": "Rock_Stone"
    },
    {
      "x": -15,
      "y": 9,
      "z": -8,
      "name": "Rock_Stone"
    },
    {
      "x": -15,
      "y": 10,
      "z": -8,
      "name": "Rock_Stone"
    },
    {
      "x": -15,
      "y": 11,
      "z": -8,
      "name": "Rock_Stone"
    },
    {
      "x": -15,
      "y": 12,
      "z": -8,
      "name": "Rock_Stone"
    },
    {
      "x": -15,
      "y": 13,
      "z": -8,
      "name": "Rock_Stone"
    },
    {
      "x": -15,
      "y": 14,
      "z": -8,
      "name": "Rock_Stone"
    },
    {
      "x": -15,
      "y": 15,
      "z": -8,
      "name": "Rock_Stone"
    },
    {
      "x": -15,
      "y": 16,
      "z": -8,
      "name": "Soil_Dirt"
    },
    {
      "x": -15,
      "y": 17,
      "z": -8,
      "name": "Soil_Grass"
    },
    {
      "x": -15,
      "y": 0,
      "z": -7,
      "name": "Rock_Stone"
    },
    {
      "x": -15,
      "y": 1,
      "z": -7,
      "name": "Rock_Stone"
    },
    {
      "x": -15,
      "y": 2,
      "z": -7,
      "name": "Rock_Stone"
    },
    {
      "x": -15,
      "y": 3,
      "z": -7,
      "name": "Rock_Stone"
    },
    {
      "x": -15,
      "y": 4,
      "z": -7,
      "name": "Rock_Stone"
    },
    {
      "x": -15,
      "y": 5,
      "z": -7,
      "name": "Rock_Stone"
    },
    {
      "x": -15,
      "y": 6,
      "z": -7,
      "name": "Rock_Stone"
    },
    {
      "x": -15,
      "y": 7,
      "z": -7,
      "name": "Rock_Stone"
    },
    {
      "x": -15,
      "y": 8,
      "z": -7,
      "name": "Rock_Stone"
    },
    {
      "x": -15,
      "y": 9,
      "z": -7,
      "name": "Rock_Stone"
    },
    {
      "x": -15,
      "y": 10,
      "z": -7,
      "name": "Rock_Stone"
    },
    {
      "x": -15,
      "y": 11,
      "z": -7,
      "name": "Rock_Stone"
    },
    {
      "x": -15,
      "y": 12,
      "z": -7,
      "name": "Rock_Stone"
    },
    {
      "x": -15,
      "y": 13,
      "z": -7,
      "name": "Rock_Stone"
    },
    {
      "x": -15,
      "y": 14,
      "z": -7,
      "name": "Rock_Stone"
    },
    {
      "x": -15,
      "y": 15,
      "z": -7,
      "name": "Rock_Stone"
    },
    {
      "x": -15,
      "y": 16,
      "z": -7,
      "name": "Rock_Stone"
    },
    {
      "x": -15,
      "y": 17,
      "z": -7,
      "name": "Soil_Dirt"
    },
    {
      "x": -15,
      "y": 18,
      "z": -7,
      "name": "Soil_Grass"
    },
    {
      "x": -15,
      "y": 19,
      "z": -7,
      "name": "Plant_Grass_Sharp_Short"
    },
    {
      "x": -15,
      "y": 0,
      "z": -6,
      "name": "Rock_Stone"
    },
    {
      "x": -15,
      "y": 1,
      "z": -6,
      "name": "Rock_Stone"
    },
    {
      "x": -15,
      "y": 2,
      "z": -6,
      "name": "Rock_Stone"
    },
    {
      "x": -15,
      "y": 3,
      "z": -6,
      "name": "Rock_Stone"
    },
    {
      "x": -15,
      "y": 4,
      "z": -6,
      "name": "Rock_Stone"
    },
    {
      "x": -15,
      "y": 5,
      "z": -6,
      "name": "Rock_Stone"
    },
    {
      "x": -15,
      "y": 6,
      "z": -6,
      "name": "Rock_Stone"
    },
    {
      "x": -15,
      "y": 7,
      "z": -6,
      "name": "Rock_Stone"
    },
    {
      "x": -15,
      "y": 8,
      "z": -6,
      "name": "Rock_Stone"
    },
    {
      "x": -15,
      "y": 9,
      "z": -6,
      "name": "Rock_Stone"
    },
    {
      "x": -15,
      "y": 10,
      "z": -6,
      "name": "Rock_Stone"
    },
    {
      "x": -15,
      "y": 11,
      "z": -6,
      "name": "Rock_Stone"
    },
    {
      "x": -15,
      "y": 12,
      "z": -6,
      "name": "Rock_Stone"
    },
    {
      "x": -15,
      "y": 13,
      "z": -6,
      "name": "Rock_Stone"
    },
    {
      "x": -15,
      "y": 14,
      "z": -6,
      "name": "Rock_Stone"
    },
    {
      "x": -15,
      "y": 15,
      "z": -6,
      "name": "Rock_Stone"
    },
    {
      "x": -15,
      "y": 16,
      "z": -6,
      "name": "Rock_Stone"
    },
    {
      "x": -15,
      "y": 17,
      "z": -6,
      "name": "Rock_Stone"
    },
    {
      "x": -15,
      "y": 18,
      "z": -6,
      "name": "Soil_Grass"
    },
    {
      "x": -15,
      "y": 19,
      "z": -6,
      "name": "Plant_Grass_Sharp_Tall"
    },
    {
      "x": -15,
      "y": 20,
      "z": -6,
      "name": "Plant_Grass_Sharp_Tall",
      "filler": 1024
    },
    {
      "x": -15,
      "y": 0,
      "z": -5,
      "name": "Rock_Stone"
    },
    {
      "x": -15,
      "y": 1,
      "z": -5,
      "name": "Rock_Stone"
    },
    {
      "x": -15,
      "y": 2,
      "z": -5,
      "name": "Rock_Stone"
    },
    {
      "x": -15,
      "y": 3,
      "z": -5,
      "name": "Rock_Stone"
    },
    {
      "x": -15,
      "y": 4,
      "z": -5,
      "name": "Rock_Stone"
    },
    {
      "x": -15,
      "y": 5,
      "z": -5,
      "name": "Rock_Stone"
    },
    {
      "x": -15,
      "y": 6,
      "z": -5,
      "name": "Rock_Stone"
    },
    {
      "x": -15,
      "y": 7,
      "z": -5,
      "name": "Rock_Stone"
    },
    {
      "x": -15,
      "y": 8,
      "z": -5,
      "name": "Rock_Stone"
    },
    {
      "x": -15,
      "y": 9,
      "z": -5,
      "name": "Rock_Stone"
    },
    {
      "x": -15,
      "y": 10,
      "z": -5,
      "name": "Rock_Stone"
    },
    {
      "x": -15,
      "y": 11,
      "z": -5,
      "name": "Rock_Stone"
    },
    {
      "x": -15,
      "y": 12,
      "z": -5,
      "name": "Rock_Stone"
    },
    {
      "x": -15,
      "y": 13,
      "z": -5,
      "name": "Rock_Stone"
    },
    {
      "x": -15,
      "y": 14,
      "z": -5,
      "name": "Rock_Stone"
    },
    {
      "x": -15,
      "y": 15,
      "z": -5,
      "name": "Rock_Stone"
    },
    {
      "x": -15,
      "y": 16,
      "z": -5,
      "name": "Rock_Stone"
    },
    {
      "x": -15,
      "y": 17,
      "z": -5,
      "name": "Soil_Dirt"
    },
    {
      "x": -15,
      "y": 18,
      "z": -5,
      "name": "Soil_Grass"
    },
    {
      "x": -15,
      "y": 19,
      "z": -5,
      "name": "Plant_Grass_Sharp"
    },
    {
      "x": -15,
      "y": 0,
      "z": -4,
      "name": "Rock_Stone"
    },
    {
      "x": -15,
      "y": 1,
      "z": -4,
      "name": "Rock_Stone"
    },
    {
      "x": -15,
      "y": 2,
      "z": -4,
      "name": "Rock_Stone"
    },
    {
      "x": -15,
      "y": 3,
      "z": -4,
      "name": "Rock_Stone"
    },
    {
      "x": -15,
      "y": 4,
      "z": -4,
      "name": "Rock_Stone"
    },
    {
      "x": -15,
      "y": 5,
      "z": -4,
      "name": "Rock_Stone"
    },
    {
      "x": -15,
      "y": 6,
      "z": -4,
      "name": "Rock_Stone"
    },
    {
      "x": -15,
      "y": 7,
      "z": -4,
      "name": "Rock_Stone"
    },
    {
      "x": -15,
      "y": 8,
      "z": -4,
      "name": "Rock_Stone"
    },
    {
      "x": -15,
      "y": 9,
      "z": -4,
      "name": "Rock_Stone"
    },
    {
      "x": -15,
      "y": 10,
      "z": -4,
      "name": "Rock_Stone"
    },
    {
      "x": -15,
      "y": 11,
      "z": -4,
      "name": "Rock_Stone"
    },
    {
      "x": -15,
      "y": 12,
      "z": -4,
      "name": "Rock_Stone"
    },
    {
      "x": -15,
      "y": 13,
      "z": -4,
      "name": "Rock_Stone"
    },
    {
      "x": -15,
      "y": 14,
      "z": -4,
      "name": "Rock_Stone"
    },
    {
      "x": -15,
      "y": 15,
      "z": -4,
      "name": "Rock_Stone"
    },
    {
      "x": -15,
      "y": 16,
      "z": -4,
      "name": "Rock_Stone"
    },
    {
      "x": -15,
      "y": 17,
      "z": -4,
      "name": "Soil_Dirt"
    },
    {
      "x": -15,
      "y": 18,
      "z": -4,
      "name": "Soil_Grass"
    },
    {
      "x": -15,
      "y": 19,
      "z": -4,
      "name": "Plant_Bush"
    },
    {
      "x": -15,
      "y": 0,
      "z": -3,
      "name": "Rock_Stone"
    },
    {
      "x": -15,
      "y": 1,
      "z": -3,
      "name": "Rock_Stone"
    },
    {
      "x": -15,
      "y": 2,
      "z": -3,
      "name": "Rock_Stone"
    },
    {
      "x": -15,
      "y": 3,
      "z": -3,
      "name": "Rock_Stone"
    },
    {
      "x": -15,
      "y": 4,
      "z": -3,
      "name": "Rock_Stone"
    },
    {
      "x": -15,
      "y": 5,
      "z": -3,
      "name": "Rock_Stone"
    },
    {
      "x": -15,
      "y": 6,
      "z": -3,
      "name": "Rock_Stone"
    },
    {
      "x": -15,
      "y": 7,
      "z": -3,
      "name": "Rock_Stone"
    },
    {
      "x": -15,
      "y": 8,
      "z": -3,
      "name": "Rock_Stone"
    },
    {
      "x": -15,
      "y": 9,
      "z": -3,
      "name": "Rock_Stone"
    },
    {
      "x": -15,
      "y": 10,
      "z": -3,
      "name": "Rock_Stone"
    },
    {
      "x": -15,
      "y": 11,
      "z": -3,
      "name": "Rock_Stone"
    },
    {
      "x": -15,
      "y": 12,
      "z": -3,
      "name": "Rock_Stone"
    },
    {
      "x": -15,
      "y": 13,
      "z": -3,
      "name": "Rock_Stone"
    },
    {
      "x": -15,
      "y": 14,
      "z": -3,
      "name": "Rock_Stone"
    },
    {
      "x": -15,
      "y": 15,
      "z": -3,
      "name": "Rock_Stone"
    },
    {
      "x": -15,
      "y": 16,
      "z": -3,
      "name": "Rock_Stone"
    },
    {
      "x": -15,
      "y": 17,
      "z": -3,
      "name": "Soil_Dirt"
    },
    {
      "x": -15,
      "y": 18,
      "z": -3,
      "name": "Soil_Grass"
    },
    {
      "x": -15,
      "y": 19,
      "z": -3,
      "name": "Plant_Grass_Sharp_Short"
    },
    {
      "x": -15,
      "y": 0,
      "z": -2,
      "name": "Rock_Stone"
    },
    {
      "x": -15,
      "y": 1,
      "z": -2,
      "name": "Rock_Stone"
    },
    {
      "x": -15,
      "y": 2,
      "z": -2,
      "name": "Rock_Stone"
    },
    {
      "x": -15,
      "y": 3,
      "z": -2,
      "name": "Rock_Stone"
    },
    {
      "x": -15,
      "y": 4,
      "z": -2,
      "name": "Rock_Stone"
    },
    {
      "x": -15,
      "y": 5,
      "z": -2,
      "name": "Rock_Stone"
    },
    {
      "x": -15,
      "y": 6,
      "z": -2,
      "name": "Rock_Stone"
    },
    {
      "x": -15,
      "y": 7,
      "z": -2,
      "name": "Rock_Stone"
    },
    {
      "x": -15,
      "y": 8,
      "z": -2,
      "name": "Rock_Stone"
    },
    {
      "x": -15,
      "y": 9,
      "z": -2,
      "name": "Rock_Stone"
    },
    {
      "x": -15,
      "y": 10,
      "z": -2,
      "name": "Rock_Stone"
    },
    {
      "x": -15,
      "y": 11,
      "z": -2,
      "name": "Rock_Stone"
    },
    {
      "x": -15,
      "y": 12,
      "z": -2,
      "name": "Rock_Stone"
    },
    {
      "x": -15,
      "y": 13,
      "z": -2,
      "name": "Rock_Stone"
    },
    {
      "x": -15,
      "y": 14,
      "z": -2,
      "name": "Rock_Stone"
    },
    {
      "x": -15,
      "y": 15,
      "z": -2,
      "name": "Rock_Stone"
    },
    {
      "x": -15,
      "y": 16,
      "z": -2,
      "name": "Rock_Stone"
    },
    {
      "x": -15,
      "y": 17,
      "z": -2,
      "name": "Soil_Dirt"
    },
    {
      "x": -15,
      "y": 18,
      "z": -2,
      "name": "Soil_Grass"
    },
    {
      "x": -15,
      "y": 19,
      "z": -2,
      "name": "Plant_Grass_Sharp_Short"
    },
    {
      "x": -15,
      "y": 0,
      "z": -1,
      "name": "Rock_Stone"
    },
    {
      "x": -15,
      "y": 1,
      "z": -1,
      "name": "Rock_Stone"
    },
    {
      "x": -15,
      "y": 2,
      "z": -1,
      "name": "Rock_Stone"
    },
    {
      "x": -15,
      "y": 3,
      "z": -1,
      "name": "Rock_Stone"
    },
    {
      "x": -15,
      "y": 4,
      "z": -1,
      "name": "Rock_Stone"
    },
    {
      "x": -15,
      "y": 5,
      "z": -1,
      "name": "Rock_Stone"
    },
    {
      "x": -15,
      "y": 6,
      "z": -1,
      "name": "Rock_Stone"
    },
    {
      "x": -15,
      "y": 7,
      "z": -1,
      "name": "Rock_Stone"
    },
    {
      "x": -15,
      "y": 8,
      "z": -1,
      "name": "Rock_Stone"
    },
    {
      "x": -15,
      "y": 9,
      "z": -1,
      "name": "Rock_Stone"
    },
    {
      "x": -15,
      "y": 10,
      "z": -1,
      "name": "Rock_Stone"
    },
    {
      "x": -15,
      "y": 11,
      "z": -1,
      "name": "Rock_Stone"
    },
    {
      "x": -15,
      "y": 12,
      "z": -1,
      "name": "Rock_Stone"
    },
    {
      "x": -15,
      "y": 13,
      "z": -1,
      "name": "Rock_Stone"
    },
    {
      "x": -15,
      "y": 14,
      "z": -1,
      "name": "Rock_Stone"
    },
    {
      "x": -15,
      "y": 15,
      "z": -1,
      "name": "Rock_Stone"
    },
    {
      "x": -15,
      "y": 16,
      "z": -1,
      "name": "Rock_Stone"
    },
    {
      "x": -15,
      "y": 17,
      "z": -1,
      "name": "Soil_Dirt"
    },
    {
      "x": -15,
      "y": 18,
      "z": -1,
      "name": "Soil_Grass"
    },
    {
      "x": -15,
      "y": 0,
      "z": 0,
      "name": "Rock_Stone"
    },
    {
      "x": -15,
      "y": 1,
      "z": 0,
      "name": "Rock_Stone"
    },
    {
      "x": -15,
      "y": 2,
      "z": 0,
      "name": "Rock_Stone"
    },
    {
      "x": -15,
      "y": 3,
      "z": 0,
      "name": "Rock_Stone"
    },
    {
      "x": -15,
      "y": 4,
      "z": 0,
      "name": "Rock_Stone"
    },
    {
      "x": -15,
      "y": 5,
      "z": 0,
      "name": "Rock_Stone"
    },
    {
      "x": -15,
      "y": 6,
      "z": 0,
      "name": "Rock_Stone"
    },
    {
      "x": -15,
      "y": 7,
      "z": 0,
      "name": "Rock_Stone"
    },
    {
      "x": -15,
      "y": 8,
      "z": 0,
      "name": "Rock_Stone"
    },
    {
      "x": -15,
      "y": 9,
      "z": 0,
      "name": "Rock_Stone"
    },
    {
      "x": -15,
      "y": 10,
      "z": 0,
      "name": "Rock_Stone"
    },
    {
      "x": -15,
      "y": 11,
      "z": 0,
      "name": "Rock_Stone"
    },
    {
      "x": -15,
      "y": 12,
      "z": 0,
      "name": "Rock_Stone"
    },
    {
      "x": -15,
      "y": 13,
      "z": 0,
      "name": "Rock_Stone"
    },
    {
      "x": -15,
      "y": 14,
      "z": 0,
      "name": "Rock_Stone"
    },
    {
      "x": -15,
      "y": 15,
      "z": 0,
      "name": "Soil_Dirt"
    },
    {
      "x": -15,
      "y": 16,
      "z": 0,
      "name": "Soil_Grass"
    },
    {
      "x": -15,
      "y": 0,
      "z": 1,
      "name": "Rock_Stone"
    },
    {
      "x": -15,
      "y": 1,
      "z": 1,
      "name": "Rock_Stone"
    },
    {
      "x": -15,
      "y": 2,
      "z": 1,
      "name": "Rock_Stone"
    },
    {
      "x": -15,
      "y": 3,
      "z": 1,
      "name": "Rock_Stone"
    },
    {
      "x": -15,
      "y": 4,
      "z": 1,
      "name": "Rock_Stone"
    },
    {
      "x": -15,
      "y": 5,
      "z": 1,
      "name": "Rock_Stone"
    },
    {
      "x": -15,
      "y": 6,
      "z": 1,
      "name": "Rock_Stone"
    },
    {
      "x": -15,
      "y": 7,
      "z": 1,
      "name": "Rock_Stone"
    },
    {
      "x": -15,
      "y": 8,
      "z": 1,
      "name": "Rock_Stone"
    },
    {
      "x": -15,
      "y": 9,
      "z": 1,
      "name": "Rock_Stone"
    },
    {
      "x": -15,
      "y": 10,
      "z": 1,
      "name": "Rock_Stone"
    },
    {
      "x": -15,
      "y": 0,
      "z": 6,
      "name": "Rock_Quartzite"
    },
    {
      "x": -15,
      "y": 1,
      "z": 6,
      "name": "Rock_Quartzite"
    },
    {
      "x": -15,
      "y": 2,
      "z": 6,
      "name": "Rock_Quartzite"
    },
    {
      "x": -15,
      "y": 3,
      "z": 6,
      "name": "Rock_Quartzite"
    },
    {
      "x": -15,
      "y": 4,
      "z": 6,
      "name": "Rock_Quartzite"
    },
    {
      "x": -15,
      "y": 5,
      "z": 6,
      "name": "Rock_Quartzite"
    },
    {
      "x": -15,
      "y": 6,
      "z": 6,
      "name": "Rock_Quartzite"
    },
    {
      "x": -15,
      "y": 7,
      "z": 6,
      "name": "Rock_Quartzite"
    },
    {
      "x": -15,
      "y": 8,
      "z": 6,
      "name": "Rock_Quartzite"
    },
    {
      "x": -15,
      "y": 9,
      "z": 6,
      "name": "Rock_Quartzite"
    },
    {
      "x": -15,
      "y": 10,
      "z": 6,
      "name": "Rock_Quartzite_Cobble"
    },
    {
      "x": -15,
      "y": 11,
      "z": 6,
      "name": "Rock_Quartzite_Cobble"
    },
    {
      "x": -15,
      "y": 12,
      "z": 6,
      "name": "Rock_Quartzite_Cobble"
    },
    {
      "x": -15,
      "y": 13,
      "z": 6,
      "name": "Rock_Quartzite_Brick"
    },
    {
      "x": -15,
      "y": 0,
      "z": 7,
      "name": "Rock_Quartzite"
    },
    {
      "x": -15,
      "y": 1,
      "z": 7,
      "name": "Rock_Quartzite"
    },
    {
      "x": -15,
      "y": 2,
      "z": 7,
      "name": "Rock_Quartzite"
    },
    {
      "x": -15,
      "y": 3,
      "z": 7,
      "name": "Rock_Quartzite"
    },
    {
      "x": -15,
      "y": 4,
      "z": 7,
      "name": "Rock_Quartzite"
    },
    {
      "x": -15,
      "y": 5,
      "z": 7,
      "name": "Rock_Quartzite"
    },
    {
      "x": -15,
      "y": 6,
      "z": 7,
      "name": "Rock_Quartzite"
    },
    {
      "x": -15,
      "y": 7,
      "z": 7,
      "name": "Rock_Quartzite"
    },
    {
      "x": -15,
      "y": 8,
      "z": 7,
      "name": "Rock_Quartzite"
    },
    {
      "x": -15,
      "y": 9,
      "z": 7,
      "name": "Rock_Quartzite"
    },
    {
      "x": -15,
      "y": 10,
      "z": 7,
      "name": "Rock_Quartzite_Cobble"
    },
    {
      "x": -15,
      "y": 11,
      "z": 7,
      "name": "Rock_Quartzite_Cobble"
    },
    {
      "x": -15,
      "y": 12,
      "z": 7,
      "name": "Rock_Quartzite_Cobble"
    },
    {
      "x": -15,
      "y": 13,
      "z": 7,
      "name": "Rock_Quartzite_Brick"
    },
    {
      "x": -14,
      "y": 0,
      "z": -14,
      "name": "Rock_Stone"
    },
    {
      "x": -14,
      "y": 1,
      "z": -14,
      "name": "Rock_Stone"
    },
    {
      "x": -14,
      "y": 2,
      "z": -14,
      "name": "Rock_Stone"
    },
    {
      "x": -14,
      "y": 3,
      "z": -14,
      "name": "Rock_Stone"
    },
    {
      "x": -14,
      "y": 4,
      "z": -14,
      "name": "Rock_Stone"
    },
    {
      "x": -14,
      "y": 5,
      "z": -14,
      "name": "Rock_Stone"
    },
    {
      "x": -14,
      "y": 6,
      "z": -14,
      "name": "Rock_Stone"
    },
    {
      "x": -14,
      "y": 7,
      "z": -14,
      "name": "Rock_Stone"
    },
    {
      "x": -14,
      "y": 8,
      "z": -14,
      "name": "Rock_Stone"
    },
    {
      "x": -14,
      "y": 9,
      "z": -14,
      "name": "Rock_Stone"
    },
    {
      "x": -14,
      "y": 10,
      "z": -14,
      "name": "Rock_Stone"
    },
    {
      "x": -14,
      "y": 11,
      "z": -14,
      "name": "Rock_Stone"
    },
    {
      "x": -14,
      "y": 0,
      "z": -13,
      "name": "Rock_Stone"
    },
    {
      "x": -14,
      "y": 1,
      "z": -13,
      "name": "Rock_Stone"
    },
    {
      "x": -14,
      "y": 2,
      "z": -13,
      "name": "Rock_Stone"
    },
    {
      "x": -14,
      "y": 3,
      "z": -13,
      "name": "Rock_Stone"
    },
    {
      "x": -14,
      "y": 4,
      "z": -13,
      "name": "Rock_Stone"
    },
    {
      "x": -14,
      "y": 5,
      "z": -13,
      "name": "Rock_Stone"
    },
    {
      "x": -14,
      "y": 6,
      "z": -13,
      "name": "Rock_Stone"
    },
    {
      "x": -14,
      "y": 7,
      "z": -13,
      "name": "Rock_Stone"
    },
    {
      "x": -14,
      "y": 8,
      "z": -13,
      "name": "Rock_Stone"
    },
    {
      "x": -14,
      "y": 9,
      "z": -13,
      "name": "Rock_Stone"
    },
    {
      "x": -14,
      "y": 10,
      "z": -13,
      "name": "Rock_Stone"
    },
    {
      "x": -14,
      "y": 11,
      "z": -13,
      "name": "Rock_Stone"
    },
    {
      "x": -14,
      "y": 12,
      "z": -13,
      "name": "Rock_Stone"
    },
    {
      "x": -14,
      "y": 13,
      "z": -13,
      "name": "Rock_Stone"
    },
    {
      "x": -14,
      "y": 14,
      "z": -13,
      "name": "Rock_Stone"
    },
    {
      "x": -14,
      "y": 15,
      "z": -13,
      "name": "Soil_Dirt"
    },
    {
      "x": -14,
      "y": 16,
      "z": -13,
      "name": "Soil_Grass"
    },
    {
      "x": -14,
      "y": 0,
      "z": -12,
      "name": "Rock_Stone"
    },
    {
      "x": -14,
      "y": 1,
      "z": -12,
      "name": "Rock_Stone"
    },
    {
      "x": -14,
      "y": 2,
      "z": -12,
      "name": "Rock_Stone"
    },
    {
      "x": -14,
      "y": 3,
      "z": -12,
      "name": "Rock_Stone"
    },
    {
      "x": -14,
      "y": 4,
      "z": -12,
      "name": "Rock_Stone"
    },
    {
      "x": -14,
      "y": 5,
      "z": -12,
      "name": "Rock_Stone"
    },
    {
      "x": -14,
      "y": 6,
      "z": -12,
      "name": "Rock_Stone"
    },
    {
      "x": -14,
      "y": 7,
      "z": -12,
      "name": "Rock_Stone"
    },
    {
      "x": -14,
      "y": 8,
      "z": -12,
      "name": "Rock_Stone"
    },
    {
      "x": -14,
      "y": 9,
      "z": -12,
      "name": "Rock_Stone"
    },
    {
      "x": -14,
      "y": 10,
      "z": -12,
      "name": "Rock_Stone"
    },
    {
      "x": -14,
      "y": 11,
      "z": -12,
      "name": "Rock_Stone"
    },
    {
      "x": -14,
      "y": 12,
      "z": -12,
      "name": "Rock_Stone"
    },
    {
      "x": -14,
      "y": 13,
      "z": -12,
      "name": "Rock_Stone"
    },
    {
      "x": -14,
      "y": 14,
      "z": -12,
      "name": "Rock_Stone"
    },
    {
      "x": -14,
      "y": 15,
      "z": -12,
      "name": "Rock_Stone"
    },
    {
      "x": -14,
      "y": 16,
      "z": -12,
      "name": "Soil_Grass"
    },
    {
      "x": -14,
      "y": 17,
      "z": -12,
      "name": "Plant_Grass_Sharp_Short"
    },
    {
      "x": -14,
      "y": 0,
      "z": -11,
      "name": "Rock_Stone"
    },
    {
      "x": -14,
      "y": 1,
      "z": -11,
      "name": "Rock_Stone"
    },
    {
      "x": -14,
      "y": 2,
      "z": -11,
      "name": "Rock_Stone"
    },
    {
      "x": -14,
      "y": 3,
      "z": -11,
      "name": "Rock_Stone"
    },
    {
      "x": -14,
      "y": 4,
      "z": -11,
      "name": "Rock_Stone"
    },
    {
      "x": -14,
      "y": 5,
      "z": -11,
      "name": "Rock_Stone"
    },
    {
      "x": -14,
      "y": 6,
      "z": -11,
      "name": "Rock_Stone"
    },
    {
      "x": -14,
      "y": 7,
      "z": -11,
      "name": "Rock_Stone"
    },
    {
      "x": -14,
      "y": 8,
      "z": -11,
      "name": "Rock_Stone"
    },
    {
      "x": -14,
      "y": 9,
      "z": -11,
      "name": "Rock_Stone"
    },
    {
      "x": -14,
      "y": 10,
      "z": -11,
      "name": "Rock_Stone"
    },
    {
      "x": -14,
      "y": 11,
      "z": -11,
      "name": "Rock_Stone"
    },
    {
      "x": -14,
      "y": 12,
      "z": -11,
      "name": "Rock_Stone"
    },
    {
      "x": -14,
      "y": 13,
      "z": -11,
      "name": "Rock_Stone"
    },
    {
      "x": -14,
      "y": 14,
      "z": -11,
      "name": "Rock_Stone"
    },
    {
      "x": -14,
      "y": 15,
      "z": -11,
      "name": "Soil_Dirt"
    },
    {
      "x": -14,
      "y": 16,
      "z": -11,
      "name": "Soil_Grass"
    },
    {
      "x": -14,
      "y": 0,
      "z": -10,
      "name": "Rock_Stone"
    },
    {
      "x": -14,
      "y": 1,
      "z": -10,
      "name": "Rock_Stone"
    },
    {
      "x": -14,
      "y": 2,
      "z": -10,
      "name": "Rock_Stone"
    },
    {
      "x": -14,
      "y": 3,
      "z": -10,
      "name": "Rock_Stone"
    },
    {
      "x": -14,
      "y": 4,
      "z": -10,
      "name": "Rock_Stone"
    },
    {
      "x": -14,
      "y": 5,
      "z": -10,
      "name": "Rock_Stone"
    },
    {
      "x": -14,
      "y": 6,
      "z": -10,
      "name": "Rock_Stone"
    },
    {
      "x": -14,
      "y": 7,
      "z": -10,
      "name": "Rock_Stone"
    },
    {
      "x": -14,
      "y": 8,
      "z": -10,
      "name": "Rock_Stone"
    },
    {
      "x": -14,
      "y": 9,
      "z": -10,
      "name": "Rock_Stone"
    },
    {
      "x": -14,
      "y": 10,
      "z": -10,
      "name": "Rock_Stone"
    },
    {
      "x": -14,
      "y": 11,
      "z": -10,
      "name": "Rock_Stone"
    },
    {
      "x": -14,
      "y": 12,
      "z": -10,
      "name": "Rock_Stone"
    },
    {
      "x": -14,
      "y": 13,
      "z": -10,
      "name": "Rock_Stone"
    },
    {
      "x": -14,
      "y": 14,
      "z": -10,
      "name": "Rock_Stone"
    },
    {
      "x": -14,
      "y": 15,
      "z": -10,
      "name": "Rock_Stone"
    },
    {
      "x": -14,
      "y": 16,
      "z": -10,
      "name": "Soil_Dirt"
    },
    {
      "x": -14,
      "y": 17,
      "z": -10,
      "name": "Soil_Grass"
    },
    {
      "x": -14,
      "y": 0,
      "z": -9,
      "name": "Rock_Stone"
    },
    {
      "x": -14,
      "y": 1,
      "z": -9,
      "name": "Rock_Stone"
    },
    {
      "x": -14,
      "y": 2,
      "z": -9,
      "name": "Rock_Stone"
    },
    {
      "x": -14,
      "y": 3,
      "z": -9,
      "name": "Rock_Stone"
    },
    {
      "x": -14,
      "y": 4,
      "z": -9,
      "name": "Rock_Stone"
    },
    {
      "x": -14,
      "y": 5,
      "z": -9,
      "name": "Rock_Stone"
    },
    {
      "x": -14,
      "y": 6,
      "z": -9,
      "name": "Rock_Stone"
    },
    {
      "x": -14,
      "y": 7,
      "z": -9,
      "name": "Rock_Stone"
    },
    {
      "x": -14,
      "y": 8,
      "z": -9,
      "name": "Rock_Stone"
    },
    {
      "x": -14,
      "y": 9,
      "z": -9,
      "name": "Rock_Stone"
    },
    {
      "x": -14,
      "y": 10,
      "z": -9,
      "name": "Rock_Stone"
    },
    {
      "x": -14,
      "y": 11,
      "z": -9,
      "name": "Rock_Stone"
    },
    {
      "x": -14,
      "y": 12,
      "z": -9,
      "name": "Rock_Stone"
    },
    {
      "x": -14,
      "y": 13,
      "z": -9,
      "name": "Rock_Stone"
    },
    {
      "x": -14,
      "y": 14,
      "z": -9,
      "name": "Rock_Stone"
    },
    {
      "x": -14,
      "y": 15,
      "z": -9,
      "name": "Rock_Stone"
    },
    {
      "x": -14,
      "y": 16,
      "z": -9,
      "name": "Soil_Dirt"
    },
    {
      "x": -14,
      "y": 17,
      "z": -9,
      "name": "Soil_Grass"
    },
    {
      "x": -14,
      "y": 0,
      "z": -8,
      "name": "Rock_Stone"
    },
    {
      "x": -14,
      "y": 1,
      "z": -8,
      "name": "Rock_Stone"
    },
    {
      "x": -14,
      "y": 2,
      "z": -8,
      "name": "Rock_Stone"
    },
    {
      "x": -14,
      "y": 3,
      "z": -8,
      "name": "Rock_Stone"
    },
    {
      "x": -14,
      "y": 4,
      "z": -8,
      "name": "Rock_Stone"
    },
    {
      "x": -14,
      "y": 5,
      "z": -8,
      "name": "Rock_Stone"
    },
    {
      "x": -14,
      "y": 6,
      "z": -8,
      "name": "Rock_Stone"
    },
    {
      "x": -14,
      "y": 7,
      "z": -8,
      "name": "Rock_Stone"
    },
    {
      "x": -14,
      "y": 8,
      "z": -8,
      "name": "Rock_Stone"
    },
    {
      "x": -14,
      "y": 9,
      "z": -8,
      "name": "Rock_Stone"
    },
    {
      "x": -14,
      "y": 10,
      "z": -8,
      "name": "Rock_Stone"
    },
    {
      "x": -14,
      "y": 11,
      "z": -8,
      "name": "Rock_Stone"
    },
    {
      "x": -14,
      "y": 12,
      "z": -8,
      "name": "Rock_Stone"
    },
    {
      "x": -14,
      "y": 13,
      "z": -8,
      "name": "Rock_Stone"
    },
    {
      "x": -14,
      "y": 14,
      "z": -8,
      "name": "Rock_Stone"
    },
    {
      "x": -14,
      "y": 15,
      "z": -8,
      "name": "Rock_Stone"
    },
    {
      "x": -14,
      "y": 16,
      "z": -8,
      "name": "Soil_Dirt"
    },
    {
      "x": -14,
      "y": 17,
      "z": -8,
      "name": "Soil_Grass"
    },
    {
      "x": -14,
      "y": 18,
      "z": -8,
      "name": "Plant_Grass_Sharp"
    },
    {
      "x": -14,
      "y": 0,
      "z": -7,
      "name": "Rock_Stone"
    },
    {
      "x": -14,
      "y": 1,
      "z": -7,
      "name": "Rock_Stone"
    },
    {
      "x": -14,
      "y": 2,
      "z": -7,
      "name": "Rock_Stone"
    },
    {
      "x": -14,
      "y": 3,
      "z": -7,
      "name": "Rock_Stone"
    },
    {
      "x": -14,
      "y": 4,
      "z": -7,
      "name": "Rock_Stone"
    },
    {
      "x": -14,
      "y": 5,
      "z": -7,
      "name": "Rock_Stone"
    },
    {
      "x": -14,
      "y": 6,
      "z": -7,
      "name": "Rock_Stone"
    },
    {
      "x": -14,
      "y": 7,
      "z": -7,
      "name": "Rock_Stone"
    },
    {
      "x": -14,
      "y": 8,
      "z": -7,
      "name": "Rock_Stone"
    },
    {
      "x": -14,
      "y": 9,
      "z": -7,
      "name": "Rock_Stone"
    },
    {
      "x": -14,
      "y": 10,
      "z": -7,
      "name": "Rock_Stone"
    },
    {
      "x": -14,
      "y": 11,
      "z": -7,
      "name": "Rock_Stone"
    },
    {
      "x": -14,
      "y": 12,
      "z": -7,
      "name": "Rock_Stone"
    },
    {
      "x": -14,
      "y": 13,
      "z": -7,
      "name": "Rock_Stone"
    },
    {
      "x": -14,
      "y": 14,
      "z": -7,
      "name": "Rock_Stone"
    },
    {
      "x": -14,
      "y": 15,
      "z": -7,
      "name": "Rock_Stone"
    },
    {
      "x": -14,
      "y": 16,
      "z": -7,
      "name": "Rock_Stone"
    },
    {
      "x": -14,
      "y": 17,
      "z": -7,
      "name": "Soil_Grass"
    },
    {
      "x": -14,
      "y": 18,
      "z": -7,
      "name": "Soil_Grass"
    },
    {
      "x": -14,
      "y": 0,
      "z": -6,
      "name": "Rock_Stone"
    },
    {
      "x": -14,
      "y": 1,
      "z": -6,
      "name": "Rock_Stone"
    },
    {
      "x": -14,
      "y": 2,
      "z": -6,
      "name": "Rock_Stone"
    },
    {
      "x": -14,
      "y": 3,
      "z": -6,
      "name": "Rock_Stone"
    },
    {
      "x": -14,
      "y": 4,
      "z": -6,
      "name": "Rock_Stone"
    },
    {
      "x": -14,
      "y": 5,
      "z": -6,
      "name": "Rock_Stone"
    },
    {
      "x": -14,
      "y": 6,
      "z": -6,
      "name": "Rock_Stone"
    },
    {
      "x": -14,
      "y": 7,
      "z": -6,
