{
  "version": 8,
  "blockIdVersion": 8,
  "anchorX": 21,
  "anchorY": 20,
  "anchorZ": 24,
  "blocks": [
    {
      "x": 2,
      "y": 28,
      "z": 27,
      "name": "Rock_Stone"
    },
    {
      "x": 2,
      "y": 26,
      "z": 28,
      "name": "Rock_Stone"
    },
    {
      "x": 2,
      "y": 27,
      "z": 28,
      "name": "Rock_Stone"
    },
    {
      "x": 2,
      "y": 28,
      "z": 28,
      "name": "Rock_Stone"
    },
    {
      "x": 2,
      "y": 29,
      "z": 28,
      "name": "Rock_Stone"
    },
    {
      "x": 2,
      "y": 30,
      "z": 28,
      "name": "Soil_Grass_Deep"
    },
    {
      "x": 2,
      "y": 26,
      "z": 29,
      "name": "Rock_Stone"
    },
    {
      "x": 2,
      "y": 27,
      "z": 29,
      "name": "Rock_Stone"
    },
    {
      "x": 2,
      "y": 28,
      "z": 29,
      "name": "Rock_Stone"
    },
    {
      "x": 2,
      "y": 29,
      "z": 29,
      "name": "Soil_Dirt"
    },
    {
      "x": 2,
      "y": 30,
      "z": 29,
      "name": "Soil_Grass_Deep"
    },
    {
      "x": 2,
      "y": 31,
      "z": 29,
      "name": "Plant_Grass_Sharp"
    },
    {
      "x": 2,
      "y": 27,
      "z": 30,
      "name": "Rock_Stone"
    },
    {
      "x": 2,
      "y": 28,
      "z": 30,
      "name": "Rock_Stone"
    },
    {
      "x": 2,
      "y": 29,
      "z": 30,
      "name": "Soil_Dirt"
    },
    {
      "x": 3,
      "y": 27,
      "z": 27,
      "name": "Rock_Stone"
    },
    {
      "x": 3,
      "y": 28,
      "z": 27,
      "name": "Rock_Stone"
    },
    {
      "x": 3,
      "y": 29,
      "z": 27,
      "name": "Rock_Stone"
    },
    {
      "x": 3,
      "y": 30,
      "z": 27,
      "name": "Rock_Stone"
    },
    {
      "x": 3,
      "y": 31,
      "z": 27,
      "name": "Soil_Grass_Deep"
    },
    {
      "x": 3,
      "y": 24,
      "z": 28,
      "name": "Rock_Stone"
    },
    {
      "x": 3,
      "y": 25,
      "z": 28,
      "name": "Rock_Stone"
    },
    {
      "x": 3,
      "y": 26,
      "z": 28,
      "name": "Rock_Stone"
    },
    {
      "x": 3,
      "y": 27,
      "z": 28,
      "name": "Rock_Stone"
    },
    {
      "x": 3,
      "y": 28,
      "z": 28,
      "name": "Rock_Stone"
    },
    {
      "x": 3,
      "y": 29,
      "z": 28,
      "name": "Rock_Stone"
    },
    {
      "x": 3,
      "y": 30,
      "z": 28,
      "name": "Soil_Dirt"
    },
    {
      "x": 3,
      "y": 31,
      "z": 28,
      "name": "Soil_Dirt"
    },
    {
      "x": 3,
      "y": 32,
      "z": 28,
      "name": "Soil_Grass_Deep"
    },
    {
      "x": 3,
      "y": 23,
      "z": 29,
      "name": "Rock_Stone"
    },
    {
      "x": 3,
      "y": 24,
      "z": 29,
      "name": "Rock_Stone"
    },
    {
      "x": 3,
      "y": 25,
      "z": 29,
      "name": "Rock_Stone"
    },
    {
      "x": 3,
      "y": 26,
      "z": 29,
      "name": "Rock_Stone"
    },
    {
      "x": 3,
      "y": 27,
      "z": 29,
      "name": "Rock_Stone"
    },
    {
      "x": 3,
      "y": 28,
      "z": 29,
      "name": "Rock_Stone"
    },
    {
      "x": 3,
      "y": 29,
      "z": 29,
      "name": "Soil_Dirt"
    },
    {
      "x": 3,
      "y": 30,
      "z": 29,
      "name": "Soil_Dirt"
    },
    {
      "x": 3,
      "y": 31,
      "z": 29,
      "name": "Soil_Dirt"
    },
    {
      "x": 3,
      "y": 32,
      "z": 29,
      "name": "Soil_Grass_Deep"
    },
    {
      "x": 3,
      "y": 33,
      "z": 29,
      "name": "Plant_Grass_Sharp"
    },
    {
      "x": 3,
      "y": 21,
      "z": 30,
      "name": "Rock_Stone"
    },
    {
      "x": 3,
      "y": 22,
      "z": 30,
      "name": "Rock_Stone"
    },
    {
      "x": 3,
      "y": 23,
      "z": 30,
      "name": "Rock_Stone"
    },
    {
      "x": 3,
      "y": 24,
      "z": 30,
      "name": "Rock_Stone"
    },
    {
      "x": 3,
      "y": 25,
      "z": 30,
      "name": "Rock_Stone"
    },
    {
      "x": 3,
      "y": 26,
      "z": 30,
      "name": "Rock_Stone"
    },
    {
      "x": 3,
      "y": 27,
      "z": 30,
      "name": "Rock_Stone"
    },
    {
      "x": 3,
      "y": 28,
      "z": 30,
      "name": "Rock_Stone"
    },
    {
      "x": 3,
      "y": 29,
      "z": 30,
      "name": "Soil_Dirt"
    },
    {
      "x": 3,
      "y": 30,
      "z": 30,
      "name": "Soil_Dirt"
    },
    {
      "x": 3,
      "y": 31,
      "z": 30,
      "name": "Soil_Grass_Deep"
    },
    {
      "x": 3,
      "y": 32,
      "z": 30,
      "name": "Plant_Grass_Lush"
    },
    {
      "x": 3,
      "y": 21,
      "z": 31,
      "name": "Rock_Stone"
    },
    {
      "x": 3,
      "y": 22,
      "z": 31,
      "name": "Rock_Stone"
    },
    {
      "x": 3,
      "y": 23,
      "z": 31,
      "name": "Rock_Stone"
    },
    {
      "x": 3,
      "y": 24,
      "z": 31,
      "name": "Rock_Stone"
    },
    {
      "x": 3,
      "y": 25,
      "z": 31,
      "name": "Rock_Stone"
    },
    {
      "x": 3,
      "y": 26,
      "z": 31,
      "name": "Rock_Stone"
    },
    {
      "x": 3,
      "y": 27,
      "z": 31,
      "name": "Rock_Stone"
    },
    {
      "x": 3,
      "y": 28,
      "z": 31,
      "name": "Soil_Dirt"
    },
    {
      "x": 3,
      "y": 29,
      "z": 31,
      "name": "Soil_Dirt"
    },
    {
      "x": 3,
      "y": 30,
      "z": 31,
      "name": "Soil_Grass_Deep"
    },
    {
      "x": 3,
      "y": 22,
      "z": 32,
      "name": "Rock_Stone"
    },
    {
      "x": 3,
      "y": 23,
      "z": 32,
      "name": "Rock_Stone"
    },
    {
      "x": 3,
      "y": 24,
      "z": 32,
      "name": "Rock_Stone"
    },
    {
      "x": 4,
      "y": 29,
      "z": 26,
      "name": "Rock_Stone"
    },
    {
      "x": 4,
      "y": 30,
      "z": 26,
      "name": "Rock_Stone"
    },
    {
      "x": 4,
      "y": 31,
      "z": 26,
      "name": "Soil_Grass_Deep"
    },
    {
      "x": 4,
      "y": 25,
      "z": 27,
      "name": "Rock_Stone"
    },
    {
      "x": 4,
      "y": 26,
      "z": 27,
      "name": "Rock_Stone"
    },
    {
      "x": 4,
      "y": 27,
      "z": 27,
      "name": "Rock_Stone"
    },
    {
      "x": 4,
      "y": 28,
      "z": 27,
      "name": "Rock_Stone"
    },
    {
      "x": 4,
      "y": 29,
      "z": 27,
      "name": "Rock_Stone"
    },
    {
      "x": 4,
      "y": 30,
      "z": 27,
      "name": "Rock_Stone"
    },
    {
      "x": 4,
      "y": 31,
      "z": 27,
      "name": "Rock_Stone"
    },
    {
      "x": 4,
      "y": 32,
      "z": 27,
      "name": "Soil_Grass_Deep"
    },
    {
      "x": 4,
      "y": 33,
      "z": 27,
      "name": "Plant_Grass_Lush"
    },
    {
      "x": 4,
      "y": 22,
      "z": 28,
      "name": "Rock_Stone"
    },
    {
      "x": 4,
      "y": 23,
      "z": 28,
      "name": "Rock_Stone"
    },
    {
      "x": 4,
      "y": 24,
      "z": 28,
      "name": "Rock_Stone"
    },
    {
      "x": 4,
      "y": 25,
      "z": 28,
      "name": "Rock_Stone"
    },
    {
      "x": 4,
      "y": 26,
      "z": 28,
      "name": "Rock_Stone"
    },
    {
      "x": 4,
      "y": 27,
      "z": 28,
      "name": "Rock_Stone"
    },
    {
      "x": 4,
      "y": 28,
      "z": 28,
      "name": "Rock_Stone"
    },
    {
      "x": 4,
      "y": 29,
      "z": 28,
      "name": "Rock_Stone"
    },
    {
      "x": 4,
      "y": 30,
      "z": 28,
      "name": "Soil_Dirt"
    },
    {
      "x": 4,
      "y": 31,
      "z": 28,
      "name": "Soil_Dirt"
    },
    {
      "x": 4,
      "y": 32,
      "z": 28,
      "name": "Soil_Grass_Deep"
    },
    {
      "x": 4,
      "y": 33,
      "z": 28,
      "name": "Plant_Grass_Lush"
    },
    {
      "x": 4,
      "y": 22,
      "z": 29,
      "name": "Rock_Stone"
    },
    {
      "x": 4,
      "y": 23,
      "z": 29,
      "name": "Rock_Stone"
    },
    {
      "x": 4,
      "y": 24,
      "z": 29,
      "name": "Rock_Stone"
    },
    {
      "x": 4,
      "y": 25,
      "z": 29,
      "name": "Rock_Stone"
    },
    {
      "x": 4,
      "y": 26,
      "z": 29,
      "name": "Rock_Stone"
    },
    {
      "x": 4,
      "y": 27,
      "z": 29,
      "name": "Rock_Stone"
    },
    {
      "x": 4,
      "y": 28,
      "z": 29,
      "name": "Rock_Stone"
    },
    {
      "x": 4,
      "y": 29,
      "z": 29,
      "name": "Soil_Dirt"
    },
    {
      "x": 4,
      "y": 30,
      "z": 29,
      "name": "Soil_Dirt"
    },
    {
      "x": 4,
      "y": 31,
      "z": 29,
      "name": "Soil_Dirt"
    },
    {
      "x": 4,
      "y": 32,
      "z": 29,
      "name": "Soil_Grass_Deep"
    },
    {
      "x": 4,
      "y": 33,
      "z": 29,
      "name": "Plant_Grass_Sharp"
    },
    {
      "x": 4,
      "y": 20,
      "z": 30,
      "name": "Rock_Stone"
    },
    {
      "x": 4,
      "y": 21,
      "z": 30,
      "name": "Rock_Stone"
    },
    {
      "x": 4,
      "y": 22,
      "z": 30,
      "name": "Rock_Stone"
    },
    {
      "x": 4,
      "y": 23,
      "z": 30,
      "name": "Rock_Stone"
    },
    {
      "x": 4,
      "y": 24,
      "z": 30,
      "name": "Rock_Stone"
    },
    {
      "x": 4,
      "y": 25,
      "z": 30,
      "name": "Rock_Stone"
    },
    {
      "x": 4,
      "y": 26,
      "z": 30,
      "name": "Rock_Stone"
    },
    {
      "x": 4,
      "y": 27,
      "z": 30,
      "name": "Rock_Stone"
    },
    {
      "x": 4,
      "y": 28,
      "z": 30,
      "name": "Rock_Stone"
    },
    {
      "x": 4,
      "y": 29,
      "z": 30,
      "name": "Soil_Dirt"
    },
    {
      "x": 4,
      "y": 30,
      "z": 30,
      "name": "Soil_Dirt"
    },
    {
      "x": 4,
      "y": 31,
      "z": 30,
      "name": "Soil_Dirt"
    },
    {
      "x": 4,
      "y": 32,
      "z": 30,
      "name": "Soil_Grass_Deep"
    },
    {
      "x": 4,
      "y": 20,
      "z": 31,
      "name": "Rock_Stone"
    },
    {
      "x": 4,
      "y": 21,
      "z": 31,
      "name": "Rock_Stone"
    },
    {
      "x": 4,
      "y": 22,
      "z": 31,
      "name": "Rock_Stone"
    },
    {
      "x": 4,
      "y": 23,
      "z": 31,
      "name": "Rock_Stone"
    },
    {
      "x": 4,
      "y": 24,
      "z": 31,
      "name": "Rock_Stone"
    },
    {
      "x": 4,
      "y": 25,
      "z": 31,
      "name": "Rock_Stone"
    },
    {
      "x": 4,
      "y": 26,
      "z": 31,
      "name": "Rock_Stone"
    },
    {
      "x": 4,
      "y": 27,
      "z": 31,
      "name": "Rock_Stone"
    },
    {
      "x": 4,
      "y": 28,
      "z": 31,
      "name": "Rock_Stone"
    },
    {
      "x": 4,
      "y": 29,
      "z": 31,
      "name": "Soil_Dirt"
    },
    {
      "x": 4,
      "y": 30,
      "z": 31,
      "name": "Soil_Grass_Deep"
    },
    {
      "x": 4,
      "y": 21,
      "z": 32,
      "name": "Rock_Stone"
    },
    {
      "x": 4,
      "y": 22,
      "z": 32,
      "name": "Rock_Stone"
    },
    {
      "x": 4,
      "y": 23,
      "z": 32,
      "name": "Rock_Stone"
    },
    {
      "x": 4,
      "y": 24,
      "z": 32,
      "name": "Rock_Stone"
    },
    {
      "x": 4,
      "y": 25,
      "z": 32,
      "name": "Rock_Stone"
    },
    {
      "x": 5,
      "y": 29,
      "z": 26,
      "name": "Rock_Stone"
    },
    {
      "x": 5,
      "y": 30,
      "z": 26,
      "name": "Rock_Stone"
    },
    {
      "x": 5,
      "y": 31,
      "z": 26,
      "name": "Rock_Stone"
    },
    {
      "x": 5,
      "y": 32,
      "z": 26,
      "name": "Soil_Dirt"
    },
    {
      "x": 5,
      "y": 33,
      "z": 26,
      "name": "Soil_Grass_Deep"
    },
    {
      "x": 5,
      "y": 34,
      "z": 26,
      "name": "Plant_Grass_Sharp"
    },
    {
      "x": 5,
      "y": 26,
      "z": 27,
      "name": "Rock_Stone"
    },
    {
      "x": 5,
      "y": 27,
      "z": 27,
      "name": "Rock_Stone"
    },
    {
      "x": 5,
      "y": 28,
      "z": 27,
      "name": "Rock_Stone"
    },
    {
      "x": 5,
      "y": 29,
      "z": 27,
      "name": "Rock_Stone"
    },
    {
      "x": 5,
      "y": 30,
      "z": 27,
      "name": "Rock_Stone"
    },
    {
      "x": 5,
      "y": 31,
      "z": 27,
      "name": "Soil_Dirt"
    },
    {
      "x": 5,
      "y": 32,
      "z": 27,
      "name": "Soil_Dirt"
    },
    {
      "x": 5,
      "y": 33,
      "z": 27,
      "name": "Soil_Grass_Deep"
    },
    {
      "x": 5,
      "y": 22,
      "z": 28,
      "name": "Rock_Stone"
    },
    {
      "x": 5,
      "y": 23,
      "z": 28,
      "name": "Rock_Stone"
    },
    {
      "x": 5,
      "y": 24,
      "z": 28,
      "name": "Rock_Stone"
    },
    {
      "x": 5,
      "y": 25,
      "z": 28,
      "name": "Rock_Stone"
    },
    {
      "x": 5,
      "y": 26,
      "z": 28,
      "name": "Rock_Stone"
    },
    {
      "x": 5,
      "y": 27,
      "z": 28,
      "name": "Rock_Stone"
    },
    {
      "x": 5,
      "y": 28,
      "z": 28,
      "name": "Rock_Stone"
    },
    {
      "x": 5,
      "y": 29,
      "z": 28,
      "name": "Rock_Stone"
    },
    {
      "x": 5,
      "y": 30,
      "z": 28,
      "name": "Rock_Stone"
    },
    {
      "x": 5,
      "y": 31,
      "z": 28,
      "name": "Soil_Dirt"
    },
    {
      "x": 5,
      "y": 32,
      "z": 28,
      "name": "Soil_Dirt"
    },
    {
      "x": 5,
      "y": 33,
      "z": 28,
      "name": "Soil_Dirt"
    },
    {
      "x": 5,
      "y": 34,
      "z": 28,
      "name": "Soil_Grass_Deep"
    },
    {
      "x": 5,
      "y": 35,
      "z": 28,
      "name": "Plant_Grass_Sharp"
    },
    {
      "x": 5,
      "y": 21,
      "z": 29,
      "name": "Rock_Stone"
    },
    {
      "x": 5,
      "y": 22,
      "z": 29,
      "name": "Rock_Stone"
    },
    {
      "x": 5,
      "y": 23,
      "z": 29,
      "name": "Rock_Stone"
    },
    {
      "x": 5,
      "y": 24,
      "z": 29,
      "name": "Rock_Stone"
    },
    {
      "x": 5,
      "y": 25,
      "z": 29,
      "name": "Rock_Stone"
    },
    {
      "x": 5,
      "y": 26,
      "z": 29,
      "name": "Rock_Stone"
    },
    {
      "x": 5,
      "y": 27,
      "z": 29,
      "name": "Rock_Stone"
    },
    {
      "x": 5,
      "y": 28,
      "z": 29,
      "name": "Rock_Stone"
    },
    {
      "x": 5,
      "y": 29,
      "z": 29,
      "name": "Rock_Stone"
    },
    {
      "x": 5,
      "y": 30,
      "z": 29,
      "name": "Soil_Dirt"
    },
    {
      "x": 5,
      "y": 31,
      "z": 29,
      "name": "Soil_Dirt"
    },
    {
      "x": 5,
      "y": 32,
      "z": 29,
      "name": "Soil_Dirt"
    },
    {
      "x": 5,
      "y": 33,
      "z": 29,
      "name": "Soil_Dirt"
    },
    {
      "x": 5,
      "y": 34,
      "z": 29,
      "name": "Soil_Grass_Deep"
    },
    {
      "x": 5,
      "y": 20,
      "z": 30,
      "name": "Rock_Stone"
    },
    {
      "x": 5,
      "y": 21,
      "z": 30,
      "name": "Rock_Stone"
    },
    {
      "x": 5,
      "y": 22,
      "z": 30,
      "name": "Rock_Stone"
    },
    {
      "x": 5,
      "y": 23,
      "z": 30,
      "name": "Rock_Stone"
    },
    {
      "x": 5,
      "y": 24,
      "z": 30,
      "name": "Rock_Stone"
    },
    {
      "x": 5,
      "y": 25,
      "z": 30,
      "name": "Rock_Stone"
    },
    {
      "x": 5,
      "y": 26,
      "z": 30,
      "name": "Rock_Stone"
    },
    {
      "x": 5,
      "y": 27,
      "z": 30,
      "name": "Rock_Stone"
    },
    {
      "x": 5,
      "y": 28,
      "z": 30,
      "name": "Rock_Stone"
    },
    {
      "x": 5,
      "y": 29,
      "z": 30,
      "name": "Soil_Dirt"
    },
    {
      "x": 5,
      "y": 30,
      "z": 30,
      "name": "Soil_Dirt"
    },
    {
      "x": 5,
      "y": 31,
      "z": 30,
      "name": "Soil_Dirt"
    },
    {
      "x": 5,
      "y": 32,
      "z": 30,
      "name": "Soil_Dirt"
    },
    {
      "x": 5,
      "y": 33,
      "z": 30,
      "name": "Soil_Grass_Deep"
    },
    {
      "x": 5,
      "y": 19,
      "z": 31,
      "name": "Rock_Stone"
    },
    {
      "x": 5,
      "y": 20,
      "z": 31,
      "name": "Rock_Stone"
    },
    {
      "x": 5,
      "y": 21,
      "z": 31,
      "name": "Rock_Stone"
    },
    {
      "x": 5,
      "y": 22,
      "z": 31,
      "name": "Rock_Stone"
    },
    {
      "x": 5,
      "y": 23,
      "z": 31,
      "name": "Rock_Stone"
    },
    {
      "x": 5,
      "y": 24,
      "z": 31,
      "name": "Rock_Stone"
    },
    {
      "x": 5,
      "y": 25,
      "z": 31,
      "name": "Rock_Stone"
    },
    {
      "x": 5,
      "y": 26,
      "z": 31,
      "name": "Rock_Stone"
    },
    {
      "x": 5,
      "y": 27,
      "z": 31,
      "name": "Rock_Stone"
    },
    {
      "x": 5,
      "y": 28,
      "z": 31,
      "name": "Rock_Stone"
    },
    {
      "x": 5,
      "y": 29,
      "z": 31,
      "name": "Soil_Dirt"
    },
    {
      "x": 5,
      "y": 30,
      "z": 31,
      "name": "Soil_Dirt"
    },
    {
      "x": 5,
      "y": 31,
      "z": 31,
      "name": "Soil_Grass_Deep"
    },
    {
      "x": 5,
      "y": 32,
      "z": 31,
      "name": "Plant_Grass_Sharp"
    },
    {
      "x": 5,
      "y": 21,
      "z": 32,
      "name": "Rock_Stone"
    },
    {
      "x": 5,
      "y": 22,
      "z": 32,
      "name": "Rock_Stone"
    },
    {
      "x": 5,
      "y": 23,
      "z": 32,
      "name": "Rock_Stone"
    },
    {
      "x": 5,
      "y": 24,
      "z": 32,
      "name": "Rock_Stone"
    },
    {
      "x": 5,
      "y": 25,
      "z": 32,
      "name": "Rock_Stone"
    },
    {
      "x": 6,
      "y": 33,
      "z": 25,
      "name": "Soil_Dirt"
    },
    {
      "x": 6,
      "y": 34,
      "z": 25,
      "name": "Soil_Grass_Deep"
    },
    {
      "x": 6,
      "y": 30,
      "z": 26,
      "name": "Rock_Stone"
    },
    {
      "x": 6,
      "y": 31,
      "z": 26,
      "name": "Rock_Stone"
    },
    {
      "x": 6,
      "y": 32,
      "z": 26,
      "name": "Soil_Dirt"
    },
    {
      "x": 6,
      "y": 33,
      "z": 26,
      "name": "Soil_Dirt"
    },
    {
      "x": 6,
      "y": 34,
      "z": 26,
      "name": "Soil_Dirt"
    },
    {
      "x": 6,
      "y": 35,
      "z": 26,
      "name": "Soil_Grass_Deep"
    },
    {
      "x": 6,
      "y": 36,
      "z": 26,
      "name": "Plant_Grass_Sharp"
    },
    {
      "x": 6,
      "y": 26,
      "z": 27,
      "name": "Rock_Stone"
    },
    {
      "x": 6,
      "y": 27,
      "z": 27,
      "name": "Rock_Stone"
    },
    {
      "x": 6,
      "y": 28,
      "z": 27,
      "name": "Rock_Stone"
    },
    {
      "x": 6,
      "y": 29,
      "z": 27,
      "name": "Rock_Stone"
    },
    {
      "x": 6,
      "y": 30,
      "z": 27,
      "name": "Rock_Stone"
    },
    {
      "x": 6,
      "y": 31,
      "z": 27,
      "name": "Rock_Stone"
    },
    {
      "x": 6,
      "y": 32,
      "z": 27,
      "name": "Soil_Dirt"
    },
    {
      "x": 6,
      "y": 33,
      "z": 27,
      "name": "Soil_Dirt"
    },
    {
      "x": 6,
      "y": 34,
      "z": 27,
      "name": "Soil_Dirt"
    },
    {
      "x": 6,
      "y": 35,
      "z": 27,
      "name": "Soil_Grass_Deep"
    },
    {
      "x": 6,
      "y": 21,
      "z": 28,
      "name": "Rock_Stone"
    },
    {
      "x": 6,
      "y": 22,
      "z": 28,
      "name": "Rock_Stone"
    },
    {
      "x": 6,
      "y": 23,
      "z": 28,
      "name": "Rock_Stone"
    },
    {
      "x": 6,
      "y": 24,
      "z": 28,
      "name": "Rock_Stone"
    },
    {
      "x": 6,
      "y": 25,
      "z": 28,
      "name": "Rock_Stone"
    },
    {
      "x": 6,
      "y": 26,
      "z": 28,
      "name": "Rock_Stone"
    },
    {
      "x": 6,
      "y": 27,
      "z": 28,
      "name": "Rock_Stone"
    },
    {
      "x": 6,
      "y": 28,
      "z": 28,
      "name": "Rock_Stone"
    },
    {
      "x": 6,
      "y": 29,
      "z": 28,
      "name": "Rock_Stone"
    },
    {
      "x": 6,
      "y": 30,
      "z": 28,
      "name": "Rock_Stone"
    },
    {
      "x": 6,
      "y": 31,
      "z": 28,
      "name": "Rock_Stone"
    },
    {
      "x": 6,
      "y": 32,
      "z": 28,
      "name": "Soil_Dirt"
    },
    {
      "x": 6,
      "y": 33,
      "z": 28,
      "name": "Soil_Dirt"
    },
    {
      "x": 6,
      "y": 34,
      "z": 28,
      "name": "Soil_Grass_Deep"
    },
    {
      "x": 6,
      "y": 19,
      "z": 29,
      "name": "Rock_Stone"
    },
    {
      "x": 6,
      "y": 20,
      "z": 29,
      "name": "Rock_Stone"
    },
    {
      "x": 6,
      "y": 21,
      "z": 29,
      "name": "Rock_Stone"
    },
    {
      "x": 6,
      "y": 22,
      "z": 29,
      "name": "Rock_Stone"
    },
    {
      "x": 6,
      "y": 23,
      "z": 29,
      "name": "Rock_Stone"
    },
    {
      "x": 6,
      "y": 24,
      "z": 29,
      "name": "Rock_Stone"
    },
    {
      "x": 6,
      "y": 25,
      "z": 29,
      "name": "Rock_Stone"
    },
    {
      "x": 6,
      "y": 26,
      "z": 29,
      "name": "Rock_Stone"
    },
    {
      "x": 6,
      "y": 27,
      "z": 29,
      "name": "Rock_Stone"
    },
    {
      "x": 6,
      "y": 28,
      "z": 29,
      "name": "Rock_Stone"
    },
    {
      "x": 6,
      "y": 29,
      "z": 29,
      "name": "Rock_Stone"
    },
    {
      "x": 6,
      "y": 30,
      "z": 29,
      "name": "Rock_Stone"
    },
    {
      "x": 6,
      "y": 31,
      "z": 29,
      "name": "Soil_Dirt"
    },
    {
      "x": 6,
      "y": 32,
      "z": 29,
      "name": "Soil_Dirt"
    },
    {
      "x": 6,
      "y": 33,
      "z": 29,
      "name": "Soil_Dirt"
    },
    {
      "x": 6,
      "y": 34,
      "z": 29,
      "name": "Soil_Dirt"
    },
    {
      "x": 6,
      "y": 35,
      "z": 29,
      "name": "Soil_Grass_Deep"
    },
    {
      "x": 6,
      "y": 18,
      "z": 30,
      "name": "Rock_Stone"
    },
    {
      "x": 6,
      "y": 19,
      "z": 30,
      "name": "Rock_Stone"
    },
    {
      "x": 6,
      "y": 20,
      "z": 30,
      "name": "Rock_Stone"
    },
    {
      "x": 6,
      "y": 21,
      "z": 30,
      "name": "Rock_Stone"
    },
    {
      "x": 6,
      "y": 22,
      "z": 30,
      "name": "Rock_Stone"
    },
    {
      "x": 6,
      "y": 23,
      "z": 30,
      "name": "Rock_Stone"
    },
    {
      "x": 6,
      "y": 24,
      "z": 30,
      "name": "Rock_Stone"
    },
    {
      "x": 6,
      "y": 25,
      "z": 30,
      "name": "Rock_Stone"
    },
    {
      "x": 6,
      "y": 26,
      "z": 30,
      "name": "Rock_Stone"
    },
    {
      "x": 6,
      "y": 27,
      "z": 30,
      "name": "Rock_Stone"
    },
    {
      "x": 6,
      "y": 28,
      "z": 30,
      "name": "Rock_Stone"
    },
    {
      "x": 6,
      "y": 29,
      "z": 30,
      "name": "Rock_Stone"
    },
    {
      "x": 6,
      "y": 30,
      "z": 30,
      "name": "Rock_Stone"
    },
    {
      "x": 6,
      "y": 31,
      "z": 30,
      "name": "Soil_Dirt"
    },
    {
      "x": 6,
      "y": 32,
      "z": 30,
      "name": "Soil_Dirt"
    },
    {
      "x": 6,
      "y": 33,
      "z": 30,
      "name": "Soil_Dirt"
    },
    {
      "x": 6,
      "y": 34,
      "z": 30,
      "name": "Soil_Dirt"
    },
    {
      "x": 6,
      "y": 35,
      "z": 30,
      "name": "Soil_Grass_Deep"
    },
    {
      "x": 6,
      "y": 18,
      "z": 31,
      "name": "Rock_Stone"
    },
    {
      "x": 6,
      "y": 19,
      "z": 31,
      "name": "Rock_Stone"
    },
    {
      "x": 6,
      "y": 20,
      "z": 31,
      "name": "Rock_Stone"
    },
    {
      "x": 6,
      "y": 21,
      "z": 31,
      "name": "Rock_Stone"
    },
    {
      "x": 6,
      "y": 22,
      "z": 31,
      "name": "Rock_Stone"
    },
    {
      "x": 6,
      "y": 23,
      "z": 31,
      "name": "Rock_Stone"
    },
    {
      "x": 6,
      "y": 24,
      "z": 31,
      "name": "Rock_Stone"
    },
    {
      "x": 6,
      "y": 25,
      "z": 31,
      "name": "Rock_Stone"
    },
    {
      "x": 6,
      "y": 26,
      "z": 31,
      "name": "Rock_Stone"
    },
    {
      "x": 6,
      "y": 30,
      "z": 31,
      "name": "Soil_Dirt"
    },
    {
      "x": 6,
      "y": 31,
      "z": 31,
      "name": "Soil_Dirt"
    },
    {
      "x": 6,
      "y": 32,
      "z": 31,
      "name": "Soil_Dirt"
    },
    {
      "x": 6,
      "y": 33,
      "z": 31,
      "name": "Soil_Dirt"
    },
    {
      "x": 6,
      "y": 34,
      "z": 31,
      "name": "Soil_Grass_Deep"
    },
    {
      "x": 6,
      "y": 18,
      "z": 32,
      "name": "Rock_Stone"
    },
    {
      "x": 6,
      "y": 19,
      "z": 32,
      "name": "Rock_Stone"
    },
    {
      "x": 6,
      "y": 20,
      "z": 32,
      "name": "Rock_Stone"
    },
    {
      "x": 6,
      "y": 21,
      "z": 32,
      "name": "Rock_Stone"
    },
    {
      "x": 6,
      "y": 22,
      "z": 32,
      "name": "Rock_Stone"
    },
    {
      "x": 6,
      "y": 23,
      "z": 32,
      "name": "Rock_Stone"
    },
    {
      "x": 7,
      "y": 31,
      "z": 25,
      "name": "Rock_Stone"
    },
    {
      "x": 7,
      "y": 32,
      "z": 25,
      "name": "Rock_Stone"
    },
    {
      "x": 7,
      "y": 33,
      "z": 25,
      "name": "Soil_Dirt"
    },
    {
      "x": 7,
      "y": 34,
      "z": 25,
      "name": "Soil_Dirt"
    },
    {
      "x": 7,
      "y": 35,
      "z": 25,
      "name": "Soil_Grass_Deep"
    },
    {
      "x": 7,
      "y": 30,
      "z": 26,
      "name": "Rock_Stone"
    },
    {
      "x": 7,
      "y": 31,
      "z": 26,
      "name": "Rock_Stone"
    },
    {
      "x": 7,
      "y": 32,
      "z": 26,
      "name": "Soil_Dirt"
    },
    {
      "x": 7,
      "y": 33,
      "z": 26,
      "name": "Soil_Dirt"
    },
    {
      "x": 7,
      "y": 34,
      "z": 26,
      "name": "Soil_Dirt"
    },
    {
      "x": 7,
      "y": 35,
      "z": 26,
      "name": "Soil_Grass_Deep"
    },
    {
      "x": 7,
      "y": 28,
      "z": 27,
      "name": "Rock_Stone"
    },
    {
      "x": 7,
      "y": 29,
      "z": 27,
      "name": "Rock_Stone"
    },
    {
      "x": 7,
      "y": 30,
      "z": 27,
      "name": "Rock_Stone"
    },
    {
      "x": 7,
      "y": 31,
      "z": 27,
      "name": "Rock_Stone"
    },
    {
      "x": 7,
      "y": 32,
      "z": 27,
      "name": "Soil_Dirt"
    },
    {
      "x": 7,
      "y": 33,
      "z": 27,
      "name": "Soil_Dirt"
    },
    {
      "x": 7,
      "y": 34,
      "z": 27,
      "name": "Soil_Dirt"
    },
    {
      "x": 7,
      "y": 35,
      "z": 27,
      "name": "Soil_Leaves"
    },
    {
      "x": 7,
      "y": 36,
      "z": 27,
      "name": "Plant_Grass_Sharp"
    },
    {
      "x": 7,
      "y": 23,
      "z": 28,
      "name": "Rock_Stone"
    },
    {
      "x": 7,
      "y": 24,
      "z": 28,
      "name": "Rock_Stone"
    },
    {
      "x": 7,
      "y": 25,
      "z": 28,
      "name": "Rock_Stone"
    },
    {
      "x": 7,
      "y": 26,
      "z": 28,
      "name": "Rock_Stone"
    },
    {
      "x": 7,
      "y": 27,
      "z": 28,
      "name": "Rock_Stone"
    },
    {
      "x": 7,
      "y": 28,
      "z": 28,
      "name": "Rock_Stone"
    },
    {
      "x": 7,
      "y": 29,
      "z": 28,
      "name": "Rock_Stone"
    },
    {
      "x": 7,
      "y": 30,
      "z": 28,
      "name": "Rock_Stone"
    },
    {
      "x": 7,
      "y": 31,
      "z": 28,
      "name": "Rock_Stone"
    },
    {
      "x": 7,
      "y": 32,
      "z": 28,
      "name": "Soil_Dirt"
    },
    {
      "x": 7,
      "y": 33,
      "z": 28,
      "name": "Soil_Dirt"
    },
    {
      "x": 7,
      "y": 34,
      "z": 28,
      "name": "Soil_Dirt"
    },
    {
      "x": 7,
      "y": 35,
      "z": 28,
      "name": "Soil_Leaves"
    },
    {
      "x": 7,
      "y": 18,
      "z": 29,
      "name": "Rock_Stone"
    },
    {
      "x": 7,
      "y": 19,
      "z": 29,
      "name": "Rock_Stone"
    },
    {
      "x": 7,
      "y": 20,
      "z": 29,
      "name": "Rock_Stone"
    },
    {
      "x": 7,
      "y": 21,
      "z": 29,
      "name": "Rock_Stone"
    },
    {
      "x": 7,
      "y": 22,
      "z": 29,
      "name": "Rock_Stone"
    },
    {
      "x": 7,
      "y": 23,
      "z": 29,
      "name": "Rock_Stone"
    },
    {
      "x": 7,
      "y": 24,
      "z": 29,
      "name": "Rock_Stone"
    },
    {
      "x": 7,
      "y": 25,
      "z": 29,
      "name": "Rock_Stone"
    },
    {
      "x": 7,
      "y": 26,
      "z": 29,
      "name": "Rock_Stone"
    },
    {
      "x": 7,
      "y": 27,
      "z": 29,
      "name": "Rock_Stone"
    },
    {
      "x": 7,
      "y": 28,
      "z": 29,
      "name": "Rock_Stone"
    },
    {
      "x": 7,
      "y": 29,
      "z": 29,
      "name": "Rock_Stone"
    },
    {
      "x": 7,
      "y": 30,
      "z": 29,
      "name": "Rock_Stone"
    },
    {
      "x": 7,
      "y": 31,
      "z": 29,
      "name": "Rock_Stone"
    },
    {
      "x": 7,
      "y": 32,
      "z": 29,
      "name": "Rock_Stone"
    },
    {
      "x": 7,
      "y": 33,
      "z": 29,
      "name": "Soil_Dirt"
    },
    {
      "x": 7,
      "y": 34,
      "z": 29,
      "name": "Soil_Dirt"
    },
    {
      "x": 7,
      "y": 35,
      "z": 29,
      "name": "Soil_Leaves"
    },
    {
      "x": 7,
      "y": 36,
      "z": 29,
      "name": "Plant_Grass_Lush"
    },
    {
      "x": 7,
      "y": 17,
      "z": 30,
      "name": "Rock_Stone"
    },
    {
      "x": 7,
      "y": 18,
      "z": 30,
      "name": "Rock_Stone"
    },
    {
      "x": 7,
      "y": 19,
      "z": 30,
      "name": "Rock_Stone"
    },
    {
      "x": 7,
      "y": 20,
      "z": 30,
      "name": "Rock_Stone"
    },
    {
      "x": 7,
      "y": 21,
      "z": 30,
      "name": "Rock_Stone"
    },
    {
      "x": 7,
      "y": 22,
      "z": 30,
      "name": "Rock_Stone"
    },
    {
      "x": 7,
      "y": 23,
      "z": 30,
      "name": "Rock_Stone"
    },
    {
      "x": 7,
      "y": 24,
      "z": 30,
      "name": "Rock_Stone"
    },
    {
      "x": 7,
      "y": 25,
      "z": 30,
      "name": "Rock_Stone"
    },
    {
      "x": 7,
      "y": 26,
      "z": 30,
      "name": "Rock_Stone"
    },
    {
      "x": 7,
      "y": 29,
      "z": 30,
      "name": "Rock_Stone"
    },
    {
      "x": 7,
      "y": 30,
      "z": 30,
      "name": "Rock_Stone"
    },
    {
      "x": 7,
      "y": 31,
      "z": 30,
      "name": "Rock_Stone"
    },
    {
      "x": 7,
      "y": 32,
      "z": 30,
      "name": "Soil_Dirt"
    },
    {
      "x": 7,
      "y": 33,
      "z": 30,
      "name": "Soil_Dirt"
    },
    {
      "x": 7,
      "y": 34,
      "z": 30,
      "name": "Soil_Dirt"
    },
    {
      "x": 7,
      "y": 35,
      "z": 30,
      "name": "Soil_Grass_Deep"
    },
    {
      "x": 7,
      "y": 36,
      "z": 30,
      "name": "Plant_Grass_Lush"
    },
    {
      "x": 7,
      "y": 16,
      "z": 31,
      "name": "Rock_Stone"
    },
    {
      "x": 7,
      "y": 17,
      "z": 31,
      "name": "Rock_Stone"
    },
    {
      "x": 7,
      "y": 18,
      "z": 31,
      "name": "Rock_Stone"
    },
    {
      "x": 7,
      "y": 19,
      "z": 31,
      "name": "Rock_Stone"
    },
    {
      "x": 7,
      "y": 20,
      "z": 31,
      "name": "Rock_Stone"
    },
    {
      "x": 7,
      "y": 21,
      "z": 31,
      "name": "Rock_Stone"
    },
    {
      "x": 7,
      "y": 22,
      "z": 31,
      "name": "Rock_Stone"
    },
    {
      "x": 7,
      "y": 23,
      "z": 31,
      "name": "Rock_Stone"
    },
    {
      "x": 7,
      "y": 24,
      "z": 31,
      "name": "Rock_Stone"
    },
    {
      "x": 7,
      "y": 25,
      "z": 31,
      "name": "Rock_Stone"
    },
    {
      "x": 7,
      "y": 31,
      "z": 31,
      "name": "Rock_Stone"
    },
    {
      "x": 7,
      "y": 32,
      "z": 31,
      "name": "Rock_Stone"
    },
    {
      "x": 7,
      "y": 33,
      "z": 31,
      "name": "Rock_Stone"
    },
    {
      "x": 7,
      "y": 34,
      "z": 31,
      "name": "Soil_Dirt"
    },
    {
      "x": 7,
      "y": 35,
      "z": 31,
      "name": "Soil_Grass_Deep"
    },
    {
      "x": 7,
      "y": 16,
      "z": 32,
      "name": "Rock_Stone"
    },
    {
      "x": 7,
      "y": 17,
      "z": 32,
      "name": "Rock_Stone"
    },
    {
      "x": 7,
      "y": 18,
      "z": 32,
      "name": "Rock_Stone"
    },
    {
      "x": 7,
      "y": 19,
      "z": 32,
      "name": "Rock_Stone"
    },
    {
      "x": 7,
      "y": 20,
      "z": 32,
      "name": "Rock_Stone"
    },
    {
      "x": 7,
      "y": 21,
      "z": 32,
      "name": "Rock_Stone"
    },
    {
      "x": 7,
      "y": 22,
      "z": 32,
      "name": "Rock_Stone"
    },
    {
      "x": 7,
      "y": 23,
      "z": 32,
      "name": "Rock_Stone"
    },
    {
      "x": 7,
      "y": 18,
      "z": 33,
      "name": "Rock_Stone"
    },
    {
      "x": 7,
      "y": 19,
      "z": 33,
      "name": "Rock_Stone"
    },
    {
      "x": 7,
      "y": 20,
      "z": 33,
      "name": "Rock_Stone"
    },
    {
      "x": 8,
      "y": 34,
      "z": 24,
      "name": "Soil_Dirt"
    },
    {
      "x": 8,
      "y": 35,
      "z": 24,
      "name": "Soil_Grass_Deep"
    },
    {
      "x": 8,
      "y": 31,
      "z": 25,
      "name": "Rock_Stone"
    },
    {
      "x": 8,
      "y": 32,
      "z": 25,
      "name": "Rock_Stone"
    },
    {
      "x": 8,
      "y": 33,
      "z": 25,
      "name": "Rock_Stone"
    },
    {
      "x": 8,
      "y": 34,
      "z": 25,
      "name": "Soil_Dirt"
    },
    {
      "x": 8,
      "y": 35,
      "z": 25,
      "name": "Soil_Dirt"
    },
    {
      "x": 8,
      "y": 36,
      "z": 25,
      "name": "Soil_Grass_Deep"
    },
    {
      "x": 8,
      "y": 31,
      "z": 26,
      "name": "Rock_Stone"
    },
    {
      "x": 8,
      "y": 32,
      "z": 26,
      "name": "Rock_Stone"
    },
    {
      "x": 8,
      "y": 33,
      "z": 26,
      "name": "Rock_Stone"
    },
    {
      "x": 8,
      "y": 34,
      "z": 26,
      "name": "Soil_Dirt"
    },
    {
      "x": 8,
      "y": 35,
      "z": 26,
      "name": "Soil_Dirt"
    },
    {
      "x": 8,
      "y": 36,
      "z": 26,
      "name": "Soil_Grass_Deep"
    },
    {
      "x": 8,
      "y": 37,
      "z": 26,
      "name": "Plant_Grass_Sharp"
    },
    {
      "x": 8,
      "y": 30,
      "z": 27,
      "name": "Rock_Stone"
    },
    {
      "x": 8,
      "y": 31,
      "z": 27,
      "name": "Rock_Stone"
    },
    {
      "x": 8,
      "y": 32,
      "z": 27,
      "name": "Rock_Stone"
    },
    {
      "x": 8,
      "y": 33,
      "z": 27,
      "name": "Soil_Dirt"
    },
    {
      "x": 8,
      "y": 34,
      "z": 27,
      "name": "Soil_Dirt"
    },
    {
      "x": 8,
      "y": 35,
      "z": 27,
      "name": "Soil_Dirt"
    },
    {
      "x": 8,
      "y": 36,
      "z": 27,
      "name": "Soil_Dirt"
    },
    {
      "x": 8,
      "y": 37,
      "z": 27,
      "name": "Soil_Leaves"
    },
    {
      "x": 8,
      "y": 30,
      "z": 28,
      "name": "Rock_Stone"
    },
    {
      "x": 8,
      "y": 31,
      "z": 28,
      "name": "Rock_Stone"
    },
    {
      "x": 8,
      "y": 32,
      "z": 28,
      "name": "Rock_Stone"
    },
    {
      "x": 8,
      "y": 33,
      "z": 28,
      "name": "Rock_Stone"
    },
    {
      "x": 8,
      "y": 34,
      "z": 28,
      "name": "Rock_Stone"
    },
    {
      "x": 8,
      "y": 35,
      "z": 28,
      "name": "Soil_Dirt"
    },
    {
      "x": 8,
      "y": 36,
      "z": 28,
      "name": "Soil_Dirt"
    },
    {
      "x": 8,
      "y": 37,
      "z": 28,
      "name": "Soil_Leaves"
    },
    {
      "x": 8,
      "y": 38,
      "z": 28,
      "name": "Plant_Fern"
    },
    {
      "x": 8,
      "y": 16,
      "z": 29,
      "name": "Rock_Stone"
    },
    {
      "x": 8,
      "y": 17,
      "z": 29,
      "name": "Rock_Stone"
    },
    {
      "x": 8,
      "y": 18,
      "z": 29,
      "name": "Rock_Stone"
    },
    {
      "x": 8,
      "y": 19,
      "z": 29,
      "name": "Rock_Stone"
    },
    {
      "x": 8,
      "y": 20,
      "z": 29,
      "name": "Rock_Stone"
    },
    {
      "x": 8,
      "y": 21,
      "z": 29,
      "name": "Rock_Stone"
    },
    {
      "x": 8,
      "y": 22,
      "z": 29,
      "name": "Rock_Stone"
    },
    {
      "x": 8,
      "y": 23,
      "z": 29,
      "name": "Rock_Stone"
    },
    {
      "x": 8,
      "y": 24,
      "z": 29,
      "name": "Rock_Stone"
    },
    {
      "x": 8,
      "y": 30,
      "z": 29,
      "name": "Rock_Stone"
    },
    {
      "x": 8,
      "y": 31,
      "z": 29,
      "name": "Rock_Stone"
    },
    {
      "x": 8,
      "y": 32,
      "z": 29,
      "name": "Rock_Stone"
    },
    {
      "x": 8,
      "y": 33,
      "z": 29,
      "name": "Rock_Stone"
    },
    {
      "x": 8,
      "y": 34,
      "z": 29,
      "name": "Soil_Dirt"
    },
    {
      "x": 8,
      "y": 35,
      "z": 29,
      "name": "Soil_Dirt"
    },
    {
      "x": 8,
      "y": 36,
      "z": 29,
      "name": "Soil_Leaves"
    },
    {
      "x": 8,
      "y": 37,
      "z": 29,
      "name": "Plant_Grass_Lush"
    },
    {
      "x": 8,
      "y": 16,
      "z": 30,
      "name": "Rock_Stone"
    },
    {
      "x": 8,
      "y": 17,
      "z": 30,
      "name": "Rock_Stone"
    },
    {
      "x": 8,
      "y": 18,
      "z": 30,
      "name": "Rock_Stone"
    },
    {
      "x": 8,
      "y": 19,
      "z": 30,
      "name": "Rock_Stone"
    },
    {
      "x": 8,
      "y": 20,
      "z": 30,
      "name": "Rock_Stone"
    },
    {
      "x": 8,
      "y": 21,
      "z": 30,
      "name": "Rock_Stone"
    },
    {
      "x": 8,
      "y": 22,
      "z": 30,
      "name": "Rock_Stone"
    },
    {
      "x": 8,
      "y": 23,
      "z": 30,
      "name": "Rock_Stone"
    },
    {
      "x": 8,
      "y": 24,
      "z": 30,
      "name": "Rock_Stone"
    },
    {
      "x": 8,
      "y": 30,
      "z": 30,
      "name": "Rock_Stone"
    },
    {
      "x": 8,
      "y": 31,
      "z": 30,
      "name": "Rock_Stone"
    },
    {
      "x": 8,
      "y": 32,
      "z": 30,
      "name": "Rock_Stone"
    },
    {
      "x": 8,
      "y": 33,
      "z": 30,
      "name": "Rock_Stone"
    },
    {
      "x": 8,
      "y": 34,
      "z": 30,
      "name": "Soil_Dirt"
    },
    {
      "x": 8,
      "y": 35,
      "z": 30,
      "name": "Soil_Dirt"
    },
    {
      "x": 8,
      "y": 36,
      "z": 30,
      "name": "Soil_Grass_Deep"
    },
    {
      "x": 8,
      "y": 16,
      "z": 31,
      "name": "Rock_Stone"
    },
    {
      "x": 8,
      "y": 17,
      "z": 31,
      "name": "Rock_Stone"
    },
    {
      "x": 8,
      "y": 18,
      "z": 31,
      "name": "Rock_Stone"
    },
    {
      "x": 8,
      "y": 19,
      "z": 31,
      "name": "Rock_Stone"
    },
    {
      "x": 8,
      "y": 20,
      "z": 31,
      "name": "Rock_Stone"
    },
    {
      "x": 8,
      "y": 21,
      "z": 31,
      "name": "Rock_Stone"
    },
    {
      "x": 8,
      "y": 22,
      "z": 31,
      "name": "Rock_Stone"
    },
    {
      "x": 8,
      "y": 32,
      "z": 31,
      "name": "Rock_Stone"
    },
    {
      "x": 8,
      "y": 33,
      "z": 31,
      "name": "Rock_Stone"
    },
    {
      "x": 8,
      "y": 34,
      "z": 31,
      "name": "Soil_Dirt"
    },
    {
      "x": 8,
      "y": 35,
      "z": 31,
      "name": "Soil_Grass_Deep"
    },
    {
      "x": 8,
      "y": 16,
      "z": 32,
      "name": "Rock_Stone"
    },
    {
      "x": 8,
      "y": 17,
      "z": 32,
      "name": "Rock_Stone"
    },
    {
      "x": 8,
      "y": 18,
      "z": 32,
      "name": "Rock_Stone"
    },
    {
      "x": 8,
      "y": 19,
      "z": 32,
      "name": "Rock_Stone"
    },
    {
      "x": 8,
      "y": 20,
      "z": 32,
      "name": "Rock_Stone"
    },
    {
      "x": 8,
      "y": 21,
      "z": 32,
      "name": "Rock_Stone"
    },
    {
      "x": 8,
      "y": 17,
      "z": 33,
      "name": "Rock_Stone"
    },
    {
      "x": 8,
      "y": 18,
      "z": 33,
      "name": "Rock_Stone"
    },
    {
      "x": 8,
      "y": 19,
      "z": 33,
      "name": "Rock_Stone"
    },
    {
      "x": 8,
      "y": 20,
      "z": 33,
      "name": "Rock_Stone"
    },
    {
      "x": 9,
      "y": 36,
      "z": 22,
      "name": "Soil_Grass_Deep"
    },
    {
      "x": 9,
      "y": 38,
      "z": 22,
      "name": "Soil_Grass_Deep"
    },
    {
      "x": 9,
      "y": 39,
      "z": 22,
      "name": "Plant_Grass_Sharp"
    },
    {
      "x": 9,
      "y": 35,
      "z": 23,
      "name": "Soil_Dirt"
    },
    {
      "x": 9,
      "y": 36,
      "z": 23,
      "name": "Soil_Dirt"
    },
    {
      "x": 9,
      "y": 37,
      "z": 23,
      "name": "Soil_Dirt"
    },
    {
      "x": 9,
      "y": 38,
      "z": 23,
      "name": "Soil_Grass_Deep"
    },
    {
      "x": 9,
      "y": 33,
      "z": 24,
      "name": "Rock_Stone"
    },
    {
      "x": 9,
      "y": 34,
      "z": 24,
      "name": "Soil_Dirt"
    },
    {
      "x": 9,
      "y": 35,
      "z": 24,
      "name": "Soil_Dirt"
    },
    {
      "x": 9,
      "y": 36,
      "z": 24,
      "name": "Soil_Dirt"
    },
    {
      "x": 9,
      "y": 37,
      "z": 24,
      "name": "Soil_Dirt"
    },
    {
      "x": 9,
      "y": 38,
      "z": 24,
      "name": "Soil_Grass_Deep"
    },
    {
      "x": 9,
      "y": 32,
      "z": 25,
      "name": "Rock_Stone"
    },
    {
      "x": 9,
      "y": 33,
      "z": 25,
      "name": "Rock_Stone"
    },
    {
      "x": 9,
      "y": 34,
      "z": 25,
      "name": "Soil_Dirt"
    },
    {
      "x": 9,
      "y": 35,
      "z": 25,
      "name": "Soil_Dirt"
    },
    {
      "x": 9,
      "y": 36,
      "z": 25,
      "name": "Soil_Dirt"
    },
    {
      "x": 9,
      "y": 37,
      "z": 25,
      "name": "Soil_Dirt"
    },
    {
      "x": 9,
      "y": 38,
      "z": 25,
      "name": "Soil_Grass_Deep"
    },
    {
      "x": 9,
      "y": 31,
      "z": 26,
      "name": "Rock_Stone"
    },
    {
      "x": 9,
      "y": 32,
      "z": 26,
      "name": "Rock_Stone"
    },
    {
      "x": 9,
      "y": 33,
      "z": 26,
      "name": "Rock_Stone"
    },
    {
      "x": 9,
      "y": 34,
      "z": 26,
      "name": "Soil_Dirt"
    },
    {
      "x": 9,
      "y": 35,
      "z": 26,
      "name": "Soil_Dirt"
    },
    {
      "x": 9,
      "y": 36,
      "z": 26,
      "name": "Soil_Dirt"
    },
    {
      "x": 9,
      "y": 37,
      "z": 26,
      "name": "Soil_Grass_Deep"
    },
    {
      "x": 9,
      "y": 31,
      "z": 27,
      "name": "Rock_Stone"
    },
    {
      "x": 9,
      "y": 32,
      "z": 27,
      "name": "Rock_Stone"
    },
    {
      "x": 9,
      "y": 33,
      "z": 27,
      "name": "Rock_Stone"
    },
    {
      "x": 9,
      "y": 34,
      "z": 27,
      "name": "Rock_Stone"
    },
    {
      "x": 9,
      "y": 35,
      "z": 27,
      "name": "Soil_Dirt"
    },
    {
      "x": 9,
      "y": 36,
      "z": 27,
      "name": "Soil_Dirt"
    },
    {
      "x": 9,
      "y": 37,
      "z": 27,
      "name": "Soil_Leaves"
    },
    {
      "x": 9,
      "y": 30,
      "z": 28,
      "name": "Rock_Stone"
    },
    {
      "x": 9,
      "y": 31,
      "z": 28,
      "name": "Rock_Stone"
    },
    {
      "x": 9,
      "y": 32,
      "z": 28,
      "name": "Rock_Stone"
    },
    {
      "x": 9,
      "y": 33,
      "z": 28,
      "name": "Rock_Stone"
    },
    {
      "x": 9,
      "y": 34,
      "z": 28,
      "name": "Rock_Stone"
    },
    {
      "x": 9,
      "y": 35,
      "z": 28,
      "name": "Soil_Dirt"
    },
    {
      "x": 9,
      "y": 36,
      "z": 28,
      "name": "Soil_Dirt"
    },
    {
      "x": 9,
      "y": 37,
      "z": 28,
      "name": "Soil_Leaves"
    },
    {
      "x": 9,
      "y": 17,
      "z": 29,
      "name": "Rock_Stone"
    },
    {
      "x": 9,
      "y": 18,
      "z": 29,
      "name": "Rock_Stone"
    },
    {
      "x": 9,
      "y": 30,
      "z": 29,
      "name": "Rock_Stone"
    },
    {
      "x": 9,
      "y": 31,
      "z": 29,
      "name": "Rock_Stone"
    },
    {
      "x": 9,
      "y": 32,
      "z": 29,
      "name": "Rock_Stone"
    },
    {
      "x": 9,
      "y": 33,
      "z": 29,
      "name": "Rock_Stone"
    },
    {
      "x": 9,
      "y": 34,
      "z": 29,
      "name": "Rock_Stone"
    },
    {
      "x": 9,
      "y": 35,
      "z": 29,
      "name": "Soil_Dirt"
    },
    {
      "x": 9,
      "y": 36,
      "z": 29,
      "name": "Soil_Leaves"
    },
    {
      "x": 9,
      "y": 15,
      "z": 30,
      "name": "Rock_Stone"
    },
    {
      "x": 9,
      "y": 16,
      "z": 30,
      "name": "Rock_Stone"
    },
    {
      "x": 9,
      "y": 17,
      "z": 30,
      "name": "Rock_Stone"
    },
    {
      "x": 9,
      "y": 18,
      "z": 30,
      "name": "Rock_Stone"
    },
    {
      "x": 9,
      "y": 19,
      "z": 30,
      "name": "Rock_Stone"
    },
    {
      "x": 9,
      "y": 20,
      "z": 30,
      "name": "Rock_Stone"
    },
    {
      "x": 9,
      "y": 30,
      "z": 30,
      "name": "Rock_Stone"
    },
    {
      "x": 9,
      "y": 31,
      "z": 30,
      "name": "Rock_Stone"
    },
    {
      "x": 9,
      "y": 32,
      "z": 30,
      "name": "Rock_Stone"
    },
    {
      "x": 9,
      "y": 33,
      "z": 30,
      "name": "Rock_Stone"
    },
    {
      "x": 9,
      "y": 34,
      "z": 30,
      "name": "Rock_Stone"
    },
    {
      "x": 9,
      "y": 35,
      "z": 30,
      "name": "Soil_Dirt"
    },
    {
      "x": 9,
      "y": 36,
      "z": 30,
      "name": "Soil_Grass_Deep"
    },
    {
      "x": 9,
      "y": 15,
      "z": 31,
      "name": "Rock_Stone"
    },
    {
      "x": 9,
      "y": 16,
      "z": 31,
      "name": "Rock_Stone"
    },
    {
      "x": 9,
      "y": 17,
      "z": 31,
      "name": "Rock_Stone"
    },
    {
      "x": 9,
      "y": 18,
      "z": 31,
      "name": "Rock_Stone"
    },
    {
      "x": 9,
      "y": 19,
      "z": 31,
      "name": "Rock_Stone"
    },
    {
      "x": 9,
      "y": 20,
      "z": 31,
      "name": "Rock_Stone"
    },
    {
      "x": 9,
      "y": 32,
      "z": 31,
      "name": "Rock_Stone"
    },
    {
      "x": 9,
      "y": 33,
      "z": 31,
      "name": "Rock_Stone"
    },
    {
      "x": 9,
      "y": 34,
      "z": 31,
      "name": "Rock_Stone"
    },
    {
      "x": 9,
      "y": 35,
      "z": 31,
      "name": "Soil_Dirt"
    },
    {
      "x": 9,
      "y": 36,
      "z": 31,
      "name": "Soil_Grass_Deep"
    },
    {
      "x": 9,
      "y": 15,
      "z": 32,
      "name": "Rock_Stone"
    },
    {
      "x": 9,
      "y": 16,
      "z": 32,
      "name": "Rock_Stone"
    },
    {
      "x": 9,
      "y": 17,
      "z": 32,
      "name": "Rock_Stone"
    },
    {
      "x": 9,
      "y": 18,
      "z": 32,
      "name": "Rock_Stone"
    },
    {
      "x": 9,
      "y": 19,
      "z": 32,
      "name": "Rock_Stone"
    },
    {
      "x": 9,
      "y": 20,
      "z": 32,
      "name": "Rock_Stone"
    },
    {
      "x": 9,
      "y": 17,
      "z": 33,
      "name": "Rock_Stone"
    },
    {
      "x": 9,
      "y": 18,
      "z": 33,
      "name": "Rock_Stone"
    },
    {
      "x": 9,
      "y": 19,
      "z": 33,
      "name": "Rock_Stone"
    },
    {
      "x": 10,
      "y": 37,
      "z": 19,
      "name": "Rock_Stone"
    },
    {
      "x": 10,
      "y": 38,
      "z": 19,
      "name": "Soil_Grass_Deep"
    },
    {
      "x": 10,
      "y": 36,
      "z": 20,
      "name": "Rock_Stone"
    },
    {
      "x": 10,
      "y": 37,
      "z": 20,
      "name": "Rock_Stone"
    },
    {
      "x": 10,
      "y": 38,
      "z": 20,
      "name": "Soil_Grass_Deep"
    },
    {
      "x": 10,
      "y": 35,
      "z": 21,
      "name": "Rock_Stone"
    },
    {
      "x": 10,
      "y": 36,
      "z": 21,
      "name": "Rock_Stone"
    },
    {
      "x": 10,
      "y": 37,
      "z": 21,
      "name": "Soil_Dirt"
    },
    {
      "x": 10,
      "y": 38,
      "z": 21,
      "name": "Soil_Dirt"
    },
    {
      "x": 10,
      "y": 39,
      "z": 21,
      "name": "Soil_Grass_Deep"
    },
    {
      "x": 10,
      "y": 35,
      "z": 22,
      "name": "Rock_Stone"
    },
    {
      "x": 10,
      "y": 36,
      "z": 22,
      "name": "Soil_Dirt"
    },
    {
      "x": 10,
      "y": 37,
      "z": 22,
      "name": "Soil_Dirt"
    },
    {
      "x": 10,
      "y": 38,
      "z": 22,
      "name": "Soil_Dirt"
    },
    {
      "x": 10,
      "y": 39,
      "z": 22,
      "name": "Soil_Grass_Deep"
    },
    {
      "x": 10,
      "y": 40,
      "z": 22,
      "name": "Plant_Grass_Lush"
    },
    {
      "x": 10,
      "y": 34,
      "z": 23,
      "name": "Rock_Stone"
    },
    {
      "x": 10,
      "y": 35,
      "z": 23,
      "name": "Rock_Stone"
    },
    {
      "x": 10,
      "y": 36,
      "z": 23,
      "name": "Soil_Dirt"
    },
    {
      "x": 10,
      "y": 37,
      "z": 23,
      "name": "Soil_Dirt"
    },
    {
      "x": 10,
      "y": 38,
      "z": 23,
      "name": "Soil_Dirt"
    },
    {
      "x": 10,
      "y": 39,
      "z": 23,
      "name": "Soil_Grass_Deep"
    },
    {
      "x": 10,
      "y": 33,
      "z": 24,
      "name": "Rock_Stone"
    },
    {
      "x": 10,
      "y": 34,
      "z": 24,
      "name": "Rock_Stone"
    },
    {
      "x": 10,
      "y": 35,
      "z": 24,
      "name": "Rock_Stone"
    },
    {
      "x": 10,
      "y": 36,
      "z": 24,
      "name": "Soil_Dirt"
    },
    {
      "x": 10,
      "y": 37,
      "z": 24,
      "name": "Soil_Dirt"
    },
    {
      "x": 10,
      "y": 38,
      "z": 24,
      "name": "Soil_Grass_Deep"
    },
    {
      "x": 10,
      "y": 39,
      "z": 24,
      "name": "Plant_Grass_Sharp"
    },
    {
      "x": 10,
      "y": 33,
      "z": 25,
      "name": "Rock_Stone"
    },
    {
      "x": 10,
      "y": 34,
      "z": 25,
      "name": "Rock_Stone"
    },
    {
      "x": 10,
      "y": 35,
      "z": 25,
      "name": "Soil_Dirt"
    },
    {
      "x": 10,
      "y": 36,
      "z": 25,
      "name": "Soil_Dirt"
    },
    {
      "x": 10,
      "y": 37,
      "z": 25,
      "name": "Soil_Dirt"
    },
    {
      "x": 10,
      "y": 38,
      "z": 25,
      "name": "Soil_Grass_Deep"
    },
    {
      "x": 10,
      "y": 39,
      "z": 25,
      "name": "Plant_Grass_Sharp"
    },
    {
      "x": 10,
      "y": 32,
      "z": 26,
      "name": "Rock_Stone"
    },
    {
      "x": 10,
      "y": 33,
      "z": 26,
      "name": "Rock_Stone"
    },
    {
      "x": 10,
      "y": 34,
      "z": 26,
      "name": "Rock_Stone"
    },
    {
      "x": 10,
      "y": 35,
      "z": 26,
      "name": "Rock_Stone"
    },
    {
      "x": 10,
      "y": 36,
      "z": 26,
      "name": "Soil_Dirt"
    },
    {
      "x": 10,
      "y": 37,
      "z": 26,
      "name": "Soil_Dirt"
    },
    {
      "x": 10,
      "y": 38,
      "z": 26,
      "name": "Soil_Grass_Deep"
    },
    {
      "x": 10,
      "y": 31,
      "z": 27,
      "name": "Rock_Stone"
    },
    {
      "x": 10,
      "y": 32,
      "z": 27,
      "name": "Rock_Stone"
    },
    {
      "x": 10,
      "y": 33,
      "z": 27,
      "name": "Rock_Stone"
    },
    {
      "x": 10,
      "y": 34,
      "z": 27,
      "name": "Rock_Stone"
    },
    {
      "x": 10,
      "y": 35,
      "z": 27,
      "name": "Rock_Stone"
    },
    {
      "x": 10,
      "y": 36,
      "z": 27,
      "name": "Soil_Dirt"
    },
    {
      "x": 10,
      "y": 37,
      "z": 27,
      "name": "Soil_Dirt"
    },
    {
      "x": 10,
      "y": 38,
      "z": 27,
      "name": "Soil_Dirt"
    },
    {
      "x": 10,
      "y": 39,
      "z": 27,
      "name": "Soil_Leaves"
    },
    {
      "x": 10,
      "y": 31,
      "z": 28,
      "name": "Rock_Stone"
    },
    {
      "x": 10,
      "y": 32,
      "z": 28,
      "name": "Rock_Stone"
    },
    {
      "x": 10,
      "y": 33,
      "z": 28,
      "name": "Rock_Stone"
    },
    {
      "x": 10,
      "y": 34,
      "z": 28,
      "name": "Rock_Stone"
    },
    {
      "x": 10,
      "y": 35,
      "z": 28,
      "name": "Rock_Stone"
    },
    {
      "x": 10,
      "y": 36,
      "z": 28,
      "name": "Soil_Dirt"
    },
    {
      "x": 10,
      "y": 37,
      "z": 28,
      "name": "Soil_Dirt"
    },
    {
      "x": 10,
      "y": 38,
      "z": 28,
      "name": "Soil_Dirt"
    },
    {
      "x": 10,
      "y": 39,
      "z": 28,
      "name": "Soil_Leaves"
    },
    {
      "x": 10,
      "y": 16,
      "z": 29,
      "name": "Rock_Stone"
    },
    {
      "x": 10,
      "y": 17,
      "z": 29,
      "name": "Rock_Stone"
    },
    {
      "x": 10,
      "y": 32,
      "z": 29,
      "name": "Rock_Stone"
    },
    {
      "x": 10,
      "y": 33,
      "z": 29,
      "name": "Rock_Stone"
    },
    {
      "x": 10,
      "y": 34,
      "z": 29,
      "name": "Rock_Stone"
    },
    {
      "x": 10,
      "y": 35,
      "z": 29,
      "name": "Soil_Dirt"
    },
    {
      "x": 10,
      "y": 36,
      "z": 29,
      "name": "Soil_Dirt"
    },
    {
      "x": 10,
      "y": 37,
      "z": 29,
      "name": "Soil_Dirt"
    },
    {
      "x": 10,
      "y": 38,
      "z": 29,
      "name": "Soil_Dirt"
    },
    {
      "x": 10,
      "y": 39,
      "z": 29,
      "name": "Soil_Leaves"
    },
    {
      "x": 10,
      "y": 15,
      "z": 30,
      "name": "Rock_Stone"
    },
    {
      "x": 10,
      "y": 16,
      "z": 30,
      "name": "Rock_Stone"
    },
    {
      "x": 10,
      "y": 17,
      "z": 30,
      "name": "Rock_Stone"
    },
    {
      "x": 10,
      "y": 32,
      "z": 30,
      "name": "Rock_Stone"
    },
    {
      "x": 10,
      "y": 33,
      "z": 30,
      "name": "Rock_Stone"
    },
    {
      "x": 10,
      "y": 34,
      "z": 30,
      "name": "Rock_Stone"
    },
    {
      "x": 10,
      "y": 35,
      "z": 30,
      "name": "Soil_Dirt"
    },
    {
      "x": 10,
      "y": 36,
      "z": 30,
      "name": "Soil_Dirt"
    },
    {
      "x": 10,
      "y": 37,
      "z": 30,
      "name": "Soil_Dirt"
    },
    {
      "x": 10,
      "y": 38,
      "z": 30,
      "name": "Soil_Grass_Deep"
    },
    {
      "x": 10,
      "y": 15,
      "z": 31,
      "name": "Rock_Stone"
    },
    {
      "x": 10,
      "y": 16,
      "z": 31,
      "name": "Rock_Stone"
    },
    {
      "x": 10,
      "y": 17,
      "z": 31,
      "name": "Rock_Stone"
    },
    {
      "x": 10,
      "y": 18,
      "z": 31,
      "name": "Rock_Stone"
    },
    {
      "x": 10,
      "y": 19,
      "z": 31,
      "name": "Rock_Stone"
    },
    {
      "x": 10,
      "y": 33,
      "z": 31,
      "name": "Rock_Stone"
    },
    {
      "x": 10,
      "y": 34,
      "z": 31,
      "name": "Rock_Stone"
    },
    {
      "x": 10,
      "y": 35,
      "z": 31,
      "name": "Soil_Dirt"
    },
    {
      "x": 10,
      "y": 36,
      "z": 31,
      "name": "Soil_Dirt"
    },
    {
      "x": 10,
      "y": 37,
      "z": 31,
      "name": "Soil_Grass_Deep"
    },
    {
      "x": 10,
      "y": 15,
      "z": 32,
      "name": "Rock_Stone"
    },
    {
      "x": 10,
      "y": 16,
      "z": 32,
      "name": "Rock_Stone"
    },
    {
      "x": 10,
      "y": 17,
      "z": 32,
      "name": "Rock_Stone"
    },
    {
      "x": 10,
      "y": 18,
      "z": 32,
      "name": "Rock_Stone"
    },
    {
      "x": 10,
      "y": 16,
      "z": 33,
      "name": "Rock_Stone"
    },
    {
      "x": 10,
      "y": 17,
      "z": 33,
      "name": "Rock_Stone"
    },
    {
      "x": 11,
      "y": 38,
      "z": 18,
      "name": "Soil_Grass_Deep"
    },
    {
      "x": 11,
      "y": 37,
      "z": 19,
      "name": "Rock_Stone"
    },
    {
      "x": 11,
      "y": 38,
      "z": 19,
      "name": "Soil_Grass_Deep"
    },
    {
      "x": 11,
      "y": 39,
      "z": 19,
      "name": "Plant_Grass_Lush"
    },
    {
      "x": 11,
      "y": 35,
      "z": 20,
      "name": "Rock_Stone"
    },
    {
      "x": 11,
      "y": 36,
      "z": 20,
      "name": "Rock_Stone"
    },
    {
      "x": 11,
      "y": 37,
      "z": 20,
      "name": "Soil_Dirt"
    },
    {
      "x": 11,
      "y": 38,
      "z": 20,
      "name": "Soil_Dirt"
    },
    {
      "x": 11,
      "y": 39,
      "z": 20,
      "name": "Soil_Grass_Deep"
    },
    {
      "x": 11,
      "y": 40,
      "z": 20,
      "name": "Plant_Grass_Lush"
    },
    {
      "x": 11,
      "y": 35,
      "z": 21,
      "name": "Rock_Stone"
    },
    {
      "x": 11,
      "y": 36,
      "z": 21,
      "name": "Rock_Stone"
    },
    {
      "x": 11,
      "y": 37,
      "z": 21,
      "name": "Rock_Stone"
    },
    {
      "x": 11,
      "y": 38,
      "z": 21,
      "name": "Soil_Dirt"
    },
    {
      "x": 11,
      "y": 39,
      "z": 21,
      "name": "Soil_Grass_Deep"
    },
    {
      "x": 11,
      "y": 34,
      "z": 22,
      "name": "Rock_Stone"
    },
    {
      "x": 11,
      "y": 35,
      "z": 22,
      "name": "Rock_Stone"
    },
    {
      "x": 11,
      "y": 36,
      "z": 22,
      "name": "Rock_Stone"
    },
    {
      "x": 11,
      "y": 37,
      "z": 22,
      "name": "Soil_Dirt"
    },
    {
      "x": 11,
      "y": 38,
      "z": 22,
      "name": "Soil_Dirt"
    },
    {
      "x": 11,
      "y": 39,
      "z": 22,
      "name": "Soil_Grass_Deep"
    },
    {
      "x": 11,
      "y": 40,
      "z": 22,
      "name": "Plant_Grass_Lush"
    },
    {
      "x": 11,
      "y": 34,
      "z": 23,
      "name": "Rock_Stone"
    },
    {
      "x": 11,
      "y": 35,
      "z": 23,
      "name": "Rock_Stone"
    },
    {
      "x": 11,
      "y": 36,
      "z": 23,
      "name": "Soil_Dirt"
    },
    {
      "x": 11,
      "y": 37,
      "z": 23,
      "name": "Soil_Dirt"
    },
    {
      "x": 11,
      "y": 38,
      "z": 23,
      "name": "Soil_Dirt"
    },
    {
      "x": 11,
      "y": 39,
      "z": 23,
      "name": "Soil_Grass_Deep"
    },
    {
      "x": 11,
      "y": 33,
      "z": 24,
      "name": "Rock_Stone"
    },
    {
      "x": 11,
      "y": 34,
      "z": 24,
      "name": "Rock_Stone"
    },
    {
      "x": 11,
      "y": 35,
      "z": 24,
      "name": "Rock_Stone"
    },
    {
      "x": 11,
      "y": 36,
      "z": 24,
      "name": "Soil_Dirt"
    },
    {
      "x": 11,
      "y": 37,
      "z": 24,
      "name": "Soil_Dirt"
    },
    {
      "x": 11,
      "y": 38,
      "z": 24,
      "name": "Soil_Dirt"
    },
    {
      "x": 11,
      "y": 39,
      "z": 24,
      "name": "Soil_Grass_Deep"
    },
    {
      "x": 11,
      "y": 33,
      "z": 25,
      "name": "Rock_Stone"
    },
    {
      "x": 11,
      "y": 34,
      "z": 25,
      "name": "Rock_Stone"
    },
    {
      "x": 11,
      "y": 35,
      "z": 25,
      "name": "Rock_Stone"
    },
    {
      "x": 11,
      "y": 36,
      "z": 25,
      "name": "Soil_Dirt"
    },
    {
      "x": 11,
      "y": 37,
      "z": 25,
      "name": "Soil_Dirt"
    },
    {
      "x": 11,
      "y": 38,
      "z": 25,
      "name": "Soil_Dirt"
    },
    {
      "x": 11,
      "y": 39,
      "z": 25,
      "name": "Soil_Grass_Deep"
    },
    {
      "x": 11,
      "y": 33,
      "z": 26,
      "name": "Rock_Stone"
    },
    {
      "x": 11,
      "y": 34,
      "z": 26,
      "name": "Rock_Stone"
    },
    {
      "x": 11,
      "y": 35,
      "z": 26,
      "name": "Rock_Stone"
    },
    {
      "x": 11,
      "y": 36,
      "z": 26,
      "name": "Soil_Dirt"
    },
    {
      "x": 11,
      "y": 37,
      "z": 26,
      "name": "Soil_Dirt"
    },
    {
      "x": 11,
      "y": 38,
      "z": 26,
      "name": "Soil_Dirt"
    },
    {
      "x": 11,
      "y": 39,
      "z": 26,
      "name": "Soil_Grass_Deep"
    },
    {
      "x": 11,
      "y": 40,
      "z": 26,
      "name": "Plant_Grass_Lush"
    },
    {
      "x": 11,
      "y": 33,
      "z": 27,
      "name": "Rock_Stone"
    },
    {
      "x": 11,
      "y": 34,
      "z": 27,
      "name": "Rock_Stone"
    },
    {
      "x": 11,
      "y": 35,
      "z": 27,
      "name": "Rock_Stone"
    },
    {
      "x": 11,
      "y": 36,
      "z": 27,
      "name": "Soil_Dirt"
    },
    {
      "x": 11,
      "y": 37,
      "z": 27,
      "name": "Soil_Dirt"
    },
    {
      "x": 11,
      "y": 38,
      "z": 27,
      "name": "Soil_Dirt"
    },
    {
      "x": 11,
      "y": 39,
      "z": 27,
      "name": "Soil_Leaves"
    },
    {
      "x": 11,
      "y": 40,
      "z": 27,
      "name": "Plant_Grass_Lush"
    },
    {
      "x": 11,
      "y": 32,
      "z": 28,
      "name": "Rock_Stone"
    },
    {
      "x": 11,
      "y": 33,
      "z": 28,
      "name": "Rock_Stone"
    },
    {
      "x": 11,
      "y": 34,
      "z": 28,
      "name": "Rock_Stone"
    },
    {
      "x": 11,
      "y": 35,
      "z": 28,
      "name": "Rock_Stone"
    },
    {
      "x": 11,
      "y": 36,
      "z": 28,
      "name": "Soil_Dirt"
    },
    {
      "x": 11,
      "y": 37,
      "z": 28,
      "name": "Soil_Dirt"
    },
    {
      "x": 11,
      "y": 38,
      "z": 28,
      "name": "Soil_Dirt"
    },
    {
      "x": 11,
      "y": 39,
      "z": 28,
      "name": "Soil_Leaves"
    },
    {
      "x": 11,
      "y": 15,
      "z": 29,
      "name": "Rock_Stone"
    },
    {
      "x": 11,
      "y": 16,
      "z": 29,
      "name": "Rock_Stone"
    },
    {
      "x": 11,
      "y": 32,
      "z": 29,
      "name": "Rock_Stone"
    },
    {
      "x": 11,
      "y": 33,
      "z": 29,
      "name": "Rock_Stone"
    },
    {
      "x": 11,
      "y": 34,
      "z": 29,
      "name": "Rock_Stone"
    },
    {
      "x": 11,
      "y": 35,
      "z": 29,
      "name": "Rock_Stone"
    },
    {
      "x": 11,
      "y": 36,
      "z": 29,
      "name": "Soil_Dirt"
    },
    {
      "x": 11,
      "y": 37,
      "z": 29,
      "name": "Soil_Dirt"
    },
    {
      "x": 11,
      "y": 38,
      "z": 29,
      "name": "Soil_Dirt"
    },
    {
      "x": 11,
      "y": 39,
      "z": 29,
      "name": "Soil_Leaves"
    },
    {
      "x": 11,
      "y": 40,
      "z": 29,
      "name": "Plant_Grass_Lush"
    },
    {
      "x": 11,
      "y": 14,
      "z": 30,
      "name": "Rock_Stone"
    },
    {
      "x": 11,
      "y": 15,
      "z": 30,
      "name": "Rock_Stone"
    },
    {
      "x": 11,
      "y": 16,
      "z": 30,
      "name": "Rock_Stone"
    },
    {
      "x": 11,
      "y": 17,
      "z": 30,
      "name": "Rock_Stone"
    },
    {
      "x": 11,
      "y": 32,
      "z": 30,
      "name": "Rock_Stone"
    },
    {
      "x": 11,
      "y": 33,
      "z": 30,
      "name": "Rock_Stone"
    },
    {
      "x": 11,
      "y": 34,
      "z": 30,
      "name": "Rock_Stone"
    },
    {
      "x": 11,
      "y": 35,
      "z": 30,
      "name": "Rock_Stone"
    },
    {
      "x": 11,
      "y": 36,
      "z": 30,
      "name": "Soil_Dirt"
    },
    {
      "x": 11,
      "y": 37,
      "z": 30,
      "name": "Soil_Dirt"
    },
    {
      "x": 11,
      "y": 38,
      "z": 30,
      "name": "Soil_Grass_Deep"
    },
    {
      "x": 11,
      "y": 14,
      "z": 31,
      "name": "Rock_Stone"
    },
    {
      "x": 11,
      "y": 15,
      "z": 31,
      "name": "Rock_Stone"
    },
    {
      "x": 11,
      "y": 16,
      "z": 31,
      "name": "Rock_Stone"
    },
    {
      "x": 11,
      "y": 17,
      "z": 31,
      "name": "Rock_Stone"
    },
    {
      "x": 11,
      "y": 33,
      "z": 31,
      "name": "Rock_Stone"
    },
    {
      "x": 11,
      "y": 34,
      "z": 31,
      "name": "Rock_Stone"
    },
    {
      "x": 11,
      "y": 35,
      "z": 31,
      "name": "Soil_Dirt"
    },
    {
      "x": 11,
      "y": 36,
      "z": 31,
      "name": "Soil_Dirt"
    },
    {
      "x": 11,
      "y": 37,
      "z": 31,
      "name": "Soil_Dirt"
    },
    {
      "x": 11,
      "y": 38,
      "z": 31,
      "name": "Soil_Grass_Deep"
    },
    {
      "x": 11,
      "y": 39,
      "z": 31,
      "name": "Plant_Grass_Lush"
    },
    {
      "x": 11,
      "y": 15,
      "z": 32,
      "name": "Rock_Stone"
    },
    {
      "x": 11,
      "y": 16,
      "z": 32,
      "name": "Rock_Stone"
    },
    {
      "x": 11,
      "y": 17,
      "z": 32,
      "name": "Rock_Stone"
    },
    {
      "x": 12,
      "y": 37,
      "z": 16,
      "name": "Rock_Stone"
    },
    {
      "x": 12,
      "y": 38,
      "z": 16,
      "name": "Soil_Grass_Deep"
    },
    {
      "x": 12,
      "y": 37,
      "z": 17,
      "name": "Rock_Stone"
    },
    {
      "x": 12,
      "y": 38,
      "z": 17,
      "name": "Soil_Grass_Deep"
    },
    {
      "x": 12,
      "y": 36,
      "z": 18,
      "name": "Rock_Stone"
    },
    {
      "x": 12,
      "y": 37,
      "z": 18,
      "name": "Rock_Stone"
    },
    {
      "x": 12,
      "y": 38,
      "z": 18,
      "name": "Soil_Dirt"
    },
    {
      "x": 12,
      "y": 39,
      "z": 18,
      "name": "Soil_Grass_Deep"
    },
    {
      "x": 12,
      "y": 35,
      "z": 19,
      "name": "Rock_Stone"
    },
    {
      "x": 12,
      "y": 36,
      "z": 19,
      "name": "Rock_Stone"
    },
    {
      "x": 12,
      "y": 37,
      "z": 19,
      "name": "Rock_Stone"
    },
    {
      "x": 12,
      "y": 38,
      "z": 19,
      "name": "Soil_Dirt"
    },
    {
      "x": 12,
      "y": 39,
      "z": 19,
      "name": "Soil_Grass_Deep"
    },
    {
      "x": 12,
      "y": 35,
      "z": 20,
      "name": "Rock_Stone"
    },
    {
      "x": 12,
      "y": 36,
      "z": 20,
      "name": "Rock_Stone"
    },
    {
      "x": 12,
      "y": 37,
      "z": 20,
      "name": "Rock_Stone"
    },
    {
      "x": 12,
      "y": 38,
      "z": 20,
      "name": "Soil_Dirt"
    },
    {
      "x": 12,
      "y": 39,
      "z": 20,
      "name": "Rock_Stone"
    },
    {
      "x": 12,
      "y": 40,
      "z": 20,
      "name": "Rock_Stone"
    },
    {
      "x": 12,
      "y": 35,
      "z": 21,
      "name": "Rock_Stone"
    },
    {
      "x": 12,
      "y": 36,
      "z": 21,
      "name": "Rock_Stone"
    },
    {
      "x": 12,
      "y": 37,
      "z": 21,
      "name": "Rock_Stone"
    },
    {
      "x": 12,
      "y": 38,
      "z": 21,
      "name": "Soil_Dirt"
    },
    {
      "x": 12,
      "y": 39,
      "z": 21,
      "name": "Rock_Stone"
    },
    {
      "x": 12,
      "y": 40,
      "z": 21,
      "name": "Rock_Stone"
    },
    {
      "x": 12,
      "y": 34,
      "z": 22,
      "name": "Rock_Stone"
    },
    {
      "x": 12,
      "y": 35,
      "z": 22,
      "name": "Rock_Stone"
    },
    {
      "x": 12,
      "y": 36,
      "z": 22,
      "name": "Rock_Stone"
    },
    {
      "x": 12,
      "y": 37,
      "z": 22,
      "name": "Rock_Stone"
    },
    {
      "x": 12,
      "y": 38,
      "z": 22,
      "name": "Soil_Dirt"
    },
    {
      "x": 12,
      "y": 39,
      "z": 22,
      "name": "Soil_Grass_Deep"
    },
    {
      "x": 12,
      "y": 40,
      "z": 22,
      "name": "Rubble_Stone"
    },
    {
      "x": 12,
      "y": 34,
      "z": 23,
      "name": "Rock_Stone"
    },
    {
      "x": 12,
      "y": 35,
      "z": 23,
      "name": "Rock_Stone"
    },
    {
      "x": 12,
      "y": 36,
      "z": 23,
      "name": "Rock_Stone"
    },
    {
      "x": 12,
      "y": 37,
      "z": 23,
      "name": "Rock_Stone"
    },
    {
      "x": 12,
      "y": 38,
      "z": 23,
      "name": "Soil_Dirt"
    },
    {
      "x": 12,
      "y": 39,
      "z": 23,
      "name": "Soil_Grass_Deep"
    },
    {
      "x": 12,
      "y": 40,
      "z": 23,
      "name": "Plant_Grass_Sharp"
    },
    {
      "x": 12,
      "y": 34,
      "z": 24,
      "name": "Rock_Stone"
    },
    {
      "x": 12,
      "y": 35,
      "z": 24,
      "name": "Rock_Stone"
    },
    {
      "x": 12,
      "y": 36,
      "z": 24,
      "name": "Rock_Stone"
    },
    {
      "x": 12,
      "y": 37,
      "z": 24,
      "name": "Soil_Dirt"
    },
    {
      "x": 12,
      "y": 38,
      "z": 24,
      "name": "Soil_Dirt"
    },
    {
      "x": 12,
      "y": 39,
      "z": 24,
      "name": "Soil_Leaves"
    },
    {
      "x": 12,
      "y": 34,
      "z": 25,
      "name": "Rock_Stone"
    },
    {
      "x": 12,
      "y": 35,
      "z": 25,
      "name": "Rock_Stone"
    },
    {
      "x": 12,
      "y": 36,
      "z": 25,
      "name": "Rock_Stone"
    },
    {
      "x": 12,
      "y": 37,
      "z": 25,
      "name": "Rock_Stone"
    },
    {
      "x": 12,
      "y": 38,
      "z": 25,
      "name": "Soil_Dirt"
    },
    {
      "x": 12,
      "y": 39,
      "z": 25,
      "name": "Soil_Dirt"
    },
    {
      "x": 12,
      "y": 40,
      "z": 25,
      "name": "Soil_Leaves"
    },
    {
      "x": 12,
      "y": 34,
      "z": 26,
      "name": "Rock_Stone"
    },
    {
      "x": 12,
      "y": 35,
      "z": 26,
      "name": "Rock_Stone"
    },
    {
      "x": 12,
      "y": 36,
      "z": 26,
      "name": "Rock_Stone"
    },
    {
      "x": 12,
      "y": 37,
      "z": 26,
      "name": "Rock_Stone"
    },
    {
      "x": 12,
      "y": 38,
      "z": 26,
      "name": "Soil_Dirt"
    },
    {
      "x": 12,
      "y": 39,
      "z": 26,
      "name": "Soil_Dirt"
    },
    {
      "x": 12,
      "y": 40,
      "z": 26,
      "name": "Soil_Leaves"
    },
    {
      "x": 12,
      "y": 41,
      "z": 26,
      "name": "Plant_Fern_Winter"
    },
    {
      "x": 12,
      "y": 34,
      "z": 27,
      "name": "Rock_Stone"
    },
    {
      "x": 12,
      "y": 35,
      "z": 27,
      "name": "Rock_Stone"
    },
    {
      "x": 12,
      "y": 36,
      "z": 27,
      "name": "Rock_Stone"
    },
    {
      "x": 12,
      "y": 37,
      "z": 27,
      "name": "Soil_Dirt"
    },
    {
      "x": 12,
      "y": 38,
      "z": 27,
      "name": "Soil_Dirt"
    },
    {
      "x": 12,
      "y": 39,
      "z": 27,
      "name": "Soil_Dirt"
    },
    {
      "x": 12,
      "y": 40,
      "z": 27,
      "name": "Soil_Grass_Deep"
    },
    {
      "x": 12,
      "y": 34,
      "z": 28,
      "name": "Rock_Stone"
    },
    {
      "x": 12,
      "y": 35,
      "z": 28,
      "name": "Rock_Stone"
    },
    {
      "x": 12,
      "y": 36,
      "z": 28,
      "name": "Rock_Stone"
    },
    {
      "x": 12,
      "y": 37,
      "z": 28,
      "name": "Soil_Dirt"
    },
    {
      "x": 12,
      "y": 38,
      "z": 28,
      "name": "Soil_Dirt"
    },
    {
      "x": 12,
      "y": 39,
      "z": 28,
      "name": "Soil_Dirt"
    },
    {
      "x": 12,
      "y": 40,
      "z": 28,
      "name": "Soil_Grass_Deep"
    },
    {
      "x": 12,
      "y": 41,
      "z": 28,
      "name": "Plant_Flower_Common_Violet"
    },
    {
      "x": 12,
      "y": 15,
      "z": 29,
      "name": "Rock_Stone"
    },
    {
      "x": 12,
      "y": 34,
      "z": 29,
      "name": "Rock_Stone"
    },
    {
      "x": 12,
      "y": 35,
      "z": 29,
      "name": "Rock_Stone"
    },
    {
      "x": 12,
      "y": 36,
      "z": 29,
      "name": "Soil_Dirt"
    },
    {
      "x": 12,
      "y": 37,
      "z": 29,
      "name": "Soil_Dirt"
    },
    {
      "x": 12,
      "y": 38,
      "z": 29,
      "name": "Soil_Dirt"
    },
    {
      "x": 12,
      "y": 39,
      "z": 29,
      "name": "Soil_Grass_Deep"
    },
    {
      "x": 12,
      "y": 14,
      "z": 30,
      "name": "Rock_Stone"
    },
    {
      "x": 12,
      "y": 15,
      "z": 30,
      "name": "Rock_Stone"
    },
    {
      "x": 12,
      "y": 16,
      "z": 30,
      "name": "Rock_Stone"
    },
    {
      "x": 12,
      "y": 17,
      "z": 30,
      "name": "Rock_Stone"
    },
    {
      "x": 12,
      "y": 34,
      "z": 30,
      "name": "Rock_Stone"
    },
    {
      "x": 12,
      "y": 35,
      "z": 30,
      "name": "Rock_Stone"
    },
    {
      "x": 12,
      "y": 36,
      "z": 30,
      "name": "Soil_Dirt"
    },
    {
      "x": 12,
      "y": 37,
      "z": 30,
      "name": "Soil_Dirt"
    },
    {
      "x": 12,
      "y": 38,
      "z": 30,
      "name": "Soil_Dirt"
    },
    {
      "x": 12,
      "y": 39,
      "z": 30,
      "name": "Soil_Leaves"
    },
    {
      "x": 12,
      "y": 14,
      "z": 31,
      "name": "Rock_Stone"
    },
    {
      "x": 12,
      "y": 15,
      "z": 31,
      "name": "Rock_Stone"
    },
    {
      "x": 12,
      "y": 16,
      "z": 31,
      "name": "Rock_Stone"
    },
    {
      "x": 12,
      "y": 34,
      "z": 31,
      "name": "Rock_Stone"
    },
    {
      "x": 12,
      "y": 35,
      "z": 31,
      "name": "Rock_Stone"
    },
    {
      "x": 12,
      "y": 36,
      "z": 31,
      "name": "Soil_Dirt"
    },
    {
      "x": 12,
      "y": 37,
      "z": 31,
      "name": "Soil_Dirt"
    },
    {
      "x": 12,
      "y": 38,
      "z": 31,
      "name": "Soil_Dirt"
    },
    {
      "x": 12,
      "y": 39,
      "z": 31,
      "name": "Soil_Leaves"
    },
    {
      "x": 12,
      "y": 40,
      "z": 31,
      "name": "Plant_Grass_Lush"
    },
    {
      "x": 12,
      "y": 14,
      "z": 32,
      "name": "Rock_Stone"
    },
    {
      "x": 12,
      "y": 15,
      "z": 32,
      "name": "Rock_Stone"
    },
    {
      "x": 12,
      "y": 16,
      "z": 32,
      "name": "Rock_Stone"
    },
    {
      "x": 12,
      "y": 35,
      "z": 32,
      "name": "Rock_Stone"
    },
    {
      "x": 12,
      "y": 36,
      "z": 32,
      "name": "Soil_Dirt"
    },
    {
      "x": 12,
      "y": 37,
      "z": 32,
      "name": "Soil_Leaves"
    },
    {
      "x": 13,
      "y": 38,
      "z": 15,
      "name": "Soil_Dirt"
    },
    {
      "x": 13,
      "y": 39,
      "z": 15,
      "name": "Soil_Grass_Deep"
    },
    {
      "x": 13,
      "y": 37,
      "z": 16,
      "name": "Rock_Stone"
    },
    {
      "x": 13,
      "y": 38,
      "z": 16,
      "name": "Soil_Dirt"
    },
    {
      "x": 13,
      "y": 39,
      "z": 16,
      "name": "Soil_Grass_Deep"
    },
    {
      "x": 13,
      "y": 35,
      "z": 17,
      "name": "Rock_Stone"
    },
    {
      "x": 13,
      "y": 36,
      "z": 17,
      "name": "Rock_Stone"
    },
    {
      "x": 13,
      "y": 37,
      "z": 17,
      "name": "Rock_Stone"
    },
    {
      "x": 13,
      "y": 38,
      "z": 17,
      "name": "Soil_Dirt"
    },
    {
      "x": 13,
      "y": 39,
      "z": 17,
      "name": "Soil_Grass_Deep"
    },
    {
      "x": 13,
      "y": 35,
      "z": 18,
      "name": "Rock_Stone"
    },
    {
      "x": 13,
      "y": 36,
      "z": 18,
      "name": "Rock_Stone"
    },
    {
      "x": 13,
      "y": 37,
      "z": 18,
      "name": "Soil_Dirt"
    },
    {
      "x": 13,
      "y": 38,
      "z": 18,
      "name": "Soil_Dirt"
    },
    {
      "x": 13,
      "y": 39,
      "z": 18,
      "name": "Soil_Grass_Deep"
    },
    {
      "x": 13,
      "y": 35,
      "z": 19,
      "name": "Rock_Stone"
    },
    {
      "x": 13,
      "y": 36,
      "z": 19,
      "name": "Rock_Stone"
    },
    {
      "x": 13,
      "y": 37,
      "z": 19,
      "name": "Rock_Stone"
    },
    {
      "x": 13,
      "y": 38,
      "z": 19,
      "name": "Rock_Stone"
    },
    {
      "x": 13,
      "y": 39,
      "z": 19,
      "name": "Rock_Stone"
    },
    {
      "x": 13,
      "y": 40,
      "z": 19,
      "name": "Rock_Stone_Mossy"
    },
    {
      "x": 13,
      "y": 41,
      "z": 19,
      "name": "Rock_Stone_Mossy"
    },
    {
      "x": 13,
      "y": 42,
      "z": 19,
      "name": "Rock_Stone_Mossy"
    },
    {
      "x": 13,
      "y": 35,
      "z": 20,
      "name": "Rock_Stone"
    },
    {
      "x": 13,
      "y": 36,
      "z": 20,
      "name": "Rock_Stone"
    },
    {
      "x": 13,
      "y": 37,
      "z": 20,
      "name": "Rock_Stone"
    },
    {
      "x": 13,
      "y": 38,
      "z": 20,
      "name": "Rock_Stone"
    },
    {
      "x": 13,
      "y": 39,
      "z": 20,
      "name": "Rock_Stone"
    },
    {
      "x": 13,
      "y": 40,
      "z": 20,
      "name": "Rock_Stone"
    },
    {
      "x": 13,
      "y": 41,
      "z": 20,
      "name": "Rock_Stone"
    },
    {
      "x": 13,
      "y": 42,
      "z": 20,
      "name": "Rock_Stone_Mossy"
    },
    {
      "x": 13,
      "y": 43,
      "z": 20,
      "name": "Rubble_Stone_Mossy_Medium"
    },
    {
      "x": 13,
      "y": 35,
      "z": 21,
      "name": "Rock_Stone"
    },
    {
      "x": 13,
      "y": 36,
      "z": 21,
      "name": "Rock_Stone"
    },
    {
      "x": 13,
      "y": 37,
      "z": 21,
      "name": "Rock_Stone"
    },
    {
      "x": 13,
      "y": 38,
      "z": 21,
      "name": "Rock_Stone"
    },
    {
      "x": 13,
      "y": 39,
      "z": 21,
      "name": "Rock_Stone"
    },
    {
      "x": 13,
      "y": 40,
      "z": 21,
      "name": "Rock_Stone"
    },
    {
      "x": 13,
      "y": 41,
      "z": 21,
      "name": "Rock_Stone_Mossy"
    },
    {
      "x": 13,
      "y": 42,
      "z": 21,
      "name": "Rock_Stone"
    },
    {
      "x": 13,
      "y": 35,
      "z": 22,
      "name": "Rock_Stone"
    },
    {
      "x": 13,
      "y": 36,
      "z": 22,
      "name": "Rock_Stone"
    },
    {
      "x": 13,
      "y": 37,
      "z": 22,
      "name": "Rock_Stone"
    },
    {
      "x": 13,
      "y": 38,
      "z": 22,
      "name": "Soil_Dirt"
    },
    {
      "x": 13,
      "y": 39,
      "z": 22,
      "name": "Soil_Dirt"
    },
    {
      "x": 13,
      "y": 40,
      "z": 22,
      "name": "Soil_Grass_Deep"
    },
    {
      "x": 13,
      "y": 35,
      "z": 23,
      "name": "Rock_Stone"
    },
    {
      "x": 13,
      "y": 36,
      "z": 23,
      "name": "Rock_Stone"
    },
    {
      "x": 13,
      "y": 37,
      "z": 23,
      "name": "Rock_Stone"
    },
    {
      "x": 13,
      "y": 38,
      "z": 23,
      "name": "Soil_Dirt"
    },
    {
      "x": 13,
      "y": 39,
      "z": 23,
      "name": "Soil_Dirt"
    },
    {
      "x": 13,
      "y": 40,
      "z": 23,
      "name": "Soil_Leaves"
    },
    {
      "x": 13,
      "y": 35,
      "z": 24,
      "name": "Rock_Stone"
    },
    {
      "x": 13,
      "y": 36,
      "z": 24,
      "name": "Rock_Stone"
    },
    {
      "x": 13,
      "y": 37,
      "z": 24,
      "name": "Rock_Stone"
    },
    {
      "x": 13,
      "y": 38,
      "z": 24,
      "name": "Soil_Dirt"
    },
    {
      "x": 13,
      "y": 39,
      "z": 24,
      "name": "Soil_Dirt"
    },
    {
      "x": 13,
      "y": 40,
      "z": 24,
      "name": "Soil_Leaves"
    },
    {
      "x": 13,
      "y": 41,
      "z": 24,
      "name": "Plant_Grass_Sharp"
    },
    {
      "x": 13,
      "y": 35,
      "z": 25,
      "name": "Rock_Stone"
    },
    {
      "x": 13,
      "y": 36,
      "z": 25,
      "name": "Rock_Stone"
    },
    {
      "x": 13,
      "y": 37,
      "z": 25,
      "name": "Rock_Stone"
    },
    {
      "x": 13,
      "y": 38,
      "z": 25,
      "name": "Rock_Stone"
    },
    {
      "x": 13,
      "y": 39,
      "z": 25,
      "name": "Soil_Dirt"
    },
    {
      "x": 13,
      "y": 40,
      "z": 25,
      "name": "Soil_Leaves"
    },
    {
      "x": 13,
      "y": 41,
      "z": 25,
      "name": "Plant_Flower_Common_Violet"
    },
    {
      "x": 13,
      "y": 35,
      "z": 26,
      "name": "Rock_Stone"
    },
    {
      "x": 13,
      "y": 36,
      "z": 26,
      "name": "Rock_Stone"
    },
    {
      "x": 13,
      "y": 37,
      "z": 26,
      "name": "Rock_Stone"
    },
    {
      "x": 13,
      "y": 38,
      "z": 26,
      "name": "Rock_Stone"
    },
    {
      "x": 13,
      "y": 39,
      "z": 26,
      "name": "Soil_Dirt"
    },
    {
      "x": 13,
      "y": 40,
      "z": 26,
      "name": "Soil_Leaves"
    },
    {
      "x": 13,
      "y": 34,
      "z": 27,
      "name": "Rock_Stone"
    },
    {
      "x": 13,
      "y": 35,
      "z": 27,
      "name": "Rock_Stone"
    },
    {
      "x": 13,
      "y": 36,
      "z": 27,
      "name": "Rock_Stone"
    },
    {
      "x": 13,
      "y": 37,
      "z": 27,
      "name": "Rock_Stone"
    },
    {
      "x": 13,
      "y": 38,
      "z": 27,
      "name": "Rock_Stone"
    },
    {
      "x": 13,
      "y": 39,
      "z": 27,
      "name": "Soil_Dirt"
    },
    {
      "x": 13,
      "y": 40,
      "z": 27,
      "name": "Soil_Leaves"
    },
    {
      "x": 13,
      "y": 41,
      "z": 27,
      "name": "Plant_Grass_Sharp"
    },
    {
      "x": 13,
      "y": 34,
      "z": 28,
      "name": "Rock_Stone"
    },
    {
      "x": 13,
      "y": 35,
      "z": 28,
      "name": "Rock_Stone"
    },
    {
      "x": 13,
      "y": 36,
      "z": 28,
      "name": "Rock_Stone"
    },
    {
      "x": 13,
      "y": 37,
      "z": 28,
      "name": "Rock_Stone"
    },
    {
      "x": 13,
      "y": 38,
      "z": 28,
      "name": "Soil_Dirt"
    },
    {
      "x": 13,
      "y": 39,
      "z": 28,
      "name": "Soil_Dirt"
    },
    {
      "x": 13,
      "y": 40,
      "z": 28,
      "name": "Soil_Grass_Deep"
    },
    {
      "x": 13,
      "y": 41,
      "z": 28,
      "name": "Plant_Grass_Lush"
    },
    {
      "x": 13,
      "y": 15,
      "z": 29,
      "name": "Rock_Stone"
    },
    {
      "x": 13,
      "y": 34,
      "z": 29,
      "name": "Rock_Stone"
    },
    {
      "x": 13,
      "y": 35,
      "z": 29,
      "name": "Rock_Stone"
    },
    {
      "x": 13,
      "y": 36,
      "z": 29,
      "name": "Rock_Stone"
    },
    {
      "x": 13,
      "y": 37,
      "z": 29,
      "name": "Soil_Dirt"
    },
    {
      "x": 13,
      "y": 38,
      "z": 29,
      "name": "Soil_Dirt"
    },
    {
      "x": 13,
      "y": 39,
      "z": 29,
      "name": "Soil_Dirt"
    },
    {
      "x": 13,
      "y": 40,
      "z": 29,
      "name": "Soil_Grass_Deep"
    },
    {
      "x": 13,
      "y": 13,
      "z": 30,
      "name": "Rock_Stone"
    },
    {
      "x": 13,
      "y": 14,
      "z": 30,
      "name": "Rock_Stone"
    },
    {
      "x": 13,
      "y": 15,
      "z": 30,
      "name": "Rock_Stone"
    },
    {
      "x": 13,
      "y": 16,
      "z": 30,
      "name": "Rock_Stone"
    },
    {
      "x": 13,
      "y": 34,
      "z": 30,
      "name": "Rock_Stone"
    },
    {
      "x": 13,
      "y": 35,
      "z": 30,
      "name": "Rock_Stone"
    },
    {
      "x": 13,
      "y": 36,
      "z": 30,
      "name": "Soil_Dirt"
    },
    {
      "x": 13,
      "y": 37,
      "z": 30,
      "name": "Soil_Dirt"
    },
    {
      "x": 13,
      "y": 38,
      "z": 30,
      "name": "Soil_Dirt"
    },
    {
      "x": 13,
      "y": 39,
      "z": 30,
      "name": "Soil_Dirt"
    },
    {
      "x": 13,
      "y": 40,
      "z": 30,
      "name": "Soil_Leaves"
    },
    {
      "x": 13,
      "y": 13,
      "z": 31,
      "name": "Rock_Stone"
    },
    {
      "x": 13,
      "y": 14,
      "z": 31,
      "name": "Rock_Stone"
    },
    {
      "x": 13,
      "y": 15,
      "z": 31,
      "name": "Rock_Stone"
    },
    {
      "x": 13,
      "y": 16,
      "z": 31,
      "name": "Rock_Stone"
    },
    {
      "x": 13,
      "y": 35,
      "z": 31,
      "name": "Rock_Stone"
    },
    {
      "x": 13,
      "y": 36,
      "z": 31,
      "name": "Soil_Dirt"
    },
    {
      "x": 13,
      "y": 37,
      "z": 31,
      "name": "Soil_Dirt"
    },
    {
      "x": 13,
      "y": 38,
      "z": 31,
      "name": "Soil_Dirt"
    },
    {
      "x": 13,
      "y": 39,
      "z": 31,
      "name": "Soil_Leaves"
    },
    {
      "x": 13,
      "y": 14,
      "z": 32,
      "name": "Rock_Stone"
    },
    {
      "x": 13,
      "y": 15,
      "z": 32,
      "name": "Rock_Stone"
    },
    {
      "x": 13,
      "y": 35,
      "z": 32,
      "name": "Rock_Stone"
    },
    {
      "x": 13,
      "y": 36,
      "z": 32,
      "name": "Soil_Dirt"
    },
    {
      "x": 13,
      "y": 37,
      "z": 32,
      "name": "Soil_Dirt"
    },
    {
      "x": 13,
      "y": 38,
      "z": 32,
      "name": "Soil_Dirt"
    },
    {
      "x": 13,
      "y": 39,
      "z": 32,
      "name": "Soil_Leaves"
    },
    {
      "x": 13,
      "y": 40,
      "z": 32,
      "name": "Plant_Grass_Lush"
    },
    {
      "x": 14,
      "y": 37,
      "z": 14,
      "name": "Rock_Stone"
    },
    {
      "x": 14,
      "y": 38,
      "z": 14,
      "name": "Soil_Grass_Deep"
    },
    {
      "x": 14,
      "y": 36,
      "z": 15,
      "name": "Rock_Stone"
    },
    {
      "x": 14,
      "y": 37,
      "z": 15,
      "name": "Rock_Stone"
    },
    {
      "x": 14,
      "y": 38,
      "z": 15,
      "name": "Soil_Dirt"
    },
    {
      "x": 14,
      "y": 39,
      "z": 15,
      "name": "Soil_Grass_Deep"
    },
    {
      "x": 14,
      "y": 35,
      "z": 16,
      "name": "Rock_Stone"
    },
    {
      "x": 14,
      "y": 36,
      "z": 16,
      "name": "Rock_Stone"
    },
    {
      "x": 14,
      "y": 37,
      "z": 16,
      "name": "Soil_Dirt"
    },
    {
      "x": 14,
      "y": 38,
      "z": 16,
      "name": "Soil_Dirt"
    },
    {
      "x": 14,
      "y": 39,
      "z": 16,
      "name": "Soil_Grass_Deep"
    },
    {
      "x": 14,
      "y": 35,
      "z": 17,
      "name": "Rock_Stone"
    },
    {
      "x": 14,
      "y": 36,
      "z": 17,
      "name": "Rock_Stone"
    },
    {
      "x": 14,
      "y": 37,
      "z": 17,
      "name": "Soil_Dirt"
    },
    {
      "x": 14,
      "y": 38,
      "z": 17,
      "name": "Soil_Dirt"
    },
    {
      "x": 14,
      "y": 39,
      "z": 17,
      "name": "Soil_Grass_Deep"
    },
    {
      "x": 14,
      "y": 35,
      "z": 18,
      "name": "Rock_Stone"
    },
    {
      "x": 14,
      "y": 36,
      "z": 18,
      "name": "Rock_Stone"
    },
    {
      "x": 14,
      "y": 37,
      "z": 18,
      "name": "Rock_Stone"
    },
    {
      "x": 14,
      "y": 38,
      "z": 18,
      "name": "Soil_Dirt"
    },
    {
      "x": 14,
      "y": 39,
      "z": 18,
      "name": "Soil_Dirt"
    },
    {
      "x": 14,
      "y": 40,
      "z": 18,
      "name": "Rock_Stone"
    },
    {
      "x": 14,
      "y": 35,
      "z": 19,
      "name": "Rock_Stone"
    },
    {
      "x": 14,
      "y": 36,
      "z": 19,
      "name": "Rock_Stone"
    },
    {
      "x": 14,
      "y": 37,
      "z": 19,
      "name": "Rock_Stone"
    },
    {
      "x": 14,
      "y": 38,
      "z": 19,
      "name": "Rock_Stone"
    },
    {
      "x": 14,
      "y": 39,
      "z": 19,
      "name": "Rock_Stone"
    },
    {
      "x": 14,
      "y": 40,
      "z": 19,
      "name": "Rock_Stone"
    },
    {
      "x": 14,
      "y": 41,
      "z": 19,
      "name": "Rock_Stone"
    },
    {
      "x": 14,
      "y": 42,
      "z": 19,
      "name": "Rock_Stone_Mossy"
    },
    {
      "x": 14,
      "y": 35,
      "z": 20,
      "name": "Rock_Stone"
    },
    {
      "x": 14,
      "y": 36,
      "z": 20,
      "name": "Rock_Stone"
    },
    {
      "x": 14,
      "y": 37,
      "z": 20,
      "name": "Rock_Stone"
    },
    {
      "x": 14,
      "y": 38,
      "z": 20,
      "name": "Rock_Stone"
    },
    {
      "x": 14,
      "y": 39,
      "z": 20,
      "name": "Rock_Stone"
    },
    {
      "x": 14,
      "y": 40,
      "z": 20,
      "name": "Rock_Stone"
    },
    {
      "x": 14,
      "y": 41,
      "z": 20,
      "name": "Rock_Stone_Mossy"
    },
    {
      "x": 14,
      "y": 42,
      "z": 20,
      "name": "Rock_Stone"
    },
    {
      "x": 14,
      "y": 43,
      "z": 20,
      "name": "Rock_Stone"
    },
    {
      "x": 14,
      "y": 35,
      "z": 21,
      "name": "Rock_Stone"
    },
    {
      "x": 14,
      "y": 36,
      "z": 21,
      "name": "Rock_Stone"
    },
    {
      "x": 14,
      "y": 37,
      "z": 21,
      "name": "Rock_Stone"
    },
    {
      "x": 14,
      "y": 38,
      "z": 21,
      "name": "Rock_Stone"
    },
    {
      "x": 14,
      "y": 39,
      "z": 21,
      "name": "Rock_Stone_Mossy"
    },
    {
      "x": 14,
      "y": 40,
      "z": 21,
      "name": "Rock_Stone_Mossy"
    },
    {
      "x": 14,
      "y": 41,
      "z": 21,
      "name": "Rock_Stone_Mossy"
    },
    {
      "x": 14,
      "y": 42,
      "z": 21,
      "name": "Rock_Stone_Mossy"
    },
    {
      "x": 14,
      "y": 43,
      "z": 21,
      "name": "Rock_Stone_Mossy"
    },
    {
      "x": 14,
      "y": 35,
      "z": 22,
      "name": "Rock_Stone"
    },
    {
      "x": 14,
      "y": 36,
      "z": 22,
      "name": "Rock_Stone"
    },
    {
      "x": 14,
      "y": 37,
      "z": 22,
      "name": "Rock_Stone"
    },
    {
      "x": 14,
      "y": 38,
      "z": 22,
      "name": "Rock_Stone"
    },
    {
      "x": 14,
      "y": 39,
      "z": 22,
      "name": "Rock_Stone"
    },
    {
      "x": 14,
      "y": 40,
      "z": 22,
      "name": "Rock_Stone"
    },
    {
      "x": 14,
      "y": 41,
      "z": 22,
      "name": "Rock_Stone"
    },
    {
      "x": 14,
      "y": 42,
      "z": 22,
      "name": "Rubble_Stone"
    },
    {
      "x": 14,
      "y": 35,
      "z": 23,
      "name": "Rock_Stone"
    },
    {
      "x": 14,
      "y": 36,
      "z": 23,
      "name": "Rock_Stone"
    },
    {
      "x": 14,
      "y": 37,
      "z": 23,
      "name": "Rock_Stone"
    },
    {
      "x": 14,
      "y": 38,
      "z": 23,
      "name": "Rock_Stone"
    },
    {
      "x": 14,
      "y": 39,
      "z": 23,
      "name": "Soil_Dirt"
    },
    {
      "x": 14,
      "y": 40,
      "z": 23,
      "name": "Soil_Grass_Deep"
    },
    {
      "x": 14,
      "y": 41,
      "z": 23,
      "name": "Rubble_Stone"
    },
    {
      "x": 14,
      "y": 35,
      "z": 24,
      "name": "Rock_Stone"
    },
    {
      "x": 14,
      "y": 36,
      "z": 24,
      "name": "Rock_Stone"
    },
    {
      "x": 14,
      "y": 37,
      "z": 24,
      "name": "Rock_Stone"
    },
    {
      "x": 14,
      "y": 38,
      "z": 24,
      "name": "Rock_Stone"
    },
    {
      "x": 14,
      "y": 39,
      "z": 24,
      "name": "Rock_Stone"
    },
    {
      "x": 14,
      "y": 40,
      "z": 24,
      "name": "Soil_Dirt"
    },
    {
      "x": 14,
      "y": 41,
      "z": 24,
      "name": "Rock_Stone_Mossy"
    },
    {
      "x": 14,
      "y": 35,
      "z": 25,
      "name": "Rock_Stone"
    },
    {
      "x": 14,
      "y": 36,
      "z": 25,
      "name": "Rock_Stone"
    },
    {
      "x": 14,
      "y": 37,
      "z": 25,
      "name": "Rock_Stone"
    },
    {
      "x": 14,
      "y": 38,
      "z": 25,
      "name": "Rock_Stone"
    },
    {
      "x": 14,
      "y": 39,
      "z": 25,
      "name": "Rock_Stone"
    },
    {
      "x": 14,
      "y": 40,
      "z": 25,
      "name": "Soil_Dirt"
    },
    {
      "x": 14,
      "y": 41,
      "z": 25,
      "name": "Soil_Leaves"
    },
    {
      "x": 14,
      "y": 35,
      "z": 26,
      "name": "Rock_Stone"
    },
    {
      "x": 14,
      "y": 36,
      "z": 26,
      "name": "Rock_Stone"
    },
    {
      "x": 14,
      "y": 37,
      "z": 26,
      "name": "Rock_Stone"
    },
    {
      "x": 14,
      "y": 38,
      "z": 26,
      "name": "Rock_Stone"
    },
    {
      "x": 14,
      "y": 39,
      "z": 26,
      "name": "Soil_Dirt"
    },
    {
      "x": 14,
      "y": 40,
      "z": 26,
      "name": "Soil_Dirt"
    },
    {
      "x": 14,
      "y": 41,
      "z": 26,
      "name": "Soil_Leaves"
    },
    {
      "x": 14,
      "y": 35,
      "z": 27,
      "name": "Rock_Stone"
    },
    {
      "x": 14,
      "y": 36,
      "z": 27,
      "name": "Rock_Stone"
    },
    {
      "x": 14,
      "y": 37,
      "z": 27,
      "name": "Rock_Stone"
    },
    {
      "x": 14,
      "y": 38,
      "z": 27,
      "name": "Rock_Stone"
    },
    {
      "x": 14,
      "y": 39,
      "z": 27,
      "name": "Soil_Dirt"
    },
    {
      "x": 14,
      "y": 40,
      "z": 27,
      "name": "Soil_Grass_Deep"
    },
    {
      "x": 14,
      "y": 35,
      "z": 28,
      "name": "Rock_Stone"
    },
    {
      "x": 14,
      "y": 36,
      "z": 28,
      "name": "Rock_Stone"
    },
    {
      "x": 14,
      "y": 37,
      "z": 28,
      "name": "Rock_Stone"
    },
    {
      "x": 14,
      "y": 38,
      "z": 28,
      "name": "Rock_Stone"
    },
    {
      "x": 14,
      "y": 39,
      "z": 28,
      "name": "Soil_Dirt"
    },
    {
      "x": 14,
      "y": 40,
      "z": 28,
      "name": "Soil_Leaves"
    },
    {
      "x": 14,
      "y": 41,
      "z": 28,
      "name": "Plant_Grass_Sharp"
    },
    {
      "x": 14,
      "y": 13,
      "z": 29,
      "name": "Rock_Stone"
    },
    {
      "x": 14,
      "y": 14,
      "z": 29,
      "name": "Rock_Stone"
    },
    {
      "x": 14,
      "y": 35,
      "z": 29,
      "name": "Rock_Stone"
    },
    {
      "x": 14,
      "y": 36,
      "z": 29,
      "name": "Rock_Stone"
    },
    {
      "x": 14,
      "y": 37,
      "z": 29,
      "name": "Rock_Stone"
    },
    {
      "x": 14,
      "y": 38,
      "z": 29,
      "name": "Soil_Dirt"
    },
    {
      "x": 14,
      "y": 39,
      "z": 29,
      "name": "Soil_Dirt"
    },
    {
      "x": 14,
      "y": 40,
      "z": 29,
      "name": "Soil_Leaves"
    },
    {
      "x": 14,
      "y": 41,
      "z": 29,
      "name": "Plant_Flower_Common_Violet"
    },
    {
      "x": 14,
      "y": 13,
      "z": 30,
      "name": "Rock_Stone"
    },
    {
      "x": 14,
      "y": 14,
      "z": 30,
      "name": "Rock_Stone"
    },
    {
      "x": 14,
      "y": 35,
      "z": 30,
      "name": "Rock_Stone"
    },
    {
      "x": 14,
      "y": 36,
      "z": 30,
      "name": "Rock_Stone"
    },
    {
      "x": 14,
      "y": 37,
      "z": 30,
      "name": "Rock_Stone"
    },
    {
      "x": 14,
      "y": 38,
      "z": 30,
      "name": "Soil_Dirt"
    },
    {
      "x": 14,
      "y": 39,
      "z": 30,
      "name": "Soil_Dirt"
    },
    {
      "x": 14,
      "y": 40,
      "z": 30,
      "name": "Soil_Leaves"
    },
    {
      "x": 14,
      "y": 41,
      "z": 30,
      "name": "Plant_Grass_Lush"
    },
    {
      "x": 14,
      "y": 13,
      "z": 31,
      "name": "Rock_Stone"
    },
    {
      "x": 14,
      "y": 14,
      "z": 31,
      "name": "Rock_Stone"
    },
    {
      "x": 14,
      "y": 15,
      "z": 31,
      "name": "Rock_Stone"
    },
    {
      "x": 14,
      "y": 16,
      "z": 31,
      "name": "Rock_Stone"
    },
    {
      "x": 14,
      "y": 35,
      "z": 31,
      "name": "Rock_Stone"
    },
    {
      "x": 14,
      "y": 36,
      "z": 31,
      "name": "Rock_Stone"
    },
    {
      "x": 14,
      "y": 37,
      "z": 31,
      "name": "Soil_Dirt"
    },
    {
      "x": 14,
      "y": 38,
      "z": 31,
      "name": "Soil_Dirt"
    },
    {
      "x": 14,
      "y": 39,
      "z": 31,
      "name": "Soil_Dirt"
    },
    {
      "x": 14,
      "y": 40,
      "z": 31,
      "name": "Soil_Leaves"
    },
    {
      "x": 14,
      "y": 14,
      "z": 32,
      "name": "Rock_Stone"
    },
    {
      "x": 14,
      "y": 15,
      "z": 32,
      "name": "Rock_Stone"
    },
    {
      "x": 14,
      "y": 35,
      "z": 32,
      "name": "Rock_Stone"
    },
    {
      "x": 14,
      "y": 36,
      "z": 32,
      "name": "Rock_Stone"
    },
    {
      "x": 14,
      "y": 37,
      "z": 32,
      "name": "Rock_Stone"
    },
    {
      "x": 14,
      "y": 38,
      "z": 32,
      "name": "Rock_Stone"
    },
    {
      "x": 14,
      "y": 39,
      "z": 32,
      "name": "Soil_Leaves"
    },
    {
      "x": 15,
      "y": 36,
      "z": 13,
      "name": "Soil_Dirt"
    },
    {
      "x": 15,
      "y": 37,
      "z": 13,
      "name": "Soil_Dirt"
    },
    {
      "x": 15,
      "y": 35,
      "z": 14,
      "name": "Rock_Stone"
    },
    {
      "x": 15,
      "y": 36,
      "z": 14,
      "name": "Rock_Stone"
    },
    {
      "x": 15,
      "y": 37,
      "z": 14,
      "name": "Soil_Dirt"
    },
    {
      "x": 15,
      "y": 38,
      "z": 14,
      "name": "Soil_Dirt"
    },
    {
      "x": 15,
      "y": 39,
      "z": 14,
      "name": "Soil_Grass_Deep"
    },
    {
      "x": 15,
      "y": 35,
      "z": 15,
      "name": "Rock_Stone"
    },
    {
      "x": 15,
      "y": 36,
      "z": 15,
      "name": "Rock_Stone"
    },
    {
      "x": 15,
      "y": 37,
      "z": 15,
      "name": "Rock_Stone"
    },
    {
      "x": 15,
      "y": 38,
      "z": 15,
      "name": "Soil_Dirt"
    },
    {
      "x": 15,
      "y": 39,
      "z": 15,
      "name": "Soil_Leaves"
    },
    {
      "x": 15,
      "y": 35,
      "z": 16,
      "name": "Rock_Stone"
    },
    {
      "x": 15,
      "y": 36,
      "z": 16,
      "name": "Rock_Stone"
    },
    {
      "x": 15,
      "y": 37,
      "z": 16,
      "name": "Rock_Stone"
    },
    {
      "x": 15,
      "y": 38,
      "z": 16,
      "name": "Soil_Dirt"
    },
    {
      "x": 15,
      "y": 39,
      "z": 16,
      "name": "Soil_Grass_Deep"
    },
    {
      "x": 15,
      "y": 40,
      "z": 16,
      "name": "Plant_Grass_Lush"
    },
    {
      "x": 15,
      "y": 35,
      "z": 17,
      "name": "Rock_Stone"
    },
    {
      "x": 15,
      "y": 36,
      "z": 17,
      "name": "Rock_Stone"
    },
    {
      "x": 15,
      "y": 37,
      "z": 17,
      "name": "Rock_Stone"
    },
    {
      "x": 15,
      "y": 38,
      "z": 17,
      "name": "Soil_Dirt"
    },
    {
      "x": 15,
      "y": 39,
      "z": 17,
      "name": "Soil_Dirt"
    },
    {
      "x": 15,
      "y": 40,
      "z": 17,
      "name": "Soil_Grass_Deep"
    },
    {
      "x": 15,
      "y": 35,
      "z": 18,
      "name": "Rock_Stone"
    },
    {
      "x": 15,
      "y": 36,
      "z": 18,
      "name": "Rock_Stone"
    },
    {
      "x": 15,
      "y": 37,
      "z": 18,
      "name": "Rock_Stone"
    },
    {
      "x": 15,
      "y": 38,
      "z": 18,
      "name": "Soil_Dirt"
    },
    {
      "x": 15,
      "y": 39,
      "z": 18,
      "name": "Soil_Dirt"
    },
    {
      "x": 15,
      "y": 40,
      "z": 18,
      "name": "Soil_Grass_Deep"
    },
    {
      "x": 15,
      "y": 35,
      "z": 19,
      "name": "Rock_Stone"
    },
    {
      "x": 15,
      "y": 36,
      "z": 19,
      "name": "Rock_Stone"
    },
    {
      "x": 15,
      "y": 37,
      "z": 19,
      "name": "Rock_Stone"
    },
    {
      "x": 15,
      "y": 38,
      "z": 19,
      "name": "Rock_Stone"
    },
    {
      "x": 15,
      "y": 39,
      "z": 19,
      "name": "Rock_Stone"
    },
    {
      "x": 15,
      "y": 40,
      "z": 19,
      "name": "Rock_Stone"
    },
    {
      "x": 15,
      "y": 41,
      "z": 19,
      "name": "Soil_Gravel"
    },
    {
      "x": 15,
      "y": 42,
      "z": 19,
      "name": "Soil_Gravel"
    },
    {
      "x": 15,
      "y": 43,
      "z": 19,
      "name": "Soil_Gravel"
    },
    {
      "x": 15,
      "y": 44,
      "z": 19,
      "name": "Rubble_Stone"
    },
    {
      "x": 15,
      "y": 35,
      "z": 20,
      "name": "Rock_Stone"
    },
    {
      "x": 15,
      "y": 36,
      "z": 20,
      "name": "Rock_Stone"
    },
    {
      "x": 15,
      "y": 37,
      "z": 20,
      "name": "Rock_Stone"
    },
    {
      "x": 15,
      "y": 38,
      "z": 20,
      "name": "Rock_Stone"
    },
    {
      "x": 15,
      "y": 39,
      "z": 20,
      "name": "Rock_Stone"
    },
    {
      "x": 15,
      "y": 40,
      "z": 20,
      "name": "Rock_Stone"
    },
    {
      "x": 15,
      "y": 41,
      "z": 20,
      "name": "Rock_Stone"
    },
    {
      "x": 15,
      "y": 42,
      "z": 20,
      "name": "Rock_Stone"
    },
    {
      "x": 15,
      "y": 43,
      "z": 20,
      "name": "Soil_Gravel"
    },
    {
      "x": 15,
      "y": 36,
      "z": 21,
      "name": "Rock_Stone"
    },
    {
      "x": 15,
      "y": 37,
      "z": 21,
      "name": "Rock_Stone"
    },
    {
      "x": 15,
      "y": 38,
      "z": 21,
      "name": "Rock_Stone"
    },
    {
      "x": 15,
      "y": 39,
