{
  "version": 8,
  "blockIdVersion": 8,
  "anchorX": 27,
  "anchorY": 24,
  "anchorZ": 15,
  "blocks": [
    {
      "x": 7,
      "y": 28,
      "z": 17,
      "name": "Rock_Stone"
    },
    {
      "x": 7,
      "y": 29,
      "z": 17,
      "name": "Rock_Stone"
    },
    {
      "x": 7,
      "y": 30,
      "z": 17,
      "name": "Rock_Stone"
    },
    {
      "x": 7,
      "y": 26,
      "z": 18,
      "name": "Rock_Stone"
    },
    {
      "x": 7,
      "y": 27,
      "z": 18,
      "name": "Rock_Stone"
    },
    {
      "x": 7,
      "y": 28,
      "z": 18,
      "name": "Rock_Stone"
    },
    {
      "x": 7,
      "y": 29,
      "z": 18,
      "name": "Rock_Stone"
    },
    {
      "x": 7,
      "y": 30,
      "z": 18,
      "name": "Rock_Stone"
    },
    {
      "x": 7,
      "y": 31,
      "z": 18,
      "name": "Rock_Stone"
    },
    {
      "x": 7,
      "y": 32,
      "z": 18,
      "name": "Rock_Stone"
    },
    {
      "x": 7,
      "y": 27,
      "z": 19,
      "name": "Rock_Stone"
    },
    {
      "x": 7,
      "y": 28,
      "z": 19,
      "name": "Rock_Stone"
    },
    {
      "x": 7,
      "y": 29,
      "z": 19,
      "name": "Rock_Stone"
    },
    {
      "x": 7,
      "y": 30,
      "z": 19,
      "name": "Rock_Stone"
    },
    {
      "x": 7,
      "y": 31,
      "z": 19,
      "name": "Rock_Stone"
    },
    {
      "x": 8,
      "y": 30,
      "z": 16,
      "name": "Rock_Stone"
    },
    {
      "x": 8,
      "y": 31,
      "z": 16,
      "name": "Rock_Stone"
    },
    {
      "x": 8,
      "y": 32,
      "z": 16,
      "name": "Rock_Stone"
    },
    {
      "x": 8,
      "y": 25,
      "z": 17,
      "name": "Rock_Stone"
    },
    {
      "x": 8,
      "y": 26,
      "z": 17,
      "name": "Rock_Stone"
    },
    {
      "x": 8,
      "y": 27,
      "z": 17,
      "name": "Rock_Stone"
    },
    {
      "x": 8,
      "y": 28,
      "z": 17,
      "name": "Rock_Stone"
    },
    {
      "x": 8,
      "y": 29,
      "z": 17,
      "name": "Rock_Stone"
    },
    {
      "x": 8,
      "y": 30,
      "z": 17,
      "name": "Rock_Stone"
    },
    {
      "x": 8,
      "y": 31,
      "z": 17,
      "name": "Rock_Stone"
    },
    {
      "x": 8,
      "y": 32,
      "z": 17,
      "name": "Rock_Stone"
    },
    {
      "x": 8,
      "y": 33,
      "z": 17,
      "name": "Soil_Grass_Deep"
    },
    {
      "x": 8,
      "y": 24,
      "z": 18,
      "name": "Rock_Stone"
    },
    {
      "x": 8,
      "y": 25,
      "z": 18,
      "name": "Rock_Stone"
    },
    {
      "x": 8,
      "y": 26,
      "z": 18,
      "name": "Rock_Stone"
    },
    {
      "x": 8,
      "y": 27,
      "z": 18,
      "name": "Rock_Stone"
    },
    {
      "x": 8,
      "y": 28,
      "z": 18,
      "name": "Rock_Stone"
    },
    {
      "x": 8,
      "y": 29,
      "z": 18,
      "name": "Rock_Stone"
    },
    {
      "x": 8,
      "y": 30,
      "z": 18,
      "name": "Rock_Stone"
    },
    {
      "x": 8,
      "y": 31,
      "z": 18,
      "name": "Rock_Stone"
    },
    {
      "x": 8,
      "y": 32,
      "z": 18,
      "name": "Soil_Dirt"
    },
    {
      "x": 8,
      "y": 33,
      "z": 18,
      "name": "Soil_Dirt"
    },
    {
      "x": 8,
      "y": 34,
      "z": 18,
      "name": "Soil_Leaves"
    },
    {
      "x": 8,
      "y": 24,
      "z": 19,
      "name": "Rock_Stone"
    },
    {
      "x": 8,
      "y": 25,
      "z": 19,
      "name": "Rock_Stone"
    },
    {
      "x": 8,
      "y": 26,
      "z": 19,
      "name": "Rock_Stone"
    },
    {
      "x": 8,
      "y": 27,
      "z": 19,
      "name": "Rock_Stone"
    },
    {
      "x": 8,
      "y": 28,
      "z": 19,
      "name": "Rock_Stone"
    },
    {
      "x": 8,
      "y": 29,
      "z": 19,
      "name": "Rock_Stone"
    },
    {
      "x": 8,
      "y": 30,
      "z": 19,
      "name": "Rock_Stone"
    },
    {
      "x": 8,
      "y": 31,
      "z": 19,
      "name": "Rock_Stone"
    },
    {
      "x": 8,
      "y": 32,
      "z": 19,
      "name": "Rock_Stone"
    },
    {
      "x": 8,
      "y": 33,
      "z": 19,
      "name": "Soil_Dirt"
    },
    {
      "x": 8,
      "y": 34,
      "z": 19,
      "name": "Soil_Leaves"
    },
    {
      "x": 8,
      "y": 29,
      "z": 20,
      "name": "Rock_Stone"
    },
    {
      "x": 8,
      "y": 30,
      "z": 20,
      "name": "Rock_Stone"
    },
    {
      "x": 8,
      "y": 31,
      "z": 20,
      "name": "Rock_Stone"
    },
    {
      "x": 8,
      "y": 32,
      "z": 20,
      "name": "Rock_Stone"
    },
    {
      "x": 8,
      "y": 33,
      "z": 20,
      "name": "Soil_Dirt"
    },
    {
      "x": 8,
      "y": 34,
      "z": 20,
      "name": "Soil_Grass_Deep"
    },
    {
      "x": 9,
      "y": 29,
      "z": 16,
      "name": "Rock_Stone"
    },
    {
      "x": 9,
      "y": 30,
      "z": 16,
      "name": "Rock_Stone"
    },
    {
      "x": 9,
      "y": 31,
      "z": 16,
      "name": "Rock_Stone"
    },
    {
      "x": 9,
      "y": 32,
      "z": 16,
      "name": "Rock_Stone"
    },
    {
      "x": 9,
      "y": 33,
      "z": 16,
      "name": "Soil_Dirt"
    },
    {
      "x": 9,
      "y": 34,
      "z": 16,
      "name": "Soil_Grass_Deep"
    },
    {
      "x": 9,
      "y": 22,
      "z": 17,
      "name": "Rock_Stone"
    },
    {
      "x": 9,
      "y": 23,
      "z": 17,
      "name": "Rock_Stone"
    },
    {
      "x": 9,
      "y": 24,
      "z": 17,
      "name": "Rock_Stone"
    },
    {
      "x": 9,
      "y": 25,
      "z": 17,
      "name": "Rock_Stone"
    },
    {
      "x": 9,
      "y": 26,
      "z": 17,
      "name": "Rock_Stone"
    },
    {
      "x": 9,
      "y": 27,
      "z": 17,
      "name": "Rock_Stone"
    },
    {
      "x": 9,
      "y": 28,
      "z": 17,
      "name": "Rock_Stone"
    },
    {
      "x": 9,
      "y": 29,
      "z": 17,
      "name": "Rock_Stone"
    },
    {
      "x": 9,
      "y": 30,
      "z": 17,
      "name": "Rock_Stone"
    },
    {
      "x": 9,
      "y": 31,
      "z": 17,
      "name": "Rock_Stone"
    },
    {
      "x": 9,
      "y": 32,
      "z": 17,
      "name": "Rock_Stone"
    },
    {
      "x": 9,
      "y": 33,
      "z": 17,
      "name": "Soil_Dirt"
    },
    {
      "x": 9,
      "y": 34,
      "z": 17,
      "name": "Soil_Dirt"
    },
    {
      "x": 9,
      "y": 35,
      "z": 17,
      "name": "Soil_Dirt"
    },
    {
      "x": 9,
      "y": 36,
      "z": 17,
      "name": "Soil_Leaves"
    },
    {
      "x": 9,
      "y": 37,
      "z": 17,
      "name": "Plant_Grass_Lush"
    },
    {
      "x": 9,
      "y": 22,
      "z": 18,
      "name": "Rock_Stone"
    },
    {
      "x": 9,
      "y": 23,
      "z": 18,
      "name": "Rock_Stone"
    },
    {
      "x": 9,
      "y": 24,
      "z": 18,
      "name": "Rock_Stone"
    },
    {
      "x": 9,
      "y": 25,
      "z": 18,
      "name": "Rock_Stone"
    },
    {
      "x": 9,
      "y": 26,
      "z": 18,
      "name": "Rock_Stone"
    },
    {
      "x": 9,
      "y": 27,
      "z": 18,
      "name": "Rock_Stone"
    },
    {
      "x": 9,
      "y": 28,
      "z": 18,
      "name": "Rock_Stone"
    },
    {
      "x": 9,
      "y": 29,
      "z": 18,
      "name": "Rock_Stone"
    },
    {
      "x": 9,
      "y": 30,
      "z": 18,
      "name": "Rock_Stone"
    },
    {
      "x": 9,
      "y": 31,
      "z": 18,
      "name": "Rock_Stone"
    },
    {
      "x": 9,
      "y": 32,
      "z": 18,
      "name": "Rock_Stone"
    },
    {
      "x": 9,
      "y": 33,
      "z": 18,
      "name": "Soil_Dirt"
    },
    {
      "x": 9,
      "y": 34,
      "z": 18,
      "name": "Soil_Dirt"
    },
    {
      "x": 9,
      "y": 35,
      "z": 18,
      "name": "Soil_Dirt"
    },
    {
      "x": 9,
      "y": 36,
      "z": 18,
      "name": "Soil_Leaves"
    },
    {
      "x": 9,
      "y": 23,
      "z": 19,
      "name": "Rock_Stone"
    },
    {
      "x": 9,
      "y": 24,
      "z": 19,
      "name": "Rock_Stone"
    },
    {
      "x": 9,
      "y": 25,
      "z": 19,
      "name": "Rock_Stone"
    },
    {
      "x": 9,
      "y": 26,
      "z": 19,
      "name": "Rock_Stone"
    },
    {
      "x": 9,
      "y": 27,
      "z": 19,
      "name": "Rock_Stone"
    },
    {
      "x": 9,
      "y": 28,
      "z": 19,
      "name": "Rock_Stone"
    },
    {
      "x": 9,
      "y": 29,
      "z": 19,
      "name": "Rock_Stone"
    },
    {
      "x": 9,
      "y": 30,
      "z": 19,
      "name": "Rock_Stone"
    },
    {
      "x": 9,
      "y": 31,
      "z": 19,
      "name": "Rock_Stone"
    },
    {
      "x": 9,
      "y": 32,
      "z": 19,
      "name": "Rock_Stone"
    },
    {
      "x": 9,
      "y": 33,
      "z": 19,
      "name": "Soil_Dirt"
    },
    {
      "x": 9,
      "y": 34,
      "z": 19,
      "name": "Soil_Dirt"
    },
    {
      "x": 9,
      "y": 35,
      "z": 19,
      "name": "Soil_Dirt"
    },
    {
      "x": 9,
      "y": 36,
      "z": 19,
      "name": "Soil_Dirt"
    },
    {
      "x": 9,
      "y": 37,
      "z": 19,
      "name": "Soil_Leaves"
    },
    {
      "x": 9,
      "y": 27,
      "z": 20,
      "name": "Rock_Stone"
    },
    {
      "x": 9,
      "y": 28,
      "z": 20,
      "name": "Rock_Stone"
    },
    {
      "x": 9,
      "y": 29,
      "z": 20,
      "name": "Rock_Stone"
    },
    {
      "x": 9,
      "y": 30,
      "z": 20,
      "name": "Rock_Stone"
    },
    {
      "x": 9,
      "y": 31,
      "z": 20,
      "name": "Rock_Stone"
    },
    {
      "x": 9,
      "y": 32,
      "z": 20,
      "name": "Rock_Stone"
    },
    {
      "x": 9,
      "y": 33,
      "z": 20,
      "name": "Soil_Dirt"
    },
    {
      "x": 9,
      "y": 34,
      "z": 20,
      "name": "Soil_Dirt"
    },
    {
      "x": 9,
      "y": 35,
      "z": 20,
      "name": "Soil_Dirt"
    },
    {
      "x": 9,
      "y": 36,
      "z": 20,
      "name": "Soil_Dirt"
    },
    {
      "x": 9,
      "y": 37,
      "z": 20,
      "name": "Soil_Grass_Deep"
    },
    {
      "x": 9,
      "y": 38,
      "z": 20,
      "name": "Plant_Grass_Lush"
    },
    {
      "x": 9,
      "y": 33,
      "z": 21,
      "name": "Rock_Stone"
    },
    {
      "x": 9,
      "y": 34,
      "z": 21,
      "name": "Rock_Stone"
    },
    {
      "x": 9,
      "y": 35,
      "z": 21,
      "name": "Soil_Dirt"
    },
    {
      "x": 9,
      "y": 36,
      "z": 21,
      "name": "Soil_Dirt"
    },
    {
      "x": 9,
      "y": 37,
      "z": 21,
      "name": "Soil_Grass_Deep"
    },
    {
      "x": 9,
      "y": 38,
      "z": 21,
      "name": "Plant_Fern_Winter"
    },
    {
      "x": 10,
      "y": 29,
      "z": 16,
      "name": "Rock_Stone"
    },
    {
      "x": 10,
      "y": 30,
      "z": 16,
      "name": "Rock_Stone"
    },
    {
      "x": 10,
      "y": 31,
      "z": 16,
      "name": "Rock_Stone"
    },
    {
      "x": 10,
      "y": 32,
      "z": 16,
      "name": "Rock_Stone"
    },
    {
      "x": 10,
      "y": 33,
      "z": 16,
      "name": "Rock_Stone"
    },
    {
      "x": 10,
      "y": 34,
      "z": 16,
      "name": "Soil_Dirt"
    },
    {
      "x": 10,
      "y": 35,
      "z": 16,
      "name": "Soil_Grass_Deep"
    },
    {
      "x": 10,
      "y": 22,
      "z": 17,
      "name": "Rock_Stone"
    },
    {
      "x": 10,
      "y": 23,
      "z": 17,
      "name": "Rock_Stone"
    },
    {
      "x": 10,
      "y": 24,
      "z": 17,
      "name": "Rock_Stone"
    },
    {
      "x": 10,
      "y": 25,
      "z": 17,
      "name": "Rock_Stone"
    },
    {
      "x": 10,
      "y": 26,
      "z": 17,
      "name": "Rock_Stone"
    },
    {
      "x": 10,
      "y": 27,
      "z": 17,
      "name": "Rock_Stone"
    },
    {
      "x": 10,
      "y": 28,
      "z": 17,
      "name": "Rock_Stone"
    },
    {
      "x": 10,
      "y": 29,
      "z": 17,
      "name": "Rock_Stone"
    },
    {
      "x": 10,
      "y": 30,
      "z": 17,
      "name": "Rock_Stone"
    },
    {
      "x": 10,
      "y": 31,
      "z": 17,
      "name": "Rock_Stone"
    },
    {
      "x": 10,
      "y": 32,
      "z": 17,
      "name": "Rock_Stone"
    },
    {
      "x": 10,
      "y": 33,
      "z": 17,
      "name": "Soil_Dirt"
    },
    {
      "x": 10,
      "y": 34,
      "z": 17,
      "name": "Soil_Dirt"
    },
    {
      "x": 10,
      "y": 35,
      "z": 17,
      "name": "Soil_Dirt"
    },
    {
      "x": 10,
      "y": 36,
      "z": 17,
      "name": "Soil_Dirt"
    },
    {
      "x": 10,
      "y": 37,
      "z": 17,
      "name": "Soil_Leaves"
    },
    {
      "x": 10,
      "y": 21,
      "z": 18,
      "name": "Rock_Stone"
    },
    {
      "x": 10,
      "y": 22,
      "z": 18,
      "name": "Rock_Stone"
    },
    {
      "x": 10,
      "y": 23,
      "z": 18,
      "name": "Rock_Stone"
    },
    {
      "x": 10,
      "y": 24,
      "z": 18,
      "name": "Rock_Stone"
    },
    {
      "x": 10,
      "y": 25,
      "z": 18,
      "name": "Rock_Stone"
    },
    {
      "x": 10,
      "y": 26,
      "z": 18,
      "name": "Rock_Stone"
    },
    {
      "x": 10,
      "y": 27,
      "z": 18,
      "name": "Rock_Stone"
    },
    {
      "x": 10,
      "y": 28,
      "z": 18,
      "name": "Rock_Stone"
    },
    {
      "x": 10,
      "y": 29,
      "z": 18,
      "name": "Rock_Stone"
    },
    {
      "x": 10,
      "y": 30,
      "z": 18,
      "name": "Rock_Stone"
    },
    {
      "x": 10,
      "y": 31,
      "z": 18,
      "name": "Rock_Stone"
    },
    {
      "x": 10,
      "y": 32,
      "z": 18,
      "name": "Rock_Stone"
    },
    {
      "x": 10,
      "y": 33,
      "z": 18,
      "name": "Soil_Dirt"
    },
    {
      "x": 10,
      "y": 34,
      "z": 18,
      "name": "Soil_Dirt"
    },
    {
      "x": 10,
      "y": 35,
      "z": 18,
      "name": "Soil_Dirt"
    },
    {
      "x": 10,
      "y": 36,
      "z": 18,
      "name": "Soil_Dirt"
    },
    {
      "x": 10,
      "y": 37,
      "z": 18,
      "name": "Soil_Leaves"
    },
    {
      "x": 10,
      "y": 20,
      "z": 19,
      "name": "Rock_Stone"
    },
    {
      "x": 10,
      "y": 21,
      "z": 19,
      "name": "Rock_Stone"
    },
    {
      "x": 10,
      "y": 22,
      "z": 19,
      "name": "Rock_Stone"
    },
    {
      "x": 10,
      "y": 23,
      "z": 19,
      "name": "Rock_Stone"
    },
    {
      "x": 10,
      "y": 24,
      "z": 19,
      "name": "Rock_Stone"
    },
    {
      "x": 10,
      "y": 25,
      "z": 19,
      "name": "Rock_Stone"
    },
    {
      "x": 10,
      "y": 27,
      "z": 19,
      "name": "Rock_Stone"
    },
    {
      "x": 10,
      "y": 28,
      "z": 19,
      "name": "Rock_Stone"
    },
    {
      "x": 10,
      "y": 29,
      "z": 19,
      "name": "Rock_Stone"
    },
    {
      "x": 10,
      "y": 30,
      "z": 19,
      "name": "Rock_Stone"
    },
    {
      "x": 10,
      "y": 31,
      "z": 19,
      "name": "Rock_Stone"
    },
    {
      "x": 10,
      "y": 32,
      "z": 19,
      "name": "Rock_Stone"
    },
    {
      "x": 10,
      "y": 33,
      "z": 19,
      "name": "Soil_Dirt"
    },
    {
      "x": 10,
      "y": 34,
      "z": 19,
      "name": "Soil_Dirt"
    },
    {
      "x": 10,
      "y": 35,
      "z": 19,
      "name": "Soil_Dirt"
    },
    {
      "x": 10,
      "y": 36,
      "z": 19,
      "name": "Soil_Dirt"
    },
    {
      "x": 10,
      "y": 37,
      "z": 19,
      "name": "Soil_Leaves"
    },
    {
      "x": 10,
      "y": 21,
      "z": 20,
      "name": "Rock_Stone"
    },
    {
      "x": 10,
      "y": 22,
      "z": 20,
      "name": "Rock_Stone"
    },
    {
      "x": 10,
      "y": 23,
      "z": 20,
      "name": "Rock_Stone"
    },
    {
      "x": 10,
      "y": 28,
      "z": 20,
      "name": "Rock_Stone"
    },
    {
      "x": 10,
      "y": 29,
      "z": 20,
      "name": "Rock_Stone"
    },
    {
      "x": 10,
      "y": 30,
      "z": 20,
      "name": "Rock_Stone"
    },
    {
      "x": 10,
      "y": 31,
      "z": 20,
      "name": "Rock_Stone"
    },
    {
      "x": 10,
      "y": 32,
      "z": 20,
      "name": "Rock_Stone"
    },
    {
      "x": 10,
      "y": 33,
      "z": 20,
      "name": "Rock_Stone"
    },
    {
      "x": 10,
      "y": 34,
      "z": 20,
      "name": "Soil_Dirt"
    },
    {
      "x": 10,
      "y": 35,
      "z": 20,
      "name": "Soil_Dirt"
    },
    {
      "x": 10,
      "y": 36,
      "z": 20,
      "name": "Soil_Dirt"
    },
    {
      "x": 10,
      "y": 37,
      "z": 20,
      "name": "Soil_Grass_Deep"
    },
    {
      "x": 10,
      "y": 32,
      "z": 21,
      "name": "Rock_Stone"
    },
    {
      "x": 10,
      "y": 33,
      "z": 21,
      "name": "Rock_Stone"
    },
    {
      "x": 10,
      "y": 34,
      "z": 21,
      "name": "Rock_Stone"
    },
    {
      "x": 10,
      "y": 35,
      "z": 21,
      "name": "Soil_Dirt"
    },
    {
      "x": 10,
      "y": 36,
      "z": 21,
      "name": "Soil_Dirt"
    },
    {
      "x": 10,
      "y": 37,
      "z": 21,
      "name": "Soil_Grass_Deep"
    },
    {
      "x": 10,
      "y": 35,
      "z": 22,
      "name": "Soil_Dirt"
    },
    {
      "x": 10,
      "y": 36,
      "z": 22,
      "name": "Soil_Dirt"
    },
    {
      "x": 10,
      "y": 37,
      "z": 22,
      "name": "Soil_Grass_Deep"
    },
    {
      "x": 11,
      "y": 34,
      "z": 15,
      "name": "Rock_Stone"
    },
    {
      "x": 11,
      "y": 35,
      "z": 15,
      "name": "Rock_Stone"
    },
    {
      "x": 11,
      "y": 36,
      "z": 15,
      "name": "Soil_Grass_Deep"
    },
    {
      "x": 11,
      "y": 37,
      "z": 15,
      "name": "Plant_Grass_Lush"
    },
    {
      "x": 11,
      "y": 31,
      "z": 16,
      "name": "Rock_Stone"
    },
    {
      "x": 11,
      "y": 32,
      "z": 16,
      "name": "Rock_Stone"
    },
    {
      "x": 11,
      "y": 33,
      "z": 16,
      "name": "Rock_Stone"
    },
    {
      "x": 11,
      "y": 34,
      "z": 16,
      "name": "Rock_Stone"
    },
    {
      "x": 11,
      "y": 35,
      "z": 16,
      "name": "Rock_Stone"
    },
    {
      "x": 11,
      "y": 36,
      "z": 16,
      "name": "Soil_Dirt"
    },
    {
      "x": 11,
      "y": 37,
      "z": 16,
      "name": "Rock_Stone"
    },
    {
      "x": 11,
      "y": 38,
      "z": 16,
      "name": "Soil_Dirt"
    },
    {
      "x": 11,
      "y": 39,
      "z": 16,
      "name": "Soil_Leaves"
    },
    {
      "x": 11,
      "y": 20,
      "z": 17,
      "name": "Rock_Stone"
    },
    {
      "x": 11,
      "y": 21,
      "z": 17,
      "name": "Rock_Stone"
    },
    {
      "x": 11,
      "y": 22,
      "z": 17,
      "name": "Rock_Stone"
    },
    {
      "x": 11,
      "y": 23,
      "z": 17,
      "name": "Rock_Stone"
    },
    {
      "x": 11,
      "y": 24,
      "z": 17,
      "name": "Rock_Stone"
    },
    {
      "x": 11,
      "y": 25,
      "z": 17,
      "name": "Rock_Stone"
    },
    {
      "x": 11,
      "y": 26,
      "z": 17,
      "name": "Rock_Stone"
    },
    {
      "x": 11,
      "y": 28,
      "z": 17,
      "name": "Rock_Stone"
    },
    {
      "x": 11,
      "y": 29,
      "z": 17,
      "name": "Rock_Stone"
    },
    {
      "x": 11,
      "y": 30,
      "z": 17,
      "name": "Rock_Stone"
    },
    {
      "x": 11,
      "y": 31,
      "z": 17,
      "name": "Rock_Stone"
    },
    {
      "x": 11,
      "y": 32,
      "z": 17,
      "name": "Rock_Stone"
    },
    {
      "x": 11,
      "y": 33,
      "z": 17,
      "name": "Rock_Stone"
    },
    {
      "x": 11,
      "y": 34,
      "z": 17,
      "name": "Rock_Stone"
    },
    {
      "x": 11,
      "y": 35,
      "z": 17,
      "name": "Soil_Dirt"
    },
    {
      "x": 11,
      "y": 36,
      "z": 17,
      "name": "Soil_Dirt"
    },
    {
      "x": 11,
      "y": 37,
      "z": 17,
      "name": "Soil_Dirt"
    },
    {
      "x": 11,
      "y": 38,
      "z": 17,
      "name": "Soil_Dirt"
    },
    {
      "x": 11,
      "y": 39,
      "z": 17,
      "name": "Soil_Leaves"
    },
    {
      "x": 11,
      "y": 40,
      "z": 17,
      "name": "Plant_Grass_Sharp"
    },
    {
      "x": 11,
      "y": 19,
      "z": 18,
      "name": "Rock_Stone"
    },
    {
      "x": 11,
      "y": 20,
      "z": 18,
      "name": "Rock_Stone"
    },
    {
      "x": 11,
      "y": 21,
      "z": 18,
      "name": "Rock_Stone"
    },
    {
      "x": 11,
      "y": 22,
      "z": 18,
      "name": "Rock_Stone"
    },
    {
      "x": 11,
      "y": 23,
      "z": 18,
      "name": "Rock_Stone"
    },
    {
      "x": 11,
      "y": 24,
      "z": 18,
      "name": "Rock_Stone"
    },
    {
      "x": 11,
      "y": 25,
      "z": 18,
      "name": "Rock_Stone"
    },
    {
      "x": 11,
      "y": 26,
      "z": 18,
      "name": "Rock_Stone"
    },
    {
      "x": 11,
      "y": 27,
      "z": 18,
      "name": "Rock_Stone"
    },
    {
      "x": 11,
      "y": 28,
      "z": 18,
      "name": "Rock_Stone"
    },
    {
      "x": 11,
      "y": 29,
      "z": 18,
      "name": "Rock_Stone"
    },
    {
      "x": 11,
      "y": 30,
      "z": 18,
      "name": "Rock_Stone"
    },
    {
      "x": 11,
      "y": 31,
      "z": 18,
      "name": "Rock_Stone"
    },
    {
      "x": 11,
      "y": 32,
      "z": 18,
      "name": "Rock_Stone"
    },
    {
      "x": 11,
      "y": 33,
      "z": 18,
      "name": "Rock_Stone"
    },
    {
      "x": 11,
      "y": 34,
      "z": 18,
      "name": "Soil_Dirt"
    },
    {
      "x": 11,
      "y": 35,
      "z": 18,
      "name": "Soil_Dirt"
    },
    {
      "x": 11,
      "y": 36,
      "z": 18,
      "name": "Soil_Dirt"
    },
    {
      "x": 11,
      "y": 37,
      "z": 18,
      "name": "Soil_Dirt"
    },
    {
      "x": 11,
      "y": 38,
      "z": 18,
      "name": "Soil_Dirt"
    },
    {
      "x": 11,
      "y": 39,
      "z": 18,
      "name": "Soil_Leaves"
    },
    {
      "x": 11,
      "y": 40,
      "z": 18,
      "name": "Plant_Grass_Sharp"
    },
    {
      "x": 11,
      "y": 19,
      "z": 19,
      "name": "Rock_Stone"
    },
    {
      "x": 11,
      "y": 20,
      "z": 19,
      "name": "Rock_Stone"
    },
    {
      "x": 11,
      "y": 21,
      "z": 19,
      "name": "Rock_Stone"
    },
    {
      "x": 11,
      "y": 22,
      "z": 19,
      "name": "Rock_Stone"
    },
    {
      "x": 11,
      "y": 23,
      "z": 19,
      "name": "Rock_Stone"
    },
    {
      "x": 11,
      "y": 24,
      "z": 19,
      "name": "Rock_Stone"
    },
    {
      "x": 11,
      "y": 25,
      "z": 19,
      "name": "Rock_Stone"
    },
    {
      "x": 11,
      "y": 29,
      "z": 19,
      "name": "Rock_Stone"
    },
    {
      "x": 11,
      "y": 30,
      "z": 19,
      "name": "Rock_Stone"
    },
    {
      "x": 11,
      "y": 31,
      "z": 19,
      "name": "Rock_Stone"
    },
    {
      "x": 11,
      "y": 32,
      "z": 19,
      "name": "Rock_Stone"
    },
    {
      "x": 11,
      "y": 33,
      "z": 19,
      "name": "Rock_Stone"
    },
    {
      "x": 11,
      "y": 34,
      "z": 19,
      "name": "Rock_Stone"
    },
    {
      "x": 11,
      "y": 35,
      "z": 19,
      "name": "Soil_Dirt"
    },
    {
      "x": 11,
      "y": 36,
      "z": 19,
      "name": "Soil_Dirt"
    },
    {
      "x": 11,
      "y": 37,
      "z": 19,
      "name": "Soil_Dirt"
    },
    {
      "x": 11,
      "y": 38,
      "z": 19,
      "name": "Soil_Dirt"
    },
    {
      "x": 11,
      "y": 39,
      "z": 19,
      "name": "Soil_Leaves"
    },
    {
      "x": 11,
      "y": 40,
      "z": 19,
      "name": "Plant_Fern_Winter"
    },
    {
      "x": 11,
      "y": 19,
      "z": 20,
      "name": "Rock_Stone"
    },
    {
      "x": 11,
      "y": 20,
      "z": 20,
      "name": "Rock_Stone"
    },
    {
      "x": 11,
      "y": 21,
      "z": 20,
      "name": "Rock_Stone"
    },
    {
      "x": 11,
      "y": 22,
      "z": 20,
      "name": "Rock_Stone"
    },
    {
      "x": 11,
      "y": 23,
      "z": 20,
      "name": "Rock_Stone"
    },
    {
      "x": 11,
      "y": 31,
      "z": 20,
      "name": "Rock_Stone"
    },
    {
      "x": 11,
      "y": 32,
      "z": 20,
      "name": "Rock_Stone"
    },
    {
      "x": 11,
      "y": 33,
      "z": 20,
      "name": "Rock_Stone"
    },
    {
      "x": 11,
      "y": 34,
      "z": 20,
      "name": "Rock_Stone"
    },
    {
      "x": 11,
      "y": 35,
      "z": 20,
      "name": "Soil_Dirt"
    },
    {
      "x": 11,
      "y": 36,
      "z": 20,
      "name": "Soil_Dirt"
    },
    {
      "x": 11,
      "y": 37,
      "z": 20,
      "name": "Soil_Dirt"
    },
    {
      "x": 11,
      "y": 38,
      "z": 20,
      "name": "Soil_Dirt"
    },
    {
      "x": 11,
      "y": 39,
      "z": 20,
      "name": "Soil_Leaves"
    },
    {
      "x": 11,
      "y": 40,
      "z": 20,
      "name": "Plant_Grass_Sharp"
    },
    {
      "x": 11,
      "y": 32,
      "z": 21,
      "name": "Rock_Stone"
    },
    {
      "x": 11,
      "y": 33,
      "z": 21,
      "name": "Rock_Stone"
    },
    {
      "x": 11,
      "y": 34,
      "z": 21,
      "name": "Rock_Stone"
    },
    {
      "x": 11,
      "y": 35,
      "z": 21,
      "name": "Soil_Dirt"
    },
    {
      "x": 11,
      "y": 36,
      "z": 21,
      "name": "Soil_Dirt"
    },
    {
      "x": 11,
      "y": 37,
      "z": 21,
      "name": "Soil_Dirt"
    },
    {
      "x": 11,
      "y": 38,
      "z": 21,
      "name": "Soil_Dirt"
    },
    {
      "x": 11,
      "y": 39,
      "z": 21,
      "name": "Soil_Grass_Deep"
    },
    {
      "x": 11,
      "y": 40,
      "z": 21,
      "name": "Plant_Grass_Lush"
    },
    {
      "x": 11,
      "y": 35,
      "z": 22,
      "name": "Rock_Stone"
    },
    {
      "x": 11,
      "y": 36,
      "z": 22,
      "name": "Soil_Dirt"
    },
    {
      "x": 11,
      "y": 37,
      "z": 22,
      "name": "Soil_Grass_Deep"
    },
    {
      "x": 11,
      "y": 35,
      "z": 23,
      "name": "Rock_Stone"
    },
    {
      "x": 11,
      "y": 36,
      "z": 23,
      "name": "Soil_Dirt"
    },
    {
      "x": 11,
      "y": 28,
      "z": 30,
      "name": "Rock_Stone"
    },
    {
      "x": 11,
      "y": 29,
      "z": 30,
      "name": "Rock_Stone"
    },
    {
      "x": 11,
      "y": 26,
      "z": 31,
      "name": "Rock_Stone"
    },
    {
      "x": 11,
      "y": 27,
      "z": 31,
      "name": "Rock_Stone"
    },
    {
      "x": 11,
      "y": 28,
      "z": 31,
      "name": "Rock_Stone"
    },
    {
      "x": 11,
      "y": 29,
      "z": 31,
      "name": "Rock_Stone"
    },
    {
      "x": 11,
      "y": 30,
      "z": 31,
      "name": "Rock_Stone"
    },
    {
      "x": 11,
      "y": 31,
      "z": 31,
      "name": "Rock_Stone"
    },
    {
      "x": 11,
      "y": 27,
      "z": 32,
      "name": "Rock_Stone"
    },
    {
      "x": 11,
      "y": 28,
      "z": 32,
      "name": "Rock_Stone"
    },
    {
      "x": 12,
      "y": 33,
      "z": 15,
      "name": "Rock_Stone"
    },
    {
      "x": 12,
      "y": 34,
      "z": 15,
      "name": "Rock_Stone"
    },
    {
      "x": 12,
      "y": 35,
      "z": 15,
      "name": "Rock_Stone"
    },
    {
      "x": 12,
      "y": 36,
      "z": 15,
      "name": "Rock_Stone"
    },
    {
      "x": 12,
      "y": 37,
      "z": 15,
      "name": "Rock_Stone"
    },
    {
      "x": 12,
      "y": 38,
      "z": 15,
      "name": "Soil_Leaves"
    },
    {
      "x": 12,
      "y": 32,
      "z": 16,
      "name": "Rock_Stone"
    },
    {
      "x": 12,
      "y": 33,
      "z": 16,
      "name": "Rock_Stone"
    },
    {
      "x": 12,
      "y": 34,
      "z": 16,
      "name": "Rock_Stone"
    },
    {
      "x": 12,
      "y": 35,
      "z": 16,
      "name": "Rock_Stone"
    },
    {
      "x": 12,
      "y": 36,
      "z": 16,
      "name": "Rock_Stone"
    },
    {
      "x": 12,
      "y": 37,
      "z": 16,
      "name": "Rock_Stone"
    },
    {
      "x": 12,
      "y": 38,
      "z": 16,
      "name": "Soil_Dirt"
    },
    {
      "x": 12,
      "y": 39,
      "z": 16,
      "name": "Soil_Leaves"
    },
    {
      "x": 12,
      "y": 20,
      "z": 17,
      "name": "Rock_Stone"
    },
    {
      "x": 12,
      "y": 21,
      "z": 17,
      "name": "Rock_Stone"
    },
    {
      "x": 12,
      "y": 22,
      "z": 17,
      "name": "Rock_Stone"
    },
    {
      "x": 12,
      "y": 23,
      "z": 17,
      "name": "Rock_Stone"
    },
    {
      "x": 12,
      "y": 30,
      "z": 17,
      "name": "Rock_Stone"
    },
    {
      "x": 12,
      "y": 31,
      "z": 17,
      "name": "Rock_Stone"
    },
    {
      "x": 12,
      "y": 32,
      "z": 17,
      "name": "Rock_Stone"
    },
    {
      "x": 12,
      "y": 33,
      "z": 17,
      "name": "Rock_Stone"
    },
    {
      "x": 12,
      "y": 34,
      "z": 17,
      "name": "Rock_Stone"
    },
    {
      "x": 12,
      "y": 35,
      "z": 17,
      "name": "Rock_Stone"
    },
    {
      "x": 12,
      "y": 36,
      "z": 17,
      "name": "Rock_Stone"
    },
    {
      "x": 12,
      "y": 37,
      "z": 17,
      "name": "Rock_Stone"
    },
    {
      "x": 12,
      "y": 38,
      "z": 17,
      "name": "Soil_Dirt"
    },
    {
      "x": 12,
      "y": 39,
      "z": 17,
      "name": "Soil_Leaves"
    },
    {
      "x": 12,
      "y": 19,
      "z": 18,
      "name": "Rock_Stone"
    },
    {
      "x": 12,
      "y": 20,
      "z": 18,
      "name": "Rock_Stone"
    },
    {
      "x": 12,
      "y": 21,
      "z": 18,
      "name": "Rock_Stone"
    },
    {
      "x": 12,
      "y": 22,
      "z": 18,
      "name": "Rock_Stone"
    },
    {
      "x": 12,
      "y": 23,
      "z": 18,
      "name": "Rock_Stone"
    },
    {
      "x": 12,
      "y": 24,
      "z": 18,
      "name": "Rock_Stone"
    },
    {
      "x": 12,
      "y": 30,
      "z": 18,
      "name": "Rock_Stone"
    },
    {
      "x": 12,
      "y": 31,
      "z": 18,
      "name": "Rock_Stone"
    },
    {
      "x": 12,
      "y": 32,
      "z": 18,
      "name": "Rock_Stone"
    },
    {
      "x": 12,
      "y": 33,
      "z": 18,
      "name": "Rock_Stone"
    },
    {
      "x": 12,
      "y": 34,
      "z": 18,
      "name": "Rock_Stone"
    },
    {
      "x": 12,
      "y": 35,
      "z": 18,
      "name": "Rock_Stone"
    },
    {
      "x": 12,
      "y": 36,
      "z": 18,
      "name": "Soil_Dirt"
    },
    {
      "x": 12,
      "y": 37,
      "z": 18,
      "name": "Rock_Stone"
    },
    {
      "x": 12,
      "y": 38,
      "z": 18,
      "name": "Soil_Dirt"
    },
    {
      "x": 12,
      "y": 39,
      "z": 18,
      "name": "Soil_Leaves"
    },
    {
      "x": 12,
      "y": 40,
      "z": 18,
      "name": "Plant_Grass_Lush"
    },
    {
      "x": 12,
      "y": 18,
      "z": 19,
      "name": "Rock_Stone"
    },
    {
      "x": 12,
      "y": 19,
      "z": 19,
      "name": "Rock_Stone"
    },
    {
      "x": 12,
      "y": 20,
      "z": 19,
      "name": "Rock_Stone"
    },
    {
      "x": 12,
      "y": 21,
      "z": 19,
      "name": "Rock_Stone"
    },
    {
      "x": 12,
      "y": 22,
      "z": 19,
      "name": "Rock_Stone"
    },
    {
      "x": 12,
      "y": 23,
      "z": 19,
      "name": "Rock_Stone"
    },
    {
      "x": 12,
      "y": 24,
      "z": 19,
      "name": "Rock_Stone"
    },
    {
      "x": 12,
      "y": 31,
      "z": 19,
      "name": "Rock_Stone"
    },
    {
      "x": 12,
      "y": 32,
      "z": 19,
      "name": "Rock_Stone"
    },
    {
      "x": 12,
      "y": 33,
      "z": 19,
      "name": "Rock_Stone"
    },
    {
      "x": 12,
      "y": 34,
      "z": 19,
      "name": "Rock_Stone"
    },
    {
      "x": 12,
      "y": 35,
      "z": 19,
      "name": "Rock_Stone"
    },
    {
      "x": 12,
      "y": 36,
      "z": 19,
      "name": "Rock_Stone"
    },
    {
      "x": 12,
      "y": 37,
      "z": 19,
      "name": "Soil_Dirt"
    },
    {
      "x": 12,
      "y": 38,
      "z": 19,
      "name": "Soil_Dirt"
    },
    {
      "x": 12,
      "y": 39,
      "z": 19,
      "name": "Soil_Leaves"
    },
    {
      "x": 12,
      "y": 18,
      "z": 20,
      "name": "Rock_Stone"
    },
    {
      "x": 12,
      "y": 19,
      "z": 20,
      "name": "Rock_Stone"
    },
    {
      "x": 12,
      "y": 20,
      "z": 20,
      "name": "Rock_Stone"
    },
    {
      "x": 12,
      "y": 21,
      "z": 20,
      "name": "Rock_Stone"
    },
    {
      "x": 12,
      "y": 22,
      "z": 20,
      "name": "Rock_Stone"
    },
    {
      "x": 12,
      "y": 32,
      "z": 20,
      "name": "Rock_Stone"
    },
    {
      "x": 12,
      "y": 33,
      "z": 20,
      "name": "Rock_Stone"
    },
    {
      "x": 12,
      "y": 34,
      "z": 20,
      "name": "Rock_Stone"
    },
    {
      "x": 12,
      "y": 35,
      "z": 20,
      "name": "Rock_Stone"
    },
    {
      "x": 12,
      "y": 36,
      "z": 20,
      "name": "Soil_Dirt"
    },
    {
      "x": 12,
      "y": 37,
      "z": 20,
      "name": "Soil_Dirt"
    },
    {
      "x": 12,
      "y": 38,
      "z": 20,
      "name": "Soil_Dirt"
    },
    {
      "x": 12,
      "y": 39,
      "z": 20,
      "name": "Soil_Grass_Deep"
    },
    {
      "x": 12,
      "y": 40,
      "z": 20,
      "name": "Plant_Grass_Lush"
    },
    {
      "x": 12,
      "y": 18,
      "z": 21,
      "name": "Rock_Stone"
    },
    {
      "x": 12,
      "y": 19,
      "z": 21,
      "name": "Rock_Stone"
    },
    {
      "x": 12,
      "y": 32,
      "z": 21,
      "name": "Rock_Stone"
    },
    {
      "x": 12,
      "y": 33,
      "z": 21,
      "name": "Rock_Stone"
    },
    {
      "x": 12,
      "y": 34,
      "z": 21,
      "name": "Rock_Stone"
    },
    {
      "x": 12,
      "y": 35,
      "z": 21,
      "name": "Rock_Stone"
    },
    {
      "x": 12,
      "y": 36,
      "z": 21,
      "name": "Soil_Dirt"
    },
    {
      "x": 12,
      "y": 37,
      "z": 21,
      "name": "Soil_Dirt"
    },
    {
      "x": 12,
      "y": 38,
      "z": 21,
      "name": "Soil_Dirt"
    },
    {
      "x": 12,
      "y": 39,
      "z": 21,
      "name": "Soil_Grass_Deep"
    },
    {
      "x": 12,
      "y": 34,
      "z": 22,
      "name": "Rock_Stone"
    },
    {
      "x": 12,
      "y": 35,
      "z": 22,
      "name": "Rock_Stone"
    },
    {
      "x": 12,
      "y": 36,
      "z": 22,
      "name": "Soil_Dirt"
    },
    {
      "x": 12,
      "y": 37,
      "z": 22,
      "name": "Soil_Dirt"
    },
    {
      "x": 12,
      "y": 38,
      "z": 22,
      "name": "Soil_Grass_Deep"
    },
    {
      "x": 12,
      "y": 39,
      "z": 22,
      "name": "Plant_Grass_Lush"
    },
    {
      "x": 12,
      "y": 35,
      "z": 23,
      "name": "Rock_Stone"
    },
    {
      "x": 12,
      "y": 36,
      "z": 23,
      "name": "Rock_Stone"
    },
    {
      "x": 12,
      "y": 37,
      "z": 23,
      "name": "Soil_Dirt"
    },
    {
      "x": 12,
      "y": 38,
      "z": 23,
      "name": "Soil_Grass_Deep"
    },
    {
      "x": 12,
      "y": 36,
      "z": 24,
      "name": "Rock_Stone"
    },
    {
      "x": 12,
      "y": 37,
      "z": 24,
      "name": "Rock_Stone"
    },
    {
      "x": 12,
      "y": 24,
      "z": 29,
      "name": "Rock_Stone"
    },
    {
      "x": 12,
      "y": 25,
      "z": 29,
      "name": "Rock_Stone"
    },
    {
      "x": 12,
      "y": 29,
      "z": 29,
      "name": "Rock_Stone"
    },
    {
      "x": 12,
      "y": 30,
      "z": 29,
      "name": "Rock_Stone"
    },
    {
      "x": 12,
      "y": 31,
      "z": 29,
      "name": "Rock_Stone"
    },
    {
      "x": 12,
      "y": 32,
      "z": 29,
      "name": "Rock_Stone"
    },
    {
      "x": 12,
      "y": 33,
      "z": 29,
      "name": "Rock_Stone"
    },
    {
      "x": 12,
      "y": 34,
      "z": 29,
      "name": "Soil_Dirt"
    },
    {
      "x": 12,
      "y": 23,
      "z": 30,
      "name": "Rock_Stone"
    },
    {
      "x": 12,
      "y": 24,
      "z": 30,
      "name": "Rock_Stone"
    },
    {
      "x": 12,
      "y": 25,
      "z": 30,
      "name": "Rock_Stone"
    },
    {
      "x": 12,
      "y": 26,
      "z": 30,
      "name": "Rock_Stone"
    },
    {
      "x": 12,
      "y": 27,
      "z": 30,
      "name": "Rock_Stone"
    },
    {
      "x": 12,
      "y": 28,
      "z": 30,
      "name": "Rock_Stone"
    },
    {
      "x": 12,
      "y": 29,
      "z": 30,
      "name": "Rock_Stone"
    },
    {
      "x": 12,
      "y": 30,
      "z": 30,
      "name": "Rock_Stone"
    },
    {
      "x": 12,
      "y": 31,
      "z": 30,
      "name": "Rock_Stone"
    },
    {
      "x": 12,
      "y": 32,
      "z": 30,
      "name": "Rock_Stone"
    },
    {
      "x": 12,
      "y": 33,
      "z": 30,
      "name": "Rock_Stone"
    },
    {
      "x": 12,
      "y": 34,
      "z": 30,
      "name": "Soil_Dirt"
    },
    {
      "x": 12,
      "y": 25,
      "z": 31,
      "name": "Rock_Stone"
    },
    {
      "x": 12,
      "y": 26,
      "z": 31,
      "name": "Rock_Stone"
    },
    {
      "x": 12,
      "y": 27,
      "z": 31,
      "name": "Rock_Stone"
    },
    {
      "x": 12,
      "y": 28,
      "z": 31,
      "name": "Rock_Stone"
    },
    {
      "x": 12,
      "y": 29,
      "z": 31,
      "name": "Rock_Stone"
    },
    {
      "x": 12,
      "y": 30,
      "z": 31,
      "name": "Rock_Stone"
    },
    {
      "x": 12,
      "y": 31,
      "z": 31,
      "name": "Rock_Stone"
    },
    {
      "x": 12,
      "y": 32,
      "z": 31,
      "name": "Rock_Stone"
    },
    {
      "x": 12,
      "y": 33,
      "z": 31,
      "name": "Rock_Stone"
    },
    {
      "x": 12,
      "y": 26,
      "z": 32,
      "name": "Rock_Stone"
    },
    {
      "x": 12,
      "y": 27,
      "z": 32,
      "name": "Rock_Stone"
    },
    {
      "x": 12,
      "y": 28,
      "z": 32,
      "name": "Rock_Stone"
    },
    {
      "x": 12,
      "y": 29,
      "z": 32,
      "name": "Rock_Stone"
    },
    {
      "x": 12,
      "y": 30,
      "z": 32,
      "name": "Rock_Stone"
    },
    {
      "x": 12,
      "y": 31,
      "z": 32,
      "name": "Rock_Stone"
    },
    {
      "x": 12,
      "y": 32,
      "z": 32,
      "name": "Rock_Stone"
    },
    {
      "x": 13,
      "y": 33,
      "z": 15,
      "name": "Rock_Stone"
    },
    {
      "x": 13,
      "y": 34,
      "z": 15,
      "name": "Rock_Stone"
    },
    {
      "x": 13,
      "y": 35,
      "z": 15,
      "name": "Rock_Stone"
    },
    {
      "x": 13,
      "y": 36,
      "z": 15,
      "name": "Rock_Stone"
    },
    {
      "x": 13,
      "y": 37,
      "z": 15,
      "name": "Rock_Stone"
    },
    {
      "x": 13,
      "y": 38,
      "z": 15,
      "name": "Soil_Dirt"
    },
    {
      "x": 13,
      "y": 39,
      "z": 15,
      "name": "Soil_Leaves"
    },
    {
      "x": 13,
      "y": 32,
      "z": 16,
      "name": "Rock_Stone"
    },
    {
      "x": 13,
      "y": 33,
      "z": 16,
      "name": "Rock_Stone"
    },
    {
      "x": 13,
      "y": 34,
      "z": 16,
      "name": "Rock_Stone"
    },
    {
      "x": 13,
      "y": 35,
      "z": 16,
      "name": "Rock_Stone"
    },
    {
      "x": 13,
      "y": 36,
      "z": 16,
      "name": "Rock_Stone"
    },
    {
      "x": 13,
      "y": 37,
      "z": 16,
      "name": "Rock_Stone"
    },
    {
      "x": 13,
      "y": 38,
      "z": 16,
      "name": "Soil_Dirt"
    },
    {
      "x": 13,
      "y": 39,
      "z": 16,
      "name": "Soil_Leaves"
    },
    {
      "x": 13,
      "y": 40,
      "z": 16,
      "name": "Plant_Grass_Lush"
    },
    {
      "x": 13,
      "y": 19,
      "z": 17,
      "name": "Rock_Stone"
    },
    {
      "x": 13,
      "y": 20,
      "z": 17,
      "name": "Rock_Stone"
    },
    {
      "x": 13,
      "y": 21,
      "z": 17,
      "name": "Rock_Stone"
    },
    {
      "x": 13,
      "y": 31,
      "z": 17,
      "name": "Rock_Stone"
    },
    {
      "x": 13,
      "y": 32,
      "z": 17,
      "name": "Rock_Stone"
    },
    {
      "x": 13,
      "y": 33,
      "z": 17,
      "name": "Rock_Stone"
    },
    {
      "x": 13,
      "y": 34,
      "z": 17,
      "name": "Rock_Stone"
    },
    {
      "x": 13,
      "y": 35,
      "z": 17,
      "name": "Rock_Stone"
    },
    {
      "x": 13,
      "y": 36,
      "z": 17,
      "name": "Rock_Stone"
    },
    {
      "x": 13,
      "y": 37,
      "z": 17,
      "name": "Soil_Dirt"
    },
    {
      "x": 13,
      "y": 38,
      "z": 17,
      "name": "Soil_Dirt"
    },
    {
      "x": 13,
      "y": 39,
      "z": 17,
      "name": "Soil_Leaves"
    },
    {
      "x": 13,
      "y": 40,
      "z": 17,
      "name": "Plant_Grass_Lush"
    },
    {
      "x": 13,
      "y": 17,
      "z": 18,
      "name": "Rock_Stone"
    },
    {
      "x": 13,
      "y": 18,
      "z": 18,
      "name": "Rock_Stone"
    },
    {
      "x": 13,
      "y": 19,
      "z": 18,
      "name": "Rock_Stone"
    },
    {
      "x": 13,
      "y": 20,
      "z": 18,
      "name": "Rock_Stone"
    },
    {
      "x": 13,
      "y": 21,
      "z": 18,
      "name": "Rock_Stone"
    },
    {
      "x": 13,
      "y": 22,
      "z": 18,
      "name": "Rock_Stone"
    },
    {
      "x": 13,
      "y": 31,
      "z": 18,
      "name": "Rock_Stone"
    },
    {
      "x": 13,
      "y": 32,
      "z": 18,
      "name": "Rock_Stone"
    },
    {
      "x": 13,
      "y": 33,
      "z": 18,
      "name": "Rock_Stone"
    },
    {
      "x": 13,
      "y": 34,
      "z": 18,
      "name": "Rock_Stone"
    },
    {
      "x": 13,
      "y": 35,
      "z": 18,
      "name": "Rock_Stone"
    },
    {
      "x": 13,
      "y": 36,
      "z": 18,
      "name": "Rock_Stone"
    },
    {
      "x": 13,
      "y": 37,
      "z": 18,
      "name": "Rock_Stone"
    },
    {
      "x": 13,
      "y": 38,
      "z": 18,
      "name": "Soil_Dirt"
    },
    {
      "x": 13,
      "y": 39,
      "z": 18,
      "name": "Soil_Dirt"
    },
    {
      "x": 13,
      "y": 40,
      "z": 18,
      "name": "Soil_Grass_Deep"
    },
    {
      "x": 13,
      "y": 17,
      "z": 19,
      "name": "Rock_Stone"
    },
    {
      "x": 13,
      "y": 18,
      "z": 19,
      "name": "Rock_Stone"
    },
    {
      "x": 13,
      "y": 19,
      "z": 19,
      "name": "Rock_Stone"
    },
    {
      "x": 13,
      "y": 20,
      "z": 19,
      "name": "Rock_Stone"
    },
    {
      "x": 13,
      "y": 21,
      "z": 19,
      "name": "Rock_Stone"
    },
    {
      "x": 13,
      "y": 22,
      "z": 19,
      "name": "Rock_Stone"
    },
    {
      "x": 13,
      "y": 31,
      "z": 19,
      "name": "Rock_Stone"
    },
    {
      "x": 13,
      "y": 32,
      "z": 19,
      "name": "Rock_Stone"
    },
    {
      "x": 13,
      "y": 33,
      "z": 19,
      "name": "Rock_Stone"
    },
    {
      "x": 13,
      "y": 34,
      "z": 19,
      "name": "Rock_Stone"
    },
    {
      "x": 13,
      "y": 35,
      "z": 19,
      "name": "Rock_Stone"
    },
    {
      "x": 13,
      "y": 36,
      "z": 19,
      "name": "Rock_Stone"
    },
    {
      "x": 13,
      "y": 37,
      "z": 19,
      "name": "Rock_Stone"
    },
    {
      "x": 13,
      "y": 38,
      "z": 19,
      "name": "Soil_Dirt"
    },
    {
      "x": 13,
      "y": 39,
      "z": 19,
      "name": "Soil_Dirt"
    },
    {
      "x": 13,
      "y": 40,
      "z": 19,
      "name": "Soil_Leaves"
    },
    {
      "x": 13,
      "y": 41,
      "z": 19,
      "name": "Plant_Grass_Lush"
    },
    {
      "x": 13,
      "y": 17,
      "z": 20,
      "name": "Rock_Stone"
    },
    {
      "x": 13,
      "y": 18,
      "z": 20,
      "name": "Rock_Stone"
    },
    {
      "x": 13,
      "y": 19,
      "z": 20,
      "name": "Rock_Stone"
    },
    {
      "x": 13,
      "y": 20,
      "z": 20,
      "name": "Rock_Stone"
    },
    {
      "x": 13,
      "y": 21,
      "z": 20,
      "name": "Rock_Stone"
    },
    {
      "x": 13,
      "y": 32,
      "z": 20,
      "name": "Rock_Stone"
    },
    {
      "x": 13,
      "y": 33,
      "z": 20,
      "name": "Rock_Stone"
    },
    {
      "x": 13,
      "y": 34,
      "z": 20,
      "name": "Rock_Stone"
    },
    {
      "x": 13,
      "y": 35,
      "z": 20,
      "name": "Rock_Stone"
    },
    {
      "x": 13,
      "y": 36,
      "z": 20,
      "name": "Rock_Stone"
    },
    {
      "x": 13,
      "y": 37,
      "z": 20,
      "name": "Rock_Stone"
    },
    {
      "x": 13,
      "y": 38,
      "z": 20,
      "name": "Soil_Dirt"
    },
    {
      "x": 13,
      "y": 39,
      "z": 20,
      "name": "Soil_Dirt"
    },
    {
      "x": 13,
      "y": 40,
      "z": 20,
      "name": "Soil_Leaves"
    },
    {
      "x": 13,
      "y": 41,
      "z": 20,
      "name": "Plant_Flower_Common_Violet"
    },
    {
      "x": 13,
      "y": 17,
      "z": 21,
      "name": "Rock_Stone"
    },
    {
      "x": 13,
      "y": 18,
      "z": 21,
      "name": "Rock_Stone"
    },
    {
      "x": 13,
      "y": 19,
      "z": 21,
      "name": "Rock_Stone"
    },
    {
      "x": 13,
      "y": 20,
      "z": 21,
      "name": "Rock_Stone"
    },
    {
      "x": 13,
      "y": 32,
      "z": 21,
      "name": "Rock_Stone"
    },
    {
      "x": 13,
      "y": 33,
      "z": 21,
      "name": "Rock_Stone"
    },
    {
      "x": 13,
      "y": 34,
      "z": 21,
      "name": "Rock_Stone"
    },
    {
      "x": 13,
      "y": 35,
      "z": 21,
      "name": "Rock_Stone"
    },
    {
      "x": 13,
      "y": 36,
      "z": 21,
      "name": "Rock_Stone"
    },
    {
      "x": 13,
      "y": 37,
      "z": 21,
      "name": "Soil_Dirt"
    },
    {
      "x": 13,
      "y": 38,
      "z": 21,
      "name": "Soil_Dirt"
    },
    {
      "x": 13,
      "y": 39,
      "z": 21,
      "name": "Soil_Dirt"
    },
    {
      "x": 13,
      "y": 40,
      "z": 21,
      "name": "Soil_Leaves"
    },
    {
      "x": 13,
      "y": 41,
      "z": 21,
      "name": "Plant_Grass_Sharp"
    },
    {
      "x": 13,
      "y": 19,
      "z": 22,
      "name": "Rock_Stone"
    },
    {
      "x": 13,
      "y": 20,
      "z": 22,
      "name": "Rock_Stone"
    },
    {
      "x": 13,
      "y": 34,
      "z": 22,
      "name": "Rock_Stone"
    },
    {
      "x": 13,
      "y": 35,
      "z": 22,
      "name": "Rock_Stone"
    },
    {
      "x": 13,
      "y": 36,
      "z": 22,
      "name": "Rock_Stone"
    },
    {
      "x": 13,
      "y": 37,
      "z": 22,
      "name": "Rock_Stone"
    },
    {
      "x": 13,
      "y": 38,
      "z": 22,
      "name": "Soil_Dirt"
    },
    {
      "x": 13,
      "y": 39,
      "z": 22,
      "name": "Soil_Dirt"
    },
    {
      "x": 13,
      "y": 40,
      "z": 22,
      "name": "Soil_Grass_Deep"
    },
    {
      "x": 13,
      "y": 35,
      "z": 23,
      "name": "Rock_Stone"
    },
    {
      "x": 13,
      "y": 36,
      "z": 23,
      "name": "Rock_Stone"
    },
    {
      "x": 13,
      "y": 37,
      "z": 23,
      "name": "Rock_Stone"
    },
    {
      "x": 13,
      "y": 38,
      "z": 23,
      "name": "Rock_Stone"
    },
    {
      "x": 13,
      "y": 39,
      "z": 23,
      "name": "Soil_Grass_Deep"
    },
    {
      "x": 13,
      "y": 36,
      "z": 24,
      "name": "Rock_Stone"
    },
    {
      "x": 13,
      "y": 37,
      "z": 24,
      "name": "Rock_Stone"
    },
    {
      "x": 13,
      "y": 38,
      "z": 24,
      "name": "Soil_Dirt"
    },
    {
      "x": 13,
      "y": 39,
      "z": 24,
      "name": "Soil_Grass_Deep"
    },
    {
      "x": 13,
      "y": 40,
      "z": 24,
      "name": "Plant_Flower_Common_Violet"
    },
    {
      "x": 13,
      "y": 36,
      "z": 25,
      "name": "Rock_Stone"
    },
    {
      "x": 13,
      "y": 37,
      "z": 25,
      "name": "Soil_Dirt"
    },
    {
      "x": 13,
      "y": 38,
      "z": 25,
      "name": "Soil_Dirt"
    },
    {
      "x": 13,
      "y": 39,
      "z": 25,
      "name": "Soil_Grass_Deep"
    },
    {
      "x": 13,
      "y": 21,
      "z": 26,
      "name": "Rock_Stone"
    },
    {
      "x": 13,
      "y": 22,
      "z": 26,
      "name": "Rock_Stone"
    },
    {
      "x": 13,
      "y": 23,
      "z": 26,
      "name": "Rock_Stone"
    },
    {
      "x": 13,
      "y": 36,
      "z": 26,
      "name": "Soil_Dirt"
    },
    {
      "x": 13,
      "y": 37,
      "z": 26,
      "name": "Soil_Dirt"
    },
    {
      "x": 13,
      "y": 38,
      "z": 26,
      "name": "Soil_Dirt"
    },
    {
      "x": 13,
      "y": 21,
      "z": 27,
      "name": "Rock_Stone"
    },
    {
      "x": 13,
      "y": 22,
      "z": 27,
      "name": "Rock_Stone"
    },
    {
      "x": 13,
      "y": 23,
      "z": 27,
      "name": "Rock_Stone"
    },
    {
      "x": 13,
      "y": 24,
      "z": 27,
      "name": "Rock_Stone"
    },
    {
      "x": 13,
      "y": 25,
      "z": 27,
      "name": "Rock_Stone"
    },
    {
      "x": 13,
      "y": 34,
      "z": 27,
      "name": "Rock_Stone"
    },
    {
      "x": 13,
      "y": 35,
      "z": 27,
      "name": "Rock_Stone"
    },
    {
      "x": 13,
      "y": 36,
      "z": 27,
      "name": "Soil_Dirt"
    },
    {
      "x": 13,
      "y": 37,
      "z": 27,
      "name": "Soil_Dirt"
    },
    {
      "x": 13,
      "y": 38,
      "z": 27,
      "name": "Soil_Dirt"
    },
    {
      "x": 13,
      "y": 22,
      "z": 28,
      "name": "Rock_Stone"
    },
    {
      "x": 13,
      "y": 23,
      "z": 28,
      "name": "Rock_Stone"
    },
    {
      "x": 13,
      "y": 24,
      "z": 28,
      "name": "Rock_Stone"
    },
    {
      "x": 13,
      "y": 25,
      "z": 28,
      "name": "Rock_Stone"
    },
    {
      "x": 13,
      "y": 26,
      "z": 28,
      "name": "Rock_Stone"
    },
    {
      "x": 13,
      "y": 32,
      "z": 28,
      "name": "Rock_Stone"
    },
    {
      "x": 13,
      "y": 33,
      "z": 28,
      "name": "Rock_Stone"
    },
    {
      "x": 13,
      "y": 34,
      "z": 28,
      "name": "Rock_Stone"
    },
    {
      "x": 13,
      "y": 35,
      "z": 28,
      "name": "Soil_Dirt"
    },
    {
      "x": 13,
      "y": 36,
      "z": 28,
      "name": "Soil_Dirt"
    },
    {
      "x": 13,
      "y": 37,
      "z": 28,
      "name": "Soil_Dirt"
    },
    {
      "x": 13,
      "y": 22,
      "z": 29,
      "name": "Rock_Stone"
    },
    {
      "x": 13,
      "y": 23,
      "z": 29,
      "name": "Rock_Stone"
    },
    {
      "x": 13,
      "y": 24,
      "z": 29,
      "name": "Rock_Stone"
    },
    {
      "x": 13,
      "y": 25,
      "z": 29,
      "name": "Rock_Stone"
    },
    {
      "x": 13,
      "y": 26,
      "z": 29,
      "name": "Rock_Stone"
    },
    {
      "x": 13,
      "y": 27,
      "z": 29,
      "name": "Rock_Stone"
    },
    {
      "x": 13,
      "y": 28,
      "z": 29,
      "name": "Rock_Stone"
    },
    {
      "x": 13,
      "y": 29,
      "z": 29,
      "name": "Rock_Stone"
    },
    {
      "x": 13,
      "y": 30,
      "z": 29,
      "name": "Rock_Stone"
    },
    {
      "x": 13,
      "y": 31,
      "z": 29,
      "name": "Rock_Stone"
    },
    {
      "x": 13,
      "y": 32,
      "z": 29,
      "name": "Rock_Stone"
    },
    {
      "x": 13,
      "y": 33,
      "z": 29,
      "name": "Rock_Stone"
    },
    {
      "x": 13,
      "y": 34,
      "z": 29,
      "name": "Soil_Dirt"
    },
    {
      "x": 13,
      "y": 35,
      "z": 29,
      "name": "Soil_Dirt"
    },
    {
      "x": 13,
      "y": 36,
      "z": 29,
      "name": "Soil_Dirt"
    },
    {
      "x": 13,
      "y": 37,
      "z": 29,
      "name": "Soil_Grass_Deep"
    },
    {
      "x": 13,
      "y": 22,
      "z": 30,
      "name": "Rock_Stone"
    },
    {
      "x": 13,
      "y": 23,
      "z": 30,
      "name": "Rock_Stone"
    },
    {
      "x": 13,
      "y": 24,
      "z": 30,
      "name": "Rock_Stone"
    },
    {
      "x": 13,
      "y": 25,
      "z": 30,
      "name": "Rock_Stone"
    },
    {
      "x": 13,
      "y": 26,
      "z": 30,
      "name": "Rock_Stone"
    },
    {
      "x": 13,
      "y": 27,
      "z": 30,
      "name": "Rock_Stone"
    },
    {
      "x": 13,
      "y": 28,
      "z": 30,
      "name": "Rock_Stone"
    },
    {
      "x": 13,
      "y": 29,
      "z": 30,
      "name": "Rock_Stone"
    },
    {
      "x": 13,
      "y": 30,
      "z": 30,
      "name": "Rock_Stone"
    },
    {
      "x": 13,
      "y": 31,
      "z": 30,
      "name": "Rock_Stone"
    },
    {
      "x": 13,
      "y": 32,
      "z": 30,
      "name": "Rock_Stone"
    },
    {
      "x": 13,
      "y": 33,
      "z": 30,
      "name": "Rock_Stone"
    },
    {
      "x": 13,
      "y": 34,
      "z": 30,
      "name": "Soil_Dirt"
    },
    {
      "x": 13,
      "y": 35,
      "z": 30,
      "name": "Soil_Dirt"
    },
    {
      "x": 13,
      "y": 36,
      "z": 30,
      "name": "Soil_Dirt"
    },
    {
      "x": 13,
      "y": 37,
      "z": 30,
      "name": "Soil_Grass_Deep"
    },
    {
      "x": 13,
      "y": 24,
      "z": 31,
      "name": "Rock_Stone"
    },
    {
      "x": 13,
      "y": 25,
      "z": 31,
      "name": "Rock_Stone"
    },
    {
      "x": 13,
      "y": 26,
      "z": 31,
      "name": "Rock_Stone"
    },
    {
      "x": 13,
      "y": 27,
      "z": 31,
      "name": "Rock_Stone"
    },
    {
      "x": 13,
      "y": 28,
      "z": 31,
      "name": "Rock_Stone"
    },
    {
      "x": 13,
      "y": 29,
      "z": 31,
      "name": "Rock_Stone"
    },
    {
      "x": 13,
      "y": 30,
      "z": 31,
      "name": "Rock_Stone"
    },
    {
      "x": 13,
      "y": 31,
      "z": 31,
      "name": "Rock_Stone"
    },
    {
      "x": 13,
      "y": 32,
      "z": 31,
      "name": "Rock_Stone"
    },
    {
      "x": 13,
      "y": 33,
      "z": 31,
      "name": "Soil_Dirt"
    },
    {
      "x": 13,
      "y": 34,
      "z": 31,
      "name": "Soil_Dirt"
    },
    {
      "x": 13,
      "y": 35,
      "z": 31,
      "name": "Soil_Dirt"
    },
    {
      "x": 13,
      "y": 36,
      "z": 31,
      "name": "Soil_Grass_Deep"
    },
    {
      "x": 13,
      "y": 26,
      "z": 32,
      "name": "Rock_Stone"
    },
    {
      "x": 13,
      "y": 27,
      "z": 32,
      "name": "Rock_Stone"
    },
    {
      "x": 13,
      "y": 28,
      "z": 32,
      "name": "Rock_Stone"
    },
    {
      "x": 13,
      "y": 29,
      "z": 32,
      "name": "Rock_Stone"
    },
    {
      "x": 13,
      "y": 30,
      "z": 32,
      "name": "Rock_Stone"
    },
    {
      "x": 13,
      "y": 31,
      "z": 32,
      "name": "Rock_Stone"
    },
    {
      "x": 13,
      "y": 32,
      "z": 32,
      "name": "Rock_Stone"
    },
    {
      "x": 13,
      "y": 33,
      "z": 32,
      "name": "Rock_Stone"
    },
    {
      "x": 13,
      "y": 34,
      "z": 32,
      "name": "Soil_Dirt"
    },
    {
      "x": 14,
      "y": 34,
      "z": 15,
      "name": "Rock_Stone"
    },
    {
      "x": 14,
      "y": 35,
      "z": 15,
      "name": "Rock_Stone"
    },
    {
      "x": 14,
      "y": 36,
      "z": 15,
      "name": "Rock_Stone"
    },
    {
      "x": 14,
      "y": 37,
      "z": 15,
      "name": "Rock_Stone"
    },
    {
      "x": 14,
      "y": 38,
      "z": 15,
      "name": "Soil_Dirt"
    },
    {
      "x": 14,
      "y": 39,
      "z": 15,
      "name": "Soil_Leaves"
    },
    {
      "x": 14,
      "y": 40,
      "z": 15,
      "name": "Plant_Grass_Lush"
    },
    {
      "x": 14,
      "y": 33,
      "z": 16,
      "name": "Rock_Stone"
    },
    {
      "x": 14,
      "y": 34,
      "z": 16,
      "name": "Rock_Stone"
    },
    {
      "x": 14,
      "y": 35,
      "z": 16,
      "name": "Rock_Stone"
    },
    {
      "x": 14,
      "y": 36,
      "z": 16,
      "name": "Rock_Stone"
    },
    {
      "x": 14,
      "y": 37,
      "z": 16,
      "name": "Rock_Stone"
    },
    {
      "x": 14,
      "y": 38,
      "z": 16,
      "name": "Soil_Dirt"
    },
    {
      "x": 14,
      "y": 39,
      "z": 16,
      "name": "Soil_Dirt"
    },
    {
      "x": 14,
      "y": 40,
      "z": 16,
      "name": "Soil_Leaves"
    },
    {
      "x": 14,
      "y": 33,
      "z": 17,
      "name": "Rock_Stone"
    },
    {
      "x": 14,
      "y": 34,
      "z": 17,
      "name": "Rock_Stone"
    },
    {
      "x": 14,
      "y": 35,
      "z": 17,
      "name": "Rock_Stone"
    },
    {
      "x": 14,
      "y": 36,
      "z": 17,
      "name": "Rock_Stone"
    },
    {
      "x": 14,
      "y": 37,
      "z": 17,
      "name": "Rock_Stone"
    },
    {
      "x": 14,
      "y": 38,
      "z": 17,
      "name": "Soil_Dirt"
    },
    {
      "x": 14,
      "y": 39,
      "z": 17,
      "name": "Soil_Dirt"
    },
    {
      "x": 14,
      "y": 40,
      "z": 17,
      "name": "Soil_Dirt"
    },
    {
      "x": 14,
      "y": 41,
      "z": 17,
      "name": "Soil_Leaves"
    },
    {
      "x": 14,
      "y": 17,
      "z": 18,
      "name": "Rock_Stone"
    },
    {
      "x": 14,
      "y": 18,
      "z": 18,
      "name": "Rock_Stone"
    },
    {
      "x": 14,
      "y": 19,
      "z": 18,
      "name": "Rock_Stone"
    },
    {
      "x": 14,
      "y": 32,
      "z": 18,
      "name": "Rock_Stone"
    },
    {
      "x": 14,
      "y": 33,
      "z": 18,
      "name": "Rock_Stone"
    },
    {
      "x": 14,
      "y": 34,
      "z": 18,
      "name": "Rock_Stone"
    },
    {
      "x": 14,
      "y": 35,
      "z": 18,
      "name": "Rock_Stone"
    },
    {
      "x": 14,
      "y": 36,
      "z": 18,
      "name": "Rock_Stone"
    },
    {
      "x": 14,
      "y": 37,
      "z": 18,
      "name": "Rock_Stone"
    },
    {
      "x": 14,
      "y": 38,
      "z": 18,
      "name": "Soil_Dirt"
    },
    {
      "x": 14,
      "y": 39,
      "z": 18,
      "name": "Soil_Dirt"
    },
    {
      "x": 14,
      "y": 40,
      "z": 18,
      "name": "Soil_Dirt"
    },
    {
      "x": 14,
      "y": 41,
      "z": 18,
      "name": "Soil_Grass_Deep"
    },
    {
      "x": 14,
      "y": 16,
      "z": 19,
      "name": "Rock_Stone"
    },
    {
      "x": 14,
      "y": 17,
      "z": 19,
      "name": "Rock_Stone"
    },
    {
      "x": 14,
      "y": 18,
      "z": 19,
      "name": "Rock_Stone"
    },
    {
      "x": 14,
      "y": 19,
      "z": 19,
      "name": "Rock_Stone"
    },
    {
      "x": 14,
      "y": 20,
      "z": 19,
      "name": "Rock_Stone"
    },
    {
      "x": 14,
      "y": 21,
      "z": 19,
      "name": "Rock_Stone"
    },
    {
      "x": 14,
      "y": 32,
      "z": 19,
      "name": "Rock_Stone"
    },
    {
      "x": 14,
      "y": 33,
      "z": 19,
      "name": "Rock_Stone"
    },
    {
      "x": 14,
      "y": 34,
      "z": 19,
      "name": "Rock_Stone"
    },
    {
      "x": 14,
      "y": 35,
      "z": 19,
      "name": "Rock_Stone"
    },
    {
      "x": 14,
      "y": 36,
      "z": 19,
      "name": "Rock_Stone"
    },
    {
      "x": 14,
      "y": 37,
      "z": 19,
      "name": "Rock_Stone"
    },
    {
      "x": 14,
      "y": 38,
      "z": 19,
      "name": "Soil_Dirt"
    },
    {
      "x": 14,
      "y": 39,
      "z": 19,
      "name": "Soil_Dirt"
    },
    {
      "x": 14,
      "y": 40,
      "z": 19,
      "name": "Soil_Dirt"
    },
    {
      "x": 14,
      "y": 41,
      "z": 19,
      "name": "Soil_Leaves"
    },
    {
      "x": 14,
      "y": 16,
      "z": 20,
      "name": "Rock_Stone"
    },
    {
      "x": 14,
      "y": 17,
      "z": 20,
      "name": "Rock_Stone"
    },
    {
      "x": 14,
      "y": 18,
      "z": 20,
      "name": "Rock_Stone"
    },
    {
      "x": 14,
      "y": 19,
      "z": 20,
      "name": "Rock_Stone"
    },
    {
      "x": 14,
      "y": 20,
      "z": 20,
      "name": "Rock_Stone"
    },
    {
      "x": 14,
      "y": 21,
      "z": 20,
      "name": "Rock_Stone"
    },
    {
      "x": 14,
      "y": 32,
      "z": 20,
      "name": "Rock_Stone"
    },
    {
      "x": 14,
      "y": 33,
      "z": 20,
      "name": "Rock_Stone"
    },
    {
      "x": 14,
      "y": 34,
      "z": 20,
      "name": "Rock_Stone"
    },
    {
      "x": 14,
      "y": 35,
      "z": 20,
      "name": "Rock_Stone"
    },
    {
      "x": 14,
      "y": 36,
      "z": 20,
      "name": "Rock_Stone"
    },
    {
      "x": 14,
      "y": 37,
      "z": 20,
      "name": "Rock_Stone"
    },
    {
      "x": 14,
      "y": 38,
      "z": 20,
      "name": "Rock_Stone"
    },
    {
      "x": 14,
      "y": 39,
      "z": 20,
      "name": "Soil_Dirt"
    },
    {
      "x": 14,
      "y": 40,
      "z": 20,
      "name": "Soil_Leaves"
    },
    {
      "x": 14,
      "y": 17,
      "z": 21,
      "name": "Rock_Stone"
    },
    {
      "x": 14,
      "y": 18,
      "z": 21,
      "name": "Rock_Stone"
    },
    {
      "x": 14,
      "y": 19,
      "z": 21,
      "name": "Rock_Stone"
    },
    {
      "x": 14,
      "y": 20,
      "z": 21,
      "name": "Rock_Stone"
    },
    {
      "x": 14,
      "y": 33,
      "z": 21,
      "name": "Rock_Stone"
    },
    {
      "x": 14,
      "y": 34,
      "z": 21,
      "name": "Rock_Stone"
    },
    {
      "x": 14,
      "y": 35,
      "z": 21,
      "name": "Rock_Stone"
    },
    {
      "x": 14,
      "y": 36,
      "z": 21,
      "name": "Rock_Stone"
    },
    {
      "x": 14,
      "y": 37,
      "z": 21,
      "name": "Rock_Stone"
    },
    {
      "x": 14,
      "y": 38,
      "z": 21,
      "name": "Rock_Stone"
    },
    {
      "x": 14,
      "y": 39,
      "z": 21,
      "name": "Soil_Dirt"
    },
    {
      "x": 14,
      "y": 40,
      "z": 21,
      "name": "Soil_Leaves"
    },
    {
      "x": 14,
      "y": 17,
      "z": 22,
      "name": "Rock_Stone"
    },
    {
      "x": 14,
      "y": 18,
      "z": 22,
      "name": "Rock_Stone"
    },
    {
      "x": 14,
      "y": 19,
      "z": 22,
      "name": "Rock_Stone"
    },
    {
      "x": 14,
      "y": 20,
      "z": 22,
      "name": "Rock_Stone"
    },
    {
      "x": 14,
      "y": 35,
      "z": 22,
      "name": "Rock_Stone"
    },
    {
      "x": 14,
      "y": 36,
      "z": 22,
      "name": "Rock_Stone"
    },
    {
      "x": 14,
      "y": 37,
      "z": 22,
      "name": "Rock_Stone"
    },
    {
      "x": 14,
      "y": 38,
      "z": 22,
      "name": "Rock_Stone"
    },
    {
      "x": 14,
      "y": 39,
      "z": 22,
      "name": "Soil_Dirt"
    },
    {
      "x": 14,
      "y": 40,
      "z": 22,
      "name": "Soil_Leaves"
    },
    {
      "x": 14,
      "y": 17,
      "z": 23,
      "name": "Rock_Stone"
    },
    {
      "x": 14,
      "y": 18,
      "z": 23,
      "name": "Rock_Stone"
    },
    {
      "x": 14,
      "y": 19,
      "z": 23,
      "name": "Rock_Stone"
    },
    {
      "x": 14,
      "y": 20,
      "z": 23,
      "name": "Rock_Stone"
    },
    {
      "x": 14,
      "y": 21,
      "z": 23,
      "name": "Rock_Stone"
    },
    {
      "x": 14,
      "y": 35,
      "z": 23,
      "name": "Rock_Stone"
    },
    {
      "x": 14,
      "y": 36,
      "z": 23,
      "name": "Rock_Stone"
    },
    {
      "x": 14,
      "y": 37,
      "z": 23,
      "name": "Rock_Stone"
    },
    {
      "x": 14,
      "y": 38,
      "z": 23,
      "name": "Rock_Stone"
    },
    {
      "x": 14,
      "y": 39,
      "z": 23,
      "name": "Soil_Dirt"
    },
    {
      "x": 14,
      "y": 40,
      "z": 23,
      "name": "Soil_Grass_Deep"
    },
    {
      "x": 14,
      "y": 19,
      "z": 24,
      "name": "Rock_Stone"
    },
    {
      "x": 14,
      "y": 20,
      "z": 24,
      "name": "Rock_Stone"
    },
    {
      "x": 14,
      "y": 21,
      "z": 24,
      "name": "Rock_Stone"
    },
    {
      "x": 14,
      "y": 22,
      "z": 24,
      "name": "Rock_Stone"
    },
    {
      "x": 14,
      "y": 35,
      "z": 24,
      "name": "Rock_Stone"
    },
    {
      "x": 14,
      "y": 36,
      "z": 24,
      "name": "Rock_Stone"
    },
    {
      "x": 14,
      "y": 37,
      "z": 24,
      "name": "Rock_Stone"
    },
    {
      "x": 14,
      "y": 38,
      "z": 24,
      "name": "Soil_Dirt"
    },
    {
      "x": 14,
      "y": 39,
      "z": 24,
      "name": "Soil_Dirt"
    },
    {
      "x": 14,
      "y": 40,
      "z": 24,
      "name": "Soil_Grass_Deep"
    },
    {
      "x": 14,
      "y": 41,
      "z": 24,
      "name": "Plant_Flower_Common_Violet"
    },
    {
      "x": 14,
      "y": 19,
      "z": 25,
      "name": "Rock_Stone"
    },
    {
      "x": 14,
      "y": 20,
      "z": 25,
      "name": "Rock_Stone"
    },
    {
      "x": 14,
      "y": 21,
      "z": 25,
      "name": "Rock_Stone"
    },
    {
      "x": 14,
      "y": 22,
      "z": 25,
      "name": "Rock_Stone"
    },
    {
      "x": 14,
      "y": 23,
      "z": 25,
      "name": "Rock_Stone"
    },
    {
      "x": 14,
      "y": 24,
      "z": 25,
      "name": "Rock_Stone"
    },
    {
      "x": 14,
      "y": 35,
      "z": 25,
      "name": "Rock_Stone"
    },
    {
      "x": 14,
      "y": 36,
      "z": 25,
      "name": "Rock_Stone"
    },
    {
      "x": 14,
      "y": 37,
      "z": 25,
      "name": "Rock_Stone"
    },
    {
      "x": 14,
      "y": 38,
      "z": 25,
      "name": "Soil_Dirt"
    },
    {
      "x": 14,
      "y": 39,
      "z": 25,
      "name": "Soil_Dirt"
    },
    {
      "x": 14,
      "y": 40,
      "z": 25,
      "name": "Soil_Grass_Deep"
    },
    {
      "x": 14,
      "y": 19,
      "z": 26,
      "name": "Rock_Stone"
    },
    {
      "x": 14,
      "y": 20,
      "z": 26,
      "name": "Rock_Stone"
    },
    {
      "x": 14,
      "y": 21,
      "z": 26,
      "name": "Rock_Stone"
    },
    {
      "x": 14,
      "y": 22,
      "z": 26,
      "name": "Rock_Stone"
    },
    {
      "x": 14,
      "y": 23,
      "z": 26,
      "name": "Rock_Stone"
    },
    {
      "x": 14,
      "y": 24,
      "z": 26,
      "name": "Rock_Stone"
    },
    {
      "x": 14,
      "y": 34,
      "z": 26,
      "name": "Rock_Stone"
    },
    {
      "x": 14,
      "y": 35,
      "z": 26,
      "name": "Rock_Stone"
    },
    {
      "x": 14,
      "y": 36,
      "z": 26,
      "name": "Soil_Dirt"
    },
    {
      "x": 14,
      "y": 37,
      "z": 26,
      "name": "Soil_Dirt"
    },
    {
      "x": 14,
      "y": 38,
      "z": 26,
      "name": "Soil_Dirt"
    },
    {
      "x": 14,
      "y": 39,
      "z": 26,
      "name": "Soil_Dirt"
    },
    {
      "x": 14,
      "y": 40,
      "z": 26,
      "name": "Soil_Grass_Deep"
    },
    {
      "x": 14,
      "y": 21,
      "z": 27,
      "name": "Rock_Stone"
    },
    {
      "x": 14,
      "y": 22,
      "z": 27,
      "name": "Rock_Stone"
    },
    {
      "x": 14,
      "y": 23,
      "z": 27,
      "name": "Rock_Stone"
    },
    {
      "x": 14,
      "y": 24,
      "z": 27,
      "name": "Rock_Stone"
    },
    {
      "x": 14,
      "y": 25,
      "z": 27,
      "name": "Rock_Stone"
    },
    {
      "x": 14,
      "y": 32,
      "z": 27,
      "name": "Rock_Stone"
    },
    {
      "x": 14,
      "y": 33,
      "z": 27,
      "name": "Rock_Stone"
    },
    {
      "x": 14,
      "y": 34,
      "z": 27,
      "name": "Rock_Stone"
    },
    {
      "x": 14,
      "y": 35,
      "z": 27,
      "name": "Rock_Stone"
    },
    {
      "x": 14,
      "y": 36,
      "z": 27,
      "name": "Soil_Dirt"
    },
    {
      "x": 14,
      "y": 37,
      "z": 27,
      "name": "Soil_Dirt"
    },
    {
      "x": 14,
      "y": 38,
      "z": 27,
      "name": "Soil_Dirt"
    },
    {
      "x": 14,
      "y": 39,
      "z": 27,
      "name": "Soil_Grass_Deep"
    },
    {
      "x": 14,
      "y": 40,
      "z": 27,
      "name": "Plant_Grass_Lush"
    },
    {
      "x": 14,
      "y": 21,
      "z": 28,
      "name": "Rock_Stone"
    },
    {
      "x": 14,
      "y": 22,
      "z": 28,
      "name": "Rock_Stone"
    },
    {
      "x": 14,
      "y": 23,
      "z": 28,
      "name": "Rock_Stone"
    },
    {
      "x": 14,
      "y": 24,
      "z": 28,
      "name": "Rock_Stone"
    },
    {
      "x": 14,
      "y": 25,
      "z": 28,
      "name": "Rock_Stone"
    },
    {
      "x": 14,
      "y": 26,
      "z": 28,
      "name": "Rock_Stone"
    },
    {
      "x": 14,
      "y": 31,
      "z": 28,
      "name": "Rock_Stone"
    },
    {
      "x": 14,
      "y": 32,
      "z": 28,
      "name": "Rock_Stone"
    },
    {
      "x": 14,
      "y": 33,
      "z": 28,
      "name": "Rock_Stone"
    },
    {
      "x": 14,
      "y": 34,
      "z": 28,
      "name": "Rock_Stone"
    },
    {
      "x": 14,
      "y": 35,
      "z": 28,
      "name": "Rock_Stone"
    },
    {
      "x": 14,
      "y": 36,
      "z": 28,
      "name": "Soil_Dirt"
    },
    {
      "x": 14,
      "y": 37,
      "z": 28,
      "name": "Soil_Dirt"
    },
    {
      "x": 14,
      "y": 38,
      "z": 28,
      "name": "Soil_Dirt"
    },
    {
      "x": 14,
      "y": 39,
      "z": 28,
      "name": "Soil_Grass_Deep"
    },
    {
      "x": 14,
      "y": 22,
      "z": 29,
      "name": "Rock_Stone"
    },
    {
      "x": 14,
      "y": 23,
      "z": 29,
      "name": "Rock_Stone"
    },
    {
      "x": 14,
      "y": 24,
      "z": 29,
      "name": "Rock_Stone"
    },
    {
      "x": 14,
      "y": 25,
      "z": 29,
      "name": "Rock_Stone"
    },
    {
      "x": 14,
      "y": 26,
      "z": 29,
      "name": "Rock_Stone"
    },
    {
      "x": 14,
      "y": 27,
      "z": 29,
      "name": "Rock_Stone"
    },
    {
      "x": 14,
      "y": 28,
      "z": 29,
      "name": "Rock_Stone"
    },
    {
      "x": 14,
      "y": 29,
      "z": 29,
      "name": "Rock_Stone"
    },
    {
      "x": 14,
      "y": 30,
      "z": 29,
      "name": "Rock_Stone"
    },
    {
      "x": 14,
      "y": 31,
      "z": 29,
      "name": "Rock_Stone"
    },
    {
      "x": 14,
      "y": 32,
      "z": 29,
      "name": "Rock_Stone"
    },
    {
      "x": 14,
      "y": 33,
      "z": 29,
      "name": "Rock_Stone"
    },
    {
      "x": 14,
      "y": 34,
      "z": 29,
      "name": "Soil_Dirt"
    },
    {
      "x": 14,
      "y": 35,
      "z": 29,
      "name": "Soil_Dirt"
    },
    {
      "x": 14,
      "y": 36,
      "z": 29,
      "name": "Soil_Dirt"
    },
    {
      "x": 14,
      "y": 37,
      "z": 29,
      "name": "Soil_Dirt"
    },
    {
      "x": 14,
      "y": 38,
      "z": 29,
      "name": "Soil_Dirt"
    },
    {
      "x": 14,
      "y": 39,
      "z": 29,
      "name": "Soil_Grass_Deep"
    },
    {
      "x": 14,
      "y": 40,
      "z": 29,
      "name": "Plant_Grass_Lush"
    },
    {
      "x": 14,
      "y": 22,
      "z": 30,
      "name": "Rock_Stone"
    },
    {
      "x": 14,
      "y": 23,
      "z": 30,
      "name": "Rock_Stone"
    },
    {
      "x": 14,
      "y": 24,
      "z": 30,
      "name": "Rock_Stone"
    },
    {
      "x": 14,
      "y": 25,
      "z": 30,
      "name": "Rock_Stone"
    },
    {
      "x": 14,
      "y": 26,
      "z": 30,
      "name": "Rock_Stone"
    },
    {
      "x": 14,
      "y": 27,
      "z": 30,
      "name": "Rock_Stone"
    },
    {
      "x": 14,
      "y": 28,
      "z": 30,
      "name": "Rock_Stone"
    },
    {
      "x": 14,
      "y": 29,
      "z": 30,
      "name": "Rock_Stone"
    },
    {
      "x": 14,
      "y": 30,
      "z": 30,
      "name": "Rock_Stone"
    },
    {
      "x": 14,
      "y": 31,
      "z": 30,
      "name": "Rock_Stone"
    },
    {
      "x": 14,
      "y": 32,
      "z": 30,
      "name": "Rock_Stone"
    },
    {
      "x": 14,
      "y": 33,
      "z": 30,
      "name": "Rock_Stone"
    },
    {
      "x": 14,
      "y": 34,
      "z": 30,
      "name": "Soil_Dirt"
    },
    {
      "x": 14,
      "y": 35,
      "z": 30,
      "name": "Soil_Dirt"
    },
    {
      "x": 14,
      "y": 36,
      "z": 30,
      "name": "Soil_Dirt"
    },
    {
      "x": 14,
      "y": 37,
      "z": 30,
      "name": "Soil_Grass_Deep"
    },
    {
      "x": 14,
      "y": 38,
      "z": 30,
      "name": "Plant_Grass_Lush"
    },
    {
      "x": 14,
      "y": 24,
      "z": 31,
      "name": "Rock_Stone"
    },
    {
      "x": 14,
      "y": 25,
      "z": 31,
      "name": "Rock_Stone"
    },
    {
      "x": 14,
      "y": 26,
      "z": 31,
      "name": "Rock_Stone"
    },
    {
      "x": 14,
      "y": 27,
      "z": 31,
      "name": "Rock_Stone"
    },
    {
      "x": 14,
      "y": 28,
      "z": 31,
      "name": "Rock_Stone"
    },
    {
      "x": 14,
      "y": 29,
      "z": 31,
      "name": "Rock_Stone"
    },
    {
      "x": 14,
      "y": 30,
      "z": 31,
      "name": "Rock_Stone"
    },
    {
      "x": 14,
      "y": 31,
      "z": 31,
      "name": "Rock_Stone"
    },
    {
      "x": 14,
      "y": 32,
      "z": 31,
      "name": "Rock_Stone"
    },
    {
      "x": 14,
      "y": 33,
      "z": 31,
      "name": "Rock_Stone"
    },
    {
      "x": 14,
      "y": 34,
      "z": 31,
      "name": "Soil_Dirt"
    },
    {
      "x": 14,
      "y": 35,
      "z": 31,
      "name": "Soil_Dirt"
    },
    {
      "x": 14,
      "y": 36,
      "z": 31,
      "name": "Soil_Dirt"
    },
    {
      "x": 14,
      "y": 37,
      "z": 31,
      "name": "Soil_Grass_Deep"
    },
    {
      "x": 14,
      "y": 28,
      "z": 32,
      "name": "Rock_Stone"
    },
    {
      "x": 14,
      "y": 29,
      "z": 32,
      "name": "Rock_Stone"
    },
    {
      "x": 14,
      "y": 30,
      "z": 32,
      "name": "Rock_Stone"
    },
    {
      "x": 14,
      "y": 31,
      "z": 32,
      "name": "Rock_Stone"
    },
    {
      "x": 14,
      "y": 32,
      "z": 32,
      "name": "Rock_Stone"
    },
    {
      "x": 14,
      "y": 33,
      "z": 32,
      "name": "Rock_Stone"
    },
    {
      "x": 14,
      "y": 34,
      "z": 32,
      "name": "Soil_Dirt"
    },
    {
      "x": 14,
      "y": 35,
      "z": 32,
      "name": "Soil_Grass_Deep"
    },
    {
      "x": 15,
      "y": 34,
      "z": 15,
      "name": "Rock_Stone"
    },
    {
      "x": 15,
      "y": 35,
      "z": 15,
      "name": "Rock_Stone"
    },
    {
      "x": 15,
      "y": 36,
      "z": 15,
      "name": "Rock_Stone"
    },
    {
      "x": 15,
      "y": 37,
      "z": 15,
      "name": "Rock_Stone"
    },
    {
      "x": 15,
      "y": 38,
      "z": 15,
      "name": "Rock_Stone"
    },
    {
      "x": 15,
      "y": 39,
      "z": 15,
      "name": "Soil_Dirt"
    },
    {
      "x": 15,
      "y": 40,
      "z": 15,
      "name": "Soil_Grass_Deep"
    },
    {
      "x": 15,
      "y": 33,
      "z": 16,
      "name": "Rock_Stone"
    },
    {
      "x": 15,
      "y": 34,
      "z": 16,
      "name": "Rock_Stone"
    },
    {
      "x": 15,
      "y": 35,
      "z": 16,
      "name": "Rock_Stone"
    },
    {
      "x": 15,
      "y": 36,
      "z": 16,
      "name": "Rock_Stone"
    },
    {
      "x": 15,
      "y": 37,
      "z": 16,
      "name": "Rock_Stone"
    },
    {
      "x": 15,
      "y": 38,
      "z": 16,
      "name": "Soil_Dirt"
    },
    {
      "x": 15,
      "y": 39,
      "z": 16,
      "name": "Soil_Dirt"
    },
    {
      "x": 15,
      "y": 40,
      "z": 16,
      "name": "Soil_Grass_Deep"
    },
    {
      "x": 15,
      "y": 33,
      "z": 17,
      "name": "Rock_Stone"
    },
    {
      "x": 15,
      "y": 34,
      "z": 17,
      "name": "Rock_Stone"
    },
    {
      "x": 15,
      "y": 35,
      "z": 17,
      "name": "Rock_Stone"
    },
    {
      "x": 15,
      "y": 36,
      "z": 17,
      "name": "Rock_Stone"
    },
    {
      "x": 15,
      "y": 37,
      "z": 17,
      "name": "Rock_Stone"
    },
    {
      "x": 15,
      "y": 38,
      "z": 17,
      "name": "Soil_Dirt"
    },
    {
      "x": 15,
      "y": 39,
      "z": 17,
      "name": "Soil_Dirt"
    },
    {
      "x": 15,
      "y": 40,
      "z": 17,
      "name": "Soil_Dirt"
    },
    {
      "x": 15,
      "y": 41,
      "z": 17,
      "name": "Soil_Grass_Deep"
    },
    {
      "x": 15,
      "y": 17,
      "z": 18,
      "name": "Rock_Stone"
    },
    {
      "x": 15,
      "y": 18,
      "z": 18,
      "name": "Rock_Stone"
    },
    {
      "x": 15,
      "y": 33,
      "z": 18,
      "name": "Rock_Stone"
    },
    {
      "x": 15,
      "y": 34,
      "z": 18,
      "name": "Rock_Stone"
    },
    {
      "x": 15,
      "y": 35,
      "z": 18,
      "name": "Rock_Stone"
    },
    {
      "x": 15,
      "y": 36,
      "z": 18,
      "name": "Rock_Stone"
    },
    {
      "x": 15,
      "y": 37,
      "z": 18,
      "name": "Rock_Stone"
    },
    {
      "x": 15,
      "y": 38,
      "z": 18,
      "name": "Soil_Dirt"
    },
    {
      "x": 15,
      "y": 39,
      "z": 18,
      "name": "Soil_Dirt"
    },
    {
      "x": 15,
      "y": 40,
      "z": 18,
      "name": "Soil_Dirt"
    },
    {
      "x": 15,
      "y": 41,
      "z": 18,
      "name": "Soil_Grass_Deep"
    },
    {
      "x": 15,
      "y": 15,
      "z": 19,
      "name": "Rock_Stone"
    },
    {
      "x": 15,
      "y": 16,
      "z": 19,
      "name": "Rock_Stone"
    },
    {
      "x": 15,
      "y": 17,
      "z": 19,
      "name": "Rock_Stone"
    },
    {
      "x": 15,
      "y": 18,
      "z": 19,
      "name": "Rock_Stone"
    },
    {
      "x": 15,
      "y": 33,
      "z": 19,
      "name": "Rock_Stone"
    },
    {
      "x": 15,
      "y": 34,
      "z": 19,
      "name": "Rock_Stone"
    },
    {
      "x": 15,
      "y": 35,
      "z": 19,
      "name": "Rock_Stone"
    },
    {
      "x": 15,
      "y": 36,
      "z": 19,
      "name": "Rock_Stone"
    },
    {
      "x": 15,
      "y": 37,
      "z": 19,
      "name": "Rock_Stone"
    },
    {
      "x": 15,
      "y": 38,
      "z": 19,
      "name": "Rock_Stone"
    },
    {
      "x": 15,
      "y": 39,
      "z": 19,
      "name": "Soil_Dirt"
    },
    {
      "x": 15,
      "y": 40,
      "z": 19,
      "name": "Soil_Dirt"
    },
    {
      "x": 15,
      "y": 41,
      "z": 19,
      "name": "Soil_Leaves"
    },
    {
      "x": 15,
      "y": 15,
      "z": 20,
      "name": "Rock_Stone"
    },
    {
      "x": 15,
      "y": 16,
      "z": 20,
      "name": "Rock_Stone"
    },
    {
      "x": 15,
      "y": 17,
      "z": 20,
      "name": "Rock_Stone"
    },
    {
      "x": 15,
      "y": 18,
      "z": 20,
      "name": "Rock_Stone"
    },
    {
      "x": 15,
      "y": 19,
      "z": 20,
      "name": "Rock_Stone"
    },
    {
      "x": 15,
      "y": 34,
      "z": 20,
      "name": "Rock_Stone"
    },
    {
      "x": 15,
      "y": 35,
      "z": 20,
      "name": "Rock_Stone"
    },
    {
      "x": 15,
      "y": 36,
      "z": 20,
      "name": "Rock_Stone"
    },
    {
      "x": 15,
      "y": 37,
      "z": 20,
      "name": "Rock_Stone"
    },
    {
      "x": 15,
      "y": 38,
      "z": 20,
      "name": "Rock_Stone"
    },
    {
      "x": 15,
      "y": 39,
      "z": 20,
      "name": "Rock_Stone"
    },
    {
      "x": 15,
      "y": 40,
      "z": 20,
      "name": "Soil_Dirt"
    },
    {
      "x": 15,
      "y": 41,
      "z": 20,
      "name": "Soil_Leaves"
    },
    {
      "x": 15,
      "y": 15,
      "z": 21,
      "name": "Rock_Stone"
    },
    {
      "x": 15,
      "y": 16,
      "z": 21,
      "name": "Rock_Stone"
    },
    {
      "x": 15,
      "y": 17,
      "z": 21,
      "name": "Rock_Stone"
    },
    {
      "x": 15,
      "y": 18,
      "z": 21,
      "name": "Rock_Stone"
    },
    {
      "x": 15,
      "y": 19,
      "z": 21,
      "name": "Rock_Stone"
    },
    {
      "x": 15,
      "y": 20,
      "z": 21,
      "name": "Rock_Stone"
    },
    {
      "x": 15,
      "y": 34,
      "z": 21,
      "name": "Rock_Stone"
    },
    {
      "x": 15,
      "y": 35,
      "z": 21,
      "name": "Rock_Stone"
    },
    {
      "x": 15,
      "y": 36,
      "z": 21,
      "name": "Rock_Stone"
    },
    {
      "x": 15,
      "y": 37,
      "z": 21,
      "name": "Rock_Stone"
    },
    {
      "x": 15,
      "y": 38,
      "z": 21,
      "name": "Rock_Stone"
    },
    {
      "x": 15,
      "y": 39,
      "z": 21,
      "name": "Soil_Dirt"
    },
    {
      "x": 15,
      "y": 40,
      "z": 21,
      "name": "Soil_Leaves"
    },
    {
      "x": 15,
      "y": 41,
      "z": 21,
      "name": "Plant_Flower_Common_Violet"
    },
    {
      "x": 15,
      "y": 16,
      "z": 22,
      "name": "Rock_Stone"
    },
    {
      "x": 15,
      "y": 17,
      "z": 22,
      "name": "Rock_Stone"
    },
    {
      "x": 15,
      "y": 18,
      "z": 22,
      "name": "Rock_Stone"
    },
    {
      "x": 15,
      "y": 19,
      "z": 22,
      "name": "Rock_Stone"
    },
    {
      "x": 15,
      "y": 20,
      "z": 22,
      "name": "Rock_Stone"
    },
    {
      "x": 15,
      "y": 35,
      "z": 22,
      "name": "Rock_Stone"
    },
    {
      "x": 15,
      "y": 36,
      "z": 22,
      "name": "Rock_Stone"
    },
    {
      "x": 15,
      "y": 37,
      "z": 22,
      "name": "Rock_Stone"
    },
    {
      "x": 15,
      "y": 38,
      "z": 22,
      "name": "Rock_Stone"
    },
    {
      "x": 15,
      "y": 39,
      "z": 22,
      "name": "Soil_Dirt"
    },
    {
      "x": 15,
      "y": 40,
      "z": 22,
      "name": "Soil_Grass_Deep"
    },
    {
      "x": 15,
      "y": 16,
      "z": 23,
      "name": "Rock_Stone"
    },
    {
      "x": 15,
      "y": 17,
      "z": 23,
      "name": "Rock_Stone"
    },
    {
      "x": 15,
      "y": 18,
      "z": 23,
      "name": "Rock_Stone"
    },
    {
      "x": 15,
      "y": 19,
      "z": 23,
      "name": "Rock_Stone"
    },
    {
      "x": 15,
      "y": 20,
      "z": 23,
      "name": "Rock_Stone"
    },
    {
      "x": 15,
      "y": 35,
      "z": 23,
      "name": "Rock_Stone"
    },
    {
      "x": 15,
      "y": 36,
      "z": 23,
      "name": "Rock_Stone"
    },
    {
      "x": 15,
      "y": 37,
      "z": 23,
      "name": "Rock_Stone"
    },
    {
      "x": 15,
      "y": 38,
      "z": 23,
      "name": "Rock_Stone"
    },
    {
      "x": 15,
      "y": 39,
      "z": 23,
      "name": "Soil_Dirt"
    },
    {
      "x": 15,
      "y": 40,
      "z": 23,
      "name": "Soil_Grass_Deep"
    },
    {
      "x": 15,
      "y": 41,
      "z": 23,
      "name": "Plant_Grass_Lush"
    },
    {
      "x": 15,
      "y": 16,
      "z": 24,
      "name": "Rock_Stone"
    },
    {
      "x": 15,
      "y": 17,
      "z": 24,
      "name": "Rock_Stone"
    },
    {
      "x": 15,
      "y": 18,
      "z": 24,
      "name": "Rock_Stone"
    },
    {
      "x": 15,
      "y": 19,
      "z": 24,
      "name": "Rock_Stone"
    },
    {
      "x": 15,
      "y": 20,
      "z": 24,
      "name": "Rock_Stone"
    },
    {
      "x": 15,
      "y": 21,
      "z": 24,
      "name": "Rock_Stone"
    },
    {
      "x": 15,
      "y": 22,
      "z": 24,
      "name": "Rock_Stone"
    },
    {
      "x": 15,
      "y": 35,
      "z": 24,
      "name": "Rock_Stone"
    },
    {
      "x": 15,
      "y": 36,
      "z": 24,
      "name": "Rock_Stone"
    },
    {
      "x": 15,
      "y": 37,
      "z": 24,
      "name": "Rock_Stone"
    },
    {
      "x": 15,
      "y": 38,
      "z": 24,
      "name": "Soil_Dirt"
    },
    {
      "x": 15,
      "y": 39,
      "z": 24,
      "name": "Soil_Dirt"
    },
    {
      "x": 15,
      "y": 40,
      "z": 24,
      "name": "Soil_Dirt"
    },
    {
      "x": 15,
      "y": 41,
      "z": 24,
      "name": "Soil_Grass_Deep"
    },
    {
      "x": 15,
      "y": 42,
      "z": 24,
      "name": "Plant_Flower_Common_Violet"
    },
    {
      "x": 15,
      "y": 17,
      "z": 25,
      "name": "Rock_Stone"
    },
    {
      "x": 15,
      "y": 18,
      "z": 25,
      "name": "Rock_Stone"
    },
    {
      "x": 15,
      "y": 19,
      "z": 25,
      "name": "Rock_Stone"
    },
    {
      "x": 15,
      "y": 20,
      "z": 25,
      "name": "Rock_Stone"
    },
    {
      "x": 15,
      "y": 21,
      "z": 25,
      "name": "Rock_Stone"
    },
    {
      "x": 15,
      "y": 22,
      "z": 25,
      "name": "Rock_Stone"
    },
    {
      "x": 15,
      "y": 23,
      "z": 25,
      "name": "Rock_Stone"
    },
    {
      "x": 15,
      "y": 24,
      "z": 25,
      "name": "Rock_Stone"
    },
    {
      "x": 15,
      "y": 34,
      "z": 25,
      "name": "Rock_Stone"
    },
    {
      "x": 15,
      "y": 35,
      "z": 25,
      "name": "Rock_Stone"
    },
    {
      "x": 15,
      "y": 36,
      "z": 25,
      "name": "Rock_Stone"
    },
    {
      "x": 15,
      "y": 37,
      "z": 25,
      "name": "Rock_Stone"
    },
    {
      "x": 15,
      "y": 38,
      "z": 25,
      "name": "Soil_Dirt"
    },
    {
      "x": 15,
      "y": 39,
      "z": 25,
      "name": "Soil_Dirt"
    },
    {
      "x": 15,
      "y": 40,
      "z": 25,
      "name": "Soil_Dirt"
    },
    {
      "x": 15,
      "y": 41,
      "z": 25,
      "name": "Soil_Grass_Deep"
    },
    {
      "x": 15,
      "y": 42,
      "z": 25,
      "name": "Plant_Flower_Common_Violet"
    },
    {
      "x": 15,
      "y": 17,
      "z": 26,
      "name": "Rock_Stone"
    },
    {
      "x": 15,
      "y": 18,
      "z": 26,
      "name": "Rock_Stone"
    },
    {
      "x": 15,
      "y": 19,
      "z": 26,
      "name": "Rock_Stone"
    },
    {
      "x": 15,
      "y": 20,
      "z": 26,
      "name": "Rock_Stone"
    },
    {
      "x": 15,
      "y": 21,
      "z": 26,
      "name": "Rock_Stone"
    },
    {
      "x": 15,
      "y": 22,
      "z": 26,
      "name": "Rock_Stone"
    },
    {
      "x": 15,
      "y": 23,
      "z": 26,
      "name": "Rock_Stone"
    },
    {
      "x": 15,
      "y": 24,
      "z": 26,
      "name": "Rock_Stone"
    },
    {
      "x": 15,
      "y": 34,
      "z": 26,
      "name": "Rock_Stone"
    },
    {
      "x": 15,
      "y": 35,
      "z": 26,
      "name": "Rock_Stone"
    },
    {
      "x": 15,
      "y": 36,
      "z": 26,
      "name": "Rock_Stone"
    },
    {
      "x": 15,
      "y": 37,
      "z": 26,
      "name": "Soil_Dirt"
    },
    {
      "x": 15,
      "y": 38,
      "z": 26,
      "name": "Soil_Dirt"
    },
    {
      "x": 15,
      "y": 39,
      "z": 26,
      "name": "Soil_Dirt"
    },
    {
      "x": 15,
      "y": 40,
      "z": 26,
      "name": "Soil_Dirt"
    },
    {
      "x": 15,
      "y": 41,
      "z": 26,
      "name": "Soil_Grass_Deep"
    },
    {
      "x": 15,
      "y": 18,
      "z": 27,
      "name": "Rock_Stone"
    },
    {
      "x": 15,
      "y": 19,
      "z": 27,
      "name": "Rock_Stone"
    },
    {
      "x": 15,
      "y": 20,
      "z": 27,
      "name": "Rock_Stone"
    },
    {
      "x": 15,
      "y": 21,
      "z": 27,
      "name": "Rock_Stone"
    },
    {
      "x": 15,
      "y": 22,
      "z": 27,
      "name": "Rock_Stone"
    },
    {
      "x": 15,
      "y": 23,
      "z": 27,
      "name": "Rock_Stone"
    },
    {
      "x": 15,
      "y": 24,
      "z": 27,
      "name": "Rock_Stone"
    },
    {
      "x": 15,
      "y": 25,
      "z": 27,
      "name": "Rock_Stone"
    },
    {
      "x": 15,
      "y": 32,
      "z": 27,
      "name": "Rock_Stone"
    },
    {
      "x": 15,
      "y": 33,
      "z": 27,
      "name": "Rock_Stone"
    },
    {
      "x": 15,
      "y": 34,
      "z": 27,
      "name": "Rock_Stone"
    },
    {
      "x": 15,
      "y": 35,
      "z": 27,
      "name": "Rock_Stone"
    },
    {
      "x": 15,
      "y": 36,
      "z": 27,
      "name": "Soil_Dirt"
    },
    {
      "x": 15,
      "y": 37,
      "z": 27,
      "name": "Soil_Dirt"
    },
    {
      "x": 15,
      "y": 38,
      "z": 27,
      "name": "Soil_Dirt"
    },
    {
      "x": 15,
      "y": 39,
      "z": 27,
      "name": "Soil_Dirt"
    },
    {
      "x": 15,
      "y": 40,
      "z": 27,
      "name": "Soil_Dirt"
    },
    {
      "x": 15,
      "y": 41,
      "z": 27,
      "name": "Soil_Grass_Deep"
    },
    {
      "x": 15,
      "y": 21,
      "z": 28,
      "name": "Rock_Stone"
    },
    {
      "x": 15,
      "y": 22,
      "z": 28,
      "name": "Rock_Stone"
    },
    {
      "x": 15,
      "y": 23,
      "z": 28,
      "name": "Rock_Stone"
    },
    {
      "x": 15,
      "y": 24,
      "z": 28,
      "name": "Rock_Stone"
    },
    {
      "x": 15,
      "y": 25,
      "z": 28,
      "name": "Rock_Stone"
    },
    {
      "x": 15,
      "y": 31,
      "z": 28,
      "name": "Rock_Stone"
    },
    {
      "x": 15,
      "y": 32,
      "z": 28,
      "name": "Rock_Stone"
    },
    {
      "x": 15,
      "y": 33,
      "z": 28,
      "name": "Rock_Stone"
    },
    {
      "x": 15,
      "y": 34,
      "z": 28,
      "name": "Rock_Stone"
    },
    {
      "x": 15,
      "y": 35,
      "z": 28,
      "name": "Rock_Stone"
    },
    {
      "x": 15,
      "y": 36,
      "z": 28,
      "name": "Soil_Dirt"
    },
    {
      "x": 15,
      "y": 37,
      "z": 28,
      "name": "Soil_Dirt"
    },
    {
      "x": 15,
      "y": 38,
      "z": 28,
      "name": "Soil_Dirt"
    },
    {
      "x": 15,
      "y": 39,
      "z": 28,
      "name": "Soil_Dirt"
    },
    {
      "x": 15,
      "y": 40,
      "z": 28,
      "name": "Soil_Grass_Deep"
    },
    {
      "x": 15,
      "y": 22,
      "z": 29,
      "name": "Rock_Stone"
    },
    {
      "x": 15,
      "y": 23,
      "z": 29,
      "name": "Rock_Stone"
    },
    {
      "x": 15,
      "y": 24,
      "z": 29,
      "name": "Rock_Stone"
    },
    {
      "x": 15,
      "y": 25,
      "z": 29,
      "name": "Rock_Stone"
    },
    {
      "x": 15,
      "y": 26,
      "z": 29,
      "name": "Rock_Stone"
    },
    {
      "x": 15,
      "y": 27,
      "z": 29,
      "name": "Rock_Stone"
    },
    {
      "x": 15,
      "y": 28,
      "z": 29,
      "name": "Rock_Stone"
    },
    {
      "x": 15,
      "y": 31,
      "z": 29,
      "name": "Rock_Stone"
    },
    {
      "x": 15,
      "y": 32,
      "z": 29,
      "name": "Rock_Stone"
    },
    {
      "x": 15,
      "y": 33,
      "z": 29,
      "name": "Rock_Stone"
    },
    {
      "x": 15,
      "y": 34,
      "z": 29,
      "name": "Rock_Stone"
    },
    {
      "x": 15,
      "y": 35,
      "z": 29,
      "name": "Soil_Dirt"
    },
    {
      "x": 15,
      "y": 36,
      "z": 29,
      "name": "Soil_Dirt"
    },
    {
      "x": 15,
      "y": 37,
      "z": 29,
      "name": "Soil_Dirt"
    },
    {
      "x": 15,
      "y": 38,
      "z": 29,
      "name": "Soil_Dirt"
    },
    {
      "x": 15,
      "y": 39,
      "z": 29,
      "name": "Soil_Dirt"
    },
    {
      "x": 15,
      "y": 40,
      "z": 29,
      "name": "Soil_Grass_Deep"
    },
    {
      "x": 15,
      "y": 23,
      "z": 30,
      "name": "Rock_Stone"
    },
    {
      "x": 15,
      "y": 24,
      "z": 30,
      "name": "Rock_Stone"
    },
    {
      "x": 15,
      "y": 25,
      "z": 30,
      "name": "Rock_Stone"
    },
    {
      "x": 15,
      "y": 26,
      "z": 30,
      "name": "Rock_Stone"
    },
    {
      "x": 15,
      "y": 27,
      "z": 30,
      "name": "Rock_Stone"
    },
    {
      "x": 15,
      "y": 28,
      "z": 30,
      "name": "Rock_Stone"
    },
    {
      "x": 15,
      "y": 30,
      "z": 30,
      "name": "Rock_Stone"
    },
    {
      "x": 15,
      "y": 31,
      "z": 30,
      "name": "Rock_Stone"
    },
    {
      "x": 15,
      "y": 32,
      "z": 30,
      "name": "Rock_Stone"
    },
    {
      "x": 15,
      "y": 33,
      "z": 30,
      "name": "Rock_Stone"
    },
    {
      "x": 15,
      "y": 34,
      "z": 30,
      "name": "Soil_Dirt"
    },
    {
      "x": 15,
      "y": 35,
      "z": 30,
      "name": "Soil_Dirt"
    },
    {
      "x": 15,
      "y": 36,
      "z": 30,
      "name": "Soil_Dirt"
    },
    {
      "x": 15,
      "y": 37,
      "z": 30,
      "name": "Soil_Grass_Deep"
    },
    {
      "x": 15,
      "y": 38,
      "z": 30,
      "name": "Plant_Grass_Lush"
    },
    {
      "x": 15,
      "y": 30,
      "z": 31,
      "name": "Rock_Stone"
    },
    {
      "x": 15,
      "y": 31,
      "z": 31,
      "name": "Rock_Stone"
    },
    {
      "x": 15,
      "y": 32,
      "z": 31,
      "name": "Rock_Stone"
    },
    {
      "x": 15,
      "y": 33,
      "z": 31,
      "name": "Rock_Stone"
    },
    {
      "x": 15,
      "y": 34,
      "z": 31,
      "name": "Soil_Dirt"
    },
    {
      "x": 15,
      "y": 35,
      "z": 31,
      "name": "Soil_Dirt"
    },
    {
      "x": 15,
      "y": 36,
      "z": 31,
      "name": "Soil_Dirt"
    },
    {
      "x": 15,
      "y": 37,
      "z": 31,
      "name": "Soil_Grass_Deep"
    },
    {
      "x": 15,
      "y": 31,
      "z": 32,
      "name": "Rock_Stone"
    },
    {
      "x": 15,
      "y": 32,
      "z": 32,
      "name": "Rock_Stone"
    },
    {
      "x": 15,
      "y": 33,
      "z": 32,
      "name": "Rock_Stone"
    },
    {
      "x": 15,
      "y": 34,
      "z": 32,
      "name": "Soil_Dirt"
    },
    {
      "x": 15,
      "y": 35,
      "z": 32,
      "name": "Soil_Grass_Deep"
    },
    {
      "x": 16,
      "y": 36,
      "z": 14,
      "name": "Rock_Stone"
    },
    {
      "x": 16,
      "y": 37,
      "z": 14,
      "name": "Rock_Stone"
    },
    {
      "x": 16,
      "y": 38,
      "z": 14,
      "name": "Rock_Stone"
    },
    {
      "x": 16,
      "y": 34,
      "z": 15,
      "name": "Rock_Stone"
    },
    {
      "x": 16,
      "y": 35,
      "z": 15,
      "name": "Rock_Stone"
    },
    {
      "x": 16,
      "y": 36,
      "z": 15,
      "name": "Rock_Stone"
    },
    {
      "x": 16,
      "y": 37,
      "z": 15,
      "name": "Rock_Stone"
    },
    {
      "x": 16,
      "y": 38,
      "z": 15,
      "name": "Rock_Stone"
    },
    {
      "x": 16,
      "y": 39,
      "z": 15,
      "name": "Rock_Stone"
    },
    {
      "x": 16,
      "y": 40,
      "z": 15,
      "name": "Soil_Grass_Deep"
    },
    {
      "x": 16,
      "y": 33,
      "z": 16,
      "name": "Rock_Stone"
    },
    {
      "x": 16,
      "y": 34,
      "z": 16,
      "name": "Rock_Stone"
    },
    {
      "x": 16,
      "y": 35,
      "z": 16,
      "name": "Rock_Stone"
    },
    {
      "x": 16,
      "y": 36,
      "z": 16,
      "name": "Rock_Stone"
    },
    {
      "x": 16,
      "y": 37,
      "z": 16,
      "name": "Rock_Stone"
    },
    {
      "x": 16,
      "y": 38,
      "z": 16,
      "name": "Rock_Stone"
    },
    {
      "x": 16,
      "y": 39,
      "z": 16,
      "name": "Soil_Dirt"
    },
    {
      "x": 16,
      "y": 40,
      "z": 16,
      "name": "Soil_Dirt"
    },
    {
      "x": 16,
      "y": 41,
      "z": 16,
      "name": "Rock_Stone"
    },
    {
      "x": 16,
      "y": 42,
      "z": 16,
      "name": "Rock_Stone"
    },
    {
      "x": 16,
      "y": 33,
      "z": 17,
      "name": "Rock_Stone"
    },
    {
      "x": 16,
      "y": 34,
      "z": 17,
      "name": "Rock_Stone"
    },
    {
      "x": 16,
      "y": 35,
      "z": 17,
      "name": "Rock_Stone"
    },
    {
      "x": 16,
      "y": 36,
      "z": 17,
      "name": "Rock_Stone"
    },
    {
      "x": 16,
      "y": 37,
      "z": 17,
      "name": "Rock_Stone"
    },
    {
      "x": 16,
      "y": 38,
      "z": 17,
      "name": "Rock_Stone"
    },
    {
      "x": 16,
      "y": 39,
      "z": 17,
      "name": "Soil_Dirt"
    },
    {
      "x": 16,
      "y": 40,
      "z": 17,
      "name": "Soil_Dirt"
    },
    {
      "x": 16,
      "y": 41,
      "z": 17,
      "name": "Rock_Stone"
    },
    {
      "x": 16,
      "y": 42,
      "z": 17,
      "name": "Rock_Stone"
    },
    {
      "x": 16,
      "y": 34,
      "z": 18,
      "name": "Rock_Stone"
    },
    {
      "x": 16,
      "y": 35,
      "z": 18,
      "name": "Rock_Stone"
    },
    {
      "x": 16,
      "y": 36,
      "z": 18,
      "name": "Rock_Stone"
    },
    {
      "x": 16,
      "y": 37,
      "z": 18,
      "name": "Rock_Stone"
    },
    {
      "x": 16,
      "y": 38,
      "z": 18,
      "name": "Rock_Stone"
    },
    {
      "x": 16,
      "y": 39,
      "z": 18,
      "name": "Rock_Stone"
    },
    {
      "x": 16,
      "y": 40,
      "z": 18,
      "name": "Soil_Dirt"
    },
    {
      "x": 16,
      "y": 41,
      "z": 18,
      "name": "Soil_Dirt"
    },
    {
      "x": 16,
      "y": 42,
      "z": 18,
      "name": "Soil_Grass_Deep"
    },
    {
      "x": 16,
      "y": 13,
      "z": 19,
      "name": "Rock_Stone"
    },
    {
      "x": 16,
      "y": 14,
      "z": 19,
      "name": "Rock_Stone"
    },
    {
      "x": 16,
      "y": 15,
      "z": 19,
      "name": "Rock_Stone"
    },
    {
      "x": 16,
      "y": 16,
      "z": 19,
      "name": "Rock_Stone"
    },
    {
      "x": 16,
      "y": 17,
      "z": 19,
      "name": "Rock_Stone"
    },
    {
      "x": 16,
      "y": 18,
      "z": 19,
      "name": "Rock_Stone"
    },
    {
      "x": 16,
      "y": 34,
      "z": 19,
      "name": "Rock_Stone"
    },
    {
      "x": 16,
      "y": 35,
      "z": 19,
      "name": "Rock_Stone"
    },
    {
      "x": 16,
      "y": 36,
      "z": 19,
      "name": "Rock_Stone"
    },
    {
      "x": 16,
      "y": 37,
      "z": 19,
      "name": "Rock_Stone"
    },
    {
      "x": 16,
      "y": 38,
      "z": 19,
      "name": "Rock_Stone"
    },
    {
      "x": 16,
      "y": 39,
      "z": 19,
      "name": "Rock_Stone"
    },
    {
      "x": 16,
      "y": 40,
      "z": 19,
      "name": "Soil_Dirt"
    },
    {
      "x": 16,
      "y": 41,
      "z": 19,
      "name": "Soil_Dirt"
    },
    {
      "x": 16,
      "y": 42,
      "z": 19,
      "name": "Soil_Grass_Deep"
    },
    {
      "x": 16,
      "y": 43,
      "z": 19,
      "name": "Plant_Grass_Lush"
    },
    {
      "x": 16,
      "y": 13,
      "z": 20,
      "name": "Rock_Stone"
    },
    {
      "x": 16,
      "y": 14,
      "z": 20,
      "name": "Rock_Stone"
    },
    {
      "x": 16,
      "y": 15,
      "z": 20,
      "name": "Rock_Stone"
    },
    {
      "x": 16,
      "y": 16,
      "z": 20,
      "name": "Rock_Stone"
    },
    {
      "x": 16,
      "y": 17,
      "z": 20,
      "name": "Rock_Stone"
    },
    {
      "x": 16,
      "y": 18,
      "z": 20,
      "name": "Rock_Stone"
    },
    {
      "x": 16,
      "y": 34,
      "z": 20,
      "name": "Rock_Stone"
    },
    {
      "x": 16,
      "y": 35,
      "z": 20,
      "name": "Rock_Stone"
    },
    {
      "x": 16,
      "y": 36,
      "z": 20,
      "name": "Rock_Stone"
    },
    {
      "x": 16,
      "y": 37,
      "z": 20,
      "name": "Rock_Stone"
    },
    {
      "x": 16,
      "y": 38,
      "z": 20,
      "name": "Rock_Stone"
    },
    {
      "x": 16,
      "y": 39,
      "z": 20,
      "name": "Rock_Stone"
    },
    {
      "x": 16,
      "y": 40,
      "z": 20,
      "name": "Soil_Dirt"
    },
    {
      "x": 16,
      "y": 41,
      "z": 20,
      "name": "Soil_Grass_Deep"
    },
    {
      "x": 16,
      "y": 13,
      "z": 21,
      "name": "Rock_Stone"
    },
    {
      "x": 16,
      "y": 14,
      "z": 21,
      "name": "Rock_Stone"
    },
    {
      "x": 16,
      "y": 15,
      "z": 21,
      "name": "Rock_Stone"
    },
    {
      "x": 16,
      "y": 16,
      "z": 21,
      "name": "Rock_Stone"
    },
    {
      "x": 16,
      "y": 17,
      "z": 21,
      "name": "Rock_Stone"
    },
    {
      "x": 16,
      "y": 18,
      "z": 21,
      "name": "Rock_Stone"
    },
    {
      "x": 16,
      "y": 19,
      "z": 21,
      "name": "Rock_Stone"
    },
    {
      "x": 16,
      "y": 35,
      "z": 21,
      "name": "Rock_Stone"
    },
    {
      "x": 16,
      "y": 36,
      "z": 21,
      "name": "Rock_Stone"
    },
    {
      "x": 16,
      "y": 37,
      "z": 21,
      "name": "Rock_Stone"
    },
    {
      "x": 16,
      "y": 38,
      "z": 21,
