{
  "version": 8,
  "blockIdVersion": 8,
  "anchorX": 0,
  "anchorY": 2,
  "anchorZ": 0,
  "blocks": [
    {
      "x": -2,
      "y": 2,
      "z": -3,
      "name": "Soil_Pathway"
    },
    {
      "x": -2,
      "y": 1,
      "z": -2,
      "name": "Soil_Dirt"
    },
    {
      "x": -2,
      "y": 2,
      "z": -2,
      "name": "Soil_Dirt"
    },
    {
      "x": -2,
      "y": 3,
      "z": -2,
      "name": "Deco_Rope_Diagonal",
      "rotation": 3
    },
    {
      "x": -2,
      "y": 0,
      "z": -1,
      "name": "Soil_Dirt"
    },
    {
      "x": -2,
      "y": 1,
      "z": -1,
      "name": "Soil_Dirt"
    },
    {
      "x": -2,
      "y": 2,
      "z": -1,
      "name": "Soil_Dirt"
    },
    {
      "x": -2,
      "y": 0,
      "z": 0,
      "name": "Soil_Dirt"
    },
    {
      "x": -2,
      "y": 1,
      "z": 0,
      "name": "Soil_Dirt"
    },
    {
      "x": -2,
      "y": 2,
      "z": 0,
      "name": "Soil_Dirt"
    },
    {
      "x": -2,
      "y": 0,
      "z": 1,
      "name": "Soil_Dirt"
    },
    {
      "x": -2,
      "y": 1,
      "z": 1,
      "name": "Soil_Dirt"
    },
    {
      "x": -2,
      "y": 2,
      "z": 1,
      "name": "Soil_Dirt"
    },
    {
      "x": -2,
      "y": 3,
      "z": 1,
      "name": "Deco_Rope_Diagonal",
      "rotation": 3
    },
    {
      "x": -2,
      "y": 0,
      "z": 2,
      "name": "Soil_Dirt"
    },
    {
      "x": -2,
      "y": 1,
      "z": 2,
      "name": "Soil_Dirt"
    },
    {
      "x": -2,
      "y": 2,
      "z": 2,
      "name": "Soil_Dirt"
    },
    {
      "x": -2,
      "y": 0,
      "z": 3,
      "name": "Soil_Dirt"
    },
    {
      "x": -2,
      "y": 1,
      "z": 3,
      "name": "Soil_Dirt"
    },
    {
      "x": -2,
      "y": 2,
      "z": 3,
      "name": "Soil_Dirt"
    },
    {
      "x": -1,
      "y": 0,
      "z": -3,
      "name": "Soil_Dirt"
    },
    {
      "x": -1,
      "y": 1,
      "z": -3,
      "name": "Soil_Dirt"
    },
    {
      "x": -1,
      "y": 2,
      "z": -3,
      "name": "Soil_Dirt"
    },
    {
      "x": -1,
      "y": 0,
      "z": -2,
      "name": "Soil_Dirt"
    },
    {
      "x": -1,
      "y": 1,
      "z": -2,
      "name": "Soil_Dirt"
    },
    {
      "x": -1,
      "y": 2,
      "z": -2,
      "name": "Soil_Dirt"
    },
    {
      "x": -1,
      "y": 3,
      "z": -2,
      "name": "Wood_Birch_Trunk",
      "support": 15,
      "rotation": 4
    },
    {
      "x": -1,
      "y": 4,
      "z": -2,
      "name": "Deco_Rope_Diagonal",
      "rotation": 3
    },
    {
      "x": -1,
      "y": 0,
      "z": -1,
      "name": "Soil_Dirt"
    },
    {
      "x": -1,
      "y": 1,
      "z": -1,
      "name": "Soil_Dirt"
    },
    {
      "x": -1,
      "y": 2,
      "z": -1,
      "name": "Soil_Dirt"
    },
    {
      "x": -1,
      "y": 3,
      "z": -1,
      "name": "Wood_Birch_Trunk",
      "support": 15,
      "rotation": 4
    },
    {
      "x": -1,
      "y": 0,
      "z": 0,
      "name": "Soil_Dirt"
    },
    {
      "x": -1,
      "y": 1,
      "z": 0,
      "name": "Soil_Dirt"
    },
    {
      "x": -1,
      "y": 2,
      "z": 0,
      "name": "Soil_Dirt"
    },
    {
      "x": -1,
      "y": 3,
      "z": 0,
      "name": "Wood_Birch_Trunk",
      "support": 15,
      "rotation": 4
    },
    {
      "x": -1,
      "y": 0,
      "z": 1,
      "name": "Soil_Dirt"
    },
    {
      "x": -1,
      "y": 1,
      "z": 1,
      "name": "Soil_Dirt"
    },
    {
      "x": -1,
      "y": 2,
      "z": 1,
      "name": "Soil_Dirt"
    },
    {
      "x": -1,
      "y": 3,
      "z": 1,
      "name": "Wood_Birch_Trunk",
      "support": 15,
      "rotation": 4
    },
    {
      "x": -1,
      "y": 0,
      "z": 2,
      "name": "Soil_Dirt"
    },
    {
      "x": -1,
      "y": 1,
      "z": 2,
      "name": "Soil_Dirt"
    },
    {
      "x": -1,
      "y": 2,
      "z": 2,
      "name": "Soil_Dirt"
    },
    {
      "x": -1,
      "y": 3,
      "z": 2,
      "name": "Wood_Birch_Trunk",
      "support": 15,
      "rotation": 4
    },
    {
      "x": -1,
      "y": 0,
      "z": 3,
      "name": "Soil_Dirt"
    },
    {
      "x": -1,
      "y": 1,
      "z": 3,
      "name": "Soil_Dirt"
    },
    {
      "x": -1,
      "y": 2,
      "z": 3,
      "name": "Soil_Dirt"
    },
    {
      "x": 0,
      "y": 1,
      "z": -3,
      "name": "Soil_Dirt"
    },
    {
      "x": 0,
      "y": 2,
      "z": -3,
      "name": "Soil_Dirt"
    },
    {
      "x": 0,
      "y": 3,
      "z": -3,
      "name": "Wood_Maple_Trunk",
      "support": 15,
      "rotation": 4
    },
    {
      "x": 0,
      "y": 4,
      "z": -3,
      "name": "Wood_Birch_Trunk",
      "support": 15,
      "rotation": 4
    },
    {
      "x": 0,
      "y": 0,
      "z": -2,
      "name": "Soil_Pathway"
    },
    {
      "x": 0,
      "y": 1,
      "z": -2,
      "name": "Soil_Pathway"
    },
    {
      "x": 0,
      "y": 2,
      "z": -2,
      "name": "Soil_Pathway"
    },
    {
      "x": 0,
      "y": 3,
      "z": -2,
      "name": "Wood_Maple_Trunk",
      "support": 15,
      "rotation": 4
    },
    {
      "x": 0,
      "y": 4,
      "z": -2,
      "name": "Wood_Birch_Trunk",
      "support": 15,
      "rotation": 4
    },
    {
      "x": 0,
      "y": 0,
      "z": -1,
      "name": "Soil_Pathway"
    },
    {
      "x": 0,
      "y": 1,
      "z": -1,
      "name": "Soil_Pathway"
    },
    {
      "x": 0,
      "y": 2,
      "z": -1,
      "name": "Soil_Pathway"
    },
    {
      "x": 0,
      "y": 3,
      "z": -1,
      "name": "Wood_Maple_Trunk",
      "support": 15,
      "rotation": 4
    },
    {
      "x": 0,
      "y": 4,
      "z": -1,
      "name": "Wood_Birch_Trunk",
      "support": 15,
      "rotation": 4
    },
    {
      "x": 0,
      "y": 2,
      "z": 0,
      "name": "Soil_Dirt"
    },
    {
      "x": 0,
      "y": 3,
      "z": 0,
      "name": "Wood_Maple_Trunk",
      "support": 15,
      "rotation": 4
    },
    {
      "x": 0,
      "y": 4,
      "z": 0,
      "name": "Wood_Birch_Trunk",
      "support": 15,
      "rotation": 4
    },
    {
      "x": 0,
      "y": 0,
      "z": 1,
      "name": "Soil_Dirt"
    },
    {
      "x": 0,
      "y": 1,
      "z": 1,
      "name": "Soil_Dirt"
    },
    {
      "x": 0,
      "y": 2,
      "z": 1,
      "name": "Soil_Dirt"
    },
    {
      "x": 0,
      "y": 3,
      "z": 1,
      "name": "Wood_Maple_Trunk",
      "support": 15,
      "rotation": 4
    },
    {
      "x": 0,
      "y": 4,
      "z": 1,
      "name": "Wood_Birch_Trunk",
      "support": 15,
      "rotation": 4
    },
    {
      "x": 0,
      "y": 0,
      "z": 2,
      "name": "Soil_Dirt"
    },
    {
      "x": 0,
      "y": 1,
      "z": 2,
      "name": "Soil_Dirt"
    },
    {
      "x": 0,
      "y": 2,
      "z": 2,
      "name": "Soil_Dirt"
    },
    {
      "x": 0,
      "y": 3,
      "z": 2,
      "name": "Wood_Maple_Trunk",
      "support": 15,
      "rotation": 4
    },
    {
      "x": 0,
      "y": 1,
      "z": 3,
      "name": "Soil_Dirt"
    },
    {
      "x": 0,
      "y": 2,
      "z": 3,
      "name": "Soil_Dirt"
    },
    {
      "x": 0,
      "y": 3,
      "z": 3,
      "name": "Wood_Maple_Trunk",
      "support": 15,
      "rotation": 4
    },
    {
      "x": 1,
      "y": 0,
      "z": -1,
      "name": "Soil_Pathway"
    },
    {
      "x": 1,
      "y": 1,
      "z": -1,
      "name": "Soil_Pathway"
    },
    {
      "x": 1,
      "y": 2,
      "z": -1,
      "name": "Soil_Pathway"
    },
    {
      "x": 1,
      "y": 4,
      "z": -1,
      "name": "Deco_Rope_Diagonal",
      "rotation": 1
    },
    {
      "x": 1,
      "y": 0,
      "z": 0,
      "name": "Soil_Pathway"
    },
    {
      "x": 1,
      "y": 1,
      "z": 0,
      "name": "Soil_Pathway"
    },
    {
      "x": 1,
      "y": 2,
      "z": 0,
      "name": "Soil_Pathway"
    },
    {
      "x": 1,
      "y": 0,
      "z": 1,
      "name": "Soil_Pathway"
    },
    {
      "x": 1,
      "y": 1,
      "z": 1,
      "name": "Soil_Pathway"
    },
    {
      "x": 1,
      "y": 2,
      "z": 1,
      "name": "Soil_Pathway"
    },
    {
      "x": 1,
      "y": 2,
      "z": 2,
      "name": "Soil_Pathway"
    },
    {
      "x": 1,
      "y": 3,
      "z": 2,
      "name": "Deco_Rope_Diagonal",
      "rotation": 1
    },
    {
      "x": 2,
      "y": 1,
      "z": -1,
      "name": "Soil_Pathway"
    },
    {
      "x": 2,
      "y": 2,
      "z": -1,
      "name": "Soil_Pathway"
    },
    {
      "x": 2,
      "y": 3,
      "z": -1,
      "name": "Deco_Rope_Diagonal",
      "rotation": 1
    }
  ]
}