{
  "version": 8,
  "blockIdVersion": 8,
  "anchorX": 0,
  "anchorY": 2,
  "anchorZ": 8,
  "blocks": [
    {
      "x": -11,
      "y": 0,
      "z": -8,
      "name": "Rock_Stone"
    },
    {
      "x": -11,
      "y": 1,
      "z": -8,
      "name": "Rock_Stone"
    },
    {
      "x": -11,
      "y": 2,
      "z": -8,
      "name": "Rock_Stone_Cobble"
    },
    {
      "x": -11,
      "y": 3,
      "z": -8,
      "name": "Rock_Quartzite_Brick"
    },
    {
      "x": -11,
      "y": 4,
      "z": -8,
      "name": "Rock_Quartzite_Brick"
    },
    {
      "x": -11,
      "y": 5,
      "z": -8,
      "name": "Rock_Quartzite_Brick"
    },
    {
      "x": -11,
      "y": 6,
      "z": -8,
      "name": "Rock_Quartzite"
    },
    {
      "x": -11,
      "y": 7,
      "z": -8,
      "name": "Rock_Quartzite"
    },
    {
      "x": -11,
      "y": 8,
      "z": -8,
      "name": "Rock_Quartzite"
    },
    {
      "x": -11,
      "y": 9,
      "z": -8,
      "name": "Rock_Quartzite"
    },
    {
      "x": -11,
      "y": 10,
      "z": -8,
      "name": "Rock_Quartzite"
    },
    {
      "x": -11,
      "y": 11,
      "z": -8,
      "name": "Rock_Quartzite"
    },
    {
      "x": -11,
      "y": 12,
      "z": -8,
      "name": "Rock_Quartzite"
    },
    {
      "x": -11,
      "y": 13,
      "z": -8,
      "name": "Rock_Quartzite"
    },
    {
      "x": -11,
      "y": 14,
      "z": -8,
      "name": "Rock_Quartzite"
    },
    {
      "x": -11,
      "y": 15,
      "z": -8,
      "name": "Rock_Quartzite"
    },
    {
      "x": -11,
      "y": 16,
      "z": -8,
      "name": "Rock_Quartzite"
    },
    {
      "x": -11,
      "y": 17,
      "z": -8,
      "name": "Rock_Quartzite"
    },
    {
      "x": -11,
      "y": 0,
      "z": -7,
      "name": "Rock_Stone"
    },
    {
      "x": -11,
      "y": 1,
      "z": -7,
      "name": "Rock_Stone"
    },
    {
      "x": -11,
      "y": 2,
      "z": -7,
      "name": "Rock_Stone_Cobble"
    },
    {
      "x": -11,
      "y": 3,
      "z": -7,
      "name": "Rock_Quartzite_Brick"
    },
    {
      "x": -11,
      "y": 4,
      "z": -7,
      "name": "Rock_Quartzite_Brick"
    },
    {
      "x": -11,
      "y": 5,
      "z": -7,
      "name": "Rock_Quartzite_Brick"
    },
    {
      "x": -11,
      "y": 6,
      "z": -7,
      "name": "Rock_Quartzite"
    },
    {
      "x": -11,
      "y": 7,
      "z": -7,
      "name": "Rock_Quartzite"
    },
    {
      "x": -11,
      "y": 8,
      "z": -7,
      "name": "Rock_Quartzite"
    },
    {
      "x": -11,
      "y": 9,
      "z": -7,
      "name": "Rock_Quartzite"
    },
    {
      "x": -11,
      "y": 10,
      "z": -7,
      "name": "Rock_Quartzite"
    },
    {
      "x": -11,
      "y": 11,
      "z": -7,
      "name": "Rock_Quartzite"
    },
    {
      "x": -11,
      "y": 12,
      "z": -7,
      "name": "Rock_Quartzite"
    },
    {
      "x": -11,
      "y": 13,
      "z": -7,
      "name": "Rock_Quartzite"
    },
    {
      "x": -11,
      "y": 14,
      "z": -7,
      "name": "Rock_Quartzite"
    },
    {
      "x": -11,
      "y": 15,
      "z": -7,
      "name": "Rock_Quartzite"
    },
    {
      "x": -11,
      "y": 16,
      "z": -7,
      "name": "Rock_Quartzite"
    },
    {
      "x": -11,
      "y": 17,
      "z": -7,
      "name": "Rock_Quartzite"
    },
    {
      "x": -11,
      "y": 0,
      "z": -6,
      "name": "Rock_Stone"
    },
    {
      "x": -11,
      "y": 1,
      "z": -6,
      "name": "Rock_Stone"
    },
    {
      "x": -11,
      "y": 2,
      "z": -6,
      "name": "Rock_Stone_Cobble"
    },
    {
      "x": -11,
      "y": 3,
      "z": -6,
      "name": "Rock_Quartzite_Brick"
    },
    {
      "x": -11,
      "y": 4,
      "z": -6,
      "name": "Rock_Quartzite_Brick"
    },
    {
      "x": -11,
      "y": 5,
      "z": -6,
      "name": "Rock_Quartzite_Brick"
    },
    {
      "x": -11,
      "y": 6,
      "z": -6,
      "name": "Rock_Quartzite"
    },
    {
      "x": -11,
      "y": 7,
      "z": -6,
      "name": "Rock_Quartzite"
    },
    {
      "x": -11,
      "y": 8,
      "z": -6,
      "name": "Rock_Quartzite"
    },
    {
      "x": -11,
      "y": 9,
      "z": -6,
      "name": "Rock_Quartzite"
    },
    {
      "x": -11,
      "y": 10,
      "z": -6,
      "name": "Rock_Quartzite"
    },
    {
      "x": -11,
      "y": 11,
      "z": -6,
      "name": "Rock_Quartzite"
    },
    {
      "x": -11,
      "y": 12,
      "z": -6,
      "name": "Rock_Quartzite"
    },
    {
      "x": -11,
      "y": 13,
      "z": -6,
      "name": "Rock_Quartzite"
    },
    {
      "x": -11,
      "y": 14,
      "z": -6,
      "name": "Rock_Quartzite"
    },
    {
      "x": -11,
      "y": 15,
      "z": -6,
      "name": "Rock_Quartzite"
    },
    {
      "x": -11,
      "y": 16,
      "z": -6,
      "name": "Rock_Quartzite"
    },
    {
      "x": -11,
      "y": 17,
      "z": -6,
      "name": "Rock_Quartzite"
    },
    {
      "x": -11,
      "y": 0,
      "z": -5,
      "name": "Rock_Stone"
    },
    {
      "x": -11,
      "y": 1,
      "z": -5,
      "name": "Rock_Stone"
    },
    {
      "x": -11,
      "y": 2,
      "z": -5,
      "name": "Rock_Stone_Cobble"
    },
    {
      "x": -11,
      "y": 3,
      "z": -5,
      "name": "Rock_Quartzite_Brick"
    },
    {
      "x": -11,
      "y": 4,
      "z": -5,
      "name": "Rock_Quartzite_Brick"
    },
    {
      "x": -11,
      "y": 5,
      "z": -5,
      "name": "Rock_Quartzite_Brick"
    },
    {
      "x": -11,
      "y": 6,
      "z": -5,
      "name": "Rock_Quartzite"
    },
    {
      "x": -11,
      "y": 7,
      "z": -5,
      "name": "Rock_Quartzite"
    },
    {
      "x": -11,
      "y": 8,
      "z": -5,
      "name": "Rock_Quartzite"
    },
    {
      "x": -11,
      "y": 9,
      "z": -5,
      "name": "Rock_Quartzite"
    },
    {
      "x": -11,
      "y": 10,
      "z": -5,
      "name": "Rock_Quartzite"
    },
    {
      "x": -11,
      "y": 11,
      "z": -5,
      "name": "Rock_Quartzite"
    },
    {
      "x": -11,
      "y": 12,
      "z": -5,
      "name": "Rock_Quartzite"
    },
    {
      "x": -11,
      "y": 13,
      "z": -5,
      "name": "Rock_Quartzite"
    },
    {
      "x": -11,
      "y": 14,
      "z": -5,
      "name": "Rock_Quartzite"
    },
    {
      "x": -11,
      "y": 15,
      "z": -5,
      "name": "Rock_Quartzite"
    },
    {
      "x": -11,
      "y": 16,
      "z": -5,
      "name": "Rock_Quartzite"
    },
    {
      "x": -11,
      "y": 17,
      "z": -5,
      "name": "Rock_Quartzite"
    },
    {
      "x": -11,
      "y": 0,
      "z": -4,
      "name": "Rock_Stone"
    },
    {
      "x": -11,
      "y": 1,
      "z": -4,
      "name": "Rock_Stone"
    },
    {
      "x": -11,
      "y": 2,
      "z": -4,
      "name": "Rock_Stone_Cobble"
    },
    {
      "x": -11,
      "y": 3,
      "z": -4,
      "name": "Rock_Quartzite_Brick"
    },
    {
      "x": -11,
      "y": 4,
      "z": -4,
      "name": "Rock_Quartzite_Brick"
    },
    {
      "x": -11,
      "y": 5,
      "z": -4,
      "name": "Rock_Quartzite_Brick"
    },
    {
      "x": -11,
      "y": 6,
      "z": -4,
      "name": "Rock_Quartzite"
    },
    {
      "x": -11,
      "y": 7,
      "z": -4,
      "name": "Rock_Quartzite"
    },
    {
      "x": -11,
      "y": 8,
      "z": -4,
      "name": "Rock_Quartzite"
    },
    {
      "x": -11,
      "y": 9,
      "z": -4,
      "name": "Rock_Quartzite"
    },
    {
      "x": -11,
      "y": 10,
      "z": -4,
      "name": "Rock_Quartzite"
    },
    {
      "x": -11,
      "y": 11,
      "z": -4,
      "name": "Rock_Quartzite"
    },
    {
      "x": -11,
      "y": 12,
      "z": -4,
      "name": "Rock_Quartzite"
    },
    {
      "x": -11,
      "y": 13,
      "z": -4,
      "name": "Rock_Quartzite"
    },
    {
      "x": -11,
      "y": 14,
      "z": -4,
      "name": "Rock_Quartzite"
    },
    {
      "x": -11,
      "y": 15,
      "z": -4,
      "name": "Rock_Quartzite"
    },
    {
      "x": -11,
      "y": 16,
      "z": -4,
      "name": "Rock_Quartzite"
    },
    {
      "x": -11,
      "y": 17,
      "z": -4,
      "name": "Rock_Quartzite"
    },
    {
      "x": -11,
      "y": 0,
      "z": -3,
      "name": "Rock_Stone"
    },
    {
      "x": -11,
      "y": 1,
      "z": -3,
      "name": "Rock_Stone"
    },
    {
      "x": -11,
      "y": 2,
      "z": -3,
      "name": "Rock_Stone_Cobble"
    },
    {
      "x": -11,
      "y": 3,
      "z": -3,
      "name": "Rock_Quartzite_Brick"
    },
    {
      "x": -11,
      "y": 4,
      "z": -3,
      "name": "Rock_Quartzite_Brick"
    },
    {
      "x": -11,
      "y": 5,
      "z": -3,
      "name": "Rock_Quartzite_Brick"
    },
    {
      "x": -11,
      "y": 6,
      "z": -3,
      "name": "Rock_Quartzite"
    },
    {
      "x": -11,
      "y": 7,
      "z": -3,
      "name": "Rock_Quartzite"
    },
    {
      "x": -11,
      "y": 8,
      "z": -3,
      "name": "Rock_Quartzite"
    },
    {
      "x": -11,
      "y": 9,
      "z": -3,
      "name": "Rock_Quartzite"
    },
    {
      "x": -11,
      "y": 10,
      "z": -3,
      "name": "Rock_Quartzite"
    },
    {
      "x": -11,
      "y": 11,
      "z": -3,
      "name": "Rock_Quartzite"
    },
    {
      "x": -11,
      "y": 12,
      "z": -3,
      "name": "Rock_Quartzite"
    },
    {
      "x": -11,
      "y": 13,
      "z": -3,
      "name": "Rock_Quartzite"
    },
    {
      "x": -11,
      "y": 14,
      "z": -3,
      "name": "Rock_Quartzite"
    },
    {
      "x": -11,
      "y": 15,
      "z": -3,
      "name": "Rock_Quartzite"
    },
    {
      "x": -11,
      "y": 16,
      "z": -3,
      "name": "Rock_Quartzite"
    },
    {
      "x": -11,
      "y": 17,
      "z": -3,
      "name": "Rock_Quartzite"
    },
    {
      "x": -11,
      "y": 0,
      "z": -2,
      "name": "Rock_Stone"
    },
    {
      "x": -11,
      "y": 1,
      "z": -2,
      "name": "Rock_Stone"
    },
    {
      "x": -11,
      "y": 2,
      "z": -2,
      "name": "Rock_Stone_Cobble"
    },
    {
      "x": -11,
      "y": 3,
      "z": -2,
      "name": "Rock_Quartzite_Brick"
    },
    {
      "x": -11,
      "y": 4,
      "z": -2,
      "name": "Rock_Quartzite_Brick"
    },
    {
      "x": -11,
      "y": 5,
      "z": -2,
      "name": "Rock_Quartzite_Brick"
    },
    {
      "x": -11,
      "y": 6,
      "z": -2,
      "name": "Rock_Quartzite"
    },
    {
      "x": -11,
      "y": 7,
      "z": -2,
      "name": "Rock_Quartzite"
    },
    {
      "x": -11,
      "y": 8,
      "z": -2,
      "name": "Rock_Quartzite"
    },
    {
      "x": -11,
      "y": 9,
      "z": -2,
      "name": "Rock_Quartzite"
    },
    {
      "x": -11,
      "y": 10,
      "z": -2,
      "name": "Rock_Quartzite"
    },
    {
      "x": -11,
      "y": 11,
      "z": -2,
      "name": "Rock_Quartzite"
    },
    {
      "x": -11,
      "y": 12,
      "z": -2,
      "name": "Rock_Quartzite"
    },
    {
      "x": -11,
      "y": 13,
      "z": -2,
      "name": "Rock_Quartzite"
    },
    {
      "x": -11,
      "y": 14,
      "z": -2,
      "name": "Rock_Quartzite"
    },
    {
      "x": -11,
      "y": 15,
      "z": -2,
      "name": "Rock_Quartzite"
    },
    {
      "x": -11,
      "y": 16,
      "z": -2,
      "name": "Rock_Quartzite"
    },
    {
      "x": -11,
      "y": 17,
      "z": -2,
      "name": "Rock_Quartzite"
    },
    {
      "x": -11,
      "y": 0,
      "z": -1,
      "name": "Rock_Stone"
    },
    {
      "x": -11,
      "y": 1,
      "z": -1,
      "name": "Rock_Stone"
    },
    {
      "x": -11,
      "y": 2,
      "z": -1,
      "name": "Rock_Stone_Cobble"
    },
    {
      "x": -11,
      "y": 3,
      "z": -1,
      "name": "Rock_Quartzite_Brick"
    },
    {
      "x": -11,
      "y": 4,
      "z": -1,
      "name": "Rock_Quartzite_Brick"
    },
    {
      "x": -11,
      "y": 5,
      "z": -1,
      "name": "Rock_Quartzite_Brick"
    },
    {
      "x": -11,
      "y": 6,
      "z": -1,
      "name": "Rock_Quartzite"
    },
    {
      "x": -11,
      "y": 7,
      "z": -1,
      "name": "Rock_Quartzite"
    },
    {
      "x": -11,
      "y": 8,
      "z": -1,
      "name": "Rock_Quartzite"
    },
    {
      "x": -11,
      "y": 9,
      "z": -1,
      "name": "Rock_Quartzite"
    },
    {
      "x": -11,
      "y": 10,
      "z": -1,
      "name": "Rock_Quartzite"
    },
    {
      "x": -11,
      "y": 11,
      "z": -1,
      "name": "Rock_Quartzite"
    },
    {
      "x": -11,
      "y": 12,
      "z": -1,
      "name": "Rock_Quartzite"
    },
    {
      "x": -11,
      "y": 13,
      "z": -1,
      "name": "Rock_Quartzite"
    },
    {
      "x": -11,
      "y": 14,
      "z": -1,
      "name": "Rock_Quartzite"
    },
    {
      "x": -11,
      "y": 15,
      "z": -1,
      "name": "Rock_Quartzite"
    },
    {
      "x": -11,
      "y": 16,
      "z": -1,
      "name": "Rock_Quartzite"
    },
    {
      "x": -11,
      "y": 17,
      "z": -1,
      "name": "Rock_Quartzite"
    },
    {
      "x": -11,
      "y": 0,
      "z": 0,
      "name": "Rock_Stone"
    },
    {
      "x": -11,
      "y": 1,
      "z": 0,
      "name": "Rock_Stone"
    },
    {
      "x": -11,
      "y": 2,
      "z": 0,
      "name": "Rock_Stone_Cobble"
    },
    {
      "x": -11,
      "y": 3,
      "z": 0,
      "name": "Rock_Quartzite_Brick"
    },
    {
      "x": -11,
      "y": 4,
      "z": 0,
      "name": "Rock_Quartzite_Brick"
    },
    {
      "x": -11,
      "y": 5,
      "z": 0,
      "name": "Rock_Quartzite_Brick"
    },
    {
      "x": -11,
      "y": 6,
      "z": 0,
      "name": "Rock_Quartzite"
    },
    {
      "x": -11,
      "y": 7,
      "z": 0,
      "name": "Rock_Quartzite"
    },
    {
      "x": -11,
      "y": 8,
      "z": 0,
      "name": "Rock_Quartzite"
    },
    {
      "x": -11,
      "y": 9,
      "z": 0,
      "name": "Rock_Quartzite"
    },
    {
      "x": -11,
      "y": 10,
      "z": 0,
      "name": "Rock_Quartzite"
    },
    {
      "x": -11,
      "y": 11,
      "z": 0,
      "name": "Rock_Quartzite"
    },
    {
      "x": -11,
      "y": 12,
      "z": 0,
      "name": "Rock_Quartzite"
    },
    {
      "x": -11,
      "y": 13,
      "z": 0,
      "name": "Rock_Quartzite"
    },
    {
      "x": -11,
      "y": 14,
      "z": 0,
      "name": "Rock_Quartzite"
    },
    {
      "x": -11,
      "y": 15,
      "z": 0,
      "name": "Rock_Quartzite"
    },
    {
      "x": -11,
      "y": 16,
      "z": 0,
      "name": "Rock_Quartzite"
    },
    {
      "x": -11,
      "y": 17,
      "z": 0,
      "name": "Rock_Quartzite"
    },
    {
      "x": -11,
      "y": 0,
      "z": 1,
      "name": "Rock_Stone"
    },
    {
      "x": -11,
      "y": 1,
      "z": 1,
      "name": "Rock_Stone"
    },
    {
      "x": -11,
      "y": 2,
      "z": 1,
      "name": "Rock_Stone_Cobble"
    },
    {
      "x": -11,
      "y": 3,
      "z": 1,
      "name": "Rock_Quartzite_Brick"
    },
    {
      "x": -11,
      "y": 4,
      "z": 1,
      "name": "Rock_Quartzite_Brick"
    },
    {
      "x": -11,
      "y": 5,
      "z": 1,
      "name": "Rock_Quartzite_Brick"
    },
    {
      "x": -11,
      "y": 6,
      "z": 1,
      "name": "Rock_Quartzite"
    },
    {
      "x": -11,
      "y": 7,
      "z": 1,
      "name": "Rock_Quartzite"
    },
    {
      "x": -11,
      "y": 8,
      "z": 1,
      "name": "Rock_Quartzite"
    },
    {
      "x": -11,
      "y": 9,
      "z": 1,
      "name": "Rock_Quartzite"
    },
    {
      "x": -11,
      "y": 10,
      "z": 1,
      "name": "Rock_Quartzite"
    },
    {
      "x": -11,
      "y": 11,
      "z": 1,
      "name": "Rock_Quartzite"
    },
    {
      "x": -11,
      "y": 12,
      "z": 1,
      "name": "Rock_Quartzite"
    },
    {
      "x": -11,
      "y": 13,
      "z": 1,
      "name": "Rock_Quartzite"
    },
    {
      "x": -11,
      "y": 14,
      "z": 1,
      "name": "Rock_Quartzite"
    },
    {
      "x": -11,
      "y": 15,
      "z": 1,
      "name": "Rock_Quartzite"
    },
    {
      "x": -11,
      "y": 16,
      "z": 1,
      "name": "Rock_Quartzite"
    },
    {
      "x": -11,
      "y": 17,
      "z": 1,
      "name": "Rock_Quartzite"
    },
    {
      "x": -11,
      "y": 0,
      "z": 2,
      "name": "Rock_Stone"
    },
    {
      "x": -11,
      "y": 1,
      "z": 2,
      "name": "Rock_Stone"
    },
    {
      "x": -11,
      "y": 2,
      "z": 2,
      "name": "Rock_Stone_Cobble"
    },
    {
      "x": -11,
      "y": 3,
      "z": 2,
      "name": "Rock_Quartzite_Brick"
    },
    {
      "x": -11,
      "y": 4,
      "z": 2,
      "name": "Rock_Quartzite_Brick"
    },
    {
      "x": -11,
      "y": 5,
      "z": 2,
      "name": "Rock_Quartzite_Brick"
    },
    {
      "x": -11,
      "y": 6,
      "z": 2,
      "name": "Rock_Quartzite"
    },
    {
      "x": -11,
      "y": 7,
      "z": 2,
      "name": "Rock_Quartzite"
    },
    {
      "x": -11,
      "y": 8,
      "z": 2,
      "name": "Rock_Quartzite"
    },
    {
      "x": -11,
      "y": 9,
      "z": 2,
      "name": "Rock_Quartzite"
    },
    {
      "x": -11,
      "y": 10,
      "z": 2,
      "name": "Rock_Quartzite"
    },
    {
      "x": -11,
      "y": 11,
      "z": 2,
      "name": "Rock_Quartzite"
    },
    {
      "x": -11,
      "y": 12,
      "z": 2,
      "name": "Rock_Quartzite"
    },
    {
      "x": -11,
      "y": 13,
      "z": 2,
      "name": "Rock_Quartzite"
    },
    {
      "x": -11,
      "y": 14,
      "z": 2,
      "name": "Rock_Quartzite"
    },
    {
      "x": -11,
      "y": 15,
      "z": 2,
      "name": "Rock_Quartzite"
    },
    {
      "x": -11,
      "y": 16,
      "z": 2,
      "name": "Rock_Quartzite"
    },
    {
      "x": -11,
      "y": 17,
      "z": 2,
      "name": "Rock_Quartzite"
    },
    {
      "x": -11,
      "y": 0,
      "z": 3,
      "name": "Rock_Stone"
    },
    {
      "x": -11,
      "y": 1,
      "z": 3,
      "name": "Rock_Stone"
    },
    {
      "x": -11,
      "y": 2,
      "z": 3,
      "name": "Rock_Stone_Cobble"
    },
    {
      "x": -11,
      "y": 3,
      "z": 3,
      "name": "Rock_Quartzite_Brick"
    },
    {
      "x": -11,
      "y": 4,
      "z": 3,
      "name": "Rock_Quartzite_Brick"
    },
    {
      "x": -11,
      "y": 5,
      "z": 3,
      "name": "Rock_Quartzite_Brick"
    },
    {
      "x": -11,
      "y": 6,
      "z": 3,
      "name": "Rock_Quartzite"
    },
    {
      "x": -11,
      "y": 7,
      "z": 3,
      "name": "Rock_Quartzite"
    },
    {
      "x": -11,
      "y": 8,
      "z": 3,
      "name": "Rock_Quartzite"
    },
    {
      "x": -11,
      "y": 9,
      "z": 3,
      "name": "Rock_Quartzite"
    },
    {
      "x": -11,
      "y": 10,
      "z": 3,
      "name": "Rock_Quartzite"
    },
    {
      "x": -11,
      "y": 11,
      "z": 3,
      "name": "Rock_Quartzite"
    },
    {
      "x": -11,
      "y": 12,
      "z": 3,
      "name": "Rock_Quartzite"
    },
    {
      "x": -11,
      "y": 13,
      "z": 3,
      "name": "Rock_Quartzite"
    },
    {
      "x": -11,
      "y": 14,
      "z": 3,
      "name": "Rock_Quartzite"
    },
    {
      "x": -11,
      "y": 15,
      "z": 3,
      "name": "Rock_Quartzite"
    },
    {
      "x": -11,
      "y": 16,
      "z": 3,
      "name": "Rock_Quartzite"
    },
    {
      "x": -11,
      "y": 17,
      "z": 3,
      "name": "Rock_Quartzite"
    },
    {
      "x": -11,
      "y": 0,
      "z": 4,
      "name": "Rock_Stone"
    },
    {
      "x": -11,
      "y": 1,
      "z": 4,
      "name": "Rock_Stone"
    },
    {
      "x": -11,
      "y": 2,
      "z": 4,
      "name": "Rock_Stone_Cobble"
    },
    {
      "x": -11,
      "y": 3,
      "z": 4,
      "name": "Rock_Quartzite_Brick"
    },
    {
      "x": -11,
      "y": 4,
      "z": 4,
      "name": "Rock_Quartzite_Brick"
    },
    {
      "x": -11,
      "y": 5,
      "z": 4,
      "name": "Rock_Quartzite_Brick"
    },
    {
      "x": -11,
      "y": 6,
      "z": 4,
      "name": "Rock_Quartzite_Brick"
    },
    {
      "x": -11,
      "y": 7,
      "z": 4,
      "name": "Rock_Quartzite"
    },
    {
      "x": -11,
      "y": 8,
      "z": 4,
      "name": "Rock_Quartzite"
    },
    {
      "x": -11,
      "y": 9,
      "z": 4,
      "name": "Rock_Quartzite"
    },
    {
      "x": -11,
      "y": 10,
      "z": 4,
      "name": "Rock_Quartzite"
    },
    {
      "x": -11,
      "y": 11,
      "z": 4,
      "name": "Rock_Quartzite"
    },
    {
      "x": -11,
      "y": 12,
      "z": 4,
      "name": "Rock_Quartzite"
    },
    {
      "x": -11,
      "y": 13,
      "z": 4,
      "name": "Rock_Quartzite"
    },
    {
      "x": -11,
      "y": 14,
      "z": 4,
      "name": "Rock_Quartzite"
    },
    {
      "x": -11,
      "y": 15,
      "z": 4,
      "name": "Rock_Quartzite"
    },
    {
      "x": -11,
      "y": 16,
      "z": 4,
      "name": "Rock_Quartzite"
    },
    {
      "x": -11,
      "y": 17,
      "z": 4,
      "name": "Rock_Quartzite"
    },
    {
      "x": -11,
      "y": 0,
      "z": 5,
      "name": "Rock_Stone"
    },
    {
      "x": -11,
      "y": 1,
      "z": 5,
      "name": "Rock_Stone"
    },
    {
      "x": -11,
      "y": 2,
      "z": 5,
      "name": "Rock_Stone_Cobble"
    },
    {
      "x": -11,
      "y": 3,
      "z": 5,
      "name": "Rock_Quartzite_Brick"
    },
    {
      "x": -11,
      "y": 4,
      "z": 5,
      "name": "Rock_Quartzite_Brick"
    },
    {
      "x": -11,
      "y": 5,
      "z": 5,
      "name": "Rock_Quartzite_Brick"
    },
    {
      "x": -11,
      "y": 6,
      "z": 5,
      "name": "Rock_Quartzite_Brick"
    },
    {
      "x": -11,
      "y": 7,
      "z": 5,
      "name": "Rock_Quartzite_Brick"
    },
    {
      "x": -11,
      "y": 8,
      "z": 5,
      "name": "Rock_Quartzite"
    },
    {
      "x": -11,
      "y": 9,
      "z": 5,
      "name": "Rock_Quartzite"
    },
    {
      "x": -11,
      "y": 10,
      "z": 5,
      "name": "Rock_Quartzite"
    },
    {
      "x": -11,
      "y": 11,
      "z": 5,
      "name": "Rock_Quartzite"
    },
    {
      "x": -11,
      "y": 12,
      "z": 5,
      "name": "Rock_Quartzite"
    },
    {
      "x": -11,
      "y": 13,
      "z": 5,
      "name": "Rock_Quartzite"
    },
    {
      "x": -11,
      "y": 14,
      "z": 5,
      "name": "Rock_Quartzite"
    },
    {
      "x": -11,
      "y": 15,
      "z": 5,
      "name": "Rock_Quartzite"
    },
    {
      "x": -11,
      "y": 16,
      "z": 5,
      "name": "Rock_Quartzite"
    },
    {
      "x": -11,
      "y": 17,
      "z": 5,
      "name": "Rock_Quartzite"
    },
    {
      "x": -11,
      "y": 0,
      "z": 6,
      "name": "Rock_Stone"
    },
    {
      "x": -11,
      "y": 1,
      "z": 6,
      "name": "Rock_Stone"
    },
    {
      "x": -11,
      "y": 2,
      "z": 6,
      "name": "Rock_Stone_Cobble"
    },
    {
      "x": -11,
      "y": 3,
      "z": 6,
      "name": "Rock_Quartzite_Brick"
    },
    {
      "x": -11,
      "y": 4,
      "z": 6,
      "name": "Rock_Quartzite_Brick"
    },
    {
      "x": -11,
      "y": 5,
      "z": 6,
      "name": "Rock_Quartzite_Brick"
    },
    {
      "x": -11,
      "y": 6,
      "z": 6,
      "name": "Rock_Quartzite"
    },
    {
      "x": -11,
      "y": 7,
      "z": 6,
      "name": "Rock_Quartzite"
    },
    {
      "x": -11,
      "y": 8,
      "z": 6,
      "name": "Rock_Quartzite"
    },
    {
      "x": -11,
      "y": 9,
      "z": 6,
      "name": "Rock_Quartzite"
    },
    {
      "x": -11,
      "y": 10,
      "z": 6,
      "name": "Rock_Quartzite"
    },
    {
      "x": -11,
      "y": 11,
      "z": 6,
      "name": "Rock_Quartzite"
    },
    {
      "x": -11,
      "y": 12,
      "z": 6,
      "name": "Rock_Quartzite"
    },
    {
      "x": -11,
      "y": 13,
      "z": 6,
      "name": "Rock_Quartzite"
    },
    {
      "x": -11,
      "y": 14,
      "z": 6,
      "name": "Rock_Quartzite"
    },
    {
      "x": -11,
      "y": 15,
      "z": 6,
      "name": "Rock_Quartzite"
    },
    {
      "x": -11,
      "y": 16,
      "z": 6,
      "name": "Rock_Quartzite"
    },
    {
      "x": -11,
      "y": 17,
      "z": 6,
      "name": "Rock_Quartzite"
    },
    {
      "x": -11,
      "y": 0,
      "z": 7,
      "name": "Rock_Stone"
    },
    {
      "x": -11,
      "y": 1,
      "z": 7,
      "name": "Rock_Stone"
    },
    {
      "x": -11,
      "y": 2,
      "z": 7,
      "name": "Rock_Stone_Cobble"
    },
    {
      "x": -11,
      "y": 3,
      "z": 7,
      "name": "Rock_Quartzite_Brick"
    },
    {
      "x": -11,
      "y": 4,
      "z": 7,
      "name": "Rock_Quartzite_Brick"
    },
    {
      "x": -11,
      "y": 5,
      "z": 7,
      "name": "Rock_Quartzite_Brick"
    },
    {
      "x": -11,
      "y": 6,
      "z": 7,
      "name": "Rock_Quartzite"
    },
    {
      "x": -11,
      "y": 7,
      "z": 7,
      "name": "Rock_Quartzite"
    },
    {
      "x": -11,
      "y": 8,
      "z": 7,
      "name": "Rock_Quartzite"
    },
    {
      "x": -11,
      "y": 9,
      "z": 7,
      "name": "Rock_Quartzite"
    },
    {
      "x": -11,
      "y": 10,
      "z": 7,
      "name": "Rock_Quartzite"
    },
    {
      "x": -11,
      "y": 11,
      "z": 7,
      "name": "Rock_Quartzite"
    },
    {
      "x": -11,
      "y": 12,
      "z": 7,
      "name": "Rock_Quartzite"
    },
    {
      "x": -11,
      "y": 13,
      "z": 7,
      "name": "Rock_Quartzite"
    },
    {
      "x": -11,
      "y": 14,
      "z": 7,
      "name": "Rock_Quartzite"
    },
    {
      "x": -11,
      "y": 15,
      "z": 7,
      "name": "Rock_Quartzite"
    },
    {
      "x": -11,
      "y": 16,
      "z": 7,
      "name": "Rock_Quartzite"
    },
    {
      "x": -11,
      "y": 17,
      "z": 7,
      "name": "Rock_Quartzite"
    },
    {
      "x": -11,
      "y": 0,
      "z": 8,
      "name": "Rock_Stone"
    },
    {
      "x": -11,
      "y": 1,
      "z": 8,
      "name": "Rock_Stone"
    },
    {
      "x": -11,
      "y": 2,
      "z": 8,
      "name": "Rock_Stone_Cobble"
    },
    {
      "x": -11,
      "y": 3,
      "z": 8,
      "name": "Rock_Quartzite_Brick"
    },
    {
      "x": -11,
      "y": 4,
      "z": 8,
      "name": "Rock_Quartzite_Brick"
    },
    {
      "x": -11,
      "y": 5,
      "z": 8,
      "name": "Rock_Quartzite_Brick"
    },
    {
      "x": -11,
      "y": 6,
      "z": 8,
      "name": "Rock_Quartzite"
    },
    {
      "x": -11,
      "y": 7,
      "z": 8,
      "name": "Rock_Quartzite"
    },
    {
      "x": -11,
      "y": 8,
      "z": 8,
      "name": "Rock_Quartzite"
    },
    {
      "x": -11,
      "y": 9,
      "z": 8,
      "name": "Rock_Quartzite"
    },
    {
      "x": -11,
      "y": 10,
      "z": 8,
      "name": "Rock_Quartzite"
    },
    {
      "x": -11,
      "y": 11,
      "z": 8,
      "name": "Rock_Quartzite"
    },
    {
      "x": -11,
      "y": 12,
      "z": 8,
      "name": "Rock_Quartzite"
    },
    {
      "x": -11,
      "y": 13,
      "z": 8,
      "name": "Rock_Quartzite"
    },
    {
      "x": -11,
      "y": 14,
      "z": 8,
      "name": "Rock_Quartzite"
    },
    {
      "x": -11,
      "y": 15,
      "z": 8,
      "name": "Rock_Quartzite"
    },
    {
      "x": -11,
      "y": 16,
      "z": 8,
      "name": "Rock_Quartzite"
    },
    {
      "x": -11,
      "y": 17,
      "z": 8,
      "name": "Rock_Quartzite"
    },
    {
      "x": -10,
      "y": 0,
      "z": -8,
      "name": "Rock_Stone"
    },
    {
      "x": -10,
      "y": 1,
      "z": -8,
      "name": "Rock_Stone"
    },
    {
      "x": -10,
      "y": 2,
      "z": -8,
      "name": "Rock_Stone_Cobble"
    },
    {
      "x": -10,
      "y": 3,
      "z": -8,
      "name": "Rock_Quartzite_Brick"
    },
    {
      "x": -10,
      "y": 4,
      "z": -8,
      "name": "Rock_Quartzite_Brick"
    },
    {
      "x": -10,
      "y": 5,
      "z": -8,
      "name": "Rock_Quartzite_Brick"
    },
    {
      "x": -10,
      "y": 6,
      "z": -8,
      "name": "Rock_Quartzite_Brick"
    },
    {
      "x": -10,
      "y": 7,
      "z": -8,
      "name": "Rock_Quartzite"
    },
    {
      "x": -10,
      "y": 8,
      "z": -8,
      "name": "Rock_Quartzite"
    },
    {
      "x": -10,
      "y": 9,
      "z": -8,
      "name": "Rock_Quartzite"
    },
    {
      "x": -10,
      "y": 10,
      "z": -8,
      "name": "Rock_Quartzite"
    },
    {
      "x": -10,
      "y": 11,
      "z": -8,
      "name": "Rock_Quartzite"
    },
    {
      "x": -10,
      "y": 12,
      "z": -8,
      "name": "Rock_Quartzite"
    },
    {
      "x": -10,
      "y": 13,
      "z": -8,
      "name": "Rock_Quartzite"
    },
    {
      "x": -10,
      "y": 14,
      "z": -8,
      "name": "Rock_Quartzite"
    },
    {
      "x": -10,
      "y": 15,
      "z": -8,
      "name": "Rock_Quartzite"
    },
    {
      "x": -10,
      "y": 16,
      "z": -8,
      "name": "Rock_Quartzite"
    },
    {
      "x": -10,
      "y": 17,
      "z": -8,
      "name": "Rock_Quartzite"
    },
    {
      "x": -10,
      "y": 0,
      "z": -7,
      "name": "Rock_Stone"
    },
    {
      "x": -10,
      "y": 1,
      "z": -7,
      "name": "Rock_Stone"
    },
    {
      "x": -10,
      "y": 2,
      "z": -7,
      "name": "Rock_Stone_Cobble"
    },
    {
      "x": -10,
      "y": 3,
      "z": -7,
      "name": "Rock_Stone_Cobble"
    },
    {
      "x": -10,
      "y": 4,
      "z": -7,
      "name": "Rock_Stone_Cobble"
    },
    {
      "x": -10,
      "y": 5,
      "z": -7,
      "name": "Rock_Quartzite_Brick"
    },
    {
      "x": -10,
      "y": 6,
      "z": -7,
      "name": "Rock_Quartzite_Brick"
    },
    {
      "x": -10,
      "y": 7,
      "z": -7,
      "name": "Rock_Quartzite_Brick"
    },
    {
      "x": -10,
      "y": 8,
      "z": -7,
      "name": "Rock_Quartzite_Brick"
    },
    {
      "x": -10,
      "y": 9,
      "z": -7,
      "name": "Rock_Quartzite_Brick"
    },
    {
      "x": -10,
      "y": 10,
      "z": -7,
      "name": "Wood_Deadwood_Planks"
    },
    {
      "x": -10,
      "y": 11,
      "z": -7,
      "name": "Rock_Quartzite_Brick"
    },
    {
      "x": -10,
      "y": 12,
      "z": -7,
      "name": "Rock_Quartzite"
    },
    {
      "x": -10,
      "y": 13,
      "z": -7,
      "name": "Rock_Quartzite_Brick"
    },
    {
      "x": -10,
      "y": 14,
      "z": -7,
      "name": "Rock_Quartzite_Brick"
    },
    {
      "x": -10,
      "y": 15,
      "z": -7,
      "name": "Rock_Quartzite"
    },
    {
      "x": -10,
      "y": 16,
      "z": -7,
      "name": "Rock_Quartzite"
    },
    {
      "x": -10,
      "y": 17,
      "z": -7,
      "name": "Rock_Quartzite"
    },
    {
      "x": -10,
      "y": 0,
      "z": -6,
      "name": "Rock_Stone"
    },
    {
      "x": -10,
      "y": 1,
      "z": -6,
      "name": "Rock_Stone"
    },
    {
      "x": -10,
      "y": 2,
      "z": -6,
      "name": "Rock_Stone_Cobble"
    },
    {
      "x": -10,
      "y": 3,
      "z": -6,
      "name": "Rock_Stone_Cobble"
    },
    {
      "x": -10,
      "y": 4,
      "z": -6,
      "name": "Rock_Stone_Cobble"
    },
    {
      "x": -10,
      "y": 5,
      "z": -6,
      "name": "Rock_Quartzite_Brick"
    },
    {
      "x": -10,
      "y": 6,
      "z": -6,
      "name": "Rock_Quartzite_Brick"
    },
    {
      "x": -10,
      "y": 7,
      "z": -6,
      "name": "Rock_Quartzite_Brick"
    },
    {
      "x": -10,
      "y": 8,
      "z": -6,
      "name": "Rock_Quartzite_Brick"
    },
    {
      "x": -10,
      "y": 9,
      "z": -6,
      "name": "Rock_Quartzite_Brick"
    },
    {
      "x": -10,
      "y": 10,
      "z": -6,
      "name": "Wood_Deadwood_Planks"
    },
    {
      "x": -10,
      "y": 11,
      "z": -6,
      "name": "Rock_Quartzite_Brick"
    },
    {
      "x": -10,
      "y": 12,
      "z": -6,
      "name": "Rock_Quartzite_Brick"
    },
    {
      "x": -10,
      "y": 13,
      "z": -6,
      "name": "Rock_Quartzite"
    },
    {
      "x": -10,
      "y": 14,
      "z": -6,
      "name": "Rock_Quartzite"
    },
    {
      "x": -10,
      "y": 15,
      "z": -6,
      "name": "Rock_Quartzite"
    },
    {
      "x": -10,
      "y": 16,
      "z": -6,
      "name": "Rock_Quartzite"
    },
    {
      "x": -10,
      "y": 17,
      "z": -6,
      "name": "Rock_Quartzite"
    },
    {
      "x": -10,
      "y": 0,
      "z": -5,
      "name": "Rock_Stone"
    },
    {
      "x": -10,
      "y": 1,
      "z": -5,
      "name": "Rock_Stone"
    },
    {
      "x": -10,
      "y": 2,
      "z": -5,
      "name": "Rock_Stone_Cobble"
    },
    {
      "x": -10,
      "y": 3,
      "z": -5,
      "name": "Rock_Stone_Cobble"
    },
    {
      "x": -10,
      "y": 4,
      "z": -5,
      "name": "Rock_Stone_Cobble"
    },
    {
      "x": -10,
      "y": 5,
      "z": -5,
      "name": "Rock_Quartzite_Brick"
    },
    {
      "x": -10,
      "y": 6,
      "z": -5,
      "name": "Rock_Quartzite_Brick"
    },
    {
      "x": -10,
      "y": 7,
      "z": -5,
      "name": "Rock_Quartzite_Brick"
    },
    {
      "x": -10,
      "y": 8,
      "z": -5,
      "name": "Rock_Quartzite_Brick"
    },
    {
      "x": -10,
      "y": 9,
      "z": -5,
      "name": "Rock_Quartzite_Brick"
    },
    {
      "x": -10,
      "y": 10,
      "z": -5,
      "name": "Rock_Quartzite_Brick"
    },
    {
      "x": -10,
      "y": 11,
      "z": -5,
      "name": "Rock_Quartzite_Brick"
    },
    {
      "x": -10,
      "y": 12,
      "z": -5,
      "name": "Rock_Quartzite_Brick"
    },
    {
      "x": -10,
      "y": 13,
      "z": -5,
      "name": "Rock_Quartzite"
    },
    {
      "x": -10,
      "y": 14,
      "z": -5,
      "name": "Rock_Quartzite"
    },
    {
      "x": -10,
      "y": 15,
      "z": -5,
      "name": "Rock_Quartzite"
    },
    {
      "x": -10,
      "y": 16,
      "z": -5,
      "name": "Rock_Quartzite"
    },
    {
      "x": -10,
      "y": 17,
      "z": -5,
      "name": "Rock_Quartzite"
    },
    {
      "x": -10,
      "y": 0,
      "z": -4,
      "name": "Rock_Stone"
    },
    {
      "x": -10,
      "y": 1,
      "z": -4,
      "name": "Rock_Stone"
    },
    {
      "x": -10,
      "y": 2,
      "z": -4,
      "name": "Rock_Stone_Cobble"
    },
    {
      "x": -10,
      "y": 3,
      "z": -4,
      "name": "Rock_Stone_Cobble"
    },
    {
      "x": -10,
      "y": 4,
      "z": -4,
      "name": "Rock_Stone_Cobble"
    },
    {
      "x": -10,
      "y": 5,
      "z": -4,
      "name": "Rock_Quartzite_Brick"
    },
    {
      "x": -10,
      "y": 6,
      "z": -4,
      "name": "Rock_Quartzite_Brick"
    },
    {
      "x": -10,
      "y": 7,
      "z": -4,
      "name": "Rock_Quartzite_Brick"
    },
    {
      "x": -10,
      "y": 8,
      "z": -4,
      "name": "Rock_Quartzite_Brick"
    },
    {
      "x": -10,
      "y": 9,
      "z": -4,
      "name": "Rock_Quartzite_Brick"
    },
    {
      "x": -10,
      "y": 10,
      "z": -4,
      "name": "Wood_Deadwood_Planks"
    },
    {
      "x": -10,
      "y": 11,
      "z": -4,
      "name": "Rock_Quartzite_Brick"
    },
    {
      "x": -10,
      "y": 12,
      "z": -4,
      "name": "Rock_Quartzite_Brick"
    },
    {
      "x": -10,
      "y": 13,
      "z": -4,
      "name": "Rock_Quartzite_Brick"
    },
    {
      "x": -10,
      "y": 14,
      "z": -4,
      "name": "Rock_Quartzite"
    },
    {
      "x": -10,
      "y": 15,
      "z": -4,
      "name": "Rock_Quartzite"
    },
    {
      "x": -10,
      "y": 16,
      "z": -4,
      "name": "Rock_Quartzite"
    },
    {
      "x": -10,
      "y": 17,
      "z": -4,
      "name": "Rock_Quartzite"
    },
    {
      "x": -10,
      "y": 0,
      "z": -3,
      "name": "Rock_Stone"
    },
    {
      "x": -10,
      "y": 1,
      "z": -3,
      "name": "Rock_Stone"
    },
    {
      "x": -10,
      "y": 2,
      "z": -3,
      "name": "Rock_Stone_Cobble"
    },
    {
      "x": -10,
      "y": 3,
      "z": -3,
      "name": "Rock_Stone_Cobble"
    },
    {
      "x": -10,
      "y": 4,
      "z": -3,
      "name": "Rock_Stone_Cobble"
    },
    {
      "x": -10,
      "y": 5,
      "z": -3,
      "name": "Rock_Quartzite_Brick"
    },
    {
      "x": -10,
      "y": 6,
      "z": -3,
      "name": "Rock_Quartzite_Brick"
    },
    {
      "x": -10,
      "y": 7,
      "z": -3,
      "name": "Rock_Quartzite_Brick"
    },
    {
      "x": -10,
      "y": 8,
      "z": -3,
      "name": "Rock_Quartzite_Brick"
    },
    {
      "x": -10,
      "y": 9,
      "z": -3,
      "name": "Rock_Quartzite_Brick"
    },
    {
      "x": -10,
      "y": 10,
      "z": -3,
      "name": "Wood_Deadwood_Planks"
    },
    {
      "x": -10,
      "y": 11,
      "z": -3,
      "name": "Rock_Quartzite_Brick"
    },
    {
      "x": -10,
      "y": 12,
      "z": -3,
      "name": "Rock_Quartzite_Brick"
    },
    {
      "x": -10,
      "y": 13,
      "z": -3,
      "name": "Rock_Quartzite_Brick"
    },
    {
      "x": -10,
      "y": 14,
      "z": -3,
      "name": "Rock_Quartzite_Brick"
    },
    {
      "x": -10,
      "y": 15,
      "z": -3,
      "name": "Rock_Quartzite"
    },
    {
      "x": -10,
      "y": 16,
      "z": -3,
      "name": "Rock_Quartzite"
    },
    {
      "x": -10,
      "y": 17,
      "z": -3,
      "name": "Rock_Quartzite"
    },
    {
      "x": -10,
      "y": 0,
      "z": -2,
      "name": "Rock_Stone"
    },
    {
      "x": -10,
      "y": 1,
      "z": -2,
      "name": "Rock_Stone"
    },
    {
      "x": -10,
      "y": 2,
      "z": -2,
      "name": "Rock_Stone_Cobble"
    },
    {
      "x": -10,
      "y": 3,
      "z": -2,
      "name": "Rock_Stone_Cobble"
    },
    {
      "x": -10,
      "y": 4,
      "z": -2,
      "name": "Rock_Stone_Cobble"
    },
    {
      "x": -10,
      "y": 5,
      "z": -2,
      "name": "Rock_Quartzite_Brick"
    },
    {
      "x": -10,
      "y": 6,
      "z": -2,
      "name": "Rock_Quartzite_Brick"
    },
    {
      "x": -10,
      "y": 7,
      "z": -2,
      "name": "Rock_Quartzite_Brick"
    },
    {
      "x": -10,
      "y": 8,
      "z": -2,
      "name": "Rock_Quartzite_Brick"
    },
    {
      "x": -10,
      "y": 9,
      "z": -2,
      "name": "Rock_Quartzite_Brick"
    },
    {
      "x": -10,
      "y": 10,
      "z": -2,
      "name": "Wood_Deadwood_Planks"
    },
    {
      "x": -10,
      "y": 11,
      "z": -2,
      "name": "Rock_Quartzite_Brick"
    },
    {
      "x": -10,
      "y": 12,
      "z": -2,
      "name": "Rock_Quartzite_Brick"
    },
    {
      "x": -10,
      "y": 13,
      "z": -2,
      "name": "Rock_Quartzite_Brick"
    },
    {
      "x": -10,
      "y": 14,
      "z": -2,
      "name": "Rock_Quartzite_Brick"
    },
    {
      "x": -10,
      "y": 15,
      "z": -2,
      "name": "Rock_Quartzite"
    },
    {
      "x": -10,
      "y": 16,
      "z": -2,
      "name": "Rock_Quartzite"
    },
    {
      "x": -10,
      "y": 17,
      "z": -2,
      "name": "Rock_Quartzite"
    },
    {
      "x": -10,
      "y": 0,
      "z": -1,
      "name": "Rock_Stone"
    },
    {
      "x": -10,
      "y": 1,
      "z": -1,
      "name": "Rock_Stone"
    },
    {
      "x": -10,
      "y": 2,
      "z": -1,
      "name": "Rock_Stone_Cobble"
    },
    {
      "x": -10,
      "y": 3,
      "z": -1,
      "name": "Rock_Stone_Cobble"
    },
    {
      "x": -10,
      "y": 4,
      "z": -1,
      "name": "Rock_Stone_Cobble"
    },
    {
      "x": -10,
      "y": 5,
      "z": -1,
      "name": "Rock_Quartzite_Brick"
    },
    {
      "x": -10,
      "y": 6,
      "z": -1,
      "name": "Rock_Quartzite_Brick"
    },
    {
      "x": -10,
      "y": 7,
      "z": -1,
      "name": "Rock_Quartzite_Brick"
    },
    {
      "x": -10,
      "y": 8,
      "z": -1,
      "name": "Rock_Quartzite_Brick"
    },
    {
      "x": -10,
      "y": 9,
      "z": -1,
      "name": "Rock_Quartzite_Brick"
    },
    {
      "x": -10,
      "y": 10,
      "z": -1,
      "name": "Wood_Deadwood_Planks"
    },
    {
      "x": -10,
      "y": 11,
      "z": -1,
      "name": "Rock_Quartzite_Brick"
    },
    {
      "x": -10,
      "y": 12,
      "z": -1,
      "name": "Rock_Quartzite_Brick"
    },
    {
      "x": -10,
      "y": 13,
      "z": -1,
      "name": "Rock_Quartzite_Brick"
    },
    {
      "x": -10,
      "y": 14,
      "z": -1,
      "name": "Rock_Quartzite_Brick"
    },
    {
      "x": -10,
      "y": 15,
      "z": -1,
      "name": "Rock_Quartzite"
    },
    {
      "x": -10,
      "y": 16,
      "z": -1,
      "name": "Rock_Quartzite"
    },
    {
      "x": -10,
      "y": 17,
      "z": -1,
      "name": "Rock_Quartzite"
    },
    {
      "x": -10,
      "y": 0,
      "z": 0,
      "name": "Rock_Stone"
    },
    {
      "x": -10,
      "y": 1,
      "z": 0,
      "name": "Rock_Stone"
    },
    {
      "x": -10,
      "y": 2,
      "z": 0,
      "name": "Rock_Stone_Cobble"
    },
    {
      "x": -10,
      "y": 3,
      "z": 0,
      "name": "Rock_Stone_Cobble"
    },
    {
      "x": -10,
      "y": 4,
      "z": 0,
      "name": "Rock_Stone_Cobble"
    },
    {
      "x": -10,
      "y": 5,
      "z": 0,
      "name": "Rock_Quartzite_Brick"
    },
    {
      "x": -10,
      "y": 6,
      "z": 0,
      "name": "Rock_Quartzite_Brick"
    },
    {
      "x": -10,
      "y": 7,
      "z": 0,
      "name": "Rock_Quartzite_Brick"
    },
    {
      "x": -10,
      "y": 8,
      "z": 0,
      "name": "Rock_Quartzite_Brick"
    },
    {
      "x": -10,
      "y": 9,
      "z": 0,
      "name": "Rock_Quartzite_Brick"
    },
    {
      "x": -10,
      "y": 10,
      "z": 0,
      "name": "Wood_Deadwood_Planks"
    },
    {
      "x": -10,
      "y": 11,
      "z": 0,
      "name": "Rock_Quartzite_Brick_Half",
      "rotation": 4
    },
    {
      "x": -10,
      "y": 12,
      "z": 0,
      "name": "Empty"
    },
    {
      "x": -10,
      "y": 13,
      "z": 0,
      "name": "Empty"
    },
    {
      "x": -10,
      "y": 14,
      "z": 0,
      "name": "Rock_Quartzite_Brick"
    },
    {
      "x": -10,
      "y": 15,
      "z": 0,
      "name": "Rock_Quartzite"
    },
    {
      "x": -10,
      "y": 16,
      "z": 0,
      "name": "Rock_Quartzite"
    },
    {
      "x": -10,
      "y": 17,
      "z": 0,
      "name": "Rock_Quartzite"
    },
    {
      "x": -10,
      "y": 0,
      "z": 1,
      "name": "Rock_Stone"
    },
    {
      "x": -10,
      "y": 1,
      "z": 1,
      "name": "Rock_Stone"
    },
    {
      "x": -10,
      "y": 2,
      "z": 1,
      "name": "Rock_Stone_Cobble"
    },
    {
      "x": -10,
      "y": 3,
      "z": 1,
      "name": "Rock_Stone_Cobble"
    },
    {
      "x": -10,
      "y": 4,
      "z": 1,
      "name": "Rock_Stone_Cobble"
    },
    {
      "x": -10,
      "y": 5,
      "z": 1,
      "name": "Rock_Quartzite_Brick"
    },
    {
      "x": -10,
      "y": 6,
      "z": 1,
      "name": "Rock_Quartzite_Brick"
    },
    {
      "x": -10,
      "y": 7,
      "z": 1,
      "name": "Rock_Quartzite_Brick"
    },
    {
      "x": -10,
      "y": 8,
      "z": 1,
      "name": "Rock_Quartzite_Brick"
    },
    {
      "x": -10,
      "y": 9,
      "z": 1,
      "name": "Rock_Quartzite_Brick"
    },
    {
      "x": -10,
      "y": 10,
      "z": 1,
      "name": "Wood_Deadwood_Planks"
    },
    {
      "x": -10,
      "y": 11,
      "z": 1,
      "name": "Block_Spawner_Block",
      "components": {
        "Components": {
          "BlockSpawner": {
            "BlockSpawnerId": "Zone1_Encounters_Tier3"
          }
        }
      },
      "rotation": 1
    },
    {
      "x": -10,
      "y": 12,
      "z": 1,
      "name": "Empty"
    },
    {
      "x": -10,
      "y": 13,
      "z": 1,
      "name": "Empty"
    },
    {
      "x": -10,
      "y": 14,
      "z": 1,
      "name": "Rock_Quartzite_Brick_Half",
      "rotation": 8
    },
    {
      "x": -10,
      "y": 15,
      "z": 1,
      "name": "Rock_Quartzite"
    },
    {
      "x": -10,
      "y": 16,
      "z": 1,
      "name": "Rock_Quartzite"
    },
    {
      "x": -10,
      "y": 17,
      "z": 1,
      "name": "Rock_Quartzite"
    },
    {
      "x": -10,
      "y": 0,
      "z": 2,
      "name": "Rock_Stone"
    },
    {
      "x": -10,
      "y": 1,
      "z": 2,
      "name": "Rock_Stone"
    },
    {
      "x": -10,
      "y": 2,
      "z": 2,
      "name": "Rock_Stone_Cobble"
    },
    {
      "x": -10,
      "y": 3,
      "z": 2,
      "name": "Rock_Stone_Cobble"
    },
    {
      "x": -10,
      "y": 4,
      "z": 2,
      "name": "Rock_Stone_Cobble"
    },
    {
      "x": -10,
      "y": 5,
      "z": 2,
      "name": "Rock_Quartzite_Brick"
    },
    {
      "x": -10,
      "y": 6,
      "z": 2,
      "name": "Rock_Quartzite_Brick"
    },
    {
      "x": -10,
      "y": 7,
      "z": 2,
      "name": "Rock_Quartzite_Brick"
    },
    {
      "x": -10,
      "y": 8,
      "z": 2,
      "name": "Rock_Quartzite_Brick"
    },
    {
      "x": -10,
      "y": 9,
      "z": 2,
      "name": "Rock_Quartzite_Brick"
    },
    {
      "x": -10,
      "y": 10,
      "z": 2,
      "name": "Wood_Deadwood_Planks"
    },
    {
      "x": -10,
      "y": 11,
      "z": 2,
      "name": "Furniture_Ancient_Bookshelf",
      "rotation": 1
    },
    {
      "x": -10,
      "y": 12,
      "z": 2,
      "name": "Empty"
    },
    {
      "x": -10,
      "y": 13,
      "z": 2,
      "name": "Empty"
    },
    {
      "x": -10,
      "y": 14,
      "z": 2,
      "name": "Rock_Quartzite_Brick_Half",
      "rotation": 8
    },
    {
      "x": -10,
      "y": 15,
      "z": 2,
      "name": "Rock_Quartzite"
    },
    {
      "x": -10,
      "y": 16,
      "z": 2,
      "name": "Rock_Quartzite"
    },
    {
      "x": -10,
      "y": 17,
      "z": 2,
      "name": "Rock_Quartzite"
    },
    {
      "x": -10,
      "y": 0,
      "z": 3,
      "name": "Rock_Stone"
    },
    {
      "x": -10,
      "y": 1,
      "z": 3,
      "name": "Rock_Stone"
    },
    {
      "x": -10,
      "y": 2,
      "z": 3,
      "name": "Rock_Stone_Cobble"
    },
    {
      "x": -10,
      "y": 3,
      "z": 3,
      "name": "Rock_Stone_Cobble"
    },
    {
      "x": -10,
      "y": 4,
      "z": 3,
      "name": "Rock_Stone_Brick"
    },
    {
      "x": -10,
      "y": 5,
      "z": 3,
      "name": "Rock_Quartzite_Brick_Wall",
      "rotation": 1
    },
    {
      "x": -10,
      "y": 6,
      "z": 3,
      "name": "Furniture_Ancient_Shelf",
      "rotation": 1
    },
    {
      "x": -10,
      "y": 7,
      "z": 3,
      "name": "Empty"
    },
    {
      "x": -10,
      "y": 8,
      "z": 3,
      "name": "Rock_Quartzite_Brick_Half",
      "rotation": 4
    },
    {
      "x": -10,
      "y": 9,
      "z": 3,
      "name": "Rock_Quartzite_Brick"
    },
    {
      "x": -10,
      "y": 10,
      "z": 3,
      "name": "Wood_Deadwood_Planks"
    },
    {
      "x": -10,
      "y": 11,
      "z": 3,
      "name": "Empty"
    },
    {
      "x": -10,
      "y": 12,
      "z": 3,
      "name": "Empty"
    },
    {
      "x": -10,
      "y": 13,
      "z": 3,
      "name": "Deco_Scroll",
      "rotation": 1
    },
    {
      "x": -10,
      "y": 14,
      "z": 3,
      "name": "Rock_Quartzite_Brick_Half",
      "rotation": 8
    },
    {
      "x": -10,
      "y": 15,
      "z": 3,
      "name": "Rock_Quartzite"
    },
    {
      "x": -10,
      "y": 16,
      "z": 3,
      "name": "Rock_Quartzite"
    },
    {
      "x": -10,
      "y": 17,
      "z": 3,
      "name": "Rock_Quartzite"
    },
    {
      "x": -10,
      "y": 0,
      "z": 4,
      "name": "Rock_Stone"
    },
    {
      "x": -10,
      "y": 1,
      "z": 4,
      "name": "Rock_Stone"
    },
    {
      "x": -10,
      "y": 2,
      "z": 4,
      "name": "Rock_Stone_Cobble"
    },
    {
      "x": -10,
      "y": 3,
      "z": 4,
      "name": "Rock_Stone_Cobble"
    },
    {
      "x": -10,
      "y": 4,
      "z": 4,
      "name": "Rock_Stone_Brick"
    },
    {
      "x": -10,
      "y": 5,
      "z": 4,
      "name": "Rock_Quartzite_Brick_Wall",
      "rotation": 1
    },
    {
      "x": -10,
      "y": 6,
      "z": 4,
      "name": "Empty"
    },
    {
      "x": -10,
      "y": 7,
      "z": 4,
      "name": "Empty"
    },
    {
      "x": -10,
      "y": 8,
      "z": 4,
      "name": "Empty"
    },
    {
      "x": -10,
      "y": 9,
      "z": 4,
      "name": "Rock_Quartzite_Brick_Half",
      "rotation": 8
    },
    {
      "x": -10,
      "y": 10,
      "z": 4,
      "name": "Wood_Deadwood_Planks"
    },
    {
      "x": -10,
      "y": 11,
      "z": 4,
      "name": "Rock_Quartzite_Brick_Pillar_Base"
    },
    {
      "x": -10,
      "y": 12,
      "z": 4,
      "name": "Rock_Quartzite_Brick_Pillar_Middle"
    },
    {
      "x": -10,
      "y": 13,
      "z": 4,
      "name": "Rock_Quartzite_Brick_Pillar_Base",
      "rotation": 8
    },
    {
      "x": -10,
      "y": 14,
      "z": 4,
      "name": "Rock_Quartzite_Brick"
    },
    {
      "x": -10,
      "y": 15,
      "z": 4,
      "name": "Rock_Quartzite"
    },
    {
      "x": -10,
      "y": 16,
      "z": 4,
      "name": "Rock_Quartzite"
    },
    {
      "x": -10,
      "y": 17,
      "z": 4,
      "name": "Rock_Quartzite"
    },
    {
      "x": -10,
      "y": 0,
      "z": 5,
      "name": "Rock_Stone"
    },
    {
      "x": -10,
      "y": 1,
      "z": 5,
      "name": "Rock_Stone"
    },
    {
      "x": -10,
      "y": 2,
      "z": 5,
      "name": "Rock_Stone_Cobble"
    },
    {
      "x": -10,
      "y": 3,
      "z": 5,
      "name": "Rock_Stone_Cobble"
    },
    {
      "x": -10,
      "y": 4,
      "z": 5,
      "name": "Rock_Stone_Brick"
    },
    {
      "x": -10,
      "y": 5,
      "z": 5,
      "name": "Rock_Quartzite_Brick_Wall",
      "rotation": 1
    },
    {
      "x": -10,
      "y": 6,
      "z": 5,
      "name": "Furniture_Tavern_Shelf",
      "rotation": 1
    },
    {
      "x": -10,
      "y": 7,
      "z": 5,
      "name": "Empty"
    },
    {
      "x": -10,
      "y": 8,
      "z": 5,
      "name": "Rock_Quartzite_Brick_Half",
      "rotation": 6
    },
    {
      "x": -10,
      "y": 9,
      "z": 5,
      "name": "Rock_Quartzite_Brick"
    },
    {
      "x": -10,
      "y": 10,
      "z": 5,
      "name": "Wood_Deadwood_Planks"
    },
    {
      "x": -10,
      "y": 11,
      "z": 5,
      "name": "Plant_Moss_Block_Blue"
    },
    {
      "x": -10,
      "y": 12,
      "z": 5,
      "name": "Empty"
    },
    {
      "x": -10,
      "y": 13,
      "z": 5,
      "name": "Empty"
    },
    {
      "x": -10,
      "y": 14,
      "z": 5,
      "name": "Rock_Quartzite_Brick"
    },
    {
      "x": -10,
      "y": 15,
      "z": 5,
      "name": "Rock_Quartzite"
    },
    {
      "x": -10,
      "y": 16,
      "z": 5,
      "name": "Rock_Quartzite"
    },
    {
      "x": -10,
      "y": 17,
      "z": 5,
      "name": "Rock_Quartzite"
    },
    {
      "x": -10,
      "y": 0,
      "z": 6,
      "name": "Rock_Stone"
    },
    {
      "x": -10,
      "y": 1,
      "z": 6,
      "name": "Rock_Stone"
    },
    {
      "x": -10,
      "y": 2,
      "z": 6,
      "name": "Rock_Stone_Cobble"
    },
    {
      "x": -10,
      "y": 3,
      "z": 6,
      "name": "Rock_Stone_Cobble"
    },
    {
      "x": -10,
      "y": 4,
      "z": 6,
      "name": "Rock_Stone_Cobble"
    },
    {
      "x": -10,
      "y": 5,
      "z": 6,
      "name": "Rock_Quartzite_Brick"
    },
    {
      "x": -10,
      "y": 6,
      "z": 6,
      "name": "Rock_Quartzite_Brick"
    },
    {
      "x": -10,
      "y": 7,
      "z": 6,
      "name": "Rock_Quartzite_Brick"
    },
    {
      "x": -10,
      "y": 8,
      "z": 6,
      "name": "Rock_Quartzite_Brick"
    },
    {
      "x": -10,
      "y": 9,
      "z": 6,
      "name": "Rock_Quartzite_Brick"
    },
    {
      "x": -10,
      "y": 10,
      "z": 6,
      "name": "Wood_Deadwood_Planks"
    },
    {
      "x": -10,
      "y": 11,
      "z": 6,
      "name": "Plant_Moss_Block_Blue"
    },
    {
      "x": -10,
      "y": 12,
      "z": 6,
      "name": "Plant_Moss_Rug_Blue"
    },
    {
      "x": -10,
      "y": 13,
      "z": 6,
      "name": "Rock_Quartzite_Brick_Half",
      "rotation": 6
    },
    {
      "x": -10,
      "y": 14,
      "z": 6,
      "name": "Rock_Quartzite_Brick"
    },
    {
      "x": -10,
      "y": 15,
      "z": 6,
      "name": "Rock_Quartzite"
    },
    {
      "x": -10,
      "y": 16,
      "z": 6,
      "name": "Rock_Quartzite"
    },
    {
      "x": -10,
      "y": 17,
      "z": 6,
      "name": "Rock_Quartzite"
    },
    {
      "x": -10,
      "y": 0,
      "z": 7,
      "name": "Rock_Stone"
    },
    {
      "x": -10,
      "y": 1,
      "z": 7,
      "name": "Rock_Stone"
    },
    {
      "x": -10,
      "y": 2,
      "z": 7,
      "name": "Rock_Stone_Cobble"
    },
    {
      "x": -10,
      "y": 3,
      "z": 7,
      "name": "Rock_Stone_Cobble"
    },
    {
      "x": -10,
      "y": 4,
      "z": 7,
      "name": "Rock_Stone_Cobble"
    },
    {
      "x": -10,
      "y": 5,
      "z": 7,
      "name": "Rock_Quartzite_Brick"
    },
    {
      "x": -10,
      "y": 6,
      "z": 7,
      "name": "Rock_Quartzite_Brick"
    },
    {
      "x": -10,
      "y": 7,
      "z": 7,
      "name": "Rock_Quartzite_Brick"
    },
    {
      "x": -10,
      "y": 8,
      "z": 7,
      "name": "Rock_Quartzite_Brick"
    },
    {
      "x": -10,
      "y": 9,
      "z": 7,
      "name": "Rock_Quartzite_Brick"
    },
    {
      "x": -10,
      "y": 10,
      "z": 7,
      "name": "Wood_Deadwood_Planks"
    },
    {
      "x": -10,
      "y": 11,
      "z": 7,
      "name": "Rock_Quartzite_Brick"
    },
    {
      "x": -10,
      "y": 12,
      "z": 7,
      "name": "Rock_Quartzite_Brick"
    },
    {
      "x": -10,
      "y": 13,
      "z": 7,
      "name": "Rock_Quartzite_Brick"
    },
    {
      "x": -10,
      "y": 14,
      "z": 7,
      "name": "Rock_Quartzite_Brick"
    },
    {
      "x": -10,
      "y": 15,
      "z": 7,
      "name": "Rock_Quartzite"
    },
    {
      "x": -10,
      "y": 16,
      "z": 7,
      "name": "Rock_Quartzite"
    },
    {
      "x": -10,
      "y": 17,
      "z": 7,
      "name": "Rock_Quartzite"
    },
    {
      "x": -10,
      "y": 0,
      "z": 8,
      "name": "Rock_Stone"
    },
    {
      "x": -10,
      "y": 1,
      "z": 8,
      "name": "Rock_Stone"
    },
    {
      "x": -10,
      "y": 2,
      "z": 8,
      "name": "Rock_Stone_Cobble"
    },
    {
      "x": -10,
      "y": 3,
      "z": 8,
      "name": "Rock_Quartzite_Brick"
    },
    {
      "x": -10,
      "y": 4,
      "z": 8,
      "name": "Rock_Quartzite_Brick"
    },
    {
      "x": -10,
      "y": 5,
      "z": 8,
      "name": "Rock_Quartzite_Brick"
    },
    {
      "x": -10,
      "y": 6,
      "z": 8,
      "name": "Rock_Quartzite"
    },
    {
      "x": -10,
      "y": 7,
      "z": 8,
      "name": "Rock_Quartzite"
    },
    {
      "x": -10,
      "y": 8,
      "z": 8,
      "name": "Rock_Quartzite"
    },
    {
      "x": -10,
      "y": 9,
      "z": 8,
      "name": "Rock_Quartzite"
    },
    {
      "x": -10,
      "y": 10,
      "z": 8,
      "name": "Rock_Quartzite"
    },
    {
      "x": -10,
      "y": 11,
      "z": 8,
      "name": "Rock_Quartzite"
    },
    {
      "x": -10,
      "y": 12,
      "z": 8,
      "name": "Rock_Quartzite"
    },
    {
      "x": -10,
      "y": 13,
      "z": 8,
      "name": "Rock_Quartzite"
    },
    {
      "x": -10,
      "y": 14,
      "z": 8,
      "name": "Rock_Quartzite"
    },
    {
      "x": -10,
      "y": 15,
      "z": 8,
      "name": "Rock_Quartzite"
    },
    {
      "x": -10,
      "y": 16,
      "z": 8,
      "name": "Rock_Quartzite"
    },
    {
      "x": -10,
      "y": 17,
      "z": 8,
      "name": "Rock_Quartzite"
    },
    {
      "x": -9,
      "y": 0,
      "z": -8,
      "name": "Rock_Stone"
    },
    {
      "x": -9,
      "y": 1,
      "z": -8,
      "name": "Rock_Stone"
    },
    {
      "x": -9,
      "y": 2,
      "z": -8,
      "name": "Rock_Stone_Cobble"
    },
    {
      "x": -9,
      "y": 3,
      "z": -8,
      "name": "Rock_Quartzite_Brick"
    },
    {
      "x": -9,
      "y": 4,
      "z": -8,
      "name": "Rock_Quartzite_Brick"
    },
    {
      "x": -9,
      "y": 5,
      "z": -8,
      "name": "Rock_Quartzite_Brick"
    },
    {
      "x": -9,
      "y": 6,
      "z": -8,
      "name": "Rock_Quartzite_Brick"
    },
    {
      "x": -9,
      "y": 7,
      "z": -8,
      "name": "Rock_Quartzite_Brick"
    },
    {
      "x": -9,
      "y": 8,
      "z": -8,
      "name": "Rock_Quartzite"
    },
    {
      "x": -9,
      "y": 9,
      "z": -8,
      "name": "Rock_Quartzite"
    },
    {
      "x": -9,
      "y": 10,
      "z": -8,
      "name": "Rock_Quartzite"
    },
    {
      "x": -9,
      "y": 11,
      "z": -8,
      "name": "Rock_Quartzite"
    },
    {
      "x": -9,
      "y": 12,
      "z": -8,
      "name": "Rock_Quartzite"
    },
    {
      "x": -9,
      "y": 13,
      "z": -8,
      "name": "Rock_Quartzite_Brick"
    },
    {
      "x": -9,
      "y": 14,
      "z": -8,
      "name": "Rock_Quartzite_Brick"
    },
    {
      "x": -9,
      "y": 15,
      "z": -8,
      "name": "Rock_Quartzite"
    },
    {
      "x": -9,
      "y": 16,
      "z": -8,
      "name": "Rock_Quartzite"
    },
    {
      "x": -9,
      "y": 17,
      "z": -8,
      "name": "Rock_Quartzite"
    },
    {
      "x": -9,
      "y": 0,
      "z": -7,
      "name": "Rock_Stone"
    },
    {
      "x": -9,
      "y": 1,
      "z": -7,
      "name": "Rock_Stone"
    },
    {
      "x": -9,
      "y": 2,
      "z": -7,
      "name": "Rock_Stone_Cobble"
    },
    {
      "x": -9,
      "y": 3,
      "z": -7,
      "name": "Rock_Stone_Cobble"
    },
    {
      "x": -9,
      "y": 4,
      "z": -7,
      "name": "Wood_Deadwood_Planks"
    },
    {
      "x": -9,
      "y": 5,
      "z": -7,
      "name": "Rock_Quartzite_Brick"
    },
    {
      "x": -9,
      "y": 6,
      "z": -7,
      "name": "Rock_Quartzite_Brick"
    },
    {
      "x": -9,
      "y": 7,
      "z": -7,
      "name": "Rock_Quartzite_Brick"
    },
    {
      "x": -9,
      "y": 8,
      "z": -7,
      "name": "Rock_Quartzite_Brick"
    },
    {
      "x": -9,
      "y": 9,
      "z": -7,
      "name": "Rock_Quartzite_Brick"
    },
    {
      "x": -9,
      "y": 10,
      "z": -7,
      "name": "Wood_Deadwood_Planks"
    },
    {
      "x": -9,
      "y": 11,
      "z": -7,
      "name": "Rubble_Quartzite"
    },
    {
      "x": -9,
      "y": 12,
      "z": -7,
      "name": "Empty"
    },
    {
      "x": -9,
      "y": 13,
      "z": -7,
      "name": "Rock_Quartzite_Brick_Half",
      "rotation": 4
    },
    {
      "x": -9,
      "y": 14,
      "z": -7,
      "name": "Rock_Quartzite_Brick"
    },
    {
      "x": -9,
      "y": 15,
      "z": -7,
      "name": "Rock_Quartzite"
    },
    {
      "x": -9,
      "y": 16,
      "z": -7,
      "name": "Rock_Quartzite"
    },
    {
      "x": -9,
      "y": 17,
      "z": -7,
      "name": "Rock_Quartzite"
    },
    {
      "x": -9,
      "y": 0,
      "z": -6,
      "name": "Rock_Stone"
    },
    {
      "x": -9,
      "y": 1,
      "z": -6,
      "name": "Rock_Stone"
    },
    {
      "x": -9,
      "y": 2,
      "z": -6,
      "name": "Rock_Stone_Cobble"
    },
    {
      "x": -9,
      "y": 3,
      "z": -6,
      "name": "Rock_Stone_Cobble"
    },
    {
      "x": -9,
      "y": 4,
      "z": -6,
      "name": "Wood_Deadwood_Planks"
    },
    {
      "x": -9,
      "y": 5,
      "z": -6,
      "name": "Rock_Quartzite_Brick"
    },
    {
      "x": -9,
      "y": 6,
      "z": -6,
      "name": "Rock_Quartzite_Brick"
    },
    {
      "x": -9,
      "y": 7,
      "z": -6,
      "name": "Rock_Quartzite_Brick"
    },
    {
      "x": -9,
      "y": 8,
      "z": -6,
      "name": "Rock_Quartzite_Brick"
    },
    {
      "x": -9,
      "y": 9,
      "z": -6,
      "name": "Rock_Quartzite_Brick"
    },
    {
      "x": -9,
      "y": 10,
      "z": -6,
      "name": "Wood_Deadwood_Planks"
    },
    {
      "x": -9,
      "y": 11,
      "z": -6,
      "name": "Empty"
    },
    {
      "x": -9,
      "y": 12,
      "z": -6,
      "name": "Furniture_Tavern_Shelf",
      "rotation": 1
    },
    {
      "x": -9,
      "y": 13,
      "z": -6,
      "name": "Empty"
    },
    {
      "x": -9,
      "y": 14,
      "z": -6,
      "name": "Rock_Quartzite_Brick_Half",
      "rotation": 8
    },
    {
      "x": -9,
      "y": 15,
      "z": -6,
      "name": "Rock_Quartzite"
    },
    {
      "x": -9,
      "y": 16,
      "z": -6,
      "name": "Rock_Quartzite"
    },
    {
      "x": -9,
      "y": 17,
      "z": -6,
      "name": "Rock_Quartzite"
    },
    {
      "x": -9,
      "y": 0,
      "z": -5,
      "name": "Rock_Stone"
    },
    {
      "x": -9,
      "y": 1,
      "z": -5,
      "name": "Rock_Stone"
    },
    {
      "x": -9,
      "y": 2,
      "z": -5,
      "name": "Rock_Stone_Cobble"
    },
    {
      "x": -9,
      "y": 3,
      "z": -5,
      "name": "Rock_Stone_Cobble"
    },
    {
      "x": -9,
      "y": 4,
      "z": -5,
      "name": "Wood_Deadwood_Planks"
    },
    {
      "x": -9,
      "y": 5,
      "z": -5,
      "name": "Furniture_Village_Bookcase",
      "rotation": 1
    },
    {
      "x": -9,
      "y": 6,
      "z": -5,
      "name": "Furniture_Village_Bookcase",
      "rotation": 1
    },
    {
      "x": -9,
      "y": 7,
      "z": -5,
      "name": "Furniture_Village_Bookcase",
      "rotation": 1
    },
    {
      "x": -9,
      "y": 8,
      "z": -5,
      "name": "Empty"
    },
    {
      "x": -9,
      "y": 9,
      "z": -5,
      "name": "Empty"
    },
    {
      "x": -9,
      "y": 10,
      "z": -5,
      "name": "*Furniture_Ancient_Trapdoor_State_Definitions_CloseDoorOut"
    },
    {
      "x": -9,
      "y": 11,
      "z": -5,
      "name": "Empty"
    },
    {
      "x": -9,
      "y": 12,
      "z": -5,
      "name": "Empty"
    },
    {
      "x": -9,
      "y": 13,
      "z": -5,
      "name": "Empty"
    },
    {
      "x": -9,
      "y": 14,
      "z": -5,
      "name": "Rock_Quartzite_Brick_Half",
      "rotation": 8
    },
    {
      "x": -9,
      "y": 15,
      "z": -5,
      "name": "Rock_Quartzite"
    },
    {
      "x": -9,
      "y": 16,
      "z": -5,
      "name": "Rock_Quartzite"
    },
    {
      "x": -9,
      "y": 17,
      "z": -5,
      "name": "Rock_Quartzite"
    },
    {
      "x": -9,
      "y": 0,
      "z": -4,
      "name": "Rock_Stone"
    },
    {
      "x": -9,
      "y": 1,
      "z": -4,
      "name": "Rock_Stone"
    },
    {
      "x": -9,
      "y": 2,
      "z": -4,
      "name": "Rock_Stone_Cobble"
    },
    {
      "x": -9,
      "y": 3,
      "z": -4,
      "name": "Rock_Stone_Cobble"
    },
    {
      "x": -9,
      "y": 4,
      "z": -4,
      "name": "Wood_Deadwood_Planks"
    },
    {
      "x": -9,
      "y": 5,
      "z": -4,
      "name": "Furniture_Village_Bookcase",
      "rotation": 1
    },
    {
      "x": -9,
      "y": 6,
      "z": -4,
      "name": "Furniture_Village_Bookcase",
      "rotation": 1
    },
    {
      "x": -9,
      "y": 7,
      "z": -4,
      "name": "Furniture_Village_Bookcase",
      "rotation": 1
    },
    {
      "x": -9,
      "y": 8,
      "z": -4,
      "name": "Empty"
    },
    {
      "x": -9,
      "y": 9,
      "z": -4,
      "name": "Empty"
    },
    {
      "x": -9,
      "y": 10,
      "z": -4,
      "name": "Wood_Deadwood_Planks"
    },
    {
      "x": -9,
      "y": 11,
      "z": -4,
      "name": "Empty"
    },
    {
      "x": -9,
      "y": 12,
      "z": -4,
      "name": "Empty"
    },
    {
      "x": -9,
      "y": 13,
      "z": -4,
      "name": "Empty"
    },
    {
      "x": -9,
      "y": 14,
      "z": -4,
      "name": "Rock_Quartzite_Brick_Half",
      "rotation": 8
    },
    {
      "x": -9,
      "y": 15,
      "z": -4,
      "name": "Rock_Quartzite"
    },
    {
      "x": -9,
      "y": 16,
      "z": -4,
      "name": "Rock_Quartzite"
    },
    {
      "x": -9,
      "y": 17,
      "z": -4,
      "name": "Rock_Quartzite"
    },
    {
      "x": -9,
      "y": 0,
      "z": -3,
      "name": "Rock_Stone"
    },
    {
      "x": -9,
      "y": 1,
      "z": -3,
      "name": "Rock_Stone"
    },
    {
      "x": -9,
      "y": 2,
      "z": -3,
      "name": "Rock_Stone_Cobble"
    },
    {
      "x": -9,
      "y": 3,
      "z": -3,
      "name": "Rock_Stone_Cobble"
    },
    {
      "x": -9,
      "y": 4,
      "z": -3,
      "name": "Wood_Deadwood_Planks"
    },
    {
      "x": -9,
      "y": 5,
      "z": -3,
      "name": "Furniture_Village_Bookcase",
      "rotation": 1
    },
    {
      "x": -9,
      "y": 6,
      "z": -3,
      "name": "Furniture_Village_Bookcase",
      "rotation": 1
    },
    {
      "x": -9,
      "y": 7,
      "z": -3,
      "name": "Empty"
    },
    {
      "x": -9,
      "y": 8,
      "z": -3,
      "name": "Empty"
    },
    {
      "x": -9,
      "y": 9,
      "z": -3,
      "name": "Rock_Quartzite_Brick_Half",
      "rotation": 6
    },
    {
      "x": -9,
      "y": 10,
      "z": -3,
      "name": "Wood_Deadwood_Planks"
    },
    {
      "x": -9,
      "y": 11,
      "z": -3,
      "name": "Furniture_Ancient_Shelf",
      "rotation": 1
    },
    {
      "x": -9,
      "y": 12,
      "z": -3,
      "name": "Empty"
    },
    {
      "x": -9,
      "y": 13,
      "z": -3,
      "name": "Empty"
    },
    {
      "x": -9,
      "y": 14,
      "z": -3,
      "name": "Rock_Quartzite_Brick"
    },
    {
      "x": -9,
      "y": 15,
      "z": -3,
      "name": "Rock_Quartzite"
    },
    {
      "x": -9,
      "y": 16,
      "z": -3,
      "name": "Rock_Quartzite"
    },
    {
      "x": -9,
      "y": 17,
      "z": -3,
      "name": "Rock_Quartzite"
    },
    {
      "x": -9,
      "y": 0,
      "z": -2,
      "name": "Rock_Stone"
    },
    {
      "x": -9,
      "y": 1,
      "z": -2,
      "name": "Rock_Stone"
    },
    {
      "x": -9,
      "y": 2,
      "z": -2,
      "name": "Rock_Stone_Cobble"
    },
    {
      "x": -9,
      "y": 3,
      "z": -2,
      "name": "Rock_Stone_Cobble"
    },
    {
      "x": -9,
      "y": 4,
      "z": -2,
      "name": "Wood_Deadwood_Planks"
    },
    {
      "x": -9,
      "y": 5,
      "z": -2,
      "name": "Rock_Quartzite_Brick"
    },
    {
      "x": -9,
      "y": 6,
      "z": -2,
      "name": "Rock_Quartzite_Brick"
    },
    {
      "x": -9,
      "y": 7,
      "z": -2,
      "name": "Rock_Quartzite_Brick"
    },
    {
      "x": -9,
      "y": 8,
      "z": -2,
      "name": "Rock_Quartzite_Brick"
    },
    {
      "x": -9,
      "y": 9,
      "z": -2,
      "name": "Rock_Quartzite_Brick"
    },
    {
      "x": -9,
      "y": 10,
      "z": -2,
      "name": "Wood_Deadwood_Planks"
    },
    {
      "x": -9,
      "y": 11,
      "z": -2,
      "name": "Rock_Quartzite_Brick"
    },
    {
      "x": -9,
      "y": 12,
      "z": -2,
      "name": "Rock_Quartzite_Brick"
    },
    {
      "x": -9,
      "y": 13,
      "z": -2,
      "name": "Rock_Quartzite_Brick"
    },
    {
      "x": -9,
      "y": 14,
      "z": -2,
      "name": "Rock_Quartzite_Brick"
    },
    {
      "x": -9,
      "y": 15,
      "z": -2,
      "name": "Rock_Quartzite"
    },
    {
      "x": -9,
      "y": 16,
      "z": -2,
      "name": "Rock_Quartzite"
    },
    {
      "x": -9,
      "y": 17,
      "z": -2,
      "name": "Rock_Quartzite"
    },
    {
      "x": -9,
      "y": 0,
      "z": -1,
      "name": "Rock_Stone"
    },
    {
      "x": -9,
      "y": 1,
      "z": -1,
      "name": "Rock_Stone"
    },
    {
      "x": -9,
      "y": 2,
      "z": -1,
      "name": "Rock_Stone_Cobble"
    },
    {
      "x": -9,
      "y": 3,
      "z": -1,
      "name": "Rock_Stone_Cobble"
    },
    {
      "x": -9,
      "y": 4,
      "z": -1,
      "name": "Wood_Deadwood_Planks"
    },
    {
      "x": -9,
      "y": 5,
      "z": -1,
      "name": "Rock_Quartzite_Brick"
    },
    {
      "x": -9,
      "y": 6,
      "z": -1,
      "name": "Rock_Quartzite_Brick"
    },
    {
      "x": -9,
      "y": 7,
      "z": -1,
      "name": "Rock_Quartzite_Brick"
    },
    {
      "x": -9,
      "y": 8,
      "z": -1,
      "name": "Rock_Quartzite_Brick"
    },
    {
      "x": -9,
      "y": 9,
      "z": -1,
      "name": "Rock_Quartzite_Brick"
    },
    {
      "x": -9,
      "y": 10,
      "z": -1,
      "name": "Wood_Deadwood_Planks"
    },
    {
      "x": -9,
      "y": 11,
      "z": -1,
      "name": "Empty"
    },
    {
      "x": -9,
      "y": 12,
      "z": -1,
      "name": "Empty"
    },
    {
      "x": -9,
      "y": 13,
      "z": -1,
      "name": "Empty"
    },
    {
      "x": -9,
      "y": 14,
      "z": -1,
      "name": "Rock_Quartzite_Brick_Half",
      "rotation": 8
    },
    {
      "x": -9,
      "y": 15,
      "z": -1,
      "name": "Rock_Quartzite"
    },
    {
      "x": -9,
      "y": 16,
      "z": -1,
      "name": "Rock_Quartzite"
    },
    {
      "x": -9,
      "y": 17,
      "z": -1,
      "name": "Rock_Quartzite"
    },
    {
      "x": -9,
      "y": 0,
      "z": 0,
      "name": "Rock_Stone"
    },
    {
      "x": -9,
      "y": 1,
      "z": 0,
      "name": "Rock_Stone"
    },
    {
      "x": -9,
      "y": 2,
      "z": 0,
      "name": "Rock_Stone_Cobble"
    },
    {
      "x": -9,
      "y": 3,
      "z": 0,
      "name": "Rock_Stone_Cobble"
    },
    {
      "x": -9,
      "y": 4,
      "z": 0,
      "name": "Wood_Deadwood_Planks"
    },
    {
      "x": -9,
      "y": 5,
      "z": 0,
      "name": "Furniture_Village_Bookcase",
      "rotation": 1
    },
    {
      "x": -9,
      "y": 6,
      "z": 0,
      "name": "Furniture_Village_Bookcase",
      "rotation": 1
    },
    {
      "x": -9,
      "y": 7,
      "z": 0,
      "name": "Furniture_Village_Bookcase",
      "rotation": 1
    },
    {
      "x": -9,
      "y": 8,
      "z": 0,
      "name": "Empty"
    },
    {
      "x": -9,
      "y": 9,
      "z": 0,
      "name": "Rock_Quartzite_Brick_Half",
      "rotation": 8
    },
    {
      "x": -9,
      "y": 10,
      "z": 0,
      "name": "Wood_Deadwood_Planks"
    },
    {
      "x": -9,
      "y": 11,
      "z": 0,
      "name": "Empty"
    },
    {
      "x": -9,
      "y": 12,
      "z": 0,
      "name": "Empty"
    },
    {
      "x": -9,
      "y": 13,
      "z": 0,
      "name": "Empty"
    },
    {
      "x": -9,
      "y": 14,
      "z": 0,
      "name": "Empty"
    },
    {
      "x": -9,
      "y": 15,
      "z": 0,
      "name": "Rock_Quartzite"
    },
    {
      "x": -9,
      "y": 16,
      "z": 0,
      "name": "Rock_Quartzite"
    },
    {
      "x": -9,
      "y": 17,
      "z": 0,
      "name": "Rock_Quartzite"
    },
    {
      "x": -9,
      "y": 0,
      "z": 1,
      "name": "Rock_Stone"
    },
    {
      "x": -9,
      "y": 1,
      "z": 1,
      "name": "Rock_Stone"
    },
    {
      "x": -9,
      "y": 2,
      "z": 1,
      "name": "Rock_Stone_Cobble"
    },
    {
      "x": -9,
      "y": 3,
      "z": 1,
      "name": "Rock_Stone_Cobble"
    },
    {
      "x": -9,
      "y": 4,
      "z": 1,
      "name": "Wood_Deadwood_Planks"
    },
    {
      "x": -9,
      "y": 5,
      "z": 1,
      "name": "Furniture_Village_Bookcase",
      "rotation": 1
    },
    {
      "x": -9,
      "y": 6,
      "z": 1,
      "name": "Furniture_Village_Bookcase",
      "rotation": 1
    },
    {
      "x": -9,
      "y": 7,
      "z": 1,
      "name": "Furniture_Village_Bookcase",
      "rotation": 1
    },
    {
      "x": -9,
      "y": 8,
      "z": 1,
      "name": "Furniture_Village_Bookcase",
      "rotation": 1
    },
    {
      "x": -9,
      "y": 9,
      "z": 1,
      "name": "Empty"
    },
    {
      "x": -9,
      "y": 10,
      "z": 1,
      "name": "Wood_Deadwood_Planks"
    },
    {
      "x": -9,
      "y": 11,
      "z": 1,
      "name": "Empty"
    },
    {
      "x": -9,
      "y": 12,
      "z": 1,
      "name": "Empty"
    },
    {
      "x": -9,
      "y": 13,
      "z": 1,
      "name": "Empty"
    },
    {
      "x": -9,
      "y": 14,
      "z": 1,
      "name": "Empty"
    },
    {
      "x": -9,
      "y": 15,
      "z": 1,
      "name": "Rock_Quartzite"
    },
    {
      "x": -9,
      "y": 16,
      "z": 1,
      "name": "Rock_Quartzite"
    },
    {
      "x": -9,
      "y": 17,
      "z": 1,
      "name": "Rock_Quartzite"
    },
    {
      "x": -9,
      "y": 0,
      "z": 2,
      "name": "Rock_Stone"
    },
    {
      "x": -9,
      "y": 1,
      "z": 2,
      "name": "Rock_Stone"
    },
    {
      "x": -9,
      "y": 2,
      "z": 2,
      "name": "Rock_Stone_Cobble"
    },
    {
      "x": -9,
      "y": 3,
      "z": 2,
      "name": "Rock_Stone_Cobble"
    },
    {
      "x": -9,
      "y": 4,
      "z": 2,
      "name": "Wood_Deadwood_Planks"
    },
    {
      "x": -9,
      "y": 5,
      "z": 2,
      "name": "Furniture_Ancient_Table"
    },
    {
      "x": -9,
      "y": 6,
      "z": 2,
      "name": "Deco_Scroll",
      "rotation": 1
    },
    {
      "x": -9,
      "y": 7,
      "z": 2,
      "name": "Empty"
    },
    {
      "x": -9,
      "y": 8,
      "z": 2,
      "name": "Empty"
    },
    {
      "x": -9,
      "y": 9,
      "z": 2,
      "name": "Empty"
    },
    {
      "x": -9,
      "y": 10,
      "z": 2,
      "name": "Wood_Deadwood_Planks"
    },
    {
      "x": -9,
      "y": 11,
      "z": 2,
      "name": "Empty"
    },
    {
      "x": -9,
      "y": 12,
      "z": 2,
      "name": "Empty"
    },
    {
      "x": -9,
      "y": 13,
      "z": 2,
      "name": "Empty"
    },
    {
      "x": -9,
      "y": 14,
      "z": 2,
      "name": "Empty"
    },
    {
      "x": -9,
      "y": 15,
      "z": 2,
      "name": "Rock_Quartzite"
    },
    {
      "x": -9,
      "y": 16,
      "z": 2,
      "name": "Rock_Quartzite"
    },
    {
      "x": -9,
      "y": 17,
      "z": 2,
      "name": "Rock_Quartzite"
    },
    {
      "x": -9,
      "y": 0,
      "z": 3,
      "name": "Rock_Stone"
    },
    {
      "x": -9,
      "y": 1,
      "z": 3,
      "name": "Rock_Stone"
    },
    {
      "x": -9,
      "y": 2,
      "z": 3,
      "name": "Rock_Stone_Cobble"
    },
    {
      "x": -9,
      "y": 3,
      "z": 3,
      "name": "Rock_Stone_Cobble"
    },
    {
      "x": -9,
      "y": 4,
      "z": 3,
      "name": "Wood_Deadwood_Planks"
    },
    {
      "x": -9,
      "y": 5,
      "z": 3,
      "name": "Furniture_Ancient_Table",
      "filler": 32
    },
    {
      "x": -9,
      "y": 6,
      "z": 3,
      "name": "Deco_Potion",
      "rotation": 1
    },
    {
      "x": -9,
      "y": 7,
      "z": 3,
      "name": "Empty"
    },
    {
      "x": -9,
      "y": 8,
      "z": 3,
      "name": "Empty"
    },
    {
      "x": -9,
      "y": 9,
      "z": 3,
      "name": "Empty"
    },
    {
      "x": -9,
      "y": 10,
      "z": 3,
      "name": "Wood_Deadwood_Planks"
    },
    {
      "x": -9,
      "y": 11,
      "z": 3,
      "name": "Empty"
    },
    {
      "x": -9,
      "y": 12,
      "z": 3,
      "name": "Empty"
    },
    {
      "x": -9,
      "y": 13,
      "z": 3,
      "name": "Empty"
    },
    {
      "x": -9,
      "y": 14,
      "z": 3,
      "name": "Empty"
    },
    {
      "x": -9,
      "y": 15,
      "z": 3,
      "name": "Rock_Quartzite"
    },
    {
      "x": -9,
      "y": 16,
      "z": 3,
      "name": "Rock_Quartzite"
    },
    {
      "x": -9,
      "y": 17,
      "z": 3,
      "name": "Rock_Quartzite"
    },
    {
      "x": -9,
      "y": 0,
      "z": 4,
      "name": "Rock_Stone"
    },
    {
      "x": -9,
      "y": 1,
      "z": 4,
      "name": "Rock_Stone"
    },
    {
      "x": -9,
      "y": 2,
      "z": 4,
      "name": "Rock_Stone_Cobble"
    },
    {
      "x": -9,
      "y": 3,
      "z": 4,
      "name": "Rock_Stone_Cobble"
    },
    {
      "x": -9,
      "y": 4,
      "z": 4,
      "name": "Wood_Deadwood_Planks"
    },
    {
      "x": -9,
      "y": 5,
      "z": 4,
      "name": "Furniture_Ancient_Chair",
      "rotation": 1
    },
    {
      "x": -9,
      "y": 6,
      "z": 4,
      "name": "Empty"
    },
    {
      "x": -9,
      "y": 7,
      "z": 4,
      "name": "Empty"
    },
    {
      "x": -9,
      "y": 8,
      "z": 4,
      "name": "Empty"
    },
    {
      "x": -9,
      "y": 9,
      "z": 4,
      "name": "Empty"
    },
    {
      "x": -9,
      "y": 10,
      "z": 4,
      "name": "Wood_Deadwood_Planks"
    },
    {
      "x": -9,
      "y": 11,
      "z": 4,
      "name": "Empty"
    },
    {
      "x": -9,
      "y": 12,
      "z": 4,
      "name": "Empty"
    },
    {
      "x": -9,
      "y": 13,
      "z": 4,
      "name": "Empty"
    },
    {
      "x": -9,
      "y": 14,
      "z": 4,
      "name": "Rock_Quartzite_Brick_Half",
      "rotation": 8
    },
    {
      "x": -9,
      "y": 15,
      "z": 4,
      "name": "Rock_Quartzite"
    },
    {
      "x": -9,
      "y": 16,
      "z": 4,
      "name": "Rock_Quartzite"
    },
    {
      "x": -9,
      "y": 17,
      "z": 4,
      "name": "Rock_Quartzite"
    },
    {
      "x": -9,
      "y": 0,
      "z": 5,
      "name": "Rock_Stone"
    },
    {
      "x": -9,
      "y": 1,
      "z": 5,
      "name": "Rock_Stone"
    },
    {
      "x": -9,
      "y": 2,
      "z": 5,
      "name": "Rock_Stone_Cobble"
    },
    {
      "x": -9,
      "y": 3,
      "z": 5,
      "name": "Rock_Stone_Cobble"
    },
    {
      "x": -9,
      "y": 4,
      "z": 5,
      "name": "Wood_Deadwood_Planks"
    },
    {
      "x": -9,
      "y": 5,
      "z": 5,
      "name": "Plant_Crop_Mushroom_Flatcap_Green",
      "components": {
        "Components": {
          "FarmingBlock": {
            "LastTickGameTime": "0001-01-01T12:00:00Z"
          }
        }
      }
    },
    {
      "x": -9,
      "y": 6,
      "z": 5,
      "name": "Empty"
    },
    {
      "x": -9,
      "y": 7,
      "z": 5,
      "name": "Empty"
    },
    {
      "x": -9,
      "y": 8,
      "z": 5,
      "name": "Empty"
    },
    {
      "x": -9,
      "y": 9,
      "z": 5,
      "name": "Empty"
    },
    {
      "x": -9,
      "y": 10,
      "z": 5,
      "name": "Wood_Deadwood_Planks"
    },
    {
      "x": -9,
      "y": 11,
      "z": 5,
      "name": "Plant_Moss_Rug_Blue"
    },
    {
      "x": -9,
      "y": 12,
      "z": 5,
      "name": "Empty"
    },
    {
      "x": -9,
      "y": 13,
      "z": 5,
      "name": "Empty"
    },
    {
      "x": -9,
      "y": 14,
      "z": 5,
      "name": "Rock_Quartzite_Brick_Half",
      "rotation": 8
    },
    {
      "x": -9,
      "y": 15,
      "z": 5,
      "name": "Rock_Quartzite"
    },
    {
      "x": -9,
      "y": 16,
      "z": 5,
      "name": "Rock_Quartzite"
    },
    {
      "x": -9,
      "y": 17,
      "z": 5,
      "name": "Rock_Quartzite"
    },
    {
      "x": -9,
      "y": 0,
      "z": 6,
      "name": "Rock_Stone"
    },
    {
      "x": -9,
      "y": 1,
      "z": 6,
      "name": "Rock_Stone"
    },
    {
      "x": -9,
      "y": 2,
      "z": 6,
      "name": "Rock_Stone_Cobble"
    },
    {
      "x": -9,
      "y": 3,
      "z": 6,
      "name": "Rock_Stone_Cobble"
    },
    {
      "x": -9,
      "y": 4,
      "z": 6,
      "name": "Wood_Deadwood_Planks"
    },
    {
      "x": -9,
      "y": 5,
      "z": 6,
      "name": "Furniture_Ancient_Crate",
      "rotation": 2
    },
    {
      "x": -9,
      "y": 6,
      "z": 6,
      "name": "Plant_Crop_Mushroom_Flatcap_Green",
      "components": {
        "Components": {
          "FarmingBlock": {
            "LastTickGameTime": "0001-01-01T12:00:00Z"
          }
        }
      }
    },
    {
      "x": -9,
      "y": 7,
      "z": 6,
      "name": "Empty"
    },
    {
      "x": -9,
      "y": 8,
      "z": 6,
      "name": "Empty"
    },
    {
      "x": -9,
      "y": 9,
      "z": 6,
      "name": "Rock_Quartzite_Brick_Half",
      "rotation": 8
    },
    {
      "x": -9,
      "y": 10,
      "z": 6,
      "name": "Wood_Deadwood_Planks"
    },
    {
      "x": -9,
      "y": 11,
      "z": 6,
      "name": "Plant_Moss_Block_Blue"
    },
    {
      "x": -9,
      "y": 12,
      "z": 6,
      "name": "Empty"
    },
    {
      "x": -9,
      "y": 13,
      "z": 6,
      "name": "Empty"
    },
    {
      "x": -9,
      "y": 14,
      "z": 6,
      "name": "Rock_Quartzite_Brick_Half",
      "rotation": 8
    },
    {
      "x": -9,
      "y": 15,
      "z": 6,
      "name": "Rock_Quartzite"
    },
    {
      "x": -9,
      "y": 16,
      "z": 6,
      "name": "Rock_Quartzite"
    },
    {
      "x": -9,
      "y": 17,
      "z": 6,
      "name": "Rock_Quartzite"
    },
    {
      "x": -9,
      "y": 0,
      "z": 7,
      "name": "Rock_Stone"
    },
    {
      "x": -9,
      "y": 1,
      "z": 7,
      "name": "Rock_Stone"
    },
    {
      "x": -9,
      "y": 2,
      "z": 7,
      "name": "Rock_Stone_Cobble"
    },
    {
      "x": -9,
      "y": 3,
      "z": 7,
      "name": "Rock_Stone_Cobble"
    },
    {
      "x": -9,
      "y": 4,
      "z": 7,
      "name": "Rock_Stone_Cobble"
    },
    {
      "x": -9,
      "y": 5,
      "z": 7,
      "name": "Rock_Quartzite_Brick"
    },
    {
      "x": -9,
      "y": 6,
      "z": 7,
      "name": "Rock_Quartzite_Brick"
    },
    {
      "x": -9,
      "y": 7,
      "z": 7,
      "name": "Rock_Quartzite_Brick"
    },
    {
      "x": -9,
      "y": 8,
      "z": 7,
      "name": "Rock_Quartzite_Brick"
    },
    {
      "x": -9,
      "y": 9,
      "z": 7,
      "name": "Rock_Quartzite_Brick"
    },
    {
      "x": -9,
      "y": 10,
      "z": 7,
      "name": "Wood_Deadwood_Planks"
    },
    {
      "x": -9,
      "y": 11,
      "z": 7,
      "name": "Plant_Moss_Block_Blue"
    },
    {
      "x": -9,
      "y": 12,
      "z": 7,
      "name": "Rock_Quartzite_Brick_Half",
      "rotation": 5
    },
    {
      "x": -9,
      "y": 13,
      "z": 7,
      "name": "Rock_Quartzite_Brick"
    },
    {
      "x": -9,
      "y": 14,
      "z": 7,
      "name": "Rock_Quartzite_Brick"
    },
    {
      "x": -9,
      "y": 15,
      "z": 7,
      "name": "Rock_Quartzite"
    },
    {
      "x": -9,
      "y": 16,
      "z": 7,
      "name": "Rock_Quartzite"
    },
    {
      "x": -9,
      "y": 17,
      "z": 7,
      "name": "Rock_Quartzite"
    },
    {
      "x": -9,
      "y": 0,
      "z": 8,
      "name": "Rock_Stone"
    },
    {
      "x": -9,
      "y": 1,
      "z": 8,
      "name": "Rock_Stone"
    },
    {
      "x": -9,
      "y": 2,
      "z": 8,
      "name": "Rock_Stone_Cobble"
    },
    {
      "x": -9,
      "y": 3,
      "z": 8,
      "name": "Rock_Quartzite_Brick"
    },
    {
      "x": -9,
      "y": 4,
      "z": 8,
      "name": "Rock_Quartzite_Brick"
    },
    {
      "x": -9,
      "y": 5,
      "z": 8,
      "name": "Rock_Quartzite_Brick"
    },
    {
      "x": -9,
      "y": 6,
      "z": 8,
      "name": "Rock_Quartzite"
    },
    {
      "x": -9,
      "y": 7,
      "z": 8,
      "name": "Rock_Quartzite"
    },
    {
      "x": -9,
      "y": 8,
      "z": 8,
      "name": "Rock_Quartzite"
    },
    {
      "x": -9,
      "y": 9,
      "z": 8,
      "name": "Rock_Quartzite"
    },
    {
      "x": -9,
      "y": 10,
      "z": 8,
      "name": "Rock_Quartzite"
    },
    {
      "x": -9,
      "y": 11,
      "z": 8,
      "name": "Rock_Quartzite"
    },
    {
      "x": -9,
      "y": 12,
      "z": 8,
      "name": "Rock_Quartzite"
    },
    {
      "x": -9,
      "y": 13,
      "z": 8,
      "name": "Rock_Quartzite"
    },
    {
      "x": -9,
      "y": 14,
      "z": 8,
      "name": "Rock_Quartzite"
    },
    {
      "x": -9,
      "y": 15,
      "z": 8,
      "name": "Rock_Quartzite"
    },
    {
      "x": -9,
      "y": 16,
      "z": 8,
      "name": "Rock_Quartzite"
    },
    {
      "x": -9,
      "y": 17,
      "z": 8,
      "name": "Rock_Quartzite"
    },
    {
      "x": -8,
      "y": 0,
      "z": -8,
      "name": "Rock_Stone"
    },
    {
      "x": -8,
      "y": 1,
      "z": -8,
      "name": "Rock_Stone"
    },
    {
      "x": -8,
      "y": 2,
      "z": -8,
      "name": "Rock_Stone_Cobble"
    },
    {
      "x": -8,
      "y": 3,
      "z": -8,
      "name": "Rock_Quartzite_Brick"
    },
    {
      "x": -8,
      "y": 4,
      "z": -8,
      "name": "Rock_Quartzite_Brick"
    },
    {
      "x": -8,
      "y": 5,
      "z": -8,
      "name": "Rock_Quartzite_Brick"
    },
    {
      "x": -8,
      "y": 6,
      "z": -8,
      "name": "Rock_Quartzite_Brick"
    },
    {
      "x": -8,
      "y": 7,
      "z": -8,
      "name": "Rock_Quartzite_Brick"
    },
    {
      "x": -8,
      "y": 8,
      "z": -8,
      "name": "Rock_Quartzite"
    },
    {
      "x": -8,
      "y": 9,
      "z": -8,
      "name": "Rock_Quartzite"
    },
    {
      "x": -8,
      "y": 10,
      "z": -8,
      "name": "Rock_Quartzite"
    },
    {
      "x": -8,
      "y": 11,
      "z": -8,
      "name": "Rock_Quartzite_Brick"
    },
    {
      "x": -8,
      "y": 12,
      "z": -8,
      "name": "Rock_Quartzite"
    },
    {
      "x": -8,
      "y": 13,
      "z": -8,
      "name": "Rock_Quartzite"
    },
    {
      "x": -8,
      "y": 14,
      "z": -8,
      "name": "Rock_Quartzite_Brick"
    },
    {
      "x": -8,
      "y": 15,
      "z": -8,
      "name": "Rock_Quartzite"
    },
    {
      "x": -8,
      "y": 16,
      "z": -8,
      "name": "Rock_Quartzite"
    },
    {
      "x": -8,
      "y": 17,
      "z": -8,
      "name": "Rock_Quartzite"
    },
    {
      "x": -8,
      "y": 0,
      "z": -7,
      "name": "Rock_Stone"
    },
    {
      "x": -8,
      "y": 1,
      "z": -7,
      "name": "Rock_Stone"
    },
    {
      "x": -8,
      "y": 2,
      "z": -7,
      "name": "Rock_Stone_Cobble"
    },
    {
      "x": -8,
      "y": 3,
      "z": -7,
      "name": "Rock_Stone_Cobble"
    },
    {
      "x": -8,
      "y": 4,
      "z": -7,
      "name": "Wood_Deadwood_Planks"
    },
    {
      "x": -8,
      "y": 5,
      "z": -7,
      "name": "Furniture_Village_Bookcase"
    },
    {
      "x": -8,
      "y": 6,
      "z": -7,
      "name": "Furniture_Village_Bookcase"
    },
    {
      "x": -8,
      "y": 7,
      "z": -7,
      "name": "Empty"
    },
    {
      "x": -8,
      "y": 8,
      "z": -7,
      "name": "Empty"
    },
    {
      "x": -8,
      "y": 9,
      "z": -7,
      "name": "Rock_Quartzite_Brick_Half",
      "rotation": 8
    },
    {
      "x": -8,
      "y": 10,
      "z": -7,
      "name": "Wood_Deadwood_Planks"
    },
    {
      "x": -8,
      "y": 11,
      "z": -7,
      "name": "Empty"
    },
    {
      "x": -8,
      "y": 12,
      "z": -7,
      "name": "Empty"
    },
    {
      "x": -8,
      "y": 13,
      "z": -7,
      "name": "Empty"
    },
    {
      "x": -8,
      "y": 14,
      "z": -7,
      "name": "Rock_Quartzite_Brick"
    },
    {
      "x": -8,
      "y": 15,
      "z": -7,
      "name": "Rock_Quartzite"
    },
    {
      "x": -8,
      "y": 16,
      "z": -7,
      "name": "Rock_Quartzite"
    },
    {
      "x": -8,
      "y": 17,
      "z": -7,
      "name": "Rock_Quartzite"
    },
    {
      "x": -8,
      "y": 0,
      "z": -6,
      "name": "Rock_Stone"
    },
    {
      "x": -8,
      "y": 1,
      "z": -6,
      "name": "Rock_Stone"
    },
    {
      "x": -8,
      "y": 2,
      "z": -6,
      "name": "Rock_Stone_Cobble"
    },
    {
      "x": -8,
      "y": 3,
      "z": -6,
      "name": "Rock_Stone_Cobble"
    },
    {
      "x": -8,
      "y": 4,
      "z": -6,
      "name": "Wood_Deadwood_Planks"
    },
    {
      "x": -8,
      "y": 5,
      "z": -6,
      "name": "Furniture_Ancient_Ladder",
      "rotation": 1
    },
    {
      "x": -8,
      "y": 6,
      "z": -6,
      "name": "Furniture_Ancient_Ladder",
      "rotation": 1
    },
    {
      "x": -8,
      "y": 7,
      "z": -6,
      "name": "Furniture_Ancient_Ladder",
      "rotation": 1
    },
    {
      "x": -8,
      "y": 8,
      "z": -6,
      "name": "Empty"
    },
    {
      "x": -8,
      "y": 9,
      "z": -6,
      "name": "Empty"
    },
    {
      "x": -8,
      "y": 10,
      "z": -6,
      "name": "Wood_Deadwood_Planks"
    },
    {
      "x": -8,
      "y": 11,
      "z": -6,
      "name": "Empty"
    },
    {
      "x": -8,
      "y": 12,
      "z": -6,
      "name": "Empty"
    },
    {
      "x": -8,
      "y": 13,
      "z": -6,
      "name": "Empty"
    },
    {
      "x": -8,
      "y": 14,
      "z": -6,
      "name": "Empty"
    },
    {
      "x": -8,
      "y": 15,
      "z": -6,
      "name": "Rock_Quartzite"
    },
    {
      "x": -8,
      "y": 16,
      "z": -6,
      "name": "Rock_Quartzite"
    },
    {
      "x": -8,
      "y": 17,
      "z": -6,
      "name": "Rock_Quartzite"
    },
    {
      "x": -8,
      "y": 0,
      "z": -5,
      "name": "Rock_Stone"
    },
    {
      "x": -8,
      "y": 1,
      "z": -5,
      "name": "Rock_Stone"
    },
    {
      "x": -8,
      "y": 2,
      "z": -5,
      "name": "Rock_Stone_Cobble"
    },
    {
      "x": -8,
      "y": 3,
      "z": -5,
      "name": "Rock_Stone_Cobble"
    },
    {
      "x": -8,
      "y": 4,
      "z": -5,
      "name": "Wood_Deadwood_Planks"
    },
    {
      "x": -8,
      "y": 5,
      "z": -5,
      "name": "Empty"
    },
    {
      "x": -8,
      "y": 6,
      "z": -5,
      "name": "Empty"
    },
    {
      "x": -8,
      "y": 7,
      "z": -5,
      "name": "Empty"
    },
    {
      "x": -8,
      "y": 8,
      "z": -5,
      "name": "Empty"
    },
    {
      "x": -8,
      "y": 9,
      "z": -5,
      "name": "Empty"
    },
    {
      "x": -8,
      "y": 10,
      "z": -5,
      "name": "Wood_Deadwood_Planks"
    },
    {
      "x": -8,
      "y": 11,
      "z": -5,
      "name": "Empty"
    },
    {
      "x": -8,
      "y": 12,
      "z": -5,
      "name": "Empty"
    },
    {
      "x": -8,
      "y": 13,
      "z": -5,
      "name": "Empty"
    },
    {
      "x": -8,
      "y": 14,
      "z": -5,
      "name": "Empty"
    },
    {
      "x": -8,
      "y": 15,
      "z": -5,
      "name": "Rock_Quartzite"
    },
    {
      "x": -8,
      "y": 16,
      "z": -5,
      "name": "Rock_Quartzite"
    },
    {
      "x": -8,
      "y": 17,
      "z": -5,
      "name": "Rock_Quartzite"
    },
    {
      "x": -8,
      "y": 0,
      "z": -4,
      "name": "Rock_Stone"
    },
    {
      "x": -8,
      "y": 1,
      "z": -4,
      "name": "Rock_Stone"
    },
    {
      "x": -8,
      "y": 2,
      "z": -4,
      "name": "Rock_Stone_Cobble"
    },
    {
      "x": -8,
      "y": 3,
      "z": -4,
      "name": "Rock_Stone_Cobble"
    },
    {
      "x": -8,
      "y": 4,
      "z": -4,
      "name": "Wood_Deadwood_Planks"
    },
    {
      "x": -8,
      "y": 5,
      "z": -4,
      "name": "Empty"
    },
    {
      "x": -8,
      "y": 6,
      "z": -4,
      "name": "Empty"
    },
    {
      "x": -8,
      "y": 7,
      "z": -4,
      "name": "Empty"
    },
    {
      "x": -8,
      "y": 8,
      "z": -4,
      "name": "Empty"
    },
    {
      "x": -8,
      "y": 9,
      "z": -4,
      "name": "Empty"
    },
    {
      "x": -8,
      "y": 10,
      "z": -4,
      "name": "Wood_Deadwood_Planks"
    },
    {
      "x": -8,
      "y": 11,
      "z": -4,
      "name": "Empty"
    },
    {
      "x": -8,
      "y": 12,
      "z": -4,
      "name": "Empty"
    },
    {
      "x": -8,
      "y": 13,
      "z": -4,
      "name": "Empty"
    },
    {
      "x": -8,
      "y": 14,
      "z": -4,
      "name": "Empty"
    },
    {
      "x": -8,
      "y": 15,
      "z": -4,
      "name": "Rock_Quartzite"
    },
    {
      "x": -8,
      "y": 16,
      "z": -4,
      "name": "Rock_Quartzite"
    },
    {
      "x": -8,
      "y": 17,
      "z": -4,
      "name": "Rock_Quartzite"
    },
    {
      "x": -8,
      "y": 0,
      "z": -3,
      "name": "Rock_Stone"
    },
    {
      "x": -8,
      "y": 1,
      "z": -3,
      "name": "Rock_Stone"
    },
    {
      "x": -8,
      "y": 2,
      "z": -3,
      "name": "Rock_Stone_Cobble"
    },
    {
      "x": -8,
      "y": 3,
      "z": -3,
      "name": "Rock_Stone_Cobble"
    },
    {
      "x": -8,
      "y": 4,
      "z": -3,
      "name": "Wood_Deadwood_Planks"
    },
    {
      "x": -8,
      "y": 5,
      "z": -3,
      "name": "Empty"
    },
    {
      "x": -8,
      "y": 6,
      "z": -3,
      "name": "Empty"
    },
    {
      "x": -8,
      "y": 7,
      "z": -3,
      "name": "Empty"
    },
    {
      "x": -8,
      "y": 8,
      "z": -3,
      "name": "Empty"
    },
    {
      "x": -8,
      "y": 9,
      "z": -3,
      "name": "Empty"
    },
    {
      "x": -8,
      "y": 10,
      "z": -3,
      "name": "Wood_Deadwood_Planks"
    },
    {
      "x": -8,
      "y": 11,
      "z": -3,
      "name": "Empty"
    },
    {
      "x": -8,
      "y": 12,
      "z": -3,
      "name": "Empty"
    },
    {
      "x": -8,
      "y": 13,
      "z": -3,
      "name": "Empty"
    },
    {
      "x": -8,
      "y": 14,
      "z": -3,
      "name": "Empty"
    },
    {
      "x": -8,
      "y": 15,
      "z": -3,
      "name": "Rock_Quartzite"
    },
    {
      "x": -8,
      "y": 16,
      "z": -3,
      "name": "Rock_Quartzite"
    },
    {
      "x": -8,
      "y": 17,
      "z": -3,
      "name": "Rock_Quartzite"
    },
    {
      "x": -8,
      "y": 0,
      "z": -2,
      "name": "Rock_Stone"
    },
    {
      "x": -8,
      "y": 1,
      "z": -2,
      "name": "Rock_Stone"
    },
    {
      "x": -8,
      "y": 2,
      "z": -2,
      "name": "Rock_Stone_Cobble"
    },
    {
      "x": -8,
      "y": 3,
      "z": -2,
      "name": "Rock_Stone_Cobble"
    },
    {
      "x": -8,
      "y": 4,
      "z": -2,
      "name": "Wood_Deadwood_Planks"
    },
    {
      "x": -8,
      "y": 5,
      "z": -2,
      "name": "Furniture_Ancient_Bookshelf",
      "rotation": 1
    },
    {
      "x": -8,
      "y": 6,
      "z": -2,
      "name": "Empty"
    },
    {
      "x": -8,
      "y": 7,
      "z": -2,
      "name": "Empty"
    },
    {
      "x": -8,
      "y": 8,
      "z": -2,
      "name": "Empty"
    },
    {
      "x": -8,
      "y": 9,
      "z": -2,
      "name": "Empty"
    },
    {
      "x": -8,
      "y": 10,
      "z": -2,
      "name": "Wood_Deadwood_Planks"
    },
    {
      "x": -8,
      "y": 11,
      "z": -2,
      "name": "Empty"
    },
    {
      "x": -8,
      "y": 12,
      "z": -2,
      "name": "Empty"
    },
    {
      "x": -8,
      "y": 13,
      "z": -2,
      "name": "Rock_Quartzite_Brick_Half",
      "rotation": 5
    },
    {
      "x": -8,
      "y": 14,
      "z": -2,
      "name": "Rock_Quartzite_Brick"
    },
    {
      "x": -8,
      "y": 15,
      "z": -2,
      "name": "Rock_Quartzite"
    },
    {
      "x": -8,
      "y": 16,
      "z": -2,
      "name": "Rock_Quartzite"
    },
    {
      "x": -8,
      "y": 17,
      "z": -2,
      "name": "Rock_Quartzite"
    },
    {
      "x": -8,
      "y": 0,
      "z": -1,
      "name": "Rock_Stone"
    },
    {
      "x": -8,
      "y": 1,
      "z": -1,
      "name": "Rock_Stone"
    },
    {
      "x": -8,
      "y": 2,
      "z": -1,
      "name": "Rock_Stone_Cobble"
    },
    {
      "x": -8,
      "y": 3,
      "z": -1,
      "name": "Rock_Stone_Cobble"
    },
    {
      "x": -8,
      "y": 4,
      "z": -1,
      "name": "Wood_Deadwood_Planks"
    },
    {
      "x": -8,
      "y": 5,
      "z": -1,
      "name": "Empty"
    },
    {
      "x": -8,
      "y": 6,
      "z": -1,
      "name": "Empty"
    },
    {
      "x": -8,
      "y": 7,
      "z": -1,
      "name": "Plant_Moss_Rug_Blue"
    },
    {
      "x": -8,
      "y": 8,
      "z": -1,
      "name": "Empty"
    },
    {
      "x": -8,
      "y": 9,
      "z": -1,
      "name": "Empty"
    },
    {
      "x": -8,
      "y": 10,
      "z": -1,
      "name": "Wood_Deadwood_Planks"
    },
    {
      "x": -8,
      "y": 11,
      "z": -1,
      "name": "Empty"
    },
    {
      "x": -8,
      "y": 12,
      "z": -1,
      "name": "Empty"
    },
    {
      "x": -8,
      "y": 13,
      "z": -1,
      "name": "Empty"
    },
    {
      "x": -8,
      "y": 14,
      "z": -1,
      "name": "Empty"
    },
    {
      "x": -8,
      "y": 15,
      "z": -1,
      "name": "Rock_Quartzite"
    },
    {
      "x": -8,
      "y": 16,
      "z": -1,
      "name": "Rock_Quartzite"
    },
    {
      "x": -8,
      "y": 17,
      "z": -1,
      "name": "Rock_Quartzite"
    },
    {
      "x": -8,
      "y": 0,
      "z": 0,
      "name": "Rock_Stone"
    },
    {
      "x": -8,
      "y": 1,
      "z": 0,
      "name": "Rock_Stone"
    },
    {
      "x": -8,
      "y": 2,
      "z": 0,
      "name": "Rock_Stone_Cobble"
    },
    {
      "x": -8,
      "y": 3,
      "z": 0,
      "name": "Rock_Stone_Cobble"
    },
    {
      "x": -8,
      "y": 4,
      "z": 0,
      "name": "Wood_Deadwood_Planks"
    },
    {
      "x": -8,
      "y": 5,
      "z": 0,
      "name": "Empty"
    },
    {
      "x": -8,
      "y": 6,
      "z": 0,
      "name": "Empty"
    },
    {
      "x": -8,
      "y": 7,
      "z": 0,
      "name": "Empty"
    },
    {
      "x": -8,
      "y": 8,
      "z": 0,
      "name": "Empty"
    },
    {
      "x": -8,
      "y": 9,
      "z": 0,
      "name": "Empty"
    },
    {
      "x": -8,
      "y": 10,
      "z": 0,
      "name": "Wood_Deadwood_Planks"
    },
    {
      "x": -8,
      "y": 11,
      "z": 0,
      "name": "Empty"
    },
    {
      "x": -8,
      "y": 12,
      "z": 0,
      "name": "Empty"
    },
    {
      "x": -8,
      "y": 13,
      "z": 0,
      "name": "Empty"
    },
    {
      "x": -8,
      "y": 14,
      "z": 0,
      "name": "Empty"
    },
    {
      "x": -8,
      "y": 15,
      "z": 0,
      "name": "Rock_Quartzite"
    },
    {
      "x": -8,
      "y": 16,
      "z": 0,
      "name": "Rock_Quartzite"
    },
    {
      "x": -8,
      "y": 17,
      "z": 0,
      "name": "Rock_Quartzite"
    },
    {
      "x": -8,
      "y": 0,
      "z": 1,
      "name": "Rock_Stone"
    },
    {
      "x": -8,
      "y": 1,
      "z": 1,
      "name": "Rock_Stone"
    },
    {
      "x": -8,
      "y": 2,
      "z": 1,
      "name": "Rock_Stone_Cobble"
    },
    {
      "x": -8,
      "y": 3,
      "z": 1,
      "name": "Rock_Stone_Cobble"
    },
    {
      "x": -8,
      "y": 4,
      "z": 1,
      "name": "Wood_Deadwood_Planks"
    },
    {
      "x": -8,
      "y": 5,
      "z": 1,
      "name": "Empty"
    },
    {
      "x": -8,
      "y": 6,
      "z": 1,
      "name": "Empty"
    },
    {
      "x": -8,
      "y": 7,
      "z": 1,
      "name": "Empty"
    },
    {
      "x": -8,
      "y": 8,
      "z": 1,
      "name": "Empty"
    },
    {
      "x": -8,
      "y": 9,
      "z": 1,
      "name": "Empty"
    },
    {
      "x": -8,
      "y": 10,
      "z": 1,
      "name": "Wood_Deadwood_Planks"
    },
    {
      "x": -8,
      "y": 11,
      "z": 1,
      "name": "Empty"
    },
    {
      "x": -8,
      "y": 12,
      "z": 1,
      "name": "Empty"
    },
    {
      "x": -8,
      "y": 13,
      "z": 1,
      "name": "Empty"
    },
    {
      "x": -8,
      "y": 14,
      "z": 1,
      "name": "Empty"
    },
    {
      "x": -8,
      "y": 15,
      "z": 1,
      "name": "Rock_Quartzite"
    },
    {
      "x": -8,
      "y": 16,
      "z": 1,
      "name": "Rock_Quartzite"
    },
    {
      "x": -8,
      "y": 17,
      "z": 1,
      "name": "Rock_Quartzite"
    },
    {
      "x": -8,
      "y": 0,
      "z": 2,
      "name": "Rock_Stone"
    },
    {
