{
  "version": 8,
  "blockIdVersion": 8,
  "anchorX": 1,
  "anchorY": 11,
  "anchorZ": 3,
  "blocks": [
    {
      "x": -2,
      "y": 5,
      "z": 2,
      "name": "Soil_Sand_Ashen"
    },
    {
      "x": -2,
      "y": 6,
      "z": 2,
      "name": "Soil_Sand_Ashen"
    },
    {
      "x": -2,
      "y": 7,
      "z": 2,
      "name": "Soil_Sand_Ashen"
    },
    {
      "x": -2,
      "y": 8,
      "z": 2,
      "name": "Soil_Sand_Ashen"
    },
    {
      "x": -2,
      "y": 9,
      "z": 2,
      "name": "Soil_Sand_Ashen"
    },
    {
      "x": -2,
      "y": 10,
      "z": 2,
      "name": "Soil_Sand_Ashen"
    },
    {
      "x": -2,
      "y": 11,
      "z": 2,
      "name": "Soil_Sand_Ashen"
    },
    {
      "x": -2,
      "y": 12,
      "z": 2,
      "name": "Furniture_Ancient_Barrel"
    },
    {
      "x": -1,
      "y": 5,
      "z": 1,
      "name": "Soil_Sand_Ashen"
    },
    {
      "x": -1,
      "y": 6,
      "z": 1,
      "name": "Soil_Sand_Ashen"
    },
    {
      "x": -1,
      "y": 7,
      "z": 1,
      "name": "Soil_Sand_Ashen"
    },
    {
      "x": -1,
      "y": 8,
      "z": 1,
      "name": "Soil_Sand_Ashen"
    },
    {
      "x": -1,
      "y": 9,
      "z": 1,
      "name": "Soil_Sand_Ashen"
    },
    {
      "x": -1,
      "y": 10,
      "z": 1,
      "name": "Soil_Sand_Ashen"
    },
    {
      "x": -1,
      "y": 11,
      "z": 1,
      "name": "Soil_Sand_Ashen"
    },
    {
      "x": -1,
      "y": 12,
      "z": 1,
      "name": "Cloth_Roof_Leather_Flap",
      "rotation": 3
    },
    {
      "x": -1,
      "y": 13,
      "z": 1,
      "name": "Cloth_Roof_Leather_Vertical",
      "rotation": 3
    },
    {
      "x": -1,
      "y": 14,
      "z": 1,
      "name": "Cloth_Roof_Leather_Vertical",
      "rotation": 3
    },
    {
      "x": -1,
      "y": 5,
      "z": 2,
      "name": "Soil_Sand_Ashen"
    },
    {
      "x": -1,
      "y": 6,
      "z": 2,
      "name": "Soil_Sand_Ashen"
    },
    {
      "x": -1,
      "y": 7,
      "z": 2,
      "name": "Soil_Sand_Ashen"
    },
    {
      "x": -1,
      "y": 8,
      "z": 2,
      "name": "Soil_Sand_Ashen"
    },
    {
      "x": -1,
      "y": 9,
      "z": 2,
      "name": "Soil_Sand_Ashen"
    },
    {
      "x": -1,
      "y": 10,
      "z": 2,
      "name": "Soil_Sand_Ashen"
    },
    {
      "x": -1,
      "y": 11,
      "z": 2,
      "name": "Soil_Sand_Ashen"
    },
    {
      "x": -1,
      "y": 12,
      "z": 2,
      "name": "Furniture_Ancient_Crate",
      "rotation": 3
    },
    {
      "x": -1,
      "y": 5,
      "z": 3,
      "name": "Soil_Sand_Ashen"
    },
    {
      "x": -1,
      "y": 6,
      "z": 3,
      "name": "Soil_Sand_Ashen"
    },
    {
      "x": -1,
      "y": 7,
      "z": 3,
      "name": "Soil_Sand_Ashen"
    },
    {
      "x": -1,
      "y": 8,
      "z": 3,
      "name": "Soil_Sand_Ashen"
    },
    {
      "x": -1,
      "y": 9,
      "z": 3,
      "name": "Soil_Sand_Ashen"
    },
    {
      "x": -1,
      "y": 10,
      "z": 3,
      "name": "Soil_Sand_Ashen"
    },
    {
      "x": -1,
      "y": 11,
      "z": 3,
      "name": "Soil_Sand_Ashen"
    },
    {
      "x": -1,
      "y": 12,
      "z": 3,
      "name": "Furniture_Ancient_Crate",
      "rotation": 3
    },
    {
      "x": -1,
      "y": 13,
      "z": 3,
      "name": "Cloth_Roof_Leather_Flap",
      "rotation": 3
    },
    {
      "x": -1,
      "y": 5,
      "z": 4,
      "name": "Soil_Sand_Ashen"
    },
    {
      "x": -1,
      "y": 6,
      "z": 4,
      "name": "Soil_Sand_Ashen"
    },
    {
      "x": -1,
      "y": 7,
      "z": 4,
      "name": "Soil_Sand_Ashen"
    },
    {
      "x": -1,
      "y": 8,
      "z": 4,
      "name": "Soil_Sand_Ashen"
    },
    {
      "x": -1,
      "y": 9,
      "z": 4,
      "name": "Soil_Sand_Ashen"
    },
    {
      "x": -1,
      "y": 10,
      "z": 4,
      "name": "Soil_Sand_Ashen"
    },
    {
      "x": -1,
      "y": 11,
      "z": 4,
      "name": "Soil_Sand_Ashen"
    },
    {
      "x": -1,
      "y": 12,
      "z": 4,
      "name": "Cloth_Roof_Leather_Flap",
      "rotation": 3
    },
    {
      "x": -1,
      "y": 13,
      "z": 4,
      "name": "Cloth_Roof_Leather_Vertical",
      "rotation": 3
    },
    {
      "x": 0,
      "y": 13,
      "z": 0,
      "name": "Cloth_Roof_Leather_Flap",
      "rotation": 2
    },
    {
      "x": 0,
      "y": 14,
      "z": 0,
      "name": "Cloth_Roof_Leather_Vertical",
      "rotation": 2
    },
    {
      "x": 0,
      "y": 5,
      "z": 1,
      "name": "Soil_Sand_Ashen"
    },
    {
      "x": 0,
      "y": 6,
      "z": 1,
      "name": "Soil_Sand_Ashen"
    },
    {
      "x": 0,
      "y": 7,
      "z": 1,
      "name": "Soil_Sand_Ashen"
    },
    {
      "x": 0,
      "y": 8,
      "z": 1,
      "name": "Soil_Sand_Ashen"
    },
    {
      "x": 0,
      "y": 9,
      "z": 1,
      "name": "Soil_Sand_Ashen"
    },
    {
      "x": 0,
      "y": 10,
      "z": 1,
      "name": "Soil_Sand_Ashen"
    },
    {
      "x": 0,
      "y": 11,
      "z": 1,
      "name": "Soil_Sand_Ashen"
    },
    {
      "x": 0,
      "y": 12,
      "z": 1,
      "name": "Wood_Deadwood_Ornate"
    },
    {
      "x": 0,
      "y": 13,
      "z": 1,
      "name": "Wood_Deadwood_Ornate"
    },
    {
      "x": 0,
      "y": 14,
      "z": 1,
      "name": "Wood_Deadwood_Ornate"
    },
    {
      "x": 0,
      "y": 15,
      "z": 1,
      "name": "Cloth_Roof_Leather_Flat"
    },
    {
      "x": 0,
      "y": 5,
      "z": 2,
      "name": "Soil_Sand_Ashen"
    },
    {
      "x": 0,
      "y": 6,
      "z": 2,
      "name": "Soil_Sand_Ashen"
    },
    {
      "x": 0,
      "y": 7,
      "z": 2,
      "name": "Soil_Sand_Ashen"
    },
    {
      "x": 0,
      "y": 8,
      "z": 2,
      "name": "Soil_Sand_Ashen"
    },
    {
      "x": 0,
      "y": 9,
      "z": 2,
      "name": "Soil_Sand_Ashen"
    },
    {
      "x": 0,
      "y": 10,
      "z": 2,
      "name": "Soil_Sand_Ashen"
    },
    {
      "x": 0,
      "y": 11,
      "z": 2,
      "name": "Soil_Sand_Ashen"
    },
    {
      "x": 0,
      "y": 12,
      "z": 2,
      "name": "Empty"
    },
    {
      "x": 0,
      "y": 13,
      "z": 2,
      "name": "Empty"
    },
    {
      "x": 0,
      "y": 14,
      "z": 2,
      "name": "Cloth_Roof_Leather"
    },
    {
      "x": 0,
      "y": 5,
      "z": 3,
      "name": "Soil_Sand_Ashen"
    },
    {
      "x": 0,
      "y": 6,
      "z": 3,
      "name": "Soil_Sand_Ashen"
    },
    {
      "x": 0,
      "y": 7,
      "z": 3,
      "name": "Soil_Sand_Ashen"
    },
    {
      "x": 0,
      "y": 8,
      "z": 3,
      "name": "Soil_Sand_Ashen"
    },
    {
      "x": 0,
      "y": 9,
      "z": 3,
      "name": "Soil_Sand_Ashen"
    },
    {
      "x": 0,
      "y": 10,
      "z": 3,
      "name": "Soil_Sand_Ashen"
    },
    {
      "x": 0,
      "y": 11,
      "z": 3,
      "name": "Soil_Sand_Ashen"
    },
    {
      "x": 0,
      "y": 12,
      "z": 3,
      "name": "Empty"
    },
    {
      "x": 0,
      "y": 13,
      "z": 3,
      "name": "Empty"
    },
    {
      "x": 0,
      "y": 14,
      "z": 3,
      "name": "Cloth_Roof_Leather_Flat"
    },
    {
      "x": 0,
      "y": 5,
      "z": 4,
      "name": "Soil_Sand_Ashen"
    },
    {
      "x": 0,
      "y": 6,
      "z": 4,
      "name": "Soil_Sand_Ashen"
    },
    {
      "x": 0,
      "y": 7,
      "z": 4,
      "name": "Soil_Sand_Ashen"
    },
    {
      "x": 0,
      "y": 8,
      "z": 4,
      "name": "Soil_Sand_Ashen"
    },
    {
      "x": 0,
      "y": 9,
      "z": 4,
      "name": "Soil_Sand_Ashen"
    },
    {
      "x": 0,
      "y": 10,
      "z": 4,
      "name": "Soil_Sand_Ashen"
    },
    {
      "x": 0,
      "y": 11,
      "z": 4,
      "name": "Soil_Sand_Ashen"
    },
    {
      "x": 0,
      "y": 12,
      "z": 4,
      "name": "Wood_Deadwood_Beam"
    },
    {
      "x": 0,
      "y": 13,
      "z": 4,
      "name": "Wood_Deadwood_Beam"
    },
    {
      "x": 0,
      "y": 14,
      "z": 4,
      "name": "Cloth_Roof_Leather_Flat"
    },
    {
      "x": 0,
      "y": 13,
      "z": 5,
      "name": "Cloth_Roof_Leather_Flap"
    },
    {
      "x": 1,
      "y": 14,
      "z": 0,
      "name": "Cloth_Roof_Leather_Vertical",
      "rotation": 2
    },
    {
      "x": 1,
      "y": 5,
      "z": 1,
      "name": "Soil_Sand_Ashen"
    },
    {
      "x": 1,
      "y": 6,
      "z": 1,
      "name": "Soil_Sand_Ashen"
    },
    {
      "x": 1,
      "y": 7,
      "z": 1,
      "name": "Soil_Sand_Ashen"
    },
    {
      "x": 1,
      "y": 8,
      "z": 1,
      "name": "Soil_Sand_Ashen"
    },
    {
      "x": 1,
      "y": 9,
      "z": 1,
      "name": "Soil_Sand_Ashen"
    },
    {
      "x": 1,
      "y": 10,
      "z": 1,
      "name": "Soil_Sand_Ashen"
    },
    {
      "x": 1,
      "y": 11,
      "z": 1,
      "name": "Soil_Sand_Ashen"
    },
    {
      "x": 1,
      "y": 12,
      "z": 1,
      "name": "Wood_Deadwood_Planks"
    },
    {
      "x": 1,
      "y": 13,
      "z": 1,
      "name": "Wood_Deadwood_Planks"
    },
    {
      "x": 1,
      "y": 14,
      "z": 1,
      "name": "Wood_Deadwood_Planks"
    },
    {
      "x": 1,
      "y": 15,
      "z": 1,
      "name": "Cloth_Roof_Leather_Flat"
    },
    {
      "x": 1,
      "y": 5,
      "z": 2,
      "name": "Soil_Sand_Ashen"
    },
    {
      "x": 1,
      "y": 6,
      "z": 2,
      "name": "Soil_Sand_Ashen"
    },
    {
      "x": 1,
      "y": 7,
      "z": 2,
      "name": "Soil_Sand_Ashen"
    },
    {
      "x": 1,
      "y": 8,
      "z": 2,
      "name": "Soil_Sand_Ashen"
    },
    {
      "x": 1,
      "y": 9,
      "z": 2,
      "name": "Soil_Sand_Ashen"
    },
    {
      "x": 1,
      "y": 10,
      "z": 2,
      "name": "Soil_Sand_Ashen"
    },
    {
      "x": 1,
      "y": 11,
      "z": 2,
      "name": "Soil_Sand_Ashen"
    },
    {
      "x": 1,
      "y": 12,
      "z": 2,
      "name": "Empty"
    },
    {
      "x": 1,
      "y": 13,
      "z": 2,
      "name": "Empty"
    },
    {
      "x": 1,
      "y": 14,
      "z": 2,
      "name": "Cloth_Roof_Leather"
    },
    {
      "x": 1,
      "y": 5,
      "z": 3,
      "name": "Soil_Sand_Ashen"
    },
    {
      "x": 1,
      "y": 6,
      "z": 3,
      "name": "Soil_Sand_Ashen"
    },
    {
      "x": 1,
      "y": 7,
      "z": 3,
      "name": "Soil_Sand_Ashen"
    },
    {
      "x": 1,
      "y": 8,
      "z": 3,
      "name": "Soil_Sand_Ashen"
    },
    {
      "x": 1,
      "y": 9,
      "z": 3,
      "name": "Soil_Sand_Ashen"
    },
    {
      "x": 1,
      "y": 10,
      "z": 3,
      "name": "Soil_Sand_Ashen"
    },
    {
      "x": 1,
      "y": 11,
      "z": 3,
      "name": "Soil_Sand_Ashen"
    },
    {
      "x": 1,
      "y": 12,
      "z": 3,
      "name": "Furniture_Ancient_Chair"
    },
    {
      "x": 1,
      "y": 13,
      "z": 3,
      "name": "Empty"
    },
    {
      "x": 1,
      "y": 14,
      "z": 3,
      "name": "Cloth_Roof_Leather_Flat"
    },
    {
      "x": 1,
      "y": 5,
      "z": 4,
      "name": "Soil_Sand_Ashen"
    },
    {
      "x": 1,
      "y": 6,
      "z": 4,
      "name": "Soil_Sand_Ashen"
    },
    {
      "x": 1,
      "y": 7,
      "z": 4,
      "name": "Soil_Sand_Ashen"
    },
    {
      "x": 1,
      "y": 8,
      "z": 4,
      "name": "Soil_Sand_Ashen"
    },
    {
      "x": 1,
      "y": 9,
      "z": 4,
      "name": "Soil_Sand_Ashen"
    },
    {
      "x": 1,
      "y": 10,
      "z": 4,
      "name": "Soil_Sand_Ashen"
    },
    {
      "x": 1,
      "y": 11,
      "z": 4,
      "name": "Soil_Sand_Ashen"
    },
    {
      "x": 1,
      "y": 12,
      "z": 4,
      "name": "Furniture_Human_Ruins_Desk",
      "filler": 31
    },
    {
      "x": 1,
      "y": 13,
      "z": 4,
      "name": "Empty"
    },
    {
      "x": 1,
      "y": 14,
      "z": 4,
      "name": "Cloth_Roof_Leather_Flat"
    },
    {
      "x": 2,
      "y": 14,
      "z": 0,
      "name": "Cloth_Roof_Leather_Vertical",
      "rotation": 2
    },
    {
      "x": 2,
      "y": 5,
      "z": 1,
      "name": "Soil_Sand_Ashen"
    },
    {
      "x": 2,
      "y": 6,
      "z": 1,
      "name": "Soil_Sand_Ashen"
    },
    {
      "x": 2,
      "y": 7,
      "z": 1,
      "name": "Soil_Sand_Ashen"
    },
    {
      "x": 2,
      "y": 8,
      "z": 1,
      "name": "Soil_Sand_Ashen"
    },
    {
      "x": 2,
      "y": 9,
      "z": 1,
      "name": "Soil_Sand_Ashen"
    },
    {
      "x": 2,
      "y": 10,
      "z": 1,
      "name": "Soil_Sand_Ashen"
    },
    {
      "x": 2,
      "y": 11,
      "z": 1,
      "name": "Soil_Sand_Ashen"
    },
    {
      "x": 2,
      "y": 12,
      "z": 1,
      "name": "Wood_Deadwood_Planks"
    },
    {
      "x": 2,
      "y": 13,
      "z": 1,
      "name": "Wood_Deadwood_Planks"
    },
    {
      "x": 2,
      "y": 14,
      "z": 1,
      "name": "Wood_Deadwood_Planks"
    },
    {
      "x": 2,
      "y": 15,
      "z": 1,
      "name": "Cloth_Roof_Leather_Flat"
    },
    {
      "x": 2,
      "y": 5,
      "z": 2,
      "name": "Soil_Sand_Ashen"
    },
    {
      "x": 2,
      "y": 6,
      "z": 2,
      "name": "Soil_Sand_Ashen"
    },
    {
      "x": 2,
      "y": 7,
      "z": 2,
      "name": "Soil_Sand_Ashen"
    },
    {
      "x": 2,
      "y": 8,
      "z": 2,
      "name": "Soil_Sand_Ashen"
    },
    {
      "x": 2,
      "y": 9,
      "z": 2,
      "name": "Soil_Sand_Ashen"
    },
    {
      "x": 2,
      "y": 10,
      "z": 2,
      "name": "Soil_Sand_Ashen"
    },
    {
      "x": 2,
      "y": 11,
      "z": 2,
      "name": "Soil_Sand_Ashen"
    },
    {
      "x": 2,
      "y": 12,
      "z": 2,
      "name": "Empty"
    },
    {
      "x": 2,
      "y": 13,
      "z": 2,
      "name": "Empty"
    },
    {
      "x": 2,
      "y": 14,
      "z": 2,
      "name": "Cloth_Roof_Leather"
    },
    {
      "x": 2,
      "y": 5,
      "z": 3,
      "name": "Soil_Sand_Ashen"
    },
    {
      "x": 2,
      "y": 6,
      "z": 3,
      "name": "Soil_Sand_Ashen"
    },
    {
      "x": 2,
      "y": 7,
      "z": 3,
      "name": "Soil_Sand_Ashen"
    },
    {
      "x": 2,
      "y": 8,
      "z": 3,
      "name": "Soil_Sand_Ashen"
    },
    {
      "x": 2,
      "y": 9,
      "z": 3,
      "name": "Soil_Sand_Ashen"
    },
    {
      "x": 2,
      "y": 10,
      "z": 3,
      "name": "Soil_Sand_Ashen"
    },
    {
      "x": 2,
      "y": 11,
      "z": 3,
      "name": "Soil_Sand_Ashen"
    },
    {
      "x": 2,
      "y": 12,
      "z": 3,
      "name": "Empty"
    },
    {
      "x": 2,
      "y": 13,
      "z": 3,
      "name": "Empty"
    },
    {
      "x": 2,
      "y": 14,
      "z": 3,
      "name": "Cloth_Roof_Leather_Flat"
    },
    {
      "x": 2,
      "y": 5,
      "z": 4,
      "name": "Soil_Sand_Ashen"
    },
    {
      "x": 2,
      "y": 6,
      "z": 4,
      "name": "Soil_Sand_Ashen"
    },
    {
      "x": 2,
      "y": 7,
      "z": 4,
      "name": "Soil_Sand_Ashen"
    },
    {
      "x": 2,
      "y": 8,
      "z": 4,
      "name": "Soil_Sand_Ashen"
    },
    {
      "x": 2,
      "y": 9,
      "z": 4,
      "name": "Soil_Sand_Ashen"
    },
    {
      "x": 2,
      "y": 10,
      "z": 4,
      "name": "Soil_Sand_Ashen"
    },
    {
      "x": 2,
      "y": 11,
      "z": 4,
      "name": "Soil_Sand_Ashen"
    },
    {
      "x": 2,
      "y": 12,
      "z": 4,
      "name": "Furniture_Human_Ruins_Desk"
    },
    {
      "x": 2,
      "y": 13,
      "z": 4,
      "name": "Empty"
    },
    {
      "x": 2,
      "y": 14,
      "z": 4,
      "name": "Cloth_Roof_Leather_Flat"
    },
    {
      "x": 3,
      "y": 14,
      "z": 0,
      "name": "Cloth_Roof_Leather_Flap",
      "rotation": 2
    },
    {
      "x": 3,
      "y": 5,
      "z": 1,
      "name": "Soil_Sand_Ashen"
    },
    {
      "x": 3,
      "y": 6,
      "z": 1,
      "name": "Soil_Sand_Ashen"
    },
    {
      "x": 3,
      "y": 7,
      "z": 1,
      "name": "Soil_Sand_Ashen"
    },
    {
      "x": 3,
      "y": 8,
      "z": 1,
      "name": "Soil_Sand_Ashen"
    },
    {
      "x": 3,
      "y": 9,
      "z": 1,
      "name": "Soil_Sand_Ashen"
    },
    {
      "x": 3,
      "y": 10,
      "z": 1,
      "name": "Soil_Sand_Ashen"
    },
    {
      "x": 3,
      "y": 11,
      "z": 1,
      "name": "Soil_Sand_Ashen"
    },
    {
      "x": 3,
      "y": 12,
      "z": 1,
      "name": "Wood_Deadwood_Ornate"
    },
    {
      "x": 3,
      "y": 13,
      "z": 1,
      "name": "Wood_Deadwood_Ornate"
    },
    {
      "x": 3,
      "y": 14,
      "z": 1,
      "name": "Wood_Deadwood_Ornate"
    },
    {
      "x": 3,
      "y": 15,
      "z": 1,
      "name": "Cloth_Roof_Leather_Flat"
    },
    {
      "x": 3,
      "y": 5,
      "z": 2,
      "name": "Soil_Sand_Ashen"
    },
    {
      "x": 3,
      "y": 6,
      "z": 2,
      "name": "Soil_Sand_Ashen"
    },
    {
      "x": 3,
      "y": 7,
      "z": 2,
      "name": "Soil_Sand_Ashen"
    },
    {
      "x": 3,
      "y": 8,
      "z": 2,
      "name": "Soil_Sand_Ashen"
    },
    {
      "x": 3,
      "y": 9,
      "z": 2,
      "name": "Soil_Sand_Ashen"
    },
    {
      "x": 3,
      "y": 10,
      "z": 2,
      "name": "Soil_Sand_Ashen"
    },
    {
      "x": 3,
      "y": 11,
      "z": 2,
      "name": "Soil_Sand_Ashen"
    },
    {
      "x": 3,
      "y": 12,
      "z": 2,
      "name": "Furniture_Ancient_Barrel"
    },
    {
      "x": 3,
      "y": 13,
      "z": 2,
      "name": "Empty"
    },
    {
      "x": 3,
      "y": 14,
      "z": 2,
      "name": "Cloth_Roof_Leather"
    },
    {
      "x": 3,
      "y": 5,
      "z": 3,
      "name": "Soil_Sand_Ashen"
    },
    {
      "x": 3,
      "y": 6,
      "z": 3,
      "name": "Soil_Sand_Ashen"
    },
    {
      "x": 3,
      "y": 7,
      "z": 3,
      "name": "Soil_Sand_Ashen"
    },
    {
      "x": 3,
      "y": 8,
      "z": 3,
      "name": "Soil_Sand_Ashen"
    },
    {
      "x": 3,
      "y": 9,
      "z": 3,
      "name": "Soil_Sand_Ashen"
    },
    {
      "x": 3,
      "y": 10,
      "z": 3,
      "name": "Soil_Sand_Ashen"
    },
    {
      "x": 3,
      "y": 11,
      "z": 3,
      "name": "Soil_Sand_Ashen"
    },
    {
      "x": 3,
      "y": 12,
      "z": 3,
      "name": "Empty"
    },
    {
      "x": 3,
      "y": 13,
      "z": 3,
      "name": "Empty"
    },
    {
      "x": 3,
      "y": 14,
      "z": 3,
      "name": "Cloth_Roof_Leather_Flat"
    },
    {
      "x": 3,
      "y": 5,
      "z": 4,
      "name": "Soil_Sand_Ashen"
    },
    {
      "x": 3,
      "y": 6,
      "z": 4,
      "name": "Soil_Sand_Ashen"
    },
    {
      "x": 3,
      "y": 7,
      "z": 4,
      "name": "Soil_Sand_Ashen"
    },
    {
      "x": 3,
      "y": 8,
      "z": 4,
      "name": "Soil_Sand_Ashen"
    },
    {
      "x": 3,
      "y": 9,
      "z": 4,
      "name": "Soil_Sand_Ashen"
    },
    {
      "x": 3,
      "y": 10,
      "z": 4,
      "name": "Soil_Sand_Ashen"
    },
    {
      "x": 3,
      "y": 11,
      "z": 4,
      "name": "Soil_Sand_Ashen"
    },
    {
      "x": 3,
      "y": 12,
      "z": 4,
      "name": "Wood_Deadwood_Beam"
    },
    {
      "x": 3,
      "y": 13,
      "z": 4,
      "name": "Wood_Deadwood_Beam"
    },
    {
      "x": 3,
      "y": 14,
      "z": 4,
      "name": "Cloth_Roof_Leather_Flat"
    },
    {
      "x": 3,
      "y": 13,
      "z": 5,
      "name": "Cloth_Roof_Leather_Flap"
    },
    {
      "x": 4,
      "y": 14,
      "z": 1,
      "name": "Cloth_Roof_Leather_Flap",
      "rotation": 1
    },
    {
      "x": 4,
      "y": 13,
      "z": 3,
      "name": "Cloth_Roof_Leather_Flap",
      "rotation": 1
    },
    {
      "x": 4,
      "y": 12,
      "z": 4,
      "name": "Cloth_Roof_Leather_Vertical",
      "rotation": 1
    },
    {
      "x": 4,
      "y": 13,
      "z": 4,
      "name": "Cloth_Roof_Leather_Vertical",
      "rotation": 1
    }
  ]
}