{
  "version": 8,
  "blockIdVersion": 8,
  "anchorX": 0,
  "anchorY": 0,
  "anchorZ": 0,
  "blocks": [
    {
      "x": -11,
      "y": 0,
      "z": -22,
      "name": "Rock_Stone"
    },
    {
      "x": -11,
      "y": 1,
      "z": -22,
      "name": "Rock_Stone"
    },
    {
      "x": -11,
      "y": 2,
      "z": -22,
      "name": "Rock_Stone"
    },
    {
      "x": -11,
      "y": 3,
      "z": -22,
      "name": "Rock_Stone"
    },
    {
      "x": -11,
      "y": 4,
      "z": -22,
      "name": "Rock_Stone"
    },
    {
      "x": -11,
      "y": 5,
      "z": -22,
      "name": "Rock_Stone"
    },
    {
      "x": -11,
      "y": 6,
      "z": -22,
      "name": "Rock_Stone"
    },
    {
      "x": -11,
      "y": 7,
      "z": -22,
      "name": "Rock_Stone"
    },
    {
      "x": -11,
      "y": 8,
      "z": -22,
      "name": "Rock_Stone"
    },
    {
      "x": -11,
      "y": 9,
      "z": -22,
      "name": "Rock_Stone"
    },
    {
      "x": -11,
      "y": 10,
      "z": -22,
      "name": "Rock_Stone"
    },
    {
      "x": -11,
      "y": 11,
      "z": -22,
      "name": "Rock_Stone"
    },
    {
      "x": -11,
      "y": 12,
      "z": -22,
      "name": "Rock_Stone"
    },
    {
      "x": -11,
      "y": 0,
      "z": -21,
      "name": "Rock_Stone"
    },
    {
      "x": -11,
      "y": 1,
      "z": -21,
      "name": "Rock_Stone"
    },
    {
      "x": -11,
      "y": 2,
      "z": -21,
      "name": "Rock_Stone"
    },
    {
      "x": -11,
      "y": 3,
      "z": -21,
      "name": "Rock_Stone"
    },
    {
      "x": -11,
      "y": 4,
      "z": -21,
      "name": "Rock_Stone"
    },
    {
      "x": -11,
      "y": 5,
      "z": -21,
      "name": "Rock_Stone"
    },
    {
      "x": -11,
      "y": 6,
      "z": -21,
      "name": "Rock_Stone"
    },
    {
      "x": -11,
      "y": 7,
      "z": -21,
      "name": "Rock_Stone"
    },
    {
      "x": -11,
      "y": 8,
      "z": -21,
      "name": "Rock_Stone"
    },
    {
      "x": -11,
      "y": 9,
      "z": -21,
      "name": "Rock_Stone"
    },
    {
      "x": -11,
      "y": 10,
      "z": -21,
      "name": "Rock_Stone"
    },
    {
      "x": -11,
      "y": 11,
      "z": -21,
      "name": "Rock_Stone"
    },
    {
      "x": -11,
      "y": 12,
      "z": -21,
      "name": "Rock_Stone"
    },
    {
      "x": -11,
      "y": 0,
      "z": -20,
      "name": "Rock_Stone"
    },
    {
      "x": -11,
      "y": 1,
      "z": -20,
      "name": "Rock_Stone"
    },
    {
      "x": -11,
      "y": 2,
      "z": -20,
      "name": "Rock_Stone"
    },
    {
      "x": -11,
      "y": 3,
      "z": -20,
      "name": "Rock_Stone"
    },
    {
      "x": -11,
      "y": 4,
      "z": -20,
      "name": "Rock_Stone"
    },
    {
      "x": -11,
      "y": 5,
      "z": -20,
      "name": "Rock_Stone"
    },
    {
      "x": -11,
      "y": 6,
      "z": -20,
      "name": "Rock_Stone"
    },
    {
      "x": -11,
      "y": 7,
      "z": -20,
      "name": "Rock_Stone"
    },
    {
      "x": -11,
      "y": 8,
      "z": -20,
      "name": "Rock_Stone"
    },
    {
      "x": -11,
      "y": 9,
      "z": -20,
      "name": "Rock_Stone"
    },
    {
      "x": -11,
      "y": 10,
      "z": -20,
      "name": "Rock_Stone"
    },
    {
      "x": -11,
      "y": 11,
      "z": -20,
      "name": "Rock_Stone"
    },
    {
      "x": -11,
      "y": 12,
      "z": -20,
      "name": "Rock_Stone"
    },
    {
      "x": -11,
      "y": 0,
      "z": -19,
      "name": "Rock_Stone"
    },
    {
      "x": -11,
      "y": 1,
      "z": -19,
      "name": "Rock_Stone"
    },
    {
      "x": -11,
      "y": 2,
      "z": -19,
      "name": "Rock_Stone"
    },
    {
      "x": -11,
      "y": 3,
      "z": -19,
      "name": "Rock_Stone"
    },
    {
      "x": -11,
      "y": 4,
      "z": -19,
      "name": "Rock_Stone"
    },
    {
      "x": -11,
      "y": 5,
      "z": -19,
      "name": "Rock_Stone"
    },
    {
      "x": -11,
      "y": 6,
      "z": -19,
      "name": "Rock_Stone"
    },
    {
      "x": -11,
      "y": 7,
      "z": -19,
      "name": "Rock_Stone"
    },
    {
      "x": -11,
      "y": 8,
      "z": -19,
      "name": "Rock_Stone"
    },
    {
      "x": -11,
      "y": 9,
      "z": -19,
      "name": "Rock_Stone"
    },
    {
      "x": -11,
      "y": 10,
      "z": -19,
      "name": "Rock_Stone"
    },
    {
      "x": -11,
      "y": 11,
      "z": -19,
      "name": "Rock_Stone"
    },
    {
      "x": -11,
      "y": 12,
      "z": -19,
      "name": "Rock_Stone"
    },
    {
      "x": -11,
      "y": 0,
      "z": -18,
      "name": "Rock_Stone"
    },
    {
      "x": -11,
      "y": 1,
      "z": -18,
      "name": "Rock_Stone"
    },
    {
      "x": -11,
      "y": 2,
      "z": -18,
      "name": "Rock_Stone"
    },
    {
      "x": -11,
      "y": 3,
      "z": -18,
      "name": "Rock_Stone"
    },
    {
      "x": -11,
      "y": 4,
      "z": -18,
      "name": "Rock_Stone"
    },
    {
      "x": -11,
      "y": 5,
      "z": -18,
      "name": "Rock_Stone"
    },
    {
      "x": -11,
      "y": 6,
      "z": -18,
      "name": "Rock_Stone"
    },
    {
      "x": -11,
      "y": 7,
      "z": -18,
      "name": "Rock_Stone"
    },
    {
      "x": -11,
      "y": 8,
      "z": -18,
      "name": "Rock_Stone"
    },
    {
      "x": -11,
      "y": 9,
      "z": -18,
      "name": "Rock_Stone"
    },
    {
      "x": -11,
      "y": 10,
      "z": -18,
      "name": "Rock_Stone"
    },
    {
      "x": -11,
      "y": 11,
      "z": -18,
      "name": "Rock_Stone"
    },
    {
      "x": -11,
      "y": 12,
      "z": -18,
      "name": "Rock_Stone"
    },
    {
      "x": -11,
      "y": 0,
      "z": -17,
      "name": "Rock_Stone"
    },
    {
      "x": -11,
      "y": 1,
      "z": -17,
      "name": "Rock_Stone"
    },
    {
      "x": -11,
      "y": 2,
      "z": -17,
      "name": "Rock_Stone"
    },
    {
      "x": -11,
      "y": 3,
      "z": -17,
      "name": "Rock_Stone"
    },
    {
      "x": -11,
      "y": 4,
      "z": -17,
      "name": "Rock_Stone"
    },
    {
      "x": -11,
      "y": 5,
      "z": -17,
      "name": "Rock_Stone"
    },
    {
      "x": -11,
      "y": 6,
      "z": -17,
      "name": "Rock_Stone"
    },
    {
      "x": -11,
      "y": 7,
      "z": -17,
      "name": "Rock_Stone"
    },
    {
      "x": -11,
      "y": 8,
      "z": -17,
      "name": "Rock_Stone"
    },
    {
      "x": -11,
      "y": 9,
      "z": -17,
      "name": "Rock_Stone"
    },
    {
      "x": -11,
      "y": 10,
      "z": -17,
      "name": "Rock_Stone"
    },
    {
      "x": -11,
      "y": 11,
      "z": -17,
      "name": "Rock_Stone"
    },
    {
      "x": -11,
      "y": 12,
      "z": -17,
      "name": "Rock_Stone"
    },
    {
      "x": -11,
      "y": 0,
      "z": -16,
      "name": "Rock_Stone"
    },
    {
      "x": -11,
      "y": 1,
      "z": -16,
      "name": "Rock_Stone"
    },
    {
      "x": -11,
      "y": 2,
      "z": -16,
      "name": "Rock_Stone"
    },
    {
      "x": -11,
      "y": 3,
      "z": -16,
      "name": "Rock_Stone"
    },
    {
      "x": -11,
      "y": 4,
      "z": -16,
      "name": "Rock_Stone"
    },
    {
      "x": -11,
      "y": 5,
      "z": -16,
      "name": "Rock_Stone"
    },
    {
      "x": -11,
      "y": 6,
      "z": -16,
      "name": "Rock_Stone"
    },
    {
      "x": -11,
      "y": 7,
      "z": -16,
      "name": "Rock_Stone"
    },
    {
      "x": -11,
      "y": 8,
      "z": -16,
      "name": "Rock_Stone"
    },
    {
      "x": -11,
      "y": 9,
      "z": -16,
      "name": "Rock_Stone"
    },
    {
      "x": -11,
      "y": 10,
      "z": -16,
      "name": "Rock_Stone"
    },
    {
      "x": -11,
      "y": 11,
      "z": -16,
      "name": "Rock_Stone"
    },
    {
      "x": -11,
      "y": 12,
      "z": -16,
      "name": "Rock_Stone"
    },
    {
      "x": -11,
      "y": 0,
      "z": -15,
      "name": "Rock_Stone"
    },
    {
      "x": -11,
      "y": 1,
      "z": -15,
      "name": "Rock_Stone"
    },
    {
      "x": -11,
      "y": 2,
      "z": -15,
      "name": "Rock_Stone"
    },
    {
      "x": -11,
      "y": 3,
      "z": -15,
      "name": "Rock_Stone"
    },
    {
      "x": -11,
      "y": 4,
      "z": -15,
      "name": "Rock_Stone"
    },
    {
      "x": -11,
      "y": 5,
      "z": -15,
      "name": "Rock_Stone"
    },
    {
      "x": -11,
      "y": 6,
      "z": -15,
      "name": "Rock_Stone"
    },
    {
      "x": -11,
      "y": 7,
      "z": -15,
      "name": "Rock_Stone_Brick_Smooth"
    },
    {
      "x": -11,
      "y": 8,
      "z": -15,
      "name": "Rock_Stone_Brick_Smooth"
    },
    {
      "x": -11,
      "y": 9,
      "z": -15,
      "name": "Rock_Stone_Brick_Smooth"
    },
    {
      "x": -11,
      "y": 10,
      "z": -15,
      "name": "Rock_Stone_Brick_Smooth"
    },
    {
      "x": -11,
      "y": 11,
      "z": -15,
      "name": "Rock_Stone_Brick_Smooth"
    },
    {
      "x": -11,
      "y": 12,
      "z": -15,
      "name": "Rock_Stone"
    },
    {
      "x": -11,
      "y": 0,
      "z": -14,
      "name": "Rock_Stone_Brick"
    },
    {
      "x": -11,
      "y": 1,
      "z": -14,
      "name": "Rock_Stone_Brick_Smooth"
    },
    {
      "x": -11,
      "y": 2,
      "z": -14,
      "name": "Rock_Stone_Brick_Smooth"
    },
    {
      "x": -11,
      "y": 3,
      "z": -14,
      "name": "Rock_Stone_Brick_Smooth"
    },
    {
      "x": -11,
      "y": 4,
      "z": -14,
      "name": "Rock_Stone_Brick_Smooth"
    },
    {
      "x": -11,
      "y": 5,
      "z": -14,
      "name": "Rock_Stone_Brick_Smooth"
    },
    {
      "x": -11,
      "y": 6,
      "z": -14,
      "name": "Rock_Stone_Brick_Smooth"
    },
    {
      "x": -11,
      "y": 7,
      "z": -14,
      "name": "Rock_Stone_Brick_Smooth"
    },
    {
      "x": -11,
      "y": 8,
      "z": -14,
      "name": "Rock_Stone_Brick_Smooth"
    },
    {
      "x": -11,
      "y": 9,
      "z": -14,
      "name": "Rock_Stone_Brick_Smooth"
    },
    {
      "x": -11,
      "y": 10,
      "z": -14,
      "name": "*Rock_Stone_Brick_Smooth_Half_State_Definitions_Block",
      "rotation": 8
    },
    {
      "x": -11,
      "y": 11,
      "z": -14,
      "name": "Rock_Stone_Brick_Smooth"
    },
    {
      "x": -11,
      "y": 12,
      "z": -14,
      "name": "Rock_Stone"
    },
    {
      "x": -11,
      "y": 0,
      "z": -13,
      "name": "Rock_Stone_Brick"
    },
    {
      "x": -11,
      "y": 1,
      "z": -13,
      "name": "Rock_Stone_Brick_Smooth_Half",
      "rotation": 4
    },
    {
      "x": -11,
      "y": 2,
      "z": -13,
      "name": "Rock_Stone_Brick_Smooth_Half",
      "rotation": 4
    },
    {
      "x": -11,
      "y": 3,
      "z": -13,
      "name": "Rock_Stone_Brick_Smooth_Half",
      "rotation": 4
    },
    {
      "x": -11,
      "y": 4,
      "z": -13,
      "name": "Rock_Stone_Brick_Smooth_Half",
      "rotation": 4
    },
    {
      "x": -11,
      "y": 5,
      "z": -13,
      "name": "Rock_Stone_Brick_Smooth"
    },
    {
      "x": -11,
      "y": 6,
      "z": -13,
      "name": "Rock_Stone_Brick_Smooth"
    },
    {
      "x": -11,
      "y": 7,
      "z": -13,
      "name": "*Rock_Stone_Brick_Wall_State_Definitions_Corner",
      "rotation": 1
    },
    {
      "x": -11,
      "y": 8,
      "z": -13,
      "name": "Empty"
    },
    {
      "x": -11,
      "y": 9,
      "z": -13,
      "name": "Empty"
    },
    {
      "x": -11,
      "y": 10,
      "z": -13,
      "name": "Rock_Stone_Brick_Smooth_Half",
      "rotation": 4
    },
    {
      "x": -11,
      "y": 11,
      "z": -13,
      "name": "Rock_Stone_Brick_Smooth"
    },
    {
      "x": -11,
      "y": 12,
      "z": -13,
      "name": "Rock_Stone"
    },
    {
      "x": -11,
      "y": 0,
      "z": -12,
      "name": "Rock_Stone_Brick"
    },
    {
      "x": -11,
      "y": 1,
      "z": -12,
      "name": "Empty"
    },
    {
      "x": -11,
      "y": 2,
      "z": -12,
      "name": "Empty"
    },
    {
      "x": -11,
      "y": 3,
      "z": -12,
      "name": "Empty"
    },
    {
      "x": -11,
      "y": 4,
      "z": -12,
      "name": "Empty"
    },
    {
      "x": -11,
      "y": 5,
      "z": -12,
      "name": "Rock_Stone_Brick_Smooth_Half",
      "rotation": 8
    },
    {
      "x": -11,
      "y": 6,
      "z": -12,
      "name": "Rock_Stone_Brick_Smooth"
    },
    {
      "x": -11,
      "y": 7,
      "z": -12,
      "name": "Rock_Stone_Brick_Wall",
      "rotation": 1
    },
    {
      "x": -11,
      "y": 8,
      "z": -12,
      "name": "Empty"
    },
    {
      "x": -11,
      "y": 9,
      "z": -12,
      "name": "Empty"
    },
    {
      "x": -11,
      "y": 10,
      "z": -12,
      "name": "Empty"
    },
    {
      "x": -11,
      "y": 11,
      "z": -12,
      "name": "Rock_Stone_Brick_Smooth"
    },
    {
      "x": -11,
      "y": 12,
      "z": -12,
      "name": "Rock_Stone"
    },
    {
      "x": -11,
      "y": 0,
      "z": -11,
      "name": "Rock_Stone_Cobble"
    },
    {
      "x": -11,
      "y": 1,
      "z": -11,
      "name": "Empty"
    },
    {
      "x": -11,
      "y": 2,
      "z": -11,
      "name": "Empty"
    },
    {
      "x": -11,
      "y": 3,
      "z": -11,
      "name": "Empty"
    },
    {
      "x": -11,
      "y": 4,
      "z": -11,
      "name": "Empty"
    },
    {
      "x": -11,
      "y": 5,
      "z": -11,
      "name": "Rock_Stone_Brick_Smooth_Half",
      "rotation": 8
    },
    {
      "x": -11,
      "y": 6,
      "z": -11,
      "name": "Rock_Stone_Brick_Smooth"
    },
    {
      "x": -11,
      "y": 7,
      "z": -11,
      "name": "Rock_Stone_Brick_Wall",
      "rotation": 1
    },
    {
      "x": -11,
      "y": 8,
      "z": -11,
      "name": "Empty"
    },
    {
      "x": -11,
      "y": 9,
      "z": -11,
      "name": "Empty"
    },
    {
      "x": -11,
      "y": 10,
      "z": -11,
      "name": "Empty"
    },
    {
      "x": -11,
      "y": 11,
      "z": -11,
      "name": "Rock_Stone_Brick_Smooth_Half",
      "rotation": 8
    },
    {
      "x": -11,
      "y": 12,
      "z": -11,
      "name": "Rock_Stone"
    },
    {
      "x": -11,
      "y": 0,
      "z": -10,
      "name": "Rock_Stone_Cobble"
    },
    {
      "x": -11,
      "y": 1,
      "z": -10,
      "name": "Empty"
    },
    {
      "x": -11,
      "y": 2,
      "z": -10,
      "name": "Empty"
    },
    {
      "x": -11,
      "y": 3,
      "z": -10,
      "name": "Empty"
    },
    {
      "x": -11,
      "y": 4,
      "z": -10,
      "name": "Empty"
    },
    {
      "x": -11,
      "y": 5,
      "z": -10,
      "name": "Rock_Stone_Brick_Smooth_Half",
      "rotation": 8
    },
    {
      "x": -11,
      "y": 6,
      "z": -10,
      "name": "Rock_Stone_Brick_Smooth"
    },
    {
      "x": -11,
      "y": 7,
      "z": -10,
      "name": "Rock_Stone_Brick_Wall",
      "rotation": 1
    },
    {
      "x": -11,
      "y": 8,
      "z": -10,
      "name": "Empty"
    },
    {
      "x": -11,
      "y": 9,
      "z": -10,
      "name": "Empty"
    },
    {
      "x": -11,
      "y": 10,
      "z": -10,
      "name": "Empty"
    },
    {
      "x": -11,
      "y": 11,
      "z": -10,
      "name": "Rock_Stone_Brick_Smooth"
    },
    {
      "x": -11,
      "y": 12,
      "z": -10,
      "name": "Rock_Stone"
    },
    {
      "x": -11,
      "y": 0,
      "z": -9,
      "name": "Rock_Stone_Cobble"
    },
    {
      "x": -11,
      "y": 1,
      "z": -9,
      "name": "Rock_Stone_Brick_Smooth_Half",
      "rotation": 6
    },
    {
      "x": -11,
      "y": 2,
      "z": -9,
      "name": "Rock_Stone_Brick_Smooth_Half",
      "rotation": 6
    },
    {
      "x": -11,
      "y": 3,
      "z": -9,
      "name": "Rock_Stone_Brick_Smooth_Half",
      "rotation": 6
    },
    {
      "x": -11,
      "y": 4,
      "z": -9,
      "name": "Rock_Stone_Brick_Smooth_Half",
      "rotation": 6
    },
    {
      "x": -11,
      "y": 5,
      "z": -9,
      "name": "Rock_Stone_Brick_Smooth"
    },
    {
      "x": -11,
      "y": 6,
      "z": -9,
      "name": "Rock_Stone_Brick_Smooth"
    },
    {
      "x": -11,
      "y": 7,
      "z": -9,
      "name": "*Rock_Stone_Brick_Wall_State_Definitions_Corner",
      "rotation": 2
    },
    {
      "x": -11,
      "y": 8,
      "z": -9,
      "name": "Empty"
    },
    {
      "x": -11,
      "y": 9,
      "z": -9,
      "name": "Empty"
    },
    {
      "x": -11,
      "y": 10,
      "z": -9,
      "name": "Rock_Stone_Brick_Smooth_Half",
      "rotation": 6
    },
    {
      "x": -11,
      "y": 11,
      "z": -9,
      "name": "Rock_Stone_Brick_Smooth"
    },
    {
      "x": -11,
      "y": 12,
      "z": -9,
      "name": "Rock_Stone"
    },
    {
      "x": -11,
      "y": 0,
      "z": -8,
      "name": "Rock_Stone_Cobble"
    },
    {
      "x": -11,
      "y": 1,
      "z": -8,
      "name": "Rock_Stone_Brick_Smooth"
    },
    {
      "x": -11,
      "y": 2,
      "z": -8,
      "name": "Rock_Stone_Brick_Smooth"
    },
    {
      "x": -11,
      "y": 3,
      "z": -8,
      "name": "Rock_Stone_Brick_Smooth"
    },
    {
      "x": -11,
      "y": 4,
      "z": -8,
      "name": "Rock_Stone_Brick_Smooth"
    },
    {
      "x": -11,
      "y": 5,
      "z": -8,
      "name": "Rock_Stone_Brick_Smooth"
    },
    {
      "x": -11,
      "y": 6,
      "z": -8,
      "name": "Rock_Stone_Brick_Smooth"
    },
    {
      "x": -11,
      "y": 7,
      "z": -8,
      "name": "Rock_Stone_Brick_Smooth"
    },
    {
      "x": -11,
      "y": 8,
      "z": -8,
      "name": "Rock_Stone_Brick_Smooth"
    },
    {
      "x": -11,
      "y": 9,
      "z": -8,
      "name": "Rock_Stone_Brick_Smooth"
    },
    {
      "x": -11,
      "y": 10,
      "z": -8,
      "name": "*Rock_Stone_Brick_Smooth_Half_State_Definitions_Block",
      "rotation": 8
    },
    {
      "x": -11,
      "y": 11,
      "z": -8,
      "name": "Rock_Stone_Brick_Smooth"
    },
    {
      "x": -11,
      "y": 12,
      "z": -8,
      "name": "Rock_Stone"
    },
    {
      "x": -11,
      "y": 0,
      "z": -7,
      "name": "Rock_Stone_Cobble"
    },
    {
      "x": -11,
      "y": 1,
      "z": -7,
      "name": "Rock_Stone_Brick_Smooth"
    },
    {
      "x": -11,
      "y": 2,
      "z": -7,
      "name": "Rock_Stone_Brick_Smooth"
    },
    {
      "x": -11,
      "y": 3,
      "z": -7,
      "name": "Rock_Stone_Brick_Smooth"
    },
    {
      "x": -11,
      "y": 4,
      "z": -7,
      "name": "Rock_Stone_Brick_Smooth"
    },
    {
      "x": -11,
      "y": 5,
      "z": -7,
      "name": "Rock_Stone_Brick_Smooth"
    },
    {
      "x": -11,
      "y": 6,
      "z": -7,
      "name": "Rock_Stone_Brick_Smooth"
    },
    {
      "x": -11,
      "y": 7,
      "z": -7,
      "name": "Rock_Stone_Brick_Smooth"
    },
    {
      "x": -11,
      "y": 8,
      "z": -7,
      "name": "Rock_Stone_Brick_Smooth"
    },
    {
      "x": -11,
      "y": 9,
      "z": -7,
      "name": "Rock_Stone_Brick_Smooth"
    },
    {
      "x": -11,
      "y": 10,
      "z": -7,
      "name": "Rock_Stone_Brick_Smooth"
    },
    {
      "x": -11,
      "y": 11,
      "z": -7,
      "name": "Rock_Stone_Brick_Smooth"
    },
    {
      "x": -11,
      "y": 12,
      "z": -7,
      "name": "Rock_Stone"
    },
    {
      "x": -11,
      "y": 0,
      "z": -6,
      "name": "Rock_Stone_Cobble"
    },
    {
      "x": -11,
      "y": 1,
      "z": -6,
      "name": "Rock_Stone_Brick_Smooth"
    },
    {
      "x": -11,
      "y": 2,
      "z": -6,
      "name": "Rock_Stone_Brick_Smooth"
    },
    {
      "x": -11,
      "y": 3,
      "z": -6,
      "name": "Rock_Stone_Brick_Smooth"
    },
    {
      "x": -11,
      "y": 4,
      "z": -6,
      "name": "Rock_Stone_Brick_Smooth"
    },
    {
      "x": -11,
      "y": 5,
      "z": -6,
      "name": "Rock_Stone_Brick_Smooth"
    },
    {
      "x": -11,
      "y": 6,
      "z": -6,
      "name": "Rock_Stone_Brick_Smooth"
    },
    {
      "x": -11,
      "y": 7,
      "z": -6,
      "name": "Rock_Stone_Brick_Smooth"
    },
    {
      "x": -11,
      "y": 8,
      "z": -6,
      "name": "Rock_Stone_Brick_Smooth"
    },
    {
      "x": -11,
      "y": 9,
      "z": -6,
      "name": "Rock_Stone_Brick_Smooth"
    },
    {
      "x": -11,
      "y": 10,
      "z": -6,
      "name": "Rock_Stone_Brick_Smooth"
    },
    {
      "x": -11,
      "y": 11,
      "z": -6,
      "name": "Rock_Stone_Brick_Smooth"
    },
    {
      "x": -11,
      "y": 12,
      "z": -6,
      "name": "Rock_Stone"
    },
    {
      "x": -11,
      "y": 0,
      "z": -5,
      "name": "Rock_Stone_Cobble"
    },
    {
      "x": -11,
      "y": 1,
      "z": -5,
      "name": "Rock_Stone_Brick_Smooth"
    },
    {
      "x": -11,
      "y": 2,
      "z": -5,
      "name": "Rock_Stone_Brick_Smooth"
    },
    {
      "x": -11,
      "y": 3,
      "z": -5,
      "name": "Rock_Stone_Brick_Smooth"
    },
    {
      "x": -11,
      "y": 4,
      "z": -5,
      "name": "Rock_Stone_Brick_Smooth"
    },
    {
      "x": -11,
      "y": 5,
      "z": -5,
      "name": "Rock_Stone_Brick_Smooth"
    },
    {
      "x": -11,
      "y": 6,
      "z": -5,
      "name": "Rock_Stone_Brick_Smooth"
    },
    {
      "x": -11,
      "y": 7,
      "z": -5,
      "name": "Rock_Stone_Brick_Smooth"
    },
    {
      "x": -11,
      "y": 8,
      "z": -5,
      "name": "Rock_Stone_Brick_Smooth"
    },
    {
      "x": -11,
      "y": 9,
      "z": -5,
      "name": "Rock_Stone_Brick_Smooth"
    },
    {
      "x": -11,
      "y": 10,
      "z": -5,
      "name": "Rock_Stone_Brick_Smooth"
    },
    {
      "x": -11,
      "y": 11,
      "z": -5,
      "name": "Rock_Stone_Brick_Smooth"
    },
    {
      "x": -11,
      "y": 12,
      "z": -5,
      "name": "Rock_Stone"
    },
    {
      "x": -11,
      "y": 0,
      "z": -4,
      "name": "Rock_Stone_Cobble"
    },
    {
      "x": -11,
      "y": 1,
      "z": -4,
      "name": "Rock_Stone_Brick_Smooth"
    },
    {
      "x": -11,
      "y": 2,
      "z": -4,
      "name": "Rock_Stone_Brick_Smooth"
    },
    {
      "x": -11,
      "y": 3,
      "z": -4,
      "name": "Rock_Stone_Brick_Smooth"
    },
    {
      "x": -11,
      "y": 4,
      "z": -4,
      "name": "Rock_Stone_Brick_Smooth"
    },
    {
      "x": -11,
      "y": 5,
      "z": -4,
      "name": "Rock_Stone_Brick_Smooth"
    },
    {
      "x": -11,
      "y": 6,
      "z": -4,
      "name": "Rock_Stone_Brick_Smooth"
    },
    {
      "x": -11,
      "y": 7,
      "z": -4,
      "name": "Rock_Stone_Brick_Smooth"
    },
    {
      "x": -11,
      "y": 8,
      "z": -4,
      "name": "Rock_Stone_Brick_Smooth"
    },
    {
      "x": -11,
      "y": 9,
      "z": -4,
      "name": "Rock_Stone_Brick_Smooth"
    },
    {
      "x": -11,
      "y": 10,
      "z": -4,
      "name": "Rock_Stone_Brick_Smooth"
    },
    {
      "x": -11,
      "y": 11,
      "z": -4,
      "name": "Rock_Stone_Brick_Smooth"
    },
    {
      "x": -11,
      "y": 12,
      "z": -4,
      "name": "Rock_Stone"
    },
    {
      "x": -11,
      "y": 0,
      "z": -3,
      "name": "Rock_Stone_Cobble"
    },
    {
      "x": -11,
      "y": 1,
      "z": -3,
      "name": "Rock_Stone_Brick_Smooth"
    },
    {
      "x": -11,
      "y": 2,
      "z": -3,
      "name": "Rock_Stone_Brick_Smooth"
    },
    {
      "x": -11,
      "y": 3,
      "z": -3,
      "name": "Rock_Stone_Brick_Smooth"
    },
    {
      "x": -11,
      "y": 4,
      "z": -3,
      "name": "Rock_Stone_Brick_Smooth"
    },
    {
      "x": -11,
      "y": 5,
      "z": -3,
      "name": "Rock_Stone_Brick_Smooth"
    },
    {
      "x": -11,
      "y": 6,
      "z": -3,
      "name": "Rock_Stone_Brick_Smooth"
    },
    {
      "x": -11,
      "y": 7,
      "z": -3,
      "name": "Rock_Stone_Brick_Smooth"
    },
    {
      "x": -11,
      "y": 8,
      "z": -3,
      "name": "Rock_Stone_Brick_Smooth"
    },
    {
      "x": -11,
      "y": 9,
      "z": -3,
      "name": "Rock_Stone_Brick_Smooth"
    },
    {
      "x": -11,
      "y": 10,
      "z": -3,
      "name": "Rock_Stone_Brick_Smooth"
    },
    {
      "x": -11,
      "y": 11,
      "z": -3,
      "name": "Rock_Stone_Brick_Smooth"
    },
    {
      "x": -11,
      "y": 12,
      "z": -3,
      "name": "Rock_Stone"
    },
    {
      "x": -11,
      "y": 0,
      "z": -2,
      "name": "Rock_Stone_Cobble"
    },
    {
      "x": -11,
      "y": 1,
      "z": -2,
      "name": "Rock_Stone_Brick_Smooth"
    },
    {
      "x": -11,
      "y": 2,
      "z": -2,
      "name": "Rock_Stone_Brick_Smooth"
    },
    {
      "x": -11,
      "y": 3,
      "z": -2,
      "name": "Rock_Stone_Brick_Smooth"
    },
    {
      "x": -11,
      "y": 4,
      "z": -2,
      "name": "Rock_Stone_Brick_Smooth"
    },
    {
      "x": -11,
      "y": 5,
      "z": -2,
      "name": "Rock_Stone_Brick_Smooth"
    },
    {
      "x": -11,
      "y": 6,
      "z": -2,
      "name": "Rock_Stone_Brick_Smooth"
    },
    {
      "x": -11,
      "y": 7,
      "z": -2,
      "name": "Rock_Stone_Brick_Smooth"
    },
    {
      "x": -11,
      "y": 8,
      "z": -2,
      "name": "Rock_Stone_Brick_Smooth"
    },
    {
      "x": -11,
      "y": 9,
      "z": -2,
      "name": "Rock_Stone_Brick_Smooth"
    },
    {
      "x": -11,
      "y": 10,
      "z": -2,
      "name": "Rock_Stone_Brick_Smooth"
    },
    {
      "x": -11,
      "y": 11,
      "z": -2,
      "name": "Rock_Stone_Brick_Smooth"
    },
    {
      "x": -11,
      "y": 12,
      "z": -2,
      "name": "Rock_Stone"
    },
    {
      "x": -11,
      "y": 0,
      "z": -1,
      "name": "Rock_Stone_Cobble"
    },
    {
      "x": -11,
      "y": 1,
      "z": -1,
      "name": "Rock_Stone_Brick_Smooth"
    },
    {
      "x": -11,
      "y": 2,
      "z": -1,
      "name": "Rock_Stone_Brick_Smooth"
    },
    {
      "x": -11,
      "y": 3,
      "z": -1,
      "name": "Rock_Stone_Brick_Smooth"
    },
    {
      "x": -11,
      "y": 4,
      "z": -1,
      "name": "Rock_Stone_Brick_Smooth"
    },
    {
      "x": -11,
      "y": 5,
      "z": -1,
      "name": "Rock_Stone_Brick_Smooth"
    },
    {
      "x": -11,
      "y": 6,
      "z": -1,
      "name": "Rock_Stone_Brick_Smooth"
    },
    {
      "x": -11,
      "y": 7,
      "z": -1,
      "name": "Rock_Stone_Brick_Smooth"
    },
    {
      "x": -11,
      "y": 8,
      "z": -1,
      "name": "Rock_Stone_Brick_Smooth"
    },
    {
      "x": -11,
      "y": 9,
      "z": -1,
      "name": "Rock_Stone_Brick_Smooth"
    },
    {
      "x": -11,
      "y": 10,
      "z": -1,
      "name": "Rock_Stone_Brick_Smooth"
    },
    {
      "x": -11,
      "y": 11,
      "z": -1,
      "name": "Rock_Stone_Brick_Smooth"
    },
    {
      "x": -11,
      "y": 12,
      "z": -1,
      "name": "Rock_Stone"
    },
    {
      "x": -11,
      "y": 0,
      "z": 0,
      "name": "Rock_Stone_Cobble"
    },
    {
      "x": -11,
      "y": 1,
      "z": 0,
      "name": "Rock_Stone_Brick_Smooth"
    },
    {
      "x": -11,
      "y": 2,
      "z": 0,
      "name": "Rock_Stone_Brick_Smooth"
    },
    {
      "x": -11,
      "y": 3,
      "z": 0,
      "name": "Rock_Stone_Brick_Smooth"
    },
    {
      "x": -11,
      "y": 4,
      "z": 0,
      "name": "Rock_Stone_Brick_Smooth"
    },
    {
      "x": -11,
      "y": 5,
      "z": 0,
      "name": "Rock_Stone_Brick_Smooth"
    },
    {
      "x": -11,
      "y": 6,
      "z": 0,
      "name": "Rock_Stone_Brick_Smooth"
    },
    {
      "x": -11,
      "y": 7,
      "z": 0,
      "name": "Rock_Stone_Brick_Smooth"
    },
    {
      "x": -11,
      "y": 8,
      "z": 0,
      "name": "Rock_Stone_Brick_Smooth"
    },
    {
      "x": -11,
      "y": 9,
      "z": 0,
      "name": "Rock_Stone_Brick_Smooth"
    },
    {
      "x": -11,
      "y": 10,
      "z": 0,
      "name": "Rock_Stone_Brick_Smooth"
    },
    {
      "x": -11,
      "y": 11,
      "z": 0,
      "name": "Rock_Stone_Brick_Smooth"
    },
    {
      "x": -11,
      "y": 12,
      "z": 0,
      "name": "Rock_Stone"
    },
    {
      "x": -10,
      "y": 0,
      "z": -22,
      "name": "Rock_Stone"
    },
    {
      "x": -10,
      "y": 1,
      "z": -22,
      "name": "Rock_Stone"
    },
    {
      "x": -10,
      "y": 2,
      "z": -22,
      "name": "Rock_Stone"
    },
    {
      "x": -10,
      "y": 3,
      "z": -22,
      "name": "Rock_Stone"
    },
    {
      "x": -10,
      "y": 4,
      "z": -22,
      "name": "Rock_Stone"
    },
    {
      "x": -10,
      "y": 5,
      "z": -22,
      "name": "Rock_Stone"
    },
    {
      "x": -10,
      "y": 6,
      "z": -22,
      "name": "Rock_Stone"
    },
    {
      "x": -10,
      "y": 7,
      "z": -22,
      "name": "Rock_Stone"
    },
    {
      "x": -10,
      "y": 8,
      "z": -22,
      "name": "Rock_Stone"
    },
    {
      "x": -10,
      "y": 9,
      "z": -22,
      "name": "Rock_Stone"
    },
    {
      "x": -10,
      "y": 10,
      "z": -22,
      "name": "Rock_Stone"
    },
    {
      "x": -10,
      "y": 11,
      "z": -22,
      "name": "Rock_Stone"
    },
    {
      "x": -10,
      "y": 12,
      "z": -22,
      "name": "Rock_Stone"
    },
    {
      "x": -10,
      "y": 0,
      "z": -21,
      "name": "Rock_Stone"
    },
    {
      "x": -10,
      "y": 1,
      "z": -21,
      "name": "Rock_Stone"
    },
    {
      "x": -10,
      "y": 2,
      "z": -21,
      "name": "Rock_Stone"
    },
    {
      "x": -10,
      "y": 3,
      "z": -21,
      "name": "Rock_Stone"
    },
    {
      "x": -10,
      "y": 4,
      "z": -21,
      "name": "Rock_Stone"
    },
    {
      "x": -10,
      "y": 5,
      "z": -21,
      "name": "Rock_Stone"
    },
    {
      "x": -10,
      "y": 6,
      "z": -21,
      "name": "Rock_Stone"
    },
    {
      "x": -10,
      "y": 7,
      "z": -21,
      "name": "Rock_Stone"
    },
    {
      "x": -10,
      "y": 8,
      "z": -21,
      "name": "Rock_Stone"
    },
    {
      "x": -10,
      "y": 9,
      "z": -21,
      "name": "Rock_Stone"
    },
    {
      "x": -10,
      "y": 10,
      "z": -21,
      "name": "Rock_Stone"
    },
    {
      "x": -10,
      "y": 11,
      "z": -21,
      "name": "Rock_Stone"
    },
    {
      "x": -10,
      "y": 12,
      "z": -21,
      "name": "Rock_Stone"
    },
    {
      "x": -10,
      "y": 0,
      "z": -20,
      "name": "Rock_Stone"
    },
    {
      "x": -10,
      "y": 1,
      "z": -20,
      "name": "Rock_Stone"
    },
    {
      "x": -10,
      "y": 2,
      "z": -20,
      "name": "Rock_Stone"
    },
    {
      "x": -10,
      "y": 3,
      "z": -20,
      "name": "Rock_Stone"
    },
    {
      "x": -10,
      "y": 4,
      "z": -20,
      "name": "Rock_Stone"
    },
    {
      "x": -10,
      "y": 5,
      "z": -20,
      "name": "Rock_Stone"
    },
    {
      "x": -10,
      "y": 6,
      "z": -20,
      "name": "Rock_Stone"
    },
    {
      "x": -10,
      "y": 7,
      "z": -20,
      "name": "Rock_Stone"
    },
    {
      "x": -10,
      "y": 8,
      "z": -20,
      "name": "Rock_Stone"
    },
    {
      "x": -10,
      "y": 9,
      "z": -20,
      "name": "Rock_Stone"
    },
    {
      "x": -10,
      "y": 10,
      "z": -20,
      "name": "Rock_Stone"
    },
    {
      "x": -10,
      "y": 11,
      "z": -20,
      "name": "Rock_Stone"
    },
    {
      "x": -10,
      "y": 12,
      "z": -20,
      "name": "Rock_Stone"
    },
    {
      "x": -10,
      "y": 0,
      "z": -19,
      "name": "Rock_Stone"
    },
    {
      "x": -10,
      "y": 1,
      "z": -19,
      "name": "Rock_Stone"
    },
    {
      "x": -10,
      "y": 2,
      "z": -19,
      "name": "Rock_Stone"
    },
    {
      "x": -10,
      "y": 3,
      "z": -19,
      "name": "Rock_Stone"
    },
    {
      "x": -10,
      "y": 4,
      "z": -19,
      "name": "Rock_Stone"
    },
    {
      "x": -10,
      "y": 5,
      "z": -19,
      "name": "Rock_Stone"
    },
    {
      "x": -10,
      "y": 6,
      "z": -19,
      "name": "Rock_Stone"
    },
    {
      "x": -10,
      "y": 7,
      "z": -19,
      "name": "Rock_Stone"
    },
    {
      "x": -10,
      "y": 8,
      "z": -19,
      "name": "Rock_Stone"
    },
    {
      "x": -10,
      "y": 9,
      "z": -19,
      "name": "Rock_Stone"
    },
    {
      "x": -10,
      "y": 10,
      "z": -19,
      "name": "Rock_Stone"
    },
    {
      "x": -10,
      "y": 11,
      "z": -19,
      "name": "Rock_Stone"
    },
    {
      "x": -10,
      "y": 12,
      "z": -19,
      "name": "Rock_Stone"
    },
    {
      "x": -10,
      "y": 0,
      "z": -18,
      "name": "Rock_Stone"
    },
    {
      "x": -10,
      "y": 1,
      "z": -18,
      "name": "Rock_Stone"
    },
    {
      "x": -10,
      "y": 2,
      "z": -18,
      "name": "Rock_Stone"
    },
    {
      "x": -10,
      "y": 3,
      "z": -18,
      "name": "Rock_Stone"
    },
    {
      "x": -10,
      "y": 4,
      "z": -18,
      "name": "Rock_Stone"
    },
    {
      "x": -10,
      "y": 5,
      "z": -18,
      "name": "Rock_Stone"
    },
    {
      "x": -10,
      "y": 6,
      "z": -18,
      "name": "Rock_Stone"
    },
    {
      "x": -10,
      "y": 7,
      "z": -18,
      "name": "Rock_Stone"
    },
    {
      "x": -10,
      "y": 8,
      "z": -18,
      "name": "Rock_Stone"
    },
    {
      "x": -10,
      "y": 9,
      "z": -18,
      "name": "Rock_Stone"
    },
    {
      "x": -10,
      "y": 10,
      "z": -18,
      "name": "Rock_Stone"
    },
    {
      "x": -10,
      "y": 11,
      "z": -18,
      "name": "Rock_Stone"
    },
    {
      "x": -10,
      "y": 12,
      "z": -18,
      "name": "Rock_Stone"
    },
    {
      "x": -10,
      "y": 0,
      "z": -17,
      "name": "Rock_Stone"
    },
    {
      "x": -10,
      "y": 1,
      "z": -17,
      "name": "Rock_Stone"
    },
    {
      "x": -10,
      "y": 2,
      "z": -17,
      "name": "Rock_Stone"
    },
    {
      "x": -10,
      "y": 3,
      "z": -17,
      "name": "Rock_Stone"
    },
    {
      "x": -10,
      "y": 4,
      "z": -17,
      "name": "Rock_Stone"
    },
    {
      "x": -10,
      "y": 5,
      "z": -17,
      "name": "Rock_Stone"
    },
    {
      "x": -10,
      "y": 6,
      "z": -17,
      "name": "Rock_Stone"
    },
    {
      "x": -10,
      "y": 7,
      "z": -17,
      "name": "Rock_Stone"
    },
    {
      "x": -10,
      "y": 8,
      "z": -17,
      "name": "Rock_Stone"
    },
    {
      "x": -10,
      "y": 9,
      "z": -17,
      "name": "Rock_Stone"
    },
    {
      "x": -10,
      "y": 10,
      "z": -17,
      "name": "Rock_Stone"
    },
    {
      "x": -10,
      "y": 11,
      "z": -17,
      "name": "Rock_Stone"
    },
    {
      "x": -10,
      "y": 12,
      "z": -17,
      "name": "Rock_Stone"
    },
    {
      "x": -10,
      "y": 0,
      "z": -16,
      "name": "Rock_Stone"
    },
    {
      "x": -10,
      "y": 1,
      "z": -16,
      "name": "Rock_Stone"
    },
    {
      "x": -10,
      "y": 2,
      "z": -16,
      "name": "Rock_Stone"
    },
    {
      "x": -10,
      "y": 3,
      "z": -16,
      "name": "Rock_Stone"
    },
    {
      "x": -10,
      "y": 4,
      "z": -16,
      "name": "Rock_Stone"
    },
    {
      "x": -10,
      "y": 5,
      "z": -16,
      "name": "Rock_Stone"
    },
    {
      "x": -10,
      "y": 6,
      "z": -16,
      "name": "Rock_Stone"
    },
    {
      "x": -10,
      "y": 7,
      "z": -16,
      "name": "Rock_Stone"
    },
    {
      "x": -10,
      "y": 8,
      "z": -16,
      "name": "Rock_Stone"
    },
    {
      "x": -10,
      "y": 9,
      "z": -16,
      "name": "Rock_Stone"
    },
    {
      "x": -10,
      "y": 10,
      "z": -16,
      "name": "Rock_Stone"
    },
    {
      "x": -10,
      "y": 11,
      "z": -16,
      "name": "Rock_Stone"
    },
    {
      "x": -10,
      "y": 12,
      "z": -16,
      "name": "Rock_Stone"
    },
    {
      "x": -10,
      "y": 0,
      "z": -15,
      "name": "Rock_Stone"
    },
    {
      "x": -10,
      "y": 1,
      "z": -15,
      "name": "Rock_Stone"
    },
    {
      "x": -10,
      "y": 2,
      "z": -15,
      "name": "Rock_Stone"
    },
    {
      "x": -10,
      "y": 3,
      "z": -15,
      "name": "Rock_Stone"
    },
    {
      "x": -10,
      "y": 4,
      "z": -15,
      "name": "Rock_Stone"
    },
    {
      "x": -10,
      "y": 5,
      "z": -15,
      "name": "Rock_Stone"
    },
    {
      "x": -10,
      "y": 6,
      "z": -15,
      "name": "Rock_Stone"
    },
    {
      "x": -10,
      "y": 7,
      "z": -15,
      "name": "Rock_Stone"
    },
    {
      "x": -10,
      "y": 8,
      "z": -15,
      "name": "Rock_Stone"
    },
    {
      "x": -10,
      "y": 9,
      "z": -15,
      "name": "Rock_Stone"
    },
    {
      "x": -10,
      "y": 10,
      "z": -15,
      "name": "Rock_Stone"
    },
    {
      "x": -10,
      "y": 11,
      "z": -15,
      "name": "Rock_Stone"
    },
    {
      "x": -10,
      "y": 12,
      "z": -15,
      "name": "Rock_Stone"
    },
    {
      "x": -10,
      "y": 0,
      "z": -14,
      "name": "Rock_Stone_Brick"
    },
    {
      "x": -10,
      "y": 1,
      "z": -14,
      "name": "Rock_Volcanic_Cobble"
    },
    {
      "x": -10,
      "y": 2,
      "z": -14,
      "name": "Rock_Volcanic_Cobble"
    },
    {
      "x": -10,
      "y": 3,
      "z": -14,
      "name": "Rock_Volcanic_Cobble"
    },
    {
      "x": -10,
      "y": 4,
      "z": -14,
      "name": "Rock_Volcanic_Cobble"
    },
    {
      "x": -10,
      "y": 5,
      "z": -14,
      "name": "Rock_Volcanic_Cobble"
    },
    {
      "x": -10,
      "y": 6,
      "z": -14,
      "name": "Rock_Volcanic_Cobble"
    },
    {
      "x": -10,
      "y": 7,
      "z": -14,
      "name": "Rock_Stone_Brick"
    },
    {
      "x": -10,
      "y": 8,
      "z": -14,
      "name": "Rock_Stone_Brick"
    },
    {
      "x": -10,
      "y": 9,
      "z": -14,
      "name": "Rock_Stone_Brick"
    },
    {
      "x": -10,
      "y": 10,
      "z": -14,
      "name": "Rock_Volcanic_Cobble"
    },
    {
      "x": -10,
      "y": 11,
      "z": -14,
      "name": "Rock_Volcanic_Cobble"
    },
    {
      "x": -10,
      "y": 12,
      "z": -14,
      "name": "Rock_Stone"
    },
    {
      "x": -10,
      "y": 0,
      "z": -13,
      "name": "Rock_Stone_Brick"
    },
    {
      "x": -10,
      "y": 1,
      "z": -13,
      "name": "Rock_Volcanic_Brick_Smooth"
    },
    {
      "x": -10,
      "y": 2,
      "z": -13,
      "name": "Rock_Volcanic_Brick_Smooth"
    },
    {
      "x": -10,
      "y": 3,
      "z": -13,
      "name": "Rock_Volcanic_Brick_Smooth"
    },
    {
      "x": -10,
      "y": 4,
      "z": -13,
      "name": "Rock_Volcanic_Brick_Smooth"
    },
    {
      "x": -10,
      "y": 5,
      "z": -13,
      "name": "Rock_Volcanic_Brick_Smooth"
    },
    {
      "x": -10,
      "y": 6,
      "z": -13,
      "name": "Rock_Stone_Brick_Smooth"
    },
    {
      "x": -10,
      "y": 7,
      "z": -13,
      "name": "Furniture_Village_Statue"
    },
    {
      "x": -10,
      "y": 8,
      "z": -13,
      "name": "Furniture_Village_Statue",
      "filler": 1024
    },
    {
      "x": -10,
      "y": 9,
      "z": -13,
      "name": "Furniture_Village_Statue",
      "filler": 2048
    },
    {
      "x": -10,
      "y": 10,
      "z": -13,
      "name": "Rock_Stone_Brick_Smooth_Half",
      "rotation": 4
    },
    {
      "x": -10,
      "y": 11,
      "z": -13,
      "name": "Rock_Stone_Brick_Smooth"
    },
    {
      "x": -10,
      "y": 12,
      "z": -13,
      "name": "Rock_Stone_Cobble"
    },
    {
      "x": -10,
      "y": 0,
      "z": -12,
      "name": "Rock_Stone_Cobble"
    },
    {
      "x": -10,
      "y": 1,
      "z": -12,
      "name": "Furniture_Temple_Dark_Window",
      "rotation": 1
    },
    {
      "x": -10,
      "y": 2,
      "z": -12,
      "name": "Furniture_Temple_Dark_Window",
      "rotation": 1
    },
    {
      "x": -10,
      "y": 3,
      "z": -12,
      "name": "Furniture_Temple_Dark_Window",
      "rotation": 1
    },
    {
      "x": -10,
      "y": 4,
      "z": -12,
      "name": "Furniture_Temple_Dark_Window",
      "rotation": 1
    },
    {
      "x": -10,
      "y": 5,
      "z": -12,
      "name": "Rock_Volcanic_Brick_Smooth"
    },
    {
      "x": -10,
      "y": 6,
      "z": -12,
      "name": "Rock_Stone_Brick_Smooth"
    },
    {
      "x": -10,
      "y": 7,
      "z": -12,
      "name": "Empty"
    },
    {
      "x": -10,
      "y": 8,
      "z": -12,
      "name": "Empty"
    },
    {
      "x": -10,
      "y": 9,
      "z": -12,
      "name": "Empty"
    },
    {
      "x": -10,
      "y": 10,
      "z": -12,
      "name": "Empty"
    },
    {
      "x": -10,
      "y": 11,
      "z": -12,
      "name": "Rock_Stone_Brick_Smooth"
    },
    {
      "x": -10,
      "y": 12,
      "z": -12,
      "name": "Rock_Stone_Cobble"
    },
    {
      "x": -10,
      "y": 0,
      "z": -11,
      "name": "Rock_Stone_Brick"
    },
    {
      "x": -10,
      "y": 1,
      "z": -11,
      "name": "Furniture_Human_Ruins_Door",
      "rotation": 3
    },
    {
      "x": -10,
      "y": 2,
      "z": -11,
      "name": "Furniture_Human_Ruins_Door",
      "filler": 1024,
      "rotation": 3
    },
    {
      "x": -10,
      "y": 3,
      "z": -11,
      "name": "Furniture_Temple_Dark_Window",
      "rotation": 1
    },
    {
      "x": -10,
      "y": 4,
      "z": -11,
      "name": "Furniture_Temple_Dark_Window",
      "rotation": 1
    },
    {
      "x": -10,
      "y": 5,
      "z": -11,
      "name": "Rock_Volcanic_Brick_Smooth"
    },
    {
      "x": -10,
      "y": 6,
      "z": -11,
      "name": "Rock_Stone_Brick_Smooth"
    },
    {
      "x": -10,
      "y": 7,
      "z": -11,
      "name": "Empty"
    },
    {
      "x": -10,
      "y": 8,
      "z": -11,
      "name": "Empty"
    },
    {
      "x": -10,
      "y": 9,
      "z": -11,
      "name": "Empty"
    },
    {
      "x": -10,
      "y": 10,
      "z": -11,
      "name": "Empty"
    },
    {
      "x": -10,
      "y": 11,
      "z": -11,
      "name": "Rock_Stone_Brick_Smooth_Half",
      "rotation": 8
    },
    {
      "x": -10,
      "y": 12,
      "z": -11,
      "name": "Rock_Stone_Cobble"
    },
    {
      "x": -10,
      "y": 0,
      "z": -10,
      "name": "Rock_Stone_Brick"
    },
    {
      "x": -10,
      "y": 1,
      "z": -10,
      "name": "Furniture_Temple_Dark_Window",
      "rotation": 1
    },
    {
      "x": -10,
      "y": 2,
      "z": -10,
      "name": "Furniture_Temple_Dark_Window",
      "rotation": 1
    },
    {
      "x": -10,
      "y": 3,
      "z": -10,
      "name": "Furniture_Temple_Dark_Window",
      "rotation": 1
    },
    {
      "x": -10,
      "y": 4,
      "z": -10,
      "name": "Furniture_Temple_Dark_Window",
      "rotation": 1
    },
    {
      "x": -10,
      "y": 5,
      "z": -10,
      "name": "Rock_Volcanic_Brick_Smooth"
    },
    {
      "x": -10,
      "y": 6,
      "z": -10,
      "name": "Rock_Stone_Brick_Smooth"
    },
    {
      "x": -10,
      "y": 7,
      "z": -10,
      "name": "Empty"
    },
    {
      "x": -10,
      "y": 8,
      "z": -10,
      "name": "Empty"
    },
    {
      "x": -10,
      "y": 9,
      "z": -10,
      "name": "Empty"
    },
    {
      "x": -10,
      "y": 10,
      "z": -10,
      "name": "Empty"
    },
    {
      "x": -10,
      "y": 11,
      "z": -10,
      "name": "Rock_Stone_Brick_Smooth"
    },
    {
      "x": -10,
      "y": 12,
      "z": -10,
      "name": "Rock_Stone_Cobble"
    },
    {
      "x": -10,
      "y": 0,
      "z": -9,
      "name": "Rock_Stone_Brick"
    },
    {
      "x": -10,
      "y": 1,
      "z": -9,
      "name": "Rock_Volcanic_Brick_Smooth"
    },
    {
      "x": -10,
      "y": 2,
      "z": -9,
      "name": "Rock_Volcanic_Brick_Smooth"
    },
    {
      "x": -10,
      "y": 3,
      "z": -9,
      "name": "Rock_Volcanic_Brick_Smooth"
    },
    {
      "x": -10,
      "y": 4,
      "z": -9,
      "name": "Rock_Volcanic_Brick_Smooth"
    },
    {
      "x": -10,
      "y": 5,
      "z": -9,
      "name": "Rock_Volcanic_Brick_Smooth"
    },
    {
      "x": -10,
      "y": 6,
      "z": -9,
      "name": "Rock_Stone_Brick_Smooth"
    },
    {
      "x": -10,
      "y": 7,
      "z": -9,
      "name": "Furniture_Village_Statue",
      "rotation": 2
    },
    {
      "x": -10,
      "y": 8,
      "z": -9,
      "name": "Furniture_Village_Statue",
      "filler": 1024,
      "rotation": 2
    },
    {
      "x": -10,
      "y": 9,
      "z": -9,
      "name": "Furniture_Village_Statue",
      "filler": 2048,
      "rotation": 2
    },
    {
      "x": -10,
      "y": 10,
      "z": -9,
      "name": "Rock_Stone_Brick_Smooth_Half",
      "rotation": 6
    },
    {
      "x": -10,
      "y": 11,
      "z": -9,
      "name": "Rock_Stone_Brick_Smooth"
    },
    {
      "x": -10,
      "y": 12,
      "z": -9,
      "name": "Rock_Stone_Cobble"
    },
    {
      "x": -10,
      "y": 0,
      "z": -8,
      "name": "Plant_Moss_Block_Blue"
    },
    {
      "x": -10,
      "y": 1,
      "z": -8,
      "name": "Rock_Volcanic_Cobble"
    },
    {
      "x": -10,
      "y": 2,
      "z": -8,
      "name": "Rock_Volcanic_Cobble"
    },
    {
      "x": -10,
      "y": 3,
      "z": -8,
      "name": "Rock_Volcanic_Cobble"
    },
    {
      "x": -10,
      "y": 4,
      "z": -8,
      "name": "Rock_Volcanic_Cobble"
    },
    {
      "x": -10,
      "y": 5,
      "z": -8,
      "name": "Rock_Volcanic_Cobble"
    },
    {
      "x": -10,
      "y": 6,
      "z": -8,
      "name": "Rock_Volcanic_Cobble"
    },
    {
      "x": -10,
      "y": 7,
      "z": -8,
      "name": "Rock_Stone_Brick"
    },
    {
      "x": -10,
      "y": 8,
      "z": -8,
      "name": "Rock_Stone_Brick"
    },
    {
      "x": -10,
      "y": 9,
      "z": -8,
      "name": "Rock_Stone_Brick"
    },
    {
      "x": -10,
      "y": 10,
      "z": -8,
      "name": "Rock_Volcanic_Cobble"
    },
    {
      "x": -10,
      "y": 11,
      "z": -8,
      "name": "Rock_Volcanic_Cobble"
    },
    {
      "x": -10,
      "y": 12,
      "z": -8,
      "name": "Rock_Stone_Cobble"
    },
    {
      "x": -10,
      "y": 0,
      "z": -7,
      "name": "Plant_Moss_Block_Blue"
    },
    {
      "x": -10,
      "y": 1,
      "z": -7,
      "name": "Rock_Stone_Brick_Smooth"
    },
    {
      "x": -10,
      "y": 2,
      "z": -7,
      "name": "Rock_Stone_Brick_Smooth"
    },
    {
      "x": -10,
      "y": 3,
      "z": -7,
      "name": "Rock_Stone_Brick_Smooth"
    },
    {
      "x": -10,
      "y": 4,
      "z": -7,
      "name": "Rock_Stone_Brick_Smooth"
    },
    {
      "x": -10,
      "y": 5,
      "z": -7,
      "name": "Rock_Stone_Brick_Smooth"
    },
    {
      "x": -10,
      "y": 6,
      "z": -7,
      "name": "Rock_Stone_Brick_Smooth"
    },
    {
      "x": -10,
      "y": 7,
      "z": -7,
      "name": "Rock_Stone_Brick_Smooth"
    },
    {
      "x": -10,
      "y": 8,
      "z": -7,
      "name": "Rock_Stone_Brick_Smooth"
    },
    {
      "x": -10,
      "y": 9,
      "z": -7,
      "name": "Rock_Stone_Brick_Smooth"
    },
    {
      "x": -10,
      "y": 10,
      "z": -7,
      "name": "Rock_Stone_Brick_Smooth"
    },
    {
      "x": -10,
      "y": 11,
      "z": -7,
      "name": "Rock_Stone_Brick_Smooth"
    },
    {
      "x": -10,
      "y": 12,
      "z": -7,
      "name": "Rock_Stone_Cobble"
    },
    {
      "x": -10,
      "y": 0,
      "z": -6,
      "name": "Rock_Stone_Cobble"
    },
    {
      "x": -10,
      "y": 1,
      "z": -6,
      "name": "Soil_Ash"
    },
    {
      "x": -10,
      "y": 2,
      "z": -6,
      "name": "Furniture_Ancient_Crate",
      "rotation": 1
    },
    {
      "x": -10,
      "y": 3,
      "z": -6,
      "name": "Furniture_Ancient_Crate",
      "rotation": 1
    },
    {
      "x": -10,
      "y": 4,
      "z": -6,
      "name": "Empty"
    },
    {
      "x": -10,
      "y": 5,
      "z": -6,
      "name": "Rock_Stone_Brick_Smooth"
    },
    {
      "x": -10,
      "y": 6,
      "z": -6,
      "name": "Rock_Stone_Brick_Smooth"
    },
    {
      "x": -10,
      "y": 7,
      "z": -6,
      "name": "Rock_Stone_Brick_Pillar_Base"
    },
    {
      "x": -10,
      "y": 8,
      "z": -6,
      "name": "Rock_Stone_Brick_Pillar_Middle"
    },
    {
      "x": -10,
      "y": 9,
      "z": -6,
      "name": "Rock_Stone_Brick_Pillar_Middle"
    },
    {
      "x": -10,
      "y": 10,
      "z": -6,
      "name": "Rock_Stone_Brick_Pillar_Middle"
    },
    {
      "x": -10,
      "y": 11,
      "z": -6,
      "name": "Rock_Stone_Brick_Pillar_Base",
      "rotation": 8
    },
    {
      "x": -10,
      "y": 12,
      "z": -6,
      "name": "Rock_Stone_Cobble"
    },
    {
      "x": -10,
      "y": 0,
      "z": -5,
      "name": "Rock_Stone_Cobble"
    },
    {
      "x": -10,
      "y": 1,
      "z": -5,
      "name": "Soil_Ash"
    },
    {
      "x": -10,
      "y": 2,
      "z": -5,
      "name": "Furniture_Ancient_Crate",
      "rotation": 1
    },
    {
      "x": -10,
      "y": 3,
      "z": -5,
      "name": "Deco_Bone_Skulls_Wall",
      "rotation": 1
    },
    {
      "x": -10,
      "y": 4,
      "z": -5,
      "name": "Empty"
    },
    {
      "x": -10,
      "y": 5,
      "z": -5,
      "name": "Rock_Stone_Brick_Smooth_Half",
      "rotation": 5
    },
    {
      "x": -10,
      "y": 6,
      "z": -5,
      "name": "Empty"
    },
    {
      "x": -10,
      "y": 7,
      "z": -5,
      "name": "Empty"
    },
    {
      "x": -10,
      "y": 8,
      "z": -5,
      "name": "Empty"
    },
    {
      "x": -10,
      "y": 9,
      "z": -5,
      "name": "Empty"
    },
    {
      "x": -10,
      "y": 10,
      "z": -5,
      "name": "Empty"
    },
    {
      "x": -10,
      "y": 11,
      "z": -5,
      "name": "Empty"
    },
    {
      "x": -10,
      "y": 12,
      "z": -5,
      "name": "Rock_Stone_Cobble"
    },
    {
      "x": -10,
      "y": 0,
      "z": -4,
      "name": "Rock_Stone_Cobble"
    },
    {
      "x": -10,
      "y": 1,
      "z": -4,
      "name": "Soil_Ash"
    },
    {
      "x": -10,
      "y": 2,
      "z": -4,
      "name": "Deco_Bone_Skulls_Wall",
      "rotation": 1
    },
    {
      "x": -10,
      "y": 3,
      "z": -4,
      "name": "Empty"
    },
    {
      "x": -10,
      "y": 4,
      "z": -4,
      "name": "Empty"
    },
    {
      "x": -10,
      "y": 5,
      "z": -4,
      "name": "Rock_Stone_Brick_Smooth_Half",
      "rotation": 5
    },
    {
      "x": -10,
      "y": 6,
      "z": -4,
      "name": "Empty"
    },
    {
      "x": -10,
      "y": 7,
      "z": -4,
      "name": "Empty"
    },
    {
      "x": -10,
      "y": 8,
      "z": -4,
      "name": "Empty"
    },
    {
      "x": -10,
      "y": 9,
      "z": -4,
      "name": "Empty"
    },
    {
      "x": -10,
      "y": 10,
      "z": -4,
      "name": "Empty"
    },
    {
      "x": -10,
      "y": 11,
      "z": -4,
      "name": "Empty"
    },
    {
      "x": -10,
      "y": 12,
      "z": -4,
      "name": "Rock_Stone_Cobble"
    },
    {
      "x": -10,
      "y": 0,
      "z": -3,
      "name": "Rock_Stone_Cobble"
    },
    {
      "x": -10,
      "y": 1,
      "z": -3,
      "name": "Soil_Ash"
    },
    {
      "x": -10,
      "y": 2,
      "z": -3,
      "name": "Deco_Bone_Skulls_Wall",
      "rotation": 1
    },
    {
      "x": -10,
      "y": 3,
      "z": -3,
      "name": "Deco_Bone_Skulls_Wall",
      "rotation": 1
    },
    {
      "x": -10,
      "y": 4,
      "z": -3,
      "name": "Empty"
    },
    {
      "x": -10,
      "y": 5,
      "z": -3,
      "name": "Rock_Stone_Brick_Smooth_Half",
      "rotation": 5
    },
    {
      "x": -10,
      "y": 6,
      "z": -3,
      "name": "Empty"
    },
    {
      "x": -10,
      "y": 7,
      "z": -3,
      "name": "Empty"
    },
    {
      "x": -10,
      "y": 8,
      "z": -3,
      "name": "Empty"
    },
    {
      "x": -10,
      "y": 9,
      "z": -3,
      "name": "Empty"
    },
    {
      "x": -10,
      "y": 10,
      "z": -3,
      "name": "Empty"
    },
    {
      "x": -10,
      "y": 11,
      "z": -3,
      "name": "Empty"
    },
    {
      "x": -10,
      "y": 12,
      "z": -3,
      "name": "Rock_Stone_Cobble"
    },
    {
      "x": -10,
      "y": 0,
      "z": -2,
      "name": "Rock_Stone_Cobble"
    },
    {
      "x": -10,
      "y": 1,
      "z": -2,
      "name": "Soil_Ash"
    },
    {
      "x": -10,
      "y": 2,
      "z": -2,
      "name": "Deco_Bone_Skulls_Wall",
      "rotation": 1
    },
    {
      "x": -10,
      "y": 3,
      "z": -2,
      "name": "Deco_Bone_Skulls_Wall",
      "rotation": 1
    },
    {
      "x": -10,
      "y": 4,
      "z": -2,
      "name": "Empty"
    },
    {
      "x": -10,
      "y": 5,
      "z": -2,
      "name": "Rock_Stone_Brick_Smooth_Half",
      "rotation": 5
    },
    {
      "x": -10,
      "y": 6,
      "z": -2,
      "name": "Empty"
    },
    {
      "x": -10,
      "y": 7,
      "z": -2,
      "name": "Empty"
    },
    {
      "x": -10,
      "y": 8,
      "z": -2,
      "name": "Empty"
    },
    {
      "x": -10,
      "y": 9,
      "z": -2,
      "name": "Empty"
    },
    {
      "x": -10,
      "y": 10,
      "z": -2,
      "name": "Empty"
    },
    {
      "x": -10,
      "y": 11,
      "z": -2,
      "name": "Empty"
    },
    {
      "x": -10,
      "y": 12,
      "z": -2,
      "name": "Rock_Stone_Cobble"
    },
    {
      "x": -10,
      "y": 0,
      "z": -1,
      "name": "Rock_Stone_Cobble"
    },
    {
      "x": -10,
      "y": 1,
      "z": -1,
      "name": "Soil_Ash"
    },
    {
      "x": -10,
      "y": 2,
      "z": -1,
      "name": "Deco_Bone_Skulls_Wall",
      "rotation": 2
    },
    {
      "x": -10,
      "y": 3,
      "z": -1,
      "name": "Deco_Bone_Skulls_Wall",
      "rotation": 1
    },
    {
      "x": -10,
      "y": 4,
      "z": -1,
      "name": "Deco_Bone_Skulls_Wall",
      "rotation": 1
    },
    {
      "x": -10,
      "y": 5,
      "z": -1,
      "name": "Rock_Stone_Brick_Smooth"
    },
    {
      "x": -10,
      "y": 6,
      "z": -1,
      "name": "Rock_Stone_Brick_Pillar_Base"
    },
    {
      "x": -10,
      "y": 7,
      "z": -1,
      "name": "Rock_Stone_Brick_Pillar_Middle"
    },
    {
      "x": -10,
      "y": 8,
      "z": -1,
      "name": "Rock_Stone_Brick_Pillar_Middle"
    },
    {
      "x": -10,
      "y": 9,
      "z": -1,
      "name": "Rock_Stone_Brick_Pillar_Middle"
    },
    {
      "x": -10,
      "y": 10,
      "z": -1,
      "name": "Rock_Stone_Brick_Pillar_Middle"
    },
    {
      "x": -10,
      "y": 11,
      "z": -1,
      "name": "Rock_Stone_Brick_Pillar_Base",
      "rotation": 8
    },
    {
      "x": -10,
      "y": 12,
      "z": -1,
      "name": "Rock_Stone_Cobble"
    },
    {
      "x": -10,
      "y": 0,
      "z": 0,
      "name": "Rock_Stone_Cobble"
    },
    {
      "x": -10,
      "y": 1,
      "z": 0,
      "name": "Rock_Stone_Brick_Smooth"
    },
    {
      "x": -10,
      "y": 2,
      "z": 0,
      "name": "Rock_Stone_Brick_Smooth"
    },
    {
      "x": -10,
      "y": 3,
      "z": 0,
      "name": "Rock_Stone_Brick_Smooth"
    },
    {
      "x": -10,
      "y": 4,
      "z": 0,
      "name": "Rock_Stone_Brick_Smooth"
    },
    {
      "x": -10,
      "y": 5,
      "z": 0,
      "name": "Rock_Stone_Brick_Smooth"
    },
    {
      "x": -10,
      "y": 6,
      "z": 0,
      "name": "Rock_Stone_Brick_Smooth"
    },
    {
      "x": -10,
      "y": 7,
      "z": 0,
      "name": "Rock_Stone_Brick_Smooth"
    },
    {
      "x": -10,
      "y": 8,
      "z": 0,
      "name": "Rock_Stone_Brick_Smooth"
    },
    {
      "x": -10,
      "y": 9,
      "z": 0,
      "name": "Rock_Stone_Brick_Smooth"
    },
    {
      "x": -10,
      "y": 10,
      "z": 0,
      "name": "Rock_Stone_Brick_Smooth"
    },
    {
      "x": -10,
      "y": 11,
      "z": 0,
      "name": "Rock_Stone_Brick_Smooth"
    },
    {
      "x": -10,
      "y": 12,
      "z": 0,
      "name": "Rock_Stone"
    },
    {
      "x": -9,
      "y": 0,
      "z": -22,
      "name": "Rock_Stone"
    },
    {
      "x": -9,
      "y": 1,
      "z": -22,
      "name": "Rock_Stone"
    },
    {
      "x": -9,
      "y": 2,
      "z": -22,
      "name": "Rock_Stone"
    },
    {
      "x": -9,
      "y": 3,
      "z": -22,
      "name": "Rock_Stone"
    },
    {
      "x": -9,
      "y": 4,
      "z": -22,
      "name": "Rock_Stone"
    },
    {
      "x": -9,
      "y": 5,
      "z": -22,
      "name": "Rock_Stone"
    },
    {
      "x": -9,
      "y": 6,
      "z": -22,
      "name": "Rock_Stone"
    },
    {
      "x": -9,
      "y": 7,
      "z": -22,
      "name": "Rock_Stone"
    },
    {
      "x": -9,
      "y": 8,
      "z": -22,
      "name": "Rock_Stone"
    },
    {
      "x": -9,
      "y": 9,
      "z": -22,
      "name": "Rock_Stone"
    },
    {
      "x": -9,
      "y": 10,
      "z": -22,
      "name": "Rock_Stone"
    },
    {
      "x": -9,
      "y": 11,
      "z": -22,
      "name": "Rock_Stone"
    },
    {
      "x": -9,
      "y": 12,
      "z": -22,
      "name": "Rock_Stone"
    },
    {
      "x": -9,
      "y": 0,
      "z": -21,
      "name": "Rock_Stone"
    },
    {
      "x": -9,
      "y": 1,
      "z": -21,
      "name": "Rock_Stone"
    },
    {
      "x": -9,
      "y": 2,
      "z": -21,
      "name": "Rock_Stone"
    },
    {
      "x": -9,
      "y": 3,
      "z": -21,
      "name": "Rock_Stone"
    },
    {
      "x": -9,
      "y": 4,
      "z": -21,
      "name": "Rock_Stone"
    },
    {
      "x": -9,
      "y": 5,
      "z": -21,
      "name": "Rock_Stone"
    },
    {
      "x": -9,
      "y": 6,
      "z": -21,
      "name": "Rock_Stone"
    },
    {
      "x": -9,
      "y": 7,
      "z": -21,
      "name": "Rock_Stone"
    },
    {
      "x": -9,
      "y": 8,
      "z": -21,
      "name": "Rock_Stone"
    },
    {
      "x": -9,
      "y": 9,
      "z": -21,
      "name": "Rock_Stone"
    },
    {
      "x": -9,
      "y": 10,
      "z": -21,
      "name": "Rock_Stone"
    },
    {
      "x": -9,
      "y": 11,
      "z": -21,
      "name": "Rock_Stone"
    },
    {
      "x": -9,
      "y": 12,
      "z": -21,
      "name": "Rock_Stone"
    },
    {
      "x": -9,
      "y": 0,
      "z": -20,
      "name": "Rock_Stone"
    },
    {
      "x": -9,
      "y": 1,
      "z": -20,
      "name": "Rock_Stone"
    },
    {
      "x": -9,
      "y": 2,
      "z": -20,
      "name": "Rock_Stone"
    },
    {
      "x": -9,
      "y": 3,
      "z": -20,
      "name": "Rock_Stone"
    },
    {
      "x": -9,
      "y": 4,
      "z": -20,
      "name": "Rock_Stone"
    },
    {
      "x": -9,
      "y": 5,
      "z": -20,
      "name": "Rock_Stone"
    },
    {
      "x": -9,
      "y": 6,
      "z": -20,
      "name": "Rock_Stone"
    },
    {
      "x": -9,
      "y": 7,
      "z": -20,
      "name": "Rock_Stone"
    },
    {
      "x": -9,
      "y": 8,
      "z": -20,
      "name": "Rock_Stone"
    },
    {
      "x": -9,
      "y": 9,
      "z": -20,
      "name": "Rock_Stone"
    },
    {
      "x": -9,
      "y": 10,
      "z": -20,
      "name": "Rock_Stone"
    },
    {
      "x": -9,
      "y": 11,
      "z": -20,
      "name": "Rock_Stone"
    },
    {
      "x": -9,
      "y": 12,
      "z": -20,
      "name": "Rock_Stone"
    },
    {
      "x": -9,
      "y": 0,
      "z": -19,
      "name": "Rock_Stone"
    },
    {
      "x": -9,
      "y": 1,
      "z": -19,
      "name": "Rock_Stone"
    },
    {
      "x": -9,
      "y": 2,
      "z": -19,
      "name": "Rock_Stone"
    },
    {
      "x": -9,
      "y": 3,
      "z": -19,
      "name": "Rock_Stone"
    },
    {
      "x": -9,
      "y": 4,
      "z": -19,
      "name": "Rock_Stone"
    },
    {
      "x": -9,
      "y": 5,
      "z": -19,
      "name": "Rock_Stone"
    },
    {
      "x": -9,
      "y": 6,
      "z": -19,
      "name": "Rock_Stone"
    },
    {
      "x": -9,
      "y": 7,
      "z": -19,
      "name": "Rock_Stone"
    },
    {
      "x": -9,
      "y": 8,
      "z": -19,
      "name": "Rock_Stone"
    },
    {
      "x": -9,
      "y": 9,
      "z": -19,
      "name": "Rock_Stone"
    },
    {
      "x": -9,
      "y": 10,
      "z": -19,
      "name": "Rock_Stone"
    },
    {
      "x": -9,
      "y": 11,
      "z": -19,
      "name": "Rock_Stone"
    },
    {
      "x": -9,
      "y": 12,
      "z": -19,
      "name": "Rock_Stone"
    },
    {
      "x": -9,
      "y": 0,
      "z": -18,
      "name": "Rock_Stone"
    },
    {
      "x": -9,
      "y": 1,
      "z": -18,
      "name": "Rock_Stone"
    },
    {
      "x": -9,
      "y": 2,
      "z": -18,
      "name": "Rock_Stone"
    },
    {
      "x": -9,
      "y": 3,
      "z": -18,
      "name": "Rock_Stone"
    },
    {
      "x": -9,
      "y": 4,
      "z": -18,
      "name": "Rock_Stone"
    },
    {
      "x": -9,
      "y": 5,
      "z": -18,
      "name": "Rock_Stone"
    },
    {
      "x": -9,
      "y": 6,
      "z": -18,
      "name": "Rock_Stone"
    },
    {
      "x": -9,
      "y": 7,
      "z": -18,
      "name": "Rock_Stone"
    },
    {
      "x": -9,
      "y": 8,
      "z": -18,
      "name": "Rock_Stone"
    },
    {
      "x": -9,
      "y": 9,
      "z": -18,
      "name": "Rock_Stone"
    },
    {
      "x": -9,
      "y": 10,
      "z": -18,
      "name": "Rock_Stone"
    },
    {
      "x": -9,
      "y": 11,
      "z": -18,
      "name": "Rock_Stone"
    },
    {
      "x": -9,
      "y": 12,
      "z": -18,
      "name": "Rock_Stone"
    },
    {
      "x": -9,
      "y": 0,
      "z": -17,
      "name": "Rock_Stone"
    },
    {
      "x": -9,
      "y": 1,
      "z": -17,
      "name": "Rock_Stone"
    },
    {
      "x": -9,
      "y": 2,
      "z": -17,
      "name": "Rock_Stone"
    },
    {
      "x": -9,
      "y": 3,
      "z": -17,
      "name": "Rock_Stone"
    },
    {
      "x": -9,
      "y": 4,
      "z": -17,
      "name": "Rock_Stone"
    },
    {
      "x": -9,
      "y": 5,
      "z": -17,
      "name": "Rock_Stone"
    },
    {
      "x": -9,
      "y": 6,
      "z": -17,
      "name": "Rock_Stone"
    },
    {
      "x": -9,
      "y": 7,
      "z": -17,
      "name": "Rock_Stone"
    },
    {
      "x": -9,
      "y": 8,
      "z": -17,
      "name": "Rock_Stone"
    },
    {
      "x": -9,
      "y": 9,
      "z": -17,
      "name": "Rock_Stone"
    },
    {
      "x": -9,
      "y": 10,
      "z": -17,
      "name": "Rock_Stone"
    },
    {
      "x": -9,
      "y": 11,
      "z": -17,
      "name": "Rock_Stone"
    },
    {
      "x": -9,
      "y": 12,
      "z": -17,
      "name": "Rock_Stone"
    },
    {
      "x": -9,
      "y": 0,
      "z": -16,
      "name": "Rock_Stone"
    },
    {
      "x": -9,
      "y": 1,
      "z": -16,
      "name": "Rock_Stone"
    },
    {
      "x": -9,
      "y": 2,
      "z": -16,
      "name": "Rock_Stone"
    },
    {
      "x": -9,
      "y": 3,
      "z": -16,
      "name": "Rock_Stone"
    },
    {
      "x": -9,
      "y": 4,
      "z": -16,
      "name": "Rock_Stone"
    },
    {
      "x": -9,
      "y": 5,
      "z": -16,
      "name": "Rock_Stone"
    },
    {
      "x": -9,
      "y": 6,
      "z": -16,
      "name": "Rock_Stone"
    },
    {
      "x": -9,
      "y": 7,
      "z": -16,
      "name": "Rock_Stone"
    },
    {
      "x": -9,
      "y": 8,
      "z": -16,
      "name": "Rock_Stone"
    },
    {
      "x": -9,
      "y": 9,
      "z": -16,
      "name": "Rock_Stone"
    },
    {
      "x": -9,
      "y": 10,
      "z": -16,
      "name": "Rock_Stone"
    },
    {
      "x": -9,
      "y": 11,
      "z": -16,
      "name": "Rock_Stone"
    },
    {
      "x": -9,
      "y": 12,
      "z": -16,
      "name": "Rock_Stone"
    },
    {
      "x": -9,
      "y": 0,
      "z": -15,
      "name": "Rock_Stone"
    },
    {
      "x": -9,
      "y": 1,
      "z": -15,
      "name": "Rock_Stone"
    },
    {
      "x": -9,
      "y": 2,
      "z": -15,
      "name": "Rock_Stone"
    },
    {
      "x": -9,
      "y": 3,
      "z": -15,
      "name": "Rock_Stone"
    },
    {
      "x": -9,
      "y": 4,
      "z": -15,
      "name": "Rock_Stone"
    },
    {
      "x": -9,
      "y": 5,
      "z": -15,
      "name": "Rock_Stone"
    },
    {
      "x": -9,
      "y": 6,
      "z": -15,
      "name": "Rock_Stone"
    },
    {
      "x": -9,
      "y": 7,
      "z": -15,
      "name": "Rock_Stone"
    },
    {
      "x": -9,
      "y": 8,
      "z": -15,
      "name": "Rock_Stone"
    },
    {
      "x": -9,
      "y": 9,
      "z": -15,
      "name": "Rock_Stone"
    },
    {
      "x": -9,
      "y": 10,
      "z": -15,
      "name": "Rock_Stone"
    },
    {
      "x": -9,
      "y": 11,
      "z": -15,
      "name": "Rock_Stone"
    },
    {
      "x": -9,
      "y": 12,
      "z": -15,
      "name": "Rock_Stone"
    },
    {
      "x": -9,
      "y": 0,
      "z": -14,
      "name": "Rock_Stone_Cobble"
    },
    {
      "x": -9,
      "y": 1,
      "z": -14,
      "name": "Rock_Stone_Brick_Smooth"
    },
    {
      "x": -9,
      "y": 2,
      "z": -14,
      "name": "Rock_Stone_Brick_Smooth"
    },
    {
      "x": -9,
      "y": 3,
      "z": -14,
      "name": "Rock_Stone_Brick_Smooth"
    },
    {
      "x": -9,
      "y": 4,
      "z": -14,
      "name": "Rock_Stone_Brick_Smooth"
    },
    {
      "x": -9,
      "y": 5,
      "z": -14,
      "name": "Rock_Stone_Brick_Smooth"
    },
    {
      "x": -9,
      "y": 6,
      "z": -14,
      "name": "Rock_Stone_Brick_Smooth"
    },
    {
      "x": -9,
      "y": 7,
      "z": -14,
      "name": "Rock_Stone_Brick_Smooth"
    },
    {
      "x": -9,
      "y": 8,
      "z": -14,
      "name": "Rock_Stone_Brick_Smooth"
    },
    {
      "x": -9,
      "y": 9,
      "z": -14,
      "name": "Rock_Stone_Brick_Smooth"
    },
    {
      "x": -9,
      "y": 10,
      "z": -14,
      "name": "*Rock_Stone_Brick_Smooth_Half_State_Definitions_Block",
      "rotation": 8
    },
    {
      "x": -9,
      "y": 11,
      "z": -14,
      "name": "Rock_Stone_Brick_Smooth"
    },
    {
      "x": -9,
      "y": 12,
      "z": -14,
      "name": "Rock_Stone"
    },
    {
      "x": -9,
      "y": 0,
      "z": -13,
      "name": "Rock_Stone_Cobble"
    },
    {
      "x": -9,
      "y": 1,
      "z": -13,
      "name": "Rock_Stone_Brick_Smooth_Half",
      "rotation": 4
    },
    {
      "x": -9,
      "y": 2,
      "z": -13,
      "name": "Rock_Stone_Brick_Smooth_Half",
      "rotation": 4
    },
    {
      "x": -9,
      "y": 3,
      "z": -13,
      "name": "Rock_Stone_Brick_Smooth_Half",
      "rotation": 4
    },
    {
      "x": -9,
      "y": 4,
      "z": -13,
      "name": "Rock_Stone_Brick_Smooth_Half",
      "rotation": 4
    },
    {
      "x": -9,
      "y": 5,
      "z": -13,
      "name": "Rock_Stone_Brick_Smooth"
    },
    {
      "x": -9,
      "y": 6,
      "z": -13,
      "name": "Rock_Stone_Brick_Smooth"
    },
    {
      "x": -9,
      "y": 7,
      "z": -13,
      "name": "Empty"
    },
    {
      "x": -9,
      "y": 8,
      "z": -13,
      "name": "Empty"
    },
    {
      "x": -9,
      "y": 9,
      "z": -13,
      "name": "Empty"
    },
    {
      "x": -9,
      "y": 10,
      "z": -13,
      "name": "Rock_Stone_Brick_Smooth_Half",
      "rotation": 4
    },
    {
      "x": -9,
      "y": 11,
      "z": -13,
      "name": "Rock_Stone_Brick_Smooth"
    },
    {
      "x": -9,
      "y": 12,
      "z": -13,
      "name": "Rock_Stone_Cobble"
    },
    {
      "x": -9,
      "y": 0,
      "z": -12,
      "name": "Rock_Stone_Brick"
    },
    {
      "x": -9,
      "y": 1,
      "z": -12,
      "name": "Empty"
    },
    {
      "x": -9,
      "y": 2,
      "z": -12,
      "name": "Empty"
    },
    {
      "x": -9,
      "y": 3,
      "z": -12,
      "name": "Empty"
    },
    {
      "x": -9,
      "y": 4,
      "z": -12,
      "name": "Empty"
    },
    {
      "x": -9,
      "y": 5,
      "z": -12,
      "name": "Rock_Stone_Brick_Smooth_Half",
      "rotation": 8
    },
    {
      "x": -9,
      "y": 6,
      "z": -12,
      "name": "Rock_Stone_Brick_Smooth"
    },
    {
      "x": -9,
      "y": 7,
      "z": -12,
      "name": "Empty"
    },
    {
      "x": -9,
      "y": 8,
      "z": -12,
      "name": "Empty"
    },
    {
      "x": -9,
      "y": 9,
      "z": -12,
      "name": "Empty"
    },
    {
      "x": -9,
      "y": 10,
      "z": -12,
      "name": "Empty"
    },
    {
      "x": -9,
      "y": 11,
      "z": -12,
      "name": "Rock_Stone_Brick_Smooth"
    },
    {
      "x": -9,
      "y": 12,
      "z": -12,
      "name": "Rock_Stone_Cobble"
    },
    {
      "x": -9,
      "y": 0,
      "z": -11,
      "name": "Rock_Stone_Brick"
    },
    {
      "x": -9,
      "y": 1,
      "z": -11,
      "name": "Empty"
    },
    {
      "x": -9,
      "y": 2,
      "z": -11,
      "name": "Empty"
    },
    {
      "x": -9,
      "y": 3,
      "z": -11,
      "name": "Empty"
    },
    {
      "x": -9,
      "y": 4,
      "z": -11,
      "name": "Empty"
    },
    {
      "x": -9,
      "y": 5,
      "z": -11,
      "name": "Rock_Stone_Brick_Smooth_Half",
      "rotation": 8
    },
    {
      "x": -9,
      "y": 6,
      "z": -11,
      "name": "Rock_Stone_Brick_Smooth"
    },
    {
      "x": -9,
      "y": 7,
      "z": -11,
      "name": "Empty"
    },
    {
      "x": -9,
      "y": 8,
      "z": -11,
      "name": "Empty"
    },
    {
      "x": -9,
      "y": 9,
      "z": -11,
      "name": "Empty"
    },
    {
      "x": -9,
      "y": 10,
      "z": -11,
      "name": "Empty"
    },
    {
      "x": -9,
      "y": 11,
      "z": -11,
      "name": "Rock_Stone_Brick_Smooth_Half",
      "rotation": 8
    },
    {
      "x": -9,
      "y": 12,
      "z": -11,
      "name": "Rock_Stone_Cobble"
    },
    {
      "x": -9,
      "y": 0,
      "z": -10,
      "name": "Rock_Stone_Brick"
    },
    {
      "x": -9,
      "y": 1,
      "z": -10,
      "name": "Empty"
    },
    {
      "x": -9,
      "y": 2,
      "z": -10,
      "name": "Empty"
    },
    {
      "x": -9,
      "y": 3,
      "z": -10,
      "name": "Empty"
    },
    {
      "x": -9,
      "y": 4,
      "z": -10,
      "name": "Empty"
    },
    {
      "x": -9,
      "y": 5,
      "z": -10,
      "name": "Rock_Stone_Brick_Smooth_Half",
      "rotation": 8
    },
    {
      "x": -9,
      "y": 6,
      "z": -10,
      "name": "Rock_Stone_Brick_Smooth"
    },
    {
      "x": -9,
      "y": 7,
      "z": -10,
      "name": "Empty"
    },
    {
      "x": -9,
      "y": 8,
      "z": -10,
      "name": "Empty"
    },
    {
      "x": -9,
      "y": 9,
      "z": -10,
      "name": "Empty"
    },
    {
      "x": -9,
      "y": 10,
      "z": -10,
      "name": "Empty"
    },
    {
      "x": -9,
      "y": 11,
      "z": -10,
      "name": "Rock_Stone_Brick_Smooth"
    },
    {
      "x": -9,
      "y": 12,
      "z": -10,
      "name": "Rock_Stone_Cobble"
    },
    {
      "x": -9,
      "y": 0,
      "z": -9,
      "name": "Rock_Stone_Brick"
    },
    {
      "x": -9,
      "y": 1,
      "z": -9,
      "name": "Rock_Stone_Brick_Smooth_Half",
      "rotation": 6
    },
    {
      "x": -9,
      "y": 2,
      "z": -9,
      "name": "Rock_Stone_Brick_Smooth_Half",
      "rotation": 6
    },
    {
      "x": -9,
      "y": 3,
      "z": -9,
      "name": "Rock_Stone_Brick_Smooth_Half",
      "rotation": 6
    },
    {
      "x": -9,
      "y": 4,
      "z": -9,
      "name": "Rock_Stone_Brick_Smooth_Half",
      "rotation": 6
    },
    {
      "x": -9,
      "y": 5,
      "z": -9,
      "name": "Rock_Stone_Brick_Smooth"
    },
    {
      "x": -9,
      "y": 6,
      "z": -9,
      "name": "Rock_Stone_Brick_Smooth"
    },
    {
      "x": -9,
      "y": 7,
      "z": -9,
      "name": "Empty"
    },
    {
      "x": -9,
      "y": 8,
      "z": -9,
      "name": "Empty"
    },
    {
      "x": -9,
      "y": 9,
      "z": -9,
      "name": "Empty"
    },
    {
      "x": -9,
      "y": 10,
      "z": -9,
      "name": "Rock_Stone_Brick_Smooth_Half",
      "rotation": 6
    },
    {
      "x": -9,
      "y": 11,
      "z": -9,
      "name": "Rock_Stone_Brick_Smooth"
    },
    {
      "x": -9,
      "y": 12,
      "z": -9,
      "name": "Rock_Stone_Cobble"
    },
    {
      "x": -9,
      "y": 0,
      "z": -8,
      "name": "Plant_Moss_Block_Blue"
    },
    {
      "x": -9,
      "y": 1,
      "z": -8,
      "name": "Rock_Stone_Brick_Smooth"
    },
    {
      "x": -9,
      "y": 2,
      "z": -8,
      "name": "Rock_Stone_Brick_Smooth"
    },
    {
      "x": -9,
      "y": 3,
      "z": -8,
      "name": "Rock_Stone_Brick_Smooth"
    },
    {
      "x": -9,
      "y": 4,
      "z": -8,
      "name": "Rock_Stone_Brick_Smooth"
    },
    {
      "x": -9,
      "y": 5,
      "z": -8,
      "name": "Rock_Stone_Brick_Smooth"
    },
    {
      "x": -9,
      "y": 6,
      "z": -8,
      "name": "Rock_Stone_Brick_Smooth"
    },
    {
      "x": -9,
      "y": 7,
      "z": -8,
      "name": "Rock_Stone_Brick_Smooth"
    },
    {
      "x": -9,
      "y": 8,
      "z": -8,
      "name": "Rock_Stone_Brick_Smooth"
    },
    {
      "x": -9,
      "y": 9,
      "z": -8,
      "name": "Rock_Stone_Brick_Smooth"
    },
    {
      "x": -9,
      "y": 10,
      "z": -8,
      "name": "Rock_Stone_Brick_Smooth"
    },
    {
      "x": -9,
      "y": 11,
      "z": -8,
      "name": "Rock_Stone_Brick_Smooth"
    },
    {
      "x": -9,
      "y": 12,
      "z": -8,
      "name": "Rock_Stone_Cobble"
    },
    {
      "x": -9,
      "y": 0,
      "z": -7,
      "name": "Plant_Moss_Block_Blue"
    },
    {
      "x": -9,
      "y": 1,
      "z": -7,
      "name": "Rock_Stone_Brick_Smooth"
    },
    {
      "x": -9,
      "y": 2,
      "z": -7,
      "name": "Rock_Stone_Brick_Smooth"
    },
    {
      "x": -9,
      "y": 3,
      "z": -7,
      "name": "Rock_Stone_Brick_Smooth"
    },
    {
      "x": -9,
      "y": 4,
      "z": -7,
      "name": "Rock_Stone_Brick_Smooth"
    },
    {
      "x": -9,
      "y": 5,
      "z": -7,
      "name": "Rock_Stone_Brick_Smooth"
    },
    {
      "x": -9,
      "y": 6,
      "z": -7,
      "name": "Rock_Stone_Brick_Smooth"
    },
    {
      "x": -9,
      "y": 7,
      "z": -7,
      "name": "Rock_Stone_Brick_Smooth"
    },
    {
      "x": -9,
      "y": 8,
      "z": -7,
      "name": "Rock_Stone_Brick_Smooth"
    },
    {
      "x": -9,
      "y": 9,
      "z": -7,
      "name": "Rock_Stone_Brick_Smooth"
    },
    {
      "x": -9,
      "y": 10,
      "z": -7,
      "name": "Rock_Stone_Brick_Smooth"
    },
    {
      "x": -9,
      "y": 11,
      "z": -7,
      "name": "Rock_Stone_Brick_Smooth"
    },
    {
      "x": -9,
      "y": 12,
      "z": -7,
      "name": "Rock_Stone_Cobble"
    },
    {
      "x": -9,
      "y": 0,
      "z": -6,
      "name": "Rock_Stone_Cobble"
    },
    {
      "x": -9,
      "y": 1,
      "z": -6,
      "name": "Soil_Ash"
    },
    {
      "x": -9,
      "y": 2,
      "z": -6,
      "name": "Furniture_Ancient_Crate",
      "rotation": 1
    },
    {
      "x": -9,
      "y": 3,
      "z": -6,
      "name": "Empty"
    },
    {
      "x": -9,
      "y": 4,
      "z": -6,
      "name": "Empty"
    },
    {
      "x": -9,
      "y": 5,
      "z": -6,
      "name": "Rock_Stone_Brick_Smooth_Half",
      "rotation": 4
    },
    {
      "x": -9,
      "y": 6,
      "z": -6,
      "name": "Rock_Stone_Brick_Smooth"
    },
    {
      "x": -9,
      "y": 7,
      "z": -6,
      "name": "Empty"
    },
    {
      "x": -9,
      "y": 8,
      "z": -6,
      "name": "Empty"
    },
    {
      "x": -9,
      "y": 9,
      "z": -6,
      "name": "Empty"
    },
    {
      "x": -9,
      "y": 10,
      "z": -6,
      "name": "Empty"
    },
    {
      "x": -9,
      "y": 11,
      "z": -6,
      "name": "Empty"
    },
    {
      "x": -9,
      "y": 12,
      "z": -6,
      "name": "Rock_Stone_Cobble"
    },
    {
      "x": -9,
      "y": 0,
      "z": -5,
      "name": "Rock_Stone_Cobble"
    },
    {
      "x": -9,
      "y": 1,
      "z": -5,
      "name": "Soil_Ash"
    },
    {
      "x": -9,
      "y": 2,
      "z": -5,
      "name": "Empty"
    },
    {
      "x": -9,
      "y": 3,
      "z": -5,
      "name": "Empty"
    },
    {
      "x": -9,
      "y": 4,
      "z": -5,
      "name": "Empty"
    },
    {
      "x": -9,
      "y": 5,
      "z": -5,
      "name": "Empty"
    },
    {
      "x": -9,
      "y": 6,
      "z": -5,
      "name": "Empty"
    },
    {
      "x": -9,
      "y": 7,
      "z": -5,
      "name": "Empty"
    },
    {
      "x": -9,
      "y": 8,
      "z": -5,
      "name": "Empty"
    },
    {
      "x": -9,
      "y": 9,
      "z": -5,
      "name": "Empty"
    },
    {
      "x": -9,
      "y": 10,
      "z": -5,
      "name": "Empty"
    },
    {
      "x": -9,
      "y": 11,
      "z": -5,
      "name": "Empty"
    },
    {
      "x": -9,
      "y": 12,
      "z": -5,
      "name": "Rock_Stone_Cobble"
    },
    {
      "x": -9,
      "y": 0,
      "z": -4,
      "name": "Rock_Stone_Cobble"
    },
    {
      "x": -9,
      "y": 1,
      "z": -4,
      "name": "Soil_Ash"
    },
    {
      "x": -9,
      "y": 2,
      "z": -4,
      "name": "Deco_Bone_Skulls"
    },
    {
      "x": -9,
      "y": 3,
      "z": -4,
      "name": "Empty"
    },
    {
      "x": -9,
      "y": 4,
      "z": -4,
      "name": "Empty"
    },
    {
      "x": -9,
      "y": 5,
      "z": -4,
      "name": "Empty"
    },
    {
      "x": -9,
      "y": 6,
      "z": -4,
      "name": "Empty"
    },
    {
      "x": -9,
      "y": 7,
      "z": -4,
      "name": "Empty"
    },
    {
      "x": -9,
      "y": 8,
      "z": -4,
      "name": "Empty"
    },
    {
      "x": -9,
      "y": 9,
      "z": -4,
      "name": "Empty"
    },
    {
      "x": -9,
      "y": 10,
      "z": -4,
      "name": "Empty"
    },
    {
      "x": -9,
      "y": 11,
      "z": -4,
      "name": "Empty"
    },
    {
      "x": -9,
      "y": 12,
      "z": -4,
      "name": "Rock_Stone_Cobble"
    },
    {
      "x": -9,
      "y": 0,
      "z": -3,
      "name": "Rock_Stone_Cobble"
    },
    {
      "x": -9,
      "y": 1,
      "z": -3,
      "name": "Soil_Ash"
    },
    {
      "x": -9,
      "y": 2,
      "z": -3,
      "name": "Deco_Bone_Skulls"
    },
    {
      "x": -9,
      "y": 3,
      "z": -3,
      "name": "Empty"
    },
    {
      "x": -9,
      "y": 4,
      "z": -3,
      "name": "Empty"
    },
    {
      "x": -9,
      "y": 5,
      "z": -3,
      "name": "Empty"
    },
    {
      "x": -9,
      "y": 6,
      "z": -3,
      "name": "Empty"
    },
    {
      "x": -9,
      "y": 7,
      "z": -3,
      "name": "Empty"
    },
    {
      "x": -9,
      "y": 8,
      "z": -3,
      "name": "Empty"
    },
    {
      "x": -9,
      "y": 9,
      "z": -3,
      "name": "Empty"
    },
    {
      "x": -9,
      "y": 10,
      "z": -3,
      "name": "Empty"
    },
    {
      "x": -9,
      "y": 11,
      "z": -3,
      "name": "Empty"
    },
    {
      "x": -9,
      "y": 12,
      "z": -3,
      "name": "Rock_Stone_Cobble"
    },
    {
      "x": -9,
      "y": 0,
      "z": -2,
      "name": "Rock_Stone_Cobble"
    },
    {
      "x": -9,
      "y": 1,
      "z": -2,
      "name": "Soil_Ash"
    },
    {
      "x": -9,
      "y": 2,
      "z": -2,
      "name": "Deco_Bone_Skulls"
    },
    {
      "x": -9,
      "y": 3,
      "z": -2,
      "name": "Empty"
    },
    {
      "x": -9,
      "y": 4,
      "z": -2,
      "name": "Empty"
    },
    {
      "x": -9,
      "y": 5,
      "z": -2,
      "name": "Empty"
    },
    {
      "x": -9,
      "y": 6,
      "z": -2,
      "name": "Empty"
    },
    {
      "x": -9,
      "y": 7,
      "z": -2,
      "name": "Empty"
    },
    {
      "x": -9,
      "y": 8,
      "z": -2,
      "name": "Empty"
    },
    {
      "x": -9,
      "y": 9,
      "z": -2,
      "name": "Empty"
    },
    {
      "x": -9,
      "y": 10,
      "z": -2,
      "name": "Empty"
    },
    {
      "x": -9,
      "y": 11,
      "z": -2,
      "name": "Empty"
    },
    {
      "x": -9,
      "y": 12,
      "z": -2,
      "name": "Rock_Stone_Cobble"
    },
    {
      "x": -9,
      "y": 0,
      "z": -1,
      "name": "Rock_Stone_Cobble"
    },
    {
      "x": -9,
      "y": 1,
      "z": -1,
      "name": "Soil_Ash"
    },
    {
      "x": -9,
      "y": 2,
      "z": -1,
      "name": "Deco_Bone_Skulls_Wall",
      "rotation": 2
    },
    {
      "x": -9,
      "y": 3,
      "z": -1,
      "name": "Deco_Bone_Skulls_Wall",
      "rotation": 2
    },
    {
      "x": -9,
      "y": 4,
      "z": -1,
      "name": "Deco_Bone_Skulls_Wall",
      "rotation": 2
    },
    {
      "x": -9,
      "y": 5,
      "z": -1,
      "name": "Rock_Stone_Brick_Smooth_Half",
      "rotation": 4
    },
    {
      "x": -9,
      "y": 6,
      "z": -1,
      "name": "Empty"
    },
    {
      "x": -9,
      "y": 7,
      "z": -1,
      "name": "Empty"
    },
    {
      "x": -9,
      "y": 8,
      "z": -1,
      "name": "Empty"
    },
    {
      "x": -9,
      "y": 9,
      "z": -1,
      "name": "Empty"
    },
    {
      "x": -9,
      "y": 10,
      "z": -1,
      "name": "Empty"
    },
    {
      "x": -9,
      "y": 11,
      "z": -1,
      "name": "Empty"
    },
    {
      "x": -9,
      "y": 12,
      "z": -1,
      "name": "Rock_Stone_Cobble"
    },
    {
      "x": -9,
      "y": 0,
      "z": 0,
      "name": "Rock_Stone_Cobble"
    },
    {
      "x": -9,
      "y": 1,
      "z": 0,
      "name": "Rock_Stone_Brick_Smooth"
    },
    {
      "x": -9,
      "y": 2,
      "z": 0,
      "name": "Rock_Stone_Brick_Smooth"
    },
    {
      "x": -9,
      "y": 3,
      "z": 0,
      "name": "Rock_Stone_Brick_Smooth"
    },
    {
      "x": -9,
      "y": 4,
      "z": 0,
      "name": "Rock_Stone_Brick_Smooth"
    },
    {
      "x": -9,
      "y": 5,
      "z": 0,
      "name": "Rock_Stone_Brick_Smooth"
    },
    {
      "x": -9,
      "y": 6,
      "z": 0,
      "name": "Rock_Stone_Brick_Smooth"
    },
    {
      "x": -9,
      "y": 7,
      "z": 0,
      "name": "Rock_Stone_Brick_Smooth"
    },
    {
      "x": -9,
      "y": 8,
      "z": 0,
      "name": "Rock_Stone_Brick_Smooth_Half",
      "rotation": 5
    },
    {
      "x": -9,
      "y": 9,
      "z": 0,
      "name": "Rock_Stone_Brick_Smooth_Half",
      "rotation": 5
    },
    {
      "x": -9,
      "y": 10,
      "z": 0,
      "name": "Rock_Stone_Brick_Smooth"
    },
    {
      "x": -9,
      "y": 11,
      "z": 0,
      "name": "Rock_Stone_Brick_Smooth"
    },
    {
      "x": -9,
      "y": 12,
      "z": 0,
      "name": "Rock_Stone"
    },
    {
      "x": -8,
      "y": 0,
      "z": -22,
      "name": "Rock_Stone"
    },
    {
      "x": -8,
      "y": 1,
      "z": -22,
      "name": "Rock_Stone"
    },
    {
      "x": -8,
      "y": 2,
      "z": -22,
      "name": "Rock_Stone"
    },
    {
      "x": -8,
      "y": 3,
      "z": -22,
      "name": "Rock_Stone"
    },
    {
      "x": -8,
      "y": 4,
      "z": -22,
      "name": "Rock_Stone"
    },
    {
      "x": -8,
      "y": 5,
      "z": -22,
      "name": "Rock_Stone"
    },
    {
      "x": -8,
      "y": 6,
      "z": -22,
      "name": "Rock_Stone"
    },
    {
      "x": -8,
      "y": 7,
      "z": -22,
      "name": "Rock_Stone"
    },
    {
      "x": -8,
      "y": 8,
      "z": -22,
      "name": "Rock_Stone"
    },
    {
      "x": -8,
      "y": 9,
      "z": -22,
      "name": "Rock_Stone"
    },
    {
      "x": -8,
      "y": 10,
      "z": -22,
      "name": "Rock_Stone"
    },
    {
      "x": -8,
      "y": 11,
      "z": -22,
      "name": "Rock_Stone"
    },
    {
      "x": -8,
      "y": 12,
      "z": -22,
      "name": "Rock_Stone"
    },
    {
      "x": -8,
      "y": 0,
      "z": -21,
      "name": "Rock_Stone"
    },
    {
      "x": -8,
      "y": 1,
      "z": -21,
      "name": "Rock_Stone"
    },
    {
      "x": -8,
      "y": 2,
      "z": -21,
      "name": "Rock_Stone"
    },
    {
      "x": -8,
      "y": 3,
      "z": -21,
      "name": "Rock_Stone"
    },
    {
      "x": -8,
      "y": 4,
      "z": -21,
      "name": "Rock_Stone"
    },
    {
      "x": -8,
      "y": 5,
      "z": -21,
      "name": "Rock_Stone"
    },
    {
      "x": -8,
      "y": 6,
      "z": -21,
      "name": "Rock_Stone"
    },
    {
      "x": -8,
      "y": 7,
      "z": -21,
      "name": "Rock_Stone"
    },
    {
      "x": -8,
      "y": 8,
      "z": -21,
      "name": "Rock_Stone"
    },
    {
      "x": -8,
      "y": 9,
      "z": -21,
      "name": "Rock_Stone"
    },
    {
      "x": -8,
      "y": 10,
      "z": -21,
      "name": "Rock_Stone"
    },
    {
      "x": -8,
      "y": 11,
      "z": -21,
      "name": "Rock_Stone"
    },
    {
      "x": -8,
      "y": 12,
      "z": -21,
      "name": "Rock_Stone"
    },
    {
      "x": -8,
      "y": 0,
      "z": -20,
      "name": "Rock_Stone"
    },
    {
      "x": -8,
      "y": 1,
      "z": -20,
      "name": "Rock_Stone"
    },
    {
      "x": -8,
      "y": 2,
      "z": -20,
      "name": "Rock_Stone"
    },
    {
      "x": -8,
      "y": 3,
      "z": -20,
      "name": "Rock_Stone"
    },
    {
      "x": -8,
      "y": 4,
      "z": -20,
      "name": "Rock_Stone"
    },
    {
      "x": -8,
      "y": 5,
      "z": -20,
      "name": "Rock_Stone"
    },
    {
      "x": -8,
      "y": 6,
      "z": -20,
      "name": "Rock_Stone"
    },
    {
      "x": -8,
      "y": 7,
      "z": -20,
      "name": "Rock_Stone"
    },
    {
      "x": -8,
      "y": 8,
      "z": -20,
      "name": "Rock_Stone"
    },
    {
      "x": -8,
      "y": 9,
      "z": -20,
      "name": "Rock_Stone"
    },
    {
      "x": -8,
      "y": 10,
      "z": -20,
      "name": "Rock_Stone"
    },
    {
      "x": -8,
      "y": 11,
      "z": -20,
      "name": "Rock_Stone"
    },
    {
      "x": -8,
      "y": 12,
      "z": -20,
      "name": "Rock_Stone"
    },
    {
      "x": -8,
      "y": 0,
      "z": -19,
      "name": "Rock_Stone"
    },
    {
      "x": -8,
      "y": 1,
      "z": -19,
      "name": "Rock_Stone"
    },
    {
      "x": -8,
      "y": 2,
      "z": -19,
      "name": "Rock_Stone"
    },
    {
      "x": -8,
      "y": 3,
      "z": -19,
      "name": "Rock_Stone"
    },
    {
      "x": -8,
      "y": 4,
      "z": -19,
      "name": "Rock_Stone"
    },
    {
      "x": -8,
      "y": 5,
      "z": -19,
      "name": "Rock_Stone"
    },
    {
      "x": -8,
      "y": 6,
      "z": -19,
      "name": "Rock_Stone"
    },
    {
      "x": -8,
      "y": 7,
      "z": -19,
      "name": "Rock_Stone"
    },
    {
      "x": -8,
      "y": 8,
      "z": -19,
      "name": "Rock_Stone"
    },
    {
      "x": -8,
      "y": 9,
      "z": -19,
      "name": "Rock_Stone"
    },
    {
      "x": -8,
      "y": 10,
      "z": -19,
      "name": "Rock_Stone"
    },
    {
      "x": -8,
      "y": 11,
      "z": -19,
      "name": "Rock_Stone"
    },
    {
      "x": -8,
      "y": 12,
      "z": -19,
      "name": "Rock_Stone"
    },
    {
      "x": -8,
      "y": 0,
      "z": -18,
      "name": "Rock_Stone"
    },
    {
      "x": -8,
      "y": 1,
      "z": -18,
      "name": "Rock_Stone"
    },
    {
      "x": -8,
      "y": 2,
      "z": -18,
      "name": "Rock_Stone"
    },
    {
      "x": -8,
      "y": 3,
      "z": -18,
      "name": "Rock_Stone"
    },
    {
      "x": -8,
      "y": 4,
      "z": -18,
      "name": "Rock_Stone"
    },
    {
      "x": -8,
      "y": 5,
      "z": -18,
      "name": "Rock_Stone"
    },
    {
      "x": -8,
      "y": 6,
      "z": -18,
      "name": "Rock_Stone"
    },
    {
      "x": -8,
      "y": 7,
      "z": -18,
      "name": "Rock_Stone"
    },
    {
      "x": -8,
      "y": 8,
      "z": -18,
      "name": "Rock_Stone"
    },
    {
      "x": -8,
      "y": 9,
      "z": -18,
      "name": "Rock_Stone"
    },
    {
      "x": -8,
      "y": 10,
      "z": -18,
      "name": "Rock_Stone"
    },
    {
      "x": -8,
      "y": 11,
      "z": -18,
      "name": "Rock_Stone"
    },
    {
      "x": -8,
      "y": 12,
      "z": -18,
      "name": "Rock_Stone"
    },
    {
      "x": -8,
      "y": 0,
      "z": -17,
      "name": "Rock_Stone"
    },
    {
      "x": -8,
      "y": 1,
      "z": -17,
      "name": "Rock_Stone"
    },
    {
      "x": -8,
      "y": 2,
      "z": -17,
      "name": "Rock_Stone"
    },
    {
      "x": -8,
      "y": 3,
      "z": -17,
      "name": "Rock_Stone"
    },
    {
      "x": -8,
      "y": 4,
      "z": -17,
      "name": "Rock_Stone"
    },
    {
      "x": -8,
      "y": 5,
      "z": -17,
      "name": "Rock_Stone"
    },
    {
      "x": -8,
      "y": 6,
      "z": -17,
      "name": "Rock_Stone"
    },
    {
      "x": -8,
      "y": 7,
      "z": -17,
      "name": "Rock_Stone"
    },
    {
      "x": -8,
      "y": 8,
      "z": -17,
      "name": "Rock_Stone"
    },
    {
      "x": -8,
      "y": 9,
      "z": -17,
      "name": "Rock_Stone"
    },
    {
      "x": -8,
      "y": 10,
      "z": -17,
      "name": "Rock_Stone"
    },
    {
      "x": -8,
      "y": 11,
      "z": -17,
      "name": "Rock_Stone"
    },
    {
      "x": -8,
      "y": 12,
      "z": -17,
      "name": "Rock_Stone"
    },
    {
      "x": -8,
      "y": 0,
      "z": -16,
      "name": "Rock_Stone"
    },
    {
      "x": -8,
      "y": 1,
      "z": -16,
      "name": "Rock_Stone"
    },
    {
      "x": -8,
      "y": 2,
      "z": -16,
      "name": "Rock_Stone"
    },
    {
      "x": -8,
      "y": 3,
      "z": -16,
      "name": "Rock_Stone"
    },
    {
      "x": -8,
      "y": 4,
      "z": -16,
      "name": "Rock_Stone"
    },
    {
      "x": -8,
      "y": 5,
      "z": -16,
      "name": "Rock_Stone"
    },
    {
      "x": -8,
      "y": 6,
      "z": -16,
      "name": "Rock_Stone"
    },
    {
      "x": -8,
      "y": 7,
      "z": -16,
      "name": "Rock_Stone"
    },
    {
      "x": -8,
      "y": 8,
      "z": -16,
      "name": "Rock_Stone"
    },
    {
      "x": -8,
      "y": 9,
      "z": -16,
      "name": "Rock_Stone"
    },
    {
      "x": -8,
      "y": 10,
      "z": -16,
      "name": "Rock_Stone"
    },
    {
      "x": -8,
      "y": 11,
      "z": -16,
      "name": "Rock_Stone"
    },
    {
      "x": -8,
      "y": 12,
      "z": -16,
      "name": "Rock_Stone"
    },
    {
      "x": -8,
      "y": 0,
      "z": -15,
      "name": "Rock_Stone"
    },
    {
      "x": -8,
      "y": 1,
      "z": -15,
      "name": "Rock_Stone"
    },
    {
      "x": -8,
      "y": 2,
      "z": -15,
      "name": "Rock_Stone"
    },
    {
      "x": -8,
      "y": 3,
      "z": -15,
      "name": "Rock_Stone"
    },
    {
      "x": -8,
      "y": 4,
      "z": -15,
      "name": "Rock_Stone"
    },
    {
      "x": -8,
      "y": 5,
      "z": -15,
      "name": "Rock_Stone"
    },
    {
      "x": -8,
      "y": 6,
      "z": -15,
      "name": "Rock_Stone"
    },
    {
      "x": -8,
      "y": 7,
      "z": -15,
      "name": "Rock_Stone"
    },
    {
      "x": -8,
      "y": 8,
      "z": -15,
      "name": "Rock_Stone"
    },
    {
      "x": -8,
      "y": 9,
      "z": -15,
      "name": "Rock_Stone"
    },
    {
      "x": -8,
      "y": 10,
      "z": -15,
      "name": "Rock_Stone"
    },
    {
      "x": -8,
      "y": 11,
      "z": -15,
      "name": "Rock_Stone"
    },
    {
      "x": -8,
      "y": 12,
      "z": -15,
      "name": "Rock_Stone"
    },
    {
      "x": -8,
      "y": 0,
      "z": -14,
      "name": "Rock_Stone"
    },
    {
      "x": -8,
      "y": 1,
      "z": -14,
      "name": "Rock_Stone_Brick_Smooth"
    },
    {
      "x": -8,
      "y": 2,
      "z": -14,
      "name": "Rock_Stone_Brick_Smooth"
    },
    {
      "x": -8,
      "y": 3,
      "z": -14,
      "name": "Rock_Stone_Brick_Smooth"
    },
    {
      "x": -8,
      "y": 4,
      "z": -14,
      "name": "Rock_Stone_Brick_Smooth"
    },
    {
      "x": -8,
      "y": 5,
      "z": -14,
      "name": "Rock_Stone_Brick_Smooth"
    },
    {
      "x": -8,
      "y": 6,
      "z": -14,
      "name": "Rock_Stone_Brick_Smooth"
    },
    {
      "x": -8,
      "y": 7,
      "z": -14,
      "name": "Rock_Stone_Brick_Smooth"
    },
    {
      "x": -8,
      "y": 8,
      "z": -14,
      "name": "Rock_Stone_Brick_Smooth"
    },
    {
      "x": -8,
      "y": 9,
      "z": -14,
      "name": "Rock_Stone_Brick_Smooth"
    },
    {
      "x": -8,
      "y": 10,
      "z": -14,
      "name": "Rock_Stone_Brick_Smooth"
    },
    {
      "x": -8,
      "y": 11,
      "z": -14,
      "name": "Rock_Stone_Brick_Smooth"
    },
    {
      "x": -8,
      "y": 12,
      "z": -14,
      "name": "Rock_Stone"
    },
    {
      "x": -8,
      "y": 0,
      "z": -13,
      "name": "Rock_Stone_Cobble"
    },
    {
      "x": -8,
      "y": 1,
      "z": -13,
      "name": "Empty"
    },
    {
      "x": -8,
      "y": 2,
      "z": -13,
      "name": "Empty"
    },
    {
      "x": -8,
      "y": 3,
      "z": -13,
      "name": "Empty"
    },
    {
      "x": -8,
      "y": 4,
      "z": -13,
      "name": "Empty"
    },
    {
      "x": -8,
      "y": 5,
      "z": -13,
      "name": "Empty"
    },
    {
      "x": -8,
      "y": 6,
      "z": -13,
      "name": "Empty"
    },
    {
      "x": -8,
      "y": 7,
      "z": -13,
      "name": "Empty"
    },
    {
      "x": -8,
      "y": 8,
      "z": -13,
      "name": "Empty"
    },
    {
      "x": -8,
      "y": 9,
      "z": -13,
      "name": "Empty"
    },
    {
      "x": -8,
      "y": 10,
      "z": -13,
      "name": "Rock_Stone_Brick_Smooth_Half",
      "rotation": 5
    },
    {
      "x": -8,
      "y": 11,
      "z": -13,
      "name": "Rock_Stone_Brick_Smooth"
    },
    {
      "x": -8,
      "y": 12,
      "z": -13,
      "name": "Rock_Stone_Cobble"
    },
    {
      "x": -8,
      "y": 0,
      "z": -12,
      "name": "Rock_Stone_Brick"
    },
    {
      "x": -8,
      "y": 1,
      "z": -12,
      "name": "Empty"
    },
    {
      "x": -8,
      "y": 2,
      "z": -12,
      "name": "Empty"
    },
    {
      "x": -8,
      "y": 3,
      "z": -12,
      "name": "Empty"
    },
    {
      "x": -8,
      "y": 4,
      "z": -12,
      "name": "Empty"
    },
    {
      "x": -8,
      "y": 5,
      "z": -12,
      "name": "Empty"
    },
    {
      "x": -8,
      "y": 6,
      "z": -12,
      "name": "Empty"
    },
    {
      "x": -8,
      "y": 7,
      "z": -12,
      "name": "Empty"
    },
    {
      "x": -8,
      "y": 8,
      "z": -12,
      "name": "Empty"
    },
    {
      "x": -8,
      "y": 9,
      "z": -12,
      "name": "Empty"
    },
    {
      "x": -8,
      "y": 10,
      "z": -12,
      "name": "Empty"
    },
    {
      "x": -8,
      "y": 11,
      "z": -12,
      "name": "Empty"
    },
    {
      "x": -8,
      "y": 12,
      "z": -12,
      "name": "Rock_Stone_Cobble"
    },
    {
      "x": -8,
      "y": 0,
      "z": -11,
      "name": "Rock_Stone_Brick"
    },
    {
      "x": -8,
      "y": 1,
      "z": -11,
      "name": "Empty"
    },
    {
      "x": -8,
      "y": 2,
      "z": -11,
      "name": "Empty"
    },
    {
      "x": -8,
      "y": 3,
      "z": -11,
      "name": "Empty"
    },
    {
      "x": -8,
      "y": 4,
      "z": -11,
      "name": "Empty"
    },
    {
      "x": -8,
      "y": 5,
      "z": -11,
      "name": "Empty"
    },
    {
      "x": -8,
      "y": 6,
      "z": -11,
      "name": "Empty"
    },
    {
      "x": -8,
      "y": 7,
      "z": -11,
      "name": "Empty"
    },
    {
      "x": -8,
      "y": 8,
      "z": -11,
      "name": "Empty"
    },
    {
      "x": -8,
      "y": 9,
      "z": -11,
      "name": "Empty"
    },
    {
      "x": -8,
      "y": 10,
      "z": -11,
      "name": "Empty"
    },
    {
      "x": -8,
      "y": 11,
      "z": -11,
      "name": "Empty"
    },
    {
      "x": -8,
      "y": 12,
      "z": -11,
      "name": "Rock_Stone_Cobble"
    },
    {
      "x": -8,
      "y": 0,
      "z": -10,
      "name": "Rock_Stone_Brick"
    },
    {
      "x": -8,
      "y": 1,
      "z": -10,
      "name": "Empty"
    },
    {
      "x": -8,
      "y": 2,
      "z": -10,
      "name": "Empty"
    },
    {
      "x": -8,
      "y": 3,
      "z": -10,
      "name": "Empty"
    },
    {
      "x": -8,
      "y": 4,
      "z": -10,
      "name": "Empty"
    },
    {
      "x": -8,
      "y": 5,
      "z": -10,
      "name": "Empty"
    },
    {
      "x": -8,
      "y": 6,
      "z": -10,
      "name": "Empty"
    },
    {
      "x": -8,
      "y": 7,
      "z": -10,
      "name": "Empty"
    },
    {
      "x": -8,
      "y": 8,
      "z": -10,
      "name": "Empty"
    },
    {
      "x": -8,
      "y": 9,
      "z": -10,
      "name": "Empty"
    },
    {
      "x": -8,
      "y": 10,
      "z": -10,
      "name": "Empty"
    },
    {
      "x": -8,
      "y": 11,
      "z": -10,
      "name": "Empty"
    },
    {
      "x": -8,
      "y": 12,
      "z": -10,
      "name": "Rock_Stone_Cobble"
    },
    {
      "x": -8,
      "y": 0,
      "z": -9,
      "name": "Rock_Stone_Cobble"
    },
    {
      "x": -8,
      "y": 1,
      "z": -9,
      "name": "Empty"
    },
    {
      "x": -8,
      "y": 2,
      "z": -9,
      "name": "Empty"
    },
    {
      "x": -8,
      "y": 3,
      "z": -9,
      "name": "Empty"
    },
    {
      "x": -8,
      "y": 4,
      "z": -9,
      "name": "Empty"
    },
    {
      "x": -8,
      "y": 5,
      "z": -9,
      "name": "Empty"
    },
    {
      "x": -8,
      "y": 6,
      "z": -9,
      "name": "Empty"
    },
    {
      "x": -8,
      "y": 7,
      "z": -9,
      "name": "Empty"
    },
    {
      "x": -8,
      "y": 8,
      "z": -9,
      "name": "Empty"
    },
    {
      "x": -8,
      "y": 9,
      "z": -9,
      "name": "Empty"
    },
    {
      "x": -8,
      "y": 10,
      "z": -9,
      "name": "Empty"
    },
    {
      "x": -8,
      "y": 11,
      "z": -9,
      "name": "Empty"
    },
    {
      "x": -8,
      "y": 12,
      "z": -9,
      "name": "Rock_Stone_Cobble"
    },
    {
      "x": -8,
      "y": 0,
      "z": -8,
      "name": "Soil_Ash"
    },
    {
      "x": -8,
      "y": 1,
      "z": -8,
      "name": "Rubble_Stone"
    },
    {
      "x": -8,
      "y": 2,
      "z": -8,
      "name": "Empty"
    },
    {
      "x": -8,
      "y": 3,
      "z": -8,
      "name": "Empty"
    },
    {
      "x": -8,
      "y": 4,
      "z": -8,
      "name": "Empty"
    },
    {
      "x": -8,
      "y": 5,
      "z": -8,
      "name": "Rock_Stone_Brick_Smooth_Half",
      "rotation": 5
    },
    {
      "x": -8,
      "y": 6,
      "z": -8,
      "name": "Rock_Stone_Brick_Smooth"
    },
    {
      "x": -8,
      "y": 7,
      "z": -8,
      "name": "Empty"
    },
    {
      "x": -8,
      "y": 8,
      "z": -8,
      "name": "Empty"
    },
    {
      "x": -8,
      "y": 9,
      "z": -8,
      "name": "Empty"
    },
    {
      "x": -8,
      "y": 10,
      "z": -8,
      "name": "Rock_Stone_Brick_Smooth_Half",
      "rotation": 5
    },
    {
      "x": -8,
      "y": 11,
      "z": -8,
      "name": "Rock_Stone_Brick_Smooth"
    },
    {
      "x": -8,
      "y": 12,
      "z": -8,
      "name": "Rock_Stone_Cobble"
    },
    {
      "x": -8,
      "y": 0,
      "z": -7,
      "name": "Rock_Stone_Cobble"
    },
    {
      "x": -8,
      "y": 1,
      "z": -7,
      "name": "Soil_Ash"
    },
    {
      "x": -8,
      "y": 2,
      "z": -7,
      "name": "Empty"
    },
    {
      "x": -8,
