{
  "version": 8,
  "blockIdVersion": 8,
  "anchorX": 0,
  "anchorY": 0,
  "anchorZ": 0,
  "blocks": [
    {
      "x": -4,
      "y": -1,
      "z": 0,
      "name": "Rock_Stone"
    },
    {
      "x": -4,
      "y": 0,
      "z": 0,
      "name": "Rock_Stone"
    },
    {
      "x": -4,
      "y": 1,
      "z": 0,
      "name": "Rock_Stone"
    },
    {
      "x": -4,
      "y": 2,
      "z": 0,
      "name": "Rock_Stone"
    },
    {
      "x": -4,
      "y": 3,
      "z": 0,
      "name": "Rock_Stone"
    },
    {
      "x": -4,
      "y": 4,
      "z": 0,
      "name": "Rock_Stone"
    },
    {
      "x": -4,
      "y": 5,
      "z": 0,
      "name": "Rock_Stone"
    },
    {
      "x": -4,
      "y": 6,
      "z": 0,
      "name": "Rock_Stone"
    },
    {
      "x": -4,
      "y": 7,
      "z": 0,
      "name": "Rock_Stone"
    },
    {
      "x": -4,
      "y": 8,
      "z": 0,
      "name": "Rock_Stone"
    },
    {
      "x": -4,
      "y": 9,
      "z": 0,
      "name": "Rock_Stone"
    },
    {
      "x": -4,
      "y": 10,
      "z": 0,
      "name": "Rock_Stone"
    },
    {
      "x": -4,
      "y": 11,
      "z": 0,
      "name": "Rock_Stone"
    },
    {
      "x": -4,
      "y": -1,
      "z": 1,
      "name": "Rock_Stone"
    },
    {
      "x": -4,
      "y": 0,
      "z": 1,
      "name": "Rock_Stone"
    },
    {
      "x": -4,
      "y": 1,
      "z": 1,
      "name": "Rock_Stone"
    },
    {
      "x": -4,
      "y": 2,
      "z": 1,
      "name": "Rock_Stone"
    },
    {
      "x": -4,
      "y": 3,
      "z": 1,
      "name": "Rock_Stone"
    },
    {
      "x": -4,
      "y": 4,
      "z": 1,
      "name": "Rock_Stone"
    },
    {
      "x": -4,
      "y": 5,
      "z": 1,
      "name": "Rock_Stone"
    },
    {
      "x": -4,
      "y": 6,
      "z": 1,
      "name": "Rock_Stone"
    },
    {
      "x": -4,
      "y": 7,
      "z": 1,
      "name": "Rock_Stone"
    },
    {
      "x": -4,
      "y": 8,
      "z": 1,
      "name": "Rock_Stone"
    },
    {
      "x": -4,
      "y": 9,
      "z": 1,
      "name": "Rock_Stone"
    },
    {
      "x": -4,
      "y": 10,
      "z": 1,
      "name": "Rock_Stone"
    },
    {
      "x": -4,
      "y": 11,
      "z": 1,
      "name": "Rock_Stone"
    },
    {
      "x": -4,
      "y": -1,
      "z": 2,
      "name": "Rock_Stone"
    },
    {
      "x": -4,
      "y": 0,
      "z": 2,
      "name": "Rock_Stone"
    },
    {
      "x": -4,
      "y": 1,
      "z": 2,
      "name": "Rock_Stone"
    },
    {
      "x": -4,
      "y": 2,
      "z": 2,
      "name": "Rock_Stone"
    },
    {
      "x": -4,
      "y": 3,
      "z": 2,
      "name": "Rock_Stone"
    },
    {
      "x": -4,
      "y": 4,
      "z": 2,
      "name": "Rock_Stone"
    },
    {
      "x": -4,
      "y": 5,
      "z": 2,
      "name": "Rock_Stone"
    },
    {
      "x": -4,
      "y": 6,
      "z": 2,
      "name": "Rock_Stone"
    },
    {
      "x": -4,
      "y": 7,
      "z": 2,
      "name": "Rock_Stone"
    },
    {
      "x": -4,
      "y": 8,
      "z": 2,
      "name": "Rock_Stone"
    },
    {
      "x": -4,
      "y": 9,
      "z": 2,
      "name": "Rock_Stone"
    },
    {
      "x": -4,
      "y": 10,
      "z": 2,
      "name": "Rock_Stone"
    },
    {
      "x": -4,
      "y": 11,
      "z": 2,
      "name": "Rock_Stone"
    },
    {
      "x": -4,
      "y": -1,
      "z": 3,
      "name": "Rock_Stone"
    },
    {
      "x": -4,
      "y": 0,
      "z": 3,
      "name": "Rock_Stone"
    },
    {
      "x": -4,
      "y": 1,
      "z": 3,
      "name": "Rock_Stone"
    },
    {
      "x": -4,
      "y": 2,
      "z": 3,
      "name": "Rock_Stone"
    },
    {
      "x": -4,
      "y": 3,
      "z": 3,
      "name": "Rock_Stone"
    },
    {
      "x": -4,
      "y": 4,
      "z": 3,
      "name": "Rock_Stone"
    },
    {
      "x": -4,
      "y": 5,
      "z": 3,
      "name": "Rock_Stone"
    },
    {
      "x": -4,
      "y": 6,
      "z": 3,
      "name": "Rock_Stone"
    },
    {
      "x": -4,
      "y": 7,
      "z": 3,
      "name": "Rock_Stone"
    },
    {
      "x": -4,
      "y": 8,
      "z": 3,
      "name": "Rock_Stone"
    },
    {
      "x": -4,
      "y": 9,
      "z": 3,
      "name": "Rock_Stone"
    },
    {
      "x": -4,
      "y": 10,
      "z": 3,
      "name": "Rock_Stone"
    },
    {
      "x": -4,
      "y": 11,
      "z": 3,
      "name": "Rock_Stone"
    },
    {
      "x": -4,
      "y": -1,
      "z": 4,
      "name": "Rock_Stone"
    },
    {
      "x": -4,
      "y": 0,
      "z": 4,
      "name": "Rock_Stone"
    },
    {
      "x": -4,
      "y": 1,
      "z": 4,
      "name": "Rock_Stone"
    },
    {
      "x": -4,
      "y": 2,
      "z": 4,
      "name": "Rock_Stone"
    },
    {
      "x": -4,
      "y": 3,
      "z": 4,
      "name": "Rock_Stone"
    },
    {
      "x": -4,
      "y": 4,
      "z": 4,
      "name": "Rock_Stone"
    },
    {
      "x": -4,
      "y": 5,
      "z": 4,
      "name": "Rock_Stone"
    },
    {
      "x": -4,
      "y": 6,
      "z": 4,
      "name": "Rock_Stone"
    },
    {
      "x": -4,
      "y": 7,
      "z": 4,
      "name": "Rock_Stone"
    },
    {
      "x": -4,
      "y": 8,
      "z": 4,
      "name": "Rock_Stone"
    },
    {
      "x": -4,
      "y": 9,
      "z": 4,
      "name": "Rock_Stone"
    },
    {
      "x": -4,
      "y": 10,
      "z": 4,
      "name": "Rock_Stone"
    },
    {
      "x": -4,
      "y": 11,
      "z": 4,
      "name": "Rock_Stone"
    },
    {
      "x": -3,
      "y": -1,
      "z": 0,
      "name": "Rock_Stone"
    },
    {
      "x": -3,
      "y": 0,
      "z": 0,
      "name": "Rock_Stone"
    },
    {
      "x": -3,
      "y": 1,
      "z": 0,
      "name": "Rock_Stone_Cobble"
    },
    {
      "x": -3,
      "y": 2,
      "z": 0,
      "name": "Rock_Stone_Cobble_Half",
      "rotation": 6
    },
    {
      "x": -3,
      "y": 3,
      "z": 0,
      "name": "Empty"
    },
    {
      "x": -3,
      "y": 4,
      "z": 0,
      "name": "Empty"
    },
    {
      "x": -3,
      "y": 5,
      "z": 0,
      "name": "Empty"
    },
    {
      "x": -3,
      "y": 6,
      "z": 0,
      "name": "Rock_Stone"
    },
    {
      "x": -3,
      "y": 7,
      "z": 0,
      "name": "Rock_Stone"
    },
    {
      "x": -3,
      "y": 8,
      "z": 0,
      "name": "Rock_Stone"
    },
    {
      "x": -3,
      "y": 9,
      "z": 0,
      "name": "Rock_Stone"
    },
    {
      "x": -3,
      "y": 10,
      "z": 0,
      "name": "Rock_Stone"
    },
    {
      "x": -3,
      "y": 11,
      "z": 0,
      "name": "Rock_Stone"
    },
    {
      "x": -3,
      "y": -1,
      "z": 1,
      "name": "Rock_Stone"
    },
    {
      "x": -3,
      "y": 0,
      "z": 1,
      "name": "Rock_Stone"
    },
    {
      "x": -3,
      "y": 1,
      "z": 1,
      "name": "Rock_Stone"
    },
    {
      "x": -3,
      "y": 2,
      "z": 1,
      "name": "Rock_Stone_Cobble"
    },
    {
      "x": -3,
      "y": 3,
      "z": 1,
      "name": "Rock_Stone_Cobble"
    },
    {
      "x": -3,
      "y": 4,
      "z": 1,
      "name": "Rock_Stone_Cobble_Half"
    },
    {
      "x": -3,
      "y": 5,
      "z": 1,
      "name": "Empty"
    },
    {
      "x": -3,
      "y": 6,
      "z": 1,
      "name": "Rock_Stone"
    },
    {
      "x": -3,
      "y": 7,
      "z": 1,
      "name": "Rock_Stone"
    },
    {
      "x": -3,
      "y": 8,
      "z": 1,
      "name": "Rock_Stone"
    },
    {
      "x": -3,
      "y": 9,
      "z": 1,
      "name": "Rock_Stone"
    },
    {
      "x": -3,
      "y": 10,
      "z": 1,
      "name": "Rock_Stone"
    },
    {
      "x": -3,
      "y": 11,
      "z": 1,
      "name": "Rock_Stone"
    },
    {
      "x": -3,
      "y": -1,
      "z": 2,
      "name": "Rock_Stone"
    },
    {
      "x": -3,
      "y": 0,
      "z": 2,
      "name": "Rock_Stone"
    },
    {
      "x": -3,
      "y": 1,
      "z": 2,
      "name": "Rock_Stone"
    },
    {
      "x": -3,
      "y": 2,
      "z": 2,
      "name": "Wood_Beech_Trunk"
    },
    {
      "x": -3,
      "y": 3,
      "z": 2,
      "name": "Wood_Beech_Trunk"
    },
    {
      "x": -3,
      "y": 4,
      "z": 2,
      "name": "Wood_Beech_Trunk"
    },
    {
      "x": -3,
      "y": 5,
      "z": 2,
      "name": "Wood_Beech_Trunk"
    },
    {
      "x": -3,
      "y": 6,
      "z": 2,
      "name": "Wood_Beech_Trunk"
    },
    {
      "x": -3,
      "y": 7,
      "z": 2,
      "name": "Wood_Beech_Trunk"
    },
    {
      "x": -3,
      "y": 8,
      "z": 2,
      "name": "Wood_Beech_Trunk",
      "rotation": 5
    },
    {
      "x": -3,
      "y": 9,
      "z": 2,
      "name": "Rock_Stone"
    },
    {
      "x": -3,
      "y": 10,
      "z": 2,
      "name": "Rock_Stone"
    },
    {
      "x": -3,
      "y": 11,
      "z": 2,
      "name": "Rock_Stone"
    },
    {
      "x": -3,
      "y": -1,
      "z": 3,
      "name": "Rock_Stone"
    },
    {
      "x": -3,
      "y": 0,
      "z": 3,
      "name": "Rock_Stone"
    },
    {
      "x": -3,
      "y": 1,
      "z": 3,
      "name": "Rock_Stone"
    },
    {
      "x": -3,
      "y": 2,
      "z": 3,
      "name": "Rock_Stone"
    },
    {
      "x": -3,
      "y": 3,
      "z": 3,
      "name": "Rock_Stone"
    },
    {
      "x": -3,
      "y": 4,
      "z": 3,
      "name": "Rock_Stone_Cobble"
    },
    {
      "x": -3,
      "y": 5,
      "z": 3,
      "name": "Rock_Stone_Cobble"
    },
    {
      "x": -3,
      "y": 6,
      "z": 3,
      "name": "Empty"
    },
    {
      "x": -3,
      "y": 7,
      "z": 3,
      "name": "Empty"
    },
    {
      "x": -3,
      "y": 8,
      "z": 3,
      "name": "Wood_Softwood_Planks_Half",
      "rotation": 4
    },
    {
      "x": -3,
      "y": 9,
      "z": 3,
      "name": "Rock_Stone"
    },
    {
      "x": -3,
      "y": 10,
      "z": 3,
      "name": "Rock_Stone"
    },
    {
      "x": -3,
      "y": 11,
      "z": 3,
      "name": "Rock_Stone"
    },
    {
      "x": -3,
      "y": -1,
      "z": 4,
      "name": "Rock_Stone"
    },
    {
      "x": -3,
      "y": 0,
      "z": 4,
      "name": "Rock_Stone"
    },
    {
      "x": -3,
      "y": 1,
      "z": 4,
      "name": "Rock_Stone"
    },
    {
      "x": -3,
      "y": 2,
      "z": 4,
      "name": "Rock_Stone"
    },
    {
      "x": -3,
      "y": 3,
      "z": 4,
      "name": "Rock_Stone"
    },
    {
      "x": -3,
      "y": 4,
      "z": 4,
      "name": "Rock_Stone_Cobble"
    },
    {
      "x": -3,
      "y": 5,
      "z": 4,
      "name": "Empty"
    },
    {
      "x": -3,
      "y": 6,
      "z": 4,
      "name": "Empty"
    },
    {
      "x": -3,
      "y": 7,
      "z": 4,
      "name": "Empty"
    },
    {
      "x": -3,
      "y": 8,
      "z": 4,
      "name": "Empty"
    },
    {
      "x": -3,
      "y": 9,
      "z": 4,
      "name": "Rock_Stone"
    },
    {
      "x": -3,
      "y": 10,
      "z": 4,
      "name": "Rock_Stone"
    },
    {
      "x": -3,
      "y": 11,
      "z": 4,
      "name": "Rock_Stone"
    },
    {
      "x": -2,
      "y": -1,
      "z": 0,
      "name": "Rock_Stone"
    },
    {
      "x": -2,
      "y": 0,
      "z": 0,
      "name": "Rock_Stone"
    },
    {
      "x": -2,
      "y": 1,
      "z": 0,
      "name": "Empty"
    },
    {
      "x": -2,
      "y": 2,
      "z": 0,
      "name": "Empty"
    },
    {
      "x": -2,
      "y": 3,
      "z": 0,
      "name": "Empty"
    },
    {
      "x": -2,
      "y": 4,
      "z": 0,
      "name": "Empty"
    },
    {
      "x": -2,
      "y": 5,
      "z": 0,
      "name": "Empty"
    },
    {
      "x": -2,
      "y": 6,
      "z": 0,
      "name": "Empty"
    },
    {
      "x": -2,
      "y": 7,
      "z": 0,
      "name": "Empty"
    },
    {
      "x": -2,
      "y": 8,
      "z": 0,
      "name": "Rock_Stone"
    },
    {
      "x": -2,
      "y": 9,
      "z": 0,
      "name": "Rock_Stone"
    },
    {
      "x": -2,
      "y": 10,
      "z": 0,
      "name": "Rock_Stone"
    },
    {
      "x": -2,
      "y": 11,
      "z": 0,
      "name": "Rock_Stone"
    },
    {
      "x": -2,
      "y": -1,
      "z": 1,
      "name": "Rock_Stone"
    },
    {
      "x": -2,
      "y": 0,
      "z": 1,
      "name": "Rock_Stone"
    },
    {
      "x": -2,
      "y": 1,
      "z": 1,
      "name": "Rock_Stone"
    },
    {
      "x": -2,
      "y": 2,
      "z": 1,
      "name": "Empty"
    },
    {
      "x": -2,
      "y": 3,
      "z": 1,
      "name": "Empty"
    },
    {
      "x": -2,
      "y": 4,
      "z": 1,
      "name": "Empty"
    },
    {
      "x": -2,
      "y": 5,
      "z": 1,
      "name": "Empty"
    },
    {
      "x": -2,
      "y": 6,
      "z": 1,
      "name": "Empty"
    },
    {
      "x": -2,
      "y": 7,
      "z": 1,
      "name": "Rock_Stone"
    },
    {
      "x": -2,
      "y": 8,
      "z": 1,
      "name": "Rock_Stone"
    },
    {
      "x": -2,
      "y": 9,
      "z": 1,
      "name": "Rock_Stone"
    },
    {
      "x": -2,
      "y": 10,
      "z": 1,
      "name": "Rock_Stone"
    },
    {
      "x": -2,
      "y": 11,
      "z": 1,
      "name": "Rock_Stone"
    },
    {
      "x": -2,
      "y": -1,
      "z": 2,
      "name": "Rock_Stone"
    },
    {
      "x": -2,
      "y": 0,
      "z": 2,
      "name": "Rock_Stone"
    },
    {
      "x": -2,
      "y": 1,
      "z": 2,
      "name": "Rock_Stone"
    },
    {
      "x": -2,
      "y": 2,
      "z": 2,
      "name": "Rock_Stone"
    },
    {
      "x": -2,
      "y": 3,
      "z": 2,
      "name": "Rock_Stone_Cobble_Half",
      "rotation": 5
    },
    {
      "x": -2,
      "y": 4,
      "z": 2,
      "name": "Rock_Stone_Cobble_Half",
      "rotation": 5
    },
    {
      "x": -2,
      "y": 5,
      "z": 2,
      "name": "Empty"
    },
    {
      "x": -2,
      "y": 6,
      "z": 2,
      "name": "Empty"
    },
    {
      "x": -2,
      "y": 7,
      "z": 2,
      "name": "Wood_Softwood_Stairs",
      "rotation": 11
    },
    {
      "x": -2,
      "y": 8,
      "z": 2,
      "name": "Wood_Beech_Trunk",
      "rotation": 5
    },
    {
      "x": -2,
      "y": 9,
      "z": 2,
      "name": "Rock_Stone"
    },
    {
      "x": -2,
      "y": 10,
      "z": 2,
      "name": "Rock_Stone"
    },
    {
      "x": -2,
      "y": 11,
      "z": 2,
      "name": "Rock_Stone"
    },
    {
      "x": -2,
      "y": -1,
      "z": 3,
      "name": "Rock_Stone"
    },
    {
      "x": -2,
      "y": 0,
      "z": 3,
      "name": "Rock_Stone"
    },
    {
      "x": -2,
      "y": 1,
      "z": 3,
      "name": "Rock_Stone"
    },
    {
      "x": -2,
      "y": 2,
      "z": 3,
      "name": "Rock_Stone"
    },
    {
      "x": -2,
      "y": 3,
      "z": 3,
      "name": "Rock_Stone"
    },
    {
      "x": -2,
      "y": 4,
      "z": 3,
      "name": "Empty"
    },
    {
      "x": -2,
      "y": 5,
      "z": 3,
      "name": "Empty"
    },
    {
      "x": -2,
      "y": 6,
      "z": 3,
      "name": "Empty"
    },
    {
      "x": -2,
      "y": 7,
      "z": 3,
      "name": "Empty"
    },
    {
      "x": -2,
      "y": 8,
      "z": 3,
      "name": "Empty"
    },
    {
      "x": -2,
      "y": 9,
      "z": 3,
      "name": "Rock_Stone"
    },
    {
      "x": -2,
      "y": 10,
      "z": 3,
      "name": "Rock_Stone"
    },
    {
      "x": -2,
      "y": 11,
      "z": 3,
      "name": "Rock_Stone"
    },
    {
      "x": -2,
      "y": -1,
      "z": 4,
      "name": "Rock_Stone"
    },
    {
      "x": -2,
      "y": 0,
      "z": 4,
      "name": "Rock_Stone"
    },
    {
      "x": -2,
      "y": 1,
      "z": 4,
      "name": "Rock_Stone"
    },
    {
      "x": -2,
      "y": 2,
      "z": 4,
      "name": "Rock_Stone"
    },
    {
      "x": -2,
      "y": 3,
      "z": 4,
      "name": "Rock_Stone"
    },
    {
      "x": -2,
      "y": 4,
      "z": 4,
      "name": "Empty"
    },
    {
      "x": -2,
      "y": 5,
      "z": 4,
      "name": "Empty"
    },
    {
      "x": -2,
      "y": 6,
      "z": 4,
      "name": "Empty"
    },
    {
      "x": -2,
      "y": 7,
      "z": 4,
      "name": "Empty"
    },
    {
      "x": -2,
      "y": 8,
      "z": 4,
      "name": "Empty"
    },
    {
      "x": -2,
      "y": 9,
      "z": 4,
      "name": "Empty"
    },
    {
      "x": -2,
      "y": 10,
      "z": 4,
      "name": "Rock_Stone"
    },
    {
      "x": -2,
      "y": 11,
      "z": 4,
      "name": "Rock_Stone"
    },
    {
      "x": -1,
      "y": -1,
      "z": 0,
      "name": "Rock_Stone"
    },
    {
      "x": -1,
      "y": 0,
      "z": 0,
      "name": "Soil_Gravel"
    },
    {
      "x": -1,
      "y": 1,
      "z": 0,
      "name": "Empty"
    },
    {
      "x": -1,
      "y": 2,
      "z": 0,
      "name": "Empty"
    },
    {
      "x": -1,
      "y": 3,
      "z": 0,
      "name": "Empty"
    },
    {
      "x": -1,
      "y": 4,
      "z": 0,
      "name": "Empty"
    },
    {
      "x": -1,
      "y": 5,
      "z": 0,
      "name": "Empty"
    },
    {
      "x": -1,
      "y": 6,
      "z": 0,
      "name": "Empty"
    },
    {
      "x": -1,
      "y": 7,
      "z": 0,
      "name": "Empty"
    },
    {
      "x": -1,
      "y": 8,
      "z": 0,
      "name": "Rock_Stone"
    },
    {
      "x": -1,
      "y": 9,
      "z": 0,
      "name": "Rock_Stone"
    },
    {
      "x": -1,
      "y": 10,
      "z": 0,
      "name": "Rock_Stone"
    },
    {
      "x": -1,
      "y": 11,
      "z": 0,
      "name": "Rock_Stone"
    },
    {
      "x": -1,
      "y": -1,
      "z": 1,
      "name": "Rock_Stone"
    },
    {
      "x": -1,
      "y": 0,
      "z": 1,
      "name": "Rock_Stone"
    },
    {
      "x": -1,
      "y": 1,
      "z": 1,
      "name": "Soil_Gravel"
    },
    {
      "x": -1,
      "y": 2,
      "z": 1,
      "name": "Empty"
    },
    {
      "x": -1,
      "y": 3,
      "z": 1,
      "name": "Empty"
    },
    {
      "x": -1,
      "y": 4,
      "z": 1,
      "name": "Empty"
    },
    {
      "x": -1,
      "y": 5,
      "z": 1,
      "name": "Empty"
    },
    {
      "x": -1,
      "y": 6,
      "z": 1,
      "name": "Empty"
    },
    {
      "x": -1,
      "y": 7,
      "z": 1,
      "name": "Empty"
    },
    {
      "x": -1,
      "y": 8,
      "z": 1,
      "name": "Rock_Stone"
    },
    {
      "x": -1,
      "y": 9,
      "z": 1,
      "name": "Rock_Stone"
    },
    {
      "x": -1,
      "y": 10,
      "z": 1,
      "name": "Rock_Stone"
    },
    {
      "x": -1,
      "y": 11,
      "z": 1,
      "name": "Rock_Stone"
    },
    {
      "x": -1,
      "y": -1,
      "z": 2,
      "name": "Rock_Stone"
    },
    {
      "x": -1,
      "y": 0,
      "z": 2,
      "name": "Rock_Stone"
    },
    {
      "x": -1,
      "y": 1,
      "z": 2,
      "name": "Rock_Stone"
    },
    {
      "x": -1,
      "y": 2,
      "z": 2,
      "name": "Rock_Stone"
    },
    {
      "x": -1,
      "y": 3,
      "z": 2,
      "name": "Empty"
    },
    {
      "x": -1,
      "y": 4,
      "z": 2,
      "name": "Empty"
    },
    {
      "x": -1,
      "y": 5,
      "z": 2,
      "name": "Empty"
    },
    {
      "x": -1,
      "y": 6,
      "z": 2,
      "name": "Empty"
    },
    {
      "x": -1,
      "y": 7,
      "z": 2,
      "name": "Empty"
    },
    {
      "x": -1,
      "y": 8,
      "z": 2,
      "name": "Wood_Beech_Trunk",
      "rotation": 5
    },
    {
      "x": -1,
      "y": 9,
      "z": 2,
      "name": "Rock_Stone"
    },
    {
      "x": -1,
      "y": 10,
      "z": 2,
      "name": "Rock_Stone"
    },
    {
      "x": -1,
      "y": 11,
      "z": 2,
      "name": "Rock_Stone"
    },
    {
      "x": -1,
      "y": -1,
      "z": 3,
      "name": "Rock_Stone"
    },
    {
      "x": -1,
      "y": 0,
      "z": 3,
      "name": "Rock_Stone"
    },
    {
      "x": -1,
      "y": 1,
      "z": 3,
      "name": "Rock_Stone"
    },
    {
      "x": -1,
      "y": 2,
      "z": 3,
      "name": "Rock_Stone"
    },
    {
      "x": -1,
      "y": 3,
      "z": 3,
      "name": "Soil_Gravel"
    },
    {
      "x": -1,
      "y": 4,
      "z": 3,
      "name": "Empty"
    },
    {
      "x": -1,
      "y": 5,
      "z": 3,
      "name": "Empty"
    },
    {
      "x": -1,
      "y": 6,
      "z": 3,
      "name": "Empty"
    },
    {
      "x": -1,
      "y": 7,
      "z": 3,
      "name": "Empty"
    },
    {
      "x": -1,
      "y": 8,
      "z": 3,
      "name": "Empty"
    },
    {
      "x": -1,
      "y": 9,
      "z": 3,
      "name": "Empty"
    },
    {
      "x": -1,
      "y": 10,
      "z": 3,
      "name": "Rock_Stone"
    },
    {
      "x": -1,
      "y": 11,
      "z": 3,
      "name": "Rock_Stone"
    },
    {
      "x": -1,
      "y": -1,
      "z": 4,
      "name": "Rock_Stone"
    },
    {
      "x": -1,
      "y": 0,
      "z": 4,
      "name": "Rock_Stone"
    },
    {
      "x": -1,
      "y": 1,
      "z": 4,
      "name": "Rock_Stone"
    },
    {
      "x": -1,
      "y": 2,
      "z": 4,
      "name": "Rock_Stone"
    },
    {
      "x": -1,
      "y": 3,
      "z": 4,
      "name": "Rock_Stone"
    },
    {
      "x": -1,
      "y": 4,
      "z": 4,
      "name": "Empty"
    },
    {
      "x": -1,
      "y": 5,
      "z": 4,
      "name": "Empty"
    },
    {
      "x": -1,
      "y": 6,
      "z": 4,
      "name": "Empty"
    },
    {
      "x": -1,
      "y": 7,
      "z": 4,
      "name": "Empty"
    },
    {
      "x": -1,
      "y": 8,
      "z": 4,
      "name": "Empty"
    },
    {
      "x": -1,
      "y": 9,
      "z": 4,
      "name": "Empty"
    },
    {
      "x": -1,
      "y": 10,
      "z": 4,
      "name": "Rock_Stone"
    },
    {
      "x": -1,
      "y": 11,
      "z": 4,
      "name": "Rock_Stone"
    },
    {
      "x": 0,
      "y": -1,
      "z": 0,
      "name": "Rock_Stone"
    },
    {
      "x": 0,
      "y": 0,
      "z": 0,
      "name": "Rock_Stone"
    },
    {
      "x": 0,
      "y": 1,
      "z": 0,
      "name": "*Rail_State_Definitions_Slope",
      "rotation": 2
    },
    {
      "x": 0,
      "y": 2,
      "z": 0,
      "name": "Empty"
    },
    {
      "x": 0,
      "y": 3,
      "z": 0,
      "name": "Empty"
    },
    {
      "x": 0,
      "y": 4,
      "z": 0,
      "name": "Empty"
    },
    {
      "x": 0,
      "y": 5,
      "z": 0,
      "name": "Empty"
    },
    {
      "x": 0,
      "y": 6,
      "z": 0,
      "name": "Empty"
    },
    {
      "x": 0,
      "y": 7,
      "z": 0,
      "name": "Empty"
    },
    {
      "x": 0,
      "y": 8,
      "z": 0,
      "name": "Rock_Stone"
    },
    {
      "x": 0,
      "y": 9,
      "z": 0,
      "name": "Rock_Stone"
    },
    {
      "x": 0,
      "y": 10,
      "z": 0,
      "name": "Rock_Stone"
    },
    {
      "x": 0,
      "y": 11,
      "z": 0,
      "name": "Rock_Stone"
    },
    {
      "x": 0,
      "y": -1,
      "z": 1,
      "name": "Rock_Stone"
    },
    {
      "x": 0,
      "y": 0,
      "z": 1,
      "name": "Rock_Stone"
    },
    {
      "x": 0,
      "y": 1,
      "z": 1,
      "name": "Soil_Gravel"
    },
    {
      "x": 0,
      "y": 2,
      "z": 1,
      "name": "Rail"
    },
    {
      "x": 0,
      "y": 3,
      "z": 1,
      "name": "Empty"
    },
    {
      "x": 0,
      "y": 4,
      "z": 1,
      "name": "Empty"
    },
    {
      "x": 0,
      "y": 5,
      "z": 1,
      "name": "Empty"
    },
    {
      "x": 0,
      "y": 6,
      "z": 1,
      "name": "Empty"
    },
    {
      "x": 0,
      "y": 7,
      "z": 1,
      "name": "Empty"
    },
    {
      "x": 0,
      "y": 8,
      "z": 1,
      "name": "Rock_Stone"
    },
    {
      "x": 0,
      "y": 9,
      "z": 1,
      "name": "Rock_Stone"
    },
    {
      "x": 0,
      "y": 10,
      "z": 1,
      "name": "Rock_Stone"
    },
    {
      "x": 0,
      "y": 11,
      "z": 1,
      "name": "Rock_Stone"
    },
    {
      "x": 0,
      "y": -1,
      "z": 2,
      "name": "Rock_Stone"
    },
    {
      "x": 0,
      "y": 0,
      "z": 2,
      "name": "Rock_Stone"
    },
    {
      "x": 0,
      "y": 1,
      "z": 2,
      "name": "Rock_Stone"
    },
    {
      "x": 0,
      "y": 2,
      "z": 2,
      "name": "Soil_Gravel"
    },
    {
      "x": 0,
      "y": 3,
      "z": 2,
      "name": "Rail"
    },
    {
      "x": 0,
      "y": 4,
      "z": 2,
      "name": "Empty"
    },
    {
      "x": 0,
      "y": 5,
      "z": 2,
      "name": "Empty"
    },
    {
      "x": 0,
      "y": 6,
      "z": 2,
      "name": "Empty"
    },
    {
      "x": 0,
      "y": 7,
      "z": 2,
      "name": "Empty"
    },
    {
      "x": 0,
      "y": 8,
      "z": 2,
      "name": "Wood_Beech_Trunk",
      "rotation": 5
    },
    {
      "x": 0,
      "y": 9,
      "z": 2,
      "name": "Rock_Stone"
    },
    {
      "x": 0,
      "y": 10,
      "z": 2,
      "name": "Rock_Stone"
    },
    {
      "x": 0,
      "y": 11,
      "z": 2,
      "name": "Rock_Stone"
    },
    {
      "x": 0,
      "y": -1,
      "z": 3,
      "name": "Rock_Stone"
    },
    {
      "x": 0,
      "y": 0,
      "z": 3,
      "name": "Rock_Stone"
    },
    {
      "x": 0,
      "y": 1,
      "z": 3,
      "name": "Rock_Stone"
    },
    {
      "x": 0,
      "y": 2,
      "z": 3,
      "name": "Rock_Stone"
    },
    {
      "x": 0,
      "y": 3,
      "z": 3,
      "name": "*Rail_State_Definitions_Slope",
      "rotation": 2
    },
    {
      "x": 0,
      "y": 4,
      "z": 3,
      "name": "Empty"
    },
    {
      "x": 0,
      "y": 5,
      "z": 3,
      "name": "Empty"
    },
    {
      "x": 0,
      "y": 6,
      "z": 3,
      "name": "Empty"
    },
    {
      "x": 0,
      "y": 7,
      "z": 3,
      "name": "Empty"
    },
    {
      "x": 0,
      "y": 8,
      "z": 3,
      "name": "Empty"
    },
    {
      "x": 0,
      "y": 9,
      "z": 3,
      "name": "Empty"
    },
    {
      "x": 0,
      "y": 10,
      "z": 3,
      "name": "Rock_Stone"
    },
    {
      "x": 0,
      "y": 11,
      "z": 3,
      "name": "Rock_Stone"
    },
    {
      "x": 0,
      "y": -1,
      "z": 4,
      "name": "Rock_Stone"
    },
    {
      "x": 0,
      "y": 0,
      "z": 4,
      "name": "Rock_Stone"
    },
    {
      "x": 0,
      "y": 1,
      "z": 4,
      "name": "Rock_Stone"
    },
    {
      "x": 0,
      "y": 2,
      "z": 4,
      "name": "Rock_Stone"
    },
    {
      "x": 0,
      "y": 3,
      "z": 4,
      "name": "Soil_Gravel"
    },
    {
      "x": 0,
      "y": 4,
      "z": 4,
      "name": "Rail"
    },
    {
      "x": 0,
      "y": 5,
      "z": 4,
      "name": "Empty"
    },
    {
      "x": 0,
      "y": 6,
      "z": 4,
      "name": "Empty"
    },
    {
      "x": 0,
      "y": 7,
      "z": 4,
      "name": "Empty"
    },
    {
      "x": 0,
      "y": 8,
      "z": 4,
      "name": "Empty"
    },
    {
      "x": 0,
      "y": 9,
      "z": 4,
      "name": "Empty"
    },
    {
      "x": 0,
      "y": 10,
      "z": 4,
      "name": "Empty"
    },
    {
      "x": 0,
      "y": 11,
      "z": 4,
      "name": "Rock_Stone"
    },
    {
      "x": 1,
      "y": -1,
      "z": 0,
      "name": "Rock_Stone"
    },
    {
      "x": 1,
      "y": 0,
      "z": 0,
      "name": "Rock_Stone"
    },
    {
      "x": 1,
      "y": 1,
      "z": 0,
      "name": "Soil_Gravel"
    },
    {
      "x": 1,
      "y": 2,
      "z": 0,
      "name": "Empty"
    },
    {
      "x": 1,
      "y": 3,
      "z": 0,
      "name": "Empty"
    },
    {
      "x": 1,
      "y": 4,
      "z": 0,
      "name": "Empty"
    },
    {
      "x": 1,
      "y": 5,
      "z": 0,
      "name": "Empty"
    },
    {
      "x": 1,
      "y": 6,
      "z": 0,
      "name": "Empty"
    },
    {
      "x": 1,
      "y": 7,
      "z": 0,
      "name": "Rock_Stone"
    },
    {
      "x": 1,
      "y": 8,
      "z": 0,
      "name": "Rock_Stone"
    },
    {
      "x": 1,
      "y": 9,
      "z": 0,
      "name": "Rock_Stone"
    },
    {
      "x": 1,
      "y": 10,
      "z": 0,
      "name": "Rock_Stone"
    },
    {
      "x": 1,
      "y": 11,
      "z": 0,
      "name": "Rock_Stone"
    },
    {
      "x": 1,
      "y": -1,
      "z": 1,
      "name": "Rock_Stone"
    },
    {
      "x": 1,
      "y": 0,
      "z": 1,
      "name": "Rock_Stone"
    },
    {
      "x": 1,
      "y": 1,
      "z": 1,
      "name": "Soil_Gravel"
    },
    {
      "x": 1,
      "y": 2,
      "z": 1,
      "name": "Empty"
    },
    {
      "x": 1,
      "y": 3,
      "z": 1,
      "name": "Empty"
    },
    {
      "x": 1,
      "y": 4,
      "z": 1,
      "name": "Empty"
    },
    {
      "x": 1,
      "y": 5,
      "z": 1,
      "name": "Empty"
    },
    {
      "x": 1,
      "y": 6,
      "z": 1,
      "name": "Empty"
    },
    {
      "x": 1,
      "y": 7,
      "z": 1,
      "name": "Rock_Stone"
    },
    {
      "x": 1,
      "y": 8,
      "z": 1,
      "name": "Rock_Stone"
    },
    {
      "x": 1,
      "y": 9,
      "z": 1,
      "name": "Rock_Stone"
    },
    {
      "x": 1,
      "y": 10,
      "z": 1,
      "name": "Rock_Stone"
    },
    {
      "x": 1,
      "y": 11,
      "z": 1,
      "name": "Rock_Stone"
    },
    {
      "x": 1,
      "y": -1,
      "z": 2,
      "name": "Rock_Stone"
    },
    {
      "x": 1,
      "y": 0,
      "z": 2,
      "name": "Rock_Stone"
    },
    {
      "x": 1,
      "y": 1,
      "z": 2,
      "name": "Rock_Stone"
    },
    {
      "x": 1,
      "y": 2,
      "z": 2,
      "name": "Soil_Gravel"
    },
    {
      "x": 1,
      "y": 3,
      "z": 2,
      "name": "Empty"
    },
    {
      "x": 1,
      "y": 4,
      "z": 2,
      "name": "Empty"
    },
    {
      "x": 1,
      "y": 5,
      "z": 2,
      "name": "Empty"
    },
    {
      "x": 1,
      "y": 6,
      "z": 2,
      "name": "Empty"
    },
    {
      "x": 1,
      "y": 7,
      "z": 2,
      "name": "Empty"
    },
    {
      "x": 1,
      "y": 8,
      "z": 2,
      "name": "Wood_Beech_Trunk",
      "rotation": 5
    },
    {
      "x": 1,
      "y": 9,
      "z": 2,
      "name": "Rock_Stone"
    },
    {
      "x": 1,
      "y": 10,
      "z": 2,
      "name": "Rock_Stone"
    },
    {
      "x": 1,
      "y": 11,
      "z": 2,
      "name": "Rock_Stone"
    },
    {
      "x": 1,
      "y": -1,
      "z": 3,
      "name": "Rock_Stone"
    },
    {
      "x": 1,
      "y": 0,
      "z": 3,
      "name": "Rock_Stone"
    },
    {
      "x": 1,
      "y": 1,
      "z": 3,
      "name": "Rock_Stone"
    },
    {
      "x": 1,
      "y": 2,
      "z": 3,
      "name": "Soil_Gravel"
    },
    {
      "x": 1,
      "y": 3,
      "z": 3,
      "name": "Empty"
    },
    {
      "x": 1,
      "y": 4,
      "z": 3,
      "name": "Empty"
    },
    {
      "x": 1,
      "y": 5,
      "z": 3,
      "name": "Empty"
    },
    {
      "x": 1,
      "y": 6,
      "z": 3,
      "name": "Empty"
    },
    {
      "x": 1,
      "y": 7,
      "z": 3,
      "name": "Empty"
    },
    {
      "x": 1,
      "y": 8,
      "z": 3,
      "name": "Empty"
    },
    {
      "x": 1,
      "y": 9,
      "z": 3,
      "name": "Rock_Stone"
    },
    {
      "x": 1,
      "y": 10,
      "z": 3,
      "name": "Rock_Stone"
    },
    {
      "x": 1,
      "y": 11,
      "z": 3,
      "name": "Rock_Stone"
    },
    {
      "x": 1,
      "y": -1,
      "z": 4,
      "name": "Rock_Stone"
    },
    {
      "x": 1,
      "y": 0,
      "z": 4,
      "name": "Rock_Stone"
    },
    {
      "x": 1,
      "y": 1,
      "z": 4,
      "name": "Rock_Stone"
    },
    {
      "x": 1,
      "y": 2,
      "z": 4,
      "name": "Rock_Stone"
    },
    {
      "x": 1,
      "y": 3,
      "z": 4,
      "name": "Soil_Gravel"
    },
    {
      "x": 1,
      "y": 4,
      "z": 4,
      "name": "Empty"
    },
    {
      "x": 1,
      "y": 5,
      "z": 4,
      "name": "Empty"
    },
    {
      "x": 1,
      "y": 6,
      "z": 4,
      "name": "Empty"
    },
    {
      "x": 1,
      "y": 7,
      "z": 4,
      "name": "Empty"
    },
    {
      "x": 1,
      "y": 8,
      "z": 4,
      "name": "Empty"
    },
    {
      "x": 1,
      "y": 9,
      "z": 4,
      "name": "Empty"
    },
    {
      "x": 1,
      "y": 10,
      "z": 4,
      "name": "Empty"
    },
    {
      "x": 1,
      "y": 11,
      "z": 4,
      "name": "Rock_Stone"
    },
    {
      "x": 2,
      "y": -1,
      "z": 0,
      "name": "Rock_Stone"
    },
    {
      "x": 2,
      "y": 0,
      "z": 0,
      "name": "Rock_Stone"
    },
    {
      "x": 2,
      "y": 1,
      "z": 0,
      "name": "Rock_Stone"
    },
    {
      "x": 2,
      "y": 2,
      "z": 0,
      "name": "Empty"
    },
    {
      "x": 2,
      "y": 3,
      "z": 0,
      "name": "Empty"
    },
    {
      "x": 2,
      "y": 4,
      "z": 0,
      "name": "Empty"
    },
    {
      "x": 2,
      "y": 5,
      "z": 0,
      "name": "Empty"
    },
    {
      "x": 2,
      "y": 6,
      "z": 0,
      "name": "Empty"
    },
    {
      "x": 2,
      "y": 7,
      "z": 0,
      "name": "Rock_Stone"
    },
    {
      "x": 2,
      "y": 8,
      "z": 0,
      "name": "Rock_Stone"
    },
    {
      "x": 2,
      "y": 9,
      "z": 0,
      "name": "Rock_Stone"
    },
    {
      "x": 2,
      "y": 10,
      "z": 0,
      "name": "Rock_Stone"
    },
    {
      "x": 2,
      "y": 11,
      "z": 0,
      "name": "Rock_Stone"
    },
    {
      "x": 2,
      "y": -1,
      "z": 1,
      "name": "Rock_Stone"
    },
    {
      "x": 2,
      "y": 0,
      "z": 1,
      "name": "Rock_Stone"
    },
    {
      "x": 2,
      "y": 1,
      "z": 1,
      "name": "Rock_Stone"
    },
    {
      "x": 2,
      "y": 2,
      "z": 1,
      "name": "Wood_Softwood_Beam"
    },
    {
      "x": 2,
      "y": 3,
      "z": 1,
      "name": "*Furniture_Crude_Torch_State_Definitions_Off"
    },
    {
      "x": 2,
      "y": 4,
      "z": 1,
      "name": "Empty"
    },
    {
      "x": 2,
      "y": 5,
      "z": 1,
      "name": "Empty"
    },
    {
      "x": 2,
      "y": 6,
      "z": 1,
      "name": "Empty"
    },
    {
      "x": 2,
      "y": 7,
      "z": 1,
      "name": "Rock_Stone"
    },
    {
      "x": 2,
      "y": 8,
      "z": 1,
      "name": "Rock_Stone"
    },
    {
      "x": 2,
      "y": 9,
      "z": 1,
      "name": "Rock_Stone"
    },
    {
      "x": 2,
      "y": 10,
      "z": 1,
      "name": "Rock_Stone"
    },
    {
      "x": 2,
      "y": 11,
      "z": 1,
      "name": "Rock_Stone"
    },
    {
      "x": 2,
      "y": -1,
      "z": 2,
      "name": "Rock_Stone"
    },
    {
      "x": 2,
      "y": 0,
      "z": 2,
      "name": "Rock_Stone"
    },
    {
      "x": 2,
      "y": 1,
      "z": 2,
      "name": "Rock_Stone"
    },
    {
      "x": 2,
      "y": 2,
      "z": 2,
      "name": "Rock_Stone"
    },
    {
      "x": 2,
      "y": 3,
      "z": 2,
      "name": "Empty"
    },
    {
      "x": 2,
      "y": 4,
      "z": 2,
      "name": "Empty"
    },
    {
      "x": 2,
      "y": 5,
      "z": 2,
      "name": "Empty"
    },
    {
      "x": 2,
      "y": 6,
      "z": 2,
      "name": "Empty"
    },
    {
      "x": 2,
      "y": 7,
      "z": 2,
      "name": "Wood_Softwood_Stairs",
      "rotation": 9
    },
    {
      "x": 2,
      "y": 8,
      "z": 2,
      "name": "Wood_Beech_Trunk",
      "rotation": 5
    },
    {
      "x": 2,
      "y": 9,
      "z": 2,
      "name": "Rock_Stone"
    },
    {
      "x": 2,
      "y": 10,
      "z": 2,
      "name": "Rock_Stone"
    },
    {
      "x": 2,
      "y": 11,
      "z": 2,
      "name": "Rock_Stone"
    },
    {
      "x": 2,
      "y": -1,
      "z": 3,
      "name": "Rock_Stone"
    },
    {
      "x": 2,
      "y": 0,
      "z": 3,
      "name": "Rock_Stone"
    },
    {
      "x": 2,
      "y": 1,
      "z": 3,
      "name": "Rock_Stone"
    },
    {
      "x": 2,
      "y": 2,
      "z": 3,
      "name": "Rock_Stone"
    },
    {
      "x": 2,
      "y": 3,
      "z": 3,
      "name": "Rubble_Stone_Medium"
    },
    {
      "x": 2,
      "y": 4,
      "z": 3,
      "name": "Empty"
    },
    {
      "x": 2,
      "y": 5,
      "z": 3,
      "name": "Empty"
    },
    {
      "x": 2,
      "y": 6,
      "z": 3,
      "name": "Empty"
    },
    {
      "x": 2,
      "y": 7,
      "z": 3,
      "name": "Empty"
    },
    {
      "x": 2,
      "y": 8,
      "z": 3,
      "name": "Empty"
    },
    {
      "x": 2,
      "y": 9,
      "z": 3,
      "name": "Rock_Stone"
    },
    {
      "x": 2,
      "y": 10,
      "z": 3,
      "name": "Rock_Stone"
    },
    {
      "x": 2,
      "y": 11,
      "z": 3,
      "name": "Rock_Stone"
    },
    {
      "x": 2,
      "y": -1,
      "z": 4,
      "name": "Rock_Stone"
    },
    {
      "x": 2,
      "y": 0,
      "z": 4,
      "name": "Rock_Stone"
    },
    {
      "x": 2,
      "y": 1,
      "z": 4,
      "name": "Rock_Stone"
    },
    {
      "x": 2,
      "y": 2,
      "z": 4,
      "name": "Rock_Stone"
    },
    {
      "x": 2,
      "y": 3,
      "z": 4,
      "name": "Soil_Gravel"
    },
    {
      "x": 2,
      "y": 4,
      "z": 4,
      "name": "Empty"
    },
    {
      "x": 2,
      "y": 5,
      "z": 4,
      "name": "Empty"
    },
    {
      "x": 2,
      "y": 6,
      "z": 4,
      "name": "Empty"
    },
    {
      "x": 2,
      "y": 7,
      "z": 4,
      "name": "Empty"
    },
    {
      "x": 2,
      "y": 8,
      "z": 4,
      "name": "Empty"
    },
    {
      "x": 2,
      "y": 9,
      "z": 4,
      "name": "Empty"
    },
    {
      "x": 2,
      "y": 10,
      "z": 4,
      "name": "Rock_Stone"
    },
    {
      "x": 2,
      "y": 11,
      "z": 4,
      "name": "Rock_Stone"
    },
    {
      "x": 3,
      "y": -1,
      "z": 0,
      "name": "Rock_Stone"
    },
    {
      "x": 3,
      "y": 0,
      "z": 0,
      "name": "Rock_Stone"
    },
    {
      "x": 3,
      "y": 1,
      "z": 0,
      "name": "Rock_Stone"
    },
    {
      "x": 3,
      "y": 2,
      "z": 0,
      "name": "Rock_Stone_Cobble"
    },
    {
      "x": 3,
      "y": 3,
      "z": 0,
      "name": "Rock_Stone_Cobble_Half"
    },
    {
      "x": 3,
      "y": 4,
      "z": 0,
      "name": "Empty"
    },
    {
      "x": 3,
      "y": 5,
      "z": 0,
      "name": "Empty"
    },
    {
      "x": 3,
      "y": 6,
      "z": 0,
      "name": "Rock_Stone"
    },
    {
      "x": 3,
      "y": 7,
      "z": 0,
      "name": "Rock_Stone"
    },
    {
      "x": 3,
      "y": 8,
      "z": 0,
      "name": "Rock_Stone"
    },
    {
      "x": 3,
      "y": 9,
      "z": 0,
      "name": "Rock_Stone"
    },
    {
      "x": 3,
      "y": 10,
      "z": 0,
      "name": "Rock_Stone"
    },
    {
      "x": 3,
      "y": 11,
      "z": 0,
      "name": "Rock_Stone"
    },
    {
      "x": 3,
      "y": -1,
      "z": 1,
      "name": "Rock_Stone"
    },
    {
      "x": 3,
      "y": 0,
      "z": 1,
      "name": "Rock_Stone"
    },
    {
      "x": 3,
      "y": 1,
      "z": 1,
      "name": "Rock_Stone"
    },
    {
      "x": 3,
      "y": 2,
      "z": 1,
      "name": "Rock_Stone_Cobble"
    },
    {
      "x": 3,
      "y": 3,
      "z": 1,
      "name": "Rock_Stone_Cobble"
    },
    {
      "x": 3,
      "y": 4,
      "z": 1,
      "name": "Empty"
    },
    {
      "x": 3,
      "y": 5,
      "z": 1,
      "name": "Empty"
    },
    {
      "x": 3,
      "y": 6,
      "z": 1,
      "name": "Rock_Stone"
    },
    {
      "x": 3,
      "y": 7,
      "z": 1,
      "name": "Rock_Stone"
    },
    {
      "x": 3,
      "y": 8,
      "z": 1,
      "name": "Rock_Stone"
    },
    {
      "x": 3,
      "y": 9,
      "z": 1,
      "name": "Rock_Stone"
    },
    {
      "x": 3,
      "y": 10,
      "z": 1,
      "name": "Rock_Stone"
    },
    {
      "x": 3,
      "y": 11,
      "z": 1,
      "name": "Rock_Stone"
    },
    {
      "x": 3,
      "y": -1,
      "z": 2,
      "name": "Rock_Stone"
    },
    {
      "x": 3,
      "y": 0,
      "z": 2,
      "name": "Rock_Stone"
    },
    {
      "x": 3,
      "y": 1,
      "z": 2,
      "name": "Rock_Stone"
    },
    {
      "x": 3,
      "y": 2,
      "z": 2,
      "name": "Rock_Stone"
    },
    {
      "x": 3,
      "y": 3,
      "z": 2,
      "name": "Wood_Beech_Trunk"
    },
    {
      "x": 3,
      "y": 4,
      "z": 2,
      "name": "Wood_Beech_Trunk"
    },
    {
      "x": 3,
      "y": 5,
      "z": 2,
      "name": "Wood_Beech_Trunk"
    },
    {
      "x": 3,
      "y": 6,
      "z": 2,
      "name": "Wood_Beech_Trunk"
    },
    {
      "x": 3,
      "y": 7,
      "z": 2,
      "name": "Wood_Beech_Trunk"
    },
    {
      "x": 3,
      "y": 8,
      "z": 2,
      "name": "Wood_Beech_Trunk",
      "rotation": 5
    },
    {
      "x": 3,
      "y": 9,
      "z": 2,
      "name": "Rock_Stone"
    },
    {
      "x": 3,
      "y": 10,
      "z": 2,
      "name": "Rock_Stone"
    },
    {
      "x": 3,
      "y": 11,
      "z": 2,
      "name": "Rock_Stone"
    },
    {
      "x": 3,
      "y": -1,
      "z": 3,
      "name": "Rock_Stone"
    },
    {
      "x": 3,
      "y": 0,
      "z": 3,
      "name": "Rock_Stone"
    },
    {
      "x": 3,
      "y": 1,
      "z": 3,
      "name": "Rock_Stone"
    },
    {
      "x": 3,
      "y": 2,
      "z": 3,
      "name": "Rock_Stone"
    },
    {
      "x": 3,
      "y": 3,
      "z": 3,
      "name": "Rock_Stone"
    },
    {
      "x": 3,
      "y": 4,
      "z": 3,
      "name": "Rock_Stone"
    },
    {
      "x": 3,
      "y": 5,
      "z": 3,
      "name": "Rock_Stone"
    },
    {
      "x": 3,
      "y": 6,
      "z": 3,
      "name": "Empty"
    },
    {
      "x": 3,
      "y": 7,
      "z": 3,
      "name": "Empty"
    },
    {
      "x": 3,
      "y": 8,
      "z": 3,
      "name": "Wood_Softwood_Planks_Half",
      "rotation": 4
    },
    {
      "x": 3,
      "y": 9,
      "z": 3,
      "name": "Rock_Stone"
    },
    {
      "x": 3,
      "y": 10,
      "z": 3,
      "name": "Rock_Stone"
    },
    {
      "x": 3,
      "y": 11,
      "z": 3,
      "name": "Rock_Stone"
    },
    {
      "x": 3,
      "y": -1,
      "z": 4,
      "name": "Rock_Stone"
    },
    {
      "x": 3,
      "y": 0,
      "z": 4,
      "name": "Rock_Stone"
    },
    {
      "x": 3,
      "y": 1,
      "z": 4,
      "name": "Rock_Stone"
    },
    {
      "x": 3,
      "y": 2,
      "z": 4,
      "name": "Rock_Stone"
    },
    {
      "x": 3,
      "y": 3,
      "z": 4,
      "name": "Rock_Stone"
    },
    {
      "x": 3,
      "y": 4,
      "z": 4,
      "name": "Empty"
    },
    {
      "x": 3,
      "y": 5,
      "z": 4,
      "name": "Empty"
    },
    {
      "x": 3,
      "y": 6,
      "z": 4,
      "name": "Empty"
    },
    {
      "x": 3,
      "y": 7,
      "z": 4,
      "name": "Empty"
    },
    {
      "x": 3,
      "y": 8,
      "z": 4,
      "name": "Empty"
    },
    {
      "x": 3,
      "y": 9,
      "z": 4,
      "name": "Rock_Stone"
    },
    {
      "x": 3,
      "y": 10,
      "z": 4,
      "name": "Rock_Stone"
    },
    {
      "x": 3,
      "y": 11,
      "z": 4,
      "name": "Rock_Stone"
    },
    {
      "x": 4,
      "y": -1,
      "z": 0,
      "name": "Rock_Stone"
    },
    {
      "x": 4,
      "y": 0,
      "z": 0,
      "name": "Rock_Stone"
    },
    {
      "x": 4,
      "y": 1,
      "z": 0,
      "name": "Rock_Stone"
    },
    {
      "x": 4,
      "y": 2,
      "z": 0,
      "name": "Rock_Stone"
    },
    {
      "x": 4,
      "y": 3,
      "z": 0,
      "name": "Rock_Stone"
    },
    {
      "x": 4,
      "y": 4,
      "z": 0,
      "name": "Rock_Stone"
    },
    {
      "x": 4,
      "y": 5,
      "z": 0,
      "name": "Rock_Stone"
    },
    {
      "x": 4,
      "y": 6,
      "z": 0,
      "name": "Rock_Stone"
    },
    {
      "x": 4,
      "y": 7,
      "z": 0,
      "name": "Rock_Stone"
    },
    {
      "x": 4,
      "y": 8,
      "z": 0,
      "name": "Rock_Stone"
    },
    {
      "x": 4,
      "y": 9,
      "z": 0,
      "name": "Rock_Stone"
    },
    {
      "x": 4,
      "y": 10,
      "z": 0,
      "name": "Rock_Stone"
    },
    {
      "x": 4,
      "y": 11,
      "z": 0,
      "name": "Rock_Stone"
    },
    {
      "x": 4,
      "y": -1,
      "z": 1,
      "name": "Rock_Stone"
    },
    {
      "x": 4,
      "y": 0,
      "z": 1,
      "name": "Rock_Stone"
    },
    {
      "x": 4,
      "y": 1,
      "z": 1,
      "name": "Rock_Stone"
    },
    {
      "x": 4,
      "y": 2,
      "z": 1,
      "name": "Rock_Stone"
    },
    {
      "x": 4,
      "y": 3,
      "z": 1,
      "name": "Rock_Stone"
    },
    {
      "x": 4,
      "y": 4,
      "z": 1,
      "name": "Rock_Stone"
    },
    {
      "x": 4,
      "y": 5,
      "z": 1,
      "name": "Rock_Stone"
    },
    {
      "x": 4,
      "y": 6,
      "z": 1,
      "name": "Rock_Stone"
    },
    {
      "x": 4,
      "y": 7,
      "z": 1,
      "name": "Rock_Stone"
    },
    {
      "x": 4,
      "y": 8,
      "z": 1,
      "name": "Rock_Stone"
    },
    {
      "x": 4,
      "y": 9,
      "z": 1,
      "name": "Rock_Stone"
    },
    {
      "x": 4,
      "y": 10,
      "z": 1,
      "name": "Rock_Stone"
    },
    {
      "x": 4,
      "y": 11,
      "z": 1,
      "name": "Rock_Stone"
    },
    {
      "x": 4,
      "y": -1,
      "z": 2,
      "name": "Rock_Stone"
    },
    {
      "x": 4,
      "y": 0,
      "z": 2,
      "name": "Rock_Stone"
    },
    {
      "x": 4,
      "y": 1,
      "z": 2,
      "name": "Rock_Stone"
    },
    {
      "x": 4,
      "y": 2,
      "z": 2,
      "name": "Rock_Stone"
    },
    {
      "x": 4,
      "y": 3,
      "z": 2,
      "name": "Rock_Stone"
    },
    {
      "x": 4,
      "y": 4,
      "z": 2,
      "name": "Rock_Stone"
    },
    {
      "x": 4,
      "y": 5,
      "z": 2,
      "name": "Rock_Stone"
    },
    {
      "x": 4,
      "y": 6,
      "z": 2,
      "name": "Rock_Stone"
    },
    {
      "x": 4,
      "y": 7,
      "z": 2,
      "name": "Rock_Stone"
    },
    {
      "x": 4,
      "y": 8,
      "z": 2,
      "name": "Rock_Stone"
    },
    {
      "x": 4,
      "y": 9,
      "z": 2,
      "name": "Rock_Stone"
    },
    {
      "x": 4,
      "y": 10,
      "z": 2,
      "name": "Rock_Stone"
    },
    {
      "x": 4,
      "y": 11,
      "z": 2,
      "name": "Rock_Stone"
    },
    {
      "x": 4,
      "y": -1,
      "z": 3,
      "name": "Rock_Stone"
    },
    {
      "x": 4,
      "y": 0,
      "z": 3,
      "name": "Rock_Stone"
    },
    {
      "x": 4,
      "y": 1,
      "z": 3,
      "name": "Rock_Stone"
    },
    {
      "x": 4,
      "y": 2,
      "z": 3,
      "name": "Rock_Stone"
    },
    {
      "x": 4,
      "y": 3,
      "z": 3,
      "name": "Rock_Stone"
    },
    {
      "x": 4,
      "y": 4,
      "z": 3,
      "name": "Rock_Stone"
    },
    {
      "x": 4,
      "y": 5,
      "z": 3,
      "name": "Rock_Stone"
    },
    {
      "x": 4,
      "y": 6,
      "z": 3,
      "name": "Rock_Stone"
    },
    {
      "x": 4,
      "y": 7,
      "z": 3,
      "name": "Rock_Stone"
    },
    {
      "x": 4,
      "y": 8,
      "z": 3,
      "name": "Rock_Stone"
    },
    {
      "x": 4,
      "y": 9,
      "z": 3,
      "name": "Rock_Stone"
    },
    {
      "x": 4,
      "y": 10,
      "z": 3,
      "name": "Rock_Stone"
    },
    {
      "x": 4,
      "y": 11,
      "z": 3,
      "name": "Rock_Stone"
    },
    {
      "x": 4,
      "y": -1,
      "z": 4,
      "name": "Rock_Stone"
    },
    {
      "x": 4,
      "y": 0,
      "z": 4,
      "name": "Rock_Stone"
    },
    {
      "x": 4,
      "y": 1,
      "z": 4,
      "name": "Rock_Stone"
    },
    {
      "x": 4,
      "y": 2,
      "z": 4,
      "name": "Rock_Stone"
    },
    {
      "x": 4,
      "y": 3,
      "z": 4,
      "name": "Rock_Stone"
    },
    {
      "x": 4,
      "y": 4,
      "z": 4,
      "name": "Rock_Stone"
    },
    {
      "x": 4,
      "y": 5,
      "z": 4,
      "name": "Rock_Stone"
    },
    {
      "x": 4,
      "y": 6,
      "z": 4,
      "name": "Rock_Stone"
    },
    {
      "x": 4,
      "y": 7,
      "z": 4,
      "name": "Rock_Stone"
    },
    {
      "x": 4,
      "y": 8,
      "z": 4,
      "name": "Rock_Stone"
    },
    {
      "x": 4,
      "y": 9,
      "z": 4,
      "name": "Rock_Stone"
    },
    {
      "x": 4,
      "y": 10,
      "z": 4,
      "name": "Rock_Stone"
    },
    {
      "x": 4,
      "y": 11,
      "z": 4,
      "name": "Rock_Stone"
    }
  ]
}