{
  "version": 8,
  "blockIdVersion": 8,
  "anchorX": -4,
  "anchorY": 8,
  "anchorZ": 0,
  "blocks": [
    {
      "x": -12,
      "y": 6,
      "z": -3,
      "name": "Rock_Basalt"
    },
    {
      "x": -12,
      "y": 7,
      "z": -3,
      "name": "Rock_Basalt"
    },
    {
      "x": -12,
      "y": 8,
      "z": -3,
      "name": "Rock_Basalt"
    },
    {
      "x": -12,
      "y": 6,
      "z": -2,
      "name": "Rock_Basalt"
    },
    {
      "x": -12,
      "y": 7,
      "z": -2,
      "name": "Rock_Basalt"
    },
    {
      "x": -12,
      "y": 8,
      "z": -2,
      "name": "Rock_Basalt"
    },
    {
      "x": -11,
      "y": 6,
      "z": -4,
      "name": "Rock_Basalt"
    },
    {
      "x": -11,
      "y": 7,
      "z": -4,
      "name": "Rock_Basalt"
    },
    {
      "x": -11,
      "y": 8,
      "z": -4,
      "name": "Rock_Basalt"
    },
    {
      "x": -11,
      "y": 5,
      "z": -3,
      "name": "Rock_Basalt"
    },
    {
      "x": -11,
      "y": 6,
      "z": -3,
      "name": "Rock_Basalt"
    },
    {
      "x": -11,
      "y": 7,
      "z": -3,
      "name": "Rock_Basalt"
    },
    {
      "x": -11,
      "y": 8,
      "z": -3,
      "name": "Rock_Basalt"
    },
    {
      "x": -11,
      "y": 9,
      "z": -3,
      "name": "Rock_Basalt"
    },
    {
      "x": -11,
      "y": 5,
      "z": -2,
      "name": "Rock_Basalt"
    },
    {
      "x": -11,
      "y": 6,
      "z": -2,
      "name": "Rock_Basalt"
    },
    {
      "x": -11,
      "y": 7,
      "z": -2,
      "name": "Rock_Basalt"
    },
    {
      "x": -11,
      "y": 8,
      "z": -2,
      "name": "Rock_Basalt"
    },
    {
      "x": -11,
      "y": 9,
      "z": -2,
      "name": "Rock_Basalt"
    },
    {
      "x": -11,
      "y": 6,
      "z": -1,
      "name": "Rock_Basalt"
    },
    {
      "x": -11,
      "y": 7,
      "z": -1,
      "name": "Rock_Basalt"
    },
    {
      "x": -11,
      "y": 8,
      "z": -1,
      "name": "Rock_Basalt"
    },
    {
      "x": -11,
      "y": 9,
      "z": -1,
      "name": "Rock_Basalt"
    },
    {
      "x": -11,
      "y": 7,
      "z": 0,
      "name": "Rock_Basalt"
    },
    {
      "x": -11,
      "y": 8,
      "z": 0,
      "name": "Rock_Basalt"
    },
    {
      "x": -11,
      "y": 9,
      "z": 0,
      "name": "Rock_Basalt"
    },
    {
      "x": -10,
      "y": 6,
      "z": -4,
      "name": "Rock_Basalt"
    },
    {
      "x": -10,
      "y": 7,
      "z": -4,
      "name": "Rock_Basalt"
    },
    {
      "x": -10,
      "y": 8,
      "z": -4,
      "name": "Rock_Basalt"
    },
    {
      "x": -10,
      "y": 9,
      "z": -4,
      "name": "Rock_Basalt"
    },
    {
      "x": -10,
      "y": 5,
      "z": -3,
      "name": "Rock_Basalt"
    },
    {
      "x": -10,
      "y": 6,
      "z": -3,
      "name": "Rock_Basalt"
    },
    {
      "x": -10,
      "y": 7,
      "z": -3,
      "name": "Rock_Basalt"
    },
    {
      "x": -10,
      "y": 8,
      "z": -3,
      "name": "Rock_Basalt"
    },
    {
      "x": -10,
      "y": 9,
      "z": -3,
      "name": "Rock_Basalt"
    },
    {
      "x": -10,
      "y": 5,
      "z": -2,
      "name": "Rock_Basalt"
    },
    {
      "x": -10,
      "y": 6,
      "z": -2,
      "name": "Rock_Basalt"
    },
    {
      "x": -10,
      "y": 7,
      "z": -2,
      "name": "Rock_Basalt"
    },
    {
      "x": -10,
      "y": 8,
      "z": -2,
      "name": "Rock_Basalt"
    },
    {
      "x": -10,
      "y": 9,
      "z": -2,
      "name": "Rock_Basalt"
    },
    {
      "x": -10,
      "y": 10,
      "z": -2,
      "name": "Rock_Basalt"
    },
    {
      "x": -10,
      "y": 5,
      "z": -1,
      "name": "Rock_Basalt"
    },
    {
      "x": -10,
      "y": 6,
      "z": -1,
      "name": "Rock_Basalt"
    },
    {
      "x": -10,
      "y": 7,
      "z": -1,
      "name": "Rock_Basalt"
    },
    {
      "x": -10,
      "y": 8,
      "z": -1,
      "name": "Rock_Basalt"
    },
    {
      "x": -10,
      "y": 9,
      "z": -1,
      "name": "Rock_Basalt"
    },
    {
      "x": -10,
      "y": 10,
      "z": -1,
      "name": "Rock_Basalt"
    },
    {
      "x": -10,
      "y": 5,
      "z": 0,
      "name": "Rock_Basalt"
    },
    {
      "x": -10,
      "y": 6,
      "z": 0,
      "name": "Rock_Basalt"
    },
    {
      "x": -10,
      "y": 7,
      "z": 0,
      "name": "Rock_Basalt"
    },
    {
      "x": -10,
      "y": 8,
      "z": 0,
      "name": "Rock_Basalt"
    },
    {
      "x": -10,
      "y": 9,
      "z": 0,
      "name": "Rock_Basalt"
    },
    {
      "x": -9,
      "y": 6,
      "z": -4,
      "name": "Rock_Basalt"
    },
    {
      "x": -9,
      "y": 7,
      "z": -4,
      "name": "Rock_Basalt"
    },
    {
      "x": -9,
      "y": 8,
      "z": -4,
      "name": "Rock_Basalt"
    },
    {
      "x": -9,
      "y": 9,
      "z": -4,
      "name": "Rock_Basalt"
    },
    {
      "x": -9,
      "y": 5,
      "z": -3,
      "name": "Rock_Basalt"
    },
    {
      "x": -9,
      "y": 6,
      "z": -3,
      "name": "Rock_Basalt"
    },
    {
      "x": -9,
      "y": 7,
      "z": -3,
      "name": "Rock_Basalt"
    },
    {
      "x": -9,
      "y": 8,
      "z": -3,
      "name": "Rock_Basalt"
    },
    {
      "x": -9,
      "y": 9,
      "z": -3,
      "name": "Rock_Basalt"
    },
    {
      "x": -9,
      "y": 10,
      "z": -3,
      "name": "Rock_Basalt"
    },
    {
      "x": -9,
      "y": 11,
      "z": -3,
      "name": "Plant_Moss_Rug_Green"
    },
    {
      "x": -9,
      "y": 5,
      "z": -2,
      "name": "Rock_Basalt"
    },
    {
      "x": -9,
      "y": 6,
      "z": -2,
      "name": "Rock_Basalt"
    },
    {
      "x": -9,
      "y": 7,
      "z": -2,
      "name": "Rock_Basalt"
    },
    {
      "x": -9,
      "y": 8,
      "z": -2,
      "name": "Rock_Basalt"
    },
    {
      "x": -9,
      "y": 9,
      "z": -2,
      "name": "Rock_Basalt"
    },
    {
      "x": -9,
      "y": 10,
      "z": -2,
      "name": "Plant_Moss_Block_Green"
    },
    {
      "x": -9,
      "y": 11,
      "z": -2,
      "name": "Plant_Moss_Rug_Green"
    },
    {
      "x": -9,
      "y": 5,
      "z": -1,
      "name": "Rock_Basalt"
    },
    {
      "x": -9,
      "y": 6,
      "z": -1,
      "name": "Rock_Basalt"
    },
    {
      "x": -9,
      "y": 7,
      "z": -1,
      "name": "Rock_Basalt"
    },
    {
      "x": -9,
      "y": 8,
      "z": -1,
      "name": "Rock_Basalt"
    },
    {
      "x": -9,
      "y": 9,
      "z": -1,
      "name": "Rock_Basalt"
    },
    {
      "x": -9,
      "y": 10,
      "z": -1,
      "name": "Plant_Moss_Block_Green"
    },
    {
      "x": -9,
      "y": 5,
      "z": 0,
      "name": "Rock_Basalt"
    },
    {
      "x": -9,
      "y": 6,
      "z": 0,
      "name": "Rock_Basalt"
    },
    {
      "x": -9,
      "y": 7,
      "z": 0,
      "name": "Rock_Basalt"
    },
    {
      "x": -9,
      "y": 8,
      "z": 0,
      "name": "Rock_Basalt"
    },
    {
      "x": -9,
      "y": 9,
      "z": 0,
      "name": "Rock_Basalt"
    },
    {
      "x": -9,
      "y": 10,
      "z": 0,
      "name": "Rock_Basalt"
    },
    {
      "x": -9,
      "y": 11,
      "z": 0,
      "name": "Plant_Moss_Rug_Green"
    },
    {
      "x": -9,
      "y": 7,
      "z": 1,
      "name": "Rock_Basalt"
    },
    {
      "x": -9,
      "y": 8,
      "z": 1,
      "name": "Rock_Basalt"
    },
    {
      "x": -9,
      "y": 9,
      "z": 1,
      "name": "Rock_Basalt"
    },
    {
      "x": -9,
      "y": 10,
      "z": 1,
      "name": "Rock_Basalt"
    },
    {
      "x": -8,
      "y": 6,
      "z": -4,
      "name": "Rock_Basalt"
    },
    {
      "x": -8,
      "y": 7,
      "z": -4,
      "name": "Rock_Basalt"
    },
    {
      "x": -8,
      "y": 8,
      "z": -4,
      "name": "Rock_Basalt"
    },
    {
      "x": -8,
      "y": 9,
      "z": -4,
      "name": "Rock_Basalt"
    },
    {
      "x": -8,
      "y": 10,
      "z": -4,
      "name": "Rock_Basalt"
    },
    {
      "x": -8,
      "y": 5,
      "z": -3,
      "name": "Rock_Basalt"
    },
    {
      "x": -8,
      "y": 6,
      "z": -3,
      "name": "Rock_Basalt"
    },
    {
      "x": -8,
      "y": 7,
      "z": -3,
      "name": "Rock_Basalt"
    },
    {
      "x": -8,
      "y": 8,
      "z": -3,
      "name": "Rock_Basalt"
    },
    {
      "x": -8,
      "y": 9,
      "z": -3,
      "name": "Rock_Basalt"
    },
    {
      "x": -8,
      "y": 10,
      "z": -3,
      "name": "Rock_Basalt"
    },
    {
      "x": -8,
      "y": 11,
      "z": -3,
      "name": "Plant_Moss_Rug_Green"
    },
    {
      "x": -8,
      "y": 5,
      "z": -2,
      "name": "Rock_Basalt"
    },
    {
      "x": -8,
      "y": 6,
      "z": -2,
      "name": "Rock_Basalt"
    },
    {
      "x": -8,
      "y": 7,
      "z": -2,
      "name": "Rock_Basalt"
    },
    {
      "x": -8,
      "y": 8,
      "z": -2,
      "name": "Rock_Basalt"
    },
    {
      "x": -8,
      "y": 9,
      "z": -2,
      "name": "Rock_Basalt"
    },
    {
      "x": -8,
      "y": 10,
      "z": -2,
      "name": "Rock_Basalt"
    },
    {
      "x": -8,
      "y": 11,
      "z": -2,
      "name": "Rock_Basalt"
    },
    {
      "x": -8,
      "y": 5,
      "z": -1,
      "name": "Rock_Basalt"
    },
    {
      "x": -8,
      "y": 6,
      "z": -1,
      "name": "Rock_Basalt"
    },
    {
      "x": -8,
      "y": 7,
      "z": -1,
      "name": "Rock_Basalt"
    },
    {
      "x": -8,
      "y": 8,
      "z": -1,
      "name": "Rock_Basalt"
    },
    {
      "x": -8,
      "y": 9,
      "z": -1,
      "name": "Rock_Basalt"
    },
    {
      "x": -8,
      "y": 10,
      "z": -1,
      "name": "Rock_Basalt"
    },
    {
      "x": -8,
      "y": 11,
      "z": -1,
      "name": "Plant_Moss_Block_Green"
    },
    {
      "x": -8,
      "y": 5,
      "z": 0,
      "name": "Rock_Basalt"
    },
    {
      "x": -8,
      "y": 6,
      "z": 0,
      "name": "Rock_Basalt"
    },
    {
      "x": -8,
      "y": 7,
      "z": 0,
      "name": "Rock_Basalt"
    },
    {
      "x": -8,
      "y": 8,
      "z": 0,
      "name": "Rock_Basalt"
    },
    {
      "x": -8,
      "y": 9,
      "z": 0,
      "name": "Rock_Basalt"
    },
    {
      "x": -8,
      "y": 10,
      "z": 0,
      "name": "Rock_Basalt"
    },
    {
      "x": -8,
      "y": 11,
      "z": 0,
      "name": "Plant_Moss_Block_Green"
    },
    {
      "x": -8,
      "y": 6,
      "z": 1,
      "name": "Rock_Basalt"
    },
    {
      "x": -8,
      "y": 7,
      "z": 1,
      "name": "Rock_Basalt"
    },
    {
      "x": -8,
      "y": 8,
      "z": 1,
      "name": "Rock_Basalt"
    },
    {
      "x": -8,
      "y": 9,
      "z": 1,
      "name": "Rock_Basalt"
    },
    {
      "x": -8,
      "y": 10,
      "z": 1,
      "name": "Rock_Basalt"
    },
    {
      "x": -7,
      "y": 7,
      "z": -4,
      "name": "Rock_Basalt"
    },
    {
      "x": -7,
      "y": 8,
      "z": -4,
      "name": "Rock_Basalt"
    },
    {
      "x": -7,
      "y": 9,
      "z": -4,
      "name": "Rock_Basalt"
    },
    {
      "x": -7,
      "y": 10,
      "z": -4,
      "name": "Rock_Basalt"
    },
    {
      "x": -7,
      "y": 6,
      "z": -3,
      "name": "Rock_Basalt"
    },
    {
      "x": -7,
      "y": 7,
      "z": -3,
      "name": "Rock_Basalt"
    },
    {
      "x": -7,
      "y": 8,
      "z": -3,
      "name": "Rock_Basalt"
    },
    {
      "x": -7,
      "y": 9,
      "z": -3,
      "name": "Rock_Basalt"
    },
    {
      "x": -7,
      "y": 10,
      "z": -3,
      "name": "Rock_Basalt"
    },
    {
      "x": -7,
      "y": 11,
      "z": -3,
      "name": "Rock_Basalt"
    },
    {
      "x": -7,
      "y": 5,
      "z": -2,
      "name": "Rock_Basalt"
    },
    {
      "x": -7,
      "y": 6,
      "z": -2,
      "name": "Rock_Basalt"
    },
    {
      "x": -7,
      "y": 7,
      "z": -2,
      "name": "Rock_Basalt"
    },
    {
      "x": -7,
      "y": 8,
      "z": -2,
      "name": "Rock_Basalt"
    },
    {
      "x": -7,
      "y": 9,
      "z": -2,
      "name": "Rock_Basalt"
    },
    {
      "x": -7,
      "y": 10,
      "z": -2,
      "name": "Rock_Basalt"
    },
    {
      "x": -7,
      "y": 11,
      "z": -2,
      "name": "Rock_Basalt"
    },
    {
      "x": -7,
      "y": 5,
      "z": -1,
      "name": "Rock_Basalt"
    },
    {
      "x": -7,
      "y": 6,
      "z": -1,
      "name": "Rock_Basalt"
    },
    {
      "x": -7,
      "y": 7,
      "z": -1,
      "name": "Rock_Basalt"
    },
    {
      "x": -7,
      "y": 8,
      "z": -1,
      "name": "Rock_Basalt"
    },
    {
      "x": -7,
      "y": 9,
      "z": -1,
      "name": "Rock_Basalt"
    },
    {
      "x": -7,
      "y": 10,
      "z": -1,
      "name": "Rock_Basalt"
    },
    {
      "x": -7,
      "y": 11,
      "z": -1,
      "name": "Plant_Moss_Block_Green"
    },
    {
      "x": -7,
      "y": 5,
      "z": 0,
      "name": "Rock_Basalt"
    },
    {
      "x": -7,
      "y": 6,
      "z": 0,
      "name": "Rock_Basalt"
    },
    {
      "x": -7,
      "y": 7,
      "z": 0,
      "name": "Rock_Basalt"
    },
    {
      "x": -7,
      "y": 8,
      "z": 0,
      "name": "Rock_Basalt"
    },
    {
      "x": -7,
      "y": 9,
      "z": 0,
      "name": "Rock_Basalt"
    },
    {
      "x": -7,
      "y": 10,
      "z": 0,
      "name": "Rock_Basalt"
    },
    {
      "x": -7,
      "y": 11,
      "z": 0,
      "name": "Plant_Moss_Block_Green"
    },
    {
      "x": -7,
      "y": 6,
      "z": 1,
      "name": "Rock_Basalt"
    },
    {
      "x": -7,
      "y": 7,
      "z": 1,
      "name": "Rock_Basalt"
    },
    {
      "x": -7,
      "y": 8,
      "z": 1,
      "name": "Rock_Basalt"
    },
    {
      "x": -7,
      "y": 9,
      "z": 1,
      "name": "Rock_Basalt"
    },
    {
      "x": -7,
      "y": 10,
      "z": 1,
      "name": "Rock_Basalt"
    },
    {
      "x": -7,
      "y": 11,
      "z": 1,
      "name": "Rock_Basalt"
    },
    {
      "x": -6,
      "y": 6,
      "z": -3,
      "name": "Rock_Basalt"
    },
    {
      "x": -6,
      "y": 7,
      "z": -3,
      "name": "Rock_Basalt"
    },
    {
      "x": -6,
      "y": 8,
      "z": -3,
      "name": "Rock_Basalt"
    },
    {
      "x": -6,
      "y": 9,
      "z": -3,
      "name": "Rock_Basalt"
    },
    {
      "x": -6,
      "y": 10,
      "z": -3,
      "name": "Rock_Basalt"
    },
    {
      "x": -6,
      "y": 11,
      "z": -3,
      "name": "Rock_Basalt"
    },
    {
      "x": -6,
      "y": 5,
      "z": -2,
      "name": "Rock_Basalt"
    },
    {
      "x": -6,
      "y": 6,
      "z": -2,
      "name": "Rock_Basalt"
    },
    {
      "x": -6,
      "y": 7,
      "z": -2,
      "name": "Rock_Basalt"
    },
    {
      "x": -6,
      "y": 8,
      "z": -2,
      "name": "Rock_Basalt"
    },
    {
      "x": -6,
      "y": 9,
      "z": -2,
      "name": "Rock_Basalt"
    },
    {
      "x": -6,
      "y": 10,
      "z": -2,
      "name": "Rock_Basalt"
    },
    {
      "x": -6,
      "y": 11,
      "z": -2,
      "name": "Plant_Moss_Block_Green"
    },
    {
      "x": -6,
      "y": 5,
      "z": -1,
      "name": "Rock_Basalt"
    },
    {
      "x": -6,
      "y": 6,
      "z": -1,
      "name": "Rock_Basalt"
    },
    {
      "x": -6,
      "y": 7,
      "z": -1,
      "name": "Rock_Basalt"
    },
    {
      "x": -6,
      "y": 8,
      "z": -1,
      "name": "Rock_Basalt"
    },
    {
      "x": -6,
      "y": 9,
      "z": -1,
      "name": "Rock_Basalt"
    },
    {
      "x": -6,
      "y": 10,
      "z": -1,
      "name": "Rock_Basalt"
    },
    {
      "x": -6,
      "y": 11,
      "z": -1,
      "name": "Plant_Moss_Block_Green"
    },
    {
      "x": -6,
      "y": 5,
      "z": 0,
      "name": "Rock_Basalt"
    },
    {
      "x": -6,
      "y": 6,
      "z": 0,
      "name": "Rock_Basalt"
    },
    {
      "x": -6,
      "y": 7,
      "z": 0,
      "name": "Rock_Basalt"
    },
    {
      "x": -6,
      "y": 8,
      "z": 0,
      "name": "Rock_Basalt"
    },
    {
      "x": -6,
      "y": 9,
      "z": 0,
      "name": "Rock_Basalt"
    },
    {
      "x": -6,
      "y": 10,
      "z": 0,
      "name": "Rock_Basalt"
    },
    {
      "x": -6,
      "y": 11,
      "z": 0,
      "name": "Plant_Moss_Block_Green"
    },
    {
      "x": -6,
      "y": 7,
      "z": 1,
      "name": "Rock_Basalt"
    },
    {
      "x": -6,
      "y": 8,
      "z": 1,
      "name": "Rock_Basalt"
    },
    {
      "x": -6,
      "y": 9,
      "z": 1,
      "name": "Rock_Basalt"
    },
    {
      "x": -6,
      "y": 10,
      "z": 1,
      "name": "Rock_Basalt"
    },
    {
      "x": -6,
      "y": 11,
      "z": 1,
      "name": "Rock_Basalt"
    },
    {
      "x": -5,
      "y": 8,
      "z": -3,
      "name": "Rock_Basalt"
    },
    {
      "x": -5,
      "y": 9,
      "z": -3,
      "name": "Rock_Basalt"
    },
    {
      "x": -5,
      "y": 10,
      "z": -3,
      "name": "Rock_Basalt"
    },
    {
      "x": -5,
      "y": 11,
      "z": -3,
      "name": "Rock_Basalt"
    },
    {
      "x": -5,
      "y": 5,
      "z": -2,
      "name": "Rock_Basalt"
    },
    {
      "x": -5,
      "y": 6,
      "z": -2,
      "name": "Rock_Basalt"
    },
    {
      "x": -5,
      "y": 7,
      "z": -2,
      "name": "Rock_Basalt"
    },
    {
      "x": -5,
      "y": 8,
      "z": -2,
      "name": "Rock_Basalt"
    },
    {
      "x": -5,
      "y": 9,
      "z": -2,
      "name": "Rock_Basalt"
    },
    {
      "x": -5,
      "y": 10,
      "z": -2,
      "name": "Rock_Basalt"
    },
    {
      "x": -5,
      "y": 11,
      "z": -2,
      "name": "Plant_Moss_Block_Green"
    },
    {
      "x": -5,
      "y": 5,
      "z": -1,
      "name": "Rock_Basalt"
    },
    {
      "x": -5,
      "y": 6,
      "z": -1,
      "name": "Rock_Basalt"
    },
    {
      "x": -5,
      "y": 7,
      "z": -1,
      "name": "Rock_Basalt"
    },
    {
      "x": -5,
      "y": 8,
      "z": -1,
      "name": "Rock_Basalt"
    },
    {
      "x": -5,
      "y": 9,
      "z": -1,
      "name": "Rock_Basalt"
    },
    {
      "x": -5,
      "y": 10,
      "z": -1,
      "name": "Rock_Basalt"
    },
    {
      "x": -5,
      "y": 11,
      "z": -1,
      "name": "Plant_Moss_Block_Green"
    },
    {
      "x": -5,
      "y": 12,
      "z": -1,
      "name": "Plant_Moss_Rug_Green"
    },
    {
      "x": -5,
      "y": 6,
      "z": 0,
      "name": "Rock_Basalt"
    },
    {
      "x": -5,
      "y": 7,
      "z": 0,
      "name": "Rock_Basalt"
    },
    {
      "x": -5,
      "y": 8,
      "z": 0,
      "name": "Rock_Basalt"
    },
    {
      "x": -5,
      "y": 9,
      "z": 0,
      "name": "Rock_Basalt"
    },
    {
      "x": -5,
      "y": 10,
      "z": 0,
      "name": "Rock_Basalt"
    },
    {
      "x": -5,
      "y": 11,
      "z": 0,
      "name": "Plant_Moss_Block_Green"
    },
    {
      "x": -5,
      "y": 12,
      "z": 0,
      "name": "Plant_Moss_Rug_Green"
    },
    {
      "x": -5,
      "y": 6,
      "z": 1,
      "name": "Rock_Basalt"
    },
    {
      "x": -5,
      "y": 7,
      "z": 1,
      "name": "Rock_Basalt"
    },
    {
      "x": -5,
      "y": 8,
      "z": 1,
      "name": "Rock_Basalt"
    },
    {
      "x": -5,
      "y": 9,
      "z": 1,
      "name": "Rock_Basalt"
    },
    {
      "x": -5,
      "y": 10,
      "z": 1,
      "name": "Rock_Basalt"
    },
    {
      "x": -5,
      "y": 11,
      "z": 1,
      "name": "Rock_Basalt"
    },
    {
      "x": -5,
      "y": 7,
      "z": 2,
      "name": "Rock_Basalt"
    },
    {
      "x": -5,
      "y": 8,
      "z": 2,
      "name": "Rock_Basalt"
    },
    {
      "x": -5,
      "y": 9,
      "z": 2,
      "name": "Rock_Basalt"
    },
    {
      "x": -4,
      "y": 7,
      "z": -2,
      "name": "Rock_Basalt"
    },
    {
      "x": -4,
      "y": 8,
      "z": -2,
      "name": "Rock_Basalt"
    },
    {
      "x": -4,
      "y": 9,
      "z": -2,
      "name": "Rock_Basalt"
    },
    {
      "x": -4,
      "y": 10,
      "z": -2,
      "name": "Rock_Basalt"
    },
    {
      "x": -4,
      "y": 11,
      "z": -2,
      "name": "Rock_Basalt"
    },
    {
      "x": -4,
      "y": 12,
      "z": -2,
      "name": "Plant_Moss_Rug_Green"
    },
    {
      "x": -4,
      "y": 7,
      "z": -1,
      "name": "Rock_Basalt"
    },
    {
      "x": -4,
      "y": 8,
      "z": -1,
      "name": "Rock_Basalt"
    },
    {
      "x": -4,
      "y": 9,
      "z": -1,
      "name": "Rock_Basalt"
    },
    {
      "x": -4,
      "y": 10,
      "z": -1,
      "name": "Rock_Basalt"
    },
    {
      "x": -4,
      "y": 11,
      "z": -1,
      "name": "Rock_Basalt"
    },
    {
      "x": -4,
      "y": 12,
      "z": -1,
      "name": "Plant_Moss_Rug_Green"
    },
    {
      "x": -4,
      "y": 6,
      "z": 0,
      "name": "Rock_Basalt"
    },
    {
      "x": -4,
      "y": 7,
      "z": 0,
      "name": "Rock_Basalt"
    },
    {
      "x": -4,
      "y": 8,
      "z": 0,
      "name": "Rock_Basalt"
    },
    {
      "x": -4,
      "y": 9,
      "z": 0,
      "name": "Rock_Basalt"
    },
    {
      "x": -4,
      "y": 10,
      "z": 0,
      "name": "Rock_Basalt"
    },
    {
      "x": -4,
      "y": 11,
      "z": 0,
      "name": "Rock_Basalt"
    },
    {
      "x": -4,
      "y": 12,
      "z": 0,
      "name": "Plant_Moss_Rug_Green"
    },
    {
      "x": -4,
      "y": 6,
      "z": 1,
      "name": "Rock_Basalt"
    },
    {
      "x": -4,
      "y": 7,
      "z": 1,
      "name": "Rock_Basalt"
    },
    {
      "x": -4,
      "y": 8,
      "z": 1,
      "name": "Rock_Basalt"
    },
    {
      "x": -4,
      "y": 9,
      "z": 1,
      "name": "Rock_Basalt"
    },
    {
      "x": -4,
      "y": 6,
      "z": 2,
      "name": "Rock_Basalt"
    },
    {
      "x": -4,
      "y": 7,
      "z": 2,
      "name": "Rock_Basalt"
    },
    {
      "x": -4,
      "y": 8,
      "z": 2,
      "name": "Rock_Basalt"
    },
    {
      "x": -4,
      "y": 9,
      "z": 2,
      "name": "Rock_Basalt"
    },
    {
      "x": -4,
      "y": 7,
      "z": 3,
      "name": "Rock_Basalt"
    },
    {
      "x": -4,
      "y": 8,
      "z": 3,
      "name": "Rock_Basalt"
    },
    {
      "x": -4,
      "y": 9,
      "z": 3,
      "name": "Rock_Basalt"
    },
    {
      "x": -3,
      "y": 7,
      "z": -1,
      "name": "Rock_Basalt"
    },
    {
      "x": -3,
      "y": 8,
      "z": -1,
      "name": "Rock_Basalt"
    },
    {
      "x": -3,
      "y": 9,
      "z": -1,
      "name": "Rock_Basalt"
    },
    {
      "x": -3,
      "y": 5,
      "z": 0,
      "name": "Rock_Basalt"
    },
    {
      "x": -3,
      "y": 6,
      "z": 0,
      "name": "Rock_Basalt"
    },
    {
      "x": -3,
      "y": 7,
      "z": 0,
      "name": "Rock_Basalt"
    },
    {
      "x": -3,
      "y": 8,
      "z": 0,
      "name": "Rock_Basalt"
    },
    {
      "x": -3,
      "y": 9,
      "z": 0,
      "name": "Rock_Basalt"
    },
    {
      "x": -3,
      "y": 5,
      "z": 1,
      "name": "Rock_Basalt"
    },
    {
      "x": -3,
      "y": 6,
      "z": 1,
      "name": "Rock_Basalt"
    },
    {
      "x": -3,
      "y": 7,
      "z": 1,
      "name": "Rock_Basalt"
    },
    {
      "x": -3,
      "y": 8,
      "z": 1,
      "name": "Rock_Basalt"
    },
    {
      "x": -3,
      "y": 9,
      "z": 1,
      "name": "Rock_Basalt"
    },
    {
      "x": -3,
      "y": 5,
      "z": 2,
      "name": "Rock_Basalt"
    },
    {
      "x": -3,
      "y": 6,
      "z": 2,
      "name": "Rock_Basalt"
    },
    {
      "x": -3,
      "y": 7,
      "z": 2,
      "name": "Rock_Basalt"
    },
    {
      "x": -3,
      "y": 8,
      "z": 2,
      "name": "Rock_Basalt"
    },
    {
      "x": -3,
      "y": 9,
      "z": 2,
      "name": "Plant_Moss_Block_Green"
    },
    {
      "x": -3,
      "y": 6,
      "z": 3,
      "name": "Rock_Basalt"
    },
    {
      "x": -3,
      "y": 7,
      "z": 3,
      "name": "Rock_Basalt"
    },
    {
      "x": -3,
      "y": 8,
      "z": 3,
      "name": "Rock_Basalt"
    },
    {
      "x": -3,
      "y": 9,
      "z": 3,
      "name": "Rock_Basalt"
    },
    {
      "x": -2,
      "y": 6,
      "z": -1,
      "name": "Rock_Basalt"
    },
    {
      "x": -2,
      "y": 7,
      "z": -1,
      "name": "Rock_Basalt"
    },
    {
      "x": -2,
      "y": 8,
      "z": -1,
      "name": "Rock_Basalt"
    },
    {
      "x": -2,
      "y": 9,
      "z": -1,
      "name": "Rock_Basalt"
    },
    {
      "x": -2,
      "y": 5,
      "z": 0,
      "name": "Rock_Basalt"
    },
    {
      "x": -2,
      "y": 6,
      "z": 0,
      "name": "Rock_Basalt"
    },
    {
      "x": -2,
      "y": 7,
      "z": 0,
      "name": "Rock_Basalt"
    },
    {
      "x": -2,
      "y": 8,
      "z": 0,
      "name": "Rock_Basalt"
    },
    {
      "x": -2,
      "y": 9,
      "z": 0,
      "name": "Plant_Moss_Block_Green"
    },
    {
      "x": -2,
      "y": 5,
      "z": 1,
      "name": "Rock_Basalt"
    },
    {
      "x": -2,
      "y": 6,
      "z": 1,
      "name": "Rock_Basalt"
    },
    {
      "x": -2,
      "y": 7,
      "z": 1,
      "name": "Rock_Basalt"
    },
    {
      "x": -2,
      "y": 8,
      "z": 1,
      "name": "Rock_Basalt"
    },
    {
      "x": -2,
      "y": 9,
      "z": 1,
      "name": "Rock_Basalt"
    },
    {
      "x": -2,
      "y": 10,
      "z": 1,
      "name": "Plant_Moss_Block_Green"
    },
    {
      "x": -2,
      "y": 5,
      "z": 2,
      "name": "Rock_Basalt"
    },
    {
      "x": -2,
      "y": 6,
      "z": 2,
      "name": "Rock_Basalt"
    },
    {
      "x": -2,
      "y": 7,
      "z": 2,
      "name": "Rock_Basalt"
    },
    {
      "x": -2,
      "y": 8,
      "z": 2,
      "name": "Rock_Basalt"
    },
    {
      "x": -2,
      "y": 9,
      "z": 2,
      "name": "Rock_Basalt"
    },
    {
      "x": -2,
      "y": 10,
      "z": 2,
      "name": "Plant_Moss_Block_Green"
    },
    {
      "x": -2,
      "y": 6,
      "z": 3,
      "name": "Rock_Basalt"
    },
    {
      "x": -2,
      "y": 7,
      "z": 3,
      "name": "Rock_Basalt"
    },
    {
      "x": -2,
      "y": 8,
      "z": 3,
      "name": "Rock_Basalt"
    },
    {
      "x": -2,
      "y": 9,
      "z": 3,
      "name": "Rock_Basalt"
    },
    {
      "x": -2,
      "y": 10,
      "z": 3,
      "name": "Rock_Basalt"
    },
    {
      "x": -2,
      "y": 7,
      "z": 4,
      "name": "Rock_Basalt"
    },
    {
      "x": -2,
      "y": 8,
      "z": 4,
      "name": "Rock_Basalt"
    },
    {
      "x": -1,
      "y": 6,
      "z": -1,
      "name": "Rock_Basalt"
    },
    {
      "x": -1,
      "y": 7,
      "z": -1,
      "name": "Rock_Basalt"
    },
    {
      "x": -1,
      "y": 8,
      "z": -1,
      "name": "Rock_Basalt"
    },
    {
      "x": -1,
      "y": 9,
      "z": -1,
      "name": "Rock_Basalt"
    },
    {
      "x": -1,
      "y": 10,
      "z": -1,
      "name": "Plant_Moss_Rug_Green"
    },
    {
      "x": -1,
      "y": 5,
      "z": 0,
      "name": "Rock_Basalt"
    },
    {
      "x": -1,
      "y": 6,
      "z": 0,
      "name": "Rock_Basalt"
    },
    {
      "x": -1,
      "y": 7,
      "z": 0,
      "name": "Rock_Basalt"
    },
    {
      "x": -1,
      "y": 8,
      "z": 0,
      "name": "Rock_Basalt"
    },
    {
      "x": -1,
      "y": 9,
      "z": 0,
      "name": "Rock_Basalt"
    },
    {
      "x": -1,
      "y": 10,
      "z": 0,
      "name": "Plant_Moss_Block_Green"
    },
    {
      "x": -1,
      "y": 11,
      "z": 0,
      "name": "Plant_Moss_Rug_Green"
    },
    {
      "x": -1,
      "y": 5,
      "z": 1,
      "name": "Rock_Basalt"
    },
    {
      "x": -1,
      "y": 6,
      "z": 1,
      "name": "Rock_Basalt"
    },
    {
      "x": -1,
      "y": 7,
      "z": 1,
      "name": "Rock_Basalt"
    },
    {
      "x": -1,
      "y": 8,
      "z": 1,
      "name": "Rock_Basalt"
    },
    {
      "x": -1,
      "y": 9,
      "z": 1,
      "name": "Rock_Basalt"
    },
    {
      "x": -1,
      "y": 10,
      "z": 1,
      "name": "Plant_Moss_Block_Green"
    },
    {
      "x": -1,
      "y": 5,
      "z": 2,
      "name": "Rock_Basalt"
    },
    {
      "x": -1,
      "y": 6,
      "z": 2,
      "name": "Rock_Basalt"
    },
    {
      "x": -1,
      "y": 7,
      "z": 2,
      "name": "Rock_Basalt"
    },
    {
      "x": -1,
      "y": 8,
      "z": 2,
      "name": "Rock_Basalt"
    },
    {
      "x": -1,
      "y": 9,
      "z": 2,
      "name": "Rock_Basalt"
    },
    {
      "x": -1,
      "y": 10,
      "z": 2,
      "name": "Plant_Moss_Block_Green"
    },
    {
      "x": -1,
      "y": 6,
      "z": 3,
      "name": "Rock_Basalt"
    },
    {
      "x": -1,
      "y": 7,
      "z": 3,
      "name": "Rock_Basalt"
    },
    {
      "x": -1,
      "y": 8,
      "z": 3,
      "name": "Rock_Basalt"
    },
    {
      "x": -1,
      "y": 9,
      "z": 3,
      "name": "Rock_Basalt"
    },
    {
      "x": -1,
      "y": 10,
      "z": 3,
      "name": "Rock_Basalt"
    },
    {
      "x": -1,
      "y": 11,
      "z": 3,
      "name": "Plant_Moss_Rug_Green"
    },
    {
      "x": -1,
      "y": 7,
      "z": 4,
      "name": "Rock_Basalt"
    },
    {
      "x": -1,
      "y": 8,
      "z": 4,
      "name": "Rock_Basalt"
    },
    {
      "x": -1,
      "y": 9,
      "z": 4,
      "name": "Rock_Basalt"
    },
    {
      "x": 0,
      "y": 6,
      "z": -1,
      "name": "Rock_Basalt"
    },
    {
      "x": 0,
      "y": 7,
      "z": -1,
      "name": "Rock_Basalt"
    },
    {
      "x": 0,
      "y": 8,
      "z": -1,
      "name": "Rock_Basalt"
    },
    {
      "x": 0,
      "y": 9,
      "z": -1,
      "name": "Rock_Basalt"
    },
    {
      "x": 0,
      "y": 5,
      "z": 0,
      "name": "Rock_Basalt"
    },
    {
      "x": 0,
      "y": 6,
      "z": 0,
      "name": "Rock_Basalt"
    },
    {
      "x": 0,
      "y": 7,
      "z": 0,
      "name": "Rock_Basalt"
    },
    {
      "x": 0,
      "y": 8,
      "z": 0,
      "name": "Rock_Basalt"
    },
    {
      "x": 0,
      "y": 9,
      "z": 0,
      "name": "Rock_Basalt"
    },
    {
      "x": 0,
      "y": 10,
      "z": 0,
      "name": "Rock_Basalt"
    },
    {
      "x": 0,
      "y": 11,
      "z": 0,
      "name": "Plant_Moss_Rug_Green"
    },
    {
      "x": 0,
      "y": 5,
      "z": 1,
      "name": "Rock_Basalt"
    },
    {
      "x": 0,
      "y": 6,
      "z": 1,
      "name": "Rock_Basalt"
    },
    {
      "x": 0,
      "y": 7,
      "z": 1,
      "name": "Rock_Basalt"
    },
    {
      "x": 0,
      "y": 8,
      "z": 1,
      "name": "Rock_Basalt"
    },
    {
      "x": 0,
      "y": 9,
      "z": 1,
      "name": "Rock_Basalt"
    },
    {
      "x": 0,
      "y": 10,
      "z": 1,
      "name": "Plant_Moss_Block_Green"
    },
    {
      "x": 0,
      "y": 11,
      "z": 1,
      "name": "Plant_Moss_Rug_Green"
    },
    {
      "x": 0,
      "y": 6,
      "z": 2,
      "name": "Rock_Basalt"
    },
    {
      "x": 0,
      "y": 7,
      "z": 2,
      "name": "Rock_Basalt"
    },
    {
      "x": 0,
      "y": 8,
      "z": 2,
      "name": "Rock_Basalt"
    },
    {
      "x": 0,
      "y": 9,
      "z": 2,
      "name": "Rock_Basalt"
    },
    {
      "x": 0,
      "y": 10,
      "z": 2,
      "name": "Plant_Moss_Block_Green"
    },
    {
      "x": 0,
      "y": 6,
      "z": 3,
      "name": "Rock_Basalt"
    },
    {
      "x": 0,
      "y": 7,
      "z": 3,
      "name": "Rock_Basalt"
    },
    {
      "x": 0,
      "y": 8,
      "z": 3,
      "name": "Rock_Basalt"
    },
    {
      "x": 0,
      "y": 9,
      "z": 3,
      "name": "Rock_Basalt"
    },
    {
      "x": 0,
      "y": 10,
      "z": 3,
      "name": "Plant_Moss_Block_Green"
    },
    {
      "x": 0,
      "y": 11,
      "z": 3,
      "name": "Plant_Moss_Rug_Green"
    },
    {
      "x": 0,
      "y": 8,
      "z": 4,
      "name": "Rock_Basalt"
    },
    {
      "x": 0,
      "y": 9,
      "z": 4,
      "name": "Rock_Basalt"
    },
    {
      "x": 0,
      "y": 10,
      "z": 4,
      "name": "Plant_Moss_Rug_Green"
    },
    {
      "x": 1,
      "y": 7,
      "z": -1,
      "name": "Rock_Basalt"
    },
    {
      "x": 1,
      "y": 8,
      "z": -1,
      "name": "Rock_Basalt"
    },
    {
      "x": 1,
      "y": 5,
      "z": 0,
      "name": "Rock_Basalt"
    },
    {
      "x": 1,
      "y": 6,
      "z": 0,
      "name": "Rock_Basalt"
    },
    {
      "x": 1,
      "y": 7,
      "z": 0,
      "name": "Rock_Basalt"
    },
    {
      "x": 1,
      "y": 8,
      "z": 0,
      "name": "Rock_Basalt"
    },
    {
      "x": 1,
      "y": 9,
      "z": 0,
      "name": "Rock_Basalt"
    },
    {
      "x": 1,
      "y": 10,
      "z": 0,
      "name": "Rock_Basalt"
    },
    {
      "x": 1,
      "y": 11,
      "z": 0,
      "name": "Plant_Moss_Rug_Green"
    },
    {
      "x": 1,
      "y": 5,
      "z": 1,
      "name": "Rock_Basalt"
    },
    {
      "x": 1,
      "y": 6,
      "z": 1,
      "name": "Rock_Basalt"
    },
    {
      "x": 1,
      "y": 7,
      "z": 1,
      "name": "Rock_Basalt"
    },
    {
      "x": 1,
      "y": 8,
      "z": 1,
      "name": "Rock_Basalt"
    },
    {
      "x": 1,
      "y": 9,
      "z": 1,
      "name": "Rock_Basalt"
    },
    {
      "x": 1,
      "y": 10,
      "z": 1,
      "name": "Plant_Moss_Block_Green"
    },
    {
      "x": 1,
      "y": 11,
      "z": 1,
      "name": "Plant_Moss_Rug_Green"
    },
    {
      "x": 1,
      "y": 6,
      "z": 2,
      "name": "Rock_Basalt"
    },
    {
      "x": 1,
      "y": 7,
      "z": 2,
      "name": "Rock_Basalt"
    },
    {
      "x": 1,
      "y": 8,
      "z": 2,
      "name": "Rock_Basalt"
    },
    {
      "x": 1,
      "y": 9,
      "z": 2,
      "name": "Rock_Basalt"
    },
    {
      "x": 1,
      "y": 10,
      "z": 2,
      "name": "Plant_Moss_Block_Green"
    },
    {
      "x": 1,
      "y": 7,
      "z": 3,
      "name": "Rock_Basalt"
    },
    {
      "x": 1,
      "y": 8,
      "z": 3,
      "name": "Rock_Basalt"
    },
    {
      "x": 1,
      "y": 9,
      "z": 3,
      "name": "Rock_Basalt"
    },
    {
      "x": 1,
      "y": 10,
      "z": 3,
      "name": "Rock_Basalt"
    },
    {
      "x": 1,
      "y": 8,
      "z": 4,
      "name": "Rock_Basalt"
    },
    {
      "x": 1,
      "y": 9,
      "z": 4,
      "name": "Rock_Basalt"
    },
    {
      "x": 1,
      "y": 10,
      "z": 4,
      "name": "Plant_Moss_Rug_Green"
    },
    {
      "x": 2,
      "y": 6,
      "z": 0,
      "name": "Rock_Basalt"
    },
    {
      "x": 2,
      "y": 7,
      "z": 0,
      "name": "Rock_Basalt"
    },
    {
      "x": 2,
      "y": 8,
      "z": 0,
      "name": "Rock_Basalt"
    },
    {
      "x": 2,
      "y": 9,
      "z": 0,
      "name": "Rock_Basalt"
    },
    {
      "x": 2,
      "y": 5,
      "z": 1,
      "name": "Rock_Basalt"
    },
    {
      "x": 2,
      "y": 6,
      "z": 1,
      "name": "Rock_Basalt"
    },
    {
      "x": 2,
      "y": 7,
      "z": 1,
      "name": "Rock_Basalt"
    },
    {
      "x": 2,
      "y": 8,
      "z": 1,
      "name": "Rock_Basalt"
    },
    {
      "x": 2,
      "y": 9,
      "z": 1,
      "name": "Rock_Basalt"
    },
    {
      "x": 2,
      "y": 10,
      "z": 1,
      "name": "Rock_Basalt"
    },
    {
      "x": 2,
      "y": 6,
      "z": 2,
      "name": "Rock_Basalt"
    },
    {
      "x": 2,
      "y": 7,
      "z": 2,
      "name": "Rock_Basalt"
    },
    {
      "x": 2,
      "y": 8,
      "z": 2,
      "name": "Rock_Basalt"
    },
    {
      "x": 2,
      "y": 9,
      "z": 2,
      "name": "Rock_Basalt"
    },
    {
      "x": 2,
      "y": 10,
      "z": 2,
      "name": "Rock_Basalt"
    },
    {
      "x": 2,
      "y": 7,
      "z": 3,
      "name": "Rock_Basalt"
    },
    {
      "x": 2,
      "y": 8,
      "z": 3,
      "name": "Rock_Basalt"
    },
    {
      "x": 2,
      "y": 9,
      "z": 3,
      "name": "Rock_Basalt"
    },
    {
      "x": 3,
      "y": 6,
      "z": 1,
      "name": "Rock_Basalt"
    },
    {
      "x": 3,
      "y": 7,
      "z": 1,
      "name": "Rock_Basalt"
    },
    {
      "x": 3,
      "y": 8,
      "z": 1,
      "name": "Rock_Basalt"
    },
    {
      "x": 3,
      "y": 9,
      "z": 1,
      "name": "Rock_Basalt"
    },
    {
      "x": 3,
      "y": 7,
      "z": 2,
      "name": "Rock_Basalt"
    },
    {
      "x": 3,
      "y": 8,
      "z": 2,
      "name": "Rock_Basalt"
    },
    {
      "x": 3,
      "y": 9,
      "z": 2,
      "name": "Rock_Basalt"
    }
  ]
}