{
  "version": 8,
  "blockIdVersion": 8,
  "anchorX": 0,
  "anchorY": 0,
  "anchorZ": 0,
  "blocks": [
    {
      "x": -8,
      "y": 0,
      "z": -16,
      "name": "Rock_Basalt"
    },
    {
      "x": -8,
      "y": 1,
      "z": -16,
      "name": "Rock_Basalt"
    },
    {
      "x": -8,
      "y": 2,
      "z": -16,
      "name": "Rock_Basalt"
    },
    {
      "x": -8,
      "y": 3,
      "z": -16,
      "name": "Rock_Basalt"
    },
    {
      "x": -8,
      "y": 4,
      "z": -16,
      "name": "Rock_Basalt"
    },
    {
      "x": -8,
      "y": 5,
      "z": -16,
      "name": "Rock_Basalt"
    },
    {
      "x": -8,
      "y": 6,
      "z": -16,
      "name": "Rock_Basalt"
    },
    {
      "x": -8,
      "y": 7,
      "z": -16,
      "name": "Rock_Basalt"
    },
    {
      "x": -8,
      "y": 8,
      "z": -16,
      "name": "Rock_Basalt"
    },
    {
      "x": -8,
      "y": 9,
      "z": -16,
      "name": "Rock_Basalt"
    },
    {
      "x": -8,
      "y": 10,
      "z": -16,
      "name": "Rock_Basalt"
    },
    {
      "x": -8,
      "y": 0,
      "z": -15,
      "name": "Rock_Basalt"
    },
    {
      "x": -8,
      "y": 1,
      "z": -15,
      "name": "Rock_Basalt"
    },
    {
      "x": -8,
      "y": 2,
      "z": -15,
      "name": "Rock_Basalt"
    },
    {
      "x": -8,
      "y": 3,
      "z": -15,
      "name": "Rock_Basalt"
    },
    {
      "x": -8,
      "y": 4,
      "z": -15,
      "name": "Rock_Basalt"
    },
    {
      "x": -8,
      "y": 5,
      "z": -15,
      "name": "Rock_Basalt"
    },
    {
      "x": -8,
      "y": 6,
      "z": -15,
      "name": "Rock_Basalt"
    },
    {
      "x": -8,
      "y": 7,
      "z": -15,
      "name": "Rock_Basalt"
    },
    {
      "x": -8,
      "y": 8,
      "z": -15,
      "name": "Rock_Basalt"
    },
    {
      "x": -8,
      "y": 9,
      "z": -15,
      "name": "Rock_Basalt"
    },
    {
      "x": -8,
      "y": 10,
      "z": -15,
      "name": "Rock_Basalt"
    },
    {
      "x": -8,
      "y": 0,
      "z": -14,
      "name": "Rock_Basalt"
    },
    {
      "x": -8,
      "y": 1,
      "z": -14,
      "name": "Rock_Basalt"
    },
    {
      "x": -8,
      "y": 2,
      "z": -14,
      "name": "Rock_Basalt"
    },
    {
      "x": -8,
      "y": 3,
      "z": -14,
      "name": "Rock_Basalt"
    },
    {
      "x": -8,
      "y": 4,
      "z": -14,
      "name": "Rock_Basalt"
    },
    {
      "x": -8,
      "y": 5,
      "z": -14,
      "name": "Rock_Basalt"
    },
    {
      "x": -8,
      "y": 6,
      "z": -14,
      "name": "Rock_Basalt"
    },
    {
      "x": -8,
      "y": 7,
      "z": -14,
      "name": "Rock_Basalt"
    },
    {
      "x": -8,
      "y": 8,
      "z": -14,
      "name": "Rock_Basalt"
    },
    {
      "x": -8,
      "y": 9,
      "z": -14,
      "name": "Rock_Basalt"
    },
    {
      "x": -8,
      "y": 10,
      "z": -14,
      "name": "Rock_Basalt"
    },
    {
      "x": -8,
      "y": 0,
      "z": -13,
      "name": "Rock_Basalt"
    },
    {
      "x": -8,
      "y": 1,
      "z": -13,
      "name": "Rock_Basalt"
    },
    {
      "x": -8,
      "y": 2,
      "z": -13,
      "name": "Rock_Basalt"
    },
    {
      "x": -8,
      "y": 3,
      "z": -13,
      "name": "Rock_Basalt"
    },
    {
      "x": -8,
      "y": 4,
      "z": -13,
      "name": "Rock_Basalt"
    },
    {
      "x": -8,
      "y": 5,
      "z": -13,
      "name": "Rock_Basalt"
    },
    {
      "x": -8,
      "y": 6,
      "z": -13,
      "name": "Rock_Basalt"
    },
    {
      "x": -8,
      "y": 7,
      "z": -13,
      "name": "Rock_Basalt"
    },
    {
      "x": -8,
      "y": 8,
      "z": -13,
      "name": "Rock_Basalt"
    },
    {
      "x": -8,
      "y": 9,
      "z": -13,
      "name": "Rock_Basalt"
    },
    {
      "x": -8,
      "y": 10,
      "z": -13,
      "name": "Rock_Basalt"
    },
    {
      "x": -8,
      "y": 0,
      "z": -12,
      "name": "Rock_Basalt"
    },
    {
      "x": -8,
      "y": 1,
      "z": -12,
      "name": "Rock_Basalt"
    },
    {
      "x": -8,
      "y": 2,
      "z": -12,
      "name": "Rock_Basalt"
    },
    {
      "x": -8,
      "y": 3,
      "z": -12,
      "name": "Rock_Basalt"
    },
    {
      "x": -8,
      "y": 4,
      "z": -12,
      "name": "Rock_Basalt"
    },
    {
      "x": -8,
      "y": 5,
      "z": -12,
      "name": "Rock_Basalt"
    },
    {
      "x": -8,
      "y": 6,
      "z": -12,
      "name": "Rock_Basalt"
    },
    {
      "x": -8,
      "y": 7,
      "z": -12,
      "name": "Rock_Basalt"
    },
    {
      "x": -8,
      "y": 8,
      "z": -12,
      "name": "Rock_Basalt"
    },
    {
      "x": -8,
      "y": 9,
      "z": -12,
      "name": "Rock_Basalt"
    },
    {
      "x": -8,
      "y": 10,
      "z": -12,
      "name": "Rock_Basalt"
    },
    {
      "x": -8,
      "y": 0,
      "z": -11,
      "name": "Rock_Basalt"
    },
    {
      "x": -8,
      "y": 1,
      "z": -11,
      "name": "Rock_Basalt"
    },
    {
      "x": -8,
      "y": 2,
      "z": -11,
      "name": "Rock_Basalt"
    },
    {
      "x": -8,
      "y": 3,
      "z": -11,
      "name": "Rock_Basalt"
    },
    {
      "x": -8,
      "y": 4,
      "z": -11,
      "name": "Rock_Basalt"
    },
    {
      "x": -8,
      "y": 5,
      "z": -11,
      "name": "Rock_Basalt"
    },
    {
      "x": -8,
      "y": 6,
      "z": -11,
      "name": "Rock_Basalt"
    },
    {
      "x": -8,
      "y": 7,
      "z": -11,
      "name": "Rock_Basalt"
    },
    {
      "x": -8,
      "y": 8,
      "z": -11,
      "name": "Rock_Basalt"
    },
    {
      "x": -8,
      "y": 9,
      "z": -11,
      "name": "Rock_Basalt"
    },
    {
      "x": -8,
      "y": 10,
      "z": -11,
      "name": "Rock_Basalt"
    },
    {
      "x": -8,
      "y": 0,
      "z": -10,
      "name": "Rock_Basalt"
    },
    {
      "x": -8,
      "y": 1,
      "z": -10,
      "name": "Rock_Basalt"
    },
    {
      "x": -8,
      "y": 2,
      "z": -10,
      "name": "Rock_Basalt"
    },
    {
      "x": -8,
      "y": 3,
      "z": -10,
      "name": "Rock_Basalt"
    },
    {
      "x": -8,
      "y": 4,
      "z": -10,
      "name": "Rock_Basalt"
    },
    {
      "x": -8,
      "y": 5,
      "z": -10,
      "name": "Rock_Basalt"
    },
    {
      "x": -8,
      "y": 6,
      "z": -10,
      "name": "Rock_Basalt"
    },
    {
      "x": -8,
      "y": 7,
      "z": -10,
      "name": "Rock_Basalt"
    },
    {
      "x": -8,
      "y": 8,
      "z": -10,
      "name": "Rock_Basalt"
    },
    {
      "x": -8,
      "y": 9,
      "z": -10,
      "name": "Rock_Basalt"
    },
    {
      "x": -8,
      "y": 10,
      "z": -10,
      "name": "Rock_Basalt"
    },
    {
      "x": -8,
      "y": 0,
      "z": -9,
      "name": "Rock_Basalt"
    },
    {
      "x": -8,
      "y": 1,
      "z": -9,
      "name": "Rock_Basalt"
    },
    {
      "x": -8,
      "y": 2,
      "z": -9,
      "name": "Rock_Basalt"
    },
    {
      "x": -8,
      "y": 3,
      "z": -9,
      "name": "Rock_Basalt"
    },
    {
      "x": -8,
      "y": 4,
      "z": -9,
      "name": "Rock_Basalt"
    },
    {
      "x": -8,
      "y": 5,
      "z": -9,
      "name": "Rock_Basalt"
    },
    {
      "x": -8,
      "y": 6,
      "z": -9,
      "name": "Rock_Basalt"
    },
    {
      "x": -8,
      "y": 7,
      "z": -9,
      "name": "Rock_Basalt"
    },
    {
      "x": -8,
      "y": 8,
      "z": -9,
      "name": "Rock_Basalt"
    },
    {
      "x": -8,
      "y": 9,
      "z": -9,
      "name": "Rock_Basalt"
    },
    {
      "x": -8,
      "y": 10,
      "z": -9,
      "name": "Rock_Basalt"
    },
    {
      "x": -8,
      "y": 0,
      "z": -8,
      "name": "Rock_Basalt"
    },
    {
      "x": -8,
      "y": 1,
      "z": -8,
      "name": "Rock_Basalt"
    },
    {
      "x": -8,
      "y": 2,
      "z": -8,
      "name": "Rock_Basalt"
    },
    {
      "x": -8,
      "y": 3,
      "z": -8,
      "name": "Rock_Basalt"
    },
    {
      "x": -8,
      "y": 4,
      "z": -8,
      "name": "Rock_Basalt"
    },
    {
      "x": -8,
      "y": 5,
      "z": -8,
      "name": "Rock_Basalt"
    },
    {
      "x": -8,
      "y": 6,
      "z": -8,
      "name": "Rock_Basalt"
    },
    {
      "x": -8,
      "y": 7,
      "z": -8,
      "name": "Rock_Basalt"
    },
    {
      "x": -8,
      "y": 8,
      "z": -8,
      "name": "Rock_Basalt"
    },
    {
      "x": -8,
      "y": 9,
      "z": -8,
      "name": "Rock_Basalt"
    },
    {
      "x": -8,
      "y": 10,
      "z": -8,
      "name": "Rock_Basalt"
    },
    {
      "x": -8,
      "y": 0,
      "z": -7,
      "name": "Rock_Basalt"
    },
    {
      "x": -8,
      "y": 1,
      "z": -7,
      "name": "Rock_Basalt"
    },
    {
      "x": -8,
      "y": 2,
      "z": -7,
      "name": "Rock_Basalt"
    },
    {
      "x": -8,
      "y": 3,
      "z": -7,
      "name": "Rock_Basalt"
    },
    {
      "x": -8,
      "y": 4,
      "z": -7,
      "name": "Rock_Basalt"
    },
    {
      "x": -8,
      "y": 5,
      "z": -7,
      "name": "Rock_Basalt"
    },
    {
      "x": -8,
      "y": 6,
      "z": -7,
      "name": "Rock_Basalt"
    },
    {
      "x": -8,
      "y": 7,
      "z": -7,
      "name": "Rock_Basalt"
    },
    {
      "x": -8,
      "y": 8,
      "z": -7,
      "name": "Rock_Basalt"
    },
    {
      "x": -8,
      "y": 9,
      "z": -7,
      "name": "Rock_Basalt"
    },
    {
      "x": -8,
      "y": 10,
      "z": -7,
      "name": "Rock_Basalt"
    },
    {
      "x": -8,
      "y": 0,
      "z": -6,
      "name": "Rock_Basalt"
    },
    {
      "x": -8,
      "y": 1,
      "z": -6,
      "name": "Rock_Basalt"
    },
    {
      "x": -8,
      "y": 2,
      "z": -6,
      "name": "Rock_Basalt"
    },
    {
      "x": -8,
      "y": 3,
      "z": -6,
      "name": "Rock_Basalt"
    },
    {
      "x": -8,
      "y": 4,
      "z": -6,
      "name": "Rock_Basalt"
    },
    {
      "x": -8,
      "y": 5,
      "z": -6,
      "name": "Rock_Basalt"
    },
    {
      "x": -8,
      "y": 6,
      "z": -6,
      "name": "Rock_Basalt"
    },
    {
      "x": -8,
      "y": 0,
      "z": -5,
      "name": "Rock_Basalt"
    },
    {
      "x": -8,
      "y": 1,
      "z": -5,
      "name": "Rock_Basalt"
    },
    {
      "x": -8,
      "y": 2,
      "z": -5,
      "name": "Rock_Basalt"
    },
    {
      "x": -8,
      "y": 3,
      "z": -5,
      "name": "Rock_Basalt"
    },
    {
      "x": -8,
      "y": 4,
      "z": -5,
      "name": "Rock_Basalt"
    },
    {
      "x": -8,
      "y": 5,
      "z": -5,
      "name": "Rock_Basalt"
    },
    {
      "x": -8,
      "y": 6,
      "z": -5,
      "name": "Rock_Basalt"
    },
    {
      "x": -8,
      "y": 0,
      "z": -4,
      "name": "Rock_Basalt"
    },
    {
      "x": -8,
      "y": 1,
      "z": -4,
      "name": "Rock_Basalt"
    },
    {
      "x": -8,
      "y": 2,
      "z": -4,
      "name": "Rock_Basalt"
    },
    {
      "x": -8,
      "y": 3,
      "z": -4,
      "name": "Rock_Basalt"
    },
    {
      "x": -8,
      "y": 4,
      "z": -4,
      "name": "Rock_Basalt"
    },
    {
      "x": -8,
      "y": 5,
      "z": -4,
      "name": "Rock_Basalt"
    },
    {
      "x": -8,
      "y": 6,
      "z": -4,
      "name": "Rock_Basalt"
    },
    {
      "x": -8,
      "y": 0,
      "z": -3,
      "name": "Rock_Basalt"
    },
    {
      "x": -8,
      "y": 1,
      "z": -3,
      "name": "Rock_Basalt"
    },
    {
      "x": -8,
      "y": 2,
      "z": -3,
      "name": "Rock_Basalt"
    },
    {
      "x": -8,
      "y": 3,
      "z": -3,
      "name": "Rock_Basalt"
    },
    {
      "x": -8,
      "y": 4,
      "z": -3,
      "name": "Rock_Basalt"
    },
    {
      "x": -8,
      "y": 5,
      "z": -3,
      "name": "Rock_Basalt"
    },
    {
      "x": -8,
      "y": 6,
      "z": -3,
      "name": "Rock_Basalt"
    },
    {
      "x": -8,
      "y": 0,
      "z": -2,
      "name": "Rock_Basalt"
    },
    {
      "x": -8,
      "y": 1,
      "z": -2,
      "name": "Rock_Basalt"
    },
    {
      "x": -8,
      "y": 2,
      "z": -2,
      "name": "Rock_Basalt"
    },
    {
      "x": -8,
      "y": 3,
      "z": -2,
      "name": "Rock_Basalt"
    },
    {
      "x": -8,
      "y": 4,
      "z": -2,
      "name": "Rock_Basalt"
    },
    {
      "x": -8,
      "y": 5,
      "z": -2,
      "name": "Rock_Basalt"
    },
    {
      "x": -8,
      "y": 6,
      "z": -2,
      "name": "Rock_Basalt"
    },
    {
      "x": -8,
      "y": 0,
      "z": -1,
      "name": "Rock_Basalt"
    },
    {
      "x": -8,
      "y": 1,
      "z": -1,
      "name": "Rock_Basalt"
    },
    {
      "x": -8,
      "y": 2,
      "z": -1,
      "name": "Rock_Basalt"
    },
    {
      "x": -8,
      "y": 3,
      "z": -1,
      "name": "Rock_Basalt"
    },
    {
      "x": -8,
      "y": 4,
      "z": -1,
      "name": "Rock_Basalt"
    },
    {
      "x": -8,
      "y": 5,
      "z": -1,
      "name": "Rock_Basalt"
    },
    {
      "x": -8,
      "y": 6,
      "z": -1,
      "name": "Rock_Basalt"
    },
    {
      "x": -8,
      "y": 0,
      "z": 0,
      "name": "Rock_Basalt"
    },
    {
      "x": -8,
      "y": 1,
      "z": 0,
      "name": "Rock_Basalt"
    },
    {
      "x": -8,
      "y": 2,
      "z": 0,
      "name": "Rock_Basalt"
    },
    {
      "x": -8,
      "y": 3,
      "z": 0,
      "name": "Rock_Basalt"
    },
    {
      "x": -8,
      "y": 4,
      "z": 0,
      "name": "Rock_Basalt"
    },
    {
      "x": -8,
      "y": 5,
      "z": 0,
      "name": "Rock_Basalt"
    },
    {
      "x": -8,
      "y": 6,
      "z": 0,
      "name": "Rock_Basalt"
    },
    {
      "x": -7,
      "y": 0,
      "z": -16,
      "name": "Rock_Basalt"
    },
    {
      "x": -7,
      "y": 1,
      "z": -16,
      "name": "Rock_Basalt"
    },
    {
      "x": -7,
      "y": 2,
      "z": -16,
      "name": "Rock_Basalt"
    },
    {
      "x": -7,
      "y": 3,
      "z": -16,
      "name": "Rock_Basalt"
    },
    {
      "x": -7,
      "y": 4,
      "z": -16,
      "name": "Rock_Basalt"
    },
    {
      "x": -7,
      "y": 5,
      "z": -16,
      "name": "Rock_Basalt"
    },
    {
      "x": -7,
      "y": 6,
      "z": -16,
      "name": "Rock_Basalt"
    },
    {
      "x": -7,
      "y": 7,
      "z": -16,
      "name": "Rock_Basalt"
    },
    {
      "x": -7,
      "y": 8,
      "z": -16,
      "name": "Rock_Basalt"
    },
    {
      "x": -7,
      "y": 9,
      "z": -16,
      "name": "Rock_Basalt"
    },
    {
      "x": -7,
      "y": 10,
      "z": -16,
      "name": "Rock_Basalt"
    },
    {
      "x": -7,
      "y": 0,
      "z": -15,
      "name": "Rock_Basalt_Cobble"
    },
    {
      "x": -7,
      "y": 1,
      "z": -15,
      "name": "Empty"
    },
    {
      "x": -7,
      "y": 2,
      "z": -15,
      "name": "Empty"
    },
    {
      "x": -7,
      "y": 3,
      "z": -15,
      "name": "Empty"
    },
    {
      "x": -7,
      "y": 4,
      "z": -15,
      "name": "Empty"
    },
    {
      "x": -7,
      "y": 5,
      "z": -15,
      "name": "Rock_Basalt"
    },
    {
      "x": -7,
      "y": 6,
      "z": -15,
      "name": "Empty"
    },
    {
      "x": -7,
      "y": 10,
      "z": -15,
      "name": "Rock_Basalt"
    },
    {
      "x": -7,
      "y": 0,
      "z": -14,
      "name": "Rock_Basalt_Cobble"
    },
    {
      "x": -7,
      "y": 1,
      "z": -14,
      "name": "Empty"
    },
    {
      "x": -7,
      "y": 2,
      "z": -14,
      "name": "Empty"
    },
    {
      "x": -7,
      "y": 3,
      "z": -14,
      "name": "Empty"
    },
    {
      "x": -7,
      "y": 4,
      "z": -14,
      "name": "Empty"
    },
    {
      "x": -7,
      "y": 5,
      "z": -14,
      "name": "Rock_Basalt"
    },
    {
      "x": -7,
      "y": 6,
      "z": -14,
      "name": "Empty"
    },
    {
      "x": -7,
      "y": 10,
      "z": -14,
      "name": "Rock_Basalt"
    },
    {
      "x": -7,
      "y": 0,
      "z": -13,
      "name": "Rock_Basalt_Cobble"
    },
    {
      "x": -7,
      "y": 1,
      "z": -13,
      "name": "Empty"
    },
    {
      "x": -7,
      "y": 2,
      "z": -13,
      "name": "Empty"
    },
    {
      "x": -7,
      "y": 3,
      "z": -13,
      "name": "Empty"
    },
    {
      "x": -7,
      "y": 4,
      "z": -13,
      "name": "Empty"
    },
    {
      "x": -7,
      "y": 5,
      "z": -13,
      "name": "Rock_Basalt"
    },
    {
      "x": -7,
      "y": 6,
      "z": -13,
      "name": "Empty"
    },
    {
      "x": -7,
      "y": 10,
      "z": -13,
      "name": "Rock_Basalt"
    },
    {
      "x": -7,
      "y": 0,
      "z": -12,
      "name": "Rock_Basalt_Cobble"
    },
    {
      "x": -7,
      "y": 1,
      "z": -12,
      "name": "Empty"
    },
    {
      "x": -7,
      "y": 2,
      "z": -12,
      "name": "Empty"
    },
    {
      "x": -7,
      "y": 3,
      "z": -12,
      "name": "Empty"
    },
    {
      "x": -7,
      "y": 4,
      "z": -12,
      "name": "Empty"
    },
    {
      "x": -7,
      "y": 5,
      "z": -12,
      "name": "Rock_Basalt"
    },
    {
      "x": -7,
      "y": 6,
      "z": -12,
      "name": "Empty"
    },
    {
      "x": -7,
      "y": 10,
      "z": -12,
      "name": "Rock_Basalt"
    },
    {
      "x": -7,
      "y": 0,
      "z": -11,
      "name": "Rock_Basalt"
    },
    {
      "x": -7,
      "y": 1,
      "z": -11,
      "name": "Rock_Basalt"
    },
    {
      "x": -7,
      "y": 2,
      "z": -11,
      "name": "Rock_Basalt"
    },
    {
      "x": -7,
      "y": 3,
      "z": -11,
      "name": "Rock_Basalt"
    },
    {
      "x": -7,
      "y": 4,
      "z": -11,
      "name": "Rock_Basalt"
    },
    {
      "x": -7,
      "y": 5,
      "z": -11,
      "name": "Rock_Basalt"
    },
    {
      "x": -7,
      "y": 6,
      "z": -11,
      "name": "Empty"
    },
    {
      "x": -7,
      "y": 10,
      "z": -11,
      "name": "Rock_Basalt"
    },
    {
      "x": -7,
      "y": 0,
      "z": -10,
      "name": "Rock_Basalt"
    },
    {
      "x": -7,
      "y": 1,
      "z": -10,
      "name": "Rock_Basalt"
    },
    {
      "x": -7,
      "y": 2,
      "z": -10,
      "name": "Rock_Basalt"
    },
    {
      "x": -7,
      "y": 3,
      "z": -10,
      "name": "Rock_Basalt"
    },
    {
      "x": -7,
      "y": 4,
      "z": -10,
      "name": "Rock_Basalt"
    },
    {
      "x": -7,
      "y": 5,
      "z": -10,
      "name": "Rock_Basalt_Cobble_Stairs"
    },
    {
      "x": -7,
      "y": 6,
      "z": -10,
      "name": "Empty"
    },
    {
      "x": -7,
      "y": 10,
      "z": -10,
      "name": "Rock_Basalt"
    },
    {
      "x": -7,
      "y": 0,
      "z": -9,
      "name": "Rock_Basalt"
    },
    {
      "x": -7,
      "y": 1,
      "z": -9,
      "name": "Rock_Basalt"
    },
    {
      "x": -7,
      "y": 2,
      "z": -9,
      "name": "Rock_Basalt"
    },
    {
      "x": -7,
      "y": 3,
      "z": -9,
      "name": "Rock_Basalt"
    },
    {
      "x": -7,
      "y": 4,
      "z": -9,
      "name": "Rock_Basalt_Cobble_Stairs"
    },
    {
      "x": -7,
      "y": 5,
      "z": -9,
      "name": "Empty"
    },
    {
      "x": -7,
      "y": 6,
      "z": -9,
      "name": "Empty"
    },
    {
      "x": -7,
      "y": 10,
      "z": -9,
      "name": "Rock_Basalt"
    },
    {
      "x": -7,
      "y": 0,
      "z": -8,
      "name": "Rock_Basalt"
    },
    {
      "x": -7,
      "y": 1,
      "z": -8,
      "name": "Rock_Basalt"
    },
    {
      "x": -7,
      "y": 2,
      "z": -8,
      "name": "Rock_Basalt"
    },
    {
      "x": -7,
      "y": 3,
      "z": -8,
      "name": "Rock_Basalt_Cobble_Stairs"
    },
    {
      "x": -7,
      "y": 4,
      "z": -8,
      "name": "Empty"
    },
    {
      "x": -7,
      "y": 5,
      "z": -8,
      "name": "Empty"
    },
    {
      "x": -7,
      "y": 6,
      "z": -8,
      "name": "Empty"
    },
    {
      "x": -7,
      "y": 10,
      "z": -8,
      "name": "Rock_Basalt"
    },
    {
      "x": -7,
      "y": 0,
      "z": -7,
      "name": "Rock_Basalt"
    },
    {
      "x": -7,
      "y": 1,
      "z": -7,
      "name": "Rock_Basalt"
    },
    {
      "x": -7,
      "y": 2,
      "z": -7,
      "name": "Rock_Basalt_Cobble_Stairs"
    },
    {
      "x": -7,
      "y": 3,
      "z": -7,
      "name": "Empty"
    },
    {
      "x": -7,
      "y": 4,
      "z": -7,
      "name": "Empty"
    },
    {
      "x": -7,
      "y": 5,
      "z": -7,
      "name": "Empty"
    },
    {
      "x": -7,
      "y": 6,
      "z": -7,
      "name": "Empty"
    },
    {
      "x": -7,
      "y": 7,
      "z": -7,
      "name": "Rock_Basalt"
    },
    {
      "x": -7,
      "y": 8,
      "z": -7,
      "name": "Rock_Basalt"
    },
    {
      "x": -7,
      "y": 9,
      "z": -7,
      "name": "Rock_Basalt"
    },
    {
      "x": -7,
      "y": 10,
      "z": -7,
      "name": "Rock_Basalt"
    },
    {
      "x": -7,
      "y": 0,
      "z": -6,
      "name": "Rock_Basalt"
    },
    {
      "x": -7,
      "y": 1,
      "z": -6,
      "name": "Rock_Basalt"
    },
    {
      "x": -7,
      "y": 2,
      "z": -6,
      "name": "Empty"
    },
    {
      "x": -7,
      "y": 3,
      "z": -6,
      "name": "Empty"
    },
    {
      "x": -7,
      "y": 4,
      "z": -6,
      "name": "Empty"
    },
    {
      "x": -7,
      "y": 5,
      "z": -6,
      "name": "Empty"
    },
    {
      "x": -7,
      "y": 6,
      "z": -6,
      "name": "Rock_Basalt"
    },
    {
      "x": -7,
      "y": 0,
      "z": -5,
      "name": "Rock_Basalt"
    },
    {
      "x": -7,
      "y": 1,
      "z": -5,
      "name": "Rock_Basalt"
    },
    {
      "x": -7,
      "y": 2,
      "z": -5,
      "name": "Empty"
    },
    {
      "x": -7,
      "y": 3,
      "z": -5,
      "name": "Empty"
    },
    {
      "x": -7,
      "y": 4,
      "z": -5,
      "name": "Empty"
    },
    {
      "x": -7,
      "y": 5,
      "z": -5,
      "name": "Empty"
    },
    {
      "x": -7,
      "y": 6,
      "z": -5,
      "name": "Rock_Basalt"
    },
    {
      "x": -7,
      "y": 0,
      "z": -4,
      "name": "Rock_Basalt"
    },
    {
      "x": -7,
      "y": 1,
      "z": -4,
      "name": "Rock_Basalt"
    },
    {
      "x": -7,
      "y": 2,
      "z": -4,
      "name": "Wood_Deadwood_Fence"
    },
    {
      "x": -7,
      "y": 3,
      "z": -4,
      "name": "Empty"
    },
    {
      "x": -7,
      "y": 4,
      "z": -4,
      "name": "Empty"
    },
    {
      "x": -7,
      "y": 5,
      "z": -4,
      "name": "Wood_Fir_Trunk",
      "rotation": 5
    },
    {
      "x": -7,
      "y": 6,
      "z": -4,
      "name": "Rock_Basalt"
    },
    {
      "x": -7,
      "y": 0,
      "z": -3,
      "name": "Rock_Basalt_Cobble"
    },
    {
      "x": -7,
      "y": 1,
      "z": -3,
      "name": "Empty"
    },
    {
      "x": -7,
      "y": 2,
      "z": -3,
      "name": "Empty"
    },
    {
      "x": -7,
      "y": 3,
      "z": -3,
      "name": "Empty"
    },
    {
      "x": -7,
      "y": 4,
      "z": -3,
      "name": "Empty"
    },
    {
      "x": -7,
      "y": 5,
      "z": -3,
      "name": "Empty"
    },
    {
      "x": -7,
      "y": 6,
      "z": -3,
      "name": "Rock_Basalt"
    },
    {
      "x": -7,
      "y": 0,
      "z": -2,
      "name": "Rock_Basalt_Cobble"
    },
    {
      "x": -7,
      "y": 1,
      "z": -2,
      "name": "Empty"
    },
    {
      "x": -7,
      "y": 2,
      "z": -2,
      "name": "Empty"
    },
    {
      "x": -7,
      "y": 3,
      "z": -2,
      "name": "Empty"
    },
    {
      "x": -7,
      "y": 4,
      "z": -2,
      "name": "Empty"
    },
    {
      "x": -7,
      "y": 5,
      "z": -2,
      "name": "Rock_Basalt"
    },
    {
      "x": -7,
      "y": 6,
      "z": -2,
      "name": "Rock_Basalt"
    },
    {
      "x": -7,
      "y": 0,
      "z": -1,
      "name": "Rock_Basalt_Cobble"
    },
    {
      "x": -7,
      "y": 1,
      "z": -1,
      "name": "Empty"
    },
    {
      "x": -7,
      "y": 2,
      "z": -1,
      "name": "Empty"
    },
    {
      "x": -7,
      "y": 3,
      "z": -1,
      "name": "Empty"
    },
    {
      "x": -7,
      "y": 4,
      "z": -1,
      "name": "Rock_Basalt"
    },
    {
      "x": -7,
      "y": 5,
      "z": -1,
      "name": "Rock_Basalt"
    },
    {
      "x": -7,
      "y": 6,
      "z": -1,
      "name": "Rock_Basalt"
    },
    {
      "x": -7,
      "y": 0,
      "z": 0,
      "name": "Rock_Basalt"
    },
    {
      "x": -7,
      "y": 1,
      "z": 0,
      "name": "Rock_Basalt"
    },
    {
      "x": -7,
      "y": 2,
      "z": 0,
      "name": "Rock_Basalt"
    },
    {
      "x": -7,
      "y": 3,
      "z": 0,
      "name": "Rock_Basalt"
    },
    {
      "x": -7,
      "y": 4,
      "z": 0,
      "name": "Rock_Basalt"
    },
    {
      "x": -7,
      "y": 5,
      "z": 0,
      "name": "Rock_Basalt"
    },
    {
      "x": -7,
      "y": 6,
      "z": 0,
      "name": "Rock_Basalt"
    },
    {
      "x": -6,
      "y": 0,
      "z": -16,
      "name": "Rock_Basalt"
    },
    {
      "x": -6,
      "y": 1,
      "z": -16,
      "name": "Rock_Basalt"
    },
    {
      "x": -6,
      "y": 2,
      "z": -16,
      "name": "Rock_Basalt"
    },
    {
      "x": -6,
      "y": 3,
      "z": -16,
      "name": "Rock_Basalt"
    },
    {
      "x": -6,
      "y": 4,
      "z": -16,
      "name": "Rock_Basalt"
    },
    {
      "x": -6,
      "y": 5,
      "z": -16,
      "name": "Rock_Basalt"
    },
    {
      "x": -6,
      "y": 6,
      "z": -16,
      "name": "Rock_Basalt"
    },
    {
      "x": -6,
      "y": 7,
      "z": -16,
      "name": "Rock_Basalt"
    },
    {
      "x": -6,
      "y": 8,
      "z": -16,
      "name": "Rock_Basalt"
    },
    {
      "x": -6,
      "y": 9,
      "z": -16,
      "name": "Rock_Basalt"
    },
    {
      "x": -6,
      "y": 10,
      "z": -16,
      "name": "Rock_Basalt"
    },
    {
      "x": -6,
      "y": 0,
      "z": -15,
      "name": "Rock_Basalt_Cobble"
    },
    {
      "x": -6,
      "y": 1,
      "z": -15,
      "name": "Empty"
    },
    {
      "x": -6,
      "y": 2,
      "z": -15,
      "name": "Empty"
    },
    {
      "x": -6,
      "y": 3,
      "z": -15,
      "name": "Empty"
    },
    {
      "x": -6,
      "y": 4,
      "z": -15,
      "name": "Empty"
    },
    {
      "x": -6,
      "y": 5,
      "z": -15,
      "name": "Rock_Basalt"
    },
    {
      "x": -6,
      "y": 6,
      "z": -15,
      "name": "Empty"
    },
    {
      "x": -6,
      "y": 7,
      "z": -15,
      "name": "Empty"
    },
    {
      "x": -6,
      "y": 10,
      "z": -15,
      "name": "Rock_Basalt"
    },
    {
      "x": -6,
      "y": 0,
      "z": -14,
      "name": "Rock_Basalt_Cobble"
    },
    {
      "x": -6,
      "y": 1,
      "z": -14,
      "name": "Empty"
    },
    {
      "x": -6,
      "y": 2,
      "z": -14,
      "name": "Empty"
    },
    {
      "x": -6,
      "y": 3,
      "z": -14,
      "name": "Empty"
    },
    {
      "x": -6,
      "y": 4,
      "z": -14,
      "name": "Empty"
    },
    {
      "x": -6,
      "y": 5,
      "z": -14,
      "name": "Rock_Basalt"
    },
    {
      "x": -6,
      "y": 6,
      "z": -14,
      "name": "Empty"
    },
    {
      "x": -6,
      "y": 7,
      "z": -14,
      "name": "Empty"
    },
    {
      "x": -6,
      "y": 10,
      "z": -14,
      "name": "Rock_Basalt"
    },
    {
      "x": -6,
      "y": 0,
      "z": -13,
      "name": "Rock_Basalt_Cobble"
    },
    {
      "x": -6,
      "y": 1,
      "z": -13,
      "name": "Empty"
    },
    {
      "x": -6,
      "y": 2,
      "z": -13,
      "name": "Empty"
    },
    {
      "x": -6,
      "y": 3,
      "z": -13,
      "name": "Empty"
    },
    {
      "x": -6,
      "y": 4,
      "z": -13,
      "name": "Empty"
    },
    {
      "x": -6,
      "y": 5,
      "z": -13,
      "name": "Rock_Basalt"
    },
    {
      "x": -6,
      "y": 6,
      "z": -13,
      "name": "Empty"
    },
    {
      "x": -6,
      "y": 7,
      "z": -13,
      "name": "Empty"
    },
    {
      "x": -6,
      "y": 10,
      "z": -13,
      "name": "Rock_Basalt"
    },
    {
      "x": -6,
      "y": 0,
      "z": -12,
      "name": "Rock_Basalt_Cobble"
    },
    {
      "x": -6,
      "y": 1,
      "z": -12,
      "name": "Empty"
    },
    {
      "x": -6,
      "y": 2,
      "z": -12,
      "name": "Empty"
    },
    {
      "x": -6,
      "y": 3,
      "z": -12,
      "name": "Empty"
    },
    {
      "x": -6,
      "y": 4,
      "z": -12,
      "name": "Empty"
    },
    {
      "x": -6,
      "y": 5,
      "z": -12,
      "name": "Rock_Basalt"
    },
    {
      "x": -6,
      "y": 6,
      "z": -12,
      "name": "Empty"
    },
    {
      "x": -6,
      "y": 7,
      "z": -12,
      "name": "Empty"
    },
    {
      "x": -6,
      "y": 10,
      "z": -12,
      "name": "Rock_Basalt"
    },
    {
      "x": -6,
      "y": 0,
      "z": -11,
      "name": "Rock_Basalt_Cobble"
    },
    {
      "x": -6,
      "y": 1,
      "z": -11,
      "name": "Rock_Basalt"
    },
    {
      "x": -6,
      "y": 2,
      "z": -11,
      "name": "Rock_Basalt"
    },
    {
      "x": -6,
      "y": 3,
      "z": -11,
      "name": "Rock_Basalt"
    },
    {
      "x": -6,
      "y": 4,
      "z": -11,
      "name": "Rock_Basalt"
    },
    {
      "x": -6,
      "y": 5,
      "z": -11,
      "name": "Rock_Basalt"
    },
    {
      "x": -6,
      "y": 6,
      "z": -11,
      "name": "Empty"
    },
    {
      "x": -6,
      "y": 7,
      "z": -11,
      "name": "Empty"
    },
    {
      "x": -6,
      "y": 10,
      "z": -11,
      "name": "Rock_Basalt"
    },
    {
      "x": -6,
      "y": 0,
      "z": -10,
      "name": "Rock_Basalt_Cobble"
    },
    {
      "x": -6,
      "y": 1,
      "z": -10,
      "name": "Rock_Basalt"
    },
    {
      "x": -6,
      "y": 2,
      "z": -10,
      "name": "Rock_Basalt"
    },
    {
      "x": -6,
      "y": 3,
      "z": -10,
      "name": "Rock_Basalt"
    },
    {
      "x": -6,
      "y": 4,
      "z": -10,
      "name": "Rock_Basalt"
    },
    {
      "x": -6,
      "y": 5,
      "z": -10,
      "name": "Rock_Basalt_Cobble_Stairs"
    },
    {
      "x": -6,
      "y": 6,
      "z": -10,
      "name": "Empty"
    },
    {
      "x": -6,
      "y": 7,
      "z": -10,
      "name": "Empty"
    },
    {
      "x": -6,
      "y": 10,
      "z": -10,
      "name": "Rock_Basalt"
    },
    {
      "x": -6,
      "y": 0,
      "z": -9,
      "name": "Rock_Basalt_Cobble"
    },
    {
      "x": -6,
      "y": 1,
      "z": -9,
      "name": "Rock_Basalt"
    },
    {
      "x": -6,
      "y": 2,
      "z": -9,
      "name": "Rock_Basalt"
    },
    {
      "x": -6,
      "y": 3,
      "z": -9,
      "name": "Rock_Basalt"
    },
    {
      "x": -6,
      "y": 4,
      "z": -9,
      "name": "Rock_Basalt_Cobble_Stairs"
    },
    {
      "x": -6,
      "y": 5,
      "z": -9,
      "name": "Empty"
    },
    {
      "x": -6,
      "y": 6,
      "z": -9,
      "name": "Empty"
    },
    {
      "x": -6,
      "y": 7,
      "z": -9,
      "name": "Empty"
    },
    {
      "x": -6,
      "y": 10,
      "z": -9,
      "name": "Rock_Basalt"
    },
    {
      "x": -6,
      "y": 0,
      "z": -8,
      "name": "Rock_Basalt_Cobble"
    },
    {
      "x": -6,
      "y": 1,
      "z": -8,
      "name": "Rock_Basalt"
    },
    {
      "x": -6,
      "y": 2,
      "z": -8,
      "name": "Rock_Basalt"
    },
    {
      "x": -6,
      "y": 3,
      "z": -8,
      "name": "Rock_Basalt_Cobble_Stairs"
    },
    {
      "x": -6,
      "y": 4,
      "z": -8,
      "name": "Empty"
    },
    {
      "x": -6,
      "y": 5,
      "z": -8,
      "name": "Empty"
    },
    {
      "x": -6,
      "y": 6,
      "z": -8,
      "name": "Empty"
    },
    {
      "x": -6,
      "y": 7,
      "z": -8,
      "name": "Empty"
    },
    {
      "x": -6,
      "y": 10,
      "z": -8,
      "name": "Rock_Basalt"
    },
    {
      "x": -6,
      "y": 0,
      "z": -7,
      "name": "Rock_Basalt"
    },
    {
      "x": -6,
      "y": 1,
      "z": -7,
      "name": "Rock_Basalt"
    },
    {
      "x": -6,
      "y": 2,
      "z": -7,
      "name": "Rock_Basalt_Cobble_Stairs"
    },
    {
      "x": -6,
      "y": 3,
      "z": -7,
      "name": "Empty"
    },
    {
      "x": -6,
      "y": 4,
      "z": -7,
      "name": "Empty"
    },
    {
      "x": -6,
      "y": 5,
      "z": -7,
      "name": "Empty"
    },
    {
      "x": -6,
      "y": 6,
      "z": -7,
      "name": "Empty"
    },
    {
      "x": -6,
      "y": 7,
      "z": -7,
      "name": "Rock_Basalt"
    },
    {
      "x": -6,
      "y": 8,
      "z": -7,
      "name": "Rock_Basalt"
    },
    {
      "x": -6,
      "y": 9,
      "z": -7,
      "name": "Rock_Basalt"
    },
    {
      "x": -6,
      "y": 10,
      "z": -7,
      "name": "Rock_Basalt"
    },
    {
      "x": -6,
      "y": 0,
      "z": -6,
      "name": "Rock_Basalt"
    },
    {
      "x": -6,
      "y": 1,
      "z": -6,
      "name": "Rock_Basalt"
    },
    {
      "x": -6,
      "y": 2,
      "z": -6,
      "name": "Empty"
    },
    {
      "x": -6,
      "y": 3,
      "z": -6,
      "name": "Empty"
    },
    {
      "x": -6,
      "y": 4,
      "z": -6,
      "name": "Empty"
    },
    {
      "x": -6,
      "y": 5,
      "z": -6,
      "name": "Empty"
    },
    {
      "x": -6,
      "y": 6,
      "z": -6,
      "name": "Empty"
    },
    {
      "x": -6,
      "y": 7,
      "z": -6,
      "name": "Rock_Basalt"
    },
    {
      "x": -6,
      "y": 0,
      "z": -5,
      "name": "Rock_Basalt"
    },
    {
      "x": -6,
      "y": 1,
      "z": -5,
      "name": "Rock_Basalt"
    },
    {
      "x": -6,
      "y": 2,
      "z": -5,
      "name": "Empty"
    },
    {
      "x": -6,
      "y": 3,
      "z": -5,
      "name": "Empty"
    },
    {
      "x": -6,
      "y": 4,
      "z": -5,
      "name": "Empty"
    },
    {
      "x": -6,
      "y": 5,
      "z": -5,
      "name": "Empty"
    },
    {
      "x": -6,
      "y": 6,
      "z": -5,
      "name": "Empty"
    },
    {
      "x": -6,
      "y": 7,
      "z": -5,
      "name": "Rock_Basalt"
    },
    {
      "x": -6,
      "y": 0,
      "z": -4,
      "name": "Rock_Basalt"
    },
    {
      "x": -6,
      "y": 1,
      "z": -4,
      "name": "Rock_Basalt"
    },
    {
      "x": -6,
      "y": 2,
      "z": -4,
      "name": "Wood_Deadwood_Fence"
    },
    {
      "x": -6,
      "y": 3,
      "z": -4,
      "name": "Empty"
    },
    {
      "x": -6,
      "y": 4,
      "z": -4,
      "name": "Empty"
    },
    {
      "x": -6,
      "y": 5,
      "z": -4,
      "name": "Wood_Fir_Trunk",
      "rotation": 5
    },
    {
      "x": -6,
      "y": 6,
      "z": -4,
      "name": "Empty"
    },
    {
      "x": -6,
      "y": 7,
      "z": -4,
      "name": "Rock_Basalt"
    },
    {
      "x": -6,
      "y": 0,
      "z": -3,
      "name": "Rock_Basalt_Cobble"
    },
    {
      "x": -6,
      "y": 1,
      "z": -3,
      "name": "Empty"
    },
    {
      "x": -6,
      "y": 2,
      "z": -3,
      "name": "Empty"
    },
    {
      "x": -6,
      "y": 3,
      "z": -3,
      "name": "Empty"
    },
    {
      "x": -6,
      "y": 4,
      "z": -3,
      "name": "Empty"
    },
    {
      "x": -6,
      "y": 5,
      "z": -3,
      "name": "Empty"
    },
    {
      "x": -6,
      "y": 6,
      "z": -3,
      "name": "Rock_Basalt"
    },
    {
      "x": -6,
      "y": 7,
      "z": -3,
      "name": "Rock_Basalt"
    },
    {
      "x": -6,
      "y": 0,
      "z": -2,
      "name": "Rock_Basalt_Cobble"
    },
    {
      "x": -6,
      "y": 1,
      "z": -2,
      "name": "Empty"
    },
    {
      "x": -6,
      "y": 2,
      "z": -2,
      "name": "Empty"
    },
    {
      "x": -6,
      "y": 3,
      "z": -2,
      "name": "Empty"
    },
    {
      "x": -6,
      "y": 4,
      "z": -2,
      "name": "Empty"
    },
    {
      "x": -6,
      "y": 5,
      "z": -2,
      "name": "Empty"
    },
    {
      "x": -6,
      "y": 6,
      "z": -2,
      "name": "Rock_Basalt"
    },
    {
      "x": -6,
      "y": 7,
      "z": -2,
      "name": "Rock_Basalt"
    },
    {
      "x": -6,
      "y": 0,
      "z": -1,
      "name": "Rock_Basalt_Cobble"
    },
    {
      "x": -6,
      "y": 1,
      "z": -1,
      "name": "Empty"
    },
    {
      "x": -6,
      "y": 2,
      "z": -1,
      "name": "Empty"
    },
    {
      "x": -6,
      "y": 3,
      "z": -1,
      "name": "Empty"
    },
    {
      "x": -6,
      "y": 4,
      "z": -1,
      "name": "Empty"
    },
    {
      "x": -6,
      "y": 5,
      "z": -1,
      "name": "Empty"
    },
    {
      "x": -6,
      "y": 6,
      "z": -1,
      "name": "Rock_Basalt"
    },
    {
      "x": -6,
      "y": 7,
      "z": -1,
      "name": "Rock_Basalt"
    },
    {
      "x": -6,
      "y": 0,
      "z": 0,
      "name": "Rock_Basalt"
    },
    {
      "x": -6,
      "y": 1,
      "z": 0,
      "name": "Rock_Basalt"
    },
    {
      "x": -6,
      "y": 2,
      "z": 0,
      "name": "Rock_Basalt"
    },
    {
      "x": -6,
      "y": 3,
      "z": 0,
      "name": "Rock_Basalt"
    },
    {
      "x": -6,
      "y": 4,
      "z": 0,
      "name": "Rock_Basalt"
    },
    {
      "x": -6,
      "y": 5,
      "z": 0,
      "name": "Rock_Basalt"
    },
    {
      "x": -6,
      "y": 6,
      "z": 0,
      "name": "Rock_Basalt"
    },
    {
      "x": -6,
      "y": 7,
      "z": 0,
      "name": "Rock_Basalt"
    },
    {
      "x": -5,
      "y": 0,
      "z": -16,
      "name": "Rock_Basalt"
    },
    {
      "x": -5,
      "y": 1,
      "z": -16,
      "name": "Rock_Basalt"
    },
    {
      "x": -5,
      "y": 2,
      "z": -16,
      "name": "Rock_Basalt"
    },
    {
      "x": -5,
      "y": 3,
      "z": -16,
      "name": "Rock_Basalt"
    },
    {
      "x": -5,
      "y": 4,
      "z": -16,
      "name": "Rock_Basalt"
    },
    {
      "x": -5,
      "y": 5,
      "z": -16,
      "name": "Rock_Basalt"
    },
    {
      "x": -5,
      "y": 6,
      "z": -16,
      "name": "Rock_Basalt"
    },
    {
      "x": -5,
      "y": 7,
      "z": -16,
      "name": "Rock_Basalt"
    },
    {
      "x": -5,
      "y": 8,
      "z": -16,
      "name": "Rock_Basalt"
    },
    {
      "x": -5,
      "y": 9,
      "z": -16,
      "name": "Rock_Basalt"
    },
    {
      "x": -5,
      "y": 10,
      "z": -16,
      "name": "Rock_Basalt"
    },
    {
      "x": -5,
      "y": 0,
      "z": -15,
      "name": "Rock_Basalt_Cobble"
    },
    {
      "x": -5,
      "y": 1,
      "z": -15,
      "name": "Empty"
    },
    {
      "x": -5,
      "y": 2,
      "z": -15,
      "name": "Empty"
    },
    {
      "x": -5,
      "y": 3,
      "z": -15,
      "name": "Empty"
    },
    {
      "x": -5,
      "y": 4,
      "z": -15,
      "name": "Empty"
    },
    {
      "x": -5,
      "y": 5,
      "z": -15,
      "name": "Rock_Basalt"
    },
    {
      "x": -5,
      "y": 6,
      "z": -15,
      "name": "Empty"
    },
    {
      "x": -5,
      "y": 7,
      "z": -15,
      "name": "Empty"
    },
    {
      "x": -5,
      "y": 10,
      "z": -15,
      "name": "Rock_Basalt"
    },
    {
      "x": -5,
      "y": 0,
      "z": -14,
      "name": "Rock_Basalt_Cobble"
    },
    {
      "x": -5,
      "y": 1,
      "z": -14,
      "name": "Empty"
    },
    {
      "x": -5,
      "y": 2,
      "z": -14,
      "name": "Empty"
    },
    {
      "x": -5,
      "y": 3,
      "z": -14,
      "name": "Empty"
    },
    {
      "x": -5,
      "y": 4,
      "z": -14,
      "name": "Empty"
    },
    {
      "x": -5,
      "y": 5,
      "z": -14,
      "name": "Rock_Basalt"
    },
    {
      "x": -5,
      "y": 6,
      "z": -14,
      "name": "Empty"
    },
    {
      "x": -5,
      "y": 7,
      "z": -14,
      "name": "Empty"
    },
    {
      "x": -5,
      "y": 10,
      "z": -14,
      "name": "Rock_Basalt"
    },
    {
      "x": -5,
      "y": 0,
      "z": -13,
      "name": "Rock_Basalt_Cobble"
    },
    {
      "x": -5,
      "y": 1,
      "z": -13,
      "name": "Empty"
    },
    {
      "x": -5,
      "y": 2,
      "z": -13,
      "name": "Empty"
    },
    {
      "x": -5,
      "y": 3,
      "z": -13,
      "name": "Empty"
    },
    {
      "x": -5,
      "y": 4,
      "z": -13,
      "name": "Empty"
    },
    {
      "x": -5,
      "y": 5,
      "z": -13,
      "name": "Rock_Basalt"
    },
    {
      "x": -5,
      "y": 6,
      "z": -13,
      "name": "Empty"
    },
    {
      "x": -5,
      "y": 7,
      "z": -13,
      "name": "Empty"
    },
    {
      "x": -5,
      "y": 10,
      "z": -13,
      "name": "Rock_Basalt"
    },
    {
      "x": -5,
      "y": 0,
      "z": -12,
      "name": "Rock_Basalt_Cobble"
    },
    {
      "x": -5,
      "y": 1,
      "z": -12,
      "name": "Empty"
    },
    {
      "x": -5,
      "y": 2,
      "z": -12,
      "name": "Empty"
    },
    {
      "x": -5,
      "y": 3,
      "z": -12,
      "name": "Empty"
    },
    {
      "x": -5,
      "y": 4,
      "z": -12,
      "name": "Empty"
    },
    {
      "x": -5,
      "y": 5,
      "z": -12,
      "name": "Rock_Basalt"
    },
    {
      "x": -5,
      "y": 6,
      "z": -12,
      "name": "Empty"
    },
    {
      "x": -5,
      "y": 7,
      "z": -12,
      "name": "Empty"
    },
    {
      "x": -5,
      "y": 10,
      "z": -12,
      "name": "Rock_Basalt"
    },
    {
      "x": -5,
      "y": 0,
      "z": -11,
      "name": "Rock_Basalt"
    },
    {
      "x": -5,
      "y": 1,
      "z": -11,
      "name": "Rock_Basalt"
    },
    {
      "x": -5,
      "y": 2,
      "z": -11,
      "name": "Rock_Basalt"
    },
    {
      "x": -5,
      "y": 3,
      "z": -11,
      "name": "Rock_Basalt"
    },
    {
      "x": -5,
      "y": 4,
      "z": -11,
      "name": "Rock_Basalt"
    },
    {
      "x": -5,
      "y": 5,
      "z": -11,
      "name": "Rock_Basalt"
    },
    {
      "x": -5,
      "y": 6,
      "z": -11,
      "name": "Empty"
    },
    {
      "x": -5,
      "y": 7,
      "z": -11,
      "name": "Empty"
    },
    {
      "x": -5,
      "y": 10,
      "z": -11,
      "name": "Rock_Basalt"
    },
    {
      "x": -5,
      "y": 0,
      "z": -10,
      "name": "Rock_Basalt"
    },
    {
      "x": -5,
      "y": 1,
      "z": -10,
      "name": "Rock_Basalt"
    },
    {
      "x": -5,
      "y": 2,
      "z": -10,
      "name": "Rock_Basalt"
    },
    {
      "x": -5,
      "y": 3,
      "z": -10,
      "name": "Rock_Basalt"
    },
    {
      "x": -5,
      "y": 4,
      "z": -10,
      "name": "Rock_Basalt"
    },
    {
      "x": -5,
      "y": 5,
      "z": -10,
      "name": "Rock_Basalt"
    },
    {
      "x": -5,
      "y": 6,
      "z": -10,
      "name": "Empty"
    },
    {
      "x": -5,
      "y": 7,
      "z": -10,
      "name": "Empty"
    },
    {
      "x": -5,
      "y": 10,
      "z": -10,
      "name": "Rock_Basalt"
    },
    {
      "x": -5,
      "y": 0,
      "z": -9,
      "name": "Rock_Basalt"
    },
    {
      "x": -5,
      "y": 1,
      "z": -9,
      "name": "Rock_Basalt"
    },
    {
      "x": -5,
      "y": 2,
      "z": -9,
      "name": "Rock_Basalt"
    },
    {
      "x": -5,
      "y": 3,
      "z": -9,
      "name": "Rock_Basalt"
    },
    {
      "x": -5,
      "y": 4,
      "z": -9,
      "name": "Rock_Basalt"
    },
    {
      "x": -5,
      "y": 5,
      "z": -9,
      "name": "Rock_Basalt"
    },
    {
      "x": -5,
      "y": 6,
      "z": -9,
      "name": "Empty"
    },
    {
      "x": -5,
      "y": 7,
      "z": -9,
      "name": "Empty"
    },
    {
      "x": -5,
      "y": 10,
      "z": -9,
      "name": "Rock_Basalt"
    },
    {
      "x": -5,
      "y": 0,
      "z": -8,
      "name": "Rock_Basalt"
    },
    {
      "x": -5,
      "y": 1,
      "z": -8,
      "name": "Rock_Basalt"
    },
    {
      "x": -5,
      "y": 2,
      "z": -8,
      "name": "Rock_Basalt"
    },
    {
      "x": -5,
      "y": 3,
      "z": -8,
      "name": "Rock_Basalt"
    },
    {
      "x": -5,
      "y": 4,
      "z": -8,
      "name": "Rock_Basalt"
    },
    {
      "x": -5,
      "y": 5,
      "z": -8,
      "name": "Rock_Basalt"
    },
    {
      "x": -5,
      "y": 6,
      "z": -8,
      "name": "Empty"
    },
    {
      "x": -5,
      "y": 7,
      "z": -8,
      "name": "Empty"
    },
    {
      "x": -5,
      "y": 10,
      "z": -8,
      "name": "Rock_Basalt"
    },
    {
      "x": -5,
      "y": 0,
      "z": -7,
      "name": "Rock_Basalt"
    },
    {
      "x": -5,
      "y": 1,
      "z": -7,
      "name": "Rock_Basalt"
    },
    {
      "x": -5,
      "y": 2,
      "z": -7,
      "name": "Rock_Basalt"
    },
    {
      "x": -5,
      "y": 3,
      "z": -7,
      "name": "Rock_Basalt"
    },
    {
      "x": -5,
      "y": 4,
      "z": -7,
      "name": "Rock_Basalt"
    },
    {
      "x": -5,
      "y": 5,
      "z": -7,
      "name": "Rock_Basalt"
    },
    {
      "x": -5,
      "y": 6,
      "z": -7,
      "name": "Rock_Basalt"
    },
    {
      "x": -5,
      "y": 7,
      "z": -7,
      "name": "Rock_Basalt"
    },
    {
      "x": -5,
      "y": 8,
      "z": -7,
      "name": "Rock_Basalt"
    },
    {
      "x": -5,
      "y": 9,
      "z": -7,
      "name": "Rock_Basalt"
    },
    {
      "x": -5,
      "y": 10,
      "z": -7,
      "name": "Rock_Basalt"
    },
    {
      "x": -5,
      "y": 0,
      "z": -6,
      "name": "Rock_Basalt"
    },
    {
      "x": -5,
      "y": 1,
      "z": -6,
      "name": "Rock_Basalt_Cobble_Stairs",
      "rotation": 1
    },
    {
      "x": -5,
      "y": 2,
      "z": -6,
      "name": "Empty"
    },
    {
      "x": -5,
      "y": 3,
      "z": -6,
      "name": "Empty"
    },
    {
      "x": -5,
      "y": 4,
      "z": -6,
      "name": "Empty"
    },
    {
      "x": -5,
      "y": 5,
      "z": -6,
      "name": "Empty"
    },
    {
      "x": -5,
      "y": 6,
      "z": -6,
      "name": "Rock_Basalt"
    },
    {
      "x": -5,
      "y": 7,
      "z": -6,
      "name": "Rock_Basalt"
    },
    {
      "x": -5,
      "y": 0,
      "z": -5,
      "name": "Rock_Basalt"
    },
    {
      "x": -5,
      "y": 1,
      "z": -5,
      "name": "Rock_Basalt_Cobble_Stairs",
      "rotation": 1
    },
    {
      "x": -5,
      "y": 2,
      "z": -5,
      "name": "Empty"
    },
    {
      "x": -5,
      "y": 3,
      "z": -5,
      "name": "Empty"
    },
    {
      "x": -5,
      "y": 4,
      "z": -5,
      "name": "Empty"
    },
    {
      "x": -5,
      "y": 5,
      "z": -5,
      "name": "Empty"
    },
    {
      "x": -5,
      "y": 6,
      "z": -5,
      "name": "Rock_Basalt"
    },
    {
      "x": -5,
      "y": 7,
      "z": -5,
      "name": "Rock_Basalt"
    },
    {
      "x": -5,
      "y": 0,
      "z": -4,
      "name": "Rock_Basalt"
    },
    {
      "x": -5,
      "y": 1,
      "z": -4,
      "name": "Rock_Basalt"
    },
    {
      "x": -5,
      "y": 2,
      "z": -4,
      "name": "Wood_Deadwood_Fence"
    },
    {
      "x": -5,
      "y": 3,
      "z": -4,
      "name": "Empty"
    },
    {
      "x": -5,
      "y": 4,
      "z": -4,
      "name": "Empty"
    },
    {
      "x": -5,
      "y": 5,
      "z": -4,
      "name": "Wood_Fir_Trunk",
      "rotation": 5
    },
    {
      "x": -5,
      "y": 6,
      "z": -4,
      "name": "Empty"
    },
    {
      "x": -5,
      "y": 7,
      "z": -4,
      "name": "Rock_Basalt"
    },
    {
      "x": -5,
      "y": 0,
      "z": -3,
      "name": "Rock_Basalt_Cobble"
    },
    {
      "x": -5,
      "y": 1,
      "z": -3,
      "name": "Empty"
    },
    {
      "x": -5,
      "y": 2,
      "z": -3,
      "name": "Empty"
    },
    {
      "x": -5,
      "y": 3,
      "z": -3,
      "name": "Empty"
    },
    {
      "x": -5,
      "y": 4,
      "z": -3,
      "name": "Empty"
    },
    {
      "x": -5,
      "y": 5,
      "z": -3,
      "name": "Empty"
    },
    {
      "x": -5,
      "y": 6,
      "z": -3,
      "name": "Empty"
    },
    {
      "x": -5,
      "y": 7,
      "z": -3,
      "name": "Rock_Basalt"
    },
    {
      "x": -5,
      "y": 0,
      "z": -2,
      "name": "Rock_Basalt_Cobble"
    },
    {
      "x": -5,
      "y": 1,
      "z": -2,
      "name": "Empty"
    },
    {
      "x": -5,
      "y": 2,
      "z": -2,
      "name": "Empty"
    },
    {
      "x": -5,
      "y": 3,
      "z": -2,
      "name": "Empty"
    },
    {
      "x": -5,
      "y": 4,
      "z": -2,
      "name": "Empty"
    },
    {
      "x": -5,
      "y": 5,
      "z": -2,
      "name": "Empty"
    },
    {
      "x": -5,
      "y": 6,
      "z": -2,
      "name": "Empty"
    },
    {
      "x": -5,
      "y": 7,
      "z": -2,
      "name": "Rock_Basalt"
    },
    {
      "x": -5,
      "y": 0,
      "z": -1,
      "name": "Rock_Basalt_Cobble"
    },
    {
      "x": -5,
      "y": 1,
      "z": -1,
      "name": "Empty"
    },
    {
      "x": -5,
      "y": 2,
      "z": -1,
      "name": "Empty"
    },
    {
      "x": -5,
      "y": 3,
      "z": -1,
      "name": "Empty"
    },
    {
      "x": -5,
      "y": 4,
      "z": -1,
      "name": "Empty"
    },
    {
      "x": -5,
      "y": 5,
      "z": -1,
      "name": "Empty"
    },
    {
      "x": -5,
      "y": 6,
      "z": -1,
      "name": "Empty"
    },
    {
      "x": -5,
      "y": 7,
      "z": -1,
      "name": "Rock_Basalt"
    },
    {
      "x": -5,
      "y": 0,
      "z": 0,
      "name": "Rock_Basalt"
    },
    {
      "x": -5,
      "y": 1,
      "z": 0,
      "name": "Rock_Basalt"
    },
    {
      "x": -5,
      "y": 2,
      "z": 0,
      "name": "Rock_Basalt"
    },
    {
      "x": -5,
      "y": 3,
      "z": 0,
      "name": "Rock_Basalt"
    },
    {
      "x": -5,
      "y": 4,
      "z": 0,
      "name": "Rock_Basalt"
    },
    {
      "x": -5,
      "y": 5,
      "z": 0,
      "name": "Rock_Basalt"
    },
    {
      "x": -5,
      "y": 6,
      "z": 0,
      "name": "Rock_Basalt"
    },
    {
      "x": -5,
      "y": 7,
      "z": 0,
      "name": "Rock_Basalt"
    },
    {
      "x": -4,
      "y": 0,
      "z": -16,
      "name": "Rock_Basalt"
    },
    {
      "x": -4,
      "y": 1,
      "z": -16,
      "name": "Rock_Basalt"
    },
    {
      "x": -4,
      "y": 2,
      "z": -16,
      "name": "Rock_Basalt"
    },
    {
      "x": -4,
      "y": 3,
      "z": -16,
      "name": "Rock_Basalt"
    },
    {
      "x": -4,
      "y": 4,
      "z": -16,
      "name": "Rock_Basalt"
    },
    {
      "x": -4,
      "y": 5,
      "z": -16,
      "name": "Rock_Basalt"
    },
    {
      "x": -4,
      "y": 6,
      "z": -16,
      "name": "Rock_Basalt"
    },
    {
      "x": -4,
      "y": 7,
      "z": -16,
      "name": "Rock_Basalt"
    },
    {
      "x": -4,
      "y": 8,
      "z": -16,
      "name": "Rock_Basalt"
    },
    {
      "x": -4,
      "y": 9,
      "z": -16,
      "name": "Rock_Basalt"
    },
    {
      "x": -4,
      "y": 10,
      "z": -16,
      "name": "Rock_Basalt"
    },
    {
      "x": -4,
      "y": 0,
      "z": -15,
      "name": "Rock_Basalt_Cobble"
    },
    {
      "x": -4,
      "y": 1,
      "z": -15,
      "name": "Empty"
    },
    {
      "x": -4,
      "y": 2,
      "z": -15,
      "name": "Empty"
    },
    {
      "x": -4,
      "y": 3,
      "z": -15,
      "name": "Empty"
    },
    {
      "x": -4,
      "y": 4,
      "z": -15,
      "name": "Empty"
    },
    {
      "x": -4,
      "y": 5,
      "z": -15,
      "name": "Rock_Basalt"
    },
    {
      "x": -4,
      "y": 6,
      "z": -15,
      "name": "Empty"
    },
    {
      "x": -4,
      "y": 7,
      "z": -15,
      "name": "Empty"
    },
    {
      "x": -4,
      "y": 8,
      "z": -15,
      "name": "Empty"
    },
    {
      "x": -4,
      "y": 10,
      "z": -15,
      "name": "Rock_Basalt"
    },
    {
      "x": -4,
      "y": 0,
      "z": -14,
      "name": "Rock_Basalt_Cobble"
    },
    {
      "x": -4,
      "y": 1,
      "z": -14,
      "name": "Empty"
    },
    {
      "x": -4,
      "y": 2,
      "z": -14,
      "name": "Empty"
    },
    {
      "x": -4,
      "y": 3,
      "z": -14,
      "name": "Empty"
    },
    {
      "x": -4,
      "y": 4,
      "z": -14,
      "name": "Empty"
    },
    {
      "x": -4,
      "y": 5,
      "z": -14,
      "name": "Rock_Basalt"
    },
    {
      "x": -4,
      "y": 6,
      "z": -14,
      "name": "Empty"
    },
    {
      "x": -4,
      "y": 7,
      "z": -14,
      "name": "Empty"
    },
    {
      "x": -4,
      "y": 8,
      "z": -14,
      "name": "Empty"
    },
    {
      "x": -4,
      "y": 10,
      "z": -14,
      "name": "Rock_Basalt"
    },
    {
      "x": -4,
      "y": 0,
      "z": -13,
      "name": "Rock_Basalt_Cobble"
    },
    {
      "x": -4,
      "y": 1,
      "z": -13,
      "name": "Empty"
    },
    {
      "x": -4,
      "y": 2,
      "z": -13,
      "name": "Empty"
    },
    {
      "x": -4,
      "y": 3,
      "z": -13,
      "name": "Empty"
    },
    {
      "x": -4,
      "y": 4,
      "z": -13,
      "name": "Empty"
    },
    {
      "x": -4,
      "y": 5,
      "z": -13,
      "name": "Rock_Basalt"
    },
    {
      "x": -4,
      "y": 6,
      "z": -13,
      "name": "Empty"
    },
    {
      "x": -4,
      "y": 7,
      "z": -13,
      "name": "Empty"
    },
    {
      "x": -4,
      "y": 8,
      "z": -13,
      "name": "Empty"
    },
    {
      "x": -4,
      "y": 10,
      "z": -13,
      "name": "Rock_Basalt"
    },
    {
      "x": -4,
      "y": 0,
      "z": -12,
      "name": "Rock_Basalt_Cobble"
    },
    {
      "x": -4,
      "y": 1,
      "z": -12,
      "name": "Empty"
    },
    {
      "x": -4,
      "y": 2,
      "z": -12,
      "name": "Empty"
    },
    {
      "x": -4,
      "y": 3,
      "z": -12,
      "name": "Empty"
    },
    {
      "x": -4,
      "y": 4,
      "z": -12,
      "name": "Empty"
    },
    {
      "x": -4,
      "y": 5,
      "z": -12,
      "name": "Rock_Basalt"
    },
    {
      "x": -4,
      "y": 6,
      "z": -12,
      "name": "Empty"
    },
    {
      "x": -4,
      "y": 7,
      "z": -12,
      "name": "Empty"
    },
    {
      "x": -4,
      "y": 8,
      "z": -12,
      "name": "Empty"
    },
    {
      "x": -4,
      "y": 10,
      "z": -12,
      "name": "Rock_Basalt"
    },
    {
      "x": -4,
      "y": 0,
      "z": -11,
      "name": "Rock_Basalt_Cobble"
    },
    {
      "x": -4,
      "y": 1,
      "z": -11,
      "name": "Empty"
    },
    {
      "x": -4,
      "y": 2,
      "z": -11,
      "name": "Empty"
    },
    {
      "x": -4,
      "y": 3,
      "z": -11,
      "name": "Empty"
    },
    {
      "x": -4,
      "y": 4,
      "z": -11,
      "name": "Empty"
    },
    {
      "x": -4,
      "y": 5,
      "z": -11,
      "name": "Rock_Basalt"
    },
    {
      "x": -4,
      "y": 6,
      "z": -11,
      "name": "Empty"
    },
    {
      "x": -4,
      "y": 7,
      "z": -11,
      "name": "Empty"
    },
    {
      "x": -4,
      "y": 8,
      "z": -11,
      "name": "Empty"
    },
    {
      "x": -4,
      "y": 10,
      "z": -11,
      "name": "Rock_Basalt"
    },
    {
      "x": -4,
      "y": 0,
      "z": -10,
      "name": "Rock_Basalt_Cobble"
    },
    {
      "x": -4,
      "y": 1,
      "z": -10,
      "name": "Empty"
    },
    {
      "x": -4,
      "y": 2,
      "z": -10,
      "name": "Empty"
    },
    {
      "x": -4,
      "y": 3,
      "z": -10,
      "name": "Empty"
    },
    {
      "x": -4,
      "y": 4,
      "z": -10,
      "name": "Empty"
    },
    {
      "x": -4,
      "y": 5,
      "z": -10,
      "name": "Rock_Basalt"
    },
    {
      "x": -4,
      "y": 6,
      "z": -10,
      "name": "Empty"
    },
    {
      "x": -4,
      "y": 7,
      "z": -10,
      "name": "Empty"
    },
    {
      "x": -4,
      "y": 8,
      "z": -10,
      "name": "Empty"
    },
    {
      "x": -4,
      "y": 10,
      "z": -10,
      "name": "Rock_Basalt"
    },
    {
      "x": -4,
      "y": 0,
      "z": -9,
      "name": "Rock_Basalt_Cobble"
    },
    {
      "x": -4,
      "y": 1,
      "z": -9,
      "name": "Empty"
    },
    {
      "x": -4,
      "y": 2,
      "z": -9,
      "name": "Empty"
    },
    {
      "x": -4,
      "y": 3,
      "z": -9,
      "name": "Empty"
    },
    {
      "x": -4,
      "y": 4,
      "z": -9,
      "name": "Empty"
    },
    {
      "x": -4,
      "y": 5,
      "z": -9,
      "name": "Rock_Basalt"
    },
    {
      "x": -4,
      "y": 6,
      "z": -9,
      "name": "Empty"
    },
    {
      "x": -4,
      "y": 7,
      "z": -9,
      "name": "Empty"
    },
    {
      "x": -4,
      "y": 8,
      "z": -9,
      "name": "Empty"
    },
    {
      "x": -4,
      "y": 10,
      "z": -9,
      "name": "Rock_Basalt"
    },
    {
      "x": -4,
      "y": 0,
      "z": -8,
      "name": "Rock_Basalt_Cobble"
    },
    {
      "x": -4,
      "y": 1,
      "z": -8,
      "name": "Empty"
    },
    {
      "x": -4,
      "y": 2,
      "z": -8,
      "name": "Empty"
    },
    {
      "x": -4,
      "y": 3,
      "z": -8,
      "name": "Empty"
    },
    {
      "x": -4,
      "y": 4,
      "z": -8,
      "name": "Empty"
    },
    {
      "x": -4,
      "y": 5,
      "z": -8,
      "name": "Rock_Basalt"
    },
    {
      "x": -4,
      "y": 6,
      "z": -8,
      "name": "Empty"
    },
    {
      "x": -4,
      "y": 7,
      "z": -8,
      "name": "Empty"
    },
    {
      "x": -4,
      "y": 8,
      "z": -8,
      "name": "Empty"
    },
    {
      "x": -4,
      "y": 10,
      "z": -8,
      "name": "Rock_Basalt"
    },
    {
      "x": -4,
      "y": 0,
      "z": -7,
      "name": "Rock_Basalt"
    },
    {
      "x": -4,
      "y": 1,
      "z": -7,
      "name": "Rock_Basalt"
    },
    {
      "x": -4,
      "y": 2,
      "z": -7,
      "name": "Rock_Basalt"
    },
    {
      "x": -4,
      "y": 3,
      "z": -7,
      "name": "Rock_Basalt"
    },
    {
      "x": -4,
      "y": 4,
      "z": -7,
      "name": "Rock_Basalt"
    },
    {
      "x": -4,
      "y": 5,
      "z": -7,
      "name": "Rock_Basalt"
    },
    {
      "x": -4,
      "y": 6,
      "z": -7,
      "name": "Rock_Basalt"
    },
    {
      "x": -4,
      "y": 7,
      "z": -7,
      "name": "Rock_Basalt"
    },
    {
      "x": -4,
      "y": 8,
      "z": -7,
      "name": "Rock_Basalt"
    },
    {
      "x": -4,
      "y": 9,
      "z": -7,
      "name": "Rock_Basalt"
    },
    {
      "x": -4,
      "y": 10,
      "z": -7,
      "name": "Rock_Basalt"
    },
    {
      "x": -4,
      "y": 0,
      "z": -6,
      "name": "Rock_Basalt"
    },
    {
      "x": -4,
      "y": 1,
      "z": -6,
      "name": "Empty"
    },
    {
      "x": -4,
      "y": 2,
      "z": -6,
      "name": "Empty"
    },
    {
      "x": -4,
      "y": 3,
      "z": -6,
      "name": "Empty"
    },
    {
      "x": -4,
      "y": 4,
      "z": -6,
      "name": "Empty"
    },
    {
      "x": -4,
      "y": 5,
      "z": -6,
      "name": "Empty"
    },
    {
      "x": -4,
      "y": 6,
      "z": -6,
      "name": "Rock_Basalt"
    },
    {
      "x": -4,
      "y": 7,
      "z": -6,
      "name": "Rock_Basalt"
    },
    {
      "x": -4,
      "y": 8,
      "z": -6,
      "name": "Rock_Basalt"
    },
    {
      "x": -4,
      "y": 0,
      "z": -5,
      "name": "Rock_Basalt"
    },
    {
      "x": -4,
      "y": 1,
      "z": -5,
      "name": "Empty"
    },
    {
      "x": -4,
      "y": 2,
      "z": -5,
      "name": "Empty"
    },
    {
      "x": -4,
      "y": 3,
      "z": -5,
      "name": "Empty"
    },
    {
      "x": -4,
      "y": 4,
      "z": -5,
      "name": "Empty"
    },
    {
      "x": -4,
      "y": 5,
      "z": -5,
      "name": "Empty"
    },
    {
      "x": -4,
      "y": 6,
      "z": -5,
      "name": "Empty"
    },
    {
      "x": -4,
      "y": 7,
      "z": -5,
      "name": "Rock_Basalt"
    },
    {
      "x": -4,
      "y": 8,
      "z": -5,
      "name": "Rock_Basalt"
    },
    {
      "x": -4,
      "y": 0,
      "z": -4,
      "name": "Rock_Basalt"
    },
    {
      "x": -4,
      "y": 1,
      "z": -4,
      "name": "Empty"
    },
    {
      "x": -4,
      "y": 2,
      "z": -4,
      "name": "Empty"
    },
    {
      "x": -4,
      "y": 3,
      "z": -4,
      "name": "Empty"
    },
    {
      "x": -4,
      "y": 4,
      "z": -4,
      "name": "Empty"
    },
    {
      "x": -4,
      "y": 5,
      "z": -4,
      "name": "Wood_Fir_Trunk",
      "rotation": 5
    },
    {
      "x": -4,
      "y": 6,
      "z": -4,
      "name": "Empty"
    },
    {
      "x": -4,
      "y": 7,
      "z": -4,
      "name": "Empty"
    },
    {
      "x": -4,
      "y": 8,
      "z": -4,
      "name": "Rock_Basalt"
    },
    {
      "x": -4,
      "y": 0,
      "z": -3,
      "name": "Rock_Basalt_Cobble"
    },
    {
      "x": -4,
      "y": 1,
      "z": -3,
      "name": "Empty"
    },
    {
      "x": -4,
      "y": 2,
      "z": -3,
      "name": "Empty"
    },
    {
      "x": -4,
      "y": 3,
      "z": -3,
      "name": "Empty"
    },
    {
      "x": -4,
      "y": 4,
      "z": -3,
      "name": "Empty"
    },
    {
      "x": -4,
      "y": 5,
      "z": -3,
      "name": "Wood_Fir_Branch_Long",
      "rotation": 4
    },
    {
      "x": -4,
      "y": 6,
      "z": -3,
      "name": "Empty"
    },
    {
      "x": -4,
      "y": 7,
      "z": -3,
      "name": "Empty"
    },
    {
      "x": -4,
      "y": 8,
      "z": -3,
      "name": "Rock_Basalt"
    },
    {
      "x": -4,
      "y": 0,
      "z": -2,
      "name": "Rock_Basalt_Cobble"
    },
    {
      "x": -4,
      "y": 1,
      "z": -2,
      "name": "Empty"
    },
    {
      "x": -4,
      "y": 2,
      "z": -2,
      "name": "Empty"
    },
    {
      "x": -4,
      "y": 3,
      "z": -2,
      "name": "Empty"
    },
    {
      "x": -4,
      "y": 4,
      "z": -2,
      "name": "Empty"
    },
    {
      "x": -4,
      "y": 5,
      "z": -2,
      "name": "Wood_Fir_Branch_Long",
      "rotation": 4
    },
    {
      "x": -4,
      "y": 6,
      "z": -2,
      "name": "Empty"
    },
    {
      "x": -4,
      "y": 7,
      "z": -2,
      "name": "Empty"
    },
    {
      "x": -4,
      "y": 8,
      "z": -2,
      "name": "Rock_Basalt"
    },
    {
      "x": -4,
      "y": 0,
      "z": -1,
      "name": "Rock_Basalt_Cobble"
    },
    {
      "x": -4,
      "y": 1,
      "z": -1,
      "name": "Empty"
    },
    {
      "x": -4,
      "y": 2,
      "z": -1,
      "name": "Empty"
    },
    {
      "x": -4,
      "y": 3,
      "z": -1,
      "name": "Empty"
    },
    {
      "x": -4,
      "y": 4,
      "z": -1,
      "name": "Empty"
    },
    {
      "x": -4,
      "y": 5,
      "z": -1,
      "name": "Wood_Fir_Branch_Long",
      "rotation": 4
    },
    {
      "x": -4,
      "y": 6,
      "z": -1,
      "name": "Empty"
    },
    {
      "x": -4,
      "y": 7,
      "z": -1,
      "name": "Empty"
    },
    {
      "x": -4,
      "y": 8,
      "z": -1,
      "name": "Rock_Basalt"
    },
    {
      "x": -4,
      "y": 0,
      "z": 0,
      "name": "Rock_Basalt"
    },
    {
      "x": -4,
      "y": 1,
      "z": 0,
      "name": "Rock_Basalt"
    },
    {
      "x": -4,
      "y": 2,
      "z": 0,
      "name": "Rock_Basalt"
    },
    {
      "x": -4,
      "y": 3,
      "z": 0,
      "name": "Rock_Basalt"
    },
    {
      "x": -4,
      "y": 4,
      "z": 0,
      "name": "Rock_Basalt"
    },
    {
      "x": -4,
      "y": 5,
      "z": 0,
      "name": "Rock_Basalt"
    },
    {
      "x": -4,
      "y": 6,
      "z": 0,
      "name": "Rock_Basalt"
    },
    {
      "x": -4,
      "y": 7,
      "z": 0,
      "name": "Rock_Basalt"
    },
    {
      "x": -4,
      "y": 8,
      "z": 0,
      "name": "Rock_Basalt"
    },
    {
      "x": -3,
      "y": 0,
      "z": -16,
      "name": "Rock_Basalt"
    },
    {
      "x": -3,
      "y": 1,
      "z": -16,
      "name": "Rock_Basalt"
    },
    {
      "x": -3,
      "y": 2,
      "z": -16,
      "name": "Rock_Basalt"
    },
    {
      "x": -3,
      "y": 3,
      "z": -16,
      "name": "Rock_Basalt"
    },
    {
      "x": -3,
      "y": 4,
      "z": -16,
      "name": "Rock_Basalt"
    },
    {
      "x": -3,
      "y": 5,
      "z": -16,
      "name": "Rock_Basalt"
    },
    {
      "x": -3,
      "y": 6,
      "z": -16,
      "name": "Rock_Basalt"
    },
    {
      "x": -3,
      "y": 7,
      "z": -16,
      "name": "Rock_Basalt"
    },
    {
      "x": -3,
      "y": 8,
      "z": -16,
      "name": "Rock_Basalt"
    },
    {
      "x": -3,
      "y": 9,
      "z": -16,
      "name": "Rock_Basalt"
    },
    {
      "x": -3,
      "y": 10,
      "z": -16,
      "name": "Rock_Basalt"
    },
    {
      "x": -3,
      "y": 0,
      "z": -15,
      "name": "Rock_Basalt_Cobble"
    },
    {
      "x": -3,
      "y": 1,
      "z": -15,
      "name": "Rock_Basalt"
    },
    {
      "x": -3,
      "y": 2,
      "z": -15,
      "name": "Rock_Basalt"
    },
    {
      "x": -3,
      "y": 3,
      "z": -15,
      "name": "Empty"
    },
    {
      "x": -3,
      "y": 4,
      "z": -15,
      "name": "Empty"
    },
    {
      "x": -3,
      "y": 5,
      "z": -15,
      "name": "Rock_Basalt"
    },
    {
      "x": -3,
      "y": 6,
      "z": -15,
      "name": "Empty"
    },
    {
      "x": -3,
      "y": 7,
      "z": -15,
      "name": "Empty"
    },
    {
      "x": -3,
      "y": 8,
      "z": -15,
      "name": "Empty"
    },
    {
      "x": -3,
      "y": 10,
      "z": -15,
      "name": "Rock_Basalt"
    },
    {
      "x": -3,
      "y": 0,
      "z": -14,
      "name": "Rock_Basalt_Cobble"
    },
    {
      "x": -3,
      "y": 1,
      "z": -14,
      "name": "Empty"
    },
    {
      "x": -3,
      "y": 2,
      "z": -14,
      "name": "Empty"
    },
    {
      "x": -3,
      "y": 3,
      "z": -14,
      "name": "Empty"
    },
    {
      "x": -3,
      "y": 4,
      "z": -14,
      "name": "Empty"
    },
    {
      "x": -3,
      "y": 5,
      "z": -14,
      "name": "Rock_Basalt"
    },
    {
      "x": -3,
      "y": 6,
      "z": -14,
      "name": "Empty"
    },
    {
      "x": -3,
      "y": 7,
      "z": -14,
      "name": "Empty"
    },
    {
      "x": -3,
      "y": 8,
      "z": -14,
      "name": "Empty"
    },
    {
      "x": -3,
      "y": 10,
      "z": -14,
      "name": "Rock_Basalt"
    },
    {
      "x": -3,
      "y": 0,
      "z": -13,
      "name": "Rock_Basalt_Cobble"
    },
    {
      "x": -3,
      "y": 1,
      "z": -13,
      "name": "Empty"
    },
    {
      "x": -3,
      "y": 2,
      "z": -13,
      "name": "Empty"
    },
    {
      "x": -3,
      "y": 3,
      "z": -13,
      "name": "Empty"
    },
    {
      "x": -3,
      "y": 4,
      "z": -13,
      "name": "Empty"
    },
    {
      "x": -3,
      "y": 5,
      "z": -13,
      "name": "Rock_Basalt"
    },
    {
      "x": -3,
      "y": 6,
      "z": -13,
      "name": "Empty"
    },
    {
      "x": -3,
      "y": 7,
      "z": -13,
      "name": "Empty"
    },
    {
      "x": -3,
      "y": 8,
      "z": -13,
      "name": "Empty"
    },
    {
      "x": -3,
      "y": 10,
      "z": -13,
      "name": "Rock_Basalt"
    },
    {
      "x": -3,
      "y": 0,
      "z": -12,
      "name": "Rock_Basalt_Cobble"
    },
    {
      "x": -3,
      "y": 1,
      "z": -12,
      "name": "Empty"
    },
    {
      "x": -3,
      "y": 2,
      "z": -12,
      "name": "Empty"
    },
    {
      "x": -3,
      "y": 3,
      "z": -12,
      "name": "Empty"
    },
    {
      "x": -3,
      "y": 4,
      "z": -12,
      "name": "Empty"
    },
    {
      "x": -3,
      "y": 5,
      "z": -12,
      "name": "Rock_Basalt"
    },
    {
      "x": -3,
      "y": 6,
      "z": -12,
      "name": "Empty"
    },
    {
      "x": -3,
      "y": 7,
      "z": -12,
      "name": "Empty"
    },
    {
      "x": -3,
      "y": 8,
      "z": -12,
      "name": "Empty"
    },
    {
      "x": -3,
      "y": 10,
      "z": -12,
      "name": "Rock_Basalt"
    },
    {
      "x": -3,
      "y": 0,
      "z": -11,
      "name": "Rock_Basalt_Cobble"
    },
    {
      "x": -3,
      "y": 1,
      "z": -11,
      "name": "Empty"
    },
    {
      "x": -3,
      "y": 2,
      "z": -11,
      "name": "Empty"
    },
    {
      "x": -3,
      "y": 3,
      "z": -11,
      "name": "Empty"
    },
    {
      "x": -3,
      "y": 4,
      "z": -11,
      "name": "Empty"
    },
    {
      "x": -3,
      "y": 5,
      "z": -11,
      "name": "Rock_Basalt"
    },
    {
      "x": -3,
      "y": 6,
      "z": -11,
      "name": "Empty"
    },
    {
      "x": -3,
      "y": 7,
      "z": -11,
      "name": "Empty"
    },
    {
      "x": -3,
      "y": 8,
      "z": -11,
      "name": "Empty"
    },
    {
      "x": -3,
      "y": 10,
      "z": -11,
      "name": "Rock_Basalt"
    },
    {
      "x": -3,
      "y": 0,
      "z": -10,
      "name": "Rock_Basalt_Cobble"
    },
    {
      "x": -3,
      "y": 1,
      "z": -10,
      "name": "Empty"
    },
    {
      "x": -3,
      "y": 2,
      "z": -10,
      "name": "Empty"
    },
    {
      "x": -3,
      "y": 3,
      "z": -10,
      "name": "Empty"
    },
    {
      "x": -3,
      "y": 4,
      "z": -10,
      "name": "Empty"
    },
    {
      "x": -3,
      "y": 5,
      "z": -10,
      "name": "Rock_Basalt"
    },
    {
      "x": -3,
      "y": 6,
      "z": -10,
      "name": "Empty"
    },
    {
      "x": -3,
      "y": 7,
      "z": -10,
      "name": "Empty"
    },
    {
      "x": -3,
      "y": 8,
      "z": -10,
      "name": "Empty"
    },
    {
      "x": -3,
      "y": 10,
      "z": -10,
      "name": "Rock_Basalt"
    },
    {
      "x": -3,
      "y": 0,
      "z": -9,
      "name": "Rock_Basalt_Cobble"
    },
    {
      "x": -3,
      "y": 1,
      "z": -9,
      "name": "Empty"
    },
    {
      "x": -3,
      "y": 2,
      "z": -9,
      "name": "Empty"
    },
    {
      "x": -3,
      "y": 3,
      "z": -9,
      "name": "Empty"
    },
    {
      "x": -3,
      "y": 4,
      "z": -9,
      "name": "Empty"
    },
    {
      "x": -3,
      "y": 5,
      "z": -9,
      "name": "Rock_Basalt"
    },
    {
      "x": -3,
      "y": 6,
      "z": -9,
      "name": "Empty"
    },
    {
      "x": -3,
      "y": 7,
      "z": -9,
      "name": "Empty"
    },
    {
      "x": -3,
      "y": 8,
      "z": -9,
      "name": "Empty"
    },
    {
      "x": -3,
      "y": 10,
      "z": -9,
      "name": "Rock_Basalt"
    },
    {
      "x": -3,
      "y": 0,
      "z": -8,
      "name": "Rock_Basalt_Cobble"
    },
    {
      "x": -3,
      "y": 1,
      "z": -8,
      "name": "Empty"
    },
    {
      "x": -3,
      "y": 2,
      "z": -8,
      "name": "Empty"
    },
    {
      "x": -3,
      "y": 3,
      "z": -8,
      "name": "Empty"
    },
    {
      "x": -3,
      "y": 4,
      "z": -8,
      "name": "Empty"
    },
    {
      "x": -3,
      "y": 5,
      "z": -8,
      "name": "Rock_Basalt"
    },
    {
      "x": -3,
      "y": 6,
      "z": -8,
      "name": "Furniture_Ancient_Shelf",
      "rotation": 2
    },
    {
      "x": -3,
      "y": 7,
      "z": -8,
      "name": "Furniture_Crude_Candle"
    },
    {
      "x": -3,
      "y": 8,
      "z": -8,
      "name": "Empty"
    },
    {
      "x": -3,
      "y": 10,
      "z": -8,
      "name": "Rock_Basalt"
    },
    {
      "x": -3,
      "y": 0,
      "z": -7,
      "name": "Rock_Basalt"
    },
    {
      "x": -3,
      "y": 1,
      "z": -7,
      "name": "Rock_Basalt"
    },
    {
      "x": -3,
      "y": 2,
      "z": -7,
      "name": "Rock_Basalt"
    },
    {
      "x": -3,
      "y": 3,
      "z": -7,
      "name": "Rock_Basalt"
    },
    {
      "x": -3,
      "y": 4,
      "z": -7,
      "name": "Rock_Basalt"
    },
    {
      "x": -3,
      "y": 5,
      "z": -7,
      "name": "Rock_Basalt"
    },
    {
      "x": -3,
      "y": 6,
      "z": -7,
      "name": "Rock_Basalt"
    },
    {
      "x": -3,
      "y": 7,
      "z": -7,
      "name": "Rock_Basalt"
    },
    {
      "x": -3,
      "y": 8,
      "z": -7,
      "name": "Rock_Basalt"
    },
    {
      "x": -3,
      "y": 9,
      "z": -7,
      "name": "Rock_Basalt"
    },
    {
      "x": -3,
      "y": 10,
      "z": -7,
      "name": "Rock_Basalt"
    },
    {
      "x": -3,
      "y": 0,
      "z": -6,
      "name": "Rock_Basalt_Cobble"
    },
    {
      "x": -3,
      "y": 1,
      "z": -6,
      "name": "Empty"
    },
    {
      "x": -3,
      "y": 2,
      "z": -6,
      "name": "Empty"
    },
    {
      "x": -3,
      "y": 3,
      "z": -6,
      "name": "Empty"
    },
    {
      "x": -3,
      "y": 4,
      "z": -6,
      "name": "Empty"
    },
    {
      "x": -3,
      "y": 5,
      "z": -6,
      "name": "Empty"
    },
    {
      "x": -3,
      "y": 6,
      "z": -6,
      "name": "Empty"
    },
    {
      "x": -3,
      "y": 7,
      "z": -6,
      "name": "Rock_Basalt"
    },
    {
      "x": -3,
      "y": 8,
      "z": -6,
      "name": "Rock_Basalt"
    },
    {
      "x": -3,
      "y": 9,
      "z": -6,
      "name": "Rock_Basalt"
    },
    {
      "x": -3,
      "y": 10,
      "z": -6,
      "name": "Rock_Basalt"
    },
    {
      "x": -3,
      "y": 0,
      "z": -5,
      "name": "Rock_Basalt_Cobble"
    },
    {
      "x": -3,
      "y": 1,
      "z": -5,
      "name": "Empty"
    },
    {
      "x": -3,
      "y": 2,
      "z": -5,
      "name": "Empty"
    },
    {
      "x": -3,
      "y": 3,
      "z": -5,
      "name": "Empty"
    },
    {
      "x": -3,
      "y": 4,
      "z": -5,
      "name": "Empty"
    },
    {
      "x": -3,
      "y": 5,
      "z": -5,
      "name": "Empty"
    },
    {
      "x": -3,
      "y": 6,
      "z": -5,
      "name": "Empty"
    },
    {
      "x": -3,
      "y": 7,
      "z": -5,
      "name": "Empty"
    },
    {
      "x": -3,
      "y": 8,
      "z": -5,
      "name": "Rock_Basalt"
    },
    {
      "x": -3,
      "y": 0,
      "z": -4,
      "name": "Rock_Basalt"
    },
    {
      "x": -3,
      "y": 1,
      "z": -4,
      "name": "Empty"
    },
    {
      "x": -3,
      "y": 2,
      "z": -4,
      "name": "Empty"
    },
    {
      "x": -3,
      "y": 3,
      "z": -4,
      "name": "Empty"
    },
    {
      "x": -3,
      "y": 4,
      "z": -4,
      "name": "Empty"
    },
    {
      "x": -3,
      "y": 5,
      "z": -4,
      "name": "Wood_Fir_Trunk",
      "rotation": 5
    },
    {
      "x": -3,
      "y": 6,
      "z": -4,
      "name": "Empty"
    },
    {
      "x": -3,
      "y": 7,
      "z": -4,
      "name": "Empty"
    },
    {
      "x": -3,
      "y": 8,
      "z": -4,
      "name": "Rock_Basalt"
    },
    {
      "x": -3,
      "y": 0,
      "z": -3,
      "name": "Rock_Basalt_Cobble"
    },
    {
      "x": -3,
      "y": 1,
      "z": -3,
      "name": "Empty"
    },
    {
      "x": -3,
      "y": 2,
      "z": -3,
      "name": "Empty"
    },
    {
      "x": -3,
      "y": 3,
      "z": -3,
      "name": "Empty"
    },
    {
      "x": -3,
      "y": 4,
      "z": -3,
      "name": "Empty"
    },
    {
      "x": -3,
      "y": 5,
      "z": -3,
      "name": "Cloth_Roof_Hide_Vertical",
      "rotation": 3
    },
    {
      "x": -3,
      "y": 6,
      "z": -3,
      "name": "Empty"
    },
    {
      "x": -3,
      "y": 7,
      "z": -3,
      "name": "Empty"
    },
    {
      "x": -3,
      "y": 8,
      "z": -3,
      "name": "Rock_Basalt"
    },
    {
      "x": -3,
      "y": 0,
      "z": -2,
      "name": "Rock_Basalt_Cobble"
    },
    {
      "x": -3,
      "y": 1,
      "z": -2,
      "name": "Empty"
    },
    {
      "x": -3,
      "y": 2,
      "z": -2,
      "name": "Empty"
    },
    {
      "x": -3,
      "y": 3,
      "z": -2,
      "name": "Cloth_Roof_Hide_Flap",
      "rotation": 3
    },
    {
      "x": -3,
      "y": 4,
      "z": -2,
      "name": "Cloth_Roof_Hide_Vertical",
      "rotation": 3
    },
    {
      "x": -3,
      "y": 5,
      "z": -2,
      "name": "Cloth_Roof_Hide_Vertical",
      "rotation": 3
    },
    {
      "x": -3,
      "y": 6,
      "z": -2,
      "name": "Empty"
    },
    {
      "x": -3,
      "y": 7,
      "z": -2,
      "name": "Empty"
    },
    {
      "x": -3,
      "y": 8,
      "z": -2,
      "name": "Rock_Basalt"
    },
    {
      "x": -3,
      "y": 0,
      "z": -1,
      "name": "Rock_Basalt_Cobble"
    },
    {
      "x": -3,
      "y": 1,
      "z": -1,
      "name": "Empty"
    },
    {
      "x": -3,
      "y": 2,
      "z": -1,
      "name": "Empty"
    },
    {
      "x": -3,
      "y": 3,
      "z": -1,
      "name": "Empty"
    },
    {
      "x": -3,
      "y": 4,
      "z": -1,
      "name": "Cloth_Roof_Hide_Flap",
      "rotation": 3
    },
    {
      "x": -3,
      "y": 5,
      "z": -1,
      "name": "Cloth_Roof_Hide_Vertical",
      "rotation": 3
    },
    {
      "x": -3,
      "y": 6,
      "z": -1,
      "name": "Empty"
    },
    {
      "x": -3,
      "y": 7,
      "z": -1,
      "name": "Empty"
    },
    {
      "x": -3,
      "y": 8,
      "z": -1,
      "name": "Rock_Basalt"
    },
    {
      "x": -3,
      "y": 0,
      "z": 0,
      "name": "Rock_Basalt"
    },
    {
      "x": -3,
      "y": 1,
      "z": 0,
      "name": "Rock_Basalt"
    },
    {
      "x": -3,
      "y": 2,
      "z": 0,
      "name": "Rock_Basalt"
    },
    {
      "x": -3,
      "y": 3,
      "z": 0,
      "name": "Rock_Basalt"
    },
    {
      "x": -3,
      "y": 4,
      "z": 0,
      "name": "Rock_Basalt"
    },
    {
      "x": -3,
      "y": 5,
      "z": 0,
      "name": "Rock_Basalt"
    },
    {
      "x": -3,
      "y": 6,
      "z": 0,
      "name": "Rock_Basalt"
    },
    {
      "x": -3,
      "y": 7,
      "z": 0,
      "name": "Rock_Basalt"
    },
    {
      "x": -3,
      "y": 8,
      "z": 0,
      "name": "Rock_Basalt"
    },
    {
      "x": -2,
      "y": 0,
      "z": -16,
      "name": "Rock_Basalt"
    },
    {
      "x": -2,
      "y": 1,
      "z": -16,
      "name": "Rock_Basalt"
    },
    {
      "x": -2,
      "y": 2,
      "z": -16,
      "name": "Rock_Basalt"
    },
    {
      "x": -2,
      "y": 3,
      "z": -16,
      "name": "Rock_Basalt"
    },
    {
      "x": -2,
      "y": 4,
      "z": -16,
      "name": "Rock_Basalt"
    },
    {
      "x": -2,
      "y": 5,
      "z": -16,
      "name": "Rock_Basalt"
    },
    {
      "x": -2,
      "y": 6,
      "z": -16,
      "name": "Rock_Basalt"
    },
    {
      "x": -2,
      "y": 7,
      "z": -16,
      "name": "Rock_Basalt"
    },
    {
      "x": -2,
      "y": 8,
      "z": -16,
      "name": "Rock_Basalt"
    },
    {
      "x": -2,
      "y": 9,
      "z": -16,
      "name": "Rock_Basalt"
    },
    {
      "x": -2,
      "y": 10,
      "z": -16,
      "name": "Rock_Basalt"
    },
    {
      "x": -2,
      "y": 11,
      "z": -16,
      "name": "Rock_Basalt"
    },
    {
      "x": -2,
      "y": 0,
      "z": -15,
      "name": "Rock_Basalt_Cobble"
    },
    {
      "x": -2,
      "y": 1,
      "z": -15,
      "name": "Rock_Basalt"
    },
    {
      "x": -2,
      "y": 2,
      "z": -15,
      "name": "Rock_Basalt"
    },
    {
      "x": -2,
      "y": 3,
      "z": -15,
      "name": "Rock_Basalt"
    },
    {
      "x": -2,
      "y": 4,
      "z": -15,
      "name": "Rock_Basalt"
    },
    {
      "x": -2,
      "y": 5,
      "z": -15,
      "name": "Rock_Basalt"
    },
    {
      "x": -2,
      "y": 6,
      "z": -15,
      "name": "Empty"
    },
    {
      "x": -2,
      "y": 7,
      "z": -15,
      "name": "Empty"
    },
    {
      "x": -2,
      "y": 8,
      "z": -15,
      "name": "Empty"
    },
    {
      "x": -2,
      "y": 9,
      "z": -15,
      "name": "Empty"
    },
    {
      "x": -2,
      "y": 10,
      "z": -15,
      "name": "Rock_Basalt"
    },
    {
      "x": -2,
      "y": 11,
      "z": -15,
      "name": "Rock_Basalt_Cobble"
    },
    {
      "x": -2,
      "y": 0,
      "z": -14,
      "name": "Rock_Basalt_Cobble"
    },
    {
      "x": -2,
      "y": 1,
      "z": -14,
      "name": "Empty"
    },
    {
      "x": -2,
      "y": 2,
      "z": -14,
      "name": "Empty"
    },
    {
      "x": -2,
      "y": 3,
      "z": -14,
      "name": "Empty"
    },
    {
      "x": -2,
      "y": 4,
      "z": -14,
      "name": "Empty"
    },
    {
      "x": -2,
      "y": 5,
      "z": -14,
      "name": "Rock_Basalt"
    },
    {
      "x": -2,
      "y": 6,
      "z": -14,
      "name": "Empty"
    },
    {
      "x": -2,
      "y": 7,
      "z": -14,
      "name": "Empty"
    },
    {
      "x": -2,
      "y": 8,
      "z": -14,
      "name": "Empty"
    },
    {
      "x": -2,
      "y": 9,
      "z": -14,
      "name": "Empty"
    },
    {
      "x": -2,
      "y": 10,
      "z": -14,
      "name": "Rock_Basalt"
    },
    {
      "x": -2,
      "y": 11,
      "z": -14,
      "name": "Rock_Basalt_Cobble"
    },
    {
      "x": -2,
      "y": 0,
      "z": -13,
      "name": "Rock_Basalt_Cobble"
    },
    {
      "x": -2,
      "y": 1,
      "z": -13,
      "name": "Empty"
    },
    {
      "x": -2,
      "y": 2,
      "z": -13,
      "name": "Empty"
    },
    {
      "x": -2,
      "y": 3,
      "z": -13,
      "name": "Empty"
    },
    {
      "x": -2,
      "y": 4,
      "z": -13,
      "name": "Empty"
    },
    {
      "x": -2,
      "y": 5,
      "z": -13,
      "name": "Rock_Basalt"
    },
    {
      "x": -2,
      "y": 6,
      "z": -13,
      "name": "*Rock_Shale_Cobble_Wall_State_Definitions_Corner",
      "rotation": 1
    },
    {
      "x": -2,
      "y": 7,
      "z": -13,
      "name": "Rock_Shale_Brick_Beam"
    },
    {
      "x": -2,
      "y": 8,
      "z": -13,
      "name": "Rock_Shale_Brick_Beam"
    },
    {
      "x": -2,
      "y": 9,
      "z": -13,
      "name": "Rock_Shale_Brick_Beam"
    },
    {
      "x": -2,
      "y": 10,
      "z": -13,
      "name": "Rock_Basalt"
    },
    {
      "x": -2,
      "y": 11,
      "z": -13,
      "name": "Rock_Basalt_Cobble"
    },
    {
      "x": -2,
      "y": 0,
      "z": -12,
      "name": "Rock_Basalt_Cobble"
    },
    {
      "x": -2,
      "y": 1,
      "z": -12,
      "name": "Empty"
    },
    {
      "x": -2,
      "y": 2,
      "z": -12,
      "name": "Empty"
    },
    {
      "x": -2,
      "y": 3,
      "z": -12,
      "name": "Empty"
    },
    {
      "x": -2,
      "y": 4,
      "z": -12,
      "name": "Empty"
    },
    {
      "x": -2,
      "y": 5,
      "z": -12,
      "name": "Rock_Basalt"
    },
    {
      "x": -2,
      "y": 6,
      "z": -12,
      "name": "Rock_Shale_Cobble_Wall",
      "rotation": 3
    },
    {
      "x": -2,
      "y": 7,
      "z": -12,
      "name": "Empty"
    },
    {
      "x": -2,
      "y": 8,
      "z": -12,
      "name": "Empty"
    },
    {
      "x": -2,
      "y": 9,
      "z": -12,
      "name": "Empty"
    },
    {
      "x": -2,
      "y": 10,
      "z": -12,
      "name": "Rock_Basalt"
    },
    {
      "x": -2,
      "y": 11,
      "z": -12,
      "name": "Rock_Basalt_Cobble"
    },
    {
      "x": -2,
      "y": 0,
      "z": -11,
      "name": "Rock_Basalt_Cobble"
    },
    {
      "x": -2,
      "y": 1,
      "z": -11,
      "name": "Empty"
    },
    {
      "x": -2,
      "y": 2,
      "z": -11,
      "name": "Empty"
    },
    {
      "x": -2,
      "y": 3,
      "z": -11,
      "name": "Empty"
    },
    {
      "x": -2,
      "y": 4,
      "z": -11,
      "name": "Empty"
    },
    {
      "x": -2,
      "y": 5,
      "z": -11,
      "name": "Rock_Basalt"
    },
    {
      "x": -2,
      "y": 6,
      "z": -11,
      "name": "Rock_Shale_Cobble_Wall",
      "rotation": 3
    },
    {
      "x": -2,
      "y": 7,
      "z": -11,
      "name": "Empty"
    },
    {
      "x": -2,
      "y": 8,
      "z": -11,
      "name": "Empty"
    },
    {
      "x": -2,
      "y": 9,
      "z": -11,
      "name": "Empty"
    },
    {
      "x": -2,
      "y": 10,
      "z": -11,
      "name": "Rock_Basalt"
    },
    {
      "x": -2,
      "y": 11,
      "z": -11,
      "name": "Rock_Basalt_Cobble"
    },
    {
      "x": -2,
      "y": 0,
      "z": -10,
      "name": "Rock_Basalt_Cobble"
    },
    {
      "x": -2,
      "y": 1,
      "z": -10,
      "name": "Empty"
    },
    {
      "x": -2,
      "y": 2,
      "z": -10,
      "name": "Empty"
    },
    {
      "x": -2,
      "y": 3,
      "z": -10,
      "name": "Empty"
    },
    {
      "x": -2,
      "y": 4,
      "z": -10,
      "name": "Empty"
    },
    {
      "x": -2,
      "y": 5,
      "z": -10,
      "name": "Rock_Basalt"
    },
    {
      "x": -2,
      "y": 6,
      "z": -10,
      "name": "Rock_Shale_Cobble_Wall",
      "rotation": 3
    },
    {
      "x": -2,
      "y": 7,
      "z": -10,
      "name": "Empty"
    },
    {
      "x": -2,
      "y": 8,
      "z": -10,
      "name": "Empty"
    },
    {
      "x": -2,
      "y": 9,
      "z": -10,
      "name": "Empty"
    },
    {
      "x": -2,
      "y": 10,
      "z": -10,
      "name": "Rock_Basalt"
    },
    {
      "x": -2,
      "y": 11,
      "z": -10,
      "name": "Rock_Basalt_Cobble"
    },
    {
      "x": -2,
      "y": 0,
      "z": -9,
      "name": "Rock_Basalt_Cobble"
    },
    {
      "x": -2,
      "y": 1,
      "z": -9,
      "name": "Empty"
    },
    {
      "x": -2,
      "y": 2,
      "z": -9,
      "name": "Empty"
    },
    {
      "x": -2,
      "y": 3,
      "z": -9,
      "name": "Empty"
    },
    {
      "x": -2,
      "y": 4,
      "z": -9,
      "name": "Empty"
    },
    {
      "x": -2,
      "y": 5,
      "z": -9,
      "name": "Rock_Basalt"
    },
    {
      "x": -2,
      "y": 6,
      "z": -9,
      "name": "Rock_Shale_Cobble_Wall",
      "rotation": 3
    },
    {
      "x": -2,
      "y": 7,
      "z": -9,
      "name": "Empty"
    },
    {
      "x": -2,
      "y": 8,
      "z": -9,
      "name": "Empty"
    },
    {
      "x": -2,
      "y": 9,
      "z": -9,
      "name": "Empty"
    },
    {
      "x": -2,
      "y": 10,
      "z": -9,
      "name": "Rock_Basalt"
    },
    {
      "x": -2,
      "y": 11,
      "z": -9,
      "name": "Rock_Basalt_Cobble"
    },
    {
      "x": -2,
      "y": 0,
      "z": -8,
      "name": "Rock_Basalt_Cobble"
    },
    {
      "x": -2,
      "y": 1,
      "z": -8,
      "name": "Empty"
    },
    {
      "x": -2,
      "y": 2,
      "z": -8,
      "name": "Empty"
    },
    {
      "x": -2,
      "y": 3,
      "z": -8,
      "name": "Empty"
    },
    {
      "x": -2,
      "y": 4,
      "z": -8,
      "name": "Empty"
    },
    {
      "x": -2,
      "y": 5,
      "z": -8,
      "name": "Rock_Basalt"
    },
    {
      "x": -2,
      "y": 6,
      "z": -8,
      "name": "Rock_Shale_Cobble_Wall",
      "rotation": 3
    },
    {
      "x": -2,
      "y": 7,
      "z": -8,
      "name": "Rock_Shale_Brick_Beam"
    },
    {
      "x": -2,
      "y": 8,
      "z": -8,
      "name": "Rock_Shale_Brick_Beam"
    },
    {
      "x": -2,
      "y": 9,
      "z": -8,
      "name": "Rock_Shale_Brick_Beam"
    },
    {
      "x": -2,
      "y": 10,
      "z": -8,
      "name": "Rock_Basalt"
    },
    {
      "x": -2,
      "y": 11,
      "z": -8,
      "name": "Rock_Basalt_Cobble"
    },
    {
      "x": -2,
      "y": 0,
      "z": -7,
      "name": "Rock_Basalt"
    },
    {
      "x": -2,
      "y": 1,
      "z": -7,
      "name": "Rock_Basalt"
    },
    {
      "x": -2,
      "y": 2,
      "z": -7,
      "name": "Rock_Basalt"
    },
    {
      "x": -2,
      "y": 3,
      "z": -7,
      "name": "Rock_Basalt"
    },
    {
      "x": -2,
      "y": 4,
      "z": -7,
      "name": "Rock_Basalt"
    },
    {
      "x": -2,
      "y": 5,
      "z": -7,
      "name": "Rock_Basalt"
    },
    {
      "x": -2,
      "y": 6,
      "z": -7,
      "name": "Rock_Shale"
    },
    {
      "x": -2,
      "y": 7,
      "z": -7,
      "name": "Rock_Shale"
    },
    {
      "x": -2,
      "y": 8,
      "z": -7,
      "name": "Rock_Shale"
    },
    {
      "x": -2,
      "y": 9,
      "z": -7,
      "name": "Rock_Shale"
    },
    {
      "x": -2,
      "y": 10,
      "z": -7,
      "name": "Rock_Basalt"
    },
    {
      "x": -2,
      "y": 11,
      "z": -7,
      "name": "Rock_Basalt"
    },
    {
      "x": -2,
      "y": 0,
      "z": -6,
      "name": "Rock_Basalt_Cobble"
    },
    {
      "x": -2,
      "y": 1,
      "z": -6,
      "name": "Wood_Deadwood_Beam"
    },
    {
      "x": -2,
      "y": 2,
      "z": -6,
      "name": "Furniture_Ancient_Torch"
    },
    {
      "x": -2,
      "y": 3,
      "z": -6,
      "name": "Empty"
    },
    {
      "x": -2,
      "y": 4,
      "z": -6,
      "name": "Empty"
    },
    {
      "x": -2,
      "y": 5,
      "z": -6,
      "name": "Wood_Fir_Trunk",
      "rotation": 4
    },
    {
      "x": -2,
      "y": 6,
      "z": -6,
      "name": "Wood_Fir_Branch_Long"
    },
    {
      "x": -2,
      "y": 7,
      "z": -6,
      "name": "Wood_Fir_Branch_Long"
    },
    {
      "x": -2,
      "y": 8,
      "z": -6,
      "name": "Wood_Fir_Branch_Long"
    },
    {
      "x": -2,
      "y": 9,
      "z": -6,
      "name": "Rock_Basalt"
    },
    {
      "x": -2,
      "y": 10,
      "z": -6,
      "name": "Rock_Basalt"
    },
    {
      "x": -2,
      "y": 0,
      "z": -5,
      "name": "Rock_Basalt_Cobble"
    },
    {
      "x": -2,
      "y": 1,
      "z": -5,
      "name": "Empty"
    },
    {
      "x": -2,
      "y": 2,
      "z": -5,
      "name": "Empty"
    },
    {
      "x": -2,
      "y": 3,
      "z": -5,
      "name": "Empty"
    },
    {
      "x": -2,
      "y": 4,
      "z": -5,
      "name": "Empty"
    },
    {
      "x": -2,
      "y": 5,
      "z": -5,
      "name": "Wood_Fir_Trunk",
      "rotation": 4
    },
    {
      "x": -2,
      "y": 6,
      "z": -5,
      "name": "Empty"
    },
    {
      "x": -2,
      "y": 7,
      "z": -5,
      "name": "Empty"
    },
    {
      "x": -2,
      "y": 8,
      "z": -5,
      "name": "Empty"
    },
    {
      "x": -2,
      "y": 9,
      "z": -5,
      "name": "Rock_Basalt"
    },
    {
      "x": -2,
      "y": 0,
      "z": -4,
      "name": "Rock_Basalt_Cobble"
    },
    {
      "x": -2,
      "y": 1,
      "z": -4,
      "name": "Empty"
    },
    {
      "x": -2,
      "y": 2,
      "z": -4,
      "name": "Empty"
    },
    {
      "x": -2,
      "y": 3,
      "z": -4,
      "name": "Empty"
    },
    {
      "x": -2,
      "y": 4,
      "z": -4,
      "name": "Empty"
    },
    {
      "x": -2,
      "y": 5,
      "z": -4,
      "name": "Wood_Fir_Trunk",
      "rotation": 4
    },
    {
      "x": -2,
      "y": 6,
      "z": -4,
      "name": "Wood_Fir_Branch_Long"
    },
    {
      "x": -2,
      "y": 7,
      "z": -4,
      "name": "Wood_Fir_Branch_Long"
    },
    {
      "x": -2,
      "y": 8,
      "z": -4,
      "name": "Wood_Fir_Branch_Long"
    },
    {
      "x": -2,
      "y": 9,
      "z": -4,
      "name": "Rock_Basalt"
    },
    {
      "x": -2,
      "y": 0,
      "z": -3,
      "name": "Rock_Basalt_Cobble"
    },
    {
      "x": -2,
      "y": 1,
      "z": -3,
      "name": "Empty"
    },
    {
      "x": -2,
      "y": 2,
      "z": -3,
      "name": "Empty"
    },
    {
      "x": -2,
      "y": 3,
      "z": -3,
      "name": "Empty"
    },
    {
      "x": -2,
      "y": 4,
      "z": -3,
      "name": "Empty"
    },
    {
      "x": -2,
      "y": 5,
      "z": -3,
      "name": "Wood_Fir_Trunk",
      "rotation": 4
    },
    {
      "x": -2,
      "y": 6,
      "z": -3,
      "name": "Cloth_Roof_Hide_Flat"
    },
    {
      "x": -2,
      "y": 7,
      "z": -3,
      "name": "Empty"
    },
    {
      "x": -2,
      "y": 8,
      "z": -3,
      "name": "Empty"
    },
    {
      "x": -2,
      "y": 9,
      "z": -3,
      "name": "Rock_Basalt"
    },
    {
      "x": -2,
      "y": 0,
      "z": -2,
      "name": "Rock_Basalt_Cobble"
    },
    {
      "x": -2,
      "y": 1,
      "z": -2,
      "name": "Empty"
    },
    {
      "x": -2,
      "y": 2,
      "z": -2,
      "name": "Empty"
    },
    {
      "x": -2,
      "y": 3,
      "z": -2,
      "name": "Empty"
    },
    {
      "x": -2,
      "y": 4,
      "z": -2,
      "name": "Empty"
    },
    {
      "x": -2,
      "y": 5,
      "z": -2,
      "name": "Wood_Fir_Trunk",
      "rotation": 4
    },
    {
      "x": -2,
      "y": 6,
      "z": -2,
      "name": "Cloth_Roof_Hide_Flat"
    },
    {
      "x": -2,
      "y": 7,
      "z": -2,
      "name": "Empty"
    },
    {
      "x": -2,
      "y": 8,
      "z": -2,
      "name": "Empty"
    },
    {
      "x": -2,
      "y": 9,
      "z": -2,
      "name": "Rock_Basalt"
    },
    {
      "x": -2,
      "y": 0,
      "z": -1,
      "name": "Rock_Basalt_Cobble"
    },
    {
      "x": -2,
      "y": 1,
      "z": -1,
      "name": "Empty"
    },
    {
      "x": -2,
      "y": 2,
      "z": -1,
      "name": "Empty"
    },
    {
      "x": -2,
      "y": 3,
      "z": -1,
      "name": "Empty"
    },
    {
      "x": -2,
      "y": 4,
      "z": -1,
      "name": "Empty"
    },
    {
      "x": -2,
      "y": 5,
      "z": -1,
      "name": "Wood_Fir_Trunk",
      "rotation": 4
    },
    {
      "x": -2,
      "y": 6,
      "z": -1,
      "name": "Wood_Fir_Branch_Long"
    },
    {
      "x": -2,
      "y": 7,
      "z": -1,
      "name": "Wood_Fir_Branch_Long"
    },
    {
      "x": -2,
      "y": 8,
      "z": -1,
      "name": "Wood_Fir_Branch_Long"
    },
    {
      "x": -2,
      "y": 9,
      "z": -1,
      "name": "Rock_Basalt"
    },
    {
      "x": -2,
      "y": 0,
      "z": 0,
      "name": "Rock_Basalt"
    },
    {
      "x": -2,
      "y": 1,
      "z": 0,
      "name": "Rock_Basalt"
    },
    {
      "x": -2,
      "y": 2,
      "z": 0,
      "name": "Rock_Basalt"
    },
    {
      "x": -2,
      "y": 3,
      "z": 0,
      "name": "Rock_Basalt"
    },
    {
      "x": -2,
      "y": 4,
      "z": 0,
      "name": "Rock_Basalt"
    },
    {
      "x": -2,
      "y": 5,
      "z": 0,
      "name": "Rock_Basalt"
    },
    {
      "x": -2,
      "y": 6,
      "z": 0,
      "name": "Rock_Basalt"
    },
    {
      "x": -2,
      "y": 7,
      "z": 0,
      "name": "Rock_Basalt"
    },
    {
      "x": -2,
      "y": 8,
      "z": 0,
      "name": "Rock_Basalt"
    },
    {
      "x": -2,
      "y": 9,
      "z": 0,
      "name": "Rock_Basalt"
    },
    {
      "x": -1,
      "y": 0,
      "z": -16,
      "name": "Rock_Basalt_Cobble"
    },
    {
      "x": -1,
      "y": 1,
      "z": -16,
      "name": "Empty"
    },
    {
      "x": -1,
      "y": 2,
      "z": -16,
      "name": "Empty"
    },
    {
      "x": -1,
      "y": 3,
      "z": -16,
      "name": "Empty"
    },
    {
      "x": -1,
      "y": 4,
      "z": -16,
      "name": "Empty"
    },
    {
      "x": -1,
      "y": 5,
      "z": -16,
      "name": "Rock_Basalt"
    },
    {
      "x": -1,
      "y": 6,
      "z": -16,
      "name": "Rock_Basalt"
    },
    {
      "x": -1,
      "y": 7,
      "z": -16,
      "name": "Rock_Basalt"
    },
    {
      "x": -1,
      "y": 8,
      "z": -16,
      "name": "Rock_Basalt"
    },
    {
      "x": -1,
      "y": 9,
      "z": -16,
      "name": "Rock_Basalt"
    },
    {
      "x": -1,
      "y": 10,
      "z": -16,
      "name": "Rock_Basalt"
    },
    {
      "x": -1,
      "y": 11,
      "z": -16,
      "name": "Rock_Basalt"
    },
    {
      "x": -1,
      "y": 12,
      "z": -16,
      "name": "Rock_Basalt"
    },
    {
      "x": -1,
      "y": 0,
      "z": -15,
      "name": "Rock_Basalt_Cobble"
    },
    {
      "x": -1,
      "y": 1,
      "z": -15,
      "name": "Empty"
    },
    {
      "x": -1,
      "y": 2,
      "z": -15,
      "name": "Empty"
    },
    {
      "x": -1,
      "y": 3,
      "z": -15,
      "name": "Empty"
    },
    {
      "x": -1,
      "y": 4,
      "z": -15,
      "name": "Empty"
    },
    {
      "x": -1,
      "y": 5,
      "z": -15,
      "name": "Wood_Deadwood_Planks_Half",
      "rotation": 8
    },
    {
      "x": -1,
      "y": 6,
      "z": -15,
      "name": "Empty"
    },
    {
      "x": -1,
      "y": 7,
      "z": -15,
      "name": "Empty"
    },
    {
      "x": -1,
      "y": 8,
      "z": -15,
      "name": "Empty"
    },
    {
      "x": -1,
      "y": 9,
      "z": -15,
      "name": "Empty"
    },
    {
      "x": -1,
      "y": 10,
      "z": -15,
      "name": "Rock_Basalt_Cobble_Half",
      "rotation": 5
    },
    {
      "x": -1,
      "y": 11,
      "z": -15,
      "name": "Rock_Basalt_Cobble"
    },
    {
      "x": -1,
      "y": 12,
      "z": -15,
      "name": "Rock_Basalt_Cobble"
    },
    {
      "x": -1,
      "y": 0,
      "z": -14,
      "name": "Rock_Basalt_Cobble"
    },
    {
      "x": -1,
      "y": 1,
      "z": -14,
      "name": "Empty"
    },
    {
      "x": -1,
      "y": 2,
      "z": -14,
      "name": "Empty"
    },
    {
      "x": -1,
      "y": 3,
      "z": -14,
      "name": "Empty"
    },
    {
      "x": -1,
      "y": 4,
      "z": -14,
      "name": "Empty"
    },
    {
      "x": -1,
      "y": 5,
      "z": -14,
      "name": "Wood_Deadwood_Planks_Half",
      "rotation": 8
    },
    {
      "x": -1,
      "y": 6,
      "z": -14,
      "name": "Empty"
    },
    {
      "x": -1,
      "y": 7,
      "z": -14,
      "name": "Empty"
    },
    {
      "x": -1,
      "y": 8,
      "z": -14,
      "name": "Empty"
    },
    {
      "x": -1,
      "y": 9,
      "z": -14,
      "name": "Empty"
    },
    {
      "x": -1,
      "y": 10,
      "z": -14,
      "name": "Rock_Basalt_Cobble_Half",
      "rotation": 5
    },
    {
      "x": -1,
      "y": 11,
      "z": -14,
      "name": "Rock_Basalt_Cobble"
    },
    {
      "x": -1,
      "y": 12,
      "z": -14,
      "name": "Rock_Basalt_Cobble"
    },
    {
      "x": -1,
      "y": 0,
      "z": -13,
      "name": "Rock_Basalt_Cobble"
    },
    {
      "x": -1,
      "y": 1,
      "z": -13,
      "name": "Empty"
    },
    {
      "x": -1,
      "y": 2,
      "z": -13,
      "name": "Empty"
    },
    {
      "x": -1,
      "y": 3,
      "z": -13,
      "name": "Empty"
    },
    {
      "x": -1,
      "y": 4,
      "z": -13,
      "name": "Empty"
    },
    {
      "x": -1,
      "y": 5,
      "z": -13,
      "name": "Rock_Shale_Cobble_Half",
      "rotation": 8
    },
    {
      "x": -1,
      "y": 6,
      "z": -13,
      "name": "Rock_Shale_Cobble_Wall"
    },
    {
      "x": -1,
      "y": 7,
      "z": -13,
      "name": "Empty"
    },
    {
      "x": -1,
      "y": 8,
      "z": -13,
      "name": "Empty"
    },
    {
      "x": -1,
      "y": 9,
      "z": -13,
      "name": "Empty"
    },
    {
      "x": -1,
      "y": 10,
      "z": -13,
      "name": "Rock_Basalt_Cobble_Half",
      "rotation": 5
    },
    {
      "x": -1,
      "y": 11,
      "z": -13,
      "name": "Rock_Basalt_Cobble"
    },
    {
      "x": -1,
      "y": 12,
      "z": -13,
      "name": "Rock_Basalt_Cobble"
    },
    {
      "x": -1,
      "y": 0,
      "z": -12,
      "name": "Rock_Basalt_Cobble"
    },
    {
      "x": -1,
      "y": 1,
      "z": -12,
      "name": "Empty"
    },
    {
      "x": -1,
      "y": 2,
      "z": -12,
      "name": "Empty"
    },
    {
      "x": -1,
      "y": 3,
      "z": -12,
      "name": "Empty"
    },
    {
      "x": -1,
      "y": 4,
      "z": -12,
      "name": "Empty"
    },
    {
      "x": -1,
      "y": 5,
      "z": -12,
      "name": "Empty"
    },
    {
      "x": -1,
      "y": 6,
      "z": -12,
      "name": "Empty"
    },
    {
      "x": -1,
      "y": 7,
      "z": -12,
      "name": "Empty"
    },
    {
      "x": -1,
      "y": 8,
      "z": -12,
      "name": "Empty"
    },
    {
