{
  "version": 8,
  "blockIdVersion": 8,
  "anchorX": 7,
  "anchorY": 10,
  "anchorZ": 10,
  "blocks": [
    {
      "x": 2,
      "y": 11,
      "z": 3,
      "name": "Wood_Burnt_Branch_Short",
      "rotation": 3
    },
    {
      "x": 3,
      "y": 10,
      "z": 3,
      "name": "Wood_Burnt_Trunk"
    },
    {
      "x": 3,
      "y": 11,
      "z": 3,
      "name": "Wood_Burnt_Trunk"
    },
    {
      "x": 3,
      "y": 14,
      "z": 5,
      "name": "Wood_Burnt_Branch_Corner",
      "rotation": 3
    },
    {
      "x": 4,
      "y": 11,
      "z": 3,
      "name": "Wood_Burnt_Trunk"
    },
    {
      "x": 4,
      "y": 11,
      "z": 4,
      "name": "Wood_Burnt_Trunk"
    },
    {
      "x": 4,
      "y": 12,
      "z": 4,
      "name": "Wood_Burnt_Trunk"
    },
    {
      "x": 4,
      "y": 13,
      "z": 4,
      "name": "Wood_Burnt_Trunk"
    },
    {
      "x": 4,
      "y": 14,
      "z": 4,
      "name": "Wood_Burnt_Trunk"
    },
    {
      "x": 4,
      "y": 13,
      "z": 5,
      "name": "Wood_Burnt_Trunk"
    },
    {
      "x": 4,
      "y": 14,
      "z": 5,
      "name": "Wood_Burnt_Trunk"
    },
    {
      "x": 4,
      "y": 15,
      "z": 5,
      "name": "Wood_Burnt_Trunk"
    },
    {
      "x": 4,
      "y": 16,
      "z": 5,
      "name": "Wood_Burnt_Trunk"
    },
    {
      "x": 4,
      "y": 15,
      "z": 6,
      "name": "Wood_Burnt_Trunk"
    },
    {
      "x": 4,
      "y": 16,
      "z": 6,
      "name": "Wood_Burnt_Trunk"
    },
    {
      "x": 4,
      "y": 17,
      "z": 6,
      "name": "Wood_Burnt_Trunk"
    },
    {
      "x": 4,
      "y": 18,
      "z": 6,
      "name": "Wood_Burnt_Trunk"
    },
    {
      "x": 4,
      "y": 18,
      "z": 7,
      "name": "Wood_Burnt_Trunk"
    },
    {
      "x": 4,
      "y": 19,
      "z": 7,
      "name": "Wood_Burnt_Trunk"
    },
    {
      "x": 4,
      "y": 20,
      "z": 7,
      "name": "Wood_Burnt_Trunk"
    },
    {
      "x": 4,
      "y": 19,
      "z": 8,
      "name": "Wood_Burnt_Trunk"
    },
    {
      "x": 5,
      "y": 13,
      "z": 4,
      "name": "Wood_Burnt_Trunk"
    },
    {
      "x": 5,
      "y": 12,
      "z": 5,
      "name": "Wood_Burnt_Trunk"
    },
    {
      "x": 5,
      "y": 13,
      "z": 5,
      "name": "Wood_Burnt_Trunk"
    },
    {
      "x": 5,
      "y": 14,
      "z": 5,
      "name": "Wood_Burnt_Trunk"
    },
    {
      "x": 5,
      "y": 15,
      "z": 5,
      "name": "Wood_Burnt_Trunk"
    },
    {
      "x": 5,
      "y": 16,
      "z": 5,
      "name": "Wood_Burnt_Trunk"
    },
    {
      "x": 5,
      "y": 14,
      "z": 6,
      "name": "Wood_Burnt_Trunk"
    },
    {
      "x": 5,
      "y": 15,
      "z": 6,
      "name": "Wood_Burnt_Trunk"
    },
    {
      "x": 5,
      "y": 16,
      "z": 6,
      "name": "Wood_Burnt_Trunk"
    },
    {
      "x": 5,
      "y": 17,
      "z": 6,
      "name": "Wood_Burnt_Trunk"
    },
    {
      "x": 5,
      "y": 18,
      "z": 6,
      "name": "Wood_Burnt_Trunk"
    },
    {
      "x": 5,
      "y": 16,
      "z": 7,
      "name": "Wood_Burnt_Trunk"
    },
    {
      "x": 5,
      "y": 17,
      "z": 7,
      "name": "Wood_Burnt_Trunk"
    },
    {
      "x": 5,
      "y": 18,
      "z": 7,
      "name": "Wood_Burnt_Trunk"
    },
    {
      "x": 5,
      "y": 19,
      "z": 7,
      "name": "Wood_Burnt_Trunk"
    },
    {
      "x": 5,
      "y": 20,
      "z": 7,
      "name": "Wood_Burnt_Trunk"
    },
    {
      "x": 5,
      "y": 18,
      "z": 8,
      "name": "Wood_Burnt_Trunk"
    },
    {
      "x": 5,
      "y": 19,
      "z": 8,
      "name": "Wood_Burnt_Trunk"
    },
    {
      "x": 5,
      "y": 20,
      "z": 8,
      "name": "Wood_Burnt_Trunk"
    },
    {
      "x": 5,
      "y": 21,
      "z": 8,
      "name": "Wood_Burnt_Trunk"
    },
    {
      "x": 5,
      "y": 22,
      "z": 8,
      "name": "Wood_Burnt_Trunk"
    },
    {
      "x": 5,
      "y": 20,
      "z": 9,
      "name": "Wood_Burnt_Trunk"
    },
    {
      "x": 5,
      "y": 21,
      "z": 9,
      "name": "Wood_Burnt_Trunk"
    },
    {
      "x": 5,
      "y": 22,
      "z": 9,
      "name": "Wood_Burnt_Trunk"
    },
    {
      "x": 5,
      "y": 23,
      "z": 9,
      "name": "Wood_Burnt_Trunk"
    },
    {
      "x": 5,
      "y": 8,
      "z": 10,
      "name": "Wood_Burnt_Trunk"
    },
    {
      "x": 5,
      "y": 9,
      "z": 10,
      "name": "Wood_Burnt_Trunk"
    },
    {
      "x": 5,
      "y": 10,
      "z": 10,
      "name": "Wood_Burnt_Trunk"
    },
    {
      "x": 5,
      "y": 11,
      "z": 10,
      "name": "Wood_Burnt_Trunk"
    },
    {
      "x": 5,
      "y": 22,
      "z": 10,
      "name": "Wood_Burnt_Trunk"
    },
    {
      "x": 5,
      "y": 23,
      "z": 10,
      "name": "Wood_Burnt_Trunk"
    },
    {
      "x": 5,
      "y": 7,
      "z": 11,
      "name": "Wood_Burnt_Trunk"
    },
    {
      "x": 5,
      "y": 8,
      "z": 11,
      "name": "Wood_Burnt_Trunk"
    },
    {
      "x": 6,
      "y": 17,
      "z": 6,
      "name": "Wood_Burnt_Branch_Long",
      "rotation": 5
    },
    {
      "x": 6,
      "y": 19,
      "z": 7,
      "name": "Wood_Burnt_Trunk"
    },
    {
      "x": 6,
      "y": 11,
      "z": 8,
      "name": "Wood_Burnt_Trunk"
    },
    {
      "x": 6,
      "y": 12,
      "z": 8,
      "name": "Wood_Burnt_Trunk"
    },
    {
      "x": 6,
      "y": 13,
      "z": 8,
      "name": "Wood_Burnt_Trunk"
    },
    {
      "x": 6,
      "y": 18,
      "z": 8,
      "name": "Wood_Burnt_Trunk"
    },
    {
      "x": 6,
      "y": 19,
      "z": 8,
      "name": "Wood_Burnt_Trunk"
    },
    {
      "x": 6,
      "y": 20,
      "z": 8,
      "name": "Wood_Burnt_Trunk"
    },
    {
      "x": 6,
      "y": 21,
      "z": 8,
      "name": "Wood_Burnt_Trunk"
    },
    {
      "x": 6,
      "y": 22,
      "z": 8,
      "name": "Wood_Burnt_Trunk"
    },
    {
      "x": 6,
      "y": 11,
      "z": 9,
      "name": "Wood_Burnt_Trunk"
    },
    {
      "x": 6,
      "y": 12,
      "z": 9,
      "name": "Wood_Burnt_Trunk"
    },
    {
      "x": 6,
      "y": 13,
      "z": 9,
      "name": "Wood_Burnt_Trunk"
    },
    {
      "x": 6,
      "y": 14,
      "z": 9,
      "name": "Wood_Burnt_Trunk"
    },
    {
      "x": 6,
      "y": 15,
      "z": 9,
      "name": "Wood_Burnt_Trunk"
    },
    {
      "x": 6,
      "y": 16,
      "z": 9,
      "name": "Wood_Burnt_Trunk"
    },
    {
      "x": 6,
      "y": 17,
      "z": 9,
      "name": "Wood_Burnt_Trunk"
    },
    {
      "x": 6,
      "y": 18,
      "z": 9,
      "name": "Wood_Burnt_Trunk"
    },
    {
      "x": 6,
      "y": 19,
      "z": 9,
      "name": "Wood_Burnt_Trunk"
    },
    {
      "x": 6,
      "y": 20,
      "z": 9,
      "name": "Wood_Burnt_Trunk"
    },
    {
      "x": 6,
      "y": 21,
      "z": 9,
      "name": "Wood_Burnt_Trunk"
    },
    {
      "x": 6,
      "y": 22,
      "z": 9,
      "name": "Wood_Burnt_Trunk"
    },
    {
      "x": 6,
      "y": 23,
      "z": 9,
      "name": "Wood_Burnt_Trunk"
    },
    {
      "x": 6,
      "y": 10,
      "z": 10,
      "name": "Wood_Burnt_Trunk"
    },
    {
      "x": 6,
      "y": 11,
      "z": 10,
      "name": "Wood_Burnt_Trunk"
    },
    {
      "x": 6,
      "y": 12,
      "z": 10,
      "name": "Wood_Burnt_Trunk"
    },
    {
      "x": 6,
      "y": 13,
      "z": 10,
      "name": "Wood_Burnt_Trunk"
    },
    {
      "x": 6,
      "y": 14,
      "z": 10,
      "name": "Wood_Burnt_Trunk"
    },
    {
      "x": 6,
      "y": 15,
      "z": 10,
      "name": "Wood_Burnt_Trunk"
    },
    {
      "x": 6,
      "y": 16,
      "z": 10,
      "name": "Wood_Burnt_Trunk"
    },
    {
      "x": 6,
      "y": 21,
      "z": 10,
      "name": "Wood_Burnt_Trunk"
    },
    {
      "x": 6,
      "y": 22,
      "z": 10,
      "name": "Wood_Burnt_Trunk"
    },
    {
      "x": 6,
      "y": 23,
      "z": 10,
      "name": "Wood_Burnt_Trunk"
    },
    {
      "x": 6,
      "y": 11,
      "z": 11,
      "name": "Wood_Burnt_Trunk"
    },
    {
      "x": 6,
      "y": 12,
      "z": 11,
      "name": "Wood_Burnt_Trunk"
    },
    {
      "x": 7,
      "y": 7,
      "z": 7,
      "name": "Wood_Burnt_Trunk"
    },
    {
      "x": 7,
      "y": 8,
      "z": 7,
      "name": "Wood_Burnt_Trunk"
    },
    {
      "x": 7,
      "y": 8,
      "z": 8,
      "name": "Wood_Burnt_Trunk"
    },
    {
      "x": 7,
      "y": 9,
      "z": 8,
      "name": "Wood_Burnt_Trunk"
    },
    {
      "x": 7,
      "y": 10,
      "z": 8,
      "name": "Wood_Burnt_Trunk"
    },
    {
      "x": 7,
      "y": 11,
      "z": 8,
      "name": "Wood_Burnt_Trunk"
    },
    {
      "x": 7,
      "y": 12,
      "z": 8,
      "name": "Wood_Burnt_Trunk"
    },
    {
      "x": 7,
      "y": 11,
      "z": 9,
      "name": "Wood_Burnt_Trunk"
    },
    {
      "x": 7,
      "y": 12,
      "z": 9,
      "name": "Wood_Burnt_Trunk"
    },
    {
      "x": 7,
      "y": 13,
      "z": 9,
      "name": "Wood_Burnt_Trunk"
    },
    {
      "x": 7,
      "y": 14,
      "z": 9,
      "name": "Wood_Burnt_Trunk"
    },
    {
      "x": 7,
      "y": 15,
      "z": 9,
      "name": "Wood_Burnt_Trunk"
    },
    {
      "x": 7,
      "y": 16,
      "z": 9,
      "name": "Wood_Burnt_Trunk"
    },
    {
      "x": 7,
      "y": 17,
      "z": 9,
      "name": "Wood_Burnt_Trunk"
    },
    {
      "x": 7,
      "y": 18,
      "z": 9,
      "name": "Wood_Burnt_Trunk"
    },
    {
      "x": 7,
      "y": 19,
      "z": 9,
      "name": "Wood_Burnt_Trunk"
    },
    {
      "x": 7,
      "y": 20,
      "z": 9,
      "name": "Wood_Burnt_Trunk"
    },
    {
      "x": 7,
      "y": 21,
      "z": 9,
      "name": "Wood_Burnt_Trunk"
    },
    {
      "x": 7,
      "y": 10,
      "z": 10,
      "name": "Wood_Burnt_Trunk"
    },
    {
      "x": 7,
      "y": 11,
      "z": 10,
      "name": "Wood_Burnt_Trunk"
    },
    {
      "x": 7,
      "y": 12,
      "z": 10,
      "name": "Wood_Burnt_Trunk"
    },
    {
      "x": 7,
      "y": 13,
      "z": 10,
      "name": "Wood_Burnt_Trunk"
    },
    {
      "x": 7,
      "y": 14,
      "z": 10,
      "name": "Wood_Burnt_Trunk"
    },
    {
      "x": 7,
      "y": 15,
      "z": 10,
      "name": "Wood_Burnt_Trunk"
    },
    {
      "x": 7,
      "y": 16,
      "z": 10,
      "name": "Wood_Burnt_Trunk"
    },
    {
      "x": 7,
      "y": 17,
      "z": 10,
      "name": "Wood_Burnt_Trunk"
    },
    {
      "x": 7,
      "y": 18,
      "z": 10,
      "name": "Wood_Burnt_Trunk"
    },
    {
      "x": 7,
      "y": 21,
      "z": 10,
      "name": "Wood_Burnt_Trunk"
    },
    {
      "x": 7,
      "y": 10,
      "z": 11,
      "name": "Wood_Burnt_Trunk"
    },
    {
      "x": 7,
      "y": 11,
      "z": 11,
      "name": "Wood_Burnt_Trunk"
    },
    {
      "x": 7,
      "y": 17,
      "z": 11,
      "name": "Wood_Burnt_Branch_Long",
      "rotation": 4
    },
    {
      "x": 8,
      "y": 16,
      "z": 9,
      "name": "Wood_Burnt_Branch_Short",
      "rotation": 1
    },
    {
      "x": 8,
      "y": 8,
      "z": 10,
      "name": "Wood_Burnt_Trunk"
    },
    {
      "x": 8,
      "y": 9,
      "z": 10,
      "name": "Wood_Burnt_Trunk"
    },
    {
      "x": 8,
      "y": 10,
      "z": 10,
      "name": "Wood_Burnt_Trunk"
    },
    {
      "x": 8,
      "y": 11,
      "z": 10,
      "name": "Wood_Burnt_Trunk"
    },
    {
      "x": 8,
      "y": 12,
      "z": 10,
      "name": "Wood_Burnt_Trunk"
    },
    {
      "x": 8,
      "y": 13,
      "z": 10,
      "name": "Wood_Burnt_Trunk"
    },
    {
      "x": 9,
      "y": 8,
      "z": 10,
      "name": "Wood_Burnt_Trunk"
    },
    {
      "x": 9,
      "y": 7,
      "z": 11,
      "name": "Wood_Burnt_Trunk"
    },
    {
      "x": 9,
      "y": 8,
      "z": 11,
      "name": "Wood_Burnt_Trunk"
    }
  ]
}