{
  "version": 8,
  "blockIdVersion": 8,
  "anchorX": 0,
  "anchorY": 0,
  "anchorZ": 0,
  "blocks": [
    {
      "x": -8,
      "y": 0,
      "z": -12,
      "name": "Rock_Stone_Cobble"
    },
    {
      "x": -8,
      "y": 1,
      "z": -12,
      "name": "Rock_Quartzite_Brick"
    },
    {
      "x": -8,
      "y": 2,
      "z": -12,
      "name": "Rock_Quartzite_Brick"
    },
    {
      "x": -8,
      "y": 3,
      "z": -12,
      "name": "Rock_Quartzite_Brick"
    },
    {
      "x": -8,
      "y": 4,
      "z": -12,
      "name": "Rock_Quartzite"
    },
    {
      "x": -8,
      "y": 5,
      "z": -12,
      "name": "Rock_Quartzite"
    },
    {
      "x": -8,
      "y": 6,
      "z": -12,
      "name": "Rock_Quartzite"
    },
    {
      "x": -8,
      "y": 7,
      "z": -12,
      "name": "Rock_Quartzite"
    },
    {
      "x": -8,
      "y": 8,
      "z": -12,
      "name": "Rock_Quartzite"
    },
    {
      "x": -8,
      "y": 9,
      "z": -12,
      "name": "Rock_Quartzite"
    },
    {
      "x": -8,
      "y": 10,
      "z": -12,
      "name": "Rock_Quartzite"
    },
    {
      "x": -8,
      "y": 11,
      "z": -12,
      "name": "Rock_Quartzite"
    },
    {
      "x": -8,
      "y": 12,
      "z": -12,
      "name": "Rock_Quartzite"
    },
    {
      "x": -8,
      "y": 13,
      "z": -12,
      "name": "Rock_Quartzite"
    },
    {
      "x": -8,
      "y": 14,
      "z": -12,
      "name": "Rock_Quartzite"
    },
    {
      "x": -8,
      "y": 15,
      "z": -12,
      "name": "Rock_Quartzite"
    },
    {
      "x": -8,
      "y": 0,
      "z": -11,
      "name": "Rock_Stone_Cobble"
    },
    {
      "x": -8,
      "y": 1,
      "z": -11,
      "name": "Rock_Quartzite_Brick"
    },
    {
      "x": -8,
      "y": 2,
      "z": -11,
      "name": "Rock_Quartzite_Brick"
    },
    {
      "x": -8,
      "y": 3,
      "z": -11,
      "name": "Rock_Quartzite_Brick"
    },
    {
      "x": -8,
      "y": 4,
      "z": -11,
      "name": "Rock_Quartzite"
    },
    {
      "x": -8,
      "y": 5,
      "z": -11,
      "name": "Rock_Quartzite"
    },
    {
      "x": -8,
      "y": 6,
      "z": -11,
      "name": "Rock_Quartzite"
    },
    {
      "x": -8,
      "y": 7,
      "z": -11,
      "name": "Rock_Quartzite"
    },
    {
      "x": -8,
      "y": 8,
      "z": -11,
      "name": "Rock_Quartzite"
    },
    {
      "x": -8,
      "y": 9,
      "z": -11,
      "name": "Rock_Quartzite"
    },
    {
      "x": -8,
      "y": 10,
      "z": -11,
      "name": "Rock_Quartzite"
    },
    {
      "x": -8,
      "y": 11,
      "z": -11,
      "name": "Rock_Quartzite"
    },
    {
      "x": -8,
      "y": 12,
      "z": -11,
      "name": "Rock_Quartzite"
    },
    {
      "x": -8,
      "y": 13,
      "z": -11,
      "name": "Rock_Quartzite"
    },
    {
      "x": -8,
      "y": 14,
      "z": -11,
      "name": "Rock_Quartzite"
    },
    {
      "x": -8,
      "y": 15,
      "z": -11,
      "name": "Rock_Quartzite"
    },
    {
      "x": -8,
      "y": 0,
      "z": -10,
      "name": "Rock_Stone_Cobble"
    },
    {
      "x": -8,
      "y": 1,
      "z": -10,
      "name": "Rock_Quartzite_Brick"
    },
    {
      "x": -8,
      "y": 2,
      "z": -10,
      "name": "Rock_Quartzite_Brick"
    },
    {
      "x": -8,
      "y": 3,
      "z": -10,
      "name": "Rock_Quartzite_Brick"
    },
    {
      "x": -8,
      "y": 4,
      "z": -10,
      "name": "Rock_Quartzite"
    },
    {
      "x": -8,
      "y": 5,
      "z": -10,
      "name": "Rock_Quartzite"
    },
    {
      "x": -8,
      "y": 6,
      "z": -10,
      "name": "Rock_Quartzite"
    },
    {
      "x": -8,
      "y": 7,
      "z": -10,
      "name": "Rock_Quartzite"
    },
    {
      "x": -8,
      "y": 8,
      "z": -10,
      "name": "Rock_Quartzite"
    },
    {
      "x": -8,
      "y": 9,
      "z": -10,
      "name": "Rock_Quartzite"
    },
    {
      "x": -8,
      "y": 10,
      "z": -10,
      "name": "Rock_Quartzite"
    },
    {
      "x": -8,
      "y": 11,
      "z": -10,
      "name": "Rock_Quartzite"
    },
    {
      "x": -8,
      "y": 12,
      "z": -10,
      "name": "Rock_Quartzite"
    },
    {
      "x": -8,
      "y": 13,
      "z": -10,
      "name": "Rock_Quartzite"
    },
    {
      "x": -8,
      "y": 14,
      "z": -10,
      "name": "Rock_Quartzite"
    },
    {
      "x": -8,
      "y": 15,
      "z": -10,
      "name": "Rock_Quartzite"
    },
    {
      "x": -8,
      "y": 0,
      "z": -9,
      "name": "Rock_Stone_Cobble"
    },
    {
      "x": -8,
      "y": 1,
      "z": -9,
      "name": "Rock_Quartzite_Brick"
    },
    {
      "x": -8,
      "y": 2,
      "z": -9,
      "name": "Rock_Quartzite_Brick"
    },
    {
      "x": -8,
      "y": 3,
      "z": -9,
      "name": "Rock_Quartzite_Brick"
    },
    {
      "x": -8,
      "y": 4,
      "z": -9,
      "name": "Rock_Quartzite"
    },
    {
      "x": -8,
      "y": 5,
      "z": -9,
      "name": "Rock_Quartzite"
    },
    {
      "x": -8,
      "y": 6,
      "z": -9,
      "name": "Rock_Quartzite"
    },
    {
      "x": -8,
      "y": 7,
      "z": -9,
      "name": "Rock_Quartzite"
    },
    {
      "x": -8,
      "y": 8,
      "z": -9,
      "name": "Rock_Quartzite"
    },
    {
      "x": -8,
      "y": 9,
      "z": -9,
      "name": "Rock_Quartzite"
    },
    {
      "x": -8,
      "y": 10,
      "z": -9,
      "name": "Rock_Quartzite"
    },
    {
      "x": -8,
      "y": 11,
      "z": -9,
      "name": "Rock_Quartzite"
    },
    {
      "x": -8,
      "y": 12,
      "z": -9,
      "name": "Rock_Quartzite"
    },
    {
      "x": -8,
      "y": 13,
      "z": -9,
      "name": "Rock_Quartzite"
    },
    {
      "x": -8,
      "y": 14,
      "z": -9,
      "name": "Rock_Quartzite"
    },
    {
      "x": -8,
      "y": 15,
      "z": -9,
      "name": "Rock_Quartzite"
    },
    {
      "x": -8,
      "y": 0,
      "z": -8,
      "name": "Rock_Stone_Cobble"
    },
    {
      "x": -8,
      "y": 1,
      "z": -8,
      "name": "Rock_Quartzite_Brick"
    },
    {
      "x": -8,
      "y": 2,
      "z": -8,
      "name": "Rock_Quartzite_Brick"
    },
    {
      "x": -8,
      "y": 3,
      "z": -8,
      "name": "Rock_Quartzite_Brick"
    },
    {
      "x": -8,
      "y": 4,
      "z": -8,
      "name": "Rock_Quartzite_Brick"
    },
    {
      "x": -8,
      "y": 5,
      "z": -8,
      "name": "Rock_Quartzite"
    },
    {
      "x": -8,
      "y": 6,
      "z": -8,
      "name": "Rock_Quartzite"
    },
    {
      "x": -8,
      "y": 7,
      "z": -8,
      "name": "Rock_Quartzite"
    },
    {
      "x": -8,
      "y": 8,
      "z": -8,
      "name": "Rock_Quartzite"
    },
    {
      "x": -8,
      "y": 9,
      "z": -8,
      "name": "Rock_Quartzite"
    },
    {
      "x": -8,
      "y": 10,
      "z": -8,
      "name": "Rock_Quartzite"
    },
    {
      "x": -8,
      "y": 11,
      "z": -8,
      "name": "Rock_Quartzite"
    },
    {
      "x": -8,
      "y": 12,
      "z": -8,
      "name": "Rock_Quartzite"
    },
    {
      "x": -8,
      "y": 13,
      "z": -8,
      "name": "Rock_Quartzite"
    },
    {
      "x": -8,
      "y": 14,
      "z": -8,
      "name": "Rock_Quartzite"
    },
    {
      "x": -8,
      "y": 15,
      "z": -8,
      "name": "Rock_Quartzite"
    },
    {
      "x": -8,
      "y": 0,
      "z": -7,
      "name": "Rock_Stone_Cobble"
    },
    {
      "x": -8,
      "y": 1,
      "z": -7,
      "name": "Rock_Quartzite_Brick"
    },
    {
      "x": -8,
      "y": 2,
      "z": -7,
      "name": "Rock_Quartzite_Brick"
    },
    {
      "x": -8,
      "y": 3,
      "z": -7,
      "name": "Rock_Quartzite_Brick"
    },
    {
      "x": -8,
      "y": 4,
      "z": -7,
      "name": "Rock_Quartzite_Brick"
    },
    {
      "x": -8,
      "y": 5,
      "z": -7,
      "name": "Rock_Quartzite_Brick"
    },
    {
      "x": -8,
      "y": 6,
      "z": -7,
      "name": "Rock_Quartzite"
    },
    {
      "x": -8,
      "y": 7,
      "z": -7,
      "name": "Rock_Quartzite"
    },
    {
      "x": -8,
      "y": 8,
      "z": -7,
      "name": "Rock_Quartzite"
    },
    {
      "x": -8,
      "y": 9,
      "z": -7,
      "name": "Rock_Quartzite_Brick"
    },
    {
      "x": -8,
      "y": 10,
      "z": -7,
      "name": "Rock_Quartzite_Brick"
    },
    {
      "x": -8,
      "y": 11,
      "z": -7,
      "name": "Rock_Quartzite"
    },
    {
      "x": -8,
      "y": 12,
      "z": -7,
      "name": "Rock_Quartzite"
    },
    {
      "x": -8,
      "y": 13,
      "z": -7,
      "name": "Rock_Quartzite"
    },
    {
      "x": -8,
      "y": 14,
      "z": -7,
      "name": "Rock_Quartzite"
    },
    {
      "x": -8,
      "y": 15,
      "z": -7,
      "name": "Rock_Quartzite"
    },
    {
      "x": -8,
      "y": 0,
      "z": -6,
      "name": "Rock_Stone_Cobble"
    },
    {
      "x": -8,
      "y": 1,
      "z": -6,
      "name": "Rock_Quartzite_Brick"
    },
    {
      "x": -8,
      "y": 2,
      "z": -6,
      "name": "Rock_Quartzite_Brick"
    },
    {
      "x": -8,
      "y": 3,
      "z": -6,
      "name": "Rock_Quartzite_Brick"
    },
    {
      "x": -8,
      "y": 4,
      "z": -6,
      "name": "Rock_Quartzite"
    },
    {
      "x": -8,
      "y": 5,
      "z": -6,
      "name": "Rock_Quartzite"
    },
    {
      "x": -8,
      "y": 6,
      "z": -6,
      "name": "Rock_Quartzite"
    },
    {
      "x": -8,
      "y": 7,
      "z": -6,
      "name": "Rock_Quartzite"
    },
    {
      "x": -8,
      "y": 8,
      "z": -6,
      "name": "Rock_Quartzite"
    },
    {
      "x": -8,
      "y": 9,
      "z": -6,
      "name": "Rock_Quartzite_Brick"
    },
    {
      "x": -8,
      "y": 10,
      "z": -6,
      "name": "Rock_Quartzite_Brick"
    },
    {
      "x": -8,
      "y": 11,
      "z": -6,
      "name": "Rock_Quartzite"
    },
    {
      "x": -8,
      "y": 12,
      "z": -6,
      "name": "Rock_Quartzite"
    },
    {
      "x": -8,
      "y": 13,
      "z": -6,
      "name": "Rock_Quartzite"
    },
    {
      "x": -8,
      "y": 14,
      "z": -6,
      "name": "Rock_Quartzite"
    },
    {
      "x": -8,
      "y": 15,
      "z": -6,
      "name": "Rock_Quartzite"
    },
    {
      "x": -8,
      "y": 0,
      "z": -5,
      "name": "Rock_Stone_Cobble"
    },
    {
      "x": -8,
      "y": 1,
      "z": -5,
      "name": "Rock_Quartzite_Brick"
    },
    {
      "x": -8,
      "y": 2,
      "z": -5,
      "name": "Rock_Quartzite_Brick"
    },
    {
      "x": -8,
      "y": 3,
      "z": -5,
      "name": "Rock_Quartzite_Brick"
    },
    {
      "x": -8,
      "y": 4,
      "z": -5,
      "name": "Rock_Quartzite"
    },
    {
      "x": -8,
      "y": 5,
      "z": -5,
      "name": "Rock_Quartzite"
    },
    {
      "x": -8,
      "y": 6,
      "z": -5,
      "name": "Rock_Quartzite"
    },
    {
      "x": -8,
      "y": 7,
      "z": -5,
      "name": "Rock_Quartzite"
    },
    {
      "x": -8,
      "y": 8,
      "z": -5,
      "name": "Rock_Quartzite"
    },
    {
      "x": -8,
      "y": 9,
      "z": -5,
      "name": "Rock_Quartzite_Brick"
    },
    {
      "x": -8,
      "y": 10,
      "z": -5,
      "name": "Rock_Quartzite_Brick"
    },
    {
      "x": -8,
      "y": 11,
      "z": -5,
      "name": "Rock_Quartzite"
    },
    {
      "x": -8,
      "y": 12,
      "z": -5,
      "name": "Rock_Quartzite"
    },
    {
      "x": -8,
      "y": 13,
      "z": -5,
      "name": "Rock_Quartzite"
    },
    {
      "x": -8,
      "y": 14,
      "z": -5,
      "name": "Rock_Quartzite"
    },
    {
      "x": -8,
      "y": 15,
      "z": -5,
      "name": "Rock_Quartzite"
    },
    {
      "x": -8,
      "y": 0,
      "z": -4,
      "name": "Rock_Stone_Cobble"
    },
    {
      "x": -8,
      "y": 1,
      "z": -4,
      "name": "Rock_Quartzite_Brick"
    },
    {
      "x": -8,
      "y": 2,
      "z": -4,
      "name": "Rock_Quartzite_Brick"
    },
    {
      "x": -8,
      "y": 3,
      "z": -4,
      "name": "Rock_Quartzite_Brick"
    },
    {
      "x": -8,
      "y": 4,
      "z": -4,
      "name": "Rock_Quartzite_Brick"
    },
    {
      "x": -8,
      "y": 5,
      "z": -4,
      "name": "Rock_Quartzite_Brick"
    },
    {
      "x": -8,
      "y": 6,
      "z": -4,
      "name": "Rock_Quartzite"
    },
    {
      "x": -8,
      "y": 7,
      "z": -4,
      "name": "Rock_Quartzite"
    },
    {
      "x": -8,
      "y": 8,
      "z": -4,
      "name": "Rock_Quartzite"
    },
    {
      "x": -8,
      "y": 9,
      "z": -4,
      "name": "Rock_Quartzite_Brick"
    },
    {
      "x": -8,
      "y": 10,
      "z": -4,
      "name": "Rock_Quartzite_Brick"
    },
    {
      "x": -8,
      "y": 11,
      "z": -4,
      "name": "Rock_Quartzite"
    },
    {
      "x": -8,
      "y": 12,
      "z": -4,
      "name": "Rock_Quartzite"
    },
    {
      "x": -8,
      "y": 13,
      "z": -4,
      "name": "Rock_Quartzite"
    },
    {
      "x": -8,
      "y": 14,
      "z": -4,
      "name": "Rock_Quartzite"
    },
    {
      "x": -8,
      "y": 15,
      "z": -4,
      "name": "Rock_Quartzite"
    },
    {
      "x": -8,
      "y": 0,
      "z": -3,
      "name": "Rock_Stone_Cobble"
    },
    {
      "x": -8,
      "y": 1,
      "z": -3,
      "name": "Rock_Quartzite_Brick"
    },
    {
      "x": -8,
      "y": 2,
      "z": -3,
      "name": "Rock_Quartzite_Brick"
    },
    {
      "x": -8,
      "y": 3,
      "z": -3,
      "name": "Rock_Quartzite_Brick"
    },
    {
      "x": -8,
      "y": 4,
      "z": -3,
      "name": "Rock_Quartzite"
    },
    {
      "x": -8,
      "y": 5,
      "z": -3,
      "name": "Rock_Quartzite"
    },
    {
      "x": -8,
      "y": 6,
      "z": -3,
      "name": "Rock_Quartzite"
    },
    {
      "x": -8,
      "y": 7,
      "z": -3,
      "name": "Rock_Quartzite"
    },
    {
      "x": -8,
      "y": 8,
      "z": -3,
      "name": "Rock_Quartzite"
    },
    {
      "x": -8,
      "y": 9,
      "z": -3,
      "name": "Rock_Quartzite_Brick"
    },
    {
      "x": -8,
      "y": 10,
      "z": -3,
      "name": "Rock_Quartzite_Brick"
    },
    {
      "x": -8,
      "y": 11,
      "z": -3,
      "name": "Rock_Quartzite_Brick"
    },
    {
      "x": -8,
      "y": 12,
      "z": -3,
      "name": "Rock_Quartzite"
    },
    {
      "x": -8,
      "y": 13,
      "z": -3,
      "name": "Rock_Quartzite"
    },
    {
      "x": -8,
      "y": 14,
      "z": -3,
      "name": "Rock_Quartzite"
    },
    {
      "x": -8,
      "y": 15,
      "z": -3,
      "name": "Rock_Quartzite"
    },
    {
      "x": -8,
      "y": 0,
      "z": -2,
      "name": "Rock_Stone_Cobble"
    },
    {
      "x": -8,
      "y": 1,
      "z": -2,
      "name": "Rock_Quartzite_Brick"
    },
    {
      "x": -8,
      "y": 2,
      "z": -2,
      "name": "Rock_Quartzite_Brick"
    },
    {
      "x": -8,
      "y": 3,
      "z": -2,
      "name": "Rock_Quartzite_Brick"
    },
    {
      "x": -8,
      "y": 4,
      "z": -2,
      "name": "Rock_Quartzite_Brick"
    },
    {
      "x": -8,
      "y": 5,
      "z": -2,
      "name": "Rock_Quartzite"
    },
    {
      "x": -8,
      "y": 6,
      "z": -2,
      "name": "Rock_Quartzite"
    },
    {
      "x": -8,
      "y": 7,
      "z": -2,
      "name": "Rock_Quartzite"
    },
    {
      "x": -8,
      "y": 8,
      "z": -2,
      "name": "Rock_Quartzite"
    },
    {
      "x": -8,
      "y": 9,
      "z": -2,
      "name": "Rock_Quartzite"
    },
    {
      "x": -8,
      "y": 10,
      "z": -2,
      "name": "Rock_Quartzite_Brick"
    },
    {
      "x": -8,
      "y": 11,
      "z": -2,
      "name": "Rock_Quartzite"
    },
    {
      "x": -8,
      "y": 12,
      "z": -2,
      "name": "Rock_Quartzite"
    },
    {
      "x": -8,
      "y": 13,
      "z": -2,
      "name": "Rock_Quartzite"
    },
    {
      "x": -8,
      "y": 14,
      "z": -2,
      "name": "Rock_Quartzite"
    },
    {
      "x": -8,
      "y": 15,
      "z": -2,
      "name": "Rock_Quartzite"
    },
    {
      "x": -8,
      "y": 0,
      "z": -1,
      "name": "Rock_Stone_Cobble"
    },
    {
      "x": -8,
      "y": 1,
      "z": -1,
      "name": "Rock_Quartzite_Brick"
    },
    {
      "x": -8,
      "y": 2,
      "z": -1,
      "name": "Rock_Quartzite_Brick"
    },
    {
      "x": -8,
      "y": 3,
      "z": -1,
      "name": "Rock_Quartzite_Brick"
    },
    {
      "x": -8,
      "y": 4,
      "z": -1,
      "name": "Rock_Quartzite_Brick"
    },
    {
      "x": -8,
      "y": 5,
      "z": -1,
      "name": "Rock_Quartzite_Brick"
    },
    {
      "x": -8,
      "y": 6,
      "z": -1,
      "name": "Rock_Quartzite"
    },
    {
      "x": -8,
      "y": 7,
      "z": -1,
      "name": "Rock_Quartzite"
    },
    {
      "x": -8,
      "y": 8,
      "z": -1,
      "name": "Rock_Quartzite"
    },
    {
      "x": -8,
      "y": 9,
      "z": -1,
      "name": "Rock_Quartzite"
    },
    {
      "x": -8,
      "y": 10,
      "z": -1,
      "name": "Rock_Quartzite"
    },
    {
      "x": -8,
      "y": 11,
      "z": -1,
      "name": "Rock_Quartzite"
    },
    {
      "x": -8,
      "y": 12,
      "z": -1,
      "name": "Rock_Quartzite"
    },
    {
      "x": -8,
      "y": 13,
      "z": -1,
      "name": "Rock_Quartzite"
    },
    {
      "x": -8,
      "y": 14,
      "z": -1,
      "name": "Rock_Quartzite"
    },
    {
      "x": -8,
      "y": 15,
      "z": -1,
      "name": "Rock_Quartzite"
    },
    {
      "x": -8,
      "y": 0,
      "z": 0,
      "name": "Rock_Stone_Cobble"
    },
    {
      "x": -8,
      "y": 1,
      "z": 0,
      "name": "Rock_Quartzite_Brick"
    },
    {
      "x": -8,
      "y": 2,
      "z": 0,
      "name": "Rock_Quartzite_Brick"
    },
    {
      "x": -8,
      "y": 3,
      "z": 0,
      "name": "Rock_Quartzite_Brick"
    },
    {
      "x": -8,
      "y": 4,
      "z": 0,
      "name": "Rock_Quartzite"
    },
    {
      "x": -8,
      "y": 5,
      "z": 0,
      "name": "Rock_Quartzite"
    },
    {
      "x": -8,
      "y": 6,
      "z": 0,
      "name": "Rock_Quartzite"
    },
    {
      "x": -8,
      "y": 7,
      "z": 0,
      "name": "Rock_Quartzite"
    },
    {
      "x": -8,
      "y": 8,
      "z": 0,
      "name": "Rock_Quartzite"
    },
    {
      "x": -8,
      "y": 9,
      "z": 0,
      "name": "Rock_Quartzite"
    },
    {
      "x": -8,
      "y": 10,
      "z": 0,
      "name": "Rock_Quartzite"
    },
    {
      "x": -8,
      "y": 11,
      "z": 0,
      "name": "Rock_Quartzite"
    },
    {
      "x": -8,
      "y": 12,
      "z": 0,
      "name": "Rock_Quartzite"
    },
    {
      "x": -8,
      "y": 13,
      "z": 0,
      "name": "Rock_Quartzite"
    },
    {
      "x": -8,
      "y": 14,
      "z": 0,
      "name": "Rock_Quartzite"
    },
    {
      "x": -8,
      "y": 15,
      "z": 0,
      "name": "Rock_Quartzite"
    },
    {
      "x": -7,
      "y": 0,
      "z": -12,
      "name": "Rock_Stone_Cobble"
    },
    {
      "x": -7,
      "y": 1,
      "z": -12,
      "name": "Rock_Quartzite_Brick"
    },
    {
      "x": -7,
      "y": 2,
      "z": -12,
      "name": "Rock_Quartzite_Brick"
    },
    {
      "x": -7,
      "y": 3,
      "z": -12,
      "name": "Rock_Quartzite_Brick"
    },
    {
      "x": -7,
      "y": 4,
      "z": -12,
      "name": "Rock_Quartzite_Brick"
    },
    {
      "x": -7,
      "y": 5,
      "z": -12,
      "name": "Rock_Quartzite_Brick"
    },
    {
      "x": -7,
      "y": 6,
      "z": -12,
      "name": "Rock_Quartzite"
    },
    {
      "x": -7,
      "y": 7,
      "z": -12,
      "name": "Rock_Quartzite"
    },
    {
      "x": -7,
      "y": 8,
      "z": -12,
      "name": "Rock_Quartzite"
    },
    {
      "x": -7,
      "y": 9,
      "z": -12,
      "name": "Rock_Quartzite"
    },
    {
      "x": -7,
      "y": 10,
      "z": -12,
      "name": "Rock_Quartzite"
    },
    {
      "x": -7,
      "y": 11,
      "z": -12,
      "name": "Rock_Quartzite"
    },
    {
      "x": -7,
      "y": 12,
      "z": -12,
      "name": "Rock_Quartzite"
    },
    {
      "x": -7,
      "y": 13,
      "z": -12,
      "name": "Rock_Quartzite"
    },
    {
      "x": -7,
      "y": 14,
      "z": -12,
      "name": "Rock_Quartzite"
    },
    {
      "x": -7,
      "y": 15,
      "z": -12,
      "name": "Rock_Quartzite"
    },
    {
      "x": -7,
      "y": 0,
      "z": -11,
      "name": "Rock_Stone_Cobble"
    },
    {
      "x": -7,
      "y": 1,
      "z": -11,
      "name": "Rock_Stone_Brick"
    },
    {
      "x": -7,
      "y": 2,
      "z": -11,
      "name": "Furniture_Village_Bookcase",
      "rotation": 1
    },
    {
      "x": -7,
      "y": 3,
      "z": -11,
      "name": "Empty"
    },
    {
      "x": -7,
      "y": 4,
      "z": -11,
      "name": "Empty"
    },
    {
      "x": -7,
      "y": 5,
      "z": -11,
      "name": "Rock_Quartzite_Brick_Half",
      "rotation": 5
    },
    {
      "x": -7,
      "y": 6,
      "z": -11,
      "name": "Rock_Quartzite_Brick"
    },
    {
      "x": -7,
      "y": 7,
      "z": -11,
      "name": "Rock_Quartzite_Brick"
    },
    {
      "x": -7,
      "y": 8,
      "z": -11,
      "name": "Rock_Quartzite_Brick"
    },
    {
      "x": -7,
      "y": 9,
      "z": -11,
      "name": "Rock_Quartzite_Brick"
    },
    {
      "x": -7,
      "y": 10,
      "z": -11,
      "name": "Empty"
    },
    {
      "x": -7,
      "y": 11,
      "z": -11,
      "name": "Rock_Quartzite"
    },
    {
      "x": -7,
      "y": 12,
      "z": -11,
      "name": "Rock_Quartzite"
    },
    {
      "x": -7,
      "y": 13,
      "z": -11,
      "name": "Rock_Quartzite"
    },
    {
      "x": -7,
      "y": 14,
      "z": -11,
      "name": "Rock_Quartzite"
    },
    {
      "x": -7,
      "y": 15,
      "z": -11,
      "name": "Rock_Quartzite"
    },
    {
      "x": -7,
      "y": 0,
      "z": -10,
      "name": "Rock_Stone_Cobble"
    },
    {
      "x": -7,
      "y": 1,
      "z": -10,
      "name": "Rock_Stone_Brick"
    },
    {
      "x": -7,
      "y": 2,
      "z": -10,
      "name": "Furniture_Village_Bookcase",
      "rotation": 1
    },
    {
      "x": -7,
      "y": 3,
      "z": -10,
      "name": "Furniture_Village_Bookcase",
      "rotation": 1
    },
    {
      "x": -7,
      "y": 4,
      "z": -10,
      "name": "Empty"
    },
    {
      "x": -7,
      "y": 5,
      "z": -10,
      "name": "Empty"
    },
    {
      "x": -7,
      "y": 6,
      "z": -10,
      "name": "Rock_Quartzite_Brick_Half",
      "rotation": 8
    },
    {
      "x": -7,
      "y": 7,
      "z": -10,
      "name": "Rock_Quartzite_Brick"
    },
    {
      "x": -7,
      "y": 8,
      "z": -10,
      "name": "Rock_Quartzite_Brick"
    },
    {
      "x": -7,
      "y": 9,
      "z": -10,
      "name": "Rock_Quartzite_Brick"
    },
    {
      "x": -7,
      "y": 10,
      "z": -10,
      "name": "Rock_Quartzite"
    },
    {
      "x": -7,
      "y": 11,
      "z": -10,
      "name": "Rock_Quartzite"
    },
    {
      "x": -7,
      "y": 12,
      "z": -10,
      "name": "Rock_Quartzite"
    },
    {
      "x": -7,
      "y": 13,
      "z": -10,
      "name": "Rock_Quartzite"
    },
    {
      "x": -7,
      "y": 14,
      "z": -10,
      "name": "Rock_Quartzite"
    },
    {
      "x": -7,
      "y": 15,
      "z": -10,
      "name": "Rock_Quartzite"
    },
    {
      "x": -7,
      "y": 0,
      "z": -9,
      "name": "Rock_Stone_Cobble"
    },
    {
      "x": -7,
      "y": 1,
      "z": -9,
      "name": "Rock_Stone_Brick"
    },
    {
      "x": -7,
      "y": 2,
      "z": -9,
      "name": "Furniture_Ancient_Bed",
      "components": {
        "Components": {
          "RespawnBlock": {}
        }
      },
      "filler": 991,
      "rotation": 2
    },
    {
      "x": -7,
      "y": 3,
      "z": -9,
      "name": "Furniture_Ancient_Bed",
      "components": {
        "Components": {
          "RespawnBlock": {}
        }
      },
      "filler": 2015,
      "rotation": 2
    },
    {
      "x": -7,
      "y": 4,
      "z": -9,
      "name": "Empty"
    },
    {
      "x": -7,
      "y": 5,
      "z": -9,
      "name": "Empty"
    },
    {
      "x": -7,
      "y": 6,
      "z": -9,
      "name": "Rock_Quartzite_Brick"
    },
    {
      "x": -7,
      "y": 7,
      "z": -9,
      "name": "Rock_Quartzite_Brick"
    },
    {
      "x": -7,
      "y": 8,
      "z": -9,
      "name": "Rock_Quartzite_Brick"
    },
    {
      "x": -7,
      "y": 9,
      "z": -9,
      "name": "Rock_Quartzite_Brick"
    },
    {
      "x": -7,
      "y": 10,
      "z": -9,
      "name": "Rock_Quartzite"
    },
    {
      "x": -7,
      "y": 11,
      "z": -9,
      "name": "Rock_Quartzite"
    },
    {
      "x": -7,
      "y": 12,
      "z": -9,
      "name": "Rock_Quartzite"
    },
    {
      "x": -7,
      "y": 13,
      "z": -9,
      "name": "Rock_Quartzite"
    },
    {
      "x": -7,
      "y": 14,
      "z": -9,
      "name": "Rock_Quartzite"
    },
    {
      "x": -7,
      "y": 15,
      "z": -9,
      "name": "Rock_Quartzite"
    },
    {
      "x": -7,
      "y": 0,
      "z": -8,
      "name": "Rock_Stone_Cobble"
    },
    {
      "x": -7,
      "y": 1,
      "z": -8,
      "name": "Rock_Stone_Brick"
    },
    {
      "x": -7,
      "y": 2,
      "z": -8,
      "name": "Furniture_Ancient_Bed",
      "components": {
        "Components": {
          "RespawnBlock": {}
        }
      },
      "filler": 1023,
      "rotation": 2
    },
    {
      "x": -7,
      "y": 3,
      "z": -8,
      "name": "Furniture_Ancient_Bed",
      "components": {
        "Components": {
          "RespawnBlock": {}
        }
      },
      "filler": 2047,
      "rotation": 2
    },
    {
      "x": -7,
      "y": 4,
      "z": -8,
      "name": "Empty"
    },
    {
      "x": -7,
      "y": 5,
      "z": -8,
      "name": "Empty"
    },
    {
      "x": -7,
      "y": 6,
      "z": -8,
      "name": "Rock_Quartzite_Brick"
    },
    {
      "x": -7,
      "y": 7,
      "z": -8,
      "name": "Rock_Quartzite_Brick"
    },
    {
      "x": -7,
      "y": 8,
      "z": -8,
      "name": "Rock_Quartzite_Brick"
    },
    {
      "x": -7,
      "y": 9,
      "z": -8,
      "name": "Rock_Quartzite_Brick"
    },
    {
      "x": -7,
      "y": 10,
      "z": -8,
      "name": "Rock_Quartzite"
    },
    {
      "x": -7,
      "y": 11,
      "z": -8,
      "name": "Rock_Quartzite"
    },
    {
      "x": -7,
      "y": 12,
      "z": -8,
      "name": "Rock_Quartzite"
    },
    {
      "x": -7,
      "y": 13,
      "z": -8,
      "name": "Rock_Quartzite"
    },
    {
      "x": -7,
      "y": 14,
      "z": -8,
      "name": "Rock_Quartzite"
    },
    {
      "x": -7,
      "y": 15,
      "z": -8,
      "name": "Rock_Quartzite"
    },
    {
      "x": -7,
      "y": 0,
      "z": -7,
      "name": "Rock_Stone_Cobble"
    },
    {
      "x": -7,
      "y": 1,
      "z": -7,
      "name": "Rock_Stone_Cobble"
    },
    {
      "x": -7,
      "y": 2,
      "z": -7,
      "name": "Furniture_Ancient_Bed",
      "components": {
        "Components": {
          "RespawnBlock": {}
        }
      },
      "filler": 31,
      "rotation": 2
    },
    {
      "x": -7,
      "y": 3,
      "z": -7,
      "name": "Furniture_Ancient_Bed",
      "components": {
        "Components": {
          "RespawnBlock": {}
        }
      },
      "filler": 1055,
      "rotation": 2
    },
    {
      "x": -7,
      "y": 4,
      "z": -7,
      "name": "Empty"
    },
    {
      "x": -7,
      "y": 5,
      "z": -7,
      "name": "Rock_Quartzite_Brick_Half",
      "rotation": 5
    },
    {
      "x": -7,
      "y": 6,
      "z": -7,
      "name": "Rock_Quartzite_Brick"
    },
    {
      "x": -7,
      "y": 7,
      "z": -7,
      "name": "Rock_Quartzite_Brick"
    },
    {
      "x": -7,
      "y": 8,
      "z": -7,
      "name": "Rock_Stone_Brick"
    },
    {
      "x": -7,
      "y": 9,
      "z": -7,
      "name": "Empty"
    },
    {
      "x": -7,
      "y": 10,
      "z": -7,
      "name": "Empty"
    },
    {
      "x": -7,
      "y": 11,
      "z": -7,
      "name": "Rock_Quartzite_Brick_Half",
      "rotation": 4
    },
    {
      "x": -7,
      "y": 12,
      "z": -7,
      "name": "Rock_Quartzite_Brick"
    },
    {
      "x": -7,
      "y": 13,
      "z": -7,
      "name": "Rock_Quartzite"
    },
    {
      "x": -7,
      "y": 14,
      "z": -7,
      "name": "Rock_Quartzite"
    },
    {
      "x": -7,
      "y": 15,
      "z": -7,
      "name": "Rock_Quartzite"
    },
    {
      "x": -7,
      "y": 0,
      "z": -6,
      "name": "Rock_Stone_Cobble"
    },
    {
      "x": -7,
      "y": 1,
      "z": -6,
      "name": "Rock_Quartzite_Brick"
    },
    {
      "x": -7,
      "y": 2,
      "z": -6,
      "name": "Rock_Quartzite_Brick"
    },
    {
      "x": -7,
      "y": 3,
      "z": -6,
      "name": "Rock_Quartzite"
    },
    {
      "x": -7,
      "y": 4,
      "z": -6,
      "name": "Rock_Quartzite"
    },
    {
      "x": -7,
      "y": 5,
      "z": -6,
      "name": "Rock_Quartzite"
    },
    {
      "x": -7,
      "y": 6,
      "z": -6,
      "name": "Rock_Quartzite_Brick"
    },
    {
      "x": -7,
      "y": 7,
      "z": -6,
      "name": "Rock_Quartzite_Brick"
    },
    {
      "x": -7,
      "y": 8,
      "z": -6,
      "name": "Rock_Stone_Brick"
    },
    {
      "x": -7,
      "y": 9,
      "z": -6,
      "name": "Furniture_Ancient_Bench",
      "rotation": 1
    },
    {
      "x": -7,
      "y": 10,
      "z": -6,
      "name": "Empty"
    },
    {
      "x": -7,
      "y": 11,
      "z": -6,
      "name": "Empty"
    },
    {
      "x": -7,
      "y": 12,
      "z": -6,
      "name": "Rock_Quartzite_Brick"
    },
    {
      "x": -7,
      "y": 13,
      "z": -6,
      "name": "Rock_Quartzite"
    },
    {
      "x": -7,
      "y": 14,
      "z": -6,
      "name": "Rock_Quartzite"
    },
    {
      "x": -7,
      "y": 15,
      "z": -6,
      "name": "Rock_Quartzite"
    },
    {
      "x": -7,
      "y": 0,
      "z": -5,
      "name": "Rock_Stone_Cobble"
    },
    {
      "x": -7,
      "y": 1,
      "z": -5,
      "name": "Rock_Quartzite_Brick"
    },
    {
      "x": -7,
      "y": 2,
      "z": -5,
      "name": "Rock_Quartzite_Brick"
    },
    {
      "x": -7,
      "y": 3,
      "z": -5,
      "name": "Rock_Quartzite_Brick"
    },
    {
      "x": -7,
      "y": 4,
      "z": -5,
      "name": "Rock_Quartzite_Brick"
    },
    {
      "x": -7,
      "y": 5,
      "z": -5,
      "name": "Rock_Quartzite_Brick"
    },
    {
      "x": -7,
      "y": 6,
      "z": -5,
      "name": "Rock_Quartzite"
    },
    {
      "x": -7,
      "y": 7,
      "z": -5,
      "name": "Rock_Quartzite_Brick"
    },
    {
      "x": -7,
      "y": 8,
      "z": -5,
      "name": "Rock_Stone_Cobble"
    },
    {
      "x": -7,
      "y": 9,
      "z": -5,
      "name": "Furniture_Ancient_Bench",
      "filler": 32,
      "rotation": 1
    },
    {
      "x": -7,
      "y": 10,
      "z": -5,
      "name": "Empty"
    },
    {
      "x": -7,
      "y": 11,
      "z": -5,
      "name": "Empty"
    },
    {
      "x": -7,
      "y": 12,
      "z": -5,
      "name": "Rock_Quartzite_Brick_Half",
      "rotation": 8
    },
    {
      "x": -7,
      "y": 13,
      "z": -5,
      "name": "Rock_Quartzite"
    },
    {
      "x": -7,
      "y": 14,
      "z": -5,
      "name": "Rock_Quartzite"
    },
    {
      "x": -7,
      "y": 15,
      "z": -5,
      "name": "Rock_Quartzite"
    },
    {
      "x": -7,
      "y": 0,
      "z": -4,
      "name": "Rock_Stone_Cobble"
    },
    {
      "x": -7,
      "y": 1,
      "z": -4,
      "name": "Rock_Stone"
    },
    {
      "x": -7,
      "y": 2,
      "z": -4,
      "name": "Rock_Stone"
    },
    {
      "x": -7,
      "y": 3,
      "z": -4,
      "name": "Plant_Moss_Block_Blue"
    },
    {
      "x": -7,
      "y": 4,
      "z": -4,
      "name": "Empty"
    },
    {
      "x": -7,
      "y": 5,
      "z": -4,
      "name": "Empty"
    },
    {
      "x": -7,
      "y": 6,
      "z": -4,
      "name": "Empty"
    },
    {
      "x": -7,
      "y": 7,
      "z": -4,
      "name": "Rock_Quartzite_Brick"
    },
    {
      "x": -7,
      "y": 8,
      "z": -4,
      "name": "Rock_Quartzite_Brick"
    },
    {
      "x": -7,
      "y": 9,
      "z": -4,
      "name": "Furniture_Village_Bookcase",
      "rotation": 1
    },
    {
      "x": -7,
      "y": 10,
      "z": -4,
      "name": "Empty"
    },
    {
      "x": -7,
      "y": 11,
      "z": -4,
      "name": "Empty"
    },
    {
      "x": -7,
      "y": 12,
      "z": -4,
      "name": "Rock_Quartzite_Brick_Half",
      "rotation": 8
    },
    {
      "x": -7,
      "y": 13,
      "z": -4,
      "name": "Rock_Quartzite"
    },
    {
      "x": -7,
      "y": 14,
      "z": -4,
      "name": "Rock_Quartzite"
    },
    {
      "x": -7,
      "y": 15,
      "z": -4,
      "name": "Rock_Quartzite"
    },
    {
      "x": -7,
      "y": 0,
      "z": -3,
      "name": "Rock_Stone_Cobble"
    },
    {
      "x": -7,
      "y": 1,
      "z": -3,
      "name": "Rock_Stone"
    },
    {
      "x": -7,
      "y": 2,
      "z": -3,
      "name": "Rock_Stone"
    },
    {
      "x": -7,
      "y": 3,
      "z": -3,
      "name": "Rock_Stone"
    },
    {
      "x": -7,
      "y": 4,
      "z": -3,
      "name": "Rock_Stone"
    },
    {
      "x": -7,
      "y": 5,
      "z": -3,
      "name": "Rock_Stone"
    },
    {
      "x": -7,
      "y": 6,
      "z": -3,
      "name": "Plant_Moss_Rug_Blue"
    },
    {
      "x": -7,
      "y": 7,
      "z": -3,
      "name": "Rock_Quartzite_Brick"
    },
    {
      "x": -7,
      "y": 8,
      "z": -3,
      "name": "Rock_Stone_Cobble"
    },
    {
      "x": -7,
      "y": 9,
      "z": -3,
      "name": "Furniture_Village_Bookcase",
      "rotation": 1
    },
    {
      "x": -7,
      "y": 10,
      "z": -3,
      "name": "Furniture_Village_Bookcase",
      "rotation": 1
    },
    {
      "x": -7,
      "y": 11,
      "z": -3,
      "name": "Empty"
    },
    {
      "x": -7,
      "y": 12,
      "z": -3,
      "name": "Rock_Quartzite_Brick"
    },
    {
      "x": -7,
      "y": 13,
      "z": -3,
      "name": "Rock_Quartzite"
    },
    {
      "x": -7,
      "y": 14,
      "z": -3,
      "name": "Rock_Quartzite"
    },
    {
      "x": -7,
      "y": 15,
      "z": -3,
      "name": "Rock_Quartzite"
    },
    {
      "x": -7,
      "y": 0,
      "z": -2,
      "name": "Rock_Stone_Cobble"
    },
    {
      "x": -7,
      "y": 1,
      "z": -2,
      "name": "Rock_Stone"
    },
    {
      "x": -7,
      "y": 2,
      "z": -2,
      "name": "Rock_Stone"
    },
    {
      "x": -7,
      "y": 3,
      "z": -2,
      "name": "Rock_Stone"
    },
    {
      "x": -7,
      "y": 4,
      "z": -2,
      "name": "Rock_Stone"
    },
    {
      "x": -7,
      "y": 5,
      "z": -2,
      "name": "Rock_Stone"
    },
    {
      "x": -7,
      "y": 6,
      "z": -2,
      "name": "Rock_Stone"
    },
    {
      "x": -7,
      "y": 7,
      "z": -2,
      "name": "Rock_Quartzite_Brick"
    },
    {
      "x": -7,
      "y": 8,
      "z": -2,
      "name": "Rock_Quartzite"
    },
    {
      "x": -7,
      "y": 9,
      "z": -2,
      "name": "Rock_Quartzite_Brick"
    },
    {
      "x": -7,
      "y": 10,
      "z": -2,
      "name": "Rock_Quartzite_Brick"
    },
    {
      "x": -7,
      "y": 11,
      "z": -2,
      "name": "Rock_Quartzite_Brick"
    },
    {
      "x": -7,
      "y": 12,
      "z": -2,
      "name": "Rock_Quartzite_Brick"
    },
    {
      "x": -7,
      "y": 13,
      "z": -2,
      "name": "Rock_Quartzite"
    },
    {
      "x": -7,
      "y": 14,
      "z": -2,
      "name": "Rock_Quartzite"
    },
    {
      "x": -7,
      "y": 15,
      "z": -2,
      "name": "Rock_Quartzite"
    },
    {
      "x": -7,
      "y": 0,
      "z": -1,
      "name": "Rock_Stone_Cobble"
    },
    {
      "x": -7,
      "y": 1,
      "z": -1,
      "name": "Rock_Quartzite_Brick"
    },
    {
      "x": -7,
      "y": 2,
      "z": -1,
      "name": "Rock_Stone"
    },
    {
      "x": -7,
      "y": 3,
      "z": -1,
      "name": "Rock_Stone"
    },
    {
      "x": -7,
      "y": 4,
      "z": -1,
      "name": "Rock_Stone"
    },
    {
      "x": -7,
      "y": 5,
      "z": -1,
      "name": "Rock_Stone"
    },
    {
      "x": -7,
      "y": 6,
      "z": -1,
      "name": "Rock_Stone"
    },
    {
      "x": -7,
      "y": 7,
      "z": -1,
      "name": "Rock_Quartzite_Brick"
    },
    {
      "x": -7,
      "y": 8,
      "z": -1,
      "name": "Rock_Quartzite"
    },
    {
      "x": -7,
      "y": 9,
      "z": -1,
      "name": "Rock_Quartzite_Brick"
    },
    {
      "x": -7,
      "y": 10,
      "z": -1,
      "name": "Rock_Quartzite_Brick"
    },
    {
      "x": -7,
      "y": 11,
      "z": -1,
      "name": "Rock_Quartzite_Brick"
    },
    {
      "x": -7,
      "y": 12,
      "z": -1,
      "name": "Rock_Quartzite_Brick"
    },
    {
      "x": -7,
      "y": 13,
      "z": -1,
      "name": "Rock_Quartzite"
    },
    {
      "x": -7,
      "y": 14,
      "z": -1,
      "name": "Rock_Quartzite"
    },
    {
      "x": -7,
      "y": 15,
      "z": -1,
      "name": "Rock_Quartzite"
    },
    {
      "x": -7,
      "y": 0,
      "z": 0,
      "name": "Rock_Stone_Cobble"
    },
    {
      "x": -7,
      "y": 1,
      "z": 0,
      "name": "Rock_Quartzite_Brick"
    },
    {
      "x": -7,
      "y": 2,
      "z": 0,
      "name": "Rock_Quartzite_Brick"
    },
    {
      "x": -7,
      "y": 3,
      "z": 0,
      "name": "Rock_Quartzite_Brick"
    },
    {
      "x": -7,
      "y": 4,
      "z": 0,
      "name": "Rock_Quartzite"
    },
    {
      "x": -7,
      "y": 5,
      "z": 0,
      "name": "Rock_Quartzite"
    },
    {
      "x": -7,
      "y": 6,
      "z": 0,
      "name": "Rock_Quartzite"
    },
    {
      "x": -7,
      "y": 7,
      "z": 0,
      "name": "Rock_Quartzite"
    },
    {
      "x": -7,
      "y": 8,
      "z": 0,
      "name": "Rock_Quartzite"
    },
    {
      "x": -7,
      "y": 9,
      "z": 0,
      "name": "Rock_Quartzite"
    },
    {
      "x": -7,
      "y": 10,
      "z": 0,
      "name": "Rock_Quartzite"
    },
    {
      "x": -7,
      "y": 11,
      "z": 0,
      "name": "Rock_Quartzite"
    },
    {
      "x": -7,
      "y": 12,
      "z": 0,
      "name": "Rock_Quartzite"
    },
    {
      "x": -7,
      "y": 13,
      "z": 0,
      "name": "Rock_Quartzite"
    },
    {
      "x": -7,
      "y": 14,
      "z": 0,
      "name": "Rock_Quartzite"
    },
    {
      "x": -7,
      "y": 15,
      "z": 0,
      "name": "Rock_Quartzite"
    },
    {
      "x": -6,
      "y": 0,
      "z": -12,
      "name": "Rock_Stone_Cobble"
    },
    {
      "x": -6,
      "y": 1,
      "z": -12,
      "name": "Rock_Quartzite_Brick"
    },
    {
      "x": -6,
      "y": 2,
      "z": -12,
      "name": "Rock_Quartzite_Brick"
    },
    {
      "x": -6,
      "y": 3,
      "z": -12,
      "name": "Rock_Quartzite_Brick"
    },
    {
      "x": -6,
      "y": 4,
      "z": -12,
      "name": "Rock_Quartzite_Brick"
    },
    {
      "x": -6,
      "y": 5,
      "z": -12,
      "name": "Rock_Quartzite"
    },
    {
      "x": -6,
      "y": 6,
      "z": -12,
      "name": "Rock_Quartzite"
    },
    {
      "x": -6,
      "y": 7,
      "z": -12,
      "name": "Rock_Quartzite"
    },
    {
      "x": -6,
      "y": 8,
      "z": -12,
      "name": "Rock_Quartzite"
    },
    {
      "x": -6,
      "y": 9,
      "z": -12,
      "name": "Rock_Quartzite"
    },
    {
      "x": -6,
      "y": 10,
      "z": -12,
      "name": "Rock_Quartzite"
    },
    {
      "x": -6,
      "y": 11,
      "z": -12,
      "name": "Rock_Quartzite"
    },
    {
      "x": -6,
      "y": 12,
      "z": -12,
      "name": "Rock_Quartzite"
    },
    {
      "x": -6,
      "y": 13,
      "z": -12,
      "name": "Rock_Quartzite"
    },
    {
      "x": -6,
      "y": 14,
      "z": -12,
      "name": "Rock_Quartzite"
    },
    {
      "x": -6,
      "y": 15,
      "z": -12,
      "name": "Rock_Quartzite"
    },
    {
      "x": -6,
      "y": 0,
      "z": -11,
      "name": "Rock_Stone_Cobble"
    },
    {
      "x": -6,
      "y": 1,
      "z": -11,
      "name": "Rock_Stone_Brick"
    },
    {
      "x": -6,
      "y": 2,
      "z": -11,
      "name": "Block_Spawner_Block",
      "components": {
        "Components": {
          "BlockSpawner": {
            "BlockSpawnerId": "Zone1_Encounters_Tier3"
          }
        }
      }
    },
    {
      "x": -6,
      "y": 3,
      "z": -11,
      "name": "Empty"
    },
    {
      "x": -6,
      "y": 4,
      "z": -11,
      "name": "Empty"
    },
    {
      "x": -6,
      "y": 5,
      "z": -11,
      "name": "Empty"
    },
    {
      "x": -6,
      "y": 6,
      "z": -11,
      "name": "Rock_Quartzite_Brick"
    },
    {
      "x": -6,
      "y": 7,
      "z": -11,
      "name": "Rock_Quartzite_Brick"
    },
    {
      "x": -6,
      "y": 8,
      "z": -11,
      "name": "Rock_Quartzite_Brick"
    },
    {
      "x": -6,
      "y": 9,
      "z": -11,
      "name": "Rock_Quartzite_Brick"
    },
    {
      "x": -6,
      "y": 10,
      "z": -11,
      "name": "Rock_Quartzite"
    },
    {
      "x": -6,
      "y": 11,
      "z": -11,
      "name": "Rock_Quartzite_Brick"
    },
    {
      "x": -6,
      "y": 12,
      "z": -11,
      "name": "Rock_Quartzite_Brick"
    },
    {
      "x": -6,
      "y": 13,
      "z": -11,
      "name": "Rock_Quartzite"
    },
    {
      "x": -6,
      "y": 14,
      "z": -11,
      "name": "Rock_Quartzite"
    },
    {
      "x": -6,
      "y": 15,
      "z": -11,
      "name": "Rock_Quartzite"
    },
    {
      "x": -6,
      "y": 0,
      "z": -10,
      "name": "Rock_Stone_Cobble"
    },
    {
      "x": -6,
      "y": 1,
      "z": -10,
      "name": "Rock_Stone_Brick"
    },
    {
      "x": -6,
      "y": 2,
      "z": -10,
      "name": "Empty"
    },
    {
      "x": -6,
      "y": 3,
      "z": -10,
      "name": "Empty"
    },
    {
      "x": -6,
      "y": 4,
      "z": -10,
      "name": "Empty"
    },
    {
      "x": -6,
      "y": 5,
      "z": -10,
      "name": "Empty"
    },
    {
      "x": -6,
      "y": 6,
      "z": -10,
      "name": "Empty"
    },
    {
      "x": -6,
      "y": 7,
      "z": -10,
      "name": "Rock_Quartzite_Brick"
    },
    {
      "x": -6,
      "y": 8,
      "z": -10,
      "name": "Rock_Quartzite_Brick"
    },
    {
      "x": -6,
      "y": 9,
      "z": -10,
      "name": "Rock_Quartzite_Brick"
    },
    {
      "x": -6,
      "y": 10,
      "z": -10,
      "name": "Rock_Quartzite"
    },
    {
      "x": -6,
      "y": 11,
      "z": -10,
      "name": "Rock_Quartzite"
    },
    {
      "x": -6,
      "y": 12,
      "z": -10,
      "name": "Rock_Quartzite_Brick"
    },
    {
      "x": -6,
      "y": 13,
      "z": -10,
      "name": "Rock_Quartzite"
    },
    {
      "x": -6,
      "y": 14,
      "z": -10,
      "name": "Rock_Quartzite"
    },
    {
      "x": -6,
      "y": 15,
      "z": -10,
      "name": "Rock_Quartzite"
    },
    {
      "x": -6,
      "y": 0,
      "z": -9,
      "name": "Rock_Stone_Cobble"
    },
    {
      "x": -6,
      "y": 1,
      "z": -9,
      "name": "Rock_Stone_Cobble"
    },
    {
      "x": -6,
      "y": 2,
      "z": -9,
      "name": "Furniture_Ancient_Bed",
      "components": {
        "Components": {
          "RespawnBlock": {}
        }
      },
      "filler": 960,
      "rotation": 2
    },
    {
      "x": -6,
      "y": 3,
      "z": -9,
      "name": "Furniture_Ancient_Bed",
      "components": {
        "Components": {
          "RespawnBlock": {}
        }
      },
      "filler": 1984,
      "rotation": 2
    },
    {
      "x": -6,
      "y": 4,
      "z": -9,
      "name": "Empty"
    },
    {
      "x": -6,
      "y": 5,
      "z": -9,
      "name": "Empty"
    },
    {
      "x": -6,
      "y": 6,
      "z": -9,
      "name": "Empty"
    },
    {
      "x": -6,
      "y": 7,
      "z": -9,
      "name": "Rock_Quartzite_Brick"
    },
    {
      "x": -6,
      "y": 8,
      "z": -9,
      "name": "Rock_Quartzite_Brick"
    },
    {
      "x": -6,
      "y": 9,
      "z": -9,
      "name": "Rock_Quartzite_Brick"
    },
    {
      "x": -6,
      "y": 10,
      "z": -9,
      "name": "Rock_Quartzite_Brick"
    },
    {
      "x": -6,
      "y": 11,
      "z": -9,
      "name": "Rock_Quartzite"
    },
    {
      "x": -6,
      "y": 12,
      "z": -9,
      "name": "Rock_Quartzite_Brick"
    },
    {
      "x": -6,
      "y": 13,
      "z": -9,
      "name": "Rock_Quartzite"
    },
    {
      "x": -6,
      "y": 14,
      "z": -9,
      "name": "Rock_Quartzite"
    },
    {
      "x": -6,
      "y": 15,
      "z": -9,
      "name": "Rock_Quartzite"
    },
    {
      "x": -6,
      "y": 0,
      "z": -8,
      "name": "Rock_Stone_Cobble"
    },
    {
      "x": -6,
      "y": 1,
      "z": -8,
      "name": "Rock_Stone_Cobble"
    },
    {
      "x": -6,
      "y": 2,
      "z": -8,
      "name": "Furniture_Ancient_Bed",
      "components": {
        "Components": {
          "RespawnBlock": {}
        }
      },
      "filler": 992,
      "rotation": 2
    },
    {
      "x": -6,
      "y": 3,
      "z": -8,
      "name": "Furniture_Ancient_Bed",
      "components": {
        "Components": {
          "RespawnBlock": {}
        }
      },
      "filler": 2016,
      "rotation": 2
    },
    {
      "x": -6,
      "y": 4,
      "z": -8,
      "name": "Empty"
    },
    {
      "x": -6,
      "y": 5,
      "z": -8,
      "name": "Empty"
    },
    {
      "x": -6,
      "y": 6,
      "z": -8,
      "name": "Empty"
    },
    {
      "x": -6,
      "y": 7,
      "z": -8,
      "name": "Rock_Quartzite_Brick"
    },
    {
      "x": -6,
      "y": 8,
      "z": -8,
      "name": "Rock_Quartzite_Brick"
    },
    {
      "x": -6,
      "y": 9,
      "z": -8,
      "name": "Rock_Quartzite_Brick"
    },
    {
      "x": -6,
      "y": 10,
      "z": -8,
      "name": "Rock_Quartzite_Brick"
    },
    {
      "x": -6,
      "y": 11,
      "z": -8,
      "name": "Rock_Quartzite"
    },
    {
      "x": -6,
      "y": 12,
      "z": -8,
      "name": "Rock_Quartzite"
    },
    {
      "x": -6,
      "y": 13,
      "z": -8,
      "name": "Rock_Quartzite"
    },
    {
      "x": -6,
      "y": 14,
      "z": -8,
      "name": "Rock_Quartzite"
    },
    {
      "x": -6,
      "y": 15,
      "z": -8,
      "name": "Rock_Quartzite"
    },
    {
      "x": -6,
      "y": 0,
      "z": -7,
      "name": "Rock_Stone_Cobble"
    },
    {
      "x": -6,
      "y": 1,
      "z": -7,
      "name": "Rock_Stone_Cobble"
    },
    {
      "x": -6,
      "y": 2,
      "z": -7,
      "name": "Furniture_Ancient_Bed",
      "components": {
        "Components": {
          "RespawnBlock": {}
        }
      },
      "rotation": 2
    },
    {
      "x": -6,
      "y": 3,
      "z": -7,
      "name": "Furniture_Ancient_Bed",
      "components": {
        "Components": {
          "RespawnBlock": {}
        }
      },
      "filler": 1024,
      "rotation": 2
    },
    {
      "x": -6,
      "y": 4,
      "z": -7,
      "name": "Empty"
    },
    {
      "x": -6,
      "y": 5,
      "z": -7,
      "name": "Empty"
    },
    {
      "x": -6,
      "y": 6,
      "z": -7,
      "name": "Rock_Quartzite_Brick_Half",
      "rotation": 8
    },
    {
      "x": -6,
      "y": 7,
      "z": -7,
      "name": "Rock_Quartzite_Brick"
    },
    {
      "x": -6,
      "y": 8,
      "z": -7,
      "name": "Rock_Stone_Brick"
    },
    {
      "x": -6,
      "y": 9,
      "z": -7,
      "name": "Empty"
    },
    {
      "x": -6,
      "y": 10,
      "z": -7,
      "name": "Empty"
    },
    {
      "x": -6,
      "y": 11,
      "z": -7,
      "name": "Empty"
    },
    {
      "x": -6,
      "y": 12,
      "z": -7,
      "name": "Rock_Quartzite_Brick"
    },
    {
      "x": -6,
      "y": 13,
      "z": -7,
      "name": "Rock_Quartzite"
    },
    {
      "x": -6,
      "y": 14,
      "z": -7,
      "name": "Rock_Quartzite"
    },
    {
      "x": -6,
      "y": 15,
      "z": -7,
      "name": "Rock_Quartzite"
    },
    {
      "x": -6,
      "y": 0,
      "z": -6,
      "name": "Rock_Stone_Cobble"
    },
    {
      "x": -6,
      "y": 1,
      "z": -6,
      "name": "Rock_Quartzite_Brick"
    },
    {
      "x": -6,
      "y": 2,
      "z": -6,
      "name": "Rock_Quartzite_Brick"
    },
    {
      "x": -6,
      "y": 3,
      "z": -6,
      "name": "Rock_Quartzite_Brick"
    },
    {
      "x": -6,
      "y": 4,
      "z": -6,
      "name": "Rock_Quartzite"
    },
    {
      "x": -6,
      "y": 5,
      "z": -6,
      "name": "Rock_Quartzite"
    },
    {
      "x": -6,
      "y": 6,
      "z": -6,
      "name": "Rock_Quartzite_Brick"
    },
    {
      "x": -6,
      "y": 7,
      "z": -6,
      "name": "Rock_Quartzite_Brick"
    },
    {
      "x": -6,
      "y": 8,
      "z": -6,
      "name": "Rock_Stone_Brick"
    },
    {
      "x": -6,
      "y": 9,
      "z": -6,
      "name": "Empty"
    },
    {
      "x": -6,
      "y": 10,
      "z": -6,
      "name": "Empty"
    },
    {
      "x": -6,
      "y": 11,
      "z": -6,
      "name": "Empty"
    },
    {
      "x": -6,
      "y": 12,
      "z": -6,
      "name": "Rock_Quartzite_Brick_Half",
      "rotation": 8
    },
    {
      "x": -6,
      "y": 13,
      "z": -6,
      "name": "Rock_Quartzite"
    },
    {
      "x": -6,
      "y": 14,
      "z": -6,
      "name": "Rock_Quartzite"
    },
    {
      "x": -6,
      "y": 15,
      "z": -6,
      "name": "Rock_Quartzite"
    },
    {
      "x": -6,
      "y": 0,
      "z": -5,
      "name": "Rock_Stone_Cobble"
    },
    {
      "x": -6,
      "y": 1,
      "z": -5,
      "name": "Rock_Stone"
    },
    {
      "x": -6,
      "y": 2,
      "z": -5,
      "name": "Rock_Stone"
    },
    {
      "x": -6,
      "y": 3,
      "z": -5,
      "name": "Rock_Quartzite_Brick_Half",
      "rotation": 5
    },
    {
      "x": -6,
      "y": 4,
      "z": -5,
      "name": "Empty"
    },
    {
      "x": -6,
      "y": 5,
      "z": -5,
      "name": "Rock_Quartzite_Brick"
    },
    {
      "x": -6,
      "y": 6,
      "z": -5,
      "name": "Rock_Quartzite"
    },
    {
      "x": -6,
      "y": 7,
      "z": -5,
      "name": "Rock_Quartzite_Brick"
    },
    {
      "x": -6,
      "y": 8,
      "z": -5,
      "name": "Rock_Stone_Cobble"
    },
    {
      "x": -6,
      "y": 9,
      "z": -5,
      "name": "Empty"
    },
    {
      "x": -6,
      "y": 10,
      "z": -5,
      "name": "Empty"
    },
    {
      "x": -6,
      "y": 11,
      "z": -5,
      "name": "Empty"
    },
    {
      "x": -6,
      "y": 12,
      "z": -5,
      "name": "Rock_Quartzite_Brick_Half",
      "rotation": 8
    },
    {
      "x": -6,
      "y": 13,
      "z": -5,
      "name": "Rock_Quartzite"
    },
    {
      "x": -6,
      "y": 14,
      "z": -5,
      "name": "Rock_Quartzite"
    },
    {
      "x": -6,
      "y": 15,
      "z": -5,
      "name": "Rock_Quartzite"
    },
    {
      "x": -6,
      "y": 0,
      "z": -4,
      "name": "Rock_Stone_Cobble"
    },
    {
      "x": -6,
      "y": 1,
      "z": -4,
      "name": "Rock_Stone"
    },
    {
      "x": -6,
      "y": 2,
      "z": -4,
      "name": "Rock_Stone"
    },
    {
      "x": -6,
      "y": 3,
      "z": -4,
      "name": "Plant_Moss_Block_Blue"
    },
    {
      "x": -6,
      "y": 4,
      "z": -4,
      "name": "Empty"
    },
    {
      "x": -6,
      "y": 5,
      "z": -4,
      "name": "Empty"
    },
    {
      "x": -6,
      "y": 6,
      "z": -4,
      "name": "Empty"
    },
    {
      "x": -6,
      "y": 7,
      "z": -4,
      "name": "Rock_Quartzite_Brick"
    },
    {
      "x": -6,
      "y": 8,
      "z": -4,
      "name": "Rock_Stone_Cobble"
    },
    {
      "x": -6,
      "y": 9,
      "z": -4,
      "name": "Empty"
    },
    {
      "x": -6,
      "y": 10,
      "z": -4,
      "name": "Empty"
    },
    {
      "x": -6,
      "y": 11,
      "z": -4,
      "name": "Empty"
    },
    {
      "x": -6,
      "y": 12,
      "z": -4,
      "name": "Empty"
    },
    {
      "x": -6,
      "y": 13,
      "z": -4,
      "name": "Rock_Quartzite"
    },
    {
      "x": -6,
      "y": 14,
      "z": -4,
      "name": "Rock_Quartzite"
    },
    {
      "x": -6,
      "y": 15,
      "z": -4,
      "name": "Rock_Quartzite"
    },
    {
      "x": -6,
      "y": 0,
      "z": -3,
      "name": "Rock_Stone_Cobble"
    },
    {
      "x": -6,
      "y": 1,
      "z": -3,
      "name": "Rock_Stone"
    },
    {
      "x": -6,
      "y": 2,
      "z": -3,
      "name": "Rock_Stone"
    },
    {
      "x": -6,
      "y": 3,
      "z": -3,
      "name": "Rock_Stone"
    },
    {
      "x": -6,
      "y": 4,
      "z": -3,
      "name": "Rock_Stone"
    },
    {
      "x": -6,
      "y": 5,
      "z": -3,
      "name": "Rock_Stone"
    },
    {
      "x": -6,
      "y": 6,
      "z": -3,
      "name": "Empty"
    },
    {
      "x": -6,
      "y": 7,
      "z": -3,
      "name": "Empty"
    },
    {
      "x": -6,
      "y": 8,
      "z": -3,
      "name": "Rock_Quartzite_Brick"
    },
    {
      "x": -6,
      "y": 9,
      "z": -3,
      "name": "Empty"
    },
    {
      "x": -6,
      "y": 10,
      "z": -3,
      "name": "Empty"
    },
    {
      "x": -6,
      "y": 11,
      "z": -3,
      "name": "Empty"
    },
    {
      "x": -6,
      "y": 12,
      "z": -3,
      "name": "Rock_Quartzite_Brick_Half",
      "rotation": 8
    },
    {
      "x": -6,
      "y": 13,
      "z": -3,
      "name": "Rock_Quartzite"
    },
    {
      "x": -6,
      "y": 14,
      "z": -3,
      "name": "Rock_Quartzite"
    },
    {
      "x": -6,
      "y": 15,
      "z": -3,
      "name": "Rock_Quartzite"
    },
    {
      "x": -6,
      "y": 0,
      "z": -2,
      "name": "Rock_Stone_Cobble"
    },
    {
      "x": -6,
      "y": 1,
      "z": -2,
      "name": "Rock_Stone"
    },
    {
      "x": -6,
      "y": 2,
      "z": -2,
      "name": "Rock_Stone"
    },
    {
      "x": -6,
      "y": 3,
      "z": -2,
      "name": "Rock_Stone"
    },
    {
      "x": -6,
      "y": 4,
      "z": -2,
      "name": "Rock_Stone"
    },
    {
      "x": -6,
      "y": 5,
      "z": -2,
      "name": "Plant_Moss_Block_Blue"
    },
    {
      "x": -6,
      "y": 6,
      "z": -2,
      "name": "Empty"
    },
    {
      "x": -6,
      "y": 7,
      "z": -2,
      "name": "Rock_Quartzite_Brick"
    },
    {
      "x": -6,
      "y": 8,
      "z": -2,
      "name": "Rock_Quartzite_Brick"
    },
    {
      "x": -6,
      "y": 9,
      "z": -2,
      "name": "Empty"
    },
    {
      "x": -6,
      "y": 10,
      "z": -2,
      "name": "Rock_Quartzite_Brick_Half",
      "rotation": 5
    },
    {
      "x": -6,
      "y": 11,
      "z": -2,
      "name": "Rock_Quartzite_Brick"
    },
    {
      "x": -6,
      "y": 12,
      "z": -2,
      "name": "Rock_Quartzite_Brick"
    },
    {
      "x": -6,
      "y": 13,
      "z": -2,
      "name": "Rock_Quartzite"
    },
    {
      "x": -6,
      "y": 14,
      "z": -2,
      "name": "Rock_Quartzite"
    },
    {
      "x": -6,
      "y": 15,
      "z": -2,
      "name": "Rock_Quartzite"
    },
    {
      "x": -6,
      "y": 0,
      "z": -1,
      "name": "Rock_Stone_Cobble"
    },
    {
      "x": -6,
      "y": 1,
      "z": -1,
      "name": "Rock_Stone"
    },
    {
      "x": -6,
      "y": 2,
      "z": -1,
      "name": "Rock_Stone"
    },
    {
      "x": -6,
      "y": 3,
      "z": -1,
      "name": "Rock_Stone"
    },
    {
      "x": -6,
      "y": 4,
      "z": -1,
      "name": "Rock_Stone"
    },
    {
      "x": -6,
      "y": 5,
      "z": -1,
      "name": "Plant_Moss_Block_Blue"
    },
    {
      "x": -6,
      "y": 6,
      "z": -1,
      "name": "Empty"
    },
    {
      "x": -6,
      "y": 7,
      "z": -1,
      "name": "Rock_Quartzite_Brick"
    },
    {
      "x": -6,
      "y": 8,
      "z": -1,
      "name": "Rock_Quartzite"
    },
    {
      "x": -6,
      "y": 9,
      "z": -1,
      "name": "Empty"
    },
    {
      "x": -6,
      "y": 10,
      "z": -1,
      "name": "Rock_Quartzite_Brick_Half",
      "rotation": 5
    },
    {
      "x": -6,
      "y": 11,
      "z": -1,
      "name": "Rock_Quartzite_Brick"
    },
    {
      "x": -6,
      "y": 12,
      "z": -1,
      "name": "Rock_Quartzite_Brick"
    },
    {
      "x": -6,
      "y": 13,
      "z": -1,
      "name": "Rock_Quartzite"
    },
    {
      "x": -6,
      "y": 14,
      "z": -1,
      "name": "Rock_Quartzite"
    },
    {
      "x": -6,
      "y": 15,
      "z": -1,
      "name": "Rock_Quartzite"
    },
    {
      "x": -6,
      "y": 0,
      "z": 0,
      "name": "Rock_Stone_Cobble"
    },
    {
      "x": -6,
      "y": 1,
      "z": 0,
      "name": "Rock_Quartzite_Brick"
    },
    {
      "x": -6,
      "y": 2,
      "z": 0,
      "name": "Rock_Quartzite_Brick"
    },
    {
      "x": -6,
      "y": 3,
      "z": 0,
      "name": "Rock_Quartzite_Brick"
    },
    {
      "x": -6,
      "y": 4,
      "z": 0,
      "name": "Rock_Quartzite_Brick"
    },
    {
      "x": -6,
      "y": 5,
      "z": 0,
      "name": "Rock_Quartzite_Brick"
    },
    {
      "x": -6,
      "y": 6,
      "z": 0,
      "name": "Rock_Quartzite"
    },
    {
      "x": -6,
      "y": 7,
      "z": 0,
      "name": "Rock_Quartzite"
    },
    {
      "x": -6,
      "y": 8,
      "z": 0,
      "name": "Rock_Quartzite"
    },
    {
      "x": -6,
      "y": 9,
      "z": 0,
      "name": "Rock_Quartzite_Brick"
    },
    {
      "x": -6,
      "y": 10,
      "z": 0,
      "name": "Rock_Quartzite"
    },
    {
      "x": -6,
      "y": 11,
      "z": 0,
      "name": "Rock_Quartzite"
    },
    {
      "x": -6,
      "y": 12,
      "z": 0,
      "name": "Rock_Quartzite"
    },
    {
      "x": -6,
      "y": 13,
      "z": 0,
      "name": "Rock_Quartzite"
    },
    {
      "x": -6,
      "y": 14,
      "z": 0,
      "name": "Rock_Quartzite"
    },
    {
      "x": -6,
      "y": 15,
      "z": 0,
      "name": "Rock_Quartzite"
    },
    {
      "x": -5,
      "y": 0,
      "z": -12,
      "name": "Rock_Stone_Cobble"
    },
    {
      "x": -5,
      "y": 1,
      "z": -12,
      "name": "Rock_Quartzite_Brick"
    },
    {
      "x": -5,
      "y": 2,
      "z": -12,
      "name": "Rock_Quartzite_Brick"
    },
    {
      "x": -5,
      "y": 3,
      "z": -12,
      "name": "Rock_Quartzite"
    },
    {
      "x": -5,
      "y": 4,
      "z": -12,
      "name": "Rock_Quartzite"
    },
    {
      "x": -5,
      "y": 5,
      "z": -12,
      "name": "Rock_Quartzite"
    },
    {
      "x": -5,
      "y": 6,
      "z": -12,
      "name": "Rock_Quartzite"
    },
    {
      "x": -5,
      "y": 7,
      "z": -12,
      "name": "Rock_Quartzite"
    },
    {
      "x": -5,
      "y": 8,
      "z": -12,
      "name": "Rock_Quartzite"
    },
    {
      "x": -5,
      "y": 9,
      "z": -12,
      "name": "Rock_Quartzite_Brick"
    },
    {
      "x": -5,
      "y": 10,
      "z": -12,
      "name": "Rock_Quartzite_Brick"
    },
    {
      "x": -5,
      "y": 11,
      "z": -12,
      "name": "Rock_Quartzite_Brick"
    },
    {
      "x": -5,
      "y": 12,
      "z": -12,
      "name": "Rock_Quartzite"
    },
    {
      "x": -5,
      "y": 13,
      "z": -12,
      "name": "Rock_Quartzite"
    },
    {
      "x": -5,
      "y": 14,
      "z": -12,
      "name": "Rock_Quartzite"
    },
    {
      "x": -5,
      "y": 15,
      "z": -12,
      "name": "Rock_Quartzite"
    },
    {
      "x": -5,
      "y": 0,
      "z": -11,
      "name": "Rock_Stone_Cobble"
    },
    {
      "x": -5,
      "y": 1,
      "z": -11,
      "name": "Rock_Stone_Cobble"
    },
    {
      "x": -5,
      "y": 2,
      "z": -11,
      "name": "Furniture_Ancient_Wardrobe",
      "filler": 31
    },
    {
      "x": -5,
      "y": 3,
      "z": -11,
      "name": "Furniture_Ancient_Wardrobe",
      "filler": 1055
    },
    {
      "x": -5,
      "y": 4,
      "z": -11,
      "name": "Empty"
    },
    {
      "x": -5,
      "y": 5,
      "z": -11,
      "name": "Empty"
    },
    {
      "x": -5,
      "y": 6,
      "z": -11,
      "name": "Rock_Quartzite_Brick_Half",
      "rotation": 8
    },
    {
      "x": -5,
      "y": 7,
      "z": -11,
      "name": "Rock_Quartzite_Brick"
    },
    {
      "x": -5,
      "y": 8,
      "z": -11,
      "name": "Rock_Stone_Brick"
    },
    {
      "x": -5,
      "y": 9,
      "z": -11,
      "name": "Furniture_Ancient_Barrel"
    },
    {
      "x": -5,
      "y": 10,
      "z": -11,
      "name": "Empty"
    },
    {
      "x": -5,
      "y": 11,
      "z": -11,
      "name": "Rock_Quartzite_Brick_Half",
      "rotation": 5
    },
    {
      "x": -5,
      "y": 12,
      "z": -11,
      "name": "Rock_Quartzite_Brick"
    },
    {
      "x": -5,
      "y": 13,
      "z": -11,
      "name": "Rock_Quartzite"
    },
    {
      "x": -5,
      "y": 14,
      "z": -11,
      "name": "Rock_Quartzite"
    },
    {
      "x": -5,
      "y": 15,
      "z": -11,
      "name": "Rock_Quartzite"
    },
    {
      "x": -5,
      "y": 0,
      "z": -10,
      "name": "Rock_Stone_Cobble"
    },
    {
      "x": -5,
      "y": 1,
      "z": -10,
      "name": "Rock_Stone_Cobble"
    },
    {
      "x": -5,
      "y": 2,
      "z": -10,
      "name": "Empty"
    },
    {
      "x": -5,
      "y": 3,
      "z": -10,
      "name": "Empty"
    },
    {
      "x": -5,
      "y": 4,
      "z": -10,
      "name": "Empty"
    },
    {
      "x": -5,
      "y": 5,
      "z": -10,
      "name": "Empty"
    },
    {
      "x": -5,
      "y": 6,
      "z": -10,
      "name": "Empty"
    },
    {
      "x": -5,
      "y": 7,
      "z": -10,
      "name": "Rock_Quartzite_Brick"
    },
    {
      "x": -5,
      "y": 8,
      "z": -10,
      "name": "Rock_Stone_Brick"
    },
    {
      "x": -5,
      "y": 9,
      "z": -10,
      "name": "Furniture_Ancient_Bookshelf",
      "rotation": 1
    },
    {
      "x": -5,
      "y": 10,
      "z": -10,
      "name": "Empty"
    },
    {
      "x": -5,
      "y": 11,
      "z": -10,
      "name": "Rock_Quartzite_Brick_Half",
      "rotation": 5
    },
    {
      "x": -5,
      "y": 12,
      "z": -10,
      "name": "Rock_Quartzite_Brick"
    },
    {
      "x": -5,
      "y": 13,
      "z": -10,
      "name": "Rock_Quartzite"
    },
    {
      "x": -5,
      "y": 14,
      "z": -10,
      "name": "Rock_Quartzite"
    },
    {
      "x": -5,
      "y": 15,
      "z": -10,
      "name": "Rock_Quartzite"
    },
    {
      "x": -5,
      "y": 0,
      "z": -9,
      "name": "Rock_Stone_Cobble"
    },
    {
      "x": -5,
      "y": 1,
      "z": -9,
      "name": "Rock_Stone_Cobble"
    },
    {
      "x": -5,
      "y": 2,
      "z": -9,
      "name": "Empty"
    },
    {
      "x": -5,
      "y": 3,
      "z": -9,
      "name": "Empty"
    },
    {
      "x": -5,
      "y": 4,
      "z": -9,
      "name": "Empty"
    },
    {
      "x": -5,
      "y": 5,
      "z": -9,
      "name": "Empty"
    },
    {
      "x": -5,
      "y": 6,
      "z": -9,
      "name": "Empty"
    },
    {
      "x": -5,
      "y": 7,
      "z": -9,
      "name": "Rock_Quartzite_Brick"
    },
    {
      "x": -5,
      "y": 8,
      "z": -9,
      "name": "Rock_Stone_Cobble"
    },
    {
      "x": -5,
      "y": 9,
      "z": -9,
      "name": "Empty"
    },
    {
      "x": -5,
      "y": 10,
      "z": -9,
      "name": "Empty"
    },
    {
      "x": -5,
      "y": 11,
      "z": -9,
      "name": "Rock_Quartzite_Brick_Half",
      "rotation": 5
    },
    {
      "x": -5,
      "y": 12,
      "z": -9,
      "name": "Rock_Quartzite_Brick"
    },
    {
      "x": -5,
      "y": 13,
      "z": -9,
      "name": "Rock_Quartzite"
    },
    {
      "x": -5,
      "y": 14,
      "z": -9,
      "name": "Rock_Quartzite"
    },
    {
      "x": -5,
      "y": 15,
      "z": -9,
      "name": "Rock_Quartzite"
    },
    {
      "x": -5,
      "y": 0,
      "z": -8,
      "name": "Rock_Stone_Cobble"
    },
    {
      "x": -5,
      "y": 1,
      "z": -8,
      "name": "Rock_Stone_Cobble"
    },
    {
      "x": -5,
      "y": 2,
      "z": -8,
      "name": "Empty"
    },
    {
      "x": -5,
      "y": 3,
      "z": -8,
      "name": "Empty"
    },
    {
      "x": -5,
      "y": 4,
      "z": -8,
      "name": "Empty"
    },
    {
      "x": -5,
      "y": 5,
      "z": -8,
      "name": "Empty"
    },
    {
      "x": -5,
      "y": 6,
      "z": -8,
      "name": "Empty"
    },
    {
      "x": -5,
      "y": 7,
      "z": -8,
      "name": "Rock_Quartzite_Brick"
    },
    {
      "x": -5,
      "y": 8,
      "z": -8,
      "name": "Rock_Quartzite_Brick"
    },
    {
      "x": -5,
      "y": 9,
      "z": -8,
      "name": "Rock_Quartzite_Brick"
    },
    {
      "x": -5,
      "y": 10,
      "z": -8,
      "name": "Rock_Quartzite"
    },
    {
      "x": -5,
      "y": 11,
      "z": -8,
      "name": "Rock_Quartzite_Brick"
    },
    {
      "x": -5,
      "y": 12,
      "z": -8,
      "name": "Rock_Quartzite_Brick"
    },
    {
      "x": -5,
      "y": 13,
      "z": -8,
      "name": "Rock_Quartzite"
    },
    {
      "x": -5,
      "y": 14,
      "z": -8,
      "name": "Rock_Quartzite"
    },
    {
      "x": -5,
      "y": 15,
      "z": -8,
      "name": "Rock_Quartzite"
    },
    {
      "x": -5,
      "y": 0,
      "z": -7,
      "name": "Rock_Stone_Cobble"
    },
    {
      "x": -5,
      "y": 1,
      "z": -7,
      "name": "Rock_Stone_Cobble"
    },
    {
      "x": -5,
      "y": 2,
      "z": -7,
      "name": "Plant_Moss_Block_Blue"
    },
    {
      "x": -5,
      "y": 3,
      "z": -7,
      "name": "Empty"
    },
    {
      "x": -5,
      "y": 4,
      "z": -7,
      "name": "Empty"
    },
    {
      "x": -5,
      "y": 5,
      "z": -7,
      "name": "Empty"
    },
    {
      "x": -5,
      "y": 6,
      "z": -7,
      "name": "Rock_Quartzite_Brick_Half",
      "rotation": 8
    },
    {
      "x": -5,
      "y": 7,
      "z": -7,
      "name": "Rock_Quartzite_Brick"
    },
    {
      "x": -5,
      "y": 8,
      "z": -7,
      "name": "Rock_Stone_Brick"
    },
    {
      "x": -5,
      "y": 9,
      "z": -7,
      "name": "Empty"
    },
    {
      "x": -5,
      "y": 10,
      "z": -7,
      "name": "Empty"
    },
    {
      "x": -5,
      "y": 11,
      "z": -7,
      "name": "Empty"
    },
    {
      "x": -5,
      "y": 12,
      "z": -7,
      "name": "Rock_Quartzite_Brick_Half",
      "rotation": 8
    },
    {
      "x": -5,
      "y": 13,
      "z": -7,
      "name": "Rock_Quartzite"
    },
    {
      "x": -5,
      "y": 14,
      "z": -7,
      "name": "Rock_Quartzite"
    },
    {
      "x": -5,
      "y": 15,
      "z": -7,
      "name": "Rock_Quartzite"
    },
    {
      "x": -5,
      "y": 0,
      "z": -6,
      "name": "Rock_Stone_Cobble"
    },
    {
      "x": -5,
      "y": 1,
      "z": -6,
      "name": "Rock_Quartzite_Brick"
    },
    {
      "x": -5,
      "y": 2,
      "z": -6,
      "name": "Rock_Quartzite_Brick"
    },
    {
      "x": -5,
      "y": 3,
      "z": -6,
      "name": "Rock_Quartzite_Brick"
    },
    {
      "x": -5,
      "y": 4,
      "z": -6,
      "name": "Rock_Quartzite_Brick"
    },
    {
      "x": -5,
      "y": 5,
      "z": -6,
      "name": "Rock_Quartzite"
    },
    {
      "x": -5,
      "y": 6,
      "z": -6,
      "name": "Rock_Quartzite_Brick"
    },
    {
      "x": -5,
      "y": 7,
      "z": -6,
      "name": "Rock_Quartzite_Brick"
    },
    {
      "x": -5,
      "y": 8,
      "z": -6,
      "name": "Rock_Stone_Cobble"
    },
    {
      "x": -5,
      "y": 9,
      "z": -6,
      "name": "Empty"
    },
    {
      "x": -5,
      "y": 10,
      "z": -6,
      "name": "Empty"
    },
    {
      "x": -5,
      "y": 11,
      "z": -6,
      "name": "Empty"
    },
    {
      "x": -5,
      "y": 12,
      "z": -6,
      "name": "Rock_Quartzite_Brick_Half",
      "rotation": 8
    },
    {
      "x": -5,
      "y": 13,
      "z": -6,
      "name": "Rock_Quartzite"
    },
    {
      "x": -5,
      "y": 14,
      "z": -6,
      "name": "Rock_Quartzite"
    },
    {
      "x": -5,
      "y": 15,
      "z": -6,
      "name": "Rock_Quartzite"
    },
    {
      "x": -5,
      "y": 0,
      "z": -5,
      "name": "Rock_Stone_Cobble"
    },
    {
      "x": -5,
      "y": 1,
      "z": -5,
      "name": "Rock_Stone"
    },
    {
      "x": -5,
      "y": 2,
      "z": -5,
      "name": "Rock_Stone"
    },
    {
      "x": -5,
      "y": 3,
      "z": -5,
      "name": "Plant_Moss_Rug_Blue"
    },
    {
      "x": -5,
      "y": 4,
      "z": -5,
      "name": "Empty"
    },
    {
      "x": -5,
      "y": 5,
      "z": -5,
      "name": "Rock_Quartzite_Brick"
    },
    {
      "x": -5,
      "y": 6,
      "z": -5,
      "name": "Rock_Quartzite_Brick"
    },
    {
      "x": -5,
      "y": 7,
      "z": -5,
      "name": "Rock_Quartzite_Brick"
    },
    {
      "x": -5,
      "y": 8,
      "z": -5,
      "name": "Rock_Stone_Cobble"
    },
    {
      "x": -5,
      "y": 9,
      "z": -5,
      "name": "Empty"
    },
    {
      "x": -5,
      "y": 10,
      "z": -5,
      "name": "Empty"
    },
    {
      "x": -5,
      "y": 11,
      "z": -5,
      "name": "Empty"
    },
    {
      "x": -5,
      "y": 12,
      "z": -5,
      "name": "Empty"
    },
    {
      "x": -5,
      "y": 13,
      "z": -5,
      "name": "Empty"
    },
    {
      "x": -5,
      "y": 14,
      "z": -5,
      "name": "Rock_Quartzite"
    },
    {
      "x": -5,
      "y": 15,
      "z": -5,
      "name": "Rock_Quartzite"
    },
    {
      "x": -5,
      "y": 0,
      "z": -4,
      "name": "Rock_Stone_Cobble"
    },
    {
      "x": -5,
      "y": 1,
      "z": -4,
      "name": "Rock_Stone"
    },
    {
      "x": -5,
      "y": 2,
      "z": -4,
      "name": "Plant_Moss_Block_Blue"
    },
    {
      "x": -5,
      "y": 3,
      "z": -4,
      "name": "Empty"
    },
    {
      "x": -5,
      "y": 4,
      "z": -4,
      "name": "Empty"
    },
    {
      "x": -5,
      "y": 5,
      "z": -4,
      "name": "Empty"
    },
    {
      "x": -5,
      "y": 6,
      "z": -4,
      "name": "Empty"
    },
    {
      "x": -5,
      "y": 7,
      "z": -4,
      "name": "Empty"
    },
    {
      "x": -5,
      "y": 8,
      "z": -4,
      "name": "Rock_Quartzite_Brick"
    },
    {
      "x": -5,
      "y": 9,
      "z": -4,
      "name": "Empty"
    },
    {
      "x": -5,
      "y": 10,
      "z": -4,
      "name": "Empty"
    },
    {
      "x": -5,
      "y": 11,
      "z": -4,
      "name": "Empty"
    },
    {
      "x": -5,
      "y": 12,
      "z": -4,
      "name": "Empty"
    },
    {
      "x": -5,
      "y": 13,
      "z": -4,
      "name": "Empty"
    },
    {
      "x": -5,
      "y": 14,
      "z": -4,
      "name": "Rock_Quartzite"
    },
    {
      "x": -5,
      "y": 15,
      "z": -4,
      "name": "Rock_Quartzite"
    },
    {
      "x": -5,
      "y": 0,
      "z": -3,
      "name": "Rock_Stone_Cobble"
    },
    {
      "x": -5,
      "y": 1,
      "z": -3,
      "name": "Rock_Stone"
    },
    {
      "x": -5,
      "y": 2,
      "z": -3,
      "name": "Rock_Stone"
    },
    {
      "x": -5,
      "y": 3,
      "z": -3,
      "name": "Rock_Stone"
    },
    {
      "x": -5,
      "y": 4,
      "z": -3,
      "name": "Rubble_Stone"
    },
    {
      "x": -5,
      "y": 5,
      "z": -3,
      "name": "Empty"
    },
    {
      "x": -5,
      "y": 6,
      "z": -3,
      "name": "Empty"
    },
    {
      "x": -5,
      "y": 7,
      "z": -3,
      "name": "Empty"
    },
    {
      "x": -5,
      "y": 8,
      "z": -3,
      "name": "Rock_Quartzite_Brick_Half",
      "rotation": 5
    },
    {
      "x": -5,
      "y": 9,
      "z": -3,
      "name": "Empty"
    },
    {
      "x": -5,
      "y": 10,
      "z": -3,
      "name": "Empty"
    },
    {
      "x": -5,
      "y": 11,
      "z": -3,
      "name": "Empty"
    },
    {
      "x": -5,
      "y": 12,
      "z": -3,
      "name": "Rock_Quartzite_Brick_Half",
      "rotation": 8
    },
    {
      "x": -5,
      "y": 13,
      "z": -3,
      "name": "Rock_Quartzite"
    },
    {
      "x": -5,
      "y": 14,
      "z": -3,
      "name": "Rock_Quartzite"
    },
    {
      "x": -5,
      "y": 15,
      "z": -3,
      "name": "Rock_Quartzite"
    },
    {
      "x": -5,
      "y": 0,
      "z": -2,
      "name": "Rock_Stone_Cobble"
    },
    {
      "x": -5,
      "y": 1,
      "z": -2,
      "name": "Rock_Stone"
    },
    {
      "x": -5,
      "y": 2,
      "z": -2,
      "name": "Rock_Stone"
    },
    {
      "x": -5,
      "y": 3,
      "z": -2,
      "name": "Rock_Stone"
    },
    {
      "x": -5,
      "y": 4,
      "z": -2,
      "name": "Plant_Moss_Block_Blue"
    },
    {
      "x": -5,
      "y": 5,
      "z": -2,
      "name": "Empty"
    },
    {
      "x": -5,
      "y": 6,
      "z": -2,
      "name": "Empty"
    },
    {
      "x": -5,
      "y": 7,
      "z": -2,
      "name": "Empty"
    },
    {
      "x": -5,
      "y": 8,
      "z": -2,
      "name": "Empty"
    },
    {
      "x": -5,
      "y": 9,
      "z": -2,
      "name": "Empty"
    },
    {
      "x": -5,
      "y": 10,
      "z": -2,
      "name": "Empty"
    },
    {
      "x": -5,
      "y": 11,
      "z": -2,
      "name": "Rock_Quartzite_Brick_Half",
      "rotation": 8
    },
    {
      "x": -5,
      "y": 12,
      "z": -2,
      "name": "Rock_Quartzite_Brick"
    },
    {
      "x": -5,
      "y": 13,
      "z": -2,
      "name": "Rock_Quartzite"
    },
    {
      "x": -5,
      "y": 14,
      "z": -2,
      "name": "Rock_Quartzite"
    },
    {
      "x": -5,
      "y": 15,
      "z": -2,
      "name": "Rock_Quartzite"
    },
    {
      "x": -5,
      "y": 0,
      "z": -1,
      "name": "Rock_Stone_Cobble"
    },
    {
      "x": -5,
      "y": 1,
      "z": -1,
      "name": "Rock_Stone"
    },
    {
      "x": -5,
      "y": 2,
      "z": -1,
      "name": "Rock_Stone"
    },
    {
      "x": -5,
      "y": 3,
      "z": -1,
      "name": "Rock_Stone"
    },
    {
      "x": -5,
      "y": 4,
      "z": -1,
      "name": "Rock_Stone"
    },
    {
      "x": -5,
      "y": 5,
      "z": -1,
      "name": "Empty"
    },
    {
      "x": -5,
      "y": 6,
      "z": -1,
      "name": "Empty"
    },
    {
      "x": -5,
      "y": 7,
      "z": -1,
      "name": "Rock_Quartzite_Brick_Half",
      "rotation": 6
    },
    {
      "x": -5,
      "y": 8,
      "z": -1,
      "name": "Empty"
    },
    {
      "x": -5,
      "y": 9,
      "z": -1,
      "name": "Empty"
    },
    {
      "x": -5,
      "y": 10,
      "z": -1,
      "name": "Empty"
    },
    {
      "x": -5,
      "y": 11,
      "z": -1,
      "name": "Rock_Quartzite_Brick_Half",
      "rotation": 8
    },
    {
      "x": -5,
      "y": 12,
      "z": -1,
      "name": "Rock_Quartzite_Brick"
    },
    {
      "x": -5,
      "y": 13,
      "z": -1,
      "name": "Rock_Quartzite"
    },
    {
      "x": -5,
      "y": 14,
      "z": -1,
      "name": "Rock_Quartzite"
    },
    {
      "x": -5,
      "y": 15,
      "z": -1,
      "name": "Rock_Quartzite"
    },
    {
      "x": -5,
      "y": 0,
      "z": 0,
      "name": "Rock_Stone_Cobble"
    },
    {
      "x": -5,
      "y": 1,
      "z": 0,
      "name": "Rock_Quartzite_Brick"
    },
    {
      "x": -5,
      "y": 2,
      "z": 0,
      "name": "Rock_Quartzite_Brick"
    },
    {
      "x": -5,
      "y": 3,
      "z": 0,
      "name": "Rock_Quartzite_Brick"
    },
    {
      "x": -5,
      "y": 4,
      "z": 0,
      "name": "Rock_Quartzite_Brick"
    },
    {
      "x": -5,
      "y": 5,
      "z": 0,
      "name": "Rock_Quartzite_Brick"
    },
    {
      "x": -5,
      "y": 6,
      "z": 0,
      "name": "Rock_Quartzite"
    },
    {
      "x": -5,
      "y": 7,
      "z": 0,
      "name": "Rock_Quartzite"
    },
    {
      "x": -5,
      "y": 8,
      "z": 0,
      "name": "Rock_Quartzite"
    },
    {
      "x": -5,
      "y": 9,
      "z": 0,
      "name": "Rock_Quartzite"
    },
    {
      "x": -5,
      "y": 10,
      "z": 0,
      "name": "Rock_Quartzite"
    },
    {
      "x": -5,
      "y": 11,
      "z": 0,
      "name": "Rock_Quartzite"
    },
    {
      "x": -5,
      "y": 12,
      "z": 0,
      "name": "Rock_Quartzite"
    },
    {
      "x": -5,
      "y": 13,
      "z": 0,
      "name": "Rock_Quartzite"
    },
    {
      "x": -5,
      "y": 14,
      "z": 0,
      "name": "Rock_Quartzite"
    },
    {
      "x": -5,
      "y": 15,
      "z": 0,
      "name": "Rock_Quartzite"
    },
    {
      "x": -4,
      "y": 0,
      "z": -12,
      "name": "Rock_Stone_Cobble"
    },
    {
      "x": -4,
      "y": 1,
      "z": -12,
      "name": "Rock_Quartzite_Brick"
    },
    {
      "x": -4,
      "y": 2,
      "z": -12,
      "name": "Rock_Quartzite_Brick"
    },
    {
      "x": -4,
      "y": 3,
      "z": -12,
      "name": "Rock_Quartzite"
    },
    {
      "x": -4,
      "y": 4,
      "z": -12,
      "name": "Rock_Quartzite"
    },
    {
      "x": -4,
      "y": 5,
      "z": -12,
      "name": "Rock_Quartzite"
    },
    {
      "x": -4,
      "y": 6,
      "z": -12,
      "name": "Rock_Quartzite"
    },
    {
      "x": -4,
      "y": 7,
      "z": -12,
      "name": "Rock_Quartzite"
    },
    {
      "x": -4,
      "y": 8,
      "z": -12,
      "name": "Rock_Quartzite"
    },
    {
      "x": -4,
      "y": 9,
      "z": -12,
      "name": "Rock_Quartzite_Brick"
    },
    {
      "x": -4,
      "y": 10,
      "z": -12,
      "name": "Rock_Quartzite_Brick"
    },
    {
      "x": -4,
      "y": 11,
      "z": -12,
      "name": "Rock_Quartzite_Brick"
    },
    {
      "x": -4,
      "y": 12,
      "z": -12,
      "name": "Rock_Quartzite"
    },
    {
      "x": -4,
      "y": 13,
      "z": -12,
      "name": "Rock_Quartzite"
    },
    {
      "x": -4,
      "y": 14,
      "z": -12,
      "name": "Rock_Quartzite"
    },
    {
      "x": -4,
      "y": 15,
      "z": -12,
      "name": "Rock_Quartzite"
    },
    {
      "x": -4,
      "y": 0,
      "z": -11,
      "name": "Rock_Stone_Cobble"
    },
    {
      "x": -4,
      "y": 1,
      "z": -11,
      "name": "Rock_Stone_Cobble"
    },
    {
      "x": -4,
      "y": 2,
      "z": -11,
      "name": "Furniture_Ancient_Wardrobe"
    },
    {
      "x": -4,
      "y": 3,
      "z": -11,
      "name": "Furniture_Ancient_Wardrobe",
      "filler": 1024
    },
    {
      "x": -4,
      "y": 4,
      "z": -11,
      "name": "Empty"
    },
    {
      "x": -4,
      "y": 5,
      "z": -11,
      "name": "Empty"
    },
    {
      "x": -4,
      "y": 6,
      "z": -11,
      "name": "Rock_Quartzite_Brick_Half",
      "rotation": 8
    },
    {
      "x": -4,
      "y": 7,
      "z": -11,
      "name": "Rock_Quartzite_Brick"
    },
    {
      "x": -4,
      "y": 8,
      "z": -11,
      "name": "Rock_Stone_Brick"
    },
    {
      "x": -4,
      "y": 9,
      "z": -11,
      "name": "Rubble_Quartzite"
    },
    {
      "x": -4,
      "y": 10,
      "z": -11,
      "name": "Furniture_Tavern_Shelf"
    },
    {
      "x": -4,
      "y": 11,
      "z": -11,
      "name": "Empty"
    },
    {
      "x": -4,
      "y": 12,
      "z": -11,
      "name": "Rock_Quartzite_Brick_Half",
      "rotation": 8
    },
    {
      "x": -4,
      "y": 13,
      "z": -11,
      "name": "Rock_Quartzite"
    },
    {
      "x": -4,
      "y": 14,
      "z": -11,
      "name": "Rock_Quartzite"
    },
    {
      "x": -4,
      "y": 15,
      "z": -11,
      "name": "Rock_Quartzite"
    },
    {
      "x": -4,
      "y": 0,
      "z": -10,
      "name": "Rock_Stone_Cobble"
    },
    {
      "x": -4,
      "y": 1,
      "z": -10,
      "name": "Rock_Stone_Cobble"
    },
    {
      "x": -4,
      "y": 2,
      "z": -10,
      "name": "Empty"
    },
    {
      "x": -4,
      "y": 3,
      "z": -10,
      "name": "Empty"
    },
    {
      "x": -4,
      "y": 4,
      "z": -10,
      "name": "Empty"
    },
    {
      "x": -4,
      "y": 5,
      "z": -10,
      "name": "Empty"
    },
    {
      "x": -4,
      "y": 6,
      "z": -10,
      "name": "Empty"
    },
    {
      "x": -4,
      "y": 7,
      "z": -10,
      "name": "Rock_Quartzite_Brick"
    },
    {
      "x": -4,
      "y": 8,
      "z": -10,
      "name": "Rock_Stone_Brick"
    },
    {
      "x": -4,
      "y": 9,
      "z": -10,
      "name": "Empty"
    },
    {
      "x": -4,
      "y": 10,
      "z": -10,
      "name": "Empty"
    },
    {
      "x": -4,
      "y": 11,
      "z": -10,
      "name": "Empty"
    },
    {
      "x": -4,
      "y": 12,
      "z": -10,
      "name": "Rock_Quartzite_Brick_Half",
      "rotation": 8
    },
    {
      "x": -4,
      "y": 13,
      "z": -10,
      "name": "Rock_Quartzite"
    },
    {
      "x": -4,
      "y": 14,
      "z": -10,
      "name": "Rock_Quartzite"
    },
    {
      "x": -4,
      "y": 15,
      "z": -10,
      "name": "Rock_Quartzite"
    },
    {
      "x": -4,
      "y": 0,
      "z": -9,
      "name": "Rock_Stone_Cobble"
    },
    {
      "x": -4,
      "y": 1,
      "z": -9,
      "name": "Rock_Stone_Cobble"
    },
    {
      "x": -4,
      "y": 2,
      "z": -9,
      "name": "Empty"
    },
    {
      "x": -4,
      "y": 3,
      "z": -9,
      "name": "Empty"
    },
    {
      "x": -4,
      "y": 4,
      "z": -9,
      "name": "Empty"
    },
    {
      "x": -4,
      "y": 5,
      "z": -9,
      "name": "Empty"
    },
    {
      "x": -4,
      "y": 6,
      "z": -9,
      "name": "Rock_Quartzite_Brick_Half",
      "rotation": 8
    },
    {
      "x": -4,
      "y": 7,
      "z": -9,
      "name": "Rock_Quartzite_Brick"
    },
    {
      "x": -4,
      "y": 8,
      "z": -9,
      "name": "Rock_Stone_Cobble"
    },
    {
      "x": -4,
      "y": 9,
      "z": -9,
      "name": "Empty"
    },
    {
      "x": -4,
      "y": 10,
      "z": -9,
      "name": "Empty"
    },
    {
      "x": -4,
      "y": 11,
      "z": -9,
      "name": "Empty"
    },
    {
      "x": -4,
      "y": 12,
      "z": -9,
      "name": "Rock_Quartzite_Brick_Half",
      "rotation": 8
    },
    {
      "x": -4,
      "y": 13,
      "z": -9,
      "name": "Rock_Quartzite"
    },
    {
      "x": -4,
      "y": 14,
      "z": -9,
      "name": "Rock_Quartzite"
    },
    {
      "x": -4,
      "y": 15,
      "z": -9,
      "name": "Rock_Quartzite"
    },
    {
      "x": -4,
      "y": 0,
      "z": -8,
      "name": "Rock_Stone_Cobble"
    },
    {
      "x": -4,
      "y": 1,
      "z": -8,
      "name": "Rock_Stone_Brick"
    },
    {
      "x": -4,
      "y": 2,
      "z": -8,
      "name": "Plant_Moss_Rug_Blue"
    },
    {
      "x": -4,
      "y": 3,
      "z": -8,
      "name": "Empty"
    },
    {
      "x": -4,
      "y": 4,
      "z": -8,
      "name": "Empty"
    },
    {
      "x": -4,
      "y": 5,
      "z": -8,
      "name": "Empty"
    },
    {
      "x": -4,
      "y": 6,
      "z": -8,
      "name": "Rock_Quartzite_Brick_Half",
      "rotation": 8
    },
    {
      "x": -4,
      "y": 7,
      "z": -8,
      "name": "Rock_Quartzite_Brick"
    },
    {
      "x": -4,
      "y": 8,
      "z": -8,
      "name": "Rock_Quartzite_Brick"
    },
    {
      "x": -4,
      "y": 9,
      "z": -8,
      "name": "Rock_Quartzite_Brick"
    },
    {
      "x": -4,
      "y": 10,
      "z": -8,
      "name": "Rock_Quartzite_Brick"
    },
    {
      "x": -4,
      "y": 11,
      "z": -8,
      "name": "Rock_Quartzite_Brick"
    },
    {
      "x": -4,
      "y": 12,
      "z": -8,
      "name": "Rock_Quartzite_Brick"
    },
    {
      "x": -4,
      "y": 13,
      "z": -8,
      "name": "Rock_Quartzite_Brick"
    },
    {
      "x": -4,
      "y": 14,
      "z": -8,
      "name": "Rock_Quartzite"
    },
    {
      "x": -4,
      "y": 15,
      "z": -8,
      "name": "Rock_Quartzite"
    },
    {
      "x": -4,
      "y": 0,
      "z": -7,
      "name": "Rock_Stone_Cobble"
    },
    {
      "x": -4,
      "y": 1,
      "z": -7,
      "name": "Rock_Stone_Brick"
    },
    {
      "x": -4,
      "y": 2,
      "z": -7,
      "name": "Furniture_Ancient_Crate",
      "rotation": 2
    },
    {
      "x": -4,
      "y": 3,
      "z": -7,
      "name": "Plant_Moss_Rug_Blue"
    },
    {
      "x": -4,
      "y": 4,
      "z": -7,
      "name": "Empty"
    },
    {
      "x": -4,
      "y": 5,
      "z": -7,
      "name": "Empty"
    },
    {
      "x": -4,
      "y": 6,
      "z": -7,
      "name": "Rock_Quartzite_Brick"
    },
    {
      "x": -4,
      "y": 7,
      "z": -7,
      "name": "Rock_Quartzite_Brick"
    },
    {
      "x": -4,
      "y": 8,
      "z": -7,
      "name": "Rock_Stone_Cobble"
    },
    {
      "x": -4,
      "y": 9,
      "z": -7,
      "name": "Empty"
    },
    {
      "x": -4,
      "y": 10,
      "z": -7,
      "name": "Empty"
    },
    {
      "x": -4,
      "y": 11,
      "z": -7,
      "name": "Empty"
    },
    {
      "x": -4,
      "y": 12,
      "z": -7,
      "name": "Empty"
    },
    {
      "x": -4,
      "y": 13,
      "z": -7,
      "name": "Rock_Quartzite_Brick"
    },
    {
      "x": -4,
      "y": 14,
      "z": -7,
      "name": "Rock_Quartzite"
    },
    {
      "x": -4,
      "y": 15,
      "z": -7,
      "name": "Rock_Quartzite"
    },
    {
      "x": -4,
      "y": 0,
      "z": -6,
      "name": "Rock_Stone_Cobble"
    },
    {
      "x": -4,
      "y": 1,
      "z": -6,
      "name": "Rock_Quartzite_Brick"
    },
    {
      "x": -4,
      "y": 2,
      "z": -6,
      "name": "Rock_Quartzite_Brick"
    },
    {
      "x": -4,
      "y": 3,
      "z": -6,
      "name": "Rock_Quartzite_Brick"
    },
    {
      "x": -4,
      "y": 4,
      "z": -6,
      "name": "Rock_Quartzite_Brick"
    },
    {
      "x": -4,
      "y": 5,
      "z": -6,
      "name": "Rock_Quartzite_Brick"
    },
    {
      "x": -4,
      "y": 6,
      "z": -6,
      "name": "Rock_Quartzite_Brick"
    },
    {
      "x": -4,
      "y": 7,
      "z": -6,
      "name": "Rock_Quartzite_Brick"
    },
    {
      "x": -4,
      "y": 8,
      "z": -6,
      "name": "Rock_Stone_Cobble"
    },
    {
      "x": -4,
      "y": 9,
      "z": -6,
      "name": "Empty"
    },
    {
      "x": -4,
      "y": 10,
      "z": -6,
      "name": "Empty"
    },
    {
      "x": -4,
      "y": 11,
      "z": -6,
      "name": "Empty"
    },
    {
      "x": -4,
      "y": 12,
      "z": -6,
      "name": "Empty"
    },
    {
      "x": -4,
      "y": 13,
      "z": -6,
      "name": "Rock_Quartzite"
    },
    {
      "x": -4,
      "y": 14,
      "z": -6,
      "name": "Rock_Quartzite"
    },
    {
      "x": -4,
      "y": 15,
      "z": -6,
      "name": "Rock_Quartzite"
    },
    {
      "x": -4,
      "y": 0,
      "z": -5,
      "name": "Rock_Stone_Cobble"
    },
    {
      "x": -4,
      "y": 1,
      "z": -5,
      "name": "Rock_Stone"
    },
    {
      "x": -4,
      "y": 2,
      "z": -5,
      "name": "Rock_Stone"
    },
    {
      "x": -4,
      "y": 3,
      "z": -5,
      "name": "Empty"
    },
    {
      "x": -4,
      "y": 4,
      "z": -5,
      "name": "Rock_Quartzite_Brick_Half",
      "rotation": 8
    },
    {
      "x": -4,
      "y": 5,
      "z": -5,
      "name": "Rock_Quartzite_Brick"
    },
    {
      "x": -4,
      "y": 6,
      "z": -5,
      "name": "Rock_Quartzite_Brick"
    },
    {
      "x": -4,
      "y": 7,
      "z": -5,
      "name": "Rock_Quartzite_Brick"
    },
    {
      "x": -4,
      "y": 8,
      "z": -5,
      "name": "Rock_Quartzite_Brick"
    },
    {
      "x": -4,
      "y": 9,
      "z": -5,
      "name": "Empty"
    },
    {
      "x": -4,
      "y": 10,
      "z": -5,
      "name": "Empty"
    },
    {
      "x": -4,
      "y": 11,
      "z": -5,
      "name": "Empty"
    },
    {
      "x": -4,
      "y": 12,
      "z": -5,
      "name": "Empty"
    },
    {
      "x": -4,
      "y": 13,
      "z": -5,
      "name": "Empty"
    },
    {
      "x": -4,
      "y": 14,
      "z": -5,
      "name": "Rock_Quartzite"
    },
    {
      "x": -4,
      "y": 15,
      "z": -5,
      "name": "Rock_Quartzite"
    },
    {
      "x": -4,
      "y": 0,
      "z": -4,
      "name": "Rock_Stone_Cobble"
    },
    {
      "x": -4,
      "y": 1,
      "z": -4,
      "name": "Rock_Stone"
    },
    {
      "x": -4,
      "y": 2,
      "z": -4,
      "name": "Plant_Moss_Rug_Blue"
    },
    {
      "x": -4,
      "y": 3,
      "z": -4,
      "name": "Empty"
    },
    {
      "x": -4,
      "y": 4,
      "z": -4,
      "name": "Empty"
    },
    {
      "x": -4,
      "y": 5,
      "z": -4,
      "name": "Empty"
    },
    {
      "x": -4,
      "y": 6,
      "z": -4,
      "name": "Empty"
    },
    {
      "x": -4,
      "y": 7,
      "z": -4,
      "name": "Rock_Quartzite_Brick"
    },
    {
      "x": -4,
      "y": 8,
      "z": -4,
      "name": "Rock_Quartzite_Brick_Half",
      "rotation": 4
    },
    {
      "x": -4,
      "y": 9,
      "z": -4,
      "name": "Empty"
    },
    {
      "x": -4,
      "y": 10,
      "z": -4,
      "name": "Empty"
    },
    {
      "x": -4,
      "y": 11,
      "z": -4,
      "name": "Empty"
    },
    {
      "x": -4,
      "y": 12,
      "z": -4,
      "name": "Empty"
    },
    {
      "x": -4,
      "y": 13,
      "z": -4,
      "name": "Rock_Quartzite_Brick"
    },
    {
      "x": -4,
      "y": 14,
      "z": -4,
      "name": "Rock_Quartzite"
    },
    {
      "x": -4,
      "y": 15,
      "z": -4,
      "name": "Rock_Quartzite"
    },
    {
      "x": -4,
      "y": 0,
      "z": -3,
      "name": "Rock_Stone_Cobble"
    },
    {
      "x": -4,
      "y": 1,
      "z": -3,
      "name": "Plant_Moss_Rug_Blue"
    },
    {
      "x": -4,
      "y": 2,
      "z": -3,
      "name": "Empty"
    },
    {
      "x": -4,
      "y": 3,
      "z": -3,
      "name": "Empty"
    },
    {
      "x": -4,
      "y": 4,
      "z": -3,
      "name": "Empty"
    },
    {
      "x": -4,
      "y": 5,
      "z": -3,
      "name": "Empty"
    },
    {
      "x": -4,
      "y": 6,
      "z": -3,
      "name": "Empty"
    },
    {
      "x": -4,
      "y": 7,
      "z": -3,
      "name": "Empty"
    },
    {
      "x": -4,
      "y": 8,
      "z": -3,
      "name": "Empty"
    },
    {
      "x": -4,
      "y": 9,
      "z": -3,
      "name": "Empty"
    },
    {
      "x": -4,
      "y": 10,
      "z": -3,
      "name": "Empty"
    },
    {
      "x": -4,
      "y": 11,
      "z": -3,
      "name": "Empty"
    },
    {
      "x": -4,
      "y": 12,
      "z": -3,
      "name": "Empty"
    },
    {
      "x": -4,
      "y": 13,
      "z": -3,
      "name": "Rock_Quartzite_Brick"
    },
    {
      "x": -4,
      "y": 14,
      "z": -3,
      "name": "Rock_Quartzite"
    },
    {
      "x": -4,
      "y": 15,
      "z": -3,
      "name": "Rock_Quartzite"
    },
    {
      "x": -4,
      "y": 0,
      "z": -2,
      "name": "Rock_Stone_Cobble"
    },
    {
      "x": -4,
      "y": 1,
      "z": -2,
      "name": "Plant_Moss_Block_Blue"
    },
    {
      "x": -4,
      "y": 2,
      "z": -2,
      "name": "Plant_Moss_Rug_Blue"
    },
    {
      "x": -4,
      "y": 3,
      "z": -2,
      "name": "Empty"
    },
    {
      "x": -4,
      "y": 4,
      "z": -2,
      "name": "Empty"
    },
    {
      "x": -4,
      "y": 5,
      "z": -2,
      "name": "Empty"
    },
    {
      "x": -4,
      "y": 6,
      "z": -2,
      "name": "Empty"
    },
    {
      "x": -4,
      "y": 7,
      "z": -2,
      "name": "Empty"
    },
    {
      "x": -4,
      "y": 8,
      "z": -2,
      "name": "Empty"
    },
    {
      "x": -4,
      "y": 9,
      "z": -2,
      "name": "Empty"
    },
    {
      "x": -4,
      "y": 10,
      "z": -2,
      "name": "Empty"
    },
    {
      "x": -4,
      "y": 11,
      "z": -2,
      "name": "Empty"
    },
    {
      "x": -4,
      "y": 12,
      "z": -2,
      "name": "Rock_Quartzite_Brick"
    },
    {
      "x": -4,
      "y": 13,
      "z": -2,
      "name": "Rock_Quartzite"
    },
    {
      "x": -4,
      "y": 14,
      "z": -2,
      "name": "Rock_Quartzite"
    },
    {
      "x": -4,
      "y": 15,
      "z": -2,
      "name": "Rock_Quartzite"
    },
    {
      "x": -4,
      "y": 0,
      "z": -1,
      "name": "Rock_Stone_Cobble"
    },
    {
      "x": -4,
      "y": 1,
      "z": -1,
      "name": "Rock_Stone"
    },
    {
      "x": -4,
      "y": 2,
      "z": -1,
      "name": "Plant_Moss_Rug_Blue"
    },
    {
      "x": -4,
      "y": 3,
      "z": -1,
      "name": "Empty"
    },
    {
      "x": -4,
      "y": 4,
      "z": -1,
      "name": "Empty"
    },
    {
      "x": -4,
      "y": 5,
      "z": -1,
      "name": "Empty"
    },
    {
      "x": -4,
      "y": 6,
      "z": -1,
      "name": "Empty"
    },
    {
      "x": -4,
      "y": 7,
      "z": -1,
      "name": "Empty"
    },
    {
      "x": -4,
      "y": 8,
      "z": -1,
      "name": "Rock_Quartzite_Brick"
    },
    {
      "x": -4,
      "y": 9,
      "z": -1,
      "name": "Empty"
    },
    {
      "x": -4,
      "y": 10,
      "z": -1,
      "name": "Empty"
    },
    {
      "x": -4,
      "y": 11,
      "z": -1,
      "name": "Empty"
    },
    {
      "x": -4,
      "y": 12,
      "z": -1,
      "name": "Rock_Quartzite_Brick"
    },
    {
      "x": -4,
      "y": 13,
      "z": -1,
      "name": "Rock_Quartzite"
    },
    {
      "x": -4,
      "y": 14,
      "z": -1,
      "name": "Rock_Quartzite"
    },
    {
      "x": -4,
      "y": 15,
      "z": -1,
      "name": "Rock_Quartzite"
    },
    {
      "x": -4,
      "y": 0,
      "z": 0,
      "name": "Rock_Stone_Cobble"
    },
    {
      "x": -4,
      "y": 1,
      "z": 0,
      "name": "Rock_Quartzite_Brick"
    },
    {
      "x": -4,
      "y": 2,
      "z": 0,
      "name": "Rock_Quartzite_Brick"
    },
    {
      "x": -4,
      "y": 3,
      "z": 0,
      "name": "Rock_Quartzite_Brick"
    },
    {
      "x": -4,
      "y": 4,
      "z": 0,
      "name": "Rock_Quartzite_Brick"
    },
    {
      "x": -4,
      "y": 5,
      "z": 0,
      "name": "Rock_Quartzite"
    },
    {
      "x": -4,
      "y": 6,
      "z": 0,
      "name": "Rock_Quartzite"
    },
    {
      "x": -4,
      "y": 7,
      "z": 0,
      "name": "Rock_Quartzite"
    },
    {
      "x": -4,
      "y": 8,
      "z": 0,
      "name": "Rock_Quartzite"
    },
    {
      "x": -4,
      "y": 9,
      "z": 0,
      "name": "Rock_Quartzite"
    },
    {
      "x": -4,
      "y": 10,
      "z": 0,
      "name": "Rock_Quartzite"
    },
    {
      "x": -4,
      "y": 11,
      "z": 0,
      "name": "Rock_Quartzite"
    },
    {
      "x": -4,
      "y": 12,
      "z": 0,
      "name": "Rock_Quartzite"
    },
    {
      "x": -4,
      "y": 13,
      "z": 0,
      "name": "Rock_Quartzite"
    },
    {
      "x": -4,
      "y": 14,
      "z": 0,
      "name": "Rock_Quartzite"
    },
    {
      "x": -4,
      "y": 15,
      "z": 0,
      "name": "Rock_Quartzite"
    },
    {
      "x": -3,
      "y": 0,
      "z": -12,
      "name": "Rock_Stone_Cobble"
    },
    {
      "x": -3,
      "y": 1,
      "z": -12,
      "name": "Rock_Quartzite_Brick"
    },
    {
      "x": -3,
      "y": 2,
      "z": -12,
      "name": "Rock_Quartzite_Brick"
    },
    {
      "x": -3,
      "y": 3,
      "z": -12,
      "name": "Rock_Quartzite_Brick"
    },
    {
      "x": -3,
      "y": 4,
      "z": -12,
      "name": "Rock_Quartzite"
    },
    {
      "x": -3,
      "y": 5,
      "z": -12,
      "name": "Rock_Quartzite"
    },
    {
      "x": -3,
      "y": 6,
      "z": -12,
      "name": "Rock_Quartzite"
    },
    {
      "x": -3,
      "y": 7,
      "z": -12,
      "name": "Rock_Quartzite"
    },
    {
      "x": -3,
      "y": 8,
      "z": -12,
      "name": "Rock_Quartzite"
    },
    {
      "x": -3,
      "y": 9,
      "z": -12,
      "name": "Rock_Quartzite_Brick"
    },
    {
      "x": -3,
      "y": 10,
      "z": -12,
      "name": "Rock_Quartzite_Brick"
    },
    {
      "x": -3,
      "y": 11,
      "z": -12,
      "name": "Rock_Quartzite"
    },
    {
      "x": -3,
      "y": 12,
      "z": -12,
      "name": "Rock_Quartzite"
    },
    {
      "x": -3,
      "y": 13,
      "z": -12,
      "name": "Rock_Quartzite"
    },
    {
      "x": -3,
      "y": 14,
      "z": -12,
      "name": "Rock_Quartzite"
    },
    {
      "x": -3,
      "y": 15,
      "z": -12,
      "name": "Rock_Quartzite"
    },
    {
      "x": -3,
      "y": 0,
      "z": -11,
      "name": "Rock_Stone_Cobble"
    },
    {
      "x": -3,
      "y": 1,
      "z": -11,
      "name": "Rock_Stone_Cobble"
    },
    {
      "x": -3,
      "y": 2,
      "z": -11,
      "name": "Furniture_Ancient_Chair"
    },
    {
      "x": -3,
      "y": 3,
      "z": -11,
      "name": "Empty"
    },
    {
      "x": -3,
      "y": 4,
      "z": -11,
      "name": "Empty"
    },
    {
      "x": -3,
      "y": 5,
      "z": -11,
      "name": "Empty"
    },
    {
      "x": -3,
      "y": 6,
      "z": -11,
      "name": "Rock_Quartzite_Brick"
    },
    {
      "x": -3,
      "y": 7,
      "z": -11,
      "name": "Rock_Quartzite_Brick"
    },
    {
      "x": -3,
      "y": 8,
      "z": -11,
      "name": "Rock_Stone_Brick"
    },
    {
      "x": -3,
      "y": 9,
      "z": -11,
      "name": "Block_Spawner_Block",
      "components": {
        "Components": {
          "BlockSpawner": {
            "BlockSpawnerId": "Zone1_Encounters_Tier3"
          }
        }
      }
    },
    {
      "x": -3,
      "y": 10,
      "z": -11,
      "name": "Empty"
    },
    {
      "x": -3,
      "y": 11,
      "z": -11,
      "name": "Empty"
    },
    {
      "x": -3,
      "y": 12,
      "z": -11,
      "name": "Empty"
    },
    {
      "x": -3,
      "y": 13,
      "z": -11,
      "name": "Rock_Quartzite_Brick"
    },
    {
      "x": -3,
      "y": 14,
      "z": -11,
      "name": "Rock_Quartzite"
    },
    {
      "x": -3,
      "y": 15,
      "z": -11,
      "name": "Rock_Quartzite"
    },
    {
      "x": -3,
      "y": 0,
      "z": -10,
      "name": "Rock_Stone_Cobble"
    },
    {
      "x": -3,
      "y": 1,
      "z": -10,
      "name": "Rock_Stone_Cobble"
    },
    {
      "x": -3,
      "y": 2,
      "z": -10,
      "name": "Empty"
    },
    {
      "x": -3,
      "y": 3,
      "z": -10,
      "name": "Empty"
    },
    {
      "x": -3,
      "y": 4,
      "z": -10,
      "name": "Empty"
    },
    {
      "x": -3,
      "y": 5,
      "z": -10,
      "name": "Empty"
    },
    {
      "x": -3,
      "y": 6,
      "z": -10,
      "name": "Empty"
    },
    {
      "x": -3,
      "y": 7,
      "z": -10,
      "name": "Rock_Quartzite_Brick"
    },
    {
      "x": -3,
      "y": 8,
      "z": -10,
      "name": "Rock_Stone_Cobble"
    },
    {
      "x": -3,
      "y": 9,
      "z": -10,
      "name": "Empty"
    },
    {
      "x": -3,
      "y": 10,
      "z": -10,
      "name": "Empty"
    },
    {
      "x": -3,
      "y": 11,
      "z": -10,
      "name": "Empty"
    },
    {
      "x": -3,
      "y": 12,
      "z": -10,
      "name": "Empty"
    },
    {
      "x": -3,
      "y": 13,
      "z": -10,
      "name": "Rock_Quartzite_Brick"
    },
    {
      "x": -3,
      "y": 14,
      "z": -10,
      "name": "Rock_Quartzite"
    },
    {
      "x": -3,
      "y": 15,
      "z": -10,
      "name": "Rock_Quartzite"
    },
    {
      "x": -3,
      "y": 0,
      "z": -9,
      "name": "Rock_Stone_Cobble"
    },
    {
      "x": -3,
      "y": 1,
      "z": -9,
      "name": "Rock_Stone_Brick"
    },
    {
      "x": -3,
      "y": 2,
      "z": -9,
      "name": "Empty"
