{
  "version": 8,
  "blockIdVersion": 8,
  "anchorX": 0,
  "anchorY": 0,
  "anchorZ": 0,
  "blocks": [
    {
      "x": -8,
      "y": 0,
      "z": -12,
      "name": "Rock_Stone_Cobble"
    },
    {
      "x": -8,
      "y": 1,
      "z": -12,
      "name": "Rock_Quartzite_Brick"
    },
    {
      "x": -8,
      "y": 2,
      "z": -12,
      "name": "Rock_Quartzite_Brick"
    },
    {
      "x": -8,
      "y": 3,
      "z": -12,
      "name": "Rock_Quartzite_Brick"
    },
    {
      "x": -8,
      "y": 4,
      "z": -12,
      "name": "Rock_Quartzite_Brick"
    },
    {
      "x": -8,
      "y": 5,
      "z": -12,
      "name": "Rock_Quartzite"
    },
    {
      "x": -8,
      "y": 6,
      "z": -12,
      "name": "Rock_Quartzite"
    },
    {
      "x": -8,
      "y": 7,
      "z": -12,
      "name": "Rock_Quartzite"
    },
    {
      "x": -8,
      "y": 8,
      "z": -12,
      "name": "Rock_Quartzite"
    },
    {
      "x": -8,
      "y": 9,
      "z": -12,
      "name": "Rock_Quartzite"
    },
    {
      "x": -8,
      "y": 10,
      "z": -12,
      "name": "Rock_Quartzite"
    },
    {
      "x": -8,
      "y": 0,
      "z": -11,
      "name": "Rock_Stone_Cobble"
    },
    {
      "x": -8,
      "y": 1,
      "z": -11,
      "name": "Rock_Quartzite_Brick"
    },
    {
      "x": -8,
      "y": 2,
      "z": -11,
      "name": "Rock_Quartzite_Brick"
    },
    {
      "x": -8,
      "y": 3,
      "z": -11,
      "name": "Rock_Quartzite_Brick"
    },
    {
      "x": -8,
      "y": 4,
      "z": -11,
      "name": "Rock_Quartzite_Brick"
    },
    {
      "x": -8,
      "y": 5,
      "z": -11,
      "name": "Rock_Quartzite"
    },
    {
      "x": -8,
      "y": 6,
      "z": -11,
      "name": "Rock_Quartzite"
    },
    {
      "x": -8,
      "y": 7,
      "z": -11,
      "name": "Rock_Quartzite"
    },
    {
      "x": -8,
      "y": 8,
      "z": -11,
      "name": "Rock_Quartzite"
    },
    {
      "x": -8,
      "y": 9,
      "z": -11,
      "name": "Rock_Quartzite"
    },
    {
      "x": -8,
      "y": 10,
      "z": -11,
      "name": "Rock_Quartzite"
    },
    {
      "x": -8,
      "y": 0,
      "z": -10,
      "name": "Rock_Stone_Cobble"
    },
    {
      "x": -8,
      "y": 1,
      "z": -10,
      "name": "Rock_Quartzite_Brick"
    },
    {
      "x": -8,
      "y": 2,
      "z": -10,
      "name": "Rock_Quartzite_Brick"
    },
    {
      "x": -8,
      "y": 3,
      "z": -10,
      "name": "Rock_Quartzite_Brick"
    },
    {
      "x": -8,
      "y": 4,
      "z": -10,
      "name": "Rock_Quartzite"
    },
    {
      "x": -8,
      "y": 5,
      "z": -10,
      "name": "Rock_Quartzite_Brick"
    },
    {
      "x": -8,
      "y": 6,
      "z": -10,
      "name": "Rock_Quartzite"
    },
    {
      "x": -8,
      "y": 7,
      "z": -10,
      "name": "Rock_Quartzite"
    },
    {
      "x": -8,
      "y": 8,
      "z": -10,
      "name": "Rock_Quartzite"
    },
    {
      "x": -8,
      "y": 9,
      "z": -10,
      "name": "Rock_Quartzite"
    },
    {
      "x": -8,
      "y": 10,
      "z": -10,
      "name": "Rock_Quartzite"
    },
    {
      "x": -8,
      "y": 0,
      "z": -9,
      "name": "Rock_Stone_Cobble"
    },
    {
      "x": -8,
      "y": 1,
      "z": -9,
      "name": "Rock_Quartzite_Brick"
    },
    {
      "x": -8,
      "y": 2,
      "z": -9,
      "name": "Rock_Quartzite_Brick"
    },
    {
      "x": -8,
      "y": 3,
      "z": -9,
      "name": "Rock_Quartzite_Brick"
    },
    {
      "x": -8,
      "y": 4,
      "z": -9,
      "name": "Rock_Quartzite_Brick"
    },
    {
      "x": -8,
      "y": 5,
      "z": -9,
      "name": "Rock_Quartzite_Brick"
    },
    {
      "x": -8,
      "y": 6,
      "z": -9,
      "name": "Rock_Quartzite"
    },
    {
      "x": -8,
      "y": 7,
      "z": -9,
      "name": "Rock_Quartzite"
    },
    {
      "x": -8,
      "y": 8,
      "z": -9,
      "name": "Rock_Quartzite"
    },
    {
      "x": -8,
      "y": 9,
      "z": -9,
      "name": "Rock_Quartzite"
    },
    {
      "x": -8,
      "y": 10,
      "z": -9,
      "name": "Rock_Quartzite"
    },
    {
      "x": -8,
      "y": 0,
      "z": -8,
      "name": "Rock_Stone_Cobble"
    },
    {
      "x": -8,
      "y": 1,
      "z": -8,
      "name": "Rock_Quartzite_Brick"
    },
    {
      "x": -8,
      "y": 2,
      "z": -8,
      "name": "Rock_Quartzite_Brick"
    },
    {
      "x": -8,
      "y": 3,
      "z": -8,
      "name": "Rock_Quartzite_Brick"
    },
    {
      "x": -8,
      "y": 4,
      "z": -8,
      "name": "Rock_Quartzite_Brick"
    },
    {
      "x": -8,
      "y": 5,
      "z": -8,
      "name": "Rock_Quartzite_Brick"
    },
    {
      "x": -8,
      "y": 6,
      "z": -8,
      "name": "Rock_Quartzite"
    },
    {
      "x": -8,
      "y": 7,
      "z": -8,
      "name": "Rock_Quartzite"
    },
    {
      "x": -8,
      "y": 8,
      "z": -8,
      "name": "Rock_Quartzite"
    },
    {
      "x": -8,
      "y": 9,
      "z": -8,
      "name": "Rock_Quartzite"
    },
    {
      "x": -8,
      "y": 10,
      "z": -8,
      "name": "Rock_Quartzite"
    },
    {
      "x": -8,
      "y": 0,
      "z": -7,
      "name": "Rock_Stone_Cobble"
    },
    {
      "x": -8,
      "y": 1,
      "z": -7,
      "name": "Rock_Quartzite_Brick"
    },
    {
      "x": -8,
      "y": 2,
      "z": -7,
      "name": "Rock_Quartzite_Brick"
    },
    {
      "x": -8,
      "y": 3,
      "z": -7,
      "name": "Rock_Quartzite_Brick"
    },
    {
      "x": -8,
      "y": 4,
      "z": -7,
      "name": "Rock_Quartzite_Brick"
    },
    {
      "x": -8,
      "y": 5,
      "z": -7,
      "name": "Rock_Quartzite"
    },
    {
      "x": -8,
      "y": 6,
      "z": -7,
      "name": "Rock_Quartzite"
    },
    {
      "x": -8,
      "y": 7,
      "z": -7,
      "name": "Rock_Quartzite"
    },
    {
      "x": -8,
      "y": 8,
      "z": -7,
      "name": "Rock_Quartzite_Brick"
    },
    {
      "x": -8,
      "y": 9,
      "z": -7,
      "name": "Rock_Quartzite"
    },
    {
      "x": -8,
      "y": 10,
      "z": -7,
      "name": "Rock_Quartzite"
    },
    {
      "x": -8,
      "y": 0,
      "z": -6,
      "name": "Rock_Stone_Cobble"
    },
    {
      "x": -8,
      "y": 1,
      "z": -6,
      "name": "Rock_Quartzite_Brick"
    },
    {
      "x": -8,
      "y": 2,
      "z": -6,
      "name": "Rock_Quartzite_Brick"
    },
    {
      "x": -8,
      "y": 3,
      "z": -6,
      "name": "Rock_Quartzite"
    },
    {
      "x": -8,
      "y": 4,
      "z": -6,
      "name": "Rock_Quartzite"
    },
    {
      "x": -8,
      "y": 5,
      "z": -6,
      "name": "Rock_Quartzite"
    },
    {
      "x": -8,
      "y": 6,
      "z": -6,
      "name": "Rock_Quartzite"
    },
    {
      "x": -8,
      "y": 7,
      "z": -6,
      "name": "Rock_Quartzite_Brick"
    },
    {
      "x": -8,
      "y": 8,
      "z": -6,
      "name": "Rock_Quartzite_Brick"
    },
    {
      "x": -8,
      "y": 9,
      "z": -6,
      "name": "Rock_Quartzite"
    },
    {
      "x": -8,
      "y": 10,
      "z": -6,
      "name": "Rock_Quartzite"
    },
    {
      "x": -8,
      "y": 0,
      "z": -5,
      "name": "Rock_Stone_Cobble"
    },
    {
      "x": -8,
      "y": 1,
      "z": -5,
      "name": "Rock_Quartzite_Brick"
    },
    {
      "x": -8,
      "y": 2,
      "z": -5,
      "name": "Rock_Quartzite_Brick"
    },
    {
      "x": -8,
      "y": 3,
      "z": -5,
      "name": "Rock_Quartzite_Brick"
    },
    {
      "x": -8,
      "y": 4,
      "z": -5,
      "name": "Rock_Quartzite"
    },
    {
      "x": -8,
      "y": 5,
      "z": -5,
      "name": "Rock_Quartzite"
    },
    {
      "x": -8,
      "y": 6,
      "z": -5,
      "name": "Rock_Quartzite"
    },
    {
      "x": -8,
      "y": 7,
      "z": -5,
      "name": "Rock_Quartzite_Brick"
    },
    {
      "x": -8,
      "y": 8,
      "z": -5,
      "name": "Rock_Quartzite"
    },
    {
      "x": -8,
      "y": 9,
      "z": -5,
      "name": "Rock_Quartzite"
    },
    {
      "x": -8,
      "y": 10,
      "z": -5,
      "name": "Rock_Quartzite"
    },
    {
      "x": -8,
      "y": 0,
      "z": -4,
      "name": "Rock_Stone_Cobble"
    },
    {
      "x": -8,
      "y": 1,
      "z": -4,
      "name": "Rock_Quartzite_Brick"
    },
    {
      "x": -8,
      "y": 2,
      "z": -4,
      "name": "Rock_Quartzite_Brick"
    },
    {
      "x": -8,
      "y": 3,
      "z": -4,
      "name": "Rock_Quartzite_Brick"
    },
    {
      "x": -8,
      "y": 4,
      "z": -4,
      "name": "Rock_Quartzite"
    },
    {
      "x": -8,
      "y": 5,
      "z": -4,
      "name": "Rock_Quartzite"
    },
    {
      "x": -8,
      "y": 6,
      "z": -4,
      "name": "Rock_Quartzite_Brick"
    },
    {
      "x": -8,
      "y": 7,
      "z": -4,
      "name": "Rock_Quartzite_Brick"
    },
    {
      "x": -8,
      "y": 8,
      "z": -4,
      "name": "Rock_Quartzite"
    },
    {
      "x": -8,
      "y": 9,
      "z": -4,
      "name": "Rock_Quartzite"
    },
    {
      "x": -8,
      "y": 10,
      "z": -4,
      "name": "Rock_Quartzite"
    },
    {
      "x": -8,
      "y": 0,
      "z": -3,
      "name": "Rock_Stone_Cobble"
    },
    {
      "x": -8,
      "y": 1,
      "z": -3,
      "name": "Rock_Quartzite_Brick"
    },
    {
      "x": -8,
      "y": 2,
      "z": -3,
      "name": "Rock_Quartzite_Brick"
    },
    {
      "x": -8,
      "y": 3,
      "z": -3,
      "name": "Rock_Quartzite_Brick"
    },
    {
      "x": -8,
      "y": 4,
      "z": -3,
      "name": "Rock_Quartzite"
    },
    {
      "x": -8,
      "y": 5,
      "z": -3,
      "name": "Rock_Quartzite"
    },
    {
      "x": -8,
      "y": 6,
      "z": -3,
      "name": "Rock_Quartzite"
    },
    {
      "x": -8,
      "y": 7,
      "z": -3,
      "name": "Rock_Quartzite"
    },
    {
      "x": -8,
      "y": 8,
      "z": -3,
      "name": "Rock_Quartzite"
    },
    {
      "x": -8,
      "y": 9,
      "z": -3,
      "name": "Rock_Quartzite"
    },
    {
      "x": -8,
      "y": 10,
      "z": -3,
      "name": "Rock_Quartzite"
    },
    {
      "x": -8,
      "y": 0,
      "z": -2,
      "name": "Rock_Stone_Cobble"
    },
    {
      "x": -8,
      "y": 1,
      "z": -2,
      "name": "Rock_Quartzite_Brick"
    },
    {
      "x": -8,
      "y": 2,
      "z": -2,
      "name": "Rock_Quartzite_Brick"
    },
    {
      "x": -8,
      "y": 3,
      "z": -2,
      "name": "Rock_Quartzite_Brick"
    },
    {
      "x": -8,
      "y": 4,
      "z": -2,
      "name": "Rock_Quartzite"
    },
    {
      "x": -8,
      "y": 5,
      "z": -2,
      "name": "Rock_Quartzite"
    },
    {
      "x": -8,
      "y": 6,
      "z": -2,
      "name": "Rock_Quartzite"
    },
    {
      "x": -8,
      "y": 7,
      "z": -2,
      "name": "Rock_Quartzite"
    },
    {
      "x": -8,
      "y": 8,
      "z": -2,
      "name": "Rock_Quartzite"
    },
    {
      "x": -8,
      "y": 9,
      "z": -2,
      "name": "Rock_Quartzite"
    },
    {
      "x": -8,
      "y": 10,
      "z": -2,
      "name": "Rock_Quartzite"
    },
    {
      "x": -8,
      "y": 0,
      "z": -1,
      "name": "Rock_Stone_Cobble"
    },
    {
      "x": -8,
      "y": 1,
      "z": -1,
      "name": "Rock_Quartzite_Brick"
    },
    {
      "x": -8,
      "y": 2,
      "z": -1,
      "name": "Rock_Quartzite_Brick"
    },
    {
      "x": -8,
      "y": 3,
      "z": -1,
      "name": "Rock_Quartzite_Brick"
    },
    {
      "x": -8,
      "y": 4,
      "z": -1,
      "name": "Rock_Quartzite"
    },
    {
      "x": -8,
      "y": 5,
      "z": -1,
      "name": "Rock_Quartzite"
    },
    {
      "x": -8,
      "y": 6,
      "z": -1,
      "name": "Rock_Quartzite"
    },
    {
      "x": -8,
      "y": 7,
      "z": -1,
      "name": "Rock_Quartzite"
    },
    {
      "x": -8,
      "y": 8,
      "z": -1,
      "name": "Rock_Quartzite"
    },
    {
      "x": -8,
      "y": 9,
      "z": -1,
      "name": "Rock_Quartzite"
    },
    {
      "x": -8,
      "y": 10,
      "z": -1,
      "name": "Rock_Quartzite"
    },
    {
      "x": -8,
      "y": 0,
      "z": 0,
      "name": "Rock_Stone_Cobble"
    },
    {
      "x": -8,
      "y": 1,
      "z": 0,
      "name": "Rock_Quartzite_Brick"
    },
    {
      "x": -8,
      "y": 2,
      "z": 0,
      "name": "Rock_Quartzite_Brick"
    },
    {
      "x": -8,
      "y": 3,
      "z": 0,
      "name": "Rock_Quartzite_Brick"
    },
    {
      "x": -8,
      "y": 4,
      "z": 0,
      "name": "Rock_Quartzite"
    },
    {
      "x": -8,
      "y": 5,
      "z": 0,
      "name": "Rock_Quartzite"
    },
    {
      "x": -8,
      "y": 6,
      "z": 0,
      "name": "Rock_Quartzite"
    },
    {
      "x": -8,
      "y": 7,
      "z": 0,
      "name": "Rock_Quartzite"
    },
    {
      "x": -8,
      "y": 8,
      "z": 0,
      "name": "Rock_Quartzite"
    },
    {
      "x": -8,
      "y": 9,
      "z": 0,
      "name": "Rock_Quartzite"
    },
    {
      "x": -8,
      "y": 10,
      "z": 0,
      "name": "Rock_Quartzite"
    },
    {
      "x": -7,
      "y": 0,
      "z": -12,
      "name": "Rock_Stone_Cobble"
    },
    {
      "x": -7,
      "y": 1,
      "z": -12,
      "name": "Rock_Quartzite_Brick"
    },
    {
      "x": -7,
      "y": 2,
      "z": -12,
      "name": "Rock_Quartzite_Brick"
    },
    {
      "x": -7,
      "y": 3,
      "z": -12,
      "name": "Rock_Quartzite_Brick"
    },
    {
      "x": -7,
      "y": 4,
      "z": -12,
      "name": "Rock_Quartzite"
    },
    {
      "x": -7,
      "y": 5,
      "z": -12,
      "name": "Rock_Quartzite"
    },
    {
      "x": -7,
      "y": 6,
      "z": -12,
      "name": "Rock_Quartzite"
    },
    {
      "x": -7,
      "y": 7,
      "z": -12,
      "name": "Rock_Quartzite"
    },
    {
      "x": -7,
      "y": 8,
      "z": -12,
      "name": "Rock_Quartzite"
    },
    {
      "x": -7,
      "y": 9,
      "z": -12,
      "name": "Rock_Quartzite"
    },
    {
      "x": -7,
      "y": 10,
      "z": -12,
      "name": "Rock_Quartzite"
    },
    {
      "x": -7,
      "y": 0,
      "z": -11,
      "name": "Rock_Stone_Cobble"
    },
    {
      "x": -7,
      "y": 1,
      "z": -11,
      "name": "Rock_Stone_Cobble"
    },
    {
      "x": -7,
      "y": 2,
      "z": -11,
      "name": "Rock_Stone_Brick_Pillar_Base"
    },
    {
      "x": -7,
      "y": 3,
      "z": -11,
      "name": "Rock_Stone_Brick_Pillar_Middle"
    },
    {
      "x": -7,
      "y": 4,
      "z": -11,
      "name": "Rock_Stone_Brick_Pillar_Middle"
    },
    {
      "x": -7,
      "y": 5,
      "z": -11,
      "name": "Rock_Stone_Brick_Pillar_Base",
      "rotation": 8
    },
    {
      "x": -7,
      "y": 6,
      "z": -11,
      "name": "Rock_Quartzite_Brick_Smooth"
    },
    {
      "x": -7,
      "y": 7,
      "z": -11,
      "name": "Rock_Quartzite_Brick"
    },
    {
      "x": -7,
      "y": 8,
      "z": -11,
      "name": "Rock_Quartzite_Brick"
    },
    {
      "x": -7,
      "y": 9,
      "z": -11,
      "name": "Rock_Quartzite"
    },
    {
      "x": -7,
      "y": 10,
      "z": -11,
      "name": "Rock_Quartzite"
    },
    {
      "x": -7,
      "y": 0,
      "z": -10,
      "name": "Rock_Stone_Cobble"
    },
    {
      "x": -7,
      "y": 1,
      "z": -10,
      "name": "Rock_Stone_Cobble"
    },
    {
      "x": -7,
      "y": 2,
      "z": -10,
      "name": "Furniture_Ancient_Barrel"
    },
    {
      "x": -7,
      "y": 3,
      "z": -10,
      "name": "Empty"
    },
    {
      "x": -7,
      "y": 4,
      "z": -10,
      "name": "Empty"
    },
    {
      "x": -7,
      "y": 5,
      "z": -10,
      "name": "Empty"
    },
    {
      "x": -7,
      "y": 6,
      "z": -10,
      "name": "Empty"
    },
    {
      "x": -7,
      "y": 7,
      "z": -10,
      "name": "Rock_Quartzite_Brick_Half",
      "rotation": 8
    },
    {
      "x": -7,
      "y": 8,
      "z": -10,
      "name": "Rock_Quartzite_Brick"
    },
    {
      "x": -7,
      "y": 9,
      "z": -10,
      "name": "Rock_Quartzite"
    },
    {
      "x": -7,
      "y": 10,
      "z": -10,
      "name": "Rock_Quartzite"
    },
    {
      "x": -7,
      "y": 0,
      "z": -9,
      "name": "Rock_Stone_Cobble"
    },
    {
      "x": -7,
      "y": 1,
      "z": -9,
      "name": "Rock_Stone_Cobble"
    },
    {
      "x": -7,
      "y": 2,
      "z": -9,
      "name": "Empty"
    },
    {
      "x": -7,
      "y": 3,
      "z": -9,
      "name": "Empty"
    },
    {
      "x": -7,
      "y": 4,
      "z": -9,
      "name": "Empty"
    },
    {
      "x": -7,
      "y": 5,
      "z": -9,
      "name": "Empty"
    },
    {
      "x": -7,
      "y": 6,
      "z": -9,
      "name": "Empty"
    },
    {
      "x": -7,
      "y": 7,
      "z": -9,
      "name": "Empty"
    },
    {
      "x": -7,
      "y": 8,
      "z": -9,
      "name": "Rock_Quartzite_Brick"
    },
    {
      "x": -7,
      "y": 9,
      "z": -9,
      "name": "Rock_Quartzite"
    },
    {
      "x": -7,
      "y": 10,
      "z": -9,
      "name": "Rock_Quartzite"
    },
    {
      "x": -7,
      "y": 0,
      "z": -8,
      "name": "Rock_Stone_Cobble"
    },
    {
      "x": -7,
      "y": 1,
      "z": -8,
      "name": "Rock_Stone_Brick"
    },
    {
      "x": -7,
      "y": 2,
      "z": -8,
      "name": "Rock_Stone_Brick_Wall"
    },
    {
      "x": -7,
      "y": 3,
      "z": -8,
      "name": "Empty"
    },
    {
      "x": -7,
      "y": 4,
      "z": -8,
      "name": "Empty"
    },
    {
      "x": -7,
      "y": 5,
      "z": -8,
      "name": "Empty"
    },
    {
      "x": -7,
      "y": 6,
      "z": -8,
      "name": "Empty"
    },
    {
      "x": -7,
      "y": 7,
      "z": -8,
      "name": "Empty"
    },
    {
      "x": -7,
      "y": 8,
      "z": -8,
      "name": "Empty"
    },
    {
      "x": -7,
      "y": 9,
      "z": -8,
      "name": "Rock_Quartzite"
    },
    {
      "x": -7,
      "y": 10,
      "z": -8,
      "name": "Rock_Quartzite"
    },
    {
      "x": -7,
      "y": 0,
      "z": -7,
      "name": "Rock_Stone_Cobble"
    },
    {
      "x": -7,
      "y": 1,
      "z": -7,
      "name": "Empty"
    },
    {
      "x": -7,
      "y": 2,
      "z": -7,
      "name": "Empty"
    },
    {
      "x": -7,
      "y": 3,
      "z": -7,
      "name": "Empty"
    },
    {
      "x": -7,
      "y": 4,
      "z": -7,
      "name": "Empty"
    },
    {
      "x": -7,
      "y": 5,
      "z": -7,
      "name": "Empty"
    },
    {
      "x": -7,
      "y": 6,
      "z": -7,
      "name": "Wood_Beech_Branch_Corner",
      "rotation": 1
    },
    {
      "x": -7,
      "y": 7,
      "z": -7,
      "name": "Wood_Beech_Branch_Corner",
      "rotation": 9
    },
    {
      "x": -7,
      "y": 8,
      "z": -7,
      "name": "Rock_Quartzite_Brick_Half",
      "rotation": 8
    },
    {
      "x": -7,
      "y": 9,
      "z": -7,
      "name": "Rock_Quartzite"
    },
    {
      "x": -7,
      "y": 10,
      "z": -7,
      "name": "Rock_Quartzite"
    },
    {
      "x": -7,
      "y": 0,
      "z": -6,
      "name": "Rock_Stone_Cobble"
    },
    {
      "x": -7,
      "y": 1,
      "z": -6,
      "name": "Furniture_Ancient_Table"
    },
    {
      "x": -7,
      "y": 2,
      "z": -6,
      "name": "Empty"
    },
    {
      "x": -7,
      "y": 3,
      "z": -6,
      "name": "Empty"
    },
    {
      "x": -7,
      "y": 4,
      "z": -6,
      "name": "Empty"
    },
    {
      "x": -7,
      "y": 5,
      "z": -6,
      "name": "Empty"
    },
    {
      "x": -7,
      "y": 6,
      "z": -6,
      "name": "Empty"
    },
    {
      "x": -7,
      "y": 7,
      "z": -6,
      "name": "Empty"
    },
    {
      "x": -7,
      "y": 8,
      "z": -6,
      "name": "Rock_Quartzite_Brick"
    },
    {
      "x": -7,
      "y": 9,
      "z": -6,
      "name": "Rock_Quartzite"
    },
    {
      "x": -7,
      "y": 10,
      "z": -6,
      "name": "Rock_Quartzite"
    },
    {
      "x": -7,
      "y": 0,
      "z": -5,
      "name": "Rock_Stone_Cobble"
    },
    {
      "x": -7,
      "y": 1,
      "z": -5,
      "name": "Furniture_Ancient_Table",
      "filler": 32
    },
    {
      "x": -7,
      "y": 2,
      "z": -5,
      "name": "Furniture_Ancient_Shelf",
      "rotation": 1
    },
    {
      "x": -7,
      "y": 3,
      "z": -5,
      "name": "Empty"
    },
    {
      "x": -7,
      "y": 4,
      "z": -5,
      "name": "Empty"
    },
    {
      "x": -7,
      "y": 5,
      "z": -5,
      "name": "Empty"
    },
    {
      "x": -7,
      "y": 6,
      "z": -5,
      "name": "Empty"
    },
    {
      "x": -7,
      "y": 7,
      "z": -5,
      "name": "Rock_Quartzite_Brick_Half",
      "rotation": 8
    },
    {
      "x": -7,
      "y": 8,
      "z": -5,
      "name": "Rock_Quartzite_Brick"
    },
    {
      "x": -7,
      "y": 9,
      "z": -5,
      "name": "Rock_Quartzite"
    },
    {
      "x": -7,
      "y": 10,
      "z": -5,
      "name": "Rock_Quartzite"
    },
    {
      "x": -7,
      "y": 0,
      "z": -4,
      "name": "Plant_Moss_Block_Blue"
    },
    {
      "x": -7,
      "y": 1,
      "z": -4,
      "name": "Plant_Crop_Mushroom_Flatcap_Green",
      "components": {
        "Components": {
          "FarmingBlock": {}
        }
      }
    },
    {
      "x": -7,
      "y": 2,
      "z": -4,
      "name": "Furniture_Ancient_Shelf",
      "rotation": 1
    },
    {
      "x": -7,
      "y": 3,
      "z": -4,
      "name": "Deco_Scroll",
      "rotation": 1
    },
    {
      "x": -7,
      "y": 4,
      "z": -4,
      "name": "Empty"
    },
    {
      "x": -7,
      "y": 5,
      "z": -4,
      "name": "Empty"
    },
    {
      "x": -7,
      "y": 6,
      "z": -4,
      "name": "Empty"
    },
    {
      "x": -7,
      "y": 7,
      "z": -4,
      "name": "Rock_Quartzite_Brick"
    },
    {
      "x": -7,
      "y": 8,
      "z": -4,
      "name": "Rock_Quartzite_Brick"
    },
    {
      "x": -7,
      "y": 9,
      "z": -4,
      "name": "Rock_Quartzite"
    },
    {
      "x": -7,
      "y": 10,
      "z": -4,
      "name": "Rock_Quartzite"
    },
    {
      "x": -7,
      "y": 0,
      "z": -3,
      "name": "Rock_Stone_Cobble"
    },
    {
      "x": -7,
      "y": 1,
      "z": -3,
      "name": "Rock_Stone_Brick_Pillar_Base"
    },
    {
      "x": -7,
      "y": 2,
      "z": -3,
      "name": "Rock_Stone_Brick_Pillar_Middle"
    },
    {
      "x": -7,
      "y": 3,
      "z": -3,
      "name": "Rock_Stone_Brick_Pillar_Middle"
    },
    {
      "x": -7,
      "y": 4,
      "z": -3,
      "name": "Rock_Stone_Brick_Pillar_Middle"
    },
    {
      "x": -7,
      "y": 5,
      "z": -3,
      "name": "Rock_Stone_Brick_Pillar_Base",
      "rotation": 8
    },
    {
      "x": -7,
      "y": 6,
      "z": -3,
      "name": "Rock_Quartzite_Brick_Smooth"
    },
    {
      "x": -7,
      "y": 7,
      "z": -3,
      "name": "Rock_Quartzite_Brick"
    },
    {
      "x": -7,
      "y": 8,
      "z": -3,
      "name": "Rock_Quartzite_Brick"
    },
    {
      "x": -7,
      "y": 9,
      "z": -3,
      "name": "Rock_Quartzite"
    },
    {
      "x": -7,
      "y": 10,
      "z": -3,
      "name": "Rock_Quartzite"
    },
    {
      "x": -7,
      "y": 0,
      "z": -2,
      "name": "Rock_Stone_Cobble"
    },
    {
      "x": -7,
      "y": 1,
      "z": -2,
      "name": "Rock_Quartzite_Brick"
    },
    {
      "x": -7,
      "y": 2,
      "z": -2,
      "name": "Rock_Quartzite_Brick"
    },
    {
      "x": -7,
      "y": 3,
      "z": -2,
      "name": "Rock_Quartzite_Brick"
    },
    {
      "x": -7,
      "y": 4,
      "z": -2,
      "name": "Rock_Quartzite_Brick"
    },
    {
      "x": -7,
      "y": 5,
      "z": -2,
      "name": "Rock_Quartzite_Brick"
    },
    {
      "x": -7,
      "y": 6,
      "z": -2,
      "name": "Rock_Quartzite_Brick"
    },
    {
      "x": -7,
      "y": 7,
      "z": -2,
      "name": "Rock_Quartzite_Brick"
    },
    {
      "x": -7,
      "y": 8,
      "z": -2,
      "name": "Rock_Quartzite_Brick"
    },
    {
      "x": -7,
      "y": 9,
      "z": -2,
      "name": "Rock_Quartzite"
    },
    {
      "x": -7,
      "y": 10,
      "z": -2,
      "name": "Rock_Quartzite"
    },
    {
      "x": -7,
      "y": 0,
      "z": -1,
      "name": "Rock_Stone_Cobble"
    },
    {
      "x": -7,
      "y": 1,
      "z": -1,
      "name": "Rock_Quartzite_Brick"
    },
    {
      "x": -7,
      "y": 2,
      "z": -1,
      "name": "Rock_Quartzite_Brick"
    },
    {
      "x": -7,
      "y": 3,
      "z": -1,
      "name": "Rock_Quartzite_Brick"
    },
    {
      "x": -7,
      "y": 4,
      "z": -1,
      "name": "Rock_Quartzite_Brick"
    },
    {
      "x": -7,
      "y": 5,
      "z": -1,
      "name": "Rock_Quartzite_Brick"
    },
    {
      "x": -7,
      "y": 6,
      "z": -1,
      "name": "Rock_Quartzite_Brick"
    },
    {
      "x": -7,
      "y": 7,
      "z": -1,
      "name": "Rock_Quartzite_Brick"
    },
    {
      "x": -7,
      "y": 8,
      "z": -1,
      "name": "Rock_Quartzite_Brick"
    },
    {
      "x": -7,
      "y": 9,
      "z": -1,
      "name": "Rock_Quartzite"
    },
    {
      "x": -7,
      "y": 10,
      "z": -1,
      "name": "Rock_Quartzite"
    },
    {
      "x": -7,
      "y": 0,
      "z": 0,
      "name": "Rock_Stone_Cobble"
    },
    {
      "x": -7,
      "y": 1,
      "z": 0,
      "name": "Rock_Quartzite_Brick"
    },
    {
      "x": -7,
      "y": 2,
      "z": 0,
      "name": "Rock_Quartzite_Brick"
    },
    {
      "x": -7,
      "y": 3,
      "z": 0,
      "name": "Rock_Quartzite_Brick"
    },
    {
      "x": -7,
      "y": 4,
      "z": 0,
      "name": "Rock_Quartzite"
    },
    {
      "x": -7,
      "y": 5,
      "z": 0,
      "name": "Rock_Quartzite"
    },
    {
      "x": -7,
      "y": 6,
      "z": 0,
      "name": "Rock_Quartzite"
    },
    {
      "x": -7,
      "y": 7,
      "z": 0,
      "name": "Rock_Quartzite"
    },
    {
      "x": -7,
      "y": 8,
      "z": 0,
      "name": "Rock_Quartzite"
    },
    {
      "x": -7,
      "y": 9,
      "z": 0,
      "name": "Rock_Quartzite"
    },
    {
      "x": -7,
      "y": 10,
      "z": 0,
      "name": "Rock_Quartzite"
    },
    {
      "x": -6,
      "y": 0,
      "z": -12,
      "name": "Rock_Stone_Cobble"
    },
    {
      "x": -6,
      "y": 1,
      "z": -12,
      "name": "Rock_Quartzite_Brick"
    },
    {
      "x": -6,
      "y": 2,
      "z": -12,
      "name": "Rock_Quartzite_Brick"
    },
    {
      "x": -6,
      "y": 3,
      "z": -12,
      "name": "Rock_Quartzite_Brick"
    },
    {
      "x": -6,
      "y": 4,
      "z": -12,
      "name": "Rock_Quartzite"
    },
    {
      "x": -6,
      "y": 5,
      "z": -12,
      "name": "Rock_Quartzite"
    },
    {
      "x": -6,
      "y": 6,
      "z": -12,
      "name": "Rock_Quartzite"
    },
    {
      "x": -6,
      "y": 7,
      "z": -12,
      "name": "Rock_Quartzite"
    },
    {
      "x": -6,
      "y": 8,
      "z": -12,
      "name": "Rock_Quartzite"
    },
    {
      "x": -6,
      "y": 9,
      "z": -12,
      "name": "Rock_Quartzite"
    },
    {
      "x": -6,
      "y": 10,
      "z": -12,
      "name": "Rock_Quartzite"
    },
    {
      "x": -6,
      "y": 0,
      "z": -11,
      "name": "Rock_Stone_Cobble"
    },
    {
      "x": -6,
      "y": 1,
      "z": -11,
      "name": "Rock_Stone_Cobble"
    },
    {
      "x": -6,
      "y": 2,
      "z": -11,
      "name": "Furniture_Village_Bookcase"
    },
    {
      "x": -6,
      "y": 3,
      "z": -11,
      "name": "Furniture_Village_Bookcase"
    },
    {
      "x": -6,
      "y": 4,
      "z": -11,
      "name": "Empty"
    },
    {
      "x": -6,
      "y": 5,
      "z": -11,
      "name": "Empty"
    },
    {
      "x": -6,
      "y": 6,
      "z": -11,
      "name": "Rock_Quartzite_Brick_Smooth"
    },
    {
      "x": -6,
      "y": 7,
      "z": -11,
      "name": "Rock_Quartzite_Brick"
    },
    {
      "x": -6,
      "y": 8,
      "z": -11,
      "name": "Rock_Quartzite_Brick"
    },
    {
      "x": -6,
      "y": 9,
      "z": -11,
      "name": "Rock_Quartzite"
    },
    {
      "x": -6,
      "y": 10,
      "z": -11,
      "name": "Rock_Quartzite"
    },
    {
      "x": -6,
      "y": 0,
      "z": -10,
      "name": "Rock_Stone_Cobble"
    },
    {
      "x": -6,
      "y": 1,
      "z": -10,
      "name": "Rock_Stone_Cobble"
    },
    {
      "x": -6,
      "y": 2,
      "z": -10,
      "name": "Empty"
    },
    {
      "x": -6,
      "y": 3,
      "z": -10,
      "name": "Empty"
    },
    {
      "x": -6,
      "y": 4,
      "z": -10,
      "name": "Empty"
    },
    {
      "x": -6,
      "y": 5,
      "z": -10,
      "name": "Empty"
    },
    {
      "x": -6,
      "y": 6,
      "z": -10,
      "name": "Empty"
    },
    {
      "x": -6,
      "y": 7,
      "z": -10,
      "name": "Rock_Quartzite_Brick_Half",
      "rotation": 8
    },
    {
      "x": -6,
      "y": 8,
      "z": -10,
      "name": "Rock_Quartzite_Brick"
    },
    {
      "x": -6,
      "y": 9,
      "z": -10,
      "name": "Rock_Quartzite"
    },
    {
      "x": -6,
      "y": 10,
      "z": -10,
      "name": "Rock_Quartzite"
    },
    {
      "x": -6,
      "y": 0,
      "z": -9,
      "name": "Rock_Stone_Cobble"
    },
    {
      "x": -6,
      "y": 1,
      "z": -9,
      "name": "Rock_Stone_Cobble"
    },
    {
      "x": -6,
      "y": 2,
      "z": -9,
      "name": "Empty"
    },
    {
      "x": -6,
      "y": 3,
      "z": -9,
      "name": "Empty"
    },
    {
      "x": -6,
      "y": 4,
      "z": -9,
      "name": "Empty"
    },
    {
      "x": -6,
      "y": 5,
      "z": -9,
      "name": "Empty"
    },
    {
      "x": -6,
      "y": 6,
      "z": -9,
      "name": "Empty"
    },
    {
      "x": -6,
      "y": 7,
      "z": -9,
      "name": "Wood_Beech_Trunk_Full",
      "rotation": 4
    },
    {
      "x": -6,
      "y": 8,
      "z": -9,
      "name": "Rock_Quartzite_Brick"
    },
    {
      "x": -6,
      "y": 9,
      "z": -9,
      "name": "Rock_Quartzite"
    },
    {
      "x": -6,
      "y": 10,
      "z": -9,
      "name": "Rock_Quartzite"
    },
    {
      "x": -6,
      "y": 0,
      "z": -8,
      "name": "Rock_Stone_Cobble"
    },
    {
      "x": -6,
      "y": 1,
      "z": -8,
      "name": "Rock_Stone_Brick"
    },
    {
      "x": -6,
      "y": 2,
      "z": -8,
      "name": "Rock_Stone_Brick_Wall"
    },
    {
      "x": -6,
      "y": 3,
      "z": -8,
      "name": "Empty"
    },
    {
      "x": -6,
      "y": 4,
      "z": -8,
      "name": "Empty"
    },
    {
      "x": -6,
      "y": 5,
      "z": -8,
      "name": "Empty"
    },
    {
      "x": -6,
      "y": 6,
      "z": -8,
      "name": "Empty"
    },
    {
      "x": -6,
      "y": 7,
      "z": -8,
      "name": "Wood_Beech_Trunk_Full",
      "rotation": 4
    },
    {
      "x": -6,
      "y": 8,
      "z": -8,
      "name": "Empty"
    },
    {
      "x": -6,
      "y": 9,
      "z": -8,
      "name": "Rock_Quartzite"
    },
    {
      "x": -6,
      "y": 10,
      "z": -8,
      "name": "Rock_Quartzite"
    },
    {
      "x": -6,
      "y": 0,
      "z": -7,
      "name": "Rock_Stone_Cobble"
    },
    {
      "x": -6,
      "y": 1,
      "z": -7,
      "name": "Furniture_Ancient_Chair",
      "rotation": 1
    },
    {
      "x": -6,
      "y": 2,
      "z": -7,
      "name": "Empty"
    },
    {
      "x": -6,
      "y": 3,
      "z": -7,
      "name": "Empty"
    },
    {
      "x": -6,
      "y": 4,
      "z": -7,
      "name": "Empty"
    },
    {
      "x": -6,
      "y": 5,
      "z": -7,
      "name": "Empty"
    },
    {
      "x": -6,
      "y": 6,
      "z": -7,
      "name": "Empty"
    },
    {
      "x": -6,
      "y": 7,
      "z": -7,
      "name": "Wood_Beech_Trunk_Full",
      "rotation": 4
    },
    {
      "x": -6,
      "y": 8,
      "z": -7,
      "name": "Wood_Beech_Trunk_Full",
      "rotation": 4
    },
    {
      "x": -6,
      "y": 9,
      "z": -7,
      "name": "Rock_Quartzite"
    },
    {
      "x": -6,
      "y": 10,
      "z": -7,
      "name": "Rock_Quartzite"
    },
    {
      "x": -6,
      "y": 0,
      "z": -6,
      "name": "Rock_Stone_Cobble"
    },
    {
      "x": -6,
      "y": 1,
      "z": -6,
      "name": "Furniture_Ancient_Table",
      "filler": 1
    },
    {
      "x": -6,
      "y": 2,
      "z": -6,
      "name": "Empty"
    },
    {
      "x": -6,
      "y": 3,
      "z": -6,
      "name": "Empty"
    },
    {
      "x": -6,
      "y": 4,
      "z": -6,
      "name": "Empty"
    },
    {
      "x": -6,
      "y": 5,
      "z": -6,
      "name": "Empty"
    },
    {
      "x": -6,
      "y": 6,
      "z": -6,
      "name": "Empty"
    },
    {
      "x": -6,
      "y": 7,
      "z": -6,
      "name": "Empty"
    },
    {
      "x": -6,
      "y": 8,
      "z": -6,
      "name": "Wood_Beech_Trunk_Full",
      "rotation": 4
    },
    {
      "x": -6,
      "y": 9,
      "z": -6,
      "name": "Rock_Quartzite"
    },
    {
      "x": -6,
      "y": 10,
      "z": -6,
      "name": "Rock_Quartzite"
    },
    {
      "x": -6,
      "y": 0,
      "z": -5,
      "name": "Rock_Stone_Cobble"
    },
    {
      "x": -6,
      "y": 1,
      "z": -5,
      "name": "Furniture_Ancient_Table",
      "filler": 33
    },
    {
      "x": -6,
      "y": 2,
      "z": -5,
      "name": "Empty"
    },
    {
      "x": -6,
      "y": 3,
      "z": -5,
      "name": "Empty"
    },
    {
      "x": -6,
      "y": 4,
      "z": -5,
      "name": "Empty"
    },
    {
      "x": -6,
      "y": 5,
      "z": -5,
      "name": "Empty"
    },
    {
      "x": -6,
      "y": 6,
      "z": -5,
      "name": "Empty"
    },
    {
      "x": -6,
      "y": 7,
      "z": -5,
      "name": "Empty"
    },
    {
      "x": -6,
      "y": 8,
      "z": -5,
      "name": "Rock_Quartzite_Brick"
    },
    {
      "x": -6,
      "y": 9,
      "z": -5,
      "name": "Rock_Quartzite"
    },
    {
      "x": -6,
      "y": 10,
      "z": -5,
      "name": "Rock_Quartzite"
    },
    {
      "x": -6,
      "y": 0,
      "z": -4,
      "name": "Plant_Moss_Block_Blue"
    },
    {
      "x": -6,
      "y": 1,
      "z": -4,
      "name": "Plant_Crop_Mushroom_Flatcap_Green",
      "components": {
        "Components": {
          "FarmingBlock": {}
        }
      }
    },
    {
      "x": -6,
      "y": 2,
      "z": -4,
      "name": "Empty"
    },
    {
      "x": -6,
      "y": 3,
      "z": -4,
      "name": "Empty"
    },
    {
      "x": -6,
      "y": 4,
      "z": -4,
      "name": "Empty"
    },
    {
      "x": -6,
      "y": 5,
      "z": -4,
      "name": "Empty"
    },
    {
      "x": -6,
      "y": 6,
      "z": -4,
      "name": "Empty"
    },
    {
      "x": -6,
      "y": 7,
      "z": -4,
      "name": "Rock_Quartzite_Brick"
    },
    {
      "x": -6,
      "y": 8,
      "z": -4,
      "name": "Rock_Quartzite_Brick"
    },
    {
      "x": -6,
      "y": 9,
      "z": -4,
      "name": "Rock_Quartzite"
    },
    {
      "x": -6,
      "y": 10,
      "z": -4,
      "name": "Rock_Quartzite"
    },
    {
      "x": -6,
      "y": 0,
      "z": -3,
      "name": "Plant_Moss_Block_Blue"
    },
    {
      "x": -6,
      "y": 1,
      "z": -3,
      "name": "Plant_Moss_Rug_Blue"
    },
    {
      "x": -6,
      "y": 2,
      "z": -3,
      "name": "Empty"
    },
    {
      "x": -6,
      "y": 3,
      "z": -3,
      "name": "Empty"
    },
    {
      "x": -6,
      "y": 4,
      "z": -3,
      "name": "Empty"
    },
    {
      "x": -6,
      "y": 5,
      "z": -3,
      "name": "Empty"
    },
    {
      "x": -6,
      "y": 6,
      "z": -3,
      "name": "Rock_Quartzite_Brick_Smooth"
    },
    {
      "x": -6,
      "y": 7,
      "z": -3,
      "name": "Rock_Quartzite_Brick"
    },
    {
      "x": -6,
      "y": 8,
      "z": -3,
      "name": "Rock_Quartzite_Brick"
    },
    {
      "x": -6,
      "y": 9,
      "z": -3,
      "name": "Rock_Quartzite"
    },
    {
      "x": -6,
      "y": 10,
      "z": -3,
      "name": "Rock_Quartzite"
    },
    {
      "x": -6,
      "y": 0,
      "z": -2,
      "name": "Plant_Moss_Block_Blue"
    },
    {
      "x": -6,
      "y": 1,
      "z": -2,
      "name": "Furniture_Ancient_Barrel"
    },
    {
      "x": -6,
      "y": 2,
      "z": -2,
      "name": "Empty"
    },
    {
      "x": -6,
      "y": 3,
      "z": -2,
      "name": "Empty"
    },
    {
      "x": -6,
      "y": 4,
      "z": -2,
      "name": "Rock_Quartzite_Brick_Half",
      "rotation": 5
    },
    {
      "x": -6,
      "y": 5,
      "z": -2,
      "name": "Rock_Quartzite_Brick"
    },
    {
      "x": -6,
      "y": 6,
      "z": -2,
      "name": "Rock_Quartzite_Brick"
    },
    {
      "x": -6,
      "y": 7,
      "z": -2,
      "name": "Rock_Quartzite_Brick"
    },
    {
      "x": -6,
      "y": 8,
      "z": -2,
      "name": "Rock_Quartzite_Brick"
    },
    {
      "x": -6,
      "y": 9,
      "z": -2,
      "name": "Rock_Quartzite"
    },
    {
      "x": -6,
      "y": 10,
      "z": -2,
      "name": "Rock_Quartzite"
    },
    {
      "x": -6,
      "y": 0,
      "z": -1,
      "name": "Rock_Stone_Cobble"
    },
    {
      "x": -6,
      "y": 1,
      "z": -1,
      "name": "Furniture_Ancient_Crate",
      "rotation": 2
    },
    {
      "x": -6,
      "y": 2,
      "z": -1,
      "name": "Furniture_Ancient_Crate",
      "rotation": 2
    },
    {
      "x": -6,
      "y": 3,
      "z": -1,
      "name": "Empty"
    },
    {
      "x": -6,
      "y": 4,
      "z": -1,
      "name": "Rock_Quartzite_Brick_Half",
      "rotation": 5
    },
    {
      "x": -6,
      "y": 5,
      "z": -1,
      "name": "Rock_Quartzite_Brick"
    },
    {
      "x": -6,
      "y": 6,
      "z": -1,
      "name": "Rock_Quartzite_Brick"
    },
    {
      "x": -6,
      "y": 7,
      "z": -1,
      "name": "Rock_Quartzite_Brick"
    },
    {
      "x": -6,
      "y": 8,
      "z": -1,
      "name": "Rock_Quartzite_Brick"
    },
    {
      "x": -6,
      "y": 9,
      "z": -1,
      "name": "Rock_Quartzite"
    },
    {
      "x": -6,
      "y": 10,
      "z": -1,
      "name": "Rock_Quartzite"
    },
    {
      "x": -6,
      "y": 0,
      "z": 0,
      "name": "Rock_Stone_Cobble"
    },
    {
      "x": -6,
      "y": 1,
      "z": 0,
      "name": "Rock_Quartzite_Brick"
    },
    {
      "x": -6,
      "y": 2,
      "z": 0,
      "name": "Rock_Quartzite_Brick"
    },
    {
      "x": -6,
      "y": 3,
      "z": 0,
      "name": "Rock_Quartzite"
    },
    {
      "x": -6,
      "y": 4,
      "z": 0,
      "name": "Rock_Quartzite"
    },
    {
      "x": -6,
      "y": 5,
      "z": 0,
      "name": "Rock_Quartzite"
    },
    {
      "x": -6,
      "y": 6,
      "z": 0,
      "name": "Rock_Quartzite"
    },
    {
      "x": -6,
      "y": 7,
      "z": 0,
      "name": "Rock_Quartzite"
    },
    {
      "x": -6,
      "y": 8,
      "z": 0,
      "name": "Rock_Quartzite"
    },
    {
      "x": -6,
      "y": 9,
      "z": 0,
      "name": "Rock_Quartzite"
    },
    {
      "x": -6,
      "y": 10,
      "z": 0,
      "name": "Rock_Quartzite"
    },
    {
      "x": -5,
      "y": 0,
      "z": -12,
      "name": "Rock_Stone_Cobble"
    },
    {
      "x": -5,
      "y": 1,
      "z": -12,
      "name": "Rock_Quartzite_Brick"
    },
    {
      "x": -5,
      "y": 2,
      "z": -12,
      "name": "Rock_Quartzite_Brick"
    },
    {
      "x": -5,
      "y": 3,
      "z": -12,
      "name": "Rock_Quartzite_Brick"
    },
    {
      "x": -5,
      "y": 4,
      "z": -12,
      "name": "Rock_Quartzite"
    },
    {
      "x": -5,
      "y": 5,
      "z": -12,
      "name": "Rock_Quartzite"
    },
    {
      "x": -5,
      "y": 6,
      "z": -12,
      "name": "Rock_Quartzite"
    },
    {
      "x": -5,
      "y": 7,
      "z": -12,
      "name": "Rock_Quartzite"
    },
    {
      "x": -5,
      "y": 8,
      "z": -12,
      "name": "Rock_Quartzite"
    },
    {
      "x": -5,
      "y": 9,
      "z": -12,
      "name": "Rock_Quartzite"
    },
    {
      "x": -5,
      "y": 10,
      "z": -12,
      "name": "Rock_Quartzite"
    },
    {
      "x": -5,
      "y": 0,
      "z": -11,
      "name": "Rock_Stone_Cobble"
    },
    {
      "x": -5,
      "y": 1,
      "z": -11,
      "name": "Rock_Stone_Cobble"
    },
    {
      "x": -5,
      "y": 2,
      "z": -11,
      "name": "Furniture_Village_Bookcase"
    },
    {
      "x": -5,
      "y": 3,
      "z": -11,
      "name": "Furniture_Village_Bookcase"
    },
    {
      "x": -5,
      "y": 4,
      "z": -11,
      "name": "Empty"
    },
    {
      "x": -5,
      "y": 5,
      "z": -11,
      "name": "Empty"
    },
    {
      "x": -5,
      "y": 6,
      "z": -11,
      "name": "Wood_Beech_Trunk_Full",
      "rotation": 4
    },
    {
      "x": -5,
      "y": 7,
      "z": -11,
      "name": "Rock_Quartzite_Brick"
    },
    {
      "x": -5,
      "y": 8,
      "z": -11,
      "name": "Rock_Quartzite_Brick"
    },
    {
      "x": -5,
      "y": 9,
      "z": -11,
      "name": "Rock_Quartzite"
    },
    {
      "x": -5,
      "y": 10,
      "z": -11,
      "name": "Rock_Quartzite"
    },
    {
      "x": -5,
      "y": 0,
      "z": -10,
      "name": "Rock_Stone_Cobble"
    },
    {
      "x": -5,
      "y": 1,
      "z": -10,
      "name": "Rock_Stone_Cobble"
    },
    {
      "x": -5,
      "y": 2,
      "z": -10,
      "name": "Empty"
    },
    {
      "x": -5,
      "y": 3,
      "z": -10,
      "name": "Empty"
    },
    {
      "x": -5,
      "y": 4,
      "z": -10,
      "name": "Empty"
    },
    {
      "x": -5,
      "y": 5,
      "z": -10,
      "name": "Empty"
    },
    {
      "x": -5,
      "y": 6,
      "z": -10,
      "name": "Wood_Beech_Trunk_Full",
      "rotation": 4
    },
    {
      "x": -5,
      "y": 7,
      "z": -10,
      "name": "Rock_Quartzite_Brick_Half",
      "rotation": 8
    },
    {
      "x": -5,
      "y": 8,
      "z": -10,
      "name": "Rock_Quartzite_Brick"
    },
    {
      "x": -5,
      "y": 9,
      "z": -10,
      "name": "Rock_Quartzite"
    },
    {
      "x": -5,
      "y": 10,
      "z": -10,
      "name": "Rock_Quartzite"
    },
    {
      "x": -5,
      "y": 0,
      "z": -9,
      "name": "Rock_Stone_Cobble"
    },
    {
      "x": -5,
      "y": 1,
      "z": -9,
      "name": "Rock_Stone_Cobble"
    },
    {
      "x": -5,
      "y": 2,
      "z": -9,
      "name": "Empty"
    },
    {
      "x": -5,
      "y": 3,
      "z": -9,
      "name": "Empty"
    },
    {
      "x": -5,
      "y": 4,
      "z": -9,
      "name": "Empty"
    },
    {
      "x": -5,
      "y": 5,
      "z": -9,
      "name": "Wood_Beech_Roots"
    },
    {
      "x": -5,
      "y": 6,
      "z": -9,
      "name": "Wood_Beech_Trunk_Full",
      "rotation": 4
    },
    {
      "x": -5,
      "y": 7,
      "z": -9,
      "name": "Wood_Beech_Trunk_Full",
      "rotation": 4
    },
    {
      "x": -5,
      "y": 8,
      "z": -9,
      "name": "Rock_Quartzite_Brick"
    },
    {
      "x": -5,
      "y": 9,
      "z": -9,
      "name": "Rock_Quartzite"
    },
    {
      "x": -5,
      "y": 10,
      "z": -9,
      "name": "Rock_Quartzite"
    },
    {
      "x": -5,
      "y": 0,
      "z": -8,
      "name": "Rock_Stone_Cobble"
    },
    {
      "x": -5,
      "y": 1,
      "z": -8,
      "name": "Rock_Stone_Brick"
    },
    {
      "x": -5,
      "y": 2,
      "z": -8,
      "name": "Empty"
    },
    {
      "x": -5,
      "y": 3,
      "z": -8,
      "name": "Empty"
    },
    {
      "x": -5,
      "y": 4,
      "z": -8,
      "name": "Empty"
    },
    {
      "x": -5,
      "y": 5,
      "z": -8,
      "name": "Empty"
    },
    {
      "x": -5,
      "y": 6,
      "z": -8,
      "name": "Empty"
    },
    {
      "x": -5,
      "y": 7,
      "z": -8,
      "name": "Empty"
    },
    {
      "x": -5,
      "y": 8,
      "z": -8,
      "name": "Empty"
    },
    {
      "x": -5,
      "y": 9,
      "z": -8,
      "name": "Rock_Quartzite"
    },
    {
      "x": -5,
      "y": 10,
      "z": -8,
      "name": "Rock_Quartzite"
    },
    {
      "x": -5,
      "y": 0,
      "z": -7,
      "name": "Rock_Stone_Cobble"
    },
    {
      "x": -5,
      "y": 1,
      "z": -7,
      "name": "Empty"
    },
    {
      "x": -5,
      "y": 2,
      "z": -7,
      "name": "Empty"
    },
    {
      "x": -5,
      "y": 3,
      "z": -7,
      "name": "Empty"
    },
    {
      "x": -5,
      "y": 4,
      "z": -7,
      "name": "Empty"
    },
    {
      "x": -5,
      "y": 5,
      "z": -7,
      "name": "Empty"
    },
    {
      "x": -5,
      "y": 6,
      "z": -7,
      "name": "Empty"
    },
    {
      "x": -5,
      "y": 7,
      "z": -7,
      "name": "Wood_Beech_Branch_Corner",
      "rotation": 1
    },
    {
      "x": -5,
      "y": 8,
      "z": -7,
      "name": "Rock_Quartzite_Brick_Half",
      "rotation": 8
    },
    {
      "x": -5,
      "y": 9,
      "z": -7,
      "name": "Rock_Quartzite"
    },
    {
      "x": -5,
      "y": 10,
      "z": -7,
      "name": "Rock_Quartzite"
    },
    {
      "x": -5,
      "y": 0,
      "z": -6,
      "name": "Rock_Stone_Cobble"
    },
    {
      "x": -5,
      "y": 1,
      "z": -6,
      "name": "Furniture_Ancient_Table"
    },
    {
      "x": -5,
      "y": 2,
      "z": -6,
      "name": "Deco_Scroll",
      "rotation": 1
    },
    {
      "x": -5,
      "y": 3,
      "z": -6,
      "name": "Empty"
    },
    {
      "x": -5,
      "y": 4,
      "z": -6,
      "name": "Empty"
    },
    {
      "x": -5,
      "y": 5,
      "z": -6,
      "name": "Empty"
    },
    {
      "x": -5,
      "y": 6,
      "z": -6,
      "name": "Empty"
    },
    {
      "x": -5,
      "y": 7,
      "z": -6,
      "name": "Empty"
    },
    {
      "x": -5,
      "y": 8,
      "z": -6,
      "name": "Rock_Quartzite_Brick_Half",
      "rotation": 8
    },
    {
      "x": -5,
      "y": 9,
      "z": -6,
      "name": "Rock_Quartzite"
    },
    {
      "x": -5,
      "y": 10,
      "z": -6,
      "name": "Rock_Quartzite"
    },
    {
      "x": -5,
      "y": 0,
      "z": -5,
      "name": "Rock_Stone_Cobble"
    },
    {
      "x": -5,
      "y": 1,
      "z": -5,
      "name": "Furniture_Ancient_Table",
      "filler": 32
    },
    {
      "x": -5,
      "y": 2,
      "z": -5,
      "name": "Deco_Potion"
    },
    {
      "x": -5,
      "y": 3,
      "z": -5,
      "name": "Empty"
    },
    {
      "x": -5,
      "y": 4,
      "z": -5,
      "name": "Empty"
    },
    {
      "x": -5,
      "y": 5,
      "z": -5,
      "name": "Empty"
    },
    {
      "x": -5,
      "y": 6,
      "z": -5,
      "name": "Empty"
    },
    {
      "x": -5,
      "y": 7,
      "z": -5,
      "name": "Empty"
    },
    {
      "x": -5,
      "y": 8,
      "z": -5,
      "name": "Rock_Quartzite_Brick"
    },
    {
      "x": -5,
      "y": 9,
      "z": -5,
      "name": "Rock_Quartzite"
    },
    {
      "x": -5,
      "y": 10,
      "z": -5,
      "name": "Rock_Quartzite"
    },
    {
      "x": -5,
      "y": 0,
      "z": -4,
      "name": "Rock_Stone_Cobble"
    },
    {
      "x": -5,
      "y": 1,
      "z": -4,
      "name": "Empty"
    },
    {
      "x": -5,
      "y": 2,
      "z": -4,
      "name": "Empty"
    },
    {
      "x": -5,
      "y": 3,
      "z": -4,
      "name": "Empty"
    },
    {
      "x": -5,
      "y": 4,
      "z": -4,
      "name": "Empty"
    },
    {
      "x": -5,
      "y": 5,
      "z": -4,
      "name": "Empty"
    },
    {
      "x": -5,
      "y": 6,
      "z": -4,
      "name": "Empty"
    },
    {
      "x": -5,
      "y": 7,
      "z": -4,
      "name": "Rock_Quartzite_Brick_Half",
      "rotation": 8
    },
    {
      "x": -5,
      "y": 8,
      "z": -4,
      "name": "Rock_Quartzite_Brick"
    },
    {
      "x": -5,
      "y": 9,
      "z": -4,
      "name": "Rock_Quartzite"
    },
    {
      "x": -5,
      "y": 10,
      "z": -4,
      "name": "Rock_Quartzite"
    },
    {
      "x": -5,
      "y": 0,
      "z": -3,
      "name": "Plant_Moss_Block_Blue"
    },
    {
      "x": -5,
      "y": 1,
      "z": -3,
      "name": "Empty"
    },
    {
      "x": -5,
      "y": 2,
      "z": -3,
      "name": "Empty"
    },
    {
      "x": -5,
      "y": 3,
      "z": -3,
      "name": "Empty"
    },
    {
      "x": -5,
      "y": 4,
      "z": -3,
      "name": "Empty"
    },
    {
      "x": -5,
      "y": 5,
      "z": -3,
      "name": "Empty"
    },
    {
      "x": -5,
      "y": 6,
      "z": -3,
      "name": "Rock_Quartzite_Brick_Smooth"
    },
    {
      "x": -5,
      "y": 7,
      "z": -3,
      "name": "Rock_Quartzite_Brick"
    },
    {
      "x": -5,
      "y": 8,
      "z": -3,
      "name": "Rock_Quartzite_Brick"
    },
    {
      "x": -5,
      "y": 9,
      "z": -3,
      "name": "Rock_Quartzite"
    },
    {
      "x": -5,
      "y": 10,
      "z": -3,
      "name": "Rock_Quartzite"
    },
    {
      "x": -5,
      "y": 0,
      "z": -2,
      "name": "Rock_Stone_Cobble"
    },
    {
      "x": -5,
      "y": 1,
      "z": -2,
      "name": "Block_Spawner_Block",
      "components": {
        "Components": {
          "BlockSpawner": {
            "BlockSpawnerId": "Zone1_Encounters_Tier3"
          }
        }
      },
      "rotation": 2
    },
    {
      "x": -5,
      "y": 2,
      "z": -2,
      "name": "Empty"
    },
    {
      "x": -5,
      "y": 3,
      "z": -2,
      "name": "Empty"
    },
    {
      "x": -5,
      "y": 4,
      "z": -2,
      "name": "Empty"
    },
    {
      "x": -5,
      "y": 5,
      "z": -2,
      "name": "Rock_Quartzite_Brick_Half",
      "rotation": 8
    },
    {
      "x": -5,
      "y": 6,
      "z": -2,
      "name": "Rock_Quartzite_Brick"
    },
    {
      "x": -5,
      "y": 7,
      "z": -2,
      "name": "Rock_Quartzite_Brick"
    },
    {
      "x": -5,
      "y": 8,
      "z": -2,
      "name": "Rock_Quartzite_Brick"
    },
    {
      "x": -5,
      "y": 9,
      "z": -2,
      "name": "Rock_Quartzite"
    },
    {
      "x": -5,
      "y": 10,
      "z": -2,
      "name": "Rock_Quartzite"
    },
    {
      "x": -5,
      "y": 0,
      "z": -1,
      "name": "Rock_Stone_Cobble"
    },
    {
      "x": -5,
      "y": 1,
      "z": -1,
      "name": "Furniture_Ancient_Crate",
      "rotation": 2
    },
    {
      "x": -5,
      "y": 2,
      "z": -1,
      "name": "Plant_Moss_Rug_Blue"
    },
    {
      "x": -5,
      "y": 3,
      "z": -1,
      "name": "Empty"
    },
    {
      "x": -5,
      "y": 4,
      "z": -1,
      "name": "Empty"
    },
    {
      "x": -5,
      "y": 5,
      "z": -1,
      "name": "Empty"
    },
    {
      "x": -5,
      "y": 6,
      "z": -1,
      "name": "Rock_Quartzite_Brick"
    },
    {
      "x": -5,
      "y": 7,
      "z": -1,
      "name": "Rock_Quartzite_Brick"
    },
    {
      "x": -5,
      "y": 8,
      "z": -1,
      "name": "Rock_Quartzite_Brick"
    },
    {
      "x": -5,
      "y": 9,
      "z": -1,
      "name": "Rock_Quartzite"
    },
    {
      "x": -5,
      "y": 10,
      "z": -1,
      "name": "Rock_Quartzite"
    },
    {
      "x": -5,
      "y": 0,
      "z": 0,
      "name": "Rock_Stone_Cobble"
    },
    {
      "x": -5,
      "y": 1,
      "z": 0,
      "name": "Rock_Quartzite_Brick"
    },
    {
      "x": -5,
      "y": 2,
      "z": 0,
      "name": "Rock_Quartzite_Brick"
    },
    {
      "x": -5,
      "y": 3,
      "z": 0,
      "name": "Rock_Quartzite"
    },
    {
      "x": -5,
      "y": 4,
      "z": 0,
      "name": "Rock_Quartzite"
    },
    {
      "x": -5,
      "y": 5,
      "z": 0,
      "name": "Rock_Quartzite"
    },
    {
      "x": -5,
      "y": 6,
      "z": 0,
      "name": "Rock_Quartzite"
    },
    {
      "x": -5,
      "y": 7,
      "z": 0,
      "name": "Rock_Quartzite"
    },
    {
      "x": -5,
      "y": 8,
      "z": 0,
      "name": "Rock_Quartzite"
    },
    {
      "x": -5,
      "y": 9,
      "z": 0,
      "name": "Rock_Quartzite"
    },
    {
      "x": -5,
      "y": 10,
      "z": 0,
      "name": "Rock_Quartzite"
    },
    {
      "x": -4,
      "y": 0,
      "z": -12,
      "name": "Rock_Stone_Cobble"
    },
    {
      "x": -4,
      "y": 1,
      "z": -12,
      "name": "Rock_Quartzite_Brick"
    },
    {
      "x": -4,
      "y": 2,
      "z": -12,
      "name": "Rock_Quartzite_Brick"
    },
    {
      "x": -4,
      "y": 3,
      "z": -12,
      "name": "Rock_Quartzite"
    },
    {
      "x": -4,
      "y": 4,
      "z": -12,
      "name": "Rock_Quartzite"
    },
    {
      "x": -4,
      "y": 5,
      "z": -12,
      "name": "Rock_Quartzite"
    },
    {
      "x": -4,
      "y": 6,
      "z": -12,
      "name": "Rock_Quartzite"
    },
    {
      "x": -4,
      "y": 7,
      "z": -12,
      "name": "Rock_Quartzite"
    },
    {
      "x": -4,
      "y": 8,
      "z": -12,
      "name": "Rock_Quartzite"
    },
    {
      "x": -4,
      "y": 9,
      "z": -12,
      "name": "Rock_Quartzite"
    },
    {
      "x": -4,
      "y": 10,
      "z": -12,
      "name": "Rock_Quartzite"
    },
    {
      "x": -4,
      "y": 0,
      "z": -11,
      "name": "Rock_Stone_Cobble"
    },
    {
      "x": -4,
      "y": 1,
      "z": -11,
      "name": "Rock_Stone_Cobble"
    },
    {
      "x": -4,
      "y": 2,
      "z": -11,
      "name": "Furniture_Village_Bookcase"
    },
    {
      "x": -4,
      "y": 3,
      "z": -11,
      "name": "Empty"
    },
    {
      "x": -4,
      "y": 4,
      "z": -11,
      "name": "Empty"
    },
    {
      "x": -4,
      "y": 5,
      "z": -11,
      "name": "Empty"
    },
    {
      "x": -4,
      "y": 6,
      "z": -11,
      "name": "Rock_Quartzite_Brick_Smooth"
    },
    {
      "x": -4,
      "y": 7,
      "z": -11,
      "name": "Rock_Quartzite_Brick"
    },
    {
      "x": -4,
      "y": 8,
      "z": -11,
      "name": "Rock_Quartzite_Brick"
    },
    {
      "x": -4,
      "y": 9,
      "z": -11,
      "name": "Rock_Quartzite"
    },
    {
      "x": -4,
      "y": 10,
      "z": -11,
      "name": "Rock_Quartzite"
    },
    {
      "x": -4,
      "y": 0,
      "z": -10,
      "name": "Rock_Stone_Cobble"
    },
    {
      "x": -4,
      "y": 1,
      "z": -10,
      "name": "Rock_Stone_Cobble"
    },
    {
      "x": -4,
      "y": 2,
      "z": -10,
      "name": "Empty"
    },
    {
      "x": -4,
      "y": 3,
      "z": -10,
      "name": "Empty"
    },
    {
      "x": -4,
      "y": 4,
      "z": -10,
      "name": "Empty"
    },
    {
      "x": -4,
      "y": 5,
      "z": -10,
      "name": "Empty"
    },
    {
      "x": -4,
      "y": 6,
      "z": -10,
      "name": "Empty"
    },
    {
      "x": -4,
      "y": 7,
      "z": -10,
      "name": "Empty"
    },
    {
      "x": -4,
      "y": 8,
      "z": -10,
      "name": "Rock_Quartzite_Brick"
    },
    {
      "x": -4,
      "y": 9,
      "z": -10,
      "name": "Rock_Quartzite"
    },
    {
      "x": -4,
      "y": 10,
      "z": -10,
      "name": "Rock_Quartzite"
    },
    {
      "x": -4,
      "y": 0,
      "z": -9,
      "name": "Rock_Stone_Cobble"
    },
    {
      "x": -4,
      "y": 1,
      "z": -9,
      "name": "Rock_Stone_Cobble"
    },
    {
      "x": -4,
      "y": 2,
      "z": -9,
      "name": "Empty"
    },
    {
      "x": -4,
      "y": 3,
      "z": -9,
      "name": "Empty"
    },
    {
      "x": -4,
      "y": 4,
      "z": -9,
      "name": "Empty"
    },
    {
      "x": -4,
      "y": 5,
      "z": -9,
      "name": "Empty"
    },
    {
      "x": -4,
      "y": 6,
      "z": -9,
      "name": "Wood_Beech_Branch_Corner",
      "rotation": 1
    },
    {
      "x": -4,
      "y": 7,
      "z": -9,
      "name": "Wood_Beech_Branch_Corner",
      "rotation": 9
    },
    {
      "x": -4,
      "y": 8,
      "z": -9,
      "name": "Rock_Quartzite_Brick"
    },
    {
      "x": -4,
      "y": 9,
      "z": -9,
      "name": "Rock_Quartzite"
    },
    {
      "x": -4,
      "y": 10,
      "z": -9,
      "name": "Rock_Quartzite"
    },
    {
      "x": -4,
      "y": 0,
      "z": -8,
      "name": "Rock_Stone_Cobble"
    },
    {
      "x": -4,
      "y": 1,
      "z": -8,
      "name": "Rock_Stone_Brick"
    },
    {
      "x": -4,
      "y": 2,
      "z": -8,
      "name": "Rock_Stone_Brick_Wall"
    },
    {
      "x": -4,
      "y": 3,
      "z": -8,
      "name": "Empty"
    },
    {
      "x": -4,
      "y": 4,
      "z": -8,
      "name": "Empty"
    },
    {
      "x": -4,
      "y": 5,
      "z": -8,
      "name": "Empty"
    },
    {
      "x": -4,
      "y": 6,
      "z": -8,
      "name": "Empty"
    },
    {
      "x": -4,
      "y": 7,
      "z": -8,
      "name": "Empty"
    },
    {
      "x": -4,
      "y": 8,
      "z": -8,
      "name": "Empty"
    },
    {
      "x": -4,
      "y": 9,
      "z": -8,
      "name": "Rock_Quartzite"
    },
    {
      "x": -4,
      "y": 10,
      "z": -8,
      "name": "Rock_Quartzite"
    },
    {
      "x": -4,
      "y": 0,
      "z": -7,
      "name": "Rock_Stone_Brick"
    },
    {
      "x": -4,
      "y": 1,
      "z": -7,
      "name": "Empty"
    },
    {
      "x": -4,
      "y": 2,
      "z": -7,
      "name": "Empty"
    },
    {
      "x": -4,
      "y": 3,
      "z": -7,
      "name": "Empty"
    },
    {
      "x": -4,
      "y": 4,
      "z": -7,
      "name": "Empty"
    },
    {
      "x": -4,
      "y": 5,
      "z": -7,
      "name": "Empty"
    },
    {
      "x": -4,
      "y": 6,
      "z": -7,
      "name": "Deco_Iron_Chain_Small"
    },
    {
      "x": -4,
      "y": 7,
      "z": -7,
      "name": "Deco_Iron_Chain_Small"
    },
    {
      "x": -4,
      "y": 8,
      "z": -7,
      "name": "Deco_Iron_Chain_Small"
    },
    {
      "x": -4,
      "y": 9,
      "z": -7,
      "name": "Rock_Quartzite"
    },
    {
      "x": -4,
      "y": 10,
      "z": -7,
      "name": "Rock_Quartzite"
    },
    {
      "x": -4,
      "y": 0,
      "z": -6,
      "name": "Rock_Stone_Brick"
    },
    {
      "x": -4,
      "y": 1,
      "z": -6,
      "name": "Furniture_Ancient_Table",
      "filler": 1
    },
    {
      "x": -4,
      "y": 2,
      "z": -6,
      "name": "Empty"
    },
    {
      "x": -4,
      "y": 3,
      "z": -6,
      "name": "Empty"
    },
    {
      "x": -4,
      "y": 4,
      "z": -6,
      "name": "Empty"
    },
    {
      "x": -4,
      "y": 5,
      "z": -6,
      "name": "Empty"
    },
    {
      "x": -4,
      "y": 6,
      "z": -6,
      "name": "Empty"
    },
    {
      "x": -4,
      "y": 7,
      "z": -6,
      "name": "Empty"
    },
    {
      "x": -4,
      "y": 8,
      "z": -6,
      "name": "Rock_Quartzite_Brick_Half",
      "rotation": 8
    },
    {
      "x": -4,
      "y": 9,
      "z": -6,
      "name": "Rock_Quartzite"
    },
    {
      "x": -4,
      "y": 10,
      "z": -6,
      "name": "Rock_Quartzite"
    },
    {
      "x": -4,
      "y": 0,
      "z": -5,
      "name": "Rock_Stone_Cobble"
    },
    {
      "x": -4,
      "y": 1,
      "z": -5,
      "name": "Furniture_Ancient_Table",
      "filler": 33
    },
    {
      "x": -4,
      "y": 2,
      "z": -5,
      "name": "Empty"
    },
    {
      "x": -4,
      "y": 3,
      "z": -5,
      "name": "Empty"
    },
    {
      "x": -4,
      "y": 4,
      "z": -5,
      "name": "Empty"
    },
    {
      "x": -4,
      "y": 5,
      "z": -5,
      "name": "Empty"
    },
    {
      "x": -4,
      "y": 6,
      "z": -5,
      "name": "Empty"
    },
    {
      "x": -4,
      "y": 7,
      "z": -5,
      "name": "Empty"
    },
    {
      "x": -4,
      "y": 8,
      "z": -5,
      "name": "Rock_Quartzite_Brick"
    },
    {
      "x": -4,
      "y": 9,
      "z": -5,
      "name": "Rock_Quartzite"
    },
    {
      "x": -4,
      "y": 10,
      "z": -5,
      "name": "Rock_Quartzite"
    },
    {
      "x": -4,
      "y": 0,
      "z": -4,
      "name": "Rock_Stone_Brick"
    },
    {
      "x": -4,
      "y": 1,
      "z": -4,
      "name": "Empty"
    },
    {
      "x": -4,
      "y": 2,
      "z": -4,
      "name": "Empty"
    },
    {
      "x": -4,
      "y": 3,
      "z": -4,
      "name": "Empty"
    },
    {
      "x": -4,
      "y": 4,
      "z": -4,
      "name": "Empty"
    },
    {
      "x": -4,
      "y": 5,
      "z": -4,
      "name": "Empty"
    },
    {
      "x": -4,
      "y": 6,
      "z": -4,
      "name": "Empty"
    },
    {
      "x": -4,
      "y": 7,
      "z": -4,
      "name": "Rock_Quartzite_Brick_Half",
      "rotation": 8
    },
    {
      "x": -4,
      "y": 8,
      "z": -4,
      "name": "Rock_Quartzite_Brick"
    },
    {
      "x": -4,
      "y": 9,
      "z": -4,
      "name": "Rock_Quartzite"
    },
    {
      "x": -4,
      "y": 10,
      "z": -4,
      "name": "Rock_Quartzite"
    },
    {
      "x": -4,
      "y": 0,
      "z": -3,
      "name": "Rock_Stone_Brick"
    },
    {
      "x": -4,
      "y": 1,
      "z": -3,
      "name": "Empty"
    },
    {
      "x": -4,
      "y": 2,
      "z": -3,
      "name": "Empty"
    },
    {
      "x": -4,
      "y": 3,
      "z": -3,
      "name": "Empty"
    },
    {
      "x": -4,
      "y": 4,
      "z": -3,
      "name": "Empty"
    },
    {
      "x": -4,
      "y": 5,
      "z": -3,
      "name": "Empty"
    },
    {
      "x": -4,
      "y": 6,
      "z": -3,
      "name": "Rock_Quartzite_Brick_Smooth"
    },
    {
      "x": -4,
      "y": 7,
      "z": -3,
      "name": "Rock_Quartzite_Brick"
    },
    {
      "x": -4,
      "y": 8,
      "z": -3,
      "name": "Rock_Quartzite_Brick"
    },
    {
      "x": -4,
      "y": 9,
      "z": -3,
      "name": "Rock_Quartzite"
    },
    {
      "x": -4,
      "y": 10,
      "z": -3,
      "name": "Rock_Quartzite"
    },
    {
      "x": -4,
      "y": 0,
      "z": -2,
      "name": "Rock_Stone_Brick"
    },
    {
      "x": -4,
      "y": 1,
      "z": -2,
      "name": "Empty"
    },
    {
      "x": -4,
      "y": 2,
      "z": -2,
      "name": "Empty"
    },
    {
      "x": -4,
      "y": 3,
      "z": -2,
      "name": "Empty"
    },
    {
      "x": -4,
      "y": 4,
      "z": -2,
      "name": "Empty"
    },
    {
      "x": -4,
      "y": 5,
      "z": -2,
      "name": "Empty"
    },
    {
      "x": -4,
      "y": 6,
      "z": -2,
      "name": "Rock_Quartzite_Brick"
    },
    {
      "x": -4,
      "y": 7,
      "z": -2,
      "name": "Rock_Quartzite_Brick"
    },
    {
      "x": -4,
      "y": 8,
      "z": -2,
      "name": "Rock_Quartzite_Brick"
    },
    {
      "x": -4,
      "y": 9,
      "z": -2,
      "name": "Rock_Quartzite"
    },
    {
      "x": -4,
      "y": 10,
      "z": -2,
      "name": "Rock_Quartzite"
    },
    {
      "x": -4,
      "y": 0,
      "z": -1,
      "name": "Rock_Stone_Brick"
    },
    {
      "x": -4,
      "y": 1,
      "z": -1,
      "name": "Furniture_Ancient_Barrel"
    },
    {
      "x": -4,
      "y": 2,
      "z": -1,
      "name": "Furniture_Ancient_Shelf",
      "rotation": 2
    },
    {
      "x": -4,
      "y": 3,
      "z": -1,
      "name": "Empty"
    },
    {
      "x": -4,
      "y": 4,
      "z": -1,
      "name": "Empty"
    },
    {
      "x": -4,
      "y": 5,
      "z": -1,
      "name": "Rock_Quartzite_Brick_Half",
      "rotation": 8
    },
    {
      "x": -4,
      "y": 6,
      "z": -1,
      "name": "Rock_Quartzite_Brick"
    },
    {
      "x": -4,
      "y": 7,
      "z": -1,
      "name": "Rock_Quartzite_Brick"
    },
    {
      "x": -4,
      "y": 8,
      "z": -1,
      "name": "Rock_Quartzite_Brick"
    },
    {
      "x": -4,
      "y": 9,
      "z": -1,
      "name": "Rock_Quartzite"
    },
    {
      "x": -4,
      "y": 10,
      "z": -1,
      "name": "Rock_Quartzite"
    },
    {
      "x": -4,
      "y": 0,
      "z": 0,
      "name": "Rock_Stone_Cobble"
    },
    {
      "x": -4,
      "y": 1,
      "z": 0,
      "name": "Rock_Quartzite_Brick"
    },
    {
      "x": -4,
      "y": 2,
      "z": 0,
      "name": "Rock_Quartzite_Brick"
    },
    {
      "x": -4,
      "y": 3,
      "z": 0,
      "name": "Rock_Quartzite_Brick"
    },
    {
      "x": -4,
      "y": 4,
      "z": 0,
      "name": "Rock_Quartzite"
    },
    {
      "x": -4,
      "y": 5,
      "z": 0,
      "name": "Rock_Quartzite"
    },
    {
      "x": -4,
      "y": 6,
      "z": 0,
      "name": "Rock_Quartzite"
    },
    {
      "x": -4,
      "y": 7,
      "z": 0,
      "name": "Rock_Quartzite"
    },
    {
      "x": -4,
      "y": 8,
      "z": 0,
      "name": "Rock_Quartzite"
    },
    {
      "x": -4,
      "y": 9,
      "z": 0,
      "name": "Rock_Quartzite"
    },
    {
      "x": -4,
      "y": 10,
      "z": 0,
      "name": "Rock_Quartzite"
    },
    {
      "x": -3,
      "y": 0,
      "z": -12,
      "name": "Rock_Stone_Cobble"
    },
    {
      "x": -3,
      "y": 1,
      "z": -12,
      "name": "Rock_Quartzite_Brick"
    },
    {
      "x": -3,
      "y": 2,
      "z": -12,
      "name": "Rock_Quartzite_Brick"
    },
    {
      "x": -3,
      "y": 3,
      "z": -12,
      "name": "Rock_Quartzite"
    },
    {
      "x": -3,
      "y": 4,
      "z": -12,
      "name": "Rock_Quartzite"
    },
    {
      "x": -3,
      "y": 5,
      "z": -12,
      "name": "Rock_Quartzite"
    },
    {
      "x": -3,
      "y": 6,
      "z": -12,
      "name": "Rock_Quartzite"
    },
    {
      "x": -3,
      "y": 7,
      "z": -12,
      "name": "Rock_Quartzite"
    },
    {
      "x": -3,
      "y": 8,
      "z": -12,
      "name": "Rock_Quartzite"
    },
    {
      "x": -3,
      "y": 9,
      "z": -12,
      "name": "Rock_Quartzite"
    },
    {
      "x": -3,
      "y": 10,
      "z": -12,
      "name": "Rock_Quartzite"
    },
    {
      "x": -3,
      "y": 0,
      "z": -11,
      "name": "Rock_Stone_Cobble"
    },
    {
      "x": -3,
      "y": 1,
      "z": -11,
      "name": "Rock_Stone_Brick_Stairs",
      "rotation": 1
    },
    {
      "x": -3,
      "y": 2,
      "z": -11,
      "name": "Empty"
    },
    {
      "x": -3,
      "y": 3,
      "z": -11,
      "name": "Empty"
    },
    {
      "x": -3,
      "y": 4,
      "z": -11,
      "name": "Empty"
    },
    {
      "x": -3,
      "y": 5,
      "z": -11,
      "name": "Empty"
    },
    {
      "x": -3,
      "y": 6,
      "z": -11,
      "name": "Rock_Quartzite_Brick_Smooth"
    },
    {
      "x": -3,
      "y": 7,
      "z": -11,
      "name": "Rock_Quartzite_Brick"
    },
    {
      "x": -3,
      "y": 8,
      "z": -11,
      "name": "Rock_Quartzite_Brick"
    },
    {
      "x": -3,
      "y": 9,
      "z": -11,
      "name": "Rock_Quartzite"
    },
    {
      "x": -3,
      "y": 10,
      "z": -11,
      "name": "Rock_Quartzite"
    },
    {
      "x": -3,
      "y": 0,
      "z": -10,
      "name": "Rock_Stone_Cobble"
    },
    {
      "x": -3,
      "y": 1,
      "z": -10,
      "name": "Rock_Stone_Brick_Stairs",
      "rotation": 1
    },
    {
      "x": -3,
      "y": 2,
      "z": -10,
      "name": "Empty"
    },
    {
      "x": -3,
      "y": 3,
      "z": -10,
      "name": "Empty"
    },
    {
      "x": -3,
      "y": 4,
      "z": -10,
      "name": "Empty"
    },
    {
      "x": -3,
      "y": 5,
      "z": -10,
      "name": "Empty"
    },
    {
      "x": -3,
      "y": 6,
      "z": -10,
      "name": "Empty"
    },
    {
      "x": -3,
      "y": 7,
      "z": -10,
      "name": "Empty"
    },
    {
      "x": -3,
      "y": 8,
      "z": -10,
      "name": "Rock_Quartzite_Brick"
    },
    {
      "x": -3,
      "y": 9,
      "z": -10,
      "name": "Rock_Quartzite"
    },
    {
      "x": -3,
      "y": 10,
      "z": -10,
      "name": "Rock_Quartzite"
    },
    {
      "x": -3,
      "y": 0,
      "z": -9,
      "name": "Rock_Stone_Cobble"
    },
    {
      "x": -3,
      "y": 1,
      "z": -9,
      "name": "Rock_Stone_Brick_Stairs",
      "rotation": 1
    },
    {
      "x": -3,
      "y": 2,
      "z": -9,
      "name": "Empty"
    },
    {
      "x": -3,
      "y": 3,
      "z": -9,
      "name": "Empty"
    },
    {
      "x": -3,
      "y": 4,
      "z": -9,
      "name": "Empty"
    },
    {
      "x": -3,
      "y": 5,
      "z": -9,
      "name": "Empty"
    },
    {
      "x": -3,
      "y": 6,
      "z": -9,
      "name": "Empty"
    },
    {
      "x": -3,
      "y": 7,
      "z": -9,
      "name": "Wood_Beech_Branch_Corner",
      "rotation": 11
    },
    {
      "x": -3,
      "y": 8,
      "z": -9,
      "name": "Rock_Quartzite_Brick"
    },
    {
      "x": -3,
      "y": 9,
      "z": -9,
      "name": "Rock_Quartzite"
    },
    {
      "x": -3,
      "y": 10,
      "z": -9,
      "name": "Rock_Quartzite"
    },
    {
      "x": -3,
      "y": 0,
      "z": -8,
      "name": "Rock_Stone_Cobble"
    },
    {
      "x": -3,
      "y": 1,
      "z": -8,
      "name": "Rock_Stone_Brick"
    },
    {
      "x": -3,
      "y": 2,
      "z": -8,
      "name": "Rock_Stone_Brick_Wall"
    },
    {
      "x": -3,
      "y": 3,
      "z": -8,
      "name": "Empty"
    },
    {
      "x": -3,
      "y": 4,
      "z": -8,
      "name": "Empty"
    },
    {
      "x": -3,
      "y": 5,
      "z": -8,
      "name": "Empty"
    },
    {
      "x": -3,
      "y": 6,
      "z": -8,
      "name": "Empty"
    },
    {
      "x": -3,
      "y": 7,
      "z": -8,
      "name": "Empty"
    },
    {
      "x": -3,
      "y": 8,
      "z": -8,
      "name": "Rock_Quartzite_Brick_Half",
      "rotation": 8
    },
    {
      "x": -3,
      "y": 9,
      "z": -8,
      "name": "Rock_Quartzite"
    },
    {
      "x": -3,
      "y": 10,
      "z": -8,
      "name": "Rock_Quartzite"
    },
    {
      "x": -3,
      "y": 0,
      "z": -7,
      "name": "Rock_Stone_Brick"
    },
    {
      "x": -3,
      "y": 1,
      "z": -7,
      "name": "Empty"
    },
    {
      "x": -3,
      "y": 2,
      "z": -7,
      "name": "Empty"
    },
    {
      "x": -3,
      "y": 3,
      "z": -7,
      "name": "Empty"
    },
    {
      "x": -3,
      "y": 4,
      "z": -7,
      "name": "Empty"
    },
    {
      "x": -3,
      "y": 5,
      "z": -7,
      "name": "Empty"
    },
    {
      "x": -3,
      "y": 6,
      "z": -7,
      "name": "Empty"
    },
    {
      "x": -3,
      "y": 7,
      "z": -7,
      "name": "Empty"
    },
    {
      "x": -3,
      "y": 8,
      "z": -7,
      "name": "Empty"
    },
    {
      "x": -3,
      "y": 9,
      "z": -7,
      "name": "Rock_Quartzite"
    },
    {
      "x": -3,
      "y": 10,
      "z": -7,
      "name": "Rock_Quartzite"
    },
    {
      "x": -3,
      "y": 0,
      "z": -6,
      "name": "Rock_Stone_Brick"
    },
    {
      "x": -3,
      "y": 1,
      "z": -6,
      "name": "Empty"
    },
    {
      "x": -3,
      "y": 2,
      "z": -6,
      "name": "Empty"
    },
    {
      "x": -3,
      "y": 3,
      "z": -6,
      "name": "Empty"
    },
    {
      "x": -3,
      "y": 4,
      "z": -6,
      "name": "Empty"
    },
    {
      "x": -3,
      "y": 5,
      "z": -6,
      "name": "Empty"
    },
    {
      "x": -3,
      "y": 6,
      "z": -6,
      "name": "Empty"
    },
    {
      "x": -3,
      "y": 7,
      "z": -6,
      "name": "Empty"
    },
    {
      "x": -3,
      "y": 8,
      "z": -6,
      "name": "Rock_Quartzite_Brick_Half",
      "rotation": 8
    },
    {
      "x": -3,
      "y": 9,
      "z": -6,
      "name": "Rock_Quartzite"
    },
    {
      "x": -3,
      "y": 10,
      "z": -6,
      "name": "Rock_Quartzite"
    },
    {
      "x": -3,
      "y": 0,
      "z": -5,
      "name": "Rock_Stone_Cobble"
    },
    {
      "x": -3,
      "y": 1,
      "z": -5,
      "name": "Empty"
    },
    {
      "x": -3,
      "y": 2,
      "z": -5,
      "name": "Empty"
    },
    {
      "x": -3,
      "y": 3,
      "z": -5,
      "name": "Empty"
    },
    {
      "x": -3,
      "y": 4,
      "z": -5,
      "name": "Empty"
    },
    {
      "x": -3,
      "y": 5,
      "z": -5,
      "name": "Empty"
    },
    {
      "x": -3,
      "y": 6,
      "z": -5,
      "name": "Empty"
    },
    {
      "x": -3,
      "y": 7,
      "z": -5,
      "name": "Empty"
    },
    {
      "x": -3,
      "y": 8,
      "z": -5,
      "name": "Rock_Quartzite_Brick"
    },
    {
      "x": -3,
      "y": 9,
      "z": -5,
      "name": "Rock_Quartzite"
    },
    {
      "x": -3,
      "y": 10,
      "z": -5,
      "name": "Rock_Quartzite"
    },
    {
      "x": -3,
      "y": 0,
      "z": -4,
      "name": "Rock_Stone_Brick"
    },
    {
      "x": -3,
      "y": 1,
      "z": -4,
      "name": "Empty"
    },
    {
      "x": -3,
      "y": 2,
      "z": -4,
      "name": "Empty"
    },
    {
      "x": -3,
      "y": 3,
      "z": -4,
      "name": "Empty"
    },
    {
      "x": -3,
      "y": 4,
      "z": -4,
      "name": "Empty"
    },
    {
      "x": -3,
      "y": 5,
      "z": -4,
      "name": "Empty"
    },
    {
      "x": -3,
      "y": 6,
      "z": -4,
      "name": "Empty"
    },
    {
      "x": -3,
      "y": 7,
      "z": -4,
      "name": "Empty"
    },
    {
      "x": -3,
      "y": 8,
      "z": -4,
      "name": "Rock_Quartzite_Brick"
    },
    {
      "x": -3,
      "y": 9,
      "z": -4,
      "name": "Rock_Quartzite"
    },
    {
      "x": -3,
      "y": 10,
      "z": -4,
      "name": "Rock_Quartzite"
    },
    {
      "x": -3,
      "y": 0,
      "z": -3,
      "name": "Rock_Stone_Brick"
    },
    {
      "x": -3,
      "y": 1,
      "z": -3,
      "name": "Empty"
    },
    {
      "x": -3,
      "y": 2,
      "z": -3,
      "name": "Empty"
    },
    {
      "x": -3,
      "y": 3,
      "z": -3,
      "name": "Empty"
    },
    {
      "x": -3,
      "y": 4,
      "z": -3,
      "name": "Empty"
    },
    {
      "x": -3,
      "y": 5,
      "z": -3,
      "name": "Empty"
    },
    {
      "x": -3,
      "y": 6,
      "z": -3,
      "name": "Rock_Quartzite_Brick_Smooth"
    },
    {
      "x": -3,
      "y": 7,
      "z": -3,
      "name": "Rock_Quartzite_Brick"
    },
    {
      "x": -3,
      "y": 8,
      "z": -3,
      "name": "Rock_Quartzite_Brick"
    },
    {
      "x": -3,
      "y": 9,
      "z": -3,
      "name": "Rock_Quartzite"
    },
    {
      "x": -3,
      "y": 10,
      "z": -3,
      "name": "Rock_Quartzite"
    },
    {
      "x": -3,
      "y": 0,
      "z": -2,
      "name": "Rock_Stone_Brick"
    },
    {
      "x": -3,
      "y": 1,
      "z": -2,
      "name": "Rubble_Quartzite_Medium"
    },
    {
      "x": -3,
      "y": 2,
      "z": -2,
      "name": "Empty"
    },
    {
      "x": -3,
      "y": 3,
      "z": -2,
      "name": "Empty"
    },
    {
      "x": -3,
      "y": 4,
      "z": -2,
      "name": "Rock_Quartzite_Brick_Half",
      "rotation": 7
    },
    {
      "x": -3,
      "y": 5,
      "z": -2,
      "name": "Rock_Quartzite_Brick"
    },
    {
      "x": -3,
      "y": 6,
      "z": -2,
      "name": "Rock_Quartzite_Brick"
    },
    {
      "x": -3,
      "y": 7,
      "z": -2,
      "name": "Rock_Quartzite_Brick"
    },
    {
      "x": -3,
      "y": 8,
      "z": -2,
      "name": "Rock_Quartzite_Brick"
    },
    {
      "x": -3,
      "y": 9,
      "z": -2,
      "name": "Rock_Quartzite"
    },
    {
      "x": -3,
      "y": 10,
      "z": -2,
      "name": "Rock_Quartzite"
    },
    {
      "x": -3,
      "y": 0,
      "z": -1,
      "name": "Rock_Stone_Cobble"
    },
    {
      "x": -3,
      "y": 1,
      "z": -1,
      "name": "Furniture_Ancient_Shelf",
      "rotation": 2
    },
    {
      "x": -3,
      "y": 2,
      "z": -1,
      "name": "Furniture_Ancient_Shelf",
      "rotation": 2
    },
    {
      "x": -3,
      "y": 3,
      "z": -1,
      "name": "Empty"
    },
    {
      "x": -3,
      "y": 4,
      "z": -1,
      "name": "Rock_Quartzite_Brick_Half",
      "rotation": 7
    },
    {
      "x": -3,
      "y": 5,
      "z": -1,
      "name": "Rock_Quartzite_Brick"
    },
    {
      "x": -3,
      "y": 6,
      "z": -1,
      "name": "Rock_Quartzite_Brick"
    },
    {
      "x": -3,
      "y": 7,
      "z": -1,
      "name": "Rock_Quartzite_Brick"
    },
    {
      "x": -3,
      "y": 8,
      "z": -1,
      "name": "Rock_Quartzite_Brick"
    },
    {
      "x": -3,
      "y": 9,
      "z": -1,
      "name": "Rock_Quartzite"
    },
    {
      "x": -3,
      "y": 10,
      "z": -1,
      "name": "Rock_Quartzite"
    },
    {
      "x": -3,
      "y": 0,
      "z": 0,
      "name": "Rock_Stone_Cobble"
    },
    {
      "x": -3,
      "y": 1,
      "z": 0,
      "name": "Rock_Quartzite_Brick"
    },
    {
      "x": -3,
      "y": 2,
      "z": 0,
      "name": "Rock_Quartzite_Brick"
    },
    {
      "x": -3,
      "y": 3,
      "z": 0,
      "name": "Rock_Quartzite_Brick"
    },
    {
      "x": -3,
      "y": 4,
      "z": 0,
      "name": "Rock_Quartzite_Brick"
    },
    {
      "x": -3,
      "y": 5,
      "z": 0,
      "name": "Rock_Quartzite_Brick_Smooth"
    },
    {
      "x": -3,
      "y": 6,
      "z": 0,
      "name": "Rock_Quartzite_Brick"
    },
    {
      "x": -3,
      "y": 7,
      "z": 0,
      "name": "Rock_Quartzite_Brick"
    },
    {
      "x": -3,
      "y": 8,
      "z": 0,
      "name": "Rock_Quartzite_Brick"
    },
    {
      "x": -3,
      "y": 9,
      "z": 0,
      "name": "Rock_Quartzite_Brick"
    },
    {
      "x": -3,
      "y": 10,
      "z": 0,
      "name": "Rock_Quartzite_Brick"
    },
    {
      "x": -2,
      "y": 0,
      "z": -12,
      "name": "Rock_Stone_Cobble"
    },
    {
      "x": -2,
      "y": 1,
      "z": -12,
      "name": "Rock_Quartzite_Brick"
    },
    {
      "x": -2,
      "y": 2,
      "z": -12,
      "name": "Rock_Quartzite_Brick"
    },
    {
      "x": -2,
      "y": 3,
      "z": -12,
      "name": "Rock_Quartzite_Brick"
    },
    {
      "x": -2,
      "y": 4,
      "z": -12,
      "name": "Rock_Quartzite"
    },
    {
      "x": -2,
      "y": 5,
      "z": -12,
      "name": "Rock_Quartzite"
    },
    {
      "x": -2,
      "y": 6,
      "z": -12,
      "name": "Rock_Quartzite"
    },
    {
      "x": -2,
      "y": 7,
      "z": -12,
      "name": "Rock_Quartzite"
    },
    {
      "x": -2,
      "y": 8,
      "z": -12,
      "name": "Rock_Quartzite"
    },
    {
      "x": -2,
      "y": 9,
      "z": -12,
      "name": "Rock_Quartzite"
    },
    {
      "x": -2,
      "y": 10,
      "z": -12,
      "name": "Rock_Quartzite"
    },
    {
      "x": -2,
      "y": 0,
      "z": -11,
      "name": "Rock_Stone_Cobble"
    },
    {
      "x": -2,
      "y": 1,
      "z": -11,
      "name": "Rock_Stone_Brick_Pillar_Base"
    },
    {
      "x": -2,
      "y": 2,
      "z": -11,
      "name": "Rock_Stone_Brick_Pillar_Middle"
    },
    {
      "x": -2,
      "y": 3,
      "z": -11,
      "name": "Rock_Stone_Brick_Pillar_Middle"
    },
    {
      "x": -2,
      "y": 4,
      "z": -11,
      "name": "Rock_Stone_Brick_Pillar_Middle"
    },
    {
      "x": -2,
      "y": 5,
      "z": -11,
      "name": "Rock_Stone_Brick_Pillar_Base",
      "rotation": 8
    },
    {
      "x": -2,
      "y": 6,
      "z": -11,
      "name": "Rock_Quartzite_Brick_Smooth"
    },
    {
      "x": -2,
      "y": 7,
      "z": -11,
      "name": "Rock_Quartzite_Brick"
    },
    {
      "x": -2,
      "y": 8,
      "z": -11,
      "name": "Rock_Quartzite_Brick"
    },
    {
      "x": -2,
      "y": 9,
      "z": -11,
      "name": "Rock_Quartzite"
    },
    {
      "x": -2,
      "y": 10,
      "z": -11,
      "name": "Rock_Quartzite"
    },
    {
      "x": -2,
      "y": 0,
      "z": -10,
      "name": "Rock_Stone_Brick"
    },
    {
      "x": -2,
      "y": 1,
      "z": -10,
      "name": "Empty"
    },
    {
      "x": -2,
      "y": 2,
      "z": -10,
      "name": "Empty"
    },
    {
      "x": -2,
      "y": 3,
      "z": -10,
      "name": "Empty"
    },
    {
      "x": -2,
      "y": 4,
      "z": -10,
      "name": "Empty"
    },
    {
      "x": -2,
      "y": 5,
      "z": -10,
      "name": "Empty"
    },
    {
      "x": -2,
      "y": 6,
      "z": -10,
      "name": "Empty"
    },
    {
      "x": -2,
      "y": 7,
      "z": -10,
      "name": "Empty"
    },
    {
      "x": -2,
      "y": 8,
      "z": -10,
      "name": "Rock_Quartzite_Brick"
    },
    {
      "x": -2,
      "y": 9,
      "z": -10,
      "name": "Rock_Quartzite"
    },
    {
      "x": -2,
      "y": 10,
      "z": -10,
      "name": "Rock_Quartzite"
    },
    {
      "x": -2,
      "y": 0,
      "z": -9,
      "name": "Rock_Stone_Brick"
    },
    {
      "x": -2,
      "y": 1,
      "z": -9,
      "name": "Empty"
    },
    {
      "x": -2,
      "y": 2,
      "z": -9,
      "name": "Empty"
    },
    {
      "x": -2,
      "y": 3,
      "z": -9,
      "name": "Empty"
    },
    {
      "x": -2,
      "y": 4,
      "z": -9,
      "name": "Empty"
    },
    {
      "x": -2,
      "y": 5,
      "z": -9,
      "name": "Empty"
    },
    {
      "x": -2,
      "y": 6,
      "z": -9,
      "name": "Empty"
    },
    {
      "x": -2,
      "y": 7,
      "z": -9,
      "name": "Empty"
    },
    {
      "x": -2,
      "y": 8,
      "z": -9,
      "name": "Rock_Quartzite_Brick"
    },
    {
      "x": -2,
      "y": 9,
      "z": -9,
      "name": "Rock_Quartzite"
    },
    {
      "x": -2,
      "y": 10,
      "z": -9,
      "name": "Rock_Quartzite"
    },
    {
      "x": -2,
      "y": 0,
      "z": -8,
      "name": "Rock_Stone_Brick"
    },
    {
      "x": -2,
      "y": 1,
      "z": -8,
      "name": "Empty"
    },
    {
      "x": -2,
      "y": 2,
      "z": -8,
      "name": "Empty"
    },
    {
      "x": -2,
      "y": 3,
      "z": -8,
      "name": "Empty"
    },
    {
      "x": -2,
      "y": 4,
      "z": -8,
      "name": "Empty"
    },
    {
      "x": -2,
      "y": 5,
      "z": -8,
      "name": "Empty"
    },
    {
      "x": -2,
      "y": 6,
      "z": -8,
      "name": "Empty"
    },
    {
      "x": -2,
      "y": 7,
      "z": -8,
      "name": "Empty"
    },
    {
      "x": -2,
      "y": 8,
      "z": -8,
      "name": "Rock_Quartzite_Brick_Half",
      "rotation": 8
    },
    {
      "x": -2,
      "y": 9,
      "z": -8,
      "name": "Rock_Quartzite"
    },
    {
      "x": -2,
      "y": 10,
      "z": -8,
      "name": "Rock_Quartzite"
    },
    {
      "x": -2,
      "y": 0,
      "z": -7,
      "name": "Rock_Stone_Brick"
    },
    {
      "x": -2,
      "y": 1,
      "z": -7,
      "name": "Empty"
    },
    {
      "x": -2,
      "y": 2,
      "z": -7,
      "name": "Empty"
    },
    {
      "x": -2,
      "y": 3,
      "z": -7,
      "name": "Empty"
    },
    {
      "x": -2,
      "y": 4,
      "z": -7,
      "name": "Empty"
    },
    {
      "x": -2,
      "y": 5,
      "z": -7,
      "name": "Empty"
    },
    {
      "x": -2,
      "y": 6,
      "z": -7,
      "name": "Empty"
    },
    {
      "x": -2,
      "y": 7,
      "z": -7,
      "name": "Empty"
    },
    {
      "x": -2,
      "y": 8,
      "z": -7,
      "name": "Empty"
    },
    {
      "x": -2,
      "y": 9,
      "z": -7,
      "name": "Rock_Quartzite"
    },
    {
      "x": -2,
      "y": 10,
      "z": -7,
      "name": "Rock_Quartzite"
    },
    {
      "x": -2,
      "y": 0,
      "z": -6,
      "name": "Rock_Stone_Cobble"
    },
    {
      "x": -2,
      "y": 1,
      "z": -6,
      "name": "Empty"
    },
    {
      "x": -2,
      "y": 2,
      "z": -6,
      "name": "Empty"
    },
    {
      "x": -2,
      "y": 3,
      "z": -6,
      "name": "Empty"
    },
    {
      "x": -2,
      "y": 4,
      "z": -6,
      "name": "Empty"
    },
    {
      "x": -2,
      "y": 5,
      "z": -6,
      "name": "Empty"
    },
    {
      "x": -2,
      "y": 6,
      "z": -6,
      "name": "Empty"
    },
    {
      "x": -2,
      "y": 7,
      "z": -6,
      "name": "Empty"
    },
    {
      "x": -2,
      "y": 8,
      "z": -6,
      "name": "Empty"
    },
    {
      "x": -2,
      "y": 9,
      "z": -6,
      "name": "Rock_Quartzite"
    },
    {
      "x": -2,
      "y": 10,
      "z": -6,
      "name": "Rock_Quartzite"
    },
    {
      "x": -2,
      "y": 0,
      "z": -5,
      "name": "Rock_Stone_Cobble"
    },
    {
      "x": -2,
      "y": 1,
      "z": -5,
      "name": "Empty"
    },
    {
      "x": -2,
      "y": 2,
      "z": -5,
      "name": "Empty"
    },
    {
      "x": -2,
      "y": 3,
      "z": -5,
      "name": "Empty"
    },
    {
      "x": -2,
      "y": 4,
      "z": -5,
      "name": "Empty"
    },
    {
      "x": -2,
      "y": 5,
      "z": -5,
      "name": "Empty"
    },
    {
      "x": -2,
      "y": 6,
      "z": -5,
      "name": "Empty"
    },
    {
      "x": -2,
      "y": 7,
      "z": -5,
      "name": "Empty"
    },
    {
      "x": -2,
      "y": 8,
      "z": -5,
      "name": "Rock_Quartzite_Brick"
    },
    {
      "x": -2,
      "y": 9,
      "z": -5,
      "name": "Rock_Quartzite"
    },
    {
      "x": -2,
      "y": 10,
      "z": -5,
      "name": "Rock_Quartzite"
    },
    {
      "x": -2,
      "y": 0,
      "z": -4,
      "name": "Rock_Stone_Brick"
    },
    {
      "x": -2,
      "y": 1,
      "z": -4,
      "name": "Empty"
    },
    {
      "x": -2,
      "y": 2,
      "z": -4,
      "name": "Empty"
    },
    {
      "x": -2,
      "y": 3,
      "z": -4,
      "name": "Empty"
    },
    {
      "x": -2,
      "y": 4,
      "z": -4,
      "name": "Empty"
    },
    {
      "x": -2,
      "y": 5,
      "z": -4,
      "name": "Empty"
    },
    {
      "x": -2,
      "y": 6,
      "z": -4,
      "name": "Empty"
    },
    {
      "x": -2,
      "y": 7,
      "z": -4,
      "name": "Empty"
    },
    {
      "x": -2,
      "y": 8,
      "z": -4,
      "name": "Rock_Quartzite_Brick"
    },
    {
      "x": -2,
      "y": 9,
      "z": -4,
      "name": "Rock_Quartzite"
    },
    {
      "x": -2,
      "y": 10,
      "z": -4,
      "name": "Rock_Quartzite"
    },
    {
      "x": -2,
      "y": 0,
      "z": -3,
      "name": "Rock_Stone_Cobble"
    },
    {
      "x": -2,
      "y": 1,
      "z": -3,
      "name": "Rock_Stone_Brick_Pillar_Base"
    },
    {
      "x": -2,
      "y": 2,
      "z": -3,
      "name": "Rock_Stone_Brick_Pillar_Middle"
    },
    {
      "x": -2,
      "y": 3,
      "z": -3,
      "name": "Rock_Stone_Brick_Pillar_Middle"
    },
    {
      "x": -2,
      "y": 4,
      "z": -3,
      "name": "Rock_Stone_Brick_Pillar_Middle"
    },
    {
      "x": -2,
      "y": 5,
      "z": -3,
      "name": "Rock_Stone_Brick_Pillar_Base",
      "rotation": 8
    },
    {
      "x": -2,
      "y": 6,
      "z": -3,
      "name": "Rock_Quartzite_Brick_Smooth"
    },
    {
      "x": -2,
      "y": 7,
      "z": -3,
      "name": "Rock_Quartzite_Brick"
    },
    {
      "x": -2,
      "y": 8,
      "z": -3,
      "name": "Rock_Quartzite_Brick"
    },
    {
      "x": -2,
      "y": 9,
      "z": -3,
      "name": "Rock_Quartzite"
    },
    {
      "x": -2,
      "y": 10,
      "z": -3,
      "name": "Rock_Quartzite"
    },
    {
      "x": -2,
      "y": 0,
      "z": -2,
      "name": "Rock_Stone_Cobble"
    },
    {
      "x": -2,
      "y": 1,
      "z": -2,
      "name": "Rock_Quartzite_Brick"
    },
    {
      "x": -2,
      "y": 2,
      "z": -2,
      "name": "Rock_Quartzite_Brick"
    },
    {
      "x": -2,
      "y": 3,
      "z": -2,
      "name": "Rock_Quartzite_Brick"
    },
    {
      "x": -2,
      "y": 4,
      "z": -2,
      "name": "Rock_Quartzite_Brick"
    },
    {
      "x": -2,
      "y": 5,
      "z": -2,
      "name": "Rock_Quartzite_Brick"
    },
    {
      "x": -2,
      "y": 6,
      "z": -2,
      "name": "Rock_Quartzite_Brick_Smooth"
    },
    {
      "x": -2,
      "y": 7,
      "z": -2,
      "name": "Rock_Quartzite_Brick"
    },
    {
      "x": -2,
      "y": 8,
      "z": -2,
      "name": "Rock_Quartzite_Brick"
    },
    {
      "x": -2,
      "y": 9,
      "z": -2,
      "name": "Rock_Quartzite"
    },
    {
      "x": -2,
      "y": 10,
      "z": -2,
      "name": "Rock_Quartzite"
    },
    {
      "x": -2,
      "y": 0,
      "z": -1,
      "name": "Rock_Stone_Cobble"
    },
    {
      "x": -2,
      "y": 1,
      "z": -1,
      "name": "Rock_Quartzite_Brick"
    },
    {
      "x": -2,
      "y": 2,
      "z": -1,
      "name": "Rock_Quartzite_Brick"
    },
    {
      "x": -2,
      "y": 3,
      "z": -1,
      "name": "Rock_Quartzite_Brick"
    },
    {
      "x": -2,
      "y": 4,
      "z": -1,
      "name": "Rock_Quartzite_Brick"
    },
    {
      "x": -2,
      "y": 5,
      "z": -1,
      "name": "Rock_Quartzite_Brick"
    },
    {
      "x": -2,
      "y": 6,
      "z": -1,
      "name": "Rock_Quartzite_Brick_Smooth"
    },
    {
      "x": -2,
      "y": 7,
      "z": -1,
      "name": "Rock_Quartzite_Brick"
    },
    {
      "x": -2,
      "y": 8,
      "z": -1,
      "name": "Rock_Quartzite_Brick"
    },
    {
      "x": -2,
      "y": 9,
      "z": -1,
      "name": "Rock_Quartzite"
    },
    {
      "x": -2,
      "y": 10,
      "z": -1,
      "name": "Rock_Quartzite"
    },
    {
      "x": -2,
      "y": 0,
      "z": 0,
      "name": "Rock_Stone_Cobble"
    },
    {
      "x": -2,
      "y": 1,
      "z": 0,
      "name": "Rock_Quartzite_Brick"
    },
    {
      "x": -2,
      "y": 2,
      "z": 0,
      "name": "Rock_Quartzite_Brick"
    },
    {
      "x": -2,
      "y": 3,
      "z": 0,
      "name": "Rock_Quartzite_Brick"
    },
    {
      "x": -2,
      "y": 4,
      "z": 0,
      "name": "Rock_Quartzite_Brick"
    },
    {
      "x": -2,
      "y": 5,
      "z": 0,
      "name": "Rock_Quartzite_Brick_Smooth"
    },
    {
      "x": -2,
      "y": 6,
      "z": 0,
      "name": "Rock_Quartzite_Brick"
    },
    {
      "x": -2,
      "y": 7,
      "z": 0,
      "name": "Rock_Quartzite_Brick"
    },
    {
      "x": -2,
      "y": 8,
      "z": 0,
      "name": "Rock_Quartzite_Brick"
    },
    {
      "x": -2,
      "y": 9,
      "z": 0,
      "name": "Rock_Quartzite_Brick"
    },
    {
      "x": -2,
      "y": 10,
      "z": 0,
      "name": "Rock_Quartzite_Brick"
    },
    {
      "x": -1,
      "y": 0,
      "z": -12,
      "name": "Rock_Stone_Cobble"
    },
    {
      "x": -1,
      "y": 1,
      "z": -12,
      "name": "Rock_Quartzite_Brick"
    },
    {
      "x": -1,
      "y": 2,
      "z": -12,
      "name": "Rock_Quartzite_Brick"
    },
    {
      "x": -1,
      "y": 3,
      "z": -12,
      "name": "Rock_Quartzite_Brick"
    },
    {
      "x": -1,
      "y": 4,
      "z": -12,
      "name": "Rock_Quartzite"
    },
    {
      "x": -1,
      "y": 5,
      "z": -12,
      "name": "Rock_Quartzite"
    },
    {
      "x": -1,
      "y": 6,
      "z": -12,
      "name": "Rock_Quartzite"
    },
    {
      "x": -1,
      "y": 7,
      "z": -12,
      "name": "Rock_Quartzite"
    },
    {
      "x": -1,
      "y": 8,
      "z": -12,
      "name": "Rock_Quartzite"
    },
    {
      "x": -1,
      "y": 9,
      "z": -12,
      "name": "Rock_Quartzite"
    },
    {
      "x": -1,
      "y": 10,
      "z": -12,
      "name": "Rock_Quartzite"
    },
    {
      "x": -1,
      "y": 0,
      "z": -11,
      "name": "Rock_Stone_Brick"
    },
    {
      "x": -1,
      "y": 1,
      "z": -11,
      "name": "Rubble_Quartzite"
    },
    {
      "x": -1,
      "y": 2,
      "z": -11,
      "name": "Deco_Wallchain"
    },
    {
      "x": -1,
      "y": 3,
      "z": -11,
      "name": "Empty"
    },
    {
      "x": -1,
      "y": 4,
      "z": -11,
      "name": "Empty"
    },
    {
      "x": -1,
      "y": 5,
      "z": -11,
      "name": "Empty"
    },
    {
      "x": -1,
      "y": 6,
      "z": -11,
      "name": "Rock_Quartzite_Brick_Smooth"
    },
    {
      "x": -1,
      "y": 7,
      "z": -11,
      "name": "Rock_Quartzite_Brick"
    },
    {
      "x": -1,
      "y": 8,
      "z": -11,
      "name": "Rock_Quartzite_Brick"
    },
    {
      "x": -1,
      "y": 9,
      "z": -11,
      "name": "Rock_Quartzite"
    },
    {
      "x": -1,
      "y": 10,
      "z": -11,
      "name": "Rock_Quartzite"
    },
    {
      "x": -1,
      "y": 0,
      "z": -10,
      "name": "Rock_Stone_Brick"
    },
    {
      "x": -1,
      "y": 1,
      "z": -10,
      "name": "Empty"
    },
    {
      "x": -1,
      "y": 2,
      "z": -10,
      "name": "Empty"
    },
    {
      "x": -1,
      "y": 3,
      "z": -10,
      "name": "Empty"
    },
    {
      "x": -1,
      "y": 4,
      "z": -10,
      "name": "Empty"
    },
    {
      "x": -1,
      "y": 5,
      "z": -10,
      "name": "Empty"
    },
    {
      "x": -1,
      "y": 6,
      "z": -10,
      "name": "Empty"
    },
    {
      "x": -1,
      "y": 7,
      "z": -10,
      "name": "Rock_Quartzite_Brick_Half",
      "rotation": 8
    },
    {
      "x": -1,
      "y": 8,
      "z": -10,
      "name": "Rock_Quartzite_Brick"
    },
    {
      "x": -1,
      "y": 9,
      "z": -10,
      "name": "Rock_Quartzite"
    },
    {
      "x": -1,
      "y": 10,
      "z": -10,
      "name": "Rock_Quartzite"
    },
    {
      "x": -1,
      "y": 0,
      "z": -9,
      "name": "Rock_Stone_Brick"
    },
    {
      "x": -1,
      "y": 1,
      "z": -9,
      "name": "Empty"
    },
    {
      "x": -1,
      "y": 2,
      "z": -9,
      "name": "Empty"
    },
    {
      "x": -1,
      "y": 3,
      "z": -9,
      "name": "Empty"
    },
    {
      "x": -1,
      "y": 4,
      "z": -9,
      "name": "Empty"
    },
    {
      "x": -1,
      "y": 5,
      "z": -9,
      "name": "Empty"
    },
    {
      "x": -1,
      "y": 6,
      "z": -9,
      "name": "Empty"
    },
    {
      "x": -1,
      "y": 7,
      "z": -9,
      "name": "Empty"
    },
    {
      "x": -1,
      "y": 8,
      "z": -9,
      "name": "Rock_Quartzite_Brick"
    },
    {
      "x": -1,
      "y": 9,
      "z": -9,
      "name": "Rock_Quartzite"
    },
    {
      "x": -1,
      "y": 10,
      "z": -9,
      "name": "Rock_Quartzite"
    },
    {
      "x": -1,
      "y": 0,
      "z": -8,
      "name": "Rock_Stone_Cobble"
    },
    {
      "x": -1,
      "y": 1,
      "z": -8,
      "name": "Empty"
    },
    {
      "x": -1,
      "y": 2,
      "z": -8,
      "name": "Empty"
    },
    {
      "x": -1,
      "y": 3,
      "z": -8,
      "name": "Empty"
    },
    {
      "x": -1,
      "y": 4,
      "z": -8,
      "name": "Empty"
    },
    {
      "x": -1,
      "y": 5,
      "z": -8,
      "name": "Empty"
    },
    {
      "x": -1,
      "y": 6,
      "z": -8,
      "name": "Empty"
    },
    {
      "x": -1,
      "y": 7,
      "z": -8,
      "name": "Empty"
    },
    {
      "x": -1,
      "y": 8,
      "z": -8,
      "name": "Rock_Quartzite_Brick_Half",
      "rotation": 8
    },
    {
      "x": -1,
      "y": 9,
      "z": -8,
      "name": "Rock_Quartzite"
    },
    {
      "x": -1,
      "y": 10,
      "z": -8,
      "name": "Rock_Quartzite"
    },
    {
      "x": -1,
      "y": 0,
      "z": -7,
      "name": "Rock_Stone_Cobble"
    },
    {
      "x": -1,
      "y": 1,
      "z": -7,
      "name": "Empty"
    },
    {
      "x": -1,
      "y": 2,
      "z": -7,
      "name": "Empty"
    },
    {
      "x": -1,
      "y": 3,
      "z": -7,
      "name": "Empty"
    },
    {
      "x": -1,
      "y": 4,
      "z": -7,
      "name": "Empty"
    },
    {
      "x": -1,
      "y": 5,
      "z": -7,
      "name": "Empty"
    },
    {
      "x": -1,
      "y": 6,
      "z": -7,
      "name": "Empty"
    },
    {
      "x": -1,
      "y": 7,
      "z": -7,
      "name": "Empty"
    },
    {
      "x": -1,
      "y": 8,
      "z": -7,
      "name": "Empty"
    },
    {
      "x": -1,
      "y": 9,
      "z": -7,
      "name": "Rock_Quartzite"
    },
    {
      "x": -1,
      "y": 10,
      "z": -7,
      "name": "Rock_Quartzite"
    },
    {
      "x": -1,
      "y": 0,
      "z": -6,
      "name": "Rock_Stone_Cobble"
    },
    {
      "x": -1,
      "y": 1,
      "z": -6,
      "name": "Empty"
    },
    {
      "x": -1,
      "y": 2,
      "z": -6,
      "name": "Empty"
    },
    {
      "x": -1,
      "y": 3,
      "z": -6,
      "name": "Empty"
    },
    {
      "x": -1,
      "y": 4,
      "z": -6,
      "name": "Empty"
    },
    {
      "x": -1,
      "y": 5,
      "z": -6,
      "name": "Empty"
    },
    {
      "x": -1,
      "y": 6,
      "z": -6,
      "name": "Empty"
    },
    {
      "x": -1,
      "y": 7,
      "z": -6,
      "name": "Empty"
    },
    {
      "x": -1,
      "y": 8,
      "z": -6,
      "name": "Empty"
    },
    {
      "x": -1,
      "y": 9,
      "z": -6,
      "name": "Rock_Quartzite"
    },
    {
      "x": -1,
      "y": 10,
      "z": -6,
      "name": "Rock_Quartzite"
    },
    {
      "x": -1,
      "y": 0,
      "z": -5,
      "name": "Rock_Stone_Cobble"
    },
    {
      "x": -1,
      "y": 1,
      "z": -5,
      "name": "Empty"
    },
    {
      "x": -1,
      "y": 2,
      "z": -5,
      "name": "Empty"
    },
    {
      "x": -1,
      "y": 3,
      "z": -5,
      "name": "Empty"
    },
    {
      "x": -1,
      "y": 4,
      "z": -5,
      "name": "Empty"
    },
    {
      "x": -1,
      "y": 5,
      "z": -5,
      "name": "Empty"
    },
    {
      "x": -1,
      "y": 6,
      "z": -5,
      "name": "Empty"
    },
    {
      "x": -1,
      "y": 7,
      "z": -5,
      "name": "Empty"
    },
    {
      "x": -1,
      "y": 8,
      "z": -5,
      "name": "Rock_Quartzite_Brick"
    },
    {
      "x": -1,
      "y": 9,
      "z": -5,
      "name": "Rock_Quartzite"
    },
    {
      "x": -1,
      "y": 10,
      "z": -5,
      "name": "Rock_Quartzite"
    },
    {
      "x": -1,
      "y": 0,
      "z": -4,
      "name": "Rock_Stone_Cobble"
    },
    {
      "x": -1,
      "y": 1,
      "z": -4,
      "name": "Empty"
    },
    {
      "x": -1,
      "y": 2,
      "z": -4,
      "name": "Empty"
    },
    {
      "x": -1,
      "y": 3,
      "z": -4,
      "name": "Empty"
    },
    {
      "x": -1,
      "y": 4,
      "z": -4,
      "name": "Empty"
    },
    {
      "x": -1,
      "y": 5,
      "z": -4,
      "name": "Empty"
    },
    {
      "x": -1,
      "y": 6,
      "z": -4,
      "name": "Empty"
    },
    {
      "x": -1,
      "y": 7,
      "z": -4,
      "name": "Empty"
    },
    {
      "x": -1,
      "y": 8,
      "z": -4,
      "name": "Rock_Quartzite_Brick"
    },
    {
      "x": -1,
      "y": 9,
      "z": -4,
      "name": "Rock_Quartzite"
    },
    {
      "x": -1,
      "y": 10,
      "z": -4,
      "name": "Rock_Quartzite"
    },
    {
      "x": -1,
      "y": 0,
      "z": -3,
      "name": "Rock_Stone_Brick"
    },
    {
      "x": -1,
      "y": 1,
      "z": -3,
      "name": "Empty"
    },
    {
      "x": -1,
      "y": 2,
      "z": -3,
      "name": "Empty"
    },
    {
      "x": -1,
      "y": 3,
      "z": -3,
      "name": "Empty"
    },
    {
      "x": -1,
      "y": 4,
      "z": -3,
      "name": "Empty"
    },
    {
      "x": -1,
      "y": 5,
      "z": -3,
      "name": "Empty"
    },
    {
      "x": -1,
      "y": 6,
      "z": -3,
      "name": "Rock_Quartzite_Brick_Smooth"
    },
    {
      "x": -1,
      "y": 7,
      "z": -3,
      "name": "Rock_Quartzite_Brick"
    },
    {
      "x": -1,
      "y": 8,
      "z": -3,
      "name": "Rock_Quartzite_Brick"
    },
    {
      "x": -1,
      "y": 9,
      "z": -3,
      "name": "Rock_Quartzite"
    },
    {
      "x": -1,
      "y": 10,
      "z": -3,
      "name": "Rock_Quartzite"
    },
    {
      "x": -1,
      "y": 0,
      "z": -2,
      "name": "Rock_Stone_Brick"
    },
    {
      "x": -1,
      "y": 1,
      "z": -2,
      "name": "Rock_Quartzite_Brick"
    },
    {
      "x": -1,
      "y": 2,
      "z": -2,
      "name": "Rock_Quartzite_Brick"
    },
    {
      "x": -1,
      "y": 3,
      "z": -2,
      "name": "Rock_Quartzite_Brick"
    },
    {
      "x": -1,
      "y": 4,
      "z": -2,
      "name": "Rock_Quartzite_Brick"
    },
    {
