{
  "version": 8,
  "blockIdVersion": 8,
  "anchorX": 0,
  "anchorY": 3,
  "anchorZ": 0,
  "blocks": [
    {
      "x": -3,
      "y": 9,
      "z": -1,
      "name": "Plant_Coral_Block_White"
    },
    {
      "x": -3,
      "y": 10,
      "z": -1,
      "name": "Plant_Coral_Block_White"
    },
    {
      "x": -3,
      "y": 11,
      "z": -1,
      "name": "Plant_Coral_Block_White"
    },
    {
      "x": -3,
      "y": 12,
      "z": -1,
      "name": "Plant_Coral_Block_White"
    },
    {
      "x": -2,
      "y": 6,
      "z": -1,
      "name": "Plant_Coral_Block_White"
    },
    {
      "x": -2,
      "y": 7,
      "z": -1,
      "name": "Plant_Coral_Block_White"
    },
    {
      "x": -2,
      "y": 8,
      "z": -1,
      "name": "Plant_Coral_Block_White"
    },
    {
      "x": -2,
      "y": 9,
      "z": -1,
      "name": "Plant_Coral_Block_White"
    },
    {
      "x": -2,
      "y": 9,
      "z": 2,
      "name": "Plant_Coral_Block_White"
    },
    {
      "x": -2,
      "y": 10,
      "z": 2,
      "name": "Plant_Coral_Block_White"
    },
    {
      "x": -2,
      "y": 11,
      "z": 2,
      "name": "Plant_Coral_Block_White"
    },
    {
      "x": -1,
      "y": 4,
      "z": -2,
      "name": "Plant_Coral_Block_White"
    },
    {
      "x": -1,
      "y": 5,
      "z": -2,
      "name": "Plant_Coral_Block_White"
    },
    {
      "x": -1,
      "y": 6,
      "z": -2,
      "name": "Plant_Coral_Block_White"
    },
    {
      "x": -1,
      "y": 3,
      "z": -1,
      "name": "Plant_Coral_Block_White"
    },
    {
      "x": -1,
      "y": 4,
      "z": -1,
      "name": "Plant_Coral_Block_White"
    },
    {
      "x": -1,
      "y": 5,
      "z": -1,
      "name": "Plant_Coral_Block_White"
    },
    {
      "x": -1,
      "y": 6,
      "z": -1,
      "name": "Plant_Coral_Block_White"
    },
    {
      "x": -1,
      "y": 1,
      "z": 0,
      "name": "Plant_Coral_Block_White"
    },
    {
      "x": -1,
      "y": 2,
      "z": 0,
      "name": "Plant_Coral_Block_White"
    },
    {
      "x": -1,
      "y": 3,
      "z": 0,
      "name": "Plant_Coral_Block_White"
    },
    {
      "x": -1,
      "y": 4,
      "z": 0,
      "name": "Plant_Coral_Block_White"
    },
    {
      "x": -1,
      "y": 5,
      "z": 0,
      "name": "Plant_Coral_Block_White"
    },
    {
      "x": -1,
      "y": 6,
      "z": 0,
      "name": "Plant_Coral_Block_White"
    },
    {
      "x": -1,
      "y": 6,
      "z": 1,
      "name": "Plant_Coral_Block_White"
    },
    {
      "x": -1,
      "y": 7,
      "z": 1,
      "name": "Plant_Coral_Block_White"
    },
    {
      "x": -1,
      "y": 8,
      "z": 1,
      "name": "Plant_Coral_Block_White"
    },
    {
      "x": -1,
      "y": 9,
      "z": 1,
      "name": "Plant_Coral_Block_White"
    },
    {
      "x": 0,
      "y": 8,
      "z": -4,
      "name": "Plant_Coral_Block_White"
    },
    {
      "x": 0,
      "y": 9,
      "z": -4,
      "name": "Plant_Coral_Block_White"
    },
    {
      "x": 0,
      "y": 10,
      "z": -4,
      "name": "Plant_Coral_Block_White"
    },
    {
      "x": 0,
      "y": 6,
      "z": -3,
      "name": "Plant_Coral_Block_White"
    },
    {
      "x": 0,
      "y": 7,
      "z": -3,
      "name": "Plant_Coral_Block_White"
    },
    {
      "x": 0,
      "y": 8,
      "z": -3,
      "name": "Plant_Coral_Block_White"
    },
    {
      "x": 0,
      "y": 1,
      "z": -1,
      "name": "Plant_Coral_Block_White"
    },
    {
      "x": 0,
      "y": 2,
      "z": -1,
      "name": "Plant_Coral_Block_White"
    },
    {
      "x": 0,
      "y": 3,
      "z": -1,
      "name": "Plant_Coral_Block_White"
    },
    {
      "x": 0,
      "y": 4,
      "z": -1,
      "name": "Plant_Coral_Block_White"
    },
    {
      "x": 0,
      "y": 5,
      "z": -1,
      "name": "Plant_Coral_Block_White"
    },
    {
      "x": 0,
      "y": 6,
      "z": -1,
      "name": "Plant_Coral_Block_White"
    },
    {
      "x": 0,
      "y": 7,
      "z": -1,
      "name": "Plant_Coral_Block_White"
    },
    {
      "x": 0,
      "y": 1,
      "z": 0,
      "name": "Plant_Coral_Block_White"
    },
    {
      "x": 0,
      "y": 2,
      "z": 0,
      "name": "Plant_Coral_Block_White"
    },
    {
      "x": 0,
      "y": 3,
      "z": 0,
      "name": "Plant_Coral_Block_White"
    },
    {
      "x": 0,
      "y": 4,
      "z": 0,
      "name": "Plant_Coral_Block_White"
    },
    {
      "x": 0,
      "y": 5,
      "z": 0,
      "name": "Plant_Coral_Block_White"
    },
    {
      "x": 0,
      "y": 1,
      "z": 1,
      "name": "Plant_Coral_Block_White"
    },
    {
      "x": 0,
      "y": 2,
      "z": 1,
      "name": "Plant_Coral_Block_White"
    },
    {
      "x": 0,
      "y": 3,
      "z": 1,
      "name": "Plant_Coral_Block_White"
    },
    {
      "x": 0,
      "y": 4,
      "z": 1,
      "name": "Plant_Coral_Block_White"
    },
    {
      "x": 0,
      "y": 3,
      "z": 2,
      "name": "Plant_Coral_Block_White"
    },
    {
      "x": 0,
      "y": 4,
      "z": 2,
      "name": "Plant_Coral_Block_White"
    },
    {
      "x": 0,
      "y": 5,
      "z": 2,
      "name": "Plant_Coral_Block_White"
    },
    {
      "x": 0,
      "y": 6,
      "z": 2,
      "name": "Plant_Coral_Block_White"
    },
    {
      "x": 0,
      "y": 6,
      "z": 3,
      "name": "Plant_Coral_Block_White"
    },
    {
      "x": 0,
      "y": 7,
      "z": 3,
      "name": "Plant_Coral_Block_White"
    },
    {
      "x": 0,
      "y": 8,
      "z": 3,
      "name": "Plant_Coral_Block_White"
    },
    {
      "x": 0,
      "y": 8,
      "z": 4,
      "name": "Plant_Coral_Block_White"
    },
    {
      "x": 0,
      "y": 9,
      "z": 4,
      "name": "Plant_Coral_Block_White"
    },
    {
      "x": 0,
      "y": 10,
      "z": 4,
      "name": "Plant_Coral_Block_White"
    },
    {
      "x": 1,
      "y": 1,
      "z": -1,
      "name": "Plant_Coral_Block_White"
    },
    {
      "x": 1,
      "y": 2,
      "z": -1,
      "name": "Plant_Coral_Block_White"
    },
    {
      "x": 1,
      "y": 3,
      "z": -1,
      "name": "Plant_Coral_Block_White"
    },
    {
      "x": 1,
      "y": 7,
      "z": -1,
      "name": "Plant_Coral_Block_White"
    },
    {
      "x": 1,
      "y": 8,
      "z": -1,
      "name": "Plant_Coral_Block_White"
    },
    {
      "x": 1,
      "y": 9,
      "z": -1,
      "name": "Plant_Coral_Block_White"
    },
    {
      "x": 1,
      "y": 10,
      "z": -1,
      "name": "Plant_Coral_Block_White"
    },
    {
      "x": 1,
      "y": 11,
      "z": -1,
      "name": "Plant_Coral_Block_White"
    },
    {
      "x": 1,
      "y": 1,
      "z": 0,
      "name": "Plant_Coral_Block_White"
    },
    {
      "x": 1,
      "y": 2,
      "z": 0,
      "name": "Plant_Coral_Block_White"
    },
    {
      "x": 1,
      "y": 3,
      "z": 0,
      "name": "Plant_Coral_Block_White"
    },
    {
      "x": 1,
      "y": 4,
      "z": 0,
      "name": "Plant_Coral_Block_White"
    },
    {
      "x": 1,
      "y": 5,
      "z": 0,
      "name": "Plant_Coral_Block_White"
    },
    {
      "x": 1,
      "y": 1,
      "z": 1,
      "name": "Plant_Coral_Block_White"
    },
    {
      "x": 1,
      "y": 2,
      "z": 1,
      "name": "Plant_Coral_Block_White"
    },
    {
      "x": 1,
      "y": 3,
      "z": 1,
      "name": "Plant_Coral_Block_White"
    },
    {
      "x": 1,
      "y": 4,
      "z": 1,
      "name": "Plant_Coral_Block_White"
    },
    {
      "x": 1,
      "y": 5,
      "z": 1,
      "name": "Plant_Coral_Block_White"
    },
    {
      "x": 1,
      "y": 6,
      "z": 1,
      "name": "Plant_Coral_Block_White"
    },
    {
      "x": 1,
      "y": 7,
      "z": 1,
      "name": "Plant_Coral_Block_White"
    },
    {
      "x": 1,
      "y": 8,
      "z": 1,
      "name": "Plant_Coral_Block_White"
    },
    {
      "x": 1,
      "y": 9,
      "z": 1,
      "name": "Plant_Coral_Block_White"
    },
    {
      "x": 1,
      "y": 3,
      "z": 2,
      "name": "Plant_Coral_Block_White"
    },
    {
      "x": 1,
      "y": 4,
      "z": 2,
      "name": "Plant_Coral_Block_White"
    },
    {
      "x": 2,
      "y": 6,
      "z": -4,
      "name": "Plant_Coral_Block_White"
    },
    {
      "x": 2,
      "y": 7,
      "z": -4,
      "name": "Plant_Coral_Block_White"
    },
    {
      "x": 2,
      "y": 8,
      "z": -4,
      "name": "Plant_Coral_Block_White"
    },
    {
      "x": 2,
      "y": 4,
      "z": -3,
      "name": "Plant_Coral_Block_White"
    },
    {
      "x": 2,
      "y": 5,
      "z": -3,
      "name": "Plant_Coral_Block_White"
    },
    {
      "x": 2,
      "y": 6,
      "z": -3,
      "name": "Plant_Coral_Block_White"
    },
    {
      "x": 2,
      "y": 3,
      "z": -2,
      "name": "Plant_Coral_Block_White"
    },
    {
      "x": 2,
      "y": 4,
      "z": -2,
      "name": "Plant_Coral_Block_White"
    },
    {
      "x": 2,
      "y": 1,
      "z": -1,
      "name": "Plant_Coral_Block_White"
    },
    {
      "x": 2,
      "y": 2,
      "z": -1,
      "name": "Plant_Coral_Block_White"
    },
    {
      "x": 2,
      "y": 3,
      "z": -1,
      "name": "Plant_Coral_Block_White"
    },
    {
      "x": 2,
      "y": 4,
      "z": -1,
      "name": "Plant_Coral_Block_White"
    },
    {
      "x": 2,
      "y": 5,
      "z": -1,
      "name": "Plant_Coral_Block_White"
    },
    {
      "x": 2,
      "y": 1,
      "z": 0,
      "name": "Plant_Coral_Block_White"
    },
    {
      "x": 2,
      "y": 2,
      "z": 0,
      "name": "Plant_Coral_Block_White"
    },
    {
      "x": 2,
      "y": 3,
      "z": 0,
      "name": "Plant_Coral_Block_White"
    },
    {
      "x": 2,
      "y": 4,
      "z": 0,
      "name": "Plant_Coral_Block_White"
    },
    {
      "x": 2,
      "y": 5,
      "z": 0,
      "name": "Plant_Coral_Block_White"
    },
    {
      "x": 2,
      "y": 3,
      "z": 1,
      "name": "Plant_Coral_Block_White"
    },
    {
      "x": 2,
      "y": 4,
      "z": 1,
      "name": "Plant_Coral_Block_White"
    },
    {
      "x": 2,
      "y": 4,
      "z": 2,
      "name": "Plant_Coral_Block_White"
    },
    {
      "x": 2,
      "y": 5,
      "z": 2,
      "name": "Plant_Coral_Block_White"
    },
    {
      "x": 2,
      "y": 9,
      "z": 2,
      "name": "Plant_Coral_Block_White"
    },
    {
      "x": 2,
      "y": 10,
      "z": 2,
      "name": "Plant_Coral_Block_White"
    },
    {
      "x": 2,
      "y": 11,
      "z": 2,
      "name": "Plant_Coral_Block_White"
    },
    {
      "x": 2,
      "y": 12,
      "z": 2,
      "name": "Plant_Coral_Block_White"
    },
    {
      "x": 2,
      "y": 5,
      "z": 3,
      "name": "Plant_Coral_Block_White"
    },
    {
      "x": 2,
      "y": 6,
      "z": 3,
      "name": "Plant_Coral_Block_White"
    },
    {
      "x": 2,
      "y": 7,
      "z": 3,
      "name": "Plant_Coral_Block_White"
    },
    {
      "x": 2,
      "y": 7,
      "z": 4,
      "name": "Plant_Coral_Block_White"
    },
    {
      "x": 2,
      "y": 8,
      "z": 4,
      "name": "Plant_Coral_Block_White"
    },
    {
      "x": 2,
      "y": 9,
      "z": 4,
      "name": "Plant_Coral_Block_White"
    },
    {
      "x": 3,
      "y": 5,
      "z": -2,
      "name": "Plant_Coral_Block_White"
    },
    {
      "x": 3,
      "y": 6,
      "z": -2,
      "name": "Plant_Coral_Block_White"
    },
    {
      "x": 3,
      "y": 7,
      "z": -2,
      "name": "Plant_Coral_Block_White"
    },
    {
      "x": 3,
      "y": 5,
      "z": 0,
      "name": "Plant_Coral_Block_White"
    },
    {
      "x": 3,
      "y": 6,
      "z": 0,
      "name": "Plant_Coral_Block_White"
    },
    {
      "x": 3,
      "y": 7,
      "z": 0,
      "name": "Plant_Coral_Block_White"
    },
    {
      "x": 3,
      "y": 8,
      "z": 0,
      "name": "Plant_Coral_Block_White"
    },
    {
      "x": 4,
      "y": 7,
      "z": -2,
      "name": "Plant_Coral_Block_White"
    },
    {
      "x": 4,
      "y": 8,
      "z": -2,
      "name": "Plant_Coral_Block_White"
    },
    {
      "x": 4,
      "y": 9,
      "z": -2,
      "name": "Plant_Coral_Block_White"
    },
    {
      "x": 4,
      "y": 8,
      "z": 0,
      "name": "Plant_Coral_Block_White"
    },
    {
      "x": 4,
      "y": 9,
      "z": 0,
      "name": "Plant_Coral_Block_White"
    },
    {
      "x": 4,
      "y": 10,
      "z": 0,
      "name": "Plant_Coral_Block_White"
    }
  ]
}