{
  "version": 8,
  "blockIdVersion": 8,
  "anchorX": 0,
  "anchorY": 10,
  "anchorZ": -1,
  "blocks": [
    {
      "x": -9,
      "y": 24,
      "z": -1,
      "name": "Plant_Leaves_Dead"
    },
    {
      "x": -9,
      "y": 25,
      "z": -1,
      "name": "Plant_Leaves_Dead"
    },
    {
      "x": -8,
      "y": 25,
      "z": -1,
      "name": "Plant_Leaves_Dead"
    },
    {
      "x": -8,
      "y": 31,
      "z": -1,
      "name": "Plant_Leaves_Dead"
    },
    {
      "x": -7,
      "y": 28,
      "z": -7,
      "name": "Plant_Leaves_Dead"
    },
    {
      "x": -7,
      "y": 28,
      "z": -6,
      "name": "Plant_Leaves_Dead"
    },
    {
      "x": -7,
      "y": 26,
      "z": -2,
      "name": "Plant_Leaves_Dead"
    },
    {
      "x": -7,
      "y": 25,
      "z": -1,
      "name": "Plant_Leaves_Dead"
    },
    {
      "x": -7,
      "y": 26,
      "z": -1,
      "name": "Plant_Leaves_Dead"
    },
    {
      "x": -7,
      "y": 30,
      "z": -1,
      "name": "Plant_Leaves_Dead"
    },
    {
      "x": -7,
      "y": 31,
      "z": -1,
      "name": "Plant_Leaves_Dead"
    },
    {
      "x": -7,
      "y": 34,
      "z": -1,
      "name": "Plant_Leaves_Dead"
    },
    {
      "x": -7,
      "y": 38,
      "z": -1,
      "name": "Plant_Leaves_Dead"
    },
    {
      "x": -6,
      "y": 28,
      "z": -7,
      "name": "Plant_Leaves_Dead"
    },
    {
      "x": -6,
      "y": 28,
      "z": -6,
      "name": "Plant_Leaves_Dead"
    },
    {
      "x": -6,
      "y": 28,
      "z": -5,
      "name": "Plant_Leaves_Dead"
    },
    {
      "x": -6,
      "y": 26,
      "z": -2,
      "name": "Plant_Leaves_Dead"
    },
    {
      "x": -6,
      "y": 25,
      "z": -1,
      "name": "Plant_Leaves_Dead"
    },
    {
      "x": -6,
      "y": 26,
      "z": -1,
      "name": "Plant_Leaves_Dead"
    },
    {
      "x": -6,
      "y": 30,
      "z": -1,
      "name": "Plant_Leaves_Dead"
    },
    {
      "x": -6,
      "y": 33,
      "z": -1,
      "name": "Plant_Leaves_Dead"
    },
    {
      "x": -6,
      "y": 34,
      "z": -1,
      "name": "Plant_Leaves_Dead"
    },
    {
      "x": -6,
      "y": 37,
      "z": -1,
      "name": "Plant_Leaves_Dead"
    },
    {
      "x": -6,
      "y": 26,
      "z": 0,
      "name": "Plant_Leaves_Dead"
    },
    {
      "x": -6,
      "y": 29,
      "z": 4,
      "name": "Plant_Leaves_Dead"
    },
    {
      "x": -6,
      "y": 1,
      "z": 5,
      "name": "Wood_Fir_Trunk_Full"
    },
    {
      "x": -6,
      "y": 29,
      "z": 5,
      "name": "Plant_Leaves_Dead"
    },
    {
      "x": -5,
      "y": 28,
      "z": -6,
      "name": "Plant_Leaves_Dead"
    },
    {
      "x": -5,
      "y": 32,
      "z": -6,
      "name": "Plant_Leaves_Dead"
    },
    {
      "x": -5,
      "y": 28,
      "z": -5,
      "name": "Plant_Leaves_Dead"
    },
    {
      "x": -5,
      "y": 32,
      "z": -5,
      "name": "Plant_Leaves_Dead"
    },
    {
      "x": -5,
      "y": 28,
      "z": -4,
      "name": "Plant_Leaves_Dead"
    },
    {
      "x": -5,
      "y": 28,
      "z": -3,
      "name": "Plant_Leaves_Dead"
    },
    {
      "x": -5,
      "y": 26,
      "z": -2,
      "name": "Plant_Leaves_Dead"
    },
    {
      "x": -5,
      "y": 26,
      "z": -1,
      "name": "Wood_Fir_Branch_Corner",
      "rotation": 3
    },
    {
      "x": -5,
      "y": 27,
      "z": -1,
      "name": "Plant_Leaves_Dead"
    },
    {
      "x": -5,
      "y": 30,
      "z": -1,
      "name": "Plant_Leaves_Dead"
    },
    {
      "x": -5,
      "y": 33,
      "z": -1,
      "name": "Plant_Leaves_Dead"
    },
    {
      "x": -5,
      "y": 36,
      "z": -1,
      "name": "Plant_Leaves_Dead"
    },
    {
      "x": -5,
      "y": 37,
      "z": -1,
      "name": "Plant_Leaves_Dead"
    },
    {
      "x": -5,
      "y": 39,
      "z": -1,
      "name": "Plant_Leaves_Dead"
    },
    {
      "x": -5,
      "y": 26,
      "z": 0,
      "name": "Plant_Leaves_Dead"
    },
    {
      "x": -5,
      "y": 30,
      "z": 0,
      "name": "Plant_Leaves_Dead"
    },
    {
      "x": -5,
      "y": 29,
      "z": 3,
      "name": "Plant_Leaves_Dead"
    },
    {
      "x": -5,
      "y": 34,
      "z": 3,
      "name": "Plant_Leaves_Dead"
    },
    {
      "x": -5,
      "y": 1,
      "z": 4,
      "name": "Wood_Fir_Trunk_Full"
    },
    {
      "x": -5,
      "y": 29,
      "z": 4,
      "name": "Plant_Leaves_Dead"
    },
    {
      "x": -5,
      "y": 33,
      "z": 4,
      "name": "Plant_Leaves_Dead"
    },
    {
      "x": -5,
      "y": 1,
      "z": 5,
      "name": "Wood_Fir_Trunk"
    },
    {
      "x": -5,
      "y": 2,
      "z": 5,
      "name": "Wood_Fir_Trunk_Full"
    },
    {
      "x": -5,
      "y": 29,
      "z": 5,
      "name": "Plant_Leaves_Dead"
    },
    {
      "x": -4,
      "y": 32,
      "z": -6,
      "name": "Plant_Leaves_Dead"
    },
    {
      "x": -4,
      "y": 5,
      "z": -5,
      "name": "Wood_Fir_Trunk_Full"
    },
    {
      "x": -4,
      "y": 28,
      "z": -5,
      "name": "Plant_Leaves_Dead"
    },
    {
      "x": -4,
      "y": 32,
      "z": -5,
      "name": "Plant_Leaves_Dead"
    },
    {
      "x": -4,
      "y": 37,
      "z": -5,
      "name": "Plant_Leaves_Dead"
    },
    {
      "x": -4,
      "y": 3,
      "z": -4,
      "name": "Wood_Fir_Trunk"
    },
    {
      "x": -4,
      "y": 4,
      "z": -4,
      "name": "Wood_Fir_Trunk"
    },
    {
      "x": -4,
      "y": 5,
      "z": -4,
      "name": "Wood_Fir_Trunk_Full"
    },
    {
      "x": -4,
      "y": 28,
      "z": -4,
      "name": "Plant_Leaves_Dead"
    },
    {
      "x": -4,
      "y": 29,
      "z": -4,
      "name": "Plant_Leaves_Dead"
    },
    {
      "x": -4,
      "y": 32,
      "z": -4,
      "name": "Plant_Leaves_Dead"
    },
    {
      "x": -4,
      "y": 38,
      "z": -4,
      "name": "Plant_Leaves_Dead"
    },
    {
      "x": -4,
      "y": 26,
      "z": -3,
      "name": "Plant_Leaves_Dead"
    },
    {
      "x": -4,
      "y": 27,
      "z": -3,
      "name": "Plant_Leaves_Dead"
    },
    {
      "x": -4,
      "y": 28,
      "z": -3,
      "name": "Plant_Leaves_Dead"
    },
    {
      "x": -4,
      "y": 26,
      "z": -2,
      "name": "Plant_Leaves_Dead"
    },
    {
      "x": -4,
      "y": 28,
      "z": -2,
      "name": "Plant_Leaves_Dead"
    },
    {
      "x": -4,
      "y": 30,
      "z": -2,
      "name": "Plant_Leaves_Dead"
    },
    {
      "x": -4,
      "y": 26,
      "z": -1,
      "name": "Wood_Fir_Branch_Long",
      "rotation": 5
    },
    {
      "x": -4,
      "y": 27,
      "z": -1,
      "name": "Plant_Leaves_Dead"
    },
    {
      "x": -4,
      "y": 29,
      "z": -1,
      "name": "Plant_Leaves_Dead"
    },
    {
      "x": -4,
      "y": 30,
      "z": -1,
      "name": "Wood_Fir_Branch_Long",
      "rotation": 5
    },
    {
      "x": -4,
      "y": 33,
      "z": -1,
      "name": "Plant_Leaves_Dead"
    },
    {
      "x": -4,
      "y": 36,
      "z": -1,
      "name": "Plant_Leaves_Dead"
    },
    {
      "x": -4,
      "y": 39,
      "z": -1,
      "name": "Plant_Leaves_Dead"
    },
    {
      "x": -4,
      "y": 41,
      "z": -1,
      "name": "Plant_Leaves_Dead"
    },
    {
      "x": -4,
      "y": 45,
      "z": -1,
      "name": "Plant_Leaves_Dead"
    },
    {
      "x": -4,
      "y": 26,
      "z": 0,
      "name": "Plant_Leaves_Dead"
    },
    {
      "x": -4,
      "y": 27,
      "z": 0,
      "name": "Plant_Leaves_Dead"
    },
    {
      "x": -4,
      "y": 30,
      "z": 0,
      "name": "Plant_Leaves_Dead"
    },
    {
      "x": -4,
      "y": 33,
      "z": 0,
      "name": "Plant_Leaves_Dead"
    },
    {
      "x": -4,
      "y": 36,
      "z": 0,
      "name": "Plant_Leaves_Dead"
    },
    {
      "x": -4,
      "y": 39,
      "z": 0,
      "name": "Plant_Leaves_Dead"
    },
    {
      "x": -4,
      "y": 26,
      "z": 1,
      "name": "Plant_Leaves_Dead"
    },
    {
      "x": -4,
      "y": 29,
      "z": 1,
      "name": "Plant_Leaves_Dead"
    },
    {
      "x": -4,
      "y": 29,
      "z": 2,
      "name": "Plant_Leaves_Dead"
    },
    {
      "x": -4,
      "y": 34,
      "z": 2,
      "name": "Plant_Leaves_Dead"
    },
    {
      "x": -4,
      "y": 39,
      "z": 2,
      "name": "Plant_Leaves_Dead"
    },
    {
      "x": -4,
      "y": 2,
      "z": 3,
      "name": "Wood_Fir_Trunk"
    },
    {
      "x": -4,
      "y": 3,
      "z": 3,
      "name": "Wood_Fir_Trunk_Full"
    },
    {
      "x": -4,
      "y": 28,
      "z": 3,
      "name": "Plant_Leaves_Dead"
    },
    {
      "x": -4,
      "y": 29,
      "z": 3,
      "name": "Plant_Leaves_Dead"
    },
    {
      "x": -4,
      "y": 34,
      "z": 3,
      "name": "Plant_Leaves_Dead"
    },
    {
      "x": -4,
      "y": 38,
      "z": 3,
      "name": "Plant_Leaves_Dead"
    },
    {
      "x": -4,
      "y": 1,
      "z": 4,
      "name": "Wood_Fir_Trunk"
    },
    {
      "x": -4,
      "y": 2,
      "z": 4,
      "name": "Wood_Fir_Trunk"
    },
    {
      "x": -4,
      "y": 3,
      "z": 4,
      "name": "Wood_Fir_Trunk_Full"
    },
    {
      "x": -4,
      "y": 29,
      "z": 4,
      "name": "Plant_Leaves_Dead"
    },
    {
      "x": -4,
      "y": 34,
      "z": 4,
      "name": "Plant_Leaves_Dead"
    },
    {
      "x": -4,
      "y": 1,
      "z": 5,
      "name": "Wood_Fir_Trunk"
    },
    {
      "x": -4,
      "y": 2,
      "z": 5,
      "name": "Wood_Fir_Trunk_Full"
    },
    {
      "x": -3,
      "y": 2,
      "z": -6,
      "name": "Wood_Fir_Roots"
    },
    {
      "x": -3,
      "y": 3,
      "z": -6,
      "name": "Wood_Fir_Trunk_Full"
    },
    {
      "x": -3,
      "y": 2,
      "z": -5,
      "name": "Wood_Fir_Trunk"
    },
    {
      "x": -3,
      "y": 3,
      "z": -5,
      "name": "Wood_Fir_Trunk"
    },
    {
      "x": -3,
      "y": 4,
      "z": -5,
      "name": "Wood_Fir_Trunk"
    },
    {
      "x": -3,
      "y": 5,
      "z": -5,
      "name": "Wood_Fir_Trunk_Full"
    },
    {
      "x": -3,
      "y": 28,
      "z": -5,
      "name": "Plant_Leaves_Dead"
    },
    {
      "x": -3,
      "y": 32,
      "z": -5,
      "name": "Plant_Leaves_Dead"
    },
    {
      "x": -3,
      "y": 38,
      "z": -5,
      "name": "Plant_Leaves_Dead"
    },
    {
      "x": -3,
      "y": 2,
      "z": -4,
      "name": "Wood_Fir_Roots"
    },
    {
      "x": -3,
      "y": 3,
      "z": -4,
      "name": "Wood_Fir_Trunk"
    },
    {
      "x": -3,
      "y": 4,
      "z": -4,
      "name": "Wood_Fir_Trunk"
    },
    {
      "x": -3,
      "y": 5,
      "z": -4,
      "name": "Wood_Fir_Trunk"
    },
    {
      "x": -3,
      "y": 6,
      "z": -4,
      "name": "Wood_Fir_Trunk"
    },
    {
      "x": -3,
      "y": 7,
      "z": -4,
      "name": "Wood_Fir_Trunk_Full"
    },
    {
      "x": -3,
      "y": 26,
      "z": -4,
      "name": "Plant_Leaves_Dead"
    },
    {
      "x": -3,
      "y": 27,
      "z": -4,
      "name": "Plant_Leaves_Dead"
    },
    {
      "x": -3,
      "y": 28,
      "z": -4,
      "name": "Plant_Leaves_Dead"
    },
    {
      "x": -3,
      "y": 32,
      "z": -4,
      "name": "Plant_Leaves_Dead"
    },
    {
      "x": -3,
      "y": 38,
      "z": -4,
      "name": "Plant_Leaves_Dead"
    },
    {
      "x": -3,
      "y": 42,
      "z": -4,
      "name": "Plant_Leaves_Dead"
    },
    {
      "x": -3,
      "y": 5,
      "z": -3,
      "name": "Wood_Fir_Trunk"
    },
    {
      "x": -3,
      "y": 6,
      "z": -3,
      "name": "Wood_Fir_Trunk"
    },
    {
      "x": -3,
      "y": 7,
      "z": -3,
      "name": "Wood_Fir_Trunk"
    },
    {
      "x": -3,
      "y": 8,
      "z": -3,
      "name": "Wood_Fir_Trunk_Full"
    },
    {
      "x": -3,
      "y": 26,
      "z": -3,
      "name": "Plant_Leaves_Dead"
    },
    {
      "x": -3,
      "y": 27,
      "z": -3,
      "name": "Plant_Leaves_Dead"
    },
    {
      "x": -3,
      "y": 28,
      "z": -3,
      "name": "Plant_Leaves_Dead"
    },
    {
      "x": -3,
      "y": 29,
      "z": -3,
      "name": "Plant_Leaves_Dead"
    },
    {
      "x": -3,
      "y": 32,
      "z": -3,
      "name": "Plant_Leaves_Dead"
    },
    {
      "x": -3,
      "y": 33,
      "z": -3,
      "name": "Plant_Leaves_Dead"
    },
    {
      "x": -3,
      "y": 38,
      "z": -3,
      "name": "Plant_Leaves_Dead"
    },
    {
      "x": -3,
      "y": 42,
      "z": -3,
      "name": "Plant_Leaves_Dead"
    },
    {
      "x": -3,
      "y": 26,
      "z": -2,
      "name": "Plant_Leaves_Dead"
    },
    {
      "x": -3,
      "y": 27,
      "z": -2,
      "name": "Plant_Leaves_Dead"
    },
    {
      "x": -3,
      "y": 28,
      "z": -2,
      "name": "Plant_Leaves_Dead"
    },
    {
      "x": -3,
      "y": 29,
      "z": -2,
      "name": "Plant_Leaves_Dead"
    },
    {
      "x": -3,
      "y": 30,
      "z": -2,
      "name": "Plant_Leaves_Dead"
    },
    {
      "x": -3,
      "y": 33,
      "z": -2,
      "name": "Plant_Leaves_Dead"
    },
    {
      "x": -3,
      "y": 36,
      "z": -2,
      "name": "Plant_Leaves_Dead"
    },
    {
      "x": -3,
      "y": 39,
      "z": -2,
      "name": "Plant_Leaves_Dead"
    },
    {
      "x": -3,
      "y": 25,
      "z": -1,
      "name": "Plant_Leaves_Dead"
    },
    {
      "x": -3,
      "y": 26,
      "z": -1,
      "name": "Wood_Fir_Branch_Long",
      "rotation": 5
    },
    {
      "x": -3,
      "y": 27,
      "z": -1,
      "name": "Plant_Leaves_Dead"
    },
    {
      "x": -3,
      "y": 28,
      "z": -1,
      "name": "Plant_Leaves_Dead"
    },
    {
      "x": -3,
      "y": 29,
      "z": -1,
      "name": "Plant_Leaves_Dead"
    },
    {
      "x": -3,
      "y": 30,
      "z": -1,
      "name": "Wood_Fir_Branch_Long",
      "rotation": 5
    },
    {
      "x": -3,
      "y": 32,
      "z": -1,
      "name": "Plant_Leaves_Dead"
    },
    {
      "x": -3,
      "y": 33,
      "z": -1,
      "name": "Wood_Fir_Branch_Long",
      "rotation": 5
    },
    {
      "x": -3,
      "y": 36,
      "z": -1,
      "name": "Plant_Leaves_Dead"
    },
    {
      "x": -3,
      "y": 39,
      "z": -1,
      "name": "Wood_Fir_Branch_Corner",
      "rotation": 3
    },
    {
      "x": -3,
      "y": 41,
      "z": -1,
      "name": "Plant_Leaves_Dead"
    },
    {
      "x": -3,
      "y": 44,
      "z": -1,
      "name": "Plant_Leaves_Dead"
    },
    {
      "x": -3,
      "y": 26,
      "z": 0,
      "name": "Plant_Leaves_Dead"
    },
    {
      "x": -3,
      "y": 27,
      "z": 0,
      "name": "Plant_Leaves_Dead"
    },
    {
      "x": -3,
      "y": 29,
      "z": 0,
      "name": "Plant_Leaves_Dead"
    },
    {
      "x": -3,
      "y": 30,
      "z": 0,
      "name": "Plant_Leaves_Dead"
    },
    {
      "x": -3,
      "y": 33,
      "z": 0,
      "name": "Plant_Leaves_Dead"
    },
    {
      "x": -3,
      "y": 36,
      "z": 0,
      "name": "Plant_Leaves_Dead"
    },
    {
      "x": -3,
      "y": 39,
      "z": 0,
      "name": "Plant_Leaves_Dead"
    },
    {
      "x": -3,
      "y": 41,
      "z": 0,
      "name": "Plant_Leaves_Dead"
    },
    {
      "x": -3,
      "y": 44,
      "z": 0,
      "name": "Plant_Leaves_Dead"
    },
    {
      "x": -3,
      "y": 5,
      "z": 1,
      "name": "Wood_Fir_Trunk"
    },
    {
      "x": -3,
      "y": 6,
      "z": 1,
      "name": "Wood_Fir_Trunk"
    },
    {
      "x": -3,
      "y": 7,
      "z": 1,
      "name": "Wood_Fir_Trunk"
    },
    {
      "x": -3,
      "y": 8,
      "z": 1,
      "name": "Wood_Fir_Trunk_Full"
    },
    {
      "x": -3,
      "y": 26,
      "z": 1,
      "name": "Plant_Leaves_Dead"
    },
    {
      "x": -3,
      "y": 28,
      "z": 1,
      "name": "Plant_Leaves_Dead"
    },
    {
      "x": -3,
      "y": 29,
      "z": 1,
      "name": "Plant_Leaves_Dead"
    },
    {
      "x": -3,
      "y": 34,
      "z": 1,
      "name": "Plant_Leaves_Dead"
    },
    {
      "x": -3,
      "y": 39,
      "z": 1,
      "name": "Plant_Leaves_Dead"
    },
    {
      "x": -3,
      "y": 44,
      "z": 1,
      "name": "Plant_Leaves_Dead"
    },
    {
      "x": -3,
      "y": 2,
      "z": 2,
      "name": "Wood_Fir_Roots"
    },
    {
      "x": -3,
      "y": 3,
      "z": 2,
      "name": "Wood_Fir_Trunk"
    },
    {
      "x": -3,
      "y": 4,
      "z": 2,
      "name": "Wood_Fir_Trunk"
    },
    {
      "x": -3,
      "y": 5,
      "z": 2,
      "name": "Wood_Fir_Trunk"
    },
    {
      "x": -3,
      "y": 6,
      "z": 2,
      "name": "Wood_Fir_Trunk"
    },
    {
      "x": -3,
      "y": 7,
      "z": 2,
      "name": "Wood_Fir_Trunk_Full"
    },
    {
      "x": -3,
      "y": 28,
      "z": 2,
      "name": "Plant_Leaves_Dead"
    },
    {
      "x": -3,
      "y": 29,
      "z": 2,
      "name": "Plant_Leaves_Dead"
    },
    {
      "x": -3,
      "y": 30,
      "z": 2,
      "name": "Plant_Leaves_Dead"
    },
    {
      "x": -3,
      "y": 34,
      "z": 2,
      "name": "Plant_Leaves_Dead"
    },
    {
      "x": -3,
      "y": 39,
      "z": 2,
      "name": "Plant_Leaves_Dead"
    },
    {
      "x": -3,
      "y": 45,
      "z": 2,
      "name": "Plant_Leaves_Dead"
    },
    {
      "x": -3,
      "y": 1,
      "z": 3,
      "name": "Wood_Fir_Roots"
    },
    {
      "x": -3,
      "y": 2,
      "z": 3,
      "name": "Wood_Fir_Trunk"
    },
    {
      "x": -3,
      "y": 3,
      "z": 3,
      "name": "Wood_Fir_Trunk"
    },
    {
      "x": -3,
      "y": 4,
      "z": 3,
      "name": "Wood_Fir_Trunk_Full"
    },
    {
      "x": -3,
      "y": 29,
      "z": 3,
      "name": "Plant_Leaves_Dead"
    },
    {
      "x": -3,
      "y": 34,
      "z": 3,
      "name": "Plant_Leaves_Dead"
    },
    {
      "x": -3,
      "y": 39,
      "z": 3,
      "name": "Plant_Leaves_Dead"
    },
    {
      "x": -3,
      "y": 2,
      "z": 4,
      "name": "Wood_Fir_Trunk"
    },
    {
      "x": -3,
      "y": 3,
      "z": 4,
      "name": "Wood_Fir_Trunk_Full"
    },
    {
      "x": -2,
      "y": 1,
      "z": -6,
      "name": "Wood_Fir_Roots"
    },
    {
      "x": -2,
      "y": 2,
      "z": -6,
      "name": "Wood_Fir_Trunk"
    },
    {
      "x": -2,
      "y": 3,
      "z": -6,
      "name": "Wood_Fir_Trunk_Full"
    },
    {
      "x": -2,
      "y": 3,
      "z": -5,
      "name": "Wood_Fir_Trunk_Full"
    },
    {
      "x": -2,
      "y": 27,
      "z": -5,
      "name": "Plant_Leaves_Dead"
    },
    {
      "x": -2,
      "y": 5,
      "z": -4,
      "name": "Wood_Fir_Trunk"
    },
    {
      "x": -2,
      "y": 6,
      "z": -4,
      "name": "Wood_Fir_Trunk"
    },
    {
      "x": -2,
      "y": 7,
      "z": -4,
      "name": "Wood_Fir_Trunk"
    },
    {
      "x": -2,
      "y": 8,
      "z": -4,
      "name": "Wood_Fir_Trunk_Full"
    },
    {
      "x": -2,
      "y": 27,
      "z": -4,
      "name": "Plant_Leaves_Dead"
    },
    {
      "x": -2,
      "y": 28,
      "z": -4,
      "name": "Plant_Leaves_Dead"
    },
    {
      "x": -2,
      "y": 32,
      "z": -4,
      "name": "Plant_Leaves_Dead"
    },
    {
      "x": -2,
      "y": 33,
      "z": -4,
      "name": "Plant_Leaves_Dead"
    },
    {
      "x": -2,
      "y": 38,
      "z": -4,
      "name": "Plant_Leaves_Dead"
    },
    {
      "x": -2,
      "y": 42,
      "z": -4,
      "name": "Plant_Leaves_Dead"
    },
    {
      "x": -2,
      "y": 6,
      "z": -3,
      "name": "Wood_Fir_Trunk"
    },
    {
      "x": -2,
      "y": 7,
      "z": -3,
      "name": "Wood_Fir_Trunk"
    },
    {
      "x": -2,
      "y": 8,
      "z": -3,
      "name": "Wood_Fir_Trunk"
    },
    {
      "x": -2,
      "y": 9,
      "z": -3,
      "name": "Wood_Fir_Trunk"
    },
    {
      "x": -2,
      "y": 10,
      "z": -3,
      "name": "Wood_Fir_Trunk"
    },
    {
      "x": -2,
      "y": 11,
      "z": -3,
      "name": "Wood_Fir_Trunk_Full"
    },
    {
      "x": -2,
      "y": 27,
      "z": -3,
      "name": "Plant_Leaves_Dead"
    },
    {
      "x": -2,
      "y": 28,
      "z": -3,
      "name": "Plant_Leaves_Dead"
    },
    {
      "x": -2,
      "y": 29,
      "z": -3,
      "name": "Plant_Leaves_Dead"
    },
    {
      "x": -2,
      "y": 32,
      "z": -3,
      "name": "Plant_Leaves_Dead"
    },
    {
      "x": -2,
      "y": 33,
      "z": -3,
      "name": "Plant_Leaves_Dead"
    },
    {
      "x": -2,
      "y": 34,
      "z": -3,
      "name": "Plant_Leaves_Dead"
    },
    {
      "x": -2,
      "y": 38,
      "z": -3,
      "name": "Plant_Leaves_Dead"
    },
    {
      "x": -2,
      "y": 42,
      "z": -3,
      "name": "Plant_Leaves_Dead"
    },
    {
      "x": -2,
      "y": 8,
      "z": -2,
      "name": "Wood_Fir_Trunk"
    },
    {
      "x": -2,
      "y": 9,
      "z": -2,
      "name": "Wood_Fir_Trunk"
    },
    {
      "x": -2,
      "y": 10,
      "z": -2,
      "name": "Wood_Fir_Trunk"
    },
    {
      "x": -2,
      "y": 11,
      "z": -2,
      "name": "Wood_Fir_Trunk"
    },
    {
      "x": -2,
      "y": 12,
      "z": -2,
      "name": "Wood_Fir_Trunk"
    },
    {
      "x": -2,
      "y": 13,
      "z": -2,
      "name": "Wood_Fir_Trunk"
    },
    {
      "x": -2,
      "y": 14,
      "z": -2,
      "name": "Wood_Fir_Trunk"
    },
    {
      "x": -2,
      "y": 15,
      "z": -2,
      "name": "Wood_Fir_Trunk_Full"
    },
    {
      "x": -2,
      "y": 28,
      "z": -2,
      "name": "Plant_Leaves_Dead"
    },
    {
      "x": -2,
      "y": 29,
      "z": -2,
      "name": "Plant_Leaves_Dead"
    },
    {
      "x": -2,
      "y": 30,
      "z": -2,
      "name": "Plant_Leaves_Dead"
    },
    {
      "x": -2,
      "y": 32,
      "z": -2,
      "name": "Plant_Leaves_Dead"
    },
    {
      "x": -2,
      "y": 33,
      "z": -2,
      "name": "Plant_Leaves_Dead"
    },
    {
      "x": -2,
      "y": 34,
      "z": -2,
      "name": "Plant_Leaves_Dead"
    },
    {
      "x": -2,
      "y": 36,
      "z": -2,
      "name": "Plant_Leaves_Dead"
    },
    {
      "x": -2,
      "y": 37,
      "z": -2,
      "name": "Plant_Leaves_Dead"
    },
    {
      "x": -2,
      "y": 38,
      "z": -2,
      "name": "Plant_Leaves_Dead"
    },
    {
      "x": -2,
      "y": 39,
      "z": -2,
      "name": "Plant_Leaves_Dead"
    },
    {
      "x": -2,
      "y": 41,
      "z": -2,
      "name": "Plant_Leaves_Dead"
    },
    {
      "x": -2,
      "y": 42,
      "z": -2,
      "name": "Plant_Leaves_Dead"
    },
    {
      "x": -2,
      "y": 44,
      "z": -2,
      "name": "Plant_Leaves_Dead"
    },
    {
      "x": -2,
      "y": 46,
      "z": -2,
      "name": "Plant_Leaves_Dead"
    },
    {
      "x": -2,
      "y": 11,
      "z": -1,
      "name": "Wood_Fir_Trunk"
    },
    {
      "x": -2,
      "y": 12,
      "z": -1,
      "name": "Wood_Fir_Trunk"
    },
    {
      "x": -2,
      "y": 13,
      "z": -1,
      "name": "Wood_Fir_Trunk"
    },
    {
      "x": -2,
      "y": 14,
      "z": -1,
      "name": "Wood_Fir_Trunk"
    },
    {
      "x": -2,
      "y": 15,
      "z": -1,
      "name": "Wood_Fir_Trunk"
    },
    {
      "x": -2,
      "y": 16,
      "z": -1,
      "name": "Wood_Fir_Trunk"
    },
    {
      "x": -2,
      "y": 17,
      "z": -1,
      "name": "Wood_Fir_Trunk"
    },
    {
      "x": -2,
      "y": 18,
      "z": -1,
      "name": "Wood_Fir_Trunk"
    },
    {
      "x": -2,
      "y": 19,
      "z": -1,
      "name": "Wood_Fir_Trunk"
    },
    {
      "x": -2,
      "y": 20,
      "z": -1,
      "name": "Wood_Fir_Trunk"
    },
    {
      "x": -2,
      "y": 21,
      "z": -1,
      "name": "Wood_Fir_Trunk"
    },
    {
      "x": -2,
      "y": 22,
      "z": -1,
      "name": "Wood_Fir_Trunk"
    },
    {
      "x": -2,
      "y": 23,
      "z": -1,
      "name": "Wood_Fir_Trunk"
    },
    {
      "x": -2,
      "y": 24,
      "z": -1,
      "name": "Wood_Fir_Trunk"
    },
    {
      "x": -2,
      "y": 25,
      "z": -1,
      "name": "Wood_Fir_Trunk"
    },
    {
      "x": -2,
      "y": 26,
      "z": -1,
      "name": "Wood_Fir_Trunk"
    },
    {
      "x": -2,
      "y": 27,
      "z": -1,
      "name": "Wood_Fir_Trunk"
    },
    {
      "x": -2,
      "y": 28,
      "z": -1,
      "name": "Wood_Fir_Trunk"
    },
    {
      "x": -2,
      "y": 29,
      "z": -1,
      "name": "Wood_Fir_Trunk"
    },
    {
      "x": -2,
      "y": 30,
      "z": -1,
      "name": "Wood_Fir_Trunk"
    },
    {
      "x": -2,
      "y": 32,
      "z": -1,
      "name": "Plant_Leaves_Dead"
    },
    {
      "x": -2,
      "y": 33,
      "z": -1,
      "name": "Wood_Fir_Branch_Long",
      "rotation": 5
    },
    {
      "x": -2,
      "y": 34,
      "z": -1,
      "name": "Plant_Leaves_Dead"
    },
    {
      "x": -2,
      "y": 35,
      "z": -1,
      "name": "Plant_Leaves_Dead"
    },
    {
      "x": -2,
      "y": 36,
      "z": -1,
      "name": "Wood_Fir_Branch_Long",
      "rotation": 5
    },
    {
      "x": -2,
      "y": 39,
      "z": -1,
      "name": "Wood_Fir_Branch_Long",
      "rotation": 5
    },
    {
      "x": -2,
      "y": 41,
      "z": -1,
      "name": "Wood_Fir_Branch_Corner",
      "rotation": 3
    },
    {
      "x": -2,
      "y": 44,
      "z": -1,
      "name": "Wood_Fir_Branch_Corner",
      "rotation": 3
    },
    {
      "x": -2,
      "y": 45,
      "z": -1,
      "name": "Plant_Leaves_Dead"
    },
    {
      "x": -2,
      "y": 46,
      "z": -1,
      "name": "Plant_Leaves_Dead"
    },
    {
      "x": -2,
      "y": 47,
      "z": -1,
      "name": "Plant_Leaves_Dead"
    },
    {
      "x": -2,
      "y": 48,
      "z": -1,
      "name": "Plant_Leaves_Dead"
    },
    {
      "x": -2,
      "y": 9,
      "z": 0,
      "name": "Wood_Fir_Trunk"
    },
    {
      "x": -2,
      "y": 10,
      "z": 0,
      "name": "Wood_Fir_Trunk"
    },
    {
      "x": -2,
      "y": 11,
      "z": 0,
      "name": "Wood_Fir_Trunk"
    },
    {
      "x": -2,
      "y": 12,
      "z": 0,
      "name": "Wood_Fir_Trunk"
    },
    {
      "x": -2,
      "y": 13,
      "z": 0,
      "name": "Wood_Fir_Trunk"
    },
    {
      "x": -2,
      "y": 14,
      "z": 0,
      "name": "Wood_Fir_Trunk"
    },
    {
      "x": -2,
      "y": 15,
      "z": 0,
      "name": "Wood_Fir_Trunk"
    },
    {
      "x": -2,
      "y": 16,
      "z": 0,
      "name": "Wood_Fir_Trunk"
    },
    {
      "x": -2,
      "y": 17,
      "z": 0,
      "name": "Wood_Fir_Trunk"
    },
    {
      "x": -2,
      "y": 18,
      "z": 0,
      "name": "Wood_Fir_Trunk_Full"
    },
    {
      "x": -2,
      "y": 29,
      "z": 0,
      "name": "Plant_Leaves_Dead"
    },
    {
      "x": -2,
      "y": 30,
      "z": 0,
      "name": "Plant_Leaves_Dead"
    },
    {
      "x": -2,
      "y": 33,
      "z": 0,
      "name": "Plant_Leaves_Dead"
    },
    {
      "x": -2,
      "y": 34,
      "z": 0,
      "name": "Plant_Leaves_Dead"
    },
    {
      "x": -2,
      "y": 35,
      "z": 0,
      "name": "Plant_Leaves_Dead"
    },
    {
      "x": -2,
      "y": 36,
      "z": 0,
      "name": "Plant_Leaves_Dead"
    },
    {
      "x": -2,
      "y": 39,
      "z": 0,
      "name": "Plant_Leaves_Dead"
    },
    {
      "x": -2,
      "y": 41,
      "z": 0,
      "name": "Plant_Leaves_Dead"
    },
    {
      "x": -2,
      "y": 44,
      "z": 0,
      "name": "Plant_Leaves_Dead"
    },
    {
      "x": -2,
      "y": 4,
      "z": 1,
      "name": "Wood_Fir_Roots"
    },
    {
      "x": -2,
      "y": 5,
      "z": 1,
      "name": "Wood_Fir_Trunk"
    },
    {
      "x": -2,
      "y": 6,
      "z": 1,
      "name": "Wood_Fir_Trunk"
    },
    {
      "x": -2,
      "y": 7,
      "z": 1,
      "name": "Wood_Fir_Trunk"
    },
    {
      "x": -2,
      "y": 8,
      "z": 1,
      "name": "Wood_Fir_Trunk"
    },
    {
      "x": -2,
      "y": 9,
      "z": 1,
      "name": "Wood_Fir_Trunk"
    },
    {
      "x": -2,
      "y": 10,
      "z": 1,
      "name": "Wood_Fir_Trunk"
    },
    {
      "x": -2,
      "y": 11,
      "z": 1,
      "name": "Wood_Fir_Trunk"
    },
    {
      "x": -2,
      "y": 12,
      "z": 1,
      "name": "Wood_Fir_Trunk_Full"
    },
    {
      "x": -2,
      "y": 28,
      "z": 1,
      "name": "Plant_Leaves_Dead"
    },
    {
      "x": -2,
      "y": 29,
      "z": 1,
      "name": "Plant_Leaves_Dead"
    },
    {
      "x": -2,
      "y": 30,
      "z": 1,
      "name": "Plant_Leaves_Dead"
    },
    {
      "x": -2,
      "y": 34,
      "z": 1,
      "name": "Plant_Leaves_Dead"
    },
    {
      "x": -2,
      "y": 39,
      "z": 1,
      "name": "Plant_Leaves_Dead"
    },
    {
      "x": -2,
      "y": 44,
      "z": 1,
      "name": "Plant_Leaves_Dead"
    },
    {
      "x": -2,
      "y": 6,
      "z": 2,
      "name": "Wood_Fir_Trunk"
    },
    {
      "x": -2,
      "y": 7,
      "z": 2,
      "name": "Wood_Fir_Trunk"
    },
    {
      "x": -2,
      "y": 8,
      "z": 2,
      "name": "Wood_Fir_Trunk_Full"
    },
    {
      "x": -2,
      "y": 28,
      "z": 2,
      "name": "Plant_Leaves_Dead"
    },
    {
      "x": -2,
      "y": 29,
      "z": 2,
      "name": "Plant_Leaves_Dead"
    },
    {
      "x": -2,
      "y": 34,
      "z": 2,
      "name": "Plant_Leaves_Dead"
    },
    {
      "x": -2,
      "y": 39,
      "z": 2,
      "name": "Plant_Leaves_Dead"
    },
    {
      "x": -2,
      "y": 44,
      "z": 2,
      "name": "Plant_Leaves_Dead"
    },
    {
      "x": -2,
      "y": 2,
      "z": 3,
      "name": "Wood_Fir_Roots"
    },
    {
      "x": -2,
      "y": 3,
      "z": 3,
      "name": "Wood_Fir_Trunk"
    },
    {
      "x": -2,
      "y": 4,
      "z": 3,
      "name": "Wood_Fir_Trunk"
    },
    {
      "x": -2,
      "y": 5,
      "z": 3,
      "name": "Wood_Fir_Trunk"
    },
    {
      "x": -2,
      "y": 6,
      "z": 3,
      "name": "Wood_Fir_Trunk_Full"
    },
    {
      "x": -2,
      "y": 29,
      "z": 3,
      "name": "Plant_Leaves_Dead"
    },
    {
      "x": -1,
      "y": 27,
      "z": -7,
      "name": "Plant_Leaves_Dead"
    },
    {
      "x": -1,
      "y": 27,
      "z": -6,
      "name": "Plant_Leaves_Dead"
    },
    {
      "x": -1,
      "y": 30,
      "z": -6,
      "name": "Plant_Leaves_Dead"
    },
    {
      "x": -1,
      "y": 34,
      "z": -6,
      "name": "Plant_Leaves_Dead"
    },
    {
      "x": -1,
      "y": 27,
      "z": -5,
      "name": "Plant_Leaves_Dead"
    },
    {
      "x": -1,
      "y": 28,
      "z": -5,
      "name": "Plant_Leaves_Dead"
    },
    {
      "x": -1,
      "y": 30,
      "z": -5,
      "name": "Plant_Leaves_Dead"
    },
    {
      "x": -1,
      "y": 34,
      "z": -5,
      "name": "Plant_Leaves_Dead"
    },
    {
      "x": -1,
      "y": 37,
      "z": -5,
      "name": "Plant_Leaves_Dead"
    },
    {
      "x": -1,
      "y": 27,
      "z": -4,
      "name": "Plant_Leaves_Dead"
    },
    {
      "x": -1,
      "y": 28,
      "z": -4,
      "name": "Plant_Leaves_Dead"
    },
    {
      "x": -1,
      "y": 30,
      "z": -4,
      "name": "Plant_Leaves_Dead"
    },
    {
      "x": -1,
      "y": 34,
      "z": -4,
      "name": "Plant_Leaves_Dead"
    },
    {
      "x": -1,
      "y": 37,
      "z": -4,
      "name": "Plant_Leaves_Dead"
    },
    {
      "x": -1,
      "y": 41,
      "z": -4,
      "name": "Plant_Leaves_Dead"
    },
    {
      "x": -1,
      "y": 43,
      "z": -4,
      "name": "Plant_Leaves_Dead"
    },
    {
      "x": -1,
      "y": 8,
      "z": -3,
      "name": "Wood_Fir_Trunk"
    },
    {
      "x": -1,
      "y": 9,
      "z": -3,
      "name": "Wood_Fir_Trunk"
    },
    {
      "x": -1,
      "y": 10,
      "z": -3,
      "name": "Wood_Fir_Trunk"
    },
    {
      "x": -1,
      "y": 11,
      "z": -3,
      "name": "Wood_Fir_Trunk"
    },
    {
      "x": -1,
      "y": 12,
      "z": -3,
      "name": "Wood_Fir_Trunk"
    },
    {
      "x": -1,
      "y": 13,
      "z": -3,
      "name": "Wood_Fir_Trunk"
    },
    {
      "x": -1,
      "y": 14,
      "z": -3,
      "name": "Wood_Fir_Trunk"
    },
    {
      "x": -1,
      "y": 15,
      "z": -3,
      "name": "Wood_Fir_Trunk"
    },
    {
      "x": -1,
      "y": 16,
      "z": -3,
      "name": "Wood_Fir_Trunk"
    },
    {
      "x": -1,
      "y": 17,
      "z": -3,
      "name": "Wood_Fir_Trunk"
    },
    {
      "x": -1,
      "y": 18,
      "z": -3,
      "name": "Wood_Fir_Trunk"
    },
    {
      "x": -1,
      "y": 19,
      "z": -3,
      "name": "Wood_Fir_Trunk_Full"
    },
    {
      "x": -1,
      "y": 28,
      "z": -3,
      "name": "Plant_Leaves_Dead"
    },
    {
      "x": -1,
      "y": 29,
      "z": -3,
      "name": "Plant_Leaves_Dead"
    },
    {
      "x": -1,
      "y": 30,
      "z": -3,
      "name": "Plant_Leaves_Dead"
    },
    {
      "x": -1,
      "y": 32,
      "z": -3,
      "name": "Plant_Leaves_Dead"
    },
    {
      "x": -1,
      "y": 33,
      "z": -3,
      "name": "Plant_Leaves_Dead"
    },
    {
      "x": -1,
      "y": 34,
      "z": -3,
      "name": "Plant_Leaves_Dead"
    },
    {
      "x": -1,
      "y": 37,
      "z": -3,
      "name": "Plant_Leaves_Dead"
    },
    {
      "x": -1,
      "y": 38,
      "z": -3,
      "name": "Plant_Leaves_Dead"
    },
    {
      "x": -1,
      "y": 41,
      "z": -3,
      "name": "Plant_Leaves_Dead"
    },
    {
      "x": -1,
      "y": 42,
      "z": -3,
      "name": "Plant_Leaves_Dead"
    },
    {
      "x": -1,
      "y": 43,
      "z": -3,
      "name": "Plant_Leaves_Dead"
    },
    {
      "x": -1,
      "y": 46,
      "z": -3,
      "name": "Plant_Leaves_Dead"
    },
    {
      "x": -1,
      "y": 8,
      "z": -2,
      "name": "Wood_Fir_Trunk"
    },
    {
      "x": -1,
      "y": 9,
      "z": -2,
      "name": "Wood_Fir_Trunk"
    },
    {
      "x": -1,
      "y": 10,
      "z": -2,
      "name": "Wood_Fir_Trunk"
    },
    {
      "x": -1,
      "y": 12,
      "z": -2,
      "name": "Wood_Fir_Trunk"
    },
    {
      "x": -1,
      "y": 13,
      "z": -2,
      "name": "Wood_Fir_Trunk"
    },
    {
      "x": -1,
      "y": 14,
      "z": -2,
      "name": "Wood_Fir_Trunk"
    },
    {
      "x": -1,
      "y": 15,
      "z": -2,
      "name": "Wood_Fir_Trunk"
    },
    {
      "x": -1,
      "y": 16,
      "z": -2,
      "name": "Wood_Fir_Trunk"
    },
    {
      "x": -1,
      "y": 17,
      "z": -2,
      "name": "Wood_Fir_Trunk"
    },
    {
      "x": -1,
      "y": 18,
      "z": -2,
      "name": "Wood_Fir_Trunk"
    },
    {
      "x": -1,
      "y": 19,
      "z": -2,
      "name": "Wood_Fir_Trunk"
    },
    {
      "x": -1,
      "y": 20,
      "z": -2,
      "name": "Wood_Fir_Trunk"
    },
    {
      "x": -1,
      "y": 21,
      "z": -2,
      "name": "Wood_Fir_Trunk"
    },
    {
      "x": -1,
      "y": 22,
      "z": -2,
      "name": "Wood_Fir_Trunk"
    },
    {
      "x": -1,
      "y": 23,
      "z": -2,
      "name": "Wood_Fir_Trunk"
    },
    {
      "x": -1,
      "y": 24,
      "z": -2,
      "name": "Wood_Fir_Trunk"
    },
    {
      "x": -1,
      "y": 25,
      "z": -2,
      "name": "Wood_Fir_Trunk"
    },
    {
      "x": -1,
      "y": 26,
      "z": -2,
      "name": "Wood_Fir_Trunk"
    },
    {
      "x": -1,
      "y": 27,
      "z": -2,
      "name": "Wood_Fir_Trunk"
    },
    {
      "x": -1,
      "y": 28,
      "z": -2,
      "name": "Wood_Fir_Trunk"
    },
    {
      "x": -1,
      "y": 29,
      "z": -2,
      "name": "Wood_Fir_Trunk"
    },
    {
      "x": -1,
      "y": 30,
      "z": -2,
      "name": "Wood_Fir_Trunk"
    },
    {
      "x": -1,
      "y": 31,
      "z": -2,
      "name": "Wood_Fir_Trunk"
    },
    {
      "x": -1,
      "y": 32,
      "z": -2,
      "name": "Wood_Fir_Trunk"
    },
    {
      "x": -1,
      "y": 33,
      "z": -2,
      "name": "Wood_Fir_Trunk"
    },
    {
      "x": -1,
      "y": 34,
      "z": -2,
      "name": "Wood_Fir_Trunk"
    },
    {
      "x": -1,
      "y": 35,
      "z": -2,
      "name": "Wood_Fir_Trunk"
    },
    {
      "x": -1,
      "y": 36,
      "z": -2,
      "name": "Wood_Fir_Trunk"
    },
    {
      "x": -1,
      "y": 37,
      "z": -2,
      "name": "Wood_Fir_Trunk"
    },
    {
      "x": -1,
      "y": 38,
      "z": -2,
      "name": "Wood_Fir_Trunk"
    },
    {
      "x": -1,
      "y": 39,
      "z": -2,
      "name": "Plant_Leaves_Dead"
    },
    {
      "x": -1,
      "y": 41,
      "z": -2,
      "name": "Plant_Leaves_Dead"
    },
    {
      "x": -1,
      "y": 42,
      "z": -2,
      "name": "Plant_Leaves_Dead"
    },
    {
      "x": -1,
      "y": 43,
      "z": -2,
      "name": "Plant_Leaves_Dead"
    },
    {
      "x": -1,
      "y": 44,
      "z": -2,
      "name": "Plant_Leaves_Dead"
    },
    {
      "x": -1,
      "y": 45,
      "z": -2,
      "name": "Plant_Leaves_Dead"
    },
    {
      "x": -1,
      "y": 46,
      "z": -2,
      "name": "Plant_Leaves_Dead"
    },
    {
      "x": -1,
      "y": 47,
      "z": -2,
      "name": "Plant_Leaves_Dead"
    },
    {
      "x": -1,
      "y": 13,
      "z": -1,
      "name": "Wood_Fir_Trunk"
    },
    {
      "x": -1,
      "y": 14,
      "z": -1,
      "name": "Wood_Fir_Trunk"
    },
    {
      "x": -1,
      "y": 15,
      "z": -1,
      "name": "Wood_Fir_Trunk"
    },
    {
      "x": -1,
      "y": 16,
      "z": -1,
      "name": "Wood_Fir_Trunk"
    },
    {
      "x": -1,
      "y": 17,
      "z": -1,
      "name": "Wood_Fir_Trunk"
    },
    {
      "x": -1,
      "y": 18,
      "z": -1,
      "name": "Wood_Fir_Trunk"
    },
    {
      "x": -1,
      "y": 19,
      "z": -1,
      "name": "Wood_Fir_Trunk"
    },
    {
      "x": -1,
      "y": 20,
      "z": -1,
      "name": "Wood_Fir_Trunk"
    },
    {
      "x": -1,
      "y": 21,
      "z": -1,
      "name": "Wood_Fir_Trunk"
    },
    {
      "x": -1,
      "y": 22,
      "z": -1,
      "name": "Wood_Fir_Trunk"
    },
    {
      "x": -1,
      "y": 23,
      "z": -1,
      "name": "Wood_Fir_Trunk"
    },
    {
      "x": -1,
      "y": 24,
      "z": -1,
      "name": "Wood_Fir_Trunk"
    },
    {
      "x": -1,
      "y": 25,
      "z": -1,
      "name": "Wood_Fir_Trunk"
    },
    {
      "x": -1,
      "y": 26,
      "z": -1,
      "name": "Wood_Fir_Trunk"
    },
    {
      "x": -1,
      "y": 27,
      "z": -1,
      "name": "Wood_Fir_Trunk"
    },
    {
      "x": -1,
      "y": 28,
      "z": -1,
      "name": "Wood_Fir_Trunk"
    },
    {
      "x": -1,
      "y": 29,
      "z": -1,
      "name": "Wood_Fir_Trunk"
    },
    {
      "x": -1,
      "y": 30,
      "z": -1,
      "name": "Wood_Fir_Trunk"
    },
    {
      "x": -1,
      "y": 31,
      "z": -1,
      "name": "Wood_Fir_Trunk"
    },
    {
      "x": -1,
      "y": 32,
      "z": -1,
      "name": "Wood_Fir_Trunk"
    },
    {
      "x": -1,
      "y": 33,
      "z": -1,
      "name": "Wood_Fir_Trunk"
    },
    {
      "x": -1,
      "y": 34,
      "z": -1,
      "name": "Wood_Fir_Trunk"
    },
    {
      "x": -1,
      "y": 35,
      "z": -1,
      "name": "Wood_Fir_Trunk"
    },
    {
      "x": -1,
      "y": 36,
      "z": -1,
      "name": "Wood_Fir_Trunk"
    },
    {
      "x": -1,
      "y": 37,
      "z": -1,
      "name": "Wood_Fir_Trunk"
    },
    {
      "x": -1,
      "y": 38,
      "z": -1,
      "name": "Wood_Fir_Trunk"
    },
    {
      "x": -1,
      "y": 39,
      "z": -1,
      "name": "Wood_Fir_Trunk"
    },
    {
      "x": -1,
      "y": 40,
      "z": -1,
      "name": "Wood_Fir_Trunk"
    },
    {
      "x": -1,
      "y": 41,
      "z": -1,
      "name": "Wood_Fir_Trunk"
    },
    {
      "x": -1,
      "y": 42,
      "z": -1,
      "name": "Wood_Fir_Trunk"
    },
    {
      "x": -1,
      "y": 43,
      "z": -1,
      "name": "Wood_Fir_Trunk"
    },
    {
      "x": -1,
      "y": 44,
      "z": -1,
      "name": "Wood_Fir_Trunk"
    },
    {
      "x": -1,
      "y": 45,
      "z": -1,
      "name": "Wood_Fir_Trunk"
    },
    {
      "x": -1,
      "y": 46,
      "z": -1,
      "name": "Wood_Fir_Trunk"
    },
    {
      "x": -1,
      "y": 47,
      "z": -1,
      "name": "Plant_Leaves_Dead"
    },
    {
      "x": -1,
      "y": 48,
      "z": -1,
      "name": "Plant_Leaves_Dead"
    },
    {
      "x": -1,
      "y": 49,
      "z": -1,
      "name": "Plant_Leaves_Dead"
    },
    {
      "x": -1,
      "y": 50,
      "z": -1,
      "name": "Plant_Leaves_Dead"
    },
    {
      "x": -1,
      "y": 51,
      "z": -1,
      "name": "Plant_Leaves_Dead"
    },
    {
      "x": -1,
      "y": 9,
      "z": 0,
      "name": "Wood_Fir_Trunk"
    },
    {
      "x": -1,
      "y": 10,
      "z": 0,
      "name": "Wood_Fir_Trunk"
    },
    {
      "x": -1,
      "y": 11,
      "z": 0,
      "name": "Wood_Fir_Trunk"
    },
    {
      "x": -1,
      "y": 12,
      "z": 0,
      "name": "Wood_Fir_Trunk"
    },
    {
      "x": -1,
      "y": 13,
      "z": 0,
      "name": "Wood_Fir_Trunk"
    },
    {
      "x": -1,
      "y": 14,
      "z": 0,
      "name": "Wood_Fir_Trunk"
    },
    {
      "x": -1,
      "y": 15,
      "z": 0,
      "name": "Wood_Fir_Trunk"
    },
    {
      "x": -1,
      "y": 16,
      "z": 0,
      "name": "Wood_Fir_Trunk"
    },
    {
      "x": -1,
      "y": 17,
      "z": 0,
      "name": "Wood_Fir_Trunk"
    },
    {
      "x": -1,
      "y": 18,
      "z": 0,
      "name": "Wood_Fir_Trunk"
    },
    {
      "x": -1,
      "y": 19,
      "z": 0,
      "name": "Wood_Fir_Trunk"
    },
    {
      "x": -1,
      "y": 20,
      "z": 0,
      "name": "Wood_Fir_Trunk"
    },
    {
      "x": -1,
      "y": 21,
      "z": 0,
      "name": "Wood_Fir_Trunk"
    },
    {
      "x": -1,
      "y": 22,
      "z": 0,
      "name": "Wood_Fir_Trunk"
    },
    {
      "x": -1,
      "y": 23,
      "z": 0,
      "name": "Wood_Fir_Trunk"
    },
    {
      "x": -1,
      "y": 24,
      "z": 0,
      "name": "Wood_Fir_Trunk"
    },
    {
      "x": -1,
      "y": 25,
      "z": 0,
      "name": "Wood_Fir_Trunk"
    },
    {
      "x": -1,
      "y": 26,
      "z": 0,
      "name": "Wood_Fir_Trunk"
    },
    {
      "x": -1,
      "y": 27,
      "z": 0,
      "name": "Wood_Fir_Trunk"
    },
    {
      "x": -1,
      "y": 28,
      "z": 0,
      "name": "Wood_Fir_Trunk"
    },
    {
      "x": -1,
      "y": 29,
      "z": 0,
      "name": "Wood_Fir_Trunk"
    },
    {
      "x": -1,
      "y": 30,
      "z": 0,
      "name": "Wood_Fir_Trunk"
    },
    {
      "x": -1,
      "y": 31,
      "z": 0,
      "name": "Wood_Fir_Trunk"
    },
    {
      "x": -1,
      "y": 32,
      "z": 0,
      "name": "Wood_Fir_Trunk"
    },
    {
      "x": -1,
      "y": 33,
      "z": 0,
      "name": "Wood_Fir_Trunk"
    },
    {
      "x": -1,
      "y": 34,
      "z": 0,
      "name": "Wood_Fir_Trunk"
    },
    {
      "x": -1,
      "y": 35,
      "z": 0,
      "name": "Wood_Fir_Trunk"
    },
    {
      "x": -1,
      "y": 36,
      "z": 0,
      "name": "Plant_Leaves_Dead"
    },
    {
      "x": -1,
      "y": 38,
      "z": 0,
      "name": "Plant_Leaves_Dead"
    },
    {
      "x": -1,
      "y": 39,
      "z": 0,
      "name": "Plant_Leaves_Dead"
    },
    {
      "x": -1,
      "y": 40,
      "z": 0,
      "name": "Plant_Leaves_Dead"
    },
    {
      "x": -1,
      "y": 41,
      "z": 0,
      "name": "Plant_Leaves_Dead"
    },
    {
      "x": -1,
      "y": 43,
      "z": 0,
      "name": "Plant_Leaves_Dead"
    },
    {
      "x": -1,
      "y": 44,
      "z": 0,
      "name": "Plant_Leaves_Dead"
    },
    {
      "x": -1,
      "y": 45,
      "z": 0,
      "name": "Plant_Leaves_Dead"
    },
    {
      "x": -1,
      "y": 46,
      "z": 0,
      "name": "Plant_Leaves_Dead"
    },
    {
      "x": -1,
      "y": 47,
      "z": 0,
      "name": "Plant_Leaves_Dead"
    },
    {
      "x": -1,
      "y": 9,
      "z": 1,
      "name": "Wood_Fir_Trunk"
    },
    {
      "x": -1,
      "y": 10,
      "z": 1,
      "name": "Wood_Fir_Trunk"
    },
    {
      "x": -1,
      "y": 11,
      "z": 1,
      "name": "Wood_Fir_Trunk"
    },
    {
      "x": -1,
      "y": 12,
      "z": 1,
      "name": "Wood_Fir_Trunk"
    },
    {
      "x": -1,
      "y": 13,
      "z": 1,
      "name": "Wood_Fir_Trunk"
    },
    {
      "x": -1,
      "y": 14,
      "z": 1,
      "name": "Wood_Fir_Trunk_Full"
    },
    {
      "x": -1,
      "y": 28,
      "z": 1,
      "name": "Plant_Leaves_Dead"
    },
    {
      "x": -1,
      "y": 29,
      "z": 1,
      "name": "Plant_Leaves_Dead"
    },
    {
      "x": -1,
      "y": 30,
      "z": 1,
      "name": "Plant_Leaves_Dead"
    },
    {
      "x": -1,
      "y": 31,
      "z": 1,
      "name": "Plant_Leaves_Dead"
    },
    {
      "x": -1,
      "y": 32,
      "z": 1,
      "name": "Plant_Leaves_Dead"
    },
    {
      "x": -1,
      "y": 34,
      "z": 1,
      "name": "Plant_Leaves_Dead"
    },
    {
      "x": -1,
      "y": 35,
      "z": 1,
      "name": "Plant_Leaves_Dead"
    },
    {
      "x": -1,
      "y": 38,
      "z": 1,
      "name": "Plant_Leaves_Dead"
    },
    {
      "x": -1,
      "y": 40,
      "z": 1,
      "name": "Plant_Leaves_Dead"
    },
    {
      "x": -1,
      "y": 43,
      "z": 1,
      "name": "Plant_Leaves_Dead"
    },
    {
      "x": -1,
      "y": 44,
      "z": 1,
      "name": "Plant_Leaves_Dead"
    },
    {
      "x": -1,
      "y": 45,
      "z": 1,
      "name": "Plant_Leaves_Dead"
    },
    {
      "x": -1,
      "y": 46,
      "z": 1,
      "name": "Plant_Leaves_Dead"
    },
    {
      "x": -1,
      "y": 28,
      "z": 2,
      "name": "Plant_Leaves_Dead"
    },
    {
      "x": -1,
      "y": 29,
      "z": 2,
      "name": "Plant_Leaves_Dead"
    },
    {
      "x": -1,
      "y": 32,
      "z": 2,
      "name": "Plant_Leaves_Dead"
    },
    {
      "x": -1,
      "y": 38,
      "z": 2,
      "name": "Plant_Leaves_Dead"
    },
    {
      "x": -1,
      "y": 45,
      "z": 2,
      "name": "Plant_Leaves_Dead"
    },
    {
      "x": -1,
      "y": 28,
      "z": 3,
      "name": "Plant_Leaves_Dead"
    },
    {
      "x": -1,
      "y": 32,
      "z": 3,
      "name": "Plant_Leaves_Dead"
    },
    {
      "x": -1,
      "y": 28,
      "z": 4,
      "name": "Plant_Leaves_Dead"
    },
    {
      "x": -1,
      "y": 32,
      "z": 4,
      "name": "Plant_Leaves_Dead"
    },
    {
      "x": -1,
      "y": 28,
      "z": 5,
      "name": "Plant_Leaves_Dead"
    },
    {
      "x": 0,
      "y": 25,
      "z": -11,
      "name": "Plant_Leaves_Dead"
    },
    {
      "x": 0,
      "y": 25,
      "z": -10,
      "name": "Plant_Leaves_Dead"
    },
    {
      "x": 0,
      "y": 26,
      "z": -10,
      "name": "Plant_Leaves_Dead"
    },
    {
      "x": 0,
      "y": 26,
      "z": -9,
      "name": "Plant_Leaves_Dead"
    },
    {
      "x": 0,
      "y": 27,
      "z": -9,
      "name": "Plant_Leaves_Dead"
    },
    {
      "x": 0,
      "y": 31,
      "z": -9,
      "name": "Plant_Leaves_Dead"
    },
    {
      "x": 0,
      "y": 26,
      "z": -8,
      "name": "Plant_Leaves_Dead"
    },
    {
      "x": 0,
      "y": 27,
      "z": -8,
      "name": "Plant_Leaves_Dead"
    },
    {
      "x": 0,
      "y": 30,
      "z": -8,
      "name": "Plant_Leaves_Dead"
    },
    {
      "x": 0,
      "y": 31,
      "z": -8,
      "name": "Plant_Leaves_Dead"
    },
    {
      "x": 0,
      "y": 34,
      "z": -8,
      "name": "Plant_Leaves_Dead"
    },
    {
      "x": 0,
      "y": 26,
      "z": -7,
      "name": "Plant_Leaves_Dead"
    },
    {
      "x": 0,
      "y": 27,
      "z": -7,
      "name": "Plant_Leaves_Dead"
    },
    {
      "x": 0,
      "y": 30,
      "z": -7,
      "name": "Plant_Leaves_Dead"
    },
    {
      "x": 0,
      "y": 34,
      "z": -7,
      "name": "Plant_Leaves_Dead"
    },
    {
      "x": 0,
      "y": 37,
      "z": -7,
      "name": "Plant_Leaves_Dead"
    },
    {
      "x": 0,
      "y": 27,
      "z": -6,
      "name": "Wood_Fir_Branch_Corner",
      "rotation": 2
    },
    {
      "x": 0,
      "y": 28,
      "z": -6,
      "name": "Plant_Leaves_Dead"
    },
    {
      "x": 0,
      "y": 30,
      "z": -6,
      "name": "Wood_Fir_Branch_Corner",
      "rotation": 2
    },
    {
      "x": 0,
      "y": 34,
      "z": -6,
      "name": "Plant_Leaves_Dead"
    },
    {
      "x": 0,
      "y": 37,
      "z": -6,
      "name": "Plant_Leaves_Dead"
    },
    {
      "x": 0,
      "y": 42,
      "z": -6,
      "name": "Plant_Leaves_Dead"
    },
    {
      "x": 0,
      "y": 27,
      "z": -5,
      "name": "Wood_Fir_Branch_Long",
      "rotation": 4
    },
    {
      "x": 0,
      "y": 28,
      "z": -5,
      "name": "Plant_Leaves_Dead"
    },
    {
      "x": 0,
      "y": 30,
      "z": -5,
      "name": "Wood_Fir_Branch_Long",
      "rotation": 4
    },
    {
      "x": 0,
      "y": 31,
      "z": -5,
      "name": "Plant_Leaves_Dead"
    },
    {
      "x": 0,
      "y": 34,
      "z": -5,
      "name": "Plant_Leaves_Dead"
    },
    {
      "x": 0,
      "y": 37,
      "z": -5,
      "name": "Plant_Leaves_Dead"
    },
    {
      "x": 0,
      "y": 41,
      "z": -5,
      "name": "Plant_Leaves_Dead"
    },
    {
      "x": 0,
      "y": 44,
      "z": -5,
      "name": "Plant_Leaves_Dead"
    },
    {
      "x": 0,
      "y": 26,
      "z": -4,
      "name": "Plant_Leaves_Dead"
    },
    {
      "x": 0,
      "y": 27,
      "z": -4,
      "name": "Wood_Fir_Branch_Long",
      "rotation": 4
    },
    {
      "x": 0,
      "y": 28,
      "z": -4,
      "name": "Plant_Leaves_Dead"
    },
    {
      "x": 0,
      "y": 29,
      "z": -4,
      "name": "Plant_Leaves_Dead"
    },
    {
      "x": 0,
      "y": 30,
      "z": -4,
      "name": "Wood_Fir_Branch_Long",
      "rotation": 4
    },
    {
      "x": 0,
      "y": 31,
      "z": -4,
      "name": "Plant_Leaves_Dead"
    },
    {
      "x": 0,
      "y": 33,
      "z": -4,
      "name": "Plant_Leaves_Dead"
    },
    {
      "x": 0,
      "y": 34,
      "z": -4,
      "name": "Wood_Fir_Branch_Long",
      "rotation": 4
    },
    {
      "x": 0,
      "y": 36,
      "z": -4,
      "name": "Plant_Leaves_Dead"
    },
    {
      "x": 0,
      "y": 37,
      "z": -4,
      "name": "Plant_Leaves_Dead"
    },
    {
      "x": 0,
      "y": 39,
      "z": -4,
      "name": "Plant_Leaves_Dead"
    },
    {
      "x": 0,
      "y": 41,
      "z": -4,
      "name": "Plant_Leaves_Dead"
    },
    {
      "x": 0,
      "y": 43,
      "z": -4,
      "name": "Plant_Leaves_Dead"
    },
    {
      "x": 0,
      "y": 11,
      "z": -3,
      "name": "Wood_Fir_Trunk"
    },
    {
      "x": 0,
      "y": 12,
      "z": -3,
      "name": "Wood_Fir_Trunk"
    },
    {
      "x": 0,
      "y": 13,
      "z": -3,
      "name": "Wood_Fir_Trunk"
    },
    {
      "x": 0,
      "y": 14,
      "z": -3,
      "name": "Wood_Fir_Trunk"
    },
    {
      "x": 0,
      "y": 15,
      "z": -3,
      "name": "Wood_Fir_Trunk"
    },
    {
      "x": 0,
      "y": 16,
      "z": -3,
      "name": "Wood_Fir_Trunk"
    },
    {
      "x": 0,
      "y": 17,
      "z": -3,
      "name": "Wood_Fir_Trunk"
    },
    {
      "x": 0,
      "y": 18,
      "z": -3,
      "name": "Wood_Fir_Trunk"
    },
    {
      "x": 0,
      "y": 19,
      "z": -3,
      "name": "Wood_Fir_Trunk"
    },
    {
      "x": 0,
      "y": 20,
      "z": -3,
      "name": "Wood_Fir_Trunk"
    },
    {
      "x": 0,
      "y": 21,
      "z": -3,
      "name": "Wood_Fir_Trunk"
    },
    {
      "x": 0,
      "y": 22,
      "z": -3,
      "name": "Wood_Fir_Trunk"
    },
    {
      "x": 0,
      "y": 23,
      "z": -3,
      "name": "Wood_Fir_Trunk"
    },
    {
      "x": 0,
      "y": 24,
      "z": -3,
      "name": "Wood_Fir_Trunk"
    },
    {
      "x": 0,
      "y": 25,
      "z": -3,
      "name": "Wood_Fir_Trunk"
    },
    {
      "x": 0,
      "y": 26,
      "z": -3,
      "name": "Wood_Fir_Trunk"
    },
    {
      "x": 0,
      "y": 27,
      "z": -3,
      "name": "Wood_Fir_Trunk"
    },
    {
      "x": 0,
      "y": 28,
      "z": -3,
      "name": "Wood_Fir_Trunk"
    },
    {
      "x": 0,
      "y": 29,
      "z": -3,
      "name": "Wood_Fir_Trunk"
    },
    {
      "x": 0,
      "y": 30,
      "z": -3,
      "name": "Wood_Fir_Trunk"
    },
    {
      "x": 0,
      "y": 31,
      "z": -3,
      "name": "Wood_Fir_Trunk"
    },
    {
      "x": 0,
      "y": 32,
      "z": -3,
      "name": "Wood_Fir_Trunk"
    },
    {
      "x": 0,
      "y": 33,
      "z": -3,
      "name": "Wood_Fir_Trunk"
    },
    {
      "x": 0,
      "y": 34,
      "z": -3,
      "name": "Wood_Fir_Branch_Long",
      "rotation": 4
    },
    {
      "x": 0,
      "y": 36,
      "z": -3,
      "name": "Plant_Leaves_Dead"
    },
    {
      "x": 0,
      "y": 37,
      "z": -3,
      "name": "Wood_Fir_Branch_Long",
      "rotation": 4
    },
    {
      "x": 0,
      "y": 39,
      "z": -3,
      "name": "Plant_Leaves_Dead"
    },
    {
      "x": 0,
      "y": 41,
      "z": -3,
      "name": "Wood_Fir_Branch_Long",
      "rotation": 4
    },
    {
      "x": 0,
      "y": 43,
      "z": -3,
      "name": "Wood_Fir_Branch_Long",
      "rotation": 4
    },
    {
      "x": 0,
      "y": 45,
      "z": -3,
      "name": "Plant_Leaves_Dead"
    },
    {
      "x": 0,
      "y": 46,
      "z": -3,
      "name": "Plant_Leaves_Dead"
    },
    {
      "x": 0,
      "y": 13,
      "z": -2,
      "name": "Wood_Fir_Trunk"
    },
    {
      "x": 0,
      "y": 14,
      "z": -2,
      "name": "Wood_Fir_Trunk"
    },
    {
      "x": 0,
      "y": 15,
      "z": -2,
      "name": "Wood_Fir_Trunk"
    },
    {
      "x": 0,
      "y": 16,
      "z": -2,
      "name": "Wood_Fir_Trunk"
    },
    {
      "x": 0,
      "y": 17,
      "z": -2,
      "name": "Wood_Fir_Trunk"
    },
    {
      "x": 0,
      "y": 18,
      "z": -2,
      "name": "Wood_Fir_Trunk"
    },
    {
      "x": 0,
      "y": 19,
      "z": -2,
      "name": "Wood_Fir_Trunk"
    },
    {
      "x": 0,
      "y": 20,
      "z": -2,
      "name": "Wood_Fir_Trunk"
    },
    {
      "x": 0,
      "y": 21,
      "z": -2,
      "name": "Wood_Fir_Trunk"
    },
    {
      "x": 0,
      "y": 22,
      "z": -2,
      "name": "Wood_Fir_Trunk"
    },
    {
      "x": 0,
      "y": 23,
      "z": -2,
      "name": "Wood_Fir_Trunk"
    },
    {
      "x": 0,
      "y": 24,
      "z": -2,
      "name": "Wood_Fir_Trunk"
    },
    {
      "x": 0,
      "y": 25,
      "z": -2,
      "name": "Wood_Fir_Trunk"
    },
    {
      "x": 0,
      "y": 26,
      "z": -2,
      "name": "Wood_Fir_Trunk"
    },
    {
      "x": 0,
      "y": 27,
      "z": -2,
      "name": "Wood_Fir_Trunk"
    },
    {
      "x": 0,
      "y": 28,
      "z": -2,
      "name": "Wood_Fir_Trunk"
    },
    {
      "x": 0,
      "y": 29,
      "z": -2,
      "name": "Wood_Fir_Trunk"
    },
    {
      "x": 0,
      "y": 30,
      "z": -2,
      "name": "Wood_Fir_Trunk"
    },
    {
      "x": 0,
      "y": 31,
      "z": -2,
      "name": "Wood_Fir_Trunk"
    },
    {
      "x": 0,
      "y": 32,
      "z": -2,
      "name": "Wood_Fir_Trunk"
    },
    {
      "x": 0,
      "y": 33,
      "z": -2,
      "name": "Wood_Fir_Trunk"
    },
    {
      "x": 0,
      "y": 34,
      "z": -2,
      "name": "Wood_Fir_Trunk"
    },
    {
      "x": 0,
      "y": 35,
      "z": -2,
      "name": "Wood_Fir_Trunk"
    },
    {
      "x": 0,
      "y": 36,
      "z": -2,
      "name": "Wood_Fir_Trunk"
    },
    {
      "x": 0,
      "y": 37,
      "z": -2,
      "name": "Wood_Fir_Trunk"
    },
    {
      "x": 0,
      "y": 38,
      "z": -2,
      "name": "Wood_Fir_Trunk"
    },
    {
      "x": 0,
      "y": 39,
      "z": -2,
      "name": "Wood_Fir_Trunk"
    },
    {
      "x": 0,
      "y": 40,
      "z": -2,
      "name": "Wood_Fir_Trunk"
    },
    {
      "x": 0,
      "y": 41,
      "z": -2,
      "name": "Wood_Fir_Trunk"
    },
    {
      "x": 0,
      "y": 42,
      "z": -2,
      "name": "Wood_Fir_Trunk"
    },
    {
      "x": 0,
      "y": 43,
      "z": -2,
      "name": "Wood_Fir_Trunk"
    },
    {
      "x": 0,
      "y": 44,
      "z": -2,
      "name": "Wood_Fir_Trunk"
    },
    {
      "x": 0,
      "y": 45,
      "z": -2,
      "name": "Wood_Fir_Trunk"
    },
    {
      "x": 0,
      "y": 46,
      "z": -2,
      "name": "Wood_Fir_Trunk"
    },
    {
      "x": 0,
      "y": 47,
      "z": -2,
      "name": "Plant_Leaves_Dead"
    },
    {
      "x": 0,
      "y": 48,
      "z": -2,
      "name": "Plant_Leaves_Dead"
    },
    {
      "x": 0,
      "y": 49,
      "z": -2,
      "name": "Plant_Leaves_Dead"
    },
    {
      "x": 0,
      "y": 50,
      "z": -2,
      "name": "Plant_Leaves_Dead"
    },
    {
      "x": 0,
      "y": 51,
      "z": -2,
      "name": "Plant_Leaves_Dead"
    },
    {
      "x": 0,
      "y": 52,
      "z": -2,
      "name": "Plant_Leaves_Dead"
    },
    {
      "x": 0,
      "y": 14,
      "z": -1,
      "name": "Wood_Fir_Trunk"
    },
    {
      "x": 0,
      "y": 15,
      "z": -1,
      "name": "Wood_Fir_Trunk"
    },
    {
      "x": 0,
      "y": 16,
      "z": -1,
      "name": "Wood_Fir_Trunk"
    },
    {
      "x": 0,
      "y": 17,
      "z": -1,
      "name": "Wood_Fir_Trunk"
    },
    {
      "x": 0,
      "y": 18,
      "z": -1,
      "name": "Wood_Fir_Trunk"
    },
    {
      "x": 0,
      "y": 19,
      "z": -1,
      "name": "Wood_Fir_Trunk"
    },
    {
      "x": 0,
      "y": 20,
      "z": -1,
      "name": "Wood_Fir_Trunk"
    },
    {
      "x": 0,
      "y": 21,
      "z": -1,
      "name": "Wood_Fir_Trunk"
    },
    {
      "x": 0,
      "y": 22,
      "z": -1,
      "name": "Wood_Fir_Trunk"
    },
    {
      "x": 0,
      "y": 23,
      "z": -1,
      "name": "Wood_Fir_Trunk"
    },
    {
      "x": 0,
      "y": 24,
      "z": -1,
      "name": "Wood_Fir_Trunk"
    },
    {
      "x": 0,
      "y": 25,
      "z": -1,
      "name": "Wood_Fir_Trunk"
    },
    {
      "x": 0,
      "y": 26,
      "z": -1,
      "name": "Wood_Fir_Trunk"
    },
    {
      "x": 0,
      "y": 27,
      "z": -1,
      "name": "Wood_Fir_Trunk"
    },
    {
      "x": 0,
      "y": 28,
      "z": -1,
      "name": "Wood_Fir_Trunk"
    },
    {
      "x": 0,
      "y": 29,
      "z": -1,
      "name": "Wood_Fir_Trunk"
    },
    {
      "x": 0,
      "y": 30,
      "z": -1,
      "name": "Wood_Fir_Trunk"
    },
    {
      "x": 0,
      "y": 31,
      "z": -1,
      "name": "Wood_Fir_Trunk"
    },
    {
      "x": 0,
      "y": 32,
      "z": -1,
      "name": "Wood_Fir_Trunk"
    },
    {
      "x": 0,
      "y": 33,
      "z": -1,
      "name": "Wood_Fir_Trunk"
    },
    {
      "x": 0,
      "y": 34,
      "z": -1,
      "name": "Wood_Fir_Trunk"
    },
    {
      "x": 0,
      "y": 35,
      "z": -1,
      "name": "Wood_Fir_Trunk"
    },
    {
      "x": 0,
      "y": 36,
      "z": -1,
      "name": "Wood_Fir_Trunk"
    },
    {
      "x": 0,
      "y": 37,
      "z": -1,
      "name": "Wood_Fir_Trunk"
    },
    {
      "x": 0,
      "y": 38,
      "z": -1,
      "name": "Wood_Fir_Trunk"
    },
    {
      "x": 0,
      "y": 39,
      "z": -1,
      "name": "Wood_Fir_Trunk"
    },
    {
      "x": 0,
      "y": 40,
      "z": -1,
      "name": "Wood_Fir_Trunk"
    },
    {
      "x": 0,
      "y": 41,
      "z": -1,
      "name": "Wood_Fir_Trunk"
    },
    {
      "x": 0,
      "y": 42,
      "z": -1,
      "name": "Wood_Fir_Trunk"
    },
    {
      "x": 0,
      "y": 43,
      "z": -1,
      "name": "Wood_Fir_Trunk"
    },
    {
      "x": 0,
      "y": 44,
      "z": -1,
      "name": "Wood_Fir_Trunk"
    },
    {
      "x": 0,
      "y": 45,
      "z": -1,
      "name": "Wood_Fir_Trunk"
    },
    {
      "x": 0,
      "y": 46,
      "z": -1,
      "name": "Wood_Fir_Trunk"
    },
    {
      "x": 0,
      "y": 47,
      "z": -1,
      "name": "Plant_Leaves_Dead"
    },
    {
      "x": 0,
      "y": 48,
      "z": -1,
      "name": "Plant_Leaves_Dead"
    },
    {
      "x": 0,
      "y": 49,
      "z": -1,
      "name": "Plant_Leaves_Dead"
    },
    {
      "x": 0,
      "y": 50,
      "z": -1,
      "name": "Plant_Leaves_Dead"
    },
    {
      "x": 0,
      "y": 51,
      "z": -1,
      "name": "Plant_Leaves_Dead"
    },
    {
      "x": 0,
      "y": 52,
      "z": -1,
      "name": "Plant_Leaves_Dead"
    },
    {
      "x": 0,
      "y": 53,
      "z": -1,
      "name": "Plant_Leaves_Dead"
    },
    {
      "x": 0,
      "y": 54,
      "z": -1,
      "name": "Plant_Leaves_Dead"
    },
    {
      "x": 0,
      "y": 55,
      "z": -1,
      "name": "Plant_Leaves_Dead"
    },
    {
      "x": 0,
      "y": 56,
      "z": -1,
      "name": "Plant_Leaves_Dead"
    },
    {
      "x": 0,
      "y": 57,
      "z": -1,
      "name": "Plant_Leaves_Dead"
    },
    {
      "x": 0,
      "y": 13,
      "z": 0,
      "name": "Wood_Fir_Trunk"
    },
    {
      "x": 0,
      "y": 14,
      "z": 0,
      "name": "Wood_Fir_Trunk"
    },
    {
      "x": 0,
      "y": 15,
      "z": 0,
      "name": "Wood_Fir_Trunk"
    },
    {
      "x": 0,
      "y": 16,
      "z": 0,
      "name": "Wood_Fir_Trunk"
    },
    {
      "x": 0,
      "y": 17,
      "z": 0,
      "name": "Wood_Fir_Trunk"
    },
    {
      "x": 0,
      "y": 18,
      "z": 0,
      "name": "Wood_Fir_Trunk"
    },
    {
      "x": 0,
      "y": 19,
      "z": 0,
      "name": "Wood_Fir_Trunk"
    },
    {
      "x": 0,
      "y": 20,
      "z": 0,
      "name": "Wood_Fir_Trunk"
    },
    {
      "x": 0,
      "y": 21,
      "z": 0,
      "name": "Wood_Fir_Trunk"
    },
    {
      "x": 0,
      "y": 22,
      "z": 0,
      "name": "Wood_Fir_Trunk"
    },
    {
      "x": 0,
      "y": 23,
      "z": 0,
      "name": "Wood_Fir_Trunk"
    },
    {
      "x": 0,
      "y": 24,
      "z": 0,
      "name": "Wood_Fir_Trunk"
    },
    {
      "x": 0,
      "y": 25,
      "z": 0,
      "name": "Wood_Fir_Trunk"
    },
    {
      "x": 0,
      "y": 26,
      "z": 0,
      "name": "Wood_Fir_Trunk"
    },
    {
      "x": 0,
      "y": 27,
      "z": 0,
      "name": "Wood_Fir_Trunk"
    },
    {
      "x": 0,
      "y": 28,
      "z": 0,
      "name": "Wood_Fir_Branch_Long",
      "rotation": 4
    },
    {
      "x": 0,
      "y": 29,
      "z": 0,
      "name": "Wood_Fir_Trunk"
    },
    {
      "x": 0,
      "y": 30,
      "z": 0,
      "name": "Wood_Fir_Trunk"
    },
    {
      "x": 0,
      "y": 31,
      "z": 0,
      "name": "Wood_Fir_Trunk"
    },
    {
      "x": 0,
      "y": 32,
      "z": 0,
      "name": "Wood_Fir_Trunk"
    },
    {
      "x": 0,
      "y": 33,
      "z": 0,
      "name": "Wood_Fir_Trunk"
    },
    {
      "x": 0,
      "y": 34,
      "z": 0,
      "name": "Wood_Fir_Trunk"
    },
    {
      "x": 0,
      "y": 35,
      "z": 0,
      "name": "Wood_Fir_Trunk"
    },
    {
      "x": 0,
      "y": 36,
      "z": 0,
      "name": "Wood_Fir_Trunk"
    },
    {
      "x": 0,
      "y": 37,
      "z": 0,
      "name": "Wood_Fir_Trunk"
    },
    {
      "x": 0,
      "y": 38,
      "z": 0,
      "name": "Wood_Fir_Trunk"
    },
    {
      "x": 0,
      "y": 39,
      "z": 0,
      "name": "Wood_Fir_Trunk"
    },
    {
      "x": 0,
      "y": 40,
      "z": 0,
      "name": "Wood_Fir_Trunk"
    },
    {
      "x": 0,
      "y": 41,
      "z": 0,
      "name": "Wood_Fir_Trunk"
    },
    {
      "x": 0,
      "y": 42,
      "z": 0,
      "name": "Wood_Fir_Trunk"
    },
    {
      "x": 0,
      "y": 43,
      "z": 0,
      "name": "Wood_Fir_Trunk"
    },
    {
      "x": 0,
      "y": 44,
      "z": 0,
      "name": "Wood_Fir_Trunk"
    },
    {
      "x": 0,
      "y": 45,
      "z": 0,
      "name": "Wood_Fir_Trunk"
    },
    {
      "x": 0,
      "y": 46,
      "z": 0,
      "name": "Wood_Fir_Trunk"
    },
    {
      "x": 0,
      "y": 47,
      "z": 0,
      "name": "Plant_Leaves_Dead"
    },
    {
      "x": 0,
      "y": 48,
      "z": 0,
      "name": "Plant_Leaves_Dead"
    },
    {
      "x": 0,
      "y": 49,
      "z": 0,
      "name": "Plant_Leaves_Dead"
    },
    {
      "x": 0,
      "y": 50,
      "z": 0,
      "name": "Plant_Leaves_Dead"
    },
    {
      "x": 0,
      "y": 11,
      "z": 1,
      "name": "Wood_Fir_Trunk"
    },
    {
      "x": 0,
      "y": 12,
      "z": 1,
      "name": "Wood_Fir_Trunk"
    },
    {
      "x": 0,
      "y": 13,
      "z": 1,
      "name": "Wood_Fir_Trunk"
    },
    {
      "x": 0,
      "y": 14,
      "z": 1,
      "name": "Wood_Fir_Trunk"
    },
    {
      "x": 0,
      "y": 15,
      "z": 1,
      "name": "Wood_Fir_Trunk"
    },
    {
      "x": 0,
      "y": 16,
      "z": 1,
      "name": "Wood_Fir_Trunk"
    },
    {
      "x": 0,
      "y": 17,
      "z": 1,
      "name": "Wood_Fir_Trunk"
    },
    {
      "x": 0,
      "y": 18,
      "z": 1,
      "name": "Wood_Fir_Trunk"
    },
    {
      "x": 0,
      "y": 19,
      "z": 1,
      "name": "Wood_Fir_Trunk"
    },
    {
      "x": 0,
      "y": 20,
      "z": 1,
      "name": "Wood_Fir_Trunk"
    },
    {
      "x": 0,
      "y": 21,
      "z": 1,
      "name": "Wood_Fir_Trunk"
    },
    {
      "x": 0,
      "y": 22,
      "z": 1,
      "name": "Wood_Fir_Trunk"
    },
    {
      "x": 0,
      "y": 23,
      "z": 1,
      "name": "Wood_Fir_Trunk"
    },
    {
      "x": 0,
      "y": 27,
      "z": 1,
      "name": "Plant_Leaves_Dead"
    },
    {
      "x": 0,
      "y": 28,
      "z": 1,
      "name": "Wood_Fir_Branch_Long",
      "rotation": 4
    },
    {
      "x": 0,
      "y": 29,
      "z": 1,
      "name": "Plant_Leaves_Dead"
    },
    {
      "x": 0,
      "y": 30,
      "z": 1,
      "name": "Plant_Leaves_Dead"
    },
    {
      "x": 0,
      "y": 31,
      "z": 1,
      "name": "Plant_Leaves_Dead"
    },
    {
      "x": 0,
      "y": 32,
      "z": 1,
      "name": "Wood_Fir_Branch_Long",
      "rotation": 4
    },
    {
      "x": 0,
      "y": 34,
      "z": 1,
      "name": "Plant_Leaves_Dead"
    },
    {
      "x": 0,
      "y": 35,
      "z": 1,
      "name": "Plant_Leaves_Dead"
    },
    {
      "x": 0,
      "y": 36,
      "z": 1,
      "name": "Plant_Leaves_Dead"
    },
    {
      "x": 0,
      "y": 38,
      "z": 1,
      "name": "Wood_Fir_Branch_Long",
      "rotation": 4
    },
    {
      "x": 0,
      "y": 40,
      "z": 1,
      "name": "Wood_Fir_Branch_Long",
      "rotation": 4
    },
    {
      "x": 0,
      "y": 43,
      "z": 1,
      "name": "Wood_Fir_Branch_Long",
      "rotation": 4
    },
    {
      "x": 0,
      "y": 45,
      "z": 1,
      "name": "Wood_Fir_Branch_Long",
      "rotation": 4
    },
    {
      "x": 0,
      "y": 46,
      "z": 1,
      "name": "Plant_Leaves_Dead"
    },
    {
      "x": 0,
      "y": 47,
      "z": 1,
      "name": "Plant_Leaves_Dead"
    },
    {
      "x": 0,
      "y": 27,
      "z": 2,
      "name": "Plant_Leaves_Dead"
    },
    {
      "x": 0,
      "y": 28,
      "z": 2,
      "name": "Wood_Fir_Branch_Long",
      "rotation": 4
    },
    {
      "x": 0,
      "y": 29,
      "z": 2,
      "name": "Plant_Leaves_Dead"
    },
    {
      "x": 0,
      "y": 31,
      "z": 2,
      "name": "Plant_Leaves_Dead"
    },
    {
      "x": 0,
      "y": 32,
      "z": 2,
      "name": "Wood_Fir_Branch_Long",
      "rotation": 4
    },
    {
      "x": 0,
      "y": 35,
      "z": 2,
      "name": "Plant_Leaves_Dead"
    },
    {
      "x": 0,
      "y": 38,
      "z": 2,
      "name": "Wood_Fir_Branch_Long",
      "rotation": 4
    },
    {
      "x": 0,
      "y": 40,
      "z": 2,
      "name": "Plant_Leaves_Dead"
    },
    {
      "x": 0,
      "y": 43,
      "z": 2,
      "name": "Plant_Leaves_Dead"
    },
    {
      "x": 0,
      "y": 45,
      "z": 2,
      "name": "Plant_Leaves_Dead"
    },
    {
      "x": 0,
      "y": 27,
      "z": 3,
      "name": "Plant_Leaves_Dead"
    },
    {
      "x": 0,
      "y": 28,
      "z": 3,
      "name": "Wood_Fir_Branch_Corner"
    },
    {
      "x": 0,
      "y": 29,
      "z": 3,
      "name": "Plant_Leaves_Dead"
    },
    {
      "x": 0,
      "y": 32,
      "z": 3,
      "name": "Wood_Fir_Branch_Long",
      "rotation": 4
    },
    {
      "x": 0,
      "y": 35,
      "z": 3,
      "name": "Plant_Leaves_Dead"
    },
    {
      "x": 0,
      "y": 38,
      "z": 3,
      "name": "Plant_Leaves_Dead"
    },
    {
      "x": 0,
      "y": 40,
      "z": 3,
      "name": "Plant_Leaves_Dead"
    },
    {
      "x": 0,
      "y": 43,
      "z": 3,
      "name": "Plant_Leaves_Dead"
    },
    {
      "x": 0,
      "y": 46,
      "z": 3,
      "name": "Plant_Leaves_Dead"
    },
    {
      "x": 0,
      "y": 32,
      "z": 4,
      "name": "Plant_Leaves_Dead"
    },
    {
      "x": 0,
      "y": 38,
      "z": 4,
      "name": "Plant_Leaves_Dead"
    },
    {
      "x": 0,
      "y": 41,
      "z": 4,
      "name": "Plant_Leaves_Dead"
    },
    {
      "x": 0,
      "y": 44,
      "z": 4,
      "name": "Plant_Leaves_Dead"
    },
    {
      "x": 0,
      "y": 28,
      "z": 5,
      "name": "Plant_Leaves_Dead"
    },
    {
      "x": 0,
      "y": 32,
      "z": 5,
      "name": "Plant_Leaves_Dead"
    },
    {
      "x": 0,
      "y": 38,
      "z": 5,
      "name": "Plant_Leaves_Dead"
    },
    {
      "x": 0,
      "y": 39,
      "z": 5,
      "name": "Plant_Leaves_Dead"
    },
    {
      "x": 0,
      "y": 28,
      "z": 6,
      "name": "Plant_Leaves_Dead"
    },
    {
      "x": 0,
      "y": 32,
      "z": 6,
      "name": "Plant_Leaves_Dead"
    },
    {
      "x": 0,
      "y": 33,
      "z": 6,
      "name": "Plant_Leaves_Dead"
    },
    {
      "x": 0,
      "y": 39,
      "z": 6,
      "name": "Plant_Leaves_Dead"
    },
    {
      "x": 0,
      "y": 28,
      "z": 7,
      "name": "Plant_Leaves_Dead"
    },
    {
      "x": 0,
      "y": 33,
      "z": 7,
      "name": "Plant_Leaves_Dead"
    },
    {
      "x": 0,
      "y": 29,
      "z": 8,
      "name": "Plant_Leaves_Dead"
    },
    {
      "x": 0,
      "y": 30,
      "z": 9,
      "name": "Plant_Leaves_Dead"
    },
    {
      "x": 1,
      "y": 27,
      "z": -8,
      "name": "Plant_Leaves_Dead"
    },
    {
      "x": 1,
      "y": 27,
      "z": -7,
      "name": "Plant_Leaves_Dead"
    },
    {
      "x": 1,
      "y": 30,
      "z": -7,
      "name": "Plant_Leaves_Dead"
    },
    {
      "x": 1,
      "y": 27,
      "z": -6,
      "name": "Plant_Leaves_Dead"
    },
    {
      "x": 1,
      "y": 30,
      "z": -6,
      "name": "Plant_Leaves_Dead"
    },
    {
      "x": 1,
      "y": 39,
      "z": -6,
      "name": "Plant_Leaves_Dead"
    },
    {
      "x": 1,
      "y": 27,
      "z": -5,
      "name": "Plant_Leaves_Dead"
    },
    {
      "x": 1,
      "y": 30,
      "z": -5,
      "name": "Plant_Leaves_Dead"
    },
    {
      "x": 1,
      "y": 39,
      "z": -5,
      "name": "Plant_Leaves_Dead"
    },
    {
      "x": 1,
      "y": 27,
      "z": -4,
      "name": "Plant_Leaves_Dead"
    },
    {
      "x": 1,
      "y": 28,
      "z": -4,
      "name": "Plant_Leaves_Dead"
    },
    {
      "x": 1,
      "y": 29,
      "z": -4,
      "name": "Plant_Leaves_Dead"
    },
    {
      "x": 1,
      "y": 30,
      "z": -4,
      "name": "Plant_Leaves_Dead"
    },
    {
      "x": 1,
      "y": 31,
      "z": -4,
      "name": "Plant_Leaves_Dead"
    },
    {
      "x": 1,
      "y": 34,
      "z": -4,
      "name": "Plant_Leaves_Dead"
    },
    {
      "x": 1,
      "y": 37,
      "z": -4,
      "name": "Plant_Leaves_Dead"
    },
    {
      "x": 1,
      "y": 39,
      "z": -4,
      "name": "Plant_Leaves_Dead"
    },
    {
      "x": 1,
      "y": 41,
      "z": -4,
      "name": "Plant_Leaves_Dead"
    },
    {
      "x": 1,
      "y": 10,
      "z": -3,
      "name": "Wood_Fir_Trunk"
    },
    {
      "x": 1,
      "y": 11,
      "z": -3,
      "name": "Wood_Fir_Trunk"
    },
    {
      "x": 1,
      "y": 12,
      "z": -3,
      "name": "Wood_Fir_Trunk"
    },
    {
      "x": 1,
      "y": 13,
      "z": -3,
      "name": "Wood_Fir_Trunk"
    },
    {
      "x": 1,
      "y": 14,
      "z": -3,
      "name": "Wood_Fir_Trunk"
    },
    {
      "x": 1,
      "y": 15,
      "z": -3,
      "name": "Wood_Fir_Trunk"
    },
    {
      "x": 1,
      "y": 16,
      "z": -3,
      "name": "Wood_Fir_Trunk_Full"
    },
    {
      "x": 1,
      "y": 29,
      "z": -3,
      "name": "Plant_Leaves_Dead"
    },
    {
      "x": 1,
      "y": 30,
      "z": -3,
      "name": "Plant_Leaves_Dead"
    },
    {
      "x": 1,
      "y": 31,
      "z": -3,
      "name": "Plant_Leaves_Dead"
    },
    {
      "x": 1,
      "y": 33,
      "z": -3,
      "name": "Plant_Leaves_Dead"
    },
    {
      "x": 1,
      "y": 34,
      "z": -3,
      "name": "Plant_Leaves_Dead"
    },
    {
      "x": 1,
      "y": 35,
      "z": -3,
      "name": "Plant_Leaves_Dead"
    },
    {
      "x": 1,
      "y": 37,
      "z": -3,
      "name": "Plant_Leaves_Dead"
    },
    {
      "x": 1,
      "y": 39,
      "z": -3,
      "name": "Wood_Fir_Branch_Long",
      "rotation": 4
    },
    {
      "x": 1,
      "y": 41,
      "z": -3,
      "name": "Plant_Leaves_Dead"
    },
    {
      "x": 1,
      "y": 42,
      "z": -3,
      "name": "Plant_Leaves_Dead"
    },
    {
      "x": 1,
      "y": 43,
      "z": -3,
      "name": "Plant_Leaves_Dead"
    },
    {
      "x": 1,
      "y": 10,
      "z": -2,
      "name": "Wood_Fir_Trunk"
    },
    {
      "x": 1,
      "y": 11,
      "z": -2,
      "name": "Wood_Fir_Trunk"
    },
    {
      "x": 1,
      "y": 12,
      "z": -2,
      "name": "Wood_Fir_Trunk"
    },
    {
      "x": 1,
      "y": 13,
      "z": -2,
      "name": "Wood_Fir_Trunk"
    },
    {
      "x": 1,
      "y": 14,
      "z": -2,
      "name": "Wood_Fir_Trunk"
    },
    {
      "x": 1,
      "y": 15,
      "z": -2,
      "name": "Wood_Fir_Trunk"
    },
    {
      "x": 1,
      "y": 16,
      "z": -2,
      "name": "Wood_Fir_Trunk"
    },
    {
      "x": 1,
      "y": 17,
      "z": -2,
      "name": "Wood_Fir_Trunk"
    },
    {
      "x": 1,
      "y": 18,
      "z": -2,
      "name": "Wood_Fir_Trunk"
    },
    {
      "x": 1,
      "y": 19,
      "z": -2,
      "name": "Wood_Fir_Trunk"
    },
    {
      "x": 1,
      "y": 20,
      "z": -2,
      "name": "Wood_Fir_Trunk"
    },
    {
      "x": 1,
      "y": 21,
      "z": -2,
      "name": "Wood_Fir_Trunk"
    },
    {
      "x": 1,
      "y": 22,
      "z": -2,
      "name": "Wood_Fir_Trunk"
    },
    {
      "x": 1,
      "y": 23,
      "z": -2,
      "name": "Wood_Fir_Trunk"
    },
    {
      "x": 1,
      "y": 24,
      "z": -2,
      "name": "Wood_Fir_Trunk"
    },
    {
      "x": 1,
      "y": 25,
      "z": -2,
      "name": "Wood_Fir_Trunk"
    },
    {
      "x": 1,
      "y": 26,
      "z": -2,
      "name": "Wood_Fir_Trunk"
    },
    {
      "x": 1,
      "y": 27,
      "z": -2,
      "name": "Wood_Fir_Trunk"
    },
    {
      "x": 1,
      "y": 28,
      "z": -2,
      "name": "Wood_Fir_Trunk"
    },
    {
      "x": 1,
      "y": 29,
      "z": -2,
      "name": "Wood_Fir_Trunk"
    },
    {
      "x": 1,
      "y": 30,
      "z": -2,
      "name": "Wood_Fir_Trunk"
    },
    {
      "x": 1,
      "y": 31,
      "z": -2,
      "name": "Wood_Fir_Trunk"
    },
    {
      "x": 1,
      "y": 32,
      "z": -2,
      "name": "Wood_Fir_Trunk"
    },
    {
      "x": 1,
      "y": 33,
      "z": -2,
      "name": "Wood_Fir_Trunk"
    },
    {
      "x": 1,
      "y": 34,
      "z": -2,
      "name": "Wood_Fir_Trunk"
    },
    {
      "x": 1,
      "y": 35,
      "z": -2,
      "name": "Wood_Fir_Trunk"
    },
    {
      "x": 1,
      "y": 36,
      "z": -2,
      "name": "Wood_Fir_Trunk"
    },
    {
      "x": 1,
      "y": 37,
      "z": -2,
      "name": "Wood_Fir_Trunk"
    },
    {
      "x": 1,
      "y": 38,
      "z": -2,
      "name": "Wood_Fir_Trunk"
    },
    {
      "x": 1,
      "y": 39,
      "z": -2,
      "name": "Wood_Fir_Trunk"
    },
    {
      "x": 1,
      "y": 40,
      "z": -2,
      "name": "Wood_Fir_Trunk"
    },
    {
      "x": 1,
      "y": 41,
      "z": -2,
      "name": "Wood_Fir_Trunk"
    },
    {
      "x": 1,
      "y": 42,
      "z": -2,
      "name": "Wood_Fir_Trunk"
    },
    {
      "x": 1,
      "y": 43,
      "z": -2,
      "name": "Wood_Fir_Trunk"
    },
    {
      "x": 1,
      "y": 44,
      "z": -2,
      "name": "Plant_Leaves_Dead"
    },
    {
      "x": 1,
      "y": 45,
      "z": -2,
      "name": "Plant_Leaves_Dead"
    },
    {
      "x": 1,
      "y": 46,
      "z": -2,
      "name": "Plant_Leaves_Dead"
    },
    {
      "x": 1,
      "y": 47,
      "z": -2,
      "name": "Plant_Leaves_Dead"
    },
    {
      "x": 1,
      "y": 12,
      "z": -1,
      "name": "Wood_Fir_Trunk"
    },
    {
      "x": 1,
      "y": 13,
      "z": -1,
      "name": "Wood_Fir_Trunk"
    },
    {
      "x": 1,
      "y": 14,
      "z": -1,
      "name": "Wood_Fir_Trunk"
    },
    {
      "x": 1,
      "y": 15,
      "z": -1,
      "name": "Wood_Fir_Trunk"
    },
    {
      "x": 1,
      "y": 16,
      "z": -1,
      "name": "Wood_Fir_Trunk"
    },
    {
      "x": 1,
      "y": 17,
      "z": -1,
      "name": "Wood_Fir_Trunk"
    },
    {
      "x": 1,
      "y": 18,
      "z": -1,
      "name": "Wood_Fir_Trunk"
    },
    {
      "x": 1,
      "y": 19,
      "z": -1,
      "name": "Wood_Fir_Trunk"
    },
    {
      "x": 1,
      "y": 20,
      "z": -1,
      "name": "Wood_Fir_Trunk"
    },
    {
      "x": 1,
      "y": 21,
      "z": -1,
      "name": "Wood_Fir_Trunk"
    },
    {
      "x": 1,
      "y": 22,
      "z": -1,
      "name": "Wood_Fir_Trunk"
    },
    {
      "x": 1,
      "y": 23,
      "z": -1,
      "name": "Wood_Fir_Trunk"
    },
    {
      "x": 1,
      "y": 24,
      "z": -1,
      "name": "Wood_Fir_Trunk"
    },
    {
      "x": 1,
      "y": 25,
      "z": -1,
      "name": "Wood_Fir_Trunk"
    },
    {
      "x": 1,
      "y": 26,
      "z": -1,
      "name": "Wood_Fir_Trunk"
    },
    {
      "x": 1,
      "y": 27,
      "z": -1,
      "name": "Wood_Fir_Trunk"
    },
    {
      "x": 1,
      "y": 28,
      "z": -1,
      "name": "Wood_Fir_Branch_Long",
      "rotation": 5
    },
    {
      "x": 1,
      "y": 29,
      "z": -1,
      "name": "Wood_Fir_Trunk"
    },
    {
      "x": 1,
      "y": 30,
      "z": -1,
      "name": "Wood_Fir_Trunk"
    },
    {
      "x": 1,
      "y": 31,
      "z": -1,
      "name": "Wood_Fir_Trunk"
    },
    {
      "x": 1,
      "y": 32,
      "z": -1,
      "name": "Wood_Fir_Trunk"
    },
    {
      "x": 1,
      "y": 33,
      "z": -1,
      "name": "Wood_Fir_Trunk"
    },
    {
      "x": 1,
      "y": 34,
      "z": -1,
      "name": "Wood_Fir_Trunk"
    },
    {
      "x": 1,
      "y": 35,
      "z": -1,
      "name": "Wood_Fir_Trunk"
    },
    {
      "x": 1,
      "y": 36,
      "z": -1,
      "name": "Wood_Fir_Trunk"
    },
    {
      "x": 1,
      "y": 37,
      "z": -1,
      "name": "Wood_Fir_Trunk"
    },
    {
      "x": 1,
      "y": 38,
      "z": -1,
      "name": "Wood_Fir_Trunk"
    },
    {
      "x": 1,
      "y": 39,
      "z": -1,
      "name": "Wood_Fir_Trunk"
    },
    {
      "x": 1,
      "y": 40,
      "z": -1,
      "name": "Wood_Fir_Trunk"
    },
    {
      "x": 1,
      "y": 41,
      "z": -1,
      "name": "Wood_Fir_Trunk"
    },
    {
      "x": 1,
      "y": 42,
      "z": -1,
      "name": "Wood_Fir_Trunk"
    },
    {
      "x": 1,
      "y": 43,
      "z": -1,
      "name": "Wood_Fir_Trunk"
    },
    {
      "x": 1,
      "y": 44,
      "z": -1,
      "name": "Wood_Fir_Trunk"
    },
    {
      "x": 1,
      "y": 45,
      "z": -1,
      "name": "Wood_Fir_Trunk"
    },
    {
      "x": 1,
      "y": 46,
      "z": -1,
      "name": "Wood_Fir_Trunk"
    },
    {
      "x": 1,
      "y": 47,
      "z": -1,
      "name": "Plant_Leaves_Dead"
    },
    {
      "x": 1,
      "y": 9,
      "z": 0,
      "name": "Wood_Fir_Trunk"
    },
    {
      "x": 1,
      "y": 10,
      "z": 0,
      "name": "Wood_Fir_Trunk"
    },
    {
      "x": 1,
      "y": 11,
      "z": 0,
      "name": "Wood_Fir_Trunk"
    },
    {
      "x": 1,
      "y": 12,
      "z": 0,
      "name": "Wood_Fir_Trunk"
    },
    {
      "x": 1,
      "y": 13,
      "z": 0,
      "name": "Wood_Fir_Trunk"
    },
    {
      "x": 1,
      "y": 14,
      "z": 0,
      "name": "Wood_Fir_Trunk"
    },
    {
      "x": 1,
      "y": 15,
      "z": 0,
      "name": "Wood_Fir_Trunk"
    },
    {
      "x": 1,
      "y": 16,
      "z": 0,
      "name": "Wood_Fir_Trunk"
    },
    {
      "x": 1,
      "y": 17,
      "z": 0,
      "name": "Wood_Fir_Trunk"
    },
    {
      "x": 1,
      "y": 18,
      "z": 0,
      "name": "Wood_Fir_Trunk"
    },
    {
      "x": 1,
      "y": 19,
      "z": 0,
      "name": "Wood_Fir_Trunk"
    },
    {
      "x": 1,
      "y": 20,
      "z": 0,
      "name": "Wood_Fir_Trunk"
    },
    {
      "x": 1,
      "y": 21,
      "z": 0,
      "name": "Wood_Fir_Trunk"
    },
    {
      "x": 1,
      "y": 22,
      "z": 0,
      "name": "Wood_Fir_Trunk"
    },
    {
      "x": 1,
      "y": 23,
      "z": 0,
      "name": "Wood_Fir_Trunk"
    },
    {
      "x": 1,
      "y": 24,
      "z": 0,
      "name": "Wood_Fir_Trunk"
    },
    {
      "x": 1,
      "y": 25,
      "z": 0,
      "name": "Wood_Fir_Trunk"
    },
    {
      "x": 1,
      "y": 26,
      "z": 0,
      "name": "Wood_Fir_Trunk"
    },
    {
      "x": 1,
      "y": 27,
      "z": 0,
      "name": "Wood_Fir_Trunk"
    },
    {
      "x": 1,
      "y": 28,
      "z": 0,
      "name": "Wood_Fir_Trunk"
    },
    {
      "x": 1,
      "y": 29,
      "z": 0,
      "name": "Wood_Fir_Trunk"
    },
    {
      "x": 1,
      "y": 30,
      "z": 0,
      "name": "Wood_Fir_Trunk"
    },
    {
      "x": 1,
      "y": 31,
      "z": 0,
      "name": "Wood_Fir_Trunk"
    },
    {
      "x": 1,
      "y": 32,
      "z": 0,
      "name": "Wood_Fir_Trunk"
    },
    {
      "x": 1,
      "y": 33,
      "z": 0,
      "name": "Wood_Fir_Trunk"
    },
    {
      "x": 1,
      "y": 34,
      "z": 0,
      "name": "Wood_Fir_Trunk"
    },
    {
      "x": 1,
      "y": 35,
      "z": 0,
      "name": "Wood_Fir_Trunk"
    },
    {
      "x": 1,
      "y": 36,
      "z": 0,
      "name": "Wood_Fir_Trunk"
    },
    {
      "x": 1,
      "y": 37,
      "z": 0,
      "name": "Wood_Fir_Trunk"
    },
    {
      "x": 1,
      "y": 38,
      "z": 0,
      "name": "Wood_Fir_Trunk"
    },
    {
      "x": 1,
      "y": 39,
      "z": 0,
      "name": "Wood_Fir_Trunk"
    },
    {
      "x": 1,
      "y": 40,
      "z": 0,
      "name": "Plant_Leaves_Dead"
    },
    {
      "x": 1,
      "y": 41,
      "z": 0,
      "name": "Plant_Leaves_Dead"
    },
    {
      "x": 1,
      "y": 42,
      "z": 0,
      "name": "Plant_Leaves_Dead"
    },
    {
      "x": 1,
      "y": 43,
      "z": 0,
      "name": "Plant_Leaves_Dead"
    },
    {
      "x": 1,
      "y": 44,
      "z": 0,
      "name": "Plant_Leaves_Dead"
    },
    {
      "x": 1,
      "y": 45,
      "z": 0,
      "name": "Plant_Leaves_Dead"
    },
    {
      "x": 1,
      "y": 46,
      "z": 0,
      "name": "Plant_Leaves_Dead"
    },
    {
      "x": 1,
      "y": 47,
      "z": 0,
      "name": "Plant_Leaves_Dead"
    },
    {
      "x": 1,
      "y": 48,
      "z": 0,
      "name": "Plant_Leaves_Dead"
    },
    {
      "x": 1,
      "y": 6,
      "z": 1,
      "name": "Wood_Fir_Trunk"
    },
    {
      "x": 1,
      "y": 7,
      "z": 1,
      "name": "Wood_Fir_Trunk"
    },
    {
      "x": 1,
      "y": 8,
      "z": 1,
      "name": "Wood_Fir_Trunk"
    },
    {
      "x": 1,
      "y": 9,
      "z": 1,
      "name": "Wood_Fir_Trunk"
    },
    {
      "x": 1,
      "y": 10,
      "z": 1,
      "name": "Wood_Fir_Trunk"
    },
    {
      "x": 1,
      "y": 11,
      "z": 1,
      "name": "Wood_Fir_Trunk_Full"
    },
    {
      "x": 1,
      "y": 27,
      "z": 1,
      "name": "Plant_Leaves_Dead"
    },
    {
      "x": 1,
      "y": 29,
      "z": 1,
      "name": "Plant_Leaves_Dead"
    },
    {
      "x": 1,
      "y": 30,
      "z": 1,
      "name": "Plant_Leaves_Dead"
    },
    {
      "x": 1,
      "y": 31,
      "z": 1,
      "name": "Plant_Leaves_Dead"
    },
    {
      "x": 1,
      "y": 32,
      "z": 1,
      "name": "Plant_Leaves_Dead"
    },
    {
      "x": 1,
      "y": 33,
      "z": 1,
      "name": "Plant_Leaves_Dead"
    },
    {
      "x": 1,
      "y": 34,
      "z": 1,
      "name": "Plant_Leaves_Dead"
    },
    {
      "x": 1,
      "y": 35,
      "z": 1,
      "name": "Wood_Fir_Branch_Long",
      "rotation": 4
    },
    {
      "x": 1,
      "y": 37,
      "z": 1,
      "name": "Plant_Leaves_Dead"
    },
    {
      "x": 1,
      "y": 38,
      "z": 1,
      "name": "Plant_Leaves_Dead"
    },
    {
      "x": 1,
      "y": 40,
      "z": 1,
      "name": "Plant_Leaves_Dead"
    },
    {
      "x": 1,
      "y": 41,
      "z": 1,
      "name": "Plant_Leaves_Dead"
    },
    {
      "x": 1,
      "y": 43,
      "z": 1,
      "name": "Plant_Leaves_Dead"
    },
    {
      "x": 1,
      "y": 45,
      "z": 1,
      "name": "Plant_Leaves_Dead"
    },
    {
      "x": 1,
      "y": 46,
      "z": 1,
      "name": "Plant_Leaves_Dead"
    },
    {
      "x": 1,
      "y": 5,
      "z": 2,
      "name": "Wood_Fir_Trunk"
    },
    {
      "x": 1,
      "y": 6,
      "z": 2,
      "name": "Wood_Fir_Trunk"
    },
    {
      "x": 1,
      "y": 7,
      "z": 2,
      "name": "Wood_Fir_Trunk"
    },
    {
      "x": 1,
      "y": 8,
      "z": 2,
      "name": "Wood_Fir_Trunk_Full"
    },
    {
      "x": 1,
      "y": 27,
      "z": 2,
      "name": "Plant_Leaves_Dead"
    },
    {
      "x": 1,
      "y": 28,
      "z": 2,
      "name": "Plant_Leaves_Dead"
    },
    {
      "x": 1,
      "y": 29,
      "z": 2,
      "name": "Plant_Leaves_Dead"
    },
    {
      "x": 1,
      "y": 30,
      "z": 2,
      "name": "Plant_Leaves_Dead"
    },
    {
      "x": 1,
      "y": 32,
      "z": 2,
      "name": "Plant_Leaves_Dead"
    },
    {
      "x": 1,
      "y": 35,
      "z": 2,
      "name": "Wood_Fir_Branch_Long",
      "rotation": 4
    },
    {
      "x": 1,
      "y": 38,
      "z": 2,
      "name": "Plant_Leaves_Dead"
    },
    {
      "x": 1,
      "y": 40,
      "z": 2,
      "name": "Plant_Leaves_Dead"
    },
    {
      "x": 1,
      "y": 43,
      "z": 2,
      "name": "Plant_Leaves_Dead"
    },
    {
      "x": 1,
      "y": 45,
      "z": 2,
      "name": "Plant_Leaves_Dead"
    },
    {
      "x": 1,
      "y": 28,
      "z": 3,
      "name": "Plant_Leaves_Dead"
    },
    {
      "x": 1,
      "y": 32,
      "z": 3,
      "name": "Plant_Leaves_Dead"
    },
    {
      "x": 1,
      "y": 35,
      "z": 3,
      "name": "Plant_Leaves_Dead"
    },
    {
      "x": 1,
      "y": 38,
      "z": 3,
      "name": "Plant_Leaves_Dead"
    },
    {
      "x": 1,
      "y": 28,
      "z": 4,
      "name": "Plant_Leaves_Dead"
    },
    {
      "x": 1,
      "y": 32,
      "z": 4,
      "name": "Plant_Leaves_Dead"
    },
    {
      "x": 1,
      "y": 35,
      "z": 4,
      "name": "Plant_Leaves_Dead"
    },
    {
      "x": 1,
      "y": 28,
      "z": 5,
      "name": "Plant_Leaves_Dead"
    },
    {
      "x": 1,
      "y": 35,
      "z": 5,
      "name": "Plant_Leaves_Dead"
    },
    {
      "x": 1,
      "y": 36,
      "z": 5,
      "name": "Plant_Leaves_Dead"
    },
    {
      "x": 1,
      "y": 28,
      "z": 6,
      "name": "Plant_Leaves_Dead"
    },
    {
      "x": 1,
      "y": 36,
      "z": 6,
      "name": "Plant_Leaves_Dead"
    },
    {
      "x": 1,
      "y": 28,
      "z": 7,
      "name": "Plant_Leaves_Dead"
    },
    {
      "x": 1,
      "y": 29,
      "z": 7,
      "name": "Plant_Leaves_Dead"
    },
    {
      "x": 1,
      "y": 29,
      "z": 8,
      "name": "Plant_Leaves_Dead"
    },
    {
      "x": 2,
      "y": 27,
      "z": -5,
      "name": "Plant_Leaves_Dead"
    },
    {
      "x": 2,
      "y": 29,
      "z": -5,
      "name": "Plant_Leaves_Dead"
    },
    {
      "x": 2,
      "y": 39,
      "z": -5,
      "name": "Plant_Leaves_Dead"
    },
    {
      "x": 2,
      "y": 6,
      "z": -4,
      "name": "Wood_Fir_Trunk"
    },
    {
      "x": 2,
      "y": 7,
      "z": -4,
      "name": "Wood_Fir_Trunk"
    },
    {
      "x": 2,
      "y": 8,
      "z": -4,
      "name": "Wood_Fir_Trunk"
    },
    {
      "x": 2,
      "y": 9,
      "z": -4,
      "name": "Wood_Fir_Trunk"
    },
    {
      "x": 2,
      "y": 10,
      "z": -4,
      "name": "Wood_Fir_Trunk_Full"
    },
    {
      "x": 2,
      "y": 27,
      "z": -4,
      "name": "Plant_Leaves_Dead"
    },
    {
      "x": 2,
      "y": 28,
      "z": -4,
      "name": "Plant_Leaves_Dead"
    },
    {
      "x": 2,
      "y": 29,
      "z": -4,
      "name": "Plant_Leaves_Dead"
    },
    {
      "x": 2,
      "y": 30,
      "z": -4,
      "name": "Plant_Leaves_Dead"
    },
    {
      "x": 2,
      "y": 33,
      "z": -4,
      "name": "Plant_Leaves_Dead"
    },
    {
      "x": 2,
      "y": 34,
      "z": -4,
      "name": "Plant_Leaves_Dead"
    },
    {
      "x": 2,
      "y": 39,
      "z": -4,
      "name": "Plant_Leaves_Dead"
    },
    {
      "x": 2,
      "y": 42,
      "z": -4,
      "name": "Plant_Leaves_Dead"
    },
    {
      "x": 2,
      "y": 8,
      "z": -3,
      "name": "Wood_Fir_Trunk"
    },
    {
      "x": 2,
      "y": 9,
      "z": -3,
      "name": "Wood_Fir_Trunk"
    },
    {
      "x": 2,
      "y": 10,
      "z": -3,
      "name": "Wood_Fir_Trunk"
    },
    {
      "x": 2,
      "y": 11,
      "z": -3,
      "name": "Wood_Fir_Trunk"
    },
    {
      "x": 2,
      "y": 12,
      "z": -3,
      "name": "Wood_Fir_Trunk"
    },
    {
      "x": 2,
      "y": 13,
      "z": -3,
      "name": "Wood_Fir_Trunk_Full"
    },
    {
      "x": 2,
      "y": 28,
      "z": -3,
      "name": "Plant_Leaves_Dead"
    },
    {
      "x": 2,
      "y": 29,
      "z": -3,
      "name": "Plant_Leaves_Dead"
    },
    {
      "x": 2,
      "y": 30,
      "z": -3,
      "name": "Plant_Leaves_Dead"
    },
    {
      "x": 2,
      "y": 31,
      "z": -3,
      "name": "Plant_Leaves_Dead"
    },
    {
      "x": 2,
      "y": 33,
      "z": -3,
      "name": "Plant_Leaves_Dead"
    },
    {
      "x": 2,
      "y": 34,
      "z": -3,
      "name": "Plant_Leaves_Dead"
    },
    {
      "x": 2,
      "y": 35,
      "z": -3,
      "name": "Plant_Leaves_Dead"
    },
    {
      "x": 2,
      "y": 39,
      "z": -3,
      "name": "Plant_Leaves_Dead"
    },
    {
      "x": 2,
      "y": 42,
      "z": -3,
      "name": "Plant_Leaves_Dead"
    },
    {
      "x": 2,
      "y": 9,
      "z": -2,
      "name": "Wood_Fir_Trunk"
    },
    {
      "x": 2,
      "y": 10,
      "z": -2,
      "name": "Wood_Fir_Trunk"
    },
    {
      "x": 2,
      "y": 11,
      "z": -2,
      "name": "Wood_Fir_Trunk"
    },
    {
      "x": 2,
      "y": 12,
      "z": -2,
      "name": "Wood_Fir_Trunk"
    },
    {
      "x": 2,
      "y": 13,
      "z": -2,
      "name": "Wood_Fir_Trunk"
    },
    {
      "x": 2,
      "y": 14,
      "z": -2,
      "name": "Wood_Fir_Trunk"
    },
    {
      "x": 2,
      "y": 15,
      "z": -2,
      "name": "Wood_Fir_Trunk"
    },
    {
      "x": 2,
      "y": 16,
      "z": -2,
      "name": "Wood_Fir_Trunk"
    },
    {
      "x": 2,
      "y": 17,
      "z": -2,
      "name": "Wood_Fir_Trunk"
    },
    {
      "x": 2,
      "y": 18,
      "z": -2,
      "name": "Wood_Fir_Trunk"
    },
    {
      "x": 2,
      "y": 19,
      "z": -2,
      "name": "Wood_Fir_Trunk"
    },
    {
      "x": 2,
      "y": 20,
      "z": -2,
      "name": "Wood_Fir_Trunk_Full"
    },
    {
      "x": 2,
      "y": 27,
      "z": -2,
      "name": "Plant_Leaves_Dead"
    },
    {
      "x": 2,
      "y": 28,
      "z": -2,
      "name": "Plant_Leaves_Dead"
    },
    {
      "x": 2,
      "y": 29,
      "z": -2,
      "name": "Plant_Leaves_Dead"
    },
    {
      "x": 2,
      "y": 31,
      "z": -2,
      "name": "Plant_Leaves_Dead"
    },
    {
      "x": 2,
      "y": 32,
      "z": -2,
      "name": "Plant_Leaves_Dead"
    },
    {
      "x": 2,
      "y": 33,
      "z": -2,
      "name": "Plant_Leaves_Dead"
    },
    {
      "x": 2,
      "y": 34,
      "z": -2,
      "name": "Plant_Leaves_Dead"
    },
    {
      "x": 2,
      "y": 35,
      "z": -2,
      "name": "Plant_Leaves_Dead"
    },
    {
      "x": 2,
      "y": 36,
      "z": -2,
      "name": "Plant_Leaves_Dead"
    },
    {
      "x": 2,
      "y": 38,
      "z": -2,
      "name": "Plant_Leaves_Dead"
    },
    {
      "x": 2,
      "y": 39,
      "z": -2,
      "name": "Plant_Leaves_Dead"
    },
    {
      "x": 2,
      "y": 42,
      "z": -2,
      "name": "Plant_Leaves_Dead"
    },
    {
      "x": 2,
      "y": 44,
      "z": -2,
      "name": "Plant_Leaves_Dead"
    },
    {
      "x": 2,
      "y": 11,
      "z": -1,
      "name": "Wood_Fir_Trunk"
    },
    {
      "x": 2,
      "y": 12,
      "z": -1,
      "name": "Wood_Fir_Trunk"
    },
    {
      "x": 2,
      "y": 13,
      "z": -1,
      "name": "Wood_Fir_Trunk"
    },
    {
      "x": 2,
      "y": 14,
      "z": -1,
      "name": "Wood_Fir_Trunk"
    },
    {
      "x": 2,
      "y": 15,
      "z": -1,
      "name": "Wood_Fir_Trunk"
    },
    {
      "x": 2,
      "y": 16,
      "z": -1,
      "name": "Wood_Fir_Trunk"
    },
    {
      "x": 2,
      "y": 17,
      "z": -1,
      "name": "Wood_Fir_Trunk_Full"
    },
    {
      "x": 2,
      "y": 27,
      "z": -1,
      "name": "Plant_Leaves_Dead"
    },
    {
      "x": 2,
      "y": 28,
      "z": -1,
      "name": "Wood_Fir_Branch_Long",
      "rotation": 5
    },
    {
      "x": 2,
      "y": 29,
      "z": -1,
      "name": "Plant_Leaves_Dead"
    },
    {
      "x": 2,
      "y": 30,
      "z": -1,
      "name": "Plant_Leaves_Dead"
    },
    {
      "x": 2,
      "y": 31,
      "z": -1,
      "name": "Wood_Fir_Branch_Long",
      "rotation": 5
    },
    {
      "x": 2,
      "y": 33,
      "z": -1,
      "name": "Wood_Fir_Branch_Long",
      "rotation": 5
    },
    {
      "x": 2,
      "y": 34,
      "z": -1,
      "name": "Plant_Leaves_Dead"
    },
    {
      "x": 2,
      "y": 35,
      "z": -1,
      "name": "Wood_Fir_Branch_Long",
      "rotation": 5
    },
    {
      "x": 2,
      "y": 36,
      "z": -1,
      "name": "Plant_Leaves_Dead"
    },
    {
      "x": 2,
      "y": 38,
      "z": -1,
      "name": "Plant_Leaves_Dead"
    },
    {
      "x": 2,
      "y": 39,
      "z": -1,
      "name": "Wood_Fir_Branch_Long",
      "rotation": 5
    },
    {
      "x": 2,
      "y": 42,
      "z": -1,
      "name": "Wood_Fir_Branch_Long",
      "rotation": 5
    },
    {
      "x": 2,
      "y": 44,
      "z": -1,
      "name": "Wood_Fir_Branch_Long",
      "rotation": 5
    },
    {
      "x": 2,
      "y": 46,
      "z": -1,
      "name": "Plant_Leaves_Dead"
    },
    {
      "x": 2,
      "y": 47,
      "z": -1,
      "name": "Plant_Leaves_Dead"
    },
    {
      "x": 2,
      "y": 4,
      "z": 0,
      "name": "Wood_Fir_Roots"
    },
    {
      "x": 2,
      "y": 5,
      "z": 0,
      "name": "Wood_Fir_Trunk"
    },
    {
      "x": 2,
      "y": 6,
      "z": 0,
      "name": "Wood_Fir_Trunk_Full"
    },
    {
      "x": 2,
      "y": 9,
      "z": 0,
      "name": "Wood_Fir_Trunk"
    },
    {
      "x": 2,
      "y": 10,
      "z": 0,
      "name": "Wood_Fir_Trunk"
    },
    {
      "x": 2,
      "y": 11,
      "z": 0,
      "name": "Wood_Fir_Trunk"
    },
    {
      "x": 2,
      "y": 12,
      "z": 0,
      "name": "Wood_Fir_Trunk_Full"
    },
    {
      "x": 2,
      "y": 27,
      "z": 0,
      "name": "Plant_Leaves_Dead"
    },
    {
      "x": 2,
      "y": 28,
      "z": 0,
      "name": "Plant_Leaves_Dead"
    },
    {
      "x": 2,
      "y": 29,
      "z": 0,
      "name": "Plant_Leaves_Dead"
    },
    {
      "x": 2,
      "y": 30,
      "z": 0,
      "name": "Plant_Leaves_Dead"
    },
    {
      "x": 2,
      "y": 31,
      "z": 0,
      "name": "Plant_Leaves_Dead"
    },
    {
      "x": 2,
      "y": 33,
      "z": 0,
      "name": "Plant_Leaves_Dead"
    },
    {
      "x": 2,
      "y": 35,
      "z": 0,
      "name": "Plant_Leaves_Dead"
    },
    {
      "x": 2,
      "y": 37,
      "z": 0,
      "name": "Plant_Leaves_Dead"
    },
    {
      "x": 2,
      "y": 39,
      "z": 0,
      "name": "Plant_Leaves_Dead"
    },
    {
      "x": 2,
      "y": 41,
      "z": 0,
      "name": "Plant_Leaves_Dead"
    },
    {
      "x": 2,
      "y": 42,
      "z": 0,
      "name": "Plant_Leaves_Dead"
    },
    {
      "x": 2,
      "y": 44,
      "z": 0,
      "name": "Plant_Leaves_Dead"
    },
    {
      "x": 2,
      "y": 5,
      "z": 1,
      "name": "Wood_Fir_Trunk"
    },
    {
      "x": 2,
      "y": 6,
      "z": 1,
      "name": "Wood_Fir_Trunk"
    },
    {
      "x": 2,
      "y": 7,
      "z": 1,
      "name": "Wood_Fir_Trunk"
    },
    {
      "x": 2,
      "y": 8,
      "z": 1,
      "name": "Wood_Fir_Trunk"
    },
    {
      "x": 2,
      "y": 9,
      "z": 1,
      "name": "Wood_Fir_Trunk"
    },
    {
      "x": 2,
      "y": 10,
      "z": 1,
      "name": "Wood_Fir_Trunk_Full"
    },
    {
      "x": 2,
      "y": 28,
      "z": 1,
      "name": "Plant_Leaves_Dead"
    },
    {
      "x": 2,
      "y": 30,
      "z": 1,
      "name": "Plant_Leaves_Dead"
    },
    {
      "x": 2,
      "y": 31,
      "z": 1,
      "name": "Plant_Leaves_Dead"
    },
    {
      "x": 2,
      "y": 33,
      "z": 1,
      "name": "Plant_Leaves_Dead"
    },
    {
      "x": 2,
      "y": 34,
      "z": 1,
      "name": "Plant_Leaves_Dead"
    },
    {
      "x": 2,
      "y": 35,
      "z": 1,
      "name": "Plant_Leaves_Dead"
    },
    {
      "x": 2,
      "y": 37,
      "z": 1,
      "name": "Plant_Leaves_Dead"
    },
    {
      "x": 2,
      "y": 41,
      "z": 1,
      "name": "Plant_Leaves_Dead"
    },
    {
      "x": 2,
      "y": 6,
      "z": 2,
      "name": "Wood_Fir_Trunk"
    },
    {
      "x": 2,
      "y": 7,
      "z": 2,
      "name": "Wood_Fir_Trunk_Full"
    },
    {
      "x": 2,
      "y": 28,
      "z": 2,
      "name": "Plant_Leaves_Dead"
    },
    {
      "x": 2,
      "y": 30,
      "z": 2,
      "name": "Plant_Leaves_Dead"
    },
    {
      "x": 2,
      "y": 33,
      "z": 2,
      "name": "Plant_Leaves_Dead"
    },
    {
      "x": 2,
      "y": 35,
      "z": 2,
      "name": "Plant_Leaves_Dead"
    },
    {
      "x": 2,
      "y": 37,
      "z": 2,
      "name": "Plant_Leaves_Dead"
    },
    {
      "x": 2,
      "y": 41,
      "z": 2,
      "name": "Plant_Leaves_Dead"
    },
    {
      "x": 2,
      "y": 4,
      "z": 3,
      "name": "Wood_Fir_Roots"
    },
    {
      "x": 2,
      "y": 5,
      "z": 3,
      "name": "Wood_Fir_Trunk"
    },
    {
      "x": 2,
      "y": 6,
      "z": 3,
      "name": "Wood_Fir_Trunk_Full"
    },
    {
      "x": 2,
      "y": 28,
      "z": 3,
      "name": "Plant_Leaves_Dead"
    },
    {
      "x": 2,
      "y": 30,
      "z": 3,
      "name": "Plant_Leaves_Dead"
    },
    {
      "x": 2,
      "y": 35,
      "z": 3,
      "name": "Plant_Leaves_Dead"
    },
    {
      "x": 2,
      "y": 3,
      "z": 4,
      "name": "Wood_Fir_Roots"
    },
    {
      "x": 2,
      "y": 4,
      "z": 4,
      "name": "Wood_Fir_Trunk"
    },
    {
      "x": 2,
      "y": 5,
      "z": 4,
      "name": "Wood_Fir_Trunk_Full"
    },
    {
      "x": 2,
      "y": 28,
      "z": 4,
      "name": "Plant_Leaves_Dead"
    },
    {
      "x": 2,
      "y": 35,
      "z": 4,
      "name": "Plant_Leaves_Dead"
    },
    {
      "x": 2,
      "y": 28,
      "z": 5,
      "name": "Plant_Leaves_Dead"
    },
    {
      "x": 2,
      "y": 28,
      "z": 6,
      "name": "Plant_Leaves_Dead"
    },
    {
      "x": 3,
      "y": 3,
      "z": -5,
      "name": "Wood_Fir_Roots"
    },
    {
      "x": 3,
      "y": 4,
