{
  "version": 8,
  "blockIdVersion": 8,
  "anchorX": 0,
  "anchorY": 0,
  "anchorZ": 0,
  "blocks": [
    {
      "x": -16,
      "y": 5,
      "z": -4,
      "name": "Wood_Deadwood_Roof_Hollow",
      "rotation": 3
    },
    {
      "x": -16,
      "y": 5,
      "z": -3,
      "name": "Wood_Deadwood_Roof_Hollow",
      "rotation": 3
    },
    {
      "x": -15,
      "y": -4,
      "z": -6,
      "name": "Rock_Stone_Cobble",
      "rotation": 2
    },
    {
      "x": -15,
      "y": -3,
      "z": -6,
      "name": "Rock_Stone_Cobble",
      "rotation": 2
    },
    {
      "x": -15,
      "y": -2,
      "z": -6,
      "name": "Rock_Stone_Cobble",
      "rotation": 2
    },
    {
      "x": -15,
      "y": -1,
      "z": -6,
      "name": "Rock_Stone_Cobble",
      "rotation": 2
    },
    {
      "x": -15,
      "y": 0,
      "z": -6,
      "name": "Rock_Stone_Cobble",
      "rotation": 2
    },
    {
      "x": -15,
      "y": 1,
      "z": -6,
      "name": "Rock_Stone",
      "rotation": 2
    },
    {
      "x": -15,
      "y": 2,
      "z": -6,
      "name": "Rock_Stone",
      "rotation": 2
    },
    {
      "x": -15,
      "y": 3,
      "z": -6,
      "name": "Rock_Stone",
      "rotation": 2
    },
    {
      "x": -15,
      "y": 4,
      "z": -6,
      "name": "Rock_Stone",
      "rotation": 2
    },
    {
      "x": -15,
      "y": 5,
      "z": -6,
      "name": "Rock_Stone",
      "rotation": 2
    },
    {
      "x": -15,
      "y": 6,
      "z": -6,
      "name": "Plant_Moss_Rug_Green"
    },
    {
      "x": -15,
      "y": -3,
      "z": -5,
      "name": "Rock_Stone_Cobble",
      "rotation": 2
    },
    {
      "x": -15,
      "y": -2,
      "z": -5,
      "name": "Rock_Stone_Cobble",
      "rotation": 2
    },
    {
      "x": -15,
      "y": -1,
      "z": -5,
      "name": "Rock_Stone_Cobble",
      "rotation": 2
    },
    {
      "x": -15,
      "y": 0,
      "z": -5,
      "name": "Rock_Stone_Cobble",
      "rotation": 2
    },
    {
      "x": -15,
      "y": 1,
      "z": -5,
      "name": "Rock_Stone_Cobble_Half",
      "rotation": 4
    },
    {
      "x": -15,
      "y": 2,
      "z": -5,
      "name": "Rock_Stone_Cobble_Half",
      "rotation": 4
    },
    {
      "x": -15,
      "y": 3,
      "z": -5,
      "name": "Rock_Stone_Cobble_Half",
      "rotation": 4
    },
    {
      "x": -15,
      "y": 4,
      "z": -5,
      "name": "Rock_Stone_Cobble_Stairs",
      "rotation": 10
    },
    {
      "x": -15,
      "y": 5,
      "z": -5,
      "name": "Rock_Stone",
      "rotation": 2
    },
    {
      "x": -15,
      "y": 6,
      "z": -5,
      "name": "Wood_Deadwood_Roof",
      "rotation": 3
    },
    {
      "x": -15,
      "y": -6,
      "z": -4,
      "name": "Rock_Stone_Cobble",
      "rotation": 2
    },
    {
      "x": -15,
      "y": -5,
      "z": -4,
      "name": "Rock_Stone_Cobble",
      "rotation": 2
    },
    {
      "x": -15,
      "y": -4,
      "z": -4,
      "name": "Rock_Stone_Cobble",
      "rotation": 2
    },
    {
      "x": -15,
      "y": -3,
      "z": -4,
      "name": "Rock_Stone_Cobble",
      "rotation": 2
    },
    {
      "x": -15,
      "y": -2,
      "z": -4,
      "name": "Rock_Stone_Cobble",
      "rotation": 2
    },
    {
      "x": -15,
      "y": -1,
      "z": -4,
      "name": "Rock_Stone_Cobble",
      "rotation": 2
    },
    {
      "x": -15,
      "y": 0,
      "z": -4,
      "name": "Rock_Stone_Cobble",
      "rotation": 2
    },
    {
      "x": -15,
      "y": 1,
      "z": -4,
      "name": "Rail",
      "rotation": 1
    },
    {
      "x": -15,
      "y": 2,
      "z": -4,
      "name": "Empty"
    },
    {
      "x": -15,
      "y": 3,
      "z": -4,
      "name": "Empty"
    },
    {
      "x": -15,
      "y": 4,
      "z": -4,
      "name": "Rock_Stone_Cobble_Half",
      "rotation": 10
    },
    {
      "x": -15,
      "y": 5,
      "z": -4,
      "name": "Rock_Stone",
      "rotation": 2
    },
    {
      "x": -15,
      "y": 6,
      "z": -4,
      "name": "Wood_Deadwood_Roof",
      "rotation": 3
    },
    {
      "x": -15,
      "y": -4,
      "z": -3,
      "name": "Rock_Stone_Cobble",
      "rotation": 2
    },
    {
      "x": -15,
      "y": -3,
      "z": -3,
      "name": "Rock_Stone_Cobble",
      "rotation": 2
    },
    {
      "x": -15,
      "y": -2,
      "z": -3,
      "name": "Rock_Stone_Cobble",
      "rotation": 2
    },
    {
      "x": -15,
      "y": -1,
      "z": -3,
      "name": "Rock_Stone_Cobble",
      "rotation": 2
    },
    {
      "x": -15,
      "y": 0,
      "z": -3,
      "name": "Rock_Stone_Cobble",
      "rotation": 2
    },
    {
      "x": -15,
      "y": 1,
      "z": -3,
      "name": "Rock_Stone_Cobble_Half",
      "rotation": 6
    },
    {
      "x": -15,
      "y": 2,
      "z": -3,
      "name": "Rock_Stone_Cobble_Half",
      "rotation": 6
    },
    {
      "x": -15,
      "y": 3,
      "z": -3,
      "name": "Rock_Stone_Cobble_Half",
      "rotation": 6
    },
    {
      "x": -15,
      "y": 4,
      "z": -3,
      "name": "Rock_Stone_Cobble_Stairs",
      "rotation": 8
    },
    {
      "x": -15,
      "y": 5,
      "z": -3,
      "name": "Rock_Stone",
      "rotation": 2
    },
    {
      "x": -15,
      "y": 6,
      "z": -3,
      "name": "Wood_Deadwood_Roof",
      "rotation": 3
    },
    {
      "x": -15,
      "y": -3,
      "z": -2,
      "name": "Rock_Stone_Cobble",
      "rotation": 2
    },
    {
      "x": -15,
      "y": -2,
      "z": -2,
      "name": "Rock_Stone_Cobble",
      "rotation": 2
    },
    {
      "x": -15,
      "y": -1,
      "z": -2,
      "name": "Rock_Stone_Cobble",
      "rotation": 2
    },
    {
      "x": -15,
      "y": 0,
      "z": -2,
      "name": "Rock_Stone_Cobble",
      "rotation": 2
    },
    {
      "x": -15,
      "y": 1,
      "z": -2,
      "name": "Rock_Stone",
      "rotation": 2
    },
    {
      "x": -15,
      "y": 2,
      "z": -2,
      "name": "Rock_Stone",
      "rotation": 2
    },
    {
      "x": -15,
      "y": 3,
      "z": -2,
      "name": "Rock_Stone",
      "rotation": 2
    },
    {
      "x": -15,
      "y": 4,
      "z": -2,
      "name": "Rock_Stone",
      "rotation": 2
    },
    {
      "x": -15,
      "y": 5,
      "z": -2,
      "name": "Rock_Stone",
      "rotation": 2
    },
    {
      "x": -15,
      "y": 6,
      "z": -2,
      "name": "Wood_Deadwood_Roof",
      "rotation": 3
    },
    {
      "x": -14,
      "y": -3,
      "z": -6,
      "name": "Rock_Stone_Cobble",
      "rotation": 2
    },
    {
      "x": -14,
      "y": -2,
      "z": -6,
      "name": "Rock_Stone_Cobble",
      "rotation": 2
    },
    {
      "x": -14,
      "y": -1,
      "z": -6,
      "name": "Rock_Stone_Cobble",
      "rotation": 2
    },
    {
      "x": -14,
      "y": 0,
      "z": -6,
      "name": "Rock_Stone_Cobble",
      "rotation": 2
    },
    {
      "x": -14,
      "y": 1,
      "z": -6,
      "name": "Rock_Stone_Cobble",
      "rotation": 2
    },
    {
      "x": -14,
      "y": 2,
      "z": -6,
      "name": "Rock_Stone",
      "rotation": 2
    },
    {
      "x": -14,
      "y": 3,
      "z": -6,
      "name": "Rock_Stone",
      "rotation": 2
    },
    {
      "x": -14,
      "y": 4,
      "z": -6,
      "name": "Rock_Stone",
      "rotation": 2
    },
    {
      "x": -14,
      "y": 5,
      "z": -6,
      "name": "Rock_Stone",
      "rotation": 2
    },
    {
      "x": -14,
      "y": 6,
      "z": -6,
      "name": "Rock_Stone",
      "rotation": 2
    },
    {
      "x": -14,
      "y": 7,
      "z": -6,
      "name": "Plant_Moss_Rug_Green"
    },
    {
      "x": -14,
      "y": -3,
      "z": -5,
      "name": "Rock_Stone_Cobble",
      "rotation": 2
    },
    {
      "x": -14,
      "y": -2,
      "z": -5,
      "name": "Rock_Stone_Cobble",
      "rotation": 2
    },
    {
      "x": -14,
      "y": -1,
      "z": -5,
      "name": "Rock_Stone_Cobble",
      "rotation": 2
    },
    {
      "x": -14,
      "y": 0,
      "z": -5,
      "name": "Rock_Stone_Cobble",
      "rotation": 2
    },
    {
      "x": -14,
      "y": 1,
      "z": -5,
      "name": "Empty"
    },
    {
      "x": -14,
      "y": 2,
      "z": -5,
      "name": "Empty"
    },
    {
      "x": -14,
      "y": 3,
      "z": -5,
      "name": "Empty"
    },
    {
      "x": -14,
      "y": 4,
      "z": -5,
      "name": "Empty"
    },
    {
      "x": -14,
      "y": 5,
      "z": -5,
      "name": "Wood_Softwood_Planks"
    },
    {
      "x": -14,
      "y": 6,
      "z": -5,
      "name": "Soil_Grass"
    },
    {
      "x": -14,
      "y": 7,
      "z": -5,
      "name": "Plant_Fern_Forest"
    },
    {
      "x": -14,
      "y": 8,
      "z": -5,
      "name": "Empty"
    },
    {
      "x": -14,
      "y": 9,
      "z": -5,
      "name": "Empty"
    },
    {
      "x": -14,
      "y": -5,
      "z": -4,
      "name": "Rock_Stone_Cobble",
      "rotation": 2
    },
    {
      "x": -14,
      "y": -4,
      "z": -4,
      "name": "Rock_Stone_Cobble",
      "rotation": 2
    },
    {
      "x": -14,
      "y": -3,
      "z": -4,
      "name": "Rock_Stone_Cobble",
      "rotation": 2
    },
    {
      "x": -14,
      "y": -2,
      "z": -4,
      "name": "Rock_Stone_Cobble",
      "rotation": 2
    },
    {
      "x": -14,
      "y": -1,
      "z": -4,
      "name": "Rock_Stone_Cobble",
      "rotation": 2
    },
    {
      "x": -14,
      "y": 0,
      "z": -4,
      "name": "Rock_Stone_Cobble",
      "rotation": 2
    },
    {
      "x": -14,
      "y": 1,
      "z": -4,
      "name": "Rail",
      "rotation": 1
    },
    {
      "x": -14,
      "y": 2,
      "z": -4,
      "name": "Empty"
    },
    {
      "x": -14,
      "y": 3,
      "z": -4,
      "name": "Empty"
    },
    {
      "x": -14,
      "y": 4,
      "z": -4,
      "name": "Empty"
    },
    {
      "x": -14,
      "y": 5,
      "z": -4,
      "name": "Wood_Softwood_Planks",
      "rotation": 2
    },
    {
      "x": -14,
      "y": 6,
      "z": -4,
      "name": "Furniture_Village_Crate",
      "rotation": 2
    },
    {
      "x": -14,
      "y": 7,
      "z": -4,
      "name": "Wood_Deadwood_Roof",
      "rotation": 3
    },
    {
      "x": -14,
      "y": 8,
      "z": -4,
      "name": "Empty"
    },
    {
      "x": -14,
      "y": 9,
      "z": -4,
      "name": "Empty"
    },
    {
      "x": -14,
      "y": -4,
      "z": -3,
      "name": "Rock_Stone_Cobble",
      "rotation": 2
    },
    {
      "x": -14,
      "y": -3,
      "z": -3,
      "name": "Rock_Stone_Cobble",
      "rotation": 2
    },
    {
      "x": -14,
      "y": -2,
      "z": -3,
      "name": "Rock_Stone_Cobble",
      "rotation": 2
    },
    {
      "x": -14,
      "y": -1,
      "z": -3,
      "name": "Rock_Stone_Cobble",
      "rotation": 2
    },
    {
      "x": -14,
      "y": 0,
      "z": -3,
      "name": "Rock_Stone_Cobble",
      "rotation": 2
    },
    {
      "x": -14,
      "y": 1,
      "z": -3,
      "name": "Empty"
    },
    {
      "x": -14,
      "y": 2,
      "z": -3,
      "name": "Empty"
    },
    {
      "x": -14,
      "y": 3,
      "z": -3,
      "name": "Empty"
    },
    {
      "x": -14,
      "y": 4,
      "z": -3,
      "name": "Empty"
    },
    {
      "x": -14,
      "y": 5,
      "z": -3,
      "name": "Wood_Softwood_Planks",
      "rotation": 2
    },
    {
      "x": -14,
      "y": 6,
      "z": -3,
      "name": "Empty"
    },
    {
      "x": -14,
      "y": 7,
      "z": -3,
      "name": "Wood_Deadwood_Roof_Hollow",
      "rotation": 3
    },
    {
      "x": -14,
      "y": 8,
      "z": -3,
      "name": "Empty"
    },
    {
      "x": -14,
      "y": 9,
      "z": -3,
      "name": "Empty"
    },
    {
      "x": -14,
      "y": -4,
      "z": -2,
      "name": "Rock_Stone_Cobble",
      "rotation": 2
    },
    {
      "x": -14,
      "y": -3,
      "z": -2,
      "name": "Rock_Stone_Cobble",
      "rotation": 2
    },
    {
      "x": -14,
      "y": -2,
      "z": -2,
      "name": "Rock_Stone_Cobble",
      "rotation": 2
    },
    {
      "x": -14,
      "y": -1,
      "z": -2,
      "name": "Rock_Stone_Cobble",
      "rotation": 2
    },
    {
      "x": -14,
      "y": 0,
      "z": -2,
      "name": "Rock_Stone_Cobble",
      "rotation": 2
    },
    {
      "x": -14,
      "y": 1,
      "z": -2,
      "name": "Rock_Stone",
      "rotation": 2
    },
    {
      "x": -14,
      "y": 2,
      "z": -2,
      "name": "Rock_Stone",
      "rotation": 2
    },
    {
      "x": -14,
      "y": 3,
      "z": -2,
      "name": "Rock_Stone",
      "rotation": 2
    },
    {
      "x": -14,
      "y": 4,
      "z": -2,
      "name": "Rock_Stone",
      "rotation": 2
    },
    {
      "x": -14,
      "y": 5,
      "z": -2,
      "name": "Rock_Stone_Cobble_Stairs",
      "rotation": 11
    },
    {
      "x": -14,
      "y": 6,
      "z": -2,
      "name": "Rock_Stone",
      "rotation": 2
    },
    {
      "x": -14,
      "y": 7,
      "z": -2,
      "name": "Wood_Deadwood_Roof",
      "rotation": 3
    },
    {
      "x": -14,
      "y": 2,
      "z": -1,
      "name": "Plant_Moss_Wall_Green"
    },
    {
      "x": -13,
      "y": -5,
      "z": -6,
      "name": "Rock_Stone_Cobble",
      "rotation": 2
    },
    {
      "x": -13,
      "y": -4,
      "z": -6,
      "name": "Rock_Stone_Cobble",
      "rotation": 2
    },
    {
      "x": -13,
      "y": -3,
      "z": -6,
      "name": "Rock_Stone_Cobble",
      "rotation": 2
    },
    {
      "x": -13,
      "y": -2,
      "z": -6,
      "name": "Rock_Stone_Cobble",
      "rotation": 2
    },
    {
      "x": -13,
      "y": -1,
      "z": -6,
      "name": "Rock_Stone_Cobble",
      "rotation": 2
    },
    {
      "x": -13,
      "y": 0,
      "z": -6,
      "name": "Rock_Stone_Cobble",
      "rotation": 2
    },
    {
      "x": -13,
      "y": 1,
      "z": -6,
      "name": "Rock_Stone_Cobble",
      "rotation": 2
    },
    {
      "x": -13,
      "y": 2,
      "z": -6,
      "name": "Rock_Stone_Cobble",
      "rotation": 2
    },
    {
      "x": -13,
      "y": 3,
      "z": -6,
      "name": "Rock_Stone",
      "rotation": 2
    },
    {
      "x": -13,
      "y": 4,
      "z": -6,
      "name": "Rock_Stone",
      "rotation": 2
    },
    {
      "x": -13,
      "y": 5,
      "z": -6,
      "name": "Rock_Stone",
      "rotation": 2
    },
    {
      "x": -13,
      "y": 6,
      "z": -6,
      "name": "Rock_Stone",
      "rotation": 2
    },
    {
      "x": -13,
      "y": 7,
      "z": -6,
      "name": "Rock_Stone",
      "rotation": 2
    },
    {
      "x": -13,
      "y": 8,
      "z": -6,
      "name": "Wood_Deadwood_Roof",
      "rotation": 3
    },
    {
      "x": -13,
      "y": -3,
      "z": -5,
      "name": "Rock_Stone_Cobble",
      "rotation": 2
    },
    {
      "x": -13,
      "y": -2,
      "z": -5,
      "name": "Rock_Stone_Cobble",
      "rotation": 2
    },
    {
      "x": -13,
      "y": -1,
      "z": -5,
      "name": "Rock_Stone_Cobble",
      "rotation": 2
    },
    {
      "x": -13,
      "y": 0,
      "z": -5,
      "name": "Rock_Stone_Cobble",
      "rotation": 2
    },
    {
      "x": -13,
      "y": 1,
      "z": -5,
      "name": "Empty"
    },
    {
      "x": -13,
      "y": 2,
      "z": -5,
      "name": "Empty"
    },
    {
      "x": -13,
      "y": 3,
      "z": -5,
      "name": "Empty"
    },
    {
      "x": -13,
      "y": 4,
      "z": -5,
      "name": "Empty"
    },
    {
      "x": -13,
      "y": 5,
      "z": -5,
      "name": "Wood_Softwood_Planks",
      "rotation": 2
    },
    {
      "x": -13,
      "y": 6,
      "z": -5,
      "name": "Furniture_Village_Crate",
      "rotation": 2
    },
    {
      "x": -13,
      "y": 7,
      "z": -5,
      "name": "Empty"
    },
    {
      "x": -13,
      "y": 8,
      "z": -5,
      "name": "Wood_Softwood_Beam",
      "rotation": 4
    },
    {
      "x": -13,
      "y": 9,
      "z": -5,
      "name": "Empty"
    },
    {
      "x": -13,
      "y": -3,
      "z": -4,
      "name": "Rock_Stone_Cobble",
      "rotation": 2
    },
    {
      "x": -13,
      "y": -2,
      "z": -4,
      "name": "Rock_Stone_Cobble",
      "rotation": 2
    },
    {
      "x": -13,
      "y": -1,
      "z": -4,
      "name": "Rock_Stone_Cobble",
      "rotation": 2
    },
    {
      "x": -13,
      "y": 0,
      "z": -4,
      "name": "Rock_Stone_Cobble",
      "rotation": 2
    },
    {
      "x": -13,
      "y": 1,
      "z": -4,
      "name": "Rail",
      "rotation": 1
    },
    {
      "x": -13,
      "y": 2,
      "z": -4,
      "name": "Empty"
    },
    {
      "x": -13,
      "y": 3,
      "z": -4,
      "name": "Empty"
    },
    {
      "x": -13,
      "y": 4,
      "z": -4,
      "name": "Empty"
    },
    {
      "x": -13,
      "y": 5,
      "z": -4,
      "name": "Wood_Softwood_Planks",
      "rotation": 2
    },
    {
      "x": -13,
      "y": 6,
      "z": -4,
      "name": "Empty"
    },
    {
      "x": -13,
      "y": 7,
      "z": -4,
      "name": "Empty"
    },
    {
      "x": -13,
      "y": 8,
      "z": -4,
      "name": "Wood_Softwood_Beam",
      "rotation": 4
    },
    {
      "x": -13,
      "y": 9,
      "z": -4,
      "name": "Empty"
    },
    {
      "x": -13,
      "y": -3,
      "z": -3,
      "name": "Rock_Stone_Cobble",
      "rotation": 2
    },
    {
      "x": -13,
      "y": -2,
      "z": -3,
      "name": "Rock_Stone_Cobble",
      "rotation": 2
    },
    {
      "x": -13,
      "y": -1,
      "z": -3,
      "name": "Rock_Stone_Cobble",
      "rotation": 2
    },
    {
      "x": -13,
      "y": 0,
      "z": -3,
      "name": "Rock_Stone_Cobble",
      "rotation": 2
    },
    {
      "x": -13,
      "y": 1,
      "z": -3,
      "name": "Empty"
    },
    {
      "x": -13,
      "y": 2,
      "z": -3,
      "name": "Empty"
    },
    {
      "x": -13,
      "y": 3,
      "z": -3,
      "name": "Wood_Torch_Wall",
      "rotation": 2
    },
    {
      "x": -13,
      "y": 4,
      "z": -3,
      "name": "Empty"
    },
    {
      "x": -13,
      "y": 5,
      "z": -3,
      "name": "Wood_Softwood_Planks",
      "rotation": 2
    },
    {
      "x": -13,
      "y": 6,
      "z": -3,
      "name": "Empty"
    },
    {
      "x": -13,
      "y": 7,
      "z": -3,
      "name": "Empty"
    },
    {
      "x": -13,
      "y": 8,
      "z": -3,
      "name": "Wood_Deadwood_Roof_Hollow",
      "rotation": 3
    },
    {
      "x": -13,
      "y": 9,
      "z": -3,
      "name": "Empty"
    },
    {
      "x": -13,
      "y": -5,
      "z": -2,
      "name": "Rock_Stone_Cobble",
      "rotation": 2
    },
    {
      "x": -13,
      "y": -4,
      "z": -2,
      "name": "Rock_Stone_Cobble",
      "rotation": 2
    },
    {
      "x": -13,
      "y": -3,
      "z": -2,
      "name": "Rock_Stone_Cobble",
      "rotation": 2
    },
    {
      "x": -13,
      "y": -2,
      "z": -2,
      "name": "Rock_Stone_Cobble",
      "rotation": 2
    },
    {
      "x": -13,
      "y": -1,
      "z": -2,
      "name": "Rock_Stone_Cobble",
      "rotation": 2
    },
    {
      "x": -13,
      "y": 0,
      "z": -2,
      "name": "Rock_Stone_Cobble",
      "rotation": 2
    },
    {
      "x": -13,
      "y": 1,
      "z": -2,
      "name": "Rock_Stone_Cobble",
      "rotation": 2
    },
    {
      "x": -13,
      "y": 2,
      "z": -2,
      "name": "Rock_Stone",
      "rotation": 2
    },
    {
      "x": -13,
      "y": 3,
      "z": -2,
      "name": "Rock_Stone",
      "rotation": 2
    },
    {
      "x": -13,
      "y": 4,
      "z": -2,
      "name": "Empty"
    },
    {
      "x": -13,
      "y": 5,
      "z": -2,
      "name": "Rock_Stone_Cobble_Mossy_Half",
      "rotation": 8
    },
    {
      "x": -13,
      "y": 6,
      "z": -2,
      "name": "Rock_Stone",
      "rotation": 2
    },
    {
      "x": -13,
      "y": 7,
      "z": -2,
      "name": "Rock_Stone",
      "rotation": 2
    },
    {
      "x": -13,
      "y": 8,
      "z": -2,
      "name": "Wood_Deadwood_Roof",
      "rotation": 3
    },
    {
      "x": -13,
      "y": 1,
      "z": -1,
      "name": "Plant_Moss_Wall_Green"
    },
    {
      "x": -12,
      "y": 9,
      "z": -9,
      "name": "Plant_Moss_Wall_Green",
      "rotation": 3
    },
    {
      "x": -12,
      "y": 12,
      "z": -7,
      "name": "Wood_Deadwood_Roof_Hollow",
      "rotation": 2
    },
    {
      "x": -12,
      "y": -4,
      "z": -6,
      "name": "Rock_Stone_Cobble",
      "rotation": 2
    },
    {
      "x": -12,
      "y": -3,
      "z": -6,
      "name": "Rock_Stone_Cobble",
      "rotation": 2
    },
    {
      "x": -12,
      "y": -2,
      "z": -6,
      "name": "Rock_Stone_Cobble",
      "rotation": 2
    },
    {
      "x": -12,
      "y": -1,
      "z": -6,
      "name": "Rock_Stone_Cobble",
      "rotation": 2
    },
    {
      "x": -12,
      "y": 0,
      "z": -6,
      "name": "Rock_Stone_Cobble",
      "rotation": 2
    },
    {
      "x": -12,
      "y": 1,
      "z": -6,
      "name": "Rock_Stone_Cobble",
      "rotation": 2
    },
    {
      "x": -12,
      "y": 2,
      "z": -6,
      "name": "Rock_Stone",
      "rotation": 2
    },
    {
      "x": -12,
      "y": 3,
      "z": -6,
      "name": "Rock_Stone",
      "rotation": 2
    },
    {
      "x": -12,
      "y": 4,
      "z": -6,
      "name": "Rock_Stone",
      "rotation": 2
    },
    {
      "x": -12,
      "y": 5,
      "z": -6,
      "name": "Rock_Stone",
      "rotation": 2
    },
    {
      "x": -12,
      "y": 6,
      "z": -6,
      "name": "Rock_Stone",
      "rotation": 2
    },
    {
      "x": -12,
      "y": 7,
      "z": -6,
      "name": "Rock_Stone",
      "rotation": 2
    },
    {
      "x": -12,
      "y": 8,
      "z": -6,
      "name": "Rock_Stone",
      "rotation": 2
    },
    {
      "x": -12,
      "y": 9,
      "z": -6,
      "name": "Wood_Deadwood_Roof",
      "rotation": 3
    },
    {
      "x": -12,
      "y": 13,
      "z": -6,
      "name": "Wood_Deadwood_Roof_Hollow",
      "rotation": 2
    },
    {
      "x": -12,
      "y": -3,
      "z": -5,
      "name": "Rock_Stone_Cobble",
      "rotation": 2
    },
    {
      "x": -12,
      "y": -2,
      "z": -5,
      "name": "Rock_Stone_Cobble",
      "rotation": 2
    },
    {
      "x": -12,
      "y": -1,
      "z": -5,
      "name": "Rock_Stone_Cobble",
      "rotation": 2
    },
    {
      "x": -12,
      "y": 0,
      "z": -5,
      "name": "Rock_Stone_Cobble",
      "rotation": 2
    },
    {
      "x": -12,
      "y": 1,
      "z": -5,
      "name": "Empty"
    },
    {
      "x": -12,
      "y": 2,
      "z": -5,
      "name": "Empty"
    },
    {
      "x": -12,
      "y": 3,
      "z": -5,
      "name": "Empty"
    },
    {
      "x": -12,
      "y": 4,
      "z": -5,
      "name": "Empty"
    },
    {
      "x": -12,
      "y": 5,
      "z": -5,
      "name": "Wood_Softwood_Planks",
      "rotation": 2
    },
    {
      "x": -12,
      "y": 6,
      "z": -5,
      "name": "Empty"
    },
    {
      "x": -12,
      "y": 7,
      "z": -5,
      "name": "Empty"
    },
    {
      "x": -12,
      "y": 8,
      "z": -5,
      "name": "Empty"
    },
    {
      "x": -12,
      "y": 9,
      "z": -5,
      "name": "Wood_Deadwood_Roof_Hollow",
      "rotation": 3
    },
    {
      "x": -12,
      "y": 14,
      "z": -5,
      "name": "Wood_Deadwood_Roof_Hollow",
      "rotation": 2
    },
    {
      "x": -12,
      "y": -3,
      "z": -4,
      "name": "Rock_Stone_Cobble",
      "rotation": 2
    },
    {
      "x": -12,
      "y": -2,
      "z": -4,
      "name": "Rock_Stone_Cobble",
      "rotation": 2
    },
    {
      "x": -12,
      "y": -1,
      "z": -4,
      "name": "Rock_Stone_Cobble",
      "rotation": 2
    },
    {
      "x": -12,
      "y": 0,
      "z": -4,
      "name": "Rock_Stone_Cobble",
      "rotation": 2
    },
    {
      "x": -12,
      "y": 1,
      "z": -4,
      "name": "Rail",
      "rotation": 1
    },
    {
      "x": -12,
      "y": 2,
      "z": -4,
      "name": "Empty"
    },
    {
      "x": -12,
      "y": 3,
      "z": -4,
      "name": "Empty"
    },
    {
      "x": -12,
      "y": 4,
      "z": -4,
      "name": "Empty"
    },
    {
      "x": -12,
      "y": 5,
      "z": -4,
      "name": "Wood_Softwood_Planks",
      "rotation": 2
    },
    {
      "x": -12,
      "y": 6,
      "z": -4,
      "name": "Rail",
      "rotation": 1
    },
    {
      "x": -12,
      "y": 7,
      "z": -4,
      "name": "Empty"
    },
    {
      "x": -12,
      "y": 8,
      "z": -4,
      "name": "Empty"
    },
    {
      "x": -12,
      "y": 9,
      "z": -4,
      "name": "Wood_Softwood_Beam",
      "rotation": 4
    },
    {
      "x": -12,
      "y": 15,
      "z": -4,
      "name": "Wood_Deadwood_Roof_Flat",
      "rotation": 2
    },
    {
      "x": -12,
      "y": -3,
      "z": -3,
      "name": "Rock_Stone_Cobble",
      "rotation": 2
    },
    {
      "x": -12,
      "y": -2,
      "z": -3,
      "name": "Rock_Stone_Cobble",
      "rotation": 2
    },
    {
      "x": -12,
      "y": -1,
      "z": -3,
      "name": "Rock_Stone_Cobble",
      "rotation": 2
    },
    {
      "x": -12,
      "y": 0,
      "z": -3,
      "name": "Rock_Stone_Cobble",
      "rotation": 2
    },
    {
      "x": -12,
      "y": 1,
      "z": -3,
      "name": "Empty"
    },
    {
      "x": -12,
      "y": 2,
      "z": -3,
      "name": "Empty"
    },
    {
      "x": -12,
      "y": 3,
      "z": -3,
      "name": "Empty"
    },
    {
      "x": -12,
      "y": 4,
      "z": -3,
      "name": "Empty"
    },
    {
      "x": -12,
      "y": 5,
      "z": -3,
      "name": "Wood_Softwood_Planks",
      "rotation": 2
    },
    {
      "x": -12,
      "y": 6,
      "z": -3,
      "name": "Block_Spawner_Block",
      "components": {
        "Components": {
          "PlacedByInteraction": {
            "WhoPlacedUuid": {
              "$binary": "x9M0GYCLPG+IqIodoDzEcQ==",
              "$type": "04"
            }
          },
          "BlockSpawner": {
            "BlockSpawnerId": "Zone1_Encounters_Tier1"
          }
        }
      },
      "rotation": 1
    },
    {
      "x": -12,
      "y": 7,
      "z": -3,
      "name": "Empty"
    },
    {
      "x": -12,
      "y": 8,
      "z": -3,
      "name": "Empty"
    },
    {
      "x": -12,
      "y": 9,
      "z": -3,
      "name": "Wood_Softwood_Beam",
      "rotation": 4
    },
    {
      "x": -12,
      "y": 14,
      "z": -3,
      "name": "Wood_Deadwood_Roof_Hollow"
    },
    {
      "x": -12,
      "y": -4,
      "z": -2,
      "name": "Rock_Stone_Cobble",
      "rotation": 2
    },
    {
      "x": -12,
      "y": -3,
      "z": -2,
      "name": "Rock_Stone_Cobble",
      "rotation": 2
    },
    {
      "x": -12,
      "y": -2,
      "z": -2,
      "name": "Rock_Stone_Cobble",
      "rotation": 2
    },
    {
      "x": -12,
      "y": -1,
      "z": -2,
      "name": "Rock_Stone_Cobble",
      "rotation": 2
    },
    {
      "x": -12,
      "y": 0,
      "z": -2,
      "name": "Rock_Stone_Cobble",
      "rotation": 2
    },
    {
      "x": -12,
      "y": 1,
      "z": -2,
      "name": "Rock_Stone_Cobble",
      "rotation": 2
    },
    {
      "x": -12,
      "y": 2,
      "z": -2,
      "name": "Rock_Stone_Cobble",
      "rotation": 2
    },
    {
      "x": -12,
      "y": 3,
      "z": -2,
      "name": "Rock_Stone",
      "rotation": 2
    },
    {
      "x": -12,
      "y": 4,
      "z": -2,
      "name": "Rock_Stone_Cobble_Stairs",
      "rotation": 3
    },
    {
      "x": -12,
      "y": 5,
      "z": -2,
      "name": "Rock_Stone",
      "rotation": 2
    },
    {
      "x": -12,
      "y": 6,
      "z": -2,
      "name": "Rock_Stone",
      "rotation": 2
    },
    {
      "x": -12,
      "y": 7,
      "z": -2,
      "name": "Rock_Stone",
      "rotation": 2
    },
    {
      "x": -12,
      "y": 8,
      "z": -2,
      "name": "Rock_Stone",
      "rotation": 2
    },
    {
      "x": -12,
      "y": 9,
      "z": -2,
      "name": "Wood_Deadwood_Roof",
      "rotation": 3
    },
    {
      "x": -12,
      "y": 13,
      "z": -2,
      "name": "Wood_Deadwood_Roof_Hollow"
    },
    {
      "x": -12,
      "y": 1,
      "z": -1,
      "name": "Plant_Moss_Wall_Green"
    },
    {
      "x": -12,
      "y": 2,
      "z": -1,
      "name": "Plant_Moss_Wall_Green"
    },
    {
      "x": -12,
      "y": 3,
      "z": -1,
      "name": "Plant_Moss_Wall_Green"
    },
    {
      "x": -12,
      "y": 12,
      "z": -1,
      "name": "Wood_Deadwood_Roof_Hollow"
    },
    {
      "x": -12,
      "y": 11,
      "z": 0,
      "name": "Wood_Deadwood_Roof_Hollow"
    },
    {
      "x": -12,
      "y": 10,
      "z": 1,
      "name": "Wood_Deadwood_Roof_Hollow"
    },
    {
      "x": -11,
      "y": 9,
      "z": -10,
      "name": "Plant_Moss_Wall_Green",
      "rotation": 2
    },
    {
      "x": -11,
      "y": 4,
      "z": -9,
      "name": "Furniture_Crude_Platform",
      "rotation": 2
    },
    {
      "x": -11,
      "y": 5,
      "z": -9,
      "name": "Wood_Beech_Trunk",
      "support": 15,
      "rotation": 2
    },
    {
      "x": -11,
      "y": 6,
      "z": -9,
      "name": "Wood_Beech_Trunk",
      "support": 15,
      "rotation": 2
    },
    {
      "x": -11,
      "y": 7,
      "z": -9,
      "name": "Wood_Beech_Trunk",
      "support": 15,
      "rotation": 2
    },
    {
      "x": -11,
      "y": 8,
      "z": -9,
      "name": "Wood_Beech_Trunk",
      "support": 15,
      "rotation": 2
    },
    {
      "x": -11,
      "y": 9,
      "z": -9,
      "name": "Wood_Beech_Trunk",
      "support": 15
    },
    {
      "x": -11,
      "y": 10,
      "z": -9,
      "name": "Plant_Moss_Rug_Green"
    },
    {
      "x": -11,
      "y": 11,
      "z": -9,
      "name": "Empty"
    },
    {
      "x": -11,
      "y": 12,
      "z": -9,
      "name": "Empty"
    },
    {
      "x": -11,
      "y": 13,
      "z": -9,
      "name": "Empty"
    },
    {
      "x": -11,
      "y": -3,
      "z": -8,
      "name": "Rock_Stone_Cobble",
      "rotation": 2
    },
    {
      "x": -11,
      "y": -2,
      "z": -8,
      "name": "Rock_Stone_Cobble",
      "rotation": 2
    },
    {
      "x": -11,
      "y": -1,
      "z": -8,
      "name": "Rock_Stone_Cobble",
      "rotation": 2
    },
    {
      "x": -11,
      "y": 0,
      "z": -8,
      "name": "Rock_Stone_Cobble",
      "rotation": 2
    },
    {
      "x": -11,
      "y": 1,
      "z": -8,
      "name": "Rock_Stone",
      "rotation": 2
    },
    {
      "x": -11,
      "y": 2,
      "z": -8,
      "name": "Rock_Stone",
      "rotation": 2
    },
    {
      "x": -11,
      "y": 3,
      "z": -8,
      "name": "Rock_Stone",
      "rotation": 2
    },
    {
      "x": -11,
      "y": 4,
      "z": -8,
      "name": "Rock_Stone",
      "rotation": 2
    },
    {
      "x": -11,
      "y": 5,
      "z": -8,
      "name": "Wood_Softwood_Decorative",
      "rotation": 2
    },
    {
      "x": -11,
      "y": 6,
      "z": -8,
      "name": "Wood_Softwood_Decorative",
      "rotation": 2
    },
    {
      "x": -11,
      "y": 7,
      "z": -8,
      "name": "Wood_Softwood_Decorative",
      "rotation": 2
    },
    {
      "x": -11,
      "y": 8,
      "z": -8,
      "name": "Wood_Softwood_Decorative",
      "rotation": 2
    },
    {
      "x": -11,
      "y": 9,
      "z": -8,
      "name": "Wood_Softwood_Planks",
      "rotation": 2
    },
    {
      "x": -11,
      "y": 10,
      "z": -8,
      "name": "Wood_Softwood_Planks",
      "rotation": 2
    },
    {
      "x": -11,
      "y": 11,
      "z": -8,
      "name": "Wood_Deadwood_Roof",
      "rotation": 2
    },
    {
      "x": -11,
      "y": 12,
      "z": -8,
      "name": "Empty"
    },
    {
      "x": -11,
      "y": 13,
      "z": -8,
      "name": "Empty"
    },
    {
      "x": -11,
      "y": -3,
      "z": -7,
      "name": "Rock_Stone_Cobble",
      "rotation": 2
    },
    {
      "x": -11,
      "y": -2,
      "z": -7,
      "name": "Rock_Stone_Cobble",
      "rotation": 2
    },
    {
      "x": -11,
      "y": -1,
      "z": -7,
      "name": "Rock_Stone_Cobble",
      "rotation": 2
    },
    {
      "x": -11,
      "y": 0,
      "z": -7,
      "name": "Rock_Stone_Cobble",
      "rotation": 2
    },
    {
      "x": -11,
      "y": 1,
      "z": -7,
      "name": "Rock_Stone",
      "rotation": 2
    },
    {
      "x": -11,
      "y": 2,
      "z": -7,
      "name": "Rock_Stone_Cobble_Stairs"
    },
    {
      "x": -11,
      "y": 3,
      "z": -7,
      "name": "Rock_Stone",
      "rotation": 2
    },
    {
      "x": -11,
      "y": 4,
      "z": -7,
      "name": "Rock_Stone",
      "rotation": 2
    },
    {
      "x": -11,
      "y": 5,
      "z": -7,
      "name": "Wood_Softwood_Planks",
      "rotation": 2
    },
    {
      "x": -11,
      "y": 6,
      "z": -7,
      "name": "Wood_Softwood_Planks",
      "rotation": 2
    },
    {
      "x": -11,
      "y": 7,
      "z": -7,
      "name": "Wood_Softwood_Planks",
      "rotation": 2
    },
    {
      "x": -11,
      "y": 8,
      "z": -7,
      "name": "Wood_Softwood_Planks",
      "rotation": 2
    },
    {
      "x": -11,
      "y": 9,
      "z": -7,
      "name": "Wood_Softwood_Planks",
      "rotation": 2
    },
    {
      "x": -11,
      "y": 10,
      "z": -7,
      "name": "Wood_Softwood_Planks",
      "rotation": 2
    },
    {
      "x": -11,
      "y": 11,
      "z": -7,
      "name": "Wood_Softwood_Planks",
      "rotation": 2
    },
    {
      "x": -11,
      "y": 12,
      "z": -7,
      "name": "Wood_Deadwood_Roof",
      "rotation": 2
    },
    {
      "x": -11,
      "y": 13,
      "z": -7,
      "name": "Empty"
    },
    {
      "x": -11,
      "y": -3,
      "z": -6,
      "name": "Rock_Stone_Cobble",
      "rotation": 2
    },
    {
      "x": -11,
      "y": -2,
      "z": -6,
      "name": "Rock_Stone_Cobble",
      "rotation": 2
    },
    {
      "x": -11,
      "y": -1,
      "z": -6,
      "name": "Rock_Stone_Cobble",
      "rotation": 2
    },
    {
      "x": -11,
      "y": 0,
      "z": -6,
      "name": "Rock_Stone_Cobble",
      "rotation": 2
    },
    {
      "x": -11,
      "y": 1,
      "z": -6,
      "name": "Empty"
    },
    {
      "x": -11,
      "y": 2,
      "z": -6,
      "name": "Empty"
    },
    {
      "x": -11,
      "y": 3,
      "z": -6,
      "name": "Rock_Stone_Cobble_Stairs",
      "rotation": 11
    },
    {
      "x": -11,
      "y": 4,
      "z": -6,
      "name": "Rock_Stone",
      "rotation": 2
    },
    {
      "x": -11,
      "y": 5,
      "z": -6,
      "name": "Wood_Softwood_Planks",
      "rotation": 2
    },
    {
      "x": -11,
      "y": 6,
      "z": -6,
      "name": "Wood_Softwood_Planks",
      "rotation": 2
    },
    {
      "x": -11,
      "y": 7,
      "z": -6,
      "name": "Wood_Softwood_Planks",
      "rotation": 2
    },
    {
      "x": -11,
      "y": 8,
      "z": -6,
      "name": "Wood_Softwood_Planks",
      "rotation": 2
    },
    {
      "x": -11,
      "y": 9,
      "z": -6,
      "name": "Wood_Softwood_Planks",
      "rotation": 2
    },
    {
      "x": -11,
      "y": 10,
      "z": -6,
      "name": "Wood_Softwood_Planks",
      "rotation": 2
    },
    {
      "x": -11,
      "y": 11,
      "z": -6,
      "name": "Wood_Softwood_Planks",
      "rotation": 2
    },
    {
      "x": -11,
      "y": 12,
      "z": -6,
      "name": "Wood_Softwood_Fence",
      "rotation": 3
    },
    {
      "x": -11,
      "y": 13,
      "z": -6,
      "name": "Wood_Deadwood_Roof",
      "rotation": 2
    },
    {
      "x": -11,
      "y": -3,
      "z": -5,
      "name": "Rock_Stone_Cobble",
      "rotation": 2
    },
    {
      "x": -11,
      "y": -2,
      "z": -5,
      "name": "Rock_Stone_Cobble",
      "rotation": 2
    },
    {
      "x": -11,
      "y": -1,
      "z": -5,
      "name": "Rock_Stone_Cobble",
      "rotation": 2
    },
    {
      "x": -11,
      "y": 0,
      "z": -5,
      "name": "Rock_Stone_Cobble",
      "rotation": 2
    },
    {
      "x": -11,
      "y": 1,
      "z": -5,
      "name": "Empty"
    },
    {
      "x": -11,
      "y": 2,
      "z": -5,
      "name": "Empty"
    },
    {
      "x": -11,
      "y": 3,
      "z": -5,
      "name": "Empty"
    },
    {
      "x": -11,
      "y": 4,
      "z": -5,
      "name": "Empty"
    },
    {
      "x": -11,
      "y": 5,
      "z": -5,
      "name": "Wood_Softwood_Planks",
      "rotation": 2
    },
    {
      "x": -11,
      "y": 6,
      "z": -5,
      "name": "Empty"
    },
    {
      "x": -11,
      "y": 7,
      "z": -5,
      "name": "Empty"
    },
    {
      "x": -11,
      "y": 8,
      "z": -5,
      "name": "Empty"
    },
    {
      "x": -11,
      "y": 9,
      "z": -5,
      "name": "Wood_Softwood_Planks",
      "rotation": 2
    },
    {
      "x": -11,
      "y": 10,
      "z": -5,
      "name": "Wood_Softwood_Planks",
      "rotation": 2
    },
    {
      "x": -11,
      "y": 11,
      "z": -5,
      "name": "Wood_Softwood_Fence",
      "rotation": 3
    },
    {
      "x": -11,
      "y": 12,
      "z": -5,
      "name": "Wood_Softwood_Fence",
      "rotation": 3
    },
    {
      "x": -11,
      "y": 13,
      "z": -5,
      "name": "Wood_Softwood_Fence",
      "rotation": 3
    },
    {
      "x": -11,
      "y": 14,
      "z": -5,
      "name": "Wood_Deadwood_Roof",
      "rotation": 2
    },
    {
      "x": -11,
      "y": -3,
      "z": -4,
      "name": "Rock_Stone_Cobble",
      "rotation": 2
    },
    {
      "x": -11,
      "y": -2,
      "z": -4,
      "name": "Rock_Stone_Cobble",
      "rotation": 2
    },
    {
      "x": -11,
      "y": -1,
      "z": -4,
      "name": "Rock_Stone_Cobble",
      "rotation": 2
    },
    {
      "x": -11,
      "y": 0,
      "z": -4,
      "name": "Rock_Stone_Cobble",
      "rotation": 2
    },
    {
      "x": -11,
      "y": 1,
      "z": -4,
      "name": "Rail",
      "rotation": 1
    },
    {
      "x": -11,
      "y": 2,
      "z": -4,
      "name": "Empty"
    },
    {
      "x": -11,
      "y": 3,
      "z": -4,
      "name": "Empty"
    },
    {
      "x": -11,
      "y": 4,
      "z": -4,
      "name": "Empty"
    },
    {
      "x": -11,
      "y": 5,
      "z": -4,
      "name": "Wood_Softwood_Planks",
      "rotation": 2
    },
    {
      "x": -11,
      "y": 6,
      "z": -4,
      "name": "Rail",
      "rotation": 1
    },
    {
      "x": -11,
      "y": 7,
      "z": -4,
      "name": "Empty"
    },
    {
      "x": -11,
      "y": 8,
      "z": -4,
      "name": "Empty"
    },
    {
      "x": -11,
      "y": 9,
      "z": -4,
      "name": "Wood_Softwood_Planks",
      "rotation": 2
    },
    {
      "x": -11,
      "y": 10,
      "z": -4,
      "name": "Wood_Softwood_Planks",
      "rotation": 2
    },
    {
      "x": -11,
      "y": 11,
      "z": -4,
      "name": "Wood_Softwood_Planks",
      "rotation": 2
    },
    {
      "x": -11,
      "y": 12,
      "z": -4,
      "name": "Wood_Softwood_Planks",
      "rotation": 2
    },
    {
      "x": -11,
      "y": 13,
      "z": -4,
      "name": "Wood_Softwood_Fence",
      "rotation": 3
    },
    {
      "x": -11,
      "y": 14,
      "z": -4,
      "name": "Wood_Softwood_Planks",
      "rotation": 2
    },
    {
      "x": -11,
      "y": 15,
      "z": -4,
      "name": "Wood_Deadwood_Roof_Flat",
      "rotation": 2
    },
    {
      "x": -11,
      "y": -3,
      "z": -3,
      "name": "Rock_Stone_Cobble",
      "rotation": 2
    },
    {
      "x": -11,
      "y": -2,
      "z": -3,
      "name": "Rock_Stone_Cobble",
      "rotation": 2
    },
    {
      "x": -11,
      "y": -1,
      "z": -3,
      "name": "Rock_Stone_Cobble",
      "rotation": 2
    },
    {
      "x": -11,
      "y": 0,
      "z": -3,
      "name": "Rock_Stone_Cobble",
      "rotation": 2
    },
    {
      "x": -11,
      "y": 1,
      "z": -3,
      "name": "Empty"
    },
    {
      "x": -11,
      "y": 2,
      "z": -3,
      "name": "Empty"
    },
    {
      "x": -11,
      "y": 3,
      "z": -3,
      "name": "Empty"
    },
    {
      "x": -11,
      "y": 4,
      "z": -3,
      "name": "Empty"
    },
    {
      "x": -11,
      "y": 5,
      "z": -3,
      "name": "Wood_Softwood_Planks",
      "rotation": 2
    },
    {
      "x": -11,
      "y": 6,
      "z": -3,
      "name": "Empty"
    },
    {
      "x": -11,
      "y": 7,
      "z": -3,
      "name": "Empty"
    },
    {
      "x": -11,
      "y": 8,
      "z": -3,
      "name": "Empty"
    },
    {
      "x": -11,
      "y": 9,
      "z": -3,
      "name": "Wood_Softwood_Planks",
      "rotation": 2
    },
    {
      "x": -11,
      "y": 10,
      "z": -3,
      "name": "Wood_Softwood_Planks",
      "rotation": 2
    },
    {
      "x": -11,
      "y": 11,
      "z": -3,
      "name": "Wood_Softwood_Planks",
      "rotation": 2
    },
    {
      "x": -11,
      "y": 12,
      "z": -3,
      "name": "Wood_Softwood_Planks",
      "rotation": 2
    },
    {
      "x": -11,
      "y": 13,
      "z": -3,
      "name": "Wood_Softwood_Planks",
      "rotation": 2
    },
    {
      "x": -11,
      "y": 14,
      "z": -3,
      "name": "Wood_Deadwood_Roof"
    },
    {
      "x": -11,
      "y": -3,
      "z": -2,
      "name": "Rock_Stone_Cobble",
      "rotation": 2
    },
    {
      "x": -11,
      "y": -2,
      "z": -2,
      "name": "Rock_Stone_Cobble",
      "rotation": 2
    },
    {
      "x": -11,
      "y": -1,
      "z": -2,
      "name": "Rock_Stone_Cobble",
      "rotation": 2
    },
    {
      "x": -11,
      "y": 0,
      "z": -2,
      "name": "Rock_Stone_Cobble",
      "rotation": 2
    },
    {
      "x": -11,
      "y": 1,
      "z": -2,
      "name": "Rock_Stone_Cobble",
      "rotation": 2
    },
    {
      "x": -11,
      "y": 2,
      "z": -2,
      "name": "Rock_Stone",
      "rotation": 2
    },
    {
      "x": -11,
      "y": 3,
      "z": -2,
      "name": "Rock_Stone",
      "rotation": 2
    },
    {
      "x": -11,
      "y": 4,
      "z": -2,
      "name": "Rock_Stone",
      "rotation": 2
    },
    {
      "x": -11,
      "y": 5,
      "z": -2,
      "name": "Wood_Softwood_Planks",
      "rotation": 2
    },
    {
      "x": -11,
      "y": 6,
      "z": -2,
      "name": "Wood_Softwood_Planks",
      "rotation": 2
    },
    {
      "x": -11,
      "y": 7,
      "z": -2,
      "name": "Wood_Softwood_Planks",
      "rotation": 2
    },
    {
      "x": -11,
      "y": 8,
      "z": -2,
      "name": "Wood_Softwood_Planks",
      "rotation": 2
    },
    {
      "x": -11,
      "y": 9,
      "z": -2,
      "name": "Wood_Softwood_Planks",
      "rotation": 2
    },
    {
      "x": -11,
      "y": 10,
      "z": -2,
      "name": "Wood_Softwood_Planks",
      "rotation": 2
    },
    {
      "x": -11,
      "y": 11,
      "z": -2,
      "name": "Wood_Softwood_Decorative",
      "rotation": 2
    },
    {
      "x": -11,
      "y": 12,
      "z": -2,
      "name": "Wood_Softwood_Decorative",
      "rotation": 2
    },
    {
      "x": -11,
      "y": 13,
      "z": -2,
      "name": "Wood_Deadwood_Roof"
    },
    {
      "x": -11,
      "y": -4,
      "z": -1,
      "name": "Rock_Stone_Cobble",
      "rotation": 2
    },
    {
      "x": -11,
      "y": -3,
      "z": -1,
      "name": "Rock_Stone_Cobble",
      "rotation": 2
    },
    {
      "x": -11,
      "y": -2,
      "z": -1,
      "name": "Rock_Stone_Cobble",
      "rotation": 2
    },
    {
      "x": -11,
      "y": -1,
      "z": -1,
      "name": "Rock_Stone_Cobble",
      "rotation": 2
    },
    {
      "x": -11,
      "y": 0,
      "z": -1,
      "name": "Rock_Stone_Cobble",
      "rotation": 2
    },
    {
      "x": -11,
      "y": 1,
      "z": -1,
      "name": "Rock_Stone_Cobble",
      "rotation": 2
    },
    {
      "x": -11,
      "y": 2,
      "z": -1,
      "name": "Rock_Stone",
      "rotation": 2
    },
    {
      "x": -11,
      "y": 3,
      "z": -1,
      "name": "Rock_Stone",
      "rotation": 2
    },
    {
      "x": -11,
      "y": 4,
      "z": -1,
      "name": "Rock_Stone",
      "rotation": 2
    },
    {
      "x": -11,
      "y": 5,
      "z": -1,
      "name": "Wood_Softwood_Fence",
      "rotation": 3
    },
    {
      "x": -11,
      "y": 6,
      "z": -1,
      "name": "Wood_Softwood_Planks",
      "rotation": 2
    },
    {
      "x": -11,
      "y": 7,
      "z": -1,
      "name": "Wood_Softwood_Planks",
      "rotation": 2
    },
    {
      "x": -11,
      "y": 8,
      "z": -1,
      "name": "Wood_Softwood_Planks",
      "rotation": 2
    },
    {
      "x": -11,
      "y": 9,
      "z": -1,
      "name": "Wood_Softwood_Planks",
      "rotation": 2
    },
    {
      "x": -11,
      "y": 10,
      "z": -1,
      "name": "Wood_Softwood_Decorative",
      "rotation": 2
    },
    {
      "x": -11,
      "y": 11,
      "z": -1,
      "name": "Wood_Softwood_Decorative",
      "rotation": 2
    },
    {
      "x": -11,
      "y": 12,
      "z": -1,
      "name": "Wood_Deadwood_Roof_Hollow"
    },
    {
      "x": -11,
      "y": 13,
      "z": -1,
      "name": "Empty"
    },
    {
      "x": -11,
      "y": -3,
      "z": 0,
      "name": "Rock_Stone_Cobble",
      "rotation": 2
    },
    {
      "x": -11,
      "y": -2,
      "z": 0,
      "name": "Rock_Stone_Cobble",
      "rotation": 2
    },
    {
      "x": -11,
      "y": -1,
      "z": 0,
      "name": "Rock_Stone_Cobble",
      "rotation": 2
    },
    {
      "x": -11,
      "y": 0,
      "z": 0,
      "name": "Rock_Stone_Cobble",
      "rotation": 2
    },
    {
      "x": -11,
      "y": 1,
      "z": 0,
      "name": "Rock_Stone",
      "rotation": 2
    },
    {
      "x": -11,
      "y": 2,
      "z": 0,
      "name": "Rock_Stone",
      "rotation": 2
    },
    {
      "x": -11,
      "y": 3,
      "z": 0,
      "name": "Rock_Stone",
      "rotation": 2
    },
    {
      "x": -11,
      "y": 4,
      "z": 0,
      "name": "Rock_Stone",
      "rotation": 2
    },
    {
      "x": -11,
      "y": 5,
      "z": 0,
      "name": "Wood_Softwood_Fence",
      "rotation": 3
    },
    {
      "x": -11,
      "y": 6,
      "z": 0,
      "name": "Wood_Softwood_Planks",
      "rotation": 2
    },
    {
      "x": -11,
      "y": 7,
      "z": 0,
      "name": "Wood_Softwood_Planks",
      "rotation": 2
    },
    {
      "x": -11,
      "y": 8,
      "z": 0,
      "name": "Wood_Beech_Trunk",
      "support": 15,
      "rotation": 2
    },
    {
      "x": -11,
      "y": 9,
      "z": 0,
      "name": "Wood_Beech_Trunk",
      "support": 15,
      "rotation": 2
    },
    {
      "x": -11,
      "y": 10,
      "z": 0,
      "name": "Wood_Beech_Trunk",
      "support": 15,
      "rotation": 2
    },
    {
      "x": -11,
      "y": 11,
      "z": 0,
      "name": "Wood_Softwood_Beam",
      "rotation": 7
    },
    {
      "x": -11,
      "y": 12,
      "z": 0,
      "name": "Empty"
    },
    {
      "x": -11,
      "y": 13,
      "z": 0,
      "name": "Empty"
    },
    {
      "x": -11,
      "y": 4,
      "z": 1,
      "name": "Furniture_Crude_Platform",
      "rotation": 2
    },
    {
      "x": -11,
      "y": 5,
      "z": 1,
      "name": "Wood_Softwood_Planks",
      "rotation": 2
    },
    {
      "x": -11,
      "y": 6,
      "z": 1,
      "name": "Wood_Softwood_Planks",
      "rotation": 2
    },
    {
      "x": -11,
      "y": 7,
      "z": 1,
      "name": "*Wood_Softwood_Fence_State_Definitions_Corner",
      "rotation": 2
    },
    {
      "x": -11,
      "y": 8,
      "z": 1,
      "name": "*Wood_Softwood_Fence_State_Definitions_Corner",
      "rotation": 2
    },
    {
      "x": -11,
      "y": 9,
      "z": 1,
      "name": "Wood_Softwood_Planks",
      "rotation": 2
    },
    {
      "x": -11,
      "y": 10,
      "z": 1,
      "name": "Wood_Deadwood_Roof"
    },
    {
      "x": -11,
      "y": 9,
      "z": 2,
      "name": "Wood_Deadwood_Roof_Hollow"
    },
    {
      "x": -10,
      "y": 4,
      "z": -9,
      "name": "Furniture_Crude_Platform",
      "rotation": 2
    },
    {
      "x": -10,
      "y": 5,
      "z": -9,
      "name": "Wood_Softwood_Planks",
      "rotation": 2
    },
    {
      "x": -10,
      "y": 6,
      "z": -9,
      "name": "Wood_Softwood_Planks",
      "rotation": 2
    },
    {
      "x": -10,
      "y": 7,
      "z": -9,
      "name": "Furniture_Crude_Window",
      "rotation": 2
    },
    {
      "x": -10,
      "y": 8,
      "z": -9,
      "name": "Furniture_Crude_Window",
      "rotation": 2
    },
    {
      "x": -10,
      "y": 9,
      "z": -9,
      "name": "Wood_Softwood_Fence",
      "rotation": 2
    },
    {
      "x": -10,
      "y": 10,
      "z": -9,
      "name": "Empty"
    },
    {
      "x": -10,
      "y": 11,
      "z": -9,
      "name": "Empty"
    },
    {
      "x": -10,
      "y": 12,
      "z": -9,
      "name": "Empty"
    },
    {
      "x": -10,
      "y": 13,
      "z": -9,
      "name": "Empty"
    },
    {
      "x": -10,
      "y": -4,
      "z": -8,
      "name": "Rock_Stone_Cobble",
      "rotation": 2
    },
    {
      "x": -10,
      "y": -3,
      "z": -8,
      "name": "Rock_Stone_Cobble",
      "rotation": 2
    },
    {
      "x": -10,
      "y": -2,
      "z": -8,
      "name": "Rock_Stone_Cobble",
      "rotation": 2
    },
    {
      "x": -10,
      "y": -1,
      "z": -8,
      "name": "Rock_Stone_Cobble",
      "rotation": 2
    },
    {
      "x": -10,
      "y": 0,
      "z": -8,
      "name": "Rock_Stone_Cobble",
      "rotation": 2
    },
    {
      "x": -10,
      "y": 1,
      "z": -8,
      "name": "Rock_Stone_Cobble_Half",
      "rotation": 5
    },
    {
      "x": -10,
      "y": 2,
      "z": -8,
      "name": "Rock_Stone_Cobble_Half",
      "rotation": 5
    },
    {
      "x": -10,
      "y": 3,
      "z": -8,
      "name": "Rock_Stone_Cobble_Half",
      "rotation": 5
    },
    {
      "x": -10,
      "y": 4,
      "z": -8,
      "name": "Rock_Stone_Cobble_Stairs",
      "rotation": 11
    },
    {
      "x": -10,
      "y": 5,
      "z": -8,
      "name": "Wood_Softwood_Planks",
      "rotation": 2
    },
    {
      "x": -10,
      "y": 6,
      "z": -8,
      "name": "Furniture_Village_Crate",
      "rotation": 2
    },
    {
      "x": -10,
      "y": 7,
      "z": -8,
      "name": "Empty"
    },
    {
      "x": -10,
      "y": 8,
      "z": -8,
      "name": "Empty"
    },
    {
      "x": -10,
      "y": 9,
      "z": -8,
      "name": "Empty"
    },
    {
      "x": -10,
      "y": 10,
      "z": -8,
      "name": "Empty"
    },
    {
      "x": -10,
      "y": 11,
      "z": -8,
      "name": "Wood_Deadwood_Roof_Hollow",
      "rotation": 2
    },
    {
      "x": -10,
      "y": 12,
      "z": -8,
      "name": "Empty"
    },
    {
      "x": -10,
      "y": 13,
      "z": -8,
      "name": "Empty"
    },
    {
      "x": -10,
      "y": -3,
      "z": -7,
      "name": "Rock_Stone_Cobble",
      "rotation": 2
    },
    {
      "x": -10,
      "y": -2,
      "z": -7,
      "name": "Rock_Stone_Cobble",
      "rotation": 2
    },
    {
      "x": -10,
      "y": -1,
      "z": -7,
      "name": "Rock_Stone_Cobble",
      "rotation": 2
    },
    {
      "x": -10,
      "y": 0,
      "z": -7,
      "name": "Rock_Stone_Cobble",
      "rotation": 2
    },
    {
      "x": -10,
      "y": 1,
      "z": -7,
      "name": "Empty"
    },
    {
      "x": -10,
      "y": 2,
      "z": -7,
      "name": "Empty"
    },
    {
      "x": -10,
      "y": 3,
      "z": -7,
      "name": "Empty"
    },
    {
      "x": -10,
      "y": 4,
      "z": -7,
      "name": "Empty"
    },
    {
      "x": -10,
      "y": 5,
      "z": -7,
      "name": "Wood_Softwood_Planks",
      "rotation": 2
    },
    {
      "x": -10,
      "y": 6,
      "z": -7,
      "name": "Empty"
    },
    {
      "x": -10,
      "y": 7,
      "z": -7,
      "name": "Empty"
    },
    {
      "x": -10,
      "y": 8,
      "z": -7,
      "name": "Empty"
    },
    {
      "x": -10,
      "y": 9,
      "z": -7,
      "name": "Empty"
    },
    {
      "x": -10,
      "y": 10,
      "z": -7,
      "name": "Empty"
    },
    {
      "x": -10,
      "y": 11,
      "z": -7,
      "name": "Empty"
    },
    {
      "x": -10,
      "y": 12,
      "z": -7,
      "name": "Wood_Softwood_Beam",
      "rotation": 7
    },
    {
      "x": -10,
      "y": 13,
      "z": -7,
      "name": "Empty"
    },
    {
      "x": -10,
      "y": -3,
      "z": -6,
      "name": "Rock_Stone_Cobble",
      "rotation": 2
    },
    {
      "x": -10,
      "y": -2,
      "z": -6,
      "name": "Rock_Stone_Cobble",
      "rotation": 2
    },
    {
      "x": -10,
      "y": -1,
      "z": -6,
      "name": "Rock_Stone_Cobble",
      "rotation": 2
    },
    {
      "x": -10,
      "y": 0,
      "z": -6,
      "name": "Rock_Stone_Cobble",
      "rotation": 2
    },
    {
      "x": -10,
      "y": 1,
      "z": -6,
      "name": "Empty"
    },
    {
      "x": -10,
      "y": 2,
      "z": -6,
      "name": "Empty"
    },
    {
      "x": -10,
      "y": 3,
      "z": -6,
      "name": "Empty"
    },
    {
      "x": -10,
      "y": 4,
      "z": -6,
      "name": "Empty"
    },
    {
      "x": -10,
      "y": 5,
      "z": -6,
      "name": "Wood_Softwood_Planks",
      "rotation": 2
    },
    {
      "x": -10,
      "y": 6,
      "z": -6,
      "name": "Empty"
    },
    {
      "x": -10,
      "y": 7,
      "z": -6,
      "name": "*Wood_Torch_Wall_State_Definitions_Off",
      "rotation": 1
    },
    {
      "x": -10,
      "y": 8,
      "z": -6,
      "name": "Empty"
    },
    {
      "x": -10,
      "y": 9,
      "z": -6,
      "name": "Empty"
    },
    {
      "x": -10,
      "y": 10,
      "z": -6,
      "name": "Empty"
    },
    {
      "x": -10,
      "y": 11,
      "z": -6,
      "name": "Empty"
    },
    {
      "x": -10,
      "y": 12,
      "z": -6,
      "name": "Empty"
    },
    {
      "x": -10,
      "y": 13,
      "z": -6,
      "name": "Wood_Deadwood_Roof_Hollow",
      "rotation": 2
    },
    {
      "x": -10,
      "y": -3,
      "z": -5,
      "name": "Rock_Stone_Cobble",
      "rotation": 2
    },
    {
      "x": -10,
      "y": -2,
      "z": -5,
      "name": "Rock_Stone_Cobble",
      "rotation": 2
    },
    {
      "x": -10,
      "y": -1,
      "z": -5,
      "name": "Rock_Stone_Cobble",
      "rotation": 2
    },
    {
      "x": -10,
      "y": 0,
      "z": -5,
      "name": "Rock_Stone_Cobble",
      "rotation": 2
    },
    {
      "x": -10,
      "y": 1,
      "z": -5,
      "name": "Empty"
    },
    {
      "x": -10,
      "y": 2,
      "z": -5,
      "name": "Empty"
    },
    {
      "x": -10,
      "y": 3,
      "z": -5,
      "name": "Empty"
    },
    {
      "x": -10,
      "y": 4,
      "z": -5,
      "name": "Empty"
    },
    {
      "x": -10,
      "y": 5,
      "z": -5,
      "name": "Wood_Softwood_Planks",
      "rotation": 2
    },
    {
      "x": -10,
      "y": 6,
      "z": -5,
      "name": "Empty"
    },
    {
      "x": -10,
      "y": 7,
      "z": -5,
      "name": "Empty"
    },
    {
      "x": -10,
      "y": 8,
      "z": -5,
      "name": "Empty"
    },
    {
      "x": -10,
      "y": 9,
      "z": -5,
      "name": "Empty"
    },
    {
      "x": -10,
      "y": 10,
      "z": -5,
      "name": "Empty"
    },
    {
      "x": -10,
      "y": 11,
      "z": -5,
      "name": "Empty"
    },
    {
      "x": -10,
      "y": 12,
      "z": -5,
      "name": "Empty"
    },
    {
      "x": -10,
      "y": 13,
      "z": -5,
      "name": "Empty"
    },
    {
      "x": -10,
      "y": 14,
      "z": -5,
      "name": "Wood_Deadwood_Roof_Hollow",
      "rotation": 2
    },
    {
      "x": -10,
      "y": -3,
      "z": -4,
      "name": "Rock_Stone_Cobble",
      "rotation": 2
    },
    {
      "x": -10,
      "y": -2,
      "z": -4,
      "name": "Rock_Stone_Cobble",
      "rotation": 2
    },
    {
      "x": -10,
      "y": -1,
      "z": -4,
      "name": "Rock_Stone_Cobble",
      "rotation": 2
    },
    {
      "x": -10,
      "y": 0,
      "z": -4,
      "name": "Rock_Stone_Cobble",
      "rotation": 2
    },
    {
      "x": -10,
      "y": 1,
      "z": -4,
      "name": "Rail",
      "rotation": 1
    },
    {
      "x": -10,
      "y": 2,
      "z": -4,
      "name": "Empty"
    },
    {
      "x": -10,
      "y": 3,
      "z": -4,
      "name": "Empty"
    },
    {
      "x": -10,
      "y": 4,
      "z": -4,
      "name": "Empty"
    },
    {
      "x": -10,
      "y": 5,
      "z": -4,
      "name": "Wood_Softwood_Planks",
      "rotation": 2
    },
    {
      "x": -10,
      "y": 6,
      "z": -4,
      "name": "Rail",
      "rotation": 1
    },
    {
      "x": -10,
      "y": 7,
      "z": -4,
      "name": "Empty"
    },
    {
      "x": -10,
      "y": 8,
      "z": -4,
      "name": "Empty"
    },
    {
      "x": -10,
      "y": 9,
      "z": -4,
      "name": "Empty"
    },
    {
      "x": -10,
      "y": 10,
      "z": -4,
      "name": "Empty"
    },
    {
      "x": -10,
      "y": 11,
      "z": -4,
      "name": "Empty"
    },
    {
      "x": -10,
      "y": 12,
      "z": -4,
      "name": "Empty"
    },
    {
      "x": -10,
      "y": 13,
      "z": -4,
      "name": "Empty"
    },
    {
      "x": -10,
      "y": 15,
      "z": -4,
      "name": "Wood_Deadwood_Roof_Flat",
      "rotation": 2
    },
    {
      "x": -10,
      "y": -3,
      "z": -3,
      "name": "Rock_Stone_Cobble",
      "rotation": 2
    },
    {
      "x": -10,
      "y": -2,
      "z": -3,
      "name": "Rock_Stone_Cobble",
      "rotation": 2
    },
    {
      "x": -10,
      "y": -1,
      "z": -3,
      "name": "Rock_Stone_Cobble",
      "rotation": 2
    },
    {
      "x": -10,
      "y": 0,
      "z": -3,
      "name": "Rock_Stone_Cobble",
      "rotation": 2
    },
    {
      "x": -10,
      "y": 1,
      "z": -3,
      "name": "Empty"
    },
    {
      "x": -10,
      "y": 2,
      "z": -3,
      "name": "Empty"
    },
    {
      "x": -10,
      "y": 3,
      "z": -3,
      "name": "Empty"
    },
    {
      "x": -10,
      "y": 4,
      "z": -3,
      "name": "Empty"
    },
    {
      "x": -10,
      "y": 5,
      "z": -3,
      "name": "Wood_Softwood_Planks",
      "rotation": 2
    },
    {
      "x": -10,
      "y": 6,
      "z": -3,
      "name": "Empty"
    },
    {
      "x": -10,
      "y": 7,
      "z": -3,
      "name": "Empty"
    },
    {
      "x": -10,
      "y": 8,
      "z": -3,
      "name": "Empty"
    },
    {
      "x": -10,
      "y": 9,
      "z": -3,
      "name": "Empty"
    },
    {
      "x": -10,
      "y": 10,
      "z": -3,
      "name": "Empty"
    },
    {
      "x": -10,
      "y": 11,
      "z": -3,
      "name": "Empty"
    },
    {
      "x": -10,
      "y": 12,
      "z": -3,
      "name": "Empty"
    },
    {
      "x": -10,
      "y": 13,
      "z": -3,
      "name": "Empty"
    },
    {
      "x": -10,
      "y": 14,
      "z": -3,
      "name": "Wood_Deadwood_Roof_Hollow"
    },
    {
      "x": -10,
      "y": -3,
      "z": -2,
      "name": "Rock_Stone_Cobble",
      "rotation": 2
    },
    {
      "x": -10,
      "y": -2,
      "z": -2,
      "name": "Rock_Stone_Cobble",
      "rotation": 2
    },
    {
      "x": -10,
      "y": -1,
      "z": -2,
      "name": "Rock_Stone_Cobble",
      "rotation": 2
    },
    {
      "x": -10,
      "y": 0,
      "z": -2,
      "name": "Rock_Stone_Cobble",
      "rotation": 2
    },
    {
      "x": -10,
      "y": 1,
      "z": -2,
      "name": "Bench_Furnace",
      "components": {
        "Components": {
          "processingBench": {
            "Position": {
              "X": -10,
              "Y": 1,
              "Z": -2
            },
            "TierLevel": 1,
            "UpgradeItems": [],
            "InputContainer": {
              "Id": "Simple",
              "Capacity": 2,
              "Items": {}
            },
            "FuelContainer": {
              "Id": "Simple",
              "Capacity": 2,
              "Items": {}
            },
            "OutputContainer": {
              "Id": "Simple",
              "Capacity": 4,
              "Items": {}
            },
            "Progress": 0.0,
            "FuelTime": 0.0,
            "Active": false,
            "NextExtra": 2
          },
          "PlacedByInteraction": {
            "WhoPlacedUuid": {
              "$binary": "x9M0GYCLPG+IqIodoDzEcQ==",
              "$type": "04"
            }
          }
        }
      },
      "rotation": 1
    },
    {
      "x": -10,
      "y": 2,
      "z": -2,
      "name": "Bench_Furnace",
      "components": {
        "Components": {
          "processingBench": {
            "Position": {
              "X": 22,
              "Y": 2,
              "Z": 30
            },
            "TierLevel": 1,
            "UpgradeItems": [],
            "Progress": 0.0,
            "FuelTime": 0.0,
            "Active": false,
            "NextExtra": -1
          }
        }
      },
      "filler": 1024,
      "rotation": 1
    },
    {
      "x": -10,
      "y": 3,
      "z": -2,
      "name": "Empty"
    },
    {
      "x": -10,
      "y": 4,
      "z": -2,
      "name": "Empty"
    },
    {
      "x": -10,
      "y": 5,
      "z": -2,
      "name": "Wood_Softwood_Planks",
      "rotation": 2
    },
    {
      "x": -10,
      "y": 6,
      "z": -2,
      "name": "Empty"
    },
    {
      "x": -10,
      "y": 7,
      "z": -2,
      "name": "Empty"
    },
    {
      "x": -10,
      "y": 8,
      "z": -2,
      "name": "Empty"
    },
    {
      "x": -10,
      "y": 9,
      "z": -2,
      "name": "Empty"
    },
    {
      "x": -10,
      "y": 10,
      "z": -2,
      "name": "Empty"
    },
    {
      "x": -10,
      "y": 11,
      "z": -2,
      "name": "Empty"
    },
    {
      "x": -10,
      "y": 12,
      "z": -2,
      "name": "Empty"
    },
    {
      "x": -10,
      "y": 13,
      "z": -2,
      "name": "Wood_Softwood_Beam",
      "rotation": 7
    },
    {
      "x": -10,
      "y": -3,
      "z": -1,
      "name": "Rock_Stone_Cobble",
      "rotation": 2
    },
    {
      "x": -10,
      "y": -2,
      "z": -1,
      "name": "Rock_Stone_Cobble",
      "rotation": 2
    },
    {
      "x": -10,
      "y": -1,
      "z": -1,
      "name": "Rock_Stone_Cobble",
      "rotation": 2
    },
    {
      "x": -10,
      "y": 0,
      "z": -1,
      "name": "Rock_Stone_Cobble",
      "rotation": 2
    },
    {
      "x": -10,
      "y": 1,
      "z": -1,
      "name": "Bench_Furnace",
      "components": {
        "Components": {
          "processingBench": {
            "Position": {
              "X": 22,
              "Y": 1,
              "Z": 31
            },
            "TierLevel": 1,
            "UpgradeItems": [],
            "Progress": 0.0,
            "FuelTime": 0.0,
            "Active": false,
            "NextExtra": -1
          }
        }
      },
      "filler": 32,
      "rotation": 1
    },
    {
      "x": -10,
      "y": 2,
      "z": -1,
      "name": "Bench_Furnace",
      "components": {
        "Components": {
          "processingBench": {
            "Position": {
              "X": 22,
              "Y": 2,
              "Z": 31
            },
            "TierLevel": 1,
            "UpgradeItems": [],
            "Progress": 0.0,
            "FuelTime": 0.0,
            "Active": false,
            "NextExtra": -1
          }
        }
      },
      "filler": 1056,
      "rotation": 1
    },
    {
      "x": -10,
      "y": 3,
      "z": -1,
      "name": "Empty"
    },
    {
      "x": -10,
      "y": 4,
      "z": -1,
      "name": "Empty"
    },
    {
      "x": -10,
      "y": 5,
      "z": -1,
      "name": "Wood_Softwood_Planks",
      "rotation": 2
    },
    {
      "x": -10,
      "y": 6,
      "z": -1,
      "name": "Empty"
    },
    {
      "x": -10,
      "y": 7,
      "z": -1,
      "name": "Empty"
    },
    {
      "x": -10,
      "y": 8,
      "z": -1,
      "name": "Empty"
    },
    {
      "x": -10,
      "y": 9,
      "z": -1,
      "name": "Empty"
    },
    {
      "x": -10,
      "y": 10,
      "z": -1,
      "name": "Empty"
    },
    {
      "x": -10,
      "y": 11,
      "z": -1,
      "name": "Empty"
    },
    {
      "x": -10,
      "y": 12,
      "z": -1,
      "name": "Wood_Softwood_Beam",
      "rotation": 7
    },
    {
      "x": -10,
      "y": 13,
      "z": -1,
      "name": "Empty"
    },
    {
      "x": -10,
      "y": -4,
      "z": 0,
      "name": "Rock_Stone_Cobble",
      "rotation": 2
    },
    {
      "x": -10,
      "y": -3,
      "z": 0,
      "name": "Rock_Stone_Cobble",
      "rotation": 2
    },
    {
      "x": -10,
      "y": -2,
      "z": 0,
      "name": "Rock_Stone_Cobble",
      "rotation": 2
    },
    {
      "x": -10,
      "y": -1,
      "z": 0,
      "name": "Rock_Stone_Cobble",
      "rotation": 2
    },
    {
      "x": -10,
      "y": 0,
      "z": 0,
      "name": "Rock_Stone_Cobble",
      "rotation": 2
    },
    {
      "x": -10,
      "y": 1,
      "z": 0,
      "name": "Rock_Stone",
      "rotation": 2
    },
    {
      "x": -10,
      "y": 2,
      "z": 0,
      "name": "Rock_Stone",
      "rotation": 2
    },
    {
      "x": -10,
      "y": 3,
      "z": 0,
      "name": "Rock_Stone",
      "rotation": 2
    },
    {
      "x": -10,
      "y": 4,
      "z": 0,
      "name": "Rock_Stone",
      "rotation": 2
    },
    {
      "x": -10,
      "y": 5,
      "z": 0,
      "name": "Wood_Softwood_Planks",
      "rotation": 2
    },
    {
      "x": -10,
      "y": 6,
      "z": 0,
      "name": "Empty"
    },
    {
      "x": -10,
      "y": 7,
      "z": 0,
      "name": "Empty"
    },
    {
      "x": -10,
      "y": 8,
      "z": 0,
      "name": "Empty"
    },
    {
      "x": -10,
      "y": 9,
      "z": 0,
      "name": "Empty"
    },
    {
      "x": -10,
      "y": 10,
      "z": 0,
      "name": "Empty"
    },
    {
      "x": -10,
      "y": 11,
      "z": 0,
      "name": "Wood_Softwood_Beam",
      "rotation": 7
    },
    {
      "x": -10,
      "y": 12,
      "z": 0,
      "name": "Empty"
    },
    {
      "x": -10,
      "y": 13,
      "z": 0,
      "name": "Empty"
    },
    {
      "x": -10,
      "y": -2,
      "z": 1,
      "name": "Wood_Beech_Trunk",
      "support": 15,
      "rotation": 2
    },
    {
      "x": -10,
      "y": -1,
      "z": 1,
      "name": "Wood_Beech_Trunk",
      "support": 15,
      "rotation": 2
    },
    {
      "x": -10,
      "y": 0,
      "z": 1,
      "name": "Wood_Beech_Trunk",
      "support": 15,
      "rotation": 2
    },
    {
      "x": -10,
      "y": 1,
      "z": 1,
      "name": "Wood_Beech_Trunk",
      "support": 15,
      "rotation": 2
    },
    {
      "x": -10,
      "y": 2,
      "z": 1,
      "name": "Wood_Beech_Trunk",
      "support": 15,
      "rotation": 2
    },
    {
      "x": -10,
      "y": 3,
      "z": 1,
      "name": "Wood_Beech_Trunk",
      "support": 15,
      "rotation": 2
    },
    {
      "x": -10,
      "y": 4,
      "z": 1,
      "name": "Wood_Beech_Trunk",
      "support": 15,
      "rotation": 2
    },
    {
      "x": -10,
      "y": 5,
      "z": 1,
      "name": "Wood_Softwood_Planks",
      "rotation": 2
    },
    {
      "x": -10,
      "y": 6,
      "z": 1,
      "name": "Wood_Softwood_Planks",
      "rotation": 2
    },
    {
      "x": -10,
      "y": 7,
      "z": 1,
      "name": "Wood_Softwood_Fence"
    },
    {
      "x": -10,
      "y": 8,
      "z": 1,
      "name": "Wood_Softwood_Fence"
    },
    {
      "x": -10,
      "y": 9,
      "z": 1,
      "name": "Wood_Softwood_Planks",
      "rotation": 2
    },
    {
      "x": -10,
      "y": 10,
      "z": 1,
      "name": "Wood_Softwood_Beam",
      "rotation": 7
    },
    {
      "x": -10,
      "y": 0,
      "z": 2,
      "name": "Wood_Softwood_Planks",
      "rotation": 2
    },
    {
      "x": -10,
      "y": 1,
      "z": 2,
      "name": "Wood_Softwood_Planks",
      "rotation": 2
    },
    {
      "x": -10,
      "y": 2,
      "z": 2,
      "name": "Wood_Softwood_Planks",
      "rotation": 2
    },
    {
      "x": -10,
      "y": 3,
      "z": 2,
      "name": "Wood_Softwood_Planks",
      "rotation": 2
    },
    {
      "x": -10,
      "y": 4,
      "z": 2,
      "name": "Wood_Softwood_Planks",
      "rotation": 2
    },
    {
      "x": -10,
      "y": 5,
      "z": 2,
      "name": "Wood_Softwood_Planks",
      "rotation": 2
    },
    {
      "x": -10,
      "y": 6,
      "z": 2,
      "name": "Wood_Deadwood_Roof"
    },
    {
      "x": -10,
      "y": 9,
      "z": 2,
      "name": "Wood_Deadwood_Roof_Hollow"
    },
    {
      "x": -10,
      "y": 0,
      "z": 3,
      "name": "Wood_Softwood_Planks",
      "rotation": 2
    },
    {
      "x": -10,
      "y": 1,
      "z": 3,
      "name": "Wood_Softwood_Planks",
      "rotation": 2
    },
    {
      "x": -10,
      "y": 2,
      "z": 3,
      "name": "Wood_Softwood_Planks",
      "rotation": 2
    },
    {
      "x": -10,
      "y": 3,
      "z": 3,
      "name": "Wood_Softwood_Planks",
      "rotation": 2
    },
    {
      "x": -10,
      "y": 4,
      "z": 3,
      "name": "Wood_Softwood_Planks",
      "rotation": 2
    },
    {
      "x": -10,
      "y": 5,
      "z": 3,
      "name": "Wood_Softwood_Planks",
      "rotation": 2
    },
    {
      "x": -10,
      "y": 0,
      "z": 4,
      "name": "Wood_Softwood_Planks",
      "rotation": 2
    },
    {
      "x": -10,
      "y": 1,
      "z": 4,
      "name": "Wood_Softwood_Decorative",
      "rotation": 2
    },
    {
      "x": -10,
      "y": 2,
      "z": 4,
      "name": "Wood_Softwood_Decorative",
      "rotation": 2
    },
    {
      "x": -10,
      "y": 3,
      "z": 4,
      "name": "Wood_Softwood_Decorative",
      "rotation": 2
    },
    {
      "x": -10,
      "y": 4,
      "z": 4,
      "name": "Wood_Softwood_Decorative",
      "rotation": 2
    },
    {
      "x": -10,
      "y": 5,
      "z": 4,
      "name": "Wood_Deadwood_Roof"
    },
    {
      "x": -10,
      "y": -3,
      "z": 5,
      "name": "Wood_Beech_Trunk",
      "support": 15,
      "rotation": 2
    },
    {
      "x": -10,
      "y": -2,
      "z": 5,
      "name": "Wood_Beech_Trunk",
      "support": 15,
      "rotation": 2
    },
    {
      "x": -10,
      "y": -1,
      "z": 5,
      "name": "Wood_Beech_Trunk",
      "support": 15,
      "rotation": 2
    },
    {
      "x": -10,
      "y": 0,
      "z": 5,
      "name": "Wood_Beech_Trunk",
      "support": 15,
      "rotation": 2
    },
    {
      "x": -10,
      "y": 1,
      "z": 5,
      "name": "Wood_Beech_Trunk",
      "support": 15,
      "rotation": 2
    },
    {
      "x": -10,
      "y": 2,
      "z": 5,
      "name": "Wood_Beech_Trunk",
      "support": 15,
      "rotation": 2
    },
    {
      "x": -10,
      "y": 3,
      "z": 5,
      "name": "Wood_Beech_Trunk",
      "support": 15,
      "rotation": 2
    },
    {
      "x": -10,
      "y": 4,
      "z": 5,
      "name": "Wood_Beech_Trunk",
      "support": 15,
      "rotation": 2
    },
    {
      "x": -10,
      "y": 4,
      "z": 6,
      "name": "Wood_Deadwood_Roof_Hollow"
    },
    {
      "x": -9,
      "y": 0,
      "z": -10,
      "name": "Wood_Softwood_Planks",
      "rotation": 2
    },
    {
      "x": -9,
      "y": 1,
      "z": -10,
      "name": "*Rail_State_Definitions_Corner_Left",
      "rotation": 1
    },
    {
      "x": -9,
      "y": 2,
      "z": -10,
      "name": "Empty"
    },
    {
      "x": -9,
      "y": 3,
      "z": -10,
      "name": "Empty"
    },
    {
      "x": -9,
      "y": 4,
      "z": -10,
      "name": "Empty"
    },
    {
      "x": -9,
      "y": 9,
      "z": -10,
      "name": "Wood_Deadwood_Roof_Hollow",
      "rotation": 2
    },
    {
      "x": -9,
      "y": 0,
      "z": -9,
      "name": "Wood_Softwood_Planks",
      "rotation": 2
    },
    {
      "x": -9,
      "y": 1,
      "z": -9,
      "name": "Rail",
      "rotation": 2
    },
    {
      "x": -9,
      "y": 2,
      "z": -9,
      "name": "Empty"
    },
    {
      "x": -9,
      "y": 4,
      "z": -9,
      "name": "Furniture_Crude_Platform",
      "rotation": 2
    },
    {
      "x": -9,
      "y": 5,
      "z": -9,
      "name": "Wood_Softwood_Planks",
      "rotation": 2
    },
    {
      "x": -9,
      "y": 6,
      "z": -9,
      "name": "Wood_Softwood_Planks",
      "rotation": 2
    },
    {
      "x": -9,
      "y": 7,
      "z": -9,
      "name": "Wood_Softwood_Planks",
      "rotation": 2
    },
    {
      "x": -9,
      "y": 8,
      "z": -9,
      "name": "Wood_Softwood_Fence",
      "rotation": 2
    },
    {
      "x": -9,
      "y": 9,
      "z": -9,
      "name": "Wood_Softwood_Fence",
      "rotation": 2
    },
    {
      "x": -9,
      "y": 10,
      "z": -9,
      "name": "Empty"
    },
    {
      "x": -9,
      "y": 11,
      "z": -9,
      "name": "Empty"
    },
    {
      "x": -9,
      "y": 12,
      "z": -9,
      "name": "Empty"
    },
    {
      "x": -9,
      "y": 13,
      "z": -9,
      "name": "Empty"
    },
    {
      "x": -9,
      "y": -2,
      "z": -8,
      "name": "Rock_Stone_Cobble",
      "rotation": 2
    },
    {
      "x": -9,
      "y": -1,
      "z": -8,
      "name": "Rock_Stone_Cobble",
      "rotation": 2
    },
    {
      "x": -9,
      "y": 0,
      "z": -8,
      "name": "Rock_Stone_Cobble",
      "rotation": 2
    },
    {
      "x": -9,
      "y": 1,
      "z": -8,
      "name": "Rail"
    },
    {
      "x": -9,
      "y": 2,
      "z": -8,
      "name": "Empty"
    },
    {
      "x": -9,
      "y": 3,
      "z": -8,
      "name": "Empty"
    },
    {
      "x": -9,
      "y": 4,
      "z": -8,
      "name": "Rock_Stone_Cobble_Half",
      "rotation": 10
    },
    {
      "x": -9,
      "y": 5,
      "z": -8,
      "name": "Wood_Softwood_Planks",
      "rotation": 2
    },
    {
      "x": -9,
      "y": 6,
      "z": -8,
      "name": "Empty"
    },
    {
      "x": -9,
      "y": 7,
      "z": -8,
      "name": "Empty"
    },
    {
      "x": -9,
      "y": 8,
      "z": -8,
      "name": "Empty"
    },
    {
      "x": -9,
      "y": 9,
      "z": -8,
      "name": "Empty"
    },
    {
      "x": -9,
      "y": 10,
      "z": -8,
      "name": "Empty"
    },
    {
      "x": -9,
      "y": 11,
      "z": -8,
      "name": "Wood_Deadwood_Roof_Hollow",
      "rotation": 2
    },
    {
      "x": -9,
      "y": 12,
      "z": -8,
      "name": "Empty"
    },
    {
      "x": -9,
      "y": 13,
      "z": -8,
      "name": "Empty"
    },
    {
      "x": -9,
      "y": -3,
      "z": -7,
      "name": "Rock_Stone_Cobble",
      "rotation": 2
    },
    {
      "x": -9,
      "y": -2,
      "z": -7,
      "name": "Rock_Stone_Cobble",
      "rotation": 2
    },
    {
      "x": -9,
      "y": -1,
      "z": -7,
      "name": "Rock_Stone_Cobble",
      "rotation": 2
    },
    {
      "x": -9,
      "y": 0,
      "z": -7,
      "name": "Rock_Stone_Cobble",
      "rotation": 2
    },
    {
      "x": -9,
      "y": 1,
      "z": -7,
      "name": "Rail"
    },
    {
      "x": -9,
      "y": 2,
      "z": -7,
      "name": "Empty"
    },
    {
      "x": -9,
      "y": 3,
      "z": -7,
      "name": "Empty"
    },
    {
      "x": -9,
      "y": 4,
      "z": -7,
      "name": "Empty"
    },
    {
      "x": -9,
      "y": 5,
      "z": -7,
      "name": "Wood_Softwood_Planks",
      "rotation": 2
    },
    {
      "x": -9,
      "y": 6,
      "z": -7,
      "name": "Empty"
    },
    {
      "x": -9,
      "y": 7,
      "z": -7,
      "name": "Empty"
    },
    {
      "x": -9,
      "y": 8,
      "z": -7,
      "name": "Empty"
    },
    {
      "x": -9,
      "y": 9,
      "z": -7,
      "name": "Empty"
    },
    {
      "x": -9,
      "y": 10,
      "z": -7,
      "name": "Empty"
    },
    {
      "x": -9,
      "y": 11,
      "z": -7,
      "name": "Empty"
    },
    {
      "x": -9,
      "y": 12,
      "z": -7,
      "name": "Wood_Softwood_Beam",
      "rotation": 7
    },
    {
      "x": -9,
      "y": 13,
      "z": -7,
      "name": "Empty"
    },
    {
      "x": -9,
      "y": -3,
      "z": -6,
      "name": "Rock_Stone_Cobble",
      "rotation": 2
    },
    {
      "x": -9,
      "y": -2,
      "z": -6,
      "name": "Rock_Stone_Cobble",
      "rotation": 2
    },
    {
      "x": -9,
      "y": -1,
      "z": -6,
      "name": "Rock_Stone_Cobble",
      "rotation": 2
    },
    {
      "x": -9,
      "y": 0,
      "z": -6,
      "name": "Rock_Stone_Cobble",
      "rotation": 2
    },
    {
      "x": -9,
      "y": 1,
      "z": -6,
      "name": "Rail"
    },
    {
      "x": -9,
      "y": 2,
      "z": -6,
      "name": "Empty"
    },
    {
      "x": -9,
      "y": 3,
      "z": -6,
      "name": "Empty"
    },
    {
      "x": -9,
      "y": 4,
      "z": -6,
      "name": "Empty"
    },
    {
      "x": -9,
      "y": 5,
      "z": -6,
      "name": "Wood_Softwood_Planks",
      "rotation": 2
    },
    {
      "x": -9,
      "y": 6,
      "z": -6,
      "name": "Empty"
    },
    {
      "x": -9,
      "y": 7,
      "z": -6,
      "name": "Empty"
    },
    {
      "x": -9,
      "y": 8,
      "z": -6,
      "name": "Empty"
    },
    {
      "x": -9,
      "y": 9,
      "z": -6,
      "name": "Empty"
    },
    {
      "x": -9,
      "y": 10,
      "z": -6,
      "name": "Empty"
    },
    {
      "x": -9,
      "y": 11,
      "z": -6,
      "name": "Empty"
    },
    {
      "x": -9,
      "y": 12,
      "z": -6,
      "name": "Empty"
    },
    {
      "x": -9,
      "y": 13,
      "z": -6,
      "name": "Wood_Deadwood_Roof_Hollow",
      "rotation": 2
    },
    {
      "x": -9,
      "y": -3,
      "z": -5,
      "name": "Rock_Stone_Cobble",
      "rotation": 2
    },
    {
      "x": -9,
      "y": -2,
      "z": -5,
      "name": "Rock_Stone_Cobble",
      "rotation": 2
    },
    {
      "x": -9,
      "y": -1,
      "z": -5,
      "name": "Rock_Stone_Cobble",
      "rotation": 2
    },
    {
      "x": -9,
      "y": 0,
      "z": -5,
      "name": "Rock_Stone_Cobble",
      "rotation": 2
    },
    {
      "x": -9,
      "y": 1,
      "z": -5,
      "name": "Rail"
    },
    {
      "x": -9,
      "y": 2,
      "z": -5,
      "name": "Empty"
    },
    {
      "x": -9,
      "y": 3,
      "z": -5,
      "name": "Empty"
    },
    {
      "x": -9,
      "y": 4,
      "z": -5,
      "name": "Empty"
    },
    {
      "x": -9,
      "y": 5,
      "z": -5,
      "name": "Wood_Softwood_Planks",
      "rotation": 2
    },
    {
      "x": -9,
      "y": 6,
      "z": -5,
      "name": "Empty"
    },
    {
      "x": -9,
      "y": 7,
      "z": -5,
      "name": "Empty"
    },
    {
      "x": -9,
      "y": 8,
      "z": -5,
      "name": "Empty"
    },
    {
      "x": -9,
      "y": 9,
      "z": -5,
      "name": "Empty"
    },
    {
      "x": -9,
      "y": 10,
      "z": -5,
      "name": "Empty"
    },
    {
      "x": -9,
      "y": 11,
      "z": -5,
      "name": "Empty"
    },
    {
      "x": -9,
      "y": 12,
      "z": -5,
      "name": "Empty"
    },
    {
      "x": -9,
      "y": 13,
      "z": -5,
      "name": "Empty"
    },
    {
      "x": -9,
      "y": 14,
      "z": -5,
      "name": "Wood_Deadwood_Roof_Hollow",
      "rotation": 2
    },
    {
      "x": -9,
      "y": -3,
      "z": -4,
      "name": "Rock_Stone_Cobble",
      "rotation": 2
    },
    {
      "x": -9,
      "y": -2,
      "z": -4,
      "name": "Rock_Stone_Cobble",
      "rotation": 2
    },
    {
      "x": -9,
      "y": -1,
      "z": -4,
      "name": "Rock_Stone_Cobble",
      "rotation": 2
    },
    {
      "x": -9,
      "y": 0,
      "z": -4,
      "name": "Rock_Stone_Cobble",
      "rotation": 2
    },
    {
      "x": -9,
      "y": 1,
      "z": -4,
      "name": "*Rail_State_Definitions_T",
      "rotation": 2
    },
    {
      "x": -9,
      "y": 2,
      "z": -4,
      "name": "Empty"
    },
    {
      "x": -9,
      "y": 3,
      "z": -4,
      "name": "Empty"
    },
    {
      "x": -9,
      "y": 4,
      "z": -4,
      "name": "Empty"
    },
    {
      "x": -9,
      "y": 5,
      "z": -4,
      "name": "Wood_Softwood_Planks",
      "rotation": 2
    },
    {
      "x": -9,
      "y": 6,
      "z": -4,
      "name": "Rail",
      "rotation": 1
    },
    {
      "x": -9,
      "y": 7,
      "z": -4,
      "name": "Empty"
    },
    {
      "x": -9,
      "y": 8,
      "z": -4,
      "name": "Empty"
    },
    {
      "x": -9,
      "y": 9,
      "z": -4,
      "name": "Empty"
    },
    {
      "x": -9,
      "y": 10,
      "z": -4,
      "name": "Empty"
    },
    {
      "x": -9,
      "y": 11,
      "z": -4,
      "name": "Empty"
    },
    {
      "x": -9,
      "y": 12,
      "z": -4,
      "name": "Empty"
    },
    {
      "x": -9,
      "y": 13,
      "z": -4,
      "name": "Empty"
    },
    {
      "x": -9,
      "y": -3,
      "z": -3,
      "name": "Rock_Stone_Cobble",
      "rotation": 2
    },
    {
      "x": -9,
      "y": -2,
      "z": -3,
      "name": "Rock_Stone_Cobble",
      "rotation": 2
    },
    {
      "x": -9,
      "y": -1,
      "z": -3,
      "name": "Rock_Stone_Cobble",
      "rotation": 2
    },
    {
      "x": -9,
      "y": 0,
      "z": -3,
      "name": "Rock_Stone_Cobble",
      "rotation": 2
    },
    {
      "x": -9,
      "y": 1,
      "z": -3,
      "name": "Empty"
    },
    {
      "x": -9,
      "y": 2,
      "z": -3,
      "name": "Empty"
    },
    {
      "x": -9,
      "y": 3,
      "z": -3,
      "name": "Empty"
    },
    {
      "x": -9,
      "y": 4,
      "z": -3,
      "name": "Empty"
    },
    {
      "x": -9,
      "y": 5,
      "z": -3,
      "name": "Wood_Softwood_Planks",
      "rotation": 2
    },
    {
      "x": -9,
      "y": 6,
      "z": -3,
      "name": "Empty"
    },
    {
      "x": -9,
      "y": 7,
      "z": -3,
      "name": "Empty"
    },
    {
      "x": -9,
      "y": 8,
      "z": -3,
      "name": "Empty"
    },
    {
      "x": -9,
      "y": 9,
      "z": -3,
      "name": "Empty"
    },
    {
      "x": -9,
      "y": 10,
      "z": -3,
      "name": "Empty"
    },
    {
      "x": -9,
      "y": 11,
      "z": -3,
      "name": "Empty"
    },
    {
      "x": -9,
      "y": 12,
      "z": -3,
      "name": "Empty"
    },
    {
      "x": -9,
      "y": 13,
      "z": -3,
      "name": "Empty"
    },
    {
      "x": -9,
      "y": -3,
      "z": -2,
      "name": "Rock_Stone_Cobble",
      "rotation": 2
    },
    {
      "x": -9,
      "y": -2,
      "z": -2,
      "name": "Rock_Stone_Cobble",
      "rotation": 2
    },
    {
      "x": -9,
      "y": -1,
      "z": -2,
      "name": "Rock_Stone_Cobble",
      "rotation": 2
    },
    {
      "x": -9,
      "y": 0,
      "z": -2,
      "name": "Rock_Stone_Cobble",
      "rotation": 2
    },
    {
      "x": -9,
      "y": 1,
      "z": -2,
      "name": "Empty"
    },
    {
      "x": -9,
      "y": 2,
      "z": -2,
      "name": "Empty"
    },
    {
      "x": -9,
      "y": 3,
      "z": -2,
      "name": "Empty"
    },
    {
      "x": -9,
      "y": 4,
      "z": -2,
      "name": "Empty"
    },
    {
      "x": -9,
      "y": 5,
      "z": -2,
      "name": "Wood_Softwood_Planks",
      "rotation": 2
    },
    {
      "x": -9,
      "y": 6,
      "z": -2,
      "name": "Empty"
    },
    {
      "x": -9,
      "y": 7,
      "z": -2,
      "name": "Empty"
    },
    {
      "x": -9,
      "y": 8,
      "z": -2,
      "name": "Empty"
    },
    {
      "x": -9,
      "y": 9,
      "z": -2,
      "name": "Empty"
    },
    {
      "x": -9,
      "y": 10,
      "z": -2,
      "name": "Empty"
    },
    {
      "x": -9,
      "y": 11,
      "z": -2,
      "name": "Empty"
    },
    {
      "x": -9,
      "y": 12,
      "z": -2,
      "name": "Empty"
    },
    {
      "x": -9,
      "y": 13,
      "z": -2,
      "name": "Wood_Deadwood_Roof_Hollow"
    },
    {
      "x": -9,
      "y": -3,
      "z": -1,
      "name": "Rock_Stone_Cobble",
      "rotation": 2
    },
    {
      "x": -9,
      "y": -2,
      "z": -1,
      "name": "Rock_Stone_Cobble",
      "rotation": 2
    },
    {
      "x": -9,
      "y": -1,
      "z": -1,
      "name": "Rock_Stone_Cobble",
      "rotation": 2
    },
    {
      "x": -9,
      "y": 0,
      "z": -1,
      "name": "Rock_Stone_Cobble",
      "rotation": 2
    },
    {
      "x": -9,
      "y": 1,
      "z": -1,
      "name": "Empty"
    },
    {
      "x": -9,
      "y": 2,
      "z": -1,
      "name": "Empty"
    },
    {
      "x": -9,
      "y": 3,
      "z": -1,
      "name": "Empty"
    },
    {
      "x": -9,
      "y": 4,
      "z": -1,
      "name": "Empty"
    },
    {
      "x": -9,
      "y": 5,
      "z": -1,
      "name": "Wood_Softwood_Planks",
      "rotation": 2
    },
    {
      "x": -9,
      "y": 6,
      "z": -1,
      "name": "Empty"
    },
    {
      "x": -9,
      "y": 7,
      "z": -1,
      "name": "Empty"
    },
    {
      "x": -9,
      "y": 8,
      "z": -1,
      "name": "Empty"
    },
    {
      "x": -9,
      "y": 9,
      "z": -1,
      "name": "Empty"
    },
    {
      "x": -9,
      "y": 10,
      "z": -1,
      "name": "Empty"
    },
    {
      "x": -9,
      "y": 11,
      "z": -1,
      "name": "Empty"
    },
    {
      "x": -9,
      "y": 12,
      "z": -1,
      "name": "Wood_Softwood_Beam",
      "rotation": 7
    },
    {
      "x": -9,
      "y": 13,
      "z": -1,
      "name": "Empty"
    },
    {
      "x": -9,
      "y": -3,
      "z": 0,
      "name": "Rock_Stone_Cobble",
      "rotation": 2
    },
    {
      "x": -9,
      "y": -2,
      "z": 0,
      "name": "Rock_Stone_Cobble",
      "rotation": 2
    },
    {
      "x": -9,
      "y": -1,
      "z": 0,
      "name": "Rock_Stone_Cobble",
      "rotation": 2
    },
    {
      "x": -9,
      "y": 0,
      "z": 0,
      "name": "Rock_Stone_Cobble",
      "rotation": 2
    },
    {
      "x": -9,
      "y": 1,
      "z": 0,
      "name": "Rock_Stone",
      "rotation": 2
    },
    {
      "x": -9,
      "y": 2,
      "z": 0,
      "name": "Rock_Stone",
      "rotation": 2
    },
    {
      "x": -9,
      "y": 3,
      "z": 0,
      "name": "Rock_Stone",
      "rotation": 2
    },
    {
      "x": -9,
      "y": 4,
      "z": 0,
      "name": "Rock_Stone",
      "rotation": 2
    },
    {
      "x": -9,
      "y": 5,
      "z": 0,
      "name": "Wood_Softwood_Planks",
      "rotation": 2
    },
    {
      "x": -9,
      "y": 6,
      "z": 0,
      "name": "Furniture_Village_Crate",
      "rotation": 2
    },
    {
      "x": -9,
      "y": 7,
      "z": 0,
      "name": "Empty"
    },
    {
      "x": -9,
      "y": 8,
      "z": 0,
      "name": "Empty"
    },
    {
      "x": -9,
      "y": 9,
      "z": 0,
      "name": "Plant_Moss_Wall_Green",
      "rotation": 2
    },
    {
      "x": -9,
      "y": 10,
      "z": 0,
      "name": "Empty"
    },
    {
      "x": -9,
      "y": 11,
      "z": 0,
      "name": "Wood_Softwood_Beam",
      "rotation": 7
    },
    {
      "x": -9,
      "y": 12,
      "z": 0,
      "name": "Empty"
    },
    {
      "x": -9,
      "y": 13,
      "z": 0,
      "name": "Empty"
    },
    {
      "x": -9,
      "y": 0,
      "z": 1,
      "name": "Wood_Softwood_Planks",
      "rotation": 2
    },
    {
      "x": -9,
      "y": 1,
      "z": 1,
      "name": "Wood_Softwood_Planks",
      "rotation": 2
    },
    {
      "x": -9,
      "y": 5,
      "z": 1,
      "name": "Furniture_Crude_Platform",
      "rotation": 2
    },
    {
      "x": -9,
      "y": 6,
      "z": 1,
      "name": "Wood_Softwood_Planks",
      "rotation": 2
    },
    {
      "x": -9,
      "y": 7,
      "z": 1,
      "name": "Wood_Softwood_Planks",
      "rotation": 2
    },
    {
      "x": -9,
      "y": 8,
      "z": 1,
      "name": "Wood_Softwood_Fence"
    },
    {
      "x": -9,
      "y": 9,
      "z": 1,
      "name": "Wood_Softwood_Planks",
      "rotation": 2
    },
    {
      "x": -9,
      "y": 10,
      "z": 1,
      "name": "Wood_Deadwood_Roof_Hollow"
    },
    {
      "x": -9,
      "y": 0,
      "z": 2,
      "name": "Wood_Softwood_Planks",
      "rotation": 2
    },
    {
      "x": -9,
      "y": 1,
      "z": 2,
      "name": "Wood_Softwood_Planks",
      "rotation": 2
    },
    {
      "x": -9,
      "y": 6,
      "z": 2,
      "name": "Wood_Deadwood_Roof_Shallow",
      "filler": 992
    },
    {
      "x": -9,
      "y": 9,
      "z": 2,
      "name": "Wood_Deadwood_Roof_Hollow"
    },
    {
      "x": -9,
      "y": 0,
      "z": 3,
      "name": "Wood_Softwood_Planks",
      "rotation": 2
    },
    {
      "x": -9,
      "y": 1,
      "z": 3,
      "name": "Wood_Softwood_Planks",
      "rotation": 2
    },
    {
      "x": -9,
      "y": 6,
      "z": 3,
      "name": "Wood_Deadwood_Roof_Shallow"
    },
    {
      "x": -9,
      "y": 0,
      "z": 4,
      "name": "Wood_Softwood_Planks",
      "rotation": 2
    },
    {
      "x": -9,
      "y": 1,
      "z": 4,
      "name": "Wood_Softwood_Planks",
      "rotation": 2
    },
    {
      "x": -9,
      "y": 5,
      "z": 4,
      "name": "Wood_Deadwood_Roof_Shallow",
      "filler": 992
    },
    {
      "x": -9,
      "y": 0,
      "z": 5,
      "name": "Wood_Softwood_Planks",
      "rotation": 2
    },
    {
      "x": -9,
      "y": 1,
      "z": 5,
      "name": "Wood_Softwood_Planks",
      "rotation": 2
    },
    {
      "x": -9,
      "y": 2,
      "z": 5,
      "name": "Furniture_Crude_Door"
    },
    {
      "x": -9,
      "y": 3,
      "z": 5,
      "name": "Furniture_Crude_Door",
      "filler": 1024
    },
    {
      "x": -9,
      "y": 4,
      "z": 5,
      "name": "Wood_Softwood_Planks",
      "rotation": 2
    },
    {
      "x": -9,
      "y": 5,
      "z": 5,
      "name": "Wood_Deadwood_Roof_Shallow"
    },
    {
      "x": -9,
      "y": 0,
      "z": 6,
      "name": "Wood_Softwood_Planks",
      "rotation": 2
    },
    {
      "x": -9,
      "y": 1,
      "z": 6,
      "name": "Wood_Softwood_Stairs"
    },
    {
      "x": -9,
      "y": 4,
      "z": 6,
      "name": "Wood_Deadwood_Roof_Hollow"
    },
    {
      "x": -8,
      "y": 0,
      "z": -10,
      "name": "Wood_Softwood_Planks",
      "rotation": 2
    },
    {
      "x": -8,
      "y": 1,
      "z": -10,
      "name": "*Rail_State_Definitions_Slope",
      "rotation": 3
    },
    {
      "x": -8,
      "y": 2,
      "z": -10,
      "name": "Empty"
    },
    {
      "x": -8,
      "y": 3,
      "z": -10,
      "name": "Empty"
    },
    {
      "x": -8,
      "y": 4,
      "z": -10,
      "name": "Empty"
    },
    {
      "x": -8,
      "y": 9,
      "z": -10,
      "name": "Wood_Deadwood_Roof_Hollow",
      "rotation": 2
    },
    {
      "x": -8,
      "y": 4,
      "z": -9,
      "name": "Furniture_Crude_Platform",
      "rotation": 2
    },
    {
      "x": -8,
      "y": 5,
      "z": -9,
      "name": "Wood_Softwood_Planks",
      "rotation": 2
    },
    {
      "x": -8,
      "y": 6,
      "z": -9,
      "name": "Wood_Softwood_Decorative",
      "rotation": 2
    },
    {
      "x": -8,
      "y": 7,
      "z": -9,
      "name": "Wood_Softwood_Decorative",
      "rotation": 2
    },
    {
      "x": -8,
      "y": 8,
      "z": -9,
      "name": "Wood_Softwood_Decorative",
      "rotation": 2
    },
    {
      "x": -8,
      "y": 9,
      "z": -9,
      "name": "Wood_Softwood_Decorative",
      "rotation": 2
    },
    {
      "x": -8,
      "y": 10,
      "z": -9,
      "name": "Empty"
    },
    {
      "x": -8,
      "y": 11,
      "z": -9,
      "name": "Empty"
    },
    {
      "x": -8,
      "y": 12,
      "z": -9,
      "name": "Empty"
    },
    {
      "x": -8,
      "y": 13,
      "z": -9,
      "name": "Empty"
    },
    {
      "x": -8,
      "y": -5,
      "z": -8,
      "name": "Rock_Stone_Cobble",
      "rotation": 2
    },
    {
      "x": -8,
      "y": -4,
      "z": -8,
      "name": "Rock_Stone_Cobble",
      "rotation": 2
    },
    {
      "x": -8,
      "y": -3,
      "z": -8,
      "name": "Rock_Stone_Cobble",
      "rotation": 2
    },
    {
      "x": -8,
      "y": -2,
      "z": -8,
      "name": "Rock_Stone_Cobble",
      "rotation": 2
    },
    {
      "x": -8,
      "y": -1,
      "z": -8,
      "name": "Rock_Stone_Cobble",
      "rotation": 2
    },
    {
      "x": -8,
      "y": 0,
      "z": -8,
      "name": "Rock_Stone_Cobble",
      "rotation": 2
    },
    {
      "x": -8,
      "y": 1,
      "z": -8,
      "name": "Empty"
    },
    {
      "x": -8,
      "y": 2,
      "z": -8,
      "name": "Empty"
    },
    {
      "x": -8,
      "y": 3,
      "z": -8,
      "name": "Empty"
    },
    {
      "x": -8,
      "y": 4,
      "z": -8,
      "name": "Rock_Stone_Cobble_Stairs",
      "rotation": 9
    },
    {
      "x": -8,
      "y": 5,
      "z": -8,
      "name": "Wood_Softwood_Planks",
      "rotation": 2
    },
    {
      "x": -8,
      "y": 6,
      "z": -8,
      "name": "Empty"
    },
    {
      "x": -8,
      "y": 7,
      "z": -8,
      "name": "Empty"
    },
    {
      "x": -8,
      "y": 8,
      "z": -8,
      "name": "Empty"
    },
    {
      "x": -8,
      "y": 9,
      "z": -8,
      "name": "Empty"
    },
    {
      "x": -8,
      "y": 10,
      "z": -8,
      "name": "Empty"
    },
    {
      "x": -8,
      "y": 11,
      "z": -8,
      "name": "Wood_Softwood_Beam",
      "rotation": 7
    },
    {
      "x": -8,
      "y": 12,
      "z": -8,
      "name": "Empty"
    },
    {
      "x": -8,
      "y": 13,
      "z": -8,
      "name": "Empty"
    },
    {
      "x": -8,
      "y": -4,
      "z": -7,
      "name": "Rock_Stone_Cobble",
      "rotation": 2
    },
    {
      "x": -8,
      "y": -3,
      "z": -7,
      "name": "Rock_Stone_Cobble",
      "rotation": 2
    },
    {
      "x": -8,
      "y": -2,
      "z": -7,
      "name": "Rock_Stone_Cobble",
      "rotation": 2
    },
    {
      "x": -8,
      "y": -1,
      "z": -7,
      "name": "Rock_Stone_Cobble",
      "rotation": 2
    },
    {
      "x": -8,
      "y": 0,
      "z": -7,
      "name": "Rock_Stone_Cobble",
      "rotation": 2
    },
    {
      "x": -8,
      "y": 1,
      "z": -7,
      "name": "Empty"
    },
    {
      "x": -8,
      "y": 2,
      "z": -7,
      "name": "Empty"
    },
    {
      "x": -8,
      "y": 3,
      "z": -7,
      "name": "Empty"
    },
    {
      "x": -8,
      "y": 4,
      "z": -7,
      "name": "Empty"
    },
    {
      "x": -8,
      "y": 5,
      "z": -7,
      "name": "Wood_Softwood_Planks",
      "rotation": 2
    },
    {
      "x": -8,
      "y": 6,
      "z": -7,
      "name": "Empty"
    },
    {
      "x": -8,
      "y": 7,
      "z": -7,
      "name": "Empty"
    },
    {
      "x": -8,
      "y": 8,
      "z": -7,
      "name": "Empty"
    },
    {
      "x": -8,
      "y": 9,
      "z": -7,
      "name": "Empty"
    },
    {
      "x": -8,
      "y": 10,
      "z": -7,
      "name": "Empty"
    },
    {
      "x": -8,
      "y": 11,
      "z": -7,
      "name": "Empty"
    },
    {
      "x": -8,
      "y": 12,
      "z": -7,
      "name": "Wood_Softwood_Beam",
      "rotation": 7
    },
    {
      "x": -8,
      "y": 13,
      "z": -7,
      "name": "Empty"
    },
    {
      "x": -8,
      "y": -3,
      "z": -6,
      "name": "Rock_Stone_Cobble",
      "rotation": 2
    },
    {
      "x": -8,
      "y": -2,
      "z": -6,
      "name": "Rock_Stone_Cobble",
      "rotation": 2
    },
    {
      "x": -8,
      "y": -1,
      "z": -6,
      "name": "Rock_Stone_Cobble",
      "rotation": 2
    },
    {
      "x": -8,
      "y": 0,
      "z": -6,
      "name": "Rock_Stone_Cobble",
      "rotation": 2
    },
    {
      "x": -8,
      "y": 1,
      "z": -6,
      "name": "Empty"
    },
    {
      "x": -8,
      "y": 2,
      "z": -6,
      "name": "Empty"
    },
    {
      "x": -8,
      "y": 3,
      "z": -6,
      "name": "Empty"
    },
    {
      "x": -8,
      "y": 4,
      "z": -6,
      "name": "Empty"
    },
    {
      "x": -8,
      "y": 5,
      "z": -6,
      "name": "Wood_Softwood_Planks",
      "rotation": 2
    },
    {
      "x": -8,
      "y": 6,
      "z": -6,
      "name": "Empty"
    },
    {
      "x": -8,
      "y": 7,
      "z": -6,
      "name": "Empty"
    },
    {
      "x": -8,
      "y": 8,
      "z": -6,
      "name": "Empty"
    },
    {
      "x": -8,
      "y": 9,
      "z": -6,
      "name": "Empty"
    },
    {
      "x": -8,
      "y": 10,
      "z": -6,
      "name": "Empty"
    },
    {
      "x": -8,
      "y": 11,
      "z": -6,
      "name": "Empty"
    },
    {
      "x": -8,
      "y": 12,
      "z": -6,
      "name": "Empty"
    },
    {
      "x": -8,
      "y": 13,
      "z": -6,
      "name": "Wood_Softwood_Beam",
      "rotation": 7
    },
    {
      "x": -8,
      "y": -3,
      "z": -5,
      "name": "Rock_Stone_Cobble",
      "rotation": 2
    },
    {
      "x": -8,
      "y": -2,
      "z": -5,
      "name": "Rock_Stone_Cobble",
      "rotation": 2
    },
    {
      "x": -8,
      "y": -1,
      "z": -5,
      "name": "Rock_Stone_Cobble",
      "rotation": 2
    },
    {
      "x": -8,
      "y": 0,
      "z": -5,
      "name": "Rock_Stone_Cobble",
      "rotation": 2
    },
    {
      "x": -8,
      "y": 1,
      "z": -5,
      "name": "Empty"
    },
    {
      "x": -8,
      "y": 2,
      "z": -5,
      "name": "Empty"
    },
    {
      "x": -8,
      "y": 3,
      "z": -5,
      "name": "Empty"
    },
    {
      "x": -8,
      "y": 4,
      "z": -5,
      "name": "Empty"
    },
    {
      "x": -8,
      "y": 5,
      "z": -5,
      "name": "Wood_Softwood_Planks",
      "rotation": 2
    },
    {
      "x": -8,
      "y": 6,
      "z": -5,
      "name": "Empty"
    },
    {
      "x": -8,
      "y": 7,
      "z": -5,
      "name": "Empty"
    },
    {
      "x": -8,
      "y": 8,
      "z": -5,
      "name": "Empty"
    },
    {
      "x": -8,
      "y": 9,
      "z": -5,
      "name": "Empty"
    },
    {
      "x": -8,
      "y": 10,
      "z": -5,
      "name": "Empty"
    },
    {
      "x": -8,
      "y": 11,
      "z": -5,
      "name": "Empty"
    },
    {
      "x": -8,
      "y": 12,
      "z": -5,
      "name": "Empty"
    },
    {
      "x": -8,
      "y": 13,
      "z": -5,
      "name": "Empty"
    },
    {
      "x": -8,
      "y": 14,
      "z": -5,
      "name": "Wood_Softwood_Beam",
      "rotation": 5
    },
    {
      "x": -8,
      "y": -3,
      "z": -4,
      "name": "Rock_Stone_Cobble",
      "rotation": 2
    },
    {
      "x": -8,
      "y": -2,
      "z": -4,
      "name": "Rock_Stone_Cobble",
      "rotation": 2
    },
    {
      "x": -8,
      "y": -1,
      "z": -4,
      "name": "Rock_Stone_Cobble",
      "rotation": 2
    },
    {
      "x": -8,
      "y": 0,
      "z": -4,
      "name": "Rock_Stone_Cobble",
      "rotation": 2
    },
    {
      "x": -8,
      "y": 1,
      "z": -4,
      "name": "Rail",
      "rotation": 1
    },
    {
      "x": -8,
      "y": 2,
      "z": -4,
      "name": "Empty"
    },
    {
      "x": -8,
      "y": 3,
      "z": -4,
      "name": "Empty"
    },
    {
      "x": -8,
      "y": 4,
      "z": -4,
      "name": "Empty"
    },
    {
      "x": -8,
      "y": 5,
      "z": -4,
      "name": "Wood_Softwood_Planks",
      "rotation": 2
    },
    {
      "x": -8,
      "y": 6,
      "z": -4,
      "name": "Rail",
      "rotation": 1
    },
    {
      "x": -8,
      "y": 7,
      "z": -4,
      "name": "Empty"
    },
    {
      "x": -8,
      "y": 8,
      "z": -4,
      "name": "Empty"
    },
    {
      "x": -8,
      "y": 9,
      "z": -4,
      "name": "Empty"
    },
    {
      "x": -8,
      "y": 10,
      "z": -4,
      "name": "Empty"
    },
    {
