{
  "version": 8,
  "blockIdVersion": 8,
  "anchorX": 2,
  "anchorY": 28,
  "anchorZ": 0,
  "blocks": [
    {
      "x": -19,
      "y": 54,
      "z": -2,
      "name": "Soil_Dirt_Dry"
    },
    {
      "x": -19,
      "y": 54,
      "z": -1,
      "name": "Soil_Dirt_Dry"
    },
    {
      "x": -19,
      "y": 54,
      "z": 0,
      "name": "Soil_Dirt_Dry"
    },
    {
      "x": -19,
      "y": 54,
      "z": 1,
      "name": "Soil_Dirt_Dry"
    },
    {
      "x": -18,
      "y": 54,
      "z": -4,
      "name": "Soil_Dirt_Dry"
    },
    {
      "x": -18,
      "y": 54,
      "z": -3,
      "name": "Soil_Dirt_Dry"
    },
    {
      "x": -18,
      "y": 55,
      "z": -3,
      "name": "Soil_Dirt_Dry"
    },
    {
      "x": -18,
      "y": 54,
      "z": -2,
      "name": "Soil_Dirt_Dry"
    },
    {
      "x": -18,
      "y": 55,
      "z": -2,
      "name": "Soil_Dirt_Dry"
    },
    {
      "x": -18,
      "y": 54,
      "z": -1,
      "name": "Soil_Dirt_Dry"
    },
    {
      "x": -18,
      "y": 55,
      "z": -1,
      "name": "Soil_Dirt_Dry"
    },
    {
      "x": -18,
      "y": 53,
      "z": 0,
      "name": "Rock_Sandstone_Stalactite_Small",
      "rotation": 8
    },
    {
      "x": -18,
      "y": 54,
      "z": 0,
      "name": "Soil_Dirt_Dry"
    },
    {
      "x": -18,
      "y": 55,
      "z": 0,
      "name": "Soil_Dirt_Dry"
    },
    {
      "x": -18,
      "y": 54,
      "z": 1,
      "name": "Soil_Dirt_Dry"
    },
    {
      "x": -18,
      "y": 55,
      "z": 1,
      "name": "Soil_Dirt_Dry"
    },
    {
      "x": -18,
      "y": 53,
      "z": 2,
      "name": "Rock_Sandstone"
    },
    {
      "x": -18,
      "y": 54,
      "z": 2,
      "name": "Soil_Dirt_Dry"
    },
    {
      "x": -18,
      "y": 55,
      "z": 2,
      "name": "Soil_Dirt_Dry"
    },
    {
      "x": -17,
      "y": 54,
      "z": -6,
      "name": "Soil_Dirt_Dry"
    },
    {
      "x": -17,
      "y": 54,
      "z": -5,
      "name": "Soil_Dirt_Dry"
    },
    {
      "x": -17,
      "y": 55,
      "z": -5,
      "name": "Soil_Dirt_Dry"
    },
    {
      "x": -17,
      "y": 54,
      "z": -4,
      "name": "Soil_Dirt_Dry"
    },
    {
      "x": -17,
      "y": 55,
      "z": -4,
      "name": "Soil_Dirt_Dry"
    },
    {
      "x": -17,
      "y": 54,
      "z": -3,
      "name": "Soil_Dirt_Dry"
    },
    {
      "x": -17,
      "y": 55,
      "z": -3,
      "name": "Soil_Dirt_Dry"
    },
    {
      "x": -17,
      "y": 54,
      "z": -2,
      "name": "Soil_Dirt_Dry"
    },
    {
      "x": -17,
      "y": 55,
      "z": -2,
      "name": "Soil_Dirt_Dry"
    },
    {
      "x": -17,
      "y": 54,
      "z": -1,
      "name": "Soil_Dirt_Dry"
    },
    {
      "x": -17,
      "y": 55,
      "z": -1,
      "name": "Soil_Dirt_Dry"
    },
    {
      "x": -17,
      "y": 54,
      "z": 0,
      "name": "Soil_Dirt_Dry"
    },
    {
      "x": -17,
      "y": 55,
      "z": 0,
      "name": "Soil_Dirt_Dry"
    },
    {
      "x": -17,
      "y": 54,
      "z": 1,
      "name": "Soil_Dirt_Dry"
    },
    {
      "x": -17,
      "y": 55,
      "z": 1,
      "name": "Soil_Dirt_Dry"
    },
    {
      "x": -17,
      "y": 53,
      "z": 2,
      "name": "Rock_Sandstone"
    },
    {
      "x": -17,
      "y": 54,
      "z": 2,
      "name": "Soil_Dirt_Dry"
    },
    {
      "x": -17,
      "y": 55,
      "z": 2,
      "name": "Soil_Dirt_Dry"
    },
    {
      "x": -17,
      "y": 51,
      "z": 3,
      "name": "Rock_Sandstone_Stalactite_Large",
      "filler": 31744,
      "rotation": 8
    },
    {
      "x": -17,
      "y": 52,
      "z": 3,
      "name": "Rock_Sandstone_Stalactite_Large",
      "rotation": 8
    },
    {
      "x": -17,
      "y": 53,
      "z": 3,
      "name": "Rock_Sandstone"
    },
    {
      "x": -17,
      "y": 54,
      "z": 3,
      "name": "Soil_Dirt_Dry"
    },
    {
      "x": -17,
      "y": 55,
      "z": 3,
      "name": "Soil_Dirt_Dry"
    },
    {
      "x": -17,
      "y": 54,
      "z": 4,
      "name": "Soil_Dirt_Dry"
    },
    {
      "x": -16,
      "y": 54,
      "z": -7,
      "name": "Soil_Dirt_Dry"
    },
    {
      "x": -16,
      "y": 54,
      "z": -6,
      "name": "Soil_Dirt_Dry"
    },
    {
      "x": -16,
      "y": 55,
      "z": -6,
      "name": "Soil_Dirt_Dry"
    },
    {
      "x": -16,
      "y": 54,
      "z": -5,
      "name": "Soil_Dirt_Dry"
    },
    {
      "x": -16,
      "y": 55,
      "z": -5,
      "name": "Soil_Dirt_Dry"
    },
    {
      "x": -16,
      "y": 54,
      "z": -4,
      "name": "Soil_Dirt_Dry"
    },
    {
      "x": -16,
      "y": 55,
      "z": -4,
      "name": "Soil_Dirt_Dry"
    },
    {
      "x": -16,
      "y": 54,
      "z": -3,
      "name": "Soil_Dirt_Dry"
    },
    {
      "x": -16,
      "y": 55,
      "z": -3,
      "name": "Soil_Sand_White"
    },
    {
      "x": -16,
      "y": 54,
      "z": -2,
      "name": "Soil_Dirt_Dry"
    },
    {
      "x": -16,
      "y": 55,
      "z": -2,
      "name": "Soil_Sand_White"
    },
    {
      "x": -16,
      "y": 54,
      "z": -1,
      "name": "Soil_Dirt_Dry"
    },
    {
      "x": -16,
      "y": 55,
      "z": -1,
      "name": "Soil_Sand_White"
    },
    {
      "x": -16,
      "y": 54,
      "z": 0,
      "name": "Soil_Dirt_Dry"
    },
    {
      "x": -16,
      "y": 55,
      "z": 0,
      "name": "Soil_Sand_White"
    },
    {
      "x": -16,
      "y": 54,
      "z": 1,
      "name": "Soil_Dirt_Dry"
    },
    {
      "x": -16,
      "y": 55,
      "z": 1,
      "name": "Soil_Sand_White"
    },
    {
      "x": -16,
      "y": 54,
      "z": 2,
      "name": "Soil_Dirt_Dry"
    },
    {
      "x": -16,
      "y": 55,
      "z": 2,
      "name": "Soil_Sand_White"
    },
    {
      "x": -16,
      "y": 53,
      "z": 3,
      "name": "Rock_Sandstone"
    },
    {
      "x": -16,
      "y": 54,
      "z": 3,
      "name": "Soil_Dirt_Dry"
    },
    {
      "x": -16,
      "y": 55,
      "z": 3,
      "name": "Soil_Dirt_Dry"
    },
    {
      "x": -16,
      "y": 52,
      "z": 4,
      "name": "Rock_Sandstone"
    },
    {
      "x": -16,
      "y": 53,
      "z": 4,
      "name": "Rock_Sandstone"
    },
    {
      "x": -16,
      "y": 54,
      "z": 4,
      "name": "Soil_Dirt_Dry"
    },
    {
      "x": -16,
      "y": 55,
      "z": 4,
      "name": "Soil_Dirt_Dry"
    },
    {
      "x": -16,
      "y": 50,
      "z": 5,
      "name": "Rock_Sandstone_Stalactite_Large",
      "filler": 31744,
      "rotation": 8
    },
    {
      "x": -16,
      "y": 51,
      "z": 5,
      "name": "Rock_Sandstone_Stalactite_Large",
      "rotation": 8
    },
    {
      "x": -16,
      "y": 52,
      "z": 5,
      "name": "Rock_Sandstone"
    },
    {
      "x": -16,
      "y": 53,
      "z": 5,
      "name": "Rock_Sandstone"
    },
    {
      "x": -16,
      "y": 54,
      "z": 5,
      "name": "Soil_Dirt_Dry"
    },
    {
      "x": -15,
      "y": 54,
      "z": -7,
      "name": "Soil_Dirt_Dry"
    },
    {
      "x": -15,
      "y": 55,
      "z": -7,
      "name": "Soil_Dirt_Dry"
    },
    {
      "x": -15,
      "y": 54,
      "z": -6,
      "name": "Soil_Dirt_Dry"
    },
    {
      "x": -15,
      "y": 55,
      "z": -6,
      "name": "Soil_Sand_White"
    },
    {
      "x": -15,
      "y": 54,
      "z": -5,
      "name": "Soil_Dirt_Dry"
    },
    {
      "x": -15,
      "y": 55,
      "z": -5,
      "name": "Soil_Sand_White"
    },
    {
      "x": -15,
      "y": 54,
      "z": -4,
      "name": "Soil_Dirt_Dry"
    },
    {
      "x": -15,
      "y": 55,
      "z": -4,
      "name": "Soil_Sand_White"
    },
    {
      "x": -15,
      "y": 54,
      "z": -3,
      "name": "Soil_Dirt_Dry"
    },
    {
      "x": -15,
      "y": 55,
      "z": -3,
      "name": "Soil_Sand_White"
    },
    {
      "x": -15,
      "y": 54,
      "z": -2,
      "name": "Soil_Dirt_Dry"
    },
    {
      "x": -15,
      "y": 55,
      "z": -2,
      "name": "Soil_Sand_White"
    },
    {
      "x": -15,
      "y": 54,
      "z": -1,
      "name": "Soil_Dirt_Dry"
    },
    {
      "x": -15,
      "y": 55,
      "z": -1,
      "name": "Soil_Sand_White"
    },
    {
      "x": -15,
      "y": 54,
      "z": 0,
      "name": "Soil_Dirt_Dry"
    },
    {
      "x": -15,
      "y": 55,
      "z": 0,
      "name": "Soil_Sand_White"
    },
    {
      "x": -15,
      "y": 54,
      "z": 1,
      "name": "Soil_Dirt_Dry"
    },
    {
      "x": -15,
      "y": 55,
      "z": 1,
      "name": "Soil_Sand_White"
    },
    {
      "x": -15,
      "y": 54,
      "z": 2,
      "name": "Soil_Dirt_Dry"
    },
    {
      "x": -15,
      "y": 55,
      "z": 2,
      "name": "Soil_Sand_White"
    },
    {
      "x": -15,
      "y": 53,
      "z": 3,
      "name": "Rock_Sandstone"
    },
    {
      "x": -15,
      "y": 54,
      "z": 3,
      "name": "Soil_Dirt_Dry"
    },
    {
      "x": -15,
      "y": 55,
      "z": 3,
      "name": "Soil_Sand_White"
    },
    {
      "x": -15,
      "y": 52,
      "z": 4,
      "name": "Rock_Sandstone"
    },
    {
      "x": -15,
      "y": 53,
      "z": 4,
      "name": "Rock_Sandstone"
    },
    {
      "x": -15,
      "y": 54,
      "z": 4,
      "name": "Soil_Dirt_Dry"
    },
    {
      "x": -15,
      "y": 55,
      "z": 4,
      "name": "Soil_Sand_White"
    },
    {
      "x": -15,
      "y": 52,
      "z": 5,
      "name": "Rock_Sandstone"
    },
    {
      "x": -15,
      "y": 53,
      "z": 5,
      "name": "Rock_Sandstone"
    },
    {
      "x": -15,
      "y": 54,
      "z": 5,
      "name": "Soil_Dirt_Dry"
    },
    {
      "x": -15,
      "y": 54,
      "z": 6,
      "name": "Soil_Dirt_Dry"
    },
    {
      "x": -14,
      "y": 54,
      "z": -8,
      "name": "Soil_Dirt_Dry"
    },
    {
      "x": -14,
      "y": 54,
      "z": -7,
      "name": "Soil_Dirt_Dry"
    },
    {
      "x": -14,
      "y": 55,
      "z": -7,
      "name": "Soil_Sand_White"
    },
    {
      "x": -14,
      "y": 54,
      "z": -6,
      "name": "Soil_Dirt_Dry"
    },
    {
      "x": -14,
      "y": 55,
      "z": -6,
      "name": "Soil_Sand_White"
    },
    {
      "x": -14,
      "y": 54,
      "z": -5,
      "name": "Soil_Dirt_Dry"
    },
    {
      "x": -14,
      "y": 55,
      "z": -5,
      "name": "Soil_Sand_White"
    },
    {
      "x": -14,
      "y": 54,
      "z": -4,
      "name": "Soil_Dirt_Dry"
    },
    {
      "x": -14,
      "y": 55,
      "z": -4,
      "name": "Soil_Sand_White"
    },
    {
      "x": -14,
      "y": 54,
      "z": -3,
      "name": "Soil_Dirt_Dry"
    },
    {
      "x": -14,
      "y": 55,
      "z": -3,
      "name": "Soil_Sand_White"
    },
    {
      "x": -14,
      "y": 54,
      "z": -2,
      "name": "Soil_Dirt_Dry"
    },
    {
      "x": -14,
      "y": 55,
      "z": -2,
      "name": "Soil_Sand_White"
    },
    {
      "x": -14,
      "y": 56,
      "z": -2,
      "name": "Soil_Sand_White"
    },
    {
      "x": -14,
      "y": 54,
      "z": -1,
      "name": "Soil_Dirt_Dry"
    },
    {
      "x": -14,
      "y": 55,
      "z": -1,
      "name": "Soil_Sand_White"
    },
    {
      "x": -14,
      "y": 56,
      "z": -1,
      "name": "Soil_Sand_White"
    },
    {
      "x": -14,
      "y": 54,
      "z": 0,
      "name": "Soil_Dirt_Dry"
    },
    {
      "x": -14,
      "y": 55,
      "z": 0,
      "name": "Soil_Sand_White"
    },
    {
      "x": -14,
      "y": 54,
      "z": 1,
      "name": "Soil_Dirt_Dry"
    },
    {
      "x": -14,
      "y": 55,
      "z": 1,
      "name": "Soil_Sand_White"
    },
    {
      "x": -14,
      "y": 54,
      "z": 2,
      "name": "Soil_Dirt_Dry"
    },
    {
      "x": -14,
      "y": 55,
      "z": 2,
      "name": "Soil_Sand_White"
    },
    {
      "x": -14,
      "y": 54,
      "z": 3,
      "name": "Soil_Dirt_Dry"
    },
    {
      "x": -14,
      "y": 55,
      "z": 3,
      "name": "Soil_Sand_White"
    },
    {
      "x": -14,
      "y": 54,
      "z": 4,
      "name": "Soil_Dirt_Dry"
    },
    {
      "x": -14,
      "y": 55,
      "z": 4,
      "name": "Soil_Sand_White"
    },
    {
      "x": -14,
      "y": 51,
      "z": 5,
      "name": "Rock_Sandstone_Stalactite_Small",
      "rotation": 8
    },
    {
      "x": -14,
      "y": 52,
      "z": 5,
      "name": "Rock_Sandstone"
    },
    {
      "x": -14,
      "y": 53,
      "z": 5,
      "name": "Rock_Sandstone"
    },
    {
      "x": -14,
      "y": 54,
      "z": 5,
      "name": "Soil_Dirt_Dry"
    },
    {
      "x": -14,
      "y": 55,
      "z": 5,
      "name": "Soil_Sand_White"
    },
    {
      "x": -14,
      "y": 53,
      "z": 6,
      "name": "Rock_Sandstone"
    },
    {
      "x": -14,
      "y": 54,
      "z": 6,
      "name": "Soil_Dirt_Dry"
    },
    {
      "x": -13,
      "y": 54,
      "z": -8,
      "name": "Soil_Dirt_Dry"
    },
    {
      "x": -13,
      "y": 55,
      "z": -8,
      "name": "Soil_Sand_White"
    },
    {
      "x": -13,
      "y": 54,
      "z": -7,
      "name": "Soil_Dirt_Dry"
    },
    {
      "x": -13,
      "y": 55,
      "z": -7,
      "name": "Soil_Sand_White"
    },
    {
      "x": -13,
      "y": 54,
      "z": -6,
      "name": "Soil_Dirt_Dry"
    },
    {
      "x": -13,
      "y": 55,
      "z": -6,
      "name": "Soil_Sand_White"
    },
    {
      "x": -13,
      "y": 54,
      "z": -5,
      "name": "Soil_Dirt_Dry"
    },
    {
      "x": -13,
      "y": 55,
      "z": -5,
      "name": "Soil_Sand_White"
    },
    {
      "x": -13,
      "y": 54,
      "z": -4,
      "name": "Soil_Dirt_Dry"
    },
    {
      "x": -13,
      "y": 55,
      "z": -4,
      "name": "Soil_Sand_White"
    },
    {
      "x": -13,
      "y": 56,
      "z": -4,
      "name": "Soil_Sand_White"
    },
    {
      "x": -13,
      "y": 54,
      "z": -3,
      "name": "Soil_Dirt_Dry"
    },
    {
      "x": -13,
      "y": 55,
      "z": -3,
      "name": "Soil_Sand_White"
    },
    {
      "x": -13,
      "y": 56,
      "z": -3,
      "name": "Soil_Sand_White"
    },
    {
      "x": -13,
      "y": 54,
      "z": -2,
      "name": "Soil_Dirt_Dry"
    },
    {
      "x": -13,
      "y": 55,
      "z": -2,
      "name": "Soil_Sand_White"
    },
    {
      "x": -13,
      "y": 56,
      "z": -2,
      "name": "Soil_Sand_White"
    },
    {
      "x": -13,
      "y": 54,
      "z": -1,
      "name": "Soil_Dirt_Dry"
    },
    {
      "x": -13,
      "y": 55,
      "z": -1,
      "name": "Soil_Sand_White"
    },
    {
      "x": -13,
      "y": 56,
      "z": -1,
      "name": "Soil_Sand_White"
    },
    {
      "x": -13,
      "y": 54,
      "z": 0,
      "name": "Soil_Dirt_Dry"
    },
    {
      "x": -13,
      "y": 55,
      "z": 0,
      "name": "Soil_Sand_White"
    },
    {
      "x": -13,
      "y": 54,
      "z": 1,
      "name": "Soil_Dirt_Dry"
    },
    {
      "x": -13,
      "y": 55,
      "z": 1,
      "name": "Soil_Sand_White"
    },
    {
      "x": -13,
      "y": 54,
      "z": 2,
      "name": "Soil_Dirt_Dry"
    },
    {
      "x": -13,
      "y": 55,
      "z": 2,
      "name": "Soil_Sand_White"
    },
    {
      "x": -13,
      "y": 54,
      "z": 3,
      "name": "Soil_Dirt_Dry"
    },
    {
      "x": -13,
      "y": 55,
      "z": 3,
      "name": "Soil_Sand_White"
    },
    {
      "x": -13,
      "y": 54,
      "z": 4,
      "name": "Soil_Dirt_Dry"
    },
    {
      "x": -13,
      "y": 55,
      "z": 4,
      "name": "Soil_Sand_White"
    },
    {
      "x": -13,
      "y": 54,
      "z": 5,
      "name": "Soil_Dirt_Dry"
    },
    {
      "x": -13,
      "y": 55,
      "z": 5,
      "name": "Soil_Sand_White"
    },
    {
      "x": -13,
      "y": 53,
      "z": 6,
      "name": "Rock_Sandstone"
    },
    {
      "x": -13,
      "y": 54,
      "z": 6,
      "name": "Soil_Dirt_Dry"
    },
    {
      "x": -13,
      "y": 55,
      "z": 6,
      "name": "Soil_Sand_White"
    },
    {
      "x": -13,
      "y": 53,
      "z": 7,
      "name": "Rock_Sandstone"
    },
    {
      "x": -13,
      "y": 54,
      "z": 7,
      "name": "Soil_Dirt_Dry"
    },
    {
      "x": -13,
      "y": 54,
      "z": 8,
      "name": "Soil_Dirt_Dry"
    },
    {
      "x": -12,
      "y": 54,
      "z": -9,
      "name": "Soil_Dirt_Dry"
    },
    {
      "x": -12,
      "y": 54,
      "z": -8,
      "name": "Soil_Dirt_Dry"
    },
    {
      "x": -12,
      "y": 55,
      "z": -8,
      "name": "Soil_Sand_White"
    },
    {
      "x": -12,
      "y": 54,
      "z": -7,
      "name": "Soil_Dirt_Dry"
    },
    {
      "x": -12,
      "y": 55,
      "z": -7,
      "name": "Soil_Sand_White"
    },
    {
      "x": -12,
      "y": 54,
      "z": -6,
      "name": "Soil_Dirt_Dry"
    },
    {
      "x": -12,
      "y": 55,
      "z": -6,
      "name": "Soil_Sand_White"
    },
    {
      "x": -12,
      "y": 54,
      "z": -5,
      "name": "Soil_Dirt_Dry"
    },
    {
      "x": -12,
      "y": 55,
      "z": -5,
      "name": "Soil_Sand_White"
    },
    {
      "x": -12,
      "y": 56,
      "z": -5,
      "name": "Soil_Sand_White"
    },
    {
      "x": -12,
      "y": 54,
      "z": -4,
      "name": "Soil_Dirt_Dry"
    },
    {
      "x": -12,
      "y": 55,
      "z": -4,
      "name": "Soil_Sand_White"
    },
    {
      "x": -12,
      "y": 56,
      "z": -4,
      "name": "Soil_Sand_White"
    },
    {
      "x": -12,
      "y": 54,
      "z": -3,
      "name": "Soil_Dirt_Dry"
    },
    {
      "x": -12,
      "y": 55,
      "z": -3,
      "name": "Soil_Sand_White"
    },
    {
      "x": -12,
      "y": 56,
      "z": -3,
      "name": "Soil_Sand_White"
    },
    {
      "x": -12,
      "y": 54,
      "z": -2,
      "name": "Soil_Dirt_Dry"
    },
    {
      "x": -12,
      "y": 55,
      "z": -2,
      "name": "Soil_Sand_White"
    },
    {
      "x": -12,
      "y": 56,
      "z": -2,
      "name": "Soil_Sand_White"
    },
    {
      "x": -12,
      "y": 54,
      "z": -1,
      "name": "Soil_Dirt_Dry"
    },
    {
      "x": -12,
      "y": 55,
      "z": -1,
      "name": "Soil_Sand_White"
    },
    {
      "x": -12,
      "y": 56,
      "z": -1,
      "name": "Soil_Sand_White"
    },
    {
      "x": -12,
      "y": 54,
      "z": 0,
      "name": "Soil_Dirt_Dry"
    },
    {
      "x": -12,
      "y": 55,
      "z": 0,
      "name": "Soil_Sand_White"
    },
    {
      "x": -12,
      "y": 56,
      "z": 0,
      "name": "Soil_Sand_White"
    },
    {
      "x": -12,
      "y": 54,
      "z": 1,
      "name": "Soil_Dirt_Dry"
    },
    {
      "x": -12,
      "y": 55,
      "z": 1,
      "name": "Soil_Sand_White"
    },
    {
      "x": -12,
      "y": 56,
      "z": 1,
      "name": "Soil_Sand_White"
    },
    {
      "x": -12,
      "y": 54,
      "z": 2,
      "name": "Soil_Dirt_Dry"
    },
    {
      "x": -12,
      "y": 55,
      "z": 2,
      "name": "Soil_Sand_White"
    },
    {
      "x": -12,
      "y": 54,
      "z": 3,
      "name": "Soil_Dirt_Dry"
    },
    {
      "x": -12,
      "y": 55,
      "z": 3,
      "name": "Soil_Sand_White"
    },
    {
      "x": -12,
      "y": 54,
      "z": 4,
      "name": "Soil_Dirt_Dry"
    },
    {
      "x": -12,
      "y": 55,
      "z": 4,
      "name": "Soil_Sand_White"
    },
    {
      "x": -12,
      "y": 54,
      "z": 5,
      "name": "Soil_Dirt_Dry"
    },
    {
      "x": -12,
      "y": 55,
      "z": 5,
      "name": "Soil_Sand_White"
    },
    {
      "x": -12,
      "y": 54,
      "z": 6,
      "name": "Soil_Dirt_Dry"
    },
    {
      "x": -12,
      "y": 55,
      "z": 6,
      "name": "Soil_Sand_White"
    },
    {
      "x": -12,
      "y": 54,
      "z": 7,
      "name": "Soil_Dirt_Dry"
    },
    {
      "x": -12,
      "y": 55,
      "z": 7,
      "name": "Soil_Sand_White"
    },
    {
      "x": -12,
      "y": 53,
      "z": 8,
      "name": "Rock_Sandstone"
    },
    {
      "x": -12,
      "y": 54,
      "z": 8,
      "name": "Soil_Dirt_Dry"
    },
    {
      "x": -12,
      "y": 55,
      "z": 8,
      "name": "Soil_Sand_White"
    },
    {
      "x": -12,
      "y": 54,
      "z": 9,
      "name": "Soil_Dirt_Dry"
    },
    {
      "x": -12,
      "y": 55,
      "z": 9,
      "name": "Soil_Dirt_Dry"
    },
    {
      "x": -12,
      "y": 54,
      "z": 10,
      "name": "Soil_Dirt_Dry"
    },
    {
      "x": -11,
      "y": 54,
      "z": -10,
      "name": "Rock_Sandstone"
    },
    {
      "x": -11,
      "y": 55,
      "z": -10,
      "name": "Soil_Sand_White"
    },
    {
      "x": -11,
      "y": 54,
      "z": -9,
      "name": "Rock_Sandstone"
    },
    {
      "x": -11,
      "y": 55,
      "z": -9,
      "name": "Soil_Sand_White"
    },
    {
      "x": -11,
      "y": 52,
      "z": -8,
      "name": "Rock_Sandstone_Stalactite_Large",
      "filler": 31744,
      "rotation": 8
    },
    {
      "x": -11,
      "y": 53,
      "z": -8,
      "name": "Rock_Sandstone_Stalactite_Large",
      "rotation": 8
    },
    {
      "x": -11,
      "y": 54,
      "z": -8,
      "name": "Soil_Dirt_Dry"
    },
    {
      "x": -11,
      "y": 55,
      "z": -8,
      "name": "Soil_Sand_White"
    },
    {
      "x": -11,
      "y": 54,
      "z": -7,
      "name": "Soil_Dirt_Dry"
    },
    {
      "x": -11,
      "y": 55,
      "z": -7,
      "name": "Soil_Sand_White"
    },
    {
      "x": -11,
      "y": 56,
      "z": -7,
      "name": "Soil_Sand_White"
    },
    {
      "x": -11,
      "y": 54,
      "z": -6,
      "name": "Soil_Dirt_Dry"
    },
    {
      "x": -11,
      "y": 55,
      "z": -6,
      "name": "Soil_Sand_White"
    },
    {
      "x": -11,
      "y": 56,
      "z": -6,
      "name": "Soil_Sand_White"
    },
    {
      "x": -11,
      "y": 54,
      "z": -5,
      "name": "Soil_Dirt_Dry"
    },
    {
      "x": -11,
      "y": 55,
      "z": -5,
      "name": "Soil_Sand_White"
    },
    {
      "x": -11,
      "y": 56,
      "z": -5,
      "name": "Soil_Sand_White"
    },
    {
      "x": -11,
      "y": 54,
      "z": -4,
      "name": "Soil_Dirt_Dry"
    },
    {
      "x": -11,
      "y": 55,
      "z": -4,
      "name": "Soil_Sand_White"
    },
    {
      "x": -11,
      "y": 56,
      "z": -4,
      "name": "Soil_Sand_White"
    },
    {
      "x": -11,
      "y": 54,
      "z": -3,
      "name": "Soil_Dirt_Dry"
    },
    {
      "x": -11,
      "y": 55,
      "z": -3,
      "name": "Soil_Sand_White"
    },
    {
      "x": -11,
      "y": 56,
      "z": -3,
      "name": "Soil_Sand_White"
    },
    {
      "x": -11,
      "y": 54,
      "z": -2,
      "name": "Soil_Dirt_Dry"
    },
    {
      "x": -11,
      "y": 55,
      "z": -2,
      "name": "Soil_Sand_White"
    },
    {
      "x": -11,
      "y": 56,
      "z": -2,
      "name": "Soil_Sand_White"
    },
    {
      "x": -11,
      "y": 54,
      "z": -1,
      "name": "Soil_Dirt_Dry"
    },
    {
      "x": -11,
      "y": 55,
      "z": -1,
      "name": "Soil_Sand_White"
    },
    {
      "x": -11,
      "y": 56,
      "z": -1,
      "name": "Soil_Sand_White"
    },
    {
      "x": -11,
      "y": 46,
      "z": 0,
      "name": "Soil_Dirt_Dry"
    },
    {
      "x": -11,
      "y": 54,
      "z": 0,
      "name": "Soil_Dirt_Dry"
    },
    {
      "x": -11,
      "y": 55,
      "z": 0,
      "name": "Soil_Sand_White"
    },
    {
      "x": -11,
      "y": 56,
      "z": 0,
      "name": "Soil_Sand_White"
    },
    {
      "x": -11,
      "y": 46,
      "z": 1,
      "name": "Soil_Dirt_Dry"
    },
    {
      "x": -11,
      "y": 54,
      "z": 1,
      "name": "Soil_Dirt_Dry"
    },
    {
      "x": -11,
      "y": 55,
      "z": 1,
      "name": "Soil_Sand_White"
    },
    {
      "x": -11,
      "y": 56,
      "z": 1,
      "name": "Soil_Sand_White"
    },
    {
      "x": -11,
      "y": 46,
      "z": 2,
      "name": "Soil_Dirt_Dry"
    },
    {
      "x": -11,
      "y": 47,
      "z": 2,
      "name": "Rubble_Sandstone"
    },
    {
      "x": -11,
      "y": 54,
      "z": 2,
      "name": "Soil_Dirt_Dry"
    },
    {
      "x": -11,
      "y": 55,
      "z": 2,
      "name": "Soil_Sand_White"
    },
    {
      "x": -11,
      "y": 46,
      "z": 3,
      "name": "Soil_Dirt_Dry"
    },
    {
      "x": -11,
      "y": 54,
      "z": 3,
      "name": "Soil_Dirt_Dry"
    },
    {
      "x": -11,
      "y": 55,
      "z": 3,
      "name": "Soil_Sand_White"
    },
    {
      "x": -11,
      "y": 46,
      "z": 4,
      "name": "Soil_Dirt_Dry"
    },
    {
      "x": -11,
      "y": 54,
      "z": 4,
      "name": "Soil_Dirt_Dry"
    },
    {
      "x": -11,
      "y": 55,
      "z": 4,
      "name": "Soil_Sand_White"
    },
    {
      "x": -11,
      "y": 54,
      "z": 5,
      "name": "Soil_Dirt_Dry"
    },
    {
      "x": -11,
      "y": 55,
      "z": 5,
      "name": "Soil_Sand_White"
    },
    {
      "x": -11,
      "y": 54,
      "z": 6,
      "name": "Soil_Dirt_Dry"
    },
    {
      "x": -11,
      "y": 55,
      "z": 6,
      "name": "Soil_Sand_White"
    },
    {
      "x": -11,
      "y": 54,
      "z": 7,
      "name": "Soil_Dirt_Dry"
    },
    {
      "x": -11,
      "y": 55,
      "z": 7,
      "name": "Soil_Sand_White"
    },
    {
      "x": -11,
      "y": 54,
      "z": 8,
      "name": "Soil_Dirt_Dry"
    },
    {
      "x": -11,
      "y": 55,
      "z": 8,
      "name": "Soil_Sand_White"
    },
    {
      "x": -11,
      "y": 52,
      "z": 9,
      "name": "Rock_Sandstone_Stalactite_Large",
      "filler": 31744,
      "rotation": 8
    },
    {
      "x": -11,
      "y": 53,
      "z": 9,
      "name": "Rock_Sandstone_Stalactite_Large",
      "rotation": 8
    },
    {
      "x": -11,
      "y": 54,
      "z": 9,
      "name": "Soil_Dirt_Dry"
    },
    {
      "x": -11,
      "y": 55,
      "z": 9,
      "name": "Soil_Sand_White"
    },
    {
      "x": -11,
      "y": 54,
      "z": 10,
      "name": "Soil_Dirt_Dry"
    },
    {
      "x": -11,
      "y": 55,
      "z": 10,
      "name": "Soil_Dirt_Dry"
    },
    {
      "x": -11,
      "y": 54,
      "z": 11,
      "name": "Soil_Dirt_Dry"
    },
    {
      "x": -10,
      "y": 54,
      "z": -13,
      "name": "Rock_Sandstone"
    },
    {
      "x": -10,
      "y": 55,
      "z": -13,
      "name": "Soil_Dirt_Dry"
    },
    {
      "x": -10,
      "y": 53,
      "z": -12,
      "name": "Rock_Sandstone_Stalactite_Small",
      "rotation": 8
    },
    {
      "x": -10,
      "y": 54,
      "z": -12,
      "name": "Rock_Sandstone"
    },
    {
      "x": -10,
      "y": 55,
      "z": -12,
      "name": "Soil_Dirt_Dry"
    },
    {
      "x": -10,
      "y": 54,
      "z": -11,
      "name": "Rock_Sandstone"
    },
    {
      "x": -10,
      "y": 55,
      "z": -11,
      "name": "Soil_Dirt_Dry"
    },
    {
      "x": -10,
      "y": 53,
      "z": -10,
      "name": "Rock_Sandstone"
    },
    {
      "x": -10,
      "y": 54,
      "z": -10,
      "name": "Rock_Sandstone"
    },
    {
      "x": -10,
      "y": 55,
      "z": -10,
      "name": "Soil_Sand_White"
    },
    {
      "x": -10,
      "y": 51,
      "z": -9,
      "name": "Rock_Sandstone_Stalactite_Large",
      "filler": 31744,
      "rotation": 8
    },
    {
      "x": -10,
      "y": 52,
      "z": -9,
      "name": "Rock_Sandstone_Stalactite_Large",
      "rotation": 8
    },
    {
      "x": -10,
      "y": 53,
      "z": -9,
      "name": "Rock_Sandstone"
    },
    {
      "x": -10,
      "y": 54,
      "z": -9,
      "name": "Soil_Dirt_Dry"
    },
    {
      "x": -10,
      "y": 55,
      "z": -9,
      "name": "Soil_Dirt_Dry"
    },
    {
      "x": -10,
      "y": 56,
      "z": -9,
      "name": "Soil_Sand_White"
    },
    {
      "x": -10,
      "y": 54,
      "z": -8,
      "name": "Soil_Dirt_Dry"
    },
    {
      "x": -10,
      "y": 55,
      "z": -8,
      "name": "Soil_Dirt_Dry"
    },
    {
      "x": -10,
      "y": 56,
      "z": -8,
      "name": "Soil_Sand_White"
    },
    {
      "x": -10,
      "y": 54,
      "z": -7,
      "name": "Soil_Dirt_Dry"
    },
    {
      "x": -10,
      "y": 55,
      "z": -7,
      "name": "Soil_Dirt_Dry"
    },
    {
      "x": -10,
      "y": 56,
      "z": -7,
      "name": "Soil_Sand_White"
    },
    {
      "x": -10,
      "y": 54,
      "z": -6,
      "name": "Soil_Dirt_Dry"
    },
    {
      "x": -10,
      "y": 55,
      "z": -6,
      "name": "Soil_Dirt_Dry"
    },
    {
      "x": -10,
      "y": 56,
      "z": -6,
      "name": "Soil_Sand_White"
    },
    {
      "x": -10,
      "y": 54,
      "z": -5,
      "name": "Soil_Dirt_Dry"
    },
    {
      "x": -10,
      "y": 55,
      "z": -5,
      "name": "Soil_Dirt_Dry"
    },
    {
      "x": -10,
      "y": 56,
      "z": -5,
      "name": "Soil_Sand_White"
    },
    {
      "x": -10,
      "y": 54,
      "z": -4,
      "name": "Soil_Dirt_Dry"
    },
    {
      "x": -10,
      "y": 55,
      "z": -4,
      "name": "Soil_Dirt_Dry"
    },
    {
      "x": -10,
      "y": 56,
      "z": -4,
      "name": "Soil_Sand_White"
    },
    {
      "x": -10,
      "y": 54,
      "z": -3,
      "name": "Soil_Dirt_Dry"
    },
    {
      "x": -10,
      "y": 55,
      "z": -3,
      "name": "Soil_Dirt_Dry"
    },
    {
      "x": -10,
      "y": 56,
      "z": -3,
      "name": "Soil_Sand_White"
    },
    {
      "x": -10,
      "y": 46,
      "z": -2,
      "name": "Soil_Dirt_Dry"
    },
    {
      "x": -10,
      "y": 54,
      "z": -2,
      "name": "Soil_Dirt_Dry"
    },
    {
      "x": -10,
      "y": 55,
      "z": -2,
      "name": "Soil_Sand_White"
    },
    {
      "x": -10,
      "y": 56,
      "z": -2,
      "name": "Soil_Sand_White"
    },
    {
      "x": -10,
      "y": 46,
      "z": -1,
      "name": "Soil_Dirt_Dry"
    },
    {
      "x": -10,
      "y": 47,
      "z": -1,
      "name": "Soil_Dirt_Dry"
    },
    {
      "x": -10,
      "y": 54,
      "z": -1,
      "name": "Soil_Dirt_Dry"
    },
    {
      "x": -10,
      "y": 55,
      "z": -1,
      "name": "Soil_Sand_White"
    },
    {
      "x": -10,
      "y": 56,
      "z": -1,
      "name": "Soil_Sand_White"
    },
    {
      "x": -10,
      "y": 46,
      "z": 0,
      "name": "Soil_Dirt_Dry"
    },
    {
      "x": -10,
      "y": 47,
      "z": 0,
      "name": "Soil_Grass_Dry"
    },
    {
      "x": -10,
      "y": 54,
      "z": 0,
      "name": "Soil_Dirt_Dry"
    },
    {
      "x": -10,
      "y": 55,
      "z": 0,
      "name": "Soil_Sand_White"
    },
    {
      "x": -10,
      "y": 56,
      "z": 0,
      "name": "Soil_Sand_White"
    },
    {
      "x": -10,
      "y": 46,
      "z": 1,
      "name": "Soil_Dirt_Dry"
    },
    {
      "x": -10,
      "y": 47,
      "z": 1,
      "name": "Soil_Grass_Dry"
    },
    {
      "x": -10,
      "y": 54,
      "z": 1,
      "name": "Soil_Dirt_Dry"
    },
    {
      "x": -10,
      "y": 55,
      "z": 1,
      "name": "Soil_Sand_White"
    },
    {
      "x": -10,
      "y": 56,
      "z": 1,
      "name": "Soil_Sand_White"
    },
    {
      "x": -10,
      "y": 45,
      "z": 2,
      "name": "Rock_Sandstone"
    },
    {
      "x": -10,
      "y": 46,
      "z": 2,
      "name": "Soil_Dirt_Dry"
    },
    {
      "x": -10,
      "y": 54,
      "z": 2,
      "name": "Soil_Dirt_Dry"
    },
    {
      "x": -10,
      "y": 55,
      "z": 2,
      "name": "Soil_Sand_White"
    },
    {
      "x": -10,
      "y": 56,
      "z": 2,
      "name": "Soil_Sand_White"
    },
    {
      "x": -10,
      "y": 45,
      "z": 3,
      "name": "Rock_Sandstone"
    },
    {
      "x": -10,
      "y": 46,
      "z": 3,
      "name": "Soil_Dirt_Dry"
    },
    {
      "x": -10,
      "y": 54,
      "z": 3,
      "name": "Soil_Dirt_Dry"
    },
    {
      "x": -10,
      "y": 55,
      "z": 3,
      "name": "Soil_Sand_White"
    },
    {
      "x": -10,
      "y": 43,
      "z": 4,
      "name": "Rock_Sandstone_Stalactite_Large",
      "filler": 31744,
      "rotation": 8
    },
    {
      "x": -10,
      "y": 44,
      "z": 4,
      "name": "Rock_Sandstone_Stalactite_Large",
      "rotation": 8
    },
    {
      "x": -10,
      "y": 45,
      "z": 4,
      "name": "Rock_Sandstone"
    },
    {
      "x": -10,
      "y": 46,
      "z": 4,
      "name": "Soil_Dirt_Dry"
    },
    {
      "x": -10,
      "y": 54,
      "z": 4,
      "name": "Soil_Dirt_Dry"
    },
    {
      "x": -10,
      "y": 55,
      "z": 4,
      "name": "Soil_Sand_White"
    },
    {
      "x": -10,
      "y": 46,
      "z": 5,
      "name": "Soil_Dirt_Dry"
    },
    {
      "x": -10,
      "y": 54,
      "z": 5,
      "name": "Soil_Dirt_Dry"
    },
    {
      "x": -10,
      "y": 55,
      "z": 5,
      "name": "Soil_Sand_White"
    },
    {
      "x": -10,
      "y": 54,
      "z": 6,
      "name": "Soil_Dirt_Dry"
    },
    {
      "x": -10,
      "y": 55,
      "z": 6,
      "name": "Soil_Sand_White"
    },
    {
      "x": -10,
      "y": 54,
      "z": 7,
      "name": "Soil_Dirt_Dry"
    },
    {
      "x": -10,
      "y": 55,
      "z": 7,
      "name": "Soil_Sand_White"
    },
    {
      "x": -10,
      "y": 54,
      "z": 8,
      "name": "Soil_Dirt_Dry"
    },
    {
      "x": -10,
      "y": 55,
      "z": 8,
      "name": "Soil_Sand_White"
    },
    {
      "x": -10,
      "y": 54,
      "z": 9,
      "name": "Soil_Dirt_Dry"
    },
    {
      "x": -10,
      "y": 55,
      "z": 9,
      "name": "Soil_Sand_White"
    },
    {
      "x": -10,
      "y": 54,
      "z": 10,
      "name": "Soil_Dirt_Dry"
    },
    {
      "x": -10,
      "y": 55,
      "z": 10,
      "name": "Soil_Sand_White"
    },
    {
      "x": -10,
      "y": 54,
      "z": 11,
      "name": "Soil_Dirt_Dry"
    },
    {
      "x": -10,
      "y": 55,
      "z": 11,
      "name": "Soil_Dirt_Dry"
    },
    {
      "x": -10,
      "y": 54,
      "z": 12,
      "name": "Soil_Dirt_Dry"
    },
    {
      "x": -9,
      "y": 55,
      "z": -14,
      "name": "Soil_Dirt_Dry"
    },
    {
      "x": -9,
      "y": 55,
      "z": -13,
      "name": "Soil_Dirt_Dry"
    },
    {
      "x": -9,
      "y": 56,
      "z": -13,
      "name": "Soil_Dirt_Dry"
    },
    {
      "x": -9,
      "y": 55,
      "z": -12,
      "name": "Soil_Dirt_Dry"
    },
    {
      "x": -9,
      "y": 56,
      "z": -12,
      "name": "Soil_Sand_White"
    },
    {
      "x": -9,
      "y": 54,
      "z": -11,
      "name": "Rock_Sandstone"
    },
    {
      "x": -9,
      "y": 55,
      "z": -11,
      "name": "Soil_Dirt_Dry"
    },
    {
      "x": -9,
      "y": 56,
      "z": -11,
      "name": "Soil_Sand_White"
    },
    {
      "x": -9,
      "y": 54,
      "z": -10,
      "name": "Rock_Sandstone"
    },
    {
      "x": -9,
      "y": 55,
      "z": -10,
      "name": "Soil_Dirt_Dry"
    },
    {
      "x": -9,
      "y": 56,
      "z": -10,
      "name": "Soil_Sand_White"
    },
    {
      "x": -9,
      "y": 53,
      "z": -9,
      "name": "Rock_Sandstone"
    },
    {
      "x": -9,
      "y": 54,
      "z": -9,
      "name": "Rock_Sandstone"
    },
    {
      "x": -9,
      "y": 55,
      "z": -9,
      "name": "Soil_Dirt_Dry"
    },
    {
      "x": -9,
      "y": 56,
      "z": -9,
      "name": "Soil_Sand_White"
    },
    {
      "x": -9,
      "y": 54,
      "z": -8,
      "name": "Soil_Dirt_Dry"
    },
    {
      "x": -9,
      "y": 55,
      "z": -8,
      "name": "Soil_Dirt_Dry"
    },
    {
      "x": -9,
      "y": 56,
      "z": -8,
      "name": "Soil_Sand_White"
    },
    {
      "x": -9,
      "y": 54,
      "z": -7,
      "name": "Soil_Dirt_Dry"
    },
    {
      "x": -9,
      "y": 55,
      "z": -7,
      "name": "Soil_Dirt_Dry"
    },
    {
      "x": -9,
      "y": 56,
      "z": -7,
      "name": "Soil_Sand_White"
    },
    {
      "x": -9,
      "y": 54,
      "z": -6,
      "name": "Soil_Dirt_Dry"
    },
    {
      "x": -9,
      "y": 55,
      "z": -6,
      "name": "Soil_Dirt_Dry"
    },
    {
      "x": -9,
      "y": 56,
      "z": -6,
      "name": "Soil_Sand_White"
    },
    {
      "x": -9,
      "y": 54,
      "z": -5,
      "name": "Soil_Dirt_Dry"
    },
    {
      "x": -9,
      "y": 55,
      "z": -5,
      "name": "Soil_Dirt_Dry"
    },
    {
      "x": -9,
      "y": 56,
      "z": -5,
      "name": "Soil_Sand_White"
    },
    {
      "x": -9,
      "y": 46,
      "z": -4,
      "name": "Soil_Dirt_Dry"
    },
    {
      "x": -9,
      "y": 54,
      "z": -4,
      "name": "Soil_Dirt_Dry"
    },
    {
      "x": -9,
      "y": 55,
      "z": -4,
      "name": "Soil_Dirt_Dry"
    },
    {
      "x": -9,
      "y": 56,
      "z": -4,
      "name": "Soil_Sand_White"
    },
    {
      "x": -9,
      "y": 46,
      "z": -3,
      "name": "Soil_Dirt_Dry"
    },
    {
      "x": -9,
      "y": 54,
      "z": -3,
      "name": "Soil_Dirt_Dry"
    },
    {
      "x": -9,
      "y": 55,
      "z": -3,
      "name": "Soil_Dirt_Dry"
    },
    {
      "x": -9,
      "y": 56,
      "z": -3,
      "name": "Soil_Sand_White"
    },
    {
      "x": -9,
      "y": 46,
      "z": -2,
      "name": "Soil_Dirt_Dry"
    },
    {
      "x": -9,
      "y": 47,
      "z": -2,
      "name": "Soil_Dirt_Dry"
    },
    {
      "x": -9,
      "y": 54,
      "z": -2,
      "name": "Soil_Dirt_Dry"
    },
    {
      "x": -9,
      "y": 55,
      "z": -2,
      "name": "Soil_Dirt_Dry"
    },
    {
      "x": -9,
      "y": 56,
      "z": -2,
      "name": "Soil_Sand_White"
    },
    {
      "x": -9,
      "y": 46,
      "z": -1,
      "name": "Soil_Dirt_Dry"
    },
    {
      "x": -9,
      "y": 47,
      "z": -1,
      "name": "Soil_Grass_Dry"
    },
    {
      "x": -9,
      "y": 54,
      "z": -1,
      "name": "Soil_Dirt_Dry"
    },
    {
      "x": -9,
      "y": 55,
      "z": -1,
      "name": "Soil_Dirt_Dry"
    },
    {
      "x": -9,
      "y": 56,
      "z": -1,
      "name": "Soil_Sand_White"
    },
    {
      "x": -9,
      "y": 46,
      "z": 0,
      "name": "Soil_Dirt_Dry"
    },
    {
      "x": -9,
      "y": 47,
      "z": 0,
      "name": "Soil_Grass_Dry"
    },
    {
      "x": -9,
      "y": 48,
      "z": 0,
      "name": "Plant_Grass_Arid_Tall"
    },
    {
      "x": -9,
      "y": 54,
      "z": 0,
      "name": "Soil_Dirt_Dry"
    },
    {
      "x": -9,
      "y": 55,
      "z": 0,
      "name": "Soil_Dirt_Dry"
    },
    {
      "x": -9,
      "y": 56,
      "z": 0,
      "name": "Soil_Sand_White"
    },
    {
      "x": -9,
      "y": 46,
      "z": 1,
      "name": "Soil_Dirt_Dry"
    },
    {
      "x": -9,
      "y": 47,
      "z": 1,
      "name": "Soil_Grass_Dry"
    },
    {
      "x": -9,
      "y": 48,
      "z": 1,
      "name": "Plant_Grass_Dry"
    },
    {
      "x": -9,
      "y": 54,
      "z": 1,
      "name": "Soil_Dirt_Dry"
    },
    {
      "x": -9,
      "y": 55,
      "z": 1,
      "name": "Soil_Dirt_Dry"
    },
    {
      "x": -9,
      "y": 56,
      "z": 1,
      "name": "Soil_Sand_White"
    },
    {
      "x": -9,
      "y": 46,
      "z": 2,
      "name": "Soil_Dirt_Dry"
    },
    {
      "x": -9,
      "y": 47,
      "z": 2,
      "name": "Soil_Grass_Dry"
    },
    {
      "x": -9,
      "y": 54,
      "z": 2,
      "name": "Soil_Dirt_Dry"
    },
    {
      "x": -9,
      "y": 55,
      "z": 2,
      "name": "Soil_Dirt_Dry"
    },
    {
      "x": -9,
      "y": 56,
      "z": 2,
      "name": "Soil_Sand_White"
    },
    {
      "x": -9,
      "y": 46,
      "z": 3,
      "name": "Soil_Dirt_Dry"
    },
    {
      "x": -9,
      "y": 47,
      "z": 3,
      "name": "Rubble_Sandstone_Medium"
    },
    {
      "x": -9,
      "y": 54,
      "z": 3,
      "name": "Soil_Dirt_Dry"
    },
    {
      "x": -9,
      "y": 55,
      "z": 3,
      "name": "Soil_Dirt_Dry"
    },
    {
      "x": -9,
      "y": 56,
      "z": 3,
      "name": "Soil_Sand_White"
    },
    {
      "x": -9,
      "y": 45,
      "z": 4,
      "name": "Rock_Sandstone"
    },
    {
      "x": -9,
      "y": 46,
      "z": 4,
      "name": "Soil_Dirt_Dry"
    },
    {
      "x": -9,
      "y": 54,
      "z": 4,
      "name": "Soil_Dirt_Dry"
    },
    {
      "x": -9,
      "y": 55,
      "z": 4,
      "name": "Soil_Dirt_Dry"
    },
    {
      "x": -9,
      "y": 56,
      "z": 4,
      "name": "Soil_Sand_White"
    },
    {
      "x": -9,
      "y": 44,
      "z": 5,
      "name": "Rock_Sandstone_Stalactite_Small",
      "rotation": 8
    },
    {
      "x": -9,
      "y": 45,
      "z": 5,
      "name": "Rock_Sandstone"
    },
    {
      "x": -9,
      "y": 46,
      "z": 5,
      "name": "Soil_Dirt_Dry"
    },
    {
      "x": -9,
      "y": 54,
      "z": 5,
      "name": "Soil_Dirt_Dry"
    },
    {
      "x": -9,
      "y": 55,
      "z": 5,
      "name": "Soil_Sand_White"
    },
    {
      "x": -9,
      "y": 54,
      "z": 6,
      "name": "Soil_Dirt_Dry"
    },
    {
      "x": -9,
      "y": 55,
      "z": 6,
      "name": "Soil_Sand_White"
    },
    {
      "x": -9,
      "y": 54,
      "z": 7,
      "name": "Soil_Dirt_Dry"
    },
    {
      "x": -9,
      "y": 55,
      "z": 7,
      "name": "Soil_Sand_White"
    },
    {
      "x": -9,
      "y": 54,
      "z": 8,
      "name": "Soil_Dirt_Dry"
    },
    {
      "x": -9,
      "y": 55,
      "z": 8,
      "name": "Soil_Sand_White"
    },
    {
      "x": -9,
      "y": 54,
      "z": 9,
      "name": "Soil_Dirt_Dry"
    },
    {
      "x": -9,
      "y": 55,
      "z": 9,
      "name": "Soil_Sand_White"
    },
    {
      "x": -9,
      "y": 54,
      "z": 10,
      "name": "Soil_Dirt_Dry"
    },
    {
      "x": -9,
      "y": 55,
      "z": 10,
      "name": "Soil_Sand_White"
    },
    {
      "x": -9,
      "y": 54,
      "z": 11,
      "name": "Soil_Dirt_Dry"
    },
    {
      "x": -9,
      "y": 55,
      "z": 11,
      "name": "Soil_Dirt_Dry"
    },
    {
      "x": -9,
      "y": 54,
      "z": 12,
      "name": "Soil_Dirt_Dry"
    },
    {
      "x": -8,
      "y": 55,
      "z": -15,
      "name": "Soil_Dirt_Dry"
    },
    {
      "x": -8,
      "y": 55,
      "z": -14,
      "name": "Soil_Dirt_Dry"
    },
    {
      "x": -8,
      "y": 55,
      "z": -13,
      "name": "Soil_Dirt_Dry"
    },
    {
      "x": -8,
      "y": 56,
      "z": -13,
      "name": "Soil_Dirt_Dry"
    },
    {
      "x": -8,
      "y": 55,
      "z": -12,
      "name": "Soil_Dirt_Dry"
    },
    {
      "x": -8,
      "y": 56,
      "z": -12,
      "name": "Soil_Sand_White"
    },
    {
      "x": -8,
      "y": 55,
      "z": -11,
      "name": "Soil_Dirt_Dry"
    },
    {
      "x": -8,
      "y": 56,
      "z": -11,
      "name": "Soil_Sand_White"
    },
    {
      "x": -8,
      "y": 55,
      "z": -10,
      "name": "Soil_Dirt_Dry"
    },
    {
      "x": -8,
      "y": 56,
      "z": -10,
      "name": "Soil_Sand_White"
    },
    {
      "x": -8,
      "y": 55,
      "z": -9,
      "name": "Soil_Dirt_Dry"
    },
    {
      "x": -8,
      "y": 56,
      "z": -9,
      "name": "Soil_Sand_White"
    },
    {
      "x": -8,
      "y": 55,
      "z": -8,
      "name": "Soil_Dirt_Dry"
    },
    {
      "x": -8,
      "y": 56,
      "z": -8,
      "name": "Soil_Sand_White"
    },
    {
      "x": -8,
      "y": 55,
      "z": -7,
      "name": "Soil_Dirt_Dry"
    },
    {
      "x": -8,
      "y": 56,
      "z": -7,
      "name": "Soil_Sand_White"
    },
    {
      "x": -8,
      "y": 54,
      "z": -6,
      "name": "Soil_Dirt_Dry"
    },
    {
      "x": -8,
      "y": 55,
      "z": -6,
      "name": "Soil_Dirt_Dry"
    },
    {
      "x": -8,
      "y": 56,
      "z": -6,
      "name": "Soil_Sand_White"
    },
    {
      "x": -8,
      "y": 46,
      "z": -5,
      "name": "Soil_Dirt_Dry"
    },
    {
      "x": -8,
      "y": 54,
      "z": -5,
      "name": "Soil_Dirt_Dry"
    },
    {
      "x": -8,
      "y": 55,
      "z": -5,
      "name": "Soil_Dirt_Dry"
    },
    {
      "x": -8,
      "y": 56,
      "z": -5,
      "name": "Soil_Sand_White"
    },
    {
      "x": -8,
      "y": 46,
      "z": -4,
      "name": "Soil_Dirt_Dry"
    },
    {
      "x": -8,
      "y": 54,
      "z": -4,
      "name": "Soil_Dirt_Dry"
    },
    {
      "x": -8,
      "y": 55,
      "z": -4,
      "name": "Soil_Dirt_Dry"
    },
    {
      "x": -8,
      "y": 56,
      "z": -4,
      "name": "Soil_Sand_White"
    },
    {
      "x": -8,
      "y": 46,
      "z": -3,
      "name": "Soil_Dirt_Dry"
    },
    {
      "x": -8,
      "y": 47,
      "z": -3,
      "name": "Soil_Dirt_Dry"
    },
    {
      "x": -8,
      "y": 54,
      "z": -3,
      "name": "Soil_Dirt_Dry"
    },
    {
      "x": -8,
      "y": 55,
      "z": -3,
      "name": "Soil_Dirt_Dry"
    },
    {
      "x": -8,
      "y": 56,
      "z": -3,
      "name": "Soil_Dirt_Dry"
    },
    {
      "x": -8,
      "y": 57,
      "z": -3,
      "name": "Soil_Sand_White"
    },
    {
      "x": -8,
      "y": 31,
      "z": -2,
      "name": "Rock_Quartzite"
    },
    {
      "x": -8,
      "y": 32,
      "z": -2,
      "name": "Rock_Quartzite"
    },
    {
      "x": -8,
      "y": 46,
      "z": -2,
      "name": "Soil_Dirt_Dry"
    },
    {
      "x": -8,
      "y": 47,
      "z": -2,
      "name": "Soil_Grass_Dry"
    },
    {
      "x": -8,
      "y": 54,
      "z": -2,
      "name": "Soil_Dirt_Dry"
    },
    {
      "x": -8,
      "y": 55,
      "z": -2,
      "name": "Soil_Dirt_Dry"
    },
    {
      "x": -8,
      "y": 56,
      "z": -2,
      "name": "Soil_Dirt_Dry"
    },
    {
      "x": -8,
      "y": 57,
      "z": -2,
      "name": "Soil_Sand_White"
    },
    {
      "x": -8,
      "y": 31,
      "z": -1,
      "name": "Rock_Quartzite"
    },
    {
      "x": -8,
      "y": 32,
      "z": -1,
      "name": "Rock_Quartzite"
    },
    {
      "x": -8,
      "y": 46,
      "z": -1,
      "name": "Soil_Dirt_Dry"
    },
    {
      "x": -8,
      "y": 47,
      "z": -1,
      "name": "Soil_Grass_Dry"
    },
    {
      "x": -8,
      "y": 48,
      "z": -1,
      "name": "Plant_Grass_Arid"
    },
    {
      "x": -8,
      "y": 54,
      "z": -1,
      "name": "Soil_Dirt_Dry"
    },
    {
      "x": -8,
      "y": 55,
      "z": -1,
      "name": "Soil_Dirt_Dry"
    },
    {
      "x": -8,
      "y": 56,
      "z": -1,
      "name": "Soil_Dirt_Dry"
    },
    {
      "x": -8,
      "y": 57,
      "z": -1,
      "name": "Soil_Sand_White"
    },
    {
      "x": -8,
      "y": 31,
      "z": 0,
      "name": "Rock_Quartzite"
    },
    {
      "x": -8,
      "y": 46,
      "z": 0,
      "name": "Soil_Dirt_Dry"
    },
    {
      "x": -8,
      "y": 47,
      "z": 0,
      "name": "Soil_Grass_Dry"
    },
    {
      "x": -8,
      "y": 54,
      "z": 0,
      "name": "Soil_Dirt_Dry"
    },
    {
      "x": -8,
      "y": 55,
      "z": 0,
      "name": "Soil_Dirt_Dry"
    },
    {
      "x": -8,
      "y": 56,
      "z": 0,
      "name": "Soil_Dirt_Dry"
    },
    {
      "x": -8,
      "y": 57,
      "z": 0,
      "name": "Soil_Sand_White"
    },
    {
      "x": -8,
      "y": 46,
      "z": 1,
      "name": "Soil_Dirt_Dry"
    },
    {
      "x": -8,
      "y": 47,
      "z": 1,
      "name": "Soil_Grass_Dry"
    },
    {
      "x": -8,
      "y": 48,
      "z": 1,
      "name": "Plant_Flower_Flax_Purple"
    },
    {
      "x": -8,
      "y": 54,
      "z": 1,
      "name": "Soil_Dirt_Dry"
    },
    {
      "x": -8,
      "y": 55,
      "z": 1,
      "name": "Soil_Dirt_Dry"
    },
    {
      "x": -8,
      "y": 56,
      "z": 1,
      "name": "Soil_Sand_White"
    },
    {
      "x": -8,
      "y": 45,
      "z": 2,
      "name": "Rock_Sandstone"
    },
    {
      "x": -8,
      "y": 46,
      "z": 2,
      "name": "Rock_Sandstone"
    },
    {
      "x": -8,
      "y": 47,
      "z": 2,
      "name": "Soil_Grass_Dry"
    },
    {
      "x": -8,
      "y": 54,
      "z": 2,
      "name": "Soil_Dirt_Dry"
    },
    {
      "x": -8,
      "y": 55,
      "z": 2,
      "name": "Soil_Dirt_Dry"
    },
    {
      "x": -8,
      "y": 56,
      "z": 2,
      "name": "Soil_Sand_White"
    },
    {
      "x": -8,
      "y": 44,
      "z": 3,
      "name": "Rock_Sandstone"
    },
    {
      "x": -8,
      "y": 45,
      "z": 3,
      "name": "Rock_Sandstone"
    },
    {
      "x": -8,
      "y": 46,
      "z": 3,
      "name": "Soil_Dirt_Dry"
    },
    {
      "x": -8,
      "y": 47,
      "z": 3,
      "name": "Soil_Grass_Dry"
    },
    {
      "x": -8,
      "y": 54,
      "z": 3,
      "name": "Soil_Dirt_Dry"
    },
    {
      "x": -8,
      "y": 55,
      "z": 3,
      "name": "Soil_Dirt_Dry"
    },
    {
      "x": -8,
      "y": 56,
      "z": 3,
      "name": "Soil_Sand_White"
    },
    {
      "x": -8,
      "y": 45,
      "z": 4,
      "name": "Rock_Sandstone"
    },
    {
      "x": -8,
      "y": 46,
      "z": 4,
      "name": "Soil_Grass_Dry"
    },
    {
      "x": -8,
      "y": 47,
      "z": 4,
      "name": "Plant_Grass_Dry_Tall"
    },
    {
      "x": -8,
      "y": 48,
      "z": 4,
      "name": "Plant_Grass_Dry_Tall",
      "filler": 1024
    },
    {
      "x": -8,
      "y": 54,
      "z": 4,
      "name": "Soil_Dirt_Dry"
    },
    {
      "x": -8,
      "y": 55,
      "z": 4,
      "name": "Soil_Dirt_Dry"
    },
    {
      "x": -8,
      "y": 56,
      "z": 4,
      "name": "Soil_Sand_White"
    },
    {
      "x": -8,
      "y": 45,
      "z": 5,
      "name": "Rock_Sandstone"
    },
    {
      "x": -8,
      "y": 46,
      "z": 5,
      "name": "Soil_Dirt_Dry"
    },
    {
      "x": -8,
      "y": 54,
      "z": 5,
      "name": "Soil_Dirt_Dry"
    },
    {
      "x": -8,
      "y": 55,
      "z": 5,
      "name": "Soil_Dirt_Dry"
    },
    {
      "x": -8,
      "y": 56,
      "z": 5,
      "name": "Soil_Sand_White"
    },
    {
      "x": -8,
      "y": 46,
      "z": 6,
      "name": "Soil_Dirt_Dry"
    },
    {
      "x": -8,
      "y": 54,
      "z": 6,
      "name": "Soil_Dirt_Dry"
    },
    {
      "x": -8,
      "y": 55,
      "z": 6,
      "name": "Soil_Sand_White"
    },
    {
      "x": -8,
      "y": 54,
      "z": 7,
      "name": "Soil_Dirt_Dry"
    },
    {
      "x": -8,
      "y": 55,
      "z": 7,
      "name": "Soil_Sand_White"
    },
    {
      "x": -8,
      "y": 56,
      "z": 7,
      "name": "Rubble_Sandstone_White"
    },
    {
      "x": -8,
      "y": 54,
      "z": 8,
      "name": "Soil_Dirt_Dry"
    },
    {
      "x": -8,
      "y": 55,
      "z": 8,
      "name": "Soil_Sand_White"
    },
    {
      "x": -8,
      "y": 54,
      "z": 9,
      "name": "Soil_Dirt_Dry"
    },
    {
      "x": -8,
      "y": 55,
      "z": 9,
      "name": "Soil_Sand_White"
    },
    {
      "x": -8,
      "y": 54,
      "z": 10,
      "name": "Soil_Dirt_Dry"
    },
    {
      "x": -8,
      "y": 55,
      "z": 10,
      "name": "Soil_Sand_White"
    },
    {
      "x": -8,
      "y": 54,
      "z": 11,
      "name": "Soil_Dirt_Dry"
    },
    {
      "x": -8,
      "y": 55,
      "z": 11,
      "name": "Soil_Dirt_Dry"
    },
    {
      "x": -8,
      "y": 54,
      "z": 12,
      "name": "Soil_Dirt_Dry"
    },
    {
      "x": -8,
      "y": 55,
      "z": 12,
      "name": "Soil_Dirt_Dry"
    },
    {
      "x": -7,
      "y": 55,
      "z": -16,
      "name": "Soil_Dirt_Dry"
    },
    {
      "x": -7,
      "y": 55,
      "z": -15,
      "name": "Soil_Dirt_Dry"
    },
    {
      "x": -7,
      "y": 56,
      "z": -15,
      "name": "Soil_Dirt_Dry"
    },
    {
      "x": -7,
      "y": 55,
      "z": -14,
      "name": "Soil_Dirt_Dry"
    },
    {
      "x": -7,
      "y": 56,
      "z": -14,
      "name": "Soil_Dirt_Dry"
    },
    {
      "x": -7,
      "y": 55,
      "z": -13,
      "name": "Soil_Dirt_Dry"
    },
    {
      "x": -7,
      "y": 56,
      "z": -13,
      "name": "Soil_Sand_White"
    },
    {
      "x": -7,
      "y": 55,
      "z": -12,
      "name": "Soil_Dirt_Dry"
    },
    {
      "x": -7,
      "y": 56,
      "z": -12,
      "name": "Soil_Sand_White"
    },
    {
      "x": -7,
      "y": 55,
      "z": -11,
      "name": "Soil_Dirt_Dry"
    },
    {
      "x": -7,
      "y": 56,
      "z": -11,
      "name": "Soil_Sand_White"
    },
    {
      "x": -7,
      "y": 55,
      "z": -10,
      "name": "Soil_Dirt_Dry"
    },
    {
      "x": -7,
      "y": 56,
      "z": -10,
      "name": "Soil_Sand_White"
    },
    {
      "x": -7,
      "y": 55,
      "z": -9,
      "name": "Soil_Dirt_Dry"
    },
    {
      "x": -7,
      "y": 56,
      "z": -9,
      "name": "Soil_Sand_White"
    },
    {
      "x": -7,
      "y": 55,
      "z": -8,
      "name": "Soil_Dirt_Dry"
    },
    {
      "x": -7,
      "y": 56,
      "z": -8,
      "name": "Soil_Sand_White"
    },
    {
      "x": -7,
      "y": 55,
      "z": -7,
      "name": "Soil_Dirt_Dry"
    },
    {
      "x": -7,
      "y": 56,
      "z": -7,
      "name": "Soil_Sand_White"
    },
    {
      "x": -7,
      "y": 31,
      "z": -6,
      "name": "Rock_Quartzite"
    },
    {
      "x": -7,
      "y": 44,
      "z": -6,
      "name": "Rock_Sandstone_Stalactite_Large",
      "filler": 31744,
      "rotation": 8
    },
    {
      "x": -7,
      "y": 45,
      "z": -6,
      "name": "Rock_Sandstone_Stalactite_Large",
      "rotation": 8
    },
    {
      "x": -7,
      "y": 46,
      "z": -6,
      "name": "Soil_Dirt_Dry"
    },
    {
      "x": -7,
      "y": 54,
      "z": -6,
      "name": "Soil_Dirt_Dry"
    },
    {
      "x": -7,
      "y": 55,
      "z": -6,
      "name": "Soil_Dirt_Dry"
    },
    {
      "x": -7,
      "y": 56,
      "z": -6,
      "name": "Soil_Sand_White"
    },
    {
      "x": -7,
      "y": 31,
      "z": -5,
      "name": "Rock_Quartzite"
    },
    {
      "x": -7,
      "y": 32,
      "z": -5,
      "name": "Rock_Quartzite"
    },
    {
      "x": -7,
      "y": 46,
      "z": -5,
      "name": "Soil_Dirt_Dry"
    },
    {
      "x": -7,
      "y": 54,
      "z": -5,
      "name": "Soil_Dirt_Dry"
    },
    {
      "x": -7,
      "y": 55,
      "z": -5,
      "name": "Soil_Dirt_Dry"
    },
    {
      "x": -7,
      "y": 56,
      "z": -5,
      "name": "Soil_Sand_White"
    },
    {
      "x": -7,
      "y": 31,
      "z": -4,
      "name": "Rock_Quartzite"
    },
    {
      "x": -7,
      "y": 32,
      "z": -4,
      "name": "Rock_Quartzite"
    },
    {
      "x": -7,
      "y": 46,
      "z": -4,
      "name": "Soil_Dirt_Dry"
    },
    {
      "x": -7,
      "y": 47,
      "z": -4,
      "name": "Soil_Dirt_Dry"
    },
    {
      "x": -7,
      "y": 54,
      "z": -4,
      "name": "Soil_Dirt_Dry"
    },
    {
      "x": -7,
      "y": 55,
      "z": -4,
      "name": "Soil_Dirt_Dry"
    },
    {
      "x": -7,
      "y": 56,
      "z": -4,
      "name": "Soil_Dirt_Dry"
    },
    {
      "x": -7,
      "y": 57,
      "z": -4,
      "name": "Soil_Sand_White"
    },
    {
      "x": -7,
      "y": 31,
      "z": -3,
      "name": "Rock_Quartzite"
    },
    {
      "x": -7,
      "y": 32,
      "z": -3,
      "name": "Rock_Quartzite"
    },
    {
      "x": -7,
      "y": 33,
      "z": -3,
      "name": "Rock_Quartzite"
    },
    {
      "x": -7,
      "y": 46,
      "z": -3,
      "name": "Soil_Dirt_Dry"
    },
    {
      "x": -7,
      "y": 47,
      "z": -3,
      "name": "Soil_Dirt_Dry"
    },
    {
      "x": -7,
      "y": 54,
      "z": -3,
      "name": "Soil_Dirt_Dry"
    },
    {
      "x": -7,
      "y": 55,
      "z": -3,
      "name": "Soil_Dirt_Dry"
    },
    {
      "x": -7,
      "y": 56,
      "z": -3,
      "name": "Soil_Dirt_Dry"
    },
    {
      "x": -7,
      "y": 57,
      "z": -3,
      "name": "Soil_Sand_White"
    },
    {
      "x": -7,
      "y": 30,
      "z": -2,
      "name": "Rock_Quartzite"
    },
    {
      "x": -7,
      "y": 31,
      "z": -2,
      "name": "Rock_Quartzite"
    },
    {
      "x": -7,
      "y": 32,
      "z": -2,
      "name": "Rock_Quartzite"
    },
    {
      "x": -7,
      "y": 33,
      "z": -2,
      "name": "Rock_Quartzite"
    },
    {
      "x": -7,
      "y": 46,
      "z": -2,
      "name": "Soil_Dirt_Dry"
    },
    {
      "x": -7,
      "y": 47,
      "z": -2,
      "name": "Soil_Grass_Dry"
    },
    {
      "x": -7,
      "y": 54,
      "z": -2,
      "name": "Soil_Dirt_Dry"
    },
    {
      "x": -7,
      "y": 55,
      "z": -2,
      "name": "Soil_Dirt_Dry"
    },
    {
      "x": -7,
      "y": 56,
      "z": -2,
      "name": "Soil_Dirt_Dry"
    },
    {
      "x": -7,
      "y": 57,
      "z": -2,
      "name": "Soil_Sand_White"
    },
    {
      "x": -7,
      "y": 30,
      "z": -1,
      "name": "Rock_Quartzite"
    },
    {
      "x": -7,
      "y": 31,
      "z": -1,
      "name": "Rock_Quartzite"
    },
    {
      "x": -7,
      "y": 32,
      "z": -1,
      "name": "Rock_Quartzite"
    },
    {
      "x": -7,
      "y": 33,
      "z": -1,
      "name": "Rock_Quartzite"
    },
    {
      "x": -7,
      "y": 46,
      "z": -1,
      "name": "Soil_Dirt_Dry"
    },
    {
      "x": -7,
      "y": 47,
      "z": -1,
      "name": "Soil_Grass_Dry"
    },
    {
      "x": -7,
      "y": 54,
      "z": -1,
      "name": "Soil_Dirt_Dry"
    },
    {
      "x": -7,
      "y": 55,
      "z": -1,
      "name": "Soil_Dirt_Dry"
    },
    {
      "x": -7,
      "y": 56,
      "z": -1,
      "name": "Soil_Dirt_Dry"
    },
    {
      "x": -7,
      "y": 57,
      "z": -1,
      "name": "Soil_Sand_White"
    },
    {
      "x": -7,
      "y": 30,
      "z": 0,
      "name": "Rock_Quartzite"
    },
    {
      "x": -7,
      "y": 31,
      "z": 0,
      "name": "Rock_Quartzite"
    },
    {
      "x": -7,
      "y": 32,
      "z": 0,
      "name": "Rock_Quartzite"
    },
    {
      "x": -7,
      "y": 33,
      "z": 0,
      "name": "Rock_Quartzite"
    },
    {
      "x": -7,
      "y": 46,
      "z": 0,
      "name": "Soil_Dirt_Dry"
    },
    {
      "x": -7,
      "y": 47,
      "z": 0,
      "name": "Soil_Grass_Dry"
    },
    {
      "x": -7,
      "y": 54,
      "z": 0,
      "name": "Soil_Dirt_Dry"
    },
    {
      "x": -7,
      "y": 55,
      "z": 0,
      "name": "Soil_Dirt_Dry"
    },
    {
      "x": -7,
      "y": 56,
      "z": 0,
      "name": "Soil_Dirt_Dry"
    },
    {
      "x": -7,
      "y": 57,
      "z": 0,
      "name": "Soil_Sand_White"
    },
    {
      "x": -7,
      "y": 31,
      "z": 1,
      "name": "Rock_Quartzite"
    },
    {
      "x": -7,
      "y": 32,
      "z": 1,
      "name": "Rock_Quartzite"
    },
    {
      "x": -7,
      "y": 46,
      "z": 1,
      "name": "Soil_Dirt_Dry"
    },
    {
      "x": -7,
      "y": 47,
      "z": 1,
      "name": "Soil_Grass_Dry"
    },
    {
      "x": -7,
      "y": 54,
      "z": 1,
      "name": "Soil_Dirt_Dry"
    },
    {
      "x": -7,
      "y": 55,
      "z": 1,
      "name": "Soil_Dirt_Dry"
    },
    {
      "x": -7,
      "y": 56,
      "z": 1,
      "name": "Soil_Dirt_Dry"
    },
    {
      "x": -7,
      "y": 57,
      "z": 1,
      "name": "Soil_Sand_White"
    },
    {
      "x": -7,
      "y": 44,
      "z": 2,
      "name": "Rock_Sandstone"
    },
    {
      "x": -7,
      "y": 45,
      "z": 2,
      "name": "Rock_Sandstone"
    },
    {
      "x": -7,
      "y": 46,
      "z": 2,
      "name": "Soil_Dirt_Dry"
    },
    {
      "x": -7,
      "y": 47,
      "z": 2,
      "name": "Soil_Grass_Dry"
    },
    {
      "x": -7,
      "y": 54,
      "z": 2,
      "name": "Soil_Dirt_Dry"
    },
    {
      "x": -7,
      "y": 55,
      "z": 2,
      "name": "Soil_Dirt_Dry"
    },
    {
      "x": -7,
      "y": 56,
      "z": 2,
      "name": "Soil_Dirt_Dry"
    },
    {
      "x": -7,
      "y": 57,
      "z": 2,
      "name": "Soil_Sand_White"
    },
    {
      "x": -7,
      "y": 31,
      "z": 3,
      "name": "Rock_Quartzite"
    },
    {
      "x": -7,
      "y": 32,
      "z": 3,
      "name": "Rock_Quartzite"
    },
    {
      "x": -7,
      "y": 43,
      "z": 3,
      "name": "Rock_Sandstone"
    },
    {
      "x": -7,
      "y": 44,
      "z": 3,
      "name": "Rock_Sandstone"
    },
    {
      "x": -7,
      "y": 45,
      "z": 3,
      "name": "Rock_Sandstone"
    },
    {
      "x": -7,
      "y": 46,
      "z": 3,
      "name": "Rock_Sandstone"
    },
    {
      "x": -7,
      "y": 47,
      "z": 3,
      "name": "Soil_Grass_Dry"
    },
    {
      "x": -7,
      "y": 54,
      "z": 3,
      "name": "Soil_Dirt_Dry"
    },
    {
      "x": -7,
      "y": 55,
      "z": 3,
      "name": "Soil_Dirt_Dry"
    },
    {
      "x": -7,
      "y": 56,
      "z": 3,
      "name": "Soil_Dirt_Dry"
    },
    {
      "x": -7,
      "y": 57,
      "z": 3,
      "name": "Soil_Sand_White"
    },
    {
      "x": -7,
      "y": 31,
      "z": 4,
      "name": "Rock_Quartzite"
    },
    {
      "x": -7,
      "y": 44,
      "z": 4,
      "name": "Rock_Sandstone"
    },
    {
      "x": -7,
      "y": 45,
      "z": 4,
      "name": "Rock_Sandstone"
    },
    {
      "x": -7,
      "y": 46,
      "z": 4,
      "name": "Soil_Dirt_Dry"
    },
    {
      "x": -7,
      "y": 47,
      "z": 4,
      "name": "Soil_Grass_Dry"
    },
    {
      "x": -7,
      "y": 54,
      "z": 4,
      "name": "Soil_Dirt_Dry"
    },
    {
      "x": -7,
      "y": 55,
      "z": 4,
      "name": "Soil_Dirt_Dry"
    },
    {
      "x": -7,
      "y": 56,
      "z": 4,
      "name": "Soil_Sand_White"
    },
    {
      "x": -7,
      "y": 45,
      "z": 5,
      "name": "Rock_Sandstone"
    },
    {
      "x": -7,
      "y": 46,
      "z": 5,
      "name": "Soil_Grass_Dry"
    },
    {
      "x": -7,
      "y": 47,
      "z": 5,
      "name": "Plant_Grass_Dry"
    },
    {
      "x": -7,
      "y": 54,
      "z": 5,
      "name": "Soil_Dirt_Dry"
    },
    {
      "x": -7,
      "y": 55,
      "z": 5,
      "name": "Soil_Dirt_Dry"
    },
    {
      "x": -7,
      "y": 56,
      "z": 5,
      "name": "Soil_Sand_White"
    },
    {
      "x": -7,
      "y": 44,
      "z": 6,
      "name": "Rock_Sandstone_Stalactite_Small",
      "rotation": 8
    },
    {
      "x": -7,
      "y": 45,
      "z": 6,
      "name": "Rock_Sandstone"
    },
    {
      "x": -7,
      "y": 46,
      "z": 6,
      "name": "Soil_Dirt_Dry"
    },
    {
      "x": -7,
      "y": 54,
      "z": 6,
      "name": "Soil_Dirt_Dry"
    },
    {
      "x": -7,
      "y": 55,
      "z": 6,
      "name": "Soil_Sand_White"
    },
    {
      "x": -7,
      "y": 56,
      "z": 6,
      "name": "Soil_Sand_White"
    },
    {
      "x": -7,
      "y": 54,
      "z": 7,
      "name": "Soil_Dirt_Dry"
    },
    {
      "x": -7,
      "y": 55,
      "z": 7,
      "name": "Soil_Sand_White"
    },
    {
      "x": -7,
      "y": 54,
      "z": 8,
      "name": "Soil_Dirt_Dry"
    },
    {
      "x": -7,
      "y": 55,
      "z": 8,
      "name": "Soil_Sand_White"
    },
    {
      "x": -7,
      "y": 54,
      "z": 9,
      "name": "Soil_Dirt_Dry"
    },
    {
      "x": -7,
      "y": 55,
      "z": 9,
      "name": "Soil_Sand_White"
    },
    {
      "x": -7,
      "y": 54,
      "z": 10,
      "name": "Soil_Dirt_Dry"
    },
    {
      "x": -7,
      "y": 55,
      "z": 10,
      "name": "Soil_Sand_White"
    },
    {
      "x": -7,
      "y": 54,
      "z": 11,
      "name": "Soil_Dirt_Dry"
    },
    {
      "x": -7,
      "y": 55,
      "z": 11,
      "name": "Soil_Sand_White"
    },
    {
      "x": -7,
      "y": 54,
      "z": 12,
      "name": "Soil_Dirt_Dry"
    },
    {
      "x": -7,
      "y": 55,
      "z": 12,
      "name": "Soil_Dirt_Dry"
    },
    {
      "x": -6,
      "y": 55,
      "z": -16,
      "name": "Soil_Dirt_Dry"
    },
    {
      "x": -6,
      "y": 56,
      "z": -16,
      "name": "Soil_Dirt_Dry"
    },
    {
      "x": -6,
      "y": 55,
      "z": -15,
      "name": "Soil_Dirt_Dry"
    },
    {
      "x": -6,
      "y": 56,
      "z": -15,
      "name": "Soil_Dirt_Dry"
    },
    {
      "x": -6,
      "y": 55,
      "z": -14,
      "name": "Soil_Dirt_Dry"
    },
    {
      "x": -6,
      "y": 56,
      "z": -14,
      "name": "Soil_Sand_White"
    },
    {
      "x": -6,
      "y": 55,
      "z": -13,
      "name": "Soil_Dirt_Dry"
    },
    {
      "x": -6,
      "y": 56,
      "z": -13,
      "name": "Soil_Sand_White"
    },
    {
      "x": -6,
      "y": 55,
      "z": -12,
      "name": "Soil_Dirt_Dry"
    },
    {
      "x": -6,
      "y": 56,
      "z": -12,
      "name": "Soil_Sand_White"
    },
    {
      "x": -6,
      "y": 55,
      "z": -11,
      "name": "Soil_Dirt_Dry"
    },
    {
      "x": -6,
      "y": 56,
      "z": -11,
      "name": "Soil_Sand_White"
    },
    {
      "x": -6,
      "y": 55,
      "z": -10,
      "name": "Soil_Dirt_Dry"
    },
    {
      "x": -6,
      "y": 56,
      "z": -10,
      "name": "Soil_Sand_White"
    },
    {
      "x": -6,
      "y": 55,
      "z": -9,
      "name": "Soil_Dirt_Dry"
    },
    {
      "x": -6,
      "y": 56,
      "z": -9,
      "name": "Soil_Sand_White"
    },
    {
      "x": -6,
      "y": 55,
      "z": -8,
      "name": "Soil_Dirt_Dry"
    },
    {
      "x": -6,
      "y": 56,
      "z": -8,
      "name": "Soil_Sand_White"
    },
    {
      "x": -6,
      "y": 31,
      "z": -7,
      "name": "Rock_Quartzite"
    },
    {
      "x": -6,
      "y": 46,
      "z": -7,
      "name": "Soil_Dirt_Dry"
    },
    {
      "x": -6,
      "y": 55,
      "z": -7,
      "name": "Soil_Dirt_Dry"
    },
    {
      "x": -6,
      "y": 56,
      "z": -7,
      "name": "Soil_Dirt_Dry"
    },
    {
      "x": -6,
      "y": 57,
      "z": -7,
      "name": "Soil_Sand_White"
    },
    {
      "x": -6,
      "y": 31,
      "z": -6,
      "name": "Rock_Quartzite"
    },
    {
      "x": -6,
      "y": 45,
      "z": -6,
      "name": "Rock_Sandstone"
    },
    {
      "x": -6,
      "y": 46,
      "z": -6,
      "name": "Soil_Dirt_Dry"
    },
    {
      "x": -6,
      "y": 54,
      "z": -6,
      "name": "Soil_Dirt_Dry"
    },
    {
      "x": -6,
      "y": 55,
      "z": -6,
      "name": "Soil_Dirt_Dry"
    },
    {
      "x": -6,
      "y": 56,
      "z": -6,
      "name": "Soil_Dirt_Dry"
    },
    {
      "x": -6,
      "y": 57,
      "z": -6,
      "name": "Soil_Sand_White"
    },
    {
      "x": -6,
      "y": 31,
      "z": -5,
      "name": "Rock_Quartzite"
    },
    {
      "x": -6,
      "y": 32,
      "z": -5,
      "name": "Rock_Quartzite"
    },
    {
      "x": -6,
      "y": 45,
      "z": -5,
      "name": "Rock_Sandstone"
    },
    {
      "x": -6,
      "y": 46,
      "z": -5,
      "name": "Soil_Dirt_Dry"
    },
    {
      "x": -6,
      "y": 47,
      "z": -5,
      "name": "Soil_Dirt_Dry"
    },
    {
      "x": -6,
      "y": 54,
      "z": -5,
      "name": "Soil_Dirt_Dry"
    },
    {
      "x": -6,
      "y": 55,
      "z": -5,
      "name": "Soil_Dirt_Dry"
    },
    {
      "x": -6,
      "y": 56,
      "z": -5,
      "name": "Soil_Dirt_Dry"
    },
    {
      "x": -6,
      "y": 57,
      "z": -5,
      "name": "Soil_Sand_White"
    },
    {
      "x": -6,
      "y": 30,
      "z": -4,
      "name": "Rock_Quartzite"
    },
    {
      "x": -6,
      "y": 31,
      "z": -4,
      "name": "Rock_Quartzite"
    },
    {
      "x": -6,
      "y": 32,
      "z": -4,
      "name": "Rock_Quartzite"
    },
    {
      "x": -6,
      "y": 33,
      "z": -4,
      "name": "Rock_Quartzite"
    },
    {
      "x": -6,
      "y": 43,
      "z": -4,
      "name": "Rock_Quartzite"
    },
    {
      "x": -6,
      "y": 44,
      "z": -4,
      "name": "Rock_Quartzite"
    },
    {
      "x": -6,
      "y": 45,
      "z": -4,
      "name": "Rock_Sandstone"
    },
    {
      "x": -6,
      "y": 46,
      "z": -4,
      "name": "Soil_Dirt_Dry"
    },
    {
      "x": -6,
      "y": 47,
      "z": -4,
      "name": "Soil_Dirt_Dry"
    },
    {
      "x": -6,
      "y": 54,
      "z": -4,
      "name": "Soil_Dirt_Dry"
    },
    {
      "x": -6,
      "y": 55,
      "z": -4,
      "name": "Soil_Dirt_Dry"
    },
    {
      "x": -6,
      "y": 56,
      "z": -4,
      "name": "Soil_Dirt_Dry"
    },
    {
      "x": -6,
      "y": 57,
      "z": -4,
      "name": "Soil_Sand_White"
    },
    {
      "x": -6,
      "y": 30,
      "z": -3,
      "name": "Rock_Quartzite"
    },
    {
      "x": -6,
      "y": 31,
      "z": -3,
      "name": "Rock_Quartzite"
    },
    {
      "x": -6,
      "y": 32,
      "z": -3,
      "name": "Rock_Quartzite"
    },
    {
      "x": -6,
      "y": 33,
      "z": -3,
      "name": "Rock_Quartzite"
    },
    {
      "x": -6,
      "y": 34,
      "z": -3,
      "name": "Rock_Quartzite"
    },
    {
      "x": -6,
      "y": 42,
      "z": -3,
      "name": "Rock_Quartzite"
    },
    {
      "x": -6,
      "y": 43,
      "z": -3,
      "name": "Rock_Quartzite"
    },
    {
      "x": -6,
      "y": 44,
      "z": -3,
      "name": "Rock_Quartzite"
    },
    {
      "x": -6,
      "y": 46,
      "z": -3,
      "name": "Soil_Dirt_Dry"
    },
    {
      "x": -6,
      "y": 47,
      "z": -3,
      "name": "Soil_Grass_Dry"
    },
    {
      "x": -6,
      "y": 54,
      "z": -3,
      "name": "Soil_Dirt_Dry"
    },
    {
      "x": -6,
      "y": 55,
      "z": -3,
      "name": "Soil_Dirt_Dry"
    },
    {
      "x": -6,
      "y": 56,
      "z": -3,
      "name": "Soil_Dirt_Dry"
    },
    {
      "x": -6,
      "y": 57,
      "z": -3,
      "name": "Soil_Sand_White"
    },
    {
      "x": -6,
      "y": 22,
      "z": -2,
      "name": "Rock_Sandstone_White"
    },
    {
      "x": -6,
      "y": 29,
      "z": -2,
      "name": "Rock_Quartzite"
    },
    {
      "x": -6,
      "y": 30,
      "z": -2,
      "name": "Rock_Quartzite"
    },
    {
      "x": -6,
      "y": 31,
      "z": -2,
      "name": "Rock_Quartzite"
    },
    {
      "x": -6,
      "y": 32,
      "z": -2,
      "name": "Rock_Quartzite"
    },
    {
      "x": -6,
      "y": 33,
      "z": -2,
      "name": "Rock_Quartzite"
    },
    {
      "x": -6,
      "y": 34,
      "z": -2,
      "name": "Rock_Quartzite"
    },
    {
      "x": -6,
      "y": 42,
      "z": -2,
      "name": "Rock_Quartzite"
    },
    {
      "x": -6,
      "y": 43,
      "z": -2,
      "name": "Rock_Quartzite"
    },
    {
      "x": -6,
      "y": 44,
      "z": -2,
      "name": "Rock_Quartzite"
    },
    {
      "x": -6,
      "y": 46,
      "z": -2,
      "name": "Soil_Dirt_Dry"
    },
    {
      "x": -6,
      "y": 47,
      "z": -2,
      "name": "Soil_Grass_Dry"
    },
    {
      "x": -6,
      "y": 54,
      "z": -2,
      "name": "Soil_Dirt_Dry"
    },
    {
      "x": -6,
      "y": 55,
      "z": -2,
      "name": "Soil_Dirt_Dry"
    },
    {
      "x": -6,
      "y": 56,
      "z": -2,
      "name": "Soil_Dirt_Dry"
    },
    {
      "x": -6,
      "y": 57,
      "z": -2,
      "name": "Soil_Sand_White"
    },
    {
      "x": -6,
      "y": 22,
      "z": -1,
      "name": "Rock_Sandstone_White"
    },
    {
      "x": -6,
      "y": 23,
      "z": -1,
      "name": "Rock_Sandstone_White"
    },
    {
      "x": -6,
      "y": 29,
      "z": -1,
      "name": "Rock_Quartzite"
    },
    {
      "x": -6,
      "y": 30,
      "z": -1,
      "name": "Rock_Quartzite"
    },
    {
      "x": -6,
      "y": 31,
      "z": -1,
      "name": "Rock_Quartzite"
    },
    {
      "x": -6,
      "y": 32,
      "z": -1,
      "name": "Rock_Quartzite"
    },
    {
      "x": -6,
      "y": 33,
      "z": -1,
      "name": "Rock_Quartzite"
    },
    {
      "x": -6,
      "y": 34,
      "z": -1,
      "name": "Rock_Quartzite"
    },
    {
      "x": -6,
      "y": 43,
      "z": -1,
      "name": "Rock_Quartzite"
    },
    {
      "x": -6,
      "y": 44,
      "z": -1,
      "name": "Rock_Quartzite"
    },
    {
      "x": -6,
      "y": 46,
      "z": -1,
      "name": "Soil_Dirt_Dry"
    },
    {
      "x": -6,
      "y": 47,
      "z": -1,
      "name": "Soil_Grass_Dry"
    },
    {
      "x": -6,
      "y": 54,
      "z": -1,
      "name": "Soil_Dirt_Dry"
    },
    {
      "x": -6,
      "y": 55,
      "z": -1,
      "name": "Soil_Dirt_Dry"
    },
    {
      "x": -6,
      "y": 56,
      "z": -1,
      "name": "Soil_Dirt_Dry"
    },
    {
      "x": -6,
      "y": 57,
      "z": -1,
      "name": "Soil_Sand_White"
    },
    {
      "x": -6,
      "y": 22,
      "z": 0,
      "name": "Rock_Quartzite"
    },
    {
      "x": -6,
      "y": 23,
      "z": 0,
      "name": "Rock_Sandstone_White"
    },
    {
      "x": -6,
      "y": 29,
      "z": 0,
      "name": "Rock_Quartzite"
    },
    {
      "x": -6,
      "y": 30,
      "z": 0,
      "name": "Rock_Quartzite"
    },
    {
      "x": -6,
      "y": 31,
      "z": 0,
      "name": "Rock_Quartzite"
    },
    {
      "x": -6,
      "y": 32,
      "z": 0,
      "name": "Rock_Quartzite"
    },
    {
      "x": -6,
      "y": 33,
      "z": 0,
      "name": "Rock_Quartzite"
    },
    {
      "x": -6,
      "y": 34,
      "z": 0,
      "name": "Rock_Quartzite"
    },
    {
      "x": -6,
      "y": 46,
      "z": 0,
      "name": "Soil_Dirt_Dry"
    },
    {
      "x": -6,
      "y": 47,
      "z": 0,
      "name": "Soil_Grass_Dry"
    },
    {
      "x": -6,
      "y": 54,
      "z": 0,
      "name": "Soil_Dirt_Dry"
    },
    {
      "x": -6,
      "y": 55,
      "z": 0,
      "name": "Soil_Dirt_Dry"
    },
    {
      "x": -6,
      "y": 56,
      "z": 0,
      "name": "Soil_Dirt_Dry"
    },
    {
      "x": -6,
      "y": 57,
      "z": 0,
      "name": "Soil_Sand_White"
    },
    {
      "x": -6,
      "y": 30,
      "z": 1,
      "name": "Rock_Quartzite"
    },
    {
      "x": -6,
      "y": 31,
      "z": 1,
      "name": "Rock_Quartzite"
    },
    {
      "x": -6,
      "y": 32,
      "z": 1,
      "name": "Rock_Quartzite"
    },
    {
      "x": -6,
      "y": 33,
      "z": 1,
      "name": "Rock_Quartzite"
    },
    {
      "x": -6,
      "y": 46,
      "z": 1,
      "name": "Soil_Dirt_Dry"
    },
    {
      "x": -6,
      "y": 47,
      "z": 1,
      "name": "Soil_Grass_Dry"
    },
    {
      "x": -6,
      "y": 54,
      "z": 1,
      "name": "Soil_Dirt_Dry"
    },
    {
      "x": -6,
      "y": 55,
      "z": 1,
      "name": "Soil_Dirt_Dry"
    },
    {
      "x": -6,
      "y": 56,
      "z": 1,
      "name": "Soil_Dirt_Dry"
    },
    {
      "x": -6,
      "y": 57,
      "z": 1,
      "name": "Soil_Sand_White"
    },
    {
      "x": -6,
      "y": 31,
      "z": 2,
      "name": "Rock_Quartzite"
    },
    {
      "x": -6,
      "y": 32,
      "z": 2,
      "name": "Rock_Quartzite"
    },
    {
      "x": -6,
      "y": 33,
      "z": 2,
      "name": "Rock_Quartzite"
    },
    {
      "x": -6,
      "y": 42,
      "z": 2,
      "name": "Rock_Sandstone"
    },
    {
      "x": -6,
      "y": 43,
      "z": 2,
      "name": "Rock_Sandstone"
    },
    {
      "x": -6,
      "y": 44,
      "z": 2,
      "name": "Rock_Sandstone"
    },
    {
      "x": -6,
      "y": 46,
      "z": 2,
      "name": "Soil_Dirt_Dry"
    },
    {
      "x": -6,
      "y": 47,
      "z": 2,
      "name": "Soil_Grass_Dry"
    },
    {
      "x": -6,
      "y": 54,
      "z": 2,
      "name": "Soil_Dirt_Dry"
    },
    {
      "x": -6,
      "y": 55,
      "z": 2,
      "name": "Soil_Dirt_Dry"
    },
    {
      "x": -6,
      "y": 56,
      "z": 2,
      "name": "Soil_Dirt_Dry"
    },
    {
      "x": -6,
      "y": 57,
      "z": 2,
      "name": "Soil_Sand_White"
    },
    {
      "x": -6,
      "y": 31,
      "z": 3,
      "name": "Rock_Quartzite"
    },
    {
      "x": -6,
      "y": 32,
      "z": 3,
      "name": "Rock_Quartzite"
    },
    {
      "x": -6,
      "y": 33,
      "z": 3,
      "name": "Rock_Quartzite"
    },
    {
      "x": -6,
      "y": 42,
      "z": 3,
      "name": "Rock_Sandstone"
    },
    {
      "x": -6,
      "y": 43,
      "z": 3,
      "name": "Rock_Sandstone"
    },
    {
      "x": -6,
      "y": 44,
      "z": 3,
      "name": "Rock_Sandstone"
    },
    {
      "x": -6,
      "y": 45,
      "z": 3,
      "name": "Rock_Sandstone"
    },
    {
      "x": -6,
      "y": 46,
      "z": 3,
      "name": "Soil_Dirt_Dry"
    },
    {
      "x": -6,
      "y": 47,
      "z": 3,
      "name": "Soil_Grass_Dry"
    },
    {
      "x": -6,
      "y": 54,
      "z": 3,
      "name": "Soil_Dirt_Dry"
    },
    {
      "x": -6,
      "y": 55,
      "z": 3,
      "name": "Soil_Dirt_Dry"
    },
    {
      "x": -6,
      "y": 56,
      "z": 3,
      "name": "Soil_Dirt_Dry"
    },
    {
      "x": -6,
      "y": 57,
      "z": 3,
      "name": "Soil_Sand_White"
    },
    {
      "x": -6,
      "y": 31,
      "z": 4,
      "name": "Rock_Quartzite"
    },
    {
      "x": -6,
      "y": 32,
      "z": 4,
      "name": "Rock_Quartzite"
    },
    {
      "x": -6,
      "y": 33,
      "z": 4,
      "name": "Rock_Quartzite"
    },
    {
      "x": -6,
      "y": 43,
      "z": 4,
      "name": "Rock_Sandstone"
    },
    {
      "x": -6,
      "y": 44,
      "z": 4,
      "name": "Rock_Sandstone"
    },
    {
      "x": -6,
      "y": 46,
      "z": 4,
      "name": "Soil_Dirt_Dry"
    },
    {
      "x": -6,
      "y": 47,
      "z": 4,
      "name": "Soil_Grass_Dry"
    },
    {
      "x": -6,
      "y": 48,
      "z": 4,
      "name": "Plant_Flower_Common_Cyan"
    },
    {
      "x": -6,
      "y": 54,
      "z": 4,
      "name": "Soil_Dirt_Dry"
    },
    {
      "x": -6,
      "y": 55,
      "z": 4,
      "name": "Soil_Dirt_Dry"
    },
    {
      "x": -6,
      "y": 56,
      "z": 4,
      "name": "Soil_Dirt_Dry"
    },
    {
      "x": -6,
      "y": 57,
      "z": 4,
      "name": "Soil_Sand_White"
    },
    {
      "x": -6,
      "y": 31,
      "z": 5,
      "name": "Rock_Quartzite"
    },
    {
      "x": -6,
      "y": 32,
      "z": 5,
      "name": "Rock_Quartzite"
    },
    {
      "x": -6,
      "y": 46,
      "z": 5,
      "name": "Soil_Dirt_Dry"
    },
    {
      "x": -6,
      "y": 47,
      "z": 5,
      "name": "Soil_Grass_Dry"
    },
    {
      "x": -6,
      "y": 48,
      "z": 5,
      "name": "Plant_Grass_Arid"
    },
    {
      "x": -6,
      "y": 54,
      "z": 5,
      "name": "Soil_Dirt_Dry"
    },
    {
      "x": -6,
      "y": 55,
      "z": 5,
      "name": "Soil_Dirt_Dry"
    },
    {
      "x": -6,
      "y": 56,
      "z": 5,
      "name": "Soil_Sand_White"
    },
    {
      "x": -6,
      "y": 46,
      "z": 6,
      "name": "Soil_Dirt_Dry"
    },
    {
      "x": -6,
      "y": 47,
      "z": 6,
      "name": "Rubble_Sandstone_Medium"
    },
    {
      "x": -6,
      "y": 54,
      "z": 6,
      "name": "Soil_Dirt_Dry"
    },
    {
      "x": -6,
      "y": 55,
      "z": 6,
      "name": "Soil_Dirt_Dry"
    },
    {
      "x": -6,
      "y": 56,
      "z": 6,
      "name": "Soil_Sand_White"
    },
    {
      "x": -6,
      "y": 46,
      "z": 7,
      "name": "Soil_Dirt_Dry"
    },
    {
      "x": -6,
      "y": 54,
      "z": 7,
      "name": "Soil_Dirt_Dry"
    },
    {
      "x": -6,
      "y": 55,
      "z": 7,
      "name": "Soil_Sand_White"
    },
    {
      "x": -6,
      "y": 56,
      "z": 7,
      "name": "Soil_Sand_White"
    },
    {
      "x": -6,
      "y": 54,
      "z": 8,
      "name": "Soil_Dirt_Dry"
    },
    {
      "x": -6,
      "y": 55,
      "z": 8,
      "name": "Soil_Sand_White"
    },
    {
      "x": -6,
      "y": 54,
      "z": 9,
      "name": "Soil_Dirt_Dry"
    },
    {
      "x": -6,
      "y": 55,
      "z": 9,
      "name": "Soil_Sand_White"
    },
    {
      "x": -6,
      "y": 54,
      "z": 10,
      "name": "Soil_Dirt_Dry"
    },
    {
      "x": -6,
      "y": 55,
      "z": 10,
      "name": "Soil_Sand_White"
    },
    {
      "x": -6,
      "y": 54,
      "z": 11,
      "name": "Soil_Dirt_Dry"
    },
    {
      "x": -6,
      "y": 55,
      "z": 11,
      "name": "Soil_Sand_White"
    },
    {
      "x": -6,
      "y": 54,
      "z": 12,
      "name": "Soil_Dirt_Dry"
    },
    {
      "x": -5,
      "y": 55,
      "z": -17,
      "name": "Soil_Dirt_Dry"
    },
    {
      "x": -5,
      "y": 55,
      "z": -16,
      "name": "Soil_Dirt_Dry"
    },
    {
      "x": -5,
      "y": 56,
      "z": -16,
      "name": "Soil_Dirt_Dry"
    },
    {
      "x": -5,
      "y": 55,
      "z": -15,
      "name": "Soil_Dirt_Dry"
    },
    {
      "x": -5,
      "y": 56,
      "z": -15,
      "name": "Soil_Sand_White"
    },
    {
      "x": -5,
      "y": 55,
      "z": -14,
      "name": "Soil_Dirt_Dry"
    },
    {
      "x": -5,
      "y": 56,
      "z": -14,
      "name": "Soil_Sand_White"
    },
    {
      "x": -5,
      "y": 55,
      "z": -13,
      "name": "Soil_Dirt_Dry"
    },
    {
      "x": -5,
      "y": 56,
      "z": -13,
      "name": "Soil_Sand_White"
    },
    {
      "x": -5,
      "y": 55,
      "z": -12,
      "name": "Soil_Dirt_Dry"
    },
    {
      "x": -5,
      "y": 56,
      "z": -12,
      "name": "Soil_Sand_White"
    },
    {
      "x": -5,
      "y": 55,
      "z": -11,
      "name": "Soil_Dirt_Dry"
    },
    {
      "x": -5,
      "y": 56,
      "z": -11,
      "name": "Soil_Sand_White"
    },
    {
      "x": -5,
      "y": 55,
      "z": -10,
      "name": "Soil_Dirt_Dry"
    },
    {
      "x": -5,
      "y": 56,
      "z": -10,
      "name": "Soil_Sand_White"
    },
    {
      "x": -5,
      "y": 55,
      "z": -9,
      "name": "Soil_Dirt_Dry"
    },
    {
      "x": -5,
      "y": 56,
      "z": -9,
      "name": "Soil_Dirt_Dry"
    },
    {
      "x": -5,
      "y": 57,
      "z": -9,
      "name": "Soil_Sand_White"
    },
    {
      "x": -5,
      "y": 46,
      "z": -8,
      "name": "Soil_Dirt_Dry"
    },
    {
      "x": -5,
      "y": 55,
      "z": -8,
      "name": "Soil_Dirt_Dry"
    },
    {
      "x": -5,
      "y": 56,
      "z": -8,
      "name": "Soil_Dirt_Dry"
    },
    {
      "x": -5,
      "y": 57,
      "z": -8,
      "name": "Soil_Sand_White"
    },
    {
      "x": -5,
      "y": 58,
      "z": -8,
      "name": "Rubble_Sandstone_White"
    },
    {
      "x": -5,
      "y": 31,
      "z": -7,
      "name": "Rock_Quartzite"
    },
    {
      "x": -5,
      "y": 32,
      "z": -7,
      "name": "Rock_Quartzite"
    },
    {
      "x": -5,
      "y": 46,
      "z": -7,
      "name": "Soil_Dirt_Dry"
    },
    {
      "x": -5,
      "y": 54,
      "z": -7,
      "name": "Soil_Dirt_Dry"
    },
    {
      "x": -5,
      "y": 55,
      "z": -7,
      "name": "Soil_Dirt_Dry"
    },
    {
      "x": -5,
      "y": 56,
      "z": -7,
      "name": "Soil_Dirt_Dry"
    },
    {
      "x": -5,
      "y": 57,
      "z": -7,
      "name": "Soil_Sand_White"
    },
    {
      "x": -5,
      "y": 31,
      "z": -6,
      "name": "Rock_Quartzite"
    },
    {
      "x": -5,
      "y": 32,
      "z": -6,
      "name": "Rock_Quartzite"
    },
    {
      "x": -5,
      "y": 33,
      "z": -6,
      "name": "Rock_Quartzite"
    },
    {
      "x": -5,
      "y": 44,
      "z": -6,
      "name": "Rock_Sandstone_Stalactite_Small",
      "rotation": 8
    },
    {
      "x": -5,
      "y": 45,
      "z": -6,
      "name": "Rock_Sandstone"
    },
    {
      "x": -5,
      "y": 46,
      "z": -6,
      "name": "Soil_Dirt_Dry"
    },
    {
      "x": -5,
      "y": 47,
      "z": -6,
      "name": "Rubble_Sandstone_Medium"
    },
    {
      "x": -5,
      "y": 54,
      "z": -6,
      "name": "Soil_Dirt_Dry"
    },
    {
      "x": -5,
      "y": 55,
      "z": -6,
      "name": "Soil_Dirt_Dry"
    },
    {
      "x": -5,
      "y": 56,
      "z": -6,
      "name": "Soil_Dirt_Dry"
    },
    {
      "x": -5,
      "y": 57,
      "z": -6,
      "name": "Soil_Sand_White"
    },
    {
      "x": -5,
      "y": 29,
      "z": -5,
      "name": "Rock_Quartzite"
    },
    {
      "x": -5,
      "y": 30,
      "z": -5,
      "name": "Rock_Quartzite"
    },
    {
      "x": -5,
      "y": 31,
      "z": -5,
      "name": "Rock_Quartzite"
    },
    {
      "x": -5,
      "y": 32,
      "z": -5,
      "name": "Rock_Quartzite"
    },
    {
      "x": -5,
      "y": 33,
      "z": -5,
      "name": "Rock_Quartzite"
    },
    {
      "x": -5,
      "y": 34,
      "z": -5,
      "name": "Rock_Quartzite"
    },
    {
      "x": -5,
      "y": 43,
      "z": -5,
      "name": "Rock_Quartzite"
    },
    {
      "x": -5,
      "y": 44,
      "z": -5,
      "name": "Rock_Quartzite"
    },
    {
      "x": -5,
      "y": 45,
      "z": -5,
      "name": "Rock_Sandstone"
    },
    {
      "x": -5,
      "y": 46,
      "z": -5,
      "name": "Soil_Dirt_Dry"
    },
    {
      "x": -5,
      "y": 47,
      "z": -5,
      "name": "Rock_Sandstone"
    },
    {
      "x": -5,
      "y": 54,
      "z": -5,
      "name": "Soil_Dirt_Dry"
    },
    {
      "x": -5,
      "y": 55,
      "z": -5,
      "name": "Soil_Dirt_Dry"
    },
    {
      "x": -5,
      "y": 56,
      "z": -5,
      "name": "Soil_Dirt_Dry"
    },
    {
      "x": -5,
      "y": 57,
      "z": -5,
      "name": "Soil_Sand_White"
    },
    {
      "x": -5,
      "y": 22,
      "z": -4,
      "name": "Rock_Sandstone_White"
    },
    {
      "x": -5,
      "y": 29,
      "z": -4,
      "name": "Rock_Quartzite"
    },
    {
      "x": -5,
      "y": 30,
      "z": -4,
      "name": "Rock_Quartzite"
    },
    {
      "x": -5,
      "y": 31,
      "z": -4,
      "name": "Rock_Quartzite"
    },
    {
      "x": -5,
      "y": 32,
      "z": -4,
      "name": "Rock_Quartzite"
    },
    {
      "x": -5,
      "y": 33,
      "z": -4,
      "name": "Rock_Quartzite"
    },
    {
      "x": -5,
      "y": 34,
      "z": -4,
      "name": "Rock_Quartzite"
    },
    {
      "x": -5,
      "y": 41,
      "z": -4,
      "name": "Rock_Quartzite"
    },
    {
      "x": -5,
      "y": 42,
      "z": -4,
      "name": "Rock_Quartzite"
    },
    {
      "x": -5,
      "y": 43,
      "z": -4,
      "name": "Rock_Quartzite"
    },
    {
      "x": -5,
      "y": 44,
      "z": -4,
      "name": "Rock_Quartzite"
    },
    {
      "x": -5,
      "y": 45,
      "z": -4,
      "name": "Rock_Quartzite"
    },
    {
      "x": -5,
      "y": 46,
      "z": -4,
      "name": "Soil_Dirt_Dry"
    },
    {
      "x": -5,
      "y": 47,
      "z": -4,
      "name": "Soil_Grass_Dry"
    },
    {
      "x": -5,
      "y": 54,
      "z": -4,
      "name": "Soil_Dirt_Dry"
    },
    {
      "x": -5,
      "y": 55,
      "z": -4,
      "name": "Soil_Dirt_Dry"
    },
    {
      "x": -5,
      "y": 56,
      "z": -4,
      "name": "Soil_Dirt_Dry"
    },
    {
      "x": -5,
      "y": 57,
      "z": -4,
      "name": "Soil_Sand_White"
    },
    {
      "x": -5,
      "y": 22,
      "z": -3,
      "name": "Rock_Sandstone_White"
    },
    {
      "x": -5,
      "y": 23,
      "z": -3,
      "name": "Rock_Sandstone_White"
    },
    {
      "x": -5,
      "y": 28,
      "z": -3,
      "name": "Rock_Quartzite"
    },
    {
      "x": -5,
      "y": 29,
      "z": -3,
      "name": "Rock_Quartzite"
    },
    {
      "x": -5,
      "y": 30,
      "z": -3,
      "name": "Rock_Quartzite"
    },
    {
      "x": -5,
      "y": 31,
      "z": -3,
      "name": "Rock_Quartzite"
    },
    {
      "x": -5,
      "y": 32,
      "z": -3,
      "name": "Rock_Quartzite"
    },
    {
      "x": -5,
      "y": 33,
      "z": -3,
      "name": "Rock_Quartzite"
    },
    {
      "x": -5,
      "y": 34,
      "z": -3,
      "name": "Rock_Quartzite"
    },
    {
      "x": -5,
      "y": 40,
      "z": -3,
      "name": "Rock_Quartzite"
    },
    {
      "x": -5,
      "y": 41,
      "z": -3,
      "name": "Rock_Quartzite"
    },
    {
      "x": -5,
      "y": 42,
      "z": -3,
      "name": "Rock_Quartzite"
    },
    {
      "x": -5,
      "y": 43,
      "z": -3,
      "name": "Rock_Quartzite"
    },
    {
      "x": -5,
      "y": 44,
      "z": -3,
      "name": "Rock_Quartzite"
    },
    {
      "x": -5,
      "y": 45,
      "z": -3,
      "name": "Rock_Quartzite"
    },
    {
      "x": -5,
      "y": 46,
      "z": -3,
      "name": "Soil_Dirt_Dry"
    },
    {
      "x": -5,
      "y": 47,
      "z": -3,
      "name": "Soil_Grass_Dry"
    },
    {
      "x": -5,
      "y": 54,
      "z": -3,
      "name": "Soil_Dirt_Dry"
    },
    {
      "x": -5,
      "y": 55,
      "z": -3,
      "name": "Soil_Dirt_Dry"
    },
    {
      "x": -5,
      "y": 56,
      "z": -3,
      "name": "Soil_Dirt_Dry"
    },
    {
      "x": -5,
      "y": 57,
      "z": -3,
      "name": "Soil_Sand_White"
    },
    {
      "x": -5,
      "y": 21,
      "z": -2,
      "name": "Rock_Quartzite"
    },
    {
      "x": -5,
      "y": 22,
      "z": -2,
      "name": "Rock_Quartzite"
    },
    {
      "x": -5,
      "y": 23,
      "z": -2,
      "name": "Rock_Sandstone_White"
    },
    {
      "x": -5,
      "y": 28,
      "z": -2,
      "name": "Rock_Quartzite"
    },
    {
      "x": -5,
      "y": 29,
      "z": -2,
      "name": "Rock_Quartzite"
    },
    {
      "x": -5,
      "y": 30,
      "z": -2,
      "name": "Rock_Quartzite"
    },
    {
      "x": -5,
      "y": 31,
      "z": -2,
      "name": "Rock_Quartzite"
    },
    {
      "x": -5,
      "y": 32,
      "z": -2,
      "name": "Rock_Quartzite"
    },
    {
      "x": -5,
      "y": 33,
      "z": -2,
      "name": "Rock_Quartzite"
    },
    {
      "x": -5,
      "y": 34,
      "z": -2,
      "name": "Rock_Quartzite"
    },
    {
      "x": -5,
      "y": 35,
      "z": -2,
      "name": "Rock_Quartzite"
    },
    {
      "x": -5,
      "y": 40,
      "z": -2,
      "name": "Rock_Quartzite"
    },
    {
      "x": -5,
      "y": 41,
      "z": -2,
      "name": "Rock_Quartzite"
    },
    {
      "x": -5,
      "y": 42,
      "z": -2,
      "name": "Rock_Quartzite"
    },
    {
      "x": -5,
      "y": 43,
      "z": -2,
      "name": "Rock_Quartzite"
    },
    {
      "x": -5,
      "y": 44,
      "z": -2,
      "name": "Rock_Quartzite"
    },
    {
      "x": -5,
      "y": 45,
      "z": -2,
      "name": "Rock_Quartzite"
    },
    {
      "x": -5,
      "y": 46,
      "z": -2,
      "name": "Rock_Quartzite"
    },
    {
      "x": -5,
      "y": 47,
      "z": -2,
      "name": "Soil_Grass_Dry"
    },
    {
      "x": -5,
      "y": 54,
      "z": -2,
      "name": "Soil_Dirt_Dry"
    },
    {
      "x": -5,
      "y": 55,
      "z": -2,
      "name": "Soil_Dirt_Dry"
    },
    {
      "x": -5,
      "y": 56,
      "z": -2,
      "name": "Soil_Dirt_Dry"
    },
    {
      "x": -5,
      "y": 57,
      "z": -2,
      "name": "Soil_Dirt_Dry"
    },
    {
      "x": -5,
      "y": 58,
      "z": -2,
      "name": "Soil_Sand_White"
    },
    {
      "x": -5,
      "y": 21,
      "z": -1,
      "name": "Rock_Quartzite"
    },
    {
      "x": -5,
      "y": 22,
      "z": -1,
      "name": "Rock_Quartzite"
    },
    {
      "x": -5,
      "y": 23,
      "z": -1,
      "name": "Rock_Sandstone_White"
    },
    {
      "x": -5,
      "y": 28,
      "z": -1,
      "name": "Rock_Quartzite"
    },
    {
      "x": -5,
      "y": 29,
      "z": -1,
      "name": "Rock_Quartzite"
    },
    {
      "x": -5,
      "y": 30,
      "z": -1,
      "name": "Rock_Quartzite"
    },
    {
      "x": -5,
      "y": 31,
      "z": -1,
      "name": "Rock_Quartzite"
    },
    {
      "x": -5,
      "y": 32,
      "z": -1,
      "name": "Rock_Quartzite"
    },
    {
      "x": -5,
      "y": 33,
      "z": -1,
      "name": "Rock_Quartzite"
    },
    {
      "x": -5,
      "y": 34,
      "z": -1,
      "name": "Rock_Quartzite"
    },
    {
      "x": -5,
      "y": 35,
      "z": -1,
      "name": "Rock_Quartzite"
    },
    {
      "x": -5,
      "y": 40,
      "z": -1,
      "name": "Rock_Quartzite"
    },
    {
      "x": -5,
      "y": 41,
      "z": -1,
      "name": "Rock_Quartzite"
    },
    {
      "x": -5,
      "y": 42,
      "z": -1,
      "name": "Rock_Quartzite"
    },
    {
      "x": -5,
      "y": 43,
      "z": -1,
      "name": "Rock_Quartzite"
    },
    {
      "x": -5,
      "y": 44,
      "z": -1,
      "name": "Rock_Quartzite"
    },
    {
      "x": -5,
      "y": 45,
      "z": -1,
      "name": "Rock_Quartzite"
    },
    {
      "x": -5,
      "y": 46,
      "z": -1,
      "name": "Soil_Dirt_Dry"
    },
    {
      "x": -5,
      "y": 47,
      "z": -1,
      "name": "Soil_Grass_Dry"
    },
    {
      "x": -5,
      "y": 54,
      "z": -1,
      "name": "Soil_Dirt_Dry"
    },
    {
      "x": -5,
      "y": 55,
      "z": -1,
      "name": "Soil_Dirt_Dry"
    },
    {
      "x": -5,
      "y": 56,
      "z": -1,
      "name": "Soil_Dirt_Dry"
    },
    {
      "x": -5,
      "y": 57,
      "z": -1,
      "name": "Soil_Dirt_Dry"
    },
    {
      "x": -5,
      "y": 58,
      "z": -1,
      "name": "Soil_Sand_White"
    },
    {
      "x": -5,
      "y": 21,
      "z": 0,
      "name": "Rock_Quartzite"
    },
    {
      "x": -5,
      "y": 22,
      "z": 0,
      "name": "Rock_Quartzite"
    },
    {
      "x": -5,
      "y": 23,
      "z": 0,
      "name": "Rock_Sandstone_White"
    },
    {
      "x": -5,
      "y": 29,
      "z": 0,
      "name": "Rock_Quartzite"
    },
    {
      "x": -5,
      "y": 30,
      "z": 0,
      "name": "Rock_Quartzite"
    },
    {
      "x": -5,
      "y": 31,
      "z": 0,
      "name": "Rock_Quartzite"
    },
    {
      "x": -5,
      "y": 32,
      "z": 0,
      "name": "Rock_Quartzite"
    },
    {
      "x": -5,
      "y": 33,
      "z": 0,
      "name": "Rock_Quartzite"
    },
    {
      "x": -5,
      "y": 34,
      "z": 0,
      "name": "Rock_Quartzite"
    },
    {
      "x": -5,
      "y": 35,
      "z": 0,
      "name": "Rock_Quartzite"
    },
    {
      "x": -5,
      "y": 41,
      "z": 0,
      "name": "Rock_Quartzite"
    },
    {
      "x": -5,
      "y": 42,
      "z": 0,
      "name": "Rock_Quartzite"
    },
    {
      "x": -5,
      "y": 43,
      "z": 0,
      "name": "Rock_Quartzite"
    },
    {
      "x": -5,
      "y": 44,
      "z": 0,
      "name": "Rock_Quartzite"
    },
    {
      "x": -5,
      "y": 45,
      "z": 0,
      "name": "Rock_Quartzite"
    },
    {
      "x": -5,
      "y": 46,
      "z": 0,
      "name": "Soil_Dirt_Dry"
    },
    {
      "x": -5,
      "y": 47,
      "z": 0,
      "name": "Soil_Grass_Dry"
    },
    {
      "x": -5,
      "y": 54,
      "z": 0,
      "name": "Soil_Dirt_Dry"
    },
    {
      "x": -5,
      "y": 55,
      "z": 0,
      "name": "Soil_Dirt_Dry"
    },
    {
      "x": -5,
      "y": 56,
      "z": 0,
      "name": "Soil_Dirt_Dry"
    },
    {
      "x": -5,
      "y": 57,
      "z": 0,
      "name": "Soil_Dirt_Dry"
    },
    {
      "x": -5,
      "y": 58,
      "z": 0,
      "name": "Soil_Sand_White"
    },
    {
      "x": -5,
      "y": 22,
      "z": 1,
      "name": "Rock_Quartzite"
    },
    {
      "x": -5,
      "y": 23,
      "z": 1,
      "name": "Rock_Sandstone_White"
    },
    {
      "x": -5,
      "y": 29,
      "z": 1,
      "name": "Rock_Quartzite"
    },
    {
      "x": -5,
      "y": 30,
      "z": 1,
      "name": "Rock_Quartzite"
    },
    {
      "x": -5,
      "y": 31,
      "z": 1,
      "name": "Rock_Quartzite"
    },
    {
      "x": -5,
      "y": 32,
      "z": 1,
      "name": "Rock_Quartzite"
    },
    {
      "x": -5,
      "y": 33,
      "z": 1,
      "name": "Rock_Quartzite"
    },
    {
      "x": -5,
      "y": 34,
      "z": 1,
      "name": "Rock_Quartzite"
    },
    {
      "x": -5,
      "y": 41,
      "z": 1,
      "name": "Rock_Sandstone"
    },
    {
      "x": -5,
      "y": 42,
      "z": 1,
      "name": "Rock_Sandstone"
    },
    {
      "x": -5,
      "y": 43,
      "z": 1,
      "name": "Rock_Sandstone"
    },
    {
      "x": -5,
      "y": 46,
      "z": 1,
      "name": "Soil_Dirt_Dry"
    },
    {
      "x": -5,
      "y": 47,
      "z": 1,
      "name": "Soil_Grass_Dry"
    },
    {
      "x": -5,
      "y": 54,
      "z": 1,
      "name": "Soil_Dirt_Dry"
    },
    {
      "x": -5,
      "y": 55,
      "z": 1,
      "name": "Soil_Dirt_Dry"
    },
    {
      "x": -5,
      "y": 56,
      "z": 1,
      "name": "Soil_Dirt_Dry"
    },
    {
      "x": -5,
      "y": 57,
      "z": 1,
      "name": "Soil_Sand_White"
    },
    {
      "x": -5,
      "y": 22,
      "z": 2,
      "name": "Rock_Quartzite"
    },
    {
      "x": -5,
      "y": 23,
      "z": 2,
      "name": "Rock_Sandstone_White"
    },
    {
      "x": -5,
      "y": 30,
      "z": 2,
      "name": "Rock_Quartzite"
    },
    {
      "x": -5,
      "y": 31,
      "z": 2,
      "name": "Rock_Quartzite"
    },
    {
      "x": -5,
      "y": 32,
      "z": 2,
      "name": "Rock_Quartzite"
    },
    {
      "x": -5,
      "y": 33,
      "z": 2,
      "name": "Rock_Quartzite"
    },
    {
      "x": -5,
      "y": 34,
      "z": 2,
      "name": "Rock_Quartzite"
    },
    {
      "x": -5,
      "y": 40,
      "z": 2,
      "name": "Rock_Sandstone"
    },
    {
      "x": -5,
      "y": 41,
      "z": 2,
      "name": "Rock_Sandstone"
    },
    {
      "x": -5,
      "y": 42,
      "z": 2,
      "name": "Rock_Sandstone"
    },
    {
      "x": -5,
      "y": 43,
      "z": 2,
      "name": "Rock_Sandstone"
    },
    {
      "x": -5,
      "y": 46,
      "z": 2,
      "name": "Soil_Dirt_Dry"
    },
    {
      "x": -5,
      "y": 47,
      "z": 2,
      "name": "Soil_Grass_Dry"
    },
    {
      "x": -5,
      "y": 54,
      "z": 2,
      "name": "Soil_Dirt_Dry"
    },
    {
      "x": -5,
      "y": 55,
      "z": 2,
      "name": "Soil_Dirt_Dry"
    },
    {
      "x": -5,
      "y": 56,
      "z": 2,
      "name": "Soil_Dirt_Dry"
    },
    {
      "x": -5,
      "y": 57,
      "z": 2,
      "name": "Soil_Sand_White"
    },
    {
      "x": -5,
      "y": 22,
      "z": 3,
      "name": "Rock_Quartzite"
    },
    {
      "x": -5,
      "y": 23,
      "z": 3,
      "name": "Rock_Sandstone_White"
    },
    {
      "x": -5,
      "y": 30,
      "z": 3,
      "name": "Rock_Quartzite"
    },
    {
      "x": -5,
      "y": 31,
      "z": 3,
      "name": "Rock_Quartzite"
    },
    {
      "x": -5,
      "y": 32,
      "z": 3,
      "name": "Rock_Quartzite"
    },
    {
      "x": -5,
      "y": 33,
      "z": 3,
      "name": "Rock_Quartzite"
    },
    {
      "x": -5,
      "y": 34,
      "z": 3,
      "name": "Rock_Quartzite"
    },
    {
      "x": -5,
      "y": 41,
      "z": 3,
      "name": "Rock_Sandstone"
    },
    {
      "x": -5,
      "y": 42,
      "z": 3,
      "name": "Rock_Sandstone"
    },
    {
      "x": -5,
      "y": 43,
      "z": 3,
      "name": "Rock_Sandstone"
    },
    {
      "x": -5,
      "y": 46,
      "z": 3,
      "name": "Soil_Dirt_Dry"
    },
    {
      "x": -5,
      "y": 47,
      "z": 3,
      "name": "Soil_Grass_Dry"
    },
    {
      "x": -5,
      "y": 54,
      "z": 3,
      "name": "Rock_Sandstone"
    },
    {
      "x": -5,
      "y": 55,
      "z": 3,
      "name": "Soil_Dirt_Dry"
    },
    {
      "x": -5,
      "y": 56,
      "z": 3,
      "name": "Soil_Dirt_Dry"
    },
    {
      "x": -5,
      "y": 57,
      "z": 3,
      "name": "Soil_Sand_White"
    },
    {
      "x": -5,
      "y": 23,
      "z": 4,
      "name": "Rock_Sandstone_White"
    },
    {
      "x": -5,
      "y": 30,
      "z": 4,
      "name": "Rock_Quartzite"
    },
    {
      "x": -5,
      "y": 31,
      "z": 4,
      "name": "Rock_Quartzite"
    },
    {
      "x": -5,
      "y": 32,
      "z": 4,
      "name": "Rock_Quartzite"
    },
    {
      "x": -5,
      "y": 33,
      "z": 4,
      "name": "Rock_Quartzite"
    },
    {
      "x": -5,
      "y": 46,
      "z": 4,
      "name": "Soil_Dirt_Dry"
    },
    {
      "x": -5,
      "y": 47,
      "z": 4,
      "name": "Soil_Grass_Dry"
    },
    {
      "x": -5,
      "y": 54,
      "z": 4,
      "name": "Soil_Dirt_Dry"
    },
    {
      "x": -5,
      "y": 55,
      "z": 4,
      "name": "Soil_Dirt_Dry"
    },
    {
      "x": -5,
      "y": 56,
      "z": 4,
      "name": "Soil_Dirt_Dry"
    },
    {
      "x": -5,
      "y": 57,
      "z": 4,
      "name": "Soil_Sand_White"
    },
    {
      "x": -5,
      "y": 30,
      "z": 5,
      "name": "Rock_Quartzite"
    },
    {
      "x": -5,
