{
  "version": 8,
  "blockIdVersion": 0,
  "anchorX": 9,
  "anchorY": 9,
  "anchorZ": 9,
  "blocks": [
    {
      "x": 5,
      "y": 14,
      "z": 8,
      "name": "Plant_Leaves_Ash"
    },
    {
      "x": 5,
      "y": 14,
      "z": 9,
      "name": "Plant_Leaves_Ash"
    },
    {
      "x": 5,
      "y": 15,
      "z": 9,
      "name": "Plant_Leaves_Ash"
    },
    {
      "x": 5,
      "y": 14,
      "z": 10,
      "name": "Plant_Leaves_Ash"
    },
    {
      "x": 6,
      "y": 14,
      "z": 7,
      "name": "Plant_Leaves_Ash"
    },
    {
      "x": 6,
      "y": 14,
      "z": 8,
      "name": "Plant_Leaves_Ash"
    },
    {
      "x": 6,
      "y": 15,
      "z": 8,
      "name": "Plant_Leaves_Ash"
    },
    {
      "x": 6,
      "y": 17,
      "z": 8,
      "name": "Plant_Leaves_Ash"
    },
    {
      "x": 6,
      "y": 18,
      "z": 8,
      "name": "Plant_Leaves_Ash"
    },
    {
      "x": 6,
      "y": 19,
      "z": 8,
      "name": "Plant_Leaves_Ash"
    },
    {
      "x": 6,
      "y": 14,
      "z": 9,
      "name": "Plant_Leaves_Ash"
    },
    {
      "x": 6,
      "y": 15,
      "z": 9,
      "name": "Plant_Leaves_Ash"
    },
    {
      "x": 6,
      "y": 17,
      "z": 9,
      "name": "Plant_Leaves_Ash"
    },
    {
      "x": 6,
      "y": 18,
      "z": 9,
      "name": "Plant_Leaves_Ash"
    },
    {
      "x": 6,
      "y": 14,
      "z": 10,
      "name": "Plant_Leaves_Ash"
    },
    {
      "x": 6,
      "y": 15,
      "z": 10,
      "name": "Plant_Leaves_Ash"
    },
    {
      "x": 6,
      "y": 17,
      "z": 10,
      "name": "Plant_Leaves_Ash"
    },
    {
      "x": 6,
      "y": 18,
      "z": 10,
      "name": "Plant_Leaves_Ash"
    },
    {
      "x": 6,
      "y": 14,
      "z": 11,
      "name": "Plant_Leaves_Ash"
    },
    {
      "x": 6,
      "y": 15,
      "z": 11,
      "name": "Plant_Leaves_Ash"
    },
    {
      "x": 7,
      "y": 17,
      "z": 6,
      "name": "Plant_Leaves_Ash"
    },
    {
      "x": 7,
      "y": 14,
      "z": 7,
      "name": "Plant_Leaves_Ash"
    },
    {
      "x": 7,
      "y": 15,
      "z": 7,
      "name": "Plant_Leaves_Ash"
    },
    {
      "x": 7,
      "y": 14,
      "z": 8,
      "name": "Plant_Leaves_Ash"
    },
    {
      "x": 7,
      "y": 15,
      "z": 8,
      "name": "Plant_Leaves_Ash"
    },
    {
      "x": 7,
      "y": 17,
      "z": 8,
      "name": "Plant_Leaves_Ash"
    },
    {
      "x": 7,
      "y": 19,
      "z": 8,
      "name": "Plant_Leaves_Ash"
    },
    {
      "x": 7,
      "y": 14,
      "z": 9,
      "name": "Plant_Leaves_Ash"
    },
    {
      "x": 7,
      "y": 15,
      "z": 9,
      "name": "Plant_Leaves_Ash"
    },
    {
      "x": 7,
      "y": 17,
      "z": 9,
      "name": "Wood_Ash_Branch_Long",
      "rotation": 5
    },
    {
      "x": 7,
      "y": 18,
      "z": 9,
      "name": "Plant_Leaves_Ash"
    },
    {
      "x": 7,
      "y": 19,
      "z": 9,
      "name": "Plant_Leaves_Ash"
    },
    {
      "x": 7,
      "y": 20,
      "z": 9,
      "name": "Plant_Leaves_Ash"
    },
    {
      "x": 7,
      "y": 21,
      "z": 9,
      "name": "Plant_Leaves_Ash"
    },
    {
      "x": 7,
      "y": 14,
      "z": 10,
      "name": "Plant_Leaves_Ash"
    },
    {
      "x": 7,
      "y": 15,
      "z": 10,
      "name": "Plant_Leaves_Ash"
    },
    {
      "x": 7,
      "y": 17,
      "z": 10,
      "name": "Plant_Leaves_Ash"
    },
    {
      "x": 7,
      "y": 18,
      "z": 10,
      "name": "Plant_Leaves_Ash"
    },
    {
      "x": 7,
      "y": 19,
      "z": 10,
      "name": "Plant_Leaves_Ash"
    },
    {
      "x": 7,
      "y": 20,
      "z": 10,
      "name": "Plant_Leaves_Ash"
    },
    {
      "x": 7,
      "y": 14,
      "z": 11,
      "name": "Plant_Leaves_Ash"
    },
    {
      "x": 7,
      "y": 15,
      "z": 11,
      "name": "Plant_Leaves_Ash"
    },
    {
      "x": 7,
      "y": 14,
      "z": 12,
      "name": "Plant_Leaves_Ash"
    },
    {
      "x": 7,
      "y": 17,
      "z": 12,
      "name": "Plant_Leaves_Ash"
    },
    {
      "x": 7,
      "y": 14,
      "z": 13,
      "name": "Plant_Leaves_Ash"
    },
    {
      "x": 8,
      "y": 17,
      "z": 5,
      "name": "Plant_Leaves_Ash"
    },
    {
      "x": 8,
      "y": 17,
      "z": 6,
      "name": "Plant_Leaves_Ash"
    },
    {
      "x": 8,
      "y": 18,
      "z": 6,
      "name": "Plant_Leaves_Ash"
    },
    {
      "x": 8,
      "y": 18,
      "z": 7,
      "name": "Plant_Leaves_Ash"
    },
    {
      "x": 8,
      "y": 14,
      "z": 8,
      "name": "Plant_Leaves_Ash"
    },
    {
      "x": 8,
      "y": 21,
      "z": 8,
      "name": "Plant_Leaves_Ash"
    },
    {
      "x": 8,
      "y": 14,
      "z": 9,
      "name": "Wood_Ash_Branch_Long",
      "rotation": 5
    },
    {
      "x": 8,
      "y": 16,
      "z": 9,
      "name": "Wood_Ash_Trunk_Full"
    },
    {
      "x": 8,
      "y": 17,
      "z": 9,
      "name": "Wood_Ash_Trunk_Full"
    },
    {
      "x": 8,
      "y": 19,
      "z": 9,
      "name": "Plant_Leaves_Ash"
    },
    {
      "x": 8,
      "y": 20,
      "z": 9,
      "name": "Plant_Leaves_Ash"
    },
    {
      "x": 8,
      "y": 21,
      "z": 9,
      "name": "Plant_Leaves_Ash"
    },
    {
      "x": 8,
      "y": 22,
      "z": 9,
      "name": "Plant_Leaves_Ash"
    },
    {
      "x": 8,
      "y": 14,
      "z": 10,
      "name": "Plant_Leaves_Ash"
    },
    {
      "x": 8,
      "y": 19,
      "z": 10,
      "name": "Plant_Leaves_Ash"
    },
    {
      "x": 8,
      "y": 20,
      "z": 10,
      "name": "Plant_Leaves_Ash"
    },
    {
      "x": 8,
      "y": 21,
      "z": 10,
      "name": "Plant_Leaves_Ash"
    },
    {
      "x": 8,
      "y": 18,
      "z": 11,
      "name": "Plant_Leaves_Ash"
    },
    {
      "x": 8,
      "y": 19,
      "z": 11,
      "name": "Plant_Leaves_Ash"
    },
    {
      "x": 8,
      "y": 14,
      "z": 12,
      "name": "Plant_Leaves_Ash"
    },
    {
      "x": 8,
      "y": 15,
      "z": 12,
      "name": "Plant_Leaves_Ash"
    },
    {
      "x": 8,
      "y": 17,
      "z": 12,
      "name": "Plant_Leaves_Ash"
    },
    {
      "x": 8,
      "y": 18,
      "z": 12,
      "name": "Plant_Leaves_Ash"
    },
    {
      "x": 8,
      "y": 19,
      "z": 12,
      "name": "Plant_Leaves_Ash"
    },
    {
      "x": 8,
      "y": 14,
      "z": 13,
      "name": "Plant_Leaves_Ash"
    },
    {
      "x": 8,
      "y": 14,
      "z": 14,
      "name": "Plant_Leaves_Ash"
    },
    {
      "x": 9,
      "y": 16,
      "z": 5,
      "name": "Plant_Leaves_Ash"
    },
    {
      "x": 9,
      "y": 17,
      "z": 5,
      "name": "Plant_Leaves_Ash"
    },
    {
      "x": 9,
      "y": 17,
      "z": 6,
      "name": "Plant_Leaves_Ash"
    },
    {
      "x": 9,
      "y": 18,
      "z": 6,
      "name": "Plant_Leaves_Ash"
    },
    {
      "x": 9,
      "y": 19,
      "z": 6,
      "name": "Plant_Leaves_Ash"
    },
    {
      "x": 9,
      "y": 16,
      "z": 7,
      "name": "Wood_Ash_Trunk_Full"
    },
    {
      "x": 9,
      "y": 17,
      "z": 7,
      "name": "Wood_Ash_Trunk_Full"
    },
    {
      "x": 9,
      "y": 18,
      "z": 7,
      "name": "Wood_Ash_Branch_Long"
    },
    {
      "x": 9,
      "y": 19,
      "z": 7,
      "name": "Plant_Leaves_Ash"
    },
    {
      "x": 9,
      "y": 20,
      "z": 7,
      "name": "Plant_Leaves_Ash"
    },
    {
      "x": 9,
      "y": 21,
      "z": 7,
      "name": "Plant_Leaves_Ash"
    },
    {
      "x": 9,
      "y": 15,
      "z": 8,
      "name": "Wood_Ash_Trunk_Full"
    },
    {
      "x": 9,
      "y": 16,
      "z": 8,
      "name": "Wood_Ash_Trunk_Full"
    },
    {
      "x": 9,
      "y": 20,
      "z": 8,
      "name": "Wood_Ash_Branch_Long",
      "rotation": 4
    },
    {
      "x": 9,
      "y": 21,
      "z": 8,
      "name": "Plant_Leaves_Ash"
    },
    {
      "x": 9,
      "y": 22,
      "z": 8,
      "name": "Plant_Leaves_Ash"
    },
    {
      "x": 9,
      "y": 9,
      "z": 9,
      "name": "Wood_Ash_Trunk"
    },
    {
      "x": 9,
      "y": 10,
      "z": 9,
      "name": "Wood_Ash_Trunk"
    },
    {
      "x": 9,
      "y": 11,
      "z": 9,
      "name": "Wood_Ash_Trunk"
    },
    {
      "x": 9,
      "y": 12,
      "z": 9,
      "name": "Wood_Ash_Trunk"
    },
    {
      "x": 9,
      "y": 13,
      "z": 9,
      "name": "Wood_Ash_Trunk"
    },
    {
      "x": 9,
      "y": 14,
      "z": 9,
      "name": "Wood_Ash_Trunk"
    },
    {
      "x": 9,
      "y": 15,
      "z": 9,
      "name": "Wood_Ash_Trunk"
    },
    {
      "x": 9,
      "y": 16,
      "z": 9,
      "name": "Wood_Ash_Trunk"
    },
    {
      "x": 9,
      "y": 17,
      "z": 9,
      "name": "Wood_Ash_Trunk"
    },
    {
      "x": 9,
      "y": 18,
      "z": 9,
      "name": "Wood_Ash_Trunk"
    },
    {
      "x": 9,
      "y": 19,
      "z": 9,
      "name": "Wood_Ash_Trunk_Full"
    },
    {
      "x": 9,
      "y": 20,
      "z": 9,
      "name": "Wood_Ash_Trunk_Full"
    },
    {
      "x": 9,
      "y": 21,
      "z": 9,
      "name": "Wood_Ash_Branch_Long"
    },
    {
      "x": 9,
      "y": 22,
      "z": 9,
      "name": "Plant_Leaves_Ash"
    },
    {
      "x": 9,
      "y": 9,
      "z": 10,
      "name": "Wood_Ash_Trunk"
    },
    {
      "x": 9,
      "y": 10,
      "z": 10,
      "name": "Wood_Ash_Trunk"
    },
    {
      "x": 9,
      "y": 11,
      "z": 10,
      "name": "Wood_Ash_Trunk_Full"
    },
    {
      "x": 9,
      "y": 19,
      "z": 10,
      "name": "Plant_Leaves_Ash"
    },
    {
      "x": 9,
      "y": 20,
      "z": 10,
      "name": "Plant_Leaves_Ash"
    },
    {
      "x": 9,
      "y": 21,
      "z": 10,
      "name": "Plant_Leaves_Ash"
    },
    {
      "x": 9,
      "y": 22,
      "z": 10,
      "name": "Plant_Leaves_Ash"
    },
    {
      "x": 9,
      "y": 14,
      "z": 11,
      "name": "Wood_Ash_Trunk_Full"
    },
    {
      "x": 9,
      "y": 19,
      "z": 11,
      "name": "Plant_Leaves_Ash"
    },
    {
      "x": 9,
      "y": 14,
      "z": 12,
      "name": "Wood_Ash_Branch_Long",
      "rotation": 4
    },
    {
      "x": 9,
      "y": 15,
      "z": 12,
      "name": "Plant_Leaves_Ash"
    },
    {
      "x": 9,
      "y": 17,
      "z": 12,
      "name": "Plant_Leaves_Ash"
    },
    {
      "x": 9,
      "y": 14,
      "z": 13,
      "name": "Plant_Leaves_Ash"
    },
    {
      "x": 9,
      "y": 15,
      "z": 13,
      "name": "Plant_Leaves_Ash"
    },
    {
      "x": 9,
      "y": 14,
      "z": 14,
      "name": "Plant_Leaves_Ash"
    },
    {
      "x": 10,
      "y": 16,
      "z": 5,
      "name": "Plant_Leaves_Ash"
    },
    {
      "x": 10,
      "y": 17,
      "z": 5,
      "name": "Plant_Leaves_Ash"
    },
    {
      "x": 10,
      "y": 15,
      "z": 6,
      "name": "Plant_Leaves_Ash"
    },
    {
      "x": 10,
      "y": 17,
      "z": 6,
      "name": "Plant_Leaves_Ash"
    },
    {
      "x": 10,
      "y": 19,
      "z": 6,
      "name": "Plant_Leaves_Ash"
    },
    {
      "x": 10,
      "y": 20,
      "z": 6,
      "name": "Plant_Leaves_Ash"
    },
    {
      "x": 10,
      "y": 19,
      "z": 7,
      "name": "Plant_Leaves_Ash"
    },
    {
      "x": 10,
      "y": 20,
      "z": 7,
      "name": "Plant_Leaves_Ash"
    },
    {
      "x": 10,
      "y": 21,
      "z": 8,
      "name": "Plant_Leaves_Ash"
    },
    {
      "x": 10,
      "y": 22,
      "z": 8,
      "name": "Plant_Leaves_Ash"
    },
    {
      "x": 10,
      "y": 9,
      "z": 9,
      "name": "Wood_Ash_Trunk"
    },
    {
      "x": 10,
      "y": 10,
      "z": 9,
      "name": "Wood_Ash_Trunk_Full"
    },
    {
      "x": 10,
      "y": 14,
      "z": 9,
      "name": "Wood_Ash_Trunk_Full"
    },
    {
      "x": 10,
      "y": 15,
      "z": 9,
      "name": "Wood_Ash_Trunk_Full"
    },
    {
      "x": 10,
      "y": 19,
      "z": 9,
      "name": "Wood_Ash_Trunk_Full"
    },
    {
      "x": 10,
      "y": 20,
      "z": 9,
      "name": "Plant_Leaves_Ash"
    },
    {
      "x": 10,
      "y": 21,
      "z": 9,
      "name": "Plant_Leaves_Ash"
    },
    {
      "x": 10,
      "y": 22,
      "z": 9,
      "name": "Plant_Leaves_Ash"
    },
    {
      "x": 10,
      "y": 9,
      "z": 10,
      "name": "Wood_Ash_Trunk"
    },
    {
      "x": 10,
      "y": 10,
      "z": 10,
      "name": "Wood_Ash_Trunk"
    },
    {
      "x": 10,
      "y": 11,
      "z": 10,
      "name": "Wood_Ash_Trunk"
    },
    {
      "x": 10,
      "y": 12,
      "z": 10,
      "name": "Wood_Ash_Trunk"
    },
    {
      "x": 10,
      "y": 13,
      "z": 10,
      "name": "Wood_Ash_Trunk"
    },
    {
      "x": 10,
      "y": 14,
      "z": 10,
      "name": "Wood_Ash_Trunk_Full"
    },
    {
      "x": 10,
      "y": 19,
      "z": 10,
      "name": "Wood_Ash_Trunk_Full"
    },
    {
      "x": 10,
      "y": 20,
      "z": 10,
      "name": "Wood_Ash_Trunk_Full"
    },
    {
      "x": 10,
      "y": 14,
      "z": 11,
      "name": "Wood_Ash_Trunk_Full"
    },
    {
      "x": 10,
      "y": 15,
      "z": 11,
      "name": "Wood_Ash_Trunk_Full"
    },
    {
      "x": 10,
      "y": 20,
      "z": 11,
      "name": "Plant_Leaves_Ash"
    },
    {
      "x": 10,
      "y": 21,
      "z": 11,
      "name": "Plant_Leaves_Ash"
    },
    {
      "x": 10,
      "y": 14,
      "z": 12,
      "name": "Plant_Leaves_Ash"
    },
    {
      "x": 10,
      "y": 18,
      "z": 12,
      "name": "Plant_Leaves_Ash"
    },
    {
      "x": 10,
      "y": 19,
      "z": 12,
      "name": "Plant_Leaves_Ash"
    },
    {
      "x": 10,
      "y": 14,
      "z": 13,
      "name": "Plant_Leaves_Ash"
    },
    {
      "x": 10,
      "y": 15,
      "z": 13,
      "name": "Plant_Leaves_Ash"
    },
    {
      "x": 10,
      "y": 18,
      "z": 13,
      "name": "Plant_Leaves_Ash"
    },
    {
      "x": 10,
      "y": 19,
      "z": 13,
      "name": "Plant_Leaves_Ash"
    },
    {
      "x": 11,
      "y": 14,
      "z": 5,
      "name": "Plant_Leaves_Ash"
    },
    {
      "x": 11,
      "y": 15,
      "z": 5,
      "name": "Plant_Leaves_Ash"
    },
    {
      "x": 11,
      "y": 16,
      "z": 5,
      "name": "Plant_Leaves_Ash"
    },
    {
      "x": 11,
      "y": 14,
      "z": 6,
      "name": "Plant_Leaves_Ash"
    },
    {
      "x": 11,
      "y": 15,
      "z": 6,
      "name": "Plant_Leaves_Ash"
    },
    {
      "x": 11,
      "y": 16,
      "z": 6,
      "name": "Plant_Leaves_Ash"
    },
    {
      "x": 11,
      "y": 17,
      "z": 6,
      "name": "Plant_Leaves_Ash"
    },
    {
      "x": 11,
      "y": 19,
      "z": 6,
      "name": "Plant_Leaves_Ash"
    },
    {
      "x": 11,
      "y": 15,
      "z": 7,
      "name": "Plant_Leaves_Ash"
    },
    {
      "x": 11,
      "y": 16,
      "z": 7,
      "name": "Plant_Leaves_Ash"
    },
    {
      "x": 11,
      "y": 21,
      "z": 8,
      "name": "Plant_Leaves_Ash"
    },
    {
      "x": 11,
      "y": 15,
      "z": 9,
      "name": "Wood_Ash_Trunk_Full"
    },
    {
      "x": 11,
      "y": 16,
      "z": 9,
      "name": "Wood_Ash_Trunk_Full"
    },
    {
      "x": 11,
      "y": 20,
      "z": 9,
      "name": "Plant_Leaves_Ash"
    },
    {
      "x": 11,
      "y": 21,
      "z": 9,
      "name": "Plant_Leaves_Ash"
    },
    {
      "x": 11,
      "y": 13,
      "z": 10,
      "name": "Wood_Ash_Trunk_Full"
    },
    {
      "x": 11,
      "y": 14,
      "z": 10,
      "name": "Plant_Leaves_Ash"
    },
    {
      "x": 11,
      "y": 20,
      "z": 10,
      "name": "Wood_Ash_Branch_Long",
      "rotation": 5
    },
    {
      "x": 11,
      "y": 21,
      "z": 10,
      "name": "Plant_Leaves_Ash"
    },
    {
      "x": 11,
      "y": 13,
      "z": 11,
      "name": "Plant_Leaves_Ash"
    },
    {
      "x": 11,
      "y": 15,
      "z": 11,
      "name": "Wood_Ash_Trunk_Full"
    },
    {
      "x": 11,
      "y": 16,
      "z": 11,
      "name": "Wood_Ash_Trunk"
    },
    {
      "x": 11,
      "y": 17,
      "z": 11,
      "name": "Wood_Ash_Trunk_Full"
    },
    {
      "x": 11,
      "y": 20,
      "z": 11,
      "name": "Plant_Leaves_Ash"
    },
    {
      "x": 11,
      "y": 13,
      "z": 12,
      "name": "Plant_Leaves_Ash"
    },
    {
      "x": 11,
      "y": 17,
      "z": 12,
      "name": "Wood_Ash_Trunk_Full"
    },
    {
      "x": 11,
      "y": 18,
      "z": 12,
      "name": "Wood_Ash_Trunk_Full"
    },
    {
      "x": 11,
      "y": 19,
      "z": 12,
      "name": "Plant_Leaves_Ash"
    },
    {
      "x": 11,
      "y": 17,
      "z": 13,
      "name": "Wood_Ash_Branch_Long",
      "rotation": 4
    },
    {
      "x": 11,
      "y": 18,
      "z": 13,
      "name": "Plant_Leaves_Ash"
    },
    {
      "x": 11,
      "y": 17,
      "z": 14,
      "name": "Plant_Leaves_Ash"
    },
    {
      "x": 12,
      "y": 14,
      "z": 5,
      "name": "Plant_Leaves_Ash"
    },
    {
      "x": 12,
      "y": 15,
      "z": 5,
      "name": "Plant_Leaves_Ash"
    },
    {
      "x": 12,
      "y": 17,
      "z": 5,
      "name": "Plant_Leaves_Ash"
    },
    {
      "x": 12,
      "y": 18,
      "z": 5,
      "name": "Plant_Leaves_Ash"
    },
    {
      "x": 12,
      "y": 14,
      "z": 6,
      "name": "Plant_Leaves_Ash"
    },
    {
      "x": 12,
      "y": 15,
      "z": 6,
      "name": "Plant_Leaves_Ash"
    },
    {
      "x": 12,
      "y": 16,
      "z": 6,
      "name": "Plant_Leaves_Ash"
    },
    {
      "x": 12,
      "y": 17,
      "z": 6,
      "name": "Plant_Leaves_Ash"
    },
    {
      "x": 12,
      "y": 18,
      "z": 6,
      "name": "Plant_Leaves_Ash"
    },
    {
      "x": 12,
      "y": 14,
      "z": 7,
      "name": "Plant_Leaves_Ash"
    },
    {
      "x": 12,
      "y": 16,
      "z": 7,
      "name": "Wood_Ash_Trunk_Full"
    },
    {
      "x": 12,
      "y": 17,
      "z": 7,
      "name": "Plant_Leaves_Ash"
    },
    {
      "x": 12,
      "y": 16,
      "z": 8,
      "name": "Wood_Ash_Trunk_Full"
    },
    {
      "x": 12,
      "y": 13,
      "z": 9,
      "name": "Plant_Leaves_Ash"
    },
    {
      "x": 12,
      "y": 16,
      "z": 9,
      "name": "Wood_Ash_Trunk_Full"
    },
    {
      "x": 12,
      "y": 17,
      "z": 9,
      "name": "Wood_Ash_Trunk_Full"
    },
    {
      "x": 12,
      "y": 13,
      "z": 10,
      "name": "Wood_Ash_Trunk_Full"
    },
    {
      "x": 12,
      "y": 14,
      "z": 10,
      "name": "Plant_Leaves_Ash"
    },
    {
      "x": 12,
      "y": 20,
      "z": 10,
      "name": "Plant_Leaves_Ash"
    },
    {
      "x": 12,
      "y": 21,
      "z": 10,
      "name": "Plant_Leaves_Ash"
    },
    {
      "x": 12,
      "y": 13,
      "z": 11,
      "name": "Wood_Ash_Trunk_Full"
    },
    {
      "x": 12,
      "y": 14,
      "z": 11,
      "name": "Plant_Leaves_Ash"
    },
    {
      "x": 12,
      "y": 16,
      "z": 11,
      "name": "Plant_Leaves_Ash"
    },
    {
      "x": 12,
      "y": 17,
      "z": 11,
      "name": "Plant_Leaves_Ash"
    },
    {
      "x": 12,
      "y": 13,
      "z": 12,
      "name": "Plant_Leaves_Ash"
    },
    {
      "x": 12,
      "y": 14,
      "z": 12,
      "name": "Plant_Leaves_Ash"
    },
    {
      "x": 12,
      "y": 17,
      "z": 12,
      "name": "Plant_Leaves_Ash"
    },
    {
      "x": 12,
      "y": 18,
      "z": 12,
      "name": "Wood_Ash_Branch_Long",
      "rotation": 5
    },
    {
      "x": 12,
      "y": 19,
      "z": 12,
      "name": "Plant_Leaves_Ash"
    },
    {
      "x": 12,
      "y": 13,
      "z": 13,
      "name": "Plant_Leaves_Ash"
    },
    {
      "x": 12,
      "y": 17,
      "z": 13,
      "name": "Plant_Leaves_Ash"
    },
    {
      "x": 12,
      "y": 18,
      "z": 13,
      "name": "Plant_Leaves_Ash"
    },
    {
      "x": 12,
      "y": 19,
      "z": 13,
      "name": "Plant_Leaves_Ash"
    },
    {
      "x": 12,
      "y": 17,
      "z": 14,
      "name": "Plant_Leaves_Ash"
    },
    {
      "x": 13,
      "y": 14,
      "z": 5,
      "name": "Plant_Leaves_Ash"
    },
    {
      "x": 13,
      "y": 15,
      "z": 5,
      "name": "Plant_Leaves_Ash"
    },
    {
      "x": 13,
      "y": 16,
      "z": 5,
      "name": "Plant_Leaves_Ash"
    },
    {
      "x": 13,
      "y": 17,
      "z": 5,
      "name": "Plant_Leaves_Ash"
    },
    {
      "x": 13,
      "y": 14,
      "z": 6,
      "name": "Plant_Leaves_Ash"
    },
    {
      "x": 13,
      "y": 15,
      "z": 6,
      "name": "Plant_Leaves_Ash"
    },
    {
      "x": 13,
      "y": 16,
      "z": 6,
      "name": "Plant_Leaves_Ash"
    },
    {
      "x": 13,
      "y": 17,
      "z": 6,
      "name": "Plant_Leaves_Ash"
    },
    {
      "x": 13,
      "y": 18,
      "z": 6,
      "name": "Plant_Leaves_Ash"
    },
    {
      "x": 13,
      "y": 14,
      "z": 7,
      "name": "Plant_Leaves_Ash"
    },
    {
      "x": 13,
      "y": 17,
      "z": 7,
      "name": "Plant_Leaves_Ash"
    },
    {
      "x": 13,
      "y": 16,
      "z": 8,
      "name": "Plant_Leaves_Ash"
    },
    {
      "x": 13,
      "y": 17,
      "z": 8,
      "name": "Plant_Leaves_Ash"
    },
    {
      "x": 13,
      "y": 19,
      "z": 8,
      "name": "Plant_Leaves_Ash"
    },
    {
      "x": 13,
      "y": 20,
      "z": 8,
      "name": "Plant_Leaves_Ash"
    },
    {
      "x": 13,
      "y": 15,
      "z": 9,
      "name": "Plant_Leaves_Ash"
    },
    {
      "x": 13,
      "y": 16,
      "z": 9,
      "name": "Plant_Leaves_Ash"
    },
    {
      "x": 13,
      "y": 17,
      "z": 9,
      "name": "Wood_Ash_Branch_Long",
      "rotation": 5
    },
    {
      "x": 13,
      "y": 18,
      "z": 9,
      "name": "Plant_Leaves_Ash"
    },
    {
      "x": 13,
      "y": 19,
      "z": 9,
      "name": "Plant_Leaves_Ash"
    },
    {
      "x": 13,
      "y": 20,
      "z": 9,
      "name": "Plant_Leaves_Ash"
    },
    {
      "x": 13,
      "y": 13,
      "z": 10,
      "name": "Plant_Leaves_Ash"
    },
    {
      "x": 13,
      "y": 17,
      "z": 10,
      "name": "Plant_Leaves_Ash"
    },
    {
      "x": 13,
      "y": 18,
      "z": 10,
      "name": "Plant_Leaves_Ash"
    },
    {
      "x": 13,
      "y": 19,
      "z": 10,
      "name": "Plant_Leaves_Ash"
    },
    {
      "x": 13,
      "y": 13,
      "z": 11,
      "name": "Wood_Ash_Branch_Long",
      "rotation": 5
    },
    {
      "x": 13,
      "y": 14,
      "z": 11,
      "name": "Plant_Leaves_Ash"
    },
    {
      "x": 13,
      "y": 16,
      "z": 11,
      "name": "Plant_Leaves_Ash"
    },
    {
      "x": 13,
      "y": 17,
      "z": 11,
      "name": "Plant_Leaves_Ash"
    },
    {
      "x": 13,
      "y": 13,
      "z": 12,
      "name": "Plant_Leaves_Ash"
    },
    {
      "x": 13,
      "y": 17,
      "z": 12,
      "name": "Plant_Leaves_Ash"
    },
    {
      "x": 13,
      "y": 18,
      "z": 12,
      "name": "Plant_Leaves_Ash"
    },
    {
      "x": 13,
      "y": 13,
      "z": 13,
      "name": "Plant_Leaves_Ash"
    },
    {
      "x": 13,
      "y": 18,
      "z": 13,
      "name": "Plant_Leaves_Ash"
    },
    {
      "x": 14,
      "y": 14,
      "z": 6,
      "name": "Plant_Leaves_Ash"
    },
    {
      "x": 14,
      "y": 15,
      "z": 8,
      "name": "Plant_Leaves_Ash"
    },
    {
      "x": 14,
      "y": 16,
      "z": 8,
      "name": "Plant_Leaves_Ash"
    },
    {
      "x": 14,
      "y": 17,
      "z": 8,
      "name": "Plant_Leaves_Ash"
    },
    {
      "x": 14,
      "y": 18,
      "z": 8,
      "name": "Plant_Leaves_Ash"
    },
    {
      "x": 14,
      "y": 15,
      "z": 9,
      "name": "Plant_Leaves_Ash"
    },
    {
      "x": 14,
      "y": 16,
      "z": 9,
      "name": "Plant_Leaves_Ash"
    },
    {
      "x": 14,
      "y": 17,
      "z": 9,
      "name": "Plant_Leaves_Ash"
    },
    {
      "x": 14,
      "y": 18,
      "z": 9,
      "name": "Plant_Leaves_Ash"
    },
    {
      "x": 14,
      "y": 19,
      "z": 9,
      "name": "Plant_Leaves_Ash"
    },
    {
      "x": 14,
      "y": 18,
      "z": 10,
      "name": "Plant_Leaves_Ash"
    },
    {
      "x": 14,
      "y": 13,
      "z": 11,
      "name": "Plant_Leaves_Ash"
    },
    {
      "x": 14,
      "y": 13,
      "z": 12,
      "name": "Plant_Leaves_Ash"
    },
    {
      "x": 14,
      "y": 14,
      "z": 12,
      "name": "Plant_Leaves_Ash"
    },
    {
      "x": 15,
      "y": 15,
      "z": 8,
      "name": "Plant_Leaves_Ash"
    },
    {
      "x": 15,
      "y": 15,
      "z": 9,
      "name": "Plant_Leaves_Ash"
    },
    {
      "x": 15,
      "y": 16,
      "z": 9,
      "name": "Plant_Leaves_Ash"
    }
  ]
}