{
  "version": 8,
  "blockIdVersion": 10,
  "anchorX": 13,
  "anchorY": 13,
  "anchorZ": 15,
  "blocks": [
    {
      "x": 4,
      "y": 24,
      "z": 10,
      "name": "Plant_Leaves_Windwillow"
    },
    {
      "x": 4,
      "y": 24,
      "z": 11,
      "name": "Plant_Leaves_Windwillow"
    },
    {
      "x": 4,
      "y": 25,
      "z": 11,
      "name": "Plant_Leaves_Windwillow"
    },
    {
      "x": 4,
      "y": 28,
      "z": 13,
      "name": "Plant_Leaves_Windwillow"
    },
    {
      "x": 4,
      "y": 29,
      "z": 13,
      "name": "Plant_Leaves_Windwillow"
    },
    {
      "x": 4,
      "y": 30,
      "z": 13,
      "name": "Plant_Leaves_Windwillow"
    },
    {
      "x": 4,
      "y": 29,
      "z": 14,
      "name": "Plant_Leaves_Windwillow"
    },
    {
      "x": 4,
      "y": 30,
      "z": 14,
      "name": "Plant_Leaves_Windwillow"
    },
    {
      "x": 5,
      "y": 24,
      "z": 8,
      "name": "Plant_Leaves_Windwillow"
    },
    {
      "x": 5,
      "y": 22,
      "z": 9,
      "name": "Plant_Fruit_Windwillow",
      "rotation": 8
    },
    {
      "x": 5,
      "y": 23,
      "z": 9,
      "name": "Plant_Leaves_Windwillow"
    },
    {
      "x": 5,
      "y": 24,
      "z": 9,
      "name": "Plant_Leaves_Windwillow"
    },
    {
      "x": 5,
      "y": 25,
      "z": 9,
      "name": "Plant_Leaves_Windwillow"
    },
    {
      "x": 5,
      "y": 22,
      "z": 10,
      "name": "Plant_Leaves_Windwillow"
    },
    {
      "x": 5,
      "y": 23,
      "z": 10,
      "name": "Plant_Leaves_Windwillow"
    },
    {
      "x": 5,
      "y": 24,
      "z": 10,
      "name": "Plant_Leaves_Windwillow"
    },
    {
      "x": 5,
      "y": 25,
      "z": 10,
      "name": "Plant_Leaves_Windwillow"
    },
    {
      "x": 5,
      "y": 26,
      "z": 10,
      "name": "Plant_Leaves_Windwillow"
    },
    {
      "x": 5,
      "y": 27,
      "z": 10,
      "name": "Plant_Leaves_Windwillow"
    },
    {
      "x": 5,
      "y": 24,
      "z": 11,
      "name": "Plant_Leaves_Windwillow"
    },
    {
      "x": 5,
      "y": 25,
      "z": 11,
      "name": "Plant_Leaves_Windwillow"
    },
    {
      "x": 5,
      "y": 26,
      "z": 11,
      "name": "Plant_Leaves_Windwillow"
    },
    {
      "x": 5,
      "y": 24,
      "z": 12,
      "name": "Plant_Leaves_Windwillow"
    },
    {
      "x": 5,
      "y": 28,
      "z": 12,
      "name": "Plant_Leaves_Windwillow"
    },
    {
      "x": 5,
      "y": 29,
      "z": 12,
      "name": "Plant_Leaves_Windwillow"
    },
    {
      "x": 5,
      "y": 30,
      "z": 12,
      "name": "Plant_Leaves_Windwillow"
    },
    {
      "x": 5,
      "y": 28,
      "z": 13,
      "name": "Plant_Leaves_Windwillow"
    },
    {
      "x": 5,
      "y": 29,
      "z": 13,
      "name": "Plant_Leaves_Windwillow"
    },
    {
      "x": 5,
      "y": 30,
      "z": 13,
      "name": "Plant_Leaves_Windwillow"
    },
    {
      "x": 5,
      "y": 31,
      "z": 13,
      "name": "Plant_Leaves_Windwillow"
    },
    {
      "x": 5,
      "y": 30,
      "z": 14,
      "name": "Plant_Leaves_Windwillow"
    },
    {
      "x": 5,
      "y": 31,
      "z": 14,
      "name": "Plant_Leaves_Windwillow"
    },
    {
      "x": 5,
      "y": 29,
      "z": 15,
      "name": "Plant_Leaves_Windwillow"
    },
    {
      "x": 5,
      "y": 30,
      "z": 15,
      "name": "Plant_Leaves_Windwillow"
    },
    {
      "x": 6,
      "y": 23,
      "z": 8,
      "name": "Plant_Leaves_Windwillow"
    },
    {
      "x": 6,
      "y": 24,
      "z": 8,
      "name": "Plant_Leaves_Windwillow"
    },
    {
      "x": 6,
      "y": 25,
      "z": 8,
      "name": "Plant_Leaves_Windwillow"
    },
    {
      "x": 6,
      "y": 27,
      "z": 8,
      "name": "Plant_Leaves_Windwillow"
    },
    {
      "x": 6,
      "y": 23,
      "z": 9,
      "name": "Plant_Leaves_Windwillow"
    },
    {
      "x": 6,
      "y": 24,
      "z": 9,
      "name": "Plant_Leaves_Windwillow"
    },
    {
      "x": 6,
      "y": 25,
      "z": 9,
      "name": "Plant_Leaves_Windwillow"
    },
    {
      "x": 6,
      "y": 26,
      "z": 9,
      "name": "Plant_Leaves_Windwillow"
    },
    {
      "x": 6,
      "y": 27,
      "z": 9,
      "name": "Plant_Leaves_Windwillow"
    },
    {
      "x": 6,
      "y": 28,
      "z": 9,
      "name": "Plant_Leaves_Windwillow"
    },
    {
      "x": 6,
      "y": 23,
      "z": 10,
      "name": "Plant_Leaves_Windwillow"
    },
    {
      "x": 6,
      "y": 24,
      "z": 10,
      "name": "Plant_Leaves_Windwillow"
    },
    {
      "x": 6,
      "y": 25,
      "z": 10,
      "name": "Plant_Leaves_Windwillow"
    },
    {
      "x": 6,
      "y": 26,
      "z": 10,
      "name": "Plant_Leaves_Windwillow"
    },
    {
      "x": 6,
      "y": 27,
      "z": 10,
      "name": "Plant_Leaves_Windwillow"
    },
    {
      "x": 6,
      "y": 28,
      "z": 10,
      "name": "Plant_Leaves_Windwillow"
    },
    {
      "x": 6,
      "y": 23,
      "z": 11,
      "name": "Plant_Leaves_Windwillow"
    },
    {
      "x": 6,
      "y": 24,
      "z": 11,
      "name": "Plant_Leaves_Windwillow"
    },
    {
      "x": 6,
      "y": 25,
      "z": 11,
      "name": "Plant_Leaves_Windwillow"
    },
    {
      "x": 6,
      "y": 26,
      "z": 11,
      "name": "Plant_Leaves_Windwillow"
    },
    {
      "x": 6,
      "y": 27,
      "z": 11,
      "name": "Plant_Leaves_Windwillow"
    },
    {
      "x": 6,
      "y": 31,
      "z": 11,
      "name": "Plant_Leaves_Windwillow"
    },
    {
      "x": 6,
      "y": 23,
      "z": 12,
      "name": "Plant_Leaves_Windwillow"
    },
    {
      "x": 6,
      "y": 24,
      "z": 12,
      "name": "Plant_Leaves_Windwillow"
    },
    {
      "x": 6,
      "y": 25,
      "z": 12,
      "name": "Plant_Leaves_Windwillow"
    },
    {
      "x": 6,
      "y": 26,
      "z": 12,
      "name": "Plant_Leaves_Windwillow"
    },
    {
      "x": 6,
      "y": 30,
      "z": 12,
      "name": "Plant_Leaves_Windwillow"
    },
    {
      "x": 6,
      "y": 31,
      "z": 12,
      "name": "Plant_Leaves_Windwillow"
    },
    {
      "x": 6,
      "y": 32,
      "z": 12,
      "name": "Plant_Leaves_Windwillow"
    },
    {
      "x": 6,
      "y": 30,
      "z": 13,
      "name": "Plant_Leaves_Windwillow"
    },
    {
      "x": 6,
      "y": 31,
      "z": 13,
      "name": "Plant_Leaves_Windwillow"
    },
    {
      "x": 6,
      "y": 32,
      "z": 13,
      "name": "Plant_Leaves_Windwillow"
    },
    {
      "x": 6,
      "y": 31,
      "z": 14,
      "name": "Plant_Leaves_Windwillow"
    },
    {
      "x": 6,
      "y": 28,
      "z": 15,
      "name": "Plant_Fruit_Windwillow",
      "rotation": 8
    },
    {
      "x": 6,
      "y": 29,
      "z": 15,
      "name": "Plant_Leaves_Windwillow"
    },
    {
      "x": 6,
      "y": 30,
      "z": 15,
      "name": "Plant_Leaves_Windwillow"
    },
    {
      "x": 6,
      "y": 31,
      "z": 15,
      "name": "Plant_Leaves_Windwillow"
    },
    {
      "x": 6,
      "y": 30,
      "z": 16,
      "name": "Plant_Leaves_Windwillow"
    },
    {
      "x": 7,
      "y": 26,
      "z": 5,
      "name": "Plant_Leaves_Windwillow"
    },
    {
      "x": 7,
      "y": 26,
      "z": 6,
      "name": "Plant_Leaves_Windwillow"
    },
    {
      "x": 7,
      "y": 27,
      "z": 6,
      "name": "Plant_Leaves_Windwillow"
    },
    {
      "x": 7,
      "y": 23,
      "z": 7,
      "name": "Plant_Leaves_Windwillow"
    },
    {
      "x": 7,
      "y": 24,
      "z": 7,
      "name": "Plant_Leaves_Windwillow"
    },
    {
      "x": 7,
      "y": 25,
      "z": 7,
      "name": "Plant_Leaves_Windwillow"
    },
    {
      "x": 7,
      "y": 26,
      "z": 7,
      "name": "Plant_Leaves_Windwillow"
    },
    {
      "x": 7,
      "y": 27,
      "z": 7,
      "name": "Plant_Leaves_Windwillow"
    },
    {
      "x": 7,
      "y": 28,
      "z": 7,
      "name": "Plant_Leaves_Windwillow"
    },
    {
      "x": 7,
      "y": 25,
      "z": 8,
      "name": "Plant_Leaves_Windwillow"
    },
    {
      "x": 7,
      "y": 26,
      "z": 8,
      "name": "Plant_Leaves_Windwillow"
    },
    {
      "x": 7,
      "y": 27,
      "z": 8,
      "name": "Plant_Leaves_Windwillow"
    },
    {
      "x": 7,
      "y": 28,
      "z": 8,
      "name": "Plant_Leaves_Windwillow"
    },
    {
      "x": 7,
      "y": 24,
      "z": 9,
      "name": "Plant_Leaves_Windwillow"
    },
    {
      "x": 7,
      "y": 25,
      "z": 9,
      "name": "Plant_Leaves_Windwillow"
    },
    {
      "x": 7,
      "y": 26,
      "z": 9,
      "name": "Plant_Leaves_Windwillow"
    },
    {
      "x": 7,
      "y": 27,
      "z": 9,
      "name": "Plant_Leaves_Windwillow"
    },
    {
      "x": 7,
      "y": 28,
      "z": 9,
      "name": "Plant_Leaves_Windwillow"
    },
    {
      "x": 7,
      "y": 29,
      "z": 9,
      "name": "Plant_Leaves_Windwillow"
    },
    {
      "x": 7,
      "y": 25,
      "z": 10,
      "name": "Wood_Windwillow_Trunk_Full"
    },
    {
      "x": 7,
      "y": 26,
      "z": 10,
      "name": "Wood_Windwillow_Trunk_Full"
    },
    {
      "x": 7,
      "y": 28,
      "z": 10,
      "name": "Plant_Leaves_Windwillow"
    },
    {
      "x": 7,
      "y": 29,
      "z": 10,
      "name": "Plant_Leaves_Windwillow"
    },
    {
      "x": 7,
      "y": 25,
      "z": 11,
      "name": "Plant_Fruit_Windwillow",
      "rotation": 8
    },
    {
      "x": 7,
      "y": 26,
      "z": 11,
      "name": "Plant_Leaves_Windwillow"
    },
    {
      "x": 7,
      "y": 27,
      "z": 11,
      "name": "Plant_Leaves_Windwillow"
    },
    {
      "x": 7,
      "y": 28,
      "z": 11,
      "name": "Plant_Leaves_Windwillow"
    },
    {
      "x": 7,
      "y": 31,
      "z": 11,
      "name": "Plant_Leaves_Windwillow"
    },
    {
      "x": 7,
      "y": 23,
      "z": 12,
      "name": "Plant_Leaves_Windwillow"
    },
    {
      "x": 7,
      "y": 24,
      "z": 12,
      "name": "Plant_Leaves_Windwillow"
    },
    {
      "x": 7,
      "y": 25,
      "z": 12,
      "name": "Plant_Leaves_Windwillow"
    },
    {
      "x": 7,
      "y": 26,
      "z": 12,
      "name": "Plant_Leaves_Windwillow"
    },
    {
      "x": 7,
      "y": 27,
      "z": 12,
      "name": "Plant_Leaves_Windwillow"
    },
    {
      "x": 7,
      "y": 31,
      "z": 12,
      "name": "Plant_Leaves_Windwillow"
    },
    {
      "x": 7,
      "y": 32,
      "z": 12,
      "name": "Plant_Leaves_Windwillow"
    },
    {
      "x": 7,
      "y": 24,
      "z": 13,
      "name": "Plant_Leaves_Windwillow"
    },
    {
      "x": 7,
      "y": 30,
      "z": 13,
      "name": "Wood_Windwillow_Trunk_Full"
    },
    {
      "x": 7,
      "y": 32,
      "z": 13,
      "name": "Plant_Leaves_Windwillow"
    },
    {
      "x": 7,
      "y": 31,
      "z": 14,
      "name": "Plant_Leaves_Windwillow"
    },
    {
      "x": 7,
      "y": 32,
      "z": 14,
      "name": "Plant_Leaves_Windwillow"
    },
    {
      "x": 7,
      "y": 29,
      "z": 15,
      "name": "Plant_Leaves_Windwillow"
    },
    {
      "x": 7,
      "y": 30,
      "z": 15,
      "name": "Plant_Leaves_Windwillow"
    },
    {
      "x": 7,
      "y": 31,
      "z": 15,
      "name": "Plant_Leaves_Windwillow"
    },
    {
      "x": 7,
      "y": 29,
      "z": 16,
      "name": "Plant_Leaves_Windwillow"
    },
    {
      "x": 8,
      "y": 31,
      "z": 5,
      "name": "Plant_Leaves_Windwillow"
    },
    {
      "x": 8,
      "y": 31,
      "z": 6,
      "name": "Plant_Leaves_Windwillow"
    },
    {
      "x": 8,
      "y": 27,
      "z": 7,
      "name": "Plant_Fruit_Windwillow",
      "rotation": 8
    },
    {
      "x": 8,
      "y": 30,
      "z": 7,
      "name": "Plant_Leaves_Windwillow"
    },
    {
      "x": 8,
      "y": 31,
      "z": 7,
      "name": "Plant_Leaves_Windwillow"
    },
    {
      "x": 8,
      "y": 30,
      "z": 8,
      "name": "Plant_Leaves_Windwillow"
    },
    {
      "x": 8,
      "y": 31,
      "z": 8,
      "name": "Plant_Leaves_Windwillow"
    },
    {
      "x": 8,
      "y": 29,
      "z": 9,
      "name": "Plant_Leaves_Windwillow"
    },
    {
      "x": 8,
      "y": 31,
      "z": 9,
      "name": "Plant_Leaves_Windwillow"
    },
    {
      "x": 8,
      "y": 25,
      "z": 10,
      "name": "Wood_Windwillow_Trunk_Full"
    },
    {
      "x": 8,
      "y": 26,
      "z": 10,
      "name": "Wood_Windwillow_Trunk_Full"
    },
    {
      "x": 8,
      "y": 27,
      "z": 10,
      "name": "Wood_Windwillow_Trunk_Full"
    },
    {
      "x": 8,
      "y": 29,
      "z": 10,
      "name": "Plant_Leaves_Windwillow"
    },
    {
      "x": 8,
      "y": 25,
      "z": 11,
      "name": "Plant_Leaves_Windwillow"
    },
    {
      "x": 8,
      "y": 26,
      "z": 11,
      "name": "Plant_Leaves_Windwillow"
    },
    {
      "x": 8,
      "y": 27,
      "z": 11,
      "name": "Plant_Leaves_Windwillow"
    },
    {
      "x": 8,
      "y": 28,
      "z": 11,
      "name": "Plant_Leaves_Windwillow"
    },
    {
      "x": 8,
      "y": 29,
      "z": 11,
      "name": "Plant_Leaves_Windwillow"
    },
    {
      "x": 8,
      "y": 22,
      "z": 12,
      "name": "Plant_Fruit_Windwillow",
      "rotation": 8
    },
    {
      "x": 8,
      "y": 23,
      "z": 12,
      "name": "Plant_Leaves_Windwillow"
    },
    {
      "x": 8,
      "y": 24,
      "z": 12,
      "name": "Plant_Leaves_Windwillow"
    },
    {
      "x": 8,
      "y": 25,
      "z": 12,
      "name": "Plant_Leaves_Windwillow"
    },
    {
      "x": 8,
      "y": 26,
      "z": 12,
      "name": "Plant_Leaves_Windwillow"
    },
    {
      "x": 8,
      "y": 27,
      "z": 12,
      "name": "Plant_Leaves_Windwillow"
    },
    {
      "x": 8,
      "y": 28,
      "z": 12,
      "name": "Plant_Leaves_Windwillow"
    },
    {
      "x": 8,
      "y": 24,
      "z": 13,
      "name": "Plant_Leaves_Windwillow"
    },
    {
      "x": 8,
      "y": 25,
      "z": 13,
      "name": "Plant_Leaves_Windwillow"
    },
    {
      "x": 8,
      "y": 30,
      "z": 13,
      "name": "Wood_Windwillow_Trunk_Full"
    },
    {
      "x": 8,
      "y": 32,
      "z": 13,
      "name": "Plant_Leaves_Windwillow"
    },
    {
      "x": 8,
      "y": 30,
      "z": 14,
      "name": "Plant_Leaves_Windwillow"
    },
    {
      "x": 8,
      "y": 31,
      "z": 14,
      "name": "Plant_Leaves_Windwillow"
    },
    {
      "x": 8,
      "y": 28,
      "z": 15,
      "name": "Plant_Leaves_Windwillow"
    },
    {
      "x": 8,
      "y": 29,
      "z": 15,
      "name": "Plant_Leaves_Windwillow"
    },
    {
      "x": 8,
      "y": 30,
      "z": 15,
      "name": "Plant_Leaves_Windwillow"
    },
    {
      "x": 8,
      "y": 28,
      "z": 16,
      "name": "Plant_Leaves_Windwillow"
    },
    {
      "x": 8,
      "y": 30,
      "z": 18,
      "name": "Plant_Leaves_Windwillow"
    },
    {
      "x": 8,
      "y": 32,
      "z": 18,
      "name": "Plant_Leaves_Windwillow"
    },
    {
      "x": 8,
      "y": 29,
      "z": 19,
      "name": "Plant_Leaves_Windwillow"
    },
    {
      "x": 8,
      "y": 30,
      "z": 19,
      "name": "Plant_Leaves_Windwillow"
    },
    {
      "x": 9,
      "y": 30,
      "z": 5,
      "name": "Plant_Leaves_Windwillow"
    },
    {
      "x": 9,
      "y": 31,
      "z": 5,
      "name": "Plant_Leaves_Windwillow"
    },
    {
      "x": 9,
      "y": 32,
      "z": 5,
      "name": "Plant_Leaves_Windwillow"
    },
    {
      "x": 9,
      "y": 32,
      "z": 6,
      "name": "Plant_Leaves_Windwillow"
    },
    {
      "x": 9,
      "y": 31,
      "z": 7,
      "name": "Plant_Leaves_Windwillow"
    },
    {
      "x": 9,
      "y": 32,
      "z": 7,
      "name": "Plant_Leaves_Windwillow"
    },
    {
      "x": 9,
      "y": 29,
      "z": 8,
      "name": "Plant_Leaves_Windwillow"
    },
    {
      "x": 9,
      "y": 30,
      "z": 8,
      "name": "Plant_Leaves_Windwillow"
    },
    {
      "x": 9,
      "y": 31,
      "z": 8,
      "name": "Plant_Leaves_Windwillow"
    },
    {
      "x": 9,
      "y": 32,
      "z": 8,
      "name": "Plant_Leaves_Windwillow"
    },
    {
      "x": 9,
      "y": 29,
      "z": 9,
      "name": "Plant_Leaves_Windwillow"
    },
    {
      "x": 9,
      "y": 30,
      "z": 9,
      "name": "Plant_Leaves_Windwillow"
    },
    {
      "x": 9,
      "y": 31,
      "z": 9,
      "name": "Plant_Leaves_Windwillow"
    },
    {
      "x": 9,
      "y": 25,
      "z": 10,
      "name": "Wood_Windwillow_Trunk_Full"
    },
    {
      "x": 9,
      "y": 26,
      "z": 10,
      "name": "Wood_Windwillow_Trunk_Full"
    },
    {
      "x": 9,
      "y": 29,
      "z": 10,
      "name": "Plant_Leaves_Windwillow"
    },
    {
      "x": 9,
      "y": 27,
      "z": 11,
      "name": "Plant_Leaves_Windwillow"
    },
    {
      "x": 9,
      "y": 28,
      "z": 11,
      "name": "Plant_Leaves_Windwillow"
    },
    {
      "x": 9,
      "y": 29,
      "z": 11,
      "name": "Plant_Leaves_Windwillow"
    },
    {
      "x": 9,
      "y": 25,
      "z": 12,
      "name": "Plant_Leaves_Windwillow"
    },
    {
      "x": 9,
      "y": 26,
      "z": 12,
      "name": "Plant_Leaves_Windwillow"
    },
    {
      "x": 9,
      "y": 27,
      "z": 12,
      "name": "Plant_Leaves_Windwillow"
    },
    {
      "x": 9,
      "y": 30,
      "z": 12,
      "name": "Wood_Windwillow_Trunk_Full"
    },
    {
      "x": 9,
      "y": 30,
      "z": 13,
      "name": "Wood_Windwillow_Trunk_Full"
    },
    {
      "x": 9,
      "y": 9,
      "z": 17,
      "name": "Wood_Windwillow_Roots"
    },
    {
      "x": 9,
      "y": 10,
      "z": 17,
      "name": "Wood_Windwillow_Trunk_Full"
    },
    {
      "x": 9,
      "y": 11,
      "z": 17,
      "name": "Wood_Windwillow_Trunk"
    },
    {
      "x": 9,
      "y": 12,
      "z": 17,
      "name": "Wood_Windwillow_Trunk_Full"
    },
    {
      "x": 9,
      "y": 32,
      "z": 17,
      "name": "Plant_Leaves_Windwillow"
    },
    {
      "x": 9,
      "y": 7,
      "z": 18,
      "name": "Wood_Windwillow_Roots"
    },
    {
      "x": 9,
      "y": 8,
      "z": 18,
      "name": "Wood_Windwillow_Trunk"
    },
    {
      "x": 9,
      "y": 9,
      "z": 18,
      "name": "Wood_Windwillow_Trunk"
    },
    {
      "x": 9,
      "y": 10,
      "z": 18,
      "name": "Wood_Windwillow_Trunk_Full"
    },
    {
      "x": 9,
      "y": 31,
      "z": 18,
      "name": "Plant_Fruit_Windwillow",
      "rotation": 8
    },
    {
      "x": 9,
      "y": 32,
      "z": 18,
      "name": "Plant_Leaves_Windwillow"
    },
    {
      "x": 9,
      "y": 33,
      "z": 18,
      "name": "Plant_Leaves_Windwillow"
    },
    {
      "x": 9,
      "y": 28,
      "z": 19,
      "name": "Plant_Leaves_Windwillow"
    },
    {
      "x": 9,
      "y": 29,
      "z": 19,
      "name": "Plant_Leaves_Windwillow"
    },
    {
      "x": 9,
      "y": 30,
      "z": 19,
      "name": "Plant_Leaves_Windwillow"
    },
    {
      "x": 9,
      "y": 31,
      "z": 19,
      "name": "Plant_Leaves_Windwillow"
    },
    {
      "x": 9,
      "y": 32,
      "z": 19,
      "name": "Plant_Leaves_Windwillow"
    },
    {
      "x": 9,
      "y": 29,
      "z": 20,
      "name": "Plant_Leaves_Windwillow"
    },
    {
      "x": 9,
      "y": 30,
      "z": 20,
      "name": "Plant_Leaves_Windwillow"
    },
    {
      "x": 9,
      "y": 31,
      "z": 20,
      "name": "Plant_Leaves_Windwillow"
    },
    {
      "x": 9,
      "y": 28,
      "z": 21,
      "name": "Plant_Leaves_Windwillow"
    },
    {
      "x": 9,
      "y": 29,
      "z": 21,
      "name": "Plant_Leaves_Windwillow"
    },
    {
      "x": 9,
      "y": 30,
      "z": 21,
      "name": "Plant_Leaves_Windwillow"
    },
    {
      "x": 9,
      "y": 31,
      "z": 21,
      "name": "Plant_Leaves_Windwillow"
    },
    {
      "x": 10,
      "y": 30,
      "z": 4,
      "name": "Plant_Leaves_Windwillow"
    },
    {
      "x": 10,
      "y": 29,
      "z": 5,
      "name": "Plant_Leaves_Windwillow"
    },
    {
      "x": 10,
      "y": 30,
      "z": 5,
      "name": "Plant_Leaves_Windwillow"
    },
    {
      "x": 10,
      "y": 31,
      "z": 5,
      "name": "Plant_Leaves_Windwillow"
    },
    {
      "x": 10,
      "y": 32,
      "z": 5,
      "name": "Plant_Leaves_Windwillow"
    },
    {
      "x": 10,
      "y": 32,
      "z": 6,
      "name": "Plant_Leaves_Windwillow"
    },
    {
      "x": 10,
      "y": 33,
      "z": 6,
      "name": "Plant_Leaves_Windwillow"
    },
    {
      "x": 10,
      "y": 33,
      "z": 7,
      "name": "Plant_Leaves_Windwillow"
    },
    {
      "x": 10,
      "y": 31,
      "z": 8,
      "name": "Plant_Leaves_Windwillow"
    },
    {
      "x": 10,
      "y": 32,
      "z": 8,
      "name": "Plant_Leaves_Windwillow"
    },
    {
      "x": 10,
      "y": 33,
      "z": 8,
      "name": "Plant_Leaves_Windwillow"
    },
    {
      "x": 10,
      "y": 31,
      "z": 9,
      "name": "Plant_Leaves_Windwillow"
    },
    {
      "x": 10,
      "y": 32,
      "z": 9,
      "name": "Plant_Leaves_Windwillow"
    },
    {
      "x": 10,
      "y": 24,
      "z": 10,
      "name": "Wood_Windwillow_Trunk_Full"
    },
    {
      "x": 10,
      "y": 25,
      "z": 10,
      "name": "Wood_Windwillow_Trunk_Full"
    },
    {
      "x": 10,
      "y": 30,
      "z": 10,
      "name": "Plant_Leaves_Windwillow"
    },
    {
      "x": 10,
      "y": 31,
      "z": 10,
      "name": "Plant_Leaves_Windwillow"
    },
    {
      "x": 10,
      "y": 33,
      "z": 11,
      "name": "Plant_Leaves_Windwillow"
    },
    {
      "x": 10,
      "y": 30,
      "z": 12,
      "name": "Wood_Windwillow_Trunk_Full"
    },
    {
      "x": 10,
      "y": 8,
      "z": 14,
      "name": "Wood_Windwillow_Roots"
    },
    {
      "x": 10,
      "y": 9,
      "z": 14,
      "name": "Wood_Windwillow_Trunk"
    },
    {
      "x": 10,
      "y": 10,
      "z": 14,
      "name": "Wood_Windwillow_Trunk"
    },
    {
      "x": 10,
      "y": 11,
      "z": 14,
      "name": "Wood_Windwillow_Trunk_Full"
    },
    {
      "x": 10,
      "y": 11,
      "z": 15,
      "name": "Wood_Windwillow_Trunk_Full"
    },
    {
      "x": 10,
      "y": 12,
      "z": 16,
      "name": "Wood_Windwillow_Trunk_Full"
    },
    {
      "x": 10,
      "y": 13,
      "z": 16,
      "name": "Wood_Windwillow_Trunk_Full"
    },
    {
      "x": 10,
      "y": 12,
      "z": 17,
      "name": "Wood_Windwillow_Trunk_Full"
    },
    {
      "x": 10,
      "y": 32,
      "z": 17,
      "name": "Plant_Fruit_Windwillow",
      "rotation": 8
    },
    {
      "x": 10,
      "y": 33,
      "z": 17,
      "name": "Plant_Leaves_Windwillow"
    },
    {
      "x": 10,
      "y": 24,
      "z": 18,
      "name": "Plant_Leaves_Windwillow"
    },
    {
      "x": 10,
      "y": 25,
      "z": 18,
      "name": "Plant_Leaves_Windwillow"
    },
    {
      "x": 10,
      "y": 26,
      "z": 18,
      "name": "Plant_Leaves_Windwillow"
    },
    {
      "x": 10,
      "y": 27,
      "z": 18,
      "name": "Plant_Leaves_Windwillow"
    },
    {
      "x": 10,
      "y": 28,
      "z": 18,
      "name": "Plant_Leaves_Windwillow"
    },
    {
      "x": 10,
      "y": 32,
      "z": 18,
      "name": "Plant_Leaves_Windwillow"
    },
    {
      "x": 10,
      "y": 33,
      "z": 18,
      "name": "Plant_Leaves_Windwillow"
    },
    {
      "x": 10,
      "y": 34,
      "z": 18,
      "name": "Plant_Leaves_Windwillow"
    },
    {
      "x": 10,
      "y": 31,
      "z": 19,
      "name": "Plant_Leaves_Windwillow"
    },
    {
      "x": 10,
      "y": 32,
      "z": 19,
      "name": "Plant_Leaves_Windwillow"
    },
    {
      "x": 10,
      "y": 33,
      "z": 19,
      "name": "Plant_Leaves_Windwillow"
    },
    {
      "x": 10,
      "y": 26,
      "z": 20,
      "name": "Plant_Leaves_Windwillow"
    },
    {
      "x": 10,
      "y": 27,
      "z": 20,
      "name": "Plant_Leaves_Windwillow"
    },
    {
      "x": 10,
      "y": 28,
      "z": 20,
      "name": "Plant_Leaves_Windwillow"
    },
    {
      "x": 10,
      "y": 29,
      "z": 20,
      "name": "Plant_Leaves_Windwillow"
    },
    {
      "x": 10,
      "y": 30,
      "z": 20,
      "name": "Plant_Leaves_Windwillow"
    },
    {
      "x": 10,
      "y": 31,
      "z": 20,
      "name": "Plant_Leaves_Windwillow"
    },
    {
      "x": 10,
      "y": 32,
      "z": 20,
      "name": "Plant_Leaves_Windwillow"
    },
    {
      "x": 10,
      "y": 33,
      "z": 20,
      "name": "Plant_Leaves_Windwillow"
    },
    {
      "x": 10,
      "y": 28,
      "z": 21,
      "name": "Plant_Leaves_Windwillow"
    },
    {
      "x": 10,
      "y": 29,
      "z": 21,
      "name": "Plant_Leaves_Windwillow"
    },
    {
      "x": 10,
      "y": 30,
      "z": 21,
      "name": "Plant_Leaves_Windwillow"
    },
    {
      "x": 10,
      "y": 31,
      "z": 21,
      "name": "Plant_Leaves_Windwillow"
    },
    {
      "x": 10,
      "y": 32,
      "z": 21,
      "name": "Plant_Leaves_Windwillow"
    },
    {
      "x": 10,
      "y": 29,
      "z": 22,
      "name": "Plant_Leaves_Windwillow"
    },
    {
      "x": 10,
      "y": 30,
      "z": 22,
      "name": "Plant_Leaves_Windwillow"
    },
    {
      "x": 11,
      "y": 29,
      "z": 4,
      "name": "Plant_Leaves_Windwillow"
    },
    {
      "x": 11,
      "y": 28,
      "z": 5,
      "name": "Plant_Leaves_Windwillow"
    },
    {
      "x": 11,
      "y": 29,
      "z": 5,
      "name": "Plant_Leaves_Windwillow"
    },
    {
      "x": 11,
      "y": 30,
      "z": 5,
      "name": "Plant_Leaves_Windwillow"
    },
    {
      "x": 11,
      "y": 31,
      "z": 5,
      "name": "Plant_Leaves_Windwillow"
    },
    {
      "x": 11,
      "y": 32,
      "z": 5,
      "name": "Plant_Leaves_Windwillow"
    },
    {
      "x": 11,
      "y": 30,
      "z": 6,
      "name": "Plant_Leaves_Windwillow"
    },
    {
      "x": 11,
      "y": 31,
      "z": 6,
      "name": "Plant_Leaves_Windwillow"
    },
    {
      "x": 11,
      "y": 32,
      "z": 6,
      "name": "Plant_Leaves_Windwillow"
    },
    {
      "x": 11,
      "y": 33,
      "z": 6,
      "name": "Plant_Leaves_Windwillow"
    },
    {
      "x": 11,
      "y": 31,
      "z": 7,
      "name": "Wood_Windwillow_Trunk_Full"
    },
    {
      "x": 11,
      "y": 33,
      "z": 7,
      "name": "Plant_Leaves_Windwillow"
    },
    {
      "x": 11,
      "y": 31,
      "z": 8,
      "name": "Wood_Windwillow_Trunk_Full"
    },
    {
      "x": 11,
      "y": 33,
      "z": 8,
      "name": "Plant_Leaves_Windwillow"
    },
    {
      "x": 11,
      "y": 31,
      "z": 9,
      "name": "Plant_Leaves_Windwillow"
    },
    {
      "x": 11,
      "y": 32,
      "z": 9,
      "name": "Plant_Leaves_Windwillow"
    },
    {
      "x": 11,
      "y": 24,
      "z": 10,
      "name": "Wood_Windwillow_Trunk_Full"
    },
    {
      "x": 11,
      "y": 31,
      "z": 10,
      "name": "Plant_Leaves_Windwillow"
    },
    {
      "x": 11,
      "y": 32,
      "z": 10,
      "name": "Plant_Leaves_Windwillow"
    },
    {
      "x": 11,
      "y": 33,
      "z": 10,
      "name": "Plant_Leaves_Windwillow"
    },
    {
      "x": 11,
      "y": 34,
      "z": 10,
      "name": "Plant_Leaves_Windwillow"
    },
    {
      "x": 11,
      "y": 33,
      "z": 11,
      "name": "Plant_Leaves_Windwillow"
    },
    {
      "x": 11,
      "y": 6,
      "z": 12,
      "name": "Wood_Windwillow_Roots"
    },
    {
      "x": 11,
      "y": 7,
      "z": 12,
      "name": "Wood_Windwillow_Trunk"
    },
    {
      "x": 11,
      "y": 8,
      "z": 12,
      "name": "Wood_Windwillow_Trunk"
    },
    {
      "x": 11,
      "y": 9,
      "z": 12,
      "name": "Wood_Windwillow_Trunk_Full"
    },
    {
      "x": 11,
      "y": 29,
      "z": 12,
      "name": "Wood_Windwillow_Trunk_Full"
    },
    {
      "x": 11,
      "y": 30,
      "z": 12,
      "name": "Wood_Windwillow_Trunk_Full"
    },
    {
      "x": 11,
      "y": 11,
      "z": 15,
      "name": "Wood_Windwillow_Trunk_Full"
    },
    {
      "x": 11,
      "y": 12,
      "z": 15,
      "name": "Wood_Windwillow_Trunk"
    },
    {
      "x": 11,
      "y": 13,
      "z": 15,
      "name": "Wood_Windwillow_Trunk"
    },
    {
      "x": 11,
      "y": 14,
      "z": 15,
      "name": "Wood_Windwillow_Trunk_Full"
    },
    {
      "x": 11,
      "y": 13,
      "z": 16,
      "name": "Wood_Windwillow_Trunk_Full"
    },
    {
      "x": 11,
      "y": 14,
      "z": 16,
      "name": "Wood_Windwillow_Trunk"
    },
    {
      "x": 11,
      "y": 15,
      "z": 16,
      "name": "Wood_Windwillow_Trunk_Full"
    },
    {
      "x": 11,
      "y": 29,
      "z": 16,
      "name": "Wood_Windwillow_Trunk_Full"
    },
    {
      "x": 11,
      "y": 30,
      "z": 16,
      "name": "Wood_Windwillow_Trunk_Full"
    },
    {
      "x": 11,
      "y": 29,
      "z": 17,
      "name": "Plant_Leaves_Windwillow"
    },
    {
      "x": 11,
      "y": 30,
      "z": 17,
      "name": "Wood_Windwillow_Trunk_Full"
    },
    {
      "x": 11,
      "y": 8,
      "z": 18,
      "name": "Wood_Windwillow_Roots"
    },
    {
      "x": 11,
      "y": 9,
      "z": 18,
      "name": "Wood_Windwillow_Trunk"
    },
    {
      "x": 11,
      "y": 10,
      "z": 18,
      "name": "Wood_Windwillow_Trunk"
    },
    {
      "x": 11,
      "y": 11,
      "z": 18,
      "name": "Wood_Windwillow_Trunk_Full"
    },
    {
      "x": 11,
      "y": 26,
      "z": 18,
      "name": "Plant_Leaves_Windwillow"
    },
    {
      "x": 11,
      "y": 27,
      "z": 18,
      "name": "Plant_Leaves_Windwillow"
    },
    {
      "x": 11,
      "y": 28,
      "z": 18,
      "name": "Plant_Leaves_Windwillow"
    },
    {
      "x": 11,
      "y": 29,
      "z": 18,
      "name": "Plant_Leaves_Windwillow"
    },
    {
      "x": 11,
      "y": 30,
      "z": 18,
      "name": "Wood_Windwillow_Trunk_Full"
    },
    {
      "x": 11,
      "y": 31,
      "z": 18,
      "name": "Wood_Windwillow_Trunk_Full"
    },
    {
      "x": 11,
      "y": 24,
      "z": 19,
      "name": "Plant_Leaves_Windwillow"
    },
    {
      "x": 11,
      "y": 25,
      "z": 19,
      "name": "Plant_Leaves_Windwillow"
    },
    {
      "x": 11,
      "y": 26,
      "z": 19,
      "name": "Plant_Leaves_Windwillow"
    },
    {
      "x": 11,
      "y": 27,
      "z": 19,
      "name": "Plant_Leaves_Windwillow"
    },
    {
      "x": 11,
      "y": 28,
      "z": 19,
      "name": "Plant_Leaves_Windwillow"
    },
    {
      "x": 11,
      "y": 30,
      "z": 19,
      "name": "Wood_Windwillow_Trunk_Full"
    },
    {
      "x": 11,
      "y": 31,
      "z": 19,
      "name": "Wood_Windwillow_Trunk_Full"
    },
    {
      "x": 11,
      "y": 34,
      "z": 19,
      "name": "Plant_Leaves_Windwillow"
    },
    {
      "x": 11,
      "y": 27,
      "z": 20,
      "name": "Plant_Leaves_Windwillow"
    },
    {
      "x": 11,
      "y": 28,
      "z": 20,
      "name": "Plant_Leaves_Windwillow"
    },
    {
      "x": 11,
      "y": 30,
      "z": 20,
      "name": "Wood_Windwillow_Trunk_Full"
    },
    {
      "x": 11,
      "y": 31,
      "z": 20,
      "name": "Wood_Windwillow_Trunk_Full"
    },
    {
      "x": 11,
      "y": 33,
      "z": 20,
      "name": "Plant_Leaves_Windwillow"
    },
    {
      "x": 11,
      "y": 34,
      "z": 20,
      "name": "Plant_Leaves_Windwillow"
    },
    {
      "x": 11,
      "y": 29,
      "z": 21,
      "name": "Plant_Leaves_Windwillow"
    },
    {
      "x": 11,
      "y": 30,
      "z": 21,
      "name": "Plant_Leaves_Windwillow"
    },
    {
      "x": 11,
      "y": 31,
      "z": 21,
      "name": "Plant_Leaves_Windwillow"
    },
    {
      "x": 11,
      "y": 32,
      "z": 21,
      "name": "Plant_Leaves_Windwillow"
    },
    {
      "x": 11,
      "y": 33,
      "z": 21,
      "name": "Plant_Leaves_Windwillow"
    },
    {
      "x": 11,
      "y": 28,
      "z": 22,
      "name": "Plant_Leaves_Windwillow"
    },
    {
      "x": 11,
      "y": 29,
      "z": 22,
      "name": "Plant_Leaves_Windwillow"
    },
    {
      "x": 11,
      "y": 30,
      "z": 22,
      "name": "Plant_Leaves_Windwillow"
    },
    {
      "x": 11,
      "y": 31,
      "z": 22,
      "name": "Plant_Leaves_Windwillow"
    },
    {
      "x": 11,
      "y": 28,
      "z": 23,
      "name": "Plant_Leaves_Windwillow"
    },
    {
      "x": 12,
      "y": 30,
      "z": 5,
      "name": "Plant_Leaves_Windwillow"
    },
    {
      "x": 12,
      "y": 31,
      "z": 5,
      "name": "Plant_Leaves_Windwillow"
    },
    {
      "x": 12,
      "y": 28,
      "z": 6,
      "name": "Plant_Leaves_Windwillow"
    },
    {
      "x": 12,
      "y": 29,
      "z": 6,
      "name": "Plant_Leaves_Windwillow"
    },
    {
      "x": 12,
      "y": 30,
      "z": 6,
      "name": "Plant_Leaves_Windwillow"
    },
    {
      "x": 12,
      "y": 31,
      "z": 6,
      "name": "Plant_Leaves_Windwillow"
    },
    {
      "x": 12,
      "y": 32,
      "z": 6,
      "name": "Plant_Leaves_Windwillow"
    },
    {
      "x": 12,
      "y": 29,
      "z": 7,
      "name": "Plant_Leaves_Windwillow"
    },
    {
      "x": 12,
      "y": 30,
      "z": 7,
      "name": "Plant_Leaves_Windwillow"
    },
    {
      "x": 12,
      "y": 31,
      "z": 7,
      "name": "Plant_Leaves_Windwillow"
    },
    {
      "x": 12,
      "y": 32,
      "z": 7,
      "name": "Plant_Leaves_Windwillow"
    },
    {
      "x": 12,
      "y": 33,
      "z": 7,
      "name": "Plant_Leaves_Windwillow"
    },
    {
      "x": 12,
      "y": 31,
      "z": 8,
      "name": "Wood_Windwillow_Trunk_Full"
    },
    {
      "x": 12,
      "y": 33,
      "z": 8,
      "name": "Plant_Leaves_Windwillow"
    },
    {
      "x": 12,
      "y": 31,
      "z": 9,
      "name": "Wood_Windwillow_Trunk_Full"
    },
    {
      "x": 12,
      "y": 33,
      "z": 9,
      "name": "Plant_Leaves_Windwillow"
    },
    {
      "x": 12,
      "y": 24,
      "z": 10,
      "name": "Wood_Windwillow_Trunk_Full"
    },
    {
      "x": 12,
      "y": 31,
      "z": 10,
      "name": "Wood_Windwillow_Trunk_Full"
    },
    {
      "x": 12,
      "y": 33,
      "z": 10,
      "name": "Plant_Leaves_Windwillow"
    },
    {
      "x": 12,
      "y": 24,
      "z": 11,
      "name": "Wood_Windwillow_Trunk_Full"
    },
    {
      "x": 12,
      "y": 9,
      "z": 12,
      "name": "Wood_Windwillow_Trunk_Full"
    },
    {
      "x": 12,
      "y": 10,
      "z": 12,
      "name": "Wood_Windwillow_Trunk"
    },
    {
      "x": 12,
      "y": 11,
      "z": 12,
      "name": "Wood_Windwillow_Trunk_Full"
    },
    {
      "x": 12,
      "y": 29,
      "z": 12,
      "name": "Wood_Windwillow_Trunk_Full"
    },
    {
      "x": 12,
      "y": 11,
      "z": 13,
      "name": "Wood_Windwillow_Trunk_Full"
    },
    {
      "x": 12,
      "y": 13,
      "z": 14,
      "name": "Wood_Windwillow_Trunk_Full"
    },
    {
      "x": 12,
      "y": 14,
      "z": 14,
      "name": "Wood_Windwillow_Trunk_Full"
    },
    {
      "x": 12,
      "y": 29,
      "z": 14,
      "name": "Wood_Windwillow_Trunk_Full"
    },
    {
      "x": 12,
      "y": 30,
      "z": 14,
      "name": "Wood_Windwillow_Trunk_Full"
    },
    {
      "x": 12,
      "y": 13,
      "z": 15,
      "name": "Wood_Windwillow_Trunk_Full"
    },
    {
      "x": 12,
      "y": 14,
      "z": 15,
      "name": "Wood_Windwillow_Trunk"
    },
    {
      "x": 12,
      "y": 15,
      "z": 15,
      "name": "Wood_Windwillow_Trunk"
    },
    {
      "x": 12,
      "y": 16,
      "z": 15,
      "name": "Wood_Windwillow_Trunk_Full"
    },
    {
      "x": 12,
      "y": 29,
      "z": 15,
      "name": "Wood_Windwillow_Trunk_Full"
    },
    {
      "x": 12,
      "y": 13,
      "z": 16,
      "name": "Wood_Windwillow_Trunk_Full"
    },
    {
      "x": 12,
      "y": 14,
      "z": 16,
      "name": "Wood_Windwillow_Trunk"
    },
    {
      "x": 12,
      "y": 15,
      "z": 16,
      "name": "Wood_Windwillow_Trunk"
    },
    {
      "x": 12,
      "y": 16,
      "z": 16,
      "name": "Wood_Windwillow_Trunk"
    },
    {
      "x": 12,
      "y": 17,
      "z": 16,
      "name": "Wood_Windwillow_Trunk_Full"
    },
    {
      "x": 12,
      "y": 29,
      "z": 16,
      "name": "Wood_Windwillow_Trunk_Full"
    },
    {
      "x": 12,
      "y": 14,
      "z": 17,
      "name": "Wood_Windwillow_Trunk_Full"
    },
    {
      "x": 12,
      "y": 15,
      "z": 17,
      "name": "Wood_Windwillow_Trunk"
    },
    {
      "x": 12,
      "y": 16,
      "z": 17,
      "name": "Wood_Windwillow_Trunk_Full"
    },
    {
      "x": 12,
      "y": 26,
      "z": 17,
      "name": "Wood_Windwillow_Trunk_Full"
    },
    {
      "x": 12,
      "y": 32,
      "z": 17,
      "name": "Plant_Fruit_Windwillow",
      "rotation": 8
    },
    {
      "x": 12,
      "y": 33,
      "z": 17,
      "name": "Plant_Leaves_Windwillow"
    },
    {
      "x": 12,
      "y": 10,
      "z": 18,
      "name": "Wood_Windwillow_Roots"
    },
    {
      "x": 12,
      "y": 11,
      "z": 18,
      "name": "Wood_Windwillow_Trunk_Full"
    },
    {
      "x": 12,
      "y": 12,
      "z": 18,
      "name": "Wood_Windwillow_Trunk_Full"
    },
    {
      "x": 12,
      "y": 26,
      "z": 18,
      "name": "Wood_Windwillow_Trunk_Full"
    },
    {
      "x": 12,
      "y": 27,
      "z": 18,
      "name": "Wood_Windwillow_Trunk_Full"
    },
    {
      "x": 12,
      "y": 33,
      "z": 18,
      "name": "Plant_Leaves_Windwillow"
    },
    {
      "x": 12,
      "y": 34,
      "z": 18,
      "name": "Plant_Leaves_Windwillow"
    },
    {
      "x": 12,
      "y": 26,
      "z": 19,
      "name": "Wood_Windwillow_Trunk_Full"
    },
    {
      "x": 12,
      "y": 27,
      "z": 19,
      "name": "Wood_Windwillow_Trunk_Full"
    },
    {
      "x": 12,
      "y": 29,
      "z": 19,
      "name": "Plant_Leaves_Windwillow"
    },
    {
      "x": 12,
      "y": 31,
      "z": 19,
      "name": "Plant_Leaves_Windwillow"
    },
    {
      "x": 12,
      "y": 32,
      "z": 19,
      "name": "Plant_Leaves_Windwillow"
    },
    {
      "x": 12,
      "y": 33,
      "z": 19,
      "name": "Plant_Leaves_Windwillow"
    },
    {
      "x": 12,
      "y": 34,
      "z": 19,
      "name": "Plant_Leaves_Windwillow"
    },
    {
      "x": 12,
      "y": 25,
      "z": 20,
      "name": "Plant_Leaves_Windwillow"
    },
    {
      "x": 12,
      "y": 26,
      "z": 20,
      "name": "Plant_Leaves_Windwillow"
    },
    {
      "x": 12,
      "y": 27,
      "z": 20,
      "name": "Plant_Leaves_Windwillow"
    },
    {
      "x": 12,
      "y": 28,
      "z": 20,
      "name": "Plant_Leaves_Windwillow"
    },
    {
      "x": 12,
      "y": 30,
      "z": 20,
      "name": "Wood_Windwillow_Trunk_Full"
    },
    {
      "x": 12,
      "y": 31,
      "z": 20,
      "name": "Wood_Windwillow_Trunk_Full"
    },
    {
      "x": 12,
      "y": 33,
      "z": 20,
      "name": "Plant_Leaves_Windwillow"
    },
    {
      "x": 12,
      "y": 30,
      "z": 21,
      "name": "Wood_Windwillow_Trunk_Full"
    },
    {
      "x": 12,
      "y": 32,
      "z": 21,
      "name": "Plant_Leaves_Windwillow"
    },
    {
      "x": 12,
      "y": 33,
      "z": 21,
      "name": "Plant_Leaves_Windwillow"
    },
    {
      "x": 12,
      "y": 29,
      "z": 22,
      "name": "Plant_Leaves_Windwillow"
    },
    {
      "x": 12,
      "y": 30,
      "z": 22,
      "name": "Plant_Leaves_Windwillow"
    },
    {
      "x": 12,
      "y": 31,
      "z": 22,
      "name": "Plant_Leaves_Windwillow"
    },
    {
      "x": 12,
      "y": 32,
      "z": 22,
      "name": "Plant_Leaves_Windwillow"
    },
    {
      "x": 12,
      "y": 27,
      "z": 23,
      "name": "Plant_Leaves_Windwillow"
    },
    {
      "x": 12,
      "y": 28,
      "z": 23,
      "name": "Plant_Leaves_Windwillow"
    },
    {
      "x": 12,
      "y": 29,
      "z": 23,
      "name": "Plant_Leaves_Windwillow"
    },
    {
      "x": 12,
      "y": 30,
      "z": 23,
      "name": "Plant_Leaves_Windwillow"
    },
    {
      "x": 12,
      "y": 31,
      "z": 23,
      "name": "Plant_Leaves_Windwillow"
    },
    {
      "x": 13,
      "y": 31,
      "z": 6,
      "name": "Plant_Leaves_Windwillow"
    },
    {
      "x": 13,
      "y": 32,
      "z": 6,
      "name": "Plant_Leaves_Windwillow"
    },
    {
      "x": 13,
      "y": 29,
      "z": 7,
      "name": "Plant_Fruit_Windwillow",
      "rotation": 8
    },
    {
      "x": 13,
      "y": 30,
      "z": 7,
      "name": "Plant_Leaves_Windwillow"
    },
    {
      "x": 13,
      "y": 31,
      "z": 7,
      "name": "Plant_Leaves_Windwillow"
    },
    {
      "x": 13,
      "y": 32,
      "z": 7,
      "name": "Plant_Leaves_Windwillow"
    },
    {
      "x": 13,
      "y": 28,
      "z": 8,
      "name": "Plant_Leaves_Windwillow"
    },
    {
      "x": 13,
      "y": 29,
      "z": 8,
      "name": "Plant_Leaves_Windwillow"
    },
    {
      "x": 13,
      "y": 30,
      "z": 8,
      "name": "Plant_Leaves_Windwillow"
    },
    {
      "x": 13,
      "y": 31,
      "z": 8,
      "name": "Plant_Leaves_Windwillow"
    },
    {
      "x": 13,
      "y": 32,
      "z": 8,
      "name": "Plant_Leaves_Windwillow"
    },
    {
      "x": 13,
      "y": 30,
      "z": 10,
      "name": "Wood_Windwillow_Trunk_Full"
    },
    {
      "x": 13,
      "y": 31,
      "z": 10,
      "name": "Wood_Windwillow_Trunk_Full"
    },
    {
      "x": 13,
      "y": 33,
      "z": 10,
      "name": "Plant_Leaves_Windwillow"
    },
    {
      "x": 13,
      "y": 23,
      "z": 11,
      "name": "Wood_Windwillow_Trunk_Full"
    },
    {
      "x": 13,
      "y": 24,
      "z": 11,
      "name": "Wood_Windwillow_Trunk_Full"
    },
    {
      "x": 13,
      "y": 29,
      "z": 11,
      "name": "Wood_Windwillow_Trunk_Full"
    },
    {
      "x": 13,
      "y": 30,
      "z": 11,
      "name": "Wood_Windwillow_Trunk_Full"
    },
    {
      "x": 13,
      "y": 23,
      "z": 12,
      "name": "Wood_Windwillow_Trunk_Full"
    },
    {
      "x": 13,
      "y": 24,
      "z": 12,
      "name": "Wood_Windwillow_Trunk_Full"
    },
    {
      "x": 13,
      "y": 27,
      "z": 12,
      "name": "Wood_Windwillow_Trunk_Full"
    },
    {
      "x": 13,
      "y": 28,
      "z": 12,
      "name": "Wood_Windwillow_Trunk_Full"
    },
    {
      "x": 13,
      "y": 29,
      "z": 12,
      "name": "Wood_Windwillow_Trunk_Full"
    },
    {
      "x": 13,
      "y": 9,
      "z": 13,
      "name": "Wood_Windwillow_Roots"
    },
    {
      "x": 13,
      "y": 10,
      "z": 13,
      "name": "Wood_Windwillow_Trunk_Full"
    },
    {
      "x": 13,
      "y": 11,
      "z": 13,
      "name": "Wood_Windwillow_Trunk"
    },
    {
      "x": 13,
      "y": 12,
      "z": 13,
      "name": "Wood_Windwillow_Trunk"
    },
    {
      "x": 13,
      "y": 13,
      "z": 13,
      "name": "Wood_Windwillow_Trunk_Full"
    },
    {
      "x": 13,
      "y": 28,
      "z": 13,
      "name": "Wood_Windwillow_Trunk_Full"
    },
    {
      "x": 13,
      "y": 29,
      "z": 13,
      "name": "Wood_Windwillow_Trunk_Full"
    },
    {
      "x": 13,
      "y": 30,
      "z": 13,
      "name": "Wood_Windwillow_Trunk_Full"
    },
    {
      "x": 13,
      "y": 12,
      "z": 14,
      "name": "Wood_Windwillow_Trunk_Full"
    },
    {
      "x": 13,
      "y": 13,
      "z": 14,
      "name": "Wood_Windwillow_Trunk"
    },
    {
      "x": 13,
      "y": 14,
      "z": 14,
      "name": "Wood_Windwillow_Trunk"
    },
    {
      "x": 13,
      "y": 15,
      "z": 14,
      "name": "Wood_Windwillow_Trunk_Full"
    },
    {
      "x": 13,
      "y": 28,
      "z": 14,
      "name": "Wood_Windwillow_Trunk_Full"
    },
    {
      "x": 13,
      "y": 29,
      "z": 14,
      "name": "Wood_Windwillow_Trunk_Full"
    },
    {
      "x": 13,
      "y": 30,
      "z": 14,
      "name": "Wood_Windwillow_Trunk_Full"
    },
    {
      "x": 13,
      "y": 13,
      "z": 15,
      "name": "Wood_Windwillow_Trunk_Full"
    },
    {
      "x": 13,
      "y": 14,
      "z": 15,
      "name": "Wood_Windwillow_Trunk"
    },
    {
      "x": 13,
      "y": 15,
      "z": 15,
      "name": "Wood_Windwillow_Trunk"
    },
    {
      "x": 13,
      "y": 16,
      "z": 15,
      "name": "Wood_Windwillow_Trunk"
    },
    {
      "x": 13,
      "y": 17,
      "z": 15,
      "name": "Wood_Windwillow_Trunk_Full"
    },
    {
      "x": 13,
      "y": 25,
      "z": 15,
      "name": "Wood_Windwillow_Trunk_Full"
    },
    {
      "x": 13,
      "y": 13,
      "z": 16,
      "name": "Wood_Windwillow_Trunk_Full"
    },
    {
      "x": 13,
      "y": 14,
      "z": 16,
      "name": "Wood_Windwillow_Trunk"
    },
    {
      "x": 13,
      "y": 15,
      "z": 16,
      "name": "Wood_Windwillow_Trunk"
    },
    {
      "x": 13,
      "y": 16,
      "z": 16,
      "name": "Wood_Windwillow_Trunk"
    },
    {
      "x": 13,
      "y": 17,
      "z": 16,
      "name": "Wood_Windwillow_Trunk"
    },
    {
      "x": 13,
      "y": 18,
      "z": 16,
      "name": "Wood_Windwillow_Trunk"
    },
    {
      "x": 13,
      "y": 19,
      "z": 16,
      "name": "Wood_Windwillow_Trunk_Full"
    },
    {
      "x": 13,
      "y": 25,
      "z": 16,
      "name": "Wood_Windwillow_Trunk_Full"
    },
    {
      "x": 13,
      "y": 26,
      "z": 16,
      "name": "Wood_Windwillow_Trunk_Full"
    },
    {
      "x": 13,
      "y": 13,
      "z": 17,
      "name": "Wood_Windwillow_Trunk_Full"
    },
    {
      "x": 13,
      "y": 14,
      "z": 17,
      "name": "Wood_Windwillow_Trunk"
    },
    {
      "x": 13,
      "y": 15,
      "z": 17,
      "name": "Wood_Windwillow_Trunk"
    },
    {
      "x": 13,
      "y": 16,
      "z": 17,
      "name": "Wood_Windwillow_Trunk"
    },
    {
      "x": 13,
      "y": 17,
      "z": 17,
      "name": "Wood_Windwillow_Trunk"
    },
    {
      "x": 13,
      "y": 18,
      "z": 17,
      "name": "Wood_Windwillow_Trunk"
    },
    {
      "x": 13,
      "y": 19,
      "z": 17,
      "name": "Wood_Windwillow_Trunk_Full"
    },
    {
      "x": 13,
      "y": 26,
      "z": 17,
      "name": "Wood_Windwillow_Trunk_Full"
    },
    {
      "x": 13,
      "y": 12,
      "z": 18,
      "name": "Wood_Windwillow_Trunk_Full"
    },
    {
      "x": 13,
      "y": 13,
      "z": 18,
      "name": "Wood_Windwillow_Trunk_Full"
    },
    {
      "x": 13,
      "y": 26,
      "z": 18,
      "name": "Plant_Fruit_Windwillow",
      "rotation": 8
    },
    {
      "x": 13,
      "y": 27,
      "z": 18,
      "name": "Plant_Leaves_Windwillow"
    },
    {
      "x": 13,
      "y": 28,
      "z": 18,
      "name": "Plant_Leaves_Windwillow"
    },
    {
      "x": 13,
      "y": 29,
      "z": 18,
      "name": "Plant_Leaves_Windwillow"
    },
    {
      "x": 13,
      "y": 33,
      "z": 18,
      "name": "Plant_Leaves_Windwillow"
    },
    {
      "x": 13,
      "y": 25,
      "z": 19,
      "name": "Plant_Leaves_Windwillow"
    },
    {
      "x": 13,
      "y": 26,
      "z": 19,
      "name": "Plant_Leaves_Windwillow"
    },
    {
      "x": 13,
      "y": 27,
      "z": 19,
      "name": "Plant_Leaves_Windwillow"
    },
    {
      "x": 13,
      "y": 28,
      "z": 19,
      "name": "Plant_Leaves_Windwillow"
    },
    {
      "x": 13,
      "y": 29,
      "z": 19,
      "name": "Plant_Leaves_Windwillow"
    },
    {
      "x": 13,
      "y": 30,
      "z": 19,
      "name": "Plant_Leaves_Windwillow"
    },
    {
      "x": 13,
      "y": 31,
      "z": 19,
      "name": "Plant_Leaves_Windwillow"
    },
    {
      "x": 13,
      "y": 32,
      "z": 19,
      "name": "Plant_Leaves_Windwillow"
    },
    {
      "x": 13,
      "y": 33,
      "z": 19,
      "name": "Plant_Leaves_Windwillow"
    },
    {
      "x": 13,
      "y": 23,
      "z": 20,
      "name": "Plant_Leaves_Windwillow"
    },
    {
      "x": 13,
      "y": 24,
      "z": 20,
      "name": "Plant_Leaves_Windwillow"
    },
    {
      "x": 13,
      "y": 25,
      "z": 20,
      "name": "Plant_Leaves_Windwillow"
    },
    {
      "x": 13,
      "y": 26,
      "z": 20,
      "name": "Plant_Leaves_Windwillow"
    },
    {
      "x": 13,
      "y": 27,
      "z": 20,
      "name": "Plant_Leaves_Windwillow"
    },
    {
      "x": 13,
      "y": 32,
      "z": 20,
      "name": "Plant_Leaves_Windwillow"
    },
    {
      "x": 13,
      "y": 33,
      "z": 20,
      "name": "Plant_Leaves_Windwillow"
    },
    {
      "x": 13,
      "y": 29,
      "z": 21,
      "name": "Plant_Fruit_Windwillow",
      "rotation": 8
    },
    {
      "x": 13,
      "y": 30,
      "z": 21,
      "name": "Plant_Leaves_Windwillow"
    },
    {
      "x": 13,
      "y": 31,
      "z": 21,
      "name": "Plant_Leaves_Windwillow"
    },
    {
      "x": 13,
      "y": 32,
      "z": 21,
      "name": "Plant_Leaves_Windwillow"
    },
    {
      "x": 13,
      "y": 33,
      "z": 21,
      "name": "Plant_Leaves_Windwillow"
    },
    {
      "x": 13,
      "y": 28,
      "z": 22,
      "name": "Plant_Leaves_Windwillow"
    },
    {
      "x": 13,
      "y": 29,
      "z": 22,
      "name": "Plant_Leaves_Windwillow"
    },
    {
      "x": 13,
      "y": 30,
      "z": 22,
      "name": "Plant_Leaves_Windwillow"
    },
    {
      "x": 13,
      "y": 31,
      "z": 22,
      "name": "Plant_Leaves_Windwillow"
    },
    {
      "x": 13,
      "y": 32,
      "z": 22,
      "name": "Plant_Leaves_Windwillow"
    },
    {
      "x": 13,
      "y": 28,
      "z": 23,
      "name": "Plant_Leaves_Windwillow"
    },
    {
      "x": 13,
      "y": 29,
      "z": 23,
      "name": "Plant_Leaves_Windwillow"
    },
    {
      "x": 14,
      "y": 29,
      "z": 7,
      "name": "Plant_Leaves_Windwillow"
    },
    {
      "x": 14,
      "y": 30,
      "z": 7,
      "name": "Plant_Leaves_Windwillow"
    },
    {
      "x": 14,
      "y": 31,
      "z": 7,
      "name": "Plant_Leaves_Windwillow"
    },
    {
      "x": 14,
      "y": 23,
      "z": 12,
      "name": "Wood_Windwillow_Trunk_Full"
    },
    {
      "x": 14,
      "y": 24,
      "z": 12,
      "name": "Wood_Windwillow_Trunk_Full"
    },
    {
      "x": 14,
      "y": 25,
      "z": 12,
      "name": "Wood_Windwillow_Trunk"
    },
    {
      "x": 14,
      "y": 26,
      "z": 12,
      "name": "Wood_Windwillow_Trunk"
    },
    {
      "x": 14,
      "y": 27,
      "z": 12,
      "name": "Wood_Windwillow_Trunk"
    },
    {
      "x": 14,
      "y": 28,
      "z": 12,
      "name": "Wood_Windwillow_Trunk"
    },
    {
      "x": 14,
      "y": 29,
      "z": 12,
      "name": "Wood_Windwillow_Trunk_Full"
    },
    {
      "x": 14,
      "y": 23,
      "z": 13,
      "name": "Wood_Windwillow_Trunk_Full"
    },
    {
      "x": 14,
      "y": 24,
      "z": 13,
      "name": "Wood_Windwillow_Trunk_Full"
    },
    {
      "x": 14,
      "y": 25,
      "z": 13,
      "name": "Wood_Windwillow_Trunk_Full"
    },
    {
      "x": 14,
      "y": 26,
      "z": 13,
      "name": "Wood_Windwillow_Trunk"
    },
    {
      "x": 14,
      "y": 27,
      "z": 13,
      "name": "Wood_Windwillow_Trunk_Full"
    },
    {
      "x": 14,
      "y": 30,
      "z": 13,
      "name": "Wood_Windwillow_Trunk_Full"
    },
    {
      "x": 14,
      "y": 31,
      "z": 13,
      "name": "Wood_Windwillow_Trunk_Full"
    },
    {
      "x": 14,
      "y": 25,
      "z": 14,
      "name": "Wood_Windwillow_Trunk_Full"
    },
    {
      "x": 14,
      "y": 26,
      "z": 14,
      "name": "Wood_Windwillow_Trunk_Full"
    },
    {
      "x": 14,
      "y": 28,
      "z": 14,
      "name": "Wood_Windwillow_Trunk_Full"
    },
    {
      "x": 14,
      "y": 29,
      "z": 14,
      "name": "Wood_Windwillow_Trunk_Full"
    },
    {
      "x": 14,
      "y": 30,
      "z": 14,
      "name": "Wood_Windwillow_Trunk_Full"
    },
    {
      "x": 14,
      "y": 13,
      "z": 15,
      "name": "Wood_Windwillow_Trunk_Full"
    },
    {
      "x": 14,
      "y": 14,
      "z": 15,
      "name": "Wood_Windwillow_Trunk"
    },
    {
      "x": 14,
      "y": 15,
      "z": 15,
      "name": "Wood_Windwillow_Trunk"
    },
    {
      "x": 14,
      "y": 16,
      "z": 15,
      "name": "Wood_Windwillow_Trunk_Full"
    },
    {
      "x": 14,
      "y": 19,
      "z": 15,
      "name": "Wood_Windwillow_Trunk_Full"
    },
    {
      "x": 14,
      "y": 20,
      "z": 15,
      "name": "Wood_Windwillow_Trunk"
    },
    {
      "x": 14,
      "y": 21,
      "z": 15,
      "name": "Wood_Windwillow_Trunk_Full"
    },
    {
      "x": 14,
      "y": 25,
      "z": 15,
      "name": "Wood_Windwillow_Trunk_Full"
    },
    {
      "x": 14,
      "y": 26,
      "z": 15,
      "name": "Wood_Windwillow_Trunk_Full"
    },
    {
      "x": 14,
      "y": 13,
      "z": 16,
      "name": "Wood_Windwillow_Trunk_Full"
    },
    {
      "x": 14,
      "y": 14,
      "z": 16,
      "name": "Wood_Windwillow_Trunk"
    },
    {
      "x": 14,
      "y": 15,
      "z": 16,
      "name": "Wood_Windwillow_Trunk"
    },
    {
      "x": 14,
      "y": 16,
      "z": 16,
      "name": "Wood_Windwillow_Trunk"
    },
    {
      "x": 14,
      "y": 17,
      "z": 16,
      "name": "Wood_Windwillow_Trunk"
    },
    {
      "x": 14,
      "y": 18,
      "z": 16,
      "name": "Wood_Windwillow_Trunk"
    },
    {
      "x": 14,
      "y": 19,
      "z": 16,
      "name": "Wood_Windwillow_Trunk"
    },
    {
      "x": 14,
      "y": 20,
      "z": 16,
      "name": "Wood_Windwillow_Trunk"
    },
    {
      "x": 14,
      "y": 21,
      "z": 16,
      "name": "Wood_Windwillow_Trunk"
    },
    {
      "x": 14,
      "y": 22,
      "z": 16,
      "name": "Wood_Windwillow_Trunk_Full"
    },
    {
      "x": 14,
      "y": 16,
      "z": 17,
      "name": "Wood_Windwillow_Trunk_Full"
    },
    {
      "x": 14,
      "y": 17,
      "z": 17,
      "name": "Wood_Windwillow_Trunk"
    },
    {
      "x": 14,
      "y": 18,
      "z": 17,
      "name": "Wood_Windwillow_Trunk"
    },
    {
      "x": 14,
      "y": 19,
      "z": 17,
      "name": "Wood_Windwillow_Trunk"
    },
    {
      "x": 14,
      "y": 20,
      "z": 17,
      "name": "Wood_Windwillow_Trunk"
    },
    {
      "x": 14,
      "y": 21,
      "z": 17,
      "name": "Wood_Windwillow_Trunk_Full"
    },
    {
      "x": 14,
      "y": 8,
      "z": 18,
      "name": "Wood_Windwillow_Roots"
    },
    {
      "x": 14,
      "y": 9,
      "z": 18,
      "name": "Wood_Windwillow_Trunk"
    },
    {
      "x": 14,
      "y": 10,
      "z": 18,
      "name": "Wood_Windwillow_Trunk"
    },
    {
      "x": 14,
      "y": 11,
      "z": 18,
      "name": "Wood_Windwillow_Trunk"
    },
    {
      "x": 14,
      "y": 12,
      "z": 18,
      "name": "Wood_Windwillow_Trunk_Full"
    },
    {
      "x": 14,
      "y": 24,
      "z": 18,
      "name": "Plant_Leaves_Windwillow"
    },
    {
      "x": 14,
      "y": 25,
      "z": 18,
      "name": "Plant_Leaves_Windwillow"
    },
    {
      "x": 14,
      "y": 26,
      "z": 18,
      "name": "Plant_Leaves_Windwillow"
    },
    {
      "x": 14,
      "y": 27,
      "z": 18,
      "name": "Plant_Leaves_Windwillow"
    },
    {
      "x": 14,
      "y": 28,
      "z": 18,
      "name": "Plant_Leaves_Windwillow"
    },
    {
      "x": 14,
      "y": 26,
      "z": 19,
      "name": "Plant_Leaves_Windwillow"
    },
    {
      "x": 14,
      "y": 27,
      "z": 19,
      "name": "Plant_Leaves_Windwillow"
    },
    {
      "x": 14,
      "y": 30,
      "z": 19,
      "name": "Plant_Leaves_Windwillow"
    },
    {
      "x": 14,
      "y": 31,
      "z": 19,
      "name": "Plant_Leaves_Windwillow"
    },
    {
      "x": 14,
      "y": 32,
      "z": 19,
      "name": "Plant_Leaves_Windwillow"
    },
    {
      "x": 14,
      "y": 30,
      "z": 20,
      "name": "Plant_Leaves_Windwillow"
    },
    {
      "x": 14,
      "y": 31,
      "z": 20,
      "name": "Plant_Leaves_Windwillow"
    },
    {
      "x": 14,
      "y": 32,
      "z": 20,
      "name": "Plant_Leaves_Windwillow"
    },
    {
      "x": 14,
      "y": 29,
      "z": 21,
      "name": "Plant_Leaves_Windwillow"
    },
    {
      "x": 14,
      "y": 30,
      "z": 21,
      "name": "Plant_Leaves_Windwillow"
    },
    {
      "x": 14,
      "y": 31,
      "z": 21,
      "name": "Plant_Leaves_Windwillow"
    },
    {
      "x": 14,
      "y": 32,
      "z": 21,
      "name": "Plant_Leaves_Windwillow"
    },
    {
      "x": 14,
      "y": 28,
      "z": 22,
      "name": "Plant_Leaves_Windwillow"
    },
    {
      "x": 14,
      "y": 29,
      "z": 22,
      "name": "Plant_Leaves_Windwillow"
    },
    {
      "x": 14,
      "y": 30,
      "z": 22,
      "name": "Plant_Leaves_Windwillow"
    },
    {
      "x": 15,
      "y": 29,
      "z": 6,
      "name": "Plant_Leaves_Windwillow"
    },
    {
      "x": 15,
      "y": 25,
      "z": 12,
      "name": "Wood_Windwillow_Trunk_Full"
    },
    {
      "x": 15,
      "y": 26,
      "z": 12,
      "name": "Wood_Windwillow_Trunk"
    },
    {
      "x": 15,
      "y": 27,
      "z": 12,
      "name": "Wood_Windwillow_Trunk"
    },
    {
      "x": 15,
      "y": 28,
      "z": 12,
      "name": "Wood_Windwillow_Trunk_Full"
    },
    {
      "x": 15,
      "y": 23,
      "z": 13,
      "name": "Wood_Windwillow_Trunk_Full"
    },
    {
      "x": 15,
      "y": 24,
      "z": 13,
      "name": "Wood_Windwillow_Trunk_Full"
    },
    {
      "x": 15,
      "y": 25,
      "z": 13,
      "name": "Wood_Windwillow_Trunk"
    },
    {
      "x": 15,
      "y": 26,
      "z": 13,
      "name": "Wood_Windwillow_Trunk"
    },
    {
      "x": 15,
      "y": 27,
      "z": 13,
      "name": "Wood_Windwillow_Trunk"
    },
    {
      "x": 15,
      "y": 28,
      "z": 13,
      "name": "Wood_Windwillow_Trunk_Full"
    },
    {
      "x": 15,
      "y": 9,
      "z": 14,
      "name": "Wood_Windwillow_Roots"
    },
    {
      "x": 15,
      "y": 10,
      "z": 14,
      "name": "Wood_Windwillow_Trunk"
    },
    {
      "x": 15,
      "y": 11,
      "z": 14,
      "name": "Wood_Windwillow_Trunk"
    },
    {
      "x": 15,
      "y": 12,
      "z": 14,
      "name": "Wood_Windwillow_Trunk_Full"
    },
    {
      "x": 15,
      "y": 21,
      "z": 14,
      "name": "Wood_Windwillow_Trunk_Full"
    },
    {
      "x": 15,
      "y": 22,
      "z": 14,
      "name": "Wood_Windwillow_Trunk"
    },
    {
      "x": 15,
      "y": 23,
      "z": 14,
      "name": "Wood_Windwillow_Trunk"
    },
    {
      "x": 15,
      "y": 24,
      "z": 14,
      "name": "Wood_Windwillow_Trunk"
    },
    {
      "x": 15,
      "y": 25,
      "z": 14,
      "name": "Wood_Windwillow_Trunk"
    },
    {
      "x": 15,
      "y": 26,
      "z": 14,
      "name": "Wood_Windwillow_Trunk_Full"
    },
    {
      "x": 15,
      "y": 28,
      "z": 14,
      "name": "Wood_Windwillow_Trunk_Full"
    },
    {
      "x": 15,
      "y": 29,
      "z": 14,
      "name": "Wood_Windwillow_Trunk_Full"
    },
    {
      "x": 15,
      "y": 12,
      "z": 15,
      "name": "Wood_Windwillow_Trunk_Full"
    },
    {
      "x": 15,
      "y": 13,
      "z": 15,
      "name": "Wood_Windwillow_Trunk_Full"
    },
    {
      "x": 15,
      "y": 20,
      "z": 15,
      "name": "Wood_Windwillow_Trunk_Full"
    },
    {
      "x": 15,
      "y": 21,
      "z": 15,
      "name": "Wood_Windwillow_Trunk"
    },
    {
      "x": 15,
      "y": 22,
      "z": 15,
      "name": "Wood_Windwillow_Trunk"
    },
    {
      "x": 15,
      "y": 23,
      "z": 15,
      "name": "Wood_Windwillow_Trunk"
    },
    {
      "x": 15,
      "y": 24,
      "z": 15,
      "name": "Wood_Windwillow_Trunk_Full"
    },
    {
      "x": 15,
      "y": 29,
      "z": 15,
      "name": "Wood_Windwillow_Trunk_Full"
    },
    {
      "x": 15,
      "y": 12,
      "z": 16,
      "name": "Wood_Windwillow_Trunk_Full"
    },
    {
      "x": 15,
      "y": 13,
      "z": 16,
      "name": "Wood_Windwillow_Trunk_Full"
    },
    {
      "x": 15,
      "y": 17,
      "z": 16,
      "name": "Wood_Windwillow_Trunk_Full"
    },
    {
      "x": 15,
      "y": 18,
      "z": 16,
      "name": "Wood_Windwillow_Trunk"
    },
    {
      "x": 15,
      "y": 19,
      "z": 16,
      "name": "Wood_Windwillow_Trunk"
    },
    {
      "x": 15,
      "y": 20,
      "z": 16,
      "name": "Wood_Windwillow_Trunk"
    },
    {
      "x": 15,
      "y": 21,
      "z": 16,
      "name": "Wood_Windwillow_Trunk"
    },
    {
      "x": 15,
      "y": 22,
      "z": 16,
      "name": "Wood_Windwillow_Trunk"
    },
    {
      "x": 15,
      "y": 23,
      "z": 16,
      "name": "Wood_Windwillow_Trunk_Full"
    },
    {
      "x": 15,
      "y": 29,
      "z": 16,
      "name": "Wood_Windwillow_Trunk_Full"
    },
    {
      "x": 15,
      "y": 30,
      "z": 16,
      "name": "Plant_Leaves_Windwillow"
    },
    {
      "x": 15,
      "y": 18,
      "z": 17,
      "name": "Wood_Windwillow_Trunk_Full"
    },
    {
      "x": 15,
      "y": 19,
      "z": 17,
      "name": "Wood_Windwillow_Trunk"
    },
    {
      "x": 15,
      "y": 20,
      "z": 17,
      "name": "Wood_Windwillow_Trunk"
    },
    {
      "x": 15,
      "y": 21,
      "z": 17,
      "name": "Wood_Windwillow_Trunk"
    },
    {
      "x": 15,
      "y": 22,
      "z": 17,
      "name": "Wood_Windwillow_Trunk_Full"
    },
    {
      "x": 15,
      "y": 32,
      "z": 17,
      "name": "Plant_Leaves_Windwillow"
    },
    {
      "x": 15,
      "y": 33,
      "z": 17,
      "name": "Plant_Leaves_Windwillow"
    },
    {
      "x": 15,
      "y": 31,
      "z": 18,
      "name": "Plant_Leaves_Windwillow"
    },
    {
      "x": 15,
      "y": 32,
      "z": 18,
      "name": "Plant_Leaves_Windwillow"
    },
    {
      "x": 15,
      "y": 33,
      "z": 18,
      "name": "Plant_Leaves_Windwillow"
    },
    {
      "x": 15,
      "y": 30,
      "z": 19,
      "name": "Plant_Leaves_Windwillow"
    },
    {
      "x": 15,
      "y": 31,
      "z": 19,
      "name": "Plant_Leaves_Windwillow"
    },
    {
      "x": 15,
      "y": 32,
      "z": 19,
      "name": "Plant_Leaves_Windwillow"
    },
    {
      "x": 15,
      "y": 33,
      "z": 19,
      "name": "Plant_Leaves_Windwillow"
    },
    {
      "x": 15,
      "y": 28,
      "z": 20,
      "name": "Plant_Leaves_Windwillow"
    },
    {
      "x": 15,
      "y": 29,
      "z": 20,
      "name": "Plant_Leaves_Windwillow"
    },
    {
      "x": 15,
      "y": 30,
      "z": 20,
      "name": "Plant_Leaves_Windwillow"
    },
    {
      "x": 15,
      "y": 29,
      "z": 21,
      "name": "Plant_Leaves_Windwillow"
    },
    {
      "x": 15,
      "y": 30,
      "z": 21,
      "name": "Plant_Leaves_Windwillow"
    },
    {
      "x": 15,
      "y": 31,
      "z": 21,
      "name": "Plant_Leaves_Windwillow"
    },
    {
      "x": 16,
      "y": 30,
      "z": 4,
      "name": "Plant_Leaves_Windwillow"
    },
    {
      "x": 16,
      "y": 29,
      "z": 5,
      "name": "Plant_Leaves_Windwillow"
    },
    {
      "x": 16,
      "y": 30,
      "z": 5,
      "name": "Plant_Leaves_Windwillow"
    },
    {
      "x": 16,
      "y": 31,
      "z": 5,
      "name": "Plant_Leaves_Windwillow"
    },
    {
      "x": 16,
      "y": 28,
      "z": 6,
      "name": "Plant_Leaves_Windwillow"
    },
    {
      "x": 16,
      "y": 29,
      "z": 6,
      "name": "Plant_Leaves_Windwillow"
    },
    {
      "x": 16,
      "y": 30,
      "z": 6,
      "name": "Plant_Leaves_Windwillow"
    },
    {
      "x": 16,
      "y": 31,
      "z": 6,
      "name": "Plant_Leaves_Windwillow"
    },
    {
      "x": 16,
      "y": 27,
      "z": 7,
      "name": "Plant_Leaves_Windwillow"
    },
    {
      "x": 16,
      "y": 28,
      "z": 7,
      "name": "Plant_Leaves_Windwillow"
    },
    {
      "x": 16,
      "y": 29,
      "z": 7,
      "name": "Plant_Leaves_Windwillow"
    },
    {
      "x": 16,
      "y": 30,
      "z": 7,
      "name": "Plant_Leaves_Windwillow"
    },
    {
      "x": 16,
      "y": 31,
      "z": 7,
      "name": "Plant_Leaves_Windwillow"
    },
    {
      "x": 16,
      "y": 27,
      "z": 9,
      "name": "Plant_Leaves_Windwillow"
    },
    {
      "x": 16,
      "y": 28,
      "z": 9,
      "name": "Plant_Leaves_Windwillow"
    },
    {
      "x": 16,
      "y": 29,
      "z": 9,
      "name": "Plant_Leaves_Windwillow"
    },
    {
      "x": 16,
      "y": 30,
      "z": 9,
      "name": "Plant_Leaves_Windwillow"
    },
    {
      "x": 16,
      "y": 33,
      "z": 9,
      "name": "Plant_Leaves_Windwillow"
    },
    {
      "x": 16,
      "y": 28,
      "z": 11,
      "name": "Wood_Windwillow_Trunk_Full"
    },
    {
      "x": 16,
      "y": 29,
      "z": 11,
      "name": "Wood_Windwillow_Trunk_Full"
    },
    {
      "x": 16,
      "y": 27,
      "z": 12,
      "name": "Wood_Windwillow_Trunk_Full"
    },
    {
      "x": 16,
      "y": 28,
      "z": 12,
      "name": "Wood_Windwillow_Trunk_Full"
    },
    {
      "x": 16,
      "y": 21,
      "z": 13,
      "name": "Wood_Windwillow_Trunk_Full"
    },
    {
      "x": 16,
      "y": 22,
      "z": 13,
      "name": "Wood_Windwillow_Trunk_Full"
    },
    {
      "x": 16,
      "y": 24,
      "z": 13,
      "name": "Wood_Windwillow_Trunk_Full"
    },
    {
      "x": 16,
      "y": 25,
      "z": 13,
      "name": "Wood_Windwillow_Trunk"
    },
    {
      "x": 16,
      "y": 26,
      "z": 13,
      "name": "Wood_Windwillow_Trunk"
    },
    {
      "x": 16,
      "y": 27,
      "z": 13,
      "name": "Wood_Windwillow_Trunk_Full"
    },
    {
      "x": 16,
      "y": 21,
      "z": 14,
      "name": "Wood_Windwillow_Trunk_Full"
    },
    {
      "x": 16,
      "y": 22,
      "z": 14,
      "name": "Wood_Windwillow_Trunk"
    },
    {
      "x": 16,
      "y": 23,
      "z": 14,
      "name": "Wood_Windwillow_Trunk"
    },
    {
      "x": 16,
      "y": 24,
      "z": 14,
      "name": "Wood_Windwillow_Trunk"
    },
    {
      "x": 16,
      "y": 25,
      "z": 14,
      "name": "Wood_Windwillow_Trunk"
    },
    {
      "x": 16,
      "y": 26,
      "z": 14,
      "name": "Wood_Windwillow_Trunk_Full"
    },
    {
      "x": 16,
      "y": 21,
      "z": 15,
      "name": "Wood_Windwillow_Trunk_Full"
    },
    {
      "x": 16,
      "y": 22,
      "z": 15,
      "name": "Wood_Windwillow_Trunk"
    },
    {
      "x": 16,
      "y": 23,
      "z": 15,
      "name": "Wood_Windwillow_Trunk"
    },
    {
      "x": 16,
      "y": 24,
      "z": 15,
      "name": "Wood_Windwillow_Trunk"
    },
    {
      "x": 16,
      "y": 25,
      "z": 15,
      "name": "Wood_Windwillow_Trunk"
    },
    {
      "x": 16,
      "y": 26,
      "z": 15,
      "name": "Wood_Windwillow_Trunk_Full"
    },
    {
      "x": 16,
      "y": 31,
      "z": 15,
      "name": "Plant_Leaves_Windwillow"
    },
    {
      "x": 16,
      "y": 32,
      "z": 15,
      "name": "Plant_Leaves_Windwillow"
    },
    {
      "x": 16,
      "y": 6,
      "z": 16,
      "name": "Wood_Windwillow_Roots"
    },
    {
      "x": 16,
      "y": 7,
      "z": 16,
      "name": "Wood_Windwillow_Trunk"
    },
    {
      "x": 16,
      "y": 8,
      "z": 16,
      "name": "Wood_Windwillow_Trunk_Full"
    },
    {
      "x": 16,
      "y": 11,
      "z": 16,
      "name": "Wood_Windwillow_Trunk_Full"
    },
    {
      "x": 16,
      "y": 12,
      "z": 16,
      "name": "Wood_Windwillow_Trunk_Full"
    },
    {
      "x": 16,
      "y": 21,
      "z": 16,
      "name": "Wood_Windwillow_Trunk_Full"
    },
    {
      "x": 16,
      "y": 22,
      "z": 16,
      "name": "Wood_Windwillow_Trunk"
    },
    {
      "x": 16,
      "y": 23,
      "z": 16,
      "name": "Wood_Windwillow_Trunk_Full"
    },
    {
      "x": 16,
      "y": 29,
      "z": 16,
      "name": "Wood_Windwillow_Trunk_Full"
    },
    {
      "x": 16,
      "y": 30,
      "z": 16,
      "name": "Plant_Leaves_Windwillow"
    },
    {
      "x": 16,
      "y": 31,
      "z": 16,
      "name": "Plant_Leaves_Windwillow"
    },
    {
      "x": 16,
      "y": 8,
      "z": 17,
      "name": "Wood_Windwillow_Trunk_Full"
    },
    {
      "x": 16,
      "y": 9,
      "z": 17,
      "name": "Wood_Windwillow_Trunk"
    },
    {
      "x": 16,
      "y": 10,
      "z": 17,
      "name": "Wood_Windwillow_Trunk"
    },
    {
      "x": 16,
      "y": 11,
      "z": 17,
      "name": "Wood_Windwillow_Trunk_Full"
    },
    {
      "x": 16,
      "y": 29,
      "z": 17,
      "name": "Wood_Windwillow_Trunk_Full"
    },
    {
      "x": 16,
      "y": 30,
      "z": 17,
      "name": "Wood_Windwillow_Trunk_Full"
    },
    {
      "x": 16,
      "y": 31,
      "z": 17,
      "name": "Plant_Leaves_Windwillow"
    },
    {
      "x": 16,
      "y": 32,
      "z": 17,
      "name": "Plant_Leaves_Windwillow"
    },
    {
      "x": 16,
      "y": 30,
      "z": 18,
      "name": "Wood_Windwillow_Trunk_Full"
    },
    {
      "x": 16,
      "y": 31,
      "z": 18,
      "name": "Wood_Windwillow_Trunk_Full"
    },
    {
      "x": 16,
      "y": 32,
      "z": 18,
      "name": "Plant_Leaves_Windwillow"
    },
    {
      "x": 16,
      "y": 32,
      "z": 19,
      "name": "Plant_Leaves_Windwillow"
    },
    {
      "x": 16,
      "y": 33,
      "z": 19,
      "name": "Plant_Leaves_Windwillow"
    },
    {
      "x": 16,
      "y": 28,
      "z": 20,
      "name": "Plant_Leaves_Windwillow"
    },
    {
      "x": 16,
      "y": 29,
      "z": 20,
      "name": "Plant_Leaves_Windwillow"
    },
    {
      "x": 16,
      "y": 30,
      "z": 20,
      "name": "Plant_Leaves_Windwillow"
    },
    {
      "x": 16,
      "y": 31,
      "z": 20,
      "name": "Plant_Leaves_Windwillow"
    },
    {
      "x": 16,
      "y": 32,
      "z": 20,
      "name": "Plant_Leaves_Windwillow"
    },
    {
      "x": 16,
      "y": 28,
      "z": 21,
      "name": "Plant_Leaves_Windwillow"
    },
    {
      "x": 16,
      "y": 29,
      "z": 21,
      "name": "Plant_Leaves_Windwillow"
    },
    {
      "x": 17,
      "y": 32,
      "z": 6,
      "name": "Plant_Leaves_Windwillow"
    },
    {
      "x": 17,
      "y": 28,
      "z": 7,
      "name": "Plant_Leaves_Windwillow"
    },
    {
      "x": 17,
      "y": 29,
      "z": 7,
      "name": "Plant_Leaves_Windwillow"
    },
    {
      "x": 17,
      "y": 30,
      "z": 7,
      "name": "Plant_Leaves_Windwillow"
    },
    {
      "x": 17,
      "y": 31,
      "z": 7,
      "name": "Plant_Leaves_Windwillow"
    },
    {
      "x": 17,
      "y": 32,
      "z": 7,
      "name": "Plant_Leaves_Windwillow"
    },
    {
      "x": 17,
      "y": 27,
      "z": 8,
      "name": "Plant_Leaves_Windwillow"
    },
    {
      "x": 17,
      "y": 28,
      "z": 8,
      "name": "Plant_Leaves_Windwillow"
    },
    {
      "x": 17,
      "y": 29,
      "z": 8,
      "name": "Plant_Leaves_Windwillow"
    },
    {
      "x": 17,
      "y": 30,
      "z": 8,
      "name": "Plant_Leaves_Windwillow"
    },
    {
      "x": 17,
      "y": 31,
      "z": 8,
      "name": "Plant_Leaves_Windwillow"
    },
    {
      "x": 17,
      "y": 32,
      "z": 8,
      "name": "Plant_Leaves_Windwillow"
    },
    {
      "x": 17,
      "y": 33,
      "z": 8,
      "name": "Plant_Leaves_Windwillow"
    },
    {
      "x": 17,
      "y": 23,
      "z": 9,
      "name": "Plant_Leaves_Windwillow"
    },
    {
      "x": 17,
      "y": 30,
      "z": 9,
      "name": "Plant_Leaves_Windwillow"
    },
    {
      "x": 17,
      "y": 31,
      "z": 9,
      "name": "Plant_Leaves_Windwillow"
    },
    {
      "x": 17,
      "y": 32,
      "z": 9,
      "name": "Plant_Leaves_Windwillow"
    },
    {
      "x": 17,
      "y": 33,
      "z": 9,
      "name": "Plant_Leaves_Windwillow"
    },
    {
      "x": 17,
      "y": 29,
      "z": 10,
      "name": "Wood_Windwillow_Trunk_Full"
    },
    {
      "x": 17,
      "y": 30,
      "z": 10,
      "name": "Wood_Windwillow_Trunk_Full"
    },
    {
      "x": 17,
      "y": 32,
      "z": 10,
      "name": "Plant_Leaves_Windwillow"
    },
    {
      "x": 17,
      "y": 33,
      "z": 10,
      "name": "Plant_Leaves_Windwillow"
    },
    {
      "x": 17,
      "y": 29,
      "z": 11,
      "name": "Wood_Windwillow_Trunk_Full"
    },
    {
      "x": 17,
      "y": 32,
      "z": 11,
      "name": "Plant_Leaves_Windwillow"
    },
    {
      "x": 17,
      "y": 23,
      "z": 12,
      "name": "Wood_Windwillow_Trunk_Full"
    },
    {
      "x": 17,
      "y": 28,
      "z": 12,
      "name": "Plant_Leaves_Windwillow"
    },
    {
      "x": 17,
      "y": 29,
      "z": 12,
      "name": "Plant_Leaves_Windwillow"
    },
    {
      "x": 17,
      "y": 30,
      "z": 12,
      "name": "Plant_Leaves_Windwillow"
    },
    {
      "x": 17,
      "y": 31,
      "z": 12,
      "name": "Plant_Leaves_Windwillow"
    },
    {
      "x": 17,
      "y": 22,
      "z": 13,
      "name": "Wood_Windwillow_Trunk_Full"
    },
    {
      "x": 17,
      "y": 23,
      "z": 13,
      "name": "Wood_Windwillow_Trunk_Full"
    },
    {
      "x": 17,
      "y": 31,
      "z": 13,
      "name": "Plant_Leaves_Windwillow"
    },
    {
      "x": 17,
      "y": 32,
      "z": 13,
      "name": "Plant_Leaves_Windwillow"
    },
    {
      "x": 17,
      "y": 22,
      "z": 14,
      "name": "Wood_Windwillow_Trunk_Full"
    },
    {
      "x": 17,
      "y": 26,
      "z": 15,
      "name": "Wood_Windwillow_Trunk_Full"
    },
    {
      "x": 17,
      "y": 27,
      "z": 15,
      "name": "Wood_Windwillow_Trunk_Full"
    },
    {
      "x": 17,
      "y": 30,
      "z": 15,
      "name": "Plant_Leaves_Windwillow"
    },
    {
      "x": 17,
      "y": 31,
      "z": 15,
      "name": "Plant_Leaves_Windwillow"
    },
    {
      "x": 17,
      "y": 32,
      "z": 15,
      "name": "Plant_Leaves_Windwillow"
    },
    {
      "x": 17,
      "y": 27,
      "z": 16,
      "name": "Plant_Leaves_Windwillow"
    },
    {
      "x": 17,
      "y": 28,
      "z": 16,
      "name": "Plant_Leaves_Windwillow"
    },
    {
      "x": 17,
      "y": 29,
      "z": 16,
      "name": "Plant_Leaves_Windwillow"
    },
    {
      "x": 17,
      "y": 30,
      "z": 16,
      "name": "Plant_Leaves_Windwillow"
    },
    {
      "x": 17,
      "y": 31,
      "z": 16,
      "name": "Plant_Leaves_Windwillow"
    },
    {
      "x": 17,
      "y": 32,
      "z": 16,
      "name": "Plant_Leaves_Windwillow"
    },
    {
      "x": 17,
      "y": 33,
      "z": 16,
      "name": "Plant_Leaves_Windwillow"
    },
    {
      "x": 17,
      "y": 29,
      "z": 17,
      "name": "Plant_Fruit_Windwillow",
      "rotation": 8
    },
    {
      "x": 17,
      "y": 30,
      "z": 17,
      "name": "Plant_Leaves_Windwillow"
    },
    {
      "x": 17,
      "y": 31,
      "z": 17,
      "name": "Plant_Leaves_Windwillow"
    },
    {
      "x": 17,
      "y": 32,
      "z": 17,
      "name": "Plant_Leaves_Windwillow"
    },
    {
      "x": 17,
      "y": 33,
      "z": 17,
      "name": "Plant_Leaves_Windwillow"
    },
    {
      "x": 17,
      "y": 30,
      "z": 18,
      "name": "Wood_Windwillow_Trunk_Full"
    },
    {
      "x": 17,
      "y": 31,
      "z": 18,
      "name": "Wood_Windwillow_Trunk_Full"
    },
    {
      "x": 17,
      "y": 32,
      "z": 18,
      "name": "Plant_Leaves_Windwillow"
    },
    {
      "x": 17,
      "y": 34,
      "z": 18,
      "name": "Plant_Leaves_Windwillow"
    },
    {
      "x": 17,
      "y": 30,
      "z": 19,
      "name": "Wood_Windwillow_Trunk_Full"
    },
    {
      "x": 17,
      "y": 31,
      "z": 19,
      "name": "Wood_Windwillow_Trunk_Full"
    },
    {
      "x": 17,
      "y": 32,
      "z": 19,
      "name": "Plant_Leaves_Windwillow"
    },
    {
      "x": 17,
      "y": 33,
      "z": 19,
      "name": "Plant_Leaves_Windwillow"
    },
    {
      "x": 17,
      "y": 34,
      "z": 19,
      "name": "Plant_Leaves_Windwillow"
    },
    {
      "x": 17,
      "y": 29,
      "z": 20,
      "name": "Plant_Fruit_Windwillow",
      "rotation": 8
    },
    {
      "x": 17,
      "y": 30,
      "z": 20,
      "name": "Plant_Leaves_Windwillow"
    },
    {
      "x": 17,
      "y": 31,
      "z": 20,
      "name": "Plant_Leaves_Windwillow"
    },
    {
      "x": 17,
      "y": 32,
      "z": 20,
      "name": "Plant_Leaves_Windwillow"
    },
    {
      "x": 17,
      "y": 33,
      "z": 20,
      "name": "Plant_Leaves_Windwillow"
    },
    {
      "x": 17,
      "y": 28,
      "z": 21,
      "name": "Plant_Leaves_Windwillow"
    },
    {
      "x": 17,
      "y": 29,
      "z": 21,
      "name": "Plant_Leaves_Windwillow"
    },
    {
      "x": 17,
      "y": 30,
      "z": 21,
      "name": "Plant_Leaves_Windwillow"
    },
    {
      "x": 17,
      "y": 31,
      "z": 21,
      "name": "Plant_Leaves_Windwillow"
    },
    {
      "x": 17,
      "y": 29,
      "z": 22,
      "name": "Plant_Leaves_Windwillow"
    },
    {
      "x": 17,
      "y": 30,
      "z": 22,
      "name": "Plant_Leaves_Windwillow"
    },
    {
      "x": 18,
      "y": 30,
      "z": 4,
      "name": "Plant_Leaves_Windwillow"
    },
    {
      "x": 18,
      "y": 29,
      "z": 5,
      "name": "Plant_Leaves_Windwillow"
    },
    {
      "x": 18,
      "y": 30,
      "z": 5,
      "name": "Plant_Leaves_Windwillow"
    },
    {
      "x": 18,
      "y": 31,
      "z": 5,
      "name": "Plant_Leaves_Windwillow"
    },
    {
      "x": 18,
      "y": 28,
      "z": 6,
      "name": "Plant_Leaves_Windwillow"
    },
    {
      "x": 18,
      "y": 31,
      "z": 6,
      "name": "Plant_Leaves_Windwillow"
    },
    {
      "x": 18,
      "y": 32,
      "z": 6,
      "name": "Plant_Leaves_Windwillow"
    },
    {
      "x": 18,
      "y": 30,
      "z": 7,
      "name": "Wood_Windwillow_Trunk_Full"
    },
    {
      "x": 18,
      "y": 32,
      "z": 7,
      "name": "Plant_Leaves_Windwillow"
    },
    {
      "x": 18,
      "y": 22,
      "z": 8,
      "name": "Plant_Leaves_Windwillow"
    },
    {
      "x": 18,
      "y": 23,
      "z": 8,
      "name": "Plant_Leaves_Windwillow"
    },
    {
      "x": 18,
      "y": 30,
      "z": 8,
      "name": "Wood_Windwillow_Trunk_Full"
    },
    {
      "x": 18,
      "y": 32,
      "z": 8,
      "name": "Plant_Leaves_Windwillow"
    },
    {
      "x": 18,
      "y": 33,
      "z": 8,
      "name": "Plant_Leaves_Windwillow"
    },
    {
      "x": 18,
      "y": 21,
      "z": 9,
      "name": "Plant_Leaves_Windwillow"
    },
    {
      "x": 18,
      "y": 22,
      "z": 9,
      "name": "Plant_Leaves_Windwillow"
    },
    {
      "x": 18,
      "y": 23,
      "z": 9,
      "name": "Plant_Leaves_Windwillow"
    },
    {
      "x": 18,
      "y": 24,
      "z": 9,
      "name": "Plant_Leaves_Windwillow"
    },
    {
      "x": 18,
      "y": 30,
      "z": 9,
      "name": "Wood_Windwillow_Trunk_Full"
    },
    {
      "x": 18,
      "y": 32,
      "z": 9,
      "name": "Plant_Leaves_Windwillow"
    },
    {
      "x": 18,
      "y": 33,
      "z": 9,
      "name": "Plant_Leaves_Windwillow"
    },
    {
      "x": 18,
      "y": 23,
      "z": 10,
      "name": "Plant_Leaves_Windwillow"
    },
    {
      "x": 18,
      "y": 24,
      "z": 10,
      "name": "Plant_Leaves_Windwillow"
    },
    {
      "x": 18,
      "y": 30,
      "z": 10,
      "name": "Wood_Windwillow_Trunk_Full"
    },
    {
      "x": 18,
      "y": 32,
      "z": 10,
      "name": "Plant_Leaves_Windwillow"
    },
    {
      "x": 18,
      "y": 23,
      "z": 11,
      "name": "Wood_Windwillow_Trunk_Full"
    },
    {
      "x": 18,
      "y": 27,
      "z": 11,
      "name": "Plant_Fruit_Windwillow",
      "rotation": 8
    },
    {
      "x": 18,
      "y": 28,
      "z": 11,
      "name": "Plant_Leaves_Windwillow"
    },
    {
      "x": 18,
      "y": 29,
      "z": 11,
      "name": "Plant_Leaves_Windwillow"
    },
    {
      "x": 18,
      "y": 30,
      "z": 11,
      "name": "Plant_Leaves_Windwillow"
    },
    {
      "x": 18,
      "y": 23,
      "z": 12,
      "name": "Wood_Windwillow_Trunk_Full"
    },
    {
      "x": 18,
      "y": 26,
      "z": 12,
      "name": "Plant_Leaves_Windwillow"
    },
    {
      "x": 18,
      "y": 27,
      "z": 12,
      "name": "Plant_Leaves_Windwillow"
    },
    {
      "x": 18,
      "y": 28,
      "z": 12,
      "name": "Plant_Leaves_Windwillow"
    },
    {
      "x": 18,
      "y": 29,
      "z": 12,
      "name": "Plant_Leaves_Windwillow"
    },
    {
      "x": 18,
      "y": 31,
      "z": 12,
      "name": "Plant_Leaves_Windwillow"
    },
    {
      "x": 18,
      "y": 32,
      "z": 12,
      "name": "Plant_Leaves_Windwillow"
    },
    {
      "x": 18,
      "y": 23,
      "z": 13,
      "name": "Wood_Windwillow_Trunk_Full"
    },
    {
      "x": 18,
      "y": 31,
      "z": 13,
      "name": "Plant_Leaves_Windwillow"
    },
    {
      "x": 18,
      "y": 27,
      "z": 14,
      "name": "Wood_Windwillow_Trunk_Full"
    },
    {
      "x": 18,
      "y": 27,
      "z": 15,
      "name": "Wood_Windwillow_Trunk_Full"
    },
    {
      "x": 18,
      "y": 29,
      "z": 16,
      "name": "Plant_Leaves_Windwillow"
    },
    {
      "x": 18,
      "y": 30,
      "z": 16,
      "name": "Plant_Leaves_Windwillow"
    },
    {
      "x": 18,
      "y": 31,
      "z": 16,
      "name": "Plant_Leaves_Windwillow"
    },
    {
      "x": 18,
      "y": 32,
      "z": 16,
      "name": "Plant_Leaves_Windwillow"
    },
    {
      "x": 18,
      "y": 33,
      "z": 16,
      "name": "Plant_Leaves_Windwillow"
    },
    {
      "x": 18,
      "y": 30,
      "z": 17,
      "name": "Plant_Leaves_Windwillow"
    },
    {
      "x": 18,
      "y": 31,
      "z": 17,
      "name": "Plant_Leaves_Windwillow"
    },
    {
      "x": 18,
      "y": 32,
      "z": 17,
      "name": "Plant_Leaves_Windwillow"
    },
    {
      "x": 18,
      "y": 33,
      "z": 17,
      "name": "Plant_Leaves_Windwillow"
    },
    {
      "x": 18,
      "y": 29,
      "z": 18,
      "name": "Plant_Leaves_Windwillow"
    },
    {
      "x": 18,
      "y": 30,
      "z": 18,
      "name": "Plant_Leaves_Windwillow"
    },
    {
      "x": 18,
      "y": 31,
      "z": 18,
      "name": "Plant_Leaves_Windwillow"
    },
    {
      "x": 18,
      "y": 32,
      "z": 18,
      "name": "Plant_Leaves_Windwillow"
    },
    {
      "x": 18,
      "y": 33,
      "z": 18,
      "name": "Plant_Leaves_Windwillow"
    },
    {
      "x": 18,
      "y": 34,
      "z": 18,
      "name": "Plant_Leaves_Windwillow"
    },
    {
      "x": 18,
      "y": 30,
      "z": 19,
      "name": "Plant_Leaves_Windwillow"
    },
    {
      "x": 18,
      "y": 31,
      "z": 19,
      "name": "Plant_Leaves_Windwillow"
    },
    {
      "x": 18,
      "y": 32,
      "z": 19,
      "name": "Plant_Leaves_Windwillow"
    },
    {
      "x": 18,
      "y": 33,
      "z": 19,
      "name": "Plant_Leaves_Windwillow"
    },
    {
      "x": 18,
      "y": 28,
      "z": 20,
      "name": "Plant_Leaves_Windwillow"
    },
    {
      "x": 18,
      "y": 29,
      "z": 20,
      "name": "Plant_Leaves_Windwillow"
    },
    {
      "x": 18,
      "y": 30,
      "z": 20,
      "name": "Plant_Leaves_Windwillow"
    },
    {
      "x": 18,
      "y": 31,
      "z": 20,
      "name": "Plant_Leaves_Windwillow"
    },
    {
      "x": 18,
      "y": 32,
      "z": 20,
      "name": "Plant_Leaves_Windwillow"
    },
    {
      "x": 18,
      "y": 28,
      "z": 21,
      "name": "Plant_Leaves_Windwillow"
    },
    {
      "x": 18,
      "y": 29,
      "z": 21,
      "name": "Plant_Leaves_Windwillow"
    },
    {
      "x": 18,
      "y": 30,
      "z": 21,
      "name": "Plant_Leaves_Windwillow"
    },
    {
      "x": 18,
      "y": 29,
      "z": 22,
      "name": "Plant_Leaves_Windwillow"
    },
    {
      "x": 19,
      "y": 29,
      "z": 4,
      "name": "Plant_Leaves_Windwillow"
    },
    {
      "x": 19,
      "y": 29,
      "z": 5,
      "name": "Plant_Leaves_Windwillow"
    },
    {
      "x": 19,
      "y": 30,
      "z": 5,
      "name": "Plant_Leaves_Windwillow"
    },
    {
      "x": 19,
      "y": 27,
      "z": 6,
      "name": "Plant_Leaves_Windwillow"
    },
    {
      "x": 19,
      "y": 28,
      "z": 6,
      "name": "Plant_Leaves_Windwillow"
    },
    {
      "x": 19,
      "y": 29,
      "z": 6,
      "name": "Plant_Leaves_Windwillow"
    },
    {
      "x": 19,
      "y": 30,
      "z": 6,
      "name": "Plant_Leaves_Windwillow"
    },
    {
      "x": 19,
      "y": 31,
      "z": 6,
      "name": "Plant_Leaves_Windwillow"
    },
    {
      "x": 19,
      "y": 26,
      "z": 7,
      "name": "Plant_Leaves_Windwillow"
    },
    {
      "x": 19,
      "y": 27,
      "z": 7,
      "name": "Plant_Leaves_Windwillow"
    },
    {
      "x": 19,
      "y": 28,
      "z": 7,
      "name": "Plant_Leaves_Windwillow"
    },
    {
      "x": 19,
      "y": 29,
      "z": 7,
      "name": "Plant_Leaves_Windwillow"
    },
    {
      "x": 19,
      "y": 30,
      "z": 7,
      "name": "Plant_Leaves_Windwillow"
    },
    {
      "x": 19,
      "y": 31,
      "z": 7,
      "name": "Plant_Leaves_Windwillow"
    },
    {
      "x": 19,
      "y": 32,
      "z": 7,
      "name": "Plant_Leaves_Windwillow"
    },
    {
      "x": 19,
      "y": 22,
      "z": 8,
      "name": "Plant_Leaves_Windwillow"
    },
    {
      "x": 19,
      "y": 23,
      "z": 8,
      "name": "Plant_Leaves_Windwillow"
    },
    {
      "x": 19,
      "y": 24,
      "z": 8,
      "name": "Plant_Leaves_Windwillow"
    },
    {
      "x": 19,
      "y": 27,
      "z": 8,
      "name": "Plant_Fruit_Windwillow",
      "rotation": 8
    },
    {
      "x": 19,
      "y": 28,
      "z": 8,
      "name": "Plant_Leaves_Windwillow"
    },
    {
      "x": 19,
      "y": 29,
      "z": 8,
      "name": "Plant_Leaves_Windwillow"
    },
    {
      "x": 19,
      "y": 30,
      "z": 8,
      "name": "Plant_Leaves_Windwillow"
    },
    {
      "x": 19,
      "y": 31,
      "z": 8,
      "name": "Plant_Leaves_Windwillow"
    },
    {
      "x": 19,
      "y": 32,
      "z": 8,
      "name": "Plant_Leaves_Windwillow"
    },
    {
      "x": 19,
      "y": 24,
      "z": 9,
      "name": "Plant_Leaves_Windwillow"
    },
    {
      "x": 19,
      "y": 25,
      "z": 9,
      "name": "Plant_Leaves_Windwillow"
    },
    {
      "x": 19,
      "y": 28,
      "z": 9,
      "name": "Plant_Leaves_Windwillow"
    },
    {
      "x": 19,
      "y": 29,
      "z": 9,
      "name": "Plant_Leaves_Windwillow"
    },
    {
      "x": 19,
      "y": 30,
      "z": 9,
      "name": "Plant_Leaves_Windwillow"
    },
    {
      "x": 19,
      "y": 31,
      "z": 9,
      "name": "Plant_Leaves_Windwillow"
    },
    {
      "x": 19,
      "y": 32,
      "z": 9,
      "name": "Plant_Leaves_Windwillow"
    },
    {
      "x": 19,
      "y": 23,
      "z": 10,
      "name": "Wood_Windwillow_Trunk_Full"
    },
    {
      "x": 19,
      "y": 25,
      "z": 10,
      "name": "Plant_Leaves_Windwillow"
    },
    {
      "x": 19,
      "y": 29,
      "z": 10,
      "name": "Plant_Leaves_Windwillow"
    },
    {
      "x": 19,
      "y": 30,
      "z": 10,
      "name": "Plant_Leaves_Windwillow"
    },
    {
      "x": 19,
      "y": 31,
      "z": 10,
      "name": "Plant_Leaves_Windwillow"
    },
    {
      "x": 19,
      "y": 23,
      "z": 11,
      "name": "Wood_Windwillow_Trunk_Full"
    },
    {
      "x": 19,
      "y": 25,
      "z": 11,
      "name": "Plant_Leaves_Windwillow"
    },
    {
      "x": 19,
      "y": 28,
      "z": 11,
      "name": "Plant_Leaves_Windwillow"
    },
    {
      "x": 19,
      "y": 29,
      "z": 11,
      "name": "Plant_Leaves_Windwillow"
    },
    {
      "x": 19,
      "y": 30,
      "z": 11,
      "name": "Plant_Leaves_Windwillow"
    },
    {
      "x": 19,
      "y": 24,
      "z": 12,
      "name": "Plant_Leaves_Windwillow"
    },
    {
      "x": 19,
      "y": 29,
      "z": 13,
      "name": "Plant_Leaves_Windwillow"
    },
    {
      "x": 19,
      "y": 27,
      "z": 14,
      "name": "Wood_Windwillow_Trunk_Full"
    },
    {
      "x": 19,
      "y": 28,
      "z": 15,
      "name": "Plant_Leaves_Windwillow"
    },
    {
      "x": 19,
      "y": 29,
      "z": 15,
      "name": "Plant_Leaves_Windwillow"
    },
    {
      "x": 19,
      "y": 28,
      "z": 16,
      "name": "Plant_Leaves_Windwillow"
    },
    {
      "x": 19,
      "y": 31,
      "z": 17,
      "name": "Plant_Leaves_Windwillow"
    },
    {
      "x": 19,
      "y": 32,
      "z": 17,
      "name": "Plant_Leaves_Windwillow"
    },
    {
      "x": 19,
      "y": 28,
      "z": 18,
      "name": "Plant_Leaves_Windwillow"
    },
    {
      "x": 19,
      "y": 29,
      "z": 18,
      "name": "Plant_Leaves_Windwillow"
    },
    {
      "x": 19,
      "y": 30,
      "z": 18,
      "name": "Plant_Leaves_Windwillow"
    },
    {
      "x": 19,
      "y": 31,
      "z": 18,
      "name": "Plant_Leaves_Windwillow"
    },
    {
      "x": 19,
      "y": 32,
      "z": 18,
      "name": "Plant_Leaves_Windwillow"
    },
    {
      "x": 19,
      "y": 33,
      "z": 18,
      "name": "Plant_Leaves_Windwillow"
    },
    {
      "x": 19,
      "y": 28,
      "z": 19,
      "name": "Plant_Leaves_Windwillow"
    },
    {
      "x": 19,
      "y": 29,
      "z": 19,
      "name": "Plant_Leaves_Windwillow"
    },
    {
      "x": 19,
      "y": 30,
      "z": 19,
      "name": "Plant_Leaves_Windwillow"
    },
    {
      "x": 19,
      "y": 31,
      "z": 19,
      "name": "Plant_Leaves_Windwillow"
    },
    {
      "x": 19,
      "y": 32,
      "z": 19,
      "name": "Plant_Leaves_Windwillow"
    },
    {
      "x": 19,
      "y": 28,
      "z": 20,
      "name": "Plant_Leaves_Windwillow"
    },
    {
      "x": 19,
      "y": 29,
      "z": 20,
      "name": "Plant_Leaves_Windwillow"
    },
    {
      "x": 20,
      "y": 29,
      "z": 5,
      "name": "Plant_Leaves_Windwillow"
    },
    {
      "x": 20,
      "y": 28,
      "z": 6,
      "name": "Plant_Leaves_Windwillow"
    },
    {
      "x": 20,
      "y": 29,
      "z": 6,
      "name": "Plant_Leaves_Windwillow"
    },
    {
      "x": 20,
      "y": 30,
      "z": 6,
      "name": "Plant_Leaves_Windwillow"
    },
    {
      "x": 20,
      "y": 28,
      "z": 7,
      "name": "Plant_Leaves_Windwillow"
    },
    {
      "x": 20,
      "y": 29,
      "z": 7,
      "name": "Plant_Leaves_Windwillow"
    },
    {
      "x": 20,
      "y": 23,
      "z": 8,
      "name": "Plant_Leaves_Windwillow"
    },
    {
      "x": 20,
      "y": 24,
      "z": 8,
      "name": "Plant_Leaves_Windwillow"
    },
    {
      "x": 20,
      "y": 29,
      "z": 8,
      "name": "Plant_Leaves_Windwillow"
    },
    {
      "x": 20,
      "y": 30,
      "z": 8,
      "name": "Plant_Leaves_Windwillow"
    },
    {
      "x": 20,
      "y": 24,
      "z": 9,
      "name": "Plant_Leaves_Windwillow"
    },
    {
      "x": 20,
      "y": 25,
      "z": 9,
      "name": "Plant_Leaves_Windwillow"
    },
    {
      "x": 20,
      "y": 29,
      "z": 9,
      "name": "Plant_Leaves_Windwillow"
    },
    {
      "x": 20,
      "y": 30,
      "z": 9,
      "name": "Plant_Leaves_Windwillow"
    },
    {
      "x": 20,
      "y": 22,
      "z": 10,
      "name": "Plant_Fruit_Windwillow",
      "rotation": 8
    },
    {
      "x": 20,
      "y": 23,
      "z": 10,
      "name": "Plant_Leaves_Windwillow"
    },
    {
      "x": 20,
      "y": 24,
      "z": 10,
      "name": "Plant_Leaves_Windwillow"
    },
    {
      "x": 20,
      "y": 25,
      "z": 10,
      "name": "Plant_Leaves_Windwillow"
    },
    {
      "x": 20,
      "y": 27,
      "z": 10,
      "name": "Plant_Leaves_Windwillow"
    },
    {
      "x": 20,
      "y": 28,
      "z": 10,
      "name": "Plant_Leaves_Windwillow"
    },
    {
      "x": 20,
      "y": 29,
      "z": 10,
      "name": "Plant_Leaves_Windwillow"
    },
    {
      "x": 20,
      "y": 30,
      "z": 10,
      "name": "Plant_Leaves_Windwillow"
    },
    {
      "x": 20,
      "y": 20,
      "z": 11,
      "name": "Plant_Leaves_Windwillow"
    },
    {
      "x": 20,
      "y": 21,
      "z": 11,
      "name": "Plant_Leaves_Windwillow"
    },
    {
      "x": 20,
      "y": 22,
      "z": 11,
      "name": "Plant_Leaves_Windwillow"
    },
    {
      "x": 20,
      "y": 23,
      "z": 11,
      "name": "Plant_Leaves_Windwillow"
    },
    {
      "x": 20,
      "y": 24,
      "z": 11,
      "name": "Plant_Leaves_Windwillow"
    },
    {
      "x": 20,
      "y": 23,
      "z": 12,
      "name": "Plant_Leaves_Windwillow"
    },
    {
      "x": 20,
      "y": 24,
      "z": 12,
      "name": "Plant_Leaves_Windwillow"
    },
    {
      "x": 20,
      "y": 29,
      "z": 12,
      "name": "Plant_Leaves_Windwillow"
    },
    {
      "x": 20,
      "y": 28,
      "z": 13,
      "name": "Plant_Leaves_Windwillow"
    },
    {
      "x": 20,
      "y": 29,
      "z": 13,
      "name": "Plant_Leaves_Windwillow"
    },
    {
      "x": 20,
      "y": 27,
      "z": 14,
      "name": "Wood_Windwillow_Trunk_Full"
    },
    {
      "x": 20,
      "y": 29,
      "z": 14,
      "name": "Plant_Leaves_Windwillow"
    },
    {
      "x": 20,
      "y": 28,
      "z": 15,
      "name": "Plant_Leaves_Windwillow"
    },
    {
      "x": 20,
      "y": 29,
      "z": 15,
      "name": "Plant_Leaves_Windwillow"
    },
    {
      "x": 20,
      "y": 25,
      "z": 16,
      "name": "Plant_Leaves_Windwillow"
    },
    {
      "x": 20,
      "y": 26,
      "z": 16,
      "name": "Plant_Leaves_Windwillow"
    },
    {
      "x": 20,
      "y": 27,
      "z": 16,
      "name": "Plant_Leaves_Windwillow"
    },
    {
      "x": 20,
      "y": 28,
      "z": 16,
      "name": "Plant_Leaves_Windwillow"
    },
    {
      "x": 20,
      "y": 29,
      "z": 16,
      "name": "Plant_Leaves_Windwillow"
    },
    {
      "x": 20,
      "y": 26,
      "z": 17,
      "name": "Plant_Leaves_Windwillow"
    },
    {
      "x": 20,
      "y": 27,
      "z": 17,
      "name": "Plant_Leaves_Windwillow"
    },
    {
      "x": 20,
      "y": 28,
      "z": 18,
      "name": "Plant_Leaves_Windwillow"
    },
    {
      "x": 20,
      "y": 29,
      "z": 18,
      "name": "Plant_Leaves_Windwillow"
    },
    {
      "x": 20,
      "y": 30,
      "z": 18,
      "name": "Plant_Leaves_Windwillow"
    },
    {
      "x": 20,
      "y": 28,
      "z": 19,
      "name": "Plant_Leaves_Windwillow"
    },
    {
      "x": 20,
      "y": 29,
      "z": 19,
      "name": "Plant_Leaves_Windwillow"
    },
    {
      "x": 21,
      "y": 23,
      "z": 7,
      "name": "Plant_Leaves_Windwillow"
    },
    {
      "x": 21,
      "y": 22,
      "z": 8,
      "name": "Plant_Leaves_Windwillow"
    },
    {
      "x": 21,
      "y": 23,
      "z": 8,
      "name": "Plant_Leaves_Windwillow"
    },
    {
      "x": 21,
      "y": 21,
      "z": 9,
      "name": "Plant_Leaves_Windwillow"
    },
    {
      "x": 21,
      "y": 22,
      "z": 9,
      "name": "Plant_Leaves_Windwillow"
    },
    {
      "x": 21,
      "y": 23,
      "z": 9,
      "name": "Plant_Leaves_Windwillow"
    },
    {
      "x": 21,
      "y": 24,
      "z": 9,
      "name": "Plant_Leaves_Windwillow"
    },
    {
      "x": 21,
      "y": 21,
      "z": 10,
      "name": "Plant_Leaves_Windwillow"
    },
    {
      "x": 21,
      "y": 22,
      "z": 10,
      "name": "Plant_Leaves_Windwillow"
    },
    {
      "x": 21,
      "y": 23,
      "z": 10,
      "name": "Plant_Leaves_Windwillow"
    },
    {
      "x": 21,
      "y": 24,
      "z": 10,
      "name": "Plant_Leaves_Windwillow"
    },
    {
      "x": 21,
      "y": 22,
      "z": 11,
      "name": "Plant_Leaves_Windwillow"
    },
    {
      "x": 21,
      "y": 23,
      "z": 11,
      "name": "Plant_Leaves_Windwillow"
    },
    {
      "x": 21,
      "y": 27,
      "z": 12,
      "name": "Plant_Leaves_Windwillow"
    },
    {
      "x": 21,
      "y": 28,
      "z": 12,
      "name": "Plant_Leaves_Windwillow"
    },
    {
      "x": 21,
      "y": 27,
      "z": 13,
      "name": "Plant_Leaves_Windwillow"
    },
    {
      "x": 21,
      "y": 28,
      "z": 13,
      "name": "Plant_Leaves_Windwillow"
    },
    {
      "x": 21,
      "y": 29,
      "z": 13,
      "name": "Plant_Leaves_Windwillow"
    },
    {
      "x": 21,
      "y": 27,
      "z": 14,
      "name": "Wood_Windwillow_Trunk_Full"
    },
    {
      "x": 21,
      "y": 29,
      "z": 14,
      "name": "Plant_Leaves_Windwillow"
    },
    {
      "x": 21,
      "y": 25,
      "z": 15,
      "name": "Plant_Fruit_Windwillow",
      "rotation": 8
    },
    {
      "x": 21,
      "y": 26,
      "z": 15,
      "name": "Plant_Leaves_Windwillow"
    },
    {
      "x": 21,
      "y": 27,
      "z": 15,
      "name": "Plant_Leaves_Windwillow"
    },
    {
      "x": 21,
      "y": 28,
      "z": 15,
      "name": "Plant_Leaves_Windwillow"
    },
    {
      "x": 21,
      "y": 29,
      "z": 15,
      "name": "Plant_Leaves_Windwillow"
    },
    {
      "x": 21,
      "y": 25,
      "z": 16,
      "name": "Plant_Leaves_Windwillow"
    },
    {
      "x": 21,
      "y": 26,
      "z": 16,
      "name": "Plant_Leaves_Windwillow"
    },
    {
      "x": 21,
      "y": 27,
      "z": 16,
      "name": "Plant_Leaves_Windwillow"
    },
    {
      "x": 21,
      "y": 28,
      "z": 16,
      "name": "Plant_Leaves_Windwillow"
    },
    {
      "x": 21,
      "y": 25,
      "z": 17,
      "name": "Plant_Leaves_Windwillow"
    },
    {
      "x": 22,
      "y": 22,
      "z": 9,
      "name": "Plant_Leaves_Windwillow"
    },
    {
      "x": 22,
      "y": 23,
      "z": 9,
      "name": "Plant_Leaves_Windwillow"
    },
    {
      "x": 22,
      "y": 22,
      "z": 10,
      "name": "Plant_Leaves_Windwillow"
    },
    {
      "x": 22,
      "y": 23,
      "z": 10,
      "name": "Plant_Leaves_Windwillow"
    },
    {
      "x": 22,
      "y": 26,
      "z": 12,
      "name": "Plant_Leaves_Windwillow"
    },
    {
      "x": 22,
      "y": 27,
      "z": 12,
      "name": "Plant_Leaves_Windwillow"
    },
    {
      "x": 22,
      "y": 26,
      "z": 13,
      "name": "Plant_Leaves_Windwillow"
    },
    {
      "x": 22,
      "y": 27,
      "z": 13,
      "name": "Plant_Leaves_Windwillow"
    },
    {
      "x": 22,
      "y": 28,
      "z": 13,
      "name": "Plant_Leaves_Windwillow"
    },
    {
      "x": 22,
      "y": 28,
      "z": 14,
      "name": "Plant_Leaves_Windwillow"
    },
    {
      "x": 22,
      "y": 29,
      "z": 14,
      "name": "Plant_Leaves_Windwillow"
    },
    {
      "x": 22,
      "y": 25,
      "z": 15,
      "name": "Plant_Leaves_Windwillow"
    },
    {
      "x": 22,
      "y": 26,
      "z": 15,
      "name": "Plant_Leaves_Windwillow"
    },
    {
      "x": 22,
      "y": 27,
      "z": 15,
      "name": "Plant_Leaves_Windwillow"
    },
    {
      "x": 22,
      "y": 28,
      "z": 15,
      "name": "Plant_Leaves_Windwillow"
    },
    {
      "x": 22,
      "y": 25,
      "z": 16,
      "name": "Plant_Leaves_Windwillow"
    },
    {
      "x": 22,
      "y": 26,
      "z": 16,
      "name": "Plant_Leaves_Windwillow"
    },
    {
      "x": 23,
      "y": 26,
      "z": 12,
      "name": "Plant_Leaves_Windwillow"
    },
    {
      "x": 23,
      "y": 25,
      "z": 13,
      "name": "Plant_Leaves_Windwillow"
    },
    {
      "x": 23,
      "y": 26,
      "z": 13,
      "name": "Plant_Leaves_Windwillow"
    },
    {
      "x": 23,
      "y": 27,
      "z": 13,
      "name": "Plant_Leaves_Windwillow"
    },
    {
      "x": 23,
      "y": 26,
      "z": 14,
      "name": "Plant_Leaves_Windwillow"
    },
    {
      "x": 23,
      "y": 27,
      "z": 14,
      "name": "Plant_Leaves_Windwillow"
    },
    {
      "x": 23,
