{
  "version": 8,
  "blockIdVersion": 8,
  "anchorX": -3,
  "anchorY": 9,
  "anchorZ": 0,
  "blocks": [
    {
      "x": -10,
      "y": 8,
      "z": -2,
      "name": "Rock_Basalt"
    },
    {
      "x": -10,
      "y": 9,
      "z": -2,
      "name": "Rock_Basalt"
    },
    {
      "x": -10,
      "y": 10,
      "z": -2,
      "name": "Rock_Basalt"
    },
    {
      "x": -10,
      "y": 11,
      "z": -2,
      "name": "Rock_Basalt"
    },
    {
      "x": -10,
      "y": 8,
      "z": -1,
      "name": "Rock_Basalt"
    },
    {
      "x": -10,
      "y": 9,
      "z": -1,
      "name": "Rock_Basalt"
    },
    {
      "x": -10,
      "y": 10,
      "z": -1,
      "name": "Rock_Basalt"
    },
    {
      "x": -10,
      "y": 11,
      "z": -1,
      "name": "Rock_Basalt"
    },
    {
      "x": -10,
      "y": 12,
      "z": -1,
      "name": "Rock_Basalt"
    },
    {
      "x": -10,
      "y": 13,
      "z": -1,
      "name": "Soil_Needles"
    },
    {
      "x": -10,
      "y": 9,
      "z": 0,
      "name": "Rock_Basalt"
    },
    {
      "x": -10,
      "y": 10,
      "z": 0,
      "name": "Rock_Basalt"
    },
    {
      "x": -9,
      "y": 9,
      "z": -3,
      "name": "Rock_Basalt"
    },
    {
      "x": -9,
      "y": 10,
      "z": -3,
      "name": "Rock_Basalt"
    },
    {
      "x": -9,
      "y": 11,
      "z": -3,
      "name": "Rock_Basalt"
    },
    {
      "x": -9,
      "y": 12,
      "z": -3,
      "name": "Rock_Basalt"
    },
    {
      "x": -9,
      "y": 8,
      "z": -2,
      "name": "Rock_Basalt"
    },
    {
      "x": -9,
      "y": 9,
      "z": -2,
      "name": "Rock_Basalt"
    },
    {
      "x": -9,
      "y": 10,
      "z": -2,
      "name": "Rock_Basalt"
    },
    {
      "x": -9,
      "y": 11,
      "z": -2,
      "name": "Rock_Basalt"
    },
    {
      "x": -9,
      "y": 12,
      "z": -2,
      "name": "Rock_Basalt"
    },
    {
      "x": -9,
      "y": 13,
      "z": -2,
      "name": "Soil_Needles"
    },
    {
      "x": -9,
      "y": 14,
      "z": -2,
      "name": "Soil_Needles"
    },
    {
      "x": -9,
      "y": 15,
      "z": -2,
      "name": "Plant_Moss_Rug_Lime"
    },
    {
      "x": -9,
      "y": 8,
      "z": -1,
      "name": "Rock_Basalt"
    },
    {
      "x": -9,
      "y": 9,
      "z": -1,
      "name": "Rock_Basalt"
    },
    {
      "x": -9,
      "y": 10,
      "z": -1,
      "name": "Rock_Basalt"
    },
    {
      "x": -9,
      "y": 11,
      "z": -1,
      "name": "Rock_Basalt"
    },
    {
      "x": -9,
      "y": 12,
      "z": -1,
      "name": "Soil_Needles"
    },
    {
      "x": -9,
      "y": 13,
      "z": -1,
      "name": "Soil_Needles"
    },
    {
      "x": -9,
      "y": 14,
      "z": -1,
      "name": "Soil_Needles"
    },
    {
      "x": -9,
      "y": 6,
      "z": 0,
      "name": "Rock_Basalt"
    },
    {
      "x": -9,
      "y": 7,
      "z": 0,
      "name": "Rock_Basalt"
    },
    {
      "x": -9,
      "y": 8,
      "z": 0,
      "name": "Rock_Basalt"
    },
    {
      "x": -9,
      "y": 9,
      "z": 0,
      "name": "Rock_Basalt"
    },
    {
      "x": -9,
      "y": 10,
      "z": 0,
      "name": "Rock_Basalt"
    },
    {
      "x": -9,
      "y": 11,
      "z": 0,
      "name": "Rock_Basalt"
    },
    {
      "x": -9,
      "y": 12,
      "z": 0,
      "name": "Soil_Grass"
    },
    {
      "x": -9,
      "y": 13,
      "z": 0,
      "name": "Plant_Grass_Sharp_Tall"
    },
    {
      "x": -9,
      "y": 14,
      "z": 0,
      "name": "Plant_Grass_Sharp_Tall",
      "filler": 1024
    },
    {
      "x": -9,
      "y": 8,
      "z": 1,
      "name": "Rock_Basalt"
    },
    {
      "x": -9,
      "y": 9,
      "z": 1,
      "name": "Rock_Basalt"
    },
    {
      "x": -9,
      "y": 10,
      "z": 1,
      "name": "Rock_Basalt"
    },
    {
      "x": -9,
      "y": 11,
      "z": 1,
      "name": "Rock_Basalt"
    },
    {
      "x": -8,
      "y": 8,
      "z": -3,
      "name": "Rock_Basalt"
    },
    {
      "x": -8,
      "y": 9,
      "z": -3,
      "name": "Rock_Basalt"
    },
    {
      "x": -8,
      "y": 11,
      "z": -3,
      "name": "Rock_Basalt"
    },
    {
      "x": -8,
      "y": 12,
      "z": -3,
      "name": "Rock_Basalt"
    },
    {
      "x": -8,
      "y": 13,
      "z": -3,
      "name": "Soil_Grass"
    },
    {
      "x": -8,
      "y": 14,
      "z": -3,
      "name": "Plant_Grass_Sharp_Tall"
    },
    {
      "x": -8,
      "y": 15,
      "z": -3,
      "name": "Plant_Grass_Sharp_Tall",
      "filler": 1024
    },
    {
      "x": -8,
      "y": 8,
      "z": -2,
      "name": "Rock_Basalt"
    },
    {
      "x": -8,
      "y": 9,
      "z": -2,
      "name": "Rock_Basalt"
    },
    {
      "x": -8,
      "y": 10,
      "z": -2,
      "name": "Rock_Basalt"
    },
    {
      "x": -8,
      "y": 11,
      "z": -2,
      "name": "Rock_Basalt"
    },
    {
      "x": -8,
      "y": 12,
      "z": -2,
      "name": "Rock_Basalt"
    },
    {
      "x": -8,
      "y": 13,
      "z": -2,
      "name": "Soil_Needles"
    },
    {
      "x": -8,
      "y": 14,
      "z": -2,
      "name": "Soil_Needles"
    },
    {
      "x": -8,
      "y": 6,
      "z": -1,
      "name": "Rock_Basalt"
    },
    {
      "x": -8,
      "y": 7,
      "z": -1,
      "name": "Rock_Basalt"
    },
    {
      "x": -8,
      "y": 8,
      "z": -1,
      "name": "Rock_Basalt"
    },
    {
      "x": -8,
      "y": 9,
      "z": -1,
      "name": "Rock_Basalt"
    },
    {
      "x": -8,
      "y": 10,
      "z": -1,
      "name": "Rock_Basalt"
    },
    {
      "x": -8,
      "y": 11,
      "z": -1,
      "name": "Rock_Basalt"
    },
    {
      "x": -8,
      "y": 12,
      "z": -1,
      "name": "Soil_Dirt"
    },
    {
      "x": -8,
      "y": 13,
      "z": -1,
      "name": "Soil_Needles"
    },
    {
      "x": -8,
      "y": 14,
      "z": -1,
      "name": "Soil_Needles"
    },
    {
      "x": -8,
      "y": 15,
      "z": -1,
      "name": "Soil_Needles"
    },
    {
      "x": -8,
      "y": 5,
      "z": 0,
      "name": "Rock_Basalt"
    },
    {
      "x": -8,
      "y": 6,
      "z": 0,
      "name": "Rock_Basalt"
    },
    {
      "x": -8,
      "y": 7,
      "z": 0,
      "name": "Rock_Basalt"
    },
    {
      "x": -8,
      "y": 8,
      "z": 0,
      "name": "Rock_Basalt"
    },
    {
      "x": -8,
      "y": 9,
      "z": 0,
      "name": "Rock_Basalt"
    },
    {
      "x": -8,
      "y": 10,
      "z": 0,
      "name": "Rock_Basalt"
    },
    {
      "x": -8,
      "y": 11,
      "z": 0,
      "name": "Rock_Basalt"
    },
    {
      "x": -8,
      "y": 12,
      "z": 0,
      "name": "Soil_Dirt"
    },
    {
      "x": -8,
      "y": 13,
      "z": 0,
      "name": "Soil_Needles"
    },
    {
      "x": -8,
      "y": 14,
      "z": 0,
      "name": "Soil_Needles"
    },
    {
      "x": -8,
      "y": 15,
      "z": 0,
      "name": "Soil_Needles"
    },
    {
      "x": -8,
      "y": 16,
      "z": 0,
      "name": "Plant_Moss_Rug_Lime"
    },
    {
      "x": -8,
      "y": 5,
      "z": 1,
      "name": "Rock_Basalt"
    },
    {
      "x": -8,
      "y": 6,
      "z": 1,
      "name": "Rock_Basalt"
    },
    {
      "x": -8,
      "y": 7,
      "z": 1,
      "name": "Rock_Basalt"
    },
    {
      "x": -8,
      "y": 8,
      "z": 1,
      "name": "Rock_Basalt"
    },
    {
      "x": -8,
      "y": 9,
      "z": 1,
      "name": "Rock_Basalt"
    },
    {
      "x": -8,
      "y": 10,
      "z": 1,
      "name": "Rock_Basalt"
    },
    {
      "x": -8,
      "y": 11,
      "z": 1,
      "name": "Rock_Basalt"
    },
    {
      "x": -8,
      "y": 12,
      "z": 1,
      "name": "Rock_Basalt"
    },
    {
      "x": -8,
      "y": 13,
      "z": 1,
      "name": "Soil_Dirt"
    },
    {
      "x": -8,
      "y": 14,
      "z": 1,
      "name": "Soil_Dirt"
    },
    {
      "x": -8,
      "y": 15,
      "z": 1,
      "name": "Soil_Needles"
    },
    {
      "x": -7,
      "y": 8,
      "z": -3,
      "name": "Rock_Basalt"
    },
    {
      "x": -7,
      "y": 7,
      "z": -2,
      "name": "Rock_Basalt"
    },
    {
      "x": -7,
      "y": 8,
      "z": -2,
      "name": "Rock_Basalt"
    },
    {
      "x": -7,
      "y": 12,
      "z": -2,
      "name": "Rock_Basalt"
    },
    {
      "x": -7,
      "y": 13,
      "z": -2,
      "name": "Soil_Dirt"
    },
    {
      "x": -7,
      "y": 14,
      "z": -2,
      "name": "Soil_Needles"
    },
    {
      "x": -7,
      "y": 15,
      "z": -2,
      "name": "Soil_Needles"
    },
    {
      "x": -7,
      "y": 16,
      "z": -2,
      "name": "Soil_Needles"
    },
    {
      "x": -7,
      "y": 17,
      "z": -2,
      "name": "Plant_Moss_Rug_Lime"
    },
    {
      "x": -7,
      "y": 6,
      "z": -1,
      "name": "Rock_Basalt"
    },
    {
      "x": -7,
      "y": 7,
      "z": -1,
      "name": "Rock_Basalt"
    },
    {
      "x": -7,
      "y": 8,
      "z": -1,
      "name": "Rock_Basalt"
    },
    {
      "x": -7,
      "y": 9,
      "z": -1,
      "name": "Rock_Basalt"
    },
    {
      "x": -7,
      "y": 10,
      "z": -1,
      "name": "Rock_Basalt"
    },
    {
      "x": -7,
      "y": 12,
      "z": -1,
      "name": "Rock_Basalt"
    },
    {
      "x": -7,
      "y": 13,
      "z": -1,
      "name": "Soil_Dirt"
    },
    {
      "x": -7,
      "y": 14,
      "z": -1,
      "name": "Soil_Needles"
    },
    {
      "x": -7,
      "y": 15,
      "z": -1,
      "name": "Soil_Needles"
    },
    {
      "x": -7,
      "y": 16,
      "z": -1,
      "name": "Soil_Needles"
    },
    {
      "x": -7,
      "y": 17,
      "z": -1,
      "name": "Plant_Moss_Rug_Lime"
    },
    {
      "x": -7,
      "y": 4,
      "z": 0,
      "name": "Rock_Basalt"
    },
    {
      "x": -7,
      "y": 5,
      "z": 0,
      "name": "Rock_Basalt"
    },
    {
      "x": -7,
      "y": 6,
      "z": 0,
      "name": "Rock_Basalt"
    },
    {
      "x": -7,
      "y": 7,
      "z": 0,
      "name": "Rock_Basalt"
    },
    {
      "x": -7,
      "y": 8,
      "z": 0,
      "name": "Rock_Basalt"
    },
    {
      "x": -7,
      "y": 9,
      "z": 0,
      "name": "Rock_Basalt"
    },
    {
      "x": -7,
      "y": 10,
      "z": 0,
      "name": "Rock_Basalt"
    },
    {
      "x": -7,
      "y": 11,
      "z": 0,
      "name": "Rock_Basalt"
    },
    {
      "x": -7,
      "y": 12,
      "z": 0,
      "name": "Rock_Basalt"
    },
    {
      "x": -7,
      "y": 13,
      "z": 0,
      "name": "Soil_Dirt"
    },
    {
      "x": -7,
      "y": 14,
      "z": 0,
      "name": "Soil_Needles"
    },
    {
      "x": -7,
      "y": 15,
      "z": 0,
      "name": "Soil_Needles"
    },
    {
      "x": -7,
      "y": 16,
      "z": 0,
      "name": "Soil_Needles"
    },
    {
      "x": -7,
      "y": 17,
      "z": 0,
      "name": "Plant_Moss_Rug_Lime"
    },
    {
      "x": -7,
      "y": 5,
      "z": 1,
      "name": "Rock_Basalt"
    },
    {
      "x": -7,
      "y": 6,
      "z": 1,
      "name": "Rock_Basalt"
    },
    {
      "x": -7,
      "y": 7,
      "z": 1,
      "name": "Rock_Basalt"
    },
    {
      "x": -7,
      "y": 8,
      "z": 1,
      "name": "Rock_Basalt"
    },
    {
      "x": -7,
      "y": 12,
      "z": 1,
      "name": "Rock_Basalt"
    },
    {
      "x": -7,
      "y": 13,
      "z": 1,
      "name": "Soil_Dirt"
    },
    {
      "x": -7,
      "y": 14,
      "z": 1,
      "name": "Soil_Dirt"
    },
    {
      "x": -7,
      "y": 15,
      "z": 1,
      "name": "Soil_Grass"
    },
    {
      "x": -7,
      "y": 6,
      "z": 2,
      "name": "Rock_Basalt"
    },
    {
      "x": -7,
      "y": 7,
      "z": 2,
      "name": "Rock_Basalt"
    },
    {
      "x": -7,
      "y": 14,
      "z": 2,
      "name": "Soil_Dirt"
    },
    {
      "x": -7,
      "y": 15,
      "z": 2,
      "name": "Soil_Grass"
    },
    {
      "x": -7,
      "y": 16,
      "z": 2,
      "name": "Plant_Grass_Sharp_Tall"
    },
    {
      "x": -7,
      "y": 17,
      "z": 2,
      "name": "Plant_Grass_Sharp_Tall",
      "filler": 1024
    },
    {
      "x": -6,
      "y": 6,
      "z": -2,
      "name": "Rock_Basalt"
    },
    {
      "x": -6,
      "y": 7,
      "z": -2,
      "name": "Rock_Basalt"
    },
    {
      "x": -6,
      "y": 8,
      "z": -2,
      "name": "Rock_Basalt"
    },
    {
      "x": -6,
      "y": 15,
      "z": -2,
      "name": "Soil_Needles"
    },
    {
      "x": -6,
      "y": 16,
      "z": -2,
      "name": "Soil_Needles"
    },
    {
      "x": -6,
      "y": 5,
      "z": -1,
      "name": "Rock_Basalt"
    },
    {
      "x": -6,
      "y": 6,
      "z": -1,
      "name": "Rock_Basalt"
    },
    {
      "x": -6,
      "y": 7,
      "z": -1,
      "name": "Rock_Basalt"
    },
    {
      "x": -6,
      "y": 8,
      "z": -1,
      "name": "Rock_Basalt"
    },
    {
      "x": -6,
      "y": 13,
      "z": -1,
      "name": "Soil_Dirt"
    },
    {
      "x": -6,
      "y": 14,
      "z": -1,
      "name": "Soil_Dirt"
    },
    {
      "x": -6,
      "y": 15,
      "z": -1,
      "name": "Soil_Needles"
    },
    {
      "x": -6,
      "y": 16,
      "z": -1,
      "name": "Soil_Needles"
    },
    {
      "x": -6,
      "y": 17,
      "z": -1,
      "name": "Soil_Needles"
    },
    {
      "x": -6,
      "y": 18,
      "z": -1,
      "name": "Plant_Moss_Rug_Lime"
    },
    {
      "x": -6,
      "y": 5,
      "z": 0,
      "name": "Rock_Basalt"
    },
    {
      "x": -6,
      "y": 6,
      "z": 0,
      "name": "Rock_Basalt"
    },
    {
      "x": -6,
      "y": 7,
      "z": 0,
      "name": "Rock_Basalt"
    },
    {
      "x": -6,
      "y": 8,
      "z": 0,
      "name": "Rock_Basalt"
    },
    {
      "x": -6,
      "y": 13,
      "z": 0,
      "name": "Soil_Dirt"
    },
    {
      "x": -6,
      "y": 14,
      "z": 0,
      "name": "Soil_Dirt"
    },
    {
      "x": -6,
      "y": 15,
      "z": 0,
      "name": "Soil_Dirt"
    },
    {
      "x": -6,
      "y": 16,
      "z": 0,
      "name": "Soil_Dirt"
    },
    {
      "x": -6,
      "y": 17,
      "z": 0,
      "name": "Soil_Grass"
    },
    {
      "x": -6,
      "y": 18,
      "z": 0,
      "name": "Plant_Grass_Sharp_Tall"
    },
    {
      "x": -6,
      "y": 19,
      "z": 0,
      "name": "Plant_Grass_Sharp_Tall",
      "filler": 1024
    },
    {
      "x": -6,
      "y": 5,
      "z": 1,
      "name": "Rock_Basalt"
    },
    {
      "x": -6,
      "y": 6,
      "z": 1,
      "name": "Rock_Basalt"
    },
    {
      "x": -6,
      "y": 7,
      "z": 1,
      "name": "Rock_Basalt"
    },
    {
      "x": -6,
      "y": 15,
      "z": 1,
      "name": "Soil_Dirt"
    },
    {
      "x": -6,
      "y": 16,
      "z": 1,
      "name": "Soil_Dirt"
    },
    {
      "x": -6,
      "y": 17,
      "z": 1,
      "name": "Soil_Grass"
    },
    {
      "x": -6,
      "y": 6,
      "z": 2,
      "name": "Rock_Basalt"
    },
    {
      "x": -6,
      "y": 7,
      "z": 2,
      "name": "Rock_Basalt"
    },
    {
      "x": -6,
      "y": 15,
      "z": 2,
      "name": "Soil_Dirt"
    },
    {
      "x": -6,
      "y": 16,
      "z": 2,
      "name": "Soil_Dirt"
    },
    {
      "x": -6,
      "y": 17,
      "z": 2,
      "name": "Soil_Grass"
    },
    {
      "x": -5,
      "y": 16,
      "z": -2,
      "name": "Soil_Needles"
    },
    {
      "x": -5,
      "y": 17,
      "z": -2,
      "name": "Soil_Grass"
    },
    {
      "x": -5,
      "y": 5,
      "z": -1,
      "name": "Rock_Basalt"
    },
    {
      "x": -5,
      "y": 6,
      "z": -1,
      "name": "Rock_Basalt"
    },
    {
      "x": -5,
      "y": 14,
      "z": -1,
      "name": "Rock_Basalt"
    },
    {
      "x": -5,
      "y": 15,
      "z": -1,
      "name": "Soil_Dirt"
    },
    {
      "x": -5,
      "y": 16,
      "z": -1,
      "name": "Soil_Dirt"
    },
    {
      "x": -5,
      "y": 17,
      "z": -1,
      "name": "Soil_Grass"
    },
    {
      "x": -5,
      "y": 4,
      "z": 0,
      "name": "Rock_Basalt"
    },
    {
      "x": -5,
      "y": 5,
      "z": 0,
      "name": "Rock_Basalt"
    },
    {
      "x": -5,
      "y": 6,
      "z": 0,
      "name": "Rock_Basalt"
    },
    {
      "x": -5,
      "y": 7,
      "z": 0,
      "name": "Rock_Basalt"
    },
    {
      "x": -5,
      "y": 14,
      "z": 0,
      "name": "Rock_Basalt"
    },
    {
      "x": -5,
      "y": 15,
      "z": 0,
      "name": "Soil_Dirt"
    },
    {
      "x": -5,
      "y": 16,
      "z": 0,
      "name": "Soil_Dirt"
    },
    {
      "x": -5,
      "y": 17,
      "z": 0,
      "name": "Soil_Dirt"
    },
    {
      "x": -5,
      "y": 18,
      "z": 0,
      "name": "Soil_Grass"
    },
    {
      "x": -5,
      "y": 4,
      "z": 1,
      "name": "Rock_Basalt"
    },
    {
      "x": -5,
      "y": 5,
      "z": 1,
      "name": "Rock_Basalt"
    },
    {
      "x": -5,
      "y": 6,
      "z": 1,
      "name": "Rock_Basalt"
    },
    {
      "x": -5,
      "y": 15,
      "z": 1,
      "name": "Rock_Basalt"
    },
    {
      "x": -5,
      "y": 16,
      "z": 1,
      "name": "Soil_Dirt"
    },
    {
      "x": -5,
      "y": 17,
      "z": 1,
      "name": "Soil_Grass"
    },
    {
      "x": -5,
      "y": 18,
      "z": 1,
      "name": "Plant_Grass_Sharp_Tall"
    },
    {
      "x": -5,
      "y": 19,
      "z": 1,
      "name": "Plant_Grass_Sharp_Tall",
      "filler": 1024
    },
    {
      "x": -5,
      "y": 5,
      "z": 2,
      "name": "Rock_Basalt"
    },
    {
      "x": -5,
      "y": 6,
      "z": 2,
      "name": "Rock_Basalt"
    },
    {
      "x": -5,
      "y": 16,
      "z": 2,
      "name": "Soil_Dirt"
    },
    {
      "x": -5,
      "y": 17,
      "z": 2,
      "name": "Soil_Grass"
    },
    {
      "x": -4,
      "y": 16,
      "z": -2,
      "name": "Soil_Dirt"
    },
    {
      "x": -4,
      "y": 17,
      "z": -2,
      "name": "Soil_Grass"
    },
    {
      "x": -4,
      "y": 18,
      "z": -2,
      "name": "Plant_Grass_Sharp_Tall"
    },
    {
      "x": -4,
      "y": 19,
      "z": -2,
      "name": "Plant_Grass_Sharp_Tall",
      "filler": 1024
    },
    {
      "x": -4,
      "y": 5,
      "z": -1,
      "name": "Rock_Basalt"
    },
    {
      "x": -4,
      "y": 6,
      "z": -1,
      "name": "Rock_Basalt"
    },
    {
      "x": -4,
      "y": 15,
      "z": -1,
      "name": "Rock_Basalt"
    },
    {
      "x": -4,
      "y": 16,
      "z": -1,
      "name": "Soil_Dirt"
    },
    {
      "x": -4,
      "y": 17,
      "z": -1,
      "name": "Soil_Dirt"
    },
    {
      "x": -4,
      "y": 18,
      "z": -1,
      "name": "Soil_Grass"
    },
    {
      "x": -4,
      "y": 19,
      "z": -1,
      "name": "Plant_Grass_Sharp_Tall"
    },
    {
      "x": -4,
      "y": 20,
      "z": -1,
      "name": "Plant_Grass_Sharp_Tall",
      "filler": 1024
    },
    {
      "x": -4,
      "y": 27,
      "z": -1,
      "name": "Plant_Leaves_Redwood"
    },
    {
      "x": -4,
      "y": 4,
      "z": 0,
      "name": "Rock_Basalt"
    },
    {
      "x": -4,
      "y": 5,
      "z": 0,
      "name": "Rock_Basalt"
    },
    {
      "x": -4,
      "y": 6,
      "z": 0,
      "name": "Rock_Basalt"
    },
    {
      "x": -4,
      "y": 15,
      "z": 0,
      "name": "Rock_Basalt"
    },
    {
      "x": -4,
      "y": 16,
      "z": 0,
      "name": "Soil_Dirt"
    },
    {
      "x": -4,
      "y": 17,
      "z": 0,
      "name": "Soil_Dirt"
    },
    {
      "x": -4,
      "y": 18,
      "z": 0,
      "name": "Soil_Dirt"
    },
    {
      "x": -4,
      "y": 19,
      "z": 0,
      "name": "Soil_Grass"
    },
    {
      "x": -4,
      "y": 4,
      "z": 1,
      "name": "Rock_Basalt"
    },
    {
      "x": -4,
      "y": 5,
      "z": 1,
      "name": "Rock_Basalt"
    },
    {
      "x": -4,
      "y": 6,
      "z": 1,
      "name": "Rock_Basalt"
    },
    {
      "x": -4,
      "y": 16,
      "z": 1,
      "name": "Soil_Dirt"
    },
    {
      "x": -4,
      "y": 17,
      "z": 1,
      "name": "Soil_Dirt"
    },
    {
      "x": -4,
      "y": 18,
      "z": 1,
      "name": "Soil_Dirt"
    },
    {
      "x": -4,
      "y": 19,
      "z": 1,
      "name": "Soil_Grass"
    },
    {
      "x": -4,
      "y": 20,
      "z": 1,
      "name": "Plant_Grass_Sharp_Tall"
    },
    {
      "x": -4,
      "y": 21,
      "z": 1,
      "name": "Plant_Grass_Sharp_Tall",
      "filler": 1024
    },
    {
      "x": -4,
      "y": 5,
      "z": 2,
      "name": "Rock_Basalt"
    },
    {
      "x": -4,
      "y": 6,
      "z": 2,
      "name": "Rock_Basalt"
    },
    {
      "x": -4,
      "y": 17,
      "z": 2,
      "name": "Soil_Grass"
    },
    {
      "x": -4,
      "y": 18,
      "z": 2,
      "name": "Plant_Grass_Sharp_Tall"
    },
    {
      "x": -4,
      "y": 19,
      "z": 2,
      "name": "Plant_Grass_Sharp_Tall",
      "filler": 1024
    },
    {
      "x": -3,
      "y": 17,
      "z": -2,
      "name": "Soil_Dirt"
    },
    {
      "x": -3,
      "y": 18,
      "z": -2,
      "name": "Soil_Grass"
    },
    {
      "x": -3,
      "y": 6,
      "z": -1,
      "name": "Rock_Basalt"
    },
    {
      "x": -3,
      "y": 16,
      "z": -1,
      "name": "Soil_Dirt"
    },
    {
      "x": -3,
      "y": 17,
      "z": -1,
      "name": "Soil_Dirt"
    },
    {
      "x": -3,
      "y": 18,
      "z": -1,
      "name": "Soil_Grass"
    },
    {
      "x": -3,
      "y": 26,
      "z": -1,
      "name": "Plant_Leaves_Redwood"
    },
    {
      "x": -3,
      "y": 27,
      "z": -1,
      "name": "Plant_Leaves_Redwood"
    },
    {
      "x": -3,
      "y": 31,
      "z": -1,
      "name": "Plant_Leaves_Redwood"
    },
    {
      "x": -3,
      "y": 4,
      "z": 0,
      "name": "Rock_Basalt"
    },
    {
      "x": -3,
      "y": 5,
      "z": 0,
      "name": "Rock_Basalt"
    },
    {
      "x": -3,
      "y": 6,
      "z": 0,
      "name": "Rock_Basalt"
    },
    {
      "x": -3,
      "y": 16,
      "z": 0,
      "name": "Soil_Dirt"
    },
    {
      "x": -3,
      "y": 17,
      "z": 0,
      "name": "Soil_Dirt"
    },
    {
      "x": -3,
      "y": 18,
      "z": 0,
      "name": "Soil_Dirt"
    },
    {
      "x": -3,
      "y": 19,
      "z": 0,
      "name": "Soil_Grass"
    },
    {
      "x": -3,
      "y": 20,
      "z": 0,
      "name": "Plant_Grass_Sharp_Tall"
    },
    {
      "x": -3,
      "y": 21,
      "z": 0,
      "name": "Plant_Grass_Sharp_Tall",
      "filler": 1024
    },
    {
      "x": -3,
      "y": 4,
      "z": 1,
      "name": "Rock_Basalt"
    },
    {
      "x": -3,
      "y": 5,
      "z": 1,
      "name": "Rock_Basalt"
    },
    {
      "x": -3,
      "y": 6,
      "z": 1,
      "name": "Rock_Basalt"
    },
    {
      "x": -3,
      "y": 16,
      "z": 1,
      "name": "Soil_Dirt"
    },
    {
      "x": -3,
      "y": 17,
      "z": 1,
      "name": "Soil_Dirt"
    },
    {
      "x": -3,
      "y": 18,
      "z": 1,
      "name": "Soil_Dirt"
    },
    {
      "x": -3,
      "y": 19,
      "z": 1,
      "name": "Soil_Grass"
    },
    {
      "x": -3,
      "y": 20,
      "z": 1,
      "name": "Plant_Moss_Rug_Lime"
    },
    {
      "x": -3,
      "y": 4,
      "z": 2,
      "name": "Rock_Basalt"
    },
    {
      "x": -3,
      "y": 5,
      "z": 2,
      "name": "Rock_Basalt"
    },
    {
      "x": -3,
      "y": 18,
      "z": 2,
      "name": "Soil_Grass"
    },
    {
      "x": -2,
      "y": 26,
      "z": -2,
      "name": "Plant_Leaves_Redwood"
    },
    {
      "x": -2,
      "y": 31,
      "z": -2,
      "name": "Plant_Leaves_Redwood"
    },
    {
      "x": -2,
      "y": 5,
      "z": -1,
      "name": "Rock_Basalt"
    },
    {
      "x": -2,
      "y": 6,
      "z": -1,
      "name": "Rock_Basalt"
    },
    {
      "x": -2,
      "y": 16,
      "z": -1,
      "name": "Soil_Dirt"
    },
    {
      "x": -2,
      "y": 17,
      "z": -1,
      "name": "Soil_Dirt"
    },
    {
      "x": -2,
      "y": 18,
      "z": -1,
      "name": "Soil_Grass"
    },
    {
      "x": -2,
      "y": 19,
      "z": -1,
      "name": "Plant_Grass_Sharp_Tall"
    },
    {
      "x": -2,
      "y": 20,
      "z": -1,
      "name": "Plant_Grass_Sharp_Tall",
      "filler": 1024
    },
    {
      "x": -2,
      "y": 26,
      "z": -1,
      "name": "Plant_Leaves_Redwood"
    },
    {
      "x": -2,
      "y": 31,
      "z": -1,
      "name": "Plant_Leaves_Redwood"
    },
    {
      "x": -2,
      "y": 36,
      "z": -1,
      "name": "Plant_Leaves_Redwood"
    },
    {
      "x": -2,
      "y": 4,
      "z": 0,
      "name": "Rock_Basalt"
    },
    {
      "x": -2,
      "y": 5,
      "z": 0,
      "name": "Rock_Basalt"
    },
    {
      "x": -2,
      "y": 6,
      "z": 0,
      "name": "Rock_Basalt"
    },
    {
      "x": -2,
      "y": 16,
      "z": 0,
      "name": "Soil_Dirt"
    },
    {
      "x": -2,
      "y": 17,
      "z": 0,
      "name": "Soil_Dirt"
    },
    {
      "x": -2,
      "y": 18,
      "z": 0,
      "name": "Soil_Dirt"
    },
    {
      "x": -2,
      "y": 19,
      "z": 0,
      "name": "Soil_Grass"
    },
    {
      "x": -2,
      "y": 26,
      "z": 0,
      "name": "Plant_Leaves_Redwood"
    },
    {
      "x": -2,
      "y": 31,
      "z": 0,
      "name": "Plant_Leaves_Redwood"
    },
    {
      "x": -2,
      "y": 4,
      "z": 1,
      "name": "Rock_Basalt"
    },
    {
      "x": -2,
      "y": 5,
      "z": 1,
      "name": "Rock_Basalt"
    },
    {
      "x": -2,
      "y": 6,
      "z": 1,
      "name": "Rock_Basalt"
    },
    {
      "x": -2,
      "y": 17,
      "z": 1,
      "name": "Soil_Dirt"
    },
    {
      "x": -2,
      "y": 18,
      "z": 1,
      "name": "Soil_Dirt"
    },
    {
      "x": -2,
      "y": 19,
      "z": 1,
      "name": "Soil_Grass"
    },
    {
      "x": -2,
      "y": 20,
      "z": 1,
      "name": "Plant_Grass_Sharp_Tall"
    },
    {
      "x": -2,
      "y": 21,
      "z": 1,
      "name": "Plant_Grass_Sharp_Tall",
      "filler": 1024
    },
    {
      "x": -2,
      "y": 4,
      "z": 2,
      "name": "Rock_Basalt"
    },
    {
      "x": -2,
      "y": 5,
      "z": 2,
      "name": "Rock_Basalt"
    },
    {
      "x": -2,
      "y": 17,
      "z": 2,
      "name": "Soil_Dirt"
    },
    {
      "x": -2,
      "y": 18,
      "z": 2,
      "name": "Soil_Grass"
    },
    {
      "x": -2,
      "y": 19,
      "z": 2,
      "name": "Plant_Grass_Sharp_Tall"
    },
    {
      "x": -2,
      "y": 20,
      "z": 2,
      "name": "Plant_Grass_Sharp_Tall",
      "filler": 1024
    },
    {
      "x": -1,
      "y": 6,
      "z": -2,
      "name": "Rock_Basalt"
    },
    {
      "x": -1,
      "y": 26,
      "z": -2,
      "name": "Plant_Leaves_Redwood"
    },
    {
      "x": -1,
      "y": 31,
      "z": -2,
      "name": "Plant_Leaves_Redwood"
    },
    {
      "x": -1,
      "y": 5,
      "z": -1,
      "name": "Rock_Basalt"
    },
    {
      "x": -1,
      "y": 6,
      "z": -1,
      "name": "Rock_Basalt"
    },
    {
      "x": -1,
      "y": 14,
      "z": -1,
      "name": "Wood_Redwood_Roots"
    },
    {
      "x": -1,
      "y": 15,
      "z": -1,
      "name": "Wood_Redwood_Trunk"
    },
    {
      "x": -1,
      "y": 16,
      "z": -1,
      "name": "Wood_Redwood_Trunk_Full"
    },
    {
      "x": -1,
      "y": 17,
      "z": -1,
      "name": "Soil_Dirt"
    },
    {
      "x": -1,
      "y": 18,
      "z": -1,
      "name": "Soil_Dirt"
    },
    {
      "x": -1,
      "y": 19,
      "z": -1,
      "name": "Soil_Grass"
    },
    {
      "x": -1,
      "y": 26,
      "z": -1,
      "name": "Wood_Redwood_Branch_Corner",
      "rotation": 3
    },
    {
      "x": -1,
      "y": 31,
      "z": -1,
      "name": "Wood_Redwood_Branch_Corner",
      "rotation": 3
    },
    {
      "x": -1,
      "y": 36,
      "z": -1,
      "name": "Plant_Leaves_Redwood"
    },
    {
      "x": -1,
      "y": 37,
      "z": -1,
      "name": "Plant_Leaves_Redwood"
    },
    {
      "x": -1,
      "y": 5,
      "z": 0,
      "name": "Rock_Basalt"
    },
    {
      "x": -1,
      "y": 6,
      "z": 0,
      "name": "Rock_Basalt"
    },
    {
      "x": -1,
      "y": 16,
      "z": 0,
      "name": "Soil_Dirt"
    },
    {
      "x": -1,
      "y": 17,
      "z": 0,
      "name": "Soil_Dirt"
    },
    {
      "x": -1,
      "y": 18,
      "z": 0,
      "name": "Soil_Dirt"
    },
    {
      "x": -1,
      "y": 19,
      "z": 0,
      "name": "Soil_Grass"
    },
    {
      "x": -1,
      "y": 26,
      "z": 0,
      "name": "Plant_Leaves_Redwood"
    },
    {
      "x": -1,
      "y": 31,
      "z": 0,
      "name": "Plant_Leaves_Redwood"
    },
    {
      "x": -1,
      "y": 36,
      "z": 0,
      "name": "Plant_Leaves_Redwood"
    },
    {
      "x": -1,
      "y": 4,
      "z": 1,
      "name": "Rock_Basalt"
    },
    {
      "x": -1,
      "y": 5,
      "z": 1,
      "name": "Rock_Basalt"
    },
    {
      "x": -1,
      "y": 6,
      "z": 1,
      "name": "Rock_Basalt"
    },
    {
      "x": -1,
      "y": 17,
      "z": 1,
      "name": "Soil_Dirt"
    },
    {
      "x": -1,
      "y": 18,
      "z": 1,
      "name": "Soil_Dirt"
    },
    {
      "x": -1,
      "y": 19,
      "z": 1,
      "name": "Soil_Grass"
    },
    {
      "x": -1,
      "y": 5,
      "z": 2,
      "name": "Rock_Basalt"
    },
    {
      "x": -1,
      "y": 6,
      "z": 2,
      "name": "Rock_Basalt"
    },
    {
      "x": -1,
      "y": 17,
      "z": 2,
      "name": "Soil_Dirt"
    },
    {
      "x": -1,
      "y": 18,
      "z": 2,
      "name": "Soil_Grass"
    },
    {
      "x": 0,
      "y": 27,
      "z": -4,
      "name": "Plant_Leaves_Redwood"
    },
    {
      "x": 0,
      "y": 30,
      "z": -4,
      "name": "Plant_Leaves_Redwood"
    },
    {
      "x": 0,
      "y": 33,
      "z": -4,
      "name": "Plant_Leaves_Redwood"
    },
    {
      "x": 0,
      "y": 24,
      "z": -3,
      "name": "Plant_Leaves_Redwood"
    },
    {
      "x": 0,
      "y": 27,
      "z": -3,
      "name": "Plant_Leaves_Redwood"
    },
    {
      "x": 0,
      "y": 30,
      "z": -3,
      "name": "Plant_Leaves_Redwood"
    },
    {
      "x": 0,
      "y": 33,
      "z": -3,
      "name": "Plant_Leaves_Redwood"
    },
    {
      "x": 0,
      "y": 37,
      "z": -3,
      "name": "Plant_Leaves_Redwood"
    },
    {
      "x": 0,
      "y": 6,
      "z": -2,
      "name": "Rock_Basalt"
    },
    {
      "x": 0,
      "y": 7,
      "z": -2,
      "name": "Rock_Basalt"
    },
    {
      "x": 0,
      "y": 8,
      "z": -2,
      "name": "Rock_Basalt"
    },
    {
      "x": 0,
      "y": 17,
      "z": -2,
      "name": "Soil_Grass"
    },
    {
      "x": 0,
      "y": 18,
      "z": -2,
      "name": "Wood_Redwood_Trunk_Full"
    },
    {
      "x": 0,
      "y": 24,
      "z": -2,
      "name": "Plant_Leaves_Redwood"
    },
    {
      "x": 0,
      "y": 26,
      "z": -2,
      "name": "Plant_Leaves_Redwood"
    },
    {
      "x": 0,
      "y": 27,
      "z": -2,
      "name": "Plant_Leaves_Redwood"
    },
    {
      "x": 0,
      "y": 30,
      "z": -2,
      "name": "Plant_Leaves_Redwood"
    },
    {
      "x": 0,
      "y": 31,
      "z": -2,
      "name": "Plant_Leaves_Redwood"
    },
    {
      "x": 0,
      "y": 33,
      "z": -2,
      "name": "Plant_Leaves_Redwood"
    },
    {
      "x": 0,
      "y": 36,
      "z": -2,
      "name": "Plant_Leaves_Redwood"
    },
    {
      "x": 0,
      "y": 37,
      "z": -2,
      "name": "Plant_Leaves_Redwood"
    },
    {
      "x": 0,
      "y": 5,
      "z": -1,
      "name": "Rock_Basalt"
    },
    {
      "x": 0,
      "y": 6,
      "z": -1,
      "name": "Rock_Basalt"
    },
    {
      "x": 0,
      "y": 7,
      "z": -1,
      "name": "Rock_Basalt"
    },
    {
      "x": 0,
      "y": 8,
      "z": -1,
      "name": "Rock_Basalt"
    },
    {
      "x": 0,
      "y": 14,
      "z": -1,
      "name": "Rock_Basalt"
    },
    {
      "x": 0,
      "y": 15,
      "z": -1,
      "name": "Soil_Dirt"
    },
    {
      "x": 0,
      "y": 16,
      "z": -1,
      "name": "Wood_Redwood_Trunk"
    },
    {
      "x": 0,
      "y": 17,
      "z": -1,
      "name": "Wood_Redwood_Trunk"
    },
    {
      "x": 0,
      "y": 18,
      "z": -1,
      "name": "Wood_Redwood_Trunk"
    },
    {
      "x": 0,
      "y": 19,
      "z": -1,
      "name": "Wood_Redwood_Trunk_Full"
    },
    {
      "x": 0,
      "y": 26,
      "z": -1,
      "name": "Wood_Redwood_Branch_Long",
      "rotation": 5
    },
    {
      "x": 0,
      "y": 27,
      "z": -1,
      "name": "Plant_Leaves_Redwood"
    },
    {
      "x": 0,
      "y": 30,
      "z": -1,
      "name": "Plant_Leaves_Redwood"
    },
    {
      "x": 0,
      "y": 31,
      "z": -1,
      "name": "Wood_Redwood_Branch_Long",
      "rotation": 5
    },
    {
      "x": 0,
      "y": 32,
      "z": -1,
      "name": "Plant_Leaves_Redwood"
    },
    {
      "x": 0,
      "y": 36,
      "z": -1,
      "name": "Wood_Redwood_Branch_Corner",
      "rotation": 3
    },
    {
      "x": 0,
      "y": 38,
      "z": -1,
      "name": "Plant_Leaves_Redwood"
    },
    {
      "x": 0,
      "y": 39,
      "z": -1,
      "name": "Plant_Leaves_Redwood"
    },
    {
      "x": 0,
      "y": 40,
      "z": -1,
      "name": "Plant_Leaves_Redwood"
    },
    {
      "x": 0,
      "y": 5,
      "z": 0,
      "name": "Rock_Basalt"
    },
    {
      "x": 0,
      "y": 6,
      "z": 0,
      "name": "Rock_Basalt"
    },
    {
      "x": 0,
      "y": 7,
      "z": 0,
      "name": "Rock_Basalt"
    },
    {
      "x": 0,
      "y": 15,
      "z": 0,
      "name": "Soil_Dirt"
    },
    {
      "x": 0,
      "y": 16,
      "z": 0,
      "name": "Soil_Dirt"
    },
    {
      "x": 0,
      "y": 17,
      "z": 0,
      "name": "Soil_Dirt"
    },
    {
      "x": 0,
      "y": 18,
      "z": 0,
      "name": "Soil_Dirt"
    },
    {
      "x": 0,
      "y": 19,
      "z": 0,
      "name": "Soil_Grass"
    },
    {
      "x": 0,
      "y": 25,
      "z": 0,
      "name": "Plant_Leaves_Redwood"
    },
    {
      "x": 0,
      "y": 26,
      "z": 0,
      "name": "Plant_Leaves_Redwood"
    },
    {
      "x": 0,
      "y": 28,
      "z": 0,
      "name": "Plant_Leaves_Redwood"
    },
    {
      "x": 0,
      "y": 31,
      "z": 0,
      "name": "Plant_Leaves_Redwood"
    },
    {
      "x": 0,
      "y": 32,
      "z": 0,
      "name": "Plant_Leaves_Redwood"
    },
    {
      "x": 0,
      "y": 35,
      "z": 0,
      "name": "Plant_Leaves_Redwood"
    },
    {
      "x": 0,
      "y": 36,
      "z": 0,
      "name": "Plant_Leaves_Redwood"
    },
    {
      "x": 0,
      "y": 5,
      "z": 1,
      "name": "Rock_Basalt"
    },
    {
      "x": 0,
      "y": 6,
      "z": 1,
      "name": "Rock_Basalt"
    },
    {
      "x": 0,
      "y": 15,
      "z": 1,
      "name": "Soil_Dirt"
    },
    {
      "x": 0,
      "y": 16,
      "z": 1,
      "name": "Soil_Dirt"
    },
    {
      "x": 0,
      "y": 17,
      "z": 1,
      "name": "Soil_Dirt"
    },
    {
      "x": 0,
      "y": 18,
      "z": 1,
      "name": "Soil_Grass"
    },
    {
      "x": 0,
      "y": 25,
      "z": 1,
      "name": "Plant_Leaves_Redwood"
    },
    {
      "x": 0,
      "y": 28,
      "z": 1,
      "name": "Plant_Leaves_Redwood"
    },
    {
      "x": 0,
      "y": 32,
      "z": 1,
      "name": "Plant_Leaves_Redwood"
    },
    {
      "x": 0,
      "y": 35,
      "z": 1,
      "name": "Plant_Leaves_Redwood"
    },
    {
      "x": 0,
      "y": 6,
      "z": 2,
      "name": "Rock_Basalt"
    },
    {
      "x": 0,
      "y": 17,
      "z": 2,
      "name": "Soil_Grass"
    },
    {
      "x": 0,
      "y": 32,
      "z": 2,
      "name": "Plant_Leaves_Redwood"
    },
    {
      "x": 1,
      "y": 25,
      "z": -5,
      "name": "Plant_Leaves_Redwood"
    },
    {
      "x": 1,
      "y": 27,
      "z": -5,
      "name": "Plant_Leaves_Redwood"
    },
    {
      "x": 1,
      "y": 30,
      "z": -5,
      "name": "Plant_Leaves_Redwood"
    },
    {
      "x": 1,
      "y": 33,
      "z": -5,
      "name": "Plant_Leaves_Redwood"
    },
    {
      "x": 1,
      "y": 24,
      "z": -4,
      "name": "Plant_Leaves_Redwood"
    },
    {
      "x": 1,
      "y": 27,
      "z": -4,
      "name": "Plant_Leaves_Redwood"
    },
    {
      "x": 1,
      "y": 30,
      "z": -4,
      "name": "Plant_Leaves_Redwood"
    },
    {
      "x": 1,
      "y": 33,
      "z": -4,
      "name": "Plant_Leaves_Redwood"
    },
    {
      "x": 1,
      "y": 37,
      "z": -4,
      "name": "Plant_Leaves_Redwood"
    },
    {
      "x": 1,
      "y": 7,
      "z": -3,
      "name": "Rock_Basalt"
    },
    {
      "x": 1,
      "y": 15,
      "z": -3,
      "name": "Wood_Redwood_Roots"
    },
    {
      "x": 1,
      "y": 16,
      "z": -3,
      "name": "Wood_Redwood_Trunk"
    },
    {
      "x": 1,
      "y": 17,
      "z": -3,
      "name": "Wood_Redwood_Trunk_Full"
    },
    {
      "x": 1,
      "y": 24,
      "z": -3,
      "name": "Plant_Leaves_Redwood"
    },
    {
      "x": 1,
      "y": 27,
      "z": -3,
      "name": "Wood_Redwood_Branch_Long",
      "rotation": 4
    },
    {
      "x": 1,
      "y": 28,
      "z": -3,
      "name": "Plant_Leaves_Redwood"
    },
    {
      "x": 1,
      "y": 30,
      "z": -3,
      "name": "Plant_Leaves_Redwood"
    },
    {
      "x": 1,
      "y": 33,
      "z": -3,
      "name": "Wood_Redwood_Branch_Corner",
      "rotation": 2
    },
    {
      "x": 1,
      "y": 37,
      "z": -3,
      "name": "Plant_Leaves_Redwood"
    },
    {
      "x": 1,
      "y": 7,
      "z": -2,
      "name": "Rock_Basalt"
    },
    {
      "x": 1,
      "y": 8,
      "z": -2,
      "name": "Rock_Basalt"
    },
    {
      "x": 1,
      "y": 9,
      "z": -2,
      "name": "Rock_Basalt"
    },
    {
      "x": 1,
      "y": 10,
      "z": -2,
      "name": "Rock_Basalt"
    },
    {
      "x": 1,
      "y": 13,
      "z": -2,
      "name": "Rock_Basalt"
    },
    {
      "x": 1,
      "y": 14,
      "z": -2,
      "name": "Rock_Basalt"
    },
    {
      "x": 1,
      "y": 15,
      "z": -2,
      "name": "Soil_Dirt"
    },
    {
      "x": 1,
      "y": 16,
      "z": -2,
      "name": "Wood_Redwood_Roots"
    },
    {
      "x": 1,
      "y": 17,
      "z": -2,
      "name": "Wood_Redwood_Trunk"
    },
    {
      "x": 1,
      "y": 18,
      "z": -2,
      "name": "Wood_Redwood_Trunk"
    },
    {
      "x": 1,
      "y": 19,
      "z": -2,
      "name": "Wood_Redwood_Trunk"
    },
    {
      "x": 1,
      "y": 20,
      "z": -2,
      "name": "Wood_Redwood_Trunk_Full"
    },
    {
      "x": 1,
      "y": 24,
      "z": -2,
      "name": "Wood_Redwood_Branch_Corner",
      "rotation": 2
    },
    {
      "x": 1,
      "y": 27,
      "z": -2,
      "name": "Wood_Redwood_Branch_Long",
      "rotation": 4
    },
    {
      "x": 1,
      "y": 28,
      "z": -2,
      "name": "Plant_Leaves_Redwood"
    },
    {
      "x": 1,
      "y": 30,
      "z": -2,
      "name": "Wood_Redwood_Branch_Long",
      "rotation": 4
    },
    {
      "x": 1,
      "y": 32,
      "z": -2,
      "name": "Plant_Leaves_Redwood"
    },
    {
      "x": 1,
      "y": 33,
      "z": -2,
      "name": "Wood_Redwood_Branch_Long",
      "rotation": 4
    },
    {
      "x": 1,
      "y": 34,
      "z": -2,
      "name": "Plant_Leaves_Redwood"
    },
    {
      "x": 1,
      "y": 37,
      "z": -2,
      "name": "Wood_Redwood_Branch_Corner",
      "rotation": 2
    },
    {
      "x": 1,
      "y": 39,
      "z": -2,
      "name": "Plant_Leaves_Redwood"
    },
    {
      "x": 1,
      "y": 5,
      "z": -1,
      "name": "Rock_Basalt"
    },
    {
      "x": 1,
      "y": 6,
      "z": -1,
      "name": "Rock_Basalt"
    },
    {
      "x": 1,
      "y": 7,
      "z": -1,
      "name": "Rock_Basalt"
    },
    {
      "x": 1,
      "y": 8,
      "z": -1,
      "name": "Rock_Basalt"
    },
    {
      "x": 1,
      "y": 9,
      "z": -1,
      "name": "Rock_Basalt"
    },
    {
      "x": 1,
      "y": 10,
      "z": -1,
      "name": "Rock_Basalt"
    },
    {
      "x": 1,
      "y": 11,
      "z": -1,
      "name": "Rock_Basalt"
    },
    {
      "x": 1,
      "y": 13,
      "z": -1,
      "name": "Rock_Basalt"
    },
    {
      "x": 1,
      "y": 14,
      "z": -1,
      "name": "Rock_Basalt"
    },
    {
      "x": 1,
      "y": 15,
      "z": -1,
      "name": "Soil_Dirt"
    },
    {
      "x": 1,
      "y": 16,
      "z": -1,
      "name": "Soil_Dirt"
    },
    {
      "x": 1,
      "y": 17,
      "z": -1,
      "name": "Soil_Grass"
    },
    {
      "x": 1,
      "y": 18,
      "z": -1,
      "name": "Wood_Redwood_Trunk_Full"
    },
    {
      "x": 1,
      "y": 19,
      "z": -1,
      "name": "Wood_Redwood_Trunk"
    },
    {
      "x": 1,
      "y": 20,
      "z": -1,
      "name": "Wood_Redwood_Trunk"
    },
    {
      "x": 1,
      "y": 21,
      "z": -1,
      "name": "Wood_Redwood_Trunk"
    },
    {
      "x": 1,
      "y": 22,
      "z": -1,
      "name": "Wood_Redwood_Trunk"
    },
    {
      "x": 1,
      "y": 23,
      "z": -1,
      "name": "Wood_Redwood_Trunk"
    },
    {
      "x": 1,
      "y": 24,
      "z": -1,
      "name": "Wood_Redwood_Trunk"
    },
    {
      "x": 1,
      "y": 25,
      "z": -1,
      "name": "Wood_Redwood_Trunk"
    },
    {
      "x": 1,
      "y": 26,
      "z": -1,
      "name": "Wood_Redwood_Trunk"
    },
    {
      "x": 1,
      "y": 27,
      "z": -1,
      "name": "Wood_Redwood_Trunk"
    },
    {
      "x": 1,
      "y": 28,
      "z": -1,
      "name": "Wood_Redwood_Trunk"
    },
    {
      "x": 1,
      "y": 29,
      "z": -1,
      "name": "Wood_Redwood_Trunk"
    },
    {
      "x": 1,
      "y": 30,
      "z": -1,
      "name": "Wood_Redwood_Trunk"
    },
    {
      "x": 1,
      "y": 31,
      "z": -1,
      "name": "Wood_Redwood_Trunk"
    },
    {
      "x": 1,
      "y": 32,
      "z": -1,
      "name": "Wood_Redwood_Trunk"
    },
    {
      "x": 1,
      "y": 33,
      "z": -1,
      "name": "Wood_Redwood_Trunk"
    },
    {
      "x": 1,
      "y": 34,
      "z": -1,
      "name": "Wood_Redwood_Trunk"
    },
    {
      "x": 1,
      "y": 35,
      "z": -1,
      "name": "Wood_Redwood_Trunk"
    },
    {
      "x": 1,
      "y": 36,
      "z": -1,
      "name": "Wood_Redwood_Trunk"
    },
    {
      "x": 1,
      "y": 37,
      "z": -1,
      "name": "Wood_Redwood_Trunk"
    },
    {
      "x": 1,
      "y": 38,
      "z": -1,
      "name": "Wood_Redwood_Trunk"
    },
    {
      "x": 1,
      "y": 39,
      "z": -1,
      "name": "Plant_Leaves_Redwood"
    },
    {
      "x": 1,
      "y": 40,
      "z": -1,
      "name": "Plant_Leaves_Redwood"
    },
    {
      "x": 1,
      "y": 41,
      "z": -1,
      "name": "Plant_Leaves_Redwood"
    },
    {
      "x": 1,
      "y": 42,
      "z": -1,
      "name": "Plant_Leaves_Redwood"
    },
    {
      "x": 1,
      "y": 5,
      "z": 0,
      "name": "Rock_Basalt"
    },
    {
      "x": 1,
      "y": 6,
      "z": 0,
      "name": "Rock_Basalt"
    },
    {
      "x": 1,
      "y": 7,
      "z": 0,
      "name": "Rock_Basalt"
    },
    {
      "x": 1,
      "y": 8,
      "z": 0,
      "name": "Rock_Basalt"
    },
    {
      "x": 1,
      "y": 9,
      "z": 0,
      "name": "Rock_Basalt"
    },
    {
      "x": 1,
      "y": 15,
      "z": 0,
      "name": "Soil_Dirt"
    },
    {
      "x": 1,
      "y": 16,
      "z": 0,
      "name": "Soil_Dirt"
    },
    {
      "x": 1,
      "y": 17,
      "z": 0,
      "name": "Soil_Grass"
    },
    {
      "x": 1,
      "y": 18,
      "z": 0,
      "name": "Wood_Redwood_Trunk_Full"
    },
    {
      "x": 1,
      "y": 25,
      "z": 0,
      "name": "Wood_Redwood_Branch_Corner"
    },
    {
      "x": 1,
      "y": 28,
      "z": 0,
      "name": "Wood_Redwood_Branch_Corner"
    },
    {
      "x": 1,
      "y": 31,
      "z": 0,
      "name": "Plant_Leaves_Redwood"
    },
    {
      "x": 1,
      "y": 32,
      "z": 0,
      "name": "Wood_Redwood_Branch_Long",
      "rotation": 4
    },
    {
      "x": 1,
      "y": 33,
      "z": 0,
      "name": "Plant_Leaves_Redwood"
    },
    {
      "x": 1,
      "y": 35,
      "z": 0,
      "name": "Wood_Redwood_Branch_Corner"
    },
    {
      "x": 1,
      "y": 37,
      "z": 0,
      "name": "Plant_Leaves_Redwood"
    },
    {
      "x": 1,
      "y": 38,
      "z": 0,
      "name": "Plant_Leaves_Redwood"
    },
    {
      "x": 1,
      "y": 39,
      "z": 0,
      "name": "Plant_Leaves_Redwood"
    },
    {
      "x": 1,
      "y": 5,
      "z": 1,
      "name": "Rock_Basalt"
    },
    {
      "x": 1,
      "y": 6,
      "z": 1,
      "name": "Rock_Basalt"
    },
    {
      "x": 1,
      "y": 7,
      "z": 1,
      "name": "Rock_Basalt"
    },
    {
      "x": 1,
      "y": 16,
      "z": 1,
      "name": "Soil_Dirt"
    },
    {
      "x": 1,
      "y": 17,
      "z": 1,
      "name": "Soil_Dirt"
    },
    {
      "x": 1,
      "y": 18,
      "z": 1,
      "name": "Soil_Grass"
    },
    {
      "x": 1,
      "y": 19,
      "z": 1,
      "name": "Plant_Grass_Sharp_Tall"
    },
    {
      "x": 1,
      "y": 20,
      "z": 1,
      "name": "Plant_Grass_Sharp_Tall",
      "filler": 1024
    },
    {
      "x": 1,
      "y": 25,
      "z": 1,
      "name": "Plant_Leaves_Redwood"
    },
    {
      "x": 1,
      "y": 28,
      "z": 1,
      "name": "Plant_Leaves_Redwood"
    },
    {
      "x": 1,
      "y": 32,
      "z": 1,
      "name": "Wood_Redwood_Branch_Long",
      "rotation": 4
    },
    {
      "x": 1,
      "y": 35,
      "z": 1,
      "name": "Plant_Leaves_Redwood"
    },
    {
      "x": 1,
      "y": 6,
      "z": 2,
      "name": "Rock_Basalt"
    },
    {
      "x": 1,
      "y": 7,
      "z": 2,
      "name": "Rock_Basalt"
    },
    {
      "x": 1,
      "y": 25,
      "z": 2,
      "name": "Plant_Leaves_Redwood"
    },
    {
      "x": 1,
      "y": 28,
      "z": 2,
      "name": "Plant_Leaves_Redwood"
    },
    {
      "x": 1,
      "y": 32,
      "z": 2,
      "name": "Plant_Leaves_Redwood"
    },
    {
      "x": 1,
      "y": 35,
      "z": 2,
      "name": "Plant_Leaves_Redwood"
    },
    {
      "x": 1,
      "y": 25,
      "z": 3,
      "name": "Plant_Leaves_Redwood"
    },
    {
      "x": 1,
      "y": 28,
      "z": 3,
      "name": "Plant_Leaves_Redwood"
    },
    {
      "x": 1,
      "y": 29,
      "z": 3,
      "name": "Plant_Leaves_Redwood"
    },
    {
      "x": 1,
      "y": 32,
      "z": 3,
      "name": "Plant_Leaves_Redwood"
    },
    {
      "x": 1,
      "y": 29,
      "z": 4,
      "name": "Plant_Leaves_Redwood"
    },
    {
      "x": 2,
      "y": 27,
      "z": -4,
      "name": "Plant_Leaves_Redwood"
    },
    {
      "x": 2,
      "y": 33,
      "z": -4,
      "name": "Plant_Leaves_Redwood"
    },
    {
      "x": 2,
      "y": 7,
      "z": -3,
      "name": "Rock_Basalt"
    },
    {
      "x": 2,
      "y": 8,
      "z": -3,
      "name": "Rock_Basalt"
    },
    {
      "x": 2,
      "y": 9,
      "z": -3,
      "name": "Rock_Basalt"
    },
    {
      "x": 2,
      "y": 14,
      "z": -3,
      "name": "Rock_Basalt"
    },
    {
      "x": 2,
      "y": 15,
      "z": -3,
      "name": "Soil_Dirt"
    },
    {
      "x": 2,
      "y": 16,
      "z": -3,
      "name": "Soil_Grass"
    },
    {
      "x": 2,
      "y": 17,
      "z": -3,
      "name": "Plant_Grass_Sharp_Tall"
    },
    {
      "x": 2,
      "y": 18,
      "z": -3,
      "name": "Plant_Grass_Sharp_Tall",
      "filler": 1024
    },
    {
      "x": 2,
      "y": 27,
      "z": -3,
      "name": "Plant_Leaves_Redwood"
    },
    {
      "x": 2,
      "y": 30,
      "z": -3,
      "name": "Plant_Leaves_Redwood"
    },
    {
      "x": 2,
      "y": 33,
      "z": -3,
      "name": "Plant_Leaves_Redwood"
    },
    {
      "x": 2,
      "y": 37,
      "z": -3,
      "name": "Plant_Leaves_Redwood"
    },
    {
      "x": 2,
      "y": 7,
      "z": -2,
      "name": "Rock_Basalt"
    },
    {
      "x": 2,
      "y": 8,
      "z": -2,
      "name": "Rock_Basalt"
    },
    {
      "x": 2,
      "y": 9,
      "z": -2,
      "name": "Rock_Basalt"
    },
    {
      "x": 2,
      "y": 10,
      "z": -2,
      "name": "Rock_Basalt"
    },
    {
      "x": 2,
      "y": 11,
      "z": -2,
      "name": "Rock_Basalt"
    },
    {
      "x": 2,
      "y": 12,
      "z": -2,
      "name": "Rock_Basalt"
    },
    {
      "x": 2,
      "y": 13,
      "z": -2,
      "name": "Rock_Basalt"
    },
    {
      "x": 2,
      "y": 14,
      "z": -2,
      "name": "Rock_Basalt"
    },
    {
      "x": 2,
      "y": 15,
      "z": -2,
      "name": "Soil_Dirt"
    },
    {
      "x": 2,
      "y": 16,
      "z": -2,
      "name": "Soil_Dirt"
    },
    {
      "x": 2,
      "y": 17,
      "z": -2,
      "name": "Soil_Grass"
    },
    {
      "x": 2,
      "y": 24,
      "z": -2,
      "name": "Plant_Leaves_Redwood"
    },
    {
      "x": 2,
      "y": 25,
      "z": -2,
      "name": "Plant_Leaves_Redwood"
    },
    {
      "x": 2,
      "y": 27,
      "z": -2,
      "name": "Plant_Leaves_Redwood"
    },
    {
      "x": 2,
      "y": 29,
      "z": -2,
      "name": "Plant_Leaves_Redwood"
    },
    {
      "x": 2,
      "y": 30,
      "z": -2,
      "name": "Plant_Leaves_Redwood"
    },
    {
      "x": 2,
      "y": 32,
      "z": -2,
      "name": "Plant_Leaves_Redwood"
    },
    {
      "x": 2,
      "y": 33,
      "z": -2,
      "name": "Plant_Leaves_Redwood"
    },
    {
      "x": 2,
      "y": 35,
      "z": -2,
      "name": "Plant_Leaves_Redwood"
    },
    {
      "x": 2,
      "y": 37,
      "z": -2,
      "name": "Plant_Leaves_Redwood"
    },
    {
      "x": 2,
      "y": 6,
      "z": -1,
      "name": "Rock_Basalt"
    },
    {
      "x": 2,
      "y": 7,
      "z": -1,
      "name": "Rock_Basalt"
    },
    {
      "x": 2,
      "y": 8,
      "z": -1,
      "name": "Rock_Basalt"
    },
    {
      "x": 2,
      "y": 9,
      "z": -1,
      "name": "Rock_Basalt"
    },
    {
      "x": 2,
      "y": 10,
      "z": -1,
      "name": "Rock_Basalt"
    },
    {
      "x": 2,
      "y": 11,
      "z": -1,
      "name": "Rock_Basalt"
    },
    {
      "x": 2,
      "y": 12,
      "z": -1,
      "name": "Rock_Basalt"
    },
    {
      "x": 2,
      "y": 13,
      "z": -1,
      "name": "Rock_Basalt"
    },
    {
      "x": 2,
      "y": 14,
      "z": -1,
      "name": "Rock_Basalt"
    },
    {
      "x": 2,
      "y": 15,
      "z": -1,
      "name": "Wood_Redwood_Roots"
    },
    {
      "x": 2,
      "y": 16,
      "z": -1,
      "name": "Wood_Redwood_Trunk"
    },
    {
      "x": 2,
      "y": 17,
      "z": -1,
      "name": "Wood_Redwood_Trunk"
    },
    {
      "x": 2,
      "y": 18,
      "z": -1,
      "name": "Wood_Redwood_Trunk_Full"
    },
    {
      "x": 2,
      "y": 25,
      "z": -1,
      "name": "Wood_Redwood_Branch_Long",
      "rotation": 5
    },
    {
      "x": 2,
      "y": 26,
      "z": -1,
      "name": "Plant_Leaves_Redwood"
    },
    {
      "x": 2,
      "y": 29,
      "z": -1,
      "name": "Wood_Redwood_Branch_Long",
      "rotation": 5
    },
    {
      "x": 2,
      "y": 31,
      "z": -1,
      "name": "Plant_Leaves_Redwood"
    },
    {
      "x": 2,
      "y": 32,
      "z": -1,
      "name": "Wood_Redwood_Branch_Long",
      "rotation": 5
    },
    {
      "x": 2,
      "y": 33,
      "z": -1,
      "name": "Plant_Leaves_Redwood"
    },
    {
      "x": 2,
      "y": 35,
      "z": -1,
      "name": "Wood_Redwood_Branch_Long",
      "rotation": 5
    },
    {
      "x": 2,
      "y": 38,
      "z": -1,
      "name": "Plant_Leaves_Redwood"
    },
    {
      "x": 2,
      "y": 39,
      "z": -1,
      "name": "Plant_Leaves_Redwood"
    },
    {
      "x": 2,
      "y": 5,
      "z": 0,
      "name": "Rock_Basalt"
    },
    {
      "x": 2,
      "y": 6,
      "z": 0,
      "name": "Rock_Basalt"
    },
    {
      "x": 2,
      "y": 7,
      "z": 0,
      "name": "Rock_Basalt"
    },
    {
      "x": 2,
      "y": 8,
      "z": 0,
      "name": "Rock_Basalt"
    },
    {
      "x": 2,
      "y": 9,
      "z": 0,
      "name": "Rock_Basalt"
    },
    {
      "x": 2,
      "y": 10,
      "z": 0,
      "name": "Rock_Basalt"
    },
    {
      "x": 2,
      "y": 11,
      "z": 0,
      "name": "Rock_Basalt"
    },
    {
      "x": 2,
      "y": 13,
      "z": 0,
      "name": "Wood_Redwood_Roots"
    },
    {
      "x": 2,
      "y": 14,
      "z": 0,
      "name": "Wood_Redwood_Trunk"
    },
    {
      "x": 2,
      "y": 15,
      "z": 0,
      "name": "Wood_Redwood_Trunk"
    },
    {
      "x": 2,
      "y": 16,
      "z": 0,
      "name": "Wood_Redwood_Trunk_Full"
    },
    {
      "x": 2,
      "y": 17,
      "z": 0,
      "name": "Soil_Grass"
    },
    {
      "x": 2,
      "y": 25,
      "z": 0,
      "name": "Plant_Leaves_Redwood"
    },
    {
      "x": 2,
      "y": 28,
      "z": 0,
      "name": "Plant_Leaves_Redwood"
    },
    {
      "x": 2,
      "y": 29,
      "z": 0,
      "name": "Plant_Leaves_Redwood"
    },
    {
      "x": 2,
      "y": 32,
      "z": 0,
      "name": "Plant_Leaves_Redwood"
    },
    {
      "x": 2,
      "y": 35,
      "z": 0,
      "name": "Plant_Leaves_Redwood"
    },
    {
      "x": 2,
      "y": 5,
      "z": 1,
      "name": "Rock_Basalt"
    },
    {
      "x": 2,
      "y": 6,
      "z": 1,
      "name": "Rock_Basalt"
    },
    {
      "x": 2,
      "y": 7,
      "z": 1,
      "name": "Rock_Basalt"
    },
    {
      "x": 2,
      "y": 8,
      "z": 1,
      "name": "Rock_Basalt"
    },
    {
      "x": 2,
      "y": 9,
      "z": 1,
      "name": "Rock_Basalt"
    },
    {
      "x": 2,
      "y": 10,
      "z": 1,
      "name": "Rock_Basalt"
    },
    {
      "x": 2,
      "y": 16,
      "z": 1,
      "name": "Soil_Dirt"
    },
    {
      "x": 2,
      "y": 17,
      "z": 1,
      "name": "Soil_Grass"
    },
    {
      "x": 2,
      "y": 18,
      "z": 1,
      "name": "Plant_Grass_Sharp_Tall"
    },
    {
      "x": 2,
      "y": 19,
      "z": 1,
      "name": "Plant_Grass_Sharp_Tall",
      "filler": 1024
    },
    {
      "x": 2,
      "y": 25,
      "z": 1,
      "name": "Plant_Leaves_Redwood"
    },
    {
      "x": 2,
      "y": 28,
      "z": 1,
      "name": "Plant_Leaves_Redwood"
    },
    {
      "x": 2,
      "y": 32,
      "z": 1,
      "name": "Plant_Leaves_Redwood"
    },
    {
      "x": 2,
      "y": 35,
      "z": 1,
      "name": "Plant_Leaves_Redwood"
    },
    {
      "x": 2,
      "y": 7,
      "z": 2,
      "name": "Rock_Basalt"
    },
    {
      "x": 2,
      "y": 25,
      "z": 2,
      "name": "Plant_Leaves_Redwood"
    },
    {
      "x": 2,
      "y": 32,
      "z": 2,
      "name": "Plant_Leaves_Redwood"
    },
    {
      "x": 3,
      "y": 8,
      "z": -3,
      "name": "Rock_Basalt"
    },
    {
      "x": 3,
      "y": 9,
      "z": -3,
      "name": "Rock_Basalt"
    },
    {
      "x": 3,
      "y": 10,
      "z": -3,
      "name": "Rock_Basalt"
    },
    {
      "x": 3,
      "y": 11,
      "z": -3,
      "name": "Rock_Basalt"
    },
    {
      "x": 3,
      "y": 13,
      "z": -3,
      "name": "Rock_Basalt"
    },
    {
      "x": 3,
      "y": 14,
      "z": -3,
      "name": "Rock_Basalt"
    },
    {
      "x": 3,
      "y": 15,
      "z": -3,
      "name": "Soil_Grass"
    },
    {
      "x": 3,
      "y": 16,
      "z": -3,
      "name": "Plant_Grass_Sharp_Tall"
    },
    {
      "x": 3,
      "y": 17,
      "z": -3,
      "name": "Plant_Grass_Sharp_Tall",
      "filler": 1024
    },
    {
      "x": 3,
      "y": 7,
      "z": -2,
      "name": "Rock_Basalt"
    },
    {
      "x": 3,
      "y": 8,
      "z": -2,
      "name": "Rock_Basalt"
    },
    {
      "x": 3,
      "y": 9,
      "z": -2,
      "name": "Rock_Basalt"
    },
    {
      "x": 3,
      "y": 10,
      "z": -2,
      "name": "Rock_Basalt"
    },
    {
      "x": 3,
      "y": 11,
      "z": -2,
      "name": "Rock_Basalt"
    },
    {
      "x": 3,
      "y": 12,
      "z": -2,
      "name": "Rock_Basalt"
    },
    {
      "x": 3,
      "y": 13,
      "z": -2,
      "name": "Rock_Basalt"
    },
    {
      "x": 3,
      "y": 14,
      "z": -2,
      "name": "Soil_Dirt"
    },
    {
      "x": 3,
      "y": 15,
      "z": -2,
      "name": "Soil_Dirt"
    },
    {
      "x": 3,
      "y": 16,
      "z": -2,
      "name": "Soil_Dirt"
    },
    {
      "x": 3,
      "y": 17,
      "z": -2,
      "name": "Soil_Grass"
    },
    {
      "x": 3,
      "y": 25,
      "z": -2,
      "name": "Plant_Leaves_Redwood"
    },
    {
      "x": 3,
      "y": 29,
      "z": -2,
      "name": "Plant_Leaves_Redwood"
    },
    {
      "x": 3,
      "y": 32,
      "z": -2,
      "name": "Plant_Leaves_Redwood"
    },
    {
      "x": 3,
      "y": 6,
      "z": -1,
      "name": "Rock_Basalt"
    },
    {
      "x": 3,
      "y": 7,
      "z": -1,
      "name": "Rock_Basalt"
    },
    {
      "x": 3,
      "y": 8,
      "z": -1,
      "name": "Rock_Basalt"
    },
    {
      "x": 3,
      "y": 9,
      "z": -1,
      "name": "Rock_Basalt"
    },
    {
      "x": 3,
      "y": 10,
      "z": -1,
      "name": "Rock_Basalt"
    },
    {
      "x": 3,
      "y": 11,
      "z": -1,
      "name": "Rock_Basalt"
    },
    {
      "x": 3,
      "y": 12,
      "z": -1,
      "name": "Rock_Basalt"
    },
    {
      "x": 3,
      "y": 13,
      "z": -1,
      "name": "Rock_Basalt"
    },
    {
      "x": 3,
      "y": 14,
      "z": -1,
      "name": "Rock_Basalt"
    },
    {
      "x": 3,
      "y": 15,
      "z": -1,
      "name": "Soil_Dirt"
    },
    {
      "x": 3,
      "y": 16,
      "z": -1,
      "name": "Soil_Dirt"
    },
    {
      "x": 3,
      "y": 17,
      "z": -1,
      "name": "Soil_Grass"
    },
    {
      "x": 3,
      "y": 18,
      "z": -1,
      "name": "Plant_Moss_Rug_Lime"
    },
    {
      "x": 3,
      "y": 25,
      "z": -1,
      "name": "Wood_Redwood_Branch_Long",
      "rotation": 5
    },
    {
      "x": 3,
      "y": 29,
      "z": -1,
      "name": "Plant_Leaves_Redwood"
    },
    {
      "x": 3,
      "y": 32,
      "z": -1,
      "name": "Wood_Redwood_Branch_Long",
      "rotation": 5
    },
    {
      "x": 3,
      "y": 35,
      "z": -1,
      "name": "Plant_Leaves_Redwood"
    },
    {
      "x": 3,
      "y": 6,
      "z": 0,
      "name": "Rock_Basalt"
    },
    {
      "x": 3,
      "y": 7,
      "z": 0,
      "name": "Rock_Basalt"
    },
    {
      "x": 3,
      "y": 8,
      "z": 0,
      "name": "Rock_Basalt"
    },
    {
      "x": 3,
      "y": 9,
      "z": 0,
      "name": "Rock_Basalt"
    },
    {
      "x": 3,
      "y": 10,
      "z": 0,
      "name": "Rock_Basalt"
    },
    {
      "x": 3,
      "y": 11,
      "z": 0,
      "name": "Rock_Basalt"
    },
    {
      "x": 3,
      "y": 12,
      "z": 0,
      "name": "Rock_Basalt"
    },
    {
      "x": 3,
      "y": 13,
      "z": 0,
      "name": "Rock_Basalt"
    },
    {
      "x": 3,
      "y": 14,
      "z": 0,
      "name": "Rock_Basalt"
    },
    {
      "x": 3,
      "y": 15,
      "z": 0,
      "name": "Soil_Dirt"
    },
    {
      "x": 3,
      "y": 16,
      "z": 0,
      "name": "Soil_Dirt"
    },
    {
      "x": 3,
      "y": 17,
      "z": 0,
      "name": "Soil_Grass"
    },
    {
      "x": 3,
      "y": 18,
      "z": 0,
      "name": "Plant_Grass_Sharp_Tall"
    },
    {
      "x": 3,
      "y": 19,
      "z": 0,
      "name": "Plant_Grass_Sharp_Tall",
      "filler": 1024
    },
    {
      "x": 3,
      "y": 25,
      "z": 0,
      "name": "Plant_Leaves_Redwood"
    },
    {
      "x": 3,
      "y": 29,
      "z": 0,
      "name": "Plant_Leaves_Redwood"
    },
    {
      "x": 3,
      "y": 32,
      "z": 0,
      "name": "Plant_Leaves_Redwood"
    },
    {
      "x": 3,
      "y": 7,
      "z": 1,
      "name": "Rock_Basalt"
    },
    {
      "x": 3,
      "y": 8,
      "z": 1,
      "name": "Rock_Basalt"
    },
    {
      "x": 3,
      "y": 9,
      "z": 1,
      "name": "Rock_Basalt"
    },
    {
      "x": 3,
      "y": 10,
      "z": 1,
      "name": "Rock_Basalt"
    },
    {
      "x": 3,
      "y": 11,
      "z": 1,
      "name": "Rock_Basalt"
    },
    {
      "x": 4,
      "y": 9,
      "z": -2,
      "name": "Rock_Basalt"
    },
    {
      "x": 4,
      "y": 10,
      "z": -2,
      "name": "Rock_Basalt"
    },
    {
      "x": 4,
      "y": 11,
      "z": -2,
      "name": "Rock_Basalt"
    },
    {
      "x": 4,
      "y": 12,
      "z": -2,
      "name": "Rock_Basalt"
    },
    {
      "x": 4,
      "y": 13,
      "z": -2,
      "name": "Rock_Basalt"
    },
    {
      "x": 4,
      "y": 14,
      "z": -2,
      "name": "Soil_Grass"
    },
    {
      "x": 4,
      "y": 15,
      "z": -2,
      "name": "Plant_Grass_Sharp_Tall"
    },
    {
      "x": 4,
      "y": 16,
      "z": -2,
      "name": "Plant_Grass_Sharp_Tall",
      "filler": 1024
    },
    {
      "x": 4,
      "y": 25,
      "z": -2,
      "name": "Plant_Leaves_Redwood"
    },
    {
      "x": 4,
      "y": 32,
      "z": -2,
      "name": "Plant_Leaves_Redwood"
    },
    {
      "x": 4,
      "y": 6,
      "z": -1,
      "name": "Rock_Basalt"
    },
    {
      "x": 4,
      "y": 7,
      "z": -1,
      "name": "Rock_Basalt"
    },
    {
      "x": 4,
      "y": 8,
      "z": -1,
      "name": "Rock_Basalt"
    },
    {
      "x": 4,
      "y": 9,
      "z": -1,
      "name": "Rock_Basalt"
    },
    {
      "x": 4,
      "y": 10,
      "z": -1,
      "name": "Rock_Basalt"
    },
    {
      "x": 4,
      "y": 11,
      "z": -1,
      "name": "Rock_Basalt"
    },
    {
      "x": 4,
      "y": 12,
      "z": -1,
      "name": "Rock_Basalt"
    },
    {
      "x": 4,
      "y": 13,
      "z": -1,
      "name": "Rock_Basalt"
    },
    {
      "x": 4,
      "y": 14,
      "z": -1,
      "name": "Rock_Basalt"
    },
    {
      "x": 4,
      "y": 15,
      "z": -1,
      "name": "Soil_Dirt"
    },
    {
      "x": 4,
      "y": 16,
      "z": -1,
      "name": "Soil_Grass"
    },
    {
      "x": 4,
      "y": 17,
      "z": -1,
      "name": "Plant_Grass_Sharp_Tall"
    },
    {
      "x": 4,
      "y": 18,
      "z": -1,
      "name": "Plant_Grass_Sharp_Tall",
      "filler": 1024
    },
    {
      "x": 4,
      "y": 25,
      "z": -1,
      "name": "Plant_Leaves_Redwood"
    },
    {
      "x": 4,
      "y": 29,
      "z": -1,
      "name": "Plant_Leaves_Redwood"
    },
    {
      "x": 4,
      "y": 32,
      "z": -1,
      "name": "Plant_Leaves_Redwood"
    },
    {
      "x": 4,
      "y": 36,
      "z": -1,
      "name": "Plant_Leaves_Redwood"
    },
    {
      "x": 4,
      "y": 6,
      "z": 0,
      "name": "Rock_Basalt"
    },
    {
      "x": 4,
      "y": 7,
      "z": 0,
      "name": "Rock_Basalt"
    },
    {
      "x": 4,
      "y": 8,
      "z": 0,
      "name": "Rock_Basalt"
    },
    {
      "x": 4,
      "y": 9,
      "z": 0,
      "name": "Rock_Basalt"
    },
    {
      "x": 4,
      "y": 10,
      "z": 0,
      "name": "Rock_Basalt"
    },
    {
      "x": 4,
      "y": 11,
      "z": 0,
      "name": "Rock_Basalt"
    },
    {
      "x": 4,
      "y": 12,
      "z": 0,
      "name": "Rock_Basalt"
    },
    {
      "x": 4,
      "y": 13,
      "z": 0,
      "name": "Rock_Basalt"
    },
    {
      "x": 4,
      "y": 14,
      "z": 0,
      "name": "Soil_Grass"
    },
    {
      "x": 4,
      "y": 25,
      "z": 0,
      "name": "Plant_Leaves_Redwood"
    },
    {
      "x": 4,
      "y": 32,
      "z": 0,
      "name": "Plant_Leaves_Redwood"
    },
    {
      "x": 5,
      "y": 10,
      "z": -2,
      "name": "Rock_Basalt"
    },
    {
      "x": 5,
      "y": 11,
      "z": -2,
      "name": "Rock_Basalt"
    },
    {
      "x": 5,
      "y": 12,
      "z": -2,
      "name": "Rock_Basalt"
    },
    {
      "x": 5,
      "y": 8,
      "z": -1,
      "name": "Rock_Basalt"
    },
    {
      "x": 5,
      "y": 9,
      "z": -1,
      "name": "Rock_Basalt"
    },
    {
      "x": 5,
      "y": 10,
      "z": -1,
      "name": "Rock_Basalt"
    },
    {
      "x": 5,
      "y": 11,
      "z": -1,
      "name": "Rock_Basalt"
    },
    {
      "x": 5,
      "y": 12,
      "z": -1,
      "name": "Rock_Basalt"
    },
    {
      "x": 5,
      "y": 13,
      "z": -1,
      "name": "Rock_Basalt"
    },
    {
      "x": 5,
      "y": 14,
      "z": -1,
      "name": "Rock_Basalt"
    },
    {
      "x": 5,
      "y": 15,
      "z": -1,
      "name": "Soil_Grass"
    },
    {
      "x": 5,
      "y": 25,
      "z": -1,
      "name": "Plant_Leaves_Redwood"
    },
    {
      "x": 5,
      "y": 29,
      "z": -1,
      "name": "Plant_Leaves_Redwood"
    },
    {
      "x": 5,
      "y": 32,
      "z": -1,
      "name": "Plant_Leaves_Redwood"
    },
    {
      "x": 5,
      "y": 11,
      "z": 0,
      "name": "Rock_Basalt"
    },
    {
      "x": 5,
      "y": 12,
      "z": 0,
      "name": "Rock_Basalt"
    },
    {
      "x": 5,
      "y": 13,
      "z": 0,
      "name": "Rock_Basalt"
    },
    {
      "x": 6,
      "y": 25,
      "z": -1,
      "name": "Plant_Leaves_Redwood"
    },
    {
      "x": 6,
      "y": 26,
      "z": -1,
      "name": "Plant_Leaves_Redwood"
    },
    {
      "x": 6,
      "y": 33,
      "z": -1,
      "name": "Plant_Leaves_Redwood"
    }
  ]
}