{
  "version": 8,
  "blockIdVersion": 8,
  "anchorX": 17,
  "anchorY": 16,
  "anchorZ": 6,
  "blocks": [
    {
      "x": 7,
      "y": 18,
      "z": 3,
      "name": "Rock_Basalt"
    },
    {
      "x": 7,
      "y": 19,
      "z": 3,
      "name": "Rock_Basalt"
    },
    {
      "x": 7,
      "y": 20,
      "z": 3,
      "name": "Rock_Basalt"
    },
    {
      "x": 7,
      "y": 21,
      "z": 3,
      "name": "Rock_Basalt"
    },
    {
      "x": 7,
      "y": 22,
      "z": 3,
      "name": "Rock_Basalt"
    },
    {
      "x": 7,
      "y": 23,
      "z": 3,
      "name": "Soil_Dirt"
    },
    {
      "x": 7,
      "y": 17,
      "z": 4,
      "name": "Rock_Basalt"
    },
    {
      "x": 7,
      "y": 18,
      "z": 4,
      "name": "Rock_Basalt"
    },
    {
      "x": 7,
      "y": 19,
      "z": 4,
      "name": "Rock_Basalt"
    },
    {
      "x": 7,
      "y": 20,
      "z": 4,
      "name": "Rock_Basalt"
    },
    {
      "x": 7,
      "y": 21,
      "z": 4,
      "name": "Rock_Basalt"
    },
    {
      "x": 7,
      "y": 22,
      "z": 4,
      "name": "Rock_Basalt"
    },
    {
      "x": 7,
      "y": 19,
      "z": 5,
      "name": "Rock_Basalt"
    },
    {
      "x": 7,
      "y": 20,
      "z": 5,
      "name": "Rock_Basalt"
    },
    {
      "x": 8,
      "y": 19,
      "z": 2,
      "name": "Rock_Basalt"
    },
    {
      "x": 8,
      "y": 20,
      "z": 2,
      "name": "Rock_Basalt"
    },
    {
      "x": 8,
      "y": 21,
      "z": 2,
      "name": "Rock_Basalt"
    },
    {
      "x": 8,
      "y": 22,
      "z": 2,
      "name": "Rock_Basalt"
    },
    {
      "x": 8,
      "y": 16,
      "z": 3,
      "name": "Rock_Basalt"
    },
    {
      "x": 8,
      "y": 17,
      "z": 3,
      "name": "Rock_Basalt"
    },
    {
      "x": 8,
      "y": 18,
      "z": 3,
      "name": "Rock_Basalt"
    },
    {
      "x": 8,
      "y": 19,
      "z": 3,
      "name": "Rock_Basalt"
    },
    {
      "x": 8,
      "y": 20,
      "z": 3,
      "name": "Rock_Basalt"
    },
    {
      "x": 8,
      "y": 21,
      "z": 3,
      "name": "Rock_Basalt"
    },
    {
      "x": 8,
      "y": 22,
      "z": 3,
      "name": "Rock_Basalt"
    },
    {
      "x": 8,
      "y": 23,
      "z": 3,
      "name": "Soil_Dirt"
    },
    {
      "x": 8,
      "y": 24,
      "z": 3,
      "name": "Soil_Grass"
    },
    {
      "x": 8,
      "y": 25,
      "z": 3,
      "name": "Plant_Grass_Sharp_Tall"
    },
    {
      "x": 8,
      "y": 26,
      "z": 3,
      "name": "Plant_Grass_Sharp_Tall",
      "filler": 1024
    },
    {
      "x": 8,
      "y": 15,
      "z": 4,
      "name": "Rock_Basalt"
    },
    {
      "x": 8,
      "y": 16,
      "z": 4,
      "name": "Rock_Basalt"
    },
    {
      "x": 8,
      "y": 17,
      "z": 4,
      "name": "Rock_Basalt"
    },
    {
      "x": 8,
      "y": 18,
      "z": 4,
      "name": "Rock_Basalt"
    },
    {
      "x": 8,
      "y": 19,
      "z": 4,
      "name": "Rock_Basalt"
    },
    {
      "x": 8,
      "y": 20,
      "z": 4,
      "name": "Rock_Basalt"
    },
    {
      "x": 8,
      "y": 21,
      "z": 4,
      "name": "Rock_Basalt"
    },
    {
      "x": 8,
      "y": 22,
      "z": 4,
      "name": "Rock_Basalt"
    },
    {
      "x": 8,
      "y": 23,
      "z": 4,
      "name": "Soil_Dirt"
    },
    {
      "x": 8,
      "y": 24,
      "z": 4,
      "name": "Soil_Dirt"
    },
    {
      "x": 8,
      "y": 25,
      "z": 4,
      "name": "Soil_Grass"
    },
    {
      "x": 8,
      "y": 15,
      "z": 5,
      "name": "Rock_Basalt"
    },
    {
      "x": 8,
      "y": 16,
      "z": 5,
      "name": "Rock_Basalt"
    },
    {
      "x": 8,
      "y": 17,
      "z": 5,
      "name": "Rock_Basalt"
    },
    {
      "x": 8,
      "y": 18,
      "z": 5,
      "name": "Rock_Basalt"
    },
    {
      "x": 8,
      "y": 19,
      "z": 5,
      "name": "Rock_Basalt"
    },
    {
      "x": 8,
      "y": 20,
      "z": 5,
      "name": "Rock_Basalt"
    },
    {
      "x": 8,
      "y": 21,
      "z": 5,
      "name": "Rock_Basalt"
    },
    {
      "x": 8,
      "y": 22,
      "z": 5,
      "name": "Rock_Basalt"
    },
    {
      "x": 8,
      "y": 24,
      "z": 5,
      "name": "Soil_Dirt"
    },
    {
      "x": 8,
      "y": 25,
      "z": 5,
      "name": "Soil_Grass"
    },
    {
      "x": 8,
      "y": 26,
      "z": 5,
      "name": "Plant_Grass_Sharp_Tall"
    },
    {
      "x": 8,
      "y": 27,
      "z": 5,
      "name": "Plant_Grass_Sharp_Tall",
      "filler": 1024
    },
    {
      "x": 8,
      "y": 15,
      "z": 6,
      "name": "Rock_Basalt"
    },
    {
      "x": 9,
      "y": 20,
      "z": 2,
      "name": "Rock_Basalt"
    },
    {
      "x": 9,
      "y": 21,
      "z": 2,
      "name": "Rock_Basalt"
    },
    {
      "x": 9,
      "y": 22,
      "z": 2,
      "name": "Rock_Basalt"
    },
    {
      "x": 9,
      "y": 23,
      "z": 2,
      "name": "Soil_Grass"
    },
    {
      "x": 9,
      "y": 17,
      "z": 3,
      "name": "Rock_Basalt"
    },
    {
      "x": 9,
      "y": 18,
      "z": 3,
      "name": "Rock_Basalt"
    },
    {
      "x": 9,
      "y": 19,
      "z": 3,
      "name": "Rock_Basalt"
    },
    {
      "x": 9,
      "y": 20,
      "z": 3,
      "name": "Rock_Basalt"
    },
    {
      "x": 9,
      "y": 21,
      "z": 3,
      "name": "Rock_Basalt"
    },
    {
      "x": 9,
      "y": 22,
      "z": 3,
      "name": "Rock_Basalt"
    },
    {
      "x": 9,
      "y": 23,
      "z": 3,
      "name": "Soil_Dirt"
    },
    {
      "x": 9,
      "y": 24,
      "z": 3,
      "name": "Soil_Grass"
    },
    {
      "x": 9,
      "y": 14,
      "z": 4,
      "name": "Rock_Basalt"
    },
    {
      "x": 9,
      "y": 15,
      "z": 4,
      "name": "Rock_Basalt"
    },
    {
      "x": 9,
      "y": 16,
      "z": 4,
      "name": "Rock_Basalt"
    },
    {
      "x": 9,
      "y": 17,
      "z": 4,
      "name": "Rock_Basalt"
    },
    {
      "x": 9,
      "y": 18,
      "z": 4,
      "name": "Rock_Basalt"
    },
    {
      "x": 9,
      "y": 19,
      "z": 4,
      "name": "Rock_Basalt"
    },
    {
      "x": 9,
      "y": 20,
      "z": 4,
      "name": "Rock_Basalt"
    },
    {
      "x": 9,
      "y": 21,
      "z": 4,
      "name": "Rock_Basalt"
    },
    {
      "x": 9,
      "y": 22,
      "z": 4,
      "name": "Soil_Dirt"
    },
    {
      "x": 9,
      "y": 23,
      "z": 4,
      "name": "Soil_Dirt"
    },
    {
      "x": 9,
      "y": 24,
      "z": 4,
      "name": "Soil_Dirt"
    },
    {
      "x": 9,
      "y": 25,
      "z": 4,
      "name": "Soil_Grass"
    },
    {
      "x": 9,
      "y": 14,
      "z": 5,
      "name": "Rock_Basalt"
    },
    {
      "x": 9,
      "y": 15,
      "z": 5,
      "name": "Rock_Basalt"
    },
    {
      "x": 9,
      "y": 16,
      "z": 5,
      "name": "Rock_Basalt"
    },
    {
      "x": 9,
      "y": 17,
      "z": 5,
      "name": "Rock_Basalt"
    },
    {
      "x": 9,
      "y": 18,
      "z": 5,
      "name": "Rock_Basalt"
    },
    {
      "x": 9,
      "y": 19,
      "z": 5,
      "name": "Rock_Basalt"
    },
    {
      "x": 9,
      "y": 20,
      "z": 5,
      "name": "Rock_Basalt"
    },
    {
      "x": 9,
      "y": 21,
      "z": 5,
      "name": "Rock_Basalt"
    },
    {
      "x": 9,
      "y": 22,
      "z": 5,
      "name": "Soil_Dirt"
    },
    {
      "x": 9,
      "y": 23,
      "z": 5,
      "name": "Soil_Dirt"
    },
    {
      "x": 9,
      "y": 24,
      "z": 5,
      "name": "Soil_Dirt"
    },
    {
      "x": 9,
      "y": 25,
      "z": 5,
      "name": "Soil_Grass"
    },
    {
      "x": 9,
      "y": 14,
      "z": 6,
      "name": "Rock_Basalt"
    },
    {
      "x": 9,
      "y": 15,
      "z": 6,
      "name": "Rock_Basalt"
    },
    {
      "x": 9,
      "y": 16,
      "z": 6,
      "name": "Rock_Basalt"
    },
    {
      "x": 9,
      "y": 17,
      "z": 6,
      "name": "Rock_Basalt"
    },
    {
      "x": 9,
      "y": 25,
      "z": 6,
      "name": "Soil_Dirt"
    },
    {
      "x": 9,
      "y": 26,
      "z": 6,
      "name": "Soil_Grass"
    },
    {
      "x": 9,
      "y": 27,
      "z": 6,
      "name": "Plant_Grass_Sharp_Tall"
    },
    {
      "x": 9,
      "y": 28,
      "z": 6,
      "name": "Plant_Grass_Sharp_Tall",
      "filler": 1024
    },
    {
      "x": 10,
      "y": 22,
      "z": 3,
      "name": "Rock_Basalt"
    },
    {
      "x": 10,
      "y": 23,
      "z": 3,
      "name": "Soil_Dirt"
    },
    {
      "x": 10,
      "y": 24,
      "z": 3,
      "name": "Soil_Dirt"
    },
    {
      "x": 10,
      "y": 25,
      "z": 3,
      "name": "Soil_Grass"
    },
    {
      "x": 10,
      "y": 26,
      "z": 3,
      "name": "Plant_Grass_Sharp_Tall"
    },
    {
      "x": 10,
      "y": 27,
      "z": 3,
      "name": "Plant_Grass_Sharp_Tall",
      "filler": 1024
    },
    {
      "x": 10,
      "y": 16,
      "z": 4,
      "name": "Rock_Basalt"
    },
    {
      "x": 10,
      "y": 17,
      "z": 4,
      "name": "Rock_Basalt"
    },
    {
      "x": 10,
      "y": 18,
      "z": 4,
      "name": "Rock_Basalt"
    },
    {
      "x": 10,
      "y": 19,
      "z": 4,
      "name": "Rock_Basalt"
    },
    {
      "x": 10,
      "y": 21,
      "z": 4,
      "name": "Rock_Basalt"
    },
    {
      "x": 10,
      "y": 22,
      "z": 4,
      "name": "Rock_Basalt"
    },
    {
      "x": 10,
      "y": 23,
      "z": 4,
      "name": "Soil_Dirt"
    },
    {
      "x": 10,
      "y": 24,
      "z": 4,
      "name": "Soil_Dirt"
    },
    {
      "x": 10,
      "y": 25,
      "z": 4,
      "name": "Soil_Dirt"
    },
    {
      "x": 10,
      "y": 26,
      "z": 4,
      "name": "Soil_Grass"
    },
    {
      "x": 10,
      "y": 13,
      "z": 5,
      "name": "Rock_Basalt"
    },
    {
      "x": 10,
      "y": 14,
      "z": 5,
      "name": "Rock_Basalt"
    },
    {
      "x": 10,
      "y": 15,
      "z": 5,
      "name": "Rock_Basalt"
    },
    {
      "x": 10,
      "y": 16,
      "z": 5,
      "name": "Rock_Basalt"
    },
    {
      "x": 10,
      "y": 17,
      "z": 5,
      "name": "Rock_Basalt"
    },
    {
      "x": 10,
      "y": 18,
      "z": 5,
      "name": "Rock_Basalt"
    },
    {
      "x": 10,
      "y": 23,
      "z": 5,
      "name": "Soil_Dirt"
    },
    {
      "x": 10,
      "y": 24,
      "z": 5,
      "name": "Soil_Dirt"
    },
    {
      "x": 10,
      "y": 25,
      "z": 5,
      "name": "Soil_Dirt"
    },
    {
      "x": 10,
      "y": 26,
      "z": 5,
      "name": "Soil_Grass"
    },
    {
      "x": 10,
      "y": 27,
      "z": 5,
      "name": "Plant_Grass_Sharp_Tall"
    },
    {
      "x": 10,
      "y": 28,
      "z": 5,
      "name": "Plant_Grass_Sharp_Tall",
      "filler": 1024
    },
    {
      "x": 10,
      "y": 13,
      "z": 6,
      "name": "Rock_Basalt"
    },
    {
      "x": 10,
      "y": 14,
      "z": 6,
      "name": "Rock_Basalt"
    },
    {
      "x": 10,
      "y": 15,
      "z": 6,
      "name": "Rock_Basalt"
    },
    {
      "x": 10,
      "y": 16,
      "z": 6,
      "name": "Rock_Basalt"
    },
    {
      "x": 10,
      "y": 25,
      "z": 6,
      "name": "Soil_Dirt"
    },
    {
      "x": 10,
      "y": 26,
      "z": 6,
      "name": "Soil_Grass"
    },
    {
      "x": 10,
      "y": 14,
      "z": 7,
      "name": "Rock_Basalt"
    },
    {
      "x": 10,
      "y": 15,
      "z": 7,
      "name": "Rock_Basalt"
    },
    {
      "x": 11,
      "y": 24,
      "z": 4,
      "name": "Soil_Dirt"
    },
    {
      "x": 11,
      "y": 25,
      "z": 4,
      "name": "Soil_Dirt"
    },
    {
      "x": 11,
      "y": 26,
      "z": 4,
      "name": "Soil_Grass"
    },
    {
      "x": 11,
      "y": 27,
      "z": 4,
      "name": "Plant_Grass_Sharp_Tall"
    },
    {
      "x": 11,
      "y": 28,
      "z": 4,
      "name": "Plant_Grass_Sharp_Tall",
      "filler": 1024
    },
    {
      "x": 11,
      "y": 13,
      "z": 5,
      "name": "Rock_Basalt"
    },
    {
      "x": 11,
      "y": 14,
      "z": 5,
      "name": "Rock_Basalt"
    },
    {
      "x": 11,
      "y": 24,
      "z": 5,
      "name": "Soil_Dirt"
    },
    {
      "x": 11,
      "y": 25,
      "z": 5,
      "name": "Soil_Dirt"
    },
    {
      "x": 11,
      "y": 26,
      "z": 5,
      "name": "Soil_Grass"
    },
    {
      "x": 11,
      "y": 13,
      "z": 6,
      "name": "Rock_Basalt"
    },
    {
      "x": 11,
      "y": 14,
      "z": 6,
      "name": "Rock_Basalt"
    },
    {
      "x": 11,
      "y": 15,
      "z": 6,
      "name": "Rock_Basalt"
    },
    {
      "x": 11,
      "y": 26,
      "z": 6,
      "name": "Soil_Dirt"
    },
    {
      "x": 11,
      "y": 27,
      "z": 6,
      "name": "Soil_Grass"
    },
    {
      "x": 11,
      "y": 28,
      "z": 6,
      "name": "Plant_Grass_Sharp_Tall"
    },
    {
      "x": 11,
      "y": 29,
      "z": 6,
      "name": "Plant_Grass_Sharp_Tall",
      "filler": 1024
    },
    {
      "x": 11,
      "y": 13,
      "z": 7,
      "name": "Rock_Basalt"
    },
    {
      "x": 11,
      "y": 14,
      "z": 7,
      "name": "Rock_Basalt"
    },
    {
      "x": 12,
      "y": 25,
      "z": 4,
      "name": "Soil_Dirt"
    },
    {
      "x": 12,
      "y": 26,
      "z": 4,
      "name": "Rock_Basalt"
    },
    {
      "x": 12,
      "y": 27,
      "z": 4,
      "name": "Soil_Grass"
    },
    {
      "x": 12,
      "y": 24,
      "z": 5,
      "name": "Rock_Basalt"
    },
    {
      "x": 12,
      "y": 25,
      "z": 5,
      "name": "Soil_Dirt"
    },
    {
      "x": 12,
      "y": 26,
      "z": 5,
      "name": "Soil_Dirt"
    },
    {
      "x": 12,
      "y": 27,
      "z": 5,
      "name": "Soil_Grass"
    },
    {
      "x": 12,
      "y": 28,
      "z": 5,
      "name": "Plant_Moss_Rug_Lime"
    },
    {
      "x": 12,
      "y": 12,
      "z": 6,
      "name": "Rock_Basalt"
    },
    {
      "x": 12,
      "y": 13,
      "z": 6,
      "name": "Rock_Basalt"
    },
    {
      "x": 12,
      "y": 14,
      "z": 6,
      "name": "Rock_Basalt"
    },
    {
      "x": 12,
      "y": 26,
      "z": 6,
      "name": "Soil_Dirt"
    },
    {
      "x": 12,
      "y": 27,
      "z": 6,
      "name": "Soil_Grass"
    },
    {
      "x": 12,
      "y": 28,
      "z": 6,
      "name": "Plant_Moss_Rug_Lime"
    },
    {
      "x": 12,
      "y": 13,
      "z": 7,
      "name": "Rock_Basalt"
    },
    {
      "x": 12,
      "y": 13,
      "z": 8,
      "name": "Rock_Basalt"
    },
    {
      "x": 13,
      "y": 25,
      "z": 4,
      "name": "Rock_Basalt"
    },
    {
      "x": 13,
      "y": 26,
      "z": 4,
      "name": "Soil_Dirt"
    },
    {
      "x": 13,
      "y": 27,
      "z": 4,
      "name": "Soil_Grass"
    },
    {
      "x": 13,
      "y": 28,
      "z": 4,
      "name": "Plant_Moss_Rug_Lime"
    },
    {
      "x": 13,
      "y": 25,
      "z": 5,
      "name": "Rock_Basalt"
    },
    {
      "x": 13,
      "y": 26,
      "z": 5,
      "name": "Soil_Dirt"
    },
    {
      "x": 13,
      "y": 27,
      "z": 5,
      "name": "Soil_Grass"
    },
    {
      "x": 13,
      "y": 13,
      "z": 6,
      "name": "Rock_Basalt"
    },
    {
      "x": 13,
      "y": 26,
      "z": 6,
      "name": "Soil_Dirt"
    },
    {
      "x": 13,
      "y": 27,
      "z": 6,
      "name": "Soil_Grass"
    },
    {
      "x": 13,
      "y": 28,
      "z": 6,
      "name": "Plant_Grass_Sharp_Tall"
    },
    {
      "x": 13,
      "y": 29,
      "z": 6,
      "name": "Plant_Grass_Sharp_Tall",
      "filler": 1024
    },
    {
      "x": 13,
      "y": 12,
      "z": 7,
      "name": "Rock_Basalt"
    },
    {
      "x": 13,
      "y": 13,
      "z": 7,
      "name": "Rock_Basalt"
    },
    {
      "x": 13,
      "y": 27,
      "z": 7,
      "name": "Soil_Dirt"
    },
    {
      "x": 13,
      "y": 28,
      "z": 7,
      "name": "Soil_Grass"
    },
    {
      "x": 13,
      "y": 29,
      "z": 7,
      "name": "Plant_Moss_Rug_Lime"
    },
    {
      "x": 13,
      "y": 13,
      "z": 8,
      "name": "Rock_Basalt"
    },
    {
      "x": 13,
      "y": 14,
      "z": 8,
      "name": "Rock_Basalt"
    },
    {
      "x": 13,
      "y": 15,
      "z": 9,
      "name": "Rock_Basalt"
    },
    {
      "x": 14,
      "y": 26,
      "z": 5,
      "name": "Soil_Dirt"
    },
    {
      "x": 14,
      "y": 27,
      "z": 5,
      "name": "Soil_Grass"
    },
    {
      "x": 14,
      "y": 28,
      "z": 5,
      "name": "Plant_Grass_Sharp_Tall"
    },
    {
      "x": 14,
      "y": 29,
      "z": 5,
      "name": "Plant_Grass_Sharp_Tall",
      "filler": 1024
    },
    {
      "x": 14,
      "y": 26,
      "z": 6,
      "name": "Soil_Dirt"
    },
    {
      "x": 14,
      "y": 27,
      "z": 6,
      "name": "Soil_Dirt"
    },
    {
      "x": 14,
      "y": 28,
      "z": 6,
      "name": "Soil_Grass"
    },
    {
      "x": 14,
      "y": 13,
      "z": 7,
      "name": "Rock_Basalt"
    },
    {
      "x": 14,
      "y": 14,
      "z": 7,
      "name": "Rock_Basalt"
    },
    {
      "x": 14,
      "y": 26,
      "z": 7,
      "name": "Soil_Dirt"
    },
    {
      "x": 14,
      "y": 27,
      "z": 7,
      "name": "Soil_Dirt"
    },
    {
      "x": 14,
      "y": 28,
      "z": 7,
      "name": "Soil_Grass"
    },
    {
      "x": 14,
      "y": 13,
      "z": 8,
      "name": "Rock_Basalt"
    },
    {
      "x": 14,
      "y": 14,
      "z": 8,
      "name": "Rock_Basalt"
    },
    {
      "x": 14,
      "y": 15,
      "z": 8,
      "name": "Rock_Basalt"
    },
    {
      "x": 14,
      "y": 14,
      "z": 9,
      "name": "Rock_Basalt"
    },
    {
      "x": 14,
      "y": 15,
      "z": 9,
      "name": "Rock_Basalt"
    },
    {
      "x": 14,
      "y": 16,
      "z": 9,
      "name": "Rock_Basalt"
    },
    {
      "x": 15,
      "y": 27,
      "z": 5,
      "name": "Soil_Grass"
    },
    {
      "x": 15,
      "y": 26,
      "z": 6,
      "name": "Soil_Dirt"
    },
    {
      "x": 15,
      "y": 27,
      "z": 6,
      "name": "Soil_Dirt"
    },
    {
      "x": 15,
      "y": 28,
      "z": 6,
      "name": "Soil_Grass"
    },
    {
      "x": 15,
      "y": 13,
      "z": 7,
      "name": "Rock_Basalt"
    },
    {
      "x": 15,
      "y": 14,
      "z": 7,
      "name": "Rock_Basalt"
    },
    {
      "x": 15,
      "y": 15,
      "z": 7,
      "name": "Rock_Basalt"
    },
    {
      "x": 15,
      "y": 26,
      "z": 7,
      "name": "Soil_Dirt"
    },
    {
      "x": 15,
      "y": 27,
      "z": 7,
      "name": "Soil_Dirt"
    },
    {
      "x": 15,
      "y": 28,
      "z": 7,
      "name": "Soil_Grass"
    },
    {
      "x": 15,
      "y": 29,
      "z": 7,
      "name": "Plant_Grass_Sharp_Tall"
    },
    {
      "x": 15,
      "y": 30,
      "z": 7,
      "name": "Plant_Grass_Sharp_Tall",
      "filler": 1024
    },
    {
      "x": 15,
      "y": 13,
      "z": 8,
      "name": "Rock_Basalt"
    },
    {
      "x": 15,
      "y": 14,
      "z": 8,
      "name": "Rock_Basalt"
    },
    {
      "x": 15,
      "y": 15,
      "z": 8,
      "name": "Rock_Basalt"
    },
    {
      "x": 15,
      "y": 16,
      "z": 8,
      "name": "Rock_Basalt"
    },
    {
      "x": 15,
      "y": 17,
      "z": 8,
      "name": "Rock_Basalt"
    },
    {
      "x": 15,
      "y": 26,
      "z": 8,
      "name": "Soil_Dirt"
    },
    {
      "x": 15,
      "y": 27,
      "z": 8,
      "name": "Soil_Dirt"
    },
    {
      "x": 15,
      "y": 28,
      "z": 8,
      "name": "Soil_Grass"
    },
    {
      "x": 15,
      "y": 14,
      "z": 9,
      "name": "Rock_Basalt"
    },
    {
      "x": 15,
      "y": 15,
      "z": 9,
      "name": "Rock_Basalt"
    },
    {
      "x": 15,
      "y": 16,
      "z": 9,
      "name": "Rock_Basalt"
    },
    {
      "x": 15,
      "y": 17,
      "z": 9,
      "name": "Rock_Basalt"
    },
    {
      "x": 15,
      "y": 15,
      "z": 10,
      "name": "Rock_Basalt"
    },
    {
      "x": 15,
      "y": 16,
      "z": 10,
      "name": "Rock_Basalt"
    },
    {
      "x": 15,
      "y": 17,
      "z": 10,
      "name": "Rock_Basalt"
    },
    {
      "x": 16,
      "y": 27,
      "z": 5,
      "name": "Soil_Dirt"
    },
    {
      "x": 16,
      "y": 28,
      "z": 5,
      "name": "Soil_Grass"
    },
    {
      "x": 16,
      "y": 25,
      "z": 6,
      "name": "Rock_Basalt"
    },
    {
      "x": 16,
      "y": 26,
      "z": 6,
      "name": "Soil_Dirt"
    },
    {
      "x": 16,
      "y": 27,
      "z": 6,
      "name": "Soil_Dirt"
    },
    {
      "x": 16,
      "y": 28,
      "z": 6,
      "name": "Soil_Grass"
    },
    {
      "x": 16,
      "y": 14,
      "z": 7,
      "name": "Rock_Basalt"
    },
    {
      "x": 16,
      "y": 15,
      "z": 7,
      "name": "Rock_Basalt"
    },
    {
      "x": 16,
      "y": 16,
      "z": 7,
      "name": "Rock_Basalt"
    },
    {
      "x": 16,
      "y": 17,
      "z": 7,
      "name": "Rock_Basalt"
    },
    {
      "x": 16,
      "y": 18,
      "z": 7,
      "name": "Rock_Basalt"
    },
    {
      "x": 16,
      "y": 22,
      "z": 7,
      "name": "Rock_Basalt"
    },
    {
      "x": 16,
      "y": 23,
      "z": 7,
      "name": "Rock_Basalt"
    },
    {
      "x": 16,
      "y": 24,
      "z": 7,
      "name": "Rock_Basalt"
    },
    {
      "x": 16,
      "y": 25,
      "z": 7,
      "name": "Soil_Dirt"
    },
    {
      "x": 16,
      "y": 26,
      "z": 7,
      "name": "Soil_Dirt"
    },
    {
      "x": 16,
      "y": 27,
      "z": 7,
      "name": "Soil_Dirt"
    },
    {
      "x": 16,
      "y": 28,
      "z": 7,
      "name": "Soil_Grass"
    },
    {
      "x": 16,
      "y": 29,
      "z": 7,
      "name": "Plant_Grass_Sharp_Tall"
    },
    {
      "x": 16,
      "y": 30,
      "z": 7,
      "name": "Plant_Grass_Sharp_Tall",
      "filler": 1024
    },
    {
      "x": 16,
      "y": 14,
      "z": 8,
      "name": "Rock_Basalt"
    },
    {
      "x": 16,
      "y": 15,
      "z": 8,
      "name": "Rock_Basalt"
    },
    {
      "x": 16,
      "y": 16,
      "z": 8,
      "name": "Rock_Basalt"
    },
    {
      "x": 16,
      "y": 17,
      "z": 8,
      "name": "Rock_Basalt"
    },
    {
      "x": 16,
      "y": 18,
      "z": 8,
      "name": "Rock_Basalt"
    },
    {
      "x": 16,
      "y": 19,
      "z": 8,
      "name": "Rock_Basalt"
    },
    {
      "x": 16,
      "y": 24,
      "z": 8,
      "name": "Rock_Basalt"
    },
    {
      "x": 16,
      "y": 25,
      "z": 8,
      "name": "Rock_Basalt"
    },
    {
      "x": 16,
      "y": 26,
      "z": 8,
      "name": "Soil_Dirt"
    },
    {
      "x": 16,
      "y": 27,
      "z": 8,
      "name": "Soil_Dirt"
    },
    {
      "x": 16,
      "y": 28,
      "z": 8,
      "name": "Soil_Grass"
    },
    {
      "x": 16,
      "y": 13,
      "z": 9,
      "name": "Rock_Basalt"
    },
    {
      "x": 16,
      "y": 14,
      "z": 9,
      "name": "Rock_Basalt"
    },
    {
      "x": 16,
      "y": 15,
      "z": 9,
      "name": "Rock_Basalt"
    },
    {
      "x": 16,
      "y": 16,
      "z": 9,
      "name": "Rock_Basalt"
    },
    {
      "x": 16,
      "y": 17,
      "z": 9,
      "name": "Rock_Basalt"
    },
    {
      "x": 16,
      "y": 18,
      "z": 9,
      "name": "Rock_Basalt"
    },
    {
      "x": 16,
      "y": 27,
      "z": 9,
      "name": "Soil_Grass"
    },
    {
      "x": 16,
      "y": 14,
      "z": 10,
      "name": "Rock_Basalt"
    },
    {
      "x": 16,
      "y": 15,
      "z": 10,
      "name": "Rock_Basalt"
    },
    {
      "x": 16,
      "y": 16,
      "z": 10,
      "name": "Rock_Basalt"
    },
    {
      "x": 16,
      "y": 17,
      "z": 10,
      "name": "Rock_Basalt"
    },
    {
      "x": 16,
      "y": 16,
      "z": 11,
      "name": "Rock_Basalt"
    },
    {
      "x": 17,
      "y": 26,
      "z": 5,
      "name": "Soil_Dirt"
    },
    {
      "x": 17,
      "y": 27,
      "z": 5,
      "name": "Soil_Grass"
    },
    {
      "x": 17,
      "y": 28,
      "z": 5,
      "name": "Plant_Grass_Sharp_Tall"
    },
    {
      "x": 17,
      "y": 29,
      "z": 5,
      "name": "Plant_Grass_Sharp_Tall",
      "filler": 1024
    },
    {
      "x": 17,
      "y": 16,
      "z": 6,
      "name": "Rock_Basalt"
    },
    {
      "x": 17,
      "y": 24,
      "z": 6,
      "name": "Rock_Basalt"
    },
    {
      "x": 17,
      "y": 25,
      "z": 6,
      "name": "Soil_Dirt"
    },
    {
      "x": 17,
      "y": 26,
      "z": 6,
      "name": "Soil_Dirt"
    },
    {
      "x": 17,
      "y": 27,
      "z": 6,
      "name": "Soil_Dirt"
    },
    {
      "x": 17,
      "y": 28,
      "z": 6,
      "name": "Soil_Grass"
    },
    {
      "x": 17,
      "y": 16,
      "z": 7,
      "name": "Rock_Basalt"
    },
    {
      "x": 17,
      "y": 17,
      "z": 7,
      "name": "Rock_Basalt"
    },
    {
      "x": 17,
      "y": 18,
      "z": 7,
      "name": "Rock_Basalt"
    },
    {
      "x": 17,
      "y": 19,
      "z": 7,
      "name": "Rock_Basalt"
    },
    {
      "x": 17,
      "y": 20,
      "z": 7,
      "name": "Rock_Basalt"
    },
    {
      "x": 17,
      "y": 21,
      "z": 7,
      "name": "Rock_Basalt"
    },
    {
      "x": 17,
      "y": 22,
      "z": 7,
      "name": "Rock_Basalt"
    },
    {
      "x": 17,
      "y": 23,
      "z": 7,
      "name": "Rock_Basalt"
    },
    {
      "x": 17,
      "y": 24,
      "z": 7,
      "name": "Rock_Basalt"
    },
    {
      "x": 17,
      "y": 25,
      "z": 7,
      "name": "Soil_Dirt"
    },
    {
      "x": 17,
      "y": 26,
      "z": 7,
      "name": "Soil_Dirt"
    },
    {
      "x": 17,
      "y": 27,
      "z": 7,
      "name": "Soil_Grass"
    },
    {
      "x": 17,
      "y": 28,
      "z": 7,
      "name": "Plant_Grass_Sharp_Tall"
    },
    {
      "x": 17,
      "y": 29,
      "z": 7,
      "name": "Plant_Grass_Sharp_Tall",
      "filler": 1024
    },
    {
      "x": 17,
      "y": 14,
      "z": 8,
      "name": "Rock_Basalt"
    },
    {
      "x": 17,
      "y": 15,
      "z": 8,
      "name": "Rock_Basalt"
    },
    {
      "x": 17,
      "y": 16,
      "z": 8,
      "name": "Rock_Basalt"
    },
    {
      "x": 17,
      "y": 17,
      "z": 8,
      "name": "Rock_Basalt"
    },
    {
      "x": 17,
      "y": 18,
      "z": 8,
      "name": "Rock_Basalt"
    },
    {
      "x": 17,
      "y": 19,
      "z": 8,
      "name": "Rock_Basalt"
    },
    {
      "x": 17,
      "y": 20,
      "z": 8,
      "name": "Rock_Basalt"
    },
    {
      "x": 17,
      "y": 21,
      "z": 8,
      "name": "Rock_Basalt"
    },
    {
      "x": 17,
      "y": 22,
      "z": 8,
      "name": "Rock_Basalt"
    },
    {
      "x": 17,
      "y": 23,
      "z": 8,
      "name": "Rock_Basalt"
    },
    {
      "x": 17,
      "y": 24,
      "z": 8,
      "name": "Rock_Basalt"
    },
    {
      "x": 17,
      "y": 25,
      "z": 8,
      "name": "Soil_Dirt"
    },
    {
      "x": 17,
      "y": 26,
      "z": 8,
      "name": "Soil_Dirt"
    },
    {
      "x": 17,
      "y": 27,
      "z": 8,
      "name": "Soil_Grass"
    },
    {
      "x": 17,
      "y": 14,
      "z": 9,
      "name": "Rock_Basalt"
    },
    {
      "x": 17,
      "y": 15,
      "z": 9,
      "name": "Rock_Basalt"
    },
    {
      "x": 17,
      "y": 16,
      "z": 9,
      "name": "Rock_Basalt"
    },
    {
      "x": 17,
      "y": 17,
      "z": 9,
      "name": "Rock_Basalt"
    },
    {
      "x": 17,
      "y": 18,
      "z": 9,
      "name": "Rock_Basalt"
    },
    {
      "x": 17,
      "y": 19,
      "z": 9,
      "name": "Rock_Basalt"
    },
    {
      "x": 17,
      "y": 25,
      "z": 9,
      "name": "Rock_Basalt"
    },
    {
      "x": 17,
      "y": 26,
      "z": 9,
      "name": "Soil_Dirt"
    },
    {
      "x": 17,
      "y": 27,
      "z": 9,
      "name": "Soil_Grass"
    },
    {
      "x": 17,
      "y": 28,
      "z": 9,
      "name": "Plant_Grass_Sharp_Tall"
    },
    {
      "x": 17,
      "y": 29,
      "z": 9,
      "name": "Plant_Grass_Sharp_Tall",
      "filler": 1024
    },
    {
      "x": 17,
      "y": 14,
      "z": 10,
      "name": "Rock_Basalt"
    },
    {
      "x": 17,
      "y": 15,
      "z": 10,
      "name": "Rock_Basalt"
    },
    {
      "x": 17,
      "y": 16,
      "z": 10,
      "name": "Rock_Basalt"
    },
    {
      "x": 17,
      "y": 17,
      "z": 10,
      "name": "Rock_Basalt"
    },
    {
      "x": 17,
      "y": 18,
      "z": 10,
      "name": "Rock_Basalt"
    },
    {
      "x": 17,
      "y": 19,
      "z": 10,
      "name": "Rock_Basalt"
    },
    {
      "x": 17,
      "y": 15,
      "z": 11,
      "name": "Rock_Basalt"
    },
    {
      "x": 17,
      "y": 16,
      "z": 11,
      "name": "Rock_Basalt"
    },
    {
      "x": 17,
      "y": 17,
      "z": 11,
      "name": "Rock_Basalt"
    },
    {
      "x": 18,
      "y": 25,
      "z": 5,
      "name": "Soil_Dirt"
    },
    {
      "x": 18,
      "y": 26,
      "z": 5,
      "name": "Soil_Dirt"
    },
    {
      "x": 18,
      "y": 27,
      "z": 5,
      "name": "Soil_Grass"
    },
    {
      "x": 18,
      "y": 24,
      "z": 6,
      "name": "Rock_Basalt"
    },
    {
      "x": 18,
      "y": 25,
      "z": 6,
      "name": "Soil_Dirt"
    },
    {
      "x": 18,
      "y": 26,
      "z": 6,
      "name": "Soil_Dirt"
    },
    {
      "x": 18,
      "y": 27,
      "z": 6,
      "name": "Soil_Grass"
    },
    {
      "x": 18,
      "y": 28,
      "z": 6,
      "name": "Plant_Grass_Sharp_Tall"
    },
    {
      "x": 18,
      "y": 29,
      "z": 6,
      "name": "Plant_Grass_Sharp_Tall",
      "filler": 1024
    },
    {
      "x": 18,
      "y": 22,
      "z": 7,
      "name": "Rock_Basalt"
    },
    {
      "x": 18,
      "y": 23,
      "z": 7,
      "name": "Rock_Basalt"
    },
    {
      "x": 18,
      "y": 24,
      "z": 7,
      "name": "Rock_Basalt"
    },
    {
      "x": 18,
      "y": 25,
      "z": 7,
      "name": "Soil_Dirt"
    },
    {
      "x": 18,
      "y": 26,
      "z": 7,
      "name": "Soil_Dirt"
    },
    {
      "x": 18,
      "y": 27,
      "z": 7,
      "name": "Soil_Grass"
    },
    {
      "x": 18,
      "y": 14,
      "z": 8,
      "name": "Rock_Basalt"
    },
    {
      "x": 18,
      "y": 15,
      "z": 8,
      "name": "Rock_Basalt"
    },
    {
      "x": 18,
      "y": 16,
      "z": 8,
      "name": "Rock_Basalt"
    },
    {
      "x": 18,
      "y": 23,
      "z": 8,
      "name": "Rock_Basalt"
    },
    {
      "x": 18,
      "y": 24,
      "z": 8,
      "name": "Rock_Basalt"
    },
    {
      "x": 18,
      "y": 25,
      "z": 8,
      "name": "Soil_Dirt"
    },
    {
      "x": 18,
      "y": 26,
      "z": 8,
      "name": "Soil_Dirt"
    },
    {
      "x": 18,
      "y": 27,
      "z": 8,
      "name": "Soil_Grass"
    },
    {
      "x": 18,
      "y": 28,
      "z": 8,
      "name": "Plant_Moss_Rug_Lime"
    },
    {
      "x": 18,
      "y": 14,
      "z": 9,
      "name": "Rock_Basalt"
    },
    {
      "x": 18,
      "y": 15,
      "z": 9,
      "name": "Rock_Basalt"
    },
    {
      "x": 18,
      "y": 16,
      "z": 9,
      "name": "Rock_Basalt"
    },
    {
      "x": 18,
      "y": 17,
      "z": 9,
      "name": "Rock_Basalt"
    },
    {
      "x": 18,
      "y": 26,
      "z": 9,
      "name": "Soil_Dirt"
    },
    {
      "x": 18,
      "y": 27,
      "z": 9,
      "name": "Soil_Grass"
    },
    {
      "x": 18,
      "y": 14,
      "z": 10,
      "name": "Rock_Basalt"
    },
    {
      "x": 18,
      "y": 15,
      "z": 10,
      "name": "Rock_Basalt"
    },
    {
      "x": 18,
      "y": 16,
      "z": 10,
      "name": "Rock_Basalt"
    },
    {
      "x": 19,
      "y": 24,
      "z": 5,
      "name": "Rock_Basalt"
    },
    {
      "x": 19,
      "y": 25,
      "z": 5,
      "name": "Soil_Dirt"
    },
    {
      "x": 19,
      "y": 26,
      "z": 5,
      "name": "Soil_Grass"
    },
    {
      "x": 19,
      "y": 24,
      "z": 6,
      "name": "Rock_Basalt"
    },
    {
      "x": 19,
      "y": 25,
      "z": 6,
      "name": "Soil_Dirt"
    },
    {
      "x": 19,
      "y": 26,
      "z": 6,
      "name": "Soil_Grass"
    },
    {
      "x": 19,
      "y": 23,
      "z": 7,
      "name": "Rock_Basalt"
    },
    {
      "x": 19,
      "y": 24,
      "z": 7,
      "name": "Soil_Dirt"
    },
    {
      "x": 19,
      "y": 25,
      "z": 7,
      "name": "Soil_Dirt"
    },
    {
      "x": 19,
      "y": 26,
      "z": 7,
      "name": "Soil_Dirt"
    },
    {
      "x": 19,
      "y": 27,
      "z": 7,
      "name": "Soil_Grass"
    },
    {
      "x": 19,
      "y": 14,
      "z": 8,
      "name": "Rock_Basalt"
    },
    {
      "x": 19,
      "y": 25,
      "z": 8,
      "name": "Soil_Dirt"
    },
    {
      "x": 19,
      "y": 26,
      "z": 8,
      "name": "Soil_Needles"
    },
    {
      "x": 19,
      "y": 27,
      "z": 8,
      "name": "Soil_Grass"
    },
    {
      "x": 19,
      "y": 28,
      "z": 8,
      "name": "Plant_Moss_Rug_Lime"
    },
    {
      "x": 19,
      "y": 14,
      "z": 9,
      "name": "Rock_Basalt"
    },
    {
      "x": 19,
      "y": 15,
      "z": 9,
      "name": "Rock_Basalt"
    },
    {
      "x": 19,
      "y": 26,
      "z": 9,
      "name": "Soil_Dirt"
    },
    {
      "x": 19,
      "y": 27,
      "z": 9,
      "name": "Soil_Grass"
    },
    {
      "x": 19,
      "y": 28,
      "z": 9,
      "name": "Plant_Grass_Sharp_Tall"
    },
    {
      "x": 19,
      "y": 29,
      "z": 9,
      "name": "Plant_Grass_Sharp_Tall",
      "filler": 1024
    },
    {
      "x": 19,
      "y": 15,
      "z": 10,
      "name": "Rock_Basalt"
    },
    {
      "x": 20,
      "y": 24,
      "z": 5,
      "name": "Rock_Basalt"
    },
    {
      "x": 20,
      "y": 25,
      "z": 5,
      "name": "Soil_Grass"
    },
    {
      "x": 20,
      "y": 23,
      "z": 6,
      "name": "Rock_Basalt"
    },
    {
      "x": 20,
      "y": 24,
      "z": 6,
      "name": "Rock_Basalt"
    },
    {
      "x": 20,
      "y": 25,
      "z": 6,
      "name": "Soil_Dirt"
    },
    {
      "x": 20,
      "y": 26,
      "z": 6,
      "name": "Soil_Grass"
    },
    {
      "x": 20,
      "y": 27,
      "z": 6,
      "name": "Plant_Grass_Sharp_Tall"
    },
    {
      "x": 20,
      "y": 28,
      "z": 6,
      "name": "Plant_Grass_Sharp_Tall",
      "filler": 1024
    },
    {
      "x": 20,
      "y": 23,
      "z": 7,
      "name": "Rock_Basalt"
    },
    {
      "x": 20,
      "y": 24,
      "z": 7,
      "name": "Soil_Dirt"
    },
    {
      "x": 20,
      "y": 25,
      "z": 7,
      "name": "Soil_Needles"
    },
    {
      "x": 20,
      "y": 26,
      "z": 7,
      "name": "Soil_Needles"
    },
    {
      "x": 20,
      "y": 27,
      "z": 7,
      "name": "Soil_Needles"
    },
    {
      "x": 20,
      "y": 28,
      "z": 7,
      "name": "Plant_Moss_Rug_Lime"
    },
    {
      "x": 20,
      "y": 25,
      "z": 8,
      "name": "Soil_Needles"
    },
    {
      "x": 20,
      "y": 26,
      "z": 8,
      "name": "Soil_Needles"
    },
    {
      "x": 20,
      "y": 27,
      "z": 8,
      "name": "Soil_Needles"
    },
    {
      "x": 20,
      "y": 14,
      "z": 9,
      "name": "Rock_Basalt"
    },
    {
      "x": 20,
      "y": 15,
      "z": 9,
      "name": "Rock_Basalt"
    },
    {
      "x": 20,
      "y": 15,
      "z": 10,
      "name": "Rock_Basalt"
    },
    {
      "x": 20,
      "y": 15,
      "z": 11,
      "name": "Rock_Basalt"
    },
    {
      "x": 21,
      "y": 25,
      "z": 5,
      "name": "Soil_Grass"
    },
    {
      "x": 21,
      "y": 26,
      "z": 5,
      "name": "Plant_Grass_Sharp_Tall"
    },
    {
      "x": 21,
      "y": 27,
      "z": 5,
      "name": "Plant_Grass_Sharp_Tall",
      "filler": 1024
    },
    {
      "x": 21,
      "y": 23,
      "z": 6,
      "name": "Rock_Basalt"
    },
    {
      "x": 21,
      "y": 24,
      "z": 6,
      "name": "Soil_Dirt"
    },
    {
      "x": 21,
      "y": 25,
      "z": 6,
      "name": "Soil_Needles"
    },
    {
      "x": 21,
      "y": 26,
      "z": 6,
      "name": "Soil_Needles"
    },
    {
      "x": 21,
      "y": 22,
      "z": 7,
      "name": "Rock_Basalt"
    },
    {
      "x": 21,
      "y": 23,
      "z": 7,
      "name": "Rock_Basalt"
    },
    {
      "x": 21,
      "y": 24,
      "z": 7,
      "name": "Soil_Dirt"
    },
    {
      "x": 21,
      "y": 25,
      "z": 7,
      "name": "Soil_Needles"
    },
    {
      "x": 21,
      "y": 26,
      "z": 7,
      "name": "Soil_Needles"
    },
    {
      "x": 21,
      "y": 27,
      "z": 7,
      "name": "Plant_Moss_Rug_Lime"
    },
    {
      "x": 21,
      "y": 22,
      "z": 8,
      "name": "Rock_Basalt"
    },
    {
      "x": 21,
      "y": 23,
      "z": 8,
      "name": "Rock_Basalt"
    },
    {
      "x": 21,
      "y": 24,
      "z": 8,
      "name": "Soil_Needles"
    },
    {
      "x": 21,
      "y": 25,
      "z": 8,
      "name": "Soil_Needles"
    },
    {
      "x": 21,
      "y": 26,
      "z": 8,
      "name": "Soil_Needles"
    },
    {
      "x": 21,
      "y": 27,
      "z": 8,
      "name": "Soil_Needles"
    },
    {
      "x": 21,
      "y": 28,
      "z": 8,
      "name": "Plant_Moss_Rug_Lime"
    },
    {
      "x": 21,
      "y": 15,
      "z": 9,
      "name": "Rock_Basalt"
    },
    {
      "x": 21,
      "y": 16,
      "z": 9,
      "name": "Rock_Basalt"
    },
    {
      "x": 21,
      "y": 22,
      "z": 9,
      "name": "Rock_Basalt"
    },
    {
      "x": 21,
      "y": 23,
      "z": 9,
      "name": "Rock_Basalt"
    },
    {
      "x": 21,
      "y": 24,
      "z": 9,
      "name": "Soil_Dirt"
    },
    {
      "x": 21,
      "y": 25,
      "z": 9,
      "name": "Soil_Needles"
    },
    {
      "x": 21,
      "y": 15,
      "z": 10,
      "name": "Rock_Basalt"
    },
    {
      "x": 21,
      "y": 16,
      "z": 10,
      "name": "Rock_Basalt"
    },
    {
      "x": 21,
      "y": 17,
      "z": 10,
      "name": "Rock_Basalt"
    },
    {
      "x": 21,
      "y": 18,
      "z": 10,
      "name": "Rock_Basalt"
    },
    {
      "x": 21,
      "y": 19,
      "z": 10,
      "name": "Rock_Basalt"
    },
    {
      "x": 21,
      "y": 16,
      "z": 11,
      "name": "Rock_Basalt"
    },
    {
      "x": 21,
      "y": 17,
      "z": 11,
      "name": "Rock_Basalt"
    },
    {
      "x": 22,
      "y": 23,
      "z": 6,
      "name": "Rock_Basalt"
    },
    {
      "x": 22,
      "y": 24,
      "z": 6,
      "name": "Soil_Dirt"
    },
    {
      "x": 22,
      "y": 25,
      "z": 6,
      "name": "Soil_Needles"
    },
    {
      "x": 22,
      "y": 26,
      "z": 6,
      "name": "Plant_Moss_Rug_Lime"
    },
    {
      "x": 22,
      "y": 22,
      "z": 7,
      "name": "Rock_Basalt"
    },
    {
      "x": 22,
      "y": 23,
      "z": 7,
      "name": "Rock_Basalt"
    },
    {
      "x": 22,
      "y": 24,
      "z": 7,
      "name": "Soil_Needles"
    },
    {
      "x": 22,
      "y": 25,
      "z": 7,
      "name": "Soil_Needles"
    },
    {
      "x": 22,
      "y": 26,
      "z": 7,
      "name": "Soil_Needles"
    },
    {
      "x": 22,
      "y": 27,
      "z": 7,
      "name": "Plant_Moss_Rug_Lime"
    },
    {
      "x": 22,
      "y": 21,
      "z": 8,
      "name": "Rock_Basalt"
    },
    {
      "x": 22,
      "y": 22,
      "z": 8,
      "name": "Rock_Basalt"
    },
    {
      "x": 22,
      "y": 23,
      "z": 8,
      "name": "Soil_Dirt"
    },
    {
      "x": 22,
      "y": 24,
      "z": 8,
      "name": "Soil_Dirt"
    },
    {
      "x": 22,
      "y": 25,
      "z": 8,
      "name": "Soil_Needles"
    },
    {
      "x": 22,
      "y": 26,
      "z": 8,
      "name": "Soil_Needles"
    },
    {
      "x": 22,
      "y": 27,
      "z": 8,
      "name": "Plant_Moss_Rug_Lime"
    },
    {
      "x": 22,
      "y": 15,
      "z": 9,
      "name": "Rock_Basalt"
    },
    {
      "x": 22,
      "y": 16,
      "z": 9,
      "name": "Rock_Basalt"
    },
    {
      "x": 22,
      "y": 17,
      "z": 9,
      "name": "Rock_Basalt"
    },
    {
      "x": 22,
      "y": 18,
      "z": 9,
      "name": "Rock_Basalt"
    },
    {
      "x": 22,
      "y": 19,
      "z": 9,
      "name": "Rock_Basalt"
    },
    {
      "x": 22,
      "y": 21,
      "z": 9,
      "name": "Rock_Basalt"
    },
    {
      "x": 22,
      "y": 22,
      "z": 9,
      "name": "Rock_Basalt"
    },
    {
      "x": 22,
      "y": 23,
      "z": 9,
      "name": "Rock_Basalt"
    },
    {
      "x": 22,
      "y": 24,
      "z": 9,
      "name": "Soil_Dirt"
    },
    {
      "x": 22,
      "y": 25,
      "z": 9,
      "name": "Soil_Needles"
    },
    {
      "x": 22,
      "y": 26,
      "z": 9,
      "name": "Soil_Needles"
    },
    {
      "x": 22,
      "y": 27,
      "z": 9,
      "name": "Plant_Moss_Rug_Lime"
    },
    {
      "x": 22,
      "y": 16,
      "z": 10,
      "name": "Rock_Basalt"
    },
    {
      "x": 22,
      "y": 17,
      "z": 10,
      "name": "Rock_Basalt"
    },
    {
      "x": 22,
      "y": 18,
      "z": 10,
      "name": "Rock_Basalt"
    },
    {
      "x": 22,
      "y": 19,
      "z": 10,
      "name": "Rock_Basalt"
    },
    {
      "x": 22,
      "y": 20,
      "z": 10,
      "name": "Rock_Basalt"
    },
    {
      "x": 22,
      "y": 21,
      "z": 10,
      "name": "Rock_Basalt"
    },
    {
      "x": 22,
      "y": 22,
      "z": 10,
      "name": "Rock_Basalt"
    },
    {
      "x": 22,
      "y": 23,
      "z": 10,
      "name": "Rock_Basalt"
    },
    {
      "x": 22,
      "y": 24,
      "z": 10,
      "name": "Soil_Grass"
    },
    {
      "x": 22,
      "y": 25,
      "z": 10,
      "name": "Plant_Grass_Sharp_Tall"
    },
    {
      "x": 22,
      "y": 26,
      "z": 10,
      "name": "Plant_Grass_Sharp_Tall",
      "filler": 1024
    },
    {
      "x": 22,
      "y": 16,
      "z": 11,
      "name": "Rock_Basalt"
    },
    {
      "x": 22,
      "y": 17,
      "z": 11,
      "name": "Rock_Basalt"
    },
    {
      "x": 22,
      "y": 18,
      "z": 11,
      "name": "Rock_Basalt"
    },
    {
      "x": 22,
      "y": 19,
      "z": 11,
      "name": "Rock_Basalt"
    },
    {
      "x": 22,
      "y": 20,
      "z": 11,
      "name": "Rock_Basalt"
    },
    {
      "x": 22,
      "y": 21,
      "z": 11,
      "name": "Rock_Basalt"
    },
    {
      "x": 23,
      "y": 22,
      "z": 7,
      "name": "Rock_Basalt"
    },
    {
      "x": 23,
      "y": 23,
      "z": 7,
      "name": "Rock_Basalt"
    },
    {
      "x": 23,
      "y": 24,
      "z": 7,
      "name": "Soil_Dirt"
    },
    {
      "x": 23,
      "y": 25,
      "z": 7,
      "name": "Soil_Needles"
    },
    {
      "x": 23,
      "y": 26,
      "z": 7,
      "name": "Soil_Needles"
    },
    {
      "x": 23,
      "y": 18,
      "z": 8,
      "name": "Rock_Basalt"
    },
    {
      "x": 23,
      "y": 19,
      "z": 8,
      "name": "Rock_Basalt"
    },
    {
      "x": 23,
      "y": 20,
      "z": 8,
      "name": "Rock_Basalt"
    },
    {
      "x": 23,
      "y": 21,
      "z": 8,
      "name": "Rock_Basalt"
    },
    {
      "x": 23,
      "y": 22,
      "z": 8,
      "name": "Rock_Basalt"
    },
    {
      "x": 23,
      "y": 23,
      "z": 8,
      "name": "Rock_Basalt"
    },
    {
      "x": 23,
      "y": 24,
      "z": 8,
      "name": "Soil_Dirt"
    },
    {
      "x": 23,
      "y": 25,
      "z": 8,
      "name": "Soil_Needles"
    },
    {
      "x": 23,
      "y": 26,
      "z": 8,
      "name": "Soil_Needles"
    },
    {
      "x": 23,
      "y": 27,
      "z": 8,
      "name": "Plant_Moss_Rug_Lime"
    },
    {
      "x": 23,
      "y": 17,
      "z": 9,
      "name": "Rock_Basalt"
    },
    {
      "x": 23,
      "y": 18,
      "z": 9,
      "name": "Rock_Basalt"
    },
    {
      "x": 23,
      "y": 19,
      "z": 9,
      "name": "Rock_Basalt"
    },
    {
      "x": 23,
      "y": 20,
      "z": 9,
      "name": "Rock_Basalt"
    },
    {
      "x": 23,
      "y": 21,
      "z": 9,
      "name": "Rock_Basalt"
    },
    {
      "x": 23,
      "y": 22,
      "z": 9,
      "name": "Rock_Basalt"
    },
    {
      "x": 23,
      "y": 23,
      "z": 9,
      "name": "Rock_Basalt"
    },
    {
      "x": 23,
      "y": 24,
      "z": 9,
      "name": "Soil_Dirt"
    },
    {
      "x": 23,
      "y": 25,
      "z": 9,
      "name": "Soil_Dirt"
    },
    {
      "x": 23,
      "y": 26,
      "z": 9,
      "name": "Soil_Grass"
    },
    {
      "x": 23,
      "y": 27,
      "z": 9,
      "name": "Plant_Grass_Sharp_Tall"
    },
    {
      "x": 23,
      "y": 28,
      "z": 9,
      "name": "Plant_Grass_Sharp_Tall",
      "filler": 1024
    },
    {
      "x": 23,
      "y": 16,
      "z": 10,
      "name": "Rock_Basalt"
    },
    {
      "x": 23,
      "y": 17,
      "z": 10,
      "name": "Rock_Basalt"
    },
    {
      "x": 23,
      "y": 18,
      "z": 10,
      "name": "Rock_Basalt"
    },
    {
      "x": 23,
      "y": 19,
      "z": 10,
      "name": "Rock_Basalt"
    },
    {
      "x": 23,
      "y": 20,
      "z": 10,
      "name": "Rock_Basalt"
    },
    {
      "x": 23,
      "y": 21,
      "z": 10,
      "name": "Rock_Basalt"
    },
    {
      "x": 23,
      "y": 22,
      "z": 10,
      "name": "Rock_Basalt"
    },
    {
      "x": 23,
      "y": 23,
      "z": 10,
      "name": "Rock_Basalt"
    },
    {
      "x": 23,
      "y": 24,
      "z": 10,
      "name": "Soil_Dirt"
    },
    {
      "x": 23,
      "y": 25,
      "z": 10,
      "name": "Soil_Grass"
    },
    {
      "x": 23,
      "y": 26,
      "z": 10,
      "name": "Plant_Grass_Sharp_Tall"
    },
    {
      "x": 23,
      "y": 27,
      "z": 10,
      "name": "Plant_Grass_Sharp_Tall",
      "filler": 1024
    },
    {
      "x": 23,
      "y": 17,
      "z": 11,
      "name": "Rock_Basalt"
    },
    {
      "x": 23,
      "y": 18,
      "z": 11,
      "name": "Rock_Basalt"
    },
    {
      "x": 23,
      "y": 19,
      "z": 11,
      "name": "Rock_Basalt"
    },
    {
      "x": 23,
      "y": 20,
      "z": 11,
      "name": "Rock_Basalt"
    },
    {
      "x": 23,
      "y": 21,
      "z": 11,
      "name": "Rock_Basalt"
    },
    {
      "x": 23,
      "y": 22,
      "z": 11,
      "name": "Rock_Basalt"
    },
    {
      "x": 24,
      "y": 23,
      "z": 7,
      "name": "Rock_Basalt"
    },
    {
      "x": 24,
      "y": 24,
      "z": 7,
      "name": "Soil_Grass"
    },
    {
      "x": 24,
      "y": 20,
      "z": 8,
      "name": "Rock_Basalt"
    },
    {
      "x": 24,
      "y": 21,
      "z": 8,
      "name": "Rock_Basalt"
    },
    {
      "x": 24,
      "y": 22,
      "z": 8,
      "name": "Rock_Basalt"
    },
    {
      "x": 24,
      "y": 23,
      "z": 8,
      "name": "Rock_Basalt"
    },
    {
      "x": 24,
      "y": 24,
      "z": 8,
      "name": "Soil_Dirt"
    },
    {
      "x": 24,
      "y": 25,
      "z": 8,
      "name": "Soil_Grass"
    },
    {
      "x": 24,
      "y": 18,
      "z": 9,
      "name": "Rock_Basalt"
    },
    {
      "x": 24,
      "y": 19,
      "z": 9,
      "name": "Rock_Basalt"
    },
    {
      "x": 24,
      "y": 20,
      "z": 9,
      "name": "Rock_Basalt"
    },
    {
      "x": 24,
      "y": 21,
      "z": 9,
      "name": "Rock_Basalt"
    },
    {
      "x": 24,
      "y": 22,
      "z": 9,
      "name": "Rock_Basalt"
    },
    {
      "x": 24,
      "y": 23,
      "z": 9,
      "name": "Rock_Basalt"
    },
    {
      "x": 24,
      "y": 24,
      "z": 9,
      "name": "Soil_Dirt"
    },
    {
      "x": 24,
      "y": 25,
      "z": 9,
      "name": "Soil_Dirt"
    },
    {
      "x": 24,
      "y": 26,
      "z": 9,
      "name": "Soil_Grass"
    },
    {
      "x": 24,
      "y": 18,
      "z": 10,
      "name": "Rock_Basalt"
    },
    {
      "x": 24,
      "y": 19,
      "z": 10,
      "name": "Rock_Basalt"
    },
    {
      "x": 24,
      "y": 20,
      "z": 10,
      "name": "Rock_Basalt"
    },
    {
      "x": 24,
      "y": 21,
      "z": 10,
      "name": "Rock_Basalt"
    },
    {
      "x": 24,
      "y": 22,
      "z": 10,
      "name": "Rock_Basalt"
    },
    {
      "x": 24,
      "y": 23,
      "z": 10,
      "name": "Soil_Grass"
    },
    {
      "x": 24,
      "y": 18,
      "z": 11,
      "name": "Rock_Basalt"
    },
    {
      "x": 24,
      "y": 19,
      "z": 11,
      "name": "Rock_Basalt"
    },
    {
      "x": 25,
      "y": 20,
      "z": 9,
      "name": "Rock_Basalt"
    },
    {
      "x": 25,
      "y": 21,
      "z": 9,
      "name": "Rock_Basalt"
    },
    {
      "x": 25,
      "y": 22,
      "z": 9,
      "name": "Rock_Basalt"
    },
    {
      "x": 25,
      "y": 21,
      "z": 10,
      "name": "Rock_Basalt"
    },
    {
      "x": 25,
      "y": 22,
      "z": 10,
      "name": "Rock_Basalt"
    }
  ]
}