{
  "version": 8,
  "blockIdVersion": 8,
  "anchorX": 14,
  "anchorY": 15,
  "anchorZ": 4,
  "blocks": [
    {
      "x": 13,
      "y": 14,
      "z": 4,
      "name": "Rock_Volcanic_Cracked_Poisoned"
    },
    {
      "x": 13,
      "y": 15,
      "z": 4,
      "name": "Rock_Volcanic_Cracked_Poisoned"
    },
    {
      "x": 13,
      "y": 16,
      "z": 4,
      "name": "Rock_Volcanic_Cracked_Poisoned"
    },
    {
      "x": 13,
      "y": 15,
      "z": 5,
      "name": "Rock_Volcanic_Cracked_Poisoned"
    },
    {
      "x": 13,
      "y": 16,
      "z": 5,
      "name": "Rock_Volcanic_Cracked_Poisoned"
    },
    {
      "x": 13,
      "y": 17,
      "z": 5,
      "name": "Rock_Volcanic_Cracked_Poisoned"
    },
    {
      "x": 14,
      "y": 13,
      "z": 3,
      "name": "Rock_Volcanic_Cracked_Poisoned"
    },
    {
      "x": 14,
      "y": 14,
      "z": 3,
      "name": "Rock_Volcanic_Cracked_Poisoned"
    },
    {
      "x": 14,
      "y": 15,
      "z": 3,
      "name": "Rock_Volcanic_Cracked_Poisoned"
    },
    {
      "x": 14,
      "y": 16,
      "z": 3,
      "name": "Rock_Volcanic_Cracked_Poisoned"
    },
    {
      "x": 14,
      "y": 17,
      "z": 3,
      "name": "Rock_Volcanic_Cracked_Poisoned"
    },
    {
      "x": 14,
      "y": 14,
      "z": 4,
      "name": "Rock_Volcanic_Cracked_Poisoned"
    },
    {
      "x": 14,
      "y": 15,
      "z": 4,
      "name": "Rock_Volcanic_Cracked_Poisoned"
    },
    {
      "x": 14,
      "y": 16,
      "z": 4,
      "name": "Rock_Volcanic_Cracked_Poisoned"
    },
    {
      "x": 14,
      "y": 17,
      "z": 4,
      "name": "Rock_Volcanic_Cracked_Poisoned"
    },
    {
      "x": 14,
      "y": 18,
      "z": 4,
      "name": "Rock_Volcanic_Cracked_Poisoned"
    },
    {
      "x": 14,
      "y": 15,
      "z": 5,
      "name": "Rock_Volcanic_Cracked_Poisoned"
    },
    {
      "x": 14,
      "y": 16,
      "z": 5,
      "name": "Rock_Volcanic_Cracked_Poisoned"
    },
    {
      "x": 14,
      "y": 17,
      "z": 5,
      "name": "Rock_Volcanic_Cracked_Poisoned"
    },
    {
      "x": 14,
      "y": 18,
      "z": 5,
      "name": "Rock_Volcanic_Cracked_Poisoned"
    },
    {
      "x": 14,
      "y": 19,
      "z": 5,
      "name": "Rock_Volcanic_Cracked_Poisoned"
    },
    {
      "x": 14,
      "y": 18,
      "z": 6,
      "name": "Rock_Volcanic_Cracked_Poisoned"
    },
    {
      "x": 14,
      "y": 19,
      "z": 6,
      "name": "Rock_Volcanic_Cracked_Poisoned"
    },
    {
      "x": 14,
      "y": 20,
      "z": 6,
      "name": "Rock_Volcanic_Cracked_Poisoned"
    },
    {
      "x": 15,
      "y": 14,
      "z": 3,
      "name": "Rock_Volcanic_Cracked_Poisoned"
    },
    {
      "x": 15,
      "y": 15,
      "z": 3,
      "name": "Rock_Volcanic_Cracked_Poisoned"
    },
    {
      "x": 15,
      "y": 16,
      "z": 3,
      "name": "Rock_Volcanic_Cracked_Poisoned"
    },
    {
      "x": 15,
      "y": 14,
      "z": 4,
      "name": "Rock_Volcanic_Cracked_Poisoned"
    },
    {
      "x": 15,
      "y": 16,
      "z": 4,
      "name": "Rock_Volcanic_Cracked_Poisoned"
    },
    {
      "x": 15,
      "y": 17,
      "z": 4,
      "name": "Rock_Volcanic_Cracked_Poisoned"
    },
    {
      "x": 15,
      "y": 18,
      "z": 4,
      "name": "Rock_Volcanic_Cracked_Poisoned"
    },
    {
      "x": 15,
      "y": 15,
      "z": 5,
      "name": "Rock_Volcanic_Cracked_Poisoned"
    },
    {
      "x": 15,
      "y": 16,
      "z": 5,
      "name": "Rock_Volcanic_Cracked_Poisoned"
    },
    {
      "x": 15,
      "y": 17,
      "z": 5,
      "name": "Rock_Volcanic_Cracked_Poisoned"
    },
    {
      "x": 15,
      "y": 18,
      "z": 5,
      "name": "Rock_Volcanic_Cracked_Poisoned"
    },
    {
      "x": 15,
      "y": 19,
      "z": 5,
      "name": "Rock_Volcanic_Cracked_Poisoned"
    },
    {
      "x": 15,
      "y": 20,
      "z": 5,
      "name": "Rock_Volcanic_Cracked_Poisoned"
    },
    {
      "x": 15,
      "y": 21,
      "z": 5,
      "name": "Rock_Volcanic_Cracked_Poisoned"
    },
    {
      "x": 15,
      "y": 17,
      "z": 6,
      "name": "Rock_Volcanic_Cracked_Poisoned"
    },
    {
      "x": 15,
      "y": 18,
      "z": 6,
      "name": "Rock_Volcanic_Cracked_Poisoned"
    },
    {
      "x": 15,
      "y": 19,
      "z": 6,
      "name": "Rock_Volcanic_Cracked_Poisoned"
    },
    {
      "x": 15,
      "y": 20,
      "z": 6,
      "name": "Rock_Volcanic_Cracked_Poisoned"
    },
    {
      "x": 15,
      "y": 21,
      "z": 6,
      "name": "Rock_Volcanic_Cracked_Poisoned"
    },
    {
      "x": 15,
      "y": 22,
      "z": 6,
      "name": "Rock_Volcanic_Cracked_Poisoned"
    },
    {
      "x": 15,
      "y": 19,
      "z": 7,
      "name": "Rock_Volcanic_Cracked_Poisoned"
    },
    {
      "x": 15,
      "y": 20,
      "z": 7,
      "name": "Rock_Volcanic_Cracked_Poisoned"
    },
    {
      "x": 15,
      "y": 21,
      "z": 7,
      "name": "Rock_Volcanic_Cracked_Poisoned"
    },
    {
      "x": 15,
      "y": 22,
      "z": 7,
      "name": "Rock_Volcanic_Cracked_Poisoned"
    },
    {
      "x": 15,
      "y": 23,
      "z": 7,
      "name": "Rock_Volcanic_Cracked_Poisoned"
    },
    {
      "x": 15,
      "y": 24,
      "z": 7,
      "name": "Rock_Volcanic_Cracked_Poisoned"
    },
    {
      "x": 15,
      "y": 21,
      "z": 8,
      "name": "Rock_Volcanic_Cracked_Poisoned"
    },
    {
      "x": 15,
      "y": 22,
      "z": 8,
      "name": "Rock_Volcanic_Cracked_Poisoned"
    },
    {
      "x": 15,
      "y": 23,
      "z": 8,
      "name": "Rock_Volcanic_Cracked_Poisoned"
    },
    {
      "x": 16,
      "y": 16,
      "z": 4,
      "name": "Rock_Volcanic_Cracked_Poisoned"
    },
    {
      "x": 16,
      "y": 17,
      "z": 4,
      "name": "Rock_Volcanic_Cracked_Poisoned"
    },
    {
      "x": 16,
      "y": 16,
      "z": 5,
      "name": "Rock_Volcanic_Cracked_Poisoned"
    },
    {
      "x": 16,
      "y": 17,
      "z": 5,
      "name": "Rock_Volcanic_Cracked_Poisoned"
    },
    {
      "x": 16,
      "y": 18,
      "z": 5,
      "name": "Rock_Volcanic_Cracked_Poisoned"
    },
    {
      "x": 16,
      "y": 19,
      "z": 5,
      "name": "Rock_Volcanic_Cracked_Poisoned"
    },
    {
      "x": 16,
      "y": 20,
      "z": 5,
      "name": "Rock_Volcanic_Cracked_Poisoned"
    },
    {
      "x": 16,
      "y": 17,
      "z": 6,
      "name": "Rock_Volcanic_Cracked_Poisoned"
    },
    {
      "x": 16,
      "y": 18,
      "z": 6,
      "name": "Rock_Volcanic_Cracked_Poisoned"
    },
    {
      "x": 16,
      "y": 19,
      "z": 6,
      "name": "Rock_Volcanic_Cracked_Poisoned"
    },
    {
      "x": 16,
      "y": 20,
      "z": 6,
      "name": "Rock_Volcanic_Cracked_Poisoned"
    },
    {
      "x": 16,
      "y": 21,
      "z": 6,
      "name": "Rock_Volcanic_Cracked_Poisoned"
    },
    {
      "x": 16,
      "y": 22,
      "z": 6,
      "name": "Rock_Volcanic_Cracked_Poisoned"
    },
    {
      "x": 16,
      "y": 23,
      "z": 6,
      "name": "Rock_Volcanic_Cracked_Poisoned"
    },
    {
      "x": 16,
      "y": 19,
      "z": 7,
      "name": "Rock_Volcanic_Cracked_Poisoned"
    },
    {
      "x": 16,
      "y": 20,
      "z": 7,
      "name": "Rock_Volcanic_Cracked_Poisoned"
    },
    {
      "x": 16,
      "y": 21,
      "z": 7,
      "name": "Rock_Volcanic_Cracked_Poisoned"
    },
    {
      "x": 16,
      "y": 22,
      "z": 7,
      "name": "Rock_Volcanic_Cracked_Poisoned"
    },
    {
      "x": 16,
      "y": 23,
      "z": 7,
      "name": "Rock_Volcanic_Cracked_Poisoned"
    },
    {
      "x": 16,
      "y": 24,
      "z": 7,
      "name": "Rock_Volcanic_Cracked_Poisoned"
    },
    {
      "x": 16,
      "y": 25,
      "z": 7,
      "name": "Rock_Volcanic_Cracked_Poisoned"
    },
    {
      "x": 16,
      "y": 26,
      "z": 7,
      "name": "Rock_Volcanic_Cracked_Poisoned"
    },
    {
      "x": 16,
      "y": 27,
      "z": 7,
      "name": "Rock_Volcanic_Cracked_Poisoned"
    },
    {
      "x": 16,
      "y": 28,
      "z": 7,
      "name": "Rock_Volcanic_Cracked_Poisoned"
    },
    {
      "x": 16,
      "y": 29,
      "z": 7,
      "name": "Rock_Volcanic_Cracked_Poisoned"
    },
    {
      "x": 16,
      "y": 30,
      "z": 7,
      "name": "Rock_Volcanic_Cracked_Poisoned"
    },
    {
      "x": 16,
      "y": 31,
      "z": 7,
      "name": "Rock_Volcanic_Cracked_Poisoned"
    },
    {
      "x": 16,
      "y": 20,
      "z": 8,
      "name": "Rock_Volcanic_Cracked_Poisoned"
    },
    {
      "x": 16,
      "y": 21,
      "z": 8,
      "name": "Rock_Volcanic_Cracked_Poisoned"
    },
    {
      "x": 16,
      "y": 22,
      "z": 8,
      "name": "Rock_Volcanic_Cracked_Poisoned"
    },
    {
      "x": 16,
      "y": 23,
      "z": 8,
      "name": "Rock_Volcanic_Cracked_Poisoned"
    },
    {
      "x": 16,
      "y": 24,
      "z": 8,
      "name": "Rock_Volcanic_Cracked_Poisoned"
    },
    {
      "x": 16,
      "y": 25,
      "z": 8,
      "name": "Rock_Volcanic_Cracked_Poisoned"
    },
    {
      "x": 16,
      "y": 26,
      "z": 8,
      "name": "Rock_Volcanic_Cracked_Poisoned"
    },
    {
      "x": 16,
      "y": 27,
      "z": 8,
      "name": "Rock_Volcanic_Cracked_Poisoned"
    },
    {
      "x": 16,
      "y": 22,
      "z": 9,
      "name": "Rock_Volcanic_Cracked_Poisoned"
    },
    {
      "x": 16,
      "y": 23,
      "z": 9,
      "name": "Rock_Volcanic_Cracked_Poisoned"
    },
    {
      "x": 17,
      "y": 19,
      "z": 6,
      "name": "Rock_Volcanic_Cracked_Poisoned"
    },
    {
      "x": 17,
      "y": 20,
      "z": 6,
      "name": "Rock_Volcanic_Cracked_Poisoned"
    },
    {
      "x": 17,
      "y": 18,
      "z": 7,
      "name": "Rock_Volcanic_Cracked_Poisoned"
    },
    {
      "x": 17,
      "y": 19,
      "z": 7,
      "name": "Rock_Volcanic_Cracked_Poisoned"
    },
    {
      "x": 17,
      "y": 20,
      "z": 7,
      "name": "Rock_Volcanic_Cracked_Poisoned"
    },
    {
      "x": 17,
      "y": 21,
      "z": 7,
      "name": "Rock_Volcanic_Cracked_Poisoned"
    },
    {
      "x": 17,
      "y": 22,
      "z": 7,
      "name": "Rock_Volcanic_Cracked_Poisoned"
    },
    {
      "x": 17,
      "y": 23,
      "z": 7,
      "name": "Rock_Volcanic_Cracked_Poisoned"
    },
    {
      "x": 17,
      "y": 24,
      "z": 7,
      "name": "Rock_Volcanic_Cracked_Poisoned"
    },
    {
      "x": 17,
      "y": 25,
      "z": 7,
      "name": "Rock_Volcanic_Cracked_Poisoned"
    },
    {
      "x": 17,
      "y": 26,
      "z": 7,
      "name": "Rock_Volcanic_Cracked_Poisoned"
    },
    {
      "x": 17,
      "y": 20,
      "z": 8,
      "name": "Rock_Volcanic_Cracked_Poisoned"
    },
    {
      "x": 17,
      "y": 21,
      "z": 8,
      "name": "Rock_Volcanic_Cracked_Poisoned"
    },
    {
      "x": 17,
      "y": 22,
      "z": 8,
      "name": "Rock_Volcanic_Cracked_Poisoned"
    },
    {
      "x": 17,
      "y": 23,
      "z": 8,
      "name": "Rock_Volcanic_Cracked_Poisoned"
    },
    {
      "x": 17,
      "y": 24,
      "z": 8,
      "name": "Rock_Volcanic_Cracked_Poisoned"
    },
    {
      "x": 17,
      "y": 25,
      "z": 8,
      "name": "Rock_Volcanic_Cracked_Poisoned"
    },
    {
      "x": 17,
      "y": 23,
      "z": 9,
      "name": "Rock_Volcanic_Cracked_Poisoned"
    },
    {
      "x": 17,
      "y": 24,
      "z": 9,
      "name": "Rock_Volcanic_Cracked_Poisoned"
    },
    {
      "x": 18,
      "y": 21,
      "z": 7,
      "name": "Rock_Volcanic_Cracked_Poisoned"
    },
    {
      "x": 18,
      "y": 22,
      "z": 7,
      "name": "Rock_Volcanic_Cracked_Poisoned"
    },
    {
      "x": 18,
      "y": 23,
      "z": 7,
      "name": "Rock_Volcanic_Cracked_Poisoned"
    },
    {
      "x": 18,
      "y": 22,
      "z": 8,
      "name": "Rock_Volcanic_Cracked_Poisoned"
    },
    {
      "x": 18,
      "y": 23,
      "z": 8,
      "name": "Rock_Volcanic_Cracked_Poisoned"
    },
    {
      "x": 18,
      "y": 24,
      "z": 8,
      "name": "Rock_Volcanic_Cracked_Poisoned"
    },
    {
      "x": 18,
      "y": 25,
      "z": 8,
      "name": "Rock_Volcanic_Cracked_Poisoned"
    },
    {
      "x": 18,
      "y": 26,
      "z": 8,
      "name": "Rock_Volcanic_Cracked_Poisoned"
    },
    {
      "x": 18,
      "y": 24,
      "z": 9,
      "name": "Rock_Volcanic_Cracked_Poisoned"
    },
    {
      "x": 18,
      "y": 25,
      "z": 9,
      "name": "Rock_Volcanic_Cracked_Poisoned"
    },
    {
      "x": 19,
      "y": 22,
      "z": 8,
      "name": "Rock_Volcanic_Cracked_Poisoned"
    },
    {
      "x": 19,
      "y": 23,
      "z": 8,
      "name": "Rock_Volcanic_Cracked_Poisoned"
    },
    {
      "x": 19,
      "y": 24,
      "z": 8,
      "name": "Rock_Volcanic_Cracked_Poisoned"
    },
    {
      "x": 19,
      "y": 23,
      "z": 9,
      "name": "Rock_Volcanic_Cracked_Poisoned"
    },
    {
      "x": 19,
      "y": 24,
      "z": 9,
      "name": "Rock_Volcanic_Cracked_Poisoned"
    },
    {
      "x": 19,
      "y": 25,
      "z": 9,
      "name": "Rock_Volcanic_Cracked_Poisoned"
    },
    {
      "x": 19,
      "y": 26,
      "z": 9,
      "name": "Rock_Volcanic_Cracked_Poisoned"
    },
    {
      "x": 19,
      "y": 27,
      "z": 9,
      "name": "Rock_Volcanic_Cracked_Poisoned"
    },
    {
      "x": 19,
      "y": 28,
      "z": 9,
      "name": "Rock_Volcanic_Cracked_Poisoned"
    }
  ]
}