{
  "version": 8,
  "blockIdVersion": 8,
  "anchorX": 1,
  "anchorY": 3,
  "anchorZ": 0,
  "blocks": [
    {
      "x": -32,
      "y": 0,
      "z": -8,
      "name": "Soil_Hive"
    },
    {
      "x": -32,
      "y": 1,
      "z": -8,
      "name": "Soil_Hive"
    },
    {
      "x": -32,
      "y": 2,
      "z": -8,
      "name": "Soil_Hive"
    },
    {
      "x": -32,
      "y": 3,
      "z": -8,
      "name": "Soil_Hive"
    },
    {
      "x": -32,
      "y": 0,
      "z": 1,
      "name": "Soil_Hive"
    },
    {
      "x": -32,
      "y": 1,
      "z": 1,
      "name": "Soil_Hive"
    },
    {
      "x": -32,
      "y": 2,
      "z": 1,
      "name": "Soil_Hive"
    },
    {
      "x": -32,
      "y": 3,
      "z": 1,
      "name": "Soil_Hive"
    },
    {
      "x": -32,
      "y": 0,
      "z": 2,
      "name": "Soil_Hive"
    },
    {
      "x": -32,
      "y": 1,
      "z": 2,
      "name": "Soil_Hive"
    },
    {
      "x": -32,
      "y": 2,
      "z": 2,
      "name": "Soil_Hive"
    },
    {
      "x": -32,
      "y": 3,
      "z": 2,
      "name": "Soil_Hive"
    },
    {
      "x": -32,
      "y": 0,
      "z": 3,
      "name": "Soil_Hive"
    },
    {
      "x": -32,
      "y": 1,
      "z": 3,
      "name": "Soil_Hive"
    },
    {
      "x": -32,
      "y": 2,
      "z": 3,
      "name": "Soil_Hive"
    },
    {
      "x": -32,
      "y": 3,
      "z": 3,
      "name": "Soil_Hive"
    },
    {
      "x": -32,
      "y": 0,
      "z": 6,
      "name": "Soil_Hive"
    },
    {
      "x": -32,
      "y": 1,
      "z": 6,
      "name": "Soil_Hive"
    },
    {
      "x": -32,
      "y": 2,
      "z": 6,
      "name": "Soil_Hive"
    },
    {
      "x": -32,
      "y": 3,
      "z": 6,
      "name": "Soil_Hive"
    },
    {
      "x": -32,
      "y": 0,
      "z": 8,
      "name": "Soil_Hive"
    },
    {
      "x": -32,
      "y": 1,
      "z": 8,
      "name": "Soil_Hive"
    },
    {
      "x": -32,
      "y": 2,
      "z": 8,
      "name": "Soil_Hive"
    },
    {
      "x": -32,
      "y": 3,
      "z": 8,
      "name": "Soil_Hive"
    },
    {
      "x": -32,
      "y": 0,
      "z": 9,
      "name": "Soil_Hive"
    },
    {
      "x": -32,
      "y": 1,
      "z": 9,
      "name": "Soil_Hive"
    },
    {
      "x": -32,
      "y": 2,
      "z": 9,
      "name": "Soil_Hive"
    },
    {
      "x": -32,
      "y": 3,
      "z": 9,
      "name": "Soil_Hive"
    },
    {
      "x": -31,
      "y": 0,
      "z": -10,
      "name": "Soil_Hive"
    },
    {
      "x": -31,
      "y": 1,
      "z": -10,
      "name": "Soil_Hive"
    },
    {
      "x": -31,
      "y": 2,
      "z": -10,
      "name": "Soil_Hive"
    },
    {
      "x": -31,
      "y": 3,
      "z": -10,
      "name": "Soil_Hive"
    },
    {
      "x": -31,
      "y": 0,
      "z": -9,
      "name": "Soil_Hive"
    },
    {
      "x": -31,
      "y": 1,
      "z": -9,
      "name": "Soil_Hive"
    },
    {
      "x": -31,
      "y": 2,
      "z": -9,
      "name": "Soil_Hive"
    },
    {
      "x": -31,
      "y": 3,
      "z": -9,
      "name": "Soil_Hive"
    },
    {
      "x": -31,
      "y": 0,
      "z": 0,
      "name": "Soil_Hive"
    },
    {
      "x": -31,
      "y": 1,
      "z": 0,
      "name": "Soil_Hive"
    },
    {
      "x": -31,
      "y": 2,
      "z": 0,
      "name": "Soil_Hive"
    },
    {
      "x": -31,
      "y": 3,
      "z": 0,
      "name": "Soil_Hive"
    },
    {
      "x": -31,
      "y": 0,
      "z": 4,
      "name": "Soil_Hive"
    },
    {
      "x": -31,
      "y": 1,
      "z": 4,
      "name": "Soil_Hive"
    },
    {
      "x": -31,
      "y": 2,
      "z": 4,
      "name": "Soil_Hive"
    },
    {
      "x": -31,
      "y": 3,
      "z": 4,
      "name": "Soil_Hive"
    },
    {
      "x": -31,
      "y": 0,
      "z": 5,
      "name": "Soil_Hive"
    },
    {
      "x": -31,
      "y": 1,
      "z": 5,
      "name": "Soil_Hive"
    },
    {
      "x": -31,
      "y": 2,
      "z": 5,
      "name": "Soil_Hive"
    },
    {
      "x": -31,
      "y": 3,
      "z": 5,
      "name": "Soil_Hive"
    },
    {
      "x": -31,
      "y": 0,
      "z": 6,
      "name": "Soil_Hive"
    },
    {
      "x": -31,
      "y": 1,
      "z": 6,
      "name": "Soil_Hive"
    },
    {
      "x": -31,
      "y": 2,
      "z": 6,
      "name": "Soil_Hive"
    },
    {
      "x": -31,
      "y": 3,
      "z": 6,
      "name": "Soil_Hive"
    },
    {
      "x": -31,
      "y": 0,
      "z": 7,
      "name": "Soil_Hive"
    },
    {
      "x": -31,
      "y": 1,
      "z": 7,
      "name": "Soil_Hive"
    },
    {
      "x": -31,
      "y": 2,
      "z": 7,
      "name": "Soil_Hive"
    },
    {
      "x": -31,
      "y": 3,
      "z": 7,
      "name": "Soil_Hive"
    },
    {
      "x": -31,
      "y": 0,
      "z": 8,
      "name": "Soil_Hive"
    },
    {
      "x": -31,
      "y": 1,
      "z": 8,
      "name": "Soil_Hive"
    },
    {
      "x": -31,
      "y": 2,
      "z": 8,
      "name": "Soil_Hive"
    },
    {
      "x": -31,
      "y": 3,
      "z": 8,
      "name": "Soil_Hive"
    },
    {
      "x": -30,
      "y": 0,
      "z": -1,
      "name": "Soil_Hive"
    },
    {
      "x": -30,
      "y": 1,
      "z": -1,
      "name": "Soil_Hive"
    },
    {
      "x": -30,
      "y": 2,
      "z": -1,
      "name": "Soil_Hive"
    },
    {
      "x": -30,
      "y": 3,
      "z": -1,
      "name": "Soil_Hive"
    },
    {
      "x": -30,
      "y": 0,
      "z": 7,
      "name": "Soil_Hive"
    },
    {
      "x": -30,
      "y": 1,
      "z": 7,
      "name": "Soil_Hive"
    },
    {
      "x": -30,
      "y": 2,
      "z": 7,
      "name": "Soil_Hive"
    },
    {
      "x": -30,
      "y": 3,
      "z": 7,
      "name": "Soil_Hive"
    },
    {
      "x": -30,
      "y": 0,
      "z": 8,
      "name": "Soil_Hive"
    },
    {
      "x": -30,
      "y": 1,
      "z": 8,
      "name": "Soil_Hive"
    },
    {
      "x": -30,
      "y": 2,
      "z": 8,
      "name": "Soil_Hive"
    },
    {
      "x": -30,
      "y": 3,
      "z": 8,
      "name": "Soil_Hive"
    },
    {
      "x": -29,
      "y": 0,
      "z": -2,
      "name": "Soil_Hive"
    },
    {
      "x": -29,
      "y": 1,
      "z": -2,
      "name": "Soil_Hive"
    },
    {
      "x": -29,
      "y": 2,
      "z": -2,
      "name": "Soil_Hive"
    },
    {
      "x": -29,
      "y": 3,
      "z": -2,
      "name": "Soil_Hive"
    },
    {
      "x": -29,
      "y": 0,
      "z": -1,
      "name": "Soil_Hive"
    },
    {
      "x": -29,
      "y": 1,
      "z": -1,
      "name": "Soil_Hive"
    },
    {
      "x": -29,
      "y": 2,
      "z": -1,
      "name": "Soil_Hive"
    },
    {
      "x": -29,
      "y": 3,
      "z": -1,
      "name": "Soil_Hive"
    },
    {
      "x": -29,
      "y": 0,
      "z": 7,
      "name": "Soil_Hive"
    },
    {
      "x": -29,
      "y": 1,
      "z": 7,
      "name": "Soil_Hive"
    },
    {
      "x": -29,
      "y": 2,
      "z": 7,
      "name": "Soil_Hive"
    },
    {
      "x": -29,
      "y": 3,
      "z": 7,
      "name": "Soil_Hive"
    },
    {
      "x": -29,
      "y": 0,
      "z": 8,
      "name": "Soil_Hive"
    },
    {
      "x": -29,
      "y": 1,
      "z": 8,
      "name": "Soil_Hive"
    },
    {
      "x": -29,
      "y": 2,
      "z": 8,
      "name": "Soil_Hive"
    },
    {
      "x": -29,
      "y": 3,
      "z": 8,
      "name": "Soil_Hive"
    },
    {
      "x": -28,
      "y": 0,
      "z": -3,
      "name": "Soil_Hive"
    },
    {
      "x": -28,
      "y": 1,
      "z": -3,
      "name": "Soil_Hive"
    },
    {
      "x": -28,
      "y": 2,
      "z": -3,
      "name": "Soil_Hive"
    },
    {
      "x": -28,
      "y": 3,
      "z": -3,
      "name": "Soil_Hive"
    },
    {
      "x": -28,
      "y": 0,
      "z": -2,
      "name": "Soil_Hive"
    },
    {
      "x": -28,
      "y": 1,
      "z": -2,
      "name": "Soil_Hive"
    },
    {
      "x": -28,
      "y": 2,
      "z": -2,
      "name": "Soil_Hive"
    },
    {
      "x": -28,
      "y": 3,
      "z": -2,
      "name": "Soil_Hive"
    },
    {
      "x": -28,
      "y": 0,
      "z": 6,
      "name": "Soil_Hive"
    },
    {
      "x": -28,
      "y": 1,
      "z": 6,
      "name": "Soil_Hive"
    },
    {
      "x": -28,
      "y": 2,
      "z": 6,
      "name": "Soil_Hive"
    },
    {
      "x": -28,
      "y": 3,
      "z": 6,
      "name": "Soil_Hive"
    },
    {
      "x": -28,
      "y": 0,
      "z": 7,
      "name": "Soil_Hive"
    },
    {
      "x": -28,
      "y": 1,
      "z": 7,
      "name": "Soil_Hive"
    },
    {
      "x": -28,
      "y": 2,
      "z": 7,
      "name": "Soil_Hive"
    },
    {
      "x": -28,
      "y": 3,
      "z": 7,
      "name": "Soil_Hive"
    },
    {
      "x": -28,
      "y": 0,
      "z": 8,
      "name": "Soil_Hive"
    },
    {
      "x": -28,
      "y": 1,
      "z": 8,
      "name": "Soil_Hive"
    },
    {
      "x": -28,
      "y": 2,
      "z": 8,
      "name": "Soil_Hive"
    },
    {
      "x": -28,
      "y": 3,
      "z": 8,
      "name": "Soil_Hive"
    },
    {
      "x": -27,
      "y": 0,
      "z": -21,
      "name": "Soil_Hive"
    },
    {
      "x": -27,
      "y": 1,
      "z": -21,
      "name": "Soil_Hive"
    },
    {
      "x": -27,
      "y": 2,
      "z": -21,
      "name": "Soil_Hive"
    },
    {
      "x": -27,
      "y": 3,
      "z": -21,
      "name": "Soil_Hive"
    },
    {
      "x": -27,
      "y": 0,
      "z": -10,
      "name": "Soil_Hive"
    },
    {
      "x": -27,
      "y": 1,
      "z": -10,
      "name": "Soil_Hive"
    },
    {
      "x": -27,
      "y": 2,
      "z": -10,
      "name": "Soil_Hive"
    },
    {
      "x": -27,
      "y": 3,
      "z": -10,
      "name": "Soil_Hive"
    },
    {
      "x": -27,
      "y": 0,
      "z": -9,
      "name": "Soil_Hive"
    },
    {
      "x": -27,
      "y": 1,
      "z": -9,
      "name": "Soil_Hive"
    },
    {
      "x": -27,
      "y": 2,
      "z": -9,
      "name": "Soil_Hive"
    },
    {
      "x": -27,
      "y": 3,
      "z": -9,
      "name": "Soil_Hive"
    },
    {
      "x": -27,
      "y": 0,
      "z": -8,
      "name": "Soil_Hive"
    },
    {
      "x": -27,
      "y": 1,
      "z": -8,
      "name": "Soil_Hive"
    },
    {
      "x": -27,
      "y": 2,
      "z": -8,
      "name": "Soil_Hive"
    },
    {
      "x": -27,
      "y": 3,
      "z": -8,
      "name": "Soil_Hive"
    },
    {
      "x": -27,
      "y": 0,
      "z": -7,
      "name": "Soil_Hive"
    },
    {
      "x": -27,
      "y": 1,
      "z": -7,
      "name": "Soil_Hive"
    },
    {
      "x": -27,
      "y": 2,
      "z": -7,
      "name": "Soil_Hive"
    },
    {
      "x": -27,
      "y": 3,
      "z": -7,
      "name": "Soil_Hive"
    },
    {
      "x": -27,
      "y": 0,
      "z": -6,
      "name": "Soil_Hive"
    },
    {
      "x": -27,
      "y": 1,
      "z": -6,
      "name": "Soil_Hive"
    },
    {
      "x": -27,
      "y": 2,
      "z": -6,
      "name": "Soil_Hive"
    },
    {
      "x": -27,
      "y": 3,
      "z": -6,
      "name": "Soil_Hive"
    },
    {
      "x": -27,
      "y": 0,
      "z": -5,
      "name": "Soil_Hive"
    },
    {
      "x": -27,
      "y": 1,
      "z": -5,
      "name": "Soil_Hive"
    },
    {
      "x": -27,
      "y": 2,
      "z": -5,
      "name": "Soil_Hive"
    },
    {
      "x": -27,
      "y": 3,
      "z": -5,
      "name": "Soil_Hive"
    },
    {
      "x": -27,
      "y": 0,
      "z": -4,
      "name": "Soil_Hive"
    },
    {
      "x": -27,
      "y": 1,
      "z": -4,
      "name": "Soil_Hive"
    },
    {
      "x": -27,
      "y": 2,
      "z": -4,
      "name": "Soil_Hive"
    },
    {
      "x": -27,
      "y": 3,
      "z": -4,
      "name": "Soil_Hive"
    },
    {
      "x": -27,
      "y": 0,
      "z": -3,
      "name": "Soil_Hive"
    },
    {
      "x": -27,
      "y": 1,
      "z": -3,
      "name": "Soil_Hive"
    },
    {
      "x": -27,
      "y": 2,
      "z": -3,
      "name": "Soil_Hive"
    },
    {
      "x": -27,
      "y": 3,
      "z": -3,
      "name": "Soil_Hive"
    },
    {
      "x": -27,
      "y": 0,
      "z": -2,
      "name": "Soil_Hive"
    },
    {
      "x": -27,
      "y": 1,
      "z": -2,
      "name": "Soil_Hive"
    },
    {
      "x": -27,
      "y": 2,
      "z": -2,
      "name": "Soil_Hive"
    },
    {
      "x": -27,
      "y": 3,
      "z": -2,
      "name": "Soil_Hive"
    },
    {
      "x": -27,
      "y": 0,
      "z": 6,
      "name": "Soil_Hive"
    },
    {
      "x": -27,
      "y": 1,
      "z": 6,
      "name": "Soil_Hive"
    },
    {
      "x": -27,
      "y": 2,
      "z": 6,
      "name": "Soil_Hive"
    },
    {
      "x": -27,
      "y": 3,
      "z": 6,
      "name": "Soil_Hive"
    },
    {
      "x": -27,
      "y": 0,
      "z": 7,
      "name": "Soil_Hive"
    },
    {
      "x": -27,
      "y": 1,
      "z": 7,
      "name": "Soil_Hive"
    },
    {
      "x": -27,
      "y": 2,
      "z": 7,
      "name": "Soil_Hive"
    },
    {
      "x": -27,
      "y": 3,
      "z": 7,
      "name": "Soil_Hive"
    },
    {
      "x": -27,
      "y": 0,
      "z": 8,
      "name": "Soil_Hive"
    },
    {
      "x": -27,
      "y": 1,
      "z": 8,
      "name": "Soil_Hive"
    },
    {
      "x": -27,
      "y": 2,
      "z": 8,
      "name": "Soil_Hive"
    },
    {
      "x": -27,
      "y": 3,
      "z": 8,
      "name": "Soil_Hive"
    },
    {
      "x": -26,
      "y": 0,
      "z": -19,
      "name": "Soil_Hive"
    },
    {
      "x": -26,
      "y": 1,
      "z": -19,
      "name": "Soil_Hive"
    },
    {
      "x": -26,
      "y": 2,
      "z": -19,
      "name": "Soil_Hive"
    },
    {
      "x": -26,
      "y": 3,
      "z": -19,
      "name": "Soil_Hive"
    },
    {
      "x": -26,
      "y": 0,
      "z": -18,
      "name": "Soil_Hive"
    },
    {
      "x": -26,
      "y": 1,
      "z": -18,
      "name": "Soil_Hive"
    },
    {
      "x": -26,
      "y": 2,
      "z": -18,
      "name": "Soil_Hive"
    },
    {
      "x": -26,
      "y": 3,
      "z": -18,
      "name": "Soil_Hive"
    },
    {
      "x": -26,
      "y": 0,
      "z": -13,
      "name": "Soil_Hive"
    },
    {
      "x": -26,
      "y": 1,
      "z": -13,
      "name": "Soil_Hive"
    },
    {
      "x": -26,
      "y": 2,
      "z": -13,
      "name": "Soil_Hive"
    },
    {
      "x": -26,
      "y": 3,
      "z": -13,
      "name": "Soil_Hive"
    },
    {
      "x": -26,
      "y": 0,
      "z": -12,
      "name": "Soil_Hive"
    },
    {
      "x": -26,
      "y": 1,
      "z": -12,
      "name": "Soil_Hive"
    },
    {
      "x": -26,
      "y": 2,
      "z": -12,
      "name": "Soil_Hive"
    },
    {
      "x": -26,
      "y": 3,
      "z": -12,
      "name": "Soil_Hive"
    },
    {
      "x": -26,
      "y": 0,
      "z": -11,
      "name": "Soil_Hive"
    },
    {
      "x": -26,
      "y": 1,
      "z": -11,
      "name": "Soil_Hive"
    },
    {
      "x": -26,
      "y": 2,
      "z": -11,
      "name": "Soil_Hive"
    },
    {
      "x": -26,
      "y": 3,
      "z": -11,
      "name": "Soil_Hive"
    },
    {
      "x": -26,
      "y": 0,
      "z": -10,
      "name": "Soil_Hive"
    },
    {
      "x": -26,
      "y": 1,
      "z": -10,
      "name": "Soil_Hive"
    },
    {
      "x": -26,
      "y": 2,
      "z": -10,
      "name": "Soil_Hive"
    },
    {
      "x": -26,
      "y": 3,
      "z": -10,
      "name": "Soil_Hive"
    },
    {
      "x": -26,
      "y": 0,
      "z": -9,
      "name": "Soil_Hive"
    },
    {
      "x": -26,
      "y": 1,
      "z": -9,
      "name": "Soil_Hive"
    },
    {
      "x": -26,
      "y": 2,
      "z": -9,
      "name": "Soil_Hive"
    },
    {
      "x": -26,
      "y": 3,
      "z": -9,
      "name": "Soil_Hive"
    },
    {
      "x": -26,
      "y": 0,
      "z": -8,
      "name": "Soil_Hive"
    },
    {
      "x": -26,
      "y": 1,
      "z": -8,
      "name": "Soil_Hive"
    },
    {
      "x": -26,
      "y": 2,
      "z": -8,
      "name": "Soil_Hive"
    },
    {
      "x": -26,
      "y": 3,
      "z": -8,
      "name": "Soil_Hive"
    },
    {
      "x": -26,
      "y": 0,
      "z": -7,
      "name": "Soil_Hive"
    },
    {
      "x": -26,
      "y": 1,
      "z": -7,
      "name": "Soil_Hive"
    },
    {
      "x": -26,
      "y": 2,
      "z": -7,
      "name": "Soil_Hive"
    },
    {
      "x": -26,
      "y": 3,
      "z": -7,
      "name": "Soil_Hive"
    },
    {
      "x": -26,
      "y": 0,
      "z": -6,
      "name": "Soil_Hive"
    },
    {
      "x": -26,
      "y": 1,
      "z": -6,
      "name": "Soil_Hive"
    },
    {
      "x": -26,
      "y": 2,
      "z": -6,
      "name": "Soil_Hive"
    },
    {
      "x": -26,
      "y": 3,
      "z": -6,
      "name": "Soil_Hive"
    },
    {
      "x": -26,
      "y": 4,
      "z": -6,
      "name": "Soil_Hive"
    },
    {
      "x": -26,
      "y": 0,
      "z": -5,
      "name": "Soil_Hive"
    },
    {
      "x": -26,
      "y": 1,
      "z": -5,
      "name": "Soil_Hive"
    },
    {
      "x": -26,
      "y": 2,
      "z": -5,
      "name": "Soil_Hive"
    },
    {
      "x": -26,
      "y": 3,
      "z": -5,
      "name": "Soil_Hive"
    },
    {
      "x": -26,
      "y": 4,
      "z": -5,
      "name": "Soil_Hive"
    },
    {
      "x": -26,
      "y": 0,
      "z": -4,
      "name": "Soil_Hive"
    },
    {
      "x": -26,
      "y": 1,
      "z": -4,
      "name": "Soil_Hive"
    },
    {
      "x": -26,
      "y": 2,
      "z": -4,
      "name": "Soil_Hive"
    },
    {
      "x": -26,
      "y": 3,
      "z": -4,
      "name": "Soil_Hive"
    },
    {
      "x": -26,
      "y": 4,
      "z": -4,
      "name": "Soil_Hive"
    },
    {
      "x": -26,
      "y": 0,
      "z": -3,
      "name": "Soil_Hive"
    },
    {
      "x": -26,
      "y": 1,
      "z": -3,
      "name": "Soil_Hive"
    },
    {
      "x": -26,
      "y": 2,
      "z": -3,
      "name": "Soil_Hive"
    },
    {
      "x": -26,
      "y": 3,
      "z": -3,
      "name": "Soil_Hive"
    },
    {
      "x": -26,
      "y": 0,
      "z": -2,
      "name": "Soil_Hive"
    },
    {
      "x": -26,
      "y": 1,
      "z": -2,
      "name": "Soil_Hive"
    },
    {
      "x": -26,
      "y": 2,
      "z": -2,
      "name": "Soil_Hive"
    },
    {
      "x": -26,
      "y": 3,
      "z": -2,
      "name": "Soil_Hive"
    },
    {
      "x": -26,
      "y": 0,
      "z": 6,
      "name": "Soil_Hive"
    },
    {
      "x": -26,
      "y": 1,
      "z": 6,
      "name": "Soil_Hive"
    },
    {
      "x": -26,
      "y": 2,
      "z": 6,
      "name": "Soil_Hive"
    },
    {
      "x": -26,
      "y": 3,
      "z": 6,
      "name": "Soil_Hive"
    },
    {
      "x": -26,
      "y": 0,
      "z": 7,
      "name": "Soil_Hive"
    },
    {
      "x": -26,
      "y": 1,
      "z": 7,
      "name": "Soil_Hive"
    },
    {
      "x": -26,
      "y": 2,
      "z": 7,
      "name": "Soil_Hive"
    },
    {
      "x": -26,
      "y": 3,
      "z": 7,
      "name": "Soil_Hive"
    },
    {
      "x": -26,
      "y": 0,
      "z": 8,
      "name": "Soil_Hive"
    },
    {
      "x": -26,
      "y": 1,
      "z": 8,
      "name": "Soil_Hive"
    },
    {
      "x": -26,
      "y": 2,
      "z": 8,
      "name": "Soil_Hive"
    },
    {
      "x": -26,
      "y": 3,
      "z": 8,
      "name": "Soil_Hive"
    },
    {
      "x": -26,
      "y": 0,
      "z": 9,
      "name": "Soil_Hive"
    },
    {
      "x": -26,
      "y": 1,
      "z": 9,
      "name": "Soil_Hive"
    },
    {
      "x": -26,
      "y": 2,
      "z": 9,
      "name": "Soil_Hive"
    },
    {
      "x": -26,
      "y": 3,
      "z": 9,
      "name": "Soil_Hive"
    },
    {
      "x": -25,
      "y": 0,
      "z": -17,
      "name": "Soil_Hive"
    },
    {
      "x": -25,
      "y": 1,
      "z": -17,
      "name": "Soil_Hive"
    },
    {
      "x": -25,
      "y": 2,
      "z": -17,
      "name": "Soil_Hive"
    },
    {
      "x": -25,
      "y": 3,
      "z": -17,
      "name": "Soil_Hive"
    },
    {
      "x": -25,
      "y": 0,
      "z": -16,
      "name": "Soil_Hive"
    },
    {
      "x": -25,
      "y": 1,
      "z": -16,
      "name": "Soil_Hive"
    },
    {
      "x": -25,
      "y": 2,
      "z": -16,
      "name": "Soil_Hive"
    },
    {
      "x": -25,
      "y": 3,
      "z": -16,
      "name": "Soil_Hive"
    },
    {
      "x": -25,
      "y": 0,
      "z": -15,
      "name": "Soil_Hive"
    },
    {
      "x": -25,
      "y": 1,
      "z": -15,
      "name": "Soil_Hive"
    },
    {
      "x": -25,
      "y": 2,
      "z": -15,
      "name": "Soil_Hive"
    },
    {
      "x": -25,
      "y": 3,
      "z": -15,
      "name": "Soil_Hive"
    },
    {
      "x": -25,
      "y": 0,
      "z": -14,
      "name": "Soil_Hive"
    },
    {
      "x": -25,
      "y": 1,
      "z": -14,
      "name": "Soil_Hive"
    },
    {
      "x": -25,
      "y": 2,
      "z": -14,
      "name": "Soil_Hive"
    },
    {
      "x": -25,
      "y": 3,
      "z": -14,
      "name": "Soil_Hive"
    },
    {
      "x": -25,
      "y": 0,
      "z": -13,
      "name": "Soil_Hive"
    },
    {
      "x": -25,
      "y": 1,
      "z": -13,
      "name": "Soil_Hive"
    },
    {
      "x": -25,
      "y": 2,
      "z": -13,
      "name": "Soil_Hive"
    },
    {
      "x": -25,
      "y": 3,
      "z": -13,
      "name": "Soil_Hive"
    },
    {
      "x": -25,
      "y": 0,
      "z": -11,
      "name": "Soil_Hive"
    },
    {
      "x": -25,
      "y": 1,
      "z": -11,
      "name": "Soil_Hive"
    },
    {
      "x": -25,
      "y": 2,
      "z": -11,
      "name": "Soil_Hive"
    },
    {
      "x": -25,
      "y": 3,
      "z": -11,
      "name": "Soil_Hive"
    },
    {
      "x": -25,
      "y": 0,
      "z": -10,
      "name": "Soil_Hive"
    },
    {
      "x": -25,
      "y": 1,
      "z": -10,
      "name": "Soil_Hive"
    },
    {
      "x": -25,
      "y": 2,
      "z": -10,
      "name": "Soil_Hive"
    },
    {
      "x": -25,
      "y": 3,
      "z": -10,
      "name": "Soil_Hive"
    },
    {
      "x": -25,
      "y": 0,
      "z": -9,
      "name": "Soil_Hive"
    },
    {
      "x": -25,
      "y": 1,
      "z": -9,
      "name": "Soil_Hive"
    },
    {
      "x": -25,
      "y": 2,
      "z": -9,
      "name": "Soil_Hive"
    },
    {
      "x": -25,
      "y": 3,
      "z": -9,
      "name": "Soil_Hive"
    },
    {
      "x": -25,
      "y": 0,
      "z": -8,
      "name": "Soil_Hive"
    },
    {
      "x": -25,
      "y": 1,
      "z": -8,
      "name": "Soil_Hive"
    },
    {
      "x": -25,
      "y": 2,
      "z": -8,
      "name": "Soil_Hive"
    },
    {
      "x": -25,
      "y": 3,
      "z": -8,
      "name": "Soil_Hive"
    },
    {
      "x": -25,
      "y": 0,
      "z": -7,
      "name": "Soil_Hive"
    },
    {
      "x": -25,
      "y": 1,
      "z": -7,
      "name": "Soil_Hive"
    },
    {
      "x": -25,
      "y": 2,
      "z": -7,
      "name": "Soil_Hive"
    },
    {
      "x": -25,
      "y": 3,
      "z": -7,
      "name": "Soil_Hive"
    },
    {
      "x": -25,
      "y": 0,
      "z": -6,
      "name": "Soil_Hive"
    },
    {
      "x": -25,
      "y": 1,
      "z": -6,
      "name": "Soil_Hive"
    },
    {
      "x": -25,
      "y": 2,
      "z": -6,
      "name": "Soil_Hive"
    },
    {
      "x": -25,
      "y": 3,
      "z": -6,
      "name": "Soil_Hive"
    },
    {
      "x": -25,
      "y": 0,
      "z": -5,
      "name": "Soil_Hive"
    },
    {
      "x": -25,
      "y": 1,
      "z": -5,
      "name": "Soil_Hive"
    },
    {
      "x": -25,
      "y": 2,
      "z": -5,
      "name": "Soil_Hive"
    },
    {
      "x": -25,
      "y": 3,
      "z": -5,
      "name": "Soil_Hive"
    },
    {
      "x": -25,
      "y": 0,
      "z": -4,
      "name": "Soil_Hive"
    },
    {
      "x": -25,
      "y": 1,
      "z": -4,
      "name": "Soil_Hive"
    },
    {
      "x": -25,
      "y": 2,
      "z": -4,
      "name": "Soil_Hive"
    },
    {
      "x": -25,
      "y": 3,
      "z": -4,
      "name": "Soil_Hive"
    },
    {
      "x": -25,
      "y": 0,
      "z": -3,
      "name": "Soil_Hive"
    },
    {
      "x": -25,
      "y": 1,
      "z": -3,
      "name": "Soil_Hive"
    },
    {
      "x": -25,
      "y": 2,
      "z": -3,
      "name": "Soil_Hive"
    },
    {
      "x": -25,
      "y": 3,
      "z": -3,
      "name": "Soil_Hive"
    },
    {
      "x": -25,
      "y": 0,
      "z": -2,
      "name": "Soil_Hive"
    },
    {
      "x": -25,
      "y": 1,
      "z": -2,
      "name": "Soil_Hive"
    },
    {
      "x": -25,
      "y": 2,
      "z": -2,
      "name": "Soil_Hive"
    },
    {
      "x": -25,
      "y": 3,
      "z": -2,
      "name": "Soil_Hive"
    },
    {
      "x": -25,
      "y": 0,
      "z": -1,
      "name": "Soil_Hive"
    },
    {
      "x": -25,
      "y": 1,
      "z": -1,
      "name": "Soil_Hive"
    },
    {
      "x": -25,
      "y": 2,
      "z": -1,
      "name": "Soil_Hive"
    },
    {
      "x": -25,
      "y": 3,
      "z": -1,
      "name": "Soil_Hive"
    },
    {
      "x": -25,
      "y": 0,
      "z": 0,
      "name": "Soil_Hive"
    },
    {
      "x": -25,
      "y": 1,
      "z": 0,
      "name": "Soil_Hive"
    },
    {
      "x": -25,
      "y": 2,
      "z": 0,
      "name": "Soil_Hive"
    },
    {
      "x": -25,
      "y": 3,
      "z": 0,
      "name": "Soil_Hive"
    },
    {
      "x": -25,
      "y": 0,
      "z": 1,
      "name": "Soil_Hive"
    },
    {
      "x": -25,
      "y": 1,
      "z": 1,
      "name": "Soil_Hive"
    },
    {
      "x": -25,
      "y": 2,
      "z": 1,
      "name": "Soil_Hive"
    },
    {
      "x": -25,
      "y": 3,
      "z": 1,
      "name": "Soil_Hive"
    },
    {
      "x": -25,
      "y": 0,
      "z": 2,
      "name": "Soil_Hive"
    },
    {
      "x": -25,
      "y": 1,
      "z": 2,
      "name": "Soil_Hive"
    },
    {
      "x": -25,
      "y": 2,
      "z": 2,
      "name": "Soil_Hive"
    },
    {
      "x": -25,
      "y": 3,
      "z": 2,
      "name": "Soil_Hive"
    },
    {
      "x": -25,
      "y": 0,
      "z": 3,
      "name": "Soil_Hive"
    },
    {
      "x": -25,
      "y": 1,
      "z": 3,
      "name": "Soil_Hive"
    },
    {
      "x": -25,
      "y": 2,
      "z": 3,
      "name": "Soil_Hive"
    },
    {
      "x": -25,
      "y": 3,
      "z": 3,
      "name": "Soil_Hive"
    },
    {
      "x": -25,
      "y": 0,
      "z": 4,
      "name": "Soil_Hive"
    },
    {
      "x": -25,
      "y": 1,
      "z": 4,
      "name": "Soil_Hive"
    },
    {
      "x": -25,
      "y": 2,
      "z": 4,
      "name": "Soil_Hive"
    },
    {
      "x": -25,
      "y": 3,
      "z": 4,
      "name": "Soil_Hive"
    },
    {
      "x": -25,
      "y": 0,
      "z": 5,
      "name": "Soil_Hive"
    },
    {
      "x": -25,
      "y": 1,
      "z": 5,
      "name": "Soil_Hive"
    },
    {
      "x": -25,
      "y": 2,
      "z": 5,
      "name": "Soil_Hive"
    },
    {
      "x": -25,
      "y": 3,
      "z": 5,
      "name": "Soil_Hive"
    },
    {
      "x": -25,
      "y": 0,
      "z": 6,
      "name": "Soil_Hive"
    },
    {
      "x": -25,
      "y": 1,
      "z": 6,
      "name": "Soil_Hive"
    },
    {
      "x": -25,
      "y": 2,
      "z": 6,
      "name": "Soil_Hive"
    },
    {
      "x": -25,
      "y": 3,
      "z": 6,
      "name": "Soil_Hive"
    },
    {
      "x": -25,
      "y": 0,
      "z": 7,
      "name": "Soil_Hive"
    },
    {
      "x": -25,
      "y": 1,
      "z": 7,
      "name": "Soil_Hive"
    },
    {
      "x": -25,
      "y": 2,
      "z": 7,
      "name": "Soil_Hive"
    },
    {
      "x": -25,
      "y": 3,
      "z": 7,
      "name": "Soil_Hive"
    },
    {
      "x": -25,
      "y": 0,
      "z": 8,
      "name": "Soil_Hive"
    },
    {
      "x": -25,
      "y": 1,
      "z": 8,
      "name": "Soil_Hive"
    },
    {
      "x": -25,
      "y": 2,
      "z": 8,
      "name": "Soil_Hive"
    },
    {
      "x": -25,
      "y": 3,
      "z": 8,
      "name": "Soil_Hive"
    },
    {
      "x": -25,
      "y": 0,
      "z": 9,
      "name": "Soil_Hive"
    },
    {
      "x": -25,
      "y": 1,
      "z": 9,
      "name": "Soil_Hive"
    },
    {
      "x": -25,
      "y": 2,
      "z": 9,
      "name": "Soil_Hive"
    },
    {
      "x": -25,
      "y": 3,
      "z": 9,
      "name": "Soil_Hive"
    },
    {
      "x": -25,
      "y": 0,
      "z": 18,
      "name": "Soil_Hive"
    },
    {
      "x": -25,
      "y": 1,
      "z": 18,
      "name": "Soil_Hive"
    },
    {
      "x": -25,
      "y": 2,
      "z": 18,
      "name": "Soil_Hive"
    },
    {
      "x": -25,
      "y": 3,
      "z": 18,
      "name": "Soil_Hive"
    },
    {
      "x": -25,
      "y": 0,
      "z": 19,
      "name": "Soil_Hive"
    },
    {
      "x": -25,
      "y": 1,
      "z": 19,
      "name": "Soil_Hive"
    },
    {
      "x": -25,
      "y": 2,
      "z": 19,
      "name": "Soil_Hive"
    },
    {
      "x": -25,
      "y": 3,
      "z": 19,
      "name": "Soil_Hive"
    },
    {
      "x": -24,
      "y": 0,
      "z": -9,
      "name": "Soil_Hive"
    },
    {
      "x": -24,
      "y": 1,
      "z": -9,
      "name": "Soil_Hive"
    },
    {
      "x": -24,
      "y": 2,
      "z": -9,
      "name": "Soil_Hive"
    },
    {
      "x": -24,
      "y": 3,
      "z": -9,
      "name": "Soil_Hive"
    },
    {
      "x": -24,
      "y": 0,
      "z": -8,
      "name": "Soil_Hive"
    },
    {
      "x": -24,
      "y": 1,
      "z": -8,
      "name": "Soil_Hive"
    },
    {
      "x": -24,
      "y": 2,
      "z": -8,
      "name": "Soil_Hive"
    },
    {
      "x": -24,
      "y": 3,
      "z": -8,
      "name": "Soil_Hive"
    },
    {
      "x": -24,
      "y": 0,
      "z": -7,
      "name": "Soil_Hive"
    },
    {
      "x": -24,
      "y": 1,
      "z": -7,
      "name": "Soil_Hive"
    },
    {
      "x": -24,
      "y": 2,
      "z": -7,
      "name": "Soil_Hive"
    },
    {
      "x": -24,
      "y": 3,
      "z": -7,
      "name": "Soil_Hive"
    },
    {
      "x": -24,
      "y": 0,
      "z": -6,
      "name": "Soil_Hive"
    },
    {
      "x": -24,
      "y": 1,
      "z": -6,
      "name": "Soil_Hive"
    },
    {
      "x": -24,
      "y": 2,
      "z": -6,
      "name": "Soil_Hive"
    },
    {
      "x": -24,
      "y": 3,
      "z": -6,
      "name": "Soil_Hive"
    },
    {
      "x": -24,
      "y": 0,
      "z": -5,
      "name": "Soil_Hive"
    },
    {
      "x": -24,
      "y": 1,
      "z": -5,
      "name": "Soil_Hive"
    },
    {
      "x": -24,
      "y": 2,
      "z": -5,
      "name": "Soil_Hive"
    },
    {
      "x": -24,
      "y": 3,
      "z": -5,
      "name": "Soil_Hive"
    },
    {
      "x": -24,
      "y": 0,
      "z": -4,
      "name": "Soil_Hive"
    },
    {
      "x": -24,
      "y": 1,
      "z": -4,
      "name": "Soil_Hive"
    },
    {
      "x": -24,
      "y": 2,
      "z": -4,
      "name": "Soil_Hive"
    },
    {
      "x": -24,
      "y": 3,
      "z": -4,
      "name": "Soil_Hive"
    },
    {
      "x": -24,
      "y": 0,
      "z": -3,
      "name": "Soil_Hive"
    },
    {
      "x": -24,
      "y": 1,
      "z": -3,
      "name": "Soil_Hive"
    },
    {
      "x": -24,
      "y": 2,
      "z": -3,
      "name": "Soil_Hive"
    },
    {
      "x": -24,
      "y": 3,
      "z": -3,
      "name": "Soil_Hive"
    },
    {
      "x": -24,
      "y": 0,
      "z": -2,
      "name": "Soil_Hive"
    },
    {
      "x": -24,
      "y": 1,
      "z": -2,
      "name": "Soil_Hive"
    },
    {
      "x": -24,
      "y": 2,
      "z": -2,
      "name": "Soil_Hive"
    },
    {
      "x": -24,
      "y": 3,
      "z": -2,
      "name": "Soil_Hive"
    },
    {
      "x": -24,
      "y": 0,
      "z": -1,
      "name": "Soil_Hive"
    },
    {
      "x": -24,
      "y": 1,
      "z": -1,
      "name": "Soil_Hive"
    },
    {
      "x": -24,
      "y": 2,
      "z": -1,
      "name": "Soil_Hive"
    },
    {
      "x": -24,
      "y": 3,
      "z": -1,
      "name": "Soil_Hive"
    },
    {
      "x": -24,
      "y": 0,
      "z": 0,
      "name": "Soil_Hive"
    },
    {
      "x": -24,
      "y": 1,
      "z": 0,
      "name": "Soil_Hive"
    },
    {
      "x": -24,
      "y": 2,
      "z": 0,
      "name": "Soil_Hive"
    },
    {
      "x": -24,
      "y": 3,
      "z": 0,
      "name": "Soil_Hive"
    },
    {
      "x": -24,
      "y": 0,
      "z": 1,
      "name": "Soil_Hive"
    },
    {
      "x": -24,
      "y": 1,
      "z": 1,
      "name": "Soil_Hive"
    },
    {
      "x": -24,
      "y": 2,
      "z": 1,
      "name": "Soil_Hive"
    },
    {
      "x": -24,
      "y": 3,
      "z": 1,
      "name": "Soil_Hive"
    },
    {
      "x": -24,
      "y": 4,
      "z": 1,
      "name": "Soil_Hive"
    },
    {
      "x": -24,
      "y": 0,
      "z": 2,
      "name": "Soil_Hive"
    },
    {
      "x": -24,
      "y": 1,
      "z": 2,
      "name": "Soil_Hive"
    },
    {
      "x": -24,
      "y": 2,
      "z": 2,
      "name": "Soil_Hive"
    },
    {
      "x": -24,
      "y": 3,
      "z": 2,
      "name": "Soil_Hive"
    },
    {
      "x": -24,
      "y": 0,
      "z": 3,
      "name": "Soil_Hive"
    },
    {
      "x": -24,
      "y": 1,
      "z": 3,
      "name": "Soil_Hive"
    },
    {
      "x": -24,
      "y": 2,
      "z": 3,
      "name": "Soil_Hive"
    },
    {
      "x": -24,
      "y": 3,
      "z": 3,
      "name": "Soil_Hive"
    },
    {
      "x": -24,
      "y": 0,
      "z": 4,
      "name": "Soil_Hive"
    },
    {
      "x": -24,
      "y": 1,
      "z": 4,
      "name": "Soil_Hive"
    },
    {
      "x": -24,
      "y": 2,
      "z": 4,
      "name": "Soil_Hive"
    },
    {
      "x": -24,
      "y": 3,
      "z": 4,
      "name": "Soil_Hive"
    },
    {
      "x": -24,
      "y": 0,
      "z": 5,
      "name": "Soil_Hive"
    },
    {
      "x": -24,
      "y": 1,
      "z": 5,
      "name": "Soil_Hive"
    },
    {
      "x": -24,
      "y": 2,
      "z": 5,
      "name": "Soil_Hive"
    },
    {
      "x": -24,
      "y": 3,
      "z": 5,
      "name": "Soil_Hive"
    },
    {
      "x": -24,
      "y": 4,
      "z": 5,
      "name": "Soil_Hive"
    },
    {
      "x": -24,
      "y": 0,
      "z": 6,
      "name": "Soil_Hive"
    },
    {
      "x": -24,
      "y": 1,
      "z": 6,
      "name": "Soil_Hive"
    },
    {
      "x": -24,
      "y": 2,
      "z": 6,
      "name": "Soil_Hive"
    },
    {
      "x": -24,
      "y": 3,
      "z": 6,
      "name": "Soil_Hive"
    },
    {
      "x": -24,
      "y": 0,
      "z": 7,
      "name": "Soil_Hive"
    },
    {
      "x": -24,
      "y": 1,
      "z": 7,
      "name": "Soil_Hive"
    },
    {
      "x": -24,
      "y": 2,
      "z": 7,
      "name": "Soil_Hive"
    },
    {
      "x": -24,
      "y": 3,
      "z": 7,
      "name": "Soil_Hive"
    },
    {
      "x": -24,
      "y": 0,
      "z": 8,
      "name": "Soil_Hive"
    },
    {
      "x": -24,
      "y": 1,
      "z": 8,
      "name": "Soil_Hive"
    },
    {
      "x": -24,
      "y": 2,
      "z": 8,
      "name": "Soil_Hive"
    },
    {
      "x": -24,
      "y": 3,
      "z": 8,
      "name": "Soil_Hive"
    },
    {
      "x": -24,
      "y": 0,
      "z": 16,
      "name": "Soil_Hive"
    },
    {
      "x": -24,
      "y": 1,
      "z": 16,
      "name": "Soil_Hive"
    },
    {
      "x": -24,
      "y": 2,
      "z": 16,
      "name": "Soil_Hive"
    },
    {
      "x": -24,
      "y": 3,
      "z": 16,
      "name": "Soil_Hive"
    },
    {
      "x": -24,
      "y": 0,
      "z": 17,
      "name": "Soil_Hive"
    },
    {
      "x": -24,
      "y": 1,
      "z": 17,
      "name": "Soil_Hive"
    },
    {
      "x": -24,
      "y": 2,
      "z": 17,
      "name": "Soil_Hive"
    },
    {
      "x": -24,
      "y": 3,
      "z": 17,
      "name": "Soil_Hive"
    },
    {
      "x": -23,
      "y": 0,
      "z": -9,
      "name": "Soil_Hive"
    },
    {
      "x": -23,
      "y": 1,
      "z": -9,
      "name": "Soil_Hive"
    },
    {
      "x": -23,
      "y": 2,
      "z": -9,
      "name": "Soil_Hive"
    },
    {
      "x": -23,
      "y": 3,
      "z": -9,
      "name": "Soil_Hive"
    },
    {
      "x": -23,
      "y": 0,
      "z": -8,
      "name": "Soil_Hive"
    },
    {
      "x": -23,
      "y": 1,
      "z": -8,
      "name": "Soil_Hive"
    },
    {
      "x": -23,
      "y": 2,
      "z": -8,
      "name": "Soil_Hive"
    },
    {
      "x": -23,
      "y": 3,
      "z": -8,
      "name": "Soil_Hive"
    },
    {
      "x": -23,
      "y": 4,
      "z": -8,
      "name": "Soil_Hive"
    },
    {
      "x": -23,
      "y": 0,
      "z": -7,
      "name": "Soil_Hive"
    },
    {
      "x": -23,
      "y": 1,
      "z": -7,
      "name": "Soil_Hive"
    },
    {
      "x": -23,
      "y": 2,
      "z": -7,
      "name": "Soil_Hive"
    },
    {
      "x": -23,
      "y": 3,
      "z": -7,
      "name": "Soil_Hive"
    },
    {
      "x": -23,
      "y": 4,
      "z": -7,
      "name": "Soil_Hive"
    },
    {
      "x": -23,
      "y": 0,
      "z": -6,
      "name": "Soil_Hive"
    },
    {
      "x": -23,
      "y": 1,
      "z": -6,
      "name": "Soil_Hive"
    },
    {
      "x": -23,
      "y": 2,
      "z": -6,
      "name": "Soil_Hive"
    },
    {
      "x": -23,
      "y": 3,
      "z": -6,
      "name": "Soil_Hive"
    },
    {
      "x": -23,
      "y": 0,
      "z": -5,
      "name": "Soil_Hive"
    },
    {
      "x": -23,
      "y": 1,
      "z": -5,
      "name": "Soil_Hive"
    },
    {
      "x": -23,
      "y": 2,
      "z": -5,
      "name": "Soil_Hive"
    },
    {
      "x": -23,
      "y": 3,
      "z": -5,
      "name": "Soil_Hive"
    },
    {
      "x": -23,
      "y": 0,
      "z": -4,
      "name": "Soil_Hive"
    },
    {
      "x": -23,
      "y": 1,
      "z": -4,
      "name": "Soil_Hive"
    },
    {
      "x": -23,
      "y": 2,
      "z": -4,
      "name": "Soil_Hive"
    },
    {
      "x": -23,
      "y": 3,
      "z": -4,
      "name": "Soil_Hive"
    },
    {
      "x": -23,
      "y": 0,
      "z": -3,
      "name": "Soil_Hive"
    },
    {
      "x": -23,
      "y": 1,
      "z": -3,
      "name": "Soil_Hive"
    },
    {
      "x": -23,
      "y": 2,
      "z": -3,
      "name": "Soil_Hive"
    },
    {
      "x": -23,
      "y": 3,
      "z": -3,
      "name": "Soil_Hive"
    },
    {
      "x": -23,
      "y": 0,
      "z": -2,
      "name": "Soil_Hive"
    },
    {
      "x": -23,
      "y": 1,
      "z": -2,
      "name": "Soil_Hive"
    },
    {
      "x": -23,
      "y": 2,
      "z": -2,
      "name": "Soil_Hive"
    },
    {
      "x": -23,
      "y": 3,
      "z": -2,
      "name": "Soil_Hive"
    },
    {
      "x": -23,
      "y": 0,
      "z": -1,
      "name": "Soil_Hive"
    },
    {
      "x": -23,
      "y": 1,
      "z": -1,
      "name": "Soil_Hive"
    },
    {
      "x": -23,
      "y": 2,
      "z": -1,
      "name": "Soil_Hive"
    },
    {
      "x": -23,
      "y": 3,
      "z": -1,
      "name": "Soil_Hive"
    },
    {
      "x": -23,
      "y": 0,
      "z": 0,
      "name": "Soil_Hive"
    },
    {
      "x": -23,
      "y": 1,
      "z": 0,
      "name": "Soil_Hive"
    },
    {
      "x": -23,
      "y": 2,
      "z": 0,
      "name": "Soil_Hive"
    },
    {
      "x": -23,
      "y": 3,
      "z": 0,
      "name": "Soil_Hive"
    },
    {
      "x": -23,
      "y": 0,
      "z": 1,
      "name": "Soil_Hive"
    },
    {
      "x": -23,
      "y": 1,
      "z": 1,
      "name": "Soil_Hive"
    },
    {
      "x": -23,
      "y": 2,
      "z": 1,
      "name": "Soil_Hive"
    },
    {
      "x": -23,
      "y": 3,
      "z": 1,
      "name": "Soil_Hive"
    },
    {
      "x": -23,
      "y": 0,
      "z": 2,
      "name": "Soil_Hive"
    },
    {
      "x": -23,
      "y": 1,
      "z": 2,
      "name": "Soil_Hive"
    },
    {
      "x": -23,
      "y": 2,
      "z": 2,
      "name": "Soil_Hive"
    },
    {
      "x": -23,
      "y": 3,
      "z": 2,
      "name": "Soil_Hive"
    },
    {
      "x": -23,
      "y": 0,
      "z": 3,
      "name": "Soil_Hive"
    },
    {
      "x": -23,
      "y": 1,
      "z": 3,
      "name": "Soil_Hive"
    },
    {
      "x": -23,
      "y": 2,
      "z": 3,
      "name": "Soil_Hive"
    },
    {
      "x": -23,
      "y": 3,
      "z": 3,
      "name": "Soil_Hive"
    },
    {
      "x": -23,
      "y": 0,
      "z": 4,
      "name": "Soil_Hive"
    },
    {
      "x": -23,
      "y": 1,
      "z": 4,
      "name": "Soil_Hive"
    },
    {
      "x": -23,
      "y": 2,
      "z": 4,
      "name": "Soil_Hive"
    },
    {
      "x": -23,
      "y": 3,
      "z": 4,
      "name": "Soil_Hive"
    },
    {
      "x": -23,
      "y": 0,
      "z": 5,
      "name": "Soil_Hive"
    },
    {
      "x": -23,
      "y": 1,
      "z": 5,
      "name": "Soil_Hive"
    },
    {
      "x": -23,
      "y": 2,
      "z": 5,
      "name": "Soil_Hive"
    },
    {
      "x": -23,
      "y": 3,
      "z": 5,
      "name": "Soil_Hive"
    },
    {
      "x": -23,
      "y": 0,
      "z": 6,
      "name": "Soil_Hive"
    },
    {
      "x": -23,
      "y": 1,
      "z": 6,
      "name": "Soil_Hive"
    },
    {
      "x": -23,
      "y": 2,
      "z": 6,
      "name": "Soil_Hive"
    },
    {
      "x": -23,
      "y": 3,
      "z": 6,
      "name": "Soil_Hive"
    },
    {
      "x": -23,
      "y": 4,
      "z": 6,
      "name": "Soil_Hive"
    },
    {
      "x": -23,
      "y": 0,
      "z": 7,
      "name": "Soil_Hive"
    },
    {
      "x": -23,
      "y": 1,
      "z": 7,
      "name": "Soil_Hive"
    },
    {
      "x": -23,
      "y": 2,
      "z": 7,
      "name": "Soil_Hive"
    },
    {
      "x": -23,
      "y": 3,
      "z": 7,
      "name": "Soil_Hive"
    },
    {
      "x": -23,
      "y": 0,
      "z": 8,
      "name": "Soil_Hive"
    },
    {
      "x": -23,
      "y": 1,
      "z": 8,
      "name": "Soil_Hive"
    },
    {
      "x": -23,
      "y": 2,
      "z": 8,
      "name": "Soil_Hive"
    },
    {
      "x": -23,
      "y": 3,
      "z": 8,
      "name": "Soil_Hive"
    },
    {
      "x": -23,
      "y": 0,
      "z": 9,
      "name": "Soil_Hive"
    },
    {
      "x": -23,
      "y": 1,
      "z": 9,
      "name": "Soil_Hive"
    },
    {
      "x": -23,
      "y": 2,
      "z": 9,
      "name": "Soil_Hive"
    },
    {
      "x": -23,
      "y": 3,
      "z": 9,
      "name": "Soil_Hive"
    },
    {
      "x": -23,
      "y": 0,
      "z": 15,
      "name": "Soil_Hive"
    },
    {
      "x": -23,
      "y": 1,
      "z": 15,
      "name": "Soil_Hive"
    },
    {
      "x": -23,
      "y": 2,
      "z": 15,
      "name": "Soil_Hive"
    },
    {
      "x": -23,
      "y": 3,
      "z": 15,
      "name": "Soil_Hive"
    },
    {
      "x": -23,
      "y": 0,
      "z": 16,
      "name": "Soil_Hive"
    },
    {
      "x": -23,
      "y": 1,
      "z": 16,
      "name": "Soil_Hive"
    },
    {
      "x": -23,
      "y": 2,
      "z": 16,
      "name": "Soil_Hive"
    },
    {
      "x": -23,
      "y": 3,
      "z": 16,
      "name": "Soil_Hive"
    },
    {
      "x": -23,
      "y": 0,
      "z": 17,
      "name": "Soil_Hive"
    },
    {
      "x": -23,
      "y": 1,
      "z": 17,
      "name": "Soil_Hive"
    },
    {
      "x": -23,
      "y": 2,
      "z": 17,
      "name": "Soil_Hive"
    },
    {
      "x": -23,
      "y": 3,
      "z": 17,
      "name": "Soil_Hive"
    },
    {
      "x": -22,
      "y": 0,
      "z": -10,
      "name": "Soil_Hive"
    },
    {
      "x": -22,
      "y": 1,
      "z": -10,
      "name": "Soil_Hive"
    },
    {
      "x": -22,
      "y": 2,
      "z": -10,
      "name": "Soil_Hive"
    },
    {
      "x": -22,
      "y": 3,
      "z": -10,
      "name": "Soil_Hive"
    },
    {
      "x": -22,
      "y": 0,
      "z": -9,
      "name": "Soil_Hive"
    },
    {
      "x": -22,
      "y": 1,
      "z": -9,
      "name": "Soil_Hive"
    },
    {
      "x": -22,
      "y": 2,
      "z": -9,
      "name": "Soil_Hive"
    },
    {
      "x": -22,
      "y": 3,
      "z": -9,
      "name": "Soil_Hive"
    },
    {
      "x": -22,
      "y": 4,
      "z": -9,
      "name": "Soil_Hive"
    },
    {
      "x": -22,
      "y": 0,
      "z": -8,
      "name": "Soil_Hive"
    },
    {
      "x": -22,
      "y": 1,
      "z": -8,
      "name": "Soil_Hive"
    },
    {
      "x": -22,
      "y": 2,
      "z": -8,
      "name": "Soil_Hive"
    },
    {
      "x": -22,
      "y": 3,
      "z": -8,
      "name": "Soil_Hive"
    },
    {
      "x": -22,
      "y": 0,
      "z": -7,
      "name": "Soil_Hive"
    },
    {
      "x": -22,
      "y": 1,
      "z": -7,
      "name": "Soil_Hive"
    },
    {
      "x": -22,
      "y": 2,
      "z": -7,
      "name": "Soil_Hive"
    },
    {
      "x": -22,
      "y": 3,
      "z": -7,
      "name": "Soil_Hive"
    },
    {
      "x": -22,
      "y": 4,
      "z": -7,
      "name": "Soil_Hive"
    },
    {
      "x": -22,
      "y": 0,
      "z": -6,
      "name": "Soil_Hive"
    },
    {
      "x": -22,
      "y": 1,
      "z": -6,
      "name": "Soil_Hive"
    },
    {
      "x": -22,
      "y": 2,
      "z": -6,
      "name": "Soil_Hive"
    },
    {
      "x": -22,
      "y": 3,
      "z": -6,
      "name": "Soil_Hive"
    },
    {
      "x": -22,
      "y": 4,
      "z": -6,
      "name": "Soil_Hive"
    },
    {
      "x": -22,
      "y": 0,
      "z": -5,
      "name": "Soil_Hive"
    },
    {
      "x": -22,
      "y": 1,
      "z": -5,
      "name": "Soil_Hive"
    },
    {
      "x": -22,
      "y": 2,
      "z": -5,
      "name": "Soil_Hive"
    },
    {
      "x": -22,
      "y": 3,
      "z": -5,
      "name": "Soil_Hive"
    },
    {
      "x": -22,
      "y": 0,
      "z": -4,
      "name": "Soil_Hive"
    },
    {
      "x": -22,
      "y": 1,
      "z": -4,
      "name": "Soil_Hive"
    },
    {
      "x": -22,
      "y": 2,
      "z": -4,
      "name": "Soil_Hive"
    },
    {
      "x": -22,
      "y": 3,
      "z": -4,
      "name": "Soil_Hive"
    },
    {
      "x": -22,
      "y": 0,
      "z": -3,
      "name": "Soil_Hive"
    },
    {
      "x": -22,
      "y": 1,
      "z": -3,
      "name": "Soil_Hive"
    },
    {
      "x": -22,
      "y": 2,
      "z": -3,
      "name": "Soil_Hive"
    },
    {
      "x": -22,
      "y": 3,
      "z": -3,
      "name": "Soil_Hive"
    },
    {
      "x": -22,
      "y": 0,
      "z": -2,
      "name": "Soil_Hive"
    },
    {
      "x": -22,
      "y": 1,
      "z": -2,
      "name": "Soil_Hive"
    },
    {
      "x": -22,
      "y": 2,
      "z": -2,
      "name": "Soil_Hive"
    },
    {
      "x": -22,
      "y": 3,
      "z": -2,
      "name": "Soil_Hive"
    },
    {
      "x": -22,
      "y": 0,
      "z": -1,
      "name": "Soil_Hive"
    },
    {
      "x": -22,
      "y": 1,
      "z": -1,
      "name": "Soil_Hive"
    },
    {
      "x": -22,
      "y": 2,
      "z": -1,
      "name": "Soil_Hive"
    },
    {
      "x": -22,
      "y": 3,
      "z": -1,
      "name": "Soil_Hive"
    },
    {
      "x": -22,
      "y": 0,
      "z": 0,
      "name": "Soil_Hive"
    },
    {
      "x": -22,
      "y": 1,
      "z": 0,
      "name": "Soil_Hive"
    },
    {
      "x": -22,
      "y": 2,
      "z": 0,
      "name": "Soil_Hive"
    },
    {
      "x": -22,
      "y": 3,
      "z": 0,
      "name": "Soil_Hive"
    },
    {
      "x": -22,
      "y": 4,
      "z": 0,
      "name": "Soil_Hive"
    },
    {
      "x": -22,
      "y": 0,
      "z": 1,
      "name": "Soil_Hive"
    },
    {
      "x": -22,
      "y": 1,
      "z": 1,
      "name": "Soil_Hive"
    },
    {
      "x": -22,
      "y": 2,
      "z": 1,
      "name": "Soil_Hive"
    },
    {
      "x": -22,
      "y": 3,
      "z": 1,
      "name": "Soil_Hive"
    },
    {
      "x": -22,
      "y": 0,
      "z": 2,
      "name": "Soil_Hive"
    },
    {
      "x": -22,
      "y": 1,
      "z": 2,
      "name": "Soil_Hive"
    },
    {
      "x": -22,
      "y": 2,
      "z": 2,
      "name": "Soil_Hive"
    },
    {
      "x": -22,
      "y": 3,
      "z": 2,
      "name": "Soil_Hive"
    },
    {
      "x": -22,
      "y": 0,
      "z": 4,
      "name": "Soil_Hive"
    },
    {
      "x": -22,
      "y": 1,
      "z": 4,
      "name": "Soil_Hive"
    },
    {
      "x": -22,
      "y": 2,
      "z": 4,
      "name": "Soil_Hive"
    },
    {
      "x": -22,
      "y": 3,
      "z": 4,
      "name": "Soil_Hive"
    },
    {
      "x": -22,
      "y": 0,
      "z": 5,
      "name": "Soil_Hive"
    },
    {
      "x": -22,
      "y": 1,
      "z": 5,
      "name": "Soil_Hive"
    },
    {
      "x": -22,
      "y": 2,
      "z": 5,
      "name": "Soil_Hive"
    },
    {
      "x": -22,
      "y": 3,
      "z": 5,
      "name": "Soil_Hive"
    },
    {
      "x": -22,
      "y": 0,
      "z": 6,
      "name": "Soil_Hive"
    },
    {
      "x": -22,
      "y": 1,
      "z": 6,
      "name": "Soil_Hive"
    },
    {
      "x": -22,
      "y": 2,
      "z": 6,
      "name": "Soil_Hive"
    },
    {
      "x": -22,
      "y": 3,
      "z": 6,
      "name": "Soil_Hive"
    },
    {
      "x": -22,
      "y": 4,
      "z": 6,
      "name": "Soil_Hive"
    },
    {
      "x": -22,
      "y": 0,
      "z": 7,
      "name": "Soil_Hive"
    },
    {
      "x": -22,
      "y": 1,
      "z": 7,
      "name": "Soil_Hive"
    },
    {
      "x": -22,
      "y": 2,
      "z": 7,
      "name": "Soil_Hive"
    },
    {
      "x": -22,
      "y": 3,
      "z": 7,
      "name": "Soil_Hive"
    },
    {
      "x": -22,
      "y": 0,
      "z": 8,
      "name": "Soil_Hive"
    },
    {
      "x": -22,
      "y": 1,
      "z": 8,
      "name": "Soil_Hive"
    },
    {
      "x": -22,
      "y": 2,
      "z": 8,
      "name": "Soil_Hive"
    },
    {
      "x": -22,
      "y": 3,
      "z": 8,
      "name": "Soil_Hive"
    },
    {
      "x": -22,
      "y": 0,
      "z": 9,
      "name": "Soil_Hive"
    },
    {
      "x": -22,
      "y": 1,
      "z": 9,
      "name": "Soil_Hive"
    },
    {
      "x": -22,
      "y": 2,
      "z": 9,
      "name": "Soil_Hive"
    },
    {
      "x": -22,
      "y": 3,
      "z": 9,
      "name": "Soil_Hive"
    },
    {
      "x": -22,
      "y": 0,
      "z": 14,
      "name": "Soil_Hive"
    },
    {
      "x": -22,
      "y": 1,
      "z": 14,
      "name": "Soil_Hive"
    },
    {
      "x": -22,
      "y": 2,
      "z": 14,
      "name": "Soil_Hive"
    },
    {
      "x": -22,
      "y": 3,
      "z": 14,
      "name": "Soil_Hive"
    },
    {
      "x": -22,
      "y": 0,
      "z": 15,
      "name": "Soil_Hive"
    },
    {
      "x": -22,
      "y": 1,
      "z": 15,
      "name": "Soil_Hive"
    },
    {
      "x": -22,
      "y": 2,
      "z": 15,
      "name": "Soil_Hive"
    },
    {
      "x": -22,
      "y": 3,
      "z": 15,
      "name": "Soil_Hive"
    },
    {
      "x": -22,
      "y": 0,
      "z": 16,
      "name": "Soil_Hive"
    },
    {
      "x": -22,
      "y": 1,
      "z": 16,
      "name": "Soil_Hive"
    },
    {
      "x": -22,
      "y": 2,
      "z": 16,
      "name": "Soil_Hive"
    },
    {
      "x": -22,
      "y": 3,
      "z": 16,
      "name": "Soil_Hive"
    },
    {
      "x": -21,
      "y": 0,
      "z": -26,
      "name": "Soil_Hive"
    },
    {
      "x": -21,
      "y": 1,
      "z": -26,
      "name": "Soil_Hive"
    },
    {
      "x": -21,
      "y": 2,
      "z": -26,
      "name": "Soil_Hive"
    },
    {
      "x": -21,
      "y": 3,
      "z": -26,
      "name": "Soil_Hive"
    },
    {
      "x": -21,
      "y": 0,
      "z": -25,
      "name": "Soil_Hive"
    },
    {
      "x": -21,
      "y": 1,
      "z": -25,
      "name": "Soil_Hive"
    },
    {
      "x": -21,
      "y": 2,
      "z": -25,
      "name": "Soil_Hive"
    },
    {
      "x": -21,
      "y": 3,
      "z": -25,
      "name": "Soil_Hive"
    },
    {
      "x": -21,
      "y": 0,
      "z": -16,
      "name": "Soil_Hive"
    },
    {
      "x": -21,
      "y": 1,
      "z": -16,
      "name": "Soil_Hive"
    },
    {
      "x": -21,
      "y": 2,
      "z": -16,
      "name": "Soil_Hive"
    },
    {
      "x": -21,
      "y": 3,
      "z": -16,
      "name": "Soil_Hive"
    },
    {
      "x": -21,
      "y": 0,
      "z": -15,
      "name": "Soil_Hive"
    },
    {
      "x": -21,
      "y": 1,
      "z": -15,
      "name": "Soil_Hive"
    },
    {
      "x": -21,
      "y": 2,
      "z": -15,
      "name": "Soil_Hive"
    },
    {
      "x": -21,
      "y": 3,
      "z": -15,
      "name": "Soil_Hive"
    },
    {
      "x": -21,
      "y": 0,
      "z": -14,
      "name": "Soil_Hive"
    },
    {
      "x": -21,
      "y": 1,
      "z": -14,
      "name": "Soil_Hive"
    },
    {
      "x": -21,
      "y": 2,
      "z": -14,
      "name": "Soil_Hive"
    },
    {
      "x": -21,
      "y": 3,
      "z": -14,
      "name": "Soil_Hive"
    },
    {
      "x": -21,
      "y": 0,
      "z": -11,
      "name": "Soil_Hive"
    },
    {
      "x": -21,
      "y": 1,
      "z": -11,
      "name": "Soil_Hive"
    },
    {
      "x": -21,
      "y": 2,
      "z": -11,
      "name": "Soil_Hive"
    },
    {
      "x": -21,
      "y": 3,
      "z": -11,
      "name": "Soil_Hive"
    },
    {
      "x": -21,
      "y": 0,
      "z": -10,
      "name": "Soil_Hive"
    },
    {
      "x": -21,
      "y": 1,
      "z": -10,
      "name": "Soil_Hive"
    },
    {
      "x": -21,
      "y": 2,
      "z": -10,
      "name": "Soil_Hive"
    },
    {
      "x": -21,
      "y": 3,
      "z": -10,
      "name": "Soil_Hive"
    },
    {
      "x": -21,
      "y": 4,
      "z": -10,
      "name": "Soil_Hive"
    },
    {
      "x": -21,
      "y": 0,
      "z": -9,
      "name": "Soil_Hive"
    },
    {
      "x": -21,
      "y": 1,
      "z": -9,
      "name": "Soil_Hive"
    },
    {
      "x": -21,
      "y": 2,
      "z": -9,
      "name": "Soil_Hive"
    },
    {
      "x": -21,
      "y": 3,
      "z": -9,
      "name": "Soil_Hive"
    },
    {
      "x": -21,
      "y": 0,
      "z": -8,
      "name": "Soil_Hive"
    },
    {
      "x": -21,
      "y": 1,
      "z": -8,
      "name": "Soil_Hive"
    },
    {
      "x": -21,
      "y": 2,
      "z": -8,
      "name": "Soil_Hive"
    },
    {
      "x": -21,
      "y": 3,
      "z": -8,
      "name": "Soil_Hive"
    },
    {
      "x": -21,
      "y": 0,
      "z": -7,
      "name": "Soil_Hive"
    },
    {
      "x": -21,
      "y": 1,
      "z": -7,
      "name": "Soil_Hive"
    },
    {
      "x": -21,
      "y": 2,
      "z": -7,
      "name": "Soil_Hive"
    },
    {
      "x": -21,
      "y": 3,
      "z": -7,
      "name": "Soil_Hive"
    },
    {
      "x": -21,
      "y": 0,
      "z": -6,
      "name": "Soil_Hive"
    },
    {
      "x": -21,
      "y": 1,
      "z": -6,
      "name": "Soil_Hive"
    },
    {
      "x": -21,
      "y": 2,
      "z": -6,
      "name": "Soil_Hive"
    },
    {
      "x": -21,
      "y": 3,
      "z": -6,
      "name": "Soil_Hive"
    },
    {
      "x": -21,
      "y": 4,
      "z": -6,
      "name": "Soil_Hive"
    },
    {
      "x": -21,
      "y": 0,
      "z": -5,
      "name": "Soil_Hive"
    },
    {
      "x": -21,
      "y": 1,
      "z": -5,
      "name": "Soil_Hive"
    },
    {
      "x": -21,
      "y": 2,
      "z": -5,
      "name": "Soil_Hive"
    },
    {
      "x": -21,
      "y": 3,
      "z": -5,
      "name": "Soil_Hive"
    },
    {
      "x": -21,
      "y": 0,
      "z": -4,
      "name": "Soil_Hive"
    },
    {
      "x": -21,
      "y": 1,
      "z": -4,
      "name": "Soil_Hive"
    },
    {
      "x": -21,
      "y": 2,
      "z": -4,
      "name": "Soil_Hive"
    },
    {
      "x": -21,
      "y": 3,
      "z": -4,
      "name": "Soil_Hive"
    },
    {
      "x": -21,
      "y": 0,
      "z": -3,
      "name": "Soil_Hive"
    },
    {
      "x": -21,
      "y": 1,
      "z": -3,
      "name": "Soil_Hive"
    },
    {
      "x": -21,
      "y": 2,
      "z": -3,
      "name": "Soil_Hive"
    },
    {
      "x": -21,
      "y": 3,
      "z": -3,
      "name": "Soil_Hive"
    },
    {
      "x": -21,
      "y": 0,
      "z": -2,
      "name": "Soil_Hive"
    },
    {
      "x": -21,
      "y": 1,
      "z": -2,
      "name": "Soil_Hive"
    },
    {
      "x": -21,
      "y": 2,
      "z": -2,
      "name": "Soil_Hive"
    },
    {
      "x": -21,
      "y": 3,
      "z": -2,
      "name": "Soil_Hive"
    },
    {
      "x": -21,
      "y": 0,
      "z": -1,
      "name": "Soil_Hive"
    },
    {
      "x": -21,
      "y": 1,
      "z": -1,
      "name": "Soil_Hive"
    },
    {
      "x": -21,
      "y": 2,
      "z": -1,
      "name": "Soil_Hive"
    },
    {
      "x": -21,
      "y": 3,
      "z": -1,
      "name": "Soil_Hive"
    },
    {
      "x": -21,
      "y": 0,
      "z": 0,
      "name": "Soil_Hive"
    },
    {
      "x": -21,
      "y": 1,
      "z": 0,
      "name": "Soil_Hive"
    },
    {
      "x": -21,
      "y": 2,
      "z": 0,
      "name": "Soil_Hive"
    },
    {
      "x": -21,
      "y": 3,
      "z": 0,
      "name": "Soil_Hive"
    },
    {
      "x": -21,
      "y": 0,
      "z": 1,
      "name": "Soil_Hive"
    },
    {
      "x": -21,
      "y": 1,
      "z": 1,
      "name": "Soil_Hive"
    },
    {
      "x": -21,
      "y": 2,
      "z": 1,
      "name": "Soil_Hive"
    },
    {
      "x": -21,
      "y": 3,
      "z": 1,
      "name": "Soil_Hive"
    },
    {
      "x": -21,
      "y": 4,
      "z": 1,
      "name": "Soil_Hive"
    },
    {
      "x": -21,
      "y": 0,
      "z": 2,
      "name": "Soil_Hive"
    },
    {
      "x": -21,
      "y": 1,
      "z": 2,
      "name": "Soil_Hive"
    },
    {
      "x": -21,
      "y": 2,
      "z": 2,
      "name": "Soil_Hive"
    },
    {
      "x": -21,
      "y": 3,
      "z": 2,
      "name": "Soil_Hive"
    },
    {
      "x": -21,
      "y": 0,
      "z": 4,
      "name": "Soil_Hive"
    },
    {
      "x": -21,
      "y": 1,
      "z": 4,
      "name": "Soil_Hive"
    },
    {
      "x": -21,
      "y": 2,
      "z": 4,
      "name": "Soil_Hive"
    },
    {
      "x": -21,
      "y": 3,
      "z": 4,
      "name": "Soil_Hive"
    },
    {
      "x": -21,
      "y": 0,
      "z": 5,
      "name": "Soil_Hive"
    },
    {
      "x": -21,
      "y": 1,
      "z": 5,
      "name": "Soil_Hive"
    },
    {
      "x": -21,
      "y": 2,
      "z": 5,
      "name": "Soil_Hive"
    },
    {
      "x": -21,
      "y": 3,
      "z": 5,
      "name": "Soil_Hive"
    },
    {
      "x": -21,
      "y": 0,
      "z": 6,
      "name": "Soil_Hive"
    },
    {
      "x": -21,
      "y": 1,
      "z": 6,
      "name": "Soil_Hive"
    },
    {
      "x": -21,
      "y": 2,
      "z": 6,
      "name": "Soil_Hive"
    },
    {
      "x": -21,
      "y": 3,
      "z": 6,
      "name": "Soil_Hive"
    },
    {
      "x": -21,
      "y": 0,
      "z": 7,
      "name": "Soil_Hive"
    },
    {
      "x": -21,
      "y": 1,
      "z": 7,
      "name": "Soil_Hive"
    },
    {
      "x": -21,
      "y": 2,
      "z": 7,
      "name": "Soil_Hive"
    },
    {
      "x": -21,
      "y": 3,
      "z": 7,
      "name": "Soil_Hive"
    },
    {
      "x": -21,
      "y": 4,
      "z": 7,
      "name": "Soil_Hive"
    },
    {
      "x": -21,
      "y": 0,
      "z": 8,
      "name": "Soil_Hive"
    },
    {
      "x": -21,
      "y": 1,
      "z": 8,
      "name": "Soil_Hive"
    },
    {
      "x": -21,
      "y": 2,
      "z": 8,
      "name": "Soil_Hive"
    },
    {
      "x": -21,
      "y": 3,
      "z": 8,
      "name": "Soil_Hive"
    },
    {
      "x": -21,
      "y": 4,
      "z": 8,
      "name": "Soil_Hive"
    },
    {
      "x": -21,
      "y": 0,
      "z": 9,
      "name": "Soil_Hive"
    },
    {
      "x": -21,
      "y": 1,
      "z": 9,
      "name": "Soil_Hive"
    },
    {
      "x": -21,
      "y": 2,
      "z": 9,
      "name": "Soil_Hive"
    },
    {
      "x": -21,
      "y": 3,
      "z": 9,
      "name": "Soil_Hive"
    },
    {
      "x": -21,
      "y": 0,
      "z": 10,
      "name": "Soil_Hive"
    },
    {
      "x": -21,
      "y": 1,
      "z": 10,
      "name": "Soil_Hive"
    },
    {
      "x": -21,
      "y": 2,
      "z": 10,
      "name": "Soil_Hive"
    },
    {
      "x": -21,
      "y": 3,
      "z": 10,
      "name": "Soil_Hive"
    },
    {
      "x": -21,
      "y": 0,
      "z": 14,
      "name": "Soil_Hive"
    },
    {
      "x": -21,
      "y": 1,
      "z": 14,
      "name": "Soil_Hive"
    },
    {
      "x": -21,
      "y": 2,
      "z": 14,
      "name": "Soil_Hive"
    },
    {
      "x": -21,
      "y": 3,
      "z": 14,
      "name": "Soil_Hive"
    },
    {
      "x": -21,
      "y": 0,
      "z": 15,
      "name": "Soil_Hive"
    },
    {
      "x": -21,
      "y": 1,
      "z": 15,
      "name": "Soil_Hive"
    },
    {
      "x": -21,
      "y": 2,
      "z": 15,
      "name": "Soil_Hive"
    },
    {
      "x": -21,
      "y": 3,
      "z": 15,
      "name": "Soil_Hive"
    },
    {
      "x": -21,
      "y": 0,
      "z": 16,
      "name": "Soil_Hive"
    },
    {
      "x": -21,
      "y": 1,
      "z": 16,
      "name": "Soil_Hive"
    },
    {
      "x": -21,
      "y": 2,
      "z": 16,
      "name": "Soil_Hive"
    },
    {
      "x": -21,
      "y": 3,
      "z": 16,
      "name": "Soil_Hive"
    },
    {
      "x": -21,
      "y": 0,
      "z": 25,
      "name": "Soil_Hive"
    },
    {
      "x": -21,
      "y": 1,
      "z": 25,
      "name": "Soil_Hive"
    },
    {
      "x": -21,
      "y": 2,
      "z": 25,
      "name": "Soil_Hive"
    },
    {
      "x": -21,
      "y": 3,
      "z": 25,
      "name": "Soil_Hive"
    },
    {
      "x": -20,
      "y": 0,
      "z": -24,
      "name": "Soil_Hive"
    },
    {
      "x": -20,
      "y": 1,
      "z": -24,
      "name": "Soil_Hive"
    },
    {
      "x": -20,
      "y": 2,
      "z": -24,
      "name": "Soil_Hive"
    },
    {
      "x": -20,
      "y": 3,
      "z": -24,
      "name": "Soil_Hive"
    },
    {
      "x": -20,
      "y": 0,
      "z": -23,
      "name": "Soil_Hive"
    },
    {
      "x": -20,
      "y": 1,
      "z": -23,
      "name": "Soil_Hive"
    },
    {
      "x": -20,
      "y": 2,
      "z": -23,
      "name": "Soil_Hive"
    },
    {
      "x": -20,
      "y": 3,
      "z": -23,
      "name": "Soil_Hive"
    },
    {
      "x": -20,
      "y": 0,
      "z": -16,
      "name": "Soil_Hive"
    },
    {
      "x": -20,
      "y": 1,
      "z": -16,
      "name": "Soil_Hive"
    },
    {
      "x": -20,
      "y": 2,
      "z": -16,
      "name": "Soil_Hive"
    },
    {
      "x": -20,
      "y": 3,
      "z": -16,
      "name": "Soil_Hive"
    },
    {
      "x": -20,
      "y": 0,
      "z": -15,
      "name": "Soil_Hive"
    },
    {
      "x": -20,
      "y": 1,
      "z": -15,
      "name": "Soil_Hive"
    },
    {
      "x": -20,
      "y": 2,
      "z": -15,
      "name": "Soil_Hive"
    },
    {
      "x": -20,
      "y": 3,
      "z": -15,
      "name": "Soil_Hive"
    },
    {
      "x": -20,
      "y": 0,
      "z": -14,
      "name": "Soil_Hive"
    },
    {
      "x": -20,
      "y": 1,
      "z": -14,
      "name": "Soil_Hive"
    },
    {
      "x": -20,
      "y": 2,
      "z": -14,
      "name": "Soil_Hive"
    },
    {
      "x": -20,
      "y": 3,
      "z": -14,
      "name": "Soil_Hive"
    },
    {
      "x": -20,
      "y": 0,
      "z": -13,
      "name": "Soil_Hive"
    },
    {
      "x": -20,
      "y": 1,
      "z": -13,
      "name": "Soil_Hive"
    },
    {
      "x": -20,
      "y": 2,
      "z": -13,
      "name": "Soil_Hive"
    },
    {
      "x": -20,
      "y": 3,
      "z": -13,
      "name": "Soil_Hive"
    },
    {
      "x": -20,
      "y": 0,
      "z": -12,
      "name": "Soil_Hive"
    },
    {
      "x": -20,
      "y": 1,
      "z": -12,
      "name": "Soil_Hive"
    },
    {
      "x": -20,
      "y": 2,
      "z": -12,
      "name": "Soil_Hive"
    },
    {
      "x": -20,
      "y": 3,
      "z": -12,
      "name": "Soil_Hive"
    },
    {
      "x": -20,
      "y": 0,
      "z": -11,
      "name": "Soil_Hive"
    },
    {
      "x": -20,
      "y": 1,
      "z": -11,
      "name": "Soil_Hive"
    },
    {
      "x": -20,
      "y": 2,
      "z": -11,
      "name": "Soil_Hive"
    },
    {
      "x": -20,
      "y": 3,
      "z": -11,
      "name": "Soil_Hive"
    },
    {
      "x": -20,
      "y": 4,
      "z": -11,
      "name": "Soil_Hive"
    },
    {
      "x": -20,
      "y": 0,
      "z": -10,
      "name": "Soil_Hive"
    },
    {
      "x": -20,
      "y": 1,
      "z": -10,
      "name": "Soil_Hive"
    },
    {
      "x": -20,
      "y": 2,
      "z": -10,
      "name": "Soil_Hive"
    },
    {
      "x": -20,
      "y": 3,
      "z": -10,
      "name": "Soil_Hive"
    },
    {
      "x": -20,
      "y": 0,
      "z": -9,
      "name": "Soil_Hive"
    },
    {
      "x": -20,
      "y": 1,
      "z": -9,
      "name": "Soil_Hive"
    },
    {
      "x": -20,
      "y": 2,
      "z": -9,
      "name": "Soil_Hive"
    },
    {
      "x": -20,
      "y": 3,
      "z": -9,
      "name": "Soil_Hive"
    },
    {
      "x": -20,
      "y": 0,
      "z": -7,
      "name": "Soil_Hive"
    },
    {
      "x": -20,
      "y": 1,
      "z": -7,
      "name": "Soil_Hive"
    },
    {
      "x": -20,
      "y": 2,
      "z": -7,
      "name": "Soil_Hive"
    },
    {
      "x": -20,
      "y": 3,
      "z": -7,
      "name": "Soil_Hive"
    },
    {
      "x": -20,
      "y": 0,
      "z": -6,
      "name": "Soil_Hive"
    },
    {
      "x": -20,
      "y": 1,
      "z": -6,
      "name": "Soil_Hive"
    },
    {
      "x": -20,
      "y": 2,
      "z": -6,
      "name": "Soil_Hive"
    },
    {
      "x": -20,
      "y": 3,
      "z": -6,
      "name": "Soil_Hive"
    },
    {
      "x": -20,
      "y": 0,
      "z": -5,
      "name": "Soil_Hive"
    },
    {
      "x": -20,
      "y": 1,
      "z": -5,
      "name": "Soil_Hive"
    },
    {
      "x": -20,
      "y": 2,
      "z": -5,
      "name": "Soil_Hive"
    },
    {
      "x": -20,
      "y": 3,
      "z": -5,
      "name": "Soil_Hive"
    },
    {
      "x": -20,
      "y": 4,
      "z": -5,
      "name": "Soil_Hive"
    },
    {
      "x": -20,
      "y": 0,
      "z": -4,
      "name": "Soil_Hive"
    },
    {
      "x": -20,
      "y": 1,
      "z": -4,
      "name": "Soil_Hive"
    },
    {
      "x": -20,
      "y": 2,
      "z": -4,
      "name": "Soil_Hive"
    },
    {
      "x": -20,
      "y": 3,
      "z": -4,
      "name": "Soil_Hive"
    },
    {
      "x": -20,
      "y": 0,
      "z": -3,
      "name": "Soil_Hive"
    },
    {
      "x": -20,
      "y": 1,
      "z": -3,
      "name": "Soil_Hive"
    },
    {
      "x": -20,
      "y": 2,
      "z": -3,
      "name": "Soil_Hive"
    },
    {
      "x": -20,
      "y": 3,
      "z": -3,
      "name": "Soil_Hive"
    },
    {
      "x": -20,
      "y": 0,
      "z": -2,
      "name": "Soil_Hive"
    },
    {
      "x": -20,
      "y": 1,
      "z": -2,
      "name": "Soil_Hive"
    },
    {
      "x": -20,
      "y": 2,
      "z": -2,
      "name": "Soil_Hive"
    },
    {
      "x": -20,
      "y": 3,
      "z": -2,
      "name": "Soil_Hive"
    },
    {
      "x": -20,
      "y": 0,
      "z": -1,
      "name": "Soil_Hive"
    },
    {
      "x": -20,
      "y": 1,
      "z": -1,
      "name": "Soil_Hive"
    },
    {
      "x": -20,
      "y": 2,
      "z": -1,
      "name": "Soil_Hive"
    },
    {
      "x": -20,
      "y": 3,
      "z": -1,
      "name": "Soil_Hive"
    },
    {
      "x": -20,
      "y": 0,
      "z": 0,
      "name": "Soil_Hive"
    },
    {
      "x": -20,
      "y": 1,
      "z": 0,
      "name": "Soil_Hive"
    },
    {
      "x": -20,
      "y": 2,
      "z": 0,
      "name": "Soil_Hive"
    },
    {
      "x": -20,
      "y": 3,
      "z": 0,
      "name": "Soil_Hive"
    },
    {
      "x": -20,
      "y": 0,
      "z": 1,
      "name": "Soil_Hive"
    },
    {
      "x": -20,
      "y": 1,
      "z": 1,
      "name": "Soil_Hive"
    },
    {
      "x": -20,
      "y": 2,
      "z": 1,
      "name": "Soil_Hive"
    },
    {
      "x": -20,
      "y": 3,
      "z": 1,
      "name": "Soil_Hive"
    },
    {
      "x": -20,
      "y": 4,
      "z": 1,
      "name": "Soil_Hive"
    },
    {
      "x": -20,
      "y": 0,
      "z": 2,
      "name": "Soil_Hive"
    },
    {
      "x": -20,
      "y": 1,
      "z": 2,
      "name": "Soil_Hive"
    },
    {
      "x": -20,
      "y": 2,
      "z": 2,
      "name": "Soil_Hive"
    },
    {
      "x": -20,
      "y": 3,
      "z": 2,
      "name": "Soil_Hive"
    },
    {
      "x": -20,
      "y": 0,
      "z": 5,
      "name": "Soil_Hive"
    },
    {
      "x": -20,
      "y": 1,
      "z": 5,
      "name": "Soil_Hive"
    },
    {
      "x": -20,
      "y": 2,
      "z": 5,
      "name": "Soil_Hive"
    },
    {
      "x": -20,
      "y": 3,
      "z": 5,
      "name": "Soil_Hive"
    },
    {
      "x": -20,
      "y": 0,
      "z": 6,
      "name": "Soil_Hive"
    },
    {
      "x": -20,
      "y": 1,
      "z": 6,
      "name": "Soil_Hive"
    },
    {
      "x": -20,
      "y": 2,
      "z": 6,
      "name": "Soil_Hive"
    },
    {
      "x": -20,
      "y": 3,
      "z": 6,
      "name": "Soil_Hive"
    },
    {
      "x": -20,
      "y": 0,
      "z": 7,
      "name": "Soil_Hive"
    },
    {
      "x": -20,
      "y": 1,
      "z": 7,
      "name": "Soil_Hive"
    },
    {
      "x": -20,
      "y": 2,
      "z": 7,
      "name": "Soil_Hive"
    },
    {
      "x": -20,
      "y": 3,
      "z": 7,
      "name": "Soil_Hive"
    },
    {
      "x": -20,
      "y": 0,
      "z": 8,
      "name": "Soil_Hive"
    },
    {
      "x": -20,
      "y": 1,
      "z": 8,
      "name": "Soil_Hive"
    },
    {
      "x": -20,
      "y": 2,
      "z": 8,
      "name": "Soil_Hive"
    },
    {
      "x": -20,
      "y": 3,
      "z": 8,
      "name": "Soil_Hive"
    },
    {
      "x": -20,
      "y": 4,
      "z": 8,
      "name": "Soil_Hive"
    },
    {
      "x": -20,
      "y": 0,
      "z": 9,
      "name": "Soil_Hive"
    },
    {
      "x": -20,
      "y": 1,
      "z": 9,
      "name": "Soil_Hive"
    },
    {
      "x": -20,
      "y": 2,
      "z": 9,
      "name": "Soil_Hive"
    },
    {
      "x": -20,
      "y": 3,
      "z": 9,
      "name": "Soil_Hive"
    },
    {
      "x": -20,
      "y": 0,
      "z": 10,
      "name": "Soil_Hive"
    },
    {
      "x": -20,
      "y": 1,
      "z": 10,
      "name": "Soil_Hive"
    },
    {
      "x": -20,
      "y": 2,
      "z": 10,
      "name": "Soil_Hive"
    },
    {
      "x": -20,
      "y": 3,
      "z": 10,
      "name": "Soil_Hive"
    },
    {
      "x": -20,
      "y": 0,
      "z": 12,
      "name": "Soil_Hive"
    },
    {
      "x": -20,
      "y": 1,
      "z": 12,
      "name": "Soil_Hive"
    },
    {
      "x": -20,
      "y": 2,
      "z": 12,
      "name": "Soil_Hive"
    },
    {
      "x": -20,
      "y": 3,
      "z": 12,
      "name": "Soil_Hive"
    },
    {
      "x": -20,
      "y": 0,
      "z": 13,
      "name": "Soil_Hive"
    },
    {
      "x": -20,
      "y": 1,
      "z": 13,
      "name": "Soil_Hive"
    },
    {
      "x": -20,
      "y": 2,
      "z": 13,
      "name": "Soil_Hive"
    },
    {
      "x": -20,
      "y": 3,
      "z": 13,
      "name": "Soil_Hive"
    },
    {
      "x": -20,
      "y": 0,
      "z": 14,
      "name": "Soil_Hive"
    },
    {
      "x": -20,
      "y": 1,
      "z": 14,
      "name": "Soil_Hive"
    },
    {
      "x": -20,
      "y": 2,
      "z": 14,
      "name": "Soil_Hive"
    },
    {
      "x": -20,
      "y": 3,
      "z": 14,
      "name": "Soil_Hive"
    },
    {
      "x": -20,
      "y": 4,
      "z": 14,
      "name": "Soil_Hive"
    },
    {
      "x": -20,
      "y": 0,
      "z": 15,
      "name": "Soil_Hive"
    },
    {
      "x": -20,
      "y": 1,
      "z": 15,
      "name": "Soil_Hive"
    },
    {
      "x": -20,
      "y": 2,
      "z": 15,
      "name": "Soil_Hive"
    },
    {
      "x": -20,
      "y": 3,
      "z": 15,
      "name": "Soil_Hive"
    },
    {
      "x": -20,
      "y": 0,
      "z": 24,
      "name": "Soil_Hive"
    },
    {
      "x": -20,
      "y": 1,
      "z": 24,
      "name": "Soil_Hive"
    },
    {
      "x": -20,
      "y": 2,
      "z": 24,
      "name": "Soil_Hive"
    },
    {
      "x": -20,
      "y": 3,
      "z": 24,
      "name": "Soil_Hive"
    },
    {
      "x": -20,
      "y": 0,
      "z": 25,
      "name": "Soil_Hive"
    },
    {
      "x": -20,
      "y": 1,
      "z": 25,
      "name": "Soil_Hive"
    },
    {
      "x": -20,
      "y": 2,
      "z": 25,
      "name": "Soil_Hive"
    },
    {
      "x": -20,
      "y": 3,
      "z": 25,
      "name": "Soil_Hive"
    },
    {
      "x": -19,
      "y": 0,
      "z": -23,
      "name": "Soil_Hive"
    },
    {
      "x": -19,
      "y": 1,
      "z": -23,
      "name": "Soil_Hive"
    },
    {
      "x": -19,
      "y": 2,
      "z": -23,
      "name": "Soil_Hive"
    },
    {
      "x": -19,
      "y": 3,
      "z": -23,
      "name": "Soil_Hive"
    },
    {
      "x": -19,
      "y": 0,
      "z": -22,
      "name": "Soil_Hive"
    },
    {
      "x": -19,
      "y": 1,
      "z": -22,
      "name": "Soil_Hive"
    },
    {
      "x": -19,
      "y": 2,
      "z": -22,
      "name": "Soil_Hive"
    },
    {
      "x": -19,
      "y": 3,
      "z": -22,
      "name": "Soil_Hive"
    },
    {
      "x": -19,
      "y": 0,
      "z": -17,
      "name": "Soil_Hive"
    },
    {
      "x": -19,
      "y": 1,
      "z": -17,
      "name": "Soil_Hive"
    },
    {
      "x": -19,
      "y": 2,
      "z": -17,
      "name": "Soil_Hive"
    },
    {
      "x": -19,
      "y": 3,
      "z": -17,
      "name": "Soil_Hive"
    },
    {
      "x": -19,
      "y": 0,
      "z": -16,
      "name": "Soil_Hive"
    },
    {
      "x": -19,
      "y": 1,
      "z": -16,
      "name": "Soil_Hive"
    },
    {
      "x": -19,
      "y": 2,
      "z": -16,
      "name": "Soil_Hive"
    },
    {
      "x": -19,
      "y": 3,
      "z": -16,
      "name": "Soil_Hive"
    },
    {
      "x": -19,
      "y": 0,
      "z": -15,
      "name": "Soil_Hive"
    },
    {
      "x": -19,
      "y": 1,
      "z": -15,
      "name": "Soil_Hive"
    },
    {
      "x": -19,
      "y": 2,
      "z": -15,
      "name": "Soil_Hive"
    },
    {
      "x": -19,
      "y": 3,
      "z": -15,
      "name": "Soil_Hive"
    },
    {
      "x": -19,
      "y": 0,
      "z": -14,
      "name": "Soil_Hive"
    },
    {
      "x": -19,
      "y": 1,
      "z": -14,
      "name": "Soil_Hive"
    },
    {
      "x": -19,
      "y": 2,
      "z": -14,
      "name": "Soil_Hive"
    },
    {
      "x": -19,
      "y": 3,
      "z": -14,
      "name": "Soil_Hive"
    },
    {
      "x": -19,
      "y": 4,
      "z": -14,
      "name": "Soil_Hive"
    },
    {
      "x": -19,
      "y": 0,
      "z": -13,
      "name": "Soil_Hive"
    },
    {
      "x": -19,
      "y": 1,
      "z": -13,
      "name": "Soil_Hive"
    },
    {
      "x": -19,
      "y": 2,
      "z": -13,
      "name": "Soil_Hive"
    },
    {
      "x": -19,
      "y": 3,
      "z": -13,
      "name": "Soil_Hive"
    },
    {
      "x": -19,
      "y": 4,
      "z": -13,
      "name": "Soil_Hive"
    },
    {
      "x": -19,
      "y": 0,
      "z": -12,
      "name": "Soil_Hive"
    },
    {
      "x": -19,
      "y": 1,
      "z": -12,
      "name": "Soil_Hive"
    },
    {
      "x": -19,
      "y": 2,
      "z": -12,
      "name": "Soil_Hive"
    },
    {
      "x": -19,
      "y": 3,
      "z": -12,
      "name": "Soil_Hive"
    },
    {
      "x": -19,
      "y": 4,
      "z": -12,
      "name": "Soil_Hive"
    },
    {
      "x": -19,
      "y": 0,
      "z": -11,
      "name": "Soil_Hive"
    },
    {
      "x": -19,
      "y": 1,
      "z": -11,
      "name": "Soil_Hive"
    },
    {
      "x": -19,
      "y": 2,
      "z": -11,
      "name": "Soil_Hive"
    },
    {
      "x": -19,
      "y": 3,
      "z": -11,
      "name": "Soil_Hive"
    },
    {
      "x": -19,
      "y": 0,
      "z": -10,
      "name": "Soil_Hive"
    },
    {
      "x": -19,
      "y": 1,
      "z": -10,
      "name": "Soil_Hive"
    },
    {
      "x": -19,
      "y": 2,
      "z": -10,
      "name": "Soil_Hive"
    },
    {
      "x": -19,
      "y": 3,
      "z": -10,
      "name": "Soil_Hive"
    },
    {
      "x": -19,
      "y": 0,
      "z": -7,
      "name": "Soil_Hive"
    },
    {
      "x": -19,
      "y": 1,
      "z": -7,
      "name": "Soil_Hive"
    },
    {
      "x": -19,
      "y": 2,
      "z": -7,
      "name": "Soil_Hive"
    },
    {
      "x": -19,
      "y": 3,
      "z": -7,
      "name": "Soil_Hive"
    },
    {
      "x": -19,
      "y": 0,
      "z": -6,
      "name": "Soil_Hive"
    },
    {
      "x": -19,
      "y": 1,
      "z": -6,
      "name": "Soil_Hive"
    },
    {
      "x": -19,
      "y": 2,
      "z": -6,
      "name": "Soil_Hive"
    },
    {
      "x": -19,
      "y": 3,
      "z": -6,
      "name": "Soil_Hive"
    },
    {
      "x": -19,
      "y": 0,
      "z": -5,
      "name": "Soil_Hive"
    },
    {
      "x": -19,
      "y": 1,
      "z": -5,
      "name": "Soil_Hive"
    },
    {
      "x": -19,
      "y": 2,
      "z": -5,
      "name": "Soil_Hive"
    },
    {
      "x": -19,
      "y": 3,
      "z": -5,
      "name": "Soil_Hive"
    },
    {
      "x": -19,
      "y": 4,
      "z": -5,
      "name": "Soil_Hive"
    },
    {
      "x": -19,
      "y": 0,
      "z": -4,
      "name": "Soil_Hive"
    },
    {
      "x": -19,
      "y": 1,
      "z": -4,
      "name": "Soil_Hive"
    },
    {
      "x": -19,
      "y": 2,
      "z": -4,
      "name": "Soil_Hive"
    },
    {
      "x": -19,
      "y": 3,
      "z": -4,
      "name": "Soil_Hive"
    },
    {
      "x": -19,
      "y": 4,
      "z": -4,
      "name": "Soil_Hive"
    },
    {
      "x": -19,
      "y": 0,
      "z": -3,
      "name": "Soil_Hive"
    },
    {
      "x": -19,
      "y": 1,
      "z": -3,
      "name": "Soil_Hive"
    },
    {
      "x": -19,
      "y": 2,
      "z": -3,
      "name": "Soil_Hive"
    },
    {
      "x": -19,
      "y": 3,
      "z": -3,
      "name": "Soil_Hive"
    },
    {
      "x": -19,
      "y": 0,
      "z": -2,
      "name": "Soil_Hive"
    },
    {
      "x": -19,
      "y": 1,
      "z": -2,
      "name": "Soil_Hive"
    },
    {
      "x": -19,
      "y": 2,
      "z": -2,
      "name": "Soil_Hive"
    },
    {
      "x": -19,
      "y": 3,
      "z": -2,
      "name": "Soil_Hive"
    },
    {
      "x": -19,
      "y": 0,
      "z": -1,
      "name": "Soil_Hive"
    },
    {
      "x": -19,
      "y": 1,
      "z": -1,
      "name": "Soil_Hive"
    },
    {
      "x": -19,
      "y": 2,
      "z": -1,
      "name": "Soil_Hive"
    },
    {
      "x": -19,
      "y": 3,
      "z": -1,
      "name": "Soil_Hive"
    },
    {
      "x": -19,
      "y": 0,
      "z": 0,
      "name": "Soil_Hive"
    },
    {
      "x": -19,
      "y": 1,
      "z": 0,
      "name": "Soil_Hive"
    },
    {
      "x": -19,
      "y": 2,
      "z": 0,
      "name": "Soil_Hive"
    },
    {
      "x": -19,
      "y": 3,
      "z": 0,
      "name": "Soil_Hive"
    },
    {
      "x": -19,
      "y": 0,
      "z": 1,
      "name": "Soil_Hive"
    },
    {
      "x": -19,
      "y": 1,
      "z": 1,
      "name": "Soil_Hive"
    },
    {
      "x": -19,
      "y": 2,
      "z": 1,
      "name": "Soil_Hive"
    },
    {
      "x": -19,
      "y": 3,
      "z": 1,
      "name": "Soil_Hive"
    },
    {
      "x": -19,
      "y": 4,
      "z": 1,
      "name": "Soil_Hive"
    },
    {
      "x": -19,
      "y": 0,
      "z": 2,
      "name": "Soil_Hive"
    },
    {
      "x": -19,
      "y": 1,
      "z": 2,
      "name": "Soil_Hive"
    },
    {
      "x": -19,
      "y": 2,
      "z": 2,
      "name": "Soil_Hive"
    },
    {
      "x": -19,
      "y": 3,
      "z": 2,
      "name": "Soil_Hive"
    },
    {
      "x": -19,
      "y": 0,
      "z": 3,
      "name": "Soil_Hive"
    },
    {
      "x": -19,
      "y": 1,
      "z": 3,
      "name": "Soil_Hive"
    },
    {
      "x": -19,
      "y": 2,
      "z": 3,
      "name": "Soil_Hive"
    },
    {
      "x": -19,
      "y": 3,
      "z": 3,
      "name": "Soil_Hive"
    },
    {
      "x": -19,
      "y": 0,
      "z": 4,
      "name": "Soil_Hive"
    },
    {
      "x": -19,
      "y": 1,
      "z": 4,
      "name": "Soil_Hive"
    },
    {
      "x": -19,
      "y": 2,
      "z": 4,
      "name": "Soil_Hive"
    },
    {
      "x": -19,
      "y": 3,
      "z": 4,
      "name": "Soil_Hive"
    },
    {
      "x": -19,
      "y": 0,
      "z": 5,
      "name": "Soil_Hive"
    },
    {
      "x": -19,
      "y": 1,
      "z": 5,
      "name": "Soil_Hive"
    },
    {
      "x": -19,
      "y": 2,
      "z": 5,
      "name": "Soil_Hive"
    },
    {
      "x": -19,
      "y": 3,
      "z": 5,
      "name": "Soil_Hive"
    },
    {
      "x": -19,
      "y": 0,
      "z": 6,
      "name": "Soil_Hive"
    },
    {
      "x": -19,
      "y": 1,
      "z": 6,
      "name": "Soil_Hive"
    },
    {
      "x": -19,
      "y": 2,
      "z": 6,
      "name": "Soil_Hive"
    },
    {
      "x": -19,
      "y": 3,
      "z": 6,
      "name": "Soil_Hive"
    },
    {
      "x": -19,
      "y": 0,
      "z": 7,
      "name": "Soil_Hive"
    },
    {
      "x": -19,
      "y": 1,
      "z": 7,
      "name": "Soil_Hive"
    },
    {
      "x": -19,
      "y": 2,
      "z": 7,
      "name": "Soil_Hive"
    },
    {
      "x": -19,
      "y": 3,
      "z": 7,
      "name": "Soil_Hive"
    },
    {
      "x": -19,
      "y": 0,
      "z": 8,
      "name": "Soil_Hive"
    },
    {
      "x": -19,
      "y": 1,
      "z": 8,
      "name": "Soil_Hive"
    },
    {
      "x": -19,
      "y": 2,
      "z": 8,
      "name": "Soil_Hive"
    },
    {
      "x": -19,
      "y": 3,
      "z": 8,
      "name": "Soil_Hive"
    },
    {
      "x": -19,
      "y": 4,
      "z": 8,
      "name": "Soil_Hive"
    },
    {
      "x": -19,
      "y": 0,
      "z": 9,
      "name": "Soil_Hive"
    },
    {
      "x": -19,
      "y": 1,
      "z": 9,
      "name": "Soil_Hive"
    },
    {
      "x": -19,
      "y": 2,
      "z": 9,
      "name": "Soil_Hive"
    },
    {
      "x": -19,
      "y": 3,
      "z": 9,
      "name": "Soil_Hive"
    },
    {
      "x": -19,
      "y": 0,
      "z": 10,
      "name": "Soil_Hive"
    },
    {
      "x": -19,
      "y": 1,
      "z": 10,
      "name": "Soil_Hive"
    },
    {
      "x": -19,
      "y": 2,
      "z": 10,
      "name": "Soil_Hive"
    },
    {
      "x": -19,
      "y": 3,
      "z": 10,
      "name": "Soil_Hive"
    },
    {
      "x": -19,
      "y": 0,
      "z": 11,
      "name": "Soil_Hive"
    },
    {
      "x": -19,
      "y": 1,
      "z": 11,
      "name": "Soil_Hive"
    },
    {
      "x": -19,
      "y": 2,
      "z": 11,
      "name": "Soil_Hive"
    },
    {
      "x": -19,
      "y": 3,
      "z": 11,
      "name": "Soil_Hive"
    },
    {
      "x": -19,
      "y": 0,
      "z": 12,
      "name": "Soil_Hive"
    },
    {
      "x": -19,
      "y": 1,
      "z": 12,
      "name": "Soil_Hive"
    },
    {
      "x": -19,
      "y": 2,
      "z": 12,
      "name": "Soil_Hive"
    },
    {
      "x": -19,
      "y": 3,
      "z": 12,
      "name": "Soil_Hive"
    },
    {
      "x": -19,
      "y": 0,
      "z": 13,
      "name": "Soil_Hive"
    },
    {
      "x": -19,
      "y": 1,
      "z": 13,
      "name": "Soil_Hive"
    },
    {
      "x": -19,
      "y": 2,
      "z": 13,
      "name": "Soil_Hive"
    },
    {
      "x": -19,
      "y": 3,
      "z": 13,
      "name": "Soil_Hive"
    },
    {
      "x": -19,
      "y": 4,
      "z": 13,
      "name": "Soil_Hive"
    },
    {
      "x": -19,
      "y": 0,
      "z": 14,
      "name": "Soil_Hive"
    },
    {
      "x": -19,
      "y": 1,
      "z": 14,
      "name": "Soil_Hive"
    },
    {
      "x": -19,
      "y": 2,
      "z": 14,
      "name": "Soil_Hive"
    },
    {
      "x": -19,
      "y": 3,
      "z": 14,
      "name": "Soil_Hive"
    },
    {
      "x": -19,
      "y": 0,
      "z": 15,
      "name": "Soil_Hive"
    },
    {
      "x": -19,
      "y": 1,
      "z": 15,
      "name": "Soil_Hive"
    },
    {
      "x": -19,
      "y": 2,
      "z": 15,
      "name": "Soil_Hive"
    },
    {
      "x": -19,
      "y": 3,
      "z": 15,
      "name": "Soil_Hive"
    },
    {
      "x": -19,
      "y": 0,
      "z": 23,
      "name": "Soil_Hive"
    },
    {
      "x": -19,
      "y": 1,
      "z": 23,
      "name": "Soil_Hive"
    },
    {
      "x": -19,
      "y": 2,
      "z": 23,
      "name": "Soil_Hive"
    },
    {
      "x": -19,
      "y": 3,
      "z": 23,
      "name": "Soil_Hive"
    },
    {
      "x": -19,
      "y": 0,
      "z": 24,
      "name": "Soil_Hive"
    },
    {
      "x": -19,
      "y": 1,
      "z": 24,
      "name": "Soil_Hive"
    },
    {
      "x": -19,
      "y": 2,
      "z": 24,
      "name": "Soil_Hive"
    },
    {
      "x": -19,
      "y": 3,
      "z": 24,
      "name": "Soil_Hive"
    },
    {
      "x": -19,
      "y": 0,
      "z": 28,
      "name": "Soil_Hive"
    },
    {
      "x": -19,
      "y": 1,
      "z": 28,
      "name": "Soil_Hive"
    },
    {
      "x": -19,
      "y": 2,
      "z": 28,
      "name": "Soil_Hive"
    },
    {
      "x": -19,
      "y": 3,
      "z": 28,
      "name": "Soil_Hive"
    },
    {
      "x": -18,
      "y": 0,
      "z": -23,
      "name": "Soil_Hive"
    },
    {
      "x": -18,
      "y": 1,
      "z": -23,
      "name": "Soil_Hive"
    },
    {
      "x": -18,
      "y": 2,
      "z": -23,
      "name": "Soil_Hive"
    },
    {
      "x": -18,
      "y": 3,
      "z": -23,
      "name": "Soil_Hive"
    },
    {
      "x": -18,
      "y": 0,
      "z": -22,
      "name": "Soil_Hive"
    },
    {
      "x": -18,
      "y": 1,
      "z": -22,
      "name": "Soil_Hive"
    },
    {
      "x": -18,
      "y": 2,
      "z": -22,
      "name": "Soil_Hive"
    },
    {
      "x": -18,
      "y": 3,
      "z": -22,
      "name": "Soil_Hive"
    },
    {
      "x": -18,
      "y": 0,
      "z": -17,
      "name": "Soil_Hive"
    },
    {
      "x": -18,
      "y": 1,
      "z": -17,
      "name": "Soil_Hive"
    },
    {
      "x": -18,
      "y": 2,
      "z": -17,
      "name": "Soil_Hive"
    },
    {
      "x": -18,
      "y": 3,
      "z": -17,
      "name": "Soil_Hive"
    },
    {
      "x": -18,
      "y": 0,
      "z": -16,
      "name": "Soil_Hive"
    },
    {
      "x": -18,
      "y": 1,
      "z": -16,
      "name": "Soil_Hive"
    },
    {
      "x": -18,
      "y": 2,
      "z": -16,
      "name": "Soil_Hive"
    },
    {
      "x": -18,
      "y": 3,
      "z": -16,
      "name": "Soil_Hive"
    },
    {
      "x": -18,
      "y": 0,
      "z": -15,
      "name": "Soil_Hive"
    },
    {
      "x": -18,
      "y": 1,
      "z": -15,
      "name": "Soil_Hive"
    },
    {
      "x": -18,
      "y": 2,
      "z": -15,
      "name": "Soil_Hive"
    },
    {
      "x": -18,
      "y": 3,
      "z": -15,
      "name": "Soil_Hive"
    },
    {
      "x": -18,
      "y": 4,
      "z": -15,
      "name": "Soil_Hive"
    },
    {
      "x": -18,
      "y": 0,
      "z": -14,
      "name": "Soil_Hive"
    },
    {
      "x": -18,
      "y": 1,
      "z": -14,
      "name": "Soil_Hive"
    },
    {
      "x": -18,
      "y": 2,
      "z": -14,
      "name": "Soil_Hive"
    },
    {
      "x": -18,
      "y": 3,
      "z": -14,
      "name": "Soil_Hive"
    },
    {
      "x": -18,
      "y": 0,
      "z": -13,
      "name": "Soil_Hive"
    },
    {
      "x": -18,
      "y": 1,
      "z": -13,
      "name": "Soil_Hive"
    },
    {
      "x": -18,
      "y": 2,
      "z": -13,
      "name": "Soil_Hive"
    },
    {
      "x": -18,
      "y": 3,
      "z": -13,
      "name": "Soil_Hive"
    },
    {
      "x": -18,
      "y": 0,
      "z": -12,
      "name": "Soil_Hive"
    },
    {
      "x": -18,
      "y": 1,
      "z": -12,
      "name": "Soil_Hive"
    },
    {
      "x": -18,
      "y": 2,
      "z": -12,
      "name": "Soil_Hive"
    },
    {
      "x": -18,
      "y": 3,
      "z": -12,
      "name": "Soil_Hive"
    },
    {
      "x": -18,
      "y": 0,
      "z": -11,
      "name": "Soil_Hive"
    },
    {
      "x": -18,
      "y": 1,
      "z": -11,
      "name": "Soil_Hive"
    },
    {
      "x": -18,
      "y": 2,
      "z": -11,
      "name": "Soil_Hive"
    },
    {
      "x": -18,
      "y": 3,
      "z": -11,
      "name": "Soil_Hive"
    },
    {
      "x": -18,
      "y": 0,
      "z": -7,
      "name": "Soil_Hive"
    },
    {
      "x": -18,
      "y": 1,
      "z": -7,
      "name": "Soil_Hive"
    },
    {
      "x": -18,
      "y": 2,
      "z": -7,
      "name": "Soil_Hive"
    },
    {
      "x": -18,
      "y": 3,
      "z": -7,
      "name": "Soil_Hive"
    },
    {
      "x": -18,
      "y": 0,
      "z": -6,
      "name": "Soil_Hive"
    },
    {
      "x": -18,
      "y": 1,
      "z": -6,
      "name": "Soil_Hive"
    },
    {
      "x": -18,
      "y": 2,
      "z": -6,
      "name": "Soil_Hive"
    },
    {
      "x": -18,
      "y": 3,
      "z": -6,
      "name": "Soil_Hive"
    },
    {
      "x": -18,
      "y": 0,
      "z": -5,
      "name": "Soil_Hive"
    },
    {
      "x": -18,
      "y": 1,
      "z": -5,
      "name": "Soil_Hive"
    },
    {
      "x": -18,
      "y": 2,
      "z": -5,
      "name": "Soil_Hive"
    },
    {
      "x": -18,
      "y": 3,
      "z": -5,
      "name": "Soil_Hive"
    },
    {
      "x": -18,
      "y": 4,
      "z": -5,
      "name": "Soil_Hive"
    },
    {
      "x": -18,
      "y": 0,
      "z": -4,
      "name": "Soil_Hive"
    },
    {
      "x": -18,
      "y": 1,
      "z": -4,
      "name": "Soil_Hive"
    },
    {
      "x": -18,
      "y": 2,
      "z": -4,
      "name": "Soil_Hive"
    },
    {
      "x": -18,
      "y": 3,
      "z": -4,
      "name": "Soil_Hive"
    },
    {
      "x": -18,
      "y": 4,
      "z": -4,
      "name": "Soil_Hive"
    },
    {
      "x": -18,
      "y": 0,
      "z": -3,
      "name": "Soil_Hive"
    },
    {
      "x": -18,
      "y": 1,
      "z": -3,
      "name": "Soil_Hive"
    },
    {
      "x": -18,
      "y": 2,
      "z": -3,
      "name": "Soil_Hive"
    },
    {
      "x": -18,
      "y": 3,
      "z": -3,
      "name": "Soil_Hive"
    },
    {
      "x": -18,
      "y": 0,
      "z": -2,
      "name": "Soil_Hive"
    },
    {
      "x": -18,
      "y": 1,
      "z": -2,
      "name": "Soil_Hive"
    },
    {
      "x": -18,
      "y": 2,
      "z": -2,
      "name": "Soil_Hive"
    },
    {
      "x": -18,
      "y": 3,
      "z": -2,
      "name": "Soil_Hive"
    },
    {
      "x": -18,
      "y": 0,
      "z": -1,
      "name": "Soil_Hive"
    },
    {
      "x": -18,
      "y": 1,
      "z": -1,
      "name": "Soil_Hive"
    },
    {
      "x": -18,
      "y": 2,
      "z": -1,
      "name": "Soil_Hive"
    },
    {
      "x": -18,
      "y": 3,
      "z": -1,
      "name": "Soil_Hive"
    },
    {
      "x": -18,
      "y": 0,
      "z": 0,
      "name": "Soil_Hive"
    },
    {
      "x": -18,
      "y": 1,
      "z": 0,
      "name": "Soil_Hive"
    },
    {
      "x": -18,
      "y": 2,
      "z": 0,
      "name": "Soil_Hive"
    },
    {
      "x": -18,
      "y": 3,
      "z": 0,
      "name": "Soil_Hive"
    },
    {
      "x": -18,
      "y": 0,
      "z": 1,
      "name": "Soil_Hive"
    },
    {
      "x": -18,
      "y": 1,
      "z": 1,
      "name": "Soil_Hive"
    },
    {
      "x": -18,
      "y": 2,
      "z": 1,
      "name": "Soil_Hive"
    },
    {
      "x": -18,
      "y": 3,
      "z": 1,
      "name": "Soil_Hive"
    },
    {
      "x": -18,
      "y": 4,
      "z": 1,
      "name": "Soil_Hive"
    },
    {
      "x": -18,
      "y": 0,
      "z": 2,
      "name": "Soil_Hive"
    },
    {
      "x": -18,
      "y": 1,
      "z": 2,
      "name": "Soil_Hive"
    },
    {
      "x": -18,
      "y": 2,
      "z": 2,
      "name": "Soil_Hive"
    },
    {
      "x": -18,
      "y": 3,
      "z": 2,
      "name": "Soil_Hive"
    },
    {
      "x": -18,
      "y": 0,
      "z": 3,
      "name": "Soil_Hive"
    },
    {
      "x": -18,
      "y": 1,
      "z": 3,
      "name": "Soil_Hive"
    },
    {
      "x": -18,
      "y": 2,
      "z": 3,
      "name": "Soil_Hive"
    },
    {
      "x": -18,
      "y": 3,
      "z": 3,
      "name": "Soil_Hive"
    },
    {
      "x": -18,
      "y": 0,
      "z": 4,
      "name": "Soil_Hive"
    },
    {
      "x": -18,
      "y": 1,
      "z": 4,
      "name": "Soil_Hive"
    },
    {
      "x": -18,
      "y": 2,
      "z": 4,
      "name": "Soil_Hive"
    },
    {
      "x": -18,
      "y": 3,
      "z": 4,
      "name": "Soil_Hive"
    },
    {
      "x": -18,
      "y": 0,
      "z": 5,
      "name": "Soil_Hive"
    },
    {
      "x": -18,
      "y": 1,
      "z": 5,
      "name": "Soil_Hive"
    },
    {
      "x": -18,
      "y": 2,
      "z": 5,
      "name": "Soil_Hive"
    },
    {
      "x": -18,
      "y": 3,
      "z": 5,
      "name": "Soil_Hive"
    },
    {
      "x": -18,
      "y": 0,
      "z": 6,
      "name": "Soil_Hive"
    },
    {
      "x": -18,
      "y": 1,
      "z": 6,
      "name": "Soil_Hive"
    },
    {
      "x": -18,
      "y": 2,
      "z": 6,
      "name": "Soil_Hive"
    },
    {
      "x": -18,
      "y": 3,
      "z": 6,
      "name": "Soil_Hive"
    },
    {
      "x": -18,
      "y": 0,
      "z": 7,
      "name": "Soil_Hive"
    },
    {
      "x": -18,
      "y": 1,
      "z": 7,
      "name": "Soil_Hive"
    },
    {
      "x": -18,
      "y": 2,
      "z": 7,
      "name": "Soil_Hive"
    },
    {
      "x": -18,
      "y": 3,
      "z": 7,
      "name": "Soil_Hive"
    },
    {
      "x": -18,
      "y": 0,
      "z": 8,
      "name": "Soil_Hive"
    },
    {
      "x": -18,
      "y": 1,
      "z": 8,
      "name": "Soil_Hive"
    },
    {
      "x": -18,
      "y": 2,
      "z": 8,
      "name": "Soil_Hive"
    },
    {
      "x": -18,
      "y": 3,
      "z": 8,
      "name": "Soil_Hive"
    },
    {
      "x": -18,
      "y": 4,
      "z": 8,
      "name": "Soil_Hive"
    },
    {
      "x": -18,
      "y": 0,
      "z": 9,
      "name": "Soil_Hive"
    },
    {
      "x": -18,
      "y": 1,
      "z": 9,
      "name": "Soil_Hive"
    },
    {
      "x": -18,
      "y": 2,
      "z": 9,
      "name": "Soil_Hive"
    },
    {
      "x": -18,
      "y": 3,
      "z": 9,
      "name": "Soil_Hive"
    },
    {
      "x": -18,
      "y": 0,
      "z": 10,
      "name": "Soil_Hive"
    },
    {
      "x": -18,
      "y": 1,
      "z": 10,
      "name": "Soil_Hive"
    },
    {
      "x": -18,
      "y": 2,
      "z": 10,
      "name": "Soil_Hive"
    },
    {
      "x": -18,
      "y": 3,
      "z": 10,
      "name": "Soil_Hive"
    },
    {
      "x": -18,
      "y": 0,
      "z": 11,
      "name": "Soil_Hive"
    },
    {
      "x": -18,
      "y": 1,
      "z": 11,
      "name": "Soil_Hive"
    },
    {
      "x": -18,
      "y": 2,
      "z": 11,
      "name": "Soil_Hive"
    },
    {
      "x": -18,
      "y": 3,
      "z": 11,
      "name": "Soil_Hive"
    },
    {
      "x": -18,
      "y": 4,
      "z": 11,
      "name": "Soil_Hive"
    },
    {
      "x": -18,
      "y": 0,
      "z": 12,
      "name": "Soil_Hive"
    },
    {
      "x": -18,
      "y": 1,
      "z": 12,
      "name": "Soil_Hive"
    },
    {
      "x": -18,
      "y": 2,
      "z": 12,
      "name": "Soil_Hive"
    },
    {
      "x": -18,
      "y": 3,
      "z": 12,
      "name": "Soil_Hive"
    },
    {
      "x": -18,
      "y": 4,
      "z": 12,
      "name": "Soil_Hive"
    },
    {
      "x": -18,
      "y": 0,
      "z": 13,
      "name": "Soil_Hive"
    },
    {
      "x": -18,
      "y": 1,
      "z": 13,
      "name": "Soil_Hive"
    },
    {
      "x": -18,
      "y": 2,
      "z": 13,
      "name": "Soil_Hive"
    },
    {
      "x": -18,
      "y": 3,
      "z": 13,
      "name": "Soil_Hive"
    },
    {
      "x": -18,
      "y": 0,
      "z": 16,
      "name": "Soil_Hive"
    },
    {
      "x": -18,
      "y": 1,
      "z": 16,
      "name": "Soil_Hive"
    },
    {
      "x": -18,
      "y": 2,
      "z": 16,
      "name": "Soil_Hive"
    },
    {
      "x": -18,
      "y": 3,
      "z": 16,
      "name": "Soil_Hive"
    },
    {
      "x": -18,
      "y": 0,
      "z": 17,
      "name": "Soil_Hive"
    },
    {
      "x": -18,
      "y": 1,
      "z": 17,
      "name": "Soil_Hive"
    },
    {
      "x": -18,
      "y": 2,
      "z": 17,
      "name": "Soil_Hive"
    },
    {
      "x": -18,
      "y": 3,
      "z": 17,
      "name": "Soil_Hive"
    },
    {
      "x": -18,
      "y": 0,
      "z": 18,
      "name": "Soil_Hive"
    },
    {
      "x": -18,
      "y": 1,
      "z": 18,
      "name": "Soil_Hive"
    },
    {
      "x": -18,
      "y": 2,
      "z": 18,
      "name": "Soil_Hive"
    },
    {
      "x": -18,
      "y": 3,
      "z": 18,
      "name": "Soil_Hive"
    },
    {
      "x": -18,
      "y": 0,
      "z": 19,
      "name": "Soil_Hive"
    },
    {
      "x": -18,
      "y": 1,
      "z": 19,
      "name": "Soil_Hive"
    },
    {
      "x": -18,
      "y": 2,
      "z": 19,
      "name": "Soil_Hive"
    },
    {
      "x": -18,
      "y": 3,
      "z": 19,
      "name": "Soil_Hive"
    },
    {
      "x": -18,
      "y": 0,
      "z": 20,
      "name": "Soil_Hive"
    },
    {
      "x": -18,
      "y": 1,
      "z": 20,
      "name": "Soil_Hive"
    },
    {
      "x": -18,
      "y": 2,
      "z": 20,
      "name": "Soil_Hive"
    },
    {
      "x": -18,
      "y": 3,
      "z": 20,
      "name": "Soil_Hive"
    },
    {
      "x": -18,
      "y": 0,
      "z": 21,
      "name": "Soil_Hive"
    },
    {
      "x": -18,
      "y": 1,
      "z": 21,
      "name": "Soil_Hive"
    },
    {
      "x": -18,
      "y": 2,
      "z": 21,
      "name": "Soil_Hive"
    },
    {
      "x": -18,
      "y": 3,
      "z": 21,
      "name": "Soil_Hive"
    },
    {
      "x": -18,
      "y": 0,
      "z": 22,
      "name": "Soil_Hive"
    },
    {
      "x": -18,
      "y": 1,
      "z": 22,
      "name": "Soil_Hive"
    },
    {
      "x": -18,
      "y": 2,
      "z": 22,
      "name": "Soil_Hive"
    },
    {
      "x": -18,
      "y": 3,
      "z": 22,
      "name": "Soil_Hive"
    },
    {
      "x": -18,
      "y": 0,
      "z": 23,
      "name": "Soil_Hive"
    },
    {
      "x": -18,
      "y": 1,
      "z": 23,
      "name": "Soil_Hive"
    },
    {
      "x": -18,
      "y": 2,
      "z": 23,
      "name": "Soil_Hive"
    },
    {
      "x": -18,
      "y": 3,
      "z": 23,
      "name": "Soil_Hive"
    },
    {
      "x": -18,
      "y": 0,
      "z": 28,
      "name": "Soil_Hive"
    },
    {
      "x": -18,
      "y": 1,
      "z": 28,
      "name": "Soil_Hive"
    },
    {
      "x": -18,
      "y": 2,
      "z": 28,
      "name": "Soil_Hive"
    },
    {
      "x": -18,
      "y": 3,
      "z": 28,
      "name": "Soil_Hive"
    },
    {
      "x": -17,
      "y": 0,
      "z": -24,
      "name": "Soil_Hive"
    },
    {
      "x": -17,
      "y": 1,
      "z": -24,
      "name": "Soil_Hive"
    },
    {
      "x": -17,
      "y": 2,
      "z": -24,
      "name": "Soil_Hive"
    },
    {
      "x": -17,
      "y": 3,
      "z": -24,
      "name": "Soil_Hive"
    },
    {
      "x": -17,
      "y": 0,
      "z": -23,
      "name": "Soil_Hive"
    },
    {
      "x": -17,
      "y": 1,
      "z": -23,
