{
  "version": 8,
  "blockIdVersion": 8,
  "anchorX": 9,
  "anchorY": 8,
  "anchorZ": 11,
  "blocks": [
    {
      "x": 2,
      "y": 32,
      "z": 4,
      "name": "Rock_Volcanic_Cracked_Poisoned"
    },
    {
      "x": 2,
      "y": 33,
      "z": 4,
      "name": "Rock_Volcanic_Cracked_Poisoned"
    },
    {
      "x": 2,
      "y": 34,
      "z": 4,
      "name": "Rock_Volcanic_Cracked_Poisoned"
    },
    {
      "x": 2,
      "y": 35,
      "z": 4,
      "name": "Rock_Volcanic_Cracked_Poisoned"
    },
    {
      "x": 2,
      "y": 36,
      "z": 4,
      "name": "Rock_Volcanic_Cracked_Poisoned"
    },
    {
      "x": 3,
      "y": 29,
      "z": 4,
      "name": "Rock_Volcanic_Cracked_Poisoned"
    },
    {
      "x": 3,
      "y": 30,
      "z": 4,
      "name": "Rock_Volcanic_Cracked_Poisoned"
    },
    {
      "x": 3,
      "y": 31,
      "z": 4,
      "name": "Rock_Volcanic_Cracked_Poisoned"
    },
    {
      "x": 3,
      "y": 32,
      "z": 4,
      "name": "Rock_Volcanic_Cracked_Poisoned"
    },
    {
      "x": 3,
      "y": 33,
      "z": 4,
      "name": "Rock_Volcanic_Cracked_Poisoned"
    },
    {
      "x": 3,
      "y": 28,
      "z": 5,
      "name": "Rock_Volcanic_Cracked_Poisoned"
    },
    {
      "x": 3,
      "y": 29,
      "z": 5,
      "name": "Rock_Volcanic_Cracked_Poisoned"
    },
    {
      "x": 3,
      "y": 30,
      "z": 5,
      "name": "Rock_Volcanic_Cracked_Poisoned"
    },
    {
      "x": 3,
      "y": 31,
      "z": 5,
      "name": "Rock_Volcanic_Cracked_Poisoned"
    },
    {
      "x": 3,
      "y": 32,
      "z": 5,
      "name": "Rock_Volcanic_Cracked_Poisoned"
    },
    {
      "x": 3,
      "y": 25,
      "z": 6,
      "name": "Plant_Coral_Block_Green"
    },
    {
      "x": 3,
      "y": 26,
      "z": 6,
      "name": "Plant_Coral_Block_Green"
    },
    {
      "x": 3,
      "y": 27,
      "z": 6,
      "name": "Rock_Volcanic_Cracked_Poisoned"
    },
    {
      "x": 3,
      "y": 28,
      "z": 6,
      "name": "Rock_Volcanic_Cracked_Poisoned"
    },
    {
      "x": 3,
      "y": 29,
      "z": 6,
      "name": "Rock_Volcanic_Cracked_Poisoned"
    },
    {
      "x": 3,
      "y": 25,
      "z": 7,
      "name": "Plant_Coral_Block_Green"
    },
    {
      "x": 3,
      "y": 26,
      "z": 7,
      "name": "Plant_Coral_Block_Green"
    },
    {
      "x": 4,
      "y": 28,
      "z": 4,
      "name": "Rock_Volcanic_Cracked_Poisoned"
    },
    {
      "x": 4,
      "y": 29,
      "z": 4,
      "name": "Rock_Volcanic_Cracked_Poisoned"
    },
    {
      "x": 4,
      "y": 30,
      "z": 4,
      "name": "Rock_Volcanic_Cracked_Poisoned"
    },
    {
      "x": 4,
      "y": 31,
      "z": 4,
      "name": "Rock_Volcanic_Cracked_Poisoned"
    },
    {
      "x": 4,
      "y": 26,
      "z": 5,
      "name": "Rock_Volcanic_Cracked_Poisoned"
    },
    {
      "x": 4,
      "y": 27,
      "z": 5,
      "name": "Rock_Volcanic_Cracked_Poisoned"
    },
    {
      "x": 4,
      "y": 28,
      "z": 5,
      "name": "Rock_Volcanic_Cracked_Poisoned"
    },
    {
      "x": 4,
      "y": 29,
      "z": 5,
      "name": "Rock_Volcanic_Cracked_Poisoned"
    },
    {
      "x": 4,
      "y": 30,
      "z": 5,
      "name": "Rock_Volcanic_Cracked_Poisoned"
    },
    {
      "x": 4,
      "y": 31,
      "z": 5,
      "name": "Rock_Volcanic_Cracked_Poisoned"
    },
    {
      "x": 4,
      "y": 6,
      "z": 6,
      "name": "Rock_Volcanic_Cracked_Poisoned"
    },
    {
      "x": 4,
      "y": 7,
      "z": 6,
      "name": "Rock_Volcanic_Cracked_Poisoned"
    },
    {
      "x": 4,
      "y": 22,
      "z": 6,
      "name": "Rock_Volcanic_Cracked_Poisoned"
    },
    {
      "x": 4,
      "y": 23,
      "z": 6,
      "name": "Rock_Volcanic_Cracked_Poisoned"
    },
    {
      "x": 4,
      "y": 24,
      "z": 6,
      "name": "Rock_Volcanic_Cracked_Poisoned"
    },
    {
      "x": 4,
      "y": 25,
      "z": 6,
      "name": "Plant_Coral_Block_Green"
    },
    {
      "x": 4,
      "y": 26,
      "z": 6,
      "name": "Plant_Coral_Block_Green"
    },
    {
      "x": 4,
      "y": 27,
      "z": 6,
      "name": "Rock_Volcanic_Cracked_Poisoned"
    },
    {
      "x": 4,
      "y": 28,
      "z": 6,
      "name": "Rock_Volcanic_Cracked_Poisoned"
    },
    {
      "x": 4,
      "y": 29,
      "z": 6,
      "name": "Rock_Volcanic_Cracked_Poisoned"
    },
    {
      "x": 4,
      "y": 7,
      "z": 7,
      "name": "Rock_Volcanic_Cracked_Poisoned"
    },
    {
      "x": 4,
      "y": 8,
      "z": 7,
      "name": "Rock_Volcanic_Cracked_Poisoned"
    },
    {
      "x": 4,
      "y": 21,
      "z": 7,
      "name": "Rock_Volcanic_Cracked_Poisoned"
    },
    {
      "x": 4,
      "y": 22,
      "z": 7,
      "name": "Rock_Volcanic_Cracked_Poisoned"
    },
    {
      "x": 4,
      "y": 23,
      "z": 7,
      "name": "Rock_Volcanic_Cracked_Poisoned"
    },
    {
      "x": 4,
      "y": 24,
      "z": 7,
      "name": "Rock_Volcanic_Cracked_Poisoned"
    },
    {
      "x": 4,
      "y": 25,
      "z": 7,
      "name": "Plant_Coral_Block_Green"
    },
    {
      "x": 4,
      "y": 26,
      "z": 7,
      "name": "Plant_Coral_Block_Green"
    },
    {
      "x": 4,
      "y": 27,
      "z": 7,
      "name": "Rock_Volcanic_Cracked_Poisoned"
    },
    {
      "x": 4,
      "y": 28,
      "z": 7,
      "name": "Rock_Volcanic_Cracked_Poisoned"
    },
    {
      "x": 4,
      "y": 22,
      "z": 8,
      "name": "Rock_Volcanic_Cracked_Poisoned"
    },
    {
      "x": 4,
      "y": 23,
      "z": 8,
      "name": "Rock_Volcanic_Cracked_Poisoned"
    },
    {
      "x": 4,
      "y": 24,
      "z": 8,
      "name": "Rock_Volcanic_Cracked_Poisoned"
    },
    {
      "x": 4,
      "y": 25,
      "z": 8,
      "name": "Rock_Volcanic_Cracked_Poisoned"
    },
    {
      "x": 4,
      "y": 26,
      "z": 8,
      "name": "Rock_Volcanic_Cracked_Poisoned"
    },
    {
      "x": 4,
      "y": 27,
      "z": 8,
      "name": "Rock_Volcanic_Cracked_Poisoned"
    },
    {
      "x": 4,
      "y": 7,
      "z": 14,
      "name": "Rock_Volcanic_Cracked_Poisoned"
    },
    {
      "x": 4,
      "y": 8,
      "z": 14,
      "name": "Rock_Volcanic_Cracked_Poisoned"
    },
    {
      "x": 4,
      "y": 5,
      "z": 15,
      "name": "Rock_Volcanic_Cracked_Poisoned"
    },
    {
      "x": 4,
      "y": 6,
      "z": 15,
      "name": "Rock_Volcanic_Cracked_Poisoned"
    },
    {
      "x": 4,
      "y": 7,
      "z": 15,
      "name": "Rock_Volcanic_Cracked_Poisoned"
    },
    {
      "x": 5,
      "y": 4,
      "z": 4,
      "name": "Rock_Volcanic_Cracked_Poisoned"
    },
    {
      "x": 5,
      "y": 5,
      "z": 4,
      "name": "Rock_Volcanic_Cracked_Poisoned"
    },
    {
      "x": 5,
      "y": 5,
      "z": 5,
      "name": "Rock_Volcanic_Cracked_Poisoned"
    },
    {
      "x": 5,
      "y": 6,
      "z": 5,
      "name": "Rock_Volcanic_Cracked_Poisoned"
    },
    {
      "x": 5,
      "y": 22,
      "z": 5,
      "name": "Rock_Volcanic_Cracked_Poisoned"
    },
    {
      "x": 5,
      "y": 23,
      "z": 5,
      "name": "Rock_Volcanic_Cracked_Poisoned"
    },
    {
      "x": 5,
      "y": 24,
      "z": 5,
      "name": "Rock_Volcanic_Cracked_Poisoned"
    },
    {
      "x": 5,
      "y": 25,
      "z": 5,
      "name": "Rock_Volcanic_Cracked_Poisoned"
    },
    {
      "x": 5,
      "y": 26,
      "z": 5,
      "name": "Rock_Volcanic_Cracked_Poisoned"
    },
    {
      "x": 5,
      "y": 27,
      "z": 5,
      "name": "Rock_Volcanic_Cracked_Poisoned"
    },
    {
      "x": 5,
      "y": 28,
      "z": 5,
      "name": "Rock_Volcanic_Cracked_Poisoned"
    },
    {
      "x": 5,
      "y": 29,
      "z": 5,
      "name": "Rock_Volcanic_Cracked_Poisoned"
    },
    {
      "x": 5,
      "y": 30,
      "z": 5,
      "name": "Rock_Volcanic_Cracked_Poisoned"
    },
    {
      "x": 5,
      "y": 5,
      "z": 6,
      "name": "Rock_Volcanic_Cracked_Poisoned"
    },
    {
      "x": 5,
      "y": 6,
      "z": 6,
      "name": "Rock_Volcanic_Cracked_Poisoned"
    },
    {
      "x": 5,
      "y": 7,
      "z": 6,
      "name": "Rock_Volcanic_Cracked_Poisoned"
    },
    {
      "x": 5,
      "y": 8,
      "z": 6,
      "name": "Rock_Volcanic_Cracked_Poisoned"
    },
    {
      "x": 5,
      "y": 20,
      "z": 6,
      "name": "Rock_Volcanic_Cracked_Poisoned"
    },
    {
      "x": 5,
      "y": 21,
      "z": 6,
      "name": "Rock_Volcanic_Cracked_Poisoned"
    },
    {
      "x": 5,
      "y": 22,
      "z": 6,
      "name": "Rock_Volcanic_Cracked_Poisoned"
    },
    {
      "x": 5,
      "y": 23,
      "z": 6,
      "name": "Rock_Volcanic_Cracked_Poisoned"
    },
    {
      "x": 5,
      "y": 24,
      "z": 6,
      "name": "Rock_Volcanic_Cracked_Poisoned"
    },
    {
      "x": 5,
      "y": 25,
      "z": 6,
      "name": "Rock_Volcanic_Cracked_Poisoned"
    },
    {
      "x": 5,
      "y": 26,
      "z": 6,
      "name": "Rock_Volcanic_Cracked_Poisoned"
    },
    {
      "x": 5,
      "y": 27,
      "z": 6,
      "name": "Rock_Volcanic_Cracked_Poisoned"
    },
    {
      "x": 5,
      "y": 28,
      "z": 6,
      "name": "Rock_Volcanic_Cracked_Poisoned"
    },
    {
      "x": 5,
      "y": 29,
      "z": 6,
      "name": "Rock_Volcanic_Cracked_Poisoned"
    },
    {
      "x": 5,
      "y": 6,
      "z": 7,
      "name": "Rock_Volcanic_Cracked_Poisoned"
    },
    {
      "x": 5,
      "y": 7,
      "z": 7,
      "name": "Rock_Volcanic_Cracked_Poisoned"
    },
    {
      "x": 5,
      "y": 8,
      "z": 7,
      "name": "Rock_Volcanic_Cracked_Poisoned"
    },
    {
      "x": 5,
      "y": 9,
      "z": 7,
      "name": "Rock_Volcanic_Cracked_Poisoned"
    },
    {
      "x": 5,
      "y": 10,
      "z": 7,
      "name": "Rock_Volcanic_Cracked_Poisoned"
    },
    {
      "x": 5,
      "y": 20,
      "z": 7,
      "name": "Rock_Volcanic_Cracked_Poisoned"
    },
    {
      "x": 5,
      "y": 21,
      "z": 7,
      "name": "Rock_Volcanic_Cracked_Poisoned"
    },
    {
      "x": 5,
      "y": 22,
      "z": 7,
      "name": "Rock_Volcanic_Cracked_Poisoned"
    },
    {
      "x": 5,
      "y": 23,
      "z": 7,
      "name": "Rock_Volcanic_Cracked_Poisoned"
    },
    {
      "x": 5,
      "y": 24,
      "z": 7,
      "name": "Rock_Volcanic_Cracked_Poisoned"
    },
    {
      "x": 5,
      "y": 25,
      "z": 7,
      "name": "Rock_Volcanic_Cracked_Poisoned"
    },
    {
      "x": 5,
      "y": 26,
      "z": 7,
      "name": "Plant_Coral_Block_Green"
    },
    {
      "x": 5,
      "y": 27,
      "z": 7,
      "name": "Rock_Volcanic_Cracked_Poisoned"
    },
    {
      "x": 5,
      "y": 28,
      "z": 7,
      "name": "Rock_Volcanic_Cracked_Poisoned"
    },
    {
      "x": 5,
      "y": 29,
      "z": 7,
      "name": "Rock_Volcanic_Cracked_Poisoned"
    },
    {
      "x": 5,
      "y": 7,
      "z": 8,
      "name": "Rock_Volcanic_Cracked_Poisoned"
    },
    {
      "x": 5,
      "y": 8,
      "z": 8,
      "name": "Rock_Volcanic_Cracked_Poisoned"
    },
    {
      "x": 5,
      "y": 9,
      "z": 8,
      "name": "Rock_Volcanic_Cracked_Poisoned"
    },
    {
      "x": 5,
      "y": 10,
      "z": 8,
      "name": "Rock_Volcanic_Cracked_Poisoned"
    },
    {
      "x": 5,
      "y": 18,
      "z": 8,
      "name": "Rock_Volcanic_Cracked_Poisoned"
    },
    {
      "x": 5,
      "y": 19,
      "z": 8,
      "name": "Rock_Volcanic_Cracked_Poisoned"
    },
    {
      "x": 5,
      "y": 20,
      "z": 8,
      "name": "Rock_Volcanic_Cracked_Poisoned"
    },
    {
      "x": 5,
      "y": 21,
      "z": 8,
      "name": "Rock_Volcanic_Cracked_Poisoned"
    },
    {
      "x": 5,
      "y": 22,
      "z": 8,
      "name": "Rock_Volcanic_Cracked_Poisoned"
    },
    {
      "x": 5,
      "y": 23,
      "z": 8,
      "name": "Rock_Volcanic_Cracked_Poisoned"
    },
    {
      "x": 5,
      "y": 24,
      "z": 8,
      "name": "Rock_Volcanic_Cracked_Poisoned"
    },
    {
      "x": 5,
      "y": 25,
      "z": 8,
      "name": "Rock_Volcanic_Cracked_Poisoned"
    },
    {
      "x": 5,
      "y": 26,
      "z": 8,
      "name": "Rock_Volcanic_Cracked_Poisoned"
    },
    {
      "x": 5,
      "y": 27,
      "z": 8,
      "name": "Rock_Volcanic_Cracked_Poisoned"
    },
    {
      "x": 5,
      "y": 28,
      "z": 8,
      "name": "Rock_Volcanic_Cracked_Poisoned"
    },
    {
      "x": 5,
      "y": 29,
      "z": 8,
      "name": "Rock_Volcanic_Cracked_Poisoned"
    },
    {
      "x": 5,
      "y": 30,
      "z": 8,
      "name": "Rock_Volcanic_Cracked_Poisoned"
    },
    {
      "x": 5,
      "y": 19,
      "z": 9,
      "name": "Rock_Volcanic_Cracked_Poisoned"
    },
    {
      "x": 5,
      "y": 20,
      "z": 9,
      "name": "Rock_Volcanic_Cracked_Poisoned"
    },
    {
      "x": 5,
      "y": 21,
      "z": 9,
      "name": "Rock_Volcanic_Cracked_Poisoned"
    },
    {
      "x": 5,
      "y": 24,
      "z": 9,
      "name": "Plant_Coral_Block_Green"
    },
    {
      "x": 5,
      "y": 25,
      "z": 9,
      "name": "Plant_Coral_Block_Green"
    },
    {
      "x": 5,
      "y": 26,
      "z": 9,
      "name": "Rock_Volcanic_Cracked_Poisoned"
    },
    {
      "x": 5,
      "y": 27,
      "z": 9,
      "name": "Rock_Volcanic_Cracked_Poisoned"
    },
    {
      "x": 5,
      "y": 28,
      "z": 9,
      "name": "Rock_Volcanic_Cracked_Poisoned"
    },
    {
      "x": 5,
      "y": 29,
      "z": 9,
      "name": "Rock_Volcanic_Cracked_Poisoned"
    },
    {
      "x": 5,
      "y": 30,
      "z": 9,
      "name": "Rock_Volcanic_Cracked_Poisoned"
    },
    {
      "x": 5,
      "y": 31,
      "z": 9,
      "name": "Plant_Coral_Block_Green"
    },
    {
      "x": 5,
      "y": 32,
      "z": 9,
      "name": "Plant_Coral_Block_Green"
    },
    {
      "x": 5,
      "y": 33,
      "z": 9,
      "name": "Plant_Coral_Block_Green"
    },
    {
      "x": 5,
      "y": 24,
      "z": 10,
      "name": "Plant_Coral_Block_Green"
    },
    {
      "x": 5,
      "y": 25,
      "z": 10,
      "name": "Plant_Coral_Block_Green"
    },
    {
      "x": 5,
      "y": 30,
      "z": 10,
      "name": "Rock_Volcanic_Cracked_Poisoned"
    },
    {
      "x": 5,
      "y": 31,
      "z": 10,
      "name": "Plant_Coral_Block_Green"
    },
    {
      "x": 5,
      "y": 32,
      "z": 10,
      "name": "Plant_Coral_Block_Green"
    },
    {
      "x": 5,
      "y": 33,
      "z": 10,
      "name": "Plant_Coral_Block_Green"
    },
    {
      "x": 5,
      "y": 31,
      "z": 11,
      "name": "Plant_Coral_Block_Green"
    },
    {
      "x": 5,
      "y": 32,
      "z": 11,
      "name": "Plant_Coral_Block_Green"
    },
    {
      "x": 5,
      "y": 8,
      "z": 12,
      "name": "Rock_Volcanic_Cracked_Poisoned"
    },
    {
      "x": 5,
      "y": 9,
      "z": 12,
      "name": "Rock_Volcanic_Cracked_Poisoned"
    },
    {
      "x": 5,
      "y": 10,
      "z": 12,
      "name": "Rock_Volcanic_Cracked_Poisoned"
    },
    {
      "x": 5,
      "y": 7,
      "z": 13,
      "name": "Rock_Volcanic_Cracked_Poisoned"
    },
    {
      "x": 5,
      "y": 8,
      "z": 13,
      "name": "Rock_Volcanic_Cracked_Poisoned"
    },
    {
      "x": 5,
      "y": 9,
      "z": 13,
      "name": "Rock_Volcanic_Cracked_Poisoned"
    },
    {
      "x": 5,
      "y": 7,
      "z": 14,
      "name": "Rock_Volcanic_Cracked_Poisoned"
    },
    {
      "x": 5,
      "y": 8,
      "z": 14,
      "name": "Rock_Volcanic_Cracked_Poisoned"
    },
    {
      "x": 5,
      "y": 9,
      "z": 14,
      "name": "Rock_Volcanic_Cracked_Poisoned"
    },
    {
      "x": 5,
      "y": 6,
      "z": 15,
      "name": "Rock_Volcanic_Cracked_Poisoned"
    },
    {
      "x": 5,
      "y": 7,
      "z": 15,
      "name": "Rock_Volcanic_Cracked_Poisoned"
    },
    {
      "x": 6,
      "y": 6,
      "z": 5,
      "name": "Rock_Volcanic_Cracked_Poisoned"
    },
    {
      "x": 6,
      "y": 7,
      "z": 5,
      "name": "Rock_Volcanic_Cracked_Poisoned"
    },
    {
      "x": 6,
      "y": 21,
      "z": 5,
      "name": "Rock_Volcanic_Cracked_Poisoned"
    },
    {
      "x": 6,
      "y": 22,
      "z": 5,
      "name": "Plant_Coral_Block_Green"
    },
    {
      "x": 6,
      "y": 23,
      "z": 5,
      "name": "Plant_Coral_Block_Green"
    },
    {
      "x": 6,
      "y": 24,
      "z": 5,
      "name": "Plant_Coral_Block_Green"
    },
    {
      "x": 6,
      "y": 25,
      "z": 5,
      "name": "Rock_Volcanic_Cracked_Poisoned"
    },
    {
      "x": 6,
      "y": 26,
      "z": 5,
      "name": "Rock_Volcanic_Cracked_Poisoned"
    },
    {
      "x": 6,
      "y": 27,
      "z": 5,
      "name": "Rock_Volcanic_Cracked_Poisoned"
    },
    {
      "x": 6,
      "y": 28,
      "z": 5,
      "name": "Rock_Volcanic_Cracked_Poisoned"
    },
    {
      "x": 6,
      "y": 6,
      "z": 6,
      "name": "Rock_Volcanic_Cracked_Poisoned"
    },
    {
      "x": 6,
      "y": 7,
      "z": 6,
      "name": "Rock_Volcanic_Cracked_Poisoned"
    },
    {
      "x": 6,
      "y": 8,
      "z": 6,
      "name": "Rock_Volcanic_Cracked_Poisoned"
    },
    {
      "x": 6,
      "y": 9,
      "z": 6,
      "name": "Rock_Volcanic_Cracked_Poisoned"
    },
    {
      "x": 6,
      "y": 20,
      "z": 6,
      "name": "Rock_Volcanic_Cracked_Poisoned"
    },
    {
      "x": 6,
      "y": 21,
      "z": 6,
      "name": "Rock_Volcanic_Cracked_Poisoned"
    },
    {
      "x": 6,
      "y": 22,
      "z": 6,
      "name": "Plant_Coral_Block_Green"
    },
    {
      "x": 6,
      "y": 23,
      "z": 6,
      "name": "Plant_Coral_Block_Green"
    },
    {
      "x": 6,
      "y": 24,
      "z": 6,
      "name": "Plant_Coral_Block_Green"
    },
    {
      "x": 6,
      "y": 25,
      "z": 6,
      "name": "Rock_Volcanic_Cracked_Poisoned"
    },
    {
      "x": 6,
      "y": 26,
      "z": 6,
      "name": "Rock_Volcanic_Cracked_Poisoned"
    },
    {
      "x": 6,
      "y": 27,
      "z": 6,
      "name": "Rock_Volcanic_Cracked_Poisoned"
    },
    {
      "x": 6,
      "y": 28,
      "z": 6,
      "name": "Rock_Volcanic_Cracked_Poisoned"
    },
    {
      "x": 6,
      "y": 29,
      "z": 6,
      "name": "Rock_Volcanic_Cracked_Poisoned"
    },
    {
      "x": 6,
      "y": 6,
      "z": 7,
      "name": "Rock_Volcanic_Cracked_Poisoned"
    },
    {
      "x": 6,
      "y": 7,
      "z": 7,
      "name": "Rock_Volcanic_Cracked_Poisoned"
    },
    {
      "x": 6,
      "y": 8,
      "z": 7,
      "name": "Rock_Volcanic_Cracked_Poisoned"
    },
    {
      "x": 6,
      "y": 9,
      "z": 7,
      "name": "Rock_Volcanic_Cracked_Poisoned"
    },
    {
      "x": 6,
      "y": 10,
      "z": 7,
      "name": "Rock_Volcanic_Cracked_Poisoned"
    },
    {
      "x": 6,
      "y": 11,
      "z": 7,
      "name": "Rock_Volcanic_Cracked_Poisoned"
    },
    {
      "x": 6,
      "y": 19,
      "z": 7,
      "name": "Rock_Volcanic_Cracked_Poisoned"
    },
    {
      "x": 6,
      "y": 20,
      "z": 7,
      "name": "Rock_Volcanic_Cracked_Poisoned"
    },
    {
      "x": 6,
      "y": 21,
      "z": 7,
      "name": "Rock_Volcanic_Cracked_Poisoned"
    },
    {
      "x": 6,
      "y": 22,
      "z": 7,
      "name": "Plant_Coral_Block_Green"
    },
    {
      "x": 6,
      "y": 23,
      "z": 7,
      "name": "Plant_Coral_Block_Green"
    },
    {
      "x": 6,
      "y": 24,
      "z": 7,
      "name": "Plant_Coral_Block_Green"
    },
    {
      "x": 6,
      "y": 25,
      "z": 7,
      "name": "Rock_Volcanic_Cracked_Poisoned"
    },
    {
      "x": 6,
      "y": 26,
      "z": 7,
      "name": "Rock_Volcanic_Cracked_Poisoned"
    },
    {
      "x": 6,
      "y": 27,
      "z": 7,
      "name": "Rock_Volcanic_Cracked_Poisoned"
    },
    {
      "x": 6,
      "y": 28,
      "z": 7,
      "name": "Rock_Volcanic_Cracked_Poisoned"
    },
    {
      "x": 6,
      "y": 29,
      "z": 7,
      "name": "Rock_Volcanic_Cracked_Poisoned"
    },
    {
      "x": 6,
      "y": 30,
      "z": 7,
      "name": "Rock_Volcanic_Cracked_Poisoned"
    },
    {
      "x": 6,
      "y": 31,
      "z": 7,
      "name": "Rock_Volcanic_Cracked_Poisoned"
    },
    {
      "x": 6,
      "y": 7,
      "z": 8,
      "name": "Rock_Volcanic_Cracked_Poisoned"
    },
    {
      "x": 6,
      "y": 8,
      "z": 8,
      "name": "Rock_Volcanic_Cracked_Poisoned"
    },
    {
      "x": 6,
      "y": 9,
      "z": 8,
      "name": "Rock_Volcanic_Cracked_Poisoned"
    },
    {
      "x": 6,
      "y": 10,
      "z": 8,
      "name": "Rock_Volcanic_Cracked_Poisoned"
    },
    {
      "x": 6,
      "y": 11,
      "z": 8,
      "name": "Rock_Volcanic_Cracked_Poisoned"
    },
    {
      "x": 6,
      "y": 12,
      "z": 8,
      "name": "Rock_Volcanic_Cracked_Poisoned"
    },
    {
      "x": 6,
      "y": 15,
      "z": 8,
      "name": "Rock_Volcanic_Cracked_Poisoned"
    },
    {
      "x": 6,
      "y": 18,
      "z": 8,
      "name": "Rock_Volcanic_Cracked_Poisoned"
    },
    {
      "x": 6,
      "y": 19,
      "z": 8,
      "name": "Rock_Volcanic_Cracked_Poisoned"
    },
    {
      "x": 6,
      "y": 20,
      "z": 8,
      "name": "Rock_Volcanic_Cracked_Poisoned"
    },
    {
      "x": 6,
      "y": 21,
      "z": 8,
      "name": "Rock_Volcanic_Cracked_Poisoned"
    },
    {
      "x": 6,
      "y": 22,
      "z": 8,
      "name": "Rock_Volcanic_Cracked_Poisoned"
    },
    {
      "x": 6,
      "y": 23,
      "z": 8,
      "name": "Rock_Volcanic_Cracked_Poisoned"
    },
    {
      "x": 6,
      "y": 24,
      "z": 8,
      "name": "Rock_Volcanic_Cracked_Poisoned"
    },
    {
      "x": 6,
      "y": 25,
      "z": 8,
      "name": "Rock_Volcanic_Cracked_Poisoned"
    },
    {
      "x": 6,
      "y": 26,
      "z": 8,
      "name": "Rock_Volcanic_Cracked_Poisoned"
    },
    {
      "x": 6,
      "y": 27,
      "z": 8,
      "name": "Rock_Volcanic_Cracked_Poisoned"
    },
    {
      "x": 6,
      "y": 28,
      "z": 8,
      "name": "Rock_Volcanic_Cracked_Poisoned"
    },
    {
      "x": 6,
      "y": 29,
      "z": 8,
      "name": "Rock_Volcanic_Cracked_Poisoned"
    },
    {
      "x": 6,
      "y": 30,
      "z": 8,
      "name": "Rock_Volcanic_Cracked_Poisoned"
    },
    {
      "x": 6,
      "y": 31,
      "z": 8,
      "name": "Rock_Volcanic_Cracked_Poisoned"
    },
    {
      "x": 6,
      "y": 32,
      "z": 8,
      "name": "Rock_Volcanic_Cracked_Poisoned"
    },
    {
      "x": 6,
      "y": 33,
      "z": 8,
      "name": "Rock_Volcanic_Cracked_Poisoned"
    },
    {
      "x": 6,
      "y": 43,
      "z": 8,
      "name": "Rock_Volcanic_Cracked_Poisoned"
    },
    {
      "x": 6,
      "y": 44,
      "z": 8,
      "name": "Rock_Volcanic_Cracked_Poisoned"
    },
    {
      "x": 6,
      "y": 45,
      "z": 8,
      "name": "Rock_Volcanic_Cracked_Poisoned"
    },
    {
      "x": 6,
      "y": 46,
      "z": 8,
      "name": "Rock_Volcanic_Cracked_Poisoned"
    },
    {
      "x": 6,
      "y": 47,
      "z": 8,
      "name": "Rock_Volcanic_Cracked_Poisoned"
    },
    {
      "x": 6,
      "y": 48,
      "z": 8,
      "name": "Rock_Volcanic_Cracked_Poisoned"
    },
    {
      "x": 6,
      "y": 49,
      "z": 8,
      "name": "Rock_Volcanic_Cracked_Poisoned"
    },
    {
      "x": 6,
      "y": 50,
      "z": 8,
      "name": "Rock_Volcanic_Cracked_Poisoned"
    },
    {
      "x": 6,
      "y": 9,
      "z": 9,
      "name": "Rock_Volcanic_Cracked_Poisoned"
    },
    {
      "x": 6,
      "y": 10,
      "z": 9,
      "name": "Rock_Volcanic_Cracked_Poisoned"
    },
    {
      "x": 6,
      "y": 11,
      "z": 9,
      "name": "Rock_Volcanic_Cracked_Poisoned"
    },
    {
      "x": 6,
      "y": 12,
      "z": 9,
      "name": "Rock_Volcanic_Cracked_Poisoned"
    },
    {
      "x": 6,
      "y": 15,
      "z": 9,
      "name": "Rock_Volcanic_Cracked_Poisoned"
    },
    {
      "x": 6,
      "y": 16,
      "z": 9,
      "name": "Rock_Volcanic_Cracked_Poisoned"
    },
    {
      "x": 6,
      "y": 17,
      "z": 9,
      "name": "Rock_Volcanic_Cracked_Poisoned"
    },
    {
      "x": 6,
      "y": 18,
      "z": 9,
      "name": "Rock_Volcanic_Cracked_Poisoned"
    },
    {
      "x": 6,
      "y": 19,
      "z": 9,
      "name": "Rock_Volcanic_Cracked_Poisoned"
    },
    {
      "x": 6,
      "y": 20,
      "z": 9,
      "name": "Rock_Volcanic_Cracked_Poisoned"
    },
    {
      "x": 6,
      "y": 21,
      "z": 9,
      "name": "Rock_Volcanic_Cracked_Poisoned"
    },
    {
      "x": 6,
      "y": 22,
      "z": 9,
      "name": "Rock_Volcanic_Cracked_Poisoned"
    },
    {
      "x": 6,
      "y": 23,
      "z": 9,
      "name": "Rock_Volcanic_Cracked_Poisoned"
    },
    {
      "x": 6,
      "y": 24,
      "z": 9,
      "name": "Plant_Coral_Block_Green"
    },
    {
      "x": 6,
      "y": 25,
      "z": 9,
      "name": "Plant_Coral_Block_Green"
    },
    {
      "x": 6,
      "y": 26,
      "z": 9,
      "name": "Rock_Volcanic_Cracked_Poisoned"
    },
    {
      "x": 6,
      "y": 27,
      "z": 9,
      "name": "Rock_Volcanic_Cracked_Poisoned"
    },
    {
      "x": 6,
      "y": 28,
      "z": 9,
      "name": "Rock_Volcanic_Cracked_Poisoned"
    },
    {
      "x": 6,
      "y": 29,
      "z": 9,
      "name": "Rock_Volcanic_Cracked_Poisoned"
    },
    {
      "x": 6,
      "y": 30,
      "z": 9,
      "name": "Rock_Volcanic_Cracked_Poisoned"
    },
    {
      "x": 6,
      "y": 31,
      "z": 9,
      "name": "Plant_Coral_Block_Green"
    },
    {
      "x": 6,
      "y": 32,
      "z": 9,
      "name": "Plant_Coral_Block_Green"
    },
    {
      "x": 6,
      "y": 33,
      "z": 9,
      "name": "Plant_Coral_Block_Green"
    },
    {
      "x": 6,
      "y": 34,
      "z": 9,
      "name": "Rock_Volcanic_Cracked_Poisoned"
    },
    {
      "x": 6,
      "y": 40,
      "z": 9,
      "name": "Rock_Volcanic_Cracked_Poisoned"
    },
    {
      "x": 6,
      "y": 42,
      "z": 9,
      "name": "Rock_Volcanic_Cracked_Poisoned"
    },
    {
      "x": 6,
      "y": 43,
      "z": 9,
      "name": "Rock_Volcanic_Cracked_Poisoned"
    },
    {
      "x": 6,
      "y": 44,
      "z": 9,
      "name": "Rock_Volcanic_Cracked_Poisoned"
    },
    {
      "x": 6,
      "y": 45,
      "z": 9,
      "name": "Rock_Volcanic_Cracked_Poisoned"
    },
    {
      "x": 6,
      "y": 46,
      "z": 9,
      "name": "Rock_Volcanic_Cracked_Poisoned"
    },
    {
      "x": 6,
      "y": 17,
      "z": 10,
      "name": "Rock_Volcanic_Cracked_Poisoned"
    },
    {
      "x": 6,
      "y": 18,
      "z": 10,
      "name": "Rock_Volcanic_Cracked_Poisoned"
    },
    {
      "x": 6,
      "y": 19,
      "z": 10,
      "name": "Rock_Volcanic_Cracked_Poisoned"
    },
    {
      "x": 6,
      "y": 24,
      "z": 10,
      "name": "Plant_Coral_Block_Green"
    },
    {
      "x": 6,
      "y": 25,
      "z": 10,
      "name": "Plant_Coral_Block_Green"
    },
    {
      "x": 6,
      "y": 27,
      "z": 10,
      "name": "Rock_Volcanic_Cracked_Poisoned"
    },
    {
      "x": 6,
      "y": 28,
      "z": 10,
      "name": "Rock_Volcanic_Cracked_Poisoned"
    },
    {
      "x": 6,
      "y": 29,
      "z": 10,
      "name": "Rock_Volcanic_Cracked_Poisoned"
    },
    {
      "x": 6,
      "y": 30,
      "z": 10,
      "name": "Rock_Volcanic_Cracked_Poisoned"
    },
    {
      "x": 6,
      "y": 31,
      "z": 10,
      "name": "Plant_Coral_Block_Green"
    },
    {
      "x": 6,
      "y": 32,
      "z": 10,
      "name": "Plant_Coral_Block_Green"
    },
    {
      "x": 6,
      "y": 33,
      "z": 10,
      "name": "Plant_Coral_Block_Green"
    },
    {
      "x": 6,
      "y": 39,
      "z": 10,
      "name": "Rock_Volcanic_Cracked_Poisoned"
    },
    {
      "x": 6,
      "y": 40,
      "z": 10,
      "name": "Rock_Volcanic_Cracked_Poisoned"
    },
    {
      "x": 6,
      "y": 41,
      "z": 10,
      "name": "Rock_Volcanic_Cracked_Poisoned"
    },
    {
      "x": 6,
      "y": 42,
      "z": 10,
      "name": "Rock_Volcanic_Cracked_Poisoned"
    },
    {
      "x": 6,
      "y": 43,
      "z": 10,
      "name": "Rock_Volcanic_Cracked_Poisoned"
    },
    {
      "x": 6,
      "y": 9,
      "z": 11,
      "name": "Rock_Volcanic_Cracked_Poisoned"
    },
    {
      "x": 6,
      "y": 10,
      "z": 11,
      "name": "Rock_Volcanic_Cracked_Poisoned"
    },
    {
      "x": 6,
      "y": 11,
      "z": 11,
      "name": "Rock_Volcanic_Cracked_Poisoned"
    },
    {
      "x": 6,
      "y": 13,
      "z": 11,
      "name": "Rock_Volcanic_Cracked_Poisoned"
    },
    {
      "x": 6,
      "y": 14,
      "z": 11,
      "name": "Rock_Volcanic_Cracked_Poisoned"
    },
    {
      "x": 6,
      "y": 16,
      "z": 11,
      "name": "Rock_Volcanic_Cracked_Poisoned"
    },
    {
      "x": 6,
      "y": 17,
      "z": 11,
      "name": "Rock_Volcanic_Cracked_Poisoned"
    },
    {
      "x": 6,
      "y": 18,
      "z": 11,
      "name": "Rock_Volcanic_Cracked_Poisoned"
    },
    {
      "x": 6,
      "y": 30,
      "z": 11,
      "name": "Rock_Volcanic_Cracked_Poisoned"
    },
    {
      "x": 6,
      "y": 31,
      "z": 11,
      "name": "Plant_Coral_Block_Green"
    },
    {
      "x": 6,
      "y": 32,
      "z": 11,
      "name": "Plant_Coral_Block_Green"
    },
    {
      "x": 6,
      "y": 33,
      "z": 11,
      "name": "Plant_Coral_Block_Green"
    },
    {
      "x": 6,
      "y": 8,
      "z": 12,
      "name": "Rock_Volcanic_Cracked_Poisoned"
    },
    {
      "x": 6,
      "y": 9,
      "z": 12,
      "name": "Rock_Volcanic_Cracked_Poisoned"
    },
    {
      "x": 6,
      "y": 10,
      "z": 12,
      "name": "Rock_Volcanic_Cracked_Poisoned"
    },
    {
      "x": 6,
      "y": 11,
      "z": 12,
      "name": "Rock_Volcanic_Cracked_Poisoned"
    },
    {
      "x": 6,
      "y": 12,
      "z": 12,
      "name": "Rock_Volcanic_Cracked_Poisoned"
    },
    {
      "x": 6,
      "y": 13,
      "z": 12,
      "name": "Rock_Volcanic_Cracked_Poisoned"
    },
    {
      "x": 6,
      "y": 17,
      "z": 12,
      "name": "Rock_Volcanic_Cracked_Poisoned"
    },
    {
      "x": 6,
      "y": 8,
      "z": 13,
      "name": "Rock_Volcanic_Cracked_Poisoned"
    },
    {
      "x": 6,
      "y": 9,
      "z": 13,
      "name": "Rock_Volcanic_Cracked_Poisoned"
    },
    {
      "x": 6,
      "y": 10,
      "z": 13,
      "name": "Rock_Volcanic_Cracked_Poisoned"
    },
    {
      "x": 6,
      "y": 11,
      "z": 13,
      "name": "Rock_Volcanic_Cracked_Poisoned"
    },
    {
      "x": 6,
      "y": 12,
      "z": 13,
      "name": "Rock_Volcanic_Cracked_Poisoned"
    },
    {
      "x": 6,
      "y": 17,
      "z": 13,
      "name": "Rock_Volcanic_Cracked_Poisoned"
    },
    {
      "x": 6,
      "y": 7,
      "z": 14,
      "name": "Rock_Volcanic_Cracked_Poisoned"
    },
    {
      "x": 6,
      "y": 8,
      "z": 14,
      "name": "Rock_Volcanic_Cracked_Poisoned"
    },
    {
      "x": 6,
      "y": 9,
      "z": 14,
      "name": "Rock_Volcanic_Cracked_Poisoned"
    },
    {
      "x": 6,
      "y": 10,
      "z": 14,
      "name": "Rock_Volcanic_Cracked_Poisoned"
    },
    {
      "x": 7,
      "y": 21,
      "z": 5,
      "name": "Rock_Volcanic_Cracked_Poisoned"
    },
    {
      "x": 7,
      "y": 22,
      "z": 5,
      "name": "Plant_Coral_Block_Green"
    },
    {
      "x": 7,
      "y": 23,
      "z": 5,
      "name": "Plant_Coral_Block_Green"
    },
    {
      "x": 7,
      "y": 24,
      "z": 5,
      "name": "Plant_Coral_Block_Green"
    },
    {
      "x": 7,
      "y": 25,
      "z": 5,
      "name": "Rock_Volcanic_Cracked_Poisoned"
    },
    {
      "x": 7,
      "y": 8,
      "z": 6,
      "name": "Rock_Volcanic_Cracked_Poisoned"
    },
    {
      "x": 7,
      "y": 9,
      "z": 6,
      "name": "Rock_Volcanic_Cracked_Poisoned"
    },
    {
      "x": 7,
      "y": 10,
      "z": 6,
      "name": "Rock_Volcanic_Cracked_Poisoned"
    },
    {
      "x": 7,
      "y": 17,
      "z": 6,
      "name": "Plant_Coral_Block_Green"
    },
    {
      "x": 7,
      "y": 18,
      "z": 6,
      "name": "Plant_Coral_Block_Green"
    },
    {
      "x": 7,
      "y": 19,
      "z": 6,
      "name": "Rock_Volcanic_Cracked_Poisoned"
    },
    {
      "x": 7,
      "y": 20,
      "z": 6,
      "name": "Rock_Volcanic_Cracked_Poisoned"
    },
    {
      "x": 7,
      "y": 21,
      "z": 6,
      "name": "Rock_Volcanic_Cracked_Poisoned"
    },
    {
      "x": 7,
      "y": 22,
      "z": 6,
      "name": "Plant_Coral_Block_Green"
    },
    {
      "x": 7,
      "y": 23,
      "z": 6,
      "name": "Plant_Coral_Block_Green"
    },
    {
      "x": 7,
      "y": 24,
      "z": 6,
      "name": "Plant_Coral_Block_Green"
    },
    {
      "x": 7,
      "y": 25,
      "z": 6,
      "name": "Rock_Volcanic_Cracked_Poisoned"
    },
    {
      "x": 7,
      "y": 26,
      "z": 6,
      "name": "Rock_Volcanic_Cracked_Poisoned"
    },
    {
      "x": 7,
      "y": 27,
      "z": 6,
      "name": "Rock_Volcanic_Cracked_Poisoned"
    },
    {
      "x": 7,
      "y": 28,
      "z": 6,
      "name": "Rock_Volcanic_Cracked_Poisoned"
    },
    {
      "x": 7,
      "y": 29,
      "z": 6,
      "name": "Rock_Volcanic_Cracked_Poisoned"
    },
    {
      "x": 7,
      "y": 30,
      "z": 6,
      "name": "Plant_Coral_Block_Green"
    },
    {
      "x": 7,
      "y": 31,
      "z": 6,
      "name": "Plant_Coral_Block_Green"
    },
    {
      "x": 7,
      "y": 7,
      "z": 7,
      "name": "Rock_Volcanic_Cracked_Poisoned"
    },
    {
      "x": 7,
      "y": 8,
      "z": 7,
      "name": "Rock_Volcanic_Cracked_Poisoned"
    },
    {
      "x": 7,
      "y": 9,
      "z": 7,
      "name": "Rock_Volcanic_Cracked_Poisoned"
    },
    {
      "x": 7,
      "y": 10,
      "z": 7,
      "name": "Rock_Volcanic_Cracked_Poisoned"
    },
    {
      "x": 7,
      "y": 11,
      "z": 7,
      "name": "Rock_Volcanic_Cracked_Poisoned"
    },
    {
      "x": 7,
      "y": 16,
      "z": 7,
      "name": "Plant_Coral_Block_Green"
    },
    {
      "x": 7,
      "y": 17,
      "z": 7,
      "name": "Plant_Coral_Block_Green"
    },
    {
      "x": 7,
      "y": 18,
      "z": 7,
      "name": "Plant_Coral_Block_Green"
    },
    {
      "x": 7,
      "y": 19,
      "z": 7,
      "name": "Rock_Volcanic_Cracked_Poisoned"
    },
    {
      "x": 7,
      "y": 20,
      "z": 7,
      "name": "Rock_Volcanic_Cracked_Poisoned"
    },
    {
      "x": 7,
      "y": 21,
      "z": 7,
      "name": "Rock_Volcanic_Cracked_Poisoned"
    },
    {
      "x": 7,
      "y": 22,
      "z": 7,
      "name": "Plant_Coral_Block_Green"
    },
    {
      "x": 7,
      "y": 23,
      "z": 7,
      "name": "Plant_Coral_Block_Green"
    },
    {
      "x": 7,
      "y": 24,
      "z": 7,
      "name": "Plant_Coral_Block_Green"
    },
    {
      "x": 7,
      "y": 25,
      "z": 7,
      "name": "Rock_Volcanic_Cracked_Poisoned"
    },
    {
      "x": 7,
      "y": 26,
      "z": 7,
      "name": "Rock_Volcanic_Cracked_Poisoned"
    },
    {
      "x": 7,
      "y": 27,
      "z": 7,
      "name": "Rock_Volcanic_Cracked_Poisoned"
    },
    {
      "x": 7,
      "y": 28,
      "z": 7,
      "name": "Rock_Volcanic_Cracked_Poisoned"
    },
    {
      "x": 7,
      "y": 29,
      "z": 7,
      "name": "Rock_Volcanic_Cracked_Poisoned"
    },
    {
      "x": 7,
      "y": 30,
      "z": 7,
      "name": "Plant_Coral_Block_Green"
    },
    {
      "x": 7,
      "y": 31,
      "z": 7,
      "name": "Plant_Coral_Block_Green"
    },
    {
      "x": 7,
      "y": 32,
      "z": 7,
      "name": "Rock_Volcanic_Cracked_Poisoned"
    },
    {
      "x": 7,
      "y": 8,
      "z": 8,
      "name": "Rock_Volcanic_Cracked_Poisoned"
    },
    {
      "x": 7,
      "y": 9,
      "z": 8,
      "name": "Rock_Volcanic_Cracked_Poisoned"
    },
    {
      "x": 7,
      "y": 10,
      "z": 8,
      "name": "Rock_Volcanic_Cracked_Poisoned"
    },
    {
      "x": 7,
      "y": 11,
      "z": 8,
      "name": "Rock_Volcanic_Cracked_Poisoned"
    },
    {
      "x": 7,
      "y": 12,
      "z": 8,
      "name": "Rock_Volcanic_Cracked_Poisoned"
    },
    {
      "x": 7,
      "y": 13,
      "z": 8,
      "name": "Rock_Volcanic_Cracked_Poisoned"
    },
    {
      "x": 7,
      "y": 14,
      "z": 8,
      "name": "Rock_Volcanic_Cracked_Poisoned"
    },
    {
      "x": 7,
      "y": 15,
      "z": 8,
      "name": "Rock_Volcanic_Cracked_Poisoned"
    },
    {
      "x": 7,
      "y": 16,
      "z": 8,
      "name": "Plant_Coral_Block_Green"
    },
    {
      "x": 7,
      "y": 17,
      "z": 8,
      "name": "Plant_Coral_Block_Green"
    },
    {
      "x": 7,
      "y": 18,
      "z": 8,
      "name": "Plant_Coral_Block_Green"
    },
    {
      "x": 7,
      "y": 19,
      "z": 8,
      "name": "Rock_Volcanic_Cracked_Poisoned"
    },
    {
      "x": 7,
      "y": 20,
      "z": 8,
      "name": "Rock_Volcanic_Cracked_Poisoned"
    },
    {
      "x": 7,
      "y": 21,
      "z": 8,
      "name": "Rock_Volcanic_Cracked_Poisoned"
    },
    {
      "x": 7,
      "y": 22,
      "z": 8,
      "name": "Rock_Volcanic_Cracked_Poisoned"
    },
    {
      "x": 7,
      "y": 23,
      "z": 8,
      "name": "Plant_Coral_Block_Green"
    },
    {
      "x": 7,
      "y": 24,
      "z": 8,
      "name": "Rock_Volcanic_Cracked_Poisoned"
    },
    {
      "x": 7,
      "y": 25,
      "z": 8,
      "name": "Rock_Volcanic_Cracked_Poisoned"
    },
    {
      "x": 7,
      "y": 26,
      "z": 8,
      "name": "Rock_Volcanic_Cracked_Poisoned"
    },
    {
      "x": 7,
      "y": 27,
      "z": 8,
      "name": "Rock_Volcanic_Cracked_Poisoned"
    },
    {
      "x": 7,
      "y": 28,
      "z": 8,
      "name": "Rock_Volcanic_Cracked_Poisoned"
    },
    {
      "x": 7,
      "y": 29,
      "z": 8,
      "name": "Rock_Volcanic_Cracked_Poisoned"
    },
    {
      "x": 7,
      "y": 30,
      "z": 8,
      "name": "Rock_Volcanic_Cracked_Poisoned"
    },
    {
      "x": 7,
      "y": 31,
      "z": 8,
      "name": "Rock_Volcanic_Cracked_Poisoned"
    },
    {
      "x": 7,
      "y": 32,
      "z": 8,
      "name": "Rock_Volcanic_Cracked_Poisoned"
    },
    {
      "x": 7,
      "y": 33,
      "z": 8,
      "name": "Rock_Volcanic_Cracked_Poisoned"
    },
    {
      "x": 7,
      "y": 34,
      "z": 8,
      "name": "Rock_Volcanic_Cracked_Poisoned"
    },
    {
      "x": 7,
      "y": 35,
      "z": 8,
      "name": "Rock_Volcanic_Cracked_Poisoned"
    },
    {
      "x": 7,
      "y": 40,
      "z": 8,
      "name": "Rock_Volcanic_Cracked_Poisoned"
    },
    {
      "x": 7,
      "y": 41,
      "z": 8,
      "name": "Rock_Volcanic_Cracked_Poisoned"
    },
    {
      "x": 7,
      "y": 42,
      "z": 8,
      "name": "Rock_Volcanic_Cracked_Poisoned"
    },
    {
      "x": 7,
      "y": 43,
      "z": 8,
      "name": "Rock_Volcanic_Cracked_Poisoned"
    },
    {
      "x": 7,
      "y": 44,
      "z": 8,
      "name": "Rock_Volcanic_Cracked_Poisoned"
    },
    {
      "x": 7,
      "y": 45,
      "z": 8,
      "name": "Rock_Volcanic_Cracked_Poisoned"
    },
    {
      "x": 7,
      "y": 46,
      "z": 8,
      "name": "Rock_Volcanic_Cracked_Poisoned"
    },
    {
      "x": 7,
      "y": 47,
      "z": 8,
      "name": "Rock_Volcanic_Cracked_Poisoned"
    },
    {
      "x": 7,
      "y": 48,
      "z": 8,
      "name": "Rock_Volcanic_Cracked_Poisoned"
    },
    {
      "x": 7,
      "y": 9,
      "z": 9,
      "name": "Rock_Volcanic_Cracked_Poisoned"
    },
    {
      "x": 7,
      "y": 10,
      "z": 9,
      "name": "Rock_Volcanic_Cracked_Poisoned"
    },
    {
      "x": 7,
      "y": 11,
      "z": 9,
      "name": "Rock_Volcanic_Cracked_Poisoned"
    },
    {
      "x": 7,
      "y": 12,
      "z": 9,
      "name": "Rock_Volcanic_Cracked_Poisoned"
    },
    {
      "x": 7,
      "y": 13,
      "z": 9,
      "name": "Rock_Volcanic_Cracked_Poisoned"
    },
    {
      "x": 7,
      "y": 14,
      "z": 9,
      "name": "Rock_Volcanic_Cracked_Poisoned"
    },
    {
      "x": 7,
      "y": 15,
      "z": 9,
      "name": "Rock_Volcanic_Cracked_Poisoned"
    },
    {
      "x": 7,
      "y": 16,
      "z": 9,
      "name": "Rock_Volcanic_Cracked_Poisoned"
    },
    {
      "x": 7,
      "y": 17,
      "z": 9,
      "name": "Rock_Volcanic_Cracked_Poisoned"
    },
    {
      "x": 7,
      "y": 18,
      "z": 9,
      "name": "Rock_Volcanic_Cracked_Poisoned"
    },
    {
      "x": 7,
      "y": 19,
      "z": 9,
      "name": "Rock_Volcanic_Cracked_Poisoned"
    },
    {
      "x": 7,
      "y": 20,
      "z": 9,
      "name": "Rock_Volcanic_Cracked_Poisoned"
    },
    {
      "x": 7,
      "y": 21,
      "z": 9,
      "name": "Rock_Volcanic_Cracked_Poisoned"
    },
    {
      "x": 7,
      "y": 22,
      "z": 9,
      "name": "Rock_Volcanic_Cracked_Poisoned"
    },
    {
      "x": 7,
      "y": 23,
      "z": 9,
      "name": "Rock_Volcanic_Cracked_Poisoned"
    },
    {
      "x": 7,
      "y": 24,
      "z": 9,
      "name": "Rock_Volcanic_Cracked_Poisoned"
    },
    {
      "x": 7,
      "y": 25,
      "z": 9,
      "name": "Rock_Volcanic_Cracked_Poisoned"
    },
    {
      "x": 7,
      "y": 26,
      "z": 9,
      "name": "Rock_Volcanic_Cracked_Poisoned"
    },
    {
      "x": 7,
      "y": 27,
      "z": 9,
      "name": "Rock_Volcanic_Cracked_Poisoned"
    },
    {
      "x": 7,
      "y": 28,
      "z": 9,
      "name": "Rock_Volcanic_Cracked_Poisoned"
    },
    {
      "x": 7,
      "y": 29,
      "z": 9,
      "name": "Rock_Volcanic_Cracked_Poisoned"
    },
    {
      "x": 7,
      "y": 30,
      "z": 9,
      "name": "Rock_Volcanic_Cracked_Poisoned"
    },
    {
      "x": 7,
      "y": 31,
      "z": 9,
      "name": "Plant_Coral_Block_Green"
    },
    {
      "x": 7,
      "y": 32,
      "z": 9,
      "name": "Plant_Coral_Block_Green"
    },
    {
      "x": 7,
      "y": 33,
      "z": 9,
      "name": "Plant_Coral_Block_Green"
    },
    {
      "x": 7,
      "y": 34,
      "z": 9,
      "name": "Rock_Volcanic_Cracked_Poisoned"
    },
    {
      "x": 7,
      "y": 35,
      "z": 9,
      "name": "Rock_Volcanic_Cracked_Poisoned"
    },
    {
      "x": 7,
      "y": 36,
      "z": 9,
      "name": "Rock_Volcanic_Cracked_Poisoned"
    },
    {
      "x": 7,
      "y": 37,
      "z": 9,
      "name": "Rock_Volcanic_Cracked_Poisoned"
    },
    {
      "x": 7,
      "y": 38,
      "z": 9,
      "name": "Rock_Volcanic_Cracked_Poisoned"
    },
    {
      "x": 7,
      "y": 39,
      "z": 9,
      "name": "Rock_Volcanic_Cracked_Poisoned"
    },
    {
      "x": 7,
      "y": 40,
      "z": 9,
      "name": "Rock_Volcanic_Cracked_Poisoned"
    },
    {
      "x": 7,
      "y": 41,
      "z": 9,
      "name": "Rock_Volcanic_Cracked_Poisoned"
    },
    {
      "x": 7,
      "y": 42,
      "z": 9,
      "name": "Rock_Volcanic_Cracked_Poisoned"
    },
    {
      "x": 7,
      "y": 43,
      "z": 9,
      "name": "Rock_Volcanic_Cracked_Poisoned"
    },
    {
      "x": 7,
      "y": 44,
      "z": 9,
      "name": "Rock_Volcanic_Cracked_Poisoned"
    },
    {
      "x": 7,
      "y": 45,
      "z": 9,
      "name": "Rock_Volcanic_Cracked_Poisoned"
    },
    {
      "x": 7,
      "y": 46,
      "z": 9,
      "name": "Rock_Volcanic_Cracked_Poisoned"
    },
    {
      "x": 7,
      "y": 47,
      "z": 9,
      "name": "Rock_Volcanic_Cracked_Poisoned"
    },
    {
      "x": 7,
      "y": 10,
      "z": 10,
      "name": "Rock_Volcanic_Cracked_Poisoned"
    },
    {
      "x": 7,
      "y": 11,
      "z": 10,
      "name": "Rock_Volcanic_Cracked_Poisoned"
    },
    {
      "x": 7,
      "y": 12,
      "z": 10,
      "name": "Rock_Volcanic_Cracked_Poisoned"
    },
    {
      "x": 7,
      "y": 13,
      "z": 10,
      "name": "Rock_Volcanic_Cracked_Poisoned"
    },
    {
      "x": 7,
      "y": 14,
      "z": 10,
      "name": "Rock_Volcanic_Cracked_Poisoned"
    },
    {
      "x": 7,
      "y": 15,
      "z": 10,
      "name": "Rock_Volcanic_Cracked_Poisoned"
    },
    {
      "x": 7,
      "y": 16,
      "z": 10,
      "name": "Rock_Volcanic_Cracked_Poisoned"
    },
    {
      "x": 7,
      "y": 17,
      "z": 10,
      "name": "Rock_Volcanic_Cracked_Poisoned"
    },
    {
      "x": 7,
      "y": 18,
      "z": 10,
      "name": "Rock_Volcanic_Cracked_Poisoned"
    },
    {
      "x": 7,
      "y": 19,
      "z": 10,
      "name": "Rock_Volcanic_Cracked_Poisoned"
    },
    {
      "x": 7,
      "y": 20,
      "z": 10,
      "name": "Rock_Volcanic_Cracked_Poisoned"
    },
    {
      "x": 7,
      "y": 21,
      "z": 10,
      "name": "Rock_Volcanic_Cracked_Poisoned"
    },
    {
      "x": 7,
      "y": 22,
      "z": 10,
      "name": "Rock_Volcanic_Cracked_Poisoned"
    },
    {
      "x": 7,
      "y": 23,
      "z": 10,
      "name": "Rock_Volcanic_Cracked_Poisoned"
    },
    {
      "x": 7,
      "y": 28,
      "z": 10,
      "name": "Rock_Volcanic_Cracked_Poisoned"
    },
    {
      "x": 7,
      "y": 29,
      "z": 10,
      "name": "Rock_Volcanic_Cracked_Poisoned"
    },
    {
      "x": 7,
      "y": 30,
      "z": 10,
      "name": "Rock_Volcanic_Cracked_Poisoned"
    },
    {
      "x": 7,
      "y": 31,
      "z": 10,
      "name": "Plant_Coral_Block_Green"
    },
    {
      "x": 7,
      "y": 32,
      "z": 10,
      "name": "Plant_Coral_Block_Green"
    },
    {
      "x": 7,
      "y": 33,
      "z": 10,
      "name": "Plant_Coral_Block_Green"
    },
    {
      "x": 7,
      "y": 34,
      "z": 10,
      "name": "Rock_Volcanic_Cracked_Poisoned"
    },
    {
      "x": 7,
      "y": 35,
      "z": 10,
      "name": "Rock_Volcanic_Cracked_Poisoned"
    },
    {
      "x": 7,
      "y": 36,
      "z": 10,
      "name": "Rock_Volcanic_Cracked_Poisoned"
    },
    {
      "x": 7,
      "y": 37,
      "z": 10,
      "name": "Rock_Volcanic_Cracked_Poisoned"
    },
    {
      "x": 7,
      "y": 38,
      "z": 10,
      "name": "Rock_Volcanic_Cracked_Poisoned"
    },
    {
      "x": 7,
      "y": 39,
      "z": 10,
      "name": "Rock_Volcanic_Cracked_Poisoned"
    },
    {
      "x": 7,
      "y": 40,
      "z": 10,
      "name": "Rock_Volcanic_Cracked_Poisoned"
    },
    {
      "x": 7,
      "y": 41,
      "z": 10,
      "name": "Rock_Volcanic_Cracked_Poisoned"
    },
    {
      "x": 7,
      "y": 42,
      "z": 10,
      "name": "Rock_Volcanic_Cracked_Poisoned"
    },
    {
      "x": 7,
      "y": 43,
      "z": 10,
      "name": "Rock_Volcanic_Cracked_Poisoned"
    },
    {
      "x": 7,
      "y": 9,
      "z": 11,
      "name": "Rock_Volcanic_Cracked_Poisoned"
    },
    {
      "x": 7,
      "y": 10,
      "z": 11,
      "name": "Rock_Volcanic_Cracked_Poisoned"
    },
    {
      "x": 7,
      "y": 11,
      "z": 11,
      "name": "Rock_Volcanic_Cracked_Poisoned"
    },
    {
      "x": 7,
      "y": 12,
      "z": 11,
      "name": "Rock_Volcanic_Cracked_Poisoned"
    },
    {
      "x": 7,
      "y": 13,
      "z": 11,
      "name": "Rock_Volcanic_Cracked_Poisoned"
    },
    {
      "x": 7,
      "y": 14,
      "z": 11,
      "name": "Rock_Volcanic_Cracked_Poisoned"
    },
    {
      "x": 7,
      "y": 15,
      "z": 11,
      "name": "Rock_Volcanic_Cracked_Poisoned"
    },
    {
      "x": 7,
      "y": 16,
      "z": 11,
      "name": "Rock_Volcanic_Cracked_Poisoned"
    },
    {
      "x": 7,
      "y": 17,
      "z": 11,
      "name": "Rock_Volcanic_Cracked_Poisoned"
    },
    {
      "x": 7,
      "y": 18,
      "z": 11,
      "name": "Rock_Volcanic_Cracked_Poisoned"
    },
    {
      "x": 7,
      "y": 19,
      "z": 11,
      "name": "Rock_Volcanic_Cracked_Poisoned"
    },
    {
      "x": 7,
      "y": 30,
      "z": 11,
      "name": "Rock_Volcanic_Cracked_Poisoned"
    },
    {
      "x": 7,
      "y": 31,
      "z": 11,
      "name": "Plant_Coral_Block_Green"
    },
    {
      "x": 7,
      "y": 32,
      "z": 11,
      "name": "Plant_Coral_Block_Green"
    },
    {
      "x": 7,
      "y": 33,
      "z": 11,
      "name": "Plant_Coral_Block_Green"
    },
    {
      "x": 7,
      "y": 34,
      "z": 11,
      "name": "Rock_Volcanic_Cracked_Poisoned"
    },
    {
      "x": 7,
      "y": 38,
      "z": 11,
      "name": "Plant_Coral_Block_Green"
    },
    {
      "x": 7,
      "y": 39,
      "z": 11,
      "name": "Plant_Coral_Block_Green"
    },
    {
      "x": 7,
      "y": 40,
      "z": 11,
      "name": "Rock_Volcanic_Cracked_Poisoned"
    },
    {
      "x": 7,
      "y": 9,
      "z": 12,
      "name": "Rock_Volcanic_Cracked_Poisoned"
    },
    {
      "x": 7,
      "y": 10,
      "z": 12,
      "name": "Rock_Volcanic_Cracked_Poisoned"
    },
    {
      "x": 7,
      "y": 11,
      "z": 12,
      "name": "Rock_Volcanic_Cracked_Poisoned"
    },
    {
      "x": 7,
      "y": 12,
      "z": 12,
      "name": "Rock_Volcanic_Cracked_Poisoned"
    },
    {
      "x": 7,
      "y": 13,
      "z": 12,
      "name": "Rock_Volcanic_Cracked_Poisoned"
    },
    {
      "x": 7,
      "y": 14,
      "z": 12,
      "name": "Plant_Coral_Block_Green"
    },
    {
      "x": 7,
      "y": 15,
      "z": 12,
      "name": "Plant_Coral_Block_Green"
    },
    {
      "x": 7,
      "y": 16,
      "z": 12,
      "name": "Plant_Coral_Block_Green"
    },
    {
      "x": 7,
      "y": 17,
      "z": 12,
      "name": "Rock_Volcanic_Cracked_Poisoned"
    },
    {
      "x": 7,
      "y": 18,
      "z": 12,
      "name": "Rock_Volcanic_Cracked_Poisoned"
    },
    {
      "x": 7,
      "y": 38,
      "z": 12,
      "name": "Plant_Coral_Block_Green"
    },
    {
      "x": 7,
      "y": 39,
      "z": 12,
      "name": "Plant_Coral_Block_Green"
    },
    {
      "x": 7,
      "y": 9,
      "z": 13,
      "name": "Rock_Volcanic_Cracked_Poisoned"
    },
    {
      "x": 7,
      "y": 10,
      "z": 13,
      "name": "Rock_Volcanic_Cracked_Poisoned"
    },
    {
      "x": 7,
      "y": 11,
      "z": 13,
      "name": "Rock_Volcanic_Cracked_Poisoned"
    },
    {
      "x": 7,
      "y": 12,
      "z": 13,
      "name": "Rock_Volcanic_Cracked_Poisoned"
    },
    {
      "x": 7,
      "y": 13,
      "z": 13,
      "name": "Plant_Coral_Block_Green"
    },
    {
      "x": 7,
      "y": 14,
      "z": 13,
      "name": "Plant_Coral_Block_Green"
    },
    {
      "x": 7,
      "y": 15,
      "z": 13,
      "name": "Plant_Coral_Block_Green"
    },
    {
      "x": 7,
      "y": 16,
      "z": 13,
      "name": "Plant_Coral_Block_Green"
    },
    {
      "x": 7,
      "y": 17,
      "z": 13,
      "name": "Rock_Volcanic_Cracked_Poisoned"
    },
    {
      "x": 7,
      "y": 18,
      "z": 13,
      "name": "Rock_Volcanic_Cracked_Poisoned"
    },
    {
      "x": 7,
      "y": 8,
      "z": 14,
      "name": "Rock_Volcanic_Cracked_Poisoned"
    },
    {
      "x": 7,
      "y": 9,
      "z": 14,
      "name": "Rock_Volcanic_Cracked_Poisoned"
    },
    {
      "x": 7,
      "y": 10,
      "z": 14,
      "name": "Rock_Volcanic_Cracked_Poisoned"
    },
    {
      "x": 7,
      "y": 11,
      "z": 14,
      "name": "Rock_Volcanic_Cracked_Poisoned"
    },
    {
      "x": 7,
      "y": 13,
      "z": 14,
      "name": "Plant_Coral_Block_Green"
    },
    {
      "x": 7,
      "y": 14,
      "z": 14,
      "name": "Plant_Coral_Block_Green"
    },
    {
      "x": 7,
      "y": 15,
      "z": 14,
      "name": "Plant_Coral_Block_Green"
    },
    {
      "x": 7,
      "y": 16,
      "z": 14,
      "name": "Plant_Coral_Block_Green"
    },
    {
      "x": 7,
      "y": 17,
      "z": 14,
      "name": "Rock_Volcanic_Cracked_Poisoned"
    },
    {
      "x": 7,
      "y": 18,
      "z": 14,
      "name": "Rock_Volcanic_Cracked_Poisoned"
    },
    {
      "x": 7,
      "y": 14,
      "z": 15,
      "name": "Plant_Coral_Block_Green"
    },
    {
      "x": 7,
      "y": 15,
      "z": 15,
      "name": "Plant_Coral_Block_Green"
    },
    {
      "x": 8,
      "y": 22,
      "z": 5,
      "name": "Plant_Coral_Block_Green"
    },
    {
      "x": 8,
      "y": 23,
      "z": 5,
      "name": "Plant_Coral_Block_Green"
    },
    {
      "x": 8,
      "y": 16,
      "z": 6,
      "name": "Plant_Coral_Block_Green"
    },
    {
      "x": 8,
      "y": 17,
      "z": 6,
      "name": "Plant_Coral_Block_Green"
    },
    {
      "x": 8,
      "y": 18,
      "z": 6,
      "name": "Plant_Coral_Block_Green"
    },
    {
      "x": 8,
      "y": 19,
      "z": 6,
      "name": "Rock_Volcanic_Cracked_Poisoned"
    },
    {
      "x": 8,
      "y": 20,
      "z": 6,
      "name": "Rock_Volcanic_Cracked_Poisoned"
    },
    {
      "x": 8,
      "y": 21,
      "z": 6,
      "name": "Rock_Volcanic_Cracked_Poisoned"
    },
    {
      "x": 8,
      "y": 22,
      "z": 6,
      "name": "Plant_Coral_Block_Green"
    },
    {
      "x": 8,
      "y": 23,
      "z": 6,
      "name": "Plant_Coral_Block_Green"
    },
    {
      "x": 8,
      "y": 24,
      "z": 6,
      "name": "Plant_Coral_Block_Green"
    },
    {
      "x": 8,
      "y": 25,
      "z": 6,
      "name": "Rock_Volcanic_Cracked_Poisoned"
    },
    {
      "x": 8,
      "y": 30,
      "z": 6,
      "name": "Plant_Coral_Block_Green"
    },
    {
      "x": 8,
      "y": 31,
      "z": 6,
      "name": "Plant_Coral_Block_Green"
    },
    {
      "x": 8,
      "y": 9,
      "z": 7,
      "name": "Rock_Volcanic_Cracked_Poisoned"
    },
    {
      "x": 8,
      "y": 10,
      "z": 7,
      "name": "Rock_Volcanic_Cracked_Poisoned"
    },
    {
      "x": 8,
      "y": 11,
      "z": 7,
      "name": "Rock_Volcanic_Cracked_Poisoned"
    },
    {
      "x": 8,
      "y": 12,
      "z": 7,
      "name": "Rock_Volcanic_Cracked_Poisoned"
    },
    {
      "x": 8,
      "y": 13,
      "z": 7,
      "name": "Rock_Volcanic_Cracked_Poisoned"
    },
    {
      "x": 8,
      "y": 16,
      "z": 7,
      "name": "Plant_Coral_Block_Green"
    },
    {
      "x": 8,
      "y": 17,
      "z": 7,
      "name": "Plant_Coral_Block_Green"
    },
    {
      "x": 8,
      "y": 18,
      "z": 7,
      "name": "Plant_Coral_Block_Green"
    },
    {
      "x": 8,
      "y": 19,
      "z": 7,
      "name": "Plant_Coral_Block_Green"
    },
    {
      "x": 8,
      "y": 20,
      "z": 7,
      "name": "Rock_Volcanic_Cracked_Poisoned"
    },
    {
      "x": 8,
      "y": 21,
      "z": 7,
      "name": "Rock_Volcanic_Cracked_Poisoned"
    },
    {
      "x": 8,
      "y": 22,
      "z": 7,
      "name": "Plant_Coral_Block_Green"
    },
    {
      "x": 8,
      "y": 23,
      "z": 7,
      "name": "Plant_Coral_Block_Green"
    },
    {
      "x": 8,
      "y": 24,
      "z": 7,
      "name": "Plant_Coral_Block_Green"
    },
    {
      "x": 8,
      "y": 25,
      "z": 7,
      "name": "Rock_Volcanic_Cracked_Poisoned"
    },
    {
      "x": 8,
      "y": 27,
      "z": 7,
      "name": "Rock_Volcanic_Cracked_Poisoned"
    },
    {
      "x": 8,
      "y": 28,
      "z": 7,
      "name": "Rock_Volcanic_Cracked_Poisoned"
    },
    {
      "x": 8,
      "y": 29,
      "z": 7,
      "name": "Rock_Volcanic_Cracked_Poisoned"
    },
    {
      "x": 8,
      "y": 30,
      "z": 7,
      "name": "Plant_Coral_Block_Green"
    },
    {
      "x": 8,
      "y": 31,
      "z": 7,
      "name": "Plant_Coral_Block_Green"
    },
    {
      "x": 8,
      "y": 32,
      "z": 7,
      "name": "Rock_Volcanic_Cracked_Poisoned"
    },
    {
      "x": 8,
      "y": 33,
      "z": 7,
      "name": "Rock_Volcanic_Cracked_Poisoned"
    },
    {
      "x": 8,
      "y": 9,
      "z": 8,
      "name": "Rock_Volcanic_Cracked_Poisoned"
    },
    {
      "x": 8,
      "y": 10,
      "z": 8,
      "name": "Rock_Volcanic_Cracked_Poisoned"
    },
    {
      "x": 8,
      "y": 11,
      "z": 8,
      "name": "Rock_Volcanic_Cracked_Poisoned"
    },
    {
      "x": 8,
      "y": 12,
      "z": 8,
      "name": "Rock_Volcanic_Cracked_Poisoned"
    },
    {
      "x": 8,
      "y": 13,
      "z": 8,
      "name": "Rock_Volcanic_Cracked_Poisoned"
    },
    {
      "x": 8,
      "y": 14,
      "z": 8,
      "name": "Rock_Volcanic_Cracked_Poisoned"
    },
    {
      "x": 8,
      "y": 15,
      "z": 8,
      "name": "Rock_Volcanic_Cracked_Poisoned"
    },
    {
      "x": 8,
      "y": 16,
      "z": 8,
      "name": "Plant_Coral_Block_Green"
    },
    {
      "x": 8,
      "y": 17,
      "z": 8,
      "name": "Plant_Coral_Block_Green"
    },
    {
      "x": 8,
      "y": 18,
      "z": 8,
      "name": "Plant_Coral_Block_Green"
    },
    {
      "x": 8,
      "y": 19,
      "z": 8,
      "name": "Rock_Volcanic_Cracked_Poisoned"
    },
    {
      "x": 8,
      "y": 20,
      "z": 8,
      "name": "Rock_Volcanic_Cracked_Poisoned"
    },
    {
      "x": 8,
      "y": 21,
      "z": 8,
      "name": "Rock_Volcanic_Cracked_Poisoned"
    },
    {
      "x": 8,
      "y": 22,
      "z": 8,
      "name": "Rock_Volcanic_Cracked_Poisoned"
    },
    {
      "x": 8,
      "y": 23,
      "z": 8,
      "name": "Rock_Volcanic_Cracked_Poisoned"
    },
    {
      "x": 8,
      "y": 24,
      "z": 8,
      "name": "Rock_Volcanic_Cracked_Poisoned"
    },
    {
      "x": 8,
      "y": 26,
      "z": 8,
      "name": "Rock_Volcanic_Cracked_Poisoned"
    },
    {
      "x": 8,
      "y": 27,
      "z": 8,
      "name": "Rock_Volcanic_Cracked_Poisoned"
    },
    {
      "x": 8,
      "y": 28,
      "z": 8,
      "name": "Rock_Volcanic_Cracked_Poisoned"
    },
    {
      "x": 8,
      "y": 29,
      "z": 8,
      "name": "Rock_Volcanic_Cracked_Poisoned"
    },
    {
      "x": 8,
      "y": 30,
      "z": 8,
      "name": "Rock_Volcanic_Cracked_Poisoned"
    },
    {
      "x": 8,
      "y": 31,
      "z": 8,
      "name": "Rock_Volcanic_Cracked_Poisoned"
    },
    {
      "x": 8,
      "y": 32,
      "z": 8,
      "name": "Rock_Volcanic_Cracked_Poisoned"
    },
    {
      "x": 8,
      "y": 33,
      "z": 8,
      "name": "Rock_Volcanic_Cracked_Poisoned"
    },
    {
      "x": 8,
      "y": 34,
      "z": 8,
      "name": "Rock_Volcanic_Cracked_Poisoned"
    },
    {
      "x": 8,
      "y": 35,
      "z": 8,
      "name": "Rock_Volcanic_Cracked_Poisoned"
    },
    {
      "x": 8,
      "y": 36,
      "z": 8,
      "name": "Rock_Volcanic_Cracked_Poisoned"
    },
    {
      "x": 8,
      "y": 39,
      "z": 8,
      "name": "Rock_Volcanic_Cracked_Poisoned"
    },
    {
      "x": 8,
      "y": 40,
      "z": 8,
      "name": "Rock_Volcanic_Cracked_Poisoned"
    },
    {
      "x": 8,
      "y": 41,
      "z": 8,
      "name": "Rock_Volcanic_Cracked_Poisoned"
    },
    {
      "x": 8,
      "y": 42,
      "z": 8,
      "name": "Rock_Volcanic_Cracked_Poisoned"
    },
    {
      "x": 8,
      "y": 43,
      "z": 8,
      "name": "Rock_Volcanic_Cracked_Poisoned"
    },
    {
      "x": 8,
      "y": 9,
      "z": 9,
      "name": "Rock_Volcanic_Cracked_Poisoned"
    },
    {
      "x": 8,
      "y": 10,
      "z": 9,
      "name": "Rock_Volcanic_Cracked_Poisoned"
    },
    {
      "x": 8,
      "y": 11,
      "z": 9,
      "name": "Rock_Volcanic_Cracked_Poisoned"
    },
    {
      "x": 8,
      "y": 12,
      "z": 9,
      "name": "Rock_Volcanic_Cracked_Poisoned"
    },
    {
      "x": 8,
      "y": 13,
      "z": 9,
      "name": "Rock_Volcanic_Cracked_Poisoned"
    },
    {
      "x": 8,
      "y": 14,
      "z": 9,
      "name": "Rock_Volcanic_Cracked_Poisoned"
    },
    {
      "x": 8,
      "y": 15,
      "z": 9,
      "name": "Rock_Volcanic_Cracked_Poisoned"
    },
    {
      "x": 8,
      "y": 16,
      "z": 9,
      "name": "Rock_Volcanic_Cracked_Poisoned"
    },
    {
      "x": 8,
      "y": 17,
      "z": 9,
      "name": "Plant_Coral_Block_Green"
    },
    {
      "x": 8,
      "y": 18,
      "z": 9,
      "name": "Rock_Volcanic_Cracked_Poisoned"
    },
    {
      "x": 8,
      "y": 19,
      "z": 9,
      "name": "Rock_Volcanic_Cracked_Poisoned"
    },
    {
      "x": 8,
      "y": 20,
      "z": 9,
      "name": "Rock_Volcanic_Cracked_Poisoned"
    },
    {
      "x": 8,
      "y": 21,
      "z": 9,
      "name": "Rock_Volcanic_Cracked_Poisoned"
    },
    {
      "x": 8,
      "y": 22,
      "z": 9,
      "name": "Rock_Volcanic_Cracked_Poisoned"
    },
    {
      "x": 8,
      "y": 23,
      "z": 9,
      "name": "Rock_Volcanic_Cracked_Poisoned"
    },
    {
      "x": 8,
      "y": 24,
      "z": 9,
      "name": "Rock_Volcanic_Cracked_Poisoned"
    },
    {
      "x": 8,
      "y": 27,
      "z": 9,
      "name": "Rock_Volcanic_Cracked_Poisoned"
    },
    {
      "x": 8,
      "y": 28,
      "z": 9,
      "name": "Rock_Volcanic_Cracked_Poisoned"
    },
    {
      "x": 8,
      "y": 29,
      "z": 9,
      "name": "Rock_Volcanic_Cracked_Poisoned"
    },
    {
      "x": 8,
      "y": 30,
      "z": 9,
      "name": "Rock_Volcanic_Cracked_Poisoned"
    },
    {
      "x": 8,
      "y": 31,
      "z": 9,
      "name": "Rock_Volcanic_Cracked_Poisoned"
    },
    {
      "x": 8,
      "y": 32,
      "z": 9,
      "name": "Rock_Volcanic_Cracked_Poisoned"
    },
    {
      "x": 8,
      "y": 33,
      "z": 9,
      "name": "Rock_Volcanic_Cracked_Poisoned"
    },
    {
      "x": 8,
      "y": 34,
      "z": 9,
      "name": "Rock_Volcanic_Cracked_Poisoned"
    },
    {
      "x": 8,
      "y": 35,
      "z": 9,
      "name": "Rock_Volcanic_Cracked_Poisoned"
    },
    {
      "x": 8,
      "y": 36,
      "z": 9,
      "name": "Rock_Volcanic_Cracked_Poisoned"
    },
    {
      "x": 8,
      "y": 37,
      "z": 9,
      "name": "Rock_Volcanic_Cracked_Poisoned"
    },
    {
      "x": 8,
      "y": 38,
      "z": 9,
      "name": "Rock_Volcanic_Cracked_Poisoned"
    },
    {
      "x": 8,
      "y": 39,
      "z": 9,
      "name": "Rock_Volcanic_Cracked_Poisoned"
    },
    {
      "x": 8,
      "y": 40,
      "z": 9,
      "name": "Rock_Volcanic_Cracked_Poisoned"
    },
    {
      "x": 8,
      "y": 41,
      "z": 9,
      "name": "Rock_Volcanic_Cracked_Poisoned"
    },
    {
      "x": 8,
      "y": 42,
      "z": 9,
      "name": "Rock_Volcanic_Cracked_Poisoned"
    },
    {
      "x": 8,
      "y": 43,
      "z": 9,
      "name": "Rock_Volcanic_Cracked_Poisoned"
    },
    {
      "x": 8,
      "y": 10,
      "z": 10,
      "name": "Rock_Volcanic_Cracked_Poisoned"
    },
    {
      "x": 8,
      "y": 11,
      "z": 10,
      "name": "Rock_Volcanic_Cracked_Poisoned"
    },
    {
      "x": 8,
      "y": 12,
      "z": 10,
      "name": "Rock_Volcanic_Cracked_Poisoned"
    },
    {
      "x": 8,
      "y": 13,
      "z": 10,
      "name": "Rock_Volcanic_Cracked_Poisoned"
    },
    {
      "x": 8,
      "y": 14,
      "z": 10,
      "name": "Rock_Volcanic_Cracked_Poisoned"
    },
    {
      "x": 8,
      "y": 15,
      "z": 10,
      "name": "Rock_Volcanic_Cracked_Poisoned"
    },
    {
      "x": 8,
      "y": 16,
      "z": 10,
      "name": "Rock_Volcanic_Cracked_Poisoned"
    },
    {
      "x": 8,
      "y": 17,
      "z": 10,
      "name": "Rock_Volcanic_Cracked_Poisoned"
    },
    {
      "x": 8,
      "y": 18,
      "z": 10,
      "name": "Rock_Volcanic_Cracked_Poisoned"
    },
    {
      "x": 8,
      "y": 19,
      "z": 10,
      "name": "Plant_Coral_Block_Green"
    },
    {
      "x": 8,
      "y": 20,
      "z": 10,
      "name": "Plant_Coral_Block_Green"
    },
    {
      "x": 8,
      "y": 21,
      "z": 10,
      "name": "Plant_Coral_Block_Green"
    },
    {
      "x": 8,
      "y": 22,
      "z": 10,
      "name": "Rock_Volcanic_Cracked_Poisoned"
    },
    {
      "x": 8,
      "y": 28,
      "z": 10,
      "name": "Rock_Volcanic_Cracked_Poisoned"
    },
    {
      "x": 8,
      "y": 29,
      "z": 10,
      "name": "Rock_Volcanic_Cracked_Poisoned"
    },
    {
      "x": 8,
      "y": 30,
      "z": 10,
      "name": "Rock_Volcanic_Cracked_Poisoned"
    },
    {
      "x": 8,
      "y": 31,
      "z": 10,
      "name": "Rock_Volcanic_Cracked_Poisoned"
    },
    {
      "x": 8,
      "y": 32,
      "z": 10,
      "name": "Plant_Coral_Block_Green"
    },
    {
      "x": 8,
      "y": 33,
      "z": 10,
      "name": "Rock_Volcanic_Cracked_Poisoned"
    },
    {
      "x": 8,
      "y": 34,
      "z": 10,
      "name": "Rock_Volcanic_Cracked_Poisoned"
    },
    {
      "x": 8,
      "y": 35,
      "z": 10,
      "name": "Rock_Volcanic_Cracked_Poisoned"
    },
    {
      "x": 8,
      "y": 36,
      "z": 10,
      "name": "Rock_Volcanic_Cracked_Poisoned"
    },
    {
      "x": 8,
      "y": 37,
      "z": 10,
      "name": "Rock_Volcanic_Cracked_Poisoned"
    },
    {
      "x": 8,
      "y": 38,
      "z": 10,
      "name": "Rock_Volcanic_Cracked_Poisoned"
    },
    {
      "x": 8,
      "y": 39,
      "z": 10,
      "name": "Rock_Volcanic_Cracked_Poisoned"
    },
    {
      "x": 8,
      "y": 40,
      "z": 10,
      "name": "Rock_Volcanic_Cracked_Poisoned"
    },
    {
      "x": 8,
      "y": 41,
      "z": 10,
      "name": "Rock_Volcanic_Cracked_Poisoned"
    },
    {
      "x": 8,
      "y": 42,
      "z": 10,
      "name": "Rock_Volcanic_Cracked_Poisoned"
    },
    {
      "x": 8,
      "y": 9,
      "z": 11,
      "name": "Rock_Volcanic_Cracked_Poisoned"
    },
    {
      "x": 8,
      "y": 10,
      "z": 11,
      "name": "Rock_Volcanic_Cracked_Poisoned"
    },
    {
      "x": 8,
      "y": 11,
      "z": 11,
      "name": "Rock_Volcanic_Cracked_Poisoned"
    },
    {
      "x": 8,
      "y": 12,
      "z": 11,
      "name": "Rock_Volcanic_Cracked_Poisoned"
    },
    {
      "x": 8,
      "y": 13,
      "z": 11,
      "name": "Rock_Volcanic_Cracked_Poisoned"
    },
    {
      "x": 8,
      "y": 14,
      "z": 11,
      "name": "Rock_Volcanic_Cracked_Poisoned"
    },
    {
      "x": 8,
      "y": 15,
      "z": 11,
      "name": "Rock_Volcanic_Cracked_Poisoned"
    },
    {
      "x": 8,
      "y": 16,
      "z": 11,
      "name": "Rock_Volcanic_Cracked_Poisoned"
    },
    {
      "x": 8,
      "y": 17,
      "z": 11,
      "name": "Rock_Volcanic_Cracked_Poisoned"
    },
    {
      "x": 8,
      "y": 18,
      "z": 11,
      "name": "Plant_Coral_Block_Green"
    },
    {
      "x": 8,
      "y": 19,
      "z": 11,
      "name": "Plant_Coral_Block_Green"
    },
    {
      "x": 8,
      "y": 20,
      "z": 11,
      "name": "Plant_Coral_Block_Green"
    },
    {
      "x": 8,
      "y": 21,
      "z": 11,
      "name": "Plant_Coral_Block_Green"
    },
    {
      "x": 8,
      "y": 30,
      "z": 11,
      "name": "Rock_Volcanic_Cracked_Poisoned"
    },
    {
      "x": 8,
      "y": 31,
      "z": 11,
      "name": "Rock_Volcanic_Cracked_Poisoned"
    },
    {
      "x": 8,
      "y": 32,
      "z": 11,
      "name": "Rock_Volcanic_Cracked_Poisoned"
    },
    {
      "x": 8,
      "y": 33,
      "z": 11,
      "name": "Rock_Volcanic_Cracked_Poisoned"
    },
    {
      "x": 8,
      "y": 34,
      "z": 11,
      "name": "Rock_Volcanic_Cracked_Poisoned"
    },
    {
      "x": 8,
      "y": 35,
      "z": 11,
      "name": "Rock_Volcanic_Cracked_Poisoned"
    },
    {
      "x": 8,
      "y": 36,
      "z": 11,
      "name": "Rock_Volcanic_Cracked_Poisoned"
    },
    {
      "x": 8,
      "y": 37,
      "z": 11,
      "name": "Rock_Volcanic_Cracked_Poisoned"
    },
    {
      "x": 8,
      "y": 38,
      "z": 11,
      "name": "Plant_Coral_Block_Green"
    },
    {
      "x": 8,
      "y": 39,
      "z": 11,
      "name": "Plant_Coral_Block_Green"
    },
    {
      "x": 8,
      "y": 40,
      "z": 11,
      "name": "Rock_Volcanic_Cracked_Poisoned"
    },
    {
      "x": 8,
      "y": 9,
      "z": 12,
      "name": "Rock_Volcanic_Cracked_Poisoned"
    },
    {
      "x": 8,
      "y": 10,
      "z": 12,
      "name": "Rock_Volcanic_Cracked_Poisoned"
    },
    {
      "x": 8,
      "y": 11,
      "z": 12,
      "name": "Rock_Volcanic_Cracked_Poisoned"
    },
    {
      "x": 8,
      "y": 12,
      "z": 12,
      "name": "Rock_Volcanic_Cracked_Poisoned"
    },
    {
      "x": 8,
      "y": 13,
      "z": 12,
      "name": "Rock_Volcanic_Cracked_Poisoned"
    },
    {
      "x": 8,
      "y": 14,
      "z": 12,
      "name": "Plant_Coral_Block_Green"
    },
    {
      "x": 8,
      "y": 15,
      "z": 12,
      "name": "Plant_Coral_Block_Green"
    },
    {
      "x": 8,
      "y": 16,
      "z": 12,
      "name": "Plant_Coral_Block_Green"
    },
    {
      "x": 8,
      "y": 17,
      "z": 12,
      "name": "Rock_Volcanic_Cracked_Poisoned"
    },
    {
      "x": 8,
      "y": 18,
      "z": 12,
      "name": "Plant_Coral_Block_Green"
    },
    {
      "x": 8,
      "y": 19,
      "z": 12,
      "name": "Plant_Coral_Block_Green"
    },
    {
      "x": 8,
      "y": 20,
      "z": 12,
      "name": "Plant_Coral_Block_Green"
    },
    {
      "x": 8,
      "y": 21,
      "z": 12,
      "name": "Plant_Coral_Block_Green"
    },
    {
      "x": 8,
      "y": 22,
      "z": 12,
      "name": "Plant_Coral_Block_Green"
    },
    {
      "x": 8,
      "y": 38,
      "z": 12,
      "name": "Plant_Coral_Block_Green"
    },
    {
      "x": 8,
      "y": 39,
      "z": 12,
      "name": "Plant_Coral_Block_Green"
    },
    {
      "x": 8,
      "y": 9,
      "z": 13,
      "name": "Rock_Volcanic_Cracked_Poisoned"
    },
    {
      "x": 8,
      "y": 10,
      "z": 13,
      "name": "Rock_Volcanic_Cracked_Poisoned"
    },
    {
      "x": 8,
      "y": 11,
      "z": 13,
      "name": "Rock_Volcanic_Cracked_Poisoned"
    },
    {
      "x": 8,
      "y": 12,
      "z": 13,
      "name": "Rock_Volcanic_Cracked_Poisoned"
    },
    {
      "x": 8,
      "y": 13,
      "z": 13,
      "name": "Plant_Coral_Block_Green"
    },
    {
      "x": 8,
      "y": 14,
      "z": 13,
      "name": "Plant_Coral_Block_Green"
    },
    {
      "x": 8,
      "y": 15,
      "z": 13,
      "name": "Plant_Coral_Block_Green"
    },
    {
      "x": 8,
      "y": 16,
      "z": 13,
      "name": "Plant_Coral_Block_Green"
    },
    {
      "x": 8,
      "y": 17,
      "z": 13,
      "name": "Plant_Coral_Block_Green"
    },
    {
      "x": 8,
      "y": 18,
      "z": 13,
      "name": "Plant_Coral_Block_Green"
    },
    {
      "x": 8,
      "y": 19,
      "z": 13,
      "name": "Plant_Coral_Block_Green"
    },
    {
      "x": 8,
      "y": 20,
      "z": 13,
      "name": "Plant_Coral_Block_Green"
    },
    {
      "x": 8,
      "y": 21,
      "z": 13,
      "name": "Plant_Coral_Block_Green"
    },
    {
      "x": 8,
      "y": 22,
      "z": 13,
      "name": "Plant_Coral_Block_Green"
    },
    {
      "x": 8,
      "y": 11,
      "z": 14,
      "name": "Rock_Volcanic_Cracked_Poisoned"
    },
    {
      "x": 8,
      "y": 13,
      "z": 14,
      "name": "Plant_Coral_Block_Green"
    },
    {
      "x": 8,
      "y": 14,
      "z": 14,
      "name": "Plant_Coral_Block_Green"
    },
    {
      "x": 8,
      "y": 15,
      "z": 14,
      "name": "Plant_Coral_Block_Green"
    },
    {
      "x": 8,
      "y": 16,
      "z": 14,
      "name": "Plant_Coral_Block_Green"
    },
    {
      "x": 8,
      "y": 17,
      "z": 14,
      "name": "Rock_Volcanic_Cracked_Poisoned"
    },
    {
      "x": 8,
      "y": 18,
      "z": 14,
      "name": "Rock_Volcanic_Cracked_Poisoned"
    },
    {
      "x": 8,
      "y": 19,
      "z": 14,
      "name": "Plant_Coral_Block_Green"
    },
    {
      "x": 8,
      "y": 20,
      "z": 14,
      "name": "Plant_Coral_Block_Green"
    },
    {
      "x": 8,
      "y": 21,
      "z": 14,
      "name": "Plant_Coral_Block_Green"
    },
    {
      "x": 8,
      "y": 13,
      "z": 15,
      "name": "Plant_Coral_Block_Green"
    },
    {
      "x": 8,
      "y": 14,
      "z": 15,
      "name": "Plant_Coral_Block_Green"
    },
    {
      "x": 8,
      "y": 15,
      "z": 15,
      "name": "Plant_Coral_Block_Green"
    },
    {
      "x": 8,
      "y": 16,
      "z": 15,
      "name": "Plant_Coral_Block_Green"
    },
    {
      "x": 8,
      "y": 17,
      "z": 15,
      "name": "Rock_Volcanic_Cracked_Poisoned"
    },
    {
      "x": 8,
      "y": 18,
      "z": 15,
      "name": "Rock_Volcanic_Cracked_Poisoned"
    },
    {
      "x": 9,
      "y": 16,
      "z": 6,
      "name": "Plant_Coral_Block_Green"
    },
    {
      "x": 9,
      "y": 17,
      "z": 6,
      "name": "Plant_Coral_Block_Green"
    },
    {
      "x": 9,
      "y": 12,
      "z": 7,
      "name": "Rock_Volcanic_Cracked_Poisoned"
    },
    {
      "x": 9,
      "y": 13,
      "z": 7,
      "name": "Rock_Volcanic_Cracked_Poisoned"
    },
    {
      "x": 9,
      "y": 14,
      "z": 7,
      "name": "Rock_Volcanic_Cracked_Poisoned"
    },
    {
      "x": 9,
      "y": 15,
      "z": 7,
      "name": "Rock_Volcanic_Cracked_Poisoned"
    },
    {
      "x": 9,
      "y": 16,
      "z": 7,
      "name": "Plant_Coral_Block_Green"
    },
    {
      "x": 9,
      "y": 17,
      "z": 7,
      "name": "Plant_Coral_Block_Green"
    },
    {
      "x": 9,
      "y": 18,
      "z": 7,
      "name": "Plant_Coral_Block_Green"
    },
    {
      "x": 9,
      "y": 19,
      "z": 7,
      "name": "Rock_Volcanic_Cracked_Poisoned"
    },
    {
      "x": 9,
      "y": 21,
      "z": 7,
      "name": "Rock_Volcanic_Cracked_Poisoned"
    },
    {
      "x": 9,
      "y": 10,
      "z": 8,
      "name": "Rock_Volcanic_Cracked_Poisoned"
    },
    {
      "x": 9,
      "y": 11,
      "z": 8,
      "name": "Rock_Volcanic_Cracked_Poisoned"
    },
    {
      "x": 9,
      "y": 12,
      "z": 8,
      "name": "Rock_Volcanic_Cracked_Poisoned"
    },
    {
      "x": 9,
      "y": 13,
      "z": 8,
      "name": "Rock_Volcanic_Cracked_Poisoned"
    },
    {
      "x": 9,
      "y": 14,
      "z": 8,
      "name": "Rock_Volcanic_Cracked_Poisoned"
    },
    {
      "x": 9,
      "y": 15,
      "z": 8,
      "name": "Rock_Volcanic_Cracked_Poisoned"
    },
    {
      "x": 9,
      "y": 16,
      "z": 8,
      "name": "Plant_Coral_Block_Green"
    },
    {
      "x": 9,
      "y": 17,
      "z": 8,
      "name": "Plant_Coral_Block_Green"
    },
    {
      "x": 9,
      "y": 18,
      "z": 8,
      "name": "Plant_Coral_Block_Green"
    },
    {
      "x": 9,
      "y": 19,
      "z": 8,
      "name": "Rock_Volcanic_Cracked_Poisoned"
    },
    {
      "x": 9,
      "y": 20,
      "z": 8,
      "name": "Rock_Volcanic_Cracked_Poisoned"
    },
    {
      "x": 9,
      "y": 21,
      "z": 8,
      "name": "Rock_Volcanic_Cracked_Poisoned"
    },
    {
      "x": 9,
      "y": 22,
      "z": 8,
      "name": "Rock_Volcanic_Cracked_Poisoned"
    },
    {
      "x": 9,
      "y": 23,
      "z": 8,
      "name": "Rock_Volcanic_Cracked_Poisoned"
    },
    {
      "x": 9,
      "y": 28,
      "z": 8,
      "name": "Rock_Volcanic_Cracked_Poisoned"
    },
    {
      "x": 9,
      "y": 30,
      "z": 8,
      "name": "Rock_Volcanic_Cracked_Poisoned"
    },
    {
      "x": 9,
      "y": 31,
      "z": 8,
      "name": "Rock_Volcanic_Cracked_Poisoned"
    },
    {
      "x": 9,
      "y": 32,
      "z": 8,
      "name": "Rock_Volcanic_Cracked_Poisoned"
    },
    {
      "x": 9,
      "y": 33,
      "z": 8,
      "name": "Rock_Volcanic_Cracked_Poisoned"
    },
    {
      "x": 9,
      "y": 34,
      "z": 8,
      "name": "Rock_Volcanic_Cracked_Poisoned"
    },
    {
      "x": 9,
      "y": 9,
      "z": 9,
      "name": "Rock_Volcanic_Cracked_Poisoned"
    },
    {
      "x": 9,
      "y": 10,
      "z": 9,
      "name": "Rock_Volcanic_Cracked_Poisoned"
    },
    {
      "x": 9,
      "y": 11,
      "z": 9,
      "name": "Rock_Volcanic_Cracked_Poisoned"
    },
    {
      "x": 9,
      "y": 12,
      "z": 9,
      "name": "Rock_Volcanic_Cracked_Poisoned"
    },
    {
      "x": 9,
      "y": 13,
      "z": 9,
      "name": "Rock_Volcanic_Cracked_Poisoned"
    },
    {
      "x": 9,
      "y": 14,
      "z": 9,
      "name": "Rock_Volcanic_Cracked_Poisoned"
    },
    {
      "x": 9,
      "y": 15,
      "z": 9,
      "name": "Rock_Volcanic_Cracked_Poisoned"
    },
    {
      "x": 9,
      "y": 16,
      "z": 9,
      "name": "Rock_Volcanic_Cracked_Poisoned"
    },
    {
      "x": 9,
      "y": 17,
      "z": 9,
      "name": "Rock_Volcanic_Cracked_Poisoned"
    },
    {
      "x": 9,
      "y": 18,
      "z": 9,
      "name": "Rock_Volcanic_Cracked_Poisoned"
    },
    {
      "x": 9,
      "y": 19,
      "z": 9,
      "name": "Rock_Volcanic_Cracked_Poisoned"
    },
    {
      "x": 9,
      "y": 20,
      "z": 9,
      "name": "Rock_Volcanic_Cracked_Poisoned"
    },
    {
      "x": 9,
      "y": 21,
      "z": 9,
      "name": "Rock_Volcanic_Cracked_Poisoned"
    },
    {
      "x": 9,
      "y": 22,
      "z": 9,
      "name": "Rock_Volcanic_Cracked_Poisoned"
    },
    {
      "x": 9,
      "y": 29,
      "z": 9,
      "name": "Rock_Volcanic_Cracked_Poisoned"
    },
    {
      "x": 9,
      "y": 30,
      "z": 9,
      "name": "Rock_Volcanic_Cracked_Poisoned"
    },
    {
      "x": 9,
      "y": 31,
      "z": 9,
      "name": "Rock_Volcanic_Cracked_Poisoned"
    },
    {
      "x": 9,
      "y": 32,
      "z": 9,
      "name": "Rock_Volcanic_Cracked_Poisoned"
    },
    {
      "x": 9,
      "y": 33,
      "z": 9,
      "name": "Rock_Volcanic_Cracked_Poisoned"
    },
    {
      "x": 9,
      "y": 34,
      "z": 9,
      "name": "Rock_Volcanic_Cracked_Poisoned"
    },
    {
      "x": 9,
      "y": 35,
      "z": 9,
      "name": "Rock_Volcanic_Cracked_Poisoned"
    },
    {
      "x": 9,
      "y": 36,
      "z": 9,
      "name": "Rock_Volcanic_Cracked_Poisoned"
    },
    {
      "x": 9,
      "y": 37,
      "z": 9,
      "name": "Rock_Volcanic_Cracked_Poisoned"
    },
    {
      "x": 9,
      "y": 38,
      "z": 9,
      "name": "Rock_Volcanic_Cracked_Poisoned"
    },
    {
      "x": 9,
      "y": 39,
      "z": 9,
      "name": "Rock_Volcanic_Cracked_Poisoned"
    },
    {
      "x": 9,
      "y": 40,
      "z": 9,
      "name": "Rock_Volcanic_Cracked_Poisoned"
    },
    {
      "x": 9,
      "y": 9,
      "z": 10,
      "name": "Rock_Volcanic_Cracked_Poisoned"
    },
    {
      "x": 9,
      "y": 10,
      "z": 10,
      "name": "Rock_Volcanic_Cracked_Poisoned"
    },
    {
      "x": 9,
      "y": 11,
      "z": 10,
      "name": "Rock_Volcanic_Cracked_Poisoned"
    },
    {
      "x": 9,
      "y": 12,
      "z": 10,
      "name": "Rock_Volcanic_Cracked_Poisoned"
    },
    {
      "x": 9,
      "y": 13,
      "z": 10,
      "name": "Rock_Volcanic_Cracked_Poisoned"
    },
    {
      "x": 9,
      "y": 14,
      "z": 10,
      "name": "Rock_Volcanic_Cracked_Poisoned"
    },
    {
      "x": 9,
      "y": 15,
      "z": 10,
      "name": "Rock_Volcanic_Cracked_Poisoned"
    },
    {
      "x": 9,
      "y": 16,
      "z": 10,
      "name": "Rock_Volcanic_Cracked_Poisoned"
    },
    {
      "x": 9,
      "y": 17,
      "z": 10,
      "name": "Rock_Volcanic_Cracked_Poisoned"
    },
    {
      "x": 9,
      "y": 18,
      "z": 10,
      "name": "Plant_Coral_Block_Green"
    },
    {
      "x": 9,
      "y": 19,
      "z": 10,
      "name": "Plant_Coral_Block_Green"
    },
    {
      "x": 9,
      "y": 20,
      "z": 10,
      "name": "Plant_Coral_Block_Green"
    },
    {
      "x": 9,
      "y": 21,
      "z": 10,
      "name": "Plant_Coral_Block_Green"
    },
    {
      "x": 9,
      "y": 22,
      "z": 10,
      "name": "Plant_Coral_Block_Green"
    },
    {
      "x": 9,
      "y": 30,
      "z": 10,
      "name": "Rock_Volcanic_Cracked_Poisoned"
    },
    {
      "x": 9,
      "y": 31,
      "z": 10,
      "name": "Rock_Volcanic_Cracked_Poisoned"
    },
    {
      "x": 9,
      "y": 32,
      "z": 10,
      "name": "Rock_Volcanic_Cracked_Poisoned"
    },
    {
      "x": 9,
      "y": 33,
      "z": 10,
      "name": "Rock_Volcanic_Cracked_Poisoned"
    },
    {
      "x": 9,
      "y": 34,
      "z": 10,
      "name": "Rock_Volcanic_Cracked_Poisoned"
    },
    {
      "x": 9,
      "y": 35,
      "z": 10,
      "name": "Rock_Volcanic_Cracked_Poisoned"
    },
    {
      "x": 9,
      "y": 36,
      "z": 10,
      "name": "Rock_Volcanic_Cracked_Poisoned"
    },
    {
      "x": 9,
      "y": 37,
      "z": 10,
      "name": "Rock_Volcanic_Cracked_Poisoned"
    },
    {
      "x": 9,
      "y": 38,
      "z": 10,
      "name": "Rock_Volcanic_Cracked_Poisoned"
    },
    {
      "x": 9,
      "y": 39,
      "z": 10,
      "name": "Rock_Volcanic_Cracked_Poisoned"
    },
    {
      "x": 9,
      "y": 40,
      "z": 10,
      "name": "Rock_Volcanic_Cracked_Poisoned"
    },
    {
      "x": 9,
      "y": 8,
      "z": 11,
      "name": "Rock_Volcanic_Cracked_Poisoned"
    },
    {
      "x": 9,
      "y": 9,
      "z": 11,
      "name": "Rock_Volcanic_Cracked_Poisoned"
    },
    {
      "x": 9,
      "y": 10,
      "z": 11,
      "name": "Rock_Volcanic_Cracked_Poisoned"
    },
    {
      "x": 9,
      "y": 11,
      "z": 11,
      "name": "Rock_Volcanic_Cracked_Poisoned"
    },
    {
      "x": 9,
      "y": 12,
      "z": 11,
      "name": "Rock_Volcanic_Cracked_Poisoned"
    },
    {
      "x": 9,
      "y": 13,
      "z": 11,
      "name": "Rock_Volcanic_Cracked_Poisoned"
    },
    {
      "x": 9,
      "y": 14,
      "z": 11,
      "name": "Rock_Volcanic_Cracked_Poisoned"
    },
    {
      "x": 9,
      "y": 15,
      "z": 11,
      "name": "Rock_Volcanic_Cracked_Poisoned"
    },
    {
      "x": 9,
      "y": 16,
      "z": 11,
      "name": "Rock_Volcanic_Cracked_Poisoned"
    },
    {
      "x": 9,
      "y": 17,
      "z": 11,
      "name": "Rock_Volcanic_Cracked_Poisoned"
    },
    {
      "x": 9,
      "y": 18,
      "z": 11,
      "name": "Plant_Coral_Block_Green"
    },
    {
      "x": 9,
      "y": 19,
      "z": 11,
      "name": "Plant_Coral_Block_Green"
    },
    {
      "x": 9,
      "y": 20,
      "z": 11,
      "name": "Plant_Coral_Block_Green"
    },
    {
      "x": 9,
      "y": 21,
      "z": 11,
      "name": "Plant_Coral_Block_Green"
    },
    {
      "x": 9,
      "y": 22,
      "z": 11,
      "name": "Plant_Coral_Block_Green"
    },
    {
      "x": 9,
      "y": 31,
      "z": 11,
      "name": "Rock_Volcanic_Cracked_Poisoned"
    },
    {
      "x": 9,
      "y": 32,
      "z": 11,
      "name": "Rock_Volcanic_Cracked_Poisoned"
    },
    {
      "x": 9,
      "y": 33,
      "z": 11,
      "name": "Rock_Volcanic_Cracked_Poisoned"
    },
    {
      "x": 9,
      "y": 34,
      "z": 11,
      "name": "Rock_Volcanic_Cracked_Poisoned"
    },
    {
      "x": 9,
      "y": 35,
      "z": 11,
      "name": "Rock_Volcanic_Cracked_Poisoned"
    },
    {
      "x": 9,
      "y": 36,
      "z": 11,
      "name": "Rock_Volcanic_Cracked_Poisoned"
    },
    {
      "x": 9,
      "y": 37,
      "z": 11,
      "name": "Rock_Volcanic_Cracked_Poisoned"
    },
    {
      "x": 9,
      "y": 38,
      "z": 11,
      "name": "Rock_Volcanic_Cracked_Poisoned"
    },
    {
      "x": 9,
      "y": 39,
      "z": 11,
      "name": "Rock_Volcanic_Cracked_Poisoned"
    },
    {
      "x": 9,
      "y": 10,
      "z": 12,
      "name": "Rock_Volcanic_Cracked_Poisoned"
    },
    {
      "x": 9,
      "y": 11,
      "z": 12,
      "name": "Rock_Volcanic_Cracked_Poisoned"
    },
    {
      "x": 9,
      "y": 12,
      "z": 12,
      "name": "Rock_Volcanic_Cracked_Poisoned"
    },
    {
      "x": 9,
      "y": 13,
      "z": 12,
      "name": "Rock_Volcanic_Cracked_Poisoned"
    },
    {
      "x": 9,
      "y": 14,
      "z": 12,
      "name": "Plant_Coral_Block_Green"
    },
    {
      "x": 9,
      "y": 15,
      "z": 12,
      "name": "Plant_Coral_Block_Green"
    },
    {
      "x": 9,
      "y": 16,
      "z": 12,
      "name": "Plant_Coral_Block_Green"
    },
    {
      "x": 9,
      "y": 17,
      "z": 12,
      "name": "Rock_Volcanic_Cracked_Poisoned"
    },
    {
      "x": 9,
      "y": 18,
      "z": 12,
      "name": "Plant_Coral_Block_Green"
    },
    {
      "x": 9,
      "y": 19,
      "z": 12,
      "name": "Plant_Coral_Block_Green"
    },
    {
      "x": 9,
      "y": 20,
      "z": 12,
      "name": "Plant_Coral_Block_Green"
    },
    {
      "x": 9,
      "y": 21,
      "z": 12,
      "name": "Plant_Coral_Block_Green"
    },
    {
      "x": 9,
      "y": 22,
      "z": 12,
      "name": "Plant_Coral_Block_Green"
    },
    {
      "x": 9,
      "y": 10,
      "z": 13,
      "name": "Rock_Volcanic_Cracked_Poisoned"
    },
    {
      "x": 9,
      "y": 11,
      "z": 13,
      "name": "Rock_Volcanic_Cracked_Poisoned"
    },
    {
      "x": 9,
      "y": 12,
      "z": 13,
      "name": "Rock_Volcanic_Cracked_Poisoned"
    },
    {
      "x": 9,
      "y": 13,
      "z": 13,
      "name": "Rock_Volcanic_Cracked_Poisoned"
    },
    {
      "x": 9,
      "y": 14,
      "z": 13,
      "name": "Plant_Coral_Block_Green"
    },
    {
      "x": 9,
      "y": 15,
      "z": 13,
      "name": "Plant_Coral_Block_Green"
    },
    {
      "x": 9,
      "y": 16,
      "z": 13,
      "name": "Plant_Coral_Block_Green"
    },
    {
      "x": 9,
      "y": 17,
      "z": 13,
      "name": "Rock_Volcanic_Cracked_Poisoned"
    },
    {
      "x": 9,
      "y": 18,
      "z": 13,
      "name": "Plant_Coral_Block_Green"
    },
    {
      "x": 9,
      "y": 19,
      "z": 13,
      "name": "Plant_Coral_Block_Green"
    },
    {
      "x": 9,
      "y": 20,
      "z": 13,
      "name": "Plant_Coral_Block_Green"
    },
    {
      "x": 9,
      "y": 21,
      "z": 13,
      "name": "Plant_Coral_Block_Green"
    },
    {
      "x": 9,
      "y": 22,
      "z": 13,
      "name": "Plant_Coral_Block_Green"
    },
    {
      "x": 9,
      "y": 13,
      "z": 14,
      "name": "Plant_Coral_Block_Green"
    },
    {
      "x": 9,
      "y": 14,
      "z": 14,
      "name": "Plant_Coral_Block_Green"
    },
    {
      "x": 9,
      "y": 15,
      "z": 14,
      "name": "Plant_Coral_Block_Green"
    },
    {
      "x": 9,
      "y": 16,
      "z": 14,
      "name": "Plant_Coral_Block_Green"
    },
    {
      "x": 9,
      "y": 17,
      "z": 14,
      "name": "Rock_Volcanic_Cracked_Poisoned"
    },
    {
      "x": 9,
      "y": 18,
      "z": 14,
      "name": "Plant_Coral_Block_Green"
    },
    {
      "x": 9,
      "y": 19,
      "z": 14,
      "name": "Plant_Coral_Block_Green"
    },
    {
      "x": 9,
      "y": 20,
      "z": 14,
      "name": "Plant_Coral_Block_Green"
    },
    {
      "x": 9,
      "y": 21,
      "z": 14,
      "name": "Plant_Coral_Block_Green"
    },
    {
      "x": 9,
      "y": 22,
      "z": 14,
      "name": "Plant_Coral_Block_Green"
    },
    {
      "x": 9,
      "y": 13,
      "z": 15,
      "name": "Plant_Coral_Block_Green"
    },
    {
      "x": 9,
      "y": 14,
      "z": 15,
      "name": "Plant_Coral_Block_Green"
    },
    {
      "x": 9,
      "y": 15,
      "z": 15,
      "name": "Plant_Coral_Block_Green"
    },
    {
      "x": 9,
      "y": 16,
      "z": 15,
      "name": "Plant_Coral_Block_Green"
    },
    {
      "x": 9,
      "y": 17,
      "z": 15,
      "name": "Rock_Volcanic_Cracked_Poisoned"
    },
    {
      "x": 10,
      "y": 12,
      "z": 7,
      "name": "Rock_Volcanic_Cracked_Poisoned"
    },
    {
      "x": 10,
      "y": 13,
      "z": 7,
      "name": "Rock_Volcanic_Cracked_Poisoned"
    },
    {
      "x": 10,
      "y": 14,
      "z": 7,
      "name": "Rock_Volcanic_Cracked_Poisoned"
    },
    {
      "x": 10,
      "y": 15,
      "z": 7,
      "name": "Rock_Volcanic_Cracked_Poisoned"
    },
    {
      "x": 10,
      "y": 16,
      "z": 7,
      "name": "Rock_Volcanic_Cracked_Poisoned"
    },
    {
      "x": 10,
      "y": 17,
      "z": 7,
      "name": "Rock_Volcanic_Cracked_Poisoned"
    },
    {
      "x": 10,
      "y": 18,
      "z": 7,
      "name": "Rock_Volcanic_Cracked_Poisoned"
    },
    {
      "x": 10,
      "y": 10,
      "z": 8,
      "name": "Rock_Volcanic_Cracked_Poisoned"
    },
    {
      "x": 10,
      "y": 11,
      "z": 8,
      "name": "Rock_Volcanic_Cracked_Poisoned"
    },
    {
      "x": 10,
      "y": 12,
      "z": 8,
      "name": "Rock_Volcanic_Cracked_Poisoned"
    },
    {
      "x": 10,
      "y": 13,
      "z": 8,
      "name": "Rock_Volcanic_Cracked_Poisoned"
    },
    {
      "x": 10,
      "y": 14,
      "z": 8,
      "name": "Rock_Volcanic_Cracked_Poisoned"
    },
    {
      "x": 10,
      "y": 15,
      "z": 8,
      "name": "Rock_Volcanic_Cracked_Poisoned"
    },
    {
      "x": 10,
      "y": 16,
      "z": 8,
      "name": "Rock_Volcanic_Cracked_Poisoned"
    },
    {
      "x": 10,
      "y": 17,
      "z": 8,
      "name": "Rock_Volcanic_Cracked_Poisoned"
    },
    {
      "x": 10,
      "y": 18,
      "z": 8,
      "name": "Rock_Volcanic_Cracked_Poisoned"
    },
    {
      "x": 10,
      "y": 9,
      "z": 9,
      "name": "Rock_Volcanic_Cracked_Poisoned"
    },
    {
      "x": 10,
      "y": 10,
      "z": 9,
      "name": "Rock_Volcanic_Cracked_Poisoned"
    },
    {
      "x": 10,
      "y": 11,
      "z": 9,
      "name": "Rock_Volcanic_Cracked_Poisoned"
    },
    {
      "x": 10,
      "y": 12,
      "z": 9,
      "name": "Rock_Volcanic_Cracked_Poisoned"
    },
    {
      "x": 10,
      "y": 13,
      "z": 9,
      "name": "Rock_Volcanic_Cracked_Poisoned"
    },
    {
      "x": 10,
      "y": 14,
      "z": 9,
      "name": "Rock_Volcanic_Cracked_Poisoned"
    },
    {
      "x": 10,
      "y": 15,
      "z": 9,
      "name": "Rock_Volcanic_Cracked_Poisoned"
    },
    {
      "x": 10,
      "y": 16,
      "z": 9,
      "name": "Rock_Volcanic_Cracked_Poisoned"
    },
    {
      "x": 10,
      "y": 17,
      "z": 9,
      "name": "Rock_Volcanic_Cracked_Poisoned"
    },
    {
      "x": 10,
      "y": 18,
      "z": 9,
      "name": "Rock_Volcanic_Cracked_Poisoned"
    },
    {
      "x": 10,
      "y": 19,
      "z": 9,
      "name": "Rock_Volcanic_Cracked_Poisoned"
    },
    {
      "x": 10,
      "y": 20,
      "z": 9,
      "name": "Rock_Volcanic_Cracked_Poisoned"
    },
    {
      "x": 10,
      "y": 32,
      "z": 9,
      "name": "Rock_Volcanic_Cracked_Poisoned"
    },
    {
      "x": 10,
      "y": 33,
      "z": 9,
      "name": "Rock_Volcanic_Cracked_Poisoned"
    },
    {
      "x": 10,
      "y": 34,
      "z": 9,
      "name": "Plant_Coral_Block_Green"
    },
    {
      "x": 10,
      "y": 35,
      "z": 9,
      "name": "Plant_Coral_Block_Green"
    },
    {
      "x": 10,
      "y": 36,
      "z": 9,
      "name": "Rock_Volcanic_Cracked_Poisoned"
    },
    {
      "x": 10,
      "y": 37,
      "z": 9,
      "name": "Rock_Volcanic_Cracked_Poisoned"
    },
    {
      "x": 10,
      "y": 38,
      "z": 9,
      "name": "Rock_Volcanic_Cracked_Poisoned"
    },
    {
      "x": 10,
      "y": 39,
      "z": 9,
      "name": "Rock_Volcanic_Cracked_Poisoned"
    },
    {
      "x": 10,
      "y": 9,
      "z": 10,
      "name": "Rock_Volcanic_Cracked_Poisoned"
    },
    {
      "x": 10,
      "y": 10,
      "z": 10,
      "name": "Rock_Volcanic_Cracked_Poisoned"
    },
    {
      "x": 10,
      "y": 11,
      "z": 10,
      "name": "Rock_Volcanic_Cracked_Poisoned"
    },
    {
      "x": 10,
      "y": 12,
      "z": 10,
      "name": "Rock_Volcanic_Cracked_Poisoned"
    },
    {
      "x": 10,
      "y": 13,
      "z": 10,
      "name": "Rock_Volcanic_Cracked_Poisoned"
    },
    {
      "x": 10,
      "y": 14,
      "z": 10,
      "name": "Rock_Volcanic_Cracked_Poisoned"
    },
    {
      "x": 10,
      "y": 15,
      "z": 10,
      "name": "Rock_Volcanic_Cracked_Poisoned"
    },
    {
      "x": 10,
      "y": 16,
      "z": 10,
      "name": "Rock_Volcanic_Cracked_Poisoned"
    },
    {
      "x": 10,
      "y": 17,
      "z": 10,
      "name": "Rock_Volcanic_Cracked_Poisoned"
    },
    {
      "x": 10,
      "y": 18,
      "z": 10,
      "name": "Plant_Coral_Block_Green"
    },
    {
      "x": 10,
      "y": 19,
      "z": 10,
      "name": "Plant_Coral_Block_Green"
    },
    {
      "x": 10,
      "y": 20,
      "z": 10,
      "name": "Plant_Coral_Block_Green"
    },
    {
      "x": 10,
      "y": 21,
      "z": 10,
      "name": "Plant_Coral_Block_Green"
    },
    {
      "x": 10,
      "y": 22,
      "z": 10,
      "name": "Plant_Coral_Block_Green"
    },
    {
      "x": 10,
      "y": 32,
      "z": 10,
      "name": "Rock_Volcanic_Cracked_Poisoned"
    },
    {
      "x": 10,
      "y": 33,
      "z": 10,
      "name": "Rock_Volcanic_Cracked_Poisoned"
    },
    {
      "x": 10,
      "y": 34,
      "z": 10,
      "name": "Plant_Coral_Block_Green"
    },
    {
      "x": 10,
      "y": 35,
      "z": 10,
      "name": "Plant_Coral_Block_Green"
    },
    {
      "x": 10,
      "y": 36,
      "z": 10,
      "name": "Rock_Volcanic_Cracked_Poisoned"
    },
    {
      "x": 10,
      "y": 37,
      "z": 10,
      "name": "Rock_Volcanic_Cracked_Poisoned"
    },
    {
      "x": 10,
      "y": 38,
      "z": 10,
      "name": "Rock_Volcanic_Cracked_Poisoned"
    },
    {
      "x": 10,
      "y": 9,
      "z": 11,
      "name": "Rock_Volcanic_Cracked_Poisoned"
    },
    {
      "x": 10,
      "y": 10,
      "z": 11,
      "name": "Rock_Volcanic_Cracked_Poisoned"
    },
    {
      "x": 10,
      "y": 11,
      "z": 11,
      "name": "Rock_Volcanic_Cracked_Poisoned"
    },
    {
      "x": 10,
      "y": 12,
      "z": 11,
      "name": "Rock_Volcanic_Cracked_Poisoned"
    },
    {
      "x": 10,
      "y": 13,
      "z": 11,
      "name": "Rock_Volcanic_Cracked_Poisoned"
    },
    {
      "x": 10,
      "y": 14,
      "z": 11,
      "name": "Rock_Volcanic_Cracked_Poisoned"
    },
    {
      "x": 10,
      "y": 15,
      "z": 11,
      "name": "Rock_Volcanic_Cracked_Poisoned"
    },
    {
      "x": 10,
      "y": 16,
      "z": 11,
      "name": "Rock_Volcanic_Cracked_Poisoned"
    },
    {
      "x": 10,
      "y": 17,
      "z": 11,
      "name": "Rock_Volcanic_Cracked_Poisoned"
    },
    {
      "x": 10,
      "y": 18,
      "z": 11,
      "name": "Plant_Coral_Block_Green"
    },
    {
      "x": 10,
      "y": 19,
      "z": 11,
      "name": "Plant_Coral_Block_Green"
    },
    {
      "x": 10,
      "y": 20,
      "z": 11,
      "name": "Plant_Coral_Block_Green"
    },
    {
      "x": 10,
      "y": 21,
      "z": 11,
      "name": "Plant_Coral_Block_Green"
    },
    {
      "x": 10,
      "y": 22,
      "z": 11,
      "name": "Plant_Coral_Block_Green"
    },
    {
      "x": 10,
      "y": 33,
      "z": 11,
      "name": "Rock_Volcanic_Cracked_Poisoned"
    },
    {
      "x": 10,
      "y": 34,
      "z": 11,
      "name": "Rock_Volcanic_Cracked_Poisoned"
    },
    {
      "x": 10,
      "y": 35,
      "z": 11,
      "name": "Rock_Volcanic_Cracked_Poisoned"
    },
    {
      "x": 10,
      "y": 36,
      "z": 11,
      "name": "Rock_Volcanic_Cracked_Poisoned"
    },
    {
      "x": 10,
      "y": 10,
      "z": 12,
      "name": "Rock_Volcanic_Cracked_Poisoned"
    },
    {
      "x": 10,
      "y": 11,
      "z": 12,
      "name": "Rock_Volcanic_Cracked_Poisoned"
    },
    {
      "x": 10,
      "y": 12,
      "z": 12,
      "name": "Rock_Volcanic_Cracked_Poisoned"
    },
    {
      "x": 10,
      "y": 13,
      "z": 12,
      "name": "Rock_Volcanic_Cracked_Poisoned"
    },
    {
      "x": 10,
      "y": 14,
      "z": 12,
      "name": "Rock_Volcanic_Cracked_Poisoned"
    },
    {
      "x": 10,
      "y": 15,
      "z": 12,
      "name": "Rock_Volcanic_Cracked_Poisoned"
    },
    {
      "x": 10,
      "y": 16,
      "z": 12,
      "name": "Rock_Volcanic_Cracked_Poisoned"
    },
    {
      "x": 10,
      "y": 17,
      "z": 12,
      "name": "Plant_Coral_Block_Green"
    },
    {
      "x": 10,
      "y": 18,
      "z": 12,
      "name": "Plant_Coral_Block_Green"
    },
    {
      "x": 10,
      "y": 19,
      "z": 12,
      "name": "Plant_Coral_Block_Green"
    },
    {
      "x": 10,
      "y": 20,
      "z": 12,
      "name": "Plant_Coral_Block_Green"
    },
    {
      "x": 10,
      "y": 21,
      "z": 12,
      "name": "Rock_Volcanic_Cracked_Poisoned"
    },
    {
      "x": 10,
      "y": 22,
      "z": 12,
      "name": "Rock_Volcanic_Cracked_Poisoned"
    },
    {
      "x": 10,
      "y": 23,
      "z": 12,
      "name": "Rock_Volcanic_Cracked_Poisoned"
    },
    {
      "x": 10,
      "y": 9,
      "z": 13,
      "name": "Rock_Volcanic_Cracked_Poisoned"
    },
    {
      "x": 10,
      "y": 10,
      "z": 13,
      "name": "Rock_Volcanic_Cracked_Poisoned"
    },
    {
      "x": 10,
      "y": 11,
      "z": 13,
      "name": "Rock_Volcanic_Cracked_Poisoned"
    },
    {
      "x": 10,
      "y": 12,
      "z": 13,
      "name": "Rock_Volcanic_Cracked_Poisoned"
    },
    {
      "x": 10,
      "y": 13,
      "z": 13,
      "name": "Plant_Coral_Block_Green"
    },
    {
      "x": 10,
      "y": 14,
      "z": 13,
      "name": "Rock_Volcanic_Cracked_Poisoned"
    },
    {
      "x": 10,
      "y": 15,
      "z": 13,
      "name": "Plant_Coral_Block_Green"
    },
    {
      "x": 10,
      "y": 16,
      "z": 13,
      "name": "Rock_Volcanic_Cracked_Poisoned"
    },
    {
      "x": 10,
      "y": 17,
      "z": 13,
      "name": "Rock_Volcanic_Cracked_Poisoned"
    },
    {
      "x": 10,
      "y": 18,
      "z": 13,
      "name": "Plant_Coral_Block_Green"
    },
    {
      "x": 10,
      "y": 19,
      "z": 13,
      "name": "Plant_Coral_Block_Green"
    },
    {
      "x": 10,
      "y": 20,
      "z": 13,
      "name": "Plant_Coral_Block_Green"
    },
    {
      "x": 10,
      "y": 21,
      "z": 13,
      "name": "Plant_Coral_Block_Green"
    },
    {
      "x": 10,
      "y": 22,
      "z": 13,
      "name": "Rock_Volcanic_Cracked_Poisoned"
    },
    {
      "x": 10,
      "y": 23,
      "z": 13,
      "name": "Rock_Volcanic_Cracked_Poisoned"
    },
    {
      "x": 10,
      "y": 24,
      "z": 13,
      "name": "Rock_Volcanic_Cracked_Poisoned"
    },
    {
      "x": 10,
      "y": 8,
      "z": 14,
      "name": "Rock_Volcanic_Cracked_Poisoned"
    },
    {
      "x": 10,
      "y": 9,
      "z": 14,
      "name": "Rock_Volcanic_Cracked_Poisoned"
    },
    {
      "x": 10,
      "y": 10,
      "z": 14,
      "name": "Rock_Volcanic_Cracked_Poisoned"
    },
    {
      "x": 10,
      "y": 11,
      "z": 14,
      "name": "Rock_Volcanic_Cracked_Poisoned"
    },
    {
      "x": 10,
      "y": 12,
      "z": 14,
      "name": "Rock_Volcanic_Cracked_Poisoned"
    },
    {
      "x": 10,
      "y": 13,
      "z": 14,
      "name": "Plant_Coral_Block_Green"
    },
    {
      "x": 10,
      "y": 14,
      "z": 14,
      "name": "Plant_Coral_Block_Green"
    },
    {
      "x": 10,
      "y": 15,
      "z": 14,
      "name": "Rock_Volcanic_Cracked_Poisoned"
    },
    {
      "x": 10,
      "y": 16,
      "z": 14,
      "name": "Plant_Coral_Block_Green"
    },
    {
      "x": 10,
      "y": 17,
      "z": 14,
      "name": "Rock_Volcanic_Cracked_Poisoned"
    },
    {
      "x": 10,
      "y": 18,
      "z": 14,
      "name": "Plant_Coral_Block_Green"
    },
    {
      "x": 10,
      "y": 19,
      "z": 14,
      "name": "Plant_Coral_Block_Green"
    },
    {
      "x": 10,
      "y": 20,
      "z": 14,
      "name": "Plant_Coral_Block_Green"
    },
    {
      "x": 10,
      "y": 21,
      "z": 14,
      "name": "Plant_Coral_Block_Green"
    },
    {
      "x": 10,
      "y": 22,
      "z": 14,
      "name": "Plant_Coral_Block_Green"
    },
    {
      "x": 10,
      "y": 8,
      "z": 15,
      "name": "Rock_Volcanic_Cracked_Poisoned"
    },
    {
      "x": 10,
      "y": 9,
      "z": 15,
      "name": "Rock_Volcanic_Cracked_Poisoned"
    },
    {
      "x": 10,
      "y": 10,
      "z": 15,
      "name": "Rock_Volcanic_Cracked_Poisoned"
    },
    {
      "x": 10,
      "y": 11,
      "z": 15,
      "name": "Rock_Volcanic_Cracked_Poisoned"
    },
    {
      "x": 10,
      "y": 14,
      "z": 15,
      "name": "Plant_Coral_Block_Green"
    },
    {
      "x": 10,
      "y": 15,
      "z": 15,
      "name": "Plant_Coral_Block_Green"
    },
    {
      "x": 10,
      "y": 16,
      "z": 15,
      "name": "Rock_Volcanic_Cracked_Poisoned"
    },
    {
      "x": 10,
