{
  "version": 8,
  "blockIdVersion": 10,
  "anchorX": -1,
  "anchorY": 6,
  "anchorZ": 0,
  "blocks": [
    {
      "x": -5,
      "y": 15,
      "z": -2,
      "name": "Plant_Leaves_Stormbark"
    },
    {
      "x": -5,
      "y": 15,
      "z": -1,
      "name": "Plant_Leaves_Stormbark"
    },
    {
      "x": -5,
      "y": 15,
      "z": 0,
      "name": "Plant_Leaves_Stormbark"
    },
    {
      "x": -4,
      "y": 15,
      "z": -3,
      "name": "Plant_Leaves_Stormbark"
    },
    {
      "x": -4,
      "y": 15,
      "z": -2,
      "name": "Plant_Leaves_Stormbark"
    },
    {
      "x": -4,
      "y": 16,
      "z": -2,
      "name": "Plant_Leaves_Stormbark"
    },
    {
      "x": -4,
      "y": 15,
      "z": -1,
      "name": "Plant_Leaves_Stormbark"
    },
    {
      "x": -4,
      "y": 16,
      "z": -1,
      "name": "Plant_Leaves_Stormbark"
    },
    {
      "x": -4,
      "y": 15,
      "z": 0,
      "name": "Plant_Leaves_Stormbark"
    },
    {
      "x": -4,
      "y": 16,
      "z": 0,
      "name": "Plant_Leaves_Stormbark"
    },
    {
      "x": -4,
      "y": 15,
      "z": 1,
      "name": "Plant_Leaves_Stormbark"
    },
    {
      "x": -3,
      "y": 15,
      "z": -3,
      "name": "Plant_Leaves_Stormbark"
    },
    {
      "x": -3,
      "y": 15,
      "z": -2,
      "name": "Plant_Leaves_Stormbark"
    },
    {
      "x": -3,
      "y": 16,
      "z": -2,
      "name": "Plant_Leaves_Stormbark"
    },
    {
      "x": -3,
      "y": 13,
      "z": -1,
      "name": "Wood_Stormbark_Branch_Corner",
      "rotation": 2
    },
    {
      "x": -3,
      "y": 14,
      "z": -1,
      "name": "Wood_Stormbark_Branch_Long"
    },
    {
      "x": -3,
      "y": 15,
      "z": -1,
      "name": "Wood_Stormbark_Branch_Long"
    },
    {
      "x": -3,
      "y": 16,
      "z": -1,
      "name": "Plant_Leaves_Stormbark"
    },
    {
      "x": -3,
      "y": 17,
      "z": -1,
      "name": "Plant_Leaves_Stormbark"
    },
    {
      "x": -3,
      "y": 13,
      "z": 0,
      "name": "Wood_Stormbark_Branch_Long",
      "rotation": 4
    },
    {
      "x": -3,
      "y": 15,
      "z": 0,
      "name": "Plant_Leaves_Stormbark"
    },
    {
      "x": -3,
      "y": 16,
      "z": 0,
      "name": "Plant_Leaves_Stormbark"
    },
    {
      "x": -3,
      "y": 17,
      "z": 0,
      "name": "Plant_Leaves_Stormbark"
    },
    {
      "x": -3,
      "y": 12,
      "z": 1,
      "name": "Wood_Stormbark_Branch_Corner",
      "rotation": 3
    },
    {
      "x": -3,
      "y": 13,
      "z": 1,
      "name": "Wood_Stormbark_Branch_Corner",
      "rotation": 10
    },
    {
      "x": -3,
      "y": 15,
      "z": 1,
      "name": "Plant_Leaves_Stormbark"
    },
    {
      "x": -3,
      "y": 17,
      "z": 1,
      "name": "Plant_Leaves_Stormbark"
    },
    {
      "x": -2,
      "y": 15,
      "z": -3,
      "name": "Plant_Leaves_Stormbark"
    },
    {
      "x": -2,
      "y": 15,
      "z": -2,
      "name": "Plant_Leaves_Stormbark"
    },
    {
      "x": -2,
      "y": 16,
      "z": -2,
      "name": "Plant_Leaves_Stormbark"
    },
    {
      "x": -2,
      "y": 17,
      "z": -2,
      "name": "Plant_Leaves_Stormbark"
    },
    {
      "x": -2,
      "y": 15,
      "z": -1,
      "name": "Plant_Leaves_Stormbark"
    },
    {
      "x": -2,
      "y": 16,
      "z": -1,
      "name": "Plant_Leaves_Stormbark"
    },
    {
      "x": -2,
      "y": 17,
      "z": -1,
      "name": "Plant_Leaves_Stormbark"
    },
    {
      "x": -2,
      "y": 18,
      "z": -1,
      "name": "Plant_Leaves_Stormbark"
    },
    {
      "x": -2,
      "y": 15,
      "z": 0,
      "name": "Plant_Leaves_Stormbark"
    },
    {
      "x": -2,
      "y": 16,
      "z": 0,
      "name": "Plant_Leaves_Stormbark"
    },
    {
      "x": -2,
      "y": 17,
      "z": 0,
      "name": "Plant_Leaves_Stormbark"
    },
    {
      "x": -2,
      "y": 18,
      "z": 0,
      "name": "Plant_Leaves_Stormbark"
    },
    {
      "x": -2,
      "y": 12,
      "z": 1,
      "name": "Wood_Stormbark_Branch_Long",
      "rotation": 5
    },
    {
      "x": -2,
      "y": 15,
      "z": 1,
      "name": "Plant_Leaves_Stormbark"
    },
    {
      "x": -2,
      "y": 17,
      "z": 1,
      "name": "Plant_Leaves_Stormbark"
    },
    {
      "x": -2,
      "y": 18,
      "z": 1,
      "name": "Plant_Leaves_Stormbark"
    },
    {
      "x": -2,
      "y": 17,
      "z": 2,
      "name": "Plant_Leaves_Stormbark"
    },
    {
      "x": -1,
      "y": 17,
      "z": -3,
      "name": "Plant_Leaves_Stormbark"
    },
    {
      "x": -1,
      "y": 15,
      "z": -2,
      "name": "Plant_Leaves_Stormbark"
    },
    {
      "x": -1,
      "y": 17,
      "z": -2,
      "name": "Plant_Leaves_Stormbark"
    },
    {
      "x": -1,
      "y": 18,
      "z": -2,
      "name": "Plant_Leaves_Stormbark"
    },
    {
      "x": -1,
      "y": 14,
      "z": -1,
      "name": "Wood_Stormbark_Branch_Corner",
      "rotation": 2
    },
    {
      "x": -1,
      "y": 15,
      "z": -1,
      "name": "Wood_Stormbark_Branch_Corner",
      "rotation": 9
    },
    {
      "x": -1,
      "y": 17,
      "z": -1,
      "name": "Plant_Leaves_Stormbark"
    },
    {
      "x": -1,
      "y": 18,
      "z": -1,
      "name": "Plant_Leaves_Stormbark"
    },
    {
      "x": -1,
      "y": 4,
      "z": 0,
      "name": "Wood_Stormbark_Roots"
    },
    {
      "x": -1,
      "y": 5,
      "z": 0,
      "name": "Wood_Stormbark_Trunk_Full"
    },
    {
      "x": -1,
      "y": 6,
      "z": 0,
      "name": "Wood_Stormbark_Trunk"
    },
    {
      "x": -1,
      "y": 7,
      "z": 0,
      "name": "Wood_Stormbark_Trunk"
    },
    {
      "x": -1,
      "y": 8,
      "z": 0,
      "name": "Wood_Stormbark_Trunk_Full"
    },
    {
      "x": -1,
      "y": 14,
      "z": 0,
      "name": "Wood_Stormbark_Branch_Long",
      "rotation": 4
    },
    {
      "x": -1,
      "y": 15,
      "z": 0,
      "name": "Plant_Leaves_Stormbark"
    },
    {
      "x": -1,
      "y": 17,
      "z": 0,
      "name": "Plant_Leaves_Stormbark"
    },
    {
      "x": -1,
      "y": 18,
      "z": 0,
      "name": "Plant_Leaves_Stormbark"
    },
    {
      "x": -1,
      "y": 19,
      "z": 0,
      "name": "Plant_Leaves_Stormbark"
    },
    {
      "x": -1,
      "y": 11,
      "z": 1,
      "name": "Wood_Stormbark_Trunk_Full"
    },
    {
      "x": -1,
      "y": 12,
      "z": 1,
      "name": "Wood_Stormbark_Trunk"
    },
    {
      "x": -1,
      "y": 13,
      "z": 1,
      "name": "Wood_Stormbark_Trunk"
    },
    {
      "x": -1,
      "y": 14,
      "z": 1,
      "name": "Wood_Stormbark_Trunk"
    },
    {
      "x": -1,
      "y": 15,
      "z": 1,
      "name": "Wood_Stormbark_Trunk_Full"
    },
    {
      "x": -1,
      "y": 17,
      "z": 1,
      "name": "Plant_Leaves_Stormbark"
    },
    {
      "x": -1,
      "y": 18,
      "z": 1,
      "name": "Plant_Leaves_Stormbark"
    },
    {
      "x": -1,
      "y": 13,
      "z": 2,
      "name": "Wood_Stormbark_Branch_Long",
      "rotation": 4
    },
    {
      "x": -1,
      "y": 17,
      "z": 2,
      "name": "Plant_Leaves_Stormbark"
    },
    {
      "x": -1,
      "y": 18,
      "z": 2,
      "name": "Plant_Leaves_Stormbark"
    },
    {
      "x": -1,
      "y": 13,
      "z": 3,
      "name": "Wood_Stormbark_Branch_Corner"
    },
    {
      "x": -1,
      "y": 14,
      "z": 3,
      "name": "Wood_Stormbark_Branch_Long"
    },
    {
      "x": -1,
      "y": 17,
      "z": 3,
      "name": "Plant_Leaves_Stormbark"
    },
    {
      "x": 0,
      "y": 17,
      "z": -3,
      "name": "Plant_Leaves_Stormbark"
    },
    {
      "x": 0,
      "y": 17,
      "z": -2,
      "name": "Plant_Leaves_Stormbark"
    },
    {
      "x": 0,
      "y": 18,
      "z": -2,
      "name": "Plant_Leaves_Stormbark"
    },
    {
      "x": 0,
      "y": 15,
      "z": -1,
      "name": "Wood_Stormbark_Branch_Corner",
      "rotation": 1
    },
    {
      "x": 0,
      "y": 16,
      "z": -1,
      "name": "Wood_Stormbark_Branch_Corner",
      "rotation": 8
    },
    {
      "x": 0,
      "y": 17,
      "z": -1,
      "name": "Plant_Leaves_Stormbark"
    },
    {
      "x": 0,
      "y": 18,
      "z": -1,
      "name": "Plant_Leaves_Stormbark"
    },
    {
      "x": 0,
      "y": 19,
      "z": -1,
      "name": "Plant_Leaves_Stormbark"
    },
    {
      "x": 0,
      "y": 8,
      "z": 0,
      "name": "Wood_Stormbark_Trunk_Full"
    },
    {
      "x": 0,
      "y": 13,
      "z": 0,
      "name": "Plant_Leaves_Stormbark"
    },
    {
      "x": 0,
      "y": 16,
      "z": 0,
      "name": "Wood_Stormbark_Branch_Corner"
    },
    {
      "x": 0,
      "y": 17,
      "z": 0,
      "name": "Wood_Stormbark_Branch_Long"
    },
    {
      "x": 0,
      "y": 18,
      "z": 0,
      "name": "Wood_Stormbark_Branch_Long"
    },
    {
      "x": 0,
      "y": 19,
      "z": 0,
      "name": "Plant_Leaves_Stormbark"
    },
    {
      "x": 0,
      "y": 11,
      "z": 1,
      "name": "Wood_Stormbark_Trunk_Full"
    },
    {
      "x": 0,
      "y": 13,
      "z": 1,
      "name": "Plant_Leaves_Stormbark"
    },
    {
      "x": 0,
      "y": 17,
      "z": 1,
      "name": "Plant_Leaves_Stormbark"
    },
    {
      "x": 0,
      "y": 18,
      "z": 1,
      "name": "Plant_Leaves_Stormbark"
    },
    {
      "x": 0,
      "y": 19,
      "z": 1,
      "name": "Plant_Leaves_Stormbark"
    },
    {
      "x": 0,
      "y": 13,
      "z": 2,
      "name": "Plant_Leaves_Stormbark"
    },
    {
      "x": 0,
      "y": 17,
      "z": 2,
      "name": "Plant_Leaves_Stormbark"
    },
    {
      "x": 0,
      "y": 18,
      "z": 2,
      "name": "Plant_Leaves_Stormbark"
    },
    {
      "x": 0,
      "y": 17,
      "z": 3,
      "name": "Plant_Leaves_Stormbark"
    },
    {
      "x": 1,
      "y": 17,
      "z": -3,
      "name": "Plant_Leaves_Stormbark"
    },
    {
      "x": 1,
      "y": 17,
      "z": -2,
      "name": "Plant_Leaves_Stormbark"
    },
    {
      "x": 1,
      "y": 18,
      "z": -2,
      "name": "Plant_Leaves_Stormbark"
    },
    {
      "x": 1,
      "y": 13,
      "z": -1,
      "name": "Plant_Leaves_Stormbark"
    },
    {
      "x": 1,
      "y": 17,
      "z": -1,
      "name": "Plant_Leaves_Stormbark"
    },
    {
      "x": 1,
      "y": 18,
      "z": -1,
      "name": "Plant_Leaves_Stormbark"
    },
    {
      "x": 1,
      "y": 8,
      "z": 0,
      "name": "Wood_Stormbark_Trunk_Full"
    },
    {
      "x": 1,
      "y": 9,
      "z": 0,
      "name": "Wood_Stormbark_Trunk"
    },
    {
      "x": 1,
      "y": 10,
      "z": 0,
      "name": "Wood_Stormbark_Trunk"
    },
    {
      "x": 1,
      "y": 11,
      "z": 0,
      "name": "Wood_Stormbark_Trunk_Full"
    },
    {
      "x": 1,
      "y": 13,
      "z": 0,
      "name": "Plant_Leaves_Stormbark"
    },
    {
      "x": 1,
      "y": 14,
      "z": 0,
      "name": "Plant_Leaves_Stormbark"
    },
    {
      "x": 1,
      "y": 17,
      "z": 0,
      "name": "Plant_Leaves_Stormbark"
    },
    {
      "x": 1,
      "y": 18,
      "z": 0,
      "name": "Plant_Leaves_Stormbark"
    },
    {
      "x": 1,
      "y": 19,
      "z": 0,
      "name": "Plant_Leaves_Stormbark"
    },
    {
      "x": 1,
      "y": 11,
      "z": 1,
      "name": "Wood_Stormbark_Trunk_Full"
    },
    {
      "x": 1,
      "y": 13,
      "z": 1,
      "name": "Plant_Leaves_Stormbark"
    },
    {
      "x": 1,
      "y": 14,
      "z": 1,
      "name": "Plant_Leaves_Stormbark"
    },
    {
      "x": 1,
      "y": 17,
      "z": 1,
      "name": "Plant_Leaves_Stormbark"
    },
    {
      "x": 1,
      "y": 18,
      "z": 1,
      "name": "Plant_Leaves_Stormbark"
    },
    {
      "x": 1,
      "y": 13,
      "z": 2,
      "name": "Plant_Leaves_Stormbark"
    },
    {
      "x": 1,
      "y": 14,
      "z": 2,
      "name": "Plant_Leaves_Stormbark"
    },
    {
      "x": 1,
      "y": 17,
      "z": 2,
      "name": "Plant_Leaves_Stormbark"
    },
    {
      "x": 1,
      "y": 18,
      "z": 2,
      "name": "Plant_Leaves_Stormbark"
    },
    {
      "x": 1,
      "y": 13,
      "z": 3,
      "name": "Plant_Leaves_Stormbark"
    },
    {
      "x": 1,
      "y": 17,
      "z": 3,
      "name": "Plant_Leaves_Stormbark"
    },
    {
      "x": 2,
      "y": 17,
      "z": -2,
      "name": "Plant_Leaves_Stormbark"
    },
    {
      "x": 2,
      "y": 13,
      "z": -1,
      "name": "Plant_Leaves_Stormbark"
    },
    {
      "x": 2,
      "y": 17,
      "z": -1,
      "name": "Plant_Leaves_Stormbark"
    },
    {
      "x": 2,
      "y": 18,
      "z": -1,
      "name": "Plant_Leaves_Stormbark"
    },
    {
      "x": 2,
      "y": 13,
      "z": 0,
      "name": "Plant_Leaves_Stormbark"
    },
    {
      "x": 2,
      "y": 14,
      "z": 0,
      "name": "Plant_Leaves_Stormbark"
    },
    {
      "x": 2,
      "y": 17,
      "z": 0,
      "name": "Plant_Leaves_Stormbark"
    },
    {
      "x": 2,
      "y": 18,
      "z": 0,
      "name": "Plant_Leaves_Stormbark"
    },
    {
      "x": 2,
      "y": 11,
      "z": 1,
      "name": "Wood_Stormbark_Branch_Corner",
      "rotation": 1
    },
    {
      "x": 2,
      "y": 12,
      "z": 1,
      "name": "Wood_Stormbark_Branch_Long"
    },
    {
      "x": 2,
      "y": 13,
      "z": 1,
      "name": "Wood_Stormbark_Branch_Long"
    },
    {
      "x": 2,
      "y": 14,
      "z": 1,
      "name": "Plant_Leaves_Stormbark"
    },
    {
      "x": 2,
      "y": 17,
      "z": 1,
      "name": "Plant_Leaves_Stormbark"
    },
    {
      "x": 2,
      "y": 18,
      "z": 1,
      "name": "Plant_Leaves_Stormbark"
    },
    {
      "x": 2,
      "y": 13,
      "z": 2,
      "name": "Plant_Leaves_Stormbark"
    },
    {
      "x": 2,
      "y": 14,
      "z": 2,
      "name": "Plant_Leaves_Stormbark"
    },
    {
      "x": 2,
      "y": 17,
      "z": 2,
      "name": "Plant_Leaves_Stormbark"
    },
    {
      "x": 2,
      "y": 13,
      "z": 3,
      "name": "Plant_Leaves_Stormbark"
    },
    {
      "x": 3,
      "y": 13,
      "z": -1,
      "name": "Plant_Leaves_Stormbark"
    },
    {
      "x": 3,
      "y": 17,
      "z": -1,
      "name": "Plant_Leaves_Stormbark"
    },
    {
      "x": 3,
      "y": 13,
      "z": 0,
      "name": "Plant_Leaves_Stormbark"
    },
    {
      "x": 3,
      "y": 14,
      "z": 0,
      "name": "Plant_Leaves_Stormbark"
    },
    {
      "x": 3,
      "y": 17,
      "z": 0,
      "name": "Plant_Leaves_Stormbark"
    },
    {
      "x": 3,
      "y": 13,
      "z": 1,
      "name": "Plant_Leaves_Stormbark"
    },
    {
      "x": 3,
      "y": 14,
      "z": 1,
      "name": "Plant_Leaves_Stormbark"
    },
    {
      "x": 3,
      "y": 17,
      "z": 1,
      "name": "Plant_Leaves_Stormbark"
    },
    {
      "x": 3,
      "y": 13,
      "z": 2,
      "name": "Plant_Leaves_Stormbark"
    },
    {
      "x": 3,
      "y": 14,
      "z": 2,
      "name": "Plant_Leaves_Stormbark"
    },
    {
      "x": 3,
      "y": 13,
      "z": 3,
      "name": "Plant_Leaves_Stormbark"
    },
    {
      "x": 4,
      "y": 13,
      "z": 0,
      "name": "Plant_Leaves_Stormbark"
    },
    {
      "x": 4,
      "y": 13,
      "z": 1,
      "name": "Plant_Leaves_Stormbark"
    },
    {
      "x": 4,
      "y": 13,
      "z": 2,
      "name": "Plant_Leaves_Stormbark"
    }
  ]
}