{
  "version": 8,
  "blockIdVersion": 10,
  "anchorX": 3,
  "anchorY": 12,
  "anchorZ": 1,
  "blocks": [
    {
      "x": -10,
      "y": 29,
      "z": -3,
      "name": "Plant_Leaves_Crystal"
    },
    {
      "x": -10,
      "y": 29,
      "z": -2,
      "name": "Plant_Leaves_Crystal"
    },
    {
      "x": -9,
      "y": 29,
      "z": -5,
      "name": "Plant_Leaves_Crystal"
    },
    {
      "x": -9,
      "y": 29,
      "z": -4,
      "name": "Plant_Leaves_Crystal"
    },
    {
      "x": -9,
      "y": 29,
      "z": -3,
      "name": "Plant_Leaves_Crystal"
    },
    {
      "x": -9,
      "y": 30,
      "z": -3,
      "name": "Plant_Leaves_Crystal"
    },
    {
      "x": -9,
      "y": 29,
      "z": -2,
      "name": "Plant_Leaves_Crystal"
    },
    {
      "x": -9,
      "y": 29,
      "z": -1,
      "name": "Plant_Leaves_Crystal"
    },
    {
      "x": -8,
      "y": 29,
      "z": -7,
      "name": "Plant_Leaves_Crystal"
    },
    {
      "x": -8,
      "y": 29,
      "z": -6,
      "name": "Plant_Leaves_Crystal"
    },
    {
      "x": -8,
      "y": 30,
      "z": -6,
      "name": "Plant_Leaves_Crystal"
    },
    {
      "x": -8,
      "y": 27,
      "z": -5,
      "name": "Plant_Leaves_Crystal"
    },
    {
      "x": -8,
      "y": 28,
      "z": -5,
      "name": "Plant_Leaves_Crystal"
    },
    {
      "x": -8,
      "y": 29,
      "z": -5,
      "name": "Plant_Leaves_Crystal"
    },
    {
      "x": -8,
      "y": 30,
      "z": -5,
      "name": "Plant_Leaves_Crystal"
    },
    {
      "x": -8,
      "y": 29,
      "z": -4,
      "name": "Plant_Leaves_Crystal"
    },
    {
      "x": -8,
      "y": 30,
      "z": -4,
      "name": "Plant_Leaves_Crystal"
    },
    {
      "x": -8,
      "y": 29,
      "z": -3,
      "name": "Plant_Leaves_Crystal"
    },
    {
      "x": -8,
      "y": 30,
      "z": -3,
      "name": "Plant_Leaves_Crystal"
    },
    {
      "x": -8,
      "y": 29,
      "z": -2,
      "name": "Plant_Leaves_Crystal"
    },
    {
      "x": -8,
      "y": 29,
      "z": -1,
      "name": "Plant_Leaves_Crystal"
    },
    {
      "x": -8,
      "y": 29,
      "z": 0,
      "name": "Plant_Leaves_Crystal"
    },
    {
      "x": -7,
      "y": 29,
      "z": -7,
      "name": "Plant_Leaves_Crystal"
    },
    {
      "x": -7,
      "y": 29,
      "z": -6,
      "name": "Plant_Leaves_Crystal"
    },
    {
      "x": -7,
      "y": 30,
      "z": -6,
      "name": "Plant_Leaves_Crystal"
    },
    {
      "x": -7,
      "y": 27,
      "z": -5,
      "name": "Plant_Leaves_Crystal"
    },
    {
      "x": -7,
      "y": 28,
      "z": -5,
      "name": "Plant_Leaves_Crystal"
    },
    {
      "x": -7,
      "y": 29,
      "z": -5,
      "name": "Plant_Leaves_Crystal"
    },
    {
      "x": -7,
      "y": 30,
      "z": -5,
      "name": "Plant_Leaves_Crystal"
    },
    {
      "x": -7,
      "y": 28,
      "z": -4,
      "name": "Plant_Fruit_Pinkberry",
      "rotation": 8
    },
    {
      "x": -7,
      "y": 29,
      "z": -4,
      "name": "Plant_Leaves_Crystal"
    },
    {
      "x": -7,
      "y": 28,
      "z": -3,
      "name": "Wood_Crystal_Branch_Corner",
      "rotation": 3
    },
    {
      "x": -7,
      "y": 29,
      "z": -3,
      "name": "Plant_Leaves_Crystal"
    },
    {
      "x": -7,
      "y": 30,
      "z": -3,
      "name": "Plant_Leaves_Crystal"
    },
    {
      "x": -7,
      "y": 31,
      "z": -3,
      "name": "Plant_Leaves_Crystal"
    },
    {
      "x": -7,
      "y": 29,
      "z": -2,
      "name": "Plant_Leaves_Crystal"
    },
    {
      "x": -7,
      "y": 30,
      "z": -2,
      "name": "Plant_Leaves_Crystal"
    },
    {
      "x": -7,
      "y": 28,
      "z": -1,
      "name": "Plant_Fruit_Pinkberry",
      "rotation": 8
    },
    {
      "x": -7,
      "y": 29,
      "z": -1,
      "name": "Plant_Leaves_Crystal"
    },
    {
      "x": -7,
      "y": 30,
      "z": -1,
      "name": "Plant_Leaves_Crystal"
    },
    {
      "x": -7,
      "y": 31,
      "z": -1,
      "name": "Plant_Leaves_Crystal"
    },
    {
      "x": -7,
      "y": 28,
      "z": 0,
      "name": "Plant_Leaves_Crystal"
    },
    {
      "x": -7,
      "y": 29,
      "z": 0,
      "name": "Plant_Leaves_Crystal"
    },
    {
      "x": -7,
      "y": 29,
      "z": 1,
      "name": "Plant_Leaves_Crystal"
    },
    {
      "x": -7,
      "y": 28,
      "z": 2,
      "name": "Plant_Leaves_Crystal"
    },
    {
      "x": -7,
      "y": 29,
      "z": 2,
      "name": "Plant_Leaves_Crystal"
    },
    {
      "x": -6,
      "y": 29,
      "z": -7,
      "name": "Plant_Leaves_Crystal"
    },
    {
      "x": -6,
      "y": 29,
      "z": -6,
      "name": "Plant_Leaves_Crystal"
    },
    {
      "x": -6,
      "y": 30,
      "z": -6,
      "name": "Plant_Leaves_Crystal"
    },
    {
      "x": -6,
      "y": 28,
      "z": -5,
      "name": "Plant_Leaves_Crystal"
    },
    {
      "x": -6,
      "y": 29,
      "z": -5,
      "name": "Plant_Leaves_Crystal"
    },
    {
      "x": -6,
      "y": 27,
      "z": -4,
      "name": "Plant_Leaves_Crystal"
    },
    {
      "x": -6,
      "y": 28,
      "z": -4,
      "name": "Plant_Leaves_Crystal"
    },
    {
      "x": -6,
      "y": 29,
      "z": -4,
      "name": "Plant_Leaves_Crystal"
    },
    {
      "x": -6,
      "y": 30,
      "z": -4,
      "name": "Plant_Leaves_Crystal"
    },
    {
      "x": -6,
      "y": 31,
      "z": -4,
      "name": "Plant_Leaves_Crystal"
    },
    {
      "x": -6,
      "y": 28,
      "z": -3,
      "name": "Wood_Crystal_Trunk_Full"
    },
    {
      "x": -6,
      "y": 29,
      "z": -3,
      "name": "Plant_Leaves_Crystal"
    },
    {
      "x": -6,
      "y": 30,
      "z": -3,
      "name": "Plant_Leaves_Crystal"
    },
    {
      "x": -6,
      "y": 31,
      "z": -3,
      "name": "Plant_Leaves_Crystal"
    },
    {
      "x": -6,
      "y": 31,
      "z": -2,
      "name": "Plant_Leaves_Crystal"
    },
    {
      "x": -6,
      "y": 29,
      "z": -1,
      "name": "Plant_Leaves_Crystal"
    },
    {
      "x": -6,
      "y": 30,
      "z": -1,
      "name": "Plant_Leaves_Crystal"
    },
    {
      "x": -6,
      "y": 28,
      "z": 0,
      "name": "Plant_Leaves_Crystal"
    },
    {
      "x": -6,
      "y": 29,
      "z": 0,
      "name": "Plant_Leaves_Crystal"
    },
    {
      "x": -6,
      "y": 30,
      "z": 0,
      "name": "Plant_Leaves_Crystal"
    },
    {
      "x": -6,
      "y": 22,
      "z": 1,
      "name": "Plant_Leaves_Crystal"
    },
    {
      "x": -6,
      "y": 28,
      "z": 1,
      "name": "Plant_Leaves_Crystal"
    },
    {
      "x": -6,
      "y": 29,
      "z": 1,
      "name": "Plant_Leaves_Crystal"
    },
    {
      "x": -6,
      "y": 30,
      "z": 1,
      "name": "Plant_Leaves_Crystal"
    },
    {
      "x": -6,
      "y": 22,
      "z": 2,
      "name": "Plant_Leaves_Crystal"
    },
    {
      "x": -6,
      "y": 28,
      "z": 2,
      "name": "Plant_Leaves_Crystal"
    },
    {
      "x": -6,
      "y": 29,
      "z": 2,
      "name": "Plant_Leaves_Crystal"
    },
    {
      "x": -6,
      "y": 28,
      "z": 3,
      "name": "Plant_Leaves_Crystal"
    },
    {
      "x": -6,
      "y": 29,
      "z": 3,
      "name": "Plant_Leaves_Crystal"
    },
    {
      "x": -6,
      "y": 29,
      "z": 4,
      "name": "Plant_Leaves_Crystal"
    },
    {
      "x": -5,
      "y": 29,
      "z": -8,
      "name": "Plant_Leaves_Crystal"
    },
    {
      "x": -5,
      "y": 28,
      "z": -7,
      "name": "Plant_Leaves_Crystal"
    },
    {
      "x": -5,
      "y": 29,
      "z": -7,
      "name": "Plant_Leaves_Crystal"
    },
    {
      "x": -5,
      "y": 30,
      "z": -7,
      "name": "Plant_Leaves_Crystal"
    },
    {
      "x": -5,
      "y": 28,
      "z": -6,
      "name": "Plant_Leaves_Crystal"
    },
    {
      "x": -5,
      "y": 29,
      "z": -6,
      "name": "Plant_Leaves_Crystal"
    },
    {
      "x": -5,
      "y": 30,
      "z": -6,
      "name": "Plant_Leaves_Crystal"
    },
    {
      "x": -5,
      "y": 29,
      "z": -5,
      "name": "Plant_Leaves_Crystal"
    },
    {
      "x": -5,
      "y": 30,
      "z": -5,
      "name": "Plant_Leaves_Crystal"
    },
    {
      "x": -5,
      "y": 28,
      "z": -4,
      "name": "Plant_Leaves_Crystal"
    },
    {
      "x": -5,
      "y": 29,
      "z": -4,
      "name": "Plant_Leaves_Crystal"
    },
    {
      "x": -5,
      "y": 30,
      "z": -4,
      "name": "Plant_Leaves_Crystal"
    },
    {
      "x": -5,
      "y": 31,
      "z": -4,
      "name": "Plant_Leaves_Crystal"
    },
    {
      "x": -5,
      "y": 32,
      "z": -4,
      "name": "Plant_Leaves_Crystal"
    },
    {
      "x": -5,
      "y": 28,
      "z": -3,
      "name": "Wood_Crystal_Trunk_Full"
    },
    {
      "x": -5,
      "y": 29,
      "z": -3,
      "name": "Plant_Leaves_Crystal"
    },
    {
      "x": -5,
      "y": 30,
      "z": -3,
      "name": "Plant_Leaves_Crystal"
    },
    {
      "x": -5,
      "y": 31,
      "z": -3,
      "name": "Plant_Leaves_Crystal"
    },
    {
      "x": -5,
      "y": 32,
      "z": -3,
      "name": "Plant_Leaves_Crystal"
    },
    {
      "x": -5,
      "y": 30,
      "z": -2,
      "name": "Plant_Leaves_Crystal"
    },
    {
      "x": -5,
      "y": 31,
      "z": -2,
      "name": "Plant_Leaves_Crystal"
    },
    {
      "x": -5,
      "y": 29,
      "z": -1,
      "name": "Plant_Leaves_Crystal"
    },
    {
      "x": -5,
      "y": 30,
      "z": -1,
      "name": "Plant_Leaves_Crystal"
    },
    {
      "x": -5,
      "y": 22,
      "z": 0,
      "name": "Plant_Leaves_Crystal"
    },
    {
      "x": -5,
      "y": 27,
      "z": 0,
      "name": "Plant_Fruit_Pinkberry",
      "rotation": 8
    },
    {
      "x": -5,
      "y": 28,
      "z": 0,
      "name": "Plant_Leaves_Crystal"
    },
    {
      "x": -5,
      "y": 30,
      "z": 0,
      "name": "Plant_Leaves_Crystal"
    },
    {
      "x": -5,
      "y": 31,
      "z": 0,
      "name": "Plant_Leaves_Crystal"
    },
    {
      "x": -5,
      "y": 22,
      "z": 1,
      "name": "Plant_Leaves_Crystal"
    },
    {
      "x": -5,
      "y": 28,
      "z": 1,
      "name": "Plant_Leaves_Crystal"
    },
    {
      "x": -5,
      "y": 29,
      "z": 1,
      "name": "Plant_Leaves_Crystal"
    },
    {
      "x": -5,
      "y": 22,
      "z": 2,
      "name": "Plant_Leaves_Crystal"
    },
    {
      "x": -5,
      "y": 28,
      "z": 2,
      "name": "Plant_Leaves_Crystal"
    },
    {
      "x": -5,
      "y": 30,
      "z": 2,
      "name": "Plant_Leaves_Crystal"
    },
    {
      "x": -5,
      "y": 20,
      "z": 3,
      "name": "Plant_Leaves_Crystal"
    },
    {
      "x": -5,
      "y": 21,
      "z": 3,
      "name": "Plant_Leaves_Crystal"
    },
    {
      "x": -5,
      "y": 22,
      "z": 3,
      "name": "Plant_Leaves_Crystal"
    },
    {
      "x": -5,
      "y": 27,
      "z": 3,
      "name": "Plant_Leaves_Crystal"
    },
    {
      "x": -5,
      "y": 28,
      "z": 3,
      "name": "Plant_Leaves_Crystal"
    },
    {
      "x": -5,
      "y": 29,
      "z": 3,
      "name": "Plant_Leaves_Crystal"
    },
    {
      "x": -5,
      "y": 27,
      "z": 4,
      "name": "Plant_Leaves_Crystal"
    },
    {
      "x": -5,
      "y": 28,
      "z": 4,
      "name": "Plant_Leaves_Crystal"
    },
    {
      "x": -5,
      "y": 29,
      "z": 4,
      "name": "Plant_Leaves_Crystal"
    },
    {
      "x": -5,
      "y": 27,
      "z": 5,
      "name": "Plant_Leaves_Crystal"
    },
    {
      "x": -5,
      "y": 29,
      "z": 5,
      "name": "Plant_Leaves_Crystal"
    },
    {
      "x": -5,
      "y": 29,
      "z": 6,
      "name": "Plant_Leaves_Crystal"
    },
    {
      "x": -4,
      "y": 29,
      "z": -9,
      "name": "Plant_Leaves_Crystal"
    },
    {
      "x": -4,
      "y": 28,
      "z": -8,
      "name": "Plant_Leaves_Crystal"
    },
    {
      "x": -4,
      "y": 29,
      "z": -8,
      "name": "Plant_Leaves_Crystal"
    },
    {
      "x": -4,
      "y": 28,
      "z": -7,
      "name": "Plant_Leaves_Crystal"
    },
    {
      "x": -4,
      "y": 29,
      "z": -7,
      "name": "Plant_Leaves_Crystal"
    },
    {
      "x": -4,
      "y": 30,
      "z": -7,
      "name": "Plant_Leaves_Crystal"
    },
    {
      "x": -4,
      "y": 28,
      "z": -6,
      "name": "Plant_Leaves_Crystal"
    },
    {
      "x": -4,
      "y": 29,
      "z": -6,
      "name": "Plant_Leaves_Crystal"
    },
    {
      "x": -4,
      "y": 30,
      "z": -6,
      "name": "Plant_Leaves_Crystal"
    },
    {
      "x": -4,
      "y": 31,
      "z": -6,
      "name": "Plant_Leaves_Crystal"
    },
    {
      "x": -4,
      "y": 27,
      "z": -5,
      "name": "Plant_Fruit_Pinkberry",
      "rotation": 8
    },
    {
      "x": -4,
      "y": 28,
      "z": -5,
      "name": "Plant_Leaves_Crystal"
    },
    {
      "x": -4,
      "y": 29,
      "z": -5,
      "name": "Plant_Leaves_Crystal"
    },
    {
      "x": -4,
      "y": 30,
      "z": -5,
      "name": "Plant_Leaves_Crystal"
    },
    {
      "x": -4,
      "y": 31,
      "z": -5,
      "name": "Plant_Leaves_Crystal"
    },
    {
      "x": -4,
      "y": 28,
      "z": -4,
      "name": "Plant_Leaves_Crystal"
    },
    {
      "x": -4,
      "y": 29,
      "z": -4,
      "name": "Plant_Leaves_Crystal"
    },
    {
      "x": -4,
      "y": 30,
      "z": -4,
      "name": "Plant_Leaves_Crystal"
    },
    {
      "x": -4,
      "y": 31,
      "z": -4,
      "name": "Plant_Leaves_Crystal"
    },
    {
      "x": -4,
      "y": 28,
      "z": -3,
      "name": "Wood_Crystal_Trunk_Full"
    },
    {
      "x": -4,
      "y": 29,
      "z": -3,
      "name": "Plant_Leaves_Crystal"
    },
    {
      "x": -4,
      "y": 31,
      "z": -3,
      "name": "Plant_Leaves_Crystal"
    },
    {
      "x": -4,
      "y": 28,
      "z": -2,
      "name": "Wood_Crystal_Trunk_Full"
    },
    {
      "x": -4,
      "y": 29,
      "z": -2,
      "name": "Plant_Leaves_Crystal"
    },
    {
      "x": -4,
      "y": 30,
      "z": -2,
      "name": "Plant_Leaves_Crystal"
    },
    {
      "x": -4,
      "y": 31,
      "z": -2,
      "name": "Plant_Leaves_Crystal"
    },
    {
      "x": -4,
      "y": 32,
      "z": -2,
      "name": "Plant_Leaves_Crystal"
    },
    {
      "x": -4,
      "y": 21,
      "z": -1,
      "name": "Plant_Leaves_Crystal"
    },
    {
      "x": -4,
      "y": 22,
      "z": -1,
      "name": "Plant_Leaves_Crystal"
    },
    {
      "x": -4,
      "y": 29,
      "z": -1,
      "name": "Plant_Leaves_Crystal"
    },
    {
      "x": -4,
      "y": 30,
      "z": -1,
      "name": "Plant_Leaves_Crystal"
    },
    {
      "x": -4,
      "y": 31,
      "z": -1,
      "name": "Plant_Leaves_Crystal"
    },
    {
      "x": -4,
      "y": 22,
      "z": 0,
      "name": "Plant_Leaves_Crystal"
    },
    {
      "x": -4,
      "y": 27,
      "z": 0,
      "name": "Wood_Crystal_Roots"
    },
    {
      "x": -4,
      "y": 28,
      "z": 0,
      "name": "Wood_Crystal_Trunk_Full"
    },
    {
      "x": -4,
      "y": 29,
      "z": 0,
      "name": "Plant_Leaves_Crystal"
    },
    {
      "x": -4,
      "y": 30,
      "z": 0,
      "name": "Plant_Leaves_Crystal"
    },
    {
      "x": -4,
      "y": 31,
      "z": 0,
      "name": "Plant_Leaves_Crystal"
    },
    {
      "x": -4,
      "y": 21,
      "z": 1,
      "name": "Plant_Leaves_Crystal"
    },
    {
      "x": -4,
      "y": 22,
      "z": 1,
      "name": "Plant_Leaves_Crystal"
    },
    {
      "x": -4,
      "y": 28,
      "z": 1,
      "name": "Wood_Crystal_Trunk_Full"
    },
    {
      "x": -4,
      "y": 29,
      "z": 1,
      "name": "Plant_Leaves_Crystal"
    },
    {
      "x": -4,
      "y": 30,
      "z": 1,
      "name": "Plant_Leaves_Crystal"
    },
    {
      "x": -4,
      "y": 31,
      "z": 1,
      "name": "Plant_Leaves_Crystal"
    },
    {
      "x": -4,
      "y": 21,
      "z": 2,
      "name": "Plant_Leaves_Crystal"
    },
    {
      "x": -4,
      "y": 22,
      "z": 2,
      "name": "Plant_Leaves_Crystal"
    },
    {
      "x": -4,
      "y": 28,
      "z": 2,
      "name": "Wood_Crystal_Branch_Corner"
    },
    {
      "x": -4,
      "y": 30,
      "z": 2,
      "name": "Plant_Leaves_Crystal"
    },
    {
      "x": -4,
      "y": 22,
      "z": 3,
      "name": "Plant_Leaves_Crystal"
    },
    {
      "x": -4,
      "y": 28,
      "z": 3,
      "name": "Plant_Leaves_Crystal"
    },
    {
      "x": -4,
      "y": 29,
      "z": 3,
      "name": "Plant_Leaves_Crystal"
    },
    {
      "x": -4,
      "y": 30,
      "z": 3,
      "name": "Plant_Leaves_Crystal"
    },
    {
      "x": -4,
      "y": 25,
      "z": 4,
      "name": "Plant_Leaves_Crystal"
    },
    {
      "x": -4,
      "y": 26,
      "z": 4,
      "name": "Plant_Leaves_Crystal"
    },
    {
      "x": -4,
      "y": 27,
      "z": 4,
      "name": "Plant_Leaves_Crystal"
    },
    {
      "x": -4,
      "y": 28,
      "z": 4,
      "name": "Plant_Leaves_Crystal"
    },
    {
      "x": -4,
      "y": 29,
      "z": 4,
      "name": "Plant_Leaves_Crystal"
    },
    {
      "x": -4,
      "y": 26,
      "z": 5,
      "name": "Plant_Leaves_Crystal"
    },
    {
      "x": -4,
      "y": 27,
      "z": 5,
      "name": "Plant_Leaves_Crystal"
    },
    {
      "x": -4,
      "y": 28,
      "z": 5,
      "name": "Plant_Leaves_Crystal"
    },
    {
      "x": -4,
      "y": 29,
      "z": 5,
      "name": "Plant_Leaves_Crystal"
    },
    {
      "x": -4,
      "y": 30,
      "z": 5,
      "name": "Plant_Leaves_Crystal"
    },
    {
      "x": -4,
      "y": 28,
      "z": 6,
      "name": "Plant_Leaves_Crystal"
    },
    {
      "x": -4,
      "y": 29,
      "z": 6,
      "name": "Plant_Leaves_Crystal"
    },
    {
      "x": -3,
      "y": 29,
      "z": -10,
      "name": "Plant_Leaves_Crystal"
    },
    {
      "x": -3,
      "y": 28,
      "z": -9,
      "name": "Plant_Leaves_Crystal"
    },
    {
      "x": -3,
      "y": 29,
      "z": -9,
      "name": "Plant_Leaves_Crystal"
    },
    {
      "x": -3,
      "y": 30,
      "z": -9,
      "name": "Plant_Leaves_Crystal"
    },
    {
      "x": -3,
      "y": 29,
      "z": -8,
      "name": "Plant_Leaves_Crystal"
    },
    {
      "x": -3,
      "y": 30,
      "z": -8,
      "name": "Plant_Leaves_Crystal"
    },
    {
      "x": -3,
      "y": 29,
      "z": -7,
      "name": "Plant_Leaves_Crystal"
    },
    {
      "x": -3,
      "y": 30,
      "z": -7,
      "name": "Plant_Leaves_Crystal"
    },
    {
      "x": -3,
      "y": 29,
      "z": -6,
      "name": "Plant_Leaves_Crystal"
    },
    {
      "x": -3,
      "y": 31,
      "z": -6,
      "name": "Plant_Leaves_Crystal"
    },
    {
      "x": -3,
      "y": 28,
      "z": -5,
      "name": "Plant_Leaves_Crystal"
    },
    {
      "x": -3,
      "y": 30,
      "z": -5,
      "name": "Plant_Leaves_Crystal"
    },
    {
      "x": -3,
      "y": 31,
      "z": -5,
      "name": "Plant_Leaves_Crystal"
    },
    {
      "x": -3,
      "y": 28,
      "z": -4,
      "name": "Plant_Leaves_Crystal"
    },
    {
      "x": -3,
      "y": 29,
      "z": -4,
      "name": "Plant_Leaves_Crystal"
    },
    {
      "x": -3,
      "y": 30,
      "z": -4,
      "name": "Plant_Leaves_Crystal"
    },
    {
      "x": -3,
      "y": 31,
      "z": -4,
      "name": "Plant_Leaves_Crystal"
    },
    {
      "x": -3,
      "y": 32,
      "z": -4,
      "name": "Plant_Leaves_Crystal"
    },
    {
      "x": -3,
      "y": 28,
      "z": -3,
      "name": "Plant_Leaves_Crystal"
    },
    {
      "x": -3,
      "y": 29,
      "z": -3,
      "name": "Plant_Leaves_Crystal"
    },
    {
      "x": -3,
      "y": 31,
      "z": -3,
      "name": "Plant_Leaves_Crystal"
    },
    {
      "x": -3,
      "y": 21,
      "z": -2,
      "name": "Plant_Fruit_Pinkberry",
      "rotation": 8
    },
    {
      "x": -3,
      "y": 22,
      "z": -2,
      "name": "Plant_Leaves_Crystal"
    },
    {
      "x": -3,
      "y": 28,
      "z": -2,
      "name": "Wood_Crystal_Trunk_Full"
    },
    {
      "x": -3,
      "y": 30,
      "z": -2,
      "name": "Plant_Leaves_Crystal"
    },
    {
      "x": -3,
      "y": 31,
      "z": -2,
      "name": "Plant_Leaves_Crystal"
    },
    {
      "x": -3,
      "y": 22,
      "z": -1,
      "name": "Plant_Leaves_Crystal"
    },
    {
      "x": -3,
      "y": 28,
      "z": -1,
      "name": "Wood_Crystal_Trunk_Full"
    },
    {
      "x": -3,
      "y": 30,
      "z": -1,
      "name": "Plant_Leaves_Crystal"
    },
    {
      "x": -3,
      "y": 31,
      "z": -1,
      "name": "Plant_Leaves_Crystal"
    },
    {
      "x": -3,
      "y": 20,
      "z": 0,
      "name": "Plant_Fruit_Pinkberry",
      "rotation": 8
    },
    {
      "x": -3,
      "y": 21,
      "z": 0,
      "name": "Plant_Leaves_Crystal"
    },
    {
      "x": -3,
      "y": 22,
      "z": 0,
      "name": "Plant_Leaves_Crystal"
    },
    {
      "x": -3,
      "y": 27,
      "z": 0,
      "name": "Wood_Crystal_Roots"
    },
    {
      "x": -3,
      "y": 28,
      "z": 0,
      "name": "Wood_Crystal_Trunk_Full"
    },
    {
      "x": -3,
      "y": 29,
      "z": 0,
      "name": "Plant_Leaves_Crystal"
    },
    {
      "x": -3,
      "y": 30,
      "z": 0,
      "name": "Plant_Leaves_Crystal"
    },
    {
      "x": -3,
      "y": 31,
      "z": 0,
      "name": "Plant_Leaves_Crystal"
    },
    {
      "x": -3,
      "y": 21,
      "z": 1,
      "name": "Plant_Leaves_Crystal"
    },
    {
      "x": -3,
      "y": 22,
      "z": 1,
      "name": "Plant_Leaves_Crystal"
    },
    {
      "x": -3,
      "y": 23,
      "z": 1,
      "name": "Plant_Leaves_Crystal"
    },
    {
      "x": -3,
      "y": 28,
      "z": 1,
      "name": "Plant_Fruit_Pinkberry",
      "rotation": 8
    },
    {
      "x": -3,
      "y": 29,
      "z": 1,
      "name": "Plant_Leaves_Crystal"
    },
    {
      "x": -3,
      "y": 30,
      "z": 1,
      "name": "Plant_Leaves_Crystal"
    },
    {
      "x": -3,
      "y": 31,
      "z": 1,
      "name": "Plant_Leaves_Crystal"
    },
    {
      "x": -3,
      "y": 21,
      "z": 2,
      "name": "Wood_Crystal_Trunk_Full"
    },
    {
      "x": -3,
      "y": 22,
      "z": 2,
      "name": "Plant_Leaves_Crystal"
    },
    {
      "x": -3,
      "y": 23,
      "z": 2,
      "name": "Plant_Leaves_Crystal"
    },
    {
      "x": -3,
      "y": 28,
      "z": 2,
      "name": "Plant_Leaves_Crystal"
    },
    {
      "x": -3,
      "y": 30,
      "z": 2,
      "name": "Plant_Leaves_Crystal"
    },
    {
      "x": -3,
      "y": 31,
      "z": 2,
      "name": "Plant_Leaves_Crystal"
    },
    {
      "x": -3,
      "y": 22,
      "z": 3,
      "name": "Plant_Leaves_Crystal"
    },
    {
      "x": -3,
      "y": 28,
      "z": 3,
      "name": "Plant_Leaves_Crystal"
    },
    {
      "x": -3,
      "y": 29,
      "z": 3,
      "name": "Plant_Leaves_Crystal"
    },
    {
      "x": -3,
      "y": 30,
      "z": 3,
      "name": "Plant_Leaves_Crystal"
    },
    {
      "x": -3,
      "y": 31,
      "z": 3,
      "name": "Plant_Leaves_Crystal"
    },
    {
      "x": -3,
      "y": 21,
      "z": 4,
      "name": "Plant_Leaves_Crystal"
    },
    {
      "x": -3,
      "y": 22,
      "z": 4,
      "name": "Plant_Leaves_Crystal"
    },
    {
      "x": -3,
      "y": 27,
      "z": 4,
      "name": "Plant_Leaves_Crystal"
    },
    {
      "x": -3,
      "y": 28,
      "z": 4,
      "name": "Plant_Leaves_Crystal"
    },
    {
      "x": -3,
      "y": 29,
      "z": 4,
      "name": "Plant_Leaves_Crystal"
    },
    {
      "x": -3,
      "y": 28,
      "z": 5,
      "name": "Plant_Leaves_Crystal"
    },
    {
      "x": -3,
      "y": 29,
      "z": 5,
      "name": "Plant_Leaves_Crystal"
    },
    {
      "x": -3,
      "y": 30,
      "z": 5,
      "name": "Plant_Leaves_Crystal"
    },
    {
      "x": -3,
      "y": 27,
      "z": 6,
      "name": "Plant_Fruit_Pinkberry",
      "rotation": 8
    },
    {
      "x": -3,
      "y": 28,
      "z": 6,
      "name": "Plant_Leaves_Crystal"
    },
    {
      "x": -3,
      "y": 29,
      "z": 6,
      "name": "Plant_Leaves_Crystal"
    },
    {
      "x": -3,
      "y": 28,
      "z": 8,
      "name": "Plant_Leaves_Crystal"
    },
    {
      "x": -3,
      "y": 29,
      "z": 8,
      "name": "Plant_Leaves_Crystal"
    },
    {
      "x": -3,
      "y": 29,
      "z": 9,
      "name": "Plant_Leaves_Crystal"
    },
    {
      "x": -3,
      "y": 29,
      "z": 10,
      "name": "Plant_Leaves_Crystal"
    },
    {
      "x": -3,
      "y": 29,
      "z": 11,
      "name": "Plant_Leaves_Crystal"
    },
    {
      "x": -3,
      "y": 29,
      "z": 12,
      "name": "Plant_Leaves_Crystal"
    },
    {
      "x": -2,
      "y": 29,
      "z": -10,
      "name": "Plant_Leaves_Crystal"
    },
    {
      "x": -2,
      "y": 29,
      "z": -9,
      "name": "Plant_Leaves_Crystal"
    },
    {
      "x": -2,
      "y": 29,
      "z": -8,
      "name": "Plant_Leaves_Crystal"
    },
    {
      "x": -2,
      "y": 30,
      "z": -8,
      "name": "Plant_Leaves_Crystal"
    },
    {
      "x": -2,
      "y": 29,
      "z": -7,
      "name": "Plant_Leaves_Crystal"
    },
    {
      "x": -2,
      "y": 30,
      "z": -7,
      "name": "Plant_Leaves_Crystal"
    },
    {
      "x": -2,
      "y": 28,
      "z": -6,
      "name": "Wood_Crystal_Trunk_Full"
    },
    {
      "x": -2,
      "y": 29,
      "z": -6,
      "name": "Plant_Leaves_Crystal"
    },
    {
      "x": -2,
      "y": 30,
      "z": -6,
      "name": "Plant_Leaves_Crystal"
    },
    {
      "x": -2,
      "y": 31,
      "z": -6,
      "name": "Plant_Leaves_Crystal"
    },
    {
      "x": -2,
      "y": 32,
      "z": -6,
      "name": "Plant_Leaves_Crystal"
    },
    {
      "x": -2,
      "y": 28,
      "z": -5,
      "name": "Wood_Crystal_Trunk_Full"
    },
    {
      "x": -2,
      "y": 29,
      "z": -5,
      "name": "Plant_Leaves_Crystal"
    },
    {
      "x": -2,
      "y": 30,
      "z": -5,
      "name": "Plant_Leaves_Crystal"
    },
    {
      "x": -2,
      "y": 31,
      "z": -5,
      "name": "Plant_Leaves_Crystal"
    },
    {
      "x": -2,
      "y": 32,
      "z": -5,
      "name": "Plant_Leaves_Crystal"
    },
    {
      "x": -2,
      "y": 24,
      "z": -4,
      "name": "Plant_Leaves_Crystal"
    },
    {
      "x": -2,
      "y": 25,
      "z": -4,
      "name": "Plant_Leaves_Crystal"
    },
    {
      "x": -2,
      "y": 26,
      "z": -4,
      "name": "Plant_Leaves_Crystal"
    },
    {
      "x": -2,
      "y": 27,
      "z": -4,
      "name": "Plant_Leaves_Crystal"
    },
    {
      "x": -2,
      "y": 28,
      "z": -4,
      "name": "Wood_Crystal_Trunk_Full"
    },
    {
      "x": -2,
      "y": 31,
      "z": -4,
      "name": "Plant_Leaves_Crystal"
    },
    {
      "x": -2,
      "y": 22,
      "z": -3,
      "name": "Plant_Leaves_Crystal"
    },
    {
      "x": -2,
      "y": 28,
      "z": -3,
      "name": "Wood_Crystal_Trunk_Full"
    },
    {
      "x": -2,
      "y": 22,
      "z": -2,
      "name": "Plant_Leaves_Crystal"
    },
    {
      "x": -2,
      "y": 27,
      "z": -2,
      "name": "Wood_Crystal_Trunk_Full"
    },
    {
      "x": -2,
      "y": 28,
      "z": -2,
      "name": "Wood_Crystal_Trunk_Full"
    },
    {
      "x": -2,
      "y": 30,
      "z": -2,
      "name": "Plant_Leaves_Crystal"
    },
    {
      "x": -2,
      "y": 21,
      "z": -1,
      "name": "Plant_Fruit_Pinkberry",
      "rotation": 8
    },
    {
      "x": -2,
      "y": 22,
      "z": -1,
      "name": "Plant_Leaves_Crystal"
    },
    {
      "x": -2,
      "y": 23,
      "z": -1,
      "name": "Plant_Leaves_Crystal"
    },
    {
      "x": -2,
      "y": 27,
      "z": -1,
      "name": "Wood_Crystal_Trunk_Full"
    },
    {
      "x": -2,
      "y": 28,
      "z": -1,
      "name": "Wood_Crystal_Trunk_Full"
    },
    {
      "x": -2,
      "y": 30,
      "z": -1,
      "name": "Plant_Leaves_Crystal"
    },
    {
      "x": -2,
      "y": 22,
      "z": 0,
      "name": "Plant_Leaves_Crystal"
    },
    {
      "x": -2,
      "y": 28,
      "z": 0,
      "name": "Wood_Crystal_Trunk_Full"
    },
    {
      "x": -2,
      "y": 31,
      "z": 0,
      "name": "Plant_Leaves_Crystal"
    },
    {
      "x": -2,
      "y": 22,
      "z": 1,
      "name": "Plant_Leaves_Crystal"
    },
    {
      "x": -2,
      "y": 23,
      "z": 1,
      "name": "Plant_Leaves_Crystal"
    },
    {
      "x": -2,
      "y": 30,
      "z": 1,
      "name": "Plant_Leaves_Crystal"
    },
    {
      "x": -2,
      "y": 31,
      "z": 1,
      "name": "Plant_Leaves_Crystal"
    },
    {
      "x": -2,
      "y": 21,
      "z": 2,
      "name": "Wood_Crystal_Trunk_Full"
    },
    {
      "x": -2,
      "y": 22,
      "z": 2,
      "name": "Plant_Leaves_Crystal"
    },
    {
      "x": -2,
      "y": 23,
      "z": 2,
      "name": "Plant_Leaves_Crystal"
    },
    {
      "x": -2,
      "y": 27,
      "z": 2,
      "name": "Plant_Leaves_Crystal"
    },
    {
      "x": -2,
      "y": 28,
      "z": 2,
      "name": "Plant_Leaves_Crystal"
    },
    {
      "x": -2,
      "y": 30,
      "z": 2,
      "name": "Plant_Leaves_Crystal"
    },
    {
      "x": -2,
      "y": 9,
      "z": 3,
      "name": "Wood_Crystal_Trunk"
    },
    {
      "x": -2,
      "y": 10,
      "z": 3,
      "name": "Wood_Crystal_Trunk"
    },
    {
      "x": -2,
      "y": 11,
      "z": 3,
      "name": "Wood_Crystal_Trunk_Full"
    },
    {
      "x": -2,
      "y": 21,
      "z": 3,
      "name": "Plant_Leaves_Crystal"
    },
    {
      "x": -2,
      "y": 22,
      "z": 3,
      "name": "Plant_Leaves_Crystal"
    },
    {
      "x": -2,
      "y": 27,
      "z": 3,
      "name": "Wood_Crystal_Trunk_Full"
    },
    {
      "x": -2,
      "y": 28,
      "z": 3,
      "name": "Plant_Leaves_Crystal"
    },
    {
      "x": -2,
      "y": 29,
      "z": 3,
      "name": "Plant_Leaves_Crystal"
    },
    {
      "x": -2,
      "y": 30,
      "z": 3,
      "name": "Plant_Leaves_Crystal"
    },
    {
      "x": -2,
      "y": 9,
      "z": 4,
      "name": "Wood_Crystal_Trunk"
    },
    {
      "x": -2,
      "y": 10,
      "z": 4,
      "name": "Wood_Crystal_Trunk_Full"
    },
    {
      "x": -2,
      "y": 22,
      "z": 4,
      "name": "Plant_Leaves_Crystal"
    },
    {
      "x": -2,
      "y": 27,
      "z": 4,
      "name": "Plant_Leaves_Crystal"
    },
    {
      "x": -2,
      "y": 28,
      "z": 4,
      "name": "Plant_Leaves_Crystal"
    },
    {
      "x": -2,
      "y": 29,
      "z": 4,
      "name": "Plant_Leaves_Crystal"
    },
    {
      "x": -2,
      "y": 30,
      "z": 4,
      "name": "Plant_Leaves_Crystal"
    },
    {
      "x": -2,
      "y": 31,
      "z": 4,
      "name": "Plant_Leaves_Crystal"
    },
    {
      "x": -2,
      "y": 22,
      "z": 5,
      "name": "Plant_Leaves_Crystal"
    },
    {
      "x": -2,
      "y": 27,
      "z": 5,
      "name": "Plant_Leaves_Crystal"
    },
    {
      "x": -2,
      "y": 28,
      "z": 5,
      "name": "Plant_Leaves_Crystal"
    },
    {
      "x": -2,
      "y": 29,
      "z": 5,
      "name": "Plant_Leaves_Crystal"
    },
    {
      "x": -2,
      "y": 30,
      "z": 5,
      "name": "Plant_Leaves_Crystal"
    },
    {
      "x": -2,
      "y": 28,
      "z": 6,
      "name": "Plant_Leaves_Crystal"
    },
    {
      "x": -2,
      "y": 29,
      "z": 6,
      "name": "Plant_Leaves_Crystal"
    },
    {
      "x": -2,
      "y": 28,
      "z": 7,
      "name": "Plant_Leaves_Crystal"
    },
    {
      "x": -2,
      "y": 29,
      "z": 7,
      "name": "Plant_Leaves_Crystal"
    },
    {
      "x": -2,
      "y": 28,
      "z": 8,
      "name": "Plant_Leaves_Crystal"
    },
    {
      "x": -2,
      "y": 29,
      "z": 8,
      "name": "Plant_Leaves_Crystal"
    },
    {
      "x": -2,
      "y": 30,
      "z": 8,
      "name": "Plant_Leaves_Crystal"
    },
    {
      "x": -2,
      "y": 28,
      "z": 9,
      "name": "Plant_Leaves_Crystal"
    },
    {
      "x": -2,
      "y": 29,
      "z": 9,
      "name": "Plant_Leaves_Crystal"
    },
    {
      "x": -2,
      "y": 30,
      "z": 9,
      "name": "Plant_Leaves_Crystal"
    },
    {
      "x": -2,
      "y": 29,
      "z": 10,
      "name": "Plant_Leaves_Crystal"
    },
    {
      "x": -2,
      "y": 30,
      "z": 10,
      "name": "Plant_Leaves_Crystal"
    },
    {
      "x": -2,
      "y": 29,
      "z": 11,
      "name": "Plant_Leaves_Crystal"
    },
    {
      "x": -2,
      "y": 30,
      "z": 11,
      "name": "Plant_Leaves_Crystal"
    },
    {
      "x": -2,
      "y": 29,
      "z": 12,
      "name": "Plant_Leaves_Crystal"
    },
    {
      "x": -2,
      "y": 30,
      "z": 12,
      "name": "Plant_Leaves_Crystal"
    },
    {
      "x": -1,
      "y": 27,
      "z": -9,
      "name": "Plant_Leaves_Crystal"
    },
    {
      "x": -1,
      "y": 29,
      "z": -9,
      "name": "Plant_Leaves_Crystal"
    },
    {
      "x": -1,
      "y": 25,
      "z": -8,
      "name": "Plant_Leaves_Crystal"
    },
    {
      "x": -1,
      "y": 26,
      "z": -8,
      "name": "Plant_Leaves_Crystal"
    },
    {
      "x": -1,
      "y": 27,
      "z": -8,
      "name": "Plant_Leaves_Crystal"
    },
    {
      "x": -1,
      "y": 28,
      "z": -8,
      "name": "Plant_Leaves_Crystal"
    },
    {
      "x": -1,
      "y": 29,
      "z": -8,
      "name": "Plant_Leaves_Crystal"
    },
    {
      "x": -1,
      "y": 30,
      "z": -8,
      "name": "Plant_Leaves_Crystal"
    },
    {
      "x": -1,
      "y": 26,
      "z": -7,
      "name": "Plant_Fruit_Pinkberry",
      "rotation": 8
    },
    {
      "x": -1,
      "y": 27,
      "z": -7,
      "name": "Plant_Leaves_Crystal"
    },
    {
      "x": -1,
      "y": 28,
      "z": -7,
      "name": "Plant_Leaves_Crystal"
    },
    {
      "x": -1,
      "y": 29,
      "z": -7,
      "name": "Plant_Leaves_Crystal"
    },
    {
      "x": -1,
      "y": 30,
      "z": -7,
      "name": "Plant_Leaves_Crystal"
    },
    {
      "x": -1,
      "y": 31,
      "z": -7,
      "name": "Plant_Leaves_Crystal"
    },
    {
      "x": -1,
      "y": 28,
      "z": -6,
      "name": "Plant_Leaves_Crystal"
    },
    {
      "x": -1,
      "y": 29,
      "z": -6,
      "name": "Plant_Leaves_Crystal"
    },
    {
      "x": -1,
      "y": 30,
      "z": -6,
      "name": "Plant_Leaves_Crystal"
    },
    {
      "x": -1,
      "y": 31,
      "z": -6,
      "name": "Plant_Leaves_Crystal"
    },
    {
      "x": -1,
      "y": 27,
      "z": -5,
      "name": "Plant_Leaves_Crystal"
    },
    {
      "x": -1,
      "y": 28,
      "z": -5,
      "name": "Wood_Crystal_Trunk_Full"
    },
    {
      "x": -1,
      "y": 29,
      "z": -5,
      "name": "Plant_Leaves_Crystal"
    },
    {
      "x": -1,
      "y": 30,
      "z": -5,
      "name": "Plant_Leaves_Crystal"
    },
    {
      "x": -1,
      "y": 31,
      "z": -5,
      "name": "Plant_Leaves_Crystal"
    },
    {
      "x": -1,
      "y": 21,
      "z": -4,
      "name": "Plant_Leaves_Crystal"
    },
    {
      "x": -1,
      "y": 22,
      "z": -4,
      "name": "Plant_Leaves_Crystal"
    },
    {
      "x": -1,
      "y": 27,
      "z": -4,
      "name": "Plant_Leaves_Crystal"
    },
    {
      "x": -1,
      "y": 28,
      "z": -4,
      "name": "Plant_Leaves_Crystal"
    },
    {
      "x": -1,
      "y": 30,
      "z": -4,
      "name": "Plant_Leaves_Crystal"
    },
    {
      "x": -1,
      "y": 31,
      "z": -4,
      "name": "Plant_Leaves_Crystal"
    },
    {
      "x": -1,
      "y": 22,
      "z": -3,
      "name": "Plant_Leaves_Crystal"
    },
    {
      "x": -1,
      "y": 28,
      "z": -3,
      "name": "Plant_Leaves_Crystal"
    },
    {
      "x": -1,
      "y": 21,
      "z": -2,
      "name": "Wood_Crystal_Branch_Corner",
      "rotation": 3
    },
    {
      "x": -1,
      "y": 22,
      "z": -2,
      "name": "Plant_Leaves_Crystal"
    },
    {
      "x": -1,
      "y": 23,
      "z": -2,
      "name": "Plant_Leaves_Crystal"
    },
    {
      "x": -1,
      "y": 30,
      "z": -2,
      "name": "Plant_Leaves_Crystal"
    },
    {
      "x": -1,
      "y": 31,
      "z": -2,
      "name": "Plant_Leaves_Crystal"
    },
    {
      "x": -1,
      "y": 22,
      "z": -1,
      "name": "Plant_Leaves_Crystal"
    },
    {
      "x": -1,
      "y": 27,
      "z": -1,
      "name": "Wood_Crystal_Trunk_Full"
    },
    {
      "x": -1,
      "y": 28,
      "z": -1,
      "name": "Wood_Crystal_Trunk_Full"
    },
    {
      "x": -1,
      "y": 30,
      "z": -1,
      "name": "Plant_Leaves_Crystal"
    },
    {
      "x": -1,
      "y": 22,
      "z": 0,
      "name": "Plant_Leaves_Crystal"
    },
    {
      "x": -1,
      "y": 12,
      "z": 1,
      "name": "Wood_Crystal_Trunk"
    },
    {
      "x": -1,
      "y": 13,
      "z": 1,
      "name": "Wood_Crystal_Trunk"
    },
    {
      "x": -1,
      "y": 14,
      "z": 1,
      "name": "Wood_Crystal_Trunk_Full"
    },
    {
      "x": -1,
      "y": 22,
      "z": 1,
      "name": "Plant_Leaves_Crystal"
    },
    {
      "x": -1,
      "y": 23,
      "z": 1,
      "name": "Plant_Leaves_Crystal"
    },
    {
      "x": -1,
      "y": 9,
      "z": 2,
      "name": "Wood_Crystal_Roots"
    },
    {
      "x": -1,
      "y": 10,
      "z": 2,
      "name": "Wood_Crystal_Trunk"
    },
    {
      "x": -1,
      "y": 11,
      "z": 2,
      "name": "Wood_Crystal_Trunk"
    },
    {
      "x": -1,
      "y": 12,
      "z": 2,
      "name": "Wood_Crystal_Trunk"
    },
    {
      "x": -1,
      "y": 13,
      "z": 2,
      "name": "Wood_Crystal_Trunk"
    },
    {
      "x": -1,
      "y": 14,
      "z": 2,
      "name": "Wood_Crystal_Trunk_Full"
    },
    {
      "x": -1,
      "y": 21,
      "z": 2,
      "name": "Wood_Crystal_Trunk_Full"
    },
    {
      "x": -1,
      "y": 22,
      "z": 2,
      "name": "Plant_Leaves_Crystal"
    },
    {
      "x": -1,
      "y": 23,
      "z": 2,
      "name": "Plant_Leaves_Crystal"
    },
    {
      "x": -1,
      "y": 28,
      "z": 2,
      "name": "Plant_Leaves_Crystal"
    },
    {
      "x": -1,
      "y": 8,
      "z": 3,
      "name": "Wood_Crystal_Roots"
    },
    {
      "x": -1,
      "y": 9,
      "z": 3,
      "name": "Wood_Crystal_Trunk"
    },
    {
      "x": -1,
      "y": 10,
      "z": 3,
      "name": "Wood_Crystal_Trunk"
    },
    {
      "x": -1,
      "y": 11,
      "z": 3,
      "name": "Wood_Crystal_Trunk"
    },
    {
      "x": -1,
      "y": 12,
      "z": 3,
      "name": "Wood_Crystal_Trunk"
    },
    {
      "x": -1,
      "y": 13,
      "z": 3,
      "name": "Wood_Crystal_Trunk_Full"
    },
    {
      "x": -1,
      "y": 21,
      "z": 3,
      "name": "Wood_Crystal_Trunk_Full"
    },
    {
      "x": -1,
      "y": 22,
      "z": 3,
      "name": "Plant_Leaves_Crystal"
    },
    {
      "x": -1,
      "y": 23,
      "z": 3,
      "name": "Plant_Leaves_Crystal"
    },
    {
      "x": -1,
      "y": 27,
      "z": 3,
      "name": "Wood_Crystal_Trunk_Full"
    },
    {
      "x": -1,
      "y": 28,
      "z": 3,
      "name": "Plant_Leaves_Crystal"
    },
    {
      "x": -1,
      "y": 29,
      "z": 3,
      "name": "Plant_Leaves_Crystal"
    },
    {
      "x": -1,
      "y": 30,
      "z": 3,
      "name": "Plant_Leaves_Crystal"
    },
    {
      "x": -1,
      "y": 31,
      "z": 3,
      "name": "Plant_Leaves_Crystal"
    },
    {
      "x": -1,
      "y": 9,
      "z": 4,
      "name": "Wood_Crystal_Trunk"
    },
    {
      "x": -1,
      "y": 10,
      "z": 4,
      "name": "Wood_Crystal_Trunk"
    },
    {
      "x": -1,
      "y": 11,
      "z": 4,
      "name": "Wood_Crystal_Trunk_Full"
    },
    {
      "x": -1,
      "y": 20,
      "z": 4,
      "name": "Plant_Fruit_Pinkberry",
      "rotation": 8
    },
    {
      "x": -1,
      "y": 21,
      "z": 4,
      "name": "Plant_Leaves_Crystal"
    },
    {
      "x": -1,
      "y": 22,
      "z": 4,
      "name": "Plant_Leaves_Crystal"
    },
    {
      "x": -1,
      "y": 23,
      "z": 4,
      "name": "Plant_Leaves_Crystal"
    },
    {
      "x": -1,
      "y": 27,
      "z": 4,
      "name": "Plant_Leaves_Crystal"
    },
    {
      "x": -1,
      "y": 28,
      "z": 4,
      "name": "Plant_Leaves_Crystal"
    },
    {
      "x": -1,
      "y": 29,
      "z": 4,
      "name": "Plant_Leaves_Crystal"
    },
    {
      "x": -1,
      "y": 30,
      "z": 4,
      "name": "Plant_Leaves_Crystal"
    },
    {
      "x": -1,
      "y": 31,
      "z": 4,
      "name": "Plant_Leaves_Crystal"
    },
    {
      "x": -1,
      "y": 22,
      "z": 5,
      "name": "Plant_Leaves_Crystal"
    },
    {
      "x": -1,
      "y": 27,
      "z": 5,
      "name": "Plant_Leaves_Crystal"
    },
    {
      "x": -1,
      "y": 28,
      "z": 5,
      "name": "Plant_Leaves_Crystal"
    },
    {
      "x": -1,
      "y": 29,
      "z": 5,
      "name": "Plant_Leaves_Crystal"
    },
    {
      "x": -1,
      "y": 30,
      "z": 5,
      "name": "Plant_Leaves_Crystal"
    },
    {
      "x": -1,
      "y": 26,
      "z": 6,
      "name": "Plant_Leaves_Crystal"
    },
    {
      "x": -1,
      "y": 27,
      "z": 6,
      "name": "Plant_Leaves_Crystal"
    },
    {
      "x": -1,
      "y": 28,
      "z": 6,
      "name": "Plant_Leaves_Crystal"
    },
    {
      "x": -1,
      "y": 29,
      "z": 6,
      "name": "Plant_Leaves_Crystal"
    },
    {
      "x": -1,
      "y": 30,
      "z": 6,
      "name": "Plant_Leaves_Crystal"
    },
    {
      "x": -1,
      "y": 28,
      "z": 7,
      "name": "Plant_Leaves_Crystal"
    },
    {
      "x": -1,
      "y": 30,
      "z": 7,
      "name": "Plant_Leaves_Crystal"
    },
    {
      "x": -1,
      "y": 31,
      "z": 7,
      "name": "Plant_Leaves_Crystal"
    },
    {
      "x": -1,
      "y": 28,
      "z": 8,
      "name": "Plant_Leaves_Crystal"
    },
    {
      "x": -1,
      "y": 29,
      "z": 8,
      "name": "Plant_Leaves_Crystal"
    },
    {
      "x": -1,
      "y": 30,
      "z": 8,
      "name": "Plant_Leaves_Crystal"
    },
    {
      "x": -1,
      "y": 31,
      "z": 8,
      "name": "Plant_Leaves_Crystal"
    },
    {
      "x": -1,
      "y": 28,
      "z": 9,
      "name": "Plant_Fruit_Pinkberry",
      "rotation": 8
    },
    {
      "x": -1,
      "y": 29,
      "z": 9,
      "name": "Plant_Leaves_Crystal"
    },
    {
      "x": -1,
      "y": 30,
      "z": 9,
      "name": "Plant_Leaves_Crystal"
    },
    {
      "x": -1,
      "y": 28,
      "z": 10,
      "name": "Plant_Leaves_Crystal"
    },
    {
      "x": -1,
      "y": 29,
      "z": 10,
      "name": "Plant_Leaves_Crystal"
    },
    {
      "x": -1,
      "y": 27,
      "z": 11,
      "name": "Plant_Leaves_Crystal"
    },
    {
      "x": -1,
      "y": 28,
      "z": 11,
      "name": "Plant_Leaves_Crystal"
    },
    {
      "x": -1,
      "y": 29,
      "z": 11,
      "name": "Plant_Leaves_Crystal"
    },
    {
      "x": -1,
      "y": 30,
      "z": 11,
      "name": "Plant_Leaves_Crystal"
    },
    {
      "x": -1,
      "y": 27,
      "z": 12,
      "name": "Plant_Leaves_Crystal"
    },
    {
      "x": -1,
      "y": 28,
      "z": 12,
      "name": "Plant_Leaves_Crystal"
    },
    {
      "x": -1,
      "y": 29,
      "z": 12,
      "name": "Plant_Leaves_Crystal"
    },
    {
      "x": -1,
      "y": 30,
      "z": 12,
      "name": "Plant_Leaves_Crystal"
    },
    {
      "x": -1,
      "y": 29,
      "z": 13,
      "name": "Plant_Leaves_Crystal"
    },
    {
      "x": 0,
      "y": 28,
      "z": -9,
      "name": "Plant_Leaves_Crystal"
    },
    {
      "x": 0,
      "y": 29,
      "z": -9,
      "name": "Plant_Leaves_Crystal"
    },
    {
      "x": 0,
      "y": 27,
      "z": -8,
      "name": "Plant_Leaves_Crystal"
    },
    {
      "x": 0,
      "y": 28,
      "z": -8,
      "name": "Plant_Leaves_Crystal"
    },
    {
      "x": 0,
      "y": 29,
      "z": -8,
      "name": "Plant_Leaves_Crystal"
    },
    {
      "x": 0,
      "y": 25,
      "z": -7,
      "name": "Plant_Leaves_Crystal"
    },
    {
      "x": 0,
      "y": 26,
      "z": -7,
      "name": "Plant_Leaves_Crystal"
    },
    {
      "x": 0,
      "y": 27,
      "z": -7,
      "name": "Plant_Leaves_Crystal"
    },
    {
      "x": 0,
      "y": 28,
      "z": -7,
      "name": "Plant_Leaves_Crystal"
    },
    {
      "x": 0,
      "y": 29,
      "z": -7,
      "name": "Plant_Leaves_Crystal"
    },
    {
      "x": 0,
      "y": 18,
      "z": -6,
      "name": "Plant_Leaves_Crystal"
    },
    {
      "x": 0,
      "y": 19,
      "z": -6,
      "name": "Plant_Leaves_Crystal"
    },
    {
      "x": 0,
      "y": 20,
      "z": -6,
      "name": "Plant_Leaves_Crystal"
    },
    {
      "x": 0,
      "y": 21,
      "z": -6,
      "name": "Plant_Leaves_Crystal"
    },
    {
      "x": 0,
      "y": 22,
      "z": -6,
      "name": "Plant_Leaves_Crystal"
    },
    {
      "x": 0,
      "y": 27,
      "z": -6,
      "name": "Plant_Leaves_Crystal"
    },
    {
      "x": 0,
      "y": 28,
      "z": -6,
      "name": "Plant_Leaves_Crystal"
    },
    {
      "x": 0,
      "y": 29,
      "z": -6,
      "name": "Plant_Leaves_Crystal"
    },
    {
      "x": 0,
      "y": 30,
      "z": -6,
      "name": "Plant_Leaves_Crystal"
    },
    {
      "x": 0,
      "y": 31,
      "z": -6,
      "name": "Plant_Leaves_Crystal"
    },
    {
      "x": 0,
      "y": 6,
      "z": -5,
      "name": "Wood_Crystal_Roots"
    },
    {
      "x": 0,
      "y": 7,
      "z": -5,
      "name": "Wood_Crystal_Trunk"
    },
    {
      "x": 0,
      "y": 8,
      "z": -5,
      "name": "Wood_Crystal_Trunk"
    },
    {
      "x": 0,
      "y": 9,
      "z": -5,
      "name": "Wood_Crystal_Trunk"
    },
    {
      "x": 0,
      "y": 10,
      "z": -5,
      "name": "Wood_Crystal_Trunk"
    },
    {
      "x": 0,
      "y": 11,
      "z": -5,
      "name": "Wood_Crystal_Trunk_Full"
    },
    {
      "x": 0,
      "y": 22,
      "z": -5,
      "name": "Plant_Leaves_Crystal"
    },
    {
      "x": 0,
      "y": 27,
      "z": -5,
      "name": "Plant_Leaves_Crystal"
    },
    {
      "x": 0,
      "y": 28,
      "z": -5,
      "name": "Plant_Leaves_Crystal"
    },
    {
      "x": 0,
      "y": 29,
      "z": -5,
      "name": "Plant_Leaves_Crystal"
    },
    {
      "x": 0,
      "y": 30,
      "z": -5,
      "name": "Plant_Leaves_Crystal"
    },
    {
      "x": 0,
      "y": 31,
      "z": -5,
      "name": "Plant_Leaves_Crystal"
    },
    {
      "x": 0,
      "y": 9,
      "z": -4,
      "name": "Wood_Crystal_Trunk"
    },
    {
      "x": 0,
      "y": 10,
      "z": -4,
      "name": "Wood_Crystal_Trunk"
    },
    {
      "x": 0,
      "y": 11,
      "z": -4,
      "name": "Wood_Crystal_Trunk"
    },
    {
      "x": 0,
      "y": 12,
      "z": -4,
      "name": "Wood_Crystal_Trunk_Full"
    },
    {
      "x": 0,
      "y": 22,
      "z": -4,
      "name": "Plant_Leaves_Crystal"
    },
    {
      "x": 0,
      "y": 27,
      "z": -4,
      "name": "Plant_Leaves_Crystal"
    },
    {
      "x": 0,
      "y": 29,
      "z": -4,
      "name": "Plant_Leaves_Crystal"
    },
    {
      "x": 0,
      "y": 31,
      "z": -4,
      "name": "Plant_Leaves_Crystal"
    },
    {
      "x": 0,
      "y": 11,
      "z": -3,
      "name": "Wood_Crystal_Trunk"
    },
    {
      "x": 0,
      "y": 12,
      "z": -3,
      "name": "Wood_Crystal_Trunk_Full"
    },
    {
      "x": 0,
      "y": 21,
      "z": -3,
      "name": "Plant_Leaves_Crystal"
    },
    {
      "x": 0,
      "y": 22,
      "z": -3,
      "name": "Plant_Leaves_Crystal"
    },
    {
      "x": 0,
      "y": 29,
      "z": -3,
      "name": "Plant_Leaves_Crystal"
    },
    {
      "x": 0,
      "y": 30,
      "z": -3,
      "name": "Plant_Leaves_Crystal"
    },
    {
      "x": 0,
      "y": 21,
      "z": -2,
      "name": "Wood_Crystal_Trunk_Full"
    },
    {
      "x": 0,
      "y": 22,
      "z": -2,
      "name": "Plant_Leaves_Crystal"
    },
    {
      "x": 0,
      "y": 23,
      "z": -2,
      "name": "Plant_Leaves_Crystal"
    },
    {
      "x": 0,
      "y": 29,
      "z": -2,
      "name": "Plant_Leaves_Crystal"
    },
    {
      "x": 0,
      "y": 30,
      "z": -2,
      "name": "Plant_Leaves_Crystal"
    },
    {
      "x": 0,
      "y": 22,
      "z": -1,
      "name": "Plant_Leaves_Crystal"
    },
    {
      "x": 0,
      "y": 26,
      "z": -1,
      "name": "Wood_Crystal_Trunk_Full"
    },
    {
      "x": 0,
      "y": 27,
      "z": -1,
      "name": "Wood_Crystal_Trunk_Full"
    },
    {
      "x": 0,
      "y": 13,
      "z": 0,
      "name": "Wood_Crystal_Trunk"
    },
    {
      "x": 0,
      "y": 14,
      "z": 0,
      "name": "Wood_Crystal_Trunk_Full"
    },
    {
      "x": 0,
      "y": 22,
      "z": 0,
      "name": "Plant_Leaves_Crystal"
    },
    {
      "x": 0,
      "y": 27,
      "z": 0,
      "name": "Wood_Crystal_Trunk_Full"
    },
    {
      "x": 0,
      "y": 12,
      "z": 1,
      "name": "Wood_Crystal_Trunk"
    },
    {
      "x": 0,
      "y": 13,
      "z": 1,
      "name": "Wood_Crystal_Trunk"
    },
    {
      "x": 0,
      "y": 14,
      "z": 1,
      "name": "Wood_Crystal_Trunk"
    },
    {
      "x": 0,
      "y": 15,
      "z": 1,
      "name": "Wood_Crystal_Trunk"
    },
    {
      "x": 0,
      "y": 16,
      "z": 1,
      "name": "Wood_Crystal_Trunk_Full"
    },
    {
      "x": 0,
      "y": 20,
      "z": 1,
      "name": "Wood_Crystal_Trunk_Full"
    },
    {
      "x": 0,
      "y": 21,
      "z": 1,
      "name": "Wood_Crystal_Trunk_Full"
    },
    {
      "x": 0,
      "y": 27,
      "z": 1,
      "name": "Wood_Crystal_Trunk_Full"
    },
    {
      "x": 0,
      "y": 10,
      "z": 2,
      "name": "Wood_Crystal_Roots"
    },
    {
      "x": 0,
      "y": 11,
      "z": 2,
      "name": "Wood_Crystal_Trunk"
    },
    {
      "x": 0,
      "y": 12,
      "z": 2,
      "name": "Wood_Crystal_Trunk"
    },
    {
      "x": 0,
      "y": 13,
      "z": 2,
      "name": "Wood_Crystal_Trunk"
    },
    {
      "x": 0,
      "y": 14,
      "z": 2,
      "name": "Wood_Crystal_Trunk"
    },
    {
      "x": 0,
      "y": 15,
      "z": 2,
      "name": "Wood_Crystal_Trunk_Full"
    },
    {
      "x": 0,
      "y": 21,
      "z": 2,
      "name": "Wood_Crystal_Trunk_Full"
    },
    {
      "x": 0,
      "y": 27,
      "z": 2,
      "name": "Wood_Crystal_Trunk_Full"
    },
    {
      "x": 0,
      "y": 28,
      "z": 2,
      "name": "Plant_Leaves_Crystal"
    },
    {
      "x": 0,
      "y": 29,
      "z": 2,
      "name": "Plant_Leaves_Crystal"
    },
    {
      "x": 0,
      "y": 10,
      "z": 3,
      "name": "Wood_Crystal_Trunk"
    },
    {
      "x": 0,
      "y": 11,
      "z": 3,
      "name": "Wood_Crystal_Trunk"
    },
    {
      "x": 0,
      "y": 12,
      "z": 3,
      "name": "Wood_Crystal_Trunk"
    },
    {
      "x": 0,
      "y": 13,
      "z": 3,
      "name": "Wood_Crystal_Trunk"
    },
    {
      "x": 0,
      "y": 14,
      "z": 3,
      "name": "Wood_Crystal_Trunk_Full"
    },
    {
      "x": 0,
      "y": 22,
      "z": 3,
      "name": "Plant_Leaves_Crystal"
    },
    {
      "x": 0,
      "y": 27,
      "z": 3,
      "name": "Wood_Crystal_Trunk_Full"
    },
    {
      "x": 0,
      "y": 28,
      "z": 3,
      "name": "Plant_Leaves_Crystal"
    },
    {
      "x": 0,
      "y": 29,
      "z": 3,
      "name": "Plant_Leaves_Crystal"
    },
    {
      "x": 0,
      "y": 10,
      "z": 4,
      "name": "Wood_Crystal_Trunk"
    },
    {
      "x": 0,
      "y": 11,
      "z": 4,
      "name": "Wood_Crystal_Trunk"
    },
    {
      "x": 0,
      "y": 12,
      "z": 4,
      "name": "Wood_Crystal_Trunk_Full"
    },
    {
      "x": 0,
      "y": 22,
      "z": 4,
      "name": "Plant_Leaves_Crystal"
    },
    {
      "x": 0,
      "y": 29,
      "z": 4,
      "name": "Plant_Leaves_Crystal"
    },
    {
      "x": 0,
      "y": 28,
      "z": 5,
      "name": "Plant_Leaves_Crystal"
    },
    {
      "x": 0,
      "y": 22,
      "z": 6,
      "name": "Plant_Leaves_Crystal"
    },
    {
      "x": 0,
      "y": 28,
      "z": 6,
      "name": "Plant_Leaves_Crystal"
    },
    {
      "x": 0,
      "y": 31,
      "z": 6,
      "name": "Plant_Leaves_Crystal"
    },
    {
      "x": 0,
      "y": 27,
      "z": 7,
      "name": "Plant_Fruit_Pinkberry",
      "rotation": 8
    },
    {
      "x": 0,
      "y": 28,
      "z": 7,
      "name": "Plant_Leaves_Crystal"
    },
    {
      "x": 0,
      "y": 29,
      "z": 7,
      "name": "Plant_Leaves_Crystal"
    },
    {
      "x": 0,
      "y": 30,
      "z": 7,
      "name": "Plant_Leaves_Crystal"
    },
    {
      "x": 0,
      "y": 31,
      "z": 7,
      "name": "Plant_Leaves_Crystal"
    },
    {
      "x": 0,
      "y": 32,
      "z": 7,
      "name": "Plant_Leaves_Crystal"
    },
    {
      "x": 0,
      "y": 28,
      "z": 8,
      "name": "Plant_Leaves_Crystal"
    },
    {
      "x": 0,
      "y": 29,
      "z": 8,
      "name": "Plant_Leaves_Crystal"
    },
    {
      "x": 0,
      "y": 30,
      "z": 8,
      "name": "Plant_Leaves_Crystal"
    },
    {
      "x": 0,
      "y": 31,
      "z": 8,
      "name": "Plant_Leaves_Crystal"
    },
    {
      "x": 0,
      "y": 28,
      "z": 9,
      "name": "Plant_Leaves_Crystal"
    },
    {
      "x": 0,
      "y": 29,
      "z": 9,
      "name": "Plant_Leaves_Crystal"
    },
    {
      "x": 0,
      "y": 30,
      "z": 9,
      "name": "Plant_Leaves_Crystal"
    },
    {
      "x": 0,
      "y": 31,
      "z": 9,
      "name": "Plant_Leaves_Crystal"
    },
    {
      "x": 0,
      "y": 32,
      "z": 9,
      "name": "Plant_Leaves_Crystal"
    },
    {
      "x": 0,
      "y": 27,
      "z": 10,
      "name": "Plant_Leaves_Crystal"
    },
    {
      "x": 0,
      "y": 28,
      "z": 10,
      "name": "Plant_Leaves_Crystal"
    },
    {
      "x": 0,
      "y": 29,
      "z": 10,
      "name": "Plant_Leaves_Crystal"
    },
    {
      "x": 0,
      "y": 30,
      "z": 10,
      "name": "Plant_Leaves_Crystal"
    },
    {
      "x": 0,
      "y": 31,
      "z": 10,
      "name": "Plant_Leaves_Crystal"
    },
    {
      "x": 0,
      "y": 29,
      "z": 11,
      "name": "Plant_Leaves_Crystal"
    },
    {
      "x": 0,
      "y": 29,
      "z": 12,
      "name": "Plant_Leaves_Crystal"
    },
    {
      "x": 0,
      "y": 30,
      "z": 12,
      "name": "Plant_Leaves_Crystal"
    },
    {
      "x": 0,
      "y": 29,
      "z": 13,
      "name": "Plant_Leaves_Crystal"
    },
    {
      "x": 1,
      "y": 28,
      "z": -9,
      "name": "Plant_Leaves_Crystal"
    },
    {
      "x": 1,
      "y": 29,
      "z": -9,
      "name": "Plant_Leaves_Crystal"
    },
    {
      "x": 1,
      "y": 27,
      "z": -8,
      "name": "Wood_Crystal_Branch_Corner",
      "rotation": 2
    },
    {
      "x": 1,
      "y": 28,
      "z": -8,
      "name": "Plant_Leaves_Crystal"
    },
    {
      "x": 1,
      "y": 29,
      "z": -8,
      "name": "Plant_Leaves_Crystal"
    },
    {
      "x": 1,
      "y": 22,
      "z": -7,
      "name": "Plant_Leaves_Crystal"
    },
    {
      "x": 1,
      "y": 27,
      "z": -7,
      "name": "Wood_Crystal_Branch_Long",
      "rotation": 4
    },
    {
      "x": 1,
      "y": 28,
      "z": -7,
      "name": "Plant_Leaves_Crystal"
    },
    {
      "x": 1,
      "y": 29,
      "z": -7,
      "name": "Plant_Leaves_Crystal"
    },
    {
      "x": 1,
      "y": 30,
      "z": -7,
      "name": "Plant_Leaves_Crystal"
    },
    {
      "x": 1,
      "y": 22,
      "z": -6,
      "name": "Plant_Leaves_Crystal"
    },
    {
      "x": 1,
      "y": 27,
      "z": -6,
      "name": "Wood_Crystal_Branch_Long",
      "rotation": 4
    },
    {
      "x": 1,
      "y": 28,
      "z": -6,
      "name": "Plant_Leaves_Crystal"
    },
    {
      "x": 1,
      "y": 29,
      "z": -6,
      "name": "Plant_Leaves_Crystal"
    },
    {
      "x": 1,
      "y": 30,
      "z": -6,
      "name": "Plant_Leaves_Crystal"
    },
    {
      "x": 1,
      "y": 31,
      "z": -6,
      "name": "Plant_Leaves_Crystal"
    },
    {
      "x": 1,
      "y": 10,
      "z": -5,
      "name": "Wood_Crystal_Trunk"
    },
    {
      "x": 1,
      "y": 11,
      "z": -5,
      "name": "Wood_Crystal_Trunk"
    },
    {
      "x": 1,
      "y": 12,
      "z": -5,
      "name": "Wood_Crystal_Trunk_Full"
    },
    {
      "x": 1,
      "y": 21,
      "z": -5,
      "name": "Wood_Crystal_Branch_Corner",
      "rotation": 2
    },
    {
      "x": 1,
      "y": 22,
      "z": -5,
      "name": "Plant_Leaves_Crystal"
    },
    {
      "x": 1,
      "y": 27,
      "z": -5,
      "name": "Wood_Crystal_Trunk_Full"
    },
    {
      "x": 1,
      "y": 28,
      "z": -5,
      "name": "Plant_Leaves_Crystal"
    },
    {
      "x": 1,
      "y": 29,
      "z": -5,
      "name": "Plant_Leaves_Crystal"
    },
    {
      "x": 1,
      "y": 30,
      "z": -5,
      "name": "Plant_Leaves_Crystal"
    },
    {
      "x": 1,
      "y": 31,
      "z": -5,
      "name": "Plant_Leaves_Crystal"
    },
    {
      "x": 1,
      "y": 9,
      "z": -4,
      "name": "Wood_Crystal_Roots"
    },
    {
      "x": 1,
      "y": 10,
      "z": -4,
      "name": "Wood_Crystal_Trunk"
    },
    {
      "x": 1,
      "y": 11,
      "z": -4,
      "name": "Wood_Crystal_Trunk"
    },
    {
      "x": 1,
      "y": 12,
      "z": -4,
      "name": "Wood_Crystal_Trunk"
    },
    {
      "x": 1,
      "y": 13,
      "z": -4,
      "name": "Wood_Crystal_Trunk_Full"
    },
    {
      "x": 1,
      "y": 21,
      "z": -4,
      "name": "Wood_Crystal_Trunk_Full"
    },
    {
      "x": 1,
      "y": 22,
      "z": -4,
      "name": "Plant_Leaves_Crystal"
    },
    {
      "x": 1,
      "y": 23,
      "z": -4,
      "name": "Plant_Leaves_Crystal"
    },
    {
      "x": 1,
      "y": 26,
      "z": -4,
      "name": "Wood_Crystal_Roots"
    },
    {
      "x": 1,
      "y": 27,
      "z": -4,
      "name": "Wood_Crystal_Trunk_Full"
    },
    {
      "x": 1,
      "y": 28,
      "z": -4,
      "name": "Plant_Leaves_Crystal"
    },
    {
      "x": 1,
      "y": 29,
      "z": -4,
      "name": "Plant_Leaves_Crystal"
    },
    {
      "x": 1,
      "y": 30,
      "z": -4,
      "name": "Plant_Leaves_Crystal"
    },
    {
      "x": 1,
      "y": 31,
      "z": -4,
      "name": "Plant_Leaves_Crystal"
    },
    {
      "x": 1,
      "y": 10,
      "z": -3,
      "name": "Wood_Crystal_Roots"
    },
    {
      "x": 1,
      "y": 11,
      "z": -3,
      "name": "Wood_Crystal_Trunk"
    },
    {
      "x": 1,
      "y": 12,
      "z": -3,
      "name": "Wood_Crystal_Trunk"
    },
    {
      "x": 1,
      "y": 13,
      "z": -3,
      "name": "Wood_Crystal_Trunk"
    },
    {
      "x": 1,
      "y": 14,
      "z": -3,
      "name": "Wood_Crystal_Trunk_Full"
    },
    {
      "x": 1,
      "y": 21,
      "z": -3,
      "name": "Wood_Crystal_Trunk_Full"
    },
    {
      "x": 1,
      "y": 22,
      "z": -3,
      "name": "Plant_Leaves_Crystal"
    },
    {
      "x": 1,
      "y": 23,
      "z": -3,
      "name": "Plant_Leaves_Crystal"
    },
    {
      "x": 1,
      "y": 26,
      "z": -3,
      "name": "Wood_Crystal_Roots"
    },
    {
      "x": 1,
      "y": 27,
      "z": -3,
      "name": "Wood_Crystal_Trunk_Full"
    },
    {
      "x": 1,
      "y": 28,
      "z": -3,
      "name": "Plant_Leaves_Crystal"
    },
    {
      "x": 1,
      "y": 29,
      "z": -3,
      "name": "Plant_Leaves_Crystal"
    },
    {
      "x": 1,
      "y": 12,
      "z": -2,
      "name": "Wood_Crystal_Trunk"
    },
    {
      "x": 1,
      "y": 13,
      "z": -2,
      "name": "Wood_Crystal_Trunk"
    },
    {
      "x": 1,
      "y": 14,
      "z": -2,
      "name": "Wood_Crystal_Trunk_Full"
    },
    {
      "x": 1,
      "y": 21,
      "z": -2,
      "name": "Wood_Crystal_Trunk_Full"
    },
    {
      "x": 1,
      "y": 22,
      "z": -2,
      "name": "Plant_Leaves_Crystal"
    },
    {
      "x": 1,
      "y": 23,
      "z": -2,
      "name": "Plant_Leaves_Crystal"
    },
    {
      "x": 1,
      "y": 13,
      "z": -1,
      "name": "Wood_Crystal_Trunk"
    },
    {
      "x": 1,
      "y": 14,
      "z": -1,
      "name": "Wood_Crystal_Trunk"
    },
    {
      "x": 1,
      "y": 15,
      "z": -1,
      "name": "Wood_Crystal_Trunk_Full"
    },
    {
      "x": 1,
      "y": 20,
      "z": -1,
      "name": "Plant_Flower_Common_Poisoned2",
      "rotation": 7
    },
    {
      "x": 1,
      "y": 21,
      "z": -1,
      "name": "Wood_Crystal_Trunk_Full"
    },
    {
      "x": 1,
      "y": 13,
      "z": 0,
      "name": "Wood_Crystal_Trunk"
    },
    {
      "x": 1,
      "y": 14,
      "z": 0,
      "name": "Wood_Crystal_Trunk"
    },
    {
      "x": 1,
      "y": 15,
      "z": 0,
      "name": "Wood_Crystal_Trunk"
    },
    {
      "x": 1,
      "y": 16,
      "z": 0,
      "name": "Wood_Crystal_Trunk_Full"
    },
    {
      "x": 1,
      "y": 18,
      "z": 0,
      "name": "Plant_Flower_Common_Poisoned2",
      "rotation": 7
    },
    {
      "x": 1,
      "y": 19,
      "z": 0,
      "name": "Plant_Flower_Common_Poisoned2",
      "rotation": 7
    },
    {
      "x": 1,
      "y": 20,
      "z": 0,
      "name": "Plant_Flower_Common_Poisoned2",
      "rotation": 7
    },
    {
      "x": 1,
      "y": 25,
      "z": 0,
      "name": "Wood_Crystal_Trunk_Full"
    },
    {
      "x": 1,
      "y": 26,
      "z": 0,
      "name": "Wood_Crystal_Trunk"
    },
    {
      "x": 1,
      "y": 27,
      "z": 0,
      "name": "Wood_Crystal_Trunk_Full"
    },
    {
      "x": 1,
      "y": 12,
      "z": 1,
      "name": "Wood_Crystal_Trunk"
    },
    {
      "x": 1,
      "y": 13,
      "z": 1,
      "name": "Wood_Crystal_Trunk"
    },
    {
      "x": 1,
      "y": 14,
      "z": 1,
      "name": "Wood_Crystal_Trunk"
    },
    {
      "x": 1,
      "y": 15,
      "z": 1,
      "name": "Wood_Crystal_Trunk"
    },
    {
      "x": 1,
      "y": 16,
      "z": 1,
      "name": "Wood_Crystal_Trunk"
    },
    {
      "x": 1,
      "y": 17,
      "z": 1,
      "name": "Wood_Crystal_Trunk"
    },
    {
      "x": 1,
      "y": 18,
      "z": 1,
      "name": "Wood_Crystal_Trunk"
    },
    {
      "x": 1,
      "y": 19,
      "z": 1,
      "name": "Wood_Crystal_Trunk"
    },
    {
      "x": 1,
      "y": 20,
      "z": 1,
      "name": "Wood_Crystal_Trunk_Full"
    },
    {
      "x": 1,
      "y": 11,
      "z": 2,
      "name": "Wood_Crystal_Roots"
    },
    {
      "x": 1,
      "y": 12,
      "z": 2,
      "name": "Wood_Crystal_Trunk"
    },
    {
      "x": 1,
      "y": 13,
      "z": 2,
      "name": "Wood_Crystal_Trunk"
    },
    {
      "x": 1,
      "y": 14,
      "z": 2,
      "name": "Wood_Crystal_Trunk"
    },
    {
      "x": 1,
      "y": 15,
      "z": 2,
      "name": "Wood_Crystal_Trunk"
    },
    {
      "x": 1,
      "y": 16,
      "z": 2,
      "name": "Wood_Crystal_Trunk"
    },
    {
      "x": 1,
      "y": 17,
      "z": 2,
      "name": "Wood_Crystal_Trunk"
    },
    {
      "x": 1,
      "y": 18,
      "z": 2,
      "name": "Wood_Crystal_Trunk_Full"
    },
    {
      "x": 1,
      "y": 11,
      "z": 3,
      "name": "Wood_Crystal_Trunk"
    },
    {
      "x": 1,
      "y": 12,
      "z": 3,
      "name": "Wood_Crystal_Trunk"
    },
    {
      "x": 1,
      "y": 13,
      "z": 3,
      "name": "Wood_Crystal_Trunk"
    },
    {
      "x": 1,
      "y": 14,
      "z": 3,
      "name": "Wood_Crystal_Trunk"
    },
    {
      "x": 1,
      "y": 15,
      "z": 3,
      "name": "Wood_Crystal_Trunk_Full"
    },
    {
      "x": 1,
      "y": 22,
      "z": 3,
      "name": "Plant_Leaves_Crystal"
    },
    {
      "x": 1,
      "y": 28,
      "z": 3,
      "name": "Plant_Leaves_Crystal"
    },
    {
      "x": 1,
      "y": 29,
      "z": 3,
      "name": "Plant_Leaves_Crystal"
    },
    {
      "x": 1,
      "y": 22,
      "z": 4,
      "name": "Plant_Leaves_Crystal"
    },
    {
      "x": 1,
      "y": 29,
      "z": 4,
      "name": "Plant_Leaves_Crystal"
    },
    {
      "x": 1,
      "y": 30,
      "z": 4,
      "name": "Plant_Leaves_Crystal"
    },
    {
      "x": 1,
      "y": 22,
      "z": 5,
      "name": "Plant_Leaves_Crystal"
    },
    {
      "x": 1,
      "y": 23,
      "z": 5,
      "name": "Plant_Leaves_Crystal"
    },
    {
      "x": 1,
      "y": 21,
      "z": 6,
      "name": "Plant_Fruit_Pinkberry",
      "rotation": 8
    },
    {
      "x": 1,
      "y": 22,
      "z": 6,
      "name": "Plant_Leaves_Crystal"
    },
    {
      "x": 1,
      "y": 28,
      "z": 6,
      "name": "Wood_Crystal_Trunk_Full"
    },
    {
      "x": 1,
      "y": 21,
      "z": 7,
      "name": "Plant_Leaves_Crystal"
    },
    {
      "x": 1,
      "y": 22,
      "z": 7,
      "name": "Plant_Leaves_Crystal"
    },
    {
      "x": 1,
      "y": 29,
      "z": 7,
      "name": "Plant_Leaves_Crystal"
    },
    {
      "x": 1,
      "y": 31,
      "z": 7,
      "name": "Plant_Leaves_Crystal"
    },
    {
      "x": 1,
      "y": 27,
      "z": 8,
      "name": "Wood_Crystal_Roots"
    },
    {
      "x": 1,
      "y": 28,
      "z": 8,
      "name": "Wood_Crystal_Trunk_Full"
    },
    {
      "x": 1,
      "y": 29,
      "z": 8,
      "name": "Plant_Leaves_Crystal"
    },
    {
      "x": 1,
      "y": 31,
      "z": 8,
      "name": "Plant_Leaves_Crystal"
    },
    {
      "x": 1,
      "y": 27,
      "z": 9,
      "name": "Wood_Crystal_Roots"
    },
    {
      "x": 1,
      "y": 28,
      "z": 9,
      "name": "Wood_Crystal_Trunk_Full"
    },
    {
      "x": 1,
      "y": 29,
      "z": 9,
      "name": "Plant_Leaves_Crystal"
    },
    {
      "x": 1,
      "y": 30,
      "z": 9,
      "name": "Plant_Leaves_Crystal"
    },
    {
      "x": 1,
      "y": 31,
      "z": 9,
      "name": "Plant_Leaves_Crystal"
    },
    {
      "x": 1,
      "y": 32,
      "z": 9,
      "name": "Plant_Leaves_Crystal"
    },
    {
      "x": 1,
      "y": 28,
      "z": 10,
      "name": "Wood_Crystal_Trunk_Full"
    },
    {
      "x": 1,
      "y": 29,
      "z": 10,
      "name": "Plant_Leaves_Crystal"
    },
    {
      "x": 1,
      "y": 30,
      "z": 10,
      "name": "Plant_Leaves_Crystal"
    },
    {
      "x": 1,
      "y": 31,
      "z": 10,
      "name": "Plant_Leaves_Crystal"
    },
    {
      "x": 1,
      "y": 28,
      "z": 11,
      "name": "Wood_Crystal_Branch_Corner"
    },
    {
      "x": 1,
      "y": 29,
      "z": 11,
      "name": "Plant_Leaves_Crystal"
    },
    {
      "x": 1,
      "y": 30,
      "z": 11,
      "name": "Plant_Leaves_Crystal"
    },
    {
      "x": 1,
      "y": 31,
      "z": 11,
      "name": "Plant_Leaves_Crystal"
    },
    {
      "x": 1,
      "y": 29,
      "z": 12,
      "name": "Plant_Leaves_Crystal"
    },
    {
      "x": 1,
      "y": 30,
      "z": 12,
      "name": "Plant_Leaves_Crystal"
    },
    {
      "x": 1,
      "y": 29,
      "z": 13,
      "name": "Plant_Leaves_Crystal"
    },
    {
      "x": 1,
      "y": 30,
      "z": 13,
      "name": "Plant_Leaves_Crystal"
    },
    {
      "x": 1,
      "y": 29,
      "z": 14,
      "name": "Plant_Leaves_Crystal"
    },
    {
      "x": 2,
      "y": 28,
      "z": -10,
      "name": "Plant_Leaves_Crystal"
    },
    {
      "x": 2,
      "y": 29,
      "z": -10,
      "name": "Plant_Leaves_Crystal"
    },
    {
      "x": 2,
      "y": 27,
      "z": -9,
      "name": "Plant_Fruit_Pinkberry",
      "rotation": 8
    },
    {
      "x": 2,
      "y": 28,
      "z": -9,
      "name": "Plant_Leaves_Crystal"
    },
    {
      "x": 2,
      "y": 29,
      "z": -9,
      "name": "Plant_Leaves_Crystal"
    },
    {
      "x": 2,
      "y": 28,
      "z": -8,
      "name": "Plant_Leaves_Crystal"
    },
    {
      "x": 2,
      "y": 30,
      "z": -8,
      "name": "Plant_Leaves_Crystal"
    },
    {
      "x": 2,
      "y": 22,
      "z": -7,
      "name": "Plant_Leaves_Crystal"
    },
    {
      "x": 2,
      "y": 28,
      "z": -7,
      "name": "Wood_Crystal_Branch_Corner",
      "rotation": 3
    },
    {
      "x": 2,
      "y": 30,
      "z": -7,
      "name": "Plant_Leaves_Crystal"
    },
    {
      "x": 2,
      "y": 22,
      "z": -6,
      "name": "Plant_Leaves_Crystal"
    },
    {
      "x": 2,
      "y": 28,
      "z": -6,
      "name": "Plant_Leaves_Crystal"
    },
    {
      "x": 2,
      "y": 30,
      "z": -6,
      "name": "Plant_Leaves_Crystal"
    },
    {
      "x": 2,
      "y": 31,
      "z": -6,
      "name": "Plant_Leaves_Crystal"
    },
    {
      "x": 2,
      "y": 21,
      "z": -5,
      "name": "Plant_Leaves_Crystal"
    },
    {
      "x": 2,
      "y": 22,
      "z": -5,
      "name": "Plant_Leaves_Crystal"
    },
    {
      "x": 2,
      "y": 27,
      "z": -5,
      "name": "Plant_Leaves_Crystal"
    },
    {
      "x": 2,
      "y": 28,
      "z": -5,
      "name": "Plant_Leaves_Crystal"
    },
    {
      "x": 2,
      "y": 30,
      "z": -5,
      "name": "Plant_Leaves_Crystal"
    },
    {
      "x": 2,
      "y": 11,
      "z": -4,
      "name": "Wood_Crystal_Trunk"
    },
    {
      "x": 2,
      "y": 12,
      "z": -4,
      "name": "Wood_Crystal_Trunk"
    },
    {
      "x": 2,
      "y": 13,
      "z": -4,
      "name": "Wood_Crystal_Trunk_Full"
    },
    {
      "x": 2,
      "y": 21,
      "z": -4,
      "name": "Plant_Leaves_Crystal"
    },
    {
      "x": 2,
      "y": 22,
      "z": -4,
      "name": "Plant_Leaves_Crystal"
    },
    {
      "x": 2,
      "y": 23,
      "z": -4,
      "name": "Plant_Leaves_Crystal"
    },
    {
      "x": 2,
      "y": 28,
      "z": -4,
      "name": "Plant_Leaves_Crystal"
    },
    {
      "x": 2,
      "y": 29,
      "z": -4,
      "name": "Plant_Leaves_Crystal"
    },
    {
      "x": 2,
      "y": 12,
      "z": -3,
      "name": "Wood_Crystal_Trunk"
    },
    {
      "x": 2,
      "y": 13,
      "z": -3,
      "name": "Wood_Crystal_Trunk"
    },
    {
      "x": 2,
      "y": 14,
      "z": -3,
      "name": "Wood_Crystal_Trunk_Full"
    },
    {
      "x": 2,
      "y": 22,
      "z": -3,
      "name": "Plant_Leaves_Crystal"
    },
    {
      "x": 2,
      "y": 23,
      "z": -3,
      "name": "Plant_Leaves_Crystal"
    },
    {
      "x": 2,
      "y": 26,
      "z": -3,
      "name": "Wood_Crystal_Roots"
    },
    {
      "x": 2,
      "y": 27,
      "z": -3,
      "name": "Wood_Crystal_Trunk_Full"
    },
    {
      "x": 2,
      "y": 11,
      "z": -2,
      "name": "Wood_Crystal_Roots"
    },
    {
      "x": 2,
      "y": 12,
      "z": -2,
      "name": "Wood_Crystal_Trunk"
    },
    {
      "x": 2,
      "y": 13,
      "z": -2,
      "name": "Wood_Crystal_Trunk"
    },
    {
      "x": 2,
      "y": 14,
      "z": -2,
      "name": "Wood_Crystal_Trunk"
    },
    {
      "x": 2,
      "y": 15,
      "z": -2,
      "name": "Wood_Crystal_Trunk_Full"
    },
    {
      "x": 2,
      "y": 20,
      "z": -2,
      "name": "Plant_Flower_Common_Poisoned2",
      "rotation": 6
    },
    {
      "x": 2,
      "y": 21,
      "z": -2,
      "name": "Plant_Fruit_Pinkberry",
      "rotation": 8
    },
    {
      "x": 2,
      "y": 22,
      "z": -2,
      "name": "Plant_Leaves_Crystal"
    },
    {
      "x": 2,
      "y": 23,
      "z": -2,
      "name": "Plant_Leaves_Crystal"
    },
    {
      "x": 2,
      "y": 13,
      "z": -1,
      "name": "Wood_Crystal_Trunk"
    },
    {
      "x": 2,
      "y": 14,
      "z": -1,
      "name": "Wood_Crystal_Trunk"
    },
    {
      "x": 2,
      "y": 15,
      "z": -1,
      "name": "Wood_Crystal_Trunk"
    },
    {
      "x": 2,
      "y": 16,
      "z": -1,
      "name": "Wood_Crystal_Trunk"
    },
    {
      "x": 2,
      "y": 17,
      "z": -1,
      "name": "Wood_Crystal_Trunk_Full"
    },
    {
      "x": 2,
      "y": 19,
      "z": -1,
      "name": "Plant_Flower_Common_Poisoned2",
      "rotation": 8
    },
    {
      "x": 2,
      "y": 20,
      "z": -1,
      "name": "Wood_Crystal_Trunk_Full"
    },
    {
      "x": 2,
      "y": 21,
      "z": -1,
      "name": "Wood_Crystal_Trunk_Full"
    },
    {
      "x": 2,
      "y": 12,
      "z": 0,
      "name": "Wood_Crystal_Roots"
    },
    {
      "x": 2,
      "y": 13,
      "z": 0,
      "name": "Wood_Crystal_Trunk"
    },
    {
      "x": 2,
      "y": 14,
      "z": 0,
      "name": "Wood_Crystal_Trunk"
    },
    {
      "x": 2,
      "y": 15,
      "z": 0,
      "name": "Wood_Crystal_Trunk"
    },
    {
      "x": 2,
      "y": 16,
      "z": 0,
      "name": "Rock_Crystal_Pink_Block"
    },
    {
      "x": 2,
      "y": 17,
      "z": 0,
      "name": "Wood_Crystal_Trunk"
    },
    {
      "x": 2,
      "y": 18,
      "z": 0,
      "name": "Wood_Crystal_Trunk"
    },
    {
      "x": 2,
      "y": 19,
      "z": 0,
      "name": "Wood_Crystal_Trunk"
    },
    {
      "x": 2,
      "y": 20,
      "z": 0,
      "name": "Wood_Crystal_Trunk"
    },
    {
      "x": 2,
      "y": 21,
      "z": 0,
      "name": "Wood_Crystal_Trunk"
    },
    {
      "x": 2,
      "y": 22,
      "z": 0,
      "name": "Wood_Crystal_Trunk"
    },
    {
      "x": 2,
      "y": 23,
      "z": 0,
      "name": "Wood_Crystal_Trunk_Full"
    },
    {
      "x": 2,
      "y": 25,
      "z": 0,
      "name": "Wood_Crystal_Trunk_Full"
    },
    {
      "x": 2,
      "y": 26,
      "z": 0,
      "name": "Wood_Crystal_Trunk_Full"
    },
    {
      "x": 2,
      "y": 13,
      "z": 1,
      "name": "Wood_Crystal_Trunk"
    },
    {
      "x": 2,
      "y": 14,
      "z": 1,
      "name": "Wood_Crystal_Trunk"
    },
    {
      "x": 2,
      "y": 15,
      "z": 1,
      "name": "Wood_Crystal_Trunk"
    },
    {
      "x": 2,
      "y": 16,
      "z": 1,
      "name": "Wood_Crystal_Trunk"
    },
    {
      "x": 2,
      "y": 17,
      "z": 1,
      "name": "Rock_Crystal_Pink_Block"
    },
    {
      "x": 2,
      "y": 18,
      "z": 1,
      "name": "Rock_Crystal_Pink_Block"
    },
    {
      "x": 2,
      "y": 19,
      "z": 1,
      "name": "Rock_Crystal_Pink_Block"
    },
    {
      "x": 2,
      "y": 20,
      "z": 1,
      "name": "Wood_Crystal_Trunk"
    },
    {
      "x": 2,
      "y": 21,
      "z": 1,
      "name": "Wood_Crystal_Trunk"
    },
    {
      "x": 2,
      "y": 22,
      "z": 1,
      "name": "Wood_Crystal_Trunk"
    },
    {
      "x": 2,
      "y": 23,
      "z": 1,
      "name": "Wood_Crystal_Trunk_Full"
    },
    {
      "x": 2,
      "y": 12,
      "z": 2,
      "name": "Wood_Crystal_Trunk"
    },
    {
      "x": 2,
      "y": 13,
      "z": 2,
      "name": "Wood_Crystal_Trunk"
    },
    {
      "x": 2,
      "y": 14,
      "z": 2,
      "name": "Wood_Crystal_Trunk"
    },
    {
      "x": 2,
      "y": 15,
      "z": 2,
      "name": "Wood_Crystal_Trunk"
    },
    {
      "x": 2,
      "y": 16,
      "z": 2,
      "name": "Wood_Crystal_Trunk"
    },
    {
      "x": 2,
      "y": 17,
      "z": 2,
      "name": "Wood_Crystal_Trunk"
    },
    {
      "x": 2,
      "y": 18,
      "z": 2,
      "name": "Wood_Crystal_Trunk"
    },
    {
      "x": 2,
      "y": 19,
      "z": 2,
      "name": "Wood_Crystal_Trunk"
    },
    {
      "x": 2,
      "y": 20,
      "z": 2,
      "name": "Wood_Crystal_Trunk"
    },
    {
      "x": 2,
      "y": 21,
      "z": 2,
      "name": "Wood_Crystal_Trunk"
    },
    {
      "x": 2,
      "y": 22,
      "z": 2,
      "name": "Wood_Crystal_Trunk_Full"
    },
    {
      "x": 2,
      "y": 12,
      "z": 3,
      "name": "Wood_Crystal_Trunk"
    },
    {
      "x": 2,
      "y": 13,
      "z": 3,
      "name": "Wood_Crystal_Trunk"
    },
    {
      "x": 2,
      "y": 14,
      "z": 3,
      "name": "Wood_Crystal_Trunk"
    },
    {
      "x": 2,
      "y": 15,
      "z": 3,
      "name": "Wood_Crystal_Trunk"
    },
    {
      "x": 2,
      "y": 16,
      "z": 3,
      "name": "Wood_Crystal_Trunk_Full"
    },
    {
      "x": 2,
      "y": 22,
      "z": 3,
      "name": "Plant_Leaves_Crystal"
    },
    {
      "x": 2,
      "y": 22,
      "z": 4,
      "name": "Plant_Leaves_Crystal"
    },
    {
      "x": 2,
      "y": 29,
      "z": 4,
      "name": "Plant_Leaves_Crystal"
    },
    {
      "x": 2,
      "y": 30,
      "z": 4,
      "name": "Plant_Leaves_Crystal"
    },
    {
      "x": 2,
      "y": 22,
      "z": 5,
      "name": "Plant_Leaves_Crystal"
    },
    {
      "x": 2,
      "y": 30,
      "z": 5,
      "name": "Plant_Leaves_Crystal"
    },
    {
      "x": 2,
      "y": 31,
      "z": 5,
      "name": "Plant_Leaves_Crystal"
    },
    {
      "x": 2,
      "y": 20,
      "z": 6,
      "name": "Plant_Fruit_Pinkberry",
      "rotation": 8
    },
    {
      "x": 2,
      "y": 21,
      "z": 6,
      "name": "Plant_Leaves_Crystal"
    },
    {
      "x": 2,
      "y": 22,
      "z": 6,
      "name": "Plant_Leaves_Crystal"
    },
    {
      "x": 2,
      "y": 28,
      "z": 6,
      "name": "Wood_Crystal_Trunk_Full"
    },
    {
      "x": 2,
      "y": 30,
      "z": 6,
      "name": "Plant_Leaves_Crystal"
    },
    {
      "x": 2,
      "y": 21,
      "z": 7,
      "name": "Plant_Fruit_Pinkberry"
    },
    {
      "x": 2,
      "y": 22,
      "z": 7,
      "name": "Plant_Leaves_Crystal"
    },
    {
      "x": 2,
      "y": 28,
      "z": 7,
      "name": "Wood_Crystal_Trunk_Full"
    },
    {
      "x": 2,
      "y": 30,
      "z": 7,
      "name": "Plant_Leaves_Crystal"
    },
    {
      "x": 2,
      "y": 31,
      "z": 7,
      "name": "Plant_Leaves_Crystal"
    },
    {
      "x": 2,
      "y": 22,
      "z": 8,
      "name": "Plant_Leaves_Crystal"
    },
    {
      "x": 2,
      "y": 27,
      "z": 8,
      "name": "Wood_Crystal_Roots"
    },
    {
      "x": 2,
      "y": 28,
      "z": 8,
      "name": "Wood_Crystal_Trunk_Full"
    },
    {
      "x": 2,
      "y": 29,
      "z": 8,
      "name": "Plant_Leaves_Crystal"
    },
    {
      "x": 2,
      "y": 30,
      "z": 8,
      "name": "Plant_Leaves_Crystal"
    },
    {
      "x": 2,
      "y": 31,
      "z": 8,
      "name": "Plant_Leaves_Crystal"
    },
    {
      "x": 2,
      "y": 32,
      "z": 8,
      "name": "Plant_Leaves_Crystal"
    },
    {
      "x": 2,
      "y": 30,
      "z": 9,
      "name": "Plant_Leaves_Crystal"
    },
    {
      "x": 2,
      "y": 31,
      "z": 9,
      "name": "Plant_Leaves_Crystal"
    },
    {
      "x": 2,
      "y": 31,
      "z": 10,
      "name": "Plant_Leaves_Crystal"
    },
    {
      "x": 2,
      "y": 29,
      "z": 11,
      "name": "Plant_Leaves_Crystal"
    },
    {
      "x": 2,
      "y": 30,
      "z": 11,
      "name": "Plant_Leaves_Crystal"
    },
    {
      "x": 2,
      "y": 28,
      "z": 12,
      "name": "Plant_Fruit_Pinkberry",
      "rotation": 8
    },
    {
      "x": 2,
      "y": 29,
      "z": 12,
      "name": "Plant_Leaves_Crystal"
    },
    {
      "x": 2,
      "y": 29,
      "z": 13,
      "name": "Plant_Leaves_Crystal"
    },
    {
      "x": 2,
      "y": 29,
      "z": 14,
      "name": "Plant_Leaves_Crystal"
    },
    {
      "x": 3,
      "y": 29,
      "z": -10,
      "name": "Plant_Leaves_Crystal"
    },
    {
      "x": 3,
      "y": 28,
      "z": -9,
      "name": "Plant_Leaves_Crystal"
    },
    {
      "x": 3,
      "y": 29,
      "z": -9,
      "name": "Plant_Leaves_Crystal"
    },
    {
      "x": 3,
      "y": 30,
      "z": -9,
      "name": "Plant_Leaves_Crystal"
    },
    {
      "x": 3,
      "y": 28,
      "z": -8,
      "name": "Plant_Leaves_Crystal"
    },
    {
      "x": 3,
      "y": 29,
      "z": -8,
      "name": "Plant_Leaves_Crystal"
    },
    {
      "x": 3,
      "y": 28,
      "z": -7,
      "name": "Wood_Crystal_Trunk_Full"
    },
    {
      "x": 3,
      "y": 29,
      "z": -7,
      "name": "Plant_Leaves_Crystal"
    },
    {
      "x": 3,
      "y": 30,
      "z": -7,
      "name": "Plant_Leaves_Crystal"
    },
    {
      "x": 3,
      "y": 31,
      "z": -7,
      "name": "Plant_Leaves_Crystal"
    },
    {
      "x": 3,
      "y": 22,
      "z": -6,
      "name": "Plant_Leaves_Crystal"
    },
    {
      "x": 3,
      "y": 29,
      "z": -6,
      "name": "Plant_Leaves_Crystal"
    },
    {
      "x": 3,
      "y": 30,
      "z": -6,
      "name": "Plant_Leaves_Crystal"
    },
    {
      "x": 3,
      "y": 31,
      "z": -6,
      "name": "Plant_Leaves_Crystal"
    },
    {
      "x": 3,
      "y": 22,
      "z": -5,
      "name": "Plant_Leaves_Crystal"
    },
    {
      "x": 3,
      "y": 30,
      "z": -5,
      "name": "Plant_Leaves_Crystal"
    },
    {
      "x": 3,
      "y": 31,
      "z": -5,
      "name": "Plant_Leaves_Crystal"
    },
    {
      "x": 3,
      "y": 21,
      "z": -4,
      "name": "Plant_Leaves_Crystal"
    },
    {
      "x": 3,
      "y": 22,
      "z": -4,
      "name": "Plant_Leaves_Crystal"
    },
    {
      "x": 3,
      "y": 12,
      "z": -3,
      "name": "Wood_Crystal_Trunk"
    },
    {
      "x": 3,
      "y": 13,
      "z": -3,
      "name": "Wood_Crystal_Trunk"
    },
    {
      "x": 3,
      "y": 14,
      "z": -3,
      "name": "Wood_Crystal_Trunk_Full"
    },
    {
      "x": 3,
      "y": 22,
      "z": -3,
      "name": "Plant_Leaves_Crystal"
    },
    {
      "x": 3,
      "y": 27,
      "z": -3,
      "name": "Wood_Crystal_Trunk_Full"
    },
    {
      "x": 3,
      "y": 13,
      "z": -2,
      "name": "Wood_Crystal_Trunk"
    },
    {
      "x": 3,
      "y": 14,
      "z": -2,
      "name": "Wood_Crystal_Trunk"
    },
    {
      "x": 3,
      "y": 15,
      "z": -2,
      "name": "Wood_Crystal_Trunk_Full"
    },
    {
      "x": 3,
      "y": 22,
      "z": -2,
      "name": "Plant_Leaves_Crystal"
    },
    {
      "x": 3,
      "y": 13,
      "z": -1,
      "name": "Wood_Crystal_Trunk"
    },
    {
      "x": 3,
      "y": 14,
      "z": -1,
      "name": "Wood_Crystal_Trunk"
    },
    {
      "x": 3,
      "y": 15,
      "z": -1,
      "name": "Wood_Crystal_Trunk"
    },
    {
      "x": 3,
      "y": 16,
      "z": -1,
      "name": "Wood_Crystal_Trunk"
    },
    {
      "x": 3,
      "y": 17,
      "z": -1,
      "name": "Wood_Crystal_Trunk"
    },
    {
      "x": 3,
      "y": 18,
      "z": -1,
      "name": "Wood_Crystal_Trunk_Full"
    },
    {
      "x": 3,
      "y": 22,
      "z": -1,
      "name": "Plant_Leaves_Crystal"
    },
    {
      "x": 3,
      "y": 13,
      "z": 0,
      "name": "Wood_Crystal_Trunk"
    },
    {
      "x": 3,
      "y": 14,
      "z": 0,
      "name": "Wood_Crystal_Trunk"
    },
    {
      "x": 3,
      "y": 15,
      "z": 0,
      "name": "Wood_Crystal_Trunk"
    },
    {
      "x": 3,
      "y": 16,
      "z": 0,
      "name": "Rock_Crystal_Pink_Block"
    },
    {
      "x": 3,
      "y": 17,
      "z": 0,
      "name": "Rock_Crystal_Pink_Block"
    },
    {
      "x": 3,
      "y": 18,
      "z": 0,
      "name": "Rock_Crystal_Pink_Block"
    },
    {
      "x": 3,
      "y": 19,
      "z": 0,
      "name": "Wood_Crystal_Trunk"
    },
    {
      "x": 3,
      "y": 20,
      "z": 0,
      "name": "Wood_Crystal_Trunk"
    },
    {
      "x": 3,
      "y": 21,
      "z": 0,
      "name": "Wood_Crystal_Trunk"
    },
    {
      "x": 3,
      "y": 22,
      "z": 0,
      "name": "Wood_Crystal_Trunk"
    },
    {
      "x": 3,
      "y": 23,
      "z": 0,
      "name": "Wood_Crystal_Trunk"
    },
    {
      "x": 3,
      "y": 24,
      "z": 0,
      "name": "Wood_Crystal_Trunk"
    },
    {
      "x": 3,
      "y": 25,
      "z": 0,
      "name": "Wood_Crystal_Trunk"
    },
    {
      "x": 3,
      "y": 26,
      "z": 0,
      "name": "Wood_Crystal_Trunk_Full"
    },
    {
      "x": 3,
      "y": 12,
      "z": 1,
      "name": "Wood_Crystal_Roots"
    },
    {
      "x": 3,
      "y": 13,
      "z": 1,
      "name": "Wood_Crystal_Trunk"
    },
    {
      "x": 3,
      "y": 14,
      "z": 1,
      "name": "Wood_Crystal_Trunk"
    },
    {
      "x": 3,
      "y": 15,
      "z": 1,
      "name": "Rock_Crystal_Pink_Block"
    },
    {
      "x": 3,
      "y": 16,
      "z": 1,
      "name": "Rock_Crystal_Pink_Block"
    },
    {
      "x": 3,
      "y": 17,
      "z": 1,
      "name": "Rock_Crystal_Pink_Block"
    },
    {
      "x": 3,
      "y": 18,
      "z": 1,
      "name": "Rock_Crystal_Pink_Block"
    },
    {
      "x": 3,
      "y": 19,
      "z": 1,
      "name": "Wood_Crystal_Trunk"
    },
    {
      "x": 3,
      "y": 20,
      "z": 1,
      "name": "Wood_Crystal_Trunk"
    },
    {
      "x": 3,
      "y": 21,
      "z": 1,
      "name": "Wood_Crystal_Trunk"
    },
    {
      "x": 3,
      "y": 22,
      "z": 1,
      "name": "Wood_Crystal_Trunk"
    },
    {
      "x": 3,
      "y": 23,
      "z": 1,
      "name": "Wood_Crystal_Trunk"
    },
    {
      "x": 3,
      "y": 24,
      "z": 1,
      "name": "Wood_Crystal_Trunk"
    },
    {
      "x": 3,
      "y": 25,
      "z": 1,
      "name": "Wood_Crystal_Trunk_Full"
    },
    {
      "x": 3,
      "y": 12,
      "z": 2,
      "name": "Wood_Crystal_Roots"
    },
    {
      "x": 3,
      "y": 13,
      "z": 2,
      "name": "Wood_Crystal_Trunk"
    },
    {
      "x": 3,
      "y": 14,
      "z": 2,
      "name": "Wood_Crystal_Trunk"
    },
    {
      "x": 3,
      "y": 15,
      "z": 2,
      "name": "Wood_Crystal_Trunk"
    },
    {
      "x": 3,
      "y": 16,
      "z": 2,
      "name": "Wood_Crystal_Trunk"
    },
    {
      "x": 3,
      "y": 17,
      "z": 2,
      "name": "Wood_Crystal_Trunk"
    },
    {
      "x": 3,
      "y": 18,
      "z": 2,
      "name": "Wood_Crystal_Trunk"
    },
    {
      "x": 3,
      "y": 19,
      "z": 2,
      "name": "Wood_Crystal_Trunk"
    },
    {
      "x": 3,
      "y": 20,
      "z": 2,
      "name": "Wood_Crystal_Trunk"
    },
    {
      "x": 3,
      "y": 21,
      "z": 2,
      "name": "Wood_Crystal_Trunk"
    },
    {
      "x": 3,
      "y": 22,
      "z": 2,
      "name": "Wood_Crystal_Trunk"
    },
    {
      "x": 3,
      "y": 23,
      "z": 2,
      "name": "Wood_Crystal_Trunk_Full"
    },
    {
      "x": 3,
      "y": 14,
      "z": 3,
      "name": "Wood_Crystal_Trunk"
    },
    {
      "x": 3,
      "y": 15,
      "z": 3,
      "name": "Wood_Crystal_Trunk"
    },
    {
      "x": 3,
      "y": 16,
      "z": 3,
      "name": "Wood_Crystal_Trunk_Full"
    },
    {
      "x": 3,
      "y": 20,
      "z": 3,
      "name": "Wood_Crystal_Trunk_Full"
    },
    {
      "x": 3,
      "y": 21,
      "z": 3,
      "name": "Wood_Crystal_Trunk_Full"
    },
    {
      "x": 3,
      "y": 22,
      "z": 4,
      "name": "Plant_Leaves_Crystal"
    },
    {
      "x": 3,
      "y": 23,
      "z": 4,
      "name": "Plant_Leaves_Crystal"
    },
    {
      "x": 3,
      "y": 26,
      "z": 4,
      "name": "Wood_Crystal_Trunk_Full"
    },
    {
      "x": 3,
      "y": 27,
      "z": 4,
      "name": "Wood_Crystal_Trunk_Full"
    },
    {
      "x": 3,
      "y": 22,
      "z": 5,
      "name": "Plant_Leaves_Crystal"
    },
    {
      "x": 3,
      "y": 23,
      "z": 5,
      "name": "Plant_Leaves_Crystal"
    },
    {
      "x": 3,
      "y": 27,
      "z": 5,
      "name": "Wood_Crystal_Trunk_Full"
    },
    {
      "x": 3,
      "y": 28,
      "z": 5,
      "name": "Wood_Crystal_Trunk_Full"
    },
    {
      "x": 3,
      "y": 30,
      "z": 5,
      "name": "Plant_Leaves_Crystal"
    },
    {
      "x": 3,
      "y": 21,
      "z": 6,
      "name": "Plant_Leaves_Crystal"
    },
    {
      "x": 3,
      "y": 22,
      "z": 6,
      "name": "Plant_Leaves_Crystal"
    },
    {
      "x": 3,
      "y": 23,
      "z": 6,
      "name": "Plant_Leaves_Crystal"
    },
    {
      "x": 3,
      "y": 27,
      "z": 6,
      "name": "Wood_Crystal_Trunk_Full"
    },
    {
      "x": 3,
      "y": 28,
      "z": 6,
      "name": "Wood_Crystal_Trunk_Full"
    },
    {
      "x": 3,
      "y": 30,
      "z": 6,
      "name": "Plant_Leaves_Crystal"
    },
    {
      "x": 3,
      "y": 21,
      "z": 7,
      "name": "Plant_Leaves_Crystal"
    },
    {
      "x": 3,
      "y": 22,
      "z": 7,
      "name": "Plant_Leaves_Crystal"
    },
    {
      "x": 3,
      "y": 30,
      "z": 7,
      "name": "Plant_Leaves_Crystal"
    },
    {
      "x": 3,
      "y": 31,
      "z": 7,
      "name": "Plant_Leaves_Crystal"
    },
    {
      "x": 3,
      "y": 22,
      "z": 8,
      "name": "Plant_Leaves_Crystal"
    },
    {
      "x": 3,
      "y": 29,
      "z": 8,
      "name": "Plant_Leaves_Crystal"
    },
    {
      "x": 3,
      "y": 30,
      "z": 8,
      "name": "Plant_Leaves_Crystal"
    },
    {
      "x": 3,
      "y": 31,
      "z": 8,
      "name": "Plant_Leaves_Crystal"
    },
    {
      "x": 3,
      "y": 22,
      "z": 9,
      "name": "Plant_Leaves_Crystal"
    },
    {
      "x": 3,
      "y": 28,
      "z": 9,
      "name": "Plant_Fruit_Pinkberry",
      "rotation": 8
    },
    {
      "x": 3,
      "y": 29,
      "z": 9,
      "name": "Plant_Leaves_Crystal"
    },
    {
      "x": 3,
      "y": 30,
      "z": 9,
      "name": "Plant_Leaves_Crystal"
    },
    {
      "x": 3,
      "y": 29,
      "z": 10,
      "name": "Plant_Leaves_Crystal"
    },
    {
      "x": 3,
      "y": 30,
      "z": 10,
      "name": "Plant_Leaves_Crystal"
    },
    {
      "x": 3,
      "y": 29,
      "z": 11,
      "name": "Plant_Leaves_Crystal"
    },
    {
      "x": 3,
      "y": 30,
      "z": 11,
      "name": "Plant_Leaves_Crystal"
    },
    {
      "x": 3,
      "y": 31,
      "z": 11,
      "name": "Plant_Leaves_Crystal"
    },
    {
      "x": 3,
      "y": 29,
      "z": 12,
      "name": "Plant_Leaves_Crystal"
    },
    {
      "x": 3,
      "y": 29,
      "z": 13,
      "name": "Plant_Leaves_Crystal"
    },
    {
      "x": 4,
      "y": 29,
      "z": -11,
      "name": "Plant_Leaves_Crystal"
    },
    {
      "x": 4,
      "y": 28,
      "z": -10,
      "name": "Plant_Leaves_Crystal"
    },
    {
      "x": 4,
      "y": 29,
      "z": -10,
      "name": "Plant_Leaves_Crystal"
    },
    {
      "x": 4,
      "y": 27,
      "z": -9,
      "name": "Plant_Fruit_Pinkberry",
      "rotation": 8
    },
    {
      "x": 4,
      "y": 28,
      "z": -9,
      "name": "Plant_Leaves_Crystal"
    },
    {
      "x": 4,
      "y": 29,
      "z": -9,
      "name": "Plant_Leaves_Crystal"
    },
    {
      "x": 4,
      "y": 30,
      "z": -9,
      "name": "Plant_Leaves_Crystal"
    },
    {
      "x": 4,
      "y": 28,
      "z": -8,
      "name": "Plant_Leaves_Crystal"
    },
    {
      "x": 4,
      "y": 30,
      "z": -8,
      "name": "Plant_Leaves_Crystal"
    },
    {
      "x": 4,
      "y": 31,
      "z": -8,
      "name": "Plant_Leaves_Crystal"
    },
    {
      "x": 4,
      "y": 28,
      "z": -7,
      "name": "Wood_Crystal_Trunk_Full"
    },
    {
      "x": 4,
      "y": 29,
      "z": -7,
      "name": "Plant_Leaves_Crystal"
    },
    {
      "x": 4,
      "y": 30,
      "z": -7,
      "name": "Plant_Leaves_Crystal"
    },
    {
      "x": 4,
      "y": 31,
      "z": -7,
      "name": "Plant_Leaves_Crystal"
    },
    {
      "x": 4,
      "y": 28,
      "z": -6,
      "name": "Wood_Crystal_Trunk_Full"
    },
    {
      "x": 4,
      "y": 29,
      "z": -6,
      "name": "Plant_Leaves_Crystal"
    },
    {
      "x": 4,
      "y": 30,
      "z": -6,
      "name": "Plant_Leaves_Crystal"
    },
    {
      "x": 4,
      "y": 31,
      "z": -6,
      "name": "Plant_Leaves_Crystal"
    },
    {
      "x": 4,
      "y": 21,
      "z": -5,
      "name": "Plant_Leaves_Crystal"
    },
    {
      "x": 4,
      "y": 22,
      "z": -5,
      "name": "Plant_Leaves_Crystal"
    },
    {
      "x": 4,
      "y": 28,
      "z": -5,
      "name": "Wood_Crystal_Trunk_Full"
    },
    {
      "x": 4,
      "y": 31,
      "z": -5,
      "name": "Plant_Leaves_Crystal"
    },
    {
      "x": 4,
      "y": 22,
      "z": -4,
      "name": "Plant_Leaves_Crystal"
    },
    {
      "x": 4,
      "y": 22,
      "z": -3,
      "name": "Plant_Leaves_Crystal"
    },
    {
      "x": 4,
      "y": 23,
      "z": -3,
      "name": "Plant_Leaves_Crystal"
    },
    {
      "x": 4,
      "y": 27,
      "z": -3,
      "name": "Wood_Crystal_Trunk_Full"
    },
    {
      "x": 4,
      "y": 20,
      "z": -2,
      "name": "Plant_Fruit_Pinkberry",
      "rotation": 8
    },
    {
      "x": 4,
      "y": 21,
      "z": -2,
      "name": "Plant_Leaves_Crystal"
    },
    {
      "x": 4,
      "y": 22,
      "z": -2,
      "name": "Plant_Leaves_Crystal"
    },
    {
      "x": 4,
      "y": 25,
      "z": -2,
      "name": "Wood_Crystal_Trunk_Full"
    },
    {
      "x": 4,
      "y": 26,
      "z": -2,
      "name": "Wood_Crystal_Trunk"
    },
    {
      "x": 4,
      "y": 27,
      "z": -2,
      "name": "Wood_Crystal_Trunk_Full"
    },
    {
      "x": 4,
      "y": 13,
      "z": -1,
      "name": "Wood_Crystal_Trunk"
    },
    {
      "x": 4,
      "y": 14,
      "z": -1,
      "name": "Wood_Crystal_Trunk"
    },
    {
      "x": 4,
      "y": 15,
      "z": -1,
      "name": "Wood_Crystal_Trunk"
    },
    {
      "x": 4,
      "y": 20,
      "z": -1,
      "name": "Plant_Fruit_Pinkberry",
      "rotation": 8
    },
    {
      "x": 4,
      "y": 21,
      "z": -1,
      "name": "Plant_Leaves_Crystal"
    },
    {
      "x": 4,
      "y": 22,
      "z": -1,
      "name": "Plant_Leaves_Crystal"
    },
    {
      "x": 4,
      "y": 24,
      "z": -1,
      "name": "Wood_Crystal_Trunk_Full"
    },
    {
      "x": 4,
      "y": 25,
      "z": -1,
      "name": "Wood_Crystal_Trunk"
    },
    {
      "x": 4,
      "y": 26,
      "z": -1,
      "name": "Wood_Crystal_Trunk_Full"
    },
    {
      "x": 4,
      "y": 14,
      "z": 0,
      "name": "Wood_Crystal_Trunk"
    },
    {
      "x": 4,
      "y": 15,
      "z": 0,
      "name": "Wood_Crystal_Trunk"
    },
    {
      "x": 4,
      "y": 16,
      "z": 0,
      "name": "Rock_Crystal_Pink_Small"
    },
    {
      "x": 4,
      "y": 18,
      "z": 0,
      "name": "Rock_Crystal_Pink_Small",
      "rotation": 8
    },
    {
      "x": 4,
      "y": 19,
      "z": 0,
      "name": "Wood_Crystal_Trunk"
    },
    {
      "x": 4,
      "y": 20,
      "z": 0,
      "name": "Wood_Crystal_Trunk_Full"
    },
    {
      "x": 4,
      "y": 23,
      "z": 0,
      "name": "Wood_Crystal_Trunk_Full"
    },
    {
      "x": 4,
      "y": 24,
      "z": 0,
      "name": "Wood_Crystal_Trunk"
    },
    {
      "x": 4,
      "y": 25,
      "z": 0,
      "name": "Wood_Crystal_Trunk"
    },
    {
      "x": 4,
      "y": 26,
      "z": 0,
      "name": "Wood_Crystal_Trunk"
    },
    {
      "x": 4,
      "y": 27,
      "z": 0,
      "name": "Wood_Crystal_Trunk_Full"
    },
    {
      "x": 4,
      "y": 12,
      "z": 1,
      "name": "Wood_Crystal_Trunk"
    },
    {
      "x": 4,
      "y": 13,
      "z": 1,
      "name": "Wood_Crystal_Trunk"
    },
    {
      "x": 4,
      "y": 14,
      "z": 1,
      "name": "Wood_Crystal_Trunk"
    },
    {
      "x": 4,
      "y": 15,
      "z": 1,
      "name": "Rock_Crystal_Pink_Large"
    },
    {
      "x": 4,
      "y": 18,
      "z": 1,
      "name": "Wood_Crystal_Trunk"
    },
    {
      "x": 4,
      "y": 19,
      "z": 1,
      "name": "Wood_Crystal_Trunk_Full"
    },
    {
      "x": 4,
      "y": 22,
      "z": 1,
      "name": "Wood_Crystal_Trunk_Full"
    },
    {
      "x": 4,
      "y": 23,
      "z": 1,
      "name": "Wood_Crystal_Trunk"
    },
    {
      "x": 4,
      "y": 24,
      "z": 1,
      "name": "Wood_Crystal_Trunk"
    },
    {
      "x": 4,
      "y": 25,
      "z": 1,
      "name": "Wood_Crystal_Trunk"
    },
    {
      "x": 4,
      "y": 26,
      "z": 1,
      "name": "Wood_Crystal_Trunk_Full"
    },
    {
      "x": 4,
      "y": 12,
      "z": 2,
      "name": "Wood_Crystal_Trunk"
    },
    {
      "x": 4,
      "y": 13,
      "z": 2,
      "name": "Wood_Crystal_Trunk"
    },
    {
      "x": 4,
      "y": 14,
      "z": 2,
      "name": "Wood_Crystal_Trunk"
    },
    {
      "x": 4,
      "y": 15,
      "z": 2,
      "name": "Wood_Crystal_Trunk"
    },
    {
      "x": 4,
      "y": 16,
      "z": 2,
      "name": "Wood_Crystal_Trunk"
    },
    {
      "x": 4,
      "y": 21,
      "z": 2,
      "name": "Plant_Leaves_Crystal"
    },
    {
      "x": 4,
      "y": 25,
      "z": 2,
      "name": "Wood_Crystal_Trunk_Full"
    },
    {
      "x": 4,
      "y": 12,
      "z": 3,
      "name": "Wood_Crystal_Trunk"
    },
    {
      "x": 4,
      "y": 13,
      "z": 3,
      "name": "Wood_Crystal_Trunk"
    },
    {
      "x": 4,
      "y": 14,
      "z": 3,
      "name": "Wood_Crystal_Trunk_Full"
    },
    {
      "x": 4,
      "y": 21,
      "z": 3,
      "name": "Plant_Leaves_Crystal"
    },
    {
      "x": 4,
      "y": 25,
      "z": 3,
      "name": "Wood_Crystal_Trunk_Full"
    },
    {
      "x": 4,
      "y": 26,
      "z": 3,
      "name": "Wood_Crystal_Trunk"
    },
    {
      "x": 4,
      "y": 27,
      "z": 3,
      "name": "Wood_Crystal_Trunk_Full"
    },
    {
      "x": 4,
      "y": 21,
      "z": 4,
      "name": "Wood_Crystal_Trunk_Full"
    },
    {
      "x": 4,
      "y": 22,
      "z": 4,
      "name": "Plant_Leaves_Crystal"
    },
    {
      "x": 4,
      "y": 23,
      "z": 4,
      "name": "Plant_Leaves_Crystal"
    },
    {
      "x": 4,
      "y": 27,
      "z": 4,
      "name": "Wood_Crystal_Trunk_Full"
    },
    {
      "x": 4,
      "y": 21,
      "z": 5,
      "name": "Wood_Crystal_Trunk_Full"
    },
    {
      "x": 4,
      "y": 22,
      "z": 5,
      "name": "Plant_Leaves_Crystal"
    },
    {
      "x": 4,
      "y": 23,
      "z": 5,
      "name": "Plant_Leaves_Crystal"
    },
    {
      "x": 4,
      "y": 21,
      "z": 6,
      "name": "Wood_Crystal_Trunk_Full"
    },
    {
      "x": 4,
      "y": 22,
      "z": 6,
      "name": "Plant_Leaves_Crystal"
    },
    {
      "x": 4,
      "y": 23,
      "z": 6,
      "name": "Plant_Leaves_Crystal"
    },
    {
      "x": 4,
      "y": 27,
      "z": 6,
      "name": "Wood_Crystal_Trunk_Full"
    },
    {
      "x": 4,
      "y": 28,
      "z": 6,
      "name": "Wood_Crystal_Trunk_Full"
    },
    {
      "x": 4,
      "y": 31,
      "z": 6,
      "name": "Plant_Leaves_Crystal"
    },
    {
      "x": 4,
      "y": 21,
      "z": 7,
      "name": "Plant_Leaves_Crystal"
    },
    {
      "x": 4,
      "y": 22,
      "z": 7,
      "name": "Plant_Leaves_Crystal"
    },
    {
      "x": 4,
      "y": 28,
      "z": 7,
      "name": "Wood_Crystal_Trunk_Full"
    },
    {
      "x": 4,
      "y": 29,
      "z": 7,
      "name": "Plant_Leaves_Crystal"
    },
    {
      "x": 4,
      "y": 30,
      "z": 7,
      "name": "Plant_Leaves_Crystal"
    },
    {
      "x": 4,
      "y": 31,
      "z": 7,
      "name": "Plant_Leaves_Crystal"
    },
    {
      "x": 4,
      "y": 22,
      "z": 8,
      "name": "Plant_Leaves_Crystal"
    },
    {
      "x": 4,
      "y": 28,
      "z": 8,
      "name": "Wood_Crystal_Trunk_Full"
    },
    {
      "x": 4,
      "y": 29,
      "z": 8,
      "name": "Plant_Leaves_Crystal"
    },
    {
      "x": 4,
      "y": 30,
      "z": 8,
      "name": "Plant_Leaves_Crystal"
    },
    {
      "x": 4,
      "y": 31,
      "z": 8,
      "name": "Plant_Leaves_Crystal"
    },
    {
      "x": 4,
      "y": 22,
      "z": 9,
      "name": "Plant_Leaves_Crystal"
    },
    {
      "x": 4,
      "y": 28,
      "z": 9,
      "name": "Plant_Leaves_Crystal"
    },
    {
      "x": 4,
      "y": 30,
      "z": 9,
      "name": "Plant_Leaves_Crystal"
    },
    {
      "x": 4,
      "y": 31,
      "z": 9,
      "name": "Plant_Leaves_Crystal"
    },
    {
      "x": 4,
      "y": 27,
      "z": 10,
      "name": "Plant_Fruit_Pinkberry",
      "rotation": 8
    },
    {
      "x": 4,
      "y": 28,
