{
  "version": 8,
  "blockIdVersion": 8,
  "anchorX": -2,
  "anchorY": 0,
  "anchorZ": -1,
  "blocks": [
    {
      "x": -6,
      "y": 0,
      "z": -8,
      "name": "Rock_Sandstone"
    },
    {
      "x": -6,
      "y": 1,
      "z": -8,
      "name": "Rock_Sandstone_Brick_Pillar_Base"
    },
    {
      "x": -6,
      "y": 2,
      "z": -8,
      "name": "Rock_Sandstone_Brick_Pillar_Middle"
    },
    {
      "x": -6,
      "y": 3,
      "z": -8,
      "name": "Rock_Sandstone_Brick_Pillar_Middle"
    },
    {
      "x": -6,
      "y": 4,
      "z": -8,
      "name": "Rock_Sandstone_Brick_Pillar_Base",
      "rotation": 8
    },
    {
      "x": -6,
      "y": 5,
      "z": -8,
      "name": "Rock_Sandstone_Brick"
    },
    {
      "x": -6,
      "y": 6,
      "z": -8,
      "name": "Rock_Sandstone_Cobble"
    },
    {
      "x": -6,
      "y": 0,
      "z": -7,
      "name": "Rock_Sandstone"
    },
    {
      "x": -6,
      "y": 1,
      "z": -7,
      "name": "Empty"
    },
    {
      "x": -6,
      "y": 2,
      "z": -7,
      "name": "Empty"
    },
    {
      "x": -6,
      "y": 3,
      "z": -7,
      "name": "Empty"
    },
    {
      "x": -6,
      "y": 4,
      "z": -7,
      "name": "Empty"
    },
    {
      "x": -6,
      "y": 5,
      "z": -7,
      "name": "Rock_Sandstone_Brick"
    },
    {
      "x": -6,
      "y": 6,
      "z": -7,
      "name": "Rock_Sandstone_Cobble"
    },
    {
      "x": -6,
      "y": 0,
      "z": -6,
      "name": "Rock_Sandstone"
    },
    {
      "x": -6,
      "y": 1,
      "z": -6,
      "name": "Empty"
    },
    {
      "x": -6,
      "y": 2,
      "z": -6,
      "name": "Empty"
    },
    {
      "x": -6,
      "y": 3,
      "z": -6,
      "name": "Empty"
    },
    {
      "x": -6,
      "y": 4,
      "z": -6,
      "name": "Empty"
    },
    {
      "x": -6,
      "y": 5,
      "z": -6,
      "name": "Rock_Sandstone_Brick"
    },
    {
      "x": -6,
      "y": 6,
      "z": -6,
      "name": "Rock_Sandstone_Cobble"
    },
    {
      "x": -6,
      "y": 0,
      "z": -5,
      "name": "Rock_Sandstone"
    },
    {
      "x": -6,
      "y": 1,
      "z": -5,
      "name": "Rock_Sandstone_Brick_Pillar_Base"
    },
    {
      "x": -6,
      "y": 2,
      "z": -5,
      "name": "Rock_Sandstone_Brick_Pillar_Middle"
    },
    {
      "x": -6,
      "y": 3,
      "z": -5,
      "name": "Rock_Sandstone_Brick_Pillar_Middle"
    },
    {
      "x": -6,
      "y": 4,
      "z": -5,
      "name": "Rock_Sandstone_Brick_Pillar_Base",
      "rotation": 8
    },
    {
      "x": -6,
      "y": 5,
      "z": -5,
      "name": "Rock_Sandstone_Brick"
    },
    {
      "x": -6,
      "y": 6,
      "z": -5,
      "name": "Rock_Sandstone_Cobble"
    },
    {
      "x": -6,
      "y": 0,
      "z": -4,
      "name": "Rock_Sandstone"
    },
    {
      "x": -6,
      "y": 1,
      "z": -4,
      "name": "Furniture_Village_Crate"
    },
    {
      "x": -6,
      "y": 2,
      "z": -4,
      "name": "Empty"
    },
    {
      "x": -6,
      "y": 3,
      "z": -4,
      "name": "Empty"
    },
    {
      "x": -6,
      "y": 4,
      "z": -4,
      "name": "Empty"
    },
    {
      "x": -6,
      "y": 5,
      "z": -4,
      "name": "Rock_Sandstone_Brick"
    },
    {
      "x": -6,
      "y": 6,
      "z": -4,
      "name": "Rock_Sandstone_Brick"
    },
    {
      "x": -6,
      "y": 0,
      "z": -3,
      "name": "Rock_Sandstone"
    },
    {
      "x": -6,
      "y": 1,
      "z": -3,
      "name": "Furniture_Village_Crate"
    },
    {
      "x": -6,
      "y": 2,
      "z": -3,
      "name": "Empty"
    },
    {
      "x": -6,
      "y": 3,
      "z": -3,
      "name": "Empty"
    },
    {
      "x": -6,
      "y": 4,
      "z": -3,
      "name": "Empty"
    },
    {
      "x": -6,
      "y": 5,
      "z": -3,
      "name": "Rock_Sandstone_Brick"
    },
    {
      "x": -6,
      "y": 6,
      "z": -3,
      "name": "Rock_Sandstone_Brick"
    },
    {
      "x": -6,
      "y": 0,
      "z": -2,
      "name": "Rock_Sandstone"
    },
    {
      "x": -6,
      "y": 1,
      "z": -2,
      "name": "Rock_Sandstone_Brick_Pillar_Base"
    },
    {
      "x": -6,
      "y": 2,
      "z": -2,
      "name": "Rock_Sandstone_Brick_Pillar_Middle"
    },
    {
      "x": -6,
      "y": 3,
      "z": -2,
      "name": "Rock_Sandstone_Brick_Pillar_Middle"
    },
    {
      "x": -6,
      "y": 4,
      "z": -2,
      "name": "Rock_Sandstone_Brick_Pillar_Base",
      "rotation": 8
    },
    {
      "x": -6,
      "y": 5,
      "z": -2,
      "name": "Rock_Sandstone_Brick"
    },
    {
      "x": -6,
      "y": 6,
      "z": -2,
      "name": "Rock_Sandstone_Brick"
    },
    {
      "x": -6,
      "y": 0,
      "z": -1,
      "name": "Rock_Sandstone_Brick"
    },
    {
      "x": -6,
      "y": 1,
      "z": -1,
      "name": "Rock_Sandstone_Brick"
    },
    {
      "x": -6,
      "y": 2,
      "z": -1,
      "name": "Rock_Sandstone_Brick"
    },
    {
      "x": -6,
      "y": 3,
      "z": -1,
      "name": "Rock_Sandstone_Brick"
    },
    {
      "x": -6,
      "y": 4,
      "z": -1,
      "name": "Rock_Sandstone_Brick"
    },
    {
      "x": -6,
      "y": 5,
      "z": -1,
      "name": "Rock_Sandstone_Brick"
    },
    {
      "x": -6,
      "y": 6,
      "z": -1,
      "name": "Rock_Sandstone_Brick"
    },
    {
      "x": -6,
      "y": 0,
      "z": 0,
      "name": "Rock_Sandstone_Brick"
    },
    {
      "x": -6,
      "y": 1,
      "z": 0,
      "name": "Rock_Sandstone_Brick"
    },
    {
      "x": -6,
      "y": 2,
      "z": 0,
      "name": "Rock_Sandstone_Brick"
    },
    {
      "x": -6,
      "y": 3,
      "z": 0,
      "name": "Rock_Sandstone_Brick"
    },
    {
      "x": -6,
      "y": 4,
      "z": 0,
      "name": "Rock_Sandstone_Brick"
    },
    {
      "x": -6,
      "y": 5,
      "z": 0,
      "name": "Rock_Sandstone_Brick"
    },
    {
      "x": -6,
      "y": 6,
      "z": 0,
      "name": "Rock_Sandstone_Cobble"
    },
    {
      "x": -6,
      "y": 0,
      "z": 1,
      "name": "Rock_Sandstone_Brick"
    },
    {
      "x": -6,
      "y": 1,
      "z": 1,
      "name": "Rock_Sandstone_Brick"
    },
    {
      "x": -6,
      "y": 2,
      "z": 1,
      "name": "Rock_Sandstone_Brick"
    },
    {
      "x": -6,
      "y": 3,
      "z": 1,
      "name": "Rock_Sandstone_Brick"
    },
    {
      "x": -6,
      "y": 4,
      "z": 1,
      "name": "Rock_Sandstone_Brick"
    },
    {
      "x": -6,
      "y": 5,
      "z": 1,
      "name": "Rock_Sandstone_Brick"
    },
    {
      "x": -6,
      "y": 6,
      "z": 1,
      "name": "Rock_Sandstone_Cobble"
    },
    {
      "x": -6,
      "y": 0,
      "z": 2,
      "name": "Rock_Sandstone"
    },
    {
      "x": -6,
      "y": 1,
      "z": 2,
      "name": "Rock_Sandstone_Brick_Pillar_Base"
    },
    {
      "x": -6,
      "y": 2,
      "z": 2,
      "name": "Rock_Sandstone_Brick_Pillar_Middle"
    },
    {
      "x": -6,
      "y": 3,
      "z": 2,
      "name": "Rock_Sandstone_Brick_Pillar_Middle"
    },
    {
      "x": -6,
      "y": 4,
      "z": 2,
      "name": "Rock_Sandstone_Brick_Pillar_Base",
      "rotation": 8
    },
    {
      "x": -6,
      "y": 5,
      "z": 2,
      "name": "Rock_Sandstone_Brick"
    },
    {
      "x": -6,
      "y": 6,
      "z": 2,
      "name": "Rock_Sandstone_Cobble"
    },
    {
      "x": -6,
      "y": 0,
      "z": 3,
      "name": "Rock_Sandstone"
    },
    {
      "x": -6,
      "y": 1,
      "z": 3,
      "name": "Furniture_Village_Crate"
    },
    {
      "x": -6,
      "y": 2,
      "z": 3,
      "name": "Empty"
    },
    {
      "x": -6,
      "y": 3,
      "z": 3,
      "name": "Empty"
    },
    {
      "x": -6,
      "y": 4,
      "z": 3,
      "name": "Empty"
    },
    {
      "x": -6,
      "y": 5,
      "z": 3,
      "name": "Rock_Sandstone_Brick"
    },
    {
      "x": -6,
      "y": 6,
      "z": 3,
      "name": "Rock_Sandstone_Cobble"
    },
    {
      "x": -6,
      "y": 0,
      "z": 4,
      "name": "Rock_Sandstone"
    },
    {
      "x": -6,
      "y": 1,
      "z": 4,
      "name": "Furniture_Village_Pot"
    },
    {
      "x": -6,
      "y": 2,
      "z": 4,
      "name": "Empty"
    },
    {
      "x": -6,
      "y": 3,
      "z": 4,
      "name": "Empty"
    },
    {
      "x": -6,
      "y": 4,
      "z": 4,
      "name": "Empty"
    },
    {
      "x": -6,
      "y": 5,
      "z": 4,
      "name": "Rock_Sandstone_Brick"
    },
    {
      "x": -6,
      "y": 6,
      "z": 4,
      "name": "Rock_Sandstone_Brick"
    },
    {
      "x": -6,
      "y": 0,
      "z": 5,
      "name": "Rock_Sandstone"
    },
    {
      "x": -6,
      "y": 1,
      "z": 5,
      "name": "Rock_Sandstone"
    },
    {
      "x": -6,
      "y": 2,
      "z": 5,
      "name": "Rock_Sandstone"
    },
    {
      "x": -6,
      "y": 3,
      "z": 5,
      "name": "Rock_Sandstone"
    },
    {
      "x": -6,
      "y": 4,
      "z": 5,
      "name": "Rock_Sandstone"
    },
    {
      "x": -6,
      "y": 5,
      "z": 5,
      "name": "Rock_Sandstone"
    },
    {
      "x": -6,
      "y": 6,
      "z": 5,
      "name": "Rock_Sandstone"
    },
    {
      "x": -6,
      "y": 0,
      "z": 6,
      "name": "Rock_Sandstone"
    },
    {
      "x": -6,
      "y": 1,
      "z": 6,
      "name": "Rock_Sandstone"
    },
    {
      "x": -6,
      "y": 2,
      "z": 6,
      "name": "Rock_Sandstone"
    },
    {
      "x": -6,
      "y": 3,
      "z": 6,
      "name": "Rock_Sandstone"
    },
    {
      "x": -6,
      "y": 4,
      "z": 6,
      "name": "Rock_Sandstone"
    },
    {
      "x": -6,
      "y": 5,
      "z": 6,
      "name": "Rock_Sandstone"
    },
    {
      "x": -6,
      "y": 6,
      "z": 6,
      "name": "Rock_Sandstone"
    },
    {
      "x": -6,
      "y": 0,
      "z": 7,
      "name": "Rock_Sandstone"
    },
    {
      "x": -6,
      "y": 1,
      "z": 7,
      "name": "Rock_Sandstone"
    },
    {
      "x": -6,
      "y": 2,
      "z": 7,
      "name": "Rock_Sandstone"
    },
    {
      "x": -6,
      "y": 3,
      "z": 7,
      "name": "Rock_Sandstone"
    },
    {
      "x": -6,
      "y": 4,
      "z": 7,
      "name": "Rock_Sandstone"
    },
    {
      "x": -6,
      "y": 5,
      "z": 7,
      "name": "Rock_Sandstone"
    },
    {
      "x": -6,
      "y": 6,
      "z": 7,
      "name": "Rock_Sandstone"
    },
    {
      "x": -6,
      "y": 0,
      "z": 8,
      "name": "Rock_Sandstone"
    },
    {
      "x": -6,
      "y": 1,
      "z": 8,
      "name": "Rock_Sandstone"
    },
    {
      "x": -6,
      "y": 2,
      "z": 8,
      "name": "Rock_Sandstone"
    },
    {
      "x": -6,
      "y": 3,
      "z": 8,
      "name": "Rock_Sandstone"
    },
    {
      "x": -6,
      "y": 4,
      "z": 8,
      "name": "Rock_Sandstone"
    },
    {
      "x": -6,
      "y": 5,
      "z": 8,
      "name": "Rock_Sandstone"
    },
    {
      "x": -5,
      "y": 0,
      "z": -8,
      "name": "Rock_Sandstone"
    },
    {
      "x": -5,
      "y": 1,
      "z": -8,
      "name": "Rock_Sandstone"
    },
    {
      "x": -5,
      "y": 2,
      "z": -8,
      "name": "Rock_Sandstone"
    },
    {
      "x": -5,
      "y": 3,
      "z": -8,
      "name": "Empty"
    },
    {
      "x": -5,
      "y": 4,
      "z": -8,
      "name": "Empty"
    },
    {
      "x": -5,
      "y": 5,
      "z": -8,
      "name": "Rock_Sandstone_Brick"
    },
    {
      "x": -5,
      "y": 6,
      "z": -8,
      "name": "Rock_Sandstone_Cobble"
    },
    {
      "x": -5,
      "y": 0,
      "z": -7,
      "name": "Rock_Sandstone"
    },
    {
      "x": -5,
      "y": 1,
      "z": -7,
      "name": "Rock_Sandstone"
    },
    {
      "x": -5,
      "y": 2,
      "z": -7,
      "name": "Rock_Sandstone"
    },
    {
      "x": -5,
      "y": 3,
      "z": -7,
      "name": "Empty"
    },
    {
      "x": -5,
      "y": 4,
      "z": -7,
      "name": "Empty"
    },
    {
      "x": -5,
      "y": 5,
      "z": -7,
      "name": "Rock_Sandstone_Cobble_Half",
      "rotation": 8
    },
    {
      "x": -5,
      "y": 6,
      "z": -7,
      "name": "Rock_Sandstone_Cobble"
    },
    {
      "x": -5,
      "y": 0,
      "z": -6,
      "name": "Rock_Sandstone_Brick_Smooth"
    },
    {
      "x": -5,
      "y": 1,
      "z": -6,
      "name": "Empty"
    },
    {
      "x": -5,
      "y": 2,
      "z": -6,
      "name": "Empty"
    },
    {
      "x": -5,
      "y": 3,
      "z": -6,
      "name": "Empty"
    },
    {
      "x": -5,
      "y": 4,
      "z": -6,
      "name": "Empty"
    },
    {
      "x": -5,
      "y": 5,
      "z": -6,
      "name": "Rock_Sandstone_Cobble_Half",
      "rotation": 8
    },
    {
      "x": -5,
      "y": 6,
      "z": -6,
      "name": "Rock_Sandstone_Brick"
    },
    {
      "x": -5,
      "y": 0,
      "z": -5,
      "name": "Rock_Sandstone_Brick_Smooth"
    },
    {
      "x": -5,
      "y": 1,
      "z": -5,
      "name": "Rubble_Sandstone"
    },
    {
      "x": -5,
      "y": 2,
      "z": -5,
      "name": "Empty"
    },
    {
      "x": -5,
      "y": 3,
      "z": -5,
      "name": "Empty"
    },
    {
      "x": -5,
      "y": 4,
      "z": -5,
      "name": "Empty"
    },
    {
      "x": -5,
      "y": 5,
      "z": -5,
      "name": "Rock_Sandstone_Brick"
    },
    {
      "x": -5,
      "y": 6,
      "z": -5,
      "name": "Rock_Sandstone_Brick"
    },
    {
      "x": -5,
      "y": 0,
      "z": -4,
      "name": "Rock_Sandstone_Brick_Smooth"
    },
    {
      "x": -5,
      "y": 1,
      "z": -4,
      "name": "Furniture_Ancient_Barrel"
    },
    {
      "x": -5,
      "y": 2,
      "z": -4,
      "name": "Empty"
    },
    {
      "x": -5,
      "y": 3,
      "z": -4,
      "name": "Empty"
    },
    {
      "x": -5,
      "y": 4,
      "z": -4,
      "name": "Empty"
    },
    {
      "x": -5,
      "y": 5,
      "z": -4,
      "name": "Rock_Sandstone_Cobble_Half",
      "rotation": 8
    },
    {
      "x": -5,
      "y": 6,
      "z": -4,
      "name": "Rock_Sandstone_Brick"
    },
    {
      "x": -5,
      "y": 0,
      "z": -3,
      "name": "Rock_Sandstone_Brick_Smooth"
    },
    {
      "x": -5,
      "y": 1,
      "z": -3,
      "name": "Empty"
    },
    {
      "x": -5,
      "y": 2,
      "z": -3,
      "name": "Empty"
    },
    {
      "x": -5,
      "y": 3,
      "z": -3,
      "name": "Empty"
    },
    {
      "x": -5,
      "y": 4,
      "z": -3,
      "name": "Empty"
    },
    {
      "x": -5,
      "y": 5,
      "z": -3,
      "name": "Rock_Sandstone_Cobble_Half",
      "rotation": 8
    },
    {
      "x": -5,
      "y": 6,
      "z": -3,
      "name": "Rock_Sandstone_Brick"
    },
    {
      "x": -5,
      "y": 0,
      "z": -2,
      "name": "Rock_Sandstone_Brick_Smooth"
    },
    {
      "x": -5,
      "y": 1,
      "z": -2,
      "name": "Block_Spawner_Block",
      "components": {
        "Components": {
          "PlacedByInteraction": {
            "WhoPlacedUuid": {
              "$binary": "x9M0GYCLPG+IqIodoDzEcQ==",
              "$type": "04"
            }
          },
          "BlockSpawner": {
            "BlockSpawnerId": "Zone2_Encounters_Tier3"
          }
        }
      },
      "rotation": 1
    },
    {
      "x": -5,
      "y": 2,
      "z": -2,
      "name": "Empty"
    },
    {
      "x": -5,
      "y": 3,
      "z": -2,
      "name": "Empty"
    },
    {
      "x": -5,
      "y": 4,
      "z": -2,
      "name": "Empty"
    },
    {
      "x": -5,
      "y": 5,
      "z": -2,
      "name": "Rock_Sandstone_Cobble_Half",
      "rotation": 8
    },
    {
      "x": -5,
      "y": 6,
      "z": -2,
      "name": "Rock_Sandstone_Brick"
    },
    {
      "x": -5,
      "y": 0,
      "z": -1,
      "name": "Rock_Sandstone"
    },
    {
      "x": -5,
      "y": 1,
      "z": -1,
      "name": "Rock_Sandstone_Brick_Pillar_Base"
    },
    {
      "x": -5,
      "y": 2,
      "z": -1,
      "name": "Rock_Sandstone_Brick_Pillar_Middle"
    },
    {
      "x": -5,
      "y": 3,
      "z": -1,
      "name": "Rock_Sandstone_Brick_Pillar_Middle"
    },
    {
      "x": -5,
      "y": 4,
      "z": -1,
      "name": "Rock_Sandstone_Brick_Pillar_Base",
      "rotation": 8
    },
    {
      "x": -5,
      "y": 5,
      "z": -1,
      "name": "Rock_Sandstone_Brick"
    },
    {
      "x": -5,
      "y": 6,
      "z": -1,
      "name": "Rock_Sandstone_Brick"
    },
    {
      "x": -5,
      "y": 0,
      "z": 0,
      "name": "Rock_Sandstone"
    },
    {
      "x": -5,
      "y": 1,
      "z": 0,
      "name": "Rock_Sandstone_Brick"
    },
    {
      "x": -5,
      "y": 2,
      "z": 0,
      "name": "Rock_Sandstone_Brick"
    },
    {
      "x": -5,
      "y": 3,
      "z": 0,
      "name": "Rock_Sandstone_Brick"
    },
    {
      "x": -5,
      "y": 4,
      "z": 0,
      "name": "Rock_Sandstone_Brick"
    },
    {
      "x": -5,
      "y": 5,
      "z": 0,
      "name": "Rock_Sandstone_Brick"
    },
    {
      "x": -5,
      "y": 6,
      "z": 0,
      "name": "Rock_Sandstone_Cobble"
    },
    {
      "x": -5,
      "y": 0,
      "z": 1,
      "name": "Rock_Sandstone"
    },
    {
      "x": -5,
      "y": 1,
      "z": 1,
      "name": "Rock_Sandstone_Brick_Pillar_Base"
    },
    {
      "x": -5,
      "y": 2,
      "z": 1,
      "name": "Rock_Sandstone_Brick_Pillar_Middle"
    },
    {
      "x": -5,
      "y": 3,
      "z": 1,
      "name": "Rock_Sandstone_Brick_Pillar_Middle"
    },
    {
      "x": -5,
      "y": 4,
      "z": 1,
      "name": "Rock_Sandstone_Brick_Pillar_Base",
      "rotation": 8
    },
    {
      "x": -5,
      "y": 5,
      "z": 1,
      "name": "Rock_Sandstone_Brick"
    },
    {
      "x": -5,
      "y": 6,
      "z": 1,
      "name": "Rock_Sandstone_Cobble"
    },
    {
      "x": -5,
      "y": 0,
      "z": 2,
      "name": "Rock_Sandstone_Brick_Smooth"
    },
    {
      "x": -5,
      "y": 1,
      "z": 2,
      "name": "Furniture_Village_Crate"
    },
    {
      "x": -5,
      "y": 2,
      "z": 2,
      "name": "Furniture_Ancient_Barrel"
    },
    {
      "x": -5,
      "y": 3,
      "z": 2,
      "name": "Empty"
    },
    {
      "x": -5,
      "y": 4,
      "z": 2,
      "name": "Empty"
    },
    {
      "x": -5,
      "y": 5,
      "z": 2,
      "name": "Rock_Sandstone_Cobble_Half",
      "rotation": 8
    },
    {
      "x": -5,
      "y": 6,
      "z": 2,
      "name": "Rock_Sandstone_Brick"
    },
    {
      "x": -5,
      "y": 0,
      "z": 3,
      "name": "Rock_Sandstone_Brick_Smooth"
    },
    {
      "x": -5,
      "y": 1,
      "z": 3,
      "name": "Furniture_Village_Crate"
    },
    {
      "x": -5,
      "y": 2,
      "z": 3,
      "name": "Furniture_Ancient_Barrel"
    },
    {
      "x": -5,
      "y": 3,
      "z": 3,
      "name": "Empty"
    },
    {
      "x": -5,
      "y": 4,
      "z": 3,
      "name": "Empty"
    },
    {
      "x": -5,
      "y": 5,
      "z": 3,
      "name": "Rock_Sandstone_Cobble_Half",
      "rotation": 8
    },
    {
      "x": -5,
      "y": 6,
      "z": 3,
      "name": "Rock_Sandstone_Brick"
    },
    {
      "x": -5,
      "y": 0,
      "z": 4,
      "name": "Rock_Sandstone_Brick_Smooth"
    },
    {
      "x": -5,
      "y": 1,
      "z": 4,
      "name": "Deco_Pot_Clay_Broken"
    },
    {
      "x": -5,
      "y": 2,
      "z": 4,
      "name": "Empty"
    },
    {
      "x": -5,
      "y": 3,
      "z": 4,
      "name": "Empty"
    },
    {
      "x": -5,
      "y": 4,
      "z": 4,
      "name": "Empty"
    },
    {
      "x": -5,
      "y": 5,
      "z": 4,
      "name": "Rock_Sandstone_Cobble_Half",
      "rotation": 8
    },
    {
      "x": -5,
      "y": 6,
      "z": 4,
      "name": "Rock_Sandstone_Brick"
    },
    {
      "x": -5,
      "y": 0,
      "z": 5,
      "name": "Rock_Sandstone"
    },
    {
      "x": -5,
      "y": 1,
      "z": 5,
      "name": "Rock_Sandstone"
    },
    {
      "x": -5,
      "y": 2,
      "z": 5,
      "name": "Rock_Sandstone"
    },
    {
      "x": -5,
      "y": 3,
      "z": 5,
      "name": "Rock_Sandstone"
    },
    {
      "x": -5,
      "y": 4,
      "z": 5,
      "name": "Rock_Sandstone"
    },
    {
      "x": -5,
      "y": 5,
      "z": 5,
      "name": "Rock_Sandstone"
    },
    {
      "x": -5,
      "y": 6,
      "z": 5,
      "name": "Rock_Sandstone"
    },
    {
      "x": -5,
      "y": 0,
      "z": 6,
      "name": "Rock_Sandstone"
    },
    {
      "x": -5,
      "y": 1,
      "z": 6,
      "name": "Rock_Sandstone"
    },
    {
      "x": -5,
      "y": 2,
      "z": 6,
      "name": "Rock_Sandstone"
    },
    {
      "x": -5,
      "y": 3,
      "z": 6,
      "name": "Rock_Sandstone"
    },
    {
      "x": -5,
      "y": 4,
      "z": 6,
      "name": "Rock_Sandstone"
    },
    {
      "x": -5,
      "y": 5,
      "z": 6,
      "name": "Rock_Sandstone"
    },
    {
      "x": -5,
      "y": 6,
      "z": 6,
      "name": "Rock_Sandstone"
    },
    {
      "x": -5,
      "y": 0,
      "z": 7,
      "name": "Rock_Sandstone"
    },
    {
      "x": -5,
      "y": 1,
      "z": 7,
      "name": "Rock_Sandstone"
    },
    {
      "x": -5,
      "y": 2,
      "z": 7,
      "name": "Rock_Sandstone"
    },
    {
      "x": -5,
      "y": 3,
      "z": 7,
      "name": "Rock_Sandstone"
    },
    {
      "x": -5,
      "y": 4,
      "z": 7,
      "name": "Rock_Sandstone"
    },
    {
      "x": -5,
      "y": 5,
      "z": 7,
      "name": "Rock_Sandstone"
    },
    {
      "x": -5,
      "y": 6,
      "z": 7,
      "name": "Empty"
    },
    {
      "x": -5,
      "y": 0,
      "z": 8,
      "name": "Rock_Sandstone"
    },
    {
      "x": -5,
      "y": 1,
      "z": 8,
      "name": "Rock_Sandstone"
    },
    {
      "x": -5,
      "y": 2,
      "z": 8,
      "name": "Rock_Sandstone"
    },
    {
      "x": -5,
      "y": 3,
      "z": 8,
      "name": "Rock_Sandstone"
    },
    {
      "x": -5,
      "y": 4,
      "z": 8,
      "name": "Rock_Sandstone"
    },
    {
      "x": -4,
      "y": 0,
      "z": -8,
      "name": "Rock_Sandstone"
    },
    {
      "x": -4,
      "y": 1,
      "z": -8,
      "name": "Rock_Sandstone"
    },
    {
      "x": -4,
      "y": 2,
      "z": -8,
      "name": "Rock_Sandstone"
    },
    {
      "x": -4,
      "y": 3,
      "z": -8,
      "name": "Empty"
    },
    {
      "x": -4,
      "y": 4,
      "z": -8,
      "name": "Empty"
    },
    {
      "x": -4,
      "y": 5,
      "z": -8,
      "name": "Empty"
    },
    {
      "x": -4,
      "y": 6,
      "z": -8,
      "name": "Rock_Sandstone_Brick"
    },
    {
      "x": -4,
      "y": 0,
      "z": -7,
      "name": "Rock_Sandstone"
    },
    {
      "x": -4,
      "y": 1,
      "z": -7,
      "name": "Rock_Sandstone"
    },
    {
      "x": -4,
      "y": 2,
      "z": -7,
      "name": "Rubble_Sandstone_Medium"
    },
    {
      "x": -4,
      "y": 3,
      "z": -7,
      "name": "Empty"
    },
    {
      "x": -4,
      "y": 4,
      "z": -7,
      "name": "Empty"
    },
    {
      "x": -4,
      "y": 5,
      "z": -7,
      "name": "Rock_Sandstone_Cobble_Half",
      "rotation": 8
    },
    {
      "x": -4,
      "y": 6,
      "z": -7,
      "name": "Rock_Sandstone_Brick"
    },
    {
      "x": -4,
      "y": 0,
      "z": -6,
      "name": "Wood_Drywood_Planks"
    },
    {
      "x": -4,
      "y": 1,
      "z": -6,
      "name": "Furniture_Temple_Dark_Candle"
    },
    {
      "x": -4,
      "y": 2,
      "z": -6,
      "name": "Furniture_Temple_Dark_Candle",
      "filler": 1024
    },
    {
      "x": -4,
      "y": 3,
      "z": -6,
      "name": "Empty"
    },
    {
      "x": -4,
      "y": 4,
      "z": -6,
      "name": "Empty"
    },
    {
      "x": -4,
      "y": 5,
      "z": -6,
      "name": "Rock_Sandstone_Cobble_Half",
      "rotation": 8
    },
    {
      "x": -4,
      "y": 6,
      "z": -6,
      "name": "Rock_Sandstone_Brick"
    },
    {
      "x": -4,
      "y": 0,
      "z": -5,
      "name": "Wood_Drywood_Planks"
    },
    {
      "x": -4,
      "y": 1,
      "z": -5,
      "name": "Empty"
    },
    {
      "x": -4,
      "y": 2,
      "z": -5,
      "name": "Empty"
    },
    {
      "x": -4,
      "y": 3,
      "z": -5,
      "name": "Empty"
    },
    {
      "x": -4,
      "y": 4,
      "z": -5,
      "name": "Empty"
    },
    {
      "x": -4,
      "y": 5,
      "z": -5,
      "name": "Rock_Sandstone_Brick"
    },
    {
      "x": -4,
      "y": 6,
      "z": -5,
      "name": "Rock_Sandstone_Brick"
    },
    {
      "x": -4,
      "y": 0,
      "z": -4,
      "name": "Wood_Drywood_Planks"
    },
    {
      "x": -4,
      "y": 1,
      "z": -4,
      "name": "Empty"
    },
    {
      "x": -4,
      "y": 2,
      "z": -4,
      "name": "Empty"
    },
    {
      "x": -4,
      "y": 3,
      "z": -4,
      "name": "Empty"
    },
    {
      "x": -4,
      "y": 4,
      "z": -4,
      "name": "Empty"
    },
    {
      "x": -4,
      "y": 5,
      "z": -4,
      "name": "Rock_Sandstone_Cobble_Half",
      "rotation": 8
    },
    {
      "x": -4,
      "y": 6,
      "z": -4,
      "name": "Rock_Sandstone_Brick"
    },
    {
      "x": -4,
      "y": 0,
      "z": -3,
      "name": "Wood_Drywood_Planks"
    },
    {
      "x": -4,
      "y": 1,
      "z": -3,
      "name": "Empty"
    },
    {
      "x": -4,
      "y": 2,
      "z": -3,
      "name": "Empty"
    },
    {
      "x": -4,
      "y": 3,
      "z": -3,
      "name": "Empty"
    },
    {
      "x": -4,
      "y": 4,
      "z": -3,
      "name": "Empty"
    },
    {
      "x": -4,
      "y": 5,
      "z": -3,
      "name": "Rock_Sandstone_Cobble_Half",
      "rotation": 8
    },
    {
      "x": -4,
      "y": 6,
      "z": -3,
      "name": "Rock_Sandstone_Brick"
    },
    {
      "x": -4,
      "y": 0,
      "z": -2,
      "name": "Wood_Drywood_Planks"
    },
    {
      "x": -4,
      "y": 1,
      "z": -2,
      "name": "Empty"
    },
    {
      "x": -4,
      "y": 2,
      "z": -2,
      "name": "Empty"
    },
    {
      "x": -4,
      "y": 3,
      "z": -2,
      "name": "Empty"
    },
    {
      "x": -4,
      "y": 4,
      "z": -2,
      "name": "Empty"
    },
    {
      "x": -4,
      "y": 5,
      "z": -2,
      "name": "Rock_Sandstone_Cobble_Half",
      "rotation": 8
    },
    {
      "x": -4,
      "y": 6,
      "z": -2,
      "name": "Rock_Sandstone_Brick"
    },
    {
      "x": -4,
      "y": 0,
      "z": -1,
      "name": "Wood_Drywood_Planks"
    },
    {
      "x": -4,
      "y": 1,
      "z": -1,
      "name": "Empty"
    },
    {
      "x": -4,
      "y": 2,
      "z": -1,
      "name": "Empty"
    },
    {
      "x": -4,
      "y": 3,
      "z": -1,
      "name": "Empty"
    },
    {
      "x": -4,
      "y": 4,
      "z": -1,
      "name": "Empty"
    },
    {
      "x": -4,
      "y": 5,
      "z": -1,
      "name": "Rock_Sandstone_Brick"
    },
    {
      "x": -4,
      "y": 6,
      "z": -1,
      "name": "Rock_Sandstone_Cobble"
    },
    {
      "x": -4,
      "y": 0,
      "z": 0,
      "name": "Wood_Drywood_Planks"
    },
    {
      "x": -4,
      "y": 1,
      "z": 0,
      "name": "Rubble_Sandstone_Medium"
    },
    {
      "x": -4,
      "y": 2,
      "z": 0,
      "name": "Empty"
    },
    {
      "x": -4,
      "y": 3,
      "z": 0,
      "name": "Empty"
    },
    {
      "x": -4,
      "y": 4,
      "z": 0,
      "name": "Rock_Sandstone_Brick_Stairs",
      "rotation": 11
    },
    {
      "x": -4,
      "y": 5,
      "z": 0,
      "name": "Rock_Sandstone_Brick"
    },
    {
      "x": -4,
      "y": 6,
      "z": 0,
      "name": "Rock_Sandstone_Cobble"
    },
    {
      "x": -4,
      "y": 0,
      "z": 1,
      "name": "Wood_Drywood_Planks"
    },
    {
      "x": -4,
      "y": 1,
      "z": 1,
      "name": "Empty"
    },
    {
      "x": -4,
      "y": 2,
      "z": 1,
      "name": "Empty"
    },
    {
      "x": -4,
      "y": 3,
      "z": 1,
      "name": "Empty"
    },
    {
      "x": -4,
      "y": 4,
      "z": 1,
      "name": "Empty"
    },
    {
      "x": -4,
      "y": 5,
      "z": 1,
      "name": "Rock_Sandstone_Brick"
    },
    {
      "x": -4,
      "y": 6,
      "z": 1,
      "name": "Rock_Sandstone_Cobble"
    },
    {
      "x": -4,
      "y": 0,
      "z": 2,
      "name": "Wood_Drywood_Planks"
    },
    {
      "x": -4,
      "y": 1,
      "z": 2,
      "name": "Empty"
    },
    {
      "x": -4,
      "y": 2,
      "z": 2,
      "name": "Empty"
    },
    {
      "x": -4,
      "y": 3,
      "z": 2,
      "name": "Empty"
    },
    {
      "x": -4,
      "y": 4,
      "z": 2,
      "name": "Empty"
    },
    {
      "x": -4,
      "y": 5,
      "z": 2,
      "name": "Rock_Sandstone_Cobble_Half",
      "rotation": 8
    },
    {
      "x": -4,
      "y": 6,
      "z": 2,
      "name": "Rock_Sandstone_Brick"
    },
    {
      "x": -4,
      "y": 0,
      "z": 3,
      "name": "Wood_Drywood_Planks"
    },
    {
      "x": -4,
      "y": 1,
      "z": 3,
      "name": "Empty"
    },
    {
      "x": -4,
      "y": 2,
      "z": 3,
      "name": "Empty"
    },
    {
      "x": -4,
      "y": 3,
      "z": 3,
      "name": "Empty"
    },
    {
      "x": -4,
      "y": 4,
      "z": 3,
      "name": "Empty"
    },
    {
      "x": -4,
      "y": 5,
      "z": 3,
      "name": "Rock_Sandstone_Cobble_Half",
      "rotation": 8
    },
    {
      "x": -4,
      "y": 6,
      "z": 3,
      "name": "Rock_Sandstone_Brick"
    },
    {
      "x": -4,
      "y": 0,
      "z": 4,
      "name": "Wood_Drywood_Planks"
    },
    {
      "x": -4,
      "y": 1,
      "z": 4,
      "name": "Empty"
    },
    {
      "x": -4,
      "y": 2,
      "z": 4,
      "name": "Empty"
    },
    {
      "x": -4,
      "y": 3,
      "z": 4,
      "name": "Empty"
    },
    {
      "x": -4,
      "y": 4,
      "z": 4,
      "name": "Empty"
    },
    {
      "x": -4,
      "y": 5,
      "z": 4,
      "name": "Rock_Sandstone_Cobble_Half",
      "rotation": 8
    },
    {
      "x": -4,
      "y": 6,
      "z": 4,
      "name": "Rock_Sandstone_Brick"
    },
    {
      "x": -4,
      "y": 0,
      "z": 5,
      "name": "Wood_Drywood_Planks"
    },
    {
      "x": -4,
      "y": 1,
      "z": 5,
      "name": "Rubble_Sandstone"
    },
    {
      "x": -4,
      "y": 2,
      "z": 5,
      "name": "Empty"
    },
    {
      "x": -4,
      "y": 3,
      "z": 5,
      "name": "Empty"
    },
    {
      "x": -4,
      "y": 4,
      "z": 5,
      "name": "Empty"
    },
    {
      "x": -4,
      "y": 5,
      "z": 5,
      "name": "Rock_Sandstone_Brick"
    },
    {
      "x": -4,
      "y": 6,
      "z": 5,
      "name": "Rock_Sandstone_Brick"
    },
    {
      "x": -4,
      "y": 0,
      "z": 6,
      "name": "Rock_Sandstone"
    },
    {
      "x": -4,
      "y": 1,
      "z": 6,
      "name": "Rock_Sandstone"
    },
    {
      "x": -4,
      "y": 2,
      "z": 6,
      "name": "Rock_Sandstone"
    },
    {
      "x": -4,
      "y": 3,
      "z": 6,
      "name": "Empty"
    },
    {
      "x": -4,
      "y": 4,
      "z": 6,
      "name": "Empty"
    },
    {
      "x": -4,
      "y": 5,
      "z": 6,
      "name": "Empty"
    },
    {
      "x": -4,
      "y": 6,
      "z": 6,
      "name": "Empty"
    },
    {
      "x": -4,
      "y": 0,
      "z": 7,
      "name": "Rock_Sandstone"
    },
    {
      "x": -4,
      "y": 1,
      "z": 7,
      "name": "Rock_Sandstone"
    },
    {
      "x": -4,
      "y": 2,
      "z": 7,
      "name": "Rock_Sandstone"
    },
    {
      "x": -4,
      "y": 3,
      "z": 7,
      "name": "Empty"
    },
    {
      "x": -4,
      "y": 4,
      "z": 7,
      "name": "Empty"
    },
    {
      "x": -4,
      "y": 5,
      "z": 7,
      "name": "Empty"
    },
    {
      "x": -4,
      "y": 6,
      "z": 7,
      "name": "Empty"
    },
    {
      "x": -4,
      "y": 0,
      "z": 8,
      "name": "Rock_Sandstone"
    },
    {
      "x": -4,
      "y": 1,
      "z": 8,
      "name": "Rock_Sandstone"
    },
    {
      "x": -4,
      "y": 2,
      "z": 8,
      "name": "Empty"
    },
    {
      "x": -4,
      "y": 3,
      "z": 8,
      "name": "Empty"
    },
    {
      "x": -4,
      "y": 4,
      "z": 8,
      "name": "Empty"
    },
    {
      "x": -4,
      "y": 5,
      "z": 8,
      "name": "Empty"
    },
    {
      "x": -3,
      "y": 0,
      "z": -8,
      "name": "Rock_Sandstone"
    },
    {
      "x": -3,
      "y": 1,
      "z": -8,
      "name": "Rock_Sandstone"
    },
    {
      "x": -3,
      "y": 2,
      "z": -8,
      "name": "Empty"
    },
    {
      "x": -3,
      "y": 3,
      "z": -8,
      "name": "Empty"
    },
    {
      "x": -3,
      "y": 4,
      "z": -8,
      "name": "Empty"
    },
    {
      "x": -3,
      "y": 5,
      "z": -8,
      "name": "Empty"
    },
    {
      "x": -3,
      "y": 6,
      "z": -8,
      "name": "Empty"
    },
    {
      "x": -3,
      "y": 0,
      "z": -7,
      "name": "Rock_Sandstone"
    },
    {
      "x": -3,
      "y": 1,
      "z": -7,
      "name": "Furniture_Ancient_Barrel"
    },
    {
      "x": -3,
      "y": 2,
      "z": -7,
      "name": "Empty"
    },
    {
      "x": -3,
      "y": 3,
      "z": -7,
      "name": "Empty"
    },
    {
      "x": -3,
      "y": 4,
      "z": -7,
      "name": "Empty"
    },
    {
      "x": -3,
      "y": 5,
      "z": -7,
      "name": "Rock_Sandstone_Cobble_Half",
      "rotation": 8
    },
    {
      "x": -3,
      "y": 6,
      "z": -7,
      "name": "Rock_Sandstone_Brick"
    },
    {
      "x": -3,
      "y": 0,
      "z": -6,
      "name": "Wood_Drywood_Planks"
    },
    {
      "x": -3,
      "y": 1,
      "z": -6,
      "name": "Empty"
    },
    {
      "x": -3,
      "y": 2,
      "z": -6,
      "name": "Empty"
    },
    {
      "x": -3,
      "y": 3,
      "z": -6,
      "name": "Empty"
    },
    {
      "x": -3,
      "y": 4,
      "z": -6,
      "name": "Empty"
    },
    {
      "x": -3,
      "y": 5,
      "z": -6,
      "name": "Rock_Sandstone_Cobble_Half",
      "rotation": 8
    },
    {
      "x": -3,
      "y": 6,
      "z": -6,
      "name": "Rock_Sandstone_Brick"
    },
    {
      "x": -3,
      "y": 0,
      "z": -5,
      "name": "Wood_Drywood_Planks"
    },
    {
      "x": -3,
      "y": 1,
      "z": -5,
      "name": "Empty"
    },
    {
      "x": -3,
      "y": 2,
      "z": -5,
      "name": "Empty"
    },
    {
      "x": -3,
      "y": 3,
      "z": -5,
      "name": "Empty"
    },
    {
      "x": -3,
      "y": 4,
      "z": -5,
      "name": "Empty"
    },
    {
      "x": -3,
      "y": 5,
      "z": -5,
      "name": "Rock_Sandstone_Brick"
    },
    {
      "x": -3,
      "y": 6,
      "z": -5,
      "name": "Rock_Sandstone_Cobble"
    },
    {
      "x": -3,
      "y": 0,
      "z": -4,
      "name": "Wood_Drywood_Planks"
    },
    {
      "x": -3,
      "y": 1,
      "z": -4,
      "name": "Empty"
    },
    {
      "x": -3,
      "y": 2,
      "z": -4,
      "name": "Empty"
    },
    {
      "x": -3,
      "y": 3,
      "z": -4,
      "name": "Empty"
    },
    {
      "x": -3,
      "y": 4,
      "z": -4,
      "name": "Empty"
    },
    {
      "x": -3,
      "y": 5,
      "z": -4,
      "name": "Rock_Sandstone_Cobble_Half",
      "rotation": 8
    },
    {
      "x": -3,
      "y": 6,
      "z": -4,
      "name": "Rock_Sandstone_Brick"
    },
    {
      "x": -3,
      "y": 0,
      "z": -3,
      "name": "Wood_Drywood_Planks"
    },
    {
      "x": -3,
      "y": 1,
      "z": -3,
      "name": "Empty"
    },
    {
      "x": -3,
      "y": 2,
      "z": -3,
      "name": "Empty"
    },
    {
      "x": -3,
      "y": 3,
      "z": -3,
      "name": "Empty"
    },
    {
      "x": -3,
      "y": 4,
      "z": -3,
      "name": "Empty"
    },
    {
      "x": -3,
      "y": 5,
      "z": -3,
      "name": "Rock_Sandstone_Cobble_Half",
      "rotation": 8
    },
    {
      "x": -3,
      "y": 6,
      "z": -3,
      "name": "Rock_Sandstone_Cobble"
    },
    {
      "x": -3,
      "y": 0,
      "z": -2,
      "name": "Wood_Drywood_Planks"
    },
    {
      "x": -3,
      "y": 1,
      "z": -2,
      "name": "Empty"
    },
    {
      "x": -3,
      "y": 2,
      "z": -2,
      "name": "Empty"
    },
    {
      "x": -3,
      "y": 3,
      "z": -2,
      "name": "Empty"
    },
    {
      "x": -3,
      "y": 4,
      "z": -2,
      "name": "Empty"
    },
    {
      "x": -3,
      "y": 5,
      "z": -2,
      "name": "Rock_Sandstone_Cobble_Half",
      "rotation": 8
    },
    {
      "x": -3,
      "y": 6,
      "z": -2,
      "name": "Rock_Sandstone_Cobble"
    },
    {
      "x": -3,
      "y": 0,
      "z": -1,
      "name": "Wood_Drywood_Planks"
    },
    {
      "x": -3,
      "y": 1,
      "z": -1,
      "name": "Empty"
    },
    {
      "x": -3,
      "y": 2,
      "z": -1,
      "name": "Empty"
    },
    {
      "x": -3,
      "y": 3,
      "z": -1,
      "name": "Empty"
    },
    {
      "x": -3,
      "y": 4,
      "z": -1,
      "name": "Empty"
    },
    {
      "x": -3,
      "y": 5,
      "z": -1,
      "name": "Rock_Sandstone_Brick"
    },
    {
      "x": -3,
      "y": 6,
      "z": -1,
      "name": "Rock_Sandstone_Cobble"
    },
    {
      "x": -3,
      "y": 0,
      "z": 0,
      "name": "Wood_Drywood_Planks"
    },
    {
      "x": -3,
      "y": 1,
      "z": 0,
      "name": "Empty"
    },
    {
      "x": -3,
      "y": 2,
      "z": 0,
      "name": "Empty"
    },
    {
      "x": -3,
      "y": 3,
      "z": 0,
      "name": "Empty"
    },
    {
      "x": -3,
      "y": 4,
      "z": 0,
      "name": "Empty"
    },
    {
      "x": -3,
      "y": 5,
      "z": 0,
      "name": "Rock_Sandstone_Brick"
    },
    {
      "x": -3,
      "y": 6,
      "z": 0,
      "name": "Rock_Sandstone_Cobble"
    },
    {
      "x": -3,
      "y": 0,
      "z": 1,
      "name": "Wood_Drywood_Planks"
    },
    {
      "x": -3,
      "y": 1,
      "z": 1,
      "name": "Empty"
    },
    {
      "x": -3,
      "y": 2,
      "z": 1,
      "name": "Empty"
    },
    {
      "x": -3,
      "y": 3,
      "z": 1,
      "name": "Empty"
    },
    {
      "x": -3,
      "y": 4,
      "z": 1,
      "name": "Empty"
    },
    {
      "x": -3,
      "y": 5,
      "z": 1,
      "name": "Rock_Sandstone_Brick"
    },
    {
      "x": -3,
      "y": 6,
      "z": 1,
      "name": "Rock_Sandstone_Brick"
    },
    {
      "x": -3,
      "y": 0,
      "z": 2,
      "name": "Wood_Drywood_Planks"
    },
    {
      "x": -3,
      "y": 1,
      "z": 2,
      "name": "Empty"
    },
    {
      "x": -3,
      "y": 2,
      "z": 2,
      "name": "Empty"
    },
    {
      "x": -3,
      "y": 3,
      "z": 2,
      "name": "Empty"
    },
    {
      "x": -3,
      "y": 4,
      "z": 2,
      "name": "Empty"
    },
    {
      "x": -3,
      "y": 5,
      "z": 2,
      "name": "Rock_Sandstone_Cobble_Half",
      "rotation": 8
    },
    {
      "x": -3,
      "y": 6,
      "z": 2,
      "name": "Rock_Sandstone_Brick"
    },
    {
      "x": -3,
      "y": 0,
      "z": 3,
      "name": "Wood_Drywood_Planks"
    },
    {
      "x": -3,
      "y": 1,
      "z": 3,
      "name": "Empty"
    },
    {
      "x": -3,
      "y": 2,
      "z": 3,
      "name": "Empty"
    },
    {
      "x": -3,
      "y": 3,
      "z": 3,
      "name": "Empty"
    },
    {
      "x": -3,
      "y": 4,
      "z": 3,
      "name": "Empty"
    },
    {
      "x": -3,
      "y": 5,
      "z": 3,
      "name": "Rock_Sandstone_Cobble_Half",
      "rotation": 8
    },
    {
      "x": -3,
      "y": 6,
      "z": 3,
      "name": "Rock_Sandstone_Brick"
    },
    {
      "x": -3,
      "y": 0,
      "z": 4,
      "name": "Wood_Drywood_Planks"
    },
    {
      "x": -3,
      "y": 1,
      "z": 4,
      "name": "Empty"
    },
    {
      "x": -3,
      "y": 2,
      "z": 4,
      "name": "Empty"
    },
    {
      "x": -3,
      "y": 3,
      "z": 4,
      "name": "Empty"
    },
    {
      "x": -3,
      "y": 4,
      "z": 4,
      "name": "Empty"
    },
    {
      "x": -3,
      "y": 5,
      "z": 4,
      "name": "Rock_Sandstone_Cobble_Half",
      "rotation": 8
    },
    {
      "x": -3,
      "y": 6,
      "z": 4,
      "name": "Rock_Sandstone_Brick"
    },
    {
      "x": -3,
      "y": 0,
      "z": 5,
      "name": "Wood_Drywood_Planks"
    },
    {
      "x": -3,
      "y": 1,
      "z": 5,
      "name": "Empty"
    },
    {
      "x": -3,
      "y": 2,
      "z": 5,
      "name": "Empty"
    },
    {
      "x": -3,
      "y": 3,
      "z": 5,
      "name": "Empty"
    },
    {
      "x": -3,
      "y": 4,
      "z": 5,
      "name": "Empty"
    },
    {
      "x": -3,
      "y": 5,
      "z": 5,
      "name": "Rock_Sandstone_Brick"
    },
    {
      "x": -3,
      "y": 6,
      "z": 5,
      "name": "Rock_Sandstone_Brick"
    },
    {
      "x": -3,
      "y": 0,
      "z": 6,
      "name": "Wood_Drywood_Planks"
    },
    {
      "x": -3,
      "y": 1,
      "z": 6,
      "name": "Empty"
    },
    {
      "x": -3,
      "y": 2,
      "z": 6,
      "name": "Empty"
    },
    {
      "x": -3,
      "y": 3,
      "z": 6,
      "name": "Empty"
    },
    {
      "x": -3,
      "y": 4,
      "z": 6,
      "name": "Empty"
    },
    {
      "x": -3,
      "y": 5,
      "z": 6,
      "name": "Rock_Sandstone_Cobble_Half",
      "rotation": 8
    },
    {
      "x": -3,
      "y": 6,
      "z": 6,
      "name": "Rock_Sandstone_Brick"
    },
    {
      "x": -3,
      "y": 0,
      "z": 7,
      "name": "Rock_Sandstone_Brick_Smooth"
    },
    {
      "x": -3,
      "y": 1,
      "z": 7,
      "name": "Rubble_Sandstone_Medium"
    },
    {
      "x": -3,
      "y": 2,
      "z": 7,
      "name": "Empty"
    },
    {
      "x": -3,
      "y": 3,
      "z": 7,
      "name": "Empty"
    },
    {
      "x": -3,
      "y": 4,
      "z": 7,
      "name": "Empty"
    },
    {
      "x": -3,
      "y": 5,
      "z": 7,
      "name": "Empty"
    },
    {
      "x": -3,
      "y": 6,
      "z": 7,
      "name": "Empty"
    },
    {
      "x": -3,
      "y": 2,
      "z": 8,
      "name": "Empty"
    },
    {
      "x": -3,
      "y": 3,
      "z": 8,
      "name": "Empty"
    },
    {
      "x": -3,
      "y": 4,
      "z": 8,
      "name": "Empty"
    },
    {
      "x": -3,
      "y": 5,
      "z": 8,
      "name": "Empty"
    },
    {
      "x": -3,
      "y": 6,
      "z": 8,
      "name": "Empty"
    },
    {
      "x": -2,
      "y": 0,
      "z": -8,
      "name": "Rock_Sandstone"
    },
    {
      "x": -2,
      "y": 1,
      "z": -8,
      "name": "Furniture_Village_Crate"
    },
    {
      "x": -2,
      "y": 2,
      "z": -8,
      "name": "Empty"
    },
    {
      "x": -2,
      "y": 3,
      "z": -8,
      "name": "Empty"
    },
    {
      "x": -2,
      "y": 4,
      "z": -8,
      "name": "Empty"
    },
    {
      "x": -2,
      "y": 5,
      "z": -8,
      "name": "Empty"
    },
    {
      "x": -2,
      "y": 6,
      "z": -8,
      "name": "Empty"
    },
    {
      "x": -2,
      "y": 0,
      "z": -7,
      "name": "Rock_Sandstone_Brick_Smooth"
    },
    {
      "x": -2,
      "y": 1,
      "z": -7,
      "name": "Furniture_Ancient_Barrel"
    },
    {
      "x": -2,
      "y": 2,
      "z": -7,
      "name": "Empty"
    },
    {
      "x": -2,
      "y": 3,
      "z": -7,
      "name": "Empty"
    },
    {
      "x": -2,
      "y": 4,
      "z": -7,
      "name": "Empty"
    },
    {
      "x": -2,
      "y": 5,
      "z": -7,
      "name": "Rock_Sandstone_Brick"
    },
    {
      "x": -2,
      "y": 6,
      "z": -7,
      "name": "Rock_Sandstone_Brick"
    },
    {
      "x": -2,
      "y": 0,
      "z": -6,
      "name": "Wood_Drywood_Planks"
    },
    {
      "x": -2,
      "y": 1,
      "z": -6,
      "name": "Empty"
    },
    {
      "x": -2,
      "y": 2,
      "z": -6,
      "name": "Empty"
    },
    {
      "x": -2,
      "y": 3,
      "z": -6,
      "name": "Empty"
    },
    {
      "x": -2,
      "y": 4,
      "z": -6,
      "name": "Empty"
    },
    {
      "x": -2,
      "y": 5,
      "z": -6,
      "name": "Rock_Sandstone_Brick"
    },
    {
      "x": -2,
      "y": 6,
      "z": -6,
      "name": "Rock_Sandstone_Brick"
    },
    {
      "x": -2,
      "y": 0,
      "z": -5,
      "name": "Wood_Drywood_Planks"
    },
    {
      "x": -2,
      "y": 1,
      "z": -5,
      "name": "Empty"
    },
    {
      "x": -2,
      "y": 2,
      "z": -5,
      "name": "Empty"
    },
    {
      "x": -2,
      "y": 3,
      "z": -5,
      "name": "Empty"
    },
    {
      "x": -2,
      "y": 4,
      "z": -5,
      "name": "Empty"
    },
    {
      "x": -2,
      "y": 5,
      "z": -5,
      "name": "Rock_Sandstone_Brick"
    },
    {
      "x": -2,
      "y": 6,
      "z": -5,
      "name": "Rock_Sandstone_Cobble"
    },
    {
      "x": -2,
      "y": 0,
      "z": -4,
      "name": "Wood_Drywood_Planks"
    },
    {
      "x": -2,
      "y": 1,
      "z": -4,
      "name": "Empty"
    },
    {
      "x": -2,
      "y": 2,
      "z": -4,
      "name": "Empty"
    },
    {
      "x": -2,
      "y": 3,
      "z": -4,
      "name": "Empty"
    },
    {
      "x": -2,
      "y": 4,
      "z": -4,
      "name": "Empty"
    },
    {
      "x": -2,
      "y": 5,
      "z": -4,
      "name": "Rock_Sandstone_Brick"
    },
    {
      "x": -2,
      "y": 6,
      "z": -4,
      "name": "Rock_Sandstone_Cobble"
    },
    {
      "x": -2,
      "y": 0,
      "z": -3,
      "name": "Wood_Drywood_Planks"
    },
    {
      "x": -2,
      "y": 1,
      "z": -3,
      "name": "Empty"
    },
    {
      "x": -2,
      "y": 2,
      "z": -3,
      "name": "Empty"
    },
    {
      "x": -2,
      "y": 3,
      "z": -3,
      "name": "Empty"
    },
    {
      "x": -2,
      "y": 4,
      "z": -3,
      "name": "Empty"
    },
    {
      "x": -2,
      "y": 5,
      "z": -3,
      "name": "Rock_Sandstone_Brick"
    },
    {
      "x": -2,
      "y": 6,
      "z": -3,
      "name": "Rock_Sandstone_Brick"
    },
    {
      "x": -2,
      "y": 0,
      "z": -2,
      "name": "Wood_Drywood_Planks"
    },
    {
      "x": -2,
      "y": 1,
      "z": -2,
      "name": "Empty"
    },
    {
      "x": -2,
      "y": 2,
      "z": -2,
      "name": "Empty"
    },
    {
      "x": -2,
      "y": 3,
      "z": -2,
      "name": "Empty"
    },
    {
      "x": -2,
      "y": 4,
      "z": -2,
      "name": "Empty"
    },
    {
      "x": -2,
      "y": 5,
      "z": -2,
      "name": "Rock_Sandstone_Brick"
    },
    {
      "x": -2,
      "y": 6,
      "z": -2,
      "name": "Rock_Sandstone_Brick"
    },
    {
      "x": -2,
      "y": 0,
      "z": -1,
      "name": "Wood_Drywood_Planks"
    },
    {
      "x": -2,
      "y": 1,
      "z": -1,
      "name": "Empty"
    },
    {
      "x": -2,
      "y": 2,
      "z": -1,
      "name": "Empty"
    },
    {
      "x": -2,
      "y": 3,
      "z": -1,
      "name": "Empty"
    },
    {
      "x": -2,
      "y": 4,
      "z": -1,
      "name": "Empty"
    },
    {
      "x": -2,
      "y": 5,
      "z": -1,
      "name": "Rock_Sandstone_Brick"
    },
    {
      "x": -2,
      "y": 6,
      "z": -1,
      "name": "Rock_Sandstone_Brick"
    },
    {
      "x": -2,
      "y": 0,
      "z": 0,
      "name": "Wood_Drywood_Planks"
    },
    {
      "x": -2,
      "y": 1,
      "z": 0,
      "name": "Empty"
    },
    {
      "x": -2,
      "y": 2,
      "z": 0,
      "name": "Empty"
    },
    {
      "x": -2,
      "y": 3,
      "z": 0,
      "name": "Empty"
    },
    {
      "x": -2,
      "y": 4,
      "z": 0,
      "name": "Rock_Sandstone_Brick_Stairs",
      "rotation": 9
    },
    {
      "x": -2,
      "y": 5,
      "z": 0,
      "name": "Rock_Sandstone_Brick"
    },
    {
      "x": -2,
      "y": 6,
      "z": 0,
      "name": "Rock_Sandstone_Cobble"
    },
    {
      "x": -2,
      "y": 0,
      "z": 1,
      "name": "Wood_Drywood_Planks"
    },
    {
      "x": -2,
      "y": 1,
      "z": 1,
      "name": "Empty"
    },
    {
      "x": -2,
      "y": 2,
      "z": 1,
      "name": "Empty"
    },
    {
      "x": -2,
      "y": 3,
      "z": 1,
      "name": "Empty"
    },
    {
      "x": -2,
      "y": 4,
      "z": 1,
      "name": "Empty"
    },
    {
      "x": -2,
      "y": 5,
      "z": 1,
      "name": "Rock_Sandstone_Brick"
    },
    {
      "x": -2,
      "y": 6,
      "z": 1,
      "name": "Rock_Sandstone_Brick"
    },
    {
      "x": -2,
      "y": 0,
      "z": 2,
      "name": "Wood_Drywood_Planks"
    },
    {
      "x": -2,
      "y": 1,
      "z": 2,
      "name": "Empty"
    },
    {
      "x": -2,
      "y": 2,
      "z": 2,
      "name": "Empty"
    },
    {
      "x": -2,
      "y": 3,
      "z": 2,
      "name": "Empty"
    },
    {
      "x": -2,
      "y": 4,
      "z": 2,
      "name": "Empty"
    },
    {
      "x": -2,
      "y": 5,
      "z": 2,
      "name": "Rock_Sandstone_Brick"
    },
    {
      "x": -2,
      "y": 6,
      "z": 2,
      "name": "Rock_Sandstone_Brick"
    },
    {
      "x": -2,
      "y": 0,
      "z": 3,
      "name": "Wood_Drywood_Planks"
    },
    {
      "x": -2,
      "y": 1,
      "z": 3,
      "name": "Empty"
    },
    {
      "x": -2,
      "y": 2,
      "z": 3,
      "name": "Empty"
    },
    {
      "x": -2,
      "y": 3,
      "z": 3,
      "name": "Empty"
    },
    {
      "x": -2,
      "y": 4,
      "z": 3,
      "name": "Empty"
    },
    {
      "x": -2,
      "y": 5,
      "z": 3,
      "name": "Rock_Sandstone_Brick"
    },
    {
      "x": -2,
      "y": 6,
      "z": 3,
      "name": "Rock_Sandstone_Brick"
    },
    {
      "x": -2,
      "y": 0,
      "z": 4,
      "name": "Wood_Drywood_Planks"
    },
    {
      "x": -2,
      "y": 1,
      "z": 4,
      "name": "Empty"
    },
    {
      "x": -2,
      "y": 2,
      "z": 4,
      "name": "Empty"
    },
    {
      "x": -2,
      "y": 3,
      "z": 4,
      "name": "Empty"
    },
    {
      "x": -2,
      "y": 4,
      "z": 4,
      "name": "Empty"
    },
    {
      "x": -2,
      "y": 5,
      "z": 4,
      "name": "Rock_Sandstone_Brick"
    },
    {
      "x": -2,
      "y": 6,
      "z": 4,
      "name": "Rock_Sandstone_Brick"
    },
    {
      "x": -2,
      "y": 0,
      "z": 5,
      "name": "Wood_Drywood_Planks"
    },
    {
      "x": -2,
      "y": 1,
      "z": 5,
      "name": "Empty"
    },
    {
      "x": -2,
      "y": 2,
      "z": 5,
      "name": "Empty"
    },
    {
      "x": -2,
      "y": 3,
      "z": 5,
      "name": "Empty"
    },
    {
      "x": -2,
      "y": 4,
      "z": 5,
      "name": "Empty"
    },
    {
      "x": -2,
      "y": 5,
      "z": 5,
      "name": "Rock_Sandstone_Brick"
    },
    {
      "x": -2,
      "y": 6,
      "z": 5,
      "name": "Rock_Sandstone_Brick"
    },
    {
      "x": -2,
      "y": 0,
      "z": 6,
      "name": "Wood_Drywood_Planks"
    },
    {
      "x": -2,
      "y": 1,
      "z": 6,
      "name": "Empty"
    },
    {
      "x": -2,
      "y": 2,
      "z": 6,
      "name": "Empty"
    },
    {
      "x": -2,
      "y": 3,
      "z": 6,
      "name": "Empty"
    },
    {
      "x": -2,
      "y": 4,
      "z": 6,
      "name": "Empty"
    },
    {
      "x": -2,
      "y": 5,
      "z": 6,
      "name": "Rock_Sandstone_Brick"
    },
    {
      "x": -2,
      "y": 6,
      "z": 6,
      "name": "Rock_Sandstone_Brick"
    },
    {
      "x": -2,
      "y": 1,
      "z": 7,
      "name": "Empty"
    },
    {
      "x": -2,
      "y": 2,
      "z": 7,
      "name": "Empty"
    },
    {
      "x": -2,
      "y": 3,
      "z": 7,
      "name": "Empty"
    },
    {
      "x": -2,
      "y": 4,
      "z": 7,
      "name": "Empty"
    },
    {
      "x": -2,
      "y": 5,
      "z": 7,
      "name": "Rock_Sandstone_Brick"
    },
    {
      "x": -2,
      "y": 6,
      "z": 7,
      "name": "Rock_Sandstone_Brick"
    },
    {
      "x": -2,
      "y": 1,
      "z": 8,
      "name": "Empty"
    },
    {
      "x": -2,
      "y": 2,
      "z": 8,
      "name": "Empty"
    },
    {
      "x": -2,
      "y": 3,
      "z": 8,
      "name": "Empty"
    },
    {
      "x": -2,
      "y": 4,
      "z": 8,
      "name": "Empty"
    },
    {
      "x": -2,
      "y": 5,
      "z": 8,
      "name": "Empty"
    },
    {
      "x": -2,
      "y": 6,
      "z": 8,
      "name": "Empty"
    },
    {
      "x": -1,
      "y": 0,
      "z": -8,
      "name": "Rock_Sandstone"
    },
    {
      "x": -1,
      "y": 1,
      "z": -8,
      "name": "Empty"
    },
    {
      "x": -1,
      "y": 2,
      "z": -8,
      "name": "Empty"
    },
    {
      "x": -1,
      "y": 3,
      "z": -8,
      "name": "Empty"
    },
    {
      "x": -1,
      "y": 4,
      "z": -8,
      "name": "Empty"
    },
    {
      "x": -1,
      "y": 5,
      "z": -8,
      "name": "Empty"
    },
    {
      "x": -1,
      "y": 0,
      "z": -7,
      "name": "Rock_Sandstone_Brick_Smooth"
    },
    {
      "x": -1,
      "y": 1,
      "z": -7,
      "name": "Block_Spawner_Block",
      "components": {
        "Components": {
          "PlacedByInteraction": {
            "WhoPlacedUuid": {
              "$binary": "x9M0GYCLPG+IqIodoDzEcQ==",
              "$type": "04"
            }
          },
          "BlockSpawner": {
            "BlockSpawnerId": "Zone2_Encounters_Tier2"
          }
        }
      }
    },
    {
      "x": -1,
      "y": 2,
      "z": -7,
      "name": "Empty"
    },
    {
      "x": -1,
      "y": 3,
      "z": -7,
      "name": "Empty"
    },
    {
      "x": -1,
      "y": 4,
      "z": -7,
      "name": "Empty"
    },
    {
      "x": -1,
      "y": 5,
      "z": -7,
      "name": "Empty"
    },
    {
      "x": -1,
      "y": 6,
      "z": -7,
      "name": "Empty"
    },
    {
      "x": -1,
      "y": 0,
      "z": -6,
      "name": "Wood_Drywood_Planks"
    },
    {
      "x": -1,
      "y": 1,
      "z": -6,
      "name": "Empty"
    },
    {
      "x": -1,
      "y": 2,
      "z": -6,
      "name": "Empty"
    },
    {
      "x": -1,
      "y": 3,
      "z": -6,
      "name": "Empty"
    },
    {
      "x": -1,
      "y": 4,
      "z": -6,
      "name": "Empty"
    },
    {
      "x": -1,
      "y": 5,
      "z": -6,
      "name": "Empty"
    },
    {
      "x": -1,
      "y": 6,
      "z": -6,
      "name": "Empty"
    },
    {
      "x": -1,
      "y": 0,
      "z": -5,
      "name": "Wood_Drywood_Planks"
    },
    {
      "x": -1,
      "y": 1,
      "z": -5,
      "name": "Empty"
    },
    {
      "x": -1,
      "y": 2,
      "z": -5,
      "name": "Empty"
    },
    {
      "x": -1,
      "y": 3,
      "z": -5,
      "name": "Empty"
    },
    {
      "x": -1,
      "y": 4,
      "z": -5,
      "name": "Empty"
    },
    {
      "x": -1,
      "y": 5,
      "z": -5,
      "name": "Rock_Sandstone_Brick"
    },
    {
      "x": -1,
      "y": 6,
      "z": -5,
      "name": "Rock_Sandstone_Cobble"
    },
    {
      "x": -1,
      "y": 0,
      "z": -4,
      "name": "Wood_Drywood_Planks"
    },
    {
      "x": -1,
      "y": 1,
      "z": -4,
      "name": "Empty"
    },
    {
      "x": -1,
      "y": 2,
      "z": -4,
      "name": "Empty"
    },
    {
      "x": -1,
      "y": 3,
      "z": -4,
      "name": "Empty"
    },
    {
      "x": -1,
      "y": 4,
      "z": -4,
      "name": "Empty"
    },
    {
      "x": -1,
      "y": 5,
      "z": -4,
      "name": "Rock_Sandstone_Cobble_Half",
      "rotation": 8
    },
    {
      "x": -1,
      "y": 6,
      "z": -4,
      "name": "Rock_Sandstone_Brick"
    },
    {
      "x": -1,
      "y": 0,
      "z": -3,
      "name": "Rock_Sandstone_Brick_Smooth"
    },
    {
      "x": -1,
      "y": 1,
      "z": -3,
      "name": "Empty"
    },
    {
      "x": -1,
      "y": 2,
      "z": -3,
      "name": "Empty"
    },
    {
      "x": -1,
      "y": 3,
      "z": -3,
      "name": "Empty"
    },
    {
      "x": -1,
      "y": 4,
      "z": -3,
      "name": "Empty"
    },
    {
      "x": -1,
      "y": 5,
      "z": -3,
      "name": "Rock_Sandstone_Cobble_Half",
      "rotation": 8
    },
    {
      "x": -1,
      "y": 6,
      "z": -3,
      "name": "Rock_Sandstone_Brick"
    },
    {
      "x": -1,
      "y": 0,
      "z": -2,
      "name": "Rock_Sandstone_Brick_Smooth"
    },
    {
      "x": -1,
      "y": 1,
      "z": -2,
      "name": "Empty"
    },
    {
      "x": -1,
      "y": 2,
      "z": -2,
      "name": "Empty"
    },
    {
      "x": -1,
      "y": 3,
      "z": -2,
      "name": "Empty"
    },
    {
      "x": -1,
      "y": 4,
      "z": -2,
      "name": "Empty"
    },
    {
      "x": -1,
      "y": 5,
      "z": -2,
      "name": "Rock_Sandstone_Cobble_Half",
      "rotation": 8
    },
    {
      "x": -1,
      "y": 6,
      "z": -2,
      "name": "Rock_Sandstone_Brick"
    },
    {
      "x": -1,
      "y": 0,
      "z": -1,
      "name": "Rock_Sandstone"
    },
    {
      "x": -1,
      "y": 1,
      "z": -1,
      "name": "Rock_Sandstone_Brick_Pillar_Base"
    },
    {
      "x": -1,
      "y": 2,
      "z": -1,
      "name": "Rock_Sandstone_Brick_Pillar_Middle"
    },
    {
      "x": -1,
      "y": 3,
      "z": -1,
      "name": "Rock_Sandstone_Brick_Pillar_Middle"
    },
    {
      "x": -1,
      "y": 4,
      "z": -1,
      "name": "Rock_Sandstone_Brick_Pillar_Base",
      "rotation": 8
    },
    {
      "x": -1,
      "y": 5,
      "z": -1,
      "name": "Rock_Sandstone_Brick"
    },
    {
      "x": -1,
      "y": 6,
      "z": -1,
      "name": "Rock_Sandstone_Brick"
    },
    {
      "x": -1,
      "y": 0,
      "z": 0,
      "name": "Rock_Sandstone"
    },
    {
      "x": -1,
      "y": 1,
      "z": 0,
      "name": "Rock_Sandstone_Brick"
    },
    {
      "x": -1,
      "y": 2,
      "z": 0,
      "name": "Rock_Sandstone_Brick"
    },
    {
      "x": -1,
      "y": 3,
      "z": 0,
      "name": "Rock_Sandstone_Brick"
    },
    {
      "x": -1,
      "y": 4,
      "z": 0,
      "name": "Rock_Sandstone_Brick"
    },
    {
      "x": -1,
      "y": 5,
      "z": 0,
      "name": "Rock_Sandstone_Brick"
    },
    {
      "x": -1,
      "y": 6,
      "z": 0,
      "name": "Rock_Sandstone_Cobble"
    },
    {
      "x": -1,
      "y": 0,
      "z": 1,
      "name": "Rock_Sandstone"
    },
    {
      "x": -1,
      "y": 1,
      "z": 1,
      "name": "Rock_Sandstone_Brick_Pillar_Base"
    },
    {
      "x": -1,
      "y": 2,
      "z": 1,
      "name": "Rock_Sandstone_Brick_Pillar_Middle"
    },
    {
      "x": -1,
      "y": 3,
      "z": 1,
      "name": "Rock_Sandstone_Brick_Pillar_Middle"
    },
    {
      "x": -1,
      "y": 4,
      "z": 1,
      "name": "Rock_Sandstone_Brick_Pillar_Base",
      "rotation": 8
    },
    {
      "x": -1,
      "y": 5,
      "z": 1,
      "name": "Rock_Sandstone_Brick"
    },
    {
      "x": -1,
      "y": 6,
      "z": 1,
      "name": "Rock_Sandstone_Brick"
    },
    {
      "x": -1,
      "y": 0,
      "z": 2,
      "name": "Rock_Sandstone_Brick_Smooth"
    },
    {
      "x": -1,
      "y": 1,
      "z": 2,
      "name": "Furniture_Temple_Dark_Candle"
    },
    {
      "x": -1,
      "y": 2,
      "z": 2,
      "name": "Furniture_Temple_Dark_Candle",
      "filler": 1024
    },
    {
      "x": -1,
      "y": 3,
      "z": 2,
      "name": "Empty"
    },
    {
      "x": -1,
      "y": 4,
      "z": 2,
      "name": "Empty"
    },
    {
      "x": -1,
      "y": 5,
      "z": 2,
      "name": "Rock_Sandstone_Cobble_Half",
      "rotation": 8
    },
    {
      "x": -1,
      "y": 6,
      "z": 2,
      "name": "Rock_Sandstone_Brick"
    },
    {
      "x": -1,
      "y": 0,
      "z": 3,
      "name": "Rock_Sandstone_Brick_Smooth"
    },
    {
      "x": -1,
      "y": 1,
      "z": 3,
      "name": "Empty"
    },
    {
      "x": -1,
      "y": 2,
      "z": 3,
      "name": "Empty"
    },
    {
      "x": -1,
      "y": 3,
      "z": 3,
      "name": "Empty"
    },
    {
      "x": -1,
      "y": 4,
      "z": 3,
      "name": "Empty"
    },
    {
      "x": -1,
      "y": 5,
      "z": 3,
      "name": "Rock_Sandstone_Cobble_Half",
      "rotation": 8
    },
    {
      "x": -1,
      "y": 6,
      "z": 3,
      "name": "Rock_Sandstone_Brick"
    },
    {
      "x": -1,
      "y": 0,
      "z": 4,
      "name": "Wood_Drywood_Planks"
    },
    {
      "x": -1,
      "y": 1,
      "z": 4,
      "name": "Empty"
    },
    {
      "x": -1,
      "y": 2,
      "z": 4,
      "name": "Empty"
    },
    {
      "x": -1,
      "y": 3,
      "z": 4,
      "name": "Empty"
    },
    {
      "x": -1,
      "y": 4,
      "z": 4,
      "name": "Empty"
    },
    {
      "x": -1,
      "y": 5,
      "z": 4,
      "name": "Rock_Sandstone_Cobble_Half",
      "rotation": 8
    },
    {
      "x": -1,
      "y": 6,
      "z": 4,
      "name": "Rock_Sandstone_Brick"
    },
    {
      "x": -1,
      "y": 0,
      "z": 5,
      "name": "Wood_Drywood_Planks"
    },
    {
      "x": -1,
      "y": 1,
      "z": 5,
      "name": "Empty"
    },
    {
      "x": -1,
      "y": 2,
      "z": 5,
      "name": "Empty"
    },
    {
      "x": -1,
      "y": 3,
      "z": 5,
      "name": "Empty"
    },
    {
      "x": -1,
      "y": 4,
      "z": 5,
      "name": "Empty"
    },
    {
      "x": -1,
      "y": 5,
      "z": 5,
      "name": "Rock_Sandstone_Brick"
    },
    {
      "x": -1,
      "y": 6,
      "z": 5,
      "name": "Rock_Sandstone_Brick"
    },
    {
      "x": -1,
      "y": 0,
      "z": 6,
      "name": "Wood_Drywood_Planks"
    },
    {
      "x": -1,
      "y": 1,
      "z": 6,
      "name": "Empty"
    },
    {
      "x": -1,
      "y": 2,
      "z": 6,
      "name": "Empty"
    },
    {
      "x": -1,
      "y": 3,
      "z": 6,
      "name": "Empty"
    },
    {
      "x": -1,
      "y": 4,
      "z": 6,
      "name": "Empty"
    },
    {
      "x": -1,
      "y": 5,
      "z": 6,
      "name": "Rock_Sandstone_Cobble_Half",
      "rotation": 8
    },
    {
      "x": -1,
      "y": 6,
      "z": 6,
      "name": "Rock_Sandstone_Brick"
    },
    {
      "x": -1,
      "y": 1,
      "z": 7,
      "name": "Empty"
    },
    {
      "x": -1,
      "y": 2,
      "z": 7,
      "name": "Empty"
    },
    {
      "x": -1,
      "y": 3,
      "z": 7,
      "name": "Empty"
    },
    {
      "x": -1,
      "y": 4,
      "z": 7,
      "name": "Empty"
    },
    {
      "x": -1,
      "y": 5,
      "z": 7,
      "name": "Rock_Sandstone_Cobble_Half",
      "rotation": 8
    },
    {
      "x": -1,
      "y": 6,
      "z": 7,
      "name": "Rock_Sandstone_Brick"
    },
    {
      "x": -1,
      "y": 1,
      "z": 8,
      "name": "Empty"
    },
    {
      "x": -1,
      "y": 2,
      "z": 8,
      "name": "Empty"
    },
    {
      "x": -1,
      "y": 3,
      "z": 8,
      "name": "Empty"
    },
    {
      "x": -1,
      "y": 4,
      "z": 8,
      "name": "Empty"
    },
    {
      "x": -1,
      "y": 5,
      "z": 8,
      "name": "Rock_Sandstone_Brick"
    },
    {
      "x": -1,
      "y": 6,
      "z": 8,
      "name": "Rock_Sandstone_Brick"
    },
    {
      "x": 0,
      "y": 0,
      "z": -8,
      "name": "Rock_Sandstone"
    },
    {
      "x": 0,
      "y": 1,
      "z": -8,
      "name": "Furniture_Village_Pot"
    },
    {
      "x": 0,
      "y": 2,
      "z": -8,
      "name": "Empty"
    },
    {
      "x": 0,
      "y": 3,
      "z": -8,
      "name": "Empty"
    },
    {
      "x": 0,
      "y": 4,
      "z": -8,
      "name": "Empty"
    },
    {
      "x": 0,
      "y": 5,
      "z": -8,
      "name": "Empty"
    },
    {
      "x": 0,
      "y": 0,
      "z": -7,
      "name": "Rock_Sandstone_Brick_Smooth"
    },
    {
      "x": 0,
      "y": 1,
      "z": -7,
      "name": "Furniture_Temple_Wind_Pot"
    },
    {
      "x": 0,
      "y": 2,
      "z": -7,
      "name": "Furniture_Temple_Wind_Pot",
      "filler": 1024
    },
    {
      "x": 0,
      "y": 3,
      "z": -7,
      "name": "Empty"
    },
    {
      "x": 0,
      "y": 4,
      "z": -7,
      "name": "Empty"
    },
    {
      "x": 0,
      "y": 5,
      "z": -7,
      "name": "Empty"
    },
    {
      "x": 0,
      "y": 6,
      "z": -7,
      "name": "Empty"
    },
    {
      "x": 0,
      "y": 0,
      "z": -6,
      "name": "Wood_Drywood_Planks"
    },
    {
      "x": 0,
      "y": 1,
      "z": -6,
      "name": "Empty"
    },
    {
      "x": 0,
      "y": 2,
      "z": -6,
      "name": "Empty"
    },
    {
      "x": 0,
      "y": 3,
      "z": -6,
      "name": "Empty"
    },
    {
      "x": 0,
      "y": 4,
      "z": -6,
      "name": "Empty"
    },
    {
      "x": 0,
      "y": 5,
      "z": -6,
      "name": "Empty"
    },
    {
      "x": 0,
      "y": 6,
      "z": -6,
      "name": "Empty"
    },
    {
      "x": 0,
      "y": 0,
      "z": -5,
      "name": "Wood_Drywood_Planks"
    },
    {
      "x": 0,
      "y": 1,
      "z": -5,
      "name": "Empty"
    },
    {
      "x": 0,
      "y": 2,
      "z": -5,
      "name": "Empty"
    },
    {
      "x": 0,
      "y": 3,
      "z": -5,
      "name": "Empty"
    },
    {
      "x": 0,
      "y": 4,
      "z": -5,
      "name": "Empty"
    },
    {
      "x": 0,
      "y": 5,
      "z": -5,
      "name": "Rock_Sandstone_Brick"
    },
    {
      "x": 0,
      "y": 6,
      "z": -5,
      "name": "Rock_Sandstone_Cobble"
    },
    {
      "x": 0,
      "y": 0,
      "z": -4,
      "name": "Wood_Drywood_Planks"
    },
    {
      "x": 0,
      "y": 1,
      "z": -4,
      "name": "Empty"
    },
    {
      "x": 0,
      "y": 2,
      "z": -4,
      "name": "Empty"
    },
    {
      "x": 0,
      "y": 3,
      "z": -4,
      "name": "Empty"
    },
    {
      "x": 0,
      "y": 4,
      "z": -4,
      "name": "Empty"
    },
    {
      "x": 0,
      "y": 5,
      "z": -4,
      "name": "Rock_Sandstone_Cobble_Half",
      "rotation": 8
    },
    {
      "x": 0,
      "y": 6,
      "z": -4,
      "name": "Rock_Sandstone_Brick"
    },
    {
      "x": 0,
      "y": 0,
      "z": -3,
      "name": "Rock_Sandstone_Brick_Smooth"
    },
    {
      "x": 0,
      "y": 1,
      "z": -3,
      "name": "Empty"
    },
    {
      "x": 0,
      "y": 2,
      "z": -3,
      "name": "Empty"
    },
    {
      "x": 0,
      "y": 3,
      "z": -3,
      "name": "Empty"
    },
    {
      "x": 0,
      "y": 4,
      "z": -3,
      "name": "Empty"
    },
    {
      "x": 0,
      "y": 5,
      "z": -3,
      "name": "Rock_Sandstone_Cobble_Half",
      "rotation": 8
    },
    {
      "x": 0,
      "y": 6,
      "z": -3,
      "name": "Rock_Sandstone_Brick"
    },
    {
      "x": 0,
      "y": 0,
      "z": -2,
      "name": "Rock_Sandstone_Brick_Smooth"
    },
    {
      "x": 0,
      "y": 1,
      "z": -2,
      "name": "Empty"
    },
    {
      "x": 0,
      "y": 2,
      "z": -2,
      "name": "Empty"
    },
    {
      "x": 0,
      "y": 3,
      "z": -2,
      "name": "Empty"
    },
    {
      "x": 0,
      "y": 4,
      "z": -2,
      "name": "Empty"
    },
    {
      "x": 0,
      "y": 5,
      "z": -2,
      "name": "Rock_Sandstone_Cobble_Half",
      "rotation": 8
    },
    {
      "x": 0,
      "y": 6,
      "z": -2,
      "name": "Rock_Sandstone_Brick"
    },
    {
      "x": 0,
      "y": 0,
      "z": -1,
      "name": "Rock_Sandstone"
    },
    {
      "x": 0,
      "y": 1,
      "z": -1,
      "name": "Rock_Sandstone_Brick"
    },
    {
      "x": 0,
      "y": 2,
      "z": -1,
      "name": "Rubble_Sandstone_Medium"
    },
    {
      "x": 0,
      "y": 3,
      "z": -1,
      "name": "Empty"
    },
    {
      "x": 0,
      "y": 4,
      "z": -1,
      "name": "Empty"
    },
    {
      "x": 0,
      "y": 5,
      "z": -1,
      "name": "Rock_Sandstone_Brick"
    },
    {
      "x": 0,
      "y": 6,
      "z": -1,
      "name": "Rock_Sandstone_Brick"
    },
    {
      "x": 0,
      "y": 0,
      "z": 0,
      "name": "Rock_Sandstone_Cobble"
    },
    {
      "x": 0,
      "y": 1,
      "z": 0,
      "name": "Rock_Sandstone_Cobble"
    },
    {
      "x": 0,
      "y": 2,
      "z": 0,
      "name": "Rock_Sandstone_Cobble"
    },
    {
      "x": 0,
      "y": 3,
      "z": 0,
      "name": "Rock_Sandstone_Cobble"
    },
    {
      "x": 0,
      "y": 4,
      "z": 0,
      "name": "Rock_Sandstone_Cobble"
    },
    {
      "x": 0,
      "y": 5,
      "z": 0,
      "name": "Rock_Sandstone_Brick"
    },
    {
      "x": 0,
      "y": 6,
      "z": 0,
      "name": "Rock_Sandstone_Brick"
    },
    {
      "x": 0,
      "y": 0,
      "z": 1,
      "name": "Rock_Sandstone"
    },
    {
      "x": 0,
      "y": 1,
      "z": 1,
      "name": "Rock_Sandstone_Brick"
    },
    {
      "x": 0,
      "y": 2,
      "z": 1,
      "name": "Block_Spawner_Block",
      "components": {
        "Components": {
          "PlacedByInteraction": {
            "WhoPlacedUuid": {
              "$binary": "x9M0GYCLPG+IqIodoDzEcQ==",
              "$type": "04"
            }
          },
          "BlockSpawner": {
            "BlockSpawnerId": "Zone2_Encounters_Tier4"
          }
        }
      }
    },
    {
      "x": 0,
      "y": 3,
      "z": 1,
      "name": "Empty"
    },
    {
      "x": 0,
      "y": 4,
      "z": 1,
      "name": "Empty"
    },
    {
      "x": 0,
      "y": 5,
      "z": 1,
      "name": "Rock_Sandstone_Brick"
    },
    {
      "x": 0,
      "y": 6,
      "z": 1,
      "name": "Rock_Sandstone_Brick"
    },
    {
      "x": 0,
      "y": 0,
      "z": 2,
      "name": "Rock_Sandstone_Brick_Smooth"
    },
    {
      "x": 0,
      "y": 1,
      "z": 2,
      "name": "Empty"
    },
    {
      "x": 0,
      "y": 2,
      "z": 2,
      "name": "Empty"
    },
    {
      "x": 0,
      "y": 3,
      "z": 2,
      "name": "Empty"
    },
    {
      "x": 0,
      "y": 4,
      "z": 2,
      "name": "Empty"
    },
    {
      "x": 0,
      "y": 5,
      "z": 2,
      "name": "Rock_Sandstone_Cobble_Half",
      "rotation": 8
    },
    {
      "x": 0,
      "y": 6,
      "z": 2,
      "name": "Rock_Sandstone_Brick"
    },
    {
      "x": 0,
      "y": 0,
      "z": 3,
      "name": "Rock_Sandstone_Brick_Smooth"
    },
    {
      "x": 0,
      "y": 1,
      "z": 3,
      "name": "Empty"
    },
    {
      "x": 0,
      "y": 2,
      "z": 3,
      "name": "Empty"
    },
    {
      "x": 0,
      "y": 3,
      "z": 3,
      "name": "Empty"
    },
    {
      "x": 0,
      "y": 4,
      "z": 3,
      "name": "Empty"
    },
    {
      "x": 0,
      "y": 5,
      "z": 3,
      "name": "Rock_Sandstone_Cobble_Half",
      "rotation": 8
    },
    {
      "x": 0,
      "y": 6,
      "z": 3,
      "name": "Rock_Sandstone_Brick"
    },
    {
      "x": 0,
      "y": 0,
      "z": 4,
      "name": "Wood_Drywood_Planks"
    },
    {
      "x": 0,
      "y": 1,
      "z": 4,
      "name": "Empty"
    },
    {
      "x": 0,
      "y": 2,
      "z": 4,
      "name": "Empty"
    },
    {
      "x": 0,
      "y": 3,
      "z": 4,
      "name": "Empty"
    },
    {
      "x": 0,
      "y": 4,
      "z": 4,
      "name": "Empty"
    },
    {
      "x": 0,
      "y": 5,
      "z": 4,
      "name": "Rock_Sandstone_Cobble_Half",
      "rotation": 8
    },
    {
      "x": 0,
      "y": 6,
      "z": 4,
      "name": "Rock_Sandstone_Brick"
    },
    {
      "x": 0,
      "y": 0,
      "z": 5,
      "name": "Wood_Drywood_Planks"
    },
    {
      "x": 0,
      "y": 1,
      "z": 5,
      "name": "Empty"
    },
    {
      "x": 0,
      "y": 2,
      "z": 5,
      "name": "Empty"
    },
    {
      "x": 0,
      "y": 3,
      "z": 5,
      "name": "Empty"
    },
    {
      "x": 0,
      "y": 4,
      "z": 5,
      "name": "Empty"
    },
    {
      "x": 0,
      "y": 5,
      "z": 5,
      "name": "Rock_Sandstone_Brick"
    },
    {
      "x": 0,
      "y": 6,
      "z": 5,
      "name": "Rock_Sandstone_Brick"
    },
    {
      "x": 0,
      "y": 0,
      "z": 6,
      "name": "Wood_Drywood_Planks"
    },
    {
      "x": 0,
      "y": 1,
      "z": 6,
      "name": "Empty"
    },
    {
      "x": 0,
      "y": 2,
      "z": 6,
      "name": "Empty"
    },
    {
      "x": 0,
      "y": 3,
      "z": 6,
      "name": "Empty"
    },
    {
      "x": 0,
      "y": 4,
      "z": 6,
      "name": "Empty"
    },
    {
      "x": 0,
      "y": 5,
      "z": 6,
      "name": "Rock_Sandstone_Cobble_Half",
      "rotation": 8
    },
    {
      "x": 0,
      "y": 6,
      "z": 6,
      "name": "Rock_Sandstone_Cobble"
    },
    {
      "x": 0,
      "y": 0,
      "z": 7,
      "name": "Rock_Sandstone_Brick_Smooth"
    },
    {
      "x": 0,
      "y": 1,
      "z": 7,
      "name": "Empty"
    },
    {
      "x": 0,
      "y": 2,
      "z": 7,
      "name": "Empty"
    },
    {
      "x": 0,
      "y": 3,
      "z": 7,
      "name": "Empty"
    },
    {
      "x": 0,
      "y": 4,
      "z": 7,
      "name": "Empty"
    },
    {
      "x": 0,
      "y": 5,
      "z": 7,
      "name": "Rock_Sandstone_Cobble_Half",
      "rotation": 8
    },
    {
      "x": 0,
      "y": 6,
      "z": 7,
      "name": "Rock_Sandstone_Brick"
    },
    {
      "x": 0,
      "y": 1,
      "z": 8,
      "name": "Empty"
    },
    {
      "x": 0,
      "y": 2,
      "z": 8,
      "name": "Empty"
    },
    {
      "x": 0,
      "y": 3,
      "z": 8,
      "name": "Empty"
    },
    {
      "x": 0,
      "y": 4,
      "z": 8,
      "name": "Empty"
    },
    {
      "x": 0,
      "y": 5,
      "z": 8,
      "name": "Rock_Sandstone_Brick"
    },
    {
      "x": 0,
      "y": 6,
      "z": 8,
      "name": "Rock_Sandstone_Brick"
    },
    {
      "x": 1,
      "y": 0,
      "z": -8,
      "name": "Rock_Sandstone"
    },
    {
      "x": 1,
      "y": 1,
      "z": -8,
      "name": "Furniture_Village_Pot"
    },
    {
      "x": 1,
      "y": 2,
      "z": -8,
      "name": "Empty"
    },
    {
      "x": 1,
      "y": 3,
      "z": -8,
      "name": "Empty"
    },
    {
      "x": 1,
      "y": 4,
      "z": -8,
      "name": "Empty"
    },
    {
      "x": 1,
      "y": 5,
      "z": -8,
      "name": "Empty"
    },
    {
      "x": 1,
      "y": 0,
      "z": -7,
      "name": "Rock_Sandstone"
    },
    {
      "x": 1,
      "y": 1,
      "z": -7,
      "name": "Rock_Sandstone"
    },
    {
      "x": 1,
      "y": 2,
      "z": -7,
      "name": "Rock_Sandstone"
    },
    {
      "x": 1,
      "y": 3,
      "z": -7,
      "name": "Rock_Sandstone"
    },
    {
      "x": 1,
      "y": 4,
      "z": -7,
      "name": "Rock_Sandstone"
    },
    {
      "x": 1,
      "y": 5,
      "z": -7,
      "name": "Rock_Sandstone"
    },
    {
      "x": 1,
      "y": 6,
      "z": -7,
      "name": "Rock_Sandstone"
    },
    {
      "x": 1,
      "y": 0,
      "z": -6,
      "name": "Rock_Sandstone"
    },
    {
      "x": 1,
      "y": 1,
      "z": -6,
      "name": "Rock_Sandstone"
    },
    {
      "x": 1,
      "y": 2,
      "z": -6,
      "name": "Furniture_Ancient_Pot"
    },
    {
      "x": 1,
      "y": 3,
      "z": -6,
      "name": "Empty"
    },
    {
      "x": 1,
      "y": 4,
      "z": -6,
      "name": "Empty"
    },
    {
      "x": 1,
      "y": 5,
      "z": -6,
      "name": "Rock_Sandstone_Cobble_Half",
      "rotation": 8
    },
    {
      "x": 1,
      "y": 6,
      "z": -6,
      "name": "Rock_Sandstone_Brick"
    },
    {
      "x": 1,
      "y": 0,
      "z": -5,
      "name": "Wood_Drywood_Planks"
    },
    {
      "x": 1,
      "y": 1,
      "z": -5,
      "name": "Empty"
    },
    {
      "x": 1,
      "y": 2,
      "z": -5,
      "name": "Empty"
    },
    {
      "x": 1,
      "y": 3,
      "z": -5,
      "name": "Empty"
    },
    {
      "x": 1,
      "y": 4,
      "z": -5,
      "name": "Empty"
    },
    {
      "x": 1,
      "y": 5,
      "z": -5,
      "name": "Rock_Sandstone_Brick"
    },
    {
      "x": 1,
      "y": 6,
      "z": -5,
      "name": "Rock_Sandstone_Cobble"
    },
    {
      "x": 1,
      "y": 0,
      "z": -4,
      "name": "Wood_Drywood_Planks"
    },
    {
      "x": 1,
      "y": 1,
      "z": -4,
      "name": "Empty"
    },
    {
      "x": 1,
      "y": 2,
      "z": -4,
      "name": "Empty"
    },
    {
      "x": 1,
      "y": 3,
      "z": -4,
      "name": "Empty"
    },
    {
      "x": 1,
      "y": 4,
      "z": -4,
      "name": "Empty"
    },
    {
      "x": 1,
      "y": 5,
      "z": -4,
      "name": "Rock_Sandstone_Cobble_Half",
      "rotation": 8
    },
    {
      "x": 1,
      "y": 6,
      "z": -4,
      "name": "Rock_Sandstone_Cobble"
    },
    {
      "x": 1,
      "y": 0,
      "z": -3,
      "name": "Rock_Sandstone_Brick_Smooth"
    },
    {
      "x": 1,
      "y": 1,
      "z": -3,
      "name": "Empty"
    },
    {
      "x": 1,
      "y": 2,
      "z": -3,
      "name": "Empty"
    },
    {
      "x": 1,
      "y": 3,
      "z": -3,
      "name": "Empty"
    },
    {
      "x": 1,
      "y": 4,
      "z": -3,
      "name": "Empty"
    },
    {
      "x": 1,
      "y": 5,
      "z": -3,
      "name": "Rock_Sandstone_Cobble_Half",
      "rotation": 8
    },
    {
      "x": 1,
      "y": 6,
      "z": -3,
      "name": "Rock_Sandstone_Brick"
    },
    {
      "x": 1,
      "y": 0,
      "z": -2,
      "name": "Rock_Sandstone_Brick_Smooth"
    },
    {
      "x": 1,
      "y": 1,
      "z": -2,
      "name": "Rubble_Sandstone"
    },
    {
      "x": 1,
      "y": 2,
      "z": -2,
      "name": "Empty"
    },
    {
      "x": 1,
      "y": 3,
      "z": -2,
      "name": "Empty"
    },
    {
      "x": 1,
      "y": 4,
      "z": -2,
      "name": "Empty"
    },
    {
      "x": 1,
      "y": 5,
      "z": -2,
      "name": "Rock_Sandstone_Cobble_Half",
      "rotation": 8
    },
    {
      "x": 1,
      "y": 6,
      "z": -2,
      "name": "Rock_Sandstone_Brick"
    },
    {
      "x": 1,
      "y": 0,
      "z": -1,
      "name": "Rock_Sandstone"
    },
    {
      "x": 1,
      "y": 1,
      "z": -1,
      "name": "Rock_Sandstone_Brick"
    },
    {
      "x": 1,
      "y": 2,
      "z": -1,
      "name": "Empty"
    },
    {
      "x": 1,
      "y": 3,
      "z": -1,
      "name": "Empty"
    },
    {
      "x": 1,
      "y": 4,
      "z": -1,
      "name": "Empty"
    },
    {
      "x": 1,
      "y": 5,
      "z": -1,
      "name": "Rock_Sandstone_Brick"
    },
    {
      "x": 1,
      "y": 6,
      "z": -1,
      "name": "Rock_Sandstone_Brick"
    },
    {
      "x": 1,
      "y": 0,
      "z": 0,
      "name": "Rock_Sandstone_Cobble"
    },
    {
      "x": 1,
      "y": 1,
      "z": 0,
      "name": "Rock_Sandstone_Cobble"
    },
    {
      "x": 1,
      "y": 2,
      "z": 0,
      "name": "Rock_Sandstone_Cobble"
    },
    {
      "x": 1,
      "y": 3,
      "z": 0,
      "name": "Rock_Sandstone_Cobble"
    },
    {
      "x": 1,
      "y": 4,
      "z": 0,
      "name": "Rock_Sandstone_Cobble"
    },
    {
      "x": 1,
      "y": 5,
      "z": 0,
      "name": "Rock_Sandstone_Brick"
    },
    {
      "x": 1,
      "y": 6,
      "z": 0,
      "name": "Rock_Sandstone_Brick"
    },
    {
      "x": 1,
      "y": 0,
      "z": 1,
      "name": "Rock_Sandstone"
    },
    {
      "x": 1,
      "y": 1,
      "z": 1,
      "name": "Rock_Sandstone_Brick"
    },
    {
      "x": 1,
      "y": 2,
      "z": 1,
      "name": "Empty"
    },
    {
      "x": 1,
      "y": 3,
      "z": 1,
      "name": "Empty"
    },
    {
      "x": 1,
      "y": 4,
      "z": 1,
      "name": "Empty"
    },
    {
      "x": 1,
      "y": 5,
      "z": 1,
      "name": "Rock_Sandstone_Brick"
    },
    {
      "x": 1,
      "y": 6,
      "z": 1,
      "name": "Rock_Sandstone_Brick"
    },
    {
      "x": 1,
      "y": 0,
      "z": 2,
      "name": "Rock_Sandstone_Brick_Smooth"
    },
    {
      "x": 1,
      "y": 1,
      "z": 2,
      "name": "Empty"
    },
    {
      "x": 1,
      "y": 2,
      "z": 2,
      "name": "Empty"
    },
    {
      "x": 1,
      "y": 3,
      "z": 2,
      "name": "Empty"
    },
    {
      "x": 1,
      "y": 4,
      "z": 2,
      "name": "Empty"
    },
    {
      "x": 1,
      "y": 5,
      "z": 2,
      "name": "Rock_Sandstone_Cobble_Half",
      "rotation": 8
    },
    {
      "x": 1,
      "y": 6,
      "z": 2,
      "name": "Rock_Sandstone_Brick"
    },
    {
      "x": 1,
      "y": 0,
      "z": 3,
      "name": "Rock_Sandstone_Brick_Smooth"
    },
    {
      "x": 1,
      "y": 1,
      "z": 3,
      "name": "Empty"
    },
    {
      "x": 1,
      "y": 2,
      "z": 3,
      "name": "Empty"
    },
    {
      "x": 1,
      "y": 3,
      "z": 3,
      "name": "Empty"
    },
    {
      "x": 1,
      "y": 4,
      "z": 3,
      "name": "Empty"
    },
    {
      "x": 1,
      "y": 5,
      "z": 3,
      "name": "Rock_Sandstone_Cobble_Half",
      "rotation": 8
    },
    {
      "x": 1,
      "y": 6,
      "z": 3,
      "name": "Rock_Sandstone_Brick"
    },
    {
      "x": 1,
      "y": 0,
      "z": 4,
      "name": "Wood_Drywood_Planks"
    },
    {
      "x": 1,
      "y": 1,
      "z": 4,
      "name": "Empty"
    },
    {
      "x": 1,
      "y": 2,
      "z": 4,
      "name": "Empty"
    },
    {
      "x": 1,
      "y": 3,
      "z": 4,
      "name": "Empty"
    },
    {
      "x": 1,
      "y": 4,
      "z": 4,
      "name": "Empty"
    },
    {
      "x": 1,
      "y": 5,
      "z": 4,
      "name": "Rock_Sandstone_Cobble_Half",
      "rotation": 8
    },
    {
      "x": 1,
      "y": 6,
      "z": 4,
      "name": "Rock_Sandstone_Brick"
    },
    {
      "x": 1,
      "y": 0,
      "z": 5,
      "name": "Wood_Drywood_Planks"
    },
    {
      "x": 1,
      "y": 1,
      "z": 5,
      "name": "Empty"
    },
    {
      "x": 1,
      "y": 2,
      "z": 5,
      "name": "Empty"
    },
    {
      "x": 1,
      "y": 3,
      "z": 5,
      "name": "Empty"
    },
    {
      "x": 1,
      "y": 4,
      "z": 5,
      "name": "Empty"
    },
    {
      "x": 1,
      "y": 5,
      "z": 5,
      "name": "Rock_Sandstone_Brick"
    },
    {
      "x": 1,
      "y": 6,
      "z": 5,
      "name": "Rock_Sandstone_Brick"
    },
    {
      "x": 1,
      "y": 0,
      "z": 6,
      "name": "Wood_Drywood_Planks"
    },
    {
      "x": 1,
      "y": 1,
      "z": 6,
      "name": "Empty"
    },
    {
      "x": 1,
      "y": 2,
      "z": 6,
      "name": "Empty"
    },
    {
      "x": 1,
      "y": 3,
      "z": 6,
      "name": "Empty"
    },
    {
      "x": 1,
      "y": 4,
      "z": 6,
      "name": "Empty"
    },
    {
      "x": 1,
      "y": 5,
      "z": 6,
      "name": "Rock_Sandstone_Cobble_Half",
      "rotation": 8
    },
    {
      "x": 1,
      "y": 6,
      "z": 6,
      "name": "Rock_Sandstone_Cobble"
    },
    {
      "x": 1,
      "y": 0,
      "z": 7,
      "name": "Rock_Sandstone_Brick_Smooth"
    },
    {
      "x": 1,
      "y": 1,
      "z": 7,
      "name": "Empty"
    },
    {
      "x": 1,
      "y": 2,
      "z": 7,
      "name": "Empty"
    },
    {
      "x": 1,
      "y": 3,
      "z": 7,
      "name": "Empty"
    },
    {
      "x": 1,
      "y": 4,
      "z": 7,
      "name": "Empty"
    },
    {
      "x": 1,
      "y": 5,
      "z": 7,
      "name": "Rock_Sandstone_Cobble_Half",
      "rotation": 8
    },
    {
      "x": 1,
      "y": 6,
      "z": 7,
      "name": "Rock_Sandstone_Cobble"
    },
    {
      "x": 1,
      "y": 1,
      "z": 8,
      "name": "Empty"
    },
    {
      "x": 1,
      "y": 2,
      "z": 8,
      "name": "Empty"
    },
    {
      "x": 1,
      "y": 3,
      "z": 8,
      "name": "Empty"
    },
    {
      "x": 1,
      "y": 4,
      "z": 8,
      "name": "Empty"
    },
    {
      "x": 1,
      "y": 5,
      "z": 8,
      "name": "Rock_Sandstone_Brick"
    },
    {
      "x": 1,
      "y": 6,
      "z": 8,
      "name": "Rock_Sandstone_Brick"
    },
    {
      "x": 2,
      "y": 0,
      "z": -8,
      "name": "Rock_Sandstone"
    },
    {
      "x": 2,
      "y": 1,
      "z": -8,
      "name": "Rock_Sandstone"
    },
    {
      "x": 2,
      "y": 2,
      "z": -8,
      "name": "Rock_Sandstone"
    },
    {
      "x": 2,
      "y": 3,
      "z": -8,
      "name": "Rock_Sandstone"
    },
    {
      "x": 2,
      "y": 4,
      "z": -8,
      "name": "Rock_Sandstone"
    },
    {
      "x": 2,
      "y": 0,
      "z": -7,
      "name": "Rock_Sandstone"
    },
    {
      "x": 2,
      "y": 1,
      "z": -7,
      "name": "Rock_Sandstone"
    },
    {
      "x": 2,
      "y": 2,
      "z": -7,
      "name": "Rock_Sandstone"
    },
    {
      "x": 2,
      "y": 3,
      "z": -7,
      "name": "Rock_Sandstone"
    },
    {
      "x": 2,
      "y": 4,
      "z": -7,
      "name": "Rock_Sandstone"
    },
    {
      "x": 2,
      "y": 5,
      "z": -7,
      "name": "Rock_Sandstone"
    },
    {
      "x": 2,
      "y": 6,
      "z": -7,
      "name": "Rock_Sandstone"
    },
    {
      "x": 2,
      "y": 0,
      "z": -6,
      "name": "Rock_Sandstone"
    },
    {
      "x": 2,
      "y": 1,
      "z": -6,
      "name": "Rock_Sandstone"
    },
    {
      "x": 2,
      "y": 2,
      "z": -6,
      "name": "Rock_Sandstone"
    },
    {
      "x": 2,
      "y": 3,
      "z": -6,
      "name": "Rock_Sandstone"
    },
    {
      "x": 2,
      "y": 4,
      "z": -6,
      "name": "Empty"
    },
    {
      "x": 2,
      "y": 5,
      "z": -6,
      "name": "Rock_Sandstone_Cobble_Half",
      "rotation": 8
    },
    {
      "x": 2,
      "y": 6,
      "z": -6,
      "name": "Rock_Sandstone_Brick"
    },
    {
      "x": 2,
      "y": 0,
      "z": -5,
      "name": "Wood_Drywood_Planks"
    },
    {
      "x": 2,
      "y": 1,
      "z": -5,
      "name": "Empty"
    },
    {
      "x": 2,
      "y": 2,
      "z": -5,
      "name": "Empty"
    },
    {
      "x": 2,
      "y": 3,
      "z": -5,
      "name": "Empty"
    },
    {
      "x": 2,
      "y": 4,
      "z": -5,
      "name": "Empty"
    },
    {
      "x": 2,
      "y": 5,
      "z": -5,
      "name": "Rock_Sandstone_Brick"
    },
    {
      "x": 2,
      "y": 6,
      "z": -5,
      "name": "Rock_Sandstone_Brick"
    },
    {
      "x": 2,
      "y": 0,
      "z": -4,
      "name": "Wood_Drywood_Planks"
    },
    {
      "x": 2,
      "y": 1,
      "z": -4,
      "name": "Empty"
    },
    {
      "x": 2,
      "y": 2,
      "z": -4,
      "name": "Empty"
    },
    {
      "x": 2,
      "y": 3,
      "z": -4,
      "name": "Empty"
    },
    {
      "x": 2,
      "y": 4,
      "z": -4,
      "name": "Empty"
    },
    {
      "x": 2,
      "y": 5,
      "z": -4,
      "name": "Rock_Sandstone_Cobble_Half",
      "rotation": 8
    },
    {
      "x": 2,
      "y": 6,
      "z": -4,
      "name": "Rock_Sandstone_Brick"
    },
    {
      "x": 2,
      "y": 0,
      "z": -3,
      "name": "Rock_Sandstone_Brick_Smooth"
    },
    {
      "x": 2,
      "y": 1,
      "z": -3,
      "name": "Empty"
    },
    {
      "x": 2,
      "y": 2,
      "z": -3,
      "name": "Empty"
    },
    {
      "x": 2,
      "y": 3,
      "z": -3,
      "name": "Empty"
    },
    {
      "x": 2,
      "y": 4,
      "z": -3,
      "name": "Empty"
    },
    {
      "x": 2,
      "y": 5,
      "z": -3,
      "name": "Rock_Sandstone_Cobble_Half",
      "rotation": 8
    },
    {
      "x": 2,
      "y": 6,
      "z": -3,
      "name": "Rock_Sandstone_Brick"
    },
    {
      "x": 2,
      "y": 0,
      "z": -2,
      "name": "Rock_Sandstone_Brick_Smooth"
    },
    {
      "x": 2,
      "y": 1,
      "z": -2,
      "name": "Empty"
    },
    {
      "x": 2,
      "y": 2,
      "z": -2,
      "name": "Empty"
    },
    {
      "x": 2,
      "y": 3,
      "z": -2,
      "name": "Empty"
    },
    {
      "x": 2,
      "y": 4,
      "z": -2,
      "name": "Empty"
    },
    {
      "x": 2,
      "y": 5,
      "z": -2,
      "name": "Rock_Sandstone_Cobble_Half",
      "rotation": 8
    },
    {
      "x": 2,
      "y": 6,
      "z": -2,
      "name": "Rock_Sandstone_Brick"
    },
    {
      "x": 2,
      "y": 0,
      "z": -1,
      "name": "Rock_Sandstone"
    },
    {
      "x": 2,
      "y": 1,
      "z": -1,
      "name": "Rock_Sandstone_Brick_Pillar_Base"
    },
    {
      "x": 2,
      "y": 2,
      "z": -1,
      "name": "Rock_Sandstone_Brick_Pillar_Middle"
    },
    {
      "x": 2,
      "y": 3,
      "z": -1,
      "name": "Rock_Sandstone_Brick_Pillar_Middle"
    },
    {
      "x": 2,
      "y": 4,
      "z": -1,
      "name": "Rock_Sandstone_Brick_Pillar_Base",
      "rotation": 8
    },
    {
      "x": 2,
      "y": 5,
      "z": -1,
      "name": "Rock_Sandstone_Brick"
    },
    {
      "x": 2,
      "y": 6,
      "z": -1,
      "name": "Rock_Sandstone_Brick"
    },
    {
      "x": 2,
      "y": 0,
      "z": 0,
      "name": "Rock_Sandstone"
    },
    {
      "x": 2,
      "y": 1,
      "z": 0,
      "name": "Rock_Sandstone_Brick"
    },
    {
      "x": 2,
      "y": 2,
      "z": 0,
      "name": "Rock_Sandstone_Brick"
    },
    {
      "x": 2,
      "y": 3,
      "z": 0,
      "name": "Rock_Sandstone_Brick"
    },
    {
      "x": 2,
      "y": 4,
      "z": 0,
      "name": "Rock_Sandstone_Brick"
    },
    {
      "x": 2,
      "y": 5,
      "z": 0,
      "name": "Rock_Sandstone_Brick"
    },
    {
      "x": 2,
      "y": 6,
      "z": 0,
      "name": "Rock_Sandstone_Brick"
    },
    {
      "x": 2,
      "y": 0,
      "z": 1,
      "name": "Rock_Sandstone"
    },
    {
      "x": 2,
      "y": 1,
      "z": 1,
      "name": "Rock_Sandstone_Brick_Pillar_Base"
    },
    {
      "x": 2,
      "y": 2,
      "z": 1,
      "name": "Rock_Sandstone_Brick_Pillar_Middle"
    },
    {
      "x": 2,
      "y": 3,
      "z": 1,
      "name": "Rock_Sandstone_Brick_Pillar_Middle"
    },
    {
      "x": 2,
      "y": 4,
      "z": 1,
      "name": "Rock_Sandstone_Brick_Pillar_Base",
      "rotation": 8
    },
    {
      "x": 2,
      "y": 5,
      "z": 1,
      "name": "Rock_Sandstone_Brick"
    },
    {
      "x": 2,
      "y": 6,
      "z": 1,
      "name": "Rock_Sandstone_Brick"
    },
    {
      "x": 2,
      "y": 0,
      "z": 2,
      "name": "Rock_Sandstone_Brick_Smooth"
    },
    {
      "x": 2,
      "y": 1,
      "z": 2,
      "name": "Wood_Deadwood_Beam"
    },
    {
      "x": 2,
      "y": 2,
      "z": 2,
      "name": "Furniture_Ancient_Torch"
    },
    {
      "x": 2,
      "y": 3,
      "z": 2,
      "name": "Empty"
    },
    {
      "x": 2,
      "y": 4,
      "z": 2,
      "name": "Empty"
    },
    {
      "x": 2,
      "y": 5,
      "z": 2,
      "name": "Rock_Sandstone_Cobble_Half",
      "rotation": 8
    },
    {
      "x": 2,
      "y": 6,
      "z": 2,
      "name": "Rock_Sandstone_Brick"
    },
    {
      "x": 2,
      "y": 0,
      "z": 3,
      "name": "Rock_Sandstone_Brick_Smooth"
    },
    {
      "x": 2,
      "y": 1,
      "z": 3,
      "name": "Rubble_Sandstone"
    },
    {
      "x": 2,
      "y": 2,
      "z": 3,
      "name": "Empty"
    },
    {
      "x": 2,
      "y": 3,
      "z": 3,
      "name": "Empty"
    },
    {
      "x": 2,
      "y": 4,
      "z": 3,
      "name": "Empty"
    },
    {
      "x": 2,
      "y": 5,
      "z": 3,
      "name": "Rock_Sandstone_Cobble_Half",
      "rotation": 8
    },
    {
      "x": 2,
      "y": 6,
      "z": 3,
      "name": "Rock_Sandstone_Brick"
    },
    {
      "x": 2,
      "y": 0,
      "z": 4,
      "name": "Wood_Drywood_Planks"
    },
    {
      "x": 2,
      "y": 1,
      "z": 4,
      "name": "Empty"
    },
    {
      "x": 2,
      "y": 2,
      "z": 4,
      "name": "Empty"
    },
    {
      "x": 2,
      "y": 3,
      "z": 4,
      "name": "Empty"
    },
    {
      "x": 2,
      "y": 4,
      "z": 4,
      "name": "Empty"
    },
    {
      "x": 2,
      "y": 5,
      "z": 4,
      "name": "Rock_Sandstone_Cobble_Half",
      "rotation": 8
    },
    {
      "x": 2,
      "y": 6,
      "z": 4,
      "name": "Rock_Sandstone_Brick"
    },
    {
      "x": 2,
      "y": 0,
      "z": 5,
      "name": "Wood_Drywood_Planks"
    },
    {
      "x": 2,
      "y": 1,
      "z": 5,
      "name": "Empty"
    },
    {
      "x": 2,
      "y": 2,
      "z": 5,
      "name": "Empty"
    },
    {
      "x": 2,
      "y": 3,
      "z": 5,
      "name": "Empty"
    },
    {
      "x": 2,
      "y": 4,
      "z": 5,
      "name": "Empty"
    },
    {
      "x": 2,
      "y": 5,
      "z": 5,
      "name": "Rock_Sandstone_Brick"
    },
    {
      "x": 2,
      "y": 6,
      "z": 5,
      "name": "Rock_Sandstone_Cobble"
    },
    {
      "x": 2,
      "y": 0,
      "z": 6,
      "name": "Wood_Drywood_Planks"
    },
    {
      "x": 2,
      "y": 1,
      "z": 6,
      "name": "Empty"
    },
    {
      "x": 2,
      "y": 2,
      "z": 6,
      "name": "Empty"
    },
    {
      "x": 2,
      "y": 3,
      "z": 6,
      "name": "Empty"
    },
    {
      "x": 2,
      "y": 4,
      "z": 6,
      "name": "Empty"
    },
    {
      "x": 2,
      "y": 5,
      "z": 6,
      "name": "Rock_Sandstone_Cobble_Half",
      "rotation": 8
    },
    {
      "x": 2,
      "y": 6,
      "z": 6,
      "name": "Rock_Sandstone_Cobble"
    },
    {
      "x": 2,
      "y": 0,
      "z": 7,
      "name": "Rock_Sandstone_Brick_Smooth"
    },
    {
      "x": 2,
      "y": 1,
      "z": 7,
      "name": "Empty"
    },
    {
      "x": 2,
      "y": 2,
      "z": 7,
      "name": "Empty"
    },
    {
      "x": 2,
      "y": 3,
      "z": 7,
      "name": "Empty"
    },
    {
      "x": 2,
      "y": 4,
      "z": 7,
      "name": "Empty"
    },
    {
      "x": 2,
      "y": 5,
      "z": 7,
      "name": "Rock_Sandstone_Cobble_Half",
      "rotation": 8
    },
    {
      "x": 2,
      "y": 6,
      "z": 7,
      "name": "Rock_Sandstone_Cobble"
    },
    {
      "x": 2,
      "y": 0,
      "z": 8,
      "name": "Rock_Sandstone"
    },
    {
      "x": 2,
      "y": 1,
      "z": 8,
      "name": "Empty"
    },
    {
      "x": 2,
      "y": 2,
      "z": 8,
      "name": "Empty"
    },
    {
      "x": 2,
      "y": 3,
      "z": 8,
      "name": "Empty"
    },
    {
      "x": 2,
      "y": 4,
      "z": 8,
      "name": "Empty"
    },
    {
      "x": 2,
      "y": 5,
      "z": 8,
      "name": "Rock_Sandstone_Brick"
    },
    {
      "x": 2,
      "y": 6,
      "z": 8,
      "name": "Rock_Sandstone_Brick"
    },
    {
      "x": 3,
      "y": 0,
      "z": -8,
      "name": "Rock_Sandstone"
    },
    {
      "x": 3,
      "y": 1,
      "z": -8,
      "name": "Rock_Sandstone"
    },
    {
      "x": 3,
      "y": 2,
      "z": -8,
      "name": "Rock_Sandstone"
    },
    {
      "x": 3,
      "y": 3,
      "z": -8,
      "name": "Rock_Sandstone"
    },
    {
      "x": 3,
      "y": 4,
      "z": -8,
      "name": "Rock_Sandstone"
    },
    {
      "x": 3,
      "y": 5,
      "z": -8,
      "name": "Rock_Sandstone"
    },
    {
      "x": 3,
      "y": 0,
      "z": -7,
      "name": "Rock_Sandstone"
    },
    {
      "x": 3,
      "y": 1,
      "z": -7,
      "name": "Rock_Sandstone"
    },
    {
      "x": 3,
      "y": 2,
      "z": -7,
      "name": "Rock_Sandstone"
    },
    {
      "x": 3,
      "y": 3,
      "z": -7,
      "name": "Rock_Sandstone"
    },
    {
      "x": 3,
      "y": 4,
      "z": -7,
      "name": "Rock_Sandstone"
    },
    {
      "x": 3,
      "y": 5,
      "z": -7,
      "name": "Rock_Sandstone"
    },
    {
      "x": 3,
      "y": 6,
      "z": -7,
      "name": "Rock_Sandstone"
    },
    {
      "x": 3,
      "y": 0,
      "z": -6,
      "name": "Rock_Sandstone"
    },
    {
      "x": 3,
      "y": 1,
      "z": -6,
      "name": "Rock_Sandstone"
    },
    {
      "x": 3,
      "y": 2,
      "z": -6,
      "name": "Rock_Sandstone"
    },
    {
      "x": 3,
      "y": 3,
      "z": -6,
      "name": "Rubble_Sandstone_Medium"
    },
    {
      "x": 3,
      "y": 4,
      "z": -6,
      "name": "Empty"
    },
    {
      "x": 3,
      "y": 5,
      "z": -6,
      "name": "Rock_Sandstone_Brick"
    },
    {
      "x": 3,
      "y": 6,
      "z": -6,
      "name": "Rock_Sandstone_Brick"
    },
    {
      "x": 3,
      "y": 0,
      "z": -5,
      "name": "Wood_Drywood_Planks"
    },
    {
      "x": 3,
      "y": 1,
      "z": -5,
      "name": "Empty"
    },
    {
      "x": 3,
      "y": 2,
      "z": -5,
      "name": "Empty"
    },
    {
      "x": 3,
      "y": 3,
      "z": -5,
      "name": "Empty"
    },
    {
      "x": 3,
      "y": 4,
      "z": -5,
      "name": "Empty"
    },
    {
      "x": 3,
      "y": 5,
      "z": -5,
      "name": "Rock_Sandstone_Brick"
    },
    {
      "x": 3,
      "y": 6,
      "z": -5,
      "name": "Rock_Sandstone_Brick"
    },
    {
      "x": 3,
      "y": 0,
      "z": -4,
      "name": "Wood_Drywood_Planks"
    },
    {
      "x": 3,
      "y": 1,
      "z": -4,
      "name": "Empty"
    },
    {
      "x": 3,
      "y": 2,
      "z": -4,
      "name": "Empty"
    },
    {
      "x": 3,
      "y": 3,
      "z": -4,
      "name": "Empty"
    },
    {
      "x": 3,
      "y": 4,
      "z": -4,
      "name": "Empty"
    },
    {
      "x": 3,
      "y": 5,
      "z": -4,
      "name": "Rock_Sandstone_Brick"
    },
    {
      "x": 3,
      "y": 6,
      "z": -4,
      "name": "Rock_Sandstone_Brick"
    },
    {
      "x": 3,
      "y": 0,
      "z": -3,
      "name": "Wood_Drywood_Planks"
    },
    {
      "x": 3,
      "y": 1,
      "z": -3,
      "name": "Empty"
    },
    {
      "x": 3,
      "y": 2,
      "z": -3,
      "name": "Empty"
    },
    {
      "x": 3,
      "y": 3,
      "z": -3,
      "name": "Empty"
    },
    {
      "x": 3,
      "y": 4,
      "z": -3,
      "name": "Empty"
    },
    {
      "x": 3,
      "y": 5,
      "z": -3,
      "name": "Rock_Sandstone_Brick"
    },
    {
      "x": 3,
      "y": 6,
      "z": -3,
      "name": "Rock_Sandstone_Brick"
    },
    {
      "x": 3,
      "y": 0,
      "z": -2,
      "name": "Wood_Drywood_Planks"
    },
    {
      "x": 3,
      "y": 1,
      "z": -2,
      "name": "Empty"
    },
    {
      "x": 3,
      "y": 2,
      "z": -2,
      "name": "Empty"
    },
    {
      "x": 3,
      "y": 3,
      "z": -2,
      "name": "Empty"
    },
    {
      "x": 3,
      "y": 4,
      "z": -2,
      "name": "Empty"
    },
    {
      "x": 3,
      "y": 5,
      "z": -2,
      "name": "Rock_Sandstone_Brick"
    },
    {
      "x": 3,
      "y": 6,
      "z": -2,
      "name": "Rock_Sandstone_Brick"
    },
    {
      "x": 3,
      "y": 0,
      "z": -1,
      "name": "Wood_Drywood_Planks"
    },
    {
      "x": 3,
      "y": 1,
      "z": -1,
      "name": "Empty"
    },
    {
      "x": 3,
      "y": 2,
      "z": -1,
      "name": "Empty"
    },
    {
      "x": 3,
      "y": 3,
      "z": -1,
      "name": "Empty"
    },
    {
      "x": 3,
      "y": 4,
      "z": -1,
      "name": "Empty"
    },
    {
      "x": 3,
      "y": 5,
      "z": -1,
      "name": "Rock_Sandstone_Brick"
    },
    {
      "x": 3,
      "y": 6,
      "z": -1,
      "name": "Rock_Sandstone_Brick"
    },
    {
      "x": 3,
      "y": 0,
      "z": 0,
      "name": "Wood_Drywood_Planks"
    },
    {
      "x": 3,
      "y": 1,
      "z": 0,
      "name": "Furniture_Temple_Wind_Pot"
    },
    {
      "x": 3,
      "y": 2,
      "z": 0,
      "name": "Furniture_Temple_Wind_Pot",
      "filler": 1024
    },
    {
      "x": 3,
      "y": 3,
      "z": 0,
      "name": "Empty"
    },
    {
      "x": 3,
      "y": 4,
      "z": 0,
      "name": "Rock_Sandstone_Brick_Stairs",
      "rotation": 11
    },
    {
      "x": 3,
      "y": 5,
      "z": 0,
      "name": "Rock_Sandstone_Brick"
    },
    {
      "x": 3,
      "y": 6,
      "z": 0,
      "name": "Rock_Sandstone_Brick"
    },
    {
      "x": 3,
      "y": 0,
      "z": 1,
      "name": "Wood_Drywood_Planks"
    },
    {
      "x": 3,
      "y": 1,
      "z": 1,
      "name": "Deco_Pot_Clay_Broken"
    },
    {
      "x": 3,
      "y": 2,
      "z": 1,
      "name": "Empty"
    },
    {
      "x": 3,
      "y": 3,
      "z": 1,
