{
  "version": 8,
  "blockIdVersion": 8,
  "anchorX": -1,
  "anchorY": 61,
  "anchorZ": 21,
  "blocks": [
    {
      "x": -8,
      "y": 59,
      "z": 17,
      "name": "Soil_Dirt_Cold"
    },
    {
      "x": -8,
      "y": 60,
      "z": 17,
      "name": "Soil_Dirt_Cold"
    },
    {
      "x": -8,
      "y": 61,
      "z": 17,
      "name": "Soil_Dirt_Cold"
    },
    {
      "x": -8,
      "y": 62,
      "z": 17,
      "name": "Wood_Redwood_Branch_Long"
    },
    {
      "x": -8,
      "y": 63,
      "z": 17,
      "name": "Wood_Redwood_Branch_Long"
    },
    {
      "x": -8,
      "y": 64,
      "z": 17,
      "name": "Wood_Redwood_Planks"
    },
    {
      "x": -8,
      "y": 65,
      "z": 17,
      "name": "Wood_Deadwood_Roof_Flat",
      "rotation": 1
    },
    {
      "x": -8,
      "y": 59,
      "z": 18,
      "name": "Soil_Dirt_Cold"
    },
    {
      "x": -8,
      "y": 60,
      "z": 18,
      "name": "Soil_Dirt_Cold"
    },
    {
      "x": -8,
      "y": 61,
      "z": 18,
      "name": "Soil_Dirt_Cold"
    },
    {
      "x": -8,
      "y": 62,
      "z": 18,
      "name": "Empty"
    },
    {
      "x": -8,
      "y": 63,
      "z": 18,
      "name": "Empty"
    },
    {
      "x": -8,
      "y": 64,
      "z": 18,
      "name": "Wood_Redwood_Stairs",
      "rotation": 10
    },
    {
      "x": -8,
      "y": 65,
      "z": 18,
      "name": "Wood_Deadwood_Roof_Flat",
      "rotation": 1
    },
    {
      "x": -8,
      "y": 59,
      "z": 19,
      "name": "Soil_Dirt_Cold"
    },
    {
      "x": -8,
      "y": 60,
      "z": 19,
      "name": "Soil_Dirt_Cold"
    },
    {
      "x": -8,
      "y": 61,
      "z": 19,
      "name": "Soil_Dirt_Cold"
    },
    {
      "x": -8,
      "y": 62,
      "z": 19,
      "name": "Empty"
    },
    {
      "x": -8,
      "y": 63,
      "z": 19,
      "name": "Empty"
    },
    {
      "x": -8,
      "y": 64,
      "z": 19,
      "name": "Empty"
    },
    {
      "x": -8,
      "y": 65,
      "z": 19,
      "name": "Wood_Deadwood_Roof_Flat",
      "rotation": 1
    },
    {
      "x": -8,
      "y": 59,
      "z": 20,
      "name": "Soil_Dirt_Cold"
    },
    {
      "x": -8,
      "y": 60,
      "z": 20,
      "name": "Soil_Dirt_Cold"
    },
    {
      "x": -8,
      "y": 61,
      "z": 20,
      "name": "Soil_Dirt_Cold"
    },
    {
      "x": -8,
      "y": 62,
      "z": 20,
      "name": "Empty"
    },
    {
      "x": -8,
      "y": 63,
      "z": 20,
      "name": "Empty"
    },
    {
      "x": -8,
      "y": 64,
      "z": 20,
      "name": "Empty"
    },
    {
      "x": -8,
      "y": 65,
      "z": 20,
      "name": "Wood_Deadwood_Roof_Flat",
      "rotation": 1
    },
    {
      "x": -8,
      "y": 59,
      "z": 21,
      "name": "Soil_Dirt_Cold"
    },
    {
      "x": -8,
      "y": 60,
      "z": 21,
      "name": "Soil_Dirt_Cold"
    },
    {
      "x": -8,
      "y": 61,
      "z": 21,
      "name": "Soil_Dirt_Cold"
    },
    {
      "x": -8,
      "y": 62,
      "z": 21,
      "name": "Empty"
    },
    {
      "x": -8,
      "y": 63,
      "z": 21,
      "name": "Empty"
    },
    {
      "x": -8,
      "y": 64,
      "z": 21,
      "name": "Empty"
    },
    {
      "x": -8,
      "y": 65,
      "z": 21,
      "name": "Wood_Deadwood_Roof_Flat",
      "rotation": 1
    },
    {
      "x": -8,
      "y": 59,
      "z": 22,
      "name": "Soil_Dirt_Cold"
    },
    {
      "x": -8,
      "y": 60,
      "z": 22,
      "name": "Soil_Dirt_Cold"
    },
    {
      "x": -8,
      "y": 61,
      "z": 22,
      "name": "Soil_Dirt_Cold"
    },
    {
      "x": -8,
      "y": 62,
      "z": 22,
      "name": "Empty"
    },
    {
      "x": -8,
      "y": 63,
      "z": 22,
      "name": "Empty"
    },
    {
      "x": -8,
      "y": 64,
      "z": 22,
      "name": "Empty"
    },
    {
      "x": -8,
      "y": 65,
      "z": 22,
      "name": "Wood_Deadwood_Roof_Flat",
      "rotation": 1
    },
    {
      "x": -8,
      "y": 59,
      "z": 23,
      "name": "Soil_Dirt_Cold"
    },
    {
      "x": -8,
      "y": 60,
      "z": 23,
      "name": "Soil_Dirt_Cold"
    },
    {
      "x": -8,
      "y": 61,
      "z": 23,
      "name": "Soil_Dirt_Cold"
    },
    {
      "x": -8,
      "y": 62,
      "z": 23,
      "name": "Empty"
    },
    {
      "x": -8,
      "y": 63,
      "z": 23,
      "name": "Empty"
    },
    {
      "x": -8,
      "y": 64,
      "z": 23,
      "name": "Wood_Redwood_Stairs",
      "rotation": 8
    },
    {
      "x": -8,
      "y": 65,
      "z": 23,
      "name": "Wood_Deadwood_Roof_Flat",
      "rotation": 1
    },
    {
      "x": -8,
      "y": 59,
      "z": 24,
      "name": "Soil_Dirt_Cold"
    },
    {
      "x": -8,
      "y": 60,
      "z": 24,
      "name": "Soil_Dirt_Cold"
    },
    {
      "x": -8,
      "y": 61,
      "z": 24,
      "name": "Soil_Dirt_Cold"
    },
    {
      "x": -8,
      "y": 62,
      "z": 24,
      "name": "Wood_Redwood_Branch_Long"
    },
    {
      "x": -8,
      "y": 63,
      "z": 24,
      "name": "Wood_Redwood_Branch_Long"
    },
    {
      "x": -8,
      "y": 64,
      "z": 24,
      "name": "Wood_Redwood_Planks"
    },
    {
      "x": -8,
      "y": 65,
      "z": 24,
      "name": "Wood_Deadwood_Roof_Flat",
      "rotation": 1
    },
    {
      "x": -7,
      "y": 59,
      "z": 17,
      "name": "Soil_Dirt_Cold"
    },
    {
      "x": -7,
      "y": 60,
      "z": 17,
      "name": "Soil_Dirt_Cold"
    },
    {
      "x": -7,
      "y": 61,
      "z": 17,
      "name": "Soil_Dirt_Cold"
    },
    {
      "x": -7,
      "y": 62,
      "z": 17,
      "name": "Empty"
    },
    {
      "x": -7,
      "y": 63,
      "z": 17,
      "name": "Empty"
    },
    {
      "x": -7,
      "y": 64,
      "z": 17,
      "name": "Wood_Redwood_Stairs",
      "rotation": 11
    },
    {
      "x": -7,
      "y": 65,
      "z": 17,
      "name": "Wood_Deadwood_Roof_Flat",
      "rotation": 1
    },
    {
      "x": -7,
      "y": 58,
      "z": 18,
      "name": "Soil_Dirt_Cold"
    },
    {
      "x": -7,
      "y": 59,
      "z": 18,
      "name": "Soil_Dirt_Cold"
    },
    {
      "x": -7,
      "y": 60,
      "z": 18,
      "name": "Soil_Dirt_Cold"
    },
    {
      "x": -7,
      "y": 61,
      "z": 18,
      "name": "Soil_Dirt_Cold"
    },
    {
      "x": -7,
      "y": 62,
      "z": 18,
      "name": "Empty"
    },
    {
      "x": -7,
      "y": 63,
      "z": 18,
      "name": "Empty"
    },
    {
      "x": -7,
      "y": 64,
      "z": 18,
      "name": "Empty"
    },
    {
      "x": -7,
      "y": 65,
      "z": 18,
      "name": "Wood_Deadwood_Roof_Flat",
      "rotation": 1
    },
    {
      "x": -7,
      "y": 58,
      "z": 19,
      "name": "Soil_Dirt_Cold"
    },
    {
      "x": -7,
      "y": 59,
      "z": 19,
      "name": "Soil_Dirt_Cold"
    },
    {
      "x": -7,
      "y": 60,
      "z": 19,
      "name": "Soil_Dirt_Cold"
    },
    {
      "x": -7,
      "y": 61,
      "z": 19,
      "name": "Soil_Dirt_Cold"
    },
    {
      "x": -7,
      "y": 62,
      "z": 19,
      "name": "Empty"
    },
    {
      "x": -7,
      "y": 63,
      "z": 19,
      "name": "Empty"
    },
    {
      "x": -7,
      "y": 64,
      "z": 19,
      "name": "Empty"
    },
    {
      "x": -7,
      "y": 65,
      "z": 19,
      "name": "Wood_Deadwood_Roof_Flat",
      "rotation": 1
    },
    {
      "x": -7,
      "y": 58,
      "z": 20,
      "name": "Soil_Dirt_Cold"
    },
    {
      "x": -7,
      "y": 59,
      "z": 20,
      "name": "Soil_Dirt_Cold"
    },
    {
      "x": -7,
      "y": 60,
      "z": 20,
      "name": "Soil_Dirt_Cold"
    },
    {
      "x": -7,
      "y": 61,
      "z": 20,
      "name": "Soil_Dirt_Cold"
    },
    {
      "x": -7,
      "y": 62,
      "z": 20,
      "name": "Empty"
    },
    {
      "x": -7,
      "y": 63,
      "z": 20,
      "name": "Empty"
    },
    {
      "x": -7,
      "y": 64,
      "z": 20,
      "name": "Empty"
    },
    {
      "x": -7,
      "y": 65,
      "z": 20,
      "name": "Wood_Deadwood_Roof_Flat",
      "rotation": 1
    },
    {
      "x": -7,
      "y": 58,
      "z": 21,
      "name": "Soil_Dirt_Cold"
    },
    {
      "x": -7,
      "y": 59,
      "z": 21,
      "name": "Soil_Dirt_Cold"
    },
    {
      "x": -7,
      "y": 60,
      "z": 21,
      "name": "Soil_Dirt_Cold"
    },
    {
      "x": -7,
      "y": 61,
      "z": 21,
      "name": "Soil_Dirt_Cold"
    },
    {
      "x": -7,
      "y": 62,
      "z": 21,
      "name": "Empty"
    },
    {
      "x": -7,
      "y": 63,
      "z": 21,
      "name": "Empty"
    },
    {
      "x": -7,
      "y": 64,
      "z": 21,
      "name": "Empty"
    },
    {
      "x": -7,
      "y": 65,
      "z": 21,
      "name": "Wood_Deadwood_Roof_Flat",
      "rotation": 1
    },
    {
      "x": -7,
      "y": 58,
      "z": 22,
      "name": "Soil_Dirt_Cold"
    },
    {
      "x": -7,
      "y": 59,
      "z": 22,
      "name": "Soil_Dirt_Cold"
    },
    {
      "x": -7,
      "y": 60,
      "z": 22,
      "name": "Soil_Dirt_Cold"
    },
    {
      "x": -7,
      "y": 61,
      "z": 22,
      "name": "Soil_Dirt_Cold"
    },
    {
      "x": -7,
      "y": 62,
      "z": 22,
      "name": "Empty"
    },
    {
      "x": -7,
      "y": 63,
      "z": 22,
      "name": "Empty"
    },
    {
      "x": -7,
      "y": 64,
      "z": 22,
      "name": "Empty"
    },
    {
      "x": -7,
      "y": 65,
      "z": 22,
      "name": "Wood_Deadwood_Roof_Flat",
      "rotation": 1
    },
    {
      "x": -7,
      "y": 58,
      "z": 23,
      "name": "Soil_Dirt_Cold"
    },
    {
      "x": -7,
      "y": 59,
      "z": 23,
      "name": "Soil_Dirt_Cold"
    },
    {
      "x": -7,
      "y": 60,
      "z": 23,
      "name": "Soil_Dirt_Cold"
    },
    {
      "x": -7,
      "y": 61,
      "z": 23,
      "name": "Soil_Dirt_Cold"
    },
    {
      "x": -7,
      "y": 62,
      "z": 23,
      "name": "Empty"
    },
    {
      "x": -7,
      "y": 63,
      "z": 23,
      "name": "Empty"
    },
    {
      "x": -7,
      "y": 64,
      "z": 23,
      "name": "Empty"
    },
    {
      "x": -7,
      "y": 65,
      "z": 23,
      "name": "Wood_Deadwood_Roof_Flat",
      "rotation": 1
    },
    {
      "x": -7,
      "y": 59,
      "z": 24,
      "name": "Soil_Dirt_Cold"
    },
    {
      "x": -7,
      "y": 60,
      "z": 24,
      "name": "Soil_Dirt_Cold"
    },
    {
      "x": -7,
      "y": 61,
      "z": 24,
      "name": "Soil_Dirt_Cold"
    },
    {
      "x": -7,
      "y": 62,
      "z": 24,
      "name": "Empty"
    },
    {
      "x": -7,
      "y": 63,
      "z": 24,
      "name": "Empty"
    },
    {
      "x": -7,
      "y": 64,
      "z": 24,
      "name": "Wood_Redwood_Stairs",
      "rotation": 11
    },
    {
      "x": -7,
      "y": 65,
      "z": 24,
      "name": "Wood_Deadwood_Roof_Flat",
      "rotation": 1
    },
    {
      "x": -7,
      "y": 59,
      "z": 25,
      "name": "Soil_Dirt_Cold"
    },
    {
      "x": -7,
      "y": 60,
      "z": 25,
      "name": "Soil_Dirt_Cold"
    },
    {
      "x": -7,
      "y": 61,
      "z": 25,
      "name": "Soil_Dirt_Cold"
    },
    {
      "x": -7,
      "y": 62,
      "z": 25,
      "name": "Empty"
    },
    {
      "x": -7,
      "y": 63,
      "z": 25,
      "name": "Empty"
    },
    {
      "x": -7,
      "y": 64,
      "z": 25,
      "name": "Empty"
    },
    {
      "x": -6,
      "y": 66,
      "z": 15,
      "name": "Wood_Redwood_Trunk",
      "rotation": 5
    },
    {
      "x": -6,
      "y": 68,
      "z": 15,
      "name": "Wood_Redwood_Trunk",
      "rotation": 5
    },
    {
      "x": -6,
      "y": 59,
      "z": 16,
      "name": "Soil_Dirt_Cold"
    },
    {
      "x": -6,
      "y": 60,
      "z": 16,
      "name": "Soil_Dirt_Cold"
    },
    {
      "x": -6,
      "y": 61,
      "z": 16,
      "name": "Soil_Dirt_Cold"
    },
    {
      "x": -6,
      "y": 62,
      "z": 16,
      "name": "Empty"
    },
    {
      "x": -6,
      "y": 63,
      "z": 16,
      "name": "Empty"
    },
    {
      "x": -6,
      "y": 64,
      "z": 16,
      "name": "Empty"
    },
    {
      "x": -6,
      "y": 65,
      "z": 16,
      "name": "Wood_Redwood_Planks_Half",
      "rotation": 7
    },
    {
      "x": -6,
      "y": 66,
      "z": 16,
      "name": "Wood_Redwood_Planks_Half",
      "rotation": 7
    },
    {
      "x": -6,
      "y": 58,
      "z": 17,
      "name": "Soil_Dirt_Cold"
    },
    {
      "x": -6,
      "y": 59,
      "z": 17,
      "name": "Soil_Dirt_Cold"
    },
    {
      "x": -6,
      "y": 60,
      "z": 17,
      "name": "Soil_Dirt_Cold"
    },
    {
      "x": -6,
      "y": 61,
      "z": 17,
      "name": "Soil_Dirt_Cold"
    },
    {
      "x": -6,
      "y": 62,
      "z": 17,
      "name": "Empty"
    },
    {
      "x": -6,
      "y": 63,
      "z": 17,
      "name": "Empty"
    },
    {
      "x": -6,
      "y": 64,
      "z": 17,
      "name": "Wood_Redwood_Stairs",
      "rotation": 9
    },
    {
      "x": -6,
      "y": 65,
      "z": 17,
      "name": "Wood_Deadwood_Roof",
      "rotation": 3
    },
    {
      "x": -6,
      "y": 66,
      "z": 17,
      "name": "Wood_Redwood_Planks_Half",
      "rotation": 7
    },
    {
      "x": -6,
      "y": 58,
      "z": 18,
      "name": "Soil_Dirt_Cold"
    },
    {
      "x": -6,
      "y": 59,
      "z": 18,
      "name": "Soil_Dirt_Cold"
    },
    {
      "x": -6,
      "y": 60,
      "z": 18,
      "name": "Soil_Dirt_Cold"
    },
    {
      "x": -6,
      "y": 61,
      "z": 18,
      "name": "Soil_Dirt_Cold"
    },
    {
      "x": -6,
      "y": 62,
      "z": 18,
      "name": "Empty"
    },
    {
      "x": -6,
      "y": 63,
      "z": 18,
      "name": "Empty"
    },
    {
      "x": -6,
      "y": 64,
      "z": 18,
      "name": "Empty"
    },
    {
      "x": -6,
      "y": 65,
      "z": 18,
      "name": "Wood_Deadwood_Roof",
      "rotation": 3
    },
    {
      "x": -6,
      "y": 66,
      "z": 18,
      "name": "Furniture_Lumberjack_Platform",
      "rotation": 1
    },
    {
      "x": -6,
      "y": 67,
      "z": 18,
      "name": "*Wood_Softwood_Fence_State_Definitions_Corner",
      "rotation": 1
    },
    {
      "x": -6,
      "y": 68,
      "z": 18,
      "name": "Empty"
    },
    {
      "x": -6,
      "y": 58,
      "z": 19,
      "name": "Soil_Dirt_Cold"
    },
    {
      "x": -6,
      "y": 59,
      "z": 19,
      "name": "Soil_Dirt_Cold"
    },
    {
      "x": -6,
      "y": 60,
      "z": 19,
      "name": "Soil_Dirt_Cold"
    },
    {
      "x": -6,
      "y": 61,
      "z": 19,
      "name": "Soil_Dirt_Cold"
    },
    {
      "x": -6,
      "y": 62,
      "z": 19,
      "name": "Empty"
    },
    {
      "x": -6,
      "y": 63,
      "z": 19,
      "name": "Empty"
    },
    {
      "x": -6,
      "y": 64,
      "z": 19,
      "name": "Empty"
    },
    {
      "x": -6,
      "y": 65,
      "z": 19,
      "name": "Wood_Deadwood_Roof",
      "rotation": 3
    },
    {
      "x": -6,
      "y": 66,
      "z": 19,
      "name": "Furniture_Lumberjack_Platform",
      "rotation": 1
    },
    {
      "x": -6,
      "y": 67,
      "z": 19,
      "name": "Wood_Softwood_Fence",
      "rotation": 3
    },
    {
      "x": -6,
      "y": 68,
      "z": 19,
      "name": "Empty"
    },
    {
      "x": -6,
      "y": 69,
      "z": 19,
      "name": "*Wood_Deadwood_Roof_State_Definitions_Corner_Right",
      "rotation": 3
    },
    {
      "x": -6,
      "y": 58,
      "z": 20,
      "name": "Soil_Dirt_Cold"
    },
    {
      "x": -6,
      "y": 59,
      "z": 20,
      "name": "Soil_Dirt_Cold"
    },
    {
      "x": -6,
      "y": 60,
      "z": 20,
      "name": "Soil_Dirt_Cold"
    },
    {
      "x": -6,
      "y": 61,
      "z": 20,
      "name": "Soil_Dirt_Cold"
    },
    {
      "x": -6,
      "y": 62,
      "z": 20,
      "name": "Empty"
    },
    {
      "x": -6,
      "y": 63,
      "z": 20,
      "name": "Empty"
    },
    {
      "x": -6,
      "y": 64,
      "z": 20,
      "name": "Empty"
    },
    {
      "x": -6,
      "y": 65,
      "z": 20,
      "name": "Wood_Deadwood_Roof",
      "rotation": 3
    },
    {
      "x": -6,
      "y": 66,
      "z": 20,
      "name": "Furniture_Lumberjack_Platform",
      "rotation": 1
    },
    {
      "x": -6,
      "y": 67,
      "z": 20,
      "name": "Wood_Softwood_Fence",
      "rotation": 3
    },
    {
      "x": -6,
      "y": 68,
      "z": 20,
      "name": "Empty"
    },
    {
      "x": -6,
      "y": 69,
      "z": 20,
      "name": "Wood_Deadwood_Roof",
      "rotation": 3
    },
    {
      "x": -6,
      "y": 58,
      "z": 21,
      "name": "Soil_Dirt_Cold"
    },
    {
      "x": -6,
      "y": 59,
      "z": 21,
      "name": "Soil_Dirt_Cold"
    },
    {
      "x": -6,
      "y": 60,
      "z": 21,
      "name": "Soil_Dirt_Cold"
    },
    {
      "x": -6,
      "y": 61,
      "z": 21,
      "name": "Soil_Dirt_Cold"
    },
    {
      "x": -6,
      "y": 62,
      "z": 21,
      "name": "Empty"
    },
    {
      "x": -6,
      "y": 63,
      "z": 21,
      "name": "Empty"
    },
    {
      "x": -6,
      "y": 64,
      "z": 21,
      "name": "Empty"
    },
    {
      "x": -6,
      "y": 65,
      "z": 21,
      "name": "Wood_Deadwood_Roof",
      "rotation": 3
    },
    {
      "x": -6,
      "y": 66,
      "z": 21,
      "name": "Furniture_Lumberjack_Platform",
      "rotation": 1
    },
    {
      "x": -6,
      "y": 67,
      "z": 21,
      "name": "Wood_Softwood_Fence",
      "rotation": 3
    },
    {
      "x": -6,
      "y": 68,
      "z": 21,
      "name": "Empty"
    },
    {
      "x": -6,
      "y": 69,
      "z": 21,
      "name": "*Wood_Deadwood_Roof_State_Definitions_Corner_Right"
    },
    {
      "x": -6,
      "y": 58,
      "z": 22,
      "name": "Soil_Dirt_Cold"
    },
    {
      "x": -6,
      "y": 59,
      "z": 22,
      "name": "Soil_Dirt_Cold"
    },
    {
      "x": -6,
      "y": 60,
      "z": 22,
      "name": "Soil_Dirt_Cold"
    },
    {
      "x": -6,
      "y": 61,
      "z": 22,
      "name": "Soil_Dirt_Cold"
    },
    {
      "x": -6,
      "y": 62,
      "z": 22,
      "name": "Empty"
    },
    {
      "x": -6,
      "y": 63,
      "z": 22,
      "name": "Empty"
    },
    {
      "x": -6,
      "y": 64,
      "z": 22,
      "name": "Empty"
    },
    {
      "x": -6,
      "y": 65,
      "z": 22,
      "name": "Wood_Deadwood_Roof",
      "rotation": 3
    },
    {
      "x": -6,
      "y": 66,
      "z": 22,
      "name": "Furniture_Lumberjack_Platform",
      "rotation": 1
    },
    {
      "x": -6,
      "y": 67,
      "z": 22,
      "name": "*Wood_Softwood_Fence_State_Definitions_Corner",
      "rotation": 2
    },
    {
      "x": -6,
      "y": 68,
      "z": 22,
      "name": "Empty"
    },
    {
      "x": -6,
      "y": 58,
      "z": 23,
      "name": "Soil_Dirt_Cold"
    },
    {
      "x": -6,
      "y": 59,
      "z": 23,
      "name": "Soil_Dirt_Cold"
    },
    {
      "x": -6,
      "y": 60,
      "z": 23,
      "name": "Soil_Dirt_Cold"
    },
    {
      "x": -6,
      "y": 61,
      "z": 23,
      "name": "Soil_Dirt_Cold"
    },
    {
      "x": -6,
      "y": 62,
      "z": 23,
      "name": "Empty"
    },
    {
      "x": -6,
      "y": 63,
      "z": 23,
      "name": "Empty"
    },
    {
      "x": -6,
      "y": 64,
      "z": 23,
      "name": "Empty"
    },
    {
      "x": -6,
      "y": 65,
      "z": 23,
      "name": "Wood_Deadwood_Roof",
      "rotation": 3
    },
    {
      "x": -6,
      "y": 58,
      "z": 24,
      "name": "Soil_Dirt_Cold"
    },
    {
      "x": -6,
      "y": 59,
      "z": 24,
      "name": "Soil_Dirt_Cold"
    },
    {
      "x": -6,
      "y": 60,
      "z": 24,
      "name": "Soil_Dirt_Cold"
    },
    {
      "x": -6,
      "y": 61,
      "z": 24,
      "name": "Soil_Dirt_Cold"
    },
    {
      "x": -6,
      "y": 62,
      "z": 24,
      "name": "Empty"
    },
    {
      "x": -6,
      "y": 63,
      "z": 24,
      "name": "Empty"
    },
    {
      "x": -6,
      "y": 64,
      "z": 24,
      "name": "Wood_Redwood_Stairs",
      "rotation": 9
    },
    {
      "x": -6,
      "y": 65,
      "z": 24,
      "name": "Wood_Deadwood_Roof",
      "rotation": 3
    },
    {
      "x": -6,
      "y": 66,
      "z": 24,
      "name": "Wood_Redwood_Planks_Half",
      "rotation": 7
    },
    {
      "x": -6,
      "y": 59,
      "z": 25,
      "name": "Soil_Dirt_Cold"
    },
    {
      "x": -6,
      "y": 60,
      "z": 25,
      "name": "Soil_Dirt_Cold"
    },
    {
      "x": -6,
      "y": 61,
      "z": 25,
      "name": "Soil_Dirt_Cold"
    },
    {
      "x": -6,
      "y": 62,
      "z": 25,
      "name": "Empty"
    },
    {
      "x": -6,
      "y": 63,
      "z": 25,
      "name": "Empty"
    },
    {
      "x": -6,
      "y": 64,
      "z": 25,
      "name": "Empty"
    },
    {
      "x": -6,
      "y": 66,
      "z": 25,
      "name": "Wood_Redwood_Planks_Half",
      "rotation": 7
    },
    {
      "x": -6,
      "y": 67,
      "z": 25,
      "name": "Wood_Redwood_Planks_Half",
      "rotation": 7
    },
    {
      "x": -6,
      "y": 66,
      "z": 26,
      "name": "Wood_Redwood_Trunk",
      "rotation": 5
    },
    {
      "x": -5,
      "y": 65,
      "z": 14,
      "name": "Wood_Redwood_Trunk",
      "rotation": 4
    },
    {
      "x": -5,
      "y": 67,
      "z": 14,
      "name": "Wood_Redwood_Trunk",
      "rotation": 4
    },
    {
      "x": -5,
      "y": 69,
      "z": 14,
      "name": "Wood_Redwood_Trunk",
      "rotation": 4
    },
    {
      "x": -5,
      "y": 70,
      "z": 14,
      "name": "Wood_Deadwood_Roof",
      "rotation": 3
    },
    {
      "x": -5,
      "y": 65,
      "z": 15,
      "name": "Wood_Redwood_Trunk",
      "rotation": 4
    },
    {
      "x": -5,
      "y": 66,
      "z": 15,
      "name": "Wood_Redwood_Trunk",
      "rotation": 5
    },
    {
      "x": -5,
      "y": 67,
      "z": 15,
      "name": "Wood_Redwood_Trunk",
      "rotation": 4
    },
    {
      "x": -5,
      "y": 68,
      "z": 15,
      "name": "Wood_Redwood_Trunk",
      "rotation": 5
    },
    {
      "x": -5,
      "y": 69,
      "z": 15,
      "name": "Wood_Redwood_Trunk",
      "rotation": 4
    },
    {
      "x": -5,
      "y": 70,
      "z": 15,
      "name": "Wood_Deadwood_Roof",
      "rotation": 3
    },
    {
      "x": -5,
      "y": 59,
      "z": 16,
      "name": "Soil_Dirt_Cold"
    },
    {
      "x": -5,
      "y": 60,
      "z": 16,
      "name": "Soil_Dirt_Cold"
    },
    {
      "x": -5,
      "y": 61,
      "z": 16,
      "name": "Wood_Redwood_Trunk"
    },
    {
      "x": -5,
      "y": 62,
      "z": 16,
      "name": "Wood_Redwood_Trunk"
    },
    {
      "x": -5,
      "y": 63,
      "z": 16,
      "name": "Wood_Redwood_Trunk"
    },
    {
      "x": -5,
      "y": 64,
      "z": 16,
      "name": "Wood_Redwood_Trunk"
    },
    {
      "x": -5,
      "y": 65,
      "z": 16,
      "name": "Wood_Redwood_Trunk",
      "rotation": 4
    },
    {
      "x": -5,
      "y": 66,
      "z": 16,
      "name": "Wood_Redwood_Planks"
    },
    {
      "x": -5,
      "y": 67,
      "z": 16,
      "name": "Wood_Redwood_Trunk",
      "rotation": 4
    },
    {
      "x": -5,
      "y": 68,
      "z": 16,
      "name": "Wood_Redwood_Planks"
    },
    {
      "x": -5,
      "y": 69,
      "z": 16,
      "name": "Wood_Redwood_Trunk",
      "rotation": 4
    },
    {
      "x": -5,
      "y": 70,
      "z": 16,
      "name": "Wood_Deadwood_Roof",
      "rotation": 3
    },
    {
      "x": -5,
      "y": 58,
      "z": 17,
      "name": "Soil_Dirt_Cold"
    },
    {
      "x": -5,
      "y": 59,
      "z": 17,
      "name": "Soil_Dirt_Cold"
    },
    {
      "x": -5,
      "y": 60,
      "z": 17,
      "name": "Soil_Dirt_Cold"
    },
    {
      "x": -5,
      "y": 61,
      "z": 17,
      "name": "Soil_Dirt_Cold"
    },
    {
      "x": -5,
      "y": 62,
      "z": 17,
      "name": "Empty"
    },
    {
      "x": -5,
      "y": 63,
      "z": 17,
      "name": "Empty"
    },
    {
      "x": -5,
      "y": 64,
      "z": 17,
      "name": "Wood_Redwood_Planks"
    },
    {
      "x": -5,
      "y": 65,
      "z": 17,
      "name": "Wood_Redwood_Trunk",
      "rotation": 4
    },
    {
      "x": -5,
      "y": 66,
      "z": 17,
      "name": "Wood_Redwood_Trunk_Full",
      "rotation": 4
    },
    {
      "x": -5,
      "y": 67,
      "z": 17,
      "name": "Wood_Redwood_Trunk",
      "rotation": 4
    },
    {
      "x": -5,
      "y": 68,
      "z": 17,
      "name": "Wood_Redwood_Planks"
    },
    {
      "x": -5,
      "y": 69,
      "z": 17,
      "name": "Wood_Redwood_Trunk",
      "rotation": 4
    },
    {
      "x": -5,
      "y": 70,
      "z": 17,
      "name": "Wood_Deadwood_Roof",
      "rotation": 3
    },
    {
      "x": -5,
      "y": 58,
      "z": 18,
      "name": "Soil_Dirt_Cold"
    },
    {
      "x": -5,
      "y": 59,
      "z": 18,
      "name": "Soil_Dirt_Cold"
    },
    {
      "x": -5,
      "y": 60,
      "z": 18,
      "name": "Soil_Dirt_Cold"
    },
    {
      "x": -5,
      "y": 61,
      "z": 18,
      "name": "Soil_Dirt_Cold"
    },
    {
      "x": -5,
      "y": 62,
      "z": 18,
      "name": "Empty"
    },
    {
      "x": -5,
      "y": 63,
      "z": 18,
      "name": "Empty"
    },
    {
      "x": -5,
      "y": 64,
      "z": 18,
      "name": "Empty"
    },
    {
      "x": -5,
      "y": 65,
      "z": 18,
      "name": "Wood_Redwood_Trunk",
      "rotation": 4
    },
    {
      "x": -5,
      "y": 66,
      "z": 18,
      "name": "Wood_Redwood_Trunk",
      "rotation": 4
    },
    {
      "x": -5,
      "y": 67,
      "z": 18,
      "name": "Wood_Redwood_Trunk",
      "rotation": 4
    },
    {
      "x": -5,
      "y": 68,
      "z": 18,
      "name": "Wood_Redwood_Planks"
    },
    {
      "x": -5,
      "y": 69,
      "z": 18,
      "name": "Wood_Redwood_Trunk",
      "rotation": 4
    },
    {
      "x": -5,
      "y": 70,
      "z": 18,
      "name": "Wood_Deadwood_Roof",
      "rotation": 3
    },
    {
      "x": -5,
      "y": 58,
      "z": 19,
      "name": "Soil_Dirt_Cold"
    },
    {
      "x": -5,
      "y": 59,
      "z": 19,
      "name": "Soil_Dirt_Cold"
    },
    {
      "x": -5,
      "y": 60,
      "z": 19,
      "name": "Soil_Dirt_Cold"
    },
    {
      "x": -5,
      "y": 61,
      "z": 19,
      "name": "Soil_Dirt_Cold"
    },
    {
      "x": -5,
      "y": 62,
      "z": 19,
      "name": "Empty"
    },
    {
      "x": -5,
      "y": 63,
      "z": 19,
      "name": "Empty"
    },
    {
      "x": -5,
      "y": 64,
      "z": 19,
      "name": "Empty"
    },
    {
      "x": -5,
      "y": 65,
      "z": 19,
      "name": "Wood_Redwood_Trunk",
      "rotation": 4
    },
    {
      "x": -5,
      "y": 66,
      "z": 19,
      "name": "Wood_Redwood_Trunk",
      "rotation": 4
    },
    {
      "x": -5,
      "y": 67,
      "z": 19,
      "name": "Wood_Redwood_Planks"
    },
    {
      "x": -5,
      "y": 68,
      "z": 19,
      "name": "Wood_Redwood_Planks"
    },
    {
      "x": -5,
      "y": 69,
      "z": 19,
      "name": "Wood_Redwood_Trunk",
      "rotation": 4
    },
    {
      "x": -5,
      "y": 70,
      "z": 19,
      "name": "Wood_Deadwood_Roof",
      "rotation": 3
    },
    {
      "x": -5,
      "y": 58,
      "z": 20,
      "name": "Soil_Dirt_Cold"
    },
    {
      "x": -5,
      "y": 59,
      "z": 20,
      "name": "Soil_Dirt_Cold"
    },
    {
      "x": -5,
      "y": 60,
      "z": 20,
      "name": "Soil_Dirt_Cold"
    },
    {
      "x": -5,
      "y": 61,
      "z": 20,
      "name": "Soil_Dirt_Cold"
    },
    {
      "x": -5,
      "y": 62,
      "z": 20,
      "name": "Empty"
    },
    {
      "x": -5,
      "y": 63,
      "z": 20,
      "name": "Wood_Torch_Wall",
      "rotation": 3
    },
    {
      "x": -5,
      "y": 64,
      "z": 20,
      "name": "Empty"
    },
    {
      "x": -5,
      "y": 65,
      "z": 20,
      "name": "Wood_Redwood_Trunk",
      "rotation": 4
    },
    {
      "x": -5,
      "y": 66,
      "z": 20,
      "name": "Wood_Redwood_Trunk",
      "rotation": 4
    },
    {
      "x": -5,
      "y": 67,
      "z": 20,
      "name": "Empty"
    },
    {
      "x": -5,
      "y": 68,
      "z": 20,
      "name": "Empty"
    },
    {
      "x": -5,
      "y": 69,
      "z": 20,
      "name": "Wood_Redwood_Trunk",
      "rotation": 4
    },
    {
      "x": -5,
      "y": 70,
      "z": 20,
      "name": "Wood_Deadwood_Roof",
      "rotation": 3
    },
    {
      "x": -5,
      "y": 58,
      "z": 21,
      "name": "Soil_Dirt_Cold"
    },
    {
      "x": -5,
      "y": 59,
      "z": 21,
      "name": "Soil_Dirt_Cold"
    },
    {
      "x": -5,
      "y": 60,
      "z": 21,
      "name": "Soil_Dirt_Cold"
    },
    {
      "x": -5,
      "y": 61,
      "z": 21,
      "name": "Soil_Dirt_Cold"
    },
    {
      "x": -5,
      "y": 62,
      "z": 21,
      "name": "Empty"
    },
    {
      "x": -5,
      "y": 63,
      "z": 21,
      "name": "Empty"
    },
    {
      "x": -5,
      "y": 64,
      "z": 21,
      "name": "Empty"
    },
    {
      "x": -5,
      "y": 65,
      "z": 21,
      "name": "Wood_Redwood_Trunk",
      "rotation": 4
    },
    {
      "x": -5,
      "y": 66,
      "z": 21,
      "name": "Wood_Redwood_Trunk",
      "rotation": 4
    },
    {
      "x": -5,
      "y": 67,
      "z": 21,
      "name": "Wood_Redwood_Planks"
    },
    {
      "x": -5,
      "y": 68,
      "z": 21,
      "name": "Wood_Redwood_Planks"
    },
    {
      "x": -5,
      "y": 69,
      "z": 21,
      "name": "Wood_Redwood_Trunk",
      "rotation": 4
    },
    {
      "x": -5,
      "y": 70,
      "z": 21,
      "name": "Wood_Deadwood_Roof",
      "rotation": 3
    },
    {
      "x": -5,
      "y": 58,
      "z": 22,
      "name": "Soil_Dirt_Cold"
    },
    {
      "x": -5,
      "y": 59,
      "z": 22,
      "name": "Soil_Dirt_Cold"
    },
    {
      "x": -5,
      "y": 60,
      "z": 22,
      "name": "Soil_Dirt_Cold"
    },
    {
      "x": -5,
      "y": 61,
      "z": 22,
      "name": "Soil_Dirt_Cold"
    },
    {
      "x": -5,
      "y": 62,
      "z": 22,
      "name": "Empty"
    },
    {
      "x": -5,
      "y": 63,
      "z": 22,
      "name": "Empty"
    },
    {
      "x": -5,
      "y": 64,
      "z": 22,
      "name": "Empty"
    },
    {
      "x": -5,
      "y": 65,
      "z": 22,
      "name": "Wood_Redwood_Trunk",
      "rotation": 4
    },
    {
      "x": -5,
      "y": 66,
      "z": 22,
      "name": "Wood_Redwood_Trunk",
      "rotation": 4
    },
    {
      "x": -5,
      "y": 67,
      "z": 22,
      "name": "Wood_Redwood_Trunk_Full",
      "rotation": 4
    },
    {
      "x": -5,
      "y": 68,
      "z": 22,
      "name": "Wood_Redwood_Planks"
    },
    {
      "x": -5,
      "y": 69,
      "z": 22,
      "name": "Wood_Redwood_Trunk",
      "rotation": 4
    },
    {
      "x": -5,
      "y": 70,
      "z": 22,
      "name": "Wood_Deadwood_Roof",
      "rotation": 3
    },
    {
      "x": -5,
      "y": 58,
      "z": 23,
      "name": "Soil_Dirt_Cold"
    },
    {
      "x": -5,
      "y": 59,
      "z": 23,
      "name": "Soil_Dirt_Cold"
    },
    {
      "x": -5,
      "y": 60,
      "z": 23,
      "name": "Soil_Dirt_Cold"
    },
    {
      "x": -5,
      "y": 61,
      "z": 23,
      "name": "Soil_Dirt_Cold"
    },
    {
      "x": -5,
      "y": 62,
      "z": 23,
      "name": "Empty"
    },
    {
      "x": -5,
      "y": 63,
      "z": 23,
      "name": "Empty"
    },
    {
      "x": -5,
      "y": 64,
      "z": 23,
      "name": "Empty"
    },
    {
      "x": -5,
      "y": 65,
      "z": 23,
      "name": "Wood_Redwood_Trunk",
      "rotation": 4
    },
    {
      "x": -5,
      "y": 66,
      "z": 23,
      "name": "Wood_Redwood_Trunk_Full",
      "rotation": 4
    },
    {
      "x": -5,
      "y": 67,
      "z": 23,
      "name": "Wood_Redwood_Trunk",
      "rotation": 4
    },
    {
      "x": -5,
      "y": 68,
      "z": 23,
      "name": "Furniture_Lumberjack_Window",
      "rotation": 1
    },
    {
      "x": -5,
      "y": 69,
      "z": 23,
      "name": "Wood_Redwood_Trunk",
      "rotation": 4
    },
    {
      "x": -5,
      "y": 70,
      "z": 23,
      "name": "Wood_Deadwood_Roof",
      "rotation": 3
    },
    {
      "x": -5,
      "y": 58,
      "z": 24,
      "name": "Soil_Dirt_Cold"
    },
    {
      "x": -5,
      "y": 59,
      "z": 24,
      "name": "Soil_Dirt_Cold"
    },
    {
      "x": -5,
      "y": 60,
      "z": 24,
      "name": "Soil_Dirt_Cold"
    },
    {
      "x": -5,
      "y": 61,
      "z": 24,
      "name": "Soil_Dirt_Cold"
    },
    {
      "x": -5,
      "y": 62,
      "z": 24,
      "name": "Empty"
    },
    {
      "x": -5,
      "y": 63,
      "z": 24,
      "name": "Empty"
    },
    {
      "x": -5,
      "y": 64,
      "z": 24,
      "name": "Wood_Redwood_Planks"
    },
    {
      "x": -5,
      "y": 65,
      "z": 24,
      "name": "Wood_Redwood_Trunk",
      "rotation": 4
    },
    {
      "x": -5,
      "y": 66,
      "z": 24,
      "name": "Wood_Redwood_Planks"
    },
    {
      "x": -5,
      "y": 67,
      "z": 24,
      "name": "Wood_Redwood_Trunk",
      "rotation": 4
    },
    {
      "x": -5,
      "y": 68,
      "z": 24,
      "name": "Wood_Redwood_Planks"
    },
    {
      "x": -5,
      "y": 69,
      "z": 24,
      "name": "Wood_Redwood_Trunk",
      "rotation": 4
    },
    {
      "x": -5,
      "y": 70,
      "z": 24,
      "name": "Wood_Deadwood_Roof",
      "rotation": 3
    },
    {
      "x": -5,
      "y": 59,
      "z": 25,
      "name": "Soil_Dirt_Cold"
    },
    {
      "x": -5,
      "y": 60,
      "z": 25,
      "name": "Soil_Dirt_Cold"
    },
    {
      "x": -5,
      "y": 61,
      "z": 25,
      "name": "Wood_Redwood_Trunk"
    },
    {
      "x": -5,
      "y": 62,
      "z": 25,
      "name": "Wood_Redwood_Trunk"
    },
    {
      "x": -5,
      "y": 63,
      "z": 25,
      "name": "Wood_Redwood_Trunk"
    },
    {
      "x": -5,
      "y": 64,
      "z": 25,
      "name": "Wood_Redwood_Trunk"
    },
    {
      "x": -5,
      "y": 65,
      "z": 25,
      "name": "Wood_Redwood_Trunk",
      "rotation": 4
    },
    {
      "x": -5,
      "y": 66,
      "z": 25,
      "name": "Wood_Redwood_Planks"
    },
    {
      "x": -5,
      "y": 67,
      "z": 25,
      "name": "Wood_Redwood_Trunk",
      "rotation": 4
    },
    {
      "x": -5,
      "y": 68,
      "z": 25,
      "name": "Wood_Redwood_Planks"
    },
    {
      "x": -5,
      "y": 69,
      "z": 25,
      "name": "Wood_Redwood_Trunk",
      "rotation": 4
    },
    {
      "x": -5,
      "y": 70,
      "z": 25,
      "name": "Wood_Deadwood_Roof",
      "rotation": 3
    },
    {
      "x": -5,
      "y": 65,
      "z": 26,
      "name": "Wood_Redwood_Trunk",
      "rotation": 4
    },
    {
      "x": -5,
      "y": 66,
      "z": 26,
      "name": "Wood_Redwood_Trunk",
      "rotation": 5
    },
    {
      "x": -5,
      "y": 67,
      "z": 26,
      "name": "Wood_Redwood_Trunk",
      "rotation": 4
    },
    {
      "x": -5,
      "y": 68,
      "z": 26,
      "name": "Wood_Redwood_Planks"
    },
    {
      "x": -5,
      "y": 69,
      "z": 26,
      "name": "Wood_Redwood_Trunk",
      "rotation": 4
    },
    {
      "x": -5,
      "y": 70,
      "z": 26,
      "name": "Wood_Deadwood_Roof",
      "rotation": 3
    },
    {
      "x": -5,
      "y": 65,
      "z": 27,
      "name": "Wood_Redwood_Trunk",
      "rotation": 4
    },
    {
      "x": -5,
      "y": 67,
      "z": 27,
      "name": "Wood_Redwood_Trunk",
      "rotation": 4
    },
    {
      "x": -5,
      "y": 69,
      "z": 27,
      "name": "Wood_Redwood_Trunk",
      "rotation": 4
    },
    {
      "x": -4,
      "y": 69,
      "z": 14,
      "name": "Wood_Redwood_Stairs",
      "rotation": 11
    },
    {
      "x": -4,
      "y": 70,
      "z": 14,
      "name": "Wood_Redwood_Stairs",
      "rotation": 3
    },
    {
      "x": -4,
      "y": 66,
      "z": 15,
      "name": "Wood_Redwood_Trunk",
      "rotation": 5
    },
    {
      "x": -4,
      "y": 67,
      "z": 15,
      "name": "Wood_Redwood_Trunk_Full",
      "rotation": 5
    },
    {
      "x": -4,
      "y": 68,
      "z": 15,
      "name": "Wood_Redwood_Trunk_Full",
      "rotation": 5
    },
    {
      "x": -4,
      "y": 69,
      "z": 15,
      "name": "Wood_Redwood_Planks"
    },
    {
      "x": -4,
      "y": 70,
      "z": 15,
      "name": "Wood_Redwood_Planks"
    },
    {
      "x": -4,
      "y": 71,
      "z": 15,
      "name": "Wood_Deadwood_Roof",
      "rotation": 3
    },
    {
      "x": -4,
      "y": 59,
      "z": 16,
      "name": "Soil_Dirt_Cold"
    },
    {
      "x": -4,
      "y": 60,
      "z": 16,
      "name": "Soil_Dirt_Cold"
    },
    {
      "x": -4,
      "y": 61,
      "z": 16,
      "name": "Rock_Shale"
    },
    {
      "x": -4,
      "y": 62,
      "z": 16,
      "name": "Rock_Shale"
    },
    {
      "x": -4,
      "y": 63,
      "z": 16,
      "name": "Rock_Shale"
    },
    {
      "x": -4,
      "y": 64,
      "z": 16,
      "name": "Rock_Shale_Brick"
    },
    {
      "x": -4,
      "y": 65,
      "z": 16,
      "name": "Rock_Shale_Brick"
    },
    {
      "x": -4,
      "y": 66,
      "z": 16,
      "name": "Wood_Redwood_Planks"
    },
    {
      "x": -4,
      "y": 67,
      "z": 16,
      "name": "Furniture_Lumberjack_Bed",
      "components": {
        "Components": {
          "RespawnBlock": {}
        }
      }
    },
    {
      "x": -4,
      "y": 68,
      "z": 16,
      "name": "Furniture_Lumberjack_Bed",
      "components": {
        "Components": {
          "RespawnBlock": {}
        }
      },
      "filler": 1024
    },
    {
      "x": -4,
      "y": 69,
      "z": 16,
      "name": "Wood_Redwood_Trunk",
      "rotation": 5
    },
    {
      "x": -4,
      "y": 70,
      "z": 16,
      "name": "Wood_Redwood_Planks"
    },
    {
      "x": -4,
      "y": 71,
      "z": 16,
      "name": "Wood_Deadwood_Roof",
      "rotation": 3
    },
    {
      "x": -4,
      "y": 58,
      "z": 17,
      "name": "Soil_Dirt_Cold"
    },
    {
      "x": -4,
      "y": 59,
      "z": 17,
      "name": "Soil_Dirt_Cold"
    },
    {
      "x": -4,
      "y": 60,
      "z": 17,
      "name": "Soil_Dirt_Cold"
    },
    {
      "x": -4,
      "y": 61,
      "z": 17,
      "name": "Rock_Shale"
    },
    {
      "x": -4,
      "y": 62,
      "z": 17,
      "name": "Rock_Shale"
    },
    {
      "x": -4,
      "y": 63,
      "z": 17,
      "name": "Rock_Shale"
    },
    {
      "x": -4,
      "y": 64,
      "z": 17,
      "name": "Rock_Shale"
    },
    {
      "x": -4,
      "y": 65,
      "z": 17,
      "name": "Rock_Shale_Brick"
    },
    {
      "x": -4,
      "y": 66,
      "z": 17,
      "name": "Wood_Redwood_Planks"
    },
    {
      "x": -4,
      "y": 67,
      "z": 17,
      "name": "Furniture_Lumberjack_Bed",
      "components": {
        "Components": {
          "RespawnBlock": {}
        }
      },
      "filler": 32
    },
    {
      "x": -4,
      "y": 68,
      "z": 17,
      "name": "Furniture_Lumberjack_Bed",
      "components": {
        "Components": {
          "RespawnBlock": {}
        }
      },
      "filler": 1056
    },
    {
      "x": -4,
      "y": 69,
      "z": 17,
      "name": "Furniture_Lumberjack_Platform"
    },
    {
      "x": -4,
      "y": 70,
      "z": 17,
      "name": "Wood_Redwood_Planks"
    },
    {
      "x": -4,
      "y": 71,
      "z": 17,
      "name": "Wood_Deadwood_Roof",
      "rotation": 3
    },
    {
      "x": -4,
      "y": 58,
      "z": 18,
      "name": "Soil_Dirt_Cold"
    },
    {
      "x": -4,
      "y": 59,
      "z": 18,
      "name": "Soil_Dirt_Cold"
    },
    {
      "x": -4,
      "y": 60,
      "z": 18,
      "name": "Soil_Dirt_Cold"
    },
    {
      "x": -4,
      "y": 61,
      "z": 18,
      "name": "Rock_Shale"
    },
    {
      "x": -4,
      "y": 62,
      "z": 18,
      "name": "Rock_Shale"
    },
    {
      "x": -4,
      "y": 63,
      "z": 18,
      "name": "Rock_Shale"
    },
    {
      "x": -4,
      "y": 64,
      "z": 18,
      "name": "Rock_Shale_Brick"
    },
    {
      "x": -4,
      "y": 65,
      "z": 18,
      "name": "Rock_Shale_Brick"
    },
    {
      "x": -4,
      "y": 66,
      "z": 18,
      "name": "Wood_Redwood_Planks"
    },
    {
      "x": -4,
      "y": 67,
      "z": 18,
      "name": "Furniture_Lumberjack_Bed",
      "components": {
        "Components": {
          "RespawnBlock": {}
        }
      },
      "filler": 64
    },
    {
      "x": -4,
      "y": 68,
      "z": 18,
      "name": "Furniture_Lumberjack_Bed",
      "components": {
        "Components": {
          "RespawnBlock": {}
        }
      },
      "filler": 1088
    },
    {
      "x": -4,
      "y": 69,
      "z": 18,
      "name": "Furniture_Lumberjack_Platform"
    },
    {
      "x": -4,
      "y": 70,
      "z": 18,
      "name": "Wood_Redwood_Planks"
    },
    {
      "x": -4,
      "y": 71,
      "z": 18,
      "name": "Wood_Deadwood_Roof",
      "rotation": 3
    },
    {
      "x": -4,
      "y": 58,
      "z": 19,
      "name": "Soil_Dirt_Cold"
    },
    {
      "x": -4,
      "y": 59,
      "z": 19,
      "name": "Soil_Dirt_Cold"
    },
    {
      "x": -4,
      "y": 60,
      "z": 19,
      "name": "Soil_Dirt_Cold"
    },
    {
      "x": -4,
      "y": 61,
      "z": 19,
      "name": "Rock_Shale_Brick"
    },
    {
      "x": -4,
      "y": 62,
      "z": 19,
      "name": "Rock_Shale_Brick"
    },
    {
      "x": -4,
      "y": 63,
      "z": 19,
      "name": "Rock_Shale_Brick"
    },
    {
      "x": -4,
      "y": 64,
      "z": 19,
      "name": "Rock_Shale_Brick"
    },
    {
      "x": -4,
      "y": 65,
      "z": 19,
      "name": "Rock_Shale_Brick"
    },
    {
      "x": -4,
      "y": 66,
      "z": 19,
      "name": "Wood_Redwood_Planks"
    },
    {
      "x": -4,
      "y": 67,
      "z": 19,
      "name": "Empty"
    },
    {
      "x": -4,
      "y": 68,
      "z": 19,
      "name": "Empty"
    },
    {
      "x": -4,
      "y": 69,
      "z": 19,
      "name": "Empty"
    },
    {
      "x": -4,
      "y": 70,
      "z": 19,
      "name": "Wood_Redwood_Planks"
    },
    {
      "x": -4,
      "y": 71,
      "z": 19,
      "name": "Wood_Deadwood_Roof",
      "rotation": 3
    },
    {
      "x": -4,
      "y": 58,
      "z": 20,
      "name": "Soil_Dirt_Cold"
    },
    {
      "x": -4,
      "y": 59,
      "z": 20,
      "name": "Soil_Dirt_Cold"
    },
    {
      "x": -4,
      "y": 60,
      "z": 20,
      "name": "Soil_Dirt_Cold"
    },
    {
      "x": -4,
      "y": 61,
      "z": 20,
      "name": "Rock_Shale_Brick"
    },
    {
      "x": -4,
      "y": 62,
      "z": 20,
      "name": "Rock_Shale_Brick"
    },
    {
      "x": -4,
      "y": 63,
      "z": 20,
      "name": "Rock_Shale_Brick"
    },
    {
      "x": -4,
      "y": 64,
      "z": 20,
      "name": "Rock_Shale_Brick"
    },
    {
      "x": -4,
      "y": 65,
      "z": 20,
      "name": "Rock_Shale_Brick"
    },
    {
      "x": -4,
      "y": 66,
      "z": 20,
      "name": "Wood_Redwood_Trunk",
      "rotation": 5
    },
    {
      "x": -4,
      "y": 67,
      "z": 20,
      "name": "Empty"
    },
    {
      "x": -4,
      "y": 68,
      "z": 20,
      "name": "Empty"
    },
    {
      "x": -4,
      "y": 69,
      "z": 20,
      "name": "Empty"
    },
    {
      "x": -4,
      "y": 70,
      "z": 20,
      "name": "Wood_Redwood_Planks"
    },
    {
      "x": -4,
      "y": 71,
      "z": 20,
      "name": "Wood_Deadwood_Roof",
      "rotation": 3
    },
    {
      "x": -4,
      "y": 58,
      "z": 21,
      "name": "Soil_Dirt_Cold"
    },
    {
      "x": -4,
      "y": 59,
      "z": 21,
      "name": "Soil_Dirt_Cold"
    },
    {
      "x": -4,
      "y": 60,
      "z": 21,
      "name": "Soil_Dirt_Cold"
    },
    {
      "x": -4,
      "y": 61,
      "z": 21,
      "name": "Rock_Shale_Brick"
    },
    {
      "x": -4,
      "y": 62,
      "z": 21,
      "name": "Rock_Shale_Brick"
    },
    {
      "x": -4,
      "y": 63,
      "z": 21,
      "name": "Rock_Shale_Brick"
    },
    {
      "x": -4,
      "y": 64,
      "z": 21,
      "name": "Rock_Shale_Brick"
    },
    {
      "x": -4,
      "y": 65,
      "z": 21,
      "name": "Rock_Shale_Brick"
    },
    {
      "x": -4,
      "y": 66,
      "z": 21,
      "name": "Wood_Redwood_Planks"
    },
    {
      "x": -4,
      "y": 67,
      "z": 21,
      "name": "Empty"
    },
    {
      "x": -4,
      "y": 68,
      "z": 21,
      "name": "Empty"
    },
    {
      "x": -4,
      "y": 69,
      "z": 21,
      "name": "Empty"
    },
    {
      "x": -4,
      "y": 70,
      "z": 21,
      "name": "Wood_Redwood_Planks"
    },
    {
      "x": -4,
      "y": 71,
      "z": 21,
      "name": "Wood_Deadwood_Roof",
      "rotation": 3
    },
    {
      "x": -4,
      "y": 58,
      "z": 22,
      "name": "Soil_Dirt_Cold"
    },
    {
      "x": -4,
      "y": 59,
      "z": 22,
      "name": "Soil_Dirt_Cold"
    },
    {
      "x": -4,
      "y": 60,
      "z": 22,
      "name": "Soil_Dirt_Cold"
    },
    {
      "x": -4,
      "y": 61,
      "z": 22,
      "name": "Rock_Shale"
    },
    {
      "x": -4,
      "y": 62,
      "z": 22,
      "name": "Rock_Shale"
    },
    {
      "x": -4,
      "y": 63,
      "z": 22,
      "name": "Rock_Shale_Brick"
    },
    {
      "x": -4,
      "y": 64,
      "z": 22,
      "name": "Rock_Shale_Brick"
    },
    {
      "x": -4,
      "y": 65,
      "z": 22,
      "name": "Rock_Shale_Brick"
    },
    {
      "x": -4,
      "y": 66,
      "z": 22,
      "name": "Wood_Redwood_Planks"
    },
    {
      "x": -4,
      "y": 67,
      "z": 22,
      "name": "Empty"
    },
    {
      "x": -4,
      "y": 68,
      "z": 22,
      "name": "Empty"
    },
    {
      "x": -4,
      "y": 69,
      "z": 22,
      "name": "Empty"
    },
    {
      "x": -4,
      "y": 70,
      "z": 22,
      "name": "Wood_Redwood_Planks"
    },
    {
      "x": -4,
      "y": 71,
      "z": 22,
      "name": "Wood_Deadwood_Roof",
      "rotation": 3
    },
    {
      "x": -4,
      "y": 58,
      "z": 23,
      "name": "Soil_Dirt_Cold"
    },
    {
      "x": -4,
      "y": 59,
      "z": 23,
      "name": "Soil_Dirt_Cold"
    },
    {
      "x": -4,
      "y": 60,
      "z": 23,
      "name": "Soil_Dirt_Cold"
    },
    {
      "x": -4,
      "y": 61,
      "z": 23,
      "name": "Soil_Dirt_Cold"
    },
    {
      "x": -4,
      "y": 62,
      "z": 23,
      "name": "Furniture_Lumberjack_Door",
      "rotation": 3
    },
    {
      "x": -4,
      "y": 63,
      "z": 23,
      "name": "Furniture_Lumberjack_Door",
      "filler": 1024,
      "rotation": 3
    },
    {
      "x": -4,
      "y": 64,
      "z": 23,
      "name": "Rock_Shale_Brick"
    },
    {
      "x": -4,
      "y": 65,
      "z": 23,
      "name": "Rock_Shale_Brick"
    },
    {
      "x": -4,
      "y": 66,
      "z": 23,
      "name": "Wood_Redwood_Planks"
    },
    {
      "x": -4,
      "y": 67,
      "z": 23,
      "name": "Empty"
    },
    {
      "x": -4,
      "y": 68,
      "z": 23,
      "name": "Empty"
    },
    {
      "x": -4,
      "y": 69,
      "z": 23,
      "name": "Empty"
    },
    {
      "x": -4,
      "y": 70,
      "z": 23,
      "name": "Wood_Redwood_Planks"
    },
    {
      "x": -4,
      "y": 71,
      "z": 23,
      "name": "Wood_Deadwood_Roof",
      "rotation": 3
    },
    {
      "x": -4,
      "y": 58,
      "z": 24,
      "name": "Soil_Dirt_Cold"
    },
    {
      "x": -4,
      "y": 59,
      "z": 24,
      "name": "Soil_Dirt_Cold"
    },
    {
      "x": -4,
      "y": 60,
      "z": 24,
      "name": "Soil_Dirt_Cold"
    },
    {
      "x": -4,
      "y": 61,
      "z": 24,
      "name": "Rock_Shale"
    },
    {
      "x": -4,
      "y": 62,
      "z": 24,
      "name": "Rock_Shale"
    },
    {
      "x": -4,
      "y": 63,
      "z": 24,
      "name": "Rock_Shale"
    },
    {
      "x": -4,
      "y": 64,
      "z": 24,
      "name": "Rock_Shale_Brick"
    },
    {
      "x": -4,
      "y": 65,
      "z": 24,
      "name": "Rock_Shale_Brick"
    },
    {
      "x": -4,
      "y": 66,
      "z": 24,
      "name": "Wood_Redwood_Planks"
    },
    {
      "x": -4,
      "y": 67,
      "z": 24,
      "name": "Empty"
    },
    {
      "x": -4,
      "y": 68,
      "z": 24,
      "name": "Empty"
    },
    {
      "x": -4,
      "y": 69,
      "z": 24,
      "name": "Empty"
    },
    {
      "x": -4,
      "y": 70,
      "z": 24,
      "name": "Wood_Redwood_Planks"
    },
    {
      "x": -4,
      "y": 71,
      "z": 24,
      "name": "Wood_Deadwood_Roof",
      "rotation": 3
    },
    {
      "x": -4,
      "y": 58,
      "z": 25,
      "name": "Soil_Dirt_Cold"
    },
    {
      "x": -4,
      "y": 59,
      "z": 25,
      "name": "Soil_Dirt_Cold"
    },
    {
      "x": -4,
      "y": 60,
      "z": 25,
      "name": "Soil_Dirt_Cold"
    },
    {
      "x": -4,
      "y": 61,
      "z": 25,
      "name": "Rock_Shale_Brick"
    },
    {
      "x": -4,
      "y": 62,
      "z": 25,
      "name": "Rock_Shale_Brick"
    },
    {
      "x": -4,
      "y": 63,
      "z": 25,
      "name": "Rock_Shale_Brick"
    },
    {
      "x": -4,
      "y": 64,
      "z": 25,
      "name": "Rock_Shale_Brick"
    },
    {
      "x": -4,
      "y": 65,
      "z": 25,
      "name": "Rock_Shale_Brick"
    },
    {
      "x": -4,
      "y": 66,
      "z": 25,
      "name": "Wood_Redwood_Planks"
    },
    {
      "x": -4,
      "y": 67,
      "z": 25,
      "name": "Empty"
    },
    {
      "x": -4,
      "y": 68,
      "z": 25,
      "name": "Empty"
    },
    {
      "x": -4,
      "y": 69,
      "z": 25,
      "name": "Empty"
    },
    {
      "x": -4,
      "y": 70,
      "z": 25,
      "name": "Wood_Redwood_Planks"
    },
    {
      "x": -4,
      "y": 71,
      "z": 25,
      "name": "Wood_Deadwood_Roof",
      "rotation": 3
    },
    {
      "x": -4,
      "y": 59,
      "z": 26,
      "name": "Soil_Dirt_Cold"
    },
    {
      "x": -4,
      "y": 60,
      "z": 26,
      "name": "Soil_Dirt_Cold"
    },
    {
      "x": -4,
      "y": 61,
      "z": 26,
      "name": "Rock_Shale"
    },
    {
      "x": -4,
      "y": 62,
      "z": 26,
      "name": "Rock_Shale"
    },
    {
      "x": -4,
      "y": 63,
      "z": 26,
      "name": "Rock_Shale"
    },
    {
      "x": -4,
      "y": 64,
      "z": 26,
      "name": "Rock_Shale"
    },
    {
      "x": -4,
      "y": 65,
      "z": 26,
      "name": "Rock_Shale"
    },
    {
      "x": -4,
      "y": 66,
      "z": 26,
      "name": "Wood_Redwood_Trunk",
      "rotation": 5
    },
    {
      "x": -4,
      "y": 67,
      "z": 26,
      "name": "Wood_Redwood_Planks"
    },
    {
      "x": -4,
      "y": 68,
      "z": 26,
      "name": "Wood_Redwood_Planks"
    },
    {
      "x": -4,
      "y": 69,
      "z": 26,
      "name": "Wood_Redwood_Trunk",
      "rotation": 5
    },
    {
      "x": -4,
      "y": 70,
      "z": 26,
      "name": "Wood_Redwood_Planks"
    },
    {
      "x": -4,
      "y": 71,
      "z": 26,
      "name": "Wood_Deadwood_Roof",
      "rotation": 3
    },
    {
      "x": -4,
      "y": 69,
      "z": 27,
      "name": "Wood_Redwood_Stairs",
      "rotation": 11
    },
    {
      "x": -4,
      "y": 70,
      "z": 27,
      "name": "Wood_Redwood_Stairs",
      "rotation": 3
    },
    {
      "x": -4,
      "y": 71,
      "z": 27,
      "name": "Wood_Deadwood_Roof",
      "rotation": 3
    },
    {
      "x": -3,
      "y": 59,
      "z": 14,
      "name": "Soil_Dirt_Cold"
    },
    {
      "x": -3,
      "y": 60,
      "z": 14,
      "name": "Soil_Dirt_Cold"
    },
    {
      "x": -3,
      "y": 61,
      "z": 14,
      "name": "Soil_Dirt_Cold"
    },
    {
      "x": -3,
      "y": 62,
      "z": 14,
      "name": "Empty"
    },
    {
      "x": -3,
      "y": 63,
      "z": 14,
      "name": "Empty"
    },
    {
      "x": -3,
      "y": 64,
      "z": 14,
      "name": "Empty"
    },
    {
      "x": -3,
      "y": 65,
      "z": 14,
      "name": "Empty"
    },
    {
      "x": -3,
      "y": 70,
      "z": 14,
      "name": "Wood_Redwood_Stairs",
      "rotation": 11
    },
    {
      "x": -3,
      "y": 71,
      "z": 14,
      "name": "Wood_Redwood_Stairs",
      "rotation": 3
    },
    {
      "x": -3,
      "y": 59,
      "z": 15,
      "name": "Soil_Dirt_Cold"
    },
    {
      "x": -3,
      "y": 60,
      "z": 15,
      "name": "Soil_Dirt_Cold"
    },
    {
      "x": -3,
      "y": 61,
      "z": 15,
      "name": "Soil_Dirt_Cold"
    },
    {
      "x": -3,
      "y": 62,
      "z": 15,
      "name": "Empty"
    },
    {
      "x": -3,
      "y": 63,
      "z": 15,
      "name": "Empty"
    },
    {
      "x": -3,
      "y": 64,
      "z": 15,
      "name": "Empty"
    },
    {
      "x": -3,
      "y": 65,
      "z": 15,
      "name": "Empty"
    },
    {
      "x": -3,
      "y": 66,
      "z": 15,
      "name": "Wood_Redwood_Trunk",
      "rotation": 5
    },
    {
      "x": -3,
      "y": 67,
      "z": 15,
      "name": "Wood_Redwood_Trunk",
      "rotation": 5
    },
    {
      "x": -3,
      "y": 68,
      "z": 15,
      "name": "Furniture_Lumberjack_Window"
    },
    {
      "x": -3,
      "y": 69,
      "z": 15,
      "name": "Wood_Redwood_Planks"
    },
    {
      "x": -3,
      "y": 70,
      "z": 15,
      "name": "Wood_Redwood_Planks"
    },
    {
      "x": -3,
      "y": 71,
      "z": 15,
      "name": "Wood_Redwood_Planks"
    },
    {
      "x": -3,
      "y": 72,
      "z": 15,
      "name": "Wood_Deadwood_Roof",
      "rotation": 3
    },
    {
      "x": -3,
      "y": 58,
      "z": 16,
      "name": "Soil_Dirt_Cold"
    },
    {
      "x": -3,
      "y": 59,
      "z": 16,
      "name": "Soil_Dirt_Cold"
    },
    {
      "x": -3,
      "y": 60,
      "z": 16,
      "name": "Soil_Dirt_Cold"
    },
    {
      "x": -3,
      "y": 61,
      "z": 16,
      "name": "Rock_Shale"
    },
    {
      "x": -3,
      "y": 62,
      "z": 16,
      "name": "Rock_Shale"
    },
    {
      "x": -3,
      "y": 63,
      "z": 16,
      "name": "Furniture_Lumberjack_Window"
    },
    {
      "x": -3,
      "y": 64,
      "z": 16,
      "name": "Rock_Shale_Brick"
    },
    {
      "x": -3,
      "y": 65,
      "z": 16,
      "name": "Rock_Shale_Brick"
    },
    {
      "x": -3,
      "y": 66,
      "z": 16,
      "name": "Wood_Redwood_Planks"
    },
    {
      "x": -3,
      "y": 67,
      "z": 16,
      "name": "Furniture_Lumberjack_Bed",
      "components": {
        "Components": {
          "RespawnBlock": {}
        }
      },
      "filler": 1
    },
    {
      "x": -3,
      "y": 68,
      "z": 16,
      "name": "Furniture_Lumberjack_Bed",
      "components": {
        "Components": {
          "RespawnBlock": {}
        }
      },
      "filler": 1025
    },
    {
      "x": -3,
      "y": 69,
      "z": 16,
      "name": "Wood_Redwood_Trunk",
      "rotation": 5
    },
    {
      "x": -3,
      "y": 70,
      "z": 16,
      "name": "Furniture_Village_Crate"
    },
    {
      "x": -3,
      "y": 71,
      "z": 16,
      "name": "Wood_Redwood_Planks"
    },
    {
      "x": -3,
      "y": 72,
      "z": 16,
      "name": "Wood_Deadwood_Roof",
      "rotation": 3
    },
    {
      "x": -3,
      "y": 58,
      "z": 17,
      "name": "Soil_Dirt_Cold"
    },
    {
      "x": -3,
      "y": 59,
      "z": 17,
      "name": "Soil_Dirt_Cold"
    },
    {
      "x": -3,
      "y": 60,
      "z": 17,
      "name": "Soil_Dirt_Cold"
    },
    {
      "x": -3,
      "y": 61,
      "z": 17,
      "name": "Soil_Dirt_Cold"
    },
    {
      "x": -3,
      "y": 62,
      "z": 17,
      "name": "Furniture_Ancient_Barrel"
    },
    {
      "x": -3,
      "y": 63,
      "z": 17,
      "name": "Furniture_Crude_Candle"
    },
    {
      "x": -3,
      "y": 64,
      "z": 17,
      "name": "Furniture_Lumberjack_Platform",
      "rotation": 1
    },
    {
      "x": -3,
      "y": 65,
      "z": 17,
      "name": "Empty"
    },
    {
      "x": -3,
      "y": 66,
      "z": 17,
      "name": "Wood_Redwood_Planks"
    },
    {
      "x": -3,
      "y": 67,
      "z": 17,
      "name": "Furniture_Lumberjack_Bed",
      "components": {
        "Components": {
          "RespawnBlock": {}
        }
      },
      "filler": 33
    },
    {
      "x": -3,
      "y": 68,
      "z": 17,
      "name": "Furniture_Lumberjack_Bed",
      "components": {
        "Components": {
          "RespawnBlock": {}
        }
      },
      "filler": 1057
    },
    {
      "x": -3,
      "y": 69,
      "z": 17,
      "name": "Furniture_Lumberjack_Platform"
    },
    {
      "x": -3,
      "y": 70,
      "z": 17,
      "name": "Furniture_Village_Crate"
    },
    {
      "x": -3,
      "y": 71,
      "z": 17,
      "name": "Wood_Redwood_Planks"
    },
    {
      "x": -3,
      "y": 72,
      "z": 17,
      "name": "Wood_Deadwood_Roof",
      "rotation": 3
    },
    {
      "x": -3,
      "y": 58,
      "z": 18,
      "name": "Soil_Dirt_Cold"
    },
    {
      "x": -3,
      "y": 59,
      "z": 18,
      "name": "Soil_Dirt_Cold"
    },
    {
      "x": -3,
      "y": 60,
      "z": 18,
      "name": "Soil_Dirt_Cold"
    },
    {
      "x": -3,
      "y": 61,
      "z": 18,
      "name": "Soil_Dirt_Cold"
    },
    {
      "x": -3,
      "y": 62,
      "z": 18,
      "name": "Furniture_Lumberjack_Shelf",
      "rotation": 1
    },
    {
      "x": -3,
      "y": 63,
      "z": 18,
      "name": "Empty"
    },
    {
      "x": -3,
      "y": 64,
      "z": 18,
      "name": "Furniture_Lumberjack_Platform",
      "rotation": 1
    },
    {
      "x": -3,
      "y": 65,
      "z": 18,
      "name": "Empty"
    },
    {
      "x": -3,
      "y": 66,
      "z": 18,
      "name": "Wood_Redwood_Planks"
    },
    {
      "x": -3,
      "y": 67,
      "z": 18,
      "name": "Furniture_Lumberjack_Bed",
      "components": {
        "Components": {
          "RespawnBlock": {}
        }
      },
      "filler": 65
    },
    {
      "x": -3,
      "y": 68,
      "z": 18,
      "name": "Furniture_Lumberjack_Bed",
      "components": {
        "Components": {
          "RespawnBlock": {}
        }
      },
      "filler": 1089
    },
    {
      "x": -3,
      "y": 69,
      "z": 18,
      "name": "Furniture_Lumberjack_Platform"
    },
    {
      "x": -3,
      "y": 70,
      "z": 18,
      "name": "Empty"
    },
    {
      "x": -3,
      "y": 71,
      "z": 18,
      "name": "Wood_Redwood_Planks"
    },
    {
      "x": -3,
      "y": 72,
      "z": 18,
      "name": "Wood_Deadwood_Roof",
      "rotation": 3
    },
    {
      "x": -3,
      "y": 58,
      "z": 19,
      "name": "Soil_Dirt_Cold"
    },
    {
      "x": -3,
      "y": 59,
      "z": 19,
      "name": "Soil_Dirt_Cold"
    },
    {
      "x": -3,
      "y": 60,
      "z": 19,
      "name": "Soil_Dirt_Cold"
    },
    {
      "x": -3,
      "y": 61,
      "z": 19,
      "name": "Soil_Dirt_Cold"
    },
    {
      "x": -3,
      "y": 62,
      "z": 19,
      "name": "Furniture_Lumberjack_Shelf",
      "rotation": 1
    },
    {
      "x": -3,
      "y": 63,
      "z": 19,
      "name": "Empty"
    },
    {
      "x": -3,
      "y": 64,
      "z": 19,
      "name": "Furniture_Lumberjack_Platform",
      "rotation": 1
    },
    {
      "x": -3,
      "y": 65,
      "z": 19,
      "name": "Empty"
    },
    {
      "x": -3,
      "y": 66,
      "z": 19,
      "name": "Wood_Redwood_Planks"
    },
    {
      "x": -3,
      "y": 67,
      "z": 19,
      "name": "Empty"
    },
    {
      "x": -3,
      "y": 68,
      "z": 19,
      "name": "Empty"
    },
    {
      "x": -3,
      "y": 69,
      "z": 19,
      "name": "Empty"
    },
    {
      "x": -3,
      "y": 70,
      "z": 19,
      "name": "Empty"
    },
    {
      "x": -3,
      "y": 71,
      "z": 19,
      "name": "Wood_Redwood_Planks"
    },
    {
      "x": -3,
      "y": 72,
      "z": 19,
      "name": "Wood_Deadwood_Roof",
      "rotation": 3
    },
    {
      "x": -3,
      "y": 58,
      "z": 20,
      "name": "Soil_Dirt_Cold"
    },
    {
      "x": -3,
      "y": 59,
      "z": 20,
      "name": "Soil_Dirt_Cold"
    },
    {
      "x": -3,
      "y": 60,
      "z": 20,
      "name": "Soil_Dirt_Cold"
    },
    {
      "x": -3,
      "y": 61,
      "z": 20,
      "name": "Soil_Dirt_Cold"
    },
    {
      "x": -3,
      "y": 62,
      "z": 20,
      "name": "Furniture_Lumberjack_Shelf",
      "rotation": 1
    },
    {
      "x": -3,
      "y": 63,
      "z": 20,
      "name": "Furniture_Lumberjack_Shelf",
      "rotation": 1
    },
    {
      "x": -3,
      "y": 64,
      "z": 20,
      "name": "Empty"
    },
    {
      "x": -3,
      "y": 65,
      "z": 20,
      "name": "Empty"
    },
    {
      "x": -3,
      "y": 66,
      "z": 20,
      "name": "Wood_Redwood_Trunk",
      "rotation": 5
    },
    {
      "x": -3,
      "y": 67,
      "z": 20,
      "name": "Empty"
    },
    {
      "x": -3,
      "y": 68,
      "z": 20,
      "name": "Empty"
    },
    {
      "x": -3,
      "y": 69,
      "z": 20,
      "name": "Empty"
    },
    {
      "x": -3,
      "y": 70,
      "z": 20,
      "name": "Empty"
    },
    {
      "x": -3,
      "y": 71,
      "z": 20,
      "name": "Wood_Redwood_Planks"
    },
    {
      "x": -3,
      "y": 72,
      "z": 20,
      "name": "Wood_Deadwood_Roof",
      "rotation": 3
    },
    {
      "x": -3,
      "y": 58,
      "z": 21,
      "name": "Soil_Dirt_Cold"
    },
    {
      "x": -3,
      "y": 59,
      "z": 21,
      "name": "Soil_Dirt_Cold"
    },
    {
      "x": -3,
      "y": 60,
      "z": 21,
      "name": "Soil_Dirt_Cold"
    },
    {
      "x": -3,
      "y": 61,
      "z": 21,
      "name": "Soil_Dirt_Cold"
    },
    {
      "x": -3,
      "y": 62,
      "z": 21,
      "name": "Wood_Redwood_Trunk"
    },
    {
      "x": -3,
      "y": 63,
      "z": 21,
      "name": "Wood_Redwood_Trunk"
    },
    {
      "x": -3,
      "y": 64,
      "z": 21,
      "name": "Wood_Redwood_Trunk"
    },
    {
      "x": -3,
      "y": 65,
      "z": 21,
      "name": "Wood_Redwood_Trunk"
    },
    {
      "x": -3,
      "y": 66,
      "z": 21,
      "name": "Wood_Redwood_Planks"
    },
    {
      "x": -3,
      "y": 67,
      "z": 21,
      "name": "Empty"
    },
    {
      "x": -3,
      "y": 68,
      "z": 21,
      "name": "Empty"
    },
    {
      "x": -3,
      "y": 69,
      "z": 21,
      "name": "Empty"
    },
    {
      "x": -3,
      "y": 70,
      "z": 21,
      "name": "Empty"
    },
    {
      "x": -3,
      "y": 71,
      "z": 21,
      "name": "Wood_Redwood_Planks"
    },
    {
      "x": -3,
      "y": 72,
      "z": 21,
      "name": "Wood_Deadwood_Roof",
      "rotation": 3
    },
    {
      "x": -3,
      "y": 58,
      "z": 22,
      "name": "Soil_Dirt_Cold"
    },
    {
      "x": -3,
      "y": 59,
      "z": 22,
      "name": "Soil_Dirt_Cold"
    },
    {
      "x": -3,
      "y": 60,
      "z": 22,
      "name": "Soil_Dirt_Cold"
    },
    {
      "x": -3,
      "y": 61,
      "z": 22,
      "name": "Soil_Dirt_Cold"
    },
    {
      "x": -3,
      "y": 62,
      "z": 22,
      "name": "Empty"
    },
    {
      "x": -3,
      "y": 63,
      "z": 22,
      "name": "Empty"
    },
    {
      "x": -3,
      "y": 64,
      "z": 22,
      "name": "Empty"
    },
    {
      "x": -3,
      "y": 65,
      "z": 22,
      "name": "Empty"
    },
    {
      "x": -3,
      "y": 66,
      "z": 22,
      "name": "Wood_Redwood_Planks"
    },
    {
      "x": -3,
      "y": 67,
      "z": 22,
      "name": "Empty"
    },
    {
      "x": -3,
      "y": 68,
      "z": 22,
      "name": "Empty"
    },
    {
      "x": -3,
      "y": 69,
      "z": 22,
      "name": "Empty"
    },
    {
      "x": -3,
      "y": 70,
      "z": 22,
      "name": "Empty"
    },
    {
      "x": -3,
      "y": 71,
      "z": 22,
      "name": "Wood_Redwood_Planks"
    },
    {
      "x": -3,
      "y": 72,
      "z": 22,
      "name": "Wood_Deadwood_Roof",
      "rotation": 3
    },
    {
      "x": -3,
      "y": 58,
      "z": 23,
      "name": "Soil_Dirt_Cold"
    },
    {
      "x": -3,
      "y": 59,
      "z": 23,
      "name": "Soil_Dirt_Cold"
    },
    {
      "x": -3,
      "y": 60,
      "z": 23,
      "name": "Soil_Dirt_Cold"
    },
    {
      "x": -3,
      "y": 61,
      "z": 23,
      "name": "Soil_Dirt_Cold"
    },
    {
      "x": -3,
      "y": 62,
      "z": 23,
      "name": "Empty"
    },
    {
      "x": -3,
      "y": 63,
      "z": 23,
      "name": "Empty"
    },
    {
      "x": -3,
      "y": 64,
      "z": 23,
      "name": "Empty"
    },
    {
      "x": -3,
      "y": 65,
      "z": 23,
      "name": "Empty"
    },
    {
      "x": -3,
      "y": 66,
      "z": 23,
      "name": "Wood_Redwood_Planks"
    },
    {
      "x": -3,
      "y": 67,
      "z": 23,
      "name": "Empty"
    },
    {
      "x": -3,
      "y": 68,
      "z": 23,
      "name": "Empty"
    },
    {
      "x": -3,
      "y": 69,
      "z": 23,
      "name": "Empty"
    },
    {
      "x": -3,
      "y": 70,
      "z": 23,
      "name": "Empty"
    },
    {
      "x": -3,
      "y": 71,
      "z": 23,
      "name": "Wood_Redwood_Planks"
    },
    {
      "x": -3,
      "y": 72,
      "z": 23,
      "name": "Wood_Deadwood_Roof",
      "rotation": 3
    },
    {
      "x": -3,
      "y": 58,
      "z": 24,
      "name": "Soil_Dirt_Cold"
    },
    {
      "x": -3,
      "y": 59,
      "z": 24,
      "name": "Soil_Dirt_Cold"
    },
    {
      "x": -3,
      "y": 60,
      "z": 24,
      "name": "Soil_Dirt_Cold"
    },
    {
      "x": -3,
      "y": 61,
      "z": 24,
      "name": "Soil_Dirt_Cold"
    },
    {
      "x": -3,
      "y": 62,
      "z": 24,
      "name": "Empty"
    },
    {
      "x": -3,
      "y": 63,
      "z": 24,
      "name": "Empty"
    },
    {
      "x": -3,
      "y": 64,
      "z": 24,
      "name": "Empty"
    },
    {
      "x": -3,
      "y": 65,
      "z": 24,
      "name": "Empty"
    },
    {
      "x": -3,
      "y": 66,
      "z": 24,
      "name": "Wood_Redwood_Planks"
    },
    {
      "x": -3,
      "y": 67,
      "z": 24,
      "name": "Empty"
    },
    {
      "x": -3,
      "y": 68,
      "z": 24,
      "name": "Empty"
    },
    {
      "x": -3,
      "y": 69,
      "z": 24,
      "name": "Empty"
    },
    {
      "x": -3,
      "y": 70,
      "z": 24,
      "name": "Empty"
    },
    {
      "x": -3,
      "y": 71,
      "z": 24,
      "name": "Wood_Redwood_Planks"
    },
    {
      "x": -3,
      "y": 72,
      "z": 24,
      "name": "Wood_Deadwood_Roof",
      "rotation": 3
    },
    {
      "x": -3,
      "y": 58,
      "z": 25,
      "name": "Soil_Dirt_Cold"
    },
    {
      "x": -3,
      "y": 59,
      "z": 25,
      "name": "Soil_Dirt_Cold"
    },
    {
      "x": -3,
      "y": 60,
      "z": 25,
      "name": "Soil_Dirt_Cold"
    },
    {
      "x": -3,
      "y": 61,
      "z": 25,
      "name": "Soil_Dirt_Cold"
    },
    {
      "x": -3,
      "y": 62,
      "z": 25,
      "name": "Furniture_Lumberjack_Shelf",
      "rotation": 2
    },
    {
      "x": -3,
      "y": 63,
      "z": 25,
      "name": "Empty"
    },
    {
      "x": -3,
      "y": 64,
      "z": 25,
      "name": "Furniture_Lumberjack_Platform"
    },
    {
      "x": -3,
      "y": 65,
      "z": 25,
      "name": "Deco_Mug"
    },
    {
      "x": -3,
      "y": 66,
      "z": 25,
      "name": "Wood_Redwood_Planks"
    },
    {
      "x": -3,
      "y": 67,
      "z": 25,
      "name": "Empty"
    },
    {
      "x": -3,
      "y": 68,
      "z": 25,
      "name": "Empty"
    },
    {
      "x": -3,
      "y": 69,
      "z": 25,
      "name": "Empty"
    },
    {
      "x": -3,
      "y": 70,
      "z": 25,
      "name": "Empty"
    },
    {
      "x": -3,
      "y": 71,
      "z": 25,
      "name": "Wood_Redwood_Planks"
    },
    {
      "x": -3,
      "y": 72,
      "z": 25,
      "name": "Wood_Deadwood_Roof",
      "rotation": 3
    },
    {
      "x": -3,
      "y": 59,
      "z": 26,
      "name": "Soil_Dirt_Cold"
    },
    {
      "x": -3,
      "y": 60,
      "z": 26,
      "name": "Soil_Dirt_Cold"
    },
    {
      "x": -3,
      "y": 61,
      "z": 26,
      "name": "Rock_Shale"
    },
    {
      "x": -3,
      "y": 62,
      "z": 26,
      "name": "Rock_Shale"
    },
    {
      "x": -3,
      "y": 63,
      "z": 26,
      "name": "Rock_Shale"
    },
    {
      "x": -3,
      "y": 64,
      "z": 26,
      "name": "Rock_Shale_Brick"
    },
    {
      "x": -3,
      "y": 65,
      "z": 26,
      "name": "Rock_Shale_Brick"
    },
    {
      "x": -3,
      "y": 66,
      "z": 26,
      "name": "Wood_Redwood_Trunk",
      "rotation": 5
    },
    {
      "x": -3,
      "y": 67,
      "z": 26,
      "name": "Wood_Redwood_Trunk",
      "rotation": 5
    },
    {
      "x": -3,
      "y": 68,
      "z": 26,
      "name": "Wood_Redwood_Planks"
    },
    {
      "x": -3,
      "y": 69,
      "z": 26,
      "name": "Wood_Redwood_Trunk",
      "rotation": 5
    },
    {
      "x": -3,
      "y": 70,
      "z": 26,
      "name": "Wood_Redwood_Planks"
    },
    {
      "x": -3,
      "y": 71,
      "z": 26,
      "name": "Wood_Redwood_Planks"
    },
    {
      "x": -3,
      "y": 72,
      "z": 26,
      "name": "Wood_Deadwood_Roof",
      "rotation": 3
    },
    {
      "x": -3,
      "y": 70,
      "z": 27,
      "name": "Wood_Redwood_Stairs",
      "rotation": 11
    },
    {
      "x": -3,
      "y": 71,
      "z": 27,
      "name": "Wood_Redwood_Planks"
    },
    {
      "x": -3,
      "y": 72,
      "z": 27,
      "name": "Wood_Deadwood_Roof",
      "rotation": 3
    },
    {
      "x": -2,
      "y": 71,
      "z": 13,
      "name": "Wood_Redwood_Stairs",
      "rotation": 8
    },
    {
      "x": -2,
      "y": 72,
      "z": 13,
      "name": "Wood_Redwood_Trunk",
      "rotation": 4
    },
    {
      "x": -2,
      "y": 59,
      "z": 14,
      "name": "Soil_Dirt_Cold"
    },
    {
      "x": -2,
      "y": 60,
      "z": 14,
      "name": "Soil_Dirt_Cold"
    },
    {
      "x": -2,
      "y": 61,
      "z": 14,
      "name": "Soil_Dirt_Cold"
    },
    {
      "x": -2,
      "y": 62,
      "z": 14,
      "name": "Empty"
    },
    {
      "x": -2,
      "y": 63,
      "z": 14,
      "name": "Empty"
    },
    {
      "x": -2,
      "y": 64,
      "z": 14,
      "name": "Empty"
    },
    {
      "x": -2,
      "y": 65,
      "z": 14,
      "name": "Empty"
    },
    {
      "x": -2,
      "y": 71,
      "z": 14,
      "name": "Wood_Redwood_Planks"
    },
    {
      "x": -2,
      "y": 72,
      "z": 14,
      "name": "Wood_Redwood_Trunk",
      "rotation": 4
    },
    {
      "x": -2,
      "y": 59,
      "z": 15,
      "name": "Soil_Dirt_Cold"
    },
    {
      "x": -2,
      "y": 60,
      "z": 15,
      "name": "Soil_Dirt_Cold"
    },
    {
      "x": -2,
      "y": 61,
      "z": 15,
      "name": "Soil_Dirt_Cold"
    },
    {
      "x": -2,
      "y": 62,
      "z": 15,
      "name": "Empty"
    },
    {
      "x": -2,
      "y": 63,
      "z": 15,
      "name": "Wood_Torch_Wall",
      "rotation": 2
    },
    {
      "x": -2,
      "y": 64,
      "z": 15,
      "name": "Empty"
    },
    {
      "x": -2,
      "y": 65,
      "z": 15,
      "name": "Empty"
    },
    {
      "x": -2,
      "y": 66,
      "z": 15,
      "name": "Wood_Redwood_Trunk",
      "rotation": 5
    },
    {
      "x": -2,
      "y": 67,
      "z": 15,
      "name": "Wood_Redwood_Trunk",
      "rotation": 5
    },
    {
      "x": -2,
      "y": 68,
      "z": 15,
      "name": "Furniture_Lumberjack_Window"
    },
    {
      "x": -2,
      "y": 69,
      "z": 15,
      "name": "Wood_Redwood_Planks"
    },
    {
      "x": -2,
      "y": 70,
      "z": 15,
      "name": "Wood_Redwood_Planks"
    },
    {
      "x": -2,
      "y": 71,
      "z": 15,
      "name": "Wood_Redwood_Planks"
    },
    {
      "x": -2,
      "y": 72,
      "z": 15,
      "name": "Wood_Redwood_Trunk",
      "rotation": 4
    },
    {
      "x": -2,
      "y": 73,
      "z": 15,
      "name": "Wood_Deadwood_Roof_Flat",
      "rotation": 1
    },
    {
      "x": -2,
      "y": 58,
      "z": 16,
      "name": "Soil_Dirt_Cold"
    },
    {
      "x": -2,
      "y": 59,
      "z": 16,
      "name": "Soil_Dirt_Cold"
    },
    {
      "x": -2,
      "y": 60,
      "z": 16,
      "name": "Soil_Dirt_Cold"
    },
    {
      "x": -2,
      "y": 61,
      "z": 16,
      "name": "Rock_Shale_Brick"
    },
    {
      "x": -2,
      "y": 62,
      "z": 16,
      "name": "Rock_Shale_Brick"
    },
    {
      "x": -2,
      "y": 63,
      "z": 16,
      "name": "Rock_Shale_Brick"
    },
    {
      "x": -2,
      "y": 64,
      "z": 16,
      "name": "Rock_Shale_Brick"
    },
    {
      "x": -2,
      "y": 65,
      "z": 16,
      "name": "Rock_Shale_Brick"
    },
    {
      "x": -2,
      "y": 66,
      "z": 16,
      "name": "Wood_Redwood_Planks"
    },
    {
      "x": -2,
      "y": 67,
      "z": 16,
      "name": "Furniture_Lumberjack_Wardrobe",
      "filler": 31
    },
    {
      "x": -2,
      "y": 68,
      "z": 16,
      "name": "Furniture_Lumberjack_Wardrobe",
      "filler": 1055
    },
    {
      "x": -2,
      "y": 69,
      "z": 16,
      "name": "Wood_Redwood_Trunk",
      "rotation": 5
    },
    {
      "x": -2,
      "y": 70,
      "z": 16,
      "name": "Furniture_Village_Crate"
    },
    {
      "x": -2,
      "y": 71,
      "z": 16,
      "name": "Empty"
    },
    {
      "x": -2,
      "y": 72,
      "z": 16,
      "name": "Wood_Redwood_Trunk",
      "rotation": 4
    },
    {
      "x": -2,
      "y": 73,
      "z": 16,
      "name": "Wood_Deadwood_Roof_Flat",
      "rotation": 1
    },
    {
      "x": -2,
      "y": 58,
      "z": 17,
      "name": "Soil_Dirt_Cold"
    },
    {
      "x": -2,
      "y": 59,
      "z": 17,
      "name": "Soil_Dirt_Cold"
    },
    {
      "x": -2,
      "y": 60,
      "z": 17,
      "name": "Soil_Dirt_Cold"
    },
    {
      "x": -2,
      "y": 61,
      "z": 17,
      "name": "Soil_Dirt_Cold"
    },
    {
      "x": -2,
      "y": 62,
      "z": 17,
      "name": "Empty"
    },
    {
      "x": -2,
      "y": 63,
      "z": 17,
      "name": "Empty"
    },
    {
      "x": -2,
      "y": 64,
      "z": 17,
      "name": "Empty"
    },
    {
      "x": -2,
      "y": 65,
      "z": 17,
      "name": "Empty"
    },
    {
      "x": -2,
      "y": 66,
      "z": 17,
      "name": "Wood_Redwood_Planks"
    },
    {
      "x": -2,
      "y": 67,
      "z": 17,
      "name": "Empty"
    },
    {
      "x": -2,
      "y": 68,
      "z": 17,
      "name": "Empty"
    },
    {
      "x": -2,
      "y": 69,
      "z": 17,
      "name": "Furniture_Lumberjack_Platform"
    },
    {
      "x": -2,
      "y": 70,
      "z": 17,
      "name": "Empty"
    },
    {
      "x": -2,
      "y": 71,
      "z": 17,
      "name": "Empty"
    },
    {
      "x": -2,
      "y": 72,
      "z": 17,
      "name": "Wood_Redwood_Trunk",
      "rotation": 4
    },
    {
      "x": -2,
      "y": 73,
      "z": 17,
      "name": "Wood_Deadwood_Roof_Flat",
      "rotation": 1
    },
    {
      "x": -2,
      "y": 58,
      "z": 18,
      "name": "Soil_Dirt_Cold"
    },
    {
      "x": -2,
      "y": 59,
      "z": 18,
      "name": "Soil_Dirt_Cold"
    },
    {
      "x": -2,
      "y": 60,
      "z": 18,
      "name": "Soil_Dirt_Cold"
    },
    {
      "x": -2,
      "y": 61,
      "z": 18,
      "name": "Soil_Dirt_Cold"
    },
    {
      "x": -2,
      "y": 62,
      "z": 18,
      "name": "Empty"
    },
    {
      "x": -2,
      "y": 63,
      "z": 18,
      "name": "Empty"
    },
    {
      "x": -2,
      "y": 64,
      "z": 18,
      "name": "Empty"
    },
    {
      "x": -2,
      "y": 65,
      "z": 18,
      "name": "Empty"
    },
    {
      "x": -2,
      "y": 66,
      "z": 18,
      "name": "Wood_Redwood_Planks"
    },
    {
      "x": -2,
      "y": 67,
      "z": 18,
      "name": "Empty"
    },
    {
      "x": -2,
      "y": 68,
      "z": 18,
      "name": "Empty"
    },
    {
      "x": -2,
      "y": 69,
      "z": 18,
      "name": "Furniture_Lumberjack_Platform"
    },
    {
      "x": -2,
      "y": 70,
      "z": 18,
      "name": "Empty"
    },
    {
      "x": -2,
      "y": 71,
      "z": 18,
      "name": "Empty"
    },
    {
      "x": -2,
      "y": 72,
      "z": 18,
      "name": "Wood_Redwood_Trunk",
      "rotation": 4
    },
    {
      "x": -2,
      "y": 73,
      "z": 18,
      "name": "Wood_Deadwood_Roof_Flat",
      "rotation": 1
    },
    {
      "x": -2,
      "y": 58,
      "z": 19,
      "name": "Soil_Dirt_Cold"
    },
    {
      "x": -2,
      "y": 59,
      "z": 19,
      "name": "Soil_Dirt_Cold"
    },
    {
      "x": -2,
      "y": 60,
      "z": 19,
      "name": "Soil_Dirt_Cold"
    },
    {
      "x": -2,
      "y": 61,
      "z": 19,
      "name": "Soil_Dirt_Cold"
    },
    {
      "x": -2,
      "y": 62,
      "z": 19,
      "name": "Empty"
    },
    {
      "x": -2,
      "y": 63,
      "z": 19,
      "name": "Empty"
    },
    {
      "x": -2,
      "y": 64,
      "z": 19,
      "name": "Empty"
    },
    {
      "x": -2,
      "y": 65,
      "z": 19,
      "name": "Empty"
    },
    {
      "x": -2,
      "y": 66,
      "z": 19,
      "name": "Wood_Redwood_Planks"
    },
    {
      "x": -2,
      "y": 67,
      "z": 19,
      "name": "Empty"
    },
    {
      "x": -2,
      "y": 68,
      "z": 19,
      "name": "Empty"
    },
    {
      "x": -2,
      "y": 69,
      "z": 19,
      "name": "Empty"
    },
    {
      "x": -2,
      "y": 70,
      "z": 19,
      "name": "Empty"
    },
    {
      "x": -2,
      "y": 71,
      "z": 19,
      "name": "Empty"
    },
    {
      "x": -2,
      "y": 72,
      "z": 19,
      "name": "Wood_Redwood_Trunk",
      "rotation": 4
    },
    {
      "x": -2,
      "y": 73,
      "z": 19,
      "name": "Wood_Deadwood_Roof_Flat",
      "rotation": 1
    },
    {
      "x": -2,
      "y": 58,
      "z": 20,
      "name": "Soil_Dirt_Cold"
    },
    {
      "x": -2,
      "y": 59,
      "z": 20,
      "name": "Soil_Dirt_Cold"
    },
    {
      "x": -2,
      "y": 60,
      "z": 20,
      "name": "Soil_Dirt_Cold"
    },
    {
      "x": -2,
      "y": 61,
      "z": 20,
      "name": "Soil_Dirt_Cold"
    },
    {
      "x": -2,
      "y": 62,
      "z": 20,
      "name": "Empty"
    },
    {
      "x": -2,
      "y": 63,
      "z": 20,
      "name": "Empty"
    },
    {
      "x": -2,
      "y": 64,
      "z": 20,
      "name": "Empty"
    },
    {
      "x": -2,
      "y": 65,
      "z": 20,
      "name": "Empty"
    },
    {
      "x": -2,
      "y": 66,
      "z": 20,
      "name": "Wood_Redwood_Trunk",
      "rotation": 5
    },
    {
      "x": -2,
      "y": 67,
      "z": 20,
      "name": "Empty"
    },
    {
      "x": -2,
      "y": 68,
      "z": 20,
      "name": "Empty"
    },
    {
      "x": -2,
      "y": 69,
      "z": 20,
      "name": "Empty"
    },
    {
      "x": -2,
      "y": 70,
      "z": 20,
      "name": "Empty"
    },
    {
      "x": -2,
      "y": 71,
      "z": 20,
      "name": "Empty"
    },
    {
      "x": -2,
      "y": 72,
      "z": 20,
      "name": "Wood_Redwood_Trunk",
      "rotation": 4
    },
    {
      "x": -2,
      "y": 73,
      "z": 20,
      "name": "Wood_Deadwood_Roof_Flat",
      "rotation": 1
    },
    {
      "x": -2,
      "y": 58,
      "z": 21,
      "name": "Soil_Dirt_Cold"
    },
    {
      "x": -2,
      "y": 59,
      "z": 21,
      "name": "Soil_Dirt_Cold"
    },
    {
      "x": -2,
      "y": 60,
      "z": 21,
      "name": "Soil_Dirt_Cold"
    },
    {
      "x": -2,
      "y": 61,
      "z": 21,
      "name": "Soil_Dirt_Cold"
    },
    {
      "x": -2,
      "y": 62,
      "z": 21,
      "name": "Empty"
    },
    {
      "x": -2,
      "y": 63,
      "z": 21,
      "name": "Empty"
    },
    {
      "x": -2,
      "y": 64,
      "z": 21,
      "name": "Empty"
    },
    {
      "x": -2,
      "y": 65,
      "z": 21,
      "name": "Empty"
    },
    {
      "x": -2,
      "y": 66,
      "z": 21,
      "name": "Wood_Redwood_Planks"
    },
    {
      "x": -2,
      "y": 67,
      "z": 21,
      "name": "Empty"
    },
    {
      "x": -2,
      "y": 68,
      "z": 21,
      "name": "Empty"
    },
    {
      "x": -2,
      "y": 69,
      "z": 21,
      "name": "Empty"
    },
    {
      "x": -2,
      "y": 70,
      "z": 21,
      "name": "Empty"
    },
    {
      "x": -2,
      "y": 71,
      "z": 21,
      "name": "Empty"
    },
    {
      "x": -2,
      "y": 72,
      "z": 21,
      "name": "Wood_Redwood_Trunk",
      "rotation": 4
    },
    {
      "x": -2,
      "y": 73,
      "z": 21,
      "name": "Wood_Deadwood_Roof_Flat",
      "rotation": 1
    },
    {
      "x": -2,
      "y": 58,
      "z": 22,
      "name": "Soil_Dirt_Cold"
    },
    {
      "x": -2,
      "y": 59,
      "z": 22,
      "name": "Soil_Dirt_Cold"
    },
    {
      "x": -2,
      "y": 60,
      "z": 22,
      "name": "Soil_Dirt_Cold"
    },
    {
      "x": -2,
      "y": 61,
      "z": 22,
      "name": "Soil_Dirt_Cold"
    },
    {
      "x": -2,
      "y": 62,
      "z": 22,
      "name": "Empty"
    },
    {
      "x": -2,
      "y": 63,
      "z": 22,
      "name": "Empty"
    },
    {
      "x": -2,
      "y": 64,
      "z": 22,
      "name": "Empty"
    },
    {
      "x": -2,
      "y": 65,
      "z": 22,
      "name": "Empty"
    },
    {
      "x": -2,
      "y": 66,
      "z": 22,
      "name": "Wood_Redwood_Planks"
    },
    {
      "x": -2,
      "y": 67,
      "z": 22,
      "name": "Empty"
    },
    {
      "x": -2,
      "y": 68,
      "z": 22,
      "name": "Empty"
    },
    {
      "x": -2,
      "y": 69,
      "z": 22,
      "name": "Empty"
    },
    {
      "x": -2,
      "y": 70,
      "z": 22,
      "name": "Empty"
    },
    {
      "x": -2,
      "y": 71,
      "z": 22,
      "name": "Empty"
    },
    {
      "x": -2,
      "y": 72,
      "z": 22,
      "name": "Wood_Redwood_Trunk",
      "rotation": 4
    },
    {
      "x": -2,
      "y": 73,
      "z": 22,
      "name": "Wood_Deadwood_Roof_Flat",
      "rotation": 1
    },
    {
      "x": -2,
      "y": 58,
      "z": 23,
      "name": "Soil_Dirt_Cold"
    },
    {
      "x": -2,
      "y": 59,
      "z": 23,
      "name": "Soil_Dirt_Cold"
    },
    {
      "x": -2,
      "y": 60,
      "z": 23,
      "name": "Soil_Dirt_Cold"
    },
    {
      "x": -2,
      "y": 61,
      "z": 23,
      "name": "Soil_Dirt_Cold"
    },
    {
      "x": -2,
      "y": 62,
      "z": 23,
      "name": "Empty"
    },
    {
      "x": -2,
      "y": 63,
      "z": 23,
      "name": "Empty"
    },
    {
      "x": -2,
      "y": 64,
      "z": 23,
      "name": "Empty"
    },
    {
      "x": -2,
      "y": 65,
      "z": 23,
      "name": "Empty"
    },
    {
      "x": -2,
      "y": 66,
      "z": 23,
      "name": "Wood_Redwood_Planks"
    },
    {
      "x": -2,
      "y": 67,
      "z": 23,
      "name": "Empty"
    },
    {
      "x": -2,
      "y": 68,
      "z": 23,
      "name": "Empty"
    },
    {
      "x": -2,
      "y": 69,
      "z": 23,
      "name": "Empty"
    },
    {
      "x": -2,
      "y": 70,
      "z": 23,
      "name": "Empty"
    },
    {
      "x": -2,
      "y": 71,
      "z": 23,
      "name": "Empty"
    },
    {
      "x": -2,
      "y": 72,
      "z": 23,
      "name": "Wood_Redwood_Trunk",
      "rotation": 4
    },
    {
      "x": -2,
      "y": 73,
      "z": 23,
      "name": "Wood_Deadwood_Roof_Flat",
      "rotation": 1
    },
    {
      "x": -2,
      "y": 58,
      "z": 24,
      "name": "Soil_Dirt_Cold"
    },
    {
      "x": -2,
      "y": 59,
      "z": 24,
      "name": "Soil_Dirt_Cold"
    },
    {
      "x": -2,
      "y": 60,
      "z": 24,
      "name": "Soil_Dirt_Cold"
    },
    {
      "x": -2,
      "y": 61,
      "z": 24,
      "name": "Soil_Dirt_Cold"
    },
    {
      "x": -2,
      "y": 62,
      "z": 24,
      "name": "Empty"
    },
    {
      "x": -2,
      "y": 63,
      "z": 24,
      "name": "Empty"
    },
    {
      "x": -2,
      "y": 64,
      "z": 24,
      "name": "Empty"
    },
    {
      "x": -2,
      "y": 65,
      "z": 24,
      "name": "Empty"
    },
    {
      "x": -2,
      "y": 66,
      "z": 24,
      "name": "Wood_Redwood_Planks"
    },
    {
      "x": -2,
      "y": 67,
      "z": 24,
      "name": "Empty"
    },
    {
      "x": -2,
      "y": 68,
      "z": 24,
      "name": "Empty"
    },
    {
      "x": -2,
      "y": 69,
      "z": 24,
      "name": "Empty"
    },
    {
      "x": -2,
      "y": 70,
      "z": 24,
      "name": "Empty"
    },
    {
      "x": -2,
      "y": 71,
      "z": 24,
      "name": "Empty"
    },
    {
      "x": -2,
      "y": 72,
      "z": 24,
      "name": "Wood_Redwood_Trunk",
      "rotation": 4
    },
    {
      "x": -2,
      "y": 73,
      "z": 24,
      "name": "Wood_Deadwood_Roof_Flat",
      "rotation": 1
    },
    {
      "x": -2,
      "y": 58,
      "z": 25,
      "name": "Soil_Dirt_Cold"
    },
    {
      "x": -2,
      "y": 59,
      "z": 25,
      "name": "Soil_Dirt_Cold"
    },
    {
      "x": -2,
      "y": 60,
      "z": 25,
      "name": "Soil_Dirt_Cold"
    },
    {
      "x": -2,
      "y": 61,
      "z": 25,
      "name": "Soil_Dirt_Cold"
    },
    {
      "x": -2,
      "y": 62,
      "z": 25,
      "name": "Bench_Cooking",
      "components": {
        "Components": {
          "crafting": {
            "Position": {
              "X": -1,
              "Y": 1,
              "Z": 4
            },
            "TierLevel": 1,
            "UpgradeItems": []
          }
        }
      },
      "rotation": 2
    },
    {
      "x": -2,
      "y": 63,
      "z": 25,
      "name": "Bench_Cooking",
      "components": {
        "Components": {
          "crafting": {
            "Position": {
              "X": 30,
              "Y": 63,
              "Z": 25
            },
            "TierLevel": 1,
            "UpgradeItems": []
          }
        }
      },
      "filler": 1024,
      "rotation": 2
    },
    {
      "x": -2,
      "y": 64,
      "z": 25,
      "name": "Empty"
    },
    {
      "x": -2,
      "y": 66,
      "z": 25,
      "name": "Wood_Redwood_Planks"
    },
    {
      "x": -2,
      "y": 67,
      "z": 25,
      "name": "Empty"
    },
    {
      "x": -2,
      "y": 68,
      "z": 25,
      "name": "Empty"
    },
    {
      "x": -2,
      "y": 69,
      "z": 25,
      "name": "Empty"
    },
    {
      "x": -2,
      "y": 70,
      "z": 25,
      "name": "Empty"
    },
    {
      "x": -2,
      "y": 71,
      "z": 25,
      "name": "Empty"
    },
    {
      "x": -2,
      "y": 72,
      "z": 25,
      "name": "Wood_Redwood_Trunk",
      "rotation": 4
    },
    {
      "x": -2,
      "y": 73,
      "z": 25,
      "name": "Wood_Deadwood_Roof_Flat",
      "rotation": 1
    },
    {
      "x": -2,
      "y": 59,
      "z": 26,
      "name": "Soil_Dirt_Cold"
    },
    {
      "x": -2,
      "y": 60,
      "z": 26,
      "name": "Soil_Dirt_Cold"
    },
    {
      "x": -2,
      "y": 61,
      "z": 26,
      "name": "Rock_Shale_Brick"
    },
    {
      "x": -2,
      "y": 62,
      "z": 26,
      "name": "Rock_Shale_Brick"
    },
    {
      "x": -2,
      "y": 63,
      "z": 26,
      "name": "Rock_Shale_Brick"
    },
    {
      "x": -2,
      "y": 64,
      "z": 26,
      "name": "Rock_Shale_Brick"
    },
    {
      "x": -2,
      "y": 65,
      "z": 26,
      "name": "Rock_Shale_Brick"
    },
    {
      "x": -2,
      "y": 66,
      "z": 26,
      "name": "Wood_Redwood_Trunk",
      "rotation": 5
    },
    {
      "x": -2,
      "y": 67,
      "z": 26,
      "name": "Wood_Redwood_Trunk",
      "rotation": 5
    },
    {
      "x": -2,
      "y": 68,
      "z": 26,
      "name": "Furniture_Lumberjack_Window"
    },
    {
      "x": -2,
      "y": 69,
      "z": 26,
      "name": "Wood_Redwood_Trunk",
      "rotation": 5
    },
    {
      "x": -2,
      "y": 70,
      "z": 26,
      "name": "Wood_Redwood_Planks"
    },
    {
      "x": -2,
      "y": 71,
      "z": 26,
      "name": "Wood_Redwood_Planks"
    },
    {
      "x": -2,
      "y": 72,
      "z": 26,
      "name": "Wood_Redwood_Trunk",
      "rotation": 4
    },
    {
      "x": -2,
      "y": 73,
      "z": 26,
      "name": "Wood_Deadwood_Roof_Flat",
      "rotation": 1
    },
    {
      "x": -2,
      "y": 71,
      "z": 27,
      "name": "Wood_Redwood_Planks"
    },
    {
      "x": -2,
      "y": 72,
      "z": 27,
      "name": "Wood_Redwood_Trunk",
      "rotation": 4
    },
    {
      "x": -2,
      "y": 71,
      "z": 28,
      "name": "Wood_Redwood_Stairs",
      "rotation": 10
    },
    {
      "x": -2,
      "y": 72,
      "z": 28,
      "name": "Wood_Redwood_Trunk",
      "rotation": 4
    },
    {
      "x": -1,
      "y": 59,
      "z": 14,
      "name": "Soil_Dirt_Cold"
    },
    {
      "x": -1,
      "y": 60,
      "z": 14,
      "name": "Soil_Dirt_Cold"
    },
    {
      "x": -1,
      "y": 61,
      "z": 14,
      "name": "Soil_Dirt_Cold"
    },
    {
      "x": -1,
      "y": 62,
      "z": 14,
      "name": "Empty"
    },
    {
      "x": -1,
      "y": 63,
      "z": 14,
      "name": "Empty"
    },
    {
      "x": -1,
      "y": 64,
      "z": 14,
      "name": "Empty"
    },
    {
      "x": -1,
      "y": 65,
      "z": 14,
      "name": "Empty"
    },
    {
      "x": -1,
      "y": 70,
      "z": 14,
      "name": "Wood_Redwood_Stairs",
      "rotation": 9
    },
    {
      "x": -1,
      "y": 71,
      "z": 14,
      "name": "Wood_Redwood_Stairs",
      "rotation": 1
    },
    {
      "x": -1,
      "y": 59,
      "z": 15,
      "name": "Soil_Dirt_Cold"
    },
    {
      "x": -1,
      "y": 60,
      "z": 15,
      "name": "Soil_Dirt_Cold"
    },
    {
      "x": -1,
      "y": 61,
      "z": 15,
      "name": "Soil_Dirt_Cold"
    },
    {
      "x": -1,
      "y": 62,
      "z": 15,
      "name": "Empty"
    },
    {
      "x": -1,
      "y": 63,
      "z": 15,
      "name": "Empty"
    },
    {
      "x": -1,
      "y": 64,
      "z": 15,
      "name": "Empty"
    },
    {
      "x": -1,
      "y": 65,
      "z": 15,
      "name": "Empty"
    },
    {
      "x": -1,
      "y": 66,
      "z": 15,
      "name": "Wood_Redwood_Trunk",
      "rotation": 5
    },
    {
      "x": -1,
      "y": 67,
      "z": 15,
      "name": "Wood_Redwood_Trunk_Full",
      "rotation": 5
    },
    {
      "x": -1,
      "y": 68,
      "z": 15,
      "name": "Wood_Redwood_Trunk_Full",
      "rotation": 5
    },
    {
      "x": -1,
      "y": 69,
      "z": 15,
      "name": "Wood_Redwood_Planks"
    },
    {
      "x": -1,
      "y": 70,
      "z": 15,
      "name": "Wood_Redwood_Planks"
    },
    {
      "x": -1,
      "y": 71,
      "z": 15,
      "name": "Wood_Redwood_Planks"
    },
    {
      "x": -1,
      "y": 72,
      "z": 15,
      "name": "Wood_Deadwood_Roof",
      "rotation": 1
    },
    {
      "x": -1,
      "y": 58,
      "z": 16,
      "name": "Soil_Dirt_Cold"
    },
    {
      "x": -1,
      "y": 59,
      "z": 16,
      "name": "Soil_Dirt_Cold"
    },
    {
      "x": -1,
      "y": 60,
      "z": 16,
      "name": "Soil_Dirt_Cold"
    },
    {
      "x": -1,
      "y": 61,
      "z": 16,
      "name": "Soil_Dirt_Cold"
    },
    {
      "x": -1,
      "y": 62,
      "z": 16,
      "name": "Furniture_Lumberjack_Door",
      "rotation": 2
    },
    {
      "x": -1,
      "y": 63,
      "z": 16,
      "name": "Furniture_Lumberjack_Door",
      "filler": 1024,
      "rotation": 2
    },
    {
      "x": -1,
      "y": 64,
      "z": 16,
      "name": "Rock_Shale_Brick"
    },
    {
      "x": -1,
      "y": 65,
      "z": 16,
      "name": "Rock_Shale_Brick"
    },
    {
      "x": -1,
      "y": 66,
      "z": 16,
      "name": "Wood_Redwood_Planks"
    },
    {
      "x": -1,
      "y": 67,
      "z": 16,
      "name": "Furniture_Lumberjack_Wardrobe"
    },
    {
      "x": -1,
      "y": 68,
      "z": 16,
      "name": "Furniture_Lumberjack_Wardrobe",
      "filler": 1024
    },
    {
      "x": -1,
      "y": 69,
      "z": 16,
      "name": "Wood_Redwood_Trunk",
      "rotation": 5
    },
    {
      "x": -1,
      "y": 70,
      "z": 16,
      "name": "Furniture_Ancient_Barrel"
    },
    {
      "x": -1,
      "y": 71,
      "z": 16,
      "name": "Wood_Redwood_Planks"
    },
    {
      "x": -1,
      "y": 72,
      "z": 16,
      "name": "Wood_Deadwood_Roof",
      "rotation": 1
    },
    {
      "x": -1,
      "y": 58,
      "z": 17,
      "name": "Soil_Dirt_Cold"
    },
    {
      "x": -1,
      "y": 59,
      "z": 17,
      "name": "Soil_Dirt_Cold"
    },
    {
      "x": -1,
      "y": 60,
      "z": 17,
      "name": "Soil_Dirt_Cold"
    },
    {
      "x": -1,
      "y": 61,
      "z": 17,
      "name": "Soil_Dirt_Cold"
    },
    {
      "x": -1,
      "y": 62,
      "z": 17,
      "name": "Empty"
    },
    {
      "x": -1,
      "y": 63,
      "z": 17,
      "name": "Empty"
    },
    {
      "x": -1,
      "y": 64,
      "z": 17,
      "name": "Empty"
    },
    {
      "x": -1,
      "y": 65,
      "z": 17,
      "name": "Empty"
    },
    {
      "x": -1,
      "y": 66,
      "z": 17,
      "name": "Wood_Redwood_Planks"
    },
    {
      "x": -1,
      "y": 67,
      "z": 17,
      "name": "Empty"
    },
    {
      "x": -1,
      "y": 68,
      "z": 17,
      "name": "Empty"
    },
    {
      "x": -1,
      "y": 69,
      "z": 17,
      "name": "Furniture_Lumberjack_Platform"
    },
    {
      "x": -1,
      "y": 70,
      "z": 17,
      "name": "Empty"
    },
    {
      "x": -1,
      "y": 71,
      "z": 17,
      "name": "Wood_Redwood_Planks"
    },
    {
      "x": -1,
      "y": 72,
      "z": 17,
      "name": "Wood_Deadwood_Roof",
      "rotation": 1
    },
    {
      "x": -1,
      "y": 58,
      "z": 18,
      "name": "Soil_Dirt_Cold"
    },
    {
      "x": -1,
      "y": 59,
      "z": 18,
      "name": "Soil_Dirt_Cold"
    },
    {
      "x": -1,
      "y": 60,
      "z": 18,
      "name": "Soil_Dirt_Cold"
    },
    {
      "x": -1,
      "y": 61,
      "z": 18,
      "name": "Soil_Dirt_Cold"
    },
    {
      "x": -1,
      "y": 62,
      "z": 18,
      "name": "Empty"
    },
    {
      "x": -1,
      "y": 63,
      "z": 18,
      "name": "Empty"
    },
    {
      "x": -1,
      "y": 64,
      "z": 18,
      "name": "Empty"
    },
    {
      "x": -1,
      "y": 65,
      "z": 18,
      "name": "Empty"
    },
    {
      "x": -1,
      "y": 66,
      "z": 18,
      "name": "Wood_Redwood_Planks"
    },
    {
      "x": -1,
      "y": 67,
      "z": 18,
      "name": "Empty"
    },
    {
      "x": -1,
      "y": 68,
      "z": 18,
      "name": "Empty"
    },
    {
      "x": -1,
      "y": 69,
      "z": 18,
      "name": "Furniture_Lumberjack_Platform"
    },
    {
      "x": -1,
      "y": 70,
      "z": 18,
      "name": "Empty"
    },
    {
      "x": -1,
      "y": 71,
      "z": 18,
      "name": "Wood_Redwood_Planks"
    },
    {
      "x": -1,
      "y": 72,
      "z": 18,
      "name": "Wood_Deadwood_Roof",
      "rotation": 1
    },
    {
      "x": -1,
      "y": 58,
      "z": 19,
      "name": "Soil_Dirt_Cold"
    },
    {
      "x": -1,
      "y": 59,
      "z": 19,
      "name": "Soil_Dirt_Cold"
    },
    {
      "x": -1,
      "y": 60,
      "z": 19,
      "name": "Soil_Dirt_Cold"
    },
    {
      "x": -1,
      "y": 61,
      "z": 19,
      "name": "Soil_Dirt_Cold"
    },
    {
      "x": -1,
      "y": 62,
      "z": 19,
      "name": "Empty"
    },
    {
      "x": -1,
      "y": 63,
      "z": 19,
      "name": "Empty"
    },
    {
      "x": -1,
      "y": 64,
      "z": 19,
      "name": "Empty"
    },
    {
      "x": -1,
      "y": 65,
      "z": 19,
      "name": "Empty"
    },
    {
      "x": -1,
      "y": 66,
      "z": 19,
      "name": "Wood_Redwood_Planks"
    },
    {
      "x": -1,
      "y": 67,
      "z": 19,
      "name": "Empty"
    },
    {
      "x": -1,
      "y": 68,
      "z": 19,
      "name": "Empty"
    },
    {
      "x": -1,
      "y": 69,
      "z": 19,
      "name": "Empty"
    },
    {
      "x": -1,
      "y": 70,
      "z": 19,
      "name": "Empty"
    },
    {
      "x": -1,
      "y": 71,
      "z": 19,
      "name": "Wood_Redwood_Planks"
    },
    {
      "x": -1,
      "y": 72,
      "z": 19,
      "name": "Wood_Deadwood_Roof",
      "rotation": 1
    },
    {
      "x": -1,
      "y": 58,
      "z": 20,
      "name": "Soil_Dirt_Cold"
    },
    {
      "x": -1,
      "y": 59,
      "z": 20,
      "name": "Soil_Dirt_Cold"
    },
    {
      "x": -1,
      "y": 60,
      "z": 20,
      "name": "Soil_Dirt_Cold"
    },
    {
      "x": -1,
      "y": 61,
      "z": 20,
      "name": "Soil_Dirt_Cold"
    },
    {
      "x": -1,
      "y": 62,
      "z": 20,
      "name": "Empty"
    },
    {
      "x": -1,
      "y": 63,
      "z": 20,
      "name": "Empty"
    },
    {
      "x": -1,
      "y": 64,
      "z": 20,
      "name": "Empty"
    },
    {
      "x": -1,
      "y": 65,
      "z": 20,
      "name": "Empty"
    },
    {
      "x": -1,
      "y": 66,
      "z": 20,
      "name": "Wood_Redwood_Trunk",
      "rotation": 5
    },
    {
      "x": -1,
      "y": 67,
      "z": 20,
      "name": "Empty"
    },
    {
      "x": -1,
      "y": 68,
      "z": 20,
      "name": "Empty"
    },
    {
      "x": -1,
      "y": 69,
      "z": 20,
      "name": "Empty"
    },
    {
      "x": -1,
      "y": 70,
      "z": 20,
      "name": "Empty"
    },
    {
      "x": -1,
      "y": 71,
      "z": 20,
      "name": "Wood_Redwood_Planks"
    },
    {
      "x": -1,
      "y": 72,
      "z": 20,
      "name": "Wood_Deadwood_Roof",
      "rotation": 1
    },
    {
      "x": -1,
      "y": 58,
      "z": 21,
      "name": "Soil_Dirt_Cold"
    },
    {
      "x": -1,
      "y": 59,
      "z": 21,
      "name": "Soil_Dirt_Cold"
    },
    {
      "x": -1,
      "y": 60,
      "z": 21,
      "name": "Soil_Dirt_Cold"
    },
    {
      "x": -1,
      "y": 61,
      "z": 21,
      "name": "Soil_Dirt_Cold"
    },
    {
      "x": -1,
      "y": 62,
      "z": 21,
      "name": "Empty"
    },
    {
      "x": -1,
      "y": 63,
      "z": 21,
      "name": "Empty"
    },
    {
      "x": -1,
      "y": 64,
      "z": 21,
      "name": "Empty"
    },
    {
      "x": -1,
      "y": 65,
      "z": 21,
      "name": "Empty"
    },
    {
      "x": -1,
      "y": 66,
      "z": 21,
      "name": "Empty"
    },
    {
      "x": -1,
      "y": 67,
      "z": 21,
      "name": "Empty"
    },
    {
      "x": -1,
      "y": 68,
      "z": 21,
      "name": "Empty"
    },
    {
      "x": -1,
      "y": 69,
      "z": 21,
      "name": "Empty"
    },
    {
      "x": -1,
      "y": 70,
      "z": 21,
      "name": "Empty"
    },
    {
      "x": -1,
      "y": 71,
      "z": 21,
      "name": "Wood_Redwood_Planks"
    },
    {
      "x": -1,
      "y": 72,
      "z": 21,
      "name": "Wood_Deadwood_Roof",
      "rotation": 1
    },
    {
      "x": -1,
      "y": 58,
      "z": 22,
      "name": "Soil_Dirt_Cold"
    },
    {
      "x": -1,
      "y": 59,
      "z": 22,
      "name": "Soil_Dirt_Cold"
    },
    {
      "x": -1,
      "y": 60,
      "z": 22,
      "name": "Soil_Dirt_Cold"
    },
    {
      "x": -1,
      "y": 61,
      "z": 22,
      "name": "Soil_Dirt_Cold"
    },
    {
      "x": -1,
      "y": 62,
      "z": 22,
      "name": "Empty"
    },
    {
      "x": -1,
      "y": 63,
      "z": 22,
      "name": "Empty"
