{
  "version": 8,
  "blockIdVersion": 8,
  "anchorX": -2,
  "anchorY": 14,
  "anchorZ": 0,
  "blocks": [
    {
      "x": -11,
      "y": 6,
      "z": 10,
      "name": "Rock_Shale_Cobble"
    },
    {
      "x": -11,
      "y": 7,
      "z": 10,
      "name": "Rock_Shale_Brick"
    },
    {
      "x": -11,
      "y": 8,
      "z": 10,
      "name": "Rock_Shale_Brick"
    },
    {
      "x": -11,
      "y": 9,
      "z": 10,
      "name": "Rock_Shale_Brick"
    },
    {
      "x": -11,
      "y": 10,
      "z": 10,
      "name": "Rock_Shale_Brick"
    },
    {
      "x": -11,
      "y": 11,
      "z": 10,
      "name": "Rock_Shale_Brick"
    },
    {
      "x": -11,
      "y": 12,
      "z": 10,
      "name": "Rock_Shale_Brick"
    },
    {
      "x": -11,
      "y": 13,
      "z": 10,
      "name": "Rock_Shale_Brick"
    },
    {
      "x": -11,
      "y": 14,
      "z": 10,
      "name": "Rock_Shale_Brick"
    },
    {
      "x": -11,
      "y": 15,
      "z": 10,
      "name": "Rock_Shale_Brick_Half"
    },
    {
      "x": -11,
      "y": 5,
      "z": 11,
      "name": "Rock_Shale"
    },
    {
      "x": -11,
      "y": 6,
      "z": 11,
      "name": "Rock_Shale_Cobble"
    },
    {
      "x": -11,
      "y": 7,
      "z": 11,
      "name": "Rock_Shale_Cobble"
    },
    {
      "x": -11,
      "y": 8,
      "z": 11,
      "name": "Rock_Shale_Cobble"
    },
    {
      "x": -11,
      "y": 9,
      "z": 11,
      "name": "Rock_Shale_Cobble"
    },
    {
      "x": -11,
      "y": 10,
      "z": 11,
      "name": "Rock_Shale_Cobble"
    },
    {
      "x": -11,
      "y": 11,
      "z": 11,
      "name": "Rock_Shale_Cobble"
    },
    {
      "x": -11,
      "y": 12,
      "z": 11,
      "name": "Rock_Shale_Cobble"
    },
    {
      "x": -11,
      "y": 13,
      "z": 11,
      "name": "Rock_Shale_Cobble"
    },
    {
      "x": -11,
      "y": 14,
      "z": 11,
      "name": "Rock_Shale_Cobble"
    },
    {
      "x": -11,
      "y": 15,
      "z": 11,
      "name": "Rock_Shale_Cobble"
    },
    {
      "x": -11,
      "y": 16,
      "z": 11,
      "name": "Rock_Shale_Brick_Smooth"
    },
    {
      "x": -11,
      "y": 4,
      "z": 12,
      "name": "Rock_Shale"
    },
    {
      "x": -11,
      "y": 5,
      "z": 12,
      "name": "Rock_Shale"
    },
    {
      "x": -11,
      "y": 6,
      "z": 12,
      "name": "Rock_Shale"
    },
    {
      "x": -11,
      "y": 7,
      "z": 12,
      "name": "Rock_Shale_Brick"
    },
    {
      "x": -11,
      "y": 8,
      "z": 12,
      "name": "Rock_Shale_Brick"
    },
    {
      "x": -11,
      "y": 9,
      "z": 12,
      "name": "Rock_Shale_Brick"
    },
    {
      "x": -11,
      "y": 10,
      "z": 12,
      "name": "Rock_Shale_Brick"
    },
    {
      "x": -11,
      "y": 11,
      "z": 12,
      "name": "Rock_Shale_Brick"
    },
    {
      "x": -11,
      "y": 12,
      "z": 12,
      "name": "Rock_Shale_Brick"
    },
    {
      "x": -11,
      "y": 13,
      "z": 12,
      "name": "Rock_Shale_Brick"
    },
    {
      "x": -11,
      "y": 14,
      "z": 12,
      "name": "Rock_Shale_Brick"
    },
    {
      "x": -11,
      "y": 15,
      "z": 12,
      "name": "Rock_Shale_Brick"
    },
    {
      "x": -11,
      "y": 16,
      "z": 12,
      "name": "Rock_Shale_Brick"
    },
    {
      "x": -11,
      "y": 2,
      "z": 13,
      "name": "Rock_Shale"
    },
    {
      "x": -11,
      "y": 3,
      "z": 13,
      "name": "Rock_Shale"
    },
    {
      "x": -11,
      "y": 4,
      "z": 13,
      "name": "Rock_Shale"
    },
    {
      "x": -11,
      "y": 5,
      "z": 13,
      "name": "Rock_Shale"
    },
    {
      "x": -11,
      "y": 6,
      "z": 13,
      "name": "Rock_Shale"
    },
    {
      "x": -11,
      "y": 7,
      "z": 13,
      "name": "Rock_Shale"
    },
    {
      "x": -11,
      "y": 8,
      "z": 13,
      "name": "Rock_Shale"
    },
    {
      "x": -11,
      "y": 9,
      "z": 13,
      "name": "Rock_Shale"
    },
    {
      "x": -11,
      "y": 10,
      "z": 13,
      "name": "Rock_Shale"
    },
    {
      "x": -11,
      "y": 11,
      "z": 13,
      "name": "Rock_Shale"
    },
    {
      "x": -11,
      "y": 12,
      "z": 13,
      "name": "Rock_Shale"
    },
    {
      "x": -11,
      "y": 13,
      "z": 13,
      "name": "Rock_Shale"
    },
    {
      "x": -11,
      "y": 14,
      "z": 13,
      "name": "Rock_Shale"
    },
    {
      "x": -11,
      "y": 15,
      "z": 13,
      "name": "Rock_Shale"
    },
    {
      "x": -11,
      "y": 16,
      "z": 13,
      "name": "Rock_Shale"
    },
    {
      "x": -11,
      "y": 2,
      "z": 14,
      "name": "Rock_Shale"
    },
    {
      "x": -11,
      "y": 3,
      "z": 14,
      "name": "Rock_Shale"
    },
    {
      "x": -11,
      "y": 4,
      "z": 14,
      "name": "Rock_Shale"
    },
    {
      "x": -11,
      "y": 5,
      "z": 14,
      "name": "Rock_Shale"
    },
    {
      "x": -11,
      "y": 6,
      "z": 14,
      "name": "Rock_Shale"
    },
    {
      "x": -11,
      "y": 7,
      "z": 14,
      "name": "Rock_Shale_Cobble"
    },
    {
      "x": -11,
      "y": 8,
      "z": 14,
      "name": "Rock_Shale_Brick"
    },
    {
      "x": -11,
      "y": 9,
      "z": 14,
      "name": "Rock_Shale_Brick"
    },
    {
      "x": -11,
      "y": 10,
      "z": 14,
      "name": "Rock_Shale_Brick"
    },
    {
      "x": -11,
      "y": 11,
      "z": 14,
      "name": "Rock_Shale_Brick"
    },
    {
      "x": -11,
      "y": 12,
      "z": 14,
      "name": "Rock_Shale_Brick"
    },
    {
      "x": -11,
      "y": 13,
      "z": 14,
      "name": "Rock_Shale_Cobble"
    },
    {
      "x": -11,
      "y": 14,
      "z": 14,
      "name": "Rock_Shale_Cobble"
    },
    {
      "x": -11,
      "y": 15,
      "z": 14,
      "name": "Rock_Shale_Cobble"
    },
    {
      "x": -11,
      "y": 16,
      "z": 14,
      "name": "Rock_Shale_Brick"
    },
    {
      "x": -11,
      "y": 17,
      "z": 14,
      "name": "Rock_Shale_Brick_Half"
    },
    {
      "x": -10,
      "y": 5,
      "z": 10,
      "name": "Rock_Shale_Cobble"
    },
    {
      "x": -10,
      "y": 6,
      "z": 10,
      "name": "Rock_Shale_Cobble"
    },
    {
      "x": -10,
      "y": 7,
      "z": 10,
      "name": "Rock_Shale_Cobble"
    },
    {
      "x": -10,
      "y": 8,
      "z": 10,
      "name": "Rock_Shale_Cobble"
    },
    {
      "x": -10,
      "y": 9,
      "z": 10,
      "name": "Rock_Shale_Brick"
    },
    {
      "x": -10,
      "y": 10,
      "z": 10,
      "name": "Rock_Shale_Brick"
    },
    {
      "x": -10,
      "y": 11,
      "z": 10,
      "name": "Rock_Shale_Brick"
    },
    {
      "x": -10,
      "y": 12,
      "z": 10,
      "name": "Rock_Shale_Brick"
    },
    {
      "x": -10,
      "y": 13,
      "z": 10,
      "name": "Rock_Shale_Brick"
    },
    {
      "x": -10,
      "y": 14,
      "z": 10,
      "name": "Rock_Shale_Brick"
    },
    {
      "x": -10,
      "y": 15,
      "z": 10,
      "name": "Soil_Snow"
    },
    {
      "x": -10,
      "y": 2,
      "z": 11,
      "name": "Rock_Shale"
    },
    {
      "x": -10,
      "y": 3,
      "z": 11,
      "name": "Rock_Shale"
    },
    {
      "x": -10,
      "y": 4,
      "z": 11,
      "name": "Rock_Shale"
    },
    {
      "x": -10,
      "y": 5,
      "z": 11,
      "name": "Rock_Shale_Cobble"
    },
    {
      "x": -10,
      "y": 6,
      "z": 11,
      "name": "Rock_Shale_Cobble"
    },
    {
      "x": -10,
      "y": 7,
      "z": 11,
      "name": "Rock_Shale_Cobble"
    },
    {
      "x": -10,
      "y": 8,
      "z": 11,
      "name": "Rock_Shale_Cobble"
    },
    {
      "x": -10,
      "y": 9,
      "z": 11,
      "name": "Rock_Shale_Cobble"
    },
    {
      "x": -10,
      "y": 10,
      "z": 11,
      "name": "Rock_Shale_Cobble"
    },
    {
      "x": -10,
      "y": 11,
      "z": 11,
      "name": "Rock_Shale_Cobble"
    },
    {
      "x": -10,
      "y": 12,
      "z": 11,
      "name": "Rock_Shale_Cobble"
    },
    {
      "x": -10,
      "y": 13,
      "z": 11,
      "name": "Rock_Shale_Cobble"
    },
    {
      "x": -10,
      "y": 14,
      "z": 11,
      "name": "Rock_Shale_Cobble"
    },
    {
      "x": -10,
      "y": 15,
      "z": 11,
      "name": "Rock_Shale_Cobble"
    },
    {
      "x": -10,
      "y": 16,
      "z": 11,
      "name": "Soil_Snow"
    },
    {
      "x": -10,
      "y": 1,
      "z": 12,
      "name": "Rock_Shale"
    },
    {
      "x": -10,
      "y": 2,
      "z": 12,
      "name": "Rock_Shale"
    },
    {
      "x": -10,
      "y": 3,
      "z": 12,
      "name": "Rock_Shale"
    },
    {
      "x": -10,
      "y": 4,
      "z": 12,
      "name": "Rock_Shale"
    },
    {
      "x": -10,
      "y": 5,
      "z": 12,
      "name": "Rock_Shale"
    },
    {
      "x": -10,
      "y": 6,
      "z": 12,
      "name": "Rock_Shale_Cobble"
    },
    {
      "x": -10,
      "y": 7,
      "z": 12,
      "name": "Rock_Shale_Brick"
    },
    {
      "x": -10,
      "y": 8,
      "z": 12,
      "name": "Rock_Shale_Brick"
    },
    {
      "x": -10,
      "y": 9,
      "z": 12,
      "name": "Rock_Shale_Brick"
    },
    {
      "x": -10,
      "y": 10,
      "z": 12,
      "name": "Rock_Shale_Brick"
    },
    {
      "x": -10,
      "y": 11,
      "z": 12,
      "name": "Rock_Shale_Brick"
    },
    {
      "x": -10,
      "y": 12,
      "z": 12,
      "name": "Rock_Shale_Brick"
    },
    {
      "x": -10,
      "y": 13,
      "z": 12,
      "name": "Rock_Shale_Brick"
    },
    {
      "x": -10,
      "y": 14,
      "z": 12,
      "name": "Rock_Shale_Brick"
    },
    {
      "x": -10,
      "y": 15,
      "z": 12,
      "name": "Rock_Shale_Brick"
    },
    {
      "x": -10,
      "y": 16,
      "z": 12,
      "name": "Rock_Shale_Brick"
    },
    {
      "x": -10,
      "y": 17,
      "z": 12,
      "name": "Rock_Shale_Brick"
    },
    {
      "x": -10,
      "y": 1,
      "z": 13,
      "name": "Rock_Shale"
    },
    {
      "x": -10,
      "y": 2,
      "z": 13,
      "name": "Rock_Shale"
    },
    {
      "x": -10,
      "y": 3,
      "z": 13,
      "name": "Rock_Shale"
    },
    {
      "x": -10,
      "y": 4,
      "z": 13,
      "name": "Rock_Shale"
    },
    {
      "x": -10,
      "y": 5,
      "z": 13,
      "name": "Rock_Shale"
    },
    {
      "x": -10,
      "y": 6,
      "z": 13,
      "name": "Rock_Shale"
    },
    {
      "x": -10,
      "y": 7,
      "z": 13,
      "name": "Rock_Shale"
    },
    {
      "x": -10,
      "y": 8,
      "z": 13,
      "name": "Rock_Shale"
    },
    {
      "x": -10,
      "y": 9,
      "z": 13,
      "name": "Rock_Shale"
    },
    {
      "x": -10,
      "y": 10,
      "z": 13,
      "name": "Rock_Shale"
    },
    {
      "x": -10,
      "y": 11,
      "z": 13,
      "name": "Rock_Shale"
    },
    {
      "x": -10,
      "y": 12,
      "z": 13,
      "name": "Rock_Shale"
    },
    {
      "x": -10,
      "y": 13,
      "z": 13,
      "name": "Rock_Shale"
    },
    {
      "x": -10,
      "y": 14,
      "z": 13,
      "name": "Rock_Shale"
    },
    {
      "x": -10,
      "y": 15,
      "z": 13,
      "name": "Rock_Shale"
    },
    {
      "x": -10,
      "y": 16,
      "z": 13,
      "name": "Rock_Shale"
    },
    {
      "x": -10,
      "y": 17,
      "z": 13,
      "name": "Soil_Snow"
    },
    {
      "x": -10,
      "y": 1,
      "z": 14,
      "name": "Rock_Shale"
    },
    {
      "x": -10,
      "y": 2,
      "z": 14,
      "name": "Rock_Shale"
    },
    {
      "x": -10,
      "y": 3,
      "z": 14,
      "name": "Rock_Shale"
    },
    {
      "x": -10,
      "y": 4,
      "z": 14,
      "name": "Rock_Shale"
    },
    {
      "x": -10,
      "y": 5,
      "z": 14,
      "name": "Rock_Shale"
    },
    {
      "x": -10,
      "y": 6,
      "z": 14,
      "name": "Rock_Shale_Cobble"
    },
    {
      "x": -10,
      "y": 7,
      "z": 14,
      "name": "Rock_Shale_Cobble"
    },
    {
      "x": -10,
      "y": 8,
      "z": 14,
      "name": "Rock_Shale_Cobble_Half",
      "rotation": 4
    },
    {
      "x": -10,
      "y": 9,
      "z": 14,
      "name": "Rock_Shale_Brick"
    },
    {
      "x": -10,
      "y": 10,
      "z": 14,
      "name": "Rock_Shale_Brick"
    },
    {
      "x": -10,
      "y": 11,
      "z": 14,
      "name": "Rock_Shale_Brick"
    },
    {
      "x": -10,
      "y": 12,
      "z": 14,
      "name": "Rock_Shale_Brick"
    },
    {
      "x": -10,
      "y": 13,
      "z": 14,
      "name": "Rock_Shale_Brick"
    },
    {
      "x": -10,
      "y": 14,
      "z": 14,
      "name": "Rock_Shale_Cobble"
    },
    {
      "x": -10,
      "y": 15,
      "z": 14,
      "name": "Rock_Shale_Cobble"
    },
    {
      "x": -10,
      "y": 16,
      "z": 14,
      "name": "Rock_Shale_Brick"
    },
    {
      "x": -10,
      "y": 17,
      "z": 14,
      "name": "Rock_Shale_Brick_Half"
    },
    {
      "x": -9,
      "y": 4,
      "z": 10,
      "name": "Rock_Shale_Cobble"
    },
    {
      "x": -9,
      "y": 5,
      "z": 10,
      "name": "Rock_Shale_Cobble"
    },
    {
      "x": -9,
      "y": 6,
      "z": 10,
      "name": "Rock_Shale_Cobble"
    },
    {
      "x": -9,
      "y": 7,
      "z": 10,
      "name": "Rock_Shale_Cobble"
    },
    {
      "x": -9,
      "y": 8,
      "z": 10,
      "name": "Rock_Shale_Brick"
    },
    {
      "x": -9,
      "y": 9,
      "z": 10,
      "name": "Rock_Shale_Brick"
    },
    {
      "x": -9,
      "y": 10,
      "z": 10,
      "name": "Rock_Shale_Brick"
    },
    {
      "x": -9,
      "y": 11,
      "z": 10,
      "name": "Rock_Shale_Brick"
    },
    {
      "x": -9,
      "y": 12,
      "z": 10,
      "name": "Rock_Shale_Brick"
    },
    {
      "x": -9,
      "y": 13,
      "z": 10,
      "name": "Rock_Shale_Brick"
    },
    {
      "x": -9,
      "y": 14,
      "z": 10,
      "name": "Soil_Snow"
    },
    {
      "x": -9,
      "y": 15,
      "z": 10,
      "name": "Soil_Snow"
    },
    {
      "x": -9,
      "y": 1,
      "z": 11,
      "name": "Rock_Shale"
    },
    {
      "x": -9,
      "y": 2,
      "z": 11,
      "name": "Rock_Shale"
    },
    {
      "x": -9,
      "y": 3,
      "z": 11,
      "name": "Rock_Shale_Cobble"
    },
    {
      "x": -9,
      "y": 4,
      "z": 11,
      "name": "Rock_Shale_Cobble"
    },
    {
      "x": -9,
      "y": 5,
      "z": 11,
      "name": "Rock_Shale_Cobble"
    },
    {
      "x": -9,
      "y": 6,
      "z": 11,
      "name": "Rock_Shale_Cobble"
    },
    {
      "x": -9,
      "y": 7,
      "z": 11,
      "name": "Rock_Shale_Cobble"
    },
    {
      "x": -9,
      "y": 8,
      "z": 11,
      "name": "Rock_Shale_Cobble"
    },
    {
      "x": -9,
      "y": 9,
      "z": 11,
      "name": "Rock_Shale_Cobble"
    },
    {
      "x": -9,
      "y": 10,
      "z": 11,
      "name": "Rock_Shale_Cobble"
    },
    {
      "x": -9,
      "y": 11,
      "z": 11,
      "name": "Rock_Shale_Cobble"
    },
    {
      "x": -9,
      "y": 12,
      "z": 11,
      "name": "Rock_Shale_Cobble"
    },
    {
      "x": -9,
      "y": 13,
      "z": 11,
      "name": "Rock_Shale_Cobble"
    },
    {
      "x": -9,
      "y": 14,
      "z": 11,
      "name": "Rock_Shale_Cobble"
    },
    {
      "x": -9,
      "y": 15,
      "z": 11,
      "name": "Rock_Shale_Cobble"
    },
    {
      "x": -9,
      "y": 16,
      "z": 11,
      "name": "Soil_Snow"
    },
    {
      "x": -9,
      "y": 1,
      "z": 12,
      "name": "Rock_Shale"
    },
    {
      "x": -9,
      "y": 2,
      "z": 12,
      "name": "Rock_Shale"
    },
    {
      "x": -9,
      "y": 3,
      "z": 12,
      "name": "Rock_Shale"
    },
    {
      "x": -9,
      "y": 4,
      "z": 12,
      "name": "Rock_Shale_Cobble"
    },
    {
      "x": -9,
      "y": 5,
      "z": 12,
      "name": "Rock_Shale_Cobble"
    },
    {
      "x": -9,
      "y": 6,
      "z": 12,
      "name": "Rock_Shale_Cobble"
    },
    {
      "x": -9,
      "y": 7,
      "z": 12,
      "name": "Rock_Shale_Brick"
    },
    {
      "x": -9,
      "y": 8,
      "z": 12,
      "name": "Rock_Shale_Brick"
    },
    {
      "x": -9,
      "y": 9,
      "z": 12,
      "name": "Rock_Shale_Brick"
    },
    {
      "x": -9,
      "y": 10,
      "z": 12,
      "name": "Rock_Shale_Brick"
    },
    {
      "x": -9,
      "y": 11,
      "z": 12,
      "name": "Rock_Shale_Brick"
    },
    {
      "x": -9,
      "y": 12,
      "z": 12,
      "name": "Rock_Shale_Brick"
    },
    {
      "x": -9,
      "y": 13,
      "z": 12,
      "name": "Rock_Shale_Brick"
    },
    {
      "x": -9,
      "y": 14,
      "z": 12,
      "name": "Rock_Shale_Brick"
    },
    {
      "x": -9,
      "y": 15,
      "z": 12,
      "name": "Rock_Shale_Brick"
    },
    {
      "x": -9,
      "y": 16,
      "z": 12,
      "name": "Rock_Shale_Brick"
    },
    {
      "x": -9,
      "y": 17,
      "z": 12,
      "name": "Rock_Shale_Brick"
    },
    {
      "x": -9,
      "y": 18,
      "z": 12,
      "name": "Rock_Shale_Brick_Half"
    },
    {
      "x": -9,
      "y": 1,
      "z": 13,
      "name": "Rock_Shale"
    },
    {
      "x": -9,
      "y": 2,
      "z": 13,
      "name": "Rock_Shale"
    },
    {
      "x": -9,
      "y": 3,
      "z": 13,
      "name": "Rock_Shale"
    },
    {
      "x": -9,
      "y": 4,
      "z": 13,
      "name": "Rock_Shale"
    },
    {
      "x": -9,
      "y": 5,
      "z": 13,
      "name": "Rock_Shale"
    },
    {
      "x": -9,
      "y": 6,
      "z": 13,
      "name": "Rock_Shale"
    },
    {
      "x": -9,
      "y": 7,
      "z": 13,
      "name": "Rock_Shale"
    },
    {
      "x": -9,
      "y": 8,
      "z": 13,
      "name": "Rock_Shale"
    },
    {
      "x": -9,
      "y": 9,
      "z": 13,
      "name": "Rock_Shale"
    },
    {
      "x": -9,
      "y": 10,
      "z": 13,
      "name": "Rock_Shale"
    },
    {
      "x": -9,
      "y": 11,
      "z": 13,
      "name": "Rock_Shale"
    },
    {
      "x": -9,
      "y": 12,
      "z": 13,
      "name": "Rock_Shale"
    },
    {
      "x": -9,
      "y": 13,
      "z": 13,
      "name": "Rock_Shale"
    },
    {
      "x": -9,
      "y": 14,
      "z": 13,
      "name": "Rock_Shale"
    },
    {
      "x": -9,
      "y": 15,
      "z": 13,
      "name": "Rock_Shale"
    },
    {
      "x": -9,
      "y": 16,
      "z": 13,
      "name": "Rock_Shale"
    },
    {
      "x": -9,
      "y": 17,
      "z": 13,
      "name": "Soil_Snow"
    },
    {
      "x": -9,
      "y": 1,
      "z": 14,
      "name": "Rock_Shale"
    },
    {
      "x": -9,
      "y": 2,
      "z": 14,
      "name": "Rock_Shale"
    },
    {
      "x": -9,
      "y": 3,
      "z": 14,
      "name": "Rock_Shale"
    },
    {
      "x": -9,
      "y": 4,
      "z": 14,
      "name": "Rock_Shale"
    },
    {
      "x": -9,
      "y": 5,
      "z": 14,
      "name": "Rock_Shale"
    },
    {
      "x": -9,
      "y": 6,
      "z": 14,
      "name": "Rock_Shale_Cobble"
    },
    {
      "x": -9,
      "y": 7,
      "z": 14,
      "name": "Rock_Shale_Cobble"
    },
    {
      "x": -9,
      "y": 8,
      "z": 14,
      "name": "Rock_Shale_Cobble_Half",
      "rotation": 4
    },
    {
      "x": -9,
      "y": 9,
      "z": 14,
      "name": "Rock_Shale_Cobble_Half",
      "rotation": 4
    },
    {
      "x": -9,
      "y": 10,
      "z": 14,
      "name": "Rock_Shale_Cobble_Half",
      "rotation": 4
    },
    {
      "x": -9,
      "y": 11,
      "z": 14,
      "name": "Rock_Shale_Brick"
    },
    {
      "x": -9,
      "y": 12,
      "z": 14,
      "name": "Rock_Shale_Brick"
    },
    {
      "x": -9,
      "y": 13,
      "z": 14,
      "name": "Rock_Shale_Brick"
    },
    {
      "x": -9,
      "y": 14,
      "z": 14,
      "name": "Rock_Shale_Cobble"
    },
    {
      "x": -9,
      "y": 15,
      "z": 14,
      "name": "Rock_Shale_Cobble"
    },
    {
      "x": -9,
      "y": 16,
      "z": 14,
      "name": "Rock_Shale_Brick"
    },
    {
      "x": -9,
      "y": 17,
      "z": 14,
      "name": "Soil_Snow"
    },
    {
      "x": -8,
      "y": 3,
      "z": 10,
      "name": "Rock_Shale"
    },
    {
      "x": -8,
      "y": 4,
      "z": 10,
      "name": "Rock_Shale"
    },
    {
      "x": -8,
      "y": 5,
      "z": 10,
      "name": "Rock_Shale"
    },
    {
      "x": -8,
      "y": 6,
      "z": 10,
      "name": "Rock_Shale_Cobble"
    },
    {
      "x": -8,
      "y": 7,
      "z": 10,
      "name": "Rock_Shale_Cobble"
    },
    {
      "x": -8,
      "y": 8,
      "z": 10,
      "name": "Rock_Shale_Brick"
    },
    {
      "x": -8,
      "y": 9,
      "z": 10,
      "name": "Rock_Shale_Brick"
    },
    {
      "x": -8,
      "y": 10,
      "z": 10,
      "name": "Rock_Shale_Brick"
    },
    {
      "x": -8,
      "y": 11,
      "z": 10,
      "name": "Rock_Shale_Brick"
    },
    {
      "x": -8,
      "y": 12,
      "z": 10,
      "name": "Rock_Shale_Brick"
    },
    {
      "x": -8,
      "y": 13,
      "z": 10,
      "name": "Rock_Shale_Brick"
    },
    {
      "x": -8,
      "y": 14,
      "z": 10,
      "name": "Soil_Snow"
    },
    {
      "x": -8,
      "y": 15,
      "z": 10,
      "name": "Soil_Snow"
    },
    {
      "x": -8,
      "y": 16,
      "z": 10,
      "name": "Soil_Snow"
    },
    {
      "x": -8,
      "y": 1,
      "z": 11,
      "name": "Rock_Shale"
    },
    {
      "x": -8,
      "y": 2,
      "z": 11,
      "name": "Rock_Shale"
    },
    {
      "x": -8,
      "y": 3,
      "z": 11,
      "name": "Rock_Shale"
    },
    {
      "x": -8,
      "y": 4,
      "z": 11,
      "name": "Rock_Shale"
    },
    {
      "x": -8,
      "y": 5,
      "z": 11,
      "name": "Rock_Shale_Cobble"
    },
    {
      "x": -8,
      "y": 6,
      "z": 11,
      "name": "Rock_Shale_Cobble"
    },
    {
      "x": -8,
      "y": 7,
      "z": 11,
      "name": "Rock_Shale_Cobble"
    },
    {
      "x": -8,
      "y": 8,
      "z": 11,
      "name": "Rock_Shale_Cobble"
    },
    {
      "x": -8,
      "y": 9,
      "z": 11,
      "name": "Rock_Shale_Cobble"
    },
    {
      "x": -8,
      "y": 10,
      "z": 11,
      "name": "Rock_Shale_Cobble"
    },
    {
      "x": -8,
      "y": 11,
      "z": 11,
      "name": "Rock_Shale_Cobble"
    },
    {
      "x": -8,
      "y": 12,
      "z": 11,
      "name": "Rock_Shale_Cobble"
    },
    {
      "x": -8,
      "y": 13,
      "z": 11,
      "name": "Rock_Shale_Cobble"
    },
    {
      "x": -8,
      "y": 14,
      "z": 11,
      "name": "Rock_Shale_Cobble"
    },
    {
      "x": -8,
      "y": 15,
      "z": 11,
      "name": "Rock_Shale_Cobble"
    },
    {
      "x": -8,
      "y": 16,
      "z": 11,
      "name": "Soil_Snow"
    },
    {
      "x": -8,
      "y": 0,
      "z": 12,
      "name": "Rock_Shale"
    },
    {
      "x": -8,
      "y": 1,
      "z": 12,
      "name": "Rock_Shale"
    },
    {
      "x": -8,
      "y": 2,
      "z": 12,
      "name": "Rock_Shale"
    },
    {
      "x": -8,
      "y": 3,
      "z": 12,
      "name": "Rock_Shale_Cobble"
    },
    {
      "x": -8,
      "y": 4,
      "z": 12,
      "name": "Rock_Shale_Cobble"
    },
    {
      "x": -8,
      "y": 5,
      "z": 12,
      "name": "Rock_Shale_Cobble"
    },
    {
      "x": -8,
      "y": 6,
      "z": 12,
      "name": "Rock_Shale_Brick"
    },
    {
      "x": -8,
      "y": 7,
      "z": 12,
      "name": "Rock_Shale_Brick"
    },
    {
      "x": -8,
      "y": 8,
      "z": 12,
      "name": "Rock_Shale_Brick"
    },
    {
      "x": -8,
      "y": 9,
      "z": 12,
      "name": "Rock_Shale_Brick"
    },
    {
      "x": -8,
      "y": 10,
      "z": 12,
      "name": "Rock_Shale_Brick"
    },
    {
      "x": -8,
      "y": 11,
      "z": 12,
      "name": "Rock_Shale_Brick"
    },
    {
      "x": -8,
      "y": 12,
      "z": 12,
      "name": "Rock_Shale_Brick"
    },
    {
      "x": -8,
      "y": 13,
      "z": 12,
      "name": "Rock_Shale_Brick"
    },
    {
      "x": -8,
      "y": 14,
      "z": 12,
      "name": "Rock_Shale_Brick"
    },
    {
      "x": -8,
      "y": 15,
      "z": 12,
      "name": "Rock_Shale_Brick"
    },
    {
      "x": -8,
      "y": 16,
      "z": 12,
      "name": "Rock_Shale_Brick"
    },
    {
      "x": -8,
      "y": 17,
      "z": 12,
      "name": "Rock_Shale_Brick"
    },
    {
      "x": -8,
      "y": 18,
      "z": 12,
      "name": "Rock_Shale_Brick"
    },
    {
      "x": -8,
      "y": 0,
      "z": 13,
      "name": "Rock_Shale"
    },
    {
      "x": -8,
      "y": 1,
      "z": 13,
      "name": "Rock_Shale"
    },
    {
      "x": -8,
      "y": 2,
      "z": 13,
      "name": "Rock_Shale"
    },
    {
      "x": -8,
      "y": 3,
      "z": 13,
      "name": "Rock_Shale"
    },
    {
      "x": -8,
      "y": 4,
      "z": 13,
      "name": "Rock_Shale"
    },
    {
      "x": -8,
      "y": 5,
      "z": 13,
      "name": "Rock_Shale"
    },
    {
      "x": -8,
      "y": 6,
      "z": 13,
      "name": "Rock_Shale"
    },
    {
      "x": -8,
      "y": 7,
      "z": 13,
      "name": "Rock_Shale"
    },
    {
      "x": -8,
      "y": 8,
      "z": 13,
      "name": "Rock_Shale"
    },
    {
      "x": -8,
      "y": 9,
      "z": 13,
      "name": "Rock_Shale"
    },
    {
      "x": -8,
      "y": 10,
      "z": 13,
      "name": "Rock_Shale"
    },
    {
      "x": -8,
      "y": 11,
      "z": 13,
      "name": "Rock_Shale"
    },
    {
      "x": -8,
      "y": 12,
      "z": 13,
      "name": "Rock_Shale"
    },
    {
      "x": -8,
      "y": 13,
      "z": 13,
      "name": "Rock_Shale"
    },
    {
      "x": -8,
      "y": 14,
      "z": 13,
      "name": "Rock_Shale"
    },
    {
      "x": -8,
      "y": 15,
      "z": 13,
      "name": "Rock_Shale"
    },
    {
      "x": -8,
      "y": 16,
      "z": 13,
      "name": "Rock_Shale"
    },
    {
      "x": -8,
      "y": 17,
      "z": 13,
      "name": "Soil_Snow"
    },
    {
      "x": -8,
      "y": 0,
      "z": 14,
      "name": "Rock_Shale"
    },
    {
      "x": -8,
      "y": 1,
      "z": 14,
      "name": "Rock_Shale"
    },
    {
      "x": -8,
      "y": 2,
      "z": 14,
      "name": "Rock_Shale"
    },
    {
      "x": -8,
      "y": 3,
      "z": 14,
      "name": "Rock_Shale"
    },
    {
      "x": -8,
      "y": 4,
      "z": 14,
      "name": "Rock_Shale_Cobble"
    },
    {
      "x": -8,
      "y": 5,
      "z": 14,
      "name": "Rock_Shale_Cobble"
    },
    {
      "x": -8,
      "y": 6,
      "z": 14,
      "name": "Rock_Shale_Cobble"
    },
    {
      "x": -8,
      "y": 7,
      "z": 14,
      "name": "Rock_Shale_Cobble_Stairs"
    },
    {
      "x": -8,
      "y": 8,
      "z": 14,
      "name": "Rock_Shale_Cobble_Half",
      "rotation": 4
    },
    {
      "x": -8,
      "y": 9,
      "z": 14,
      "name": "Rock_Shale_Cobble_Half",
      "rotation": 4
    },
    {
      "x": -8,
      "y": 10,
      "z": 14,
      "name": "Rock_Shale_Cobble_Half",
      "rotation": 4
    },
    {
      "x": -8,
      "y": 11,
      "z": 14,
      "name": "Rock_Shale_Brick"
    },
    {
      "x": -8,
      "y": 12,
      "z": 14,
      "name": "Rock_Shale_Brick"
    },
    {
      "x": -8,
      "y": 13,
      "z": 14,
      "name": "Rock_Shale_Brick"
    },
    {
      "x": -8,
      "y": 14,
      "z": 14,
      "name": "Rock_Shale_Brick"
    },
    {
      "x": -8,
      "y": 15,
      "z": 14,
      "name": "Rock_Shale_Cobble"
    },
    {
      "x": -8,
      "y": 16,
      "z": 14,
      "name": "Rock_Shale_Brick"
    },
    {
      "x": -8,
      "y": 17,
      "z": 14,
      "name": "Soil_Snow"
    },
    {
      "x": -7,
      "y": 0,
      "z": 10,
      "name": "Rock_Shale"
    },
    {
      "x": -7,
      "y": 1,
      "z": 10,
      "name": "Rock_Shale"
    },
    {
      "x": -7,
      "y": 2,
      "z": 10,
      "name": "Rock_Shale"
    },
    {
      "x": -7,
      "y": 3,
      "z": 10,
      "name": "Rock_Shale"
    },
    {
      "x": -7,
      "y": 4,
      "z": 10,
      "name": "Rock_Shale"
    },
    {
      "x": -7,
      "y": 5,
      "z": 10,
      "name": "Rock_Shale"
    },
    {
      "x": -7,
      "y": 6,
      "z": 10,
      "name": "Rock_Shale_Cobble"
    },
    {
      "x": -7,
      "y": 7,
      "z": 10,
      "name": "Rock_Shale_Cobble"
    },
    {
      "x": -7,
      "y": 8,
      "z": 10,
      "name": "Rock_Shale_Brick"
    },
    {
      "x": -7,
      "y": 9,
      "z": 10,
      "name": "Rock_Shale_Brick"
    },
    {
      "x": -7,
      "y": 10,
      "z": 10,
      "name": "Rock_Shale_Brick"
    },
    {
      "x": -7,
      "y": 11,
      "z": 10,
      "name": "Rock_Shale_Brick"
    },
    {
      "x": -7,
      "y": 12,
      "z": 10,
      "name": "Rock_Shale_Brick"
    },
    {
      "x": -7,
      "y": 13,
      "z": 10,
      "name": "Rock_Shale_Brick"
    },
    {
      "x": -7,
      "y": 14,
      "z": 10,
      "name": "Rock_Shale_Brick"
    },
    {
      "x": -7,
      "y": 15,
      "z": 10,
      "name": "Rock_Shale_Cobble_Half",
      "rotation": 6
    },
    {
      "x": -7,
      "y": 16,
      "z": 10,
      "name": "Soil_Snow"
    },
    {
      "x": -7,
      "y": 0,
      "z": 11,
      "name": "Rock_Shale"
    },
    {
      "x": -7,
      "y": 1,
      "z": 11,
      "name": "Rock_Shale"
    },
    {
      "x": -7,
      "y": 2,
      "z": 11,
      "name": "Rock_Shale"
    },
    {
      "x": -7,
      "y": 3,
      "z": 11,
      "name": "Rock_Shale"
    },
    {
      "x": -7,
      "y": 4,
      "z": 11,
      "name": "Rock_Shale"
    },
    {
      "x": -7,
      "y": 5,
      "z": 11,
      "name": "Rock_Shale"
    },
    {
      "x": -7,
      "y": 6,
      "z": 11,
      "name": "Rock_Shale_Cobble"
    },
    {
      "x": -7,
      "y": 7,
      "z": 11,
      "name": "Rock_Shale_Cobble"
    },
    {
      "x": -7,
      "y": 8,
      "z": 11,
      "name": "Rock_Shale_Cobble"
    },
    {
      "x": -7,
      "y": 9,
      "z": 11,
      "name": "Rock_Shale_Cobble"
    },
    {
      "x": -7,
      "y": 10,
      "z": 11,
      "name": "Rock_Shale_Cobble"
    },
    {
      "x": -7,
      "y": 11,
      "z": 11,
      "name": "Rock_Shale_Cobble"
    },
    {
      "x": -7,
      "y": 12,
      "z": 11,
      "name": "Rock_Shale_Cobble"
    },
    {
      "x": -7,
      "y": 13,
      "z": 11,
      "name": "Rock_Shale_Cobble"
    },
    {
      "x": -7,
      "y": 14,
      "z": 11,
      "name": "Rock_Shale_Cobble"
    },
    {
      "x": -7,
      "y": 15,
      "z": 11,
      "name": "Rock_Shale_Cobble"
    },
    {
      "x": -7,
      "y": 16,
      "z": 11,
      "name": "Soil_Snow"
    },
    {
      "x": -7,
      "y": 17,
      "z": 11,
      "name": "Plant_Bush_Winter_Snow"
    },
    {
      "x": -7,
      "y": 0,
      "z": 12,
      "name": "Rock_Shale"
    },
    {
      "x": -7,
      "y": 1,
      "z": 12,
      "name": "Rock_Shale"
    },
    {
      "x": -7,
      "y": 2,
      "z": 12,
      "name": "Rock_Shale"
    },
    {
      "x": -7,
      "y": 3,
      "z": 12,
      "name": "Rock_Shale"
    },
    {
      "x": -7,
      "y": 4,
      "z": 12,
      "name": "Rock_Shale_Brick"
    },
    {
      "x": -7,
      "y": 5,
      "z": 12,
      "name": "Rock_Shale_Brick"
    },
    {
      "x": -7,
      "y": 6,
      "z": 12,
      "name": "Rock_Shale_Brick"
    },
    {
      "x": -7,
      "y": 7,
      "z": 12,
      "name": "Rock_Shale_Brick"
    },
    {
      "x": -7,
      "y": 8,
      "z": 12,
      "name": "Rock_Shale_Brick"
    },
    {
      "x": -7,
      "y": 9,
      "z": 12,
      "name": "Rock_Shale_Brick"
    },
    {
      "x": -7,
      "y": 10,
      "z": 12,
      "name": "Rock_Shale_Brick"
    },
    {
      "x": -7,
      "y": 11,
      "z": 12,
      "name": "Rock_Shale_Brick"
    },
    {
      "x": -7,
      "y": 12,
      "z": 12,
      "name": "Rock_Shale_Brick"
    },
    {
      "x": -7,
      "y": 13,
      "z": 12,
      "name": "Rock_Shale_Brick"
    },
    {
      "x": -7,
      "y": 14,
      "z": 12,
      "name": "Rock_Shale_Brick"
    },
    {
      "x": -7,
      "y": 15,
      "z": 12,
      "name": "Rock_Shale_Brick"
    },
    {
      "x": -7,
      "y": 16,
      "z": 12,
      "name": "Rock_Shale_Brick"
    },
    {
      "x": -7,
      "y": 17,
      "z": 12,
      "name": "Rock_Shale_Brick"
    },
    {
      "x": -7,
      "y": 18,
      "z": 12,
      "name": "Rock_Shale_Brick"
    },
    {
      "x": -7,
      "y": 0,
      "z": 13,
      "name": "Rock_Shale"
    },
    {
      "x": -7,
      "y": 1,
      "z": 13,
      "name": "Rock_Shale"
    },
    {
      "x": -7,
      "y": 2,
      "z": 13,
      "name": "Rock_Shale"
    },
    {
      "x": -7,
      "y": 3,
      "z": 13,
      "name": "Rock_Shale"
    },
    {
      "x": -7,
      "y": 4,
      "z": 13,
      "name": "Rock_Shale"
    },
    {
      "x": -7,
      "y": 5,
      "z": 13,
      "name": "Rock_Shale"
    },
    {
      "x": -7,
      "y": 6,
      "z": 13,
      "name": "Rock_Shale"
    },
    {
      "x": -7,
      "y": 7,
      "z": 13,
      "name": "Rock_Shale"
    },
    {
      "x": -7,
      "y": 8,
      "z": 13,
      "name": "Rock_Shale"
    },
    {
      "x": -7,
      "y": 9,
      "z": 13,
      "name": "Rock_Shale"
    },
    {
      "x": -7,
      "y": 10,
      "z": 13,
      "name": "Rock_Shale"
    },
    {
      "x": -7,
      "y": 11,
      "z": 13,
      "name": "Rock_Shale"
    },
    {
      "x": -7,
      "y": 12,
      "z": 13,
      "name": "Rock_Shale"
    },
    {
      "x": -7,
      "y": 13,
      "z": 13,
      "name": "Rock_Shale"
    },
    {
      "x": -7,
      "y": 14,
      "z": 13,
      "name": "Rock_Shale"
    },
    {
      "x": -7,
      "y": 15,
      "z": 13,
      "name": "Rock_Shale"
    },
    {
      "x": -7,
      "y": 16,
      "z": 13,
      "name": "Rock_Shale"
    },
    {
      "x": -7,
      "y": 17,
      "z": 13,
      "name": "Rock_Shale"
    },
    {
      "x": -7,
      "y": 18,
      "z": 13,
      "name": "Soil_Snow"
    },
    {
      "x": -7,
      "y": 19,
      "z": 13,
      "name": "Plant_Grass_Snowy_Short"
    },
    {
      "x": -7,
      "y": 0,
      "z": 14,
      "name": "Rock_Shale"
    },
    {
      "x": -7,
      "y": 1,
      "z": 14,
      "name": "Rock_Shale"
    },
    {
      "x": -7,
      "y": 2,
      "z": 14,
      "name": "Rock_Shale"
    },
    {
      "x": -7,
      "y": 3,
      "z": 14,
      "name": "Rock_Shale"
    },
    {
      "x": -7,
      "y": 4,
      "z": 14,
      "name": "Rock_Shale"
    },
    {
      "x": -7,
      "y": 5,
      "z": 14,
      "name": "Rock_Shale"
    },
    {
      "x": -7,
      "y": 6,
      "z": 14,
      "name": "Rock_Shale_Brick"
    },
    {
      "x": -7,
      "y": 7,
      "z": 14,
      "name": "Rock_Shale_Brick"
    },
    {
      "x": -7,
      "y": 8,
      "z": 14,
      "name": "Rock_Shale_Brick"
    },
    {
      "x": -7,
      "y": 9,
      "z": 14,
      "name": "Rock_Shale_Brick"
    },
    {
      "x": -7,
      "y": 10,
      "z": 14,
      "name": "Rock_Shale_Brick"
    },
    {
      "x": -7,
      "y": 11,
      "z": 14,
      "name": "Rock_Shale_Brick"
    },
    {
      "x": -7,
      "y": 12,
      "z": 14,
      "name": "Rock_Shale_Brick"
    },
    {
      "x": -7,
      "y": 13,
      "z": 14,
      "name": "Rock_Shale_Brick"
    },
    {
      "x": -7,
      "y": 14,
      "z": 14,
      "name": "Rock_Shale_Brick"
    },
    {
      "x": -7,
      "y": 15,
      "z": 14,
      "name": "Rock_Shale_Cobble"
    },
    {
      "x": -7,
      "y": 16,
      "z": 14,
      "name": "Rock_Shale_Brick"
    },
    {
      "x": -7,
      "y": 17,
      "z": 14,
      "name": "Rock_Shale_Brick"
    },
    {
      "x": -7,
      "y": 18,
      "z": 14,
      "name": "Soil_Snow"
    },
    {
      "x": -6,
      "y": 0,
      "z": 10,
      "name": "Rock_Shale"
    },
    {
      "x": -6,
      "y": 1,
      "z": 10,
      "name": "Rock_Shale"
    },
    {
      "x": -6,
      "y": 2,
      "z": 10,
      "name": "Rock_Shale"
    },
    {
      "x": -6,
      "y": 3,
      "z": 10,
      "name": "Rock_Shale"
    },
    {
      "x": -6,
      "y": 4,
      "z": 10,
      "name": "Rock_Shale"
    },
    {
      "x": -6,
      "y": 5,
      "z": 10,
      "name": "Rock_Shale"
    },
    {
      "x": -6,
      "y": 6,
      "z": 10,
      "name": "Rock_Shale"
    },
    {
      "x": -6,
      "y": 7,
      "z": 10,
      "name": "Rock_Shale_Cobble"
    },
    {
      "x": -6,
      "y": 8,
      "z": 10,
      "name": "Rock_Shale_Brick"
    },
    {
      "x": -6,
      "y": 9,
      "z": 10,
      "name": "Rock_Shale_Brick"
    },
    {
      "x": -6,
      "y": 10,
      "z": 10,
      "name": "Rock_Shale_Brick"
    },
    {
      "x": -6,
      "y": 11,
      "z": 10,
      "name": "Rock_Shale_Brick"
    },
    {
      "x": -6,
      "y": 12,
      "z": 10,
      "name": "Rock_Shale_Brick"
    },
    {
      "x": -6,
      "y": 13,
      "z": 10,
      "name": "Rock_Shale_Brick"
    },
    {
      "x": -6,
      "y": 14,
      "z": 10,
      "name": "Rock_Shale_Cobble_Half",
      "rotation": 6
    },
    {
      "x": -6,
      "y": 15,
      "z": 10,
      "name": "Rock_Shale_Cobble_Stairs",
      "rotation": 8
    },
    {
      "x": -6,
      "y": 16,
      "z": 10,
      "name": "Soil_Snow"
    },
    {
      "x": -6,
      "y": 17,
      "z": 10,
      "name": "Plant_Bush_Winter_Snow"
    },
    {
      "x": -6,
      "y": 0,
      "z": 11,
      "name": "Rock_Shale"
    },
    {
      "x": -6,
      "y": 1,
      "z": 11,
      "name": "Rock_Shale"
    },
    {
      "x": -6,
      "y": 2,
      "z": 11,
      "name": "Rock_Shale"
    },
    {
      "x": -6,
      "y": 3,
      "z": 11,
      "name": "Rock_Shale"
    },
    {
      "x": -6,
      "y": 4,
      "z": 11,
      "name": "Rock_Shale"
    },
    {
      "x": -6,
      "y": 5,
      "z": 11,
      "name": "Rock_Shale"
    },
    {
      "x": -6,
      "y": 6,
      "z": 11,
      "name": "Rock_Shale_Cobble"
    },
    {
      "x": -6,
      "y": 7,
      "z": 11,
      "name": "Rock_Shale_Cobble"
    },
    {
      "x": -6,
      "y": 8,
      "z": 11,
      "name": "Rock_Shale_Cobble"
    },
    {
      "x": -6,
      "y": 9,
      "z": 11,
      "name": "Rock_Shale_Cobble"
    },
    {
      "x": -6,
      "y": 10,
      "z": 11,
      "name": "Rock_Shale_Cobble"
    },
    {
      "x": -6,
      "y": 11,
      "z": 11,
      "name": "Rock_Shale_Cobble"
    },
    {
      "x": -6,
      "y": 12,
      "z": 11,
      "name": "Rock_Shale_Cobble"
    },
    {
      "x": -6,
      "y": 13,
      "z": 11,
      "name": "Rock_Shale_Cobble"
    },
    {
      "x": -6,
      "y": 14,
      "z": 11,
      "name": "Rock_Shale_Cobble"
    },
    {
      "x": -6,
      "y": 15,
      "z": 11,
      "name": "Rock_Shale_Cobble"
    },
    {
      "x": -6,
      "y": 16,
      "z": 11,
      "name": "Soil_Snow"
    },
    {
      "x": -6,
      "y": 17,
      "z": 11,
      "name": "Rubble_Ice_Medium"
    },
    {
      "x": -6,
      "y": 0,
      "z": 12,
      "name": "Rock_Shale"
    },
    {
      "x": -6,
      "y": 1,
      "z": 12,
      "name": "Rock_Shale"
    },
    {
      "x": -6,
      "y": 2,
      "z": 12,
      "name": "Rock_Shale"
    },
    {
      "x": -6,
      "y": 3,
      "z": 12,
      "name": "Rock_Shale"
    },
    {
      "x": -6,
      "y": 4,
      "z": 12,
      "name": "Rock_Shale_Brick"
    },
    {
      "x": -6,
      "y": 5,
      "z": 12,
      "name": "Rock_Shale_Brick"
    },
    {
      "x": -6,
      "y": 6,
      "z": 12,
      "name": "Rock_Shale_Brick"
    },
    {
      "x": -6,
      "y": 7,
      "z": 12,
      "name": "Rock_Shale_Brick"
    },
    {
      "x": -6,
      "y": 8,
      "z": 12,
      "name": "Rock_Shale_Brick"
    },
    {
      "x": -6,
      "y": 9,
      "z": 12,
      "name": "Rock_Shale_Brick"
    },
    {
      "x": -6,
      "y": 10,
      "z": 12,
      "name": "Rock_Shale_Brick"
    },
    {
      "x": -6,
      "y": 11,
      "z": 12,
      "name": "Rock_Shale_Brick"
    },
    {
      "x": -6,
      "y": 12,
      "z": 12,
      "name": "Rock_Shale_Brick"
    },
    {
      "x": -6,
      "y": 13,
      "z": 12,
      "name": "Rock_Shale_Brick"
    },
    {
      "x": -6,
      "y": 14,
      "z": 12,
      "name": "Rock_Shale_Brick"
    },
    {
      "x": -6,
      "y": 15,
      "z": 12,
      "name": "Rock_Shale_Brick"
    },
    {
      "x": -6,
      "y": 16,
      "z": 12,
      "name": "Rock_Shale_Brick"
    },
    {
      "x": -6,
      "y": 17,
      "z": 12,
      "name": "Rock_Shale_Brick"
    },
    {
      "x": -6,
      "y": 18,
      "z": 12,
      "name": "Rock_Shale_Brick"
    },
    {
      "x": -6,
      "y": 0,
      "z": 13,
      "name": "Rock_Shale"
    },
    {
      "x": -6,
      "y": 1,
      "z": 13,
      "name": "Rock_Shale"
    },
    {
      "x": -6,
      "y": 2,
      "z": 13,
      "name": "Rock_Shale"
    },
    {
      "x": -6,
      "y": 3,
      "z": 13,
      "name": "Rock_Shale"
    },
    {
      "x": -6,
      "y": 4,
      "z": 13,
      "name": "Rock_Shale"
    },
    {
      "x": -6,
      "y": 5,
      "z": 13,
      "name": "Rock_Shale"
    },
    {
      "x": -6,
      "y": 6,
      "z": 13,
      "name": "Rock_Shale"
    },
    {
      "x": -6,
      "y": 7,
      "z": 13,
      "name": "Rock_Shale"
    },
    {
      "x": -6,
      "y": 8,
      "z": 13,
      "name": "Rock_Shale"
    },
    {
      "x": -6,
      "y": 9,
      "z": 13,
      "name": "Rock_Shale"
    },
    {
      "x": -6,
      "y": 10,
      "z": 13,
      "name": "Rock_Shale"
    },
    {
      "x": -6,
      "y": 11,
      "z": 13,
      "name": "Rock_Shale"
    },
    {
      "x": -6,
      "y": 12,
      "z": 13,
      "name": "Rock_Shale"
    },
    {
      "x": -6,
      "y": 13,
      "z": 13,
      "name": "Rock_Shale"
    },
    {
      "x": -6,
      "y": 14,
      "z": 13,
      "name": "Rock_Shale"
    },
    {
      "x": -6,
      "y": 15,
      "z": 13,
      "name": "Rock_Shale"
    },
    {
      "x": -6,
      "y": 16,
      "z": 13,
      "name": "Rock_Shale"
    },
    {
      "x": -6,
      "y": 17,
      "z": 13,
      "name": "Rock_Shale"
    },
    {
      "x": -6,
      "y": 18,
      "z": 13,
      "name": "Soil_Snow"
    },
    {
      "x": -6,
      "y": 0,
      "z": 14,
      "name": "Rock_Shale"
    },
    {
      "x": -6,
      "y": 1,
      "z": 14,
      "name": "Rock_Shale"
    },
    {
      "x": -6,
      "y": 2,
      "z": 14,
      "name": "Rock_Shale"
    },
    {
      "x": -6,
      "y": 3,
      "z": 14,
      "name": "Rock_Shale"
    },
    {
      "x": -6,
      "y": 4,
      "z": 14,
      "name": "Rock_Shale"
    },
    {
      "x": -6,
      "y": 5,
      "z": 14,
      "name": "Rock_Shale"
    },
    {
      "x": -6,
      "y": 6,
      "z": 14,
      "name": "Rock_Shale_Brick"
    },
    {
      "x": -6,
      "y": 7,
      "z": 14,
      "name": "Rock_Shale_Brick"
    },
    {
      "x": -6,
      "y": 8,
      "z": 14,
      "name": "Rock_Shale_Brick"
    },
    {
      "x": -6,
      "y": 9,
      "z": 14,
      "name": "Rock_Shale_Brick"
    },
    {
      "x": -6,
      "y": 10,
      "z": 14,
      "name": "Rock_Shale_Brick"
    },
    {
      "x": -6,
      "y": 11,
      "z": 14,
      "name": "Rock_Shale_Brick"
    },
    {
      "x": -6,
      "y": 12,
      "z": 14,
      "name": "Rock_Shale_Brick"
    },
    {
      "x": -6,
      "y": 13,
      "z": 14,
      "name": "Rock_Shale_Brick"
    },
    {
      "x": -6,
      "y": 14,
      "z": 14,
      "name": "Rock_Shale_Brick"
    },
    {
      "x": -6,
      "y": 15,
      "z": 14,
      "name": "Rock_Shale_Brick"
    },
    {
      "x": -6,
      "y": 16,
      "z": 14,
      "name": "Rock_Shale_Brick"
    },
    {
      "x": -6,
      "y": 17,
      "z": 14,
      "name": "Rock_Shale_Brick"
    },
    {
      "x": -6,
      "y": 18,
      "z": 14,
      "name": "Soil_Snow"
    },
    {
      "x": -6,
      "y": 17,
      "z": 15,
      "name": "Rock_Shale_Brick"
    },
    {
      "x": -6,
      "y": 18,
      "z": 15,
      "name": "Rock_Shale_Brick_Half",
      "rotation": 7
    },
    {
      "x": -5,
      "y": 2,
      "z": 10,
      "name": "Rock_Shale"
    },
    {
      "x": -5,
      "y": 3,
      "z": 10,
      "name": "Rock_Shale"
    },
    {
      "x": -5,
      "y": 4,
      "z": 10,
      "name": "Rock_Shale"
    },
    {
      "x": -5,
      "y": 5,
      "z": 10,
      "name": "Rock_Shale"
    },
    {
      "x": -5,
      "y": 6,
      "z": 10,
      "name": "Rock_Shale"
    },
    {
      "x": -5,
      "y": 7,
      "z": 10,
      "name": "Rock_Shale"
    },
    {
      "x": -5,
      "y": 8,
      "z": 10,
      "name": "Rock_Shale_Cobble"
    },
    {
      "x": -5,
      "y": 9,
      "z": 10,
      "name": "Rock_Shale_Brick"
    },
    {
      "x": -5,
      "y": 10,
      "z": 10,
      "name": "Rock_Shale_Brick"
    },
    {
      "x": -5,
      "y": 11,
      "z": 10,
      "name": "Rock_Shale_Brick"
    },
    {
      "x": -5,
      "y": 12,
      "z": 10,
      "name": "Rock_Shale_Brick"
    },
    {
      "x": -5,
      "y": 13,
      "z": 10,
      "name": "Rock_Shale_Cobble_Half",
      "rotation": 6
    },
    {
      "x": -5,
      "y": 14,
      "z": 10,
      "name": "Rock_Shale_Cobble_Half",
      "rotation": 6
    },
    {
      "x": -5,
      "y": 15,
      "z": 10,
      "name": "Rock_Shale_Cobble_Stairs",
      "rotation": 8
    },
    {
      "x": -5,
      "y": 16,
      "z": 10,
      "name": "Soil_Snow"
    },
    {
      "x": -5,
      "y": 17,
      "z": 10,
      "name": "Plant_Grass_Snowy_Short"
    },
    {
      "x": -5,
      "y": 0,
      "z": 11,
      "name": "Rock_Shale"
    },
    {
      "x": -5,
      "y": 1,
      "z": 11,
      "name": "Rock_Shale"
    },
    {
      "x": -5,
      "y": 2,
      "z": 11,
      "name": "Rock_Shale"
    },
    {
      "x": -5,
      "y": 3,
      "z": 11,
      "name": "Rock_Shale"
    },
    {
      "x": -5,
      "y": 4,
      "z": 11,
      "name": "Rock_Shale"
    },
    {
      "x": -5,
      "y": 5,
      "z": 11,
      "name": "Rock_Shale"
    },
    {
      "x": -5,
      "y": 6,
      "z": 11,
      "name": "Rock_Shale"
    },
    {
      "x": -5,
      "y": 7,
      "z": 11,
      "name": "Rock_Shale"
    },
    {
      "x": -5,
      "y": 8,
      "z": 11,
      "name": "Rock_Shale_Cobble"
    },
    {
      "x": -5,
      "y": 9,
      "z": 11,
      "name": "Rock_Shale_Cobble"
    },
    {
      "x": -5,
      "y": 10,
      "z": 11,
      "name": "Rock_Shale_Cobble"
    },
    {
      "x": -5,
      "y": 11,
      "z": 11,
      "name": "Rock_Shale_Cobble"
    },
    {
      "x": -5,
      "y": 12,
      "z": 11,
      "name": "Rock_Shale_Cobble"
    },
    {
      "x": -5,
      "y": 13,
      "z": 11,
      "name": "Rock_Shale_Cobble"
    },
    {
      "x": -5,
      "y": 14,
      "z": 11,
      "name": "Rock_Shale_Cobble"
    },
    {
      "x": -5,
      "y": 15,
      "z": 11,
      "name": "Rock_Shale_Cobble"
    },
    {
      "x": -5,
      "y": 16,
      "z": 11,
      "name": "Soil_Snow"
    },
    {
      "x": -5,
      "y": 0,
      "z": 12,
      "name": "Rock_Shale"
    },
    {
      "x": -5,
      "y": 1,
      "z": 12,
      "name": "Rock_Shale"
    },
    {
      "x": -5,
      "y": 2,
      "z": 12,
      "name": "Rock_Shale"
    },
    {
      "x": -5,
      "y": 3,
      "z": 12,
      "name": "Rock_Shale"
    },
    {
      "x": -5,
      "y": 4,
      "z": 12,
      "name": "Rock_Shale"
    },
    {
      "x": -5,
      "y": 5,
      "z": 12,
      "name": "Rock_Shale"
    },
    {
      "x": -5,
      "y": 6,
      "z": 12,
      "name": "Rock_Shale_Brick"
    },
    {
      "x": -5,
      "y": 7,
      "z": 12,
      "name": "Rock_Shale_Brick"
    },
    {
      "x": -5,
      "y": 8,
      "z": 12,
      "name": "Rock_Shale_Brick"
    },
    {
      "x": -5,
      "y": 9,
      "z": 12,
      "name": "Rock_Shale_Brick"
    },
    {
      "x": -5,
      "y": 10,
      "z": 12,
      "name": "Rock_Shale_Brick"
    },
    {
      "x": -5,
      "y": 11,
      "z": 12,
      "name": "Rock_Shale_Brick"
    },
    {
      "x": -5,
      "y": 12,
      "z": 12,
      "name": "Rock_Shale_Brick"
    },
    {
      "x": -5,
      "y": 13,
      "z": 12,
      "name": "Rock_Shale_Brick"
    },
    {
      "x": -5,
      "y": 14,
      "z": 12,
      "name": "Rock_Shale_Brick"
    },
    {
      "x": -5,
      "y": 15,
      "z": 12,
      "name": "Rock_Shale_Brick"
    },
    {
      "x": -5,
      "y": 16,
      "z": 12,
      "name": "Rock_Shale_Brick"
    },
    {
      "x": -5,
      "y": 17,
      "z": 12,
      "name": "Rock_Shale_Brick"
    },
    {
      "x": -5,
      "y": 18,
      "z": 12,
      "name": "Rock_Shale_Brick"
    },
    {
      "x": -5,
      "y": 19,
      "z": 12,
      "name": "Soil_Snow"
    },
    {
      "x": -5,
      "y": 0,
      "z": 13,
      "name": "Rock_Shale"
    },
    {
      "x": -5,
      "y": 1,
      "z": 13,
      "name": "Rock_Shale"
    },
    {
      "x": -5,
      "y": 2,
      "z": 13,
      "name": "Rock_Shale"
    },
    {
      "x": -5,
      "y": 3,
      "z": 13,
      "name": "Rock_Shale"
    },
    {
      "x": -5,
      "y": 4,
      "z": 13,
      "name": "Rock_Shale"
    },
    {
      "x": -5,
      "y": 5,
      "z": 13,
      "name": "Rock_Shale"
    },
    {
      "x": -5,
      "y": 6,
      "z": 13,
      "name": "Rock_Shale"
    },
    {
      "x": -5,
      "y": 7,
      "z": 13,
      "name": "Rock_Shale"
    },
    {
      "x": -5,
      "y": 8,
      "z": 13,
      "name": "Rock_Shale"
    },
    {
      "x": -5,
      "y": 9,
      "z": 13,
      "name": "Rock_Shale"
    },
    {
      "x": -5,
      "y": 10,
      "z": 13,
      "name": "Rock_Shale"
    },
    {
      "x": -5,
      "y": 11,
      "z": 13,
      "name": "Rock_Shale"
    },
    {
      "x": -5,
      "y": 12,
      "z": 13,
      "name": "Rock_Shale"
    },
    {
      "x": -5,
      "y": 13,
      "z": 13,
      "name": "Rock_Shale"
    },
    {
      "x": -5,
      "y": 14,
      "z": 13,
      "name": "Rock_Shale"
    },
    {
      "x": -5,
      "y": 15,
      "z": 13,
      "name": "Rock_Shale"
    },
    {
      "x": -5,
      "y": 16,
      "z": 13,
      "name": "Rock_Shale"
    },
    {
      "x": -5,
      "y": 17,
      "z": 13,
      "name": "Rock_Shale"
    },
    {
      "x": -5,
      "y": 18,
      "z": 13,
      "name": "Rock_Shale"
    },
    {
      "x": -5,
      "y": 19,
      "z": 13,
      "name": "Soil_Snow"
    },
    {
      "x": -5,
      "y": 20,
      "z": 13,
      "name": "Plant_Bush_Winter_Snow"
    },
    {
      "x": -5,
      "y": 4,
      "z": 14,
      "name": "Rock_Shale_Cobble_Half",
      "rotation": 4
    },
    {
      "x": -5,
      "y": 5,
      "z": 14,
      "name": "Rock_Shale_Cobble"
    },
    {
      "x": -5,
      "y": 6,
      "z": 14,
      "name": "Rock_Shale_Cobble"
    },
    {
      "x": -5,
      "y": 7,
      "z": 14,
      "name": "Rock_Shale_Brick"
    },
    {
      "x": -5,
      "y": 8,
      "z": 14,
      "name": "Rock_Shale_Brick"
    },
    {
      "x": -5,
      "y": 9,
      "z": 14,
      "name": "Rock_Shale_Brick"
    },
    {
      "x": -5,
      "y": 10,
      "z": 14,
      "name": "Rock_Shale_Brick"
    },
    {
      "x": -5,
      "y": 11,
      "z": 14,
      "name": "Rock_Shale_Brick"
    },
    {
      "x": -5,
      "y": 12,
      "z": 14,
      "name": "Rock_Shale_Brick"
    },
    {
      "x": -5,
      "y": 13,
      "z": 14,
      "name": "Rock_Shale_Brick"
    },
    {
      "x": -5,
      "y": 14,
      "z": 14,
      "name": "Rock_Shale_Brick"
    },
    {
      "x": -5,
      "y": 15,
      "z": 14,
      "name": "Rock_Shale_Brick"
    },
    {
      "x": -5,
      "y": 16,
      "z": 14,
      "name": "Rock_Shale_Cobble_Stairs",
      "rotation": 10
    },
    {
      "x": -5,
      "y": 17,
      "z": 14,
      "name": "Rock_Shale_Brick"
    },
    {
      "x": -5,
      "y": 18,
      "z": 14,
      "name": "Rock_Shale_Brick"
    },
    {
      "x": -5,
      "y": 19,
      "z": 14,
      "name": "Soil_Snow"
    },
    {
      "x": -5,
      "y": 17,
      "z": 15,
      "name": "Rock_Shale_Brick"
    },
    {
      "x": -5,
      "y": 18,
      "z": 15,
      "name": "Rock_Shale_Brick"
    },
    {
      "x": -4,
      "y": 3,
      "z": 10,
      "name": "Rock_Shale"
    },
    {
      "x": -4,
      "y": 4,
      "z": 10,
      "name": "Rock_Shale"
    },
    {
      "x": -4,
      "y": 5,
      "z": 10,
      "name": "Rock_Shale"
    },
    {
      "x": -4,
      "y": 6,
      "z": 10,
      "name": "Rock_Shale"
    },
    {
      "x": -4,
      "y": 7,
      "z": 10,
      "name": "Rock_Shale"
    },
    {
      "x": -4,
      "y": 8,
      "z": 10,
      "name": "Rock_Shale"
    },
    {
      "x": -4,
      "y": 9,
      "z": 10,
      "name": "Rock_Shale_Brick"
    },
    {
      "x": -4,
      "y": 10,
      "z": 10,
      "name": "Rock_Shale_Brick"
    },
    {
      "x": -4,
      "y": 11,
      "z": 10,
      "name": "Rock_Shale_Brick"
    },
    {
      "x": -4,
      "y": 12,
      "z": 10,
      "name": "Rock_Shale_Cobble_Half",
      "rotation": 6
    },
    {
      "x": -4,
      "y": 13,
      "z": 10,
      "name": "Rock_Shale_Cobble_Stairs",
      "rotation": 8
    },
    {
      "x": -4,
      "y": 14,
      "z": 10,
      "name": "Rock_Shale_Cobble"
    },
    {
      "x": -4,
      "y": 15,
      "z": 10,
      "name": "Rock_Shale_Cobble"
    },
    {
      "x": -4,
      "y": 16,
      "z": 10,
      "name": "Soil_Snow"
    },
    {
      "x": -4,
      "y": 0,
      "z": 11,
      "name": "Rock_Shale"
    },
    {
      "x": -4,
      "y": 1,
      "z": 11,
      "name": "Rock_Shale"
    },
    {
      "x": -4,
      "y": 2,
      "z": 11,
      "name": "Rock_Shale"
    },
    {
      "x": -4,
      "y": 3,
      "z": 11,
      "name": "Rock_Shale"
    },
    {
      "x": -4,
      "y": 4,
      "z": 11,
      "name": "Rock_Shale"
    },
    {
      "x": -4,
      "y": 5,
      "z": 11,
      "name": "Rock_Shale"
    },
    {
      "x": -4,
      "y": 6,
      "z": 11,
      "name": "Rock_Shale"
    },
    {
      "x": -4,
      "y": 7,
      "z": 11,
      "name": "Rock_Shale"
    },
    {
      "x": -4,
      "y": 8,
      "z": 11,
      "name": "Rock_Shale"
    },
    {
      "x": -4,
      "y": 9,
      "z": 11,
      "name": "Rock_Shale_Cobble"
    },
    {
      "x": -4,
      "y": 10,
      "z": 11,
      "name": "Rock_Shale_Cobble"
    },
    {
      "x": -4,
      "y": 11,
      "z": 11,
      "name": "Rock_Shale_Cobble"
    },
    {
      "x": -4,
      "y": 12,
      "z": 11,
      "name": "Rock_Shale_Cobble"
    },
    {
      "x": -4,
      "y": 13,
      "z": 11,
      "name": "Rock_Shale_Cobble"
    },
    {
      "x": -4,
      "y": 14,
      "z": 11,
      "name": "Rock_Shale_Cobble"
    },
    {
      "x": -4,
      "y": 15,
      "z": 11,
      "name": "Rock_Shale_Cobble"
    },
    {
      "x": -4,
      "y": 16,
      "z": 11,
      "name": "Rock_Basalt_Cobble"
    },
    {
      "x": -4,
      "y": 0,
      "z": 12,
      "name": "Rock_Shale"
    },
    {
      "x": -4,
      "y": 1,
      "z": 12,
      "name": "Rock_Shale"
    },
    {
      "x": -4,
      "y": 2,
      "z": 12,
      "name": "Rock_Shale"
    },
    {
      "x": -4,
      "y": 3,
      "z": 12,
      "name": "Rock_Shale"
    },
    {
      "x": -4,
      "y": 4,
      "z": 12,
      "name": "Rock_Shale"
    },
    {
      "x": -4,
      "y": 5,
      "z": 12,
      "name": "Rock_Shale"
    },
    {
      "x": -4,
      "y": 6,
      "z": 12,
      "name": "Rock_Shale"
    },
    {
      "x": -4,
      "y": 7,
      "z": 12,
      "name": "Rock_Shale_Brick"
    },
    {
      "x": -4,
      "y": 8,
      "z": 12,
      "name": "Rock_Shale_Brick"
    },
    {
      "x": -4,
      "y": 9,
      "z": 12,
      "name": "Rock_Shale_Brick"
    },
    {
      "x": -4,
      "y": 10,
      "z": 12,
      "name": "Rock_Shale_Brick"
    },
    {
      "x": -4,
      "y": 11,
      "z": 12,
      "name": "Rock_Shale_Brick"
    },
    {
      "x": -4,
      "y": 12,
      "z": 12,
      "name": "Rock_Shale_Brick"
    },
    {
      "x": -4,
      "y": 13,
      "z": 12,
      "name": "Rock_Shale_Brick"
    },
    {
      "x": -4,
      "y": 14,
      "z": 12,
      "name": "Rock_Shale_Brick"
    },
    {
      "x": -4,
      "y": 15,
      "z": 12,
      "name": "Rock_Shale_Brick"
    },
    {
      "x": -4,
      "y": 16,
      "z": 12,
      "name": "Rock_Shale_Brick"
    },
    {
      "x": -4,
      "y": 17,
      "z": 12,
      "name": "Rock_Basalt_Cobble"
    },
    {
      "x": -4,
      "y": 18,
      "z": 12,
      "name": "Rock_Basalt_Cobble"
    },
    {
      "x": -4,
      "y": 19,
      "z": 12,
      "name": "Rock_Shale_Brick"
    },
    {
      "x": -4,
      "y": 20,
      "z": 12,
      "name": "Soil_Snow"
    },
    {
      "x": -4,
      "y": 21,
      "z": 12,
      "name": "Rubble_Ice"
    },
    {
      "x": -4,
      "y": 1,
      "z": 13,
      "name": "Rock_Shale"
    },
    {
      "x": -4,
      "y": 2,
      "z": 13,
      "name": "Rock_Shale"
    },
    {
      "x": -4,
      "y": 3,
      "z": 13,
      "name": "Rock_Shale"
    },
    {
      "x": -4,
      "y": 4,
      "z": 13,
      "name": "Rock_Shale"
    },
    {
      "x": -4,
      "y": 5,
      "z": 13,
      "name": "Rock_Shale"
    },
    {
      "x": -4,
      "y": 6,
      "z": 13,
      "name": "Rock_Shale"
    },
    {
      "x": -4,
      "y": 7,
      "z": 13,
      "name": "Rock_Shale"
    },
    {
      "x": -4,
      "y": 8,
      "z": 13,
      "name": "Rock_Shale"
    },
    {
      "x": -4,
      "y": 9,
      "z": 13,
      "name": "Rock_Shale"
    },
    {
      "x": -4,
      "y": 10,
      "z": 13,
      "name": "Rock_Shale"
    },
    {
      "x": -4,
      "y": 11,
      "z": 13,
      "name": "Rock_Shale"
    },
    {
      "x": -4,
      "y": 12,
      "z": 13,
      "name": "Rock_Shale"
    },
    {
      "x": -4,
      "y": 13,
      "z": 13,
      "name": "Rock_Shale"
    },
    {
      "x": -4,
      "y": 14,
      "z": 13,
      "name": "Rock_Shale"
    },
    {
      "x": -4,
      "y": 15,
      "z": 13,
      "name": "Rock_Shale"
    },
    {
      "x": -4,
      "y": 16,
      "z": 13,
      "name": "Rock_Shale"
    },
    {
      "x": -4,
      "y": 17,
      "z": 13,
      "name": "Rock_Shale"
    },
    {
      "x": -4,
      "y": 18,
      "z": 13,
      "name": "Rock_Shale"
    },
    {
      "x": -4,
      "y": 19,
      "z": 13,
      "name": "Rock_Shale"
    },
    {
      "x": -4,
      "y": 20,
      "z": 13,
      "name": "Soil_Snow"
    },
    {
      "x": -4,
      "y": 4,
      "z": 14,
      "name": "Rock_Shale_Cobble"
    },
    {
      "x": -4,
      "y": 5,
      "z": 14,
      "name": "Rock_Shale_Cobble"
    },
    {
      "x": -4,
      "y": 6,
      "z": 14,
      "name": "Rock_Shale_Cobble"
    },
    {
      "x": -4,
      "y": 7,
      "z": 14,
      "name": "Rock_Shale_Brick"
    },
    {
      "x": -4,
      "y": 8,
      "z": 14,
      "name": "Rock_Shale_Brick"
    },
    {
      "x": -4,
      "y": 9,
      "z": 14,
      "name": "Rock_Shale_Brick"
    },
    {
      "x": -4,
      "y": 10,
      "z": 14,
      "name": "Rock_Shale_Brick"
    },
    {
      "x": -4,
      "y": 11,
      "z": 14,
      "name": "Rock_Shale_Brick"
    },
    {
      "x": -4,
      "y": 12,
      "z": 14,
      "name": "Rock_Shale_Brick"
    },
    {
      "x": -4,
      "y": 13,
      "z": 14,
      "name": "Rock_Shale_Brick"
    },
    {
      "x": -4,
      "y": 14,
      "z": 14,
      "name": "Rock_Shale_Brick"
    },
    {
      "x": -4,
      "y": 15,
      "z": 14,
      "name": "Rock_Shale_Brick"
    },
    {
      "x": -4,
      "y": 16,
      "z": 14,
      "name": "Rock_Shale_Cobble_Stairs",
      "rotation": 10
    },
    {
      "x": -4,
      "y": 17,
      "z": 14,
      "name": "Rock_Shale_Brick"
    },
    {
      "x": -4,
      "y": 18,
      "z": 14,
      "name": "Rock_Shale_Brick"
    },
    {
      "x": -4,
      "y": 19,
      "z": 14,
      "name": "Soil_Snow"
    },
    {
      "x": -4,
      "y": 17,
      "z": 15,
      "name": "Rock_Shale_Brick"
    },
    {
      "x": -4,
      "y": 18,
      "z": 15,
      "name": "Rock_Shale_Brick"
    },
    {
      "x": -3,
      "y": 3,
      "z": 10,
      "name": "Rock_Shale"
    },
    {
      "x": -3,
      "y": 4,
      "z": 10,
      "name": "Rock_Shale"
    },
    {
      "x": -3,
      "y": 5,
      "z": 10,
      "name": "Rock_Shale"
    },
    {
      "x": -3,
      "y": 6,
      "z": 10,
      "name": "Rock_Shale"
    },
    {
      "x": -3,
      "y": 7,
      "z": 10,
      "name": "Rock_Shale"
    },
    {
      "x": -3,
      "y": 8,
      "z": 10,
      "name": "Rock_Shale"
    },
    {
      "x": -3,
      "y": 9,
      "z": 10,
      "name": "Rock_Shale_Brick_Half",
      "rotation": 6
    },
    {
      "x": -3,
      "y": 10,
      "z": 10,
      "name": "Rock_Shale_Brick"
    },
    {
      "x": -3,
      "y": 11,
      "z": 10,
      "name": "Rock_Shale_Brick"
    },
    {
      "x": -3,
      "y": 12,
      "z": 10,
      "name": "Rock_Shale_Cobble"
    },
    {
      "x": -3,
      "y": 13,
      "z": 10,
      "name": "Rock_Shale_Cobble"
    },
    {
      "x": -3,
      "y": 14,
      "z": 10,
      "name": "Rock_Shale_Cobble"
    },
    {
      "x": -3,
      "y": 15,
      "z": 10,
      "name": "Rock_Shale_Cobble"
    },
    {
      "x": -3,
      "y": 16,
      "z": 10,
      "name": "Rock_Basalt_Cobble"
    },
    {
      "x": -3,
      "y": 1,
      "z": 11,
      "name": "Rock_Shale"
    },
    {
      "x": -3,
      "y": 2,
      "z": 11,
      "name": "Rock_Shale"
    },
    {
      "x": -3,
      "y": 3,
      "z": 11,
      "name": "Rock_Shale"
    },
    {
      "x": -3,
      "y": 4,
      "z": 11,
      "name": "Rock_Shale"
    },
    {
      "x": -3,
      "y": 5,
      "z": 11,
      "name": "Rock_Shale"
    },
    {
      "x": -3,
      "y": 6,
      "z": 11,
      "name": "Rock_Shale"
    },
    {
      "x": -3,
      "y": 7,
      "z": 11,
      "name": "Rock_Shale"
    },
    {
      "x": -3,
      "y": 8,
      "z": 11,
      "name": "Rock_Shale_Cobble"
    },
    {
      "x": -3,
      "y": 9,
      "z": 11,
      "name": "Rock_Shale_Cobble"
    },
    {
      "x": -3,
      "y": 10,
      "z": 11,
      "name": "Rock_Shale_Cobble"
    },
    {
      "x": -3,
      "y": 11,
      "z": 11,
      "name": "Rock_Shale_Cobble"
    },
    {
      "x": -3,
      "y": 12,
      "z": 11,
      "name": "Rock_Shale_Cobble"
    },
    {
      "x": -3,
      "y": 13,
      "z": 11,
      "name": "Rock_Shale_Cobble"
    },
    {
      "x": -3,
      "y": 14,
      "z": 11,
      "name": "Rock_Shale_Cobble"
    },
    {
      "x": -3,
      "y": 15,
      "z": 11,
      "name": "Rock_Shale_Cobble"
    },
    {
      "x": -3,
      "y": 16,
      "z": 11,
      "name": "Rock_Basalt_Cobble"
    },
    {
      "x": -3,
      "y": 1,
      "z": 12,
      "name": "Rock_Shale"
    },
    {
      "x": -3,
      "y": 2,
      "z": 12,
      "name": "Rock_Shale"
    },
    {
      "x": -3,
      "y": 3,
      "z": 12,
      "name": "Rock_Shale"
    },
    {
      "x": -3,
      "y": 4,
      "z": 12,
      "name": "Rock_Shale"
    },
    {
      "x": -3,
      "y": 5,
      "z": 12,
      "name": "Rock_Shale"
    },
    {
      "x": -3,
      "y": 6,
      "z": 12,
      "name": "Rock_Shale_Brick"
    },
    {
      "x": -3,
      "y": 7,
      "z": 12,
      "name": "Rock_Shale_Brick"
    },
    {
      "x": -3,
      "y": 8,
      "z": 12,
      "name": "Rock_Shale_Brick"
    },
    {
      "x": -3,
      "y": 9,
      "z": 12,
      "name": "Rock_Shale_Brick"
    },
    {
      "x": -3,
      "y": 10,
      "z": 12,
      "name": "Rock_Shale_Brick"
    },
    {
      "x": -3,
      "y": 11,
      "z": 12,
      "name": "Rock_Shale_Brick"
    },
    {
      "x": -3,
      "y": 12,
      "z": 12,
      "name": "Rock_Shale_Brick"
    },
    {
      "x": -3,
      "y": 13,
      "z": 12,
      "name": "Rock_Shale_Brick"
    },
    {
      "x": -3,
      "y": 14,
      "z": 12,
      "name": "Rock_Shale_Brick"
    },
    {
      "x": -3,
      "y": 15,
      "z": 12,
      "name": "Rock_Shale_Brick"
    },
    {
      "x": -3,
      "y": 16,
      "z": 12,
      "name": "Rock_Shale_Brick"
    },
    {
      "x": -3,
      "y": 17,
      "z": 12,
      "name": "Rock_Basalt_Cobble"
    },
    {
      "x": -3,
      "y": 18,
      "z": 12,
      "name": "Rock_Basalt_Cobble"
    },
    {
      "x": -3,
      "y": 19,
      "z": 12,
      "name": "Rock_Shale_Brick"
    },
    {
      "x": -3,
      "y": 20,
      "z": 12,
      "name": "Soil_Snow"
    },
    {
      "x": -3,
      "y": 21,
      "z": 12,
      "name": "Plant_Bush_Winter_Snow"
    },
    {
      "x": -3,
      "y": 1,
      "z": 13,
      "name": "Rock_Shale"
    },
    {
      "x": -3,
      "y": 2,
      "z": 13,
      "name": "Rock_Shale"
    },
    {
      "x": -3,
      "y": 3,
      "z": 13,
      "name": "Rock_Shale"
    },
    {
      "x": -3,
      "y": 4,
      "z": 13,
      "name": "Rock_Shale"
    },
    {
      "x": -3,
      "y": 5,
      "z": 13,
      "name": "Rock_Shale"
    },
    {
      "x": -3,
      "y": 6,
      "z": 13,
      "name": "Rock_Shale"
    },
    {
      "x": -3,
      "y": 7,
      "z": 13,
      "name": "Rock_Shale"
    },
    {
      "x": -3,
      "y": 8,
      "z": 13,
      "name": "Rock_Shale"
    },
    {
      "x": -3,
      "y": 9,
      "z": 13,
      "name": "Rock_Shale"
    },
    {
      "x": -3,
      "y": 10,
      "z": 13,
      "name": "Rock_Shale"
    },
    {
      "x": -3,
      "y": 11,
      "z": 13,
      "name": "Rock_Shale"
    },
    {
      "x": -3,
      "y": 12,
      "z": 13,
      "name": "Rock_Shale"
    },
    {
      "x": -3,
      "y": 13,
      "z": 13,
      "name": "Rock_Shale"
    },
    {
      "x": -3,
      "y": 14,
      "z": 13,
      "name": "Rock_Shale"
    },
    {
      "x": -3,
      "y": 15,
      "z": 13,
      "name": "Rock_Shale"
    },
    {
      "x": -3,
      "y": 16,
      "z": 13,
      "name": "Rock_Shale"
    },
    {
      "x": -3,
      "y": 17,
      "z": 13,
      "name": "Rock_Shale"
    },
    {
      "x": -3,
      "y": 18,
      "z": 13,
      "name": "Rock_Basalt_Cobble"
    },
    {
      "x": -3,
      "y": 19,
      "z": 13,
      "name": "Rock_Shale"
    },
    {
      "x": -3,
      "y": 20,
      "z": 13,
      "name": "Soil_Snow"
    },
    {
      "x": -3,
      "y": 4,
      "z": 14,
      "name": "Rock_Shale_Cobble_Half",
      "rotation": 4
    },
    {
      "x": -3,
      "y": 5,
      "z": 14,
      "name": "Rock_Shale_Cobble_Half",
      "rotation": 4
    },
    {
      "x": -3,
      "y": 6,
      "z": 14,
      "name": "Rock_Shale_Cobble"
    },
    {
      "x": -3,
      "y": 7,
      "z": 14,
      "name": "Rock_Shale_Cobble"
    },
    {
      "x": -3,
      "y": 8,
      "z": 14,
      "name": "Rock_Shale_Brick"
    },
    {
      "x": -3,
      "y": 9,
      "z": 14,
      "name": "Rock_Shale_Brick"
    },
    {
      "x": -3,
      "y": 10,
      "z": 14,
      "name": "Rock_Shale_Brick"
    },
    {
      "x": -3,
      "y": 11,
      "z": 14,
      "name": "Rock_Shale_Brick"
    },
    {
      "x": -3,
      "y": 12,
      "z": 14,
      "name": "Rock_Shale_Brick"
    },
    {
      "x": -3,
      "y": 13,
      "z": 14,
      "name": "Rock_Shale_Brick"
    },
    {
      "x": -3,
      "y": 14,
      "z": 14,
      "name": "Rock_Shale_Brick"
    },
    {
      "x": -3,
      "y": 15,
      "z": 14,
      "name": "Rock_Shale_Cobble_Half",
      "rotation": 4
    },
    {
      "x": -3,
      "y": 16,
      "z": 14,
      "name": "Rock_Shale_Cobble_Half",
      "rotation": 4
    },
    {
      "x": -3,
      "y": 17,
      "z": 14,
      "name": "Rock_Shale_Brick"
    },
    {
      "x": -3,
      "y": 18,
      "z": 14,
      "name": "Rock_Basalt_Cobble"
    },
    {
      "x": -3,
      "y": 19,
      "z": 14,
      "name": "Rock_Shale_Brick"
    },
    {
      "x": -3,
      "y": 20,
      "z": 14,
      "name": "Soil_Snow"
    },
    {
      "x": -3,
      "y": 17,
      "z": 15,
      "name": "Rock_Shale_Brick"
    },
    {
      "x": -3,
      "y": 18,
      "z": 15,
      "name": "Rock_Shale_Brick"
    },
    {
      "x": -2,
      "y": 2,
      "z": 10,
      "name": "Rock_Shale"
    },
    {
      "x": -2,
      "y": 3,
      "z": 10,
      "name": "Rock_Shale"
    },
    {
      "x": -2,
      "y": 4,
      "z": 10,
      "name": "Rock_Shale"
    },
    {
      "x": -2,
      "y": 5,
      "z": 10,
      "name": "Rock_Shale"
    },
    {
      "x": -2,
      "y": 6,
      "z": 10,
      "name": "Rock_Shale"
    },
    {
      "x": -2,
      "y": 7,
      "z": 10,
      "name": "Rock_Shale"
    },
    {
      "x": -2,
      "y": 8,
      "z": 10,
      "name": "Rock_Shale_Brick_Stairs",
      "rotation": 2
    },
    {
      "x": -2,
      "y": 9,
      "z": 10,
      "name": "Rock_Shale_Brick_Half",
      "rotation": 6
    },
    {
      "x": -2,
      "y": 10,
      "z": 10,
      "name": "Rock_Shale_Brick_Half",
      "rotation": 6
    },
    {
      "x": -2,
      "y": 11,
      "z": 10,
      "name": "Rock_Shale_Cobble"
    },
    {
      "x": -2,
      "y": 12,
      "z": 10,
      "name": "Rock_Shale_Cobble"
    },
    {
      "x": -2,
      "y": 13,
      "z": 10,
      "name": "Rock_Shale_Cobble"
    },
    {
      "x": -2,
      "y": 14,
      "z": 10,
      "name": "Rock_Shale_Cobble"
    },
    {
      "x": -2,
      "y": 15,
      "z": 10,
      "name": "Rock_Shale_Cobble"
    },
    {
      "x": -2,
      "y": 16,
      "z": 10,
      "name": "Rock_Shale_Cobble_Half"
    },
    {
      "x": -2,
      "y": 1,
      "z": 11,
      "name": "Rock_Shale"
    },
    {
      "x": -2,
      "y": 2,
      "z": 11,
      "name": "Rock_Shale"
    },
    {
      "x": -2,
      "y": 3,
      "z": 11,
      "name": "Rock_Shale"
    },
    {
      "x": -2,
      "y": 4,
      "z": 11,
      "name": "Rock_Shale"
    },
    {
      "x": -2,
      "y": 5,
      "z": 11,
      "name": "Rock_Shale"
    },
    {
      "x": -2,
      "y": 6,
      "z": 11,
      "name": "Rock_Shale"
    },
    {
      "x": -2,
      "y": 7,
      "z": 11,
      "name": "Rock_Shale_Cobble"
    },
    {
      "x": -2,
      "y": 8,
      "z": 11,
      "name": "Rock_Shale_Cobble"
    },
    {
      "x": -2,
      "y": 9,
      "z": 11,
      "name": "Rock_Shale_Cobble"
    },
    {
      "x": -2,
      "y": 10,
      "z": 11,
      "name": "Rock_Shale_Cobble"
    },
    {
      "x": -2,
      "y": 11,
      "z": 11,
      "name": "Rock_Shale_Cobble"
    },
    {
      "x": -2,
      "y": 12,
      "z": 11,
      "name": "Rock_Shale_Cobble"
    },
    {
      "x": -2,
      "y": 13,
      "z": 11,
      "name": "Rock_Shale_Cobble"
    },
    {
      "x": -2,
      "y": 14,
      "z": 11,
      "name": "Rock_Shale_Cobble"
    },
    {
      "x": -2,
      "y": 15,
      "z": 11,
      "name": "Rock_Shale_Cobble"
    },
    {
      "x": -2,
      "y": 16,
      "z": 11,
      "name": "Rock_Basalt_Cobble"
    },
    {
      "x": -2,
      "y": 1,
      "z": 12,
      "name": "Rock_Shale"
    },
    {
      "x": -2,
      "y": 2,
      "z": 12,
      "name": "Rock_Shale"
    },
    {
      "x": -2,
      "y": 3,
      "z": 12,
      "name": "Rock_Shale"
    },
    {
      "x": -2,
      "y": 4,
      "z": 12,
      "name": "Rock_Shale"
    },
    {
      "x": -2,
      "y": 5,
      "z": 12,
      "name": "Rock_Shale_Cobble"
    },
    {
      "x": -2,
      "y": 6,
      "z": 12,
      "name": "Rock_Shale_Brick"
    },
    {
      "x": -2,
      "y": 7,
      "z": 12,
      "name": "Rock_Shale_Brick"
    },
    {
      "x": -2,
      "y": 8,
      "z": 12,
      "name": "Rock_Shale_Brick"
    },
    {
      "x": -2,
      "y": 9,
      "z": 12,
      "name": "Rock_Shale_Brick"
    },
    {
      "x": -2,
      "y": 10,
      "z": 12,
      "name": "Rock_Shale_Brick"
    },
    {
      "x": -2,
      "y": 11,
      "z": 12,
      "name": "Rock_Shale_Brick"
    },
    {
      "x": -2,
      "y": 12,
      "z": 12,
      "name": "Rock_Shale_Brick"
    },
    {
      "x": -2,
      "y": 13,
      "z": 12,
      "name": "Rock_Shale_Brick"
    },
    {
      "x": -2,
      "y": 14,
      "z": 12,
      "name": "Rock_Shale_Brick"
    },
    {
      "x": -2,
      "y": 15,
      "z": 12,
      "name": "Rock_Shale_Brick"
    },
    {
      "x": -2,
      "y": 16,
      "z": 12,
      "name": "Rock_Shale_Brick"
    },
    {
      "x": -2,
      "y": 17,
      "z": 12,
      "name": "Rock_Shale_Brick_Half"
    },
    {
      "x": -2,
      "y": 1,
      "z": 13,
      "name": "Rock_Shale"
    },
    {
      "x": -2,
      "y": 2,
      "z": 13,
      "name": "Rock_Shale"
    },
    {
      "x": -2,
      "y": 3,
      "z": 13,
      "name": "Rock_Shale"
    },
    {
      "x": -2,
      "y": 4,
      "z": 13,
      "name": "Rock_Shale"
    },
    {
      "x": -2,
      "y": 5,
      "z": 13,
      "name": "Rock_Shale"
    },
    {
      "x": -2,
      "y": 6,
      "z": 13,
      "name": "Rock_Shale"
    },
    {
      "x": -2,
      "y": 7,
      "z": 13,
      "name": "Rock_Shale"
    },
    {
      "x": -2,
      "y": 8,
      "z": 13,
      "name": "Rock_Shale"
    },
    {
      "x": -2,
      "y": 9,
      "z": 13,
      "name": "Rock_Shale"
    },
    {
      "x": -2,
      "y": 10,
      "z": 13,
      "name": "Rock_Shale"
    },
    {
      "x": -2,
      "y": 11,
      "z": 13,
      "name": "Rock_Shale"
    },
    {
      "x": -2,
      "y": 12,
      "z": 13,
      "name": "Rock_Shale"
    },
    {
      "x": -2,
      "y": 13,
      "z": 13,
      "name": "Rock_Shale"
    },
    {
      "x": -2,
      "y": 14,
      "z": 13,
      "name": "Rock_Shale"
    },
    {
      "x": -2,
      "y": 15,
      "z": 13,
      "name": "Rock_Shale"
    },
    {
      "x": -2,
      "y": 16,
      "z": 13,
      "name": "Rock_Shale"
    },
    {
      "x": -2,
      "y": 17,
      "z": 13,
      "name": "Rock_Basalt_Cobble"
    },
    {
      "x": -2,
      "y": 4,
      "z": 14,
      "name": "Rock_Shale_Cobble_Half",
      "rotation": 4
    },
    {
      "x": -2,
      "y": 5,
      "z": 14,
      "name": "Rock_Shale"
    },
    {
      "x": -2,
      "y": 6,
      "z": 14,
      "name": "Rock_Shale"
    },
    {
      "x": -2,
      "y": 7,
      "z": 14,
      "name": "Rock_Shale_Cobble"
    },
    {
      "x": -2,
      "y": 8,
      "z": 14,
      "name": "Rock_Shale_Brick"
    },
    {
      "x": -2,
      "y": 9,
      "z": 14,
      "name": "Rock_Shale_Brick"
    },
    {
      "x": -2,
      "y": 10,
      "z": 14,
      "name": "Rock_Shale_Brick"
    },
    {
      "x": -2,
      "y": 11,
      "z": 14,
      "name": "Rock_Shale_Brick"
    },
    {
      "x": -2,
      "y": 12,
      "z": 14,
      "name": "Rock_Shale_Brick"
    },
    {
      "x": -2,
      "y": 13,
      "z": 14,
      "name": "Rock_Shale_Brick"
    },
    {
      "x": -2,
      "y": 14,
      "z": 14,
      "name": "Rock_Shale_Cobble_Half",
      "rotation": 4
    },
    {
      "x": -2,
      "y": 15,
      "z": 14,
      "name": "Rock_Shale_Cobble_Half",
      "rotation": 4
    },
    {
      "x": -2,
      "y": 16,
      "z": 14,
      "name": "Rock_Shale_Cobble_Half",
      "rotation": 4
    },
    {
      "x": -2,
      "y": 17,
      "z": 14,
      "name": "Rock_Basalt_Cobble"
    },
    {
      "x": -1,
      "y": 1,
      "z": -1,
      "name": "Rock_Shale_Brick_Smooth"
    },
    {
      "x": -1,
      "y": 2,
      "z": -1,
      "name": "Rock_Shale_Brick_Smooth"
    },
    {
      "x": -1,
      "y": 3,
      "z": -1,
      "name": "Rock_Shale_Brick_Smooth"
    },
    {
      "x": -1,
      "y": 4,
      "z": -1,
      "name": "Rock_Shale_Brick_Smooth"
    },
    {
      "x": -1,
      "y": 5,
      "z": -1,
      "name": "Rock_Shale_Brick_Smooth"
    },
    {
      "x": -1,
      "y": 6,
      "z": -1,
      "name": "Rock_Shale_Brick_Smooth_Half",
      "rotation": 7
    },
    {
      "x": -1,
      "y": 7,
      "z": -1,
      "name": "Rock_Shale_Brick_Smooth_Half",
      "rotation": 7
    },
    {
      "x": -1,
      "y": 8,
      "z": -1,
      "name": "Rock_Shale_Brick_Smooth_Half",
      "rotation": 7
    },
    {
      "x": -1,
      "y": 9,
      "z": -1,
      "name": "Rock_Shale_Brick_Smooth_Half",
      "rotation": 7
    },
    {
      "x": -1,
      "y": 10,
      "z": -1,
      "name": "Rock_Shale_Brick_Smooth_Half",
      "rotation": 7
    },
    {
      "x": -1,
      "y": 1,
      "z": 0,
      "name": "Rock_Shale_Brick_Smooth"
    },
    {
      "x": -1,
      "y": 2,
      "z": 0,
      "name": "Rock_Shale_Brick_Smooth"
    },
    {
      "x": -1,
      "y": 3,
      "z": 0,
      "name": "Rock_Shale_Brick_Smooth"
    },
    {
      "x": -1,
      "y": 4,
      "z": 0,
      "name": "Rock_Shale_Brick_Smooth"
    },
    {
      "x": -1,
      "y": 5,
      "z": 0,
      "name": "Rock_Shale_Brick_Smooth"
    },
    {
      "x": -1,
      "y": 6,
      "z": 0,
      "name": "Rock_Shale_Brick_Smooth_Half",
      "rotation": 7
    },
    {
      "x": -1,
      "y": 7,
      "z": 0,
      "name": "Rock_Shale_Brick_Smooth_Half",
      "rotation": 7
    },
    {
      "x": -1,
      "y": 8,
      "z": 0,
      "name": "Rock_Shale_Brick_Smooth_Half",
      "rotation": 7
    },
    {
      "x": -1,
      "y": 9,
      "z": 0,
      "name": "Rock_Shale_Brick_Smooth_Half",
      "rotation": 7
    },
    {
      "x": -1,
      "y": 10,
      "z": 0,
      "name": "Rock_Shale_Brick_Smooth_Half",
      "rotation": 7
    },
    {
      "x": -1,
      "y": 1,
      "z": 10,
      "name": "Rock_Shale"
    },
    {
      "x": -1,
      "y": 2,
      "z": 10,
      "name": "Rock_Shale"
    },
    {
      "x": -1,
      "y": 3,
      "z": 10,
      "name": "Rock_Shale"
    },
    {
      "x": -1,
      "y": 4,
      "z": 10,
      "name": "Rock_Shale"
    },
    {
      "x": -1,
      "y": 5,
      "z": 10,
      "name": "Rock_Shale"
    },
    {
      "x": -1,
      "y": 6,
      "z": 10,
      "name": "Rock_Shale"
    },
    {
      "x": -1,
      "y": 7,
      "z": 10,
      "name": "Rock_Shale"
    },
    {
      "x": -1,
      "y": 8,
      "z": 10,
      "name": "Rock_Shale_Brick_Stairs",
      "rotation": 2
    },
    {
      "x": -1,
      "y": 9,
      "z": 10,
      "name": "Rock_Shale_Brick_Half",
      "rotation": 6
    },
    {
      "x": -1,
      "y": 10,
      "z": 10,
      "name": "Rock_Shale_Brick"
    },
    {
      "x": -1,
      "y": 11,
      "z": 10,
      "name": "Rock_Shale_Brick"
    },
    {
      "x": -1,
      "y": 12,
      "z": 10,
      "name": "Rock_Shale_Brick"
    },
    {
      "x": -1,
      "y": 13,
      "z": 10,
      "name": "Rock_Shale_Cobble"
    },
    {
      "x": -1,
      "y": 14,
      "z": 10,
      "name": "Rock_Shale_Cobble"
    },
    {
      "x": -1,
      "y": 15,
      "z": 10,
      "name": "Rock_Shale_Cobble"
    },
    {
      "x": -1,
      "y": 16,
      "z": 10,
      "name": "Rock_Shale_Cobble_Half"
    },
    {
      "x": -1,
      "y": 1,
      "z": 11,
      "name": "Rock_Shale"
    },
    {
      "x": -1,
      "y": 2,
      "z": 11,
      "name": "Rock_Shale"
    },
    {
      "x": -1,
      "y": 3,
      "z": 11,
      "name": "Rock_Shale"
    },
    {
      "x": -1,
      "y": 4,
      "z": 11,
      "name": "Rock_Shale"
    },
    {
      "x": -1,
      "y": 5,
      "z": 11,
      "name": "Rock_Shale"
    },
    {
      "x": -1,
      "y": 6,
      "z": 11,
      "name": "Rock_Shale"
    },
    {
      "x": -1,
      "y": 7,
      "z": 11,
      "name": "Rock_Shale"
    },
    {
      "x": -1,
      "y": 8,
      "z": 11,
      "name": "Rock_Shale_Cobble"
    },
    {
      "x": -1,
      "y": 9,
      "z": 11,
      "name": "Rock_Shale_Cobble"
    },
    {
      "x": -1,
      "y": 10,
      "z": 11,
      "name": "Rock_Shale_Cobble"
    },
    {
      "x": -1,
      "y": 11,
      "z": 11,
      "name": "Rock_Shale_Cobble"
    },
    {
      "x": -1,
      "y": 12,
      "z": 11,
      "name": "Rock_Shale_Cobble"
    },
    {
      "x": -1,
      "y": 13,
      "z": 11,
      "name": "Rock_Shale_Cobble"
    },
    {
      "x": -1,
      "y": 14,
      "z": 11,
      "name": "Rock_Shale_Cobble"
    },
    {
      "x": -1,
      "y": 15,
      "z": 11,
      "name": "Rock_Shale_Cobble"
    },
    {
      "x": -1,
      "y": 16,
      "z": 11,
      "name": "Rock_Shale_Brick_Smooth"
    },
    {
      "x": -1,
      "y": 1,
      "z": 12,
      "name": "Rock_Shale"
    },
    {
      "x": -1,
      "y": 2,
      "z": 12,
      "name": "Rock_Shale"
    },
    {
      "x": -1,
      "y": 3,
      "z": 12,
      "name": "Rock_Shale"
    },
    {
      "x": -1,
      "y": 4,
      "z": 12,
      "name": "Rock_Shale"
    },
    {
      "x": -1,
      "y": 5,
      "z": 12,
      "name": "Rock_Shale"
    },
    {
      "x": -1,
      "y": 6,
      "z": 12,
      "name": "Rock_Shale_Brick"
    },
    {
      "x": -1,
      "y": 7,
      "z": 12,
      "name": "Rock_Shale_Brick"
    },
    {
      "x": -1,
      "y": 8,
      "z": 12,
      "name": "Rock_Shale_Brick"
    },
    {
      "x": -1,
      "y": 9,
      "z": 12,
      "name": "Rock_Shale_Brick"
    },
    {
      "x": -1,
      "y": 10,
      "z": 12,
      "name": "Rock_Shale_Brick"
    },
    {
      "x": -1,
      "y": 11,
      "z": 12,
      "name": "Rock_Shale_Brick"
    },
    {
      "x": -1,
      "y": 12,
      "z": 12,
      "name": "Rock_Shale_Brick"
    },
    {
      "x": -1,
      "y": 13,
      "z": 12,
      "name": "Rock_Shale_Brick"
    },
    {
      "x": -1,
      "y": 14,
      "z": 12,
      "name": "Rock_Shale_Brick"
    },
    {
      "x": -1,
      "y": 15,
      "z": 12,
      "name": "Rock_Shale_Brick"
    },
    {
      "x": -1,
      "y": 16,
      "z": 12,
      "name": "Rock_Shale_Brick"
    },
    {
      "x": -1,
      "y": 17,
      "z": 12,
      "name": "Rock_Shale_Brick_Half"
    },
    {
      "x": -1,
      "y": 1,
      "z": 13,
      "name": "Rock_Shale"
    },
    {
      "x": -1,
      "y": 2,
      "z": 13,
      "name": "Rock_Shale"
    },
    {
      "x": -1,
      "y": 3,
      "z": 13,
      "name": "Rock_Shale"
    },
    {
      "x": -1,
      "y": 4,
      "z": 13,
      "name": "Rock_Shale"
    },
    {
      "x": -1,
      "y": 5,
      "z": 13,
      "name": "Rock_Shale"
    },
    {
      "x": -1,
      "y": 6,
      "z": 13,
      "name": "Rock_Shale"
    },
    {
      "x": -1,
      "y": 7,
      "z": 13,
      "name": "Rock_Shale"
    },
    {
      "x": -1,
      "y": 8,
      "z": 13,
      "name": "Rock_Shale"
    },
    {
      "x": -1,
      "y": 9,
      "z": 13,
      "name": "Rock_Shale"
    },
    {
      "x": -1,
      "y": 10,
      "z": 13,
      "name": "Rock_Shale"
    },
    {
      "x": -1,
      "y": 11,
      "z": 13,
      "name": "Rock_Shale"
    },
    {
      "x": -1,
      "y": 12,
      "z": 13,
      "name": "Rock_Shale"
    },
    {
      "x": -1,
      "y": 13,
      "z": 13,
      "name": "Rock_Shale"
    },
    {
      "x": -1,
      "y": 14,
      "z": 13,
      "name": "Rock_Shale"
    },
    {
      "x": -1,
      "y": 15,
      "z": 13,
      "name": "Rock_Shale"
    },
    {
      "x": -1,
      "y": 16,
      "z": 13,
      "name": "Rock_Shale"
    },
    {
      "x": -1,
      "y": 17,
      "z": 13,
      "name": "Rock_Basalt_Cobble"
    },
    {
      "x": -1,
      "y": 4,
      "z": 14,
      "name": "Rock_Shale"
    },
    {
      "x": -1,
      "y": 5,
      "z": 14,
      "name": "Rock_Shale"
    },
    {
      "x": -1,
      "y": 6,
      "z": 14,
      "name": "Rock_Shale"
    },
    {
      "x": -1,
      "y": 7,
      "z": 14,
      "name": "Rock_Shale_Cobble"
    },
    {
      "x": -1,
      "y": 8,
      "z": 14,
      "name": "Rock_Shale_Cobble"
    },
    {
      "x": -1,
      "y": 9,
      "z": 14,
      "name": "Rock_Shale_Brick"
    },
    {
      "x": -1,
      "y": 10,
      "z": 14,
      "name": "Rock_Shale_Brick"
    },
    {
      "x": -1,
      "y": 11,
      "z": 14,
      "name": "Rock_Shale_Brick"
    },
    {
      "x": -1,
      "y": 12,
      "z": 14,
      "name": "Rock_Shale_Brick"
    },
    {
      "x": -1,
      "y": 13,
      "z": 14,
      "name": "Rock_Shale_Cobble_Half",
      "rotation": 4
    },
    {
      "x": -1,
      "y": 14,
      "z": 14,
      "name": "Rock_Shale_Cobble_Stairs",
      "rotation": 10
    },
    {
      "x": -1,
      "y": 15,
      "z": 14,
      "name": "Rock_Shale_Cobble"
    },
    {
      "x": -1,
      "y": 16,
      "z": 14,
      "name": "Rock_Basalt_Cobble"
    },
    {
      "x": -1,
      "y": 17,
      "z": 14,
      "name": "Rock_Basalt_Cobble"
    },
    {
      "x": 0,
      "y": 1,
      "z": -1,
      "name": "Rock_Shale_Brick_Smooth"
    },
    {
      "x": 0,
      "y": 2,
      "z": -1,
      "name": "Rock_Shale_Brick_Smooth"
    },
    {
      "x": 0,
      "y": 3,
      "z": -1,
      "name": "Rock_Shale_Brick_Smooth"
    },
    {
      "x": 0,
      "y": 4,
      "z": -1,
      "name": "Rock_Shale_Brick_Smooth"
    },
    {
      "x": 0,
      "y": 5,
      "z": -1,
      "name": "Rock_Shale_Brick_Smooth"
    },
    {
      "x": 0,
      "y": 6,
      "z": -1,
      "name": "Rock_Shale_Brick_Smooth"
    },
    {
      "x": 0,
      "y": 7,
      "z": -1,
      "name": "Rock_Shale_Brick_Smooth"
    },
    {
      "x": 0,
      "y": 8,
      "z": -1,
      "name": "Rock_Shale_Brick_Smooth"
    },
    {
      "x": 0,
      "y": 9,
      "z": -1,
      "name": "Rock_Shale_Brick_Smooth"
    },
    {
      "x": 0,
      "y": 10,
      "z": -1,
      "name": "Rock_Shale_Brick_Smooth"
    },
    {
      "x": 0,
      "y": 11,
      "z": -1,
      "name": "Rock_Shale_Brick_Smooth"
    },
    {
      "x": 0,
      "y": 12,
      "z": -1,
      "name": "Rock_Shale_Brick_Smooth"
    },
    {
      "x": 0,
      "y": 13,
      "z": -1,
      "name": "Rock_Shale_Brick_Smooth"
    },
    {
      "x": 0,
      "y": 14,
      "z": -1,
      "name": "Rock_Shale_Brick_Smooth_Half",
      "rotation": 7
    },
    {
      "x": 0,
      "y": 1,
      "z": 0,
      "name": "Rock_Shale_Brick_Smooth"
    },
    {
      "x": 0,
      "y": 2,
      "z": 0,
      "name": "Rock_Shale_Brick_Smooth"
    },
    {
      "x": 0,
      "y": 3,
      "z": 0,
      "name": "Rock_Shale_Brick_Smooth"
    },
    {
      "x": 0,
      "y": 4,
      "z": 0,
      "name": "Rock_Shale_Brick_Smooth"
    },
    {
      "x": 0,
      "y": 5,
      "z": 0,
      "name": "Rock_Shale_Brick_Smooth"
    },
    {
      "x": 0,
      "y": 6,
      "z": 0,
      "name": "Rock_Shale_Brick_Smooth"
    },
    {
      "x": 0,
      "y": 7,
      "z": 0,
      "name": "Rock_Shale_Brick_Smooth"
    },
    {
      "x": 0,
      "y": 8,
      "z": 0,
      "name": "Rock_Shale_Brick_Smooth"
    },
    {
      "x": 0,
      "y": 9,
      "z": 0,
      "name": "Rock_Shale_Brick_Smooth"
    },
    {
      "x": 0,
      "y": 10,
      "z": 0,
      "name": "Rock_Shale_Brick_Smooth"
    },
    {
      "x": 0,
      "y": 11,
      "z": 0,
      "name": "Rock_Shale_Brick_Smooth"
    },
    {
      "x": 0,
      "y": 12,
      "z": 0,
      "name": "Rock_Shale_Brick_Smooth"
    },
    {
      "x": 0,
      "y": 13,
      "z": 0,
      "name": "Rock_Shale_Brick_Smooth"
    },
    {
      "x": 0,
      "y": 14,
      "z": 0,
      "name": "Rock_Shale_Brick_Smooth_Half",
      "rotation": 7
    },
    {
      "x": 0,
      "y": 1,
      "z": 10,
      "name": "Rock_Shale"
    },
    {
      "x": 0,
      "y": 2,
      "z": 10,
      "name": "Rock_Shale"
    },
    {
      "x": 0,
      "y": 3,
      "z": 10,
      "name": "Rock_Shale"
    },
    {
      "x": 0,
      "y": 4,
      "z": 10,
      "name": "Rock_Shale"
    },
    {
      "x": 0,
      "y": 5,
      "z": 10,
      "name": "Rock_Shale"
    },
    {
      "x": 0,
      "y": 6,
      "z": 10,
      "name": "Rock_Shale"
    },
    {
      "x": 0,
      "y": 7,
      "z": 10,
      "name": "Rock_Shale"
    },
    {
      "x": 0,
      "y": 8,
      "z": 10,
      "name": "Rock_Shale_Brick"
    },
    {
      "x": 0,
      "y": 9,
      "z": 10,
      "name": "Rock_Shale_Brick"
    },
    {
      "x": 0,
      "y": 10,
      "z": 10,
      "name": "Rock_Shale_Brick"
    },
    {
      "x": 0,
      "y": 11,
      "z": 10,
      "name": "Rock_Shale_Brick"
    },
    {
      "x": 0,
      "y": 12,
      "z": 10,
      "name": "Rock_Shale_Brick"
    },
    {
      "x": 0,
      "y": 13,
      "z": 10,
      "name": "Rock_Shale_Cobble_Half",
      "rotation": 6
    },
    {
      "x": 0,
      "y": 14,
      "z": 10,
      "name": "Rock_Shale_Cobble_Half",
      "rotation": 6
    },
    {
      "x": 0,
      "y": 15,
      "z": 10,
      "name": "Rock_Shale_Cobble"
    },
    {
      "x": 0,
      "y": 1,
      "z": 11,
      "name": "Rock_Shale"
    },
    {
      "x": 0,
      "y": 2,
      "z": 11,
      "name": "Rock_Shale"
    },
    {
      "x": 0,
      "y": 3,
      "z": 11,
      "name": "Rock_Shale"
    },
    {
      "x": 0,
      "y": 4,
      "z": 11,
      "name": "Rock_Shale"
    },
    {
      "x": 0,
      "y": 5,
      "z": 11,
      "name": "Rock_Shale"
    },
    {
      "x": 0,
      "y": 6,
      "z": 11,
      "name": "Rock_Shale"
    },
    {
      "x": 0,
      "y": 7,
      "z": 11,
      "name": "Rock_Shale_Cobble"
    },
    {
      "x": 0,
      "y": 8,
      "z": 11,
      "name": "Rock_Shale_Cobble"
    },
    {
      "x": 0,
      "y": 9,
      "z": 11,
      "name": "Rock_Shale_Cobble"
    },
    {
      "x": 0,
      "y": 10,
      "z": 11,
      "name": "Rock_Shale_Cobble"
    },
    {
      "x": 0,
      "y": 11,
      "z": 11,
      "name": "Rock_Shale_Cobble"
    },
    {
      "x": 0,
      "y": 12,
      "z": 11,
      "name": "Rock_Shale_Cobble"
    },
    {
      "x": 0,
      "y": 13,
      "z": 11,
      "name": "Rock_Shale_Cobble"
    },
    {
      "x": 0,
      "y": 14,
      "z": 11,
      "name": "Rock_Shale_Cobble"
    },
    {
      "x": 0,
      "y": 15,
      "z": 11,
      "name": "Rock_Shale_Cobble"
    },
    {
      "x": 0,
      "y": 16,
      "z": 11,
      "name": "Soil_Pebbles_Frozen"
    },
    {
      "x": 0,
      "y": 17,
      "z": 11,
      "name": "Empty"
    },
    {
      "x": 0,
      "y": 18,
      "z": 11,
      "name": "Empty"
    },
    {
      "x": 0,
      "y": 19,
      "z": 11,
      "name": "Empty"
    },
    {
      "x": 0,
      "y": 1,
      "z": 12,
      "name": "Rock_Shale"
    },
    {
      "x": 0,
      "y": 2,
      "z": 12,
      "name": "Rock_Shale"
    },
    {
      "x": 0,
      "y": 3,
      "z": 12,
      "name": "Rock_Shale"
    },
    {
      "x": 0,
      "y": 4,
      "z": 12,
      "name": "Rock_Shale"
    },
    {
      "x": 0,
      "y": 5,
      "z": 12,
      "name": "Rock_Shale"
    },
    {
      "x": 0,
      "y": 6,
      "z": 12,
      "name": "Rock_Shale_Brick"
    },
    {
      "x": 0,
      "y": 7,
      "z": 12,
      "name": "Rock_Shale_Brick"
    },
    {
      "x": 0,
      "y": 8,
      "z": 12,
      "name": "Rock_Shale_Brick"
    },
    {
      "x": 0,
      "y": 9,
      "z": 12,
      "name": "Rock_Shale_Brick"
    },
    {
      "x": 0,
      "y": 10,
      "z": 12,
      "name": "Rock_Shale_Brick"
    },
    {
      "x": 0,
      "y": 11,
      "z": 12,
      "name": "Rock_Shale_Brick"
    },
    {
      "x": 0,
      "y": 12,
      "z": 12,
      "name": "Rock_Shale_Brick"
    },
    {
      "x": 0,
      "y": 13,
      "z": 12,
      "name": "Rock_Shale_Brick"
    },
    {
      "x": 0,
      "y": 14,
      "z": 12,
      "name": "Rock_Shale_Brick"
    },
    {
      "x": 0,
      "y": 15,
      "z": 12,
      "name": "Rock_Shale_Brick"
    },
    {
      "x": 0,
      "y": 16,
      "z": 12,
      "name": "Rock_Shale_Brick"
    },
    {
      "x": 0,
      "y": 17,
      "z": 12,
      "name": "Rock_Shale_Brick"
    },
    {
      "x": 0,
      "y": 18,
      "z": 12,
      "name": "Empty"
    },
    {
      "x": 0,
      "y": 19,
      "z": 12,
      "name": "Empty"
    },
    {
      "x": 0,
      "y": 20,
      "z": 12,
      "name": "Empty"
    },
    {
      "x": 0,
      "y": 1,
      "z": 13,
      "name": "Rock_Shale"
    },
    {
      "x": 0,
      "y": 2,
      "z": 13,
      "name": "Rock_Shale"
    },
    {
      "x": 0,
      "y": 3,
      "z": 13,
      "name": "Rock_Shale"
    },
    {
      "x": 0,
      "y": 4,
      "z": 13,
      "name": "Rock_Shale"
    },
    {
      "x": 0,
      "y": 5,
      "z": 13,
      "name": "Rock_Shale"
    },
    {
      "x": 0,
      "y": 6,
      "z": 13,
      "name": "Rock_Shale"
    },
    {
      "x": 0,
      "y": 7,
      "z": 13,
      "name": "Rock_Shale"
    },
    {
      "x": 0,
      "y": 8,
      "z": 13,
      "name": "Rock_Shale"
    },
    {
      "x": 0,
      "y": 9,
      "z": 13,
      "name": "Rock_Shale"
    },
    {
      "x": 0,
      "y": 10,
      "z": 13,
      "name": "Rock_Shale"
    },
    {
      "x": 0,
      "y": 11,
      "z": 13,
      "name": "Rock_Shale"
    },
    {
      "x": 0,
      "y": 12,
      "z": 13,
      "name": "Rock_Shale"
    },
    {
      "x": 0,
      "y": 13,
      "z": 13,
      "name": "Rock_Shale"
    },
    {
      "x": 0,
      "y": 14,
      "z": 13,
      "name": "Rock_Shale"
    },
    {
      "x": 0,
      "y": 15,
      "z": 13,
      "name": "Rock_Shale"
    },
    {
      "x": 0,
      "y": 16,
      "z": 13,
      "name": "Rock_Shale"
    },
    {
      "x": 0,
      "y": 17,
      "z": 13,
      "name": "Rock_Basalt_Cobble"
    },
    {
      "x": 0,
      "y": 18,
      "z": 13,
      "name": "Empty"
    },
    {
      "x": 0,
      "y": 19,
      "z": 13,
      "name": "Empty"
    },
    {
      "x": 0,
      "y": 20,
      "z": 13,
      "name": "Empty"
    },
    {
      "x": 0,
      "y": 4,
      "z": 14,
      "name": "Rock_Shale"
    },
    {
      "x": 0,
      "y": 5,
      "z": 14,
      "name": "Rock_Shale"
    },
    {
      "x": 0,
      "y": 6,
      "z": 14,
      "name": "Rock_Shale"
    },
    {
      "x": 0,
      "y": 7,
      "z": 14,
      "name": "Rock_Shale"
    },
    {
      "x": 0,
      "y": 8,
      "z": 14,
      "name": "Rock_Shale"
    },
    {
      "x": 0,
      "y": 9,
      "z": 14,
      "name": "Rock_Shale_Brick"
    },
    {
      "x": 0,
      "y": 10,
      "z": 14,
      "name": "Rock_Shale_Brick"
    },
    {
      "x": 0,
      "y": 11,
      "z": 14,
      "name": "Rock_Shale_Brick"
    },
    {
      "x": 0,
      "y": 12,
      "z": 14,
      "name": "Rock_Shale_Brick"
    },
    {
      "x": 0,
      "y": 13,
      "z": 14,
      "name": "Rock_Shale_Cobble"
    },
    {
      "x": 0,
      "y": 14,
      "z": 14,
      "name": "Rock_Shale_Cobble"
    },
    {
      "x": 0,
      "y": 15,
      "z": 14,
      "name": "Rock_Shale_Cobble"
    },
    {
      "x": 0,
      "y": 16,
      "z": 14,
      "name": "Rock_Shale_Cobble"
    },
    {
      "x": 0,
      "y": 17,
      "z": 14,
      "name": "Rock_Basalt_Cobble"
    },
    {
      "x": 0,
      "y": 18,
      "z": 14,
      "name": "Empty"
    },
    {
      "x": 0,
      "y": 19,
      "z": 14,
      "name": "Empty"
    },
    {
      "x": 1,
      "y": 4,
      "z": -5,
      "name": "Rock_Shale"
    },
    {
      "x": 1,
      "y": 5,
      "z": -5,
      "name": "Rock_Shale"
    },
    {
      "x": 1,
      "y": 6,
      "z": -5,
      "name": "Rock_Shale_Cobble"
    },
    {
      "x": 1,
      "y": 7,
      "z": -5,
      "name": "Rock_Shale_Cobble"
    },
    {
      "x": 1,
      "y": 8,
      "z": -5,
      "name": "Rock_Shale_Cobble"
    },
    {
      "x": 1,
      "y": 9,
      "z": -5,
      "name": "Rock_Shale_Cobble_Half",
      "rotation": 7
    },
    {
      "x": 1,
      "y": 10,
      "z": -5,
      "name": "Rock_Shale_Cobble_Half",
      "rotation": 7
    },
    {
      "x": 1,
      "y": 11,
      "z": -5,
      "name": "Rock_Shale_Brick_Half",
      "rotation": 7
    },
    {
      "x": 1,
      "y": 12,
      "z": -5,
      "name": "Rock_Shale_Brick_Half",
      "rotation": 7
    },
    {
      "x": 1,
      "y": 13,
      "z": -5,
      "name": "Rock_Shale_Brick"
    },
    {
      "x": 1,
      "y": 14,
      "z": -5,
      "name": "Rock_Shale_Brick"
    },
    {
      "x": 1,
      "y": 15,
      "z": -5,
      "name": "Rock_Shale_Brick"
    },
    {
      "x": 1,
      "y": 16,
      "z": -5,
      "name": "Rock_Shale_Brick_Smooth"
    },
    {
      "x": 1,
      "y": 17,
      "z": -5,
      "name": "Rock_Shale_Brick_Smooth"
    },
    {
      "x": 1,
      "y": 1,
      "z": -4,
      "name": "Rock_Shale"
    },
    {
      "x": 1,
      "y": 2,
      "z": -4,
      "name": "Rock_Shale"
    },
    {
      "x": 1,
      "y": 3,
      "z": -4,
      "name": "Rock_Shale"
    },
    {
      "x": 1,
      "y": 4,
      "z": -4,
      "name": "Rock_Shale"
    },
    {
      "x": 1,
      "y": 5,
      "z": -4,
      "name": "Rock_Shale_Cobble"
    },
    {
      "x": 1,
      "y": 6,
      "z": -4,
      "name": "Rock_Shale_Cobble"
    },
    {
      "x": 1,
      "y": 7,
      "z": -4,
      "name": "Rock_Shale_Cobble"
    },
    {
      "x": 1,
      "y": 8,
      "z": -4,
      "name": "Rock_Shale_Cobble"
    },
    {
      "x": 1,
      "y": 9,
      "z": -4,
      "name": "Rock_Shale_Cobble_Half",
      "rotation": 7
    },
    {
      "x": 1,
      "y": 10,
      "z": -4,
      "name": "Rock_Shale_Brick_Half",
      "rotation": 7
    },
    {
      "x": 1,
      "y": 11,
      "z": -4,
      "name": "Rock_Shale_Brick"
    },
    {
      "x": 1,
      "y": 12,
      "z": -4,
      "name": "Rock_Shale_Brick"
    },
    {
      "x": 1,
      "y": 13,
      "z": -4,
      "name": "Rock_Shale_Cobble_Stairs",
      "rotation": 9
    },
    {
      "x": 1,
      "y": 14,
      "z": -4,
      "name": "Rock_Shale_Cobble"
    },
    {
      "x": 1,
      "y": 15,
      "z": -4,
      "name": "Rock_Shale_Brick_Half",
      "rotation": 4
    },
    {
      "x": 1,
      "y": 16,
      "z": -4,
      "name": "Rock_Shale_Brick_Half",
      "rotation": 4
    },
    {
      "x": 1,
      "y": 1,
      "z": -3,
      "name": "Rock_Shale"
    },
    {
      "x": 1,
      "y": 2,
      "z": -3,
      "name": "Rock_Shale"
    },
    {
      "x": 1,
      "y": 3,
      "z": -3,
      "name": "Rock_Shale_Cobble"
    },
    {
      "x": 1,
      "y": 4,
      "z": -3,
      "name": "Rock_Shale_Cobble"
    },
    {
      "x": 1,
      "y": 5,
      "z": -3,
      "name": "Rock_Shale_Cobble"
    },
    {
      "x": 1,
      "y": 6,
      "z": -3,
      "name": "Rock_Shale_Cobble"
    },
    {
      "x": 1,
      "y": 7,
      "z": -3,
      "name": "Rock_Shale_Cobble"
    },
    {
      "x": 1,
      "y": 8,
      "z": -3,
      "name": "Rock_Shale_Brick"
    },
    {
      "x": 1,
      "y": 9,
      "z": -3,
      "name": "Rock_Shale_Brick"
    },
    {
      "x": 1,
      "y": 10,
      "z": -3,
      "name": "Rock_Shale_Brick"
    },
    {
      "x": 1,
      "y": 11,
      "z": -3,
      "name": "Rock_Shale_Brick"
    },
    {
      "x": 1,
      "y": 12,
      "z": -3,
      "name": "Rock_Shale_Cobble_Half",
      "rotation": 7
    },
    {
      "x": 1,
      "y": 13,
      "z": -3,
      "name": "Rock_Shale_Cobble_Half",
      "rotation": 7
    },
    {
      "x": 1,
      "y": 14,
      "z": -3,
      "name": "Soil_Snow"
    },
    {
      "x": 1,
      "y": 15,
      "z": -3,
      "name": "Plant_Grass_Snowy_Short"
    },
    {
      "x": 1,
