{
  "version": 8,
  "blockIdVersion": 8,
  "anchorX": 22,
  "anchorY": 4,
  "anchorZ": 11,
  "blocks": [
    {
      "x": 14,
      "y": 12,
      "z": 13,
      "name": "Plant_Leaves_Crystal"
    },
    {
      "x": 14,
      "y": 10,
      "z": 14,
      "name": "Plant_Leaves_Crystal"
    },
    {
      "x": 14,
      "y": 11,
      "z": 14,
      "name": "Plant_Leaves_Crystal"
    },
    {
      "x": 14,
      "y": 12,
      "z": 14,
      "name": "Plant_Leaves_Crystal"
    },
    {
      "x": 15,
      "y": 12,
      "z": 12,
      "name": "Plant_Leaves_Crystal"
    },
    {
      "x": 15,
      "y": 13,
      "z": 12,
      "name": "Plant_Leaves_Crystal"
    },
    {
      "x": 15,
      "y": 11,
      "z": 13,
      "name": "Plant_Leaves_Crystal"
    },
    {
      "x": 15,
      "y": 12,
      "z": 13,
      "name": "Plant_Leaves_Crystal"
    },
    {
      "x": 15,
      "y": 13,
      "z": 13,
      "name": "Plant_Leaves_Crystal"
    },
    {
      "x": 15,
      "y": 11,
      "z": 14,
      "name": "Plant_Leaves_Crystal"
    },
    {
      "x": 15,
      "y": 12,
      "z": 14,
      "name": "Plant_Leaves_Crystal"
    },
    {
      "x": 15,
      "y": 13,
      "z": 14,
      "name": "Plant_Leaves_Crystal"
    },
    {
      "x": 15,
      "y": 14,
      "z": 14,
      "name": "Plant_Fruit_Pinkberry"
    },
    {
      "x": 15,
      "y": 12,
      "z": 15,
      "name": "Plant_Leaves_Crystal"
    },
    {
      "x": 16,
      "y": 14,
      "z": 8,
      "name": "Plant_Leaves_Crystal"
    },
    {
      "x": 16,
      "y": 15,
      "z": 8,
      "name": "Plant_Leaves_Crystal"
    },
    {
      "x": 16,
      "y": 15,
      "z": 9,
      "name": "Plant_Leaves_Crystal"
    },
    {
      "x": 16,
      "y": 16,
      "z": 9,
      "name": "Plant_Leaves_Crystal"
    },
    {
      "x": 16,
      "y": 17,
      "z": 10,
      "name": "Plant_Leaves_Crystal"
    },
    {
      "x": 16,
      "y": 13,
      "z": 11,
      "name": "Plant_Leaves_Crystal"
    },
    {
      "x": 16,
      "y": 16,
      "z": 11,
      "name": "Plant_Leaves_Crystal"
    },
    {
      "x": 16,
      "y": 17,
      "z": 11,
      "name": "Plant_Leaves_Crystal"
    },
    {
      "x": 16,
      "y": 12,
      "z": 12,
      "name": "Plant_Leaves_Crystal"
    },
    {
      "x": 16,
      "y": 13,
      "z": 12,
      "name": "Plant_Leaves_Crystal"
    },
    {
      "x": 16,
      "y": 14,
      "z": 12,
      "name": "Plant_Leaves_Crystal"
    },
    {
      "x": 16,
      "y": 17,
      "z": 12,
      "name": "Plant_Leaves_Crystal"
    },
    {
      "x": 16,
      "y": 11,
      "z": 13,
      "name": "Plant_Leaves_Crystal"
    },
    {
      "x": 16,
      "y": 12,
      "z": 13,
      "name": "Plant_Leaves_Crystal"
    },
    {
      "x": 16,
      "y": 13,
      "z": 13,
      "name": "Plant_Leaves_Crystal"
    },
    {
      "x": 16,
      "y": 14,
      "z": 13,
      "name": "Plant_Leaves_Crystal"
    },
    {
      "x": 16,
      "y": 11,
      "z": 14,
      "name": "Plant_Leaves_Crystal"
    },
    {
      "x": 16,
      "y": 12,
      "z": 14,
      "name": "Plant_Leaves_Crystal"
    },
    {
      "x": 16,
      "y": 13,
      "z": 14,
      "name": "Plant_Leaves_Crystal"
    },
    {
      "x": 16,
      "y": 12,
      "z": 15,
      "name": "Plant_Leaves_Crystal"
    },
    {
      "x": 16,
      "y": 13,
      "z": 15,
      "name": "Plant_Leaves_Crystal"
    },
    {
      "x": 17,
      "y": 8,
      "z": 6,
      "name": "Plant_Leaves_Crystal"
    },
    {
      "x": 17,
      "y": 9,
      "z": 6,
      "name": "Plant_Leaves_Crystal"
    },
    {
      "x": 17,
      "y": 10,
      "z": 6,
      "name": "Plant_Leaves_Crystal"
    },
    {
      "x": 17,
      "y": 11,
      "z": 6,
      "name": "Plant_Fruit_Pinkberry"
    },
    {
      "x": 17,
      "y": 9,
      "z": 7,
      "name": "Plant_Leaves_Crystal"
    },
    {
      "x": 17,
      "y": 10,
      "z": 7,
      "name": "Plant_Leaves_Crystal"
    },
    {
      "x": 17,
      "y": 10,
      "z": 8,
      "name": "Plant_Leaves_Crystal"
    },
    {
      "x": 17,
      "y": 11,
      "z": 8,
      "name": "Plant_Leaves_Crystal"
    },
    {
      "x": 17,
      "y": 15,
      "z": 8,
      "name": "Plant_Leaves_Crystal"
    },
    {
      "x": 17,
      "y": 16,
      "z": 8,
      "name": "Plant_Leaves_Crystal"
    },
    {
      "x": 17,
      "y": 16,
      "z": 9,
      "name": "Plant_Leaves_Crystal"
    },
    {
      "x": 17,
      "y": 17,
      "z": 9,
      "name": "Plant_Leaves_Crystal"
    },
    {
      "x": 17,
      "y": 13,
      "z": 10,
      "name": "Plant_Leaves_Crystal"
    },
    {
      "x": 17,
      "y": 16,
      "z": 10,
      "name": "Plant_Leaves_Crystal"
    },
    {
      "x": 17,
      "y": 17,
      "z": 10,
      "name": "Plant_Leaves_Crystal"
    },
    {
      "x": 17,
      "y": 18,
      "z": 10,
      "name": "Plant_Leaves_Crystal"
    },
    {
      "x": 17,
      "y": 13,
      "z": 11,
      "name": "Plant_Leaves_Crystal"
    },
    {
      "x": 17,
      "y": 14,
      "z": 11,
      "name": "Plant_Leaves_Crystal"
    },
    {
      "x": 17,
      "y": 16,
      "z": 11,
      "name": "Plant_Leaves_Crystal"
    },
    {
      "x": 17,
      "y": 17,
      "z": 11,
      "name": "Plant_Leaves_Crystal"
    },
    {
      "x": 17,
      "y": 18,
      "z": 11,
      "name": "Plant_Leaves_Crystal"
    },
    {
      "x": 17,
      "y": 12,
      "z": 12,
      "name": "Plant_Leaves_Crystal"
    },
    {
      "x": 17,
      "y": 13,
      "z": 12,
      "name": "Plant_Leaves_Crystal"
    },
    {
      "x": 17,
      "y": 14,
      "z": 12,
      "name": "Plant_Leaves_Crystal"
    },
    {
      "x": 17,
      "y": 16,
      "z": 12,
      "name": "Plant_Leaves_Crystal"
    },
    {
      "x": 17,
      "y": 17,
      "z": 12,
      "name": "Plant_Leaves_Crystal"
    },
    {
      "x": 17,
      "y": 12,
      "z": 13,
      "name": "Wood_Crystal_Trunk_Full"
    },
    {
      "x": 17,
      "y": 13,
      "z": 13,
      "name": "Plant_Leaves_Crystal"
    },
    {
      "x": 17,
      "y": 14,
      "z": 13,
      "name": "Plant_Leaves_Crystal"
    },
    {
      "x": 17,
      "y": 17,
      "z": 13,
      "name": "Plant_Leaves_Crystal"
    },
    {
      "x": 17,
      "y": 12,
      "z": 14,
      "name": "Plant_Leaves_Crystal"
    },
    {
      "x": 17,
      "y": 13,
      "z": 14,
      "name": "Plant_Leaves_Crystal"
    },
    {
      "x": 17,
      "y": 13,
      "z": 15,
      "name": "Plant_Leaves_Crystal"
    },
    {
      "x": 18,
      "y": 9,
      "z": 6,
      "name": "Plant_Leaves_Crystal"
    },
    {
      "x": 18,
      "y": 10,
      "z": 6,
      "name": "Plant_Leaves_Crystal"
    },
    {
      "x": 18,
      "y": 11,
      "z": 6,
      "name": "Plant_Leaves_Crystal"
    },
    {
      "x": 18,
      "y": 10,
      "z": 7,
      "name": "Plant_Leaves_Crystal"
    },
    {
      "x": 18,
      "y": 11,
      "z": 7,
      "name": "Plant_Leaves_Crystal"
    },
    {
      "x": 18,
      "y": 12,
      "z": 7,
      "name": "Plant_Leaves_Crystal"
    },
    {
      "x": 18,
      "y": 9,
      "z": 8,
      "name": "Plant_Leaves_Crystal"
    },
    {
      "x": 18,
      "y": 10,
      "z": 8,
      "name": "Plant_Leaves_Crystal"
    },
    {
      "x": 18,
      "y": 11,
      "z": 8,
      "name": "Plant_Leaves_Crystal"
    },
    {
      "x": 18,
      "y": 16,
      "z": 8,
      "name": "Plant_Leaves_Crystal"
    },
    {
      "x": 18,
      "y": 17,
      "z": 8,
      "name": "Plant_Leaves_Crystal"
    },
    {
      "x": 18,
      "y": 11,
      "z": 9,
      "name": "Plant_Leaves_Crystal"
    },
    {
      "x": 18,
      "y": 16,
      "z": 9,
      "name": "Plant_Leaves_Crystal"
    },
    {
      "x": 18,
      "y": 17,
      "z": 9,
      "name": "Plant_Leaves_Crystal"
    },
    {
      "x": 18,
      "y": 13,
      "z": 10,
      "name": "Plant_Leaves_Crystal"
    },
    {
      "x": 18,
      "y": 16,
      "z": 10,
      "name": "Plant_Leaves_Crystal"
    },
    {
      "x": 18,
      "y": 17,
      "z": 10,
      "name": "Plant_Leaves_Crystal"
    },
    {
      "x": 18,
      "y": 18,
      "z": 10,
      "name": "Plant_Leaves_Crystal"
    },
    {
      "x": 18,
      "y": 19,
      "z": 10,
      "name": "Plant_Fruit_Pinkberry"
    },
    {
      "x": 18,
      "y": 13,
      "z": 11,
      "name": "Plant_Leaves_Crystal"
    },
    {
      "x": 18,
      "y": 16,
      "z": 11,
      "name": "Wood_Crystal_Trunk_Full"
    },
    {
      "x": 18,
      "y": 17,
      "z": 11,
      "name": "Plant_Leaves_Crystal"
    },
    {
      "x": 18,
      "y": 18,
      "z": 11,
      "name": "Plant_Leaves_Crystal"
    },
    {
      "x": 18,
      "y": 12,
      "z": 12,
      "name": "Plant_Leaves_Crystal"
    },
    {
      "x": 18,
      "y": 13,
      "z": 12,
      "name": "Plant_Leaves_Crystal"
    },
    {
      "x": 18,
      "y": 14,
      "z": 12,
      "name": "Plant_Leaves_Crystal"
    },
    {
      "x": 18,
      "y": 16,
      "z": 12,
      "name": "Plant_Leaves_Crystal"
    },
    {
      "x": 18,
      "y": 17,
      "z": 12,
      "name": "Plant_Leaves_Crystal"
    },
    {
      "x": 18,
      "y": 18,
      "z": 12,
      "name": "Plant_Leaves_Crystal"
    },
    {
      "x": 18,
      "y": 12,
      "z": 13,
      "name": "Wood_Crystal_Trunk_Full"
    },
    {
      "x": 18,
      "y": 13,
      "z": 13,
      "name": "Plant_Leaves_Crystal"
    },
    {
      "x": 18,
      "y": 16,
      "z": 13,
      "name": "Plant_Leaves_Crystal"
    },
    {
      "x": 18,
      "y": 17,
      "z": 13,
      "name": "Plant_Leaves_Crystal"
    },
    {
      "x": 18,
      "y": 12,
      "z": 14,
      "name": "Plant_Leaves_Crystal"
    },
    {
      "x": 18,
      "y": 13,
      "z": 14,
      "name": "Plant_Leaves_Crystal"
    },
    {
      "x": 18,
      "y": 13,
      "z": 15,
      "name": "Plant_Leaves_Crystal"
    },
    {
      "x": 19,
      "y": 10,
      "z": 6,
      "name": "Plant_Leaves_Crystal"
    },
    {
      "x": 19,
      "y": 11,
      "z": 6,
      "name": "Plant_Leaves_Crystal"
    },
    {
      "x": 19,
      "y": 10,
      "z": 7,
      "name": "Plant_Leaves_Crystal"
    },
    {
      "x": 19,
      "y": 11,
      "z": 7,
      "name": "Plant_Leaves_Crystal"
    },
    {
      "x": 19,
      "y": 12,
      "z": 7,
      "name": "Plant_Leaves_Crystal"
    },
    {
      "x": 19,
      "y": 10,
      "z": 8,
      "name": "Wood_Crystal_Trunk_Full"
    },
    {
      "x": 19,
      "y": 11,
      "z": 8,
      "name": "Plant_Leaves_Crystal"
    },
    {
      "x": 19,
      "y": 12,
      "z": 8,
      "name": "Plant_Leaves_Crystal"
    },
    {
      "x": 19,
      "y": 17,
      "z": 8,
      "name": "Plant_Leaves_Crystal"
    },
    {
      "x": 19,
      "y": 10,
      "z": 9,
      "name": "Plant_Leaves_Crystal"
    },
    {
      "x": 19,
      "y": 11,
      "z": 9,
      "name": "Plant_Leaves_Crystal"
    },
    {
      "x": 19,
      "y": 17,
      "z": 9,
      "name": "Plant_Leaves_Crystal"
    },
    {
      "x": 19,
      "y": 18,
      "z": 9,
      "name": "Plant_Leaves_Crystal"
    },
    {
      "x": 19,
      "y": 17,
      "z": 10,
      "name": "Plant_Leaves_Crystal"
    },
    {
      "x": 19,
      "y": 18,
      "z": 10,
      "name": "Plant_Leaves_Crystal"
    },
    {
      "x": 19,
      "y": 13,
      "z": 11,
      "name": "Plant_Leaves_Crystal"
    },
    {
      "x": 19,
      "y": 16,
      "z": 11,
      "name": "Wood_Crystal_Trunk_Full"
    },
    {
      "x": 19,
      "y": 17,
      "z": 11,
      "name": "Plant_Leaves_Crystal"
    },
    {
      "x": 19,
      "y": 18,
      "z": 11,
      "name": "Plant_Leaves_Crystal"
    },
    {
      "x": 19,
      "y": 12,
      "z": 12,
      "name": "Wood_Crystal_Trunk_Full"
    },
    {
      "x": 19,
      "y": 13,
      "z": 12,
      "name": "Plant_Leaves_Crystal"
    },
    {
      "x": 19,
      "y": 16,
      "z": 12,
      "name": "Plant_Leaves_Crystal"
    },
    {
      "x": 19,
      "y": 17,
      "z": 12,
      "name": "Plant_Leaves_Crystal"
    },
    {
      "x": 19,
      "y": 12,
      "z": 13,
      "name": "Wood_Crystal_Trunk_Full"
    },
    {
      "x": 19,
      "y": 13,
      "z": 13,
      "name": "Plant_Leaves_Crystal"
    },
    {
      "x": 19,
      "y": 17,
      "z": 13,
      "name": "Plant_Leaves_Crystal"
    },
    {
      "x": 20,
      "y": 11,
      "z": 6,
      "name": "Plant_Leaves_Crystal"
    },
    {
      "x": 20,
      "y": 10,
      "z": 7,
      "name": "Plant_Leaves_Crystal"
    },
    {
      "x": 20,
      "y": 11,
      "z": 7,
      "name": "Plant_Leaves_Crystal"
    },
    {
      "x": 20,
      "y": 10,
      "z": 8,
      "name": "Wood_Crystal_Trunk_Full"
    },
    {
      "x": 20,
      "y": 11,
      "z": 8,
      "name": "Plant_Leaves_Crystal"
    },
    {
      "x": 20,
      "y": 10,
      "z": 9,
      "name": "Wood_Crystal_Trunk_Full"
    },
    {
      "x": 20,
      "y": 11,
      "z": 9,
      "name": "Plant_Leaves_Crystal"
    },
    {
      "x": 20,
      "y": 17,
      "z": 9,
      "name": "Plant_Leaves_Crystal"
    },
    {
      "x": 20,
      "y": 17,
      "z": 10,
      "name": "Plant_Leaves_Crystal"
    },
    {
      "x": 20,
      "y": 16,
      "z": 11,
      "name": "Wood_Crystal_Trunk_Full"
    },
    {
      "x": 20,
      "y": 17,
      "z": 11,
      "name": "Plant_Leaves_Crystal"
    },
    {
      "x": 20,
      "y": 12,
      "z": 12,
      "name": "Wood_Crystal_Trunk_Full"
    },
    {
      "x": 20,
      "y": 16,
      "z": 12,
      "name": "Wood_Crystal_Trunk_Full"
    },
    {
      "x": 20,
      "y": 17,
      "z": 12,
      "name": "Plant_Leaves_Crystal"
    },
    {
      "x": 21,
      "y": 11,
      "z": 7,
      "name": "Plant_Leaves_Crystal"
    },
    {
      "x": 21,
      "y": 11,
      "z": 8,
      "name": "Plant_Leaves_Crystal"
    },
    {
      "x": 21,
      "y": 10,
      "z": 9,
      "name": "Wood_Crystal_Trunk_Full"
    },
    {
      "x": 21,
      "y": 9,
      "z": 10,
      "name": "Plant_Leaves_Crystal"
    },
    {
      "x": 21,
      "y": 10,
      "z": 10,
      "name": "Plant_Leaves_Crystal"
    },
    {
      "x": 21,
      "y": 11,
      "z": 10,
      "name": "Plant_Leaves_Crystal"
    },
    {
      "x": 21,
      "y": 7,
      "z": 11,
      "name": "Wood_Crystal_Trunk_Full"
    },
    {
      "x": 21,
      "y": 8,
      "z": 11,
      "name": "Wood_Crystal_Trunk_Full"
    },
    {
      "x": 21,
      "y": 9,
      "z": 11,
      "name": "Wood_Crystal_Trunk_Full"
    },
    {
      "x": 21,
      "y": 10,
      "z": 11,
      "name": "Plant_Leaves_Crystal"
    },
    {
      "x": 21,
      "y": 9,
      "z": 12,
      "name": "Wood_Crystal_Trunk_Full"
    },
    {
      "x": 21,
      "y": 10,
      "z": 12,
      "name": "Wood_Crystal_Trunk_Full"
    },
    {
      "x": 21,
      "y": 11,
      "z": 12,
      "name": "Wood_Crystal_Trunk_Full"
    },
    {
      "x": 21,
      "y": 12,
      "z": 12,
      "name": "Wood_Crystal_Trunk_Full"
    },
    {
      "x": 21,
      "y": 13,
      "z": 12,
      "name": "Wood_Crystal_Trunk_Full"
    },
    {
      "x": 21,
      "y": 14,
      "z": 12,
      "name": "Wood_Crystal_Trunk_Full"
    },
    {
      "x": 21,
      "y": 15,
      "z": 12,
      "name": "Wood_Crystal_Trunk_Full"
    },
    {
      "x": 21,
      "y": 16,
      "z": 12,
      "name": "Wood_Crystal_Trunk_Full"
    },
    {
      "x": 21,
      "y": 11,
      "z": 13,
      "name": "Plant_Leaves_Crystal"
    },
    {
      "x": 21,
      "y": 11,
      "z": 14,
      "name": "Plant_Leaves_Crystal"
    },
    {
      "x": 22,
      "y": 15,
      "z": 7,
      "name": "Plant_Leaves_Crystal"
    },
    {
      "x": 22,
      "y": 15,
      "z": 8,
      "name": "Plant_Leaves_Crystal"
    },
    {
      "x": 22,
      "y": 10,
      "z": 9,
      "name": "Wood_Crystal_Trunk_Full"
    },
    {
      "x": 22,
      "y": 8,
      "z": 10,
      "name": "Wood_Crystal_Trunk_Full"
    },
    {
      "x": 22,
      "y": 9,
      "z": 10,
      "name": "Wood_Crystal_Trunk_Full"
    },
    {
      "x": 22,
      "y": 10,
      "z": 10,
      "name": "Wood_Crystal_Trunk_Full"
    },
    {
      "x": 22,
      "y": 11,
      "z": 10,
      "name": "Wood_Crystal_Trunk_Full"
    },
    {
      "x": 22,
      "y": 3,
      "z": 11,
      "name": "Wood_Crystal_Roots"
    },
    {
      "x": 22,
      "y": 4,
      "z": 11,
      "name": "Wood_Crystal_Trunk_Full"
    },
    {
      "x": 22,
      "y": 5,
      "z": 11,
      "name": "Wood_Crystal_Trunk_Full"
    },
    {
      "x": 22,
      "y": 6,
      "z": 11,
      "name": "Wood_Crystal_Trunk_Full"
    },
    {
      "x": 22,
      "y": 7,
      "z": 11,
      "name": "Wood_Crystal_Trunk_Full"
    },
    {
      "x": 22,
      "y": 8,
      "z": 11,
      "name": "Wood_Crystal_Trunk_Full"
    },
    {
      "x": 22,
      "y": 10,
      "z": 11,
      "name": "Plant_Leaves_Crystal"
    },
    {
      "x": 22,
      "y": 11,
      "z": 11,
      "name": "Plant_Leaves_Crystal"
    },
    {
      "x": 22,
      "y": 12,
      "z": 11,
      "name": "Plant_Leaves_Crystal"
    },
    {
      "x": 22,
      "y": 11,
      "z": 12,
      "name": "Plant_Leaves_Crystal"
    },
    {
      "x": 22,
      "y": 12,
      "z": 12,
      "name": "Plant_Leaves_Crystal"
    },
    {
      "x": 22,
      "y": 14,
      "z": 12,
      "name": "Wood_Crystal_Trunk_Full"
    },
    {
      "x": 22,
      "y": 15,
      "z": 12,
      "name": "Plant_Leaves_Crystal"
    },
    {
      "x": 22,
      "y": 11,
      "z": 13,
      "name": "Plant_Leaves_Crystal"
    },
    {
      "x": 22,
      "y": 12,
      "z": 13,
      "name": "Plant_Leaves_Crystal"
    },
    {
      "x": 22,
      "y": 14,
      "z": 13,
      "name": "Wood_Crystal_Trunk_Full"
    },
    {
      "x": 22,
      "y": 15,
      "z": 13,
      "name": "Plant_Leaves_Crystal"
    },
    {
      "x": 22,
      "y": 16,
      "z": 13,
      "name": "Plant_Leaves_Crystal"
    },
    {
      "x": 22,
      "y": 11,
      "z": 14,
      "name": "Plant_Leaves_Crystal"
    },
    {
      "x": 23,
      "y": 15,
      "z": 6,
      "name": "Plant_Leaves_Crystal"
    },
    {
      "x": 23,
      "y": 15,
      "z": 7,
      "name": "Plant_Leaves_Crystal"
    },
    {
      "x": 23,
      "y": 14,
      "z": 8,
      "name": "Plant_Leaves_Crystal"
    },
    {
      "x": 23,
      "y": 15,
      "z": 8,
      "name": "Plant_Leaves_Crystal"
    },
    {
      "x": 23,
      "y": 15,
      "z": 9,
      "name": "Plant_Leaves_Crystal"
    },
    {
      "x": 23,
      "y": 11,
      "z": 10,
      "name": "Wood_Crystal_Trunk_Full"
    },
    {
      "x": 23,
      "y": 12,
      "z": 10,
      "name": "Wood_Crystal_Trunk_Full"
    },
    {
      "x": 23,
      "y": 13,
      "z": 10,
      "name": "Wood_Crystal_Trunk_Full"
    },
    {
      "x": 23,
      "y": 11,
      "z": 11,
      "name": "Plant_Leaves_Crystal"
    },
    {
      "x": 23,
      "y": 12,
      "z": 11,
      "name": "Plant_Leaves_Crystal"
    },
    {
      "x": 23,
      "y": 11,
      "z": 12,
      "name": "Plant_Leaves_Crystal"
    },
    {
      "x": 23,
      "y": 15,
      "z": 12,
      "name": "Plant_Leaves_Crystal"
    },
    {
      "x": 23,
      "y": 11,
      "z": 13,
      "name": "Plant_Leaves_Crystal"
    },
    {
      "x": 23,
      "y": 12,
      "z": 13,
      "name": "Plant_Leaves_Crystal"
    },
    {
      "x": 23,
      "y": 14,
      "z": 13,
      "name": "Wood_Crystal_Trunk_Full"
    },
    {
      "x": 23,
      "y": 15,
      "z": 13,
      "name": "Wood_Crystal_Trunk_Full"
    },
    {
      "x": 23,
      "y": 16,
      "z": 13,
      "name": "Plant_Leaves_Crystal"
    },
    {
      "x": 23,
      "y": 11,
      "z": 14,
      "name": "Plant_Leaves_Crystal"
    },
    {
      "x": 23,
      "y": 15,
      "z": 14,
      "name": "Plant_Leaves_Crystal"
    },
    {
      "x": 23,
      "y": 16,
      "z": 14,
      "name": "Plant_Leaves_Crystal"
    },
    {
      "x": 23,
      "y": 17,
      "z": 14,
      "name": "Plant_Leaves_Crystal"
    },
    {
      "x": 23,
      "y": 15,
      "z": 15,
      "name": "Plant_Leaves_Crystal"
    },
    {
      "x": 23,
      "y": 16,
      "z": 15,
      "name": "Plant_Leaves_Crystal"
    },
    {
      "x": 24,
      "y": 15,
      "z": 5,
      "name": "Plant_Leaves_Crystal"
    },
    {
      "x": 24,
      "y": 14,
      "z": 6,
      "name": "Plant_Leaves_Crystal"
    },
    {
      "x": 24,
      "y": 15,
      "z": 6,
      "name": "Plant_Leaves_Crystal"
    },
    {
      "x": 24,
      "y": 14,
      "z": 7,
      "name": "Plant_Leaves_Crystal"
    },
    {
      "x": 24,
      "y": 15,
      "z": 7,
      "name": "Plant_Leaves_Crystal"
    },
    {
      "x": 24,
      "y": 16,
      "z": 7,
      "name": "Plant_Leaves_Crystal"
    },
    {
      "x": 24,
      "y": 14,
      "z": 8,
      "name": "Wood_Crystal_Trunk_Full"
    },
    {
      "x": 24,
      "y": 15,
      "z": 8,
      "name": "Plant_Leaves_Crystal"
    },
    {
      "x": 24,
      "y": 16,
      "z": 8,
      "name": "Plant_Leaves_Crystal"
    },
    {
      "x": 24,
      "y": 14,
      "z": 9,
      "name": "Wood_Crystal_Trunk_Full"
    },
    {
      "x": 24,
      "y": 15,
      "z": 9,
      "name": "Plant_Leaves_Crystal"
    },
    {
      "x": 24,
      "y": 16,
      "z": 9,
      "name": "Plant_Leaves_Crystal"
    },
    {
      "x": 24,
      "y": 13,
      "z": 10,
      "name": "Wood_Crystal_Trunk_Full"
    },
    {
      "x": 24,
      "y": 14,
      "z": 10,
      "name": "Wood_Crystal_Trunk_Full"
    },
    {
      "x": 24,
      "y": 15,
      "z": 10,
      "name": "Plant_Leaves_Crystal"
    },
    {
      "x": 24,
      "y": 11,
      "z": 11,
      "name": "Plant_Leaves_Crystal"
    },
    {
      "x": 24,
      "y": 11,
      "z": 12,
      "name": "Plant_Leaves_Crystal"
    },
    {
      "x": 24,
      "y": 15,
      "z": 12,
      "name": "Plant_Leaves_Crystal"
    },
    {
      "x": 24,
      "y": 16,
      "z": 12,
      "name": "Plant_Leaves_Crystal"
    },
    {
      "x": 24,
      "y": 11,
      "z": 13,
      "name": "Plant_Leaves_Crystal"
    },
    {
      "x": 24,
      "y": 15,
      "z": 13,
      "name": "Wood_Crystal_Trunk_Full"
    },
    {
      "x": 24,
      "y": 16,
      "z": 13,
      "name": "Plant_Leaves_Crystal"
    },
    {
      "x": 24,
      "y": 17,
      "z": 13,
      "name": "Plant_Leaves_Crystal"
    },
    {
      "x": 24,
      "y": 15,
      "z": 14,
      "name": "Wood_Crystal_Trunk_Full"
    },
    {
      "x": 24,
      "y": 16,
      "z": 14,
      "name": "Plant_Leaves_Crystal"
    },
    {
      "x": 24,
      "y": 17,
      "z": 14,
      "name": "Plant_Leaves_Crystal"
    },
    {
      "x": 24,
      "y": 18,
      "z": 14,
      "name": "Plant_Fruit_Pinkberry"
    },
    {
      "x": 24,
      "y": 15,
      "z": 15,
      "name": "Plant_Leaves_Crystal"
    },
    {
      "x": 24,
      "y": 16,
      "z": 15,
      "name": "Plant_Leaves_Crystal"
    },
    {
      "x": 24,
      "y": 15,
      "z": 16,
      "name": "Plant_Leaves_Crystal"
    },
    {
      "x": 25,
      "y": 14,
      "z": 5,
      "name": "Plant_Leaves_Crystal"
    },
    {
      "x": 25,
      "y": 15,
      "z": 5,
      "name": "Plant_Leaves_Crystal"
    },
    {
      "x": 25,
      "y": 14,
      "z": 6,
      "name": "Plant_Leaves_Crystal"
    },
    {
      "x": 25,
      "y": 15,
      "z": 6,
      "name": "Plant_Leaves_Crystal"
    },
    {
      "x": 25,
      "y": 14,
      "z": 7,
      "name": "Plant_Leaves_Crystal"
    },
    {
      "x": 25,
      "y": 15,
      "z": 7,
      "name": "Plant_Leaves_Crystal"
    },
    {
      "x": 25,
      "y": 16,
      "z": 7,
      "name": "Plant_Leaves_Crystal"
    },
    {
      "x": 25,
      "y": 14,
      "z": 8,
      "name": "Wood_Crystal_Trunk_Full"
    },
    {
      "x": 25,
      "y": 15,
      "z": 8,
      "name": "Plant_Leaves_Crystal"
    },
    {
      "x": 25,
      "y": 16,
      "z": 8,
      "name": "Plant_Fruit_Pinkberry"
    },
    {
      "x": 25,
      "y": 15,
      "z": 9,
      "name": "Plant_Leaves_Crystal"
    },
    {
      "x": 25,
      "y": 16,
      "z": 9,
      "name": "Plant_Leaves_Crystal"
    },
    {
      "x": 25,
      "y": 14,
      "z": 10,
      "name": "Plant_Leaves_Crystal"
    },
    {
      "x": 25,
      "y": 15,
      "z": 10,
      "name": "Plant_Leaves_Crystal"
    },
    {
      "x": 25,
      "y": 16,
      "z": 11,
      "name": "Plant_Leaves_Crystal"
    },
    {
      "x": 25,
      "y": 16,
      "z": 12,
      "name": "Plant_Leaves_Crystal"
    },
    {
      "x": 25,
      "y": 14,
      "z": 13,
      "name": "Plant_Leaves_Crystal"
    },
    {
      "x": 25,
      "y": 15,
      "z": 13,
      "name": "Plant_Leaves_Crystal"
    },
    {
      "x": 25,
      "y": 16,
      "z": 13,
      "name": "Plant_Leaves_Crystal"
    },
    {
      "x": 25,
      "y": 17,
      "z": 13,
      "name": "Plant_Leaves_Crystal"
    },
    {
      "x": 25,
      "y": 15,
      "z": 14,
      "name": "Wood_Crystal_Trunk_Full"
    },
    {
      "x": 25,
      "y": 16,
      "z": 14,
      "name": "Plant_Leaves_Crystal"
    },
    {
      "x": 25,
      "y": 17,
      "z": 14,
      "name": "Plant_Leaves_Crystal"
    },
    {
      "x": 25,
      "y": 15,
      "z": 15,
      "name": "Plant_Leaves_Crystal"
    },
    {
      "x": 25,
      "y": 16,
      "z": 15,
      "name": "Plant_Leaves_Crystal"
    },
    {
      "x": 25,
      "y": 15,
      "z": 16,
      "name": "Plant_Leaves_Crystal"
    },
    {
      "x": 26,
      "y": 13,
      "z": 5,
      "name": "Plant_Leaves_Crystal"
    },
    {
      "x": 26,
      "y": 14,
      "z": 5,
      "name": "Plant_Leaves_Crystal"
    },
    {
      "x": 26,
      "y": 13,
      "z": 6,
      "name": "Plant_Leaves_Crystal"
    },
    {
      "x": 26,
      "y": 14,
      "z": 6,
      "name": "Plant_Leaves_Crystal"
    },
    {
      "x": 26,
      "y": 15,
      "z": 6,
      "name": "Plant_Leaves_Crystal"
    },
    {
      "x": 26,
      "y": 14,
      "z": 7,
      "name": "Wood_Crystal_Trunk_Full"
    },
    {
      "x": 26,
      "y": 15,
      "z": 7,
      "name": "Plant_Leaves_Crystal"
    },
    {
      "x": 26,
      "y": 16,
      "z": 7,
      "name": "Plant_Leaves_Crystal"
    },
    {
      "x": 26,
      "y": 14,
      "z": 8,
      "name": "Plant_Leaves_Crystal"
    },
    {
      "x": 26,
      "y": 15,
      "z": 8,
      "name": "Plant_Leaves_Crystal"
    },
    {
      "x": 26,
      "y": 14,
      "z": 9,
      "name": "Plant_Leaves_Crystal"
    },
    {
      "x": 26,
      "y": 15,
      "z": 9,
      "name": "Plant_Leaves_Crystal"
    },
    {
      "x": 26,
      "y": 15,
      "z": 10,
      "name": "Plant_Leaves_Crystal"
    },
    {
      "x": 26,
      "y": 15,
      "z": 12,
      "name": "Plant_Leaves_Crystal"
    },
    {
      "x": 26,
      "y": 16,
      "z": 12,
      "name": "Plant_Leaves_Crystal"
    },
    {
      "x": 26,
      "y": 14,
      "z": 13,
      "name": "Plant_Leaves_Crystal"
    },
    {
      "x": 26,
      "y": 15,
      "z": 13,
      "name": "Plant_Leaves_Crystal"
    },
    {
      "x": 26,
      "y": 16,
      "z": 13,
      "name": "Plant_Leaves_Crystal"
    },
    {
      "x": 26,
      "y": 15,
      "z": 14,
      "name": "Plant_Leaves_Crystal"
    },
    {
      "x": 26,
      "y": 16,
      "z": 14,
      "name": "Plant_Leaves_Crystal"
    },
    {
      "x": 26,
      "y": 14,
      "z": 15,
      "name": "Plant_Leaves_Crystal"
    },
    {
      "x": 26,
      "y": 15,
      "z": 15,
      "name": "Plant_Leaves_Crystal"
    },
    {
      "x": 26,
      "y": 14,
      "z": 16,
      "name": "Plant_Leaves_Crystal"
    },
    {
      "x": 27,
      "y": 13,
      "z": 5,
      "name": "Plant_Leaves_Crystal"
    },
    {
      "x": 27,
      "y": 12,
      "z": 6,
      "name": "Plant_Leaves_Crystal"
    },
    {
      "x": 27,
      "y": 13,
      "z": 6,
      "name": "Plant_Leaves_Crystal"
    },
    {
      "x": 27,
      "y": 14,
      "z": 6,
      "name": "Plant_Fruit_Pinkberry"
    },
    {
      "x": 27,
      "y": 13,
      "z": 7,
      "name": "Plant_Leaves_Crystal"
    },
    {
      "x": 27,
      "y": 14,
      "z": 7,
      "name": "Plant_Leaves_Crystal"
    },
    {
      "x": 27,
      "y": 13,
      "z": 8,
      "name": "Plant_Leaves_Crystal"
    },
    {
      "x": 27,
      "y": 14,
      "z": 8,
      "name": "Plant_Leaves_Crystal"
    },
    {
      "x": 27,
      "y": 15,
      "z": 8,
      "name": "Plant_Leaves_Crystal"
    },
    {
      "x": 27,
      "y": 15,
      "z": 9,
      "name": "Plant_Leaves_Crystal"
    },
    {
      "x": 27,
      "y": 14,
      "z": 13,
      "name": "Plant_Leaves_Crystal"
    },
    {
      "x": 27,
      "y": 15,
      "z": 13,
      "name": "Plant_Leaves_Crystal"
    },
    {
      "x": 27,
      "y": 14,
      "z": 14,
      "name": "Plant_Leaves_Crystal"
    },
    {
      "x": 27,
      "y": 15,
      "z": 14,
      "name": "Plant_Leaves_Crystal"
    },
    {
      "x": 27,
      "y": 13,
      "z": 15,
      "name": "Plant_Leaves_Crystal"
    },
    {
      "x": 27,
      "y": 14,
      "z": 15,
      "name": "Plant_Leaves_Crystal"
    },
    {
      "x": 27,
      "y": 15,
      "z": 15,
      "name": "Plant_Leaves_Crystal"
    },
    {
      "x": 28,
      "y": 11,
      "z": 6,
      "name": "Plant_Leaves_Crystal"
    },
    {
      "x": 28,
      "y": 12,
      "z": 6,
      "name": "Plant_Leaves_Crystal"
    },
    {
      "x": 28,
      "y": 13,
      "z": 6,
      "name": "Plant_Leaves_Crystal"
    }
  ]
}