{
  "version": 8,
  "blockIdVersion": 8,
  "anchorX": 14,
  "anchorY": 7,
  "anchorZ": 8,
  "blocks": [
    {
      "x": 8,
      "y": 17,
      "z": 9,
      "name": "Plant_Leaves_Crystal"
    },
    {
      "x": 8,
      "y": 17,
      "z": 10,
      "name": "Plant_Leaves_Crystal"
    },
    {
      "x": 8,
      "y": 16,
      "z": 11,
      "name": "Plant_Leaves_Crystal"
    },
    {
      "x": 8,
      "y": 15,
      "z": 12,
      "name": "Plant_Leaves_Crystal"
    },
    {
      "x": 8,
      "y": 16,
      "z": 12,
      "name": "Plant_Leaves_Crystal"
    },
    {
      "x": 8,
      "y": 17,
      "z": 12,
      "name": "Plant_Fruit_Pinkberry"
    },
    {
      "x": 9,
      "y": 18,
      "z": 4,
      "name": "Plant_Leaves_Crystal"
    },
    {
      "x": 9,
      "y": 19,
      "z": 4,
      "name": "Plant_Leaves_Crystal"
    },
    {
      "x": 9,
      "y": 19,
      "z": 5,
      "name": "Plant_Leaves_Crystal"
    },
    {
      "x": 9,
      "y": 17,
      "z": 8,
      "name": "Plant_Leaves_Crystal"
    },
    {
      "x": 9,
      "y": 17,
      "z": 9,
      "name": "Plant_Leaves_Crystal"
    },
    {
      "x": 9,
      "y": 18,
      "z": 9,
      "name": "Plant_Leaves_Crystal"
    },
    {
      "x": 9,
      "y": 17,
      "z": 10,
      "name": "Plant_Leaves_Crystal"
    },
    {
      "x": 9,
      "y": 18,
      "z": 10,
      "name": "Plant_Leaves_Crystal"
    },
    {
      "x": 9,
      "y": 17,
      "z": 11,
      "name": "Plant_Leaves_Crystal"
    },
    {
      "x": 9,
      "y": 18,
      "z": 11,
      "name": "Plant_Leaves_Crystal"
    },
    {
      "x": 9,
      "y": 16,
      "z": 12,
      "name": "Plant_Leaves_Crystal"
    },
    {
      "x": 9,
      "y": 17,
      "z": 12,
      "name": "Plant_Leaves_Crystal"
    },
    {
      "x": 10,
      "y": 19,
      "z": 4,
      "name": "Plant_Leaves_Crystal"
    },
    {
      "x": 10,
      "y": 19,
      "z": 5,
      "name": "Plant_Leaves_Crystal"
    },
    {
      "x": 10,
      "y": 20,
      "z": 5,
      "name": "Plant_Leaves_Crystal"
    },
    {
      "x": 10,
      "y": 21,
      "z": 5,
      "name": "Plant_Leaves_Crystal"
    },
    {
      "x": 10,
      "y": 20,
      "z": 6,
      "name": "Plant_Leaves_Crystal"
    },
    {
      "x": 10,
      "y": 21,
      "z": 6,
      "name": "Plant_Leaves_Crystal"
    },
    {
      "x": 10,
      "y": 20,
      "z": 7,
      "name": "Plant_Leaves_Crystal"
    },
    {
      "x": 10,
      "y": 20,
      "z": 8,
      "name": "Plant_Leaves_Crystal"
    },
    {
      "x": 10,
      "y": 17,
      "z": 9,
      "name": "Wood_Crystal_Trunk_Full"
    },
    {
      "x": 10,
      "y": 18,
      "z": 9,
      "name": "Plant_Leaves_Crystal"
    },
    {
      "x": 10,
      "y": 17,
      "z": 10,
      "name": "Wood_Crystal_Trunk_Full"
    },
    {
      "x": 10,
      "y": 18,
      "z": 10,
      "name": "Plant_Leaves_Crystal"
    },
    {
      "x": 10,
      "y": 19,
      "z": 10,
      "name": "Plant_Fruit_Pinkberry"
    },
    {
      "x": 10,
      "y": 17,
      "z": 11,
      "name": "Plant_Leaves_Crystal"
    },
    {
      "x": 10,
      "y": 18,
      "z": 11,
      "name": "Plant_Leaves_Crystal"
    },
    {
      "x": 11,
      "y": 20,
      "z": 4,
      "name": "Plant_Leaves_Crystal"
    },
    {
      "x": 11,
      "y": 20,
      "z": 5,
      "name": "Plant_Leaves_Crystal"
    },
    {
      "x": 11,
      "y": 21,
      "z": 5,
      "name": "Plant_Leaves_Crystal"
    },
    {
      "x": 11,
      "y": 20,
      "z": 6,
      "name": "Plant_Leaves_Crystal"
    },
    {
      "x": 11,
      "y": 21,
      "z": 6,
      "name": "Plant_Leaves_Crystal"
    },
    {
      "x": 11,
      "y": 20,
      "z": 7,
      "name": "Wood_Crystal_Trunk_Full"
    },
    {
      "x": 11,
      "y": 21,
      "z": 7,
      "name": "Plant_Leaves_Crystal"
    },
    {
      "x": 11,
      "y": 22,
      "z": 7,
      "name": "Plant_Fruit_Pinkberry"
    },
    {
      "x": 11,
      "y": 15,
      "z": 8,
      "name": "Plant_Leaves_Crystal"
    },
    {
      "x": 11,
      "y": 20,
      "z": 8,
      "name": "Plant_Leaves_Crystal"
    },
    {
      "x": 11,
      "y": 21,
      "z": 8,
      "name": "Plant_Leaves_Crystal"
    },
    {
      "x": 11,
      "y": 17,
      "z": 9,
      "name": "Wood_Crystal_Trunk_Full"
    },
    {
      "x": 11,
      "y": 20,
      "z": 9,
      "name": "Plant_Leaves_Crystal"
    },
    {
      "x": 11,
      "y": 17,
      "z": 10,
      "name": "Plant_Leaves_Crystal"
    },
    {
      "x": 11,
      "y": 18,
      "z": 10,
      "name": "Plant_Leaves_Crystal"
    },
    {
      "x": 11,
      "y": 17,
      "z": 11,
      "name": "Plant_Leaves_Crystal"
    },
    {
      "x": 11,
      "y": 18,
      "z": 11,
      "name": "Plant_Leaves_Crystal"
    },
    {
      "x": 12,
      "y": 20,
      "z": 4,
      "name": "Plant_Leaves_Crystal"
    },
    {
      "x": 12,
      "y": 20,
      "z": 5,
      "name": "Plant_Leaves_Crystal"
    },
    {
      "x": 12,
      "y": 20,
      "z": 6,
      "name": "Plant_Leaves_Crystal"
    },
    {
      "x": 12,
      "y": 21,
      "z": 6,
      "name": "Plant_Leaves_Crystal"
    },
    {
      "x": 12,
      "y": 22,
      "z": 6,
      "name": "Plant_Fruit_Pinkberry"
    },
    {
      "x": 12,
      "y": 15,
      "z": 7,
      "name": "Plant_Leaves_Crystal"
    },
    {
      "x": 12,
      "y": 20,
      "z": 7,
      "name": "Wood_Crystal_Trunk_Full"
    },
    {
      "x": 12,
      "y": 21,
      "z": 7,
      "name": "Plant_Leaves_Crystal"
    },
    {
      "x": 12,
      "y": 15,
      "z": 8,
      "name": "Plant_Leaves_Crystal"
    },
    {
      "x": 12,
      "y": 18,
      "z": 8,
      "name": "Wood_Crystal_Trunk_Full"
    },
    {
      "x": 12,
      "y": 19,
      "z": 8,
      "name": "Wood_Crystal_Trunk_Full"
    },
    {
      "x": 12,
      "y": 20,
      "z": 8,
      "name": "Wood_Crystal_Trunk_Full"
    },
    {
      "x": 12,
      "y": 21,
      "z": 8,
      "name": "Plant_Leaves_Crystal"
    },
    {
      "x": 12,
      "y": 15,
      "z": 9,
      "name": "Plant_Leaves_Crystal"
    },
    {
      "x": 12,
      "y": 17,
      "z": 9,
      "name": "Wood_Crystal_Trunk_Full"
    },
    {
      "x": 12,
      "y": 18,
      "z": 9,
      "name": "Wood_Crystal_Trunk_Full"
    },
    {
      "x": 12,
      "y": 20,
      "z": 9,
      "name": "Plant_Leaves_Crystal"
    },
    {
      "x": 12,
      "y": 21,
      "z": 9,
      "name": "Plant_Leaves_Crystal"
    },
    {
      "x": 12,
      "y": 17,
      "z": 11,
      "name": "Plant_Leaves_Crystal"
    },
    {
      "x": 13,
      "y": 20,
      "z": 5,
      "name": "Plant_Leaves_Crystal"
    },
    {
      "x": 13,
      "y": 15,
      "z": 6,
      "name": "Plant_Leaves_Crystal"
    },
    {
      "x": 13,
      "y": 20,
      "z": 6,
      "name": "Plant_Leaves_Crystal"
    },
    {
      "x": 13,
      "y": 21,
      "z": 6,
      "name": "Plant_Leaves_Crystal"
    },
    {
      "x": 13,
      "y": 15,
      "z": 7,
      "name": "Plant_Leaves_Crystal"
    },
    {
      "x": 13,
      "y": 16,
      "z": 7,
      "name": "Plant_Leaves_Crystal"
    },
    {
      "x": 13,
      "y": 20,
      "z": 7,
      "name": "Plant_Leaves_Crystal"
    },
    {
      "x": 13,
      "y": 21,
      "z": 7,
      "name": "Plant_Leaves_Crystal"
    },
    {
      "x": 13,
      "y": 15,
      "z": 8,
      "name": "Plant_Leaves_Crystal"
    },
    {
      "x": 13,
      "y": 16,
      "z": 8,
      "name": "Plant_Leaves_Crystal"
    },
    {
      "x": 13,
      "y": 20,
      "z": 8,
      "name": "Plant_Leaves_Crystal"
    },
    {
      "x": 13,
      "y": 21,
      "z": 8,
      "name": "Plant_Leaves_Crystal"
    },
    {
      "x": 13,
      "y": 13,
      "z": 9,
      "name": "Wood_Crystal_Trunk_Full"
    },
    {
      "x": 13,
      "y": 14,
      "z": 9,
      "name": "Wood_Crystal_Trunk_Full"
    },
    {
      "x": 13,
      "y": 15,
      "z": 9,
      "name": "Wood_Crystal_Trunk_Full"
    },
    {
      "x": 13,
      "y": 16,
      "z": 9,
      "name": "Wood_Crystal_Trunk_Full"
    },
    {
      "x": 13,
      "y": 17,
      "z": 9,
      "name": "Wood_Crystal_Trunk_Full"
    },
    {
      "x": 14,
      "y": 17,
      "z": 2,
      "name": "Plant_Leaves_Crystal"
    },
    {
      "x": 14,
      "y": 17,
      "z": 3,
      "name": "Plant_Leaves_Crystal"
    },
    {
      "x": 14,
      "y": 18,
      "z": 3,
      "name": "Plant_Leaves_Crystal"
    },
    {
      "x": 14,
      "y": 18,
      "z": 4,
      "name": "Plant_Leaves_Crystal"
    },
    {
      "x": 14,
      "y": 15,
      "z": 6,
      "name": "Plant_Leaves_Crystal"
    },
    {
      "x": 14,
      "y": 20,
      "z": 6,
      "name": "Plant_Leaves_Crystal"
    },
    {
      "x": 14,
      "y": 12,
      "z": 7,
      "name": "Wood_Crystal_Trunk_Full"
    },
    {
      "x": 14,
      "y": 13,
      "z": 7,
      "name": "Wood_Crystal_Trunk_Full"
    },
    {
      "x": 14,
      "y": 14,
      "z": 7,
      "name": "Wood_Crystal_Trunk_Full"
    },
    {
      "x": 14,
      "y": 15,
      "z": 7,
      "name": "Wood_Crystal_Trunk_Full"
    },
    {
      "x": 14,
      "y": 16,
      "z": 7,
      "name": "Plant_Leaves_Crystal"
    },
    {
      "x": 14,
      "y": 20,
      "z": 7,
      "name": "Plant_Leaves_Crystal"
    },
    {
      "x": 14,
      "y": 6,
      "z": 8,
      "name": "Wood_Crystal_Roots"
    },
    {
      "x": 14,
      "y": 7,
      "z": 8,
      "name": "Wood_Crystal_Trunk_Full"
    },
    {
      "x": 14,
      "y": 8,
      "z": 8,
      "name": "Wood_Crystal_Trunk_Full"
    },
    {
      "x": 14,
      "y": 9,
      "z": 8,
      "name": "Wood_Crystal_Trunk_Full"
    },
    {
      "x": 14,
      "y": 10,
      "z": 8,
      "name": "Wood_Crystal_Trunk_Full"
    },
    {
      "x": 14,
      "y": 11,
      "z": 8,
      "name": "Wood_Crystal_Trunk_Full"
    },
    {
      "x": 14,
      "y": 12,
      "z": 8,
      "name": "Wood_Crystal_Trunk_Full"
    },
    {
      "x": 14,
      "y": 15,
      "z": 8,
      "name": "Plant_Leaves_Crystal"
    },
    {
      "x": 14,
      "y": 16,
      "z": 8,
      "name": "Plant_Leaves_Crystal"
    },
    {
      "x": 14,
      "y": 12,
      "z": 9,
      "name": "Wood_Crystal_Trunk_Full"
    },
    {
      "x": 14,
      "y": 13,
      "z": 9,
      "name": "Wood_Crystal_Trunk_Full"
    },
    {
      "x": 14,
      "y": 14,
      "z": 9,
      "name": "Wood_Crystal_Trunk_Full"
    },
    {
      "x": 14,
      "y": 15,
      "z": 9,
      "name": "Plant_Leaves_Crystal"
    },
    {
      "x": 14,
      "y": 16,
      "z": 9,
      "name": "Plant_Leaves_Crystal"
    },
    {
      "x": 14,
      "y": 15,
      "z": 10,
      "name": "Plant_Leaves_Crystal"
    },
    {
      "x": 14,
      "y": 15,
      "z": 11,
      "name": "Plant_Leaves_Crystal"
    },
    {
      "x": 15,
      "y": 17,
      "z": 2,
      "name": "Plant_Leaves_Crystal"
    },
    {
      "x": 15,
      "y": 18,
      "z": 2,
      "name": "Plant_Leaves_Crystal"
    },
    {
      "x": 15,
      "y": 17,
      "z": 3,
      "name": "Plant_Leaves_Crystal"
    },
    {
      "x": 15,
      "y": 18,
      "z": 3,
      "name": "Plant_Leaves_Crystal"
    },
    {
      "x": 15,
      "y": 17,
      "z": 4,
      "name": "Plant_Leaves_Crystal"
    },
    {
      "x": 15,
      "y": 18,
      "z": 4,
      "name": "Plant_Leaves_Crystal"
    },
    {
      "x": 15,
      "y": 17,
      "z": 5,
      "name": "Plant_Leaves_Crystal"
    },
    {
      "x": 15,
      "y": 18,
      "z": 5,
      "name": "Plant_Leaves_Crystal"
    },
    {
      "x": 15,
      "y": 16,
      "z": 6,
      "name": "Wood_Crystal_Trunk_Full"
    },
    {
      "x": 15,
      "y": 14,
      "z": 7,
      "name": "Wood_Crystal_Trunk_Full"
    },
    {
      "x": 15,
      "y": 15,
      "z": 7,
      "name": "Wood_Crystal_Trunk_Full"
    },
    {
      "x": 15,
      "y": 16,
      "z": 7,
      "name": "Wood_Crystal_Trunk_Full"
    },
    {
      "x": 15,
      "y": 14,
      "z": 8,
      "name": "Plant_Leaves_Crystal"
    },
    {
      "x": 15,
      "y": 15,
      "z": 8,
      "name": "Plant_Leaves_Crystal"
    },
    {
      "x": 15,
      "y": 16,
      "z": 8,
      "name": "Plant_Leaves_Crystal"
    },
    {
      "x": 15,
      "y": 18,
      "z": 8,
      "name": "Plant_Leaves_Crystal"
    },
    {
      "x": 15,
      "y": 14,
      "z": 9,
      "name": "Wood_Crystal_Trunk_Full"
    },
    {
      "x": 15,
      "y": 15,
      "z": 9,
      "name": "Wood_Crystal_Trunk_Full"
    },
    {
      "x": 15,
      "y": 16,
      "z": 9,
      "name": "Wood_Crystal_Trunk_Full"
    },
    {
      "x": 15,
      "y": 17,
      "z": 9,
      "name": "Wood_Crystal_Trunk_Full"
    },
    {
      "x": 15,
      "y": 18,
      "z": 9,
      "name": "Plant_Leaves_Crystal"
    },
    {
      "x": 15,
      "y": 15,
      "z": 10,
      "name": "Plant_Leaves_Crystal"
    },
    {
      "x": 15,
      "y": 17,
      "z": 10,
      "name": "Plant_Leaves_Crystal"
    },
    {
      "x": 15,
      "y": 18,
      "z": 10,
      "name": "Plant_Leaves_Crystal"
    },
    {
      "x": 15,
      "y": 15,
      "z": 11,
      "name": "Plant_Leaves_Crystal"
    },
    {
      "x": 16,
      "y": 17,
      "z": 1,
      "name": "Plant_Leaves_Crystal"
    },
    {
      "x": 16,
      "y": 16,
      "z": 2,
      "name": "Plant_Leaves_Crystal"
    },
    {
      "x": 16,
      "y": 17,
      "z": 2,
      "name": "Plant_Leaves_Crystal"
    },
    {
      "x": 16,
      "y": 18,
      "z": 2,
      "name": "Plant_Leaves_Crystal"
    },
    {
      "x": 16,
      "y": 17,
      "z": 3,
      "name": "Plant_Leaves_Crystal"
    },
    {
      "x": 16,
      "y": 18,
      "z": 3,
      "name": "Plant_Leaves_Crystal"
    },
    {
      "x": 16,
      "y": 17,
      "z": 4,
      "name": "Wood_Crystal_Trunk_Full"
    },
    {
      "x": 16,
      "y": 18,
      "z": 4,
      "name": "Plant_Leaves_Crystal"
    },
    {
      "x": 16,
      "y": 17,
      "z": 5,
      "name": "Wood_Crystal_Trunk_Full"
    },
    {
      "x": 16,
      "y": 18,
      "z": 5,
      "name": "Plant_Leaves_Crystal"
    },
    {
      "x": 16,
      "y": 17,
      "z": 6,
      "name": "Wood_Crystal_Trunk_Full"
    },
    {
      "x": 16,
      "y": 15,
      "z": 7,
      "name": "Plant_Leaves_Crystal"
    },
    {
      "x": 16,
      "y": 15,
      "z": 8,
      "name": "Plant_Leaves_Crystal"
    },
    {
      "x": 16,
      "y": 16,
      "z": 8,
      "name": "Plant_Leaves_Crystal"
    },
    {
      "x": 16,
      "y": 17,
      "z": 8,
      "name": "Plant_Leaves_Crystal"
    },
    {
      "x": 16,
      "y": 14,
      "z": 9,
      "name": "Plant_Leaves_Crystal"
    },
    {
      "x": 16,
      "y": 15,
      "z": 9,
      "name": "Plant_Leaves_Crystal"
    },
    {
      "x": 16,
      "y": 16,
      "z": 9,
      "name": "Plant_Fruit_Pinkberry"
    },
    {
      "x": 16,
      "y": 17,
      "z": 9,
      "name": "Plant_Leaves_Crystal"
    },
    {
      "x": 16,
      "y": 18,
      "z": 9,
      "name": "Plant_Leaves_Crystal"
    },
    {
      "x": 16,
      "y": 15,
      "z": 10,
      "name": "Plant_Leaves_Crystal"
    },
    {
      "x": 16,
      "y": 17,
      "z": 10,
      "name": "Plant_Leaves_Crystal"
    },
    {
      "x": 16,
      "y": 18,
      "z": 10,
      "name": "Plant_Leaves_Crystal"
    },
    {
      "x": 17,
      "y": 16,
      "z": 1,
      "name": "Plant_Leaves_Crystal"
    },
    {
      "x": 17,
      "y": 17,
      "z": 2,
      "name": "Plant_Leaves_Crystal"
    },
    {
      "x": 17,
      "y": 17,
      "z": 3,
      "name": "Plant_Leaves_Crystal"
    },
    {
      "x": 17,
      "y": 18,
      "z": 3,
      "name": "Plant_Leaves_Crystal"
    },
    {
      "x": 17,
      "y": 19,
      "z": 3,
      "name": "Plant_Fruit_Pinkberry"
    },
    {
      "x": 17,
      "y": 17,
      "z": 4,
      "name": "Plant_Leaves_Crystal"
    },
    {
      "x": 17,
      "y": 18,
      "z": 4,
      "name": "Plant_Leaves_Crystal"
    },
    {
      "x": 17,
      "y": 17,
      "z": 5,
      "name": "Plant_Leaves_Crystal"
    },
    {
      "x": 17,
      "y": 18,
      "z": 5,
      "name": "Plant_Leaves_Crystal"
    },
    {
      "x": 17,
      "y": 15,
      "z": 6,
      "name": "Plant_Leaves_Crystal"
    },
    {
      "x": 17,
      "y": 16,
      "z": 6,
      "name": "Plant_Leaves_Crystal"
    },
    {
      "x": 17,
      "y": 17,
      "z": 6,
      "name": "Plant_Leaves_Crystal"
    },
    {
      "x": 17,
      "y": 15,
      "z": 7,
      "name": "Plant_Leaves_Crystal"
    },
    {
      "x": 17,
      "y": 15,
      "z": 8,
      "name": "Plant_Leaves_Crystal"
    },
    {
      "x": 17,
      "y": 14,
      "z": 9,
      "name": "Plant_Leaves_Crystal"
    },
    {
      "x": 17,
      "y": 15,
      "z": 9,
      "name": "Plant_Leaves_Crystal"
    },
    {
      "x": 17,
      "y": 15,
      "z": 10,
      "name": "Plant_Leaves_Crystal"
    },
    {
      "x": 18,
      "y": 15,
      "z": 1,
      "name": "Plant_Leaves_Crystal"
    },
    {
      "x": 18,
      "y": 16,
      "z": 1,
      "name": "Plant_Leaves_Crystal"
    },
    {
      "x": 18,
      "y": 16,
      "z": 2,
      "name": "Plant_Leaves_Crystal"
    },
    {
      "x": 18,
      "y": 17,
      "z": 2,
      "name": "Plant_Leaves_Crystal"
    },
    {
      "x": 18,
      "y": 17,
      "z": 3,
      "name": "Plant_Leaves_Crystal"
    },
    {
      "x": 18,
      "y": 18,
      "z": 3,
      "name": "Plant_Leaves_Crystal"
    },
    {
      "x": 18,
      "y": 17,
      "z": 4,
      "name": "Plant_Leaves_Crystal"
    },
    {
      "x": 18,
      "y": 18,
      "z": 4,
      "name": "Plant_Leaves_Crystal"
    },
    {
      "x": 18,
      "y": 17,
      "z": 5,
      "name": "Plant_Leaves_Crystal"
    },
    {
      "x": 18,
      "y": 15,
      "z": 8,
      "name": "Plant_Leaves_Crystal"
    },
    {
      "x": 19,
      "y": 16,
      "z": 1,
      "name": "Plant_Leaves_Crystal"
    },
    {
      "x": 19,
      "y": 17,
      "z": 2,
      "name": "Plant_Leaves_Crystal"
    },
    {
      "x": 19,
      "y": 17,
      "z": 4,
      "name": "Plant_Leaves_Crystal"
    }
  ]
}