{
  "version": 8,
  "blockIdVersion": 8,
  "anchorX": 0,
  "anchorY": 0,
  "anchorZ": 0,
  "blocks": [
    {
      "x": -18,
      "y": 0,
      "z": -5,
      "name": "Rock_Stone"
    },
    {
      "x": -18,
      "y": 1,
      "z": -5,
      "name": "Rock_Stone"
    },
    {
      "x": -18,
      "y": 2,
      "z": -5,
      "name": "Rock_Stone"
    },
    {
      "x": -18,
      "y": 3,
      "z": -5,
      "name": "Rock_Stone"
    },
    {
      "x": -18,
      "y": 4,
      "z": -5,
      "name": "Rock_Stone"
    },
    {
      "x": -18,
      "y": 5,
      "z": -5,
      "name": "Rock_Stone"
    },
    {
      "x": -18,
      "y": 6,
      "z": -5,
      "name": "Rock_Stone"
    },
    {
      "x": -18,
      "y": 7,
      "z": -5,
      "name": "Rock_Stone"
    },
    {
      "x": -18,
      "y": 8,
      "z": -5,
      "name": "Rock_Stone"
    },
    {
      "x": -18,
      "y": 9,
      "z": -5,
      "name": "Rock_Stone"
    },
    {
      "x": -18,
      "y": 0,
      "z": -4,
      "name": "Rock_Stone"
    },
    {
      "x": -18,
      "y": 1,
      "z": -4,
      "name": "Rock_Stone_Cobble"
    },
    {
      "x": -18,
      "y": 2,
      "z": -4,
      "name": "Rock_Stone_Cobble"
    },
    {
      "x": -18,
      "y": 3,
      "z": -4,
      "name": "Empty"
    },
    {
      "x": -18,
      "y": 4,
      "z": -4,
      "name": "Rock_Stone"
    },
    {
      "x": -18,
      "y": 5,
      "z": -4,
      "name": "Rock_Stone"
    },
    {
      "x": -18,
      "y": 6,
      "z": -4,
      "name": "Rock_Stone"
    },
    {
      "x": -18,
      "y": 7,
      "z": -4,
      "name": "Rock_Stone"
    },
    {
      "x": -18,
      "y": 8,
      "z": -4,
      "name": "Rock_Stone"
    },
    {
      "x": -18,
      "y": 9,
      "z": -4,
      "name": "Rock_Stone"
    },
    {
      "x": -18,
      "y": 0,
      "z": -3,
      "name": "Rock_Stone"
    },
    {
      "x": -18,
      "y": 1,
      "z": -3,
      "name": "Empty"
    },
    {
      "x": -18,
      "y": 2,
      "z": -3,
      "name": "Empty"
    },
    {
      "x": -18,
      "y": 3,
      "z": -3,
      "name": "Empty"
    },
    {
      "x": -18,
      "y": 4,
      "z": -3,
      "name": "Empty"
    },
    {
      "x": -18,
      "y": 5,
      "z": -3,
      "name": "Empty"
    },
    {
      "x": -18,
      "y": 6,
      "z": -3,
      "name": "Wood_Softwood_Planks_Half",
      "rotation": 8
    },
    {
      "x": -18,
      "y": 7,
      "z": -3,
      "name": "Wood_Beech_Trunk",
      "rotation": 5
    },
    {
      "x": -18,
      "y": 8,
      "z": -3,
      "name": "Rock_Stone_Cobble"
    },
    {
      "x": -18,
      "y": 9,
      "z": -3,
      "name": "Rock_Stone"
    },
    {
      "x": -18,
      "y": 0,
      "z": -2,
      "name": "Rock_Stone"
    },
    {
      "x": -18,
      "y": 1,
      "z": -2,
      "name": "Empty"
    },
    {
      "x": -18,
      "y": 2,
      "z": -2,
      "name": "Empty"
    },
    {
      "x": -18,
      "y": 3,
      "z": -2,
      "name": "Empty"
    },
    {
      "x": -18,
      "y": 4,
      "z": -2,
      "name": "Empty"
    },
    {
      "x": -18,
      "y": 5,
      "z": -2,
      "name": "Empty"
    },
    {
      "x": -18,
      "y": 6,
      "z": -2,
      "name": "Empty"
    },
    {
      "x": -18,
      "y": 7,
      "z": -2,
      "name": "Rock_Stone_Cobble_Half",
      "rotation": 8
    },
    {
      "x": -18,
      "y": 8,
      "z": -2,
      "name": "Rock_Stone_Cobble"
    },
    {
      "x": -18,
      "y": 9,
      "z": -2,
      "name": "Rock_Stone"
    },
    {
      "x": -18,
      "y": 0,
      "z": -1,
      "name": "Wood_Softwood_Planks"
    },
    {
      "x": -18,
      "y": 1,
      "z": -1,
      "name": "Empty"
    },
    {
      "x": -18,
      "y": 2,
      "z": -1,
      "name": "Empty"
    },
    {
      "x": -18,
      "y": 3,
      "z": -1,
      "name": "Empty"
    },
    {
      "x": -18,
      "y": 4,
      "z": -1,
      "name": "Empty"
    },
    {
      "x": -18,
      "y": 5,
      "z": -1,
      "name": "Empty"
    },
    {
      "x": -18,
      "y": 6,
      "z": -1,
      "name": "Empty"
    },
    {
      "x": -18,
      "y": 7,
      "z": -1,
      "name": "Empty"
    },
    {
      "x": -18,
      "y": 8,
      "z": -1,
      "name": "Rock_Stone_Cobble"
    },
    {
      "x": -18,
      "y": 9,
      "z": -1,
      "name": "Rock_Stone"
    },
    {
      "x": -18,
      "y": 0,
      "z": 0,
      "name": "Wood_Beech_Trunk",
      "rotation": 5
    },
    {
      "x": -18,
      "y": 1,
      "z": 0,
      "name": "Rail",
      "rotation": 1
    },
    {
      "x": -18,
      "y": 2,
      "z": 0,
      "name": "Empty"
    },
    {
      "x": -18,
      "y": 3,
      "z": 0,
      "name": "Empty"
    },
    {
      "x": -18,
      "y": 4,
      "z": 0,
      "name": "Empty"
    },
    {
      "x": -18,
      "y": 5,
      "z": 0,
      "name": "Empty"
    },
    {
      "x": -18,
      "y": 6,
      "z": 0,
      "name": "Empty"
    },
    {
      "x": -18,
      "y": 7,
      "z": 0,
      "name": "Empty"
    },
    {
      "x": -18,
      "y": 8,
      "z": 0,
      "name": "Rock_Stone_Cobble"
    },
    {
      "x": -18,
      "y": 9,
      "z": 0,
      "name": "Rock_Stone"
    },
    {
      "x": -18,
      "y": 0,
      "z": 1,
      "name": "Soil_Gravel"
    },
    {
      "x": -18,
      "y": 1,
      "z": 1,
      "name": "Empty"
    },
    {
      "x": -18,
      "y": 2,
      "z": 1,
      "name": "Empty"
    },
    {
      "x": -18,
      "y": 3,
      "z": 1,
      "name": "Empty"
    },
    {
      "x": -18,
      "y": 4,
      "z": 1,
      "name": "Empty"
    },
    {
      "x": -18,
      "y": 5,
      "z": 1,
      "name": "Empty"
    },
    {
      "x": -18,
      "y": 6,
      "z": 1,
      "name": "Empty"
    },
    {
      "x": -18,
      "y": 7,
      "z": 1,
      "name": "Empty"
    },
    {
      "x": -18,
      "y": 8,
      "z": 1,
      "name": "Rock_Stone_Cobble_Half",
      "rotation": 8
    },
    {
      "x": -18,
      "y": 9,
      "z": 1,
      "name": "Rock_Stone"
    },
    {
      "x": -18,
      "y": 0,
      "z": 2,
      "name": "Soil_Gravel"
    },
    {
      "x": -18,
      "y": 1,
      "z": 2,
      "name": "Empty"
    },
    {
      "x": -18,
      "y": 2,
      "z": 2,
      "name": "Empty"
    },
    {
      "x": -18,
      "y": 3,
      "z": 2,
      "name": "Empty"
    },
    {
      "x": -18,
      "y": 4,
      "z": 2,
      "name": "Empty"
    },
    {
      "x": -18,
      "y": 5,
      "z": 2,
      "name": "Empty"
    },
    {
      "x": -18,
      "y": 6,
      "z": 2,
      "name": "Empty"
    },
    {
      "x": -18,
      "y": 7,
      "z": 2,
      "name": "Empty"
    },
    {
      "x": -18,
      "y": 8,
      "z": 2,
      "name": "Rock_Stone_Cobble_Half",
      "rotation": 8
    },
    {
      "x": -18,
      "y": 9,
      "z": 2,
      "name": "Rock_Stone"
    },
    {
      "x": -18,
      "y": 0,
      "z": 3,
      "name": "Soil_Gravel"
    },
    {
      "x": -18,
      "y": 1,
      "z": 3,
      "name": "Empty"
    },
    {
      "x": -18,
      "y": 2,
      "z": 3,
      "name": "Empty"
    },
    {
      "x": -18,
      "y": 3,
      "z": 3,
      "name": "Empty"
    },
    {
      "x": -18,
      "y": 4,
      "z": 3,
      "name": "Empty"
    },
    {
      "x": -18,
      "y": 5,
      "z": 3,
      "name": "Empty"
    },
    {
      "x": -18,
      "y": 6,
      "z": 3,
      "name": "Wood_Softwood_Planks_Half",
      "rotation": 8
    },
    {
      "x": -18,
      "y": 7,
      "z": 3,
      "name": "Wood_Beech_Trunk",
      "rotation": 5
    },
    {
      "x": -18,
      "y": 8,
      "z": 3,
      "name": "Rock_Stone_Cobble"
    },
    {
      "x": -18,
      "y": 9,
      "z": 3,
      "name": "Rock_Stone"
    },
    {
      "x": -18,
      "y": 0,
      "z": 4,
      "name": "Rock_Stone"
    },
    {
      "x": -18,
      "y": 1,
      "z": 4,
      "name": "Rock_Stone_Cobble"
    },
    {
      "x": -18,
      "y": 2,
      "z": 4,
      "name": "Rock_Stone_Cobble"
    },
    {
      "x": -18,
      "y": 3,
      "z": 4,
      "name": "Rock_Stone_Cobble_Half"
    },
    {
      "x": -18,
      "y": 4,
      "z": 4,
      "name": "Rock_Stone"
    },
    {
      "x": -18,
      "y": 5,
      "z": 4,
      "name": "Rock_Stone"
    },
    {
      "x": -18,
      "y": 6,
      "z": 4,
      "name": "Rock_Stone"
    },
    {
      "x": -18,
      "y": 7,
      "z": 4,
      "name": "Rock_Stone"
    },
    {
      "x": -18,
      "y": 8,
      "z": 4,
      "name": "Rock_Stone"
    },
    {
      "x": -18,
      "y": 9,
      "z": 4,
      "name": "Rock_Stone"
    },
    {
      "x": -18,
      "y": 0,
      "z": 5,
      "name": "Rock_Stone"
    },
    {
      "x": -18,
      "y": 1,
      "z": 5,
      "name": "Rock_Stone"
    },
    {
      "x": -18,
      "y": 2,
      "z": 5,
      "name": "Rock_Stone"
    },
    {
      "x": -18,
      "y": 3,
      "z": 5,
      "name": "Rock_Stone"
    },
    {
      "x": -18,
      "y": 4,
      "z": 5,
      "name": "Rock_Stone"
    },
    {
      "x": -18,
      "y": 5,
      "z": 5,
      "name": "Rock_Stone"
    },
    {
      "x": -18,
      "y": 6,
      "z": 5,
      "name": "Rock_Stone"
    },
    {
      "x": -18,
      "y": 7,
      "z": 5,
      "name": "Rock_Stone"
    },
    {
      "x": -18,
      "y": 8,
      "z": 5,
      "name": "Rock_Stone"
    },
    {
      "x": -18,
      "y": 9,
      "z": 5,
      "name": "Rock_Stone"
    },
    {
      "x": -18,
      "y": 0,
      "z": 6,
      "name": "Rock_Stone"
    },
    {
      "x": -18,
      "y": 1,
      "z": 6,
      "name": "Rock_Stone"
    },
    {
      "x": -18,
      "y": 2,
      "z": 6,
      "name": "Rock_Stone"
    },
    {
      "x": -18,
      "y": 3,
      "z": 6,
      "name": "Rock_Stone"
    },
    {
      "x": -18,
      "y": 4,
      "z": 6,
      "name": "Rock_Stone"
    },
    {
      "x": -18,
      "y": 5,
      "z": 6,
      "name": "Rock_Stone"
    },
    {
      "x": -18,
      "y": 6,
      "z": 6,
      "name": "Rock_Stone"
    },
    {
      "x": -18,
      "y": 7,
      "z": 6,
      "name": "Rock_Stone"
    },
    {
      "x": -18,
      "y": 8,
      "z": 6,
      "name": "Rock_Stone"
    },
    {
      "x": -18,
      "y": 9,
      "z": 6,
      "name": "Rock_Stone"
    },
    {
      "x": -18,
      "y": 0,
      "z": 7,
      "name": "Rock_Stone"
    },
    {
      "x": -18,
      "y": 1,
      "z": 7,
      "name": "Rock_Stone"
    },
    {
      "x": -18,
      "y": 2,
      "z": 7,
      "name": "Rock_Stone"
    },
    {
      "x": -18,
      "y": 3,
      "z": 7,
      "name": "Rock_Stone"
    },
    {
      "x": -18,
      "y": 4,
      "z": 7,
      "name": "Rock_Stone"
    },
    {
      "x": -18,
      "y": 5,
      "z": 7,
      "name": "Rock_Stone"
    },
    {
      "x": -18,
      "y": 6,
      "z": 7,
      "name": "Rock_Stone"
    },
    {
      "x": -18,
      "y": 7,
      "z": 7,
      "name": "Rock_Stone"
    },
    {
      "x": -18,
      "y": 8,
      "z": 7,
      "name": "Rock_Stone"
    },
    {
      "x": -18,
      "y": 9,
      "z": 7,
      "name": "Rock_Stone"
    },
    {
      "x": -18,
      "y": 0,
      "z": 8,
      "name": "Rock_Stone"
    },
    {
      "x": -18,
      "y": 1,
      "z": 8,
      "name": "Rock_Stone"
    },
    {
      "x": -18,
      "y": 2,
      "z": 8,
      "name": "Rock_Stone"
    },
    {
      "x": -18,
      "y": 3,
      "z": 8,
      "name": "Rock_Stone"
    },
    {
      "x": -18,
      "y": 4,
      "z": 8,
      "name": "Rock_Stone"
    },
    {
      "x": -18,
      "y": 5,
      "z": 8,
      "name": "Rock_Stone"
    },
    {
      "x": -18,
      "y": 6,
      "z": 8,
      "name": "Rock_Stone"
    },
    {
      "x": -18,
      "y": 7,
      "z": 8,
      "name": "Rock_Stone"
    },
    {
      "x": -18,
      "y": 8,
      "z": 8,
      "name": "Rock_Stone"
    },
    {
      "x": -18,
      "y": 9,
      "z": 8,
      "name": "Rock_Stone"
    },
    {
      "x": -18,
      "y": 0,
      "z": 9,
      "name": "Rock_Stone"
    },
    {
      "x": -18,
      "y": 1,
      "z": 9,
      "name": "Rock_Stone"
    },
    {
      "x": -18,
      "y": 2,
      "z": 9,
      "name": "Rock_Stone"
    },
    {
      "x": -18,
      "y": 3,
      "z": 9,
      "name": "Rock_Stone"
    },
    {
      "x": -18,
      "y": 4,
      "z": 9,
      "name": "Rock_Stone"
    },
    {
      "x": -18,
      "y": 5,
      "z": 9,
      "name": "Rock_Stone"
    },
    {
      "x": -18,
      "y": 6,
      "z": 9,
      "name": "Rock_Stone"
    },
    {
      "x": -18,
      "y": 7,
      "z": 9,
      "name": "Rock_Stone"
    },
    {
      "x": -18,
      "y": 8,
      "z": 9,
      "name": "Rock_Stone"
    },
    {
      "x": -18,
      "y": 9,
      "z": 9,
      "name": "Rock_Stone"
    },
    {
      "x": -18,
      "y": 0,
      "z": 10,
      "name": "Rock_Stone"
    },
    {
      "x": -18,
      "y": 1,
      "z": 10,
      "name": "Rock_Stone"
    },
    {
      "x": -18,
      "y": 2,
      "z": 10,
      "name": "Rock_Stone"
    },
    {
      "x": -18,
      "y": 3,
      "z": 10,
      "name": "Rock_Stone"
    },
    {
      "x": -18,
      "y": 4,
      "z": 10,
      "name": "Rock_Stone"
    },
    {
      "x": -18,
      "y": 5,
      "z": 10,
      "name": "Rock_Stone"
    },
    {
      "x": -18,
      "y": 6,
      "z": 10,
      "name": "Rock_Stone"
    },
    {
      "x": -18,
      "y": 7,
      "z": 10,
      "name": "Rock_Stone"
    },
    {
      "x": -18,
      "y": 8,
      "z": 10,
      "name": "Rock_Stone"
    },
    {
      "x": -18,
      "y": 9,
      "z": 10,
      "name": "Rock_Stone"
    },
    {
      "x": -18,
      "y": 0,
      "z": 11,
      "name": "Rock_Stone"
    },
    {
      "x": -18,
      "y": 1,
      "z": 11,
      "name": "Rock_Stone"
    },
    {
      "x": -18,
      "y": 2,
      "z": 11,
      "name": "Rock_Stone"
    },
    {
      "x": -18,
      "y": 3,
      "z": 11,
      "name": "Rock_Stone"
    },
    {
      "x": -18,
      "y": 4,
      "z": 11,
      "name": "Rock_Stone"
    },
    {
      "x": -18,
      "y": 5,
      "z": 11,
      "name": "Rock_Stone"
    },
    {
      "x": -18,
      "y": 6,
      "z": 11,
      "name": "Rock_Stone"
    },
    {
      "x": -18,
      "y": 7,
      "z": 11,
      "name": "Rock_Stone"
    },
    {
      "x": -18,
      "y": 8,
      "z": 11,
      "name": "Rock_Stone"
    },
    {
      "x": -18,
      "y": 9,
      "z": 11,
      "name": "Rock_Stone"
    },
    {
      "x": -17,
      "y": 0,
      "z": -5,
      "name": "Rock_Stone"
    },
    {
      "x": -17,
      "y": 1,
      "z": -5,
      "name": "Rock_Stone"
    },
    {
      "x": -17,
      "y": 2,
      "z": -5,
      "name": "Rock_Stone"
    },
    {
      "x": -17,
      "y": 3,
      "z": -5,
      "name": "Rock_Stone"
    },
    {
      "x": -17,
      "y": 4,
      "z": -5,
      "name": "Rock_Stone"
    },
    {
      "x": -17,
      "y": 5,
      "z": -5,
      "name": "Rock_Stone"
    },
    {
      "x": -17,
      "y": 6,
      "z": -5,
      "name": "Rock_Stone"
    },
    {
      "x": -17,
      "y": 7,
      "z": -5,
      "name": "Rock_Stone"
    },
    {
      "x": -17,
      "y": 8,
      "z": -5,
      "name": "Rock_Stone"
    },
    {
      "x": -17,
      "y": 9,
      "z": -5,
      "name": "Rock_Stone"
    },
    {
      "x": -17,
      "y": 0,
      "z": -4,
      "name": "Rock_Stone"
    },
    {
      "x": -17,
      "y": 1,
      "z": -4,
      "name": "Rock_Stone_Cobble"
    },
    {
      "x": -17,
      "y": 2,
      "z": -4,
      "name": "Rock_Stone_Cobble"
    },
    {
      "x": -17,
      "y": 3,
      "z": -4,
      "name": "Rock_Stone_Cobble"
    },
    {
      "x": -17,
      "y": 4,
      "z": -4,
      "name": "Empty"
    },
    {
      "x": -17,
      "y": 5,
      "z": -4,
      "name": "Rock_Stone"
    },
    {
      "x": -17,
      "y": 6,
      "z": -4,
      "name": "Rock_Stone"
    },
    {
      "x": -17,
      "y": 7,
      "z": -4,
      "name": "Rock_Stone"
    },
    {
      "x": -17,
      "y": 8,
      "z": -4,
      "name": "Rock_Stone"
    },
    {
      "x": -17,
      "y": 9,
      "z": -4,
      "name": "Rock_Stone"
    },
    {
      "x": -17,
      "y": 0,
      "z": -3,
      "name": "Rock_Stone"
    },
    {
      "x": -17,
      "y": 1,
      "z": -3,
      "name": "Rubble_Stone"
    },
    {
      "x": -17,
      "y": 2,
      "z": -3,
      "name": "Empty"
    },
    {
      "x": -17,
      "y": 3,
      "z": -3,
      "name": "Empty"
    },
    {
      "x": -17,
      "y": 4,
      "z": -3,
      "name": "Empty"
    },
    {
      "x": -17,
      "y": 5,
      "z": -3,
      "name": "Empty"
    },
    {
      "x": -17,
      "y": 6,
      "z": -3,
      "name": "*Wood_Softwood_Planks_Half_State_Definitions_Block",
      "rotation": 8
    },
    {
      "x": -17,
      "y": 7,
      "z": -3,
      "name": "Wood_Beech_Trunk",
      "rotation": 5
    },
    {
      "x": -17,
      "y": 8,
      "z": -3,
      "name": "Rock_Stone_Cobble"
    },
    {
      "x": -17,
      "y": 9,
      "z": -3,
      "name": "Rock_Stone"
    },
    {
      "x": -17,
      "y": 0,
      "z": -2,
      "name": "Rock_Stone"
    },
    {
      "x": -17,
      "y": 1,
      "z": -2,
      "name": "Empty"
    },
    {
      "x": -17,
      "y": 2,
      "z": -2,
      "name": "Empty"
    },
    {
      "x": -17,
      "y": 3,
      "z": -2,
      "name": "Empty"
    },
    {
      "x": -17,
      "y": 4,
      "z": -2,
      "name": "Empty"
    },
    {
      "x": -17,
      "y": 5,
      "z": -2,
      "name": "Empty"
    },
    {
      "x": -17,
      "y": 6,
      "z": -2,
      "name": "Empty"
    },
    {
      "x": -17,
      "y": 7,
      "z": -2,
      "name": "Rock_Stone_Cobble_Half",
      "rotation": 8
    },
    {
      "x": -17,
      "y": 8,
      "z": -2,
      "name": "Rock_Stone_Cobble"
    },
    {
      "x": -17,
      "y": 9,
      "z": -2,
      "name": "Rock_Stone"
    },
    {
      "x": -17,
      "y": 0,
      "z": -1,
      "name": "Wood_Beech_Trunk",
      "rotation": 5
    },
    {
      "x": -17,
      "y": 1,
      "z": -1,
      "name": "Empty"
    },
    {
      "x": -17,
      "y": 2,
      "z": -1,
      "name": "Empty"
    },
    {
      "x": -17,
      "y": 3,
      "z": -1,
      "name": "Empty"
    },
    {
      "x": -17,
      "y": 4,
      "z": -1,
      "name": "Empty"
    },
    {
      "x": -17,
      "y": 5,
      "z": -1,
      "name": "Empty"
    },
    {
      "x": -17,
      "y": 6,
      "z": -1,
      "name": "Empty"
    },
    {
      "x": -17,
      "y": 7,
      "z": -1,
      "name": "Rock_Stone_Cobble_Half",
      "rotation": 8
    },
    {
      "x": -17,
      "y": 8,
      "z": -1,
      "name": "Rock_Stone_Cobble"
    },
    {
      "x": -17,
      "y": 9,
      "z": -1,
      "name": "Rock_Stone"
    },
    {
      "x": -17,
      "y": 0,
      "z": 0,
      "name": "Wood_Beech_Trunk",
      "rotation": 5
    },
    {
      "x": -17,
      "y": 1,
      "z": 0,
      "name": "Rail",
      "rotation": 1
    },
    {
      "x": -17,
      "y": 2,
      "z": 0,
      "name": "Empty"
    },
    {
      "x": -17,
      "y": 3,
      "z": 0,
      "name": "Empty"
    },
    {
      "x": -17,
      "y": 4,
      "z": 0,
      "name": "Empty"
    },
    {
      "x": -17,
      "y": 5,
      "z": 0,
      "name": "Empty"
    },
    {
      "x": -17,
      "y": 6,
      "z": 0,
      "name": "Empty"
    },
    {
      "x": -17,
      "y": 7,
      "z": 0,
      "name": "Wood_Softwood_Planks_Half",
      "rotation": 7
    },
    {
      "x": -17,
      "y": 8,
      "z": 0,
      "name": "Rock_Stone_Cobble"
    },
    {
      "x": -17,
      "y": 9,
      "z": 0,
      "name": "Rock_Stone"
    },
    {
      "x": -17,
      "y": 0,
      "z": 1,
      "name": "Wood_Softwood_Planks"
    },
    {
      "x": -17,
      "y": 1,
      "z": 1,
      "name": "Empty"
    },
    {
      "x": -17,
      "y": 2,
      "z": 1,
      "name": "Empty"
    },
    {
      "x": -17,
      "y": 3,
      "z": 1,
      "name": "Empty"
    },
    {
      "x": -17,
      "y": 4,
      "z": 1,
      "name": "Empty"
    },
    {
      "x": -17,
      "y": 5,
      "z": 1,
      "name": "Empty"
    },
    {
      "x": -17,
      "y": 6,
      "z": 1,
      "name": "Empty"
    },
    {
      "x": -17,
      "y": 7,
      "z": 1,
      "name": "Empty"
    },
    {
      "x": -17,
      "y": 8,
      "z": 1,
      "name": "Rock_Stone_Cobble"
    },
    {
      "x": -17,
      "y": 9,
      "z": 1,
      "name": "Rock_Stone"
    },
    {
      "x": -17,
      "y": 0,
      "z": 2,
      "name": "Soil_Gravel"
    },
    {
      "x": -17,
      "y": 1,
      "z": 2,
      "name": "Empty"
    },
    {
      "x": -17,
      "y": 2,
      "z": 2,
      "name": "Empty"
    },
    {
      "x": -17,
      "y": 3,
      "z": 2,
      "name": "Empty"
    },
    {
      "x": -17,
      "y": 4,
      "z": 2,
      "name": "Empty"
    },
    {
      "x": -17,
      "y": 5,
      "z": 2,
      "name": "Empty"
    },
    {
      "x": -17,
      "y": 6,
      "z": 2,
      "name": "Empty"
    },
    {
      "x": -17,
      "y": 7,
      "z": 2,
      "name": "Empty"
    },
    {
      "x": -17,
      "y": 8,
      "z": 2,
      "name": "Rock_Stone_Cobble_Half",
      "rotation": 8
    },
    {
      "x": -17,
      "y": 9,
      "z": 2,
      "name": "Rock_Stone"
    },
    {
      "x": -17,
      "y": 0,
      "z": 3,
      "name": "Rock_Stone"
    },
    {
      "x": -17,
      "y": 1,
      "z": 3,
      "name": "Rock_Stone_Cobble_Half",
      "rotation": 6
    },
    {
      "x": -17,
      "y": 2,
      "z": 3,
      "name": "Empty"
    },
    {
      "x": -17,
      "y": 3,
      "z": 3,
      "name": "Empty"
    },
    {
      "x": -17,
      "y": 4,
      "z": 3,
      "name": "Empty"
    },
    {
      "x": -17,
      "y": 5,
      "z": 3,
      "name": "Empty"
    },
    {
      "x": -17,
      "y": 6,
      "z": 3,
      "name": "*Wood_Softwood_Planks_Half_State_Definitions_Block",
      "rotation": 8
    },
    {
      "x": -17,
      "y": 7,
      "z": 3,
      "name": "Wood_Beech_Trunk",
      "rotation": 5
    },
    {
      "x": -17,
      "y": 8,
      "z": 3,
      "name": "Rock_Stone_Cobble"
    },
    {
      "x": -17,
      "y": 9,
      "z": 3,
      "name": "Rock_Stone"
    },
    {
      "x": -17,
      "y": 0,
      "z": 4,
      "name": "Rock_Stone"
    },
    {
      "x": -17,
      "y": 1,
      "z": 4,
      "name": "Rock_Stone_Cobble"
    },
    {
      "x": -17,
      "y": 2,
      "z": 4,
      "name": "Rock_Stone_Cobble"
    },
    {
      "x": -17,
      "y": 3,
      "z": 4,
      "name": "Empty"
    },
    {
      "x": -17,
      "y": 4,
      "z": 4,
      "name": "Empty"
    },
    {
      "x": -17,
      "y": 5,
      "z": 4,
      "name": "Empty"
    },
    {
      "x": -17,
      "y": 6,
      "z": 4,
      "name": "Rock_Stone"
    },
    {
      "x": -17,
      "y": 7,
      "z": 4,
      "name": "Rock_Stone"
    },
    {
      "x": -17,
      "y": 8,
      "z": 4,
      "name": "Rock_Stone"
    },
    {
      "x": -17,
      "y": 9,
      "z": 4,
      "name": "Rock_Stone"
    },
    {
      "x": -17,
      "y": 0,
      "z": 5,
      "name": "Rock_Stone"
    },
    {
      "x": -17,
      "y": 1,
      "z": 5,
      "name": "Rock_Stone"
    },
    {
      "x": -17,
      "y": 2,
      "z": 5,
      "name": "Rock_Stone"
    },
    {
      "x": -17,
      "y": 3,
      "z": 5,
      "name": "Rock_Stone"
    },
    {
      "x": -17,
      "y": 4,
      "z": 5,
      "name": "Rock_Stone"
    },
    {
      "x": -17,
      "y": 5,
      "z": 5,
      "name": "Rock_Stone"
    },
    {
      "x": -17,
      "y": 6,
      "z": 5,
      "name": "Rock_Stone"
    },
    {
      "x": -17,
      "y": 7,
      "z": 5,
      "name": "Rock_Stone"
    },
    {
      "x": -17,
      "y": 8,
      "z": 5,
      "name": "Rock_Stone"
    },
    {
      "x": -17,
      "y": 9,
      "z": 5,
      "name": "Rock_Stone"
    },
    {
      "x": -17,
      "y": 0,
      "z": 6,
      "name": "Rock_Stone"
    },
    {
      "x": -17,
      "y": 1,
      "z": 6,
      "name": "Rock_Stone"
    },
    {
      "x": -17,
      "y": 2,
      "z": 6,
      "name": "Rock_Stone"
    },
    {
      "x": -17,
      "y": 3,
      "z": 6,
      "name": "Rock_Stone"
    },
    {
      "x": -17,
      "y": 4,
      "z": 6,
      "name": "Rock_Stone"
    },
    {
      "x": -17,
      "y": 5,
      "z": 6,
      "name": "Rock_Stone"
    },
    {
      "x": -17,
      "y": 6,
      "z": 6,
      "name": "Rock_Stone"
    },
    {
      "x": -17,
      "y": 7,
      "z": 6,
      "name": "Rock_Stone"
    },
    {
      "x": -17,
      "y": 8,
      "z": 6,
      "name": "Rock_Stone"
    },
    {
      "x": -17,
      "y": 9,
      "z": 6,
      "name": "Rock_Stone"
    },
    {
      "x": -17,
      "y": 0,
      "z": 7,
      "name": "Rock_Stone"
    },
    {
      "x": -17,
      "y": 1,
      "z": 7,
      "name": "Rock_Stone"
    },
    {
      "x": -17,
      "y": 2,
      "z": 7,
      "name": "Rock_Stone"
    },
    {
      "x": -17,
      "y": 3,
      "z": 7,
      "name": "Rock_Stone"
    },
    {
      "x": -17,
      "y": 4,
      "z": 7,
      "name": "Rock_Stone"
    },
    {
      "x": -17,
      "y": 5,
      "z": 7,
      "name": "Rock_Stone"
    },
    {
      "x": -17,
      "y": 6,
      "z": 7,
      "name": "Rock_Stone"
    },
    {
      "x": -17,
      "y": 7,
      "z": 7,
      "name": "Rock_Stone"
    },
    {
      "x": -17,
      "y": 8,
      "z": 7,
      "name": "Rock_Stone"
    },
    {
      "x": -17,
      "y": 9,
      "z": 7,
      "name": "Rock_Stone"
    },
    {
      "x": -17,
      "y": 0,
      "z": 8,
      "name": "Rock_Stone"
    },
    {
      "x": -17,
      "y": 1,
      "z": 8,
      "name": "Rock_Stone"
    },
    {
      "x": -17,
      "y": 2,
      "z": 8,
      "name": "Rock_Stone"
    },
    {
      "x": -17,
      "y": 3,
      "z": 8,
      "name": "Rock_Stone"
    },
    {
      "x": -17,
      "y": 4,
      "z": 8,
      "name": "Rock_Stone"
    },
    {
      "x": -17,
      "y": 5,
      "z": 8,
      "name": "Rock_Stone"
    },
    {
      "x": -17,
      "y": 6,
      "z": 8,
      "name": "Rock_Stone"
    },
    {
      "x": -17,
      "y": 7,
      "z": 8,
      "name": "Rock_Stone"
    },
    {
      "x": -17,
      "y": 8,
      "z": 8,
      "name": "Rock_Stone"
    },
    {
      "x": -17,
      "y": 9,
      "z": 8,
      "name": "Rock_Stone"
    },
    {
      "x": -17,
      "y": 0,
      "z": 9,
      "name": "Rock_Stone"
    },
    {
      "x": -17,
      "y": 1,
      "z": 9,
      "name": "Rock_Stone"
    },
    {
      "x": -17,
      "y": 2,
      "z": 9,
      "name": "Rock_Stone"
    },
    {
      "x": -17,
      "y": 3,
      "z": 9,
      "name": "Rock_Stone"
    },
    {
      "x": -17,
      "y": 4,
      "z": 9,
      "name": "Rock_Stone"
    },
    {
      "x": -17,
      "y": 5,
      "z": 9,
      "name": "Rock_Stone"
    },
    {
      "x": -17,
      "y": 6,
      "z": 9,
      "name": "Rock_Stone"
    },
    {
      "x": -17,
      "y": 7,
      "z": 9,
      "name": "Rock_Stone"
    },
    {
      "x": -17,
      "y": 8,
      "z": 9,
      "name": "Rock_Stone"
    },
    {
      "x": -17,
      "y": 9,
      "z": 9,
      "name": "Rock_Stone"
    },
    {
      "x": -17,
      "y": 0,
      "z": 10,
      "name": "Rock_Stone"
    },
    {
      "x": -17,
      "y": 1,
      "z": 10,
      "name": "Rock_Stone"
    },
    {
      "x": -17,
      "y": 2,
      "z": 10,
      "name": "Rock_Stone"
    },
    {
      "x": -17,
      "y": 3,
      "z": 10,
      "name": "Rock_Stone"
    },
    {
      "x": -17,
      "y": 4,
      "z": 10,
      "name": "Rock_Stone"
    },
    {
      "x": -17,
      "y": 5,
      "z": 10,
      "name": "Rock_Stone"
    },
    {
      "x": -17,
      "y": 6,
      "z": 10,
      "name": "Rock_Stone"
    },
    {
      "x": -17,
      "y": 7,
      "z": 10,
      "name": "Rock_Stone"
    },
    {
      "x": -17,
      "y": 8,
      "z": 10,
      "name": "Rock_Stone"
    },
    {
      "x": -17,
      "y": 9,
      "z": 10,
      "name": "Rock_Stone"
    },
    {
      "x": -17,
      "y": 0,
      "z": 11,
      "name": "Rock_Stone"
    },
    {
      "x": -17,
      "y": 1,
      "z": 11,
      "name": "Rock_Stone"
    },
    {
      "x": -17,
      "y": 2,
      "z": 11,
      "name": "Rock_Stone"
    },
    {
      "x": -17,
      "y": 3,
      "z": 11,
      "name": "Rock_Stone"
    },
    {
      "x": -17,
      "y": 4,
      "z": 11,
      "name": "Rock_Stone"
    },
    {
      "x": -17,
      "y": 5,
      "z": 11,
      "name": "Rock_Stone"
    },
    {
      "x": -17,
      "y": 6,
      "z": 11,
      "name": "Rock_Stone"
    },
    {
      "x": -17,
      "y": 7,
      "z": 11,
      "name": "Rock_Stone"
    },
    {
      "x": -17,
      "y": 8,
      "z": 11,
      "name": "Rock_Stone"
    },
    {
      "x": -17,
      "y": 9,
      "z": 11,
      "name": "Rock_Stone"
    },
    {
      "x": -16,
      "y": 0,
      "z": -5,
      "name": "Rock_Stone"
    },
    {
      "x": -16,
      "y": 1,
      "z": -5,
      "name": "Rock_Stone"
    },
    {
      "x": -16,
      "y": 2,
      "z": -5,
      "name": "Rock_Stone"
    },
    {
      "x": -16,
      "y": 3,
      "z": -5,
      "name": "Rock_Stone"
    },
    {
      "x": -16,
      "y": 4,
      "z": -5,
      "name": "Rock_Stone"
    },
    {
      "x": -16,
      "y": 5,
      "z": -5,
      "name": "Rock_Stone"
    },
    {
      "x": -16,
      "y": 6,
      "z": -5,
      "name": "Rock_Stone"
    },
    {
      "x": -16,
      "y": 7,
      "z": -5,
      "name": "Rock_Stone"
    },
    {
      "x": -16,
      "y": 8,
      "z": -5,
      "name": "Rock_Stone"
    },
    {
      "x": -16,
      "y": 9,
      "z": -5,
      "name": "Rock_Stone"
    },
    {
      "x": -16,
      "y": 0,
      "z": -4,
      "name": "Rock_Stone"
    },
    {
      "x": -16,
      "y": 1,
      "z": -4,
      "name": "Rock_Stone_Cobble"
    },
    {
      "x": -16,
      "y": 2,
      "z": -4,
      "name": "Rock_Stone_Cobble"
    },
    {
      "x": -16,
      "y": 3,
      "z": -4,
      "name": "Rock_Stone_Cobble"
    },
    {
      "x": -16,
      "y": 4,
      "z": -4,
      "name": "Empty"
    },
    {
      "x": -16,
      "y": 5,
      "z": -4,
      "name": "Empty"
    },
    {
      "x": -16,
      "y": 6,
      "z": -4,
      "name": "Rock_Stone"
    },
    {
      "x": -16,
      "y": 7,
      "z": -4,
      "name": "Rock_Stone"
    },
    {
      "x": -16,
      "y": 8,
      "z": -4,
      "name": "Rock_Stone"
    },
    {
      "x": -16,
      "y": 9,
      "z": -4,
      "name": "Rock_Stone"
    },
    {
      "x": -16,
      "y": 0,
      "z": -3,
      "name": "Rock_Stone"
    },
    {
      "x": -16,
      "y": 1,
      "z": -3,
      "name": "Wood_Beech_Trunk"
    },
    {
      "x": -16,
      "y": 2,
      "z": -3,
      "name": "Wood_Beech_Trunk"
    },
    {
      "x": -16,
      "y": 3,
      "z": -3,
      "name": "Wood_Beech_Trunk"
    },
    {
      "x": -16,
      "y": 4,
      "z": -3,
      "name": "Wood_Beech_Trunk"
    },
    {
      "x": -16,
      "y": 5,
      "z": -3,
      "name": "Wood_Beech_Trunk"
    },
    {
      "x": -16,
      "y": 6,
      "z": -3,
      "name": "Wood_Beech_Trunk"
    },
    {
      "x": -16,
      "y": 7,
      "z": -3,
      "name": "Wood_Beech_Trunk",
      "rotation": 5
    },
    {
      "x": -16,
      "y": 8,
      "z": -3,
      "name": "Rock_Stone_Cobble"
    },
    {
      "x": -16,
      "y": 9,
      "z": -3,
      "name": "Rock_Stone"
    },
    {
      "x": -16,
      "y": 0,
      "z": -2,
      "name": "Soil_Gravel"
    },
    {
      "x": -16,
      "y": 1,
      "z": -2,
      "name": "Empty"
    },
    {
      "x": -16,
      "y": 2,
      "z": -2,
      "name": "Empty"
    },
    {
      "x": -16,
      "y": 3,
      "z": -2,
      "name": "Empty"
    },
    {
      "x": -16,
      "y": 4,
      "z": -2,
      "name": "Empty"
    },
    {
      "x": -16,
      "y": 5,
      "z": -2,
      "name": "Empty"
    },
    {
      "x": -16,
      "y": 6,
      "z": -2,
      "name": "*Wood_Softwood_Planks_Half_State_Definitions_Block",
      "rotation": 8
    },
    {
      "x": -16,
      "y": 7,
      "z": -2,
      "name": "Wood_Beech_Trunk",
      "rotation": 4
    },
    {
      "x": -16,
      "y": 8,
      "z": -2,
      "name": "Rock_Stone_Cobble"
    },
    {
      "x": -16,
      "y": 9,
      "z": -2,
      "name": "Rock_Stone"
    },
    {
      "x": -16,
      "y": 0,
      "z": -1,
      "name": "Wood_Beech_Trunk",
      "rotation": 5
    },
    {
      "x": -16,
      "y": 1,
      "z": -1,
      "name": "Empty"
    },
    {
      "x": -16,
      "y": 2,
      "z": -1,
      "name": "Empty"
    },
    {
      "x": -16,
      "y": 3,
      "z": -1,
      "name": "Empty"
    },
    {
      "x": -16,
      "y": 4,
      "z": -1,
      "name": "Empty"
    },
    {
      "x": -16,
      "y": 5,
      "z": -1,
      "name": "Empty"
    },
    {
      "x": -16,
      "y": 6,
      "z": -1,
      "name": "Wood_Softwood_Planks_Half",
      "rotation": 8
    },
    {
      "x": -16,
      "y": 7,
      "z": -1,
      "name": "Wood_Beech_Trunk",
      "rotation": 4
    },
    {
      "x": -16,
      "y": 8,
      "z": -1,
      "name": "Rock_Stone_Cobble"
    },
    {
      "x": -16,
      "y": 9,
      "z": -1,
      "name": "Rock_Stone"
    },
    {
      "x": -16,
      "y": 0,
      "z": 0,
      "name": "Wood_Beech_Trunk",
      "rotation": 5
    },
    {
      "x": -16,
      "y": 1,
      "z": 0,
      "name": "Rail",
      "rotation": 1
    },
    {
      "x": -16,
      "y": 2,
      "z": 0,
      "name": "Empty"
    },
    {
      "x": -16,
      "y": 3,
      "z": 0,
      "name": "Empty"
    },
    {
      "x": -16,
      "y": 4,
      "z": 0,
      "name": "Empty"
    },
    {
      "x": -16,
      "y": 5,
      "z": 0,
      "name": "Empty"
    },
    {
      "x": -16,
      "y": 6,
      "z": 0,
      "name": "Wood_Softwood_Planks_Half",
      "rotation": 8
    },
    {
      "x": -16,
      "y": 7,
      "z": 0,
      "name": "Wood_Beech_Trunk",
      "rotation": 4
    },
    {
      "x": -16,
      "y": 8,
      "z": 0,
      "name": "Rock_Stone_Cobble"
    },
    {
      "x": -16,
      "y": 9,
      "z": 0,
      "name": "Rock_Stone"
    },
    {
      "x": -16,
      "y": 0,
      "z": 1,
      "name": "Wood_Softwood_Planks"
    },
    {
      "x": -16,
      "y": 1,
      "z": 1,
      "name": "Empty"
    },
    {
      "x": -16,
      "y": 2,
      "z": 1,
      "name": "Empty"
    },
    {
      "x": -16,
      "y": 3,
      "z": 1,
      "name": "Empty"
    },
    {
      "x": -16,
      "y": 4,
      "z": 1,
      "name": "Empty"
    },
    {
      "x": -16,
      "y": 5,
      "z": 1,
      "name": "Empty"
    },
    {
      "x": -16,
      "y": 6,
      "z": 1,
      "name": "Wood_Softwood_Planks_Half",
      "rotation": 8
    },
    {
      "x": -16,
      "y": 7,
      "z": 1,
      "name": "Wood_Beech_Trunk",
      "rotation": 4
    },
    {
      "x": -16,
      "y": 8,
      "z": 1,
      "name": "Rock_Stone_Cobble"
    },
    {
      "x": -16,
      "y": 9,
      "z": 1,
      "name": "Rock_Stone"
    },
    {
      "x": -16,
      "y": 0,
      "z": 2,
      "name": "Rock_Stone"
    },
    {
      "x": -16,
      "y": 1,
      "z": 2,
      "name": "Empty"
    },
    {
      "x": -16,
      "y": 2,
      "z": 2,
      "name": "Empty"
    },
    {
      "x": -16,
      "y": 3,
      "z": 2,
      "name": "Empty"
    },
    {
      "x": -16,
      "y": 4,
      "z": 2,
      "name": "Empty"
    },
    {
      "x": -16,
      "y": 5,
      "z": 2,
      "name": "Empty"
    },
    {
      "x": -16,
      "y": 6,
      "z": 2,
      "name": "*Wood_Softwood_Planks_Half_State_Definitions_Block",
      "rotation": 8
    },
    {
      "x": -16,
      "y": 7,
      "z": 2,
      "name": "Wood_Beech_Trunk",
      "rotation": 4
    },
    {
      "x": -16,
      "y": 8,
      "z": 2,
      "name": "Rock_Stone_Cobble"
    },
    {
      "x": -16,
      "y": 9,
      "z": 2,
      "name": "Rock_Stone"
    },
    {
      "x": -16,
      "y": 0,
      "z": 3,
      "name": "Rock_Stone"
    },
    {
      "x": -16,
      "y": 1,
      "z": 3,
      "name": "Wood_Beech_Trunk"
    },
    {
      "x": -16,
      "y": 2,
      "z": 3,
      "name": "Wood_Beech_Trunk"
    },
    {
      "x": -16,
      "y": 3,
      "z": 3,
      "name": "Wood_Beech_Trunk"
    },
    {
      "x": -16,
      "y": 4,
      "z": 3,
      "name": "Wood_Beech_Trunk"
    },
    {
      "x": -16,
      "y": 5,
      "z": 3,
      "name": "Wood_Beech_Trunk"
    },
    {
      "x": -16,
      "y": 6,
      "z": 3,
      "name": "Wood_Beech_Trunk"
    },
    {
      "x": -16,
      "y": 7,
      "z": 3,
      "name": "Wood_Beech_Trunk",
      "rotation": 5
    },
    {
      "x": -16,
      "y": 8,
      "z": 3,
      "name": "Rock_Stone_Cobble"
    },
    {
      "x": -16,
      "y": 9,
      "z": 3,
      "name": "Rock_Stone"
    },
    {
      "x": -16,
      "y": 0,
      "z": 4,
      "name": "Rock_Stone"
    },
    {
      "x": -16,
      "y": 1,
      "z": 4,
      "name": "Rock_Stone_Cobble"
    },
    {
      "x": -16,
      "y": 2,
      "z": 4,
      "name": "Empty"
    },
    {
      "x": -16,
      "y": 3,
      "z": 4,
      "name": "Empty"
    },
    {
      "x": -16,
      "y": 4,
      "z": 4,
      "name": "Empty"
    },
    {
      "x": -16,
      "y": 5,
      "z": 4,
      "name": "Empty"
    },
    {
      "x": -16,
      "y": 6,
      "z": 4,
      "name": "Rock_Stone"
    },
    {
      "x": -16,
      "y": 7,
      "z": 4,
      "name": "Rock_Stone"
    },
    {
      "x": -16,
      "y": 8,
      "z": 4,
      "name": "Rock_Stone"
    },
    {
      "x": -16,
      "y": 9,
      "z": 4,
      "name": "Rock_Stone"
    },
    {
      "x": -16,
      "y": 0,
      "z": 5,
      "name": "Rock_Stone"
    },
    {
      "x": -16,
      "y": 1,
      "z": 5,
      "name": "Rock_Stone"
    },
    {
      "x": -16,
      "y": 2,
      "z": 5,
      "name": "Rock_Stone"
    },
    {
      "x": -16,
      "y": 3,
      "z": 5,
      "name": "Rock_Stone"
    },
    {
      "x": -16,
      "y": 4,
      "z": 5,
      "name": "Rock_Stone"
    },
    {
      "x": -16,
      "y": 5,
      "z": 5,
      "name": "Rock_Stone"
    },
    {
      "x": -16,
      "y": 6,
      "z": 5,
      "name": "Rock_Stone"
    },
    {
      "x": -16,
      "y": 7,
      "z": 5,
      "name": "Rock_Stone"
    },
    {
      "x": -16,
      "y": 8,
      "z": 5,
      "name": "Rock_Stone"
    },
    {
      "x": -16,
      "y": 9,
      "z": 5,
      "name": "Rock_Stone"
    },
    {
      "x": -16,
      "y": 0,
      "z": 6,
      "name": "Rock_Stone"
    },
    {
      "x": -16,
      "y": 1,
      "z": 6,
      "name": "Rock_Stone"
    },
    {
      "x": -16,
      "y": 2,
      "z": 6,
      "name": "Plant_Crop_Mushroom_Flatcap_Green",
      "components": {
        "Components": {
          "FarmingBlock": {}
        }
      }
    },
    {
      "x": -16,
      "y": 3,
      "z": 6,
      "name": "Empty"
    },
    {
      "x": -16,
      "y": 4,
      "z": 6,
      "name": "Rock_Stone"
    },
    {
      "x": -16,
      "y": 5,
      "z": 6,
      "name": "Rock_Stone"
    },
    {
      "x": -16,
      "y": 6,
      "z": 6,
      "name": "Rock_Stone"
    },
    {
      "x": -16,
      "y": 7,
      "z": 6,
      "name": "Rock_Stone"
    },
    {
      "x": -16,
      "y": 8,
      "z": 6,
      "name": "Rock_Stone"
    },
    {
      "x": -16,
      "y": 9,
      "z": 6,
      "name": "Rock_Stone"
    },
    {
      "x": -16,
      "y": 0,
      "z": 7,
      "name": "Rock_Stone"
    },
    {
      "x": -16,
      "y": 1,
      "z": 7,
      "name": "Plant_Moss_Green_Dark"
    },
    {
      "x": -16,
      "y": 2,
      "z": 7,
      "name": "Empty"
    },
    {
      "x": -16,
      "y": 3,
      "z": 7,
      "name": "Empty"
    },
    {
      "x": -16,
      "y": 4,
      "z": 7,
      "name": "Empty"
    },
    {
      "x": -16,
      "y": 5,
      "z": 7,
      "name": "Empty"
    },
    {
      "x": -16,
      "y": 6,
      "z": 7,
      "name": "Rock_Stone"
    },
    {
      "x": -16,
      "y": 7,
      "z": 7,
      "name": "Rock_Stone"
    },
    {
      "x": -16,
      "y": 8,
      "z": 7,
      "name": "Rock_Stone"
    },
    {
      "x": -16,
      "y": 9,
      "z": 7,
      "name": "Rock_Stone"
    },
    {
      "x": -16,
      "y": 0,
      "z": 8,
      "name": "Rock_Stone"
    },
    {
      "x": -16,
      "y": 1,
      "z": 8,
      "name": "Furniture_Village_Crate"
    },
    {
      "x": -16,
      "y": 2,
      "z": 8,
      "name": "Empty"
    },
    {
      "x": -16,
      "y": 3,
      "z": 8,
      "name": "Rock_Stone_Stalactite_Large",
      "filler": 31744,
      "rotation": 8
    },
    {
      "x": -16,
      "y": 4,
      "z": 8,
      "name": "Rock_Stone_Stalactite_Large",
      "rotation": 8
    },
    {
      "x": -16,
      "y": 5,
      "z": 8,
      "name": "Rock_Stone"
    },
    {
      "x": -16,
      "y": 6,
      "z": 8,
      "name": "Rock_Stone"
    },
    {
      "x": -16,
      "y": 7,
      "z": 8,
      "name": "Rock_Stone"
    },
    {
      "x": -16,
      "y": 8,
      "z": 8,
      "name": "Rock_Stone"
    },
    {
      "x": -16,
      "y": 9,
      "z": 8,
      "name": "Rock_Stone"
    },
    {
      "x": -16,
      "y": 0,
      "z": 9,
      "name": "Rock_Stone"
    },
    {
      "x": -16,
      "y": 1,
      "z": 9,
      "name": "Furniture_Village_Crate"
    },
    {
      "x": -16,
      "y": 2,
      "z": 9,
      "name": "Plant_Moss_Rug_Green_Dark"
    },
    {
      "x": -16,
      "y": 3,
      "z": 9,
      "name": "Rock_Stone"
    },
    {
      "x": -16,
      "y": 4,
      "z": 9,
      "name": "Rock_Stone"
    },
    {
      "x": -16,
      "y": 5,
      "z": 9,
      "name": "Rock_Stone"
    },
    {
      "x": -16,
      "y": 6,
      "z": 9,
      "name": "Rock_Stone"
    },
    {
      "x": -16,
      "y": 7,
      "z": 9,
      "name": "Rock_Stone"
    },
    {
      "x": -16,
      "y": 8,
      "z": 9,
      "name": "Rock_Stone"
    },
    {
      "x": -16,
      "y": 9,
      "z": 9,
      "name": "Rock_Stone"
    },
    {
      "x": -16,
      "y": 0,
      "z": 10,
      "name": "Rock_Stone"
    },
    {
      "x": -16,
      "y": 1,
      "z": 10,
      "name": "Rock_Stone"
    },
    {
      "x": -16,
      "y": 2,
      "z": 10,
      "name": "Rock_Stone"
    },
    {
      "x": -16,
      "y": 3,
      "z": 10,
      "name": "Rock_Stone"
    },
    {
      "x": -16,
      "y": 4,
      "z": 10,
      "name": "Rock_Stone"
    },
    {
      "x": -16,
      "y": 5,
      "z": 10,
      "name": "Rock_Stone"
    },
    {
      "x": -16,
      "y": 6,
      "z": 10,
      "name": "Rock_Stone"
    },
    {
      "x": -16,
      "y": 7,
      "z": 10,
      "name": "Rock_Stone"
    },
    {
      "x": -16,
      "y": 8,
      "z": 10,
      "name": "Rock_Stone"
    },
    {
      "x": -16,
      "y": 9,
      "z": 10,
      "name": "Rock_Stone"
    },
    {
      "x": -16,
      "y": 0,
      "z": 11,
      "name": "Rock_Stone"
    },
    {
      "x": -16,
      "y": 1,
      "z": 11,
      "name": "Rock_Stone"
    },
    {
      "x": -16,
      "y": 2,
      "z": 11,
      "name": "Rock_Stone"
    },
    {
      "x": -16,
      "y": 3,
      "z": 11,
      "name": "Rock_Stone"
    },
    {
      "x": -16,
      "y": 4,
      "z": 11,
      "name": "Rock_Stone"
    },
    {
      "x": -16,
      "y": 5,
      "z": 11,
      "name": "Rock_Stone"
    },
    {
      "x": -16,
      "y": 6,
      "z": 11,
      "name": "Rock_Stone"
    },
    {
      "x": -16,
      "y": 7,
      "z": 11,
      "name": "Rock_Stone"
    },
    {
      "x": -16,
      "y": 8,
      "z": 11,
      "name": "Rock_Stone"
    },
    {
      "x": -16,
      "y": 9,
      "z": 11,
      "name": "Rock_Stone"
    },
    {
      "x": -15,
      "y": 0,
      "z": -5,
      "name": "Rock_Stone"
    },
    {
      "x": -15,
      "y": 1,
      "z": -5,
      "name": "Rock_Stone"
    },
    {
      "x": -15,
      "y": 2,
      "z": -5,
      "name": "Rock_Stone"
    },
    {
      "x": -15,
      "y": 3,
      "z": -5,
      "name": "Rock_Stone"
    },
    {
      "x": -15,
      "y": 4,
      "z": -5,
      "name": "Rock_Stone"
    },
    {
      "x": -15,
      "y": 5,
      "z": -5,
      "name": "Rock_Stone"
    },
    {
      "x": -15,
      "y": 6,
      "z": -5,
      "name": "Rock_Stone"
    },
    {
      "x": -15,
      "y": 7,
      "z": -5,
      "name": "Rock_Stone"
    },
    {
      "x": -15,
      "y": 8,
      "z": -5,
      "name": "Rock_Stone"
    },
    {
      "x": -15,
      "y": 9,
      "z": -5,
      "name": "Rock_Stone"
    },
    {
      "x": -15,
      "y": 0,
      "z": -4,
      "name": "Rock_Stone"
    },
    {
      "x": -15,
      "y": 1,
      "z": -4,
      "name": "Rock_Stone_Cobble"
    },
    {
      "x": -15,
      "y": 2,
      "z": -4,
      "name": "Rock_Stone_Cobble"
    },
    {
      "x": -15,
      "y": 3,
      "z": -4,
      "name": "Rock_Stone_Cobble"
    },
    {
      "x": -15,
      "y": 4,
      "z": -4,
      "name": "Empty"
    },
    {
      "x": -15,
      "y": 5,
      "z": -4,
      "name": "Rock_Stone"
    },
    {
      "x": -15,
      "y": 6,
      "z": -4,
      "name": "Rock_Stone"
    },
    {
      "x": -15,
      "y": 7,
      "z": -4,
      "name": "Rock_Stone"
    },
    {
      "x": -15,
      "y": 8,
      "z": -4,
      "name": "Rock_Stone"
    },
    {
      "x": -15,
      "y": 9,
      "z": -4,
      "name": "Rock_Stone"
    },
    {
      "x": -15,
      "y": 0,
      "z": -3,
      "name": "Soil_Gravel"
    },
    {
      "x": -15,
      "y": 1,
      "z": -3,
      "name": "Empty"
    },
    {
      "x": -15,
      "y": 2,
      "z": -3,
      "name": "Empty"
    },
    {
      "x": -15,
      "y": 3,
      "z": -3,
      "name": "Empty"
    },
    {
      "x": -15,
      "y": 4,
      "z": -3,
      "name": "Empty"
    },
    {
      "x": -15,
      "y": 5,
      "z": -3,
      "name": "Empty"
    },
    {
      "x": -15,
      "y": 6,
      "z": -3,
      "name": "Wood_Softwood_Planks_Half",
      "rotation": 8
    },
    {
      "x": -15,
      "y": 7,
      "z": -3,
      "name": "Wood_Beech_Trunk",
      "rotation": 5
    },
    {
      "x": -15,
      "y": 8,
      "z": -3,
      "name": "Rock_Stone_Cobble"
    },
    {
      "x": -15,
      "y": 9,
      "z": -3,
      "name": "Rock_Stone"
    },
    {
      "x": -15,
      "y": 0,
      "z": -2,
      "name": "Soil_Gravel"
    },
    {
      "x": -15,
      "y": 1,
      "z": -2,
      "name": "Empty"
    },
    {
      "x": -15,
      "y": 2,
      "z": -2,
      "name": "Empty"
    },
    {
      "x": -15,
      "y": 3,
      "z": -2,
      "name": "Empty"
    },
    {
      "x": -15,
      "y": 4,
      "z": -2,
      "name": "Empty"
    },
    {
      "x": -15,
      "y": 5,
      "z": -2,
      "name": "Empty"
    },
    {
      "x": -15,
      "y": 6,
      "z": -2,
      "name": "Empty"
    },
    {
      "x": -15,
      "y": 7,
      "z": -2,
      "name": "Empty"
    },
    {
      "x": -15,
      "y": 8,
      "z": -2,
      "name": "Rock_Stone_Cobble"
    },
    {
      "x": -15,
      "y": 9,
      "z": -2,
      "name": "Rock_Stone"
    },
    {
      "x": -15,
      "y": 0,
      "z": -1,
      "name": "Wood_Softwood_Planks"
    },
    {
      "x": -15,
      "y": 1,
      "z": -1,
      "name": "Empty"
    },
    {
      "x": -15,
      "y": 2,
      "z": -1,
      "name": "Empty"
    },
    {
      "x": -15,
      "y": 3,
      "z": -1,
      "name": "Empty"
    },
    {
      "x": -15,
      "y": 4,
      "z": -1,
      "name": "Empty"
    },
    {
      "x": -15,
      "y": 5,
      "z": -1,
      "name": "Empty"
    },
    {
      "x": -15,
      "y": 6,
      "z": -1,
      "name": "Empty"
    },
    {
      "x": -15,
      "y": 7,
      "z": -1,
      "name": "Empty"
    },
    {
      "x": -15,
      "y": 8,
      "z": -1,
      "name": "Rock_Stone_Cobble"
    },
    {
      "x": -15,
      "y": 9,
      "z": -1,
      "name": "Rock_Stone"
    },
    {
      "x": -15,
      "y": 0,
      "z": 0,
      "name": "Wood_Beech_Trunk",
      "rotation": 5
    },
    {
      "x": -15,
      "y": 1,
      "z": 0,
      "name": "Rail",
      "rotation": 1
    },
    {
      "x": -15,
      "y": 2,
      "z": 0,
      "name": "Empty"
    },
    {
      "x": -15,
      "y": 3,
      "z": 0,
      "name": "Empty"
    },
    {
      "x": -15,
      "y": 4,
      "z": 0,
      "name": "Empty"
    },
    {
      "x": -15,
      "y": 5,
      "z": 0,
      "name": "Empty"
    },
    {
      "x": -15,
      "y": 6,
      "z": 0,
      "name": "Empty"
    },
    {
      "x": -15,
      "y": 7,
      "z": 0,
      "name": "Empty"
    },
    {
      "x": -15,
      "y": 8,
      "z": 0,
      "name": "Rock_Stone_Cobble"
    },
    {
      "x": -15,
      "y": 9,
      "z": 0,
      "name": "Rock_Stone"
    },
    {
      "x": -15,
      "y": 0,
      "z": 1,
      "name": "Wood_Softwood_Planks"
    },
    {
      "x": -15,
      "y": 1,
      "z": 1,
      "name": "Empty"
    },
    {
      "x": -15,
      "y": 2,
      "z": 1,
      "name": "Empty"
    },
    {
      "x": -15,
      "y": 3,
      "z": 1,
      "name": "Empty"
    },
    {
      "x": -15,
      "y": 4,
      "z": 1,
      "name": "Empty"
    },
    {
      "x": -15,
      "y": 5,
      "z": 1,
      "name": "Empty"
    },
    {
      "x": -15,
      "y": 6,
      "z": 1,
      "name": "Empty"
    },
    {
      "x": -15,
      "y": 7,
      "z": 1,
      "name": "Rock_Stone_Cobble_Half",
      "rotation": 8
    },
    {
      "x": -15,
      "y": 8,
      "z": 1,
      "name": "Rock_Stone_Cobble"
    },
    {
      "x": -15,
      "y": 9,
      "z": 1,
      "name": "Rock_Stone"
    },
    {
      "x": -15,
      "y": 0,
      "z": 2,
      "name": "Rock_Stone"
    },
    {
      "x": -15,
      "y": 1,
      "z": 2,
      "name": "Empty"
    },
    {
      "x": -15,
      "y": 2,
      "z": 2,
      "name": "Empty"
    },
    {
      "x": -15,
      "y": 3,
      "z": 2,
      "name": "Empty"
    },
    {
      "x": -15,
      "y": 4,
      "z": 2,
      "name": "Empty"
    },
    {
      "x": -15,
      "y": 5,
      "z": 2,
      "name": "Empty"
    },
    {
      "x": -15,
      "y": 6,
      "z": 2,
      "name": "Empty"
    },
    {
      "x": -15,
      "y": 7,
      "z": 2,
      "name": "Rock_Stone_Cobble_Half",
      "rotation": 8
    },
    {
      "x": -15,
      "y": 8,
      "z": 2,
      "name": "Rock_Stone_Cobble"
    },
    {
      "x": -15,
      "y": 9,
      "z": 2,
      "name": "Rock_Stone"
    },
    {
      "x": -15,
      "y": 0,
      "z": 3,
      "name": "Rock_Stone"
    },
    {
      "x": -15,
      "y": 1,
      "z": 3,
      "name": "Empty"
    },
    {
      "x": -15,
      "y": 2,
      "z": 3,
      "name": "Empty"
    },
    {
      "x": -15,
      "y": 3,
      "z": 3,
      "name": "Empty"
    },
    {
      "x": -15,
      "y": 4,
      "z": 3,
      "name": "Empty"
    },
    {
      "x": -15,
      "y": 5,
      "z": 3,
      "name": "Empty"
    },
    {
      "x": -15,
      "y": 6,
      "z": 3,
      "name": "Wood_Softwood_Planks_Half",
      "rotation": 8
    },
    {
      "x": -15,
      "y": 7,
      "z": 3,
      "name": "Wood_Beech_Trunk",
      "rotation": 5
    },
    {
      "x": -15,
      "y": 8,
      "z": 3,
      "name": "Rock_Stone_Cobble"
    },
    {
      "x": -15,
      "y": 9,
      "z": 3,
      "name": "Rock_Stone"
    },
    {
      "x": -15,
      "y": 0,
      "z": 4,
      "name": "Rock_Stone"
    },
    {
      "x": -15,
      "y": 1,
      "z": 4,
      "name": "Empty"
    },
    {
      "x": -15,
      "y": 2,
      "z": 4,
      "name": "Empty"
    },
    {
      "x": -15,
      "y": 3,
      "z": 4,
      "name": "Empty"
    },
    {
      "x": -15,
      "y": 4,
      "z": 4,
      "name": "Empty"
    },
    {
      "x": -15,
      "y": 5,
      "z": 4,
      "name": "Empty"
    },
    {
      "x": -15,
      "y": 6,
      "z": 4,
      "name": "Rock_Stone"
    },
    {
      "x": -15,
      "y": 7,
      "z": 4,
      "name": "Rock_Stone"
    },
    {
      "x": -15,
      "y": 8,
      "z": 4,
      "name": "Rock_Stone"
    },
    {
      "x": -15,
      "y": 9,
      "z": 4,
      "name": "Rock_Stone"
    },
    {
      "x": -15,
      "y": 0,
      "z": 5,
      "name": "Rock_Stone"
    },
    {
      "x": -15,
      "y": 1,
      "z": 5,
      "name": "Empty"
    },
    {
      "x": -15,
      "y": 2,
      "z": 5,
      "name": "Empty"
    },
    {
      "x": -15,
      "y": 3,
      "z": 5,
      "name": "Empty"
    },
    {
      "x": -15,
      "y": 4,
      "z": 5,
      "name": "Empty"
    },
    {
      "x": -15,
      "y": 5,
      "z": 5,
      "name": "Empty"
    },
    {
      "x": -15,
      "y": 6,
      "z": 5,
      "name": "Rock_Stone"
    },
    {
      "x": -15,
      "y": 7,
      "z": 5,
      "name": "Rock_Stone"
    },
    {
      "x": -15,
      "y": 8,
      "z": 5,
      "name": "Rock_Stone"
    },
    {
      "x": -15,
      "y": 9,
      "z": 5,
      "name": "Rock_Stone"
    },
    {
      "x": -15,
      "y": 0,
      "z": 6,
      "name": "Rock_Stone"
    },
    {
      "x": -15,
      "y": 1,
      "z": 6,
      "name": "Empty"
    },
    {
      "x": -15,
      "y": 2,
      "z": 6,
      "name": "Empty"
    },
    {
      "x": -15,
      "y": 3,
      "z": 6,
      "name": "Empty"
    },
    {
      "x": -15,
      "y": 4,
      "z": 6,
      "name": "Empty"
    },
    {
      "x": -15,
      "y": 5,
      "z": 6,
      "name": "Empty"
    },
    {
      "x": -15,
      "y": 6,
      "z": 6,
      "name": "Empty"
    },
    {
      "x": -15,
      "y": 7,
      "z": 6,
      "name": "Rock_Stone"
    },
    {
      "x": -15,
      "y": 8,
      "z": 6,
      "name": "Rock_Stone"
    },
    {
      "x": -15,
      "y": 9,
      "z": 6,
      "name": "Rock_Stone"
    },
    {
      "x": -15,
      "y": 0,
      "z": 7,
      "name": "Rock_Stone"
    },
    {
      "x": -15,
      "y": 1,
      "z": 7,
      "name": "Empty"
    },
    {
      "x": -15,
      "y": 2,
      "z": 7,
      "name": "Empty"
    },
    {
      "x": -15,
      "y": 3,
      "z": 7,
      "name": "Empty"
    },
    {
      "x": -15,
      "y": 4,
      "z": 7,
      "name": "Empty"
    },
    {
      "x": -15,
      "y": 5,
      "z": 7,
      "name": "Empty"
    },
    {
      "x": -15,
      "y": 6,
      "z": 7,
      "name": "Empty"
    },
    {
      "x": -15,
      "y": 7,
      "z": 7,
      "name": "Rock_Stone"
    },
    {
      "x": -15,
      "y": 8,
      "z": 7,
      "name": "Rock_Stone"
    },
    {
      "x": -15,
      "y": 9,
      "z": 7,
      "name": "Rock_Stone"
    },
    {
      "x": -15,
      "y": 0,
      "z": 8,
      "name": "Rock_Stone"
    },
    {
      "x": -15,
      "y": 1,
      "z": 8,
      "name": "Rubble_Stone"
    },
    {
      "x": -15,
      "y": 2,
      "z": 8,
      "name": "Empty"
    },
    {
      "x": -15,
      "y": 3,
      "z": 8,
      "name": "Empty"
    },
    {
      "x": -15,
      "y": 4,
      "z": 8,
      "name": "Empty"
    },
    {
      "x": -15,
      "y": 5,
      "z": 8,
      "name": "Empty"
    },
    {
      "x": -15,
      "y": 6,
      "z": 8,
      "name": "Empty"
    },
    {
      "x": -15,
      "y": 7,
      "z": 8,
      "name": "Rock_Stone"
    },
    {
      "x": -15,
      "y": 8,
      "z": 8,
      "name": "Rock_Stone"
    },
    {
      "x": -15,
      "y": 9,
      "z": 8,
      "name": "Rock_Stone"
    },
    {
      "x": -15,
      "y": 0,
      "z": 9,
      "name": "Rock_Stone"
    },
    {
      "x": -15,
      "y": 1,
      "z": 9,
      "name": "Furniture_Village_Crate"
    },
    {
      "x": -15,
      "y": 2,
      "z": 9,
      "name": "Plant_Moss_Rug_Green_Dark"
    },
    {
      "x": -15,
      "y": 3,
      "z": 9,
      "name": "Empty"
    },
    {
      "x": -15,
      "y": 4,
      "z": 9,
      "name": "Rock_Stone_Stalactite_Large",
      "filler": 31744,
      "rotation": 8
    },
    {
      "x": -15,
      "y": 5,
      "z": 9,
      "name": "Rock_Stone_Stalactite_Large",
      "rotation": 8
    },
    {
      "x": -15,
      "y": 6,
      "z": 9,
      "name": "Rock_Stone"
    },
    {
      "x": -15,
      "y": 7,
      "z": 9,
      "name": "Rock_Stone"
    },
    {
      "x": -15,
      "y": 8,
      "z": 9,
      "name": "Rock_Stone"
    },
    {
      "x": -15,
      "y": 9,
      "z": 9,
      "name": "Rock_Stone"
    },
    {
      "x": -15,
      "y": 0,
      "z": 10,
      "name": "Rock_Stone"
    },
    {
      "x": -15,
      "y": 1,
      "z": 10,
      "name": "Rock_Stone"
    },
    {
      "x": -15,
      "y": 2,
      "z": 10,
      "name": "Plant_Moss_Rug_Green_Dark"
    },
    {
      "x": -15,
      "y": 3,
      "z": 10,
      "name": "Empty"
    },
    {
      "x": -15,
      "y": 4,
      "z": 10,
      "name": "Rock_Stone"
    },
    {
      "x": -15,
      "y": 5,
      "z": 10,
      "name": "Rock_Stone"
    },
    {
      "x": -15,
      "y": 6,
      "z": 10,
      "name": "Rock_Stone"
    },
    {
      "x": -15,
      "y": 7,
      "z": 10,
      "name": "Rock_Stone"
    },
    {
      "x": -15,
      "y": 8,
      "z": 10,
      "name": "Rock_Stone"
    },
    {
      "x": -15,
      "y": 9,
      "z": 10,
      "name": "Rock_Stone"
    },
    {
      "x": -15,
      "y": 0,
      "z": 11,
      "name": "Rock_Stone"
    },
    {
      "x": -15,
      "y": 1,
      "z": 11,
      "name": "Rock_Stone"
    },
    {
      "x": -15,
      "y": 2,
      "z": 11,
      "name": "Rock_Stone"
    },
    {
      "x": -15,
      "y": 3,
      "z": 11,
      "name": "Rock_Stone"
    },
    {
      "x": -15,
      "y": 4,
      "z": 11,
      "name": "Rock_Stone"
    },
    {
      "x": -15,
      "y": 5,
      "z": 11,
      "name": "Rock_Stone"
    },
    {
      "x": -15,
      "y": 6,
      "z": 11,
      "name": "Rock_Stone"
    },
    {
      "x": -15,
      "y": 7,
      "z": 11,
      "name": "Rock_Stone"
    },
    {
      "x": -15,
      "y": 8,
      "z": 11,
      "name": "Rock_Stone"
    },
    {
      "x": -15,
      "y": 9,
      "z": 11,
      "name": "Rock_Stone"
    },
    {
      "x": -14,
      "y": 0,
      "z": -5,
      "name": "Rock_Stone"
    },
    {
      "x": -14,
      "y": 1,
      "z": -5,
      "name": "Rock_Stone"
    },
    {
      "x": -14,
      "y": 2,
      "z": -5,
      "name": "Rock_Stone"
    },
    {
      "x": -14,
      "y": 3,
      "z": -5,
      "name": "Rock_Stone"
    },
    {
      "x": -14,
      "y": 4,
      "z": -5,
      "name": "Rock_Stone"
    },
    {
      "x": -14,
      "y": 5,
      "z": -5,
      "name": "Rock_Stone"
    },
    {
      "x": -14,
      "y": 6,
      "z": -5,
      "name": "Rock_Stone"
    },
    {
      "x": -14,
      "y": 7,
      "z": -5,
      "name": "Rock_Stone"
    },
    {
      "x": -14,
      "y": 8,
      "z": -5,
      "name": "Rock_Stone"
    },
    {
      "x": -14,
      "y": 9,
      "z": -5,
      "name": "Rock_Stone"
    },
    {
      "x": -14,
      "y": 0,
      "z": -4,
      "name": "Rock_Stone"
    },
    {
      "x": -14,
      "y": 1,
      "z": -4,
      "name": "Rock_Stone_Cobble"
    },
    {
      "x": -14,
      "y": 2,
      "z": -4,
      "name": "Rock_Stone_Cobble"
    },
    {
      "x": -14,
      "y": 3,
      "z": -4,
      "name": "Empty"
    },
    {
      "x": -14,
      "y": 4,
      "z": -4,
      "name": "Empty"
    },
    {
      "x": -14,
      "y": 5,
      "z": -4,
      "name": "Rock_Stone"
    },
    {
      "x": -14,
      "y": 6,
      "z": -4,
      "name": "Rock_Stone"
    },
    {
      "x": -14,
      "y": 7,
      "z": -4,
      "name": "Rock_Stone"
    },
    {
      "x": -14,
      "y": 8,
      "z": -4,
      "name": "Rock_Stone"
    },
    {
      "x": -14,
      "y": 9,
      "z": -4,
      "name": "Rock_Stone"
    },
    {
      "x": -14,
      "y": 0,
      "z": -3,
      "name": "Rock_Stone"
    },
    {
      "x": -14,
      "y": 1,
      "z": -3,
      "name": "Wood_Softwood_Beam"
    },
    {
      "x": -14,
      "y": 2,
      "z": -3,
      "name": "*Furniture_Crude_Torch_State_Definitions_Off"
    },
    {
      "x": -14,
      "y": 3,
      "z": -3,
      "name": "Empty"
    },
    {
      "x": -14,
      "y": 4,
      "z": -3,
      "name": "Empty"
    },
    {
      "x": -14,
      "y": 5,
      "z": -3,
      "name": "Empty"
    },
    {
      "x": -14,
      "y": 6,
      "z": -3,
      "name": "Wood_Softwood_Planks_Half",
      "rotation": 8
    },
    {
      "x": -14,
      "y": 7,
      "z": -3,
      "name": "Wood_Beech_Trunk",
      "rotation": 5
    },
    {
      "x": -14,
      "y": 8,
      "z": -3,
      "name": "Rock_Stone_Cobble"
    },
    {
      "x": -14,
      "y": 9,
      "z": -3,
      "name": "Rock_Stone"
    },
    {
      "x": -14,
      "y": 0,
      "z": -2,
      "name": "Rock_Stone_Cobble"
    },
    {
      "x": -14,
      "y": 1,
      "z": -2,
      "name": "Empty"
    },
    {
      "x": -14,
      "y": 2,
      "z": -2,
      "name": "Empty"
    },
    {
      "x": -14,
      "y": 3,
      "z": -2,
      "name": "Empty"
    },
    {
      "x": -14,
      "y": 4,
      "z": -2,
      "name": "Empty"
    },
    {
      "x": -14,
      "y": 5,
      "z": -2,
      "name": "Empty"
    },
    {
      "x": -14,
      "y": 6,
      "z": -2,
      "name": "Empty"
    },
    {
      "x": -14,
      "y": 7,
      "z": -2,
      "name": "Empty"
    },
    {
      "x": -14,
      "y": 8,
      "z": -2,
      "name": "Rock_Stone_Cobble"
    },
    {
      "x": -14,
      "y": 9,
      "z": -2,
      "name": "Rock_Stone"
    },
    {
      "x": -14,
      "y": 0,
      "z": -1,
      "name": "Wood_Softwood_Planks"
    },
    {
      "x": -14,
      "y": 1,
      "z": -1,
      "name": "Empty"
    },
    {
      "x": -14,
      "y": 2,
      "z": -1,
      "name": "Empty"
    },
    {
      "x": -14,
      "y": 3,
      "z": -1,
      "name": "Empty"
    },
    {
      "x": -14,
      "y": 4,
      "z": -1,
      "name": "Empty"
    },
    {
      "x": -14,
      "y": 5,
      "z": -1,
      "name": "Empty"
    },
    {
      "x": -14,
      "y": 6,
      "z": -1,
      "name": "Empty"
    },
    {
      "x": -14,
      "y": 7,
      "z": -1,
      "name": "Empty"
    },
    {
      "x": -14,
      "y": 8,
      "z": -1,
      "name": "Rock_Stone_Cobble"
    },
    {
      "x": -14,
      "y": 9,
      "z": -1,
      "name": "Rock_Stone"
    },
    {
      "x": -14,
      "y": 0,
      "z": 0,
      "name": "Wood_Softwood_Planks"
    },
    {
      "x": -14,
      "y": 1,
      "z": 0,
      "name": "Rail",
      "rotation": 1
    },
    {
      "x": -14,
      "y": 2,
      "z": 0,
      "name": "Empty"
    },
    {
      "x": -14,
      "y": 3,
      "z": 0,
      "name": "Empty"
    },
    {
      "x": -14,
      "y": 4,
      "z": 0,
      "name": "Empty"
    },
    {
      "x": -14,
      "y": 5,
      "z": 0,
      "name": "Empty"
    },
    {
      "x": -14,
      "y": 6,
      "z": 0,
      "name": "Empty"
    },
    {
      "x": -14,
      "y": 7,
      "z": 0,
      "name": "Empty"
    },
    {
      "x": -14,
      "y": 8,
      "z": 0,
      "name": "Rock_Stone_Cobble"
    },
    {
      "x": -14,
      "y": 9,
      "z": 0,
      "name": "Rock_Stone"
    },
    {
      "x": -14,
      "y": 0,
      "z": 1,
      "name": "Soil_Gravel"
    },
    {
      "x": -14,
      "y": 1,
      "z": 1,
      "name": "Empty"
    },
    {
      "x": -14,
      "y": 2,
      "z": 1,
      "name": "Empty"
    },
    {
      "x": -14,
      "y": 3,
      "z": 1,
      "name": "Empty"
    },
    {
      "x": -14,
      "y": 4,
      "z": 1,
      "name": "Empty"
    },
    {
      "x": -14,
      "y": 5,
      "z": 1,
      "name": "Empty"
    },
    {
      "x": -14,
      "y": 6,
      "z": 1,
      "name": "Empty"
    },
    {
      "x": -14,
      "y": 7,
      "z": 1,
      "name": "Empty"
    },
    {
      "x": -14,
      "y": 8,
      "z": 1,
      "name": "Rock_Stone_Cobble"
    },
    {
      "x": -14,
      "y": 9,
      "z": 1,
      "name": "Rock_Stone"
    },
    {
      "x": -14,
      "y": 0,
      "z": 2,
      "name": "Soil_Gravel"
    },
    {
      "x": -14,
      "y": 1,
      "z": 2,
      "name": "Empty"
    },
    {
      "x": -14,
      "y": 2,
      "z": 2,
      "name": "Empty"
    },
    {
      "x": -14,
      "y": 3,
      "z": 2,
      "name": "Empty"
    },
    {
      "x": -14,
      "y": 4,
      "z": 2,
      "name": "Empty"
    },
    {
      "x": -14,
      "y": 5,
      "z": 2,
      "name": "Empty"
    },
    {
      "x": -14,
      "y": 6,
      "z": 2,
      "name": "Empty"
    },
    {
      "x": -14,
      "y": 7,
      "z": 2,
      "name": "Rock_Stone_Cobble_Half",
      "rotation": 8
    },
    {
      "x": -14,
      "y": 8,
      "z": 2,
      "name": "Rock_Stone_Cobble"
    },
    {
      "x": -14,
      "y": 9,
      "z": 2,
      "name": "Rock_Stone"
    },
    {
      "x": -14,
      "y": 0,
      "z": 3,
      "name": "Rock_Stone"
    },
    {
      "x": -14,
      "y": 1,
      "z": 3,
      "name": "Empty"
    },
    {
      "x": -14,
      "y": 2,
      "z": 3,
      "name": "Empty"
    },
    {
      "x": -14,
      "y": 3,
      "z": 3,
      "name": "Empty"
    },
    {
      "x": -14,
      "y": 4,
      "z": 3,
      "name": "Empty"
    },
    {
      "x": -14,
      "y": 5,
      "z": 3,
      "name": "Empty"
    },
    {
      "x": -14,
      "y": 6,
      "z": 3,
      "name": "Wood_Softwood_Planks_Half",
      "rotation": 8
    },
    {
      "x": -14,
      "y": 7,
      "z": 3,
      "name": "Wood_Beech_Trunk",
      "rotation": 5
    },
    {
      "x": -14,
      "y": 8,
      "z": 3,
      "name": "Rock_Stone_Cobble"
    },
    {
      "x": -14,
      "y": 9,
      "z": 3,
      "name": "Rock_Stone"
    },
    {
      "x": -14,
      "y": 0,
      "z": 4,
      "name": "Rock_Stone"
    },
    {
      "x": -14,
      "y": 1,
      "z": 4,
      "name": "Rock_Stone_Cobble"
    },
    {
      "x": -14,
      "y": 2,
      "z": 4,
      "name": "Rock_Stone_Cobble"
    },
    {
      "x": -14,
      "y": 3,
      "z": 4,
      "name": "Empty"
    },
    {
      "x": -14,
      "y": 4,
      "z": 4,
      "name": "Empty"
    },
    {
      "x": -14,
      "y": 5,
      "z": 4,
      "name": "Rock_Stone"
    },
    {
      "x": -14,
      "y": 6,
      "z": 4,
      "name": "Rock_Stone"
    },
    {
      "x": -14,
      "y": 7,
      "z": 4,
      "name": "Rock_Stone"
    },
    {
      "x": -14,
      "y": 8,
      "z": 4,
      "name": "Rock_Stone"
    },
    {
      "x": -14,
      "y": 9,
      "z": 4,
      "name": "Rock_Stone"
    },
    {
      "x": -14,
      "y": 0,
      "z": 5,
      "name": "Rock_Stone"
    },
    {
      "x": -14,
      "y": 1,
      "z": 5,
      "name": "Empty"
    },
    {
      "x": -14,
      "y": 2,
      "z": 5,
      "name": "Empty"
    },
    {
      "x": -14,
      "y": 3,
      "z": 5,
      "name": "Empty"
    },
    {
      "x": -14,
      "y": 4,
      "z": 5,
      "name": "Rock_Stone"
    },
    {
      "x": -14,
      "y": 5,
      "z": 5,
      "name": "Rock_Stone"
    },
    {
      "x": -14,
      "y": 6,
      "z": 5,
      "name": "Rock_Stone"
    },
    {
      "x": -14,
      "y": 7,
      "z": 5,
      "name": "Rock_Stone"
    },
    {
      "x": -14,
      "y": 8,
      "z": 5,
      "name": "Rock_Stone"
    },
    {
      "x": -14,
      "y": 9,
      "z": 5,
      "name": "Rock_Stone"
    },
    {
      "x": -14,
      "y": 0,
      "z": 6,
      "name": "Rock_Stone"
    },
    {
      "x": -14,
      "y": 1,
      "z": 6,
      "name": "Empty"
    },
    {
      "x": -14,
      "y": 2,
      "z": 6,
      "name": "Empty"
    },
    {
      "x": -14,
      "y": 3,
      "z": 6,
      "name": "Empty"
    },
    {
      "x": -14,
      "y": 4,
      "z": 6,
      "name": "Empty"
    },
    {
      "x": -14,
      "y": 5,
      "z": 6,
      "name": "Empty"
    },
    {
      "x": -14,
      "y": 6,
      "z": 6,
      "name": "Empty"
    },
    {
      "x": -14,
      "y": 7,
      "z": 6,
      "name": "Rock_Stone"
    },
    {
      "x": -14,
      "y": 8,
      "z": 6,
      "name": "Rock_Stone"
    },
    {
      "x": -14,
      "y": 9,
      "z": 6,
      "name": "Rock_Stone"
    },
    {
      "x": -14,
      "y": 0,
      "z": 7,
      "name": "Soil_Gravel_Mossy"
    },
    {
      "x": -14,
      "y": 1,
      "z": 7,
      "name": "Empty"
    },
    {
      "x": -14,
      "y": 2,
      "z": 7,
      "name": "Empty"
    },
    {
      "x": -14,
      "y": 3,
      "z": 7,
      "name": "Empty"
    },
    {
      "x": -14,
      "y": 4,
      "z": 7,
      "name": "Empty"
    },
    {
      "x": -14,
      "y": 5,
      "z": 7,
      "name": "Empty"
    },
    {
      "x": -14,
      "y": 6,
      "z": 7,
      "name": "Empty"
    },
    {
      "x": -14,
      "y": 7,
      "z": 7,
      "name": "Rock_Stone"
    },
    {
      "x": -14,
      "y": 8,
      "z": 7,
      "name": "Rock_Stone"
    },
    {
      "x": -14,
      "y": 9,
      "z": 7,
      "name": "Rock_Stone"
    },
    {
      "x": -14,
      "y": 0,
      "z": 8,
      "name": "Soil_Gravel_Mossy"
    },
    {
      "x": -14,
      "y": 1,
      "z": 8,
      "name": "Empty"
    },
    {
      "x": -14,
      "y": 2,
      "z": 8,
      "name": "Empty"
    },
    {
      "x": -14,
      "y": 3,
      "z": 8,
      "name": "Empty"
    },
    {
      "x": -14,
      "y": 4,
      "z": 8,
      "name": "Empty"
    },
    {
      "x": -14,
      "y": 5,
      "z": 8,
      "name": "Empty"
    },
    {
      "x": -14,
      "y": 6,
      "z": 8,
      "name": "Empty"
    },
    {
      "x": -14,
      "y": 7,
      "z": 8,
      "name": "Rock_Stone"
    },
    {
      "x": -14,
      "y": 8,
      "z": 8,
      "name": "Rock_Stone"
    },
    {
      "x": -14,
      "y": 9,
      "z": 8,
      "name": "Rock_Stone"
    },
    {
      "x": -14,
      "y": 0,
      "z": 9,
      "name": "Rock_Stone"
    },
    {
      "x": -14,
      "y": 1,
      "z": 9,
      "name": "Plant_Moss_Rug_Green_Dark"
    },
    {
      "x": -14,
      "y": 2,
      "z": 9,
      "name": "Empty"
    },
    {
      "x": -14,
      "y": 3,
      "z": 9,
      "name": "Empty"
    },
    {
      "x": -14,
      "y": 4,
      "z": 9,
      "name": "Empty"
    },
    {
      "x": -14,
      "y": 5,
      "z": 9,
      "name": "Empty"
    },
    {
      "x": -14,
      "y": 6,
      "z": 9,
      "name": "Empty"
    },
    {
      "x": -14,
      "y": 7,
      "z": 9,
      "name": "Rock_Stone"
    },
    {
      "x": -14,
      "y": 8,
      "z": 9,
      "name": "Rock_Stone"
    },
    {
      "x": -14,
      "y": 9,
      "z": 9,
      "name": "Rock_Stone"
    },
    {
      "x": -14,
      "y": 0,
      "z": 10,
      "name": "Rock_Stone"
    },
    {
      "x": -14,
      "y": 1,
      "z": 10,
      "name": "Plant_Moss_Rug_Green_Dark"
    },
    {
      "x": -14,
      "y": 2,
      "z": 10,
      "name": "Empty"
    },
    {
      "x": -14,
      "y": 3,
      "z": 10,
      "name": "Empty"
    },
    {
      "x": -14,
      "y": 4,
      "z": 10,
      "name": "Empty"
    },
    {
      "x": -14,
      "y": 5,
      "z": 10,
      "name": "Rock_Stone"
    },
    {
      "x": -14,
      "y": 6,
      "z": 10,
      "name": "Rock_Stone"
    },
    {
      "x": -14,
      "y": 7,
      "z": 10,
      "name": "Rock_Stone"
    },
    {
      "x": -14,
      "y": 8,
      "z": 10,
      "name": "Rock_Stone"
    },
    {
      "x": -14,
      "y": 9,
      "z": 10,
      "name": "Rock_Stone"
    },
    {
      "x": -14,
      "y": 0,
      "z": 11,
      "name": "Rock_Stone"
    },
    {
      "x": -14,
      "y": 1,
      "z": 11,
      "name": "Rock_Stone"
    },
    {
      "x": -14,
      "y": 2,
      "z": 11,
      "name": "Rock_Stone"
    },
    {
      "x": -14,
      "y": 3,
      "z": 11,
      "name": "Rock_Stone"
    },
    {
      "x": -14,
      "y": 4,
      "z": 11,
      "name": "Rock_Stone"
    },
    {
      "x": -14,
      "y": 5,
      "z": 11,
      "name": "Rock_Stone"
    },
    {
      "x": -14,
      "y": 6,
      "z": 11,
      "name": "Rock_Stone"
    },
    {
      "x": -14,
      "y": 7,
      "z": 11,
      "name": "Rock_Stone"
    },
    {
      "x": -14,
      "y": 8,
      "z": 11,
      "name": "Rock_Stone"
    },
    {
      "x": -14,
      "y": 9,
      "z": 11,
      "name": "Rock_Stone"
    },
    {
      "x": -13,
      "y": 0,
      "z": -5,
      "name": "Rock_Stone"
    },
    {
      "x": -13,
      "y": 1,
      "z": -5,
      "name": "Rock_Stone"
    },
    {
      "x": -13,
      "y": 2,
      "z": -5,
      "name": "Rock_Stone"
    },
    {
      "x": -13,
      "y": 3,
      "z": -5,
      "name": "Rock_Stone"
    },
    {
      "x": -13,
      "y": 4,
      "z": -5,
      "name": "Rock_Stone"
    },
    {
      "x": -13,
      "y": 5,
      "z": -5,
      "name": "Rock_Stone"
    },
    {
      "x": -13,
      "y": 6,
      "z": -5,
      "name": "Rock_Stone"
    },
    {
      "x": -13,
      "y": 7,
      "z": -5,
      "name": "Rock_Stone"
    },
    {
      "x": -13,
      "y": 8,
      "z": -5,
      "name": "Rock_Stone"
    },
    {
      "x": -13,
      "y": 9,
      "z": -5,
      "name": "Rock_Stone"
    },
    {
      "x": -13,
      "y": 0,
      "z": -4,
      "name": "Rock_Stone"
    },
    {
      "x": -13,
      "y": 1,
      "z": -4,
      "name": "Rock_Stone_Cobble"
    },
    {
      "x": -13,
      "y": 2,
      "z": -4,
      "name": "Rock_Stone_Cobble"
    },
    {
      "x": -13,
      "y": 3,
      "z": -4,
      "name": "Rock_Stone_Cobble"
    },
    {
      "x": -13,
      "y": 4,
      "z": -4,
      "name": "Rock_Stone"
    },
    {
      "x": -13,
      "y": 5,
      "z": -4,
      "name": "Rock_Stone"
    },
    {
      "x": -13,
      "y": 6,
      "z": -4,
      "name": "Rock_Stone"
    },
    {
      "x": -13,
      "y": 7,
      "z": -4,
      "name": "Rock_Stone"
    },
    {
      "x": -13,
      "y": 8,
      "z": -4,
      "name": "Rock_Stone"
    },
    {
      "x": -13,
      "y": 9,
      "z": -4,
      "name": "Rock_Stone"
    },
    {
      "x": -13,
      "y": 0,
      "z": -3,
      "name": "Rock_Stone"
    },
    {
      "x": -13,
      "y": 1,
      "z": -3,
      "name": "Rock_Stone_Cobble"
    },
    {
      "x": -13,
      "y": 2,
      "z": -3,
      "name": "Empty"
    },
    {
      "x": -13,
      "y": 3,
      "z": -3,
      "name": "Empty"
    },
    {
      "x": -13,
      "y": 4,
      "z": -3,
      "name": "Empty"
    },
    {
      "x": -13,
      "y": 5,
      "z": -3,
      "name": "Empty"
    },
    {
      "x": -13,
      "y": 6,
      "z": -3,
      "name": "*Wood_Softwood_Planks_Half_State_Definitions_Block",
      "rotation": 8
    },
    {
      "x": -13,
      "y": 7,
      "z": -3,
      "name": "Wood_Beech_Trunk",
      "rotation": 5
    },
    {
      "x": -13,
      "y": 8,
      "z": -3,
      "name": "Rock_Stone_Cobble"
    },
    {
      "x": -13,
      "y": 9,
      "z": -3,
      "name": "Rock_Stone"
    },
    {
      "x": -13,
      "y": 0,
      "z": -2,
      "name": "Rock_Stone"
    },
    {
      "x": -13,
      "y": 1,
      "z": -2,
      "name": "Rock_Stone_Cobble"
    },
    {
      "x": -13,
      "y": 2,
      "z": -2,
      "name": "Empty"
    },
    {
      "x": -13,
      "y": 3,
      "z": -2,
      "name": "Empty"
    },
    {
      "x": -13,
      "y": 4,
      "z": -2,
      "name": "Empty"
    },
    {
      "x": -13,
      "y": 5,
      "z": -2,
      "name": "Empty"
    },
    {
      "x": -13,
      "y": 6,
      "z": -2,
      "name": "Empty"
    },
    {
      "x": -13,
      "y": 7,
      "z": -2,
      "name": "Empty"
    },
    {
      "x": -13,
      "y": 8,
      "z": -2,
      "name": "Rock_Stone_Cobble"
    },
    {
      "x": -13,
      "y": 9,
      "z": -2,
      "name": "Rock_Stone"
    },
    {
      "x": -13,
      "y": 0,
      "z": -1,
      "name": "Rock_Stone_Cobble"
    },
    {
      "x": -13,
      "y": 1,
      "z": -1,
      "name": "Empty"
    },
    {
      "x": -13,
      "y": 2,
      "z": -1,
      "name": "Empty"
    },
    {
      "x": -13,
      "y": 3,
      "z": -1,
      "name": "Empty"
    },
    {
      "x": -13,
      "y": 4,
      "z": -1,
      "name": "Empty"
    },
    {
      "x": -13,
      "y": 5,
      "z": -1,
      "name": "Empty"
    },
    {
      "x": -13,
      "y": 6,
      "z": -1,
      "name": "Empty"
    },
    {
      "x": -13,
      "y": 7,
      "z": -1,
      "name": "Empty"
    },
    {
      "x": -13,
      "y": 8,
      "z": -1,
      "name": "Rock_Stone_Cobble"
    },
    {
      "x": -13,
      "y": 9,
      "z": -1,
      "name": "Rock_Stone"
    },
    {
      "x": -13,
      "y": 0,
      "z": 0,
      "name": "Wood_Softwood_Planks"
    },
    {
      "x": -13,
      "y": 1,
      "z": 0,
      "name": "Empty"
    },
    {
      "x": -13,
      "y": 2,
      "z": 0,
      "name": "Empty"
    },
    {
      "x": -13,
      "y": 3,
      "z": 0,
      "name": "Empty"
    },
    {
      "x": -13,
      "y": 4,
      "z": 0,
      "name": "Empty"
    },
    {
      "x": -13,
      "y": 5,
      "z": 0,
      "name": "Empty"
    },
    {
      "x": -13,
      "y": 6,
      "z": 0,
      "name": "Empty"
    },
    {
      "x": -13,
      "y": 7,
      "z": 0,
      "name": "Wood_Softwood_Planks_Half",
      "rotation": 7
    },
    {
      "x": -13,
      "y": 8,
      "z": 0,
      "name": "Empty"
    },
    {
      "x": -13,
      "y": 9,
      "z": 0,
      "name": "Rock_Stone"
    },
    {
      "x": -13,
      "y": 0,
      "z": 1,
      "name": "Rock_Stone_Cobble"
    },
    {
      "x": -13,
      "y": 1,
      "z": 1,
      "name": "Empty"
    },
    {
      "x": -13,
      "y": 2,
      "z": 1,
      "name": "Empty"
    },
    {
      "x": -13,
      "y": 3,
      "z": 1,
      "name": "Empty"
    },
    {
      "x": -13,
      "y": 4,
      "z": 1,
      "name": "Empty"
    },
    {
      "x": -13,
      "y": 5,
      "z": 1,
      "name": "Empty"
    },
    {
      "x": -13,
      "y": 6,
      "z": 1,
      "name": "Empty"
    },
    {
      "x": -13,
      "y": 7,
      "z": 1,
      "name": "Empty"
    },
    {
      "x": -13,
      "y": 8,
      "z": 1,
      "name": "Empty"
    },
    {
      "x": -13,
      "y": 9,
      "z": 1,
      "name": "Rock_Stone"
    },
    {
      "x": -13,
      "y": 0,
      "z": 2,
      "name": "Soil_Gravel"
    },
    {
      "x": -13,
      "y": 1,
      "z": 2,
      "name": "Empty"
    },
    {
      "x": -13,
      "y": 2,
      "z": 2,
      "name": "Empty"
    },
    {
      "x": -13,
      "y": 3,
      "z": 2,
      "name": "Empty"
    },
    {
      "x": -13,
      "y": 4,
      "z": 2,
      "name": "Empty"
    },
    {
      "x": -13,
      "y": 5,
      "z": 2,
      "name": "Empty"
    },
    {
      "x": -13,
      "y": 6,
      "z": 2,
      "name": "Empty"
    },
    {
      "x": -13,
      "y": 7,
      "z": 2,
      "name": "Empty"
    },
    {
      "x": -13,
      "y": 8,
      "z": 2,
      "name": "Rock_Stone_Cobble"
    },
    {
      "x": -13,
      "y": 9,
      "z": 2,
      "name": "Rock_Stone"
    },
    {
      "x": -13,
      "y": 0,
      "z": 3,
      "name": "Rock_Stone"
    },
    {
      "x": -13,
      "y": 1,
      "z": 3,
      "name": "Rubble_Stone_Medium"
    },
    {
      "x": -13,
      "y": 2,
      "z": 3,
      "name": "Empty"
    },
    {
      "x": -13,
      "y": 3,
      "z": 3,
      "name": "Empty"
    },
    {
      "x": -13,
      "y": 4,
      "z": 3,
      "name": "Empty"
    },
    {
      "x": -13,
      "y": 5,
      "z": 3,
      "name": "Empty"
    },
    {
      "x": -13,
      "y": 6,
      "z": 3,
      "name": "*Wood_Softwood_Planks_Half_State_Definitions_Block",
      "rotation": 8
    },
    {
      "x": -13,
      "y": 7,
      "z": 3,
      "name": "Wood_Beech_Trunk",
      "rotation": 5
    },
    {
      "x": -13,
      "y": 8,
      "z": 3,
      "name": "Rock_Stone_Cobble"
    },
    {
      "x": -13,
      "y": 9,
      "z": 3,
      "name": "Rock_Stone"
    },
    {
      "x": -13,
      "y": 0,
      "z": 4,
      "name": "Rock_Stone"
    },
    {
      "x": -13,
      "y": 1,
      "z": 4,
      "name": "Rock_Stone_Cobble"
    },
    {
      "x": -13,
      "y": 2,
      "z": 4,
      "name": "Rock_Stone_Cobble"
    },
    {
      "x": -13,
      "y": 3,
      "z": 4,
      "name": "Rock_Stone_Cobble"
    },
    {
      "x": -13,
      "y": 4,
      "z": 4,
      "name": "Empty"
    },
    {
      "x": -13,
      "y": 5,
      "z": 4,
      "name": "Rock_Stone"
    },
    {
      "x": -13,
      "y": 6,
      "z": 4,
      "name": "Rock_Stone"
    },
    {
      "x": -13,
      "y": 7,
      "z": 4,
      "name": "Rock_Stone"
    },
    {
      "x": -13,
      "y": 8,
      "z": 4,
      "name": "Rock_Stone"
    },
    {
      "x": -13,
      "y": 9,
      "z": 4,
      "name": "Rock_Stone"
    },
    {
      "x": -13,
      "y": 0,
      "z": 5,
      "name": "Rock_Stone"
    },
    {
      "x": -13,
      "y": 1,
      "z": 5,
      "name": "Rock_Stone"
    },
    {
      "x": -13,
      "y": 2,
      "z": 5,
      "name": "Rock_Stone"
    },
    {
      "x": -13,
      "y": 3,
      "z": 5,
      "name": "Rock_Stone"
    },
    {
      "x": -13,
      "y": 4,
      "z": 5,
      "name": "Rock_Stone"
    },
    {
      "x": -13,
      "y": 5,
      "z": 5,
      "name": "Rock_Stone"
    },
    {
      "x": -13,
      "y": 6,
      "z": 5,
      "name": "Rock_Stone"
    },
    {
      "x": -13,
      "y": 7,
      "z": 5,
      "name": "Rock_Stone"
    },
    {
      "x": -13,
      "y": 8,
      "z": 5,
      "name": "Rock_Stone"
    },
    {
      "x": -13,
      "y": 9,
      "z": 5,
      "name": "Rock_Stone"
    },
    {
      "x": -13,
      "y": -1,
      "z": 6,
      "name": "Rock_Stone"
    },
    {
      "x": -13,
      "y": 0,
      "z": 6,
      "name": "Soil_Gravel_Mossy"
    },
    {
      "x": -13,
      "y": 1,
      "z": 6,
      "name": "Plant_Moss_Wall_Green_Dark",
      "rotation": 3
    },
    {
      "x": -13,
      "y": 2,
      "z": 6,
      "name": "Empty"
    },
    {
      "x": -13,
      "y": 3,
      "z": 6,
      "name": "Empty"
    },
    {
      "x": -13,
      "y": 4,
      "z": 6,
      "name": "Rock_Stone_Stalactite_Large",
      "filler": 31744,
      "rotation": 8
    },
    {
      "x": -13,
      "y": 5,
      "z": 6,
      "name": "Rock_Stone_Stalactite_Large",
      "rotation": 8
    },
    {
      "x": -13,
      "y": 6,
      "z": 6,
      "name": "Rock_Stone"
    },
    {
      "x": -13,
      "y": 7,
      "z": 6,
      "name": "Rock_Stone"
    },
    {
      "x": -13,
      "y": 8,
      "z": 6,
      "name": "Rock_Stone"
    },
    {
      "x": -13,
      "y": 9,
      "z": 6,
      "name": "Rock_Stone"
    },
    {
      "x": -13,
      "y": -1,
      "z": 7,
      "name": "Rock_Stone"
    },
    {
      "x": -13,
      "y": 0,
      "z": 7,
      "name": "Soil_Gravel_Mossy"
    },
    {
      "x": -13,
      "y": 1,
      "z": 7,
      "name": "Empty"
    },
    {
      "x": -13,
      "y": 2,
      "z": 7,
      "name": "Empty"
    },
    {
      "x": -13,
      "y": 3,
      "z": 7,
      "name": "Empty"
    },
    {
      "x": -13,
      "y": 4,
      "z": 7,
      "name": "Empty"
    },
    {
      "x": -13,
      "y": 5,
      "z": 7,
      "name": "Empty"
    },
    {
      "x": -13,
      "y": 6,
      "z": 7,
      "name": "Empty"
    },
    {
      "x": -13,
      "y": 7,
      "z": 7,
      "name": "Rock_Stone"
    },
    {
      "x": -13,
      "y": 8,
      "z": 7,
      "name": "Rock_Stone"
    },
    {
      "x": -13,
      "y": 9,
      "z": 7,
      "name": "Rock_Stone"
    },
    {
      "x": -13,
      "y": -1,
      "z": 8,
      "name": "Rock_Stone"
    },
    {
      "x": -13,
      "y": 0,
      "z": 8,
      "name": "Soil_Gravel_Mossy"
    },
    {
      "x": -13,
      "y": 1,
      "z": 8,
      "name": "Empty"
    },
    {
      "x": -13,
      "y": 2,
      "z": 8,
      "name": "Empty"
    },
    {
      "x": -13,
      "y": 3,
      "z": 8,
      "name": "Empty"
    },
    {
      "x": -13,
      "y": 4,
      "z": 8,
      "name": "Empty"
    },
    {
      "x": -13,
      "y": 5,
      "z": 8,
      "name": "Empty"
    },
    {
      "x": -13,
      "y": 6,
      "z": 8,
      "name": "Empty"
    },
    {
      "x": -13,
      "y": 7,
      "z": 8,
      "name": "Rock_Stone"
    },
    {
      "x": -13,
      "y": 8,
      "z": 8,
      "name": "Rock_Stone"
    },
    {
      "x": -13,
      "y": 9,
      "z": 8,
      "name": "Rock_Stone"
    },
    {
      "x": -13,
      "y": -1,
      "z": 9,
      "name": "Rock_Stone"
    },
    {
      "x": -13,
      "y": 0,
      "z": 9,
      "name": "Soil_Gravel_Mossy"
    },
    {
      "x": -13,
      "y": 1,
      "z": 9,
      "name": "Empty"
    },
    {
      "x": -13,
      "y": 2,
      "z": 9,
      "name": "Empty"
    },
    {
      "x": -13,
      "y": 3,
      "z": 9,
      "name": "Empty"
    },
    {
      "x": -13,
      "y": 4,
      "z": 9,
      "name": "Empty"
    },
    {
      "x": -13,
      "y": 5,
      "z": 9,
      "name": "Empty"
    },
    {
      "x": -13,
      "y": 6,
      "z": 9,
      "name": "Rock_Stone"
    },
    {
      "x": -13,
      "y": 7,
      "z": 9,
      "name": "Rock_Stone"
    },
    {
      "x": -13,
      "y": 8,
      "z": 9,
      "name": "Rock_Stone"
    },
    {
      "x": -13,
      "y": 9,
      "z": 9,
      "name": "Rock_Stone"
    },
    {
      "x": -13,
      "y": 0,
      "z": 10,
      "name": "Rock_Stone"
    },
    {
      "x": -13,
      "y": 1,
      "z": 10,
      "name": "Plant_Moss_Rug_Green_Dark"
    },
    {
      "x": -13,
      "y": 2,
      "z": 10,
      "name": "Empty"
    },
    {
      "x": -13,
      "y": 3,
      "z": 10,
      "name": "Empty"
    },
    {
      "x": -13,
      "y": 4,
      "z": 10,
      "name": "Empty"
    },
    {
      "x": -13,
      "y": 5,
      "z": 10,
      "name": "Empty"
    },
    {
      "x": -13,
      "y": 6,
      "z": 10,
      "name": "Rock_Stone"
    },
    {
      "x": -13,
      "y": 7,
      "z": 10,
      "name": "Rock_Stone"
    },
    {
      "x": -13,
      "y": 8,
      "z": 10,
      "name": "Rock_Stone"
    },
    {
      "x": -13,
      "y": 9,
      "z": 10,
      "name": "Rock_Stone"
    },
    {
      "x": -13,
      "y": 0,
      "z": 11,
      "name": "Rock_Stone"
    },
    {
      "x": -13,
      "y": 1,
      "z": 11,
      "name": "Rock_Stone"
    },
    {
      "x": -13,
      "y": 2,
      "z": 11,
      "name": "Rock_Stone"
    },
    {
      "x": -13,
      "y": 3,
      "z": 11,
      "name": "Rock_Stone"
    },
    {
      "x": -13,
      "y": 4,
      "z": 11,
      "name": "Rock_Stone"
    },
    {
      "x": -13,
      "y": 5,
      "z": 11,
      "name": "Rock_Stone"
    },
    {
      "x": -13,
      "y": 6,
      "z": 11,
      "name": "Rock_Stone"
    },
    {
      "x": -13,
      "y": 7,
      "z": 11,
      "name": "Rock_Stone"
    },
    {
      "x": -13,
      "y": 8,
      "z": 11,
      "name": "Rock_Stone"
    },
    {
      "x": -13,
      "y": 9,
      "z": 11,
      "name": "Rock_Stone"
    },
    {
      "x": -12,
      "y": 0,
      "z": -5,
      "name": "Rock_Stone"
    },
    {
      "x": -12,
      "y": 1,
      "z": -5,
      "name": "Rock_Stone"
    },
    {
      "x": -12,
      "y": 2,
      "z": -5,
      "name": "Rock_Stone"
    },
    {
      "x": -12,
      "y": 3,
      "z": -5,
      "name": "Rock_Stone"
    },
    {
      "x": -12,
      "y": 4,
      "z": -5,
      "name": "Rock_Stone"
    },
    {
      "x": -12,
      "y": 5,
      "z": -5,
      "name": "Rock_Stone"
    },
    {
      "x": -12,
      "y": 6,
      "z": -5,
      "name": "Rock_Stone"
    },
    {
      "x": -12,
      "y": 7,
      "z": -5,
      "name": "Rock_Stone"
    },
    {
      "x": -12,
      "y": 8,
      "z": -5,
      "name": "Rock_Stone"
    },
    {
      "x": -12,
      "y": 9,
      "z": -5,
      "name": "Rock_Stone"
    },
    {
      "x": -12,
      "y": 0,
      "z": -4,
      "name": "Rock_Stone"
    },
    {
      "x": -12,
      "y": 1,
      "z": -4,
      "name": "Rock_Stone_Cobble"
    },
    {
      "x": -12,
      "y": 2,
      "z": -4,
      "name": "Rock_Stone_Cobble"
    },
    {
      "x": -12,
      "y": 3,
      "z": -4,
      "name": "Rock_Stone_Cobble"
    },
    {
      "x": -12,
      "y": 4,
      "z": -4,
      "name": "Rock_Stone"
    },
    {
      "x": -12,
      "y": 5,
      "z": -4,
      "name": "Rock_Stone"
    },
    {
      "x": -12,
      "y": 6,
      "z": -4,
      "name": "Rock_Stone"
    },
    {
      "x": -12,
      "y": 7,
      "z": -4,
      "name": "Rock_Stone"
    },
    {
      "x": -12,
      "y": 8,
      "z": -4,
      "name": "Rock_Stone"
    },
    {
      "x": -12,
      "y": 9,
      "z": -4,
      "name": "Rock_Stone"
    },
    {
      "x": -12,
      "y": 0,
      "z": -3,
      "name": "Rock_Stone"
    },
    {
      "x": -12,
      "y": 1,
      "z": -3,
      "name": "Wood_Beech_Trunk"
    },
    {
      "x": -12,
      "y": 2,
      "z": -3,
      "name": "Wood_Beech_Trunk"
    },
    {
      "x": -12,
      "y": 3,
      "z": -3,
      "name": "Wood_Beech_Trunk"
    },
    {
      "x": -12,
      "y": 4,
      "z": -3,
      "name": "Wood_Beech_Trunk"
    },
    {
      "x": -12,
      "y": 5,
      "z": -3,
      "name": "Wood_Beech_Trunk"
    },
    {
      "x": -12,
      "y": 6,
      "z": -3,
      "name": "Wood_Beech_Trunk"
    },
    {
      "x": -12,
      "y": 7,
      "z": -3,
      "name": "Wood_Beech_Trunk",
      "rotation": 4
    },
    {
      "x": -12,
      "y": 8,
      "z": -3,
      "name": "Rock_Stone"
    },
    {
      "x": -12,
      "y": 9,
      "z": -3,
      "name": "Rock_Stone"
    },
    {
      "x": -12,
      "y": 0,
      "z": -2,
      "name": "Rock_Stone"
    },
    {
      "x": -12,
      "y": 1,
      "z": -2,
      "name": "Rock_Stone_Cobble"
    },
    {
      "x": -12,
      "y": 2,
      "z": -2,
      "name": "Rock_Stone"
    },
    {
      "x": -12,
      "y": 3,
      "z": -2,
      "name": "Empty"
    },
    {
      "x": -12,
      "y": 4,
      "z": -2,
      "name": "Empty"
    },
    {
      "x": -12,
      "y": 5,
      "z": -2,
      "name": "Empty"
    },
    {
      "x": -12,
      "y": 6,
      "z": -2,
      "name": "*Wood_Softwood_Planks_Half_State_Definitions_Block",
      "rotation": 8
    },
    {
      "x": -12,
      "y": 7,
      "z": -2,
      "name": "Wood_Beech_Trunk",
      "rotation": 4
    },
    {
      "x": -12,
      "y": 8,
      "z": -2,
      "name": "Rock_Stone"
    },
    {
      "x": -12,
      "y": 9,
      "z": -2,
      "name": "Rock_Stone"
    },
    {
      "x": -12,
      "y": 0,
      "z": -1,
      "name": "Rock_Stone"
    },
    {
      "x": -12,
      "y": 1,
      "z": -1,
      "name": "Rock_Stone_Cobble"
    },
    {
      "x": -12,
      "y": 2,
      "z": -1,
      "name": "Rock_Stone"
    },
    {
      "x": -12,
      "y": 3,
      "z": -1,
      "name": "Empty"
    },
    {
      "x": -12,
      "y": 4,
      "z": -1,
      "name": "Empty"
    },
    {
      "x": -12,
      "y": 5,
      "z": -1,
      "name": "Empty"
    },
    {
      "x": -12,
      "y": 6,
      "z": -1,
      "name": "Wood_Softwood_Planks_Half",
      "rotation": 8
    },
    {
      "x": -12,
      "y": 7,
      "z": -1,
      "name": "Wood_Beech_Trunk",
      "rotation": 4
    },
    {
      "x": -12,
      "y": 8,
      "z": -1,
      "name": "Rock_Stone"
    },
    {
      "x": -12,
      "y": 9,
      "z": -1,
      "name": "Rock_Stone"
    },
    {
      "x": -12,
      "y": 0,
      "z": 0,
      "name": "Rock_Stone"
    },
    {
      "x": -12,
      "y": 1,
      "z": 0,
      "name": "Rock_Stone_Cobble"
    },
    {
      "x": -12,
      "y": 2,
      "z": 0,
      "name": "Rock_Stone_Cobble_Half"
    },
    {
      "x": -12,
      "y": 3,
      "z": 0,
      "name": "Empty"
    },
    {
      "x": -12,
      "y": 4,
      "z": 0,
      "name": "Empty"
    },
    {
      "x": -12,
      "y": 5,
      "z": 0,
      "name": "Empty"
    },
    {
      "x": -12,
      "y": 6,
      "z": 0,
      "name": "Wood_Softwood_Planks_Half",
      "rotation": 8
    },
    {
      "x": -12,
      "y": 7,
      "z": 0,
      "name": "Wood_Beech_Trunk",
      "rotation": 4
    },
    {
      "x": -12,
      "y": 8,
      "z": 0,
      "name": "Empty"
    },
    {
      "x": -12,
      "y": 9,
      "z": 0,
      "name": "Rock_Stone"
    },
    {
      "x": -12,
      "y": 0,
      "z": 1,
      "name": "Rock_Stone_Cobble"
    },
    {
      "x": -12,
      "y": 1,
      "z": 1,
      "name": "Rock_Stone_Cobble_Half"
    },
    {
      "x": -12,
      "y": 2,
      "z": 1,
      "name": "Empty"
    },
    {
      "x": -12,
      "y": 3,
      "z": 1,
      "name": "Empty"
    },
    {
      "x": -12,
      "y": 4,
      "z": 1,
      "name": "Empty"
    },
    {
      "x": -12,
      "y": 5,
      "z": 1,
      "name": "Empty"
    },
    {
      "x": -12,
      "y": 6,
      "z": 1,
      "name": "Wood_Softwood_Planks_Half",
      "rotation": 8
    },
    {
      "x": -12,
      "y": 7,
      "z": 1,
      "name": "Wood_Beech_Trunk",
      "rotation": 4
    },
    {
      "x": -12,
      "y": 8,
      "z": 1,
      "name": "Empty"
    },
    {
      "x": -12,
      "y": 9,
      "z": 1,
      "name": "Rock_Stone"
    },
    {
      "x": -12,
      "y": 0,
      "z": 2,
      "name": "Rock_Stone"
    },
    {
      "x": -12,
      "y": 1,
      "z": 2,
      "name": "Rubble_Stone"
    },
    {
      "x": -12,
      "y": 2,
      "z": 2,
      "name": "Empty"
    },
    {
      "x": -12,
      "y": 3,
      "z": 2,
      "name": "Empty"
    },
    {
      "x": -12,
      "y": 4,
      "z": 2,
      "name": "Empty"
    },
    {
      "x": -12,
      "y": 5,
      "z": 2,
      "name": "Empty"
    },
    {
      "x": -12,
      "y": 6,
      "z": 2,
      "name": "*Wood_Softwood_Planks_Half_State_Definitions_Block",
      "rotation": 8
    },
    {
      "x": -12,
      "y": 7,
      "z": 2,
      "name": "Wood_Beech_Trunk",
      "rotation": 4
    },
    {
      "x": -12,
      "y": 8,
      "z": 2,
      "name": "Empty"
    },
    {
      "x": -12,
      "y": 9,
      "z": 2,
      "name": "Rock_Stone"
    },
    {
      "x": -12,
      "y": 0,
      "z": 3,
      "name": "Rock_Stone"
    },
    {
      "x": -12,
      "y": 1,
      "z": 3,
      "name": "Wood_Beech_Trunk"
    },
    {
      "x": -12,
      "y": 2,
      "z": 3,
      "name": "Wood_Beech_Trunk"
    },
    {
      "x": -12,
      "y": 3,
      "z": 3,
      "name": "Wood_Beech_Trunk"
    },
    {
      "x": -12,
      "y": 4,
      "z": 3,
      "name": "Wood_Beech_Trunk"
    },
    {
      "x": -12,
      "y": 5,
      "z": 3,
      "name": "Wood_Beech_Trunk"
    },
    {
      "x": -12,
      "y": 6,
      "z": 3,
      "name": "Wood_Beech_Trunk"
    },
    {
      "x": -12,
      "y": 7,
      "z": 3,
      "name": "Wood_Beech_Trunk",
      "rotation": 5
    },
    {
      "x": -12,
      "y": 8,
      "z": 3,
      "name": "Empty"
    },
    {
      "x": -12,
      "y": 9,
      "z": 3,
      "name": "Rock_Stone"
    },
    {
      "x": -12,
      "y": 0,
      "z": 4,
      "name": "Rock_Stone"
    },
    {
      "x": -12,
      "y": 1,
      "z": 4,
      "name": "Rock_Stone_Cobble"
    },
    {
      "x": -12,
      "y": 2,
      "z": 4,
      "name": "Rock_Stone_Cobble"
    },
    {
      "x": -12,
      "y": 3,
      "z": 4,
      "name": "Empty"
    },
    {
      "x": -12,
      "y": 4,
      "z": 4,
      "name": "Rock_Stone"
    },
    {
      "x": -12,
      "y": 5,
      "z": 4,
      "name": "Rock_Stone"
    },
    {
      "x": -12,
      "y": 6,
      "z": 4,
      "name": "Rock_Stone"
    },
    {
      "x": -12,
      "y": 7,
      "z": 4,
      "name": "Rock_Stone"
    },
    {
      "x": -12,
      "y": 8,
      "z": 4,
      "name": "Rock_Stone"
    },
    {
      "x": -12,
      "y": 9,
      "z": 4,
      "name": "Rock_Stone"
    },
    {
      "x": -12,
      "y": 0,
      "z": 5,
      "name": "Rock_Stone"
    },
    {
      "x": -12,
      "y": 1,
      "z": 5,
      "name": "Rock_Stone"
    },
    {
      "x": -12,
      "y": 2,
      "z": 5,
      "name": "Rock_Stone"
    },
    {
      "x": -12,
      "y": 3,
      "z": 5,
      "name": "Rock_Stone"
    },
    {
      "x": -12,
      "y": 4,
      "z": 5,
      "name": "Rock_Stone"
    },
    {
      "x": -12,
      "y": 5,
      "z": 5,
      "name": "Rock_Stone"
    },
    {
      "x": -12,
      "y": 6,
      "z": 5,
      "name": "Rock_Stone"
    },
    {
      "x": -12,
      "y": 7,
      "z": 5,
      "name": "Rock_Stone"
    },
    {
      "x": -12,
      "y": 8,
      "z": 5,
      "name": "Rock_Stone"
    },
    {
      "x": -12,
      "y": 9,
      "z": 5,
      "name": "Rock_Stone"
    },
    {
      "x": -12,
      "y": -1,
      "z": 6,
      "name": "Rock_Stone"
    },
    {
      "x": -12,
      "y": 0,
      "z": 6,
      "name": "Rock_Stone"
    },
    {
      "x": -12,
      "y": 1,
      "z": 6,
      "name": "Rock_Stone"
    },
    {
      "x": -12,
      "y": 2,
      "z": 6,
      "name": "Plant_Moss_Rug_Green_Dark"
    },
    {
      "x": -12,
      "y": 3,
      "z": 6,
      "name": "Empty"
    },
    {
      "x": -12,
      "y": 4,
      "z": 6,
      "name": "Empty"
    },
    {
      "x": -12,
      "y": 5,
      "z": 6,
      "name": "Empty"
    },
    {
      "x": -12,
      "y": 6,
      "z": 6,
      "name": "Rock_Stone"
    },
    {
      "x": -12,
      "y": 7,
      "z": 6,
      "name": "Rock_Stone"
    },
    {
      "x": -12,
      "y": 8,
      "z": 6,
      "name": "Rock_Stone"
    },
    {
      "x": -12,
      "y": 9,
      "z": 6,
      "name": "Rock_Stone"
    },
    {
      "x": -12,
      "y": -1,
      "z": 7,
      "name": "Soil_Gravel_Mossy"
    },
    {
      "x": -12,
      "y": 0,
      "z": 7,
      "name": "Soil_Gravel_Mossy"
    },
    {
      "x": -12,
      "y": 1,
      "z": 7,
      "name": "Plant_Moss_Wall_Green_Dark"
    },
    {
      "x": -12,
      "y": 2,
      "z": 7,
      "name": "Empty"
    },
    {
      "x": -12,
      "y": 3,
      "z": 7,
      "name": "Empty"
    },
    {
      "x": -12,
      "y": 4,
      "z": 7,
      "name": "Empty"
    },
    {
      "x": -12,
      "y": 5,
      "z": 7,
      "name": "Empty"
    },
    {
      "x": -12,
      "y": 6,
      "z": 7,
      "name": "Empty"
    },
    {
      "x": -12,
      "y": 7,
      "z": 7,
      "name": "Rock_Stone"
    },
    {
      "x": -12,
      "y": 8,
      "z": 7,
      "name": "Rock_Stone"
    },
    {
      "x": -12,
      "y": 9,
      "z": 7,
      "name": "Rock_Stone"
    },
    {
      "x": -12,
      "y": -1,
      "z": 8,
      "name": "Soil_Gravel_Mossy"
    },
    {
      "x": -12,
      "y": 0,
      "z": 8,
      "name": "Empty"
    },
    {
      "x": -12,
      "y": 1,
      "z": 8,
      "name": "Empty"
    },
    {
      "x": -12,
      "y": 2,
      "z": 8,
      "name": "Empty"
    },
    {
      "x": -12,
      "y": 3,
      "z": 8,
