{
  "version": 8,
  "blockIdVersion": 8,
  "anchorX": 0,
  "anchorY": 4,
  "anchorZ": 1,
  "blocks": [
    {
      "x": -2,
      "y": 4,
      "z": 2,
      "name": "Soil_Leaves"
    },
    {
      "x": -2,
      "y": 4,
      "z": 3,
      "name": "Soil_Leaves"
    },
    {
      "x": -1,
      "y": 3,
      "z": 0,
      "name": "Soil_Dirt"
    },
    {
      "x": -1,
      "y": 4,
      "z": 0,
      "name": "Soil_Grass"
    },
    {
      "x": -1,
      "y": 5,
      "z": 0,
      "name": "Furniture_Kweebec_Stool"
    },
    {
      "x": -1,
      "y": 3,
      "z": 1,
      "name": "Soil_Dirt"
    },
    {
      "x": -1,
      "y": 4,
      "z": 1,
      "name": "Soil_Leaves"
    },
    {
      "x": -1,
      "y": 5,
      "z": 1,
      "name": "Furniture_Kweebec_Stool"
    },
    {
      "x": -1,
      "y": 3,
      "z": 2,
      "name": "Soil_Dirt"
    },
    {
      "x": -1,
      "y": 4,
      "z": 2,
      "name": "Soil_Leaves"
    },
    {
      "x": -1,
      "y": 5,
      "z": 2,
      "name": "Furniture_Kweebec_Stool"
    },
    {
      "x": -1,
      "y": 4,
      "z": 3,
      "name": "Soil_Leaves"
    },
    {
      "x": 0,
      "y": 4,
      "z": -1,
      "name": "Soil_Leaves"
    },
    {
      "x": 0,
      "y": 3,
      "z": 0,
      "name": "Soil_Dirt"
    },
    {
      "x": 0,
      "y": 4,
      "z": 0,
      "name": "Soil_Dirt"
    },
    {
      "x": 0,
      "y": 5,
      "z": 0,
      "name": "Wood_Oak_Trunk",
      "rotation": 4
    },
    {
      "x": 0,
      "y": 6,
      "z": 0,
      "name": "Plant_Fruit_Apple"
    },
    {
      "x": 0,
      "y": 3,
      "z": 1,
      "name": "Soil_Dirt"
    },
    {
      "x": 0,
      "y": 4,
      "z": 1,
      "name": "Soil_Dirt"
    },
    {
      "x": 0,
      "y": 5,
      "z": 1,
      "name": "Wood_Oak_Trunk",
      "rotation": 4
    },
    {
      "x": 0,
      "y": 3,
      "z": 2,
      "name": "Soil_Dirt"
    },
    {
      "x": 0,
      "y": 4,
      "z": 2,
      "name": "Soil_Dirt"
    },
    {
      "x": 0,
      "y": 5,
      "z": 2,
      "name": "Wood_Oak_Trunk",
      "rotation": 4
    },
    {
      "x": 0,
      "y": 6,
      "z": 2,
      "name": "Plant_Flower_Tall_Yellow"
    },
    {
      "x": 0,
      "y": 4,
      "z": 3,
      "name": "Soil_Leaves"
    },
    {
      "x": 1,
      "y": 4,
      "z": -1,
      "name": "Soil_Leaves"
    },
    {
      "x": 1,
      "y": 3,
      "z": 0,
      "name": "Soil_Dirt"
    },
    {
      "x": 1,
      "y": 4,
      "z": 0,
      "name": "Soil_Grass"
    },
    {
      "x": 1,
      "y": 5,
      "z": 0,
      "name": "Furniture_Kweebec_Stool"
    },
    {
      "x": 1,
      "y": 3,
      "z": 1,
      "name": "Soil_Dirt"
    },
    {
      "x": 1,
      "y": 4,
      "z": 1,
      "name": "Soil_Grass"
    },
    {
      "x": 1,
      "y": 5,
      "z": 1,
      "name": "Furniture_Kweebec_Stool"
    },
    {
      "x": 1,
      "y": 3,
      "z": 2,
      "name": "Soil_Dirt"
    },
    {
      "x": 1,
      "y": 4,
      "z": 2,
      "name": "Soil_Grass"
    },
    {
      "x": 1,
      "y": 5,
      "z": 2,
      "name": "Furniture_Kweebec_Stool"
    },
    {
      "x": 2,
      "y": 4,
      "z": -1,
      "name": "Soil_Leaves"
    },
    {
      "x": 2,
      "y": 4,
      "z": 0,
      "name": "Soil_Leaves"
    }
  ]
}