{
  "version": 8,
  "blockIdVersion": 8,
  "anchorX": 4,
  "anchorY": 32,
  "anchorZ": 0,
  "blocks": [
    {
      "x": -18,
      "y": 11,
      "z": -17,
      "name": "Rock_Volcanic"
    },
    {
      "x": -18,
      "y": 12,
      "z": -17,
      "name": "Rock_Volcanic"
    },
    {
      "x": -18,
      "y": 13,
      "z": -17,
      "name": "Rock_Volcanic"
    },
    {
      "x": -18,
      "y": 14,
      "z": -17,
      "name": "Rock_Volcanic"
    },
    {
      "x": -18,
      "y": 15,
      "z": -17,
      "name": "Rock_Volcanic"
    },
    {
      "x": -18,
      "y": 16,
      "z": -17,
      "name": "Rock_Volcanic"
    },
    {
      "x": -18,
      "y": 17,
      "z": -17,
      "name": "Rock_Volcanic"
    },
    {
      "x": -18,
      "y": 18,
      "z": -17,
      "name": "Rock_Volcanic"
    },
    {
      "x": -18,
      "y": 11,
      "z": -16,
      "name": "Rock_Volcanic"
    },
    {
      "x": -18,
      "y": 12,
      "z": -16,
      "name": "Rock_Volcanic"
    },
    {
      "x": -18,
      "y": 13,
      "z": -16,
      "name": "Rock_Volcanic"
    },
    {
      "x": -18,
      "y": 14,
      "z": -16,
      "name": "Rock_Volcanic"
    },
    {
      "x": -18,
      "y": 15,
      "z": -16,
      "name": "Rock_Volcanic"
    },
    {
      "x": -18,
      "y": 16,
      "z": -16,
      "name": "Rock_Volcanic"
    },
    {
      "x": -18,
      "y": 17,
      "z": -16,
      "name": "Rock_Volcanic"
    },
    {
      "x": -18,
      "y": 18,
      "z": -16,
      "name": "Rock_Volcanic"
    },
    {
      "x": -18,
      "y": 11,
      "z": -15,
      "name": "Rock_Volcanic"
    },
    {
      "x": -18,
      "y": 12,
      "z": -15,
      "name": "Rock_Volcanic"
    },
    {
      "x": -18,
      "y": 13,
      "z": -15,
      "name": "Rock_Volcanic"
    },
    {
      "x": -18,
      "y": 14,
      "z": -15,
      "name": "Rock_Volcanic"
    },
    {
      "x": -18,
      "y": 15,
      "z": -15,
      "name": "Rock_Volcanic"
    },
    {
      "x": -18,
      "y": 16,
      "z": -15,
      "name": "Rock_Volcanic"
    },
    {
      "x": -18,
      "y": 17,
      "z": -15,
      "name": "Rock_Volcanic"
    },
    {
      "x": -18,
      "y": 28,
      "z": -11,
      "name": "Rock_Volcanic"
    },
    {
      "x": -18,
      "y": 29,
      "z": -11,
      "name": "Rock_Volcanic"
    },
    {
      "x": -18,
      "y": 27,
      "z": -10,
      "name": "Rock_Volcanic"
    },
    {
      "x": -18,
      "y": 28,
      "z": -10,
      "name": "Rock_Volcanic"
    },
    {
      "x": -18,
      "y": 29,
      "z": -10,
      "name": "Rock_Volcanic"
    },
    {
      "x": -18,
      "y": 30,
      "z": -10,
      "name": "Rock_Volcanic"
    },
    {
      "x": -18,
      "y": 31,
      "z": -10,
      "name": "Rock_Volcanic"
    },
    {
      "x": -18,
      "y": 32,
      "z": -10,
      "name": "Rock_Volcanic"
    },
    {
      "x": -18,
      "y": 27,
      "z": -9,
      "name": "Rock_Volcanic"
    },
    {
      "x": -18,
      "y": 28,
      "z": -9,
      "name": "Rock_Volcanic"
    },
    {
      "x": -18,
      "y": 29,
      "z": -9,
      "name": "Rock_Volcanic"
    },
    {
      "x": -18,
      "y": 30,
      "z": -9,
      "name": "Rock_Volcanic"
    },
    {
      "x": -18,
      "y": 31,
      "z": -9,
      "name": "Rock_Volcanic"
    },
    {
      "x": -18,
      "y": 32,
      "z": -9,
      "name": "Rock_Volcanic"
    },
    {
      "x": -18,
      "y": 33,
      "z": -9,
      "name": "Rock_Volcanic"
    },
    {
      "x": -18,
      "y": 34,
      "z": -9,
      "name": "Rock_Volcanic"
    },
    {
      "x": -18,
      "y": 30,
      "z": -8,
      "name": "Rock_Volcanic"
    },
    {
      "x": -18,
      "y": 31,
      "z": -8,
      "name": "Rock_Volcanic"
    },
    {
      "x": -18,
      "y": 32,
      "z": -8,
      "name": "Rock_Volcanic"
    },
    {
      "x": -18,
      "y": 33,
      "z": -8,
      "name": "Rock_Volcanic"
    },
    {
      "x": -18,
      "y": 34,
      "z": -8,
      "name": "Rock_Volcanic"
    },
    {
      "x": -18,
      "y": 35,
      "z": -8,
      "name": "Rock_Volcanic"
    },
    {
      "x": -17,
      "y": 11,
      "z": -19,
      "name": "Rock_Volcanic"
    },
    {
      "x": -17,
      "y": 12,
      "z": -19,
      "name": "Rock_Volcanic"
    },
    {
      "x": -17,
      "y": 13,
      "z": -19,
      "name": "Rock_Volcanic"
    },
    {
      "x": -17,
      "y": 14,
      "z": -19,
      "name": "Rock_Volcanic"
    },
    {
      "x": -17,
      "y": 15,
      "z": -19,
      "name": "Rock_Volcanic"
    },
    {
      "x": -17,
      "y": 16,
      "z": -19,
      "name": "Rock_Volcanic"
    },
    {
      "x": -17,
      "y": 10,
      "z": -18,
      "name": "Rock_Volcanic"
    },
    {
      "x": -17,
      "y": 11,
      "z": -18,
      "name": "Rock_Volcanic"
    },
    {
      "x": -17,
      "y": 12,
      "z": -18,
      "name": "Rock_Volcanic"
    },
    {
      "x": -17,
      "y": 13,
      "z": -18,
      "name": "Rock_Volcanic"
    },
    {
      "x": -17,
      "y": 14,
      "z": -18,
      "name": "Rock_Volcanic"
    },
    {
      "x": -17,
      "y": 15,
      "z": -18,
      "name": "Rock_Volcanic"
    },
    {
      "x": -17,
      "y": 16,
      "z": -18,
      "name": "Rock_Volcanic"
    },
    {
      "x": -17,
      "y": 17,
      "z": -18,
      "name": "Rock_Volcanic"
    },
    {
      "x": -17,
      "y": 18,
      "z": -18,
      "name": "Rock_Volcanic"
    },
    {
      "x": -17,
      "y": 9,
      "z": -17,
      "name": "Rock_Volcanic"
    },
    {
      "x": -17,
      "y": 10,
      "z": -17,
      "name": "Rock_Volcanic"
    },
    {
      "x": -17,
      "y": 11,
      "z": -17,
      "name": "Rock_Volcanic"
    },
    {
      "x": -17,
      "y": 12,
      "z": -17,
      "name": "Rock_Volcanic"
    },
    {
      "x": -17,
      "y": 13,
      "z": -17,
      "name": "Rock_Volcanic"
    },
    {
      "x": -17,
      "y": 14,
      "z": -17,
      "name": "Rock_Volcanic"
    },
    {
      "x": -17,
      "y": 15,
      "z": -17,
      "name": "Rock_Volcanic"
    },
    {
      "x": -17,
      "y": 16,
      "z": -17,
      "name": "Rock_Volcanic"
    },
    {
      "x": -17,
      "y": 17,
      "z": -17,
      "name": "Rock_Volcanic"
    },
    {
      "x": -17,
      "y": 18,
      "z": -17,
      "name": "Rock_Volcanic"
    },
    {
      "x": -17,
      "y": 8,
      "z": -16,
      "name": "Rock_Volcanic"
    },
    {
      "x": -17,
      "y": 9,
      "z": -16,
      "name": "Rock_Volcanic"
    },
    {
      "x": -17,
      "y": 10,
      "z": -16,
      "name": "Rock_Volcanic"
    },
    {
      "x": -17,
      "y": 11,
      "z": -16,
      "name": "Rock_Volcanic"
    },
    {
      "x": -17,
      "y": 12,
      "z": -16,
      "name": "Rock_Volcanic"
    },
    {
      "x": -17,
      "y": 13,
      "z": -16,
      "name": "Rock_Volcanic"
    },
    {
      "x": -17,
      "y": 14,
      "z": -16,
      "name": "Rock_Volcanic"
    },
    {
      "x": -17,
      "y": 15,
      "z": -16,
      "name": "Rock_Volcanic"
    },
    {
      "x": -17,
      "y": 16,
      "z": -16,
      "name": "Rock_Volcanic"
    },
    {
      "x": -17,
      "y": 17,
      "z": -16,
      "name": "Rock_Volcanic"
    },
    {
      "x": -17,
      "y": 18,
      "z": -16,
      "name": "Rock_Volcanic"
    },
    {
      "x": -17,
      "y": 19,
      "z": -16,
      "name": "Rock_Volcanic"
    },
    {
      "x": -17,
      "y": 8,
      "z": -15,
      "name": "Rock_Volcanic"
    },
    {
      "x": -17,
      "y": 9,
      "z": -15,
      "name": "Rock_Volcanic"
    },
    {
      "x": -17,
      "y": 10,
      "z": -15,
      "name": "Rock_Volcanic"
    },
    {
      "x": -17,
      "y": 11,
      "z": -15,
      "name": "Rock_Volcanic"
    },
    {
      "x": -17,
      "y": 12,
      "z": -15,
      "name": "Rock_Volcanic"
    },
    {
      "x": -17,
      "y": 13,
      "z": -15,
      "name": "Rock_Volcanic"
    },
    {
      "x": -17,
      "y": 14,
      "z": -15,
      "name": "Rock_Volcanic"
    },
    {
      "x": -17,
      "y": 15,
      "z": -15,
      "name": "Rock_Volcanic"
    },
    {
      "x": -17,
      "y": 16,
      "z": -15,
      "name": "Rock_Volcanic"
    },
    {
      "x": -17,
      "y": 17,
      "z": -15,
      "name": "Rock_Volcanic"
    },
    {
      "x": -17,
      "y": 18,
      "z": -15,
      "name": "Rock_Volcanic"
    },
    {
      "x": -17,
      "y": 19,
      "z": -15,
      "name": "Rock_Volcanic"
    },
    {
      "x": -17,
      "y": 11,
      "z": -14,
      "name": "Rock_Volcanic"
    },
    {
      "x": -17,
      "y": 12,
      "z": -14,
      "name": "Rock_Volcanic"
    },
    {
      "x": -17,
      "y": 13,
      "z": -14,
      "name": "Rock_Volcanic"
    },
    {
      "x": -17,
      "y": 14,
      "z": -14,
      "name": "Rock_Volcanic"
    },
    {
      "x": -17,
      "y": 15,
      "z": -14,
      "name": "Rock_Volcanic"
    },
    {
      "x": -17,
      "y": 16,
      "z": -14,
      "name": "Rock_Volcanic"
    },
    {
      "x": -17,
      "y": 17,
      "z": -14,
      "name": "Rock_Volcanic"
    },
    {
      "x": -17,
      "y": 18,
      "z": -14,
      "name": "Rock_Volcanic"
    },
    {
      "x": -17,
      "y": 19,
      "z": -14,
      "name": "Rock_Volcanic"
    },
    {
      "x": -17,
      "y": 14,
      "z": -13,
      "name": "Rock_Volcanic"
    },
    {
      "x": -17,
      "y": 15,
      "z": -13,
      "name": "Rock_Volcanic"
    },
    {
      "x": -17,
      "y": 16,
      "z": -13,
      "name": "Rock_Volcanic"
    },
    {
      "x": -17,
      "y": 17,
      "z": -13,
      "name": "Rock_Volcanic"
    },
    {
      "x": -17,
      "y": 18,
      "z": -13,
      "name": "Rock_Volcanic"
    },
    {
      "x": -17,
      "y": 15,
      "z": -12,
      "name": "Rock_Volcanic"
    },
    {
      "x": -17,
      "y": 16,
      "z": -12,
      "name": "Rock_Volcanic"
    },
    {
      "x": -17,
      "y": 17,
      "z": -12,
      "name": "Rock_Volcanic"
    },
    {
      "x": -17,
      "y": 18,
      "z": -12,
      "name": "Rock_Volcanic"
    },
    {
      "x": -17,
      "y": 24,
      "z": -12,
      "name": "Rock_Volcanic"
    },
    {
      "x": -17,
      "y": 25,
      "z": -12,
      "name": "Rock_Volcanic"
    },
    {
      "x": -17,
      "y": 26,
      "z": -12,
      "name": "Rock_Volcanic"
    },
    {
      "x": -17,
      "y": 27,
      "z": -12,
      "name": "Rock_Volcanic"
    },
    {
      "x": -17,
      "y": 28,
      "z": -12,
      "name": "Rock_Volcanic"
    },
    {
      "x": -17,
      "y": 23,
      "z": -11,
      "name": "Rock_Volcanic"
    },
    {
      "x": -17,
      "y": 24,
      "z": -11,
      "name": "Rock_Volcanic"
    },
    {
      "x": -17,
      "y": 25,
      "z": -11,
      "name": "Rock_Volcanic"
    },
    {
      "x": -17,
      "y": 26,
      "z": -11,
      "name": "Rock_Volcanic"
    },
    {
      "x": -17,
      "y": 27,
      "z": -11,
      "name": "Rock_Volcanic"
    },
    {
      "x": -17,
      "y": 28,
      "z": -11,
      "name": "Rock_Volcanic"
    },
    {
      "x": -17,
      "y": 29,
      "z": -11,
      "name": "Rock_Volcanic"
    },
    {
      "x": -17,
      "y": 30,
      "z": -11,
      "name": "Rock_Volcanic"
    },
    {
      "x": -17,
      "y": 31,
      "z": -11,
      "name": "Rock_Volcanic"
    },
    {
      "x": -17,
      "y": 23,
      "z": -10,
      "name": "Rock_Volcanic"
    },
    {
      "x": -17,
      "y": 24,
      "z": -10,
      "name": "Rock_Volcanic"
    },
    {
      "x": -17,
      "y": 25,
      "z": -10,
      "name": "Rock_Volcanic"
    },
    {
      "x": -17,
      "y": 26,
      "z": -10,
      "name": "Rock_Volcanic"
    },
    {
      "x": -17,
      "y": 27,
      "z": -10,
      "name": "Rock_Volcanic"
    },
    {
      "x": -17,
      "y": 28,
      "z": -10,
      "name": "Rock_Volcanic"
    },
    {
      "x": -17,
      "y": 29,
      "z": -10,
      "name": "Rock_Volcanic"
    },
    {
      "x": -17,
      "y": 30,
      "z": -10,
      "name": "Rock_Volcanic"
    },
    {
      "x": -17,
      "y": 31,
      "z": -10,
      "name": "Rock_Volcanic"
    },
    {
      "x": -17,
      "y": 32,
      "z": -10,
      "name": "Rock_Volcanic"
    },
    {
      "x": -17,
      "y": 25,
      "z": -9,
      "name": "Rock_Volcanic"
    },
    {
      "x": -17,
      "y": 26,
      "z": -9,
      "name": "Rock_Volcanic"
    },
    {
      "x": -17,
      "y": 27,
      "z": -9,
      "name": "Rock_Volcanic"
    },
    {
      "x": -17,
      "y": 28,
      "z": -9,
      "name": "Rock_Volcanic"
    },
    {
      "x": -17,
      "y": 29,
      "z": -9,
      "name": "Rock_Volcanic"
    },
    {
      "x": -17,
      "y": 30,
      "z": -9,
      "name": "Rock_Volcanic"
    },
    {
      "x": -17,
      "y": 31,
      "z": -9,
      "name": "Rock_Volcanic"
    },
    {
      "x": -17,
      "y": 32,
      "z": -9,
      "name": "Rock_Volcanic"
    },
    {
      "x": -17,
      "y": 33,
      "z": -9,
      "name": "Rock_Volcanic"
    },
    {
      "x": -17,
      "y": 34,
      "z": -9,
      "name": "Rock_Volcanic"
    },
    {
      "x": -17,
      "y": 28,
      "z": -8,
      "name": "Rock_Volcanic"
    },
    {
      "x": -17,
      "y": 29,
      "z": -8,
      "name": "Rock_Volcanic"
    },
    {
      "x": -17,
      "y": 30,
      "z": -8,
      "name": "Rock_Volcanic"
    },
    {
      "x": -17,
      "y": 31,
      "z": -8,
      "name": "Rock_Volcanic"
    },
    {
      "x": -17,
      "y": 32,
      "z": -8,
      "name": "Rock_Volcanic"
    },
    {
      "x": -17,
      "y": 33,
      "z": -8,
      "name": "Rock_Volcanic"
    },
    {
      "x": -16,
      "y": 11,
      "z": -19,
      "name": "Rock_Volcanic"
    },
    {
      "x": -16,
      "y": 12,
      "z": -19,
      "name": "Rock_Volcanic"
    },
    {
      "x": -16,
      "y": 13,
      "z": -19,
      "name": "Rock_Volcanic"
    },
    {
      "x": -16,
      "y": 14,
      "z": -19,
      "name": "Rock_Volcanic"
    },
    {
      "x": -16,
      "y": 15,
      "z": -19,
      "name": "Rock_Volcanic"
    },
    {
      "x": -16,
      "y": 16,
      "z": -19,
      "name": "Rock_Volcanic"
    },
    {
      "x": -16,
      "y": 17,
      "z": -19,
      "name": "Rock_Volcanic"
    },
    {
      "x": -16,
      "y": 9,
      "z": -18,
      "name": "Rock_Volcanic"
    },
    {
      "x": -16,
      "y": 10,
      "z": -18,
      "name": "Rock_Volcanic"
    },
    {
      "x": -16,
      "y": 11,
      "z": -18,
      "name": "Rock_Volcanic"
    },
    {
      "x": -16,
      "y": 12,
      "z": -18,
      "name": "Rock_Volcanic"
    },
    {
      "x": -16,
      "y": 13,
      "z": -18,
      "name": "Rock_Volcanic"
    },
    {
      "x": -16,
      "y": 14,
      "z": -18,
      "name": "Rock_Volcanic"
    },
    {
      "x": -16,
      "y": 15,
      "z": -18,
      "name": "Rock_Volcanic"
    },
    {
      "x": -16,
      "y": 16,
      "z": -18,
      "name": "Rock_Volcanic"
    },
    {
      "x": -16,
      "y": 17,
      "z": -18,
      "name": "Rock_Volcanic"
    },
    {
      "x": -16,
      "y": 18,
      "z": -18,
      "name": "Rock_Volcanic"
    },
    {
      "x": -16,
      "y": 19,
      "z": -18,
      "name": "Rock_Volcanic"
    },
    {
      "x": -16,
      "y": 7,
      "z": -17,
      "name": "Rock_Volcanic"
    },
    {
      "x": -16,
      "y": 8,
      "z": -17,
      "name": "Rock_Volcanic"
    },
    {
      "x": -16,
      "y": 9,
      "z": -17,
      "name": "Rock_Volcanic"
    },
    {
      "x": -16,
      "y": 10,
      "z": -17,
      "name": "Rock_Volcanic"
    },
    {
      "x": -16,
      "y": 11,
      "z": -17,
      "name": "Rock_Volcanic"
    },
    {
      "x": -16,
      "y": 12,
      "z": -17,
      "name": "Rock_Volcanic"
    },
    {
      "x": -16,
      "y": 13,
      "z": -17,
      "name": "Rock_Volcanic"
    },
    {
      "x": -16,
      "y": 14,
      "z": -17,
      "name": "Rock_Volcanic"
    },
    {
      "x": -16,
      "y": 15,
      "z": -17,
      "name": "Rock_Volcanic"
    },
    {
      "x": -16,
      "y": 16,
      "z": -17,
      "name": "Rock_Volcanic"
    },
    {
      "x": -16,
      "y": 17,
      "z": -17,
      "name": "Rock_Volcanic"
    },
    {
      "x": -16,
      "y": 18,
      "z": -17,
      "name": "Rock_Volcanic"
    },
    {
      "x": -16,
      "y": 19,
      "z": -17,
      "name": "Rock_Volcanic"
    },
    {
      "x": -16,
      "y": 6,
      "z": -16,
      "name": "Rock_Volcanic"
    },
    {
      "x": -16,
      "y": 7,
      "z": -16,
      "name": "Rock_Volcanic"
    },
    {
      "x": -16,
      "y": 8,
      "z": -16,
      "name": "Rock_Volcanic"
    },
    {
      "x": -16,
      "y": 9,
      "z": -16,
      "name": "Rock_Volcanic"
    },
    {
      "x": -16,
      "y": 10,
      "z": -16,
      "name": "Rock_Volcanic"
    },
    {
      "x": -16,
      "y": 11,
      "z": -16,
      "name": "Rock_Volcanic"
    },
    {
      "x": -16,
      "y": 12,
      "z": -16,
      "name": "Rock_Volcanic"
    },
    {
      "x": -16,
      "y": 13,
      "z": -16,
      "name": "Rock_Volcanic"
    },
    {
      "x": -16,
      "y": 14,
      "z": -16,
      "name": "Rock_Volcanic"
    },
    {
      "x": -16,
      "y": 15,
      "z": -16,
      "name": "Rock_Volcanic"
    },
    {
      "x": -16,
      "y": 16,
      "z": -16,
      "name": "Rock_Volcanic"
    },
    {
      "x": -16,
      "y": 17,
      "z": -16,
      "name": "Rock_Volcanic"
    },
    {
      "x": -16,
      "y": 18,
      "z": -16,
      "name": "Rock_Volcanic"
    },
    {
      "x": -16,
      "y": 19,
      "z": -16,
      "name": "Rock_Volcanic"
    },
    {
      "x": -16,
      "y": 20,
      "z": -16,
      "name": "Rock_Volcanic"
    },
    {
      "x": -16,
      "y": 6,
      "z": -15,
      "name": "Rock_Volcanic"
    },
    {
      "x": -16,
      "y": 7,
      "z": -15,
      "name": "Rock_Volcanic"
    },
    {
      "x": -16,
      "y": 8,
      "z": -15,
      "name": "Rock_Volcanic"
    },
    {
      "x": -16,
      "y": 9,
      "z": -15,
      "name": "Rock_Volcanic"
    },
    {
      "x": -16,
      "y": 10,
      "z": -15,
      "name": "Rock_Volcanic"
    },
    {
      "x": -16,
      "y": 11,
      "z": -15,
      "name": "Rock_Volcanic"
    },
    {
      "x": -16,
      "y": 12,
      "z": -15,
      "name": "Rock_Volcanic"
    },
    {
      "x": -16,
      "y": 13,
      "z": -15,
      "name": "Rock_Volcanic"
    },
    {
      "x": -16,
      "y": 14,
      "z": -15,
      "name": "Rock_Volcanic"
    },
    {
      "x": -16,
      "y": 15,
      "z": -15,
      "name": "Rock_Volcanic"
    },
    {
      "x": -16,
      "y": 16,
      "z": -15,
      "name": "Rock_Volcanic"
    },
    {
      "x": -16,
      "y": 17,
      "z": -15,
      "name": "Rock_Volcanic"
    },
    {
      "x": -16,
      "y": 18,
      "z": -15,
      "name": "Rock_Volcanic"
    },
    {
      "x": -16,
      "y": 19,
      "z": -15,
      "name": "Rock_Volcanic"
    },
    {
      "x": -16,
      "y": 20,
      "z": -15,
      "name": "Rock_Volcanic"
    },
    {
      "x": -16,
      "y": 21,
      "z": -15,
      "name": "Rock_Volcanic"
    },
    {
      "x": -16,
      "y": 6,
      "z": -14,
      "name": "Rock_Volcanic"
    },
    {
      "x": -16,
      "y": 7,
      "z": -14,
      "name": "Rock_Volcanic"
    },
    {
      "x": -16,
      "y": 8,
      "z": -14,
      "name": "Rock_Volcanic"
    },
    {
      "x": -16,
      "y": 9,
      "z": -14,
      "name": "Rock_Volcanic"
    },
    {
      "x": -16,
      "y": 10,
      "z": -14,
      "name": "Rock_Volcanic"
    },
    {
      "x": -16,
      "y": 11,
      "z": -14,
      "name": "Rock_Volcanic"
    },
    {
      "x": -16,
      "y": 12,
      "z": -14,
      "name": "Rock_Volcanic"
    },
    {
      "x": -16,
      "y": 13,
      "z": -14,
      "name": "Rock_Volcanic"
    },
    {
      "x": -16,
      "y": 14,
      "z": -14,
      "name": "Rock_Volcanic"
    },
    {
      "x": -16,
      "y": 15,
      "z": -14,
      "name": "Rock_Volcanic"
    },
    {
      "x": -16,
      "y": 16,
      "z": -14,
      "name": "Rock_Volcanic"
    },
    {
      "x": -16,
      "y": 17,
      "z": -14,
      "name": "Rock_Volcanic"
    },
    {
      "x": -16,
      "y": 18,
      "z": -14,
      "name": "Rock_Volcanic"
    },
    {
      "x": -16,
      "y": 19,
      "z": -14,
      "name": "Rock_Volcanic"
    },
    {
      "x": -16,
      "y": 20,
      "z": -14,
      "name": "Rock_Volcanic"
    },
    {
      "x": -16,
      "y": 21,
      "z": -14,
      "name": "Rock_Volcanic"
    },
    {
      "x": -16,
      "y": 6,
      "z": -13,
      "name": "Rock_Volcanic"
    },
    {
      "x": -16,
      "y": 7,
      "z": -13,
      "name": "Rock_Volcanic"
    },
    {
      "x": -16,
      "y": 8,
      "z": -13,
      "name": "Rock_Volcanic"
    },
    {
      "x": -16,
      "y": 9,
      "z": -13,
      "name": "Rock_Volcanic"
    },
    {
      "x": -16,
      "y": 10,
      "z": -13,
      "name": "Rock_Volcanic"
    },
    {
      "x": -16,
      "y": 11,
      "z": -13,
      "name": "Rock_Volcanic"
    },
    {
      "x": -16,
      "y": 12,
      "z": -13,
      "name": "Rock_Volcanic"
    },
    {
      "x": -16,
      "y": 13,
      "z": -13,
      "name": "Rock_Volcanic"
    },
    {
      "x": -16,
      "y": 14,
      "z": -13,
      "name": "Rock_Volcanic"
    },
    {
      "x": -16,
      "y": 15,
      "z": -13,
      "name": "Rock_Volcanic"
    },
    {
      "x": -16,
      "y": 16,
      "z": -13,
      "name": "Rock_Volcanic"
    },
    {
      "x": -16,
      "y": 17,
      "z": -13,
      "name": "Rock_Volcanic"
    },
    {
      "x": -16,
      "y": 18,
      "z": -13,
      "name": "Rock_Volcanic"
    },
    {
      "x": -16,
      "y": 19,
      "z": -13,
      "name": "Rock_Volcanic"
    },
    {
      "x": -16,
      "y": 20,
      "z": -13,
      "name": "Rock_Volcanic"
    },
    {
      "x": -16,
      "y": 22,
      "z": -13,
      "name": "Rock_Volcanic"
    },
    {
      "x": -16,
      "y": 23,
      "z": -13,
      "name": "Rock_Volcanic"
    },
    {
      "x": -16,
      "y": 24,
      "z": -13,
      "name": "Rock_Volcanic"
    },
    {
      "x": -16,
      "y": 25,
      "z": -13,
      "name": "Rock_Volcanic"
    },
    {
      "x": -16,
      "y": 13,
      "z": -12,
      "name": "Rock_Volcanic"
    },
    {
      "x": -16,
      "y": 14,
      "z": -12,
      "name": "Rock_Volcanic"
    },
    {
      "x": -16,
      "y": 15,
      "z": -12,
      "name": "Rock_Volcanic"
    },
    {
      "x": -16,
      "y": 16,
      "z": -12,
      "name": "Rock_Volcanic"
    },
    {
      "x": -16,
      "y": 17,
      "z": -12,
      "name": "Rock_Volcanic"
    },
    {
      "x": -16,
      "y": 18,
      "z": -12,
      "name": "Rock_Volcanic"
    },
    {
      "x": -16,
      "y": 19,
      "z": -12,
      "name": "Rock_Volcanic"
    },
    {
      "x": -16,
      "y": 20,
      "z": -12,
      "name": "Rock_Volcanic"
    },
    {
      "x": -16,
      "y": 21,
      "z": -12,
      "name": "Rock_Volcanic"
    },
    {
      "x": -16,
      "y": 22,
      "z": -12,
      "name": "Rock_Volcanic"
    },
    {
      "x": -16,
      "y": 23,
      "z": -12,
      "name": "Rock_Volcanic"
    },
    {
      "x": -16,
      "y": 24,
      "z": -12,
      "name": "Rock_Volcanic"
    },
    {
      "x": -16,
      "y": 25,
      "z": -12,
      "name": "Rock_Volcanic"
    },
    {
      "x": -16,
      "y": 26,
      "z": -12,
      "name": "Rock_Volcanic"
    },
    {
      "x": -16,
      "y": 27,
      "z": -12,
      "name": "Rock_Volcanic"
    },
    {
      "x": -16,
      "y": 28,
      "z": -12,
      "name": "Rock_Volcanic"
    },
    {
      "x": -16,
      "y": 29,
      "z": -12,
      "name": "Rock_Volcanic"
    },
    {
      "x": -16,
      "y": 15,
      "z": -11,
      "name": "Rock_Volcanic"
    },
    {
      "x": -16,
      "y": 16,
      "z": -11,
      "name": "Rock_Volcanic"
    },
    {
      "x": -16,
      "y": 17,
      "z": -11,
      "name": "Rock_Volcanic"
    },
    {
      "x": -16,
      "y": 18,
      "z": -11,
      "name": "Rock_Volcanic"
    },
    {
      "x": -16,
      "y": 19,
      "z": -11,
      "name": "Rock_Volcanic"
    },
    {
      "x": -16,
      "y": 21,
      "z": -11,
      "name": "Rock_Volcanic"
    },
    {
      "x": -16,
      "y": 22,
      "z": -11,
      "name": "Rock_Volcanic"
    },
    {
      "x": -16,
      "y": 23,
      "z": -11,
      "name": "Rock_Volcanic"
    },
    {
      "x": -16,
      "y": 24,
      "z": -11,
      "name": "Rock_Volcanic"
    },
    {
      "x": -16,
      "y": 25,
      "z": -11,
      "name": "Rock_Volcanic"
    },
    {
      "x": -16,
      "y": 26,
      "z": -11,
      "name": "Rock_Volcanic"
    },
    {
      "x": -16,
      "y": 27,
      "z": -11,
      "name": "Rock_Volcanic"
    },
    {
      "x": -16,
      "y": 28,
      "z": -11,
      "name": "Rock_Volcanic"
    },
    {
      "x": -16,
      "y": 29,
      "z": -11,
      "name": "Rock_Volcanic"
    },
    {
      "x": -16,
      "y": 30,
      "z": -11,
      "name": "Rock_Volcanic"
    },
    {
      "x": -16,
      "y": 16,
      "z": -10,
      "name": "Rock_Volcanic"
    },
    {
      "x": -16,
      "y": 17,
      "z": -10,
      "name": "Rock_Volcanic"
    },
    {
      "x": -16,
      "y": 18,
      "z": -10,
      "name": "Rock_Volcanic"
    },
    {
      "x": -16,
      "y": 22,
      "z": -10,
      "name": "Rock_Volcanic"
    },
    {
      "x": -16,
      "y": 23,
      "z": -10,
      "name": "Rock_Volcanic"
    },
    {
      "x": -16,
      "y": 24,
      "z": -10,
      "name": "Rock_Volcanic"
    },
    {
      "x": -16,
      "y": 25,
      "z": -10,
      "name": "Rock_Volcanic"
    },
    {
      "x": -16,
      "y": 26,
      "z": -10,
      "name": "Rock_Volcanic"
    },
    {
      "x": -16,
      "y": 27,
      "z": -10,
      "name": "Rock_Volcanic"
    },
    {
      "x": -16,
      "y": 28,
      "z": -10,
      "name": "Rock_Volcanic"
    },
    {
      "x": -16,
      "y": 29,
      "z": -10,
      "name": "Rock_Volcanic"
    },
    {
      "x": -16,
      "y": 30,
      "z": -10,
      "name": "Rock_Volcanic"
    },
    {
      "x": -16,
      "y": 31,
      "z": -10,
      "name": "Rock_Volcanic"
    },
    {
      "x": -16,
      "y": 32,
      "z": -10,
      "name": "Rock_Volcanic"
    },
    {
      "x": -16,
      "y": 23,
      "z": -9,
      "name": "Rock_Volcanic"
    },
    {
      "x": -16,
      "y": 24,
      "z": -9,
      "name": "Rock_Volcanic"
    },
    {
      "x": -16,
      "y": 25,
      "z": -9,
      "name": "Rock_Volcanic"
    },
    {
      "x": -16,
      "y": 26,
      "z": -9,
      "name": "Rock_Volcanic"
    },
    {
      "x": -16,
      "y": 27,
      "z": -9,
      "name": "Rock_Volcanic"
    },
    {
      "x": -16,
      "y": 28,
      "z": -9,
      "name": "Rock_Volcanic"
    },
    {
      "x": -16,
      "y": 29,
      "z": -9,
      "name": "Rock_Volcanic"
    },
    {
      "x": -16,
      "y": 30,
      "z": -9,
      "name": "Rock_Volcanic"
    },
    {
      "x": -16,
      "y": 31,
      "z": -9,
      "name": "Rock_Volcanic"
    },
    {
      "x": -16,
      "y": 32,
      "z": -9,
      "name": "Rock_Volcanic"
    },
    {
      "x": -16,
      "y": 25,
      "z": -8,
      "name": "Rock_Volcanic"
    },
    {
      "x": -16,
      "y": 26,
      "z": -8,
      "name": "Rock_Volcanic"
    },
    {
      "x": -16,
      "y": 27,
      "z": -8,
      "name": "Rock_Volcanic"
    },
    {
      "x": -16,
      "y": 28,
      "z": -8,
      "name": "Rock_Volcanic"
    },
    {
      "x": -16,
      "y": 29,
      "z": -8,
      "name": "Rock_Volcanic"
    },
    {
      "x": -16,
      "y": 30,
      "z": -8,
      "name": "Rock_Volcanic"
    },
    {
      "x": -16,
      "y": 31,
      "z": -8,
      "name": "Rock_Volcanic"
    },
    {
      "x": -16,
      "y": 32,
      "z": -8,
      "name": "Rock_Volcanic"
    },
    {
      "x": -15,
      "y": 11,
      "z": -19,
      "name": "Rock_Volcanic"
    },
    {
      "x": -15,
      "y": 12,
      "z": -19,
      "name": "Rock_Volcanic"
    },
    {
      "x": -15,
      "y": 13,
      "z": -19,
      "name": "Rock_Volcanic"
    },
    {
      "x": -15,
      "y": 14,
      "z": -19,
      "name": "Rock_Volcanic"
    },
    {
      "x": -15,
      "y": 15,
      "z": -19,
      "name": "Rock_Volcanic"
    },
    {
      "x": -15,
      "y": 16,
      "z": -19,
      "name": "Rock_Volcanic"
    },
    {
      "x": -15,
      "y": 17,
      "z": -19,
      "name": "Rock_Volcanic"
    },
    {
      "x": -15,
      "y": 8,
      "z": -18,
      "name": "Rock_Volcanic"
    },
    {
      "x": -15,
      "y": 9,
      "z": -18,
      "name": "Rock_Volcanic"
    },
    {
      "x": -15,
      "y": 10,
      "z": -18,
      "name": "Rock_Volcanic"
    },
    {
      "x": -15,
      "y": 11,
      "z": -18,
      "name": "Rock_Volcanic"
    },
    {
      "x": -15,
      "y": 12,
      "z": -18,
      "name": "Rock_Volcanic"
    },
    {
      "x": -15,
      "y": 13,
      "z": -18,
      "name": "Rock_Volcanic"
    },
    {
      "x": -15,
      "y": 14,
      "z": -18,
      "name": "Rock_Volcanic"
    },
    {
      "x": -15,
      "y": 15,
      "z": -18,
      "name": "Rock_Volcanic"
    },
    {
      "x": -15,
      "y": 16,
      "z": -18,
      "name": "Rock_Volcanic"
    },
    {
      "x": -15,
      "y": 17,
      "z": -18,
      "name": "Rock_Volcanic"
    },
    {
      "x": -15,
      "y": 18,
      "z": -18,
      "name": "Rock_Volcanic"
    },
    {
      "x": -15,
      "y": 19,
      "z": -18,
      "name": "Rock_Volcanic"
    },
    {
      "x": -15,
      "y": 6,
      "z": -17,
      "name": "Rock_Volcanic"
    },
    {
      "x": -15,
      "y": 7,
      "z": -17,
      "name": "Rock_Volcanic"
    },
    {
      "x": -15,
      "y": 8,
      "z": -17,
      "name": "Rock_Volcanic"
    },
    {
      "x": -15,
      "y": 9,
      "z": -17,
      "name": "Rock_Volcanic"
    },
    {
      "x": -15,
      "y": 10,
      "z": -17,
      "name": "Rock_Volcanic"
    },
    {
      "x": -15,
      "y": 11,
      "z": -17,
      "name": "Rock_Volcanic"
    },
    {
      "x": -15,
      "y": 12,
      "z": -17,
      "name": "Rock_Volcanic"
    },
    {
      "x": -15,
      "y": 13,
      "z": -17,
      "name": "Rock_Volcanic"
    },
    {
      "x": -15,
      "y": 14,
      "z": -17,
      "name": "Rock_Volcanic"
    },
    {
      "x": -15,
      "y": 15,
      "z": -17,
      "name": "Rock_Volcanic"
    },
    {
      "x": -15,
      "y": 16,
      "z": -17,
      "name": "Rock_Volcanic"
    },
    {
      "x": -15,
      "y": 17,
      "z": -17,
      "name": "Rock_Volcanic"
    },
    {
      "x": -15,
      "y": 18,
      "z": -17,
      "name": "Rock_Volcanic"
    },
    {
      "x": -15,
      "y": 19,
      "z": -17,
      "name": "Rock_Volcanic"
    },
    {
      "x": -15,
      "y": 20,
      "z": -17,
      "name": "Rock_Volcanic"
    },
    {
      "x": -15,
      "y": 5,
      "z": -16,
      "name": "Rock_Volcanic"
    },
    {
      "x": -15,
      "y": 6,
      "z": -16,
      "name": "Rock_Volcanic"
    },
    {
      "x": -15,
      "y": 7,
      "z": -16,
      "name": "Rock_Volcanic"
    },
    {
      "x": -15,
      "y": 8,
      "z": -16,
      "name": "Rock_Volcanic"
    },
    {
      "x": -15,
      "y": 9,
      "z": -16,
      "name": "Rock_Volcanic"
    },
    {
      "x": -15,
      "y": 10,
      "z": -16,
      "name": "Rock_Volcanic"
    },
    {
      "x": -15,
      "y": 11,
      "z": -16,
      "name": "Rock_Volcanic"
    },
    {
      "x": -15,
      "y": 12,
      "z": -16,
      "name": "Rock_Volcanic"
    },
    {
      "x": -15,
      "y": 13,
      "z": -16,
      "name": "Rock_Volcanic"
    },
    {
      "x": -15,
      "y": 14,
      "z": -16,
      "name": "Rock_Volcanic"
    },
    {
      "x": -15,
      "y": 15,
      "z": -16,
      "name": "Rock_Volcanic"
    },
    {
      "x": -15,
      "y": 16,
      "z": -16,
      "name": "Rock_Volcanic"
    },
    {
      "x": -15,
      "y": 17,
      "z": -16,
      "name": "Rock_Volcanic"
    },
    {
      "x": -15,
      "y": 18,
      "z": -16,
      "name": "Rock_Volcanic"
    },
    {
      "x": -15,
      "y": 19,
      "z": -16,
      "name": "Rock_Volcanic"
    },
    {
      "x": -15,
      "y": 20,
      "z": -16,
      "name": "Rock_Volcanic"
    },
    {
      "x": -15,
      "y": 21,
      "z": -16,
      "name": "Rock_Volcanic"
    },
    {
      "x": -15,
      "y": 5,
      "z": -15,
      "name": "Rock_Volcanic"
    },
    {
      "x": -15,
      "y": 6,
      "z": -15,
      "name": "Rock_Volcanic"
    },
    {
      "x": -15,
      "y": 7,
      "z": -15,
      "name": "Rock_Volcanic"
    },
    {
      "x": -15,
      "y": 8,
      "z": -15,
      "name": "Rock_Volcanic"
    },
    {
      "x": -15,
      "y": 9,
      "z": -15,
      "name": "Rock_Volcanic"
    },
    {
      "x": -15,
      "y": 10,
      "z": -15,
      "name": "Rock_Volcanic"
    },
    {
      "x": -15,
      "y": 11,
      "z": -15,
      "name": "Rock_Volcanic"
    },
    {
      "x": -15,
      "y": 12,
      "z": -15,
      "name": "Rock_Volcanic"
    },
    {
      "x": -15,
      "y": 13,
      "z": -15,
      "name": "Rock_Volcanic"
    },
    {
      "x": -15,
      "y": 14,
      "z": -15,
      "name": "Rock_Volcanic"
    },
    {
      "x": -15,
      "y": 15,
      "z": -15,
      "name": "Rock_Volcanic"
    },
    {
      "x": -15,
      "y": 16,
      "z": -15,
      "name": "Rock_Volcanic"
    },
    {
      "x": -15,
      "y": 17,
      "z": -15,
      "name": "Rock_Volcanic"
    },
    {
      "x": -15,
      "y": 18,
      "z": -15,
      "name": "Rock_Volcanic"
    },
    {
      "x": -15,
      "y": 19,
      "z": -15,
      "name": "Rock_Volcanic"
    },
    {
      "x": -15,
      "y": 20,
      "z": -15,
      "name": "Rock_Volcanic"
    },
    {
      "x": -15,
      "y": 21,
      "z": -15,
      "name": "Rock_Volcanic"
    },
    {
      "x": -15,
      "y": 22,
      "z": -15,
      "name": "Rock_Volcanic"
    },
    {
      "x": -15,
      "y": 5,
      "z": -14,
      "name": "Rock_Volcanic"
    },
    {
      "x": -15,
      "y": 6,
      "z": -14,
      "name": "Rock_Volcanic"
    },
    {
      "x": -15,
      "y": 7,
      "z": -14,
      "name": "Rock_Volcanic"
    },
    {
      "x": -15,
      "y": 8,
      "z": -14,
      "name": "Rock_Volcanic"
    },
    {
      "x": -15,
      "y": 9,
      "z": -14,
      "name": "Rock_Volcanic"
    },
    {
      "x": -15,
      "y": 10,
      "z": -14,
      "name": "Rock_Volcanic"
    },
    {
      "x": -15,
      "y": 11,
      "z": -14,
      "name": "Rock_Volcanic"
    },
    {
      "x": -15,
      "y": 12,
      "z": -14,
      "name": "Rock_Volcanic"
    },
    {
      "x": -15,
      "y": 13,
      "z": -14,
      "name": "Rock_Volcanic"
    },
    {
      "x": -15,
      "y": 14,
      "z": -14,
      "name": "Rock_Volcanic"
    },
    {
      "x": -15,
      "y": 15,
      "z": -14,
      "name": "Rock_Volcanic"
    },
    {
      "x": -15,
      "y": 16,
      "z": -14,
      "name": "Rock_Volcanic"
    },
    {
      "x": -15,
      "y": 17,
      "z": -14,
      "name": "Rock_Volcanic"
    },
    {
      "x": -15,
      "y": 18,
      "z": -14,
      "name": "Rock_Volcanic"
    },
    {
      "x": -15,
      "y": 19,
      "z": -14,
      "name": "Rock_Volcanic"
    },
    {
      "x": -15,
      "y": 20,
      "z": -14,
      "name": "Rock_Volcanic"
    },
    {
      "x": -15,
      "y": 21,
      "z": -14,
      "name": "Rock_Volcanic"
    },
    {
      "x": -15,
      "y": 22,
      "z": -14,
      "name": "Rock_Volcanic"
    },
    {
      "x": -15,
      "y": 23,
      "z": -14,
      "name": "Rock_Volcanic"
    },
    {
      "x": -15,
      "y": 5,
      "z": -13,
      "name": "Rock_Volcanic"
    },
    {
      "x": -15,
      "y": 6,
      "z": -13,
      "name": "Rock_Volcanic"
    },
    {
      "x": -15,
      "y": 7,
      "z": -13,
      "name": "Rock_Volcanic"
    },
    {
      "x": -15,
      "y": 8,
      "z": -13,
      "name": "Rock_Volcanic"
    },
    {
      "x": -15,
      "y": 9,
      "z": -13,
      "name": "Rock_Volcanic"
    },
    {
      "x": -15,
      "y": 10,
      "z": -13,
      "name": "Rock_Volcanic"
    },
    {
      "x": -15,
      "y": 11,
      "z": -13,
      "name": "Rock_Volcanic"
    },
    {
      "x": -15,
      "y": 12,
      "z": -13,
      "name": "Rock_Volcanic"
    },
    {
      "x": -15,
      "y": 13,
      "z": -13,
      "name": "Rock_Volcanic"
    },
    {
      "x": -15,
      "y": 14,
      "z": -13,
      "name": "Rock_Volcanic"
    },
    {
      "x": -15,
      "y": 15,
      "z": -13,
      "name": "Rock_Volcanic"
    },
    {
      "x": -15,
      "y": 16,
      "z": -13,
      "name": "Rock_Volcanic"
    },
    {
      "x": -15,
      "y": 17,
      "z": -13,
      "name": "Rock_Volcanic"
    },
    {
      "x": -15,
      "y": 18,
      "z": -13,
      "name": "Rock_Volcanic"
    },
    {
      "x": -15,
      "y": 19,
      "z": -13,
      "name": "Rock_Volcanic"
    },
    {
      "x": -15,
      "y": 20,
      "z": -13,
      "name": "Rock_Volcanic"
    },
    {
      "x": -15,
      "y": 21,
      "z": -13,
      "name": "Rock_Volcanic"
    },
    {
      "x": -15,
      "y": 22,
      "z": -13,
      "name": "Rock_Volcanic"
    },
    {
      "x": -15,
      "y": 23,
      "z": -13,
      "name": "Rock_Volcanic"
    },
    {
      "x": -15,
      "y": 24,
      "z": -13,
      "name": "Rock_Volcanic"
    },
    {
      "x": -15,
      "y": 25,
      "z": -13,
      "name": "Rock_Volcanic"
    },
    {
      "x": -15,
      "y": 26,
      "z": -13,
      "name": "Rock_Volcanic"
    },
    {
      "x": -15,
      "y": 5,
      "z": -12,
      "name": "Rock_Volcanic"
    },
    {
      "x": -15,
      "y": 6,
      "z": -12,
      "name": "Rock_Volcanic"
    },
    {
      "x": -15,
      "y": 7,
      "z": -12,
      "name": "Rock_Volcanic"
    },
    {
      "x": -15,
      "y": 8,
      "z": -12,
      "name": "Rock_Volcanic"
    },
    {
      "x": -15,
      "y": 9,
      "z": -12,
      "name": "Rock_Volcanic"
    },
    {
      "x": -15,
      "y": 10,
      "z": -12,
      "name": "Rock_Volcanic"
    },
    {
      "x": -15,
      "y": 11,
      "z": -12,
      "name": "Rock_Volcanic"
    },
    {
      "x": -15,
      "y": 12,
      "z": -12,
      "name": "Rock_Volcanic"
    },
    {
      "x": -15,
      "y": 13,
      "z": -12,
      "name": "Rock_Volcanic"
    },
    {
      "x": -15,
      "y": 14,
      "z": -12,
      "name": "Rock_Volcanic"
    },
    {
      "x": -15,
      "y": 15,
      "z": -12,
      "name": "Rock_Volcanic"
    },
    {
      "x": -15,
      "y": 16,
      "z": -12,
      "name": "Rock_Volcanic"
    },
    {
      "x": -15,
      "y": 17,
      "z": -12,
      "name": "Rock_Volcanic"
    },
    {
      "x": -15,
      "y": 18,
      "z": -12,
      "name": "Rock_Volcanic"
    },
    {
      "x": -15,
      "y": 19,
      "z": -12,
      "name": "Rock_Volcanic"
    },
    {
      "x": -15,
      "y": 20,
      "z": -12,
      "name": "Rock_Volcanic"
    },
    {
      "x": -15,
      "y": 21,
      "z": -12,
      "name": "Rock_Volcanic"
    },
    {
      "x": -15,
      "y": 22,
      "z": -12,
      "name": "Rock_Volcanic"
    },
    {
      "x": -15,
      "y": 23,
      "z": -12,
      "name": "Rock_Volcanic"
    },
    {
      "x": -15,
      "y": 24,
      "z": -12,
      "name": "Rock_Volcanic"
    },
    {
      "x": -15,
      "y": 25,
      "z": -12,
      "name": "Rock_Volcanic"
    },
    {
      "x": -15,
      "y": 26,
      "z": -12,
      "name": "Rock_Volcanic"
    },
    {
      "x": -15,
      "y": 27,
      "z": -12,
      "name": "Rock_Volcanic"
    },
    {
      "x": -15,
      "y": 28,
      "z": -12,
      "name": "Rock_Volcanic"
    },
    {
      "x": -15,
      "y": 9,
      "z": -11,
      "name": "Rock_Volcanic"
    },
    {
      "x": -15,
      "y": 10,
      "z": -11,
      "name": "Rock_Volcanic"
    },
    {
      "x": -15,
      "y": 11,
      "z": -11,
      "name": "Rock_Volcanic"
    },
    {
      "x": -15,
      "y": 12,
      "z": -11,
      "name": "Rock_Volcanic"
    },
    {
      "x": -15,
      "y": 13,
      "z": -11,
      "name": "Rock_Volcanic"
    },
    {
      "x": -15,
      "y": 14,
      "z": -11,
      "name": "Rock_Volcanic"
    },
    {
      "x": -15,
      "y": 15,
      "z": -11,
      "name": "Rock_Volcanic"
    },
    {
      "x": -15,
      "y": 16,
      "z": -11,
      "name": "Rock_Volcanic"
    },
    {
      "x": -15,
      "y": 17,
      "z": -11,
      "name": "Rock_Volcanic"
    },
    {
      "x": -15,
      "y": 18,
      "z": -11,
      "name": "Rock_Volcanic"
    },
    {
      "x": -15,
      "y": 19,
      "z": -11,
      "name": "Rock_Volcanic"
    },
    {
      "x": -15,
      "y": 20,
      "z": -11,
      "name": "Rock_Volcanic"
    },
    {
      "x": -15,
      "y": 21,
      "z": -11,
      "name": "Rock_Volcanic"
    },
    {
      "x": -15,
      "y": 22,
      "z": -11,
      "name": "Rock_Volcanic"
    },
    {
      "x": -15,
      "y": 23,
      "z": -11,
      "name": "Rock_Volcanic"
    },
    {
      "x": -15,
      "y": 24,
      "z": -11,
      "name": "Rock_Volcanic"
    },
    {
      "x": -15,
      "y": 25,
      "z": -11,
      "name": "Rock_Volcanic"
    },
    {
      "x": -15,
      "y": 26,
      "z": -11,
      "name": "Rock_Volcanic"
    },
    {
      "x": -15,
      "y": 27,
      "z": -11,
      "name": "Rock_Volcanic"
    },
    {
      "x": -15,
      "y": 28,
      "z": -11,
      "name": "Rock_Volcanic"
    },
    {
      "x": -15,
      "y": 29,
      "z": -11,
      "name": "Rock_Volcanic"
    },
    {
      "x": -15,
      "y": 14,
      "z": -10,
      "name": "Rock_Volcanic"
    },
    {
      "x": -15,
      "y": 15,
      "z": -10,
      "name": "Rock_Volcanic"
    },
    {
      "x": -15,
      "y": 16,
      "z": -10,
      "name": "Rock_Volcanic"
    },
    {
      "x": -15,
      "y": 17,
      "z": -10,
      "name": "Rock_Volcanic"
    },
    {
      "x": -15,
      "y": 18,
      "z": -10,
      "name": "Rock_Volcanic"
    },
    {
      "x": -15,
      "y": 19,
      "z": -10,
      "name": "Rock_Volcanic"
    },
    {
      "x": -15,
      "y": 20,
      "z": -10,
      "name": "Rock_Volcanic"
    },
    {
      "x": -15,
      "y": 21,
      "z": -10,
      "name": "Rock_Volcanic"
    },
    {
      "x": -15,
      "y": 22,
      "z": -10,
      "name": "Rock_Volcanic"
    },
    {
      "x": -15,
      "y": 23,
      "z": -10,
      "name": "Rock_Volcanic"
    },
    {
      "x": -15,
      "y": 24,
      "z": -10,
      "name": "Rock_Volcanic"
    },
    {
      "x": -15,
      "y": 25,
      "z": -10,
      "name": "Rock_Volcanic"
    },
    {
      "x": -15,
      "y": 26,
      "z": -10,
      "name": "Rock_Volcanic"
    },
    {
      "x": -15,
      "y": 27,
      "z": -10,
      "name": "Rock_Volcanic"
    },
    {
      "x": -15,
      "y": 28,
      "z": -10,
      "name": "Rock_Volcanic"
    },
    {
      "x": -15,
      "y": 29,
      "z": -10,
      "name": "Rock_Volcanic"
    },
    {
      "x": -15,
      "y": 30,
      "z": -10,
      "name": "Rock_Volcanic"
    },
    {
      "x": -15,
      "y": 31,
      "z": -10,
      "name": "Rock_Volcanic"
    },
    {
      "x": -15,
      "y": 17,
      "z": -9,
      "name": "Rock_Volcanic"
    },
    {
      "x": -15,
      "y": 18,
      "z": -9,
      "name": "Rock_Volcanic"
    },
    {
      "x": -15,
      "y": 19,
      "z": -9,
      "name": "Rock_Volcanic"
    },
    {
      "x": -15,
      "y": 21,
      "z": -9,
      "name": "Rock_Volcanic"
    },
    {
      "x": -15,
      "y": 22,
      "z": -9,
      "name": "Rock_Volcanic"
    },
    {
      "x": -15,
      "y": 23,
      "z": -9,
      "name": "Rock_Volcanic"
    },
    {
      "x": -15,
      "y": 24,
      "z": -9,
      "name": "Rock_Volcanic"
    },
    {
      "x": -15,
      "y": 25,
      "z": -9,
      "name": "Rock_Volcanic"
    },
    {
      "x": -15,
      "y": 26,
      "z": -9,
      "name": "Rock_Volcanic"
    },
    {
      "x": -15,
      "y": 27,
      "z": -9,
      "name": "Rock_Volcanic"
    },
    {
      "x": -15,
      "y": 28,
      "z": -9,
      "name": "Rock_Volcanic"
    },
    {
      "x": -15,
      "y": 29,
      "z": -9,
      "name": "Rock_Volcanic"
    },
    {
      "x": -15,
      "y": 30,
      "z": -9,
      "name": "Rock_Volcanic"
    },
    {
      "x": -15,
      "y": 31,
      "z": -9,
      "name": "Rock_Volcanic"
    },
    {
      "x": -15,
      "y": 24,
      "z": -8,
      "name": "Rock_Volcanic"
    },
    {
      "x": -15,
      "y": 25,
      "z": -8,
      "name": "Rock_Volcanic"
    },
    {
      "x": -15,
      "y": 26,
      "z": -8,
      "name": "Rock_Volcanic"
    },
    {
      "x": -15,
      "y": 27,
      "z": -8,
      "name": "Rock_Volcanic"
    },
    {
      "x": -15,
      "y": 28,
      "z": -8,
      "name": "Rock_Volcanic"
    },
    {
      "x": -15,
      "y": 29,
      "z": -8,
      "name": "Rock_Volcanic"
    },
    {
      "x": -15,
      "y": 30,
      "z": -8,
      "name": "Rock_Volcanic"
    },
    {
      "x": -14,
      "y": 8,
      "z": -18,
      "name": "Rock_Volcanic"
    },
    {
      "x": -14,
      "y": 9,
      "z": -18,
      "name": "Rock_Volcanic"
    },
    {
      "x": -14,
      "y": 10,
      "z": -18,
      "name": "Rock_Volcanic"
    },
    {
      "x": -14,
      "y": 11,
      "z": -18,
      "name": "Rock_Volcanic"
    },
    {
      "x": -14,
      "y": 12,
      "z": -18,
      "name": "Rock_Volcanic"
    },
    {
      "x": -14,
      "y": 13,
      "z": -18,
      "name": "Rock_Volcanic"
    },
    {
      "x": -14,
      "y": 14,
      "z": -18,
      "name": "Rock_Volcanic"
    },
    {
      "x": -14,
      "y": 15,
      "z": -18,
      "name": "Rock_Volcanic"
    },
    {
      "x": -14,
      "y": 16,
      "z": -18,
      "name": "Rock_Volcanic"
    },
    {
      "x": -14,
      "y": 17,
      "z": -18,
      "name": "Rock_Volcanic"
    },
    {
      "x": -14,
      "y": 18,
      "z": -18,
      "name": "Rock_Volcanic"
    },
    {
      "x": -14,
      "y": 19,
      "z": -18,
      "name": "Rock_Volcanic"
    },
    {
      "x": -14,
      "y": 6,
      "z": -17,
      "name": "Rock_Volcanic"
    },
    {
      "x": -14,
      "y": 7,
      "z": -17,
      "name": "Rock_Volcanic"
    },
    {
      "x": -14,
      "y": 8,
      "z": -17,
      "name": "Rock_Volcanic"
    },
    {
      "x": -14,
      "y": 9,
      "z": -17,
      "name": "Rock_Volcanic"
    },
    {
      "x": -14,
      "y": 10,
      "z": -17,
      "name": "Rock_Volcanic"
    },
    {
      "x": -14,
      "y": 11,
      "z": -17,
      "name": "Rock_Volcanic"
    },
    {
      "x": -14,
      "y": 12,
      "z": -17,
      "name": "Rock_Volcanic"
    },
    {
      "x": -14,
      "y": 13,
      "z": -17,
      "name": "Rock_Volcanic"
    },
    {
      "x": -14,
      "y": 14,
      "z": -17,
      "name": "Rock_Volcanic"
    },
    {
      "x": -14,
      "y": 15,
      "z": -17,
      "name": "Rock_Volcanic"
    },
    {
      "x": -14,
      "y": 16,
      "z": -17,
      "name": "Rock_Volcanic"
    },
    {
      "x": -14,
      "y": 17,
      "z": -17,
      "name": "Rock_Volcanic"
    },
    {
      "x": -14,
      "y": 18,
      "z": -17,
      "name": "Rock_Volcanic"
    },
    {
      "x": -14,
      "y": 19,
      "z": -17,
      "name": "Rock_Volcanic"
    },
    {
      "x": -14,
      "y": 20,
      "z": -17,
      "name": "Rock_Volcanic"
    },
    {
      "x": -14,
      "y": 5,
      "z": -16,
      "name": "Rock_Volcanic"
    },
    {
      "x": -14,
      "y": 6,
      "z": -16,
      "name": "Rock_Volcanic"
    },
    {
      "x": -14,
      "y": 7,
      "z": -16,
      "name": "Rock_Volcanic"
    },
    {
      "x": -14,
      "y": 8,
      "z": -16,
      "name": "Rock_Volcanic"
    },
    {
      "x": -14,
      "y": 9,
      "z": -16,
      "name": "Rock_Volcanic"
    },
    {
      "x": -14,
      "y": 10,
      "z": -16,
      "name": "Rock_Volcanic"
    },
    {
      "x": -14,
      "y": 11,
      "z": -16,
      "name": "Rock_Volcanic"
    },
    {
      "x": -14,
      "y": 12,
      "z": -16,
      "name": "Rock_Volcanic"
    },
    {
      "x": -14,
      "y": 13,
      "z": -16,
      "name": "Rock_Volcanic"
    },
    {
      "x": -14,
      "y": 14,
      "z": -16,
      "name": "Rock_Volcanic"
    },
    {
      "x": -14,
      "y": 15,
      "z": -16,
      "name": "Rock_Volcanic"
    },
    {
      "x": -14,
      "y": 16,
      "z": -16,
      "name": "Rock_Volcanic"
    },
    {
      "x": -14,
      "y": 17,
      "z": -16,
      "name": "Rock_Volcanic"
    },
    {
      "x": -14,
      "y": 18,
      "z": -16,
      "name": "Rock_Volcanic"
    },
    {
      "x": -14,
      "y": 19,
      "z": -16,
      "name": "Rock_Volcanic"
    },
    {
      "x": -14,
      "y": 20,
      "z": -16,
      "name": "Rock_Volcanic"
    },
    {
      "x": -14,
      "y": 21,
      "z": -16,
      "name": "Rock_Volcanic"
    },
    {
      "x": -14,
      "y": 4,
      "z": -15,
      "name": "Rock_Volcanic"
    },
    {
      "x": -14,
      "y": 5,
      "z": -15,
      "name": "Rock_Volcanic"
    },
    {
      "x": -14,
      "y": 6,
      "z": -15,
      "name": "Rock_Volcanic"
    },
    {
      "x": -14,
      "y": 7,
      "z": -15,
      "name": "Rock_Volcanic"
    },
    {
      "x": -14,
      "y": 8,
      "z": -15,
      "name": "Rock_Volcanic"
    },
    {
      "x": -14,
      "y": 9,
      "z": -15,
      "name": "Rock_Volcanic"
    },
    {
      "x": -14,
      "y": 10,
      "z": -15,
      "name": "Rock_Volcanic"
    },
    {
      "x": -14,
      "y": 11,
      "z": -15,
      "name": "Rock_Volcanic"
    },
    {
      "x": -14,
      "y": 12,
      "z": -15,
      "name": "Rock_Volcanic"
    },
    {
      "x": -14,
      "y": 13,
      "z": -15,
      "name": "Rock_Volcanic"
    },
    {
      "x": -14,
      "y": 14,
      "z": -15,
      "name": "Rock_Volcanic"
    },
    {
      "x": -14,
      "y": 15,
      "z": -15,
      "name": "Rock_Volcanic"
    },
    {
      "x": -14,
      "y": 16,
      "z": -15,
      "name": "Rock_Volcanic"
    },
    {
      "x": -14,
      "y": 17,
      "z": -15,
      "name": "Rock_Volcanic"
    },
    {
      "x": -14,
      "y": 18,
      "z": -15,
      "name": "Rock_Volcanic"
    },
    {
      "x": -14,
      "y": 19,
      "z": -15,
      "name": "Rock_Volcanic"
    },
    {
      "x": -14,
      "y": 20,
      "z": -15,
      "name": "Rock_Volcanic"
    },
    {
      "x": -14,
      "y": 21,
      "z": -15,
      "name": "Rock_Volcanic"
    },
    {
      "x": -14,
      "y": 22,
      "z": -15,
      "name": "Rock_Volcanic"
    },
    {
      "x": -14,
      "y": 23,
      "z": -15,
      "name": "Rock_Volcanic"
    },
    {
      "x": -14,
      "y": 4,
      "z": -14,
      "name": "Rock_Volcanic"
    },
    {
      "x": -14,
      "y": 5,
      "z": -14,
      "name": "Rock_Volcanic"
    },
    {
      "x": -14,
      "y": 6,
      "z": -14,
      "name": "Rock_Volcanic"
    },
    {
      "x": -14,
      "y": 7,
      "z": -14,
      "name": "Rock_Volcanic"
    },
    {
      "x": -14,
      "y": 8,
      "z": -14,
      "name": "Rock_Volcanic"
    },
    {
      "x": -14,
      "y": 9,
      "z": -14,
      "name": "Rock_Volcanic"
    },
    {
      "x": -14,
      "y": 10,
      "z": -14,
      "name": "Rock_Volcanic"
    },
    {
      "x": -14,
      "y": 11,
      "z": -14,
      "name": "Rock_Volcanic"
    },
    {
      "x": -14,
      "y": 12,
      "z": -14,
      "name": "Rock_Volcanic"
    },
    {
      "x": -14,
      "y": 13,
      "z": -14,
      "name": "Rock_Volcanic"
    },
    {
      "x": -14,
      "y": 14,
      "z": -14,
      "name": "Rock_Volcanic"
    },
    {
      "x": -14,
      "y": 15,
      "z": -14,
      "name": "Rock_Volcanic"
    },
    {
      "x": -14,
      "y": 16,
      "z": -14,
      "name": "Rock_Volcanic"
    },
    {
      "x": -14,
      "y": 17,
      "z": -14,
      "name": "Rock_Volcanic"
    },
    {
      "x": -14,
      "y": 18,
      "z": -14,
      "name": "Rock_Volcanic"
    },
    {
      "x": -14,
      "y": 19,
      "z": -14,
      "name": "Rock_Volcanic"
    },
    {
      "x": -14,
      "y": 20,
      "z": -14,
      "name": "Rock_Volcanic"
    },
    {
      "x": -14,
      "y": 21,
      "z": -14,
      "name": "Rock_Volcanic"
    },
    {
      "x": -14,
      "y": 22,
      "z": -14,
      "name": "Rock_Volcanic"
    },
    {
      "x": -14,
      "y": 23,
      "z": -14,
      "name": "Rock_Volcanic"
    },
    {
      "x": -14,
      "y": 24,
      "z": -14,
      "name": "Rock_Volcanic"
    },
    {
      "x": -14,
      "y": 3,
      "z": -13,
      "name": "Rock_Volcanic"
    },
    {
      "x": -14,
      "y": 4,
      "z": -13,
      "name": "Rock_Volcanic"
    },
    {
      "x": -14,
      "y": 5,
      "z": -13,
      "name": "Rock_Volcanic"
    },
    {
      "x": -14,
      "y": 6,
      "z": -13,
      "name": "Rock_Volcanic"
    },
    {
      "x": -14,
      "y": 7,
      "z": -13,
      "name": "Rock_Volcanic"
    },
    {
      "x": -14,
      "y": 8,
      "z": -13,
      "name": "Rock_Volcanic"
    },
    {
      "x": -14,
      "y": 9,
      "z": -13,
      "name": "Rock_Volcanic"
    },
    {
      "x": -14,
      "y": 10,
      "z": -13,
      "name": "Rock_Volcanic"
    },
    {
      "x": -14,
      "y": 11,
      "z": -13,
      "name": "Rock_Volcanic"
    },
    {
      "x": -14,
      "y": 12,
      "z": -13,
      "name": "Rock_Volcanic"
    },
    {
      "x": -14,
      "y": 13,
      "z": -13,
      "name": "Rock_Volcanic"
    },
    {
      "x": -14,
      "y": 14,
      "z": -13,
      "name": "Rock_Volcanic"
    },
    {
      "x": -14,
      "y": 15,
      "z": -13,
      "name": "Rock_Volcanic"
    },
    {
      "x": -14,
      "y": 16,
      "z": -13,
      "name": "Rock_Volcanic"
    },
    {
      "x": -14,
      "y": 17,
      "z": -13,
      "name": "Rock_Volcanic"
    },
    {
      "x": -14,
      "y": 18,
      "z": -13,
      "name": "Rock_Volcanic"
    },
    {
      "x": -14,
      "y": 19,
      "z": -13,
      "name": "Rock_Volcanic"
    },
    {
      "x": -14,
      "y": 20,
      "z": -13,
      "name": "Rock_Volcanic"
    },
    {
      "x": -14,
      "y": 21,
      "z": -13,
      "name": "Rock_Volcanic"
    },
    {
      "x": -14,
      "y": 22,
      "z": -13,
      "name": "Rock_Volcanic"
    },
    {
      "x": -14,
      "y": 23,
      "z": -13,
      "name": "Rock_Volcanic"
    },
    {
      "x": -14,
      "y": 24,
      "z": -13,
      "name": "Rock_Volcanic"
    },
    {
      "x": -14,
      "y": 4,
      "z": -12,
      "name": "Rock_Volcanic"
    },
    {
      "x": -14,
      "y": 5,
      "z": -12,
      "name": "Rock_Volcanic"
    },
    {
      "x": -14,
      "y": 6,
      "z": -12,
      "name": "Rock_Volcanic"
    },
    {
      "x": -14,
      "y": 7,
      "z": -12,
      "name": "Rock_Volcanic"
    },
    {
      "x": -14,
      "y": 8,
      "z": -12,
      "name": "Rock_Volcanic"
    },
    {
      "x": -14,
      "y": 9,
      "z": -12,
      "name": "Rock_Volcanic"
    },
    {
      "x": -14,
      "y": 10,
      "z": -12,
      "name": "Rock_Volcanic"
    },
    {
      "x": -14,
      "y": 11,
      "z": -12,
      "name": "Rock_Volcanic"
    },
    {
      "x": -14,
      "y": 12,
      "z": -12,
      "name": "Rock_Volcanic"
    },
    {
      "x": -14,
      "y": 13,
      "z": -12,
      "name": "Rock_Volcanic"
    },
    {
      "x": -14,
      "y": 14,
      "z": -12,
      "name": "Rock_Volcanic"
    },
    {
      "x": -14,
      "y": 15,
      "z": -12,
      "name": "Rock_Volcanic"
    },
    {
      "x": -14,
      "y": 16,
      "z": -12,
      "name": "Rock_Volcanic"
    },
    {
      "x": -14,
      "y": 17,
      "z": -12,
      "name": "Rock_Volcanic"
    },
    {
      "x": -14,
      "y": 18,
      "z": -12,
      "name": "Rock_Volcanic"
    },
    {
      "x": -14,
      "y": 19,
      "z": -12,
      "name": "Rock_Volcanic"
    },
    {
      "x": -14,
      "y": 20,
      "z": -12,
      "name": "Rock_Volcanic"
    },
    {
      "x": -14,
      "y": 21,
      "z": -12,
      "name": "Rock_Volcanic"
    },
    {
      "x": -14,
      "y": 22,
      "z": -12,
      "name": "Rock_Volcanic"
    },
    {
      "x": -14,
      "y": 23,
      "z": -12,
      "name": "Rock_Volcanic"
    },
    {
      "x": -14,
      "y": 24,
      "z": -12,
      "name": "Rock_Volcanic"
    },
    {
      "x": -14,
      "y": 25,
      "z": -12,
      "name": "Rock_Volcanic"
    },
    {
      "x": -14,
      "y": 26,
      "z": -12,
      "name": "Rock_Volcanic"
    },
    {
      "x": -14,
      "y": 27,
      "z": -12,
      "name": "Rock_Volcanic"
    },
    {
      "x": -14,
      "y": 5,
      "z": -11,
      "name": "Rock_Volcanic"
    },
    {
      "x": -14,
      "y": 6,
      "z": -11,
      "name": "Rock_Volcanic"
    },
    {
      "x": -14,
      "y": 7,
      "z": -11,
      "name": "Rock_Volcanic"
    },
    {
      "x": -14,
      "y": 8,
      "z": -11,
      "name": "Rock_Volcanic"
    },
    {
      "x": -14,
      "y": 9,
      "z": -11,
      "name": "Rock_Volcanic"
    },
    {
      "x": -14,
      "y": 10,
      "z": -11,
      "name": "Rock_Volcanic"
    },
    {
      "x": -14,
      "y": 11,
      "z": -11,
      "name": "Rock_Volcanic"
    },
    {
      "x": -14,
      "y": 12,
      "z": -11,
      "name": "Rock_Volcanic"
    },
    {
      "x": -14,
      "y": 13,
      "z": -11,
      "name": "Rock_Volcanic"
    },
    {
      "x": -14,
      "y": 14,
      "z": -11,
      "name": "Rock_Volcanic"
    },
    {
      "x": -14,
      "y": 15,
      "z": -11,
      "name": "Rock_Volcanic"
    },
    {
      "x": -14,
      "y": 16,
      "z": -11,
      "name": "Rock_Volcanic"
    },
    {
      "x": -14,
      "y": 17,
      "z": -11,
      "name": "Rock_Volcanic"
    },
    {
      "x": -14,
      "y": 18,
      "z": -11,
      "name": "Rock_Volcanic"
    },
    {
      "x": -14,
      "y": 19,
      "z": -11,
      "name": "Rock_Volcanic"
    },
    {
      "x": -14,
      "y": 20,
      "z": -11,
      "name": "Rock_Volcanic"
    },
    {
      "x": -14,
      "y": 21,
      "z": -11,
      "name": "Rock_Volcanic"
    },
    {
      "x": -14,
      "y": 22,
      "z": -11,
      "name": "Rock_Volcanic"
    },
    {
      "x": -14,
      "y": 23,
      "z": -11,
      "name": "Rock_Volcanic"
    },
    {
      "x": -14,
      "y": 24,
      "z": -11,
      "name": "Rock_Volcanic"
    },
    {
      "x": -14,
      "y": 25,
      "z": -11,
      "name": "Rock_Volcanic"
    },
    {
      "x": -14,
      "y": 26,
      "z": -11,
      "name": "Rock_Volcanic"
    },
    {
      "x": -14,
      "y": 27,
      "z": -11,
      "name": "Rock_Volcanic"
    },
    {
      "x": -14,
      "y": 28,
      "z": -11,
      "name": "Rock_Volcanic"
    },
    {
      "x": -14,
      "y": 8,
      "z": -10,
      "name": "Rock_Volcanic"
    },
    {
      "x": -14,
      "y": 9,
      "z": -10,
      "name": "Rock_Volcanic"
    },
    {
      "x": -14,
      "y": 10,
      "z": -10,
      "name": "Rock_Volcanic"
    },
    {
      "x": -14,
      "y": 11,
      "z": -10,
      "name": "Rock_Volcanic"
    },
    {
      "x": -14,
      "y": 12,
      "z": -10,
      "name": "Rock_Volcanic"
    },
    {
      "x": -14,
      "y": 13,
      "z": -10,
      "name": "Rock_Volcanic"
    },
    {
      "x": -14,
      "y": 14,
      "z": -10,
      "name": "Rock_Volcanic"
    },
    {
      "x": -14,
      "y": 15,
      "z": -10,
      "name": "Rock_Volcanic"
    },
    {
      "x": -14,
      "y": 16,
      "z": -10,
      "name": "Rock_Volcanic"
    },
    {
      "x": -14,
      "y": 17,
      "z": -10,
      "name": "Rock_Volcanic"
    },
    {
      "x": -14,
      "y": 18,
      "z": -10,
      "name": "Rock_Volcanic"
    },
    {
      "x": -14,
      "y": 19,
      "z": -10,
      "name": "Rock_Volcanic"
    },
    {
      "x": -14,
      "y": 20,
      "z": -10,
      "name": "Rock_Volcanic"
    },
    {
      "x": -14,
      "y": 21,
      "z": -10,
      "name": "Rock_Volcanic"
    },
    {
      "x": -14,
      "y": 22,
      "z": -10,
      "name": "Rock_Volcanic"
    },
    {
      "x": -14,
      "y": 23,
      "z": -10,
      "name": "Rock_Volcanic"
    },
    {
      "x": -14,
      "y": 24,
      "z": -10,
      "name": "Rock_Volcanic"
    },
    {
      "x": -14,
      "y": 25,
      "z": -10,
      "name": "Rock_Volcanic"
    },
    {
      "x": -14,
      "y": 26,
      "z": -10,
      "name": "Rock_Volcanic"
    },
    {
      "x": -14,
      "y": 27,
      "z": -10,
      "name": "Rock_Volcanic"
    },
    {
      "x": -14,
      "y": 28,
      "z": -10,
      "name": "Rock_Volcanic"
    },
    {
      "x": -14,
      "y": 29,
      "z": -10,
      "name": "Rock_Volcanic"
    },
    {
      "x": -14,
      "y": 12,
      "z": -9,
      "name": "Rock_Volcanic"
    },
    {
      "x": -14,
      "y": 13,
      "z": -9,
      "name": "Rock_Volcanic"
    },
    {
      "x": -14,
      "y": 14,
      "z": -9,
      "name": "Rock_Volcanic"
    },
    {
      "x": -14,
      "y": 15,
      "z": -9,
      "name": "Rock_Volcanic"
    },
    {
      "x": -14,
      "y": 16,
      "z": -9,
      "name": "Rock_Volcanic"
    },
    {
      "x": -14,
      "y": 17,
      "z": -9,
      "name": "Rock_Volcanic"
    },
    {
      "x": -14,
      "y": 18,
      "z": -9,
      "name": "Rock_Volcanic"
    },
    {
      "x": -14,
      "y": 19,
      "z": -9,
      "name": "Rock_Volcanic"
    },
    {
      "x": -14,
      "y": 20,
      "z": -9,
      "name": "Rock_Volcanic"
    },
    {
      "x": -14,
      "y": 21,
      "z": -9,
      "name": "Rock_Volcanic"
    },
    {
      "x": -14,
      "y": 22,
      "z": -9,
      "name": "Rock_Volcanic"
    },
    {
      "x": -14,
      "y": 23,
      "z": -9,
      "name": "Rock_Volcanic"
    },
    {
      "x": -14,
      "y": 24,
      "z": -9,
      "name": "Rock_Volcanic"
    },
    {
      "x": -14,
      "y": 25,
      "z": -9,
      "name": "Rock_Volcanic"
    },
    {
      "x": -14,
      "y": 26,
      "z": -9,
      "name": "Rock_Volcanic"
    },
    {
      "x": -14,
      "y": 27,
      "z": -9,
      "name": "Rock_Volcanic"
    },
    {
      "x": -14,
      "y": 28,
      "z": -9,
      "name": "Rock_Volcanic"
    },
    {
      "x": -14,
      "y": 29,
      "z": -9,
      "name": "Rock_Volcanic"
    },
    {
      "x": -14,
      "y": 16,
      "z": -8,
      "name": "Rock_Volcanic"
    },
    {
      "x": -14,
      "y": 17,
      "z": -8,
      "name": "Rock_Volcanic"
    },
    {
      "x": -14,
      "y": 18,
      "z": -8,
      "name": "Rock_Volcanic"
    },
    {
      "x": -14,
      "y": 19,
      "z": -8,
      "name": "Rock_Volcanic"
    },
    {
      "x": -14,
      "y": 20,
      "z": -8,
      "name": "Rock_Volcanic"
    },
    {
      "x": -14,
      "y": 24,
      "z": -8,
      "name": "Rock_Volcanic"
    },
    {
      "x": -14,
      "y": 25,
      "z": -8,
      "name": "Rock_Volcanic"
    },
    {
      "x": -14,
      "y": 26,
      "z": -8,
      "name": "Rock_Volcanic"
    },
    {
      "x": -14,
      "y": 27,
      "z": -8,
      "name": "Rock_Volcanic"
    },
    {
      "x": -13,
      "y": 6,
      "z": -17,
      "name": "Rock_Volcanic"
    },
    {
      "x": -13,
      "y": 7,
      "z": -17,
      "name": "Rock_Volcanic"
    },
    {
      "x": -13,
      "y": 8,
      "z": -17,
      "name": "Rock_Volcanic"
    },
    {
      "x": -13,
      "y": 9,
      "z": -17,
      "name": "Rock_Volcanic"
    },
    {
      "x": -13,
      "y": 10,
      "z": -17,
      "name": "Rock_Volcanic"
    },
    {
      "x": -13,
      "y": 11,
      "z": -17,
      "name": "Rock_Volcanic"
    },
    {
      "x": -13,
      "y": 12,
      "z": -17,
      "name": "Rock_Volcanic"
    },
    {
      "x": -13,
      "y": 13,
      "z": -17,
      "name": "Rock_Volcanic"
    },
    {
      "x": -13,
      "y": 14,
      "z": -17,
      "name": "Rock_Volcanic"
    },
    {
      "x": -13,
      "y": 15,
      "z": -17,
      "name": "Rock_Volcanic"
    },
    {
      "x": -13,
      "y": 16,
      "z": -17,
      "name": "Rock_Volcanic"
    },
    {
      "x": -13,
      "y": 17,
      "z": -17,
      "name": "Rock_Volcanic"
    },
    {
      "x": -13,
      "y": 18,
      "z": -17,
      "name": "Rock_Volcanic"
    },
    {
      "x": -13,
      "y": 19,
      "z": -17,
      "name": "Rock_Volcanic"
    },
    {
      "x": -13,
      "y": 5,
      "z": -16,
      "name": "Rock_Volcanic"
    },
    {
      "x": -13,
      "y": 6,
      "z": -16,
      "name": "Rock_Volcanic"
    },
    {
      "x": -13,
      "y": 7,
      "z": -16,
      "name": "Rock_Volcanic"
    },
    {
      "x": -13,
      "y": 8,
      "z": -16,
      "name": "Rock_Volcanic"
    },
    {
      "x": -13,
      "y": 9,
      "z": -16,
      "name": "Rock_Volcanic"
    },
    {
      "x": -13,
      "y": 10,
      "z": -16,
      "name": "Rock_Volcanic"
    },
    {
      "x": -13,
      "y": 11,
      "z": -16,
      "name": "Rock_Volcanic"
    },
    {
      "x": -13,
      "y": 12,
      "z": -16,
      "name": "Rock_Volcanic"
    },
    {
      "x": -13,
      "y": 13,
      "z": -16,
      "name": "Rock_Volcanic"
    },
    {
      "x": -13,
      "y": 14,
      "z": -16,
      "name": "Rock_Volcanic"
    },
    {
      "x": -13,
      "y": 15,
      "z": -16,
      "name": "Rock_Volcanic"
    },
    {
      "x": -13,
      "y": 16,
      "z": -16,
      "name": "Rock_Volcanic"
    },
    {
      "x": -13,
      "y": 17,
      "z": -16,
      "name": "Rock_Volcanic"
    },
    {
      "x": -13,
      "y": 18,
      "z": -16,
      "name": "Rock_Volcanic"
    },
    {
      "x": -13,
      "y": 19,
      "z": -16,
      "name": "Rock_Volcanic"
    },
    {
      "x": -13,
      "y": 20,
      "z": -16,
      "name": "Rock_Volcanic"
    },
    {
      "x": -13,
      "y": 21,
      "z": -16,
      "name": "Rock_Volcanic"
    },
    {
      "x": -13,
      "y": 22,
      "z": -16,
      "name": "Rock_Volcanic"
    },
    {
      "x": -13,
      "y": 4,
      "z": -15,
      "name": "Rock_Volcanic"
    },
    {
      "x": -13,
      "y": 5,
      "z": -15,
      "name": "Rock_Volcanic"
    },
    {
      "x": -13,
      "y": 6,
      "z": -15,
      "name": "Rock_Volcanic"
    },
    {
      "x": -13,
      "y": 7,
      "z": -15,
      "name": "Rock_Volcanic"
    },
    {
      "x": -13,
      "y": 8,
      "z": -15,
      "name": "Rock_Volcanic"
    },
    {
      "x": -13,
      "y": 9,
      "z": -15,
      "name": "Rock_Volcanic"
    },
    {
      "x": -13,
      "y": 10,
      "z": -15,
      "name": "Rock_Volcanic"
    },
    {
      "x": -13,
      "y": 11,
      "z": -15,
      "name": "Rock_Volcanic"
    },
    {
      "x": -13,
      "y": 12,
      "z": -15,
      "name": "Rock_Volcanic"
    },
    {
      "x": -13,
      "y": 13,
      "z": -15,
      "name": "Rock_Volcanic"
    },
    {
      "x": -13,
      "y": 14,
      "z": -15,
      "name": "Rock_Volcanic"
    },
    {
      "x": -13,
      "y": 15,
      "z": -15,
      "name": "Rock_Volcanic"
    },
    {
      "x": -13,
      "y": 16,
      "z": -15,
      "name": "Rock_Volcanic"
    },
    {
      "x": -13,
      "y": 17,
      "z": -15,
      "name": "Rock_Volcanic"
    },
    {
      "x": -13,
      "y": 18,
      "z": -15,
      "name": "Rock_Volcanic"
    },
    {
      "x": -13,
      "y": 19,
      "z": -15,
      "name": "Rock_Volcanic"
    },
    {
      "x": -13,
      "y": 20,
      "z": -15,
      "name": "Rock_Volcanic"
    },
    {
      "x": -13,
      "y": 21,
      "z": -15,
      "name": "Rock_Volcanic"
    },
    {
      "x": -13,
      "y": 22,
      "z": -15,
      "name": "Rock_Volcanic"
    },
    {
      "x": -13,
      "y": 23,
      "z": -15,
      "name": "Rock_Volcanic"
    },
    {
      "x": -13,
      "y": 24,
      "z": -15,
      "name": "Rock_Volcanic"
    },
    {
      "x": -13,
      "y": 3,
      "z": -14,
      "name": "Rock_Volcanic"
    },
    {
      "x": -13,
      "y": 4,
      "z": -14,
      "name": "Rock_Volcanic"
    },
    {
      "x": -13,
      "y": 5,
      "z": -14,
      "name": "Rock_Volcanic"
    },
    {
      "x": -13,
      "y": 6,
      "z": -14,
      "name": "Rock_Volcanic"
    },
    {
      "x": -13,
      "y": 7,
      "z": -14,
      "name": "Rock_Volcanic"
    },
    {
      "x": -13,
      "y": 8,
      "z": -14,
      "name": "Rock_Volcanic"
    },
    {
      "x": -13,
      "y": 9,
      "z": -14,
      "name": "Rock_Volcanic"
    },
    {
      "x": -13,
      "y": 10,
      "z": -14,
      "name": "Rock_Volcanic"
    },
    {
      "x": -13,
      "y": 11,
      "z": -14,
      "name": "Rock_Volcanic"
    },
    {
      "x": -13,
      "y": 12,
      "z": -14,
      "name": "Rock_Volcanic"
    },
    {
      "x": -13,
      "y": 13,
      "z": -14,
      "name": "Rock_Volcanic"
    },
    {
      "x": -13,
      "y": 14,
      "z": -14,
      "name": "Rock_Volcanic"
    },
    {
      "x": -13,
      "y": 15,
      "z": -14,
      "name": "Rock_Volcanic"
    },
    {
      "x": -13,
      "y": 16,
      "z": -14,
      "name": "Rock_Volcanic"
    },
    {
      "x": -13,
      "y": 17,
      "z": -14,
      "name": "Rock_Volcanic"
    },
    {
      "x": -13,
      "y": 18,
      "z": -14,
      "name": "Rock_Volcanic"
    },
    {
      "x": -13,
      "y": 19,
      "z": -14,
      "name": "Rock_Volcanic"
    },
    {
      "x": -13,
      "y": 20,
      "z": -14,
      "name": "Rock_Volcanic"
    },
    {
      "x": -13,
      "y": 21,
      "z": -14,
      "name": "Rock_Volcanic"
    },
    {
      "x": -13,
      "y": 22,
      "z": -14,
      "name": "Rock_Volcanic"
    },
    {
      "x": -13,
      "y": 23,
      "z": -14,
      "name": "Rock_Volcanic"
    },
    {
      "x": -13,
      "y": 24,
      "z": -14,
      "name": "Rock_Volcanic"
    },
    {
      "x": -13,
      "y": 25,
      "z": -14,
      "name": "Rock_Volcanic"
    },
    {
      "x": -13,
      "y": 3,
      "z": -13,
      "name": "Rock_Volcanic"
    },
    {
      "x": -13,
      "y": 4,
      "z": -13,
      "name": "Rock_Volcanic"
    },
    {
      "x": -13,
      "y": 5,
      "z": -13,
      "name": "Rock_Volcanic"
    },
    {
      "x": -13,
      "y": 6,
      "z": -13,
      "name": "Rock_Volcanic"
    },
    {
      "x": -13,
      "y": 7,
      "z": -13,
      "name": "Rock_Volcanic"
    },
    {
      "x": -13,
      "y": 8,
      "z": -13,
      "name": "Rock_Volcanic"
    },
    {
      "x": -13,
      "y": 9,
      "z": -13,
      "name": "Rock_Volcanic"
    },
    {
      "x": -13,
      "y": 10,
      "z": -13,
      "name": "Rock_Volcanic"
    },
    {
      "x": -13,
      "y": 11,
      "z": -13,
      "name": "Rock_Volcanic"
    },
    {
      "x": -13,
      "y": 12,
      "z": -13,
      "name": "Rock_Volcanic"
    },
    {
      "x": -13,
      "y": 13,
      "z": -13,
      "name": "Rock_Volcanic"
    },
    {
      "x": -13,
      "y": 14,
      "z": -13,
      "name": "Rock_Volcanic"
    },
    {
      "x": -13,
      "y": 15,
      "z": -13,
      "name": "Rock_Volcanic"
    },
    {
      "x": -13,
      "y": 16,
      "z": -13,
      "name": "Rock_Volcanic"
    },
    {
      "x": -13,
      "y": 17,
      "z": -13,
      "name": "Rock_Volcanic"
    },
    {
      "x": -13,
      "y": 18,
      "z": -13,
      "name": "Rock_Volcanic"
    },
    {
      "x": -13,
      "y": 19,
      "z": -13,
      "name": "Rock_Volcanic"
    },
    {
      "x": -13,
      "y": 20,
      "z": -13,
      "name": "Rock_Volcanic"
    },
    {
      "x": -13,
      "y": 21,
      "z": -13,
      "name": "Rock_Volcanic"
    },
    {
      "x": -13,
      "y": 22,
      "z": -13,
      "name": "Rock_Volcanic"
    },
    {
      "x": -13,
      "y": 23,
      "z": -13,
      "name": "Rock_Volcanic"
    },
    {
      "x": -13,
      "y": 24,
      "z": -13,
      "name": "Rock_Volcanic"
    },
    {
      "x": -13,
      "y": 25,
      "z": -13,
      "name": "Rock_Volcanic"
    },
    {
      "x": -13,
      "y": 26,
      "z": -13,
      "name": "Rock_Volcanic"
    },
    {
      "x": -13,
      "y": 3,
      "z": -12,
      "name": "Rock_Volcanic"
    },
    {
      "x": -13,
      "y": 4,
      "z": -12,
      "name": "Rock_Volcanic"
    },
    {
      "x": -13,
      "y": 5,
      "z": -12,
      "name": "Rock_Volcanic"
    },
    {
      "x": -13,
      "y": 6,
      "z": -12,
      "name": "Rock_Volcanic"
    },
    {
      "x": -13,
      "y": 7,
      "z": -12,
      "name": "Rock_Volcanic"
    },
    {
      "x": -13,
      "y": 8,
      "z": -12,
      "name": "Rock_Volcanic"
    },
    {
      "x": -13,
      "y": 9,
      "z": -12,
      "name": "Rock_Volcanic"
    },
    {
      "x": -13,
      "y": 10,
      "z": -12,
      "name": "Rock_Volcanic"
    },
    {
      "x": -13,
      "y": 11,
      "z": -12,
      "name": "Rock_Volcanic"
    },
    {
      "x": -13,
      "y": 12,
      "z": -12,
      "name": "Rock_Volcanic"
    },
    {
      "x": -13,
      "y": 13,
      "z": -12,
      "name": "Rock_Volcanic"
    },
    {
      "x": -13,
      "y": 14,
      "z": -12,
      "name": "Rock_Volcanic"
    },
    {
      "x": -13,
      "y": 15,
      "z": -12,
      "name": "Rock_Volcanic"
    },
    {
      "x": -13,
      "y": 16,
      "z": -12,
      "name": "Rock_Volcanic"
    },
    {
      "x": -13,
      "y": 17,
      "z": -12,
      "name": "Rock_Volcanic"
    },
    {
      "x": -13,
      "y": 18,
      "z": -12,
      "name": "Rock_Volcanic"
    },
    {
      "x": -13,
      "y": 19,
      "z": -12,
      "name": "Rock_Volcanic"
    },
    {
      "x": -13,
      "y": 20,
      "z": -12,
      "name": "Rock_Volcanic"
    },
    {
      "x": -13,
      "y": 21,
      "z": -12,
      "name": "Rock_Volcanic"
    },
    {
      "x": -13,
      "y": 22,
      "z": -12,
      "name": "Rock_Volcanic"
    },
    {
      "x": -13,
      "y": 23,
      "z": -12,
      "name": "Rock_Volcanic"
    },
    {
      "x": -13,
      "y": 24,
      "z": -12,
      "name": "Rock_Volcanic"
    },
    {
      "x": -13,
      "y": 25,
      "z": -12,
      "name": "Rock_Volcanic"
    },
    {
      "x": -13,
      "y": 26,
      "z": -12,
      "name": "Rock_Volcanic"
    },
    {
      "x": -13,
      "y": 27,
      "z": -12,
      "name": "Rock_Volcanic"
    },
    {
      "x": -13,
      "y": 4,
      "z": -11,
      "name": "Rock_Volcanic"
    },
    {
      "x": -13,
      "y": 5,
      "z": -11,
      "name": "Rock_Volcanic"
    },
    {
      "x": -13,
      "y": 6,
      "z": -11,
      "name": "Rock_Volcanic"
    },
    {
      "x": -13,
      "y": 7,
      "z": -11,
      "name": "Rock_Volcanic"
    },
    {
      "x": -13,
      "y": 8,
      "z": -11,
      "name": "Rock_Volcanic"
    },
    {
      "x": -13,
      "y": 9,
      "z": -11,
      "name": "Rock_Volcanic"
    },
    {
      "x": -13,
      "y": 10,
      "z": -11,
      "name": "Rock_Volcanic"
    },
    {
      "x": -13,
      "y": 11,
      "z": -11,
      "name": "Rock_Volcanic"
    },
    {
      "x": -13,
      "y": 12,
      "z": -11,
      "name": "Rock_Volcanic"
    },
    {
      "x": -13,
      "y": 13,
      "z": -11,
      "name": "Rock_Volcanic"
    },
    {
      "x": -13,
      "y": 14,
      "z": -11,
      "name": "Rock_Volcanic"
    },
    {
      "x": -13,
      "y": 15,
      "z": -11,
      "name": "Rock_Volcanic"
    },
    {
      "x": -13,
      "y": 16,
      "z": -11,
      "name": "Rock_Volcanic"
    },
    {
      "x": -13,
      "y": 17,
      "z": -11,
      "name": "Rock_Volcanic"
    },
    {
      "x": -13,
      "y": 18,
      "z": -11,
      "name": "Rock_Volcanic"
    },
    {
      "x": -13,
      "y": 19,
      "z": -11,
      "name": "Rock_Volcanic"
    },
    {
      "x": -13,
      "y": 20,
      "z": -11,
      "name": "Rock_Volcanic"
    },
    {
      "x": -13,
      "y": 21,
      "z": -11,
      "name": "Rock_Volcanic"
    },
    {
      "x": -13,
      "y": 22,
      "z": -11,
      "name": "Rock_Volcanic"
    },
    {
      "x": -13,
      "y": 23,
      "z": -11,
      "name": "Rock_Volcanic"
    },
    {
      "x": -13,
      "y": 24,
      "z": -11,
      "name": "Rock_Volcanic"
    },
    {
      "x": -13,
      "y": 25,
      "z": -11,
      "name": "Rock_Volcanic"
    },
    {
      "x": -13,
      "y": 26,
      "z": -11,
      "name": "Rock_Volcanic"
    },
    {
      "x": -13,
      "y": 27,
      "z": -11,
      "name": "Rock_Volcanic"
    },
    {
      "x": -13,
      "y": 5,
      "z": -10,
      "name": "Rock_Volcanic"
    },
    {
      "x": -13,
      "y": 6,
      "z": -10,
      "name": "Rock_Volcanic"
    },
    {
      "x": -13,
      "y": 7,
      "z": -10,
      "name": "Rock_Volcanic"
    },
    {
      "x": -13,
      "y": 8,
      "z": -10,
      "name": "Rock_Volcanic"
    },
    {
      "x": -13,
      "y": 9,
      "z": -10,
      "name": "Rock_Volcanic"
    },
    {
      "x": -13,
      "y": 10,
      "z": -10,
      "name": "Rock_Volcanic"
    },
    {
      "x": -13,
      "y": 11,
      "z": -10,
      "name": "Rock_Volcanic"
    },
    {
      "x": -13,
      "y": 12,
      "z": -10,
      "name": "Rock_Volcanic"
    },
    {
      "x": -13,
      "y": 13,
      "z": -10,
      "name": "Rock_Volcanic"
    },
    {
      "x": -13,
      "y": 14,
      "z": -10,
      "name": "Rock_Volcanic"
    },
    {
      "x": -13,
      "y": 15,
      "z": -10,
      "name": "Rock_Volcanic"
    },
    {
      "x": -13,
      "y": 16,
      "z": -10,
      "name": "Rock_Volcanic"
    },
    {
      "x": -13,
      "y": 17,
      "z": -10,
      "name": "Rock_Volcanic"
    },
    {
      "x": -13,
      "y": 18,
      "z": -10,
      "name": "Rock_Volcanic"
    },
    {
      "x": -13,
      "y": 19,
      "z": -10,
      "name": "Rock_Volcanic"
    },
    {
      "x": -13,
      "y": 20,
      "z": -10,
      "name": "Rock_Volcanic"
    },
    {
      "x": -13,
      "y": 21,
      "z": -10,
      "name": "Rock_Volcanic"
    },
    {
      "x": -13,
      "y": 22,
      "z": -10,
      "name": "Rock_Volcanic"
    },
    {
      "x": -13,
      "y": 23,
      "z": -10,
      "name": "Rock_Volcanic"
    },
    {
      "x": -13,
      "y": 24,
      "z": -10,
      "name": "Rock_Volcanic"
    },
    {
      "x": -13,
      "y": 25,
      "z": -10,
      "name": "Rock_Volcanic"
    },
    {
      "x": -13,
      "y": 26,
      "z": -10,
      "name": "Rock_Volcanic"
    },
    {
      "x": -13,
      "y": 27,
      "z": -10,
      "name": "Rock_Volcanic"
    },
    {
      "x": -13,
      "y": 7,
      "z": -9,
      "name": "Rock_Volcanic"
    },
    {
      "x": -13,
      "y": 8,
      "z": -9,
      "name": "Rock_Volcanic"
    },
    {
      "x": -13,
      "y": 9,
      "z": -9,
      "name": "Rock_Volcanic"
    },
    {
      "x": -13,
      "y": 10,
      "z": -9,
      "name": "Rock_Volcanic"
    },
    {
      "x": -13,
      "y": 11,
      "z": -9,
      "name": "Rock_Volcanic"
    },
    {
      "x": -13,
      "y": 12,
      "z": -9,
      "name": "Rock_Volcanic"
    },
    {
      "x": -13,
      "y": 13,
      "z": -9,
      "name": "Rock_Volcanic"
    },
    {
      "x": -13,
      "y": 14,
      "z": -9,
      "name": "Rock_Volcanic"
    },
    {
      "x": -13,
      "y": 15,
      "z": -9,
      "name": "Rock_Volcanic"
    },
    {
      "x": -13,
      "y": 16,
      "z": -9,
      "name": "Rock_Volcanic"
    },
    {
      "x": -13,
      "y": 17,
      "z": -9,
      "name": "Rock_Volcanic"
    },
    {
      "x": -13,
      "y": 18,
      "z": -9,
      "name": "Rock_Volcanic"
    },
    {
      "x": -13,
      "y": 19,
      "z": -9,
      "name": "Rock_Volcanic"
    },
    {
      "x": -13,
      "y": 20,
      "z": -9,
      "name": "Rock_Volcanic"
    },
    {
      "x": -13,
      "y": 21,
      "z": -9,
      "name": "Rock_Volcanic"
    },
    {
      "x": -13,
      "y": 22,
      "z": -9,
      "name": "Rock_Volcanic"
    },
    {
      "x": -13,
      "y": 23,
      "z": -9,
      "name": "Rock_Volcanic"
    },
    {
      "x": -13,
      "y": 24,
      "z": -9,
      "name": "Rock_Volcanic"
    },
    {
      "x": -13,
      "y": 25,
      "z": -9,
      "name": "Rock_Volcanic"
    },
    {
      "x": -13,
      "y": 26,
      "z": -9,
      "name": "Rock_Volcanic"
    },
    {
      "x": -13,
      "y": 27,
      "z": -9,
      "name": "Rock_Volcanic"
    },
    {
      "x": -13,
      "y": 10,
      "z": -8,
      "name": "Rock_Volcanic"
    },
    {
      "x": -13,
      "y": 11,
      "z": -8,
      "name": "Rock_Volcanic"
    },
    {
      "x": -13,
      "y": 12,
      "z": -8,
      "name": "Rock_Volcanic"
    },
    {
      "x": -13,
      "y": 13,
      "z": -8,
      "name": "Rock_Volcanic"
    },
    {
      "x": -13,
      "y": 14,
      "z": -8,
      "name": "Rock_Volcanic"
    },
    {
      "x": -13,
      "y": 15,
      "z": -8,
      "name": "Rock_Volcanic"
    },
    {
      "x": -13,
      "y": 16,
      "z": -8,
      "name": "Rock_Volcanic"
    },
    {
      "x": -13,
      "y": 17,
      "z": -8,
      "name": "Rock_Volcanic"
    },
    {
      "x": -13,
      "y": 18,
      "z": -8,
      "name": "Rock_Volcanic"
    },
    {
      "x": -13,
      "y": 19,
      "z": -8,
      "name": "Rock_Volcanic"
    },
    {
      "x": -13,
      "y": 20,
      "z": -8,
      "name": "Rock_Volcanic"
    },
    {
      "x": -13,
      "y": 21,
      "z": -8,
      "name": "Rock_Volcanic"
    },
    {
      "x": -13,
      "y": 17,
      "z": -7,
      "name": "Rock_Volcanic"
    },
    {
      "x": -13,
      "y": 18,
      "z": -7,
      "name": "Rock_Volcanic"
    },
    {
      "x": -13,
      "y": 19,
      "z": -7,
      "name": "Rock_Volcanic"
    },
    {
      "x": -13,
      "y": 20,
      "z": -7,
      "name": "Rock_Volcanic"
    },
    {
      "x": -12,
      "y": 7,
      "z": -17,
      "name": "Rock_Volcanic"
    },
    {
      "x": -12,
      "y": 8,
      "z": -17,
      "name": "Rock_Volcanic"
    },
    {
      "x": -12,
      "y": 9,
      "z": -17,
      "name": "Rock_Volcanic"
    },
    {
      "x": -12,
      "y": 10,
      "z": -17,
      "name": "Rock_Volcanic"
    },
    {
      "x": -12,
      "y": 11,
      "z": -17,
      "name": "Rock_Volcanic"
    },
    {
      "x": -12,
      "y": 12,
      "z": -17,
      "name": "Rock_Volcanic"
    },
    {
      "x": -12,
      "y": 13,
      "z": -17,
      "name": "Rock_Volcanic"
    },
    {
      "x": -12,
      "y": 14,
      "z": -17,
      "name": "Rock_Volcanic"
    },
    {
      "x": -12,
      "y": 15,
      "z": -17,
      "name": "Rock_Volcanic"
    },
    {
      "x": -12,
      "y": 16,
      "z": -17,
      "name": "Rock_Volcanic"
    },
    {
      "x": -12,
      "y": 17,
      "z": -17,
      "name": "Rock_Volcanic"
    },
    {
      "x": -12,
      "y": 5,
      "z": -16,
      "name": "Rock_Volcanic"
    },
    {
      "x": -12,
      "y": 6,
      "z": -16,
      "name": "Rock_Volcanic"
    },
    {
      "x": -12,
      "y": 7,
      "z": -16,
      "name": "Rock_Volcanic"
    },
    {
      "x": -12,
      "y": 8,
      "z": -16,
      "name": "Rock_Volcanic"
    },
    {
      "x": -12,
      "y": 9,
      "z": -16,
      "name": "Rock_Volcanic"
    },
    {
      "x": -12,
      "y": 10,
      "z": -16,
      "name": "Rock_Volcanic"
    },
    {
      "x": -12,
      "y": 11,
      "z": -16,
      "name": "Rock_Volcanic"
    },
    {
      "x": -12,
      "y": 12,
      "z": -16,
      "name": "Rock_Volcanic"
    },
    {
      "x": -12,
      "y": 13,
      "z": -16,
      "name": "Rock_Volcanic"
    },
    {
      "x": -12,
      "y": 14,
      "z": -16,
      "name": "Rock_Volcanic"
    },
    {
      "x": -12,
      "y": 15,
      "z": -16,
      "name": "Rock_Volcanic"
    },
    {
      "x": -12,
      "y": 16,
      "z": -16,
      "name": "Rock_Volcanic"
    },
    {
      "x": -12,
      "y": 17,
      "z": -16,
      "name": "Rock_Volcanic"
    },
    {
      "x": -12,
      "y": 18,
      "z": -16,
      "name": "Rock_Volcanic"
    },
    {
      "x": -12,
      "y": 19,
      "z": -16,
      "name": "Rock_Volcanic"
    },
    {
      "x": -12,
      "y": 20,
      "z": -16,
      "name": "Rock_Volcanic"
    },
    {
      "x": -12,
      "y": 21,
      "z": -16,
      "name": "Rock_Volcanic"
    },
    {
      "x": -12,
      "y": 4,
      "z": -15,
      "name": "Rock_Volcanic"
    },
    {
      "x": -12,
      "y": 5,
      "z": -15,
      "name": "Rock_Volcanic"
    },
    {
      "x": -12,
      "y": 6,
      "z": -15,
      "name": "Rock_Volcanic"
    },
    {
      "x": -12,
      "y": 7,
      "z": -15,
      "name": "Rock_Volcanic"
    },
    {
      "x": -12,
      "y": 8,
      "z": -15,
      "name": "Rock_Volcanic"
    },
    {
      "x": -12,
      "y": 9,
      "z": -15,
      "name": "Rock_Volcanic"
    },
    {
      "x": -12,
      "y": 10,
      "z": -15,
      "name": "Rock_Volcanic"
    },
    {
      "x": -12,
      "y": 11,
      "z": -15,
      "name": "Rock_Volcanic"
    },
    {
      "x": -12,
      "y": 12,
      "z": -15,
      "name": "Rock_Volcanic"
    },
    {
      "x": -12,
      "y": 13,
      "z": -15,
      "name": "Rock_Volcanic"
    },
    {
      "x": -12,
      "y": 14,
      "z": -15,
      "name": "Rock_Volcanic"
    },
    {
      "x": -12,
      "y": 15,
      "z": -15,
      "name": "Rock_Volcanic"
    },
    {
      "x": -12,
      "y": 16,
      "z": -15,
      "name": "Rock_Volcanic"
    },
    {
      "x": -12,
      "y": 17,
      "z": -15,
      "name": "Rock_Volcanic"
    },
    {
      "x": -12,
      "y": 18,
      "z": -15,
      "name": "Rock_Volcanic"
    },
    {
      "x": -12,
      "y": 19,
      "z": -15,
      "name": "Rock_Volcanic"
    },
    {
      "x": -12,
      "y": 20,
      "z": -15,
      "name": "Rock_Volcanic"
    },
    {
      "x": -12,
      "y": 21,
      "z": -15,
      "name": "Rock_Volcanic"
    },
    {
      "x": -12,
      "y": 22,
      "z": -15,
      "name": "Rock_Volcanic"
    },
    {
      "x": -12,
      "y": 23,
      "z": -15,
      "name": "Rock_Volcanic"
    },
    {
      "x": -12,
      "y": 24,
      "z": -15,
      "name": "Rock_Volcanic"
    },
    {
      "x": -12,
      "y": 25,
      "z": -15,
      "name": "Rock_Volcanic"
    },
    {
      "x": -12,
      "y": 2,
      "z": -14,
      "name": "Rock_Volcanic"
    },
    {
      "x": -12,
      "y": 3,
      "z": -14,
      "name": "Rock_Volcanic"
    },
    {
      "x": -12,
      "y": 4,
      "z": -14,
      "name": "Rock_Volcanic"
    },
    {
      "x": -12,
      "y": 5,
      "z": -14,
      "name": "Rock_Volcanic"
    },
    {
      "x": -12,
      "y": 6,
      "z": -14,
      "name": "Rock_Volcanic"
    },
    {
      "x": -12,
      "y": 7,
      "z": -14,
      "name": "Rock_Volcanic"
    },
    {
      "x": -12,
      "y": 8,
      "z": -14,
      "name": "Rock_Volcanic"
    },
    {
      "x": -12,
      "y": 9,
      "z": -14,
      "name": "Rock_Volcanic"
    },
    {
      "x": -12,
      "y": 10,
      "z": -14,
      "name": "Rock_Volcanic"
    },
    {
      "x": -12,
      "y": 11,
      "z": -14,
      "name": "Rock_Volcanic"
    },
    {
      "x": -12,
      "y": 12,
      "z": -14,
      "name": "Rock_Volcanic"
    },
    {
      "x": -12,
      "y": 13,
      "z": -14,
      "name": "Rock_Volcanic"
    },
    {
      "x": -12,
      "y": 14,
      "z": -14,
      "name": "Rock_Volcanic"
    },
    {
      "x": -12,
      "y": 15,
      "z": -14,
      "name": "Rock_Volcanic"
    },
    {
      "x": -12,
      "y": 16,
      "z": -14,
      "name": "Rock_Volcanic"
    },
    {
      "x": -12,
      "y": 17,
      "z": -14,
      "name": "Rock_Volcanic"
    },
    {
      "x": -12,
      "y": 18,
      "z": -14,
      "name": "Rock_Volcanic"
    },
    {
      "x": -12,
      "y": 19,
      "z": -14,
      "name": "Rock_Volcanic"
    },
    {
      "x": -12,
      "y": 20,
      "z": -14,
      "name": "Rock_Volcanic"
    },
    {
      "x": -12,
      "y": 21,
      "z": -14,
      "name": "Rock_Volcanic"
    },
    {
      "x": -12,
      "y": 22,
      "z": -14,
      "name": "Rock_Volcanic"
    },
    {
      "x": -12,
      "y": 23,
      "z": -14,
      "name": "Rock_Volcanic"
    },
    {
      "x": -12,
      "y": 24,
      "z": -14,
      "name": "Rock_Volcanic"
    },
    {
      "x": -12,
      "y": 25,
      "z": -14,
      "name": "Rock_Volcanic"
    },
    {
      "x": -12,
      "y": 26,
      "z": -14,
      "name": "Rock_Volcanic"
    },
    {
      "x": -12,
      "y": 2,
      "z": -13,
      "name": "Rock_Volcanic"
    },
    {
      "x": -12,
      "y": 3,
      "z": -13,
      "name": "Rock_Volcanic"
    },
    {
      "x": -12,
      "y": 4,
      "z": -13,
      "name": "Rock_Volcanic"
    },
    {
      "x": -12,
      "y": 5,
      "z": -13,
      "name": "Rock_Volcanic"
    },
    {
      "x": -12,
      "y": 6,
      "z": -13,
      "name": "Rock_Volcanic"
    },
    {
      "x": -12,
      "y": 7,
      "z": -13,
      "name": "Rock_Volcanic"
    },
    {
      "x": -12,
      "y": 8,
      "z": -13,
      "name": "Rock_Volcanic"
    },
    {
      "x": -12,
      "y": 9,
      "z": -13,
      "name": "Rock_Volcanic"
    },
    {
      "x": -12,
      "y": 10,
      "z": -13,
      "name": "Rock_Volcanic"
    },
    {
      "x": -12,
      "y": 11,
      "z": -13,
      "name": "Rock_Volcanic"
    },
    {
      "x": -12,
      "y": 12,
      "z": -13,
      "name": "Rock_Volcanic"
    },
    {
      "x": -12,
      "y": 13,
      "z": -13,
      "name": "Rock_Volcanic"
    },
    {
      "x": -12,
      "y": 14,
      "z": -13,
      "name": "Rock_Volcanic"
    },
    {
      "x": -12,
      "y": 15,
      "z": -13,
      "name": "Rock_Volcanic"
    },
    {
      "x": -12,
      "y": 16,
      "z": -13,
      "name": "Rock_Volcanic"
    },
    {
      "x": -12,
      "y": 17,
      "z": -13,
      "name": "Rock_Volcanic"
    },
    {
      "x": -12,
      "y": 18,
      "z": -13,
      "name": "Rock_Volcanic"
    },
    {
      "x": -12,
      "y": 19,
      "z": -13,
      "name": "Rock_Volcanic"
    },
    {
      "x": -12,
      "y": 20,
      "z": -13,
      "name": "Rock_Volcanic"
    },
    {
      "x": -12,
      "y": 21,
      "z": -13,
      "name": "Rock_Volcanic"
    },
    {
      "x": -12,
      "y": 22,
      "z": -13,
      "name": "Rock_Volcanic"
    },
    {
      "x": -12,
      "y": 23,
      "z": -13,
      "name": "Rock_Volcanic"
    },
    {
      "x": -12,
      "y": 24,
      "z": -13,
      "name": "Rock_Volcanic"
    },
    {
      "x": -12,
      "y": 25,
      "z": -13,
      "name": "Rock_Volcanic"
    },
    {
      "x": -12,
      "y": 26,
      "z": -13,
      "name": "Rock_Volcanic"
    },
    {
      "x": -12,
      "y": 27,
      "z": -13,
      "name": "Rock_Volcanic"
    },
    {
      "x": -12,
      "y": 3,
      "z": -12,
      "name": "Rock_Volcanic"
    },
    {
      "x": -12,
      "y": 4,
      "z": -12,
      "name": "Rock_Volcanic"
    },
    {
      "x": -12,
      "y": 5,
      "z": -12,
      "name": "Rock_Volcanic"
    },
    {
      "x": -12,
      "y": 6,
      "z": -12,
      "name": "Rock_Volcanic"
    },
    {
      "x": -12,
      "y": 7,
      "z": -12,
      "name": "Rock_Volcanic"
    },
    {
      "x": -12,
      "y": 8,
      "z": -12,
      "name": "Rock_Volcanic"
    },
    {
      "x": -12,
      "y": 9,
      "z": -12,
      "name": "Rock_Volcanic"
    },
    {
      "x": -12,
      "y": 10,
      "z": -12,
      "name": "Rock_Volcanic"
    },
    {
      "x": -12,
      "y": 11,
      "z": -12,
      "name": "Rock_Volcanic"
    },
    {
      "x": -12,
      "y": 12,
      "z": -12,
      "name": "Rock_Volcanic"
    },
    {
      "x": -12,
      "y": 13,
      "z": -12,
      "name": "Rock_Volcanic"
    },
    {
      "x": -12,
      "y": 14,
      "z": -12,
      "name": "Rock_Volcanic"
    },
    {
      "x": -12,
      "y": 15,
      "z": -12,
      "name": "Rock_Volcanic"
    },
    {
      "x": -12,
      "y": 16,
      "z": -12,
      "name": "Rock_Volcanic"
    },
    {
      "x": -12,
      "y": 17,
      "z": -12,
      "name": "Rock_Volcanic"
    },
    {
      "x": -12,
      "y": 18,
      "z": -12,
      "name": "Rock_Volcanic"
    },
    {
      "x": -12,
      "y": 19,
      "z": -12,
      "name": "Rock_Volcanic"
    },
    {
      "x": -12,
      "y": 20,
      "z": -12,
      "name": "Rock_Volcanic"
    },
    {
      "x": -12,
      "y": 21,
      "z": -12,
      "name": "Rock_Volcanic"
    },
    {
      "x": -12,
      "y": 22,
      "z": -12,
      "name": "Rock_Volcanic"
    },
    {
      "x": -12,
      "y": 23,
      "z": -12,
      "name": "Rock_Volcanic"
    },
    {
      "x": -12,
      "y": 24,
      "z": -12,
      "name": "Rock_Volcanic"
    },
    {
      "x": -12,
      "y": 25,
      "z": -12,
      "name": "Rock_Volcanic"
    },
    {
      "x": -12,
      "y": 26,
      "z": -12,
      "name": "Rock_Volcanic"
    },
    {
      "x": -12,
      "y": 27,
      "z": -12,
      "name": "Rock_Volcanic"
    },
    {
      "x": -12,
      "y": 28,
      "z": -12,
      "name": "Rock_Volcanic"
    },
    {
      "x": -12,
      "y": 3,
      "z": -11,
      "name": "Rock_Volcanic"
    },
    {
      "x": -12,
      "y": 4,
      "z": -11,
      "name": "Rock_Volcanic"
    },
    {
      "x": -12,
      "y": 5,
      "z": -11,
      "name": "Rock_Volcanic"
    },
    {
      "x": -12,
      "y": 6,
      "z": -11,
      "name": "Rock_Volcanic"
    },
    {
      "x": -12,
      "y": 7,
      "z": -11,
      "name": "Rock_Volcanic"
    },
    {
      "x": -12,
      "y": 8,
      "z": -11,
      "name": "Rock_Volcanic"
    },
    {
      "x": -12,
      "y": 9,
      "z": -11,
      "name": "Rock_Volcanic"
    },
    {
      "x": -12,
      "y": 10,
      "z": -11,
      "name": "Rock_Volcanic"
    },
    {
      "x": -12,
      "y": 11,
      "z": -11,
      "name": "Rock_Volcanic"
    },
    {
      "x": -12,
      "y": 12,
      "z": -11,
      "name": "Rock_Volcanic"
    },
    {
      "x": -12,
      "y": 13,
      "z": -11,
      "name": "Rock_Volcanic"
    },
    {
      "x": -12,
      "y": 14,
      "z": -11,
      "name": "Rock_Volcanic"
    },
    {
      "x": -12,
      "y": 15,
      "z": -11,
      "name": "Rock_Volcanic"
    },
    {
      "x": -12,
      "y": 16,
      "z": -11,
      "name": "Rock_Volcanic"
    },
    {
      "x": -12,
      "y": 17,
      "z": -11,
      "name": "Rock_Volcanic"
    },
    {
      "x": -12,
      "y": 18,
      "z": -11,
      "name": "Rock_Volcanic"
    },
    {
      "x": -12,
      "y": 19,
      "z": -11,
      "name": "Rock_Volcanic"
    },
    {
      "x": -12,
      "y": 20,
      "z": -11,
      "name": "Rock_Volcanic"
    },
    {
      "x": -12,
      "y": 21,
      "z": -11,
      "name": "Rock_Volcanic"
    },
    {
      "x": -12,
      "y": 22,
      "z": -11,
      "name": "Rock_Volcanic"
    },
    {
      "x": -12,
      "y": 23,
      "z": -11,
      "name": "Rock_Volcanic"
    },
    {
      "x": -12,
      "y": 24,
      "z": -11,
      "name": "Rock_Volcanic"
    },
    {
      "x": -12,
      "y": 25,
      "z": -11,
      "name": "Rock_Volcanic"
    },
    {
      "x": -12,
      "y": 26,
      "z": -11,
      "name": "Rock_Volcanic"
    },
    {
      "x": -12,
      "y": 27,
      "z": -11,
      "name": "Rock_Volcanic"
    },
    {
      "x": -12,
      "y": 28,
      "z": -11,
      "name": "Rock_Volcanic"
    },
    {
      "x": -12,
      "y": 29,
      "z": -11,
      "name": "Rock_Volcanic"
    },
    {
      "x": -12,
      "y": 4,
      "z": -10,
      "name": "Rock_Volcanic"
    },
    {
      "x": -12,
      "y": 5,
      "z": -10,
      "name": "Rock_Volcanic"
    },
    {
      "x": -12,
      "y": 6,
      "z": -10,
      "name": "Rock_Volcanic"
    },
    {
      "x": -12,
      "y": 7,
      "z": -10,
      "name": "Rock_Volcanic"
    },
    {
      "x": -12,
      "y": 8,
      "z": -10,
      "name": "Rock_Volcanic"
    },
    {
      "x": -12,
      "y": 9,
      "z": -10,
      "name": "Rock_Volcanic"
    },
    {
      "x": -12,
      "y": 10,
      "z": -10,
      "name": "Rock_Volcanic"
    },
    {
      "x": -12,
      "y": 11,
      "z": -10,
      "name": "Rock_Volcanic"
    },
    {
      "x": -12,
      "y": 12,
      "z": -10,
      "name": "Rock_Volcanic"
    },
    {
      "x": -12,
      "y": 13,
      "z": -10,
      "name": "Rock_Volcanic"
    },
    {
      "x": -12,
      "y": 14,
      "z": -10,
      "name": "Rock_Volcanic"
    },
    {
      "x": -12,
      "y": 15,
      "z": -10,
      "name": "Rock_Volcanic"
    },
    {
      "x": -12,
      "y": 16,
      "z": -10,
      "name": "Rock_Volcanic"
    },
    {
      "x": -12,
      "y": 17,
      "z": -10,
      "name": "Rock_Volcanic"
    },
    {
      "x": -12,
      "y": 18,
      "z": -10,
      "name": "Rock_Volcanic"
    },
    {
      "x": -12,
      "y": 19,
      "z": -10,
      "name": "Rock_Volcanic"
    },
    {
      "x": -12,
      "y": 20,
      "z": -10,
      "name": "Rock_Volcanic"
    },
    {
      "x": -12,
      "y": 21,
      "z": -10,
      "name": "Rock_Volcanic"
    },
    {
      "x": -12,
      "y": 22,
      "z": -10,
      "name": "Rock_Volcanic"
    },
    {
      "x": -12,
      "y": 23,
      "z": -10,
      "name": "Rock_Volcanic"
    },
    {
      "x": -12,
      "y": 24,
      "z": -10,
      "name": "Rock_Volcanic"
    },
    {
      "x": -12,
      "y": 25,
      "z": -10,
      "name": "Rock_Volcanic"
    },
    {
      "x": -12,
      "y": 26,
      "z": -10,
      "name": "Rock_Volcanic"
    },
    {
      "x": -12,
      "y": 27,
      "z": -10,
      "name": "Rock_Volcanic"
    },
    {
      "x": -12,
      "y": 28,
      "z": -10,
      "name": "Rock_Volcanic"
    },
    {
      "x": -12,
      "y": 29,
      "z": -10,
      "name": "Rock_Volcanic"
    },
    {
      "x": -12,
      "y": 4,
      "z": -9,
      "name": "Rock_Volcanic"
    },
    {
      "x": -12,
      "y": 5,
      "z": -9,
      "name": "Rock_Volcanic"
    },
    {
      "x": -12,
      "y": 6,
      "z": -9,
      "name": "Rock_Volcanic"
    },
    {
      "x": -12,
      "y": 7,
      "z": -9,
      "name": "Rock_Volcanic"
    },
    {
      "x": -12,
      "y": 8,
      "z": -9,
      "name": "Rock_Volcanic"
    },
    {
      "x": -12,
      "y": 9,
      "z": -9,
      "name": "Rock_Volcanic"
    },
    {
      "x": -12,
      "y": 10,
      "z": -9,
      "name": "Rock_Volcanic"
    },
    {
      "x": -12,
      "y": 11,
      "z": -9,
      "name": "Rock_Volcanic"
    },
    {
      "x": -12,
      "y": 12,
      "z": -9,
      "name": "Rock_Volcanic"
    },
    {
      "x": -12,
      "y": 13,
      "z": -9,
      "name": "Rock_Volcanic"
    },
    {
      "x": -12,
      "y": 14,
      "z": -9,
      "name": "Rock_Volcanic"
    },
    {
      "x": -12,
      "y": 15,
      "z": -9,
      "name": "Rock_Volcanic"
    },
    {
      "x": -12,
      "y": 16,
      "z": -9,
      "name": "Rock_Volcanic"
    },
    {
      "x": -12,
      "y": 17,
      "z": -9,
