{
  "version": 8,
  "blockIdVersion": 10,
  "anchorX": 2,
  "anchorY": 2,
  "anchorZ": 1,
  "blocks": [
    {
      "x": -6,
      "y": -1,
      "z": -3,
      "name": "Wood_Poisoned_Branch_Long",
      "support": 15
    },
    {
      "x": -6,
      "y": 0,
      "z": -3,
      "name": "Wood_Poisoned_Branch_Corner",
      "support": 15,
      "rotation": 9
    },
    {
      "x": -5,
      "y": 0,
      "z": -3,
      "name": "Wood_Poisoned_Trunk_Full"
    },
    {
      "x": -5,
      "y": 1,
      "z": -3,
      "name": "Plant_Fruit_Poison"
    },
    {
      "x": -4,
      "y": 0,
      "z": -3,
      "name": "Wood_Poisoned_Trunk_Full"
    },
    {
      "x": -4,
      "y": -1,
      "z": 5,
      "name": "Wood_Poisoned_Branch_Long",
      "support": 15
    },
    {
      "x": -4,
      "y": 0,
      "z": 5,
      "name": "Wood_Poisoned_Branch_Corner",
      "support": 15,
      "rotation": 9
    },
    {
      "x": -3,
      "y": 0,
      "z": -4,
      "name": "Wood_Poisoned_Trunk_Full"
    },
    {
      "x": -3,
      "y": 0,
      "z": -3,
      "name": "Wood_Poisoned_Trunk_Full"
    },
    {
      "x": -3,
      "y": 0,
      "z": -2,
      "name": "Wood_Poisoned_Trunk_Full"
    },
    {
      "x": -3,
      "y": 0,
      "z": -1,
      "name": "Wood_Poisoned_Trunk_Full"
    },
    {
      "x": -3,
      "y": 0,
      "z": 4,
      "name": "Wood_Poisoned_Trunk_Full"
    },
    {
      "x": -3,
      "y": 0,
      "z": 5,
      "name": "Wood_Poisoned_Trunk_Full"
    },
    {
      "x": -3,
      "y": -1,
      "z": 6,
      "name": "Wood_Poisoned_Branch_Long",
      "support": 15
    },
    {
      "x": -3,
      "y": 0,
      "z": 6,
      "name": "Wood_Poisoned_Branch_Corner",
      "support": 15,
      "rotation": 10
    },
    {
      "x": -2,
      "y": -1,
      "z": -4,
      "name": "Wood_Poisoned_Branch_Long",
      "support": 15
    },
    {
      "x": -2,
      "y": 0,
      "z": -4,
      "name": "Wood_Poisoned_Branch_Corner",
      "support": 15,
      "rotation": 11
    },
    {
      "x": -2,
      "y": 0,
      "z": -1,
      "name": "Wood_Poisoned_Trunk_Full"
    },
    {
      "x": -2,
      "y": 1,
      "z": -1,
      "name": "Wood_Poisoned_Trunk_Full"
    },
    {
      "x": -2,
      "y": 1,
      "z": 0,
      "name": "Wood_Poisoned_Trunk_Full"
    },
    {
      "x": -2,
      "y": -1,
      "z": 1,
      "name": "Wood_Poisoned_Branch_Long",
      "support": 15
    },
    {
      "x": -2,
      "y": 0,
      "z": 1,
      "name": "Wood_Poisoned_Branch_Long",
      "support": 15
    },
    {
      "x": -2,
      "y": 1,
      "z": 1,
      "name": "Wood_Poisoned_Branch_Corner",
      "support": 15,
      "rotation": 10
    },
    {
      "x": -2,
      "y": 0,
      "z": 3,
      "name": "Wood_Poisoned_Trunk_Full"
    },
    {
      "x": -2,
      "y": 0,
      "z": 4,
      "name": "Wood_Poisoned_Trunk_Full"
    },
    {
      "x": -2,
      "y": -1,
      "z": 7,
      "name": "Wood_Poisoned_Branch_Long",
      "support": 15
    },
    {
      "x": -2,
      "y": 0,
      "z": 7,
      "name": "Wood_Poisoned_Branch_Corner",
      "support": 15,
      "rotation": 9
    },
    {
      "x": -1,
      "y": 1,
      "z": 0,
      "name": "Wood_Poisoned_Trunk_Full"
    },
    {
      "x": -1,
      "y": 0,
      "z": 1,
      "name": "Wood_Poisoned_Trunk_Full"
    },
    {
      "x": -1,
      "y": 1,
      "z": 1,
      "name": "Wood_Poisoned_Trunk_Full"
    },
    {
      "x": -1,
      "y": 0,
      "z": 2,
      "name": "Wood_Poisoned_Trunk_Full"
    },
    {
      "x": -1,
      "y": 0,
      "z": 3,
      "name": "Wood_Poisoned_Trunk_Full"
    },
    {
      "x": -1,
      "y": 0,
      "z": 7,
      "name": "Wood_Poisoned_Trunk_Full"
    },
    {
      "x": -1,
      "y": 1,
      "z": 7,
      "name": "Plant_Fruit_Poison"
    },
    {
      "x": 0,
      "y": 1,
      "z": 1,
      "name": "Wood_Poisoned_Trunk_Full"
    },
    {
      "x": 0,
      "y": 0,
      "z": 7,
      "name": "Wood_Poisoned_Trunk_Full"
    },
    {
      "x": 0,
      "y": 0,
      "z": 8,
      "name": "Wood_Poisoned_Trunk_Full"
    },
    {
      "x": 0,
      "y": 0,
      "z": 9,
      "name": "Wood_Poisoned_Trunk_Full"
    },
    {
      "x": 0,
      "y": -1,
      "z": 10,
      "name": "Wood_Poisoned_Branch_Long",
      "support": 15
    },
    {
      "x": 0,
      "y": 0,
      "z": 10,
      "name": "Wood_Poisoned_Branch_Corner",
      "support": 15,
      "rotation": 10
    },
    {
      "x": 1,
      "y": 1,
      "z": 0,
      "name": "Soil_Roots_Poisoned"
    },
    {
      "x": 1,
      "y": 2,
      "z": 0,
      "name": "Soil_Roots_Poisoned"
    },
    {
      "x": 1,
      "y": 1,
      "z": 1,
      "name": "Wood_Poisoned_Trunk_Full"
    },
    {
      "x": 1,
      "y": 2,
      "z": 1,
      "name": "Soil_Dirt_Poisoned"
    },
    {
      "x": 1,
      "y": 3,
      "z": 1,
      "name": "Soil_Dirt_Poisoned"
    },
    {
      "x": 1,
      "y": 1,
      "z": 2,
      "name": "Soil_Dirt_Poisoned"
    },
    {
      "x": 1,
      "y": 2,
      "z": 2,
      "name": "Soil_Dirt_Poisoned"
    },
    {
      "x": 1,
      "y": 3,
      "z": 2,
      "name": "Soil_Dirt_Poisoned"
    },
    {
      "x": 1,
      "y": 2,
      "z": 3,
      "name": "Soil_Dirt_Poisoned"
    },
    {
      "x": 1,
      "y": 0,
      "z": 6,
      "name": "Wood_Poisoned_Trunk_Full"
    },
    {
      "x": 1,
      "y": 0,
      "z": 7,
      "name": "Wood_Poisoned_Trunk_Full"
    },
    {
      "x": 2,
      "y": 1,
      "z": 0,
      "name": "Soil_Roots_Poisoned"
    },
    {
      "x": 2,
      "y": 2,
      "z": 0,
      "name": "Soil_Roots_Poisoned"
    },
    {
      "x": 2,
      "y": 3,
      "z": 0,
      "name": "Soil_Roots_Poisoned"
    },
    {
      "x": 2,
      "y": 1,
      "z": 1,
      "name": "Cloth_Block_Wool_Pink"
    },
    {
      "x": 2,
      "y": 2,
      "z": 1,
      "name": "Soil_Dirt_Poisoned"
    },
    {
      "x": 2,
      "y": 3,
      "z": 1,
      "name": "Soil_Dirt_Poisoned"
    },
    {
      "x": 2,
      "y": 1,
      "z": 2,
      "name": "Cloth_Block_Wool_Pink"
    },
    {
      "x": 2,
      "y": 2,
      "z": 2,
      "name": "Cloth_Block_Wool_Pink"
    },
    {
      "x": 2,
      "y": 3,
      "z": 2,
      "name": "Soil_Dirt_Poisoned"
    },
    {
      "x": 2,
      "y": 1,
      "z": 3,
      "name": "Soil_Dirt_Poisoned"
    },
    {
      "x": 2,
      "y": 2,
      "z": 3,
      "name": "Soil_Roots_Poisoned"
    },
    {
      "x": 2,
      "y": 3,
      "z": 3,
      "name": "Soil_Dirt_Poisoned"
    },
    {
      "x": 2,
      "y": 2,
      "z": 4,
      "name": "Wood_Poisoned_Trunk_Full",
      "support": 15
    },
    {
      "x": 2,
      "y": 3,
      "z": 4,
      "name": "Plant_Fruit_Poison"
    },
    {
      "x": 2,
      "y": 0,
      "z": 6,
      "name": "Wood_Poisoned_Trunk_Full"
    },
    {
      "x": 2,
      "y": 1,
      "z": 6,
      "name": "Wood_Poisoned_Trunk_Full"
    },
    {
      "x": 3,
      "y": 2,
      "z": 0,
      "name": "Soil_Roots_Poisoned"
    },
    {
      "x": 3,
      "y": 3,
      "z": 0,
      "name": "Soil_Roots_Poisoned"
    },
    {
      "x": 3,
      "y": 1,
      "z": 1,
      "name": "Soil_Roots_Poisoned"
    },
    {
      "x": 3,
      "y": 2,
      "z": 1,
      "name": "Wood_Poisoned_Trunk",
      "support": 15
    },
    {
      "x": 3,
      "y": 3,
      "z": 1,
      "name": "Soil_Roots_Poisoned"
    },
    {
      "x": 3,
      "y": 1,
      "z": 2,
      "name": "Soil_Roots_Poisoned"
    },
    {
      "x": 3,
      "y": 2,
      "z": 2,
      "name": "Wood_Poisoned_Trunk",
      "support": 15
    },
    {
      "x": 3,
      "y": 3,
      "z": 2,
      "name": "Soil_Roots_Poisoned"
    },
    {
      "x": 3,
      "y": 1,
      "z": 3,
      "name": "Soil_Roots_Poisoned"
    },
    {
      "x": 3,
      "y": 2,
      "z": 3,
      "name": "Wood_Poisoned_Trunk_Full",
      "support": 15
    },
    {
      "x": 3,
      "y": 3,
      "z": 3,
      "name": "Soil_Dirt_Poisoned"
    },
    {
      "x": 3,
      "y": 1,
      "z": 4,
      "name": "Wood_Poisoned_Trunk_Full"
    },
    {
      "x": 3,
      "y": 2,
      "z": 4,
      "name": "Wood_Poisoned_Trunk_Full",
      "support": 15
    },
    {
      "x": 3,
      "y": 1,
      "z": 5,
      "name": "Wood_Poisoned_Trunk_Full"
    },
    {
      "x": 3,
      "y": 1,
      "z": 6,
      "name": "Wood_Poisoned_Trunk_Full"
    },
    {
      "x": 3,
      "y": -1,
      "z": 7,
      "name": "Wood_Poisoned_Branch_Long",
      "support": 15
    },
    {
      "x": 3,
      "y": 0,
      "z": 7,
      "name": "Wood_Poisoned_Branch_Long",
      "support": 15
    },
    {
      "x": 3,
      "y": 1,
      "z": 7,
      "name": "Wood_Poisoned_Branch_Corner",
      "support": 15,
      "rotation": 10
    },
    {
      "x": 4,
      "y": 2,
      "z": 1,
      "name": "Wood_Poisoned_Trunk_Full"
    },
    {
      "x": 4,
      "y": 3,
      "z": 1,
      "name": "Wood_Poisoned_Trunk",
      "support": 15
    },
    {
      "x": 4,
      "y": 4,
      "z": 1,
      "name": "Wood_Poisoned_Trunk",
      "support": 15
    },
    {
      "x": 4,
      "y": 5,
      "z": 1,
      "name": "Wood_Poisoned_Trunk_Full",
      "support": 15
    },
    {
      "x": 4,
      "y": 6,
      "z": 1,
      "name": "Wood_Poisoned_Branch_Long",
      "support": 15
    },
    {
      "x": 4,
      "y": 1,
      "z": 2,
      "name": "Soil_Roots_Poisoned"
    },
    {
      "x": 4,
      "y": 2,
      "z": 2,
      "name": "Wood_Poisoned_Trunk",
      "support": 15
    },
    {
      "x": 4,
      "y": 3,
      "z": 2,
      "name": "Soil_Roots_Poisoned"
    },
    {
      "x": 4,
      "y": 5,
      "z": 2,
      "name": "Wood_Poisoned_Branch_Short",
      "support": 15
    },
    {
      "x": 4,
      "y": 1,
      "z": 3,
      "name": "Soil_Roots_Poisoned"
    },
    {
      "x": 4,
      "y": 2,
      "z": 3,
      "name": "Soil_Roots_Poisoned"
    },
    {
      "x": 4,
      "y": 1,
      "z": 5,
      "name": "Wood_Poisoned_Trunk_Full"
    },
    {
      "x": 5,
      "y": -1,
      "z": -1,
      "name": "Wood_Poisoned_Branch_Long",
      "support": 15
    },
    {
      "x": 5,
      "y": 0,
      "z": -1,
      "name": "Wood_Poisoned_Branch_Long",
      "support": 15
    },
    {
      "x": 5,
      "y": 1,
      "z": -1,
      "name": "Wood_Poisoned_Branch_Long",
      "support": 15
    },
    {
      "x": 5,
      "y": 2,
      "z": -1,
      "name": "Wood_Poisoned_Branch_Corner",
      "support": 15,
      "rotation": 8
    },
    {
      "x": 5,
      "y": 1,
      "z": 0,
      "name": "Wood_Poisoned_Trunk_Full"
    },
    {
      "x": 5,
      "y": 2,
      "z": 0,
      "name": "Wood_Poisoned_Trunk_Full"
    },
    {
      "x": 5,
      "y": 2,
      "z": 1,
      "name": "Wood_Poisoned_Trunk_Full"
    },
    {
      "x": 5,
      "y": 3,
      "z": 1,
      "name": "Plant_Fruit_Poison"
    },
    {
      "x": 5,
      "y": 4,
      "z": 1,
      "name": "Wood_Poisoned_Branch_Short",
      "support": 15,
      "rotation": 1
    },
    {
      "x": 5,
      "y": -1,
      "z": 2,
      "name": "Wood_Poisoned_Branch_Long",
      "support": 15
    },
    {
      "x": 5,
      "y": 0,
      "z": 2,
      "name": "Wood_Poisoned_Branch_Long",
      "support": 15
    },
    {
      "x": 5,
      "y": 1,
      "z": 2,
      "name": "Wood_Poisoned_Branch_Long",
      "support": 15
    },
    {
      "x": 5,
      "y": 2,
      "z": 2,
      "name": "Wood_Poisoned_Branch_Corner",
      "support": 15,
      "rotation": 10
    },
    {
      "x": 5,
      "y": 0,
      "z": 5,
      "name": "Wood_Poisoned_Trunk_Full"
    },
    {
      "x": 5,
      "y": 1,
      "z": 5,
      "name": "Wood_Poisoned_Trunk_Full"
    },
    {
      "x": 6,
      "y": 1,
      "z": 0,
      "name": "Wood_Poisoned_Trunk_Full"
    },
    {
      "x": 6,
      "y": 0,
      "z": 5,
      "name": "Wood_Poisoned_Trunk_Full"
    },
    {
      "x": 6,
      "y": -1,
      "z": 6,
      "name": "Wood_Poisoned_Trunk_Full"
    },
    {
      "x": 6,
      "y": 0,
      "z": 6,
      "name": "Wood_Poisoned_Trunk_Full"
    },
    {
      "x": 7,
      "y": -1,
      "z": -2,
      "name": "Wood_Poisoned_Branch_Long",
      "support": 15
    },
    {
      "x": 7,
      "y": 0,
      "z": -2,
      "name": "Wood_Poisoned_Branch_Long",
      "support": 15
    },
    {
      "x": 7,
      "y": 1,
      "z": -2,
      "name": "Wood_Poisoned_Branch_Corner",
      "support": 15,
      "rotation": 8
    },
    {
      "x": 7,
      "y": 1,
      "z": -1,
      "name": "Wood_Poisoned_Trunk_Full"
    },
    {
      "x": 7,
      "y": 1,
      "z": 0,
      "name": "Wood_Poisoned_Trunk_Full"
    },
    {
      "x": 7,
      "y": -1,
      "z": 6,
      "name": "Wood_Poisoned_Trunk_Full"
    },
    {
      "x": 8,
      "y": 1,
      "z": -1,
      "name": "Wood_Poisoned_Trunk_Full"
    },
    {
      "x": 8,
      "y": 2,
      "z": -1,
      "name": "Plant_Fruit_Poison"
    },
    {
      "x": 8,
      "y": -1,
      "z": 6,
      "name": "Wood_Poisoned_Trunk_Full"
    },
    {
      "x": 8,
      "y": -2,
      "z": 7,
      "name": "Wood_Poisoned_Branch_Long",
      "support": 15
    },
    {
      "x": 8,
      "y": -1,
      "z": 7,
      "name": "Wood_Poisoned_Branch_Corner",
      "support": 15,
      "rotation": 10
    },
    {
      "x": 9,
      "y": -1,
      "z": -1,
      "name": "Wood_Poisoned_Branch_Long",
      "support": 15
    },
    {
      "x": 9,
      "y": 0,
      "z": -1,
      "name": "Wood_Poisoned_Branch_Long",
      "support": 15
    },
    {
      "x": 9,
      "y": 1,
      "z": -1,
      "name": "Wood_Poisoned_Branch_Corner",
      "support": 15,
      "rotation": 11
    }
  ],
  "entities": [
    {
      "Components": {
        "Nameplate": {
          "Text": "Toad_Rhino"
        },
        "HiddenFromAdventurePlayer": {},
        "SpawnMarkerComponent": {
          "SpawnMarker": "Toad_Rhino",
          "RespawnTime": 0.0,
          "SpawnCount": 0,
          "PersistedFlock": {},
          "SpawnPosition": {
            "X": 0.0,
            "Y": 0.0,
            "Z": 0.0
          }
        },
        "Transform": {
          "Position": {
            "X": 2.566478729248047,
            "Y": 4.844818115234375,
            "Z": 2.687809467315674
          },
          "Rotation": {
            "Pitch": 0.0,
            "Yaw": -2.360037326812744,
            "Roll": 0.0
          }
        },
        "Intangible": {},
        "Model": {
          "Model": {
            "Id": "NPC_Spawn_Marker",
            "Scale": 1.0,
            "Static": false
          }
        },
        "UUID": {
          "UUID": {
            "$binary": "gy6/n1fKNn+ujJPEXg3tfw==",
            "$type": "04"
          }
        }
      }
    }
  ]
}