{
  "version": 8,
  "blockIdVersion": 8,
  "anchorX": 0,
  "anchorY": 0,
  "anchorZ": 0,
  "blocks": [
    {
      "x": -1,
      "y": -3,
      "z": -1,
      "name": "Rock_Shale"
    },
    {
      "x": -1,
      "y": -2,
      "z": -1,
      "name": "Rock_Shale"
    },
    {
      "x": -1,
      "y": -1,
      "z": -1,
      "name": "Rock_Shale"
    },
    {
      "x": -1,
      "y": 0,
      "z": -1,
      "name": "Rock_Shale"
    },
    {
      "x": -1,
      "y": 1,
      "z": -1,
      "name": "Rock_Shale_Brick_Smooth_Half"
    },
    {
      "x": -1,
      "y": 2,
      "z": -1,
      "name": "Rock_Shale_Brick_Smooth_Half",
      "rotation": 8
    },
    {
      "x": -1,
      "y": 3,
      "z": -1,
      "name": "Rock_Shale_Brick_Smooth_Half"
    },
    {
      "x": -1,
      "y": -3,
      "z": 0,
      "name": "Rock_Shale"
    },
    {
      "x": -1,
      "y": -2,
      "z": 0,
      "name": "Rock_Shale"
    },
    {
      "x": -1,
      "y": -1,
      "z": 0,
      "name": "Rock_Shale"
    },
    {
      "x": -1,
      "y": 0,
      "z": 0,
      "name": "Rock_Shale"
    },
    {
      "x": -1,
      "y": 1,
      "z": 0,
      "name": "Rock_Shale_Brick_Smooth_Half"
    },
    {
      "x": -1,
      "y": 2,
      "z": 0,
      "name": "Rock_Shale_Brick_Smooth_Half",
      "rotation": 8
    },
    {
      "x": -1,
      "y": 3,
      "z": 0,
      "name": "Rock_Shale_Brick_Smooth_Half"
    },
    {
      "x": -1,
      "y": -3,
      "z": 1,
      "name": "Rock_Shale"
    },
    {
      "x": -1,
      "y": -2,
      "z": 1,
      "name": "Rock_Shale"
    },
    {
      "x": -1,
      "y": -1,
      "z": 1,
      "name": "Rock_Shale"
    },
    {
      "x": -1,
      "y": 0,
      "z": 1,
      "name": "Rock_Shale"
    },
    {
      "x": -1,
      "y": 1,
      "z": 1,
      "name": "Rock_Shale_Brick_Smooth_Half"
    },
    {
      "x": -1,
      "y": 2,
      "z": 1,
      "name": "Rock_Shale_Brick_Smooth_Half",
      "rotation": 8
    },
    {
      "x": -1,
      "y": 3,
      "z": 1,
      "name": "Rock_Shale_Brick_Smooth_Half"
    },
    {
      "x": 0,
      "y": -3,
      "z": -1,
      "name": "Rock_Shale"
    },
    {
      "x": 0,
      "y": -2,
      "z": -1,
      "name": "Rock_Shale"
    },
    {
      "x": 0,
      "y": -1,
      "z": -1,
      "name": "Rock_Shale"
    },
    {
      "x": 0,
      "y": 0,
      "z": -1,
      "name": "Rock_Shale"
    },
    {
      "x": 0,
      "y": 1,
      "z": -1,
      "name": "Rock_Shale_Brick_Smooth_Half"
    },
    {
      "x": 0,
      "y": 2,
      "z": -1,
      "name": "Rock_Shale_Brick_Smooth_Half",
      "rotation": 8
    },
    {
      "x": 0,
      "y": 3,
      "z": -1,
      "name": "Rock_Shale_Brick_Smooth_Half"
    },
    {
      "x": 0,
      "y": -3,
      "z": 0,
      "name": "Rock_Shale"
    },
    {
      "x": 0,
      "y": -2,
      "z": 0,
      "name": "Rock_Shale"
    },
    {
      "x": 0,
      "y": -1,
      "z": 0,
      "name": "Rock_Shale"
    },
    {
      "x": 0,
      "y": 0,
      "z": 0,
      "name": "Rock_Shale"
    },
    {
      "x": 0,
      "y": 1,
      "z": 0,
      "name": "Rock_Shale_Brick_Smooth"
    },
    {
      "x": 0,
      "y": 2,
      "z": 0,
      "name": "Rock_Shale_Brick_Smooth"
    },
    {
      "x": 0,
      "y": 3,
      "z": 0,
      "name": "Furniture_Temple_Dark_Brazier"
    },
    {
      "x": 0,
      "y": -3,
      "z": 1,
      "name": "Rock_Shale"
    },
    {
      "x": 0,
      "y": -2,
      "z": 1,
      "name": "Rock_Shale"
    },
    {
      "x": 0,
      "y": -1,
      "z": 1,
      "name": "Rock_Shale"
    },
    {
      "x": 0,
      "y": 0,
      "z": 1,
      "name": "Rock_Shale"
    },
    {
      "x": 0,
      "y": 1,
      "z": 1,
      "name": "Rock_Shale_Brick_Smooth_Half"
    },
    {
      "x": 0,
      "y": 2,
      "z": 1,
      "name": "Rock_Shale_Brick_Smooth_Half",
      "rotation": 8
    },
    {
      "x": 0,
      "y": 3,
      "z": 1,
      "name": "Rock_Shale_Brick_Smooth_Half"
    },
    {
      "x": 1,
      "y": -2,
      "z": -1,
      "name": "Rock_Shale"
    },
    {
      "x": 1,
      "y": -1,
      "z": -1,
      "name": "Rock_Shale"
    },
    {
      "x": 1,
      "y": 0,
      "z": -1,
      "name": "Rock_Shale"
    },
    {
      "x": 1,
      "y": 1,
      "z": -1,
      "name": "Rock_Shale_Brick_Smooth_Half"
    },
    {
      "x": 1,
      "y": 2,
      "z": -1,
      "name": "Rock_Shale_Brick_Smooth_Half",
      "rotation": 8
    },
    {
      "x": 1,
      "y": 3,
      "z": -1,
      "name": "Rock_Shale_Brick_Smooth_Half"
    },
    {
      "x": 1,
      "y": -3,
      "z": 0,
      "name": "Rock_Shale"
    },
    {
      "x": 1,
      "y": -2,
      "z": 0,
      "name": "Rock_Shale"
    },
    {
      "x": 1,
      "y": -1,
      "z": 0,
      "name": "Rock_Shale"
    },
    {
      "x": 1,
      "y": 0,
      "z": 0,
      "name": "Rock_Shale"
    },
    {
      "x": 1,
      "y": 1,
      "z": 0,
      "name": "Rock_Shale_Brick_Smooth_Half"
    },
    {
      "x": 1,
      "y": 2,
      "z": 0,
      "name": "Rock_Shale_Brick_Smooth_Half",
      "rotation": 8
    },
    {
      "x": 1,
      "y": 3,
      "z": 0,
      "name": "Rock_Shale_Brick_Smooth_Half"
    },
    {
      "x": 1,
      "y": -2,
      "z": 1,
      "name": "Rock_Shale"
    },
    {
      "x": 1,
      "y": -1,
      "z": 1,
      "name": "Rock_Shale"
    },
    {
      "x": 1,
      "y": 0,
      "z": 1,
      "name": "Rock_Shale"
    },
    {
      "x": 1,
      "y": 1,
      "z": 1,
      "name": "Rock_Shale_Brick_Smooth_Half"
    },
    {
      "x": 1,
      "y": 2,
      "z": 1,
      "name": "Rock_Shale_Brick_Smooth_Half",
      "rotation": 8
    },
    {
      "x": 1,
      "y": 3,
      "z": 1,
      "name": "Rock_Shale_Brick_Smooth_Half"
    }
  ]
}