{
  "version": 8,
  "blockIdVersion": 8,
  "anchorX": -1,
  "anchorY": 6,
  "anchorZ": 1,
  "blocks": [
    {
      "x": -5,
      "y": 6,
      "z": -3,
      "name": "Wood_Oak_Trunk_Full",
      "rotation": 4
    },
    {
      "x": -5,
      "y": 6,
      "z": -2,
      "name": "Wood_Oak_Trunk_Full",
      "rotation": 4
    },
    {
      "x": -5,
      "y": 5,
      "z": 2,
      "name": "Soil_Dirt"
    },
    {
      "x": -5,
      "y": 6,
      "z": 2,
      "name": "Soil_Dirt"
    },
    {
      "x": -5,
      "y": 7,
      "z": 2,
      "name": "Soil_Clay_Brick_Half"
    },
    {
      "x": -5,
      "y": 6,
      "z": 4,
      "name": "Soil_Grass"
    },
    {
      "x": -5,
      "y": 7,
      "z": 4,
      "name": "Wood_Oak_Branch_Corner",
      "rotation": 3
    },
    {
      "x": -5,
      "y": 8,
      "z": 4,
      "name": "Plant_Flower_Bushy_Green",
      "components": {
        "Components": {
          "FarmingBlock": {}
        }
      }
    },
    {
      "x": -4,
      "y": 6,
      "z": -2,
      "name": "Soil_Dirt"
    },
    {
      "x": -4,
      "y": 7,
      "z": -2,
      "name": "Wood_Oak_Trunk_Full"
    },
    {
      "x": -4,
      "y": 5,
      "z": -1,
      "name": "Soil_Dirt"
    },
    {
      "x": -4,
      "y": 6,
      "z": -1,
      "name": "Soil_Dirt"
    },
    {
      "x": -4,
      "y": 7,
      "z": -1,
      "name": "Wood_Oak_Trunk_Full"
    },
    {
      "x": -4,
      "y": 4,
      "z": 0,
      "name": "Soil_Dirt"
    },
    {
      "x": -4,
      "y": 5,
      "z": 0,
      "name": "Soil_Grass"
    },
    {
      "x": -4,
      "y": 4,
      "z": 1,
      "name": "Soil_Dirt"
    },
    {
      "x": -4,
      "y": 5,
      "z": 1,
      "name": "Soil_Dirt"
    },
    {
      "x": -4,
      "y": 6,
      "z": 1,
      "name": "Soil_Dirt"
    },
    {
      "x": -4,
      "y": 7,
      "z": 1,
      "name": "Soil_Clay_Brick_Half"
    },
    {
      "x": -4,
      "y": 4,
      "z": 2,
      "name": "Soil_Dirt"
    },
    {
      "x": -4,
      "y": 5,
      "z": 2,
      "name": "Soil_Dirt"
    },
    {
      "x": -4,
      "y": 6,
      "z": 2,
      "name": "Soil_Dirt"
    },
    {
      "x": -4,
      "y": 7,
      "z": 2,
      "name": "Soil_Clay_Brick_Half"
    },
    {
      "x": -4,
      "y": 5,
      "z": 3,
      "name": "Soil_Dirt"
    },
    {
      "x": -4,
      "y": 6,
      "z": 3,
      "name": "Soil_Dirt"
    },
    {
      "x": -4,
      "y": 7,
      "z": 3,
      "name": "Soil_Clay_Brick"
    },
    {
      "x": -4,
      "y": 5,
      "z": 4,
      "name": "Wood_Oak_Trunk_Full"
    },
    {
      "x": -4,
      "y": 6,
      "z": 4,
      "name": "Wood_Oak_Trunk_Full"
    },
    {
      "x": -4,
      "y": 7,
      "z": 4,
      "name": "Wood_Oak_Trunk_Full"
    },
    {
      "x": -3,
      "y": 5,
      "z": -2,
      "name": "Soil_Dirt"
    },
    {
      "x": -3,
      "y": 6,
      "z": -2,
      "name": "Soil_Dirt"
    },
    {
      "x": -3,
      "y": 7,
      "z": -2,
      "name": "Wood_Oak_Trunk_Full"
    },
    {
      "x": -3,
      "y": 4,
      "z": -1,
      "name": "Soil_Dirt"
    },
    {
      "x": -3,
      "y": 5,
      "z": -1,
      "name": "Soil_Dirt"
    },
    {
      "x": -3,
      "y": 6,
      "z": -1,
      "name": "Soil_Dirt"
    },
    {
      "x": -3,
      "y": 7,
      "z": -1,
      "name": "Wood_Oak_Trunk"
    },
    {
      "x": -3,
      "y": 8,
      "z": -1,
      "name": "Wood_Oak_Trunk_Full",
      "support": 15
    },
    {
      "x": -3,
      "y": 13,
      "z": -1,
      "name": "Wood_Oak_Trunk_Full",
      "support": 15
    },
    {
      "x": -3,
      "y": 14,
      "z": -1,
      "name": "Wood_Oak_Trunk_Full"
    },
    {
      "x": -3,
      "y": 3,
      "z": 0,
      "name": "Soil_Dirt"
    },
    {
      "x": -3,
      "y": 4,
      "z": 0,
      "name": "Soil_Dirt"
    },
    {
      "x": -3,
      "y": 5,
      "z": 0,
      "name": "Soil_Dirt"
    },
    {
      "x": -3,
      "y": 6,
      "z": 0,
      "name": "Soil_Dirt"
    },
    {
      "x": -3,
      "y": 7,
      "z": 0,
      "name": "Wood_Oak_Trunk"
    },
    {
      "x": -3,
      "y": 8,
      "z": 0,
      "name": "Wood_Oak_Trunk"
    },
    {
      "x": -3,
      "y": 9,
      "z": 0,
      "name": "Wood_Oak_Trunk_Full",
      "support": 15
    },
    {
      "x": -3,
      "y": 12,
      "z": 0,
      "name": "Wood_Oak_Trunk_Full",
      "support": 15
    },
    {
      "x": -3,
      "y": 13,
      "z": 0,
      "name": "Wood_Oak_Trunk"
    },
    {
      "x": -3,
      "y": 14,
      "z": 0,
      "name": "Wood_Oak_Trunk_Full"
    },
    {
      "x": -3,
      "y": 15,
      "z": 0,
      "name": "Wood_Oak_Branch_Long",
      "support": 15
    },
    {
      "x": -3,
      "y": 16,
      "z": 0,
      "name": "Wood_Oak_Branch_Long",
      "support": 15
    },
    {
      "x": -3,
      "y": 17,
      "z": 0,
      "name": "Wood_Oak_Branch_Long",
      "support": 15
    },
    {
      "x": -3,
      "y": 18,
      "z": 0,
      "name": "Wood_Oak_Branch_Corner",
      "rotation": 9
    },
    {
      "x": -3,
      "y": 3,
      "z": 1,
      "name": "Soil_Dirt"
    },
    {
      "x": -3,
      "y": 4,
      "z": 1,
      "name": "Soil_Dirt"
    },
    {
      "x": -3,
      "y": 5,
      "z": 1,
      "name": "Soil_Dirt"
    },
    {
      "x": -3,
      "y": 6,
      "z": 1,
      "name": "Soil_Dirt"
    },
    {
      "x": -3,
      "y": 7,
      "z": 1,
      "name": "Wood_Oak_Trunk_Full",
      "support": 15
    },
    {
      "x": -3,
      "y": 10,
      "z": 1,
      "name": "Wood_Oak_Trunk_Full",
      "support": 15
    },
    {
      "x": -3,
      "y": 11,
      "z": 1,
      "name": "Wood_Oak_Trunk"
    },
    {
      "x": -3,
      "y": 12,
      "z": 1,
      "name": "Wood_Oak_Trunk"
    },
    {
      "x": -3,
      "y": 13,
      "z": 1,
      "name": "Wood_Oak_Trunk_Full"
    },
    {
      "x": -3,
      "y": 14,
      "z": 1,
      "name": "Wood_Oak_Branch_Long"
    },
    {
      "x": -3,
      "y": 15,
      "z": 1,
      "name": "Plant_Flower_Bushy_Green",
      "components": {
        "Components": {
          "FarmingBlock": {}
        }
      }
    },
    {
      "x": -3,
      "y": 3,
      "z": 2,
      "name": "Soil_Dirt"
    },
    {
      "x": -3,
      "y": 4,
      "z": 2,
      "name": "Soil_Dirt"
    },
    {
      "x": -3,
      "y": 5,
      "z": 2,
      "name": "Soil_Dirt"
    },
    {
      "x": -3,
      "y": 6,
      "z": 2,
      "name": "Soil_Dirt"
    },
    {
      "x": -3,
      "y": 7,
      "z": 2,
      "name": "Soil_Clay_Brick"
    },
    {
      "x": -3,
      "y": 11,
      "z": 2,
      "name": "Wood_Oak_Trunk_Full",
      "support": 15
    },
    {
      "x": -3,
      "y": 12,
      "z": 2,
      "name": "Wood_Oak_Trunk"
    },
    {
      "x": -3,
      "y": 13,
      "z": 2,
      "name": "Wood_Oak_Trunk_Full",
      "support": 15
    },
    {
      "x": -3,
      "y": 4,
      "z": 3,
      "name": "Soil_Dirt"
    },
    {
      "x": -3,
      "y": 5,
      "z": 3,
      "name": "Soil_Dirt"
    },
    {
      "x": -3,
      "y": 6,
      "z": 3,
      "name": "Soil_Dirt"
    },
    {
      "x": -3,
      "y": 7,
      "z": 3,
      "name": "Wood_Oak_Trunk_Full"
    },
    {
      "x": -3,
      "y": 5,
      "z": 4,
      "name": "Soil_Dirt"
    },
    {
      "x": -3,
      "y": 6,
      "z": 4,
      "name": "Soil_Dirt"
    },
    {
      "x": -3,
      "y": 7,
      "z": 4,
      "name": "Wood_Oak_Trunk_Full"
    },
    {
      "x": -2,
      "y": 12,
      "z": -3,
      "name": "Soil_Clay_Brick_Half",
      "rotation": 8
    },
    {
      "x": -2,
      "y": 13,
      "z": -3,
      "name": "Soil_Clay_Brick"
    },
    {
      "x": -2,
      "y": 4,
      "z": -2,
      "name": "Soil_Dirt"
    },
    {
      "x": -2,
      "y": 5,
      "z": -2,
      "name": "Soil_Dirt"
    },
    {
      "x": -2,
      "y": 6,
      "z": -2,
      "name": "Soil_Dirt"
    },
    {
      "x": -2,
      "y": 7,
      "z": -2,
      "name": "Wood_Oak_Trunk_Full",
      "support": 15
    },
    {
      "x": -2,
      "y": 11,
      "z": -2,
      "name": "Wood_Oak_Trunk_Full",
      "support": 15
    },
    {
      "x": -2,
      "y": 12,
      "z": -2,
      "name": "Wood_Oak_Trunk"
    },
    {
      "x": -2,
      "y": 13,
      "z": -2,
      "name": "Wood_Oak_Trunk"
    },
    {
      "x": -2,
      "y": 14,
      "z": -2,
      "name": "Plant_Moss_Rug_Green"
    },
    {
      "x": -2,
      "y": 3,
      "z": -1,
      "name": "Soil_Dirt"
    },
    {
      "x": -2,
      "y": 4,
      "z": -1,
      "name": "Soil_Dirt"
    },
    {
      "x": -2,
      "y": 5,
      "z": -1,
      "name": "Soil_Dirt"
    },
    {
      "x": -2,
      "y": 6,
      "z": -1,
      "name": "Soil_Dirt"
    },
    {
      "x": -2,
      "y": 7,
      "z": -1,
      "name": "Wood_Oak_Trunk"
    },
    {
      "x": -2,
      "y": 8,
      "z": -1,
      "name": "Wood_Oak_Trunk"
    },
    {
      "x": -2,
      "y": 9,
      "z": -1,
      "name": "Wood_Oak_Trunk"
    },
    {
      "x": -2,
      "y": 10,
      "z": -1,
      "name": "Wood_Oak_Trunk"
    },
    {
      "x": -2,
      "y": 11,
      "z": -1,
      "name": "Wood_Oak_Trunk"
    },
    {
      "x": -2,
      "y": 12,
      "z": -1,
      "name": "Wood_Oak_Trunk"
    },
    {
      "x": -2,
      "y": 13,
      "z": -1,
      "name": "Wood_Oak_Trunk"
    },
    {
      "x": -2,
      "y": 14,
      "z": -1,
      "name": "Plant_Moss_Rug_Green"
    },
    {
      "x": -2,
      "y": 3,
      "z": 0,
      "name": "Soil_Dirt"
    },
    {
      "x": -2,
      "y": 4,
      "z": 0,
      "name": "Soil_Dirt"
    },
    {
      "x": -2,
      "y": 5,
      "z": 0,
      "name": "Soil_Dirt"
    },
    {
      "x": -2,
      "y": 6,
      "z": 0,
      "name": "Soil_Dirt"
    },
    {
      "x": -2,
      "y": 7,
      "z": 0,
      "name": "Wood_Oak_Trunk"
    },
    {
      "x": -2,
      "y": 8,
      "z": 0,
      "name": "Wood_Oak_Trunk"
    },
    {
      "x": -2,
      "y": 9,
      "z": 0,
      "name": "Wood_Oak_Trunk"
    },
    {
      "x": -2,
      "y": 10,
      "z": 0,
      "name": "Wood_Oak_Trunk"
    },
    {
      "x": -2,
      "y": 11,
      "z": 0,
      "name": "Wood_Oak_Trunk"
    },
    {
      "x": -2,
      "y": 12,
      "z": 0,
      "name": "Wood_Oak_Trunk"
    },
    {
      "x": -2,
      "y": 13,
      "z": 0,
      "name": "Soil_Needles"
    },
    {
      "x": -2,
      "y": 17,
      "z": 0,
      "name": "Furniture_Kweebec_Lantern"
    },
    {
      "x": -2,
      "y": 18,
      "z": 0,
      "name": "Wood_Oak_Branch_Corner",
      "rotation": 11
    },
    {
      "x": -2,
      "y": 3,
      "z": 1,
      "name": "Soil_Dirt"
    },
    {
      "x": -2,
      "y": 4,
      "z": 1,
      "name": "Soil_Dirt"
    },
    {
      "x": -2,
      "y": 5,
      "z": 1,
      "name": "Soil_Dirt"
    },
    {
      "x": -2,
      "y": 6,
      "z": 1,
      "name": "Soil_Dirt"
    },
    {
      "x": -2,
      "y": 7,
      "z": 1,
      "name": "Wood_Oak_Trunk"
    },
    {
      "x": -2,
      "y": 8,
      "z": 1,
      "name": "Wood_Oak_Trunk_Full",
      "support": 15
    },
    {
      "x": -2,
      "y": 11,
      "z": 1,
      "name": "Wood_Oak_Trunk_Full",
      "support": 15
    },
    {
      "x": -2,
      "y": 12,
      "z": 1,
      "name": "Wood_Oak_Trunk"
    },
    {
      "x": -2,
      "y": 13,
      "z": 1,
      "name": "Soil_Needles"
    },
    {
      "x": -2,
      "y": 3,
      "z": 2,
      "name": "Soil_Dirt"
    },
    {
      "x": -2,
      "y": 4,
      "z": 2,
      "name": "Soil_Dirt"
    },
    {
      "x": -2,
      "y": 5,
      "z": 2,
      "name": "Soil_Dirt"
    },
    {
      "x": -2,
      "y": 6,
      "z": 2,
      "name": "Soil_Dirt"
    },
    {
      "x": -2,
      "y": 7,
      "z": 2,
      "name": "Wood_Oak_Trunk"
    },
    {
      "x": -2,
      "y": 8,
      "z": 2,
      "name": "Soil_Clay_Brick_Half"
    },
    {
      "x": -2,
      "y": 11,
      "z": 2,
      "name": "Wood_Oak_Branch_Corner",
      "rotation": 1
    },
    {
      "x": -2,
      "y": 12,
      "z": 2,
      "name": "Wood_Oak_Trunk_Full",
      "support": 15
    },
    {
      "x": -2,
      "y": 13,
      "z": 2,
      "name": "Soil_Needles"
    },
    {
      "x": -2,
      "y": 3,
      "z": 3,
      "name": "Soil_Dirt"
    },
    {
      "x": -2,
      "y": 4,
      "z": 3,
      "name": "Soil_Dirt"
    },
    {
      "x": -2,
      "y": 5,
      "z": 3,
      "name": "Soil_Dirt"
    },
    {
      "x": -2,
      "y": 6,
      "z": 3,
      "name": "Soil_Dirt"
    },
    {
      "x": -2,
      "y": 7,
      "z": 3,
      "name": "Wood_Oak_Trunk_Full"
    },
    {
      "x": -2,
      "y": 8,
      "z": 3,
      "name": "Soil_Clay_Brick_Half"
    },
    {
      "x": -2,
      "y": 13,
      "z": 3,
      "name": "Wood_Oak_Trunk_Full",
      "support": 15
    },
    {
      "x": -2,
      "y": 4,
      "z": 4,
      "name": "Soil_Dirt"
    },
    {
      "x": -2,
      "y": 5,
      "z": 4,
      "name": "Soil_Dirt"
    },
    {
      "x": -2,
      "y": 6,
      "z": 4,
      "name": "Soil_Dirt"
    },
    {
      "x": -2,
      "y": 7,
      "z": 4,
      "name": "Soil_Clay_Brick"
    },
    {
      "x": -2,
      "y": 8,
      "z": 4,
      "name": "Soil_Clay_Brick_Half"
    },
    {
      "x": -1,
      "y": 12,
      "z": -4,
      "name": "Soil_Clay_Brick_Half",
      "rotation": 8
    },
    {
      "x": -1,
      "y": 13,
      "z": -4,
      "name": "Soil_Clay_Brick"
    },
    {
      "x": -1,
      "y": 6,
      "z": -3,
      "name": "Wood_Oak_Trunk_Full"
    },
    {
      "x": -1,
      "y": 7,
      "z": -3,
      "name": "Wood_Oak_Trunk_Full"
    },
    {
      "x": -1,
      "y": 12,
      "z": -3,
      "name": "Soil_Clay_Brick"
    },
    {
      "x": -1,
      "y": 13,
      "z": -3,
      "name": "Soil_Clay_Brick"
    },
    {
      "x": -1,
      "y": 4,
      "z": -2,
      "name": "Soil_Dirt"
    },
    {
      "x": -1,
      "y": 5,
      "z": -2,
      "name": "Soil_Dirt"
    },
    {
      "x": -1,
      "y": 6,
      "z": -2,
      "name": "Soil_Dirt"
    },
    {
      "x": -1,
      "y": 7,
      "z": -2,
      "name": "Wood_Oak_Trunk"
    },
    {
      "x": -1,
      "y": 8,
      "z": -2,
      "name": "Wood_Oak_Trunk_Full",
      "support": 15
    },
    {
      "x": -1,
      "y": 10,
      "z": -2,
      "name": "Wood_Oak_Trunk_Full",
      "support": 15
    },
    {
      "x": -1,
      "y": 11,
      "z": -2,
      "name": "Wood_Oak_Trunk"
    },
    {
      "x": -1,
      "y": 12,
      "z": -2,
      "name": "Wood_Oak_Trunk"
    },
    {
      "x": -1,
      "y": 13,
      "z": -2,
      "name": "Wood_Oak_Trunk"
    },
    {
      "x": -1,
      "y": 3,
      "z": -1,
      "name": "Soil_Dirt"
    },
    {
      "x": -1,
      "y": 4,
      "z": -1,
      "name": "Soil_Dirt"
    },
    {
      "x": -1,
      "y": 5,
      "z": -1,
      "name": "Soil_Dirt"
    },
    {
      "x": -1,
      "y": 6,
      "z": -1,
      "name": "Soil_Dirt"
    },
    {
      "x": -1,
      "y": 7,
      "z": -1,
      "name": "Wood_Oak_Trunk"
    },
    {
      "x": -1,
      "y": 8,
      "z": -1,
      "name": "Wood_Oak_Trunk"
    },
    {
      "x": -1,
      "y": 9,
      "z": -1,
      "name": "Wood_Oak_Trunk"
    },
    {
      "x": -1,
      "y": 10,
      "z": -1,
      "name": "Wood_Oak_Trunk"
    },
    {
      "x": -1,
      "y": 11,
      "z": -1,
      "name": "Wood_Oak_Trunk"
    },
    {
      "x": -1,
      "y": 12,
      "z": -1,
      "name": "Wood_Oak_Trunk"
    },
    {
      "x": -1,
      "y": 13,
      "z": -1,
      "name": "Soil_Needles"
    },
    {
      "x": -1,
      "y": 3,
      "z": 0,
      "name": "Soil_Dirt"
    },
    {
      "x": -1,
      "y": 4,
      "z": 0,
      "name": "Soil_Dirt"
    },
    {
      "x": -1,
      "y": 5,
      "z": 0,
      "name": "Soil_Dirt"
    },
    {
      "x": -1,
      "y": 6,
      "z": 0,
      "name": "Soil_Dirt"
    },
    {
      "x": -1,
      "y": 7,
      "z": 0,
      "name": "Wood_Oak_Trunk"
    },
    {
      "x": -1,
      "y": 8,
      "z": 0,
      "name": "Wood_Oak_Trunk"
    },
    {
      "x": -1,
      "y": 9,
      "z": 0,
      "name": "Wood_Oak_Trunk"
    },
    {
      "x": -1,
      "y": 10,
      "z": 0,
      "name": "Wood_Oak_Trunk"
    },
    {
      "x": -1,
      "y": 11,
      "z": 0,
      "name": "Wood_Oak_Trunk"
    },
    {
      "x": -1,
      "y": 12,
      "z": 0,
      "name": "Wood_Oak_Trunk"
    },
    {
      "x": -1,
      "y": 13,
      "z": 0,
      "name": "Soil_Needles"
    },
    {
      "x": -1,
      "y": 3,
      "z": 1,
      "name": "Soil_Dirt"
    },
    {
      "x": -1,
      "y": 4,
      "z": 1,
      "name": "Soil_Dirt"
    },
    {
      "x": -1,
      "y": 5,
      "z": 1,
      "name": "Soil_Dirt"
    },
    {
      "x": -1,
      "y": 6,
      "z": 1,
      "name": "Soil_Dirt"
    },
    {
      "x": -1,
      "y": 7,
      "z": 1,
      "name": "Wood_Oak_Trunk"
    },
    {
      "x": -1,
      "y": 8,
      "z": 1,
      "name": "Wood_Oak_Trunk"
    },
    {
      "x": -1,
      "y": 9,
      "z": 1,
      "name": "Wood_Oak_Trunk_Full",
      "support": 15
    },
    {
      "x": -1,
      "y": 12,
      "z": 1,
      "name": "Wood_Oak_Trunk_Full",
      "support": 15
    },
    {
      "x": -1,
      "y": 13,
      "z": 1,
      "name": "Soil_Needles"
    },
    {
      "x": -1,
      "y": 3,
      "z": 2,
      "name": "Soil_Dirt"
    },
    {
      "x": -1,
      "y": 4,
      "z": 2,
      "name": "Soil_Dirt"
    },
    {
      "x": -1,
      "y": 5,
      "z": 2,
      "name": "Soil_Dirt"
    },
    {
      "x": -1,
      "y": 6,
      "z": 2,
      "name": "Soil_Dirt"
    },
    {
      "x": -1,
      "y": 7,
      "z": 2,
      "name": "Wood_Oak_Trunk"
    },
    {
      "x": -1,
      "y": 8,
      "z": 2,
      "name": "Soil_Clay_Brick"
    },
    {
      "x": -1,
      "y": 13,
      "z": 2,
      "name": "Wood_Oak_Trunk_Full",
      "support": 15
    },
    {
      "x": -1,
      "y": 14,
      "z": 2,
      "name": "Plant_Moss_Rug_Green"
    },
    {
      "x": -1,
      "y": 3,
      "z": 3,
      "name": "Soil_Dirt"
    },
    {
      "x": -1,
      "y": 4,
      "z": 3,
      "name": "Soil_Dirt"
    },
    {
      "x": -1,
      "y": 5,
      "z": 3,
      "name": "Soil_Dirt"
    },
    {
      "x": -1,
      "y": 6,
      "z": 3,
      "name": "Soil_Dirt"
    },
    {
      "x": -1,
      "y": 7,
      "z": 3,
      "name": "Soil_Clay_Brick"
    },
    {
      "x": -1,
      "y": 8,
      "z": 3,
      "name": "Soil_Clay_Brick"
    },
    {
      "x": -1,
      "y": 13,
      "z": 3,
      "name": "Wood_Oak_Trunk_Full",
      "support": 15
    },
    {
      "x": -1,
      "y": 14,
      "z": 3,
      "name": "Plant_Moss_Rug_Green"
    },
    {
      "x": -1,
      "y": 4,
      "z": 4,
      "name": "Soil_Dirt"
    },
    {
      "x": -1,
      "y": 5,
      "z": 4,
      "name": "Soil_Dirt"
    },
    {
      "x": -1,
      "y": 6,
      "z": 4,
      "name": "Soil_Dirt"
    },
    {
      "x": -1,
      "y": 7,
      "z": 4,
      "name": "Soil_Clay_Brick"
    },
    {
      "x": -1,
      "y": 8,
      "z": 4,
      "name": "Soil_Clay_Brick_Half"
    },
    {
      "x": 0,
      "y": 6,
      "z": -4,
      "name": "Wood_Oak_Trunk_Full"
    },
    {
      "x": 0,
      "y": 12,
      "z": -4,
      "name": "Soil_Clay_Brick"
    },
    {
      "x": 0,
      "y": 13,
      "z": -4,
      "name": "Soil_Clay_Brick_Half"
    },
    {
      "x": 0,
      "y": 6,
      "z": -3,
      "name": "Wood_Oak_Trunk_Full"
    },
    {
      "x": 0,
      "y": 12,
      "z": -3,
      "name": "Soil_Clay_Brick"
    },
    {
      "x": 0,
      "y": 13,
      "z": -3,
      "name": "Soil_Clay_Brick_Half"
    },
    {
      "x": 0,
      "y": 5,
      "z": -2,
      "name": "Soil_Dirt"
    },
    {
      "x": 0,
      "y": 6,
      "z": -2,
      "name": "Soil_Dirt"
    },
    {
      "x": 0,
      "y": 7,
      "z": -2,
      "name": "Wood_Oak_Trunk"
    },
    {
      "x": 0,
      "y": 8,
      "z": -2,
      "name": "Wood_Oak_Trunk"
    },
    {
      "x": 0,
      "y": 9,
      "z": -2,
      "name": "Wood_Oak_Trunk"
    },
    {
      "x": 0,
      "y": 10,
      "z": -2,
      "name": "Wood_Oak_Trunk"
    },
    {
      "x": 0,
      "y": 11,
      "z": -2,
      "name": "Wood_Oak_Trunk"
    },
    {
      "x": 0,
      "y": 12,
      "z": -2,
      "name": "Wood_Oak_Trunk"
    },
    {
      "x": 0,
      "y": 13,
      "z": -2,
      "name": "Wood_Oak_Trunk"
    },
    {
      "x": 0,
      "y": 5,
      "z": -1,
      "name": "Soil_Dirt"
    },
    {
      "x": 0,
      "y": 6,
      "z": -1,
      "name": "Soil_Dirt"
    },
    {
      "x": 0,
      "y": 7,
      "z": -1,
      "name": "Wood_Oak_Trunk"
    },
    {
      "x": 0,
      "y": 8,
      "z": -1,
      "name": "Wood_Oak_Trunk"
    },
    {
      "x": 0,
      "y": 9,
      "z": -1,
      "name": "Wood_Oak_Trunk"
    },
    {
      "x": 0,
      "y": 10,
      "z": -1,
      "name": "Wood_Oak_Trunk"
    },
    {
      "x": 0,
      "y": 11,
      "z": -1,
      "name": "Wood_Oak_Trunk"
    },
    {
      "x": 0,
      "y": 12,
      "z": -1,
      "name": "Wood_Oak_Trunk"
    },
    {
      "x": 0,
      "y": 13,
      "z": -1,
      "name": "Wood_Oak_Trunk_Full"
    },
    {
      "x": 0,
      "y": 3,
      "z": 0,
      "name": "Soil_Dirt"
    },
    {
      "x": 0,
      "y": 4,
      "z": 0,
      "name": "Soil_Dirt"
    },
    {
      "x": 0,
      "y": 5,
      "z": 0,
      "name": "Soil_Dirt"
    },
    {
      "x": 0,
      "y": 6,
      "z": 0,
      "name": "Soil_Dirt"
    },
    {
      "x": 0,
      "y": 7,
      "z": 0,
      "name": "Wood_Oak_Trunk"
    },
    {
      "x": 0,
      "y": 8,
      "z": 0,
      "name": "Wood_Oak_Trunk"
    },
    {
      "x": 0,
      "y": 9,
      "z": 0,
      "name": "Wood_Oak_Trunk"
    },
    {
      "x": 0,
      "y": 10,
      "z": 0,
      "name": "Wood_Oak_Trunk"
    },
    {
      "x": 0,
      "y": 11,
      "z": 0,
      "name": "Wood_Oak_Trunk"
    },
    {
      "x": 0,
      "y": 12,
      "z": 0,
      "name": "Wood_Oak_Trunk"
    },
    {
      "x": 0,
      "y": 13,
      "z": 0,
      "name": "Soil_Needles"
    },
    {
      "x": 0,
      "y": 3,
      "z": 1,
      "name": "Soil_Dirt"
    },
    {
      "x": 0,
      "y": 4,
      "z": 1,
      "name": "Soil_Dirt"
    },
    {
      "x": 0,
      "y": 5,
      "z": 1,
      "name": "Soil_Dirt"
    },
    {
      "x": 0,
      "y": 6,
      "z": 1,
      "name": "Soil_Dirt"
    },
    {
      "x": 0,
      "y": 7,
      "z": 1,
      "name": "Wood_Oak_Trunk"
    },
    {
      "x": 0,
      "y": 8,
      "z": 1,
      "name": "Wood_Oak_Trunk"
    },
    {
      "x": 0,
      "y": 9,
      "z": 1,
      "name": "Wood_Oak_Trunk"
    },
    {
      "x": 0,
      "y": 10,
      "z": 1,
      "name": "Wood_Oak_Trunk"
    },
    {
      "x": 0,
      "y": 11,
      "z": 1,
      "name": "Wood_Oak_Trunk"
    },
    {
      "x": 0,
      "y": 12,
      "z": 1,
      "name": "Wood_Oak_Trunk"
    },
    {
      "x": 0,
      "y": 13,
      "z": 1,
      "name": "Soil_Needles"
    },
    {
      "x": 0,
      "y": 3,
      "z": 2,
      "name": "Soil_Dirt"
    },
    {
      "x": 0,
      "y": 4,
      "z": 2,
      "name": "Soil_Dirt"
    },
    {
      "x": 0,
      "y": 5,
      "z": 2,
      "name": "Soil_Dirt"
    },
    {
      "x": 0,
      "y": 6,
      "z": 2,
      "name": "Soil_Dirt"
    },
    {
      "x": 0,
      "y": 7,
      "z": 2,
      "name": "Wood_Oak_Trunk"
    },
    {
      "x": 0,
      "y": 8,
      "z": 2,
      "name": "Wood_Oak_Trunk"
    },
    {
      "x": 0,
      "y": 9,
      "z": 2,
      "name": "Soil_Clay_Brick_Half"
    },
    {
      "x": 0,
      "y": 13,
      "z": 2,
      "name": "Wood_Oak_Trunk_Full",
      "support": 15
    },
    {
      "x": 0,
      "y": 14,
      "z": 2,
      "name": "Plant_Moss_Rug_Green"
    },
    {
      "x": 0,
      "y": 4,
      "z": 3,
      "name": "Soil_Dirt"
    },
    {
      "x": 0,
      "y": 5,
      "z": 3,
      "name": "Soil_Dirt"
    },
    {
      "x": 0,
      "y": 6,
      "z": 3,
      "name": "Soil_Dirt"
    },
    {
      "x": 0,
      "y": 7,
      "z": 3,
      "name": "Soil_Clay_Brick"
    },
    {
      "x": 0,
      "y": 8,
      "z": 3,
      "name": "Soil_Clay_Brick"
    },
    {
      "x": 0,
      "y": 9,
      "z": 3,
      "name": "Soil_Clay_Brick_Half"
    },
    {
      "x": 0,
      "y": 4,
      "z": 4,
      "name": "Soil_Dirt"
    },
    {
      "x": 0,
      "y": 5,
      "z": 4,
      "name": "Soil_Dirt"
    },
    {
      "x": 0,
      "y": 6,
      "z": 4,
      "name": "Soil_Dirt"
    },
    {
      "x": 0,
      "y": 7,
      "z": 4,
      "name": "Soil_Clay_Brick"
    },
    {
      "x": 0,
      "y": 8,
      "z": 4,
      "name": "Soil_Clay_Brick_Half"
    },
    {
      "x": 0,
      "y": 10,
      "z": 4,
      "name": "Furniture_Kweebec_Lantern"
    },
    {
      "x": 0,
      "y": 11,
      "z": 4,
      "name": "Wood_Oak_Branch_Corner",
      "rotation": 9
    },
    {
      "x": 1,
      "y": 6,
      "z": -4,
      "name": "Wood_Oak_Trunk_Full"
    },
    {
      "x": 1,
      "y": 12,
      "z": -4,
      "name": "Soil_Clay_Brick"
    },
    {
      "x": 1,
      "y": 11,
      "z": -3,
      "name": "Soil_Clay_Brick_Half",
      "rotation": 8
    },
    {
      "x": 1,
      "y": 12,
      "z": -3,
      "name": "Soil_Clay_Brick"
    },
    {
      "x": 1,
      "y": 11,
      "z": -2,
      "name": "Soil_Clay_Brick_Half",
      "rotation": 8
    },
    {
      "x": 1,
      "y": 12,
      "z": -2,
      "name": "Soil_Clay_Brick"
    },
    {
      "x": 1,
      "y": 5,
      "z": -1,
      "name": "Soil_Dirt"
    },
    {
      "x": 1,
      "y": 6,
      "z": -1,
      "name": "Soil_Dirt"
    },
    {
      "x": 1,
      "y": 7,
      "z": -1,
      "name": "Wood_Oak_Trunk_Full",
      "support": 15
    },
    {
      "x": 1,
      "y": 10,
      "z": -1,
      "name": "Wood_Oak_Trunk_Full",
      "support": 15
    },
    {
      "x": 1,
      "y": 11,
      "z": -1,
      "name": "Wood_Oak_Trunk"
    },
    {
      "x": 1,
      "y": 12,
      "z": -1,
      "name": "Wood_Oak_Trunk"
    },
    {
      "x": 1,
      "y": 13,
      "z": -1,
      "name": "Wood_Oak_Trunk"
    },
    {
      "x": 1,
      "y": 4,
      "z": 0,
      "name": "Soil_Dirt"
    },
    {
      "x": 1,
      "y": 5,
      "z": 0,
      "name": "Soil_Dirt"
    },
    {
      "x": 1,
      "y": 6,
      "z": 0,
      "name": "Soil_Dirt"
    },
    {
      "x": 1,
      "y": 7,
      "z": 0,
      "name": "Wood_Oak_Trunk"
    },
    {
      "x": 1,
      "y": 8,
      "z": 0,
      "name": "Wood_Oak_Trunk"
    },
    {
      "x": 1,
      "y": 9,
      "z": 0,
      "name": "Wood_Oak_Trunk"
    },
    {
      "x": 1,
      "y": 10,
      "z": 0,
      "name": "Wood_Oak_Trunk"
    },
    {
      "x": 1,
      "y": 11,
      "z": 0,
      "name": "Wood_Oak_Trunk"
    },
    {
      "x": 1,
      "y": 12,
      "z": 0,
      "name": "Wood_Oak_Trunk"
    },
    {
      "x": 1,
      "y": 13,
      "z": 0,
      "name": "Wood_Oak_Trunk_Full"
    },
    {
      "x": 1,
      "y": 3,
      "z": 1,
      "name": "Soil_Dirt"
    },
    {
      "x": 1,
      "y": 4,
      "z": 1,
      "name": "Soil_Dirt"
    },
    {
      "x": 1,
      "y": 5,
      "z": 1,
      "name": "Soil_Dirt"
    },
    {
      "x": 1,
      "y": 6,
      "z": 1,
      "name": "Soil_Dirt"
    },
    {
      "x": 1,
      "y": 7,
      "z": 1,
      "name": "Wood_Oak_Trunk"
    },
    {
      "x": 1,
      "y": 8,
      "z": 1,
      "name": "Wood_Oak_Trunk"
    },
    {
      "x": 1,
      "y": 9,
      "z": 1,
      "name": "Wood_Oak_Trunk"
    },
    {
      "x": 1,
      "y": 10,
      "z": 1,
      "name": "Wood_Oak_Trunk"
    },
    {
      "x": 1,
      "y": 11,
      "z": 1,
      "name": "Wood_Oak_Trunk"
    },
    {
      "x": 1,
      "y": 4,
      "z": 2,
      "name": "Soil_Dirt"
    },
    {
      "x": 1,
      "y": 5,
      "z": 2,
      "name": "Soil_Dirt"
    },
    {
      "x": 1,
      "y": 6,
      "z": 2,
      "name": "Soil_Dirt"
    },
    {
      "x": 1,
      "y": 7,
      "z": 2,
      "name": "Soil_Clay_Brick"
    },
    {
      "x": 1,
      "y": 8,
      "z": 2,
      "name": "Soil_Clay_Brick"
    },
    {
      "x": 1,
      "y": 9,
      "z": 2,
      "name": "Soil_Clay_Brick"
    },
    {
      "x": 1,
      "y": 4,
      "z": 3,
      "name": "Soil_Dirt"
    },
    {
      "x": 1,
      "y": 5,
      "z": 3,
      "name": "Soil_Dirt"
    },
    {
      "x": 1,
      "y": 6,
      "z": 3,
      "name": "Soil_Dirt"
    },
    {
      "x": 1,
      "y": 7,
      "z": 3,
      "name": "Soil_Clay_Brick"
    },
    {
      "x": 1,
      "y": 8,
      "z": 3,
      "name": "Soil_Clay_Brick"
    },
    {
      "x": 1,
      "y": 9,
      "z": 3,
      "name": "Soil_Clay_Brick"
    },
    {
      "x": 1,
      "y": 6,
      "z": 4,
      "name": "Soil_Grass"
    },
    {
      "x": 1,
      "y": 7,
      "z": 4,
      "name": "Wood_Oak_Branch_Corner"
    },
    {
      "x": 1,
      "y": 8,
      "z": 4,
      "name": "Wood_Oak_Branch_Long"
    },
    {
      "x": 1,
      "y": 9,
      "z": 4,
      "name": "Wood_Oak_Branch_Long"
    },
    {
      "x": 1,
      "y": 10,
      "z": 4,
      "name": "Wood_Oak_Branch_Long"
    },
    {
      "x": 1,
      "y": 11,
      "z": 4,
      "name": "Wood_Oak_Branch_Corner",
      "rotation": 11
    },
    {
      "x": 2,
      "y": 12,
      "z": -4,
      "name": "Soil_Clay_Brick_Half",
      "rotation": 6
    },
    {
      "x": 2,
      "y": 11,
      "z": -3,
      "name": "Soil_Clay_Brick_Half",
      "rotation": 8
    },
    {
      "x": 2,
      "y": 12,
      "z": -3,
      "name": "Soil_Clay_Brick"
    },
    {
      "x": 2,
      "y": 11,
      "z": -2,
      "name": "Soil_Clay_Brick"
    },
    {
      "x": 2,
      "y": 12,
      "z": -2,
      "name": "Soil_Clay_Brick_Half"
    },
    {
      "x": 2,
      "y": 6,
      "z": -1,
      "name": "Wood_Oak_Trunk_Full"
    },
    {
      "x": 2,
      "y": 7,
      "z": -1,
      "name": "Wood_Oak_Trunk_Full"
    },
    {
      "x": 2,
      "y": 10,
      "z": -1,
      "name": "Soil_Clay_Brick_Half",
      "rotation": 8
    },
    {
      "x": 2,
      "y": 11,
      "z": -1,
      "name": "Soil_Clay_Brick"
    },
    {
      "x": 2,
      "y": 6,
      "z": 0,
      "name": "Soil_Grass"
    },
    {
      "x": 2,
      "y": 9,
      "z": 0,
      "name": "Wood_Oak_Branch_Corner",
      "rotation": 1
    },
    {
      "x": 2,
      "y": 10,
      "z": 0,
      "name": "Soil_Clay_Brick"
    },
    {
      "x": 2,
      "y": 11,
      "z": 0,
      "name": "Soil_Clay_Brick_Half"
    },
    {
      "x": 2,
      "y": 4,
      "z": 1,
      "name": "Soil_Dirt"
    },
    {
      "x": 2,
      "y": 5,
      "z": 1,
      "name": "Soil_Dirt"
    },
    {
      "x": 2,
      "y": 6,
      "z": 1,
      "name": "Soil_Grass"
    },
    {
      "x": 2,
      "y": 9,
      "z": 1,
      "name": "Soil_Clay_Brick_Half",
      "rotation": 8
    },
    {
      "x": 2,
      "y": 10,
      "z": 1,
      "name": "Soil_Clay_Brick"
    },
    {
      "x": 2,
      "y": 4,
      "z": 2,
      "name": "Soil_Dirt"
    },
    {
      "x": 2,
      "y": 5,
      "z": 2,
      "name": "Soil_Dirt"
    },
    {
      "x": 2,
      "y": 6,
      "z": 2,
      "name": "Soil_Grass"
    },
    {
      "x": 2,
      "y": 8,
      "z": 2,
      "name": "Soil_Clay_Brick"
    },
    {
      "x": 2,
      "y": 9,
      "z": 2,
      "name": "Soil_Clay_Brick"
    },
    {
      "x": 2,
      "y": 10,
      "z": 2,
      "name": "Soil_Clay_Brick_Half"
    },
    {
      "x": 2,
      "y": 5,
      "z": 3,
      "name": "Soil_Dirt"
    },
    {
      "x": 2,
      "y": 6,
      "z": 3,
      "name": "Soil_Grass"
    },
    {
      "x": 2,
      "y": 8,
      "z": 3,
      "name": "Soil_Clay_Brick_Half",
      "rotation": 8
    },
    {
      "x": 2,
      "y": 9,
      "z": 3,
      "name": "Soil_Clay_Brick"
    },
    {
      "x": 3,
      "y": 11,
      "z": -3,
      "name": "Soil_Clay_Brick"
    },
    {
      "x": 3,
      "y": 12,
      "z": -3,
      "name": "Soil_Clay_Brick_Half"
    },
    {
      "x": 3,
      "y": 6,
      "z": -2,
      "name": "Wood_Oak_Trunk_Full"
    },
    {
      "x": 3,
      "y": 11,
      "z": -2,
      "name": "Soil_Clay_Brick"
    },
    {
      "x": 3,
      "y": 12,
      "z": -2,
      "name": "Soil_Clay_Brick_Half"
    },
    {
      "x": 3,
      "y": 6,
      "z": -1,
      "name": "Wood_Oak_Trunk_Full"
    },
    {
      "x": 3,
      "y": 10,
      "z": -1,
      "name": "Soil_Clay_Brick_Half",
      "rotation": 8
    },
    {
      "x": 3,
      "y": 11,
      "z": -1,
      "name": "Soil_Clay_Brick"
    },
    {
      "x": 3,
      "y": 10,
      "z": 0,
      "name": "Soil_Clay_Brick"
    },
    {
      "x": 3,
      "y": 11,
      "z": 0,
      "name": "Soil_Clay_Brick_Half"
    },
    {
      "x": 3,
      "y": 9,
      "z": 1,
      "name": "Soil_Clay_Brick_Half",
      "rotation": 8
    },
    {
      "x": 3,
      "y": 10,
      "z": 1,
      "name": "Soil_Clay_Brick"
    },
    {
      "x": 3,
      "y": 6,
      "z": 2,
      "name": "Soil_Grass"
    },
    {
      "x": 3,
      "y": 9,
      "z": 2,
      "name": "Soil_Clay_Brick"
    },
    {
      "x": 3,
      "y": 10,
      "z": 2,
      "name": "Soil_Clay_Brick_Half"
    }
  ],
  "entities": [
    {
      "Components": {
        "PatrolPathMarker": {
          "Version": 5,
          "Position": {
            "X": -0.4307441711425781,
            "Y": 14.0,
            "Z": -2.7762143371582155
          },
          "HeadRotation": {
            "Pitch": 0.0,
            "Yaw": -12.591473579406738,
            "Roll": 0.0
          },
          "BodyRotation": {
            "Pitch": 0.0,
            "Yaw": -12.591473579406738,
            "Roll": 0.0
          },
          "DisplayName": "0.Kweebec_Camp_Patrol_004~1 #2 [Wait 15.0s] <Rotate 0.00deg>",
          "NameTagVisible": true,
          "UUID": {
            "$binary": "TM0WsoTcNPSUxYGY426FYg==",
            "$type": "04"
          },
          "Metadata": {},
          "PathName": "Kweebec_Camp_Patrol_004~1",
          "PathLength": 3,
          "Order": 2,
          "PauseTime": 15.0,
          "ObsvAngle": 0.0
        },
        "Model": {
          "Model": {
            "Id": "Mannequin",
            "Scale": 1.0
          }
        },
        "Transform": {
          "Position": {
            "X": -0.4307441711425781,
            "Y": 14.0,
            "Z": -2.7762143371582155
          },
          "Rotation": {
            "Pitch": 0.0,
            "Yaw": -12.591473579406738,
            "Roll": 0.0
          }
        },
        "UUID": {
          "UUID": {
            "$binary": "TM0WsoTcNPSUxYGY426FYg==",
            "$type": "04"
          }
        },
        "HeadRotation": {
          "Rotation": {
            "Pitch": 0.0,
            "Yaw": -12.591473579406738,
            "Roll": 0.0
          }
        }
      }
    },
    {
      "Components": {
        "PatrolPathMarker": {
          "Version": 5,
          "Position": {
            "X": -0.5321163757324143,
            "Y": 14.0,
            "Z": 3.057323901367198
          },
          "HeadRotation": {
            "Pitch": 0.0,
            "Yaw": -9.442742347717285,
            "Roll": 0.0
          },
          "BodyRotation": {
            "Pitch": 0.0,
            "Yaw": -9.442742347717285,
            "Roll": 0.0
          },
          "DisplayName": "0.Kweebec_Camp_Patrol_004~1 #1 [Wait 15.0s] <Rotate 0.00deg>",
          "NameTagVisible": true,
          "UUID": {
            "$binary": "M74kLgtIP0aCx5zyBsFPBQ==",
            "$type": "04"
          },
          "Metadata": {},
          "PathName": "Kweebec_Camp_Patrol_004~1",
          "PathLength": 3,
          "Order": 1,
          "PauseTime": 15.0,
          "ObsvAngle": 0.0
        },
        "Model": {
          "Model": {
            "Id": "Mannequin",
            "Scale": 1.0
          }
        },
        "Transform": {
          "Position": {
            "X": -0.5321163757324143,
            "Y": 14.0,
            "Z": 3.057323901367198
          },
          "Rotation": {
            "Pitch": 0.0,
            "Yaw": -9.442742347717285,
            "Roll": 0.0
          }
        },
        "UUID": {
          "UUID": {
            "$binary": "M74kLgtIP0aCx5zyBsFPBQ==",
            "$type": "04"
          }
        },
        "HeadRotation": {
          "Rotation": {
            "Pitch": 0.0,
            "Yaw": -9.442742347717285,
            "Roll": 0.0
          }
        }
      }
    },
    {
      "Components": {
        "Nameplate": {
          "Text": "Kweebec_Razorleaf_Patrol"
        },
        "HiddenFromAdventurePlayer": {},
        "SpawnMarkerComponent": {
          "SpawnMarker": "Kweebec_Razorleaf_Patrol",
          "RespawnTime": 0.0,
          "SpawnCount": 0
        },
        "Transform": {
          "Position": {
            "X": -0.654205322265625,
            "Y": 14.416343688964844,
            "Z": 0.05258941650390625
          },
          "Rotation": {
            "Pitch": 0.0,
            "Yaw": 0.018105030059814453,
            "Roll": 0.0
          }
        },
        "Model": {
          "Model": {
            "Id": "NPC_Spawn_Marker",
            "Scale": 1.0
          }
        },
        "UUID": {
          "UUID": {
            "$binary": "oc4FL45/Mz6LrS03yKWbkw==",
            "$type": "04"
          }
        },
        "HeadRotation": {
          "Rotation": {
            "Pitch": 0.0,
            "Yaw": -3.123487949371338,
            "Roll": 0.0
          }
        }
      }
    },
    {
      "Components": {
        "PatrolPathMarker": {
          "Version": 5,
          "Position": {
            "X": -0.5943603515625,
            "Y": 14.102630615234375,
            "Z": 0.42374420166015625
          },
          "HeadRotation": {
            "Pitch": 0.0,
            "Yaw": 2.8900585174560547,
            "Roll": 0.0
          },
          "BodyRotation": {
            "Pitch": 0.0,
            "Yaw": 2.8900585174560547,
            "Roll": 0.0
          },
          "DisplayName": "0.Kweebec_Camp_Patrol_004~1 #0 [Wait 0.0s] <Rotate 0.00deg>",
          "NameTagVisible": true,
          "UUID": {
            "$binary": "UGz875K5NjeB9aaq+aDw3A==",
            "$type": "04"
          },
          "Metadata": {},
          "PathName": "Kweebec_Camp_Patrol_004~1",
          "PathLength": 3,
          "Order": 0,
          "PauseTime": 0.0,
          "ObsvAngle": 0.0
        },
        "Model": {
          "Model": {
            "Id": "Mannequin",
            "Scale": 1.0
          }
        },
        "Transform": {
          "Position": {
            "X": -0.5943603515625,
            "Y": 14.102630615234375,
            "Z": 0.42374420166015625
          },
          "Rotation": {
            "Pitch": 0.0,
            "Yaw": 2.8900585174560547,
            "Roll": 0.0
          }
        },
        "UUID": {
          "UUID": {
            "$binary": "UGz875K5NjeB9aaq+aDw3A==",
            "$type": "04"
          }
        },
        "HeadRotation": {
          "Rotation": {
            "Pitch": 0.0,
            "Yaw": 2.8900585174560547,
            "Roll": 0.0
          }
        }
      }
    }
  ]
}