{
  "version": 8,
  "blockIdVersion": 8,
  "anchorX": -2,
  "anchorY": 12,
  "anchorZ": 0,
  "blocks": [
    {
      "x": -25,
      "y": 19,
      "z": 22,
      "name": "Deco_Bone_Full"
    },
    {
      "x": -25,
      "y": 19,
      "z": 23,
      "name": "Deco_Bone_Full"
    },
    {
      "x": -24,
      "y": 20,
      "z": 16,
      "name": "Deco_Bone_Full"
    },
    {
      "x": -24,
      "y": 21,
      "z": 16,
      "name": "Deco_Bone_Full"
    },
    {
      "x": -24,
      "y": 22,
      "z": 16,
      "name": "Deco_Bone_Full"
    },
    {
      "x": -24,
      "y": 23,
      "z": 16,
      "name": "Deco_Bone_Full"
    },
    {
      "x": -24,
      "y": 24,
      "z": 16,
      "name": "Deco_Bone_Full"
    },
    {
      "x": -24,
      "y": 25,
      "z": 16,
      "name": "Deco_Bone_Full"
    },
    {
      "x": -24,
      "y": 20,
      "z": 17,
      "name": "Deco_Bone_Full"
    },
    {
      "x": -24,
      "y": 19,
      "z": 21,
      "name": "Deco_Bone_Full"
    },
    {
      "x": -24,
      "y": 18,
      "z": 22,
      "name": "Deco_Bone_Full"
    },
    {
      "x": -24,
      "y": 19,
      "z": 22,
      "name": "Deco_Bone_Full"
    },
    {
      "x": -24,
      "y": 19,
      "z": 23,
      "name": "Deco_Bone_Full"
    },
    {
      "x": -23,
      "y": 20,
      "z": 16,
      "name": "Deco_Bone_Full"
    },
    {
      "x": -23,
      "y": 19,
      "z": 17,
      "name": "Deco_Bone_Full"
    },
    {
      "x": -23,
      "y": 20,
      "z": 17,
      "name": "Deco_Bone_Full"
    },
    {
      "x": -23,
      "y": 25,
      "z": 17,
      "name": "Deco_Bone_Full"
    },
    {
      "x": -23,
      "y": 26,
      "z": 17,
      "name": "Deco_Bone_Full"
    },
    {
      "x": -23,
      "y": 18,
      "z": 18,
      "name": "Deco_Bone_Full"
    },
    {
      "x": -23,
      "y": 19,
      "z": 18,
      "name": "Deco_Bone_Full"
    },
    {
      "x": -23,
      "y": 18,
      "z": 20,
      "name": "Deco_Bone_Full"
    },
    {
      "x": -23,
      "y": 18,
      "z": 21,
      "name": "Deco_Bone_Full"
    },
    {
      "x": -23,
      "y": 19,
      "z": 21,
      "name": "Deco_Bone_Full"
    },
    {
      "x": -23,
      "y": 19,
      "z": 22,
      "name": "Deco_Bone_Full"
    },
    {
      "x": -22,
      "y": 20,
      "z": 10,
      "name": "Deco_Bone_Full"
    },
    {
      "x": -22,
      "y": 21,
      "z": 10,
      "name": "Deco_Bone_Full"
    },
    {
      "x": -22,
      "y": 22,
      "z": 10,
      "name": "Deco_Bone_Full"
    },
    {
      "x": -22,
      "y": 23,
      "z": 10,
      "name": "Deco_Bone_Full"
    },
    {
      "x": -22,
      "y": 20,
      "z": 11,
      "name": "Deco_Bone_Full"
    },
    {
      "x": -22,
      "y": 18,
      "z": 17,
      "name": "Deco_Bone_Full"
    },
    {
      "x": -22,
      "y": 19,
      "z": 17,
      "name": "Deco_Bone_Full"
    },
    {
      "x": -22,
      "y": 17,
      "z": 18,
      "name": "Deco_Bone_Full"
    },
    {
      "x": -22,
      "y": 18,
      "z": 18,
      "name": "Deco_Bone_Full"
    },
    {
      "x": -22,
      "y": 19,
      "z": 18,
      "name": "Deco_Bone_Full"
    },
    {
      "x": -22,
      "y": 16,
      "z": 19,
      "name": "Deco_Bone_Full"
    },
    {
      "x": -22,
      "y": 17,
      "z": 19,
      "name": "Deco_Bone_Full"
    },
    {
      "x": -22,
      "y": 18,
      "z": 19,
      "name": "Deco_Bone_Full"
    },
    {
      "x": -22,
      "y": 19,
      "z": 19,
      "name": "Deco_Bone_Full"
    },
    {
      "x": -22,
      "y": 15,
      "z": 20,
      "name": "Deco_Bone_Full"
    },
    {
      "x": -22,
      "y": 16,
      "z": 20,
      "name": "Deco_Bone_Full"
    },
    {
      "x": -22,
      "y": 17,
      "z": 20,
      "name": "Deco_Bone_Full"
    },
    {
      "x": -22,
      "y": 18,
      "z": 20,
      "name": "Deco_Bone_Full"
    },
    {
      "x": -22,
      "y": 19,
      "z": 20,
      "name": "Deco_Bone_Full"
    },
    {
      "x": -22,
      "y": 18,
      "z": 21,
      "name": "Deco_Bone_Full"
    },
    {
      "x": -21,
      "y": 20,
      "z": 10,
      "name": "Deco_Bone_Full"
    },
    {
      "x": -21,
      "y": 19,
      "z": 11,
      "name": "Deco_Bone_Full"
    },
    {
      "x": -21,
      "y": 20,
      "z": 11,
      "name": "Deco_Bone_Full"
    },
    {
      "x": -21,
      "y": 19,
      "z": 12,
      "name": "Deco_Bone_Full"
    },
    {
      "x": -21,
      "y": 18,
      "z": 17,
      "name": "Deco_Bone_Full"
    },
    {
      "x": -21,
      "y": 16,
      "z": 18,
      "name": "Deco_Bone_Full"
    },
    {
      "x": -21,
      "y": 17,
      "z": 18,
      "name": "Deco_Bone_Full"
    },
    {
      "x": -21,
      "y": 18,
      "z": 18,
      "name": "Deco_Bone_Full"
    },
    {
      "x": -21,
      "y": 19,
      "z": 18,
      "name": "Deco_Bone_Full"
    },
    {
      "x": -21,
      "y": 14,
      "z": 19,
      "name": "Deco_Bone_Full"
    },
    {
      "x": -21,
      "y": 15,
      "z": 19,
      "name": "Deco_Bone_Full"
    },
    {
      "x": -21,
      "y": 16,
      "z": 19,
      "name": "Deco_Bone_Full"
    },
    {
      "x": -21,
      "y": 17,
      "z": 19,
      "name": "Deco_Bone_Full"
    },
    {
      "x": -21,
      "y": 18,
      "z": 19,
      "name": "Deco_Bone_Full"
    },
    {
      "x": -21,
      "y": 19,
      "z": 19,
      "name": "Deco_Bone_Full"
    },
    {
      "x": -21,
      "y": 20,
      "z": 19,
      "name": "Deco_Bone_Full"
    },
    {
      "x": -21,
      "y": 16,
      "z": 20,
      "name": "Deco_Bone_Full"
    },
    {
      "x": -21,
      "y": 17,
      "z": 20,
      "name": "Deco_Bone_Full"
    },
    {
      "x": -21,
      "y": 18,
      "z": 20,
      "name": "Deco_Bone_Full"
    },
    {
      "x": -21,
      "y": 19,
      "z": 20,
      "name": "Deco_Bone_Full"
    },
    {
      "x": -20,
      "y": 19,
      "z": 11,
      "name": "Deco_Bone_Full"
    },
    {
      "x": -20,
      "y": 18,
      "z": 12,
      "name": "Deco_Bone_Full"
    },
    {
      "x": -20,
      "y": 19,
      "z": 12,
      "name": "Deco_Bone_Full"
    },
    {
      "x": -20,
      "y": 18,
      "z": 13,
      "name": "Deco_Bone_Full"
    },
    {
      "x": -20,
      "y": 17,
      "z": 17,
      "name": "Deco_Bone_Full"
    },
    {
      "x": -20,
      "y": 14,
      "z": 18,
      "name": "Deco_Bone_Full"
    },
    {
      "x": -20,
      "y": 15,
      "z": 18,
      "name": "Deco_Bone_Full"
    },
    {
      "x": -20,
      "y": 16,
      "z": 18,
      "name": "Deco_Bone_Full"
    },
    {
      "x": -20,
      "y": 17,
      "z": 18,
      "name": "Deco_Bone_Full"
    },
    {
      "x": -20,
      "y": 18,
      "z": 18,
      "name": "Deco_Bone_Full"
    },
    {
      "x": -20,
      "y": 16,
      "z": 19,
      "name": "Deco_Bone_Full"
    },
    {
      "x": -20,
      "y": 17,
      "z": 19,
      "name": "Deco_Bone_Full"
    },
    {
      "x": -20,
      "y": 18,
      "z": 19,
      "name": "Deco_Bone_Full"
    },
    {
      "x": -20,
      "y": 19,
      "z": 19,
      "name": "Deco_Bone_Full"
    },
    {
      "x": -20,
      "y": 17,
      "z": 20,
      "name": "Deco_Bone_Full"
    },
    {
      "x": -20,
      "y": 18,
      "z": 20,
      "name": "Deco_Bone_Full"
    },
    {
      "x": -20,
      "y": 19,
      "z": 20,
      "name": "Deco_Bone_Full"
    },
    {
      "x": -20,
      "y": 18,
      "z": 21,
      "name": "Deco_Bone_Full"
    },
    {
      "x": -20,
      "y": 19,
      "z": 21,
      "name": "Deco_Bone_Full"
    },
    {
      "x": -19,
      "y": 21,
      "z": 5,
      "name": "Deco_Bone_Full"
    },
    {
      "x": -19,
      "y": 22,
      "z": 5,
      "name": "Deco_Bone_Full"
    },
    {
      "x": -19,
      "y": 23,
      "z": 5,
      "name": "Deco_Bone_Full"
    },
    {
      "x": -19,
      "y": 24,
      "z": 5,
      "name": "Deco_Bone_Full"
    },
    {
      "x": -19,
      "y": 25,
      "z": 5,
      "name": "Deco_Bone_Full"
    },
    {
      "x": -19,
      "y": 26,
      "z": 5,
      "name": "Deco_Bone_Full"
    },
    {
      "x": -19,
      "y": 27,
      "z": 5,
      "name": "Deco_Bone_Full"
    },
    {
      "x": -19,
      "y": 28,
      "z": 5,
      "name": "Deco_Bone_Full"
    },
    {
      "x": -19,
      "y": 29,
      "z": 5,
      "name": "Deco_Bone_Full"
    },
    {
      "x": -19,
      "y": 30,
      "z": 5,
      "name": "Deco_Bone_Full"
    },
    {
      "x": -19,
      "y": 31,
      "z": 5,
      "name": "Deco_Bone_Full"
    },
    {
      "x": -19,
      "y": 18,
      "z": 12,
      "name": "Deco_Bone_Full"
    },
    {
      "x": -19,
      "y": 17,
      "z": 13,
      "name": "Deco_Bone_Full"
    },
    {
      "x": -19,
      "y": 18,
      "z": 13,
      "name": "Deco_Bone_Full"
    },
    {
      "x": -19,
      "y": 17,
      "z": 14,
      "name": "Deco_Bone_Full"
    },
    {
      "x": -19,
      "y": 18,
      "z": 14,
      "name": "Deco_Bone_Full"
    },
    {
      "x": -19,
      "y": 17,
      "z": 16,
      "name": "Deco_Bone_Full"
    },
    {
      "x": -19,
      "y": 16,
      "z": 17,
      "name": "Deco_Bone_Full"
    },
    {
      "x": -19,
      "y": 17,
      "z": 17,
      "name": "Deco_Bone_Full"
    },
    {
      "x": -19,
      "y": 17,
      "z": 18,
      "name": "Deco_Bone_Full"
    },
    {
      "x": -19,
      "y": 18,
      "z": 19,
      "name": "Deco_Bone_Full"
    },
    {
      "x": -19,
      "y": 18,
      "z": 20,
      "name": "Deco_Bone_Full"
    },
    {
      "x": -19,
      "y": 19,
      "z": 20,
      "name": "Deco_Bone_Full"
    },
    {
      "x": -19,
      "y": 19,
      "z": 21,
      "name": "Deco_Bone_Full"
    },
    {
      "x": -19,
      "y": 20,
      "z": 21,
      "name": "Deco_Bone_Full"
    },
    {
      "x": -19,
      "y": 25,
      "z": 21,
      "name": "Deco_Bone_Full"
    },
    {
      "x": -19,
      "y": 26,
      "z": 21,
      "name": "Deco_Bone_Full"
    },
    {
      "x": -19,
      "y": 20,
      "z": 22,
      "name": "Deco_Bone_Full"
    },
    {
      "x": -18,
      "y": 28,
      "z": 5,
      "name": "Plant_Crop_Health3",
      "rotation": 1
    },
    {
      "x": -18,
      "y": 29,
      "z": 5,
      "name": "Plant_Crop_Health3",
      "filler": 1024,
      "rotation": 1
    },
    {
      "x": -18,
      "y": 19,
      "z": 6,
      "name": "Deco_Bone_Full"
    },
    {
      "x": -18,
      "y": 20,
      "z": 6,
      "name": "Deco_Bone_Full"
    },
    {
      "x": -18,
      "y": 21,
      "z": 6,
      "name": "Deco_Bone_Full"
    },
    {
      "x": -18,
      "y": 31,
      "z": 6,
      "name": "Deco_Bone_Full"
    },
    {
      "x": -18,
      "y": 32,
      "z": 6,
      "name": "Deco_Bone_Full"
    },
    {
      "x": -18,
      "y": 33,
      "z": 6,
      "name": "Deco_Bone_Full"
    },
    {
      "x": -18,
      "y": 19,
      "z": 7,
      "name": "Deco_Bone_Full"
    },
    {
      "x": -18,
      "y": 17,
      "z": 13,
      "name": "Deco_Bone_Full"
    },
    {
      "x": -18,
      "y": 18,
      "z": 13,
      "name": "Deco_Bone_Full"
    },
    {
      "x": -18,
      "y": 16,
      "z": 14,
      "name": "Deco_Bone_Full"
    },
    {
      "x": -18,
      "y": 17,
      "z": 14,
      "name": "Deco_Bone_Full"
    },
    {
      "x": -18,
      "y": 18,
      "z": 14,
      "name": "Deco_Bone_Full"
    },
    {
      "x": -18,
      "y": 15,
      "z": 15,
      "name": "Deco_Bone_Full"
    },
    {
      "x": -18,
      "y": 16,
      "z": 15,
      "name": "Deco_Bone_Full"
    },
    {
      "x": -18,
      "y": 17,
      "z": 15,
      "name": "Deco_Bone_Full"
    },
    {
      "x": -18,
      "y": 18,
      "z": 15,
      "name": "Deco_Bone_Full"
    },
    {
      "x": -18,
      "y": 14,
      "z": 16,
      "name": "Deco_Bone_Full"
    },
    {
      "x": -18,
      "y": 15,
      "z": 16,
      "name": "Deco_Bone_Full"
    },
    {
      "x": -18,
      "y": 16,
      "z": 16,
      "name": "Deco_Bone_Full"
    },
    {
      "x": -18,
      "y": 17,
      "z": 16,
      "name": "Deco_Bone_Full"
    },
    {
      "x": -18,
      "y": 18,
      "z": 16,
      "name": "Deco_Bone_Full"
    },
    {
      "x": -18,
      "y": 17,
      "z": 17,
      "name": "Deco_Bone_Full"
    },
    {
      "x": -18,
      "y": 20,
      "z": 21,
      "name": "Deco_Bone_Full"
    },
    {
      "x": -18,
      "y": 20,
      "z": 22,
      "name": "Deco_Bone_Full"
    },
    {
      "x": -18,
      "y": 21,
      "z": 22,
      "name": "Deco_Bone_Full"
    },
    {
      "x": -18,
      "y": 22,
      "z": 22,
      "name": "Deco_Bone_Full"
    },
    {
      "x": -18,
      "y": 23,
      "z": 22,
      "name": "Deco_Bone_Full"
    },
    {
      "x": -18,
      "y": 24,
      "z": 22,
      "name": "Deco_Bone_Full"
    },
    {
      "x": -18,
      "y": 25,
      "z": 22,
      "name": "Deco_Bone_Full"
    },
    {
      "x": -17,
      "y": 28,
      "z": 5,
      "name": "Empty"
    },
    {
      "x": -17,
      "y": 29,
      "z": 5,
      "name": "Empty"
    },
    {
      "x": -17,
      "y": 19,
      "z": 6,
      "name": "Deco_Bone_Full"
    },
    {
      "x": -17,
      "y": 17,
      "z": 7,
      "name": "Deco_Bone_Full"
    },
    {
      "x": -17,
      "y": 18,
      "z": 7,
      "name": "Deco_Bone_Full"
    },
    {
      "x": -17,
      "y": 19,
      "z": 7,
      "name": "Deco_Bone_Full"
    },
    {
      "x": -17,
      "y": 33,
      "z": 7,
      "name": "Deco_Bone_Full"
    },
    {
      "x": -17,
      "y": 34,
      "z": 7,
      "name": "Deco_Bone_Full"
    },
    {
      "x": -17,
      "y": 18,
      "z": 8,
      "name": "Deco_Bone_Full"
    },
    {
      "x": -17,
      "y": 17,
      "z": 13,
      "name": "Deco_Bone_Full"
    },
    {
      "x": -17,
      "y": 15,
      "z": 14,
      "name": "Deco_Bone_Full"
    },
    {
      "x": -17,
      "y": 16,
      "z": 14,
      "name": "Deco_Bone_Full"
    },
    {
      "x": -17,
      "y": 17,
      "z": 14,
      "name": "Deco_Bone_Full"
    },
    {
      "x": -17,
      "y": 18,
      "z": 14,
      "name": "Deco_Bone_Full"
    },
    {
      "x": -17,
      "y": 13,
      "z": 15,
      "name": "Deco_Bone_Full"
    },
    {
      "x": -17,
      "y": 14,
      "z": 15,
      "name": "Deco_Bone_Full"
    },
    {
      "x": -17,
      "y": 15,
      "z": 15,
      "name": "Deco_Bone_Full"
    },
    {
      "x": -17,
      "y": 16,
      "z": 15,
      "name": "Deco_Bone_Full"
    },
    {
      "x": -17,
      "y": 17,
      "z": 15,
      "name": "Deco_Bone_Full"
    },
    {
      "x": -17,
      "y": 18,
      "z": 15,
      "name": "Deco_Bone_Full"
    },
    {
      "x": -17,
      "y": 19,
      "z": 15,
      "name": "Deco_Bone_Full"
    },
    {
      "x": -17,
      "y": 15,
      "z": 16,
      "name": "Deco_Bone_Full"
    },
    {
      "x": -17,
      "y": 16,
      "z": 16,
      "name": "Deco_Bone_Full"
    },
    {
      "x": -17,
      "y": 17,
      "z": 16,
      "name": "Deco_Bone_Full"
    },
    {
      "x": -17,
      "y": 18,
      "z": 16,
      "name": "Deco_Bone_Full"
    },
    {
      "x": -16,
      "y": 18,
      "z": 7,
      "name": "Deco_Bone_Full"
    },
    {
      "x": -16,
      "y": 17,
      "z": 8,
      "name": "Deco_Bone_Full"
    },
    {
      "x": -16,
      "y": 18,
      "z": 8,
      "name": "Deco_Bone_Full"
    },
    {
      "x": -16,
      "y": 34,
      "z": 8,
      "name": "Deco_Bone_Full"
    },
    {
      "x": -16,
      "y": 35,
      "z": 8,
      "name": "Deco_Bone_Full"
    },
    {
      "x": -16,
      "y": 17,
      "z": 9,
      "name": "Deco_Bone_Full"
    },
    {
      "x": -16,
      "y": 16,
      "z": 13,
      "name": "Deco_Bone_Full"
    },
    {
      "x": -16,
      "y": 12,
      "z": 14,
      "name": "Deco_Bone_Full"
    },
    {
      "x": -16,
      "y": 13,
      "z": 14,
      "name": "Deco_Bone_Full"
    },
    {
      "x": -16,
      "y": 14,
      "z": 14,
      "name": "Deco_Bone_Full"
    },
    {
      "x": -16,
      "y": 15,
      "z": 14,
      "name": "Deco_Bone_Full"
    },
    {
      "x": -16,
      "y": 16,
      "z": 14,
      "name": "Deco_Bone_Full"
    },
    {
      "x": -16,
      "y": 17,
      "z": 14,
      "name": "Deco_Bone_Full"
    },
    {
      "x": -16,
      "y": 15,
      "z": 15,
      "name": "Deco_Bone_Full"
    },
    {
      "x": -16,
      "y": 16,
      "z": 15,
      "name": "Deco_Bone_Full"
    },
    {
      "x": -16,
      "y": 17,
      "z": 15,
      "name": "Deco_Bone_Full"
    },
    {
      "x": -16,
      "y": 18,
      "z": 15,
      "name": "Deco_Bone_Full"
    },
    {
      "x": -16,
      "y": 16,
      "z": 16,
      "name": "Deco_Bone_Full"
    },
    {
      "x": -16,
      "y": 17,
      "z": 16,
      "name": "Deco_Bone_Full"
    },
    {
      "x": -16,
      "y": 18,
      "z": 16,
      "name": "Deco_Bone_Full"
    },
    {
      "x": -16,
      "y": 17,
      "z": 17,
      "name": "Deco_Bone_Full"
    },
    {
      "x": -16,
      "y": 18,
      "z": 17,
      "name": "Deco_Bone_Full"
    },
    {
      "x": -15,
      "y": 20,
      "z": 1,
      "name": "Deco_Bone_Full"
    },
    {
      "x": -15,
      "y": 21,
      "z": 1,
      "name": "Deco_Bone_Full"
    },
    {
      "x": -15,
      "y": 22,
      "z": 1,
      "name": "Deco_Bone_Full"
    },
    {
      "x": -15,
      "y": 23,
      "z": 1,
      "name": "Deco_Bone_Full"
    },
    {
      "x": -15,
      "y": 24,
      "z": 1,
      "name": "Deco_Bone_Full"
    },
    {
      "x": -15,
      "y": 25,
      "z": 1,
      "name": "Deco_Bone_Full"
    },
    {
      "x": -15,
      "y": 26,
      "z": 1,
      "name": "Deco_Bone_Full"
    },
    {
      "x": -15,
      "y": 27,
      "z": 1,
      "name": "Deco_Bone_Full"
    },
    {
      "x": -15,
      "y": 28,
      "z": 1,
      "name": "Deco_Bone_Full"
    },
    {
      "x": -15,
      "y": 29,
      "z": 1,
      "name": "Deco_Bone_Full"
    },
    {
      "x": -15,
      "y": 17,
      "z": 8,
      "name": "Deco_Bone_Full"
    },
    {
      "x": -15,
      "y": 16,
      "z": 9,
      "name": "Deco_Bone_Full"
    },
    {
      "x": -15,
      "y": 17,
      "z": 9,
      "name": "Deco_Bone_Full"
    },
    {
      "x": -15,
      "y": 16,
      "z": 10,
      "name": "Deco_Bone_Full"
    },
    {
      "x": -15,
      "y": 17,
      "z": 10,
      "name": "Deco_Bone_Full"
    },
    {
      "x": -15,
      "y": 16,
      "z": 12,
      "name": "Deco_Bone_Full"
    },
    {
      "x": -15,
      "y": 15,
      "z": 13,
      "name": "Deco_Bone_Full"
    },
    {
      "x": -15,
      "y": 16,
      "z": 13,
      "name": "Deco_Bone_Full"
    },
    {
      "x": -15,
      "y": 16,
      "z": 14,
      "name": "Deco_Bone_Full"
    },
    {
      "x": -15,
      "y": 17,
      "z": 15,
      "name": "Deco_Bone_Full"
    },
    {
      "x": -15,
      "y": 17,
      "z": 16,
      "name": "Deco_Bone_Full"
    },
    {
      "x": -15,
      "y": 18,
      "z": 16,
      "name": "Deco_Bone_Full"
    },
    {
      "x": -15,
      "y": 17,
      "z": 17,
      "name": "Deco_Bone_Full"
    },
    {
      "x": -15,
      "y": 18,
      "z": 17,
      "name": "Deco_Bone_Full"
    },
    {
      "x": -15,
      "y": 18,
      "z": 18,
      "name": "Deco_Bone_Full"
    },
    {
      "x": -14,
      "y": 18,
      "z": 2,
      "name": "Deco_Bone_Full"
    },
    {
      "x": -14,
      "y": 19,
      "z": 2,
      "name": "Deco_Bone_Full"
    },
    {
      "x": -14,
      "y": 20,
      "z": 2,
      "name": "Deco_Bone_Full"
    },
    {
      "x": -14,
      "y": 29,
      "z": 2,
      "name": "Deco_Bone_Full"
    },
    {
      "x": -14,
      "y": 30,
      "z": 2,
      "name": "Deco_Bone_Full"
    },
    {
      "x": -14,
      "y": 31,
      "z": 2,
      "name": "Deco_Bone_Full"
    },
    {
      "x": -14,
      "y": 18,
      "z": 3,
      "name": "Deco_Bone_Full"
    },
    {
      "x": -14,
      "y": 16,
      "z": 9,
      "name": "Deco_Bone_Full"
    },
    {
      "x": -14,
      "y": 17,
      "z": 9,
      "name": "Deco_Bone_Full"
    },
    {
      "x": -14,
      "y": 15,
      "z": 10,
      "name": "Deco_Bone_Full"
    },
    {
      "x": -14,
      "y": 16,
      "z": 10,
      "name": "Deco_Bone_Full"
    },
    {
      "x": -14,
      "y": 17,
      "z": 10,
      "name": "Deco_Bone_Full"
    },
    {
      "x": -14,
      "y": 14,
      "z": 11,
      "name": "Deco_Bone_Full"
    },
    {
      "x": -14,
      "y": 15,
      "z": 11,
      "name": "Deco_Bone_Full"
    },
    {
      "x": -14,
      "y": 16,
      "z": 11,
      "name": "Deco_Bone_Full"
    },
    {
      "x": -14,
      "y": 17,
      "z": 11,
      "name": "Deco_Bone_Full"
    },
    {
      "x": -14,
      "y": 14,
      "z": 12,
      "name": "Deco_Bone_Full"
    },
    {
      "x": -14,
      "y": 15,
      "z": 12,
      "name": "Deco_Bone_Full"
    },
    {
      "x": -14,
      "y": 16,
      "z": 12,
      "name": "Deco_Bone_Full"
    },
    {
      "x": -14,
      "y": 17,
      "z": 12,
      "name": "Deco_Bone_Full"
    },
    {
      "x": -14,
      "y": 16,
      "z": 13,
      "name": "Deco_Bone_Full"
    },
    {
      "x": -14,
      "y": 18,
      "z": 17,
      "name": "Deco_Bone_Full"
    },
    {
      "x": -14,
      "y": 18,
      "z": 18,
      "name": "Deco_Bone_Full"
    },
    {
      "x": -14,
      "y": 19,
      "z": 18,
      "name": "Deco_Bone_Full"
    },
    {
      "x": -14,
      "y": 28,
      "z": 18,
      "name": "Deco_Bone_Full"
    },
    {
      "x": -14,
      "y": 29,
      "z": 18,
      "name": "Deco_Bone_Full"
    },
    {
      "x": -14,
      "y": 19,
      "z": 19,
      "name": "Deco_Bone_Full"
    },
    {
      "x": -13,
      "y": 18,
      "z": 2,
      "name": "Deco_Bone_Full"
    },
    {
      "x": -13,
      "y": 17,
      "z": 3,
      "name": "Deco_Bone_Full"
    },
    {
      "x": -13,
      "y": 18,
      "z": 3,
      "name": "Deco_Bone_Full"
    },
    {
      "x": -13,
      "y": 31,
      "z": 3,
      "name": "Deco_Bone_Full"
    },
    {
      "x": -13,
      "y": 32,
      "z": 3,
      "name": "Deco_Bone_Full"
    },
    {
      "x": -13,
      "y": 17,
      "z": 4,
      "name": "Deco_Bone_Full"
    },
    {
      "x": -13,
      "y": 16,
      "z": 9,
      "name": "Deco_Bone_Full"
    },
    {
      "x": -13,
      "y": 15,
      "z": 10,
      "name": "Deco_Bone_Full"
    },
    {
      "x": -13,
      "y": 16,
      "z": 10,
      "name": "Deco_Bone_Full"
    },
    {
      "x": -13,
      "y": 17,
      "z": 10,
      "name": "Deco_Bone_Full"
    },
    {
      "x": -13,
      "y": 12,
      "z": 11,
      "name": "Deco_Bone_Full"
    },
    {
      "x": -13,
      "y": 13,
      "z": 11,
      "name": "Deco_Bone_Full"
    },
    {
      "x": -13,
      "y": 14,
      "z": 11,
      "name": "Deco_Bone_Full"
    },
    {
      "x": -13,
      "y": 15,
      "z": 11,
      "name": "Deco_Bone_Full"
    },
    {
      "x": -13,
      "y": 16,
      "z": 11,
      "name": "Deco_Bone_Full"
    },
    {
      "x": -13,
      "y": 17,
      "z": 11,
      "name": "Deco_Bone_Full"
    },
    {
      "x": -13,
      "y": 18,
      "z": 11,
      "name": "Deco_Bone_Full"
    },
    {
      "x": -13,
      "y": 14,
      "z": 12,
      "name": "Deco_Bone_Full"
    },
    {
      "x": -13,
      "y": 15,
      "z": 12,
      "name": "Deco_Bone_Full"
    },
    {
      "x": -13,
      "y": 16,
      "z": 12,
      "name": "Deco_Bone_Full"
    },
    {
      "x": -13,
      "y": 17,
      "z": 12,
      "name": "Deco_Bone_Full"
    },
    {
      "x": -13,
      "y": 19,
      "z": 18,
      "name": "Deco_Bone_Full"
    },
    {
      "x": -13,
      "y": 19,
      "z": 19,
      "name": "Deco_Bone_Full"
    },
    {
      "x": -13,
      "y": 20,
      "z": 19,
      "name": "Deco_Bone_Full"
    },
    {
      "x": -13,
      "y": 26,
      "z": 19,
      "name": "Deco_Bone_Full"
    },
    {
      "x": -13,
      "y": 27,
      "z": 19,
      "name": "Deco_Bone_Full"
    },
    {
      "x": -13,
      "y": 28,
      "z": 19,
      "name": "Deco_Bone_Full"
    },
    {
      "x": -13,
      "y": 20,
      "z": 20,
      "name": "Deco_Bone_Full"
    },
    {
      "x": -12,
      "y": 17,
      "z": 3,
      "name": "Deco_Bone_Full"
    },
    {
      "x": -12,
      "y": 16,
      "z": 4,
      "name": "Deco_Bone_Full"
    },
    {
      "x": -12,
      "y": 17,
      "z": 4,
      "name": "Deco_Bone_Full"
    },
    {
      "x": -12,
      "y": 32,
      "z": 4,
      "name": "Deco_Bone_Full"
    },
    {
      "x": -12,
      "y": 16,
      "z": 5,
      "name": "Deco_Bone_Full"
    },
    {
      "x": -12,
      "y": 15,
      "z": 9,
      "name": "Deco_Bone_Full"
    },
    {
      "x": -12,
      "y": 11,
      "z": 10,
      "name": "Deco_Bone_Full"
    },
    {
      "x": -12,
      "y": 12,
      "z": 10,
      "name": "Deco_Bone_Full"
    },
    {
      "x": -12,
      "y": 13,
      "z": 10,
      "name": "Deco_Bone_Full"
    },
    {
      "x": -12,
      "y": 14,
      "z": 10,
      "name": "Deco_Bone_Full"
    },
    {
      "x": -12,
      "y": 15,
      "z": 10,
      "name": "Deco_Bone_Full"
    },
    {
      "x": -12,
      "y": 16,
      "z": 10,
      "name": "Deco_Bone_Full"
    },
    {
      "x": -12,
      "y": 15,
      "z": 11,
      "name": "Deco_Bone_Full"
    },
    {
      "x": -12,
      "y": 16,
      "z": 11,
      "name": "Deco_Bone_Full"
    },
    {
      "x": -12,
      "y": 17,
      "z": 11,
      "name": "Deco_Bone_Full"
    },
    {
      "x": -12,
      "y": 15,
      "z": 12,
      "name": "Deco_Bone_Full"
    },
    {
      "x": -12,
      "y": 16,
      "z": 12,
      "name": "Deco_Bone_Full"
    },
    {
      "x": -12,
      "y": 17,
      "z": 12,
      "name": "Deco_Bone_Full"
    },
    {
      "x": -12,
      "y": 16,
      "z": 13,
      "name": "Deco_Bone_Full"
    },
    {
      "x": -12,
      "y": 17,
      "z": 13,
      "name": "Deco_Bone_Full"
    },
    {
      "x": -12,
      "y": 20,
      "z": 19,
      "name": "Deco_Bone_Full"
    },
    {
      "x": -12,
      "y": 20,
      "z": 20,
      "name": "Deco_Bone_Full"
    },
    {
      "x": -12,
      "y": 21,
      "z": 20,
      "name": "Deco_Bone_Full"
    },
    {
      "x": -12,
      "y": 22,
      "z": 20,
      "name": "Deco_Bone_Full"
    },
    {
      "x": -12,
      "y": 23,
      "z": 20,
      "name": "Deco_Bone_Full"
    },
    {
      "x": -12,
      "y": 24,
      "z": 20,
      "name": "Deco_Bone_Full"
    },
    {
      "x": -12,
      "y": 25,
      "z": 20,
      "name": "Deco_Bone_Full"
    },
    {
      "x": -12,
      "y": 26,
      "z": 20,
      "name": "Deco_Bone_Full"
    },
    {
      "x": -11,
      "y": 19,
      "z": -3,
      "name": "Deco_Bone_Full"
    },
    {
      "x": -11,
      "y": 20,
      "z": -3,
      "name": "Deco_Bone_Full"
    },
    {
      "x": -11,
      "y": 21,
      "z": -3,
      "name": "Deco_Bone_Full"
    },
    {
      "x": -11,
      "y": 22,
      "z": -3,
      "name": "Deco_Bone_Full"
    },
    {
      "x": -11,
      "y": 16,
      "z": 4,
      "name": "Deco_Bone_Full"
    },
    {
      "x": -11,
      "y": 15,
      "z": 5,
      "name": "Deco_Bone_Full"
    },
    {
      "x": -11,
      "y": 16,
      "z": 5,
      "name": "Deco_Bone_Full"
    },
    {
      "x": -11,
      "y": 32,
      "z": 5,
      "name": "Deco_Bone_Full"
    },
    {
      "x": -11,
      "y": 33,
      "z": 5,
      "name": "Deco_Bone_Full"
    },
    {
      "x": -11,
      "y": 15,
      "z": 6,
      "name": "Deco_Bone_Full"
    },
    {
      "x": -11,
      "y": 16,
      "z": 6,
      "name": "Deco_Bone_Full"
    },
    {
      "x": -11,
      "y": 15,
      "z": 8,
      "name": "Deco_Bone_Full"
    },
    {
      "x": -11,
      "y": 14,
      "z": 9,
      "name": "Deco_Bone_Full"
    },
    {
      "x": -11,
      "y": 15,
      "z": 9,
      "name": "Deco_Bone_Full"
    },
    {
      "x": -11,
      "y": 15,
      "z": 10,
      "name": "Deco_Bone_Full"
    },
    {
      "x": -11,
      "y": 16,
      "z": 11,
      "name": "Deco_Bone_Full"
    },
    {
      "x": -11,
      "y": 16,
      "z": 12,
      "name": "Deco_Bone_Full"
    },
    {
      "x": -11,
      "y": 17,
      "z": 12,
      "name": "Deco_Bone_Full"
    },
    {
      "x": -11,
      "y": 16,
      "z": 13,
      "name": "Deco_Bone_Full"
    },
    {
      "x": -11,
      "y": 17,
      "z": 13,
      "name": "Deco_Bone_Full"
    },
    {
      "x": -11,
      "y": 17,
      "z": 14,
      "name": "Deco_Bone_Full"
    },
    {
      "x": -10,
      "y": 17,
      "z": -2,
      "name": "Deco_Bone_Full"
    },
    {
      "x": -10,
      "y": 18,
      "z": -2,
      "name": "Deco_Bone_Full"
    },
    {
      "x": -10,
      "y": 19,
      "z": -2,
      "name": "Deco_Bone_Full"
    },
    {
      "x": -10,
      "y": 17,
      "z": -1,
      "name": "Deco_Bone_Full"
    },
    {
      "x": -10,
      "y": 15,
      "z": 5,
      "name": "Deco_Bone_Full"
    },
    {
      "x": -10,
      "y": 16,
      "z": 5,
      "name": "Deco_Bone_Full"
    },
    {
      "x": -10,
      "y": 14,
      "z": 6,
      "name": "Deco_Bone_Full"
    },
    {
      "x": -10,
      "y": 15,
      "z": 6,
      "name": "Deco_Bone_Full"
    },
    {
      "x": -10,
      "y": 16,
      "z": 6,
      "name": "Deco_Bone_Full"
    },
    {
      "x": -10,
      "y": 13,
      "z": 7,
      "name": "Deco_Bone_Full"
    },
    {
      "x": -10,
      "y": 14,
      "z": 7,
      "name": "Deco_Bone_Full"
    },
    {
      "x": -10,
      "y": 15,
      "z": 7,
      "name": "Deco_Bone_Full"
    },
    {
      "x": -10,
      "y": 16,
      "z": 7,
      "name": "Deco_Bone_Full"
    },
    {
      "x": -10,
      "y": 12,
      "z": 8,
      "name": "Deco_Bone_Full"
    },
    {
      "x": -10,
      "y": 13,
      "z": 8,
      "name": "Deco_Bone_Full"
    },
    {
      "x": -10,
      "y": 14,
      "z": 8,
      "name": "Deco_Bone_Full"
    },
    {
      "x": -10,
      "y": 15,
      "z": 8,
      "name": "Deco_Bone_Full"
    },
    {
      "x": -10,
      "y": 16,
      "z": 8,
      "name": "Deco_Bone_Full"
    },
    {
      "x": -10,
      "y": 15,
      "z": 9,
      "name": "Deco_Bone_Full"
    },
    {
      "x": -10,
      "y": 17,
      "z": 13,
      "name": "Deco_Bone_Full"
    },
    {
      "x": -10,
      "y": 17,
      "z": 14,
      "name": "Deco_Bone_Full"
    },
    {
      "x": -10,
      "y": 18,
      "z": 14,
      "name": "Deco_Bone_Full"
    },
    {
      "x": -10,
      "y": 18,
      "z": 15,
      "name": "Deco_Bone_Full"
    },
    {
      "x": -9,
      "y": 17,
      "z": -2,
      "name": "Deco_Bone_Full"
    },
    {
      "x": -9,
      "y": 16,
      "z": -1,
      "name": "Deco_Bone_Full"
    },
    {
      "x": -9,
      "y": 17,
      "z": -1,
      "name": "Deco_Bone_Full"
    },
    {
      "x": -9,
      "y": 16,
      "z": 0,
      "name": "Deco_Bone_Full"
    },
    {
      "x": -9,
      "y": 14,
      "z": 5,
      "name": "Deco_Bone_Full"
    },
    {
      "x": -9,
      "y": 15,
      "z": 5,
      "name": "Deco_Bone_Full"
    },
    {
      "x": -9,
      "y": 14,
      "z": 6,
      "name": "Deco_Bone_Full"
    },
    {
      "x": -9,
      "y": 15,
      "z": 6,
      "name": "Deco_Bone_Full"
    },
    {
      "x": -9,
      "y": 16,
      "z": 6,
      "name": "Deco_Bone_Full"
    },
    {
      "x": -9,
      "y": 10,
      "z": 7,
      "name": "Deco_Bone_Full"
    },
    {
      "x": -9,
      "y": 11,
      "z": 7,
      "name": "Deco_Bone_Full"
    },
    {
      "x": -9,
      "y": 12,
      "z": 7,
      "name": "Deco_Bone_Full"
    },
    {
      "x": -9,
      "y": 13,
      "z": 7,
      "name": "Deco_Bone_Full"
    },
    {
      "x": -9,
      "y": 14,
      "z": 7,
      "name": "Deco_Bone_Full"
    },
    {
      "x": -9,
      "y": 15,
      "z": 7,
      "name": "Deco_Bone_Full"
    },
    {
      "x": -9,
      "y": 16,
      "z": 7,
      "name": "Deco_Bone_Full"
    },
    {
      "x": -9,
      "y": 17,
      "z": 7,
      "name": "Deco_Bone_Full"
    },
    {
      "x": -9,
      "y": 13,
      "z": 8,
      "name": "Deco_Bone_Full"
    },
    {
      "x": -9,
      "y": 14,
      "z": 8,
      "name": "Deco_Bone_Full"
    },
    {
      "x": -9,
      "y": 15,
      "z": 8,
      "name": "Deco_Bone_Full"
    },
    {
      "x": -9,
      "y": 16,
      "z": 8,
      "name": "Deco_Bone_Full"
    },
    {
      "x": -9,
      "y": 18,
      "z": 14,
      "name": "Deco_Bone_Full"
    },
    {
      "x": -9,
      "y": 18,
      "z": 15,
      "name": "Deco_Bone_Full"
    },
    {
      "x": -9,
      "y": 19,
      "z": 15,
      "name": "Deco_Bone_Full"
    },
    {
      "x": -9,
      "y": 19,
      "z": 16,
      "name": "Deco_Bone_Full"
    },
    {
      "x": -8,
      "y": 16,
      "z": -1,
      "name": "Deco_Bone_Full"
    },
    {
      "x": -8,
      "y": 15,
      "z": 0,
      "name": "Deco_Bone_Full"
    },
    {
      "x": -8,
      "y": 16,
      "z": 0,
      "name": "Deco_Bone_Full"
    },
    {
      "x": -8,
      "y": 16,
      "z": 1,
      "name": "Deco_Bone_Full"
    },
    {
      "x": -8,
      "y": 15,
      "z": 5,
      "name": "Deco_Bone_Full"
    },
    {
      "x": -8,
      "y": 9,
      "z": 6,
      "name": "Deco_Bone_Full"
    },
    {
      "x": -8,
      "y": 10,
      "z": 6,
      "name": "Deco_Bone_Full"
    },
    {
      "x": -8,
      "y": 11,
      "z": 6,
      "name": "Deco_Bone_Full"
    },
    {
      "x": -8,
      "y": 12,
      "z": 6,
      "name": "Deco_Bone_Full"
    },
    {
      "x": -8,
      "y": 13,
      "z": 6,
      "name": "Deco_Bone_Full"
    },
    {
      "x": -8,
      "y": 14,
      "z": 6,
      "name": "Deco_Bone_Full"
    },
    {
      "x": -8,
      "y": 15,
      "z": 6,
      "name": "Deco_Bone_Full"
    },
    {
      "x": -8,
      "y": 14,
      "z": 7,
      "name": "Deco_Bone_Full"
    },
    {
      "x": -8,
      "y": 15,
      "z": 7,
      "name": "Deco_Bone_Full"
    },
    {
      "x": -8,
      "y": 16,
      "z": 7,
      "name": "Deco_Bone_Full"
    },
    {
      "x": -8,
      "y": 14,
      "z": 8,
      "name": "Deco_Bone_Full"
    },
    {
      "x": -8,
      "y": 15,
      "z": 8,
      "name": "Deco_Bone_Full"
    },
    {
      "x": -8,
      "y": 16,
      "z": 8,
      "name": "Deco_Bone_Full"
    },
    {
      "x": -8,
      "y": 15,
      "z": 9,
      "name": "Deco_Bone_Full"
    },
    {
      "x": -8,
      "y": 16,
      "z": 9,
      "name": "Deco_Bone_Full"
    },
    {
      "x": -8,
      "y": 19,
      "z": 15,
      "name": "Deco_Bone_Full"
    },
    {
      "x": -8,
      "y": 19,
      "z": 16,
      "name": "Deco_Bone_Full"
    },
    {
      "x": -8,
      "y": 20,
      "z": 16,
      "name": "Deco_Bone_Full"
    },
    {
      "x": -8,
      "y": 21,
      "z": 16,
      "name": "Deco_Bone_Full"
    },
    {
      "x": -7,
      "y": 16,
      "z": 0,
      "name": "Deco_Bone_Full"
    },
    {
      "x": -7,
      "y": 15,
      "z": 1,
      "name": "Deco_Bone_Full"
    },
    {
      "x": -7,
      "y": 14,
      "z": 2,
      "name": "Deco_Bone_Full"
    },
    {
      "x": -7,
      "y": 15,
      "z": 2,
      "name": "Deco_Bone_Full"
    },
    {
      "x": -7,
      "y": 14,
      "z": 4,
      "name": "Deco_Bone_Full"
    },
    {
      "x": -7,
      "y": 14,
      "z": 5,
      "name": "Deco_Bone_Full"
    },
    {
      "x": -7,
      "y": 15,
      "z": 5,
      "name": "Deco_Bone_Full"
    },
    {
      "x": -7,
      "y": 15,
      "z": 6,
      "name": "Deco_Bone_Full"
    },
    {
      "x": -7,
      "y": 14,
      "z": 7,
      "name": "Deco_Bone_Full"
    },
    {
      "x": -7,
      "y": 15,
      "z": 7,
      "name": "Deco_Bone_Full"
    },
    {
      "x": -7,
      "y": 15,
      "z": 8,
      "name": "Deco_Bone_Full"
    },
    {
      "x": -7,
      "y": 16,
      "z": 8,
      "name": "Deco_Bone_Full"
    },
    {
      "x": -7,
      "y": 15,
      "z": 9,
      "name": "Deco_Bone_Full"
    },
    {
      "x": -7,
      "y": 16,
      "z": 9,
      "name": "Deco_Bone_Full"
    },
    {
      "x": -7,
      "y": 16,
      "z": 10,
      "name": "Deco_Bone_Full"
    },
    {
      "x": -7,
      "y": 21,
      "z": 17,
      "name": "Deco_Bone_Full"
    },
    {
      "x": -7,
      "y": 22,
      "z": 17,
      "name": "Deco_Bone_Full"
    },
    {
      "x": -7,
      "y": 23,
      "z": 17,
      "name": "Deco_Bone_Full"
    },
    {
      "x": -7,
      "y": 24,
      "z": 17,
      "name": "Deco_Bone_Full"
    },
    {
      "x": -7,
      "y": 25,
      "z": 17,
      "name": "Deco_Bone_Full"
    },
    {
      "x": -6,
      "y": 19,
      "z": -8,
      "name": "Deco_Bone_Full"
    },
    {
      "x": -6,
      "y": 20,
      "z": -8,
      "name": "Deco_Bone_Full"
    },
    {
      "x": -6,
      "y": 21,
      "z": -8,
      "name": "Deco_Bone_Full"
    },
    {
      "x": -6,
      "y": 22,
      "z": -8,
      "name": "Deco_Bone_Full"
    },
    {
      "x": -6,
      "y": 23,
      "z": -8,
      "name": "Deco_Bone_Full"
    },
    {
      "x": -6,
      "y": 24,
      "z": -8,
      "name": "Deco_Bone_Full"
    },
    {
      "x": -6,
      "y": 25,
      "z": -8,
      "name": "Deco_Bone_Full"
    },
    {
      "x": -6,
      "y": 14,
      "z": 1,
      "name": "Deco_Bone_Full"
    },
    {
      "x": -6,
      "y": 15,
      "z": 1,
      "name": "Deco_Bone_Full"
    },
    {
      "x": -6,
      "y": 14,
      "z": 2,
      "name": "Deco_Bone_Full"
    },
    {
      "x": -6,
      "y": 15,
      "z": 2,
      "name": "Deco_Bone_Full"
    },
    {
      "x": -6,
      "y": 12,
      "z": 3,
      "name": "Deco_Bone_Full"
    },
    {
      "x": -6,
      "y": 13,
      "z": 3,
      "name": "Deco_Bone_Full"
    },
    {
      "x": -6,
      "y": 14,
      "z": 3,
      "name": "Deco_Bone_Full"
    },
    {
      "x": -6,
      "y": 15,
      "z": 3,
      "name": "Deco_Bone_Full"
    },
    {
      "x": -6,
      "y": 11,
      "z": 4,
      "name": "Deco_Bone_Full"
    },
    {
      "x": -6,
      "y": 12,
      "z": 4,
      "name": "Deco_Bone_Full"
    },
    {
      "x": -6,
      "y": 13,
      "z": 4,
      "name": "Deco_Bone_Full"
    },
    {
      "x": -6,
      "y": 14,
      "z": 4,
      "name": "Deco_Bone_Full"
    },
    {
      "x": -6,
      "y": 15,
      "z": 4,
      "name": "Deco_Bone_Full"
    },
    {
      "x": -6,
      "y": 14,
      "z": 5,
      "name": "Deco_Bone_Full"
    },
    {
      "x": -6,
      "y": 16,
      "z": 9,
      "name": "Deco_Bone_Full"
    },
    {
      "x": -6,
      "y": 16,
      "z": 10,
      "name": "Deco_Bone_Full"
    },
    {
      "x": -6,
      "y": 17,
      "z": 10,
      "name": "Deco_Bone_Full"
    },
    {
      "x": -6,
      "y": 17,
      "z": 11,
      "name": "Deco_Bone_Full"
    },
    {
      "x": -5,
      "y": 17,
      "z": -7,
      "name": "Deco_Bone_Full"
    },
    {
      "x": -5,
      "y": 18,
      "z": -7,
      "name": "Deco_Bone_Full"
    },
    {
      "x": -5,
      "y": 19,
      "z": -7,
      "name": "Deco_Bone_Full"
    },
    {
      "x": -5,
      "y": 25,
      "z": -7,
      "name": "Deco_Bone_Full"
    },
    {
      "x": -5,
      "y": 26,
      "z": -7,
      "name": "Deco_Bone_Full"
    },
    {
      "x": -5,
      "y": 27,
      "z": -7,
      "name": "Deco_Bone_Full"
    },
    {
      "x": -5,
      "y": 17,
      "z": -6,
      "name": "Deco_Bone_Full"
    },
    {
      "x": -5,
      "y": 14,
      "z": 1,
      "name": "Deco_Bone_Full"
    },
    {
      "x": -5,
      "y": 13,
      "z": 2,
      "name": "Deco_Bone_Full"
    },
    {
      "x": -5,
      "y": 14,
      "z": 2,
      "name": "Deco_Bone_Full"
    },
    {
      "x": -5,
      "y": 15,
      "z": 2,
      "name": "Deco_Bone_Full"
    },
    {
      "x": -5,
      "y": 9,
      "z": 3,
      "name": "Deco_Bone_Full"
    },
    {
      "x": -5,
      "y": 10,
      "z": 3,
      "name": "Deco_Bone_Full"
    },
    {
      "x": -5,
      "y": 11,
      "z": 3,
      "name": "Deco_Bone_Full"
    },
    {
      "x": -5,
      "y": 12,
      "z": 3,
      "name": "Deco_Bone_Full"
    },
    {
      "x": -5,
      "y": 13,
      "z": 3,
      "name": "Deco_Bone_Full"
    },
    {
      "x": -5,
      "y": 14,
      "z": 3,
      "name": "Deco_Bone_Full"
    },
    {
      "x": -5,
      "y": 15,
      "z": 3,
      "name": "Deco_Bone_Full"
    },
    {
      "x": -5,
      "y": 16,
      "z": 3,
      "name": "Deco_Bone_Full"
    },
    {
      "x": -5,
      "y": 12,
      "z": 4,
      "name": "Deco_Bone_Full"
    },
    {
      "x": -5,
      "y": 13,
      "z": 4,
      "name": "Deco_Bone_Full"
    },
    {
      "x": -5,
      "y": 14,
      "z": 4,
      "name": "Deco_Bone_Full"
    },
    {
      "x": -5,
      "y": 15,
      "z": 4,
      "name": "Deco_Bone_Full"
    },
    {
      "x": -5,
      "y": 17,
      "z": 10,
      "name": "Deco_Bone_Full"
    },
    {
      "x": -5,
      "y": 17,
      "z": 11,
      "name": "Deco_Bone_Full"
    },
    {
      "x": -5,
      "y": 18,
      "z": 11,
      "name": "Deco_Bone_Full"
    },
    {
      "x": -5,
      "y": 18,
      "z": 12,
      "name": "Deco_Bone_Full"
    },
    {
      "x": -4,
      "y": 17,
      "z": -7,
      "name": "Deco_Bone_Full"
    },
    {
      "x": -4,
      "y": 16,
      "z": -6,
      "name": "Deco_Bone_Full"
    },
    {
      "x": -4,
      "y": 17,
      "z": -6,
      "name": "Deco_Bone_Full"
    },
    {
      "x": -4,
      "y": 27,
      "z": -6,
      "name": "Deco_Bone_Full"
    },
    {
      "x": -4,
      "y": 28,
      "z": -6,
      "name": "Deco_Bone_Full"
    },
    {
      "x": -4,
      "y": 29,
      "z": -6,
      "name": "Deco_Bone_Full"
    },
    {
      "x": -4,
      "y": 17,
      "z": -5,
      "name": "Deco_Bone_Full"
    },
    {
      "x": -4,
      "y": 14,
      "z": 1,
      "name": "Deco_Bone_Full"
    },
    {
      "x": -4,
      "y": 8,
      "z": 2,
      "name": "Deco_Bone_Full"
    },
    {
      "x": -4,
      "y": 9,
      "z": 2,
      "name": "Deco_Bone_Full"
    },
    {
      "x": -4,
      "y": 10,
      "z": 2,
      "name": "Deco_Bone_Full"
    },
    {
      "x": -4,
      "y": 11,
      "z": 2,
      "name": "Deco_Bone_Full"
    },
    {
      "x": -4,
      "y": 12,
      "z": 2,
      "name": "Deco_Bone_Full"
    },
    {
      "x": -4,
      "y": 13,
      "z": 2,
      "name": "Deco_Bone_Full"
    },
    {
      "x": -4,
      "y": 14,
      "z": 2,
      "name": "Deco_Bone_Full"
    },
    {
      "x": -4,
      "y": 13,
      "z": 3,
      "name": "Deco_Bone_Full"
    },
    {
      "x": -4,
      "y": 14,
      "z": 3,
      "name": "Deco_Bone_Full"
    },
    {
      "x": -4,
      "y": 15,
      "z": 3,
      "name": "Deco_Bone_Full"
    },
    {
      "x": -4,
      "y": 14,
      "z": 4,
      "name": "Deco_Bone_Full"
    },
    {
      "x": -4,
      "y": 15,
      "z": 4,
      "name": "Deco_Bone_Full"
    },
    {
      "x": -4,
      "y": 14,
      "z": 5,
      "name": "Deco_Bone_Full"
    },
    {
      "x": -4,
      "y": 15,
      "z": 5,
      "name": "Deco_Bone_Full"
    },
    {
      "x": -4,
      "y": 18,
      "z": 11,
      "name": "Deco_Bone_Full"
    },
    {
      "x": -4,
      "y": 18,
      "z": 12,
      "name": "Deco_Bone_Full"
    },
    {
      "x": -4,
      "y": 19,
      "z": 12,
      "name": "Deco_Bone_Full"
    },
    {
      "x": -4,
      "y": 20,
      "z": 12,
      "name": "Deco_Bone_Full"
    },
    {
      "x": -3,
      "y": 17,
      "z": -6,
      "name": "Deco_Bone_Full"
    },
    {
      "x": -3,
      "y": 15,
      "z": -5,
      "name": "Deco_Bone_Full"
    },
    {
      "x": -3,
      "y": 16,
      "z": -5,
      "name": "Deco_Bone_Full"
    },
    {
      "x": -3,
      "y": 29,
      "z": -5,
      "name": "Deco_Bone_Full"
    },
    {
      "x": -3,
      "y": 16,
      "z": -4,
      "name": "Deco_Bone_Full"
    },
    {
      "x": -3,
      "y": 14,
      "z": 0,
      "name": "Deco_Bone_Full"
    },
    {
      "x": -3,
      "y": 13,
      "z": 1,
      "name": "Deco_Bone_Full"
    },
    {
      "x": -3,
      "y": 14,
      "z": 1,
      "name": "Deco_Bone_Full"
    },
    {
      "x": -3,
      "y": 14,
      "z": 2,
      "name": "Deco_Bone_Full"
    },
    {
      "x": -3,
      "y": 14,
      "z": 3,
      "name": "Deco_Bone_Full"
    },
    {
      "x": -3,
      "y": 14,
      "z": 4,
      "name": "Deco_Bone_Full"
    },
    {
      "x": -3,
      "y": 15,
      "z": 4,
      "name": "Deco_Bone_Full"
    },
    {
      "x": -3,
      "y": 15,
      "z": 5,
      "name": "Deco_Bone_Full"
    },
    {
      "x": -3,
      "y": 31,
      "z": 5,
      "name": "Deco_Bone_Full"
    },
    {
      "x": -3,
      "y": 32,
      "z": 5,
      "name": "Deco_Bone_Full"
    },
    {
      "x": -3,
      "y": 16,
      "z": 6,
      "name": "Deco_Bone_Full"
    },
    {
      "x": -3,
      "y": 20,
      "z": 13,
      "name": "Deco_Bone_Full"
    },
    {
      "x": -3,
      "y": 21,
      "z": 13,
      "name": "Deco_Bone_Full"
    },
    {
      "x": -3,
      "y": 22,
      "z": 13,
      "name": "Deco_Bone_Full"
    },
    {
      "x": -3,
      "y": 23,
      "z": 13,
      "name": "Deco_Bone_Full"
    },
    {
      "x": -3,
      "y": 24,
      "z": 13,
      "name": "Deco_Bone_Full"
    },
    {
      "x": -3,
      "y": 25,
      "z": 13,
      "name": "Deco_Bone_Full"
    },
    {
      "x": -3,
      "y": 26,
      "z": 13,
      "name": "Deco_Bone_Full"
    },
    {
      "x": -3,
      "y": 27,
      "z": 13,
      "name": "Deco_Bone_Full"
    },
    {
      "x": -2,
      "y": 16,
      "z": -5,
      "name": "Deco_Bone_Full"
    },
    {
      "x": -2,
      "y": 15,
      "z": -4,
      "name": "Deco_Bone_Full"
    },
    {
      "x": -2,
      "y": 29,
      "z": -4,
      "name": "Deco_Bone_Full"
    },
    {
      "x": -2,
      "y": 30,
      "z": -4,
      "name": "Deco_Bone_Full"
    },
    {
      "x": -2,
      "y": 14,
      "z": -3,
      "name": "Deco_Bone_Full"
    },
    {
      "x": -2,
      "y": 15,
      "z": -3,
      "name": "Deco_Bone_Full"
    },
    {
      "x": -2,
      "y": 14,
      "z": -1,
      "name": "Deco_Bone_Full"
    },
    {
      "x": -2,
      "y": 12,
      "z": 0,
      "name": "Deco_Bone_Full"
    },
    {
      "x": -2,
      "y": 13,
      "z": 0,
      "name": "Deco_Bone_Full"
    },
    {
      "x": -2,
      "y": 14,
      "z": 0,
      "name": "Deco_Bone_Full"
    },
    {
      "x": -2,
      "y": 14,
      "z": 1,
      "name": "Deco_Bone_Full"
    },
    {
      "x": -2,
      "y": 16,
      "z": 5,
      "name": "Deco_Bone_Full"
    },
    {
      "x": -2,
      "y": 15,
      "z": 6,
      "name": "Deco_Bone_Full"
    },
    {
      "x": -2,
      "y": 16,
      "z": 6,
      "name": "Deco_Bone_Full"
    },
    {
      "x": -2,
      "y": 31,
      "z": 6,
      "name": "Deco_Bone_Full"
    },
    {
      "x": -2,
      "y": 16,
      "z": 7,
      "name": "Deco_Bone_Full"
    },
    {
      "x": -1,
      "y": 14,
      "z": -4,
      "name": "Deco_Bone_Full"
    },
    {
      "x": -1,
      "y": 15,
      "z": -4,
      "name": "Deco_Bone_Full"
    },
    {
      "x": -1,
      "y": 14,
      "z": -3,
      "name": "Deco_Bone_Full"
    },
    {
      "x": -1,
      "y": 15,
      "z": -3,
      "name": "Deco_Bone_Full"
    },
    {
      "x": -1,
      "y": 12,
      "z": -2,
      "name": "Deco_Bone_Full"
    },
    {
      "x": -1,
      "y": 13,
      "z": -2,
      "name": "Deco_Bone_Full"
    },
    {
      "x": -1,
      "y": 14,
      "z": -2,
      "name": "Deco_Bone_Full"
    },
    {
      "x": -1,
      "y": 15,
      "z": -2,
      "name": "Deco_Bone_Full"
    },
    {
      "x": -1,
      "y": 11,
      "z": -1,
      "name": "Deco_Bone_Full"
    },
    {
      "x": -1,
      "y": 12,
      "z": -1,
      "name": "Deco_Bone_Full"
    },
    {
      "x": -1,
      "y": 13,
      "z": -1,
      "name": "Deco_Bone_Full"
    },
    {
      "x": -1,
      "y": 14,
      "z": -1,
      "name": "Deco_Bone_Full"
    },
    {
      "x": -1,
      "y": 15,
      "z": -1,
      "name": "Deco_Bone_Full"
    },
    {
      "x": -1,
      "y": 14,
      "z": 0,
      "name": "Deco_Bone_Full"
    },
    {
      "x": -1,
      "y": 16,
      "z": 6,
      "name": "Deco_Bone_Full"
    },
    {
      "x": -1,
      "y": 16,
      "z": 7,
      "name": "Deco_Bone_Full"
    },
    {
      "x": -1,
      "y": 17,
      "z": 7,
      "name": "Deco_Bone_Full"
    },
    {
      "x": -1,
      "y": 30,
      "z": 7,
      "name": "Deco_Bone_Full"
    },
    {
      "x": -1,
      "y": 31,
      "z": 7,
      "name": "Deco_Bone_Full"
    },
    {
      "x": -1,
      "y": 17,
      "z": 8,
      "name": "Deco_Bone_Full"
    },
    {
      "x": 0,
      "y": 14,
      "z": -4,
      "name": "Deco_Bone_Full"
    },
    {
      "x": 0,
      "y": 13,
      "z": -3,
      "name": "Deco_Bone_Full"
    },
    {
      "x": 0,
      "y": 14,
      "z": -3,
      "name": "Deco_Bone_Full"
    },
    {
      "x": 0,
      "y": 15,
      "z": -3,
      "name": "Deco_Bone_Full"
    },
    {
      "x": 0,
      "y": 9,
      "z": -2,
      "name": "Deco_Bone_Full"
    },
    {
      "x": 0,
      "y": 10,
      "z": -2,
      "name": "Deco_Bone_Full"
    },
    {
      "x": 0,
      "y": 11,
      "z": -2,
      "name": "Deco_Bone_Full"
    },
    {
      "x": 0,
      "y": 12,
      "z": -2,
      "name": "Deco_Bone_Full"
    },
    {
      "x": 0,
      "y": 13,
      "z": -2,
      "name": "Deco_Bone_Full"
    },
    {
      "x": 0,
      "y": 14,
      "z": -2,
      "name": "Deco_Bone_Full"
    },
    {
      "x": 0,
      "y": 15,
      "z": -2,
      "name": "Deco_Bone_Full"
    },
    {
      "x": 0,
      "y": 16,
      "z": -2,
      "name": "Deco_Bone_Full"
    },
    {
      "x": 0,
      "y": 12,
      "z": -1,
      "name": "Deco_Bone_Full"
    },
    {
      "x": 0,
      "y": 13,
      "z": -1,
      "name": "Deco_Bone_Full"
    },
    {
      "x": 0,
      "y": 14,
      "z": -1,
      "name": "Deco_Bone_Full"
    },
    {
      "x": 0,
      "y": 15,
      "z": -1,
      "name": "Deco_Bone_Full"
    },
    {
      "x": 0,
      "y": 17,
      "z": 7,
      "name": "Deco_Bone_Full"
    },
    {
      "x": 0,
      "y": 17,
      "z": 8,
      "name": "Deco_Bone_Full"
    },
    {
      "x": 0,
      "y": 18,
      "z": 8,
      "name": "Deco_Bone_Full"
    },
    {
      "x": 0,
      "y": 19,
      "z": 8,
      "name": "Deco_Bone_Full"
    },
    {
      "x": 0,
      "y": 28,
      "z": 8,
      "name": "Deco_Bone_Full"
    },
    {
      "x": 0,
      "y": 29,
      "z": 8,
      "name": "Deco_Bone_Full"
    },
    {
      "x": 0,
      "y": 30,
      "z": 8,
      "name": "Deco_Bone_Full"
    },
    {
      "x": 1,
      "y": 17,
      "z": -11,
      "name": "Deco_Bone_Full"
    },
    {
      "x": 1,
      "y": 18,
      "z": -11,
      "name": "Deco_Bone_Full"
    },
    {
      "x": 1,
      "y": 19,
      "z": -11,
      "name": "Deco_Bone_Full"
    },
    {
      "x": 1,
      "y": 20,
      "z": -11,
      "name": "Deco_Bone_Full"
    },
    {
      "x": 1,
      "y": 17,
      "z": -10,
      "name": "Deco_Bone_Full"
    },
    {
      "x": 1,
      "y": 14,
      "z": -4,
      "name": "Deco_Bone_Full"
    },
    {
      "x": 1,
      "y": 8,
      "z": -3,
      "name": "Deco_Bone_Full"
    },
    {
      "x": 1,
      "y": 9,
      "z": -3,
      "name": "Deco_Bone_Full"
    },
    {
      "x": 1,
      "y": 10,
      "z": -3,
      "name": "Deco_Bone_Full"
    },
    {
      "x": 1,
      "y": 11,
      "z": -3,
      "name": "Deco_Bone_Full"
    },
    {
      "x": 1,
      "y": 12,
      "z": -3,
      "name": "Deco_Bone_Full"
    },
    {
      "x": 1,
      "y": 13,
      "z": -3,
      "name": "Deco_Bone_Full"
    },
    {
      "x": 1,
      "y": 14,
      "z": -3,
      "name": "Deco_Bone_Full"
    },
    {
      "x": 1,
      "y": 13,
      "z": -2,
      "name": "Deco_Bone_Full"
    },
    {
      "x": 1,
      "y": 14,
      "z": -2,
      "name": "Deco_Bone_Full"
    },
    {
      "x": 1,
      "y": 15,
      "z": -2,
      "name": "Deco_Bone_Full"
    },
    {
      "x": 1,
      "y": 14,
      "z": -1,
      "name": "Deco_Bone_Full"
    },
    {
      "x": 1,
      "y": 15,
      "z": -1,
      "name": "Deco_Bone_Full"
    },
    {
      "x": 1,
      "y": 14,
      "z": 0,
      "name": "Deco_Bone_Full"
    },
    {
      "x": 1,
      "y": 15,
      "z": 0,
      "name": "Deco_Bone_Full"
    },
    {
      "x": 1,
      "y": 19,
      "z": 9,
      "name": "Deco_Bone_Full"
    },
    {
      "x": 1,
      "y": 20,
      "z": 9,
      "name": "Deco_Bone_Full"
    },
    {
      "x": 1,
      "y": 21,
      "z": 9,
      "name": "Deco_Bone_Full"
    },
    {
      "x": 1,
      "y": 22,
      "z": 9,
      "name": "Deco_Bone_Full"
    },
    {
      "x": 1,
      "y": 23,
      "z": 9,
      "name": "Deco_Bone_Full"
    },
    {
      "x": 1,
      "y": 24,
      "z": 9,
      "name": "Deco_Bone_Full"
    },
    {
      "x": 1,
      "y": 25,
      "z": 9,
      "name": "Deco_Bone_Full"
    },
    {
      "x": 1,
      "y": 26,
      "z": 9,
      "name": "Deco_Bone_Full"
    },
    {
      "x": 1,
      "y": 27,
      "z": 9,
      "name": "Deco_Bone_Full"
    },
    {
      "x": 1,
      "y": 28,
      "z": 9,
      "name": "Deco_Bone_Full"
    },
    {
      "x": 2,
      "y": 17,
      "z": -11,
      "name": "Deco_Bone_Full"
    },
    {
      "x": 2,
      "y": 15,
      "z": -10,
      "name": "Deco_Bone_Full"
    },
    {
      "x": 2,
      "y": 16,
      "z": -10,
      "name": "Deco_Bone_Full"
    },
    {
      "x": 2,
      "y": 17,
      "z": -10,
      "name": "Deco_Bone_Full"
    },
    {
      "x": 2,
      "y": 16,
      "z": -9,
      "name": "Deco_Bone_Full"
    },
    {
      "x": 2,
      "y": 14,
      "z": -5,
      "name": "Deco_Bone_Full"
    },
    {
      "x": 2,
      "y": 13,
      "z": -4,
      "name": "Deco_Bone_Full"
    },
    {
      "x": 2,
      "y": 14,
      "z": -4,
      "name": "Deco_Bone_Full"
    },
    {
      "x": 2,
      "y": 14,
      "z": -3,
      "name": "Deco_Bone_Full"
    },
    {
      "x": 2,
      "y": 14,
      "z": -2,
      "name": "Deco_Bone_Full"
    },
    {
      "x": 2,
      "y": 14,
      "z": -1,
      "name": "Deco_Bone_Full"
    },
    {
      "x": 2,
      "y": 15,
      "z": -1,
      "name": "Deco_Bone_Full"
    },
    {
      "x": 2,
      "y": 15,
      "z": 0,
      "name": "Deco_Bone_Full"
    },
    {
      "x": 2,
      "y": 16,
      "z": 1,
      "name": "Deco_Bone_Full"
    },
    {
      "x": 3,
      "y": 16,
      "z": -10,
      "name": "Deco_Bone_Full"
    },
    {
      "x": 3,
      "y": 14,
      "z": -9,
      "name": "Deco_Bone_Full"
    },
    {
      "x": 3,
      "y": 15,
      "z": -9,
      "name": "Deco_Bone_Full"
    },
    {
      "x": 3,
      "y": 16,
      "z": -9,
      "name": "Deco_Bone_Full"
    },
    {
      "x": 3,
      "y": 14,
      "z": -8,
      "name": "Deco_Bone_Full"
    },
    {
      "x": 3,
      "y": 15,
      "z": -8,
      "name": "Deco_Bone_Full"
    },
    {
      "x": 3,
      "y": 14,
      "z": -6,
      "name": "Deco_Bone_Full"
    },
    {
      "x": 3,
      "y": 13,
      "z": -5,
      "name": "Deco_Bone_Full"
    },
    {
      "x": 3,
      "y": 14,
      "z": -5,
      "name": "Deco_Bone_Full"
    },
    {
      "x": 3,
      "y": 14,
      "z": -4,
      "name": "Deco_Bone_Full"
    },
    {
      "x": 3,
      "y": 16,
      "z": 0,
      "name": "Deco_Bone_Full"
    },
    {
      "x": 3,
      "y": 15,
      "z": 1,
      "name": "Deco_Bone_Full"
    },
    {
      "x": 3,
      "y": 16,
      "z": 1,
      "name": "Deco_Bone_Full"
    },
    {
      "x": 3,
      "y": 17,
      "z": 2,
      "name": "Deco_Bone_Full"
    },
    {
      "x": 4,
      "y": 14,
      "z": -9,
      "name": "Deco_Bone_Full"
    },
    {
      "x": 4,
      "y": 15,
      "z": -9,
      "name": "Deco_Bone_Full"
    },
    {
      "x": 4,
      "y": 14,
      "z": -8,
      "name": "Deco_Bone_Full"
    },
    {
      "x": 4,
      "y": 15,
      "z": -8,
      "name": "Deco_Bone_Full"
    },
    {
      "x": 4,
      "y": 12,
      "z": -7,
      "name": "Deco_Bone_Full"
    },
    {
      "x": 4,
      "y": 13,
      "z": -7,
      "name": "Deco_Bone_Full"
    },
    {
      "x": 4,
      "y": 14,
      "z": -7,
      "name": "Deco_Bone_Full"
    },
    {
      "x": 4,
      "y": 15,
      "z": -7,
      "name": "Deco_Bone_Full"
    },
    {
      "x": 4,
      "y": 11,
      "z": -6,
      "name": "Deco_Bone_Full"
    },
    {
      "x": 4,
      "y": 12,
      "z": -6,
      "name": "Deco_Bone_Full"
    },
    {
      "x": 4,
      "y": 13,
      "z": -6,
      "name": "Deco_Bone_Full"
    },
    {
      "x": 4,
      "y": 14,
      "z": -6,
      "name": "Deco_Bone_Full"
    },
    {
      "x": 4,
      "y": 15,
      "z": -6,
      "name": "Deco_Bone_Full"
    },
    {
      "x": 4,
      "y": 14,
      "z": -5,
      "name": "Deco_Bone_Full"
    },
    {
      "x": 4,
      "y": 17,
      "z": 1,
      "name": "Deco_Bone_Full"
    },
    {
      "x": 4,
      "y": 16,
      "z": 2,
      "name": "Deco_Bone_Full"
    },
    {
      "x": 4,
      "y": 17,
      "z": 2,
      "name": "Deco_Bone_Full"
    },
    {
      "x": 4,
      "y": 17,
      "z": 3,
      "name": "Deco_Bone_Full"
    },
    {
      "x": 5,
      "y": 14,
      "z": -9,
      "name": "Deco_Bone_Full"
    },
    {
      "x": 5,
      "y": 13,
      "z": -8,
      "name": "Deco_Bone_Full"
    },
    {
      "x": 5,
      "y": 14,
      "z": -8,
      "name": "Deco_Bone_Full"
    },
    {
      "x": 5,
      "y": 15,
      "z": -8,
      "name": "Deco_Bone_Full"
    },
    {
      "x": 5,
      "y": 9,
      "z": -7,
      "name": "Deco_Bone_Full"
    },
    {
      "x": 5,
      "y": 10,
      "z": -7,
      "name": "Deco_Bone_Full"
    },
    {
      "x": 5,
      "y": 11,
      "z": -7,
      "name": "Deco_Bone_Full"
    },
    {
      "x": 5,
      "y": 12,
      "z": -7,
      "name": "Deco_Bone_Full"
    },
    {
      "x": 5,
      "y": 13,
      "z": -7,
      "name": "Deco_Bone_Full"
    },
    {
      "x": 5,
      "y": 14,
      "z": -7,
      "name": "Deco_Bone_Full"
    },
    {
      "x": 5,
      "y": 15,
      "z": -7,
      "name": "Deco_Bone_Full"
    },
    {
      "x": 5,
      "y": 16,
      "z": -7,
      "name": "Deco_Bone_Full"
    },
    {
      "x": 5,
      "y": 12,
      "z": -6,
      "name": "Deco_Bone_Full"
    },
    {
      "x": 5,
      "y": 13,
      "z": -6,
      "name": "Deco_Bone_Full"
    },
    {
      "x": 5,
      "y": 14,
      "z": -6,
      "name": "Deco_Bone_Full"
    },
    {
      "x": 5,
      "y": 15,
      "z": -6,
      "name": "Deco_Bone_Full"
    },
    {
      "x": 5,
      "y": 17,
      "z": 2,
      "name": "Deco_Bone_Full"
    },
    {
      "x": 5,
      "y": 17,
      "z": 3,
      "name": "Deco_Bone_Full"
    },
    {
      "x": 5,
      "y": 18,
      "z": 3,
      "name": "Deco_Bone_Full"
    },
    {
      "x": 5,
      "y": 19,
      "z": 3,
      "name": "Deco_Bone_Full"
    },
    {
      "x": 6,
      "y": 14,
      "z": -9,
      "name": "Deco_Bone_Full"
    },
    {
      "x": 6,
      "y": 8,
      "z": -8,
      "name": "Deco_Bone_Full"
    },
    {
      "x": 6,
      "y": 9,
      "z": -8,
      "name": "Deco_Bone_Full"
    },
    {
      "x": 6,
      "y": 10,
      "z": -8,
      "name": "Deco_Bone_Full"
    },
    {
      "x": 6,
      "y": 11,
      "z": -8,
      "name": "Deco_Bone_Full"
    },
    {
      "x": 6,
      "y": 12,
      "z": -8,
      "name": "Deco_Bone_Full"
    },
    {
      "x": 6,
      "y": 13,
      "z": -8,
      "name": "Deco_Bone_Full"
    },
    {
      "x": 6,
      "y": 14,
      "z": -8,
      "name": "Deco_Bone_Full"
    },
    {
      "x": 6,
      "y": 13,
      "z": -7,
      "name": "Deco_Bone_Full"
    },
    {
      "x": 6,
      "y": 14,
      "z": -7,
      "name": "Deco_Bone_Full"
    },
    {
      "x": 6,
      "y": 15,
      "z": -7,
      "name": "Deco_Bone_Full"
    },
    {
      "x": 6,
      "y": 14,
      "z": -6,
      "name": "Deco_Bone_Full"
    },
    {
      "x": 6,
      "y": 15,
      "z": -6,
      "name": "Deco_Bone_Full"
    },
    {
      "x": 6,
      "y": 14,
      "z": -5,
      "name": "Deco_Bone_Full"
    },
    {
      "x": 6,
      "y": 15,
      "z": -5,
      "name": "Deco_Bone_Full"
    },
    {
      "x": 6,
      "y": 19,
      "z": 4,
      "name": "Deco_Bone_Full"
    },
    {
      "x": 6,
      "y": 20,
      "z": 4,
      "name": "Deco_Bone_Full"
    },
    {
      "x": 6,
      "y": 21,
      "z": 4,
      "name": "Deco_Bone_Full"
    },
    {
      "x": 7,
      "y": 17,
      "z": -15,
      "name": "Deco_Bone_Full"
    },
    {
      "x": 7,
      "y": 18,
      "z": -15,
      "name": "Deco_Bone_Full"
    },
    {
      "x": 7,
      "y": 19,
      "z": -15,
      "name": "Deco_Bone_Full"
    },
    {
      "x": 7,
      "y": 17,
      "z": -14,
      "name": "Deco_Bone_Full"
    },
    {
      "x": 7,
      "y": 14,
      "z": -10,
      "name": "Deco_Bone_Full"
    },
    {
      "x": 7,
      "y": 13,
      "z": -9,
      "name": "Deco_Bone_Full"
    },
    {
      "x": 7,
      "y": 14,
      "z": -9,
      "name": "Deco_Bone_Full"
    },
    {
      "x": 7,
      "y": 14,
      "z": -8,
      "name": "Deco_Bone_Full"
    },
    {
      "x": 7,
      "y": 14,
      "z": -7,
      "name": "Deco_Bone_Full"
    },
    {
      "x": 7,
      "y": 14,
      "z": -6,
      "name": "Deco_Bone_Full"
    },
    {
      "x": 7,
      "y": 15,
      "z": -6,
      "name": "Deco_Bone_Full"
    },
    {
      "x": 7,
      "y": 14,
      "z": -5,
      "name": "Deco_Bone_Full"
    },
    {
      "x": 7,
      "y": 15,
      "z": -5,
      "name": "Deco_Bone_Full"
    },
    {
      "x": 7,
      "y": 16,
      "z": -5,
      "name": "Deco_Bone_Full"
    },
    {
      "x": 7,
      "y": 25,
      "z": -5,
      "name": "Deco_Bone_Full"
    },
    {
      "x": 7,
      "y": 26,
      "z": -5,
      "name": "Deco_Bone_Full"
    },
    {
      "x": 7,
      "y": 16,
      "z": -4,
      "name": "Deco_Bone_Full"
    },
    {
      "x": 7,
      "y": 21,
      "z": -3,
      "name": "Empty"
    },
    {
      "x": 7,
      "y": 22,
      "z": -3,
      "name": "Empty"
    },
    {
      "x": 8,
      "y": 17,
      "z": -15,
      "name": "Deco_Bone_Full"
    },
    {
      "x": 8,
      "y": 16,
      "z": -14,
      "name": "Deco_Bone_Full"
    },
    {
      "x": 8,
      "y": 17,
      "z": -14,
      "name": "Deco_Bone_Full"
    },
    {
      "x": 8,
      "y": 15,
      "z": -13,
      "name": "Deco_Bone_Full"
    },
    {
      "x": 8,
      "y": 16,
      "z": -13,
      "name": "Deco_Bone_Full"
    },
    {
      "x": 8,
      "y": 15,
      "z": -11,
      "name": "Deco_Bone_Full"
    },
    {
      "x": 8,
      "y": 14,
      "z": -10,
      "name": "Deco_Bone_Full"
    },
    {
      "x": 8,
      "y": 15,
      "z": -10,
      "name": "Deco_Bone_Full"
    },
    {
      "x": 8,
      "y": 14,
      "z": -9,
      "name": "Deco_Bone_Full"
    },
    {
      "x": 8,
      "y": 16,
      "z": -5,
      "name": "Deco_Bone_Full"
    },
    {
      "x": 8,
      "y": 15,
      "z": -4,
      "name": "Deco_Bone_Full"
    },
    {
      "x": 8,
      "y": 16,
      "z": -4,
      "name": "Deco_Bone_Full"
    },
    {
      "x": 8,
      "y": 17,
      "z": -4,
      "name": "Deco_Bone_Full"
    },
    {
      "x": 8,
      "y": 22,
      "z": -4,
      "name": "Deco_Bone_Full"
    },
    {
      "x": 8,
      "y": 23,
      "z": -4,
      "name": "Deco_Bone_Full"
    },
    {
      "x": 8,
      "y": 24,
      "z": -4,
      "name": "Deco_Bone_Full"
    },
    {
      "x": 8,
      "y": 25,
      "z": -4,
      "name": "Deco_Bone_Full"
    },
    {
      "x": 8,
      "y": 17,
      "z": -3,
      "name": "Deco_Bone_Full"
    },
    {
      "x": 8,
      "y": 21,
      "z": -3,
      "name": "Plant_Crop_Health3",
      "rotation": 3
    },
    {
      "x": 8,
      "y": 22,
      "z": -3,
      "name": "Plant_Crop_Health3",
      "filler": 1024,
      "rotation": 3
    },
    {
      "x": 9,
      "y": 15,
      "z": -14,
      "name": "Deco_Bone_Full"
    },
    {
      "x": 9,
      "y": 16,
      "z": -14,
      "name": "Deco_Bone_Full"
    },
    {
      "x": 9,
      "y": 15,
      "z": -13,
      "name": "Deco_Bone_Full"
    },
    {
      "x": 9,
      "y": 16,
      "z": -13,
      "name": "Deco_Bone_Full"
    },
    {
      "x": 9,
      "y": 13,
      "z": -12,
      "name": "Deco_Bone_Full"
    },
    {
      "x": 9,
      "y": 14,
      "z": -12,
      "name": "Deco_Bone_Full"
    },
    {
      "x": 9,
      "y": 15,
      "z": -12,
      "name": "Deco_Bone_Full"
    },
    {
      "x": 9,
      "y": 16,
      "z": -12,
      "name": "Deco_Bone_Full"
    },
    {
      "x": 9,
      "y": 12,
      "z": -11,
      "name": "Deco_Bone_Full"
    },
    {
      "x": 9,
      "y": 13,
      "z": -11,
      "name": "Deco_Bone_Full"
    },
    {
      "x": 9,
      "y": 14,
      "z": -11,
      "name": "Deco_Bone_Full"
    },
    {
      "x": 9,
      "y": 15,
      "z": -11,
      "name": "Deco_Bone_Full"
    },
    {
      "x": 9,
      "y": 16,
      "z": -11,
      "name": "Deco_Bone_Full"
    },
    {
      "x": 9,
      "y": 15,
      "z": -10,
      "name": "Deco_Bone_Full"
    },
    {
      "x": 9,
      "y": 17,
      "z": -4,
      "name": "Deco_Bone_Full"
    },
    {
      "x": 9,
      "y": 17,
      "z": -3,
      "name": "Deco_Bone_Full"
    },
    {
      "x": 9,
      "y": 18,
      "z": -3,
      "name": "Deco_Bone_Full"
    },
    {
      "x": 9,
      "y": 19,
      "z": -3,
      "name": "Deco_Bone_Full"
    },
    {
      "x": 9,
      "y": 20,
      "z": -3,
      "name": "Deco_Bone_Full"
    },
    {
      "x": 9,
      "y": 21,
      "z": -3,
      "name": "Deco_Bone_Full"
    },
    {
      "x": 9,
      "y": 22,
      "z": -3,
      "name": "Deco_Bone_Full"
    },
    {
      "x": 10,
      "y": 15,
      "z": -14,
      "name": "Deco_Bone_Full"
    },
    {
      "x": 10,
      "y": 14,
      "z": -13,
      "name": "Deco_Bone_Full"
    },
    {
      "x": 10,
      "y": 15,
      "z": -13,
      "name": "Deco_Bone_Full"
    },
    {
      "x": 10,
      "y": 16,
      "z": -13,
      "name": "Deco_Bone_Full"
    },
    {
      "x": 10,
      "y": 10,
      "z": -12,
      "name": "Deco_Bone_Full"
    },
    {
      "x": 10,
      "y": 11,
      "z": -12,
      "name": "Deco_Bone_Full"
    },
    {
      "x": 10,
      "y": 12,
      "z": -12,
      "name": "Deco_Bone_Full"
    },
    {
      "x": 10,
      "y": 13,
      "z": -12,
      "name": "Deco_Bone_Full"
    },
    {
      "x": 10,
      "y": 14,
      "z": -12,
      "name": "Deco_Bone_Full"
    },
    {
      "x": 10,
      "y": 15,
      "z": -12,
      "name": "Deco_Bone_Full"
    },
    {
      "x": 10,
      "y": 16,
      "z": -12,
      "name": "Deco_Bone_Full"
    },
    {
      "x": 10,
      "y": 17,
      "z": -12,
      "name": "Deco_Bone_Full"
    },
    {
      "x": 10,
      "y": 13,
      "z": -11,
      "name": "Deco_Bone_Full"
    },
    {
      "x": 10,
      "y": 14,
      "z": -11,
      "name": "Deco_Bone_Full"
    },
    {
      "x": 10,
      "y": 15,
      "z": -11,
      "name": "Deco_Bone_Full"
    },
    {
      "x": 10,
      "y": 16,
      "z": -11,
      "name": "Deco_Bone_Full"
    },
    {
      "x": 11,
      "y": 15,
      "z": -14,
      "name": "Deco_Bone_Full"
    },
    {
      "x": 11,
      "y": 9,
      "z": -13,
      "name": "Deco_Bone_Full"
    },
    {
      "x": 11,
      "y": 10,
      "z": -13,
      "name": "Deco_Bone_Full"
    },
    {
      "x": 11,
      "y": 11,
      "z": -13,
      "name": "Deco_Bone_Full"
    },
    {
      "x": 11,
      "y": 12,
      "z": -13,
      "name": "Deco_Bone_Full"
    },
    {
      "x": 11,
      "y": 13,
      "z": -13,
      "name": "Deco_Bone_Full"
    },
    {
      "x": 11,
      "y": 14,
      "z": -13,
      "name": "Deco_Bone_Full"
    },
    {
      "x": 11,
      "y": 15,
      "z": -13,
      "name": "Deco_Bone_Full"
    },
    {
      "x": 11,
      "y": 14,
      "z": -12,
      "name": "Deco_Bone_Full"
    },
    {
      "x": 11,
      "y": 15,
      "z": -12,
      "name": "Deco_Bone_Full"
    },
    {
      "x": 11,
      "y": 16,
      "z": -12,
      "name": "Deco_Bone_Full"
    },
    {
      "x": 11,
      "y": 15,
      "z": -11,
      "name": "Deco_Bone_Full"
    },
    {
      "x": 11,
      "y": 16,
      "z": -11,
      "name": "Deco_Bone_Full"
    },
    {
      "x": 11,
      "y": 15,
      "z": -10,
      "name": "Deco_Bone_Full"
    },
    {
      "x": 11,
      "y": 16,
      "z": -10,
      "name": "Deco_Bone_Full"
    },
    {
      "x": 12,
      "y": 18,
      "z": -20,
      "name": "Deco_Bone_Full"
    },
    {
      "x": 12,
      "y": 19,
      "z": -20,
      "name": "Deco_Bone_Full"
    },
    {
      "x": 12,
      "y": 20,
      "z": -20,
      "name": "Deco_Bone_Full"
    },
    {
      "x": 12,
      "y": 21,
      "z": -20,
      "name": "Deco_Bone_Full"
    },
    {
      "x": 12,
      "y": 22,
      "z": -20,
      "name": "Deco_Bone_Full"
    },
    {
      "x": 12,
      "y": 23,
      "z": -20,
      "name": "Deco_Bone_Full"
    },
    {
      "x": 12,
      "y": 18,
      "z": -19,
      "name": "Deco_Bone_Full"
    },
    {
      "x": 12,
      "y": 15,
      "z": -15,
      "name": "Deco_Bone_Full"
    },
    {
      "x": 12,
      "y": 14,
      "z": -14,
      "name": "Deco_Bone_Full"
    },
    {
      "x": 12,
      "y": 15,
      "z": -14,
      "name": "Deco_Bone_Full"
    },
    {
      "x": 12,
      "y": 15,
      "z": -13,
      "name": "Deco_Bone_Full"
    },
    {
      "x": 12,
      "y": 15,
      "z": -12,
      "name": "Deco_Bone_Full"
    },
    {
      "x": 12,
      "y": 15,
      "z": -11,
      "name": "Deco_Bone_Full"
    },
    {
      "x": 12,
      "y": 16,
      "z": -11,
      "name": "Deco_Bone_Full"
    },
    {
      "x": 12,
      "y": 16,
      "z": -10,
      "name": "Deco_Bone_Full"
    },
    {
      "x": 12,
      "y": 17,
      "z": -10,
      "name": "Deco_Bone_Full"
    },
    {
      "x": 12,
      "y": 17,
      "z": -9,
      "name": "Deco_Bone_Full"
    },
    {
      "x": 13,
      "y": 18,
      "z": -20,
      "name": "Deco_Bone_Full"
    },
    {
      "x": 13,
      "y": 17,
      "z": -19,
      "name": "Deco_Bone_Full"
    },
    {
      "x": 13,
      "y": 18,
      "z": -19,
      "name": "Deco_Bone_Full"
    },
    {
      "x": 13,
      "y": 23,
      "z": -19,
      "name": "Deco_Bone_Full"
    },
    {
      "x": 13,
      "y": 24,
      "z": -19,
      "name": "Deco_Bone_Full"
    },
    {
      "x": 13,
      "y": 16,
      "z": -18,
      "name": "Deco_Bone_Full"
    },
    {
      "x": 13,
      "y": 17,
      "z": -18,
      "name": "Deco_Bone_Full"
    },
    {
      "x": 13,
      "y": 16,
      "z": -16,
      "name": "Deco_Bone_Full"
    },
    {
      "x": 13,
      "y": 15,
      "z": -15,
      "name": "Deco_Bone_Full"
    },
    {
      "x": 13,
      "y": 16,
      "z": -15,
      "name": "Deco_Bone_Full"
    },
    {
      "x": 13,
      "y": 15,
      "z": -14,
      "name": "Deco_Bone_Full"
    },
    {
      "x": 13,
      "y": 17,
      "z": -10,
      "name": "Deco_Bone_Full"
    },
    {
      "x": 13,
      "y": 17,
      "z": -9,
      "name": "Deco_Bone_Full"
    },
    {
      "x": 13,
      "y": 18,
      "z": -9,
      "name": "Deco_Bone_Full"
    },
    {
      "x": 13,
      "y": 19,
      "z": -9,
      "name": "Deco_Bone_Full"
    },
    {
      "x": 13,
      "y": 20,
      "z": -9,
      "name": "Deco_Bone_Full"
    },
    {
      "x": 14,
      "y": 16,
      "z": -19,
      "name": "Deco_Bone_Full"
    },
    {
      "x": 14,
      "y": 17,
      "z": -19,
      "name": "Deco_Bone_Full"
    },
    {
      "x": 14,
      "y": 16,
      "z": -18,
      "name": "Deco_Bone_Full"
    },
    {
      "x": 14,
      "y": 17,
      "z": -18,
      "name": "Deco_Bone_Full"
    },
    {
      "x": 14,
      "y": 14,
      "z": -17,
      "name": "Deco_Bone_Full"
    },
    {
      "x": 14,
      "y": 15,
      "z": -17,
      "name": "Deco_Bone_Full"
    },
    {
      "x": 14,
      "y": 16,
      "z": -17,
      "name": "Deco_Bone_Full"
    },
    {
      "x": 14,
      "y": 17,
      "z": -17,
      "name": "Deco_Bone_Full"
    },
    {
      "x": 14,
      "y": 13,
      "z": -16,
      "name": "Deco_Bone_Full"
    },
    {
      "x": 14,
      "y": 14,
      "z": -16,
      "name": "Deco_Bone_Full"
    },
    {
      "x": 14,
      "y": 15,
      "z": -16,
      "name": "Deco_Bone_Full"
    },
    {
      "x": 14,
      "y": 16,
      "z": -16,
      "name": "Deco_Bone_Full"
    },
    {
      "x": 14,
      "y": 17,
      "z": -16,
      "name": "Deco_Bone_Full"
    },
    {
      "x": 14,
      "y": 16,
      "z": -15,
      "name": "Deco_Bone_Full"
    },
    {
      "x": 15,
      "y": 16,
      "z": -19,
      "name": "Deco_Bone_Full"
    },
    {
      "x": 15,
      "y": 15,
      "z": -18,
      "name": "Deco_Bone_Full"
    },
    {
      "x": 15,
      "y": 16,
      "z": -18,
      "name": "Deco_Bone_Full"
    },
    {
      "x": 15,
      "y": 17,
      "z": -18,
      "name": "Deco_Bone_Full"
    },
    {
      "x": 15,
      "y": 12,
      "z": -17,
      "name": "Deco_Bone_Full"
    },
    {
      "x": 15,
      "y": 13,
      "z": -17,
      "name": "Deco_Bone_Full"
    },
    {
      "x": 15,
      "y": 14,
      "z": -17,
      "name": "Deco_Bone_Full"
    },
    {
      "x": 15,
      "y": 15,
      "z": -17,
      "name": "Deco_Bone_Full"
    },
    {
      "x": 15,
      "y": 16,
      "z": -17,
      "name": "Deco_Bone_Full"
    },
    {
      "x": 15,
      "y": 17,
      "z": -17,
      "name": "Deco_Bone_Full"
    },
    {
      "x": 15,
      "y": 18,
      "z": -17,
      "name": "Deco_Bone_Full"
    },
    {
      "x": 15,
      "y": 14,
      "z": -16,
      "name": "Deco_Bone_Full"
    },
    {
      "x": 15,
      "y": 15,
      "z": -16,
      "name": "Deco_Bone_Full"
    },
    {
      "x": 15,
      "y": 16,
      "z": -16,
      "name": "Deco_Bone_Full"
    },
    {
      "x": 15,
      "y": 17,
      "z": -16,
      "name": "Deco_Bone_Full"
    },
    {
      "x": 16,
      "y": 16,
      "z": -19,
      "name": "Deco_Bone_Full"
    },
    {
      "x": 16,
      "y": 11,
      "z": -18,
      "name": "Deco_Bone_Full"
    },
    {
      "x": 16,
      "y": 12,
      "z": -18,
      "name": "Deco_Bone_Full"
    },
    {
      "x": 16,
      "y": 13,
      "z": -18,
      "name": "Deco_Bone_Full"
    },
    {
      "x": 16,
      "y": 14,
      "z": -18,
      "name": "Deco_Bone_Full"
    },
    {
      "x": 16,
      "y": 15,
      "z": -18,
      "name": "Deco_Bone_Full"
    },
    {
      "x": 16,
      "y": 16,
      "z": -18,
      "name": "Deco_Bone_Full"
    },
    {
      "x": 16,
      "y": 15,
      "z": -17,
      "name": "Deco_Bone_Full"
    },
    {
      "x": 16,
      "y": 16,
      "z": -17,
      "name": "Deco_Bone_Full"
    },
    {
      "x": 16,
      "y": 17,
      "z": -17,
      "name": "Deco_Bone_Full"
    },
    {
      "x": 16,
      "y": 16,
      "z": -16,
      "name": "Deco_Bone_Full"
    },
    {
      "x": 16,
      "y": 17,
      "z": -16,
      "name": "Deco_Bone_Full"
    },
    {
      "x": 16,
      "y": 16,
      "z": -15,
      "name": "Deco_Bone_Full"
    },
    {
      "x": 16,
      "y": 17,
      "z": -15,
      "name": "Deco_Bone_Full"
    },
    {
      "x": 17,
      "y": 19,
      "z": -25,
      "name": "Deco_Bone_Full"
    },
    {
      "x": 17,
      "y": 20,
      "z": -25,
      "name": "Deco_Bone_Full"
    },
    {
      "x": 17,
      "y": 21,
      "z": -25,
      "name": "Deco_Bone_Full"
    },
    {
      "x": 17,
      "y": 22,
      "z": -25,
      "name": "Deco_Bone_Full"
    },
    {
      "x": 17,
      "y": 23,
      "z": -25,
      "name": "Deco_Bone_Full"
    },
    {
      "x": 17,
      "y": 19,
      "z": -24,
      "name": "Deco_Bone_Full"
    },
    {
      "x": 17,
      "y": 17,
      "z": -20,
      "name": "Deco_Bone_Full"
    },
    {
      "x": 17,
      "y": 16,
      "z": -19,
      "name": "Deco_Bone_Full"
    },
    {
      "x": 17,
      "y": 17,
      "z": -19,
      "name": "Deco_Bone_Full"
    },
    {
      "x": 17,
      "y": 16,
      "z": -18,
      "name": "Deco_Bone_Full"
    },
    {
      "x": 17,
      "y": 16,
      "z": -17,
      "name": "Deco_Bone_Full"
    },
    {
      "x": 17,
      "y": 16,
      "z": -16,
      "name": "Deco_Bone_Full"
    },
    {
      "x": 17,
      "y": 17,
      "z": -16,
      "name": "Deco_Bone_Full"
    },
    {
      "x": 17,
      "y": 17,
      "z": -15,
      "name": "Deco_Bone_Full"
    },
    {
      "x": 17,
      "y": 18,
      "z": -15,
      "name": "Deco_Bone_Full"
    },
    {
      "x": 17,
      "y": 23,
      "z": -15,
      "name": "Deco_Bone_Full"
    },
    {
      "x": 17,
      "y": 24,
      "z": -15,
      "name": "Deco_Bone_Full"
    },
    {
      "x": 17,
      "y": 18,
      "z": -14,
      "name": "Deco_Bone_Full"
    },
    {
      "x": 18,
      "y": 19,
      "z": -25,
      "name": "Deco_Bone_Full"
    },
    {
      "x": 18,
      "y": 18,
      "z": -24,
      "name": "Deco_Bone_Full"
    },
    {
      "x": 18,
      "y": 19,
      "z": -24,
      "name": "Deco_Bone_Full"
    },
    {
      "x": 18,
      "y": 23,
      "z": -24,
      "name": "Deco_Bone_Full"
    },
    {
      "x": 18,
      "y": 24,
      "z": -24,
      "name": "Deco_Bone_Full"
    },
    {
      "x": 18,
      "y": 17,
      "z": -23,
      "name": "Deco_Bone_Full"
    },
    {
      "x": 18,
      "y": 18,
      "z": -23,
      "name": "Deco_Bone_Full"
    },
    {
      "x": 18,
      "y": 17,
      "z": -21,
      "name": "Deco_Bone_Full"
    },
    {
      "x": 18,
      "y": 16,
      "z": -20,
      "name": "Deco_Bone_Full"
    },
    {
      "x": 18,
      "y": 17,
      "z": -20,
      "name": "Deco_Bone_Full"
    },
    {
      "x": 18,
      "y": 17,
      "z": -19,
      "name": "Deco_Bone_Full"
    },
    {
      "x": 18,
      "y": 18,
      "z": -15,
      "name": "Deco_Bone_Full"
    },
    {
      "x": 18,
      "y": 18,
      "z": -14,
      "name": "Deco_Bone_Full"
    },
    {
      "x": 18,
      "y": 19,
      "z": -14,
      "name": "Deco_Bone_Full"
    },
    {
      "x": 18,
      "y": 20,
      "z": -14,
      "name": "Deco_Bone_Full"
    },
    {
      "x": 18,
      "y": 21,
      "z": -14,
      "name": "Deco_Bone_Full"
    },
    {
      "x": 18,
      "y": 22,
      "z": -14,
      "name": "Deco_Bone_Full"
    },
    {
      "x": 18,
      "y": 23,
      "z": -14,
      "name": "Deco_Bone_Full"
    },
    {
      "x": 19,
      "y": 17,
      "z": -24,
      "name": "Deco_Bone_Full"
    },
    {
      "x": 19,
      "y": 18,
      "z": -24,
      "name": "Deco_Bone_Full"
    },
    {
      "x": 19,
      "y": 17,
      "z": -23,
      "name": "Deco_Bone_Full"
    },
    {
      "x": 19,
      "y": 18,
      "z": -23,
      "name": "Deco_Bone_Full"
    },
    {
      "x": 19,
      "y": 15,
      "z": -22,
      "name": "Deco_Bone_Full"
    },
    {
      "x": 19,
      "y": 16,
      "z": -22,
      "name": "Deco_Bone_Full"
    },
    {
      "x": 19,
      "y": 17,
      "z": -22,
      "name": "Deco_Bone_Full"
    },
    {
      "x": 19,
      "y": 18,
      "z": -22,
      "name": "Deco_Bone_Full"
    },
    {
      "x": 19,
      "y": 14,
      "z": -21,
      "name": "Deco_Bone_Full"
    },
    {
      "x": 19,
      "y": 15,
      "z": -21,
      "name": "Deco_Bone_Full"
    },
    {
      "x": 19,
      "y": 16,
      "z": -21,
      "name": "Deco_Bone_Full"
    },
    {
      "x": 19,
      "y": 17,
      "z": -21,
      "name": "Deco_Bone_Full"
    },
    {
      "x": 19,
      "y": 18,
      "z": -21,
      "name": "Deco_Bone_Full"
    },
    {
      "x": 19,
      "y": 17,
      "z": -20,
      "name": "Deco_Bone_Full"
    },
    {
      "x": 20,
      "y": 17,
      "z": -24,
      "name": "Deco_Bone_Full"
    },
    {
      "x": 20,
      "y": 16,
      "z": -23,
      "name": "Deco_Bone_Full"
    },
    {
      "x": 20,
      "y": 17,
      "z": -23,
      "name": "Deco_Bone_Full"
    },
    {
      "x": 20,
      "y": 18,
      "z": -23,
      "name": "Deco_Bone_Full"
    },
    {
      "x": 20,
      "y": 13,
      "z": -22,
      "name": "Deco_Bone_Full"
    },
    {
      "x": 20,
      "y": 14,
      "z": -22,
      "name": "Deco_Bone_Full"
    },
    {
      "x": 20,
      "y": 15,
      "z": -22,
      "name": "Deco_Bone_Full"
    },
    {
      "x": 20,
      "y": 16,
      "z": -22,
      "name": "Deco_Bone_Full"
    },
    {
      "x": 20,
      "y": 17,
      "z": -22,
      "name": "Deco_Bone_Full"
    },
    {
      "x": 20,
      "y": 18,
      "z": -22,
      "name": "Deco_Bone_Full"
    },
    {
      "x": 20,
      "y": 19,
      "z": -22,
      "name": "Deco_Bone_Full"
    },
    {
      "x": 20,
      "y": 15,
      "z": -21,
      "name": "Deco_Bone_Full"
    },
    {
      "x": 20,
      "y": 16,
      "z": -21,
      "name": "Deco_Bone_Full"
    },
    {
      "x": 20,
      "y": 17,
      "z": -21,
      "name": "Deco_Bone_Full"
    },
    {
      "x": 20,
      "y": 18,
      "z": -21,
      "name": "Deco_Bone_Full"
    },
    {
      "x": 21,
      "y": 18,
      "z": -24,
      "name": "Deco_Bone_Full"
    },
    {
      "x": 21,
      "y": 13,
      "z": -23,
      "name": "Deco_Bone_Full"
    },
    {
      "x": 21,
      "y": 14,
      "z": -23,
      "name": "Deco_Bone_Full"
    },
    {
      "x": 21,
      "y": 15,
      "z": -23,
      "name": "Deco_Bone_Full"
    },
    {
      "x": 21,
      "y": 16,
      "z": -23,
      "name": "Deco_Bone_Full"
    },
    {
      "x": 21,
      "y": 17,
      "z": -23,
      "name": "Deco_Bone_Full"
    },
    {
      "x": 21,
      "y": 18,
      "z": -23,
      "name": "Deco_Bone_Full"
    },
    {
      "x": 21,
      "y": 16,
      "z": -22,
      "name": "Deco_Bone_Full"
    },
    {
      "x": 21,
      "y": 17,
      "z": -22,
      "name": "Deco_Bone_Full"
    },
    {
      "x": 21,
      "y": 18,
      "z": -22,
      "name": "Deco_Bone_Full"
    },
    {
      "x": 21,
      "y": 17,
      "z": -21,
      "name": "Deco_Bone_Full"
    },
    {
      "x": 21,
      "y": 18,
      "z": -21,
      "name": "Deco_Bone_Full"
    },
    {
      "x": 21,
      "y": 17,
      "z": -20,
      "name": "Deco_Bone_Full"
    },
    {
      "x": 21,
      "y": 18,
      "z": -20,
      "name": "Deco_Bone_Full"
    },
    {
      "x": 22,
      "y": 18,
      "z": -25,
      "name": "Deco_Bone_Full"
    },
    {
      "x": 22,
      "y": 17,
      "z": -24,
      "name": "Deco_Bone_Full"
    },
    {
      "x": 22,
      "y": 18,
      "z": -24,
      "name": "Deco_Bone_Full"
    },
    {
      "x": 22,
      "y": 18,
      "z": -23,
      "name": "Deco_Bone_Full"
    },
    {
      "x": 22,
      "y": 17,
      "z": -22,
      "name": "Deco_Bone_Full"
    },
    {
      "x": 22,
      "y": 17,
      "z": -21,
      "name": "Deco_Bone_Full"
    },
    {
      "x": 22,
      "y": 18,
      "z": -21,
      "name": "Deco_Bone_Full"
    },
    {
      "x": 22,
      "y": 18,
      "z": -20,
      "name": "Deco_Bone_Full"
    },
    {
      "x": 22,
      "y": 19,
      "z": -20,
      "name": "Deco_Bone_Full"
    },
    {
      "x": 22,
      "y": 19,
      "z": -19,
      "name": "Deco_Bone_Full"
    },
    {
      "x": 23,
      "y": 18,
      "z": -26,
      "name": "Deco_Bone_Full"
    },
    {
      "x": 23,
      "y": 17,
      "z": -25,
      "name": "Deco_Bone_Full"
    },
    {
      "x": 23,
      "y": 18,
      "z": -25,
      "name": "Deco_Bone_Full"
    },
    {
      "x": 23,
      "y": 18,
      "z": -24,
      "name": "Deco_Bone_Full"
    },
    {
      "x": 23,
      "y": 19,
      "z": -20,
      "name": "Deco_Bone_Full"
    },
    {
      "x": 23,
      "y": 19,
      "z": -19,
      "name": "Deco_Bone_Full"
    },
    {
      "x": 23,
      "y": 20,
      "z": -19,
      "name": "Deco_Bone_Full"
    },
    {
      "x": 23,
      "y": 21,
      "z": -19,
      "name": "Deco_Bone_Full"
    },
    {
      "x": 24,
      "y": 19,
      "z": -27,
      "name": "Deco_Bone_Full"
    },
    {
      "x": 24,
      "y": 18,
      "z": -26,
      "name": "Deco_Bone_Full"
    },
    {
      "x": 24,
      "y": 19,
      "z": -26,
      "name": "Deco_Bone_Full"
    },
    {
      "x": 24,
      "y": 18,
      "z": -25,
      "name": "Deco_Bone_Full"
    },
    {
      "x": 25,
      "y": 19,
      "z": -28,
      "name": "Deco_Bone_Full"
    },
    {
      "x": 25,
      "y": 18,
      "z": -27,
      "name": "Deco_Bone_Full"
    },
    {
      "x": 25,
      "y": 19,
      "z": -27,
      "name": "Deco_Bone_Full"
    },
    {
      "x": 25,
      "y": 19,
      "z": -26,
      "name": "Deco_Bone_Full"
    },
    {
      "x": 26,
      "y": 19,
      "z": -28,
      "name": "Deco_Bone_Full"
    },
    {
      "x": 26,
      "y": 19,
      "z": -27,
      "name": "Deco_Bone_Full"
    }
  ]
}