{
  "version": 8,
  "blockIdVersion": 8,
  "anchorX": 2,
  "anchorY": 9,
  "anchorZ": 2,
  "blocks": [
    {
      "x": -19,
      "y": 11,
      "z": 11,
      "name": "Deco_Bone_Full"
    },
    {
      "x": -19,
      "y": 12,
      "z": 11,
      "name": "Deco_Bone_Full"
    },
    {
      "x": -19,
      "y": 13,
      "z": 11,
      "name": "Deco_Bone_Full"
    },
    {
      "x": -19,
      "y": 14,
      "z": 11,
      "name": "Deco_Bone_Full"
    },
    {
      "x": -19,
      "y": 15,
      "z": 11,
      "name": "Deco_Bone_Full"
    },
    {
      "x": -19,
      "y": 16,
      "z": 11,
      "name": "Deco_Bone_Full"
    },
    {
      "x": -19,
      "y": 16,
      "z": 12,
      "name": "Deco_Bone_Full"
    },
    {
      "x": -19,
      "y": 17,
      "z": 12,
      "name": "Deco_Bone_Full"
    },
    {
      "x": -18,
      "y": 16,
      "z": 11,
      "name": "Deco_Bone_Full"
    },
    {
      "x": -18,
      "y": 17,
      "z": 11,
      "name": "Deco_Bone_Full"
    },
    {
      "x": -18,
      "y": 8,
      "z": 12,
      "name": "Deco_Bone_Full"
    },
    {
      "x": -18,
      "y": 9,
      "z": 12,
      "name": "Deco_Bone_Full"
    },
    {
      "x": -18,
      "y": 10,
      "z": 12,
      "name": "Deco_Bone_Full"
    },
    {
      "x": -18,
      "y": 11,
      "z": 12,
      "name": "Deco_Bone_Full"
    },
    {
      "x": -18,
      "y": 15,
      "z": 12,
      "name": "Deco_Bone_Full"
    },
    {
      "x": -18,
      "y": 16,
      "z": 12,
      "name": "Deco_Bone_Full"
    },
    {
      "x": -18,
      "y": 17,
      "z": 12,
      "name": "Deco_Bone_Full"
    },
    {
      "x": -18,
      "y": 18,
      "z": 12,
      "name": "Deco_Bone_Full"
    },
    {
      "x": -18,
      "y": 19,
      "z": 12,
      "name": "Deco_Bone_Full"
    },
    {
      "x": -18,
      "y": 17,
      "z": 13,
      "name": "Deco_Bone_Full"
    },
    {
      "x": -18,
      "y": 18,
      "z": 13,
      "name": "Deco_Bone_Full"
    },
    {
      "x": -17,
      "y": 17,
      "z": 12,
      "name": "Deco_Bone_Full"
    },
    {
      "x": -17,
      "y": 18,
      "z": 12,
      "name": "Deco_Bone_Full"
    },
    {
      "x": -17,
      "y": 7,
      "z": 13,
      "name": "Deco_Bone_Full"
    },
    {
      "x": -17,
      "y": 8,
      "z": 13,
      "name": "Deco_Bone_Full"
    },
    {
      "x": -17,
      "y": 18,
      "z": 13,
      "name": "Deco_Bone_Full"
    },
    {
      "x": -17,
      "y": 19,
      "z": 13,
      "name": "Deco_Bone_Full"
    },
    {
      "x": -17,
      "y": 20,
      "z": 13,
      "name": "Deco_Bone_Full"
    },
    {
      "x": -17,
      "y": 19,
      "z": 14,
      "name": "Deco_Bone_Full"
    },
    {
      "x": -17,
      "y": 20,
      "z": 20,
      "name": "Deco_Bone_Full"
    },
    {
      "x": -17,
      "y": 21,
      "z": 20,
      "name": "Deco_Bone_Full"
    },
    {
      "x": -17,
      "y": 20,
      "z": 21,
      "name": "Deco_Bone_Full"
    },
    {
      "x": -17,
      "y": 21,
      "z": 21,
      "name": "Deco_Bone_Full"
    },
    {
      "x": -16,
      "y": 19,
      "z": 13,
      "name": "Deco_Bone_Full"
    },
    {
      "x": -16,
      "y": 6,
      "z": 14,
      "name": "Deco_Bone_Full"
    },
    {
      "x": -16,
      "y": 7,
      "z": 14,
      "name": "Deco_Bone_Full"
    },
    {
      "x": -16,
      "y": 19,
      "z": 14,
      "name": "Deco_Bone_Full"
    },
    {
      "x": -16,
      "y": 20,
      "z": 14,
      "name": "Deco_Bone_Full"
    },
    {
      "x": -16,
      "y": 21,
      "z": 14,
      "name": "Deco_Bone_Full"
    },
    {
      "x": -16,
      "y": 20,
      "z": 15,
      "name": "Deco_Bone_Full"
    },
    {
      "x": -16,
      "y": 20,
      "z": 19,
      "name": "Deco_Bone_Full"
    },
    {
      "x": -16,
      "y": 21,
      "z": 19,
      "name": "Deco_Bone_Full"
    },
    {
      "x": -16,
      "y": 20,
      "z": 20,
      "name": "Deco_Bone_Full"
    },
    {
      "x": -16,
      "y": 21,
      "z": 20,
      "name": "Deco_Bone_Full"
    },
    {
      "x": -16,
      "y": 20,
      "z": 21,
      "name": "Deco_Bone_Full"
    },
    {
      "x": -16,
      "y": 21,
      "z": 21,
      "name": "Deco_Bone_Full"
    },
    {
      "x": -15,
      "y": 20,
      "z": 14,
      "name": "Deco_Bone_Full"
    },
    {
      "x": -15,
      "y": 20,
      "z": 15,
      "name": "Deco_Bone_Full"
    },
    {
      "x": -15,
      "y": 21,
      "z": 15,
      "name": "Deco_Bone_Full"
    },
    {
      "x": -15,
      "y": 21,
      "z": 16,
      "name": "Deco_Bone_Full"
    },
    {
      "x": -15,
      "y": 22,
      "z": 17,
      "name": "Deco_Bone_Full"
    },
    {
      "x": -15,
      "y": 22,
      "z": 18,
      "name": "Deco_Bone_Full"
    },
    {
      "x": -15,
      "y": 22,
      "z": 19,
      "name": "Deco_Bone_Full"
    },
    {
      "x": -15,
      "y": 20,
      "z": 20,
      "name": "Deco_Bone_Full"
    },
    {
      "x": -15,
      "y": 21,
      "z": 20,
      "name": "Deco_Bone_Full"
    },
    {
      "x": -14,
      "y": 21,
      "z": 15,
      "name": "Deco_Bone_Full"
    },
    {
      "x": -14,
      "y": 22,
      "z": 15,
      "name": "Deco_Bone_Full"
    },
    {
      "x": -14,
      "y": 21,
      "z": 16,
      "name": "Deco_Bone_Full"
    },
    {
      "x": -14,
      "y": 22,
      "z": 16,
      "name": "Deco_Bone_Full"
    },
    {
      "x": -14,
      "y": 21,
      "z": 17,
      "name": "Deco_Bone_Full"
    },
    {
      "x": -14,
      "y": 22,
      "z": 17,
      "name": "Deco_Bone_Full"
    },
    {
      "x": -14,
      "y": 23,
      "z": 17,
      "name": "Deco_Bone_Full"
    },
    {
      "x": -14,
      "y": 21,
      "z": 18,
      "name": "Deco_Bone_Full"
    },
    {
      "x": -14,
      "y": 22,
      "z": 18,
      "name": "Deco_Bone_Full"
    },
    {
      "x": -14,
      "y": 23,
      "z": 18,
      "name": "Deco_Bone_Full"
    },
    {
      "x": -14,
      "y": 24,
      "z": 18,
      "name": "Deco_Bone_Full"
    },
    {
      "x": -14,
      "y": 22,
      "z": 19,
      "name": "Deco_Bone_Full"
    },
    {
      "x": -13,
      "y": 22,
      "z": 15,
      "name": "Deco_Bone_Full"
    },
    {
      "x": -13,
      "y": 21,
      "z": 16,
      "name": "Deco_Bone_Full"
    },
    {
      "x": -13,
      "y": 22,
      "z": 16,
      "name": "Deco_Bone_Full"
    },
    {
      "x": -13,
      "y": 23,
      "z": 16,
      "name": "Deco_Bone_Full"
    },
    {
      "x": -13,
      "y": 24,
      "z": 16,
      "name": "Deco_Bone_Full"
    },
    {
      "x": -13,
      "y": 21,
      "z": 17,
      "name": "Deco_Bone_Full"
    },
    {
      "x": -13,
      "y": 22,
      "z": 17,
      "name": "Deco_Bone_Full"
    },
    {
      "x": -13,
      "y": 23,
      "z": 17,
      "name": "Deco_Bone_Full"
    },
    {
      "x": -13,
      "y": 24,
      "z": 17,
      "name": "Deco_Bone_Full"
    },
    {
      "x": -13,
      "y": 25,
      "z": 17,
      "name": "Deco_Bone_Full"
    },
    {
      "x": -13,
      "y": 21,
      "z": 18,
      "name": "Deco_Bone_Full"
    },
    {
      "x": -13,
      "y": 22,
      "z": 18,
      "name": "Deco_Bone_Full"
    },
    {
      "x": -13,
      "y": 23,
      "z": 18,
      "name": "Deco_Bone_Full"
    },
    {
      "x": -13,
      "y": 22,
      "z": 19,
      "name": "Deco_Bone_Full"
    },
    {
      "x": -12,
      "y": 21,
      "z": 8,
      "name": "Deco_Bone_Full"
    },
    {
      "x": -12,
      "y": 20,
      "z": 9,
      "name": "Deco_Bone_Full"
    },
    {
      "x": -12,
      "y": 22,
      "z": 15,
      "name": "Deco_Bone_Full"
    },
    {
      "x": -12,
      "y": 23,
      "z": 15,
      "name": "Deco_Bone_Full"
    },
    {
      "x": -12,
      "y": 21,
      "z": 16,
      "name": "Deco_Bone_Full"
    },
    {
      "x": -12,
      "y": 22,
      "z": 16,
      "name": "Deco_Bone_Full"
    },
    {
      "x": -12,
      "y": 23,
      "z": 16,
      "name": "Deco_Bone_Full"
    },
    {
      "x": -12,
      "y": 24,
      "z": 16,
      "name": "Deco_Bone_Full"
    },
    {
      "x": -12,
      "y": 25,
      "z": 16,
      "name": "Deco_Bone_Full"
    },
    {
      "x": -12,
      "y": 21,
      "z": 17,
      "name": "Deco_Bone_Full"
    },
    {
      "x": -12,
      "y": 22,
      "z": 17,
      "name": "Deco_Bone_Full"
    },
    {
      "x": -12,
      "y": 23,
      "z": 17,
      "name": "Deco_Bone_Full"
    },
    {
      "x": -12,
      "y": 24,
      "z": 17,
      "name": "Deco_Bone_Full"
    },
    {
      "x": -12,
      "y": 21,
      "z": 18,
      "name": "Deco_Bone_Full"
    },
    {
      "x": -12,
      "y": 22,
      "z": 18,
      "name": "Deco_Bone_Full"
    },
    {
      "x": -12,
      "y": 21,
      "z": 19,
      "name": "Deco_Bone_Full"
    },
    {
      "x": -11,
      "y": 20,
      "z": 9,
      "name": "Deco_Bone_Full"
    },
    {
      "x": -11,
      "y": 21,
      "z": 9,
      "name": "Deco_Bone_Full"
    },
    {
      "x": -11,
      "y": 22,
      "z": 9,
      "name": "Deco_Bone_Full"
    },
    {
      "x": -11,
      "y": 21,
      "z": 10,
      "name": "Deco_Bone_Full"
    },
    {
      "x": -11,
      "y": 21,
      "z": 14,
      "name": "Deco_Bone_Full"
    },
    {
      "x": -11,
      "y": 22,
      "z": 14,
      "name": "Deco_Bone_Full"
    },
    {
      "x": -11,
      "y": 21,
      "z": 15,
      "name": "Deco_Bone_Full"
    },
    {
      "x": -11,
      "y": 22,
      "z": 15,
      "name": "Deco_Bone_Full"
    },
    {
      "x": -11,
      "y": 22,
      "z": 16,
      "name": "Deco_Bone_Full"
    },
    {
      "x": -11,
      "y": 23,
      "z": 16,
      "name": "Deco_Bone_Full"
    },
    {
      "x": -11,
      "y": 22,
      "z": 17,
      "name": "Deco_Bone_Full"
    },
    {
      "x": -11,
      "y": 21,
      "z": 18,
      "name": "Deco_Bone_Full"
    },
    {
      "x": -11,
      "y": 22,
      "z": 18,
      "name": "Deco_Bone_Full"
    },
    {
      "x": -11,
      "y": 20,
      "z": 19,
      "name": "Deco_Bone_Full"
    },
    {
      "x": -11,
      "y": 21,
      "z": 19,
      "name": "Deco_Bone_Full"
    },
    {
      "x": -11,
      "y": 20,
      "z": 20,
      "name": "Deco_Bone_Full"
    },
    {
      "x": -10,
      "y": 21,
      "z": 9,
      "name": "Deco_Bone_Full"
    },
    {
      "x": -10,
      "y": 21,
      "z": 10,
      "name": "Deco_Bone_Full"
    },
    {
      "x": -10,
      "y": 22,
      "z": 10,
      "name": "Deco_Bone_Full"
    },
    {
      "x": -10,
      "y": 22,
      "z": 11,
      "name": "Deco_Bone_Full"
    },
    {
      "x": -10,
      "y": 23,
      "z": 12,
      "name": "Deco_Bone_Full"
    },
    {
      "x": -10,
      "y": 23,
      "z": 13,
      "name": "Deco_Bone_Full"
    },
    {
      "x": -10,
      "y": 23,
      "z": 14,
      "name": "Deco_Bone_Full"
    },
    {
      "x": -10,
      "y": 21,
      "z": 15,
      "name": "Deco_Bone_Full"
    },
    {
      "x": -10,
      "y": 22,
      "z": 15,
      "name": "Deco_Bone_Full"
    },
    {
      "x": -10,
      "y": 20,
      "z": 19,
      "name": "Deco_Bone_Full"
    },
    {
      "x": -10,
      "y": 6,
      "z": 20,
      "name": "Deco_Bone_Full"
    },
    {
      "x": -10,
      "y": 7,
      "z": 20,
      "name": "Deco_Bone_Full"
    },
    {
      "x": -10,
      "y": 19,
      "z": 20,
      "name": "Deco_Bone_Full"
    },
    {
      "x": -10,
      "y": 20,
      "z": 20,
      "name": "Deco_Bone_Full"
    },
    {
      "x": -10,
      "y": 21,
      "z": 20,
      "name": "Deco_Bone_Full"
    },
    {
      "x": -10,
      "y": 19,
      "z": 21,
      "name": "Deco_Bone_Full"
    },
    {
      "x": -9,
      "y": 10,
      "z": 1,
      "name": "Deco_Bone_Full"
    },
    {
      "x": -9,
      "y": 11,
      "z": 1,
      "name": "Deco_Bone_Full"
    },
    {
      "x": -9,
      "y": 12,
      "z": 1,
      "name": "Deco_Bone_Full"
    },
    {
      "x": -9,
      "y": 13,
      "z": 1,
      "name": "Deco_Bone_Full"
    },
    {
      "x": -9,
      "y": 14,
      "z": 1,
      "name": "Deco_Bone_Full"
    },
    {
      "x": -9,
      "y": 15,
      "z": 1,
      "name": "Deco_Bone_Full"
    },
    {
      "x": -9,
      "y": 16,
      "z": 1,
      "name": "Deco_Bone_Full"
    },
    {
      "x": -9,
      "y": 17,
      "z": 1,
      "name": "Deco_Bone_Full"
    },
    {
      "x": -9,
      "y": 17,
      "z": 2,
      "name": "Deco_Bone_Full"
    },
    {
      "x": -9,
      "y": 18,
      "z": 2,
      "name": "Deco_Bone_Full"
    },
    {
      "x": -9,
      "y": 22,
      "z": 10,
      "name": "Deco_Bone_Full"
    },
    {
      "x": -9,
      "y": 23,
      "z": 10,
      "name": "Deco_Bone_Full"
    },
    {
      "x": -9,
      "y": 22,
      "z": 11,
      "name": "Deco_Bone_Full"
    },
    {
      "x": -9,
      "y": 23,
      "z": 11,
      "name": "Deco_Bone_Full"
    },
    {
      "x": -9,
      "y": 22,
      "z": 12,
      "name": "Deco_Bone_Full"
    },
    {
      "x": -9,
      "y": 23,
      "z": 12,
      "name": "Deco_Bone_Full"
    },
    {
      "x": -9,
      "y": 24,
      "z": 12,
      "name": "Deco_Bone_Full"
    },
    {
      "x": -9,
      "y": 22,
      "z": 13,
      "name": "Deco_Bone_Full"
    },
    {
      "x": -9,
      "y": 23,
      "z": 13,
      "name": "Deco_Bone_Full"
    },
    {
      "x": -9,
      "y": 24,
      "z": 13,
      "name": "Deco_Bone_Full"
    },
    {
      "x": -9,
      "y": 25,
      "z": 13,
      "name": "Deco_Bone_Full"
    },
    {
      "x": -9,
      "y": 23,
      "z": 14,
      "name": "Deco_Bone_Full"
    },
    {
      "x": -9,
      "y": 19,
      "z": 20,
      "name": "Deco_Bone_Full"
    },
    {
      "x": -9,
      "y": 7,
      "z": 21,
      "name": "Deco_Bone_Full"
    },
    {
      "x": -9,
      "y": 8,
      "z": 21,
      "name": "Deco_Bone_Full"
    },
    {
      "x": -9,
      "y": 18,
      "z": 21,
      "name": "Deco_Bone_Full"
    },
    {
      "x": -9,
      "y": 19,
      "z": 21,
      "name": "Deco_Bone_Full"
    },
    {
      "x": -9,
      "y": 20,
      "z": 21,
      "name": "Deco_Bone_Full"
    },
    {
      "x": -9,
      "y": 17,
      "z": 22,
      "name": "Deco_Bone_Full"
    },
    {
      "x": -9,
      "y": 18,
      "z": 22,
      "name": "Deco_Bone_Full"
    },
    {
      "x": -8,
      "y": 17,
      "z": 1,
      "name": "Deco_Bone_Full"
    },
    {
      "x": -8,
      "y": 18,
      "z": 1,
      "name": "Deco_Bone_Full"
    },
    {
      "x": -8,
      "y": 7,
      "z": 2,
      "name": "Deco_Bone_Full"
    },
    {
      "x": -8,
      "y": 8,
      "z": 2,
      "name": "Deco_Bone_Full"
    },
    {
      "x": -8,
      "y": 9,
      "z": 2,
      "name": "Deco_Bone_Full"
    },
    {
      "x": -8,
      "y": 10,
      "z": 2,
      "name": "Deco_Bone_Full"
    },
    {
      "x": -8,
      "y": 16,
      "z": 2,
      "name": "Deco_Bone_Full"
    },
    {
      "x": -8,
      "y": 17,
      "z": 2,
      "name": "Deco_Bone_Full"
    },
    {
      "x": -8,
      "y": 18,
      "z": 2,
      "name": "Deco_Bone_Full"
    },
    {
      "x": -8,
      "y": 19,
      "z": 2,
      "name": "Deco_Bone_Full"
    },
    {
      "x": -8,
      "y": 20,
      "z": 2,
      "name": "Deco_Bone_Full"
    },
    {
      "x": -8,
      "y": 18,
      "z": 3,
      "name": "Deco_Bone_Full"
    },
    {
      "x": -8,
      "y": 19,
      "z": 3,
      "name": "Deco_Bone_Full"
    },
    {
      "x": -8,
      "y": 23,
      "z": 10,
      "name": "Deco_Bone_Full"
    },
    {
      "x": -8,
      "y": 22,
      "z": 11,
      "name": "Deco_Bone_Full"
    },
    {
      "x": -8,
      "y": 23,
      "z": 11,
      "name": "Deco_Bone_Full"
    },
    {
      "x": -8,
      "y": 24,
      "z": 11,
      "name": "Deco_Bone_Full"
    },
    {
      "x": -8,
      "y": 25,
      "z": 11,
      "name": "Deco_Bone_Full"
    },
    {
      "x": -8,
      "y": 22,
      "z": 12,
      "name": "Deco_Bone_Full"
    },
    {
      "x": -8,
      "y": 23,
      "z": 12,
      "name": "Deco_Bone_Full"
    },
    {
      "x": -8,
      "y": 24,
      "z": 12,
      "name": "Deco_Bone_Full"
    },
    {
      "x": -8,
      "y": 25,
      "z": 12,
      "name": "Deco_Bone_Full"
    },
    {
      "x": -8,
      "y": 26,
      "z": 12,
      "name": "Deco_Bone_Full"
    },
    {
      "x": -8,
      "y": 22,
      "z": 13,
      "name": "Deco_Bone_Full"
    },
    {
      "x": -8,
      "y": 23,
      "z": 13,
      "name": "Deco_Bone_Full"
    },
    {
      "x": -8,
      "y": 24,
      "z": 13,
      "name": "Deco_Bone_Full"
    },
    {
      "x": -8,
      "y": 23,
      "z": 14,
      "name": "Deco_Bone_Full"
    },
    {
      "x": -8,
      "y": 17,
      "z": 21,
      "name": "Deco_Bone_Full"
    },
    {
      "x": -8,
      "y": 18,
      "z": 21,
      "name": "Deco_Bone_Full"
    },
    {
      "x": -8,
      "y": 8,
      "z": 22,
      "name": "Deco_Bone_Full"
    },
    {
      "x": -8,
      "y": 9,
      "z": 22,
      "name": "Deco_Bone_Full"
    },
    {
      "x": -8,
      "y": 10,
      "z": 22,
      "name": "Deco_Bone_Full"
    },
    {
      "x": -8,
      "y": 11,
      "z": 22,
      "name": "Deco_Bone_Full"
    },
    {
      "x": -8,
      "y": 15,
      "z": 22,
      "name": "Deco_Bone_Full"
    },
    {
      "x": -8,
      "y": 16,
      "z": 22,
      "name": "Deco_Bone_Full"
    },
    {
      "x": -8,
      "y": 17,
      "z": 22,
      "name": "Deco_Bone_Full"
    },
    {
      "x": -8,
      "y": 18,
      "z": 22,
      "name": "Deco_Bone_Full"
    },
    {
      "x": -8,
      "y": 19,
      "z": 22,
      "name": "Deco_Bone_Full"
    },
    {
      "x": -8,
      "y": 16,
      "z": 23,
      "name": "Deco_Bone_Full"
    },
    {
      "x": -8,
      "y": 17,
      "z": 23,
      "name": "Deco_Bone_Full"
    },
    {
      "x": -7,
      "y": 18,
      "z": 2,
      "name": "Deco_Bone_Full"
    },
    {
      "x": -7,
      "y": 19,
      "z": 2,
      "name": "Deco_Bone_Full"
    },
    {
      "x": -7,
      "y": 19,
      "z": 3,
      "name": "Deco_Bone_Full"
    },
    {
      "x": -7,
      "y": 20,
      "z": 3,
      "name": "Deco_Bone_Full"
    },
    {
      "x": -7,
      "y": 21,
      "z": 3,
      "name": "Deco_Bone_Full"
    },
    {
      "x": -7,
      "y": 20,
      "z": 4,
      "name": "Deco_Bone_Full"
    },
    {
      "x": -7,
      "y": 23,
      "z": 10,
      "name": "Deco_Bone_Full"
    },
    {
      "x": -7,
      "y": 24,
      "z": 10,
      "name": "Deco_Bone_Full"
    },
    {
      "x": -7,
      "y": 22,
      "z": 11,
      "name": "Deco_Bone_Full"
    },
    {
      "x": -7,
      "y": 23,
      "z": 11,
      "name": "Deco_Bone_Full"
    },
    {
      "x": -7,
      "y": 24,
      "z": 11,
      "name": "Deco_Bone_Full"
    },
    {
      "x": -7,
      "y": 25,
      "z": 11,
      "name": "Deco_Bone_Full"
    },
    {
      "x": -7,
      "y": 26,
      "z": 11,
      "name": "Deco_Bone_Full"
    },
    {
      "x": -7,
      "y": 22,
      "z": 12,
      "name": "Deco_Bone_Full"
    },
    {
      "x": -7,
      "y": 23,
      "z": 12,
      "name": "Deco_Bone_Full"
    },
    {
      "x": -7,
      "y": 24,
      "z": 12,
      "name": "Deco_Bone_Full"
    },
    {
      "x": -7,
      "y": 25,
      "z": 12,
      "name": "Deco_Bone_Full"
    },
    {
      "x": -7,
      "y": 22,
      "z": 13,
      "name": "Deco_Bone_Full"
    },
    {
      "x": -7,
      "y": 23,
      "z": 13,
      "name": "Deco_Bone_Full"
    },
    {
      "x": -7,
      "y": 22,
      "z": 14,
      "name": "Deco_Bone_Full"
    },
    {
      "x": -7,
      "y": 13,
      "z": 21,
      "name": "Empty"
    },
    {
      "x": -7,
      "y": 14,
      "z": 21,
      "name": "Empty"
    },
    {
      "x": -7,
      "y": 13,
      "z": 22,
      "name": "Plant_Crop_Health3",
      "rotation": 2
    },
    {
      "x": -7,
      "y": 14,
      "z": 22,
      "name": "Plant_Crop_Health3",
      "filler": 1024,
      "rotation": 2
    },
    {
      "x": -7,
      "y": 16,
      "z": 22,
      "name": "Deco_Bone_Full"
    },
    {
      "x": -7,
      "y": 17,
      "z": 22,
      "name": "Deco_Bone_Full"
    },
    {
      "x": -7,
      "y": 11,
      "z": 23,
      "name": "Deco_Bone_Full"
    },
    {
      "x": -7,
      "y": 12,
      "z": 23,
      "name": "Deco_Bone_Full"
    },
    {
      "x": -7,
      "y": 13,
      "z": 23,
      "name": "Deco_Bone_Full"
    },
    {
      "x": -7,
      "y": 14,
      "z": 23,
      "name": "Deco_Bone_Full"
    },
    {
      "x": -7,
      "y": 15,
      "z": 23,
      "name": "Deco_Bone_Full"
    },
    {
      "x": -7,
      "y": 16,
      "z": 23,
      "name": "Deco_Bone_Full"
    },
    {
      "x": -6,
      "y": 20,
      "z": 3,
      "name": "Deco_Bone_Full"
    },
    {
      "x": -6,
      "y": 20,
      "z": 4,
      "name": "Deco_Bone_Full"
    },
    {
      "x": -6,
      "y": 21,
      "z": 4,
      "name": "Deco_Bone_Full"
    },
    {
      "x": -6,
      "y": 22,
      "z": 4,
      "name": "Deco_Bone_Full"
    },
    {
      "x": -6,
      "y": 21,
      "z": 5,
      "name": "Deco_Bone_Full"
    },
    {
      "x": -6,
      "y": 22,
      "z": 9,
      "name": "Deco_Bone_Full"
    },
    {
      "x": -6,
      "y": 23,
      "z": 9,
      "name": "Deco_Bone_Full"
    },
    {
      "x": -6,
      "y": 22,
      "z": 10,
      "name": "Deco_Bone_Full"
    },
    {
      "x": -6,
      "y": 23,
      "z": 10,
      "name": "Deco_Bone_Full"
    },
    {
      "x": -6,
      "y": 23,
      "z": 11,
      "name": "Deco_Bone_Full"
    },
    {
      "x": -6,
      "y": 24,
      "z": 11,
      "name": "Deco_Bone_Full"
    },
    {
      "x": -6,
      "y": 23,
      "z": 12,
      "name": "Deco_Bone_Full"
    },
    {
      "x": -6,
      "y": 22,
      "z": 13,
      "name": "Deco_Bone_Full"
    },
    {
      "x": -6,
      "y": 23,
      "z": 13,
      "name": "Deco_Bone_Full"
    },
    {
      "x": -6,
      "y": 21,
      "z": 14,
      "name": "Deco_Bone_Full"
    },
    {
      "x": -6,
      "y": 22,
      "z": 14,
      "name": "Deco_Bone_Full"
    },
    {
      "x": -6,
      "y": 21,
      "z": 15,
      "name": "Deco_Bone_Full"
    },
    {
      "x": -5,
      "y": 20,
      "z": 3,
      "name": "Plant_Crop_Health3",
      "rotation": 1
    },
    {
      "x": -5,
      "y": 21,
      "z": 3,
      "name": "Plant_Crop_Health3",
      "filler": 1024,
      "rotation": 1
    },
    {
      "x": -5,
      "y": 21,
      "z": 4,
      "name": "Deco_Bone_Full"
    },
    {
      "x": -5,
      "y": 21,
      "z": 5,
      "name": "Deco_Bone_Full"
    },
    {
      "x": -5,
      "y": 22,
      "z": 5,
      "name": "Deco_Bone_Full"
    },
    {
      "x": -5,
      "y": 22,
      "z": 6,
      "name": "Deco_Bone_Full"
    },
    {
      "x": -5,
      "y": 23,
      "z": 7,
      "name": "Deco_Bone_Full"
    },
    {
      "x": -5,
      "y": 23,
      "z": 8,
      "name": "Deco_Bone_Full"
    },
    {
      "x": -5,
      "y": 23,
      "z": 9,
      "name": "Deco_Bone_Full"
    },
    {
      "x": -5,
      "y": 22,
      "z": 10,
      "name": "Deco_Bone_Full"
    },
    {
      "x": -5,
      "y": 23,
      "z": 10,
      "name": "Deco_Bone_Full"
    },
    {
      "x": -5,
      "y": 21,
      "z": 14,
      "name": "Deco_Bone_Full"
    },
    {
      "x": -5,
      "y": 4,
      "z": 15,
      "name": "Deco_Bone_Full"
    },
    {
      "x": -5,
      "y": 5,
      "z": 15,
      "name": "Deco_Bone_Full"
    },
    {
      "x": -5,
      "y": 20,
      "z": 15,
      "name": "Deco_Bone_Full"
    },
    {
      "x": -5,
      "y": 21,
      "z": 15,
      "name": "Deco_Bone_Full"
    },
    {
      "x": -5,
      "y": 22,
      "z": 15,
      "name": "Deco_Bone_Full"
    },
    {
      "x": -5,
      "y": 20,
      "z": 16,
      "name": "Deco_Bone_Full"
    },
    {
      "x": -4,
      "y": 11,
      "z": -4,
      "name": "Deco_Bone_Full"
    },
    {
      "x": -4,
      "y": 12,
      "z": -4,
      "name": "Deco_Bone_Full"
    },
    {
      "x": -4,
      "y": 13,
      "z": -4,
      "name": "Deco_Bone_Full"
    },
    {
      "x": -4,
      "y": 14,
      "z": -4,
      "name": "Deco_Bone_Full"
    },
    {
      "x": -4,
      "y": 15,
      "z": -4,
      "name": "Deco_Bone_Full"
    },
    {
      "x": -4,
      "y": 16,
      "z": -4,
      "name": "Deco_Bone_Full"
    },
    {
      "x": -4,
      "y": 17,
      "z": -4,
      "name": "Deco_Bone_Full"
    },
    {
      "x": -4,
      "y": 18,
      "z": -4,
      "name": "Deco_Bone_Full"
    },
    {
      "x": -4,
      "y": 18,
      "z": -3,
      "name": "Deco_Bone_Full"
    },
    {
      "x": -4,
      "y": 19,
      "z": -3,
      "name": "Deco_Bone_Full"
    },
    {
      "x": -4,
      "y": 20,
      "z": 3,
      "name": "Empty"
    },
    {
      "x": -4,
      "y": 21,
      "z": 3,
      "name": "Empty"
    },
    {
      "x": -4,
      "y": 22,
      "z": 5,
      "name": "Deco_Bone_Full"
    },
    {
      "x": -4,
      "y": 23,
      "z": 5,
      "name": "Deco_Bone_Full"
    },
    {
      "x": -4,
      "y": 22,
      "z": 6,
      "name": "Deco_Bone_Full"
    },
    {
      "x": -4,
      "y": 23,
      "z": 6,
      "name": "Deco_Bone_Full"
    },
    {
      "x": -4,
      "y": 22,
      "z": 7,
      "name": "Deco_Bone_Full"
    },
    {
      "x": -4,
      "y": 23,
      "z": 7,
      "name": "Deco_Bone_Full"
    },
    {
      "x": -4,
      "y": 24,
      "z": 7,
      "name": "Deco_Bone_Full"
    },
    {
      "x": -4,
      "y": 22,
      "z": 8,
      "name": "Deco_Bone_Full"
    },
    {
      "x": -4,
      "y": 23,
      "z": 8,
      "name": "Deco_Bone_Full"
    },
    {
      "x": -4,
      "y": 24,
      "z": 8,
      "name": "Deco_Bone_Full"
    },
    {
      "x": -4,
      "y": 25,
      "z": 8,
      "name": "Deco_Bone_Full"
    },
    {
      "x": -4,
      "y": 23,
      "z": 9,
      "name": "Deco_Bone_Full"
    },
    {
      "x": -4,
      "y": 20,
      "z": 15,
      "name": "Deco_Bone_Full"
    },
    {
      "x": -4,
      "y": 5,
      "z": 16,
      "name": "Deco_Bone_Full"
    },
    {
      "x": -4,
      "y": 6,
      "z": 16,
      "name": "Deco_Bone_Full"
    },
    {
      "x": -4,
      "y": 7,
      "z": 16,
      "name": "Deco_Bone_Full"
    },
    {
      "x": -4,
      "y": 19,
      "z": 16,
      "name": "Deco_Bone_Full"
    },
    {
      "x": -4,
      "y": 20,
      "z": 16,
      "name": "Deco_Bone_Full"
    },
    {
      "x": -4,
      "y": 21,
      "z": 16,
      "name": "Deco_Bone_Full"
    },
    {
      "x": -4,
      "y": 18,
      "z": 17,
      "name": "Deco_Bone_Full"
    },
    {
      "x": -4,
      "y": 19,
      "z": 17,
      "name": "Deco_Bone_Full"
    },
    {
      "x": -3,
      "y": 18,
      "z": -4,
      "name": "Deco_Bone_Full"
    },
    {
      "x": -3,
      "y": 19,
      "z": -4,
      "name": "Deco_Bone_Full"
    },
    {
      "x": -3,
      "y": 8,
      "z": -3,
      "name": "Deco_Bone_Full"
    },
    {
      "x": -3,
      "y": 9,
      "z": -3,
      "name": "Deco_Bone_Full"
    },
    {
      "x": -3,
      "y": 10,
      "z": -3,
      "name": "Deco_Bone_Full"
    },
    {
      "x": -3,
      "y": 11,
      "z": -3,
      "name": "Deco_Bone_Full"
    },
    {
      "x": -3,
      "y": 17,
      "z": -3,
      "name": "Deco_Bone_Full"
    },
    {
      "x": -3,
      "y": 18,
      "z": -3,
      "name": "Deco_Bone_Full"
    },
    {
      "x": -3,
      "y": 19,
      "z": -3,
      "name": "Deco_Bone_Full"
    },
    {
      "x": -3,
      "y": 20,
      "z": -3,
      "name": "Deco_Bone_Full"
    },
    {
      "x": -3,
      "y": 21,
      "z": -3,
      "name": "Deco_Bone_Full"
    },
    {
      "x": -3,
      "y": 19,
      "z": -2,
      "name": "Deco_Bone_Full"
    },
    {
      "x": -3,
      "y": 20,
      "z": -2,
      "name": "Deco_Bone_Full"
    },
    {
      "x": -3,
      "y": 23,
      "z": 5,
      "name": "Deco_Bone_Full"
    },
    {
      "x": -3,
      "y": 22,
      "z": 6,
      "name": "Deco_Bone_Full"
    },
    {
      "x": -3,
      "y": 23,
      "z": 6,
      "name": "Deco_Bone_Full"
    },
    {
      "x": -3,
      "y": 24,
      "z": 6,
      "name": "Deco_Bone_Full"
    },
    {
      "x": -3,
      "y": 25,
      "z": 6,
      "name": "Deco_Bone_Full"
    },
    {
      "x": -3,
      "y": 22,
      "z": 7,
      "name": "Deco_Bone_Full"
    },
    {
      "x": -3,
      "y": 23,
      "z": 7,
      "name": "Deco_Bone_Full"
    },
    {
      "x": -3,
      "y": 24,
      "z": 7,
      "name": "Deco_Bone_Full"
    },
    {
      "x": -3,
      "y": 25,
      "z": 7,
      "name": "Deco_Bone_Full"
    },
    {
      "x": -3,
      "y": 26,
      "z": 7,
      "name": "Deco_Bone_Full"
    },
    {
      "x": -3,
      "y": 22,
      "z": 8,
      "name": "Deco_Bone_Full"
    },
    {
      "x": -3,
      "y": 23,
      "z": 8,
      "name": "Deco_Bone_Full"
    },
    {
      "x": -3,
      "y": 24,
      "z": 8,
      "name": "Deco_Bone_Full"
    },
    {
      "x": -3,
      "y": 23,
      "z": 9,
      "name": "Deco_Bone_Full"
    },
    {
      "x": -3,
      "y": 18,
      "z": 16,
      "name": "Deco_Bone_Full"
    },
    {
      "x": -3,
      "y": 19,
      "z": 16,
      "name": "Deco_Bone_Full"
    },
    {
      "x": -3,
      "y": 7,
      "z": 17,
      "name": "Deco_Bone_Full"
    },
    {
      "x": -3,
      "y": 8,
      "z": 17,
      "name": "Deco_Bone_Full"
    },
    {
      "x": -3,
      "y": 9,
      "z": 17,
      "name": "Deco_Bone_Full"
    },
    {
      "x": -3,
      "y": 10,
      "z": 17,
      "name": "Deco_Bone_Full"
    },
    {
      "x": -3,
      "y": 16,
      "z": 17,
      "name": "Deco_Bone_Full"
    },
    {
      "x": -3,
      "y": 17,
      "z": 17,
      "name": "Deco_Bone_Full"
    },
    {
      "x": -3,
      "y": 18,
      "z": 17,
      "name": "Deco_Bone_Full"
    },
    {
      "x": -3,
      "y": 19,
      "z": 17,
      "name": "Deco_Bone_Full"
    },
    {
      "x": -3,
      "y": 20,
      "z": 17,
      "name": "Deco_Bone_Full"
    },
    {
      "x": -3,
      "y": 17,
      "z": 18,
      "name": "Deco_Bone_Full"
    },
    {
      "x": -3,
      "y": 18,
      "z": 18,
      "name": "Deco_Bone_Full"
    },
    {
      "x": -2,
      "y": 19,
      "z": -3,
      "name": "Deco_Bone_Full"
    },
    {
      "x": -2,
      "y": 20,
      "z": -3,
      "name": "Deco_Bone_Full"
    },
    {
      "x": -2,
      "y": 6,
      "z": -2,
      "name": "Deco_Bone_Full"
    },
    {
      "x": -2,
      "y": 7,
      "z": -2,
      "name": "Deco_Bone_Full"
    },
    {
      "x": -2,
      "y": 8,
      "z": -2,
      "name": "Deco_Bone_Full"
    },
    {
      "x": -2,
      "y": 20,
      "z": -2,
      "name": "Deco_Bone_Full"
    },
    {
      "x": -2,
      "y": 21,
      "z": -2,
      "name": "Deco_Bone_Full"
    },
    {
      "x": -2,
      "y": 22,
      "z": -2,
      "name": "Deco_Bone_Full"
    },
    {
      "x": -2,
      "y": 21,
      "z": -1,
      "name": "Deco_Bone_Full"
    },
    {
      "x": -2,
      "y": 23,
      "z": 5,
      "name": "Deco_Bone_Full"
    },
    {
      "x": -2,
      "y": 24,
      "z": 5,
      "name": "Deco_Bone_Full"
    },
    {
      "x": -2,
      "y": 22,
      "z": 6,
      "name": "Deco_Bone_Full"
    },
    {
      "x": -2,
      "y": 23,
      "z": 6,
      "name": "Deco_Bone_Full"
    },
    {
      "x": -2,
      "y": 24,
      "z": 6,
      "name": "Deco_Bone_Full"
    },
    {
      "x": -2,
      "y": 25,
      "z": 6,
      "name": "Deco_Bone_Full"
    },
    {
      "x": -2,
      "y": 26,
      "z": 6,
      "name": "Deco_Bone_Full"
    },
    {
      "x": -2,
      "y": 22,
      "z": 7,
      "name": "Deco_Bone_Full"
    },
    {
      "x": -2,
      "y": 23,
      "z": 7,
      "name": "Deco_Bone_Full"
    },
    {
      "x": -2,
      "y": 24,
      "z": 7,
      "name": "Deco_Bone_Full"
    },
    {
      "x": -2,
      "y": 25,
      "z": 7,
      "name": "Deco_Bone_Full"
    },
    {
      "x": -2,
      "y": 22,
      "z": 8,
      "name": "Deco_Bone_Full"
    },
    {
      "x": -2,
      "y": 23,
      "z": 8,
      "name": "Deco_Bone_Full"
    },
    {
      "x": -2,
      "y": 22,
      "z": 9,
      "name": "Deco_Bone_Full"
    },
    {
      "x": -2,
      "y": 17,
      "z": 17,
      "name": "Deco_Bone_Full"
    },
    {
      "x": -2,
      "y": 18,
      "z": 17,
      "name": "Deco_Bone_Full"
    },
    {
      "x": -2,
      "y": 10,
      "z": 18,
      "name": "Deco_Bone_Full"
    },
    {
      "x": -2,
      "y": 11,
      "z": 18,
      "name": "Deco_Bone_Full"
    },
    {
      "x": -2,
      "y": 12,
      "z": 18,
      "name": "Deco_Bone_Full"
    },
    {
      "x": -2,
      "y": 13,
      "z": 18,
      "name": "Deco_Bone_Full"
    },
    {
      "x": -2,
      "y": 14,
      "z": 18,
      "name": "Deco_Bone_Full"
    },
    {
      "x": -2,
      "y": 15,
      "z": 18,
      "name": "Deco_Bone_Full"
    },
    {
      "x": -2,
      "y": 16,
      "z": 18,
      "name": "Deco_Bone_Full"
    },
    {
      "x": -2,
      "y": 17,
      "z": 18,
      "name": "Deco_Bone_Full"
    },
    {
      "x": -1,
      "y": 21,
      "z": -2,
      "name": "Deco_Bone_Full"
    },
    {
      "x": -1,
      "y": 5,
      "z": -1,
      "name": "Deco_Bone_Full"
    },
    {
      "x": -1,
      "y": 6,
      "z": -1,
      "name": "Deco_Bone_Full"
    },
    {
      "x": -1,
      "y": 21,
      "z": -1,
      "name": "Deco_Bone_Full"
    },
    {
      "x": -1,
      "y": 22,
      "z": -1,
      "name": "Deco_Bone_Full"
    },
    {
      "x": -1,
      "y": 23,
      "z": -1,
      "name": "Deco_Bone_Full"
    },
    {
      "x": -1,
      "y": 22,
      "z": 0,
      "name": "Deco_Bone_Full"
    },
    {
      "x": -1,
      "y": 22,
      "z": 4,
      "name": "Deco_Bone_Full"
    },
    {
      "x": -1,
      "y": 23,
      "z": 4,
      "name": "Deco_Bone_Full"
    },
    {
      "x": -1,
      "y": 22,
      "z": 5,
      "name": "Deco_Bone_Full"
    },
    {
      "x": -1,
      "y": 23,
      "z": 5,
      "name": "Deco_Bone_Full"
    },
    {
      "x": -1,
      "y": 23,
      "z": 6,
      "name": "Deco_Bone_Full"
    },
    {
      "x": -1,
      "y": 24,
      "z": 6,
      "name": "Deco_Bone_Full"
    },
    {
      "x": -1,
      "y": 23,
      "z": 7,
      "name": "Deco_Bone_Full"
    },
    {
      "x": -1,
      "y": 22,
      "z": 8,
      "name": "Deco_Bone_Full"
    },
    {
      "x": -1,
      "y": 23,
      "z": 8,
      "name": "Deco_Bone_Full"
    },
    {
      "x": -1,
      "y": 21,
      "z": 9,
      "name": "Deco_Bone_Full"
    },
    {
      "x": -1,
      "y": 22,
      "z": 9,
      "name": "Deco_Bone_Full"
    },
    {
      "x": -1,
      "y": 21,
      "z": 10,
      "name": "Deco_Bone_Full"
    },
    {
      "x": 0,
      "y": 22,
      "z": -1,
      "name": "Deco_Bone_Full"
    },
    {
      "x": 0,
      "y": 22,
      "z": 0,
      "name": "Deco_Bone_Full"
    },
    {
      "x": 0,
      "y": 23,
      "z": 0,
      "name": "Deco_Bone_Full"
    },
    {
      "x": 0,
      "y": 23,
      "z": 1,
      "name": "Deco_Bone_Full"
    },
    {
      "x": 0,
      "y": 24,
      "z": 2,
      "name": "Deco_Bone_Full"
    },
    {
      "x": 0,
      "y": 24,
      "z": 3,
      "name": "Deco_Bone_Full"
    },
    {
      "x": 0,
      "y": 24,
      "z": 4,
      "name": "Deco_Bone_Full"
    },
    {
      "x": 0,
      "y": 22,
      "z": 5,
      "name": "Deco_Bone_Full"
    },
    {
      "x": 0,
      "y": 23,
      "z": 5,
      "name": "Deco_Bone_Full"
    },
    {
      "x": 0,
      "y": 21,
      "z": 9,
      "name": "Deco_Bone_Full"
    },
    {
      "x": 0,
      "y": 20,
      "z": 10,
      "name": "Deco_Bone_Full"
    },
    {
      "x": 0,
      "y": 21,
      "z": 10,
      "name": "Deco_Bone_Full"
    },
    {
      "x": 0,
      "y": 22,
      "z": 10,
      "name": "Deco_Bone_Full"
    },
    {
      "x": 0,
      "y": 20,
      "z": 11,
      "name": "Deco_Bone_Full"
    },
    {
      "x": 1,
      "y": 10,
      "z": -9,
      "name": "Deco_Bone_Full"
    },
    {
      "x": 1,
      "y": 11,
      "z": -9,
      "name": "Deco_Bone_Full"
    },
    {
      "x": 1,
      "y": 12,
      "z": -9,
      "name": "Deco_Bone_Full"
    },
    {
      "x": 1,
      "y": 13,
      "z": -9,
      "name": "Deco_Bone_Full"
    },
    {
      "x": 1,
      "y": 14,
      "z": -9,
      "name": "Deco_Bone_Full"
    },
    {
      "x": 1,
      "y": 15,
      "z": -9,
      "name": "Deco_Bone_Full"
    },
    {
      "x": 1,
      "y": 16,
      "z": -9,
      "name": "Deco_Bone_Full"
    },
    {
      "x": 1,
      "y": 17,
      "z": -9,
      "name": "Deco_Bone_Full"
    },
    {
      "x": 1,
      "y": 17,
      "z": -8,
      "name": "Deco_Bone_Full"
    },
    {
      "x": 1,
      "y": 18,
      "z": -8,
      "name": "Deco_Bone_Full"
    },
    {
      "x": 1,
      "y": 23,
      "z": 0,
      "name": "Deco_Bone_Full"
    },
    {
      "x": 1,
      "y": 24,
      "z": 0,
      "name": "Deco_Bone_Full"
    },
    {
      "x": 1,
      "y": 23,
      "z": 1,
      "name": "Deco_Bone_Full"
    },
    {
      "x": 1,
      "y": 24,
      "z": 1,
      "name": "Deco_Bone_Full"
    },
    {
      "x": 1,
      "y": 23,
      "z": 2,
      "name": "Deco_Bone_Full"
    },
    {
      "x": 1,
      "y": 24,
      "z": 2,
      "name": "Deco_Bone_Full"
    },
    {
      "x": 1,
      "y": 25,
      "z": 2,
      "name": "Deco_Bone_Full"
    },
    {
      "x": 1,
      "y": 23,
      "z": 3,
      "name": "Deco_Bone_Full"
    },
    {
      "x": 1,
      "y": 24,
      "z": 3,
      "name": "Deco_Bone_Full"
    },
    {
      "x": 1,
      "y": 25,
      "z": 3,
      "name": "Deco_Bone_Full"
    },
    {
      "x": 1,
      "y": 26,
      "z": 3,
      "name": "Deco_Bone_Full"
    },
    {
      "x": 1,
      "y": 24,
      "z": 4,
      "name": "Deco_Bone_Full"
    },
    {
      "x": 1,
      "y": 20,
      "z": 10,
      "name": "Deco_Bone_Full"
    },
    {
      "x": 1,
      "y": 19,
      "z": 11,
      "name": "Deco_Bone_Full"
    },
    {
      "x": 1,
      "y": 20,
      "z": 11,
      "name": "Deco_Bone_Full"
    },
    {
      "x": 1,
      "y": 21,
      "z": 11,
      "name": "Deco_Bone_Full"
    },
    {
      "x": 1,
      "y": 18,
      "z": 12,
      "name": "Deco_Bone_Full"
    },
    {
      "x": 1,
      "y": 19,
      "z": 12,
      "name": "Deco_Bone_Full"
    },
    {
      "x": 2,
      "y": 17,
      "z": -9,
      "name": "Deco_Bone_Full"
    },
    {
      "x": 2,
      "y": 18,
      "z": -9,
      "name": "Deco_Bone_Full"
    },
    {
      "x": 2,
      "y": 7,
      "z": -8,
      "name": "Deco_Bone_Full"
    },
    {
      "x": 2,
      "y": 8,
      "z": -8,
      "name": "Deco_Bone_Full"
    },
    {
      "x": 2,
      "y": 9,
      "z": -8,
      "name": "Deco_Bone_Full"
    },
    {
      "x": 2,
      "y": 10,
      "z": -8,
      "name": "Deco_Bone_Full"
    },
    {
      "x": 2,
      "y": 16,
      "z": -8,
      "name": "Deco_Bone_Full"
    },
    {
      "x": 2,
      "y": 17,
      "z": -8,
      "name": "Deco_Bone_Full"
    },
    {
      "x": 2,
      "y": 18,
      "z": -8,
      "name": "Deco_Bone_Full"
    },
    {
      "x": 2,
      "y": 19,
      "z": -8,
      "name": "Deco_Bone_Full"
    },
    {
      "x": 2,
      "y": 20,
      "z": -8,
      "name": "Deco_Bone_Full"
    },
    {
      "x": 2,
      "y": 18,
      "z": -7,
      "name": "Deco_Bone_Full"
    },
    {
      "x": 2,
      "y": 19,
      "z": -7,
      "name": "Deco_Bone_Full"
    },
    {
      "x": 2,
      "y": 24,
      "z": 0,
      "name": "Deco_Bone_Full"
    },
    {
      "x": 2,
      "y": 23,
      "z": 1,
      "name": "Deco_Bone_Full"
    },
    {
      "x": 2,
      "y": 24,
      "z": 1,
      "name": "Deco_Bone_Full"
    },
    {
      "x": 2,
      "y": 25,
      "z": 1,
      "name": "Deco_Bone_Full"
    },
    {
      "x": 2,
      "y": 26,
      "z": 1,
      "name": "Deco_Bone_Full"
    },
    {
      "x": 2,
      "y": 23,
      "z": 2,
      "name": "Deco_Bone_Full"
    },
    {
      "x": 2,
      "y": 24,
      "z": 2,
      "name": "Deco_Bone_Full"
    },
    {
      "x": 2,
      "y": 25,
      "z": 2,
      "name": "Deco_Bone_Full"
    },
    {
      "x": 2,
      "y": 26,
      "z": 2,
      "name": "Deco_Bone_Full"
    },
    {
      "x": 2,
      "y": 27,
      "z": 2,
      "name": "Deco_Bone_Full"
    },
    {
      "x": 2,
      "y": 23,
      "z": 3,
      "name": "Deco_Bone_Full"
    },
    {
      "x": 2,
      "y": 24,
      "z": 3,
      "name": "Deco_Bone_Full"
    },
    {
      "x": 2,
      "y": 25,
      "z": 3,
      "name": "Deco_Bone_Full"
    },
    {
      "x": 2,
      "y": 24,
      "z": 4,
      "name": "Deco_Bone_Full"
    },
    {
      "x": 2,
      "y": 18,
      "z": 11,
      "name": "Deco_Bone_Full"
    },
    {
      "x": 2,
      "y": 19,
      "z": 11,
      "name": "Deco_Bone_Full"
    },
    {
      "x": 2,
      "y": 16,
      "z": 12,
      "name": "Deco_Bone_Full"
    },
    {
      "x": 2,
      "y": 17,
      "z": 12,
      "name": "Deco_Bone_Full"
    },
    {
      "x": 2,
      "y": 18,
      "z": 12,
      "name": "Deco_Bone_Full"
    },
    {
      "x": 2,
      "y": 19,
      "z": 12,
      "name": "Deco_Bone_Full"
    },
    {
      "x": 2,
      "y": 20,
      "z": 12,
      "name": "Deco_Bone_Full"
    },
    {
      "x": 2,
      "y": 17,
      "z": 13,
      "name": "Deco_Bone_Full"
    },
    {
      "x": 2,
      "y": 18,
      "z": 13,
      "name": "Deco_Bone_Full"
    },
    {
      "x": 3,
      "y": 18,
      "z": -8,
      "name": "Deco_Bone_Full"
    },
    {
      "x": 3,
      "y": 19,
      "z": -8,
      "name": "Deco_Bone_Full"
    },
    {
      "x": 3,
      "y": 5,
      "z": -7,
      "name": "Deco_Bone_Full"
    },
    {
      "x": 3,
      "y": 6,
      "z": -7,
      "name": "Deco_Bone_Full"
    },
    {
      "x": 3,
      "y": 7,
      "z": -7,
      "name": "Deco_Bone_Full"
    },
    {
      "x": 3,
      "y": 19,
      "z": -7,
      "name": "Deco_Bone_Full"
    },
    {
      "x": 3,
      "y": 20,
      "z": -7,
      "name": "Deco_Bone_Full"
    },
    {
      "x": 3,
      "y": 21,
      "z": -7,
      "name": "Deco_Bone_Full"
    },
    {
      "x": 3,
      "y": 20,
      "z": -6,
      "name": "Deco_Bone_Full"
    },
    {
      "x": 3,
      "y": 24,
      "z": 0,
      "name": "Deco_Bone_Full"
    },
    {
      "x": 3,
      "y": 25,
      "z": 0,
      "name": "Deco_Bone_Full"
    },
    {
      "x": 3,
      "y": 23,
      "z": 1,
      "name": "Deco_Bone_Full"
    },
    {
      "x": 3,
      "y": 24,
      "z": 1,
      "name": "Deco_Bone_Full"
    },
    {
      "x": 3,
      "y": 25,
      "z": 1,
      "name": "Deco_Bone_Full"
    },
    {
      "x": 3,
      "y": 26,
      "z": 1,
      "name": "Deco_Bone_Full"
    },
    {
      "x": 3,
      "y": 27,
      "z": 1,
      "name": "Deco_Bone_Full"
    },
    {
      "x": 3,
      "y": 23,
      "z": 2,
      "name": "Deco_Bone_Full"
    },
    {
      "x": 3,
      "y": 24,
      "z": 2,
      "name": "Deco_Bone_Full"
    },
    {
      "x": 3,
      "y": 25,
      "z": 2,
      "name": "Deco_Bone_Full"
    },
    {
      "x": 3,
      "y": 26,
      "z": 2,
      "name": "Deco_Bone_Full"
    },
    {
      "x": 3,
      "y": 23,
      "z": 3,
      "name": "Deco_Bone_Full"
    },
    {
      "x": 3,
      "y": 24,
      "z": 3,
      "name": "Deco_Bone_Full"
    },
    {
      "x": 3,
      "y": 23,
      "z": 4,
      "name": "Deco_Bone_Full"
    },
    {
      "x": 3,
      "y": 17,
      "z": 12,
      "name": "Deco_Bone_Full"
    },
    {
      "x": 3,
      "y": 18,
      "z": 12,
      "name": "Deco_Bone_Full"
    },
    {
      "x": 3,
      "y": 13,
      "z": 13,
      "name": "Deco_Bone_Full"
    },
    {
      "x": 3,
      "y": 14,
      "z": 13,
      "name": "Deco_Bone_Full"
    },
    {
      "x": 3,
      "y": 15,
      "z": 13,
      "name": "Deco_Bone_Full"
    },
    {
      "x": 3,
      "y": 16,
      "z": 13,
      "name": "Deco_Bone_Full"
    },
    {
      "x": 3,
      "y": 17,
      "z": 13,
      "name": "Deco_Bone_Full"
    },
    {
      "x": 4,
      "y": 20,
      "z": -7,
      "name": "Deco_Bone_Full"
    },
    {
      "x": 4,
      "y": 4,
      "z": -6,
      "name": "Deco_Bone_Full"
    },
    {
      "x": 4,
      "y": 5,
      "z": -6,
      "name": "Deco_Bone_Full"
    },
    {
      "x": 4,
      "y": 20,
      "z": -6,
      "name": "Deco_Bone_Full"
    },
    {
      "x": 4,
      "y": 21,
      "z": -6,
      "name": "Deco_Bone_Full"
    },
    {
      "x": 4,
      "y": 22,
      "z": -6,
      "name": "Deco_Bone_Full"
    },
    {
      "x": 4,
      "y": 21,
      "z": -5,
      "name": "Deco_Bone_Full"
    },
    {
      "x": 4,
      "y": 23,
      "z": -1,
      "name": "Deco_Bone_Full"
    },
    {
      "x": 4,
      "y": 24,
      "z": -1,
      "name": "Deco_Bone_Full"
    },
    {
      "x": 4,
      "y": 23,
      "z": 0,
      "name": "Deco_Bone_Full"
    },
    {
      "x": 4,
      "y": 24,
      "z": 0,
      "name": "Deco_Bone_Full"
    },
    {
      "x": 4,
      "y": 24,
      "z": 1,
      "name": "Deco_Bone_Full"
    },
    {
      "x": 4,
      "y": 25,
      "z": 1,
      "name": "Deco_Bone_Full"
    },
    {
      "x": 4,
      "y": 24,
      "z": 2,
      "name": "Deco_Bone_Full"
    },
    {
      "x": 4,
      "y": 23,
      "z": 3,
      "name": "Deco_Bone_Full"
    },
    {
      "x": 4,
      "y": 24,
      "z": 3,
      "name": "Deco_Bone_Full"
    },
    {
      "x": 4,
      "y": 22,
      "z": 4,
      "name": "Deco_Bone_Full"
    },
    {
      "x": 4,
      "y": 23,
      "z": 4,
      "name": "Deco_Bone_Full"
    },
    {
      "x": 4,
      "y": 22,
      "z": 5,
      "name": "Deco_Bone_Full"
    },
    {
      "x": 5,
      "y": 21,
      "z": -6,
      "name": "Deco_Bone_Full"
    },
    {
      "x": 5,
      "y": 21,
      "z": -5,
      "name": "Deco_Bone_Full"
    },
    {
      "x": 5,
      "y": 22,
      "z": -5,
      "name": "Deco_Bone_Full"
    },
    {
      "x": 5,
      "y": 22,
      "z": -4,
      "name": "Deco_Bone_Full"
    },
    {
      "x": 5,
      "y": 23,
      "z": -3,
      "name": "Deco_Bone_Full"
    },
    {
      "x": 5,
      "y": 23,
      "z": -2,
      "name": "Deco_Bone_Full"
    },
    {
      "x": 5,
      "y": 23,
      "z": -1,
      "name": "Deco_Bone_Full"
    },
    {
      "x": 5,
      "y": 23,
      "z": 0,
      "name": "Deco_Bone_Full"
    },
    {
      "x": 5,
      "y": 24,
      "z": 0,
      "name": "Deco_Bone_Full"
    },
    {
      "x": 5,
      "y": 22,
      "z": 4,
      "name": "Deco_Bone_Full"
    },
    {
      "x": 5,
      "y": 5,
      "z": 5,
      "name": "Deco_Bone_Full"
    },
    {
      "x": 5,
      "y": 6,
      "z": 5,
      "name": "Deco_Bone_Full"
    },
    {
      "x": 5,
      "y": 21,
      "z": 5,
      "name": "Deco_Bone_Full"
    },
    {
      "x": 5,
      "y": 22,
      "z": 5,
      "name": "Deco_Bone_Full"
    },
    {
      "x": 5,
      "y": 23,
      "z": 5,
      "name": "Deco_Bone_Full"
    },
    {
      "x": 5,
      "y": 21,
      "z": 6,
      "name": "Deco_Bone_Full"
    },
    {
      "x": 6,
      "y": 22,
      "z": -5,
      "name": "Deco_Bone_Full"
    },
    {
      "x": 6,
      "y": 23,
      "z": -5,
      "name": "Deco_Bone_Full"
    },
    {
      "x": 6,
      "y": 22,
      "z": -4,
      "name": "Deco_Bone_Full"
    },
    {
      "x": 6,
      "y": 23,
      "z": -4,
      "name": "Deco_Bone_Full"
    },
    {
      "x": 6,
      "y": 22,
      "z": -3,
      "name": "Deco_Bone_Full"
    },
    {
      "x": 6,
      "y": 23,
      "z": -3,
      "name": "Deco_Bone_Full"
    },
    {
      "x": 6,
      "y": 24,
      "z": -3,
      "name": "Deco_Bone_Full"
    },
    {
      "x": 6,
      "y": 22,
      "z": -2,
      "name": "Deco_Bone_Full"
    },
    {
      "x": 6,
      "y": 23,
      "z": -2,
      "name": "Deco_Bone_Full"
    },
    {
      "x": 6,
      "y": 24,
      "z": -2,
      "name": "Deco_Bone_Full"
    },
    {
      "x": 6,
      "y": 25,
      "z": -2,
      "name": "Deco_Bone_Full"
    },
    {
      "x": 6,
      "y": 23,
      "z": -1,
      "name": "Deco_Bone_Full"
    },
    {
      "x": 6,
      "y": 21,
      "z": 5,
      "name": "Deco_Bone_Full"
    },
    {
      "x": 6,
      "y": 6,
      "z": 6,
      "name": "Deco_Bone_Full"
    },
    {
      "x": 6,
      "y": 7,
      "z": 6,
      "name": "Deco_Bone_Full"
    },
    {
      "x": 6,
      "y": 8,
      "z": 6,
      "name": "Deco_Bone_Full"
    },
    {
      "x": 6,
      "y": 20,
      "z": 6,
      "name": "Deco_Bone_Full"
    },
    {
      "x": 6,
      "y": 21,
      "z": 6,
      "name": "Deco_Bone_Full"
    },
    {
      "x": 6,
      "y": 22,
      "z": 6,
      "name": "Deco_Bone_Full"
    },
    {
      "x": 6,
      "y": 19,
      "z": 7,
      "name": "Deco_Bone_Full"
    },
    {
      "x": 6,
      "y": 20,
      "z": 7,
      "name": "Deco_Bone_Full"
    },
    {
      "x": 7,
      "y": 17,
      "z": -13,
      "name": "Deco_Bone_Full"
    },
    {
      "x": 7,
      "y": 18,
      "z": -13,
      "name": "Deco_Bone_Full"
    },
    {
      "x": 7,
      "y": 18,
      "z": -12,
      "name": "Deco_Bone_Full"
    },
    {
      "x": 7,
      "y": 19,
      "z": -12,
      "name": "Deco_Bone_Full"
    },
    {
      "x": 7,
      "y": 23,
      "z": -5,
      "name": "Deco_Bone_Full"
    },
    {
      "x": 7,
      "y": 22,
      "z": -4,
      "name": "Deco_Bone_Full"
    },
    {
      "x": 7,
      "y": 23,
      "z": -4,
      "name": "Deco_Bone_Full"
    },
    {
      "x": 7,
      "y": 24,
      "z": -4,
      "name": "Deco_Bone_Full"
    },
    {
      "x": 7,
      "y": 25,
      "z": -4,
      "name": "Deco_Bone_Full"
    },
    {
      "x": 7,
      "y": 22,
      "z": -3,
      "name": "Deco_Bone_Full"
    },
    {
      "x": 7,
      "y": 23,
      "z": -3,
      "name": "Deco_Bone_Full"
    },
    {
      "x": 7,
      "y": 24,
      "z": -3,
      "name": "Deco_Bone_Full"
    },
    {
      "x": 7,
      "y": 25,
      "z": -3,
      "name": "Deco_Bone_Full"
    },
    {
      "x": 7,
      "y": 26,
      "z": -3,
      "name": "Deco_Bone_Full"
    },
    {
      "x": 7,
      "y": 22,
      "z": -2,
      "name": "Deco_Bone_Full"
    },
    {
      "x": 7,
      "y": 23,
      "z": -2,
      "name": "Deco_Bone_Full"
    },
    {
      "x": 7,
      "y": 24,
      "z": -2,
      "name": "Deco_Bone_Full"
    },
    {
      "x": 7,
      "y": 23,
      "z": -1,
      "name": "Deco_Bone_Full"
    },
    {
      "x": 7,
      "y": 19,
      "z": 6,
      "name": "Deco_Bone_Full"
    },
    {
      "x": 7,
      "y": 20,
      "z": 6,
      "name": "Deco_Bone_Full"
    },
    {
      "x": 7,
      "y": 8,
      "z": 7,
      "name": "Deco_Bone_Full"
    },
    {
      "x": 7,
      "y": 9,
      "z": 7,
      "name": "Deco_Bone_Full"
    },
    {
      "x": 7,
      "y": 10,
      "z": 7,
      "name": "Deco_Bone_Full"
    },
    {
      "x": 7,
      "y": 11,
      "z": 7,
      "name": "Deco_Bone_Full"
    },
    {
      "x": 7,
      "y": 17,
      "z": 7,
      "name": "Deco_Bone_Full"
    },
    {
      "x": 7,
      "y": 18,
      "z": 7,
      "name": "Deco_Bone_Full"
    },
    {
      "x": 7,
      "y": 19,
      "z": 7,
      "name": "Deco_Bone_Full"
    },
    {
      "x": 7,
      "y": 20,
      "z": 7,
      "name": "Deco_Bone_Full"
    },
    {
      "x": 7,
      "y": 21,
      "z": 7,
      "name": "Deco_Bone_Full"
    },
    {
      "x": 7,
      "y": 18,
      "z": 8,
      "name": "Deco_Bone_Full"
    },
    {
      "x": 7,
      "y": 19,
      "z": 8,
      "name": "Deco_Bone_Full"
    },
    {
      "x": 8,
      "y": 18,
      "z": -13,
      "name": "Deco_Bone_Full"
    },
    {
      "x": 8,
      "y": 19,
      "z": -13,
      "name": "Deco_Bone_Full"
    },
    {
      "x": 8,
      "y": 19,
      "z": -12,
      "name": "Deco_Bone_Full"
    },
    {
      "x": 8,
      "y": 20,
      "z": -12,
      "name": "Deco_Bone_Full"
    },
    {
      "x": 8,
      "y": 21,
      "z": -12,
      "name": "Deco_Bone_Full"
    },
    {
      "x": 8,
      "y": 20,
      "z": -11,
      "name": "Deco_Bone_Full"
    },
    {
      "x": 8,
      "y": 23,
      "z": -5,
      "name": "Deco_Bone_Full"
    },
    {
      "x": 8,
      "y": 24,
      "z": -5,
      "name": "Deco_Bone_Full"
    },
    {
      "x": 8,
      "y": 22,
      "z": -4,
      "name": "Deco_Bone_Full"
    },
    {
      "x": 8,
      "y": 23,
      "z": -4,
      "name": "Deco_Bone_Full"
    },
    {
      "x": 8,
      "y": 24,
      "z": -4,
      "name": "Deco_Bone_Full"
    },
    {
      "x": 8,
      "y": 25,
      "z": -4,
      "name": "Deco_Bone_Full"
    },
    {
      "x": 8,
      "y": 26,
      "z": -4,
      "name": "Deco_Bone_Full"
    },
    {
      "x": 8,
      "y": 22,
      "z": -3,
      "name": "Deco_Bone_Full"
    },
    {
      "x": 8,
      "y": 23,
      "z": -3,
      "name": "Deco_Bone_Full"
    },
    {
      "x": 8,
      "y": 24,
      "z": -3,
      "name": "Deco_Bone_Full"
    },
    {
      "x": 8,
      "y": 25,
      "z": -3,
      "name": "Deco_Bone_Full"
    },
    {
      "x": 8,
      "y": 22,
      "z": -2,
      "name": "Deco_Bone_Full"
    },
    {
      "x": 8,
      "y": 23,
      "z": -2,
      "name": "Deco_Bone_Full"
    },
    {
      "x": 8,
      "y": 22,
      "z": -1,
      "name": "Deco_Bone_Full"
    },
    {
      "x": 8,
      "y": 18,
      "z": 7,
      "name": "Deco_Bone_Full"
    },
    {
      "x": 8,
      "y": 19,
      "z": 7,
      "name": "Deco_Bone_Full"
    },
    {
      "x": 8,
      "y": 11,
      "z": 8,
      "name": "Deco_Bone_Full"
    },
    {
      "x": 8,
      "y": 12,
      "z": 8,
      "name": "Deco_Bone_Full"
    },
    {
      "x": 8,
      "y": 13,
      "z": 8,
      "name": "Deco_Bone_Full"
    },
    {
      "x": 8,
      "y": 14,
      "z": 8,
      "name": "Deco_Bone_Full"
    },
    {
      "x": 8,
      "y": 15,
      "z": 8,
      "name": "Deco_Bone_Full"
    },
    {
      "x": 8,
      "y": 16,
      "z": 8,
      "name": "Deco_Bone_Full"
    },
    {
      "x": 8,
      "y": 17,
      "z": 8,
      "name": "Deco_Bone_Full"
    },
    {
      "x": 8,
      "y": 18,
      "z": 8,
      "name": "Deco_Bone_Full"
    },
    {
      "x": 9,
      "y": 20,
      "z": -12,
      "name": "Deco_Bone_Full"
    },
    {
      "x": 9,
      "y": 20,
      "z": -11,
      "name": "Deco_Bone_Full"
    },
    {
      "x": 9,
      "y": 21,
      "z": -11,
      "name": "Deco_Bone_Full"
    },
    {
      "x": 9,
      "y": 22,
      "z": -11,
      "name": "Deco_Bone_Full"
    },
    {
      "x": 9,
      "y": 21,
      "z": -10,
      "name": "Deco_Bone_Full"
    },
    {
      "x": 9,
      "y": 22,
      "z": -6,
      "name": "Deco_Bone_Full"
    },
    {
      "x": 9,
      "y": 23,
      "z": -6,
      "name": "Deco_Bone_Full"
    },
    {
      "x": 9,
      "y": 22,
      "z": -5,
      "name": "Deco_Bone_Full"
    },
    {
      "x": 9,
      "y": 23,
      "z": -5,
      "name": "Deco_Bone_Full"
    },
    {
      "x": 9,
      "y": 23,
      "z": -4,
      "name": "Deco_Bone_Full"
    },
    {
      "x": 9,
      "y": 24,
      "z": -4,
      "name": "Deco_Bone_Full"
    },
    {
      "x": 9,
      "y": 23,
      "z": -3,
      "name": "Deco_Bone_Full"
    },
    {
      "x": 9,
      "y": 22,
      "z": -2,
      "name": "Deco_Bone_Full"
    },
    {
      "x": 9,
      "y": 23,
      "z": -2,
      "name": "Deco_Bone_Full"
    },
    {
      "x": 9,
      "y": 21,
      "z": -1,
      "name": "Deco_Bone_Full"
    },
    {
      "x": 9,
      "y": 22,
      "z": -1,
      "name": "Deco_Bone_Full"
    },
    {
      "x": 9,
      "y": 21,
      "z": 0,
      "name": "Deco_Bone_Full"
    },
    {
      "x": 10,
      "y": 21,
      "z": -11,
      "name": "Deco_Bone_Full"
    },
    {
      "x": 10,
      "y": 21,
      "z": -10,
      "name": "Deco_Bone_Full"
    },
    {
      "x": 10,
      "y": 22,
      "z": -10,
      "name": "Deco_Bone_Full"
    },
    {
      "x": 10,
      "y": 22,
      "z": -9,
      "name": "Deco_Bone_Full"
    },
    {
      "x": 10,
      "y": 23,
      "z": -8,
      "name": "Deco_Bone_Full"
    },
    {
      "x": 10,
      "y": 23,
      "z": -7,
      "name": "Deco_Bone_Full"
    },
    {
      "x": 10,
      "y": 23,
      "z": -6,
      "name": "Deco_Bone_Full"
    },
    {
      "x": 10,
      "y": 22,
      "z": -5,
      "name": "Deco_Bone_Full"
    },
    {
      "x": 10,
      "y": 23,
      "z": -5,
      "name": "Deco_Bone_Full"
    },
    {
      "x": 10,
      "y": 21,
      "z": -1,
      "name": "Deco_Bone_Full"
    },
    {
      "x": 10,
      "y": 20,
      "z": 0,
      "name": "Deco_Bone_Full"
    },
    {
      "x": 10,
      "y": 21,
      "z": 0,
      "name": "Deco_Bone_Full"
    },
    {
      "x": 10,
      "y": 22,
      "z": 0,
      "name": "Deco_Bone_Full"
    },
    {
      "x": 10,
      "y": 20,
      "z": 1,
      "name": "Deco_Bone_Full"
    },
    {
      "x": 11,
      "y": 22,
      "z": -10,
      "name": "Deco_Bone_Full"
    },
    {
      "x": 11,
      "y": 23,
      "z": -10,
      "name": "Deco_Bone_Full"
    },
    {
      "x": 11,
      "y": 22,
      "z": -9,
      "name": "Deco_Bone_Full"
    },
    {
      "x": 11,
      "y": 23,
      "z": -9,
      "name": "Deco_Bone_Full"
    },
    {
      "x": 11,
      "y": 22,
      "z": -8,
      "name": "Deco_Bone_Full"
    },
    {
      "x": 11,
      "y": 23,
      "z": -8,
      "name": "Deco_Bone_Full"
    },
    {
      "x": 11,
      "y": 24,
      "z": -8,
      "name": "Deco_Bone_Full"
    },
    {
      "x": 11,
      "y": 22,
      "z": -7,
      "name": "Deco_Bone_Full"
    },
    {
      "x": 11,
      "y": 23,
      "z": -7,
      "name": "Deco_Bone_Full"
    },
    {
      "x": 11,
      "y": 24,
      "z": -7,
      "name": "Deco_Bone_Full"
    },
    {
      "x": 11,
      "y": 25,
      "z": -7,
      "name": "Deco_Bone_Full"
    },
    {
      "x": 11,
      "y": 23,
      "z": -6,
      "name": "Deco_Bone_Full"
    },
    {
      "x": 11,
      "y": 20,
      "z": 0,
      "name": "Deco_Bone_Full"
    },
    {
      "x": 11,
      "y": 19,
      "z": 1,
      "name": "Deco_Bone_Full"
    },
    {
      "x": 11,
      "y": 20,
      "z": 1,
      "name": "Deco_Bone_Full"
    },
    {
      "x": 11,
      "y": 21,
      "z": 1,
      "name": "Deco_Bone_Full"
    },
    {
      "x": 11,
      "y": 18,
      "z": 2,
      "name": "Deco_Bone_Full"
    },
    {
      "x": 11,
      "y": 19,
      "z": 2,
      "name": "Deco_Bone_Full"
    },
    {
      "x": 12,
      "y": 14,
      "z": -18,
      "name": "Deco_Bone_Full"
    },
    {
      "x": 12,
      "y": 15,
      "z": -18,
      "name": "Deco_Bone_Full"
    },
    {
      "x": 12,
      "y": 16,
      "z": -18,
      "name": "Deco_Bone_Full"
    },
    {
      "x": 12,
      "y": 17,
      "z": -18,
      "name": "Deco_Bone_Full"
    },
    {
      "x": 12,
      "y": 18,
      "z": -18,
      "name": "Deco_Bone_Full"
    },
    {
      "x": 12,
      "y": 17,
      "z": -17,
      "name": "Deco_Bone_Full"
    },
    {
      "x": 12,
      "y": 18,
      "z": -17,
      "name": "Deco_Bone_Full"
    },
    {
      "x": 12,
      "y": 23,
      "z": -10,
      "name": "Deco_Bone_Full"
    },
    {
      "x": 12,
      "y": 22,
      "z": -9,
      "name": "Deco_Bone_Full"
    },
    {
      "x": 12,
      "y": 23,
      "z": -9,
      "name": "Deco_Bone_Full"
    },
    {
      "x": 12,
      "y": 24,
      "z": -9,
      "name": "Deco_Bone_Full"
    },
    {
      "x": 12,
      "y": 25,
      "z": -9,
      "name": "Deco_Bone_Full"
    },
    {
      "x": 12,
      "y": 22,
      "z": -8,
      "name": "Deco_Bone_Full"
    },
    {
      "x": 12,
      "y": 23,
      "z": -8,
      "name": "Deco_Bone_Full"
    },
    {
      "x": 12,
      "y": 24,
      "z": -8,
      "name": "Deco_Bone_Full"
    },
    {
      "x": 12,
      "y": 25,
      "z": -8,
      "name": "Deco_Bone_Full"
    },
    {
      "x": 12,
      "y": 26,
      "z": -8,
      "name": "Deco_Bone_Full"
    },
    {
      "x": 12,
      "y": 22,
      "z": -7,
      "name": "Deco_Bone_Full"
    },
    {
      "x": 12,
      "y": 23,
      "z": -7,
      "name": "Deco_Bone_Full"
    },
    {
      "x": 12,
      "y": 24,
      "z": -7,
      "name": "Deco_Bone_Full"
    },
    {
      "x": 12,
      "y": 23,
      "z": -6,
      "name": "Deco_Bone_Full"
    },
    {
      "x": 12,
      "y": 18,
      "z": 1,
      "name": "Deco_Bone_Full"
    },
    {
      "x": 12,
      "y": 19,
      "z": 1,
      "name": "Deco_Bone_Full"
    },
    {
      "x": 12,
      "y": 16,
      "z": 2,
      "name": "Deco_Bone_Full"
    },
    {
      "x": 12,
      "y": 17,
      "z": 2,
      "name": "Deco_Bone_Full"
    },
    {
      "x": 12,
      "y": 18,
      "z": 2,
      "name": "Deco_Bone_Full"
    },
    {
      "x": 12,
      "y": 19,
      "z": 2,
      "name": "Deco_Bone_Full"
    },
    {
      "x": 12,
      "y": 20,
      "z": 2,
      "name": "Deco_Bone_Full"
    },
    {
      "x": 12,
      "y": 17,
      "z": 3,
      "name": "Deco_Bone_Full"
    },
    {
      "x": 12,
      "y": 18,
      "z": 3,
      "name": "Deco_Bone_Full"
    },
    {
      "x": 13,
      "y": 17,
      "z": -18,
      "name": "Deco_Bone_Full"
    },
    {
      "x": 13,
      "y": 18,
      "z": -18,
      "name": "Deco_Bone_Full"
    },
    {
      "x": 13,
      "y": 11,
      "z": -17,
      "name": "Deco_Bone_Full"
    },
    {
      "x": 13,
      "y": 12,
      "z": -17,
      "name": "Deco_Bone_Full"
    },
    {
      "x": 13,
      "y": 13,
      "z": -17,
      "name": "Deco_Bone_Full"
    },
    {
      "x": 13,
      "y": 14,
      "z": -17,
      "name": "Deco_Bone_Full"
    },
    {
      "x": 13,
      "y": 18,
      "z": -17,
      "name": "Deco_Bone_Full"
    },
    {
      "x": 13,
      "y": 19,
      "z": -17,
      "name": "Deco_Bone_Full"
    },
    {
      "x": 13,
      "y": 20,
      "z": -17,
      "name": "Deco_Bone_Full"
    },
    {
      "x": 13,
      "y": 19,
      "z": -16,
      "name": "Deco_Bone_Full"
    },
    {
      "x": 13,
      "y": 23,
      "z": -10,
      "name": "Deco_Bone_Full"
    },
    {
      "x": 13,
      "y": 24,
      "z": -10,
      "name": "Deco_Bone_Full"
    },
    {
      "x": 13,
      "y": 22,
      "z": -9,
      "name": "Deco_Bone_Full"
    },
    {
      "x": 13,
      "y": 23,
      "z": -9,
      "name": "Deco_Bone_Full"
    },
    {
      "x": 13,
      "y": 24,
      "z": -9,
      "name": "Deco_Bone_Full"
    },
    {
      "x": 13,
      "y": 25,
      "z": -9,
      "name": "Deco_Bone_Full"
    },
    {
      "x": 13,
      "y": 26,
      "z": -9,
      "name": "Deco_Bone_Full"
    },
    {
      "x": 13,
      "y": 22,
      "z": -8,
      "name": "Deco_Bone_Full"
    },
    {
      "x": 13,
      "y": 23,
      "z": -8,
      "name": "Deco_Bone_Full"
    },
    {
      "x": 13,
      "y": 24,
      "z": -8,
      "name": "Deco_Bone_Full"
    },
    {
      "x": 13,
      "y": 25,
      "z": -8,
      "name": "Deco_Bone_Full"
    },
    {
      "x": 13,
      "y": 22,
      "z": -7,
      "name": "Deco_Bone_Full"
    },
    {
      "x": 13,
      "y": 23,
      "z": -7,
      "name": "Deco_Bone_Full"
    },
    {
      "x": 13,
      "y": 22,
      "z": -6,
      "name": "Deco_Bone_Full"
    },
    {
      "x": 13,
      "y": 17,
      "z": 2,
      "name": "Deco_Bone_Full"
    },
    {
      "x": 13,
      "y": 18,
      "z": 2,
      "name": "Deco_Bone_Full"
    },
    {
      "x": 13,
      "y": 16,
      "z": 3,
      "name": "Deco_Bone_Full"
    },
    {
      "x": 13,
      "y": 17,
      "z": 3,
      "name": "Deco_Bone_Full"
    },
    {
      "x": 14,
      "y": 19,
      "z": -17,
      "name": "Deco_Bone_Full"
    },
    {
      "x": 14,
      "y": 10,
      "z": -16,
      "name": "Deco_Bone_Full"
    },
    {
      "x": 14,
      "y": 11,
      "z": -16,
      "name": "Deco_Bone_Full"
    },
    {
      "x": 14,
      "y": 19,
      "z": -16,
      "name": "Deco_Bone_Full"
    },
    {
      "x": 14,
      "y": 20,
      "z": -16,
      "name": "Deco_Bone_Full"
    },
    {
      "x": 14,
      "y": 21,
      "z": -16,
      "name": "Deco_Bone_Full"
    },
    {
      "x": 14,
      "y": 20,
      "z": -15,
      "name": "Deco_Bone_Full"
    },
    {
      "x": 14,
      "y": 21,
      "z": -11,
      "name": "Deco_Bone_Full"
    },
    {
      "x": 14,
      "y": 22,
      "z": -11,
      "name": "Deco_Bone_Full"
    },
    {
      "x": 14,
      "y": 21,
      "z": -10,
      "name": "Deco_Bone_Full"
    },
    {
      "x": 14,
      "y": 22,
      "z": -10,
      "name": "Deco_Bone_Full"
    },
    {
      "x": 14,
      "y": 23,
      "z": -9,
      "name": "Deco_Bone_Full"
    },
    {
      "x": 14,
      "y": 24,
      "z": -9,
      "name": "Deco_Bone_Full"
    },
    {
      "x": 14,
      "y": 23,
      "z": -8,
      "name": "Deco_Bone_Full"
    },
    {
      "x": 14,
      "y": 22,
      "z": -7,
      "name": "Deco_Bone_Full"
    },
    {
      "x": 14,
      "y": 23,
      "z": -7,
      "name": "Deco_Bone_Full"
    },
    {
      "x": 14,
      "y": 21,
      "z": -6,
      "name": "Deco_Bone_Full"
    },
    {
      "x": 14,
      "y": 22,
      "z": -6,
      "name": "Deco_Bone_Full"
    },
    {
      "x": 14,
      "y": 21,
      "z": -5,
      "name": "Deco_Bone_Full"
    },
    {
      "x": 15,
      "y": 20,
      "z": -16,
      "name": "Deco_Bone_Full"
    },
    {
      "x": 15,
      "y": 9,
      "z": -15,
      "name": "Deco_Bone_Full"
    },
    {
      "x": 15,
      "y": 10,
      "z": -15,
      "name": "Deco_Bone_Full"
    },
    {
      "x": 15,
      "y": 20,
      "z": -15,
      "name": "Deco_Bone_Full"
    },
    {
      "x": 15,
      "y": 21,
      "z": -15,
      "name": "Deco_Bone_Full"
    },
    {
      "x": 15,
      "y": 21,
      "z": -14,
      "name": "Deco_Bone_Full"
    },
    {
      "x": 15,
      "y": 22,
      "z": -13,
      "name": "Deco_Bone_Full"
    },
    {
      "x": 15,
      "y": 22,
      "z": -12,
      "name": "Deco_Bone_Full"
    },
    {
      "x": 15,
      "y": 22,
      "z": -11,
      "name": "Deco_Bone_Full"
    },
    {
      "x": 15,
      "y": 21,
      "z": -10,
      "name": "Deco_Bone_Full"
    },
    {
      "x": 15,
      "y": 22,
      "z": -10,
      "name": "Deco_Bone_Full"
    },
    {
      "x": 15,
      "y": 21,
      "z": -6,
      "name": "Deco_Bone_Full"
    },
    {
      "x": 15,
      "y": 22,
      "z": -5,
      "name": "Deco_Bone_Full"
    },
    {
      "x": 16,
      "y": 21,
      "z": -15,
      "name": "Deco_Bone_Full"
    },
    {
      "x": 16,
      "y": 22,
      "z": -15,
      "name": "Deco_Bone_Full"
    },
    {
      "x": 16,
      "y": 9,
      "z": -14,
      "name": "Deco_Bone_Full"
    },
    {
      "x": 16,
      "y": 21,
      "z": -14,
      "name": "Deco_Bone_Full"
    },
    {
      "x": 16,
      "y": 22,
      "z": -14,
      "name": "Deco_Bone_Full"
    },
    {
      "x": 16,
      "y": 21,
      "z": -13,
      "name": "Deco_Bone_Full"
    },
    {
      "x": 16,
      "y": 22,
      "z": -13,
      "name": "Deco_Bone_Full"
    },
    {
      "x": 16,
      "y": 23,
      "z": -13,
      "name": "Deco_Bone_Full"
    },
    {
      "x": 16,
      "y": 21,
      "z": -12,
      "name": "Deco_Bone_Full"
    },
    {
      "x": 16,
      "y": 22,
      "z": -12,
      "name": "Deco_Bone_Full"
    },
    {
      "x": 16,
      "y": 23,
      "z": -12,
      "name": "Deco_Bone_Full"
    },
    {
      "x": 16,
      "y": 24,
      "z": -12,
      "name": "Deco_Bone_Full"
    },
    {
      "x": 16,
      "y": 22,
      "z": -11,
      "name": "Deco_Bone_Full"
    },
    {
      "x": 17,
      "y": 22,
      "z": -15,
      "name": "Deco_Bone_Full"
    },
    {
      "x": 17,
      "y": 21,
      "z": -14,
      "name": "Deco_Bone_Full"
    },
    {
      "x": 17,
      "y": 22,
      "z": -14,
      "name": "Deco_Bone_Full"
    },
    {
      "x": 17,
      "y": 23,
      "z": -14,
      "name": "Deco_Bone_Full"
    },
    {
      "x": 17,
      "y": 24,
      "z": -14,
      "name": "Deco_Bone_Full"
    },
    {
      "x": 17,
      "y": 21,
      "z": -13,
      "name": "Deco_Bone_Full"
    },
    {
      "x": 17,
      "y": 22,
      "z": -13,
      "name": "Deco_Bone_Full"
    },
    {
      "x": 17,
      "y": 23,
      "z": -13,
      "name": "Deco_Bone_Full"
    },
    {
      "x": 17,
      "y": 24,
      "z": -13,
      "name": "Deco_Bone_Full"
    },
    {
      "x": 17,
      "y": 25,
      "z": -13,
      "name": "Deco_Bone_Full"
    },
    {
      "x": 17,
      "y": 21,
      "z": -12,
      "name": "Deco_Bone_Full"
    },
    {
      "x": 17,
      "y": 22,
      "z": -12,
      "name": "Deco_Bone_Full"
    },
    {
      "x": 17,
      "y": 23,
      "z": -12,
      "name": "Deco_Bone_Full"
    },
    {
      "x": 17,
      "y": 22,
      "z": -11,
      "name": "Deco_Bone_Full"
    },
    {
      "x": 18,
      "y": 22,
      "z": -15,
      "name": "Deco_Bone_Full"
    },
    {
      "x": 18,
      "y": 23,
      "z": -15,
      "name": "Deco_Bone_Full"
    },
    {
      "x": 18,
      "y": 21,
      "z": -14,
      "name": "Deco_Bone_Full"
    },
    {
      "x": 18,
      "y": 22,
      "z": -14,
      "name": "Deco_Bone_Full"
    },
    {
      "x": 18,
      "y": 23,
      "z": -14,
      "name": "Deco_Bone_Full"
    },
    {
      "x": 18,
      "y": 24,
      "z": -14,
      "name": "Deco_Bone_Full"
    },
    {
      "x": 18,
      "y": 25,
      "z": -14,
      "name": "Deco_Bone_Full"
    },
    {
      "x": 18,
      "y": 21,
      "z": -13,
      "name": "Deco_Bone_Full"
    },
    {
      "x": 18,
      "y": 22,
      "z": -13,
      "name": "Deco_Bone_Full"
    },
    {
      "x": 18,
      "y": 23,
      "z": -13,
      "name": "Deco_Bone_Full"
    },
    {
      "x": 18,
      "y": 24,
      "z": -13,
      "name": "Deco_Bone_Full"
    },
    {
      "x": 18,
      "y": 21,
      "z": -12,
      "name": "Deco_Bone_Full"
    },
    {
      "x": 18,
      "y": 22,
      "z": -12,
      "name": "Deco_Bone_Full"
    },
    {
      "x": 18,
      "y": 21,
      "z": -11,
      "name": "Deco_Bone_Full"
    },
    {
      "x": 19,
      "y": 20,
      "z": -16,
      "name": "Deco_Bone_Full"
    },
    {
      "x": 19,
      "y": 21,
      "z": -16,
      "name": "Deco_Bone_Full"
    },
    {
      "x": 19,
      "y": 20,
      "z": -15,
      "name": "Deco_Bone_Full"
    },
    {
      "x": 19,
      "y": 21,
      "z": -15,
      "name": "Deco_Bone_Full"
    },
    {
      "x": 19,
      "y": 22,
      "z": -14,
      "name": "Deco_Bone_Full"
    },
    {
      "x": 19,
      "y": 23,
      "z": -14,
      "name": "Deco_Bone_Full"
    },
    {
      "x": 19,
      "y": 22,
      "z": -13,
      "name": "Deco_Bone_Full"
    },
    {
      "x": 19,
      "y": 21,
      "z": -12,
      "name": "Deco_Bone_Full"
    },
    {
      "x": 19,
      "y": 22,
      "z": -12,
      "name": "Deco_Bone_Full"
    },
    {
      "x": 19,
      "y": 20,
      "z": -11,
      "name": "Deco_Bone_Full"
    },
    {
      "x": 19,
      "y": 21,
      "z": -11,
      "name": "Deco_Bone_Full"
    },
    {
      "x": 19,
      "y": 20,
      "z": -10,
      "name": "Deco_Bone_Full"
    },
    {
      "x": 20,
      "y": 20,
      "z": -17,
      "name": "Deco_Bone_Full"
    },
    {
      "x": 20,
      "y": 21,
      "z": -17,
      "name": "Deco_Bone_Full"
    },
    {
      "x": 20,
      "y": 20,
      "z": -16,
      "name": "Deco_Bone_Full"
    },
    {
      "x": 20,
      "y": 21,
      "z": -16,
      "name": "Deco_Bone_Full"
    },
    {
      "x": 20,
      "y": 20,
      "z": -15,
      "name": "Deco_Bone_Full"
    },
    {
      "x": 20,
      "y": 21,
      "z": -15,
      "name": "Deco_Bone_Full"
    },
    {
      "x": 20,
      "y": 20,
      "z": -11,
      "name": "Deco_Bone_Full"
    },
    {
      "x": 20,
      "y": 19,
      "z": -10,
      "name": "Deco_Bone_Full"
    },
    {
      "x": 20,
      "y": 20,
      "z": -10,
      "name": "Deco_Bone_Full"
    },
    {
      "x": 20,
      "y": 21,
      "z": -10,
      "name": "Deco_Bone_Full"
    },
    {
      "x": 21,
      "y": 20,
      "z": -17,
      "name": "Deco_Bone_Full"
    },
    {
      "x": 21,
      "y": 21,
      "z": -17,
      "name": "Deco_Bone_Full"
    },
    {
      "x": 21,
      "y": 20,
      "z": -16,
      "name": "Deco_Bone_Full"
    },
    {
      "x": 21,
      "y": 21,
      "z": -16,
      "name": "Deco_Bone_Full"
    }
  ]
}