{
  "version": 8,
  "blockIdVersion": 8,
  "anchorX": 2,
  "anchorY": 11,
  "anchorZ": 2,
  "blocks": [
    {
      "x": -18,
      "y": 10,
      "z": 13,
      "name": "Deco_Bone_Full"
    },
    {
      "x": -18,
      "y": 11,
      "z": 13,
      "name": "Deco_Bone_Full"
    },
    {
      "x": -18,
      "y": 12,
      "z": 13,
      "name": "Deco_Bone_Full"
    },
    {
      "x": -18,
      "y": 13,
      "z": 13,
      "name": "Deco_Bone_Full"
    },
    {
      "x": -18,
      "y": 14,
      "z": 13,
      "name": "Deco_Bone_Full"
    },
    {
      "x": -18,
      "y": 15,
      "z": 13,
      "name": "Deco_Bone_Full"
    },
    {
      "x": -18,
      "y": 15,
      "z": 14,
      "name": "Deco_Bone_Full"
    },
    {
      "x": -18,
      "y": 16,
      "z": 14,
      "name": "Deco_Bone_Full"
    },
    {
      "x": -18,
      "y": 17,
      "z": 14,
      "name": "Deco_Bone_Full"
    },
    {
      "x": -18,
      "y": 16,
      "z": 15,
      "name": "Deco_Bone_Full"
    },
    {
      "x": -18,
      "y": 17,
      "z": 15,
      "name": "Deco_Bone_Full"
    },
    {
      "x": -18,
      "y": 18,
      "z": 15,
      "name": "Deco_Bone_Full"
    },
    {
      "x": -18,
      "y": 17,
      "z": 16,
      "name": "Deco_Bone_Full"
    },
    {
      "x": -18,
      "y": 17,
      "z": 21,
      "name": "Deco_Bone_Full"
    },
    {
      "x": -18,
      "y": 17,
      "z": 22,
      "name": "Deco_Bone_Full"
    },
    {
      "x": -18,
      "y": 18,
      "z": 22,
      "name": "Deco_Bone_Full"
    },
    {
      "x": -17,
      "y": 8,
      "z": 13,
      "name": "Deco_Bone_Full"
    },
    {
      "x": -17,
      "y": 9,
      "z": 13,
      "name": "Deco_Bone_Full"
    },
    {
      "x": -17,
      "y": 17,
      "z": 15,
      "name": "Deco_Bone_Full"
    },
    {
      "x": -17,
      "y": 17,
      "z": 16,
      "name": "Deco_Bone_Full"
    },
    {
      "x": -17,
      "y": 18,
      "z": 16,
      "name": "Deco_Bone_Full"
    },
    {
      "x": -17,
      "y": 19,
      "z": 16,
      "name": "Deco_Bone_Full"
    },
    {
      "x": -17,
      "y": 18,
      "z": 17,
      "name": "Deco_Bone_Full"
    },
    {
      "x": -17,
      "y": 18,
      "z": 19,
      "name": "Deco_Bone_Full"
    },
    {
      "x": -17,
      "y": 18,
      "z": 20,
      "name": "Deco_Bone_Full"
    },
    {
      "x": -17,
      "y": 17,
      "z": 21,
      "name": "Deco_Bone_Full"
    },
    {
      "x": -17,
      "y": 18,
      "z": 21,
      "name": "Deco_Bone_Full"
    },
    {
      "x": -17,
      "y": 19,
      "z": 21,
      "name": "Deco_Bone_Full"
    },
    {
      "x": -17,
      "y": 17,
      "z": 22,
      "name": "Deco_Bone_Full"
    },
    {
      "x": -16,
      "y": 6,
      "z": 13,
      "name": "Deco_Bone_Full"
    },
    {
      "x": -16,
      "y": 7,
      "z": 13,
      "name": "Deco_Bone_Full"
    },
    {
      "x": -16,
      "y": 18,
      "z": 16,
      "name": "Deco_Bone_Full"
    },
    {
      "x": -16,
      "y": 18,
      "z": 17,
      "name": "Deco_Bone_Full"
    },
    {
      "x": -16,
      "y": 19,
      "z": 17,
      "name": "Deco_Bone_Full"
    },
    {
      "x": -16,
      "y": 18,
      "z": 18,
      "name": "Deco_Bone_Full"
    },
    {
      "x": -16,
      "y": 19,
      "z": 18,
      "name": "Deco_Bone_Full"
    },
    {
      "x": -16,
      "y": 20,
      "z": 18,
      "name": "Deco_Bone_Full"
    },
    {
      "x": -16,
      "y": 18,
      "z": 19,
      "name": "Deco_Bone_Full"
    },
    {
      "x": -16,
      "y": 19,
      "z": 19,
      "name": "Deco_Bone_Full"
    },
    {
      "x": -16,
      "y": 18,
      "z": 20,
      "name": "Deco_Bone_Full"
    },
    {
      "x": -16,
      "y": 19,
      "z": 20,
      "name": "Deco_Bone_Full"
    },
    {
      "x": -16,
      "y": 18,
      "z": 21,
      "name": "Deco_Bone_Full"
    },
    {
      "x": -15,
      "y": 5,
      "z": 14,
      "name": "Deco_Bone_Full"
    },
    {
      "x": -15,
      "y": 6,
      "z": 14,
      "name": "Deco_Bone_Full"
    },
    {
      "x": -15,
      "y": 19,
      "z": 16,
      "name": "Deco_Bone_Full"
    },
    {
      "x": -15,
      "y": 18,
      "z": 17,
      "name": "Deco_Bone_Full"
    },
    {
      "x": -15,
      "y": 19,
      "z": 17,
      "name": "Deco_Bone_Full"
    },
    {
      "x": -15,
      "y": 20,
      "z": 17,
      "name": "Deco_Bone_Full"
    },
    {
      "x": -15,
      "y": 21,
      "z": 17,
      "name": "Deco_Bone_Full"
    },
    {
      "x": -15,
      "y": 17,
      "z": 18,
      "name": "Deco_Bone_Full"
    },
    {
      "x": -15,
      "y": 18,
      "z": 18,
      "name": "Deco_Bone_Full"
    },
    {
      "x": -15,
      "y": 19,
      "z": 18,
      "name": "Deco_Bone_Full"
    },
    {
      "x": -15,
      "y": 20,
      "z": 18,
      "name": "Deco_Bone_Full"
    },
    {
      "x": -15,
      "y": 21,
      "z": 18,
      "name": "Deco_Bone_Full"
    },
    {
      "x": -15,
      "y": 22,
      "z": 18,
      "name": "Deco_Bone_Full"
    },
    {
      "x": -15,
      "y": 23,
      "z": 18,
      "name": "Deco_Bone_Full"
    },
    {
      "x": -15,
      "y": 24,
      "z": 18,
      "name": "Deco_Bone_Full"
    },
    {
      "x": -15,
      "y": 25,
      "z": 18,
      "name": "Deco_Bone_Full"
    },
    {
      "x": -15,
      "y": 17,
      "z": 19,
      "name": "Deco_Bone_Full"
    },
    {
      "x": -15,
      "y": 18,
      "z": 19,
      "name": "Deco_Bone_Full"
    },
    {
      "x": -15,
      "y": 19,
      "z": 19,
      "name": "Deco_Bone_Full"
    },
    {
      "x": -15,
      "y": 20,
      "z": 19,
      "name": "Deco_Bone_Full"
    },
    {
      "x": -15,
      "y": 21,
      "z": 19,
      "name": "Deco_Bone_Full"
    },
    {
      "x": -15,
      "y": 22,
      "z": 19,
      "name": "Deco_Bone_Full"
    },
    {
      "x": -15,
      "y": 23,
      "z": 19,
      "name": "Deco_Bone_Full"
    },
    {
      "x": -15,
      "y": 24,
      "z": 19,
      "name": "Deco_Bone_Full"
    },
    {
      "x": -15,
      "y": 25,
      "z": 19,
      "name": "Deco_Bone_Full"
    },
    {
      "x": -15,
      "y": 26,
      "z": 19,
      "name": "Deco_Bone_Full"
    },
    {
      "x": -15,
      "y": 27,
      "z": 19,
      "name": "Deco_Bone_Full"
    },
    {
      "x": -15,
      "y": 28,
      "z": 19,
      "name": "Deco_Bone_Full"
    },
    {
      "x": -15,
      "y": 29,
      "z": 19,
      "name": "Deco_Bone_Full"
    },
    {
      "x": -15,
      "y": 18,
      "z": 20,
      "name": "Deco_Bone_Full"
    },
    {
      "x": -15,
      "y": 19,
      "z": 20,
      "name": "Deco_Bone_Full"
    },
    {
      "x": -15,
      "y": 18,
      "z": 21,
      "name": "Deco_Bone_Full"
    },
    {
      "x": -14,
      "y": 19,
      "z": 16,
      "name": "Deco_Bone_Full"
    },
    {
      "x": -14,
      "y": 18,
      "z": 17,
      "name": "Deco_Bone_Full"
    },
    {
      "x": -14,
      "y": 19,
      "z": 17,
      "name": "Deco_Bone_Full"
    },
    {
      "x": -14,
      "y": 20,
      "z": 17,
      "name": "Deco_Bone_Full"
    },
    {
      "x": -14,
      "y": 21,
      "z": 17,
      "name": "Deco_Bone_Full"
    },
    {
      "x": -14,
      "y": 22,
      "z": 17,
      "name": "Deco_Bone_Full"
    },
    {
      "x": -14,
      "y": 23,
      "z": 17,
      "name": "Deco_Bone_Full"
    },
    {
      "x": -14,
      "y": 17,
      "z": 18,
      "name": "Deco_Bone_Full"
    },
    {
      "x": -14,
      "y": 18,
      "z": 18,
      "name": "Deco_Bone_Full"
    },
    {
      "x": -14,
      "y": 19,
      "z": 18,
      "name": "Deco_Bone_Full"
    },
    {
      "x": -14,
      "y": 20,
      "z": 18,
      "name": "Deco_Bone_Full"
    },
    {
      "x": -14,
      "y": 21,
      "z": 18,
      "name": "Deco_Bone_Full"
    },
    {
      "x": -14,
      "y": 22,
      "z": 18,
      "name": "Deco_Bone_Full"
    },
    {
      "x": -14,
      "y": 23,
      "z": 18,
      "name": "Deco_Bone_Full"
    },
    {
      "x": -14,
      "y": 24,
      "z": 18,
      "name": "Deco_Bone_Full"
    },
    {
      "x": -14,
      "y": 25,
      "z": 18,
      "name": "Deco_Bone_Full"
    },
    {
      "x": -14,
      "y": 26,
      "z": 18,
      "name": "Deco_Bone_Full"
    },
    {
      "x": -14,
      "y": 27,
      "z": 18,
      "name": "Deco_Bone_Full"
    },
    {
      "x": -14,
      "y": 28,
      "z": 18,
      "name": "Deco_Bone_Full"
    },
    {
      "x": -14,
      "y": 29,
      "z": 18,
      "name": "Deco_Bone_Full"
    },
    {
      "x": -14,
      "y": 17,
      "z": 19,
      "name": "Deco_Bone_Full"
    },
    {
      "x": -14,
      "y": 18,
      "z": 19,
      "name": "Deco_Bone_Full"
    },
    {
      "x": -14,
      "y": 19,
      "z": 19,
      "name": "Deco_Bone_Full"
    },
    {
      "x": -14,
      "y": 20,
      "z": 19,
      "name": "Deco_Bone_Full"
    },
    {
      "x": -14,
      "y": 21,
      "z": 19,
      "name": "Deco_Bone_Full"
    },
    {
      "x": -14,
      "y": 22,
      "z": 19,
      "name": "Deco_Bone_Full"
    },
    {
      "x": -14,
      "y": 23,
      "z": 19,
      "name": "Deco_Bone_Full"
    },
    {
      "x": -14,
      "y": 24,
      "z": 19,
      "name": "Deco_Bone_Full"
    },
    {
      "x": -14,
      "y": 25,
      "z": 19,
      "name": "Deco_Bone_Full"
    },
    {
      "x": -14,
      "y": 18,
      "z": 20,
      "name": "Deco_Bone_Full"
    },
    {
      "x": -14,
      "y": 19,
      "z": 20,
      "name": "Deco_Bone_Full"
    },
    {
      "x": -14,
      "y": 20,
      "z": 20,
      "name": "Deco_Bone_Full"
    },
    {
      "x": -13,
      "y": 20,
      "z": 16,
      "name": "Deco_Bone_Full"
    },
    {
      "x": -13,
      "y": 19,
      "z": 17,
      "name": "Deco_Bone_Full"
    },
    {
      "x": -13,
      "y": 20,
      "z": 17,
      "name": "Deco_Bone_Full"
    },
    {
      "x": -13,
      "y": 21,
      "z": 17,
      "name": "Deco_Bone_Full"
    },
    {
      "x": -13,
      "y": 18,
      "z": 18,
      "name": "Deco_Bone_Full"
    },
    {
      "x": -13,
      "y": 19,
      "z": 18,
      "name": "Deco_Bone_Full"
    },
    {
      "x": -13,
      "y": 20,
      "z": 18,
      "name": "Deco_Bone_Full"
    },
    {
      "x": -13,
      "y": 21,
      "z": 18,
      "name": "Deco_Bone_Full"
    },
    {
      "x": -13,
      "y": 22,
      "z": 18,
      "name": "Deco_Bone_Full"
    },
    {
      "x": -13,
      "y": 23,
      "z": 18,
      "name": "Deco_Bone_Full"
    },
    {
      "x": -13,
      "y": 18,
      "z": 19,
      "name": "Deco_Bone_Full"
    },
    {
      "x": -13,
      "y": 19,
      "z": 19,
      "name": "Deco_Bone_Full"
    },
    {
      "x": -13,
      "y": 20,
      "z": 19,
      "name": "Deco_Bone_Full"
    },
    {
      "x": -13,
      "y": 21,
      "z": 19,
      "name": "Deco_Bone_Full"
    },
    {
      "x": -13,
      "y": 18,
      "z": 20,
      "name": "Deco_Bone_Full"
    },
    {
      "x": -13,
      "y": 19,
      "z": 20,
      "name": "Deco_Bone_Full"
    },
    {
      "x": -13,
      "y": 18,
      "z": 21,
      "name": "Deco_Bone_Full"
    },
    {
      "x": -12,
      "y": 16,
      "z": 7,
      "name": "Deco_Bone_Full"
    },
    {
      "x": -12,
      "y": 17,
      "z": 7,
      "name": "Deco_Bone_Full"
    },
    {
      "x": -12,
      "y": 18,
      "z": 7,
      "name": "Deco_Bone_Full"
    },
    {
      "x": -12,
      "y": 18,
      "z": 8,
      "name": "Deco_Bone_Full"
    },
    {
      "x": -12,
      "y": 19,
      "z": 8,
      "name": "Deco_Bone_Full"
    },
    {
      "x": -12,
      "y": 20,
      "z": 8,
      "name": "Deco_Bone_Full"
    },
    {
      "x": -12,
      "y": 20,
      "z": 9,
      "name": "Deco_Bone_Full"
    },
    {
      "x": -12,
      "y": 21,
      "z": 9,
      "name": "Deco_Bone_Full"
    },
    {
      "x": -12,
      "y": 20,
      "z": 10,
      "name": "Deco_Bone_Full"
    },
    {
      "x": -12,
      "y": 20,
      "z": 15,
      "name": "Deco_Bone_Full"
    },
    {
      "x": -12,
      "y": 20,
      "z": 16,
      "name": "Deco_Bone_Full"
    },
    {
      "x": -12,
      "y": 21,
      "z": 16,
      "name": "Deco_Bone_Full"
    },
    {
      "x": -12,
      "y": 20,
      "z": 17,
      "name": "Deco_Bone_Full"
    },
    {
      "x": -12,
      "y": 19,
      "z": 18,
      "name": "Deco_Bone_Full"
    },
    {
      "x": -12,
      "y": 19,
      "z": 19,
      "name": "Deco_Bone_Full"
    },
    {
      "x": -12,
      "y": 18,
      "z": 20,
      "name": "Deco_Bone_Full"
    },
    {
      "x": -12,
      "y": 17,
      "z": 21,
      "name": "Deco_Bone_Full"
    },
    {
      "x": -12,
      "y": 18,
      "z": 21,
      "name": "Deco_Bone_Full"
    },
    {
      "x": -12,
      "y": 19,
      "z": 21,
      "name": "Deco_Bone_Full"
    },
    {
      "x": -12,
      "y": 17,
      "z": 22,
      "name": "Deco_Bone_Full"
    },
    {
      "x": -11,
      "y": 20,
      "z": 9,
      "name": "Deco_Bone_Full"
    },
    {
      "x": -11,
      "y": 20,
      "z": 10,
      "name": "Deco_Bone_Full"
    },
    {
      "x": -11,
      "y": 21,
      "z": 10,
      "name": "Deco_Bone_Full"
    },
    {
      "x": -11,
      "y": 22,
      "z": 10,
      "name": "Deco_Bone_Full"
    },
    {
      "x": -11,
      "y": 21,
      "z": 11,
      "name": "Deco_Bone_Full"
    },
    {
      "x": -11,
      "y": 21,
      "z": 13,
      "name": "Deco_Bone_Full"
    },
    {
      "x": -11,
      "y": 21,
      "z": 14,
      "name": "Deco_Bone_Full"
    },
    {
      "x": -11,
      "y": 20,
      "z": 15,
      "name": "Deco_Bone_Full"
    },
    {
      "x": -11,
      "y": 21,
      "z": 15,
      "name": "Deco_Bone_Full"
    },
    {
      "x": -11,
      "y": 22,
      "z": 15,
      "name": "Deco_Bone_Full"
    },
    {
      "x": -11,
      "y": 20,
      "z": 16,
      "name": "Deco_Bone_Full"
    },
    {
      "x": -11,
      "y": 17,
      "z": 21,
      "name": "Deco_Bone_Full"
    },
    {
      "x": -11,
      "y": 18,
      "z": 21,
      "name": "Deco_Bone_Full"
    },
    {
      "x": -11,
      "y": 16,
      "z": 22,
      "name": "Deco_Bone_Full"
    },
    {
      "x": -11,
      "y": 17,
      "z": 22,
      "name": "Deco_Bone_Full"
    },
    {
      "x": -11,
      "y": 18,
      "z": 22,
      "name": "Deco_Bone_Full"
    },
    {
      "x": -10,
      "y": 21,
      "z": 10,
      "name": "Deco_Bone_Full"
    },
    {
      "x": -10,
      "y": 21,
      "z": 11,
      "name": "Deco_Bone_Full"
    },
    {
      "x": -10,
      "y": 22,
      "z": 11,
      "name": "Deco_Bone_Full"
    },
    {
      "x": -10,
      "y": 21,
      "z": 12,
      "name": "Deco_Bone_Full"
    },
    {
      "x": -10,
      "y": 22,
      "z": 12,
      "name": "Deco_Bone_Full"
    },
    {
      "x": -10,
      "y": 23,
      "z": 12,
      "name": "Deco_Bone_Full"
    },
    {
      "x": -10,
      "y": 21,
      "z": 13,
      "name": "Deco_Bone_Full"
    },
    {
      "x": -10,
      "y": 22,
      "z": 13,
      "name": "Deco_Bone_Full"
    },
    {
      "x": -10,
      "y": 21,
      "z": 14,
      "name": "Deco_Bone_Full"
    },
    {
      "x": -10,
      "y": 22,
      "z": 14,
      "name": "Deco_Bone_Full"
    },
    {
      "x": -10,
      "y": 21,
      "z": 15,
      "name": "Deco_Bone_Full"
    },
    {
      "x": -10,
      "y": 5,
      "z": 19,
      "name": "Deco_Bone_Full"
    },
    {
      "x": -10,
      "y": 6,
      "z": 19,
      "name": "Deco_Bone_Full"
    },
    {
      "x": -10,
      "y": 15,
      "z": 22,
      "name": "Deco_Bone_Full"
    },
    {
      "x": -10,
      "y": 16,
      "z": 22,
      "name": "Deco_Bone_Full"
    },
    {
      "x": -10,
      "y": 17,
      "z": 22,
      "name": "Deco_Bone_Full"
    },
    {
      "x": -9,
      "y": 22,
      "z": 10,
      "name": "Deco_Bone_Full"
    },
    {
      "x": -9,
      "y": 21,
      "z": 11,
      "name": "Deco_Bone_Full"
    },
    {
      "x": -9,
      "y": 22,
      "z": 11,
      "name": "Deco_Bone_Full"
    },
    {
      "x": -9,
      "y": 23,
      "z": 11,
      "name": "Deco_Bone_Full"
    },
    {
      "x": -9,
      "y": 24,
      "z": 11,
      "name": "Deco_Bone_Full"
    },
    {
      "x": -9,
      "y": 20,
      "z": 12,
      "name": "Deco_Bone_Full"
    },
    {
      "x": -9,
      "y": 21,
      "z": 12,
      "name": "Deco_Bone_Full"
    },
    {
      "x": -9,
      "y": 22,
      "z": 12,
      "name": "Deco_Bone_Full"
    },
    {
      "x": -9,
      "y": 23,
      "z": 12,
      "name": "Deco_Bone_Full"
    },
    {
      "x": -9,
      "y": 24,
      "z": 12,
      "name": "Deco_Bone_Full"
    },
    {
      "x": -9,
      "y": 25,
      "z": 12,
      "name": "Deco_Bone_Full"
    },
    {
      "x": -9,
      "y": 26,
      "z": 12,
      "name": "Deco_Bone_Full"
    },
    {
      "x": -9,
      "y": 27,
      "z": 12,
      "name": "Deco_Bone_Full"
    },
    {
      "x": -9,
      "y": 20,
      "z": 13,
      "name": "Deco_Bone_Full"
    },
    {
      "x": -9,
      "y": 21,
      "z": 13,
      "name": "Deco_Bone_Full"
    },
    {
      "x": -9,
      "y": 22,
      "z": 13,
      "name": "Deco_Bone_Full"
    },
    {
      "x": -9,
      "y": 23,
      "z": 13,
      "name": "Deco_Bone_Full"
    },
    {
      "x": -9,
      "y": 24,
      "z": 13,
      "name": "Deco_Bone_Full"
    },
    {
      "x": -9,
      "y": 25,
      "z": 13,
      "name": "Deco_Bone_Full"
    },
    {
      "x": -9,
      "y": 26,
      "z": 13,
      "name": "Deco_Bone_Full"
    },
    {
      "x": -9,
      "y": 27,
      "z": 13,
      "name": "Deco_Bone_Full"
    },
    {
      "x": -9,
      "y": 28,
      "z": 13,
      "name": "Deco_Bone_Full"
    },
    {
      "x": -9,
      "y": 29,
      "z": 13,
      "name": "Deco_Bone_Full"
    },
    {
      "x": -9,
      "y": 30,
      "z": 13,
      "name": "Deco_Bone_Full"
    },
    {
      "x": -9,
      "y": 21,
      "z": 14,
      "name": "Deco_Bone_Full"
    },
    {
      "x": -9,
      "y": 22,
      "z": 14,
      "name": "Deco_Bone_Full"
    },
    {
      "x": -9,
      "y": 21,
      "z": 15,
      "name": "Deco_Bone_Full"
    },
    {
      "x": -9,
      "y": 6,
      "z": 20,
      "name": "Deco_Bone_Full"
    },
    {
      "x": -9,
      "y": 7,
      "z": 20,
      "name": "Deco_Bone_Full"
    },
    {
      "x": -9,
      "y": 8,
      "z": 20,
      "name": "Deco_Bone_Full"
    },
    {
      "x": -9,
      "y": 8,
      "z": 21,
      "name": "Deco_Bone_Full"
    },
    {
      "x": -9,
      "y": 9,
      "z": 21,
      "name": "Deco_Bone_Full"
    },
    {
      "x": -9,
      "y": 10,
      "z": 21,
      "name": "Deco_Bone_Full"
    },
    {
      "x": -9,
      "y": 10,
      "z": 22,
      "name": "Deco_Bone_Full"
    },
    {
      "x": -9,
      "y": 11,
      "z": 22,
      "name": "Deco_Bone_Full"
    },
    {
      "x": -9,
      "y": 12,
      "z": 22,
      "name": "Deco_Bone_Full"
    },
    {
      "x": -9,
      "y": 13,
      "z": 22,
      "name": "Deco_Bone_Full"
    },
    {
      "x": -9,
      "y": 14,
      "z": 22,
      "name": "Deco_Bone_Full"
    },
    {
      "x": -9,
      "y": 15,
      "z": 22,
      "name": "Deco_Bone_Full"
    },
    {
      "x": -8,
      "y": 22,
      "z": 10,
      "name": "Deco_Bone_Full"
    },
    {
      "x": -8,
      "y": 21,
      "z": 11,
      "name": "Deco_Bone_Full"
    },
    {
      "x": -8,
      "y": 22,
      "z": 11,
      "name": "Deco_Bone_Full"
    },
    {
      "x": -8,
      "y": 23,
      "z": 11,
      "name": "Deco_Bone_Full"
    },
    {
      "x": -8,
      "y": 24,
      "z": 11,
      "name": "Deco_Bone_Full"
    },
    {
      "x": -8,
      "y": 25,
      "z": 11,
      "name": "Deco_Bone_Full"
    },
    {
      "x": -8,
      "y": 26,
      "z": 11,
      "name": "Deco_Bone_Full"
    },
    {
      "x": -8,
      "y": 20,
      "z": 12,
      "name": "Deco_Bone_Full"
    },
    {
      "x": -8,
      "y": 21,
      "z": 12,
      "name": "Deco_Bone_Full"
    },
    {
      "x": -8,
      "y": 22,
      "z": 12,
      "name": "Deco_Bone_Full"
    },
    {
      "x": -8,
      "y": 23,
      "z": 12,
      "name": "Deco_Bone_Full"
    },
    {
      "x": -8,
      "y": 24,
      "z": 12,
      "name": "Deco_Bone_Full"
    },
    {
      "x": -8,
      "y": 25,
      "z": 12,
      "name": "Deco_Bone_Full"
    },
    {
      "x": -8,
      "y": 26,
      "z": 12,
      "name": "Deco_Bone_Full"
    },
    {
      "x": -8,
      "y": 27,
      "z": 12,
      "name": "Deco_Bone_Full"
    },
    {
      "x": -8,
      "y": 28,
      "z": 12,
      "name": "Deco_Bone_Full"
    },
    {
      "x": -8,
      "y": 29,
      "z": 12,
      "name": "Deco_Bone_Full"
    },
    {
      "x": -8,
      "y": 30,
      "z": 12,
      "name": "Deco_Bone_Full"
    },
    {
      "x": -8,
      "y": 31,
      "z": 12,
      "name": "Deco_Bone_Full"
    },
    {
      "x": -8,
      "y": 20,
      "z": 13,
      "name": "Deco_Bone_Full"
    },
    {
      "x": -8,
      "y": 21,
      "z": 13,
      "name": "Deco_Bone_Full"
    },
    {
      "x": -8,
      "y": 22,
      "z": 13,
      "name": "Deco_Bone_Full"
    },
    {
      "x": -8,
      "y": 23,
      "z": 13,
      "name": "Deco_Bone_Full"
    },
    {
      "x": -8,
      "y": 24,
      "z": 13,
      "name": "Deco_Bone_Full"
    },
    {
      "x": -8,
      "y": 25,
      "z": 13,
      "name": "Deco_Bone_Full"
    },
    {
      "x": -8,
      "y": 26,
      "z": 13,
      "name": "Deco_Bone_Full"
    },
    {
      "x": -8,
      "y": 27,
      "z": 13,
      "name": "Deco_Bone_Full"
    },
    {
      "x": -8,
      "y": 21,
      "z": 14,
      "name": "Deco_Bone_Full"
    },
    {
      "x": -8,
      "y": 22,
      "z": 14,
      "name": "Deco_Bone_Full"
    },
    {
      "x": -8,
      "y": 23,
      "z": 14,
      "name": "Deco_Bone_Full"
    },
    {
      "x": -7,
      "y": 22,
      "z": 11,
      "name": "Deco_Bone_Full"
    },
    {
      "x": -7,
      "y": 23,
      "z": 11,
      "name": "Deco_Bone_Full"
    },
    {
      "x": -7,
      "y": 21,
      "z": 12,
      "name": "Deco_Bone_Full"
    },
    {
      "x": -7,
      "y": 22,
      "z": 12,
      "name": "Deco_Bone_Full"
    },
    {
      "x": -7,
      "y": 23,
      "z": 12,
      "name": "Deco_Bone_Full"
    },
    {
      "x": -7,
      "y": 24,
      "z": 12,
      "name": "Deco_Bone_Full"
    },
    {
      "x": -7,
      "y": 25,
      "z": 12,
      "name": "Deco_Bone_Full"
    },
    {
      "x": -7,
      "y": 26,
      "z": 12,
      "name": "Deco_Bone_Full"
    },
    {
      "x": -7,
      "y": 21,
      "z": 13,
      "name": "Deco_Bone_Full"
    },
    {
      "x": -7,
      "y": 22,
      "z": 13,
      "name": "Deco_Bone_Full"
    },
    {
      "x": -7,
      "y": 23,
      "z": 13,
      "name": "Deco_Bone_Full"
    },
    {
      "x": -7,
      "y": 24,
      "z": 13,
      "name": "Deco_Bone_Full"
    },
    {
      "x": -7,
      "y": 21,
      "z": 14,
      "name": "Deco_Bone_Full"
    },
    {
      "x": -7,
      "y": 22,
      "z": 14,
      "name": "Deco_Bone_Full"
    },
    {
      "x": -7,
      "y": 21,
      "z": 15,
      "name": "Deco_Bone_Full"
    },
    {
      "x": -6,
      "y": 14,
      "z": 2,
      "name": "Deco_Bone_Full"
    },
    {
      "x": -6,
      "y": 15,
      "z": 2,
      "name": "Deco_Bone_Full"
    },
    {
      "x": -6,
      "y": 16,
      "z": 2,
      "name": "Deco_Bone_Full"
    },
    {
      "x": -6,
      "y": 17,
      "z": 2,
      "name": "Deco_Bone_Full"
    },
    {
      "x": -6,
      "y": 18,
      "z": 2,
      "name": "Deco_Bone_Full"
    },
    {
      "x": -6,
      "y": 19,
      "z": 2,
      "name": "Deco_Bone_Full"
    },
    {
      "x": -6,
      "y": 20,
      "z": 2,
      "name": "Deco_Bone_Full"
    },
    {
      "x": -6,
      "y": 21,
      "z": 2,
      "name": "Deco_Bone_Full"
    },
    {
      "x": -6,
      "y": 18,
      "z": 3,
      "name": "Plant_Crop_Health3"
    },
    {
      "x": -6,
      "y": 19,
      "z": 3,
      "name": "Plant_Crop_Health3",
      "filler": 1024
    },
    {
      "x": -6,
      "y": 21,
      "z": 3,
      "name": "Deco_Bone_Full"
    },
    {
      "x": -6,
      "y": 18,
      "z": 4,
      "name": "Empty"
    },
    {
      "x": -6,
      "y": 19,
      "z": 4,
      "name": "Empty"
    },
    {
      "x": -6,
      "y": 22,
      "z": 12,
      "name": "Deco_Bone_Full"
    },
    {
      "x": -6,
      "y": 22,
      "z": 13,
      "name": "Deco_Bone_Full"
    },
    {
      "x": -6,
      "y": 21,
      "z": 14,
      "name": "Deco_Bone_Full"
    },
    {
      "x": -6,
      "y": 20,
      "z": 15,
      "name": "Deco_Bone_Full"
    },
    {
      "x": -6,
      "y": 21,
      "z": 15,
      "name": "Deco_Bone_Full"
    },
    {
      "x": -6,
      "y": 22,
      "z": 15,
      "name": "Deco_Bone_Full"
    },
    {
      "x": -6,
      "y": 20,
      "z": 16,
      "name": "Deco_Bone_Full"
    },
    {
      "x": -5,
      "y": 21,
      "z": 2,
      "name": "Deco_Bone_Full"
    },
    {
      "x": -5,
      "y": 12,
      "z": 3,
      "name": "Deco_Bone_Full"
    },
    {
      "x": -5,
      "y": 13,
      "z": 3,
      "name": "Deco_Bone_Full"
    },
    {
      "x": -5,
      "y": 14,
      "z": 3,
      "name": "Deco_Bone_Full"
    },
    {
      "x": -5,
      "y": 21,
      "z": 3,
      "name": "Deco_Bone_Full"
    },
    {
      "x": -5,
      "y": 22,
      "z": 3,
      "name": "Deco_Bone_Full"
    },
    {
      "x": -5,
      "y": 23,
      "z": 3,
      "name": "Deco_Bone_Full"
    },
    {
      "x": -5,
      "y": 22,
      "z": 4,
      "name": "Deco_Bone_Full"
    },
    {
      "x": -5,
      "y": 23,
      "z": 8,
      "name": "Deco_Bone_Full"
    },
    {
      "x": -5,
      "y": 22,
      "z": 9,
      "name": "Deco_Bone_Full"
    },
    {
      "x": -5,
      "y": 23,
      "z": 9,
      "name": "Deco_Bone_Full"
    },
    {
      "x": -5,
      "y": 22,
      "z": 10,
      "name": "Deco_Bone_Full"
    },
    {
      "x": -5,
      "y": 20,
      "z": 15,
      "name": "Deco_Bone_Full"
    },
    {
      "x": -5,
      "y": 20,
      "z": 16,
      "name": "Deco_Bone_Full"
    },
    {
      "x": -5,
      "y": 21,
      "z": 16,
      "name": "Deco_Bone_Full"
    },
    {
      "x": -4,
      "y": 22,
      "z": 3,
      "name": "Deco_Bone_Full"
    },
    {
      "x": -4,
      "y": 11,
      "z": 4,
      "name": "Deco_Bone_Full"
    },
    {
      "x": -4,
      "y": 12,
      "z": 4,
      "name": "Deco_Bone_Full"
    },
    {
      "x": -4,
      "y": 22,
      "z": 4,
      "name": "Deco_Bone_Full"
    },
    {
      "x": -4,
      "y": 23,
      "z": 4,
      "name": "Deco_Bone_Full"
    },
    {
      "x": -4,
      "y": 24,
      "z": 4,
      "name": "Deco_Bone_Full"
    },
    {
      "x": -4,
      "y": 23,
      "z": 5,
      "name": "Deco_Bone_Full"
    },
    {
      "x": -4,
      "y": 23,
      "z": 6,
      "name": "Deco_Bone_Full"
    },
    {
      "x": -4,
      "y": 23,
      "z": 7,
      "name": "Deco_Bone_Full"
    },
    {
      "x": -4,
      "y": 23,
      "z": 8,
      "name": "Deco_Bone_Full"
    },
    {
      "x": -4,
      "y": 24,
      "z": 8,
      "name": "Deco_Bone_Full"
    },
    {
      "x": -4,
      "y": 23,
      "z": 9,
      "name": "Deco_Bone_Full"
    },
    {
      "x": -4,
      "y": 11,
      "z": 15,
      "name": "Deco_Bone_Full"
    },
    {
      "x": -4,
      "y": 12,
      "z": 15,
      "name": "Deco_Bone_Full"
    },
    {
      "x": -4,
      "y": 18,
      "z": 16,
      "name": "Deco_Bone_Full"
    },
    {
      "x": -4,
      "y": 19,
      "z": 16,
      "name": "Deco_Bone_Full"
    },
    {
      "x": -4,
      "y": 20,
      "z": 16,
      "name": "Deco_Bone_Full"
    },
    {
      "x": -3,
      "y": 23,
      "z": 4,
      "name": "Deco_Bone_Full"
    },
    {
      "x": -3,
      "y": 23,
      "z": 5,
      "name": "Deco_Bone_Full"
    },
    {
      "x": -3,
      "y": 24,
      "z": 5,
      "name": "Deco_Bone_Full"
    },
    {
      "x": -3,
      "y": 22,
      "z": 6,
      "name": "Deco_Bone_Full"
    },
    {
      "x": -3,
      "y": 23,
      "z": 6,
      "name": "Deco_Bone_Full"
    },
    {
      "x": -3,
      "y": 24,
      "z": 6,
      "name": "Deco_Bone_Full"
    },
    {
      "x": -3,
      "y": 25,
      "z": 6,
      "name": "Deco_Bone_Full"
    },
    {
      "x": -3,
      "y": 23,
      "z": 7,
      "name": "Deco_Bone_Full"
    },
    {
      "x": -3,
      "y": 24,
      "z": 7,
      "name": "Deco_Bone_Full"
    },
    {
      "x": -3,
      "y": 23,
      "z": 8,
      "name": "Deco_Bone_Full"
    },
    {
      "x": -3,
      "y": 12,
      "z": 16,
      "name": "Deco_Bone_Full"
    },
    {
      "x": -3,
      "y": 13,
      "z": 16,
      "name": "Deco_Bone_Full"
    },
    {
      "x": -3,
      "y": 14,
      "z": 16,
      "name": "Deco_Bone_Full"
    },
    {
      "x": -3,
      "y": 15,
      "z": 16,
      "name": "Deco_Bone_Full"
    },
    {
      "x": -3,
      "y": 16,
      "z": 16,
      "name": "Deco_Bone_Full"
    },
    {
      "x": -3,
      "y": 17,
      "z": 16,
      "name": "Deco_Bone_Full"
    },
    {
      "x": -3,
      "y": 18,
      "z": 16,
      "name": "Deco_Bone_Full"
    },
    {
      "x": -2,
      "y": 23,
      "z": 4,
      "name": "Deco_Bone_Full"
    },
    {
      "x": -2,
      "y": 24,
      "z": 4,
      "name": "Deco_Bone_Full"
    },
    {
      "x": -2,
      "y": 25,
      "z": 4,
      "name": "Deco_Bone_Full"
    },
    {
      "x": -2,
      "y": 22,
      "z": 5,
      "name": "Deco_Bone_Full"
    },
    {
      "x": -2,
      "y": 23,
      "z": 5,
      "name": "Deco_Bone_Full"
    },
    {
      "x": -2,
      "y": 24,
      "z": 5,
      "name": "Deco_Bone_Full"
    },
    {
      "x": -2,
      "y": 25,
      "z": 5,
      "name": "Deco_Bone_Full"
    },
    {
      "x": -2,
      "y": 26,
      "z": 5,
      "name": "Deco_Bone_Full"
    },
    {
      "x": -2,
      "y": 27,
      "z": 5,
      "name": "Deco_Bone_Full"
    },
    {
      "x": -2,
      "y": 28,
      "z": 5,
      "name": "Deco_Bone_Full"
    },
    {
      "x": -2,
      "y": 22,
      "z": 6,
      "name": "Deco_Bone_Full"
    },
    {
      "x": -2,
      "y": 23,
      "z": 6,
      "name": "Deco_Bone_Full"
    },
    {
      "x": -2,
      "y": 24,
      "z": 6,
      "name": "Deco_Bone_Full"
    },
    {
      "x": -2,
      "y": 25,
      "z": 6,
      "name": "Deco_Bone_Full"
    },
    {
      "x": -2,
      "y": 26,
      "z": 6,
      "name": "Deco_Bone_Full"
    },
    {
      "x": -2,
      "y": 27,
      "z": 6,
      "name": "Deco_Bone_Full"
    },
    {
      "x": -2,
      "y": 28,
      "z": 6,
      "name": "Deco_Bone_Full"
    },
    {
      "x": -2,
      "y": 29,
      "z": 6,
      "name": "Deco_Bone_Full"
    },
    {
      "x": -2,
      "y": 30,
      "z": 6,
      "name": "Deco_Bone_Full"
    },
    {
      "x": -2,
      "y": 31,
      "z": 6,
      "name": "Deco_Bone_Full"
    },
    {
      "x": -2,
      "y": 22,
      "z": 7,
      "name": "Deco_Bone_Full"
    },
    {
      "x": -2,
      "y": 23,
      "z": 7,
      "name": "Deco_Bone_Full"
    },
    {
      "x": -2,
      "y": 24,
      "z": 7,
      "name": "Deco_Bone_Full"
    },
    {
      "x": -2,
      "y": 25,
      "z": 7,
      "name": "Deco_Bone_Full"
    },
    {
      "x": -2,
      "y": 23,
      "z": 8,
      "name": "Deco_Bone_Full"
    },
    {
      "x": -1,
      "y": 23,
      "z": 4,
      "name": "Deco_Bone_Full"
    },
    {
      "x": -1,
      "y": 24,
      "z": 4,
      "name": "Deco_Bone_Full"
    },
    {
      "x": -1,
      "y": 25,
      "z": 4,
      "name": "Deco_Bone_Full"
    },
    {
      "x": -1,
      "y": 26,
      "z": 4,
      "name": "Deco_Bone_Full"
    },
    {
      "x": -1,
      "y": 27,
      "z": 4,
      "name": "Deco_Bone_Full"
    },
    {
      "x": -1,
      "y": 22,
      "z": 5,
      "name": "Deco_Bone_Full"
    },
    {
      "x": -1,
      "y": 23,
      "z": 5,
      "name": "Deco_Bone_Full"
    },
    {
      "x": -1,
      "y": 24,
      "z": 5,
      "name": "Deco_Bone_Full"
    },
    {
      "x": -1,
      "y": 25,
      "z": 5,
      "name": "Deco_Bone_Full"
    },
    {
      "x": -1,
      "y": 26,
      "z": 5,
      "name": "Deco_Bone_Full"
    },
    {
      "x": -1,
      "y": 27,
      "z": 5,
      "name": "Deco_Bone_Full"
    },
    {
      "x": -1,
      "y": 28,
      "z": 5,
      "name": "Deco_Bone_Full"
    },
    {
      "x": -1,
      "y": 29,
      "z": 5,
      "name": "Deco_Bone_Full"
    },
    {
      "x": -1,
      "y": 30,
      "z": 5,
      "name": "Deco_Bone_Full"
    },
    {
      "x": -1,
      "y": 31,
      "z": 5,
      "name": "Deco_Bone_Full"
    },
    {
      "x": -1,
      "y": 32,
      "z": 5,
      "name": "Deco_Bone_Full"
    },
    {
      "x": -1,
      "y": 22,
      "z": 6,
      "name": "Deco_Bone_Full"
    },
    {
      "x": -1,
      "y": 23,
      "z": 6,
      "name": "Deco_Bone_Full"
    },
    {
      "x": -1,
      "y": 24,
      "z": 6,
      "name": "Deco_Bone_Full"
    },
    {
      "x": -1,
      "y": 25,
      "z": 6,
      "name": "Deco_Bone_Full"
    },
    {
      "x": -1,
      "y": 26,
      "z": 6,
      "name": "Deco_Bone_Full"
    },
    {
      "x": -1,
      "y": 27,
      "z": 6,
      "name": "Deco_Bone_Full"
    },
    {
      "x": -1,
      "y": 28,
      "z": 6,
      "name": "Deco_Bone_Full"
    },
    {
      "x": -1,
      "y": 23,
      "z": 7,
      "name": "Deco_Bone_Full"
    },
    {
      "x": -1,
      "y": 24,
      "z": 7,
      "name": "Deco_Bone_Full"
    },
    {
      "x": -1,
      "y": 23,
      "z": 8,
      "name": "Deco_Bone_Full"
    },
    {
      "x": 0,
      "y": 14,
      "z": -5,
      "name": "Deco_Bone_Full"
    },
    {
      "x": 0,
      "y": 15,
      "z": -5,
      "name": "Deco_Bone_Full"
    },
    {
      "x": 0,
      "y": 16,
      "z": -5,
      "name": "Deco_Bone_Full"
    },
    {
      "x": 0,
      "y": 17,
      "z": -5,
      "name": "Deco_Bone_Full"
    },
    {
      "x": 0,
      "y": 18,
      "z": -5,
      "name": "Deco_Bone_Full"
    },
    {
      "x": 0,
      "y": 19,
      "z": -5,
      "name": "Deco_Bone_Full"
    },
    {
      "x": 0,
      "y": 20,
      "z": -5,
      "name": "Deco_Bone_Full"
    },
    {
      "x": 0,
      "y": 21,
      "z": -5,
      "name": "Deco_Bone_Full"
    },
    {
      "x": 0,
      "y": 21,
      "z": -4,
      "name": "Deco_Bone_Full"
    },
    {
      "x": 0,
      "y": 24,
      "z": 3,
      "name": "Deco_Bone_Full"
    },
    {
      "x": 0,
      "y": 24,
      "z": 4,
      "name": "Deco_Bone_Full"
    },
    {
      "x": 0,
      "y": 25,
      "z": 4,
      "name": "Deco_Bone_Full"
    },
    {
      "x": 0,
      "y": 23,
      "z": 5,
      "name": "Deco_Bone_Full"
    },
    {
      "x": 0,
      "y": 24,
      "z": 5,
      "name": "Deco_Bone_Full"
    },
    {
      "x": 0,
      "y": 25,
      "z": 5,
      "name": "Deco_Bone_Full"
    },
    {
      "x": 0,
      "y": 26,
      "z": 5,
      "name": "Deco_Bone_Full"
    },
    {
      "x": 0,
      "y": 27,
      "z": 5,
      "name": "Deco_Bone_Full"
    },
    {
      "x": 0,
      "y": 23,
      "z": 6,
      "name": "Deco_Bone_Full"
    },
    {
      "x": 0,
      "y": 24,
      "z": 6,
      "name": "Deco_Bone_Full"
    },
    {
      "x": 0,
      "y": 25,
      "z": 6,
      "name": "Deco_Bone_Full"
    },
    {
      "x": 0,
      "y": 23,
      "z": 7,
      "name": "Deco_Bone_Full"
    },
    {
      "x": 0,
      "y": 22,
      "z": 8,
      "name": "Deco_Bone_Full"
    },
    {
      "x": 0,
      "y": 23,
      "z": 8,
      "name": "Deco_Bone_Full"
    },
    {
      "x": 0,
      "y": 24,
      "z": 8,
      "name": "Deco_Bone_Full"
    },
    {
      "x": 0,
      "y": 22,
      "z": 9,
      "name": "Deco_Bone_Full"
    },
    {
      "x": 1,
      "y": 21,
      "z": -5,
      "name": "Deco_Bone_Full"
    },
    {
      "x": 1,
      "y": 12,
      "z": -4,
      "name": "Deco_Bone_Full"
    },
    {
      "x": 1,
      "y": 13,
      "z": -4,
      "name": "Deco_Bone_Full"
    },
    {
      "x": 1,
      "y": 14,
      "z": -4,
      "name": "Deco_Bone_Full"
    },
    {
      "x": 1,
      "y": 21,
      "z": -4,
      "name": "Deco_Bone_Full"
    },
    {
      "x": 1,
      "y": 22,
      "z": -4,
      "name": "Deco_Bone_Full"
    },
    {
      "x": 1,
      "y": 23,
      "z": -4,
      "name": "Deco_Bone_Full"
    },
    {
      "x": 1,
      "y": 22,
      "z": -3,
      "name": "Deco_Bone_Full"
    },
    {
      "x": 1,
      "y": 24,
      "z": 2,
      "name": "Deco_Bone_Full"
    },
    {
      "x": 1,
      "y": 24,
      "z": 3,
      "name": "Deco_Bone_Full"
    },
    {
      "x": 1,
      "y": 25,
      "z": 3,
      "name": "Deco_Bone_Full"
    },
    {
      "x": 1,
      "y": 24,
      "z": 4,
      "name": "Deco_Bone_Full"
    },
    {
      "x": 1,
      "y": 22,
      "z": 8,
      "name": "Deco_Bone_Full"
    },
    {
      "x": 1,
      "y": 21,
      "z": 9,
      "name": "Deco_Bone_Full"
    },
    {
      "x": 1,
      "y": 22,
      "z": 9,
      "name": "Deco_Bone_Full"
    },
    {
      "x": 1,
      "y": 23,
      "z": 9,
      "name": "Deco_Bone_Full"
    },
    {
      "x": 1,
      "y": 21,
      "z": 10,
      "name": "Deco_Bone_Full"
    },
    {
      "x": 2,
      "y": 22,
      "z": -4,
      "name": "Deco_Bone_Full"
    },
    {
      "x": 2,
      "y": 11,
      "z": -3,
      "name": "Deco_Bone_Full"
    },
    {
      "x": 2,
      "y": 12,
      "z": -3,
      "name": "Deco_Bone_Full"
    },
    {
      "x": 2,
      "y": 22,
      "z": -3,
      "name": "Deco_Bone_Full"
    },
    {
      "x": 2,
      "y": 23,
      "z": -3,
      "name": "Deco_Bone_Full"
    },
    {
      "x": 2,
      "y": 24,
      "z": -3,
      "name": "Deco_Bone_Full"
    },
    {
      "x": 2,
      "y": 23,
      "z": -2,
      "name": "Deco_Bone_Full"
    },
    {
      "x": 2,
      "y": 24,
      "z": 1,
      "name": "Deco_Bone_Full"
    },
    {
      "x": 2,
      "y": 24,
      "z": 2,
      "name": "Deco_Bone_Full"
    },
    {
      "x": 2,
      "y": 25,
      "z": 2,
      "name": "Deco_Bone_Full"
    },
    {
      "x": 2,
      "y": 24,
      "z": 3,
      "name": "Deco_Bone_Full"
    },
    {
      "x": 2,
      "y": 21,
      "z": 9,
      "name": "Deco_Bone_Full"
    },
    {
      "x": 2,
      "y": 19,
      "z": 10,
      "name": "Deco_Bone_Full"
    },
    {
      "x": 2,
      "y": 20,
      "z": 10,
      "name": "Deco_Bone_Full"
    },
    {
      "x": 2,
      "y": 21,
      "z": 10,
      "name": "Deco_Bone_Full"
    },
    {
      "x": 3,
      "y": 23,
      "z": -3,
      "name": "Deco_Bone_Full"
    },
    {
      "x": 3,
      "y": 23,
      "z": -2,
      "name": "Deco_Bone_Full"
    },
    {
      "x": 3,
      "y": 24,
      "z": -2,
      "name": "Deco_Bone_Full"
    },
    {
      "x": 3,
      "y": 23,
      "z": -1,
      "name": "Deco_Bone_Full"
    },
    {
      "x": 3,
      "y": 24,
      "z": -1,
      "name": "Deco_Bone_Full"
    },
    {
      "x": 3,
      "y": 23,
      "z": 0,
      "name": "Deco_Bone_Full"
    },
    {
      "x": 3,
      "y": 24,
      "z": 0,
      "name": "Deco_Bone_Full"
    },
    {
      "x": 3,
      "y": 25,
      "z": 0,
      "name": "Deco_Bone_Full"
    },
    {
      "x": 3,
      "y": 26,
      "z": 0,
      "name": "Deco_Bone_Full"
    },
    {
      "x": 3,
      "y": 24,
      "z": 1,
      "name": "Deco_Bone_Full"
    },
    {
      "x": 3,
      "y": 25,
      "z": 1,
      "name": "Deco_Bone_Full"
    },
    {
      "x": 3,
      "y": 24,
      "z": 2,
      "name": "Deco_Bone_Full"
    },
    {
      "x": 4,
      "y": 23,
      "z": -2,
      "name": "Deco_Bone_Full"
    },
    {
      "x": 4,
      "y": 22,
      "z": -1,
      "name": "Deco_Bone_Full"
    },
    {
      "x": 4,
      "y": 23,
      "z": -1,
      "name": "Deco_Bone_Full"
    },
    {
      "x": 4,
      "y": 24,
      "z": -1,
      "name": "Deco_Bone_Full"
    },
    {
      "x": 4,
      "y": 25,
      "z": -1,
      "name": "Deco_Bone_Full"
    },
    {
      "x": 4,
      "y": 26,
      "z": -1,
      "name": "Deco_Bone_Full"
    },
    {
      "x": 4,
      "y": 27,
      "z": -1,
      "name": "Deco_Bone_Full"
    },
    {
      "x": 4,
      "y": 28,
      "z": -1,
      "name": "Deco_Bone_Full"
    },
    {
      "x": 4,
      "y": 22,
      "z": 0,
      "name": "Deco_Bone_Full"
    },
    {
      "x": 4,
      "y": 23,
      "z": 0,
      "name": "Deco_Bone_Full"
    },
    {
      "x": 4,
      "y": 24,
      "z": 0,
      "name": "Deco_Bone_Full"
    },
    {
      "x": 4,
      "y": 25,
      "z": 0,
      "name": "Deco_Bone_Full"
    },
    {
      "x": 4,
      "y": 26,
      "z": 0,
      "name": "Deco_Bone_Full"
    },
    {
      "x": 4,
      "y": 27,
      "z": 0,
      "name": "Deco_Bone_Full"
    },
    {
      "x": 4,
      "y": 28,
      "z": 0,
      "name": "Deco_Bone_Full"
    },
    {
      "x": 4,
      "y": 29,
      "z": 0,
      "name": "Deco_Bone_Full"
    },
    {
      "x": 4,
      "y": 30,
      "z": 0,
      "name": "Deco_Bone_Full"
    },
    {
      "x": 4,
      "y": 31,
      "z": 0,
      "name": "Deco_Bone_Full"
    },
    {
      "x": 4,
      "y": 32,
      "z": 0,
      "name": "Deco_Bone_Full"
    },
    {
      "x": 4,
      "y": 23,
      "z": 1,
      "name": "Deco_Bone_Full"
    },
    {
      "x": 4,
      "y": 24,
      "z": 1,
      "name": "Deco_Bone_Full"
    },
    {
      "x": 4,
      "y": 25,
      "z": 1,
      "name": "Deco_Bone_Full"
    },
    {
      "x": 4,
      "y": 26,
      "z": 1,
      "name": "Deco_Bone_Full"
    },
    {
      "x": 5,
      "y": 23,
      "z": -2,
      "name": "Deco_Bone_Full"
    },
    {
      "x": 5,
      "y": 24,
      "z": -2,
      "name": "Deco_Bone_Full"
    },
    {
      "x": 5,
      "y": 22,
      "z": -1,
      "name": "Deco_Bone_Full"
    },
    {
      "x": 5,
      "y": 23,
      "z": -1,
      "name": "Deco_Bone_Full"
    },
    {
      "x": 5,
      "y": 24,
      "z": -1,
      "name": "Deco_Bone_Full"
    },
    {
      "x": 5,
      "y": 25,
      "z": -1,
      "name": "Deco_Bone_Full"
    },
    {
      "x": 5,
      "y": 26,
      "z": -1,
      "name": "Deco_Bone_Full"
    },
    {
      "x": 5,
      "y": 27,
      "z": -1,
      "name": "Deco_Bone_Full"
    },
    {
      "x": 5,
      "y": 28,
      "z": -1,
      "name": "Deco_Bone_Full"
    },
    {
      "x": 5,
      "y": 29,
      "z": -1,
      "name": "Deco_Bone_Full"
    },
    {
      "x": 5,
      "y": 30,
      "z": -1,
      "name": "Deco_Bone_Full"
    },
    {
      "x": 5,
      "y": 31,
      "z": -1,
      "name": "Deco_Bone_Full"
    },
    {
      "x": 5,
      "y": 22,
      "z": 0,
      "name": "Deco_Bone_Full"
    },
    {
      "x": 5,
      "y": 23,
      "z": 0,
      "name": "Deco_Bone_Full"
    },
    {
      "x": 5,
      "y": 24,
      "z": 0,
      "name": "Deco_Bone_Full"
    },
    {
      "x": 5,
      "y": 25,
      "z": 0,
      "name": "Deco_Bone_Full"
    },
    {
      "x": 5,
      "y": 26,
      "z": 0,
      "name": "Deco_Bone_Full"
    },
    {
      "x": 5,
      "y": 27,
      "z": 0,
      "name": "Deco_Bone_Full"
    },
    {
      "x": 5,
      "y": 28,
      "z": 0,
      "name": "Deco_Bone_Full"
    },
    {
      "x": 5,
      "y": 23,
      "z": 1,
      "name": "Deco_Bone_Full"
    },
    {
      "x": 5,
      "y": 24,
      "z": 1,
      "name": "Deco_Bone_Full"
    },
    {
      "x": 6,
      "y": 19,
      "z": -10,
      "name": "Deco_Bone_Full"
    },
    {
      "x": 6,
      "y": 20,
      "z": -10,
      "name": "Deco_Bone_Full"
    },
    {
      "x": 6,
      "y": 23,
      "z": -3,
      "name": "Deco_Bone_Full"
    },
    {
      "x": 6,
      "y": 23,
      "z": -2,
      "name": "Deco_Bone_Full"
    },
    {
      "x": 6,
      "y": 24,
      "z": -2,
      "name": "Deco_Bone_Full"
    },
    {
      "x": 6,
      "y": 23,
      "z": -1,
      "name": "Deco_Bone_Full"
    },
    {
      "x": 6,
      "y": 24,
      "z": -1,
      "name": "Deco_Bone_Full"
    },
    {
      "x": 6,
      "y": 23,
      "z": 0,
      "name": "Deco_Bone_Full"
    },
    {
      "x": 6,
      "y": 23,
      "z": 1,
      "name": "Deco_Bone_Full"
    },
    {
      "x": 6,
      "y": 24,
      "z": 1,
      "name": "Deco_Bone_Full"
    },
    {
      "x": 6,
      "y": 23,
      "z": 2,
      "name": "Deco_Bone_Full"
    },
    {
      "x": 7,
      "y": 20,
      "z": -10,
      "name": "Deco_Bone_Full"
    },
    {
      "x": 7,
      "y": 21,
      "z": -10,
      "name": "Deco_Bone_Full"
    },
    {
      "x": 7,
      "y": 20,
      "z": -9,
      "name": "Deco_Bone_Full"
    },
    {
      "x": 7,
      "y": 23,
      "z": 1,
      "name": "Deco_Bone_Full"
    },
    {
      "x": 7,
      "y": 22,
      "z": 2,
      "name": "Deco_Bone_Full"
    },
    {
      "x": 7,
      "y": 23,
      "z": 2,
      "name": "Deco_Bone_Full"
    },
    {
      "x": 7,
      "y": 24,
      "z": 2,
      "name": "Deco_Bone_Full"
    },
    {
      "x": 7,
      "y": 22,
      "z": 3,
      "name": "Deco_Bone_Full"
    },
    {
      "x": 8,
      "y": 20,
      "z": -10,
      "name": "Deco_Bone_Full"
    },
    {
      "x": 8,
      "y": 21,
      "z": -9,
      "name": "Deco_Bone_Full"
    },
    {
      "x": 8,
      "y": 22,
      "z": -9,
      "name": "Deco_Bone_Full"
    },
    {
      "x": 8,
      "y": 21,
      "z": -8,
      "name": "Deco_Bone_Full"
    },
    {
      "x": 8,
      "y": 23,
      "z": -5,
      "name": "Deco_Bone_Full"
    },
    {
      "x": 8,
      "y": 22,
      "z": 2,
      "name": "Deco_Bone_Full"
    },
    {
      "x": 8,
      "y": 21,
      "z": 3,
      "name": "Deco_Bone_Full"
    },
    {
      "x": 8,
      "y": 22,
      "z": 3,
      "name": "Deco_Bone_Full"
    },
    {
      "x": 8,
      "y": 23,
      "z": 3,
      "name": "Deco_Bone_Full"
    },
    {
      "x": 8,
      "y": 21,
      "z": 4,
      "name": "Deco_Bone_Full"
    },
    {
      "x": 9,
      "y": 21,
      "z": -9,
      "name": "Deco_Bone_Full"
    },
    {
      "x": 9,
      "y": 21,
      "z": -8,
      "name": "Deco_Bone_Full"
    },
    {
      "x": 9,
      "y": 22,
      "z": -8,
      "name": "Deco_Bone_Full"
    },
    {
      "x": 9,
      "y": 21,
      "z": -7,
      "name": "Deco_Bone_Full"
    },
    {
      "x": 9,
      "y": 22,
      "z": -7,
      "name": "Deco_Bone_Full"
    },
    {
      "x": 9,
      "y": 23,
      "z": -7,
      "name": "Deco_Bone_Full"
    },
    {
      "x": 9,
      "y": 24,
      "z": -7,
      "name": "Deco_Bone_Full"
    },
    {
      "x": 9,
      "y": 21,
      "z": -6,
      "name": "Deco_Bone_Full"
    },
    {
      "x": 9,
      "y": 22,
      "z": -6,
      "name": "Deco_Bone_Full"
    },
    {
      "x": 9,
      "y": 23,
      "z": -6,
      "name": "Deco_Bone_Full"
    },
    {
      "x": 9,
      "y": 24,
      "z": -6,
      "name": "Deco_Bone_Full"
    },
    {
      "x": 9,
      "y": 25,
      "z": -6,
      "name": "Deco_Bone_Full"
    },
    {
      "x": 9,
      "y": 26,
      "z": -6,
      "name": "Deco_Bone_Full"
    },
    {
      "x": 9,
      "y": 22,
      "z": -5,
      "name": "Deco_Bone_Full"
    },
    {
      "x": 9,
      "y": 23,
      "z": -5,
      "name": "Deco_Bone_Full"
    },
    {
      "x": 9,
      "y": 24,
      "z": -5,
      "name": "Deco_Bone_Full"
    },
    {
      "x": 9,
      "y": 23,
      "z": -4,
      "name": "Deco_Bone_Full"
    },
    {
      "x": 9,
      "y": 21,
      "z": 3,
      "name": "Deco_Bone_Full"
    },
    {
      "x": 9,
      "y": 15,
      "z": 4,
      "name": "Deco_Bone_Full"
    },
    {
      "x": 9,
      "y": 16,
      "z": 4,
      "name": "Deco_Bone_Full"
    },
    {
      "x": 9,
      "y": 17,
      "z": 4,
      "name": "Deco_Bone_Full"
    },
    {
      "x": 9,
      "y": 18,
      "z": 4,
      "name": "Deco_Bone_Full"
    },
    {
      "x": 9,
      "y": 19,
      "z": 4,
      "name": "Deco_Bone_Full"
    },
    {
      "x": 9,
      "y": 20,
      "z": 4,
      "name": "Deco_Bone_Full"
    },
    {
      "x": 9,
      "y": 21,
      "z": 4,
      "name": "Deco_Bone_Full"
    },
    {
      "x": 10,
      "y": 21,
      "z": -8,
      "name": "Deco_Bone_Full"
    },
    {
      "x": 10,
      "y": 22,
      "z": -8,
      "name": "Deco_Bone_Full"
    },
    {
      "x": 10,
      "y": 23,
      "z": -8,
      "name": "Deco_Bone_Full"
    },
    {
      "x": 10,
      "y": 20,
      "z": -7,
      "name": "Deco_Bone_Full"
    },
    {
      "x": 10,
      "y": 21,
      "z": -7,
      "name": "Deco_Bone_Full"
    },
    {
      "x": 10,
      "y": 22,
      "z": -7,
      "name": "Deco_Bone_Full"
    },
    {
      "x": 10,
      "y": 23,
      "z": -7,
      "name": "Deco_Bone_Full"
    },
    {
      "x": 10,
      "y": 24,
      "z": -7,
      "name": "Deco_Bone_Full"
    },
    {
      "x": 10,
      "y": 25,
      "z": -7,
      "name": "Deco_Bone_Full"
    },
    {
      "x": 10,
      "y": 26,
      "z": -7,
      "name": "Deco_Bone_Full"
    },
    {
      "x": 10,
      "y": 27,
      "z": -7,
      "name": "Deco_Bone_Full"
    },
    {
      "x": 10,
      "y": 28,
      "z": -7,
      "name": "Deco_Bone_Full"
    },
    {
      "x": 10,
      "y": 20,
      "z": -6,
      "name": "Deco_Bone_Full"
    },
    {
      "x": 10,
      "y": 21,
      "z": -6,
      "name": "Deco_Bone_Full"
    },
    {
      "x": 10,
      "y": 22,
      "z": -6,
      "name": "Deco_Bone_Full"
    },
    {
      "x": 10,
      "y": 23,
      "z": -6,
      "name": "Deco_Bone_Full"
    },
    {
      "x": 10,
      "y": 24,
      "z": -6,
      "name": "Deco_Bone_Full"
    },
    {
      "x": 10,
      "y": 25,
      "z": -6,
      "name": "Deco_Bone_Full"
    },
    {
      "x": 10,
      "y": 26,
      "z": -6,
      "name": "Deco_Bone_Full"
    },
    {
      "x": 10,
      "y": 27,
      "z": -6,
      "name": "Deco_Bone_Full"
    },
    {
      "x": 10,
      "y": 28,
      "z": -6,
      "name": "Deco_Bone_Full"
    },
    {
      "x": 10,
      "y": 29,
      "z": -6,
      "name": "Deco_Bone_Full"
    },
    {
      "x": 10,
      "y": 30,
      "z": -6,
      "name": "Deco_Bone_Full"
    },
    {
      "x": 10,
      "y": 31,
      "z": -6,
      "name": "Deco_Bone_Full"
    },
    {
      "x": 10,
      "y": 21,
      "z": -5,
      "name": "Deco_Bone_Full"
    },
    {
      "x": 10,
      "y": 22,
      "z": -5,
      "name": "Deco_Bone_Full"
    },
    {
      "x": 10,
      "y": 23,
      "z": -5,
      "name": "Deco_Bone_Full"
    },
    {
      "x": 10,
      "y": 24,
      "z": -5,
      "name": "Deco_Bone_Full"
    },
    {
      "x": 10,
      "y": 25,
      "z": -5,
      "name": "Deco_Bone_Full"
    },
    {
      "x": 10,
      "y": 26,
      "z": -5,
      "name": "Deco_Bone_Full"
    },
    {
      "x": 11,
      "y": 11,
      "z": -16,
      "name": "Deco_Bone_Full"
    },
    {
      "x": 11,
      "y": 12,
      "z": -16,
      "name": "Deco_Bone_Full"
    },
    {
      "x": 11,
      "y": 13,
      "z": -16,
      "name": "Deco_Bone_Full"
    },
    {
      "x": 11,
      "y": 14,
      "z": -16,
      "name": "Deco_Bone_Full"
    },
    {
      "x": 11,
      "y": 15,
      "z": -16,
      "name": "Deco_Bone_Full"
    },
    {
      "x": 11,
      "y": 16,
      "z": -16,
      "name": "Deco_Bone_Full"
    },
    {
      "x": 11,
      "y": 9,
      "z": -15,
      "name": "Deco_Bone_Full"
    },
    {
      "x": 11,
      "y": 10,
      "z": -15,
      "name": "Deco_Bone_Full"
    },
    {
      "x": 11,
      "y": 11,
      "z": -15,
      "name": "Deco_Bone_Full"
    },
    {
      "x": 11,
      "y": 7,
      "z": -14,
      "name": "Deco_Bone_Full"
    },
    {
      "x": 11,
      "y": 8,
      "z": -14,
      "name": "Deco_Bone_Full"
    },
    {
      "x": 11,
      "y": 9,
      "z": -14,
      "name": "Deco_Bone_Full"
    },
    {
      "x": 11,
      "y": 21,
      "z": -8,
      "name": "Deco_Bone_Full"
    },
    {
      "x": 11,
      "y": 22,
      "z": -8,
      "name": "Deco_Bone_Full"
    },
    {
      "x": 11,
      "y": 20,
      "z": -7,
      "name": "Deco_Bone_Full"
    },
    {
      "x": 11,
      "y": 21,
      "z": -7,
      "name": "Deco_Bone_Full"
    },
    {
      "x": 11,
      "y": 22,
      "z": -7,
      "name": "Deco_Bone_Full"
    },
    {
      "x": 11,
      "y": 23,
      "z": -7,
      "name": "Deco_Bone_Full"
    },
    {
      "x": 11,
      "y": 24,
      "z": -7,
      "name": "Deco_Bone_Full"
    },
    {
      "x": 11,
      "y": 25,
      "z": -7,
      "name": "Deco_Bone_Full"
    },
    {
      "x": 11,
      "y": 26,
      "z": -7,
      "name": "Deco_Bone_Full"
    },
    {
      "x": 11,
      "y": 27,
      "z": -7,
      "name": "Deco_Bone_Full"
    },
    {
      "x": 11,
      "y": 28,
      "z": -7,
      "name": "Deco_Bone_Full"
    },
    {
      "x": 11,
      "y": 29,
      "z": -7,
      "name": "Deco_Bone_Full"
    },
    {
      "x": 11,
      "y": 30,
      "z": -7,
      "name": "Deco_Bone_Full"
    },
    {
      "x": 11,
      "y": 20,
      "z": -6,
      "name": "Deco_Bone_Full"
    },
    {
      "x": 11,
      "y": 21,
      "z": -6,
      "name": "Deco_Bone_Full"
    },
    {
      "x": 11,
      "y": 22,
      "z": -6,
      "name": "Deco_Bone_Full"
    },
    {
      "x": 11,
      "y": 23,
      "z": -6,
      "name": "Deco_Bone_Full"
    },
    {
      "x": 11,
      "y": 24,
      "z": -6,
      "name": "Deco_Bone_Full"
    },
    {
      "x": 11,
      "y": 25,
      "z": -6,
      "name": "Deco_Bone_Full"
    },
    {
      "x": 11,
      "y": 26,
      "z": -6,
      "name": "Deco_Bone_Full"
    },
    {
      "x": 11,
      "y": 27,
      "z": -6,
      "name": "Deco_Bone_Full"
    },
    {
      "x": 11,
      "y": 28,
      "z": -6,
      "name": "Deco_Bone_Full"
    },
    {
      "x": 11,
      "y": 21,
      "z": -5,
      "name": "Deco_Bone_Full"
    },
    {
      "x": 11,
      "y": 22,
      "z": -5,
      "name": "Deco_Bone_Full"
    },
    {
      "x": 11,
      "y": 23,
      "z": -5,
      "name": "Deco_Bone_Full"
    },
    {
      "x": 11,
      "y": 24,
      "z": -5,
      "name": "Deco_Bone_Full"
    },
    {
      "x": 12,
      "y": 16,
      "z": -16,
      "name": "Deco_Bone_Full"
    },
    {
      "x": 12,
      "y": 17,
      "z": -16,
      "name": "Deco_Bone_Full"
    },
    {
      "x": 12,
      "y": 18,
      "z": -16,
      "name": "Deco_Bone_Full"
    },
    {
      "x": 12,
      "y": 6,
      "z": -13,
      "name": "Deco_Bone_Full"
    },
    {
      "x": 12,
      "y": 7,
      "z": -13,
      "name": "Deco_Bone_Full"
    },
    {
      "x": 12,
      "y": 22,
      "z": -9,
      "name": "Deco_Bone_Full"
    },
    {
      "x": 12,
      "y": 21,
      "z": -8,
      "name": "Deco_Bone_Full"
    },
    {
      "x": 12,
      "y": 22,
      "z": -8,
      "name": "Deco_Bone_Full"
    },
    {
      "x": 12,
      "y": 23,
      "z": -8,
      "name": "Deco_Bone_Full"
    },
    {
      "x": 12,
      "y": 21,
      "z": -7,
      "name": "Deco_Bone_Full"
    },
    {
      "x": 12,
      "y": 22,
      "z": -7,
      "name": "Deco_Bone_Full"
    },
    {
      "x": 12,
      "y": 21,
      "z": -6,
      "name": "Deco_Bone_Full"
    },
    {
      "x": 12,
      "y": 22,
      "z": -6,
      "name": "Deco_Bone_Full"
    },
    {
      "x": 12,
      "y": 23,
      "z": -6,
      "name": "Deco_Bone_Full"
    },
    {
      "x": 12,
      "y": 21,
      "z": -5,
      "name": "Deco_Bone_Full"
    },
    {
      "x": 12,
      "y": 22,
      "z": -5,
      "name": "Deco_Bone_Full"
    },
    {
      "x": 12,
      "y": 21,
      "z": -4,
      "name": "Deco_Bone_Full"
    },
    {
      "x": 12,
      "y": 9,
      "z": -3,
      "name": "Deco_Bone_Full"
    },
    {
      "x": 12,
      "y": 10,
      "z": -3,
      "name": "Deco_Bone_Full"
    },
    {
      "x": 13,
      "y": 17,
      "z": -16,
      "name": "Deco_Bone_Full"
    },
    {
      "x": 13,
      "y": 18,
      "z": -16,
      "name": "Deco_Bone_Full"
    },
    {
      "x": 13,
      "y": 19,
      "z": -16,
      "name": "Deco_Bone_Full"
    },
    {
      "x": 13,
      "y": 18,
      "z": -15,
      "name": "Deco_Bone_Full"
    },
    {
      "x": 13,
      "y": 21,
      "z": -10,
      "name": "Deco_Bone_Full"
    },
    {
      "x": 13,
      "y": 21,
      "z": -9,
      "name": "Deco_Bone_Full"
    },
    {
      "x": 13,
      "y": 22,
      "z": -9,
      "name": "Deco_Bone_Full"
    },
    {
      "x": 13,
      "y": 23,
      "z": -9,
      "name": "Deco_Bone_Full"
    },
    {
      "x": 13,
      "y": 22,
      "z": -8,
      "name": "Deco_Bone_Full"
    },
    {
      "x": 13,
      "y": 21,
      "z": -5,
      "name": "Deco_Bone_Full"
    },
    {
      "x": 13,
      "y": 21,
      "z": -4,
      "name": "Deco_Bone_Full"
    },
    {
      "x": 13,
      "y": 22,
      "z": -4,
      "name": "Deco_Bone_Full"
    },
    {
      "x": 13,
      "y": 20,
      "z": -3,
      "name": "Deco_Bone_Full"
    },
    {
      "x": 13,
      "y": 10,
      "z": -2,
      "name": "Deco_Bone_Full"
    },
    {
      "x": 13,
      "y": 11,
      "z": -2,
      "name": "Deco_Bone_Full"
    },
    {
      "x": 13,
      "y": 12,
      "z": -2,
      "name": "Deco_Bone_Full"
    },
    {
      "x": 14,
      "y": 18,
      "z": -16,
      "name": "Deco_Bone_Full"
    },
    {
      "x": 14,
      "y": 18,
      "z": -15,
      "name": "Deco_Bone_Full"
    },
    {
      "x": 14,
      "y": 19,
      "z": -15,
      "name": "Deco_Bone_Full"
    },
    {
      "x": 14,
      "y": 20,
      "z": -15,
      "name": "Deco_Bone_Full"
    },
    {
      "x": 14,
      "y": 19,
      "z": -14,
      "name": "Deco_Bone_Full"
    },
    {
      "x": 14,
      "y": 21,
      "z": -11,
      "name": "Deco_Bone_Full"
    },
    {
      "x": 14,
      "y": 21,
      "z": -10,
      "name": "Deco_Bone_Full"
    },
    {
      "x": 14,
      "y": 22,
      "z": -10,
      "name": "Deco_Bone_Full"
    },
    {
      "x": 14,
      "y": 21,
      "z": -9,
      "name": "Deco_Bone_Full"
    },
    {
      "x": 14,
      "y": 20,
      "z": -4,
      "name": "Deco_Bone_Full"
    },
    {
      "x": 14,
      "y": 20,
      "z": -3,
      "name": "Deco_Bone_Full"
    },
    {
      "x": 14,
      "y": 21,
      "z": -3,
      "name": "Deco_Bone_Full"
    },
    {
      "x": 14,
      "y": 18,
      "z": -2,
      "name": "Deco_Bone_Full"
    },
    {
      "x": 14,
      "y": 19,
      "z": -2,
      "name": "Deco_Bone_Full"
    },
    {
      "x": 14,
      "y": 20,
      "z": -2,
      "name": "Deco_Bone_Full"
    },
    {
      "x": 14,
      "y": 12,
      "z": -1,
      "name": "Deco_Bone_Full"
    },
    {
      "x": 14,
      "y": 13,
      "z": -1,
      "name": "Deco_Bone_Full"
    },
    {
      "x": 14,
      "y": 14,
      "z": -1,
      "name": "Deco_Bone_Full"
    },
    {
      "x": 14,
      "y": 15,
      "z": -1,
      "name": "Deco_Bone_Full"
    },
    {
      "x": 14,
      "y": 16,
      "z": -1,
      "name": "Deco_Bone_Full"
    },
    {
      "x": 14,
      "y": 17,
      "z": -1,
      "name": "Deco_Bone_Full"
    },
    {
      "x": 14,
      "y": 18,
      "z": -1,
      "name": "Deco_Bone_Full"
    },
    {
      "x": 15,
      "y": 19,
      "z": -15,
      "name": "Deco_Bone_Full"
    },
    {
      "x": 15,
      "y": 19,
      "z": -14,
      "name": "Deco_Bone_Full"
    },
    {
      "x": 15,
      "y": 20,
      "z": -14,
      "name": "Deco_Bone_Full"
    },
    {
      "x": 15,
      "y": 19,
      "z": -13,
      "name": "Deco_Bone_Full"
    },
    {
      "x": 15,
      "y": 20,
      "z": -13,
      "name": "Deco_Bone_Full"
    },
    {
      "x": 15,
      "y": 21,
      "z": -13,
      "name": "Deco_Bone_Full"
    },
    {
      "x": 15,
      "y": 22,
      "z": -13,
      "name": "Deco_Bone_Full"
    },
    {
      "x": 15,
      "y": 19,
      "z": -12,
      "name": "Deco_Bone_Full"
    },
    {
      "x": 15,
      "y": 20,
      "z": -12,
      "name": "Deco_Bone_Full"
    },
    {
      "x": 15,
      "y": 21,
      "z": -12,
      "name": "Deco_Bone_Full"
    },
    {
      "x": 15,
      "y": 22,
      "z": -12,
      "name": "Deco_Bone_Full"
    },
    {
      "x": 15,
      "y": 23,
      "z": -12,
      "name": "Deco_Bone_Full"
    },
    {
      "x": 15,
      "y": 24,
      "z": -12,
      "name": "Deco_Bone_Full"
    },
    {
      "x": 15,
      "y": 20,
      "z": -11,
      "name": "Deco_Bone_Full"
    },
    {
      "x": 15,
      "y": 21,
      "z": -11,
      "name": "Deco_Bone_Full"
    },
    {
      "x": 15,
      "y": 22,
      "z": -11,
      "name": "Deco_Bone_Full"
    },
    {
      "x": 15,
      "y": 21,
      "z": -10,
      "name": "Deco_Bone_Full"
    },
    {
      "x": 16,
      "y": 19,
      "z": -14,
      "name": "Deco_Bone_Full"
    },
    {
      "x": 16,
      "y": 20,
      "z": -14,
      "name": "Deco_Bone_Full"
    },
    {
      "x": 16,
      "y": 21,
      "z": -14,
      "name": "Deco_Bone_Full"
    },
    {
      "x": 16,
      "y": 18,
      "z": -13,
      "name": "Deco_Bone_Full"
    },
    {
      "x": 16,
      "y": 19,
      "z": -13,
      "name": "Deco_Bone_Full"
    },
    {
      "x": 16,
      "y": 20,
      "z": -13,
      "name": "Deco_Bone_Full"
    },
    {
      "x": 16,
      "y": 21,
      "z": -13,
      "name": "Deco_Bone_Full"
    },
    {
      "x": 16,
      "y": 22,
      "z": -13,
      "name": "Deco_Bone_Full"
    },
    {
      "x": 16,
      "y": 23,
      "z": -13,
      "name": "Deco_Bone_Full"
    },
    {
      "x": 16,
      "y": 24,
      "z": -13,
      "name": "Deco_Bone_Full"
    },
    {
      "x": 16,
      "y": 25,
      "z": -13,
      "name": "Deco_Bone_Full"
    },
    {
      "x": 16,
      "y": 26,
      "z": -13,
      "name": "Deco_Bone_Full"
    },
    {
      "x": 16,
      "y": 18,
      "z": -12,
      "name": "Deco_Bone_Full"
    },
    {
      "x": 16,
      "y": 19,
      "z": -12,
      "name": "Deco_Bone_Full"
    },
    {
      "x": 16,
      "y": 20,
      "z": -12,
      "name": "Deco_Bone_Full"
    },
    {
      "x": 16,
      "y": 21,
      "z": -12,
      "name": "Deco_Bone_Full"
    },
    {
      "x": 16,
      "y": 22,
      "z": -12,
      "name": "Deco_Bone_Full"
    },
    {
      "x": 16,
      "y": 23,
      "z": -12,
      "name": "Deco_Bone_Full"
    },
    {
      "x": 16,
      "y": 24,
      "z": -12,
      "name": "Deco_Bone_Full"
    },
    {
      "x": 16,
      "y": 25,
      "z": -12,
      "name": "Deco_Bone_Full"
    },
    {
      "x": 16,
      "y": 26,
      "z": -12,
      "name": "Deco_Bone_Full"
    },
    {
      "x": 16,
      "y": 27,
      "z": -12,
      "name": "Deco_Bone_Full"
    },
    {
      "x": 16,
      "y": 28,
      "z": -12,
      "name": "Deco_Bone_Full"
    },
    {
      "x": 16,
      "y": 29,
      "z": -12,
      "name": "Deco_Bone_Full"
    },
    {
      "x": 16,
      "y": 19,
      "z": -11,
      "name": "Deco_Bone_Full"
    },
    {
      "x": 16,
      "y": 20,
      "z": -11,
      "name": "Deco_Bone_Full"
    },
    {
      "x": 16,
      "y": 21,
      "z": -11,
      "name": "Deco_Bone_Full"
    },
    {
      "x": 16,
      "y": 22,
      "z": -11,
      "name": "Deco_Bone_Full"
    },
    {
      "x": 16,
      "y": 23,
      "z": -11,
      "name": "Deco_Bone_Full"
    },
    {
      "x": 16,
      "y": 24,
      "z": -11,
      "name": "Deco_Bone_Full"
    },
    {
      "x": 17,
      "y": 19,
      "z": -14,
      "name": "Deco_Bone_Full"
    },
    {
      "x": 17,
      "y": 20,
      "z": -14,
      "name": "Deco_Bone_Full"
    },
    {
      "x": 17,
      "y": 18,
      "z": -13,
      "name": "Deco_Bone_Full"
    },
    {
      "x": 17,
      "y": 19,
      "z": -13,
      "name": "Deco_Bone_Full"
    },
    {
      "x": 17,
      "y": 20,
      "z": -13,
      "name": "Deco_Bone_Full"
    },
    {
      "x": 17,
      "y": 21,
      "z": -13,
      "name": "Deco_Bone_Full"
    },
    {
      "x": 17,
      "y": 22,
      "z": -13,
      "name": "Deco_Bone_Full"
    },
    {
      "x": 17,
      "y": 23,
      "z": -13,
      "name": "Deco_Bone_Full"
    },
    {
      "x": 17,
      "y": 24,
      "z": -13,
      "name": "Deco_Bone_Full"
    },
    {
      "x": 17,
      "y": 25,
      "z": -13,
      "name": "Deco_Bone_Full"
    },
    {
      "x": 17,
      "y": 26,
      "z": -13,
      "name": "Deco_Bone_Full"
    },
    {
      "x": 17,
      "y": 27,
      "z": -13,
      "name": "Deco_Bone_Full"
    },
    {
      "x": 17,
      "y": 28,
      "z": -13,
      "name": "Deco_Bone_Full"
    },
    {
      "x": 17,
      "y": 18,
      "z": -12,
      "name": "Deco_Bone_Full"
    },
    {
      "x": 17,
      "y": 19,
      "z": -12,
      "name": "Deco_Bone_Full"
    },
    {
      "x": 17,
      "y": 20,
      "z": -12,
      "name": "Deco_Bone_Full"
    },
    {
      "x": 17,
      "y": 21,
      "z": -12,
      "name": "Deco_Bone_Full"
    },
    {
      "x": 17,
      "y": 22,
      "z": -12,
      "name": "Deco_Bone_Full"
    },
    {
      "x": 17,
      "y": 23,
      "z": -12,
      "name": "Deco_Bone_Full"
    },
    {
      "x": 17,
      "y": 24,
      "z": -12,
      "name": "Deco_Bone_Full"
    },
    {
      "x": 17,
      "y": 25,
      "z": -12,
      "name": "Deco_Bone_Full"
    },
    {
      "x": 17,
      "y": 26,
      "z": -12,
      "name": "Deco_Bone_Full"
    },
    {
      "x": 17,
      "y": 19,
      "z": -11,
      "name": "Deco_Bone_Full"
    },
    {
      "x": 17,
      "y": 20,
      "z": -11,
      "name": "Deco_Bone_Full"
    },
    {
      "x": 17,
      "y": 21,
      "z": -11,
      "name": "Deco_Bone_Full"
    },
    {
      "x": 17,
      "y": 22,
      "z": -11,
      "name": "Deco_Bone_Full"
    },
    {
      "x": 17,
      "y": 6,
      "z": -8,
      "name": "Deco_Bone_Full"
    },
    {
      "x": 17,
      "y": 7,
      "z": -8,
      "name": "Deco_Bone_Full"
    },
    {
      "x": 18,
      "y": 19,
      "z": -15,
      "name": "Deco_Bone_Full"
    },
    {
      "x": 18,
      "y": 19,
      "z": -14,
      "name": "Deco_Bone_Full"
    },
    {
      "x": 18,
      "y": 20,
      "z": -14,
      "name": "Deco_Bone_Full"
    },
    {
      "x": 18,
      "y": 19,
      "z": -13,
      "name": "Deco_Bone_Full"
    },
    {
      "x": 18,
      "y": 20,
      "z": -13,
      "name": "Deco_Bone_Full"
    },
    {
      "x": 18,
      "y": 19,
      "z": -12,
      "name": "Deco_Bone_Full"
    },
    {
      "x": 18,
      "y": 20,
      "z": -12,
      "name": "Deco_Bone_Full"
    },
    {
      "x": 18,
      "y": 21,
      "z": -12,
      "name": "Deco_Bone_Full"
    },
    {
      "x": 18,
      "y": 19,
      "z": -11,
      "name": "Deco_Bone_Full"
    },
    {
      "x": 18,
      "y": 20,
      "z": -11,
      "name": "Deco_Bone_Full"
    },
    {
      "x": 18,
      "y": 19,
      "z": -10,
      "name": "Deco_Bone_Full"
    },
    {
      "x": 18,
      "y": 17,
      "z": -8,
      "name": "Empty"
    },
    {
      "x": 18,
      "y": 18,
      "z": -8,
      "name": "Empty"
    },
    {
      "x": 18,
      "y": 7,
      "z": -7,
      "name": "Deco_Bone_Full"
    },
    {
      "x": 18,
      "y": 8,
      "z": -7,
      "name": "Deco_Bone_Full"
    },
    {
      "x": 18,
      "y": 9,
      "z": -7,
      "name": "Deco_Bone_Full"
    },
    {
      "x": 19,
      "y": 18,
      "z": -16,
      "name": "Deco_Bone_Full"
    },
    {
      "x": 19,
      "y": 18,
      "z": -15,
      "name": "Deco_Bone_Full"
    },
    {
      "x": 19,
      "y": 19,
      "z": -15,
      "name": "Deco_Bone_Full"
    },
    {
      "x": 19,
      "y": 20,
      "z": -15,
      "name": "Deco_Bone_Full"
    },
    {
      "x": 19,
      "y": 19,
      "z": -14,
      "name": "Deco_Bone_Full"
    },
    {
      "x": 19,
      "y": 19,
      "z": -11,
      "name": "Deco_Bone_Full"
    },
    {
      "x": 19,
      "y": 18,
      "z": -10,
      "name": "Deco_Bone_Full"
    },
    {
      "x": 19,
      "y": 19,
      "z": -10,
      "name": "Deco_Bone_Full"
    },
    {
      "x": 19,
      "y": 20,
      "z": -10,
      "name": "Deco_Bone_Full"
    },
    {
      "x": 19,
      "y": 18,
      "z": -9,
      "name": "Deco_Bone_Full"
    },
    {
      "x": 19,
      "y": 17,
      "z": -8,
      "name": "Plant_Crop_Health3",
      "rotation": 3
    },
    {
      "x": 19,
      "y": 18,
      "z": -8,
      "name": "Plant_Crop_Health3",
      "filler": 1024,
      "rotation": 3
    },
    {
      "x": 19,
      "y": 9,
      "z": -7,
      "name": "Deco_Bone_Full"
    },
    {
      "x": 19,
      "y": 10,
      "z": -7,
      "name": "Deco_Bone_Full"
    },
    {
      "x": 19,
      "y": 11,
      "z": -7,
      "name": "Deco_Bone_Full"
    },
    {
      "x": 20,
      "y": 18,
      "z": -17,
      "name": "Deco_Bone_Full"
    },
    {
      "x": 20,
      "y": 18,
      "z": -16,
      "name": "Deco_Bone_Full"
    },
    {
      "x": 20,
      "y": 19,
      "z": -16,
      "name": "Deco_Bone_Full"
    },
    {
      "x": 20,
      "y": 18,
      "z": -15,
      "name": "Deco_Bone_Full"
    },
    {
      "x": 20,
      "y": 18,
      "z": -10,
      "name": "Deco_Bone_Full"
    },
    {
      "x": 20,
      "y": 17,
      "z": -9,
      "name": "Deco_Bone_Full"
    },
    {
      "x": 20,
      "y": 18,
      "z": -9,
      "name": "Deco_Bone_Full"
    },
    {
      "x": 20,
      "y": 19,
      "z": -9,
      "name": "Deco_Bone_Full"
    },
    {
      "x": 20,
      "y": 16,
      "z": -8,
      "name": "Deco_Bone_Full"
    },
    {
      "x": 20,
      "y": 17,
      "z": -8,
      "name": "Deco_Bone_Full"
    },
    {
      "x": 20,
      "y": 18,
      "z": -8,
      "name": "Deco_Bone_Full"
    },
    {
      "x": 20,
      "y": 11,
      "z": -7,
      "name": "Deco_Bone_Full"
    },
    {
      "x": 20,
      "y": 12,
      "z": -7,
      "name": "Deco_Bone_Full"
    },
    {
      "x": 20,
      "y": 13,
      "z": -7,
      "name": "Deco_Bone_Full"
    },
    {
      "x": 20,
      "y": 14,
      "z": -7,
      "name": "Deco_Bone_Full"
    },
    {
      "x": 20,
      "y": 15,
      "z": -7,
      "name": "Deco_Bone_Full"
    },
    {
      "x": 20,
      "y": 16,
      "z": -7,
      "name": "Deco_Bone_Full"
    },
    {
      "x": 21,
      "y": 17,
      "z": -18,
      "name": "Deco_Bone_Full"
    },
    {
      "x": 21,
      "y": 17,
      "z": -17,
      "name": "Deco_Bone_Full"
    },
    {
      "x": 21,
      "y": 18,
      "z": -17,
      "name": "Deco_Bone_Full"
    },
    {
      "x": 21,
      "y": 19,
      "z": -17,
      "name": "Deco_Bone_Full"
    },
    {
      "x": 21,
      "y": 18,
      "z": -16,
      "name": "Deco_Bone_Full"
    },
    {
      "x": 22,
      "y": 17,
      "z": -18,
      "name": "Deco_Bone_Full"
    },
    {
      "x": 22,
      "y": 18,
      "z": -18,
      "name": "Deco_Bone_Full"
    },
    {
      "x": 22,
      "y": 17,
      "z": -17,
      "name": "Deco_Bone_Full"
    }
  ]
}