{
  "version": 8,
  "blockIdVersion": 8,
  "anchorX": 23,
  "anchorY": 15,
  "anchorZ": 9,
  "blocks": [
    {
      "x": 17,
      "y": 29,
      "z": 13,
      "name": "Rock_Volcanic_Cracked_Poisoned"
    },
    {
      "x": 17,
      "y": 30,
      "z": 13,
      "name": "Rock_Volcanic_Cracked_Poisoned"
    },
    {
      "x": 17,
      "y": 30,
      "z": 14,
      "name": "Rock_Volcanic_Cracked_Poisoned"
    },
    {
      "x": 17,
      "y": 31,
      "z": 14,
      "name": "Rock_Volcanic_Cracked_Poisoned"
    },
    {
      "x": 17,
      "y": 32,
      "z": 14,
      "name": "Rock_Volcanic_Cracked_Poisoned"
    },
    {
      "x": 18,
      "y": 25,
      "z": 12,
      "name": "Rock_Volcanic_Cracked_Poisoned"
    },
    {
      "x": 18,
      "y": 26,
      "z": 12,
      "name": "Rock_Volcanic_Cracked_Poisoned"
    },
    {
      "x": 18,
      "y": 27,
      "z": 12,
      "name": "Rock_Volcanic_Cracked_Poisoned"
    },
    {
      "x": 18,
      "y": 28,
      "z": 12,
      "name": "Rock_Volcanic_Cracked_Poisoned"
    },
    {
      "x": 18,
      "y": 29,
      "z": 12,
      "name": "Rock_Volcanic_Cracked_Poisoned"
    },
    {
      "x": 18,
      "y": 27,
      "z": 13,
      "name": "Rock_Volcanic_Cracked_Poisoned"
    },
    {
      "x": 18,
      "y": 28,
      "z": 13,
      "name": "Rock_Volcanic_Cracked_Poisoned"
    },
    {
      "x": 18,
      "y": 29,
      "z": 13,
      "name": "Rock_Volcanic_Cracked_Poisoned"
    },
    {
      "x": 18,
      "y": 30,
      "z": 13,
      "name": "Rock_Volcanic_Cracked_Poisoned"
    },
    {
      "x": 19,
      "y": 23,
      "z": 10,
      "name": "Rock_Volcanic_Cracked_Poisoned"
    },
    {
      "x": 19,
      "y": 24,
      "z": 10,
      "name": "Rock_Volcanic_Cracked_Poisoned"
    },
    {
      "x": 19,
      "y": 22,
      "z": 11,
      "name": "Rock_Volcanic_Cracked_Poisoned"
    },
    {
      "x": 19,
      "y": 23,
      "z": 11,
      "name": "Rock_Volcanic_Cracked_Poisoned"
    },
    {
      "x": 19,
      "y": 24,
      "z": 11,
      "name": "Rock_Volcanic_Cracked_Poisoned"
    },
    {
      "x": 19,
      "y": 25,
      "z": 11,
      "name": "Rock_Volcanic_Cracked_Poisoned"
    },
    {
      "x": 19,
      "y": 26,
      "z": 11,
      "name": "Rock_Volcanic_Cracked_Poisoned"
    },
    {
      "x": 19,
      "y": 27,
      "z": 11,
      "name": "Rock_Volcanic_Cracked_Poisoned"
    },
    {
      "x": 19,
      "y": 24,
      "z": 12,
      "name": "Rock_Volcanic_Cracked_Poisoned"
    },
    {
      "x": 19,
      "y": 25,
      "z": 12,
      "name": "Rock_Volcanic_Cracked_Poisoned"
    },
    {
      "x": 19,
      "y": 26,
      "z": 12,
      "name": "Rock_Volcanic_Cracked_Poisoned"
    },
    {
      "x": 19,
      "y": 27,
      "z": 12,
      "name": "Rock_Volcanic_Cracked_Poisoned"
    },
    {
      "x": 19,
      "y": 28,
      "z": 12,
      "name": "Rock_Volcanic_Cracked_Poisoned"
    },
    {
      "x": 19,
      "y": 26,
      "z": 13,
      "name": "Rock_Volcanic_Cracked_Poisoned"
    },
    {
      "x": 20,
      "y": 20,
      "z": 10,
      "name": "Rock_Volcanic_Cracked_Poisoned"
    },
    {
      "x": 20,
      "y": 21,
      "z": 10,
      "name": "Rock_Volcanic_Cracked_Poisoned"
    },
    {
      "x": 20,
      "y": 22,
      "z": 10,
      "name": "Rock_Volcanic_Cracked_Poisoned"
    },
    {
      "x": 20,
      "y": 23,
      "z": 10,
      "name": "Rock_Volcanic_Cracked_Poisoned"
    },
    {
      "x": 20,
      "y": 21,
      "z": 11,
      "name": "Rock_Volcanic_Cracked_Poisoned"
    },
    {
      "x": 20,
      "y": 22,
      "z": 11,
      "name": "Rock_Volcanic_Cracked_Poisoned"
    },
    {
      "x": 20,
      "y": 23,
      "z": 11,
      "name": "Rock_Volcanic_Cracked_Poisoned"
    },
    {
      "x": 20,
      "y": 24,
      "z": 11,
      "name": "Rock_Volcanic_Cracked_Poisoned"
    },
    {
      "x": 20,
      "y": 25,
      "z": 11,
      "name": "Rock_Volcanic_Cracked_Poisoned"
    },
    {
      "x": 20,
      "y": 22,
      "z": 12,
      "name": "Rock_Volcanic_Cracked_Poisoned"
    },
    {
      "x": 20,
      "y": 23,
      "z": 12,
      "name": "Rock_Volcanic_Cracked_Poisoned"
    },
    {
      "x": 20,
      "y": 24,
      "z": 12,
      "name": "Rock_Volcanic_Cracked_Poisoned"
    },
    {
      "x": 20,
      "y": 25,
      "z": 12,
      "name": "Rock_Volcanic_Cracked_Poisoned"
    },
    {
      "x": 20,
      "y": 26,
      "z": 12,
      "name": "Rock_Volcanic_Cracked_Poisoned"
    },
    {
      "x": 21,
      "y": 18,
      "z": 10,
      "name": "Rock_Volcanic_Cracked_Poisoned"
    },
    {
      "x": 21,
      "y": 19,
      "z": 10,
      "name": "Rock_Volcanic_Cracked_Poisoned"
    },
    {
      "x": 21,
      "y": 20,
      "z": 10,
      "name": "Rock_Volcanic_Cracked_Poisoned"
    },
    {
      "x": 21,
      "y": 21,
      "z": 10,
      "name": "Rock_Volcanic_Cracked_Poisoned"
    },
    {
      "x": 21,
      "y": 19,
      "z": 11,
      "name": "Rock_Volcanic_Cracked_Poisoned"
    },
    {
      "x": 21,
      "y": 20,
      "z": 11,
      "name": "Rock_Volcanic_Cracked_Poisoned"
    },
    {
      "x": 21,
      "y": 21,
      "z": 11,
      "name": "Rock_Volcanic_Cracked_Poisoned"
    },
    {
      "x": 21,
      "y": 22,
      "z": 11,
      "name": "Rock_Volcanic_Cracked_Poisoned"
    },
    {
      "x": 21,
      "y": 21,
      "z": 12,
      "name": "Rock_Volcanic_Cracked_Poisoned"
    },
    {
      "x": 21,
      "y": 22,
      "z": 12,
      "name": "Rock_Volcanic_Cracked_Poisoned"
    },
    {
      "x": 22,
      "y": 10,
      "z": 8,
      "name": "Rock_Volcanic_Cracked_Poisoned"
    },
    {
      "x": 22,
      "y": 11,
      "z": 8,
      "name": "Rock_Volcanic_Cracked_Poisoned"
    },
    {
      "x": 22,
      "y": 12,
      "z": 8,
      "name": "Rock_Volcanic_Cracked_Poisoned"
    },
    {
      "x": 22,
      "y": 11,
      "z": 9,
      "name": "Rock_Volcanic_Cracked_Poisoned"
    },
    {
      "x": 22,
      "y": 12,
      "z": 9,
      "name": "Rock_Volcanic_Cracked_Poisoned"
    },
    {
      "x": 22,
      "y": 13,
      "z": 9,
      "name": "Rock_Volcanic_Cracked_Poisoned"
    },
    {
      "x": 22,
      "y": 14,
      "z": 9,
      "name": "Rock_Volcanic_Cracked_Poisoned"
    },
    {
      "x": 22,
      "y": 15,
      "z": 9,
      "name": "Rock_Volcanic_Cracked_Poisoned"
    },
    {
      "x": 22,
      "y": 16,
      "z": 9,
      "name": "Rock_Volcanic_Cracked_Poisoned"
    },
    {
      "x": 22,
      "y": 18,
      "z": 9,
      "name": "Rock_Volcanic_Cracked_Poisoned"
    },
    {
      "x": 22,
      "y": 19,
      "z": 9,
      "name": "Rock_Volcanic_Cracked_Poisoned"
    },
    {
      "x": 22,
      "y": 12,
      "z": 10,
      "name": "Rock_Volcanic_Cracked_Poisoned"
    },
    {
      "x": 22,
      "y": 13,
      "z": 10,
      "name": "Rock_Volcanic_Cracked_Poisoned"
    },
    {
      "x": 22,
      "y": 14,
      "z": 10,
      "name": "Rock_Volcanic_Cracked_Poisoned"
    },
    {
      "x": 22,
      "y": 15,
      "z": 10,
      "name": "Rock_Volcanic_Cracked_Poisoned"
    },
    {
      "x": 22,
      "y": 16,
      "z": 10,
      "name": "Rock_Volcanic_Cracked_Poisoned"
    },
    {
      "x": 22,
      "y": 17,
      "z": 10,
      "name": "Rock_Volcanic_Cracked_Poisoned"
    },
    {
      "x": 22,
      "y": 18,
      "z": 10,
      "name": "Rock_Volcanic_Cracked_Poisoned"
    },
    {
      "x": 22,
      "y": 19,
      "z": 10,
      "name": "Rock_Volcanic_Cracked_Poisoned"
    },
    {
      "x": 22,
      "y": 17,
      "z": 11,
      "name": "Rock_Volcanic_Cracked_Poisoned"
    },
    {
      "x": 22,
      "y": 18,
      "z": 11,
      "name": "Rock_Volcanic_Cracked_Poisoned"
    },
    {
      "x": 22,
      "y": 19,
      "z": 11,
      "name": "Rock_Volcanic_Cracked_Poisoned"
    },
    {
      "x": 22,
      "y": 20,
      "z": 11,
      "name": "Rock_Volcanic_Cracked_Poisoned"
    },
    {
      "x": 22,
      "y": 20,
      "z": 12,
      "name": "Rock_Volcanic_Cracked_Poisoned"
    },
    {
      "x": 22,
      "y": 21,
      "z": 12,
      "name": "Rock_Volcanic_Cracked_Poisoned"
    },
    {
      "x": 23,
      "y": 10,
      "z": 7,
      "name": "Rock_Volcanic_Cracked_Poisoned"
    },
    {
      "x": 23,
      "y": 11,
      "z": 7,
      "name": "Rock_Volcanic_Cracked_Poisoned"
    },
    {
      "x": 23,
      "y": 12,
      "z": 7,
      "name": "Rock_Volcanic_Cracked_Poisoned"
    },
    {
      "x": 23,
      "y": 13,
      "z": 7,
      "name": "Rock_Volcanic_Cracked_Poisoned"
    },
    {
      "x": 23,
      "y": 14,
      "z": 7,
      "name": "Rock_Volcanic_Cracked_Poisoned"
    },
    {
      "x": 23,
      "y": 11,
      "z": 8,
      "name": "Rock_Volcanic_Cracked_Poisoned"
    },
    {
      "x": 23,
      "y": 12,
      "z": 8,
      "name": "Rock_Volcanic_Cracked_Poisoned"
    },
    {
      "x": 23,
      "y": 13,
      "z": 8,
      "name": "Rock_Volcanic_Cracked_Poisoned"
    },
    {
      "x": 23,
      "y": 14,
      "z": 8,
      "name": "Rock_Volcanic_Cracked_Poisoned"
    },
    {
      "x": 23,
      "y": 15,
      "z": 8,
      "name": "Rock_Volcanic_Cracked_Poisoned"
    },
    {
      "x": 23,
      "y": 16,
      "z": 8,
      "name": "Rock_Volcanic_Cracked_Poisoned"
    },
    {
      "x": 23,
      "y": 17,
      "z": 8,
      "name": "Rock_Volcanic_Cracked_Poisoned"
    },
    {
      "x": 23,
      "y": 11,
      "z": 9,
      "name": "Rock_Volcanic_Cracked_Poisoned"
    },
    {
      "x": 23,
      "y": 12,
      "z": 9,
      "name": "Rock_Volcanic_Cracked_Poisoned"
    },
    {
      "x": 23,
      "y": 13,
      "z": 9,
      "name": "Rock_Volcanic_Cracked_Poisoned"
    },
    {
      "x": 23,
      "y": 14,
      "z": 9,
      "name": "Rock_Volcanic_Cracked_Poisoned"
    },
    {
      "x": 23,
      "y": 15,
      "z": 9,
      "name": "Rock_Volcanic_Cracked_Poisoned"
    },
    {
      "x": 23,
      "y": 16,
      "z": 9,
      "name": "Rock_Volcanic_Cracked_Poisoned"
    },
    {
      "x": 23,
      "y": 17,
      "z": 9,
      "name": "Rock_Volcanic_Cracked_Poisoned"
    },
    {
      "x": 23,
      "y": 18,
      "z": 9,
      "name": "Rock_Volcanic_Cracked_Poisoned"
    },
    {
      "x": 23,
      "y": 19,
      "z": 9,
      "name": "Rock_Volcanic_Cracked_Poisoned"
    },
    {
      "x": 23,
      "y": 20,
      "z": 9,
      "name": "Rock_Volcanic_Cracked_Poisoned"
    },
    {
      "x": 23,
      "y": 12,
      "z": 10,
      "name": "Rock_Volcanic_Cracked_Poisoned"
    },
    {
      "x": 23,
      "y": 13,
      "z": 10,
      "name": "Rock_Volcanic_Cracked_Poisoned"
    },
    {
      "x": 23,
      "y": 14,
      "z": 10,
      "name": "Rock_Volcanic_Cracked_Poisoned"
    },
    {
      "x": 23,
      "y": 15,
      "z": 10,
      "name": "Rock_Volcanic_Cracked_Poisoned"
    },
    {
      "x": 23,
      "y": 16,
      "z": 10,
      "name": "Rock_Volcanic_Cracked_Poisoned"
    },
    {
      "x": 23,
      "y": 17,
      "z": 10,
      "name": "Rock_Volcanic_Cracked_Poisoned"
    },
    {
      "x": 23,
      "y": 18,
      "z": 10,
      "name": "Rock_Volcanic_Cracked_Poisoned"
    },
    {
      "x": 23,
      "y": 19,
      "z": 10,
      "name": "Rock_Volcanic_Cracked_Poisoned"
    },
    {
      "x": 23,
      "y": 14,
      "z": 11,
      "name": "Rock_Volcanic_Cracked_Poisoned"
    },
    {
      "x": 23,
      "y": 15,
      "z": 11,
      "name": "Rock_Volcanic_Cracked_Poisoned"
    },
    {
      "x": 23,
      "y": 16,
      "z": 11,
      "name": "Rock_Volcanic_Cracked_Poisoned"
    },
    {
      "x": 23,
      "y": 17,
      "z": 11,
      "name": "Rock_Volcanic_Cracked_Poisoned"
    },
    {
      "x": 23,
      "y": 18,
      "z": 11,
      "name": "Rock_Volcanic_Cracked_Poisoned"
    },
    {
      "x": 23,
      "y": 19,
      "z": 11,
      "name": "Rock_Volcanic_Cracked_Poisoned"
    },
    {
      "x": 23,
      "y": 20,
      "z": 11,
      "name": "Rock_Volcanic_Cracked_Poisoned"
    },
    {
      "x": 23,
      "y": 16,
      "z": 12,
      "name": "Rock_Volcanic_Cracked_Poisoned"
    },
    {
      "x": 23,
      "y": 17,
      "z": 12,
      "name": "Rock_Volcanic_Cracked_Poisoned"
    },
    {
      "x": 23,
      "y": 18,
      "z": 12,
      "name": "Rock_Volcanic_Cracked_Poisoned"
    },
    {
      "x": 24,
      "y": 11,
      "z": 7,
      "name": "Rock_Volcanic_Cracked_Poisoned"
    },
    {
      "x": 24,
      "y": 12,
      "z": 7,
      "name": "Rock_Volcanic_Cracked_Poisoned"
    },
    {
      "x": 24,
      "y": 13,
      "z": 7,
      "name": "Rock_Volcanic_Cracked_Poisoned"
    },
    {
      "x": 24,
      "y": 14,
      "z": 7,
      "name": "Rock_Volcanic_Cracked_Poisoned"
    },
    {
      "x": 24,
      "y": 15,
      "z": 7,
      "name": "Rock_Volcanic_Cracked_Poisoned"
    },
    {
      "x": 24,
      "y": 16,
      "z": 7,
      "name": "Rock_Volcanic_Cracked_Poisoned"
    },
    {
      "x": 24,
      "y": 17,
      "z": 7,
      "name": "Rock_Volcanic_Cracked_Poisoned"
    },
    {
      "x": 24,
      "y": 18,
      "z": 7,
      "name": "Rock_Volcanic_Cracked_Poisoned"
    },
    {
      "x": 24,
      "y": 11,
      "z": 8,
      "name": "Rock_Volcanic_Cracked_Poisoned"
    },
    {
      "x": 24,
      "y": 12,
      "z": 8,
      "name": "Rock_Volcanic_Cracked_Poisoned"
    },
    {
      "x": 24,
      "y": 13,
      "z": 8,
      "name": "Rock_Volcanic_Cracked_Poisoned"
    },
    {
      "x": 24,
      "y": 14,
      "z": 8,
      "name": "Rock_Volcanic_Cracked_Poisoned"
    },
    {
      "x": 24,
      "y": 15,
      "z": 8,
      "name": "Rock_Volcanic_Cracked_Poisoned"
    },
    {
      "x": 24,
      "y": 16,
      "z": 8,
      "name": "Rock_Volcanic_Cracked_Poisoned"
    },
    {
      "x": 24,
      "y": 17,
      "z": 8,
      "name": "Rock_Volcanic_Cracked_Poisoned"
    },
    {
      "x": 24,
      "y": 18,
      "z": 8,
      "name": "Rock_Volcanic_Cracked_Poisoned"
    },
    {
      "x": 24,
      "y": 19,
      "z": 8,
      "name": "Rock_Volcanic_Cracked_Poisoned"
    },
    {
      "x": 24,
      "y": 20,
      "z": 8,
      "name": "Rock_Volcanic_Cracked_Poisoned"
    },
    {
      "x": 24,
      "y": 11,
      "z": 9,
      "name": "Rock_Volcanic_Cracked_Poisoned"
    },
    {
      "x": 24,
      "y": 12,
      "z": 9,
      "name": "Rock_Volcanic_Cracked_Poisoned"
    },
    {
      "x": 24,
      "y": 13,
      "z": 9,
      "name": "Rock_Volcanic_Cracked_Poisoned"
    },
    {
      "x": 24,
      "y": 14,
      "z": 9,
      "name": "Rock_Volcanic_Cracked_Poisoned"
    },
    {
      "x": 24,
      "y": 15,
      "z": 9,
      "name": "Rock_Volcanic_Cracked_Poisoned"
    },
    {
      "x": 24,
      "y": 16,
      "z": 9,
      "name": "Rock_Volcanic_Cracked_Poisoned"
    },
    {
      "x": 24,
      "y": 17,
      "z": 9,
      "name": "Rock_Volcanic_Cracked_Poisoned"
    },
    {
      "x": 24,
      "y": 18,
      "z": 9,
      "name": "Rock_Volcanic_Cracked_Poisoned"
    },
    {
      "x": 24,
      "y": 19,
      "z": 9,
      "name": "Rock_Volcanic_Cracked_Poisoned"
    },
    {
      "x": 24,
      "y": 20,
      "z": 9,
      "name": "Rock_Volcanic_Cracked_Poisoned"
    },
    {
      "x": 24,
      "y": 14,
      "z": 10,
      "name": "Rock_Volcanic_Cracked_Poisoned"
    },
    {
      "x": 24,
      "y": 15,
      "z": 10,
      "name": "Rock_Volcanic_Cracked_Poisoned"
    },
    {
      "x": 24,
      "y": 16,
      "z": 10,
      "name": "Rock_Volcanic_Cracked_Poisoned"
    },
    {
      "x": 24,
      "y": 17,
      "z": 10,
      "name": "Rock_Volcanic_Cracked_Poisoned"
    },
    {
      "x": 24,
      "y": 18,
      "z": 10,
      "name": "Rock_Volcanic_Cracked_Poisoned"
    },
    {
      "x": 24,
      "y": 19,
      "z": 10,
      "name": "Rock_Volcanic_Cracked_Poisoned"
    },
    {
      "x": 24,
      "y": 14,
      "z": 11,
      "name": "Rock_Volcanic_Cracked_Poisoned"
    },
    {
      "x": 24,
      "y": 15,
      "z": 11,
      "name": "Rock_Volcanic_Cracked_Poisoned"
    },
    {
      "x": 24,
      "y": 16,
      "z": 11,
      "name": "Rock_Volcanic_Cracked_Poisoned"
    },
    {
      "x": 24,
      "y": 17,
      "z": 11,
      "name": "Rock_Volcanic_Cracked_Poisoned"
    },
    {
      "x": 24,
      "y": 18,
      "z": 11,
      "name": "Rock_Volcanic_Cracked_Poisoned"
    },
    {
      "x": 24,
      "y": 19,
      "z": 11,
      "name": "Rock_Volcanic_Cracked_Poisoned"
    },
    {
      "x": 24,
      "y": 15,
      "z": 12,
      "name": "Rock_Volcanic_Cracked_Poisoned"
    },
    {
      "x": 24,
      "y": 16,
      "z": 12,
      "name": "Rock_Volcanic_Cracked_Poisoned"
    },
    {
      "x": 24,
      "y": 17,
      "z": 12,
      "name": "Rock_Volcanic_Cracked_Poisoned"
    },
    {
      "x": 24,
      "y": 18,
      "z": 12,
      "name": "Rock_Volcanic_Cracked_Poisoned"
    },
    {
      "x": 24,
      "y": 17,
      "z": 13,
      "name": "Rock_Volcanic_Cracked_Poisoned"
    },
    {
      "x": 24,
      "y": 18,
      "z": 13,
      "name": "Rock_Volcanic_Cracked_Poisoned"
    },
    {
      "x": 25,
      "y": 17,
      "z": 7,
      "name": "Rock_Volcanic_Cracked_Poisoned"
    },
    {
      "x": 25,
      "y": 18,
      "z": 7,
      "name": "Rock_Volcanic_Cracked_Poisoned"
    },
    {
      "x": 25,
      "y": 19,
      "z": 7,
      "name": "Rock_Volcanic_Cracked_Poisoned"
    },
    {
      "x": 25,
      "y": 20,
      "z": 7,
      "name": "Rock_Volcanic_Cracked_Poisoned"
    },
    {
      "x": 25,
      "y": 21,
      "z": 7,
      "name": "Rock_Volcanic_Cracked_Poisoned"
    },
    {
      "x": 25,
      "y": 22,
      "z": 7,
      "name": "Rock_Volcanic_Cracked_Poisoned"
    },
    {
      "x": 25,
      "y": 12,
      "z": 8,
      "name": "Rock_Volcanic_Cracked_Poisoned"
    },
    {
      "x": 25,
      "y": 13,
      "z": 8,
      "name": "Rock_Volcanic_Cracked_Poisoned"
    },
    {
      "x": 25,
      "y": 14,
      "z": 8,
      "name": "Rock_Volcanic_Cracked_Poisoned"
    },
    {
      "x": 25,
      "y": 15,
      "z": 8,
      "name": "Rock_Volcanic_Cracked_Poisoned"
    },
    {
      "x": 25,
      "y": 16,
      "z": 8,
      "name": "Rock_Volcanic_Cracked_Poisoned"
    },
    {
      "x": 25,
      "y": 17,
      "z": 8,
      "name": "Rock_Volcanic_Cracked_Poisoned"
    },
    {
      "x": 25,
      "y": 18,
      "z": 8,
      "name": "Rock_Volcanic_Cracked_Poisoned"
    },
    {
      "x": 25,
      "y": 19,
      "z": 8,
      "name": "Rock_Volcanic_Cracked_Poisoned"
    },
    {
      "x": 25,
      "y": 20,
      "z": 8,
      "name": "Rock_Volcanic_Cracked_Poisoned"
    },
    {
      "x": 25,
      "y": 21,
      "z": 8,
      "name": "Rock_Volcanic_Cracked_Poisoned"
    },
    {
      "x": 25,
      "y": 22,
      "z": 8,
      "name": "Rock_Volcanic_Cracked_Poisoned"
    },
    {
      "x": 25,
      "y": 13,
      "z": 9,
      "name": "Rock_Volcanic_Cracked_Poisoned"
    },
    {
      "x": 25,
      "y": 14,
      "z": 9,
      "name": "Rock_Volcanic_Cracked_Poisoned"
    },
    {
      "x": 25,
      "y": 15,
      "z": 9,
      "name": "Rock_Volcanic_Cracked_Poisoned"
    },
    {
      "x": 25,
      "y": 16,
      "z": 9,
      "name": "Rock_Volcanic_Cracked_Poisoned"
    },
    {
      "x": 25,
      "y": 17,
      "z": 9,
      "name": "Rock_Volcanic_Cracked_Poisoned"
    },
    {
      "x": 25,
      "y": 18,
      "z": 9,
      "name": "Rock_Volcanic_Cracked_Poisoned"
    },
    {
      "x": 25,
      "y": 19,
      "z": 9,
      "name": "Rock_Volcanic_Cracked_Poisoned"
    },
    {
      "x": 25,
      "y": 20,
      "z": 9,
      "name": "Rock_Volcanic_Cracked_Poisoned"
    },
    {
      "x": 25,
      "y": 21,
      "z": 9,
      "name": "Rock_Volcanic_Cracked_Poisoned"
    },
    {
      "x": 25,
      "y": 15,
      "z": 10,
      "name": "Rock_Volcanic_Cracked_Poisoned"
    },
    {
      "x": 25,
      "y": 16,
      "z": 10,
      "name": "Rock_Volcanic_Cracked_Poisoned"
    },
    {
      "x": 25,
      "y": 17,
      "z": 10,
      "name": "Rock_Volcanic_Cracked_Poisoned"
    },
    {
      "x": 25,
      "y": 18,
      "z": 10,
      "name": "Rock_Volcanic_Cracked_Poisoned"
    },
    {
      "x": 25,
      "y": 19,
      "z": 10,
      "name": "Rock_Volcanic_Cracked_Poisoned"
    },
    {
      "x": 25,
      "y": 20,
      "z": 10,
      "name": "Rock_Volcanic_Cracked_Poisoned"
    },
    {
      "x": 25,
      "y": 18,
      "z": 11,
      "name": "Rock_Volcanic_Cracked_Poisoned"
    },
    {
      "x": 25,
      "y": 19,
      "z": 11,
      "name": "Rock_Volcanic_Cracked_Poisoned"
    },
    {
      "x": 25,
      "y": 18,
      "z": 12,
      "name": "Rock_Volcanic_Cracked_Poisoned"
    },
    {
      "x": 25,
      "y": 19,
      "z": 12,
      "name": "Rock_Volcanic_Cracked_Poisoned"
    },
    {
      "x": 25,
      "y": 19,
      "z": 13,
      "name": "Rock_Volcanic_Cracked_Poisoned"
    },
    {
      "x": 25,
      "y": 20,
      "z": 13,
      "name": "Rock_Volcanic_Cracked_Poisoned"
    },
    {
      "x": 25,
      "y": 19,
      "z": 14,
      "name": "Rock_Volcanic_Cracked_Poisoned"
    },
    {
      "x": 25,
      "y": 20,
      "z": 14,
      "name": "Rock_Volcanic_Cracked_Poisoned"
    },
    {
      "x": 25,
      "y": 21,
      "z": 14,
      "name": "Rock_Volcanic_Cracked_Poisoned"
    },
    {
      "x": 26,
      "y": 22,
      "z": 6,
      "name": "Rock_Volcanic_Cracked_Poisoned"
    },
    {
      "x": 26,
      "y": 23,
      "z": 6,
      "name": "Rock_Volcanic_Cracked_Poisoned"
    },
    {
      "x": 26,
      "y": 17,
      "z": 7,
      "name": "Rock_Volcanic_Cracked_Poisoned"
    },
    {
      "x": 26,
      "y": 18,
      "z": 7,
      "name": "Rock_Volcanic_Cracked_Poisoned"
    },
    {
      "x": 26,
      "y": 19,
      "z": 7,
      "name": "Rock_Volcanic_Cracked_Poisoned"
    },
    {
      "x": 26,
      "y": 20,
      "z": 7,
      "name": "Rock_Volcanic_Cracked_Poisoned"
    },
    {
      "x": 26,
      "y": 21,
      "z": 7,
      "name": "Rock_Volcanic_Cracked_Poisoned"
    },
    {
      "x": 26,
      "y": 22,
      "z": 7,
      "name": "Rock_Volcanic_Cracked_Poisoned"
    },
    {
      "x": 26,
      "y": 23,
      "z": 7,
      "name": "Rock_Volcanic_Cracked_Poisoned"
    },
    {
      "x": 26,
      "y": 16,
      "z": 8,
      "name": "Rock_Volcanic_Cracked_Poisoned"
    },
    {
      "x": 26,
      "y": 17,
      "z": 8,
      "name": "Rock_Volcanic_Cracked_Poisoned"
    },
    {
      "x": 26,
      "y": 18,
      "z": 8,
      "name": "Rock_Volcanic_Cracked_Poisoned"
    },
    {
      "x": 26,
      "y": 19,
      "z": 8,
      "name": "Rock_Volcanic_Cracked_Poisoned"
    },
    {
      "x": 26,
      "y": 20,
      "z": 8,
      "name": "Rock_Volcanic_Cracked_Poisoned"
    },
    {
      "x": 26,
      "y": 21,
      "z": 8,
      "name": "Rock_Volcanic_Cracked_Poisoned"
    },
    {
      "x": 26,
      "y": 22,
      "z": 8,
      "name": "Rock_Volcanic_Cracked_Poisoned"
    },
    {
      "x": 26,
      "y": 16,
      "z": 9,
      "name": "Rock_Volcanic_Cracked_Poisoned"
    },
    {
      "x": 26,
      "y": 17,
      "z": 9,
      "name": "Rock_Volcanic_Cracked_Poisoned"
    },
    {
      "x": 26,
      "y": 18,
      "z": 9,
      "name": "Rock_Volcanic_Cracked_Poisoned"
    },
    {
      "x": 26,
      "y": 19,
      "z": 9,
      "name": "Rock_Volcanic_Cracked_Poisoned"
    },
    {
      "x": 26,
      "y": 20,
      "z": 9,
      "name": "Rock_Volcanic_Cracked_Poisoned"
    },
    {
      "x": 26,
      "y": 21,
      "z": 9,
      "name": "Rock_Volcanic_Cracked_Poisoned"
    },
    {
      "x": 26,
      "y": 22,
      "z": 9,
      "name": "Rock_Volcanic_Cracked_Poisoned"
    },
    {
      "x": 26,
      "y": 17,
      "z": 10,
      "name": "Rock_Volcanic_Cracked_Poisoned"
    },
    {
      "x": 26,
      "y": 18,
      "z": 10,
      "name": "Rock_Volcanic_Cracked_Poisoned"
    },
    {
      "x": 26,
      "y": 19,
      "z": 10,
      "name": "Rock_Volcanic_Cracked_Poisoned"
    },
    {
      "x": 26,
      "y": 20,
      "z": 10,
      "name": "Rock_Volcanic_Cracked_Poisoned"
    },
    {
      "x": 26,
      "y": 19,
      "z": 11,
      "name": "Rock_Volcanic_Cracked_Poisoned"
    },
    {
      "x": 26,
      "y": 20,
      "z": 13,
      "name": "Rock_Volcanic_Cracked_Poisoned"
    },
    {
      "x": 26,
      "y": 21,
      "z": 13,
      "name": "Rock_Volcanic_Cracked_Poisoned"
    },
    {
      "x": 26,
      "y": 22,
      "z": 13,
      "name": "Rock_Volcanic_Cracked_Poisoned"
    },
    {
      "x": 26,
      "y": 20,
      "z": 14,
      "name": "Rock_Volcanic_Cracked_Poisoned"
    },
    {
      "x": 26,
      "y": 21,
      "z": 14,
      "name": "Rock_Volcanic_Cracked_Poisoned"
    },
    {
      "x": 26,
      "y": 22,
      "z": 14,
      "name": "Rock_Volcanic_Cracked_Poisoned"
    },
    {
      "x": 26,
      "y": 23,
      "z": 14,
      "name": "Rock_Volcanic_Cracked_Poisoned"
    },
    {
      "x": 26,
      "y": 21,
      "z": 15,
      "name": "Rock_Volcanic_Cracked_Poisoned"
    },
    {
      "x": 26,
      "y": 22,
      "z": 15,
      "name": "Rock_Volcanic_Cracked_Poisoned"
    },
    {
      "x": 26,
      "y": 23,
      "z": 15,
      "name": "Rock_Volcanic_Cracked_Poisoned"
    },
    {
      "x": 26,
      "y": 24,
      "z": 15,
      "name": "Rock_Volcanic_Cracked_Poisoned"
    },
    {
      "x": 26,
      "y": 25,
      "z": 15,
      "name": "Rock_Volcanic_Cracked_Poisoned"
    },
    {
      "x": 27,
      "y": 25,
      "z": 5,
      "name": "Rock_Volcanic_Cracked_Poisoned"
    },
    {
      "x": 27,
      "y": 26,
      "z": 5,
      "name": "Rock_Volcanic_Cracked_Poisoned"
    },
    {
      "x": 27,
      "y": 20,
      "z": 6,
      "name": "Rock_Volcanic_Cracked_Poisoned"
    },
    {
      "x": 27,
      "y": 21,
      "z": 6,
      "name": "Rock_Volcanic_Cracked_Poisoned"
    },
    {
      "x": 27,
      "y": 22,
      "z": 6,
      "name": "Rock_Volcanic_Cracked_Poisoned"
    },
    {
      "x": 27,
      "y": 23,
      "z": 6,
      "name": "Rock_Volcanic_Cracked_Poisoned"
    },
    {
      "x": 27,
      "y": 24,
      "z": 6,
      "name": "Rock_Volcanic_Cracked_Poisoned"
    },
    {
      "x": 27,
      "y": 25,
      "z": 6,
      "name": "Rock_Volcanic_Cracked_Poisoned"
    },
    {
      "x": 27,
      "y": 18,
      "z": 7,
      "name": "Rock_Volcanic_Cracked_Poisoned"
    },
    {
      "x": 27,
      "y": 19,
      "z": 7,
      "name": "Rock_Volcanic_Cracked_Poisoned"
    },
    {
      "x": 27,
      "y": 20,
      "z": 7,
      "name": "Rock_Volcanic_Cracked_Poisoned"
    },
    {
      "x": 27,
      "y": 21,
      "z": 7,
      "name": "Rock_Volcanic_Cracked_Poisoned"
    },
    {
      "x": 27,
      "y": 22,
      "z": 7,
      "name": "Rock_Volcanic_Cracked_Poisoned"
    },
    {
      "x": 27,
      "y": 23,
      "z": 7,
      "name": "Rock_Volcanic_Cracked_Poisoned"
    },
    {
      "x": 27,
      "y": 24,
      "z": 7,
      "name": "Rock_Volcanic_Cracked_Poisoned"
    },
    {
      "x": 27,
      "y": 18,
      "z": 8,
      "name": "Rock_Volcanic_Cracked_Poisoned"
    },
    {
      "x": 27,
      "y": 19,
      "z": 8,
      "name": "Rock_Volcanic_Cracked_Poisoned"
    },
    {
      "x": 27,
      "y": 20,
      "z": 8,
      "name": "Rock_Volcanic_Cracked_Poisoned"
    },
    {
      "x": 27,
      "y": 21,
      "z": 8,
      "name": "Rock_Volcanic_Cracked_Poisoned"
    },
    {
      "x": 27,
      "y": 22,
      "z": 8,
      "name": "Rock_Volcanic_Cracked_Poisoned"
    },
    {
      "x": 27,
      "y": 19,
      "z": 9,
      "name": "Rock_Volcanic_Cracked_Poisoned"
    },
    {
      "x": 27,
      "y": 20,
      "z": 9,
      "name": "Rock_Volcanic_Cracked_Poisoned"
    },
    {
      "x": 27,
      "y": 21,
      "z": 9,
      "name": "Rock_Volcanic_Cracked_Poisoned"
    },
    {
      "x": 27,
      "y": 22,
      "z": 9,
      "name": "Rock_Volcanic_Cracked_Poisoned"
    },
    {
      "x": 27,
      "y": 23,
      "z": 14,
      "name": "Rock_Volcanic_Cracked_Poisoned"
    },
    {
      "x": 27,
      "y": 24,
      "z": 14,
      "name": "Rock_Volcanic_Cracked_Poisoned"
    },
    {
      "x": 27,
      "y": 22,
      "z": 15,
      "name": "Rock_Volcanic_Cracked_Poisoned"
    },
    {
      "x": 27,
      "y": 23,
      "z": 15,
      "name": "Rock_Volcanic_Cracked_Poisoned"
    },
    {
      "x": 27,
      "y": 24,
      "z": 15,
      "name": "Rock_Volcanic_Cracked_Poisoned"
    },
    {
      "x": 27,
      "y": 25,
      "z": 15,
      "name": "Rock_Volcanic_Cracked_Poisoned"
    },
    {
      "x": 27,
      "y": 26,
      "z": 15,
      "name": "Rock_Volcanic_Cracked_Poisoned"
    },
    {
      "x": 27,
      "y": 24,
      "z": 16,
      "name": "Rock_Volcanic_Cracked_Poisoned"
    },
    {
      "x": 27,
      "y": 25,
      "z": 16,
      "name": "Rock_Volcanic_Cracked_Poisoned"
    },
    {
      "x": 27,
      "y": 26,
      "z": 16,
      "name": "Rock_Volcanic_Cracked_Poisoned"
    },
    {
      "x": 27,
      "y": 27,
      "z": 16,
      "name": "Rock_Volcanic_Cracked_Poisoned"
    },
    {
      "x": 28,
      "y": 24,
      "z": 5,
      "name": "Rock_Volcanic_Cracked_Poisoned"
    },
    {
      "x": 28,
      "y": 25,
      "z": 5,
      "name": "Rock_Volcanic_Cracked_Poisoned"
    },
    {
      "x": 28,
      "y": 26,
      "z": 5,
      "name": "Rock_Volcanic_Cracked_Poisoned"
    },
    {
      "x": 28,
      "y": 27,
      "z": 5,
      "name": "Rock_Volcanic_Cracked_Poisoned"
    },
    {
      "x": 28,
      "y": 21,
      "z": 6,
      "name": "Rock_Volcanic_Cracked_Poisoned"
    },
    {
      "x": 28,
      "y": 22,
      "z": 6,
      "name": "Rock_Volcanic_Cracked_Poisoned"
    },
    {
      "x": 28,
      "y": 23,
      "z": 6,
      "name": "Rock_Volcanic_Cracked_Poisoned"
    },
    {
      "x": 28,
      "y": 24,
      "z": 6,
      "name": "Rock_Volcanic_Cracked_Poisoned"
    },
    {
      "x": 28,
      "y": 25,
      "z": 6,
      "name": "Rock_Volcanic_Cracked_Poisoned"
    },
    {
      "x": 28,
      "y": 26,
      "z": 6,
      "name": "Rock_Volcanic_Cracked_Poisoned"
    },
    {
      "x": 28,
      "y": 21,
      "z": 7,
      "name": "Rock_Volcanic_Cracked_Poisoned"
    },
    {
      "x": 28,
      "y": 22,
      "z": 7,
      "name": "Rock_Volcanic_Cracked_Poisoned"
    },
    {
      "x": 28,
      "y": 23,
      "z": 7,
      "name": "Rock_Volcanic_Cracked_Poisoned"
    },
    {
      "x": 28,
      "y": 24,
      "z": 7,
      "name": "Rock_Volcanic_Cracked_Poisoned"
    },
    {
      "x": 28,
      "y": 22,
      "z": 8,
      "name": "Rock_Volcanic_Cracked_Poisoned"
    },
    {
      "x": 28,
      "y": 23,
      "z": 8,
      "name": "Rock_Volcanic_Cracked_Poisoned"
    },
    {
      "x": 28,
      "y": 24,
      "z": 8,
      "name": "Rock_Volcanic_Cracked_Poisoned"
    },
    {
      "x": 28,
      "y": 25,
      "z": 15,
      "name": "Rock_Volcanic_Cracked_Poisoned"
    },
    {
      "x": 28,
      "y": 26,
      "z": 15,
      "name": "Rock_Volcanic_Cracked_Poisoned"
    },
    {
      "x": 28,
      "y": 27,
      "z": 15,
      "name": "Rock_Volcanic_Cracked_Poisoned"
    },
    {
      "x": 28,
      "y": 28,
      "z": 15,
      "name": "Rock_Volcanic_Cracked_Poisoned"
    },
    {
      "x": 28,
      "y": 26,
      "z": 16,
      "name": "Rock_Volcanic_Cracked_Poisoned"
    },
    {
      "x": 28,
      "y": 27,
      "z": 16,
      "name": "Rock_Volcanic_Cracked_Poisoned"
    },
    {
      "x": 28,
      "y": 28,
      "z": 16,
      "name": "Rock_Volcanic_Cracked_Poisoned"
    },
    {
      "x": 28,
      "y": 29,
      "z": 16,
      "name": "Rock_Volcanic_Cracked_Poisoned"
    },
    {
      "x": 28,
      "y": 27,
      "z": 17,
      "name": "Rock_Volcanic_Cracked_Poisoned"
    },
    {
      "x": 28,
      "y": 28,
      "z": 17,
      "name": "Rock_Volcanic_Cracked_Poisoned"
    },
    {
      "x": 28,
      "y": 29,
      "z": 17,
      "name": "Rock_Volcanic_Cracked_Poisoned"
    },
    {
      "x": 28,
      "y": 30,
      "z": 17,
      "name": "Rock_Volcanic_Cracked_Poisoned"
    },
    {
      "x": 29,
      "y": 26,
      "z": 5,
      "name": "Rock_Volcanic_Cracked_Poisoned"
    },
    {
      "x": 29,
      "y": 27,
      "z": 5,
      "name": "Rock_Volcanic_Cracked_Poisoned"
    },
    {
      "x": 29,
      "y": 28,
      "z": 5,
      "name": "Rock_Volcanic_Cracked_Poisoned"
    },
    {
      "x": 29,
      "y": 22,
      "z": 6,
      "name": "Rock_Volcanic_Cracked_Poisoned"
    },
    {
      "x": 29,
      "y": 23,
      "z": 6,
      "name": "Rock_Volcanic_Cracked_Poisoned"
    },
    {
      "x": 29,
      "y": 24,
      "z": 6,
      "name": "Rock_Volcanic_Cracked_Poisoned"
    },
    {
      "x": 29,
      "y": 25,
      "z": 6,
      "name": "Rock_Volcanic_Cracked_Poisoned"
    },
    {
      "x": 29,
      "y": 26,
      "z": 6,
      "name": "Rock_Volcanic_Cracked_Poisoned"
    },
    {
      "x": 29,
      "y": 27,
      "z": 6,
      "name": "Rock_Volcanic_Cracked_Poisoned"
    },
    {
      "x": 29,
      "y": 23,
      "z": 7,
      "name": "Rock_Volcanic_Cracked_Poisoned"
    },
    {
      "x": 29,
      "y": 24,
      "z": 7,
      "name": "Rock_Volcanic_Cracked_Poisoned"
    },
    {
      "x": 29,
      "y": 25,
      "z": 7,
      "name": "Rock_Volcanic_Cracked_Poisoned"
    },
    {
      "x": 29,
      "y": 28,
      "z": 15,
      "name": "Rock_Volcanic_Cracked_Poisoned"
    },
    {
      "x": 29,
      "y": 29,
      "z": 15,
      "name": "Rock_Volcanic_Cracked_Poisoned"
    },
    {
      "x": 29,
      "y": 30,
      "z": 15,
      "name": "Rock_Volcanic_Cracked_Poisoned"
    },
    {
      "x": 29,
      "y": 27,
      "z": 16,
      "name": "Rock_Volcanic_Cracked_Poisoned"
    },
    {
      "x": 29,
      "y": 28,
      "z": 16,
      "name": "Rock_Volcanic_Cracked_Poisoned"
    },
    {
      "x": 29,
      "y": 29,
      "z": 16,
      "name": "Rock_Volcanic_Cracked_Poisoned"
    },
    {
      "x": 29,
      "y": 30,
      "z": 16,
      "name": "Rock_Volcanic_Cracked_Poisoned"
    },
    {
      "x": 29,
      "y": 31,
      "z": 16,
      "name": "Rock_Volcanic_Cracked_Poisoned"
    },
    {
      "x": 29,
      "y": 32,
      "z": 16,
      "name": "Rock_Volcanic_Cracked_Poisoned"
    },
    {
      "x": 29,
      "y": 33,
      "z": 16,
      "name": "Rock_Volcanic_Cracked_Poisoned"
    },
    {
      "x": 29,
      "y": 29,
      "z": 17,
      "name": "Rock_Volcanic_Cracked_Poisoned"
    },
    {
      "x": 29,
      "y": 30,
      "z": 17,
      "name": "Rock_Volcanic_Cracked_Poisoned"
    },
    {
      "x": 29,
      "y": 31,
      "z": 17,
      "name": "Rock_Volcanic_Cracked_Poisoned"
    },
    {
      "x": 29,
      "y": 32,
      "z": 17,
      "name": "Rock_Volcanic_Cracked_Poisoned"
    },
    {
      "x": 30,
      "y": 28,
      "z": 4,
      "name": "Rock_Volcanic_Cracked_Poisoned"
    },
    {
      "x": 30,
      "y": 29,
      "z": 4,
      "name": "Rock_Volcanic_Cracked_Poisoned"
    },
    {
      "x": 30,
      "y": 30,
      "z": 4,
      "name": "Rock_Volcanic_Cracked_Poisoned"
    },
    {
      "x": 30,
      "y": 31,
      "z": 4,
      "name": "Rock_Volcanic_Cracked_Poisoned"
    },
    {
      "x": 30,
      "y": 27,
      "z": 5,
      "name": "Rock_Volcanic_Cracked_Poisoned"
    },
    {
      "x": 30,
      "y": 28,
      "z": 5,
      "name": "Rock_Volcanic_Cracked_Poisoned"
    },
    {
      "x": 30,
      "y": 29,
      "z": 5,
      "name": "Rock_Volcanic_Cracked_Poisoned"
    },
    {
      "x": 30,
      "y": 30,
      "z": 5,
      "name": "Rock_Volcanic_Cracked_Poisoned"
    },
    {
      "x": 30,
      "y": 29,
      "z": 16,
      "name": "Rock_Volcanic_Cracked_Poisoned"
    },
    {
      "x": 30,
      "y": 30,
      "z": 16,
      "name": "Rock_Volcanic_Cracked_Poisoned"
    },
    {
      "x": 30,
      "y": 31,
      "z": 16,
      "name": "Rock_Volcanic_Cracked_Poisoned"
    },
    {
      "x": 30,
      "y": 31,
      "z": 17,
      "name": "Rock_Volcanic_Cracked_Poisoned"
    },
    {
      "x": 30,
      "y": 32,
      "z": 17,
      "name": "Rock_Volcanic_Cracked_Poisoned"
    },
    {
      "x": 30,
      "y": 33,
      "z": 17,
      "name": "Rock_Volcanic_Cracked_Poisoned"
    },
    {
      "x": 30,
      "y": 34,
      "z": 17,
      "name": "Rock_Volcanic_Cracked_Poisoned"
    },
    {
      "x": 30,
      "y": 35,
      "z": 17,
      "name": "Rock_Volcanic_Cracked_Poisoned"
    },
    {
      "x": 30,
      "y": 34,
      "z": 18,
      "name": "Rock_Volcanic_Cracked_Poisoned"
    },
    {
      "x": 31,
      "y": 30,
      "z": 4,
      "name": "Rock_Volcanic_Cracked_Poisoned"
    },
    {
      "x": 31,
      "y": 31,
      "z": 4,
      "name": "Rock_Volcanic_Cracked_Poisoned"
    },
    {
      "x": 31,
      "y": 32,
      "z": 4,
      "name": "Rock_Volcanic_Cracked_Poisoned"
    },
    {
      "x": 31,
      "y": 33,
      "z": 4,
      "name": "Rock_Volcanic_Cracked_Poisoned"
    },
    {
      "x": 31,
      "y": 34,
      "z": 18,
      "name": "Rock_Volcanic_Cracked_Poisoned"
    },
    {
      "x": 31,
      "y": 35,
      "z": 18,
      "name": "Rock_Volcanic_Cracked_Poisoned"
    },
    {
      "x": 31,
      "y": 36,
      "z": 18,
      "name": "Rock_Volcanic_Cracked_Poisoned"
    },
    {
      "x": 31,
      "y": 37,
      "z": 18,
      "name": "Rock_Volcanic_Cracked_Poisoned"
    }
  ]
}