{
  "version": 8,
  "blockIdVersion": 8,
  "anchorX": -6,
  "anchorY": 23,
  "anchorZ": -3,
  "blocks": [
    {
      "x": -21,
      "y": 30,
      "z": 2,
      "name": "Deco_Bone_Full"
    },
    {
      "x": -21,
      "y": 31,
      "z": 2,
      "name": "Deco_Bone_Full"
    },
    {
      "x": -21,
      "y": 32,
      "z": 2,
      "name": "Deco_Bone_Full"
    },
    {
      "x": -21,
      "y": 33,
      "z": 2,
      "name": "Deco_Bone_Full"
    },
    {
      "x": -21,
      "y": 34,
      "z": 2,
      "name": "Deco_Bone_Full"
    },
    {
      "x": -21,
      "y": 35,
      "z": 2,
      "name": "Deco_Bone_Full"
    },
    {
      "x": -21,
      "y": 36,
      "z": 2,
      "name": "Deco_Bone_Full"
    },
    {
      "x": -21,
      "y": 30,
      "z": 3,
      "name": "Deco_Bone_Full"
    },
    {
      "x": -20,
      "y": 30,
      "z": 2,
      "name": "Deco_Bone_Full"
    },
    {
      "x": -20,
      "y": 29,
      "z": 3,
      "name": "Deco_Bone_Full"
    },
    {
      "x": -20,
      "y": 30,
      "z": 3,
      "name": "Deco_Bone_Full"
    },
    {
      "x": -20,
      "y": 36,
      "z": 3,
      "name": "Deco_Bone_Full"
    },
    {
      "x": -20,
      "y": 37,
      "z": 3,
      "name": "Deco_Bone_Full"
    },
    {
      "x": -20,
      "y": 38,
      "z": 3,
      "name": "Deco_Bone_Full"
    },
    {
      "x": -20,
      "y": 29,
      "z": 4,
      "name": "Deco_Bone_Full"
    },
    {
      "x": -19,
      "y": 29,
      "z": 3,
      "name": "Deco_Bone_Full"
    },
    {
      "x": -19,
      "y": 28,
      "z": 4,
      "name": "Deco_Bone_Full"
    },
    {
      "x": -19,
      "y": 29,
      "z": 4,
      "name": "Deco_Bone_Full"
    },
    {
      "x": -19,
      "y": 38,
      "z": 4,
      "name": "Deco_Bone_Full"
    },
    {
      "x": -19,
      "y": 39,
      "z": 4,
      "name": "Deco_Bone_Full"
    },
    {
      "x": -19,
      "y": 28,
      "z": 5,
      "name": "Deco_Bone_Full"
    },
    {
      "x": -18,
      "y": 31,
      "z": -3,
      "name": "Deco_Bone_Full"
    },
    {
      "x": -18,
      "y": 32,
      "z": -3,
      "name": "Deco_Bone_Full"
    },
    {
      "x": -18,
      "y": 33,
      "z": -3,
      "name": "Deco_Bone_Full"
    },
    {
      "x": -18,
      "y": 34,
      "z": -3,
      "name": "Deco_Bone_Full"
    },
    {
      "x": -18,
      "y": 35,
      "z": -3,
      "name": "Deco_Bone_Full"
    },
    {
      "x": -18,
      "y": 36,
      "z": -3,
      "name": "Deco_Bone_Full"
    },
    {
      "x": -18,
      "y": 37,
      "z": -3,
      "name": "Deco_Bone_Full"
    },
    {
      "x": -18,
      "y": 38,
      "z": -3,
      "name": "Deco_Bone_Full"
    },
    {
      "x": -18,
      "y": 39,
      "z": -3,
      "name": "Deco_Bone_Full"
    },
    {
      "x": -18,
      "y": 40,
      "z": -3,
      "name": "Deco_Bone_Full"
    },
    {
      "x": -18,
      "y": 41,
      "z": -3,
      "name": "Deco_Bone_Full"
    },
    {
      "x": -18,
      "y": 28,
      "z": 4,
      "name": "Deco_Bone_Full"
    },
    {
      "x": -18,
      "y": 27,
      "z": 5,
      "name": "Deco_Bone_Full"
    },
    {
      "x": -18,
      "y": 28,
      "z": 5,
      "name": "Deco_Bone_Full"
    },
    {
      "x": -18,
      "y": 27,
      "z": 6,
      "name": "Deco_Bone_Full"
    },
    {
      "x": -18,
      "y": 28,
      "z": 6,
      "name": "Deco_Bone_Full"
    },
    {
      "x": -18,
      "y": 27,
      "z": 8,
      "name": "Deco_Bone_Full"
    },
    {
      "x": -17,
      "y": 37,
      "z": -3,
      "name": "Plant_Crop_Health3",
      "rotation": 1
    },
    {
      "x": -17,
      "y": 38,
      "z": -3,
      "name": "Plant_Crop_Health3",
      "filler": 1024,
      "rotation": 1
    },
    {
      "x": -17,
      "y": 29,
      "z": -2,
      "name": "Deco_Bone_Full"
    },
    {
      "x": -17,
      "y": 30,
      "z": -2,
      "name": "Deco_Bone_Full"
    },
    {
      "x": -17,
      "y": 31,
      "z": -2,
      "name": "Deco_Bone_Full"
    },
    {
      "x": -17,
      "y": 41,
      "z": -2,
      "name": "Deco_Bone_Full"
    },
    {
      "x": -17,
      "y": 42,
      "z": -2,
      "name": "Deco_Bone_Full"
    },
    {
      "x": -17,
      "y": 43,
      "z": -2,
      "name": "Deco_Bone_Full"
    },
    {
      "x": -17,
      "y": 29,
      "z": -1,
      "name": "Deco_Bone_Full"
    },
    {
      "x": -17,
      "y": 27,
      "z": 5,
      "name": "Deco_Bone_Full"
    },
    {
      "x": -17,
      "y": 28,
      "z": 5,
      "name": "Deco_Bone_Full"
    },
    {
      "x": -17,
      "y": 26,
      "z": 6,
      "name": "Deco_Bone_Full"
    },
    {
      "x": -17,
      "y": 27,
      "z": 6,
      "name": "Deco_Bone_Full"
    },
    {
      "x": -17,
      "y": 28,
      "z": 6,
      "name": "Deco_Bone_Full"
    },
    {
      "x": -17,
      "y": 25,
      "z": 7,
      "name": "Deco_Bone_Full"
    },
    {
      "x": -17,
      "y": 26,
      "z": 7,
      "name": "Deco_Bone_Full"
    },
    {
      "x": -17,
      "y": 27,
      "z": 7,
      "name": "Deco_Bone_Full"
    },
    {
      "x": -17,
      "y": 28,
      "z": 7,
      "name": "Deco_Bone_Full"
    },
    {
      "x": -17,
      "y": 27,
      "z": 8,
      "name": "Deco_Bone_Full"
    },
    {
      "x": -17,
      "y": 28,
      "z": 8,
      "name": "Deco_Bone_Full"
    },
    {
      "x": -16,
      "y": 37,
      "z": -3,
      "name": "Empty"
    },
    {
      "x": -16,
      "y": 38,
      "z": -3,
      "name": "Empty"
    },
    {
      "x": -16,
      "y": 29,
      "z": -2,
      "name": "Deco_Bone_Full"
    },
    {
      "x": -16,
      "y": 27,
      "z": -1,
      "name": "Deco_Bone_Full"
    },
    {
      "x": -16,
      "y": 28,
      "z": -1,
      "name": "Deco_Bone_Full"
    },
    {
      "x": -16,
      "y": 29,
      "z": -1,
      "name": "Deco_Bone_Full"
    },
    {
      "x": -16,
      "y": 43,
      "z": -1,
      "name": "Deco_Bone_Full"
    },
    {
      "x": -16,
      "y": 44,
      "z": -1,
      "name": "Deco_Bone_Full"
    },
    {
      "x": -16,
      "y": 28,
      "z": 0,
      "name": "Deco_Bone_Full"
    },
    {
      "x": -16,
      "y": 27,
      "z": 5,
      "name": "Deco_Bone_Full"
    },
    {
      "x": -16,
      "y": 25,
      "z": 6,
      "name": "Deco_Bone_Full"
    },
    {
      "x": -16,
      "y": 26,
      "z": 6,
      "name": "Deco_Bone_Full"
    },
    {
      "x": -16,
      "y": 27,
      "z": 6,
      "name": "Deco_Bone_Full"
    },
    {
      "x": -16,
      "y": 28,
      "z": 6,
      "name": "Deco_Bone_Full"
    },
    {
      "x": -16,
      "y": 23,
      "z": 7,
      "name": "Deco_Bone_Full"
    },
    {
      "x": -16,
      "y": 24,
      "z": 7,
      "name": "Deco_Bone_Full"
    },
    {
      "x": -16,
      "y": 25,
      "z": 7,
      "name": "Deco_Bone_Full"
    },
    {
      "x": -16,
      "y": 26,
      "z": 7,
      "name": "Deco_Bone_Full"
    },
    {
      "x": -16,
      "y": 27,
      "z": 7,
      "name": "Deco_Bone_Full"
    },
    {
      "x": -16,
      "y": 28,
      "z": 7,
      "name": "Deco_Bone_Full"
    },
    {
      "x": -16,
      "y": 29,
      "z": 7,
      "name": "Deco_Bone_Full"
    },
    {
      "x": -16,
      "y": 25,
      "z": 8,
      "name": "Deco_Bone_Full"
    },
    {
      "x": -16,
      "y": 26,
      "z": 8,
      "name": "Deco_Bone_Full"
    },
    {
      "x": -16,
      "y": 27,
      "z": 8,
      "name": "Deco_Bone_Full"
    },
    {
      "x": -16,
      "y": 28,
      "z": 8,
      "name": "Deco_Bone_Full"
    },
    {
      "x": -15,
      "y": 28,
      "z": -1,
      "name": "Deco_Bone_Full"
    },
    {
      "x": -15,
      "y": 27,
      "z": 0,
      "name": "Deco_Bone_Full"
    },
    {
      "x": -15,
      "y": 28,
      "z": 0,
      "name": "Deco_Bone_Full"
    },
    {
      "x": -15,
      "y": 44,
      "z": 0,
      "name": "Deco_Bone_Full"
    },
    {
      "x": -15,
      "y": 27,
      "z": 1,
      "name": "Deco_Bone_Full"
    },
    {
      "x": -15,
      "y": 26,
      "z": 5,
      "name": "Deco_Bone_Full"
    },
    {
      "x": -15,
      "y": 22,
      "z": 6,
      "name": "Deco_Bone_Full"
    },
    {
      "x": -15,
      "y": 23,
      "z": 6,
      "name": "Deco_Bone_Full"
    },
    {
      "x": -15,
      "y": 24,
      "z": 6,
      "name": "Deco_Bone_Full"
    },
    {
      "x": -15,
      "y": 25,
      "z": 6,
      "name": "Deco_Bone_Full"
    },
    {
      "x": -15,
      "y": 26,
      "z": 6,
      "name": "Deco_Bone_Full"
    },
    {
      "x": -15,
      "y": 27,
      "z": 6,
      "name": "Deco_Bone_Full"
    },
    {
      "x": -15,
      "y": 25,
      "z": 7,
      "name": "Deco_Bone_Full"
    },
    {
      "x": -15,
      "y": 26,
      "z": 7,
      "name": "Deco_Bone_Full"
    },
    {
      "x": -15,
      "y": 27,
      "z": 7,
      "name": "Deco_Bone_Full"
    },
    {
      "x": -15,
      "y": 28,
      "z": 7,
      "name": "Deco_Bone_Full"
    },
    {
      "x": -15,
      "y": 26,
      "z": 8,
      "name": "Deco_Bone_Full"
    },
    {
      "x": -15,
      "y": 27,
      "z": 8,
      "name": "Deco_Bone_Full"
    },
    {
      "x": -15,
      "y": 28,
      "z": 8,
      "name": "Deco_Bone_Full"
    },
    {
      "x": -15,
      "y": 27,
      "z": 9,
      "name": "Deco_Bone_Full"
    },
    {
      "x": -15,
      "y": 28,
      "z": 9,
      "name": "Deco_Bone_Full"
    },
    {
      "x": -14,
      "y": 30,
      "z": -7,
      "name": "Deco_Bone_Full"
    },
    {
      "x": -14,
      "y": 31,
      "z": -7,
      "name": "Deco_Bone_Full"
    },
    {
      "x": -14,
      "y": 32,
      "z": -7,
      "name": "Deco_Bone_Full"
    },
    {
      "x": -14,
      "y": 33,
      "z": -7,
      "name": "Deco_Bone_Full"
    },
    {
      "x": -14,
      "y": 34,
      "z": -7,
      "name": "Deco_Bone_Full"
    },
    {
      "x": -14,
      "y": 35,
      "z": -7,
      "name": "Deco_Bone_Full"
    },
    {
      "x": -14,
      "y": 36,
      "z": -7,
      "name": "Deco_Bone_Full"
    },
    {
      "x": -14,
      "y": 37,
      "z": -7,
      "name": "Deco_Bone_Full"
    },
    {
      "x": -14,
      "y": 38,
      "z": -7,
      "name": "Deco_Bone_Full"
    },
    {
      "x": -14,
      "y": 39,
      "z": -7,
      "name": "Deco_Bone_Full"
    },
    {
      "x": -14,
      "y": 27,
      "z": 0,
      "name": "Deco_Bone_Full"
    },
    {
      "x": -14,
      "y": 26,
      "z": 1,
      "name": "Deco_Bone_Full"
    },
    {
      "x": -14,
      "y": 27,
      "z": 1,
      "name": "Deco_Bone_Full"
    },
    {
      "x": -14,
      "y": 26,
      "z": 2,
      "name": "Deco_Bone_Full"
    },
    {
      "x": -14,
      "y": 27,
      "z": 2,
      "name": "Deco_Bone_Full"
    },
    {
      "x": -14,
      "y": 26,
      "z": 4,
      "name": "Deco_Bone_Full"
    },
    {
      "x": -14,
      "y": 25,
      "z": 5,
      "name": "Deco_Bone_Full"
    },
    {
      "x": -14,
      "y": 26,
      "z": 5,
      "name": "Deco_Bone_Full"
    },
    {
      "x": -14,
      "y": 26,
      "z": 6,
      "name": "Deco_Bone_Full"
    },
    {
      "x": -14,
      "y": 27,
      "z": 7,
      "name": "Deco_Bone_Full"
    },
    {
      "x": -14,
      "y": 27,
      "z": 8,
      "name": "Deco_Bone_Full"
    },
    {
      "x": -14,
      "y": 28,
      "z": 8,
      "name": "Deco_Bone_Full"
    },
    {
      "x": -14,
      "y": 27,
      "z": 9,
      "name": "Deco_Bone_Full"
    },
    {
      "x": -14,
      "y": 28,
      "z": 9,
      "name": "Deco_Bone_Full"
    },
    {
      "x": -14,
      "y": 28,
      "z": 10,
      "name": "Deco_Bone_Full"
    },
    {
      "x": -13,
      "y": 28,
      "z": -6,
      "name": "Deco_Bone_Full"
    },
    {
      "x": -13,
      "y": 29,
      "z": -6,
      "name": "Deco_Bone_Full"
    },
    {
      "x": -13,
      "y": 30,
      "z": -6,
      "name": "Deco_Bone_Full"
    },
    {
      "x": -13,
      "y": 39,
      "z": -6,
      "name": "Deco_Bone_Full"
    },
    {
      "x": -13,
      "y": 40,
      "z": -6,
      "name": "Deco_Bone_Full"
    },
    {
      "x": -13,
      "y": 41,
      "z": -6,
      "name": "Deco_Bone_Full"
    },
    {
      "x": -13,
      "y": 28,
      "z": -5,
      "name": "Deco_Bone_Full"
    },
    {
      "x": -13,
      "y": 26,
      "z": 1,
      "name": "Deco_Bone_Full"
    },
    {
      "x": -13,
      "y": 27,
      "z": 1,
      "name": "Deco_Bone_Full"
    },
    {
      "x": -13,
      "y": 25,
      "z": 2,
      "name": "Deco_Bone_Full"
    },
    {
      "x": -13,
      "y": 26,
      "z": 2,
      "name": "Deco_Bone_Full"
    },
    {
      "x": -13,
      "y": 27,
      "z": 2,
      "name": "Deco_Bone_Full"
    },
    {
      "x": -13,
      "y": 24,
      "z": 3,
      "name": "Deco_Bone_Full"
    },
    {
      "x": -13,
      "y": 25,
      "z": 3,
      "name": "Deco_Bone_Full"
    },
    {
      "x": -13,
      "y": 26,
      "z": 3,
      "name": "Deco_Bone_Full"
    },
    {
      "x": -13,
      "y": 27,
      "z": 3,
      "name": "Deco_Bone_Full"
    },
    {
      "x": -13,
      "y": 24,
      "z": 4,
      "name": "Deco_Bone_Full"
    },
    {
      "x": -13,
      "y": 25,
      "z": 4,
      "name": "Deco_Bone_Full"
    },
    {
      "x": -13,
      "y": 26,
      "z": 4,
      "name": "Deco_Bone_Full"
    },
    {
      "x": -13,
      "y": 27,
      "z": 4,
      "name": "Deco_Bone_Full"
    },
    {
      "x": -13,
      "y": 26,
      "z": 5,
      "name": "Deco_Bone_Full"
    },
    {
      "x": -13,
      "y": 28,
      "z": 9,
      "name": "Deco_Bone_Full"
    },
    {
      "x": -13,
      "y": 28,
      "z": 10,
      "name": "Deco_Bone_Full"
    },
    {
      "x": -13,
      "y": 29,
      "z": 10,
      "name": "Deco_Bone_Full"
    },
    {
      "x": -13,
      "y": 38,
      "z": 10,
      "name": "Deco_Bone_Full"
    },
    {
      "x": -13,
      "y": 39,
      "z": 10,
      "name": "Deco_Bone_Full"
    },
    {
      "x": -13,
      "y": 29,
      "z": 11,
      "name": "Deco_Bone_Full"
    },
    {
      "x": -12,
      "y": 28,
      "z": -6,
      "name": "Deco_Bone_Full"
    },
    {
      "x": -12,
      "y": 27,
      "z": -5,
      "name": "Deco_Bone_Full"
    },
    {
      "x": -12,
      "y": 28,
      "z": -5,
      "name": "Deco_Bone_Full"
    },
    {
      "x": -12,
      "y": 41,
      "z": -5,
      "name": "Deco_Bone_Full"
    },
    {
      "x": -12,
      "y": 42,
      "z": -5,
      "name": "Deco_Bone_Full"
    },
    {
      "x": -12,
      "y": 27,
      "z": -4,
      "name": "Deco_Bone_Full"
    },
    {
      "x": -12,
      "y": 26,
      "z": 1,
      "name": "Deco_Bone_Full"
    },
    {
      "x": -12,
      "y": 25,
      "z": 2,
      "name": "Deco_Bone_Full"
    },
    {
      "x": -12,
      "y": 26,
      "z": 2,
      "name": "Deco_Bone_Full"
    },
    {
      "x": -12,
      "y": 27,
      "z": 2,
      "name": "Deco_Bone_Full"
    },
    {
      "x": -12,
      "y": 22,
      "z": 3,
      "name": "Deco_Bone_Full"
    },
    {
      "x": -12,
      "y": 23,
      "z": 3,
      "name": "Deco_Bone_Full"
    },
    {
      "x": -12,
      "y": 24,
      "z": 3,
      "name": "Deco_Bone_Full"
    },
    {
      "x": -12,
      "y": 25,
      "z": 3,
      "name": "Deco_Bone_Full"
    },
    {
      "x": -12,
      "y": 26,
      "z": 3,
      "name": "Deco_Bone_Full"
    },
    {
      "x": -12,
      "y": 27,
      "z": 3,
      "name": "Deco_Bone_Full"
    },
    {
      "x": -12,
      "y": 28,
      "z": 3,
      "name": "Deco_Bone_Full"
    },
    {
      "x": -12,
      "y": 24,
      "z": 4,
      "name": "Deco_Bone_Full"
    },
    {
      "x": -12,
      "y": 25,
      "z": 4,
      "name": "Deco_Bone_Full"
    },
    {
      "x": -12,
      "y": 26,
      "z": 4,
      "name": "Deco_Bone_Full"
    },
    {
      "x": -12,
      "y": 27,
      "z": 4,
      "name": "Deco_Bone_Full"
    },
    {
      "x": -12,
      "y": 29,
      "z": 10,
      "name": "Deco_Bone_Full"
    },
    {
      "x": -12,
      "y": 29,
      "z": 11,
      "name": "Deco_Bone_Full"
    },
    {
      "x": -12,
      "y": 30,
      "z": 11,
      "name": "Deco_Bone_Full"
    },
    {
      "x": -12,
      "y": 36,
      "z": 11,
      "name": "Deco_Bone_Full"
    },
    {
      "x": -12,
      "y": 37,
      "z": 11,
      "name": "Deco_Bone_Full"
    },
    {
      "x": -12,
      "y": 38,
      "z": 11,
      "name": "Deco_Bone_Full"
    },
    {
      "x": -12,
      "y": 30,
      "z": 12,
      "name": "Deco_Bone_Full"
    },
    {
      "x": -11,
      "y": 27,
      "z": -5,
      "name": "Deco_Bone_Full"
    },
    {
      "x": -11,
      "y": 26,
      "z": -4,
      "name": "Deco_Bone_Full"
    },
    {
      "x": -11,
      "y": 27,
      "z": -4,
      "name": "Deco_Bone_Full"
    },
    {
      "x": -11,
      "y": 42,
      "z": -4,
      "name": "Deco_Bone_Full"
    },
    {
      "x": -11,
      "y": 26,
      "z": -3,
      "name": "Deco_Bone_Full"
    },
    {
      "x": -11,
      "y": 25,
      "z": 1,
      "name": "Deco_Bone_Full"
    },
    {
      "x": -11,
      "y": 21,
      "z": 2,
      "name": "Deco_Bone_Full"
    },
    {
      "x": -11,
      "y": 22,
      "z": 2,
      "name": "Deco_Bone_Full"
    },
    {
      "x": -11,
      "y": 23,
      "z": 2,
      "name": "Deco_Bone_Full"
    },
    {
      "x": -11,
      "y": 24,
      "z": 2,
      "name": "Deco_Bone_Full"
    },
    {
      "x": -11,
      "y": 25,
      "z": 2,
      "name": "Deco_Bone_Full"
    },
    {
      "x": -11,
      "y": 26,
      "z": 2,
      "name": "Deco_Bone_Full"
    },
    {
      "x": -11,
      "y": 25,
      "z": 3,
      "name": "Deco_Bone_Full"
    },
    {
      "x": -11,
      "y": 26,
      "z": 3,
      "name": "Deco_Bone_Full"
    },
    {
      "x": -11,
      "y": 27,
      "z": 3,
      "name": "Deco_Bone_Full"
    },
    {
      "x": -11,
      "y": 25,
      "z": 4,
      "name": "Deco_Bone_Full"
    },
    {
      "x": -11,
      "y": 26,
      "z": 4,
      "name": "Deco_Bone_Full"
    },
    {
      "x": -11,
      "y": 27,
      "z": 4,
      "name": "Deco_Bone_Full"
    },
    {
      "x": -11,
      "y": 26,
      "z": 5,
      "name": "Deco_Bone_Full"
    },
    {
      "x": -11,
      "y": 27,
      "z": 5,
      "name": "Deco_Bone_Full"
    },
    {
      "x": -11,
      "y": 30,
      "z": 11,
      "name": "Deco_Bone_Full"
    },
    {
      "x": -11,
      "y": 30,
      "z": 12,
      "name": "Deco_Bone_Full"
    },
    {
      "x": -11,
      "y": 31,
      "z": 12,
      "name": "Deco_Bone_Full"
    },
    {
      "x": -11,
      "y": 32,
      "z": 12,
      "name": "Deco_Bone_Full"
    },
    {
      "x": -11,
      "y": 33,
      "z": 12,
      "name": "Deco_Bone_Full"
    },
    {
      "x": -11,
      "y": 34,
      "z": 12,
      "name": "Deco_Bone_Full"
    },
    {
      "x": -11,
      "y": 35,
      "z": 12,
      "name": "Deco_Bone_Full"
    },
    {
      "x": -11,
      "y": 36,
      "z": 12,
      "name": "Deco_Bone_Full"
    },
    {
      "x": -10,
      "y": 29,
      "z": -11,
      "name": "Deco_Bone_Full"
    },
    {
      "x": -10,
      "y": 30,
      "z": -11,
      "name": "Deco_Bone_Full"
    },
    {
      "x": -10,
      "y": 31,
      "z": -11,
      "name": "Deco_Bone_Full"
    },
    {
      "x": -10,
      "y": 32,
      "z": -11,
      "name": "Deco_Bone_Full"
    },
    {
      "x": -10,
      "y": 33,
      "z": -11,
      "name": "Deco_Bone_Full"
    },
    {
      "x": -10,
      "y": 34,
      "z": -11,
      "name": "Deco_Bone_Full"
    },
    {
      "x": -10,
      "y": 35,
      "z": -11,
      "name": "Deco_Bone_Full"
    },
    {
      "x": -10,
      "y": 36,
      "z": -11,
      "name": "Deco_Bone_Full"
    },
    {
      "x": -10,
      "y": 37,
      "z": -11,
      "name": "Deco_Bone_Full"
    },
    {
      "x": -10,
      "y": 38,
      "z": -11,
      "name": "Deco_Bone_Full"
    },
    {
      "x": -10,
      "y": 26,
      "z": -4,
      "name": "Deco_Bone_Full"
    },
    {
      "x": -10,
      "y": 25,
      "z": -3,
      "name": "Deco_Bone_Full"
    },
    {
      "x": -10,
      "y": 26,
      "z": -3,
      "name": "Deco_Bone_Full"
    },
    {
      "x": -10,
      "y": 42,
      "z": -3,
      "name": "Deco_Bone_Full"
    },
    {
      "x": -10,
      "y": 43,
      "z": -3,
      "name": "Deco_Bone_Full"
    },
    {
      "x": -10,
      "y": 25,
      "z": -2,
      "name": "Deco_Bone_Full"
    },
    {
      "x": -10,
      "y": 26,
      "z": -2,
      "name": "Deco_Bone_Full"
    },
    {
      "x": -10,
      "y": 25,
      "z": 0,
      "name": "Deco_Bone_Full"
    },
    {
      "x": -10,
      "y": 24,
      "z": 1,
      "name": "Deco_Bone_Full"
    },
    {
      "x": -10,
      "y": 25,
      "z": 1,
      "name": "Deco_Bone_Full"
    },
    {
      "x": -10,
      "y": 25,
      "z": 2,
      "name": "Deco_Bone_Full"
    },
    {
      "x": -10,
      "y": 26,
      "z": 3,
      "name": "Deco_Bone_Full"
    },
    {
      "x": -10,
      "y": 26,
      "z": 4,
      "name": "Deco_Bone_Full"
    },
    {
      "x": -10,
      "y": 27,
      "z": 4,
      "name": "Deco_Bone_Full"
    },
    {
      "x": -10,
      "y": 26,
      "z": 5,
      "name": "Deco_Bone_Full"
    },
    {
      "x": -10,
      "y": 27,
      "z": 5,
      "name": "Deco_Bone_Full"
    },
    {
      "x": -10,
      "y": 27,
      "z": 6,
      "name": "Deco_Bone_Full"
    },
    {
      "x": -9,
      "y": 27,
      "z": -10,
      "name": "Deco_Bone_Full"
    },
    {
      "x": -9,
      "y": 28,
      "z": -10,
      "name": "Deco_Bone_Full"
    },
    {
      "x": -9,
      "y": 29,
      "z": -10,
      "name": "Deco_Bone_Full"
    },
    {
      "x": -9,
      "y": 38,
      "z": -10,
      "name": "Deco_Bone_Full"
    },
    {
      "x": -9,
      "y": 39,
      "z": -10,
      "name": "Deco_Bone_Full"
    },
    {
      "x": -9,
      "y": 40,
      "z": -10,
      "name": "Deco_Bone_Full"
    },
    {
      "x": -9,
      "y": 27,
      "z": -9,
      "name": "Deco_Bone_Full"
    },
    {
      "x": -9,
      "y": 25,
      "z": -3,
      "name": "Deco_Bone_Full"
    },
    {
      "x": -9,
      "y": 26,
      "z": -3,
      "name": "Deco_Bone_Full"
    },
    {
      "x": -9,
      "y": 24,
      "z": -2,
      "name": "Deco_Bone_Full"
    },
    {
      "x": -9,
      "y": 25,
      "z": -2,
      "name": "Deco_Bone_Full"
    },
    {
      "x": -9,
      "y": 26,
      "z": -2,
      "name": "Deco_Bone_Full"
    },
    {
      "x": -9,
      "y": 23,
      "z": -1,
      "name": "Deco_Bone_Full"
    },
    {
      "x": -9,
      "y": 24,
      "z": -1,
      "name": "Deco_Bone_Full"
    },
    {
      "x": -9,
      "y": 25,
      "z": -1,
      "name": "Deco_Bone_Full"
    },
    {
      "x": -9,
      "y": 26,
      "z": -1,
      "name": "Deco_Bone_Full"
    },
    {
      "x": -9,
      "y": 22,
      "z": 0,
      "name": "Deco_Bone_Full"
    },
    {
      "x": -9,
      "y": 23,
      "z": 0,
      "name": "Deco_Bone_Full"
    },
    {
      "x": -9,
      "y": 24,
      "z": 0,
      "name": "Deco_Bone_Full"
    },
    {
      "x": -9,
      "y": 25,
      "z": 0,
      "name": "Deco_Bone_Full"
    },
    {
      "x": -9,
      "y": 26,
      "z": 0,
      "name": "Deco_Bone_Full"
    },
    {
      "x": -9,
      "y": 25,
      "z": 1,
      "name": "Deco_Bone_Full"
    },
    {
      "x": -9,
      "y": 27,
      "z": 5,
      "name": "Deco_Bone_Full"
    },
    {
      "x": -9,
      "y": 27,
      "z": 6,
      "name": "Deco_Bone_Full"
    },
    {
      "x": -9,
      "y": 28,
      "z": 6,
      "name": "Deco_Bone_Full"
    },
    {
      "x": -9,
      "y": 44,
      "z": 6,
      "name": "Deco_Bone_Full"
    },
    {
      "x": -9,
      "y": 28,
      "z": 7,
      "name": "Deco_Bone_Full"
    },
    {
      "x": -8,
      "y": 27,
      "z": -10,
      "name": "Deco_Bone_Full"
    },
    {
      "x": -8,
      "y": 26,
      "z": -9,
      "name": "Deco_Bone_Full"
    },
    {
      "x": -8,
      "y": 27,
      "z": -9,
      "name": "Deco_Bone_Full"
    },
    {
      "x": -8,
      "y": 40,
      "z": -9,
      "name": "Deco_Bone_Full"
    },
    {
      "x": -8,
      "y": 41,
      "z": -9,
      "name": "Deco_Bone_Full"
    },
    {
      "x": -8,
      "y": 26,
      "z": -8,
      "name": "Deco_Bone_Full"
    },
    {
      "x": -8,
      "y": 24,
      "z": -3,
      "name": "Deco_Bone_Full"
    },
    {
      "x": -8,
      "y": 25,
      "z": -3,
      "name": "Deco_Bone_Full"
    },
    {
      "x": -8,
      "y": 24,
      "z": -2,
      "name": "Deco_Bone_Full"
    },
    {
      "x": -8,
      "y": 25,
      "z": -2,
      "name": "Deco_Bone_Full"
    },
    {
      "x": -8,
      "y": 26,
      "z": -2,
      "name": "Deco_Bone_Full"
    },
    {
      "x": -8,
      "y": 20,
      "z": -1,
      "name": "Deco_Bone_Full"
    },
    {
      "x": -8,
      "y": 21,
      "z": -1,
      "name": "Deco_Bone_Full"
    },
    {
      "x": -8,
      "y": 22,
      "z": -1,
      "name": "Deco_Bone_Full"
    },
    {
      "x": -8,
      "y": 23,
      "z": -1,
      "name": "Deco_Bone_Full"
    },
    {
      "x": -8,
      "y": 24,
      "z": -1,
      "name": "Deco_Bone_Full"
    },
    {
      "x": -8,
      "y": 25,
      "z": -1,
      "name": "Deco_Bone_Full"
    },
    {
      "x": -8,
      "y": 26,
      "z": -1,
      "name": "Deco_Bone_Full"
    },
    {
      "x": -8,
      "y": 27,
      "z": -1,
      "name": "Deco_Bone_Full"
    },
    {
      "x": -8,
      "y": 23,
      "z": 0,
      "name": "Deco_Bone_Full"
    },
    {
      "x": -8,
      "y": 24,
      "z": 0,
      "name": "Deco_Bone_Full"
    },
    {
      "x": -8,
      "y": 25,
      "z": 0,
      "name": "Deco_Bone_Full"
    },
    {
      "x": -8,
      "y": 26,
      "z": 0,
      "name": "Deco_Bone_Full"
    },
    {
      "x": -8,
      "y": 28,
      "z": 6,
      "name": "Deco_Bone_Full"
    },
    {
      "x": -8,
      "y": 28,
      "z": 7,
      "name": "Deco_Bone_Full"
    },
    {
      "x": -8,
      "y": 29,
      "z": 7,
      "name": "Deco_Bone_Full"
    },
    {
      "x": -8,
      "y": 43,
      "z": 7,
      "name": "Deco_Bone_Full"
    },
    {
      "x": -8,
      "y": 44,
      "z": 7,
      "name": "Deco_Bone_Full"
    },
    {
      "x": -8,
      "y": 29,
      "z": 8,
      "name": "Deco_Bone_Full"
    },
    {
      "x": -7,
      "y": 26,
      "z": -9,
      "name": "Deco_Bone_Full"
    },
    {
      "x": -7,
      "y": 25,
      "z": -8,
      "name": "Deco_Bone_Full"
    },
    {
      "x": -7,
      "y": 26,
      "z": -8,
      "name": "Deco_Bone_Full"
    },
    {
      "x": -7,
      "y": 41,
      "z": -8,
      "name": "Deco_Bone_Full"
    },
    {
      "x": -7,
      "y": 26,
      "z": -7,
      "name": "Deco_Bone_Full"
    },
    {
      "x": -7,
      "y": 25,
      "z": -3,
      "name": "Deco_Bone_Full"
    },
    {
      "x": -7,
      "y": 19,
      "z": -2,
      "name": "Deco_Bone_Full"
    },
    {
      "x": -7,
      "y": 20,
      "z": -2,
      "name": "Deco_Bone_Full"
    },
    {
      "x": -7,
      "y": 21,
      "z": -2,
      "name": "Deco_Bone_Full"
    },
    {
      "x": -7,
      "y": 22,
      "z": -2,
      "name": "Deco_Bone_Full"
    },
    {
      "x": -7,
      "y": 23,
      "z": -2,
      "name": "Deco_Bone_Full"
    },
    {
      "x": -7,
      "y": 24,
      "z": -2,
      "name": "Deco_Bone_Full"
    },
    {
      "x": -7,
      "y": 25,
      "z": -2,
      "name": "Deco_Bone_Full"
    },
    {
      "x": -7,
      "y": 24,
      "z": -1,
      "name": "Deco_Bone_Full"
    },
    {
      "x": -7,
      "y": 25,
      "z": -1,
      "name": "Deco_Bone_Full"
    },
    {
      "x": -7,
      "y": 26,
      "z": -1,
      "name": "Deco_Bone_Full"
    },
    {
      "x": -7,
      "y": 24,
      "z": 0,
      "name": "Deco_Bone_Full"
    },
    {
      "x": -7,
      "y": 25,
      "z": 0,
      "name": "Deco_Bone_Full"
    },
    {
      "x": -7,
      "y": 26,
      "z": 0,
      "name": "Deco_Bone_Full"
    },
    {
      "x": -7,
      "y": 25,
      "z": 1,
      "name": "Deco_Bone_Full"
    },
    {
      "x": -7,
      "y": 26,
      "z": 1,
      "name": "Deco_Bone_Full"
    },
    {
      "x": -7,
      "y": 29,
      "z": 7,
      "name": "Deco_Bone_Full"
    },
    {
      "x": -7,
      "y": 29,
      "z": 8,
      "name": "Deco_Bone_Full"
    },
    {
      "x": -7,
      "y": 30,
      "z": 8,
      "name": "Deco_Bone_Full"
    },
    {
      "x": -7,
      "y": 31,
      "z": 8,
      "name": "Deco_Bone_Full"
    },
    {
      "x": -7,
      "y": 41,
      "z": 8,
      "name": "Deco_Bone_Full"
    },
    {
      "x": -7,
      "y": 42,
      "z": 8,
      "name": "Deco_Bone_Full"
    },
    {
      "x": -7,
      "y": 43,
      "z": 8,
      "name": "Deco_Bone_Full"
    },
    {
      "x": -6,
      "y": 26,
      "z": -8,
      "name": "Deco_Bone_Full"
    },
    {
      "x": -6,
      "y": 25,
      "z": -7,
      "name": "Deco_Bone_Full"
    },
    {
      "x": -6,
      "y": 41,
      "z": -7,
      "name": "Deco_Bone_Full"
    },
    {
      "x": -6,
      "y": 42,
      "z": -7,
      "name": "Deco_Bone_Full"
    },
    {
      "x": -6,
      "y": 24,
      "z": -6,
      "name": "Deco_Bone_Full"
    },
    {
      "x": -6,
      "y": 25,
      "z": -6,
      "name": "Deco_Bone_Full"
    },
    {
      "x": -6,
      "y": 24,
      "z": -4,
      "name": "Deco_Bone_Full"
    },
    {
      "x": -6,
      "y": 23,
      "z": -3,
      "name": "Deco_Bone_Full"
    },
    {
      "x": -6,
      "y": 24,
      "z": -3,
      "name": "Deco_Bone_Full"
    },
    {
      "x": -6,
      "y": 25,
      "z": -3,
      "name": "Deco_Bone_Full"
    },
    {
      "x": -6,
      "y": 25,
      "z": -2,
      "name": "Deco_Bone_Full"
    },
    {
      "x": -6,
      "y": 24,
      "z": -1,
      "name": "Deco_Bone_Full"
    },
    {
      "x": -6,
      "y": 25,
      "z": -1,
      "name": "Deco_Bone_Full"
    },
    {
      "x": -6,
      "y": 25,
      "z": 0,
      "name": "Deco_Bone_Full"
    },
    {
      "x": -6,
      "y": 26,
      "z": 0,
      "name": "Deco_Bone_Full"
    },
    {
      "x": -6,
      "y": 25,
      "z": 1,
      "name": "Deco_Bone_Full"
    },
    {
      "x": -6,
      "y": 26,
      "z": 1,
      "name": "Deco_Bone_Full"
    },
    {
      "x": -6,
      "y": 42,
      "z": 1,
      "name": "Deco_Bone_Full"
    },
    {
      "x": -6,
      "y": 43,
      "z": 1,
      "name": "Deco_Bone_Full"
    },
    {
      "x": -6,
      "y": 26,
      "z": 2,
      "name": "Deco_Bone_Full"
    },
    {
      "x": -6,
      "y": 31,
      "z": 9,
      "name": "Deco_Bone_Full"
    },
    {
      "x": -6,
      "y": 32,
      "z": 9,
      "name": "Deco_Bone_Full"
    },
    {
      "x": -6,
      "y": 33,
      "z": 9,
      "name": "Deco_Bone_Full"
    },
    {
      "x": -6,
      "y": 34,
      "z": 9,
      "name": "Deco_Bone_Full"
    },
    {
      "x": -6,
      "y": 35,
      "z": 9,
      "name": "Deco_Bone_Full"
    },
    {
      "x": -6,
      "y": 36,
      "z": 9,
      "name": "Deco_Bone_Full"
    },
    {
      "x": -6,
      "y": 37,
      "z": 9,
      "name": "Deco_Bone_Full"
    },
    {
      "x": -6,
      "y": 38,
      "z": 9,
      "name": "Deco_Bone_Full"
    },
    {
      "x": -6,
      "y": 39,
      "z": 9,
      "name": "Deco_Bone_Full"
    },
    {
      "x": -6,
      "y": 40,
      "z": 9,
      "name": "Deco_Bone_Full"
    },
    {
      "x": -6,
      "y": 41,
      "z": 9,
      "name": "Deco_Bone_Full"
    },
    {
      "x": -5,
      "y": 29,
      "z": -16,
      "name": "Deco_Bone_Full"
    },
    {
      "x": -5,
      "y": 30,
      "z": -16,
      "name": "Deco_Bone_Full"
    },
    {
      "x": -5,
      "y": 31,
      "z": -16,
      "name": "Deco_Bone_Full"
    },
    {
      "x": -5,
      "y": 32,
      "z": -16,
      "name": "Deco_Bone_Full"
    },
    {
      "x": -5,
      "y": 33,
      "z": -16,
      "name": "Deco_Bone_Full"
    },
    {
      "x": -5,
      "y": 34,
      "z": -16,
      "name": "Deco_Bone_Full"
    },
    {
      "x": -5,
      "y": 35,
      "z": -16,
      "name": "Deco_Bone_Full"
    },
    {
      "x": -5,
      "y": 24,
      "z": -7,
      "name": "Deco_Bone_Full"
    },
    {
      "x": -5,
      "y": 25,
      "z": -7,
      "name": "Deco_Bone_Full"
    },
    {
      "x": -5,
      "y": 24,
      "z": -6,
      "name": "Deco_Bone_Full"
    },
    {
      "x": -5,
      "y": 25,
      "z": -6,
      "name": "Deco_Bone_Full"
    },
    {
      "x": -5,
      "y": 22,
      "z": -5,
      "name": "Deco_Bone_Full"
    },
    {
      "x": -5,
      "y": 23,
      "z": -5,
      "name": "Deco_Bone_Full"
    },
    {
      "x": -5,
      "y": 24,
      "z": -5,
      "name": "Deco_Bone_Full"
    },
    {
      "x": -5,
      "y": 25,
      "z": -5,
      "name": "Deco_Bone_Full"
    },
    {
      "x": -5,
      "y": 21,
      "z": -4,
      "name": "Deco_Bone_Full"
    },
    {
      "x": -5,
      "y": 22,
      "z": -4,
      "name": "Deco_Bone_Full"
    },
    {
      "x": -5,
      "y": 23,
      "z": -4,
      "name": "Deco_Bone_Full"
    },
    {
      "x": -5,
      "y": 24,
      "z": -4,
      "name": "Deco_Bone_Full"
    },
    {
      "x": -5,
      "y": 25,
      "z": -4,
      "name": "Deco_Bone_Full"
    },
    {
      "x": -5,
      "y": 24,
      "z": -3,
      "name": "Deco_Bone_Full"
    },
    {
      "x": -5,
      "y": 26,
      "z": 1,
      "name": "Deco_Bone_Full"
    },
    {
      "x": -5,
      "y": 26,
      "z": 2,
      "name": "Deco_Bone_Full"
    },
    {
      "x": -5,
      "y": 27,
      "z": 2,
      "name": "Deco_Bone_Full"
    },
    {
      "x": -5,
      "y": 42,
      "z": 2,
      "name": "Deco_Bone_Full"
    },
    {
      "x": -5,
      "y": 27,
      "z": 3,
      "name": "Deco_Bone_Full"
    },
    {
      "x": -4,
      "y": 27,
      "z": -15,
      "name": "Deco_Bone_Full"
    },
    {
      "x": -4,
      "y": 28,
      "z": -15,
      "name": "Deco_Bone_Full"
    },
    {
      "x": -4,
      "y": 29,
      "z": -15,
      "name": "Deco_Bone_Full"
    },
    {
      "x": -4,
      "y": 35,
      "z": -15,
      "name": "Deco_Bone_Full"
    },
    {
      "x": -4,
      "y": 36,
      "z": -15,
      "name": "Deco_Bone_Full"
    },
    {
      "x": -4,
      "y": 37,
      "z": -15,
      "name": "Deco_Bone_Full"
    },
    {
      "x": -4,
      "y": 27,
      "z": -14,
      "name": "Deco_Bone_Full"
    },
    {
      "x": -4,
      "y": 24,
      "z": -7,
      "name": "Deco_Bone_Full"
    },
    {
      "x": -4,
      "y": 23,
      "z": -6,
      "name": "Deco_Bone_Full"
    },
    {
      "x": -4,
      "y": 24,
      "z": -6,
      "name": "Deco_Bone_Full"
    },
    {
      "x": -4,
      "y": 25,
      "z": -6,
      "name": "Deco_Bone_Full"
    },
    {
      "x": -4,
      "y": 19,
      "z": -5,
      "name": "Deco_Bone_Full"
    },
    {
      "x": -4,
      "y": 20,
      "z": -5,
      "name": "Deco_Bone_Full"
    },
    {
      "x": -4,
      "y": 21,
      "z": -5,
      "name": "Deco_Bone_Full"
    },
    {
      "x": -4,
      "y": 22,
      "z": -5,
      "name": "Deco_Bone_Full"
    },
    {
      "x": -4,
      "y": 23,
      "z": -5,
      "name": "Deco_Bone_Full"
    },
    {
      "x": -4,
      "y": 24,
      "z": -5,
      "name": "Deco_Bone_Full"
    },
    {
      "x": -4,
      "y": 25,
      "z": -5,
      "name": "Deco_Bone_Full"
    },
    {
      "x": -4,
      "y": 26,
      "z": -5,
      "name": "Deco_Bone_Full"
    },
    {
      "x": -4,
      "y": 22,
      "z": -4,
      "name": "Deco_Bone_Full"
    },
    {
      "x": -4,
      "y": 23,
      "z": -4,
      "name": "Deco_Bone_Full"
    },
    {
      "x": -4,
      "y": 24,
      "z": -4,
      "name": "Deco_Bone_Full"
    },
    {
      "x": -4,
      "y": 25,
      "z": -4,
      "name": "Deco_Bone_Full"
    },
    {
      "x": -4,
      "y": 27,
      "z": 2,
      "name": "Deco_Bone_Full"
    },
    {
      "x": -4,
      "y": 27,
      "z": 3,
      "name": "Deco_Bone_Full"
    },
    {
      "x": -4,
      "y": 28,
      "z": 3,
      "name": "Deco_Bone_Full"
    },
    {
      "x": -4,
      "y": 41,
      "z": 3,
      "name": "Deco_Bone_Full"
    },
    {
      "x": -4,
      "y": 42,
      "z": 3,
      "name": "Deco_Bone_Full"
    },
    {
      "x": -4,
      "y": 28,
      "z": 4,
      "name": "Deco_Bone_Full"
    },
    {
      "x": -3,
      "y": 27,
      "z": -15,
      "name": "Deco_Bone_Full"
    },
    {
      "x": -3,
      "y": 26,
      "z": -14,
      "name": "Deco_Bone_Full"
    },
    {
      "x": -3,
      "y": 27,
      "z": -14,
      "name": "Deco_Bone_Full"
    },
    {
      "x": -3,
      "y": 37,
      "z": -14,
      "name": "Deco_Bone_Full"
    },
    {
      "x": -3,
      "y": 38,
      "z": -14,
      "name": "Deco_Bone_Full"
    },
    {
      "x": -3,
      "y": 39,
      "z": -14,
      "name": "Deco_Bone_Full"
    },
    {
      "x": -3,
      "y": 27,
      "z": -13,
      "name": "Deco_Bone_Full"
    },
    {
      "x": -3,
      "y": 24,
      "z": -7,
      "name": "Deco_Bone_Full"
    },
    {
      "x": -3,
      "y": 18,
      "z": -6,
      "name": "Deco_Bone_Full"
    },
    {
      "x": -3,
      "y": 19,
      "z": -6,
      "name": "Deco_Bone_Full"
    },
    {
      "x": -3,
      "y": 20,
      "z": -6,
      "name": "Deco_Bone_Full"
    },
    {
      "x": -3,
      "y": 21,
      "z": -6,
      "name": "Deco_Bone_Full"
    },
    {
      "x": -3,
      "y": 22,
      "z": -6,
      "name": "Deco_Bone_Full"
    },
    {
      "x": -3,
      "y": 23,
      "z": -6,
      "name": "Deco_Bone_Full"
    },
    {
      "x": -3,
      "y": 24,
      "z": -6,
      "name": "Deco_Bone_Full"
    },
    {
      "x": -3,
      "y": 23,
      "z": -5,
      "name": "Deco_Bone_Full"
    },
    {
      "x": -3,
      "y": 24,
      "z": -5,
      "name": "Deco_Bone_Full"
    },
    {
      "x": -3,
      "y": 25,
      "z": -5,
      "name": "Deco_Bone_Full"
    },
    {
      "x": -3,
      "y": 24,
      "z": -4,
      "name": "Deco_Bone_Full"
    },
    {
      "x": -3,
      "y": 25,
      "z": -4,
      "name": "Deco_Bone_Full"
    },
    {
      "x": -3,
      "y": 24,
      "z": -3,
      "name": "Deco_Bone_Full"
    },
    {
      "x": -3,
      "y": 25,
      "z": -3,
      "name": "Deco_Bone_Full"
    },
    {
      "x": -3,
      "y": 28,
      "z": 3,
      "name": "Deco_Bone_Full"
    },
    {
      "x": -3,
      "y": 28,
      "z": 4,
      "name": "Deco_Bone_Full"
    },
    {
      "x": -3,
      "y": 29,
      "z": 4,
      "name": "Deco_Bone_Full"
    },
    {
      "x": -3,
      "y": 30,
      "z": 4,
      "name": "Deco_Bone_Full"
    },
    {
      "x": -3,
      "y": 39,
      "z": 4,
      "name": "Deco_Bone_Full"
    },
    {
      "x": -3,
      "y": 40,
      "z": 4,
      "name": "Deco_Bone_Full"
    },
    {
      "x": -3,
      "y": 41,
      "z": 4,
      "name": "Deco_Bone_Full"
    },
    {
      "x": -2,
      "y": 27,
      "z": -14,
      "name": "Deco_Bone_Full"
    },
    {
      "x": -2,
      "y": 25,
      "z": -13,
      "name": "Deco_Bone_Full"
    },
    {
      "x": -2,
      "y": 26,
      "z": -13,
      "name": "Deco_Bone_Full"
    },
    {
      "x": -2,
      "y": 39,
      "z": -13,
      "name": "Deco_Bone_Full"
    },
    {
      "x": -2,
      "y": 26,
      "z": -12,
      "name": "Deco_Bone_Full"
    },
    {
      "x": -2,
      "y": 24,
      "z": -8,
      "name": "Deco_Bone_Full"
    },
    {
      "x": -2,
      "y": 23,
      "z": -7,
      "name": "Deco_Bone_Full"
    },
    {
      "x": -2,
      "y": 24,
      "z": -7,
      "name": "Deco_Bone_Full"
    },
    {
      "x": -2,
      "y": 24,
      "z": -6,
      "name": "Deco_Bone_Full"
    },
    {
      "x": -2,
      "y": 24,
      "z": -5,
      "name": "Deco_Bone_Full"
    },
    {
      "x": -2,
      "y": 24,
      "z": -4,
      "name": "Deco_Bone_Full"
    },
    {
      "x": -2,
      "y": 25,
      "z": -4,
      "name": "Deco_Bone_Full"
    },
    {
      "x": -2,
      "y": 25,
      "z": -3,
      "name": "Deco_Bone_Full"
    },
    {
      "x": -2,
      "y": 41,
      "z": -3,
      "name": "Deco_Bone_Full"
    },
    {
      "x": -2,
      "y": 42,
      "z": -3,
      "name": "Deco_Bone_Full"
    },
    {
      "x": -2,
      "y": 26,
      "z": -2,
      "name": "Deco_Bone_Full"
    },
    {
      "x": -2,
      "y": 30,
      "z": 5,
      "name": "Deco_Bone_Full"
    },
    {
      "x": -2,
      "y": 31,
      "z": 5,
      "name": "Deco_Bone_Full"
    },
    {
      "x": -2,
      "y": 32,
      "z": 5,
      "name": "Deco_Bone_Full"
    },
    {
      "x": -2,
      "y": 33,
      "z": 5,
      "name": "Deco_Bone_Full"
    },
    {
      "x": -2,
      "y": 34,
      "z": 5,
      "name": "Deco_Bone_Full"
    },
    {
      "x": -2,
      "y": 35,
      "z": 5,
      "name": "Deco_Bone_Full"
    },
    {
      "x": -2,
      "y": 36,
      "z": 5,
      "name": "Deco_Bone_Full"
    },
    {
      "x": -2,
      "y": 37,
      "z": 5,
      "name": "Deco_Bone_Full"
    },
    {
      "x": -2,
      "y": 38,
      "z": 5,
      "name": "Deco_Bone_Full"
    },
    {
      "x": -2,
      "y": 39,
      "z": 5,
      "name": "Deco_Bone_Full"
    },
    {
      "x": -1,
      "y": 26,
      "z": -13,
      "name": "Deco_Bone_Full"
    },
    {
      "x": -1,
      "y": 25,
      "z": -12,
      "name": "Deco_Bone_Full"
    },
    {
      "x": -1,
      "y": 39,
      "z": -12,
      "name": "Deco_Bone_Full"
    },
    {
      "x": -1,
      "y": 40,
      "z": -12,
      "name": "Deco_Bone_Full"
    },
    {
      "x": -1,
      "y": 24,
      "z": -11,
      "name": "Deco_Bone_Full"
    },
    {
      "x": -1,
      "y": 25,
      "z": -11,
      "name": "Deco_Bone_Full"
    },
    {
      "x": -1,
      "y": 24,
      "z": -9,
      "name": "Deco_Bone_Full"
    },
    {
      "x": -1,
      "y": 23,
      "z": -8,
      "name": "Deco_Bone_Full"
    },
    {
      "x": -1,
      "y": 24,
      "z": -8,
      "name": "Deco_Bone_Full"
    },
    {
      "x": -1,
      "y": 24,
      "z": -7,
      "name": "Deco_Bone_Full"
    },
    {
      "x": -1,
      "y": 26,
      "z": -3,
      "name": "Deco_Bone_Full"
    },
    {
      "x": -1,
      "y": 25,
      "z": -2,
      "name": "Deco_Bone_Full"
    },
    {
      "x": -1,
      "y": 26,
      "z": -2,
      "name": "Deco_Bone_Full"
    },
    {
      "x": -1,
      "y": 41,
      "z": -2,
      "name": "Deco_Bone_Full"
    },
    {
      "x": -1,
      "y": 26,
      "z": -1,
      "name": "Deco_Bone_Full"
    },
    {
      "x": 0,
      "y": 24,
      "z": -12,
      "name": "Deco_Bone_Full"
    },
    {
      "x": 0,
      "y": 25,
      "z": -12,
      "name": "Deco_Bone_Full"
    },
    {
      "x": 0,
      "y": 24,
      "z": -11,
      "name": "Deco_Bone_Full"
    },
    {
      "x": 0,
      "y": 25,
      "z": -11,
      "name": "Deco_Bone_Full"
    },
    {
      "x": 0,
      "y": 22,
      "z": -10,
      "name": "Deco_Bone_Full"
    },
    {
      "x": 0,
      "y": 23,
      "z": -10,
      "name": "Deco_Bone_Full"
    },
    {
      "x": 0,
      "y": 24,
      "z": -10,
      "name": "Deco_Bone_Full"
    },
    {
      "x": 0,
      "y": 25,
      "z": -10,
      "name": "Deco_Bone_Full"
    },
    {
      "x": 0,
      "y": 21,
      "z": -9,
      "name": "Deco_Bone_Full"
    },
    {
      "x": 0,
      "y": 22,
      "z": -9,
      "name": "Deco_Bone_Full"
    },
    {
      "x": 0,
      "y": 23,
      "z": -9,
      "name": "Deco_Bone_Full"
    },
    {
      "x": 0,
      "y": 24,
      "z": -9,
      "name": "Deco_Bone_Full"
    },
    {
      "x": 0,
      "y": 25,
      "z": -9,
      "name": "Deco_Bone_Full"
    },
    {
      "x": 0,
      "y": 24,
      "z": -8,
      "name": "Deco_Bone_Full"
    },
    {
      "x": 0,
      "y": 26,
      "z": -2,
      "name": "Deco_Bone_Full"
    },
    {
      "x": 0,
      "y": 26,
      "z": -1,
      "name": "Deco_Bone_Full"
    },
    {
      "x": 0,
      "y": 27,
      "z": -1,
      "name": "Deco_Bone_Full"
    },
    {
      "x": 0,
      "y": 40,
      "z": -1,
      "name": "Deco_Bone_Full"
    },
    {
      "x": 0,
      "y": 41,
      "z": -1,
      "name": "Deco_Bone_Full"
    },
    {
      "x": 0,
      "y": 27,
      "z": 0,
      "name": "Deco_Bone_Full"
    },
    {
      "x": 1,
      "y": 24,
      "z": -12,
      "name": "Deco_Bone_Full"
    },
    {
      "x": 1,
      "y": 23,
      "z": -11,
      "name": "Deco_Bone_Full"
    },
    {
      "x": 1,
      "y": 24,
      "z": -11,
      "name": "Deco_Bone_Full"
    },
    {
      "x": 1,
      "y": 25,
      "z": -11,
      "name": "Deco_Bone_Full"
    },
    {
      "x": 1,
      "y": 19,
      "z": -10,
      "name": "Deco_Bone_Full"
    },
    {
      "x": 1,
      "y": 20,
      "z": -10,
      "name": "Deco_Bone_Full"
    },
    {
      "x": 1,
      "y": 21,
      "z": -10,
      "name": "Deco_Bone_Full"
    },
    {
      "x": 1,
      "y": 22,
      "z": -10,
      "name": "Deco_Bone_Full"
    },
    {
      "x": 1,
      "y": 23,
      "z": -10,
      "name": "Deco_Bone_Full"
    },
    {
      "x": 1,
      "y": 24,
      "z": -10,
      "name": "Deco_Bone_Full"
    },
    {
      "x": 1,
      "y": 25,
      "z": -10,
      "name": "Deco_Bone_Full"
    },
    {
      "x": 1,
      "y": 26,
      "z": -10,
      "name": "Deco_Bone_Full"
    },
    {
      "x": 1,
      "y": 22,
      "z": -9,
      "name": "Deco_Bone_Full"
    },
    {
      "x": 1,
      "y": 23,
      "z": -9,
      "name": "Deco_Bone_Full"
    },
    {
      "x": 1,
      "y": 24,
      "z": -9,
      "name": "Deco_Bone_Full"
    },
    {
      "x": 1,
      "y": 25,
      "z": -9,
      "name": "Deco_Bone_Full"
    },
    {
      "x": 1,
      "y": 27,
      "z": -1,
      "name": "Deco_Bone_Full"
    },
    {
      "x": 1,
      "y": 27,
      "z": 0,
      "name": "Deco_Bone_Full"
    },
    {
      "x": 1,
      "y": 28,
      "z": 0,
      "name": "Deco_Bone_Full"
    },
    {
      "x": 1,
      "y": 29,
      "z": 0,
      "name": "Deco_Bone_Full"
    },
    {
      "x": 1,
      "y": 38,
      "z": 0,
      "name": "Deco_Bone_Full"
    },
    {
      "x": 1,
      "y": 39,
      "z": 0,
      "name": "Deco_Bone_Full"
    },
    {
      "x": 1,
      "y": 40,
      "z": 0,
      "name": "Deco_Bone_Full"
    },
    {
      "x": 2,
      "y": 24,
      "z": -12,
      "name": "Deco_Bone_Full"
    },
    {
      "x": 2,
      "y": 18,
      "z": -11,
      "name": "Deco_Bone_Full"
    },
    {
      "x": 2,
      "y": 19,
      "z": -11,
      "name": "Deco_Bone_Full"
    },
    {
      "x": 2,
      "y": 20,
      "z": -11,
      "name": "Deco_Bone_Full"
    },
    {
      "x": 2,
      "y": 21,
      "z": -11,
      "name": "Deco_Bone_Full"
    },
    {
      "x": 2,
      "y": 22,
      "z": -11,
      "name": "Deco_Bone_Full"
    },
    {
      "x": 2,
      "y": 23,
      "z": -11,
      "name": "Deco_Bone_Full"
    },
    {
      "x": 2,
      "y": 24,
      "z": -11,
      "name": "Deco_Bone_Full"
    },
    {
      "x": 2,
      "y": 23,
      "z": -10,
      "name": "Deco_Bone_Full"
    },
    {
      "x": 2,
      "y": 24,
      "z": -10,
      "name": "Deco_Bone_Full"
    },
    {
      "x": 2,
      "y": 25,
      "z": -10,
      "name": "Deco_Bone_Full"
    },
    {
      "x": 2,
      "y": 24,
      "z": -9,
      "name": "Deco_Bone_Full"
    },
    {
      "x": 2,
      "y": 25,
      "z": -9,
      "name": "Deco_Bone_Full"
    },
    {
      "x": 2,
      "y": 24,
      "z": -8,
      "name": "Deco_Bone_Full"
    },
    {
      "x": 2,
      "y": 25,
      "z": -8,
      "name": "Deco_Bone_Full"
    },
    {
      "x": 2,
      "y": 29,
      "z": 1,
      "name": "Deco_Bone_Full"
    },
    {
      "x": 2,
      "y": 30,
      "z": 1,
      "name": "Deco_Bone_Full"
    },
    {
      "x": 2,
      "y": 31,
      "z": 1,
      "name": "Deco_Bone_Full"
    },
    {
      "x": 2,
      "y": 32,
      "z": 1,
      "name": "Deco_Bone_Full"
    },
    {
      "x": 2,
      "y": 33,
      "z": 1,
      "name": "Deco_Bone_Full"
    },
    {
      "x": 2,
      "y": 34,
      "z": 1,
      "name": "Deco_Bone_Full"
    },
    {
      "x": 2,
      "y": 35,
      "z": 1,
      "name": "Deco_Bone_Full"
    },
    {
      "x": 2,
      "y": 36,
      "z": 1,
      "name": "Deco_Bone_Full"
    },
    {
      "x": 2,
      "y": 37,
      "z": 1,
      "name": "Deco_Bone_Full"
    },
    {
      "x": 2,
      "y": 38,
      "z": 1,
      "name": "Deco_Bone_Full"
    },
    {
      "x": 3,
      "y": 23,
      "z": -12,
      "name": "Deco_Bone_Full"
    },
    {
      "x": 3,
      "y": 24,
      "z": -12,
      "name": "Deco_Bone_Full"
    },
    {
      "x": 3,
      "y": 24,
      "z": -11,
      "name": "Deco_Bone_Full"
    },
    {
      "x": 3,
      "y": 24,
      "z": -10,
      "name": "Deco_Bone_Full"
    },
    {
      "x": 3,
      "y": 24,
      "z": -9,
      "name": "Deco_Bone_Full"
    },
    {
      "x": 3,
      "y": 25,
      "z": -9,
      "name": "Deco_Bone_Full"
    },
    {
      "x": 3,
      "y": 25,
      "z": -8,
      "name": "Deco_Bone_Full"
    },
    {
      "x": 3,
      "y": 39,
      "z": -8,
      "name": "Deco_Bone_Full"
    },
    {
      "x": 3,
      "y": 40,
      "z": -8,
      "name": "Deco_Bone_Full"
    },
    {
      "x": 3,
      "y": 26,
      "z": -7,
      "name": "Deco_Bone_Full"
    },
    {
      "x": 4,
      "y": 26,
      "z": -8,
      "name": "Deco_Bone_Full"
    },
    {
      "x": 4,
      "y": 25,
      "z": -7,
      "name": "Deco_Bone_Full"
    },
    {
      "x": 4,
      "y": 26,
      "z": -7,
      "name": "Deco_Bone_Full"
    },
    {
      "x": 4,
      "y": 39,
      "z": -7,
      "name": "Deco_Bone_Full"
    },
    {
      "x": 4,
      "y": 27,
      "z": -6,
      "name": "Deco_Bone_Full"
    },
    {
      "x": 5,
      "y": 27,
      "z": -7,
      "name": "Deco_Bone_Full"
    },
    {
      "x": 5,
      "y": 26,
      "z": -6,
      "name": "Deco_Bone_Full"
    },
    {
      "x": 5,
      "y": 27,
      "z": -6,
      "name": "Deco_Bone_Full"
    },
    {
      "x": 5,
      "y": 37,
      "z": -6,
      "name": "Deco_Bone_Full"
    },
    {
      "x": 5,
      "y": 38,
      "z": -6,
      "name": "Deco_Bone_Full"
    },
    {
      "x": 5,
      "y": 39,
      "z": -6,
      "name": "Deco_Bone_Full"
    },
    {
      "x": 5,
      "y": 27,
      "z": -5,
      "name": "Deco_Bone_Full"
    },
    {
      "x": 6,
      "y": 27,
      "z": -6,
      "name": "Deco_Bone_Full"
    },
    {
      "x": 6,
      "y": 27,
      "z": -5,
      "name": "Deco_Bone_Full"
    },
    {
      "x": 6,
      "y": 28,
      "z": -5,
      "name": "Deco_Bone_Full"
    },
    {
      "x": 6,
      "y": 29,
      "z": -5,
      "name": "Deco_Bone_Full"
    },
    {
      "x": 6,
      "y": 35,
      "z": -5,
      "name": "Deco_Bone_Full"
    },
    {
      "x": 6,
      "y": 36,
      "z": -5,
      "name": "Deco_Bone_Full"
    },
    {
      "x": 6,
      "y": 37,
      "z": -5,
      "name": "Deco_Bone_Full"
    },
    {
      "x": 7,
      "y": 29,
      "z": -4,
      "name": "Deco_Bone_Full"
    },
    {
      "x": 7,
      "y": 30,
      "z": -4,
      "name": "Deco_Bone_Full"
    },
    {
      "x": 7,
      "y": 31,
      "z": -4,
      "name": "Deco_Bone_Full"
    },
    {
      "x": 7,
      "y": 32,
      "z": -4,
      "name": "Deco_Bone_Full"
    },
    {
      "x": 7,
      "y": 33,
      "z": -4,
      "name": "Deco_Bone_Full"
    },
    {
      "x": 7,
      "y": 34,
      "z": -4,
      "name": "Deco_Bone_Full"
    },
    {
      "x": 7,
      "y": 35,
      "z": -4,
      "name": "Deco_Bone_Full"
    }
  ]
}