{
  "version": 8,
  "blockIdVersion": 8,
  "anchorX": 5,
  "anchorY": 8,
  "anchorZ": 6,
  "blocks": [
    {
      "x": 3,
      "y": 8,
      "z": 4,
      "name": "Rock_Stone"
    },
    {
      "x": 3,
      "y": 9,
      "z": 4,
      "name": "Rock_Stone"
    },
    {
      "x": 3,
      "y": 7,
      "z": 5,
      "name": "Rock_Stone"
    },
    {
      "x": 3,
      "y": 8,
      "z": 5,
      "name": "Rock_Stone"
    },
    {
      "x": 3,
      "y": 9,
      "z": 5,
      "name": "Rock_Stone"
    },
    {
      "x": 3,
      "y": 10,
      "z": 5,
      "name": "Rock_Stone_Mossy"
    },
    {
      "x": 3,
      "y": 7,
      "z": 6,
      "name": "Rock_Stone"
    },
    {
      "x": 3,
      "y": 8,
      "z": 6,
      "name": "Rock_Stone"
    },
    {
      "x": 3,
      "y": 9,
      "z": 6,
      "name": "Rock_Stone"
    },
    {
      "x": 4,
      "y": 8,
      "z": 3,
      "name": "Rock_Stone"
    },
    {
      "x": 4,
      "y": 9,
      "z": 3,
      "name": "Rock_Stone"
    },
    {
      "x": 4,
      "y": 8,
      "z": 4,
      "name": "Rock_Stone"
    },
    {
      "x": 4,
      "y": 9,
      "z": 4,
      "name": "Rock_Stone"
    },
    {
      "x": 4,
      "y": 10,
      "z": 4,
      "name": "Rock_Stone_Mossy"
    },
    {
      "x": 4,
      "y": 6,
      "z": 5,
      "name": "Rock_Stone"
    },
    {
      "x": 4,
      "y": 7,
      "z": 5,
      "name": "Rock_Stone"
    },
    {
      "x": 4,
      "y": 8,
      "z": 5,
      "name": "Rock_Stone"
    },
    {
      "x": 4,
      "y": 9,
      "z": 5,
      "name": "Rock_Stone"
    },
    {
      "x": 4,
      "y": 10,
      "z": 5,
      "name": "Rock_Stone_Mossy"
    },
    {
      "x": 4,
      "y": 6,
      "z": 6,
      "name": "Rock_Stone"
    },
    {
      "x": 4,
      "y": 7,
      "z": 6,
      "name": "Rock_Stone"
    },
    {
      "x": 4,
      "y": 8,
      "z": 6,
      "name": "Rock_Stone"
    },
    {
      "x": 4,
      "y": 9,
      "z": 6,
      "name": "Rock_Stone"
    },
    {
      "x": 4,
      "y": 10,
      "z": 6,
      "name": "Rock_Stone_Mossy"
    },
    {
      "x": 4,
      "y": 7,
      "z": 7,
      "name": "Rock_Stone"
    },
    {
      "x": 4,
      "y": 8,
      "z": 7,
      "name": "Rock_Stone"
    },
    {
      "x": 4,
      "y": 9,
      "z": 7,
      "name": "Rock_Stone"
    },
    {
      "x": 5,
      "y": 8,
      "z": 3,
      "name": "Rock_Stone"
    },
    {
      "x": 5,
      "y": 9,
      "z": 3,
      "name": "Rock_Stone"
    },
    {
      "x": 5,
      "y": 7,
      "z": 4,
      "name": "Rock_Stone"
    },
    {
      "x": 5,
      "y": 8,
      "z": 4,
      "name": "Rock_Stone"
    },
    {
      "x": 5,
      "y": 9,
      "z": 4,
      "name": "Rock_Stone"
    },
    {
      "x": 5,
      "y": 10,
      "z": 4,
      "name": "Rock_Stone"
    },
    {
      "x": 5,
      "y": 6,
      "z": 5,
      "name": "Rock_Stone"
    },
    {
      "x": 5,
      "y": 7,
      "z": 5,
      "name": "Rock_Stone"
    },
    {
      "x": 5,
      "y": 8,
      "z": 5,
      "name": "Rock_Stone"
    },
    {
      "x": 5,
      "y": 9,
      "z": 5,
      "name": "Rock_Stone"
    },
    {
      "x": 5,
      "y": 10,
      "z": 5,
      "name": "Rock_Stone_Mossy"
    },
    {
      "x": 5,
      "y": 5,
      "z": 6,
      "name": "Rock_Stone"
    },
    {
      "x": 5,
      "y": 6,
      "z": 6,
      "name": "Rock_Stone"
    },
    {
      "x": 5,
      "y": 7,
      "z": 6,
      "name": "Rock_Stone"
    },
    {
      "x": 5,
      "y": 8,
      "z": 6,
      "name": "Rock_Stone"
    },
    {
      "x": 5,
      "y": 9,
      "z": 6,
      "name": "Rock_Stone"
    },
    {
      "x": 5,
      "y": 10,
      "z": 6,
      "name": "Rock_Stone"
    },
    {
      "x": 5,
      "y": 5,
      "z": 7,
      "name": "Rock_Stone"
    },
    {
      "x": 5,
      "y": 6,
      "z": 7,
      "name": "Rock_Stone"
    },
    {
      "x": 5,
      "y": 7,
      "z": 7,
      "name": "Rock_Stone"
    },
    {
      "x": 5,
      "y": 8,
      "z": 7,
      "name": "Rock_Stone"
    },
    {
      "x": 5,
      "y": 9,
      "z": 7,
      "name": "Rock_Stone"
    },
    {
      "x": 6,
      "y": 7,
      "z": 4,
      "name": "Rock_Stone"
    },
    {
      "x": 6,
      "y": 8,
      "z": 4,
      "name": "Rock_Stone"
    },
    {
      "x": 6,
      "y": 5,
      "z": 5,
      "name": "Rock_Stone"
    },
    {
      "x": 6,
      "y": 6,
      "z": 5,
      "name": "Rock_Stone"
    },
    {
      "x": 6,
      "y": 7,
      "z": 5,
      "name": "Rock_Stone"
    },
    {
      "x": 6,
      "y": 8,
      "z": 5,
      "name": "Rock_Stone"
    },
    {
      "x": 6,
      "y": 9,
      "z": 5,
      "name": "Rock_Stone"
    },
    {
      "x": 6,
      "y": 10,
      "z": 5,
      "name": "Rock_Stone_Mossy"
    },
    {
      "x": 6,
      "y": 4,
      "z": 6,
      "name": "Rock_Stone"
    },
    {
      "x": 6,
      "y": 5,
      "z": 6,
      "name": "Rock_Stone"
    },
    {
      "x": 6,
      "y": 6,
      "z": 6,
      "name": "Rock_Stone"
    },
    {
      "x": 6,
      "y": 7,
      "z": 6,
      "name": "Rock_Stone"
    },
    {
      "x": 6,
      "y": 8,
      "z": 6,
      "name": "Rock_Stone"
    },
    {
      "x": 6,
      "y": 9,
      "z": 6,
      "name": "Rock_Stone"
    },
    {
      "x": 6,
      "y": 5,
      "z": 7,
      "name": "Rock_Stone"
    },
    {
      "x": 6,
      "y": 6,
      "z": 7,
      "name": "Rock_Stone"
    },
    {
      "x": 6,
      "y": 7,
      "z": 7,
      "name": "Rock_Stone"
    },
    {
      "x": 6,
      "y": 8,
      "z": 7,
      "name": "Rock_Stone"
    },
    {
      "x": 7,
      "y": 7,
      "z": 5,
      "name": "Rock_Stone"
    },
    {
      "x": 7,
      "y": 8,
      "z": 5,
      "name": "Rock_Stone"
    },
    {
      "x": 7,
      "y": 9,
      "z": 5,
      "name": "Rock_Stone"
    },
    {
      "x": 7,
      "y": 5,
      "z": 6,
      "name": "Rock_Stone"
    },
    {
      "x": 7,
      "y": 6,
      "z": 6,
      "name": "Rock_Stone"
    },
    {
      "x": 7,
      "y": 7,
      "z": 6,
      "name": "Rock_Stone"
    },
    {
      "x": 7,
      "y": 8,
      "z": 6,
      "name": "Rock_Stone"
    },
    {
      "x": 7,
      "y": 6,
      "z": 7,
      "name": "Rock_Stone"
    }
  ]
}