{
  "version": 8,
  "blockIdVersion": 8,
  "anchorX": 1,
  "anchorY": 6,
  "anchorZ": 2,
  "blocks": [
    {
      "x": -30,
      "y": 12,
      "z": -8,
      "name": "Plant_Moss_Wall_Green",
      "rotation": 3
    },
    {
      "x": -30,
      "y": 12,
      "z": -7,
      "name": "Plant_Vine_Wall",
      "rotation": 3
    },
    {
      "x": -29,
      "y": 4,
      "z": -19,
      "name": "Rock_Quartzite"
    },
    {
      "x": -29,
      "y": 5,
      "z": -19,
      "name": "Rock_Quartzite"
    },
    {
      "x": -29,
      "y": 6,
      "z": -19,
      "name": "Rock_Quartzite"
    },
    {
      "x": -29,
      "y": 3,
      "z": -18,
      "name": "Rock_Quartzite"
    },
    {
      "x": -29,
      "y": 4,
      "z": -18,
      "name": "Rock_Quartzite"
    },
    {
      "x": -29,
      "y": 5,
      "z": -18,
      "name": "Rock_Quartzite"
    },
    {
      "x": -29,
      "y": 6,
      "z": -18,
      "name": "Rock_Quartzite"
    },
    {
      "x": -29,
      "y": 7,
      "z": -18,
      "name": "Rock_Quartzite_Brick"
    },
    {
      "x": -29,
      "y": 8,
      "z": -18,
      "name": "Rock_Quartzite_Brick_Half",
      "rotation": 7
    },
    {
      "x": -29,
      "y": 9,
      "z": -18,
      "name": "Rock_Quartzite_Brick_Half",
      "rotation": 7
    },
    {
      "x": -29,
      "y": 10,
      "z": -18,
      "name": "Rock_Quartzite_Brick_Half",
      "rotation": 7
    },
    {
      "x": -29,
      "y": 11,
      "z": -18,
      "name": "Rock_Quartzite_Brick_Half",
      "rotation": 7
    },
    {
      "x": -29,
      "y": 12,
      "z": -18,
      "name": "Rock_Quartzite_Brick_Half"
    },
    {
      "x": -29,
      "y": 3,
      "z": -17,
      "name": "Rock_Quartzite"
    },
    {
      "x": -29,
      "y": 4,
      "z": -17,
      "name": "Rock_Quartzite"
    },
    {
      "x": -29,
      "y": 5,
      "z": -17,
      "name": "Rock_Quartzite_Cobble"
    },
    {
      "x": -29,
      "y": 6,
      "z": -17,
      "name": "Rock_Quartzite_Cobble"
    },
    {
      "x": -29,
      "y": 12,
      "z": -17,
      "name": "Rock_Quartzite_Brick"
    },
    {
      "x": -29,
      "y": 2,
      "z": -16,
      "name": "Rock_Quartzite"
    },
    {
      "x": -29,
      "y": 3,
      "z": -16,
      "name": "Rock_Quartzite"
    },
    {
      "x": -29,
      "y": 4,
      "z": -16,
      "name": "Rock_Quartzite"
    },
    {
      "x": -29,
      "y": 5,
      "z": -16,
      "name": "Rock_Quartzite"
    },
    {
      "x": -29,
      "y": 6,
      "z": -16,
      "name": "Rock_Quartzite_Cobble"
    },
    {
      "x": -29,
      "y": 11,
      "z": -16,
      "name": "Plant_Roots_Cave_Small",
      "rotation": 8
    },
    {
      "x": -29,
      "y": 12,
      "z": -16,
      "name": "Rock_Quartzite_Brick"
    },
    {
      "x": -29,
      "y": 1,
      "z": -15,
      "name": "Rock_Quartzite"
    },
    {
      "x": -29,
      "y": 2,
      "z": -15,
      "name": "Rock_Quartzite"
    },
    {
      "x": -29,
      "y": 3,
      "z": -15,
      "name": "Rock_Quartzite"
    },
    {
      "x": -29,
      "y": 4,
      "z": -15,
      "name": "Rock_Quartzite"
    },
    {
      "x": -29,
      "y": 11,
      "z": -15,
      "name": "Plant_Vine",
      "rotation": 3
    },
    {
      "x": -29,
      "y": 12,
      "z": -15,
      "name": "Rock_Quartzite_Brick"
    },
    {
      "x": -29,
      "y": 1,
      "z": -14,
      "name": "Rock_Quartzite"
    },
    {
      "x": -29,
      "y": 2,
      "z": -14,
      "name": "Rock_Quartzite"
    },
    {
      "x": -29,
      "y": 3,
      "z": -14,
      "name": "Rock_Quartzite"
    },
    {
      "x": -29,
      "y": 9,
      "z": -14,
      "name": "Plant_Vine_Wall",
      "rotation": 3
    },
    {
      "x": -29,
      "y": 10,
      "z": -14,
      "name": "Plant_Vine",
      "rotation": 3
    },
    {
      "x": -29,
      "y": 11,
      "z": -14,
      "name": "Plant_Vine",
      "rotation": 3
    },
    {
      "x": -29,
      "y": 1,
      "z": -13,
      "name": "Rock_Quartzite"
    },
    {
      "x": -29,
      "y": 2,
      "z": -13,
      "name": "Rock_Quartzite"
    },
    {
      "x": -29,
      "y": 11,
      "z": -13,
      "name": "Plant_Vine_Wall",
      "rotation": 3
    },
    {
      "x": -29,
      "y": 11,
      "z": -12,
      "name": "Plant_Moss_Wall_Green",
      "rotation": 3
    },
    {
      "x": -29,
      "y": 1,
      "z": -11,
      "name": "Rock_Quartzite"
    },
    {
      "x": -29,
      "y": 2,
      "z": -11,
      "name": "Rock_Quartzite"
    },
    {
      "x": -29,
      "y": 3,
      "z": -11,
      "name": "Rock_Quartzite"
    },
    {
      "x": -29,
      "y": 4,
      "z": -11,
      "name": "Rock_Quartzite"
    },
    {
      "x": -29,
      "y": 5,
      "z": -11,
      "name": "Rock_Quartzite"
    },
    {
      "x": -29,
      "y": 1,
      "z": -10,
      "name": "Rock_Quartzite"
    },
    {
      "x": -29,
      "y": 2,
      "z": -10,
      "name": "Rock_Quartzite"
    },
    {
      "x": -29,
      "y": 3,
      "z": -10,
      "name": "Rock_Quartzite"
    },
    {
      "x": -29,
      "y": 4,
      "z": -10,
      "name": "Rock_Quartzite"
    },
    {
      "x": -29,
      "y": 5,
      "z": -10,
      "name": "Rock_Quartzite"
    },
    {
      "x": -29,
      "y": 6,
      "z": -10,
      "name": "Rock_Quartzite"
    },
    {
      "x": -29,
      "y": 7,
      "z": -10,
      "name": "Rock_Quartzite_Brick"
    },
    {
      "x": -29,
      "y": 8,
      "z": -10,
      "name": "Rock_Quartzite_Brick_Half",
      "rotation": 7
    },
    {
      "x": -29,
      "y": 9,
      "z": -10,
      "name": "Rock_Quartzite_Brick_Half",
      "rotation": 7
    },
    {
      "x": -29,
      "y": 10,
      "z": -10,
      "name": "Rock_Quartzite_Brick_Half",
      "rotation": 7
    },
    {
      "x": -29,
      "y": 11,
      "z": -10,
      "name": "Rock_Quartzite_Brick_Half",
      "rotation": 7
    },
    {
      "x": -29,
      "y": 12,
      "z": -10,
      "name": "Rock_Quartzite_Cobble_Half"
    },
    {
      "x": -29,
      "y": 2,
      "z": -9,
      "name": "Rock_Quartzite"
    },
    {
      "x": -29,
      "y": 3,
      "z": -9,
      "name": "Rock_Quartzite"
    },
    {
      "x": -29,
      "y": 4,
      "z": -9,
      "name": "Rock_Quartzite"
    },
    {
      "x": -29,
      "y": 5,
      "z": -9,
      "name": "Rock_Quartzite"
    },
    {
      "x": -29,
      "y": 6,
      "z": -9,
      "name": "Rock_Quartzite"
    },
    {
      "x": -29,
      "y": 12,
      "z": -9,
      "name": "Rock_Quartzite_Cobble_Stairs",
      "rotation": 2
    },
    {
      "x": -29,
      "y": 2,
      "z": -8,
      "name": "Rock_Quartzite"
    },
    {
      "x": -29,
      "y": 3,
      "z": -8,
      "name": "Rock_Quartzite"
    },
    {
      "x": -29,
      "y": 4,
      "z": -8,
      "name": "Rock_Quartzite"
    },
    {
      "x": -29,
      "y": 5,
      "z": -8,
      "name": "Rock_Quartzite"
    },
    {
      "x": -29,
      "y": 6,
      "z": -8,
      "name": "Rock_Quartzite"
    },
    {
      "x": -29,
      "y": 12,
      "z": -8,
      "name": "Rock_Quartzite_Brick_Stairs",
      "rotation": 9
    },
    {
      "x": -29,
      "y": 13,
      "z": -8,
      "name": "Plant_Moss_Rug_Green"
    },
    {
      "x": -29,
      "y": 1,
      "z": -7,
      "name": "Rock_Quartzite"
    },
    {
      "x": -29,
      "y": 2,
      "z": -7,
      "name": "Rock_Quartzite"
    },
    {
      "x": -29,
      "y": 3,
      "z": -7,
      "name": "Rock_Quartzite"
    },
    {
      "x": -29,
      "y": 4,
      "z": -7,
      "name": "Rock_Quartzite"
    },
    {
      "x": -29,
      "y": 5,
      "z": -7,
      "name": "Rock_Quartzite"
    },
    {
      "x": -29,
      "y": 6,
      "z": -7,
      "name": "Rock_Quartzite"
    },
    {
      "x": -29,
      "y": 12,
      "z": -7,
      "name": "Rock_Quartzite_Brick_Stairs",
      "rotation": 9
    },
    {
      "x": -29,
      "y": 13,
      "z": -7,
      "name": "Plant_Moss_Rug_Green"
    },
    {
      "x": -29,
      "y": 1,
      "z": -6,
      "name": "Rock_Quartzite"
    },
    {
      "x": -29,
      "y": 2,
      "z": -6,
      "name": "Rock_Quartzite"
    },
    {
      "x": -29,
      "y": 3,
      "z": -6,
      "name": "Rock_Quartzite"
    },
    {
      "x": -29,
      "y": 4,
      "z": -6,
      "name": "Rock_Quartzite"
    },
    {
      "x": -29,
      "y": 5,
      "z": -6,
      "name": "Rock_Quartzite"
    },
    {
      "x": -29,
      "y": 6,
      "z": -6,
      "name": "Rock_Quartzite"
    },
    {
      "x": -29,
      "y": 1,
      "z": -5,
      "name": "Rock_Quartzite"
    },
    {
      "x": -29,
      "y": 2,
      "z": -5,
      "name": "Rock_Quartzite"
    },
    {
      "x": -29,
      "y": 3,
      "z": -5,
      "name": "Rock_Quartzite"
    },
    {
      "x": -29,
      "y": 4,
      "z": -5,
      "name": "Rock_Quartzite"
    },
    {
      "x": -29,
      "y": 5,
      "z": -5,
      "name": "Rock_Quartzite"
    },
    {
      "x": -29,
      "y": 1,
      "z": -4,
      "name": "Rock_Quartzite"
    },
    {
      "x": -29,
      "y": 2,
      "z": -4,
      "name": "Rock_Quartzite"
    },
    {
      "x": -29,
      "y": 3,
      "z": -4,
      "name": "Rock_Quartzite"
    },
    {
      "x": -29,
      "y": 4,
      "z": -4,
      "name": "Rock_Quartzite"
    },
    {
      "x": -29,
      "y": 3,
      "z": -3,
      "name": "Rock_Quartzite"
    },
    {
      "x": -29,
      "y": 4,
      "z": -3,
      "name": "Rock_Quartzite_Cobble"
    },
    {
      "x": -29,
      "y": 4,
      "z": -2,
      "name": "Rock_Quartzite"
    },
    {
      "x": -29,
      "y": 5,
      "z": -2,
      "name": "Rock_Quartzite"
    },
    {
      "x": -29,
      "y": 6,
      "z": -2,
      "name": "Rock_Quartzite"
    },
    {
      "x": -29,
      "y": 7,
      "z": -2,
      "name": "Rock_Quartzite_Brick"
    },
    {
      "x": -29,
      "y": 8,
      "z": -2,
      "name": "Rock_Quartzite_Brick_Half",
      "rotation": 7
    },
    {
      "x": -29,
      "y": 9,
      "z": -2,
      "name": "Rock_Quartzite_Brick_Half",
      "rotation": 7
    },
    {
      "x": -29,
      "y": 10,
      "z": -2,
      "name": "Rock_Quartzite_Brick_Half",
      "rotation": 7
    },
    {
      "x": -29,
      "y": 4,
      "z": 13,
      "name": "Rock_Quartzite"
    },
    {
      "x": -29,
      "y": 5,
      "z": 13,
      "name": "Rock_Quartzite"
    },
    {
      "x": -29,
      "y": 6,
      "z": 13,
      "name": "Rock_Quartzite"
    },
    {
      "x": -29,
      "y": 7,
      "z": 13,
      "name": "Rock_Quartzite_Cobble_Half"
    },
    {
      "x": -29,
      "y": 5,
      "z": 14,
      "name": "Rock_Quartzite"
    },
    {
      "x": -29,
      "y": 6,
      "z": 14,
      "name": "Rock_Quartzite"
    },
    {
      "x": -29,
      "y": 7,
      "z": 14,
      "name": "Rock_Quartzite_Cobble_Half"
    },
    {
      "x": -28,
      "y": 4,
      "z": -19,
      "name": "Rock_Quartzite"
    },
    {
      "x": -28,
      "y": 5,
      "z": -19,
      "name": "Rock_Quartzite"
    },
    {
      "x": -28,
      "y": 6,
      "z": -19,
      "name": "Rock_Quartzite"
    },
    {
      "x": -28,
      "y": 7,
      "z": -19,
      "name": "Rock_Quartzite_Brick"
    },
    {
      "x": -28,
      "y": 8,
      "z": -19,
      "name": "Rock_Quartzite_Brick_Half",
      "rotation": 6
    },
    {
      "x": -28,
      "y": 9,
      "z": -19,
      "name": "Rock_Quartzite_Brick_Half",
      "rotation": 6
    },
    {
      "x": -28,
      "y": 10,
      "z": -19,
      "name": "Rock_Quartzite_Brick_Half",
      "rotation": 6
    },
    {
      "x": -28,
      "y": 1,
      "z": -18,
      "name": "Rock_Quartzite"
    },
    {
      "x": -28,
      "y": 2,
      "z": -18,
      "name": "Rock_Quartzite"
    },
    {
      "x": -28,
      "y": 3,
      "z": -18,
      "name": "Rock_Quartzite"
    },
    {
      "x": -28,
      "y": 4,
      "z": -18,
      "name": "Rock_Quartzite"
    },
    {
      "x": -28,
      "y": 5,
      "z": -18,
      "name": "Rock_Quartzite"
    },
    {
      "x": -28,
      "y": 6,
      "z": -18,
      "name": "Rock_Quartzite"
    },
    {
      "x": -28,
      "y": 7,
      "z": -18,
      "name": "Rock_Quartzite_Brick"
    },
    {
      "x": -28,
      "y": 8,
      "z": -18,
      "name": "Rock_Quartzite"
    },
    {
      "x": -28,
      "y": 9,
      "z": -18,
      "name": "Rock_Quartzite"
    },
    {
      "x": -28,
      "y": 10,
      "z": -18,
      "name": "Rock_Quartzite"
    },
    {
      "x": -28,
      "y": 11,
      "z": -18,
      "name": "Rock_Quartzite_Brick"
    },
    {
      "x": -28,
      "y": 0,
      "z": -17,
      "name": "Rock_Quartzite"
    },
    {
      "x": -28,
      "y": 1,
      "z": -17,
      "name": "Rock_Quartzite"
    },
    {
      "x": -28,
      "y": 2,
      "z": -17,
      "name": "Rock_Quartzite"
    },
    {
      "x": -28,
      "y": 3,
      "z": -17,
      "name": "Rock_Quartzite"
    },
    {
      "x": -28,
      "y": 4,
      "z": -17,
      "name": "Rock_Quartzite"
    },
    {
      "x": -28,
      "y": 5,
      "z": -17,
      "name": "Rock_Quartzite"
    },
    {
      "x": -28,
      "y": 6,
      "z": -17,
      "name": "Rock_Quartzite"
    },
    {
      "x": -28,
      "y": 7,
      "z": -17,
      "name": "Rock_Quartzite_Brick"
    },
    {
      "x": -28,
      "y": 8,
      "z": -17,
      "name": "Rock_Quartzite_Cobble"
    },
    {
      "x": -28,
      "y": 9,
      "z": -17,
      "name": "Rock_Quartzite_Cobble"
    },
    {
      "x": -28,
      "y": 10,
      "z": -17,
      "name": "Rock_Quartzite_Cobble_Half",
      "rotation": 7
    },
    {
      "x": -28,
      "y": 11,
      "z": -17,
      "name": "Rock_Quartzite_Cobble_Stairs",
      "rotation": 9
    },
    {
      "x": -28,
      "y": 12,
      "z": -17,
      "name": "Soil_Grass"
    },
    {
      "x": -28,
      "y": 0,
      "z": -16,
      "name": "Rock_Quartzite"
    },
    {
      "x": -28,
      "y": 1,
      "z": -16,
      "name": "Rock_Quartzite"
    },
    {
      "x": -28,
      "y": 2,
      "z": -16,
      "name": "Rock_Quartzite"
    },
    {
      "x": -28,
      "y": 3,
      "z": -16,
      "name": "Rock_Quartzite"
    },
    {
      "x": -28,
      "y": 4,
      "z": -16,
      "name": "Rock_Quartzite"
    },
    {
      "x": -28,
      "y": 5,
      "z": -16,
      "name": "Rock_Quartzite"
    },
    {
      "x": -28,
      "y": 6,
      "z": -16,
      "name": "Rock_Quartzite"
    },
    {
      "x": -28,
      "y": 7,
      "z": -16,
      "name": "Rock_Quartzite_Brick"
    },
    {
      "x": -28,
      "y": 8,
      "z": -16,
      "name": "Rock_Quartzite"
    },
    {
      "x": -28,
      "y": 9,
      "z": -16,
      "name": "Rock_Quartzite"
    },
    {
      "x": -28,
      "y": 10,
      "z": -16,
      "name": "Soil_Dirt"
    },
    {
      "x": -28,
      "y": 11,
      "z": -16,
      "name": "Soil_Dirt"
    },
    {
      "x": -28,
      "y": 12,
      "z": -16,
      "name": "Soil_Grass"
    },
    {
      "x": -28,
      "y": 13,
      "z": -16,
      "name": "Plant_Grass_Lush_Short"
    },
    {
      "x": -28,
      "y": 0,
      "z": -15,
      "name": "Rock_Quartzite"
    },
    {
      "x": -28,
      "y": 1,
      "z": -15,
      "name": "Rock_Quartzite"
    },
    {
      "x": -28,
      "y": 2,
      "z": -15,
      "name": "Rock_Quartzite"
    },
    {
      "x": -28,
      "y": 3,
      "z": -15,
      "name": "Rock_Quartzite"
    },
    {
      "x": -28,
      "y": 4,
      "z": -15,
      "name": "Rock_Quartzite"
    },
    {
      "x": -28,
      "y": 5,
      "z": -15,
      "name": "Rock_Quartzite"
    },
    {
      "x": -28,
      "y": 6,
      "z": -15,
      "name": "Rock_Quartzite"
    },
    {
      "x": -28,
      "y": 7,
      "z": -15,
      "name": "Rock_Quartzite_Brick"
    },
    {
      "x": -28,
      "y": 8,
      "z": -15,
      "name": "Rock_Quartzite"
    },
    {
      "x": -28,
      "y": 9,
      "z": -15,
      "name": "Rock_Quartzite"
    },
    {
      "x": -28,
      "y": 10,
      "z": -15,
      "name": "Soil_Dirt"
    },
    {
      "x": -28,
      "y": 11,
      "z": -15,
      "name": "Soil_Dirt"
    },
    {
      "x": -28,
      "y": 12,
      "z": -15,
      "name": "Soil_Grass"
    },
    {
      "x": -28,
      "y": 13,
      "z": -15,
      "name": "Plant_Grass_Lush"
    },
    {
      "x": -28,
      "y": 0,
      "z": -14,
      "name": "Rock_Quartzite"
    },
    {
      "x": -28,
      "y": 1,
      "z": -14,
      "name": "Rock_Quartzite"
    },
    {
      "x": -28,
      "y": 2,
      "z": -14,
      "name": "Rock_Quartzite"
    },
    {
      "x": -28,
      "y": 3,
      "z": -14,
      "name": "Rock_Quartzite"
    },
    {
      "x": -28,
      "y": 4,
      "z": -14,
      "name": "Rock_Quartzite"
    },
    {
      "x": -28,
      "y": 5,
      "z": -14,
      "name": "Rock_Quartzite_Cobble"
    },
    {
      "x": -28,
      "y": 7,
      "z": -14,
      "name": "Rock_Quartzite_Brick_Half",
      "rotation": 7
    },
    {
      "x": -28,
      "y": 8,
      "z": -14,
      "name": "Rock_Quartzite_Brick_Half",
      "rotation": 7
    },
    {
      "x": -28,
      "y": 9,
      "z": -14,
      "name": "Rock_Quartzite"
    },
    {
      "x": -28,
      "y": 10,
      "z": -14,
      "name": "Rock_Quartzite_Cobble"
    },
    {
      "x": -28,
      "y": 11,
      "z": -14,
      "name": "Soil_Grass"
    },
    {
      "x": -28,
      "y": 12,
      "z": -14,
      "name": "Plant_Moss_Rug_Green"
    },
    {
      "x": -28,
      "y": 0,
      "z": -13,
      "name": "Rock_Quartzite"
    },
    {
      "x": -28,
      "y": 1,
      "z": -13,
      "name": "Rock_Quartzite"
    },
    {
      "x": -28,
      "y": 2,
      "z": -13,
      "name": "Rock_Quartzite"
    },
    {
      "x": -28,
      "y": 3,
      "z": -13,
      "name": "Rock_Quartzite"
    },
    {
      "x": -28,
      "y": 4,
      "z": -13,
      "name": "Rock_Quartzite"
    },
    {
      "x": -28,
      "y": 5,
      "z": -13,
      "name": "Rock_Quartzite_Cobble"
    },
    {
      "x": -28,
      "y": 7,
      "z": -13,
      "name": "Empty"
    },
    {
      "x": -28,
      "y": 8,
      "z": -13,
      "name": "Empty"
    },
    {
      "x": -28,
      "y": 9,
      "z": -13,
      "name": "Empty"
    },
    {
      "x": -28,
      "y": 10,
      "z": -13,
      "name": "Rock_Quartzite"
    },
    {
      "x": -28,
      "y": 11,
      "z": -13,
      "name": "Soil_Grass"
    },
    {
      "x": -28,
      "y": 12,
      "z": -13,
      "name": "Plant_Grass_Lush_Short"
    },
    {
      "x": -28,
      "y": 0,
      "z": -12,
      "name": "Rock_Quartzite"
    },
    {
      "x": -28,
      "y": 1,
      "z": -12,
      "name": "Rock_Quartzite"
    },
    {
      "x": -28,
      "y": 2,
      "z": -12,
      "name": "Rock_Quartzite"
    },
    {
      "x": -28,
      "y": 3,
      "z": -12,
      "name": "Rock_Quartzite_Cobble"
    },
    {
      "x": -28,
      "y": 4,
      "z": -12,
      "name": "Rock_Quartzite_Cobble"
    },
    {
      "x": -28,
      "y": 5,
      "z": -12,
      "name": "Rock_Quartzite_Cobble"
    },
    {
      "x": -28,
      "y": 7,
      "z": -12,
      "name": "Empty"
    },
    {
      "x": -28,
      "y": 8,
      "z": -12,
      "name": "Empty"
    },
    {
      "x": -28,
      "y": 9,
      "z": -12,
      "name": "Empty"
    },
    {
      "x": -28,
      "y": 10,
      "z": -12,
      "name": "Soil_Dirt"
    },
    {
      "x": -28,
      "y": 11,
      "z": -12,
      "name": "Soil_Grass"
    },
    {
      "x": -28,
      "y": 0,
      "z": -11,
      "name": "Rock_Quartzite"
    },
    {
      "x": -28,
      "y": 1,
      "z": -11,
      "name": "Rock_Quartzite"
    },
    {
      "x": -28,
      "y": 2,
      "z": -11,
      "name": "Rock_Quartzite"
    },
    {
      "x": -28,
      "y": 3,
      "z": -11,
      "name": "Rock_Quartzite"
    },
    {
      "x": -28,
      "y": 4,
      "z": -11,
      "name": "Rock_Quartzite"
    },
    {
      "x": -28,
      "y": 5,
      "z": -11,
      "name": "Rock_Quartzite"
    },
    {
      "x": -28,
      "y": 6,
      "z": -11,
      "name": "Rock_Quartzite"
    },
    {
      "x": -28,
      "y": 7,
      "z": -11,
      "name": "Rock_Quartzite_Brick"
    },
    {
      "x": -28,
      "y": 8,
      "z": -11,
      "name": "Rock_Quartzite_Cobble_Stairs",
      "rotation": 3
    },
    {
      "x": -28,
      "y": 9,
      "z": -11,
      "name": "Rock_Quartzite_Cobble_Half",
      "rotation": 7
    },
    {
      "x": -28,
      "y": 10,
      "z": -11,
      "name": "Soil_Dirt"
    },
    {
      "x": -28,
      "y": 11,
      "z": -11,
      "name": "Soil_Grass"
    },
    {
      "x": -28,
      "y": 12,
      "z": -11,
      "name": "Plant_Grass_Sharp"
    },
    {
      "x": -28,
      "y": 0,
      "z": -10,
      "name": "Rock_Quartzite"
    },
    {
      "x": -28,
      "y": 1,
      "z": -10,
      "name": "Rock_Quartzite"
    },
    {
      "x": -28,
      "y": 2,
      "z": -10,
      "name": "Rock_Quartzite"
    },
    {
      "x": -28,
      "y": 3,
      "z": -10,
      "name": "Rock_Quartzite"
    },
    {
      "x": -28,
      "y": 4,
      "z": -10,
      "name": "Rock_Quartzite"
    },
    {
      "x": -28,
      "y": 5,
      "z": -10,
      "name": "Rock_Quartzite"
    },
    {
      "x": -28,
      "y": 6,
      "z": -10,
      "name": "Rock_Quartzite"
    },
    {
      "x": -28,
      "y": 7,
      "z": -10,
      "name": "Rock_Quartzite_Cobble"
    },
    {
      "x": -28,
      "y": 8,
      "z": -10,
      "name": "Rock_Quartzite_Cobble"
    },
    {
      "x": -28,
      "y": 9,
      "z": -10,
      "name": "Rock_Quartzite_Cobble"
    },
    {
      "x": -28,
      "y": 10,
      "z": -10,
      "name": "Rock_Quartzite"
    },
    {
      "x": -28,
      "y": 11,
      "z": -10,
      "name": "Rock_Quartzite"
    },
    {
      "x": -28,
      "y": 12,
      "z": -10,
      "name": "Soil_Grass"
    },
    {
      "x": -28,
      "y": 0,
      "z": -9,
      "name": "Rock_Quartzite"
    },
    {
      "x": -28,
      "y": 1,
      "z": -9,
      "name": "Rock_Quartzite"
    },
    {
      "x": -28,
      "y": 2,
      "z": -9,
      "name": "Rock_Quartzite"
    },
    {
      "x": -28,
      "y": 3,
      "z": -9,
      "name": "Rock_Quartzite"
    },
    {
      "x": -28,
      "y": 4,
      "z": -9,
      "name": "Rock_Quartzite"
    },
    {
      "x": -28,
      "y": 5,
      "z": -9,
      "name": "Rock_Quartzite"
    },
    {
      "x": -28,
      "y": 6,
      "z": -9,
      "name": "Rock_Quartzite"
    },
    {
      "x": -28,
      "y": 7,
      "z": -9,
      "name": "Rock_Quartzite_Brick"
    },
    {
      "x": -28,
      "y": 8,
      "z": -9,
      "name": "Rock_Quartzite"
    },
    {
      "x": -28,
      "y": 9,
      "z": -9,
      "name": "Rock_Quartzite"
    },
    {
      "x": -28,
      "y": 10,
      "z": -9,
      "name": "Rock_Quartzite"
    },
    {
      "x": -28,
      "y": 11,
      "z": -9,
      "name": "Rock_Quartzite"
    },
    {
      "x": -28,
      "y": 12,
      "z": -9,
      "name": "Soil_Grass"
    },
    {
      "x": -28,
      "y": 0,
      "z": -8,
      "name": "Rock_Quartzite"
    },
    {
      "x": -28,
      "y": 1,
      "z": -8,
      "name": "Rock_Quartzite"
    },
    {
      "x": -28,
      "y": 2,
      "z": -8,
      "name": "Rock_Quartzite"
    },
    {
      "x": -28,
      "y": 3,
      "z": -8,
      "name": "Rock_Quartzite"
    },
    {
      "x": -28,
      "y": 4,
      "z": -8,
      "name": "Rock_Quartzite"
    },
    {
      "x": -28,
      "y": 5,
      "z": -8,
      "name": "Rock_Quartzite"
    },
    {
      "x": -28,
      "y": 6,
      "z": -8,
      "name": "Rock_Quartzite"
    },
    {
      "x": -28,
      "y": 7,
      "z": -8,
      "name": "Rock_Quartzite_Brick"
    },
    {
      "x": -28,
      "y": 8,
      "z": -8,
      "name": "Rock_Quartzite"
    },
    {
      "x": -28,
      "y": 9,
      "z": -8,
      "name": "Rock_Quartzite"
    },
    {
      "x": -28,
      "y": 10,
      "z": -8,
      "name": "Rock_Quartzite"
    },
    {
      "x": -28,
      "y": 11,
      "z": -8,
      "name": "Rock_Quartzite"
    },
    {
      "x": -28,
      "y": 12,
      "z": -8,
      "name": "Soil_Grass"
    },
    {
      "x": -28,
      "y": 13,
      "z": -8,
      "name": "Plant_Fern_Winter"
    },
    {
      "x": -28,
      "y": 0,
      "z": -7,
      "name": "Rock_Quartzite"
    },
    {
      "x": -28,
      "y": 1,
      "z": -7,
      "name": "Rock_Quartzite"
    },
    {
      "x": -28,
      "y": 2,
      "z": -7,
      "name": "Rock_Quartzite"
    },
    {
      "x": -28,
      "y": 3,
      "z": -7,
      "name": "Rock_Quartzite"
    },
    {
      "x": -28,
      "y": 4,
      "z": -7,
      "name": "Rock_Quartzite"
    },
    {
      "x": -28,
      "y": 5,
      "z": -7,
      "name": "Rock_Quartzite"
    },
    {
      "x": -28,
      "y": 6,
      "z": -7,
      "name": "Rock_Quartzite"
    },
    {
      "x": -28,
      "y": 7,
      "z": -7,
      "name": "Rock_Quartzite_Brick"
    },
    {
      "x": -28,
      "y": 11,
      "z": -7,
      "name": "Rock_Quartzite_Cobble_Stairs",
      "rotation": 9
    },
    {
      "x": -28,
      "y": 12,
      "z": -7,
      "name": "Soil_Grass"
    },
    {
      "x": -28,
      "y": 13,
      "z": -7,
      "name": "Plant_Grass_Lush"
    },
    {
      "x": -28,
      "y": 0,
      "z": -6,
      "name": "Rock_Quartzite"
    },
    {
      "x": -28,
      "y": 1,
      "z": -6,
      "name": "Rock_Quartzite"
    },
    {
      "x": -28,
      "y": 2,
      "z": -6,
      "name": "Rock_Quartzite"
    },
    {
      "x": -28,
      "y": 3,
      "z": -6,
      "name": "Rock_Quartzite"
    },
    {
      "x": -28,
      "y": 4,
      "z": -6,
      "name": "Rock_Quartzite"
    },
    {
      "x": -28,
      "y": 5,
      "z": -6,
      "name": "Rock_Quartzite"
    },
    {
      "x": -28,
      "y": 6,
      "z": -6,
      "name": "Rock_Quartzite"
    },
    {
      "x": -28,
      "y": 7,
      "z": -6,
      "name": "Rock_Quartzite_Brick"
    },
    {
      "x": -28,
      "y": 9,
      "z": -6,
      "name": "Plant_Roots_Cave_Small",
      "rotation": 8
    },
    {
      "x": -28,
      "y": 10,
      "z": -6,
      "name": "Soil_Dirt"
    },
    {
      "x": -28,
      "y": 11,
      "z": -6,
      "name": "Soil_Grass"
    },
    {
      "x": -28,
      "y": 0,
      "z": -5,
      "name": "Rock_Quartzite"
    },
    {
      "x": -28,
      "y": 1,
      "z": -5,
      "name": "Rock_Quartzite"
    },
    {
      "x": -28,
      "y": 2,
      "z": -5,
      "name": "Rock_Quartzite"
    },
    {
      "x": -28,
      "y": 3,
      "z": -5,
      "name": "Rock_Quartzite"
    },
    {
      "x": -28,
      "y": 4,
      "z": -5,
      "name": "Rock_Quartzite"
    },
    {
      "x": -28,
      "y": 5,
      "z": -5,
      "name": "Rock_Quartzite"
    },
    {
      "x": -28,
      "y": 6,
      "z": -5,
      "name": "Rock_Quartzite"
    },
    {
      "x": -28,
      "y": 7,
      "z": -5,
      "name": "Rock_Quartzite_Brick"
    },
    {
      "x": -28,
      "y": 8,
      "z": -5,
      "name": "Rock_Quartzite"
    },
    {
      "x": -28,
      "y": 9,
      "z": -5,
      "name": "Rock_Quartzite_Cobble"
    },
    {
      "x": -28,
      "y": 10,
      "z": -5,
      "name": "Soil_Grass"
    },
    {
      "x": -28,
      "y": 11,
      "z": -5,
      "name": "Plant_Grass_Sharp_Tall"
    },
    {
      "x": -28,
      "y": 12,
      "z": -5,
      "name": "Plant_Grass_Sharp_Tall",
      "filler": 1024
    },
    {
      "x": -28,
      "y": 0,
      "z": -4,
      "name": "Rock_Quartzite"
    },
    {
      "x": -28,
      "y": 1,
      "z": -4,
      "name": "Rock_Quartzite"
    },
    {
      "x": -28,
      "y": 2,
      "z": -4,
      "name": "Rock_Quartzite"
    },
    {
      "x": -28,
      "y": 3,
      "z": -4,
      "name": "Rock_Quartzite"
    },
    {
      "x": -28,
      "y": 4,
      "z": -4,
      "name": "Rock_Quartzite"
    },
    {
      "x": -28,
      "y": 5,
      "z": -4,
      "name": "Rock_Quartzite_Cobble"
    },
    {
      "x": -28,
      "y": 6,
      "z": -4,
      "name": "Rock_Quartzite_Cobble"
    },
    {
      "x": -28,
      "y": 7,
      "z": -4,
      "name": "Rock_Quartzite_Cobble"
    },
    {
      "x": -28,
      "y": 8,
      "z": -4,
      "name": "Rock_Quartzite_Cobble_Stairs",
      "rotation": 3
    },
    {
      "x": -28,
      "y": 9,
      "z": -4,
      "name": "Rock_Quartzite_Cobble"
    },
    {
      "x": -28,
      "y": 10,
      "z": -4,
      "name": "Soil_Grass"
    },
    {
      "x": -28,
      "y": 11,
      "z": -4,
      "name": "Plant_Grass_Sharp"
    },
    {
      "x": -28,
      "y": 0,
      "z": -3,
      "name": "Rock_Quartzite"
    },
    {
      "x": -28,
      "y": 1,
      "z": -3,
      "name": "Rock_Quartzite"
    },
    {
      "x": -28,
      "y": 2,
      "z": -3,
      "name": "Rock_Quartzite"
    },
    {
      "x": -28,
      "y": 3,
      "z": -3,
      "name": "Rock_Quartzite"
    },
    {
      "x": -28,
      "y": 4,
      "z": -3,
      "name": "Rock_Quartzite"
    },
    {
      "x": -28,
      "y": 5,
      "z": -3,
      "name": "Rock_Quartzite_Cobble"
    },
    {
      "x": -28,
      "y": 6,
      "z": -3,
      "name": "Rock_Quartzite_Cobble"
    },
    {
      "x": -28,
      "y": 7,
      "z": -3,
      "name": "Rock_Quartzite_Cobble"
    },
    {
      "x": -28,
      "y": 8,
      "z": -3,
      "name": "Rock_Quartzite_Cobble_Stairs",
      "rotation": 3
    },
    {
      "x": -28,
      "y": 9,
      "z": -3,
      "name": "Rock_Quartzite_Cobble_Half",
      "rotation": 7
    },
    {
      "x": -28,
      "y": 4,
      "z": -2,
      "name": "Rock_Quartzite"
    },
    {
      "x": -28,
      "y": 5,
      "z": -2,
      "name": "Rock_Quartzite"
    },
    {
      "x": -28,
      "y": 6,
      "z": -2,
      "name": "Rock_Quartzite"
    },
    {
      "x": -28,
      "y": 7,
      "z": -2,
      "name": "Rock_Quartzite_Cobble"
    },
    {
      "x": -28,
      "y": 8,
      "z": -2,
      "name": "Rock_Quartzite_Cobble"
    },
    {
      "x": -28,
      "y": 9,
      "z": -2,
      "name": "Rock_Quartzite"
    },
    {
      "x": -28,
      "y": 10,
      "z": -2,
      "name": "Rock_Quartzite"
    },
    {
      "x": -28,
      "y": 11,
      "z": -2,
      "name": "Rock_Quartzite_Cobble_Beam"
    },
    {
      "x": -28,
      "y": 12,
      "z": -2,
      "name": "Rock_Quartzite_Cobble_Beam"
    },
    {
      "x": -28,
      "y": 1,
      "z": 13,
      "name": "Rock_Quartzite"
    },
    {
      "x": -28,
      "y": 2,
      "z": 13,
      "name": "Rock_Quartzite"
    },
    {
      "x": -28,
      "y": 3,
      "z": 13,
      "name": "Rock_Quartzite"
    },
    {
      "x": -28,
      "y": 4,
      "z": 13,
      "name": "Rock_Quartzite"
    },
    {
      "x": -28,
      "y": 5,
      "z": 13,
      "name": "Rock_Quartzite"
    },
    {
      "x": -28,
      "y": 6,
      "z": 13,
      "name": "Rock_Quartzite"
    },
    {
      "x": -28,
      "y": 7,
      "z": 13,
      "name": "Rock_Quartzite"
    },
    {
      "x": -28,
      "y": 2,
      "z": 14,
      "name": "Rock_Quartzite"
    },
    {
      "x": -28,
      "y": 3,
      "z": 14,
      "name": "Rock_Quartzite"
    },
    {
      "x": -28,
      "y": 4,
      "z": 14,
      "name": "Rock_Quartzite"
    },
    {
      "x": -28,
      "y": 5,
      "z": 14,
      "name": "Rock_Quartzite_Cobble"
    },
    {
      "x": -28,
      "y": 6,
      "z": 14,
      "name": "Rock_Quartzite_Cobble"
    },
    {
      "x": -28,
      "y": 7,
      "z": 14,
      "name": "Rock_Quartzite_Cobble"
    },
    {
      "x": -28,
      "y": 8,
      "z": 14,
      "name": "Rock_Quartzite_Cobble_Half",
      "rotation": 7
    },
    {
      "x": -27,
      "y": 3,
      "z": -19,
      "name": "Rock_Quartzite"
    },
    {
      "x": -27,
      "y": 4,
      "z": -19,
      "name": "Rock_Quartzite"
    },
    {
      "x": -27,
      "y": 5,
      "z": -19,
      "name": "Rock_Quartzite"
    },
    {
      "x": -27,
      "y": 6,
      "z": -19,
      "name": "Rock_Quartzite"
    },
    {
      "x": -27,
      "y": 0,
      "z": -18,
      "name": "Rock_Quartzite"
    },
    {
      "x": -27,
      "y": 1,
      "z": -18,
      "name": "Rock_Quartzite"
    },
    {
      "x": -27,
      "y": 2,
      "z": -18,
      "name": "Rock_Quartzite"
    },
    {
      "x": -27,
      "y": 3,
      "z": -18,
      "name": "Rock_Quartzite"
    },
    {
      "x": -27,
      "y": 4,
      "z": -18,
      "name": "Rock_Quartzite"
    },
    {
      "x": -27,
      "y": 5,
      "z": -18,
      "name": "Rock_Quartzite"
    },
    {
      "x": -27,
      "y": 6,
      "z": -18,
      "name": "Rock_Quartzite"
    },
    {
      "x": -27,
      "y": 7,
      "z": -18,
      "name": "Rock_Quartzite_Brick"
    },
    {
      "x": -27,
      "y": 8,
      "z": -18,
      "name": "Rock_Quartzite"
    },
    {
      "x": -27,
      "y": 9,
      "z": -18,
      "name": "Rock_Quartzite_Cobble"
    },
    {
      "x": -27,
      "y": 10,
      "z": -18,
      "name": "Rock_Quartzite_Cobble"
    },
    {
      "x": -27,
      "y": 11,
      "z": -18,
      "name": "Soil_Dirt"
    },
    {
      "x": -27,
      "y": 12,
      "z": -18,
      "name": "Soil_Grass"
    },
    {
      "x": -27,
      "y": 13,
      "z": -18,
      "name": "Plant_Moss_Rug_Green"
    },
    {
      "x": -27,
      "y": 0,
      "z": -17,
      "name": "Rock_Quartzite"
    },
    {
      "x": -27,
      "y": 1,
      "z": -17,
      "name": "Rock_Quartzite"
    },
    {
      "x": -27,
      "y": 2,
      "z": -17,
      "name": "Rock_Quartzite"
    },
    {
      "x": -27,
      "y": 3,
      "z": -17,
      "name": "Rock_Quartzite"
    },
    {
      "x": -27,
      "y": 4,
      "z": -17,
      "name": "Rock_Quartzite"
    },
    {
      "x": -27,
      "y": 5,
      "z": -17,
      "name": "Rock_Quartzite"
    },
    {
      "x": -27,
      "y": 6,
      "z": -17,
      "name": "Rock_Quartzite"
    },
    {
      "x": -27,
      "y": 7,
      "z": -17,
      "name": "Rock_Quartzite_Brick"
    },
    {
      "x": -27,
      "y": 8,
      "z": -17,
      "name": "Rock_Quartzite"
    },
    {
      "x": -27,
      "y": 9,
      "z": -17,
      "name": "Rock_Quartzite"
    },
    {
      "x": -27,
      "y": 10,
      "z": -17,
      "name": "Rock_Quartzite"
    },
    {
      "x": -27,
      "y": 11,
      "z": -17,
      "name": "Rock_Quartzite"
    },
    {
      "x": -27,
      "y": 12,
      "z": -17,
      "name": "Soil_Grass"
    },
    {
      "x": -27,
      "y": 13,
      "z": -17,
      "name": "Plant_Fern_Winter"
    },
    {
      "x": -27,
      "y": 0,
      "z": -16,
      "name": "Rock_Quartzite"
    },
    {
      "x": -27,
      "y": 1,
      "z": -16,
      "name": "Rock_Quartzite"
    },
    {
      "x": -27,
      "y": 2,
      "z": -16,
      "name": "Rock_Quartzite"
    },
    {
      "x": -27,
      "y": 3,
      "z": -16,
      "name": "Rock_Quartzite"
    },
    {
      "x": -27,
      "y": 4,
      "z": -16,
      "name": "Rock_Quartzite"
    },
    {
      "x": -27,
      "y": 5,
      "z": -16,
      "name": "Rock_Quartzite"
    },
    {
      "x": -27,
      "y": 6,
      "z": -16,
      "name": "Rock_Quartzite"
    },
    {
      "x": -27,
      "y": 7,
      "z": -16,
      "name": "Rock_Quartzite_Brick"
    },
    {
      "x": -27,
      "y": 8,
      "z": -16,
      "name": "Rock_Quartzite"
    },
    {
      "x": -27,
      "y": 9,
      "z": -16,
      "name": "Rock_Quartzite"
    },
    {
      "x": -27,
      "y": 10,
      "z": -16,
      "name": "Rock_Quartzite"
    },
    {
      "x": -27,
      "y": 11,
      "z": -16,
      "name": "Rock_Quartzite"
    },
    {
      "x": -27,
      "y": 12,
      "z": -16,
      "name": "Soil_Grass"
    },
    {
      "x": -27,
      "y": 0,
      "z": -15,
      "name": "Rock_Quartzite"
    },
    {
      "x": -27,
      "y": 1,
      "z": -15,
      "name": "Rock_Quartzite"
    },
    {
      "x": -27,
      "y": 2,
      "z": -15,
      "name": "Rock_Quartzite"
    },
    {
      "x": -27,
      "y": 3,
      "z": -15,
      "name": "Rock_Quartzite"
    },
    {
      "x": -27,
      "y": 4,
      "z": -15,
      "name": "Rock_Quartzite"
    },
    {
      "x": -27,
      "y": 5,
      "z": -15,
      "name": "Rock_Quartzite"
    },
    {
      "x": -27,
      "y": 6,
      "z": -15,
      "name": "Rock_Quartzite"
    },
    {
      "x": -27,
      "y": 7,
      "z": -15,
      "name": "Rock_Quartzite_Brick"
    },
    {
      "x": -27,
      "y": 8,
      "z": -15,
      "name": "Rock_Quartzite"
    },
    {
      "x": -27,
      "y": 9,
      "z": -15,
      "name": "Rock_Quartzite"
    },
    {
      "x": -27,
      "y": 10,
      "z": -15,
      "name": "Rock_Quartzite"
    },
    {
      "x": -27,
      "y": 11,
      "z": -15,
      "name": "Rock_Quartzite"
    },
    {
      "x": -27,
      "y": 12,
      "z": -15,
      "name": "Soil_Grass"
    },
    {
      "x": -27,
      "y": 0,
      "z": -14,
      "name": "Rock_Quartzite"
    },
    {
      "x": -27,
      "y": 1,
      "z": -14,
      "name": "Rock_Quartzite"
    },
    {
      "x": -27,
      "y": 2,
      "z": -14,
      "name": "Rock_Quartzite"
    },
    {
      "x": -27,
      "y": 3,
      "z": -14,
      "name": "Rock_Quartzite"
    },
    {
      "x": -27,
      "y": 4,
      "z": -14,
      "name": "Rock_Quartzite"
    },
    {
      "x": -27,
      "y": 5,
      "z": -14,
      "name": "Rock_Quartzite"
    },
    {
      "x": -27,
      "y": 6,
      "z": -14,
      "name": "Rock_Quartzite"
    },
    {
      "x": -27,
      "y": 7,
      "z": -14,
      "name": "Rock_Quartzite_Brick"
    },
    {
      "x": -27,
      "y": 8,
      "z": -14,
      "name": "Rock_Quartzite"
    },
    {
      "x": -27,
      "y": 9,
      "z": -14,
      "name": "Rock_Quartzite"
    },
    {
      "x": -27,
      "y": 10,
      "z": -14,
      "name": "Rock_Quartzite"
    },
    {
      "x": -27,
      "y": 11,
      "z": -14,
      "name": "Rock_Quartzite"
    },
    {
      "x": -27,
      "y": 12,
      "z": -14,
      "name": "Soil_Grass"
    },
    {
      "x": -27,
      "y": 0,
      "z": -13,
      "name": "Rock_Quartzite"
    },
    {
      "x": -27,
      "y": 1,
      "z": -13,
      "name": "Rock_Quartzite"
    },
    {
      "x": -27,
      "y": 2,
      "z": -13,
      "name": "Rock_Quartzite"
    },
    {
      "x": -27,
      "y": 3,
      "z": -13,
      "name": "Rock_Quartzite"
    },
    {
      "x": -27,
      "y": 4,
      "z": -13,
      "name": "Rock_Quartzite"
    },
    {
      "x": -27,
      "y": 5,
      "z": -13,
      "name": "Rock_Quartzite"
    },
    {
      "x": -27,
      "y": 7,
      "z": -13,
      "name": "Empty"
    },
    {
      "x": -27,
      "y": 8,
      "z": -13,
      "name": "Empty"
    },
    {
      "x": -27,
      "y": 9,
      "z": -13,
      "name": "Rock_Quartzite_Brick_Half",
      "rotation": 8
    },
    {
      "x": -27,
      "y": 10,
      "z": -13,
      "name": "Rock_Quartzite"
    },
    {
      "x": -27,
      "y": 11,
      "z": -13,
      "name": "Soil_Grass"
    },
    {
      "x": -27,
      "y": 12,
      "z": -13,
      "name": "Plant_Grass_Sharp"
    },
    {
      "x": -27,
      "y": 0,
      "z": -12,
      "name": "Rock_Quartzite"
    },
    {
      "x": -27,
      "y": 1,
      "z": -12,
      "name": "Rock_Quartzite"
    },
    {
      "x": -27,
      "y": 2,
      "z": -12,
      "name": "Rock_Quartzite"
    },
    {
      "x": -27,
      "y": 3,
      "z": -12,
      "name": "Rock_Quartzite"
    },
    {
      "x": -27,
      "y": 4,
      "z": -12,
      "name": "Rock_Quartzite"
    },
    {
      "x": -27,
      "y": 5,
      "z": -12,
      "name": "Rock_Quartzite_Cobble"
    },
    {
      "x": -27,
      "y": 7,
      "z": -12,
      "name": "Empty"
    },
    {
      "x": -27,
      "y": 8,
      "z": -12,
      "name": "Empty"
    },
    {
      "x": -27,
      "y": 9,
      "z": -12,
      "name": "Rock_Quartzite_Brick_Stairs",
      "rotation": 8
    },
    {
      "x": -27,
      "y": 10,
      "z": -12,
      "name": "Soil_Dirt"
    },
    {
      "x": -27,
      "y": 11,
      "z": -12,
      "name": "Soil_Grass"
    },
    {
      "x": -27,
      "y": 12,
      "z": -12,
      "name": "Plant_Grass_Lush"
    },
    {
      "x": -27,
      "y": 0,
      "z": -11,
      "name": "Rock_Quartzite"
    },
    {
      "x": -27,
      "y": 1,
      "z": -11,
      "name": "Rock_Quartzite"
    },
    {
      "x": -27,
      "y": 2,
      "z": -11,
      "name": "Rock_Quartzite"
    },
    {
      "x": -27,
      "y": 3,
      "z": -11,
      "name": "Rock_Quartzite"
    },
    {
      "x": -27,
      "y": 4,
      "z": -11,
      "name": "Rock_Quartzite"
    },
    {
      "x": -27,
      "y": 5,
      "z": -11,
      "name": "Rock_Quartzite"
    },
    {
      "x": -27,
      "y": 6,
      "z": -11,
      "name": "Rock_Quartzite"
    },
    {
      "x": -27,
      "y": 7,
      "z": -11,
      "name": "Rock_Quartzite_Brick"
    },
    {
      "x": -27,
      "y": 8,
      "z": -11,
      "name": "Rock_Quartzite"
    },
    {
      "x": -27,
      "y": 9,
      "z": -11,
      "name": "Rock_Quartzite"
    },
    {
      "x": -27,
      "y": 10,
      "z": -11,
      "name": "Rock_Quartzite"
    },
    {
      "x": -27,
      "y": 11,
      "z": -11,
      "name": "Soil_Grass"
    },
    {
      "x": -27,
      "y": 0,
      "z": -10,
      "name": "Rock_Quartzite"
    },
    {
      "x": -27,
      "y": 1,
      "z": -10,
      "name": "Rock_Quartzite"
    },
    {
      "x": -27,
      "y": 2,
      "z": -10,
      "name": "Rock_Quartzite"
    },
    {
      "x": -27,
      "y": 3,
      "z": -10,
      "name": "Rock_Quartzite"
    },
    {
      "x": -27,
      "y": 4,
      "z": -10,
      "name": "Rock_Quartzite"
    },
    {
      "x": -27,
      "y": 5,
      "z": -10,
      "name": "Rock_Quartzite"
    },
    {
      "x": -27,
      "y": 6,
      "z": -10,
      "name": "Rock_Quartzite"
    },
    {
      "x": -27,
      "y": 7,
      "z": -10,
      "name": "Rock_Quartzite_Cobble"
    },
    {
      "x": -27,
      "y": 8,
      "z": -10,
      "name": "Rock_Quartzite_Cobble"
    },
    {
      "x": -27,
      "y": 9,
      "z": -10,
      "name": "Rock_Quartzite"
    },
    {
      "x": -27,
      "y": 10,
      "z": -10,
      "name": "Rock_Quartzite"
    },
    {
      "x": -27,
      "y": 11,
      "z": -10,
      "name": "Rock_Quartzite"
    },
    {
      "x": -27,
      "y": 12,
      "z": -10,
      "name": "Soil_Grass"
    },
    {
      "x": -27,
      "y": 0,
      "z": -9,
      "name": "Rock_Quartzite"
    },
    {
      "x": -27,
      "y": 1,
      "z": -9,
      "name": "Rock_Quartzite"
    },
    {
      "x": -27,
      "y": 2,
      "z": -9,
      "name": "Rock_Quartzite"
    },
    {
      "x": -27,
      "y": 3,
      "z": -9,
      "name": "Rock_Quartzite"
    },
    {
      "x": -27,
      "y": 4,
      "z": -9,
      "name": "Rock_Quartzite"
    },
    {
      "x": -27,
      "y": 5,
      "z": -9,
      "name": "Rock_Quartzite"
    },
    {
      "x": -27,
      "y": 6,
      "z": -9,
      "name": "Rock_Quartzite"
    },
    {
      "x": -27,
      "y": 7,
      "z": -9,
      "name": "Rock_Quartzite"
    },
    {
      "x": -27,
      "y": 8,
      "z": -9,
      "name": "Rock_Quartzite"
    },
    {
      "x": -27,
      "y": 9,
      "z": -9,
      "name": "Rock_Quartzite"
    },
    {
      "x": -27,
      "y": 10,
      "z": -9,
      "name": "Rock_Quartzite"
    },
    {
      "x": -27,
      "y": 11,
      "z": -9,
      "name": "Rock_Quartzite"
    },
    {
      "x": -27,
      "y": 12,
      "z": -9,
      "name": "Soil_Grass"
    },
    {
      "x": -27,
      "y": 13,
      "z": -9,
      "name": "Plant_Grass_Lush"
    },
    {
      "x": -27,
      "y": 0,
      "z": -8,
      "name": "Rock_Quartzite"
    },
    {
      "x": -27,
      "y": 1,
      "z": -8,
      "name": "Rock_Quartzite"
    },
    {
      "x": -27,
      "y": 2,
      "z": -8,
      "name": "Rock_Quartzite"
    },
    {
      "x": -27,
      "y": 3,
      "z": -8,
      "name": "Rock_Quartzite"
    },
    {
      "x": -27,
      "y": 4,
      "z": -8,
      "name": "Rock_Quartzite"
    },
    {
      "x": -27,
      "y": 5,
      "z": -8,
      "name": "Rock_Quartzite"
    },
    {
      "x": -27,
      "y": 6,
      "z": -8,
      "name": "Rock_Quartzite"
    },
    {
      "x": -27,
      "y": 7,
      "z": -8,
      "name": "Rock_Quartzite"
    },
    {
      "x": -27,
      "y": 8,
      "z": -8,
      "name": "Rock_Quartzite"
    },
    {
      "x": -27,
      "y": 9,
      "z": -8,
      "name": "Rock_Quartzite"
    },
    {
      "x": -27,
      "y": 10,
      "z": -8,
      "name": "Rock_Quartzite"
    },
    {
      "x": -27,
      "y": 11,
      "z": -8,
      "name": "Rock_Quartzite"
    },
    {
      "x": -27,
      "y": 12,
      "z": -8,
      "name": "Soil_Grass"
    },
    {
      "x": -27,
      "y": 0,
      "z": -7,
      "name": "Rock_Quartzite"
    },
    {
      "x": -27,
      "y": 1,
      "z": -7,
      "name": "Rock_Quartzite"
    },
    {
      "x": -27,
      "y": 2,
      "z": -7,
      "name": "Rock_Quartzite"
    },
    {
      "x": -27,
      "y": 3,
      "z": -7,
      "name": "Rock_Quartzite"
    },
    {
      "x": -27,
      "y": 4,
      "z": -7,
      "name": "Rock_Quartzite"
    },
    {
      "x": -27,
      "y": 5,
      "z": -7,
      "name": "Rock_Quartzite"
    },
    {
      "x": -27,
      "y": 6,
      "z": -7,
      "name": "Rock_Quartzite"
    },
    {
      "x": -27,
      "y": 7,
      "z": -7,
      "name": "Rock_Quartzite"
    },
    {
      "x": -27,
      "y": 8,
      "z": -7,
      "name": "Rock_Quartzite"
    },
    {
      "x": -27,
      "y": 9,
      "z": -7,
      "name": "Rock_Quartzite"
    },
    {
      "x": -27,
      "y": 10,
      "z": -7,
      "name": "Rock_Quartzite"
    },
    {
      "x": -27,
      "y": 11,
      "z": -7,
      "name": "Rock_Quartzite"
    },
    {
      "x": -27,
      "y": 12,
      "z": -7,
      "name": "Soil_Grass"
    },
    {
      "x": -27,
      "y": 0,
      "z": -6,
      "name": "Rock_Quartzite"
    },
    {
      "x": -27,
      "y": 1,
      "z": -6,
      "name": "Rock_Quartzite"
    },
    {
      "x": -27,
      "y": 2,
      "z": -6,
      "name": "Rock_Quartzite"
    },
    {
      "x": -27,
      "y": 3,
      "z": -6,
      "name": "Rock_Quartzite"
    },
    {
      "x": -27,
      "y": 4,
      "z": -6,
      "name": "Rock_Quartzite"
    },
    {
      "x": -27,
      "y": 5,
      "z": -6,
      "name": "Rock_Quartzite"
    },
    {
      "x": -27,
      "y": 6,
      "z": -6,
      "name": "Rock_Quartzite"
    },
    {
      "x": -27,
      "y": 7,
      "z": -6,
      "name": "Rock_Quartzite"
    },
    {
      "x": -27,
      "y": 8,
      "z": -6,
      "name": "Rock_Quartzite"
    },
    {
      "x": -27,
      "y": 9,
      "z": -6,
      "name": "Rock_Quartzite"
    },
    {
      "x": -27,
      "y": 10,
      "z": -6,
      "name": "Rock_Quartzite"
    },
    {
      "x": -27,
      "y": 11,
      "z": -6,
      "name": "Rock_Quartzite"
    },
    {
      "x": -27,
      "y": 12,
      "z": -6,
      "name": "Soil_Grass"
    },
    {
      "x": -27,
      "y": 0,
      "z": -5,
      "name": "Rock_Quartzite"
    },
    {
      "x": -27,
      "y": 1,
      "z": -5,
      "name": "Rock_Quartzite"
    },
    {
      "x": -27,
      "y": 2,
      "z": -5,
      "name": "Rock_Quartzite"
    },
    {
      "x": -27,
      "y": 3,
      "z": -5,
      "name": "Rock_Quartzite"
    },
    {
      "x": -27,
      "y": 4,
      "z": -5,
      "name": "Rock_Quartzite"
    },
    {
      "x": -27,
      "y": 5,
      "z": -5,
      "name": "Rock_Quartzite"
    },
    {
      "x": -27,
      "y": 6,
      "z": -5,
      "name": "Rock_Quartzite"
    },
    {
      "x": -27,
      "y": 7,
      "z": -5,
      "name": "Rock_Quartzite"
    },
    {
      "x": -27,
      "y": 8,
      "z": -5,
      "name": "Rock_Quartzite"
    },
    {
      "x": -27,
      "y": 9,
      "z": -5,
      "name": "Rock_Quartzite"
    },
    {
      "x": -27,
      "y": 10,
      "z": -5,
      "name": "Rock_Quartzite"
    },
    {
      "x": -27,
      "y": 11,
      "z": -5,
      "name": "Soil_Dirt"
    },
    {
      "x": -27,
      "y": 12,
      "z": -5,
      "name": "Soil_Grass"
    },
    {
      "x": -27,
      "y": 0,
      "z": -4,
      "name": "Rock_Quartzite"
    },
    {
      "x": -27,
      "y": 1,
      "z": -4,
      "name": "Rock_Quartzite"
    },
    {
      "x": -27,
      "y": 2,
      "z": -4,
      "name": "Rock_Quartzite"
    },
    {
      "x": -27,
      "y": 3,
      "z": -4,
      "name": "Rock_Quartzite"
    },
    {
      "x": -27,
      "y": 4,
      "z": -4,
      "name": "Rock_Quartzite"
    },
    {
      "x": -27,
      "y": 5,
      "z": -4,
      "name": "Rock_Quartzite"
    },
    {
      "x": -27,
      "y": 6,
      "z": -4,
      "name": "Rock_Quartzite"
    },
    {
      "x": -27,
      "y": 7,
      "z": -4,
      "name": "Rock_Quartzite"
    },
    {
      "x": -27,
      "y": 8,
      "z": -4,
      "name": "Rock_Quartzite"
    },
    {
      "x": -27,
      "y": 9,
      "z": -4,
      "name": "Rock_Quartzite"
    },
    {
      "x": -27,
      "y": 10,
      "z": -4,
      "name": "Rock_Quartzite"
    },
    {
      "x": -27,
      "y": 11,
      "z": -4,
      "name": "Soil_Dirt"
    },
    {
      "x": -27,
      "y": 12,
      "z": -4,
      "name": "Soil_Grass"
    },
    {
      "x": -27,
      "y": 13,
      "z": -4,
      "name": "Plant_Grass_Lush"
    },
    {
      "x": -27,
      "y": 0,
      "z": -3,
      "name": "Rock_Quartzite"
    },
    {
      "x": -27,
      "y": 1,
      "z": -3,
      "name": "Rock_Quartzite"
    },
    {
      "x": -27,
      "y": 2,
      "z": -3,
      "name": "Rock_Quartzite"
    },
    {
      "x": -27,
      "y": 3,
      "z": -3,
      "name": "Rock_Quartzite"
    },
    {
      "x": -27,
      "y": 4,
      "z": -3,
      "name": "Rock_Quartzite"
    },
    {
      "x": -27,
      "y": 5,
      "z": -3,
      "name": "Rock_Quartzite"
    },
    {
      "x": -27,
      "y": 6,
      "z": -3,
      "name": "Rock_Quartzite"
    },
    {
      "x": -27,
      "y": 7,
      "z": -3,
      "name": "Rock_Quartzite"
    },
    {
      "x": -27,
      "y": 8,
      "z": -3,
      "name": "Rock_Quartzite"
    },
    {
      "x": -27,
      "y": 9,
      "z": -3,
      "name": "Rock_Quartzite"
    },
    {
      "x": -27,
      "y": 10,
      "z": -3,
      "name": "Rock_Quartzite"
    },
    {
      "x": -27,
      "y": 11,
      "z": -3,
      "name": "Soil_Dirt"
    },
    {
      "x": -27,
      "y": 12,
      "z": -3,
      "name": "Soil_Grass"
    },
    {
      "x": -27,
      "y": 2,
      "z": -2,
      "name": "Rock_Quartzite"
    },
    {
      "x": -27,
      "y": 3,
      "z": -2,
      "name": "Rock_Quartzite"
    },
    {
      "x": -27,
      "y": 4,
      "z": -2,
      "name": "Rock_Quartzite"
    },
    {
      "x": -27,
      "y": 5,
      "z": -2,
      "name": "Rock_Quartzite"
    },
    {
      "x": -27,
      "y": 6,
      "z": -2,
      "name": "Rock_Quartzite"
    },
    {
      "x": -27,
      "y": 7,
      "z": -2,
      "name": "Rock_Quartzite"
    },
    {
      "x": -27,
      "y": 8,
      "z": -2,
      "name": "Rock_Quartzite"
    },
    {
      "x": -27,
      "y": 9,
      "z": -2,
      "name": "Rock_Quartzite"
    },
    {
      "x": -27,
      "y": 10,
      "z": -2,
      "name": "Rock_Quartzite"
    },
    {
      "x": -27,
      "y": 11,
      "z": -2,
      "name": "Soil_Grass"
    },
    {
      "x": -27,
      "y": 3,
      "z": -1,
      "name": "Rock_Quartzite"
    },
    {
      "x": -27,
      "y": 4,
      "z": -1,
      "name": "Rock_Quartzite"
    },
    {
      "x": -27,
      "y": 5,
      "z": -1,
      "name": "Rock_Quartzite"
    },
    {
      "x": -27,
      "y": 6,
      "z": -1,
      "name": "Rock_Quartzite"
    },
    {
      "x": -27,
      "y": 7,
      "z": -1,
      "name": "Rock_Quartzite"
    },
    {
      "x": -27,
      "y": 8,
      "z": -1,
      "name": "Rock_Quartzite"
    },
    {
      "x": -27,
      "y": 9,
      "z": -1,
      "name": "Rock_Quartzite"
    },
    {
      "x": -27,
      "y": 10,
      "z": -1,
      "name": "Rock_Quartzite"
    },
    {
      "x": -27,
      "y": 4,
      "z": 0,
      "name": "Rock_Quartzite"
    },
    {
      "x": -27,
      "y": 5,
      "z": 0,
      "name": "Rock_Quartzite"
    },
    {
      "x": -27,
      "y": 6,
      "z": 0,
      "name": "Rock_Quartzite"
    },
    {
      "x": -27,
      "y": 7,
      "z": 0,
      "name": "Rock_Quartzite"
    },
    {
      "x": -27,
      "y": 8,
      "z": 0,
      "name": "Rock_Quartzite"
    },
    {
      "x": -27,
      "y": 5,
      "z": 1,
      "name": "Rock_Quartzite"
    },
    {
      "x": -27,
      "y": 6,
      "z": 1,
      "name": "Rock_Quartzite"
    },
    {
      "x": -27,
      "y": 7,
      "z": 1,
      "name": "Rock_Quartzite"
    },
    {
      "x": -27,
      "y": 1,
      "z": 13,
      "name": "Rock_Quartzite"
    },
    {
      "x": -27,
      "y": 2,
      "z": 13,
      "name": "Rock_Quartzite"
    },
    {
      "x": -27,
      "y": 3,
      "z": 13,
      "name": "Rock_Quartzite"
    },
    {
      "x": -27,
      "y": 4,
      "z": 13,
      "name": "Rock_Quartzite"
    },
    {
      "x": -27,
      "y": 5,
      "z": 13,
      "name": "Rock_Quartzite_Cobble"
    },
    {
      "x": -27,
      "y": 6,
      "z": 13,
      "name": "Rock_Quartzite"
    },
    {
      "x": -27,
      "y": 7,
      "z": 13,
      "name": "Rock_Quartzite"
    },
    {
      "x": -27,
      "y": 8,
      "z": 13,
      "name": "Rock_Quartzite"
    },
    {
      "x": -27,
      "y": 1,
      "z": 14,
      "name": "Rock_Quartzite"
    },
    {
      "x": -27,
      "y": 2,
      "z": 14,
      "name": "Rock_Quartzite"
    },
    {
      "x": -27,
      "y": 3,
      "z": 14,
      "name": "Rock_Quartzite"
    },
    {
      "x": -27,
      "y": 4,
      "z": 14,
      "name": "Rock_Quartzite"
    },
    {
      "x": -27,
      "y": 5,
      "z": 14,
      "name": "Rock_Quartzite_Cobble"
    },
    {
      "x": -27,
      "y": 6,
      "z": 14,
      "name": "Rock_Quartzite_Cobble"
    },
    {
      "x": -27,
      "y": 7,
      "z": 14,
      "name": "Rock_Quartzite_Cobble"
    },
    {
      "x": -27,
      "y": 8,
      "z": 14,
      "name": "Rock_Quartzite_Cobble"
    },
    {
      "x": -26,
      "y": 1,
      "z": -19,
      "name": "Rock_Quartzite"
    },
    {
      "x": -26,
      "y": 2,
      "z": -19,
      "name": "Rock_Quartzite"
    },
    {
      "x": -26,
      "y": 3,
      "z": -19,
      "name": "Rock_Quartzite"
    },
    {
      "x": -26,
      "y": 4,
      "z": -19,
      "name": "Rock_Quartzite"
    },
    {
      "x": -26,
      "y": 5,
      "z": -19,
      "name": "Rock_Quartzite"
    },
    {
      "x": -26,
      "y": 6,
      "z": -19,
      "name": "Rock_Quartzite"
    },
    {
      "x": -26,
      "y": 0,
      "z": -18,
      "name": "Rock_Quartzite"
    },
    {
      "x": -26,
      "y": 1,
      "z": -18,
      "name": "Rock_Quartzite"
    },
    {
      "x": -26,
      "y": 2,
      "z": -18,
      "name": "Rock_Quartzite"
    },
    {
      "x": -26,
      "y": 3,
      "z": -18,
      "name": "Rock_Quartzite"
    },
    {
      "x": -26,
      "y": 4,
      "z": -18,
      "name": "Rock_Quartzite"
    },
    {
      "x": -26,
      "y": 5,
      "z": -18,
      "name": "Rock_Quartzite"
    },
    {
      "x": -26,
      "y": 6,
      "z": -18,
      "name": "Rock_Quartzite"
    },
    {
      "x": -26,
      "y": 7,
      "z": -18,
      "name": "Rock_Quartzite_Brick"
    },
    {
      "x": -26,
      "y": 8,
      "z": -18,
      "name": "Rock_Quartzite"
    },
    {
      "x": -26,
      "y": 10,
      "z": -18,
      "name": "Rock_Quartzite_Cobble_Half",
      "rotation": 6
    },
    {
      "x": -26,
      "y": 11,
      "z": -18,
      "name": "Soil_Dirt"
    },
    {
      "x": -26,
      "y": 12,
      "z": -18,
      "name": "Soil_Grass"
    },
    {
      "x": -26,
      "y": 13,
      "z": -18,
      "name": "Plant_Fern_Winter"
    },
    {
      "x": -26,
      "y": 0,
      "z": -17,
      "name": "Rock_Quartzite"
    },
    {
      "x": -26,
      "y": 1,
      "z": -17,
      "name": "Rock_Quartzite"
    },
    {
      "x": -26,
      "y": 2,
      "z": -17,
      "name": "Rock_Quartzite"
    },
    {
      "x": -26,
      "y": 3,
      "z": -17,
      "name": "Rock_Quartzite"
    },
    {
      "x": -26,
      "y": 4,
      "z": -17,
      "name": "Rock_Quartzite"
    },
    {
      "x": -26,
      "y": 5,
      "z": -17,
      "name": "Rock_Quartzite"
    },
    {
      "x": -26,
      "y": 6,
      "z": -17,
      "name": "Rock_Quartzite"
    },
    {
      "x": -26,
      "y": 7,
      "z": -17,
      "name": "Rock_Quartzite_Brick"
    },
    {
      "x": -26,
      "y": 8,
      "z": -17,
      "name": "Rock_Quartzite"
    },
    {
      "x": -26,
      "y": 9,
      "z": -17,
      "name": "Rock_Quartzite"
    },
    {
      "x": -26,
      "y": 10,
      "z": -17,
      "name": "Rock_Quartzite"
    },
    {
      "x": -26,
      "y": 11,
      "z": -17,
      "name": "Rock_Quartzite"
    },
    {
      "x": -26,
      "y": 12,
      "z": -17,
      "name": "Soil_Grass"
    },
    {
      "x": -26,
      "y": 13,
      "z": -17,
      "name": "Plant_Grass_Sharp"
    },
    {
      "x": -26,
      "y": 0,
      "z": -16,
      "name": "Rock_Quartzite"
    },
    {
      "x": -26,
      "y": 1,
      "z": -16,
      "name": "Rock_Quartzite"
    },
    {
      "x": -26,
      "y": 2,
      "z": -16,
      "name": "Rock_Quartzite"
    },
    {
      "x": -26,
      "y": 3,
      "z": -16,
      "name": "Rock_Quartzite"
    },
    {
      "x": -26,
      "y": 4,
      "z": -16,
      "name": "Rock_Quartzite"
    },
    {
      "x": -26,
      "y": 5,
      "z": -16,
      "name": "Rock_Quartzite"
    },
    {
      "x": -26,
      "y": 6,
      "z": -16,
      "name": "Rock_Quartzite"
    },
    {
      "x": -26,
      "y": 7,
      "z": -16,
      "name": "Rock_Quartzite_Brick"
    },
    {
      "x": -26,
      "y": 8,
      "z": -16,
      "name": "Rock_Quartzite"
    },
    {
      "x": -26,
      "y": 9,
      "z": -16,
      "name": "Rock_Quartzite"
    },
    {
      "x": -26,
      "y": 10,
      "z": -16,
      "name": "Rock_Quartzite"
    },
    {
      "x": -26,
      "y": 11,
      "z": -16,
      "name": "Rock_Quartzite"
    },
    {
      "x": -26,
      "y": 12,
      "z": -16,
      "name": "Soil_Grass"
    },
    {
      "x": -26,
      "y": 0,
      "z": -15,
      "name": "Rock_Quartzite"
    },
    {
      "x": -26,
      "y": 1,
      "z": -15,
      "name": "Rock_Quartzite"
    },
    {
      "x": -26,
      "y": 2,
      "z": -15,
      "name": "Rock_Quartzite"
    },
    {
      "x": -26,
      "y": 3,
      "z": -15,
      "name": "Rock_Quartzite"
    },
    {
      "x": -26,
      "y": 4,
      "z": -15,
      "name": "Rock_Quartzite"
    },
    {
      "x": -26,
      "y": 5,
      "z": -15,
      "name": "Rock_Quartzite"
    },
    {
      "x": -26,
      "y": 6,
      "z": -15,
      "name": "Rock_Quartzite"
    },
    {
      "x": -26,
      "y": 7,
      "z": -15,
      "name": "Rock_Quartzite_Brick"
    },
    {
      "x": -26,
      "y": 8,
      "z": -15,
      "name": "Rock_Quartzite"
    },
    {
      "x": -26,
      "y": 9,
      "z": -15,
      "name": "Rock_Quartzite"
    },
    {
      "x": -26,
      "y": 10,
      "z": -15,
      "name": "Rock_Quartzite"
    },
    {
      "x": -26,
      "y": 11,
      "z": -15,
      "name": "Rock_Quartzite"
    },
    {
      "x": -26,
      "y": 12,
      "z": -15,
      "name": "Soil_Grass"
    },
    {
      "x": -26,
      "y": 0,
      "z": -14,
      "name": "Rock_Quartzite"
    },
    {
      "x": -26,
      "y": 1,
      "z": -14,
      "name": "Rock_Quartzite"
    },
    {
      "x": -26,
      "y": 2,
      "z": -14,
      "name": "Rock_Quartzite"
    },
    {
      "x": -26,
      "y": 3,
      "z": -14,
      "name": "Rock_Quartzite"
    },
    {
      "x": -26,
      "y": 4,
      "z": -14,
      "name": "Rock_Quartzite"
    },
    {
      "x": -26,
      "y": 5,
      "z": -14,
      "name": "Rock_Quartzite"
    },
    {
      "x": -26,
      "y": 6,
      "z": -14,
      "name": "Rock_Quartzite"
    },
    {
      "x": -26,
      "y": 7,
      "z": -14,
      "name": "Rock_Quartzite_Brick"
    },
    {
      "x": -26,
      "y": 8,
      "z": -14,
      "name": "Rock_Quartzite"
    },
    {
      "x": -26,
      "y": 9,
      "z": -14,
      "name": "Rock_Quartzite_Cobble_Half",
      "rotation": 5
    },
    {
      "x": -26,
      "y": 10,
      "z": -14,
      "name": "Rock_Quartzite_Cobble_Stairs",
      "rotation": 11
    },
    {
      "x": -26,
      "y": 11,
      "z": -14,
      "name": "Soil_Dirt"
    },
    {
      "x": -26,
      "y": 12,
      "z": -14,
      "name": "Soil_Grass"
    },
    {
      "x": -26,
      "y": 13,
      "z": -14,
      "name": "Plant_Grass_Lush_Short"
    },
    {
      "x": -26,
      "y": 0,
      "z": -13,
      "name": "Rock_Quartzite"
    },
    {
      "x": -26,
      "y": 1,
      "z": -13,
      "name": "Rock_Quartzite"
    },
    {
      "x": -26,
      "y": 2,
      "z": -13,
      "name": "Rock_Quartzite"
    },
    {
      "x": -26,
      "y": 3,
      "z": -13,
      "name": "Rock_Quartzite"
    },
    {
      "x": -26,
      "y": 4,
      "z": -13,
      "name": "Rock_Quartzite"
    },
    {
      "x": -26,
      "y": 5,
      "z": -13,
      "name": "Rock_Quartzite"
    },
    {
      "x": -26,
      "y": 7,
      "z": -13,
      "name": "Empty"
    },
    {
      "x": -26,
      "y": 8,
      "z": -13,
      "name": "Empty"
    },
    {
      "x": -26,
      "y": 9,
      "z": -13,
      "name": "Empty"
    },
    {
      "x": -26,
      "y": 10,
      "z": -13,
      "name": "Rock_Quartzite_Cobble_Stairs",
      "rotation": 11
    },
    {
      "x": -26,
      "y": 11,
      "z": -13,
      "name": "Soil_Dirt"
    },
    {
      "x": -26,
      "y": 12,
      "z": -13,
      "name": "Soil_Grass"
    },
    {
      "x": -26,
      "y": 0,
      "z": -12,
      "name": "Rock_Quartzite"
    },
    {
      "x": -26,
      "y": 1,
      "z": -12,
      "name": "Rock_Quartzite"
    },
    {
      "x": -26,
      "y": 2,
      "z": -12,
      "name": "Rock_Quartzite"
    },
    {
      "x": -26,
      "y": 3,
      "z": -12,
      "name": "Rock_Quartzite"
    },
    {
      "x": -26,
      "y": 4,
      "z": -12,
      "name": "Rock_Quartzite"
    },
    {
      "x": -26,
      "y": 5,
      "z": -12,
      "name": "Rock_Quartzite"
    },
    {
      "x": -26,
      "y": 7,
      "z": -12,
      "name": "Empty"
    },
    {
      "x": -26,
      "y": 8,
      "z": -12,
      "name": "Empty"
    },
    {
      "x": -26,
      "y": 9,
      "z": -12,
      "name": "Rock_Quartzite_Brick_Stairs",
      "rotation": 8
    },
    {
      "x": -26,
      "y": 10,
      "z": -12,
      "name": "Soil_Dirt"
    },
    {
      "x": -26,
      "y": 11,
      "z": -12,
      "name": "Soil_Grass"
    },
    {
      "x": -26,
      "y": 0,
      "z": -11,
      "name": "Rock_Quartzite"
    },
    {
      "x": -26,
      "y": 1,
      "z": -11,
      "name": "Rock_Quartzite"
    },
    {
      "x": -26,
      "y": 2,
      "z": -11,
      "name": "Rock_Quartzite"
    },
    {
      "x": -26,
      "y": 3,
      "z": -11,
      "name": "Rock_Quartzite"
    },
    {
      "x": -26,
      "y": 4,
      "z": -11,
      "name": "Rock_Quartzite"
    },
    {
      "x": -26,
      "y": 5,
      "z": -11,
      "name": "Rock_Quartzite"
    },
    {
      "x": -26,
      "y": 6,
      "z": -11,
      "name": "Rock_Quartzite"
    },
    {
      "x": -26,
      "y": 7,
      "z": -11,
      "name": "Rock_Quartzite_Cobble"
    },
    {
      "x": -26,
      "y": 8,
      "z": -11,
      "name": "Rock_Quartzite"
    },
    {
      "x": -26,
      "y": 9,
      "z": -11,
      "name": "Soil_Dirt"
    },
    {
      "x": -26,
      "y": 10,
      "z": -11,
      "name": "Soil_Dirt"
    },
    {
      "x": -26,
      "y": 11,
      "z": -11,
      "name": "Soil_Grass"
    },
    {
      "x": -26,
      "y": 12,
      "z": -11,
      "name": "Plant_Grass_Lush_Short"
    },
    {
      "x": -26,
      "y": 0,
      "z": -10,
      "name": "Rock_Quartzite"
    },
    {
      "x": -26,
      "y": 1,
      "z": -10,
      "name": "Rock_Quartzite"
    },
    {
      "x": -26,
      "y": 2,
      "z": -10,
      "name": "Rock_Quartzite"
    },
    {
      "x": -26,
      "y": 3,
      "z": -10,
      "name": "Rock_Quartzite"
    },
    {
      "x": -26,
      "y": 4,
      "z": -10,
      "name": "Rock_Quartzite"
    },
    {
      "x": -26,
      "y": 5,
      "z": -10,
      "name": "Rock_Quartzite"
    },
    {
      "x": -26,
      "y": 6,
      "z": -10,
      "name": "Rock_Quartzite"
    },
    {
      "x": -26,
      "y": 7,
      "z": -10,
      "name": "Rock_Quartzite_Brick"
    },
    {
      "x": -26,
      "y": 8,
      "z": -10,
      "name": "Rock_Quartzite"
    },
    {
      "x": -26,
      "y": 9,
      "z": -10,
      "name": "Rock_Quartzite"
    },
    {
      "x": -26,
      "y": 10,
      "z": -10,
      "name": "Rock_Quartzite"
    },
    {
      "x": -26,
      "y": 11,
      "z": -10,
      "name": "Rock_Quartzite"
    },
    {
      "x": -26,
      "y": 12,
      "z": -10,
      "name": "Soil_Grass"
    },
    {
      "x": -26,
      "y": 13,
      "z": -10,
      "name": "Plant_Grass_Lush_Short"
    },
    {
      "x": -26,
      "y": 0,
      "z": -9,
      "name": "Rock_Quartzite"
    },
    {
      "x": -26,
      "y": 1,
      "z": -9,
      "name": "Rock_Quartzite"
    },
    {
      "x": -26,
      "y": 2,
      "z": -9,
      "name": "Rock_Quartzite"
    },
    {
      "x": -26,
      "y": 3,
      "z": -9,
      "name": "Rock_Quartzite"
    },
    {
      "x": -26,
      "y": 4,
      "z": -9,
      "name": "Rock_Quartzite"
    },
    {
      "x": -26,
      "y": 5,
      "z": -9,
      "name": "Rock_Quartzite_Cobble"
    },
    {
      "x": -26,
      "y": 6,
      "z": -9,
      "name": "Rock_Quartzite_Cobble"
    },
    {
      "x": -26,
      "y": 7,
      "z": -9,
      "name": "Rock_Quartzite_Cobble"
    },
    {
      "x": -26,
      "y": 8,
      "z": -9,
      "name": "Rock_Quartzite"
    },
    {
      "x": -26,
      "y": 9,
      "z": -9,
      "name": "Rock_Quartzite"
    },
    {
      "x": -26,
      "y": 10,
      "z": -9,
      "name": "Rock_Quartzite"
    },
    {
      "x": -26,
      "y": 11,
      "z": -9,
      "name": "Rock_Quartzite"
    },
    {
      "x": -26,
      "y": 12,
      "z": -9,
      "name": "Soil_Grass"
    },
    {
      "x": -26,
      "y": 0,
      "z": -8,
      "name": "Rock_Quartzite"
    },
    {
      "x": -26,
      "y": 1,
      "z": -8,
      "name": "Rock_Quartzite"
    },
    {
      "x": -26,
      "y": 2,
      "z": -8,
      "name": "Rock_Quartzite"
    },
    {
      "x": -26,
      "y": 3,
      "z": -8,
      "name": "Rock_Quartzite"
    },
    {
      "x": -26,
      "y": 4,
      "z": -8,
      "name": "Rock_Quartzite"
    },
    {
      "x": -26,
      "y": 5,
      "z": -8,
      "name": "Rock_Quartzite_Cobble"
    },
    {
      "x": -26,
      "y": 6,
      "z": -8,
      "name": "Rock_Quartzite_Cobble"
    },
    {
      "x": -26,
      "y": 7,
      "z": -8,
      "name": "Rock_Quartzite_Cobble"
    },
    {
      "x": -26,
      "y": 8,
      "z": -8,
      "name": "Rock_Quartzite_Cobble"
    },
    {
      "x": -26,
      "y": 9,
      "z": -8,
      "name": "Rock_Quartzite_Cobble"
    },
    {
      "x": -26,
      "y": 10,
      "z": -8,
      "name": "Rock_Quartzite"
    },
    {
      "x": -26,
      "y": 11,
      "z": -8,
      "name": "Rock_Quartzite"
    },
    {
      "x": -26,
      "y": 12,
      "z": -8,
      "name": "Soil_Grass"
    },
    {
      "x": -26,
      "y": 0,
      "z": -7,
      "name": "Rock_Quartzite"
    },
    {
      "x": -26,
      "y": 1,
      "z": -7,
      "name": "Rock_Quartzite"
    },
    {
      "x": -26,
      "y": 2,
      "z": -7,
      "name": "Rock_Quartzite"
    },
    {
      "x": -26,
      "y": 3,
      "z": -7,
      "name": "Rock_Quartzite"
    },
    {
      "x": -26,
      "y": 4,
      "z": -7,
      "name": "Rock_Quartzite"
    },
    {
      "x": -26,
      "y": 5,
      "z": -7,
      "name": "Rock_Quartzite"
    },
    {
      "x": -26,
      "y": 6,
      "z": -7,
      "name": "Rock_Quartzite"
    },
    {
      "x": -26,
      "y": 7,
      "z": -7,
      "name": "Rock_Quartzite_Brick"
    },
    {
      "x": -26,
      "y": 8,
      "z": -7,
      "name": "Rock_Quartzite"
    },
    {
      "x": -26,
      "y": 9,
      "z": -7,
      "name": "Rock_Quartzite"
    },
    {
      "x": -26,
      "y": 10,
      "z": -7,
      "name": "Rock_Quartzite"
    },
    {
      "x": -26,
      "y": 11,
      "z": -7,
      "name": "Rock_Quartzite"
    },
    {
      "x": -26,
      "y": 12,
      "z": -7,
      "name": "Soil_Grass"
    },
    {
      "x": -26,
      "y": 0,
      "z": -6,
      "name": "Rock_Quartzite"
    },
    {
      "x": -26,
      "y": 1,
      "z": -6,
      "name": "Rock_Quartzite"
    },
    {
      "x": -26,
      "y": 2,
      "z": -6,
      "name": "Rock_Quartzite"
    },
    {
      "x": -26,
      "y": 3,
      "z": -6,
      "name": "Rock_Quartzite"
    },
    {
      "x": -26,
      "y": 4,
      "z": -6,
      "name": "Rock_Quartzite"
    },
    {
      "x": -26,
      "y": 5,
      "z": -6,
      "name": "Rock_Quartzite"
    },
    {
      "x": -26,
      "y": 6,
      "z": -6,
      "name": "Rock_Quartzite"
    },
    {
      "x": -26,
      "y": 7,
      "z": -6,
      "name": "Rock_Quartzite"
    },
    {
      "x": -26,
      "y": 8,
      "z": -6,
      "name": "Rock_Quartzite"
    },
    {
      "x": -26,
      "y": 9,
      "z": -6,
      "name": "Rock_Quartzite"
    },
    {
      "x": -26,
      "y": 10,
      "z": -6,
      "name": "Rock_Quartzite"
    },
    {
      "x": -26,
      "y": 11,
      "z": -6,
      "name": "Rock_Quartzite"
    },
    {
      "x": -26,
      "y": 12,
      "z": -6,
      "name": "Soil_Grass"
    },
    {
      "x": -26,
      "y": 13,
      "z": -6,
      "name": "Plant_Grass_Sharp"
    },
    {
      "x": -26,
      "y": 0,
      "z": -5,
      "name": "Rock_Quartzite"
    },
    {
      "x": -26,
      "y": 1,
      "z": -5,
      "name": "Rock_Quartzite"
    },
    {
      "x": -26,
      "y": 2,
      "z": -5,
      "name": "Rock_Quartzite"
    },
    {
      "x": -26,
      "y": 3,
      "z": -5,
      "name": "Rock_Quartzite"
    },
    {
      "x": -26,
      "y": 4,
      "z": -5,
      "name": "Rock_Quartzite"
    },
    {
      "x": -26,
      "y": 5,
      "z": -5,
      "name": "Rock_Quartzite"
    },
    {
      "x": -26,
      "y": 6,
      "z": -5,
      "name": "Rock_Quartzite"
    },
    {
      "x": -26,
      "y": 7,
      "z": -5,
      "name": "Rock_Quartzite_Brick"
    },
    {
      "x": -26,
      "y": 8,
      "z": -5,
      "name": "Rock_Quartzite"
    },
    {
      "x": -26,
      "y": 9,
      "z": -5,
      "name": "Rock_Quartzite"
    },
    {
      "x": -26,
      "y": 10,
      "z": -5,
      "name": "Rock_Quartzite"
    },
    {
      "x": -26,
      "y": 11,
      "z": -5,
      "name": "Rock_Quartzite"
    },
    {
      "x": -26,
      "y": 12,
      "z": -5,
      "name": "Soil_Grass"
    },
    {
      "x": -26,
      "y": 0,
      "z": -4,
      "name": "Rock_Quartzite"
    },
    {
      "x": -26,
      "y": 1,
      "z": -4,
      "name": "Rock_Quartzite"
    },
    {
      "x": -26,
      "y": 2,
      "z": -4,
      "name": "Rock_Quartzite"
    },
    {
      "x": -26,
      "y": 3,
      "z": -4,
      "name": "Rock_Quartzite"
    },
    {
      "x": -26,
      "y": 4,
      "z": -4,
      "name": "Rock_Quartzite"
    },
    {
      "x": -26,
      "y": 5,
      "z": -4,
      "name": "Rock_Quartzite"
    },
    {
      "x": -26,
      "y": 6,
      "z": -4,
      "name": "Rock_Quartzite"
    },
    {
      "x": -26,
      "y": 7,
      "z": -4,
      "name": "Rock_Quartzite_Brick"
    },
    {
      "x": -26,
      "y": 8,
      "z": -4,
      "name": "Rock_Quartzite"
    },
    {
      "x": -26,
      "y": 9,
      "z": -4,
      "name": "Rock_Quartzite"
    },
    {
      "x": -26,
      "y": 10,
      "z": -4,
      "name": "Rock_Quartzite"
    },
    {
      "x": -26,
      "y": 11,
      "z": -4,
      "name": "Rock_Quartzite"
    },
    {
      "x": -26,
      "y": 12,
      "z": -4,
      "name": "Soil_Grass"
    },
    {
      "x": -26,
      "y": 0,
      "z": -3,
      "name": "Rock_Quartzite"
    },
    {
      "x": -26,
      "y": 1,
      "z": -3,
      "name": "Rock_Quartzite"
    },
    {
      "x": -26,
      "y": 2,
      "z": -3,
      "name": "Rock_Quartzite"
    },
    {
      "x": -26,
      "y": 3,
      "z": -3,
      "name": "Rock_Quartzite"
    },
    {
      "x": -26,
      "y": 4,
      "z": -3,
      "name": "Rock_Quartzite"
    },
    {
      "x": -26,
      "y": 5,
      "z": -3,
      "name": "Rock_Quartzite"
    },
    {
      "x": -26,
      "y": 6,
      "z": -3,
      "name": "Rock_Quartzite"
    },
    {
      "x": -26,
      "y": 7,
      "z": -3,
      "name": "Rock_Quartzite_Brick"
    },
    {
      "x": -26,
      "y": 8,
      "z": -3,
      "name": "Rock_Quartzite"
    },
    {
      "x": -26,
      "y": 9,
      "z": -3,
      "name": "Rock_Quartzite"
    },
    {
      "x": -26,
      "y": 10,
      "z": -3,
      "name": "Rock_Quartzite"
    },
    {
      "x": -26,
      "y": 11,
      "z": -3,
      "name": "Rock_Quartzite"
    },
    {
      "x": -26,
      "y": 12,
      "z": -3,
      "name": "Soil_Grass"
    },
    {
      "x": -26,
      "y": 13,
      "z": -3,
      "name": "Plant_Grass_Lush_Short"
    },
    {
      "x": -26,
      "y": 1,
      "z": -2,
      "name": "Rock_Quartzite"
    },
    {
      "x": -26,
      "y": 2,
      "z": -2,
      "name": "Rock_Quartzite"
    },
    {
      "x": -26,
      "y": 3,
      "z": -2,
      "name": "Rock_Quartzite"
    },
    {
      "x": -26,
      "y": 4,
      "z": -2,
      "name": "Rock_Quartzite"
    },
    {
      "x": -26,
      "y": 5,
      "z": -2,
      "name": "Rock_Quartzite"
    },
    {
      "x": -26,
      "y": 6,
      "z": -2,
      "name": "Rock_Quartzite"
    },
    {
      "x": -26,
      "y": 7,
      "z": -2,
      "name": "Rock_Quartzite"
    },
    {
      "x": -26,
      "y": 8,
      "z": -2,
      "name": "Rock_Quartzite"
    },
    {
      "x": -26,
      "y": 9,
      "z": -2,
      "name": "Rock_Quartzite"
    },
    {
      "x": -26,
      "y": 10,
      "z": -2,
      "name": "Rock_Quartzite"
    },
    {
      "x": -26,
      "y": 11,
      "z": -2,
      "name": "Soil_Grass"
    },
    {
      "x": -26,
      "y": 2,
      "z": -1,
      "name": "Rock_Quartzite"
    },
    {
      "x": -26,
      "y": 3,
      "z": -1,
      "name": "Rock_Quartzite"
    },
    {
      "x": -26,
      "y": 4,
      "z": -1,
      "name": "Rock_Quartzite"
    },
    {
      "x": -26,
      "y": 5,
      "z": -1,
      "name": "Rock_Quartzite"
    },
    {
      "x": -26,
      "y": 6,
      "z": -1,
      "name": "Rock_Quartzite"
    },
    {
      "x": -26,
      "y": 7,
      "z": -1,
      "name": "Rock_Quartzite"
    },
    {
      "x": -26,
      "y": 8,
      "z": -1,
      "name": "Rock_Quartzite"
    },
    {
      "x": -26,
      "y": 9,
      "z": -1,
      "name": "Rock_Quartzite"
    },
    {
      "x": -26,
      "y": 10,
      "z": -1,
      "name": "Rock_Quartzite"
    },
    {
      "x": -26,
      "y": 3,
      "z": 0,
      "name": "Rock_Quartzite"
    },
    {
      "x": -26,
      "y": 4,
      "z": 0,
      "name": "Rock_Quartzite"
    },
    {
      "x": -26,
      "y": 5,
      "z": 0,
      "name": "Rock_Quartzite"
    },
    {
      "x": -26,
      "y": 6,
      "z": 0,
      "name": "Rock_Quartzite"
    },
    {
      "x": -26,
      "y": 7,
      "z": 0,
      "name": "Rock_Quartzite"
    },
    {
      "x": -26,
      "y": 8,
      "z": 0,
      "name": "Rock_Quartzite"
    },
    {
      "x": -26,
      "y": 9,
      "z": 0,
      "name": "Rock_Quartzite"
    },
    {
      "x": -26,
      "y": 4,
      "z": 1,
      "name": "Rock_Quartzite"
    },
    {
      "x": -26,
      "y": 5,
      "z": 1,
      "name": "Rock_Quartzite"
    },
    {
      "x": -26,
      "y": 6,
      "z": 1,
      "name": "Rock_Quartzite"
    },
    {
      "x": -26,
      "y": 7,
      "z": 1,
      "name": "Rock_Quartzite"
    },
    {
      "x": -26,
      "y": 11,
      "z": 8,
      "name": "Plant_Moss_Wall_Green",
      "rotation": 3
    },
    {
      "x": -26,
      "y": 10,
      "z": 9,
      "name": "Plant_Vine_Wall",
      "rotation": 3
    },
    {
      "x": -26,
      "y": 11,
      "z": 9,
      "name": "Plant_Vine",
      "rotation": 3
    },
    {
      "x": -26,
      "y": 12,
      "z": 9,
      "name": "Plant_Vine",
      "rotation": 3
    },
    {
      "x": -25,
      "y": 1,
      "z": -19,
      "name": "Rock_Quartzite"
    },
    {
      "x": -25,
      "y": 2,
      "z": -19,
      "name": "Rock_Quartzite"
    },
    {
      "x": -25,
      "y": 3,
      "z": -19,
      "name": "Rock_Quartzite"
    },
    {
      "x": -25,
      "y": 4,
      "z": -19,
      "name": "Rock_Quartzite"
    },
    {
      "x": -25,
      "y": 5,
      "z": -19,
      "name": "Rock_Quartzite"
    },
    {
      "x": -25,
      "y": 6,
      "z": -19,
      "name": "Rock_Quartzite"
    },
    {
      "x": -25,
      "y": 12,
      "z": -19,
      "name": "Rock_Quartzite_Brick"
    },
    {
      "x": -25,
      "y": 0,
      "z": -18,
      "name": "Rock_Quartzite"
    },
    {
      "x": -25,
      "y": 1,
      "z": -18,
      "name": "Rock_Quartzite"
    },
    {
      "x": -25,
      "y": 2,
      "z": -18,
      "name": "Rock_Quartzite"
    },
    {
      "x": -25,
      "y": 3,
      "z": -18,
      "name": "Rock_Quartzite"
    },
    {
      "x": -25,
      "y": 4,
      "z": -18,
      "name": "Rock_Quartzite"
    },
    {
      "x": -25,
      "y": 5,
      "z": -18,
      "name": "Rock_Quartzite"
    },
    {
      "x": -25,
      "y": 6,
      "z": -18,
      "name": "Rock_Quartzite"
    },
    {
      "x": -25,
      "y": 7,
      "z": -18,
      "name": "Rock_Quartzite_Brick"
    },
    {
      "x": -25,
      "y": 8,
      "z": -18,
      "name": "Rock_Quartzite"
    },
    {
      "x": -25,
      "y": 11,
      "z": -18,
      "name": "Rock_Quartzite_Cobble_Stairs",
      "rotation": 8
    },
    {
      "x": -25,
      "y": 12,
      "z": -18,
      "name": "Soil_Grass"
    },
    {
      "x": -25,
      "y": 13,
      "z": -18,
      "name": "Plant_Grass_Lush_Short"
    },
    {
      "x": -25,
      "y": 0,
      "z": -17,
      "name": "Rock_Quartzite"
    },
    {
      "x": -25,
      "y": 1,
      "z": -17,
      "name": "Rock_Quartzite"
    },
    {
      "x": -25,
      "y": 2,
      "z": -17,
      "name": "Rock_Quartzite"
    },
    {
      "x": -25,
      "y": 3,
      "z": -17,
      "name": "Rock_Quartzite"
    },
    {
      "x": -25,
      "y": 4,
      "z": -17,
      "name": "Rock_Quartzite"
    },
    {
      "x": -25,
      "y": 5,
      "z": -17,
      "name": "Rock_Quartzite"
    },
    {
      "x": -25,
      "y": 6,
      "z": -17,
      "name": "Rock_Quartzite"
    },
    {
      "x": -25,
      "y": 7,
      "z": -17,
      "name": "Rock_Quartzite_Brick"
    },
    {
      "x": -25,
      "y": 8,
      "z": -17,
      "name": "Rock_Quartzite"
    },
    {
      "x": -25,
      "y": 9,
      "z": -17,
      "name": "Rock_Quartzite"
    },
    {
      "x": -25,
      "y": 10,
      "z": -17,
      "name": "Rock_Quartzite"
    },
    {
      "x": -25,
      "y": 11,
      "z": -17,
      "name": "Rock_Quartzite"
    },
    {
      "x": -25,
      "y": 12,
      "z": -17,
      "name": "Soil_Grass"
    },
    {
      "x": -25,
      "y": 0,
      "z": -16,
      "name": "Rock_Quartzite"
    },
    {
      "x": -25,
      "y": 1,
      "z": -16,
      "name": "Rock_Quartzite"
    },
    {
      "x": -25,
      "y": 2,
      "z": -16,
      "name": "Rock_Quartzite"
    },
    {
      "x": -25,
      "y": 3,
      "z": -16,
      "name": "Rock_Quartzite"
    },
    {
      "x": -25,
      "y": 4,
      "z": -16,
      "name": "Rock_Quartzite"
    },
    {
      "x": -25,
      "y": 5,
      "z": -16,
      "name": "Rock_Quartzite"
    },
    {
      "x": -25,
      "y": 6,
      "z": -16,
      "name": "Rock_Quartzite"
    },
    {
      "x": -25,
      "y": 7,
      "z": -16,
      "name": "Rock_Quartzite_Brick"
    },
    {
      "x": -25,
      "y": 8,
      "z": -16,
      "name": "Rock_Quartzite"
    },
    {
      "x": -25,
      "y": 9,
      "z": -16,
      "name": "Rock_Quartzite"
    },
    {
      "x": -25,
      "y": 10,
      "z": -16,
      "name": "Rock_Quartzite"
    },
    {
      "x": -25,
      "y": 11,
      "z": -16,
      "name": "Rock_Quartzite"
    },
    {
      "x": -25,
      "y": 12,
      "z": -16,
      "name": "Soil_Grass"
    },
    {
      "x": -25,
      "y": 13,
      "z": -16,
      "name": "Plant_Moss_Rug_Green"
    },
    {
      "x": -25,
      "y": 0,
      "z": -15,
      "name": "Rock_Quartzite"
    },
    {
      "x": -25,
      "y": 1,
      "z": -15,
      "name": "Rock_Quartzite"
    },
    {
      "x": -25,
      "y": 2,
      "z": -15,
      "name": "Rock_Quartzite"
    },
    {
      "x": -25,
      "y": 3,
      "z": -15,
      "name": "Rock_Quartzite"
    },
    {
      "x": -25,
      "y": 4,
      "z": -15,
      "name": "Rock_Quartzite"
    },
    {
      "x": -25,
      "y": 5,
      "z": -15,
      "name": "Rock_Quartzite"
    },
    {
      "x": -25,
      "y": 6,
      "z": -15,
      "name": "Rock_Quartzite"
    },
    {
      "x": -25,
      "y": 7,
      "z": -15,
      "name": "Rock_Quartzite_Brick"
    },
    {
      "x": -25,
      "y": 8,
      "z": -15,
      "name": "Rock_Quartzite_Brick"
    },
    {
      "x": -25,
      "y": 9,
      "z": -15,
      "name": "Rock_Quartzite_Brick"
    },
    {
      "x": -25,
      "y": 10,
      "z": -15,
      "name": "Rock_Quartzite_Brick"
    },
    {
      "x": -25,
      "y": 11,
      "z": -15,
      "name": "Rock_Quartzite_Brick"
    },
    {
      "x": -25,
      "y": 12,
      "z": -15,
      "name": "Rock_Quartzite_Brick"
    },
    {
      "x": -25,
      "y": 13,
      "z": -15,
      "name": "Rock_Quartzite_Brick_Half"
    },
    {
      "x": -25,
      "y": 0,
      "z": -14,
      "name": "Rock_Quartzite"
    },
    {
      "x": -25,
      "y": 1,
      "z": -14,
      "name": "Rock_Quartzite"
    },
    {
      "x": -25,
      "y": 2,
      "z": -14,
      "name": "Rock_Quartzite"
    },
    {
      "x": -25,
      "y": 3,
      "z": -14,
      "name": "Rock_Quartzite"
    },
    {
      "x": -25,
      "y": 4,
      "z": -14,
      "name": "Rock_Quartzite"
    },
    {
      "x": -25,
      "y": 5,
      "z": -14,
      "name": "Rock_Quartzite"
    },
    {
      "x": -25,
      "y": 7,
      "z": -14,
      "name": "Empty"
    },
    {
      "x": -25,
      "y": 8,
      "z": -14,
      "name": "Empty"
    },
    {
      "x": -25,
      "y": 9,
      "z": -14,
      "name": "Empty"
    },
    {
      "x": -25,
      "y": 10,
      "z": -14,
      "name": "Empty"
    },
    {
      "x": -25,
      "y": 11,
      "z": -14,
      "name": "Empty"
    },
    {
      "x": -25,
      "y": 12,
      "z": -14,
      "name": "Rock_Quartzite_Brick"
    },
    {
      "x": -25,
      "y": 0,
      "z": -13,
      "name": "Rock_Quartzite"
    },
    {
      "x": -25,
      "y": 1,
      "z": -13,
      "name": "Rock_Quartzite"
    },
    {
      "x": -25,
      "y": 2,
      "z": -13,
      "name": "Rock_Quartzite"
    },
    {
      "x": -25,
      "y": 3,
      "z": -13,
      "name": "Rock_Quartzite"
    },
    {
      "x": -25,
      "y": 7,
      "z": -13,
      "name": "Empty"
    },
    {
      "x": -25,
      "y": 8,
      "z": -13,
      "name": "Empty"
    },
    {
      "x": -25,
      "y": 9,
      "z": -13,
      "name": "Empty"
    },
    {
      "x": -25,
      "y": 10,
      "z": -13,
      "name": "Empty"
    },
    {
      "x": -25,
      "y": 11,
      "z": -13,
      "name": "Empty"
    },
    {
      "x": -25,
      "y": 12,
      "z": -13,
      "name": "Rock_Quartzite_Brick"
    },
    {
      "x": -25,
      "y": 0,
      "z": -12,
      "name": "Rock_Quartzite"
    },
    {
      "x": -25,
      "y": 1,
      "z": -12,
      "name": "Rock_Quartzite"
    },
    {
      "x": -25,
      "y": 2,
      "z": -12,
      "name": "Rock_Quartzite"
    },
    {
      "x": -25,
      "y": 3,
      "z": -12,
      "name": "Rock_Quartzite"
    },
    {
      "x": -25,
      "y": 7,
      "z": -12,
      "name": "Empty"
    },
    {
      "x": -25,
      "y": 8,
      "z": -12,
      "name": "Empty"
    },
    {
      "x": -25,
      "y": 9,
      "z": -12,
      "name": "Empty"
    },
    {
      "x": -25,
      "y": 10,
      "z": -12,
      "name": "Empty"
    },
    {
      "x": -25,
      "y": 11,
      "z": -12,
      "name": "Empty"
    },
    {
      "x": -25,
      "y": 12,
      "z": -12,
      "name": "Empty"
    },
    {
      "x": -25,
      "y": 1,
      "z": -11,
      "name": "Rock_Quartzite"
    },
    {
      "x": -25,
      "y": 2,
      "z": -11,
      "name": "Rock_Quartzite"
    },
    {
      "x": -25,
      "y": 3,
      "z": -11,
      "name": "Rock_Quartzite"
    },
    {
      "x": -25,
      "y": 4,
      "z": -11,
      "name": "Rock_Quartzite"
    },
    {
      "x": -25,
      "y": 7,
      "z": -11,
      "name": "Empty"
    },
    {
      "x": -25,
      "y": 8,
      "z": -11,
      "name": "Empty"
    },
    {
      "x": -25,
      "y": 9,
      "z": -11,
      "name": "Empty"
    },
    {
      "x": -25,
      "y": 10,
      "z": -11,
      "name": "Empty"
    },
    {
      "x": -25,
      "y": 11,
      "z": -11,
      "name": "Empty"
    },
    {
      "x": -25,
      "y": 12,
      "z": -11,
      "name": "Empty"
    },
    {
      "x": -25,
      "y": 2,
      "z": -10,
      "name": "Rock_Quartzite"
    },
    {
      "x": -25,
      "y": 3,
      "z": -10,
      "name": "Rock_Quartzite"
    },
    {
      "x": -25,
      "y": 4,
      "z": -10,
      "name": "Rock_Quartzite"
    },
    {
      "x": -25,
      "y": 5,
      "z": -10,
      "name": "Rock_Quartzite_Cobble"
    },
    {
      "x": -25,
      "y": 6,
      "z": -10,
      "name": "Rock_Quartzite_Cobble"
    },
    {
      "x": -25,
      "y": 7,
      "z": -10,
      "name": "Empty"
    },
    {
      "x": -25,
      "y": 8,
      "z": -10,
      "name": "Empty"
    },
    {
      "x": -25,
      "y": 9,
      "z": -10,
      "name": "Empty"
    },
    {
      "x": -25,
      "y": 10,
      "z": -10,
      "name": "Empty"
    },
    {
      "x": -25,
      "y": 11,
      "z": -10,
      "name": "Empty"
    },
    {
      "x": -25,
      "y": 12,
      "z": -10,
      "name": "Empty"
    },
    {
      "x": -25,
      "y": 3,
      "z": -9,
      "name": "Rock_Quartzite_Cobble"
    },
    {
      "x": -25,
      "y": 4,
      "z": -9,
      "name": "Rock_Quartzite_Cobble"
    },
    {
      "x": -25,
      "y": 5,
      "z": -9,
      "name": "Rock_Quartzite_Cobble"
    },
    {
      "x": -25,
      "y": 6,
      "z": -9,
      "name": "Rock_Quartzite_Cobble"
    },
    {
      "x": -25,
      "y": 7,
      "z": -9,
      "name": "Empty"
    },
    {
      "x": -25,
      "y": 8,
      "z": -9,
      "name": "Empty"
    },
    {
      "x": -25,
      "y": 9,
      "z": -9,
      "name": "Empty"
    },
    {
      "x": -25,
      "y": 10,
      "z": -9,
      "name": "Empty"
    },
    {
      "x": -25,
      "y": 11,
      "z": -9,
      "name": "Empty"
    },
    {
      "x": -25,
      "y": 12,
      "z": -9,
      "name": "Empty"
    },
    {
      "x": -25,
      "y": 4,
      "z": -8,
      "name": "Rock_Quartzite"
    },
    {
      "x": -25,
      "y": 5,
      "z": -8,
      "name": "Rock_Quartzite"
    },
    {
      "x": -25,
      "y": 6,
      "z": -8,
      "name": "Rock_Quartzite"
    },
    {
      "x": -25,
      "y": 7,
      "z": -8,
      "name": "Rock_Quartzite_Brick"
    },
    {
      "x": -25,
      "y": 8,
      "z": -8,
      "name": "Rock_Quartzite_Brick_Half",
      "rotation": 5
    },
    {
      "x": -25,
      "y": 9,
      "z": -8,
      "name": "Rock_Quartzite_Brick_Half",
      "rotation": 5
    },
    {
      "x": -25,
      "y": 10,
      "z": -8,
      "name": "Empty"
    },
    {
      "x": -25,
      "y": 11,
      "z": -8,
      "name": "Empty"
    },
    {
      "x": -25,
      "y": 12,
      "z": -8,
      "name": "Empty"
    },
    {
      "x": -25,
      "y": 14,
      "z": -8,
      "name": "Rock_Quartzite_Brick_Half",
      "rotation": 8
    },
    {
      "x": -25,
      "y": 15,
      "z": -8,
      "name": "Rock_Quartzite_Brick"
    },
    {
      "x": -25,
      "y": 16,
      "z": -8,
      "name": "Rock_Stone_Brick_Smooth"
    },
    {
      "x": -25,
      "y": 3,
      "z": -7,
      "name": "Rock_Quartzite"
    },
    {
      "x": -25,
      "y": 4,
      "z": -7,
      "name": "Rock_Quartzite"
    },
    {
      "x": -25,
      "y": 5,
      "z": -7,
      "name": "Rock_Quartzite"
    },
    {
      "x": -25,
      "y": 6,
      "z": -7,
      "name": "Rock_Quartzite"
    },
    {
      "x": -25,
      "y": 7,
      "z": -7,
      "name": "Rock_Quartzite"
    },
    {
      "x": -25,
      "y": 8,
      "z": -7,
      "name": "Rock_Quartzite"
    },
    {
      "x": -25,
      "y": 9,
      "z": -7,
      "name": "Rock_Quartzite"
    },
    {
      "x": -25,
      "y": 10,
      "z": -7,
      "name": "Rock_Quartzite"
    },
    {
      "x": -25,
      "y": 11,
      "z": -7,
      "name": "Rock_Quartzite"
    },
    {
      "x": -25,
      "y": 12,
      "z": -7,
      "name": "Rock_Quartzite"
    },
    {
      "x": -25,
      "y": 14,
      "z": -7,
      "name": "Rock_Quartzite_Brick_Half",
      "rotation": 8
    },
    {
      "x": -25,
      "y": 15,
      "z": -7,
      "name": "Rock_Quartzite_Brick"
    },
    {
      "x": -25,
      "y": 16,
      "z": -7,
      "name": "Rock_Stone_Brick_Smooth"
    },
    {
      "x": -25,
      "y": 17,
      "z": -7,
      "name": "Rock_Stone_Brick_Smooth_Half",
      "rotation": 6
    },
    {
      "x": -25,
      "y": 3,
      "z": -6,
      "name": "Rock_Quartzite"
    },
    {
      "x": -25,
      "y": 4,
      "z": -6,
      "name": "Rock_Quartzite"
    },
    {
      "x": -25,
      "y": 5,
      "z": -6,
      "name": "Rock_Quartzite"
    },
    {
      "x": -25,
      "y": 6,
      "z": -6,
      "name": "Rock_Quartzite"
    },
    {
      "x": -25,
      "y": 7,
      "z": -6,
      "name": "Rock_Quartzite"
    },
    {
      "x": -25,
      "y": 8,
      "z": -6,
      "name": "Rock_Quartzite"
    },
    {
      "x": -25,
      "y": 9,
      "z": -6,
      "name": "Rock_Quartzite"
    },
    {
      "x": -25,
      "y": 10,
      "z": -6,
      "name": "Rock_Quartzite"
    },
    {
      "x": -25,
      "y": 11,
      "z": -6,
      "name": "Rock_Quartzite"
    },
    {
      "x": -25,
      "y": 12,
      "z": -6,
      "name": "Rock_Quartzite"
    },
    {
      "x": -25,
      "y": 13,
      "z": -6,
      "name": "Rock_Quartzite_Brick_Half",
      "rotation": 6
    },
    {
      "x": -25,
      "y": 14,
      "z": -6,
      "name": "Rock_Quartzite_Brick_Stairs",
      "rotation": 8
    },
    {
      "x": -25,
      "y": 15,
      "z": -6,
      "name": "Rock_Quartzite_Brick"
    },
    {
      "x": -25,
      "y": 16,
      "z": -6,
      "name": "Rock_Stone_Brick_Smooth"
    },
    {
      "x": -25,
      "y": 17,
      "z": -6,
      "name": "Rock_Stone_Brick_Smooth_Half",
      "rotation": 8
    },
    {
      "x": -25,
      "y": 3,
      "z": -5,
      "name": "Rock_Quartzite"
    },
    {
      "x": -25,
      "y": 4,
      "z": -5,
      "name": "Rock_Quartzite"
    },
    {
      "x": -25,
      "y": 5,
      "z": -5,
      "name": "Rock_Quartzite"
    },
    {
      "x": -25,
      "y": 6,
      "z": -5,
      "name": "Rock_Quartzite"
    },
    {
      "x": -25,
      "y": 7,
      "z": -5,
      "name": "Rock_Quartzite"
    },
    {
      "x": -25,
      "y": 8,
      "z": -5,
      "name": "Rock_Quartzite"
    },
    {
      "x": -25,
      "y": 9,
      "z": -5,
      "name": "Rock_Quartzite"
    },
    {
      "x": -25,
      "y": 10,
      "z": -5,
      "name": "Rock_Quartzite"
    },
    {
      "x": -25,
      "y": 11,
      "z": -5,
      "name": "Rock_Quartzite"
    },
    {
      "x": -25,
      "y": 12,
      "z": -5,
      "name": "Rock_Quartzite"
    },
    {
      "x": -25,
      "y": 13,
      "z": -5,
      "name": "Rock_Quartzite_Brick_Half",
      "rotation": 4
    },
    {
      "x": -25,
      "y": 14,
      "z": -5,
      "name": "Rock_Quartzite_Brick_Stairs",
      "rotation": 10
    },
    {
      "x": -25,
      "y": 15,
      "z": -5,
      "name": "Rock_Quartzite_Brick"
    },
    {
      "x": -25,
      "y": 16,
      "z": -5,
      "name": "Rock_Stone_Brick_Smooth"
    },
    {
      "x": -25,
      "y": 17,
      "z": -5,
      "name": "Rock_Stone_Brick_Smooth_Half",
      "rotation": 4
    },
    {
      "x": -25,
      "y": 1,
      "z": -4,
      "name": "Rock_Quartzite"
    },
    {
      "x": -25,
      "y": 2,
      "z": -4,
      "name": "Rock_Quartzite"
    },
    {
      "x": -25,
      "y": 3,
      "z": -4,
      "name": "Rock_Quartzite"
    },
    {
      "x": -25,
      "y": 4,
      "z": -4,
      "name": "Rock_Quartzite"
    },
    {
      "x": -25,
      "y": 5,
      "z": -4,
      "name": "Rock_Quartzite"
    },
    {
      "x": -25,
      "y": 6,
      "z": -4,
      "name": "Rock_Quartzite"
    },
    {
      "x": -25,
      "y": 7,
      "z": -4,
      "name": "Rock_Quartzite"
    },
    {
      "x": -25,
      "y": 8,
      "z": -4,
      "name": "Rock_Quartzite"
    },
    {
      "x": -25,
      "y": 9,
      "z": -4,
      "name": "Rock_Quartzite"
    },
    {
      "x": -25,
      "y": 10,
      "z": -4,
      "name": "Rock_Quartzite"
    },
    {
      "x": -25,
      "y": 11,
      "z": -4,
      "name": "Rock_Quartzite"
    },
    {
      "x": -25,
      "y": 12,
      "z": -4,
      "name": "Rock_Quartzite"
    },
    {
      "x": -25,
      "y": 13,
      "z": -4,
      "name": "Furniture_Crude_Ladder",
      "rotation": 3
    },
    {
      "x": -25,
      "y": 14,
      "z": -4,
      "name": "Furniture_Crude_Ladder",
      "rotation": 3
    },
    {
      "x": -25,
      "y": 15,
      "z": -4,
      "name": "Furniture_Crude_Ladder",
      "rotation": 3
    },
    {
      "x": -25,
      "y": 0,
      "z": -3,
      "name": "Rock_Quartzite"
    },
    {
      "x": -25,
      "y": 1,
      "z": -3,
      "name": "Rock_Quartzite"
    },
    {
      "x": -25,
      "y": 2,
      "z": -3,
      "name": "Rock_Quartzite"
    },
    {
      "x": -25,
      "y": 3,
      "z": -3,
      "name": "Rock_Quartzite"
    },
    {
      "x": -25,
      "y": 4,
      "z": -3,
      "name": "Rock_Quartzite"
    },
    {
      "x": -25,
      "y": 5,
      "z": -3,
      "name": "Rock_Quartzite_Cobble"
    },
    {
      "x": -25,
      "y": 6,
      "z": -3,
      "name": "Rock_Quartzite"
    },
    {
      "x": -25,
      "y": 7,
      "z": -3,
      "name": "Rock_Quartzite"
    },
    {
      "x": -25,
      "y": 8,
      "z": -3,
      "name": "Rock_Quartzite"
    },
    {
      "x": -25,
      "y": 9,
      "z": -3,
      "name": "Rock_Quartzite"
    },
    {
      "x": -25,
      "y": 10,
      "z": -3,
      "name": "Rock_Quartzite"
    },
    {
      "x": -25,
      "y": 11,
      "z": -3,
      "name": "Rock_Quartzite"
    },
    {
      "x": -25,
      "y": 12,
      "z": -3,
      "name": "Rock_Quartzite"
    },
    {
      "x": -25,
      "y": 0,
      "z": -2,
      "name": "Rock_Quartzite"
    },
    {
      "x": -25,
      "y": 1,
      "z": -2,
      "name": "Rock_Quartzite"
    },
    {
      "x": -25,
      "y": 2,
      "z": -2,
      "name": "Rock_Quartzite"
    },
    {
      "x": -25,
      "y": 3,
      "z": -2,
      "name": "Rock_Quartzite_Cobble"
    },
    {
      "x": -25,
      "y": 4,
      "z": -2,
      "name": "Rock_Quartzite_Cobble"
    },
    {
      "x": -25,
      "y": 5,
      "z": -2,
      "name": "Rock_Quartzite_Cobble"
    },
    {
      "x": -25,
      "y": 6,
      "z": -2,
      "name": "Rock_Quartzite"
    },
    {
      "x": -25,
      "y": 7,
      "z": -2,
      "name": "Rock_Quartzite"
    },
    {
      "x": -25,
      "y": 8,
      "z": -2,
      "name": "Rock_Quartzite"
    },
    {
      "x": -25,
      "y": 9,
      "z": -2,
      "name": "Rock_Quartzite"
    },
    {
      "x": -25,
      "y": 10,
      "z": -2,
      "name": "Rock_Quartzite"
    },
    {
      "x": -25,
      "y": 11,
      "z": -2,
      "name": "Rock_Quartzite"
    },
    {
      "x": -25,
      "y": 12,
      "z": -2,
      "name": "Rock_Quartzite"
    },
    {
      "x": -25,
      "y": 0,
      "z": -1,
      "name": "Rock_Quartzite"
    },
    {
      "x": -25,
      "y": 1,
      "z": -1,
      "name": "Rock_Quartzite"
    },
    {
      "x": -25,
      "y": 2,
      "z": -1,
      "name": "Rock_Quartzite"
    },
    {
      "x": -25,
      "y": 3,
      "z": -1,
      "name": "Rock_Quartzite"
    },
    {
      "x": -25,
      "y": 4,
      "z": -1,
      "name": "Rock_Quartzite"
    },
    {
      "x": -25,
      "y": 5,
      "z": -1,
      "name": "Rock_Quartzite"
    },
    {
      "x": -25,
      "y": 6,
      "z": -1,
      "name": "Rock_Quartzite_Cobble"
    },
    {
      "x": -25,
      "y": 7,
      "z": -1,
      "name": "Rock_Quartzite_Brick"
    },
    {
      "x": -25,
      "y": 8,
      "z": -1,
      "name": "Rock_Quartzite_Brick_Half",
      "rotation": 6
    },
    {
      "x": -25,
      "y": 9,
      "z": -1,
      "name": "Rock_Quartzite_Brick_Half",
      "rotation": 6
    },
    {
      "x": -25,
      "y": 10,
      "z": -1,
      "name": "Rock_Quartzite_Brick_Half",
      "rotation": 6
    },
    {
      "x": -25,
      "y": 11,
      "z": -1,
      "name": "Rock_Quartzite_Brick_Half",
      "rotation": 6
    },
    {
      "x": -25,
      "y": 12,
      "z": -1,
      "name": "Rock_Quartzite_Brick_Half",
      "rotation": 6
    },
    {
      "x": -25,
      "y": 13,
      "z": -1,
      "name": "Rock_Quartzite_Brick_Half",
      "rotation": 6
    },
    {
      "x": -25,
      "y": 14,
      "z": -1,
      "name": "Rock_Quartzite_Brick_Half",
      "rotation": 8
    },
    {
      "x": -25,
      "y": 15,
      "z": -1,
      "name": "Rock_Quartzite_Brick"
    },
    {
      "x": -25,
      "y": 16,
      "z": -1,
      "name": "Rock_Stone_Brick_Smooth"
    },
    {
      "x": -25,
      "y": 17,
      "z": -1,
      "name": "Rock_Stone_Brick_Smooth_Half",
      "rotation": 6
    },
    {
      "x": -25,
      "y": 0,
      "z": 0,
      "name": "Rock_Quartzite"
    },
    {
      "x": -25,
      "y": 1,
      "z": 0,
      "name": "Rock_Quartzite"
    },
    {
      "x": -25,
      "y": 2,
      "z": 0,
      "name": "Rock_Quartzite"
