{
  "version": 8,
  "blockIdVersion": 8,
  "anchorX": 0,
  "anchorY": 7,
  "anchorZ": -1,
  "blocks": [
    {
      "x": -8,
      "y": 22,
      "z": 2,
      "name": "Plant_Vine_Wall",
      "rotation": 3
    },
    {
      "x": -7,
      "y": 5,
      "z": -6,
      "name": "Rock_Quartzite"
    },
    {
      "x": -7,
      "y": 6,
      "z": -6,
      "name": "Rock_Quartzite"
    },
    {
      "x": -7,
      "y": 7,
      "z": -6,
      "name": "Rock_Quartzite_Cobble"
    },
    {
      "x": -7,
      "y": 8,
      "z": -6,
      "name": "Rock_Quartzite_Brick"
    },
    {
      "x": -7,
      "y": 17,
      "z": -6,
      "name": "Rock_Stone_Brick_Smooth_Half"
    },
    {
      "x": -7,
      "y": 22,
      "z": -6,
      "name": "Rock_Stone_Brick_Smooth"
    },
    {
      "x": -7,
      "y": 23,
      "z": -6,
      "name": "Plant_Moss_Rug_Green"
    },
    {
      "x": -7,
      "y": 4,
      "z": -5,
      "name": "Rock_Quartzite"
    },
    {
      "x": -7,
      "y": 5,
      "z": -5,
      "name": "Rock_Quartzite"
    },
    {
      "x": -7,
      "y": 6,
      "z": -5,
      "name": "Rock_Quartzite"
    },
    {
      "x": -7,
      "y": 7,
      "z": -5,
      "name": "Rock_Quartzite"
    },
    {
      "x": -7,
      "y": 8,
      "z": -5,
      "name": "Rock_Quartzite_Brick"
    },
    {
      "x": -7,
      "y": 9,
      "z": -5,
      "name": "Rock_Quartzite_Brick_Stairs",
      "rotation": 3
    },
    {
      "x": -7,
      "y": 16,
      "z": -5,
      "name": "Rock_Quartzite_Brick_Half",
      "rotation": 7
    },
    {
      "x": -7,
      "y": 17,
      "z": -5,
      "name": "Rock_Stone_Brick_Smooth_Half"
    },
    {
      "x": -7,
      "y": 21,
      "z": -5,
      "name": "Plant_Vine_Wall",
      "rotation": 3
    },
    {
      "x": -7,
      "y": 22,
      "z": -5,
      "name": "Rock_Stone_Brick_Smooth"
    },
    {
      "x": -7,
      "y": 23,
      "z": -5,
      "name": "Plant_Moss_Rug_Green"
    },
    {
      "x": -7,
      "y": 2,
      "z": -4,
      "name": "Rock_Quartzite"
    },
    {
      "x": -7,
      "y": 3,
      "z": -4,
      "name": "Rock_Quartzite"
    },
    {
      "x": -7,
      "y": 4,
      "z": -4,
      "name": "Rock_Quartzite"
    },
    {
      "x": -7,
      "y": 5,
      "z": -4,
      "name": "Rock_Quartzite"
    },
    {
      "x": -7,
      "y": 6,
      "z": -4,
      "name": "Rock_Quartzite"
    },
    {
      "x": -7,
      "y": 7,
      "z": -4,
      "name": "Rock_Quartzite"
    },
    {
      "x": -7,
      "y": 8,
      "z": -4,
      "name": "Rock_Quartzite_Brick"
    },
    {
      "x": -7,
      "y": 9,
      "z": -4,
      "name": "Rock_Quartzite_Brick_Stairs",
      "rotation": 3
    },
    {
      "x": -7,
      "y": 16,
      "z": -4,
      "name": "Rock_Quartzite_Brick_Half",
      "rotation": 7
    },
    {
      "x": -7,
      "y": 17,
      "z": -4,
      "name": "Rock_Stone_Brick_Smooth_Half"
    },
    {
      "x": -7,
      "y": 21,
      "z": -4,
      "name": "Plant_Vine",
      "rotation": 3
    },
    {
      "x": -7,
      "y": 22,
      "z": -4,
      "name": "Rock_Stone_Brick_Smooth_Half"
    },
    {
      "x": -7,
      "y": 2,
      "z": -3,
      "name": "Rock_Quartzite"
    },
    {
      "x": -7,
      "y": 3,
      "z": -3,
      "name": "Rock_Quartzite"
    },
    {
      "x": -7,
      "y": 4,
      "z": -3,
      "name": "Rock_Quartzite"
    },
    {
      "x": -7,
      "y": 5,
      "z": -3,
      "name": "Rock_Quartzite"
    },
    {
      "x": -7,
      "y": 6,
      "z": -3,
      "name": "Rock_Quartzite"
    },
    {
      "x": -7,
      "y": 7,
      "z": -3,
      "name": "Rock_Quartzite_Brick"
    },
    {
      "x": -7,
      "y": 8,
      "z": -3,
      "name": "Rock_Quartzite_Brick"
    },
    {
      "x": -7,
      "y": 9,
      "z": -3,
      "name": "Rock_Quartzite_Brick_Stairs",
      "rotation": 3
    },
    {
      "x": -7,
      "y": 16,
      "z": -3,
      "name": "Rock_Quartzite_Brick_Half",
      "rotation": 7
    },
    {
      "x": -7,
      "y": 17,
      "z": -3,
      "name": "Rock_Stone_Brick_Smooth_Half"
    },
    {
      "x": -7,
      "y": 19,
      "z": -3,
      "name": "Plant_Vine_Wall",
      "rotation": 3
    },
    {
      "x": -7,
      "y": 20,
      "z": -3,
      "name": "Plant_Vine",
      "rotation": 3
    },
    {
      "x": -7,
      "y": 21,
      "z": -3,
      "name": "Plant_Vine",
      "rotation": 3
    },
    {
      "x": -7,
      "y": 4,
      "z": -2,
      "name": "Rock_Quartzite"
    },
    {
      "x": -7,
      "y": 5,
      "z": -2,
      "name": "Rock_Quartzite"
    },
    {
      "x": -7,
      "y": 6,
      "z": -2,
      "name": "Rock_Quartzite_Brick"
    },
    {
      "x": -7,
      "y": 7,
      "z": -2,
      "name": "Rock_Quartzite_Brick"
    },
    {
      "x": -7,
      "y": 8,
      "z": -2,
      "name": "Rock_Quartzite_Brick"
    },
    {
      "x": -7,
      "y": 17,
      "z": -2,
      "name": "Rock_Stone_Brick_Smooth_Half"
    },
    {
      "x": -7,
      "y": 22,
      "z": 0,
      "name": "Rock_Stone_Brick_Smooth_Half"
    },
    {
      "x": -7,
      "y": 22,
      "z": 1,
      "name": "Rock_Stone_Brick_Smooth_Half"
    },
    {
      "x": -7,
      "y": 22,
      "z": 2,
      "name": "Rock_Stone_Brick_Smooth"
    },
    {
      "x": -7,
      "y": 23,
      "z": 2,
      "name": "Plant_Moss_Rug_Green"
    },
    {
      "x": -7,
      "y": 22,
      "z": 3,
      "name": "Rock_Stone_Brick_Smooth"
    },
    {
      "x": -7,
      "y": 2,
      "z": 4,
      "name": "Rock_Quartzite"
    },
    {
      "x": -7,
      "y": 3,
      "z": 4,
      "name": "Rock_Quartzite"
    },
    {
      "x": -7,
      "y": 4,
      "z": 4,
      "name": "Rock_Quartzite"
    },
    {
      "x": -7,
      "y": 5,
      "z": 4,
      "name": "Rock_Quartzite"
    },
    {
      "x": -7,
      "y": 6,
      "z": 4,
      "name": "Rock_Quartzite_Brick"
    },
    {
      "x": -7,
      "y": 7,
      "z": 4,
      "name": "Rock_Quartzite_Brick"
    },
    {
      "x": -7,
      "y": 8,
      "z": 4,
      "name": "Rock_Quartzite_Brick"
    },
    {
      "x": -7,
      "y": 17,
      "z": 4,
      "name": "Rock_Stone_Brick_Smooth_Half"
    },
    {
      "x": -7,
      "y": 22,
      "z": 4,
      "name": "Rock_Stone_Brick_Smooth"
    },
    {
      "x": -7,
      "y": 2,
      "z": 5,
      "name": "Rock_Quartzite"
    },
    {
      "x": -7,
      "y": 3,
      "z": 5,
      "name": "Rock_Quartzite"
    },
    {
      "x": -7,
      "y": 4,
      "z": 5,
      "name": "Rock_Quartzite"
    },
    {
      "x": -7,
      "y": 5,
      "z": 5,
      "name": "Rock_Quartzite"
    },
    {
      "x": -7,
      "y": 6,
      "z": 5,
      "name": "Rock_Quartzite_Brick"
    },
    {
      "x": -7,
      "y": 7,
      "z": 5,
      "name": "Rock_Quartzite_Brick"
    },
    {
      "x": -7,
      "y": 8,
      "z": 5,
      "name": "Rock_Quartzite_Brick"
    },
    {
      "x": -7,
      "y": 9,
      "z": 5,
      "name": "Rock_Quartzite_Brick_Stairs",
      "rotation": 3
    },
    {
      "x": -7,
      "y": 16,
      "z": 5,
      "name": "Rock_Quartzite_Brick_Half",
      "rotation": 7
    },
    {
      "x": -7,
      "y": 17,
      "z": 5,
      "name": "Rock_Stone_Brick_Smooth_Half"
    },
    {
      "x": -7,
      "y": 22,
      "z": 5,
      "name": "Rock_Stone_Brick_Smooth"
    },
    {
      "x": -7,
      "y": 2,
      "z": 6,
      "name": "Rock_Quartzite"
    },
    {
      "x": -7,
      "y": 3,
      "z": 6,
      "name": "Rock_Quartzite"
    },
    {
      "x": -7,
      "y": 4,
      "z": 6,
      "name": "Rock_Quartzite"
    },
    {
      "x": -7,
      "y": 5,
      "z": 6,
      "name": "Rock_Quartzite"
    },
    {
      "x": -7,
      "y": 6,
      "z": 6,
      "name": "Rock_Quartzite"
    },
    {
      "x": -7,
      "y": 7,
      "z": 6,
      "name": "Rock_Quartzite_Brick"
    },
    {
      "x": -7,
      "y": 8,
      "z": 6,
      "name": "Rock_Quartzite_Brick"
    },
    {
      "x": -7,
      "y": 9,
      "z": 6,
      "name": "Rock_Quartzite_Brick_Stairs",
      "rotation": 3
    },
    {
      "x": -7,
      "y": 16,
      "z": 6,
      "name": "Rock_Quartzite_Brick_Half",
      "rotation": 7
    },
    {
      "x": -7,
      "y": 17,
      "z": 6,
      "name": "Rock_Stone_Brick_Smooth_Half"
    },
    {
      "x": -7,
      "y": 22,
      "z": 6,
      "name": "Rock_Stone_Brick_Smooth"
    },
    {
      "x": -7,
      "y": 5,
      "z": 7,
      "name": "Rock_Quartzite"
    },
    {
      "x": -7,
      "y": 6,
      "z": 7,
      "name": "Rock_Quartzite"
    },
    {
      "x": -7,
      "y": 7,
      "z": 7,
      "name": "Rock_Quartzite_Brick"
    },
    {
      "x": -7,
      "y": 8,
      "z": 7,
      "name": "Rock_Quartzite_Brick"
    },
    {
      "x": -7,
      "y": 9,
      "z": 7,
      "name": "Rock_Quartzite_Brick_Stairs",
      "rotation": 3
    },
    {
      "x": -7,
      "y": 16,
      "z": 7,
      "name": "Rock_Quartzite_Brick_Half",
      "rotation": 7
    },
    {
      "x": -7,
      "y": 17,
      "z": 7,
      "name": "Rock_Stone_Brick_Smooth_Half"
    },
    {
      "x": -7,
      "y": 22,
      "z": 7,
      "name": "Rock_Stone_Brick_Smooth"
    },
    {
      "x": -7,
      "y": 6,
      "z": 8,
      "name": "Rock_Quartzite_Cobble"
    },
    {
      "x": -7,
      "y": 7,
      "z": 8,
      "name": "Rock_Quartzite_Cobble"
    },
    {
      "x": -7,
      "y": 8,
      "z": 8,
      "name": "Rock_Quartzite_Brick"
    },
    {
      "x": -7,
      "y": 17,
      "z": 8,
      "name": "Rock_Stone_Brick_Smooth_Half"
    },
    {
      "x": -7,
      "y": 22,
      "z": 8,
      "name": "Rock_Stone_Brick_Smooth"
    },
    {
      "x": -6,
      "y": 2,
      "z": -6,
      "name": "Rock_Quartzite"
    },
    {
      "x": -6,
      "y": 3,
      "z": -6,
      "name": "Rock_Quartzite"
    },
    {
      "x": -6,
      "y": 4,
      "z": -6,
      "name": "Rock_Quartzite"
    },
    {
      "x": -6,
      "y": 5,
      "z": -6,
      "name": "Rock_Quartzite_Cobble"
    },
    {
      "x": -6,
      "y": 6,
      "z": -6,
      "name": "Rock_Quartzite_Cobble"
    },
    {
      "x": -6,
      "y": 7,
      "z": -6,
      "name": "Rock_Quartzite_Brick"
    },
    {
      "x": -6,
      "y": 8,
      "z": -6,
      "name": "Rock_Quartzite_Brick"
    },
    {
      "x": -6,
      "y": 9,
      "z": -6,
      "name": "Rock_Quartzite_Brick_Stairs",
      "rotation": 2
    },
    {
      "x": -6,
      "y": 16,
      "z": -6,
      "name": "Rock_Quartzite_Brick_Half",
      "rotation": 6
    },
    {
      "x": -6,
      "y": 17,
      "z": -6,
      "name": "Rock_Stone_Brick_Smooth_Half"
    },
    {
      "x": -6,
      "y": 22,
      "z": -6,
      "name": "Rock_Stone_Brick_Smooth"
    },
    {
      "x": -6,
      "y": 23,
      "z": -6,
      "name": "Plant_Moss_Rug_Green"
    },
    {
      "x": -6,
      "y": 2,
      "z": -5,
      "name": "Rock_Quartzite"
    },
    {
      "x": -6,
      "y": 3,
      "z": -5,
      "name": "Rock_Quartzite"
    },
    {
      "x": -6,
      "y": 4,
      "z": -5,
      "name": "Rock_Quartzite"
    },
    {
      "x": -6,
      "y": 5,
      "z": -5,
      "name": "Rock_Quartzite"
    },
    {
      "x": -6,
      "y": 6,
      "z": -5,
      "name": "Rock_Quartzite"
    },
    {
      "x": -6,
      "y": 7,
      "z": -5,
      "name": "Rock_Quartzite"
    },
    {
      "x": -6,
      "y": 8,
      "z": -5,
      "name": "Rock_Quartzite_Brick"
    },
    {
      "x": -6,
      "y": 9,
      "z": -5,
      "name": "Rock_Quartzite_Brick_Smooth"
    },
    {
      "x": -6,
      "y": 10,
      "z": -5,
      "name": "Rock_Quartzite_Brick_Smooth"
    },
    {
      "x": -6,
      "y": 11,
      "z": -5,
      "name": "Rock_Quartzite"
    },
    {
      "x": -6,
      "y": 12,
      "z": -5,
      "name": "Rock_Quartzite"
    },
    {
      "x": -6,
      "y": 13,
      "z": -5,
      "name": "Rock_Quartzite"
    },
    {
      "x": -6,
      "y": 14,
      "z": -5,
      "name": "Rock_Quartzite"
    },
    {
      "x": -6,
      "y": 15,
      "z": -5,
      "name": "Rock_Quartzite_Brick_Smooth"
    },
    {
      "x": -6,
      "y": 16,
      "z": -5,
      "name": "Rock_Quartzite_Brick_Smooth"
    },
    {
      "x": -6,
      "y": 17,
      "z": -5,
      "name": "Rock_Quartzite_Brick"
    },
    {
      "x": -6,
      "y": 18,
      "z": -5,
      "name": "Rock_Quartzite_Brick"
    },
    {
      "x": -6,
      "y": 19,
      "z": -5,
      "name": "Rock_Quartzite_Brick"
    },
    {
      "x": -6,
      "y": 20,
      "z": -5,
      "name": "Rock_Quartzite_Brick"
    },
    {
      "x": -6,
      "y": 21,
      "z": -5,
      "name": "Rock_Quartzite_Brick"
    },
    {
      "x": -6,
      "y": 22,
      "z": -5,
      "name": "Rock_Stone_Brick_Smooth"
    },
    {
      "x": -6,
      "y": 23,
      "z": -5,
      "name": "Plant_Moss_Rug_Green"
    },
    {
      "x": -6,
      "y": 2,
      "z": -4,
      "name": "Rock_Quartzite"
    },
    {
      "x": -6,
      "y": 3,
      "z": -4,
      "name": "Rock_Quartzite"
    },
    {
      "x": -6,
      "y": 4,
      "z": -4,
      "name": "Rock_Quartzite"
    },
    {
      "x": -6,
      "y": 5,
      "z": -4,
      "name": "Rock_Quartzite"
    },
    {
      "x": -6,
      "y": 6,
      "z": -4,
      "name": "Rock_Quartzite"
    },
    {
      "x": -6,
      "y": 7,
      "z": -4,
      "name": "Rock_Quartzite"
    },
    {
      "x": -6,
      "y": 8,
      "z": -4,
      "name": "Rock_Quartzite_Brick"
    },
    {
      "x": -6,
      "y": 9,
      "z": -4,
      "name": "Rock_Quartzite_Brick_Smooth"
    },
    {
      "x": -6,
      "y": 10,
      "z": -4,
      "name": "Rock_Quartzite_Brick_Smooth"
    },
    {
      "x": -6,
      "y": 11,
      "z": -4,
      "name": "Rock_Quartzite"
    },
    {
      "x": -6,
      "y": 12,
      "z": -4,
      "name": "Rock_Quartzite"
    },
    {
      "x": -6,
      "y": 13,
      "z": -4,
      "name": "Rock_Quartzite"
    },
    {
      "x": -6,
      "y": 14,
      "z": -4,
      "name": "Rock_Quartzite"
    },
    {
      "x": -6,
      "y": 15,
      "z": -4,
      "name": "Rock_Quartzite_Brick_Smooth"
    },
    {
      "x": -6,
      "y": 16,
      "z": -4,
      "name": "Rock_Quartzite_Brick_Smooth"
    },
    {
      "x": -6,
      "y": 17,
      "z": -4,
      "name": "Rock_Quartzite_Cobble"
    },
    {
      "x": -6,
      "y": 18,
      "z": -4,
      "name": "Rock_Quartzite_Brick"
    },
    {
      "x": -6,
      "y": 19,
      "z": -4,
      "name": "Rock_Quartzite_Brick"
    },
    {
      "x": -6,
      "y": 20,
      "z": -4,
      "name": "Rock_Quartzite_Brick"
    },
    {
      "x": -6,
      "y": 21,
      "z": -4,
      "name": "Rock_Quartzite_Cobble"
    },
    {
      "x": -6,
      "y": 22,
      "z": -4,
      "name": "Rock_Stone_Brick_Smooth_Half"
    },
    {
      "x": -6,
      "y": 2,
      "z": -3,
      "name": "Rock_Quartzite"
    },
    {
      "x": -6,
      "y": 3,
      "z": -3,
      "name": "Rock_Quartzite"
    },
    {
      "x": -6,
      "y": 4,
      "z": -3,
      "name": "Rock_Quartzite"
    },
    {
      "x": -6,
      "y": 5,
      "z": -3,
      "name": "Rock_Quartzite"
    },
    {
      "x": -6,
      "y": 6,
      "z": -3,
      "name": "Rock_Quartzite"
    },
    {
      "x": -6,
      "y": 7,
      "z": -3,
      "name": "Rock_Quartzite"
    },
    {
      "x": -6,
      "y": 8,
      "z": -3,
      "name": "Rock_Quartzite_Brick"
    },
    {
      "x": -6,
      "y": 9,
      "z": -3,
      "name": "Rock_Quartzite_Brick_Smooth"
    },
    {
      "x": -6,
      "y": 10,
      "z": -3,
      "name": "Rock_Quartzite_Brick_Smooth"
    },
    {
      "x": -6,
      "y": 11,
      "z": -3,
      "name": "Rock_Quartzite"
    },
    {
      "x": -6,
      "y": 12,
      "z": -3,
      "name": "Rock_Quartzite"
    },
    {
      "x": -6,
      "y": 13,
      "z": -3,
      "name": "Rock_Quartzite"
    },
    {
      "x": -6,
      "y": 14,
      "z": -3,
      "name": "Rock_Quartzite"
    },
    {
      "x": -6,
      "y": 15,
      "z": -3,
      "name": "Rock_Quartzite_Brick_Smooth"
    },
    {
      "x": -6,
      "y": 16,
      "z": -3,
      "name": "Rock_Quartzite_Brick_Smooth"
    },
    {
      "x": -6,
      "y": 17,
      "z": -3,
      "name": "Rock_Quartzite_Cobble"
    },
    {
      "x": -6,
      "y": 18,
      "z": -3,
      "name": "Rock_Quartzite_Cobble"
    },
    {
      "x": -6,
      "y": 19,
      "z": -3,
      "name": "Rock_Quartzite_Cobble"
    },
    {
      "x": -6,
      "y": 20,
      "z": -3,
      "name": "Rock_Quartzite_Brick"
    },
    {
      "x": -6,
      "y": 21,
      "z": -3,
      "name": "Rock_Quartzite_Cobble"
    },
    {
      "x": -6,
      "y": 22,
      "z": -3,
      "name": "Rock_Stone_Brick_Smooth_Half"
    },
    {
      "x": -6,
      "y": 3,
      "z": -2,
      "name": "Rock_Quartzite"
    },
    {
      "x": -6,
      "y": 4,
      "z": -2,
      "name": "Rock_Quartzite"
    },
    {
      "x": -6,
      "y": 5,
      "z": -2,
      "name": "Rock_Quartzite"
    },
    {
      "x": -6,
      "y": 6,
      "z": -2,
      "name": "Rock_Quartzite_Brick"
    },
    {
      "x": -6,
      "y": 7,
      "z": -2,
      "name": "Rock_Quartzite_Brick"
    },
    {
      "x": -6,
      "y": 8,
      "z": -2,
      "name": "Rock_Quartzite_Brick"
    },
    {
      "x": -6,
      "y": 9,
      "z": -2,
      "name": "Rock_Quartzite_Brick_Stairs"
    },
    {
      "x": -6,
      "y": 16,
      "z": -2,
      "name": "Rock_Quartzite_Brick_Half",
      "rotation": 4
    },
    {
      "x": -6,
      "y": 17,
      "z": -2,
      "name": "Rock_Stone_Brick_Smooth_Half"
    },
    {
      "x": -6,
      "y": 16,
      "z": -1,
      "name": "Plant_Vine",
      "rotation": 3
    },
    {
      "x": -6,
      "y": 17,
      "z": -1,
      "name": "Plant_Vine",
      "rotation": 3
    },
    {
      "x": -6,
      "y": 18,
      "z": -1,
      "name": "Plant_Vine",
      "rotation": 3
    },
    {
      "x": -6,
      "y": 15,
      "z": 0,
      "name": "Plant_Vine_Wall",
      "rotation": 3
    },
    {
      "x": -6,
      "y": 16,
      "z": 0,
      "name": "Plant_Vine",
      "rotation": 3
    },
    {
      "x": -6,
      "y": 17,
      "z": 0,
      "name": "Plant_Vine",
      "rotation": 3
    },
    {
      "x": -6,
      "y": 21,
      "z": 0,
      "name": "Rock_Quartzite_Brick"
    },
    {
      "x": -6,
      "y": 22,
      "z": 0,
      "name": "Soil_Grass"
    },
    {
      "x": -6,
      "y": 21,
      "z": 1,
      "name": "Rock_Quartzite_Brick"
    },
    {
      "x": -6,
      "y": 22,
      "z": 1,
      "name": "Soil_Grass"
    },
    {
      "x": -6,
      "y": 23,
      "z": 1,
      "name": "Plant_Grass_Sharp"
    },
    {
      "x": -6,
      "y": 21,
      "z": 2,
      "name": "Rock_Quartzite_Brick"
    },
    {
      "x": -6,
      "y": 22,
      "z": 2,
      "name": "Rock_Stone_Brick_Smooth"
    },
    {
      "x": -6,
      "y": 23,
      "z": 2,
      "name": "Plant_Moss_Rug_Green"
    },
    {
      "x": -6,
      "y": 20,
      "z": 3,
      "name": "Rock_Quartzite_Brick_Half",
      "rotation": 8
    },
    {
      "x": -6,
      "y": 21,
      "z": 3,
      "name": "Rock_Quartzite_Brick"
    },
    {
      "x": -6,
      "y": 22,
      "z": 3,
      "name": "Rock_Stone_Brick_Smooth"
    },
    {
      "x": -6,
      "y": 23,
      "z": 3,
      "name": "Plant_Moss_Rug_Green"
    },
    {
      "x": -6,
      "y": 2,
      "z": 4,
      "name": "Rock_Quartzite"
    },
    {
      "x": -6,
      "y": 3,
      "z": 4,
      "name": "Rock_Quartzite"
    },
    {
      "x": -6,
      "y": 4,
      "z": 4,
      "name": "Rock_Quartzite"
    },
    {
      "x": -6,
      "y": 5,
      "z": 4,
      "name": "Rock_Quartzite"
    },
    {
      "x": -6,
      "y": 6,
      "z": 4,
      "name": "Rock_Quartzite"
    },
    {
      "x": -6,
      "y": 7,
      "z": 4,
      "name": "Rock_Quartzite"
    },
    {
      "x": -6,
      "y": 8,
      "z": 4,
      "name": "Rock_Quartzite_Brick"
    },
    {
      "x": -6,
      "y": 9,
      "z": 4,
      "name": "Rock_Quartzite_Brick_Stairs",
      "rotation": 2
    },
    {
      "x": -6,
      "y": 16,
      "z": 4,
      "name": "Rock_Quartzite_Brick_Half",
      "rotation": 6
    },
    {
      "x": -6,
      "y": 17,
      "z": 4,
      "name": "Rock_Stone_Brick_Smooth_Half"
    },
    {
      "x": -6,
      "y": 19,
      "z": 4,
      "name": "Rock_Quartzite_Brick_Half",
      "rotation": 6
    },
    {
      "x": -6,
      "y": 20,
      "z": 4,
      "name": "Rock_Quartzite_Brick"
    },
    {
      "x": -6,
      "y": 21,
      "z": 4,
      "name": "Rock_Quartzite_Brick"
    },
    {
      "x": -6,
      "y": 22,
      "z": 4,
      "name": "Rock_Stone_Brick_Smooth"
    },
    {
      "x": -6,
      "y": 2,
      "z": 5,
      "name": "Rock_Quartzite"
    },
    {
      "x": -6,
      "y": 3,
      "z": 5,
      "name": "Rock_Quartzite"
    },
    {
      "x": -6,
      "y": 4,
      "z": 5,
      "name": "Rock_Quartzite"
    },
    {
      "x": -6,
      "y": 5,
      "z": 5,
      "name": "Rock_Quartzite"
    },
    {
      "x": -6,
      "y": 6,
      "z": 5,
      "name": "Rock_Quartzite"
    },
    {
      "x": -6,
      "y": 7,
      "z": 5,
      "name": "Rock_Quartzite"
    },
    {
      "x": -6,
      "y": 8,
      "z": 5,
      "name": "Rock_Quartzite_Brick"
    },
    {
      "x": -6,
      "y": 9,
      "z": 5,
      "name": "Rock_Quartzite_Brick_Smooth"
    },
    {
      "x": -6,
      "y": 10,
      "z": 5,
      "name": "Rock_Quartzite_Brick_Smooth"
    },
    {
      "x": -6,
      "y": 11,
      "z": 5,
      "name": "Rock_Quartzite"
    },
    {
      "x": -6,
      "y": 12,
      "z": 5,
      "name": "Rock_Quartzite"
    },
    {
      "x": -6,
      "y": 13,
      "z": 5,
      "name": "Rock_Quartzite"
    },
    {
      "x": -6,
      "y": 14,
      "z": 5,
      "name": "Rock_Quartzite"
    },
    {
      "x": -6,
      "y": 15,
      "z": 5,
      "name": "Rock_Quartzite_Brick_Smooth"
    },
    {
      "x": -6,
      "y": 16,
      "z": 5,
      "name": "Rock_Quartzite_Brick_Smooth"
    },
    {
      "x": -6,
      "y": 17,
      "z": 5,
      "name": "Rock_Quartzite_Brick"
    },
    {
      "x": -6,
      "y": 18,
      "z": 5,
      "name": "Rock_Quartzite_Brick"
    },
    {
      "x": -6,
      "y": 19,
      "z": 5,
      "name": "Rock_Quartzite_Brick"
    },
    {
      "x": -6,
      "y": 20,
      "z": 5,
      "name": "Rock_Quartzite_Brick"
    },
    {
      "x": -6,
      "y": 21,
      "z": 5,
      "name": "Rock_Quartzite_Brick"
    },
    {
      "x": -6,
      "y": 22,
      "z": 5,
      "name": "Rock_Stone_Brick_Smooth"
    },
    {
      "x": -6,
      "y": 2,
      "z": 6,
      "name": "Rock_Quartzite"
    },
    {
      "x": -6,
      "y": 3,
      "z": 6,
      "name": "Rock_Quartzite"
    },
    {
      "x": -6,
      "y": 4,
      "z": 6,
      "name": "Rock_Quartzite"
    },
    {
      "x": -6,
      "y": 5,
      "z": 6,
      "name": "Rock_Quartzite"
    },
    {
      "x": -6,
      "y": 6,
      "z": 6,
      "name": "Rock_Quartzite"
    },
    {
      "x": -6,
      "y": 7,
      "z": 6,
      "name": "Rock_Quartzite"
    },
    {
      "x": -6,
      "y": 8,
      "z": 6,
      "name": "Rock_Quartzite_Brick"
    },
    {
      "x": -6,
      "y": 9,
      "z": 6,
      "name": "Rock_Quartzite_Brick_Smooth"
    },
    {
      "x": -6,
      "y": 10,
      "z": 6,
      "name": "Rock_Quartzite_Brick_Smooth"
    },
    {
      "x": -6,
      "y": 11,
      "z": 6,
      "name": "Rock_Quartzite"
    },
    {
      "x": -6,
      "y": 12,
      "z": 6,
      "name": "Rock_Quartzite"
    },
    {
      "x": -6,
      "y": 13,
      "z": 6,
      "name": "Rock_Quartzite"
    },
    {
      "x": -6,
      "y": 14,
      "z": 6,
      "name": "Rock_Quartzite"
    },
    {
      "x": -6,
      "y": 15,
      "z": 6,
      "name": "Rock_Quartzite_Brick_Smooth"
    },
    {
      "x": -6,
      "y": 16,
      "z": 6,
      "name": "Rock_Quartzite_Brick_Smooth"
    },
    {
      "x": -6,
      "y": 17,
      "z": 6,
      "name": "Rock_Quartzite_Brick"
    },
    {
      "x": -6,
      "y": 18,
      "z": 6,
      "name": "Rock_Quartzite_Brick"
    },
    {
      "x": -6,
      "y": 19,
      "z": 6,
      "name": "Rock_Quartzite_Brick"
    },
    {
      "x": -6,
      "y": 20,
      "z": 6,
      "name": "Rock_Quartzite_Brick"
    },
    {
      "x": -6,
      "y": 21,
      "z": 6,
      "name": "Rock_Quartzite_Brick"
    },
    {
      "x": -6,
      "y": 22,
      "z": 6,
      "name": "Rock_Stone_Brick_Smooth"
    },
    {
      "x": -6,
      "y": 2,
      "z": 7,
      "name": "Rock_Quartzite"
    },
    {
      "x": -6,
      "y": 3,
      "z": 7,
      "name": "Rock_Quartzite"
    },
    {
      "x": -6,
      "y": 4,
      "z": 7,
      "name": "Rock_Quartzite"
    },
    {
      "x": -6,
      "y": 5,
      "z": 7,
      "name": "Rock_Quartzite"
    },
    {
      "x": -6,
      "y": 6,
      "z": 7,
      "name": "Rock_Quartzite"
    },
    {
      "x": -6,
      "y": 7,
      "z": 7,
      "name": "Rock_Quartzite"
    },
    {
      "x": -6,
      "y": 8,
      "z": 7,
      "name": "Rock_Quartzite_Brick"
    },
    {
      "x": -6,
      "y": 9,
      "z": 7,
      "name": "Rock_Quartzite_Brick_Smooth"
    },
    {
      "x": -6,
      "y": 10,
      "z": 7,
      "name": "Rock_Quartzite_Brick_Smooth"
    },
    {
      "x": -6,
      "y": 11,
      "z": 7,
      "name": "Rock_Quartzite"
    },
    {
      "x": -6,
      "y": 12,
      "z": 7,
      "name": "Rock_Quartzite"
    },
    {
      "x": -6,
      "y": 13,
      "z": 7,
      "name": "Rock_Quartzite"
    },
    {
      "x": -6,
      "y": 14,
      "z": 7,
      "name": "Rock_Quartzite"
    },
    {
      "x": -6,
      "y": 15,
      "z": 7,
      "name": "Rock_Quartzite_Brick_Smooth"
    },
    {
      "x": -6,
      "y": 16,
      "z": 7,
      "name": "Rock_Quartzite_Brick_Smooth"
    },
    {
      "x": -6,
      "y": 17,
      "z": 7,
      "name": "Rock_Quartzite_Brick"
    },
    {
      "x": -6,
      "y": 19,
      "z": 7,
      "name": "Rock_Quartzite_Cobble_Half",
      "rotation": 4
    },
    {
      "x": -6,
      "y": 20,
      "z": 7,
      "name": "Rock_Quartzite_Brick"
    },
    {
      "x": -6,
      "y": 21,
      "z": 7,
      "name": "Rock_Quartzite_Brick"
    },
    {
      "x": -6,
      "y": 22,
      "z": 7,
      "name": "Rock_Stone_Brick_Smooth"
    },
    {
      "x": -6,
      "y": 4,
      "z": 8,
      "name": "Rock_Quartzite_Cobble"
    },
    {
      "x": -6,
      "y": 5,
      "z": 8,
      "name": "Rock_Quartzite_Cobble"
    },
    {
      "x": -6,
      "y": 6,
      "z": 8,
      "name": "Rock_Quartzite_Cobble"
    },
    {
      "x": -6,
      "y": 7,
      "z": 8,
      "name": "Rock_Quartzite_Cobble"
    },
    {
      "x": -6,
      "y": 8,
      "z": 8,
      "name": "Rock_Quartzite_Brick"
    },
    {
      "x": -6,
      "y": 9,
      "z": 8,
      "name": "Rock_Quartzite_Brick_Stairs"
    },
    {
      "x": -6,
      "y": 16,
      "z": 8,
      "name": "Rock_Quartzite_Brick_Half",
      "rotation": 4
    },
    {
      "x": -6,
      "y": 17,
      "z": 8,
      "name": "Rock_Stone_Brick_Smooth_Half"
    },
    {
      "x": -6,
      "y": 22,
      "z": 8,
      "name": "Rock_Stone_Brick_Smooth"
    },
    {
      "x": -5,
      "y": 2,
      "z": -6,
      "name": "Rock_Quartzite"
    },
    {
      "x": -5,
      "y": 3,
      "z": -6,
      "name": "Rock_Quartzite"
    },
    {
      "x": -5,
      "y": 4,
      "z": -6,
      "name": "Rock_Quartzite"
    },
    {
      "x": -5,
      "y": 5,
      "z": -6,
      "name": "Rock_Quartzite_Cobble"
    },
    {
      "x": -5,
      "y": 6,
      "z": -6,
      "name": "Rock_Quartzite_Cobble"
    },
    {
      "x": -5,
      "y": 7,
      "z": -6,
      "name": "Rock_Quartzite_Brick"
    },
    {
      "x": -5,
      "y": 8,
      "z": -6,
      "name": "Rock_Quartzite_Brick"
    },
    {
      "x": -5,
      "y": 9,
      "z": -6,
      "name": "Rock_Quartzite_Brick_Stairs",
      "rotation": 2
    },
    {
      "x": -5,
      "y": 16,
      "z": -6,
      "name": "Rock_Quartzite_Brick_Half",
      "rotation": 6
    },
    {
      "x": -5,
      "y": 17,
      "z": -6,
      "name": "Rock_Stone_Brick_Smooth_Half"
    },
    {
      "x": -5,
      "y": 22,
      "z": -6,
      "name": "Rock_Stone_Brick_Smooth"
    },
    {
      "x": -5,
      "y": 2,
      "z": -5,
      "name": "Rock_Quartzite"
    },
    {
      "x": -5,
      "y": 3,
      "z": -5,
      "name": "Rock_Quartzite"
    },
    {
      "x": -5,
      "y": 4,
      "z": -5,
      "name": "Rock_Quartzite"
    },
    {
      "x": -5,
      "y": 5,
      "z": -5,
      "name": "Rock_Quartzite"
    },
    {
      "x": -5,
      "y": 6,
      "z": -5,
      "name": "Rock_Quartzite"
    },
    {
      "x": -5,
      "y": 7,
      "z": -5,
      "name": "Rock_Quartzite"
    },
    {
      "x": -5,
      "y": 8,
      "z": -5,
      "name": "Rock_Quartzite_Brick"
    },
    {
      "x": -5,
      "y": 9,
      "z": -5,
      "name": "Rock_Quartzite_Brick_Smooth"
    },
    {
      "x": -5,
      "y": 10,
      "z": -5,
      "name": "Rock_Quartzite_Brick_Smooth"
    },
    {
      "x": -5,
      "y": 11,
      "z": -5,
      "name": "Rock_Quartzite"
    },
    {
      "x": -5,
      "y": 12,
      "z": -5,
      "name": "Rock_Quartzite"
    },
    {
      "x": -5,
      "y": 13,
      "z": -5,
      "name": "Rock_Quartzite"
    },
    {
      "x": -5,
      "y": 14,
      "z": -5,
      "name": "Rock_Quartzite"
    },
    {
      "x": -5,
      "y": 15,
      "z": -5,
      "name": "Rock_Quartzite_Brick_Smooth"
    },
    {
      "x": -5,
      "y": 16,
      "z": -5,
      "name": "Rock_Quartzite_Brick_Smooth"
    },
    {
      "x": -5,
      "y": 17,
      "z": -5,
      "name": "Rock_Quartzite_Brick"
    },
    {
      "x": -5,
      "y": 18,
      "z": -5,
      "name": "Rock_Quartzite_Brick"
    },
    {
      "x": -5,
      "y": 19,
      "z": -5,
      "name": "Rock_Quartzite_Brick"
    },
    {
      "x": -5,
      "y": 20,
      "z": -5,
      "name": "Rock_Quartzite_Brick"
    },
    {
      "x": -5,
      "y": 21,
      "z": -5,
      "name": "Rock_Quartzite_Brick"
    },
    {
      "x": -5,
      "y": 22,
      "z": -5,
      "name": "Rock_Stone_Brick_Smooth"
    },
    {
      "x": -5,
      "y": 23,
      "z": -5,
      "name": "Plant_Moss_Rug_Green"
    },
    {
      "x": -5,
      "y": 2,
      "z": -4,
      "name": "Rock_Quartzite"
    },
    {
      "x": -5,
      "y": 3,
      "z": -4,
      "name": "Rock_Quartzite"
    },
    {
      "x": -5,
      "y": 4,
      "z": -4,
      "name": "Rock_Quartzite"
    },
    {
      "x": -5,
      "y": 5,
      "z": -4,
      "name": "Rock_Quartzite"
    },
    {
      "x": -5,
      "y": 6,
      "z": -4,
      "name": "Rock_Quartzite"
    },
    {
      "x": -5,
      "y": 7,
      "z": -4,
      "name": "Rock_Quartzite"
    },
    {
      "x": -5,
      "y": 8,
      "z": -4,
      "name": "Rock_Quartzite"
    },
    {
      "x": -5,
      "y": 9,
      "z": -4,
      "name": "Rock_Quartzite"
    },
    {
      "x": -5,
      "y": 10,
      "z": -4,
      "name": "Rock_Quartzite"
    },
    {
      "x": -5,
      "y": 11,
      "z": -4,
      "name": "Rock_Quartzite"
    },
    {
      "x": -5,
      "y": 12,
      "z": -4,
      "name": "Rock_Quartzite"
    },
    {
      "x": -5,
      "y": 13,
      "z": -4,
      "name": "Rock_Quartzite"
    },
    {
      "x": -5,
      "y": 14,
      "z": -4,
      "name": "Rock_Quartzite"
    },
    {
      "x": -5,
      "y": 15,
      "z": -4,
      "name": "Rock_Quartzite_Brick_Smooth"
    },
    {
      "x": -5,
      "y": 16,
      "z": -4,
      "name": "Rock_Quartzite_Brick_Smooth"
    },
    {
      "x": -5,
      "y": 17,
      "z": -4,
      "name": "Rock_Quartzite_Brick"
    },
    {
      "x": -5,
      "y": 18,
      "z": -4,
      "name": "Rock_Quartzite_Brick"
    },
    {
      "x": -5,
      "y": 19,
      "z": -4,
      "name": "Rock_Quartzite_Brick"
    },
    {
      "x": -5,
      "y": 20,
      "z": -4,
      "name": "Rock_Quartzite_Brick"
    },
    {
      "x": -5,
      "y": 21,
      "z": -4,
      "name": "Rock_Quartzite_Brick"
    },
    {
      "x": -5,
      "y": 22,
      "z": -4,
      "name": "Soil_Grass"
    },
    {
      "x": -5,
      "y": 23,
      "z": -4,
      "name": "Plant_Grass_Lush"
    },
    {
      "x": -5,
      "y": 2,
      "z": -3,
      "name": "Rock_Quartzite"
    },
    {
      "x": -5,
      "y": 3,
      "z": -3,
      "name": "Rock_Quartzite"
    },
    {
      "x": -5,
      "y": 4,
      "z": -3,
      "name": "Rock_Quartzite"
    },
    {
      "x": -5,
      "y": 5,
      "z": -3,
      "name": "Rock_Quartzite"
    },
    {
      "x": -5,
      "y": 6,
      "z": -3,
      "name": "Rock_Quartzite"
    },
    {
      "x": -5,
      "y": 7,
      "z": -3,
      "name": "Rock_Quartzite"
    },
    {
      "x": -5,
      "y": 8,
      "z": -3,
      "name": "Rock_Quartzite"
    },
    {
      "x": -5,
      "y": 9,
      "z": -3,
      "name": "Rock_Quartzite"
    },
    {
      "x": -5,
      "y": 10,
      "z": -3,
      "name": "Rock_Quartzite"
    },
    {
      "x": -5,
      "y": 11,
      "z": -3,
      "name": "Rock_Quartzite"
    },
    {
      "x": -5,
      "y": 12,
      "z": -3,
      "name": "Rock_Quartzite"
    },
    {
      "x": -5,
      "y": 13,
      "z": -3,
      "name": "Rock_Quartzite"
    },
    {
      "x": -5,
      "y": 14,
      "z": -3,
      "name": "Rock_Quartzite"
    },
    {
      "x": -5,
      "y": 15,
      "z": -3,
      "name": "Rock_Quartzite_Brick_Smooth"
    },
    {
      "x": -5,
      "y": 16,
      "z": -3,
      "name": "Rock_Quartzite_Brick_Smooth"
    },
    {
      "x": -5,
      "y": 17,
      "z": -3,
      "name": "Rock_Quartzite_Brick"
    },
    {
      "x": -5,
      "y": 18,
      "z": -3,
      "name": "Rock_Quartzite_Brick"
    },
    {
      "x": -5,
      "y": 19,
      "z": -3,
      "name": "Rock_Quartzite_Brick"
    },
    {
      "x": -5,
      "y": 20,
      "z": -3,
      "name": "Rock_Quartzite_Brick"
    },
    {
      "x": -5,
      "y": 21,
      "z": -3,
      "name": "Soil_Dirt"
    },
    {
      "x": -5,
      "y": 22,
      "z": -3,
      "name": "Soil_Grass"
    },
    {
      "x": -5,
      "y": 23,
      "z": -3,
      "name": "Plant_Grass_Sharp_Tall"
    },
    {
      "x": -5,
      "y": 24,
      "z": -3,
      "name": "Plant_Grass_Sharp_Tall",
      "filler": 1024
    },
    {
      "x": -5,
      "y": 2,
      "z": -2,
      "name": "Rock_Quartzite"
    },
    {
      "x": -5,
      "y": 3,
      "z": -2,
      "name": "Rock_Quartzite"
    },
    {
      "x": -5,
      "y": 4,
      "z": -2,
      "name": "Rock_Quartzite"
    },
    {
      "x": -5,
      "y": 5,
      "z": -2,
      "name": "Rock_Quartzite"
    },
    {
      "x": -5,
      "y": 6,
      "z": -2,
      "name": "Rock_Quartzite"
    },
    {
      "x": -5,
      "y": 7,
      "z": -2,
      "name": "Rock_Quartzite"
    },
    {
      "x": -5,
      "y": 8,
      "z": -2,
      "name": "Rock_Quartzite"
    },
    {
      "x": -5,
      "y": 9,
      "z": -2,
      "name": "Rock_Quartzite_Cobble"
    },
    {
      "x": -5,
      "y": 10,
      "z": -2,
      "name": "Soil_Grass"
    },
    {
      "x": -5,
      "y": 11,
      "z": -2,
      "name": "Plant_Grass_Lush"
    },
    {
      "x": -5,
      "y": 12,
      "z": -2,
      "name": "Empty"
    },
    {
      "x": -5,
      "y": 13,
      "z": -2,
      "name": "Empty"
    },
    {
      "x": -5,
      "y": 14,
      "z": -2,
      "name": "Empty"
    },
    {
      "x": -5,
      "y": 15,
      "z": -2,
      "name": "Rock_Quartzite_Cobble_Half",
      "rotation": 7
    },
    {
      "x": -5,
      "y": 16,
      "z": -2,
      "name": "Rock_Quartzite_Cobble"
    },
    {
      "x": -5,
      "y": 17,
      "z": -2,
      "name": "Rock_Quartzite_Brick"
    },
    {
      "x": -5,
      "y": 18,
      "z": -2,
      "name": "Rock_Quartzite_Brick"
    },
    {
      "x": -5,
      "y": 19,
      "z": -2,
      "name": "Soil_Dirt"
    },
    {
      "x": -5,
      "y": 20,
      "z": -2,
      "name": "Soil_Grass"
    },
    {
      "x": -5,
      "y": 21,
      "z": -2,
      "name": "Plant_Grass_Sharp"
    },
    {
      "x": -5,
      "y": 4,
      "z": -1,
      "name": "Rock_Quartzite_Cobble"
    },
    {
      "x": -5,
      "y": 5,
      "z": -1,
      "name": "Rock_Quartzite_Cobble"
    },
    {
      "x": -5,
      "y": 6,
      "z": -1,
      "name": "Rock_Quartzite_Cobble"
    },
    {
      "x": -5,
      "y": 7,
      "z": -1,
      "name": "Rock_Quartzite_Cobble"
    },
    {
      "x": -5,
      "y": 8,
      "z": -1,
      "name": "Rock_Quartzite_Cobble"
    },
    {
      "x": -5,
      "y": 9,
      "z": -1,
      "name": "Rock_Quartzite_Cobble_Half",
      "rotation": 7
    },
    {
      "x": -5,
      "y": 10,
      "z": -1,
      "name": "Empty"
    },
    {
      "x": -5,
      "y": 11,
      "z": -1,
      "name": "Empty"
    },
    {
      "x": -5,
      "y": 12,
      "z": -1,
      "name": "Empty"
    },
    {
      "x": -5,
      "y": 13,
      "z": -1,
      "name": "Empty"
    },
    {
      "x": -5,
      "y": 14,
      "z": -1,
      "name": "Empty"
    },
    {
      "x": -5,
      "y": 15,
      "z": -1,
      "name": "Rock_Quartzite_Cobble_Half",
      "rotation": 7
    },
    {
      "x": -5,
      "y": 16,
      "z": -1,
      "name": "Rock_Quartzite_Cobble"
    },
    {
      "x": -5,
      "y": 17,
      "z": -1,
      "name": "Rock_Quartzite_Cobble"
    },
    {
      "x": -5,
      "y": 18,
      "z": -1,
      "name": "Rock_Quartzite_Brick"
    },
    {
      "x": -5,
      "y": 19,
      "z": -1,
      "name": "Soil_Grass"
    },
    {
      "x": -5,
      "y": 20,
      "z": -1,
      "name": "Plant_Grass_Sharp_Tall"
    },
    {
      "x": -5,
      "y": 21,
      "z": -1,
      "name": "Plant_Grass_Sharp_Tall",
      "filler": 1024
    },
    {
      "x": -5,
      "y": 5,
      "z": 0,
      "name": "Rock_Quartzite_Cobble"
    },
    {
      "x": -5,
      "y": 6,
      "z": 0,
      "name": "Rock_Quartzite_Cobble"
    },
    {
      "x": -5,
      "y": 7,
      "z": 0,
      "name": "Rock_Quartzite_Cobble"
    },
    {
      "x": -5,
      "y": 8,
      "z": 0,
      "name": "Rock_Quartzite"
    },
    {
      "x": -5,
      "y": 9,
      "z": 0,
      "name": "Rock_Quartzite"
    },
    {
      "x": -5,
      "y": 10,
      "z": 0,
      "name": "Rock_Quartzite"
    },
    {
      "x": -5,
      "y": 11,
      "z": 0,
      "name": "Rock_Quartzite"
    },
    {
      "x": -5,
      "y": 12,
      "z": 0,
      "name": "Rock_Quartzite"
    },
    {
      "x": -5,
      "y": 13,
      "z": 0,
      "name": "Rock_Quartzite"
    },
    {
      "x": -5,
      "y": 14,
      "z": 0,
      "name": "Rock_Quartzite"
    },
    {
      "x": -5,
      "y": 15,
      "z": 0,
      "name": "Rock_Quartzite"
    },
    {
      "x": -5,
      "y": 16,
      "z": 0,
      "name": "Rock_Quartzite_Cobble"
    },
    {
      "x": -5,
      "y": 17,
      "z": 0,
      "name": "Rock_Quartzite"
    },
    {
      "x": -5,
      "y": 18,
      "z": 0,
      "name": "Rock_Quartzite"
    },
    {
      "x": -5,
      "y": 19,
      "z": 0,
      "name": "Rock_Quartzite_Brick"
    },
    {
      "x": -5,
      "y": 20,
      "z": 0,
      "name": "Rock_Quartzite_Brick"
    },
    {
      "x": -5,
      "y": 21,
      "z": 0,
      "name": "Rock_Quartzite_Brick"
    },
    {
      "x": -5,
      "y": 22,
      "z": 0,
      "name": "Soil_Grass"
    },
    {
      "x": -5,
      "y": 7,
      "z": 1,
      "name": "Rock_Quartzite"
    },
    {
      "x": -5,
      "y": 8,
      "z": 1,
      "name": "Rock_Quartzite"
    },
    {
      "x": -5,
      "y": 9,
      "z": 1,
      "name": "Rock_Quartzite"
    },
    {
      "x": -5,
      "y": 10,
      "z": 1,
      "name": "Rock_Quartzite"
    },
    {
      "x": -5,
      "y": 11,
      "z": 1,
      "name": "Rock_Quartzite"
    },
    {
      "x": -5,
      "y": 12,
      "z": 1,
      "name": "Rock_Quartzite"
    },
    {
      "x": -5,
      "y": 13,
      "z": 1,
      "name": "Rock_Quartzite"
    },
    {
      "x": -5,
      "y": 14,
      "z": 1,
      "name": "Rock_Quartzite"
    },
    {
      "x": -5,
      "y": 15,
      "z": 1,
      "name": "Rock_Quartzite"
    },
    {
      "x": -5,
      "y": 16,
      "z": 1,
      "name": "Rock_Quartzite"
    },
    {
      "x": -5,
      "y": 17,
      "z": 1,
      "name": "Rock_Quartzite"
    },
    {
      "x": -5,
      "y": 18,
      "z": 1,
      "name": "Rock_Quartzite"
    },
    {
      "x": -5,
      "y": 19,
      "z": 1,
      "name": "Rock_Quartzite_Brick"
    },
    {
      "x": -5,
      "y": 20,
      "z": 1,
      "name": "Rock_Quartzite_Brick"
    },
    {
      "x": -5,
      "y": 21,
      "z": 1,
      "name": "Rock_Quartzite_Brick"
    },
    {
      "x": -5,
      "y": 22,
      "z": 1,
      "name": "Soil_Grass"
    },
    {
      "x": -5,
      "y": 23,
      "z": 1,
      "name": "Plant_Bush"
    },
    {
      "x": -5,
      "y": 4,
      "z": 2,
      "name": "Rock_Quartzite"
    },
    {
      "x": -5,
      "y": 5,
      "z": 2,
      "name": "Rock_Quartzite"
    },
    {
      "x": -5,
      "y": 6,
      "z": 2,
      "name": "Rock_Quartzite"
    },
    {
      "x": -5,
      "y": 7,
      "z": 2,
      "name": "Rock_Quartzite"
    },
    {
      "x": -5,
      "y": 8,
      "z": 2,
      "name": "Rock_Quartzite"
    },
    {
      "x": -5,
      "y": 9,
      "z": 2,
      "name": "Rock_Quartzite"
    },
    {
      "x": -5,
      "y": 10,
      "z": 2,
      "name": "Rock_Quartzite"
    },
    {
      "x": -5,
      "y": 11,
      "z": 2,
      "name": "Rock_Quartzite"
    },
    {
      "x": -5,
      "y": 12,
      "z": 2,
      "name": "Rock_Quartzite"
    },
    {
      "x": -5,
      "y": 13,
      "z": 2,
      "name": "Rock_Quartzite"
    },
    {
      "x": -5,
      "y": 14,
      "z": 2,
      "name": "Rock_Quartzite"
    },
    {
      "x": -5,
      "y": 15,
      "z": 2,
      "name": "Rock_Quartzite"
    },
    {
      "x": -5,
      "y": 16,
      "z": 2,
      "name": "Rock_Quartzite"
    },
    {
      "x": -5,
      "y": 17,
      "z": 2,
      "name": "Rock_Quartzite"
    },
    {
      "x": -5,
      "y": 18,
      "z": 2,
      "name": "Rock_Quartzite"
    },
    {
      "x": -5,
      "y": 19,
      "z": 2,
      "name": "Rock_Quartzite_Brick"
    },
    {
      "x": -5,
      "y": 20,
      "z": 2,
      "name": "Rock_Quartzite_Brick"
    },
    {
      "x": -5,
      "y": 21,
      "z": 2,
      "name": "Rock_Quartzite_Brick"
    },
    {
      "x": -5,
      "y": 22,
      "z": 2,
      "name": "Soil_Grass"
    },
    {
      "x": -5,
      "y": 23,
      "z": 2,
      "name": "Plant_Bush"
    },
    {
      "x": -5,
      "y": 3,
      "z": 3,
      "name": "Rock_Quartzite"
    },
    {
      "x": -5,
      "y": 4,
      "z": 3,
      "name": "Rock_Quartzite"
    },
    {
      "x": -5,
      "y": 5,
      "z": 3,
      "name": "Rock_Quartzite"
    },
    {
      "x": -5,
      "y": 6,
      "z": 3,
      "name": "Rock_Quartzite"
    },
    {
      "x": -5,
      "y": 7,
      "z": 3,
      "name": "Rock_Quartzite"
    },
    {
      "x": -5,
      "y": 8,
      "z": 3,
      "name": "Rock_Quartzite"
    },
    {
      "x": -5,
      "y": 9,
      "z": 3,
      "name": "Rock_Quartzite"
    },
    {
      "x": -5,
      "y": 10,
      "z": 3,
      "name": "Rock_Quartzite"
    },
    {
      "x": -5,
      "y": 11,
      "z": 3,
      "name": "Rock_Quartzite"
    },
    {
      "x": -5,
      "y": 12,
      "z": 3,
      "name": "Rock_Quartzite"
    },
    {
      "x": -5,
      "y": 13,
      "z": 3,
      "name": "Rock_Quartzite"
    },
    {
      "x": -5,
      "y": 14,
      "z": 3,
      "name": "Rock_Quartzite"
    },
    {
      "x": -5,
      "y": 15,
      "z": 3,
      "name": "Rock_Quartzite"
    },
    {
      "x": -5,
      "y": 16,
      "z": 3,
      "name": "Rock_Quartzite"
    },
    {
      "x": -5,
      "y": 17,
      "z": 3,
      "name": "Rock_Quartzite"
    },
    {
      "x": -5,
      "y": 18,
      "z": 3,
      "name": "Rock_Quartzite_Brick"
    },
    {
      "x": -5,
      "y": 19,
      "z": 3,
      "name": "Rock_Quartzite_Brick"
    },
    {
      "x": -5,
      "y": 20,
      "z": 3,
      "name": "Rock_Quartzite_Brick"
    },
    {
      "x": -5,
      "y": 21,
      "z": 3,
      "name": "Rock_Quartzite_Brick"
    },
    {
      "x": -5,
      "y": 22,
      "z": 3,
      "name": "Rock_Stone"
    },
    {
      "x": -5,
      "y": 23,
      "z": 3,
      "name": "Plant_Moss_Rug_Green"
    },
    {
      "x": -5,
      "y": 2,
      "z": 4,
      "name": "Rock_Quartzite"
    },
    {
      "x": -5,
      "y": 3,
      "z": 4,
      "name": "Rock_Quartzite"
    },
    {
      "x": -5,
      "y": 4,
      "z": 4,
      "name": "Rock_Quartzite"
    },
    {
      "x": -5,
      "y": 5,
      "z": 4,
      "name": "Rock_Quartzite"
    },
    {
      "x": -5,
      "y": 6,
      "z": 4,
      "name": "Rock_Quartzite"
    },
    {
      "x": -5,
      "y": 7,
      "z": 4,
      "name": "Rock_Quartzite"
    },
    {
      "x": -5,
      "y": 8,
      "z": 4,
      "name": "Rock_Quartzite_Brick"
    },
    {
      "x": -5,
      "y": 9,
      "z": 4,
      "name": "Rock_Quartzite"
    },
    {
      "x": -5,
      "y": 10,
      "z": 4,
      "name": "Rock_Quartzite"
    },
    {
      "x": -5,
      "y": 11,
      "z": 4,
      "name": "Rock_Quartzite"
    },
    {
      "x": -5,
      "y": 12,
      "z": 4,
      "name": "Rock_Quartzite"
    },
    {
      "x": -5,
      "y": 13,
      "z": 4,
      "name": "Rock_Quartzite"
    },
    {
      "x": -5,
      "y": 14,
      "z": 4,
      "name": "Rock_Quartzite"
    },
    {
      "x": -5,
      "y": 15,
      "z": 4,
      "name": "Rock_Quartzite"
    },
    {
      "x": -5,
      "y": 16,
      "z": 4,
      "name": "Rock_Quartzite"
    },
    {
      "x": -5,
      "y": 17,
      "z": 4,
      "name": "Rock_Quartzite_Brick"
    },
    {
      "x": -5,
      "y": 18,
      "z": 4,
      "name": "Rock_Quartzite_Brick"
    },
    {
      "x": -5,
      "y": 19,
      "z": 4,
      "name": "Rock_Quartzite_Brick"
    },
    {
      "x": -5,
      "y": 20,
      "z": 4,
      "name": "Rock_Quartzite_Brick"
    },
    {
      "x": -5,
      "y": 21,
      "z": 4,
      "name": "Rock_Quartzite_Brick"
    },
    {
      "x": -5,
      "y": 22,
      "z": 4,
      "name": "Rock_Stone_Mossy"
    },
    {
      "x": -5,
      "y": 2,
      "z": 5,
      "name": "Rock_Quartzite"
    },
    {
      "x": -5,
      "y": 3,
      "z": 5,
      "name": "Rock_Quartzite"
    },
    {
      "x": -5,
      "y": 4,
      "z": 5,
      "name": "Rock_Quartzite"
    },
    {
      "x": -5,
      "y": 5,
      "z": 5,
      "name": "Rock_Quartzite"
    },
    {
      "x": -5,
      "y": 6,
      "z": 5,
      "name": "Rock_Quartzite"
    },
    {
      "x": -5,
      "y": 7,
      "z": 5,
      "name": "Rock_Quartzite"
    },
    {
      "x": -5,
      "y": 8,
      "z": 5,
      "name": "Rock_Quartzite_Brick"
    },
    {
      "x": -5,
      "y": 9,
      "z": 5,
      "name": "Rock_Quartzite_Cobble"
    },
    {
      "x": -5,
      "y": 10,
      "z": 5,
      "name": "Rock_Quartzite_Cobble"
    },
    {
      "x": -5,
      "y": 11,
      "z": 5,
      "name": "Rock_Quartzite_Cobble"
    },
    {
      "x": -5,
      "y": 12,
      "z": 5,
      "name": "Rock_Quartzite"
    },
    {
      "x": -5,
      "y": 13,
      "z": 5,
      "name": "Rock_Quartzite"
    },
    {
      "x": -5,
      "y": 14,
      "z": 5,
      "name": "Rock_Quartzite"
    },
    {
      "x": -5,
      "y": 15,
      "z": 5,
      "name": "Rock_Quartzite_Brick_Smooth"
    },
    {
      "x": -5,
      "y": 16,
      "z": 5,
      "name": "Rock_Quartzite_Brick_Smooth"
    },
    {
      "x": -5,
      "y": 17,
      "z": 5,
      "name": "Rock_Quartzite_Brick"
    },
    {
      "x": -5,
      "y": 18,
      "z": 5,
      "name": "Rock_Quartzite_Brick"
    },
    {
      "x": -5,
      "y": 19,
      "z": 5,
      "name": "Rock_Quartzite_Brick"
    },
    {
      "x": -5,
      "y": 20,
      "z": 5,
      "name": "Rock_Quartzite_Brick"
    },
    {
      "x": -5,
      "y": 21,
      "z": 5,
      "name": "Rock_Quartzite_Brick"
    },
    {
      "x": -5,
      "y": 22,
      "z": 5,
      "name": "Rock_Stone"
    },
    {
      "x": -5,
      "y": 2,
      "z": 6,
      "name": "Rock_Quartzite"
    },
    {
      "x": -5,
      "y": 3,
      "z": 6,
      "name": "Rock_Quartzite"
    },
    {
      "x": -5,
      "y": 4,
      "z": 6,
      "name": "Rock_Quartzite"
    },
    {
      "x": -5,
      "y": 5,
      "z": 6,
      "name": "Rock_Quartzite"
    },
    {
      "x": -5,
      "y": 6,
      "z": 6,
      "name": "Rock_Quartzite"
    },
    {
      "x": -5,
      "y": 7,
      "z": 6,
      "name": "Rock_Quartzite"
    },
    {
      "x": -5,
      "y": 8,
      "z": 6,
      "name": "Rock_Quartzite_Brick"
    },
    {
      "x": -5,
      "y": 9,
      "z": 6,
      "name": "Rock_Quartzite_Cobble_Stairs"
    },
    {
      "x": -5,
      "y": 10,
      "z": 6,
      "name": "Rock_Quartzite_Cobble_Half",
      "rotation": 4
    },
    {
      "x": -5,
      "y": 11,
      "z": 6,
      "name": "Rock_Quartzite_Cobble_Half",
      "rotation": 4
    },
    {
      "x": -5,
      "y": 12,
      "z": 6,
      "name": "Rock_Quartzite"
    },
    {
      "x": -5,
      "y": 13,
      "z": 6,
      "name": "Rock_Quartzite"
    },
    {
      "x": -5,
      "y": 14,
      "z": 6,
      "name": "Rock_Quartzite"
    },
    {
      "x": -5,
      "y": 15,
      "z": 6,
      "name": "Rock_Quartzite_Brick_Smooth"
    },
    {
      "x": -5,
      "y": 16,
      "z": 6,
      "name": "Rock_Quartzite_Brick_Smooth"
    },
    {
      "x": -5,
      "y": 17,
      "z": 6,
      "name": "Rock_Quartzite_Brick"
    },
    {
      "x": -5,
      "y": 18,
      "z": 6,
      "name": "Rock_Quartzite_Brick"
    },
    {
      "x": -5,
      "y": 19,
      "z": 6,
      "name": "Rock_Quartzite_Brick"
    },
    {
      "x": -5,
      "y": 20,
      "z": 6,
      "name": "Rock_Quartzite_Brick"
    },
    {
      "x": -5,
      "y": 21,
      "z": 6,
      "name": "Rock_Quartzite_Brick"
    },
    {
      "x": -5,
      "y": 22,
      "z": 6,
      "name": "Rock_Stone"
    },
    {
      "x": -5,
      "y": 2,
      "z": 7,
      "name": "Rock_Quartzite"
    },
    {
      "x": -5,
      "y": 3,
      "z": 7,
      "name": "Rock_Quartzite"
    },
    {
      "x": -5,
      "y": 4,
      "z": 7,
      "name": "Rock_Quartzite"
    },
    {
      "x": -5,
      "y": 5,
      "z": 7,
      "name": "Rock_Quartzite"
    },
    {
      "x": -5,
      "y": 6,
      "z": 7,
      "name": "Rock_Quartzite"
    },
    {
      "x": -5,
      "y": 7,
      "z": 7,
      "name": "Rock_Quartzite"
    },
    {
      "x": -5,
      "y": 8,
      "z": 7,
      "name": "Rock_Quartzite_Brick"
    },
    {
      "x": -5,
      "y": 9,
      "z": 7,
      "name": "Plant_Moss_Rug_Green"
    },
    {
      "x": -5,
      "y": 13,
      "z": 7,
      "name": "Rock_Quartzite"
    },
    {
      "x": -5,
      "y": 14,
      "z": 7,
      "name": "Rock_Quartzite"
    },
    {
      "x": -5,
      "y": 15,
      "z": 7,
      "name": "Rock_Quartzite_Brick_Smooth"
    },
    {
      "x": -5,
      "y": 16,
      "z": 7,
      "name": "Rock_Quartzite_Brick_Smooth"
    },
    {
      "x": -5,
      "y": 17,
      "z": 7,
      "name": "Rock_Quartzite_Cobble"
    },
    {
      "x": -5,
      "y": 18,
      "z": 7,
      "name": "Rock_Quartzite_Cobble_Half",
      "rotation": 4
    },
    {
      "x": -5,
      "y": 19,
      "z": 7,
      "name": "Rock_Quartzite_Cobble_Half",
      "rotation": 4
    },
    {
      "x": -5,
      "y": 20,
      "z": 7,
      "name": "Rock_Quartzite_Brick"
    },
    {
      "x": -5,
      "y": 21,
      "z": 7,
      "name": "Rock_Quartzite_Brick"
    },
    {
      "x": -5,
      "y": 22,
      "z": 7,
      "name": "Rock_Stone_Brick_Smooth"
    },
    {
      "x": -5,
      "y": 3,
      "z": 8,
      "name": "Rock_Quartzite"
    },
    {
      "x": -5,
      "y": 4,
      "z": 8,
      "name": "Rock_Quartzite"
    },
    {
      "x": -5,
      "y": 5,
      "z": 8,
      "name": "Rock_Quartzite_Cobble"
    },
    {
      "x": -5,
      "y": 6,
      "z": 8,
      "name": "Rock_Quartzite_Brick"
    },
    {
      "x": -5,
      "y": 7,
      "z": 8,
      "name": "Rock_Quartzite_Brick"
    },
    {
      "x": -5,
      "y": 8,
      "z": 8,
      "name": "Rock_Quartzite_Brick"
    },
    {
      "x": -5,
      "y": 9,
      "z": 8,
      "name": "Plant_Moss_Rug_Green"
    },
    {
      "x": -5,
      "y": 16,
      "z": 8,
      "name": "Rock_Quartzite_Brick_Half",
      "rotation": 4
    },
    {
      "x": -5,
      "y": 17,
      "z": 8,
      "name": "Rock_Stone_Brick_Smooth_Half"
    },
    {
      "x": -5,
      "y": 22,
      "z": 8,
      "name": "Rock_Stone_Brick_Smooth"
    },
    {
      "x": -4,
      "y": 4,
      "z": -6,
      "name": "Rock_Quartzite_Brick"
    },
    {
      "x": -4,
      "y": 5,
      "z": -6,
      "name": "Rock_Quartzite_Brick"
    },
    {
      "x": -4,
      "y": 6,
      "z": -6,
      "name": "Rock_Quartzite_Brick"
    },
    {
      "x": -4,
      "y": 7,
      "z": -6,
      "name": "Rock_Quartzite_Brick"
    },
    {
      "x": -4,
      "y": 8,
      "z": -6,
      "name": "Rock_Quartzite_Brick"
    },
    {
      "x": -4,
      "y": 9,
      "z": -6,
      "name": "Rock_Quartzite_Brick_Stairs",
      "rotation": 2
    },
    {
      "x": -4,
      "y": 16,
      "z": -6,
      "name": "Rock_Quartzite_Brick_Half",
      "rotation": 6
    },
    {
      "x": -4,
      "y": 17,
      "z": -6,
      "name": "Rock_Stone_Brick_Smooth_Half"
    },
    {
      "x": -4,
      "y": 22,
      "z": -6,
      "name": "Rock_Stone_Brick_Smooth"
    },
    {
      "x": -4,
      "y": 2,
      "z": -5,
      "name": "Rock_Quartzite"
    },
    {
      "x": -4,
      "y": 3,
      "z": -5,
      "name": "Rock_Quartzite"
    },
    {
      "x": -4,
      "y": 4,
      "z": -5,
      "name": "Rock_Quartzite"
    },
    {
      "x": -4,
      "y": 5,
      "z": -5,
      "name": "Rock_Quartzite"
    },
    {
      "x": -4,
      "y": 6,
      "z": -5,
      "name": "Rock_Quartzite"
    },
    {
      "x": -4,
      "y": 7,
      "z": -5,
      "name": "Rock_Quartzite"
    },
    {
      "x": -4,
      "y": 8,
      "z": -5,
      "name": "Rock_Quartzite_Brick"
    },
    {
      "x": -4,
      "y": 9,
      "z": -5,
      "name": "Rock_Quartzite_Brick_Smooth"
    },
    {
      "x": -4,
      "y": 10,
      "z": -5,
      "name": "Rock_Quartzite_Brick_Smooth"
    },
    {
      "x": -4,
      "y": 11,
      "z": -5,
      "name": "Rock_Quartzite"
    },
    {
      "x": -4,
      "y": 12,
      "z": -5,
      "name": "Rock_Quartzite"
    },
    {
      "x": -4,
      "y": 13,
      "z": -5,
      "name": "Rock_Quartzite"
    },
    {
      "x": -4,
      "y": 14,
      "z": -5,
      "name": "Rock_Quartzite"
    },
    {
      "x": -4,
      "y": 15,
      "z": -5,
      "name": "Rock_Quartzite_Brick_Smooth"
    },
    {
      "x": -4,
      "y": 16,
      "z": -5,
      "name": "Rock_Quartzite_Brick_Smooth"
    },
    {
      "x": -4,
      "y": 17,
      "z": -5,
      "name": "Rock_Quartzite_Brick"
    },
    {
      "x": -4,
      "y": 18,
      "z": -5,
      "name": "Rock_Quartzite_Brick"
    },
    {
      "x": -4,
      "y": 19,
      "z": -5,
      "name": "Rock_Quartzite_Brick"
    },
    {
      "x": -4,
      "y": 20,
      "z": -5,
      "name": "Rock_Quartzite_Brick"
    },
    {
      "x": -4,
      "y": 21,
      "z": -5,
      "name": "Rock_Quartzite_Brick"
    },
    {
      "x": -4,
      "y": 22,
      "z": -5,
      "name": "Rock_Stone_Brick_Smooth"
    },
    {
      "x": -4,
      "y": 23,
      "z": -5,
      "name": "Plant_Moss_Rug_Green"
    },
    {
      "x": -4,
      "y": 2,
      "z": -4,
      "name": "Rock_Quartzite"
    },
    {
      "x": -4,
      "y": 3,
      "z": -4,
      "name": "Rock_Quartzite"
    },
    {
      "x": -4,
      "y": 4,
      "z": -4,
      "name": "Rock_Quartzite"
    },
    {
      "x": -4,
      "y": 5,
      "z": -4,
      "name": "Rock_Quartzite"
    },
    {
      "x": -4,
      "y": 6,
      "z": -4,
      "name": "Rock_Quartzite"
    },
    {
      "x": -4,
      "y": 7,
      "z": -4,
      "name": "Rock_Quartzite"
    },
    {
      "x": -4,
      "y": 8,
      "z": -4,
      "name": "Rock_Quartzite"
    },
    {
      "x": -4,
      "y": 9,
      "z": -4,
      "name": "Rock_Quartzite"
    },
    {
      "x": -4,
      "y": 10,
      "z": -4,
      "name": "Rock_Quartzite"
    },
    {
      "x": -4,
      "y": 11,
      "z": -4,
      "name": "Rock_Quartzite"
    },
    {
      "x": -4,
      "y": 12,
      "z": -4,
      "name": "Rock_Quartzite"
    },
    {
      "x": -4,
      "y": 13,
      "z": -4,
      "name": "Rock_Quartzite"
    },
    {
      "x": -4,
      "y": 14,
      "z": -4,
      "name": "Rock_Quartzite"
    },
    {
      "x": -4,
      "y": 15,
      "z": -4,
      "name": "Rock_Quartzite_Brick_Smooth"
    },
    {
      "x": -4,
      "y": 16,
      "z": -4,
      "name": "Rock_Quartzite_Brick_Smooth"
    },
    {
      "x": -4,
      "y": 17,
      "z": -4,
      "name": "Rock_Quartzite_Brick"
    },
    {
      "x": -4,
      "y": 18,
      "z": -4,
      "name": "Rock_Quartzite_Brick"
    },
    {
      "x": -4,
      "y": 19,
      "z": -4,
      "name": "Rock_Quartzite_Brick"
    },
    {
      "x": -4,
      "y": 20,
      "z": -4,
      "name": "Rock_Quartzite_Brick"
    },
    {
      "x": -4,
      "y": 21,
      "z": -4,
      "name": "Rock_Quartzite_Brick"
    },
    {
      "x": -4,
      "y": 22,
      "z": -4,
      "name": "Soil_Grass"
    },
    {
      "x": -4,
      "y": 2,
      "z": -3,
      "name": "Rock_Quartzite"
    },
    {
      "x": -4,
      "y": 3,
      "z": -3,
      "name": "Rock_Quartzite"
    },
    {
      "x": -4,
      "y": 4,
      "z": -3,
      "name": "Rock_Quartzite"
    },
    {
      "x": -4,
      "y": 5,
      "z": -3,
      "name": "Rock_Quartzite"
    },
    {
      "x": -4,
      "y": 6,
      "z": -3,
      "name": "Rock_Quartzite"
    },
    {
      "x": -4,
      "y": 7,
      "z": -3,
      "name": "Rock_Quartzite"
    },
    {
      "x": -4,
      "y": 8,
      "z": -3,
      "name": "Rock_Quartzite"
    },
    {
      "x": -4,
      "y": 9,
      "z": -3,
      "name": "Rock_Quartzite"
    },
    {
      "x": -4,
      "y": 10,
      "z": -3,
      "name": "Rock_Quartzite"
    },
    {
      "x": -4,
      "y": 11,
      "z": -3,
      "name": "Rock_Quartzite"
    },
    {
      "x": -4,
      "y": 12,
      "z": -3,
      "name": "Rock_Quartzite"
    },
    {
      "x": -4,
      "y": 13,
      "z": -3,
      "name": "Rock_Quartzite"
    },
    {
      "x": -4,
      "y": 14,
      "z": -3,
      "name": "Rock_Quartzite"
    },
    {
      "x": -4,
      "y": 15,
      "z": -3,
      "name": "Rock_Quartzite_Brick_Smooth"
    },
    {
      "x": -4,
      "y": 16,
      "z": -3,
      "name": "Rock_Quartzite_Brick_Smooth"
    },
    {
      "x": -4,
      "y": 17,
      "z": -3,
      "name": "Rock_Quartzite_Brick"
    },
    {
      "x": -4,
      "y": 18,
      "z": -3,
      "name": "Rock_Quartzite_Brick"
    },
    {
      "x": -4,
      "y": 19,
      "z": -3,
      "name": "Rock_Quartzite_Brick"
    },
    {
      "x": -4,
      "y": 20,
      "z": -3,
      "name": "Rock_Quartzite_Brick"
    },
    {
      "x": -4,
      "y": 21,
      "z": -3,
      "name": "Rock_Quartzite_Brick"
    },
    {
      "x": -4,
      "y": 22,
      "z": -3,
      "name": "Soil_Grass"
    },
    {
      "x": -4,
      "y": 23,
      "z": -3,
      "name": "Plant_Grass_Sharp_Tall"
    },
    {
      "x": -4,
      "y": 24,
      "z": -3,
      "name": "Plant_Grass_Sharp_Tall",
      "filler": 1024
    },
    {
      "x": -4,
      "y": 2,
      "z": -2,
      "name": "Rock_Quartzite"
    },
    {
      "x": -4,
      "y": 3,
      "z": -2,
      "name": "Rock_Quartzite"
    },
    {
      "x": -4,
      "y": 4,
      "z": -2,
      "name": "Rock_Quartzite"
    },
    {
      "x": -4,
      "y": 5,
      "z": -2,
      "name": "Rock_Quartzite"
    },
    {
      "x": -4,
      "y": 6,
      "z": -2,
      "name": "Rock_Quartzite"
    },
    {
      "x": -4,
      "y": 7,
      "z": -2,
      "name": "Rock_Quartzite"
    },
    {
      "x": -4,
      "y": 8,
      "z": -2,
      "name": "Rock_Quartzite"
    },
    {
      "x": -4,
      "y": 9,
      "z": -2,
      "name": "Rock_Quartzite"
    },
    {
      "x": -4,
      "y": 10,
      "z": -2,
      "name": "Soil_Grass"
    },
    {
      "x": -4,
      "y": 11,
      "z": -2,
      "name": "Plant_Fern_Winter"
    },
    {
      "x": -4,
      "y": 12,
      "z": -2,
      "name": "Empty"
    },
    {
      "x": -4,
      "y": 13,
      "z": -2,
      "name": "Empty"
    },
    {
      "x": -4,
      "y": 14,
      "z": -2,
      "name": "Rock_Quartzite_Cobble"
    },
    {
      "x": -4,
      "y": 15,
      "z": -2,
      "name": "Rock_Quartzite_Cobble"
    },
    {
      "x": -4,
      "y": 16,
      "z": -2,
      "name": "Rock_Quartzite"
    },
    {
      "x": -4,
      "y": 17,
      "z": -2,
      "name": "Rock_Quartzite_Brick"
    },
    {
      "x": -4,
      "y": 18,
      "z": -2,
      "name": "Rock_Quartzite_Brick"
    },
    {
      "x": -4,
      "y": 19,
      "z": -2,
      "name": "Rock_Quartzite_Brick"
    },
    {
      "x": -4,
      "y": 20,
      "z": -2,
      "name": "Rock_Quartzite_Brick"
    },
    {
      "x": -4,
      "y": 21,
      "z": -2,
      "name": "Soil_Dirt"
    },
    {
      "x": -4,
      "y": 22,
      "z": -2,
      "name": "Soil_Grass"
    },
    {
      "x": -4,
      "y": 23,
      "z": -2,
      "name": "Plant_Grass_Sharp"
    },
    {
      "x": -4,
      "y": 2,
      "z": -1,
      "name": "Rock_Quartzite"
    },
    {
      "x": -4,
      "y": 3,
      "z": -1,
      "name": "Rock_Quartzite"
    },
    {
      "x": -4,
      "y": 4,
      "z": -1,
      "name": "Rock_Quartzite"
    },
    {
      "x": -4,
      "y": 5,
      "z": -1,
      "name": "Rock_Quartzite"
    },
    {
      "x": -4,
      "y": 6,
      "z": -1,
      "name": "Rock_Quartzite"
    },
    {
      "x": -4,
      "y": 7,
      "z": -1,
      "name": "Rock_Quartzite"
    },
    {
      "x": -4,
      "y": 8,
      "z": -1,
      "name": "Rock_Quartzite"
    },
    {
      "x": -4,
      "y": 9,
      "z": -1,
      "name": "Soil_Grass"
    },
    {
      "x": -4,
      "y": 10,
      "z": -1,
      "name": "Plant_Grass_Sharp_Tall"
    },
    {
      "x": -4,
      "y": 11,
      "z": -1,
      "name": "Plant_Grass_Sharp_Tall",
      "filler": 1024
    },
    {
      "x": -4,
      "y": 12,
      "z": -1,
      "name": "Empty"
    },
    {
      "x": -4,
      "y": 13,
      "z": -1,
      "name": "Empty"
    },
    {
      "x": -4,
      "y": 14,
      "z": -1,
      "name": "Rock_Quartzite_Cobble_Stairs",
      "rotation": 9
    },
    {
      "x": -4,
      "y": 15,
      "z": -1,
      "name": "Rock_Quartzite_Cobble"
    },
    {
      "x": -4,
      "y": 16,
      "z": -1,
      "name": "Rock_Quartzite"
    },
    {
      "x": -4,
      "y": 17,
      "z": -1,
      "name": "Rock_Quartzite_Brick"
    },
    {
      "x": -4,
      "y": 18,
      "z": -1,
      "name": "Rock_Quartzite_Brick"
    },
    {
      "x": -4,
      "y": 19,
      "z": -1,
      "name": "Rock_Quartzite_Brick"
    },
    {
      "x": -4,
      "y": 20,
      "z": -1,
      "name": "Rock_Quartzite_Brick"
    },
    {
      "x": -4,
      "y": 21,
      "z": -1,
      "name": "Soil_Dirt"
    },
    {
      "x": -4,
      "y": 22,
      "z": -1,
      "name": "Soil_Grass"
    },
    {
      "x": -4,
      "y": 2,
      "z": 0,
      "name": "Rock_Quartzite"
    },
    {
      "x": -4,
      "y": 3,
      "z": 0,
      "name": "Rock_Quartzite"
    },
    {
      "x": -4,
      "y": 4,
      "z": 0,
      "name": "Rock_Quartzite"
    },
    {
      "x": -4,
      "y": 5,
      "z": 0,
      "name": "Rock_Quartzite"
    },
    {
      "x": -4,
      "y": 6,
      "z": 0,
      "name": "Rock_Quartzite"
    },
    {
      "x": -4,
      "y": 7,
      "z": 0,
      "name": "Rock_Quartzite"
    },
    {
      "x": -4,
      "y": 8,
      "z": 0,
      "name": "Rock_Quartzite"
    },
    {
      "x": -4,
      "y": 9,
      "z": 0,
      "name": "Rock_Quartzite"
    },
    {
      "x": -4,
      "y": 10,
      "z": 0,
      "name": "Rock_Quartzite"
    },
    {
      "x": -4,
      "y": 11,
      "z": 0,
      "name": "Rock_Quartzite"
    },
    {
      "x": -4,
      "y": 12,
      "z": 0,
      "name": "Rock_Quartzite"
    },
    {
      "x": -4,
      "y": 13,
      "z": 0,
      "name": "Rock_Quartzite"
    },
    {
      "x": -4,
      "y": 14,
      "z": 0,
      "name": "Rock_Quartzite"
    },
    {
      "x": -4,
      "y": 15,
      "z": 0,
      "name": "Rock_Quartzite"
    },
    {
      "x": -4,
      "y": 16,
      "z": 0,
      "name": "Rock_Quartzite"
    },
    {
      "x": -4,
      "y": 17,
      "z": 0,
      "name": "Rock_Quartzite"
    },
    {
      "x": -4,
      "y": 18,
      "z": 0,
      "name": "Rock_Quartzite"
    },
    {
      "x": -4,
      "y": 19,
      "z": 0,
      "name": "Rock_Quartzite_Brick"
    },
    {
      "x": -4,
      "y": 20,
      "z": 0,
      "name": "Rock_Quartzite_Brick"
    },
    {
      "x": -4,
      "y": 21,
      "z": 0,
      "name": "Rock_Quartzite_Brick"
    },
    {
      "x": -4,
      "y": 22,
      "z": 0,
      "name": "Soil_Grass"
    },
    {
      "x": -4,
      "y": 2,
      "z": 1,
      "name": "Rock_Quartzite"
    },
    {
      "x": -4,
      "y": 3,
      "z": 1,
      "name": "Rock_Quartzite"
    },
    {
      "x": -4,
      "y": 4,
      "z": 1,
      "name": "Rock_Quartzite"
    },
    {
      "x": -4,
      "y": 5,
      "z": 1,
      "name": "Rock_Quartzite"
    },
    {
      "x": -4,
      "y": 6,
      "z": 1,
      "name": "Rock_Quartzite"
    },
    {
      "x": -4,
      "y": 7,
      "z": 1,
      "name": "Rock_Quartzite"
    },
    {
      "x": -4,
      "y": 8,
      "z": 1,
      "name": "Rock_Quartzite"
    },
    {
      "x": -4,
      "y": 9,
      "z": 1,
      "name": "Rock_Quartzite"
    },
    {
      "x": -4,
      "y": 10,
      "z": 1,
      "name": "Rock_Quartzite"
    },
    {
      "x": -4,
      "y": 11,
      "z": 1,
      "name": "Rock_Quartzite"
    },
    {
      "x": -4,
      "y": 12,
      "z": 1,
      "name": "Rock_Quartzite"
    },
    {
      "x": -4,
      "y": 13,
      "z": 1,
      "name": "Rock_Quartzite"
    },
    {
      "x": -4,
      "y": 14,
      "z": 1,
      "name": "Rock_Quartzite"
    },
    {
      "x": -4,
      "y": 15,
      "z": 1,
      "name": "Rock_Quartzite"
    },
    {
      "x": -4,
      "y": 16,
      "z": 1,
      "name": "Rock_Quartzite"
    },
    {
      "x": -4,
      "y": 17,
      "z": 1,
      "name": "Rock_Quartzite"
    },
    {
      "x": -4,
      "y": 18,
      "z": 1,
      "name": "Rock_Quartzite"
    },
    {
      "x": -4,
      "y": 19,
      "z": 1,
      "name": "Rock_Quartzite_Brick"
    },
    {
      "x": -4,
      "y": 20,
      "z": 1,
      "name": "Rock_Quartzite_Brick"
    },
    {
      "x": -4,
      "y": 21,
      "z": 1,
      "name": "Rock_Quartzite_Brick"
    },
    {
      "x": -4,
      "y": 22,
      "z": 1,
      "name": "Soil_Grass"
    },
    {
      "x": -4,
      "y": 23,
      "z": 1,
      "name": "Plant_Grass_Sharp"
    },
    {
      "x": -4,
      "y": 2,
      "z": 2,
      "name": "Rock_Quartzite"
    },
    {
      "x": -4,
      "y": 3,
      "z": 2,
      "name": "Rock_Quartzite"
    },
    {
      "x": -4,
      "y": 4,
      "z": 2,
      "name": "Rock_Quartzite"
    },
    {
      "x": -4,
      "y": 5,
      "z": 2,
      "name": "Rock_Quartzite"
    },
    {
      "x": -4,
      "y": 6,
      "z": 2,
      "name": "Rock_Quartzite"
    },
    {
      "x": -4,
      "y": 7,
      "z": 2,
      "name": "Rock_Quartzite"
    },
    {
      "x": -4,
      "y": 8,
      "z": 2,
      "name": "Rock_Quartzite"
    },
    {
      "x": -4,
      "y": 9,
      "z": 2,
      "name": "Rock_Quartzite"
    },
    {
      "x": -4,
      "y": 10,
      "z": 2,
      "name": "Rock_Quartzite"
    },
    {
      "x": -4,
      "y": 11,
      "z": 2,
      "name": "Rock_Quartzite"
    },
    {
      "x": -4,
      "y": 12,
      "z": 2,
      "name": "Rock_Quartzite"
    },
    {
      "x": -4,
      "y": 13,
      "z": 2,
      "name": "Rock_Quartzite"
    },
    {
      "x": -4,
      "y": 14,
      "z": 2,
      "name": "Rock_Quartzite"
    },
    {
      "x": -4,
      "y": 15,
      "z": 2,
      "name": "Rock_Quartzite"
    },
    {
      "x": -4,
      "y": 16,
      "z": 2,
      "name": "Rock_Quartzite"
    },
    {
      "x": -4,
      "y": 17,
      "z": 2,
      "name": "Rock_Quartzite"
    },
    {
      "x": -4,
      "y": 18,
      "z": 2,
      "name": "Rock_Quartzite"
    },
    {
      "x": -4,
      "y": 19,
      "z": 2,
      "name": "Rock_Quartzite_Brick"
    },
    {
      "x": -4,
      "y": 20,
      "z": 2,
      "name": "Rock_Quartzite_Cobble"
    },
    {
      "x": -4,
      "y": 21,
      "z": 2,
      "name": "Rock_Quartzite_Brick"
    },
    {
      "x": -4,
      "y": 22,
      "z": 2,
      "name": "Rock_Stone"
    },
    {
      "x": -4,
      "y": 2,
      "z": 3,
      "name": "Rock_Quartzite"
    },
    {
      "x": -4,
      "y": 3,
      "z": 3,
      "name": "Rock_Quartzite"
    },
    {
      "x": -4,
      "y": 4,
      "z": 3,
      "name": "Rock_Quartzite"
    },
    {
      "x": -4,
      "y": 5,
      "z": 3,
      "name": "Rock_Quartzite"
    },
    {
      "x": -4,
      "y": 6,
      "z": 3,
      "name": "Rock_Quartzite"
    },
    {
      "x": -4,
      "y": 7,
      "z": 3,
      "name": "Rock_Quartzite"
    },
    {
      "x": -4,
      "y": 8,
      "z": 3,
      "name": "Rock_Quartzite"
    },
    {
      "x": -4,
      "y": 9,
      "z": 3,
      "name": "Rock_Quartzite"
    },
    {
      "x": -4,
      "y": 10,
      "z": 3,
      "name": "Rock_Quartzite"
    },
    {
      "x": -4,
      "y": 11,
      "z": 3,
      "name": "Rock_Quartzite"
    },
    {
      "x": -4,
      "y": 12,
      "z": 3,
      "name": "Rock_Quartzite"
    },
    {
      "x": -4,
      "y": 13,
      "z": 3,
      "name": "Rock_Quartzite"
    },
    {
      "x": -4,
      "y": 14,
      "z": 3,
      "name": "Rock_Quartzite"
    },
    {
      "x": -4,
      "y": 15,
      "z": 3,
      "name": "Rock_Quartzite"
    },
    {
      "x": -4,
      "y": 16,
      "z": 3,
      "name": "Rock_Quartzite"
    },
    {
      "x": -4,
      "y": 17,
      "z": 3,
      "name": "Rock_Quartzite_Brick"
    },
    {
      "x": -4,
      "y": 18,
      "z": 3,
      "name": "Rock_Quartzite_Brick"
    },
    {
      "x": -4,
      "y": 19,
      "z": 3,
      "name": "Rock_Quartzite_Brick"
    },
    {
      "x": -4,
      "y": 20,
      "z": 3,
      "name": "Rock_Quartzite_Brick"
    },
    {
      "x": -4,
      "y": 21,
      "z": 3,
      "name": "Rock_Quartzite_Brick"
    },
    {
      "x": -4,
      "y": 22,
      "z": 3,
      "name": "Rock_Stone_Mossy"
    },
    {
      "x": -4,
      "y": 2,
      "z": 4,
      "name": "Rock_Quartzite"
    },
    {
      "x": -4,
      "y": 3,
      "z": 4,
      "name": "Rock_Quartzite"
    },
    {
      "x": -4,
      "y": 4,
      "z": 4,
      "name": "Rock_Quartzite"
    },
    {
      "x": -4,
      "y": 5,
      "z": 4,
      "name": "Rock_Quartzite"
    },
    {
      "x": -4,
      "y": 6,
      "z": 4,
      "name": "Rock_Quartzite"
    },
    {
      "x": -4,
      "y": 7,
      "z": 4,
      "name": "Rock_Quartzite"
    },
    {
      "x": -4,
      "y": 8,
      "z": 4,
      "name": "Rock_Quartzite_Brick"
    },
    {
      "x": -4,
      "y": 9,
      "z": 4,
      "name": "Rock_Quartzite"
    },
    {
      "x": -4,
      "y": 10,
      "z": 4,
      "name": "Rock_Quartzite"
    },
    {
      "x": -4,
      "y": 11,
      "z": 4,
      "name": "Rock_Quartzite"
    },
    {
      "x": -4,
      "y": 12,
      "z": 4,
      "name": "Rock_Quartzite"
    },
    {
      "x": -4,
      "y": 13,
      "z": 4,
      "name": "Rock_Quartzite"
    },
    {
      "x": -4,
      "y": 14,
      "z": 4,
      "name": "Rock_Quartzite"
    },
    {
      "x": -4,
      "y": 15,
      "z": 4,
      "name": "Rock_Quartzite"
    },
    {
      "x": -4,
      "y": 16,
      "z": 4,
      "name": "Rock_Quartzite"
    },
    {
      "x": -4,
      "y": 17,
      "z": 4,
      "name": "Rock_Quartzite_Brick"
    },
    {
      "x": -4,
      "y": 18,
      "z": 4,
      "name": "Rock_Quartzite_Brick"
    },
    {
      "x": -4,
      "y": 19,
      "z": 4,
      "name": "Rock_Quartzite_Brick"
    },
    {
      "x": -4,
      "y": 20,
      "z": 4,
      "name": "Rock_Quartzite_Brick"
    },
    {
      "x": -4,
      "y": 21,
      "z": 4,
      "name": "Rock_Quartzite_Brick"
    },
    {
      "x": -4,
      "y": 22,
      "z": 4,
      "name": "Rock_Stone_Mossy"
    },
    {
      "x": -4,
      "y": 2,
      "z": 5,
      "name": "Rock_Quartzite"
    },
    {
      "x": -4,
      "y": 3,
      "z": 5,
      "name": "Rock_Quartzite"
    },
    {
      "x": -4,
      "y": 4,
      "z": 5,
      "name": "Rock_Quartzite"
    },
    {
      "x": -4,
      "y": 5,
      "z": 5,
      "name": "Rock_Quartzite"
    },
    {
      "x": -4,
      "y": 6,
      "z": 5,
      "name": "Rock_Quartzite"
    },
    {
      "x": -4,
      "y": 7,
      "z": 5,
      "name": "Rock_Quartzite"
    },
    {
      "x": -4,
      "y": 8,
      "z": 5,
      "name": "Rock_Quartzite_Brick"
    },
    {
      "x": -4,
      "y": 9,
      "z": 5,
      "name": "Rock_Quartzite_Cobble"
    },
    {
      "x": -4,
      "y": 10,
      "z": 5,
      "name": "Rock_Quartzite_Cobble"
    },
    {
      "x": -4,
      "y": 11,
      "z": 5,
      "name": "Rock_Quartzite_Cobble"
    },
    {
      "x": -4,
      "y": 12,
      "z": 5,
      "name": "Rock_Quartzite_Cobble"
    },
    {
      "x": -4,
      "y": 13,
      "z": 5,
      "name": "Rock_Quartzite"
    },
    {
      "x": -4,
      "y": 14,
      "z": 5,
      "name": "Rock_Quartzite"
    },
    {
      "x": -4,
      "y": 15,
      "z": 5,
      "name": "Rock_Quartzite_Brick_Smooth"
    },
    {
      "x": -4,
      "y": 16,
      "z": 5,
      "name": "Rock_Quartzite_Brick_Smooth"
    },
    {
      "x": -4,
      "y": 17,
      "z": 5,
      "name": "Rock_Quartzite_Brick"
    },
    {
      "x": -4,
      "y": 18,
      "z": 5,
      "name": "Rock_Quartzite_Brick"
    },
    {
      "x": -4,
      "y": 19,
      "z": 5,
      "name": "Rock_Quartzite_Brick"
    },
    {
      "x": -4,
      "y": 20,
      "z": 5,
      "name": "Rock_Quartzite_Brick"
    },
    {
      "x": -4,
      "y": 21,
      "z": 5,
      "name": "Rock_Quartzite_Brick"
    },
    {
      "x": -4,
      "y": 22,
      "z": 5,
      "name": "Rock_Stone"
    },
    {
      "x": -4,
      "y": 2,
      "z": 6,
      "name": "Rock_Quartzite"
    },
    {
      "x": -4,
      "y": 3,
      "z": 6,
      "name": "Rock_Quartzite"
    },
    {
      "x": -4,
      "y": 4,
      "z": 6,
      "name": "Rock_Quartzite"
    },
    {
      "x": -4,
      "y": 5,
      "z": 6,
      "name": "Rock_Quartzite"
    },
    {
      "x": -4,
      "y": 6,
      "z": 6,
      "name": "Rock_Quartzite"
    },
    {
      "x": -4,
      "y": 7,
      "z": 6,
      "name": "Rock_Quartzite"
    },
    {
      "x": -4,
      "y": 8,
      "z": 6,
      "name": "Rock_Quartzite_Brick"
    },
    {
      "x": -4,
      "y": 9,
      "z": 6,
      "name": "Rock_Quartzite_Cobble_Stairs"
    },
    {
      "x": -4,
      "y": 14,
      "z": 6,
      "name": "Rock_Quartzite"
    },
    {
      "x": -4,
      "y": 15,
      "z": 6,
      "name": "Rock_Quartzite_Brick_Smooth"
    },
    {
      "x": -4,
      "y": 16,
      "z": 6,
      "name": "Rock_Quartzite_Brick_Smooth"
    },
    {
      "x": -4,
      "y": 17,
      "z": 6,
      "name": "Rock_Quartzite_Brick"
    },
    {
      "x": -4,
      "y": 18,
      "z": 6,
      "name": "Rock_Quartzite_Brick"
    },
    {
      "x": -4,
      "y": 19,
      "z": 6,
      "name": "Rock_Quartzite_Brick"
    },
    {
      "x": -4,
      "y": 20,
      "z": 6,
      "name": "Rock_Quartzite_Brick"
    },
    {
      "x": -4,
      "y": 21,
      "z": 6,
      "name": "Rock_Quartzite_Brick"
    },
    {
      "x": -4,
      "y": 22,
      "z": 6,
      "name": "Rock_Stone"
    },
    {
      "x": -4,
      "y": 2,
      "z": 7,
      "name": "Rock_Quartzite"
    },
    {
      "x": -4,
      "y": 3,
      "z": 7,
      "name": "Rock_Quartzite"
    },
    {
      "x": -4,
      "y": 4,
      "z": 7,
      "name": "Rock_Quartzite"
    },
    {
      "x": -4,
      "y": 5,
      "z": 7,
      "name": "Rock_Quartzite"
    },
    {
      "x": -4,
      "y": 6,
      "z": 7,
      "name": "Rock_Quartzite"
    },
    {
      "x": -4,
      "y": 7,
      "z": 7,
      "name": "Rock_Quartzite"
    },
    {
      "x": -4,
      "y": 8,
      "z": 7,
      "name": "Rock_Quartzite_Brick"
    },
    {
      "x": -4,
      "y": 9,
      "z": 7,
      "name": "Plant_Moss_Rug_Green"
    },
    {
      "x": -4,
      "y": 14,
      "z": 7,
      "name": "Plant_Vine_Wall"
    },
    {
      "x": -4,
      "y": 15,
      "z": 7,
      "name": "Rock_Quartzite_Brick_Smooth"
    },
    {
      "x": -4,
      "y": 16,
      "z": 7,
      "name": "Rock_Quartzite_Brick_Smooth"
    },
    {
      "x": -4,
      "y": 17,
      "z": 7,
      "name": "Rock_Quartzite_Cobble"
    },
    {
      "x": -4,
      "y": 18,
      "z": 7,
      "name": "Rock_Quartzite_Cobble"
    },
    {
      "x": -4,
      "y": 19,
      "z": 7,
      "name": "Rock_Quartzite_Cobble"
    },
    {
      "x": -4,
      "y": 20,
      "z": 7,
      "name": "Rock_Quartzite_Cobble"
    },
    {
      "x": -4,
      "y": 21,
      "z": 7,
      "name": "Rock_Quartzite_Brick"
    },
    {
      "x": -4,
      "y": 22,
      "z": 7,
      "name": "Rock_Stone_Brick_Smooth"
    },
    {
      "x": -4,
      "y": 3,
      "z": 8,
      "name": "Rock_Quartzite"
    },
    {
      "x": -4,
      "y": 4,
      "z": 8,
      "name": "Rock_Quartzite"
    },
    {
      "x": -4,
      "y": 5,
      "z": 8,
      "name": "Rock_Quartzite"
    },
    {
      "x": -4,
      "y": 6,
      "z": 8,
      "name": "Rock_Quartzite_Brick"
    },
    {
      "x": -4,
      "y": 7,
      "z": 8,
      "name": "Rock_Quartzite_Brick"
    },
    {
      "x": -4,
      "y": 8,
      "z": 8,
      "name": "Rock_Quartzite_Brick"
    },
    {
      "x": -4,
      "y": 16,
      "z": 8,
      "name": "Rock_Quartzite_Brick_Half",
      "rotation": 4
    },
    {
      "x": -4,
      "y": 17,
      "z": 8,
      "name": "Rock_Stone_Brick_Smooth_Half"
    },
    {
      "x": -4,
      "y": 22,
      "z": 8,
      "name": "Rock_Stone_Brick_Smooth"
    },
    {
      "x": -3,
      "y": 6,
      "z": -6,
      "name": "Rock_Quartzite_Brick"
    },
    {
      "x": -3,
      "y": 7,
      "z": -6,
      "name": "Rock_Quartzite_Brick"
    },
    {
      "x": -3,
      "y": 8,
      "z": -6,
      "name": "Rock_Quartzite_Brick"
    },
    {
      "x": -3,
      "y": 17,
      "z": -6,
      "name": "Rock_Stone_Brick_Smooth_Half"
    },
    {
      "x": -3,
      "y": 22,
      "z": -6,
      "name": "Rock_Stone_Brick_Smooth"
    },
    {
      "x": -3,
      "y": 2,
      "z": -5,
      "name": "Rock_Quartzite"
    },
    {
      "x": -3,
      "y": 3,
      "z": -5,
      "name": "Rock_Quartzite"
    },
    {
      "x": -3,
      "y": 4,
      "z": -5,
      "name": "Rock_Quartzite"
    },
    {
      "x": -3,
      "y": 5,
      "z": -5,
      "name": "Rock_Quartzite"
    },
    {
      "x": -3,
      "y": 6,
      "z": -5,
      "name": "Rock_Quartzite"
    },
    {
      "x": -3,
      "y": 7,
      "z": -5,
      "name": "Rock_Quartzite"
    },
    {
      "x": -3,
      "y": 8,
      "z": -5,
      "name": "Rock_Quartzite_Brick"
    },
    {
      "x": -3,
      "y": 9,
      "z": -5,
      "name": "Rock_Quartzite_Brick_Stairs",
      "rotation": 1
    },
    {
      "x": -3,
      "y": 15,
      "z": -5,
      "name": "Plant_Vine_Wall",
      "rotation": 2
    },
    {
      "x": -3,
      "y": 16,
      "z": -5,
      "name": "Rock_Quartzite_Brick_Half",
      "rotation": 5
    },
    {
      "x": -3,
      "y": 17,
      "z": -5,
      "name": "Rock_Stone_Brick_Smooth_Half"
    },
    {
      "x": -3,
      "y": 19,
      "z": -5,
      "name": "Rock_Quartzite_Brick_Half",
      "rotation": 5
    },
    {
      "x": -3,
      "y": 20,
      "z": -5,
      "name": "Rock_Quartzite_Brick"
    },
    {
      "x": -3,
      "y": 21,
      "z": -5,
      "name": "Rock_Quartzite_Brick"
    },
    {
      "x": -3,
      "y": 22,
      "z": -5,
      "name": "Rock_Stone_Brick_Smooth"
    },
    {
      "x": -3,
      "y": 2,
      "z": -4,
      "name": "Rock_Quartzite"
    },
    {
      "x": -3,
      "y": 3,
      "z": -4,
      "name": "Rock_Quartzite"
    },
    {
      "x": -3,
      "y": 4,
      "z": -4,
      "name": "Rock_Quartzite"
    },
    {
      "x": -3,
      "y": 5,
      "z": -4,
      "name": "Rock_Quartzite"
    },
    {
      "x": -3,
      "y": 6,
      "z": -4,
      "name": "Rock_Quartzite"
    },
    {
      "x": -3,
      "y": 7,
      "z": -4,
      "name": "Rock_Quartzite"
    },
    {
      "x": -3,
      "y": 8,
      "z": -4,
      "name": "Rock_Quartzite"
    },
    {
      "x": -3,
      "y": 9,
      "z": -4,
      "name": "Rock_Quartzite"
    },
    {
      "x": -3,
      "y": 10,
      "z": -4,
      "name": "Rock_Quartzite_Cobble_Beam",
      "rotation": 5
    },
    {
      "x": -3,
      "y": 11,
      "z": -4,
      "name": "Empty"
    },
    {
      "x": -3,
      "y": 12,
      "z": -4,
      "name": "Empty"
    },
    {
      "x": -3,
      "y": 13,
      "z": -4,
      "name": "Empty"
    },
    {
      "x": -3,
      "y": 14,
      "z": -4,
      "name": "Empty"
    },
    {
      "x": -3,
      "y": 15,
      "z": -4,
      "name": "Rock_Quartzite"
    },
    {
      "x": -3,
      "y": 16,
      "z": -4,
      "name": "Rock_Quartzite"
    },
    {
      "x": -3,
      "y": 17,
      "z": -4,
      "name": "Rock_Quartzite_Brick"
    },
    {
      "x": -3,
      "y": 18,
      "z": -4,
      "name": "Rock_Quartzite_Brick"
    },
    {
      "x": -3,
      "y": 19,
      "z": -4,
      "name": "Rock_Quartzite_Brick"
    },
    {
      "x": -3,
      "y": 20,
      "z": -4,
      "name": "Rock_Quartzite_Brick"
    },
    {
      "x": -3,
      "y": 21,
      "z": -4,
      "name": "Rock_Quartzite_Brick"
    },
    {
      "x": -3,
      "y": 22,
      "z": -4,
      "name": "Rock_Stone_Mossy"
    },
    {
      "x": -3,
      "y": 2,
      "z": -3,
      "name": "Rock_Quartzite"
    },
    {
      "x": -3,
      "y": 3,
      "z": -3,
      "name": "Rock_Quartzite"
    },
    {
      "x": -3,
      "y": 4,
      "z": -3,
      "name": "Rock_Quartzite"
    },
    {
      "x": -3,
      "y": 5,
      "z": -3,
      "name": "Rock_Quartzite"
    },
    {
      "x": -3,
      "y": 6,
      "z": -3,
      "name": "Rock_Quartzite"
    },
    {
      "x": -3,
      "y": 7,
      "z": -3,
      "name": "Rock_Quartzite"
    },
    {
      "x": -3,
      "y": 8,
      "z": -3,
      "name": "Rock_Quartzite"
    },
    {
      "x": -3,
      "y": 9,
      "z": -3,
      "name": "Rock_Quartzite"
    },
    {
      "x": -3,
      "y": 10,
      "z": -3,
      "name": "Rock_Quartzite_Cobble"
    },
    {
      "x": -3,
      "y": 11,
      "z": -3,
      "name": "Rock_Quartzite"
    },
    {
      "x": -3,
      "y": 12,
      "z": -3,
      "name": "Rock_Quartzite"
    },
    {
      "x": -3,
      "y": 13,
      "z": -3,
      "name": "Rock_Quartzite"
    },
    {
      "x": -3,
      "y": 14,
      "z": -3,
      "name": "Rock_Quartzite"
    },
    {
      "x": -3,
      "y": 15,
      "z": -3,
      "name": "Rock_Quartzite"
    },
    {
      "x": -3,
      "y": 16,
      "z": -3,
      "name": "Rock_Quartzite"
    },
    {
      "x": -3,
      "y": 17,
      "z": -3,
      "name": "Rock_Quartzite_Brick"
    },
    {
      "x": -3,
      "y": 18,
      "z": -3,
      "name": "Rock_Quartzite_Brick"
    },
    {
      "x": -3,
      "y": 19,
      "z": -3,
      "name": "Rock_Quartzite_Brick"
    },
    {
      "x": -3,
      "y": 20,
      "z": -3,
      "name": "Rock_Quartzite_Brick"
    },
    {
      "x": -3,
      "y": 21,
      "z": -3,
      "name": "Rock_Quartzite_Brick"
    },
    {
      "x": -3,
      "y": 22,
      "z": -3,
      "name": "Soil_Grass"
    },
    {
      "x": -3,
      "y": 2,
      "z": -2,
      "name": "Rock_Quartzite"
    },
    {
      "x": -3,
      "y": 3,
      "z": -2,
      "name": "Rock_Quartzite"
    },
    {
      "x": -3,
      "y": 4,
      "z": -2,
      "name": "Rock_Quartzite"
    },
    {
      "x": -3,
      "y": 5,
      "z": -2,
      "name": "Rock_Quartzite"
    },
    {
      "x": -3,
      "y": 6,
      "z": -2,
      "name": "Rock_Quartzite"
    },
    {
      "x": -3,
      "y": 7,
      "z": -2,
      "name": "Rock_Quartzite_Brick"
    },
    {
      "x": -3,
      "y": 8,
      "z": -2,
      "name": "Rock_Quartzite_Brick"
    },
    {
      "x": -3,
      "y": 9,
      "z": -2,
      "name": "Rock_Quartzite_Brick"
    },
    {
      "x": -3,
      "y": 10,
      "z": -2,
      "name": "Rock_Quartzite_Brick"
    },
    {
      "x": -3,
      "y": 11,
      "z": -2,
      "name": "Rock_Quartzite_Brick"
    },
    {
      "x": -3,
      "y": 12,
      "z": -2,
      "name": "Rock_Quartzite_Brick"
    },
    {
      "x": -3,
      "y": 13,
      "z": -2,
      "name": "Rock_Quartzite_Brick"
    },
    {
      "x": -3,
      "y": 14,
      "z": -2,
      "name": "Rock_Quartzite_Brick"
    },
    {
      "x": -3,
      "y": 15,
      "z": -2,
      "name": "Rock_Quartzite_Brick"
    },
    {
      "x": -3,
      "y": 16,
      "z": -2,
      "name": "Rock_Quartzite_Cobble"
    },
    {
      "x": -3,
      "y": 17,
      "z": -2,
      "name": "Rock_Quartzite_Brick"
    },
    {
      "x": -3,
      "y": 18,
      "z": -2,
      "name": "Rock_Quartzite_Brick"
    },
    {
      "x": -3,
      "y": 19,
      "z": -2,
      "name": "Rock_Quartzite_Brick"
    },
    {
      "x": -3,
      "y": 20,
      "z": -2,
      "name": "Rock_Quartzite_Brick"
    },
    {
      "x": -3,
      "y": 21,
      "z": -2,
      "name": "Rock_Quartzite_Brick"
    },
    {
      "x": -3,
      "y": 22,
      "z": -2,
      "name": "Soil_Grass"
    },
    {
      "x": -3,
      "y": 2,
      "z": -1,
      "name": "Rock_Quartzite"
    },
    {
      "x": -3,
      "y": 3,
      "z": -1,
      "name": "Rock_Quartzite"
    },
    {
      "x": -3,
      "y": 4,
      "z": -1,
      "name": "Rock_Quartzite"
    },
    {
      "x": -3,
      "y": 5,
      "z": -1,
      "name": "Rock_Quartzite"
    },
    {
      "x": -3,
      "y": 6,
      "z": -1,
      "name": "Rock_Quartzite"
    },
    {
      "x": -3,
      "y": 7,
      "z": -1,
      "name": "Rock_Quartzite"
    },
    {
      "x": -3,
      "y": 8,
      "z": -1,
      "name": "Rock_Quartzite_Brick"
    },
    {
      "x": -3,
      "y": 9,
      "z": -1,
      "name": "Rock_Quartzite_Brick_Pillar_Base"
    },
    {
      "x": -3,
      "y": 10,
      "z": -1,
      "name": "Rock_Quartzite_Brick_Pillar_Middle"
    },
    {
      "x": -3,
      "y": 11,
      "z": -1,
      "name": "Rock_Quartzite_Brick_Pillar_Middle"
    },
    {
      "x": -3,
      "y": 12,
      "z": -1,
      "name": "Rock_Quartzite_Brick_Pillar_Middle"
    },
    {
      "x": -3,
      "y": 13,
      "z": -1,
      "name": "Rock_Quartzite_Brick_Pillar_Base",
      "rotation": 8
    },
    {
      "x": -3,
      "y": 14,
      "z": -1,
      "name": "Rock_Quartzite_Cobble"
    },
    {
      "x": -3,
      "y": 15,
      "z": -1,
      "name": "Rock_Quartzite_Cobble"
    },
    {
      "x": -3,
      "y": 16,
      "z": -1,
      "name": "Rock_Quartzite_Cobble"
    },
    {
      "x": -3,
      "y": 17,
      "z": -1,
      "name": "Rock_Quartzite_Brick"
    },
    {
      "x": -3,
      "y": 18,
      "z": -1,
      "name": "Rock_Quartzite_Brick"
    },
    {
      "x": -3,
      "y": 19,
      "z": -1,
      "name": "Rock_Quartzite_Brick"
    },
    {
      "x": -3,
      "y": 20,
      "z": -1,
      "name": "Rock_Quartzite_Brick"
    },
    {
      "x": -3,
      "y": 21,
      "z": -1,
      "name": "Rock_Quartzite_Brick"
    },
    {
      "x": -3,
      "y": 22,
      "z": -1,
      "name": "Soil_Grass"
    },
    {
      "x": -3,
      "y": 23,
      "z": -1,
      "name": "Plant_Grass_Lush_Short"
    },
    {
      "x": -3,
      "y": 7,
      "z": 0,
      "name": "Soil_Dirt"
    },
    {
      "x": -3,
      "y": 8,
      "z": 0,
      "name": "Empty"
    },
    {
      "x": -3,
      "y": 9,
      "z": 0,
      "name": "Empty"
    },
    {
      "x": -3,
      "y": 10,
      "z": 0,
      "name": "Empty"
    },
    {
      "x": -3,
      "y": 11,
      "z": 0,
      "name": "Empty"
    },
    {
      "x": -3,
      "y": 12,
      "z": 0,
      "name": "Empty"
    },
    {
      "x": -3,
      "y": 13,
      "z": 0,
      "name": "Empty"
    },
    {
      "x": -3,
      "y": 14,
      "z": 0,
      "name": "Empty"
    },
    {
      "x": -3,
      "y": 15,
      "z": 0,
      "name": "Rock_Quartzite_Cobble"
    },
    {
      "x": -3,
      "y": 16,
      "z": 0,
      "name": "Rock_Quartzite_Cobble"
    },
    {
      "x": -3,
      "y": 17,
      "z": 0,
      "name": "Rock_Quartzite_Brick"
    },
    {
      "x": -3,
      "y": 18,
      "z": 0,
      "name": "Rock_Quartzite_Brick"
    },
    {
      "x": -3,
      "y": 19,
      "z": 0,
      "name": "Rock_Quartzite_Brick"
    },
    {
      "x": -3,
      "y": 20,
      "z": 0,
      "name": "Rock_Quartzite_Brick"
    },
    {
      "x": -3,
      "y": 21,
      "z": 0,
      "name": "Rock_Quartzite_Brick"
    },
    {
      "x": -3,
      "y": 22,
      "z": 0,
      "name": "Soil_Grass"
    },
    {
      "x": -3,
      "y": 6,
      "z": 1,
      "name": "Rock_Quartzite"
    },
    {
      "x": -3,
      "y": 7,
      "z": 1,
      "name": "Soil_Dirt"
    },
    {
      "x": -3,
      "y": 8,
      "z": 1,
      "name": "Empty"
    },
    {
      "x": -3,
      "y": 9,
      "z": 1,
      "name": "Empty"
    },
    {
      "x": -3,
      "y": 10,
      "z": 1,
      "name": "Empty"
    },
    {
      "x": -3,
      "y": 11,
      "z": 1,
      "name": "Empty"
    },
    {
      "x": -3,
      "y": 12,
      "z": 1,
      "name": "Empty"
    },
    {
      "x": -3,
      "y": 13,
      "z": 1,
      "name": "Empty"
    },
    {
      "x": -3,
      "y": 14,
      "z": 1,
      "name": "Empty"
    },
    {
      "x": -3,
      "y": 15,
      "z": 1,
      "name": "Rock_Quartzite_Cobble"
    },
    {
      "x": -3,
      "y": 16,
      "z": 1,
      "name": "Rock_Quartzite_Cobble"
    },
    {
      "x": -3,
      "y": 17,
      "z": 1,
      "name": "Rock_Quartzite_Brick"
    },
    {
      "x": -3,
      "y": 18,
      "z": 1,
      "name": "Rock_Quartzite_Brick"
    },
    {
      "x": -3,
      "y": 19,
      "z": 1,
      "name": "Rock_Quartzite_Brick"
    },
    {
      "x": -3,
      "y": 20,
      "z": 1,
      "name": "Rock_Quartzite_Brick"
    },
    {
      "x": -3,
      "y": 21,
      "z": 1,
      "name": "Rock_Quartzite_Brick"
    },
    {
      "x": -3,
      "y": 22,
      "z": 1,
      "name": "Soil_Grass"
    },
    {
      "x": -3,
      "y": 6,
      "z": 2,
      "name": "Rock_Quartzite"
    },
    {
      "x": -3,
      "y": 7,
      "z": 2,
      "name": "Soil_Dirt"
    },
    {
      "x": -3,
      "y": 8,
      "z": 2,
      "name": "Empty"
    },
    {
      "x": -3,
      "y": 9,
      "z": 2,
      "name": "Empty"
    },
    {
      "x": -3,
      "y": 10,
      "z": 2,
      "name": "Empty"
    },
    {
      "x": -3,
      "y": 11,
      "z": 2,
      "name": "Empty"
    },
    {
      "x": -3,
      "y": 12,
      "z": 2,
      "name": "Empty"
    },
    {
      "x": -3,
      "y": 13,
      "z": 2,
      "name": "Empty"
    },
    {
      "x": -3,
      "y": 14,
      "z": 2,
      "name": "Rock_Quartzite_Cobble_Stairs",
      "rotation": 8
    },
    {
      "x": -3,
      "y": 15,
      "z": 2,
      "name": "Rock_Quartzite_Cobble"
    },
    {
      "x": -3,
      "y": 16,
      "z": 2,
      "name": "Rock_Quartzite_Cobble"
    },
    {
      "x": -3,
      "y": 17,
      "z": 2,
      "name": "Rock_Quartzite_Brick"
    },
    {
      "x": -3,
      "y": 18,
      "z": 2,
      "name": "Rock_Quartzite_Brick"
    },
    {
      "x": -3,
      "y": 19,
      "z": 2,
      "name": "Rock_Quartzite_Brick"
    },
    {
      "x": -3,
      "y": 20,
      "z": 2,
      "name": "Rock_Quartzite_Brick"
    },
    {
      "x": -3,
      "y": 21,
      "z": 2,
      "name": "Rock_Quartzite_Brick"
    },
    {
      "x": -3,
      "y": 22,
      "z": 2,
      "name": "Rock_Stone_Mossy"
    },
    {
      "x": -3,
      "y": 2,
      "z": 3,
      "name": "Rock_Quartzite"
    },
    {
      "x": -3,
      "y": 3,
      "z": 3,
      "name": "Rock_Quartzite"
    },
    {
      "x": -3,
      "y": 4,
      "z": 3,
      "name": "Rock_Quartzite"
    },
    {
      "x": -3,
      "y": 5,
      "z": 3,
      "name": "Rock_Quartzite"
    },
    {
      "x": -3,
      "y": 6,
      "z": 3,
      "name": "Rock_Quartzite"
    },
    {
      "x": -3,
      "y": 7,
      "z": 3,
      "name": "Rock_Quartzite"
    },
    {
      "x": -3,
      "y": 8,
      "z": 3,
      "name": "Rock_Quartzite_Brick"
    },
    {
      "x": -3,
      "y": 9,
      "z": 3,
      "name": "Rock_Quartzite_Brick_Pillar_Base"
    },
    {
      "x": -3,
      "y": 10,
      "z": 3,
      "name": "Rock_Quartzite_Brick_Pillar_Middle"
    },
    {
      "x": -3,
      "y": 11,
      "z": 3,
      "name": "Rock_Quartzite_Brick_Pillar_Middle"
    },
    {
      "x": -3,
      "y": 12,
      "z": 3,
      "name": "Rock_Quartzite_Brick_Pillar_Middle"
    },
    {
      "x": -3,
      "y": 13,
      "z": 3,
      "name": "Rock_Quartzite_Brick_Pillar_Base",
      "rotation": 8
    },
    {
      "x": -3,
      "y": 14,
      "z": 3,
      "name": "Rock_Quartzite_Cobble"
    },
    {
      "x": -3,
      "y": 15,
      "z": 3,
      "name": "Rock_Quartzite_Cobble"
    },
    {
      "x": -3,
      "y": 16,
      "z": 3,
      "name": "Rock_Quartzite_Cobble"
    },
    {
      "x": -3,
      "y": 17,
      "z": 3,
      "name": "Rock_Quartzite_Brick"
    },
    {
      "x": -3,
      "y": 18,
      "z": 3,
      "name": "Rock_Quartzite_Brick"
    },
    {
      "x": -3,
      "y": 19,
      "z": 3,
      "name": "Rock_Quartzite_Brick"
    },
    {
      "x": -3,
      "y": 20,
      "z": 3,
      "name": "Rock_Quartzite_Brick"
    },
    {
      "x": -3,
      "y": 21,
      "z": 3,
      "name": "Rock_Quartzite_Brick"
    },
    {
      "x": -3,
      "y": 22,
      "z": 3,
      "name": "Rock_Stone"
    },
    {
      "x": -3,
      "y": 2,
      "z": 4,
      "name": "Rock_Quartzite"
    },
    {
      "x": -3,
      "y": 3,
      "z": 4,
      "name": "Rock_Quartzite"
    },
    {
      "x": -3,
      "y": 4,
      "z": 4,
      "name": "Rock_Quartzite"
    },
    {
      "x": -3,
      "y": 5,
      "z": 4,
      "name": "Rock_Quartzite"
    },
    {
      "x": -3,
      "y": 6,
      "z": 4,
      "name": "Rock_Quartzite"
    },
    {
      "x": -3,
      "y": 7,
      "z": 4,
      "name": "Rock_Quartzite"
    },
    {
      "x": -3,
      "y": 8,
      "z": 4,
      "name": "Rock_Quartzite_Brick"
    },
    {
      "x": -3,
      "y": 9,
      "z": 4,
      "name": "Empty"
    },
    {
      "x": -3,
      "y": 10,
      "z": 4,
      "name": "Empty"
    },
    {
      "x": -3,
      "y": 11,
      "z": 4,
      "name": "Empty"
    },
    {
      "x": -3,
      "y": 12,
      "z": 4,
      "name": "Empty"
    },
    {
      "x": -3,
      "y": 13,
      "z": 4,
      "name": "Empty"
    },
    {
      "x": -3,
      "y": 14,
      "z": 4,
      "name": "Rock_Quartzite_Cobble"
    },
    {
      "x": -3,
      "y": 15,
      "z": 4,
      "name": "Rock_Quartzite_Cobble"
    },
    {
      "x": -3,
      "y": 16,
      "z": 4,
      "name": "Rock_Quartzite_Cobble"
    },
    {
      "x": -3,
      "y": 17,
      "z": 4,
      "name": "Rock_Quartzite_Brick"
    },
    {
      "x": -3,
      "y": 18,
      "z": 4,
      "name": "Rock_Quartzite_Brick"
    },
    {
      "x": -3,
      "y": 19,
      "z": 4,
      "name": "Rock_Quartzite_Brick"
    },
    {
      "x": -3,
      "y": 20,
      "z": 4,
      "name": "Rock_Quartzite_Brick"
    },
    {
      "x": -3,
      "y": 21,
      "z": 4,
      "name": "Rock_Quartzite_Brick"
    },
    {
      "x": -3,
      "y": 22,
      "z": 4,
      "name": "Rock_Stone"
    },
    {
      "x": -3,
      "y": 2,
      "z": 5,
      "name": "Rock_Quartzite"
    },
    {
      "x": -3,
      "y": 3,
      "z": 5,
      "name": "Rock_Quartzite"
    },
    {
      "x": -3,
      "y": 4,
      "z": 5,
      "name": "Rock_Quartzite"
    },
    {
      "x": -3,
      "y": 5,
      "z": 5,
      "name": "Rock_Quartzite"
    },
    {
      "x": -3,
      "y": 6,
      "z": 5,
      "name": "Rock_Quartzite"
    },
    {
      "x": -3,
      "y": 7,
      "z": 5,
      "name": "Rock_Quartzite"
    },
    {
      "x": -3,
      "y": 8,
      "z": 5,
      "name": "Rock_Quartzite_Brick"
    },
    {
      "x": -3,
      "y": 9,
      "z": 5,
      "name": "Rock_Quartzite_Brick_Stairs",
      "rotation": 1
    },
    {
      "x": -3,
      "y": 10,
      "z": 5,
      "name": "Empty"
    },
    {
      "x": -3,
      "y": 11,
      "z": 5,
      "name": "Empty"
    },
    {
      "x": -3,
      "y": 12,
      "z": 5,
      "name": "Empty"
    },
    {
      "x": -3,
      "y": 13,
      "z": 5,
      "name": "Empty"
    },
    {
      "x": -3,
      "y": 14,
      "z": 5,
      "name": "Rock_Quartzite_Cobble"
    },
    {
      "x": -3,
      "y": 15,
      "z": 5,
      "name": "Rock_Quartzite_Cobble"
    },
    {
      "x": -3,
      "y": 16,
      "z": 5,
      "name": "Rock_Quartzite_Cobble"
    },
    {
      "x": -3,
      "y": 17,
      "z": 5,
      "name": "Rock_Quartzite_Brick"
    },
    {
      "x": -3,
      "y": 18,
      "z": 5,
      "name": "Rock_Quartzite_Brick"
    },
    {
      "x": -3,
      "y": 19,
      "z": 5,
      "name": "Rock_Quartzite_Brick"
    },
    {
      "x": -3,
      "y": 20,
      "z": 5,
      "name": "Rock_Quartzite_Brick"
    },
    {
      "x": -3,
      "y": 21,
      "z": 5,
      "name": "Rock_Quartzite_Brick"
    },
    {
      "x": -3,
      "y": 22,
      "z": 5,
      "name": "Rock_Stone"
    },
    {
      "x": -3,
      "y": 2,
      "z": 6,
      "name": "Rock_Quartzite"
    },
    {
      "x": -3,
      "y": 3,
      "z": 6,
      "name": "Rock_Quartzite"
    },
    {
      "x": -3,
      "y": 4,
      "z": 6,
      "name": "Rock_Quartzite"
    },
    {
      "x": -3,
      "y": 5,
      "z": 6,
      "name": "Rock_Quartzite"
