{
  "version": 8,
  "blockIdVersion": 8,
  "anchorX": 7,
  "anchorY": 6,
  "anchorZ": 13,
  "blocks": [
    {
      "x": 2,
      "y": 7,
      "z": 13,
      "name": "Plant_Leaves_Gumboab"
    },
    {
      "x": 3,
      "y": 8,
      "z": 11,
      "name": "Plant_Leaves_Fir_Red"
    },
    {
      "x": 3,
      "y": 9,
      "z": 12,
      "name": "Plant_Leaves_Fir_Red"
    },
    {
      "x": 3,
      "y": 7,
      "z": 13,
      "name": "Plant_Leaves_Gumboab"
    },
    {
      "x": 3,
      "y": 9,
      "z": 14,
      "name": "Plant_Leaves_Gumboab"
    },
    {
      "x": 4,
      "y": 7,
      "z": 10,
      "name": "Plant_Leaves_Fir_Red"
    },
    {
      "x": 4,
      "y": 7,
      "z": 11,
      "name": "Plant_Leaves_Fir_Red"
    },
    {
      "x": 4,
      "y": 8,
      "z": 12,
      "name": "Plant_Leaves_Fir_Red"
    },
    {
      "x": 4,
      "y": 9,
      "z": 12,
      "name": "Plant_Leaves_Fir_Red"
    },
    {
      "x": 4,
      "y": 10,
      "z": 12,
      "name": "Plant_Leaves_Fir_Red"
    },
    {
      "x": 4,
      "y": 7,
      "z": 13,
      "name": "Plant_Leaves_Gumboab"
    },
    {
      "x": 4,
      "y": 9,
      "z": 13,
      "name": "Plant_Leaves_Fir_Red"
    },
    {
      "x": 4,
      "y": 8,
      "z": 14,
      "name": "Plant_Leaves_Gumboab"
    },
    {
      "x": 4,
      "y": 9,
      "z": 14,
      "name": "Plant_Leaves_Gumboab"
    },
    {
      "x": 5,
      "y": 8,
      "z": 9,
      "name": "Plant_Leaves_Fir_Red"
    },
    {
      "x": 5,
      "y": 7,
      "z": 10,
      "name": "Plant_Leaves_Fir_Red"
    },
    {
      "x": 5,
      "y": 7,
      "z": 11,
      "name": "Plant_Leaves_Fir_Red"
    },
    {
      "x": 5,
      "y": 8,
      "z": 11,
      "name": "Survival_Trap_Spike_Wood"
    },
    {
      "x": 5,
      "y": 10,
      "z": 11,
      "name": "Plant_Leaves_Fir_Red"
    },
    {
      "x": 5,
      "y": 7,
      "z": 12,
      "name": "Plant_Leaves_Fir_Red"
    },
    {
      "x": 5,
      "y": 8,
      "z": 12,
      "name": "Survival_Trap_Spike_Wood"
    },
    {
      "x": 5,
      "y": 10,
      "z": 12,
      "name": "Plant_Leaves_Fir_Red"
    },
    {
      "x": 5,
      "y": 7,
      "z": 13,
      "name": "Plant_Leaves_Gumboab"
    },
    {
      "x": 5,
      "y": 8,
      "z": 13,
      "name": "Plant_Leaves_Fir_Red"
    },
    {
      "x": 5,
      "y": 9,
      "z": 13,
      "name": "Plant_Leaves_Fir_Red"
    },
    {
      "x": 5,
      "y": 10,
      "z": 13,
      "name": "Plant_Leaves_Gumboab"
    },
    {
      "x": 5,
      "y": 11,
      "z": 13,
      "name": "Plant_Leaves_Gumboab"
    },
    {
      "x": 5,
      "y": 7,
      "z": 14,
      "name": "Plant_Leaves_Gumboab"
    },
    {
      "x": 5,
      "y": 8,
      "z": 14,
      "name": "Plant_Leaves_Gumboab"
    },
    {
      "x": 5,
      "y": 9,
      "z": 14,
      "name": "Plant_Leaves_Gumboab"
    },
    {
      "x": 6,
      "y": 7,
      "z": 8,
      "name": "Plant_Leaves_Gumboab"
    },
    {
      "x": 6,
      "y": 7,
      "z": 9,
      "name": "Plant_Leaves_Gumboab"
    },
    {
      "x": 6,
      "y": 9,
      "z": 9,
      "name": "Plant_Leaves_Fir_Red"
    },
    {
      "x": 6,
      "y": 7,
      "z": 10,
      "name": "Plant_Leaves_Gumboab"
    },
    {
      "x": 6,
      "y": 8,
      "z": 10,
      "name": "Plant_Leaves_Fir_Red"
    },
    {
      "x": 6,
      "y": 9,
      "z": 10,
      "name": "Plant_Leaves_Fir_Red"
    },
    {
      "x": 6,
      "y": 10,
      "z": 10,
      "name": "Plant_Leaves_Fir_Red"
    },
    {
      "x": 6,
      "y": 7,
      "z": 11,
      "name": "Plant_Leaves_Fir_Red"
    },
    {
      "x": 6,
      "y": 8,
      "z": 11,
      "name": "Survival_Trap_Spike_Wood"
    },
    {
      "x": 6,
      "y": 10,
      "z": 11,
      "name": "Plant_Leaves_Fir_Red"
    },
    {
      "x": 6,
      "y": 7,
      "z": 12,
      "name": "Plant_Leaves_Fir_Red"
    },
    {
      "x": 6,
      "y": 8,
      "z": 12,
      "name": "Rock_Crystal_Red_Large"
    },
    {
      "x": 6,
      "y": 10,
      "z": 12,
      "name": "Plant_Leaves_Fir_Red"
    },
    {
      "x": 6,
      "y": 7,
      "z": 13,
      "name": "Wood_Oak_Trunk"
    },
    {
      "x": 6,
      "y": 8,
      "z": 13,
      "name": "Plant_Leaves_Fir_Red"
    },
    {
      "x": 6,
      "y": 9,
      "z": 13,
      "name": "Plant_Leaves_Fir_Red"
    },
    {
      "x": 6,
      "y": 10,
      "z": 13,
      "name": "Plant_Leaves_Gumboab"
    },
    {
      "x": 6,
      "y": 7,
      "z": 14,
      "name": "Plant_Leaves_Gumboab"
    },
    {
      "x": 6,
      "y": 8,
      "z": 14,
      "name": "Plant_Leaves_Gumboab"
    },
    {
      "x": 6,
      "y": 9,
      "z": 14,
      "name": "Plant_Leaves_Gumboab"
    },
    {
      "x": 7,
      "y": 8,
      "z": 9,
      "name": "Plant_Leaves_Gumboab"
    },
    {
      "x": 7,
      "y": 7,
      "z": 10,
      "name": "Plant_Leaves_Gumboab"
    },
    {
      "x": 7,
      "y": 8,
      "z": 10,
      "name": "Plant_Leaves_Gumboab"
    },
    {
      "x": 7,
      "y": 9,
      "z": 10,
      "name": "Plant_Leaves_Fir_Red"
    },
    {
      "x": 7,
      "y": 7,
      "z": 11,
      "name": "Plant_Leaves_Gumboab"
    },
    {
      "x": 7,
      "y": 8,
      "z": 11,
      "name": "Plant_Leaves_Fir_Red"
    },
    {
      "x": 7,
      "y": 9,
      "z": 11,
      "name": "Plant_Leaves_Fir_Red"
    },
    {
      "x": 7,
      "y": 10,
      "z": 11,
      "name": "Plant_Leaves_Gumboab"
    },
    {
      "x": 7,
      "y": 11,
      "z": 11,
      "name": "Plant_Leaves_Gumboab"
    },
    {
      "x": 7,
      "y": 7,
      "z": 12,
      "name": "Wood_Oak_Trunk"
    },
    {
      "x": 7,
      "y": 8,
      "z": 12,
      "name": "Plant_Leaves_Fir_Red"
    },
    {
      "x": 7,
      "y": 9,
      "z": 12,
      "name": "Plant_Leaves_Fir_Red"
    },
    {
      "x": 7,
      "y": 10,
      "z": 12,
      "name": "Plant_Leaves_Gumboab"
    },
    {
      "x": 7,
      "y": 6,
      "z": 13,
      "name": "Wood_Oak_Trunk"
    },
    {
      "x": 7,
      "y": 7,
      "z": 13,
      "name": "Wood_Oak_Trunk"
    },
    {
      "x": 7,
      "y": 8,
      "z": 13,
      "name": "Wood_Oak_Trunk_Full"
    },
    {
      "x": 7,
      "y": 9,
      "z": 13,
      "name": "Plant_Leaves_Gumboab"
    },
    {
      "x": 7,
      "y": 8,
      "z": 14,
      "name": "Plant_Leaves_Gumboab"
    },
    {
      "x": 8,
      "y": 9,
      "z": 8,
      "name": "Plant_Leaves_Gumboab"
    },
    {
      "x": 8,
      "y": 9,
      "z": 9,
      "name": "Plant_Leaves_Gumboab"
    },
    {
      "x": 8,
      "y": 8,
      "z": 10,
      "name": "Plant_Leaves_Gumboab"
    },
    {
      "x": 8,
      "y": 9,
      "z": 10,
      "name": "Plant_Leaves_Gumboab"
    },
    {
      "x": 8,
      "y": 8,
      "z": 11,
      "name": "Plant_Leaves_Gumboab"
    },
    {
      "x": 8,
      "y": 7,
      "z": 12,
      "name": "Plant_Leaves_Gumboab"
    },
    {
      "x": 8,
      "y": 8,
      "z": 12,
      "name": "Plant_Leaves_Gumboab"
    },
    {
      "x": 8,
      "y": 9,
      "z": 12,
      "name": "Plant_Leaves_Gumboab"
    },
    {
      "x": 8,
      "y": 7,
      "z": 13,
      "name": "Plant_Leaves_Gumboab"
    },
    {
      "x": 8,
      "y": 9,
      "z": 13,
      "name": "Plant_Leaves_Gumboab"
    }
  ]
}