{
  "version": 8,
  "blockIdVersion": 8,
  "anchorX": 0,
  "anchorY": 5,
  "anchorZ": 0,
  "blocks": [
    {
      "x": -2,
      "y": 6,
      "z": -1,
      "name": "Rock_Stone"
    },
    {
      "x": -2,
      "y": 5,
      "z": 0,
      "name": "Rock_Stone"
    },
    {
      "x": -2,
      "y": 6,
      "z": 0,
      "name": "Rock_Stone"
    },
    {
      "x": -2,
      "y": 7,
      "z": 0,
      "name": "Rock_Stone"
    },
    {
      "x": -2,
      "y": 5,
      "z": 1,
      "name": "Rock_Stone"
    },
    {
      "x": -2,
      "y": 6,
      "z": 1,
      "name": "Rock_Stone"
    },
    {
      "x": -2,
      "y": 7,
      "z": 1,
      "name": "Rock_Stone"
    },
    {
      "x": -1,
      "y": 6,
      "z": -2,
      "name": "Rock_Stone"
    },
    {
      "x": -1,
      "y": 5,
      "z": -1,
      "name": "Rock_Stone"
    },
    {
      "x": -1,
      "y": 6,
      "z": -1,
      "name": "Rock_Stone"
    },
    {
      "x": -1,
      "y": 7,
      "z": -1,
      "name": "Rock_Stone_Mossy"
    },
    {
      "x": -1,
      "y": 3,
      "z": 0,
      "name": "Rock_Stone"
    },
    {
      "x": -1,
      "y": 5,
      "z": 0,
      "name": "Rock_Stone"
    },
    {
      "x": -1,
      "y": 6,
      "z": 0,
      "name": "Rock_Stone"
    },
    {
      "x": -1,
      "y": 7,
      "z": 0,
      "name": "Rock_Stone"
    },
    {
      "x": -1,
      "y": 4,
      "z": 1,
      "name": "Rock_Stone"
    },
    {
      "x": -1,
      "y": 5,
      "z": 1,
      "name": "Rock_Stone"
    },
    {
      "x": -1,
      "y": 6,
      "z": 1,
      "name": "Rock_Stone"
    },
    {
      "x": -1,
      "y": 7,
      "z": 1,
      "name": "Rock_Stone"
    },
    {
      "x": -1,
      "y": 5,
      "z": 2,
      "name": "Rock_Stone"
    },
    {
      "x": -1,
      "y": 6,
      "z": 2,
      "name": "Rock_Stone"
    },
    {
      "x": 0,
      "y": 4,
      "z": -2,
      "name": "Rock_Stone"
    },
    {
      "x": 0,
      "y": 5,
      "z": -2,
      "name": "Rock_Stone"
    },
    {
      "x": 0,
      "y": 6,
      "z": -2,
      "name": "Rock_Stone"
    },
    {
      "x": 0,
      "y": 3,
      "z": -1,
      "name": "Rock_Stone"
    },
    {
      "x": 0,
      "y": 4,
      "z": -1,
      "name": "Rock_Stone"
    },
    {
      "x": 0,
      "y": 5,
      "z": -1,
      "name": "Rock_Stone"
    },
    {
      "x": 0,
      "y": 6,
      "z": -1,
      "name": "Rock_Stone"
    },
    {
      "x": 0,
      "y": 7,
      "z": -1,
      "name": "Rock_Stone_Mossy"
    },
    {
      "x": 0,
      "y": 2,
      "z": 0,
      "name": "Rock_Stone"
    },
    {
      "x": 0,
      "y": 3,
      "z": 0,
      "name": "Rock_Stone"
    },
    {
      "x": 0,
      "y": 4,
      "z": 0,
      "name": "Rock_Stone"
    },
    {
      "x": 0,
      "y": 5,
      "z": 0,
      "name": "Rock_Stone"
    },
    {
      "x": 0,
      "y": 6,
      "z": 0,
      "name": "Rock_Stone"
    },
    {
      "x": 0,
      "y": 7,
      "z": 0,
      "name": "Rock_Stone_Mossy"
    },
    {
      "x": 0,
      "y": 3,
      "z": 1,
      "name": "Rock_Stone"
    },
    {
      "x": 0,
      "y": 4,
      "z": 1,
      "name": "Rock_Stone"
    },
    {
      "x": 0,
      "y": 5,
      "z": 1,
      "name": "Rock_Stone"
    },
    {
      "x": 0,
      "y": 6,
      "z": 1,
      "name": "Rock_Stone"
    },
    {
      "x": 0,
      "y": 7,
      "z": 1,
      "name": "Rock_Stone"
    },
    {
      "x": 0,
      "y": 4,
      "z": 2,
      "name": "Rock_Stone"
    },
    {
      "x": 0,
      "y": 5,
      "z": 2,
      "name": "Rock_Stone"
    },
    {
      "x": 0,
      "y": 6,
      "z": 2,
      "name": "Rock_Stone"
    },
    {
      "x": 1,
      "y": 3,
      "z": -2,
      "name": "Rock_Stone"
    },
    {
      "x": 1,
      "y": 4,
      "z": -2,
      "name": "Rock_Stone"
    },
    {
      "x": 1,
      "y": 5,
      "z": -2,
      "name": "Rock_Stone"
    },
    {
      "x": 1,
      "y": 6,
      "z": -2,
      "name": "Rock_Stone"
    },
    {
      "x": 1,
      "y": 1,
      "z": -1,
      "name": "Rock_Stone"
    },
    {
      "x": 1,
      "y": 2,
      "z": -1,
      "name": "Rock_Stone"
    },
    {
      "x": 1,
      "y": 3,
      "z": -1,
      "name": "Rock_Stone"
    },
    {
      "x": 1,
      "y": 4,
      "z": -1,
      "name": "Rock_Stone"
    },
    {
      "x": 1,
      "y": 5,
      "z": -1,
      "name": "Rock_Stone"
    },
    {
      "x": 1,
      "y": 6,
      "z": -1,
      "name": "Rock_Stone"
    },
    {
      "x": 1,
      "y": 7,
      "z": -1,
      "name": "Plant_Crop_Mana1"
    },
    {
      "x": 1,
      "y": 2,
      "z": 0,
      "name": "Rock_Stone"
    },
    {
      "x": 1,
      "y": 3,
      "z": 0,
      "name": "Rock_Stone"
    },
    {
      "x": 1,
      "y": 4,
      "z": 0,
      "name": "Rock_Stone"
    },
    {
      "x": 1,
      "y": 5,
      "z": 0,
      "name": "Rock_Stone"
    },
    {
      "x": 1,
      "y": 6,
      "z": 0,
      "name": "Rock_Stone"
    },
    {
      "x": 1,
      "y": 7,
      "z": 0,
      "name": "Rock_Stone"
    },
    {
      "x": 1,
      "y": 2,
      "z": 1,
      "name": "Rock_Stone"
    },
    {
      "x": 1,
      "y": 3,
      "z": 1,
      "name": "Rock_Stone"
    },
    {
      "x": 1,
      "y": 4,
      "z": 1,
      "name": "Rock_Stone"
    },
    {
      "x": 1,
      "y": 5,
      "z": 1,
      "name": "Rock_Stone"
    },
    {
      "x": 1,
      "y": 6,
      "z": 1,
      "name": "Rock_Stone"
    },
    {
      "x": 1,
      "y": 3,
      "z": 2,
      "name": "Rock_Stone"
    },
    {
      "x": 1,
      "y": 4,
      "z": 2,
      "name": "Rock_Stone"
    },
    {
      "x": 1,
      "y": 5,
      "z": 2,
      "name": "Rock_Stone"
    },
    {
      "x": 2,
      "y": 3,
      "z": -2,
      "name": "Rock_Stone"
    },
    {
      "x": 2,
      "y": 4,
      "z": -2,
      "name": "Rock_Stone"
    },
    {
      "x": 2,
      "y": 2,
      "z": -1,
      "name": "Rock_Stone"
    },
    {
      "x": 2,
      "y": 3,
      "z": -1,
      "name": "Rock_Stone"
    },
    {
      "x": 2,
      "y": 4,
      "z": -1,
      "name": "Rock_Stone"
    },
    {
      "x": 2,
      "y": 5,
      "z": -1,
      "name": "Rock_Stone"
    },
    {
      "x": 2,
      "y": 1,
      "z": 0,
      "name": "Rock_Stone"
    },
    {
      "x": 2,
      "y": 2,
      "z": 0,
      "name": "Rock_Stone"
    },
    {
      "x": 2,
      "y": 3,
      "z": 0,
      "name": "Rock_Stone"
    },
    {
      "x": 2,
      "y": 4,
      "z": 0,
      "name": "Rock_Stone"
    },
    {
      "x": 2,
      "y": 5,
      "z": 0,
      "name": "Rock_Stone"
    },
    {
      "x": 2,
      "y": 6,
      "z": 0,
      "name": "Rock_Stone"
    },
    {
      "x": 2,
      "y": 3,
      "z": 1,
      "name": "Rock_Stone"
    },
    {
      "x": 2,
      "y": 4,
      "z": 1,
      "name": "Rock_Stone"
    },
    {
      "x": 2,
      "y": 5,
      "z": 1,
      "name": "Rock_Stone"
    },
    {
      "x": 2,
      "y": 6,
      "z": 1,
      "name": "Rock_Stone"
    },
    {
      "x": 3,
      "y": 3,
      "z": -1,
      "name": "Rock_Stone"
    },
    {
      "x": 3,
      "y": 4,
      "z": -1,
      "name": "Rock_Stone"
    },
    {
      "x": 3,
      "y": 2,
      "z": 0,
      "name": "Rock_Stone"
    },
    {
      "x": 3,
      "y": 3,
      "z": 0,
      "name": "Rock_Stone"
    },
    {
      "x": 3,
      "y": 4,
      "z": 0,
      "name": "Rock_Stone"
    },
    {
      "x": 3,
      "y": 5,
      "z": 0,
      "name": "Rock_Stone"
    }
  ]
}