{
  "version": 8,
  "blockIdVersion": 8,
  "anchorX": 0,
  "anchorY": 0,
  "anchorZ": 0,
  "blocks": [
    {
      "x": -4,
      "y": 0,
      "z": -7,
      "name": "Rock_Volcanic_Cobble"
    },
    {
      "x": -4,
      "y": 1,
      "z": -7,
      "name": "Rock_Volcanic_Cobble"
    },
    {
      "x": -4,
      "y": 2,
      "z": -7,
      "name": "Rock_Volcanic_Cobble"
    },
    {
      "x": -4,
      "y": 3,
      "z": -7,
      "name": "Rock_Volcanic_Cobble"
    },
    {
      "x": -4,
      "y": 4,
      "z": -7,
      "name": "Rock_Volcanic_Cobble"
    },
    {
      "x": -4,
      "y": 5,
      "z": -7,
      "name": "Rock_Volcanic_Cobble"
    },
    {
      "x": -4,
      "y": 6,
      "z": -7,
      "name": "Rock_Stone"
    },
    {
      "x": -4,
      "y": 7,
      "z": -7,
      "name": "Rock_Stone"
    },
    {
      "x": -4,
      "y": 8,
      "z": -7,
      "name": "Rock_Stone"
    },
    {
      "x": -4,
      "y": 9,
      "z": -7,
      "name": "Rock_Stone"
    },
    {
      "x": -4,
      "y": 10,
      "z": -7,
      "name": "Rock_Stone"
    },
    {
      "x": -4,
      "y": 11,
      "z": -7,
      "name": "Rock_Stone"
    },
    {
      "x": -4,
      "y": 12,
      "z": -7,
      "name": "Rock_Stone"
    },
    {
      "x": -4,
      "y": 13,
      "z": -7,
      "name": "Rock_Stone"
    },
    {
      "x": -4,
      "y": 14,
      "z": -7,
      "name": "Rock_Stone"
    },
    {
      "x": -4,
      "y": 0,
      "z": -6,
      "name": "Rock_Volcanic_Cobble"
    },
    {
      "x": -4,
      "y": 1,
      "z": -6,
      "name": "Rock_Volcanic_Cobble"
    },
    {
      "x": -4,
      "y": 2,
      "z": -6,
      "name": "Rock_Volcanic_Cobble"
    },
    {
      "x": -4,
      "y": 3,
      "z": -6,
      "name": "Rock_Volcanic_Cobble"
    },
    {
      "x": -4,
      "y": 4,
      "z": -6,
      "name": "Rock_Volcanic_Cobble"
    },
    {
      "x": -4,
      "y": 5,
      "z": -6,
      "name": "Rock_Volcanic_Cobble"
    },
    {
      "x": -4,
      "y": 6,
      "z": -6,
      "name": "Rock_Stone"
    },
    {
      "x": -4,
      "y": 7,
      "z": -6,
      "name": "Rock_Stone"
    },
    {
      "x": -4,
      "y": 8,
      "z": -6,
      "name": "Rock_Stone"
    },
    {
      "x": -4,
      "y": 9,
      "z": -6,
      "name": "Rock_Stone"
    },
    {
      "x": -4,
      "y": 10,
      "z": -6,
      "name": "Rock_Stone"
    },
    {
      "x": -4,
      "y": 11,
      "z": -6,
      "name": "Rock_Stone"
    },
    {
      "x": -4,
      "y": 12,
      "z": -6,
      "name": "Rock_Stone"
    },
    {
      "x": -4,
      "y": 13,
      "z": -6,
      "name": "Rock_Stone"
    },
    {
      "x": -4,
      "y": 14,
      "z": -6,
      "name": "Rock_Stone"
    },
    {
      "x": -4,
      "y": 0,
      "z": -5,
      "name": "Rock_Volcanic_Cobble"
    },
    {
      "x": -4,
      "y": 1,
      "z": -5,
      "name": "Rock_Volcanic_Cobble"
    },
    {
      "x": -4,
      "y": 2,
      "z": -5,
      "name": "Rock_Volcanic_Cobble"
    },
    {
      "x": -4,
      "y": 3,
      "z": -5,
      "name": "Rock_Volcanic_Cobble"
    },
    {
      "x": -4,
      "y": 4,
      "z": -5,
      "name": "Rock_Volcanic_Cobble"
    },
    {
      "x": -4,
      "y": 5,
      "z": -5,
      "name": "Rock_Volcanic_Cobble"
    },
    {
      "x": -4,
      "y": 6,
      "z": -5,
      "name": "Rock_Stone"
    },
    {
      "x": -4,
      "y": 7,
      "z": -5,
      "name": "Rock_Stone"
    },
    {
      "x": -4,
      "y": 8,
      "z": -5,
      "name": "Rock_Stone"
    },
    {
      "x": -4,
      "y": 9,
      "z": -5,
      "name": "Rock_Stone"
    },
    {
      "x": -4,
      "y": 10,
      "z": -5,
      "name": "Rock_Stone"
    },
    {
      "x": -4,
      "y": 11,
      "z": -5,
      "name": "Rock_Stone"
    },
    {
      "x": -4,
      "y": 12,
      "z": -5,
      "name": "Rock_Stone"
    },
    {
      "x": -4,
      "y": 13,
      "z": -5,
      "name": "Rock_Stone"
    },
    {
      "x": -4,
      "y": 14,
      "z": -5,
      "name": "Rock_Stone"
    },
    {
      "x": -4,
      "y": 0,
      "z": -4,
      "name": "Rock_Volcanic_Cobble"
    },
    {
      "x": -4,
      "y": 1,
      "z": -4,
      "name": "Rock_Volcanic_Cobble"
    },
    {
      "x": -4,
      "y": 2,
      "z": -4,
      "name": "Rock_Volcanic_Cobble"
    },
    {
      "x": -4,
      "y": 3,
      "z": -4,
      "name": "Rock_Volcanic_Cobble"
    },
    {
      "x": -4,
      "y": 4,
      "z": -4,
      "name": "Rock_Volcanic_Cobble"
    },
    {
      "x": -4,
      "y": 5,
      "z": -4,
      "name": "Rock_Volcanic_Cobble"
    },
    {
      "x": -4,
      "y": 6,
      "z": -4,
      "name": "Rock_Stone"
    },
    {
      "x": -4,
      "y": 7,
      "z": -4,
      "name": "Rock_Stone"
    },
    {
      "x": -4,
      "y": 8,
      "z": -4,
      "name": "Rock_Stone"
    },
    {
      "x": -4,
      "y": 9,
      "z": -4,
      "name": "Rock_Stone"
    },
    {
      "x": -4,
      "y": 10,
      "z": -4,
      "name": "Rock_Stone"
    },
    {
      "x": -4,
      "y": 11,
      "z": -4,
      "name": "Rock_Stone"
    },
    {
      "x": -4,
      "y": 12,
      "z": -4,
      "name": "Rock_Stone"
    },
    {
      "x": -4,
      "y": 13,
      "z": -4,
      "name": "Rock_Stone"
    },
    {
      "x": -4,
      "y": 14,
      "z": -4,
      "name": "Rock_Stone"
    },
    {
      "x": -4,
      "y": 0,
      "z": -3,
      "name": "Rock_Volcanic_Cobble"
    },
    {
      "x": -4,
      "y": 1,
      "z": -3,
      "name": "Rock_Volcanic_Cobble"
    },
    {
      "x": -4,
      "y": 2,
      "z": -3,
      "name": "Rock_Volcanic_Cobble"
    },
    {
      "x": -4,
      "y": 3,
      "z": -3,
      "name": "Rock_Volcanic_Cobble"
    },
    {
      "x": -4,
      "y": 4,
      "z": -3,
      "name": "Rock_Volcanic_Cobble"
    },
    {
      "x": -4,
      "y": 5,
      "z": -3,
      "name": "Rock_Volcanic_Cobble"
    },
    {
      "x": -4,
      "y": 6,
      "z": -3,
      "name": "Rock_Stone"
    },
    {
      "x": -4,
      "y": 7,
      "z": -3,
      "name": "Rock_Stone"
    },
    {
      "x": -4,
      "y": 8,
      "z": -3,
      "name": "Rock_Stone"
    },
    {
      "x": -4,
      "y": 9,
      "z": -3,
      "name": "Rock_Stone"
    },
    {
      "x": -4,
      "y": 10,
      "z": -3,
      "name": "Rock_Stone"
    },
    {
      "x": -4,
      "y": 11,
      "z": -3,
      "name": "Rock_Stone"
    },
    {
      "x": -4,
      "y": 12,
      "z": -3,
      "name": "Rock_Stone"
    },
    {
      "x": -4,
      "y": 13,
      "z": -3,
      "name": "Rock_Stone"
    },
    {
      "x": -4,
      "y": 14,
      "z": -3,
      "name": "Rock_Stone"
    },
    {
      "x": -4,
      "y": 0,
      "z": -2,
      "name": "Rock_Volcanic_Cobble"
    },
    {
      "x": -4,
      "y": 1,
      "z": -2,
      "name": "Rock_Volcanic_Cobble"
    },
    {
      "x": -4,
      "y": 2,
      "z": -2,
      "name": "Rock_Volcanic_Cobble"
    },
    {
      "x": -4,
      "y": 3,
      "z": -2,
      "name": "Rock_Volcanic_Cobble"
    },
    {
      "x": -4,
      "y": 4,
      "z": -2,
      "name": "Rock_Volcanic_Cobble"
    },
    {
      "x": -4,
      "y": 5,
      "z": -2,
      "name": "Rock_Volcanic_Cobble"
    },
    {
      "x": -4,
      "y": 6,
      "z": -2,
      "name": "Rock_Stone"
    },
    {
      "x": -4,
      "y": 7,
      "z": -2,
      "name": "Rock_Stone"
    },
    {
      "x": -4,
      "y": 8,
      "z": -2,
      "name": "Rock_Stone"
    },
    {
      "x": -4,
      "y": 9,
      "z": -2,
      "name": "Rock_Stone"
    },
    {
      "x": -4,
      "y": 10,
      "z": -2,
      "name": "Rock_Stone"
    },
    {
      "x": -4,
      "y": 11,
      "z": -2,
      "name": "Rock_Stone"
    },
    {
      "x": -4,
      "y": 12,
      "z": -2,
      "name": "Rock_Stone"
    },
    {
      "x": -4,
      "y": 13,
      "z": -2,
      "name": "Rock_Stone"
    },
    {
      "x": -4,
      "y": 14,
      "z": -2,
      "name": "Rock_Stone"
    },
    {
      "x": -4,
      "y": 0,
      "z": -1,
      "name": "Rock_Volcanic_Cobble"
    },
    {
      "x": -4,
      "y": 1,
      "z": -1,
      "name": "Rock_Volcanic_Cobble"
    },
    {
      "x": -4,
      "y": 2,
      "z": -1,
      "name": "Rock_Volcanic_Cobble"
    },
    {
      "x": -4,
      "y": 3,
      "z": -1,
      "name": "Rock_Volcanic_Cobble"
    },
    {
      "x": -4,
      "y": 4,
      "z": -1,
      "name": "Rock_Volcanic_Cobble"
    },
    {
      "x": -4,
      "y": 5,
      "z": -1,
      "name": "Rock_Volcanic_Cobble"
    },
    {
      "x": -4,
      "y": 6,
      "z": -1,
      "name": "Rock_Stone"
    },
    {
      "x": -4,
      "y": 7,
      "z": -1,
      "name": "Rock_Stone"
    },
    {
      "x": -4,
      "y": 8,
      "z": -1,
      "name": "Rock_Stone"
    },
    {
      "x": -4,
      "y": 9,
      "z": -1,
      "name": "Rock_Stone"
    },
    {
      "x": -4,
      "y": 10,
      "z": -1,
      "name": "Rock_Stone"
    },
    {
      "x": -4,
      "y": 11,
      "z": -1,
      "name": "Rock_Stone"
    },
    {
      "x": -4,
      "y": 12,
      "z": -1,
      "name": "Rock_Stone"
    },
    {
      "x": -4,
      "y": 13,
      "z": -1,
      "name": "Rock_Stone"
    },
    {
      "x": -4,
      "y": 14,
      "z": -1,
      "name": "Rock_Stone"
    },
    {
      "x": -4,
      "y": 0,
      "z": 0,
      "name": "Rock_Volcanic_Cobble"
    },
    {
      "x": -4,
      "y": 1,
      "z": 0,
      "name": "Rock_Volcanic_Cobble"
    },
    {
      "x": -4,
      "y": 2,
      "z": 0,
      "name": "Rock_Volcanic_Cobble"
    },
    {
      "x": -4,
      "y": 3,
      "z": 0,
      "name": "Rock_Volcanic_Cobble"
    },
    {
      "x": -4,
      "y": 4,
      "z": 0,
      "name": "Rock_Volcanic_Cobble"
    },
    {
      "x": -4,
      "y": 5,
      "z": 0,
      "name": "Rock_Volcanic_Cobble"
    },
    {
      "x": -4,
      "y": 6,
      "z": 0,
      "name": "Rock_Stone"
    },
    {
      "x": -4,
      "y": 7,
      "z": 0,
      "name": "Rock_Stone"
    },
    {
      "x": -4,
      "y": 8,
      "z": 0,
      "name": "Rock_Stone"
    },
    {
      "x": -4,
      "y": 9,
      "z": 0,
      "name": "Rock_Stone"
    },
    {
      "x": -4,
      "y": 10,
      "z": 0,
      "name": "Rock_Stone"
    },
    {
      "x": -4,
      "y": 11,
      "z": 0,
      "name": "Rock_Stone"
    },
    {
      "x": -4,
      "y": 12,
      "z": 0,
      "name": "Rock_Stone"
    },
    {
      "x": -4,
      "y": 13,
      "z": 0,
      "name": "Rock_Stone"
    },
    {
      "x": -4,
      "y": 14,
      "z": 0,
      "name": "Rock_Stone"
    },
    {
      "x": -3,
      "y": 0,
      "z": -7,
      "name": "Rock_Stone_Brick_Smooth"
    },
    {
      "x": -3,
      "y": 1,
      "z": -7,
      "name": "Rock_Stone_Brick_Smooth_Half",
      "rotation": 4
    },
    {
      "x": -3,
      "y": 2,
      "z": -7,
      "name": "Rock_Stone_Brick_Smooth"
    },
    {
      "x": -3,
      "y": 3,
      "z": -7,
      "name": "Rock_Stone_Brick_Smooth_Half",
      "rotation": 4
    },
    {
      "x": -3,
      "y": 4,
      "z": -7,
      "name": "Rock_Stone_Brick_Smooth"
    },
    {
      "x": -3,
      "y": 5,
      "z": -7,
      "name": "Rock_Stone_Brick_Smooth"
    },
    {
      "x": -3,
      "y": 6,
      "z": -7,
      "name": "Rock_Stone"
    },
    {
      "x": -3,
      "y": 7,
      "z": -7,
      "name": "Rock_Stone"
    },
    {
      "x": -3,
      "y": 8,
      "z": -7,
      "name": "Rock_Stone"
    },
    {
      "x": -3,
      "y": 9,
      "z": -7,
      "name": "Rock_Stone"
    },
    {
      "x": -3,
      "y": 10,
      "z": -7,
      "name": "Rock_Stone"
    },
    {
      "x": -3,
      "y": 11,
      "z": -7,
      "name": "Rock_Stone"
    },
    {
      "x": -3,
      "y": 12,
      "z": -7,
      "name": "Rock_Stone"
    },
    {
      "x": -3,
      "y": 13,
      "z": -7,
      "name": "Rock_Stone"
    },
    {
      "x": -3,
      "y": 14,
      "z": -7,
      "name": "Rock_Stone"
    },
    {
      "x": -3,
      "y": 0,
      "z": -6,
      "name": "Rock_Stone_Brick_Smooth"
    },
    {
      "x": -3,
      "y": 1,
      "z": -6,
      "name": "Deco_Bone_Skulls"
    },
    {
      "x": -3,
      "y": 2,
      "z": -6,
      "name": "Rock_Stone_Brick_Smooth_Half",
      "rotation": 8
    },
    {
      "x": -3,
      "y": 3,
      "z": -6,
      "name": "Empty"
    },
    {
      "x": -3,
      "y": 4,
      "z": -6,
      "name": "Rock_Stone_Brick_Smooth_Half",
      "rotation": 8
    },
    {
      "x": -3,
      "y": 5,
      "z": -6,
      "name": "Rock_Stone_Brick_Smooth"
    },
    {
      "x": -3,
      "y": 6,
      "z": -6,
      "name": "Rock_Stone"
    },
    {
      "x": -3,
      "y": 7,
      "z": -6,
      "name": "Rock_Stone"
    },
    {
      "x": -3,
      "y": 8,
      "z": -6,
      "name": "Rock_Stone"
    },
    {
      "x": -3,
      "y": 9,
      "z": -6,
      "name": "Rock_Stone"
    },
    {
      "x": -3,
      "y": 10,
      "z": -6,
      "name": "Rock_Stone"
    },
    {
      "x": -3,
      "y": 11,
      "z": -6,
      "name": "Rock_Stone"
    },
    {
      "x": -3,
      "y": 12,
      "z": -6,
      "name": "Rock_Stone"
    },
    {
      "x": -3,
      "y": 13,
      "z": -6,
      "name": "Rock_Stone"
    },
    {
      "x": -3,
      "y": 14,
      "z": -6,
      "name": "Rock_Stone"
    },
    {
      "x": -3,
      "y": 0,
      "z": -5,
      "name": "Rock_Stone_Brick_Smooth"
    },
    {
      "x": -3,
      "y": 1,
      "z": -5,
      "name": "Rock_Stone_Brick_Smooth"
    },
    {
      "x": -3,
      "y": 2,
      "z": -5,
      "name": "Rock_Stone_Brick_Smooth"
    },
    {
      "x": -3,
      "y": 3,
      "z": -5,
      "name": "Rock_Stone_Brick_Smooth"
    },
    {
      "x": -3,
      "y": 4,
      "z": -5,
      "name": "Rock_Stone_Brick_Smooth"
    },
    {
      "x": -3,
      "y": 5,
      "z": -5,
      "name": "Rock_Stone_Brick_Smooth"
    },
    {
      "x": -3,
      "y": 6,
      "z": -5,
      "name": "Rock_Stone"
    },
    {
      "x": -3,
      "y": 7,
      "z": -5,
      "name": "Rock_Stone"
    },
    {
      "x": -3,
      "y": 8,
      "z": -5,
      "name": "Rock_Stone"
    },
    {
      "x": -3,
      "y": 9,
      "z": -5,
      "name": "Rock_Stone"
    },
    {
      "x": -3,
      "y": 10,
      "z": -5,
      "name": "Rock_Stone"
    },
    {
      "x": -3,
      "y": 11,
      "z": -5,
      "name": "Rock_Stone"
    },
    {
      "x": -3,
      "y": 12,
      "z": -5,
      "name": "Rock_Stone"
    },
    {
      "x": -3,
      "y": 13,
      "z": -5,
      "name": "Rock_Stone"
    },
    {
      "x": -3,
      "y": 14,
      "z": -5,
      "name": "Rock_Stone"
    },
    {
      "x": -3,
      "y": 0,
      "z": -4,
      "name": "Rock_Stone_Brick_Smooth"
    },
    {
      "x": -3,
      "y": 1,
      "z": -4,
      "name": "Rock_Stone_Brick_Smooth"
    },
    {
      "x": -3,
      "y": 2,
      "z": -4,
      "name": "Rock_Stone_Brick_Smooth"
    },
    {
      "x": -3,
      "y": 3,
      "z": -4,
      "name": "Rock_Stone_Brick_Smooth"
    },
    {
      "x": -3,
      "y": 4,
      "z": -4,
      "name": "Rock_Stone_Brick_Smooth"
    },
    {
      "x": -3,
      "y": 5,
      "z": -4,
      "name": "Rock_Stone_Brick_Smooth"
    },
    {
      "x": -3,
      "y": 6,
      "z": -4,
      "name": "Rock_Stone"
    },
    {
      "x": -3,
      "y": 7,
      "z": -4,
      "name": "Rock_Stone"
    },
    {
      "x": -3,
      "y": 8,
      "z": -4,
      "name": "Rock_Stone"
    },
    {
      "x": -3,
      "y": 9,
      "z": -4,
      "name": "Rock_Stone"
    },
    {
      "x": -3,
      "y": 10,
      "z": -4,
      "name": "Rock_Stone"
    },
    {
      "x": -3,
      "y": 11,
      "z": -4,
      "name": "Rock_Stone"
    },
    {
      "x": -3,
      "y": 12,
      "z": -4,
      "name": "Rock_Stone"
    },
    {
      "x": -3,
      "y": 13,
      "z": -4,
      "name": "Rock_Stone"
    },
    {
      "x": -3,
      "y": 14,
      "z": -4,
      "name": "Rock_Stone"
    },
    {
      "x": -3,
      "y": 0,
      "z": -3,
      "name": "Rock_Stone_Brick_Smooth"
    },
    {
      "x": -3,
      "y": 1,
      "z": -3,
      "name": "Rock_Stone_Brick_Smooth_Half",
      "rotation": 4
    },
    {
      "x": -3,
      "y": 2,
      "z": -3,
      "name": "Rock_Stone_Brick_Smooth"
    },
    {
      "x": -3,
      "y": 3,
      "z": -3,
      "name": "Rock_Stone_Brick_Smooth_Half",
      "rotation": 4
    },
    {
      "x": -3,
      "y": 4,
      "z": -3,
      "name": "Rock_Stone_Brick_Smooth"
    },
    {
      "x": -3,
      "y": 5,
      "z": -3,
      "name": "Rock_Stone_Brick_Smooth"
    },
    {
      "x": -3,
      "y": 6,
      "z": -3,
      "name": "Rock_Stone"
    },
    {
      "x": -3,
      "y": 7,
      "z": -3,
      "name": "Rock_Stone"
    },
    {
      "x": -3,
      "y": 8,
      "z": -3,
      "name": "Rock_Stone"
    },
    {
      "x": -3,
      "y": 9,
      "z": -3,
      "name": "Rock_Stone"
    },
    {
      "x": -3,
      "y": 10,
      "z": -3,
      "name": "Rock_Stone"
    },
    {
      "x": -3,
      "y": 11,
      "z": -3,
      "name": "Rock_Stone"
    },
    {
      "x": -3,
      "y": 12,
      "z": -3,
      "name": "Rock_Stone"
    },
    {
      "x": -3,
      "y": 13,
      "z": -3,
      "name": "Rock_Stone"
    },
    {
      "x": -3,
      "y": 14,
      "z": -3,
      "name": "Rock_Stone"
    },
    {
      "x": -3,
      "y": 0,
      "z": -2,
      "name": "Rock_Stone_Brick_Smooth"
    },
    {
      "x": -3,
      "y": 1,
      "z": -2,
      "name": "Furniture_Human_Ruins_Coffin",
      "filler": 992,
      "rotation": 1
    },
    {
      "x": -3,
      "y": 2,
      "z": -2,
      "name": "Rock_Stone_Brick_Smooth_Half",
      "rotation": 8
    },
    {
      "x": -3,
      "y": 3,
      "z": -2,
      "name": "Furniture_Human_Ruins_Coffin",
      "filler": 992,
      "rotation": 1
    },
    {
      "x": -3,
      "y": 4,
      "z": -2,
      "name": "Rock_Stone_Brick_Smooth_Half",
      "rotation": 8
    },
    {
      "x": -3,
      "y": 5,
      "z": -2,
      "name": "Rock_Stone_Brick_Smooth"
    },
    {
      "x": -3,
      "y": 6,
      "z": -2,
      "name": "Rock_Stone"
    },
    {
      "x": -3,
      "y": 7,
      "z": -2,
      "name": "Rock_Stone"
    },
    {
      "x": -3,
      "y": 8,
      "z": -2,
      "name": "Rock_Stone"
    },
    {
      "x": -3,
      "y": 9,
      "z": -2,
      "name": "Rock_Stone"
    },
    {
      "x": -3,
      "y": 10,
      "z": -2,
      "name": "Rock_Stone"
    },
    {
      "x": -3,
      "y": 11,
      "z": -2,
      "name": "Rock_Stone"
    },
    {
      "x": -3,
      "y": 12,
      "z": -2,
      "name": "Rock_Stone"
    },
    {
      "x": -3,
      "y": 13,
      "z": -2,
      "name": "Rock_Stone"
    },
    {
      "x": -3,
      "y": 14,
      "z": -2,
      "name": "Rock_Stone"
    },
    {
      "x": -3,
      "y": 0,
      "z": -1,
      "name": "Rock_Stone_Brick_Smooth"
    },
    {
      "x": -3,
      "y": 1,
      "z": -1,
      "name": "Furniture_Human_Ruins_Coffin",
      "rotation": 1
    },
    {
      "x": -3,
      "y": 2,
      "z": -1,
      "name": "Rock_Stone_Brick_Smooth_Half",
      "rotation": 8
    },
    {
      "x": -3,
      "y": 3,
      "z": -1,
      "name": "Furniture_Human_Ruins_Coffin",
      "rotation": 1
    },
    {
      "x": -3,
      "y": 4,
      "z": -1,
      "name": "Rock_Stone_Brick_Smooth_Half",
      "rotation": 8
    },
    {
      "x": -3,
      "y": 5,
      "z": -1,
      "name": "Rock_Stone_Brick_Smooth"
    },
    {
      "x": -3,
      "y": 6,
      "z": -1,
      "name": "Rock_Stone"
    },
    {
      "x": -3,
      "y": 7,
      "z": -1,
      "name": "Rock_Stone"
    },
    {
      "x": -3,
      "y": 8,
      "z": -1,
      "name": "Rock_Stone"
    },
    {
      "x": -3,
      "y": 9,
      "z": -1,
      "name": "Rock_Stone"
    },
    {
      "x": -3,
      "y": 10,
      "z": -1,
      "name": "Rock_Stone"
    },
    {
      "x": -3,
      "y": 11,
      "z": -1,
      "name": "Rock_Stone"
    },
    {
      "x": -3,
      "y": 12,
      "z": -1,
      "name": "Rock_Stone"
    },
    {
      "x": -3,
      "y": 13,
      "z": -1,
      "name": "Rock_Stone"
    },
    {
      "x": -3,
      "y": 14,
      "z": -1,
      "name": "Rock_Stone"
    },
    {
      "x": -3,
      "y": 0,
      "z": 0,
      "name": "Rock_Stone_Brick_Smooth"
    },
    {
      "x": -3,
      "y": 1,
      "z": 0,
      "name": "Rock_Stone_Brick_Smooth_Half",
      "rotation": 6
    },
    {
      "x": -3,
      "y": 2,
      "z": 0,
      "name": "Rock_Stone_Brick_Smooth"
    },
    {
      "x": -3,
      "y": 3,
      "z": 0,
      "name": "Rock_Stone_Brick_Smooth_Half",
      "rotation": 6
    },
    {
      "x": -3,
      "y": 4,
      "z": 0,
      "name": "Rock_Stone_Brick_Smooth"
    },
    {
      "x": -3,
      "y": 5,
      "z": 0,
      "name": "Rock_Stone_Brick_Smooth"
    },
    {
      "x": -3,
      "y": 6,
      "z": 0,
      "name": "Rock_Stone"
    },
    {
      "x": -3,
      "y": 7,
      "z": 0,
      "name": "Rock_Stone"
    },
    {
      "x": -3,
      "y": 8,
      "z": 0,
      "name": "Rock_Stone"
    },
    {
      "x": -3,
      "y": 9,
      "z": 0,
      "name": "Rock_Stone"
    },
    {
      "x": -3,
      "y": 10,
      "z": 0,
      "name": "Rock_Stone"
    },
    {
      "x": -3,
      "y": 11,
      "z": 0,
      "name": "Rock_Stone"
    },
    {
      "x": -3,
      "y": 12,
      "z": 0,
      "name": "Rock_Stone"
    },
    {
      "x": -3,
      "y": 13,
      "z": 0,
      "name": "Rock_Stone"
    },
    {
      "x": -3,
      "y": 14,
      "z": 0,
      "name": "Rock_Stone"
    },
    {
      "x": -2,
      "y": 0,
      "z": -7,
      "name": "Rock_Stone_Cobble_Stairs",
      "rotation": 3
    },
    {
      "x": -2,
      "y": 1,
      "z": -7,
      "name": "Empty"
    },
    {
      "x": -2,
      "y": 2,
      "z": -7,
      "name": "Empty"
    },
    {
      "x": -2,
      "y": 3,
      "z": -7,
      "name": "Empty"
    },
    {
      "x": -2,
      "y": 4,
      "z": -7,
      "name": "Empty"
    },
    {
      "x": -2,
      "y": 5,
      "z": -7,
      "name": "Rock_Stone_Brick_Smooth"
    },
    {
      "x": -2,
      "y": 6,
      "z": -7,
      "name": "Rock_Stone_Brick_Smooth_Half"
    },
    {
      "x": -2,
      "y": 7,
      "z": -7,
      "name": "Empty"
    },
    {
      "x": -2,
      "y": 8,
      "z": -7,
      "name": "Empty"
    },
    {
      "x": -2,
      "y": 9,
      "z": -7,
      "name": "Empty"
    },
    {
      "x": -2,
      "y": 10,
      "z": -7,
      "name": "Empty"
    },
    {
      "x": -2,
      "y": 11,
      "z": -7,
      "name": "Rock_Stone"
    },
    {
      "x": -2,
      "y": 12,
      "z": -7,
      "name": "Rock_Stone"
    },
    {
      "x": -2,
      "y": 13,
      "z": -7,
      "name": "Rock_Stone"
    },
    {
      "x": -2,
      "y": 14,
      "z": -7,
      "name": "Rock_Stone"
    },
    {
      "x": -2,
      "y": 0,
      "z": -6,
      "name": "Rock_Stone_Cobble_Stairs",
      "rotation": 3
    },
    {
      "x": -2,
      "y": 1,
      "z": -6,
      "name": "Empty"
    },
    {
      "x": -2,
      "y": 2,
      "z": -6,
      "name": "Empty"
    },
    {
      "x": -2,
      "y": 3,
      "z": -6,
      "name": "Empty"
    },
    {
      "x": -2,
      "y": 4,
      "z": -6,
      "name": "Empty"
    },
    {
      "x": -2,
      "y": 5,
      "z": -6,
      "name": "Rock_Stone_Cobble"
    },
    {
      "x": -2,
      "y": 6,
      "z": -6,
      "name": "Rock_Stone"
    },
    {
      "x": -2,
      "y": 7,
      "z": -6,
      "name": "Empty"
    },
    {
      "x": -2,
      "y": 8,
      "z": -6,
      "name": "Empty"
    },
    {
      "x": -2,
      "y": 9,
      "z": -6,
      "name": "Empty"
    },
    {
      "x": -2,
      "y": 10,
      "z": -6,
      "name": "Rock_Stone"
    },
    {
      "x": -2,
      "y": 11,
      "z": -6,
      "name": "Rock_Stone"
    },
    {
      "x": -2,
      "y": 12,
      "z": -6,
      "name": "Rock_Stone"
    },
    {
      "x": -2,
      "y": 13,
      "z": -6,
      "name": "Rock_Stone"
    },
    {
      "x": -2,
      "y": 14,
      "z": -6,
      "name": "Rock_Stone"
    },
    {
      "x": -2,
      "y": 0,
      "z": -5,
      "name": "Rock_Stone_Cobble"
    },
    {
      "x": -2,
      "y": 1,
      "z": -5,
      "name": "Empty"
    },
    {
      "x": -2,
      "y": 2,
      "z": -5,
      "name": "Empty"
    },
    {
      "x": -2,
      "y": 3,
      "z": -5,
      "name": "Empty"
    },
    {
      "x": -2,
      "y": 4,
      "z": -5,
      "name": "Empty"
    },
    {
      "x": -2,
      "y": 5,
      "z": -5,
      "name": "Rock_Stone_Cobble"
    },
    {
      "x": -2,
      "y": 6,
      "z": -5,
      "name": "Rock_Stone"
    },
    {
      "x": -2,
      "y": 7,
      "z": -5,
      "name": "Rock_Stone"
    },
    {
      "x": -2,
      "y": 8,
      "z": -5,
      "name": "Empty"
    },
    {
      "x": -2,
      "y": 9,
      "z": -5,
      "name": "Rock_Stone"
    },
    {
      "x": -2,
      "y": 10,
      "z": -5,
      "name": "Rock_Stone"
    },
    {
      "x": -2,
      "y": 11,
      "z": -5,
      "name": "Rock_Stone"
    },
    {
      "x": -2,
      "y": 12,
      "z": -5,
      "name": "Rock_Stone"
    },
    {
      "x": -2,
      "y": 13,
      "z": -5,
      "name": "Rock_Stone"
    },
    {
      "x": -2,
      "y": 14,
      "z": -5,
      "name": "Rock_Stone"
    },
    {
      "x": -2,
      "y": 0,
      "z": -4,
      "name": "Rock_Stone_Cobble"
    },
    {
      "x": -2,
      "y": 1,
      "z": -4,
      "name": "Rock_Stone_Brick_Pillar_Base"
    },
    {
      "x": -2,
      "y": 2,
      "z": -4,
      "name": "Furniture_Village_Statue",
      "rotation": 1
    },
    {
      "x": -2,
      "y": 3,
      "z": -4,
      "name": "Furniture_Village_Statue",
      "filler": 1024,
      "rotation": 1
    },
    {
      "x": -2,
      "y": 4,
      "z": -4,
      "name": "Furniture_Village_Statue",
      "filler": 2048,
      "rotation": 1
    },
    {
      "x": -2,
      "y": 5,
      "z": -4,
      "name": "Rock_Stone_Cobble"
    },
    {
      "x": -2,
      "y": 6,
      "z": -4,
      "name": "Rock_Stone"
    },
    {
      "x": -2,
      "y": 7,
      "z": -4,
      "name": "Rock_Stone"
    },
    {
      "x": -2,
      "y": 8,
      "z": -4,
      "name": "Rock_Stone"
    },
    {
      "x": -2,
      "y": 9,
      "z": -4,
      "name": "Rock_Stone"
    },
    {
      "x": -2,
      "y": 10,
      "z": -4,
      "name": "Rock_Stone"
    },
    {
      "x": -2,
      "y": 11,
      "z": -4,
      "name": "Rock_Stone"
    },
    {
      "x": -2,
      "y": 12,
      "z": -4,
      "name": "Rock_Stone"
    },
    {
      "x": -2,
      "y": 13,
      "z": -4,
      "name": "Rock_Stone"
    },
    {
      "x": -2,
      "y": 14,
      "z": -4,
      "name": "Rock_Stone"
    },
    {
      "x": -2,
      "y": 0,
      "z": -3,
      "name": "Plant_Moss_Block_Blue"
    },
    {
      "x": -2,
      "y": 1,
      "z": -3,
      "name": "Furniture_Human_Ruins_Pot_Small"
    },
    {
      "x": -2,
      "y": 2,
      "z": -3,
      "name": "Empty"
    },
    {
      "x": -2,
      "y": 3,
      "z": -3,
      "name": "Empty"
    },
    {
      "x": -2,
      "y": 4,
      "z": -3,
      "name": "Empty"
    },
    {
      "x": -2,
      "y": 5,
      "z": -3,
      "name": "Rock_Stone_Cobble"
    },
    {
      "x": -2,
      "y": 6,
      "z": -3,
      "name": "Rock_Stone"
    },
    {
      "x": -2,
      "y": 7,
      "z": -3,
      "name": "Rock_Stone"
    },
    {
      "x": -2,
      "y": 8,
      "z": -3,
      "name": "Rock_Stone"
    },
    {
      "x": -2,
      "y": 9,
      "z": -3,
      "name": "Rock_Stone"
    },
    {
      "x": -2,
      "y": 10,
      "z": -3,
      "name": "Rock_Stone"
    },
    {
      "x": -2,
      "y": 11,
      "z": -3,
      "name": "Rock_Stone"
    },
    {
      "x": -2,
      "y": 12,
      "z": -3,
      "name": "Rock_Stone"
    },
    {
      "x": -2,
      "y": 13,
      "z": -3,
      "name": "Rock_Stone"
    },
    {
      "x": -2,
      "y": 14,
      "z": -3,
      "name": "Rock_Stone"
    },
    {
      "x": -2,
      "y": 0,
      "z": -2,
      "name": "Rock_Stone_Cobble_Stairs",
      "rotation": 3
    },
    {
      "x": -2,
      "y": 1,
      "z": -2,
      "name": "Empty"
    },
    {
      "x": -2,
      "y": 2,
      "z": -2,
      "name": "Empty"
    },
    {
      "x": -2,
      "y": 3,
      "z": -2,
      "name": "Empty"
    },
    {
      "x": -2,
      "y": 4,
      "z": -2,
      "name": "Empty"
    },
    {
      "x": -2,
      "y": 5,
      "z": -2,
      "name": "Rock_Stone_Cobble"
    },
    {
      "x": -2,
      "y": 6,
      "z": -2,
      "name": "Rock_Stone"
    },
    {
      "x": -2,
      "y": 7,
      "z": -2,
      "name": "Rock_Stone"
    },
    {
      "x": -2,
      "y": 8,
      "z": -2,
      "name": "Rock_Stone"
    },
    {
      "x": -2,
      "y": 9,
      "z": -2,
      "name": "Rock_Stone"
    },
    {
      "x": -2,
      "y": 10,
      "z": -2,
      "name": "Rock_Stone"
    },
    {
      "x": -2,
      "y": 11,
      "z": -2,
      "name": "Rock_Stone"
    },
    {
      "x": -2,
      "y": 12,
      "z": -2,
      "name": "Rock_Stone"
    },
    {
      "x": -2,
      "y": 13,
      "z": -2,
      "name": "Rock_Stone"
    },
    {
      "x": -2,
      "y": 14,
      "z": -2,
      "name": "Rock_Stone"
    },
    {
      "x": -2,
      "y": 0,
      "z": -1,
      "name": "Rock_Stone_Cobble_Stairs",
      "rotation": 3
    },
    {
      "x": -2,
      "y": 1,
      "z": -1,
      "name": "Empty"
    },
    {
      "x": -2,
      "y": 2,
      "z": -1,
      "name": "Empty"
    },
    {
      "x": -2,
      "y": 3,
      "z": -1,
      "name": "Empty"
    },
    {
      "x": -2,
      "y": 4,
      "z": -1,
      "name": "Empty"
    },
    {
      "x": -2,
      "y": 5,
      "z": -1,
      "name": "Rock_Stone_Brick_Smooth"
    },
    {
      "x": -2,
      "y": 6,
      "z": -1,
      "name": "Rock_Stone"
    },
    {
      "x": -2,
      "y": 7,
      "z": -1,
      "name": "Rock_Stone"
    },
    {
      "x": -2,
      "y": 8,
      "z": -1,
      "name": "Rock_Stone"
    },
    {
      "x": -2,
      "y": 9,
      "z": -1,
      "name": "Rock_Stone"
    },
    {
      "x": -2,
      "y": 10,
      "z": -1,
      "name": "Rock_Stone"
    },
    {
      "x": -2,
      "y": 11,
      "z": -1,
      "name": "Rock_Stone"
    },
    {
      "x": -2,
      "y": 12,
      "z": -1,
      "name": "Rock_Stone"
    },
    {
      "x": -2,
      "y": 13,
      "z": -1,
      "name": "Rock_Stone"
    },
    {
      "x": -2,
      "y": 14,
      "z": -1,
      "name": "Rock_Stone"
    },
    {
      "x": -2,
      "y": 0,
      "z": 0,
      "name": "Rock_Stone_Cobble_Stairs",
      "rotation": 3
    },
    {
      "x": -2,
      "y": 1,
      "z": 0,
      "name": "Empty"
    },
    {
      "x": -2,
      "y": 2,
      "z": 0,
      "name": "Empty"
    },
    {
      "x": -2,
      "y": 3,
      "z": 0,
      "name": "Empty"
    },
    {
      "x": -2,
      "y": 4,
      "z": 0,
      "name": "Empty"
    },
    {
      "x": -2,
      "y": 5,
      "z": 0,
      "name": "Rock_Stone_Brick_Smooth"
    },
    {
      "x": -2,
      "y": 6,
      "z": 0,
      "name": "Rock_Stone_Brick_Smooth_Half"
    },
    {
      "x": -2,
      "y": 7,
      "z": 0,
      "name": "Empty"
    },
    {
      "x": -2,
      "y": 8,
      "z": 0,
      "name": "Empty"
    },
    {
      "x": -2,
      "y": 9,
      "z": 0,
      "name": "Rock_Stone"
    },
    {
      "x": -2,
      "y": 10,
      "z": 0,
      "name": "Rock_Stone"
    },
    {
      "x": -2,
      "y": 11,
      "z": 0,
      "name": "Rock_Stone"
    },
    {
      "x": -2,
      "y": 12,
      "z": 0,
      "name": "Rock_Stone"
    },
    {
      "x": -2,
      "y": 13,
      "z": 0,
      "name": "Rock_Stone"
    },
    {
      "x": -2,
      "y": 14,
      "z": 0,
      "name": "Rock_Stone"
    },
    {
      "x": -1,
      "y": 0,
      "z": -7,
      "name": "Rock_Stone_Cobble"
    },
    {
      "x": -1,
      "y": 1,
      "z": -7,
      "name": "Empty"
    },
    {
      "x": -1,
      "y": 2,
      "z": -7,
      "name": "Empty"
    },
    {
      "x": -1,
      "y": 3,
      "z": -7,
      "name": "Empty"
    },
    {
      "x": -1,
      "y": 4,
      "z": -7,
      "name": "Empty"
    },
    {
      "x": -1,
      "y": 5,
      "z": -7,
      "name": "Rock_Stone_Brick_Smooth_Half",
      "rotation": 8
    },
    {
      "x": -1,
      "y": 6,
      "z": -7,
      "name": "Rock_Stone_Brick_Smooth"
    },
    {
      "x": -1,
      "y": 7,
      "z": -7,
      "name": "Empty"
    },
    {
      "x": -1,
      "y": 8,
      "z": -7,
      "name": "Empty"
    },
    {
      "x": -1,
      "y": 9,
      "z": -7,
      "name": "Empty"
    },
    {
      "x": -1,
      "y": 10,
      "z": -7,
      "name": "Empty"
    },
    {
      "x": -1,
      "y": 11,
      "z": -7,
      "name": "Rock_Stone_Stalactite_Large",
      "filler": 31744,
      "rotation": 8
    },
    {
      "x": -1,
      "y": 12,
      "z": -7,
      "name": "Rock_Stone_Stalactite_Large",
      "rotation": 8
    },
    {
      "x": -1,
      "y": 13,
      "z": -7,
      "name": "Rock_Stone"
    },
    {
      "x": -1,
      "y": 14,
      "z": -7,
      "name": "Rock_Stone"
    },
    {
      "x": -1,
      "y": 0,
      "z": -6,
      "name": "Rock_Stone_Cobble"
    },
    {
      "x": -1,
      "y": 1,
      "z": -6,
      "name": "Empty"
    },
    {
      "x": -1,
      "y": 2,
      "z": -6,
      "name": "Empty"
    },
    {
      "x": -1,
      "y": 3,
      "z": -6,
      "name": "Empty"
    },
    {
      "x": -1,
      "y": 4,
      "z": -6,
      "name": "Empty"
    },
    {
      "x": -1,
      "y": 5,
      "z": -6,
      "name": "Rock_Stone_Cobble_Half",
      "rotation": 8
    },
    {
      "x": -1,
      "y": 6,
      "z": -6,
      "name": "Rock_Stone"
    },
    {
      "x": -1,
      "y": 7,
      "z": -6,
      "name": "Empty"
    },
    {
      "x": -1,
      "y": 8,
      "z": -6,
      "name": "Empty"
    },
    {
      "x": -1,
      "y": 9,
      "z": -6,
      "name": "Empty"
    },
    {
      "x": -1,
      "y": 10,
      "z": -6,
      "name": "Empty"
    },
    {
      "x": -1,
      "y": 11,
      "z": -6,
      "name": "Rock_Stone"
    },
    {
      "x": -1,
      "y": 12,
      "z": -6,
      "name": "Rock_Stone"
    },
    {
      "x": -1,
      "y": 13,
      "z": -6,
      "name": "Rock_Stone"
    },
    {
      "x": -1,
      "y": 14,
      "z": -6,
      "name": "Rock_Stone"
    },
    {
      "x": -1,
      "y": 0,
      "z": -5,
      "name": "Rock_Stone_Brick"
    },
    {
      "x": -1,
      "y": 1,
      "z": -5,
      "name": "Empty"
    },
    {
      "x": -1,
      "y": 2,
      "z": -5,
      "name": "Empty"
    },
    {
      "x": -1,
      "y": 3,
      "z": -5,
      "name": "Empty"
    },
    {
      "x": -1,
      "y": 4,
      "z": -5,
      "name": "Empty"
    },
    {
      "x": -1,
      "y": 5,
      "z": -5,
      "name": "Rock_Stone_Cobble_Half",
      "rotation": 8
    },
    {
      "x": -1,
      "y": 6,
      "z": -5,
      "name": "Rock_Stone_Cobble"
    },
    {
      "x": -1,
      "y": 7,
      "z": -5,
      "name": "Soil_Gravel_Half"
    },
    {
      "x": -1,
      "y": 8,
      "z": -5,
      "name": "Empty"
    },
    {
      "x": -1,
      "y": 9,
      "z": -5,
      "name": "Plant_Flower_Orchid_Blue",
      "rotation": 8
    },
    {
      "x": -1,
      "y": 10,
      "z": -5,
      "name": "Rock_Stone"
    },
    {
      "x": -1,
      "y": 11,
      "z": -5,
      "name": "Rock_Stone"
    },
    {
      "x": -1,
      "y": 12,
      "z": -5,
      "name": "Rock_Stone"
    },
    {
      "x": -1,
      "y": 13,
      "z": -5,
      "name": "Rock_Stone"
    },
    {
      "x": -1,
      "y": 14,
      "z": -5,
      "name": "Rock_Stone"
    },
    {
      "x": -1,
      "y": 0,
      "z": -4,
      "name": "Rock_Stone_Brick"
    },
    {
      "x": -1,
      "y": 1,
      "z": -4,
      "name": "Empty"
    },
    {
      "x": -1,
      "y": 2,
      "z": -4,
      "name": "Empty"
    },
    {
      "x": -1,
      "y": 3,
      "z": -4,
      "name": "Empty"
    },
    {
      "x": -1,
      "y": 4,
      "z": -4,
      "name": "Empty"
    },
    {
      "x": -1,
      "y": 5,
      "z": -4,
      "name": "Rock_Stone_Cobble_Half",
      "rotation": 8
    },
    {
      "x": -1,
      "y": 6,
      "z": -4,
      "name": "Rock_Stone_Cobble"
    },
    {
      "x": -1,
      "y": 7,
      "z": -4,
      "name": "Soil_Gravel"
    },
    {
      "x": -1,
      "y": 8,
      "z": -4,
      "name": "Empty"
    },
    {
      "x": -1,
      "y": 9,
      "z": -4,
      "name": "Empty"
    },
    {
      "x": -1,
      "y": 10,
      "z": -4,
      "name": "Rock_Stone"
    },
    {
      "x": -1,
      "y": 11,
      "z": -4,
      "name": "Rock_Stone"
    },
    {
      "x": -1,
      "y": 12,
      "z": -4,
      "name": "Rock_Stone"
    },
    {
      "x": -1,
      "y": 13,
      "z": -4,
      "name": "Rock_Stone"
    },
    {
      "x": -1,
      "y": 14,
      "z": -4,
      "name": "Rock_Stone"
    },
    {
      "x": -1,
      "y": 0,
      "z": -3,
      "name": "Rock_Stone_Cobble"
    },
    {
      "x": -1,
      "y": 1,
      "z": -3,
      "name": "Empty"
    },
    {
      "x": -1,
      "y": 2,
      "z": -3,
      "name": "Empty"
    },
    {
      "x": -1,
      "y": 3,
      "z": -3,
      "name": "Empty"
    },
    {
      "x": -1,
      "y": 4,
      "z": -3,
      "name": "Empty"
    },
    {
      "x": -1,
      "y": 5,
      "z": -3,
      "name": "Rock_Stone_Cobble_Half",
      "rotation": 8
    },
    {
      "x": -1,
      "y": 6,
      "z": -3,
      "name": "Rock_Stone_Cobble"
    },
    {
      "x": -1,
      "y": 7,
      "z": -3,
      "name": "Soil_Gravel"
    },
    {
      "x": -1,
      "y": 8,
      "z": -3,
      "name": "Empty"
    },
    {
      "x": -1,
      "y": 9,
      "z": -3,
      "name": "Empty"
    },
    {
      "x": -1,
      "y": 10,
      "z": -3,
      "name": "Rock_Stone"
    },
    {
      "x": -1,
      "y": 11,
      "z": -3,
      "name": "Rock_Stone"
    },
    {
      "x": -1,
      "y": 12,
      "z": -3,
      "name": "Rock_Stone"
    },
    {
      "x": -1,
      "y": 13,
      "z": -3,
      "name": "Rock_Stone"
    },
    {
      "x": -1,
      "y": 14,
      "z": -3,
      "name": "Rock_Stone"
    },
    {
      "x": -1,
      "y": 0,
      "z": -2,
      "name": "Rock_Stone_Brick"
    },
    {
      "x": -1,
      "y": 1,
      "z": -2,
      "name": "Empty"
    },
    {
      "x": -1,
      "y": 2,
      "z": -2,
      "name": "Empty"
    },
    {
      "x": -1,
      "y": 3,
      "z": -2,
      "name": "Empty"
    },
    {
      "x": -1,
      "y": 4,
      "z": -2,
      "name": "Empty"
    },
    {
      "x": -1,
      "y": 5,
      "z": -2,
      "name": "Rock_Stone_Cobble_Half",
      "rotation": 8
    },
    {
      "x": -1,
      "y": 6,
      "z": -2,
      "name": "Rock_Stone"
    },
    {
      "x": -1,
      "y": 7,
      "z": -2,
      "name": "Soil_Gravel_Half"
    },
    {
      "x": -1,
      "y": 8,
      "z": -2,
      "name": "Empty"
    },
    {
      "x": -1,
      "y": 9,
      "z": -2,
      "name": "Empty"
    },
    {
      "x": -1,
      "y": 10,
      "z": -2,
      "name": "Rock_Stone"
    },
    {
      "x": -1,
      "y": 11,
      "z": -2,
      "name": "Rock_Stone"
    },
    {
      "x": -1,
      "y": 12,
      "z": -2,
      "name": "Rock_Stone"
    },
    {
      "x": -1,
      "y": 13,
      "z": -2,
      "name": "Rock_Stone"
    },
    {
      "x": -1,
      "y": 14,
      "z": -2,
      "name": "Rock_Stone"
    },
    {
      "x": -1,
      "y": 0,
      "z": -1,
      "name": "Rock_Stone_Cobble"
    },
    {
      "x": -1,
      "y": 1,
      "z": -1,
      "name": "Empty"
    },
    {
      "x": -1,
      "y": 2,
      "z": -1,
      "name": "Empty"
    },
    {
      "x": -1,
      "y": 3,
      "z": -1,
      "name": "Empty"
    },
    {
      "x": -1,
      "y": 4,
      "z": -1,
      "name": "Empty"
    },
    {
      "x": -1,
      "y": 5,
      "z": -1,
      "name": "Rock_Stone_Brick_Smooth_Half",
      "rotation": 8
    },
    {
      "x": -1,
      "y": 6,
      "z": -1,
      "name": "Rock_Stone"
    },
    {
      "x": -1,
      "y": 7,
      "z": -1,
      "name": "Soil_Gravel_Half"
    },
    {
      "x": -1,
      "y": 8,
      "z": -1,
      "name": "Empty"
    },
    {
      "x": -1,
      "y": 9,
      "z": -1,
      "name": "Empty"
    },
    {
      "x": -1,
      "y": 10,
      "z": -1,
      "name": "Rock_Stone"
    },
    {
      "x": -1,
      "y": 11,
      "z": -1,
      "name": "Rock_Stone"
    },
    {
      "x": -1,
      "y": 12,
      "z": -1,
      "name": "Rock_Stone"
    },
    {
      "x": -1,
      "y": 13,
      "z": -1,
      "name": "Rock_Stone"
    },
    {
      "x": -1,
      "y": 14,
      "z": -1,
      "name": "Rock_Stone"
    },
    {
      "x": -1,
      "y": 0,
      "z": 0,
      "name": "Rock_Stone_Cobble"
    },
    {
      "x": -1,
      "y": 1,
      "z": 0,
      "name": "Empty"
    },
    {
      "x": -1,
      "y": 2,
      "z": 0,
      "name": "Empty"
    },
    {
      "x": -1,
      "y": 3,
      "z": 0,
      "name": "Empty"
    },
    {
      "x": -1,
      "y": 4,
      "z": 0,
      "name": "Empty"
    },
    {
      "x": -1,
      "y": 5,
      "z": 0,
      "name": "Rock_Stone_Brick_Smooth_Half",
      "rotation": 8
    },
    {
      "x": -1,
      "y": 6,
      "z": 0,
      "name": "Rock_Stone_Brick_Smooth"
    },
    {
      "x": -1,
      "y": 7,
      "z": 0,
      "name": "Soil_Gravel_Half"
    },
    {
      "x": -1,
      "y": 8,
      "z": 0,
      "name": "Empty"
    },
    {
      "x": -1,
      "y": 9,
      "z": 0,
      "name": "Empty"
    },
    {
      "x": -1,
      "y": 10,
      "z": 0,
      "name": "Empty"
    },
    {
      "x": -1,
      "y": 11,
      "z": 0,
      "name": "Empty"
    },
    {
      "x": -1,
      "y": 12,
      "z": 0,
      "name": "Rock_Stone"
    },
    {
      "x": -1,
      "y": 13,
      "z": 0,
      "name": "Rock_Stone"
    },
    {
      "x": -1,
      "y": 14,
      "z": 0,
      "name": "Rock_Stone"
    },
    {
      "x": 0,
      "y": 0,
      "z": -7,
      "name": "Rock_Stone_Cobble"
    },
    {
      "x": 0,
      "y": 1,
      "z": -7,
      "name": "Empty"
    },
    {
      "x": 0,
      "y": 2,
      "z": -7,
      "name": "Empty"
    },
    {
      "x": 0,
      "y": 3,
      "z": -7,
      "name": "Empty"
    },
    {
      "x": 0,
      "y": 4,
      "z": -7,
      "name": "Empty"
    },
    {
      "x": 0,
      "y": 5,
      "z": -7,
      "name": "Empty"
    },
    {
      "x": 0,
      "y": 6,
      "z": -7,
      "name": "Rock_Stone_Brick_Smooth"
    },
    {
      "x": 0,
      "y": 7,
      "z": -7,
      "name": "Empty"
    },
    {
      "x": 0,
      "y": 8,
      "z": -7,
      "name": "Empty"
    },
    {
      "x": 0,
      "y": 9,
      "z": -7,
      "name": "Empty"
    },
    {
      "x": 0,
      "y": 10,
      "z": -7,
      "name": "Empty"
    },
    {
      "x": 0,
      "y": 11,
      "z": -7,
      "name": "Empty"
    },
    {
      "x": 0,
      "y": 12,
      "z": -7,
      "name": "Empty"
    },
    {
      "x": 0,
      "y": 13,
      "z": -7,
      "name": "Empty"
    },
    {
      "x": 0,
      "y": 14,
      "z": -7,
      "name": "Rock_Stone"
    },
    {
      "x": 0,
      "y": 0,
      "z": -6,
      "name": "Rock_Stone_Brick"
    },
    {
      "x": 0,
      "y": 1,
      "z": -6,
      "name": "Empty"
    },
    {
      "x": 0,
      "y": 2,
      "z": -6,
      "name": "Empty"
    },
    {
      "x": 0,
      "y": 3,
      "z": -6,
      "name": "Empty"
    },
    {
      "x": 0,
      "y": 4,
      "z": -6,
      "name": "Empty"
    },
    {
      "x": 0,
      "y": 5,
      "z": -6,
      "name": "Empty"
    },
    {
      "x": 0,
      "y": 6,
      "z": -6,
      "name": "Rock_Stone_Cobble"
    },
    {
      "x": 0,
      "y": 7,
      "z": -6,
      "name": "Soil_Gravel_Half"
    },
    {
      "x": 0,
      "y": 8,
      "z": -6,
      "name": "Empty"
    },
    {
      "x": 0,
      "y": 9,
      "z": -6,
      "name": "Empty"
    },
    {
      "x": 0,
      "y": 10,
      "z": -6,
      "name": "Empty"
    },
    {
      "x": 0,
      "y": 11,
      "z": -6,
      "name": "Empty"
    },
    {
      "x": 0,
      "y": 12,
      "z": -6,
      "name": "Rock_Stone"
    },
    {
      "x": 0,
      "y": 13,
      "z": -6,
      "name": "Rock_Stone"
    },
    {
      "x": 0,
      "y": 14,
      "z": -6,
      "name": "Rock_Stone"
    },
    {
      "x": 0,
      "y": 0,
      "z": -5,
      "name": "Rock_Stone_Cobble"
    },
    {
      "x": 0,
      "y": 1,
      "z": -5,
      "name": "Empty"
    },
    {
      "x": 0,
      "y": 2,
      "z": -5,
      "name": "Empty"
    },
    {
      "x": 0,
      "y": 3,
      "z": -5,
      "name": "Empty"
    },
    {
      "x": 0,
      "y": 4,
      "z": -5,
      "name": "Empty"
    },
    {
      "x": 0,
      "y": 5,
      "z": -5,
      "name": "Empty"
    },
    {
      "x": 0,
      "y": 6,
      "z": -5,
      "name": "Rock_Stone_Cobble"
    },
    {
      "x": 0,
      "y": 7,
      "z": -5,
      "name": "Soil_Gravel_Half"
    },
    {
      "x": 0,
      "y": 8,
      "z": -5,
      "name": "Empty"
    },
    {
      "x": 0,
      "y": 9,
      "z": -5,
      "name": "Empty"
    },
    {
      "x": 0,
      "y": 10,
      "z": -5,
      "name": "Empty"
    },
    {
      "x": 0,
      "y": 11,
      "z": -5,
      "name": "Rock_Stone"
    },
    {
      "x": 0,
      "y": 12,
      "z": -5,
      "name": "Rock_Stone"
    },
    {
      "x": 0,
      "y": 13,
      "z": -5,
      "name": "Rock_Stone"
    },
    {
      "x": 0,
      "y": 14,
      "z": -5,
      "name": "Rock_Stone"
    },
    {
      "x": 0,
      "y": 0,
      "z": -4,
      "name": "Rock_Stone_Brick"
    },
    {
      "x": 0,
      "y": 1,
      "z": -4,
      "name": "Empty"
    },
    {
      "x": 0,
      "y": 2,
      "z": -4,
      "name": "Empty"
    },
    {
      "x": 0,
      "y": 3,
      "z": -4,
      "name": "Empty"
    },
    {
      "x": 0,
      "y": 4,
      "z": -4,
      "name": "*Furniture_Human_Ruins_Lantern_State_Definitions_Blue"
    },
    {
      "x": 0,
      "y": 5,
      "z": -4,
      "name": "Deco_Iron_Chain_Small"
    },
    {
      "x": 0,
      "y": 6,
      "z": -4,
      "name": "Rock_Stone_Cobble"
    },
    {
      "x": 0,
      "y": 7,
      "z": -4,
      "name": "Soil_Gravel"
    },
    {
      "x": 0,
      "y": 8,
      "z": -4,
      "name": "Empty"
    },
    {
      "x": 0,
      "y": 9,
      "z": -4,
      "name": "Empty"
    },
    {
      "x": 0,
      "y": 10,
      "z": -4,
      "name": "Empty"
    },
    {
      "x": 0,
      "y": 11,
      "z": -4,
      "name": "Rock_Stone"
    },
    {
      "x": 0,
      "y": 12,
      "z": -4,
      "name": "Rock_Stone"
    },
    {
      "x": 0,
      "y": 13,
      "z": -4,
      "name": "Rock_Stone"
    },
    {
      "x": 0,
      "y": 14,
      "z": -4,
      "name": "Rock_Stone"
    },
    {
      "x": 0,
      "y": 0,
      "z": -3,
      "name": "Rock_Stone_Brick"
    },
    {
      "x": 0,
      "y": 1,
      "z": -3,
      "name": "Empty"
    },
    {
      "x": 0,
      "y": 2,
      "z": -3,
      "name": "Empty"
    },
    {
      "x": 0,
      "y": 3,
      "z": -3,
      "name": "Empty"
    },
    {
      "x": 0,
      "y": 4,
      "z": -3,
      "name": "Empty"
    },
    {
      "x": 0,
      "y": 5,
      "z": -3,
      "name": "Empty"
    },
    {
      "x": 0,
      "y": 6,
      "z": -3,
      "name": "Rock_Stone_Cobble"
    },
    {
      "x": 0,
      "y": 7,
      "z": -3,
      "name": "Soil_Gravel"
    },
    {
      "x": 0,
      "y": 8,
      "z": -3,
      "name": "Empty"
    },
    {
      "x": 0,
      "y": 9,
      "z": -3,
      "name": "Empty"
    },
    {
      "x": 0,
      "y": 10,
      "z": -3,
      "name": "Rock_Stone"
    },
    {
      "x": 0,
      "y": 11,
      "z": -3,
      "name": "Rock_Stone"
    },
    {
      "x": 0,
      "y": 12,
      "z": -3,
      "name": "Rock_Stone"
    },
    {
      "x": 0,
      "y": 13,
      "z": -3,
      "name": "Rock_Stone"
    },
    {
      "x": 0,
      "y": 14,
      "z": -3,
      "name": "Rock_Stone"
    },
    {
      "x": 0,
      "y": 0,
      "z": -2,
      "name": "Rock_Stone_Brick"
    },
    {
      "x": 0,
      "y": 1,
      "z": -2,
      "name": "Empty"
    },
    {
      "x": 0,
      "y": 2,
      "z": -2,
      "name": "Empty"
    },
    {
      "x": 0,
      "y": 3,
      "z": -2,
      "name": "Empty"
    },
    {
      "x": 0,
      "y": 4,
      "z": -2,
      "name": "Empty"
    },
    {
      "x": 0,
      "y": 5,
      "z": -2,
      "name": "Empty"
    },
    {
      "x": 0,
      "y": 6,
      "z": -2,
      "name": "Rock_Stone_Cobble"
    },
    {
      "x": 0,
      "y": 7,
      "z": -2,
      "name": "Soil_Gravel"
    },
    {
      "x": 0,
      "y": 8,
      "z": -2,
      "name": "Empty"
    },
    {
      "x": 0,
      "y": 9,
      "z": -2,
      "name": "Empty"
    },
    {
      "x": 0,
      "y": 10,
      "z": -2,
      "name": "Rock_Stone"
    },
    {
      "x": 0,
      "y": 11,
      "z": -2,
      "name": "Rock_Stone"
    },
    {
      "x": 0,
      "y": 12,
      "z": -2,
      "name": "Rock_Stone"
    },
    {
      "x": 0,
      "y": 13,
      "z": -2,
      "name": "Rock_Stone"
    },
    {
      "x": 0,
      "y": 14,
      "z": -2,
      "name": "Rock_Stone"
    },
    {
      "x": 0,
      "y": 0,
      "z": -1,
      "name": "Rock_Stone_Brick"
    },
    {
      "x": 0,
      "y": 1,
      "z": -1,
      "name": "Empty"
    },
    {
      "x": 0,
      "y": 2,
      "z": -1,
      "name": "Empty"
    },
    {
      "x": 0,
      "y": 3,
      "z": -1,
      "name": "Empty"
    },
    {
      "x": 0,
      "y": 4,
      "z": -1,
      "name": "Empty"
    },
    {
      "x": 0,
      "y": 5,
      "z": -1,
      "name": "Empty"
    },
    {
      "x": 0,
      "y": 6,
      "z": -1,
      "name": "Rock_Stone_Cobble"
    },
    {
      "x": 0,
      "y": 7,
      "z": -1,
      "name": "Soil_Gravel_Half"
    },
    {
      "x": 0,
      "y": 8,
      "z": -1,
      "name": "Empty"
    },
    {
      "x": 0,
      "y": 9,
      "z": -1,
      "name": "Empty"
    },
    {
      "x": 0,
      "y": 10,
      "z": -1,
      "name": "Empty"
    },
    {
      "x": 0,
      "y": 11,
      "z": -1,
      "name": "Rock_Stone"
    },
    {
      "x": 0,
      "y": 12,
      "z": -1,
      "name": "Rock_Stone"
    },
    {
      "x": 0,
      "y": 13,
      "z": -1,
      "name": "Rock_Stone"
    },
    {
      "x": 0,
      "y": 14,
      "z": -1,
      "name": "Rock_Stone"
    },
    {
      "x": 0,
      "y": 0,
      "z": 0,
      "name": "Rock_Stone_Brick"
    },
    {
      "x": 0,
      "y": 1,
      "z": 0,
      "name": "Empty"
    },
    {
      "x": 0,
      "y": 2,
      "z": 0,
      "name": "Empty"
    },
    {
      "x": 0,
      "y": 3,
      "z": 0,
      "name": "Empty"
    },
    {
      "x": 0,
      "y": 4,
      "z": 0,
      "name": "Empty"
    },
    {
      "x": 0,
      "y": 5,
      "z": 0,
      "name": "Empty"
    },
    {
      "x": 0,
      "y": 6,
      "z": 0,
      "name": "Rock_Stone_Brick_Ornate"
    },
    {
      "x": 0,
      "y": 7,
      "z": 0,
      "name": "Soil_Gravel_Half"
    },
    {
      "x": 0,
      "y": 8,
      "z": 0,
      "name": "Empty"
    },
    {
      "x": 0,
      "y": 9,
      "z": 0,
      "name": "Empty"
    },
    {
      "x": 0,
      "y": 10,
      "z": 0,
      "name": "Empty"
    },
    {
      "x": 0,
      "y": 11,
      "z": 0,
      "name": "Empty"
    },
    {
      "x": 0,
      "y": 12,
      "z": 0,
      "name": "Empty"
    },
    {
      "x": 0,
      "y": 13,
      "z": 0,
      "name": "Rock_Stone"
    },
    {
      "x": 0,
      "y": 14,
      "z": 0,
      "name": "Rock_Stone"
    },
    {
      "x": 1,
      "y": 0,
      "z": -7,
      "name": "Rock_Stone_Cobble"
    },
    {
      "x": 1,
      "y": 1,
      "z": -7,
      "name": "Empty"
    },
    {
      "x": 1,
      "y": 2,
      "z": -7,
      "name": "Empty"
    },
    {
      "x": 1,
      "y": 3,
      "z": -7,
      "name": "Empty"
    },
    {
      "x": 1,
      "y": 4,
      "z": -7,
      "name": "Empty"
    },
    {
      "x": 1,
      "y": 5,
      "z": -7,
      "name": "Rock_Stone_Brick_Smooth_Half",
      "rotation": 8
    },
    {
      "x": 1,
      "y": 6,
      "z": -7,
      "name": "Rock_Stone_Brick_Smooth"
    },
    {
      "x": 1,
      "y": 7,
      "z": -7,
      "name": "Empty"
    },
    {
      "x": 1,
      "y": 8,
      "z": -7,
      "name": "Empty"
    },
    {
      "x": 1,
      "y": 9,
      "z": -7,
      "name": "Empty"
    },
    {
      "x": 1,
      "y": 10,
      "z": -7,
      "name": "Empty"
    },
    {
      "x": 1,
      "y": 11,
      "z": -7,
      "name": "Rock_Stone_Stalactite_Large",
      "filler": 31744,
      "rotation": 8
    },
    {
      "x": 1,
      "y": 12,
      "z": -7,
      "name": "Rock_Stone_Stalactite_Large",
      "rotation": 8
    },
    {
      "x": 1,
      "y": 13,
      "z": -7,
      "name": "Rock_Stone"
    },
    {
      "x": 1,
      "y": 14,
      "z": -7,
      "name": "Rock_Stone"
    },
    {
      "x": 1,
      "y": 0,
      "z": -6,
      "name": "Rock_Stone_Brick"
    },
    {
      "x": 1,
      "y": 1,
      "z": -6,
      "name": "Empty"
    },
    {
      "x": 1,
      "y": 2,
      "z": -6,
      "name": "Empty"
    },
    {
      "x": 1,
      "y": 3,
      "z": -6,
      "name": "Empty"
    },
    {
      "x": 1,
      "y": 4,
      "z": -6,
      "name": "Empty"
    },
    {
      "x": 1,
      "y": 5,
      "z": -6,
      "name": "Rock_Stone_Cobble_Half",
      "rotation": 8
    },
    {
      "x": 1,
      "y": 6,
      "z": -6,
      "name": "Rock_Stone_Cobble"
    },
    {
      "x": 1,
      "y": 7,
      "z": -6,
      "name": "Soil_Gravel_Half"
    },
    {
      "x": 1,
      "y": 8,
      "z": -6,
      "name": "Empty"
    },
    {
      "x": 1,
      "y": 9,
      "z": -6,
      "name": "Empty"
    },
    {
      "x": 1,
      "y": 10,
      "z": -6,
      "name": "Empty"
    },
    {
      "x": 1,
      "y": 11,
      "z": -6,
      "name": "Rock_Stone"
    },
    {
      "x": 1,
      "y": 12,
      "z": -6,
      "name": "Rock_Stone"
    },
    {
      "x": 1,
      "y": 13,
      "z": -6,
      "name": "Rock_Stone"
    },
    {
      "x": 1,
      "y": 14,
      "z": -6,
      "name": "Rock_Stone"
    },
    {
      "x": 1,
      "y": 0,
      "z": -5,
      "name": "Rock_Stone_Cobble"
    },
    {
      "x": 1,
      "y": 1,
      "z": -5,
      "name": "Empty"
    },
    {
      "x": 1,
      "y": 2,
      "z": -5,
      "name": "Empty"
    },
    {
      "x": 1,
      "y": 3,
      "z": -5,
      "name": "Empty"
    },
    {
      "x": 1,
      "y": 4,
      "z": -5,
      "name": "Empty"
    },
    {
      "x": 1,
      "y": 5,
      "z": -5,
      "name": "Rock_Stone_Cobble_Half",
      "rotation": 8
    },
    {
      "x": 1,
      "y": 6,
      "z": -5,
      "name": "Rock_Stone_Cobble"
    },
    {
      "x": 1,
      "y": 7,
      "z": -5,
      "name": "Soil_Gravel_Half"
    },
    {
      "x": 1,
      "y": 8,
      "z": -5,
      "name": "Empty"
    },
    {
      "x": 1,
      "y": 9,
      "z": -5,
      "name": "Empty"
    },
    {
      "x": 1,
      "y": 10,
      "z": -5,
      "name": "Empty"
    },
    {
      "x": 1,
      "y": 11,
      "z": -5,
      "name": "Rock_Stone"
    },
    {
      "x": 1,
      "y": 12,
      "z": -5,
      "name": "Rock_Stone"
    },
    {
      "x": 1,
      "y": 13,
      "z": -5,
      "name": "Rock_Stone"
    },
    {
      "x": 1,
      "y": 14,
      "z": -5,
      "name": "Rock_Stone"
    },
    {
      "x": 1,
      "y": 0,
      "z": -4,
      "name": "Rock_Stone_Cobble"
    },
    {
      "x": 1,
      "y": 1,
      "z": -4,
      "name": "Empty"
    },
    {
      "x": 1,
      "y": 2,
      "z": -4,
      "name": "Empty"
    },
    {
      "x": 1,
      "y": 3,
      "z": -4,
      "name": "Empty"
    },
    {
      "x": 1,
      "y": 4,
      "z": -4,
      "name": "Empty"
    },
    {
      "x": 1,
      "y": 5,
      "z": -4,
      "name": "Rock_Stone_Cobble_Half",
      "rotation": 8
    },
    {
      "x": 1,
      "y": 6,
      "z": -4,
      "name": "Rock_Stone_Cobble"
    },
    {
      "x": 1,
      "y": 7,
      "z": -4,
      "name": "Soil_Gravel_Half"
    },
    {
      "x": 1,
      "y": 8,
      "z": -4,
      "name": "Empty"
    },
    {
      "x": 1,
      "y": 9,
      "z": -4,
      "name": "Empty"
    },
    {
      "x": 1,
      "y": 10,
      "z": -4,
      "name": "Rock_Stone"
    },
    {
      "x": 1,
      "y": 11,
      "z": -4,
      "name": "Rock_Stone"
    },
    {
      "x": 1,
      "y": 12,
      "z": -4,
      "name": "Rock_Stone"
    },
    {
      "x": 1,
      "y": 13,
      "z": -4,
      "name": "Rock_Stone"
    },
    {
      "x": 1,
      "y": 14,
      "z": -4,
      "name": "Rock_Stone"
    },
    {
      "x": 1,
      "y": 0,
      "z": -3,
      "name": "Rock_Stone_Brick"
    },
    {
      "x": 1,
      "y": 1,
      "z": -3,
      "name": "Empty"
    },
    {
      "x": 1,
      "y": 2,
      "z": -3,
      "name": "Empty"
    },
    {
      "x": 1,
      "y": 3,
      "z": -3,
      "name": "Empty"
    },
    {
      "x": 1,
      "y": 4,
      "z": -3,
      "name": "Empty"
    },
    {
      "x": 1,
      "y": 5,
      "z": -3,
      "name": "Rock_Stone_Cobble_Half",
      "rotation": 8
    },
    {
      "x": 1,
      "y": 6,
      "z": -3,
      "name": "Rock_Stone_Cobble"
    },
    {
      "x": 1,
      "y": 7,
      "z": -3,
      "name": "Soil_Gravel"
    },
    {
      "x": 1,
      "y": 8,
      "z": -3,
      "name": "Empty"
    },
    {
      "x": 1,
      "y": 9,
      "z": -3,
      "name": "Plant_Flower_Orchid_Blue",
      "rotation": 8
    },
    {
      "x": 1,
      "y": 10,
      "z": -3,
      "name": "Rock_Stone"
    },
    {
      "x": 1,
      "y": 11,
      "z": -3,
      "name": "Rock_Stone"
    },
    {
      "x": 1,
      "y": 12,
      "z": -3,
      "name": "Rock_Stone"
    },
    {
      "x": 1,
      "y": 13,
      "z": -3,
      "name": "Rock_Stone"
    },
    {
      "x": 1,
      "y": 14,
      "z": -3,
      "name": "Rock_Stone"
    },
    {
      "x": 1,
      "y": 0,
      "z": -2,
      "name": "Rock_Stone_Cobble"
    },
    {
      "x": 1,
      "y": 1,
      "z": -2,
      "name": "Empty"
    },
    {
      "x": 1,
      "y": 2,
      "z": -2,
      "name": "Empty"
    },
    {
      "x": 1,
      "y": 3,
      "z": -2,
      "name": "Empty"
    },
    {
      "x": 1,
      "y": 4,
      "z": -2,
      "name": "Empty"
    },
    {
      "x": 1,
      "y": 5,
      "z": -2,
      "name": "Rock_Stone_Cobble_Half",
      "rotation": 8
    },
    {
      "x": 1,
      "y": 6,
      "z": -2,
      "name": "Rock_Stone_Cobble"
    },
    {
      "x": 1,
      "y": 7,
      "z": -2,
      "name": "Soil_Gravel"
    },
    {
      "x": 1,
      "y": 8,
      "z": -2,
      "name": "Empty"
    },
    {
      "x": 1,
      "y": 9,
      "z": -2,
      "name": "Rock_Stone"
    },
    {
      "x": 1,
      "y": 10,
      "z": -2,
      "name": "Rock_Stone"
    },
    {
      "x": 1,
      "y": 11,
      "z": -2,
      "name": "Rock_Stone"
    },
    {
      "x": 1,
      "y": 12,
      "z": -2,
      "name": "Rock_Stone"
    },
    {
      "x": 1,
      "y": 13,
      "z": -2,
      "name": "Rock_Stone"
    },
    {
      "x": 1,
      "y": 14,
      "z": -2,
      "name": "Rock_Stone"
    },
    {
      "x": 1,
      "y": 0,
      "z": -1,
      "name": "Rock_Stone_Cobble"
    },
    {
      "x": 1,
      "y": 1,
      "z": -1,
      "name": "Empty"
    },
    {
      "x": 1,
      "y": 2,
      "z": -1,
      "name": "Empty"
    },
    {
      "x": 1,
      "y": 3,
      "z": -1,
      "name": "Empty"
    },
    {
      "x": 1,
      "y": 4,
      "z": -1,
      "name": "Empty"
    },
    {
      "x": 1,
      "y": 5,
      "z": -1,
      "name": "Rock_Stone_Brick_Smooth_Half",
      "rotation": 8
    },
    {
      "x": 1,
      "y": 6,
      "z": -1,
      "name": "Rock_Stone_Cobble"
    },
    {
      "x": 1,
      "y": 7,
      "z": -1,
      "name": "Soil_Gravel_Half"
    },
    {
      "x": 1,
      "y": 8,
      "z": -1,
      "name": "Empty"
    },
    {
      "x": 1,
      "y": 9,
      "z": -1,
      "name": "Empty"
    },
    {
      "x": 1,
      "y": 10,
      "z": -1,
      "name": "Plant_Flower_Orchid_Blue",
      "rotation": 8
    },
    {
      "x": 1,
      "y": 11,
      "z": -1,
      "name": "Rock_Stone"
    },
    {
      "x": 1,
      "y": 12,
      "z": -1,
      "name": "Rock_Stone"
    },
    {
      "x": 1,
      "y": 13,
      "z": -1,
      "name": "Rock_Stone"
    },
    {
      "x": 1,
      "y": 14,
      "z": -1,
      "name": "Rock_Stone"
    },
    {
      "x": 1,
      "y": 0,
      "z": 0,
      "name": "Rock_Stone_Cobble"
    },
    {
      "x": 1,
      "y": 1,
      "z": 0,
      "name": "Empty"
    },
    {
      "x": 1,
      "y": 2,
      "z": 0,
      "name": "Empty"
    },
    {
      "x": 1,
      "y": 3,
      "z": 0,
      "name": "Empty"
    },
    {
      "x": 1,
      "y": 4,
      "z": 0,
      "name": "Empty"
    },
    {
      "x": 1,
      "y": 5,
      "z": 0,
      "name": "Rock_Stone_Brick_Smooth_Half",
      "rotation": 8
    },
    {
      "x": 1,
      "y": 6,
      "z": 0,
      "name": "Rock_Stone_Brick_Smooth"
    },
    {
      "x": 1,
      "y": 7,
      "z": 0,
      "name": "Empty"
    },
    {
      "x": 1,
      "y": 8,
      "z": 0,
      "name": "Empty"
    },
    {
      "x": 1,
      "y": 9,
      "z": 0,
      "name": "Empty"
    },
    {
      "x": 1,
      "y": 10,
      "z": 0,
      "name": "Empty"
    },
    {
      "x": 1,
      "y": 11,
      "z": 0,
      "name": "Empty"
    },
    {
      "x": 1,
      "y": 12,
      "z": 0,
      "name": "Rock_Stone"
    },
    {
      "x": 1,
      "y": 13,
      "z": 0,
      "name": "Rock_Stone"
    },
    {
      "x": 1,
      "y": 14,
      "z": 0,
      "name": "Rock_Stone"
    },
    {
      "x": 2,
      "y": 0,
      "z": -7,
      "name": "Rock_Stone_Cobble_Stairs",
      "rotation": 1
    },
    {
      "x": 2,
      "y": 1,
      "z": -7,
      "name": "Empty"
    },
    {
      "x": 2,
      "y": 2,
      "z": -7,
      "name": "Empty"
    },
    {
      "x": 2,
      "y": 3,
      "z": -7,
      "name": "Empty"
    },
    {
      "x": 2,
      "y": 4,
      "z": -7,
      "name": "Empty"
    },
    {
      "x": 2,
      "y": 5,
      "z": -7,
      "name": "Rock_Stone_Brick_Smooth"
    },
    {
      "x": 2,
      "y": 6,
      "z": -7,
      "name": "Rock_Stone_Brick_Smooth_Half"
    },
    {
      "x": 2,
      "y": 7,
      "z": -7,
      "name": "Empty"
    },
    {
      "x": 2,
      "y": 8,
      "z": -7,
      "name": "Rock_Stone_Stalactite_Large",
      "filler": 31744,
      "rotation": 8
    },
    {
      "x": 2,
      "y": 9,
      "z": -7,
      "name": "Rock_Stone_Stalactite_Large",
      "rotation": 8
    },
    {
      "x": 2,
      "y": 10,
      "z": -7,
      "name": "Rock_Stone"
    },
    {
      "x": 2,
      "y": 11,
      "z": -7,
      "name": "Rock_Stone"
    },
    {
      "x": 2,
      "y": 12,
      "z": -7,
      "name": "Rock_Stone"
    },
    {
      "x": 2,
      "y": 13,
      "z": -7,
      "name": "Rock_Stone"
    },
    {
      "x": 2,
      "y": 14,
      "z": -7,
      "name": "Rock_Stone"
    },
    {
      "x": 2,
      "y": 0,
      "z": -6,
      "name": "Rock_Stone_Cobble_Stairs",
      "rotation": 1
    },
    {
      "x": 2,
      "y": 1,
      "z": -6,
      "name": "Empty"
    },
    {
      "x": 2,
      "y": 2,
      "z": -6,
      "name": "Empty"
    },
    {
      "x": 2,
      "y": 3,
      "z": -6,
      "name": "Empty"
    },
    {
      "x": 2,
      "y": 4,
      "z": -6,
      "name": "Empty"
    },
    {
      "x": 2,
      "y": 5,
      "z": -6,
      "name": "Rock_Stone_Cobble"
    },
    {
      "x": 2,
      "y": 6,
      "z": -6,
      "name": "Rock_Stone"
    },
    {
      "x": 2,
      "y": 7,
      "z": -6,
      "name": "Empty"
    },
    {
      "x": 2,
      "y": 8,
      "z": -6,
      "name": "Empty"
    },
    {
      "x": 2,
      "y": 9,
      "z": -6,
      "name": "Rock_Stone"
    },
    {
      "x": 2,
      "y": 10,
      "z": -6,
      "name": "Rock_Stone"
    },
    {
      "x": 2,
      "y": 11,
      "z": -6,
      "name": "Rock_Stone"
    },
    {
      "x": 2,
      "y": 12,
      "z": -6,
      "name": "Rock_Stone"
    },
    {
      "x": 2,
      "y": 13,
      "z": -6,
      "name": "Rock_Stone"
    },
    {
      "x": 2,
      "y": 14,
      "z": -6,
      "name": "Rock_Stone"
    },
    {
      "x": 2,
      "y": 0,
      "z": -5,
      "name": "Rock_Stone_Brick"
    },
    {
      "x": 2,
      "y": 1,
      "z": -5,
      "name": "Furniture_Temple_Dark_Pot"
    },
    {
      "x": 2,
      "y": 2,
      "z": -5,
      "name": "Empty"
    },
    {
      "x": 2,
      "y": 3,
      "z": -5,
      "name": "Empty"
    },
    {
      "x": 2,
      "y": 4,
      "z": -5,
      "name": "Empty"
    },
    {
      "x": 2,
      "y": 5,
      "z": -5,
      "name": "Rock_Stone_Cobble"
    },
    {
      "x": 2,
      "y": 6,
      "z": -5,
      "name": "Rock_Stone"
    },
    {
      "x": 2,
      "y": 7,
      "z": -5,
      "name": "Empty"
    },
    {
      "x": 2,
      "y": 8,
      "z": -5,
      "name": "Empty"
    },
    {
      "x": 2,
      "y": 9,
      "z": -5,
      "name": "Empty"
    },
    {
      "x": 2,
      "y": 10,
      "z": -5,
      "name": "Rock_Stone"
    },
    {
      "x": 2,
      "y": 11,
      "z": -5,
      "name": "Rock_Stone"
    },
    {
      "x": 2,
      "y": 12,
      "z": -5,
      "name": "Rock_Stone"
    },
    {
      "x": 2,
      "y": 13,
      "z": -5,
      "name": "Rock_Stone"
    },
    {
      "x": 2,
      "y": 14,
      "z": -5,
      "name": "Rock_Stone"
    },
    {
      "x": 2,
      "y": 0,
      "z": -4,
      "name": "Rock_Stone_Cobble"
    },
    {
      "x": 2,
      "y": 1,
      "z": -4,
      "name": "Rock_Stone_Brick_Pillar_Base"
    },
    {
      "x": 2,
      "y": 2,
      "z": -4,
      "name": "Furniture_Village_Statue",
      "rotation": 3
    },
    {
      "x": 2,
      "y": 3,
      "z": -4,
      "name": "Furniture_Village_Statue",
      "filler": 1024,
      "rotation": 3
    },
    {
      "x": 2,
      "y": 4,
      "z": -4,
      "name": "Furniture_Village_Statue",
      "filler": 2048,
      "rotation": 3
    },
    {
      "x": 2,
      "y": 5,
      "z": -4,
      "name": "Rock_Stone_Cobble"
    },
    {
      "x": 2,
      "y": 6,
      "z": -4,
      "name": "Rock_Stone"
    },
    {
      "x": 2,
      "y": 7,
      "z": -4,
      "name": "Rock_Stone"
    },
    {
      "x": 2,
      "y": 8,
      "z": -4,
      "name": "Empty"
    },
    {
      "x": 2,
      "y": 9,
      "z": -4,
      "name": "Rock_Stone"
    },
    {
      "x": 2,
      "y": 10,
      "z": -4,
      "name": "Rock_Stone"
    },
    {
      "x": 2,
      "y": 11,
      "z": -4,
      "name": "Rock_Stone"
    },
    {
      "x": 2,
      "y": 12,
      "z": -4,
      "name": "Rock_Stone"
    },
    {
      "x": 2,
      "y": 13,
      "z": -4,
      "name": "Rock_Stone"
    },
    {
      "x": 2,
      "y": 14,
      "z": -4,
      "name": "Rock_Stone"
    },
    {
      "x": 2,
      "y": 0,
      "z": -3,
      "name": "Rock_Stone_Cobble"
    },
    {
      "x": 2,
      "y": 1,
      "z": -3,
      "name": "Empty"
    },
    {
      "x": 2,
      "y": 2,
      "z": -3,
      "name": "Empty"
    },
    {
      "x": 2,
      "y": 3,
      "z": -3,
      "name": "Empty"
    },
    {
      "x": 2,
      "y": 4,
      "z": -3,
      "name": "Empty"
    },
    {
      "x": 2,
      "y": 5,
      "z": -3,
      "name": "Rock_Stone_Cobble"
    },
    {
      "x": 2,
      "y": 6,
      "z": -3,
      "name": "Rock_Stone"
    },
    {
      "x": 2,
      "y": 7,
      "z": -3,
      "name": "Rock_Stone"
    },
    {
      "x": 2,
      "y": 8,
      "z": -3,
      "name": "Rock_Stone"
    },
    {
      "x": 2,
      "y": 9,
      "z": -3,
      "name": "Rock_Stone"
    },
    {
      "x": 2,
      "y": 10,
      "z": -3,
      "name": "Rock_Stone"
    },
    {
      "x": 2,
      "y": 11,
      "z": -3,
      "name": "Rock_Stone"
    },
    {
      "x": 2,
      "y": 12,
      "z": -3,
      "name": "Rock_Stone"
    },
    {
      "x": 2,
      "y": 13,
      "z": -3,
      "name": "Rock_Stone"
    },
    {
      "x": 2,
      "y": 14,
      "z": -3,
      "name": "Rock_Stone"
    },
    {
      "x": 2,
      "y": 0,
      "z": -2,
      "name": "Rock_Stone_Cobble_Stairs",
      "rotation": 1
    },
    {
      "x": 2,
      "y": 1,
      "z": -2,
      "name": "Empty"
    },
    {
      "x": 2,
      "y": 2,
      "z": -2,
      "name": "Empty"
    },
    {
      "x": 2,
      "y": 3,
      "z": -2,
      "name": "Empty"
    },
    {
      "x": 2,
      "y": 4,
      "z": -2,
      "name": "Empty"
    },
    {
      "x": 2,
      "y": 5,
      "z": -2,
      "name": "Rock_Stone_Cobble"
    },
    {
      "x": 2,
      "y": 6,
      "z": -2,
      "name": "Rock_Stone"
    },
    {
      "x": 2,
      "y": 7,
      "z": -2,
      "name": "Rock_Stone"
    },
    {
      "x": 2,
      "y": 8,
      "z": -2,
      "name": "Rock_Stone"
    },
    {
      "x": 2,
      "y": 9,
      "z": -2,
      "name": "Rock_Stone"
    },
    {
      "x": 2,
      "y": 10,
      "z": -2,
      "name": "Rock_Stone"
    },
    {
      "x": 2,
      "y": 11,
      "z": -2,
      "name": "Rock_Stone"
    },
    {
      "x": 2,
      "y": 12,
      "z": -2,
      "name": "Rock_Stone"
    },
    {
      "x": 2,
      "y": 13,
      "z": -2,
      "name": "Rock_Stone"
    },
    {
      "x": 2,
      "y": 14,
      "z": -2,
      "name": "Rock_Stone"
    },
    {
      "x": 2,
      "y": 0,
      "z": -1,
      "name": "Rock_Stone_Cobble_Stairs",
      "rotation": 1
    },
    {
      "x": 2,
      "y": 1,
      "z": -1,
      "name": "Empty"
    },
    {
      "x": 2,
      "y": 2,
      "z": -1,
      "name": "Empty"
    },
    {
      "x": 2,
      "y": 3,
      "z": -1,
      "name": "Empty"
    },
    {
      "x": 2,
      "y": 4,
      "z": -1,
      "name": "Empty"
    },
    {
      "x": 2,
      "y": 5,
      "z": -1,
      "name": "Rock_Stone_Brick_Smooth"
    },
    {
      "x": 2,
      "y": 6,
      "z": -1,
      "name": "Rock_Stone"
    },
    {
      "x": 2,
      "y": 7,
      "z": -1,
      "name": "Rock_Stone"
    },
    {
      "x": 2,
      "y": 8,
      "z": -1,
      "name": "Empty"
    },
    {
      "x": 2,
      "y": 9,
      "z": -1,
      "name": "Rock_Stone"
    },
    {
      "x": 2,
      "y": 10,
      "z": -1,
      "name": "Rock_Stone"
    },
    {
      "x": 2,
      "y": 11,
      "z": -1,
      "name": "Rock_Stone"
    },
    {
      "x": 2,
      "y": 12,
      "z": -1,
      "name": "Rock_Stone"
    },
    {
      "x": 2,
      "y": 13,
      "z": -1,
      "name": "Rock_Stone"
    },
    {
      "x": 2,
      "y": 14,
      "z": -1,
      "name": "Rock_Stone"
    },
    {
      "x": 2,
      "y": 0,
      "z": 0,
      "name": "Rock_Stone_Cobble_Stairs",
      "rotation": 1
    },
    {
      "x": 2,
      "y": 1,
      "z": 0,
      "name": "Empty"
    },
    {
      "x": 2,
      "y": 2,
      "z": 0,
      "name": "Empty"
    },
    {
      "x": 2,
      "y": 3,
      "z": 0,
      "name": "Empty"
    },
    {
      "x": 2,
      "y": 4,
      "z": 0,
      "name": "Empty"
    },
    {
      "x": 2,
      "y": 5,
      "z": 0,
      "name": "Rock_Stone_Brick_Smooth"
    },
    {
      "x": 2,
      "y": 6,
      "z": 0,
      "name": "Rock_Stone_Brick_Smooth_Half"
    },
    {
      "x": 2,
      "y": 7,
      "z": 0,
      "name": "Empty"
    },
    {
      "x": 2,
      "y": 8,
      "z": 0,
      "name": "Empty"
    },
    {
      "x": 2,
      "y": 9,
      "z": 0,
      "name": "Empty"
    },
    {
      "x": 2,
      "y": 10,
      "z": 0,
      "name": "Rock_Stone"
    },
    {
      "x": 2,
      "y": 11,
      "z": 0,
      "name": "Rock_Stone"
    },
    {
      "x": 2,
      "y": 12,
      "z": 0,
      "name": "Rock_Stone"
    },
    {
      "x": 2,
      "y": 13,
      "z": 0,
      "name": "Rock_Stone"
    },
    {
      "x": 2,
      "y": 14,
      "z": 0,
      "name": "Rock_Stone"
    },
    {
      "x": 3,
      "y": 0,
      "z": -7,
      "name": "Rock_Stone_Brick_Smooth"
    },
    {
      "x": 3,
      "y": 1,
      "z": -7,
      "name": "Rock_Stone_Brick_Smooth_Half",
      "rotation": 4
    },
    {
      "x": 3,
      "y": 2,
      "z": -7,
      "name": "Rock_Stone_Brick_Smooth"
    },
    {
      "x": 3,
      "y": 3,
      "z": -7,
      "name": "Rock_Stone_Brick_Smooth_Half",
      "rotation": 4
    },
    {
      "x": 3,
      "y": 4,
      "z": -7,
      "name": "Rock_Stone_Brick_Smooth"
    },
    {
      "x": 3,
      "y": 5,
      "z": -7,
      "name": "Rock_Stone_Brick_Smooth"
    },
    {
      "x": 3,
      "y": 6,
      "z": -7,
      "name": "Rock_Stone"
    },
    {
      "x": 3,
      "y": 7,
      "z": -7,
      "name": "Rock_Stone"
    },
    {
      "x": 3,
      "y": 8,
      "z": -7,
      "name": "Rock_Stone"
    },
    {
      "x": 3,
      "y": 9,
      "z": -7,
      "name": "Rock_Stone"
    },
    {
      "x": 3,
      "y": 10,
      "z": -7,
      "name": "Rock_Stone"
    },
    {
      "x": 3,
      "y": 11,
      "z": -7,
      "name": "Rock_Stone"
    },
    {
      "x": 3,
      "y": 12,
      "z": -7,
      "name": "Rock_Stone"
    },
    {
      "x": 3,
      "y": 13,
      "z": -7,
      "name": "Rock_Stone"
    },
    {
      "x": 3,
      "y": 14,
      "z": -7,
      "name": "Rock_Stone"
    },
    {
      "x": 3,
      "y": 0,
      "z": -6,
      "name": "Rock_Stone_Brick_Smooth"
    },
    {
      "x": 3,
      "y": 1,
      "z": -6,
      "name": "Block_Spawner_Block",
      "components": {
        "Components": {
          "BlockSpawner": {
            "BlockSpawnerId": "Zone1_Encounters_Tier3"
          }
        }
      },
      "rotation": 3
    },
    {
      "x": 3,
      "y": 2,
      "z": -6,
      "name": "Rock_Stone_Brick_Smooth_Half",
      "rotation": 8
    },
    {
      "x": 3,
      "y": 3,
      "z": -6,
      "name": "Empty"
    },
    {
      "x": 3,
      "y": 4,
      "z": -6,
      "name": "Rock_Stone_Brick_Smooth_Half",
      "rotation": 8
    },
    {
      "x": 3,
      "y": 5,
      "z": -6,
      "name": "Rock_Stone_Brick_Smooth"
    },
    {
      "x": 3,
      "y": 6,
      "z": -6,
      "name": "Rock_Stone"
    },
    {
      "x": 3,
      "y": 7,
      "z": -6,
      "name": "Rock_Stone"
    },
    {
      "x": 3,
      "y": 8,
      "z": -6,
      "name": "Rock_Stone"
    },
    {
      "x": 3,
      "y": 9,
      "z": -6,
      "name": "Rock_Stone"
    },
    {
      "x": 3,
      "y": 10,
      "z": -6,
      "name": "Rock_Stone"
    },
    {
      "x": 3,
      "y": 11,
      "z": -6,
      "name": "Rock_Stone"
    },
    {
      "x": 3,
      "y": 12,
      "z": -6,
      "name": "Rock_Stone"
    },
    {
      "x": 3,
      "y": 13,
      "z": -6,
      "name": "Rock_Stone"
    },
    {
      "x": 3,
      "y": 14,
      "z": -6,
      "name": "Rock_Stone"
    },
    {
      "x": 3,
      "y": 0,
      "z": -5,
      "name": "Rock_Stone_Brick_Smooth"
    },
    {
      "x": 3,
      "y": 1,
      "z": -5,
      "name": "Rock_Stone_Brick_Smooth"
    },
    {
      "x": 3,
      "y": 2,
      "z": -5,
      "name": "Rock_Stone_Brick_Smooth"
    },
    {
      "x": 3,
      "y": 3,
      "z": -5,
      "name": "Rock_Stone_Brick_Smooth"
    },
    {
      "x": 3,
      "y": 4,
      "z": -5,
      "name": "Rock_Stone_Brick_Smooth"
    },
    {
      "x": 3,
      "y": 5,
      "z": -5,
      "name": "Rock_Stone_Brick_Smooth"
    },
    {
      "x": 3,
      "y": 6,
      "z": -5,
      "name": "Rock_Stone"
    },
    {
      "x": 3,
      "y": 7,
      "z": -5,
      "name": "Rock_Stone"
    },
    {
      "x": 3,
      "y": 8,
      "z": -5,
      "name": "Rock_Stone"
    },
    {
      "x": 3,
      "y": 9,
      "z": -5,
      "name": "Rock_Stone"
    },
    {
      "x": 3,
      "y": 10,
      "z": -5,
      "name": "Rock_Stone"
    },
    {
      "x": 3,
      "y": 11,
      "z": -5,
      "name": "Rock_Stone"
    },
    {
      "x": 3,
      "y": 12,
      "z": -5,
      "name": "Rock_Stone"
    },
    {
      "x": 3,
      "y": 13,
      "z": -5,
      "name": "Rock_Stone"
    },
    {
      "x": 3,
      "y": 14,
      "z": -5,
      "name": "Rock_Stone"
    },
    {
      "x": 3,
      "y": 0,
      "z": -4,
      "name": "Rock_Stone_Brick_Smooth"
    },
    {
      "x": 3,
      "y": 1,
      "z": -4,
      "name": "Rock_Stone_Brick_Smooth"
    },
    {
      "x": 3,
      "y": 2,
      "z": -4,
      "name": "Rock_Stone_Brick_Smooth"
    },
    {
      "x": 3,
      "y": 3,
      "z": -4,
      "name": "Rock_Stone_Brick_Smooth"
    },
    {
      "x": 3,
      "y": 4,
      "z": -4,
      "name": "Rock_Stone_Brick_Smooth"
    },
    {
      "x": 3,
      "y": 5,
      "z": -4,
      "name": "Rock_Stone_Brick_Smooth"
    },
    {
      "x": 3,
      "y": 6,
      "z": -4,
      "name": "Rock_Stone"
    },
    {
      "x": 3,
      "y": 7,
      "z": -4,
      "name": "Rock_Stone"
    },
    {
      "x": 3,
      "y": 8,
      "z": -4,
      "name": "Rock_Stone"
    },
    {
      "x": 3,
      "y": 9,
      "z": -4,
      "name": "Rock_Stone"
    },
    {
      "x": 3,
      "y": 10,
      "z": -4,
      "name": "Rock_Stone"
    },
    {
      "x": 3,
      "y": 11,
      "z": -4,
      "name": "Rock_Stone"
    },
    {
      "x": 3,
      "y": 12,
      "z": -4,
      "name": "Rock_Stone"
    },
    {
      "x": 3,
      "y": 13,
      "z": -4,
      "name": "Rock_Stone"
    },
    {
      "x": 3,
      "y": 14,
      "z": -4,
      "name": "Rock_Stone"
    },
    {
      "x": 3,
      "y": 0,
      "z": -3,
      "name": "Rock_Stone_Brick_Smooth"
    },
    {
      "x": 3,
      "y": 1,
      "z": -3,
      "name": "Rock_Stone_Brick_Smooth_Half",
      "rotation": 4
    },
    {
      "x": 3,
      "y": 2,
      "z": -3,
      "name": "Rock_Stone_Brick_Smooth"
    },
    {
      "x": 3,
      "y": 3,
      "z": -3,
      "name": "Rock_Stone_Brick_Smooth_Half",
      "rotation": 4
    },
    {
      "x": 3,
      "y": 4,
      "z": -3,
      "name": "Rock_Stone_Brick_Smooth"
    },
    {
      "x": 3,
      "y": 5,
      "z": -3,
      "name": "Rock_Stone_Brick_Smooth"
    },
    {
      "x": 3,
      "y": 6,
      "z": -3,
      "name": "Rock_Stone"
    },
    {
      "x": 3,
      "y": 7,
      "z": -3,
      "name": "Rock_Stone"
    },
    {
      "x": 3,
      "y": 8,
      "z": -3,
      "name": "Rock_Stone"
    },
    {
      "x": 3,
      "y": 9,
      "z": -3,
      "name": "Rock_Stone"
    },
    {
      "x": 3,
      "y": 10,
      "z": -3,
      "name": "Rock_Stone"
    },
    {
      "x": 3,
      "y": 11,
      "z": -3,
      "name": "Rock_Stone"
    },
    {
      "x": 3,
      "y": 12,
      "z": -3,
      "name": "Rock_Stone"
    },
    {
      "x": 3,
      "y": 13,
      "z": -3,
      "name": "Rock_Stone"
    },
    {
      "x": 3,
      "y": 14,
      "z": -3,
      "name": "Rock_Stone"
    },
    {
      "x": 3,
      "y": 0,
      "z": -2,
      "name": "Rock_Stone_Brick_Smooth"
    },
    {
      "x": 3,
      "y": 1,
      "z": -2,
      "name": "Furniture_Human_Ruins_Coffin",
      "filler": 992,
      "rotation": 1
    },
    {
      "x": 3,
      "y": 2,
      "z": -2,
      "name": "Rock_Stone_Brick_Smooth_Half",
      "rotation": 8
    },
    {
      "x": 3,
      "y": 3,
      "z": -2,
      "name": "Furniture_Temple_Dark_Pot"
    },
    {
      "x": 3,
      "y": 4,
      "z": -2,
      "name": "Rock_Stone_Brick_Smooth_Half",
      "rotation": 8
    },
    {
      "x": 3,
      "y": 5,
      "z": -2,
      "name": "Rock_Stone_Brick_Smooth"
    },
    {
      "x": 3,
      "y": 6,
      "z": -2,
      "name": "Rock_Stone"
    },
    {
      "x": 3,
      "y": 7,
      "z": -2,
      "name": "Rock_Stone"
    },
    {
      "x": 3,
      "y": 8,
      "z": -2,
      "name": "Rock_Stone"
    },
    {
      "x": 3,
      "y": 9,
      "z": -2,
      "name": "Rock_Stone"
    },
    {
      "x": 3,
      "y": 10,
      "z": -2,
      "name": "Rock_Stone"
    },
    {
      "x": 3,
      "y": 11,
      "z": -2,
      "name": "Rock_Stone"
    },
    {
      "x": 3,
      "y": 12,
      "z": -2,
      "name": "Rock_Stone"
    },
    {
      "x": 3,
      "y": 13,
      "z": -2,
      "name": "Rock_Stone"
    },
    {
      "x": 3,
      "y": 14,
      "z": -2,
      "name": "Rock_Stone"
    },
    {
      "x": 3,
      "y": 0,
      "z": -1,
      "name": "Rock_Stone_Brick_Smooth"
    },
    {
      "x": 3,
      "y": 1,
      "z": -1,
      "name": "Furniture_Human_Ruins_Coffin",
      "rotation": 1
    },
    {
      "x": 3,
      "y": 2,
      "z": -1,
      "name": "Rock_Stone_Brick_Smooth_Half",
      "rotation": 8
    },
    {
      "x": 3,
      "y": 3,
      "z": -1,
      "name": "Empty"
    },
    {
      "x": 3,
      "y": 4,
      "z": -1,
      "name": "Rock_Stone_Brick_Smooth_Half",
      "rotation": 8
    },
    {
      "x": 3,
      "y": 5,
      "z": -1,
      "name": "Rock_Stone_Brick_Smooth"
    },
    {
      "x": 3,
      "y": 6,
      "z": -1,
      "name": "Rock_Stone"
    },
    {
      "x": 3,
      "y": 7,
      "z": -1,
      "name": "Rock_Stone"
    },
    {
      "x": 3,
      "y": 8,
      "z": -1,
      "name": "Rock_Stone"
    },
    {
      "x": 3,
      "y": 9,
      "z": -1,
      "name": "Rock_Stone"
    },
    {
      "x": 3,
      "y": 10,
      "z": -1,
      "name": "Rock_Stone"
    },
    {
      "x": 3,
      "y": 11,
      "z": -1,
      "name": "Rock_Stone"
    },
    {
      "x": 3,
      "y": 12,
      "z": -1,
      "name": "Rock_Stone"
    },
    {
      "x": 3,
      "y": 13,
      "z": -1,
      "name": "Rock_Stone"
    },
    {
      "x": 3,
      "y": 14,
      "z": -1,
      "name": "Rock_Stone"
    },
    {
      "x": 3,
      "y": 0,
      "z": 0,
      "name": "Rock_Stone_Brick_Smooth"
    },
    {
      "x": 3,
      "y": 1,
      "z": 0,
      "name": "Rock_Stone_Brick_Smooth_Half",
      "rotation": 6
    },
    {
      "x": 3,
      "y": 2,
      "z": 0,
      "name": "Rock_Stone_Brick_Smooth"
    },
    {
      "x": 3,
      "y": 3,
      "z": 0,
      "name": "Rock_Stone_Brick_Smooth_Half",
      "rotation": 6
    },
    {
      "x": 3,
      "y": 4,
      "z": 0,
      "name": "Rock_Stone_Brick_Smooth"
    },
    {
      "x": 3,
      "y": 5,
      "z": 0,
      "name": "Rock_Stone_Brick_Smooth"
    },
    {
      "x": 3,
      "y": 6,
      "z": 0,
      "name": "Rock_Stone"
    },
    {
      "x": 3,
      "y": 7,
      "z": 0,
      "name": "Rock_Stone"
    },
    {
      "x": 3,
      "y": 8,
      "z": 0,
      "name": "Rock_Stone"
    },
    {
      "x": 3,
      "y": 9,
      "z": 0,
      "name": "Rock_Stone"
    },
    {
      "x": 3,
      "y": 10,
      "z": 0,
      "name": "Rock_Stone"
    },
    {
      "x": 3,
      "y": 11,
      "z": 0,
      "name": "Rock_Stone"
    },
    {
      "x": 3,
      "y": 12,
      "z": 0,
      "name": "Rock_Stone"
    },
    {
      "x": 3,
      "y": 13,
      "z": 0,
      "name": "Rock_Stone"
    },
    {
      "x": 3,
      "y": 14,
      "z": 0,
      "name": "Rock_Stone"
    },
    {
      "x": 4,
      "y": 0,
      "z": -7,
      "name": "Rock_Volcanic_Cobble"
    },
    {
      "x": 4,
      "y": 1,
      "z": -7,
      "name": "Rock_Volcanic_Cobble"
    },
    {
      "x": 4,
      "y": 2,
      "z": -7,
      "name": "Rock_Volcanic_Cobble"
    },
    {
      "x": 4,
      "y": 3,
      "z": -7,
      "name": "Rock_Volcanic_Cobble"
    },
    {
      "x": 4,
      "y": 4,
      "z": -7,
      "name": "Rock_Volcanic_Cobble"
    },
    {
      "x": 4,
      "y": 5,
      "z": -7,
      "name": "Rock_Volcanic_Cobble"
    },
    {
      "x": 4,
      "y": 6,
      "z": -7,
      "name": "Rock_Stone"
    },
    {
      "x": 4,
      "y": 7,
      "z": -7,
      "name": "Rock_Stone"
    },
    {
      "x": 4,
      "y": 8,
      "z": -7,
      "name": "Rock_Stone"
    },
    {
      "x": 4,
      "y": 9,
      "z": -7,
      "name": "Rock_Stone"
    },
    {
      "x": 4,
      "y": 10,
      "z": -7,
      "name": "Rock_Stone"
    },
    {
      "x": 4,
      "y": 11,
      "z": -7,
      "name": "Rock_Stone"
    },
    {
      "x": 4,
      "y": 12,
      "z": -7,
      "name": "Rock_Stone"
    },
    {
      "x": 4,
      "y": 13,
      "z": -7,
      "name": "Rock_Stone"
    },
    {
      "x": 4,
      "y": 14,
      "z": -7,
      "name": "Rock_Stone"
    },
    {
      "x": 4,
      "y": 0,
      "z": -6,
      "name": "Rock_Volcanic_Cobble"
    },
    {
      "x": 4,
      "y": 1,
      "z": -6,
      "name": "Rock_Volcanic_Cobble"
    },
    {
      "x": 4,
      "y": 2,
      "z": -6,
      "name": "Rock_Volcanic_Cobble"
    },
    {
      "x": 4,
      "y": 3,
      "z": -6,
      "name": "Rock_Volcanic_Cobble"
    },
    {
      "x": 4,
      "y": 4,
      "z": -6,
      "name": "Rock_Volcanic_Cobble"
    },
    {
      "x": 4,
      "y": 5,
      "z": -6,
      "name": "Rock_Volcanic_Cobble"
    },
    {
      "x": 4,
      "y": 6,
      "z": -6,
      "name": "Rock_Stone"
    },
    {
      "x": 4,
      "y": 7,
      "z": -6,
      "name": "Rock_Stone"
    },
    {
      "x": 4,
      "y": 8,
      "z": -6,
      "name": "Rock_Stone"
    },
    {
      "x": 4,
      "y": 9,
      "z": -6,
      "name": "Rock_Stone"
    },
    {
      "x": 4,
      "y": 10,
      "z": -6,
      "name": "Rock_Stone"
    },
    {
      "x": 4,
      "y": 11,
      "z": -6,
      "name": "Rock_Stone"
    },
    {
      "x": 4,
      "y": 12,
      "z": -6,
      "name": "Rock_Stone"
    },
    {
      "x": 4,
      "y": 13,
      "z": -6,
      "name": "Rock_Stone"
    },
    {
      "x": 4,
      "y": 14,
      "z": -6,
      "name": "Rock_Stone"
    },
    {
      "x": 4,
      "y": 0,
      "z": -5,
      "name": "Rock_Volcanic_Cobble"
    },
    {
      "x": 4,
      "y": 1,
      "z": -5,
      "name": "Rock_Volcanic_Cobble"
    },
    {
      "x": 4,
      "y": 2,
      "z": -5,
      "name": "Rock_Volcanic_Cobble"
    },
    {
      "x": 4,
      "y": 3,
      "z": -5,
      "name": "Rock_Volcanic_Cobble"
    },
    {
      "x": 4,
      "y": 4,
      "z": -5,
      "name": "Rock_Volcanic_Cobble"
    },
    {
      "x": 4,
      "y": 5,
      "z": -5,
      "name": "Rock_Volcanic_Cobble"
    },
    {
      "x": 4,
      "y": 6,
      "z": -5,
      "name": "Rock_Stone"
    },
    {
      "x": 4,
      "y": 7,
      "z": -5,
      "name": "Rock_Stone"
    },
    {
      "x": 4,
      "y": 8,
      "z": -5,
      "name": "Rock_Stone"
    },
    {
      "x": 4,
      "y": 9,
      "z": -5,
      "name": "Rock_Stone"
    },
    {
      "x": 4,
      "y": 10,
      "z": -5,
      "name": "Rock_Stone"
    },
    {
      "x": 4,
      "y": 11,
      "z": -5,
      "name": "Rock_Stone"
    },
    {
      "x": 4,
      "y": 12,
      "z": -5,
      "name": "Rock_Stone"
    },
    {
      "x": 4,
      "y": 13,
      "z": -5,
      "name": "Rock_Stone"
    },
    {
      "x": 4,
      "y": 14,
      "z": -5,
      "name": "Rock_Stone"
    },
    {
      "x": 4,
      "y": 0,
      "z": -4,
      "name": "Rock_Volcanic_Cobble"
    },
    {
      "x": 4,
      "y": 1,
      "z": -4,
      "name": "Rock_Volcanic_Cobble"
    },
    {
      "x": 4,
      "y": 2,
      "z": -4,
      "name": "Rock_Volcanic_Cobble"
    },
    {
      "x": 4,
      "y": 3,
      "z": -4,
      "name": "Rock_Volcanic_Cobble"
    },
    {
      "x": 4,
      "y": 4,
      "z": -4,
      "name": "Rock_Volcanic_Cobble"
    },
    {
      "x": 4,
      "y": 5,
      "z": -4,
      "name": "Rock_Volcanic_Cobble"
    },
    {
      "x": 4,
      "y": 6,
      "z": -4,
      "name": "Rock_Stone"
    },
    {
      "x": 4,
      "y": 7,
      "z": -4,
      "name": "Rock_Stone"
    },
    {
      "x": 4,
      "y": 8,
      "z": -4,
      "name": "Rock_Stone"
    },
    {
      "x": 4,
      "y": 9,
      "z": -4,
      "name": "Rock_Stone"
    },
    {
      "x": 4,
      "y": 10,
      "z": -4,
      "name": "Rock_Stone"
    },
    {
      "x": 4,
      "y": 11,
      "z": -4,
      "name": "Rock_Stone"
    },
    {
      "x": 4,
      "y": 12,
      "z": -4,
      "name": "Rock_Stone"
    },
    {
      "x": 4,
      "y": 13,
      "z": -4,
      "name": "Rock_Stone"
    },
    {
      "x": 4,
      "y": 14,
      "z": -4,
      "name": "Rock_Stone"
    },
    {
      "x": 4,
      "y": 0,
      "z": -3,
      "name": "Rock_Volcanic_Cobble"
    },
    {
      "x": 4,
      "y": 1,
      "z": -3,
      "name": "Rock_Volcanic_Cobble"
    },
    {
      "x": 4,
      "y": 2,
      "z": -3,
      "name": "Rock_Volcanic_Cobble"
    },
    {
      "x": 4,
      "y": 3,
      "z": -3,
      "name": "Rock_Volcanic_Cobble"
    },
    {
      "x": 4,
      "y": 4,
      "z": -3,
      "name": "Rock_Volcanic_Cobble"
    },
    {
      "x": 4,
      "y": 5,
      "z": -3,
      "name": "Rock_Volcanic_Cobble"
    },
    {
      "x": 4,
      "y": 6,
      "z": -3,
      "name": "Rock_Stone"
    },
    {
      "x": 4,
      "y": 7,
      "z": -3,
      "name": "Rock_Stone"
    },
    {
      "x": 4,
      "y": 8,
      "z": -3,
      "name": "Rock_Stone"
    },
    {
      "x": 4,
      "y": 9,
      "z": -3,
      "name": "Rock_Stone"
    },
    {
      "x": 4,
      "y": 10,
      "z": -3,
      "name": "Rock_Stone"
    },
    {
      "x": 4,
      "y": 11,
      "z": -3,
      "name": "Rock_Stone"
    },
    {
      "x": 4,
      "y": 12,
      "z": -3,
      "name": "Rock_Stone"
    },
    {
      "x": 4,
      "y": 13,
      "z": -3,
      "name": "Rock_Stone"
    },
    {
      "x": 4,
      "y": 14,
      "z": -3,
      "name": "Rock_Stone"
    },
    {
      "x": 4,
      "y": 0,
      "z": -2,
      "name": "Rock_Volcanic_Cobble"
    },
    {
      "x": 4,
      "y": 1,
      "z": -2,
      "name": "Rock_Volcanic_Cobble"
    },
    {
      "x": 4,
      "y": 2,
      "z": -2,
      "name": "Rock_Volcanic_Cobble"
    },
    {
      "x": 4,
      "y": 3,
      "z": -2,
      "name": "Rock_Volcanic_Cobble"
    },
    {
      "x": 4,
      "y": 4,
      "z": -2,
      "name": "Rock_Volcanic_Cobble"
    },
    {
      "x": 4,
      "y": 5,
      "z": -2,
      "name": "Rock_Volcanic_Cobble"
    },
    {
      "x": 4,
      "y": 6,
      "z": -2,
      "name": "Rock_Stone"
    },
    {
      "x": 4,
      "y": 7,
      "z": -2,
      "name": "Rock_Stone"
    },
    {
      "x": 4,
      "y": 8,
      "z": -2,
      "name": "Rock_Stone"
    },
    {
      "x": 4,
      "y": 9,
      "z": -2,
      "name": "Rock_Stone"
    },
    {
      "x": 4,
      "y": 10,
      "z": -2,
      "name": "Rock_Stone"
    },
    {
      "x": 4,
      "y": 11,
      "z": -2,
      "name": "Rock_Stone"
    },
    {
      "x": 4,
      "y": 12,
      "z": -2,
      "name": "Rock_Stone"
    },
    {
      "x": 4,
      "y": 13,
      "z": -2,
      "name": "Rock_Stone"
    },
    {
      "x": 4,
      "y": 14,
      "z": -2,
      "name": "Rock_Stone"
    },
    {
      "x": 4,
      "y": 0,
      "z": -1,
      "name": "Rock_Volcanic_Cobble"
    },
    {
      "x": 4,
      "y": 1,
      "z": -1,
      "name": "Rock_Volcanic_Cobble"
    },
    {
      "x": 4,
      "y": 2,
      "z": -1,
      "name": "Rock_Volcanic_Cobble"
    },
    {
      "x": 4,
      "y": 3,
      "z": -1,
      "name": "Rock_Volcanic_Cobble"
    },
    {
      "x": 4,
      "y": 4,
      "z": -1,
      "name": "Rock_Volcanic_Cobble"
    },
    {
      "x": 4,
      "y": 5,
      "z": -1,
      "name": "Rock_Volcanic_Cobble"
    },
    {
      "x": 4,
      "y": 6,
      "z": -1,
      "name": "Rock_Stone"
    },
    {
      "x": 4,
      "y": 7,
      "z": -1,
      "name": "Rock_Stone"
    },
    {
      "x": 4,
      "y": 8,
      "z": -1,
      "name": "Rock_Stone"
    },
    {
      "x": 4,
      "y": 9,
      "z": -1,
      "name": "Rock_Stone"
    },
    {
      "x": 4,
      "y": 10,
      "z": -1,
      "name": "Rock_Stone"
    },
    {
      "x": 4,
      "y": 11,
      "z": -1,
      "name": "Rock_Stone"
    },
    {
      "x": 4,
      "y": 12,
      "z": -1,
      "name": "Rock_Stone"
    },
    {
      "x": 4,
      "y": 13,
      "z": -1,
      "name": "Rock_Stone"
    },
    {
      "x": 4,
      "y": 14,
      "z": -1,
      "name": "Rock_Stone"
    },
    {
      "x": 4,
      "y": 0,
      "z": 0,
      "name": "Rock_Volcanic_Cobble"
    },
    {
      "x": 4,
      "y": 1,
      "z": 0,
      "name": "Rock_Volcanic_Cobble"
    },
    {
      "x": 4,
      "y": 2,
      "z": 0,
      "name": "Rock_Volcanic_Cobble"
    },
    {
      "x": 4,
      "y": 3,
      "z": 0,
      "name": "Rock_Volcanic_Cobble"
    },
    {
      "x": 4,
      "y": 4,
      "z": 0,
      "name": "Rock_Volcanic_Cobble"
    },
    {
      "x": 4,
      "y": 5,
      "z": 0,
      "name": "Rock_Volcanic_Cobble"
    },
    {
      "x": 4,
      "y": 6,
      "z": 0,
      "name": "Rock_Stone"
    },
    {
      "x": 4,
      "y": 7,
      "z": 0,
      "name": "Rock_Stone"
    },
    {
      "x": 4,
      "y": 8,
      "z": 0,
      "name": "Rock_Stone"
    },
    {
      "x": 4,
      "y": 9,
      "z": 0,
      "name": "Rock_Stone"
    },
    {
      "x": 4,
      "y": 10,
      "z": 0,
      "name": "Rock_Stone"
    },
    {
      "x": 4,
      "y": 11,
      "z": 0,
      "name": "Rock_Stone"
    },
    {
      "x": 4,
      "y": 12,
      "z": 0,
      "name": "Rock_Stone"
    },
    {
      "x": 4,
      "y": 13,
      "z": 0,
      "name": "Rock_Stone"
    },
    {
      "x": 4,
      "y": 14,
      "z": 0,
      "name": "Rock_Stone"
    }
  ]
}
