{
  "version": 8,
  "blockIdVersion": 8,
  "anchorX": 0,
  "anchorY": 0,
  "anchorZ": 0,
  "blocks": [
    {
      "x": -15,
      "y": -8,
      "z": -23,
      "name": "Rock_Stone"
    },
    {
      "x": -15,
      "y": -7,
      "z": -23,
      "name": "Rock_Stone"
    },
    {
      "x": -15,
      "y": -6,
      "z": -23,
      "name": "Rock_Quartzite_Brick"
    },
    {
      "x": -15,
      "y": -5,
      "z": -23,
      "name": "Rock_Quartzite_Brick"
    },
    {
      "x": -15,
      "y": -4,
      "z": -23,
      "name": "Rock_Quartzite_Brick"
    },
    {
      "x": -15,
      "y": -3,
      "z": -23,
      "name": "Rock_Quartzite_Brick"
    },
    {
      "x": -15,
      "y": -9,
      "z": -22,
      "name": "Rock_Stone"
    },
    {
      "x": -15,
      "y": -8,
      "z": -22,
      "name": "Rock_Stone"
    },
    {
      "x": -15,
      "y": -7,
      "z": -22,
      "name": "Rock_Stone_Cobble"
    },
    {
      "x": -15,
      "y": -6,
      "z": -22,
      "name": "Empty"
    },
    {
      "x": -15,
      "y": -5,
      "z": -22,
      "name": "Empty"
    },
    {
      "x": -15,
      "y": -4,
      "z": -22,
      "name": "Empty"
    },
    {
      "x": -15,
      "y": -3,
      "z": -22,
      "name": "Rock_Quartzite_Brick"
    },
    {
      "x": -15,
      "y": -2,
      "z": -22,
      "name": "Rock_Quartzite_Brick"
    },
    {
      "x": -15,
      "y": -9,
      "z": -21,
      "name": "Rock_Stone"
    },
    {
      "x": -15,
      "y": -8,
      "z": -21,
      "name": "Rock_Stone"
    },
    {
      "x": -15,
      "y": -7,
      "z": -21,
      "name": "Rock_Stone_Cobble"
    },
    {
      "x": -15,
      "y": -6,
      "z": -21,
      "name": "Empty"
    },
    {
      "x": -15,
      "y": -5,
      "z": -21,
      "name": "Empty"
    },
    {
      "x": -15,
      "y": -4,
      "z": -21,
      "name": "Empty"
    },
    {
      "x": -15,
      "y": -3,
      "z": -21,
      "name": "Rock_Quartzite_Brick"
    },
    {
      "x": -15,
      "y": -2,
      "z": -21,
      "name": "Rock_Quartzite_Brick"
    },
    {
      "x": -15,
      "y": -9,
      "z": -20,
      "name": "Rock_Stone"
    },
    {
      "x": -15,
      "y": -8,
      "z": -20,
      "name": "Rock_Stone"
    },
    {
      "x": -15,
      "y": -7,
      "z": -20,
      "name": "Rock_Stone_Cobble"
    },
    {
      "x": -15,
      "y": -6,
      "z": -20,
      "name": "Empty"
    },
    {
      "x": -15,
      "y": -5,
      "z": -20,
      "name": "Empty"
    },
    {
      "x": -15,
      "y": -4,
      "z": -20,
      "name": "Empty"
    },
    {
      "x": -15,
      "y": -3,
      "z": -20,
      "name": "Rock_Quartzite_Brick"
    },
    {
      "x": -15,
      "y": -2,
      "z": -20,
      "name": "Rock_Quartzite_Brick"
    },
    {
      "x": -15,
      "y": -8,
      "z": -19,
      "name": "Rock_Stone"
    },
    {
      "x": -15,
      "y": -7,
      "z": -19,
      "name": "Rock_Stone"
    },
    {
      "x": -15,
      "y": -6,
      "z": -19,
      "name": "Rock_Quartzite_Brick"
    },
    {
      "x": -15,
      "y": -5,
      "z": -19,
      "name": "Rock_Quartzite_Brick"
    },
    {
      "x": -15,
      "y": -4,
      "z": -19,
      "name": "Rock_Quartzite_Brick"
    },
    {
      "x": -15,
      "y": -3,
      "z": -19,
      "name": "Rock_Quartzite_Brick"
    },
    {
      "x": -14,
      "y": -8,
      "z": -23,
      "name": "Rock_Stone"
    },
    {
      "x": -14,
      "y": -7,
      "z": -23,
      "name": "Rock_Stone"
    },
    {
      "x": -14,
      "y": -6,
      "z": -23,
      "name": "Rock_Quartzite_Brick"
    },
    {
      "x": -14,
      "y": -5,
      "z": -23,
      "name": "Rock_Quartzite_Brick"
    },
    {
      "x": -14,
      "y": -4,
      "z": -23,
      "name": "Rock_Quartzite_Brick"
    },
    {
      "x": -14,
      "y": -3,
      "z": -23,
      "name": "Rock_Quartzite_Brick"
    },
    {
      "x": -14,
      "y": -9,
      "z": -22,
      "name": "Rock_Stone"
    },
    {
      "x": -14,
      "y": -8,
      "z": -22,
      "name": "Rock_Stone"
    },
    {
      "x": -14,
      "y": -7,
      "z": -22,
      "name": "Rock_Stone_Cobble"
    },
    {
      "x": -14,
      "y": -6,
      "z": -22,
      "name": "Empty"
    },
    {
      "x": -14,
      "y": -5,
      "z": -22,
      "name": "Empty"
    },
    {
      "x": -14,
      "y": -4,
      "z": -22,
      "name": "Empty"
    },
    {
      "x": -14,
      "y": -3,
      "z": -22,
      "name": "Rock_Quartzite_Brick"
    },
    {
      "x": -14,
      "y": -2,
      "z": -22,
      "name": "Rock_Quartzite_Brick"
    },
    {
      "x": -14,
      "y": -9,
      "z": -21,
      "name": "Rock_Stone"
    },
    {
      "x": -14,
      "y": -8,
      "z": -21,
      "name": "Rock_Stone"
    },
    {
      "x": -14,
      "y": -7,
      "z": -21,
      "name": "Rock_Stone_Cobble"
    },
    {
      "x": -14,
      "y": -6,
      "z": -21,
      "name": "Empty"
    },
    {
      "x": -14,
      "y": -5,
      "z": -21,
      "name": "Empty"
    },
    {
      "x": -14,
      "y": -4,
      "z": -21,
      "name": "Empty"
    },
    {
      "x": -14,
      "y": -3,
      "z": -21,
      "name": "Rock_Quartzite_Brick"
    },
    {
      "x": -14,
      "y": -2,
      "z": -21,
      "name": "Rock_Quartzite_Brick"
    },
    {
      "x": -14,
      "y": -9,
      "z": -20,
      "name": "Rock_Stone"
    },
    {
      "x": -14,
      "y": -8,
      "z": -20,
      "name": "Rock_Stone"
    },
    {
      "x": -14,
      "y": -7,
      "z": -20,
      "name": "Rock_Stone_Cobble"
    },
    {
      "x": -14,
      "y": -6,
      "z": -20,
      "name": "Empty"
    },
    {
      "x": -14,
      "y": -5,
      "z": -20,
      "name": "Empty"
    },
    {
      "x": -14,
      "y": -4,
      "z": -20,
      "name": "Empty"
    },
    {
      "x": -14,
      "y": -3,
      "z": -20,
      "name": "Rock_Quartzite_Brick"
    },
    {
      "x": -14,
      "y": -2,
      "z": -20,
      "name": "Rock_Quartzite_Brick"
    },
    {
      "x": -14,
      "y": -8,
      "z": -19,
      "name": "Rock_Stone"
    },
    {
      "x": -14,
      "y": -7,
      "z": -19,
      "name": "Rock_Stone"
    },
    {
      "x": -14,
      "y": -6,
      "z": -19,
      "name": "Rock_Quartzite_Brick"
    },
    {
      "x": -14,
      "y": -5,
      "z": -19,
      "name": "Rock_Quartzite_Brick"
    },
    {
      "x": -14,
      "y": -4,
      "z": -19,
      "name": "Rock_Quartzite_Brick"
    },
    {
      "x": -14,
      "y": -3,
      "z": -19,
      "name": "Rock_Quartzite_Brick"
    },
    {
      "x": -14,
      "y": -8,
      "z": -18,
      "name": "Rock_Stone"
    },
    {
      "x": -14,
      "y": -7,
      "z": -18,
      "name": "Rock_Stone"
    },
    {
      "x": -13,
      "y": -8,
      "z": -24,
      "name": "Rock_Stone"
    },
    {
      "x": -13,
      "y": -7,
      "z": -24,
      "name": "Rock_Stone"
    },
    {
      "x": -13,
      "y": -8,
      "z": -23,
      "name": "Rock_Stone"
    },
    {
      "x": -13,
      "y": -7,
      "z": -23,
      "name": "Rock_Stone"
    },
    {
      "x": -13,
      "y": -6,
      "z": -23,
      "name": "Rock_Quartzite_Brick"
    },
    {
      "x": -13,
      "y": -5,
      "z": -23,
      "name": "Rock_Quartzite_Brick"
    },
    {
      "x": -13,
      "y": -4,
      "z": -23,
      "name": "Rock_Quartzite_Brick"
    },
    {
      "x": -13,
      "y": -3,
      "z": -23,
      "name": "Rock_Quartzite_Brick"
    },
    {
      "x": -13,
      "y": -2,
      "z": -23,
      "name": "Rock_Quartzite_Brick"
    },
    {
      "x": -13,
      "y": -9,
      "z": -22,
      "name": "Rock_Stone"
    },
    {
      "x": -13,
      "y": -8,
      "z": -22,
      "name": "Rock_Stone"
    },
    {
      "x": -13,
      "y": -7,
      "z": -22,
      "name": "Rock_Stone_Cobble"
    },
    {
      "x": -13,
      "y": -6,
      "z": -22,
      "name": "Furniture_Human_Ruins_Door_Medium",
      "filler": 960,
      "rotation": 1
    },
    {
      "x": -13,
      "y": -5,
      "z": -22,
      "name": "Furniture_Human_Ruins_Door_Medium",
      "filler": 1984,
      "rotation": 1
    },
    {
      "x": -13,
      "y": -4,
      "z": -22,
      "name": "Furniture_Human_Ruins_Door_Medium",
      "filler": 3008,
      "rotation": 1
    },
    {
      "x": -13,
      "y": -3,
      "z": -22,
      "name": "Rock_Quartzite_Brick_Ornate"
    },
    {
      "x": -13,
      "y": -2,
      "z": -22,
      "name": "Rock_Quartzite_Brick"
    },
    {
      "x": -13,
      "y": -9,
      "z": -21,
      "name": "Rock_Stone"
    },
    {
      "x": -13,
      "y": -8,
      "z": -21,
      "name": "Rock_Stone"
    },
    {
      "x": -13,
      "y": -7,
      "z": -21,
      "name": "Rock_Stone_Cobble"
    },
    {
      "x": -13,
      "y": -6,
      "z": -21,
      "name": "Furniture_Human_Ruins_Door_Medium",
      "filler": 992,
      "rotation": 1
    },
    {
      "x": -13,
      "y": -5,
      "z": -21,
      "name": "Furniture_Human_Ruins_Door_Medium",
      "filler": 2016,
      "rotation": 1
    },
    {
      "x": -13,
      "y": -4,
      "z": -21,
      "name": "Furniture_Human_Ruins_Door_Medium",
      "filler": 3040,
      "rotation": 1
    },
    {
      "x": -13,
      "y": -3,
      "z": -21,
      "name": "Rock_Quartzite_Brick_Ornate"
    },
    {
      "x": -13,
      "y": -2,
      "z": -21,
      "name": "Rock_Quartzite_Brick"
    },
    {
      "x": -13,
      "y": -9,
      "z": -20,
      "name": "Rock_Stone"
    },
    {
      "x": -13,
      "y": -8,
      "z": -20,
      "name": "Rock_Stone"
    },
    {
      "x": -13,
      "y": -7,
      "z": -20,
      "name": "Rock_Stone_Cobble"
    },
    {
      "x": -13,
      "y": -6,
      "z": -20,
      "name": "Furniture_Human_Ruins_Door_Medium",
      "rotation": 1
    },
    {
      "x": -13,
      "y": -5,
      "z": -20,
      "name": "Furniture_Human_Ruins_Door_Medium",
      "filler": 1024,
      "rotation": 1
    },
    {
      "x": -13,
      "y": -4,
      "z": -20,
      "name": "Furniture_Human_Ruins_Door_Medium",
      "filler": 2048,
      "rotation": 1
    },
    {
      "x": -13,
      "y": -3,
      "z": -20,
      "name": "Rock_Quartzite_Brick_Ornate"
    },
    {
      "x": -13,
      "y": -2,
      "z": -20,
      "name": "Rock_Quartzite_Brick"
    },
    {
      "x": -13,
      "y": -9,
      "z": -19,
      "name": "Rock_Stone"
    },
    {
      "x": -13,
      "y": -8,
      "z": -19,
      "name": "Rock_Stone"
    },
    {
      "x": -13,
      "y": -7,
      "z": -19,
      "name": "Rock_Stone"
    },
    {
      "x": -13,
      "y": -6,
      "z": -19,
      "name": "Rock_Quartzite_Brick"
    },
    {
      "x": -13,
      "y": -5,
      "z": -19,
      "name": "Rock_Quartzite_Brick"
    },
    {
      "x": -13,
      "y": -4,
      "z": -19,
      "name": "Rock_Quartzite_Brick"
    },
    {
      "x": -13,
      "y": -3,
      "z": -19,
      "name": "Rock_Quartzite_Brick"
    },
    {
      "x": -13,
      "y": -9,
      "z": -18,
      "name": "Rock_Stone"
    },
    {
      "x": -13,
      "y": -8,
      "z": -18,
      "name": "Rock_Stone"
    },
    {
      "x": -13,
      "y": -7,
      "z": -18,
      "name": "Rock_Stone"
    },
    {
      "x": -13,
      "y": -6,
      "z": -18,
      "name": "Rock_Stone"
    },
    {
      "x": -13,
      "y": -5,
      "z": -18,
      "name": "Rock_Quartzite_Brick"
    },
    {
      "x": -13,
      "y": -4,
      "z": -18,
      "name": "Rock_Quartzite_Brick"
    },
    {
      "x": -13,
      "y": -3,
      "z": -18,
      "name": "Rock_Quartzite_Brick"
    },
    {
      "x": -13,
      "y": -7,
      "z": -17,
      "name": "Rock_Stone"
    },
    {
      "x": -13,
      "y": -6,
      "z": -17,
      "name": "Rock_Stone"
    },
    {
      "x": -13,
      "y": -5,
      "z": -17,
      "name": "Rock_Quartzite_Brick"
    },
    {
      "x": -13,
      "y": -4,
      "z": -17,
      "name": "Rock_Quartzite_Brick"
    },
    {
      "x": -12,
      "y": -7,
      "z": -26,
      "name": "Rock_Stone"
    },
    {
      "x": -12,
      "y": -6,
      "z": -26,
      "name": "Rock_Stone"
    },
    {
      "x": -12,
      "y": -8,
      "z": -25,
      "name": "Rock_Stone"
    },
    {
      "x": -12,
      "y": -7,
      "z": -25,
      "name": "Rock_Stone"
    },
    {
      "x": -12,
      "y": -6,
      "z": -25,
      "name": "Rock_Stone"
    },
    {
      "x": -12,
      "y": -4,
      "z": -25,
      "name": "Empty"
    },
    {
      "x": -12,
      "y": -3,
      "z": -25,
      "name": "Empty"
    },
    {
      "x": -12,
      "y": -8,
      "z": -24,
      "name": "Rock_Stone"
    },
    {
      "x": -12,
      "y": -7,
      "z": -24,
      "name": "Rock_Stone"
    },
    {
      "x": -12,
      "y": -6,
      "z": -24,
      "name": "Rock_Quartzite_Brick"
    },
    {
      "x": -12,
      "y": -5,
      "z": -24,
      "name": "Rock_Quartzite_Brick"
    },
    {
      "x": -12,
      "y": -4,
      "z": -24,
      "name": "Rock_Quartzite_Brick"
    },
    {
      "x": -12,
      "y": -3,
      "z": -24,
      "name": "Rock_Quartzite_Brick"
    },
    {
      "x": -12,
      "y": -2,
      "z": -24,
      "name": "Rock_Quartzite_Brick"
    },
    {
      "x": -12,
      "y": -1,
      "z": -24,
      "name": "Rock_Quartzite_Brick"
    },
    {
      "x": -12,
      "y": 0,
      "z": -24,
      "name": "Rock_Quartzite_Brick"
    },
    {
      "x": -12,
      "y": 1,
      "z": -24,
      "name": "Rock_Quartzite_Brick"
    },
    {
      "x": -12,
      "y": 2,
      "z": -24,
      "name": "Rock_Quartzite_Brick"
    },
    {
      "x": -12,
      "y": -9,
      "z": -23,
      "name": "Rock_Stone"
    },
    {
      "x": -12,
      "y": -8,
      "z": -23,
      "name": "Rock_Stone"
    },
    {
      "x": -12,
      "y": -7,
      "z": -23,
      "name": "Rock_Stone"
    },
    {
      "x": -12,
      "y": -6,
      "z": -23,
      "name": "Rock_Quartzite_Brick"
    },
    {
      "x": -12,
      "y": -5,
      "z": -23,
      "name": "Rock_Quartzite_Brick"
    },
    {
      "x": -12,
      "y": -4,
      "z": -23,
      "name": "Rock_Quartzite_Brick"
    },
    {
      "x": -12,
      "y": -3,
      "z": -23,
      "name": "Rock_Quartzite_Brick"
    },
    {
      "x": -12,
      "y": -2,
      "z": -23,
      "name": "Rock_Quartzite_Brick"
    },
    {
      "x": -12,
      "y": -1,
      "z": -23,
      "name": "Rock_Quartzite_Brick"
    },
    {
      "x": -12,
      "y": 0,
      "z": -23,
      "name": "Rock_Quartzite_Brick"
    },
    {
      "x": -12,
      "y": 1,
      "z": -23,
      "name": "Rock_Quartzite_Brick"
    },
    {
      "x": -12,
      "y": 2,
      "z": -23,
      "name": "Rock_Quartzite_Brick"
    },
    {
      "x": -12,
      "y": 3,
      "z": -23,
      "name": "Rock_Quartzite_Brick"
    },
    {
      "x": -12,
      "y": 4,
      "z": -23,
      "name": "Rock_Quartzite_Brick"
    },
    {
      "x": -12,
      "y": 5,
      "z": -23,
      "name": "Rock_Quartzite_Brick"
    },
    {
      "x": -12,
      "y": -9,
      "z": -22,
      "name": "Rock_Stone"
    },
    {
      "x": -12,
      "y": -8,
      "z": -22,
      "name": "Rock_Stone"
    },
    {
      "x": -12,
      "y": -7,
      "z": -22,
      "name": "Rock_Stone_Cobble"
    },
    {
      "x": -12,
      "y": -6,
      "z": -22,
      "name": "Empty"
    },
    {
      "x": -12,
      "y": -5,
      "z": -22,
      "name": "Empty"
    },
    {
      "x": -12,
      "y": -4,
      "z": -22,
      "name": "Empty"
    },
    {
      "x": -12,
      "y": -3,
      "z": -22,
      "name": "Empty"
    },
    {
      "x": -12,
      "y": -2,
      "z": -22,
      "name": "Rock_Quartzite_Brick"
    },
    {
      "x": -12,
      "y": -1,
      "z": -22,
      "name": "Rock_Quartzite_Brick"
    },
    {
      "x": -12,
      "y": 0,
      "z": -22,
      "name": "Rock_Quartzite_Brick"
    },
    {
      "x": -12,
      "y": 1,
      "z": -22,
      "name": "Rock_Quartzite_Brick_Half",
      "rotation": 4
    },
    {
      "x": -12,
      "y": 2,
      "z": -22,
      "name": "Rock_Quartzite_Brick_Half",
      "rotation": 4
    },
    {
      "x": -12,
      "y": 3,
      "z": -22,
      "name": "Rock_Quartzite_Brick_Half",
      "rotation": 4
    },
    {
      "x": -12,
      "y": 4,
      "z": -22,
      "name": "Rock_Quartzite_Brick"
    },
    {
      "x": -12,
      "y": 5,
      "z": -22,
      "name": "Rock_Quartzite_Brick"
    },
    {
      "x": -12,
      "y": 6,
      "z": -22,
      "name": "Rock_Quartzite_Brick"
    },
    {
      "x": -12,
      "y": 7,
      "z": -22,
      "name": "Rock_Quartzite_Brick"
    },
    {
      "x": -12,
      "y": 8,
      "z": -22,
      "name": "Rock_Quartzite_Brick"
    },
    {
      "x": -12,
      "y": -9,
      "z": -21,
      "name": "Rock_Stone"
    },
    {
      "x": -12,
      "y": -8,
      "z": -21,
      "name": "Rock_Stone"
    },
    {
      "x": -12,
      "y": -7,
      "z": -21,
      "name": "Rock_Stone_Cobble"
    },
    {
      "x": -12,
      "y": -6,
      "z": -21,
      "name": "Empty"
    },
    {
      "x": -12,
      "y": -5,
      "z": -21,
      "name": "Empty"
    },
    {
      "x": -12,
      "y": -4,
      "z": -21,
      "name": "Empty"
    },
    {
      "x": -12,
      "y": -3,
      "z": -21,
      "name": "Empty"
    },
    {
      "x": -12,
      "y": -2,
      "z": -21,
      "name": "Rock_Quartzite_Brick"
    },
    {
      "x": -12,
      "y": -1,
      "z": -21,
      "name": "Rock_Quartzite_Brick"
    },
    {
      "x": -12,
      "y": 0,
      "z": -21,
      "name": "Rock_Quartzite_Brick"
    },
    {
      "x": -12,
      "y": 1,
      "z": -21,
      "name": "Empty"
    },
    {
      "x": -12,
      "y": 2,
      "z": -21,
      "name": "Empty"
    },
    {
      "x": -12,
      "y": 3,
      "z": -21,
      "name": "Empty"
    },
    {
      "x": -12,
      "y": 4,
      "z": -21,
      "name": "Rock_Quartzite_Brick_Half",
      "rotation": 8
    },
    {
      "x": -12,
      "y": 5,
      "z": -21,
      "name": "Rock_Quartzite_Brick"
    },
    {
      "x": -12,
      "y": 6,
      "z": -21,
      "name": "Rock_Quartzite_Brick"
    },
    {
      "x": -12,
      "y": 7,
      "z": -21,
      "name": "Rock_Quartzite_Brick"
    },
    {
      "x": -12,
      "y": 8,
      "z": -21,
      "name": "Rock_Quartzite_Brick"
    },
    {
      "x": -12,
      "y": -9,
      "z": -20,
      "name": "Rock_Stone"
    },
    {
      "x": -12,
      "y": -8,
      "z": -20,
      "name": "Rock_Stone"
    },
    {
      "x": -12,
      "y": -7,
      "z": -20,
      "name": "Rock_Stone_Cobble"
    },
    {
      "x": -12,
      "y": -6,
      "z": -20,
      "name": "Empty"
    },
    {
      "x": -12,
      "y": -5,
      "z": -20,
      "name": "Empty"
    },
    {
      "x": -12,
      "y": -4,
      "z": -20,
      "name": "Empty"
    },
    {
      "x": -12,
      "y": -3,
      "z": -20,
      "name": "Empty"
    },
    {
      "x": -12,
      "y": -2,
      "z": -20,
      "name": "Rock_Quartzite_Brick"
    },
    {
      "x": -12,
      "y": -1,
      "z": -20,
      "name": "Rock_Quartzite_Brick"
    },
    {
      "x": -12,
      "y": 0,
      "z": -20,
      "name": "Rock_Quartzite_Brick"
    },
    {
      "x": -12,
      "y": 1,
      "z": -20,
      "name": "Rock_Quartzite_Brick_Half",
      "rotation": 6
    },
    {
      "x": -12,
      "y": 2,
      "z": -20,
      "name": "Rock_Quartzite_Brick_Half",
      "rotation": 6
    },
    {
      "x": -12,
      "y": 3,
      "z": -20,
      "name": "Rock_Quartzite_Brick_Half",
      "rotation": 6
    },
    {
      "x": -12,
      "y": 4,
      "z": -20,
      "name": "Rock_Quartzite_Brick"
    },
    {
      "x": -12,
      "y": 5,
      "z": -20,
      "name": "Rock_Quartzite_Brick"
    },
    {
      "x": -12,
      "y": 6,
      "z": -20,
      "name": "Rock_Quartzite_Brick"
    },
    {
      "x": -12,
      "y": -9,
      "z": -19,
      "name": "Rock_Stone"
    },
    {
      "x": -12,
      "y": -8,
      "z": -19,
      "name": "Rock_Stone"
    },
    {
      "x": -12,
      "y": -7,
      "z": -19,
      "name": "Rock_Stone"
    },
    {
      "x": -12,
      "y": -6,
      "z": -19,
      "name": "Rock_Quartzite_Brick"
    },
    {
      "x": -12,
      "y": -5,
      "z": -19,
      "name": "Rock_Quartzite_Brick"
    },
    {
      "x": -12,
      "y": -4,
      "z": -19,
      "name": "Rock_Quartzite_Brick"
    },
    {
      "x": -12,
      "y": -3,
      "z": -19,
      "name": "Rock_Quartzite_Brick"
    },
    {
      "x": -12,
      "y": -2,
      "z": -19,
      "name": "Rock_Quartzite_Brick"
    },
    {
      "x": -12,
      "y": -1,
      "z": -19,
      "name": "Rock_Quartzite_Brick"
    },
    {
      "x": -12,
      "y": 0,
      "z": -19,
      "name": "Rock_Quartzite_Brick"
    },
    {
      "x": -12,
      "y": 1,
      "z": -19,
      "name": "Rock_Quartzite_Brick"
    },
    {
      "x": -12,
      "y": 2,
      "z": -19,
      "name": "Rock_Quartzite_Brick"
    },
    {
      "x": -12,
      "y": 3,
      "z": -19,
      "name": "Rock_Quartzite_Brick"
    },
    {
      "x": -12,
      "y": 4,
      "z": -19,
      "name": "Rock_Quartzite_Brick"
    },
    {
      "x": -12,
      "y": -9,
      "z": -18,
      "name": "Rock_Stone"
    },
    {
      "x": -12,
      "y": -8,
      "z": -18,
      "name": "Rock_Stone"
    },
    {
      "x": -12,
      "y": -7,
      "z": -18,
      "name": "Rock_Stone"
    },
    {
      "x": -12,
      "y": -6,
      "z": -18,
      "name": "Rock_Quartzite_Brick"
    },
    {
      "x": -12,
      "y": -5,
      "z": -18,
      "name": "Rock_Quartzite_Brick"
    },
    {
      "x": -12,
      "y": -4,
      "z": -18,
      "name": "Rock_Quartzite_Brick"
    },
    {
      "x": -12,
      "y": -3,
      "z": -18,
      "name": "Rock_Quartzite_Brick"
    },
    {
      "x": -12,
      "y": -2,
      "z": -18,
      "name": "Rock_Quartzite_Brick"
    },
    {
      "x": -12,
      "y": -1,
      "z": -18,
      "name": "Rock_Quartzite_Brick"
    },
    {
      "x": -12,
      "y": 0,
      "z": -18,
      "name": "Rock_Quartzite_Brick"
    },
    {
      "x": -12,
      "y": 1,
      "z": -18,
      "name": "Rock_Quartzite_Brick"
    },
    {
      "x": -12,
      "y": -9,
      "z": -17,
      "name": "Rock_Stone"
    },
    {
      "x": -12,
      "y": -8,
      "z": -17,
      "name": "Rock_Stone"
    },
    {
      "x": -12,
      "y": -7,
      "z": -17,
      "name": "Rock_Stone"
    },
    {
      "x": -12,
      "y": -6,
      "z": -17,
      "name": "Rock_Quartzite_Brick"
    },
    {
      "x": -12,
      "y": -5,
      "z": -17,
      "name": "Rock_Quartzite_Brick"
    },
    {
      "x": -12,
      "y": -4,
      "z": -17,
      "name": "Rock_Quartzite_Brick"
    },
    {
      "x": -12,
      "y": -3,
      "z": -17,
      "name": "Rock_Quartzite_Brick"
    },
    {
      "x": -12,
      "y": -2,
      "z": -17,
      "name": "Rock_Quartzite_Brick_Smooth"
    },
    {
      "x": -12,
      "y": -1,
      "z": -17,
      "name": "Rock_Quartzite_Brick_Smooth"
    },
    {
      "x": -12,
      "y": 0,
      "z": -17,
      "name": "Rock_Quartzite_Brick"
    },
    {
      "x": -12,
      "y": -9,
      "z": -16,
      "name": "Rock_Stone"
    },
    {
      "x": -12,
      "y": -8,
      "z": -16,
      "name": "Rock_Stone"
    },
    {
      "x": -12,
      "y": -7,
      "z": -16,
      "name": "Rock_Stone"
    },
    {
      "x": -12,
      "y": -6,
      "z": -16,
      "name": "Rock_Quartzite_Brick"
    },
    {
      "x": -12,
      "y": -5,
      "z": -16,
      "name": "Rock_Quartzite_Brick"
    },
    {
      "x": -12,
      "y": -4,
      "z": -16,
      "name": "Rock_Quartzite_Brick"
    },
    {
      "x": -12,
      "y": -3,
      "z": -16,
      "name": "Rock_Quartzite_Brick"
    },
    {
      "x": -12,
      "y": -2,
      "z": -16,
      "name": "Rock_Quartzite_Brick_Smooth"
    },
    {
      "x": -12,
      "y": -9,
      "z": -15,
      "name": "Rock_Stone"
    },
    {
      "x": -12,
      "y": -8,
      "z": -15,
      "name": "Rock_Stone"
    },
    {
      "x": -12,
      "y": -7,
      "z": -15,
      "name": "Rock_Stone"
    },
    {
      "x": -12,
      "y": -5,
      "z": -15,
      "name": "Rock_Quartzite_Brick"
    },
    {
      "x": -12,
      "y": -4,
      "z": -15,
      "name": "Empty"
    },
    {
      "x": -12,
      "y": -3,
      "z": -15,
      "name": "Rock_Quartzite_Brick_Half",
      "rotation": 4
    },
    {
      "x": -12,
      "y": -8,
      "z": -14,
      "name": "Rock_Stone"
    },
    {
      "x": -12,
      "y": -5,
      "z": -14,
      "name": "Empty"
    },
    {
      "x": -12,
      "y": -4,
      "z": -14,
      "name": "Empty"
    },
    {
      "x": -12,
      "y": -8,
      "z": -11,
      "name": "Rock_Stone"
    },
    {
      "x": -12,
      "y": -7,
      "z": -11,
      "name": "Rock_Stone"
    },
    {
      "x": -12,
      "y": -5,
      "z": -11,
      "name": "Empty"
    },
    {
      "x": -12,
      "y": -4,
      "z": -11,
      "name": "Empty"
    },
    {
      "x": -12,
      "y": -3,
      "z": -11,
      "name": "Empty"
    },
    {
      "x": -12,
      "y": -9,
      "z": -10,
      "name": "Rock_Stone"
    },
    {
      "x": -12,
      "y": -8,
      "z": -10,
      "name": "Rock_Stone"
    },
    {
      "x": -12,
      "y": -7,
      "z": -10,
      "name": "Rock_Stone"
    },
    {
      "x": -12,
      "y": -6,
      "z": -10,
      "name": "Rock_Stone"
    },
    {
      "x": -12,
      "y": -5,
      "z": -10,
      "name": "Empty"
    },
    {
      "x": -12,
      "y": -4,
      "z": -10,
      "name": "Empty"
    },
    {
      "x": -12,
      "y": -3,
      "z": -10,
      "name": "Empty"
    },
    {
      "x": -12,
      "y": -2,
      "z": -10,
      "name": "Empty"
    },
    {
      "x": -12,
      "y": -8,
      "z": -9,
      "name": "Rock_Stone"
    },
    {
      "x": -12,
      "y": -7,
      "z": -9,
      "name": "Rock_Stone"
    },
    {
      "x": -12,
      "y": -6,
      "z": -9,
      "name": "Rock_Stone"
    },
    {
      "x": -12,
      "y": -5,
      "z": -9,
      "name": "Empty"
    },
    {
      "x": -12,
      "y": -4,
      "z": -9,
      "name": "Empty"
    },
    {
      "x": -12,
      "y": -8,
      "z": -8,
      "name": "Rock_Stone"
    },
    {
      "x": -12,
      "y": -7,
      "z": -8,
      "name": "Rock_Stone"
    },
    {
      "x": -12,
      "y": -6,
      "z": -8,
      "name": "Rock_Stone"
    },
    {
      "x": -12,
      "y": -5,
      "z": -8,
      "name": "Rock_Stone"
    },
    {
      "x": -12,
      "y": -8,
      "z": -7,
      "name": "Rock_Stone"
    },
    {
      "x": -12,
      "y": -7,
      "z": -7,
      "name": "Rock_Stone"
    },
    {
      "x": -12,
      "y": -6,
      "z": -7,
      "name": "Rock_Stone"
    },
    {
      "x": -12,
      "y": -5,
      "z": -7,
      "name": "Rock_Stone"
    },
    {
      "x": -12,
      "y": -7,
      "z": -6,
      "name": "Rock_Stone"
    },
    {
      "x": -12,
      "y": -6,
      "z": -6,
      "name": "Rock_Stone"
    },
    {
      "x": -12,
      "y": -5,
      "z": -6,
      "name": "Rock_Stone"
    },
    {
      "x": -12,
      "y": -7,
      "z": -5,
      "name": "Rock_Stone"
    },
    {
      "x": -12,
      "y": -6,
      "z": -5,
      "name": "Rock_Stone"
    },
    {
      "x": -11,
      "y": -8,
      "z": -27,
      "name": "Rock_Stone"
    },
    {
      "x": -11,
      "y": -7,
      "z": -27,
      "name": "Rock_Stone"
    },
    {
      "x": -11,
      "y": -6,
      "z": -27,
      "name": "Rock_Stone"
    },
    {
      "x": -11,
      "y": -8,
      "z": -26,
      "name": "Rock_Stone"
    },
    {
      "x": -11,
      "y": -7,
      "z": -26,
      "name": "Rock_Stone"
    },
    {
      "x": -11,
      "y": -6,
      "z": -26,
      "name": "Rock_Stone"
    },
    {
      "x": -11,
      "y": -9,
      "z": -25,
      "name": "Rock_Stone"
    },
    {
      "x": -11,
      "y": -8,
      "z": -25,
      "name": "Rock_Stone"
    },
    {
      "x": -11,
      "y": -7,
      "z": -25,
      "name": "Rock_Stone"
    },
    {
      "x": -11,
      "y": -6,
      "z": -25,
      "name": "Rock_Stone"
    },
    {
      "x": -11,
      "y": -5,
      "z": -25,
      "name": "Empty"
    },
    {
      "x": -11,
      "y": -4,
      "z": -25,
      "name": "Empty"
    },
    {
      "x": -11,
      "y": -3,
      "z": -25,
      "name": "Empty"
    },
    {
      "x": -11,
      "y": -2,
      "z": -25,
      "name": "Empty"
    },
    {
      "x": -11,
      "y": -1,
      "z": -25,
      "name": "Empty"
    },
    {
      "x": -11,
      "y": 0,
      "z": -25,
      "name": "Empty"
    },
    {
      "x": -11,
      "y": -9,
      "z": -24,
      "name": "Rock_Stone"
    },
    {
      "x": -11,
      "y": -8,
      "z": -24,
      "name": "Rock_Stone"
    },
    {
      "x": -11,
      "y": -7,
      "z": -24,
      "name": "Rock_Stone"
    },
    {
      "x": -11,
      "y": -6,
      "z": -24,
      "name": "Plant_Crop_Mushroom_Glowing_Orange"
    },
    {
      "x": -11,
      "y": -5,
      "z": -24,
      "name": "Empty"
    },
    {
      "x": -11,
      "y": -4,
      "z": -24,
      "name": "Empty"
    },
    {
      "x": -11,
      "y": -3,
      "z": -24,
      "name": "Empty"
    },
    {
      "x": -11,
      "y": -2,
      "z": -24,
      "name": "Rock_Quartzite_Brick_Smooth"
    },
    {
      "x": -11,
      "y": -1,
      "z": -24,
      "name": "Rock_Quartzite_Brick_Smooth"
    },
    {
      "x": -11,
      "y": 0,
      "z": -24,
      "name": "Empty"
    },
    {
      "x": -11,
      "y": 1,
      "z": -24,
      "name": "Rock_Stone_Stalactite_Small",
      "rotation": 8
    },
    {
      "x": -11,
      "y": -9,
      "z": -23,
      "name": "Rock_Stone"
    },
    {
      "x": -11,
      "y": -8,
      "z": -23,
      "name": "Rock_Stone"
    },
    {
      "x": -11,
      "y": -7,
      "z": -23,
      "name": "Rock_Stone"
    },
    {
      "x": -11,
      "y": -6,
      "z": -23,
      "name": "Rock_Quartzite_Brick_Pillar_Base"
    },
    {
      "x": -11,
      "y": -5,
      "z": -23,
      "name": "Rock_Quartzite_Brick_Pillar_Middle"
    },
    {
      "x": -11,
      "y": -4,
      "z": -23,
      "name": "Rock_Quartzite_Brick_Pillar_Middle"
    },
    {
      "x": -11,
      "y": -3,
      "z": -23,
      "name": "Rock_Quartzite_Brick_Pillar_Base",
      "rotation": 8
    },
    {
      "x": -11,
      "y": -2,
      "z": -23,
      "name": "Rock_Quartzite_Brick_Smooth"
    },
    {
      "x": -11,
      "y": -1,
      "z": -23,
      "name": "Rock_Quartzite_Brick"
    },
    {
      "x": -11,
      "y": 0,
      "z": -23,
      "name": "Rock_Quartzite_Brick_Wall"
    },
    {
      "x": -11,
      "y": 1,
      "z": -23,
      "name": "Empty"
    },
    {
      "x": -11,
      "y": 2,
      "z": -23,
      "name": "Empty"
    },
    {
      "x": -11,
      "y": 3,
      "z": -23,
      "name": "Empty"
    },
    {
      "x": -11,
      "y": 4,
      "z": -23,
      "name": "Empty"
    },
    {
      "x": -11,
      "y": 5,
      "z": -23,
      "name": "Empty"
    },
    {
      "x": -11,
      "y": -9,
      "z": -22,
      "name": "Rock_Stone"
    },
    {
      "x": -11,
      "y": -8,
      "z": -22,
      "name": "Rock_Stone"
    },
    {
      "x": -11,
      "y": -7,
      "z": -22,
      "name": "Rock_Stone_Cobble"
    },
    {
      "x": -11,
      "y": -6,
      "z": -22,
      "name": "Empty"
    },
    {
      "x": -11,
      "y": -5,
      "z": -22,
      "name": "Empty"
    },
    {
      "x": -11,
      "y": -4,
      "z": -22,
      "name": "Empty"
    },
    {
      "x": -11,
      "y": -3,
      "z": -22,
      "name": "Empty"
    },
    {
      "x": -11,
      "y": -2,
      "z": -22,
      "name": "Rock_Quartzite_Brick_Smooth"
    },
    {
      "x": -11,
      "y": -1,
      "z": -22,
      "name": "Rock_Quartzite_Brick"
    },
    {
      "x": -11,
      "y": 0,
      "z": -22,
      "name": "Empty"
    },
    {
      "x": -11,
      "y": 1,
      "z": -22,
      "name": "Empty"
    },
    {
      "x": -11,
      "y": 2,
      "z": -22,
      "name": "Empty"
    },
    {
      "x": -11,
      "y": 3,
      "z": -22,
      "name": "Empty"
    },
    {
      "x": -11,
      "y": 4,
      "z": -22,
      "name": "Empty"
    },
    {
      "x": -11,
      "y": 5,
      "z": -22,
      "name": "Empty"
    },
    {
      "x": -11,
      "y": 6,
      "z": -22,
      "name": "Empty"
    },
    {
      "x": -11,
      "y": 7,
      "z": -22,
      "name": "Empty"
    },
    {
      "x": -11,
      "y": 8,
      "z": -22,
      "name": "Empty"
    },
    {
      "x": -11,
      "y": -9,
      "z": -21,
      "name": "Rock_Stone"
    },
    {
      "x": -11,
      "y": -8,
      "z": -21,
      "name": "Rock_Stone"
    },
    {
      "x": -11,
      "y": -7,
      "z": -21,
      "name": "Rock_Stone_Cobble"
    },
    {
      "x": -11,
      "y": -6,
      "z": -21,
      "name": "Empty"
    },
    {
      "x": -11,
      "y": -5,
      "z": -21,
      "name": "Empty"
    },
    {
      "x": -11,
      "y": -4,
      "z": -21,
      "name": "Empty"
    },
    {
      "x": -11,
      "y": -3,
      "z": -21,
      "name": "Empty"
    },
    {
      "x": -11,
      "y": -2,
      "z": -21,
      "name": "Rock_Quartzite_Brick_Smooth"
    },
    {
      "x": -11,
      "y": -1,
      "z": -21,
      "name": "Rock_Quartzite_Brick"
    },
    {
      "x": -11,
      "y": 0,
      "z": -21,
      "name": "Block_Spawner_Block",
      "components": {
        "Components": {
          "BlockSpawner": {
            "BlockSpawnerId": "Zone1_Encounters_Tier3"
          }
        }
      },
      "rotation": 1
    },
    {
      "x": -11,
      "y": 1,
      "z": -21,
      "name": "Empty"
    },
    {
      "x": -11,
      "y": 2,
      "z": -21,
      "name": "Empty"
    },
    {
      "x": -11,
      "y": 3,
      "z": -21,
      "name": "Empty"
    },
    {
      "x": -11,
      "y": 4,
      "z": -21,
      "name": "Empty"
    },
    {
      "x": -11,
      "y": 5,
      "z": -21,
      "name": "Empty"
    },
    {
      "x": -11,
      "y": 6,
      "z": -21,
      "name": "Empty"
    },
    {
      "x": -11,
      "y": -10,
      "z": -20,
      "name": "Rock_Stone"
    },
    {
      "x": -11,
      "y": -9,
      "z": -20,
      "name": "Rock_Stone"
    },
    {
      "x": -11,
      "y": -8,
      "z": -20,
      "name": "Rock_Stone"
    },
    {
      "x": -11,
      "y": -7,
      "z": -20,
      "name": "Rock_Stone_Cobble"
    },
    {
      "x": -11,
      "y": -6,
      "z": -20,
      "name": "Empty"
    },
    {
      "x": -11,
      "y": -5,
      "z": -20,
      "name": "Empty"
    },
    {
      "x": -11,
      "y": -4,
      "z": -20,
      "name": "Empty"
    },
    {
      "x": -11,
      "y": -3,
      "z": -20,
      "name": "Empty"
    },
    {
      "x": -11,
      "y": -2,
      "z": -20,
      "name": "Rock_Quartzite_Brick_Smooth"
    },
    {
      "x": -11,
      "y": -1,
      "z": -20,
      "name": "Rock_Quartzite_Brick"
    },
    {
      "x": -11,
      "y": 0,
      "z": -20,
      "name": "Plant_Crop_Mushroom_Glowing_Orange"
    },
    {
      "x": -11,
      "y": 1,
      "z": -20,
      "name": "Empty"
    },
    {
      "x": -11,
      "y": 2,
      "z": -20,
      "name": "Empty"
    },
    {
      "x": -11,
      "y": 3,
      "z": -20,
      "name": "Empty"
    },
    {
      "x": -11,
      "y": 4,
      "z": -20,
      "name": "Empty"
    },
    {
      "x": -11,
      "y": 5,
      "z": -20,
      "name": "Empty"
    },
    {
      "x": -11,
      "y": -10,
      "z": -19,
      "name": "Rock_Stone"
    },
    {
      "x": -11,
      "y": -9,
      "z": -19,
      "name": "Rock_Stone"
    },
    {
      "x": -11,
      "y": -8,
      "z": -19,
      "name": "Rock_Stone"
    },
    {
      "x": -11,
      "y": -7,
      "z": -19,
      "name": "Rock_Stone"
    },
    {
      "x": -11,
      "y": -6,
      "z": -19,
      "name": "Rock_Quartzite_Brick_Pillar_Base"
    },
    {
      "x": -11,
      "y": -5,
      "z": -19,
      "name": "Rock_Quartzite_Brick_Pillar_Middle"
    },
    {
      "x": -11,
      "y": -4,
      "z": -19,
      "name": "Rock_Quartzite_Brick_Pillar_Middle"
    },
    {
      "x": -11,
      "y": -3,
      "z": -19,
      "name": "Rock_Quartzite_Brick_Pillar_Base",
      "rotation": 8
    },
    {
      "x": -11,
      "y": -2,
      "z": -19,
      "name": "Rock_Quartzite_Brick_Smooth"
    },
    {
      "x": -11,
      "y": -1,
      "z": -19,
      "name": "Rock_Quartzite_Brick"
    },
    {
      "x": -11,
      "y": 0,
      "z": -19,
      "name": "Rock_Quartzite_Brick_Wall"
    },
    {
      "x": -11,
      "y": 1,
      "z": -19,
      "name": "Empty"
    },
    {
      "x": -11,
      "y": 2,
      "z": -19,
      "name": "Empty"
    },
    {
      "x": -11,
      "y": 3,
      "z": -19,
      "name": "Empty"
    },
    {
      "x": -11,
      "y": -10,
      "z": -18,
      "name": "Rock_Stone"
    },
    {
      "x": -11,
      "y": -9,
      "z": -18,
      "name": "Rock_Stone"
    },
    {
      "x": -11,
      "y": -8,
      "z": -18,
      "name": "Rock_Stone"
    },
    {
      "x": -11,
      "y": -7,
      "z": -18,
      "name": "Rock_Stone"
    },
    {
      "x": -11,
      "y": -6,
      "z": -18,
      "name": "Empty"
    },
    {
      "x": -11,
      "y": -5,
      "z": -18,
      "name": "Empty"
    },
    {
      "x": -11,
      "y": -4,
      "z": -18,
      "name": "Empty"
    },
    {
      "x": -11,
      "y": -3,
      "z": -18,
      "name": "Empty"
    },
    {
      "x": -11,
      "y": -2,
      "z": -18,
      "name": "Rock_Quartzite_Brick_Smooth"
    },
    {
      "x": -11,
      "y": -1,
      "z": -18,
      "name": "Rock_Quartzite_Brick_Smooth"
    },
    {
      "x": -11,
      "y": 0,
      "z": -18,
      "name": "Empty"
    },
    {
      "x": -11,
      "y": 1,
      "z": -18,
      "name": "Empty"
    },
    {
      "x": -11,
      "y": -11,
      "z": -17,
      "name": "Rock_Stone"
    },
    {
      "x": -11,
      "y": -10,
      "z": -17,
      "name": "Rock_Stone"
    },
    {
      "x": -11,
      "y": -9,
      "z": -17,
      "name": "Rock_Stone"
    },
    {
      "x": -11,
      "y": -8,
      "z": -17,
      "name": "Rock_Stone"
    },
    {
      "x": -11,
      "y": -7,
      "z": -17,
      "name": "Rock_Stone"
    },
    {
      "x": -11,
      "y": -6,
      "z": -17,
      "name": "Empty"
    },
    {
      "x": -11,
      "y": -5,
      "z": -17,
      "name": "Empty"
    },
    {
      "x": -11,
      "y": -4,
      "z": -17,
      "name": "Empty"
    },
    {
      "x": -11,
      "y": -3,
      "z": -17,
      "name": "Empty"
    },
    {
      "x": -11,
      "y": -2,
      "z": -17,
      "name": "Rock_Quartzite_Brick_Smooth_Half",
      "rotation": 5
    },
    {
      "x": -11,
      "y": -1,
      "z": -17,
      "name": "Rock_Quartzite_Brick_Smooth_Half",
      "rotation": 5
    },
    {
      "x": -11,
      "y": 0,
      "z": -17,
      "name": "Empty"
    },
    {
      "x": -11,
      "y": 1,
      "z": -17,
      "name": "Empty"
    },
    {
      "x": -11,
      "y": -11,
      "z": -16,
      "name": "Rock_Stone"
    },
    {
      "x": -11,
      "y": -10,
      "z": -16,
      "name": "Rock_Stone"
    },
    {
      "x": -11,
      "y": -9,
      "z": -16,
      "name": "Rock_Stone"
    },
    {
      "x": -11,
      "y": -8,
      "z": -16,
      "name": "Rock_Quartzite_Brick"
    },
    {
      "x": -11,
      "y": -7,
      "z": -16,
      "name": "Rock_Quartzite_Brick"
    },
    {
      "x": -11,
      "y": -6,
      "z": -16,
      "name": "Rock_Quartzite_Brick"
    },
    {
      "x": -11,
      "y": -5,
      "z": -16,
      "name": "Rock_Quartzite_Brick"
    },
    {
      "x": -11,
      "y": -4,
      "z": -16,
      "name": "Empty"
    },
    {
      "x": -11,
      "y": -3,
      "z": -16,
      "name": "Empty"
    },
    {
      "x": -11,
      "y": -2,
      "z": -16,
      "name": "Rock_Quartzite_Brick_Smooth_Half",
      "rotation": 5
    },
    {
      "x": -11,
      "y": -1,
      "z": -16,
      "name": "Empty"
    },
    {
      "x": -11,
      "y": 0,
      "z": -16,
      "name": "Empty"
    },
    {
      "x": -11,
      "y": -11,
      "z": -15,
      "name": "Rock_Stone"
    },
    {
      "x": -11,
      "y": -10,
      "z": -15,
      "name": "Rock_Stone"
    },
    {
      "x": -11,
      "y": -9,
      "z": -15,
      "name": "Rock_Stone"
    },
    {
      "x": -11,
      "y": -8,
      "z": -15,
      "name": "Rock_Quartzite_Brick"
    },
    {
      "x": -11,
      "y": -7,
      "z": -15,
      "name": "Rock_Quartzite_Brick"
    },
    {
      "x": -11,
      "y": -6,
      "z": -15,
      "name": "Rock_Quartzite_Brick"
    },
    {
      "x": -11,
      "y": -5,
      "z": -15,
      "name": "Rock_Quartzite_Brick"
    },
    {
      "x": -11,
      "y": -4,
      "z": -15,
      "name": "Empty"
    },
    {
      "x": -11,
      "y": -3,
      "z": -15,
      "name": "Empty"
    },
    {
      "x": -11,
      "y": -2,
      "z": -15,
      "name": "Empty"
    },
    {
      "x": -11,
      "y": -1,
      "z": -15,
      "name": "Empty"
    },
    {
      "x": -11,
      "y": -10,
      "z": -14,
      "name": "Rock_Stone"
    },
    {
      "x": -11,
      "y": -9,
      "z": -14,
      "name": "Rock_Stone"
    },
    {
      "x": -11,
      "y": -8,
      "z": -14,
      "name": "Rock_Quartzite_Brick"
    },
    {
      "x": -11,
      "y": -7,
      "z": -14,
      "name": "Rock_Quartzite_Brick"
    },
    {
      "x": -11,
      "y": -6,
      "z": -14,
      "name": "Rock_Quartzite_Brick"
    },
    {
      "x": -11,
      "y": -5,
      "z": -14,
      "name": "Empty"
    },
    {
      "x": -11,
      "y": -4,
      "z": -14,
      "name": "Empty"
    },
    {
      "x": -11,
      "y": -3,
      "z": -14,
      "name": "Empty"
    },
    {
      "x": -11,
      "y": -2,
      "z": -14,
      "name": "Empty"
    },
    {
      "x": -11,
      "y": -10,
      "z": -13,
      "name": "Rock_Stone"
    },
    {
      "x": -11,
      "y": -9,
      "z": -13,
      "name": "Rock_Stone"
    },
    {
      "x": -11,
      "y": -8,
      "z": -13,
      "name": "Rock_Stone"
    },
    {
      "x": -11,
      "y": -7,
      "z": -13,
      "name": "Rock_Stone"
    },
    {
      "x": -11,
      "y": -5,
      "z": -13,
      "name": "Empty"
    },
    {
      "x": -11,
      "y": -4,
      "z": -13,
      "name": "Empty"
    },
    {
      "x": -11,
      "y": -3,
      "z": -13,
      "name": "Empty"
    },
    {
      "x": -11,
      "y": -10,
      "z": -12,
      "name": "Rock_Stone"
    },
    {
      "x": -11,
      "y": -9,
      "z": -12,
      "name": "Rock_Stone"
    },
    {
      "x": -11,
      "y": -8,
      "z": -12,
      "name": "Rock_Stone"
    },
    {
      "x": -11,
      "y": -7,
      "z": -12,
      "name": "Rock_Stone"
    },
    {
      "x": -11,
      "y": -6,
      "z": -12,
      "name": "Rock_Stone"
    },
    {
      "x": -11,
      "y": -5,
      "z": -12,
      "name": "Empty"
    },
    {
      "x": -11,
      "y": -4,
      "z": -12,
      "name": "Empty"
    },
    {
      "x": -11,
      "y": -3,
      "z": -12,
      "name": "Empty"
    },
    {
      "x": -11,
      "y": -2,
      "z": -12,
      "name": "Empty"
    },
    {
      "x": -11,
      "y": -9,
      "z": -11,
      "name": "Rock_Stone"
    },
    {
      "x": -11,
      "y": -8,
      "z": -11,
      "name": "Rock_Stone"
    },
    {
      "x": -11,
      "y": -7,
      "z": -11,
      "name": "Rock_Stone"
    },
    {
      "x": -11,
      "y": -6,
      "z": -11,
      "name": "Rock_Stone"
    },
    {
      "x": -11,
      "y": -5,
      "z": -11,
      "name": "Empty"
    },
    {
      "x": -11,
      "y": -4,
      "z": -11,
      "name": "Empty"
    },
    {
      "x": -11,
      "y": -3,
      "z": -11,
      "name": "Empty"
    },
    {
      "x": -11,
      "y": -2,
      "z": -11,
      "name": "Empty"
    },
    {
      "x": -11,
      "y": -1,
      "z": -11,
      "name": "Empty"
    },
    {
      "x": -11,
      "y": 0,
      "z": -11,
      "name": "Empty"
    },
    {
      "x": -11,
      "y": -9,
      "z": -10,
      "name": "Rock_Stone"
    },
    {
      "x": -11,
      "y": -8,
      "z": -10,
      "name": "Rock_Stone"
    },
    {
      "x": -11,
      "y": -7,
      "z": -10,
      "name": "Rock_Stone"
    },
    {
      "x": -11,
      "y": -6,
      "z": -10,
      "name": "Empty"
    },
    {
      "x": -11,
      "y": -5,
      "z": -10,
      "name": "Empty"
    },
    {
      "x": -11,
      "y": -4,
      "z": -10,
      "name": "Empty"
    },
    {
      "x": -11,
      "y": -3,
      "z": -10,
      "name": "Empty"
    },
    {
      "x": -11,
      "y": -2,
      "z": -10,
      "name": "Empty"
    },
    {
      "x": -11,
      "y": -1,
      "z": -10,
      "name": "Empty"
    },
    {
      "x": -11,
      "y": 0,
      "z": -10,
      "name": "Empty"
    },
    {
      "x": -11,
      "y": -9,
      "z": -9,
      "name": "Rock_Stone"
    },
    {
      "x": -11,
      "y": -8,
      "z": -9,
      "name": "Rock_Stone"
    },
    {
      "x": -11,
      "y": -7,
      "z": -9,
      "name": "Rock_Stone"
    },
    {
      "x": -11,
      "y": -6,
      "z": -9,
      "name": "Plant_Moss_Block_Blue"
    },
    {
      "x": -11,
      "y": -5,
      "z": -9,
      "name": "Empty"
    },
    {
      "x": -11,
      "y": -4,
      "z": -9,
      "name": "Empty"
    },
    {
      "x": -11,
      "y": -3,
      "z": -9,
      "name": "Empty"
    },
    {
      "x": -11,
      "y": -2,
      "z": -9,
      "name": "Empty"
    },
    {
      "x": -11,
      "y": -1,
      "z": -9,
      "name": "Empty"
    },
    {
      "x": -11,
      "y": 0,
      "z": -9,
      "name": "Empty"
    },
    {
      "x": -11,
      "y": -9,
      "z": -8,
      "name": "Rock_Stone"
    },
    {
      "x": -11,
      "y": -8,
      "z": -8,
      "name": "Rock_Stone"
    },
    {
      "x": -11,
      "y": -7,
      "z": -8,
      "name": "Rock_Stone"
    },
    {
      "x": -11,
      "y": -6,
      "z": -8,
      "name": "Plant_Moss_Block_Blue"
    },
    {
      "x": -11,
      "y": -5,
      "z": -8,
      "name": "Plant_Moss_Rug_Blue"
    },
    {
      "x": -11,
      "y": -4,
      "z": -8,
      "name": "Empty"
    },
    {
      "x": -11,
      "y": -3,
      "z": -8,
      "name": "Empty"
    },
    {
      "x": -11,
      "y": -2,
      "z": -8,
      "name": "Empty"
    },
    {
      "x": -11,
      "y": -1,
      "z": -8,
      "name": "Empty"
    },
    {
      "x": -11,
      "y": 0,
      "z": -8,
      "name": "Empty"
    },
    {
      "x": -11,
      "y": -8,
      "z": -7,
      "name": "Rock_Stone"
    },
    {
      "x": -11,
      "y": -7,
      "z": -7,
      "name": "Rock_Stone"
    },
    {
      "x": -11,
      "y": -6,
      "z": -7,
      "name": "Plant_Moss_Block_Blue"
    },
    {
      "x": -11,
      "y": -5,
      "z": -7,
      "name": "Plant_Moss_Block_Blue"
    },
    {
      "x": -11,
      "y": -4,
      "z": -7,
      "name": "Empty"
    },
    {
      "x": -11,
      "y": -3,
      "z": -7,
      "name": "Empty"
    },
    {
      "x": -11,
      "y": -2,
      "z": -7,
      "name": "Empty"
    },
    {
      "x": -11,
      "y": -1,
      "z": -7,
      "name": "Empty"
    },
    {
      "x": -11,
      "y": -8,
      "z": -6,
      "name": "Rock_Stone"
    },
    {
      "x": -11,
      "y": -7,
      "z": -6,
      "name": "Rock_Stone"
    },
    {
      "x": -11,
      "y": -6,
      "z": -6,
      "name": "Rock_Stone"
    },
    {
      "x": -11,
      "y": -5,
      "z": -6,
      "name": "Plant_Moss_Block_Blue"
    },
    {
      "x": -11,
      "y": -4,
      "z": -6,
      "name": "Plant_Moss_Rug_Blue"
    },
    {
      "x": -11,
      "y": -7,
      "z": -5,
      "name": "Rock_Stone"
    },
    {
      "x": -11,
      "y": -6,
      "z": -5,
      "name": "Rock_Stone"
    },
    {
      "x": -11,
      "y": -5,
      "z": -5,
      "name": "Rock_Stone"
    },
    {
      "x": -11,
      "y": -6,
      "z": -4,
      "name": "Rock_Stone"
    },
    {
      "x": -11,
      "y": -5,
      "z": -4,
      "name": "Rock_Stone"
    },
    {
      "x": -11,
      "y": -6,
      "z": -3,
      "name": "Rock_Stone"
    },
    {
      "x": -11,
      "y": -5,
      "z": -3,
      "name": "Rock_Stone"
    },
    {
      "x": -10,
      "y": -9,
      "z": -29,
      "name": "Rock_Stone"
    },
    {
      "x": -10,
      "y": -8,
      "z": -29,
      "name": "Rock_Stone"
    },
    {
      "x": -10,
      "y": -7,
      "z": -29,
      "name": "Rock_Stone"
    },
    {
      "x": -10,
      "y": -9,
      "z": -28,
      "name": "Rock_Stone"
    },
    {
      "x": -10,
      "y": -8,
      "z": -28,
      "name": "Rock_Stone"
    },
    {
      "x": -10,
      "y": -7,
      "z": -28,
      "name": "Rock_Stone"
    },
    {
      "x": -10,
      "y": -6,
      "z": -28,
      "name": "Rock_Stone"
    },
    {
      "x": -10,
      "y": -9,
      "z": -27,
      "name": "Rock_Stone"
    },
    {
      "x": -10,
      "y": -8,
      "z": -27,
      "name": "Rock_Stone"
    },
    {
      "x": -10,
      "y": -7,
      "z": -27,
      "name": "Rock_Stone"
    },
    {
      "x": -10,
      "y": -6,
      "z": -27,
      "name": "Rock_Stone"
    },
    {
      "x": -10,
      "y": -2,
      "z": -27,
      "name": "Empty"
    },
    {
      "x": -10,
      "y": -1,
      "z": -27,
      "name": "Empty"
    },
    {
      "x": -10,
      "y": -9,
      "z": -26,
      "name": "Rock_Stone"
    },
    {
      "x": -10,
      "y": -8,
      "z": -26,
      "name": "Rock_Stone"
    },
    {
      "x": -10,
      "y": -7,
      "z": -26,
      "name": "Rock_Stone"
    },
    {
      "x": -10,
      "y": -6,
      "z": -26,
      "name": "Rock_Stone"
    },
    {
      "x": -10,
      "y": -5,
      "z": -26,
      "name": "Empty"
    },
    {
      "x": -10,
      "y": -4,
      "z": -26,
      "name": "Empty"
    },
    {
      "x": -10,
      "y": -3,
      "z": -26,
      "name": "Empty"
    },
    {
      "x": -10,
      "y": -2,
      "z": -26,
      "name": "Empty"
    },
    {
      "x": -10,
      "y": -1,
      "z": -26,
      "name": "Empty"
    },
    {
      "x": -10,
      "y": 0,
      "z": -26,
      "name": "Empty"
    },
    {
      "x": -10,
      "y": 1,
      "z": -26,
      "name": "Empty"
    },
    {
      "x": -10,
      "y": -9,
      "z": -25,
      "name": "Rock_Stone"
    },
    {
      "x": -10,
      "y": -8,
      "z": -25,
      "name": "Rock_Stone"
    },
    {
      "x": -10,
      "y": -7,
      "z": -25,
      "name": "Plant_Moss_Block_Blue"
    },
    {
      "x": -10,
      "y": -6,
      "z": -25,
      "name": "Empty"
    },
    {
      "x": -10,
      "y": -5,
      "z": -25,
      "name": "Empty"
    },
    {
      "x": -10,
      "y": -4,
      "z": -25,
      "name": "Empty"
    },
    {
      "x": -10,
      "y": -3,
      "z": -25,
      "name": "Empty"
    },
    {
      "x": -10,
      "y": -2,
      "z": -25,
      "name": "Empty"
    },
    {
      "x": -10,
      "y": -1,
      "z": -25,
      "name": "Empty"
    },
    {
      "x": -10,
      "y": 0,
      "z": -25,
      "name": "Empty"
    },
    {
      "x": -10,
      "y": 1,
      "z": -25,
      "name": "Empty"
    },
    {
      "x": -10,
      "y": 2,
      "z": -25,
      "name": "Empty"
    },
    {
      "x": -10,
      "y": -9,
      "z": -24,
      "name": "Rock_Stone"
    },
    {
      "x": -10,
      "y": -8,
      "z": -24,
      "name": "Rock_Stone"
    },
    {
      "x": -10,
      "y": -7,
      "z": -24,
      "name": "Rock_Stone"
    },
    {
      "x": -10,
      "y": -6,
      "z": -24,
      "name": "Empty"
    },
    {
      "x": -10,
      "y": -5,
      "z": -24,
      "name": "Empty"
    },
    {
      "x": -10,
      "y": -4,
      "z": -24,
      "name": "Empty"
    },
    {
      "x": -10,
      "y": -3,
      "z": -24,
      "name": "Empty"
    },
    {
      "x": -10,
      "y": -2,
      "z": -24,
      "name": "Empty"
    },
    {
      "x": -10,
      "y": -1,
      "z": -24,
      "name": "Empty"
    },
    {
      "x": -10,
      "y": 0,
      "z": -24,
      "name": "Empty"
    },
    {
      "x": -10,
      "y": 1,
      "z": -24,
      "name": "Empty"
    },
    {
      "x": -10,
      "y": 2,
      "z": -24,
      "name": "Empty"
    },
    {
      "x": -10,
      "y": 3,
      "z": -24,
      "name": "Empty"
    },
    {
      "x": -10,
      "y": 4,
      "z": -24,
      "name": "Empty"
    },
    {
      "x": -10,
      "y": -10,
      "z": -23,
      "name": "Rock_Stone"
    },
    {
      "x": -10,
      "y": -9,
      "z": -23,
      "name": "Rock_Stone"
    },
    {
      "x": -10,
      "y": -8,
      "z": -23,
      "name": "Rock_Stone"
    },
    {
      "x": -10,
      "y": -7,
      "z": -23,
      "name": "Rock_Stone"
    },
    {
      "x": -10,
      "y": -6,
      "z": -23,
      "name": "Empty"
    },
    {
      "x": -10,
      "y": -5,
      "z": -23,
      "name": "Empty"
    },
    {
      "x": -10,
      "y": -4,
      "z": -23,
      "name": "Empty"
    },
    {
      "x": -10,
      "y": -3,
      "z": -23,
      "name": "Empty"
    },
    {
      "x": -10,
      "y": -2,
      "z": -23,
      "name": "Rock_Quartzite_Brick_Smooth_Half",
      "rotation": 5
    },
    {
      "x": -10,
      "y": -1,
      "z": -23,
      "name": "Rock_Quartzite_Brick"
    },
    {
      "x": -10,
      "y": 0,
      "z": -23,
      "name": "*Rock_Quartzite_Brick_Wall_State_Definitions_Corner"
    },
    {
      "x": -10,
      "y": 1,
      "z": -23,
      "name": "Empty"
    },
    {
      "x": -10,
      "y": 2,
      "z": -23,
      "name": "Empty"
    },
    {
      "x": -10,
      "y": 3,
      "z": -23,
      "name": "Empty"
    },
    {
      "x": -10,
      "y": 4,
      "z": -23,
      "name": "Empty"
    },
    {
      "x": -10,
      "y": 5,
      "z": -23,
      "name": "Empty"
    },
    {
      "x": -10,
      "y": 6,
      "z": -23,
      "name": "Empty"
    },
    {
      "x": -10,
      "y": 7,
      "z": -23,
      "name": "Empty"
    },
    {
      "x": -10,
      "y": -10,
      "z": -22,
      "name": "Rock_Stone"
    },
    {
      "x": -10,
      "y": -9,
      "z": -22,
      "name": "Rock_Stone"
    },
    {
      "x": -10,
      "y": -8,
      "z": -22,
      "name": "Rock_Stone"
    },
    {
      "x": -10,
      "y": -7,
      "z": -22,
      "name": "Rock_Stone_Cobble_Half"
    },
    {
      "x": -10,
      "y": -6,
      "z": -22,
      "name": "Empty"
    },
    {
      "x": -10,
      "y": -5,
      "z": -22,
      "name": "Empty"
    },
    {
      "x": -10,
      "y": -4,
      "z": -22,
      "name": "Empty"
    },
    {
      "x": -10,
      "y": -3,
      "z": -22,
      "name": "Empty"
    },
    {
      "x": -10,
      "y": -2,
      "z": -22,
      "name": "Empty"
    },
    {
      "x": -10,
      "y": -1,
      "z": -22,
      "name": "Rock_Quartzite_Brick"
    },
    {
      "x": -10,
      "y": 0,
      "z": -22,
      "name": "Rock_Quartzite_Brick_Wall",
      "rotation": 1
    },
    {
      "x": -10,
      "y": 1,
      "z": -22,
      "name": "Empty"
    },
    {
      "x": -10,
      "y": 2,
      "z": -22,
      "name": "Empty"
    },
    {
      "x": -10,
      "y": 3,
      "z": -22,
      "name": "Empty"
    },
    {
      "x": -10,
      "y": 4,
      "z": -22,
      "name": "Empty"
    },
    {
      "x": -10,
      "y": 5,
      "z": -22,
      "name": "Empty"
    },
    {
      "x": -10,
      "y": 6,
      "z": -22,
      "name": "Empty"
    },
    {
      "x": -10,
      "y": 7,
      "z": -22,
      "name": "Empty"
    },
    {
      "x": -10,
      "y": 8,
      "z": -22,
      "name": "Empty"
    },
    {
      "x": -10,
      "y": 9,
      "z": -22,
      "name": "Empty"
    },
    {
      "x": -10,
      "y": -10,
      "z": -21,
      "name": "Rock_Stone"
    },
    {
      "x": -10,
      "y": -9,
      "z": -21,
      "name": "Rock_Stone"
    },
    {
      "x": -10,
      "y": -8,
      "z": -21,
      "name": "Rock_Stone"
    },
    {
      "x": -10,
      "y": -7,
      "z": -21,
      "name": "Rock_Stone_Cobble_Half"
    },
    {
      "x": -10,
      "y": -6,
      "z": -21,
      "name": "Empty"
    },
    {
      "x": -10,
      "y": -5,
      "z": -21,
      "name": "Empty"
    },
    {
      "x": -10,
      "y": -4,
      "z": -21,
      "name": "Empty"
    },
    {
      "x": -10,
      "y": -3,
      "z": -21,
      "name": "Empty"
    },
    {
      "x": -10,
      "y": -2,
      "z": -21,
      "name": "Empty"
    },
    {
      "x": -10,
      "y": -1,
      "z": -21,
      "name": "Rock_Quartzite_Brick"
    },
    {
      "x": -10,
      "y": 0,
      "z": -21,
      "name": "Rock_Quartzite_Brick_Wall",
      "rotation": 1
    },
    {
      "x": -10,
      "y": 1,
      "z": -21,
      "name": "Empty"
    },
    {
      "x": -10,
      "y": 2,
      "z": -21,
      "name": "Empty"
    },
    {
      "x": -10,
      "y": 3,
      "z": -21,
      "name": "Empty"
    },
    {
      "x": -10,
      "y": 4,
      "z": -21,
      "name": "Empty"
    },
    {
      "x": -10,
      "y": 5,
      "z": -21,
      "name": "Empty"
    },
    {
      "x": -10,
      "y": 6,
      "z": -21,
      "name": "Empty"
    },
    {
      "x": -10,
      "y": 7,
      "z": -21,
      "name": "Empty"
    },
    {
      "x": -10,
      "y": 8,
      "z": -21,
      "name": "Empty"
    },
    {
      "x": -10,
      "y": -10,
      "z": -20,
      "name": "Rock_Stone"
    },
    {
      "x": -10,
      "y": -9,
      "z": -20,
      "name": "Rock_Stone"
    },
    {
      "x": -10,
      "y": -8,
      "z": -20,
      "name": "Rock_Stone"
    },
    {
      "x": -10,
      "y": -7,
      "z": -20,
      "name": "Rock_Stone_Cobble_Half"
    },
    {
      "x": -10,
      "y": -6,
      "z": -20,
      "name": "Empty"
    },
    {
      "x": -10,
      "y": -5,
      "z": -20,
      "name": "Empty"
    },
    {
      "x": -10,
      "y": -4,
      "z": -20,
      "name": "Empty"
    },
    {
      "x": -10,
      "y": -3,
      "z": -20,
      "name": "Empty"
    },
    {
      "x": -10,
      "y": -2,
      "z": -20,
      "name": "Empty"
    },
    {
      "x": -10,
      "y": -1,
      "z": -20,
      "name": "Rock_Quartzite_Brick"
    },
    {
      "x": -10,
      "y": 0,
      "z": -20,
      "name": "Rock_Quartzite_Brick_Wall",
      "rotation": 1
    },
    {
      "x": -10,
      "y": 1,
      "z": -20,
      "name": "Empty"
    },
    {
      "x": -10,
      "y": 2,
      "z": -20,
      "name": "Empty"
    },
    {
      "x": -10,
      "y": 3,
      "z": -20,
      "name": "Empty"
    },
    {
      "x": -10,
      "y": 4,
      "z": -20,
      "name": "Empty"
    },
    {
      "x": -10,
      "y": 5,
      "z": -20,
      "name": "Empty"
    },
    {
      "x": -10,
      "y": 6,
      "z": -20,
      "name": "Empty"
    },
    {
      "x": -10,
      "y": 7,
      "z": -20,
      "name": "Empty"
    },
    {
      "x": -10,
      "y": -11,
      "z": -19,
      "name": "Rock_Stone"
    },
    {
      "x": -10,
      "y": -10,
      "z": -19,
      "name": "Rock_Stone"
    },
    {
      "x": -10,
      "y": -9,
      "z": -19,
      "name": "Rock_Stone"
    },
    {
      "x": -10,
      "y": -8,
      "z": -19,
      "name": "Rock_Stone"
    },
    {
      "x": -10,
      "y": -7,
      "z": -19,
      "name": "Rock_Stone_Cobble"
    },
    {
      "x": -10,
      "y": -6,
      "z": -19,
      "name": "Empty"
    },
    {
      "x": -10,
      "y": -5,
      "z": -19,
      "name": "Empty"
    },
    {
      "x": -10,
      "y": -4,
      "z": -19,
      "name": "Empty"
    },
    {
      "x": -10,
      "y": -3,
      "z": -19,
      "name": "Empty"
    },
    {
      "x": -10,
      "y": -2,
      "z": -19,
      "name": "Rock_Quartzite_Brick_Smooth_Half",
      "rotation": 5
    },
    {
      "x": -10,
      "y": -1,
      "z": -19,
      "name": "Rock_Quartzite_Brick"
    },
    {
      "x": -10,
      "y": 0,
      "z": -19,
      "name": "*Rock_Quartzite_Brick_Wall_State_Definitions_Corner",
      "rotation": 3
    },
    {
      "x": -10,
      "y": 1,
      "z": -19,
      "name": "Empty"
    },
    {
      "x": -10,
      "y": 2,
      "z": -19,
      "name": "Empty"
    },
    {
      "x": -10,
      "y": 3,
      "z": -19,
      "name": "Empty"
    },
    {
      "x": -10,
      "y": 4,
      "z": -19,
      "name": "Empty"
    },
    {
      "x": -10,
      "y": 5,
      "z": -19,
      "name": "Empty"
    },
    {
      "x": -10,
      "y": -11,
      "z": -18,
      "name": "Rock_Stone"
    },
    {
      "x": -10,
      "y": -10,
      "z": -18,
      "name": "Rock_Stone"
    },
    {
      "x": -10,
      "y": -9,
      "z": -18,
      "name": "Rock_Stone"
    },
    {
      "x": -10,
      "y": -8,
      "z": -18,
      "name": "Rock_Stone"
    },
    {
      "x": -10,
      "y": -7,
      "z": -18,
      "name": "Rock_Stone_Cobble"
    },
    {
      "x": -10,
      "y": -6,
      "z": -18,
      "name": "Empty"
    },
    {
      "x": -10,
      "y": -5,
      "z": -18,
      "name": "Empty"
    },
    {
      "x": -10,
      "y": -4,
      "z": -18,
      "name": "Empty"
    },
    {
      "x": -10,
      "y": -3,
      "z": -18,
      "name": "Empty"
    },
    {
      "x": -10,
      "y": -2,
      "z": -18,
      "name": "Empty"
    },
    {
      "x": -10,
      "y": -1,
      "z": -18,
      "name": "Empty"
    },
    {
      "x": -10,
      "y": 0,
      "z": -18,
      "name": "Empty"
    },
    {
      "x": -10,
      "y": 1,
      "z": -18,
      "name": "Empty"
    },
    {
      "x": -10,
      "y": 2,
      "z": -18,
      "name": "Empty"
    },
    {
      "x": -10,
      "y": 3,
      "z": -18,
      "name": "Empty"
    },
    {
      "x": -10,
      "y": 4,
      "z": -18,
      "name": "Empty"
    },
    {
      "x": -10,
      "y": -12,
      "z": -17,
      "name": "Rock_Stone"
    },
    {
      "x": -10,
      "y": -11,
      "z": -17,
      "name": "Rock_Stone"
    },
    {
      "x": -10,
      "y": -10,
      "z": -17,
      "name": "Rock_Stone"
    },
    {
      "x": -10,
      "y": -9,
      "z": -17,
      "name": "Rock_Stone"
    },
    {
      "x": -10,
      "y": -8,
      "z": -17,
      "name": "Rock_Quartzite_Brick"
    },
    {
      "x": -10,
      "y": -7,
      "z": -17,
      "name": "Rock_Quartzite_Brick"
    },
    {
      "x": -10,
      "y": -6,
      "z": -17,
      "name": "Empty"
    },
    {
      "x": -10,
      "y": -5,
      "z": -17,
      "name": "Empty"
    },
    {
      "x": -10,
      "y": -4,
      "z": -17,
      "name": "Empty"
    },
    {
      "x": -10,
      "y": -3,
      "z": -17,
      "name": "Empty"
    },
    {
      "x": -10,
      "y": -2,
      "z": -17,
      "name": "Empty"
    },
    {
      "x": -10,
      "y": -1,
      "z": -17,
      "name": "Empty"
    },
    {
      "x": -10,
      "y": 0,
      "z": -17,
      "name": "Empty"
    },
    {
      "x": -10,
      "y": 1,
      "z": -17,
      "name": "Empty"
    },
    {
      "x": -10,
      "y": 2,
      "z": -17,
      "name": "Empty"
    },
    {
      "x": -10,
      "y": 3,
      "z": -17,
      "name": "Empty"
    },
    {
      "x": -10,
      "y": -12,
      "z": -16,
      "name": "Rock_Stone"
    },
    {
      "x": -10,
      "y": -11,
      "z": -16,
      "name": "Rock_Stone"
    },
    {
      "x": -10,
      "y": -10,
      "z": -16,
      "name": "Rock_Stone"
    },
    {
      "x": -10,
      "y": -9,
      "z": -16,
      "name": "Rock_Stone"
    },
    {
      "x": -10,
      "y": -8,
      "z": -16,
      "name": "Rubble_Stone"
    },
    {
      "x": -10,
      "y": -7,
      "z": -16,
      "name": "Empty"
    },
    {
      "x": -10,
      "y": -6,
      "z": -16,
      "name": "Empty"
    },
    {
      "x": -10,
      "y": -5,
      "z": -16,
      "name": "Empty"
    },
    {
      "x": -10,
      "y": -4,
      "z": -16,
      "name": "Empty"
    },
    {
      "x": -10,
      "y": -3,
      "z": -16,
      "name": "Empty"
    },
    {
      "x": -10,
      "y": -2,
      "z": -16,
      "name": "Empty"
    },
    {
      "x": -10,
      "y": -1,
      "z": -16,
      "name": "Empty"
    },
    {
      "x": -10,
      "y": 0,
      "z": -16,
      "name": "Empty"
    },
    {
      "x": -10,
      "y": 1,
      "z": -16,
      "name": "Empty"
    },
    {
      "x": -10,
      "y": 2,
      "z": -16,
      "name": "Empty"
    },
    {
      "x": -10,
      "y": 3,
      "z": -16,
      "name": "Empty"
    },
    {
      "x": -10,
      "y": -12,
      "z": -15,
      "name": "Rock_Stone"
    },
    {
      "x": -10,
      "y": -11,
      "z": -15,
      "name": "Rock_Stone"
    },
    {
      "x": -10,
      "y": -10,
      "z": -15,
      "name": "Rock_Stone"
    },
    {
      "x": -10,
      "y": -9,
      "z": -15,
      "name": "Rock_Stone"
    },
    {
      "x": -10,
      "y": -8,
      "z": -15,
      "name": "Rock_Stone"
    },
    {
      "x": -10,
      "y": -7,
      "z": -15,
      "name": "Empty"
    },
    {
      "x": -10,
      "y": -6,
      "z": -15,
      "name": "Empty"
    },
    {
      "x": -10,
      "y": -5,
      "z": -15,
      "name": "Empty"
    },
    {
      "x": -10,
      "y": -4,
      "z": -15,
      "name": "Empty"
    },
    {
      "x": -10,
      "y": -3,
      "z": -15,
      "name": "Empty"
    },
    {
      "x": -10,
      "y": -2,
      "z": -15,
      "name": "Empty"
    },
    {
      "x": -10,
      "y": -1,
      "z": -15,
      "name": "Empty"
    },
    {
      "x": -10,
      "y": 0,
      "z": -15,
      "name": "Empty"
    },
    {
      "x": -10,
      "y": 1,
      "z": -15,
      "name": "Empty"
    },
    {
      "x": -10,
      "y": 2,
      "z": -15,
      "name": "Empty"
    },
    {
      "x": -10,
      "y": -12,
      "z": -14,
      "name": "Rock_Stone"
    },
    {
      "x": -10,
      "y": -11,
      "z": -14,
      "name": "Rock_Stone"
    },
    {
      "x": -10,
      "y": -10,
      "z": -14,
      "name": "Rock_Stone"
    },
    {
      "x": -10,
      "y": -9,
      "z": -14,
      "name": "Rock_Stone"
    },
    {
      "x": -10,
      "y": -8,
      "z": -14,
      "name": "Rock_Stone"
    },
    {
      "x": -10,
      "y": -7,
      "z": -14,
      "name": "Rubble_Stone_Medium"
    },
    {
      "x": -10,
      "y": -6,
      "z": -14,
      "name": "Empty"
    },
    {
      "x": -10,
      "y": -5,
      "z": -14,
      "name": "Empty"
    },
    {
      "x": -10,
      "y": -4,
      "z": -14,
      "name": "Empty"
    },
    {
      "x": -10,
      "y": -3,
      "z": -14,
      "name": "Empty"
    },
    {
      "x": -10,
      "y": -2,
      "z": -14,
      "name": "Empty"
    },
    {
      "x": -10,
      "y": -1,
      "z": -14,
      "name": "Empty"
    },
    {
      "x": -10,
      "y": 0,
      "z": -14,
      "name": "Empty"
    },
    {
      "x": -10,
      "y": -11,
      "z": -13,
      "name": "Rock_Stone"
    },
    {
      "x": -10,
      "y": -10,
      "z": -13,
      "name": "Rock_Stone"
    },
    {
      "x": -10,
      "y": -9,
      "z": -13,
      "name": "Rock_Stone"
    },
    {
      "x": -10,
      "y": -8,
      "z": -13,
      "name": "Rock_Quartzite_Brick"
    },
    {
      "x": -10,
      "y": -7,
      "z": -13,
      "name": "Rock_Quartzite_Brick"
    },
    {
      "x": -10,
      "y": -6,
      "z": -13,
      "name": "Rock_Quartzite_Brick"
    },
    {
      "x": -10,
      "y": -5,
      "z": -13,
      "name": "Rock_Quartzite_Brick_Pillar_Base"
    },
    {
      "x": -10,
      "y": -4,
      "z": -13,
      "name": "Rock_Quartzite_Brick_Pillar_Middle"
    },
    {
      "x": -10,
      "y": -3,
      "z": -13,
      "name": "Rock_Quartzite_Brick_Pillar_Middle"
    },
    {
      "x": -10,
      "y": -2,
      "z": -13,
      "name": "Rock_Quartzite_Brick_Pillar_Base",
      "rotation": 8
    },
    {
      "x": -10,
      "y": -1,
      "z": -13,
      "name": "Empty"
    },
    {
      "x": -10,
      "y": -11,
      "z": -12,
      "name": "Rock_Stone"
    },
    {
      "x": -10,
      "y": -10,
      "z": -12,
      "name": "Rock_Stone"
    },
    {
      "x": -10,
      "y": -9,
      "z": -12,
      "name": "Rock_Stone"
    },
    {
      "x": -10,
      "y": -8,
      "z": -12,
      "name": "Rock_Quartzite_Brick"
    },
    {
      "x": -10,
      "y": -7,
      "z": -12,
      "name": "Rock_Quartzite_Brick"
    },
    {
      "x": -10,
      "y": -6,
      "z": -12,
      "name": "Rock_Quartzite_Brick"
    },
    {
      "x": -10,
      "y": -5,
      "z": -12,
      "name": "Empty"
    },
    {
      "x": -10,
      "y": -4,
      "z": -12,
      "name": "Empty"
    },
    {
      "x": -10,
      "y": -3,
      "z": -12,
      "name": "Empty"
    },
    {
      "x": -10,
      "y": -2,
      "z": -12,
      "name": "Empty"
    },
    {
      "x": -10,
      "y": -1,
      "z": -12,
      "name": "Empty"
    },
    {
      "x": -10,
      "y": 0,
      "z": -12,
      "name": "Empty"
    },
    {
      "x": -10,
      "y": -11,
      "z": -11,
      "name": "Rock_Stone"
    },
    {
      "x": -10,
      "y": -10,
      "z": -11,
      "name": "Rock_Stone"
    },
    {
      "x": -10,
      "y": -9,
      "z": -11,
      "name": "Rock_Stone"
    },
    {
      "x": -10,
      "y": -8,
      "z": -11,
      "name": "Rock_Stone"
    },
    {
      "x": -10,
      "y": -7,
      "z": -11,
      "name": "Empty"
    },
    {
      "x": -10,
      "y": -6,
      "z": -11,
      "name": "Empty"
    },
    {
      "x": -10,
      "y": -5,
      "z": -11,
      "name": "Empty"
    },
    {
      "x": -10,
      "y": -4,
      "z": -11,
      "name": "Empty"
    },
    {
      "x": -10,
      "y": -3,
      "z": -11,
      "name": "Empty"
    },
    {
      "x": -10,
      "y": -2,
      "z": -11,
      "name": "Empty"
    },
    {
      "x": -10,
      "y": -1,
      "z": -11,
      "name": "Empty"
    },
    {
      "x": -10,
      "y": 0,
      "z": -11,
      "name": "Empty"
    },
    {
      "x": -10,
      "y": 1,
      "z": -11,
      "name": "Empty"
    },
    {
      "x": -10,
      "y": 2,
      "z": -11,
      "name": "Empty"
    },
    {
      "x": -10,
      "y": -11,
      "z": -10,
      "name": "Rock_Stone"
    },
    {
      "x": -10,
      "y": -10,
      "z": -10,
      "name": "Rock_Stone"
    },
    {
      "x": -10,
      "y": -9,
      "z": -10,
      "name": "Rock_Stone"
    },
    {
      "x": -10,
      "y": -8,
      "z": -10,
      "name": "Rock_Stone"
    },
    {
      "x": -10,
      "y": -7,
      "z": -10,
      "name": "Rock_Stone"
    },
    {
      "x": -10,
      "y": -6,
      "z": -10,
      "name": "Empty"
    },
    {
      "x": -10,
      "y": -5,
      "z": -10,
      "name": "Empty"
    },
    {
      "x": -10,
      "y": -4,
      "z": -10,
      "name": "Empty"
    },
    {
      "x": -10,
      "y": -3,
      "z": -10,
      "name": "Empty"
    },
    {
      "x": -10,
      "y": -2,
      "z": -10,
      "name": "Empty"
    },
    {
      "x": -10,
      "y": -1,
      "z": -10,
      "name": "Empty"
    },
    {
      "x": -10,
      "y": 0,
      "z": -10,
      "name": "Empty"
    },
    {
      "x": -10,
      "y": 1,
      "z": -10,
      "name": "Empty"
    },
    {
      "x": -10,
      "y": 2,
      "z": -10,
      "name": "Empty"
    },
    {
      "x": -10,
      "y": -10,
      "z": -9,
      "name": "Rock_Stone"
    },
    {
      "x": -10,
      "y": -9,
      "z": -9,
      "name": "Rock_Stone"
    },
    {
      "x": -10,
      "y": -8,
      "z": -9,
      "name": "Rock_Stone"
    },
    {
      "x": -10,
      "y": -7,
      "z": -9,
      "name": "Rock_Stone"
    },
    {
      "x": -10,
      "y": -6,
      "z": -9,
      "name": "Plant_Moss_Block_Blue"
    },
    {
      "x": -10,
      "y": -5,
      "z": -9,
      "name": "Empty"
    },
    {
      "x": -10,
      "y": -4,
      "z": -9,
      "name": "Empty"
    },
    {
      "x": -10,
      "y": -3,
      "z": -9,
      "name": "Empty"
    },
    {
      "x": -10,
      "y": -2,
      "z": -9,
      "name": "Empty"
    },
    {
      "x": -10,
      "y": -1,
      "z": -9,
      "name": "Empty"
    },
    {
      "x": -10,
      "y": 0,
      "z": -9,
      "name": "Empty"
    },
    {
      "x": -10,
      "y": 1,
      "z": -9,
      "name": "Empty"
    },
    {
      "x": -10,
      "y": 2,
      "z": -9,
      "name": "Empty"
    },
    {
      "x": -10,
      "y": -9,
      "z": -8,
      "name": "Rock_Stone"
    },
    {
      "x": -10,
      "y": -8,
      "z": -8,
      "name": "Rock_Stone"
    },
    {
      "x": -10,
      "y": -7,
      "z": -8,
      "name": "Rock_Stone"
    },
    {
      "x": -10,
      "y": -6,
      "z": -8,
      "name": "Plant_Moss_Block_Blue"
    },
    {
      "x": -10,
      "y": -5,
      "z": -8,
      "name": "Plant_Moss_Rug_Blue"
    },
    {
      "x": -10,
      "y": -4,
      "z": -8,
      "name": "Empty"
    },
    {
      "x": -10,
      "y": -3,
      "z": -8,
      "name": "Empty"
    },
    {
      "x": -10,
      "y": -2,
      "z": -8,
      "name": "Empty"
    },
    {
      "x": -10,
      "y": -1,
      "z": -8,
      "name": "Empty"
    },
    {
      "x": -10,
      "y": 0,
      "z": -8,
      "name": "Empty"
    },
    {
      "x": -10,
      "y": 1,
      "z": -8,
      "name": "Empty"
    },
    {
      "x": -10,
      "y": -8,
      "z": -7,
      "name": "Rock_Stone"
    },
    {
      "x": -10,
      "y": -7,
      "z": -7,
      "name": "Rock_Stone"
    },
    {
      "x": -10,
      "y": -6,
      "z": -7,
      "name": "Plant_Moss_Block_Blue"
    },
    {
      "x": -10,
      "y": -5,
      "z": -7,
      "name": "Plant_Moss_Rug_Blue"
    },
    {
      "x": -10,
      "y": -4,
      "z": -7,
      "name": "Empty"
    },
    {
      "x": -10,
      "y": -3,
      "z": -7,
      "name": "Empty"
    },
    {
      "x": -10,
      "y": -2,
      "z": -7,
      "name": "Empty"
    },
    {
      "x": -10,
      "y": -1,
      "z": -7,
      "name": "Empty"
    },
    {
      "x": -10,
      "y": 0,
      "z": -7,
      "name": "Empty"
    },
    {
      "x": -10,
      "y": 1,
      "z": -7,
      "name": "Empty"
    },
    {
      "x": -10,
      "y": -8,
      "z": -6,
      "name": "Rock_Stone"
    },
    {
      "x": -10,
      "y": -7,
      "z": -6,
      "name": "Rock_Stone"
    },
    {
      "x": -10,
      "y": -6,
      "z": -6,
      "name": "Plant_Moss_Block_Blue"
    },
    {
      "x": -10,
      "y": -5,
      "z": -6,
      "name": "Empty"
    },
    {
      "x": -10,
      "y": -4,
      "z": -6,
      "name": "Empty"
    },
    {
      "x": -10,
      "y": -3,
      "z": -6,
      "name": "Empty"
    },
    {
      "x": -10,
      "y": -2,
      "z": -6,
      "name": "Empty"
    },
    {
      "x": -10,
      "y": -1,
      "z": -6,
      "name": "Empty"
    },
    {
      "x": -10,
      "y": 0,
      "z": -6,
      "name": "Empty"
    },
    {
      "x": -10,
      "y": -7,
      "z": -5,
      "name": "Rock_Stone"
    },
    {
      "x": -10,
      "y": -6,
      "z": -5,
      "name": "Rock_Stone"
    },
    {
      "x": -10,
      "y": -5,
      "z": -5,
      "name": "Furniture_Temple_Dark_Pot"
    },
    {
      "x": -10,
      "y": -4,
      "z": -5,
      "name": "Empty"
    },
    {
      "x": -10,
      "y": -3,
      "z": -5,
      "name": "Empty"
    },
    {
      "x": -10,
      "y": -2,
      "z": -5,
      "name": "Empty"
    },
    {
      "x": -10,
      "y": -1,
      "z": -5,
      "name": "Empty"
    },
    {
      "x": -10,
      "y": -7,
      "z": -4,
      "name": "Rock_Stone"
    },
    {
      "x": -10,
      "y": -6,
      "z": -4,
      "name": "Rock_Stone"
    },
    {
      "x": -10,
      "y": -5,
      "z": -4,
      "name": "Rubble_Stone_Medium"
    },
    {
      "x": -10,
      "y": -4,
      "z": -4,
      "name": "Empty"
    },
    {
      "x": -10,
      "y": -6,
      "z": -3,
      "name": "Rock_Stone"
    },
    {
      "x": -10,
      "y": -5,
      "z": -3,
      "name": "Rock_Stone"
    },
    {
      "x": -10,
      "y": -5,
      "z": -2,
      "name": "Rock_Stone"
    },
    {
      "x": -9,
      "y": -9,
      "z": -29,
      "name": "Rock_Stone"
    },
    {
      "x": -9,
      "y": -8,
      "z": -29,
      "name": "Rock_Stone"
    },
    {
      "x": -9,
      "y": -7,
      "z": -29,
      "name": "Rock_Stone"
    },
    {
      "x": -9,
      "y": -6,
      "z": -29,
      "name": "Rock_Stone"
    },
    {
      "x": -9,
      "y": -2,
      "z": -29,
      "name": "Empty"
    },
    {
      "x": -9,
      "y": -1,
      "z": -29,
      "name": "Empty"
    },
    {
      "x": -9,
      "y": -9,
      "z": -28,
      "name": "Rock_Stone"
    },
    {
      "x": -9,
      "y": -8,
      "z": -28,
      "name": "Rock_Stone"
    },
    {
      "x": -9,
      "y": -7,
      "z": -28,
      "name": "Plant_Moss_Block_Blue"
    },
    {
      "x": -9,
      "y": -6,
      "z": -28,
      "name": "Plant_Moss_Block_Blue"
    },
    {
      "x": -9,
      "y": -5,
      "z": -28,
      "name": "Plant_Moss_Block_Blue"
    },
    {
      "x": -9,
      "y": -4,
      "z": -28,
      "name": "Empty"
    },
    {
      "x": -9,
      "y": -3,
      "z": -28,
      "name": "Empty"
    },
    {
      "x": -9,
      "y": -2,
      "z": -28,
      "name": "Empty"
    },
    {
      "x": -9,
      "y": -1,
      "z": -28,
      "name": "Empty"
    },
    {
      "x": -9,
      "y": 0,
      "z": -28,
      "name": "Empty"
    },
    {
      "x": -9,
      "y": 1,
      "z": -28,
      "name": "Empty"
    },
    {
      "x": -9,
      "y": -10,
      "z": -27,
      "name": "Rock_Stone"
    },
    {
      "x": -9,
      "y": -9,
      "z": -27,
      "name": "Rock_Stone"
    },
    {
      "x": -9,
      "y": -8,
      "z": -27,
      "name": "Rock_Stone"
    },
    {
      "x": -9,
      "y": -7,
      "z": -27,
      "name": "Plant_Moss_Block_Blue"
    },
    {
      "x": -9,
      "y": -6,
      "z": -27,
      "name": "Plant_Moss_Block_Blue"
    },
    {
      "x": -9,
      "y": -5,
      "z": -27,
      "name": "Empty"
    },
    {
      "x": -9,
      "y": -4,
      "z": -27,
      "name": "Empty"
    },
    {
      "x": -9,
      "y": -3,
      "z": -27,
      "name": "Empty"
    },
    {
      "x": -9,
      "y": -2,
      "z": -27,
      "name": "Empty"
    },
    {
      "x": -9,
      "y": -1,
      "z": -27,
      "name": "Empty"
    },
    {
      "x": -9,
      "y": 0,
      "z": -27,
      "name": "Empty"
    },
    {
      "x": -9,
      "y": 1,
      "z": -27,
      "name": "Empty"
    },
    {
      "x": -9,
      "y": 2,
      "z": -27,
      "name": "Empty"
    },
    {
      "x": -9,
      "y": -10,
      "z": -26,
      "name": "Rock_Stone"
    },
    {
      "x": -9,
      "y": -9,
      "z": -26,
      "name": "Rock_Stone"
    },
    {
      "x": -9,
      "y": -8,
      "z": -26,
      "name": "Rock_Stone"
    },
    {
      "x": -9,
      "y": -7,
      "z": -26,
      "name": "Plant_Moss_Block_Blue"
    },
    {
      "x": -9,
      "y": -6,
      "z": -26,
      "name": "Empty"
    },
    {
      "x": -9,
      "y": -5,
      "z": -26,
      "name": "Empty"
    },
    {
      "x": -9,
      "y": -4,
      "z": -26,
      "name": "Empty"
    },
    {
      "x": -9,
      "y": -3,
      "z": -26,
      "name": "Empty"
    },
    {
      "x": -9,
      "y": -2,
      "z": -26,
      "name": "Empty"
    },
    {
      "x": -9,
      "y": -1,
      "z": -26,
      "name": "Empty"
    },
    {
      "x": -9,
      "y": 0,
      "z": -26,
      "name": "Empty"
    },
    {
      "x": -9,
      "y": 1,
      "z": -26,
      "name": "Empty"
    },
    {
      "x": -9,
      "y": 2,
      "z": -26,
      "name": "Empty"
    },
    {
      "x": -9,
      "y": 3,
      "z": -26,
      "name": "Empty"
    },
    {
      "x": -9,
      "y": 4,
      "z": -26,
      "name": "Empty"
    },
    {
      "x": -9,
      "y": -10,
      "z": -25,
      "name": "Rock_Stone"
    },
    {
      "x": -9,
      "y": -9,
      "z": -25,
      "name": "Rock_Stone"
    },
    {
      "x": -9,
      "y": -8,
      "z": -25,
      "name": "Rock_Stone"
    },
    {
      "x": -9,
      "y": -7,
      "z": -25,
      "name": "Plant_Moss_Block_Blue"
    },
    {
      "x": -9,
      "y": -6,
      "z": -25,
      "name": "Empty"
    },
    {
      "x": -9,
      "y": -5,
      "z": -25,
      "name": "Empty"
    },
    {
      "x": -9,
      "y": -4,
      "z": -25,
      "name": "Empty"
    },
    {
      "x": -9,
      "y": -3,
      "z": -25,
      "name": "Empty"
    },
    {
      "x": -9,
      "y": -2,
      "z": -25,
      "name": "Empty"
    },
    {
      "x": -9,
      "y": -1,
      "z": -25,
      "name": "Empty"
    },
    {
      "x": -9,
      "y": 0,
      "z": -25,
      "name": "Empty"
    },
    {
      "x": -9,
      "y": 1,
      "z": -25,
      "name": "Empty"
    },
    {
      "x": -9,
      "y": 2,
      "z": -25,
      "name": "Empty"
    },
    {
      "x": -9,
      "y": 3,
      "z": -25,
      "name": "Empty"
    },
    {
      "x": -9,
      "y": 4,
      "z": -25,
      "name": "Empty"
    },
    {
      "x": -9,
      "y": 5,
      "z": -25,
      "name": "Empty"
    },
    {
      "x": -9,
      "y": -10,
      "z": -24,
      "name": "Rock_Stone"
    },
    {
      "x": -9,
      "y": -9,
      "z": -24,
      "name": "Rock_Stone"
    },
    {
      "x": -9,
      "y": -8,
      "z": -24,
      "name": "Rock_Stone"
    },
    {
      "x": -9,
      "y": -7,
      "z": -24,
      "name": "Furniture_Temple_Dark_Pot"
    },
    {
      "x": -9,
      "y": -6,
      "z": -24,
      "name": "Empty"
    },
    {
      "x": -9,
      "y": -5,
      "z": -24,
      "name": "Empty"
    },
    {
      "x": -9,
      "y": -4,
      "z": -24,
      "name": "Empty"
    },
    {
      "x": -9,
      "y": -3,
      "z": -24,
      "name": "Empty"
    },
    {
      "x": -9,
      "y": -2,
      "z": -24,
      "name": "Empty"
    },
    {
      "x": -9,
      "y": -1,
      "z": -24,
      "name": "Empty"
    },
    {
      "x": -9,
      "y": 0,
      "z": -24,
      "name": "Empty"
    },
    {
      "x": -9,
      "y": 1,
      "z": -24,
      "name": "Empty"
    },
    {
      "x": -9,
      "y": 2,
      "z": -24,
      "name": "Empty"
    },
    {
      "x": -9,
      "y": 3,
      "z": -24,
      "name": "Empty"
    },
    {
      "x": -9,
      "y": 4,
      "z": -24,
      "name": "Empty"
    },
    {
      "x": -9,
      "y": 5,
      "z": -24,
      "name": "Empty"
    },
    {
      "x": -9,
      "y": 6,
      "z": -24,
      "name": "Empty"
    },
    {
      "x": -9,
      "y": -10,
      "z": -23,
      "name": "Rock_Stone"
    },
    {
      "x": -9,
      "y": -9,
      "z": -23,
      "name": "Rock_Stone"
    },
    {
      "x": -9,
      "y": -8,
      "z": -23,
      "name": "Rock_Stone_Cobble"
    },
    {
      "x": -9,
      "y": -7,
      "z": -23,
      "name": "Empty"
    },
    {
      "x": -9,
      "y": -6,
      "z": -23,
      "name": "Empty"
    },
    {
      "x": -9,
      "y": -5,
      "z": -23,
      "name": "Empty"
    },
    {
      "x": -9,
      "y": -4,
      "z": -23,
      "name": "Empty"
    },
    {
      "x": -9,
      "y": -3,
      "z": -23,
      "name": "Empty"
    },
    {
      "x": -9,
      "y": -2,
      "z": -23,
      "name": "Empty"
    },
    {
      "x": -9,
      "y": -1,
      "z": -23,
      "name": "Empty"
    },
    {
      "x": -9,
      "y": 0,
      "z": -23,
      "name": "Empty"
    },
    {
      "x": -9,
      "y": 1,
      "z": -23,
      "name": "Empty"
    },
    {
      "x": -9,
      "y": 2,
      "z": -23,
      "name": "Empty"
    },
    {
      "x": -9,
      "y": 3,
      "z": -23,
      "name": "Empty"
    },
    {
      "x": -9,
      "y": 4,
      "z": -23,
      "name": "Empty"
    },
    {
      "x": -9,
      "y": 5,
      "z": -23,
      "name": "Empty"
    },
    {
      "x": -9,
      "y": 6,
      "z": -23,
      "name": "Empty"
    },
    {
      "x": -9,
      "y": 7,
      "z": -23,
      "name": "Empty"
    },
    {
      "x": -9,
      "y": 8,
      "z": -23,
      "name": "Empty"
    },
    {
      "x": -9,
      "y": 9,
      "z": -23,
      "name": "Empty"
    },
    {
      "x": -9,
      "y": -10,
      "z": -22,
      "name": "Rock_Stone"
    },
    {
      "x": -9,
      "y": -9,
      "z": -22,
      "name": "Rock_Stone"
    },
    {
      "x": -9,
      "y": -8,
      "z": -22,
      "name": "Rock_Stone_Cobble"
    },
    {
      "x": -9,
      "y": -7,
      "z": -22,
      "name": "Rock_Stone_Cobble_Half"
    },
    {
      "x": -9,
      "y": -6,
      "z": -22,
      "name": "Empty"
    },
    {
      "x": -9,
      "y": -5,
      "z": -22,
      "name": "Empty"
    },
    {
      "x": -9,
      "y": -4,
      "z": -22,
      "name": "Empty"
    },
    {
      "x": -9,
      "y": -3,
      "z": -22,
      "name": "Empty"
    },
    {
      "x": -9,
      "y": -2,
      "z": -22,
      "name": "Empty"
    },
    {
      "x": -9,
      "y": -1,
      "z": -22,
      "name": "Empty"
    },
    {
      "x": -9,
      "y": 0,
      "z": -22,
      "name": "Empty"
    },
    {
      "x": -9,
      "y": 1,
      "z": -22,
      "name": "Empty"
    },
    {
      "x": -9,
      "y": 2,
      "z": -22,
      "name": "Empty"
    },
    {
      "x": -9,
      "y": 3,
      "z": -22,
      "name": "Empty"
    },
    {
      "x": -9,
      "y": 4,
      "z": -22,
      "name": "Empty"
    },
    {
      "x": -9,
      "y": 5,
      "z": -22,
      "name": "Empty"
    },
    {
      "x": -9,
      "y": 6,
      "z": -22,
      "name": "Empty"
    },
    {
      "x": -9,
      "y": 7,
      "z": -22,
      "name": "Empty"
    },
    {
      "x": -9,
      "y": 8,
      "z": -22,
      "name": "Empty"
    },
    {
      "x": -9,
      "y": 9,
      "z": -22,
      "name": "Empty"
    },
    {
      "x": -9,
      "y": 10,
      "z": -22,
      "name": "Empty"
    },
    {
      "x": -9,
      "y": -11,
      "z": -21,
      "name": "Rock_Stone"
    },
    {
      "x": -9,
      "y": -10,
      "z": -21,
      "name": "Rock_Stone"
    },
    {
      "x": -9,
      "y": -9,
      "z": -21,
      "name": "Rock_Stone"
    },
    {
      "x": -9,
      "y": -8,
      "z": -21,
      "name": "Rock_Stone_Cobble"
    },
    {
      "x": -9,
      "y": -7,
      "z": -21,
      "name": "Rock_Stone_Cobble_Half"
    },
    {
      "x": -9,
      "y": -6,
      "z": -21,
      "name": "Empty"
    },
    {
      "x": -9,
      "y": -5,
      "z": -21,
      "name": "Empty"
    },
    {
      "x": -9,
      "y": -4,
      "z": -21,
      "name": "Empty"
    },
    {
      "x": -9,
      "y": -3,
      "z": -21,
      "name": "Empty"
    },
    {
      "x": -9,
      "y": -2,
      "z": -21,
      "name": "Empty"
    },
    {
      "x": -9,
      "y": -1,
      "z": -21,
      "name": "Empty"
    },
    {
      "x": -9,
      "y": 0,
      "z": -21,
      "name": "Empty"
    },
    {
      "x": -9,
      "y": 1,
      "z": -21,
      "name": "Empty"
    },
    {
      "x": -9,
      "y": 2,
      "z": -21,
      "name": "Empty"
    },
    {
      "x": -9,
      "y": 3,
      "z": -21,
      "name": "Empty"
    },
    {
      "x": -9,
      "y": 4,
      "z": -21,
      "name": "Empty"
    },
    {
      "x": -9,
      "y": 5,
      "z": -21,
      "name": "Empty"
    },
    {
      "x": -9,
      "y": 6,
      "z": -21,
      "name": "Empty"
    },
    {
      "x": -9,
      "y": 7,
      "z": -21,
      "name": "Empty"
    },
    {
      "x": -9,
      "y": 8,
      "z": -21,
      "name": "Empty"
    },
    {
      "x": -9,
      "y": 9,
      "z": -21,
      "name": "Empty"
    },
    {
      "x": -9,
      "y": -11,
      "z": -20,
      "name": "Rock_Stone"
    },
    {
      "x": -9,
      "y": -10,
      "z": -20,
      "name": "Rock_Stone"
    },
    {
      "x": -9,
      "y": -9,
      "z": -20,
      "name": "Rock_Stone"
    },
    {
      "x": -9,
      "y": -8,
      "z": -20,
      "name": "Rock_Stone"
    },
    {
      "x": -9,
      "y": -7,
      "z": -20,
      "name": "Rock_Stone_Cobble_Half"
    },
    {
      "x": -9,
      "y": -6,
      "z": -20,
      "name": "Empty"
    },
    {
      "x": -9,
      "y": -5,
      "z": -20,
      "name": "Empty"
    },
    {
      "x": -9,
      "y": -4,
      "z": -20,
      "name": "Empty"
    },
    {
      "x": -9,
      "y": -3,
      "z": -20,
      "name": "Empty"
    },
    {
      "x": -9,
      "y": -2,
      "z": -20,
      "name": "Empty"
    },
    {
      "x": -9,
      "y": -1,
      "z": -20,
      "name": "Empty"
    },
    {
      "x": -9,
      "y": 0,
      "z": -20,
      "name": "Empty"
    },
    {
      "x": -9,
      "y": 1,
      "z": -20,
      "name": "Empty"
    },
    {
      "x": -9,
      "y": 2,
      "z": -20,
      "name": "Empty"
    },
    {
      "x": -9,
      "y": 3,
      "z": -20,
      "name": "Empty"
    },
    {
      "x": -9,
      "y": 4,
      "z": -20,
      "name": "Empty"
    },
    {
      "x": -9,
      "y": 5,
      "z": -20,
      "name": "Empty"
    },
    {
      "x": -9,
      "y": 6,
      "z": -20,
      "name": "Empty"
    },
    {
      "x": -9,
      "y": 7,
      "z": -20,
      "name": "Empty"
    },
    {
      "x": -9,
      "y": 8,
      "z": -20,
      "name": "Empty"
    },
    {
      "x": -9,
      "y": 9,
      "z": -20,
      "name": "Empty"
    },
    {
      "x": -9,
      "y": -11,
      "z": -19,
      "name": "Rock_Stone"
    },
    {
      "x": -9,
      "y": -10,
      "z": -19,
      "name": "Rock_Stone"
    },
    {
      "x": -9,
      "y": -9,
      "z": -19,
      "name": "Rock_Stone"
    },
    {
      "x": -9,
      "y": -8,
      "z": -19,
      "name": "Rock_Stone"
    },
    {
      "x": -9,
      "y": -7,
      "z": -19,
      "name": "Rock_Stone_Cobble_Half"
    },
    {
      "x": -9,
      "y": -6,
      "z": -19,
      "name": "Empty"
    },
    {
      "x": -9,
      "y": -5,
      "z": -19,
      "name": "Empty"
    },
    {
      "x": -9,
      "y": -4,
      "z": -19,
      "name": "Empty"
    },
    {
      "x": -9,
      "y": -3,
      "z": -19,
      "name": "Empty"
    },
    {
      "x": -9,
      "y": -2,
      "z": -19,
      "name": "Empty"
    },
    {
      "x": -9,
      "y": -1,
      "z": -19,
      "name": "Empty"
    },
    {
      "x": -9,
      "y": 0,
      "z": -19,
      "name": "Empty"
    },
    {
      "x": -9,
      "y": 1,
      "z": -19,
      "name": "Empty"
    },
    {
      "x": -9,
      "y": 2,
      "z": -19,
      "name": "Empty"
    },
    {
      "x": -9,
      "y": 3,
      "z": -19,
      "name": "Empty"
    },
    {
      "x": -9,
      "y": 4,
      "z": -19,
      "name": "Empty"
    },
    {
      "x": -9,
      "y": 5,
      "z": -19,
      "name": "Empty"
    },
    {
      "x": -9,
      "y": 6,
      "z": -19,
      "name": "Empty"
    },
    {
      "x": -9,
      "y": -12,
      "z": -18,
      "name": "Rock_Stone"
    },
    {
      "x": -9,
      "y": -11,
      "z": -18,
      "name": "Rock_Stone"
    },
    {
      "x": -9,
      "y": -10,
      "z": -18,
      "name": "Rock_Stone"
    },
    {
      "x": -9,
      "y": -9,
      "z": -18,
      "name": "Rock_Stone"
    },
    {
      "x": -9,
      "y": -8,
      "z": -18,
      "name": "Rock_Stone"
    },
    {
      "x": -9,
      "y": -7,
      "z": -18,
      "name": "Rock_Stone_Cobble_Half"
    },
    {
      "x": -9,
      "y": -6,
      "z": -18,
      "name": "Empty"
    },
    {
      "x": -9,
      "y": -5,
      "z": -18,
      "name": "Empty"
    },
    {
      "x": -9,
      "y": -4,
      "z": -18,
      "name": "Empty"
    },
    {
      "x": -9,
      "y": -3,
      "z": -18,
      "name": "Empty"
    },
    {
      "x": -9,
      "y": -2,
      "z": -18,
      "name": "Empty"
    },
    {
      "x": -9,
      "y": -1,
      "z": -18,
      "name": "Empty"
    },
    {
      "x": -9,
      "y": 0,
      "z": -18,
      "name": "Empty"
    },
    {
      "x": -9,
      "y": 1,
      "z": -18,
      "name": "Empty"
    },
    {
      "x": -9,
      "y": 2,
      "z": -18,
      "name": "Empty"
    },
    {
      "x": -9,
      "y": 3,
      "z": -18,
      "name": "Empty"
    },
    {
      "x": -9,
      "y": 4,
      "z": -18,
      "name": "Empty"
    },
    {
      "x": -9,
      "y": 5,
      "z": -18,
      "name": "Empty"
    },
    {
      "x": -9,
      "y": -12,
      "z": -17,
      "name": "Rock_Stone"
    },
    {
      "x": -9,
      "y": -11,
      "z": -17,
      "name": "Rock_Stone"
    },
    {
      "x": -9,
      "y": -10,
      "z": -17,
      "name": "Rock_Stone"
    },
    {
      "x": -9,
      "y": -9,
      "z": -17,
      "name": "Rock_Quartzite_Brick"
    },
    {
      "x": -9,
      "y": -8,
      "z": -17,
      "name": "Rock_Quartzite_Brick"
    },
    {
      "x": -9,
      "y": -7,
      "z": -17,
      "name": "Rock_Quartzite_Brick"
    },
    {
      "x": -9,
      "y": -6,
      "z": -17,
      "name": "Empty"
    },
    {
      "x": -9,
      "y": -5,
      "z": -17,
      "name": "Empty"
    },
    {
      "x": -9,
      "y": -4,
      "z": -17,
      "name": "Empty"
    },
    {
      "x": -9,
      "y": -3,
      "z": -17,
      "name": "Empty"
    },
    {
      "x": -9,
      "y": -2,
      "z": -17,
      "name": "Empty"
    },
    {
      "x": -9,
      "y": -1,
      "z": -17,
      "name": "Empty"
    },
    {
      "x": -9,
      "y": 0,
      "z": -17,
      "name": "Empty"
    },
    {
      "x": -9,
      "y": 1,
      "z": -17,
      "name": "Empty"
    },
    {
      "x": -9,
      "y": 2,
      "z": -17,
      "name": "Empty"
    },
    {
      "x": -9,
      "y": 3,
      "z": -17,
      "name": "Empty"
    },
    {
      "x": -9,
      "y": 4,
      "z": -17,
      "name": "Empty"
    },
    {
      "x": -9,
      "y": -13,
      "z": -16,
      "name": "Rock_Stone"
    },
    {
      "x": -9,
      "y": -12,
      "z": -16,
      "name": "Rock_Stone"
    },
    {
      "x": -9,
      "y": -11,
      "z": -16,
      "name": "Rock_Stone"
    },
    {
      "x": -9,
      "y": -10,
      "z": -16,
      "name": "Rock_Stone"
    },
    {
      "x": -9,
      "y": -9,
      "z": -16,
      "name": "Rock_Stone"
    },
    {
      "x": -9,
      "y": -8,
      "z": -16,
      "name": "Empty"
    },
    {
      "x": -9,
      "y": -7,
      "z": -16,
      "name": "Empty"
    },
    {
      "x": -9,
      "y": -6,
      "z": -16,
      "name": "Empty"
    },
    {
      "x": -9,
      "y": -5,
      "z": -16,
      "name": "Empty"
    },
    {
      "x": -9,
      "y": -4,
      "z": -16,
      "name": "Empty"
    },
    {
      "x": -9,
      "y": -3,
      "z": -16,
      "name": "Empty"
    },
    {
      "x": -9,
      "y": -2,
      "z": -16,
      "name": "Empty"
    },
    {
      "x": -9,
      "y": -1,
      "z": -16,
      "name": "Empty"
    },
    {
      "x": -9,
      "y": 0,
      "z": -16,
      "name": "Empty"
    },
    {
      "x": -9,
      "y": 1,
      "z": -16,
      "name": "Empty"
    },
    {
      "x": -9,
      "y": 2,
      "z": -16,
      "name": "Empty"
    },
    {
      "x": -9,
      "y": 3,
      "z": -16,
      "name": "Empty"
    },
    {
      "x": -9,
      "y": 4,
      "z": -16,
      "name": "Empty"
    },
    {
      "x": -9,
      "y": -12,
      "z": -15,
      "name": "Rock_Stone"
    },
    {
      "x": -9,
      "y": -11,
      "z": -15,
      "name": "Rock_Stone"
    },
    {
      "x": -9,
      "y": -10,
      "z": -15,
      "name": "Rock_Stone"
    },
    {
      "x": -9,
      "y": -9,
      "z": -15,
      "name": "Rock_Stone"
    },
    {
      "x": -9,
      "y": -8,
      "z": -15,
      "name": "Rock_Stone"
    },
    {
      "x": -9,
      "y": -7,
      "z": -15,
      "name": "Empty"
    },
    {
      "x": -9,
      "y": -6,
      "z": -15,
      "name": "Empty"
    },
    {
      "x": -9,
      "y": -5,
      "z": -15,
      "name": "Empty"
    },
    {
      "x": -9,
      "y": -4,
      "z": -15,
      "name": "Empty"
    },
    {
      "x": -9,
      "y": -3,
      "z": -15,
      "name": "Empty"
    },
    {
      "x": -9,
      "y": -2,
      "z": -15,
      "name": "Empty"
    },
    {
      "x": -9,
      "y": -1,
      "z": -15,
      "name": "Empty"
    },
    {
      "x": -9,
      "y": 0,
      "z": -15,
      "name": "Empty"
    },
    {
      "x": -9,
      "y": 1,
      "z": -15,
      "name": "Empty"
    },
    {
      "x": -9,
      "y": 2,
      "z": -15,
      "name": "Empty"
    },
    {
      "x": -9,
      "y": 3,
      "z": -15,
      "name": "Empty"
    },
    {
      "x": -9,
      "y": -12,
      "z": -14,
      "name": "Rock_Stone"
    },
    {
      "x": -9,
      "y": -11,
      "z": -14,
      "name": "Rock_Stone"
    },
    {
      "x": -9,
      "y": -10,
      "z": -14,
      "name": "Rock_Stone"
    },
    {
      "x": -9,
      "y": -9,
      "z": -14,
      "name": "Rock_Stone"
    },
    {
      "x": -9,
      "y": -8,
      "z": -14,
      "name": "Rock_Stone"
    },
    {
      "x": -9,
      "y": -7,
      "z": -14,
      "name": "Empty"
    },
    {
      "x": -9,
      "y": -6,
      "z": -14,
      "name": "Empty"
    },
    {
      "x": -9,
      "y": -5,
      "z": -14,
      "name": "Empty"
    },
    {
      "x": -9,
      "y": -4,
      "z": -14,
      "name": "Empty"
    },
    {
      "x": -9,
      "y": -3,
      "z": -14,
      "name": "Empty"
    },
    {
      "x": -9,
      "y": -2,
      "z": -14,
      "name": "Empty"
    },
    {
      "x": -9,
      "y": -1,
      "z": -14,
      "name": "Empty"
    },
    {
      "x": -9,
      "y": 0,
      "z": -14,
      "name": "Empty"
    },
    {
      "x": -9,
      "y": 1,
      "z": -14,
      "name": "Empty"
    },
    {
      "x": -9,
      "y": 2,
      "z": -14,
      "name": "Empty"
    },
    {
      "x": -9,
      "y": -12,
      "z": -13,
      "name": "Rock_Stone"
    },
    {
      "x": -9,
      "y": -11,
      "z": -13,
      "name": "Rock_Stone"
    },
    {
      "x": -9,
      "y": -10,
      "z": -13,
      "name": "Rock_Stone"
    },
    {
      "x": -9,
      "y": -9,
      "z": -13,
      "name": "Rock_Stone"
    },
    {
      "x": -9,
      "y": -8,
      "z": -13,
      "name": "Rock_Stone"
    },
    {
      "x": -9,
      "y": -7,
      "z": -13,
      "name": "Empty"
    },
    {
      "x": -9,
      "y": -6,
      "z": -13,
      "name": "Empty"
    },
    {
      "x": -9,
      "y": -5,
      "z": -13,
      "name": "Empty"
    },
    {
      "x": -9,
      "y": -4,
      "z": -13,
      "name": "Empty"
    },
    {
      "x": -9,
      "y": -3,
      "z": -13,
      "name": "Empty"
    },
    {
      "x": -9,
      "y": -2,
      "z": -13,
      "name": "Empty"
    },
    {
      "x": -9,
      "y": -1,
      "z": -13,
      "name": "Empty"
    },
    {
      "x": -9,
      "y": 0,
      "z": -13,
      "name": "Empty"
    },
    {
      "x": -9,
      "y": 1,
      "z": -13,
      "name": "Empty"
    },
    {
      "x": -9,
      "y": 2,
      "z": -13,
      "name": "Empty"
    },
    {
      "x": -9,
      "y": -12,
      "z": -12,
      "name": "Rock_Stone"
    },
    {
      "x": -9,
      "y": -11,
      "z": -12,
      "name": "Rock_Stone"
    },
    {
      "x": -9,
      "y": -10,
