{
  "version": 8,
  "blockIdVersion": 8,
  "anchorX": 0,
  "anchorY": 0,
  "anchorZ": 0,
  "blocks": [
    {
      "x": -7,
      "y": -1,
      "z": 0,
      "name": "Rock_Stone"
    },
    {
      "x": -7,
      "y": 0,
      "z": 0,
      "name": "Rock_Stone"
    },
    {
      "x": -7,
      "y": 1,
      "z": 0,
      "name": "Rock_Stone"
    },
    {
      "x": -7,
      "y": 2,
      "z": 0,
      "name": "Rock_Stone"
    },
    {
      "x": -7,
      "y": 3,
      "z": 0,
      "name": "Rock_Stone"
    },
    {
      "x": -7,
      "y": 4,
      "z": 0,
      "name": "Rock_Stone"
    },
    {
      "x": -7,
      "y": 5,
      "z": 0,
      "name": "Rock_Stone"
    },
    {
      "x": -7,
      "y": 6,
      "z": 0,
      "name": "Rock_Stone"
    },
    {
      "x": -7,
      "y": 7,
      "z": 0,
      "name": "Rock_Stone"
    },
    {
      "x": -7,
      "y": 8,
      "z": 0,
      "name": "Rock_Stone"
    },
    {
      "x": -7,
      "y": 9,
      "z": 0,
      "name": "Rock_Stone"
    },
    {
      "x": -7,
      "y": 10,
      "z": 0,
      "name": "Rock_Stone"
    },
    {
      "x": -7,
      "y": -1,
      "z": 1,
      "name": "Rock_Stone"
    },
    {
      "x": -7,
      "y": 0,
      "z": 1,
      "name": "Rock_Stone"
    },
    {
      "x": -7,
      "y": 1,
      "z": 1,
      "name": "Rock_Stone"
    },
    {
      "x": -7,
      "y": 2,
      "z": 1,
      "name": "Rock_Stone"
    },
    {
      "x": -7,
      "y": 3,
      "z": 1,
      "name": "Rock_Stone"
    },
    {
      "x": -7,
      "y": 4,
      "z": 1,
      "name": "Rock_Stone"
    },
    {
      "x": -7,
      "y": 5,
      "z": 1,
      "name": "Rock_Stone"
    },
    {
      "x": -7,
      "y": 6,
      "z": 1,
      "name": "Rock_Stone"
    },
    {
      "x": -7,
      "y": 7,
      "z": 1,
      "name": "Rock_Stone"
    },
    {
      "x": -7,
      "y": 8,
      "z": 1,
      "name": "Rock_Stone"
    },
    {
      "x": -7,
      "y": 9,
      "z": 1,
      "name": "Rock_Stone"
    },
    {
      "x": -7,
      "y": 10,
      "z": 1,
      "name": "Rock_Stone"
    },
    {
      "x": -7,
      "y": -1,
      "z": 2,
      "name": "Rock_Stone"
    },
    {
      "x": -7,
      "y": 0,
      "z": 2,
      "name": "Rock_Stone"
    },
    {
      "x": -7,
      "y": 1,
      "z": 2,
      "name": "Rock_Stone"
    },
    {
      "x": -7,
      "y": 2,
      "z": 2,
      "name": "Rock_Stone"
    },
    {
      "x": -7,
      "y": 3,
      "z": 2,
      "name": "Rock_Stone"
    },
    {
      "x": -7,
      "y": 4,
      "z": 2,
      "name": "Rock_Stone"
    },
    {
      "x": -7,
      "y": 5,
      "z": 2,
      "name": "Rock_Stone"
    },
    {
      "x": -7,
      "y": 6,
      "z": 2,
      "name": "Rock_Stone"
    },
    {
      "x": -7,
      "y": 7,
      "z": 2,
      "name": "Rock_Stone"
    },
    {
      "x": -7,
      "y": 8,
      "z": 2,
      "name": "Rock_Stone"
    },
    {
      "x": -7,
      "y": 9,
      "z": 2,
      "name": "Rock_Stone"
    },
    {
      "x": -7,
      "y": 10,
      "z": 2,
      "name": "Rock_Stone"
    },
    {
      "x": -7,
      "y": -1,
      "z": 3,
      "name": "Rock_Stone"
    },
    {
      "x": -7,
      "y": 0,
      "z": 3,
      "name": "Rock_Stone"
    },
    {
      "x": -7,
      "y": 1,
      "z": 3,
      "name": "Rock_Stone"
    },
    {
      "x": -7,
      "y": 2,
      "z": 3,
      "name": "Rock_Stone"
    },
    {
      "x": -7,
      "y": 3,
      "z": 3,
      "name": "Rock_Stone"
    },
    {
      "x": -7,
      "y": 4,
      "z": 3,
      "name": "Rock_Stone"
    },
    {
      "x": -7,
      "y": 5,
      "z": 3,
      "name": "Rock_Stone"
    },
    {
      "x": -7,
      "y": 6,
      "z": 3,
      "name": "Rock_Stone"
    },
    {
      "x": -7,
      "y": 7,
      "z": 3,
      "name": "Rock_Stone"
    },
    {
      "x": -7,
      "y": 8,
      "z": 3,
      "name": "Rock_Stone"
    },
    {
      "x": -7,
      "y": 9,
      "z": 3,
      "name": "Rock_Stone"
    },
    {
      "x": -7,
      "y": 10,
      "z": 3,
      "name": "Rock_Stone"
    },
    {
      "x": -7,
      "y": -1,
      "z": 4,
      "name": "Rock_Stone"
    },
    {
      "x": -7,
      "y": 0,
      "z": 4,
      "name": "Rock_Stone"
    },
    {
      "x": -7,
      "y": 1,
      "z": 4,
      "name": "Rock_Stone"
    },
    {
      "x": -7,
      "y": 2,
      "z": 4,
      "name": "Rock_Stone"
    },
    {
      "x": -7,
      "y": 3,
      "z": 4,
      "name": "Rock_Stone"
    },
    {
      "x": -7,
      "y": 4,
      "z": 4,
      "name": "Rock_Stone"
    },
    {
      "x": -7,
      "y": 5,
      "z": 4,
      "name": "Rock_Stone"
    },
    {
      "x": -7,
      "y": 6,
      "z": 4,
      "name": "Rock_Stone"
    },
    {
      "x": -7,
      "y": 7,
      "z": 4,
      "name": "Rock_Stone"
    },
    {
      "x": -7,
      "y": 8,
      "z": 4,
      "name": "Rock_Stone"
    },
    {
      "x": -7,
      "y": 9,
      "z": 4,
      "name": "Rock_Stone"
    },
    {
      "x": -7,
      "y": 10,
      "z": 4,
      "name": "Rock_Stone"
    },
    {
      "x": -7,
      "y": -1,
      "z": 5,
      "name": "Rock_Stone"
    },
    {
      "x": -7,
      "y": 0,
      "z": 5,
      "name": "Rock_Stone"
    },
    {
      "x": -7,
      "y": 1,
      "z": 5,
      "name": "Rock_Stone"
    },
    {
      "x": -7,
      "y": 2,
      "z": 5,
      "name": "Rock_Stone"
    },
    {
      "x": -7,
      "y": 3,
      "z": 5,
      "name": "Rock_Stone"
    },
    {
      "x": -7,
      "y": 4,
      "z": 5,
      "name": "Rock_Stone"
    },
    {
      "x": -7,
      "y": 5,
      "z": 5,
      "name": "Rock_Stone"
    },
    {
      "x": -7,
      "y": 6,
      "z": 5,
      "name": "Rock_Stone"
    },
    {
      "x": -7,
      "y": 7,
      "z": 5,
      "name": "Rock_Stone"
    },
    {
      "x": -7,
      "y": 8,
      "z": 5,
      "name": "Rock_Stone"
    },
    {
      "x": -7,
      "y": 9,
      "z": 5,
      "name": "Rock_Stone"
    },
    {
      "x": -7,
      "y": 10,
      "z": 5,
      "name": "Rock_Stone"
    },
    {
      "x": -7,
      "y": -1,
      "z": 6,
      "name": "Rock_Stone"
    },
    {
      "x": -7,
      "y": 0,
      "z": 6,
      "name": "Rock_Stone"
    },
    {
      "x": -7,
      "y": 1,
      "z": 6,
      "name": "Rock_Stone"
    },
    {
      "x": -7,
      "y": 2,
      "z": 6,
      "name": "Rock_Stone"
    },
    {
      "x": -7,
      "y": 3,
      "z": 6,
      "name": "Rock_Stone"
    },
    {
      "x": -7,
      "y": 4,
      "z": 6,
      "name": "Rock_Stone"
    },
    {
      "x": -7,
      "y": 5,
      "z": 6,
      "name": "Rock_Stone"
    },
    {
      "x": -7,
      "y": 6,
      "z": 6,
      "name": "Rock_Stone"
    },
    {
      "x": -7,
      "y": 7,
      "z": 6,
      "name": "Rock_Stone"
    },
    {
      "x": -7,
      "y": 8,
      "z": 6,
      "name": "Rock_Stone"
    },
    {
      "x": -7,
      "y": 9,
      "z": 6,
      "name": "Rock_Stone"
    },
    {
      "x": -7,
      "y": 10,
      "z": 6,
      "name": "Rock_Stone"
    },
    {
      "x": -7,
      "y": -1,
      "z": 7,
      "name": "Rock_Stone"
    },
    {
      "x": -7,
      "y": 0,
      "z": 7,
      "name": "Rock_Stone"
    },
    {
      "x": -7,
      "y": 1,
      "z": 7,
      "name": "Rock_Stone"
    },
    {
      "x": -7,
      "y": 2,
      "z": 7,
      "name": "Rock_Stone"
    },
    {
      "x": -7,
      "y": 3,
      "z": 7,
      "name": "Rock_Stone"
    },
    {
      "x": -7,
      "y": 4,
      "z": 7,
      "name": "Rock_Stone"
    },
    {
      "x": -7,
      "y": 5,
      "z": 7,
      "name": "Rock_Stone"
    },
    {
      "x": -7,
      "y": 6,
      "z": 7,
      "name": "Rock_Stone"
    },
    {
      "x": -7,
      "y": 7,
      "z": 7,
      "name": "Rock_Stone"
    },
    {
      "x": -7,
      "y": 8,
      "z": 7,
      "name": "Rock_Stone"
    },
    {
      "x": -7,
      "y": 9,
      "z": 7,
      "name": "Rock_Stone"
    },
    {
      "x": -7,
      "y": 10,
      "z": 7,
      "name": "Rock_Stone"
    },
    {
      "x": -7,
      "y": -1,
      "z": 8,
      "name": "Rock_Stone"
    },
    {
      "x": -7,
      "y": 0,
      "z": 8,
      "name": "Rock_Stone"
    },
    {
      "x": -7,
      "y": 1,
      "z": 8,
      "name": "Rock_Stone"
    },
    {
      "x": -7,
      "y": 2,
      "z": 8,
      "name": "Rock_Stone"
    },
    {
      "x": -7,
      "y": 3,
      "z": 8,
      "name": "Rock_Stone"
    },
    {
      "x": -7,
      "y": 4,
      "z": 8,
      "name": "Rock_Stone"
    },
    {
      "x": -7,
      "y": 5,
      "z": 8,
      "name": "Rock_Stone"
    },
    {
      "x": -7,
      "y": 6,
      "z": 8,
      "name": "Rock_Stone"
    },
    {
      "x": -7,
      "y": 7,
      "z": 8,
      "name": "Rock_Stone"
    },
    {
      "x": -7,
      "y": 8,
      "z": 8,
      "name": "Rock_Stone"
    },
    {
      "x": -7,
      "y": 9,
      "z": 8,
      "name": "Rock_Stone"
    },
    {
      "x": -7,
      "y": 10,
      "z": 8,
      "name": "Rock_Stone"
    },
    {
      "x": -7,
      "y": -1,
      "z": 9,
      "name": "Rock_Stone"
    },
    {
      "x": -7,
      "y": 0,
      "z": 9,
      "name": "Rock_Stone"
    },
    {
      "x": -7,
      "y": 1,
      "z": 9,
      "name": "Rock_Stone"
    },
    {
      "x": -7,
      "y": 2,
      "z": 9,
      "name": "Rock_Stone"
    },
    {
      "x": -7,
      "y": 3,
      "z": 9,
      "name": "Rock_Stone"
    },
    {
      "x": -7,
      "y": 4,
      "z": 9,
      "name": "Rock_Stone"
    },
    {
      "x": -7,
      "y": 5,
      "z": 9,
      "name": "Rock_Stone"
    },
    {
      "x": -7,
      "y": 6,
      "z": 9,
      "name": "Rock_Stone"
    },
    {
      "x": -7,
      "y": 7,
      "z": 9,
      "name": "Rock_Stone"
    },
    {
      "x": -7,
      "y": 8,
      "z": 9,
      "name": "Rock_Stone"
    },
    {
      "x": -7,
      "y": 9,
      "z": 9,
      "name": "Rock_Stone"
    },
    {
      "x": -7,
      "y": 10,
      "z": 9,
      "name": "Rock_Stone"
    },
    {
      "x": -7,
      "y": -1,
      "z": 10,
      "name": "Rock_Stone"
    },
    {
      "x": -7,
      "y": 0,
      "z": 10,
      "name": "Rock_Stone"
    },
    {
      "x": -7,
      "y": 1,
      "z": 10,
      "name": "Rock_Stone"
    },
    {
      "x": -7,
      "y": 2,
      "z": 10,
      "name": "Rock_Stone"
    },
    {
      "x": -7,
      "y": 3,
      "z": 10,
      "name": "Rock_Stone"
    },
    {
      "x": -7,
      "y": 4,
      "z": 10,
      "name": "Rock_Stone"
    },
    {
      "x": -7,
      "y": 5,
      "z": 10,
      "name": "Rock_Stone"
    },
    {
      "x": -7,
      "y": 6,
      "z": 10,
      "name": "Rock_Stone"
    },
    {
      "x": -7,
      "y": 7,
      "z": 10,
      "name": "Rock_Stone"
    },
    {
      "x": -7,
      "y": 8,
      "z": 10,
      "name": "Rock_Stone"
    },
    {
      "x": -7,
      "y": 9,
      "z": 10,
      "name": "Rock_Stone"
    },
    {
      "x": -7,
      "y": 10,
      "z": 10,
      "name": "Rock_Stone"
    },
    {
      "x": -7,
      "y": -1,
      "z": 11,
      "name": "Rock_Stone"
    },
    {
      "x": -7,
      "y": 0,
      "z": 11,
      "name": "Rock_Stone"
    },
    {
      "x": -7,
      "y": 1,
      "z": 11,
      "name": "Rock_Stone"
    },
    {
      "x": -7,
      "y": 2,
      "z": 11,
      "name": "Rock_Stone"
    },
    {
      "x": -7,
      "y": 3,
      "z": 11,
      "name": "Rock_Stone"
    },
    {
      "x": -7,
      "y": 4,
      "z": 11,
      "name": "Rock_Stone"
    },
    {
      "x": -7,
      "y": 5,
      "z": 11,
      "name": "Rock_Stone"
    },
    {
      "x": -7,
      "y": 6,
      "z": 11,
      "name": "Rock_Stone"
    },
    {
      "x": -7,
      "y": 7,
      "z": 11,
      "name": "Rock_Stone"
    },
    {
      "x": -7,
      "y": 8,
      "z": 11,
      "name": "Rock_Stone"
    },
    {
      "x": -7,
      "y": 9,
      "z": 11,
      "name": "Rock_Stone"
    },
    {
      "x": -7,
      "y": 10,
      "z": 11,
      "name": "Rock_Stone"
    },
    {
      "x": -7,
      "y": -1,
      "z": 12,
      "name": "Rock_Stone"
    },
    {
      "x": -7,
      "y": 0,
      "z": 12,
      "name": "Rock_Stone"
    },
    {
      "x": -7,
      "y": 1,
      "z": 12,
      "name": "Rock_Stone"
    },
    {
      "x": -7,
      "y": 2,
      "z": 12,
      "name": "Rock_Stone"
    },
    {
      "x": -7,
      "y": 3,
      "z": 12,
      "name": "Rock_Stone"
    },
    {
      "x": -7,
      "y": 4,
      "z": 12,
      "name": "Rock_Stone"
    },
    {
      "x": -7,
      "y": 5,
      "z": 12,
      "name": "Rock_Stone"
    },
    {
      "x": -7,
      "y": 6,
      "z": 12,
      "name": "Rock_Stone"
    },
    {
      "x": -7,
      "y": 7,
      "z": 12,
      "name": "Rock_Stone"
    },
    {
      "x": -7,
      "y": 8,
      "z": 12,
      "name": "Rock_Stone"
    },
    {
      "x": -7,
      "y": 9,
      "z": 12,
      "name": "Rock_Stone"
    },
    {
      "x": -7,
      "y": 10,
      "z": 12,
      "name": "Rock_Stone"
    },
    {
      "x": -7,
      "y": -1,
      "z": 13,
      "name": "Rock_Stone"
    },
    {
      "x": -7,
      "y": 0,
      "z": 13,
      "name": "Rock_Stone"
    },
    {
      "x": -7,
      "y": 1,
      "z": 13,
      "name": "Rock_Stone"
    },
    {
      "x": -7,
      "y": 2,
      "z": 13,
      "name": "Rock_Stone"
    },
    {
      "x": -7,
      "y": 3,
      "z": 13,
      "name": "Rock_Stone"
    },
    {
      "x": -7,
      "y": 4,
      "z": 13,
      "name": "Rock_Stone"
    },
    {
      "x": -7,
      "y": 5,
      "z": 13,
      "name": "Rock_Stone"
    },
    {
      "x": -7,
      "y": 6,
      "z": 13,
      "name": "Rock_Stone"
    },
    {
      "x": -7,
      "y": 7,
      "z": 13,
      "name": "Rock_Stone"
    },
    {
      "x": -7,
      "y": 8,
      "z": 13,
      "name": "Rock_Stone"
    },
    {
      "x": -7,
      "y": 9,
      "z": 13,
      "name": "Rock_Stone"
    },
    {
      "x": -7,
      "y": 10,
      "z": 13,
      "name": "Rock_Stone"
    },
    {
      "x": -7,
      "y": -1,
      "z": 14,
      "name": "Rock_Stone"
    },
    {
      "x": -7,
      "y": 0,
      "z": 14,
      "name": "Rock_Stone"
    },
    {
      "x": -7,
      "y": 1,
      "z": 14,
      "name": "Rock_Stone"
    },
    {
      "x": -7,
      "y": 2,
      "z": 14,
      "name": "Rock_Stone"
    },
    {
      "x": -7,
      "y": 3,
      "z": 14,
      "name": "Rock_Stone"
    },
    {
      "x": -7,
      "y": 4,
      "z": 14,
      "name": "Rock_Stone"
    },
    {
      "x": -7,
      "y": 5,
      "z": 14,
      "name": "Rock_Stone"
    },
    {
      "x": -7,
      "y": 6,
      "z": 14,
      "name": "Rock_Stone"
    },
    {
      "x": -7,
      "y": 7,
      "z": 14,
      "name": "Rock_Stone"
    },
    {
      "x": -7,
      "y": 8,
      "z": 14,
      "name": "Rock_Stone"
    },
    {
      "x": -7,
      "y": 9,
      "z": 14,
      "name": "Rock_Stone"
    },
    {
      "x": -7,
      "y": 10,
      "z": 14,
      "name": "Rock_Stone"
    },
    {
      "x": -6,
      "y": -1,
      "z": 0,
      "name": "Rock_Stone"
    },
    {
      "x": -6,
      "y": 0,
      "z": 0,
      "name": "Rock_Stone"
    },
    {
      "x": -6,
      "y": 1,
      "z": 0,
      "name": "Rock_Stone"
    },
    {
      "x": -6,
      "y": 2,
      "z": 0,
      "name": "Rock_Stone"
    },
    {
      "x": -6,
      "y": 3,
      "z": 0,
      "name": "Rock_Stone"
    },
    {
      "x": -6,
      "y": 4,
      "z": 0,
      "name": "Rock_Stone"
    },
    {
      "x": -6,
      "y": 5,
      "z": 0,
      "name": "Rock_Stone"
    },
    {
      "x": -6,
      "y": 6,
      "z": 0,
      "name": "Rock_Stone"
    },
    {
      "x": -6,
      "y": 7,
      "z": 0,
      "name": "Rock_Stone"
    },
    {
      "x": -6,
      "y": 8,
      "z": 0,
      "name": "Rock_Stone"
    },
    {
      "x": -6,
      "y": 9,
      "z": 0,
      "name": "Rock_Stone"
    },
    {
      "x": -6,
      "y": 10,
      "z": 0,
      "name": "Rock_Stone"
    },
    {
      "x": -6,
      "y": -1,
      "z": 1,
      "name": "Rock_Stone"
    },
    {
      "x": -6,
      "y": 0,
      "z": 1,
      "name": "Rock_Stone"
    },
    {
      "x": -6,
      "y": 1,
      "z": 1,
      "name": "Rock_Stone"
    },
    {
      "x": -6,
      "y": 2,
      "z": 1,
      "name": "Rock_Stone"
    },
    {
      "x": -6,
      "y": 3,
      "z": 1,
      "name": "Rock_Stone"
    },
    {
      "x": -6,
      "y": 4,
      "z": 1,
      "name": "Rock_Stone"
    },
    {
      "x": -6,
      "y": 5,
      "z": 1,
      "name": "Rock_Stone"
    },
    {
      "x": -6,
      "y": 6,
      "z": 1,
      "name": "Rock_Stone"
    },
    {
      "x": -6,
      "y": 7,
      "z": 1,
      "name": "Rock_Stone"
    },
    {
      "x": -6,
      "y": 8,
      "z": 1,
      "name": "Rock_Stone"
    },
    {
      "x": -6,
      "y": 9,
      "z": 1,
      "name": "Rock_Stone"
    },
    {
      "x": -6,
      "y": 10,
      "z": 1,
      "name": "Rock_Stone"
    },
    {
      "x": -6,
      "y": -1,
      "z": 2,
      "name": "Rock_Stone"
    },
    {
      "x": -6,
      "y": 0,
      "z": 2,
      "name": "Rock_Stone"
    },
    {
      "x": -6,
      "y": 1,
      "z": 2,
      "name": "Rock_Stone"
    },
    {
      "x": -6,
      "y": 2,
      "z": 2,
      "name": "Rock_Stone"
    },
    {
      "x": -6,
      "y": 3,
      "z": 2,
      "name": "Rock_Stone"
    },
    {
      "x": -6,
      "y": 4,
      "z": 2,
      "name": "Rock_Stone"
    },
    {
      "x": -6,
      "y": 5,
      "z": 2,
      "name": "Rock_Stone"
    },
    {
      "x": -6,
      "y": 6,
      "z": 2,
      "name": "Rock_Stone"
    },
    {
      "x": -6,
      "y": 7,
      "z": 2,
      "name": "Rock_Stone"
    },
    {
      "x": -6,
      "y": 8,
      "z": 2,
      "name": "Rock_Stone"
    },
    {
      "x": -6,
      "y": 9,
      "z": 2,
      "name": "Rock_Stone"
    },
    {
      "x": -6,
      "y": 10,
      "z": 2,
      "name": "Rock_Stone"
    },
    {
      "x": -6,
      "y": -1,
      "z": 3,
      "name": "Rock_Stone"
    },
    {
      "x": -6,
      "y": 0,
      "z": 3,
      "name": "Rock_Stone"
    },
    {
      "x": -6,
      "y": 1,
      "z": 3,
      "name": "Rock_Stone"
    },
    {
      "x": -6,
      "y": 2,
      "z": 3,
      "name": "Rock_Stone"
    },
    {
      "x": -6,
      "y": 3,
      "z": 3,
      "name": "Rock_Stone"
    },
    {
      "x": -6,
      "y": 4,
      "z": 3,
      "name": "Rock_Stone"
    },
    {
      "x": -6,
      "y": 5,
      "z": 3,
      "name": "Rock_Stone"
    },
    {
      "x": -6,
      "y": 6,
      "z": 3,
      "name": "Rock_Stone"
    },
    {
      "x": -6,
      "y": 7,
      "z": 3,
      "name": "Rock_Stone"
    },
    {
      "x": -6,
      "y": 8,
      "z": 3,
      "name": "Rock_Stone"
    },
    {
      "x": -6,
      "y": 9,
      "z": 3,
      "name": "Rock_Stone"
    },
    {
      "x": -6,
      "y": 10,
      "z": 3,
      "name": "Rock_Stone"
    },
    {
      "x": -6,
      "y": -1,
      "z": 4,
      "name": "Rock_Stone"
    },
    {
      "x": -6,
      "y": 0,
      "z": 4,
      "name": "Rock_Stone"
    },
    {
      "x": -6,
      "y": 1,
      "z": 4,
      "name": "Rock_Stone"
    },
    {
      "x": -6,
      "y": 2,
      "z": 4,
      "name": "Rock_Stone"
    },
    {
      "x": -6,
      "y": 3,
      "z": 4,
      "name": "Rock_Stone"
    },
    {
      "x": -6,
      "y": 4,
      "z": 4,
      "name": "Rock_Stone"
    },
    {
      "x": -6,
      "y": 5,
      "z": 4,
      "name": "Rock_Stone"
    },
    {
      "x": -6,
      "y": 6,
      "z": 4,
      "name": "Rock_Stone"
    },
    {
      "x": -6,
      "y": 7,
      "z": 4,
      "name": "Rock_Stone"
    },
    {
      "x": -6,
      "y": 8,
      "z": 4,
      "name": "Rock_Stone"
    },
    {
      "x": -6,
      "y": 9,
      "z": 4,
      "name": "Rock_Stone"
    },
    {
      "x": -6,
      "y": 10,
      "z": 4,
      "name": "Rock_Stone"
    },
    {
      "x": -6,
      "y": -1,
      "z": 5,
      "name": "Rock_Stone"
    },
    {
      "x": -6,
      "y": 0,
      "z": 5,
      "name": "Rock_Stone"
    },
    {
      "x": -6,
      "y": 1,
      "z": 5,
      "name": "Rock_Stone"
    },
    {
      "x": -6,
      "y": 2,
      "z": 5,
      "name": "Rock_Stone"
    },
    {
      "x": -6,
      "y": 3,
      "z": 5,
      "name": "Rock_Stone"
    },
    {
      "x": -6,
      "y": 4,
      "z": 5,
      "name": "Rock_Stone"
    },
    {
      "x": -6,
      "y": 5,
      "z": 5,
      "name": "Rock_Stone"
    },
    {
      "x": -6,
      "y": 6,
      "z": 5,
      "name": "Rock_Stone"
    },
    {
      "x": -6,
      "y": 7,
      "z": 5,
      "name": "Rock_Stone"
    },
    {
      "x": -6,
      "y": 8,
      "z": 5,
      "name": "Rock_Stone"
    },
    {
      "x": -6,
      "y": 9,
      "z": 5,
      "name": "Rock_Stone"
    },
    {
      "x": -6,
      "y": 10,
      "z": 5,
      "name": "Rock_Stone"
    },
    {
      "x": -6,
      "y": -1,
      "z": 6,
      "name": "Rock_Stone"
    },
    {
      "x": -6,
      "y": 0,
      "z": 6,
      "name": "Rock_Stone"
    },
    {
      "x": -6,
      "y": 1,
      "z": 6,
      "name": "Rock_Stone"
    },
    {
      "x": -6,
      "y": 2,
      "z": 6,
      "name": "Rock_Stone_Cobble"
    },
    {
      "x": -6,
      "y": 3,
      "z": 6,
      "name": "Rock_Stone_Cobble"
    },
    {
      "x": -6,
      "y": 4,
      "z": 6,
      "name": "Rock_Stone"
    },
    {
      "x": -6,
      "y": 5,
      "z": 6,
      "name": "Rock_Stone"
    },
    {
      "x": -6,
      "y": 6,
      "z": 6,
      "name": "Rock_Stone"
    },
    {
      "x": -6,
      "y": 7,
      "z": 6,
      "name": "Rock_Stone"
    },
    {
      "x": -6,
      "y": 8,
      "z": 6,
      "name": "Rock_Stone"
    },
    {
      "x": -6,
      "y": 9,
      "z": 6,
      "name": "Rock_Stone"
    },
    {
      "x": -6,
      "y": 10,
      "z": 6,
      "name": "Rock_Stone"
    },
    {
      "x": -6,
      "y": -1,
      "z": 7,
      "name": "Rock_Stone"
    },
    {
      "x": -6,
      "y": 0,
      "z": 7,
      "name": "Rock_Stone"
    },
    {
      "x": -6,
      "y": 1,
      "z": 7,
      "name": "Rock_Stone"
    },
    {
      "x": -6,
      "y": 2,
      "z": 7,
      "name": "Rock_Stone_Cobble"
    },
    {
      "x": -6,
      "y": 3,
      "z": 7,
      "name": "Rock_Stone_Cobble"
    },
    {
      "x": -6,
      "y": 4,
      "z": 7,
      "name": "Plant_Moss_Rug_Yellow"
    },
    {
      "x": -6,
      "y": 5,
      "z": 7,
      "name": "Empty"
    },
    {
      "x": -6,
      "y": 6,
      "z": 7,
      "name": "Empty"
    },
    {
      "x": -6,
      "y": 7,
      "z": 7,
      "name": "Rock_Stone"
    },
    {
      "x": -6,
      "y": 8,
      "z": 7,
      "name": "Rock_Stone"
    },
    {
      "x": -6,
      "y": 9,
      "z": 7,
      "name": "Rock_Stone"
    },
    {
      "x": -6,
      "y": 10,
      "z": 7,
      "name": "Rock_Stone"
    },
    {
      "x": -6,
      "y": -1,
      "z": 8,
      "name": "Rock_Stone"
    },
    {
      "x": -6,
      "y": 0,
      "z": 8,
      "name": "Rock_Stone"
    },
    {
      "x": -6,
      "y": 1,
      "z": 8,
      "name": "Rock_Stone"
    },
    {
      "x": -6,
      "y": 2,
      "z": 8,
      "name": "Rock_Stone_Cobble"
    },
    {
      "x": -6,
      "y": 3,
      "z": 8,
      "name": "Rock_Stone_Cobble"
    },
    {
      "x": -6,
      "y": 4,
      "z": 8,
      "name": "Empty"
    },
    {
      "x": -6,
      "y": 5,
      "z": 8,
      "name": "Empty"
    },
    {
      "x": -6,
      "y": 6,
      "z": 8,
      "name": "Empty"
    },
    {
      "x": -6,
      "y": 7,
      "z": 8,
      "name": "Rock_Stone"
    },
    {
      "x": -6,
      "y": 8,
      "z": 8,
      "name": "Rock_Stone"
    },
    {
      "x": -6,
      "y": 9,
      "z": 8,
      "name": "Rock_Stone"
    },
    {
      "x": -6,
      "y": 10,
      "z": 8,
      "name": "Rock_Stone"
    },
    {
      "x": -6,
      "y": -1,
      "z": 9,
      "name": "Rock_Stone"
    },
    {
      "x": -6,
      "y": 0,
      "z": 9,
      "name": "Rock_Stone"
    },
    {
      "x": -6,
      "y": 1,
      "z": 9,
      "name": "Rock_Stone"
    },
    {
      "x": -6,
      "y": 2,
      "z": 9,
      "name": "Wood_Softwood_Planks"
    },
    {
      "x": -6,
      "y": 3,
      "z": 9,
      "name": "Rock_Stone_Cobble_Wall",
      "rotation": 1
    },
    {
      "x": -6,
      "y": 4,
      "z": 9,
      "name": "Empty"
    },
    {
      "x": -6,
      "y": 5,
      "z": 9,
      "name": "Empty"
    },
    {
      "x": -6,
      "y": 6,
      "z": 9,
      "name": "Rock_Stone"
    },
    {
      "x": -6,
      "y": 7,
      "z": 9,
      "name": "Rock_Stone"
    },
    {
      "x": -6,
      "y": 8,
      "z": 9,
      "name": "Rock_Stone"
    },
    {
      "x": -6,
      "y": 9,
      "z": 9,
      "name": "Rock_Stone"
    },
    {
      "x": -6,
      "y": 10,
      "z": 9,
      "name": "Rock_Stone"
    },
    {
      "x": -6,
      "y": -1,
      "z": 10,
      "name": "Rock_Stone"
    },
    {
      "x": -6,
      "y": 0,
      "z": 10,
      "name": "Rock_Stone"
    },
    {
      "x": -6,
      "y": 1,
      "z": 10,
      "name": "Rock_Stone"
    },
    {
      "x": -6,
      "y": 2,
      "z": 10,
      "name": "Wood_Softwood_Planks"
    },
    {
      "x": -6,
      "y": 3,
      "z": 10,
      "name": "Rock_Stone_Cobble_Wall",
      "rotation": 1
    },
    {
      "x": -6,
      "y": 4,
      "z": 10,
      "name": "Empty"
    },
    {
      "x": -6,
      "y": 5,
      "z": 10,
      "name": "Empty"
    },
    {
      "x": -6,
      "y": 6,
      "z": 10,
      "name": "Rock_Stone"
    },
    {
      "x": -6,
      "y": 7,
      "z": 10,
      "name": "Rock_Stone"
    },
    {
      "x": -6,
      "y": 8,
      "z": 10,
      "name": "Rock_Stone"
    },
    {
      "x": -6,
      "y": 9,
      "z": 10,
      "name": "Rock_Stone"
    },
    {
      "x": -6,
      "y": 10,
      "z": 10,
      "name": "Rock_Stone"
    },
    {
      "x": -6,
      "y": -1,
      "z": 11,
      "name": "Rock_Stone"
    },
    {
      "x": -6,
      "y": 0,
      "z": 11,
      "name": "Rock_Stone"
    },
    {
      "x": -6,
      "y": 1,
      "z": 11,
      "name": "Rock_Stone"
    },
    {
      "x": -6,
      "y": 2,
      "z": 11,
      "name": "Rock_Stone"
    },
    {
      "x": -6,
      "y": 3,
      "z": 11,
      "name": "Rock_Stone"
    },
    {
      "x": -6,
      "y": 4,
      "z": 11,
      "name": "Rock_Stone"
    },
    {
      "x": -6,
      "y": 5,
      "z": 11,
      "name": "Rock_Stone"
    },
    {
      "x": -6,
      "y": 6,
      "z": 11,
      "name": "Rock_Stone"
    },
    {
      "x": -6,
      "y": 7,
      "z": 11,
      "name": "Rock_Stone"
    },
    {
      "x": -6,
      "y": 8,
      "z": 11,
      "name": "Rock_Stone"
    },
    {
      "x": -6,
      "y": 9,
      "z": 11,
      "name": "Rock_Stone"
    },
    {
      "x": -6,
      "y": 10,
      "z": 11,
      "name": "Rock_Stone"
    },
    {
      "x": -6,
      "y": -1,
      "z": 12,
      "name": "Rock_Stone"
    },
    {
      "x": -6,
      "y": 0,
      "z": 12,
      "name": "Rock_Stone"
    },
    {
      "x": -6,
      "y": 1,
      "z": 12,
      "name": "Rock_Stone"
    },
    {
      "x": -6,
      "y": 2,
      "z": 12,
      "name": "Rock_Stone"
    },
    {
      "x": -6,
      "y": 3,
      "z": 12,
      "name": "Rock_Stone"
    },
    {
      "x": -6,
      "y": 4,
      "z": 12,
      "name": "Rock_Stone"
    },
    {
      "x": -6,
      "y": 5,
      "z": 12,
      "name": "Rock_Stone"
    },
    {
      "x": -6,
      "y": 6,
      "z": 12,
      "name": "Rock_Stone"
    },
    {
      "x": -6,
      "y": 7,
      "z": 12,
      "name": "Rock_Stone"
    },
    {
      "x": -6,
      "y": 8,
      "z": 12,
      "name": "Rock_Stone"
    },
    {
      "x": -6,
      "y": 9,
      "z": 12,
      "name": "Rock_Stone"
    },
    {
      "x": -6,
      "y": 10,
      "z": 12,
      "name": "Rock_Stone"
    },
    {
      "x": -6,
      "y": -1,
      "z": 13,
      "name": "Rock_Stone"
    },
    {
      "x": -6,
      "y": 0,
      "z": 13,
      "name": "Rock_Stone"
    },
    {
      "x": -6,
      "y": 1,
      "z": 13,
      "name": "Rock_Stone"
    },
    {
      "x": -6,
      "y": 2,
      "z": 13,
      "name": "Rock_Stone"
    },
    {
      "x": -6,
      "y": 3,
      "z": 13,
      "name": "Rock_Stone"
    },
    {
      "x": -6,
      "y": 4,
      "z": 13,
      "name": "Rock_Stone"
    },
    {
      "x": -6,
      "y": 5,
      "z": 13,
      "name": "Rock_Stone"
    },
    {
      "x": -6,
      "y": 6,
      "z": 13,
      "name": "Rock_Stone"
    },
    {
      "x": -6,
      "y": 7,
      "z": 13,
      "name": "Rock_Stone"
    },
    {
      "x": -6,
      "y": 8,
      "z": 13,
      "name": "Rock_Stone"
    },
    {
      "x": -6,
      "y": 9,
      "z": 13,
      "name": "Rock_Stone"
    },
    {
      "x": -6,
      "y": 10,
      "z": 13,
      "name": "Rock_Stone"
    },
    {
      "x": -6,
      "y": -1,
      "z": 14,
      "name": "Rock_Stone"
    },
    {
      "x": -6,
      "y": 0,
      "z": 14,
      "name": "Rock_Stone"
    },
    {
      "x": -6,
      "y": 1,
      "z": 14,
      "name": "Rock_Stone"
    },
    {
      "x": -6,
      "y": 2,
      "z": 14,
      "name": "Rock_Stone"
    },
    {
      "x": -6,
      "y": 3,
      "z": 14,
      "name": "Rock_Stone"
    },
    {
      "x": -6,
      "y": 4,
      "z": 14,
      "name": "Rock_Stone"
    },
    {
      "x": -6,
      "y": 5,
      "z": 14,
      "name": "Rock_Stone"
    },
    {
      "x": -6,
      "y": 6,
      "z": 14,
      "name": "Rock_Stone"
    },
    {
      "x": -6,
      "y": 7,
      "z": 14,
      "name": "Rock_Stone"
    },
    {
      "x": -6,
      "y": 8,
      "z": 14,
      "name": "Rock_Stone"
    },
    {
      "x": -6,
      "y": 9,
      "z": 14,
      "name": "Rock_Stone"
    },
    {
      "x": -6,
      "y": 10,
      "z": 14,
      "name": "Rock_Stone"
    },
    {
      "x": -5,
      "y": -1,
      "z": 0,
      "name": "Rock_Stone"
    },
    {
      "x": -5,
      "y": 0,
      "z": 0,
      "name": "Rock_Stone"
    },
    {
      "x": -5,
      "y": 1,
      "z": 0,
      "name": "Rock_Stone"
    },
    {
      "x": -5,
      "y": 2,
      "z": 0,
      "name": "Rock_Stone"
    },
    {
      "x": -5,
      "y": 3,
      "z": 0,
      "name": "Rock_Stone"
    },
    {
      "x": -5,
      "y": 4,
      "z": 0,
      "name": "Rock_Stone"
    },
    {
      "x": -5,
      "y": 5,
      "z": 0,
      "name": "Rock_Stone"
    },
    {
      "x": -5,
      "y": 6,
      "z": 0,
      "name": "Rock_Stone"
    },
    {
      "x": -5,
      "y": 7,
      "z": 0,
      "name": "Rock_Stone"
    },
    {
      "x": -5,
      "y": 8,
      "z": 0,
      "name": "Rock_Stone"
    },
    {
      "x": -5,
      "y": 9,
      "z": 0,
      "name": "Rock_Stone"
    },
    {
      "x": -5,
      "y": 10,
      "z": 0,
      "name": "Rock_Stone"
    },
    {
      "x": -5,
      "y": -1,
      "z": 1,
      "name": "Rock_Stone"
    },
    {
      "x": -5,
      "y": 0,
      "z": 1,
      "name": "Rock_Stone"
    },
    {
      "x": -5,
      "y": 1,
      "z": 1,
      "name": "Rock_Stone"
    },
    {
      "x": -5,
      "y": 2,
      "z": 1,
      "name": "Rock_Stone"
    },
    {
      "x": -5,
      "y": 3,
      "z": 1,
      "name": "Rock_Stone"
    },
    {
      "x": -5,
      "y": 4,
      "z": 1,
      "name": "Rock_Stone"
    },
    {
      "x": -5,
      "y": 5,
      "z": 1,
      "name": "Rock_Stone"
    },
    {
      "x": -5,
      "y": 6,
      "z": 1,
      "name": "Rock_Stone"
    },
    {
      "x": -5,
      "y": 7,
      "z": 1,
      "name": "Rock_Stone"
    },
    {
      "x": -5,
      "y": 8,
      "z": 1,
      "name": "Rock_Stone"
    },
    {
      "x": -5,
      "y": 9,
      "z": 1,
      "name": "Rock_Stone"
    },
    {
      "x": -5,
      "y": 10,
      "z": 1,
      "name": "Rock_Stone"
    },
    {
      "x": -5,
      "y": -1,
      "z": 2,
      "name": "Rock_Stone"
    },
    {
      "x": -5,
      "y": 0,
      "z": 2,
      "name": "Rock_Stone"
    },
    {
      "x": -5,
      "y": 1,
      "z": 2,
      "name": "Rock_Stone"
    },
    {
      "x": -5,
      "y": 2,
      "z": 2,
      "name": "Rock_Stone"
    },
    {
      "x": -5,
      "y": 3,
      "z": 2,
      "name": "Rock_Stone"
    },
    {
      "x": -5,
      "y": 4,
      "z": 2,
      "name": "Rock_Stone"
    },
    {
      "x": -5,
      "y": 5,
      "z": 2,
      "name": "Rock_Stone"
    },
    {
      "x": -5,
      "y": 6,
      "z": 2,
      "name": "Rock_Stone"
    },
    {
      "x": -5,
      "y": 7,
      "z": 2,
      "name": "Rock_Stone"
    },
    {
      "x": -5,
      "y": 8,
      "z": 2,
      "name": "Rock_Stone"
    },
    {
      "x": -5,
      "y": 9,
      "z": 2,
      "name": "Rock_Stone"
    },
    {
      "x": -5,
      "y": 10,
      "z": 2,
      "name": "Rock_Stone"
    },
    {
      "x": -5,
      "y": -1,
      "z": 3,
      "name": "Rock_Stone"
    },
    {
      "x": -5,
      "y": 0,
      "z": 3,
      "name": "Rock_Stone"
    },
    {
      "x": -5,
      "y": 1,
      "z": 3,
      "name": "Rock_Stone"
    },
    {
      "x": -5,
      "y": 2,
      "z": 3,
      "name": "Rock_Stone"
    },
    {
      "x": -5,
      "y": 3,
      "z": 3,
      "name": "Rock_Stone_Cobble"
    },
    {
      "x": -5,
      "y": 4,
      "z": 3,
      "name": "Rock_Stone_Cobble"
    },
    {
      "x": -5,
      "y": 5,
      "z": 3,
      "name": "Rock_Stone"
    },
    {
      "x": -5,
      "y": 6,
      "z": 3,
      "name": "Rock_Stone"
    },
    {
      "x": -5,
      "y": 7,
      "z": 3,
      "name": "Rock_Stone"
    },
    {
      "x": -5,
      "y": 8,
      "z": 3,
      "name": "Rock_Stone"
    },
    {
      "x": -5,
      "y": 9,
      "z": 3,
      "name": "Rock_Stone"
    },
    {
      "x": -5,
      "y": 10,
      "z": 3,
      "name": "Rock_Stone"
    },
    {
      "x": -5,
      "y": -1,
      "z": 4,
      "name": "Rock_Stone"
    },
    {
      "x": -5,
      "y": 0,
      "z": 4,
      "name": "Rock_Stone"
    },
    {
      "x": -5,
      "y": 1,
      "z": 4,
      "name": "Rock_Stone"
    },
    {
      "x": -5,
      "y": 2,
      "z": 4,
      "name": "Rock_Stone_Cobble"
    },
    {
      "x": -5,
      "y": 3,
      "z": 4,
      "name": "Rock_Stone_Cobble"
    },
    {
      "x": -5,
      "y": 4,
      "z": 4,
      "name": "Rock_Stone_Cobble"
    },
    {
      "x": -5,
      "y": 5,
      "z": 4,
      "name": "Empty"
    },
    {
      "x": -5,
      "y": 6,
      "z": 4,
      "name": "Empty"
    },
    {
      "x": -5,
      "y": 7,
      "z": 4,
      "name": "Rock_Stone"
    },
    {
      "x": -5,
      "y": 8,
      "z": 4,
      "name": "Rock_Stone"
    },
    {
      "x": -5,
      "y": 9,
      "z": 4,
      "name": "Rock_Stone"
    },
    {
      "x": -5,
      "y": 10,
      "z": 4,
      "name": "Rock_Stone"
    },
    {
      "x": -5,
      "y": -1,
      "z": 5,
      "name": "Rock_Stone"
    },
    {
      "x": -5,
      "y": 0,
      "z": 5,
      "name": "Rock_Stone"
    },
    {
      "x": -5,
      "y": 1,
      "z": 5,
      "name": "Rock_Stone"
    },
    {
      "x": -5,
      "y": 2,
      "z": 5,
      "name": "Rock_Stone_Cobble"
    },
    {
      "x": -5,
      "y": 3,
      "z": 5,
      "name": "Rock_Stone_Cobble"
    },
    {
      "x": -5,
      "y": 4,
      "z": 5,
      "name": "Rock_Stone_Cobble"
    },
    {
      "x": -5,
      "y": 5,
      "z": 5,
      "name": "Plant_Moss_Rug_Yellow"
    },
    {
      "x": -5,
      "y": 6,
      "z": 5,
      "name": "Empty"
    },
    {
      "x": -5,
      "y": 7,
      "z": 5,
      "name": "Empty"
    },
    {
      "x": -5,
      "y": 8,
      "z": 5,
      "name": "Empty"
    },
    {
      "x": -5,
      "y": 9,
      "z": 5,
      "name": "Rock_Stone"
    },
    {
      "x": -5,
      "y": 10,
      "z": 5,
      "name": "Rock_Stone"
    },
    {
      "x": -5,
      "y": -1,
      "z": 6,
      "name": "Rock_Stone"
    },
    {
      "x": -5,
      "y": 0,
      "z": 6,
      "name": "Rock_Stone"
    },
    {
      "x": -5,
      "y": 1,
      "z": 6,
      "name": "Rock_Stone"
    },
    {
      "x": -5,
      "y": 2,
      "z": 6,
      "name": "Rock_Stone_Cobble"
    },
    {
      "x": -5,
      "y": 3,
      "z": 6,
      "name": "Rock_Stone_Cobble"
    },
    {
      "x": -5,
      "y": 4,
      "z": 6,
      "name": "Plant_Moss_Rug_Yellow"
    },
    {
      "x": -5,
      "y": 5,
      "z": 6,
      "name": "Empty"
    },
    {
      "x": -5,
      "y": 6,
      "z": 6,
      "name": "Empty"
    },
    {
      "x": -5,
      "y": 7,
      "z": 6,
      "name": "Empty"
    },
    {
      "x": -5,
      "y": 8,
      "z": 6,
      "name": "Rock_Stone"
    },
    {
      "x": -5,
      "y": 9,
      "z": 6,
      "name": "Rock_Stone"
    },
    {
      "x": -5,
      "y": 10,
      "z": 6,
      "name": "Rock_Stone"
    },
    {
      "x": -5,
      "y": -1,
      "z": 7,
      "name": "Rock_Stone"
    },
    {
      "x": -5,
      "y": 0,
      "z": 7,
      "name": "Rock_Stone"
    },
    {
      "x": -5,
      "y": 1,
      "z": 7,
      "name": "Rock_Stone"
    },
    {
      "x": -5,
      "y": 2,
      "z": 7,
      "name": "Rock_Stone_Cobble"
    },
    {
      "x": -5,
      "y": 3,
      "z": 7,
      "name": "Rock_Stone_Cobble"
    },
    {
      "x": -5,
      "y": 4,
      "z": 7,
      "name": "Plant_Moss_Rug_Yellow"
    },
    {
      "x": -5,
      "y": 5,
      "z": 7,
      "name": "Empty"
    },
    {
      "x": -5,
      "y": 6,
      "z": 7,
      "name": "Empty"
    },
    {
      "x": -5,
      "y": 7,
      "z": 7,
      "name": "Empty"
    },
    {
      "x": -5,
      "y": 8,
      "z": 7,
      "name": "Empty"
    },
    {
      "x": -5,
      "y": 9,
      "z": 7,
      "name": "Rock_Stone"
    },
    {
      "x": -5,
      "y": 10,
      "z": 7,
      "name": "Rock_Stone"
    },
    {
      "x": -5,
      "y": -1,
      "z": 8,
      "name": "Rock_Stone"
    },
    {
      "x": -5,
      "y": 0,
      "z": 8,
      "name": "Rock_Stone"
    },
    {
      "x": -5,
      "y": 1,
      "z": 8,
      "name": "Rock_Stone"
    },
    {
      "x": -5,
      "y": 2,
      "z": 8,
      "name": "Rock_Stone_Cobble"
    },
    {
      "x": -5,
      "y": 3,
      "z": 8,
      "name": "Block_Spawner_Block",
      "components": {
        "Components": {
          "BlockSpawner": {
            "BlockSpawnerId": "Zone1_Encounters_Tier2"
          }
        }
      },
      "rotation": 1
    },
    {
      "x": -5,
      "y": 4,
      "z": 8,
      "name": "Empty"
    },
    {
      "x": -5,
      "y": 5,
      "z": 8,
      "name": "Empty"
    },
    {
      "x": -5,
      "y": 6,
      "z": 8,
      "name": "Empty"
    },
    {
      "x": -5,
      "y": 7,
      "z": 8,
      "name": "Rock_Stone_Stalactite_Small",
      "rotation": 8
    },
    {
      "x": -5,
      "y": 8,
      "z": 8,
      "name": "Rock_Stone"
    },
    {
      "x": -5,
      "y": 9,
      "z": 8,
      "name": "Rock_Stone"
    },
    {
      "x": -5,
      "y": 10,
      "z": 8,
      "name": "Rock_Stone"
    },
    {
      "x": -5,
      "y": -1,
      "z": 9,
      "name": "Rock_Stone"
    },
    {
      "x": -5,
      "y": 0,
      "z": 9,
      "name": "Rock_Stone"
    },
    {
      "x": -5,
      "y": 1,
      "z": 9,
      "name": "Rock_Stone"
    },
    {
      "x": -5,
      "y": 2,
      "z": 9,
      "name": "Wood_Softwood_Planks"
    },
    {
      "x": -5,
      "y": 3,
      "z": 9,
      "name": "Empty"
    },
    {
      "x": -5,
      "y": 4,
      "z": 9,
      "name": "Empty"
    },
    {
      "x": -5,
      "y": 5,
      "z": 9,
      "name": "Rock_Stone_Stalactite_Large",
      "filler": 31744,
      "rotation": 8
    },
    {
      "x": -5,
      "y": 6,
      "z": 9,
      "name": "Rock_Stone_Stalactite_Large",
      "rotation": 8
    },
    {
      "x": -5,
      "y": 7,
      "z": 9,
      "name": "Rock_Stone"
    },
    {
      "x": -5,
      "y": 8,
      "z": 9,
      "name": "Rock_Stone"
    },
    {
      "x": -5,
      "y": 9,
      "z": 9,
      "name": "Rock_Stone"
    },
    {
      "x": -5,
      "y": 10,
      "z": 9,
      "name": "Rock_Stone"
    },
    {
      "x": -5,
      "y": -1,
      "z": 10,
      "name": "Rock_Stone"
    },
    {
      "x": -5,
      "y": 0,
      "z": 10,
      "name": "Rock_Stone"
    },
    {
      "x": -5,
      "y": 1,
      "z": 10,
      "name": "Rock_Stone"
    },
    {
      "x": -5,
      "y": 2,
      "z": 10,
      "name": "Wood_Softwood_Planks"
    },
    {
      "x": -5,
      "y": 3,
      "z": 10,
      "name": "Furniture_Crude_Bed",
      "components": {
        "Components": {
          "RespawnBlock": {}
        }
      },
      "rotation": 1
    },
    {
      "x": -5,
      "y": 4,
      "z": 10,
      "name": "Empty"
    },
    {
      "x": -5,
      "y": 5,
      "z": 10,
      "name": "Empty"
    },
    {
      "x": -5,
      "y": 6,
      "z": 10,
      "name": "Empty"
    },
    {
      "x": -5,
      "y": 7,
      "z": 10,
      "name": "Rock_Stone"
    },
    {
      "x": -5,
      "y": 8,
      "z": 10,
      "name": "Rock_Stone"
    },
    {
      "x": -5,
      "y": 9,
      "z": 10,
      "name": "Rock_Stone"
    },
    {
      "x": -5,
      "y": 10,
      "z": 10,
      "name": "Rock_Stone"
    },
    {
      "x": -5,
      "y": -1,
      "z": 11,
      "name": "Rock_Stone"
    },
    {
      "x": -5,
      "y": 0,
      "z": 11,
      "name": "Rock_Stone"
    },
    {
      "x": -5,
      "y": 1,
      "z": 11,
      "name": "Rock_Stone"
    },
    {
      "x": -5,
      "y": 2,
      "z": 11,
      "name": "Wood_Softwood_Planks"
    },
    {
      "x": -5,
      "y": 3,
      "z": 11,
      "name": "Furniture_Village_Crate"
    },
    {
      "x": -5,
      "y": 4,
      "z": 11,
      "name": "Empty"
    },
    {
      "x": -5,
      "y": 5,
      "z": 11,
      "name": "Empty"
    },
    {
      "x": -5,
      "y": 6,
      "z": 11,
      "name": "Rock_Stone"
    },
    {
      "x": -5,
      "y": 7,
      "z": 11,
      "name": "Rock_Stone"
    },
    {
      "x": -5,
      "y": 8,
      "z": 11,
      "name": "Rock_Stone"
    },
    {
      "x": -5,
      "y": 9,
      "z": 11,
      "name": "Rock_Stone"
    },
    {
      "x": -5,
      "y": 10,
      "z": 11,
      "name": "Rock_Stone"
    },
    {
      "x": -5,
      "y": -1,
      "z": 12,
      "name": "Rock_Stone"
    },
    {
      "x": -5,
      "y": 0,
      "z": 12,
      "name": "Rock_Stone"
    },
    {
      "x": -5,
      "y": 1,
      "z": 12,
      "name": "Rock_Stone"
    },
    {
      "x": -5,
      "y": 2,
      "z": 12,
      "name": "Rock_Stone"
    },
    {
      "x": -5,
      "y": 3,
      "z": 12,
      "name": "Rock_Stone"
    },
    {
      "x": -5,
      "y": 4,
      "z": 12,
      "name": "Empty"
    },
    {
      "x": -5,
      "y": 5,
      "z": 12,
      "name": "Empty"
    },
    {
      "x": -5,
      "y": 6,
      "z": 12,
      "name": "Rock_Stone"
    },
    {
      "x": -5,
      "y": 7,
      "z": 12,
      "name": "Rock_Stone"
    },
    {
      "x": -5,
      "y": 8,
      "z": 12,
      "name": "Rock_Stone"
    },
    {
      "x": -5,
      "y": 9,
      "z": 12,
      "name": "Rock_Stone"
    },
    {
      "x": -5,
      "y": 10,
      "z": 12,
      "name": "Rock_Stone"
    },
    {
      "x": -5,
      "y": -1,
      "z": 13,
      "name": "Rock_Stone"
    },
    {
      "x": -5,
      "y": 0,
      "z": 13,
      "name": "Rock_Stone"
    },
    {
      "x": -5,
      "y": 1,
      "z": 13,
      "name": "Rock_Stone"
    },
    {
      "x": -5,
      "y": 2,
      "z": 13,
      "name": "Rock_Stone"
    },
    {
      "x": -5,
      "y": 3,
      "z": 13,
      "name": "Rock_Stone"
    },
    {
      "x": -5,
      "y": 4,
      "z": 13,
      "name": "Rock_Stone"
    },
    {
      "x": -5,
      "y": 5,
      "z": 13,
      "name": "Rock_Stone"
    },
    {
      "x": -5,
      "y": 6,
      "z": 13,
      "name": "Rock_Stone"
    },
    {
      "x": -5,
      "y": 7,
      "z": 13,
      "name": "Rock_Stone"
    },
    {
      "x": -5,
      "y": 8,
      "z": 13,
      "name": "Rock_Stone"
    },
    {
      "x": -5,
      "y": 9,
      "z": 13,
      "name": "Rock_Stone"
    },
    {
      "x": -5,
      "y": 10,
      "z": 13,
      "name": "Rock_Stone"
    },
    {
      "x": -5,
      "y": -1,
      "z": 14,
      "name": "Rock_Stone"
    },
    {
      "x": -5,
      "y": 0,
      "z": 14,
      "name": "Rock_Stone"
    },
    {
      "x": -5,
      "y": 1,
      "z": 14,
      "name": "Rock_Stone"
    },
    {
      "x": -5,
      "y": 2,
      "z": 14,
      "name": "Rock_Stone"
    },
    {
      "x": -5,
      "y": 3,
      "z": 14,
      "name": "Rock_Stone"
    },
    {
      "x": -5,
      "y": 4,
      "z": 14,
      "name": "Rock_Stone"
    },
    {
      "x": -5,
      "y": 5,
      "z": 14,
      "name": "Rock_Stone"
    },
    {
      "x": -5,
      "y": 6,
      "z": 14,
      "name": "Rock_Stone"
    },
    {
      "x": -5,
      "y": 7,
      "z": 14,
      "name": "Rock_Stone"
    },
    {
      "x": -5,
      "y": 8,
      "z": 14,
      "name": "Rock_Stone"
    },
    {
      "x": -5,
      "y": 9,
      "z": 14,
      "name": "Rock_Stone"
    },
    {
      "x": -5,
      "y": 10,
      "z": 14,
      "name": "Rock_Stone"
    },
    {
      "x": -4,
      "y": -1,
      "z": 0,
      "name": "Rock_Stone"
    },
    {
      "x": -4,
      "y": 0,
      "z": 0,
      "name": "Rock_Stone"
    },
    {
      "x": -4,
      "y": 1,
      "z": 0,
      "name": "Rock_Stone"
    },
    {
      "x": -4,
      "y": 2,
      "z": 0,
      "name": "Rock_Stone"
    },
    {
      "x": -4,
      "y": 3,
      "z": 0,
      "name": "Rock_Stone"
    },
    {
      "x": -4,
      "y": 4,
      "z": 0,
      "name": "Rock_Stone"
    },
    {
      "x": -4,
      "y": 5,
      "z": 0,
      "name": "Rock_Stone"
    },
    {
      "x": -4,
      "y": 6,
      "z": 0,
      "name": "Rock_Stone"
    },
    {
      "x": -4,
      "y": 7,
      "z": 0,
      "name": "Rock_Stone"
    },
    {
      "x": -4,
      "y": 8,
      "z": 0,
      "name": "Rock_Stone"
    },
    {
      "x": -4,
      "y": 9,
      "z": 0,
      "name": "Rock_Stone"
    },
    {
      "x": -4,
      "y": 10,
      "z": 0,
      "name": "Rock_Stone"
    },
    {
      "x": -4,
      "y": -1,
      "z": 1,
      "name": "Rock_Stone"
    },
    {
      "x": -4,
      "y": 0,
      "z": 1,
      "name": "Rock_Stone"
    },
    {
      "x": -4,
      "y": 1,
      "z": 1,
      "name": "Rock_Stone"
    },
    {
      "x": -4,
      "y": 2,
      "z": 1,
      "name": "Rock_Stone"
    },
    {
      "x": -4,
      "y": 3,
      "z": 1,
      "name": "Empty"
    },
    {
      "x": -4,
      "y": 4,
      "z": 1,
      "name": "Rock_Stone"
    },
    {
      "x": -4,
      "y": 5,
      "z": 1,
      "name": "Rock_Stone"
    },
    {
      "x": -4,
      "y": 6,
      "z": 1,
      "name": "Rock_Stone"
    },
    {
      "x": -4,
      "y": 7,
      "z": 1,
      "name": "Rock_Stone"
    },
    {
      "x": -4,
      "y": 8,
      "z": 1,
      "name": "Rock_Stone"
    },
    {
      "x": -4,
      "y": 9,
      "z": 1,
      "name": "Rock_Stone"
    },
    {
      "x": -4,
      "y": 10,
      "z": 1,
      "name": "Rock_Stone"
    },
    {
      "x": -4,
      "y": -1,
      "z": 2,
      "name": "Rock_Stone"
    },
    {
      "x": -4,
      "y": 0,
      "z": 2,
      "name": "Rock_Stone"
    },
    {
      "x": -4,
      "y": 1,
      "z": 2,
      "name": "Rock_Stone"
    },
    {
      "x": -4,
      "y": 2,
      "z": 2,
      "name": "Rock_Stone_Cobble"
    },
    {
      "x": -4,
      "y": 3,
      "z": 2,
      "name": "Rock_Stone_Cobble"
    },
    {
      "x": -4,
      "y": 4,
      "z": 2,
      "name": "Rock_Stone_Cobble"
    },
    {
      "x": -4,
      "y": 5,
      "z": 2,
      "name": "Empty"
    },
    {
      "x": -4,
      "y": 6,
      "z": 2,
      "name": "Rock_Stone"
    },
    {
      "x": -4,
      "y": 7,
      "z": 2,
      "name": "Rock_Stone"
    },
    {
      "x": -4,
      "y": 8,
      "z": 2,
      "name": "Rock_Stone"
    },
    {
      "x": -4,
      "y": 9,
      "z": 2,
      "name": "Rock_Stone"
    },
    {
      "x": -4,
      "y": 10,
      "z": 2,
      "name": "Rock_Stone"
    },
    {
      "x": -4,
      "y": -1,
      "z": 3,
      "name": "Rock_Stone"
    },
    {
      "x": -4,
      "y": 0,
      "z": 3,
      "name": "Rock_Stone"
    },
    {
      "x": -4,
      "y": 1,
      "z": 3,
      "name": "Rock_Stone"
    },
    {
      "x": -4,
      "y": 2,
      "z": 3,
      "name": "Rock_Stone_Cobble"
    },
    {
      "x": -4,
      "y": 3,
      "z": 3,
      "name": "Rock_Stone_Cobble"
    },
    {
      "x": -4,
      "y": 4,
      "z": 3,
      "name": "Rock_Stone_Cobble"
    },
    {
      "x": -4,
      "y": 5,
      "z": 3,
      "name": "Empty"
    },
    {
      "x": -4,
      "y": 6,
      "z": 3,
      "name": "Empty"
    },
    {
      "x": -4,
      "y": 7,
      "z": 3,
      "name": "Empty"
    },
    {
      "x": -4,
      "y": 8,
      "z": 3,
      "name": "Rock_Stone"
    },
    {
      "x": -4,
      "y": 9,
      "z": 3,
      "name": "Rock_Stone"
    },
    {
      "x": -4,
      "y": 10,
      "z": 3,
      "name": "Rock_Stone"
    },
    {
      "x": -4,
      "y": -1,
      "z": 4,
      "name": "Rock_Stone"
    },
    {
      "x": -4,
      "y": 0,
      "z": 4,
      "name": "Rock_Stone"
    },
    {
      "x": -4,
      "y": 1,
      "z": 4,
      "name": "Rock_Stone"
    },
    {
      "x": -4,
      "y": 2,
      "z": 4,
      "name": "Rock_Stone_Cobble"
    },
    {
      "x": -4,
      "y": 3,
      "z": 4,
      "name": "Rock_Stone_Cobble"
    },
    {
      "x": -4,
      "y": 4,
      "z": 4,
      "name": "Rock_Stone_Cobble"
    },
    {
      "x": -4,
      "y": 5,
      "z": 4,
      "name": "Empty"
    },
    {
      "x": -4,
      "y": 6,
      "z": 4,
      "name": "Empty"
    },
    {
      "x": -4,
      "y": 7,
      "z": 4,
      "name": "Empty"
    },
    {
      "x": -4,
      "y": 8,
      "z": 4,
      "name": "Empty"
    },
    {
      "x": -4,
      "y": 9,
      "z": 4,
      "name": "Rock_Stone"
    },
    {
      "x": -4,
      "y": 10,
      "z": 4,
      "name": "Rock_Stone"
    },
    {
      "x": -4,
      "y": -1,
      "z": 5,
      "name": "Rock_Stone"
    },
    {
      "x": -4,
      "y": 0,
      "z": 5,
      "name": "Rock_Stone"
    },
    {
      "x": -4,
      "y": 1,
      "z": 5,
      "name": "Rock_Stone"
    },
    {
      "x": -4,
      "y": 2,
      "z": 5,
      "name": "Wood_Softwood_Planks"
    },
    {
      "x": -4,
      "y": 3,
      "z": 5,
      "name": "Plant_Moss_Yellow"
    },
    {
      "x": -4,
      "y": 4,
      "z": 5,
      "name": "Plant_Moss_Wall_Yellow",
      "rotation": 1
    },
    {
      "x": -4,
      "y": 5,
      "z": 5,
      "name": "Empty"
    },
    {
      "x": -4,
      "y": 6,
      "z": 5,
      "name": "Empty"
    },
    {
      "x": -4,
      "y": 7,
      "z": 5,
      "name": "Empty"
    },
    {
      "x": -4,
      "y": 8,
      "z": 5,
      "name": "Empty"
    },
    {
      "x": -4,
      "y": 9,
      "z": 5,
      "name": "Rock_Stone"
    },
    {
      "x": -4,
      "y": 10,
      "z": 5,
      "name": "Rock_Stone"
    },
    {
      "x": -4,
      "y": -1,
      "z": 6,
      "name": "Rock_Stone"
    },
    {
      "x": -4,
      "y": 0,
      "z": 6,
      "name": "Rock_Stone"
    },
    {
      "x": -4,
      "y": 1,
      "z": 6,
      "name": "Rock_Stone"
    },
    {
      "x": -4,
      "y": 2,
      "z": 6,
      "name": "Wood_Softwood_Planks"
    },
    {
      "x": -4,
      "y": 3,
      "z": 6,
      "name": "Wood_Softwood_Beam"
    },
    {
      "x": -4,
      "y": 4,
      "z": 6,
      "name": "*Furniture_Crude_Torch_State_Definitions_Off"
    },
    {
      "x": -4,
      "y": 5,
      "z": 6,
      "name": "Empty"
    },
    {
      "x": -4,
      "y": 6,
      "z": 6,
      "name": "Empty"
    },
    {
      "x": -4,
      "y": 7,
      "z": 6,
      "name": "Empty"
    },
    {
      "x": -4,
      "y": 8,
      "z": 6,
      "name": "Empty"
    },
    {
      "x": -4,
      "y": 9,
      "z": 6,
      "name": "Rock_Stone"
    },
    {
      "x": -4,
      "y": 10,
      "z": 6,
      "name": "Rock_Stone"
    },
    {
      "x": -4,
      "y": -1,
      "z": 7,
      "name": "Rock_Stone"
    },
    {
      "x": -4,
      "y": 0,
      "z": 7,
      "name": "Rock_Stone"
    },
    {
      "x": -4,
      "y": 1,
      "z": 7,
      "name": "Rock_Stone"
    },
    {
      "x": -4,
      "y": 2,
      "z": 7,
      "name": "Wood_Softwood_Planks"
    },
    {
      "x": -4,
      "y": 3,
      "z": 7,
      "name": "Furniture_Crude_Stool"
    },
    {
      "x": -4,
      "y": 4,
      "z": 7,
      "name": "Empty"
    },
    {
      "x": -4,
      "y": 5,
      "z": 7,
      "name": "Empty"
    },
    {
      "x": -4,
      "y": 6,
      "z": 7,
      "name": "Empty"
    },
    {
      "x": -4,
      "y": 7,
      "z": 7,
      "name": "Empty"
    },
    {
      "x": -4,
      "y": 8,
      "z": 7,
      "name": "Empty"
    },
    {
      "x": -4,
      "y": 9,
      "z": 7,
      "name": "Rock_Stone"
    },
    {
      "x": -4,
      "y": 10,
      "z": 7,
      "name": "Rock_Stone"
    },
    {
      "x": -4,
      "y": -1,
      "z": 8,
      "name": "Rock_Stone"
    },
    {
      "x": -4,
      "y": 0,
      "z": 8,
      "name": "Rock_Stone"
    },
    {
      "x": -4,
      "y": 1,
      "z": 8,
      "name": "Rock_Stone"
    },
    {
      "x": -4,
      "y": 2,
      "z": 8,
      "name": "Wood_Softwood_Planks"
    },
    {
      "x": -4,
      "y": 3,
      "z": 8,
      "name": "Empty"
    },
    {
      "x": -4,
      "y": 4,
      "z": 8,
      "name": "Empty"
    },
    {
      "x": -4,
      "y": 5,
      "z": 8,
      "name": "Empty"
    },
    {
      "x": -4,
      "y": 6,
      "z": 8,
      "name": "Empty"
    },
    {
      "x": -4,
      "y": 7,
      "z": 8,
      "name": "Empty"
    },
    {
      "x": -4,
      "y": 8,
      "z": 8,
      "name": "Empty"
    },
    {
      "x": -4,
      "y": 9,
      "z": 8,
      "name": "Rock_Stone"
    },
    {
      "x": -4,
      "y": 10,
      "z": 8,
      "name": "Rock_Stone"
    },
    {
      "x": -4,
      "y": -1,
      "z": 9,
      "name": "Rock_Stone"
    },
    {
      "x": -4,
      "y": 0,
      "z": 9,
      "name": "Rock_Stone"
    },
    {
      "x": -4,
      "y": 1,
      "z": 9,
      "name": "Rock_Stone"
    },
    {
      "x": -4,
      "y": 2,
      "z": 9,
      "name": "Wood_Softwood_Planks"
    },
    {
      "x": -4,
      "y": 3,
      "z": 9,
      "name": "Empty"
    },
    {
      "x": -4,
      "y": 4,
      "z": 9,
      "name": "Empty"
    },
    {
      "x": -4,
      "y": 5,
      "z": 9,
      "name": "Empty"
    },
    {
      "x": -4,
      "y": 6,
      "z": 9,
      "name": "Empty"
    },
    {
      "x": -4,
      "y": 7,
      "z": 9,
      "name": "Empty"
    },
    {
      "x": -4,
      "y": 8,
      "z": 9,
      "name": "Empty"
    },
    {
      "x": -4,
      "y": 9,
      "z": 9,
      "name": "Rock_Stone"
    },
    {
      "x": -4,
      "y": 10,
      "z": 9,
      "name": "Rock_Stone"
    },
    {
      "x": -4,
      "y": -1,
      "z": 10,
      "name": "Rock_Stone"
    },
    {
      "x": -4,
      "y": 0,
      "z": 10,
      "name": "Rock_Stone"
    },
    {
      "x": -4,
      "y": 1,
      "z": 10,
      "name": "Rock_Stone"
    },
    {
      "x": -4,
      "y": 2,
      "z": 10,
      "name": "Wood_Softwood_Planks"
    },
    {
      "x": -4,
      "y": 3,
      "z": 10,
      "name": "Furniture_Crude_Bed",
      "components": {
        "Components": {
          "RespawnBlock": {}
        }
      },
      "filler": 1,
      "rotation": 1
    },
    {
      "x": -4,
      "y": 4,
      "z": 10,
      "name": "Empty"
    },
    {
      "x": -4,
      "y": 5,
      "z": 10,
      "name": "Empty"
    },
    {
      "x": -4,
      "y": 6,
      "z": 10,
      "name": "Empty"
    },
    {
      "x": -4,
      "y": 7,
      "z": 10,
      "name": "Empty"
    },
    {
      "x": -4,
      "y": 8,
      "z": 10,
      "name": "Empty"
    },
    {
      "x": -4,
      "y": 9,
      "z": 10,
      "name": "Rock_Stone"
    },
    {
      "x": -4,
      "y": 10,
      "z": 10,
      "name": "Rock_Stone"
    },
    {
      "x": -4,
      "y": -1,
      "z": 11,
      "name": "Rock_Stone"
    },
    {
      "x": -4,
      "y": 0,
      "z": 11,
      "name": "Rock_Stone"
    },
    {
      "x": -4,
      "y": 1,
      "z": 11,
      "name": "Rock_Stone"
    },
    {
      "x": -4,
      "y": 2,
      "z": 11,
      "name": "Wood_Softwood_Planks"
    },
    {
      "x": -4,
      "y": 3,
      "z": 11,
      "name": "Empty"
    },
    {
      "x": -4,
      "y": 4,
      "z": 11,
      "name": "Empty"
    },
    {
      "x": -4,
      "y": 5,
      "z": 11,
      "name": "Empty"
    },
    {
      "x": -4,
      "y": 6,
      "z": 11,
      "name": "Empty"
    },
    {
      "x": -4,
      "y": 7,
      "z": 11,
      "name": "Empty"
    },
    {
      "x": -4,
      "y": 8,
      "z": 11,
      "name": "Rock_Stone"
    },
    {
      "x": -4,
      "y": 9,
      "z": 11,
      "name": "Rock_Stone"
    },
    {
      "x": -4,
      "y": 10,
      "z": 11,
      "name": "Rock_Stone"
    },
    {
      "x": -4,
      "y": -1,
      "z": 12,
      "name": "Rock_Stone"
    },
    {
      "x": -4,
      "y": 0,
      "z": 12,
      "name": "Rock_Stone"
    },
    {
      "x": -4,
      "y": 1,
      "z": 12,
      "name": "Rock_Stone"
    },
    {
      "x": -4,
      "y": 2,
      "z": 12,
      "name": "Rock_Stone"
    },
    {
      "x": -4,
      "y": 3,
      "z": 12,
      "name": "Furniture_Tavern_Barrel"
    },
    {
      "x": -4,
      "y": 4,
      "z": 12,
      "name": "Empty"
    },
    {
      "x": -4,
      "y": 5,
      "z": 12,
      "name": "Empty"
    },
    {
      "x": -4,
      "y": 6,
      "z": 12,
      "name": "Empty"
    },
    {
      "x": -4,
      "y": 7,
      "z": 12,
      "name": "Rock_Stone"
    },
    {
      "x": -4,
      "y": 8,
      "z": 12,
      "name": "Rock_Stone"
    },
    {
      "x": -4,
      "y": 9,
      "z": 12,
      "name": "Rock_Stone"
    },
    {
      "x": -4,
      "y": 10,
      "z": 12,
      "name": "Rock_Stone"
    },
    {
      "x": -4,
      "y": -1,
      "z": 13,
      "name": "Rock_Stone"
    },
    {
      "x": -4,
      "y": 0,
      "z": 13,
      "name": "Rock_Stone"
    },
    {
      "x": -4,
      "y": 1,
      "z": 13,
      "name": "Rock_Stone"
    },
    {
      "x": -4,
      "y": 2,
      "z": 13,
      "name": "Rock_Stone"
    },
    {
      "x": -4,
      "y": 3,
      "z": 13,
      "name": "Rock_Stone"
    },
    {
      "x": -4,
      "y": 4,
      "z": 13,
      "name": "Empty"
    },
    {
      "x": -4,
      "y": 5,
      "z": 13,
      "name": "Empty"
    },
    {
      "x": -4,
      "y": 6,
      "z": 13,
      "name": "Rock_Stone"
    },
    {
      "x": -4,
      "y": 7,
      "z": 13,
      "name": "Rock_Stone"
    },
    {
      "x": -4,
      "y": 8,
      "z": 13,
      "name": "Rock_Stone"
    },
    {
      "x": -4,
      "y": 9,
      "z": 13,
      "name": "Rock_Stone"
    },
    {
      "x": -4,
      "y": 10,
      "z": 13,
      "name": "Rock_Stone"
    },
    {
      "x": -4,
      "y": -1,
      "z": 14,
      "name": "Rock_Stone"
    },
    {
      "x": -4,
      "y": 0,
      "z": 14,
      "name": "Rock_Stone"
    },
    {
      "x": -4,
      "y": 1,
      "z": 14,
      "name": "Rock_Stone"
    },
    {
      "x": -4,
      "y": 2,
      "z": 14,
      "name": "Rock_Stone"
    },
    {
      "x": -4,
      "y": 3,
      "z": 14,
      "name": "Rock_Stone"
    },
    {
      "x": -4,
      "y": 4,
      "z": 14,
      "name": "Rock_Stone"
    },
    {
      "x": -4,
      "y": 5,
      "z": 14,
      "name": "Rock_Stone"
    },
    {
      "x": -4,
      "y": 6,
      "z": 14,
      "name": "Rock_Stone"
    },
    {
      "x": -4,
      "y": 7,
      "z": 14,
      "name": "Rock_Stone"
    },
    {
      "x": -4,
      "y": 8,
      "z": 14,
      "name": "Rock_Stone"
    },
    {
      "x": -4,
      "y": 9,
      "z": 14,
      "name": "Rock_Stone"
    },
    {
      "x": -4,
      "y": 10,
      "z": 14,
      "name": "Rock_Stone"
    },
    {
      "x": -3,
      "y": -1,
      "z": 0,
      "name": "Rock_Stone"
    },
    {
      "x": -3,
      "y": 0,
      "z": 0,
      "name": "Rock_Stone"
    },
    {
      "x": -3,
      "y": 1,
      "z": 0,
      "name": "Rock_Stone"
    },
    {
      "x": -3,
      "y": 2,
      "z": 0,
      "name": "Empty"
    },
    {
      "x": -3,
      "y": 3,
      "z": 0,
      "name": "Empty"
    },
    {
      "x": -3,
      "y": 4,
      "z": 0,
      "name": "Empty"
    },
    {
      "x": -3,
      "y": 5,
      "z": 0,
      "name": "Empty"
    },
    {
      "x": -3,
      "y": 6,
      "z": 0,
      "name": "Rock_Stone"
    },
    {
      "x": -3,
      "y": 7,
      "z": 0,
      "name": "Rock_Stone"
    },
    {
      "x": -3,
      "y": 8,
      "z": 0,
      "name": "Rock_Stone"
    },
    {
      "x": -3,
      "y": 9,
      "z": 0,
      "name": "Rock_Stone"
    },
    {
      "x": -3,
      "y": 10,
      "z": 0,
      "name": "Rock_Stone"
    },
    {
      "x": -3,
      "y": -1,
      "z": 1,
      "name": "Rock_Stone"
    },
    {
      "x": -3,
      "y": 0,
      "z": 1,
      "name": "Rock_Stone"
    },
    {
      "x": -3,
      "y": 1,
      "z": 1,
      "name": "Rock_Stone"
    },
    {
      "x": -3,
      "y": 2,
      "z": 1,
      "name": "Rail",
      "rotation": 1
    },
    {
      "x": -3,
      "y": 3,
      "z": 1,
      "name": "Empty"
    },
    {
      "x": -3,
      "y": 4,
      "z": 1,
      "name": "Empty"
    },
    {
      "x": -3,
      "y": 5,
      "z": 1,
      "name": "Empty"
    },
    {
      "x": -3,
      "y": 6,
      "z": 1,
      "name": "Rock_Stone"
    },
    {
      "x": -3,
      "y": 7,
      "z": 1,
      "name": "Rock_Stone"
    },
    {
      "x": -3,
      "y": 8,
      "z": 1,
      "name": "Rock_Stone"
    },
    {
      "x": -3,
      "y": 9,
      "z": 1,
      "name": "Rock_Stone"
    },
    {
      "x": -3,
      "y": 10,
      "z": 1,
      "name": "Rock_Stone"
    },
    {
      "x": -3,
      "y": -1,
      "z": 2,
      "name": "Rock_Stone"
    },
    {
      "x": -3,
      "y": 0,
      "z": 2,
      "name": "Rock_Stone"
    },
    {
      "x": -3,
      "y": 1,
      "z": 2,
      "name": "Rock_Stone"
    },
    {
      "x": -3,
      "y": 2,
      "z": 2,
      "name": "Rock_Stone_Cobble"
    },
    {
      "x": -3,
      "y": 3,
      "z": 2,
      "name": "Rock_Stone_Cobble"
    },
    {
      "x": -3,
      "y": 4,
      "z": 2,
      "name": "Empty"
    },
    {
      "x": -3,
      "y": 5,
      "z": 2,
      "name": "Empty"
    },
    {
      "x": -3,
      "y": 6,
      "z": 2,
      "name": "Empty"
    },
    {
      "x": -3,
      "y": 7,
      "z": 2,
      "name": "Rock_Stone"
    },
    {
      "x": -3,
      "y": 8,
      "z": 2,
      "name": "Rock_Stone"
    },
    {
      "x": -3,
      "y": 9,
      "z": 2,
      "name": "Rock_Stone"
    },
    {
      "x": -3,
      "y": 10,
      "z": 2,
      "name": "Rock_Stone"
    },
    {
      "x": -3,
      "y": -1,
      "z": 3,
      "name": "Rock_Stone"
    },
    {
      "x": -3,
      "y": 0,
      "z": 3,
      "name": "Rock_Stone"
    },
    {
      "x": -3,
      "y": 1,
      "z": 3,
      "name": "Rock_Stone"
    },
    {
      "x": -3,
      "y": 2,
      "z": 3,
      "name": "Rock_Stone_Cobble"
    },
    {
      "x": -3,
      "y": 3,
      "z": 3,
      "name": "Rock_Stone_Cobble"
    },
    {
      "x": -3,
      "y": 4,
      "z": 3,
      "name": "Empty"
    },
    {
      "x": -3,
      "y": 5,
      "z": 3,
      "name": "Empty"
    },
    {
      "x": -3,
      "y": 6,
      "z": 3,
      "name": "Wood_Beech_Trunk",
      "rotation": 5
    },
    {
      "x": -3,
      "y": 7,
      "z": 3,
      "name": "Empty"
    },
    {
      "x": -3,
      "y": 8,
      "z": 3,
      "name": "Rock_Stone"
    },
    {
      "x": -3,
      "y": 9,
      "z": 3,
      "name": "Rock_Stone"
    },
    {
      "x": -3,
      "y": 10,
      "z": 3,
      "name": "Rock_Stone"
    },
    {
      "x": -3,
      "y": -1,
      "z": 4,
      "name": "Rock_Stone"
    },
    {
      "x": -3,
      "y": 0,
      "z": 4,
      "name": "Rock_Stone"
    },
    {
      "x": -3,
      "y": 1,
      "z": 4,
      "name": "Rock_Stone"
    },
    {
      "x": -3,
      "y": 2,
      "z": 4,
      "name": "Wood_Softwood_Planks"
    },
    {
      "x": -3,
      "y": 3,
      "z": 4,
      "name": "Furniture_Crude_Bed",
      "components": {
        "Components": {
          "RespawnBlock": {}
        }
      },
      "filler": 31,
      "rotation": 3
    },
    {
      "x": -3,
      "y": 4,
      "z": 4,
      "name": "Empty"
    },
    {
      "x": -3,
      "y": 5,
      "z": 4,
      "name": "Empty"
    },
    {
      "x": -3,
      "y": 6,
      "z": 4,
      "name": "Empty"
    },
    {
      "x": -3,
      "y": 7,
      "z": 4,
      "name": "Empty"
    },
    {
      "x": -3,
      "y": 8,
      "z": 4,
      "name": "Empty"
    },
    {
      "x": -3,
      "y": 9,
      "z": 4,
      "name": "Rock_Stone"
    },
    {
      "x": -3,
      "y": 10,
      "z": 4,
      "name": "Rock_Stone"
    },
    {
      "x": -3,
      "y": -1,
      "z": 5,
      "name": "Rock_Stone"
    },
    {
      "x": -3,
      "y": 0,
      "z": 5,
      "name": "Rock_Stone"
    },
    {
      "x": -3,
      "y": 1,
      "z": 5,
      "name": "Rock_Stone"
    },
    {
      "x": -3,
      "y": 2,
      "z": 5,
      "name": "Furniture_Crude_Platform",
      "rotation": 1
    },
    {
      "x": -3,
      "y": 3,
      "z": 5,
      "name": "Empty"
    },
    {
      "x": -3,
      "y": 4,
      "z": 5,
      "name": "Empty"
    },
    {
      "x": -3,
      "y": 5,
      "z": 5,
      "name": "Empty"
    },
    {
      "x": -3,
      "y": 6,
      "z": 5,
      "name": "Empty"
    },
    {
      "x": -3,
      "y": 7,
      "z": 5,
      "name": "Empty"
    },
    {
      "x": -3,
      "y": 8,
      "z": 5,
      "name": "Empty"
    },
    {
      "x": -3,
      "y": 9,
      "z": 5,
      "name": "Rock_Stone"
    },
    {
      "x": -3,
      "y": 10,
      "z": 5,
      "name": "Rock_Stone"
    },
    {
      "x": -3,
      "y": -1,
      "z": 6,
      "name": "Rock_Stone"
    },
    {
      "x": -3,
      "y": 0,
      "z": 6,
      "name": "Rock_Stone"
    },
    {
      "x": -3,
      "y": 1,
      "z": 6,
      "name": "Rock_Stone"
    },
    {
      "x": -3,
      "y": 2,
      "z": 6,
      "name": "Wood_Softwood_Planks"
    },
    {
      "x": -3,
      "y": 3,
      "z": 6,
      "name": "Empty"
    },
    {
      "x": -3,
      "y": 4,
      "z": 6,
      "name": "Empty"
    },
    {
      "x": -3,
      "y": 5,
      "z": 6,
      "name": "Empty"
    },
    {
      "x": -3,
      "y": 6,
      "z": 6,
      "name": "Empty"
    },
    {
      "x": -3,
      "y": 7,
      "z": 6,
      "name": "Empty"
    },
    {
      "x": -3,
      "y": 8,
      "z": 6,
      "name": "Empty"
    },
    {
      "x": -3,
      "y": 9,
      "z": 6,
      "name": "Rock_Stone"
    },
    {
      "x": -3,
      "y": 10,
      "z": 6,
      "name": "Rock_Stone"
    },
    {
      "x": -3,
      "y": -1,
      "z": 7,
      "name": "Rock_Stone"
    },
    {
      "x": -3,
      "y": 0,
      "z": 7,
      "name": "Rock_Stone"
    },
    {
      "x": -3,
      "y": 1,
      "z": 7,
      "name": "Rock_Stone"
    },
    {
      "x": -3,
      "y": 2,
      "z": 7,
      "name": "Wood_Softwood_Planks"
    },
    {
      "x": -3,
      "y": 3,
      "z": 7,
      "name": "Empty"
    },
    {
      "x": -3,
      "y": 4,
      "z": 7,
      "name": "Empty"
    },
    {
      "x": -3,
      "y": 5,
      "z": 7,
      "name": "Empty"
    },
    {
      "x": -3,
      "y": 6,
      "z": 7,
      "name": "Empty"
    },
    {
      "x": -3,
      "y": 7,
      "z": 7,
      "name": "Empty"
    },
    {
      "x": -3,
      "y": 8,
      "z": 7,
      "name": "Empty"
    },
    {
      "x": -3,
      "y": 9,
      "z": 7,
      "name": "Rock_Stone"
    },
    {
      "x": -3,
      "y": 10,
      "z": 7,
      "name": "Rock_Stone"
    },
    {
      "x": -3,
      "y": -1,
      "z": 8,
      "name": "Rock_Stone"
    },
    {
      "x": -3,
      "y": 0,
      "z": 8,
      "name": "Rock_Stone"
    },
    {
      "x": -3,
      "y": 1,
      "z": 8,
      "name": "Rock_Stone"
    },
    {
      "x": -3,
      "y": 2,
      "z": 8,
      "name": "Wood_Softwood_Planks"
    },
    {
      "x": -3,
      "y": 3,
      "z": 8,
      "name": "Empty"
    },
    {
      "x": -3,
      "y": 4,
      "z": 8,
      "name": "Empty"
    },
    {
      "x": -3,
      "y": 5,
      "z": 8,
      "name": "Empty"
    },
    {
      "x": -3,
      "y": 6,
      "z": 8,
      "name": "Empty"
    },
    {
      "x": -3,
      "y": 7,
      "z": 8,
      "name": "Empty"
    },
    {
      "x": -3,
      "y": 8,
      "z": 8,
      "name": "Empty"
    },
    {
      "x": -3,
      "y": 9,
      "z": 8,
      "name": "Rock_Stone"
    },
    {
      "x": -3,
      "y": 10,
      "z": 8,
      "name": "Rock_Stone"
    },
    {
      "x": -3,
      "y": -1,
      "z": 9,
      "name": "Rock_Stone"
    },
    {
      "x": -3,
      "y": 0,
      "z": 9,
      "name": "Rock_Stone"
    },
    {
      "x": -3,
      "y": 1,
      "z": 9,
      "name": "Rock_Stone"
    },
    {
      "x": -3,
      "y": 2,
      "z": 9,
      "name": "Wood_Softwood_Planks"
    },
    {
      "x": -3,
      "y": 3,
      "z": 9,
      "name": "Empty"
    },
    {
      "x": -3,
      "y": 4,
      "z": 9,
      "name": "Empty"
    },
    {
      "x": -3,
      "y": 5,
      "z": 9,
      "name": "Empty"
    },
    {
      "x": -3,
      "y": 6,
      "z": 9,
      "name": "Empty"
    },
    {
      "x": -3,
      "y": 7,
      "z": 9,
      "name": "Empty"
    },
    {
      "x": -3,
      "y": 8,
      "z": 9,
      "name": "Empty"
    },
    {
      "x": -3,
      "y": 9,
      "z": 9,
      "name": "Rock_Stone"
    },
    {
      "x": -3,
      "y": 10,
      "z": 9,
      "name": "Rock_Stone"
    },
    {
      "x": -3,
      "y": -1,
      "z": 10,
      "name": "Rock_Stone"
    },
    {
      "x": -3,
      "y": 0,
      "z": 10,
      "name": "Rock_Stone"
    },
    {
      "x": -3,
      "y": 1,
      "z": 10,
      "name": "Rock_Stone"
    },
    {
      "x": -3,
      "y": 2,
      "z": 10,
      "name": "Wood_Softwood_Planks"
    },
    {
      "x": -3,
      "y": 3,
      "z": 10,
      "name": "Empty"
    },
    {
      "x": -3,
      "y": 4,
      "z": 10,
      "name": "Empty"
    },
    {
      "x": -3,
      "y": 5,
      "z": 10,
      "name": "Empty"
    },
    {
      "x": -3,
      "y": 6,
      "z": 10,
      "name": "Empty"
    },
    {
      "x": -3,
      "y": 7,
      "z": 10,
      "name": "Empty"
    },
    {
      "x": -3,
      "y": 8,
      "z": 10,
      "name": "Empty"
    },
    {
      "x": -3,
      "y": 9,
      "z": 10,
      "name": "Rock_Stone"
    },
    {
      "x": -3,
      "y": 10,
      "z": 10,
      "name": "Rock_Stone"
    },
    {
      "x": -3,
      "y": -1,
      "z": 11,
      "name": "Rock_Stone"
    },
    {
      "x": -3,
      "y": 0,
      "z": 11,
      "name": "Rock_Stone"
    },
    {
      "x": -3,
      "y": 1,
      "z": 11,
      "name": "Rock_Stone"
    },
    {
      "x": -3,
      "y": 2,
      "z": 11,
      "name": "Wood_Softwood_Planks"
    },
    {
      "x": -3,
      "y": 3,
      "z": 11,
      "name": "Empty"
    },
    {
      "x": -3,
      "y": 4,
      "z": 11,
      "name": "Empty"
    },
    {
      "x": -3,
      "y": 5,
      "z": 11,
      "name": "Empty"
    },
    {
      "x": -3,
      "y": 6,
      "z": 11,
      "name": "Empty"
    },
    {
      "x": -3,
      "y": 7,
      "z": 11,
      "name": "Empty"
    },
    {
      "x": -3,
      "y": 8,
      "z": 11,
      "name": "Empty"
    },
    {
      "x": -3,
      "y": 9,
      "z": 11,
      "name": "Rock_Stone"
    },
    {
      "x": -3,
      "y": 10,
      "z": 11,
      "name": "Rock_Stone"
    },
    {
      "x": -3,
      "y": -1,
      "z": 12,
      "name": "Rock_Stone"
    },
    {
      "x": -3,
      "y": 0,
      "z": 12,
      "name": "Rock_Stone"
    },
    {
      "x": -3,
      "y": 1,
      "z": 12,
      "name": "Rock_Stone"
    },
    {
      "x": -3,
      "y": 2,
      "z": 12,
      "name": "Wood_Softwood_Planks"
    },
    {
      "x": -3,
      "y": 3,
      "z": 12,
      "name": "Empty"
    },
    {
      "x": -3,
      "y": 4,
      "z": 12,
      "name": "Empty"
    },
    {
      "x": -3,
      "y": 5,
      "z": 12,
      "name": "Empty"
    },
    {
      "x": -3,
      "y": 6,
      "z": 12,
      "name": "Empty"
    },
    {
      "x": -3,
      "y": 7,
      "z": 12,
      "name": "Empty"
    },
    {
      "x": -3,
      "y": 8,
      "z": 12,
      "name": "Empty"
    },
    {
      "x": -3,
      "y": 9,
      "z": 12,
      "name": "Rock_Stone"
    },
    {
      "x": -3,
      "y": 10,
      "z": 12,
      "name": "Rock_Stone"
    },
    {
      "x": -3,
      "y": -1,
      "z": 13,
      "name": "Rock_Stone"
    },
    {
      "x": -3,
      "y": 0,
      "z": 13,
      "name": "Rock_Stone"
    },
    {
      "x": -3,
      "y": 1,
      "z": 13,
      "name": "Rock_Stone"
    },
    {
      "x": -3,
      "y": 2,
      "z": 13,
      "name": "Wood_Softwood_Planks"
    },
    {
      "x": -3,
      "y": 3,
      "z": 13,
      "name": "Wood_Softwood_Planks"
    },
    {
      "x": -3,
      "y": 4,
      "z": 13,
      "name": "Empty"
    },
    {
      "x": -3,
      "y": 5,
      "z": 13,
      "name": "Empty"
    },
    {
      "x": -3,
      "y": 6,
      "z": 13,
      "name": "Wood_Beech_Trunk",
      "rotation": 5
    },
    {
      "x": -3,
      "y": 7,
      "z": 13,
      "name": "Rock_Stone"
    },
    {
      "x": -3,
      "y": 8,
      "z": 13,
      "name": "Rock_Stone"
    },
    {
      "x": -3,
      "y": 9,
      "z": 13,
      "name": "Rock_Stone"
    },
    {
      "x": -3,
      "y": 10,
      "z": 13,
      "name": "Rock_Stone"
    },
    {
      "x": -3,
      "y": -1,
      "z": 14,
      "name": "Rock_Stone"
    },
    {
      "x": -3,
      "y": 0,
      "z": 14,
      "name": "Rock_Stone"
    },
    {
      "x": -3,
      "y": 1,
      "z": 14,
      "name": "Rock_Stone"
    },
    {
      "x": -3,
      "y": 2,
      "z": 14,
      "name": "Empty"
    },
    {
      "x": -3,
      "y": 3,
      "z": 14,
      "name": "Empty"
    },
    {
      "x": -3,
      "y": 4,
      "z": 14,
      "name": "Empty"
    },
    {
      "x": -3,
      "y": 5,
      "z": 14,
      "name": "Empty"
    },
    {
      "x": -3,
      "y": 6,
      "z": 14,
      "name": "Rock_Stone"
    },
    {
      "x": -3,
      "y": 7,
      "z": 14,
      "name": "Rock_Stone"
    },
    {
      "x": -3,
      "y": 8,
      "z": 14,
      "name": "Rock_Stone"
    },
    {
      "x": -3,
      "y": 9,
      "z": 14,
      "name": "Rock_Stone"
    },
    {
      "x": -3,
      "y": 10,
      "z": 14,
      "name": "Rock_Stone"
    },
    {
      "x": -2,
      "y": -1,
      "z": 0,
      "name": "Rock_Stone"
    },
    {
      "x": -2,
      "y": 0,
      "z": 0,
      "name": "Rock_Stone"
    },
    {
      "x": -2,
      "y": 1,
      "z": 0,
      "name": "Empty"
    },
    {
      "x": -2,
      "y": 2,
      "z": 0,
      "name": "Empty"
    },
    {
      "x": -2,
      "y": 3,
      "z": 0,
      "name": "Empty"
    },
    {
      "x": -2,
      "y": 4,
      "z": 0,
      "name": "Empty"
    },
    {
      "x": -2,
      "y": 5,
      "z": 0,
      "name": "Empty"
    },
    {
      "x": -2,
      "y": 6,
      "z": 0,
      "name": "Empty"
    },
    {
      "x": -2,
      "y": 7,
      "z": 0,
      "name": "Empty"
    },
    {
      "x": -2,
      "y": 8,
      "z": 0,
      "name": "Rock_Stone"
    },
    {
      "x": -2,
      "y": 9,
      "z": 0,
      "name": "Rock_Stone"
    },
    {
      "x": -2,
      "y": 10,
      "z": 0,
      "name": "Rock_Stone"
    },
    {
      "x": -2,
      "y": -1,
      "z": 1,
      "name": "Rock_Stone"
    },
    {
      "x": -2,
      "y": 0,
      "z": 1,
      "name": "Rock_Stone"
    },
    {
      "x": -2,
      "y": 1,
      "z": 1,
      "name": "*Rail_State_Definitions_Slope",
      "rotation": 1
    },
    {
      "x": -2,
      "y": 2,
      "z": 1,
      "name": "Empty"
    },
    {
      "x": -2,
      "y": 3,
      "z": 1,
      "name": "Empty"
    },
    {
      "x": -2,
      "y": 4,
      "z": 1,
      "name": "Empty"
    },
    {
      "x": -2,
      "y": 5,
      "z": 1,
      "name": "Empty"
    },
    {
      "x": -2,
      "y": 6,
      "z": 1,
      "name": "Empty"
    },
    {
      "x": -2,
      "y": 7,
      "z": 1,
      "name": "Empty"
    },
    {
      "x": -2,
      "y": 8,
      "z": 1,
      "name": "Rock_Stone"
    },
    {
      "x": -2,
      "y": 9,
      "z": 1,
      "name": "Rock_Stone"
    },
    {
      "x": -2,
      "y": 10,
      "z": 1,
      "name": "Rock_Stone"
    },
    {
      "x": -2,
      "y": -1,
      "z": 2,
      "name": "Rock_Stone"
    },
    {
      "x": -2,
      "y": 0,
      "z": 2,
      "name": "Rock_Stone"
    },
    {
      "x": -2,
      "y": 1,
      "z": 2,
      "name": "Rock_Stone"
    },
    {
      "x": -2,
      "y": 2,
      "z": 2,
      "name": "Empty"
    },
    {
      "x": -2,
      "y": 3,
      "z": 2,
      "name": "Empty"
    },
    {
      "x": -2,
      "y": 4,
      "z": 2,
      "name": "Empty"
    },
    {
      "x": -2,
      "y": 5,
      "z": 2,
      "name": "Empty"
    },
    {
      "x": -2,
      "y": 6,
      "z": 2,
      "name": "Wood_Softwood_Planks_Half",
      "rotation": 6
    },
    {
      "x": -2,
      "y": 7,
      "z": 2,
      "name": "Empty"
    },
    {
      "x": -2,
      "y": 8,
      "z": 2,
      "name": "Rock_Stone"
    },
    {
      "x": -2,
      "y": 9,
      "z": 2,
      "name": "Rock_Stone"
    },
    {
      "x": -2,
      "y": 10,
      "z": 2,
      "name": "Rock_Stone"
    },
    {
      "x": -2,
      "y": -1,
      "z": 3,
      "name": "Rock_Stone"
    },
    {
      "x": -2,
      "y": 0,
      "z": 3,
      "name": "Rock_Stone"
    },
    {
      "x": -2,
      "y": 1,
      "z": 3,
      "name": "Rock_Stone"
    },
    {
      "x": -2,
      "y": 2,
      "z": 3,
      "name": "Wood_Beech_Trunk"
    },
    {
      "x": -2,
      "y": 3,
      "z": 3,
      "name": "Wood_Beech_Trunk"
    },
    {
      "x": -2,
      "y": 4,
      "z": 3,
      "name": "Wood_Beech_Trunk"
    },
    {
      "x": -2,
      "y": 5,
      "z": 3,
      "name": "Wood_Beech_Trunk"
    },
    {
      "x": -2,
      "y": 6,
      "z": 3,
      "name": "Wood_Beech_Trunk",
      "rotation": 5
    },
    {
      "x": -2,
      "y": 7,
      "z": 3,
      "name": "Empty"
    },
    {
      "x": -2,
      "y": 8,
      "z": 3,
      "name": "Empty"
    },
    {
      "x": -2,
      "y": 9,
      "z": 3,
      "name": "Rock_Stone"
    },
    {
      "x": -2,
      "y": 10,
      "z": 3,
      "name": "Rock_Stone"
    },
    {
      "x": -2,
      "y": -1,
      "z": 4,
      "name": "Rock_Stone"
    },
    {
      "x": -2,
      "y": 0,
      "z": 4,
      "name": "Rock_Stone"
    },
    {
      "x": -2,
      "y": 1,
      "z": 4,
      "name": "Rock_Stone"
    },
    {
      "x": -2,
      "y": 2,
      "z": 4,
      "name": "Furniture_Crude_Platform",
      "rotation": 1
    },
    {
      "x": -2,
      "y": 3,
      "z": 4,
      "name": "Furniture_Crude_Bed",
      "components": {
        "Components": {
          "RespawnBlock": {}
        }
      },
      "rotation": 3
    },
    {
      "x": -2,
      "y": 4,
      "z": 4,
      "name": "Empty"
    },
    {
      "x": -2,
      "y": 5,
      "z": 4,
      "name": "Empty"
    },
    {
      "x": -2,
      "y": 6,
      "z": 4,
      "name": "Wood_Softwood_Planks_Half",
      "rotation": 4
    },
    {
      "x": -2,
      "y": 7,
      "z": 4,
      "name": "Empty"
    },
    {
      "x": -2,
      "y": 8,
      "z": 4,
      "name": "Empty"
    },
    {
      "x": -2,
      "y": 9,
      "z": 4,
      "name": "Rock_Stone"
    },
    {
      "x": -2,
      "y": 10,
      "z": 4,
      "name": "Rock_Stone"
    },
    {
      "x": -2,
      "y": -1,
      "z": 5,
      "name": "Rock_Stone"
    },
    {
      "x": -2,
      "y": 0,
      "z": 5,
      "name": "Rock_Stone"
    },
    {
      "x": -2,
      "y": 1,
      "z": 5,
      "name": "Rock_Stone"
    },
    {
      "x": -2,
      "y": 2,
      "z": 5,
      "name": "Furniture_Crude_Platform",
      "rotation": 1
    },
    {
      "x": -2,
      "y": 3,
      "z": 5,
      "name": "Empty"
    },
    {
      "x": -2,
      "y": 4,
      "z": 5,
      "name": "Empty"
    },
    {
      "x": -2,
      "y": 5,
      "z": 5,
      "name": "Empty"
    },
    {
      "x": -2,
      "y": 6,
      "z": 5,
      "name": "Empty"
    },
    {
      "x": -2,
      "y": 7,
      "z": 5,
      "name": "Empty"
    },
    {
      "x": -2,
      "y": 8,
      "z": 5,
      "name": "Empty"
    },
    {
      "x": -2,
      "y": 9,
      "z": 5,
      "name": "Rock_Stone"
    },
    {
      "x": -2,
      "y": 10,
      "z": 5,
      "name": "Rock_Stone"
    },
    {
      "x": -2,
      "y": -1,
      "z": 6,
      "name": "Rock_Stone"
    },
    {
      "x": -2,
      "y": 0,
      "z": 6,
      "name": "Rock_Stone"
    },
    {
      "x": -2,
      "y": 1,
      "z": 6,
      "name": "Rock_Stone"
    },
    {
      "x": -2,
      "y": 2,
      "z": 6,
      "name": "Wood_Softwood_Planks"
    },
    {
      "x": -2,
      "y": 3,
      "z": 6,
      "name": "Empty"
    },
    {
      "x": -2,
      "y": 4,
      "z": 6,
      "name": "Empty"
    },
    {
      "x": -2,
      "y": 5,
      "z": 6,
      "name": "Empty"
    },
    {
      "x": -2,
      "y": 6,
      "z": 6,
      "name": "Empty"
    },
    {
      "x": -2,
      "y": 7,
      "z": 6,
      "name": "Empty"
    },
    {
      "x": -2,
      "y": 8,
      "z": 6,
      "name": "Empty"
    },
    {
      "x": -2,
      "y": 9,
      "z": 6,
      "name": "Empty"
    },
    {
      "x": -2,
      "y": 10,
      "z": 6,
      "name": "Rock_Stone"
    },
    {
      "x": -2,
      "y": -1,
      "z": 7,
      "name": "Rock_Stone"
    },
    {
      "x": -2,
      "y": 0,
      "z": 7,
      "name": "Rock_Stone"
    },
    {
      "x": -2,
      "y": 1,
      "z": 7,
      "name": "Rock_Stone"
    },
    {
      "x": -2,
      "y": 2,
      "z": 7,
      "name": "Wood_Softwood_Planks"
    },
    {
      "x": -2,
      "y": 3,
      "z": 7,
      "name": "Furniture_Crude_Bed",
      "components": {
        "Components": {
          "RespawnBlock": {}
        }
      }
    },
    {
      "x": -2,
      "y": 4,
      "z": 7,
      "name": "Empty"
    },
    {
      "x": -2,
      "y": 5,
      "z": 7,
      "name": "Empty"
    },
    {
      "x": -2,
      "y": 6,
      "z": 7,
      "name": "Empty"
    },
    {
      "x": -2,
      "y": 7,
      "z": 7,
      "name": "Empty"
    },
    {
      "x": -2,
      "y": 8,
      "z": 7,
      "name": "Empty"
    },
    {
      "x": -2,
      "y": 9,
      "z": 7,
      "name": "Empty"
    },
    {
      "x": -2,
      "y": 10,
      "z": 7,
      "name": "Rock_Stone"
    },
    {
      "x": -2,
      "y": -1,
      "z": 8,
      "name": "Rock_Stone"
    },
    {
      "x": -2,
      "y": 0,
      "z": 8,
      "name": "Rock_Stone"
    },
    {
      "x": -2,
      "y": 1,
      "z": 8,
      "name": "Rock_Stone"
    },
    {
      "x": -2,
      "y": 2,
      "z": 8,
      "name": "Wood_Softwood_Planks"
    },
    {
      "x": -2,
      "y": 3,
      "z": 8,
      "name": "Furniture_Crude_Bed",
      "components": {
        "Components": {
          "RespawnBlock": {}
        }
      },
      "filler": 32
    },
    {
      "x": -2,
      "y": 4,
      "z": 8,
      "name": "Empty"
    },
    {
      "x": -2,
      "y": 5,
      "z": 8,
      "name": "Empty"
    },
    {
      "x": -2,
      "y": 6,
      "z": 8,
      "name": "Empty"
    },
    {
      "x": -2,
      "y": 7,
      "z": 8,
      "name": "Empty"
    },
    {
      "x": -2,
      "y": 8,
      "z": 8,
      "name": "Empty"
    },
    {
      "x": -2,
      "y": 9,
      "z": 8,
      "name": "Empty"
    },
    {
      "x": -2,
      "y": 10,
      "z": 8,
      "name": "Rock_Stone"
    },
    {
      "x": -2,
      "y": -1,
      "z": 9,
      "name": "Rock_Stone"
    },
    {
      "x": -2,
      "y": 0,
      "z": 9,
      "name": "Rock_Stone"
    },
    {
      "x": -2,
      "y": 1,
      "z": 9,
      "name": "Rock_Stone"
    },
    {
      "x": -2,
      "y": 2,
      "z": 9,
      "name": "Wood_Softwood_Planks"
    },
    {
      "x": -2,
      "y": 3,
      "z": 9,
      "name": "Empty"
    },
    {
      "x": -2,
      "y": 4,
      "z": 9,
      "name": "Empty"
    },
    {
      "x": -2,
      "y": 5,
      "z": 9,
      "name": "Empty"
    },
    {
      "x": -2,
      "y": 6,
      "z": 9,
      "name": "Empty"
    },
    {
      "x": -2,
      "y": 7,
      "z": 9,
      "name": "Empty"
    },
    {
      "x": -2,
      "y": 8,
      "z": 9,
      "name": "Empty"
    },
    {
      "x": -2,
      "y": 9,
      "z": 9,
      "name": "Rock_Stone"
    },
    {
      "x": -2,
      "y": 10,
      "z": 9,
      "name": "Rock_Stone"
    },
    {
      "x": -2,
      "y": -1,
      "z": 10,
      "name": "Rock_Stone"
    },
    {
      "x": -2,
      "y": 0,
      "z": 10,
      "name": "Rock_Stone"
    },
    {
      "x": -2,
      "y": 1,
      "z": 10,
      "name": "Soil_Gravel"
    },
    {
      "x": -2,
      "y": 2,
      "z": 10,
      "name": "Wood_Softwood_Stairs",
      "rotation": 1
    },
    {
      "x": -2,
      "y": 3,
      "z": 10,
      "name": "Empty"
    },
    {
      "x": -2,
      "y": 4,
      "z": 10,
      "name": "Empty"
    },
    {
      "x": -2,
      "y": 5,
      "z": 10,
      "name": "Empty"
    },
    {
      "x": -2,
      "y": 6,
      "z": 10,
      "name": "Empty"
    },
    {
      "x": -2,
      "y": 7,
      "z": 10,
      "name": "Empty"
    },
    {
      "x": -2,
      "y": 8,
      "z": 10,
      "name": "Empty"
    },
    {
      "x": -2,
      "y": 9,
      "z": 10,
      "name": "Rock_Stone"
    },
    {
      "x": -2,
      "y": 10,
      "z": 10,
      "name": "Rock_Stone"
    },
    {
      "x": -2,
      "y": -1,
      "z": 11,
      "name": "Rock_Stone"
    },
    {
      "x": -2,
      "y": 0,
      "z": 11,
      "name": "Soil_Gravel"
    },
    {
      "x": -2,
      "y": 1,
      "z": 11,
      "name": "Rock_Stone"
    },
    {
      "x": -2,
      "y": 2,
      "z": 11,
      "name": "Wood_Softwood_Stairs",
      "rotation": 1
    },
    {
      "x": -2,
      "y": 3,
      "z": 11,
      "name": "Empty"
    },
    {
      "x": -2,
      "y": 4,
      "z": 11,
      "name": "Empty"
    },
    {
      "x": -2,
      "y": 5,
      "z": 11,
      "name": "Empty"
    },
    {
      "x": -2,
      "y": 6,
      "z": 11,
      "name": "Empty"
    },
    {
      "x": -2,
      "y": 7,
      "z": 11,
      "name": "Empty"
    },
    {
      "x": -2,
      "y": 8,
      "z": 11,
      "name": "Empty"
    },
    {
      "x": -2,
      "y": 9,
      "z": 11,
      "name": "Rock_Stone"
    },
    {
      "x": -2,
      "y": 10,
      "z": 11,
      "name": "Rock_Stone"
    },
    {
      "x": -2,
      "y": -1,
      "z": 12,
      "name": "Rock_Stone"
    },
    {
      "x": -2,
      "y": 0,
      "z": 12,
      "name": "Rock_Stone"
    },
    {
      "x": -2,
      "y": 1,
      "z": 12,
      "name": "Rock_Stone"
    },
    {
      "x": -2,
      "y": 2,
      "z": 12,
      "name": "Wood_Softwood_Planks"
    },
    {
      "x": -2,
      "y": 3,
      "z": 12,
      "name": "Empty"
    },
    {
      "x": -2,
      "y": 4,
      "z": 12,
      "name": "Empty"
    },
    {
      "x": -2,
      "y": 5,
      "z": 12,
      "name": "Empty"
    },
    {
      "x": -2,
      "y": 6,
      "z": 12,
      "name": "Wood_Softwood_Planks_Half",
      "rotation": 6
    },
    {
      "x": -2,
      "y": 7,
      "z": 12,
      "name": "Empty"
    },
    {
      "x": -2,
      "y": 8,
      "z": 12,
      "name": "Empty"
    },
    {
      "x": -2,
      "y": 9,
      "z": 12,
      "name": "Rock_Stone"
    },
    {
      "x": -2,
      "y": 10,
      "z": 12,
      "name": "Rock_Stone"
    },
    {
      "x": -2,
      "y": -1,
      "z": 13,
      "name": "Rock_Stone"
    },
    {
      "x": -2,
      "y": 0,
      "z": 13,
      "name": "Rock_Stone"
    },
    {
      "x": -2,
      "y": 1,
      "z": 13,
      "name": "Wood_Beech_Trunk"
    },
    {
      "x": -2,
      "y": 2,
      "z": 13,
      "name": "Wood_Beech_Trunk"
    },
    {
      "x": -2,
      "y": 3,
      "z": 13,
      "name": "Wood_Beech_Trunk"
    },
    {
      "x": -2,
      "y": 4,
      "z": 13,
      "name": "Wood_Beech_Trunk"
    },
    {
      "x": -2,
      "y": 5,
      "z": 13,
      "name": "Wood_Beech_Trunk"
    },
    {
      "x": -2,
      "y": 6,
      "z": 13,
      "name": "Wood_Beech_Trunk",
      "rotation": 5
    },
    {
      "x": -2,
      "y": 7,
      "z": 13,
      "name": "Empty"
    },
    {
      "x": -2,
      "y": 8,
      "z": 13,
      "name": "Rock_Stone"
    },
    {
      "x": -2,
      "y": 9,
      "z": 13,
      "name": "Rock_Stone"
    },
    {
      "x": -2,
      "y": 10,
      "z": 13,
      "name": "Rock_Stone"
    },
    {
      "x": -2,
      "y": -1,
      "z": 14,
      "name": "Rock_Stone"
    },
    {
      "x": -2,
      "y": 0,
      "z": 14,
      "name": "Rock_Stone"
    },
    {
      "x": -2,
      "y": 1,
      "z": 14,
      "name": "Empty"
    },
    {
      "x": -2,
      "y": 2,
      "z": 14,
      "name": "Empty"
    },
    {
      "x": -2,
      "y": 3,
      "z": 14,
      "name": "Empty"
    },
    {
      "x": -2,
      "y": 4,
      "z": 14,
      "name": "Empty"
    },
    {
      "x": -2,
      "y": 5,
      "z": 14,
      "name": "Empty"
    },
    {
      "x": -2,
      "y": 6,
      "z": 14,
      "name": "Wood_Softwood_Planks_Half",
      "rotation": 4
    },
    {
      "x": -2,
      "y": 7,
      "z": 14,
      "name": "Rock_Stone"
    },
    {
      "x": -2,
      "y": 8,
      "z": 14,
      "name": "Rock_Stone"
    },
    {
      "x": -2,
      "y": 9,
      "z": 14,
      "name": "Rock_Stone"
    },
    {
      "x": -2,
      "y": 10,
      "z": 14,
      "name": "Rock_Stone"
    },
    {
      "x": -1,
      "y": -1,
      "z": 0,
      "name": "Rock_Stone"
    },
    {
      "x": -1,
      "y": 0,
      "z": 0,
      "name": "Rock_Stone"
    },
    {
      "x": -1,
      "y": 1,
      "z": 0,
      "name": "Empty"
    },
    {
      "x": -1,
      "y": 2,
      "z": 0,
      "name": "Empty"
    },
    {
      "x": -1,
      "y": 3,
      "z": 0,
      "name": "Empty"
    },
    {
      "x": -1,
      "y": 4,
      "z": 0,
      "name": "Empty"
    },
    {
      "x": -1,
      "y": 5,
      "z": 0,
      "name": "Empty"
    },
    {
      "x": -1,
      "y": 6,
      "z": 0,
      "name": "Empty"
    },
    {
      "x": -1,
      "y": 7,
      "z": 0,
      "name": "Empty"
    },
    {
      "x": -1,
      "y": 8,
      "z": 0,
      "name": "Rock_Stone"
    },
    {
      "x": -1,
      "y": 9,
      "z": 0,
      "name": "Rock_Stone"
    },
    {
      "x": -1,
      "y": 10,
      "z": 0,
      "name": "Rock_Stone"
    },
    {
      "x": -1,
      "y": -1,
      "z": 1,
      "name": "Rock_Stone"
    },
    {
      "x": -1,
      "y": 0,
      "z": 1,
      "name": "Rock_Stone"
    },
    {
      "x": -1,
      "y": 1,
      "z": 1,
      "name": "Rail",
      "rotation": 1
    },
    {
      "x": -1,
      "y": 2,
      "z": 1,
      "name": "Empty"
    },
    {
      "x": -1,
      "y": 3,
      "z": 1,
      "name": "Empty"
    },
    {
      "x": -1,
      "y": 4,
      "z": 1,
      "name": "Empty"
    },
    {
      "x": -1,
      "y": 5,
      "z": 1,
      "name": "Empty"
    },
    {
      "x": -1,
      "y": 6,
      "z": 1,
      "name": "Empty"
    },
    {
      "x": -1,
      "y": 7,
      "z": 1,
      "name": "Empty"
    },
    {
      "x": -1,
      "y": 8,
      "z": 1,
      "name": "Rock_Stone"
    },
    {
      "x": -1,
      "y": 9,
      "z": 1,
      "name": "Rock_Stone"
    },
    {
      "x": -1,
      "y": 10,
      "z": 1,
      "name": "Rock_Stone"
    },
    {
      "x": -1,
      "y": -1,
      "z": 2,
      "name": "Rock_Stone"
    },
    {
      "x": -1,
      "y": 0,
      "z": 2,
      "name": "Rock_Stone"
    },
    {
      "x": -1,
      "y": 1,
      "z": 2,
      "name": "Empty"
    },
    {
      "x": -1,
      "y": 2,
      "z": 2,
      "name": "Empty"
    },
    {
      "x": -1,
      "y": 3,
      "z": 2,
      "name": "Empty"
    },
    {
      "x": -1,
      "y": 4,
      "z": 2,
      "name": "Empty"
    },
    {
      "x": -1,
      "y": 5,
      "z": 2,
      "name": "Empty"
    },
    {
      "x": -1,
      "y": 6,
      "z": 2,
      "name": "Empty"
    },
    {
      "x": -1,
      "y": 7,
      "z": 2,
      "name": "Empty"
    },
    {
      "x": -1,
      "y": 8,
      "z": 2,
      "name": "Empty"
    },
    {
      "x": -1,
      "y": 9,
      "z": 2,
      "name": "Rock_Stone"
    },
    {
      "x": -1,
      "y": 10,
      "z": 2,
      "name": "Rock_Stone"
    },
    {
      "x": -1,
      "y": -1,
      "z": 3,
      "name": "Rock_Stone"
    },
    {
      "x": -1,
      "y": 0,
      "z": 3,
      "name": "Rock_Stone"
    },
    {
      "x": -1,
      "y": 1,
      "z": 3,
      "name": "Wood_Softwood_Planks"
    },
    {
      "x": -1,
      "y": 2,
      "z": 3,
      "name": "Wood_Softwood_Planks"
    },
    {
      "x": -1,
      "y": 3,
      "z": 3,
      "name": "Wood_Softwood_Planks"
    },
    {
      "x": -1,
      "y": 4,
      "z": 3,
      "name": "Wood_Softwood_Fence",
      "rotation": 2
    },
    {
      "x": -1,
      "y": 5,
      "z": 3,
      "name": "Empty"
    },
    {
      "x": -1,
      "y": 6,
      "z": 3,
      "name": "Wood_Beech_Trunk",
      "rotation": 5
    },
    {
      "x": -1,
      "y": 7,
      "z": 3,
      "name": "Empty"
    },
    {
      "x": -1,
      "y": 8,
      "z": 3,
      "name": "Empty"
    },
    {
      "x": -1,
      "y": 9,
      "z": 3,
      "name": "Rock_Stone"
    },
    {
      "x": -1,
      "y": 10,
      "z": 3,
      "name": "Rock_Stone"
    },
    {
      "x": -1,
      "y": -1,
      "z": 4,
      "name": "Rock_Stone"
    },
    {
      "x": -1,
      "y": 0,
      "z": 4,
      "name": "Rock_Stone"
    },
    {
      "x": -1,
      "y": 1,
      "z": 4,
      "name": "Rock_Stone"
    },
    {
      "x": -1,
      "y": 2,
      "z": 4,
      "name": "Furniture_Crude_Platform",
      "rotation": 1
    },
    {
      "x": -1,
      "y": 3,
      "z": 4,
      "name": "Empty"
    },
    {
      "x": -1,
      "y": 4,
      "z": 4,
      "name": "Empty"
    },
    {
      "x": -1,
      "y": 5,
      "z": 4,
      "name": "Empty"
    },
    {
      "x": -1,
      "y": 6,
      "z": 4,
      "name": "Empty"
    },
    {
      "x": -1,
      "y": 7,
      "z": 4,
      "name": "Empty"
    },
    {
      "x": -1,
      "y": 8,
      "z": 4,
      "name": "Empty"
    },
    {
      "x": -1,
      "y": 9,
      "z": 4,
      "name": "Rock_Stone"
    },
    {
      "x": -1,
      "y": 10,
      "z": 4,
      "name": "Rock_Stone"
    },
    {
      "x": -1,
      "y": -1,
      "z": 5,
      "name": "Rock_Stone"
    },
    {
      "x": -1,
      "y": 0,
      "z": 5,
      "name": "Rock_Stone"
    },
    {
      "x": -1,
      "y": 1,
      "z": 5,
      "name": "Empty"
    },
    {
      "x": -1,
      "y": 2,
      "z": 5,
      "name": "Furniture_Crude_Platform",
      "rotation": 1
    },
    {
      "x": -1,
      "y": 3,
      "z": 5,
      "name": "Empty"
    },
    {
      "x": -1,
      "y": 4,
      "z": 5,
      "name": "Empty"
    },
    {
      "x": -1,
      "y": 5,
      "z": 5,
      "name": "Empty"
    },
    {
      "x": -1,
      "y": 6,
      "z": 5,
      "name": "Empty"
    },
    {
      "x": -1,
      "y": 7,
      "z": 5,
      "name": "Empty"
    },
    {
      "x": -1,
      "y": 8,
      "z": 5,
      "name": "Empty"
    },
    {
      "x": -1,
      "y": 9,
      "z": 5,
      "name": "Empty"
    },
    {
      "x": -1,
      "y": 10,
      "z": 5,
      "name": "Rock_Stone"
    },
    {
      "x": -1,
      "y": -1,
      "z": 6,
      "name": "Rock_Stone"
    },
    {
      "x": -1,
      "y": 0,
      "z": 6,
      "name": "Rock_Stone"
    },
    {
      "x": -1,
      "y": 1,
      "z": 6,
      "name": "Furniture_Tavern_Barrel"
    },
    {
      "x": -1,
      "y": 2,
      "z": 6,
      "name": "Furniture_Crude_Platform",
      "rotation": 1
    },
    {
      "x": -1,
      "y": 3,
      "z": 6,
      "name": "Empty"
    },
    {
      "x": -1,
      "y": 4,
      "z": 6,
      "name": "Empty"
    },
    {
      "x": -1,
      "y": 5,
      "z": 6,
      "name": "Empty"
    },
    {
      "x": -1,
      "y": 6,
      "z": 6,
      "name": "Empty"
    },
    {
      "x": -1,
      "y": 7,
      "z": 6,
      "name": "Empty"
    },
    {
      "x": -1,
      "y": 8,
      "z": 6,
      "name": "Empty"
    },
    {
      "x": -1,
      "y": 9,
      "z": 6,
      "name": "Empty"
    },
    {
      "x": -1,
      "y": 10,
      "z": 6,
      "name": "Rock_Stone"
    },
    {
      "x": -1,
      "y": -1,
      "z": 7,
      "name": "Rock_Stone"
    },
    {
      "x": -1,
      "y": 0,
      "z": 7,
      "name": "Rock_Stone"
    },
    {
      "x": -1,
      "y": 1,
      "z": 7,
      "name": "Rock_Stone"
    },
    {
      "x": -1,
      "y": 2,
      "z": 7,
      "name": "Furniture_Crude_Platform",
      "rotation": 1
    },
    {
      "x": -1,
      "y": 3,
      "z": 7,
      "name": "Wood_Softwood_Fence",
      "rotation": 1
    },
    {
      "x": -1,
      "y": 4,
      "z": 7,
      "name": "Empty"
    },
    {
      "x": -1,
      "y": 5,
      "z": 7,
      "name": "Empty"
    },
    {
      "x": -1,
      "y": 6,
      "z": 7,
      "name": "Empty"
    },
    {
      "x": -1,
      "y": 7,
      "z": 7,
      "name": "Empty"
    },
    {
      "x": -1,
      "y": 8,
      "z": 7,
      "name": "Empty"
    },
    {
      "x": -1,
      "y": 9,
      "z": 7,
      "name": "Empty"
    },
    {
      "x": -1,
      "y": 10,
      "z": 7,
      "name": "Rock_Stone"
    },
    {
      "x": -1,
      "y": -1,
      "z": 8,
      "name": "Rock_Stone"
    },
    {
      "x": -1,
      "y": 0,
      "z": 8,
      "name": "Rock_Stone"
    },
    {
      "x": -1,
      "y": 1,
      "z": 8,
      "name": "Wood_Beech_Trunk"
    },
    {
      "x": -1,
      "y": 2,
      "z": 8,
      "name": "Wood_Softwood_Planks"
    },
    {
      "x": -1,
      "y": 3,
      "z": 8,
      "name": "Wood_Softwood_Fence",
      "rotation": 1
    },
    {
      "x": -1,
      "y": 4,
      "z": 8,
