{
  "version": 8,
  "blockIdVersion": 8,
  "anchorX": 0,
  "anchorY": 23,
  "anchorZ": 0,
  "blocks": [
    {
      "x": -5,
      "y": 21,
      "z": -3,
      "name": "Rock_Shale"
    },
    {
      "x": -5,
      "y": 22,
      "z": -3,
      "name": "Rock_Shale"
    },
    {
      "x": -5,
      "y": 21,
      "z": -2,
      "name": "Rock_Shale"
    },
    {
      "x": -5,
      "y": 22,
      "z": -2,
      "name": "Rock_Shale"
    },
    {
      "x": -4,
      "y": 21,
      "z": -4,
      "name": "Rock_Shale"
    },
    {
      "x": -4,
      "y": 22,
      "z": -4,
      "name": "Soil_Pebbles_Frozen"
    },
    {
      "x": -4,
      "y": 21,
      "z": -3,
      "name": "Rock_Shale"
    },
    {
      "x": -4,
      "y": 22,
      "z": -3,
      "name": "Rock_Shale"
    },
    {
      "x": -4,
      "y": 23,
      "z": -3,
      "name": "Soil_Pebbles_Frozen"
    },
    {
      "x": -4,
      "y": 21,
      "z": -2,
      "name": "Rock_Shale"
    },
    {
      "x": -4,
      "y": 22,
      "z": -2,
      "name": "Rock_Shale"
    },
    {
      "x": -4,
      "y": 23,
      "z": -2,
      "name": "Soil_Pebbles_Frozen"
    },
    {
      "x": -4,
      "y": 24,
      "z": -2,
      "name": "Rubble_Shale"
    },
    {
      "x": -4,
      "y": 21,
      "z": -1,
      "name": "Rock_Shale"
    },
    {
      "x": -4,
      "y": 22,
      "z": -1,
      "name": "Rock_Shale"
    },
    {
      "x": -4,
      "y": 23,
      "z": -1,
      "name": "Rock_Shale"
    },
    {
      "x": -4,
      "y": 24,
      "z": -1,
      "name": "Rock_Shale"
    },
    {
      "x": -4,
      "y": 25,
      "z": -1,
      "name": "Rock_Shale"
    },
    {
      "x": -4,
      "y": 26,
      "z": -1,
      "name": "Rock_Shale"
    },
    {
      "x": -4,
      "y": 27,
      "z": -1,
      "name": "Rock_Shale"
    },
    {
      "x": -4,
      "y": 28,
      "z": -1,
      "name": "Rock_Shale"
    },
    {
      "x": -4,
      "y": 21,
      "z": 0,
      "name": "Rock_Shale"
    },
    {
      "x": -4,
      "y": 22,
      "z": 0,
      "name": "Rock_Shale"
    },
    {
      "x": -4,
      "y": 23,
      "z": 0,
      "name": "Rock_Shale"
    },
    {
      "x": -4,
      "y": 24,
      "z": 0,
      "name": "Rock_Shale"
    },
    {
      "x": -4,
      "y": 25,
      "z": 0,
      "name": "Rock_Shale"
    },
    {
      "x": -4,
      "y": 26,
      "z": 0,
      "name": "Rock_Shale"
    },
    {
      "x": -4,
      "y": 27,
      "z": 0,
      "name": "Rock_Shale"
    },
    {
      "x": -4,
      "y": 28,
      "z": 0,
      "name": "Rock_Shale"
    },
    {
      "x": -4,
      "y": 20,
      "z": 1,
      "name": "Rock_Shale"
    },
    {
      "x": -4,
      "y": 21,
      "z": 1,
      "name": "Rock_Shale"
    },
    {
      "x": -4,
      "y": 22,
      "z": 1,
      "name": "Rock_Shale"
    },
    {
      "x": -4,
      "y": 23,
      "z": 1,
      "name": "Rock_Shale"
    },
    {
      "x": -4,
      "y": 24,
      "z": 1,
      "name": "Rock_Shale"
    },
    {
      "x": -4,
      "y": 25,
      "z": 1,
      "name": "Rock_Shale"
    },
    {
      "x": -4,
      "y": 26,
      "z": 1,
      "name": "Rock_Shale"
    },
    {
      "x": -4,
      "y": 27,
      "z": 1,
      "name": "Rock_Shale"
    },
    {
      "x": -4,
      "y": 28,
      "z": 1,
      "name": "Rock_Shale"
    },
    {
      "x": -4,
      "y": 25,
      "z": 2,
      "name": "Rock_Shale"
    },
    {
      "x": -4,
      "y": 26,
      "z": 2,
      "name": "Rock_Shale"
    },
    {
      "x": -3,
      "y": 22,
      "z": -5,
      "name": "Soil_Pebbles_Frozen"
    },
    {
      "x": -3,
      "y": 20,
      "z": -4,
      "name": "Rock_Shale"
    },
    {
      "x": -3,
      "y": 21,
      "z": -4,
      "name": "Rock_Shale"
    },
    {
      "x": -3,
      "y": 22,
      "z": -4,
      "name": "Rock_Shale"
    },
    {
      "x": -3,
      "y": 23,
      "z": -4,
      "name": "Soil_Pebbles_Frozen"
    },
    {
      "x": -3,
      "y": 17,
      "z": -3,
      "name": "Rock_Shale"
    },
    {
      "x": -3,
      "y": 18,
      "z": -3,
      "name": "Rock_Shale"
    },
    {
      "x": -3,
      "y": 19,
      "z": -3,
      "name": "Rock_Shale"
    },
    {
      "x": -3,
      "y": 20,
      "z": -3,
      "name": "Rock_Shale"
    },
    {
      "x": -3,
      "y": 21,
      "z": -3,
      "name": "Rock_Shale"
    },
    {
      "x": -3,
      "y": 22,
      "z": -3,
      "name": "Rock_Shale"
    },
    {
      "x": -3,
      "y": 23,
      "z": -3,
      "name": "Rock_Shale"
    },
    {
      "x": -3,
      "y": 24,
      "z": -3,
      "name": "Rock_Shale"
    },
    {
      "x": -3,
      "y": 25,
      "z": -3,
      "name": "Rock_Shale"
    },
    {
      "x": -3,
      "y": 17,
      "z": -2,
      "name": "Rock_Shale"
    },
    {
      "x": -3,
      "y": 18,
      "z": -2,
      "name": "Rock_Shale"
    },
    {
      "x": -3,
      "y": 19,
      "z": -2,
      "name": "Rock_Shale"
    },
    {
      "x": -3,
      "y": 20,
      "z": -2,
      "name": "Rock_Shale"
    },
    {
      "x": -3,
      "y": 21,
      "z": -2,
      "name": "Rock_Shale"
    },
    {
      "x": -3,
      "y": 22,
      "z": -2,
      "name": "Rock_Shale"
    },
    {
      "x": -3,
      "y": 23,
      "z": -2,
      "name": "Rock_Shale"
    },
    {
      "x": -3,
      "y": 24,
      "z": -2,
      "name": "Rock_Shale"
    },
    {
      "x": -3,
      "y": 25,
      "z": -2,
      "name": "Rock_Shale"
    },
    {
      "x": -3,
      "y": 26,
      "z": -2,
      "name": "Rock_Shale"
    },
    {
      "x": -3,
      "y": 27,
      "z": -2,
      "name": "Rock_Shale"
    },
    {
      "x": -3,
      "y": 28,
      "z": -2,
      "name": "Rock_Shale"
    },
    {
      "x": -3,
      "y": 29,
      "z": -2,
      "name": "Rock_Shale"
    },
    {
      "x": -3,
      "y": 30,
      "z": -2,
      "name": "Rock_Shale"
    },
    {
      "x": -3,
      "y": 31,
      "z": -2,
      "name": "Rock_Shale"
    },
    {
      "x": -3,
      "y": 14,
      "z": -1,
      "name": "Rock_Shale"
    },
    {
      "x": -3,
      "y": 15,
      "z": -1,
      "name": "Rock_Shale"
    },
    {
      "x": -3,
      "y": 16,
      "z": -1,
      "name": "Rock_Shale"
    },
    {
      "x": -3,
      "y": 17,
      "z": -1,
      "name": "Rock_Shale"
    },
    {
      "x": -3,
      "y": 18,
      "z": -1,
      "name": "Rock_Shale"
    },
    {
      "x": -3,
      "y": 19,
      "z": -1,
      "name": "Rock_Shale"
    },
    {
      "x": -3,
      "y": 20,
      "z": -1,
      "name": "Rock_Shale"
    },
    {
      "x": -3,
      "y": 21,
      "z": -1,
      "name": "Rock_Shale"
    },
    {
      "x": -3,
      "y": 22,
      "z": -1,
      "name": "Rock_Shale"
    },
    {
      "x": -3,
      "y": 23,
      "z": -1,
      "name": "Rock_Shale"
    },
    {
      "x": -3,
      "y": 24,
      "z": -1,
      "name": "Rock_Shale"
    },
    {
      "x": -3,
      "y": 25,
      "z": -1,
      "name": "Rock_Shale"
    },
    {
      "x": -3,
      "y": 26,
      "z": -1,
      "name": "Rock_Shale"
    },
    {
      "x": -3,
      "y": 27,
      "z": -1,
      "name": "Rock_Shale"
    },
    {
      "x": -3,
      "y": 28,
      "z": -1,
      "name": "Rock_Shale"
    },
    {
      "x": -3,
      "y": 29,
      "z": -1,
      "name": "Rock_Shale"
    },
    {
      "x": -3,
      "y": 30,
      "z": -1,
      "name": "Soil_Pebbles_Frozen"
    },
    {
      "x": -3,
      "y": 13,
      "z": 0,
      "name": "Rock_Shale"
    },
    {
      "x": -3,
      "y": 14,
      "z": 0,
      "name": "Rock_Shale"
    },
    {
      "x": -3,
      "y": 15,
      "z": 0,
      "name": "Rock_Shale"
    },
    {
      "x": -3,
      "y": 16,
      "z": 0,
      "name": "Rock_Shale"
    },
    {
      "x": -3,
      "y": 17,
      "z": 0,
      "name": "Rock_Shale"
    },
    {
      "x": -3,
      "y": 18,
      "z": 0,
      "name": "Rock_Shale"
    },
    {
      "x": -3,
      "y": 19,
      "z": 0,
      "name": "Rock_Shale"
    },
    {
      "x": -3,
      "y": 20,
      "z": 0,
      "name": "Rock_Shale"
    },
    {
      "x": -3,
      "y": 21,
      "z": 0,
      "name": "Rock_Shale"
    },
    {
      "x": -3,
      "y": 22,
      "z": 0,
      "name": "Rock_Shale"
    },
    {
      "x": -3,
      "y": 23,
      "z": 0,
      "name": "Rock_Shale"
    },
    {
      "x": -3,
      "y": 24,
      "z": 0,
      "name": "Rock_Shale"
    },
    {
      "x": -3,
      "y": 25,
      "z": 0,
      "name": "Rock_Shale"
    },
    {
      "x": -3,
      "y": 26,
      "z": 0,
      "name": "Rock_Shale"
    },
    {
      "x": -3,
      "y": 27,
      "z": 0,
      "name": "Rock_Shale"
    },
    {
      "x": -3,
      "y": 28,
      "z": 0,
      "name": "Soil_Pebbles_Frozen"
    },
    {
      "x": -3,
      "y": 29,
      "z": 0,
      "name": "Rubble_Shale"
    },
    {
      "x": -3,
      "y": 14,
      "z": 1,
      "name": "Rock_Shale"
    },
    {
      "x": -3,
      "y": 15,
      "z": 1,
      "name": "Rock_Shale"
    },
    {
      "x": -3,
      "y": 16,
      "z": 1,
      "name": "Rock_Shale"
    },
    {
      "x": -3,
      "y": 17,
      "z": 1,
      "name": "Rock_Shale"
    },
    {
      "x": -3,
      "y": 18,
      "z": 1,
      "name": "Rock_Shale"
    },
    {
      "x": -3,
      "y": 19,
      "z": 1,
      "name": "Rock_Shale"
    },
    {
      "x": -3,
      "y": 20,
      "z": 1,
      "name": "Rock_Shale"
    },
    {
      "x": -3,
      "y": 21,
      "z": 1,
      "name": "Rock_Shale"
    },
    {
      "x": -3,
      "y": 22,
      "z": 1,
      "name": "Rock_Shale"
    },
    {
      "x": -3,
      "y": 23,
      "z": 1,
      "name": "Rock_Shale"
    },
    {
      "x": -3,
      "y": 24,
      "z": 1,
      "name": "Rock_Shale"
    },
    {
      "x": -3,
      "y": 25,
      "z": 1,
      "name": "Rock_Shale"
    },
    {
      "x": -3,
      "y": 26,
      "z": 1,
      "name": "Rock_Shale"
    },
    {
      "x": -3,
      "y": 27,
      "z": 1,
      "name": "Rock_Shale"
    },
    {
      "x": -3,
      "y": 28,
      "z": 1,
      "name": "Soil_Pebbles_Frozen"
    },
    {
      "x": -3,
      "y": 19,
      "z": 2,
      "name": "Rock_Shale"
    },
    {
      "x": -3,
      "y": 20,
      "z": 2,
      "name": "Rock_Shale"
    },
    {
      "x": -3,
      "y": 21,
      "z": 2,
      "name": "Rock_Shale"
    },
    {
      "x": -3,
      "y": 22,
      "z": 2,
      "name": "Rock_Shale"
    },
    {
      "x": -3,
      "y": 23,
      "z": 2,
      "name": "Rock_Shale"
    },
    {
      "x": -3,
      "y": 24,
      "z": 2,
      "name": "Rock_Shale"
    },
    {
      "x": -3,
      "y": 25,
      "z": 2,
      "name": "Rock_Shale"
    },
    {
      "x": -3,
      "y": 26,
      "z": 2,
      "name": "Rock_Shale"
    },
    {
      "x": -3,
      "y": 27,
      "z": 2,
      "name": "Rock_Shale"
    },
    {
      "x": -3,
      "y": 28,
      "z": 2,
      "name": "Soil_Pebbles_Frozen"
    },
    {
      "x": -2,
      "y": 21,
      "z": -5,
      "name": "Rock_Shale"
    },
    {
      "x": -2,
      "y": 22,
      "z": -5,
      "name": "Rock_Shale"
    },
    {
      "x": -2,
      "y": 23,
      "z": -5,
      "name": "Soil_Pebbles_Frozen"
    },
    {
      "x": -2,
      "y": 20,
      "z": -4,
      "name": "Rock_Shale"
    },
    {
      "x": -2,
      "y": 21,
      "z": -4,
      "name": "Rock_Shale"
    },
    {
      "x": -2,
      "y": 22,
      "z": -4,
      "name": "Rock_Shale"
    },
    {
      "x": -2,
      "y": 23,
      "z": -4,
      "name": "Soil_Pebbles_Frozen"
    },
    {
      "x": -2,
      "y": 24,
      "z": -4,
      "name": "Rubble_Shale_Medium"
    },
    {
      "x": -2,
      "y": 16,
      "z": -3,
      "name": "Rock_Shale"
    },
    {
      "x": -2,
      "y": 17,
      "z": -3,
      "name": "Rock_Shale"
    },
    {
      "x": -2,
      "y": 18,
      "z": -3,
      "name": "Rock_Shale"
    },
    {
      "x": -2,
      "y": 19,
      "z": -3,
      "name": "Rock_Shale"
    },
    {
      "x": -2,
      "y": 20,
      "z": -3,
      "name": "Rock_Shale"
    },
    {
      "x": -2,
      "y": 21,
      "z": -3,
      "name": "Rock_Shale"
    },
    {
      "x": -2,
      "y": 22,
      "z": -3,
      "name": "Rock_Shale"
    },
    {
      "x": -2,
      "y": 23,
      "z": -3,
      "name": "Rock_Shale"
    },
    {
      "x": -2,
      "y": 24,
      "z": -3,
      "name": "Rock_Shale"
    },
    {
      "x": -2,
      "y": 25,
      "z": -3,
      "name": "Rock_Shale"
    },
    {
      "x": -2,
      "y": 26,
      "z": -3,
      "name": "Rock_Shale"
    },
    {
      "x": -2,
      "y": 27,
      "z": -3,
      "name": "Rock_Shale"
    },
    {
      "x": -2,
      "y": 28,
      "z": -3,
      "name": "Rock_Shale"
    },
    {
      "x": -2,
      "y": 29,
      "z": -3,
      "name": "Rock_Shale"
    },
    {
      "x": -2,
      "y": 30,
      "z": -3,
      "name": "Rock_Shale"
    },
    {
      "x": -2,
      "y": 31,
      "z": -3,
      "name": "Rock_Shale"
    },
    {
      "x": -2,
      "y": 12,
      "z": -2,
      "name": "Rock_Shale"
    },
    {
      "x": -2,
      "y": 13,
      "z": -2,
      "name": "Rock_Shale"
    },
    {
      "x": -2,
      "y": 14,
      "z": -2,
      "name": "Rock_Shale"
    },
    {
      "x": -2,
      "y": 15,
      "z": -2,
      "name": "Rock_Shale"
    },
    {
      "x": -2,
      "y": 16,
      "z": -2,
      "name": "Rock_Shale"
    },
    {
      "x": -2,
      "y": 17,
      "z": -2,
      "name": "Rock_Shale"
    },
    {
      "x": -2,
      "y": 18,
      "z": -2,
      "name": "Rock_Shale"
    },
    {
      "x": -2,
      "y": 19,
      "z": -2,
      "name": "Rock_Shale"
    },
    {
      "x": -2,
      "y": 20,
      "z": -2,
      "name": "Rock_Shale"
    },
    {
      "x": -2,
      "y": 21,
      "z": -2,
      "name": "Rock_Shale"
    },
    {
      "x": -2,
      "y": 22,
      "z": -2,
      "name": "Rock_Shale"
    },
    {
      "x": -2,
      "y": 23,
      "z": -2,
      "name": "Rock_Shale"
    },
    {
      "x": -2,
      "y": 24,
      "z": -2,
      "name": "Rock_Shale"
    },
    {
      "x": -2,
      "y": 25,
      "z": -2,
      "name": "Rock_Shale"
    },
    {
      "x": -2,
      "y": 26,
      "z": -2,
      "name": "Rock_Shale"
    },
    {
      "x": -2,
      "y": 27,
      "z": -2,
      "name": "Rock_Shale"
    },
    {
      "x": -2,
      "y": 28,
      "z": -2,
      "name": "Rock_Shale"
    },
    {
      "x": -2,
      "y": 29,
      "z": -2,
      "name": "Rock_Shale"
    },
    {
      "x": -2,
      "y": 30,
      "z": -2,
      "name": "Rock_Shale"
    },
    {
      "x": -2,
      "y": 31,
      "z": -2,
      "name": "Rock_Shale"
    },
    {
      "x": -2,
      "y": 32,
      "z": -2,
      "name": "Rock_Shale"
    },
    {
      "x": -2,
      "y": 10,
      "z": -1,
      "name": "Rock_Shale"
    },
    {
      "x": -2,
      "y": 11,
      "z": -1,
      "name": "Rock_Shale"
    },
    {
      "x": -2,
      "y": 12,
      "z": -1,
      "name": "Rock_Shale"
    },
    {
      "x": -2,
      "y": 13,
      "z": -1,
      "name": "Rock_Shale"
    },
    {
      "x": -2,
      "y": 14,
      "z": -1,
      "name": "Rock_Shale"
    },
    {
      "x": -2,
      "y": 15,
      "z": -1,
      "name": "Rock_Shale"
    },
    {
      "x": -2,
      "y": 16,
      "z": -1,
      "name": "Rock_Shale"
    },
    {
      "x": -2,
      "y": 17,
      "z": -1,
      "name": "Rock_Shale"
    },
    {
      "x": -2,
      "y": 18,
      "z": -1,
      "name": "Rock_Shale"
    },
    {
      "x": -2,
      "y": 19,
      "z": -1,
      "name": "Rock_Shale"
    },
    {
      "x": -2,
      "y": 20,
      "z": -1,
      "name": "Rock_Shale"
    },
    {
      "x": -2,
      "y": 21,
      "z": -1,
      "name": "Rock_Shale"
    },
    {
      "x": -2,
      "y": 22,
      "z": -1,
      "name": "Rock_Shale"
    },
    {
      "x": -2,
      "y": 23,
      "z": -1,
      "name": "Rock_Shale"
    },
    {
      "x": -2,
      "y": 24,
      "z": -1,
      "name": "Rock_Shale"
    },
    {
      "x": -2,
      "y": 25,
      "z": -1,
      "name": "Rock_Shale"
    },
    {
      "x": -2,
      "y": 26,
      "z": -1,
      "name": "Rock_Shale"
    },
    {
      "x": -2,
      "y": 27,
      "z": -1,
      "name": "Rock_Shale"
    },
    {
      "x": -2,
      "y": 28,
      "z": -1,
      "name": "Rock_Shale"
    },
    {
      "x": -2,
      "y": 29,
      "z": -1,
      "name": "Rock_Shale"
    },
    {
      "x": -2,
      "y": 30,
      "z": -1,
      "name": "Rock_Shale"
    },
    {
      "x": -2,
      "y": 31,
      "z": -1,
      "name": "Rock_Shale"
    },
    {
      "x": -2,
      "y": 32,
      "z": -1,
      "name": "Rock_Shale"
    },
    {
      "x": -2,
      "y": 9,
      "z": 0,
      "name": "Rock_Shale"
    },
    {
      "x": -2,
      "y": 10,
      "z": 0,
      "name": "Rock_Shale"
    },
    {
      "x": -2,
      "y": 11,
      "z": 0,
      "name": "Rock_Shale"
    },
    {
      "x": -2,
      "y": 12,
      "z": 0,
      "name": "Rock_Shale"
    },
    {
      "x": -2,
      "y": 13,
      "z": 0,
      "name": "Rock_Shale"
    },
    {
      "x": -2,
      "y": 14,
      "z": 0,
      "name": "Rock_Shale"
    },
    {
      "x": -2,
      "y": 15,
      "z": 0,
      "name": "Rock_Shale"
    },
    {
      "x": -2,
      "y": 16,
      "z": 0,
      "name": "Rock_Shale"
    },
    {
      "x": -2,
      "y": 17,
      "z": 0,
      "name": "Rock_Shale"
    },
    {
      "x": -2,
      "y": 18,
      "z": 0,
      "name": "Rock_Shale"
    },
    {
      "x": -2,
      "y": 19,
      "z": 0,
      "name": "Rock_Shale"
    },
    {
      "x": -2,
      "y": 20,
      "z": 0,
      "name": "Rock_Shale"
    },
    {
      "x": -2,
      "y": 21,
      "z": 0,
      "name": "Rock_Shale"
    },
    {
      "x": -2,
      "y": 22,
      "z": 0,
      "name": "Rock_Shale"
    },
    {
      "x": -2,
      "y": 23,
      "z": 0,
      "name": "Rock_Shale"
    },
    {
      "x": -2,
      "y": 24,
      "z": 0,
      "name": "Rock_Shale"
    },
    {
      "x": -2,
      "y": 25,
      "z": 0,
      "name": "Rock_Shale"
    },
    {
      "x": -2,
      "y": 26,
      "z": 0,
      "name": "Rock_Shale"
    },
    {
      "x": -2,
      "y": 27,
      "z": 0,
      "name": "Rock_Shale"
    },
    {
      "x": -2,
      "y": 28,
      "z": 0,
      "name": "Rock_Shale"
    },
    {
      "x": -2,
      "y": 29,
      "z": 0,
      "name": "Rock_Shale"
    },
    {
      "x": -2,
      "y": 30,
      "z": 0,
      "name": "Rock_Shale"
    },
    {
      "x": -2,
      "y": 31,
      "z": 0,
      "name": "Rock_Shale"
    },
    {
      "x": -2,
      "y": 32,
      "z": 0,
      "name": "Rock_Shale"
    },
    {
      "x": -2,
      "y": 33,
      "z": 0,
      "name": "Rubble_Shale"
    },
    {
      "x": -2,
      "y": 10,
      "z": 1,
      "name": "Rock_Shale"
    },
    {
      "x": -2,
      "y": 11,
      "z": 1,
      "name": "Rock_Shale"
    },
    {
      "x": -2,
      "y": 12,
      "z": 1,
      "name": "Rock_Shale"
    },
    {
      "x": -2,
      "y": 13,
      "z": 1,
      "name": "Rock_Shale"
    },
    {
      "x": -2,
      "y": 14,
      "z": 1,
      "name": "Rock_Shale"
    },
    {
      "x": -2,
      "y": 15,
      "z": 1,
      "name": "Rock_Shale"
    },
    {
      "x": -2,
      "y": 16,
      "z": 1,
      "name": "Rock_Shale"
    },
    {
      "x": -2,
      "y": 17,
      "z": 1,
      "name": "Rock_Shale"
    },
    {
      "x": -2,
      "y": 18,
      "z": 1,
      "name": "Rock_Shale"
    },
    {
      "x": -2,
      "y": 19,
      "z": 1,
      "name": "Rock_Shale"
    },
    {
      "x": -2,
      "y": 20,
      "z": 1,
      "name": "Rock_Shale"
    },
    {
      "x": -2,
      "y": 21,
      "z": 1,
      "name": "Rock_Shale"
    },
    {
      "x": -2,
      "y": 22,
      "z": 1,
      "name": "Rock_Shale"
    },
    {
      "x": -2,
      "y": 23,
      "z": 1,
      "name": "Rock_Shale"
    },
    {
      "x": -2,
      "y": 24,
      "z": 1,
      "name": "Rock_Shale"
    },
    {
      "x": -2,
      "y": 25,
      "z": 1,
      "name": "Rock_Shale"
    },
    {
      "x": -2,
      "y": 26,
      "z": 1,
      "name": "Rock_Shale"
    },
    {
      "x": -2,
      "y": 27,
      "z": 1,
      "name": "Rock_Shale"
    },
    {
      "x": -2,
      "y": 28,
      "z": 1,
      "name": "Soil_Pebbles_Frozen"
    },
    {
      "x": -2,
      "y": 12,
      "z": 2,
      "name": "Rock_Shale"
    },
    {
      "x": -2,
      "y": 13,
      "z": 2,
      "name": "Rock_Shale"
    },
    {
      "x": -2,
      "y": 14,
      "z": 2,
      "name": "Rock_Shale"
    },
    {
      "x": -2,
      "y": 15,
      "z": 2,
      "name": "Rock_Shale"
    },
    {
      "x": -2,
      "y": 16,
      "z": 2,
      "name": "Rock_Shale"
    },
    {
      "x": -2,
      "y": 17,
      "z": 2,
      "name": "Rock_Shale"
    },
    {
      "x": -2,
      "y": 18,
      "z": 2,
      "name": "Rock_Shale"
    },
    {
      "x": -2,
      "y": 19,
      "z": 2,
      "name": "Rock_Shale"
    },
    {
      "x": -2,
      "y": 20,
      "z": 2,
      "name": "Rock_Shale"
    },
    {
      "x": -2,
      "y": 21,
      "z": 2,
      "name": "Rock_Shale"
    },
    {
      "x": -2,
      "y": 22,
      "z": 2,
      "name": "Rock_Shale"
    },
    {
      "x": -2,
      "y": 23,
      "z": 2,
      "name": "Rock_Shale"
    },
    {
      "x": -2,
      "y": 24,
      "z": 2,
      "name": "Rock_Shale"
    },
    {
      "x": -2,
      "y": 25,
      "z": 2,
      "name": "Rock_Shale"
    },
    {
      "x": -2,
      "y": 26,
      "z": 2,
      "name": "Rock_Shale"
    },
    {
      "x": -2,
      "y": 27,
      "z": 2,
      "name": "Rock_Shale"
    },
    {
      "x": -2,
      "y": 28,
      "z": 2,
      "name": "Soil_Pebbles_Frozen"
    },
    {
      "x": -2,
      "y": 29,
      "z": 2,
      "name": "Rubble_Shale"
    },
    {
      "x": -2,
      "y": 17,
      "z": 3,
      "name": "Rock_Shale"
    },
    {
      "x": -2,
      "y": 18,
      "z": 3,
      "name": "Rock_Shale"
    },
    {
      "x": -2,
      "y": 19,
      "z": 3,
      "name": "Rock_Shale"
    },
    {
      "x": -2,
      "y": 20,
      "z": 3,
      "name": "Rock_Shale"
    },
    {
      "x": -2,
      "y": 21,
      "z": 3,
      "name": "Rock_Shale"
    },
    {
      "x": -2,
      "y": 22,
      "z": 3,
      "name": "Rock_Shale"
    },
    {
      "x": -2,
      "y": 26,
      "z": 3,
      "name": "Soil_Pebbles_Frozen"
    },
    {
      "x": -1,
      "y": 19,
      "z": -5,
      "name": "Rock_Shale"
    },
    {
      "x": -1,
      "y": 20,
      "z": -5,
      "name": "Rock_Shale"
    },
    {
      "x": -1,
      "y": 21,
      "z": -5,
      "name": "Rock_Shale"
    },
    {
      "x": -1,
      "y": 22,
      "z": -5,
      "name": "Rock_Shale"
    },
    {
      "x": -1,
      "y": 23,
      "z": -5,
      "name": "Rock_Shale"
    },
    {
      "x": -1,
      "y": 24,
      "z": -5,
      "name": "Rock_Shale"
    },
    {
      "x": -1,
      "y": 25,
      "z": -5,
      "name": "Soil_Pebbles_Frozen"
    },
    {
      "x": -1,
      "y": 16,
      "z": -4,
      "name": "Rock_Shale"
    },
    {
      "x": -1,
      "y": 17,
      "z": -4,
      "name": "Rock_Shale"
    },
    {
      "x": -1,
      "y": 18,
      "z": -4,
      "name": "Rock_Shale"
    },
    {
      "x": -1,
      "y": 19,
      "z": -4,
      "name": "Rock_Shale"
    },
    {
      "x": -1,
      "y": 20,
      "z": -4,
      "name": "Rock_Shale"
    },
    {
      "x": -1,
      "y": 21,
      "z": -4,
      "name": "Rock_Shale"
    },
    {
      "x": -1,
      "y": 22,
      "z": -4,
      "name": "Rock_Shale"
    },
    {
      "x": -1,
      "y": 23,
      "z": -4,
      "name": "Rock_Shale"
    },
    {
      "x": -1,
      "y": 24,
      "z": -4,
      "name": "Rock_Shale"
    },
    {
      "x": -1,
      "y": 25,
      "z": -4,
      "name": "Rock_Shale"
    },
    {
      "x": -1,
      "y": 26,
      "z": -4,
      "name": "Soil_Pebbles_Frozen"
    },
    {
      "x": -1,
      "y": 14,
      "z": -3,
      "name": "Rock_Shale"
    },
    {
      "x": -1,
      "y": 15,
      "z": -3,
      "name": "Rock_Shale"
    },
    {
      "x": -1,
      "y": 16,
      "z": -3,
      "name": "Rock_Shale"
    },
    {
      "x": -1,
      "y": 17,
      "z": -3,
      "name": "Rock_Shale"
    },
    {
      "x": -1,
      "y": 18,
      "z": -3,
      "name": "Rock_Shale"
    },
    {
      "x": -1,
      "y": 19,
      "z": -3,
      "name": "Rock_Shale"
    },
    {
      "x": -1,
      "y": 20,
      "z": -3,
      "name": "Rock_Shale"
    },
    {
      "x": -1,
      "y": 21,
      "z": -3,
      "name": "Rock_Shale"
    },
    {
      "x": -1,
      "y": 22,
      "z": -3,
      "name": "Rock_Shale"
    },
    {
      "x": -1,
      "y": 23,
      "z": -3,
      "name": "Rock_Shale"
    },
    {
      "x": -1,
      "y": 24,
      "z": -3,
      "name": "Rock_Shale"
    },
    {
      "x": -1,
      "y": 25,
      "z": -3,
      "name": "Rock_Shale"
    },
    {
      "x": -1,
      "y": 26,
      "z": -3,
      "name": "Rock_Shale"
    },
    {
      "x": -1,
      "y": 27,
      "z": -3,
      "name": "Rock_Shale"
    },
    {
      "x": -1,
      "y": 28,
      "z": -3,
      "name": "Rock_Shale"
    },
    {
      "x": -1,
      "y": 29,
      "z": -3,
      "name": "Rock_Shale"
    },
    {
      "x": -1,
      "y": 30,
      "z": -3,
      "name": "Rock_Shale"
    },
    {
      "x": -1,
      "y": 31,
      "z": -3,
      "name": "Rock_Shale"
    },
    {
      "x": -1,
      "y": 32,
      "z": -3,
      "name": "Rock_Shale"
    },
    {
      "x": -1,
      "y": 33,
      "z": -3,
      "name": "Rubble_Shale"
    },
    {
      "x": -1,
      "y": 10,
      "z": -2,
      "name": "Rock_Shale"
    },
    {
      "x": -1,
      "y": 11,
      "z": -2,
      "name": "Rock_Shale"
    },
    {
      "x": -1,
      "y": 12,
      "z": -2,
      "name": "Rock_Shale"
    },
    {
      "x": -1,
      "y": 13,
      "z": -2,
      "name": "Rock_Shale"
    },
    {
      "x": -1,
      "y": 14,
      "z": -2,
      "name": "Rock_Shale"
    },
    {
      "x": -1,
      "y": 15,
      "z": -2,
      "name": "Rock_Shale"
    },
    {
      "x": -1,
      "y": 16,
      "z": -2,
      "name": "Rock_Shale"
    },
    {
      "x": -1,
      "y": 17,
      "z": -2,
      "name": "Rock_Shale"
    },
    {
      "x": -1,
      "y": 18,
      "z": -2,
      "name": "Rock_Shale"
    },
    {
      "x": -1,
      "y": 19,
      "z": -2,
      "name": "Rock_Shale"
    },
    {
      "x": -1,
      "y": 20,
      "z": -2,
      "name": "Rock_Shale"
    },
    {
      "x": -1,
      "y": 21,
      "z": -2,
      "name": "Rock_Shale"
    },
    {
      "x": -1,
      "y": 22,
      "z": -2,
      "name": "Rock_Shale"
    },
    {
      "x": -1,
      "y": 23,
      "z": -2,
      "name": "Rock_Shale"
    },
    {
      "x": -1,
      "y": 24,
      "z": -2,
      "name": "Rock_Shale"
    },
    {
      "x": -1,
      "y": 25,
      "z": -2,
      "name": "Rock_Shale"
    },
    {
      "x": -1,
      "y": 26,
      "z": -2,
      "name": "Rock_Shale"
    },
    {
      "x": -1,
      "y": 27,
      "z": -2,
      "name": "Rock_Shale"
    },
    {
      "x": -1,
      "y": 28,
      "z": -2,
      "name": "Rock_Shale"
    },
    {
      "x": -1,
      "y": 29,
      "z": -2,
      "name": "Rock_Shale"
    },
    {
      "x": -1,
      "y": 30,
      "z": -2,
      "name": "Rock_Shale"
    },
    {
      "x": -1,
      "y": 31,
      "z": -2,
      "name": "Rock_Shale"
    },
    {
      "x": -1,
      "y": 32,
      "z": -2,
      "name": "Rock_Shale"
    },
    {
      "x": -1,
      "y": 8,
      "z": -1,
      "name": "Rock_Shale"
    },
    {
      "x": -1,
      "y": 9,
      "z": -1,
      "name": "Rock_Shale"
    },
    {
      "x": -1,
      "y": 10,
      "z": -1,
      "name": "Rock_Shale"
    },
    {
      "x": -1,
      "y": 11,
      "z": -1,
      "name": "Rock_Shale"
    },
    {
      "x": -1,
      "y": 12,
      "z": -1,
      "name": "Rock_Shale"
    },
    {
      "x": -1,
      "y": 13,
      "z": -1,
      "name": "Rock_Shale"
    },
    {
      "x": -1,
      "y": 14,
      "z": -1,
      "name": "Rock_Shale"
    },
    {
      "x": -1,
      "y": 15,
      "z": -1,
      "name": "Rock_Shale"
    },
    {
      "x": -1,
      "y": 16,
      "z": -1,
      "name": "Rock_Shale"
    },
    {
      "x": -1,
      "y": 17,
      "z": -1,
      "name": "Rock_Shale"
    },
    {
      "x": -1,
      "y": 18,
      "z": -1,
      "name": "Rock_Shale"
    },
    {
      "x": -1,
      "y": 19,
      "z": -1,
      "name": "Rock_Shale"
    },
    {
      "x": -1,
      "y": 20,
      "z": -1,
      "name": "Rock_Shale"
    },
    {
      "x": -1,
      "y": 21,
      "z": -1,
      "name": "Rock_Shale"
    },
    {
      "x": -1,
      "y": 22,
      "z": -1,
      "name": "Rock_Shale"
    },
    {
      "x": -1,
      "y": 23,
      "z": -1,
      "name": "Rock_Shale"
    },
    {
      "x": -1,
      "y": 24,
      "z": -1,
      "name": "Rock_Shale"
    },
    {
      "x": -1,
      "y": 25,
      "z": -1,
      "name": "Rock_Shale"
    },
    {
      "x": -1,
      "y": 26,
      "z": -1,
      "name": "Rock_Shale"
    },
    {
      "x": -1,
      "y": 27,
      "z": -1,
      "name": "Rock_Shale"
    },
    {
      "x": -1,
      "y": 28,
      "z": -1,
      "name": "Rock_Shale"
    },
    {
      "x": -1,
      "y": 29,
      "z": -1,
      "name": "Rock_Shale"
    },
    {
      "x": -1,
      "y": 30,
      "z": -1,
      "name": "Rock_Shale"
    },
    {
      "x": -1,
      "y": 31,
      "z": -1,
      "name": "Rock_Shale"
    },
    {
      "x": -1,
      "y": 32,
      "z": -1,
      "name": "Rock_Shale"
    },
    {
      "x": -1,
      "y": 33,
      "z": -1,
      "name": "Rock_Shale"
    },
    {
      "x": -1,
      "y": 8,
      "z": 0,
      "name": "Rock_Shale"
    },
    {
      "x": -1,
      "y": 9,
      "z": 0,
      "name": "Rock_Shale"
    },
    {
      "x": -1,
      "y": 10,
      "z": 0,
      "name": "Rock_Shale"
    },
    {
      "x": -1,
      "y": 11,
      "z": 0,
      "name": "Rock_Shale"
    },
    {
      "x": -1,
      "y": 12,
      "z": 0,
      "name": "Rock_Shale"
    },
    {
      "x": -1,
      "y": 13,
      "z": 0,
      "name": "Rock_Shale"
    },
    {
      "x": -1,
      "y": 14,
      "z": 0,
      "name": "Rock_Shale"
    },
    {
      "x": -1,
      "y": 15,
      "z": 0,
      "name": "Rock_Shale"
    },
    {
      "x": -1,
      "y": 16,
      "z": 0,
      "name": "Rock_Shale"
    },
    {
      "x": -1,
      "y": 17,
      "z": 0,
      "name": "Rock_Shale"
    },
    {
      "x": -1,
      "y": 18,
      "z": 0,
      "name": "Rock_Shale"
    },
    {
      "x": -1,
      "y": 19,
      "z": 0,
      "name": "Rock_Shale"
    },
    {
      "x": -1,
      "y": 20,
      "z": 0,
      "name": "Rock_Shale"
    },
    {
      "x": -1,
      "y": 21,
      "z": 0,
      "name": "Rock_Shale"
    },
    {
      "x": -1,
      "y": 22,
      "z": 0,
      "name": "Rock_Shale"
    },
    {
      "x": -1,
      "y": 23,
      "z": 0,
      "name": "Rock_Shale"
    },
    {
      "x": -1,
      "y": 24,
      "z": 0,
      "name": "Rock_Shale"
    },
    {
      "x": -1,
      "y": 25,
      "z": 0,
      "name": "Rock_Shale"
    },
    {
      "x": -1,
      "y": 26,
      "z": 0,
      "name": "Rock_Shale"
    },
    {
      "x": -1,
      "y": 27,
      "z": 0,
      "name": "Rock_Shale"
    },
    {
      "x": -1,
      "y": 28,
      "z": 0,
      "name": "Rock_Shale"
    },
    {
      "x": -1,
      "y": 29,
      "z": 0,
      "name": "Rock_Shale"
    },
    {
      "x": -1,
      "y": 30,
      "z": 0,
      "name": "Rock_Shale"
    },
    {
      "x": -1,
      "y": 31,
      "z": 0,
      "name": "Rock_Shale"
    },
    {
      "x": -1,
      "y": 32,
      "z": 0,
      "name": "Rock_Shale"
    },
    {
      "x": -1,
      "y": 33,
      "z": 0,
      "name": "Rock_Shale"
    },
    {
      "x": -1,
      "y": 8,
      "z": 1,
      "name": "Rock_Shale"
    },
    {
      "x": -1,
      "y": 9,
      "z": 1,
      "name": "Rock_Shale"
    },
    {
      "x": -1,
      "y": 10,
      "z": 1,
      "name": "Rock_Shale"
    },
    {
      "x": -1,
      "y": 11,
      "z": 1,
      "name": "Rock_Shale"
    },
    {
      "x": -1,
      "y": 12,
      "z": 1,
      "name": "Rock_Shale"
    },
    {
      "x": -1,
      "y": 13,
      "z": 1,
      "name": "Rock_Shale"
    },
    {
      "x": -1,
      "y": 14,
      "z": 1,
      "name": "Rock_Shale"
    },
    {
      "x": -1,
      "y": 15,
      "z": 1,
      "name": "Rock_Shale"
    },
    {
      "x": -1,
      "y": 16,
      "z": 1,
      "name": "Rock_Shale"
    },
    {
      "x": -1,
      "y": 17,
      "z": 1,
      "name": "Rock_Shale"
    },
    {
      "x": -1,
      "y": 18,
      "z": 1,
      "name": "Rock_Shale"
    },
    {
      "x": -1,
      "y": 19,
      "z": 1,
      "name": "Rock_Shale"
    },
    {
      "x": -1,
      "y": 20,
      "z": 1,
      "name": "Rock_Shale"
    },
    {
      "x": -1,
      "y": 21,
      "z": 1,
      "name": "Rock_Shale"
    },
    {
      "x": -1,
      "y": 22,
      "z": 1,
      "name": "Rock_Shale"
    },
    {
      "x": -1,
      "y": 23,
      "z": 1,
      "name": "Rock_Shale"
    },
    {
      "x": -1,
      "y": 24,
      "z": 1,
      "name": "Rock_Shale"
    },
    {
      "x": -1,
      "y": 25,
      "z": 1,
      "name": "Rock_Shale"
    },
    {
      "x": -1,
      "y": 26,
      "z": 1,
      "name": "Rock_Shale"
    },
    {
      "x": -1,
      "y": 27,
      "z": 1,
      "name": "Rock_Shale"
    },
    {
      "x": -1,
      "y": 28,
      "z": 1,
      "name": "Rock_Shale"
    },
    {
      "x": -1,
      "y": 29,
      "z": 1,
      "name": "Rock_Shale"
    },
    {
      "x": -1,
      "y": 30,
      "z": 1,
      "name": "Rock_Shale"
    },
    {
      "x": -1,
      "y": 31,
      "z": 1,
      "name": "Rock_Shale"
    },
    {
      "x": -1,
      "y": 32,
      "z": 1,
      "name": "Rock_Shale"
    },
    {
      "x": -1,
      "y": 10,
      "z": 2,
      "name": "Rock_Shale"
    },
    {
      "x": -1,
      "y": 11,
      "z": 2,
      "name": "Rock_Shale"
    },
    {
      "x": -1,
      "y": 12,
      "z": 2,
      "name": "Rock_Shale"
    },
    {
      "x": -1,
      "y": 13,
      "z": 2,
      "name": "Rock_Shale"
    },
    {
      "x": -1,
      "y": 14,
      "z": 2,
      "name": "Rock_Shale"
    },
    {
      "x": -1,
      "y": 15,
      "z": 2,
      "name": "Rock_Shale"
    },
    {
      "x": -1,
      "y": 16,
      "z": 2,
      "name": "Rock_Shale"
    },
    {
      "x": -1,
      "y": 17,
      "z": 2,
      "name": "Rock_Shale"
    },
    {
      "x": -1,
      "y": 18,
      "z": 2,
      "name": "Rock_Shale"
    },
    {
      "x": -1,
      "y": 19,
      "z": 2,
      "name": "Rock_Shale"
    },
    {
      "x": -1,
      "y": 20,
      "z": 2,
      "name": "Rock_Shale"
    },
    {
      "x": -1,
      "y": 21,
      "z": 2,
      "name": "Rock_Shale"
    },
    {
      "x": -1,
      "y": 22,
      "z": 2,
      "name": "Rock_Shale"
    },
    {
      "x": -1,
      "y": 23,
      "z": 2,
      "name": "Rock_Shale"
    },
    {
      "x": -1,
      "y": 24,
      "z": 2,
      "name": "Rock_Shale"
    },
    {
      "x": -1,
      "y": 25,
      "z": 2,
      "name": "Rock_Shale"
    },
    {
      "x": -1,
      "y": 26,
      "z": 2,
      "name": "Rock_Shale"
    },
    {
      "x": -1,
      "y": 27,
      "z": 2,
      "name": "Rock_Shale"
    },
    {
      "x": -1,
      "y": 28,
      "z": 2,
      "name": "Soil_Pebbles_Frozen"
    },
    {
      "x": -1,
      "y": 14,
      "z": 3,
      "name": "Rock_Shale"
    },
    {
      "x": -1,
      "y": 15,
      "z": 3,
      "name": "Rock_Shale"
    },
    {
      "x": -1,
      "y": 16,
      "z": 3,
      "name": "Rock_Shale"
    },
    {
      "x": -1,
      "y": 17,
      "z": 3,
      "name": "Rock_Shale"
    },
    {
      "x": -1,
      "y": 18,
      "z": 3,
      "name": "Rock_Shale"
    },
    {
      "x": -1,
      "y": 19,
      "z": 3,
      "name": "Rock_Shale"
    },
    {
      "x": -1,
      "y": 20,
      "z": 3,
      "name": "Rock_Shale"
    },
    {
      "x": -1,
      "y": 21,
      "z": 3,
      "name": "Rock_Shale"
    },
    {
      "x": -1,
      "y": 22,
      "z": 3,
      "name": "Rock_Shale"
    },
    {
      "x": -1,
      "y": 25,
      "z": 3,
      "name": "Rock_Shale"
    },
    {
      "x": -1,
      "y": 26,
      "z": 3,
      "name": "Soil_Pebbles_Frozen"
    },
    {
      "x": -1,
      "y": 19,
      "z": 4,
      "name": "Rock_Shale"
    },
    {
      "x": -1,
      "y": 20,
      "z": 4,
      "name": "Rock_Shale"
    },
    {
      "x": -1,
      "y": 21,
      "z": 4,
      "name": "Rock_Shale"
    },
    {
      "x": 0,
      "y": 17,
      "z": -5,
      "name": "Rock_Shale"
    },
    {
      "x": 0,
      "y": 18,
      "z": -5,
      "name": "Rock_Shale"
    },
    {
      "x": 0,
      "y": 19,
      "z": -5,
      "name": "Rock_Shale"
    },
    {
      "x": 0,
      "y": 20,
      "z": -5,
      "name": "Rock_Shale"
    },
    {
      "x": 0,
      "y": 21,
      "z": -5,
      "name": "Rock_Shale"
    },
    {
      "x": 0,
      "y": 22,
      "z": -5,
      "name": "Rock_Shale"
    },
    {
      "x": 0,
      "y": 23,
      "z": -5,
      "name": "Rock_Shale"
    },
    {
      "x": 0,
      "y": 24,
      "z": -5,
      "name": "Rock_Shale"
    },
    {
      "x": 0,
      "y": 25,
      "z": -5,
      "name": "Soil_Pebbles_Frozen"
    },
    {
      "x": 0,
      "y": 16,
      "z": -4,
      "name": "Rock_Shale"
    },
    {
      "x": 0,
      "y": 17,
      "z": -4,
      "name": "Rock_Shale"
    },
    {
      "x": 0,
      "y": 18,
      "z": -4,
      "name": "Rock_Shale"
    },
    {
      "x": 0,
      "y": 19,
      "z": -4,
      "name": "Rock_Shale"
    },
    {
      "x": 0,
      "y": 20,
      "z": -4,
      "name": "Rock_Shale"
    },
    {
      "x": 0,
      "y": 21,
      "z": -4,
      "name": "Rock_Shale"
    },
    {
      "x": 0,
      "y": 22,
      "z": -4,
      "name": "Rock_Shale"
    },
    {
      "x": 0,
      "y": 23,
      "z": -4,
      "name": "Rock_Shale"
    },
    {
      "x": 0,
      "y": 24,
      "z": -4,
      "name": "Rock_Shale"
    },
    {
      "x": 0,
      "y": 25,
      "z": -4,
      "name": "Rock_Shale"
    },
    {
      "x": 0,
      "y": 26,
      "z": -4,
      "name": "Soil_Pebbles_Frozen"
    },
    {
      "x": 0,
      "y": 27,
      "z": -4,
      "name": "Rubble_Shale"
    },
    {
      "x": 0,
      "y": 13,
      "z": -3,
      "name": "Rock_Shale"
    },
    {
      "x": 0,
      "y": 14,
      "z": -3,
      "name": "Rock_Shale"
    },
    {
      "x": 0,
      "y": 15,
      "z": -3,
      "name": "Rock_Shale"
    },
    {
      "x": 0,
      "y": 16,
      "z": -3,
      "name": "Rock_Shale"
    },
    {
      "x": 0,
      "y": 17,
      "z": -3,
      "name": "Rock_Shale"
    },
    {
      "x": 0,
      "y": 18,
      "z": -3,
      "name": "Rock_Shale"
    },
    {
      "x": 0,
      "y": 19,
      "z": -3,
      "name": "Rock_Shale"
    },
    {
      "x": 0,
      "y": 20,
      "z": -3,
      "name": "Rock_Shale"
    },
    {
      "x": 0,
      "y": 21,
      "z": -3,
      "name": "Rock_Shale"
    },
    {
      "x": 0,
      "y": 22,
      "z": -3,
      "name": "Rock_Shale"
    },
    {
      "x": 0,
      "y": 23,
      "z": -3,
      "name": "Rock_Shale"
    },
    {
      "x": 0,
      "y": 24,
      "z": -3,
      "name": "Rock_Shale"
    },
    {
      "x": 0,
      "y": 25,
      "z": -3,
      "name": "Rock_Shale"
    },
    {
      "x": 0,
      "y": 26,
      "z": -3,
      "name": "Rock_Shale"
    },
    {
      "x": 0,
      "y": 27,
      "z": -3,
      "name": "Rock_Shale"
    },
    {
      "x": 0,
      "y": 28,
      "z": -3,
      "name": "Rock_Shale"
    },
    {
      "x": 0,
      "y": 29,
      "z": -3,
      "name": "Rock_Shale"
    },
    {
      "x": 0,
      "y": 30,
      "z": -3,
      "name": "Rock_Shale"
    },
    {
      "x": 0,
      "y": 31,
      "z": -3,
      "name": "Rock_Shale"
    },
    {
      "x": 0,
      "y": 32,
      "z": -3,
      "name": "Rock_Shale"
    },
    {
      "x": 0,
      "y": 33,
      "z": -3,
      "name": "Rock_Shale"
    },
    {
      "x": 0,
      "y": 10,
      "z": -2,
      "name": "Rock_Shale"
    },
    {
      "x": 0,
      "y": 11,
      "z": -2,
      "name": "Rock_Shale"
    },
    {
      "x": 0,
      "y": 12,
      "z": -2,
      "name": "Rock_Shale"
    },
    {
      "x": 0,
      "y": 13,
      "z": -2,
      "name": "Rock_Shale"
    },
    {
      "x": 0,
      "y": 14,
      "z": -2,
      "name": "Rock_Shale"
    },
    {
      "x": 0,
      "y": 15,
      "z": -2,
      "name": "Rock_Shale"
    },
    {
      "x": 0,
      "y": 16,
      "z": -2,
      "name": "Rock_Shale"
    },
    {
      "x": 0,
      "y": 17,
      "z": -2,
      "name": "Rock_Shale"
    },
    {
      "x": 0,
      "y": 18,
      "z": -2,
      "name": "Rock_Shale"
    },
    {
      "x": 0,
      "y": 19,
      "z": -2,
      "name": "Rock_Shale"
    },
    {
      "x": 0,
      "y": 20,
      "z": -2,
      "name": "Rock_Shale"
    },
    {
      "x": 0,
      "y": 21,
      "z": -2,
      "name": "Rock_Shale"
    },
    {
      "x": 0,
      "y": 22,
      "z": -2,
      "name": "Rock_Shale"
    },
    {
      "x": 0,
      "y": 23,
      "z": -2,
      "name": "Rock_Shale"
    },
    {
      "x": 0,
      "y": 24,
      "z": -2,
      "name": "Rock_Shale"
    },
    {
      "x": 0,
      "y": 25,
      "z": -2,
      "name": "Rock_Shale"
    },
    {
      "x": 0,
      "y": 26,
      "z": -2,
      "name": "Rock_Shale"
    },
    {
      "x": 0,
      "y": 27,
      "z": -2,
      "name": "Rock_Shale"
    },
    {
      "x": 0,
      "y": 28,
      "z": -2,
      "name": "Rock_Shale"
    },
    {
      "x": 0,
      "y": 29,
      "z": -2,
      "name": "Rock_Shale"
    },
    {
      "x": 0,
      "y": 30,
      "z": -2,
      "name": "Rock_Shale"
    },
    {
      "x": 0,
      "y": 31,
      "z": -2,
      "name": "Rock_Shale"
    },
    {
      "x": 0,
      "y": 32,
      "z": -2,
      "name": "Rock_Shale"
    },
    {
      "x": 0,
      "y": 33,
      "z": -2,
      "name": "Rock_Shale"
    },
    {
      "x": 0,
      "y": 8,
      "z": -1,
      "name": "Rock_Shale"
    },
    {
      "x": 0,
      "y": 9,
      "z": -1,
      "name": "Rock_Shale"
    },
    {
      "x": 0,
      "y": 10,
      "z": -1,
      "name": "Rock_Shale"
    },
    {
      "x": 0,
      "y": 11,
      "z": -1,
      "name": "Rock_Shale"
    },
    {
      "x": 0,
      "y": 12,
      "z": -1,
      "name": "Rock_Shale"
    },
    {
      "x": 0,
      "y": 13,
      "z": -1,
      "name": "Rock_Shale"
    },
    {
      "x": 0,
      "y": 14,
      "z": -1,
      "name": "Rock_Shale"
    },
    {
      "x": 0,
      "y": 15,
      "z": -1,
      "name": "Rock_Shale"
    },
    {
      "x": 0,
      "y": 16,
      "z": -1,
      "name": "Rock_Shale"
    },
    {
      "x": 0,
      "y": 17,
      "z": -1,
      "name": "Rock_Shale"
    },
    {
      "x": 0,
      "y": 18,
      "z": -1,
      "name": "Rock_Shale"
    },
    {
      "x": 0,
      "y": 19,
      "z": -1,
      "name": "Rock_Shale"
    },
    {
      "x": 0,
      "y": 20,
      "z": -1,
      "name": "Rock_Shale"
    },
    {
      "x": 0,
      "y": 21,
      "z": -1,
      "name": "Rock_Shale"
    },
    {
      "x": 0,
      "y": 22,
      "z": -1,
      "name": "Rock_Shale"
    },
    {
      "x": 0,
      "y": 23,
      "z": -1,
      "name": "Rock_Shale"
    },
    {
      "x": 0,
      "y": 24,
      "z": -1,
      "name": "Rock_Shale"
    },
    {
      "x": 0,
      "y": 25,
      "z": -1,
      "name": "Rock_Shale"
    },
    {
      "x": 0,
      "y": 26,
      "z": -1,
      "name": "Rock_Shale"
    },
    {
      "x": 0,
      "y": 27,
      "z": -1,
      "name": "Rock_Shale"
    },
    {
      "x": 0,
      "y": 28,
      "z": -1,
      "name": "Rock_Shale"
    },
    {
      "x": 0,
      "y": 29,
      "z": -1,
      "name": "Rock_Shale"
    },
    {
      "x": 0,
      "y": 30,
      "z": -1,
      "name": "Rock_Shale"
    },
    {
      "x": 0,
      "y": 31,
      "z": -1,
      "name": "Rock_Shale"
    },
    {
      "x": 0,
      "y": 32,
      "z": -1,
      "name": "Rock_Shale"
    },
    {
      "x": 0,
      "y": 33,
      "z": -1,
      "name": "Rock_Shale"
    },
    {
      "x": 0,
      "y": 34,
      "z": -1,
      "name": "Rubble_Shale_Medium"
    },
    {
      "x": 0,
      "y": 8,
      "z": 0,
      "name": "Rock_Shale"
    },
    {
      "x": 0,
      "y": 9,
      "z": 0,
      "name": "Rock_Shale"
    },
    {
      "x": 0,
      "y": 10,
      "z": 0,
      "name": "Rock_Shale"
    },
    {
      "x": 0,
      "y": 11,
      "z": 0,
      "name": "Rock_Shale"
    },
    {
      "x": 0,
      "y": 12,
      "z": 0,
      "name": "Rock_Shale"
    },
    {
      "x": 0,
      "y": 13,
      "z": 0,
      "name": "Rock_Shale"
    },
    {
      "x": 0,
      "y": 14,
      "z": 0,
      "name": "Rock_Shale"
    },
    {
      "x": 0,
      "y": 15,
      "z": 0,
      "name": "Rock_Shale"
    },
    {
      "x": 0,
      "y": 16,
      "z": 0,
      "name": "Rock_Shale"
    },
    {
      "x": 0,
      "y": 17,
      "z": 0,
      "name": "Rock_Shale"
    },
    {
      "x": 0,
      "y": 18,
      "z": 0,
      "name": "Rock_Shale"
    },
    {
      "x": 0,
      "y": 19,
      "z": 0,
      "name": "Rock_Shale"
    },
    {
      "x": 0,
      "y": 20,
      "z": 0,
      "name": "Rock_Shale"
    },
    {
      "x": 0,
      "y": 21,
      "z": 0,
      "name": "Rock_Shale"
    },
    {
      "x": 0,
      "y": 22,
      "z": 0,
      "name": "Rock_Shale"
    },
    {
      "x": 0,
      "y": 23,
      "z": 0,
      "name": "Rock_Shale"
    },
    {
      "x": 0,
      "y": 24,
      "z": 0,
      "name": "Rock_Shale"
    },
    {
      "x": 0,
      "y": 25,
      "z": 0,
      "name": "Rock_Shale"
    },
    {
      "x": 0,
      "y": 26,
      "z": 0,
      "name": "Rock_Shale"
    },
    {
      "x": 0,
      "y": 27,
      "z": 0,
      "name": "Rock_Shale"
    },
    {
      "x": 0,
      "y": 28,
      "z": 0,
      "name": "Rock_Shale"
    },
    {
      "x": 0,
      "y": 29,
      "z": 0,
      "name": "Rock_Shale"
    },
    {
      "x": 0,
      "y": 30,
      "z": 0,
      "name": "Rock_Shale"
    },
    {
      "x": 0,
      "y": 31,
      "z": 0,
      "name": "Rock_Shale"
    },
    {
      "x": 0,
      "y": 32,
      "z": 0,
      "name": "Rock_Shale"
    },
    {
      "x": 0,
      "y": 33,
      "z": 0,
      "name": "Rock_Shale"
    },
    {
      "x": 0,
      "y": 34,
      "z": 0,
      "name": "Rock_Shale"
    },
    {
      "x": 0,
      "y": 35,
      "z": 0,
      "name": "Rock_Shale"
    },
    {
      "x": 0,
      "y": 36,
      "z": 0,
      "name": "Rock_Shale"
    },
    {
      "x": 0,
      "y": 8,
      "z": 1,
      "name": "Rock_Shale"
    },
    {
      "x": 0,
      "y": 9,
      "z": 1,
      "name": "Rock_Shale"
    },
    {
      "x": 0,
      "y": 10,
      "z": 1,
      "name": "Rock_Shale"
    },
    {
      "x": 0,
      "y": 11,
      "z": 1,
      "name": "Rock_Shale"
    },
    {
      "x": 0,
      "y": 12,
      "z": 1,
      "name": "Rock_Shale"
    },
    {
      "x": 0,
      "y": 13,
      "z": 1,
      "name": "Rock_Shale"
    },
    {
      "x": 0,
      "y": 14,
      "z": 1,
      "name": "Rock_Shale"
    },
    {
      "x": 0,
      "y": 15,
      "z": 1,
      "name": "Rock_Shale"
    },
    {
      "x": 0,
      "y": 16,
      "z": 1,
      "name": "Rock_Shale"
    },
    {
      "x": 0,
      "y": 17,
      "z": 1,
      "name": "Rock_Shale"
    },
    {
      "x": 0,
      "y": 18,
      "z": 1,
      "name": "Rock_Shale"
    },
    {
      "x": 0,
      "y": 19,
      "z": 1,
      "name": "Rock_Shale"
    },
    {
      "x": 0,
      "y": 20,
      "z": 1,
      "name": "Rock_Shale"
    },
    {
      "x": 0,
      "y": 21,
      "z": 1,
      "name": "Rock_Shale"
    },
    {
      "x": 0,
      "y": 22,
      "z": 1,
      "name": "Rock_Shale"
    },
    {
      "x": 0,
      "y": 23,
      "z": 1,
      "name": "Rock_Shale"
    },
    {
      "x": 0,
      "y": 24,
      "z": 1,
      "name": "Rock_Shale"
    },
    {
      "x": 0,
      "y": 25,
      "z": 1,
      "name": "Rock_Shale"
    },
    {
      "x": 0,
      "y": 26,
      "z": 1,
      "name": "Rock_Shale"
    },
    {
      "x": 0,
      "y": 27,
      "z": 1,
      "name": "Rock_Shale"
    },
    {
      "x": 0,
      "y": 28,
      "z": 1,
      "name": "Rock_Shale"
    },
    {
      "x": 0,
      "y": 29,
      "z": 1,
      "name": "Rock_Shale"
    },
    {
      "x": 0,
      "y": 30,
      "z": 1,
      "name": "Rock_Shale"
    },
    {
      "x": 0,
      "y": 31,
      "z": 1,
      "name": "Rock_Shale"
    },
    {
      "x": 0,
      "y": 32,
      "z": 1,
      "name": "Rock_Shale"
    },
    {
      "x": 0,
      "y": 33,
      "z": 1,
      "name": "Rock_Shale"
    },
    {
      "x": 0,
      "y": 10,
      "z": 2,
      "name": "Rock_Shale"
    },
    {
      "x": 0,
      "y": 11,
      "z": 2,
      "name": "Rock_Shale"
    },
    {
      "x": 0,
      "y": 12,
      "z": 2,
      "name": "Rock_Shale"
    },
    {
      "x": 0,
      "y": 13,
      "z": 2,
      "name": "Rock_Shale"
    },
    {
      "x": 0,
      "y": 14,
      "z": 2,
      "name": "Rock_Shale"
    },
    {
      "x": 0,
      "y": 15,
      "z": 2,
      "name": "Rock_Shale"
    },
    {
      "x": 0,
      "y": 16,
      "z": 2,
      "name": "Rock_Shale"
    },
    {
      "x": 0,
      "y": 17,
      "z": 2,
      "name": "Rock_Shale"
    },
    {
      "x": 0,
      "y": 18,
      "z": 2,
      "name": "Rock_Shale"
    },
    {
      "x": 0,
      "y": 19,
      "z": 2,
      "name": "Rock_Shale"
    },
    {
      "x": 0,
      "y": 20,
      "z": 2,
      "name": "Rock_Shale"
    },
    {
      "x": 0,
      "y": 21,
      "z": 2,
      "name": "Rock_Shale"
    },
    {
      "x": 0,
      "y": 22,
      "z": 2,
      "name": "Rock_Shale"
    },
    {
      "x": 0,
      "y": 23,
      "z": 2,
      "name": "Rock_Shale"
    },
    {
      "x": 0,
      "y": 24,
      "z": 2,
      "name": "Rock_Shale"
    },
    {
      "x": 0,
      "y": 25,
      "z": 2,
      "name": "Rock_Shale"
    },
    {
      "x": 0,
      "y": 26,
      "z": 2,
      "name": "Rock_Shale"
    },
    {
      "x": 0,
      "y": 27,
      "z": 2,
      "name": "Soil_Pebbles_Frozen"
    },
    {
      "x": 0,
      "y": 13,
      "z": 3,
      "name": "Rock_Shale"
    },
    {
      "x": 0,
      "y": 14,
      "z": 3,
      "name": "Rock_Shale"
    },
    {
      "x": 0,
      "y": 15,
      "z": 3,
      "name": "Rock_Shale"
    },
    {
      "x": 0,
      "y": 16,
      "z": 3,
      "name": "Rock_Shale"
    },
    {
      "x": 0,
      "y": 17,
      "z": 3,
      "name": "Rock_Shale"
    },
    {
      "x": 0,
      "y": 18,
      "z": 3,
      "name": "Rock_Shale"
    },
    {
      "x": 0,
      "y": 19,
      "z": 3,
      "name": "Rock_Shale"
    },
    {
      "x": 0,
      "y": 20,
      "z": 3,
      "name": "Rock_Shale"
    },
    {
      "x": 0,
      "y": 21,
      "z": 3,
      "name": "Rock_Shale"
    },
    {
      "x": 0,
      "y": 22,
      "z": 3,
      "name": "Rock_Shale"
    },
    {
      "x": 0,
      "y": 24,
      "z": 3,
      "name": "Rock_Shale"
    },
    {
      "x": 0,
      "y": 25,
      "z": 3,
      "name": "Rock_Shale"
    },
    {
      "x": 0,
      "y": 26,
      "z": 3,
      "name": "Soil_Pebbles_Frozen"
    },
    {
      "x": 0,
      "y": 27,
      "z": 3,
      "name": "Rubble_Shale_Medium"
    },
    {
      "x": 0,
      "y": 18,
      "z": 4,
      "name": "Rock_Shale"
    },
    {
      "x": 0,
      "y": 19,
      "z": 4,
      "name": "Rock_Shale"
    },
    {
      "x": 0,
      "y": 20,
      "z": 4,
      "name": "Rock_Shale"
    },
    {
      "x": 0,
      "y": 21,
      "z": 4,
      "name": "Rock_Shale"
    },
    {
      "x": 0,
      "y": 22,
      "z": 4,
      "name": "Rock_Shale"
    },
    {
      "x": 0,
      "y": 19,
      "z": 5,
      "name": "Rock_Shale"
    },
    {
      "x": 0,
      "y": 20,
      "z": 5,
      "name": "Rock_Shale"
    },
    {
      "x": 1,
      "y": 18,
      "z": -5,
      "name": "Rock_Shale"
    },
    {
      "x": 1,
      "y": 19,
      "z": -5,
      "name": "Rock_Shale"
    },
    {
      "x": 1,
      "y": 20,
      "z": -5,
      "name": "Rock_Shale"
    },
    {
      "x": 1,
      "y": 21,
      "z": -5,
      "name": "Rock_Shale"
    },
    {
      "x": 1,
      "y": 22,
      "z": -5,
      "name": "Rock_Shale"
    },
    {
      "x": 1,
      "y": 23,
      "z": -5,
      "name": "Rock_Shale"
    },
    {
      "x": 1,
      "y": 24,
      "z": -5,
      "name": "Soil_Pebbles_Frozen"
    },
    {
      "x": 1,
      "y": 17,
      "z": -4,
      "name": "Rock_Shale"
    },
    {
      "x": 1,
      "y": 18,
      "z": -4,
      "name": "Rock_Shale"
    },
    {
      "x": 1,
      "y": 19,
      "z": -4,
      "name": "Rock_Shale"
    },
    {
      "x": 1,
      "y": 20,
      "z": -4,
      "name": "Rock_Shale"
    },
    {
      "x": 1,
      "y": 21,
      "z": -4,
      "name": "Rock_Shale"
    },
    {
      "x": 1,
      "y": 22,
      "z": -4,
      "name": "Rock_Shale"
    },
    {
      "x": 1,
      "y": 23,
      "z": -4,
      "name": "Rock_Shale"
    },
    {
      "x": 1,
      "y": 24,
      "z": -4,
      "name": "Rock_Shale"
    },
    {
      "x": 1,
      "y": 25,
      "z": -4,
      "name": "Rock_Shale"
    },
    {
      "x": 1,
      "y": 26,
      "z": -4,
      "name": "Soil_Pebbles_Frozen"
    },
    {
      "x": 1,
      "y": 13,
      "z": -3,
      "name": "Rock_Shale"
    },
    {
      "x": 1,
      "y": 14,
      "z": -3,
      "name": "Rock_Shale"
    },
    {
      "x": 1,
      "y": 15,
      "z": -3,
      "name": "Rock_Shale"
    },
    {
      "x": 1,
      "y": 16,
      "z": -3,
      "name": "Rock_Shale"
    },
    {
      "x": 1,
      "y": 17,
      "z": -3,
      "name": "Rock_Shale"
    },
    {
      "x": 1,
      "y": 18,
      "z": -3,
      "name": "Rock_Shale"
    },
    {
      "x": 1,
      "y": 19,
      "z": -3,
      "name": "Rock_Shale"
    },
    {
      "x": 1,
      "y": 20,
      "z": -3,
      "name": "Rock_Shale"
    },
    {
      "x": 1,
      "y": 21,
      "z": -3,
      "name": "Rock_Shale"
    },
    {
      "x": 1,
      "y": 22,
      "z": -3,
      "name": "Rock_Shale"
    },
    {
      "x": 1,
      "y": 23,
      "z": -3,
      "name": "Rock_Shale"
    },
    {
      "x": 1,
      "y": 24,
      "z": -3,
      "name": "Rock_Shale"
    },
    {
      "x": 1,
      "y": 25,
      "z": -3,
      "name": "Rock_Shale"
    },
    {
      "x": 1,
      "y": 26,
      "z": -3,
      "name": "Soil_Pebbles_Frozen"
    },
    {
      "x": 1,
      "y": 11,
      "z": -2,
      "name": "Rock_Shale"
    },
    {
      "x": 1,
      "y": 12,
      "z": -2,
      "name": "Rock_Shale"
    },
    {
      "x": 1,
      "y": 13,
      "z": -2,
      "name": "Rock_Shale"
    },
    {
      "x": 1,
      "y": 14,
      "z": -2,
      "name": "Rock_Shale"
    },
    {
      "x": 1,
      "y": 15,
      "z": -2,
      "name": "Rock_Shale"
    },
    {
      "x": 1,
      "y": 16,
      "z": -2,
      "name": "Rock_Shale"
    },
    {
      "x": 1,
      "y": 17,
      "z": -2,
      "name": "Rock_Shale"
    },
    {
      "x": 1,
      "y": 18,
      "z": -2,
      "name": "Rock_Shale"
    },
    {
      "x": 1,
      "y": 19,
      "z": -2,
      "name": "Rock_Shale"
    },
    {
      "x": 1,
      "y": 20,
      "z": -2,
      "name": "Rock_Shale"
    },
    {
      "x": 1,
      "y": 21,
      "z": -2,
      "name": "Rock_Shale"
    },
    {
      "x": 1,
      "y": 22,
      "z": -2,
      "name": "Rock_Shale"
    },
    {
      "x": 1,
      "y": 23,
      "z": -2,
      "name": "Rock_Shale"
    },
    {
      "x": 1,
      "y": 24,
      "z": -2,
      "name": "Rock_Shale"
    },
    {
      "x": 1,
      "y": 25,
      "z": -2,
      "name": "Rock_Shale"
    },
    {
      "x": 1,
      "y": 26,
      "z": -2,
      "name": "Rock_Shale"
    },
    {
      "x": 1,
      "y": 27,
      "z": -2,
      "name": "Rock_Shale"
    },
    {
      "x": 1,
      "y": 28,
      "z": -2,
      "name": "Rock_Shale"
    },
    {
      "x": 1,
      "y": 29,
      "z": -2,
      "name": "Rock_Shale"
    },
    {
      "x": 1,
      "y": 30,
      "z": -2,
      "name": "Rock_Shale"
    },
    {
      "x": 1,
      "y": 31,
      "z": -2,
      "name": "Rock_Shale"
    },
    {
      "x": 1,
      "y": 32,
      "z": -2,
      "name": "Rock_Shale"
    },
    {
      "x": 1,
      "y": 33,
      "z": -2,
      "name": "Rock_Shale"
    },
    {
      "x": 1,
      "y": 9,
      "z": -1,
      "name": "Rock_Shale"
    },
    {
      "x": 1,
      "y": 10,
      "z": -1,
      "name": "Rock_Shale"
    },
    {
      "x": 1,
      "y": 11,
      "z": -1,
      "name": "Rock_Shale"
    },
    {
      "x": 1,
      "y": 12,
      "z": -1,
      "name": "Rock_Shale"
    },
    {
      "x": 1,
      "y": 13,
      "z": -1,
      "name": "Rock_Shale"
    },
    {
      "x": 1,
      "y": 14,
      "z": -1,
      "name": "Rock_Shale"
    },
    {
      "x": 1,
      "y": 15,
      "z": -1,
      "name": "Rock_Shale"
    },
    {
      "x": 1,
      "y": 16,
      "z": -1,
      "name": "Rock_Shale"
    },
    {
      "x": 1,
      "y": 17,
      "z": -1,
      "name": "Rock_Shale"
    },
    {
      "x": 1,
      "y": 18,
      "z": -1,
      "name": "Rock_Shale"
    },
    {
      "x": 1,
      "y": 19,
      "z": -1,
      "name": "Rock_Shale"
    },
    {
      "x": 1,
      "y": 20,
      "z": -1,
      "name": "Rock_Shale"
    },
    {
      "x": 1,
      "y": 21,
      "z": -1,
      "name": "Rock_Shale"
    },
    {
      "x": 1,
      "y": 22,
      "z": -1,
      "name": "Rock_Shale"
    },
    {
      "x": 1,
      "y": 23,
      "z": -1,
      "name": "Rock_Shale"
    },
    {
      "x": 1,
      "y": 24,
      "z": -1,
      "name": "Rock_Shale"
    },
    {
      "x": 1,
      "y": 25,
      "z": -1,
      "name": "Rock_Shale"
    },
    {
      "x": 1,
      "y": 26,
      "z": -1,
      "name": "Rock_Shale"
    },
    {
      "x": 1,
      "y": 27,
      "z": -1,
      "name": "Rock_Shale"
    },
    {
      "x": 1,
      "y": 28,
      "z": -1,
      "name": "Rock_Shale"
    },
    {
      "x": 1,
      "y": 29,
      "z": -1,
      "name": "Rock_Shale"
    },
    {
      "x": 1,
      "y": 30,
      "z": -1,
      "name": "Rock_Shale"
    },
    {
      "x": 1,
      "y": 31,
      "z": -1,
      "name": "Rock_Shale"
    },
    {
      "x": 1,
      "y": 32,
      "z": -1,
      "name": "Rock_Shale"
    },
    {
      "x": 1,
      "y": 33,
      "z": -1,
      "name": "Rock_Shale"
    },
    {
      "x": 1,
      "y": 34,
      "z": -1,
      "name": "Rock_Shale"
    },
    {
      "x": 1,
      "y": 8,
      "z": 0,
      "name": "Rock_Shale"
    },
    {
      "x": 1,
      "y": 9,
      "z": 0,
      "name": "Rock_Shale"
    },
    {
      "x": 1,
      "y": 10,
      "z": 0,
      "name": "Rock_Shale"
    },
    {
      "x": 1,
      "y": 11,
      "z": 0,
      "name": "Rock_Shale"
    },
    {
      "x": 1,
      "y": 12,
      "z": 0,
      "name": "Rock_Shale"
    },
    {
      "x": 1,
      "y": 13,
      "z": 0,
      "name": "Rock_Shale"
    },
    {
      "x": 1,
      "y": 14,
      "z": 0,
      "name": "Rock_Shale"
    },
    {
      "x": 1,
      "y": 15,
      "z": 0,
      "name": "Rock_Shale"
    },
    {
      "x": 1,
      "y": 16,
      "z": 0,
      "name": "Rock_Shale"
    },
    {
      "x": 1,
      "y": 17,
      "z": 0,
      "name": "Rock_Shale"
    },
    {
      "x": 1,
      "y": 18,
      "z": 0,
      "name": "Rock_Shale"
    },
    {
      "x": 1,
      "y": 19,
      "z": 0,
      "name": "Rock_Shale"
    },
    {
      "x": 1,
      "y": 20,
      "z": 0,
      "name": "Rock_Shale"
    },
    {
      "x": 1,
      "y": 21,
      "z": 0,
      "name": "Rock_Shale"
    },
    {
      "x": 1,
      "y": 22,
      "z": 0,
      "name": "Rock_Shale"
    },
    {
      "x": 1,
      "y": 23,
      "z": 0,
      "name": "Rock_Shale"
    },
    {
      "x": 1,
      "y": 24,
      "z": 0,
      "name": "Rock_Shale"
    },
    {
      "x": 1,
      "y": 25,
      "z": 0,
      "name": "Rock_Shale"
    },
    {
      "x": 1,
      "y": 26,
      "z": 0,
      "name": "Rock_Shale"
    },
    {
      "x": 1,
      "y": 27,
      "z": 0,
      "name": "Rock_Shale"
    },
    {
      "x": 1,
      "y": 28,
      "z": 0,
      "name": "Rock_Shale"
    },
    {
      "x": 1,
      "y": 29,
      "z": 0,
      "name": "Rock_Shale"
    },
    {
      "x": 1,
      "y": 30,
      "z": 0,
      "name": "Rock_Shale"
    },
    {
      "x": 1,
      "y": 31,
      "z": 0,
      "name": "Rock_Shale"
    },
    {
      "x": 1,
      "y": 32,
      "z": 0,
      "name": "Rock_Shale"
    },
    {
      "x": 1,
      "y": 33,
      "z": 0,
      "name": "Rock_Shale"
    },
    {
      "x": 1,
      "y": 34,
      "z": 0,
      "name": "Rock_Shale"
    },
    {
      "x": 1,
      "y": 35,
      "z": 0,
      "name": "Rock_Shale"
    },
    {
      "x": 1,
      "y": 9,
      "z": 1,
      "name": "Rock_Shale"
    },
    {
      "x": 1,
      "y": 10,
      "z": 1,
      "name": "Rock_Shale"
    },
    {
      "x": 1,
      "y": 11,
      "z": 1,
      "name": "Rock_Shale"
    },
    {
      "x": 1,
      "y": 12,
      "z": 1,
      "name": "Rock_Shale"
    },
    {
      "x": 1,
      "y": 13,
      "z": 1,
      "name": "Rock_Shale"
    },
    {
      "x": 1,
      "y": 14,
      "z": 1,
      "name": "Rock_Shale"
    },
    {
      "x": 1,
      "y": 15,
      "z": 1,
      "name": "Rock_Shale"
    },
    {
      "x": 1,
      "y": 16,
      "z": 1,
      "name": "Rock_Shale"
    },
    {
      "x": 1,
      "y": 17,
      "z": 1,
      "name": "Rock_Shale"
    },
    {
      "x": 1,
      "y": 18,
      "z": 1,
      "name": "Rock_Shale"
    },
    {
      "x": 1,
      "y": 19,
      "z": 1,
      "name": "Rock_Shale"
    },
    {
      "x": 1,
      "y": 20,
      "z": 1,
      "name": "Rock_Shale"
    },
    {
      "x": 1,
      "y": 21,
      "z": 1,
      "name": "Rock_Shale"
    },
    {
      "x": 1,
      "y": 22,
      "z": 1,
      "name": "Rock_Shale"
    },
    {
      "x": 1,
      "y": 23,
      "z": 1,
      "name": "Rock_Shale"
    },
    {
      "x": 1,
      "y": 24,
      "z": 1,
      "name": "Rock_Shale"
    },
    {
      "x": 1,
      "y": 25,
      "z": 1,
      "name": "Rock_Shale"
    },
    {
      "x": 1,
      "y": 26,
      "z": 1,
      "name": "Soil_Pebbles_Frozen"
    },
    {
      "x": 1,
      "y": 11,
      "z": 2,
      "name": "Rock_Shale"
    },
    {
      "x": 1,
      "y": 12,
      "z": 2,
      "name": "Rock_Shale"
    },
    {
      "x": 1,
      "y": 13,
      "z": 2,
      "name": "Rock_Shale"
    },
    {
      "x": 1,
      "y": 14,
      "z": 2,
      "name": "Rock_Shale"
    },
    {
      "x": 1,
      "y": 15,
      "z": 2,
      "name": "Rock_Shale"
    },
    {
      "x": 1,
      "y": 16,
      "z": 2,
      "name": "Rock_Shale"
    },
    {
      "x": 1,
      "y": 17,
      "z": 2,
      "name": "Rock_Shale"
    },
    {
      "x": 1,
      "y": 18,
      "z": 2,
      "name": "Rock_Shale"
    },
    {
      "x": 1,
      "y": 19,
      "z": 2,
      "name": "Rock_Shale"
    },
    {
      "x": 1,
      "y": 20,
      "z": 2,
      "name": "Rock_Shale"
    },
    {
      "x": 1,
      "y": 21,
      "z": 2,
      "name": "Rock_Shale"
    },
    {
      "x": 1,
      "y": 22,
      "z": 2,
      "name": "Rock_Shale"
    },
    {
      "x": 1,
      "y": 23,
      "z": 2,
      "name": "Rock_Shale"
    },
    {
      "x": 1,
      "y": 24,
      "z": 2,
      "name": "Rock_Shale"
    },
    {
      "x": 1,
      "y": 25,
      "z": 2,
      "name": "Rock_Shale"
    },
    {
      "x": 1,
      "y": 26,
      "z": 2,
      "name": "Soil_Pebbles_Frozen"
    },
    {
      "x": 1,
      "y": 27,
      "z": 2,
      "name": "Rubble_Shale"
    },
    {
      "x": 1,
      "y": 13,
      "z": 3,
      "name": "Rock_Shale"
    },
    {
      "x": 1,
      "y": 14,
      "z": 3,
      "name": "Rock_Shale"
    },
    {
      "x": 1,
      "y": 15,
      "z": 3,
      "name": "Rock_Shale"
    },
    {
      "x": 1,
      "y": 16,
      "z": 3,
      "name": "Rock_Shale"
    },
    {
      "x": 1,
      "y": 17,
      "z": 3,
      "name": "Rock_Shale"
    },
    {
      "x": 1,
      "y": 18,
      "z": 3,
      "name": "Rock_Shale"
    },
    {
      "x": 1,
      "y": 19,
      "z": 3,
      "name": "Rock_Shale"
    },
    {
      "x": 1,
      "y": 20,
      "z": 3,
      "name": "Rock_Shale"
    },
    {
      "x": 1,
      "y": 21,
      "z": 3,
      "name": "Rock_Shale"
    },
    {
      "x": 1,
      "y": 22,
      "z": 3,
      "name": "Rock_Shale"
    },
    {
      "x": 1,
      "y": 24,
      "z": 3,
      "name": "Rock_Shale"
    },
    {
      "x": 1,
      "y": 25,
      "z": 3,
      "name": "Rock_Shale"
    },
    {
      "x": 1,
      "y": 26,
      "z": 3,
      "name": "Soil_Pebbles_Frozen"
    },
    {
      "x": 1,
      "y": 18,
      "z": 4,
      "name": "Rock_Shale"
    },
    {
      "x": 1,
      "y": 19,
      "z": 4,
      "name": "Rock_Shale"
    },
    {
      "x": 1,
      "y": 20,
      "z": 4,
      "name": "Rock_Shale"
    },
    {
      "x": 1,
      "y": 21,
      "z": 4,
      "name": "Rock_Shale"
    },
    {
      "x": 1,
      "y": 22,
      "z": 4,
      "name": "Rock_Shale"
    },
    {
      "x": 1,
      "y": 19,
      "z": 5,
      "name": "Rock_Shale"
    },
    {
      "x": 1,
      "y": 20,
      "z": 5,
      "name": "Rock_Shale"
    },
    {
      "x": 1,
      "y": 21,
      "z": 5,
      "name": "Rock_Shale"
    },
    {
      "x": 2,
      "y": 20,
      "z": -4,
      "name": "Rock_Shale"
    },
    {
      "x": 2,
      "y": 21,
      "z": -4,
      "name": "Rock_Shale"
    },
    {
      "x": 2,
      "y": 22,
      "z": -4,
      "name": "Rock_Shale"
    },
    {
      "x": 2,
      "y": 23,
      "z": -4,
      "name": "Rock_Shale"
    },
    {
      "x": 2,
      "y": 24,
      "z": -4,
      "name": "Rock_Shale"
    },
    {
      "x": 2,
      "y": 25,
      "z": -4,
      "name": "Soil_Pebbles_Frozen"
    },
    {
      "x": 2,
      "y": 17,
      "z": -3,
      "name": "Rock_Shale"
    },
    {
      "x": 2,
      "y": 18,
      "z": -3,
      "name": "Rock_Shale"
    },
    {
      "x": 2,
      "y": 19,
      "z": -3,
      "name": "Rock_Shale"
    },
    {
      "x": 2,
      "y": 20,
      "z": -3,
      "name": "Rock_Shale"
    },
    {
      "x": 2,
      "y": 21,
      "z": -3,
      "name": "Rock_Shale"
    },
    {
      "x": 2,
      "y": 22,
      "z": -3,
      "name": "Rock_Shale"
    },
    {
      "x": 2,
      "y": 23,
      "z": -3,
      "name": "Rock_Shale"
    },
    {
      "x": 2,
      "y": 24,
      "z": -3,
      "name": "Rock_Shale"
    },
    {
      "x": 2,
      "y": 25,
      "z": -3,
      "name": "Rock_Shale"
    },
    {
      "x": 2,
      "y": 26,
      "z": -3,
      "name": "Soil_Pebbles_Frozen"
    },
    {
      "x": 2,
      "y": 12,
      "z": -2,
      "name": "Rock_Shale"
    },
    {
      "x": 2,
      "y": 13,
      "z": -2,
      "name": "Rock_Shale"
    },
    {
      "x": 2,
      "y": 14,
      "z": -2,
      "name": "Rock_Shale"
    },
    {
      "x": 2,
      "y": 15,
      "z": -2,
      "name": "Rock_Shale"
    },
    {
      "x": 2,
      "y": 16,
      "z": -2,
      "name": "Rock_Shale"
    },
    {
      "x": 2,
      "y": 17,
      "z": -2,
      "name": "Rock_Shale"
    },
    {
      "x": 2,
      "y": 18,
      "z": -2,
      "name": "Rock_Shale"
    },
    {
      "x": 2,
      "y": 19,
      "z": -2,
      "name": "Rock_Shale"
    },
    {
      "x": 2,
      "y": 20,
      "z": -2,
      "name": "Rock_Shale"
    },
    {
      "x": 2,
      "y": 21,
      "z": -2,
      "name": "Rock_Shale"
    },
    {
      "x": 2,
      "y": 22,
      "z": -2,
      "name": "Rock_Shale"
    },
    {
      "x": 2,
      "y": 23,
      "z": -2,
      "name": "Rock_Shale"
    },
    {
      "x": 2,
      "y": 24,
      "z": -2,
      "name": "Rock_Shale"
    },
    {
      "x": 2,
      "y": 25,
      "z": -2,
      "name": "Rock_Shale"
    },
    {
      "x": 2,
      "y": 26,
      "z": -2,
      "name": "Soil_Pebbles_Frozen"
    },
    {
      "x": 2,
      "y": 27,
      "z": -2,
      "name": "Rubble_Shale"
    },
    {
      "x": 2,
      "y": 10,
      "z": -1,
      "name": "Rock_Shale"
    },
    {
      "x": 2,
      "y": 11,
      "z": -1,
      "name": "Rock_Shale"
    },
    {
      "x": 2,
      "y": 12,
      "z": -1,
      "name": "Rock_Shale"
    },
    {
      "x": 2,
      "y": 13,
      "z": -1,
      "name": "Rock_Shale"
    },
    {
      "x": 2,
      "y": 14,
      "z": -1,
      "name": "Rock_Shale"
    },
    {
      "x": 2,
      "y": 15,
      "z": -1,
      "name": "Rock_Shale"
    },
    {
      "x": 2,
      "y": 16,
      "z": -1,
      "name": "Rock_Shale"
    },
    {
      "x": 2,
      "y": 17,
      "z": -1,
      "name": "Rock_Shale"
    },
    {
      "x": 2,
      "y": 18,
      "z": -1,
      "name": "Rock_Shale"
    },
    {
      "x": 2,
      "y": 19,
      "z": -1,
      "name": "Rock_Shale"
    },
    {
      "x": 2,
      "y": 20,
      "z": -1,
      "name": "Rock_Shale"
    },
    {
      "x": 2,
      "y": 21,
      "z": -1,
      "name": "Rock_Shale"
    },
    {
      "x": 2,
      "y": 22,
      "z": -1,
      "name": "Rock_Shale"
    },
    {
      "x": 2,
      "y": 23,
      "z": -1,
      "name": "Rock_Shale"
    },
    {
      "x": 2,
      "y": 24,
      "z": -1,
      "name": "Rock_Shale"
    },
    {
      "x": 2,
      "y": 25,
      "z": -1,
      "name": "Rock_Shale"
    },
    {
      "x": 2,
      "y": 26,
      "z": -1,
      "name": "Rock_Shale"
    },
    {
      "x": 2,
      "y": 27,
      "z": -1,
      "name": "Rock_Shale"
    },
    {
      "x": 2,
      "y": 28,
      "z": -1,
      "name": "Rock_Shale"
    },
    {
      "x": 2,
      "y": 29,
      "z": -1,
      "name": "Rock_Shale"
    },
    {
      "x": 2,
      "y": 9,
      "z": 0,
      "name": "Rock_Shale"
    },
    {
      "x": 2,
      "y": 10,
      "z": 0,
      "name": "Rock_Shale"
    },
    {
      "x": 2,
      "y": 11,
      "z": 0,
      "name": "Rock_Shale"
    },
    {
      "x": 2,
      "y": 12,
      "z": 0,
      "name": "Rock_Shale"
    },
    {
      "x": 2,
      "y": 13,
      "z": 0,
      "name": "Rock_Shale"
    },
    {
      "x": 2,
      "y": 14,
      "z": 0,
      "name": "Rock_Shale"
    },
    {
      "x": 2,
      "y": 15,
      "z": 0,
      "name": "Rock_Shale"
    },
    {
      "x": 2,
      "y": 16,
      "z": 0,
      "name": "Rock_Shale"
    },
    {
      "x": 2,
      "y": 17,
      "z": 0,
      "name": "Rock_Shale"
    },
    {
      "x": 2,
      "y": 18,
      "z": 0,
      "name": "Rock_Shale"
    },
    {
      "x": 2,
      "y": 19,
      "z": 0,
      "name": "Rock_Shale"
    },
    {
      "x": 2,
      "y": 20,
      "z": 0,
      "name": "Rock_Shale"
    },
    {
      "x": 2,
      "y": 21,
      "z": 0,
      "name": "Rock_Shale"
    },
    {
      "x": 2,
      "y": 22,
      "z": 0,
      "name": "Rock_Shale"
    },
    {
      "x": 2,
      "y": 23,
      "z": 0,
      "name": "Rock_Shale"
    },
    {
      "x": 2,
      "y": 24,
      "z": 0,
      "name": "Rock_Shale"
    },
    {
      "x": 2,
      "y": 25,
      "z": 0,
      "name": "Rock_Shale"
    },
    {
      "x": 2,
      "y": 26,
      "z": 0,
      "name": "Rock_Shale"
    },
    {
      "x": 2,
      "y": 27,
      "z": 0,
      "name": "Rock_Shale"
    },
    {
      "x": 2,
      "y": 28,
      "z": 0,
      "name": "Rock_Shale"
    },
    {
      "x": 2,
      "y": 29,
      "z": 0,
      "name": "Rock_Shale"
    },
    {
      "x": 2,
      "y": 30,
      "z": 0,
      "name": "Rock_Shale"
    },
    {
      "x": 2,
      "y": 10,
      "z": 1,
      "name": "Rock_Shale"
    },
    {
      "x": 2,
      "y": 11,
      "z": 1,
      "name": "Rock_Shale"
    },
    {
      "x": 2,
      "y": 12,
      "z": 1,
      "name": "Rock_Shale"
    },
    {
      "x": 2,
      "y": 13,
      "z": 1,
      "name": "Rock_Shale"
    },
    {
      "x": 2,
      "y": 14,
      "z": 1,
      "name": "Rock_Shale"
    },
    {
      "x": 2,
      "y": 15,
      "z": 1,
      "name": "Rock_Shale"
    },
    {
      "x": 2,
      "y": 16,
      "z": 1,
      "name": "Rock_Shale"
    },
    {
      "x": 2,
      "y": 17,
      "z": 1,
      "name": "Rock_Shale"
    },
    {
      "x": 2,
      "y": 18,
      "z": 1,
      "name": "Rock_Shale"
    },
    {
      "x": 2,
      "y": 19,
      "z": 1,
      "name": "Rock_Shale"
    },
    {
      "x": 2,
      "y": 20,
      "z": 1,
      "name": "Rock_Shale"
    },
    {
      "x": 2,
      "y": 21,
      "z": 1,
      "name": "Rock_Shale"
    },
    {
      "x": 2,
      "y": 22,
      "z": 1,
      "name": "Rock_Shale"
    },
    {
      "x": 2,
      "y": 23,
      "z": 1,
      "name": "Rock_Shale"
    },
    {
      "x": 2,
      "y": 24,
      "z": 1,
      "name": "Rock_Shale"
    },
    {
      "x": 2,
      "y": 25,
      "z": 1,
      "name": "Rock_Shale"
    },
    {
      "x": 2,
      "y": 26,
      "z": 1,
      "name": "Soil_Pebbles_Frozen"
    },
    {
      "x": 2,
      "y": 12,
      "z": 2,
      "name": "Rock_Shale"
    },
    {
      "x": 2,
      "y": 13,
      "z": 2,
      "name": "Rock_Shale"
    },
    {
      "x": 2,
      "y": 14,
      "z": 2,
      "name": "Rock_Shale"
    },
    {
      "x": 2,
      "y": 15,
      "z": 2,
      "name": "Rock_Shale"
    },
    {
      "x": 2,
      "y": 16,
      "z": 2,
      "name": "Rock_Shale"
    },
    {
      "x": 2,
      "y": 17,
      "z": 2,
      "name": "Rock_Shale"
    },
    {
      "x": 2,
      "y": 18,
      "z": 2,
      "name": "Rock_Shale"
    },
    {
      "x": 2,
      "y": 19,
      "z": 2,
      "name": "Rock_Shale"
    },
    {
      "x": 2,
      "y": 20,
      "z": 2,
      "name": "Rock_Shale"
    },
    {
      "x": 2,
      "y": 21,
      "z": 2,
      "name": "Rock_Shale"
    },
    {
      "x": 2,
      "y": 22,
      "z": 2,
      "name": "Rock_Shale"
    },
    {
      "x": 2,
      "y": 25,
      "z": 2,
      "name": "Rock_Shale"
    },
    {
      "x": 2,
      "y": 26,
      "z": 2,
      "name": "Soil_Pebbles_Frozen"
    },
    {
      "x": 2,
      "y": 14,
      "z": 3,
      "name": "Rock_Shale"
    },
    {
      "x": 2,
      "y": 17,
      "z": 3,
      "name": "Rock_Shale"
    },
    {
      "x": 2,
      "y": 18,
      "z": 3,
      "name": "Rock_Shale"
    },
    {
      "x": 2,
      "y": 19,
      "z": 3,
      "name": "Rock_Shale"
    },
    {
      "x": 2,
      "y": 20,
      "z": 3,
      "name": "Rock_Shale"
    },
    {
      "x": 2,
      "y": 21,
      "z": 3,
      "name": "Rock_Shale"
    },
    {
      "x": 2,
      "y": 22,
      "z": 3,
      "name": "Rock_Shale"
    },
    {
      "x": 2,
      "y": 18,
      "z": 4,
      "name": "Rock_Shale"
    },
    {
      "x": 2,
      "y": 19,
      "z": 4,
      "name": "Rock_Shale"
    },
    {
      "x": 2,
      "y": 20,
      "z": 4,
      "name": "Rock_Shale"
    },
    {
      "x": 2,
      "y": 21,
      "z": 4,
      "name": "Rock_Shale"
    },
    {
      "x": 3,
      "y": 21,
      "z": -3,
      "name": "Rock_Shale"
    },
    {
      "x": 3,
      "y": 22,
      "z": -3,
      "name": "Rock_Shale"
    },
    {
      "x": 3,
      "y": 23,
      "z": -3,
      "name": "Rock_Shale"
    },
    {
      "x": 3,
      "y": 24,
      "z": -3,
      "name": "Rock_Shale"
    },
    {
      "x": 3,
      "y": 25,
      "z": -3,
      "name": "Soil_Pebbles_Frozen"
    },
    {
      "x": 3,
      "y": 20,
      "z": -2,
      "name": "Rock_Shale"
    },
    {
      "x": 3,
      "y": 21,
      "z": -2,
      "name": "Rock_Shale"
    },
    {
      "x": 3,
      "y": 22,
      "z": -2,
      "name": "Rock_Shale"
    },
    {
      "x": 3,
      "y": 23,
      "z": -2,
      "name": "Rock_Shale"
    },
    {
      "x": 3,
      "y": 24,
      "z": -2,
      "name": "Rock_Shale"
    },
    {
      "x": 3,
      "y": 25,
      "z": -2,
      "name": "Soil_Pebbles_Frozen"
    },
    {
      "x": 3,
      "y": 15,
      "z": -1,
      "name": "Rock_Shale"
    },
    {
      "x": 3,
      "y": 16,
      "z": -1,
      "name": "Rock_Shale"
    },
    {
      "x": 3,
      "y": 17,
      "z": -1,
      "name": "Rock_Shale"
    },
    {
      "x": 3,
      "y": 18,
      "z": -1,
      "name": "Rock_Shale"
    },
    {
      "x": 3,
      "y": 19,
      "z": -1,
      "name": "Rock_Shale"
    },
    {
      "x": 3,
      "y": 20,
      "z": -1,
      "name": "Rock_Shale"
    },
    {
      "x": 3,
      "y": 21,
      "z": -1,
      "name": "Rock_Shale"
    },
    {
      "x": 3,
      "y": 22,
      "z": -1,
      "name": "Rock_Shale"
    },
    {
      "x": 3,
      "y": 23,
      "z": -1,
      "name": "Rock_Shale"
    },
    {
      "x": 3,
      "y": 24,
      "z": -1,
      "name": "Rock_Shale"
    },
    {
      "x": 3,
      "y": 25,
      "z": -1,
      "name": "Rock_Shale"
    },
    {
      "x": 3,
      "y": 14,
      "z": 0,
      "name": "Rock_Shale"
    },
    {
      "x": 3,
      "y": 15,
      "z": 0,
      "name": "Rock_Shale"
    },
    {
      "x": 3,
      "y": 16,
      "z": 0,
      "name": "Rock_Shale"
    },
    {
      "x": 3,
      "y": 17,
      "z": 0,
      "name": "Rock_Shale"
    },
    {
      "x": 3,
      "y": 18,
      "z": 0,
      "name": "Rock_Shale"
    },
    {
      "x": 3,
      "y": 19,
      "z": 0,
      "name": "Rock_Shale"
    },
    {
      "x": 3,
      "y": 20,
      "z": 0,
      "name": "Rock_Shale"
    },
    {
      "x": 3,
      "y": 21,
      "z": 0,
      "name": "Rock_Shale"
    },
    {
      "x": 3,
      "y": 22,
      "z": 0,
      "name": "Rock_Shale"
    },
    {
      "x": 3,
      "y": 23,
      "z": 0,
      "name": "Rock_Shale"
    },
    {
      "x": 3,
      "y": 24,
      "z": 0,
      "name": "Rock_Shale"
    },
    {
      "x": 3,
      "y": 25,
      "z": 0,
      "name": "Rock_Shale"
    },
    {
      "x": 3,
      "y": 14,
      "z": 1,
      "name": "Rock_Shale"
    },
    {
      "x": 3,
      "y": 15,
      "z": 1,
      "name": "Rock_Shale"
    },
    {
      "x": 3,
      "y": 16,
      "z": 1,
      "name": "Rock_Shale"
    },
    {
      "x": 3,
      "y": 17,
      "z": 1,
      "name": "Rock_Shale"
    },
    {
      "x": 3,
      "y": 18,
      "z": 1,
      "name": "Rock_Shale"
    },
    {
      "x": 3,
      "y": 19,
      "z": 1,
      "name": "Rock_Shale"
    },
    {
      "x": 3,
      "y": 20,
      "z": 1,
      "name": "Rock_Shale"
    },
    {
      "x": 3,
      "y": 24,
      "z": 1,
      "name": "Rock_Shale"
    },
    {
      "x": 3,
      "y": 25,
      "z": 1,
      "name": "Rock_Shale"
    },
    {
      "x": 3,
      "y": 17,
      "z": 2,
      "name": "Rock_Shale"
    },
    {
      "x": 3,
      "y": 18,
      "z": 2,
      "name": "Rock_Shale"
    },
    {
      "x": 3,
      "y": 19,
      "z": 2,
      "name": "Rock_Shale"
    },
    {
      "x": 3,
      "y": 20,
      "z": 2,
      "name": "Rock_Shale"
    },
    {
      "x": 3,
      "y": 21,
      "z": 2,
      "name": "Rock_Shale"
    },
    {
      "x": 3,
      "y": 18,
      "z": 3,
      "name": "Rock_Shale"
    },
    {
      "x": 3,
      "y": 19,
      "z": 3,
      "name": "Rock_Shale"
    },
    {
      "x": 3,
      "y": 20,
      "z": 3,
      "name": "Rock_Shale"
    },
    {
      "x": 3,
      "y": 21,
      "z": 3,
      "name": "Rock_Shale"
    },
    {
      "x": 3,
      "y": 19,
      "z": 4,
      "name": "Rock_Shale"
    },
    {
      "x": 3,
      "y": 20,
      "z": 4,
      "name": "Rock_Shale"
    },
    {
      "x": 4,
      "y": 25,
      "z": -2,
      "name": "Rock_Shale"
    },
    {
      "x": 4,
      "y": 24,
      "z": -1,
      "name": "Rock_Shale"
    },
    {
      "x": 4,
      "y": 25,
      "z": -1,
      "name": "Rock_Shale"
    },
    {
      "x": 4,
      "y": 24,
      "z": 0,
      "name": "Rock_Shale"
    },
    {
      "x": 4,
      "y": 25,
      "z": 0,
      "name": "Rock_Shale"
    }
  ]
}