{
  "version": 8,
  "blockIdVersion": 10,
  "anchorX": 2,
  "anchorY": 8,
  "anchorZ": 0,
  "blocks": [
    {
      "x": -2,
      "y": 6,
      "z": 0,
      "name": "Wood_Oak_Trunk"
    },
    {
      "x": -2,
      "y": 7,
      "z": 0,
      "name": "Wood_Oak_Trunk_Full"
    },
    {
      "x": -2,
      "y": 8,
      "z": 0,
      "name": "Soil_Grass_Deep"
    },
    {
      "x": -2,
      "y": 9,
      "z": 0,
      "name": "Plant_Grass_Sharp"
    },
    {
      "x": -2,
      "y": 13,
      "z": 0,
      "name": "Furniture_Kweebec_Platform"
    },
    {
      "x": -2,
      "y": 14,
      "z": 0,
      "name": "Plant_Moss_Rug_Green"
    },
    {
      "x": -2,
      "y": 6,
      "z": 1,
      "name": "Soil_Dirt"
    },
    {
      "x": -2,
      "y": 7,
      "z": 1,
      "name": "Soil_Dirt"
    },
    {
      "x": -2,
      "y": 8,
      "z": 1,
      "name": "Soil_Leaves"
    },
    {
      "x": -2,
      "y": 9,
      "z": 1,
      "name": "Plant_Grass_Sharp_Tall"
    },
    {
      "x": -2,
      "y": 10,
      "z": 1,
      "name": "Plant_Grass_Sharp_Tall",
      "filler": 1024
    },
    {
      "x": -2,
      "y": 13,
      "z": 1,
      "name": "Furniture_Kweebec_Platform"
    },
    {
      "x": -2,
      "y": 7,
      "z": 2,
      "name": "Soil_Dirt"
    },
    {
      "x": -2,
      "y": 8,
      "z": 2,
      "name": "Soil_Leaves"
    },
    {
      "x": -2,
      "y": 6,
      "z": 3,
      "name": "Wood_Oak_Trunk_Full"
    },
    {
      "x": -2,
      "y": 7,
      "z": 3,
      "name": "Soil_Dirt"
    },
    {
      "x": -2,
      "y": 8,
      "z": 3,
      "name": "Soil_Leaves"
    },
    {
      "x": -1,
      "y": 8,
      "z": -3,
      "name": "Soil_Grass_Deep"
    },
    {
      "x": -1,
      "y": 9,
      "z": -3,
      "name": "Wood_Oak_Branch_Corner",
      "rotation": 9
    },
    {
      "x": -1,
      "y": 6,
      "z": -2,
      "name": "Soil_Dirt"
    },
    {
      "x": -1,
      "y": 7,
      "z": -2,
      "name": "Soil_Dirt"
    },
    {
      "x": -1,
      "y": 8,
      "z": -2,
      "name": "Soil_Grass_Deep"
    },
    {
      "x": -1,
      "y": 9,
      "z": -2,
      "name": "Plant_Grass_Sharp"
    },
    {
      "x": -1,
      "y": 6,
      "z": -1,
      "name": "Soil_Dirt"
    },
    {
      "x": -1,
      "y": 7,
      "z": -1,
      "name": "Soil_Dirt"
    },
    {
      "x": -1,
      "y": 8,
      "z": -1,
      "name": "Soil_Grass_Deep"
    },
    {
      "x": -1,
      "y": 9,
      "z": -1,
      "name": "Furniture_Kweebec_Shelf",
      "rotation": 3
    },
    {
      "x": -1,
      "y": 12,
      "z": -1,
      "name": "Wood_Oak_Branch_Long",
      "rotation": 4
    },
    {
      "x": -1,
      "y": 13,
      "z": -1,
      "name": "Furniture_Kweebec_Platform"
    },
    {
      "x": -1,
      "y": 14,
      "z": -1,
      "name": "Plant_Moss_Rug_Green"
    },
    {
      "x": -1,
      "y": 5,
      "z": 0,
      "name": "Soil_Dirt"
    },
    {
      "x": -1,
      "y": 6,
      "z": 0,
      "name": "Soil_Dirt"
    },
    {
      "x": -1,
      "y": 7,
      "z": 0,
      "name": "Wood_Oak_Trunk"
    },
    {
      "x": -1,
      "y": 8,
      "z": 0,
      "name": "Wood_Oak_Trunk"
    },
    {
      "x": -1,
      "y": 9,
      "z": 0,
      "name": "Wood_Oak_Trunk"
    },
    {
      "x": -1,
      "y": 10,
      "z": 0,
      "name": "Wood_Oak_Trunk"
    },
    {
      "x": -1,
      "y": 11,
      "z": 0,
      "name": "Wood_Oak_Trunk"
    },
    {
      "x": -1,
      "y": 12,
      "z": 0,
      "name": "Wood_Oak_Trunk"
    },
    {
      "x": -1,
      "y": 13,
      "z": 0,
      "name": "Wood_Oak_Trunk_Full"
    },
    {
      "x": -1,
      "y": 14,
      "z": 0,
      "name": "Plant_Moss_Rug_Green"
    },
    {
      "x": -1,
      "y": 5,
      "z": 1,
      "name": "Soil_Dirt"
    },
    {
      "x": -1,
      "y": 6,
      "z": 1,
      "name": "Soil_Dirt"
    },
    {
      "x": -1,
      "y": 7,
      "z": 1,
      "name": "Wood_Oak_Trunk",
      "rotation": 4
    },
    {
      "x": -1,
      "y": 8,
      "z": 1,
      "name": "Soil_Grass_Deep"
    },
    {
      "x": -1,
      "y": 9,
      "z": 1,
      "name": "Plant_Grass_Sharp"
    },
    {
      "x": -1,
      "y": 13,
      "z": 1,
      "name": "Furniture_Kweebec_Platform"
    },
    {
      "x": -1,
      "y": 14,
      "z": 1,
      "name": "Plant_Moss_Rug_Green"
    },
    {
      "x": -1,
      "y": 6,
      "z": 2,
      "name": "Wood_Oak_Trunk_Full"
    },
    {
      "x": -1,
      "y": 7,
      "z": 2,
      "name": "Wood_Oak_Trunk_Full"
    },
    {
      "x": -1,
      "y": 8,
      "z": 2,
      "name": "Soil_Leaves"
    },
    {
      "x": -1,
      "y": 9,
      "z": 2,
      "name": "Wood_Oak_Branch_Corner",
      "rotation": 3
    },
    {
      "x": -1,
      "y": 10,
      "z": 2,
      "name": "Plant_Flower_Bushy_Green",
      "components": {
        "Components": {
          "FarmingBlock": {}
        }
      }
    },
    {
      "x": -1,
      "y": 13,
      "z": 2,
      "name": "Furniture_Kweebec_Platform"
    },
    {
      "x": -1,
      "y": 6,
      "z": 3,
      "name": "Wood_Oak_Trunk_Full"
    },
    {
      "x": -1,
      "y": 7,
      "z": 3,
      "name": "Soil_Dirt"
    },
    {
      "x": -1,
      "y": 8,
      "z": 3,
      "name": "Soil_Leaves"
    },
    {
      "x": 0,
      "y": 7,
      "z": -3,
      "name": "Soil_Dirt"
    },
    {
      "x": 0,
      "y": 8,
      "z": -3,
      "name": "Soil_Dirt"
    },
    {
      "x": 0,
      "y": 9,
      "z": -3,
      "name": "Wood_Oak_Trunk",
      "rotation": 4
    },
    {
      "x": 0,
      "y": 5,
      "z": -2,
      "name": "Soil_Dirt"
    },
    {
      "x": 0,
      "y": 6,
      "z": -2,
      "name": "Soil_Dirt"
    },
    {
      "x": 0,
      "y": 7,
      "z": -2,
      "name": "Soil_Dirt"
    },
    {
      "x": 0,
      "y": 8,
      "z": -2,
      "name": "Soil_Dirt"
    },
    {
      "x": 0,
      "y": 9,
      "z": -2,
      "name": "Wood_Oak_Trunk",
      "rotation": 4
    },
    {
      "x": 0,
      "y": 10,
      "z": -2,
      "name": "*Plant_Crop_Pumpkin_Block_State_Definitions_StageFinal"
    },
    {
      "x": 0,
      "y": 5,
      "z": -1,
      "name": "Soil_Dirt"
    },
    {
      "x": 0,
      "y": 6,
      "z": -1,
      "name": "Soil_Dirt"
    },
    {
      "x": 0,
      "y": 7,
      "z": -1,
      "name": "Soil_Dirt"
    },
    {
      "x": 0,
      "y": 8,
      "z": -1,
      "name": "Soil_Dirt"
    },
    {
      "x": 0,
      "y": 9,
      "z": -1,
      "name": "Wood_Oak_Trunk",
      "rotation": 4
    },
    {
      "x": 0,
      "y": 10,
      "z": -1,
      "name": "*Plant_Crop_Pumpkin_Block_State_Definitions_Stage2",
      "components": {
        "Components": {
          "FarmingBlock": {
            "GrowthProgress": 2.0,
            "LastTickGameTime": "0001-01-01T12:00:00Z"
          }
        }
      }
    },
    {
      "x": 0,
      "y": 13,
      "z": -1,
      "name": "Furniture_Kweebec_Platform"
    },
    {
      "x": 0,
      "y": 5,
      "z": 0,
      "name": "Soil_Dirt"
    },
    {
      "x": 0,
      "y": 6,
      "z": 0,
      "name": "Soil_Dirt"
    },
    {
      "x": 0,
      "y": 7,
      "z": 0,
      "name": "Soil_Dirt"
    },
    {
      "x": 0,
      "y": 8,
      "z": 0,
      "name": "Soil_Dirt"
    },
    {
      "x": 0,
      "y": 9,
      "z": 0,
      "name": "Wood_Oak_Trunk",
      "rotation": 4
    },
    {
      "x": 0,
      "y": 13,
      "z": 0,
      "name": "Furniture_Kweebec_Platform"
    },
    {
      "x": 0,
      "y": 14,
      "z": 0,
      "name": "Plant_Moss_Rug_Green"
    },
    {
      "x": 0,
      "y": 5,
      "z": 1,
      "name": "Soil_Dirt"
    },
    {
      "x": 0,
      "y": 6,
      "z": 1,
      "name": "Soil_Dirt"
    },
    {
      "x": 0,
      "y": 7,
      "z": 1,
      "name": "Soil_Dirt"
    },
    {
      "x": 0,
      "y": 8,
      "z": 1,
      "name": "Soil_Dirt"
    },
    {
      "x": 0,
      "y": 9,
      "z": 1,
      "name": "Soil_Clay_Brick_Half"
    },
    {
      "x": 0,
      "y": 13,
      "z": 1,
      "name": "Furniture_Kweebec_Platform"
    },
    {
      "x": 0,
      "y": 14,
      "z": 1,
      "name": "Plant_Moss_Rug_Green"
    },
    {
      "x": 0,
      "y": 5,
      "z": 2,
      "name": "Soil_Dirt"
    },
    {
      "x": 0,
      "y": 6,
      "z": 2,
      "name": "Soil_Dirt"
    },
    {
      "x": 0,
      "y": 7,
      "z": 2,
      "name": "Soil_Dirt"
    },
    {
      "x": 0,
      "y": 8,
      "z": 2,
      "name": "Soil_Dirt"
    },
    {
      "x": 0,
      "y": 9,
      "z": 2,
      "name": "Wood_Oak_Trunk",
      "rotation": 5
    },
    {
      "x": 0,
      "y": 13,
      "z": 2,
      "name": "Furniture_Kweebec_Platform"
    },
    {
      "x": 0,
      "y": 6,
      "z": 3,
      "name": "Soil_Dirt"
    },
    {
      "x": 0,
      "y": 7,
      "z": 3,
      "name": "Soil_Dirt"
    },
    {
      "x": 0,
      "y": 8,
      "z": 3,
      "name": "Soil_Leaves"
    },
    {
      "x": 0,
      "y": 9,
      "z": 3,
      "name": "Plant_Grass_Sharp"
    },
    {
      "x": 1,
      "y": 7,
      "z": -3,
      "name": "Soil_Dirt"
    },
    {
      "x": 1,
      "y": 8,
      "z": -3,
      "name": "Soil_Leaves"
    },
    {
      "x": 1,
      "y": 9,
      "z": -3,
      "name": "Furniture_Kweebec_Shelf",
      "rotation": 2
    },
    {
      "x": 1,
      "y": 5,
      "z": -2,
      "name": "Soil_Dirt"
    },
    {
      "x": 1,
      "y": 6,
      "z": -2,
      "name": "Soil_Dirt"
    },
    {
      "x": 1,
      "y": 7,
      "z": -2,
      "name": "Soil_Dirt"
    },
    {
      "x": 1,
      "y": 8,
      "z": -2,
      "name": "Soil_Dirt"
    },
    {
      "x": 1,
      "y": 9,
      "z": -2,
      "name": "Wood_Oak_Trunk",
      "rotation": 5
    },
    {
      "x": 1,
      "y": 5,
      "z": -1,
      "name": "Soil_Dirt"
    },
    {
      "x": 1,
      "y": 6,
      "z": -1,
      "name": "Soil_Dirt"
    },
    {
      "x": 1,
      "y": 7,
      "z": -1,
      "name": "Soil_Dirt"
    },
    {
      "x": 1,
      "y": 8,
      "z": -1,
      "name": "Soil_Dirt"
    },
    {
      "x": 1,
      "y": 9,
      "z": -1,
      "name": "Soil_Clay_Brick_Half"
    },
    {
      "x": 1,
      "y": 5,
      "z": 0,
      "name": "Soil_Dirt"
    },
    {
      "x": 1,
      "y": 6,
      "z": 0,
      "name": "Soil_Dirt"
    },
    {
      "x": 1,
      "y": 7,
      "z": 0,
      "name": "Soil_Dirt"
    },
    {
      "x": 1,
      "y": 8,
      "z": 0,
      "name": "Soil_Dirt"
    },
    {
      "x": 1,
      "y": 9,
      "z": 0,
      "name": "Soil_Clay_Brick_Half"
    },
    {
      "x": 1,
      "y": 13,
      "z": 0,
      "name": "Furniture_Kweebec_Platform"
    },
    {
      "x": 1,
      "y": 5,
      "z": 1,
      "name": "Soil_Dirt"
    },
    {
      "x": 1,
      "y": 6,
      "z": 1,
      "name": "Soil_Dirt"
    },
    {
      "x": 1,
      "y": 7,
      "z": 1,
      "name": "Soil_Dirt"
    },
    {
      "x": 1,
      "y": 8,
      "z": 1,
      "name": "Soil_Dirt"
    },
    {
      "x": 1,
      "y": 9,
      "z": 1,
      "name": "Soil_Clay_Brick_Half"
    },
    {
      "x": 1,
      "y": 13,
      "z": 1,
      "name": "Furniture_Kweebec_Platform"
    },
    {
      "x": 1,
      "y": 14,
      "z": 1,
      "name": "Plant_Moss_Rug_Green"
    },
    {
      "x": 1,
      "y": 5,
      "z": 2,
      "name": "Soil_Dirt"
    },
    {
      "x": 1,
      "y": 6,
      "z": 2,
      "name": "Soil_Dirt"
    },
    {
      "x": 1,
      "y": 7,
      "z": 2,
      "name": "Soil_Dirt"
    },
    {
      "x": 1,
      "y": 8,
      "z": 2,
      "name": "Soil_Dirt"
    },
    {
      "x": 1,
      "y": 9,
      "z": 2,
      "name": "Wood_Oak_Trunk",
      "rotation": 5
    },
    {
      "x": 1,
      "y": 10,
      "z": 2,
      "name": "*Plant_Crop_Pumpkin_Block_State_Definitions_Stage2",
      "components": {
        "Components": {
          "FarmingBlock": {
            "GrowthProgress": 2.0,
            "LastTickGameTime": "0001-01-01T12:00:00Z"
          }
        }
      }
    },
    {
      "x": 1,
      "y": 13,
      "z": 2,
      "name": "Furniture_Kweebec_Platform"
    },
    {
      "x": 1,
      "y": 6,
      "z": 3,
      "name": "Soil_Dirt"
    },
    {
      "x": 1,
      "y": 7,
      "z": 3,
      "name": "Soil_Dirt"
    },
    {
      "x": 1,
      "y": 8,
      "z": 3,
      "name": "Soil_Grass_Deep"
    },
    {
      "x": 1,
      "y": 9,
      "z": 3,
      "name": "Furniture_Kweebec_Shelf"
    },
    {
      "x": 1,
      "y": 13,
      "z": 3,
      "name": "Furniture_Kweebec_Platform"
    },
    {
      "x": 2,
      "y": 6,
      "z": -3,
      "name": "Soil_Dirt"
    },
    {
      "x": 2,
      "y": 7,
      "z": -3,
      "name": "Soil_Dirt"
    },
    {
      "x": 2,
      "y": 8,
      "z": -3,
      "name": "Soil_Leaves"
    },
    {
      "x": 2,
      "y": 9,
      "z": -3,
      "name": "Furniture_Kweebec_Shelf",
      "rotation": 2
    },
    {
      "x": 2,
      "y": 5,
      "z": -2,
      "name": "Soil_Dirt"
    },
    {
      "x": 2,
      "y": 6,
      "z": -2,
      "name": "Soil_Dirt"
    },
    {
      "x": 2,
      "y": 7,
      "z": -2,
      "name": "Soil_Dirt"
    },
    {
      "x": 2,
      "y": 8,
      "z": -2,
      "name": "Soil_Dirt"
    },
    {
      "x": 2,
      "y": 9,
      "z": -2,
      "name": "Wood_Oak_Trunk",
      "rotation": 5
    },
    {
      "x": 2,
      "y": 5,
      "z": -1,
      "name": "Soil_Dirt"
    },
    {
      "x": 2,
      "y": 6,
      "z": -1,
      "name": "Soil_Dirt"
    },
    {
      "x": 2,
      "y": 7,
      "z": -1,
      "name": "Soil_Dirt"
    },
    {
      "x": 2,
      "y": 8,
      "z": -1,
      "name": "Soil_Dirt"
    },
    {
      "x": 2,
      "y": 9,
      "z": -1,
      "name": "Soil_Clay_Brick_Half"
    },
    {
      "x": 2,
      "y": 5,
      "z": 0,
      "name": "Soil_Dirt"
    },
    {
      "x": 2,
      "y": 6,
      "z": 0,
      "name": "Soil_Dirt"
    },
    {
      "x": 2,
      "y": 7,
      "z": 0,
      "name": "Soil_Dirt"
    },
    {
      "x": 2,
      "y": 8,
      "z": 0,
      "name": "Soil_Dirt"
    },
    {
      "x": 2,
      "y": 9,
      "z": 0,
      "name": "Block_Spawner_Block",
      "components": {
        "Components": {
          "BlockSpawner": {
            "BlockSpawnerId": "Zone1_Kweebec_Tier1"
          }
        }
      },
      "rotation": 1
    },
    {
      "x": 2,
      "y": 13,
      "z": 0,
      "name": "Furniture_Kweebec_Platform"
    },
    {
      "x": 2,
      "y": 5,
      "z": 1,
      "name": "Soil_Dirt"
    },
    {
      "x": 2,
      "y": 6,
      "z": 1,
      "name": "Soil_Dirt"
    },
    {
      "x": 2,
      "y": 7,
      "z": 1,
      "name": "Soil_Dirt"
    },
    {
      "x": 2,
      "y": 8,
      "z": 1,
      "name": "Soil_Dirt"
    },
    {
      "x": 2,
      "y": 9,
      "z": 1,
      "name": "Soil_Clay_Brick_Half"
    },
    {
      "x": 2,
      "y": 13,
      "z": 1,
      "name": "Furniture_Kweebec_Platform"
    },
    {
      "x": 2,
      "y": 5,
      "z": 2,
      "name": "Soil_Dirt"
    },
    {
      "x": 2,
      "y": 6,
      "z": 2,
      "name": "Soil_Dirt"
    },
    {
      "x": 2,
      "y": 7,
      "z": 2,
      "name": "Soil_Dirt"
    },
    {
      "x": 2,
      "y": 8,
      "z": 2,
      "name": "Soil_Dirt"
    },
    {
      "x": 2,
      "y": 9,
      "z": 2,
      "name": "Wood_Oak_Trunk",
      "rotation": 5
    },
    {
      "x": 2,
      "y": 10,
      "z": 2,
      "name": "*Plant_Crop_Pumpkin_Block_State_Definitions_Stage2",
      "components": {
        "Components": {
          "FarmingBlock": {
            "GrowthProgress": 2.0,
            "LastTickGameTime": "0001-01-01T12:00:00Z"
          }
        }
      }
    },
    {
      "x": 2,
      "y": 13,
      "z": 2,
      "name": "Furniture_Kweebec_Platform"
    },
    {
      "x": 2,
      "y": 7,
      "z": 3,
      "name": "Soil_Dirt"
    },
    {
      "x": 2,
      "y": 8,
      "z": 3,
      "name": "Soil_Grass_Deep"
    },
    {
      "x": 2,
      "y": 9,
      "z": 3,
      "name": "Furniture_Kweebec_Shelf"
    },
    {
      "x": 2,
      "y": 13,
      "z": 3,
      "name": "Furniture_Kweebec_Platform"
    },
    {
      "x": 2,
      "y": 14,
      "z": 3,
      "name": "Plant_Moss_Rug_Green"
    },
    {
      "x": 3,
      "y": 6,
      "z": -3,
      "name": "Soil_Dirt"
    },
    {
      "x": 3,
      "y": 7,
      "z": -3,
      "name": "Soil_Dirt"
    },
    {
      "x": 3,
      "y": 8,
      "z": -3,
      "name": "Soil_Grass_Deep"
    },
    {
      "x": 3,
      "y": 9,
      "z": -3,
      "name": "Plant_Grass_Sharp"
    },
    {
      "x": 3,
      "y": 13,
      "z": -3,
      "name": "Furniture_Kweebec_Lantern"
    },
    {
      "x": 3,
      "y": 14,
      "z": -3,
      "name": "Wood_Oak_Branch_Corner",
      "rotation": 8
    },
    {
      "x": 3,
      "y": 6,
      "z": -2,
      "name": "Soil_Dirt"
    },
    {
      "x": 3,
      "y": 7,
      "z": -2,
      "name": "Soil_Dirt"
    },
    {
      "x": 3,
      "y": 8,
      "z": -2,
      "name": "Soil_Dirt"
    },
    {
      "x": 3,
      "y": 9,
      "z": -2,
      "name": "Wood_Oak_Trunk",
      "rotation": 5
    },
    {
      "x": 3,
      "y": 10,
      "z": -2,
      "name": "*Plant_Crop_Pumpkin_Block_State_Definitions_Stage2",
      "components": {
        "Components": {
          "FarmingBlock": {
            "GrowthProgress": 2.0,
            "LastTickGameTime": "0001-01-01T12:00:00Z"
          }
        }
      }
    },
    {
      "x": 3,
      "y": 13,
      "z": -2,
      "name": "Wood_Oak_Branch_Corner",
      "rotation": 3
    },
    {
      "x": 3,
      "y": 14,
      "z": -2,
      "name": "Wood_Oak_Branch_Corner",
      "rotation": 10
    },
    {
      "x": 3,
      "y": 5,
      "z": -1,
      "name": "Soil_Dirt"
    },
    {
      "x": 3,
      "y": 6,
      "z": -1,
      "name": "Soil_Dirt"
    },
    {
      "x": 3,
      "y": 7,
      "z": -1,
      "name": "Soil_Dirt"
    },
    {
      "x": 3,
      "y": 8,
      "z": -1,
      "name": "Soil_Dirt"
    },
    {
      "x": 3,
      "y": 9,
      "z": -1,
      "name": "Soil_Clay_Brick_Half"
    },
    {
      "x": 3,
      "y": 5,
      "z": 0,
      "name": "Soil_Dirt"
    },
    {
      "x": 3,
      "y": 6,
      "z": 0,
      "name": "Soil_Dirt"
    },
    {
      "x": 3,
      "y": 7,
      "z": 0,
      "name": "Soil_Dirt"
    },
    {
      "x": 3,
      "y": 8,
      "z": 0,
      "name": "Soil_Dirt"
    },
    {
      "x": 3,
      "y": 9,
      "z": 0,
      "name": "Soil_Clay_Brick_Half"
    },
    {
      "x": 3,
      "y": 5,
      "z": 1,
      "name": "Soil_Dirt"
    },
    {
      "x": 3,
      "y": 6,
      "z": 1,
      "name": "Soil_Dirt"
    },
    {
      "x": 3,
      "y": 7,
      "z": 1,
      "name": "Soil_Dirt"
    },
    {
      "x": 3,
      "y": 8,
      "z": 1,
      "name": "Soil_Dirt"
    },
    {
      "x": 3,
      "y": 9,
      "z": 1,
      "name": "Soil_Clay_Brick_Half"
    },
    {
      "x": 3,
      "y": 6,
      "z": 2,
      "name": "Soil_Dirt"
    },
    {
      "x": 3,
      "y": 7,
      "z": 2,
      "name": "Soil_Dirt"
    },
    {
      "x": 3,
      "y": 8,
      "z": 2,
      "name": "Soil_Dirt"
    },
    {
      "x": 3,
      "y": 9,
      "z": 2,
      "name": "Soil_Clay_Brick_Half"
    },
    {
      "x": 3,
      "y": 12,
      "z": 2,
      "name": "Wood_Oak_Trunk_Full"
    },
    {
      "x": 3,
      "y": 13,
      "z": 2,
      "name": "Wood_Oak_Trunk"
    },
    {
      "x": 3,
      "y": 14,
      "z": 2,
      "name": "Wood_Oak_Trunk"
    },
    {
      "x": 3,
      "y": 7,
      "z": 3,
      "name": "Wood_Oak_Trunk"
    },
    {
      "x": 3,
      "y": 8,
      "z": 3,
      "name": "Wood_Oak_Trunk"
    },
    {
      "x": 3,
      "y": 9,
      "z": 3,
      "name": "Wood_Oak_Trunk"
    },
    {
      "x": 3,
      "y": 10,
      "z": 3,
      "name": "Wood_Oak_Trunk"
    },
    {
      "x": 3,
      "y": 11,
      "z": 3,
      "name": "Wood_Oak_Trunk"
    },
    {
      "x": 3,
      "y": 12,
      "z": 3,
      "name": "Wood_Oak_Trunk_Full"
    },
    {
      "x": 4,
      "y": 7,
      "z": -3,
      "name": "Soil_Dirt"
    },
    {
      "x": 4,
      "y": 8,
      "z": -3,
      "name": "Soil_Grass_Deep"
    },
    {
      "x": 4,
      "y": 9,
      "z": -3,
      "name": "Wood_Oak_Branch_Short",
      "rotation": 2
    },
    {
      "x": 4,
      "y": 6,
      "z": -2,
      "name": "Soil_Dirt"
    },
    {
      "x": 4,
      "y": 7,
      "z": -2,
      "name": "Soil_Dirt"
    },
    {
      "x": 4,
      "y": 8,
      "z": -2,
      "name": "Soil_Dirt"
    },
    {
      "x": 4,
      "y": 9,
      "z": -2,
      "name": "Wood_Oak_Trunk_Full"
    },
    {
      "x": 4,
      "y": 10,
      "z": -2,
      "name": "Wood_Oak_Trunk_Full"
    },
    {
      "x": 4,
      "y": 11,
      "z": -2,
      "name": "Wood_Oak_Branch_Long"
    },
    {
      "x": 4,
      "y": 12,
      "z": -2,
      "name": "Wood_Oak_Branch_Long"
    },
    {
      "x": 4,
      "y": 13,
      "z": -2,
      "name": "Wood_Oak_Branch_Corner",
      "rotation": 11
    },
    {
      "x": 4,
      "y": 6,
      "z": -1,
      "name": "Soil_Dirt"
    },
    {
      "x": 4,
      "y": 7,
      "z": -1,
      "name": "Soil_Dirt"
    },
    {
      "x": 4,
      "y": 8,
      "z": -1,
      "name": "Soil_Dirt"
    },
    {
      "x": 4,
      "y": 9,
      "z": -1,
      "name": "Wood_Oak_Trunk",
      "rotation": 4
    },
    {
      "x": 4,
      "y": 10,
      "z": -1,
      "name": "Wood_Oak_Branch_Corner"
    },
    {
      "x": 4,
      "y": 11,
      "z": -1,
      "name": "Wood_Oak_Branch_Long"
    },
    {
      "x": 4,
      "y": 12,
      "z": -1,
      "name": "Plant_Flower_Bushy_Green",
      "components": {
        "Components": {
          "FarmingBlock": {}
        }
      }
    },
    {
      "x": 4,
      "y": 6,
      "z": 0,
      "name": "Soil_Dirt"
    },
    {
      "x": 4,
      "y": 7,
      "z": 0,
      "name": "Soil_Dirt"
    },
    {
      "x": 4,
      "y": 8,
      "z": 0,
      "name": "Soil_Dirt"
    },
    {
      "x": 4,
      "y": 9,
      "z": 0,
      "name": "Soil_Clay_Brick_Half"
    },
    {
      "x": 4,
      "y": 7,
      "z": 1,
      "name": "Soil_Dirt"
    },
    {
      "x": 4,
      "y": 8,
      "z": 1,
      "name": "Soil_Leaves"
    },
    {
      "x": 4,
      "y": 7,
      "z": 2,
      "name": "Soil_Dirt"
    },
    {
      "x": 4,
      "y": 8,
      "z": 2,
      "name": "Soil_Leaves"
    },
    {
      "x": 4,
      "y": 8,
      "z": 3,
      "name": "Soil_Leaves"
    },
    {
      "x": 4,
      "y": 9,
      "z": 3,
      "name": "Plant_Grass_Sharp_Tall"
    },
    {
      "x": 4,
      "y": 10,
      "z": 3,
      "name": "Plant_Grass_Sharp_Tall",
      "filler": 1024
    },
    {
      "x": 4,
      "y": 12,
      "z": 3,
      "name": "Wood_Oak_Branch_Corner",
      "rotation": 1
    },
    {
      "x": 5,
      "y": 8,
      "z": 0,
      "name": "Soil_Leaves"
    },
    {
      "x": 5,
      "y": 9,
      "z": 0,
      "name": "Plant_Grass_Sharp_Tall"
    },
    {
      "x": 5,
      "y": 10,
      "z": 0,
      "name": "Plant_Grass_Sharp_Tall",
      "filler": 1024
    },
    {
      "x": 5,
      "y": 8,
      "z": 1,
      "name": "Soil_Leaves"
    },
    {
      "x": 5,
      "y": 9,
      "z": 1,
      "name": "Plant_Grass_Sharp"
    }
  ],
  "entities": [
    {
      "Components": {
        "Nameplate": {
          "Text": "Kweebec_Merchant"
        },
        "HiddenFromAdventurePlayer": {},
        "SpawnMarkerComponent": {
          "SpawnMarker": "Kweebec_Merchant",
          "RespawnTime": 0.0,
          "SpawnCount": 0,
          "PersistedFlock": {},
          "SpawnPosition": {
            "X": 0.0,
            "Y": 0.0,
            "Z": 0.0
          }
        },
        "Transform": {
          "Position": {
            "X": 4.709053039550781,
            "Y": 9.209564208984375,
            "Z": 1.8409423828125
          },
          "Rotation": {
            "Pitch": 0.0,
            "Yaw": -1.5042080879211426,
            "Roll": 0.0
          }
        },
        "Intangible": {},
        "Model": {
          "Model": {
            "Id": "NPC_Spawn_Marker",
            "Scale": 1.0,
            "Static": false
          }
        },
        "UUID": {
          "UUID": {
            "$binary": "MEZ05JCQNa+bngIaYZ81fw==",
            "$type": "04"
          }
        }
      }
    }
  ]
}