{
  "version": 8,
  "blockIdVersion": 8,
  "anchorX": 1,
  "anchorY": 6,
  "anchorZ": 1,
  "blocks": [
    {
      "x": -3,
      "y": 11,
      "z": -4,
      "name": "Wood_Deadwood_Planks_Half",
      "rotation": 8
    },
    {
      "x": -3,
      "y": 11,
      "z": -3,
      "name": "Wood_Deadwood_Stairs",
      "rotation": 8
    },
    {
      "x": -3,
      "y": 11,
      "z": -2,
      "name": "Wood_Deadwood_Planks_Half"
    },
    {
      "x": -3,
      "y": 9,
      "z": -1,
      "name": "Wood_Deadwood_Planks_Half",
      "rotation": 6
    },
    {
      "x": -3,
      "y": 10,
      "z": -1,
      "name": "Wood_Deadwood_Planks_Half"
    },
    {
      "x": -3,
      "y": 0,
      "z": 0,
      "name": "Wood_Ash_Branch_Long"
    },
    {
      "x": -3,
      "y": 1,
      "z": 0,
      "name": "Wood_Ash_Branch_Long"
    },
    {
      "x": -3,
      "y": 2,
      "z": 0,
      "name": "Wood_Ash_Branch_Long"
    },
    {
      "x": -3,
      "y": 3,
      "z": 0,
      "name": "Wood_Ash_Branch_Long"
    },
    {
      "x": -3,
      "y": 4,
      "z": 0,
      "name": "Wood_Ash_Branch_Long"
    },
    {
      "x": -3,
      "y": 5,
      "z": 0,
      "name": "Wood_Ash_Branch_Long"
    },
    {
      "x": -3,
      "y": 6,
      "z": 0,
      "name": "Wood_Ash_Branch_Long"
    },
    {
      "x": -3,
      "y": 7,
      "z": 0,
      "name": "Wood_Ash_Branch_Long"
    },
    {
      "x": -3,
      "y": 8,
      "z": 0,
      "name": "Wood_Deadwood_Stairs",
      "rotation": 8
    },
    {
      "x": -3,
      "y": 9,
      "z": 0,
      "name": "Wood_Deadwood_Stairs"
    },
    {
      "x": -3,
      "y": 0,
      "z": 1,
      "name": "Wood_Ash_Branch_Long"
    },
    {
      "x": -3,
      "y": 1,
      "z": 1,
      "name": "Wood_Ash_Branch_Long"
    },
    {
      "x": -3,
      "y": 2,
      "z": 1,
      "name": "Wood_Ash_Branch_Long"
    },
    {
      "x": -3,
      "y": 3,
      "z": 1,
      "name": "Wood_Ash_Branch_Long"
    },
    {
      "x": -3,
      "y": 4,
      "z": 1,
      "name": "Wood_Ash_Branch_Long"
    },
    {
      "x": -3,
      "y": 5,
      "z": 1,
      "name": "Wood_Ash_Branch_Long"
    },
    {
      "x": -3,
      "y": 6,
      "z": 1,
      "name": "Wood_Ash_Branch_Long"
    },
    {
      "x": -3,
      "y": 7,
      "z": 1,
      "name": "Wood_Ash_Branch_Long"
    },
    {
      "x": -3,
      "y": 8,
      "z": 1,
      "name": "Wood_Deadwood_Planks"
    },
    {
      "x": -2,
      "y": 11,
      "z": -5,
      "name": "Plant_Moss_Wall_Yellow",
      "rotation": 2
    },
    {
      "x": -2,
      "y": 11,
      "z": -4,
      "name": "Wood_Deadwood_Planks_Half",
      "rotation": 8
    },
    {
      "x": -2,
      "y": 6,
      "z": -3,
      "name": "Wood_Deadwood_Planks_Half",
      "rotation": 8
    },
    {
      "x": -2,
      "y": 11,
      "z": -3,
      "name": "Wood_Deadwood_Planks_Half",
      "rotation": 8
    },
    {
      "x": -2,
      "y": 12,
      "z": -3,
      "name": "Plant_Bush_Dead_Tall"
    },
    {
      "x": -2,
      "y": 6,
      "z": -2,
      "name": "Wood_Deadwood_Planks_Half",
      "rotation": 8
    },
    {
      "x": -2,
      "y": 7,
      "z": -2,
      "name": "Wood_Deadwood_Planks_Half"
    },
    {
      "x": -2,
      "y": 11,
      "z": -2,
      "name": "Wood_Deadwood_Stairs",
      "rotation": 9
    },
    {
      "x": -2,
      "y": 12,
      "z": -2,
      "name": "Wood_Deadwood_Roof_Steep",
      "rotation": 3
    },
    {
      "x": -2,
      "y": 13,
      "z": -2,
      "name": "Wood_Deadwood_Roof_Steep",
      "filler": 1024,
      "rotation": 3
    },
    {
      "x": -2,
      "y": 7,
      "z": -1,
      "name": "Wood_Deadwood_Stairs"
    },
    {
      "x": -2,
      "y": 11,
      "z": -1,
      "name": "Wood_Deadwood_Planks_Half",
      "rotation": 8
    },
    {
      "x": -2,
      "y": 12,
      "z": -1,
      "name": "Wood_Deadwood_Roof_Steep",
      "rotation": 3
    },
    {
      "x": -2,
      "y": 13,
      "z": -1,
      "name": "Wood_Deadwood_Roof_Steep",
      "filler": 1024,
      "rotation": 3
    },
    {
      "x": -2,
      "y": 8,
      "z": 0,
      "name": "Wood_Deadwood_Stairs",
      "rotation": 2
    },
    {
      "x": -2,
      "y": 11,
      "z": 0,
      "name": "Wood_Deadwood_Planks_Half",
      "rotation": 8
    },
    {
      "x": -2,
      "y": 12,
      "z": 0,
      "name": "Wood_Deadwood_Roof_Steep",
      "rotation": 3
    },
    {
      "x": -2,
      "y": 13,
      "z": 0,
      "name": "Wood_Deadwood_Roof_Steep",
      "filler": 1024,
      "rotation": 3
    },
    {
      "x": -2,
      "y": 0,
      "z": 1,
      "name": "Wood_Ash_Branch_Long"
    },
    {
      "x": -2,
      "y": 1,
      "z": 1,
      "name": "Wood_Ash_Branch_Long"
    },
    {
      "x": -2,
      "y": 2,
      "z": 1,
      "name": "Wood_Ash_Branch_Long"
    },
    {
      "x": -2,
      "y": 3,
      "z": 1,
      "name": "Wood_Ash_Branch_Long"
    },
    {
      "x": -2,
      "y": 4,
      "z": 1,
      "name": "Wood_Ash_Branch_Long"
    },
    {
      "x": -2,
      "y": 5,
      "z": 1,
      "name": "Wood_Ash_Branch_Long"
    },
    {
      "x": -2,
      "y": 6,
      "z": 1,
      "name": "Wood_Ash_Branch_Long"
    },
    {
      "x": -2,
      "y": 7,
      "z": 1,
      "name": "Wood_Ash_Branch_Long"
    },
    {
      "x": -2,
      "y": 8,
      "z": 1,
      "name": "Wood_Deadwood_Planks"
    },
    {
      "x": -2,
      "y": 11,
      "z": 1,
      "name": "Wood_Deadwood_Stairs",
      "rotation": 9
    },
    {
      "x": -2,
      "y": 12,
      "z": 1,
      "name": "Wood_Deadwood_Roof_Steep",
      "rotation": 3
    },
    {
      "x": -2,
      "y": 13,
      "z": 1,
      "name": "Wood_Deadwood_Roof_Steep",
      "filler": 1024,
      "rotation": 3
    },
    {
      "x": -2,
      "y": 11,
      "z": 2,
      "name": "Wood_Deadwood_Planks_Half",
      "rotation": 8
    },
    {
      "x": -2,
      "y": 12,
      "z": 2,
      "name": "Wood_Deadwood_Roof_Steep",
      "rotation": 3
    },
    {
      "x": -2,
      "y": 13,
      "z": 2,
      "name": "Wood_Deadwood_Roof_Steep",
      "filler": 1024,
      "rotation": 3
    },
    {
      "x": -2,
      "y": 11,
      "z": 3,
      "name": "Wood_Deadwood_Planks_Half",
      "rotation": 8
    },
    {
      "x": -2,
      "y": 12,
      "z": 3,
      "name": "Wood_Deadwood_Roof_Steep",
      "rotation": 3
    },
    {
      "x": -2,
      "y": 13,
      "z": 3,
      "name": "Wood_Deadwood_Roof_Steep",
      "filler": 1024,
      "rotation": 3
    },
    {
      "x": -2,
      "y": 11,
      "z": 4,
      "name": "Wood_Deadwood_Stairs",
      "rotation": 9
    },
    {
      "x": -2,
      "y": 12,
      "z": 4,
      "name": "Wood_Deadwood_Roof_Steep",
      "rotation": 3
    },
    {
      "x": -2,
      "y": 13,
      "z": 4,
      "name": "Wood_Deadwood_Roof_Steep",
      "filler": 1024,
      "rotation": 3
    },
    {
      "x": -2,
      "y": 11,
      "z": 5,
      "name": "Wood_Deadwood_Planks_Half",
      "rotation": 8
    },
    {
      "x": -1,
      "y": 11,
      "z": -4,
      "name": "Wood_Deadwood_Planks_Half",
      "rotation": 8
    },
    {
      "x": -1,
      "y": 11,
      "z": -3,
      "name": "Wood_Deadwood_Stairs",
      "rotation": 8
    },
    {
      "x": -1,
      "y": 0,
      "z": -2,
      "name": "Wood_Ash_Trunk"
    },
    {
      "x": -1,
      "y": 1,
      "z": -2,
      "name": "Wood_Ash_Trunk"
    },
    {
      "x": -1,
      "y": 2,
      "z": -2,
      "name": "Wood_Ash_Trunk"
    },
    {
      "x": -1,
      "y": 3,
      "z": -2,
      "name": "Wood_Ash_Trunk"
    },
    {
      "x": -1,
      "y": 4,
      "z": -2,
      "name": "Wood_Ash_Trunk"
    },
    {
      "x": -1,
      "y": 5,
      "z": -2,
      "name": "Wood_Ash_Trunk"
    },
    {
      "x": -1,
      "y": 6,
      "z": -2,
      "name": "Wood_Ash_Trunk"
    },
    {
      "x": -1,
      "y": 7,
      "z": -2,
      "name": "Wood_Ash_Trunk"
    },
    {
      "x": -1,
      "y": 8,
      "z": -2,
      "name": "Wood_Ash_Trunk"
    },
    {
      "x": -1,
      "y": 9,
      "z": -2,
      "name": "Wood_Ash_Trunk"
    },
    {
      "x": -1,
      "y": 10,
      "z": -2,
      "name": "Wood_Ash_Trunk"
    },
    {
      "x": -1,
      "y": 11,
      "z": -2,
      "name": "Wood_Deadwood_Planks"
    },
    {
      "x": -1,
      "y": 12,
      "z": -2,
      "name": "Wood_Deadwood_Planks"
    },
    {
      "x": -1,
      "y": 13,
      "z": -2,
      "name": "Wood_Deadwood_Planks"
    },
    {
      "x": -1,
      "y": 14,
      "z": -2,
      "name": "Wood_Deadwood_Roof_Steep",
      "rotation": 3
    },
    {
      "x": -1,
      "y": 15,
      "z": -2,
      "name": "Wood_Deadwood_Roof_Steep",
      "filler": 1024,
      "rotation": 3
    },
    {
      "x": -1,
      "y": 9,
      "z": -1,
      "name": "Wood_Ash_Branch_Long",
      "rotation": 4
    },
    {
      "x": -1,
      "y": 11,
      "z": -1,
      "name": "Wood_Deadwood_Planks"
    },
    {
      "x": -1,
      "y": 12,
      "z": -1,
      "name": "Furniture_Ancient_Crate"
    },
    {
      "x": -1,
      "y": 13,
      "z": -1,
      "name": "Wood_Deadwood_Planks_Half",
      "rotation": 8
    },
    {
      "x": -1,
      "y": 14,
      "z": -1,
      "name": "Wood_Deadwood_Roof_Steep",
      "rotation": 3
    },
    {
      "x": -1,
      "y": 15,
      "z": -1,
      "name": "Wood_Deadwood_Roof_Steep",
      "filler": 1024,
      "rotation": 3
    },
    {
      "x": -1,
      "y": 9,
      "z": 0,
      "name": "Wood_Ash_Branch_Long",
      "rotation": 4
    },
    {
      "x": -1,
      "y": 11,
      "z": 0,
      "name": "Wood_Deadwood_Planks"
    },
    {
      "x": -1,
      "y": 12,
      "z": 0,
      "name": "Block_Spawner_Block",
      "components": {
        "Components": {
          "BlockSpawner": {
            "BlockSpawnerId": "Zone4_Encounters_Tier2"
          }
        }
      },
      "rotation": 1
    },
    {
      "x": -1,
      "y": 13,
      "z": 0,
      "name": "Wood_Deadwood_Planks_Half",
      "rotation": 8
    },
    {
      "x": -1,
      "y": 14,
      "z": 0,
      "name": "*Wood_Deadwood_Roof_Steep_State_Definitions_Inverted_Corner_Right",
      "rotation": 3
    },
    {
      "x": -1,
      "y": 15,
      "z": 0,
      "name": "*Wood_Deadwood_Roof_Steep_State_Definitions_Inverted_Corner_Right",
      "filler": 1024,
      "rotation": 3
    },
    {
      "x": -1,
      "y": 0,
      "z": 1,
      "name": "Wood_Ash_Trunk"
    },
    {
      "x": -1,
      "y": 1,
      "z": 1,
      "name": "Wood_Ash_Trunk"
    },
    {
      "x": -1,
      "y": 2,
      "z": 1,
      "name": "Wood_Ash_Trunk"
    },
    {
      "x": -1,
      "y": 3,
      "z": 1,
      "name": "Wood_Ash_Trunk"
    },
    {
      "x": -1,
      "y": 4,
      "z": 1,
      "name": "Wood_Ash_Trunk"
    },
    {
      "x": -1,
      "y": 5,
      "z": 1,
      "name": "Wood_Ash_Trunk"
    },
    {
      "x": -1,
      "y": 6,
      "z": 1,
      "name": "Wood_Ash_Trunk"
    },
    {
      "x": -1,
      "y": 7,
      "z": 1,
      "name": "Wood_Ash_Trunk"
    },
    {
      "x": -1,
      "y": 8,
      "z": 1,
      "name": "Wood_Ash_Trunk"
    },
    {
      "x": -1,
      "y": 9,
      "z": 1,
      "name": "Wood_Ash_Trunk"
    },
    {
      "x": -1,
      "y": 10,
      "z": 1,
      "name": "Wood_Ash_Trunk"
    },
    {
      "x": -1,
      "y": 11,
      "z": 1,
      "name": "Wood_Deadwood_Planks"
    },
    {
      "x": -1,
      "y": 12,
      "z": 1,
      "name": "Furniture_Ancient_Bed",
      "components": {
        "Components": {
          "RespawnBlock": {}
        }
      },
      "filler": 991,
      "rotation": 2
    },
    {
      "x": -1,
      "y": 13,
      "z": 1,
      "name": "Furniture_Ancient_Bed",
      "components": {
        "Components": {
          "RespawnBlock": {}
        }
      },
      "filler": 2015,
      "rotation": 2
    },
    {
      "x": -1,
      "y": 14,
      "z": 1,
      "name": "Furniture_Ancient_Window",
      "rotation": 1
    },
    {
      "x": -1,
      "y": 15,
      "z": 1,
      "name": "Furniture_Ancient_Window",
      "rotation": 1
    },
    {
      "x": -1,
      "y": 16,
      "z": 1,
      "name": "Wood_Deadwood_Roof_Flat",
      "rotation": 1
    },
    {
      "x": -1,
      "y": 8,
      "z": 2,
      "name": "Wood_Ash_Branch_Long",
      "rotation": 4
    },
    {
      "x": -1,
      "y": 10,
      "z": 2,
      "name": "Wood_Ash_Branch_Long",
      "rotation": 4
    },
    {
      "x": -1,
      "y": 11,
      "z": 2,
      "name": "Wood_Deadwood_Planks"
    },
    {
      "x": -1,
      "y": 12,
      "z": 2,
      "name": "Furniture_Ancient_Bed",
      "components": {
        "Components": {
          "RespawnBlock": {}
        }
      },
      "filler": 1023,
      "rotation": 2
    },
    {
      "x": -1,
      "y": 13,
      "z": 2,
      "name": "Furniture_Ancient_Bed",
      "components": {
        "Components": {
          "RespawnBlock": {}
        }
      },
      "filler": 2047,
      "rotation": 2
    },
    {
      "x": -1,
      "y": 14,
      "z": 2,
      "name": "*Wood_Deadwood_Roof_Steep_State_Definitions_Inverted_Corner_Right"
    },
    {
      "x": -1,
      "y": 15,
      "z": 2,
      "name": "*Wood_Deadwood_Roof_Steep_State_Definitions_Inverted_Corner_Right",
      "filler": 1024
    },
    {
      "x": -1,
      "y": 8,
      "z": 3,
      "name": "Wood_Ash_Branch_Long",
      "rotation": 4
    },
    {
      "x": -1,
      "y": 9,
      "z": 3,
      "name": "Plant_Bramble_Dead_Twisted"
    },
    {
      "x": -1,
      "y": 10,
      "z": 3,
      "name": "Wood_Ash_Branch_Long",
      "rotation": 4
    },
    {
      "x": -1,
      "y": 11,
      "z": 3,
      "name": "Wood_Deadwood_Planks"
    },
    {
      "x": -1,
      "y": 12,
      "z": 3,
      "name": "Furniture_Ancient_Bed",
      "components": {
        "Components": {
          "RespawnBlock": {}
        }
      },
      "filler": 31,
      "rotation": 2
    },
    {
      "x": -1,
      "y": 13,
      "z": 3,
      "name": "Furniture_Ancient_Bed",
      "components": {
        "Components": {
          "RespawnBlock": {}
        }
      },
      "filler": 1055,
      "rotation": 2
    },
    {
      "x": -1,
      "y": 14,
      "z": 3,
      "name": "Wood_Deadwood_Roof_Steep",
      "rotation": 3
    },
    {
      "x": -1,
      "y": 15,
      "z": 3,
      "name": "Wood_Deadwood_Roof_Steep",
      "filler": 1024,
      "rotation": 3
    },
    {
      "x": -1,
      "y": 0,
      "z": 4,
      "name": "Wood_Ash_Trunk"
    },
    {
      "x": -1,
      "y": 1,
      "z": 4,
      "name": "Wood_Ash_Trunk"
    },
    {
      "x": -1,
      "y": 2,
      "z": 4,
      "name": "Wood_Ash_Trunk"
    },
    {
      "x": -1,
      "y": 3,
      "z": 4,
      "name": "Wood_Ash_Trunk"
    },
    {
      "x": -1,
      "y": 4,
      "z": 4,
      "name": "Wood_Ash_Trunk"
    },
    {
      "x": -1,
      "y": 5,
      "z": 4,
      "name": "Wood_Ash_Trunk"
    },
    {
      "x": -1,
      "y": 6,
      "z": 4,
      "name": "Wood_Ash_Trunk"
    },
    {
      "x": -1,
      "y": 7,
      "z": 4,
      "name": "Wood_Ash_Trunk"
    },
    {
      "x": -1,
      "y": 8,
      "z": 4,
      "name": "Wood_Ash_Trunk"
    },
    {
      "x": -1,
      "y": 9,
      "z": 4,
      "name": "Wood_Ash_Trunk"
    },
    {
      "x": -1,
      "y": 10,
      "z": 4,
      "name": "Wood_Ash_Trunk"
    },
    {
      "x": -1,
      "y": 11,
      "z": 4,
      "name": "Wood_Deadwood_Planks"
    },
    {
      "x": -1,
      "y": 12,
      "z": 4,
      "name": "Wood_Deadwood_Planks"
    },
    {
      "x": -1,
      "y": 13,
      "z": 4,
      "name": "Wood_Deadwood_Planks"
    },
    {
      "x": -1,
      "y": 14,
      "z": 4,
      "name": "Wood_Deadwood_Roof_Steep",
      "rotation": 3
    },
    {
      "x": -1,
      "y": 15,
      "z": 4,
      "name": "Wood_Deadwood_Roof_Steep",
      "filler": 1024,
      "rotation": 3
    },
    {
      "x": -1,
      "y": 11,
      "z": 5,
      "name": "Wood_Deadwood_Stairs",
      "rotation": 10
    },
    {
      "x": 0,
      "y": 11,
      "z": -4,
      "name": "Wood_Deadwood_Planks_Half",
      "rotation": 8
    },
    {
      "x": 0,
      "y": 11,
      "z": -3,
      "name": "Wood_Deadwood_Planks_Half",
      "rotation": 8
    },
    {
      "x": 0,
      "y": 12,
      "z": -3,
      "name": "Empty"
    },
    {
      "x": 0,
      "y": 13,
      "z": -3,
      "name": "Cloth_Roof_Leather_Flap",
      "rotation": 2
    },
    {
      "x": 0,
      "y": 8,
      "z": -2,
      "name": "Wood_Ash_Branch_Long",
      "rotation": 5
    },
    {
      "x": 0,
      "y": 9,
      "z": -2,
      "name": "Wood_Ash_Branch_Long",
      "rotation": 5
    },
    {
      "x": 0,
      "y": 11,
      "z": -2,
      "name": "Wood_Deadwood_Planks"
    },
    {
      "x": 0,
      "y": 12,
      "z": -2,
      "name": "Wood_Deadwood_Planks_Half",
      "rotation": 5
    },
    {
      "x": 0,
      "y": 13,
      "z": -2,
      "name": "Wood_Deadwood_Planks_Half",
      "rotation": 5
    },
    {
      "x": 0,
      "y": 14,
      "z": -2,
      "name": "Wood_Deadwood_Planks"
    },
    {
      "x": 0,
      "y": 15,
      "z": -2,
      "name": "Wood_Deadwood_Planks"
    },
    {
      "x": 0,
      "y": 16,
      "z": -2,
      "name": "Wood_Deadwood_Roof_Steep",
      "rotation": 3
    },
    {
      "x": 0,
      "y": 17,
      "z": -2,
      "name": "Wood_Deadwood_Roof_Steep",
      "filler": 1024,
      "rotation": 3
    },
    {
      "x": 0,
      "y": 11,
      "z": -1,
      "name": "Wood_Deadwood_Planks"
    },
    {
      "x": 0,
      "y": 12,
      "z": -1,
      "name": "Empty"
    },
    {
      "x": 0,
      "y": 13,
      "z": -1,
      "name": "Empty"
    },
    {
      "x": 0,
      "y": 14,
      "z": -1,
      "name": "Empty"
    },
    {
      "x": 0,
      "y": 15,
      "z": -1,
      "name": "Wood_Deadwood_Planks_Half",
      "rotation": 8
    },
    {
      "x": 0,
      "y": 16,
      "z": -1,
      "name": "Wood_Deadwood_Roof_Steep",
      "rotation": 3
    },
    {
      "x": 0,
      "y": 17,
      "z": -1,
      "name": "Wood_Deadwood_Roof_Steep",
      "filler": 1024,
      "rotation": 3
    },
    {
      "x": 0,
      "y": 11,
      "z": 0,
      "name": "Wood_Deadwood_Planks"
    },
    {
      "x": 0,
      "y": 12,
      "z": 0,
      "name": "Empty"
    },
    {
      "x": 0,
      "y": 13,
      "z": 0,
      "name": "Empty"
    },
    {
      "x": 0,
      "y": 14,
      "z": 0,
      "name": "Empty"
    },
    {
      "x": 0,
      "y": 15,
      "z": 0,
      "name": "Wood_Deadwood_Planks_Half",
      "rotation": 8
    },
    {
      "x": 0,
      "y": 16,
      "z": 0,
      "name": "Wood_Deadwood_Roof_Steep",
      "rotation": 3
    },
    {
      "x": 0,
      "y": 17,
      "z": 0,
      "name": "Wood_Deadwood_Roof_Steep",
      "filler": 1024,
      "rotation": 3
    },
    {
      "x": 0,
      "y": 11,
      "z": 1,
      "name": "Wood_Deadwood_Planks"
    },
    {
      "x": 0,
      "y": 12,
      "z": 1,
      "name": "Furniture_Ancient_Bed",
      "components": {
        "Components": {
          "RespawnBlock": {}
        }
      },
      "filler": 960,
      "rotation": 2
    },
    {
      "x": 0,
      "y": 13,
      "z": 1,
      "name": "Furniture_Ancient_Bed",
      "components": {
        "Components": {
          "RespawnBlock": {}
        }
      },
      "filler": 1984,
      "rotation": 2
    },
    {
      "x": 0,
      "y": 14,
      "z": 1,
      "name": "Empty"
    },
    {
      "x": 0,
      "y": 15,
      "z": 1,
      "name": "Empty"
    },
    {
      "x": 0,
      "y": 16,
      "z": 1,
      "name": "Wood_Deadwood_Roof_Steep",
      "rotation": 3
    },
    {
      "x": 0,
      "y": 17,
      "z": 1,
      "name": "Wood_Deadwood_Roof_Steep",
      "filler": 1024,
      "rotation": 3
    },
    {
      "x": 0,
      "y": 11,
      "z": 2,
      "name": "Wood_Deadwood_Planks"
    },
    {
      "x": 0,
      "y": 12,
      "z": 2,
      "name": "Furniture_Ancient_Bed",
      "components": {
        "Components": {
          "RespawnBlock": {}
        }
      },
      "filler": 992,
      "rotation": 2
    },
    {
      "x": 0,
      "y": 13,
      "z": 2,
      "name": "Furniture_Ancient_Bed",
      "components": {
        "Components": {
          "RespawnBlock": {}
        }
      },
      "filler": 2016,
      "rotation": 2
    },
    {
      "x": 0,
      "y": 14,
      "z": 2,
      "name": "Empty"
    },
    {
      "x": 0,
      "y": 15,
      "z": 2,
      "name": "Wood_Deadwood_Planks_Half",
      "rotation": 8
    },
    {
      "x": 0,
      "y": 16,
      "z": 2,
      "name": "Wood_Deadwood_Roof_Steep",
      "rotation": 3
    },
    {
      "x": 0,
      "y": 17,
      "z": 2,
      "name": "Wood_Deadwood_Roof_Steep",
      "filler": 1024,
      "rotation": 3
    },
    {
      "x": 0,
      "y": 11,
      "z": 3,
      "name": "Wood_Deadwood_Planks"
    },
    {
      "x": 0,
      "y": 12,
      "z": 3,
      "name": "Furniture_Ancient_Bed",
      "components": {
        "Components": {
          "RespawnBlock": {}
        }
      },
      "rotation": 2
    },
    {
      "x": 0,
      "y": 13,
      "z": 3,
      "name": "Furniture_Ancient_Bed",
      "components": {
        "Components": {
          "RespawnBlock": {}
        }
      },
      "filler": 1024,
      "rotation": 2
    },
    {
      "x": 0,
      "y": 14,
      "z": 3,
      "name": "Empty"
    },
    {
      "x": 0,
      "y": 15,
      "z": 3,
      "name": "Wood_Deadwood_Planks_Half",
      "rotation": 8
    },
    {
      "x": 0,
      "y": 16,
      "z": 3,
      "name": "Wood_Deadwood_Roof_Steep",
      "rotation": 3
    },
    {
      "x": 0,
      "y": 17,
      "z": 3,
      "name": "Wood_Deadwood_Roof_Steep",
      "filler": 1024,
      "rotation": 3
    },
    {
      "x": 0,
      "y": 9,
      "z": 4,
      "name": "Wood_Ash_Branch_Long",
      "rotation": 5
    },
    {
      "x": 0,
      "y": 11,
      "z": 4,
      "name": "Wood_Deadwood_Planks"
    },
    {
      "x": 0,
      "y": 12,
      "z": 4,
      "name": "Wood_Deadwood_Planks"
    },
    {
      "x": 0,
      "y": 13,
      "z": 4,
      "name": "Furniture_Ancient_Window"
    },
    {
      "x": 0,
      "y": 14,
      "z": 4,
      "name": "Wood_Deadwood_Planks"
    },
    {
      "x": 0,
      "y": 15,
      "z": 4,
      "name": "Wood_Deadwood_Planks"
    },
    {
      "x": 0,
      "y": 16,
      "z": 4,
      "name": "Wood_Deadwood_Roof_Steep",
      "rotation": 3
    },
    {
      "x": 0,
      "y": 17,
      "z": 4,
      "name": "Wood_Deadwood_Roof_Steep",
      "filler": 1024,
      "rotation": 3
    },
    {
      "x": 0,
      "y": 11,
      "z": 5,
      "name": "Wood_Deadwood_Planks_Half",
      "rotation": 8
    },
    {
      "x": 0,
      "y": 12,
      "z": 5,
      "name": "Plant_Moss_Rug_Yellow"
    },
    {
      "x": 1,
      "y": 11,
      "z": -4,
      "name": "Wood_Deadwood_Planks_Half",
      "rotation": 8
    },
    {
      "x": 1,
      "y": 11,
      "z": -3,
      "name": "Wood_Deadwood_Planks_Half",
      "rotation": 8
    },
    {
      "x": 1,
      "y": 12,
      "z": -3,
      "name": "Empty"
    },
    {
      "x": 1,
      "y": 13,
      "z": -3,
      "name": "Empty"
    },
    {
      "x": 1,
      "y": 14,
      "z": -3,
      "name": "Empty"
    },
    {
      "x": 1,
      "y": 8,
      "z": -2,
      "name": "Wood_Ash_Branch_Long",
      "rotation": 5
    },
    {
      "x": 1,
      "y": 9,
      "z": -2,
      "name": "Wood_Ash_Branch_Long",
      "rotation": 5
    },
    {
      "x": 1,
      "y": 11,
      "z": -2,
      "name": "Wood_Deadwood_Planks"
    },
    {
      "x": 1,
      "y": 12,
      "z": -2,
      "name": "Empty"
    },
    {
      "x": 1,
      "y": 13,
      "z": -2,
      "name": "Empty"
    },
    {
      "x": 1,
      "y": 14,
      "z": -2,
      "name": "Wood_Deadwood_Planks_Half",
      "rotation": 8
    },
    {
      "x": 1,
      "y": 15,
      "z": -2,
      "name": "Furniture_Ancient_Window"
    },
    {
      "x": 1,
      "y": 16,
      "z": -2,
      "name": "Wood_Deadwood_Planks"
    },
    {
      "x": 1,
      "y": 17,
      "z": -2,
      "name": "Wood_Deadwood_Planks"
    },
    {
      "x": 1,
      "y": 18,
      "z": -2,
      "name": "Wood_Deadwood_Roof_Flat",
      "rotation": 1
    },
    {
      "x": 1,
      "y": 11,
      "z": -1,
      "name": "Wood_Deadwood_Planks"
    },
    {
      "x": 1,
      "y": 12,
      "z": -1,
      "name": "Empty"
    },
    {
      "x": 1,
      "y": 13,
      "z": -1,
      "name": "Empty"
    },
    {
      "x": 1,
      "y": 14,
      "z": -1,
      "name": "Empty"
    },
    {
      "x": 1,
      "y": 15,
      "z": -1,
      "name": "Empty"
    },
    {
      "x": 1,
      "y": 16,
      "z": -1,
      "name": "Empty"
    },
    {
      "x": 1,
      "y": 17,
      "z": -1,
      "name": "Wood_Deadwood_Planks"
    },
    {
      "x": 1,
      "y": 18,
      "z": -1,
      "name": "Wood_Deadwood_Roof_Flat",
      "rotation": 1
    },
    {
      "x": 1,
      "y": 11,
      "z": 0,
      "name": "Wood_Deadwood_Planks"
    },
    {
      "x": 1,
      "y": 12,
      "z": 0,
      "name": "Alchemy_Cauldron"
    },
    {
      "x": 1,
      "y": 13,
      "z": 0,
      "name": "Empty"
    },
    {
      "x": 1,
      "y": 14,
      "z": 0,
      "name": "Empty"
    },
    {
      "x": 1,
      "y": 15,
      "z": 0,
      "name": "Empty"
    },
    {
      "x": 1,
      "y": 16,
      "z": 0,
      "name": "Empty"
    },
    {
      "x": 1,
      "y": 17,
      "z": 0,
      "name": "Wood_Deadwood_Planks"
    },
    {
      "x": 1,
      "y": 18,
      "z": 0,
      "name": "Wood_Deadwood_Roof_Flat",
      "rotation": 1
    },
    {
      "x": 1,
      "y": 11,
      "z": 1,
      "name": "Wood_Deadwood_Planks"
    },
    {
      "x": 1,
      "y": 12,
      "z": 1,
      "name": "Empty"
    },
    {
      "x": 1,
      "y": 13,
      "z": 1,
      "name": "Empty"
    },
    {
      "x": 1,
      "y": 14,
      "z": 1,
      "name": "Empty"
    },
    {
      "x": 1,
      "y": 15,
      "z": 1,
      "name": "Empty"
    },
    {
      "x": 1,
      "y": 16,
      "z": 1,
      "name": "Empty"
    },
    {
      "x": 1,
      "y": 17,
      "z": 1,
      "name": "Wood_Deadwood_Planks"
    },
    {
      "x": 1,
      "y": 18,
      "z": 1,
      "name": "Wood_Deadwood_Roof_Flat",
      "rotation": 1
    },
    {
      "x": 1,
      "y": 11,
      "z": 2,
      "name": "Wood_Deadwood_Planks"
    },
    {
      "x": 1,
      "y": 12,
      "z": 2,
      "name": "Empty"
    },
    {
      "x": 1,
      "y": 13,
      "z": 2,
      "name": "Empty"
    },
    {
      "x": 1,
      "y": 14,
      "z": 2,
      "name": "Deco_Lantern"
    },
    {
      "x": 1,
      "y": 15,
      "z": 2,
      "name": "Wood_Deadwood_Beam"
    },
    {
      "x": 1,
      "y": 16,
      "z": 2,
      "name": "Wood_Deadwood_Beam"
    },
    {
      "x": 1,
      "y": 17,
      "z": 2,
      "name": "Wood_Deadwood_Planks"
    },
    {
      "x": 1,
      "y": 18,
      "z": 2,
      "name": "Wood_Deadwood_Roof_Flat",
      "rotation": 1
    },
    {
      "x": 1,
      "y": 11,
      "z": 3,
      "name": "Wood_Deadwood_Planks"
    },
    {
      "x": 1,
      "y": 12,
      "z": 3,
      "name": "Bench_Furnace",
      "components": {
        "Components": {
          "processingBench": {
            "Position": {
              "X": 0,
              "Y": 67,
              "Z": 2
            },
            "TierLevel": 1,
            "UpgradeItems": [],
            "InputContainer": {
              "Id": "Simple",
              "Capacity": 2,
              "Items": {}
            },
            "FuelContainer": {
              "Id": "Simple",
              "Capacity": 2,
              "Items": {}
            },
            "OutputContainer": {
              "Id": "Simple",
              "Capacity": 4,
              "Items": {}
            },
            "Progress": 0.0,
            "FuelTime": 0.0,
            "Active": false,
            "NextExtra": 4
          }
        }
      },
      "rotation": 2
    },
    {
      "x": 1,
      "y": 13,
      "z": 3,
      "name": "Bench_Furnace",
      "components": {
        "Components": {
          "processingBench": {
            "Position": {
              "X": 1,
              "Y": 13,
              "Z": 3
            },
            "TierLevel": 1,
            "UpgradeItems": [],
            "Progress": 0.0,
            "FuelTime": 0.0,
            "Active": false,
            "NextExtra": -1
          }
        }
      },
      "filler": 1024,
      "rotation": 2
    },
    {
      "x": 1,
      "y": 14,
      "z": 3,
      "name": "Cloth_Roof_Leather_Flap",
      "rotation": 2
    },
    {
      "x": 1,
      "y": 15,
      "z": 3,
      "name": "Cloth_Roof_Leather_Vertical",
      "rotation": 2
    },
    {
      "x": 1,
      "y": 16,
      "z": 3,
      "name": "Cloth_Roof_Leather_Vertical",
      "rotation": 2
    },
    {
      "x": 1,
      "y": 17,
      "z": 3,
      "name": "Wood_Deadwood_Planks"
    },
    {
      "x": 1,
      "y": 18,
      "z": 3,
      "name": "Wood_Deadwood_Roof_Flat",
      "rotation": 1
    },
    {
      "x": 1,
      "y": 9,
      "z": 4,
      "name": "Wood_Ash_Branch_Long",
      "rotation": 5
    },
    {
      "x": 1,
      "y": 11,
      "z": 4,
      "name": "Wood_Deadwood_Planks"
    },
    {
      "x": 1,
      "y": 12,
      "z": 4,
      "name": "Rock_Basalt_Cobble"
    },
    {
      "x": 1,
      "y": 13,
      "z": 4,
      "name": "Rock_Basalt_Cobble"
    },
    {
      "x": 1,
      "y": 14,
      "z": 4,
      "name": "Rock_Basalt_Cobble"
    },
    {
      "x": 1,
      "y": 15,
      "z": 4,
      "name": "Rock_Basalt_Cobble"
    },
    {
      "x": 1,
      "y": 16,
      "z": 4,
      "name": "Rock_Basalt_Cobble"
    },
    {
      "x": 1,
      "y": 17,
      "z": 4,
      "name": "Rock_Basalt_Cobble"
    },
    {
      "x": 1,
      "y": 18,
      "z": 4,
      "name": "Rock_Basalt_Cobble"
    },
    {
      "x": 1,
      "y": 19,
      "z": 4,
      "name": "Rock_Basalt_Cobble_Wall"
    },
    {
      "x": 1,
      "y": 11,
      "z": 5,
      "name": "Wood_Deadwood_Planks_Half",
      "rotation": 8
    },
    {
      "x": 1,
      "y": 12,
      "z": 5,
      "name": "Rock_Basalt_Cobble"
    },
    {
      "x": 1,
      "y": 13,
      "z": 5,
      "name": "Rock_Basalt_Cobble"
    },
    {
      "x": 1,
      "y": 14,
      "z": 5,
      "name": "Rock_Basalt_Cobble"
    },
    {
      "x": 1,
      "y": 15,
      "z": 5,
      "name": "Rock_Basalt_Cobble"
    },
    {
      "x": 1,
      "y": 16,
      "z": 5,
      "name": "Rock_Basalt_Cobble_Half",
      "rotation": 4
    },
    {
      "x": 1,
      "y": 17,
      "z": 5,
      "name": "Rock_Basalt_Cobble_Half",
      "rotation": 4
    },
    {
      "x": 2,
      "y": 11,
      "z": -4,
      "name": "Wood_Deadwood_Planks_Half",
      "rotation": 8
    },
    {
      "x": 2,
      "y": 12,
      "z": -4,
      "name": "Plant_Moss_Rug_Yellow"
    },
    {
      "x": 2,
      "y": 13,
      "z": -4,
      "name": "Deco_Lantern"
    },
    {
      "x": 2,
      "y": 14,
      "z": -4,
      "name": "Wood_Deadwood_Beam"
    },
    {
      "x": 2,
      "y": 15,
      "z": -4,
      "name": "Wood_Deadwood_Planks_Half"
    },
    {
      "x": 2,
      "y": 11,
      "z": -3,
      "name": "Wood_Deadwood_Planks_Half",
      "rotation": 8
    },
    {
      "x": 2,
      "y": 12,
      "z": -3,
      "name": "Empty"
    },
    {
      "x": 2,
      "y": 13,
      "z": -3,
      "name": "Empty"
    },
    {
      "x": 2,
      "y": 15,
      "z": -3,
      "name": "Wood_Deadwood_Planks_Half"
    },
    {
      "x": 2,
      "y": 8,
      "z": -2,
      "name": "Wood_Ash_Branch_Long",
      "rotation": 5
    },
    {
      "x": 2,
      "y": 9,
      "z": -2,
      "name": "Wood_Ash_Branch_Long",
      "rotation": 5
    },
    {
      "x": 2,
      "y": 11,
      "z": -2,
      "name": "Wood_Deadwood_Planks"
    },
    {
      "x": 2,
      "y": 12,
      "z": -2,
      "name": "Wood_Deadwood_Planks_Half",
      "rotation": 7
    },
    {
      "x": 2,
      "y": 13,
      "z": -2,
      "name": "Wood_Deadwood_Planks_Half",
      "rotation": 7
    },
    {
      "x": 2,
      "y": 14,
      "z": -2,
      "name": "Wood_Deadwood_Planks"
    },
    {
      "x": 2,
      "y": 15,
      "z": -2,
      "name": "Wood_Deadwood_Planks"
    },
    {
      "x": 2,
      "y": 16,
      "z": -2,
      "name": "Wood_Deadwood_Roof_Steep",
      "rotation": 1
    },
    {
      "x": 2,
      "y": 17,
      "z": -2,
      "name": "Wood_Deadwood_Roof_Steep",
      "filler": 1024,
      "rotation": 1
    },
    {
      "x": 2,
      "y": 11,
      "z": -1,
      "name": "Wood_Deadwood_Planks"
    },
    {
      "x": 2,
      "y": 12,
      "z": -1,
      "name": "Empty"
    },
    {
      "x": 2,
      "y": 13,
      "z": -1,
      "name": "Empty"
    },
    {
      "x": 2,
      "y": 14,
      "z": -1,
      "name": "Empty"
    },
    {
      "x": 2,
      "y": 15,
      "z": -1,
      "name": "Wood_Deadwood_Planks_Half",
      "rotation": 8
    },
    {
      "x": 2,
      "y": 16,
      "z": -1,
      "name": "Wood_Deadwood_Roof_Steep",
      "rotation": 1
    },
    {
      "x": 2,
      "y": 17,
      "z": -1,
      "name": "Wood_Deadwood_Roof_Steep",
      "filler": 1024,
      "rotation": 1
    },
    {
      "x": 2,
      "y": 11,
      "z": 0,
      "name": "Wood_Deadwood_Planks"
    },
    {
      "x": 2,
      "y": 12,
      "z": 0,
      "name": "Empty"
    },
    {
      "x": 2,
      "y": 13,
      "z": 0,
      "name": "Empty"
    },
    {
      "x": 2,
      "y": 14,
      "z": 0,
      "name": "Empty"
    },
    {
      "x": 2,
      "y": 15,
      "z": 0,
      "name": "Wood_Deadwood_Planks_Half",
      "rotation": 8
    },
    {
      "x": 2,
      "y": 16,
      "z": 0,
      "name": "Wood_Deadwood_Roof_Steep",
      "rotation": 1
    },
    {
      "x": 2,
      "y": 17,
      "z": 0,
      "name": "Wood_Deadwood_Roof_Steep",
      "filler": 1024,
      "rotation": 1
    },
    {
      "x": 2,
      "y": 11,
      "z": 1,
      "name": "Wood_Deadwood_Planks"
    },
    {
      "x": 2,
      "y": 12,
      "z": 1,
      "name": "Empty"
    },
    {
      "x": 2,
      "y": 13,
      "z": 1,
      "name": "Empty"
    },
    {
      "x": 2,
      "y": 14,
      "z": 1,
      "name": "Empty"
    },
    {
      "x": 2,
      "y": 15,
      "z": 1,
      "name": "Cloth_Roof_Leather_Flap",
      "rotation": 3
    },
    {
      "x": 2,
      "y": 16,
      "z": 1,
      "name": "Wood_Deadwood_Roof_Steep",
      "rotation": 1
    },
    {
      "x": 2,
      "y": 17,
      "z": 1,
      "name": "Wood_Deadwood_Roof_Steep",
      "filler": 1024,
      "rotation": 1
    },
    {
      "x": 2,
      "y": 11,
      "z": 2,
      "name": "Wood_Deadwood_Planks"
    },
    {
      "x": 2,
      "y": 12,
      "z": 2,
      "name": "Empty"
    },
    {
      "x": 2,
      "y": 13,
      "z": 2,
      "name": "Empty"
    },
    {
      "x": 2,
      "y": 14,
      "z": 2,
      "name": "Empty"
    },
    {
      "x": 2,
      "y": 15,
      "z": 2,
      "name": "Wood_Deadwood_Planks_Half",
      "rotation": 8
    },
    {
      "x": 2,
      "y": 16,
      "z": 2,
      "name": "Wood_Deadwood_Roof_Steep",
      "rotation": 1
    },
    {
      "x": 2,
      "y": 17,
      "z": 2,
      "name": "Wood_Deadwood_Roof_Steep",
      "filler": 1024,
      "rotation": 1
    },
    {
      "x": 2,
      "y": 11,
      "z": 3,
      "name": "Wood_Deadwood_Planks"
    },
    {
      "x": 2,
      "y": 12,
      "z": 3,
      "name": "Bench_Furnace",
      "components": {
        "Components": {
          "processingBench": {
            "Position": {
              "X": 2,
              "Y": 12,
              "Z": 3
            },
            "TierLevel": 1,
            "UpgradeItems": [],
            "Progress": 0.0,
            "FuelTime": 0.0,
            "Active": false,
            "NextExtra": -1
          }
        }
      },
      "filler": 1,
      "rotation": 2
    },
    {
      "x": 2,
      "y": 13,
      "z": 3,
      "name": "Bench_Furnace",
      "components": {
        "Components": {
          "processingBench": {
            "Position": {
              "X": 2,
              "Y": 13,
              "Z": 3
            },
            "TierLevel": 1,
            "UpgradeItems": [],
            "Progress": 0.0,
            "FuelTime": 0.0,
            "Active": false,
            "NextExtra": -1
          }
        }
      },
      "filler": 1025,
      "rotation": 2
    },
    {
      "x": 2,
      "y": 14,
      "z": 3,
      "name": "Empty"
    },
    {
      "x": 2,
      "y": 15,
      "z": 3,
      "name": "Wood_Deadwood_Planks_Half",
      "rotation": 8
    },
    {
      "x": 2,
      "y": 16,
      "z": 3,
      "name": "Wood_Deadwood_Roof_Steep",
      "rotation": 1
    },
    {
      "x": 2,
      "y": 17,
      "z": 3,
      "name": "Wood_Deadwood_Roof_Steep",
      "filler": 1024,
      "rotation": 1
    },
    {
      "x": 2,
      "y": 9,
      "z": 4,
      "name": "Wood_Ash_Branch_Long",
      "rotation": 5
    },
    {
      "x": 2,
      "y": 11,
      "z": 4,
      "name": "Wood_Deadwood_Planks"
    },
    {
      "x": 2,
      "y": 12,
      "z": 4,
      "name": "Rock_Basalt_Cobble"
    },
    {
      "x": 2,
      "y": 13,
      "z": 4,
      "name": "Rock_Basalt_Cobble"
    },
    {
      "x": 2,
      "y": 14,
      "z": 4,
      "name": "Rock_Basalt_Cobble"
    },
    {
      "x": 2,
      "y": 15,
      "z": 4,
      "name": "Rock_Basalt_Cobble"
    },
    {
      "x": 2,
      "y": 16,
      "z": 4,
      "name": "Rock_Basalt_Cobble"
    },
    {
      "x": 2,
      "y": 17,
      "z": 4,
      "name": "Rock_Basalt_Cobble"
    },
    {
      "x": 2,
      "y": 18,
      "z": 4,
      "name": "Rock_Basalt_Cobble"
    },
    {
      "x": 2,
      "y": 19,
      "z": 4,
      "name": "Rock_Basalt_Cobble"
    },
    {
      "x": 2,
      "y": 20,
      "z": 4,
      "name": "Rock_Basalt_Cobble_Wall"
    },
    {
      "x": 2,
      "y": 11,
      "z": 5,
      "name": "Wood_Deadwood_Planks_Half",
      "rotation": 8
    },
    {
      "x": 2,
      "y": 12,
      "z": 5,
      "name": "Rock_Basalt_Cobble"
    },
    {
      "x": 2,
      "y": 13,
      "z": 5,
      "name": "Rock_Basalt_Cobble"
    },
    {
      "x": 2,
      "y": 14,
      "z": 5,
      "name": "Rock_Basalt_Cobble"
    },
    {
      "x": 2,
      "y": 15,
      "z": 5,
      "name": "Rock_Basalt_Cobble_Half",
      "rotation": 4
    },
    {
      "x": 2,
      "y": 16,
      "z": 5,
      "name": "Rock_Basalt_Cobble_Half",
      "rotation": 4
    },
    {
      "x": 3,
      "y": 11,
      "z": -5,
      "name": "Plant_Moss_Wall_Yellow",
      "rotation": 2
    },
    {
      "x": 3,
      "y": 11,
      "z": -4,
      "name": "Wood_Deadwood_Planks_Half",
      "rotation": 8
    },
    {
      "x": 3,
      "y": 12,
      "z": -4,
      "name": "Plant_Moss_Rug_Yellow"
    },
    {
      "x": 3,
      "y": 11,
      "z": -3,
      "name": "Wood_Deadwood_Stairs",
      "rotation": 8
    },
    {
      "x": 3,
      "y": 0,
      "z": -2,
      "name": "Wood_Ash_Trunk"
    },
    {
      "x": 3,
      "y": 1,
      "z": -2,
      "name": "Wood_Ash_Trunk"
    },
    {
      "x": 3,
      "y": 2,
      "z": -2,
      "name": "Wood_Ash_Trunk"
    },
    {
      "x": 3,
      "y": 3,
      "z": -2,
      "name": "Wood_Ash_Trunk"
    },
    {
      "x": 3,
      "y": 4,
      "z": -2,
      "name": "Wood_Ash_Trunk"
    },
    {
      "x": 3,
      "y": 5,
      "z": -2,
      "name": "Wood_Ash_Trunk"
    },
    {
      "x": 3,
      "y": 6,
      "z": -2,
      "name": "Wood_Ash_Trunk"
    },
    {
      "x": 3,
      "y": 7,
      "z": -2,
      "name": "Wood_Ash_Trunk"
    },
    {
      "x": 3,
      "y": 8,
      "z": -2,
      "name": "Wood_Ash_Trunk"
    },
    {
      "x": 3,
      "y": 9,
      "z": -2,
      "name": "Wood_Ash_Trunk"
    },
    {
      "x": 3,
      "y": 10,
      "z": -2,
      "name": "Wood_Ash_Trunk"
    },
    {
      "x": 3,
      "y": 11,
      "z": -2,
      "name": "Wood_Deadwood_Planks"
    },
    {
      "x": 3,
      "y": 12,
      "z": -2,
      "name": "Wood_Deadwood_Planks"
    },
    {
      "x": 3,
      "y": 13,
      "z": -2,
      "name": "Wood_Deadwood_Planks"
    },
    {
      "x": 3,
      "y": 14,
      "z": -2,
      "name": "Wood_Deadwood_Roof_Steep",
      "rotation": 1
    },
    {
      "x": 3,
      "y": 15,
      "z": -2,
      "name": "Wood_Deadwood_Roof_Steep",
      "filler": 1024,
      "rotation": 1
    },
    {
      "x": 3,
      "y": 8,
      "z": -1,
      "name": "Wood_Ash_Branch_Long",
      "rotation": 4
    },
    {
      "x": 3,
      "y": 10,
      "z": -1,
      "name": "Wood_Ash_Branch_Long",
      "rotation": 4
    },
    {
      "x": 3,
      "y": 11,
      "z": -1,
      "name": "Wood_Deadwood_Planks"
    },
    {
      "x": 3,
      "y": 12,
      "z": -1,
      "name": "Furniture_Ancient_Barrel"
    },
    {
      "x": 3,
      "y": 13,
      "z": -1,
      "name": "Wood_Deadwood_Planks_Half",
      "rotation": 8
    },
    {
      "x": 3,
      "y": 14,
      "z": -1,
      "name": "Wood_Deadwood_Roof_Steep",
      "rotation": 1
    },
    {
      "x": 3,
      "y": 15,
      "z": -1,
      "name": "Wood_Deadwood_Roof_Steep",
      "filler": 1024,
      "rotation": 1
    },
    {
      "x": 3,
      "y": 8,
      "z": 0,
      "name": "Wood_Ash_Branch_Long",
      "rotation": 4
    },
    {
      "x": 3,
      "y": 10,
      "z": 0,
      "name": "Wood_Ash_Branch_Long",
      "rotation": 4
    },
    {
      "x": 3,
      "y": 11,
      "z": 0,
      "name": "Wood_Deadwood_Planks"
    },
    {
      "x": 3,
      "y": 12,
      "z": 0,
      "name": "Furniture_Human_Ruins_Bookshelf",
      "rotation": 3
    },
    {
      "x": 3,
      "y": 13,
      "z": 0,
      "name": "Wood_Deadwood_Planks_Half",
      "rotation": 8
    },
    {
      "x": 3,
      "y": 14,
      "z": 0,
      "name": "*Wood_Deadwood_Roof_Steep_State_Definitions_Inverted_Corner_Right",
      "rotation": 2
    },
    {
      "x": 3,
      "y": 15,
      "z": 0,
      "name": "*Wood_Deadwood_Roof_Steep_State_Definitions_Inverted_Corner_Right",
      "filler": 1024,
      "rotation": 2
    },
    {
      "x": 3,
      "y": 0,
      "z": 1,
      "name": "Wood_Ash_Trunk"
    },
    {
      "x": 3,
      "y": 1,
      "z": 1,
      "name": "Wood_Ash_Trunk"
    },
    {
      "x": 3,
      "y": 2,
      "z": 1,
      "name": "Wood_Ash_Trunk"
    },
    {
      "x": 3,
      "y": 3,
      "z": 1,
      "name": "Wood_Ash_Trunk"
    },
    {
      "x": 3,
      "y": 4,
      "z": 1,
      "name": "Wood_Ash_Trunk"
    },
    {
      "x": 3,
      "y": 5,
      "z": 1,
      "name": "Wood_Ash_Trunk"
    },
    {
      "x": 3,
      "y": 6,
      "z": 1,
      "name": "Wood_Ash_Trunk"
    },
    {
      "x": 3,
      "y": 7,
      "z": 1,
      "name": "Wood_Ash_Trunk"
    },
    {
      "x": 3,
      "y": 8,
      "z": 1,
      "name": "Wood_Ash_Trunk"
    },
    {
      "x": 3,
      "y": 9,
      "z": 1,
      "name": "Wood_Ash_Trunk"
    },
    {
      "x": 3,
      "y": 10,
      "z": 1,
      "name": "Wood_Ash_Trunk"
    },
    {
      "x": 3,
      "y": 11,
      "z": 1,
      "name": "Wood_Deadwood_Planks"
    },
    {
      "x": 3,
      "y": 12,
      "z": 1,
      "name": "Furniture_Human_Ruins_Desk",
      "filler": 992,
      "rotation": 3
    },
    {
      "x": 3,
      "y": 13,
      "z": 1,
      "name": "Wood_Deadwood_Planks_Half",
      "rotation": 8
    },
    {
      "x": 3,
      "y": 14,
      "z": 1,
      "name": "Furniture_Ancient_Window",
      "rotation": 1
    },
    {
      "x": 3,
      "y": 15,
      "z": 1,
      "name": "Furniture_Ancient_Window",
      "rotation": 1
    },
    {
      "x": 3,
      "y": 16,
      "z": 1,
      "name": "Wood_Deadwood_Roof_Flat",
      "rotation": 1
    },
    {
      "x": 3,
      "y": 9,
      "z": 2,
      "name": "Wood_Ash_Branch_Long",
      "rotation": 4
    },
    {
      "x": 3,
      "y": 10,
      "z": 2,
      "name": "Wood_Ash_Branch_Long",
      "rotation": 4
    },
    {
      "x": 3,
      "y": 11,
      "z": 2,
      "name": "Wood_Deadwood_Planks"
    },
    {
      "x": 3,
      "y": 12,
      "z": 2,
      "name": "Furniture_Human_Ruins_Desk",
      "rotation": 3
    },
    {
      "x": 3,
      "y": 13,
      "z": 2,
      "name": "Wood_Deadwood_Planks_Half",
      "rotation": 8
    },
    {
      "x": 3,
      "y": 14,
      "z": 2,
      "name": "*Wood_Deadwood_Roof_Steep_State_Definitions_Inverted_Corner_Right",
      "rotation": 1
    },
    {
      "x": 3,
      "y": 15,
      "z": 2,
      "name": "*Wood_Deadwood_Roof_Steep_State_Definitions_Inverted_Corner_Right",
      "filler": 1024,
      "rotation": 1
    },
    {
      "x": 3,
      "y": 9,
      "z": 3,
      "name": "Wood_Ash_Branch_Long",
      "rotation": 4
    },
    {
      "x": 3,
      "y": 10,
      "z": 3,
      "name": "Wood_Ash_Branch_Long",
      "rotation": 4
    },
    {
      "x": 3,
      "y": 11,
      "z": 3,
      "name": "Wood_Deadwood_Planks"
    },
    {
      "x": 3,
      "y": 12,
      "z": 3,
      "name": "Furniture_Ancient_Barrel"
    },
    {
      "x": 3,
      "y": 13,
      "z": 3,
      "name": "Wood_Deadwood_Planks_Half",
      "rotation": 8
    },
    {
      "x": 3,
      "y": 14,
      "z": 3,
      "name": "Wood_Deadwood_Roof_Steep",
      "rotation": 1
    },
    {
      "x": 3,
      "y": 15,
      "z": 3,
      "name": "Wood_Deadwood_Roof_Steep",
      "filler": 1024,
      "rotation": 1
    },
    {
      "x": 3,
      "y": 0,
      "z": 4,
      "name": "Wood_Ash_Trunk"
    },
    {
      "x": 3,
      "y": 1,
      "z": 4,
      "name": "Wood_Ash_Trunk"
    },
    {
      "x": 3,
      "y": 2,
      "z": 4,
      "name": "Wood_Ash_Trunk"
    },
    {
      "x": 3,
      "y": 3,
      "z": 4,
      "name": "Wood_Ash_Trunk"
    },
    {
      "x": 3,
      "y": 4,
      "z": 4,
      "name": "Wood_Ash_Trunk"
    },
    {
      "x": 3,
      "y": 5,
      "z": 4,
      "name": "Wood_Ash_Trunk"
    },
    {
      "x": 3,
      "y": 6,
      "z": 4,
      "name": "Wood_Ash_Trunk"
    },
    {
      "x": 3,
      "y": 7,
      "z": 4,
      "name": "Wood_Ash_Trunk"
    },
    {
      "x": 3,
      "y": 8,
      "z": 4,
      "name": "Wood_Ash_Trunk"
    },
    {
      "x": 3,
      "y": 9,
      "z": 4,
      "name": "Wood_Ash_Trunk"
    },
    {
      "x": 3,
      "y": 10,
      "z": 4,
      "name": "Wood_Ash_Trunk"
    },
    {
      "x": 3,
      "y": 11,
      "z": 4,
      "name": "Wood_Deadwood_Planks"
    },
    {
      "x": 3,
      "y": 12,
      "z": 4,
      "name": "Wood_Deadwood_Planks"
    },
    {
      "x": 3,
      "y": 13,
      "z": 4,
      "name": "Wood_Deadwood_Planks"
    },
    {
      "x": 3,
      "y": 14,
      "z": 4,
      "name": "Wood_Deadwood_Roof_Steep",
      "rotation": 1
    },
    {
      "x": 3,
      "y": 15,
      "z": 4,
      "name": "Wood_Deadwood_Roof_Steep",
      "filler": 1024,
      "rotation": 1
    },
    {
      "x": 3,
      "y": 11,
      "z": 5,
      "name": "Wood_Deadwood_Stairs",
      "rotation": 10
    },
    {
      "x": 3,
      "y": 12,
      "z": 5,
      "name": "Plant_Moss_Rug_Yellow"
    },
    {
      "x": 3,
      "y": 11,
      "z": 6,
      "name": "Plant_Moss_Wall_Yellow"
    },
    {
      "x": 4,
      "y": 11,
      "z": -4,
      "name": "Wood_Deadwood_Planks_Half",
      "rotation": 8
    },
    {
      "x": 4,
      "y": 12,
      "z": -4,
      "name": "Plant_Bush_Dead_Tall"
    },
    {
      "x": 4,
      "y": 11,
      "z": -3,
      "name": "Wood_Deadwood_Planks_Half",
      "rotation": 8
    },
    {
      "x": 4,
      "y": 11,
      "z": -2,
      "name": "Wood_Deadwood_Stairs",
      "rotation": 11
    },
    {
      "x": 4,
      "y": 12,
      "z": -2,
      "name": "Wood_Deadwood_Roof_Steep",
      "rotation": 1
    },
    {
      "x": 4,
      "y": 13,
      "z": -2,
      "name": "Wood_Deadwood_Roof_Steep",
      "filler": 1024,
      "rotation": 1
    },
    {
      "x": 4,
      "y": 11,
      "z": -1,
      "name": "Wood_Deadwood_Planks_Half",
      "rotation": 8
    },
    {
      "x": 4,
      "y": 12,
      "z": -1,
      "name": "Wood_Deadwood_Roof_Steep",
      "rotation": 1
    },
    {
      "x": 4,
      "y": 13,
      "z": -1,
      "name": "Wood_Deadwood_Roof_Steep",
      "filler": 1024,
      "rotation": 1
    },
    {
      "x": 4,
      "y": 11,
      "z": 0,
      "name": "Wood_Deadwood_Planks_Half",
      "rotation": 8
    },
    {
      "x": 4,
      "y": 12,
      "z": 0,
      "name": "Wood_Deadwood_Roof_Steep",
      "rotation": 1
    },
    {
      "x": 4,
      "y": 13,
      "z": 0,
      "name": "Wood_Deadwood_Roof_Steep",
      "filler": 1024,
      "rotation": 1
    },
    {
      "x": 4,
      "y": 11,
      "z": 1,
      "name": "Wood_Deadwood_Stairs",
      "rotation": 11
    },
    {
      "x": 4,
      "y": 12,
      "z": 1,
      "name": "Wood_Deadwood_Roof_Steep",
      "rotation": 1
    },
    {
      "x": 4,
      "y": 13,
      "z": 1,
      "name": "Wood_Deadwood_Roof_Steep",
      "filler": 1024,
      "rotation": 1
    },
    {
      "x": 4,
      "y": 11,
      "z": 2,
      "name": "Wood_Deadwood_Planks_Half",
      "rotation": 8
    },
    {
      "x": 4,
      "y": 12,
      "z": 2,
      "name": "Wood_Deadwood_Roof_Steep",
      "rotation": 1
    },
    {
      "x": 4,
      "y": 13,
      "z": 2,
      "name": "Wood_Deadwood_Roof_Steep",
      "filler": 1024,
      "rotation": 1
    },
    {
      "x": 4,
      "y": 11,
      "z": 3,
      "name": "Wood_Deadwood_Planks_Half",
      "rotation": 8
    },
    {
      "x": 4,
      "y": 12,
      "z": 3,
      "name": "Wood_Deadwood_Roof_Steep",
      "rotation": 1
    },
    {
      "x": 4,
      "y": 13,
      "z": 3,
      "name": "Wood_Deadwood_Roof_Steep",
      "filler": 1024,
      "rotation": 1
    },
    {
      "x": 4,
      "y": 11,
      "z": 4,
      "name": "Wood_Deadwood_Stairs",
      "rotation": 11
    },
    {
      "x": 4,
      "y": 12,
      "z": 4,
      "name": "Wood_Deadwood_Roof_Steep",
      "rotation": 1
    },
    {
      "x": 4,
      "y": 13,
      "z": 4,
      "name": "Wood_Deadwood_Roof_Steep",
      "filler": 1024,
      "rotation": 1
    },
    {
      "x": 4,
      "y": 11,
      "z": 5,
      "name": "Wood_Deadwood_Planks_Half",
      "rotation": 8
    }
  ]
}