{
  "version": 8,
  "blockIdVersion": 8,
  "anchorX": 0,
  "anchorY": 5,
  "anchorZ": 1,
  "blocks": [
    {
      "x": -9,
      "y": 7,
      "z": -11,
      "name": "Cloth_Roof_Green_Flap",
      "rotation": 3
    },
    {
      "x": -9,
      "y": 8,
      "z": -11,
      "name": "Cloth_Roof_Green_Vertical",
      "rotation": 3
    },
    {
      "x": -9,
      "y": 7,
      "z": -10,
      "name": "Cloth_Roof_Green_Flap",
      "rotation": 3
    },
    {
      "x": -9,
      "y": 8,
      "z": -10,
      "name": "Cloth_Roof_Green_Vertical",
      "rotation": 3
    },
    {
      "x": -9,
      "y": 8,
      "z": -9,
      "name": "Cloth_Roof_Green_Flap",
      "rotation": 3
    },
    {
      "x": -9,
      "y": 8,
      "z": -8,
      "name": "Cloth_Roof_Green_Flap",
      "rotation": 3
    },
    {
      "x": -9,
      "y": 7,
      "z": -7,
      "name": "Cloth_Roof_Orange_Flap",
      "rotation": 3
    },
    {
      "x": -9,
      "y": 7,
      "z": -6,
      "name": "Cloth_Roof_Orange_Flap",
      "rotation": 3
    },
    {
      "x": -9,
      "y": 6,
      "z": -5,
      "name": "Cloth_Roof_Orange_Flap",
      "rotation": 3
    },
    {
      "x": -9,
      "y": 7,
      "z": -5,
      "name": "Cloth_Roof_Orange_Vertical",
      "rotation": 3
    },
    {
      "x": -9,
      "y": 6,
      "z": -4,
      "name": "Cloth_Roof_Orange_Flap",
      "rotation": 3
    },
    {
      "x": -9,
      "y": 7,
      "z": -4,
      "name": "Cloth_Roof_Orange_Vertical",
      "rotation": 3
    },
    {
      "x": -8,
      "y": 7,
      "z": -12,
      "name": "Cloth_Roof_Green_Flap",
      "rotation": 2
    },
    {
      "x": -8,
      "y": 8,
      "z": -12,
      "name": "Cloth_Roof_Green_Vertical",
      "rotation": 2
    },
    {
      "x": -8,
      "y": 0,
      "z": -11,
      "name": "Rock_Sandstone_Brick"
    },
    {
      "x": -8,
      "y": 1,
      "z": -11,
      "name": "Rock_Sandstone_Brick"
    },
    {
      "x": -8,
      "y": 2,
      "z": -11,
      "name": "Rock_Sandstone_Brick"
    },
    {
      "x": -8,
      "y": 3,
      "z": -11,
      "name": "Rock_Sandstone_Brick"
    },
    {
      "x": -8,
      "y": 4,
      "z": -11,
      "name": "Rock_Sandstone_Brick"
    },
    {
      "x": -8,
      "y": 5,
      "z": -11,
      "name": "Rock_Sandstone_Brick"
    },
    {
      "x": -8,
      "y": 6,
      "z": -11,
      "name": "Rock_Sandstone_Brick"
    },
    {
      "x": -8,
      "y": 7,
      "z": -11,
      "name": "Wood_Dry_Branch_Long"
    },
    {
      "x": -8,
      "y": 8,
      "z": -11,
      "name": "Wood_Dry_Branch_Long"
    },
    {
      "x": -8,
      "y": 9,
      "z": -11,
      "name": "Cloth_Roof_Green_Flat"
    },
    {
      "x": -8,
      "y": 10,
      "z": -11,
      "name": "Empty"
    },
    {
      "x": -8,
      "y": 11,
      "z": -11,
      "name": "Empty"
    },
    {
      "x": -8,
      "y": 0,
      "z": -10,
      "name": "Rock_Sandstone_Cobble"
    },
    {
      "x": -8,
      "y": 1,
      "z": -10,
      "name": "Rock_Sandstone_Cobble"
    },
    {
      "x": -8,
      "y": 2,
      "z": -10,
      "name": "Rock_Sandstone_Cobble"
    },
    {
      "x": -8,
      "y": 3,
      "z": -10,
      "name": "Rock_Sandstone_Cobble"
    },
    {
      "x": -8,
      "y": 4,
      "z": -10,
      "name": "Rock_Sandstone_Cobble"
    },
    {
      "x": -8,
      "y": 5,
      "z": -10,
      "name": "Soil_Dirt_Dry"
    },
    {
      "x": -8,
      "y": 6,
      "z": -10,
      "name": "Empty"
    },
    {
      "x": -8,
      "y": 7,
      "z": -10,
      "name": "Empty"
    },
    {
      "x": -8,
      "y": 8,
      "z": -10,
      "name": "Empty"
    },
    {
      "x": -8,
      "y": 9,
      "z": -10,
      "name": "Cloth_Roof_Green_Flat"
    },
    {
      "x": -8,
      "y": 10,
      "z": -10,
      "name": "Empty"
    },
    {
      "x": -8,
      "y": 11,
      "z": -10,
      "name": "Empty"
    },
    {
      "x": -8,
      "y": 0,
      "z": -9,
      "name": "Rock_Sandstone_Cobble"
    },
    {
      "x": -8,
      "y": 1,
      "z": -9,
      "name": "Rock_Sandstone_Cobble"
    },
    {
      "x": -8,
      "y": 2,
      "z": -9,
      "name": "Rock_Sandstone_Cobble"
    },
    {
      "x": -8,
      "y": 3,
      "z": -9,
      "name": "Rock_Sandstone_Cobble"
    },
    {
      "x": -8,
      "y": 4,
      "z": -9,
      "name": "Rock_Sandstone_Cobble"
    },
    {
      "x": -8,
      "y": 5,
      "z": -9,
      "name": "Soil_Dirt_Dry"
    },
    {
      "x": -8,
      "y": 6,
      "z": -9,
      "name": "Empty"
    },
    {
      "x": -8,
      "y": 7,
      "z": -9,
      "name": "Empty"
    },
    {
      "x": -8,
      "y": 8,
      "z": -9,
      "name": "Empty"
    },
    {
      "x": -8,
      "y": 9,
      "z": -9,
      "name": "Cloth_Roof_Green_Flat"
    },
    {
      "x": -8,
      "y": 10,
      "z": -9,
      "name": "Empty"
    },
    {
      "x": -8,
      "y": 11,
      "z": -9,
      "name": "Empty"
    },
    {
      "x": -8,
      "y": 0,
      "z": -8,
      "name": "Rock_Sandstone_Cobble"
    },
    {
      "x": -8,
      "y": 1,
      "z": -8,
      "name": "Rock_Sandstone_Cobble"
    },
    {
      "x": -8,
      "y": 2,
      "z": -8,
      "name": "Rock_Sandstone_Cobble"
    },
    {
      "x": -8,
      "y": 3,
      "z": -8,
      "name": "Rock_Sandstone_Cobble"
    },
    {
      "x": -8,
      "y": 4,
      "z": -8,
      "name": "Rock_Sandstone_Cobble"
    },
    {
      "x": -8,
      "y": 5,
      "z": -8,
      "name": "Soil_Dirt_Dry"
    },
    {
      "x": -8,
      "y": 6,
      "z": -8,
      "name": "Wood_Dry_Branch_Long"
    },
    {
      "x": -8,
      "y": 7,
      "z": -8,
      "name": "Wood_Dry_Branch_Long"
    },
    {
      "x": -8,
      "y": 8,
      "z": -8,
      "name": "Wood_Dry_Branch_Long"
    },
    {
      "x": -8,
      "y": 9,
      "z": -8,
      "name": "Cloth_Roof_Green_Flat"
    },
    {
      "x": -8,
      "y": 10,
      "z": -8,
      "name": "Empty"
    },
    {
      "x": -8,
      "y": 11,
      "z": -8,
      "name": "Empty"
    },
    {
      "x": -8,
      "y": 0,
      "z": -7,
      "name": "Rock_Sandstone_Cobble"
    },
    {
      "x": -8,
      "y": 1,
      "z": -7,
      "name": "Rock_Sandstone_Cobble"
    },
    {
      "x": -8,
      "y": 2,
      "z": -7,
      "name": "Rock_Sandstone_Cobble"
    },
    {
      "x": -8,
      "y": 3,
      "z": -7,
      "name": "Rock_Sandstone_Cobble"
    },
    {
      "x": -8,
      "y": 4,
      "z": -7,
      "name": "Rock_Sandstone_Cobble"
    },
    {
      "x": -8,
      "y": 5,
      "z": -7,
      "name": "Soil_Dirt_Dry"
    },
    {
      "x": -8,
      "y": 6,
      "z": -7,
      "name": "Furniture_Village_Pot"
    },
    {
      "x": -8,
      "y": 7,
      "z": -7,
      "name": "Empty"
    },
    {
      "x": -8,
      "y": 8,
      "z": -7,
      "name": "Cloth_Roof_Orange",
      "rotation": 3
    },
    {
      "x": -8,
      "y": 9,
      "z": -7,
      "name": "Empty"
    },
    {
      "x": -8,
      "y": 10,
      "z": -7,
      "name": "Empty"
    },
    {
      "x": -8,
      "y": 11,
      "z": -7,
      "name": "Empty"
    },
    {
      "x": -8,
      "y": 0,
      "z": -6,
      "name": "Rock_Sandstone_Cobble"
    },
    {
      "x": -8,
      "y": 1,
      "z": -6,
      "name": "Rock_Sandstone_Cobble"
    },
    {
      "x": -8,
      "y": 2,
      "z": -6,
      "name": "Rock_Sandstone_Cobble"
    },
    {
      "x": -8,
      "y": 3,
      "z": -6,
      "name": "Rock_Sandstone_Cobble"
    },
    {
      "x": -8,
      "y": 4,
      "z": -6,
      "name": "Rock_Sandstone_Cobble"
    },
    {
      "x": -8,
      "y": 5,
      "z": -6,
      "name": "Soil_Dirt_Dry"
    },
    {
      "x": -8,
      "y": 6,
      "z": -6,
      "name": "Furniture_Ancient_Pot"
    },
    {
      "x": -8,
      "y": 7,
      "z": -6,
      "name": "Empty"
    },
    {
      "x": -8,
      "y": 8,
      "z": -6,
      "name": "Cloth_Roof_Orange",
      "rotation": 3
    },
    {
      "x": -8,
      "y": 9,
      "z": -6,
      "name": "Empty"
    },
    {
      "x": -8,
      "y": 10,
      "z": -6,
      "name": "Empty"
    },
    {
      "x": -8,
      "y": 11,
      "z": -6,
      "name": "Empty"
    },
    {
      "x": -8,
      "y": 0,
      "z": -5,
      "name": "Rock_Sandstone_Cobble"
    },
    {
      "x": -8,
      "y": 1,
      "z": -5,
      "name": "Rock_Sandstone_Cobble"
    },
    {
      "x": -8,
      "y": 2,
      "z": -5,
      "name": "Rock_Sandstone_Cobble"
    },
    {
      "x": -8,
      "y": 3,
      "z": -5,
      "name": "Rock_Sandstone_Cobble"
    },
    {
      "x": -8,
      "y": 4,
      "z": -5,
      "name": "Rock_Sandstone_Cobble"
    },
    {
      "x": -8,
      "y": 5,
      "z": -5,
      "name": "Soil_Dirt_Dry"
    },
    {
      "x": -8,
      "y": 6,
      "z": -5,
      "name": "Empty"
    },
    {
      "x": -8,
      "y": 7,
      "z": -5,
      "name": "Empty"
    },
    {
      "x": -8,
      "y": 8,
      "z": -5,
      "name": "Cloth_Roof_Orange",
      "rotation": 3
    },
    {
      "x": -8,
      "y": 9,
      "z": -5,
      "name": "Empty"
    },
    {
      "x": -8,
      "y": 10,
      "z": -5,
      "name": "Empty"
    },
    {
      "x": -8,
      "y": 11,
      "z": -5,
      "name": "Empty"
    },
    {
      "x": -8,
      "y": 0,
      "z": -4,
      "name": "Rock_Sandstone_Cobble"
    },
    {
      "x": -8,
      "y": 1,
      "z": -4,
      "name": "Rock_Sandstone_Cobble"
    },
    {
      "x": -8,
      "y": 2,
      "z": -4,
      "name": "Rock_Sandstone_Cobble"
    },
    {
      "x": -8,
      "y": 3,
      "z": -4,
      "name": "Rock_Sandstone_Cobble"
    },
    {
      "x": -8,
      "y": 4,
      "z": -4,
      "name": "Rock_Sandstone_Cobble"
    },
    {
      "x": -8,
      "y": 5,
      "z": -4,
      "name": "Soil_Dirt_Dry"
    },
    {
      "x": -8,
      "y": 6,
      "z": -4,
      "name": "Cloth_Roof_Orange_Flap",
      "rotation": 2
    },
    {
      "x": -8,
      "y": 7,
      "z": -4,
      "name": "Cloth_Roof_Orange_Vertical",
      "rotation": 2
    },
    {
      "x": -8,
      "y": 8,
      "z": -4,
      "name": "*Cloth_Roof_Orange_State_Definitions_Corner_Right"
    },
    {
      "x": -8,
      "y": 9,
      "z": -4,
      "name": "Empty"
    },
    {
      "x": -8,
      "y": 10,
      "z": -4,
      "name": "Empty"
    },
    {
      "x": -8,
      "y": 11,
      "z": -4,
      "name": "Empty"
    },
    {
      "x": -7,
      "y": 8,
      "z": -12,
      "name": "Cloth_Roof_Green_Vertical",
      "rotation": 2
    },
    {
      "x": -7,
      "y": 0,
      "z": -11,
      "name": "Rock_Sandstone_Brick"
    },
    {
      "x": -7,
      "y": 1,
      "z": -11,
      "name": "Rock_Sandstone_Brick"
    },
    {
      "x": -7,
      "y": 2,
      "z": -11,
      "name": "Rock_Sandstone_Brick"
    },
    {
      "x": -7,
      "y": 3,
      "z": -11,
      "name": "Rock_Sandstone_Brick"
    },
    {
      "x": -7,
      "y": 4,
      "z": -11,
      "name": "Rock_Sandstone_Brick"
    },
    {
      "x": -7,
      "y": 5,
      "z": -11,
      "name": "Rock_Sandstone_Brick"
    },
    {
      "x": -7,
      "y": 6,
      "z": -11,
      "name": "Rock_Sandstone_Brick"
    },
    {
      "x": -7,
      "y": 7,
      "z": -11,
      "name": "Rock_Sandstone_Brick_Stairs",
      "rotation": 3
    },
    {
      "x": -7,
      "y": 8,
      "z": -11,
      "name": "Empty"
    },
    {
      "x": -7,
      "y": 9,
      "z": -11,
      "name": "Cloth_Roof_Green_Flat"
    },
    {
      "x": -7,
      "y": 10,
      "z": -11,
      "name": "Empty"
    },
    {
      "x": -7,
      "y": 11,
      "z": -11,
      "name": "Empty"
    },
    {
      "x": -7,
      "y": 0,
      "z": -10,
      "name": "Rock_Sandstone_Cobble"
    },
    {
      "x": -7,
      "y": 1,
      "z": -10,
      "name": "Rock_Sandstone_Cobble"
    },
    {
      "x": -7,
      "y": 2,
      "z": -10,
      "name": "Rock_Sandstone_Cobble"
    },
    {
      "x": -7,
      "y": 3,
      "z": -10,
      "name": "Rock_Sandstone_Cobble"
    },
    {
      "x": -7,
      "y": 4,
      "z": -10,
      "name": "Rock_Sandstone_Cobble"
    },
    {
      "x": -7,
      "y": 5,
      "z": -10,
      "name": "Soil_Dirt_Dry"
    },
    {
      "x": -7,
      "y": 6,
      "z": -10,
      "name": "Furniture_Temple_Wind_Pot"
    },
    {
      "x": -7,
      "y": 7,
      "z": -10,
      "name": "Furniture_Temple_Wind_Pot",
      "filler": 1024
    },
    {
      "x": -7,
      "y": 8,
      "z": -10,
      "name": "Empty"
    },
    {
      "x": -7,
      "y": 9,
      "z": -10,
      "name": "Empty"
    },
    {
      "x": -7,
      "y": 10,
      "z": -10,
      "name": "Empty"
    },
    {
      "x": -7,
      "y": 11,
      "z": -10,
      "name": "Empty"
    },
    {
      "x": -7,
      "y": 0,
      "z": -9,
      "name": "Rock_Sandstone_Cobble"
    },
    {
      "x": -7,
      "y": 1,
      "z": -9,
      "name": "Rock_Sandstone_Cobble"
    },
    {
      "x": -7,
      "y": 2,
      "z": -9,
      "name": "Rock_Sandstone_Cobble"
    },
    {
      "x": -7,
      "y": 3,
      "z": -9,
      "name": "Rock_Sandstone_Cobble"
    },
    {
      "x": -7,
      "y": 4,
      "z": -9,
      "name": "Rock_Sandstone_Cobble"
    },
    {
      "x": -7,
      "y": 5,
      "z": -9,
      "name": "Soil_Dirt_Dry"
    },
    {
      "x": -7,
      "y": 6,
      "z": -9,
      "name": "Empty"
    },
    {
      "x": -7,
      "y": 7,
      "z": -9,
      "name": "Empty"
    },
    {
      "x": -7,
      "y": 8,
      "z": -9,
      "name": "Empty"
    },
    {
      "x": -7,
      "y": 9,
      "z": -9,
      "name": "Cloth_Roof_Green_Flat"
    },
    {
      "x": -7,
      "y": 10,
      "z": -9,
      "name": "Empty"
    },
    {
      "x": -7,
      "y": 11,
      "z": -9,
      "name": "Empty"
    },
    {
      "x": -7,
      "y": 0,
      "z": -8,
      "name": "Rock_Sandstone_Cobble"
    },
    {
      "x": -7,
      "y": 1,
      "z": -8,
      "name": "Rock_Sandstone_Cobble"
    },
    {
      "x": -7,
      "y": 2,
      "z": -8,
      "name": "Rock_Sandstone_Cobble"
    },
    {
      "x": -7,
      "y": 3,
      "z": -8,
      "name": "Rock_Sandstone_Cobble"
    },
    {
      "x": -7,
      "y": 4,
      "z": -8,
      "name": "Rock_Sandstone_Cobble"
    },
    {
      "x": -7,
      "y": 5,
      "z": -8,
      "name": "Soil_Dirt_Dry"
    },
    {
      "x": -7,
      "y": 6,
      "z": -8,
      "name": "Empty"
    },
    {
      "x": -7,
      "y": 7,
      "z": -8,
      "name": "Empty"
    },
    {
      "x": -7,
      "y": 8,
      "z": -8,
      "name": "Empty"
    },
    {
      "x": -7,
      "y": 9,
      "z": -8,
      "name": "Cloth_Roof_Green_Flat"
    },
    {
      "x": -7,
      "y": 10,
      "z": -8,
      "name": "Empty"
    },
    {
      "x": -7,
      "y": 11,
      "z": -8,
      "name": "Empty"
    },
    {
      "x": -7,
      "y": 0,
      "z": -7,
      "name": "Rock_Sandstone_Cobble"
    },
    {
      "x": -7,
      "y": 1,
      "z": -7,
      "name": "Rock_Sandstone_Cobble"
    },
    {
      "x": -7,
      "y": 2,
      "z": -7,
      "name": "Rock_Sandstone_Cobble"
    },
    {
      "x": -7,
      "y": 3,
      "z": -7,
      "name": "Rock_Sandstone_Cobble"
    },
    {
      "x": -7,
      "y": 4,
      "z": -7,
      "name": "Rock_Sandstone_Cobble"
    },
    {
      "x": -7,
      "y": 5,
      "z": -7,
      "name": "Soil_Dirt_Dry"
    },
    {
      "x": -7,
      "y": 6,
      "z": -7,
      "name": "Empty"
    },
    {
      "x": -7,
      "y": 7,
      "z": -7,
      "name": "Empty"
    },
    {
      "x": -7,
      "y": 8,
      "z": -7,
      "name": "Empty"
    },
    {
      "x": -7,
      "y": 9,
      "z": -7,
      "name": "Cloth_Roof_Orange_Flat"
    },
    {
      "x": -7,
      "y": 10,
      "z": -7,
      "name": "Empty"
    },
    {
      "x": -7,
      "y": 11,
      "z": -7,
      "name": "Empty"
    },
    {
      "x": -7,
      "y": 0,
      "z": -6,
      "name": "Rock_Sandstone_Cobble"
    },
    {
      "x": -7,
      "y": 1,
      "z": -6,
      "name": "Rock_Sandstone_Cobble"
    },
    {
      "x": -7,
      "y": 2,
      "z": -6,
      "name": "Rock_Sandstone_Cobble"
    },
    {
      "x": -7,
      "y": 3,
      "z": -6,
      "name": "Rock_Sandstone_Cobble"
    },
    {
      "x": -7,
      "y": 4,
      "z": -6,
      "name": "Rock_Sandstone_Cobble"
    },
    {
      "x": -7,
      "y": 5,
      "z": -6,
      "name": "Soil_Dirt_Dry"
    },
    {
      "x": -7,
      "y": 6,
      "z": -6,
      "name": "Empty"
    },
    {
      "x": -7,
      "y": 7,
      "z": -6,
      "name": "Empty"
    },
    {
      "x": -7,
      "y": 8,
      "z": -6,
      "name": "Empty"
    },
    {
      "x": -7,
      "y": 9,
      "z": -6,
      "name": "Empty"
    },
    {
      "x": -7,
      "y": 10,
      "z": -6,
      "name": "Empty"
    },
    {
      "x": -7,
      "y": 11,
      "z": -6,
      "name": "Empty"
    },
    {
      "x": -7,
      "y": 0,
      "z": -5,
      "name": "Rock_Sandstone_Cobble"
    },
    {
      "x": -7,
      "y": 1,
      "z": -5,
      "name": "Rock_Sandstone_Cobble"
    },
    {
      "x": -7,
      "y": 2,
      "z": -5,
      "name": "Rock_Sandstone_Cobble"
    },
    {
      "x": -7,
      "y": 3,
      "z": -5,
      "name": "Rock_Sandstone_Cobble"
    },
    {
      "x": -7,
      "y": 4,
      "z": -5,
      "name": "Rock_Sandstone_Cobble"
    },
    {
      "x": -7,
      "y": 5,
      "z": -5,
      "name": "Soil_Dirt_Dry"
    },
    {
      "x": -7,
      "y": 6,
      "z": -5,
      "name": "Wood_Drywood_Beam"
    },
    {
      "x": -7,
      "y": 7,
      "z": -5,
      "name": "Wood_Drywood_Beam"
    },
    {
      "x": -7,
      "y": 8,
      "z": -5,
      "name": "Wood_Drywood_Beam"
    },
    {
      "x": -7,
      "y": 9,
      "z": -5,
      "name": "Cloth_Roof_Orange_Flat"
    },
    {
      "x": -7,
      "y": 10,
      "z": -5,
      "name": "Empty"
    },
    {
      "x": -7,
      "y": 11,
      "z": -5,
      "name": "Empty"
    },
    {
      "x": -7,
      "y": 0,
      "z": -4,
      "name": "Rock_Sandstone_Cobble"
    },
    {
      "x": -7,
      "y": 1,
      "z": -4,
      "name": "Rock_Sandstone_Cobble"
    },
    {
      "x": -7,
      "y": 2,
      "z": -4,
      "name": "Rock_Sandstone_Cobble"
    },
    {
      "x": -7,
      "y": 3,
      "z": -4,
      "name": "Rock_Sandstone_Cobble"
    },
    {
      "x": -7,
      "y": 4,
      "z": -4,
      "name": "Rock_Sandstone_Cobble"
    },
    {
      "x": -7,
      "y": 5,
      "z": -4,
      "name": "Soil_Dirt_Dry"
    },
    {
      "x": -7,
      "y": 6,
      "z": -4,
      "name": "Furniture_Village_Pot"
    },
    {
      "x": -7,
      "y": 7,
      "z": -4,
      "name": "Cloth_Roof_Orange_Vertical",
      "rotation": 2
    },
    {
      "x": -7,
      "y": 8,
      "z": -4,
      "name": "Cloth_Roof_Orange"
    },
    {
      "x": -7,
      "y": 9,
      "z": -4,
      "name": "Empty"
    },
    {
      "x": -7,
      "y": 10,
      "z": -4,
      "name": "Empty"
    },
    {
      "x": -7,
      "y": 11,
      "z": -4,
      "name": "Empty"
    },
    {
      "x": -7,
      "y": 0,
      "z": -3,
      "name": "Rock_Sandstone_Brick"
    },
    {
      "x": -7,
      "y": 1,
      "z": -3,
      "name": "Rock_Sandstone_Brick"
    },
    {
      "x": -7,
      "y": 2,
      "z": -3,
      "name": "Rock_Sandstone_Brick"
    },
    {
      "x": -7,
      "y": 3,
      "z": -3,
      "name": "Rock_Sandstone_Brick"
    },
    {
      "x": -7,
      "y": 4,
      "z": -3,
      "name": "Rock_Sandstone_Brick"
    },
    {
      "x": -7,
      "y": 5,
      "z": -3,
      "name": "Rock_Sandstone_Brick"
    },
    {
      "x": -7,
      "y": 6,
      "z": -3,
      "name": "Rock_Sandstone_Brick"
    },
    {
      "x": -7,
      "y": 7,
      "z": -3,
      "name": "Rock_Sandstone_Brick_Stairs",
      "rotation": 3
    },
    {
      "x": -6,
      "y": 8,
      "z": -12,
      "name": "Cloth_Roof_Green_Flap",
      "rotation": 2
    },
    {
      "x": -6,
      "y": 0,
      "z": -11,
      "name": "Rock_Sandstone_Brick"
    },
    {
      "x": -6,
      "y": 1,
      "z": -11,
      "name": "Rock_Sandstone_Brick"
    },
    {
      "x": -6,
      "y": 2,
      "z": -11,
      "name": "Rock_Sandstone_Brick"
    },
    {
      "x": -6,
      "y": 3,
      "z": -11,
      "name": "Rock_Sandstone_Brick"
    },
    {
      "x": -6,
      "y": 4,
      "z": -11,
      "name": "Rock_Sandstone_Brick"
    },
    {
      "x": -6,
      "y": 5,
      "z": -11,
      "name": "Rock_Sandstone_Brick"
    },
    {
      "x": -6,
      "y": 6,
      "z": -11,
      "name": "Rock_Sandstone_Brick"
    },
    {
      "x": -6,
      "y": 7,
      "z": -11,
      "name": "Rock_Sandstone_Brick"
    },
    {
      "x": -6,
      "y": 8,
      "z": -11,
      "name": "Rock_Sandstone_Brick_Half"
    },
    {
      "x": -6,
      "y": 9,
      "z": -11,
      "name": "*Cloth_Roof_Green_State_Definitions_Corner_Right",
      "rotation": 3
    },
    {
      "x": -6,
      "y": 10,
      "z": -11,
      "name": "Empty"
    },
    {
      "x": -6,
      "y": 11,
      "z": -11,
      "name": "Empty"
    },
    {
      "x": -6,
      "y": 0,
      "z": -10,
      "name": "Rock_Sandstone_Cobble"
    },
    {
      "x": -6,
      "y": 1,
      "z": -10,
      "name": "Rock_Sandstone_Cobble"
    },
    {
      "x": -6,
      "y": 2,
      "z": -10,
      "name": "Rock_Sandstone_Cobble"
    },
    {
      "x": -6,
      "y": 3,
      "z": -10,
      "name": "Rock_Sandstone_Cobble"
    },
    {
      "x": -6,
      "y": 4,
      "z": -10,
      "name": "Rock_Sandstone_Cobble"
    },
    {
      "x": -6,
      "y": 5,
      "z": -10,
      "name": "Soil_Dirt_Dry"
    },
    {
      "x": -6,
      "y": 6,
      "z": -10,
      "name": "Furniture_Temple_Dark_Pot"
    },
    {
      "x": -6,
      "y": 7,
      "z": -10,
      "name": "Empty"
    },
    {
      "x": -6,
      "y": 8,
      "z": -10,
      "name": "Empty"
    },
    {
      "x": -6,
      "y": 9,
      "z": -10,
      "name": "Cloth_Roof_Green",
      "rotation": 3
    },
    {
      "x": -6,
      "y": 10,
      "z": -10,
      "name": "Empty"
    },
    {
      "x": -6,
      "y": 11,
      "z": -10,
      "name": "Empty"
    },
    {
      "x": -6,
      "y": 0,
      "z": -9,
      "name": "Rock_Sandstone_Cobble"
    },
    {
      "x": -6,
      "y": 1,
      "z": -9,
      "name": "Rock_Sandstone_Cobble"
    },
    {
      "x": -6,
      "y": 2,
      "z": -9,
      "name": "Rock_Sandstone_Cobble"
    },
    {
      "x": -6,
      "y": 3,
      "z": -9,
      "name": "Rock_Sandstone_Cobble"
    },
    {
      "x": -6,
      "y": 4,
      "z": -9,
      "name": "Rock_Sandstone_Cobble"
    },
    {
      "x": -6,
      "y": 5,
      "z": -9,
      "name": "Soil_Dirt_Dry"
    },
    {
      "x": -6,
      "y": 6,
      "z": -9,
      "name": "Empty"
    },
    {
      "x": -6,
      "y": 7,
      "z": -9,
      "name": "Empty"
    },
    {
      "x": -6,
      "y": 8,
      "z": -9,
      "name": "Empty"
    },
    {
      "x": -6,
      "y": 9,
      "z": -9,
      "name": "Cloth_Roof_Green",
      "rotation": 3
    },
    {
      "x": -6,
      "y": 10,
      "z": -9,
      "name": "Empty"
    },
    {
      "x": -6,
      "y": 11,
      "z": -9,
      "name": "Empty"
    },
    {
      "x": -6,
      "y": 0,
      "z": -8,
      "name": "Rock_Sandstone_Cobble"
    },
    {
      "x": -6,
      "y": 1,
      "z": -8,
      "name": "Rock_Sandstone_Cobble"
    },
    {
      "x": -6,
      "y": 2,
      "z": -8,
      "name": "Rock_Sandstone_Cobble"
    },
    {
      "x": -6,
      "y": 3,
      "z": -8,
      "name": "Rock_Sandstone_Cobble"
    },
    {
      "x": -6,
      "y": 4,
      "z": -8,
      "name": "Rock_Sandstone_Cobble"
    },
    {
      "x": -6,
      "y": 5,
      "z": -8,
      "name": "Soil_Dirt_Dry"
    },
    {
      "x": -6,
      "y": 6,
      "z": -8,
      "name": "Empty"
    },
    {
      "x": -6,
      "y": 7,
      "z": -8,
      "name": "Empty"
    },
    {
      "x": -6,
      "y": 8,
      "z": -8,
      "name": "Empty"
    },
    {
      "x": -6,
      "y": 9,
      "z": -8,
      "name": "Wood_Drywood_Beam",
      "rotation": 5
    },
    {
      "x": -6,
      "y": 10,
      "z": -8,
      "name": "Empty"
    },
    {
      "x": -6,
      "y": 11,
      "z": -8,
      "name": "Empty"
    },
    {
      "x": -6,
      "y": 0,
      "z": -7,
      "name": "Rock_Sandstone_Cobble"
    },
    {
      "x": -6,
      "y": 1,
      "z": -7,
      "name": "Rock_Sandstone_Cobble"
    },
    {
      "x": -6,
      "y": 2,
      "z": -7,
      "name": "Rock_Sandstone_Cobble"
    },
    {
      "x": -6,
      "y": 3,
      "z": -7,
      "name": "Rock_Sandstone_Cobble"
    },
    {
      "x": -6,
      "y": 4,
      "z": -7,
      "name": "Rock_Sandstone_Cobble"
    },
    {
      "x": -6,
      "y": 5,
      "z": -7,
      "name": "Soil_Dirt_Dry"
    },
    {
      "x": -6,
      "y": 6,
      "z": -7,
      "name": "Empty"
    },
    {
      "x": -6,
      "y": 7,
      "z": -7,
      "name": "Empty"
    },
    {
      "x": -6,
      "y": 8,
      "z": -7,
      "name": "Empty"
    },
    {
      "x": -6,
      "y": 9,
      "z": -7,
      "name": "Cloth_Roof_Orange",
      "rotation": 3
    },
    {
      "x": -6,
      "y": 10,
      "z": -7,
      "name": "Empty"
    },
    {
      "x": -6,
      "y": 11,
      "z": -7,
      "name": "Empty"
    },
    {
      "x": -6,
      "y": 0,
      "z": -6,
      "name": "Rock_Sandstone_Cobble"
    },
    {
      "x": -6,
      "y": 1,
      "z": -6,
      "name": "Rock_Sandstone_Cobble"
    },
    {
      "x": -6,
      "y": 2,
      "z": -6,
      "name": "Rock_Sandstone_Cobble"
    },
    {
      "x": -6,
      "y": 3,
      "z": -6,
      "name": "Rock_Sandstone_Cobble"
    },
    {
      "x": -6,
      "y": 4,
      "z": -6,
      "name": "Rock_Sandstone_Cobble"
    },
    {
      "x": -6,
      "y": 5,
      "z": -6,
      "name": "Soil_Dirt_Dry"
    },
    {
      "x": -6,
      "y": 6,
      "z": -6,
      "name": "Empty"
    },
    {
      "x": -6,
      "y": 7,
      "z": -6,
      "name": "Empty"
    },
    {
      "x": -6,
      "y": 8,
      "z": -6,
      "name": "Empty"
    },
    {
      "x": -6,
      "y": 9,
      "z": -6,
      "name": "Cloth_Roof_Orange",
      "rotation": 3
    },
    {
      "x": -6,
      "y": 10,
      "z": -6,
      "name": "Empty"
    },
    {
      "x": -6,
      "y": 11,
      "z": -6,
      "name": "Empty"
    },
    {
      "x": -6,
      "y": 0,
      "z": -5,
      "name": "Rock_Sandstone_Cobble"
    },
    {
      "x": -6,
      "y": 1,
      "z": -5,
      "name": "Rock_Sandstone_Cobble"
    },
    {
      "x": -6,
      "y": 2,
      "z": -5,
      "name": "Rock_Sandstone_Cobble"
    },
    {
      "x": -6,
      "y": 3,
      "z": -5,
      "name": "Rock_Sandstone_Cobble"
    },
    {
      "x": -6,
      "y": 4,
      "z": -5,
      "name": "Rock_Sandstone_Cobble"
    },
    {
      "x": -6,
      "y": 5,
      "z": -5,
      "name": "Soil_Dirt_Dry"
    },
    {
      "x": -6,
      "y": 6,
      "z": -5,
      "name": "Furniture_Temple_Wind_Pot"
    },
    {
      "x": -6,
      "y": 7,
      "z": -5,
      "name": "Furniture_Temple_Wind_Pot",
      "filler": 1024
    },
    {
      "x": -6,
      "y": 8,
      "z": -5,
      "name": "Empty"
    },
    {
      "x": -6,
      "y": 9,
      "z": -5,
      "name": "*Cloth_Roof_Orange_State_Definitions_Corner_Right"
    },
    {
      "x": -6,
      "y": 10,
      "z": -5,
      "name": "Empty"
    },
    {
      "x": -6,
      "y": 11,
      "z": -5,
      "name": "Empty"
    },
    {
      "x": -6,
      "y": 0,
      "z": -4,
      "name": "Rock_Sandstone_Cobble"
    },
    {
      "x": -6,
      "y": 1,
      "z": -4,
      "name": "Rock_Sandstone_Cobble"
    },
    {
      "x": -6,
      "y": 2,
      "z": -4,
      "name": "Rock_Sandstone_Cobble"
    },
    {
      "x": -6,
      "y": 3,
      "z": -4,
      "name": "Rock_Sandstone_Cobble"
    },
    {
      "x": -6,
      "y": 4,
      "z": -4,
      "name": "Rock_Sandstone_Cobble"
    },
    {
      "x": -6,
      "y": 5,
      "z": -4,
      "name": "Soil_Dirt_Dry"
    },
    {
      "x": -6,
      "y": 6,
      "z": -4,
      "name": "Furniture_Village_Pot"
    },
    {
      "x": -6,
      "y": 7,
      "z": -4,
      "name": "Cloth_Roof_Orange_Vertical",
      "rotation": 2
    },
    {
      "x": -6,
      "y": 8,
      "z": -4,
      "name": "Cloth_Roof_Orange"
    },
    {
      "x": -6,
      "y": 9,
      "z": -4,
      "name": "Empty"
    },
    {
      "x": -6,
      "y": 10,
      "z": -4,
      "name": "Empty"
    },
    {
      "x": -6,
      "y": 11,
      "z": -4,
      "name": "Empty"
    },
    {
      "x": -6,
      "y": 0,
      "z": -3,
      "name": "Rock_Sandstone_Brick"
    },
    {
      "x": -6,
      "y": 1,
      "z": -3,
      "name": "Rock_Sandstone_Brick"
    },
    {
      "x": -6,
      "y": 2,
      "z": -3,
      "name": "Rock_Sandstone_Brick"
    },
    {
      "x": -6,
      "y": 3,
      "z": -3,
      "name": "Rock_Sandstone_Brick"
    },
    {
      "x": -6,
      "y": 4,
      "z": -3,
      "name": "Rock_Sandstone_Brick"
    },
    {
      "x": -6,
      "y": 5,
      "z": -3,
      "name": "Rock_Sandstone_Brick"
    },
    {
      "x": -6,
      "y": 6,
      "z": -3,
      "name": "Rock_Sandstone_Brick"
    },
    {
      "x": -6,
      "y": 7,
      "z": -3,
      "name": "Rock_Sandstone_Brick"
    },
    {
      "x": -6,
      "y": 8,
      "z": -3,
      "name": "Rock_Sandstone_Brick_Stairs",
      "rotation": 3
    },
    {
      "x": -6,
      "y": 21,
      "z": -1,
      "name": "Wood_Dry_Branch_Short",
      "rotation": 3
    },
    {
      "x": -6,
      "y": 0,
      "z": 3,
      "name": "Rock_Sandstone_Cobble"
    },
    {
      "x": -6,
      "y": 1,
      "z": 3,
      "name": "Rock_Sandstone_Cobble"
    },
    {
      "x": -6,
      "y": 2,
      "z": 3,
      "name": "Rock_Sandstone_Cobble"
    },
    {
      "x": -6,
      "y": 3,
      "z": 3,
      "name": "Rock_Sandstone_Cobble"
    },
    {
      "x": -6,
      "y": 4,
      "z": 3,
      "name": "Rock_Sandstone_Cobble"
    },
    {
      "x": -6,
      "y": 5,
      "z": 3,
      "name": "Rock_Sandstone_Cobble"
    },
    {
      "x": -6,
      "y": 6,
      "z": 3,
      "name": "Rock_Sandstone_Brick"
    },
    {
      "x": -6,
      "y": 7,
      "z": 3,
      "name": "Rock_Sandstone_Brick"
    },
    {
      "x": -6,
      "y": 8,
      "z": 3,
      "name": "Rock_Sandstone_Brick"
    },
    {
      "x": -6,
      "y": 9,
      "z": 3,
      "name": "Rock_Sandstone_Brick"
    },
    {
      "x": -6,
      "y": 10,
      "z": 3,
      "name": "Rock_Sandstone_Brick"
    },
    {
      "x": -6,
      "y": 11,
      "z": 3,
      "name": "Rock_Sandstone_Brick_Half",
      "rotation": 7
    },
    {
      "x": -6,
      "y": 12,
      "z": 3,
      "name": "Rock_Sandstone_Brick_Half",
      "rotation": 7
    },
    {
      "x": -6,
      "y": 13,
      "z": 3,
      "name": "Rock_Sandstone_Brick_Half",
      "rotation": 7
    },
    {
      "x": -6,
      "y": 14,
      "z": 3,
      "name": "Rock_Sandstone_Brick_Half",
      "rotation": 7
    },
    {
      "x": -6,
      "y": 15,
      "z": 3,
      "name": "Rock_Sandstone_Brick_Half",
      "rotation": 7
    },
    {
      "x": -6,
      "y": 21,
      "z": 3,
      "name": "Wood_Dry_Branch_Short",
      "rotation": 3
    },
    {
      "x": -6,
      "y": 0,
      "z": 4,
      "name": "Rock_Sandstone_Cobble"
    },
    {
      "x": -6,
      "y": 1,
      "z": 4,
      "name": "Rock_Sandstone_Cobble"
    },
    {
      "x": -6,
      "y": 2,
      "z": 4,
      "name": "Rock_Sandstone_Cobble"
    },
    {
      "x": -6,
      "y": 3,
      "z": 4,
      "name": "Rock_Sandstone_Cobble"
    },
    {
      "x": -6,
      "y": 4,
      "z": 4,
      "name": "Rock_Sandstone_Cobble"
    },
    {
      "x": -6,
      "y": 5,
      "z": 4,
      "name": "Rock_Sandstone_Cobble"
    },
    {
      "x": -6,
      "y": 6,
      "z": 4,
      "name": "Rock_Sandstone_Brick"
    },
    {
      "x": -6,
      "y": 7,
      "z": 4,
      "name": "Rock_Sandstone_Brick"
    },
    {
      "x": -6,
      "y": 8,
      "z": 4,
      "name": "Rock_Sandstone_Brick"
    },
    {
      "x": -6,
      "y": 9,
      "z": 4,
      "name": "Rock_Sandstone_Brick"
    },
    {
      "x": -6,
      "y": 10,
      "z": 4,
      "name": "Rock_Sandstone_Brick"
    },
    {
      "x": -6,
      "y": 11,
      "z": 4,
      "name": "Rock_Sandstone_Brick_Half",
      "rotation": 7
    },
    {
      "x": -6,
      "y": 12,
      "z": 4,
      "name": "Rock_Sandstone_Brick_Half",
      "rotation": 7
    },
    {
      "x": -6,
      "y": 13,
      "z": 4,
      "name": "Rock_Sandstone_Brick_Half",
      "rotation": 7
    },
    {
      "x": -6,
      "y": 14,
      "z": 4,
      "name": "Rock_Sandstone_Brick_Half",
      "rotation": 7
    },
    {
      "x": -6,
      "y": 15,
      "z": 4,
      "name": "Rock_Sandstone_Brick_Half",
      "rotation": 7
    },
    {
      "x": -6,
      "y": 17,
      "z": 5,
      "name": "Rock_Sandstone_Brick_Smooth_Half",
      "rotation": 7
    },
    {
      "x": -6,
      "y": 19,
      "z": 5,
      "name": "Wood_Drywood_Roof_Hollow",
      "rotation": 3
    },
    {
      "x": -6,
      "y": 17,
      "z": 6,
      "name": "Rock_Sandstone_Brick_Smooth_Half",
      "rotation": 7
    },
    {
      "x": -6,
      "y": 19,
      "z": 6,
      "name": "Wood_Drywood_Roof_Hollow",
      "rotation": 3
    },
    {
      "x": -6,
      "y": 21,
      "z": 7,
      "name": "Wood_Dry_Branch_Short",
      "rotation": 3
    },
    {
      "x": -5,
      "y": 0,
      "z": -11,
      "name": "Rock_Sandstone_Brick"
    },
    {
      "x": -5,
      "y": 1,
      "z": -11,
      "name": "Rock_Sandstone_Brick"
    },
    {
      "x": -5,
      "y": 2,
      "z": -11,
      "name": "Rock_Sandstone_Brick"
    },
    {
      "x": -5,
      "y": 3,
      "z": -11,
      "name": "Rock_Sandstone_Brick"
    },
    {
      "x": -5,
      "y": 4,
      "z": -11,
      "name": "Rock_Sandstone_Brick"
    },
    {
      "x": -5,
      "y": 5,
      "z": -11,
      "name": "Rock_Sandstone_Brick"
    },
    {
      "x": -5,
      "y": 6,
      "z": -11,
      "name": "Rock_Sandstone_Brick_Pillar_Base"
    },
    {
      "x": -5,
      "y": 7,
      "z": -11,
      "name": "Rock_Sandstone_Brick_Pillar_Middle"
    },
    {
      "x": -5,
      "y": 8,
      "z": -11,
      "name": "Rock_Sandstone_Brick_Pillar_Base",
      "rotation": 8
    },
    {
      "x": -5,
      "y": 9,
      "z": -11,
      "name": "Rock_Sandstone_Brick"
    },
    {
      "x": -5,
      "y": 10,
      "z": -11,
      "name": "Empty"
    },
    {
      "x": -5,
      "y": 11,
      "z": -11,
      "name": "Empty"
    },
    {
      "x": -5,
      "y": 12,
      "z": -11,
      "name": "Empty"
    },
    {
      "x": -5,
      "y": 13,
      "z": -11,
      "name": "Empty"
    },
    {
      "x": -5,
      "y": 14,
      "z": -11,
      "name": "Empty"
    },
    {
      "x": -5,
      "y": 15,
      "z": -11,
      "name": "Empty"
    },
    {
      "x": -5,
      "y": 0,
      "z": -10,
      "name": "Rock_Sandstone_Cobble"
    },
    {
      "x": -5,
      "y": 1,
      "z": -10,
      "name": "Rock_Sandstone_Cobble"
    },
    {
      "x": -5,
      "y": 2,
      "z": -10,
      "name": "Rock_Sandstone_Cobble"
    },
    {
      "x": -5,
      "y": 3,
      "z": -10,
      "name": "Rock_Sandstone_Cobble"
    },
    {
      "x": -5,
      "y": 4,
      "z": -10,
      "name": "Rock_Sandstone_Cobble"
    },
    {
      "x": -5,
      "y": 5,
      "z": -10,
      "name": "Soil_Dirt_Dry"
    },
    {
      "x": -5,
      "y": 6,
      "z": -10,
      "name": "Empty"
    },
    {
      "x": -5,
      "y": 7,
      "z": -10,
      "name": "Empty"
    },
    {
      "x": -5,
      "y": 8,
      "z": -10,
      "name": "Empty"
    },
    {
      "x": -5,
      "y": 9,
      "z": -10,
      "name": "Rock_Sandstone_Brick_Stairs",
      "rotation": 10
    },
    {
      "x": -5,
      "y": 10,
      "z": -10,
      "name": "Cloth_Roof_Green_Flat"
    },
    {
      "x": -5,
      "y": 11,
      "z": -10,
      "name": "Empty"
    },
    {
      "x": -5,
      "y": 12,
      "z": -10,
      "name": "Empty"
    },
    {
      "x": -5,
      "y": 13,
      "z": -10,
      "name": "Empty"
    },
    {
      "x": -5,
      "y": 14,
      "z": -10,
      "name": "Empty"
    },
    {
      "x": -5,
      "y": 15,
      "z": -10,
      "name": "Empty"
    },
    {
      "x": -5,
      "y": 0,
      "z": -9,
      "name": "Rock_Sandstone_Cobble"
    },
    {
      "x": -5,
      "y": 1,
      "z": -9,
      "name": "Rock_Sandstone_Cobble"
    },
    {
      "x": -5,
      "y": 2,
      "z": -9,
      "name": "Rock_Sandstone_Cobble"
    },
    {
      "x": -5,
      "y": 3,
      "z": -9,
      "name": "Rock_Sandstone_Cobble"
    },
    {
      "x": -5,
      "y": 4,
      "z": -9,
      "name": "Rock_Sandstone_Cobble"
    },
    {
      "x": -5,
      "y": 5,
      "z": -9,
      "name": "Soil_Dirt_Dry"
    },
    {
      "x": -5,
      "y": 6,
      "z": -9,
      "name": "Empty"
    },
    {
      "x": -5,
      "y": 7,
      "z": -9,
      "name": "Empty"
    },
    {
      "x": -5,
      "y": 8,
      "z": -9,
      "name": "Empty"
    },
    {
      "x": -5,
      "y": 9,
      "z": -9,
      "name": "Rock_Sandstone_Brick_Stairs",
      "rotation": 8
    },
    {
      "x": -5,
      "y": 10,
      "z": -9,
      "name": "Cloth_Roof_Green_Flat"
    },
    {
      "x": -5,
      "y": 11,
      "z": -9,
      "name": "Empty"
    },
    {
      "x": -5,
      "y": 12,
      "z": -9,
      "name": "Empty"
    },
    {
      "x": -5,
      "y": 13,
      "z": -9,
      "name": "Empty"
    },
    {
      "x": -5,
      "y": 14,
      "z": -9,
      "name": "Empty"
    },
    {
      "x": -5,
      "y": 15,
      "z": -9,
      "name": "Empty"
    },
    {
      "x": -5,
      "y": 0,
      "z": -8,
      "name": "Rock_Sandstone_Brick"
    },
    {
      "x": -5,
      "y": 1,
      "z": -8,
      "name": "Rock_Sandstone_Brick"
    },
    {
      "x": -5,
      "y": 2,
      "z": -8,
      "name": "Rock_Sandstone_Brick"
    },
    {
      "x": -5,
      "y": 3,
      "z": -8,
      "name": "Rock_Sandstone_Brick"
    },
    {
      "x": -5,
      "y": 4,
      "z": -8,
      "name": "Rock_Sandstone_Brick"
    },
    {
      "x": -5,
      "y": 5,
      "z": -8,
      "name": "Rock_Sandstone_Brick"
    },
    {
      "x": -5,
      "y": 6,
      "z": -8,
      "name": "Rock_Sandstone_Brick_Pillar_Base"
    },
    {
      "x": -5,
      "y": 7,
      "z": -8,
      "name": "Rock_Sandstone_Brick_Pillar_Middle"
    },
    {
      "x": -5,
      "y": 8,
      "z": -8,
      "name": "Rock_Sandstone_Brick_Pillar_Base",
      "rotation": 8
    },
    {
      "x": -5,
      "y": 9,
      "z": -8,
      "name": "Rock_Sandstone_Brick"
    },
    {
      "x": -5,
      "y": 10,
      "z": -8,
      "name": "Cloth_Roof_Green_Flat"
    },
    {
      "x": -5,
      "y": 11,
      "z": -8,
      "name": "Empty"
    },
    {
      "x": -5,
      "y": 12,
      "z": -8,
      "name": "Empty"
    },
    {
      "x": -5,
      "y": 13,
      "z": -8,
      "name": "Empty"
    },
    {
      "x": -5,
      "y": 14,
      "z": -8,
      "name": "Empty"
    },
    {
      "x": -5,
      "y": 15,
      "z": -8,
      "name": "Empty"
    },
    {
      "x": -5,
      "y": 0,
      "z": -7,
      "name": "Rock_Sandstone_Cobble"
    },
    {
      "x": -5,
      "y": 1,
      "z": -7,
      "name": "Rock_Sandstone_Cobble"
    },
    {
      "x": -5,
      "y": 2,
      "z": -7,
      "name": "Rock_Sandstone_Cobble"
    },
    {
      "x": -5,
      "y": 3,
      "z": -7,
      "name": "Rock_Sandstone_Cobble"
    },
    {
      "x": -5,
      "y": 4,
      "z": -7,
      "name": "Rock_Sandstone_Cobble"
    },
    {
      "x": -5,
      "y": 5,
      "z": -7,
      "name": "Soil_Dirt_Dry"
    },
    {
      "x": -5,
      "y": 6,
      "z": -7,
      "name": "Bench_WorkBench",
      "components": {
        "Components": {
          "crafting": {
            "Position": {
              "X": 27,
              "Y": 6,
              "Z": 25
            },
            "TierLevel": 1,
            "UpgradeItems": []
          }
        }
      },
      "filler": 992,
      "rotation": 3
    },
    {
      "x": -5,
      "y": 7,
      "z": -7,
      "name": "Empty"
    },
    {
      "x": -5,
      "y": 8,
      "z": -7,
      "name": "Empty"
    },
    {
      "x": -5,
      "y": 9,
      "z": -7,
      "name": "Rock_Sandstone_Brick_Stairs",
      "rotation": 10
    },
    {
      "x": -5,
      "y": 10,
      "z": -7,
      "name": "Cloth_Roof_Orange_Flat"
    },
    {
      "x": -5,
      "y": 11,
      "z": -7,
      "name": "Empty"
    },
    {
      "x": -5,
      "y": 12,
      "z": -7,
      "name": "Empty"
    },
    {
      "x": -5,
      "y": 13,
      "z": -7,
      "name": "Empty"
    },
    {
      "x": -5,
      "y": 14,
      "z": -7,
      "name": "Empty"
    },
    {
      "x": -5,
      "y": 15,
      "z": -7,
      "name": "Empty"
    },
    {
      "x": -5,
      "y": 0,
      "z": -6,
      "name": "Rock_Sandstone_Cobble"
    },
    {
      "x": -5,
      "y": 1,
      "z": -6,
      "name": "Rock_Sandstone_Cobble"
    },
    {
      "x": -5,
      "y": 2,
      "z": -6,
      "name": "Rock_Sandstone_Cobble"
    },
    {
      "x": -5,
      "y": 3,
      "z": -6,
      "name": "Rock_Sandstone_Cobble"
    },
    {
      "x": -5,
      "y": 4,
      "z": -6,
      "name": "Rock_Sandstone_Cobble"
    },
    {
      "x": -5,
      "y": 5,
      "z": -6,
      "name": "Soil_Dirt_Dry"
    },
    {
      "x": -5,
      "y": 6,
      "z": -6,
      "name": "Bench_WorkBench",
      "components": {
        "Components": {
          "crafting": {
            "Position": {
              "X": 27,
              "Y": 61,
              "Z": 25
            },
            "TierLevel": 1,
            "UpgradeItems": []
          }
        }
      },
      "rotation": 3
    },
    {
      "x": -5,
      "y": 7,
      "z": -6,
      "name": "Empty"
    },
    {
      "x": -5,
      "y": 8,
      "z": -6,
      "name": "Empty"
    },
    {
      "x": -5,
      "y": 9,
      "z": -6,
      "name": "Rock_Sandstone_Brick_Stairs",
      "rotation": 8
    },
    {
      "x": -5,
      "y": 10,
      "z": -6,
      "name": "Cloth_Roof_Orange_Flat"
    },
    {
      "x": -5,
      "y": 11,
      "z": -6,
      "name": "Empty"
    },
    {
      "x": -5,
      "y": 12,
      "z": -6,
      "name": "Empty"
    },
    {
      "x": -5,
      "y": 13,
      "z": -6,
      "name": "Empty"
    },
    {
      "x": -5,
      "y": 14,
      "z": -6,
      "name": "Empty"
    },
    {
      "x": -5,
      "y": 15,
      "z": -6,
      "name": "Empty"
    },
    {
      "x": -5,
      "y": 0,
      "z": -5,
      "name": "Rock_Sandstone_Brick"
    },
    {
      "x": -5,
      "y": 1,
      "z": -5,
      "name": "Rock_Sandstone_Brick"
    },
    {
      "x": -5,
      "y": 2,
      "z": -5,
      "name": "Rock_Sandstone_Brick"
    },
    {
      "x": -5,
      "y": 3,
      "z": -5,
      "name": "Rock_Sandstone_Brick"
    },
    {
      "x": -5,
      "y": 4,
      "z": -5,
      "name": "Rock_Sandstone_Brick"
    },
    {
      "x": -5,
      "y": 5,
      "z": -5,
      "name": "Rock_Sandstone_Brick"
    },
    {
      "x": -5,
      "y": 6,
      "z": -5,
      "name": "Rock_Sandstone_Brick_Pillar_Base"
    },
    {
      "x": -5,
      "y": 7,
      "z": -5,
      "name": "Rock_Sandstone_Brick_Pillar_Middle"
    },
    {
      "x": -5,
      "y": 8,
      "z": -5,
      "name": "Rock_Sandstone_Brick_Pillar_Base",
      "rotation": 8
    },
    {
      "x": -5,
      "y": 9,
      "z": -5,
      "name": "Rock_Sandstone_Brick"
    },
    {
      "x": -5,
      "y": 10,
      "z": -5,
      "name": "Empty"
    },
    {
      "x": -5,
      "y": 11,
      "z": -5,
      "name": "Empty"
    },
    {
      "x": -5,
      "y": 12,
      "z": -5,
      "name": "Empty"
    },
    {
      "x": -5,
      "y": 13,
      "z": -5,
      "name": "Empty"
    },
    {
      "x": -5,
      "y": 14,
      "z": -5,
      "name": "Empty"
    },
    {
      "x": -5,
      "y": 15,
      "z": -5,
      "name": "Empty"
    },
    {
      "x": -5,
      "y": 0,
      "z": -4,
      "name": "Rock_Sandstone_Brick"
    },
    {
      "x": -5,
      "y": 1,
      "z": -4,
      "name": "Rock_Sandstone_Brick"
    },
    {
      "x": -5,
      "y": 2,
      "z": -4,
      "name": "Rock_Sandstone_Brick"
    },
    {
      "x": -5,
      "y": 3,
      "z": -4,
      "name": "Rock_Sandstone_Brick"
    },
    {
      "x": -5,
      "y": 4,
      "z": -4,
      "name": "Rock_Sandstone_Brick"
    },
    {
      "x": -5,
      "y": 5,
      "z": -4,
      "name": "Rock_Sandstone_Brick"
    },
    {
      "x": -5,
      "y": 6,
      "z": -4,
      "name": "Rock_Sandstone_Brick"
    },
    {
      "x": -5,
      "y": 7,
      "z": -4,
      "name": "Rock_Sandstone_Brick"
    },
    {
      "x": -5,
      "y": 8,
      "z": -4,
      "name": "Rock_Sandstone_Brick"
    },
    {
      "x": -5,
      "y": 9,
      "z": -4,
      "name": "Rock_Sandstone_Brick_Half",
      "rotation": 4
    },
    {
      "x": -5,
      "y": 10,
      "z": -4,
      "name": "Empty"
    },
    {
      "x": -5,
      "y": 11,
      "z": -4,
      "name": "Empty"
    },
    {
      "x": -5,
      "y": 12,
      "z": -4,
      "name": "Empty"
    },
    {
      "x": -5,
      "y": 13,
      "z": -4,
      "name": "Empty"
    },
    {
      "x": -5,
      "y": 14,
      "z": -4,
      "name": "Empty"
    },
    {
      "x": -5,
      "y": 15,
      "z": -4,
      "name": "Empty"
    },
    {
      "x": -5,
      "y": 0,
      "z": -3,
      "name": "Rock_Sandstone_Brick"
    },
    {
      "x": -5,
      "y": 1,
      "z": -3,
      "name": "Rock_Sandstone_Brick"
    },
    {
      "x": -5,
      "y": 2,
      "z": -3,
      "name": "Rock_Sandstone_Brick"
    },
    {
      "x": -5,
      "y": 3,
      "z": -3,
      "name": "Rock_Sandstone_Brick"
    },
    {
      "x": -5,
      "y": 4,
      "z": -3,
      "name": "Rock_Sandstone_Brick"
    },
    {
      "x": -5,
      "y": 5,
      "z": -3,
      "name": "Rock_Sandstone_Brick"
    },
    {
      "x": -5,
      "y": 6,
      "z": -3,
      "name": "Rock_Sandstone_Brick"
    },
    {
      "x": -5,
      "y": 7,
      "z": -3,
      "name": "Rock_Sandstone_Brick"
    },
    {
      "x": -5,
      "y": 8,
      "z": -3,
      "name": "Rock_Sandstone_Brick"
    },
    {
      "x": -5,
      "y": 9,
      "z": -3,
      "name": "Empty"
    },
    {
      "x": -5,
      "y": 10,
      "z": -3,
      "name": "Empty"
    },
    {
      "x": -5,
      "y": 11,
      "z": -3,
      "name": "Empty"
    },
    {
      "x": -5,
      "y": 12,
      "z": -3,
      "name": "Empty"
    },
    {
      "x": -5,
      "y": 13,
      "z": -3,
      "name": "Empty"
    },
    {
      "x": -5,
      "y": 14,
      "z": -3,
      "name": "Empty"
    },
    {
      "x": -5,
      "y": 15,
      "z": -3,
      "name": "Empty"
    },
    {
      "x": -5,
      "y": 0,
      "z": -2,
      "name": "Rock_Sandstone_Brick"
    },
    {
      "x": -5,
      "y": 1,
      "z": -2,
      "name": "Rock_Sandstone_Brick"
    },
    {
      "x": -5,
      "y": 2,
      "z": -2,
      "name": "Rock_Sandstone_Brick"
    },
    {
      "x": -5,
      "y": 3,
      "z": -2,
      "name": "Rock_Sandstone_Brick"
    },
    {
      "x": -5,
      "y": 4,
      "z": -2,
      "name": "Rock_Sandstone_Brick"
    },
    {
      "x": -5,
      "y": 5,
      "z": -2,
      "name": "Rock_Sandstone_Brick"
    },
    {
      "x": -5,
      "y": 6,
      "z": -2,
      "name": "Rock_Sandstone_Brick_Pillar_Base"
    },
    {
      "x": -5,
      "y": 7,
      "z": -2,
      "name": "Rock_Sandstone_Brick_Pillar_Middle"
    },
    {
      "x": -5,
      "y": 8,
      "z": -2,
      "name": "Wood_Drywood_Beam",
      "rotation": 4
    },
    {
      "x": -5,
      "y": 9,
      "z": -2,
      "name": "Empty"
    },
    {
      "x": -5,
      "y": 10,
      "z": -2,
      "name": "Empty"
    },
    {
      "x": -5,
      "y": 11,
      "z": -2,
      "name": "Empty"
    },
    {
      "x": -5,
      "y": 12,
      "z": -2,
      "name": "Empty"
    },
    {
      "x": -5,
      "y": 13,
      "z": -2,
      "name": "Empty"
    },
    {
      "x": -5,
      "y": 14,
      "z": -2,
      "name": "Empty"
    },
    {
      "x": -5,
      "y": 15,
      "z": -2,
      "name": "Rock_Sandstone_Brick_Half",
      "rotation": 8
    },
    {
      "x": -5,
      "y": 16,
      "z": -2,
      "name": "Rock_Sandstone_Brick_Decorative"
    },
    {
      "x": -5,
      "y": 17,
      "z": -2,
      "name": "Wood_Dry_Trunk"
    },
    {
      "x": -5,
      "y": 18,
      "z": -2,
      "name": "Wood_Dry_Trunk"
    },
    {
      "x": -5,
      "y": 19,
      "z": -2,
      "name": "Wood_Dry_Trunk"
    },
    {
      "x": -5,
      "y": 20,
      "z": -2,
      "name": "Wood_Dry_Trunk"
    },
    {
      "x": -5,
      "y": 21,
      "z": -2,
      "name": "Wood_Dry_Trunk"
    },
    {
      "x": -5,
      "y": 22,
      "z": -2,
      "name": "*Wood_Drywood_Fence_State_Definitions_Corner",
      "rotation": 1
    },
    {
      "x": -5,
      "y": 23,
      "z": -2,
      "name": "Empty"
    },
    {
      "x": -5,
      "y": 24,
      "z": -2,
      "name": "Empty"
    },
    {
      "x": -5,
      "y": 25,
      "z": -2,
      "name": "Empty"
    },
    {
      "x": -5,
      "y": 26,
      "z": -2,
      "name": "Empty"
    },
    {
      "x": -5,
      "y": 0,
      "z": -1,
      "name": "Rock_Sandstone_White_Cobble"
    },
    {
      "x": -5,
      "y": 1,
      "z": -1,
      "name": "Rock_Sandstone_White_Cobble"
    },
    {
      "x": -5,
      "y": 2,
      "z": -1,
      "name": "Rock_Sandstone_White_Cobble"
    },
    {
      "x": -5,
      "y": 3,
      "z": -1,
      "name": "Rock_Sandstone_White_Cobble"
    },
    {
      "x": -5,
      "y": 4,
      "z": -1,
      "name": "Rock_Sandstone_White_Cobble"
    },
    {
      "x": -5,
      "y": 5,
      "z": -1,
      "name": "Rock_Sandstone_White_Cobble"
    },
    {
      "x": -5,
      "y": 6,
      "z": -1,
      "name": "Empty"
    },
    {
      "x": -5,
      "y": 7,
      "z": -1,
      "name": "Empty"
    },
    {
      "x": -5,
      "y": 8,
      "z": -1,
      "name": "Wood_Drywood_Beam",
      "rotation": 4
    },
    {
      "x": -5,
      "y": 9,
      "z": -1,
      "name": "Empty"
    },
    {
      "x": -5,
      "y": 10,
      "z": -1,
      "name": "Empty"
    },
    {
      "x": -5,
      "y": 11,
      "z": -1,
      "name": "Empty"
    },
    {
      "x": -5,
      "y": 12,
      "z": -1,
      "name": "Empty"
    },
    {
      "x": -5,
      "y": 13,
      "z": -1,
      "name": "Empty"
    },
    {
      "x": -5,
      "y": 14,
      "z": -1,
      "name": "Empty"
    },
    {
      "x": -5,
      "y": 15,
      "z": -1,
      "name": "Rock_Sandstone_Brick"
    },
    {
      "x": -5,
      "y": 16,
      "z": -1,
      "name": "Rock_Sandstone_Brick_Decorative"
    },
    {
      "x": -5,
      "y": 17,
      "z": -1,
      "name": "Rock_Sandstone_White_Cobble"
    },
    {
      "x": -5,
      "y": 18,
      "z": -1,
      "name": "Rock_Sandstone_White_Cobble"
    },
    {
      "x": -5,
      "y": 19,
      "z": -1,
      "name": "Rock_Sandstone_White_Cobble"
    },
    {
      "x": -5,
      "y": 20,
      "z": -1,
      "name": "Rock_Sandstone_White_Cobble"
    },
    {
      "x": -5,
      "y": 21,
      "z": -1,
      "name": "Wood_Dry_Trunk",
      "rotation": 4
    },
    {
      "x": -5,
      "y": 22,
      "z": -1,
      "name": "Wood_Drywood_Fence",
      "rotation": 3
    },
    {
      "x": -5,
      "y": 23,
      "z": -1,
      "name": "Empty"
    },
    {
      "x": -5,
      "y": 24,
      "z": -1,
      "name": "Empty"
    },
    {
      "x": -5,
      "y": 25,
      "z": -1,
      "name": "Empty"
    },
    {
      "x": -5,
      "y": 26,
      "z": -1,
      "name": "Empty"
    },
    {
      "x": -5,
      "y": 0,
      "z": 0,
      "name": "Rock_Sandstone_White_Cobble"
    },
    {
      "x": -5,
      "y": 1,
      "z": 0,
      "name": "Rock_Sandstone_White_Cobble"
    },
    {
      "x": -5,
      "y": 2,
      "z": 0,
      "name": "Rock_Sandstone_White_Cobble"
    },
    {
      "x": -5,
      "y": 3,
      "z": 0,
      "name": "Rock_Sandstone_White_Cobble"
    },
    {
      "x": -5,
      "y": 4,
      "z": 0,
      "name": "Rock_Sandstone_White_Cobble"
    },
    {
      "x": -5,
      "y": 5,
      "z": 0,
      "name": "Rock_Sandstone_White_Cobble"
    },
    {
      "x": -5,
      "y": 6,
      "z": 0,
      "name": "Empty"
    },
    {
      "x": -5,
      "y": 7,
      "z": 0,
      "name": "Empty"
    },
    {
      "x": -5,
      "y": 8,
      "z": 0,
      "name": "Wood_Drywood_Beam",
      "rotation": 4
    },
    {
      "x": -5,
      "y": 9,
      "z": 0,
      "name": "Rock_Sandstone_Brick_Stairs",
      "rotation": 8
    },
    {
      "x": -5,
      "y": 10,
      "z": 0,
      "name": "Empty"
    },
    {
      "x": -5,
      "y": 11,
      "z": 0,
      "name": "Empty"
    },
    {
      "x": -5,
      "y": 12,
      "z": 0,
      "name": "Empty"
    },
    {
      "x": -5,
      "y": 13,
      "z": 0,
      "name": "Empty"
    },
    {
      "x": -5,
      "y": 14,
      "z": 0,
      "name": "Rock_Sandstone_Brick"
    },
    {
      "x": -5,
      "y": 15,
      "z": 0,
      "name": "Rock_Sandstone_Brick"
    },
    {
      "x": -5,
      "y": 16,
      "z": 0,
      "name": "Rock_Sandstone_Brick_Decorative"
    },
    {
      "x": -5,
      "y": 17,
      "z": 0,
      "name": "Rock_Sandstone_White_Cobble"
    },
    {
      "x": -5,
      "y": 18,
      "z": 0,
      "name": "Rock_Sandstone_White_Cobble"
    },
    {
      "x": -5,
      "y": 19,
      "z": 0,
      "name": "Rock_Sandstone_White_Cobble"
    },
    {
      "x": -5,
      "y": 20,
      "z": 0,
      "name": "Rock_Sandstone_White_Cobble"
    },
    {
      "x": -5,
      "y": 21,
      "z": 0,
      "name": "Wood_Dry_Trunk",
      "rotation": 4
    },
    {
      "x": -5,
      "y": 22,
      "z": 0,
      "name": "Wood_Drywood_Fence",
      "rotation": 3
    },
    {
      "x": -5,
      "y": 23,
      "z": 0,
      "name": "Empty"
    },
    {
      "x": -5,
      "y": 24,
      "z": 0,
      "name": "Empty"
    },
    {
      "x": -5,
      "y": 25,
      "z": 0,
      "name": "Empty"
    },
    {
      "x": -5,
      "y": 26,
      "z": 0,
      "name": "Empty"
    },
    {
      "x": -5,
      "y": 0,
      "z": 1,
      "name": "Rock_Sandstone_Brick"
    },
    {
      "x": -5,
      "y": 1,
      "z": 1,
      "name": "Rock_Sandstone_Brick"
    },
    {
      "x": -5,
      "y": 2,
      "z": 1,
      "name": "Rock_Sandstone_Brick"
    },
    {
      "x": -5,
      "y": 3,
      "z": 1,
      "name": "Rock_Sandstone_Brick"
    },
    {
      "x": -5,
      "y": 4,
      "z": 1,
      "name": "Rock_Sandstone_Brick"
    },
    {
      "x": -5,
      "y": 5,
      "z": 1,
      "name": "Rock_Sandstone_Brick"
    },
    {
      "x": -5,
      "y": 6,
      "z": 1,
      "name": "Rock_Sandstone_Brick_Pillar_Base"
    },
    {
      "x": -5,
      "y": 7,
      "z": 1,
      "name": "Rock_Sandstone_Brick_Pillar_Middle"
    },
    {
      "x": -5,
      "y": 8,
      "z": 1,
      "name": "Rock_Sandstone_Brick_Pillar_Base",
      "rotation": 8
    },
    {
      "x": -5,
      "y": 9,
      "z": 1,
      "name": "Rock_Sandstone_Brick"
    },
    {
      "x": -5,
      "y": 10,
      "z": 1,
      "name": "Rock_Sandstone_Brick_Half",
      "rotation": 6
    },
    {
      "x": -5,
      "y": 11,
      "z": 1,
      "name": "Rock_Sandstone_Brick_Half",
      "rotation": 6
    },
    {
      "x": -5,
      "y": 12,
      "z": 1,
      "name": "Rock_Sandstone_Brick"
    },
    {
      "x": -5,
      "y": 13,
      "z": 1,
      "name": "Rock_Sandstone_Brick"
    },
    {
      "x": -5,
      "y": 14,
      "z": 1,
      "name": "Rock_Sandstone_Brick"
    },
    {
      "x": -5,
      "y": 15,
      "z": 1,
      "name": "Rock_Sandstone_Brick"
    },
    {
      "x": -5,
      "y": 16,
      "z": 1,
      "name": "Rock_Sandstone_Brick_Decorative"
    },
    {
      "x": -5,
      "y": 17,
      "z": 1,
      "name": "Rock_Sandstone_White_Cobble"
    },
    {
      "x": -5,
      "y": 18,
      "z": 1,
      "name": "Rock_Sandstone_White_Cobble"
    },
    {
      "x": -5,
      "y": 19,
      "z": 1,
      "name": "Rock_Sandstone_White_Cobble"
    },
    {
      "x": -5,
      "y": 20,
      "z": 1,
      "name": "Rock_Sandstone_White_Cobble"
    },
    {
      "x": -5,
      "y": 21,
      "z": 1,
      "name": "Wood_Dry_Trunk",
      "rotation": 4
    },
    {
      "x": -5,
      "y": 22,
      "z": 1,
      "name": "Wood_Drywood_Fence",
      "rotation": 3
    },
    {
      "x": -5,
      "y": 23,
      "z": 1,
      "name": "Empty"
    },
    {
      "x": -5,
      "y": 24,
      "z": 1,
      "name": "Empty"
    },
    {
      "x": -5,
      "y": 25,
      "z": 1,
      "name": "Empty"
    },
    {
      "x": -5,
      "y": 26,
      "z": 1,
      "name": "Empty"
    },
    {
      "x": -5,
      "y": 0,
      "z": 2,
      "name": "Rock_Sandstone_Cobble"
    },
    {
      "x": -5,
      "y": 1,
      "z": 2,
      "name": "Rock_Sandstone_Cobble"
    },
    {
      "x": -5,
      "y": 2,
      "z": 2,
      "name": "Rock_Sandstone_Cobble"
    },
    {
      "x": -5,
      "y": 3,
      "z": 2,
      "name": "Rock_Sandstone_Cobble"
    },
    {
      "x": -5,
      "y": 4,
      "z": 2,
      "name": "Rock_Sandstone_Cobble"
    },
    {
      "x": -5,
      "y": 5,
      "z": 2,
      "name": "Rock_Sandstone_Cobble"
    },
    {
      "x": -5,
      "y": 6,
      "z": 2,
      "name": "Rock_Sandstone_Brick"
    },
    {
      "x": -5,
      "y": 7,
      "z": 2,
      "name": "Rock_Sandstone_Brick"
    },
    {
      "x": -5,
      "y": 8,
      "z": 2,
      "name": "Rock_Sandstone_Brick"
    },
    {
      "x": -5,
      "y": 9,
      "z": 2,
      "name": "Rock_Sandstone_Brick"
    },
    {
      "x": -5,
      "y": 10,
      "z": 2,
      "name": "Rock_Sandstone_Brick"
    },
    {
      "x": -5,
      "y": 11,
      "z": 2,
      "name": "Rock_Sandstone_Brick"
    },
    {
      "x": -5,
      "y": 12,
      "z": 2,
      "name": "Rock_Sandstone_Brick"
    },
    {
      "x": -5,
      "y": 13,
      "z": 2,
      "name": "Rock_Sandstone_Brick"
    },
    {
      "x": -5,
      "y": 14,
      "z": 2,
      "name": "Rock_Sandstone_Brick"
    },
    {
      "x": -5,
      "y": 15,
      "z": 2,
      "name": "Rock_Sandstone_Brick"
    },
    {
      "x": -5,
      "y": 16,
      "z": 2,
      "name": "Rock_Sandstone_Brick_Decorative"
    },
    {
      "x": -5,
      "y": 17,
      "z": 2,
      "name": "Rock_Sandstone_White_Cobble"
    },
    {
      "x": -5,
      "y": 18,
      "z": 2,
      "name": "Rock_Sandstone_White_Cobble"
    },
    {
      "x": -5,
      "y": 19,
      "z": 2,
      "name": "Rock_Sandstone_White_Cobble"
    },
    {
      "x": -5,
      "y": 20,
      "z": 2,
      "name": "Rock_Sandstone_White_Cobble"
    },
    {
      "x": -5,
      "y": 21,
      "z": 2,
      "name": "Wood_Dry_Trunk",
      "rotation": 4
    },
    {
      "x": -5,
      "y": 22,
      "z": 2,
      "name": "Wood_Drywood_Fence",
      "rotation": 3
    },
    {
      "x": -5,
      "y": 23,
      "z": 2,
      "name": "Empty"
    },
    {
      "x": -5,
      "y": 24,
      "z": 2,
      "name": "Empty"
    },
    {
      "x": -5,
      "y": 25,
      "z": 2,
      "name": "Empty"
    },
    {
      "x": -5,
      "y": 26,
      "z": 2,
      "name": "Empty"
    },
    {
      "x": -5,
      "y": 0,
      "z": 3,
      "name": "Rock_Sandstone_Cobble"
    },
    {
      "x": -5,
      "y": 1,
      "z": 3,
      "name": "Rock_Sandstone_Cobble"
    },
    {
      "x": -5,
      "y": 2,
      "z": 3,
      "name": "Rock_Sandstone_Cobble"
    },
    {
      "x": -5,
      "y": 3,
      "z": 3,
      "name": "Rock_Sandstone_Cobble"
    },
    {
      "x": -5,
      "y": 4,
      "z": 3,
      "name": "Rock_Sandstone_Cobble"
    },
    {
      "x": -5,
      "y": 5,
      "z": 3,
      "name": "Rock_Sandstone_Cobble"
    },
    {
      "x": -5,
      "y": 6,
      "z": 3,
      "name": "Rock_Sandstone_Brick"
    },
    {
      "x": -5,
      "y": 7,
      "z": 3,
      "name": "Rock_Sandstone_Brick"
    },
    {
      "x": -5,
      "y": 8,
      "z": 3,
      "name": "Rock_Sandstone_Brick"
    },
    {
      "x": -5,
      "y": 9,
      "z": 3,
      "name": "Rock_Sandstone_Brick"
    },
    {
      "x": -5,
      "y": 10,
      "z": 3,
      "name": "Rock_Sandstone_Brick"
    },
    {
      "x": -5,
      "y": 11,
      "z": 3,
      "name": "Rock_Sandstone_Brick"
    },
    {
      "x": -5,
      "y": 12,
      "z": 3,
      "name": "Rock_Sandstone_Brick"
    },
    {
      "x": -5,
      "y": 13,
      "z": 3,
      "name": "Rock_Sandstone_Brick"
    },
    {
      "x": -5,
      "y": 14,
      "z": 3,
      "name": "Rock_Sandstone_Brick"
    },
    {
      "x": -5,
      "y": 15,
      "z": 3,
      "name": "Rock_Sandstone_Brick"
    },
    {
      "x": -5,
      "y": 16,
      "z": 3,
      "name": "Rock_Sandstone_Brick_Decorative"
    },
    {
      "x": -5,
      "y": 17,
      "z": 3,
      "name": "Wood_Dry_Trunk"
    },
    {
      "x": -5,
      "y": 18,
      "z": 3,
      "name": "Wood_Dry_Trunk"
    },
    {
      "x": -5,
      "y": 19,
      "z": 3,
      "name": "Wood_Dry_Trunk"
    },
    {
      "x": -5,
      "y": 20,
      "z": 3,
      "name": "Wood_Dry_Trunk"
    },
    {
      "x": -5,
      "y": 21,
      "z": 3,
      "name": "Wood_Dry_Trunk"
    },
    {
      "x": -5,
      "y": 22,
      "z": 3,
      "name": "Wood_Drywood_Fence",
      "rotation": 3
    },
    {
      "x": -5,
      "y": 23,
      "z": 3,
      "name": "Empty"
    },
    {
      "x": -5,
      "y": 24,
      "z": 3,
      "name": "Empty"
    },
    {
      "x": -5,
      "y": 25,
      "z": 3,
      "name": "Empty"
    },
    {
      "x": -5,
      "y": 26,
      "z": 3,
      "name": "Empty"
    },
    {
      "x": -5,
      "y": 0,
      "z": 4,
      "name": "Rock_Sandstone_Cobble"
    },
    {
      "x": -5,
      "y": 1,
      "z": 4,
      "name": "Rock_Sandstone_Cobble"
    },
    {
      "x": -5,
      "y": 2,
      "z": 4,
      "name": "Rock_Sandstone_Cobble"
    },
    {
      "x": -5,
      "y": 3,
      "z": 4,
      "name": "Rock_Sandstone_Cobble"
    },
    {
      "x": -5,
      "y": 4,
      "z": 4,
      "name": "Rock_Sandstone_Cobble"
    },
    {
      "x": -5,
      "y": 5,
      "z": 4,
      "name": "Rock_Sandstone_Cobble"
    },
    {
      "x": -5,
      "y": 6,
      "z": 4,
      "name": "Rock_Sandstone_Cobble"
    },
    {
      "x": -5,
      "y": 7,
      "z": 4,
      "name": "Rock_Sandstone_Cobble"
    },
    {
      "x": -5,
      "y": 8,
      "z": 4,
      "name": "Rock_Sandstone_Brick"
    },
    {
      "x": -5,
      "y": 9,
      "z": 4,
      "name": "Rock_Sandstone_Brick"
    },
    {
      "x": -5,
      "y": 10,
      "z": 4,
      "name": "Rock_Sandstone_Brick"
    },
    {
      "x": -5,
      "y": 11,
      "z": 4,
      "name": "Rock_Sandstone_Brick"
    },
    {
      "x": -5,
      "y": 12,
      "z": 4,
      "name": "Rock_Sandstone_Brick"
    },
    {
      "x": -5,
      "y": 13,
      "z": 4,
      "name": "Rock_Sandstone_Brick"
    },
    {
      "x": -5,
      "y": 14,
      "z": 4,
      "name": "Rock_Sandstone_Brick"
    },
    {
      "x": -5,
      "y": 15,
      "z": 4,
      "name": "Rock_Sandstone_Brick"
    },
    {
      "x": -5,
      "y": 16,
      "z": 4,
      "name": "Rock_Sandstone_Brick_Decorative"
    },
    {
      "x": -5,
      "y": 17,
      "z": 4,
      "name": "Rock_Sandstone_White_Cobble"
    },
    {
      "x": -5,
      "y": 18,
      "z": 4,
      "name": "Rock_Sandstone_White_Cobble"
    },
    {
      "x": -5,
      "y": 19,
      "z": 4,
      "name": "Rock_Sandstone_White_Cobble"
    },
    {
      "x": -5,
      "y": 20,
      "z": 4,
      "name": "Rock_Sandstone_White_Cobble"
    },
    {
      "x": -5,
      "y": 21,
      "z": 4,
      "name": "Wood_Dry_Trunk",
      "rotation": 4
    },
    {
      "x": -5,
      "y": 22,
      "z": 4,
      "name": "Wood_Drywood_Fence",
      "rotation": 3
    },
    {
      "x": -5,
      "y": 23,
      "z": 4,
      "name": "Empty"
    },
    {
      "x": -5,
      "y": 24,
      "z": 4,
      "name": "Empty"
    },
    {
      "x": -5,
      "y": 25,
      "z": 4,
      "name": "Empty"
    },
    {
      "x": -5,
      "y": 26,
      "z": 4,
      "name": "Empty"
    },
    {
      "x": -5,
      "y": 0,
      "z": 5,
      "name": "Rock_Sandstone_Cobble"
    },
    {
      "x": -5,
      "y": 1,
      "z": 5,
      "name": "Rock_Sandstone_Cobble"
    },
    {
      "x": -5,
      "y": 2,
      "z": 5,
      "name": "Rock_Sandstone_Cobble"
    },
    {
      "x": -5,
      "y": 3,
      "z": 5,
      "name": "Rock_Sandstone_Cobble"
    },
    {
      "x": -5,
      "y": 4,
      "z": 5,
      "name": "Rock_Sandstone_Cobble"
    },
    {
      "x": -5,
      "y": 5,
      "z": 5,
      "name": "Rock_Sandstone_Cobble"
    },
    {
      "x": -5,
      "y": 6,
      "z": 5,
      "name": "Rock_Sandstone_Cobble"
    },
    {
      "x": -5,
      "y": 7,
      "z": 5,
      "name": "Rock_Sandstone_Cobble"
    },
    {
      "x": -5,
      "y": 8,
      "z": 5,
      "name": "Rock_Sandstone_Cobble"
    },
    {
      "x": -5,
      "y": 9,
      "z": 5,
      "name": "Rock_Sandstone_Brick"
    },
    {
      "x": -5,
      "y": 10,
      "z": 5,
      "name": "Rock_Sandstone_Brick"
    },
    {
      "x": -5,
      "y": 11,
      "z": 5,
      "name": "Rock_Sandstone_Brick"
    },
    {
      "x": -5,
      "y": 12,
      "z": 5,
      "name": "Rock_Sandstone_Cobble"
    },
    {
      "x": -5,
      "y": 13,
      "z": 5,
      "name": "Rock_Sandstone_Cobble"
    },
    {
      "x": -5,
      "y": 14,
      "z": 5,
      "name": "Rock_Sandstone_Cobble"
    },
    {
      "x": -5,
      "y": 15,
      "z": 5,
      "name": "Rock_Sandstone_Brick"
    },
    {
      "x": -5,
      "y": 16,
      "z": 5,
      "name": "Rock_Sandstone_Brick_Decorative"
    },
    {
      "x": -5,
      "y": 17,
      "z": 5,
      "name": "Rock_Sandstone_White_Cobble"
    },
    {
      "x": -5,
      "y": 18,
      "z": 5,
      "name": "Furniture_Desert_Window",
      "rotation": 1
    },
    {
      "x": -5,
      "y": 19,
      "z": 5,
      "name": "Furniture_Desert_Window",
      "rotation": 1
    },
    {
      "x": -5,
      "y": 20,
      "z": 5,
      "name": "Rock_Sandstone_White_Cobble"
    },
    {
      "x": -5,
      "y": 21,
      "z": 5,
      "name": "Wood_Dry_Trunk",
      "rotation": 4
    },
    {
      "x": -5,
      "y": 22,
      "z": 5,
      "name": "Wood_Drywood_Fence",
      "rotation": 3
    },
    {
      "x": -5,
      "y": 23,
      "z": 5,
      "name": "Empty"
    },
    {
      "x": -5,
      "y": 24,
      "z": 5,
      "name": "Empty"
    },
    {
      "x": -5,
      "y": 25,
      "z": 5,
      "name": "Empty"
    },
    {
      "x": -5,
      "y": 26,
      "z": 5,
      "name": "Empty"
    },
    {
      "x": -5,
      "y": 0,
      "z": 6,
      "name": "Rock_Sandstone_Cobble"
    },
    {
      "x": -5,
      "y": 1,
      "z": 6,
      "name": "Rock_Sandstone_Cobble"
    },
    {
      "x": -5,
      "y": 2,
      "z": 6,
      "name": "Rock_Sandstone_Cobble"
    },
    {
      "x": -5,
      "y": 3,
      "z": 6,
      "name": "Rock_Sandstone_Cobble"
    },
    {
      "x": -5,
      "y": 4,
      "z": 6,
      "name": "Rock_Sandstone_Cobble"
    },
    {
      "x": -5,
      "y": 5,
      "z": 6,
      "name": "Rock_Sandstone_Cobble"
    },
    {
      "x": -5,
      "y": 6,
      "z": 6,
      "name": "Rock_Sandstone_Cobble"
    },
    {
      "x": -5,
      "y": 7,
      "z": 6,
      "name": "Rock_Sandstone_Cobble"
    },
    {
      "x": -5,
      "y": 8,
      "z": 6,
      "name": "Rock_Sandstone_Cobble"
    },
    {
      "x": -5,
      "y": 9,
      "z": 6,
      "name": "Rock_Sandstone_Cobble"
    },
    {
      "x": -5,
      "y": 10,
      "z": 6,
      "name": "Rock_Sandstone_Brick"
    },
    {
      "x": -5,
      "y": 11,
      "z": 6,
      "name": "Rock_Sandstone_Brick"
    },
    {
      "x": -5,
      "y": 12,
      "z": 6,
      "name": "Rock_Sandstone_Cobble"
    },
    {
      "x": -5,
      "y": 13,
      "z": 6,
      "name": "Rock_Sandstone_Cobble"
    },
    {
      "x": -5,
      "y": 14,
      "z": 6,
      "name": "Rock_Sandstone_Cobble"
    },
    {
      "x": -5,
      "y": 15,
      "z": 6,
      "name": "Rock_Sandstone_Brick"
    },
    {
      "x": -5,
      "y": 16,
      "z": 6,
      "name": "Rock_Sandstone_Brick_Decorative"
    },
    {
      "x": -5,
      "y": 17,
      "z": 6,
      "name": "Rock_Sandstone_White_Cobble"
    },
    {
      "x": -5,
      "y": 18,
      "z": 6,
      "name": "Furniture_Desert_Window",
      "rotation": 1
    },
    {
      "x": -5,
      "y": 19,
      "z": 6,
      "name": "Furniture_Desert_Window",
      "rotation": 1
    },
    {
      "x": -5,
      "y": 20,
      "z": 6,
      "name": "Rock_Sandstone_White_Cobble"
    },
    {
      "x": -5,
      "y": 21,
      "z": 6,
      "name": "Wood_Dry_Trunk",
      "rotation": 4
    },
    {
      "x": -5,
      "y": 22,
      "z": 6,
      "name": "Wood_Drywood_Fence",
      "rotation": 3
    },
    {
      "x": -5,
      "y": 23,
      "z": 6,
      "name": "Empty"
    },
    {
      "x": -5,
      "y": 24,
      "z": 6,
      "name": "Empty"
    },
    {
      "x": -5,
      "y": 25,
      "z": 6,
      "name": "Empty"
    },
    {
      "x": -5,
      "y": 26,
      "z": 6,
      "name": "Empty"
    },
    {
      "x": -5,
      "y": 0,
      "z": 7,
      "name": "Rock_Sandstone_Cobble"
    },
    {
      "x": -5,
      "y": 1,
      "z": 7,
      "name": "Rock_Sandstone_Cobble"
    },
    {
      "x": -5,
      "y": 2,
      "z": 7,
      "name": "Rock_Sandstone_Cobble"
    },
    {
      "x": -5,
      "y": 3,
      "z": 7,
      "name": "Rock_Sandstone_Cobble"
    },
    {
      "x": -5,
      "y": 4,
      "z": 7,
      "name": "Rock_Sandstone_Cobble"
    },
    {
      "x": -5,
      "y": 5,
      "z": 7,
      "name": "Rock_Sandstone_Cobble"
    },
    {
      "x": -5,
      "y": 6,
      "z": 7,
      "name": "Rock_Sandstone_Cobble"
    },
    {
      "x": -5,
      "y": 7,
      "z": 7,
      "name": "Rock_Sandstone_Cobble"
    },
    {
      "x": -5,
      "y": 8,
      "z": 7,
      "name": "Rock_Sandstone_Cobble"
    },
    {
      "x": -5,
      "y": 9,
      "z": 7,
      "name": "Rock_Sandstone_Brick"
    },
    {
      "x": -5,
      "y": 10,
      "z": 7,
      "name": "Rock_Sandstone_Brick"
    },
    {
      "x": -5,
      "y": 11,
      "z": 7,
      "name": "Rock_Sandstone_Brick"
    },
    {
      "x": -5,
      "y": 12,
      "z": 7,
      "name": "Rock_Sandstone_Brick"
    },
    {
      "x": -5,
      "y": 13,
      "z": 7,
      "name": "Rock_Sandstone_Brick"
    },
    {
      "x": -5,
      "y": 14,
      "z": 7,
      "name": "Rock_Sandstone_Brick"
    },
    {
      "x": -5,
      "y": 15,
      "z": 7,
      "name": "Rock_Sandstone_Brick"
    },
    {
      "x": -5,
      "y": 16,
      "z": 7,
      "name": "Rock_Sandstone_Brick_Decorative"
    },
    {
      "x": -5,
      "y": 17,
      "z": 7,
      "name": "Rock_Sandstone_White_Cobble"
    },
    {
      "x": -5,
      "y": 18,
      "z": 7,
      "name": "Rock_Sandstone_White_Cobble"
    },
    {
      "x": -5,
      "y": 19,
      "z": 7,
      "name": "Rock_Sandstone_White_Cobble"
    },
    {
      "x": -5,
      "y": 20,
      "z": 7,
      "name": "Rock_Sandstone_White_Cobble"
    },
    {
      "x": -5,
      "y": 21,
      "z": 7,
      "name": "Wood_Dry_Trunk",
      "rotation": 4
    },
    {
      "x": -5,
      "y": 22,
      "z": 7,
      "name": "Wood_Drywood_Fence",
      "rotation": 3
    },
    {
      "x": -5,
      "y": 23,
      "z": 7,
      "name": "Empty"
    },
    {
      "x": -5,
      "y": 24,
      "z": 7,
      "name": "Empty"
    },
    {
      "x": -5,
      "y": 25,
      "z": 7,
      "name": "Empty"
    },
    {
      "x": -5,
      "y": 26,
      "z": 7,
      "name": "Empty"
    },
    {
      "x": -5,
      "y": 0,
      "z": 8,
      "name": "Rock_Sandstone_Cobble"
    },
    {
      "x": -5,
      "y": 1,
      "z": 8,
      "name": "Rock_Sandstone_Cobble"
    },
    {
      "x": -5,
      "y": 2,
      "z": 8,
      "name": "Rock_Sandstone_Cobble"
    },
    {
      "x": -5,
      "y": 3,
      "z": 8,
      "name": "Rock_Sandstone_Cobble"
    },
    {
      "x": -5,
      "y": 4,
      "z": 8,
      "name": "Rock_Sandstone_Cobble"
    },
    {
      "x": -5,
      "y": 5,
      "z": 8,
      "name": "Rock_Sandstone_Cobble"
    },
    {
      "x": -5,
      "y": 6,
      "z": 8,
      "name": "Rock_Sandstone_Cobble"
    },
    {
      "x": -5,
      "y": 7,
      "z": 8,
      "name": "Rock_Sandstone_Cobble"
    },
    {
      "x": -5,
      "y": 8,
      "z": 8,
      "name": "Rock_Sandstone_Cobble"
    },
    {
      "x": -5,
      "y": 9,
      "z": 8,
      "name": "Rock_Sandstone_Cobble"
    },
    {
      "x": -5,
      "y": 10,
      "z": 8,
      "name": "Rock_Sandstone_Cobble"
    },
    {
      "x": -5,
      "y": 11,
      "z": 8,
      "name": "Rock_Sandstone_Brick_Smooth"
    },
    {
      "x": -5,
      "y": 12,
      "z": 8,
      "name": "Rock_Sandstone_White_Cobble"
    },
    {
      "x": -5,
      "y": 13,
      "z": 8,
      "name": "Rock_Sandstone_White_Cobble"
    },
    {
      "x": -5,
      "y": 14,
      "z": 8,
      "name": "Rock_Sandstone_White_Cobble"
    },
    {
      "x": -5,
      "y": 15,
      "z": 8,
      "name": "Rock_Sandstone_Brick"
    },
    {
      "x": -5,
      "y": 16,
      "z": 8,
      "name": "Rock_Sandstone_Brick_Decorative"
    },
    {
      "x": -5,
      "y": 17,
      "z": 8,
      "name": "Wood_Dry_Trunk"
    },
    {
      "x": -5,
      "y": 18,
      "z": 8,
      "name": "Wood_Dry_Trunk"
    },
    {
      "x": -5,
      "y": 19,
      "z": 8,
      "name": "Wood_Dry_Trunk"
    },
    {
      "x": -5,
      "y": 20,
      "z": 8,
      "name": "Wood_Dry_Trunk"
    },
    {
      "x": -5,
      "y": 21,
      "z": 8,
      "name": "Wood_Dry_Trunk"
    },
    {
      "x": -5,
      "y": 22,
      "z": 8,
      "name": "*Wood_Drywood_Fence_State_Definitions_Corner",
      "rotation": 2
    },
    {
      "x": -5,
      "y": 23,
      "z": 8,
      "name": "Empty"
    },
    {
      "x": -5,
      "y": 24,
      "z": 8,
      "name": "Empty"
    },
    {
      "x": -5,
      "y": 25,
      "z": 8,
      "name": "Empty"
    },
    {
      "x": -5,
      "y": 26,
      "z": 8,
      "name": "Empty"
    },
    {
      "x": -5,
      "y": 0,
      "z": 9,
      "name": "Rock_Sandstone_Cobble"
    },
    {
      "x": -5,
      "y": 1,
      "z": 9,
      "name": "Rock_Sandstone_Cobble"
    },
    {
      "x": -5,
      "y": 2,
      "z": 9,
      "name": "Rock_Sandstone_Cobble"
    },
    {
      "x": -5,
      "y": 3,
      "z": 9,
      "name": "Rock_Sandstone_Cobble"
    },
    {
      "x": -5,
      "y": 4,
      "z": 9,
      "name": "Rock_Sandstone_Cobble"
    },
    {
      "x": -5,
      "y": 5,
      "z": 9,
      "name": "Rock_Sandstone_Cobble"
    },
    {
      "x": -5,
      "y": 6,
      "z": 9,
      "name": "Rock_Sandstone_Cobble"
    },
    {
      "x": -5,
      "y": 7,
      "z": 9,
      "name": "Rock_Sandstone_Cobble"
    },
    {
      "x": -5,
      "y": 8,
      "z": 9,
      "name": "Rock_Sandstone_Cobble"
    },
    {
      "x": -5,
      "y": 9,
      "z": 9,
      "name": "Rock_Sandstone_Cobble"
    },
    {
      "x": -5,
      "y": 10,
      "z": 9,
      "name": "Rock_Sandstone_Cobble"
    },
    {
      "x": -5,
      "y": 11,
      "z": 9,
      "name": "Rock_Sandstone_Brick_Smooth"
    },
    {
      "x": -5,
      "y": 12,
      "z": 9,
      "name": "Rock_Sandstone_White_Cobble"
    },
    {
      "x": -5,
      "y": 13,
      "z": 9,
      "name": "Rock_Sandstone_White_Cobble"
    },
    {
      "x": -5,
      "y": 14,
      "z": 9,
      "name": "Rock_Sandstone_White_Cobble"
    },
    {
      "x": -5,
      "y": 15,
      "z": 9,
      "name": "Rock_Sandstone_Brick"
    },
    {
      "x": -5,
      "y": 16,
      "z": 9,
      "name": "Rock_Sandstone_Brick_Smooth_Half"
    },
    {
      "x": -5,
      "y": 17,
      "z": 9,
      "name": "Empty"
    },
    {
      "x": -5,
      "y": 18,
      "z": 9,
      "name": "Empty"
    },
    {
      "x": -5,
      "y": 19,
      "z": 9,
      "name": "Empty"
    },
    {
      "x": -5,
      "y": 20,
      "z": 9,
      "name": "Empty"
    },
    {
      "x": -5,
      "y": 21,
      "z": 9,
      "name": "Empty"
    },
    {
      "x": -5,
      "y": 22,
      "z": 9,
      "name": "Empty"
    },
    {
      "x": -5,
      "y": 23,
      "z": 9,
      "name": "Empty"
    },
    {
      "x": -5,
      "y": 24,
      "z": 9,
      "name": "Empty"
    },
    {
      "x": -5,
      "y": 25,
      "z": 9,
      "name": "Empty"
    },
    {
      "x": -5,
      "y": 26,
      "z": 9,
      "name": "Empty"
    },
    {
      "x": -5,
      "y": 0,
      "z": 10,
      "name": "Rock_Sandstone_Cobble"
    },
    {
      "x": -5,
      "y": 1,
      "z": 10,
      "name": "Rock_Sandstone_Cobble"
    },
    {
      "x": -5,
      "y": 2,
      "z": 10,
      "name": "Rock_Sandstone_Cobble"
    },
    {
      "x": -5,
      "y": 3,
      "z": 10,
      "name": "Rock_Sandstone_Cobble"
    },
    {
      "x": -5,
      "y": 4,
      "z": 10,
      "name": "Rock_Sandstone_Cobble"
    },
    {
      "x": -5,
      "y": 5,
      "z": 10,
      "name": "Rock_Sandstone_Cobble"
    },
    {
      "x": -5,
      "y": 6,
      "z": 10,
      "name": "Rock_Sandstone_Brick"
    },
    {
      "x": -5,
      "y": 7,
      "z": 10,
      "name": "Rock_Sandstone_Brick"
    },
    {
      "x": -5,
      "y": 8,
      "z": 10,
      "name": "Rock_Sandstone_Cobble"
    },
    {
      "x": -5,
      "y": 9,
      "z": 10,
      "name": "Rock_Sandstone_Cobble"
    },
    {
      "x": -5,
      "y": 10,
      "z": 10,
      "name": "Rock_Sandstone_Cobble"
    },
    {
      "x": -5,
      "y": 11,
      "z": 10,
      "name": "Rock_Sandstone_Brick_Smooth"
    },
    {
      "x": -5,
      "y": 12,
      "z": 10,
      "name": "Rock_Sandstone_White_Cobble"
    },
    {
      "x": -5,
      "y": 13,
      "z": 10,
      "name": "Rock_Sandstone_White_Cobble"
    },
    {
      "x": -5,
      "y": 14,
      "z": 10,
      "name": "Rock_Sandstone_White_Cobble"
    },
    {
      "x": -5,
      "y": 15,
      "z": 10,
      "name": "Rock_Sandstone_Brick"
    },
    {
      "x": -5,
      "y": 16,
      "z": 10,
      "name": "Rock_Sandstone_Brick_Smooth_Half"
    },
    {
      "x": -5,
      "y": 17,
      "z": 10,
      "name": "Empty"
    },
    {
      "x": -5,
      "y": 18,
      "z": 10,
      "name": "Empty"
    },
    {
      "x": -5,
      "y": 19,
      "z": 10,
      "name": "Empty"
    },
    {
      "x": -5,
      "y": 20,
      "z": 10,
      "name": "Empty"
    },
    {
      "x": -5,
      "y": 21,
      "z": 10,
      "name": "Empty"
    },
    {
      "x": -5,
      "y": 22,
      "z": 10,
      "name": "Empty"
    },
    {
      "x": -5,
      "y": 23,
      "z": 10,
      "name": "Empty"
    },
    {
      "x": -5,
      "y": 24,
      "z": 10,
      "name": "Empty"
    },
    {
      "x": -5,
      "y": 25,
      "z": 10,
      "name": "Empty"
    },
    {
      "x": -5,
      "y": 26,
      "z": 10,
      "name": "Empty"
    },
    {
      "x": -5,
      "y": 0,
      "z": 11,
      "name": "Rock_Sandstone_Cobble"
    },
    {
      "x": -5,
      "y": 1,
      "z": 11,
      "name": "Rock_Sandstone_Cobble"
    },
    {
      "x": -5,
      "y": 2,
      "z": 11,
      "name": "Rock_Sandstone_Cobble"
    },
    {
      "x": -5,
      "y": 3,
      "z": 11,
      "name": "Rock_Sandstone_Cobble"
    },
    {
      "x": -5,
      "y": 4,
      "z": 11,
      "name": "Rock_Sandstone_Cobble"
    },
    {
      "x": -5,
      "y": 5,
      "z": 11,
      "name": "Rock_Sandstone_Cobble"
    },
    {
      "x": -5,
      "y": 6,
      "z": 11,
      "name": "Rock_Sandstone_Brick"
    },
    {
      "x": -5,
      "y": 7,
      "z": 11,
      "name": "Rock_Sandstone_Brick"
    },
    {
      "x": -5,
      "y": 8,
      "z": 11,
      "name": "Rock_Sandstone_Brick"
    },
    {
      "x": -5,
      "y": 9,
      "z": 11,
      "name": "Rock_Sandstone_Brick"
    },
    {
      "x": -5,
      "y": 10,
      "z": 11,
      "name": "Rock_Sandstone_Cobble"
    },
    {
      "x": -5,
      "y": 11,
      "z": 11,
      "name": "Rock_Sandstone_Brick_Smooth_Half",
      "rotation": 4
    },
    {
      "x": -5,
      "y": 15,
      "z": 11,
      "name": "Rock_Sandstone_Brick"
    },
    {
      "x": -5,
      "y": 16,
      "z": 11,
      "name": "Rock_Sandstone_Brick_Smooth_Half"
    },
    {
      "x": -5,
      "y": 17,
      "z": 11,
      "name": "Empty"
    },
    {
      "x": -5,
      "y": 18,
      "z": 11,
      "name": "Empty"
    },
    {
      "x": -5,
      "y": 19,
      "z": 11,
      "name": "Empty"
    },
    {
      "x": -5,
      "y": 20,
      "z": 11,
      "name": "Empty"
    },
    {
      "x": -5,
      "y": 21,
      "z": 11,
      "name": "Empty"
    },
    {
      "x": -4,
      "y": 6,
      "z": -11,
      "name": "Empty"
    },
    {
      "x": -4,
      "y": 7,
      "z": -11,
      "name": "Empty"
    },
    {
      "x": -4,
      "y": 8,
      "z": -11,
      "name": "Empty"
    },
    {
      "x": -4,
      "y": 9,
      "z": -11,
      "name": "Rock_Sandstone_Brick_Stairs",
      "rotation": 11
    },
    {
      "x": -4,
      "y": 10,
      "z": -11,
      "name": "Empty"
    },
    {
      "x": -4,
      "y": 11,
      "z": -11,
      "name": "Empty"
    },
    {
      "x": -4,
      "y": 12,
      "z": -11,
      "name": "Empty"
    },
    {
      "x": -4,
      "y": 13,
      "z": -11,
      "name": "Empty"
    },
    {
      "x": -4,
      "y": 14,
      "z": -11,
      "name": "Empty"
    },
    {
      "x": -4,
      "y": 15,
      "z": -11,
      "name": "Empty"
    },
    {
      "x": -4,
      "y": 0,
      "z": -10,
      "name": "Rock_Sandstone_White_Cobble"
    },
    {
      "x": -4,
      "y": 1,
      "z": -10,
      "name": "Rock_Sandstone_White_Cobble"
    },
    {
      "x": -4,
      "y": 2,
      "z": -10,
      "name": "Rock_Sandstone_White_Cobble"
    },
    {
      "x": -4,
      "y": 3,
      "z": -10,
      "name": "Rock_Sandstone_White_Cobble"
    },
    {
      "x": -4,
      "y": 4,
      "z": -10,
      "name": "Rock_Sandstone_White_Cobble"
    },
    {
      "x": -4,
      "y": 5,
      "z": -10,
      "name": "Rock_Sandstone_White_Cobble"
    },
    {
      "x": -4,
      "y": 6,
      "z": -10,
      "name": "Empty"
    },
    {
      "x": -4,
      "y": 7,
      "z": -10,
      "name": "Empty"
    },
    {
      "x": -4,
      "y": 8,
      "z": -10,
      "name": "Empty"
    },
    {
      "x": -4,
      "y": 9,
      "z": -10,
      "name": "Cloth_Roof_Green_Flap",
      "rotation": 1
    },
    {
      "x": -4,
      "y": 10,
      "z": -10,
      "name": "Empty"
    },
    {
      "x": -4,
      "y": 11,
      "z": -10,
      "name": "Empty"
    },
    {
      "x": -4,
      "y": 12,
      "z": -10,
      "name": "Empty"
    },
    {
      "x": -4,
      "y": 13,
      "z": -10,
      "name": "Empty"
    },
    {
      "x": -4,
      "y": 14,
      "z": -10,
      "name": "Empty"
    },
    {
      "x": -4,
      "y": 15,
      "z": -10,
      "name": "Empty"
    },
    {
      "x": -4,
      "y": 0,
      "z": -9,
      "name": "Rock_Sandstone_White_Cobble"
    },
    {
      "x": -4,
      "y": 1,
      "z": -9,
      "name": "Rock_Sandstone_White_Cobble"
    },
    {
      "x": -4,
      "y": 2,
      "z": -9,
      "name": "Rock_Sandstone_White_Cobble"
    },
    {
      "x": -4,
      "y": 3,
      "z": -9,
      "name": "Rock_Sandstone_White_Cobble"
    },
    {
      "x": -4,
      "y": 4,
      "z": -9,
      "name": "Rock_Sandstone_White_Cobble"
    },
    {
      "x": -4,
      "y": 5,
      "z": -9,
      "name": "Rock_Sandstone_White_Cobble"
    },
    {
      "x": -4,
      "y": 6,
      "z": -9,
      "name": "Empty"
    },
    {
      "x": -4,
      "y": 7,
      "z": -9,
      "name": "Empty"
    },
    {
      "x": -4,
      "y": 8,
      "z": -9,
      "name": "Empty"
    },
    {
      "x": -4,
      "y": 9,
      "z": -9,
      "name": "Cloth_Roof_Green_Flap",
      "rotation": 1
    },
    {
      "x": -4,
      "y": 10,
      "z": -9,
      "name": "Empty"
    },
    {
      "x": -4,
      "y": 11,
      "z": -9,
      "name": "Empty"
    },
    {
      "x": -4,
      "y": 12,
      "z": -9,
      "name": "Empty"
    },
    {
      "x": -4,
      "y": 13,
      "z": -9,
      "name": "Empty"
    },
    {
      "x": -4,
      "y": 14,
      "z": -9,
      "name": "Empty"
    },
    {
      "x": -4,
      "y": 15,
      "z": -9,
      "name": "Empty"
    },
    {
      "x": -4,
      "y": 0,
      "z": -8,
      "name": "Rock_Sandstone_White_Cobble"
    },
    {
      "x": -4,
      "y": 1,
      "z": -8,
      "name": "Rock_Sandstone_White_Cobble"
    },
    {
      "x": -4,
      "y": 2,
      "z": -8,
      "name": "Rock_Sandstone_White_Cobble"
    },
    {
      "x": -4,
      "y": 3,
      "z": -8,
      "name": "Rock_Sandstone_White_Cobble"
    },
    {
      "x": -4,
      "y": 4,
      "z": -8,
      "name": "Rock_Sandstone_White_Cobble"
    },
    {
      "x": -4,
      "y": 5,
      "z": -8,
      "name": "Rock_Sandstone_White_Cobble"
    },
    {
      "x": -4,
      "y": 6,
      "z": -8,
      "name": "Empty"
    },
    {
      "x": -4,
      "y": 7,
      "z": -8,
      "name": "Empty"
    },
    {
      "x": -4,
      "y": 8,
      "z": -8,
      "name": "Empty"
    },
    {
      "x": -4,
      "y": 9,
      "z": -8,
      "name": "Cloth_Roof_Green_Flap",
      "rotation": 1
    },
    {
      "x": -4,
      "y": 10,
      "z": -8,
      "name": "Empty"
    },
    {
      "x": -4,
      "y": 11,
      "z": -8,
      "name": "Empty"
    },
    {
      "x": -4,
      "y": 12,
      "z": -8,
      "name": "Empty"
    },
    {
      "x": -4,
      "y": 13,
      "z": -8,
      "name": "Empty"
    },
    {
      "x": -4,
      "y": 14,
      "z": -8,
      "name": "Empty"
    },
    {
      "x": -4,
      "y": 15,
      "z": -8,
      "name": "Empty"
    },
    {
      "x": -4,
      "y": 0,
      "z": -7,
      "name": "Rock_Sandstone_White_Cobble"
    },
    {
      "x": -4,
      "y": 1,
      "z": -7,
      "name": "Rock_Sandstone_White_Cobble"
    },
    {
      "x": -4,
      "y": 2,
      "z": -7,
      "name": "Rock_Sandstone_White_Cobble"
    },
    {
      "x": -4,
      "y": 3,
      "z": -7,
      "name": "Rock_Sandstone_White_Cobble"
    },
    {
      "x": -4,
      "y": 4,
      "z": -7,
      "name": "Rock_Sandstone_White_Cobble"
    },
    {
      "x": -4,
      "y": 5,
      "z": -7,
      "name": "Rock_Sandstone_White_Cobble"
    },
    {
      "x": -4,
      "y": 6,
      "z": -7,
      "name": "Empty"
    },
    {
      "x": -4,
      "y": 7,
      "z": -7,
      "name": "Empty"
    },
    {
      "x": -4,
      "y": 8,
      "z": -7,
      "name": "Empty"
    },
    {
      "x": -4,
      "y": 9,
      "z": -7,
      "name": "Cloth_Roof_Orange_Flap",
      "rotation": 1
    },
    {
      "x": -4,
      "y": 10,
      "z": -7,
      "name": "Empty"
    },
    {
      "x": -4,
      "y": 11,
      "z": -7,
      "name": "Empty"
    },
    {
      "x": -4,
      "y": 12,
      "z": -7,
      "name": "Empty"
    },
    {
      "x": -4,
      "y": 13,
      "z": -7,
      "name": "Empty"
    },
    {
      "x": -4,
      "y": 14,
      "z": -7,
      "name": "Empty"
    },
    {
      "x": -4,
      "y": 15,
      "z": -7,
      "name": "Empty"
    },
    {
      "x": -4,
      "y": 0,
      "z": -6,
      "name": "Rock_Sandstone_White_Cobble"
    },
    {
      "x": -4,
      "y": 1,
      "z": -6,
      "name": "Rock_Sandstone_White_Cobble"
    },
    {
      "x": -4,
      "y": 2,
      "z": -6,
      "name": "Rock_Sandstone_White_Cobble"
    },
    {
      "x": -4,
      "y": 3,
      "z": -6,
      "name": "Rock_Sandstone_White_Cobble"
    },
    {
      "x": -4,
      "y": 4,
      "z": -6,
      "name": "Rock_Sandstone_White_Cobble"
    },
    {
      "x": -4,
      "y": 5,
      "z": -6,
      "name": "Rock_Sandstone_White_Cobble"
    },
    {
      "x": -4,
      "y": 6,
      "z": -6,
      "name": "Empty"
    },
    {
      "x": -4,
      "y": 7,
      "z": -6,
      "name": "Empty"
    },
    {
      "x": -4,
      "y": 8,
      "z": -6,
      "name": "Cloth_Roof_Orange_Flap",
      "rotation": 1
    },
    {
      "x": -4,
      "y": 9,
      "z": -6,
      "name": "Cloth_Roof_Orange_Vertical",
      "rotation": 1
    },
    {
      "x": -4,
      "y": 10,
      "z": -6,
      "name": "Empty"
    },
    {
      "x": -4,
      "y": 11,
      "z": -6,
      "name": "Empty"
    },
    {
      "x": -4,
      "y": 12,
      "z": -6,
      "name": "Empty"
    },
    {
      "x": -4,
      "y": 13,
      "z": -6,
      "name": "Empty"
    },
    {
      "x": -4,
      "y": 14,
      "z": -6,
      "name": "Empty"
    },
    {
      "x": -4,
      "y": 15,
      "z": -6,
      "name": "Empty"
    },
    {
      "x": -4,
      "y": 0,
      "z": -5,
      "name": "Rock_Sandstone_White_Cobble"
    },
    {
      "x": -4,
      "y": 1,
      "z": -5,
      "name": "Rock_Sandstone_White_Cobble"
    },
    {
      "x": -4,
      "y": 2,
      "z": -5,
      "name": "Rock_Sandstone_White_Cobble"
    },
    {
      "x": -4,
      "y": 3,
      "z": -5,
      "name": "Rock_Sandstone_White_Cobble"
    },
    {
      "x": -4,
      "y": 4,
      "z": -5,
      "name": "Rock_Sandstone_White_Cobble"
    },
    {
      "x": -4,
      "y": 5,
      "z": -5,
      "name": "Rock_Sandstone_White_Cobble"
    },
    {
      "x": -4,
      "y": 6,
      "z": -5,
      "name": "Empty"
    },
    {
      "x": -4,
      "y": 7,
      "z": -5,
      "name": "Empty"
    },
    {
      "x": -4,
      "y": 8,
      "z": -5,
      "name": "Cloth_Roof_Orange_Flap",
      "rotation": 1
    },
    {
      "x": -4,
      "y": 9,
      "z": -5,
      "name": "Cloth_Roof_Orange_Vertical",
      "rotation": 1
    },
    {
      "x": -4,
      "y": 10,
      "z": -5,
      "name": "Empty"
    },
    {
      "x": -4,
      "y": 11,
      "z": -5,
      "name": "Empty"
    },
    {
      "x": -4,
      "y": 12,
      "z": -5,
      "name": "Empty"
    },
    {
      "x": -4,
      "y": 13,
      "z": -5,
      "name": "Empty"
    },
    {
      "x": -4,
      "y": 14,
      "z": -5,
      "name": "Empty"
    },
    {
      "x": -4,
      "y": 15,
      "z": -5,
      "name": "Empty"
    },
    {
      "x": -4,
      "y": 0,
      "z": -4,
      "name": "Rock_Sandstone_White_Cobble"
    },
    {
      "x": -4,
      "y": 1,
      "z": -4,
      "name": "Rock_Sandstone_White_Cobble"
    },
    {
      "x": -4,
      "y": 2,
      "z": -4,
      "name": "Rock_Sandstone_White_Cobble"
    },
    {
      "x": -4,
      "y": 3,
      "z": -4,
      "name": "Rock_Sandstone_White_Cobble"
    },
    {
      "x": -4,
      "y": 4,
      "z": -4,
      "name": "Rock_Sandstone_White_Cobble"
    },
    {
      "x": -4,
      "y": 5,
      "z": -4,
      "name": "Rock_Sandstone_White_Cobble"
    },
    {
      "x": -4,
      "y": 6,
      "z": -4,
      "name": "Empty"
    },
    {
      "x": -4,
      "y": 7,
      "z": -4,
      "name": "Empty"
    },
    {
      "x": -4,
      "y": 8,
      "z": -4,
      "name": "Empty"
    },
    {
      "x": -4,
      "y": 9,
      "z": -4,
      "name": "Empty"
    },
    {
      "x": -4,
      "y": 10,
      "z": -4,
      "name": "Empty"
    },
    {
      "x": -4,
      "y": 11,
      "z": -4,
      "name": "Empty"
    },
    {
      "x": -4,
      "y": 12,
      "z": -4,
      "name": "Empty"
    },
    {
      "x": -4,
      "y": 13,
      "z": -4,
      "name": "Empty"
    },
    {
      "x": -4,
      "y": 14,
      "z": -4,
      "name": "Empty"
    },
    {
      "x": -4,
      "y": 15,
      "z": -4,
      "name": "Empty"
    },
    {
      "x": -4,
      "y": 0,
      "z": -3,
      "name": "Rock_Sandstone_White_Cobble"
    },
    {
      "x": -4,
      "y": 1,
      "z": -3,
      "name": "Rock_Sandstone_White_Cobble"
    },
    {
      "x": -4,
      "y": 2,
      "z": -3,
      "name": "Rock_Sandstone_White_Cobble"
    },
    {
      "x": -4,
      "y": 3,
      "z": -3,
      "name": "Rock_Sandstone_White_Cobble"
    },
    {
      "x": -4,
      "y": 4,
      "z": -3,
      "name": "Rock_Sandstone_White_Cobble"
    },
    {
      "x": -4,
      "y": 5,
      "z": -3,
      "name": "Rock_Sandstone_White_Cobble"
    },
    {
      "x": -4,
      "y": 6,
      "z": -3,
      "name": "Furniture_Ancient_Pot"
    },
    {
      "x": -4,
      "y": 7,
      "z": -3,
      "name": "Empty"
    },
    {
      "x": -4,
      "y": 8,
      "z": -3,
      "name": "Empty"
    },
    {
      "x": -4,
      "y": 9,
      "z": -3,
      "name": "Empty"
    },
    {
      "x": -4,
      "y": 10,
      "z": -3,
      "name": "Empty"
    },
    {
      "x": -4,
      "y": 11,
      "z": -3,
      "name": "Empty"
    },
    {
      "x": -4,
      "y": 12,
      "z": -3,
      "name": "Empty"
    },
    {
      "x": -4,
      "y": 13,
      "z": -3,
      "name": "Empty"
    },
    {
      "x": -4,
      "y": 14,
      "z": -3,
      "name": "Empty"
    },
    {
      "x": -4,
      "y": 15,
      "z": -3,
      "name": "Empty"
    },
    {
      "x": -4,
      "y": 21,
      "z": -3,
      "name": "Wood_Dry_Branch_Short",
      "rotation": 2
    },
    {
      "x": -4,
      "y": 0,
      "z": -2,
      "name": "Rock_Sandstone_White_Cobble"
    },
    {
      "x": -4,
      "y": 1,
      "z": -2,
      "name": "Rock_Sandstone_White_Cobble"
    },
    {
      "x": -4,
      "y": 2,
      "z": -2,
      "name": "Rock_Sandstone_White_Cobble"
    },
    {
      "x": -4,
      "y": 3,
      "z": -2,
      "name": "Rock_Sandstone_White_Cobble"
    },
    {
      "x": -4,
      "y": 4,
      "z": -2,
      "name": "Rock_Sandstone_White_Cobble"
    },
    {
      "x": -4,
      "y": 5,
      "z": -2,
      "name": "Rock_Sandstone_White_Cobble"
    },
    {
      "x": -4,
      "y": 6,
      "z": -2,
      "name": "Empty"
    },
    {
      "x": -4,
      "y": 7,
      "z": -2,
      "name": "Empty"
    },
    {
      "x": -4,
      "y": 8,
      "z": -2,
      "name": "Empty"
    },
    {
      "x": -4,
      "y": 9,
      "z": -2,
      "name": "Empty"
    },
    {
      "x": -4,
      "y": 10,
      "z": -2,
      "name": "Empty"
    },
    {
      "x": -4,
      "y": 11,
      "z": -2,
      "name": "Empty"
    },
    {
      "x": -4,
      "y": 12,
      "z": -2,
      "name": "Empty"
    },
    {
      "x": -4,
      "y": 13,
      "z": -2,
      "name": "Empty"
    },
    {
      "x": -4,
      "y": 14,
      "z": -2,
      "name": "Empty"
    },
    {
      "x": -4,
      "y": 15,
      "z": -2,
      "name": "Rock_Sandstone_Brick_Half",
      "rotation": 8
    },
    {
      "x": -4,
      "y": 16,
      "z": -2,
      "name": "Rock_Sandstone_Brick_Decorative"
    },
    {
      "x": -4,
      "y": 17,
      "z": -2,
      "name": "Rock_Sandstone_White_Cobble"
    },
    {
      "x": -4,
      "y": 18,
      "z": -2,
      "name": "Rock_Sandstone_White_Cobble"
    },
    {
      "x": -4,
      "y": 19,
      "z": -2,
      "name": "Rock_Sandstone_White_Cobble"
    },
    {
      "x": -4,
      "y": 20,
      "z": -2,
      "name": "Rock_Sandstone_White_Cobble"
    },
    {
      "x": -4,
      "y": 21,
      "z": -2,
      "name": "Wood_Dry_Trunk",
      "rotation": 5
    },
    {
      "x": -4,
      "y": 22,
      "z": -2,
      "name": "Wood_Drywood_Fence",
      "rotation": 2
    },
    {
      "x": -4,
      "y": 23,
      "z": -2,
      "name": "Empty"
    },
    {
      "x": -4,
      "y": 24,
      "z": -2,
      "name": "Empty"
    },
    {
      "x": -4,
      "y": 25,
      "z": -2,
      "name": "Empty"
    },
    {
      "x": -4,
      "y": 26,
      "z": -2,
      "name": "Empty"
    },
    {
      "x": -4,
      "y": 0,
      "z": -1,
      "name": "Rock_Sandstone_White_Cobble"
    },
    {
      "x": -4,
      "y": 1,
      "z": -1,
      "name": "Rock_Sandstone_White_Cobble"
    },
    {
      "x": -4,
      "y": 2,
      "z": -1,
      "name": "Rock_Sandstone_White_Cobble"
    },
    {
      "x": -4,
      "y": 3,
      "z": -1,
      "name": "Rock_Sandstone_White_Cobble"
    },
    {
      "x": -4,
      "y": 4,
      "z": -1,
      "name": "Rock_Sandstone_White_Cobble"
    },
    {
      "x": -4,
      "y": 5,
      "z": -1,
      "name": "Rock_Sandstone_White_Cobble"
    },
    {
      "x": -4,
      "y": 6,
      "z": -1,
      "name": "Empty"
    },
    {
      "x": -4,
      "y": 7,
      "z": -1,
      "name": "Empty"
    },
    {
      "x": -4,
      "y": 8,
      "z": -1,
      "name": "Empty"
    },
    {
      "x": -4,
      "y": 9,
      "z": -1,
      "name": "Empty"
    },
    {
      "x": -4,
      "y": 10,
      "z": -1,
      "name": "Empty"
    },
    {
      "x": -4,
      "y": 11,
      "z": -1,
      "name": "Empty"
    },
    {
      "x": -4,
      "y": 12,
      "z": -1,
      "name": "Empty"
    },
    {
      "x": -4,
      "y": 13,
      "z": -1,
      "name": "Empty"
    },
    {
      "x": -4,
      "y": 14,
      "z": -1,
      "name": "Empty"
    },
    {
      "x": -4,
      "y": 15,
      "z": -1,
      "name": "Rock_Sandstone_Brick"
    },
    {
      "x": -4,
      "y": 16,
      "z": -1,
      "name": "Wood_Drywood_Planks"
    },
    {
      "x": -4,
      "y": 17,
      "z": -1,
      "name": "Empty"
    },
    {
      "x": -4,
      "y": 18,
      "z": -1,
      "name": "Empty"
    },
    {
      "x": -4,
      "y": 19,
      "z": -1,
      "name": "Empty"
    },
    {
      "x": -4,
      "y": 20,
      "z": -1,
      "name": "Empty"
    },
    {
      "x": -4,
      "y": 21,
      "z": -1,
      "name": "Wood_Drywood_Planks"
    },
    {
      "x": -4,
      "y": 22,
      "z": -1,
      "name": "Furniture_Temple_Wind_Pot"
    },
    {
      "x": -4,
      "y": 23,
      "z": -1,
      "name": "Furniture_Temple_Wind_Pot",
      "filler": 1024
    },
    {
      "x": -4,
      "y": 24,
      "z": -1,
      "name": "Empty"
    },
    {
      "x": -4,
      "y": 25,
      "z": -1,
      "name": "Empty"
    },
    {
      "x": -4,
      "y": 26,
      "z": -1,
      "name": "Empty"
    },
    {
      "x": -4,
      "y": 0,
      "z": 0,
      "name": "Rock_Sandstone_White_Cobble"
    },
    {
      "x": -4,
      "y": 1,
      "z": 0,
      "name": "Rock_Sandstone_White_Cobble"
    },
    {
      "x": -4,
      "y": 2,
      "z": 0,
      "name": "Rock_Sandstone_White_Cobble"
    },
    {
      "x": -4,
      "y": 3,
