{
  "version": 8,
  "blockIdVersion": 10,
  "anchorX": 6,
  "anchorY": 3,
  "anchorZ": -2,
  "blocks": [
    {
      "x": -6,
      "y": 13,
      "z": -5,
      "name": "Plant_Leaves_Beech"
    },
    {
      "x": -6,
      "y": 13,
      "z": -4,
      "name": "Plant_Leaves_Beech"
    },
    {
      "x": -6,
      "y": 14,
      "z": -4,
      "name": "Plant_Leaves_Beech"
    },
    {
      "x": -6,
      "y": 12,
      "z": -3,
      "name": "Plant_Leaves_Beech"
    },
    {
      "x": -6,
      "y": 13,
      "z": -3,
      "name": "Plant_Leaves_Beech"
    },
    {
      "x": -6,
      "y": 14,
      "z": -3,
      "name": "Plant_Leaves_Beech"
    },
    {
      "x": -6,
      "y": 15,
      "z": -3,
      "name": "Plant_Leaves_Beech"
    },
    {
      "x": -6,
      "y": 12,
      "z": -2,
      "name": "Plant_Leaves_Beech"
    },
    {
      "x": -6,
      "y": 13,
      "z": -2,
      "name": "Plant_Leaves_Beech"
    },
    {
      "x": -6,
      "y": 14,
      "z": -2,
      "name": "Plant_Leaves_Beech"
    },
    {
      "x": -6,
      "y": 15,
      "z": -2,
      "name": "Plant_Leaves_Beech"
    },
    {
      "x": -6,
      "y": 14,
      "z": -1,
      "name": "Plant_Leaves_Beech"
    },
    {
      "x": -6,
      "y": 15,
      "z": -1,
      "name": "Plant_Leaves_Beech"
    },
    {
      "x": -5,
      "y": 13,
      "z": -6,
      "name": "Plant_Leaves_Beech"
    },
    {
      "x": -5,
      "y": 14,
      "z": -6,
      "name": "Plant_Leaves_Beech"
    },
    {
      "x": -5,
      "y": 15,
      "z": -6,
      "name": "Plant_Leaves_Beech"
    },
    {
      "x": -5,
      "y": 11,
      "z": -5,
      "name": "Plant_Leaves_Beech"
    },
    {
      "x": -5,
      "y": 12,
      "z": -5,
      "name": "Plant_Leaves_Beech"
    },
    {
      "x": -5,
      "y": 13,
      "z": -5,
      "name": "Plant_Leaves_Beech"
    },
    {
      "x": -5,
      "y": 14,
      "z": -5,
      "name": "Plant_Leaves_Beech"
    },
    {
      "x": -5,
      "y": 15,
      "z": -5,
      "name": "Plant_Leaves_Beech"
    },
    {
      "x": -5,
      "y": 13,
      "z": -4,
      "name": "Plant_Leaves_Beech"
    },
    {
      "x": -5,
      "y": 14,
      "z": -4,
      "name": "Plant_Leaves_Beech"
    },
    {
      "x": -5,
      "y": 15,
      "z": -4,
      "name": "Plant_Leaves_Beech"
    },
    {
      "x": -5,
      "y": 16,
      "z": -4,
      "name": "Plant_Leaves_Beech"
    },
    {
      "x": -5,
      "y": 14,
      "z": -3,
      "name": "Wood_Gumboab_Branch_Corner",
      "rotation": 3
    },
    {
      "x": -5,
      "y": 15,
      "z": -3,
      "name": "Plant_Leaves_Beech"
    },
    {
      "x": -5,
      "y": 13,
      "z": -2,
      "name": "Plant_Leaves_Beech"
    },
    {
      "x": -5,
      "y": 14,
      "z": -2,
      "name": "Plant_Leaves_Beech"
    },
    {
      "x": -5,
      "y": 17,
      "z": -2,
      "name": "Plant_Leaves_Beech"
    },
    {
      "x": -5,
      "y": 14,
      "z": -1,
      "name": "Plant_Leaves_Beech"
    },
    {
      "x": -5,
      "y": 16,
      "z": -1,
      "name": "Plant_Leaves_Beech"
    },
    {
      "x": -5,
      "y": 14,
      "z": 0,
      "name": "Plant_Leaves_Beech"
    },
    {
      "x": -4,
      "y": 11,
      "z": -7,
      "name": "Plant_Leaves_Beech"
    },
    {
      "x": -4,
      "y": 12,
      "z": -7,
      "name": "Plant_Leaves_Beech"
    },
    {
      "x": -4,
      "y": 13,
      "z": -7,
      "name": "Plant_Leaves_Beech"
    },
    {
      "x": -4,
      "y": 11,
      "z": -6,
      "name": "Plant_Leaves_Beech"
    },
    {
      "x": -4,
      "y": 12,
      "z": -6,
      "name": "Plant_Leaves_Beech"
    },
    {
      "x": -4,
      "y": 14,
      "z": -6,
      "name": "Plant_Leaves_Beech"
    },
    {
      "x": -4,
      "y": 15,
      "z": -6,
      "name": "Plant_Leaves_Beech"
    },
    {
      "x": -4,
      "y": 16,
      "z": -6,
      "name": "Plant_Leaves_Beech"
    },
    {
      "x": -4,
      "y": 15,
      "z": -5,
      "name": "Plant_Leaves_Beech"
    },
    {
      "x": -4,
      "y": 16,
      "z": -4,
      "name": "Plant_Leaves_Beech"
    },
    {
      "x": -4,
      "y": 17,
      "z": -4,
      "name": "Plant_Leaves_Beech"
    },
    {
      "x": -4,
      "y": 14,
      "z": -3,
      "name": "Wood_Gumboab_Branch_Long",
      "rotation": 5
    },
    {
      "x": -4,
      "y": 17,
      "z": -3,
      "name": "Plant_Leaves_Beech"
    },
    {
      "x": -4,
      "y": 14,
      "z": -1,
      "name": "Plant_Leaves_Beech"
    },
    {
      "x": -4,
      "y": 16,
      "z": -1,
      "name": "Plant_Leaves_Beech"
    },
    {
      "x": -4,
      "y": 17,
      "z": -1,
      "name": "Plant_Leaves_Beech"
    },
    {
      "x": -4,
      "y": 14,
      "z": 0,
      "name": "Plant_Leaves_Beech"
    },
    {
      "x": -4,
      "y": 15,
      "z": 0,
      "name": "Plant_Leaves_Beech"
    },
    {
      "x": -4,
      "y": 16,
      "z": 0,
      "name": "Plant_Leaves_Beech"
    },
    {
      "x": -3,
      "y": 13,
      "z": -9,
      "name": "Plant_Leaves_Beech"
    },
    {
      "x": -3,
      "y": 12,
      "z": -8,
      "name": "Plant_Leaves_Beech"
    },
    {
      "x": -3,
      "y": 13,
      "z": -8,
      "name": "Plant_Leaves_Beech"
    },
    {
      "x": -3,
      "y": 14,
      "z": -8,
      "name": "Plant_Leaves_Beech"
    },
    {
      "x": -3,
      "y": 13,
      "z": -7,
      "name": "Plant_Leaves_Beech"
    },
    {
      "x": -3,
      "y": 14,
      "z": -7,
      "name": "Plant_Leaves_Beech"
    },
    {
      "x": -3,
      "y": 15,
      "z": -7,
      "name": "Plant_Leaves_Beech"
    },
    {
      "x": -3,
      "y": 16,
      "z": -7,
      "name": "Plant_Leaves_Beech"
    },
    {
      "x": -3,
      "y": 15,
      "z": -6,
      "name": "Plant_Leaves_Beech"
    },
    {
      "x": -3,
      "y": 16,
      "z": -6,
      "name": "Plant_Leaves_Beech"
    },
    {
      "x": -3,
      "y": 17,
      "z": -6,
      "name": "Plant_Leaves_Beech"
    },
    {
      "x": -3,
      "y": 17,
      "z": -5,
      "name": "Plant_Leaves_Beech"
    },
    {
      "x": -3,
      "y": 17,
      "z": -4,
      "name": "Plant_Leaves_Beech"
    },
    {
      "x": -3,
      "y": 18,
      "z": -4,
      "name": "Plant_Leaves_Beech"
    },
    {
      "x": -3,
      "y": 14,
      "z": -3,
      "name": "Wood_Gumboab_Trunk_Full"
    },
    {
      "x": -3,
      "y": 17,
      "z": -2,
      "name": "Plant_Leaves_Beech"
    },
    {
      "x": -3,
      "y": 18,
      "z": -2,
      "name": "Plant_Leaves_Beech"
    },
    {
      "x": -3,
      "y": 15,
      "z": -1,
      "name": "Plant_Leaves_Beech"
    },
    {
      "x": -3,
      "y": 16,
      "z": -1,
      "name": "Plant_Leaves_Beech"
    },
    {
      "x": -3,
      "y": 17,
      "z": -1,
      "name": "Plant_Leaves_Beech"
    },
    {
      "x": -3,
      "y": 15,
      "z": 0,
      "name": "Plant_Leaves_Beech"
    },
    {
      "x": -3,
      "y": 16,
      "z": 0,
      "name": "Plant_Leaves_Beech"
    },
    {
      "x": -2,
      "y": 12,
      "z": -9,
      "name": "Plant_Leaves_Beech"
    },
    {
      "x": -2,
      "y": 14,
      "z": -9,
      "name": "Plant_Leaves_Beech"
    },
    {
      "x": -2,
      "y": 12,
      "z": -8,
      "name": "Plant_Leaves_Beech"
    },
    {
      "x": -2,
      "y": 13,
      "z": -8,
      "name": "Plant_Leaves_Beech"
    },
    {
      "x": -2,
      "y": 14,
      "z": -8,
      "name": "Plant_Leaves_Beech"
    },
    {
      "x": -2,
      "y": 15,
      "z": -8,
      "name": "Plant_Leaves_Beech"
    },
    {
      "x": -2,
      "y": 15,
      "z": -7,
      "name": "Plant_Leaves_Beech"
    },
    {
      "x": -2,
      "y": 14,
      "z": -6,
      "name": "Wood_Gumboab_Branch_Corner",
      "rotation": 2
    },
    {
      "x": -2,
      "y": 15,
      "z": -6,
      "name": "Plant_Leaves_Beech"
    },
    {
      "x": -2,
      "y": 17,
      "z": -6,
      "name": "Plant_Leaves_Beech"
    },
    {
      "x": -2,
      "y": 14,
      "z": -5,
      "name": "Wood_Gumboab_Branch_Long",
      "rotation": 4
    },
    {
      "x": -2,
      "y": 14,
      "z": -4,
      "name": "Wood_Gumboab_Trunk_Full"
    },
    {
      "x": -2,
      "y": 15,
      "z": -4,
      "name": "Wood_Gumboab_Branch_Long"
    },
    {
      "x": -2,
      "y": 16,
      "z": -4,
      "name": "Wood_Gumboab_Branch_Long"
    },
    {
      "x": -2,
      "y": 17,
      "z": -4,
      "name": "Plant_Leaves_Beech"
    },
    {
      "x": -2,
      "y": 18,
      "z": -4,
      "name": "Plant_Leaves_Beech"
    },
    {
      "x": -2,
      "y": 14,
      "z": -3,
      "name": "Wood_Gumboab_Trunk_Full"
    },
    {
      "x": -2,
      "y": 17,
      "z": -3,
      "name": "Plant_Leaves_Beech"
    },
    {
      "x": -2,
      "y": 18,
      "z": -3,
      "name": "Plant_Leaves_Beech"
    },
    {
      "x": -2,
      "y": 18,
      "z": -1,
      "name": "Plant_Leaves_Beech"
    },
    {
      "x": -1,
      "y": 15,
      "z": -10,
      "name": "Plant_Leaves_Beech"
    },
    {
      "x": -1,
      "y": 13,
      "z": -9,
      "name": "Plant_Leaves_Beech"
    },
    {
      "x": -1,
      "y": 14,
      "z": -9,
      "name": "Plant_Leaves_Beech"
    },
    {
      "x": -1,
      "y": 15,
      "z": -9,
      "name": "Plant_Leaves_Beech"
    },
    {
      "x": -1,
      "y": 15,
      "z": -8,
      "name": "Plant_Leaves_Beech"
    },
    {
      "x": -1,
      "y": 16,
      "z": -8,
      "name": "Plant_Leaves_Beech"
    },
    {
      "x": -1,
      "y": 17,
      "z": -8,
      "name": "Plant_Leaves_Beech"
    },
    {
      "x": -1,
      "y": 17,
      "z": -6,
      "name": "Plant_Leaves_Beech"
    },
    {
      "x": -1,
      "y": 14,
      "z": -4,
      "name": "Wood_Gumboab_Trunk_Full"
    },
    {
      "x": -1,
      "y": 19,
      "z": -4,
      "name": "Plant_Leaves_Beech"
    },
    {
      "x": -1,
      "y": 18,
      "z": -3,
      "name": "Plant_Leaves_Beech"
    },
    {
      "x": -1,
      "y": 19,
      "z": -3,
      "name": "Plant_Leaves_Beech"
    },
    {
      "x": -1,
      "y": 18,
      "z": -2,
      "name": "Plant_Leaves_Beech"
    },
    {
      "x": -1,
      "y": 19,
      "z": -2,
      "name": "Plant_Leaves_Beech"
    },
    {
      "x": -1,
      "y": 18,
      "z": -1,
      "name": "Plant_Leaves_Beech"
    },
    {
      "x": -1,
      "y": 17,
      "z": 2,
      "name": "Plant_Leaves_Beech"
    },
    {
      "x": -1,
      "y": 17,
      "z": 3,
      "name": "Plant_Leaves_Beech"
    },
    {
      "x": -1,
      "y": 15,
      "z": 4,
      "name": "Plant_Leaves_Beech"
    },
    {
      "x": -1,
      "y": 16,
      "z": 4,
      "name": "Plant_Leaves_Beech"
    },
    {
      "x": -1,
      "y": 17,
      "z": 4,
      "name": "Plant_Leaves_Beech"
    },
    {
      "x": -1,
      "y": 18,
      "z": 4,
      "name": "Plant_Leaves_Beech"
    },
    {
      "x": -1,
      "y": 15,
      "z": 5,
      "name": "Plant_Leaves_Beech"
    },
    {
      "x": -1,
      "y": 16,
      "z": 5,
      "name": "Plant_Leaves_Beech"
    },
    {
      "x": -1,
      "y": 17,
      "z": 5,
      "name": "Plant_Leaves_Beech"
    },
    {
      "x": 0,
      "y": 12,
      "z": -10,
      "name": "Plant_Leaves_Beech"
    },
    {
      "x": 0,
      "y": 13,
      "z": -10,
      "name": "Plant_Leaves_Beech"
    },
    {
      "x": 0,
      "y": 14,
      "z": -10,
      "name": "Plant_Leaves_Beech"
    },
    {
      "x": 0,
      "y": 15,
      "z": -10,
      "name": "Plant_Leaves_Beech"
    },
    {
      "x": 0,
      "y": 15,
      "z": -9,
      "name": "Wood_Gumboab_Branch_Corner",
      "rotation": 2
    },
    {
      "x": 0,
      "y": 16,
      "z": -9,
      "name": "Plant_Leaves_Beech"
    },
    {
      "x": 0,
      "y": 17,
      "z": -9,
      "name": "Plant_Leaves_Beech"
    },
    {
      "x": 0,
      "y": 15,
      "z": -8,
      "name": "Wood_Gumboab_Branch_Long",
      "rotation": 4
    },
    {
      "x": 0,
      "y": 16,
      "z": -8,
      "name": "Plant_Leaves_Beech"
    },
    {
      "x": 0,
      "y": 17,
      "z": -8,
      "name": "Plant_Leaves_Beech"
    },
    {
      "x": 0,
      "y": 18,
      "z": -8,
      "name": "Plant_Leaves_Beech"
    },
    {
      "x": 0,
      "y": 15,
      "z": -7,
      "name": "Wood_Gumboab_Branch_Long",
      "rotation": 4
    },
    {
      "x": 0,
      "y": 17,
      "z": -7,
      "name": "Plant_Leaves_Beech"
    },
    {
      "x": 0,
      "y": 18,
      "z": -7,
      "name": "Plant_Leaves_Beech"
    },
    {
      "x": 0,
      "y": 14,
      "z": -6,
      "name": "Wood_Gumboab_Trunk_Full"
    },
    {
      "x": 0,
      "y": 15,
      "z": -6,
      "name": "Wood_Gumboab_Trunk_Full"
    },
    {
      "x": 0,
      "y": 16,
      "z": -6,
      "name": "Wood_Gumboab_Branch_Long"
    },
    {
      "x": 0,
      "y": 17,
      "z": -6,
      "name": "Plant_Leaves_Beech"
    },
    {
      "x": 0,
      "y": 18,
      "z": -6,
      "name": "Plant_Leaves_Beech"
    },
    {
      "x": 0,
      "y": 14,
      "z": -5,
      "name": "Wood_Gumboab_Trunk_Full"
    },
    {
      "x": 0,
      "y": 18,
      "z": -5,
      "name": "Plant_Leaves_Beech"
    },
    {
      "x": 0,
      "y": 13,
      "z": -4,
      "name": "Wood_Gumboab_Trunk_Full"
    },
    {
      "x": 0,
      "y": 14,
      "z": -4,
      "name": "Wood_Gumboab_Trunk_Full"
    },
    {
      "x": 0,
      "y": 18,
      "z": -4,
      "name": "Plant_Leaves_Beech"
    },
    {
      "x": 0,
      "y": 19,
      "z": -4,
      "name": "Plant_Leaves_Beech"
    },
    {
      "x": 0,
      "y": 13,
      "z": -3,
      "name": "Wood_Gumboab_Trunk_Full"
    },
    {
      "x": 0,
      "y": 18,
      "z": -3,
      "name": "Plant_Leaves_Beech"
    },
    {
      "x": 0,
      "y": 19,
      "z": -3,
      "name": "Plant_Leaves_Beech"
    },
    {
      "x": 0,
      "y": 19,
      "z": -2,
      "name": "Plant_Leaves_Beech"
    },
    {
      "x": 0,
      "y": 19,
      "z": -1,
      "name": "Plant_Leaves_Beech"
    },
    {
      "x": 0,
      "y": 17,
      "z": 1,
      "name": "Plant_Leaves_Beech"
    },
    {
      "x": 0,
      "y": 17,
      "z": 2,
      "name": "Plant_Leaves_Beech"
    },
    {
      "x": 0,
      "y": 18,
      "z": 2,
      "name": "Plant_Leaves_Beech"
    },
    {
      "x": 0,
      "y": 17,
      "z": 3,
      "name": "Plant_Leaves_Beech"
    },
    {
      "x": 0,
      "y": 18,
      "z": 3,
      "name": "Plant_Leaves_Beech"
    },
    {
      "x": 0,
      "y": 19,
      "z": 3,
      "name": "Plant_Leaves_Beech"
    },
    {
      "x": 0,
      "y": 17,
      "z": 4,
      "name": "Plant_Leaves_Beech"
    },
    {
      "x": 0,
      "y": 18,
      "z": 4,
      "name": "Plant_Leaves_Beech"
    },
    {
      "x": 0,
      "y": 19,
      "z": 4,
      "name": "Plant_Leaves_Beech"
    },
    {
      "x": 0,
      "y": 16,
      "z": 5,
      "name": "Plant_Leaves_Beech"
    },
    {
      "x": 0,
      "y": 17,
      "z": 5,
      "name": "Plant_Leaves_Beech"
    },
    {
      "x": 0,
      "y": 18,
      "z": 5,
      "name": "Plant_Leaves_Beech"
    },
    {
      "x": 0,
      "y": 14,
      "z": 6,
      "name": "Plant_Leaves_Beech"
    },
    {
      "x": 0,
      "y": 15,
      "z": 6,
      "name": "Plant_Leaves_Beech"
    },
    {
      "x": 0,
      "y": 16,
      "z": 6,
      "name": "Plant_Leaves_Beech"
    },
    {
      "x": 0,
      "y": 17,
      "z": 6,
      "name": "Plant_Leaves_Beech"
    },
    {
      "x": 0,
      "y": 18,
      "z": 6,
      "name": "Plant_Leaves_Beech"
    },
    {
      "x": 0,
      "y": 15,
      "z": 7,
      "name": "Plant_Leaves_Beech"
    },
    {
      "x": 0,
      "y": 16,
      "z": 7,
      "name": "Plant_Leaves_Beech"
    },
    {
      "x": 1,
      "y": 12,
      "z": -10,
      "name": "Plant_Leaves_Beech"
    },
    {
      "x": 1,
      "y": 13,
      "z": -10,
      "name": "Plant_Leaves_Beech"
    },
    {
      "x": 1,
      "y": 14,
      "z": -10,
      "name": "Plant_Leaves_Beech"
    },
    {
      "x": 1,
      "y": 15,
      "z": -10,
      "name": "Plant_Leaves_Beech"
    },
    {
      "x": 1,
      "y": 16,
      "z": -10,
      "name": "Plant_Leaves_Beech"
    },
    {
      "x": 1,
      "y": 15,
      "z": -9,
      "name": "Plant_Leaves_Beech"
    },
    {
      "x": 1,
      "y": 17,
      "z": -9,
      "name": "Plant_Leaves_Beech"
    },
    {
      "x": 1,
      "y": 17,
      "z": -8,
      "name": "Plant_Leaves_Beech"
    },
    {
      "x": 1,
      "y": 18,
      "z": -7,
      "name": "Plant_Leaves_Beech"
    },
    {
      "x": 1,
      "y": 15,
      "z": -6,
      "name": "Wood_Gumboab_Branch_Corner",
      "rotation": 1
    },
    {
      "x": 1,
      "y": 16,
      "z": -6,
      "name": "Wood_Gumboab_Branch_Long"
    },
    {
      "x": 1,
      "y": 17,
      "z": -6,
      "name": "Wood_Gumboab_Branch_Long"
    },
    {
      "x": 1,
      "y": 18,
      "z": -6,
      "name": "Plant_Leaves_Beech"
    },
    {
      "x": 1,
      "y": 19,
      "z": -5,
      "name": "Plant_Leaves_Beech"
    },
    {
      "x": 1,
      "y": 18,
      "z": -4,
      "name": "Plant_Leaves_Beech"
    },
    {
      "x": 1,
      "y": 19,
      "z": -4,
      "name": "Plant_Leaves_Beech"
    },
    {
      "x": 1,
      "y": 13,
      "z": -3,
      "name": "Wood_Gumboab_Trunk_Full"
    },
    {
      "x": 1,
      "y": 19,
      "z": -2,
      "name": "Plant_Leaves_Beech"
    },
    {
      "x": 1,
      "y": 18,
      "z": 1,
      "name": "Plant_Leaves_Beech"
    },
    {
      "x": 1,
      "y": 18,
      "z": 2,
      "name": "Plant_Leaves_Beech"
    },
    {
      "x": 1,
      "y": 15,
      "z": 3,
      "name": "Wood_Gumboab_Trunk_Full"
    },
    {
      "x": 1,
      "y": 16,
      "z": 3,
      "name": "Wood_Gumboab_Branch_Long"
    },
    {
      "x": 1,
      "y": 17,
      "z": 3,
      "name": "Wood_Gumboab_Branch_Long"
    },
    {
      "x": 1,
      "y": 18,
      "z": 3,
      "name": "Plant_Leaves_Beech"
    },
    {
      "x": 1,
      "y": 19,
      "z": 3,
      "name": "Plant_Leaves_Beech"
    },
    {
      "x": 1,
      "y": 20,
      "z": 3,
      "name": "Plant_Leaves_Beech"
    },
    {
      "x": 1,
      "y": 18,
      "z": 4,
      "name": "Plant_Leaves_Beech"
    },
    {
      "x": 1,
      "y": 19,
      "z": 4,
      "name": "Plant_Leaves_Beech"
    },
    {
      "x": 1,
      "y": 20,
      "z": 4,
      "name": "Plant_Leaves_Beech"
    },
    {
      "x": 1,
      "y": 17,
      "z": 5,
      "name": "Plant_Leaves_Beech"
    },
    {
      "x": 1,
      "y": 18,
      "z": 5,
      "name": "Plant_Leaves_Beech"
    },
    {
      "x": 1,
      "y": 19,
      "z": 5,
      "name": "Plant_Leaves_Beech"
    },
    {
      "x": 1,
      "y": 17,
      "z": 6,
      "name": "Plant_Leaves_Beech"
    },
    {
      "x": 1,
      "y": 18,
      "z": 6,
      "name": "Plant_Leaves_Beech"
    },
    {
      "x": 1,
      "y": 19,
      "z": 6,
      "name": "Plant_Leaves_Beech"
    },
    {
      "x": 1,
      "y": 14,
      "z": 7,
      "name": "Plant_Leaves_Beech"
    },
    {
      "x": 1,
      "y": 15,
      "z": 7,
      "name": "Plant_Leaves_Beech"
    },
    {
      "x": 1,
      "y": 16,
      "z": 7,
      "name": "Plant_Leaves_Beech"
    },
    {
      "x": 1,
      "y": 17,
      "z": 7,
      "name": "Plant_Leaves_Beech"
    },
    {
      "x": 1,
      "y": 18,
      "z": 7,
      "name": "Plant_Leaves_Beech"
    },
    {
      "x": 1,
      "y": 15,
      "z": 8,
      "name": "Plant_Leaves_Beech"
    },
    {
      "x": 1,
      "y": 16,
      "z": 8,
      "name": "Plant_Leaves_Beech"
    },
    {
      "x": 1,
      "y": 17,
      "z": 8,
      "name": "Plant_Leaves_Beech"
    },
    {
      "x": 2,
      "y": 14,
      "z": -10,
      "name": "Plant_Leaves_Beech"
    },
    {
      "x": 2,
      "y": 15,
      "z": -10,
      "name": "Plant_Leaves_Beech"
    },
    {
      "x": 2,
      "y": 13,
      "z": -9,
      "name": "Plant_Leaves_Beech"
    },
    {
      "x": 2,
      "y": 14,
      "z": -9,
      "name": "Plant_Leaves_Beech"
    },
    {
      "x": 2,
      "y": 15,
      "z": -9,
      "name": "Plant_Leaves_Beech"
    },
    {
      "x": 2,
      "y": 16,
      "z": -9,
      "name": "Plant_Leaves_Beech"
    },
    {
      "x": 2,
      "y": 17,
      "z": -8,
      "name": "Plant_Leaves_Beech"
    },
    {
      "x": 2,
      "y": 17,
      "z": -7,
      "name": "Plant_Leaves_Beech"
    },
    {
      "x": 2,
      "y": 18,
      "z": -6,
      "name": "Plant_Leaves_Beech"
    },
    {
      "x": 2,
      "y": 16,
      "z": -4,
      "name": "Wood_Gumboab_Trunk_Full"
    },
    {
      "x": 2,
      "y": 17,
      "z": -4,
      "name": "Wood_Gumboab_Branch_Long"
    },
    {
      "x": 2,
      "y": 18,
      "z": -4,
      "name": "Wood_Gumboab_Branch_Long"
    },
    {
      "x": 2,
      "y": 19,
      "z": -4,
      "name": "Plant_Leaves_Beech"
    },
    {
      "x": 2,
      "y": 12,
      "z": -3,
      "name": "Wood_Gumboab_Trunk_Full"
    },
    {
      "x": 2,
      "y": 13,
      "z": -3,
      "name": "Wood_Gumboab_Trunk"
    },
    {
      "x": 2,
      "y": 14,
      "z": -3,
      "name": "Wood_Gumboab_Trunk"
    },
    {
      "x": 2,
      "y": 15,
      "z": -3,
      "name": "Wood_Gumboab_Trunk"
    },
    {
      "x": 2,
      "y": 16,
      "z": -3,
      "name": "Wood_Gumboab_Trunk_Full"
    },
    {
      "x": 2,
      "y": 18,
      "z": -3,
      "name": "Plant_Leaves_Beech"
    },
    {
      "x": 2,
      "y": 19,
      "z": -2,
      "name": "Plant_Leaves_Beech"
    },
    {
      "x": 2,
      "y": 18,
      "z": 0,
      "name": "Plant_Leaves_Beech"
    },
    {
      "x": 2,
      "y": 18,
      "z": 1,
      "name": "Plant_Leaves_Beech"
    },
    {
      "x": 2,
      "y": 15,
      "z": 2,
      "name": "Wood_Gumboab_Trunk_Full"
    },
    {
      "x": 2,
      "y": 19,
      "z": 2,
      "name": "Plant_Leaves_Beech"
    },
    {
      "x": 2,
      "y": 15,
      "z": 3,
      "name": "Wood_Gumboab_Trunk_Full"
    },
    {
      "x": 2,
      "y": 19,
      "z": 3,
      "name": "Plant_Leaves_Beech"
    },
    {
      "x": 2,
      "y": 20,
      "z": 3,
      "name": "Plant_Leaves_Beech"
    },
    {
      "x": 2,
      "y": 19,
      "z": 4,
      "name": "Plant_Leaves_Beech"
    },
    {
      "x": 2,
      "y": 19,
      "z": 5,
      "name": "Plant_Leaves_Beech"
    },
    {
      "x": 2,
      "y": 20,
      "z": 5,
      "name": "Plant_Leaves_Beech"
    },
    {
      "x": 2,
      "y": 17,
      "z": 7,
      "name": "Plant_Leaves_Beech"
    },
    {
      "x": 2,
      "y": 16,
      "z": 8,
      "name": "Plant_Leaves_Beech"
    },
    {
      "x": 2,
      "y": 17,
      "z": 8,
      "name": "Plant_Leaves_Beech"
    },
    {
      "x": 2,
      "y": 18,
      "z": 8,
      "name": "Plant_Leaves_Beech"
    },
    {
      "x": 3,
      "y": 14,
      "z": -9,
      "name": "Plant_Leaves_Beech"
    },
    {
      "x": 3,
      "y": 15,
      "z": -9,
      "name": "Plant_Leaves_Beech"
    },
    {
      "x": 3,
      "y": 16,
      "z": -9,
      "name": "Plant_Leaves_Beech"
    },
    {
      "x": 3,
      "y": 16,
      "z": -8,
      "name": "Plant_Leaves_Beech"
    },
    {
      "x": 3,
      "y": 17,
      "z": -8,
      "name": "Plant_Leaves_Beech"
    },
    {
      "x": 3,
      "y": 17,
      "z": -7,
      "name": "Plant_Leaves_Beech"
    },
    {
      "x": 3,
      "y": 17,
      "z": -6,
      "name": "Plant_Leaves_Beech"
    },
    {
      "x": 3,
      "y": 18,
      "z": -4,
      "name": "Plant_Leaves_Beech"
    },
    {
      "x": 3,
      "y": 19,
      "z": -4,
      "name": "Plant_Leaves_Beech"
    },
    {
      "x": 3,
      "y": 12,
      "z": -3,
      "name": "Wood_Gumboab_Trunk_Full"
    },
    {
      "x": 3,
      "y": 18,
      "z": -3,
      "name": "Plant_Leaves_Beech"
    },
    {
      "x": 3,
      "y": 19,
      "z": -3,
      "name": "Plant_Leaves_Beech"
    },
    {
      "x": 3,
      "y": 12,
      "z": -2,
      "name": "Wood_Gumboab_Trunk_Full"
    },
    {
      "x": 3,
      "y": 19,
      "z": 1,
      "name": "Plant_Leaves_Beech"
    },
    {
      "x": 3,
      "y": 15,
      "z": 2,
      "name": "Wood_Gumboab_Trunk_Full"
    },
    {
      "x": 3,
      "y": 20,
      "z": 2,
      "name": "Plant_Leaves_Beech"
    },
    {
      "x": 3,
      "y": 20,
      "z": 3,
      "name": "Plant_Leaves_Beech"
    },
    {
      "x": 3,
      "y": 21,
      "z": 3,
      "name": "Plant_Leaves_Beech"
    },
    {
      "x": 3,
      "y": 20,
      "z": 4,
      "name": "Plant_Leaves_Beech"
    },
    {
      "x": 3,
      "y": 21,
      "z": 4,
      "name": "Plant_Leaves_Beech"
    },
    {
      "x": 3,
      "y": 20,
      "z": 5,
      "name": "Plant_Leaves_Beech"
    },
    {
      "x": 3,
      "y": 19,
      "z": 6,
      "name": "Plant_Leaves_Beech"
    },
    {
      "x": 3,
      "y": 19,
      "z": 7,
      "name": "Plant_Leaves_Beech"
    },
    {
      "x": 3,
      "y": 14,
      "z": 8,
      "name": "Plant_Leaves_Beech"
    },
    {
      "x": 3,
      "y": 17,
      "z": 8,
      "name": "Plant_Leaves_Beech"
    },
    {
      "x": 3,
      "y": 19,
      "z": 8,
      "name": "Plant_Leaves_Beech"
    },
    {
      "x": 3,
      "y": 15,
      "z": 9,
      "name": "Plant_Leaves_Beech"
    },
    {
      "x": 3,
      "y": 16,
      "z": 9,
      "name": "Plant_Leaves_Beech"
    },
    {
      "x": 3,
      "y": 17,
      "z": 9,
      "name": "Plant_Leaves_Beech"
    },
    {
      "x": 4,
      "y": 16,
      "z": -8,
      "name": "Plant_Leaves_Beech"
    },
    {
      "x": 4,
      "y": 15,
      "z": -7,
      "name": "Plant_Leaves_Beech"
    },
    {
      "x": 4,
      "y": 16,
      "z": -7,
      "name": "Plant_Leaves_Beech"
    },
    {
      "x": 4,
      "y": 15,
      "z": -6,
      "name": "Plant_Leaves_Beech"
    },
    {
      "x": 4,
      "y": 16,
      "z": -6,
      "name": "Plant_Leaves_Beech"
    },
    {
      "x": 4,
      "y": 17,
      "z": -6,
      "name": "Plant_Leaves_Beech"
    },
    {
      "x": 4,
      "y": 18,
      "z": -4,
      "name": "Plant_Leaves_Beech"
    },
    {
      "x": 4,
      "y": 1,
      "z": -3,
      "name": "Wood_Gumboab_Branch_Long"
    },
    {
      "x": 4,
      "y": 2,
      "z": -3,
      "name": "Wood_Gumboab_Branch_Corner",
      "rotation": 8
    },
    {
      "x": 4,
      "y": 1,
      "z": -2,
      "name": "Wood_Gumboab_Trunk"
    },
    {
      "x": 4,
      "y": 2,
      "z": -2,
      "name": "Wood_Gumboab_Trunk_Full"
    },
    {
      "x": 4,
      "y": 3,
      "z": -2,
      "name": "Wood_Gumboab_Branch_Long"
    },
    {
      "x": 4,
      "y": 4,
      "z": -2,
      "name": "Wood_Gumboab_Branch_Long"
    },
    {
      "x": 4,
      "y": 5,
      "z": -2,
      "name": "Wood_Gumboab_Branch_Corner",
      "rotation": 9
    },
    {
      "x": 4,
      "y": 11,
      "z": -2,
      "name": "Wood_Gumboab_Trunk_Full"
    },
    {
      "x": 4,
      "y": 12,
      "z": -2,
      "name": "Wood_Gumboab_Trunk_Full"
    },
    {
      "x": 4,
      "y": 1,
      "z": -1,
      "name": "Wood_Gumboab_Trunk"
    },
    {
      "x": 4,
      "y": 2,
      "z": -1,
      "name": "Wood_Gumboab_Trunk"
    },
    {
      "x": 4,
      "y": 3,
      "z": -1,
      "name": "Wood_Gumboab_Trunk_Full"
    },
    {
      "x": 4,
      "y": 4,
      "z": -1,
      "name": "Wood_Gumboab_Branch_Long"
    },
    {
      "x": 4,
      "y": 5,
      "z": -1,
      "name": "Wood_Gumboab_Branch_Long"
    },
    {
      "x": 4,
      "y": 6,
      "z": -1,
      "name": "Wood_Gumboab_Branch_Long"
    },
    {
      "x": 4,
      "y": 7,
      "z": -1,
      "name": "Wood_Gumboab_Branch_Corner",
      "rotation": 9
    },
    {
      "x": 4,
      "y": 11,
      "z": 0,
      "name": "Wood_Gumboab_Trunk_Full"
    },
    {
      "x": 4,
      "y": 12,
      "z": 0,
      "name": "Wood_Gumboab_Trunk"
    },
    {
      "x": 4,
      "y": 13,
      "z": 0,
      "name": "Wood_Gumboab_Trunk_Full"
    },
    {
      "x": 4,
      "y": 13,
      "z": 1,
      "name": "Wood_Gumboab_Trunk_Full"
    },
    {
      "x": 4,
      "y": 14,
      "z": 1,
      "name": "Wood_Gumboab_Trunk_Full"
    },
    {
      "x": 4,
      "y": 19,
      "z": 1,
      "name": "Plant_Leaves_Beech"
    },
    {
      "x": 4,
      "y": 20,
      "z": 1,
      "name": "Plant_Leaves_Beech"
    },
    {
      "x": 4,
      "y": 14,
      "z": 2,
      "name": "Wood_Gumboab_Trunk_Full"
    },
    {
      "x": 4,
      "y": 15,
      "z": 2,
      "name": "Wood_Gumboab_Trunk_Full"
    },
    {
      "x": 4,
      "y": 15,
      "z": 3,
      "name": "Wood_Gumboab_Trunk_Full"
    },
    {
      "x": 4,
      "y": 16,
      "z": 3,
      "name": "Wood_Gumboab_Trunk_Full"
    },
    {
      "x": 4,
      "y": 20,
      "z": 3,
      "name": "Plant_Leaves_Beech"
    },
    {
      "x": 4,
      "y": 21,
      "z": 3,
      "name": "Plant_Leaves_Beech"
    },
    {
      "x": 4,
      "y": 16,
      "z": 4,
      "name": "Wood_Gumboab_Trunk_Full"
    },
    {
      "x": 4,
      "y": 17,
      "z": 4,
      "name": "Wood_Gumboab_Branch_Long"
    },
    {
      "x": 4,
      "y": 18,
      "z": 4,
      "name": "Wood_Gumboab_Branch_Long"
    },
    {
      "x": 4,
      "y": 19,
      "z": 4,
      "name": "Wood_Gumboab_Branch_Long"
    },
    {
      "x": 4,
      "y": 20,
      "z": 4,
      "name": "Plant_Leaves_Beech"
    },
    {
      "x": 4,
      "y": 21,
      "z": 4,
      "name": "Plant_Leaves_Beech"
    },
    {
      "x": 4,
      "y": 16,
      "z": 5,
      "name": "Wood_Gumboab_Trunk_Full"
    },
    {
      "x": 4,
      "y": 20,
      "z": 5,
      "name": "Plant_Leaves_Beech"
    },
    {
      "x": 4,
      "y": 21,
      "z": 5,
      "name": "Plant_Leaves_Beech"
    },
    {
      "x": 4,
      "y": 20,
      "z": 6,
      "name": "Plant_Leaves_Beech"
    },
    {
      "x": 4,
      "y": 19,
      "z": 7,
      "name": "Plant_Leaves_Beech"
    },
    {
      "x": 4,
      "y": 20,
      "z": 7,
      "name": "Plant_Leaves_Beech"
    },
    {
      "x": 4,
      "y": 14,
      "z": 8,
      "name": "Plant_Leaves_Beech"
    },
    {
      "x": 4,
      "y": 15,
      "z": 8,
      "name": "Plant_Leaves_Beech"
    },
    {
      "x": 4,
      "y": 18,
      "z": 8,
      "name": "Plant_Leaves_Beech"
    },
    {
      "x": 4,
      "y": 19,
      "z": 8,
      "name": "Plant_Leaves_Beech"
    },
    {
      "x": 4,
      "y": 15,
      "z": 9,
      "name": "Plant_Leaves_Beech"
    },
    {
      "x": 4,
      "y": 16,
      "z": 9,
      "name": "Plant_Leaves_Beech"
    },
    {
      "x": 4,
      "y": 17,
      "z": 9,
      "name": "Plant_Leaves_Beech"
    },
    {
      "x": 4,
      "y": 18,
      "z": 9,
      "name": "Plant_Leaves_Beech"
    },
    {
      "x": 5,
      "y": 1,
      "z": -3,
      "name": "Wood_Gumboab_Trunk_Full"
    },
    {
      "x": 5,
      "y": 2,
      "z": -3,
      "name": "Wood_Gumboab_Branch_Long"
    },
    {
      "x": 5,
      "y": 3,
      "z": -3,
      "name": "Wood_Gumboab_Branch_Long"
    },
    {
      "x": 5,
      "y": 4,
      "z": -3,
      "name": "Wood_Gumboab_Branch_Corner",
      "rotation": 8
    },
    {
      "x": 5,
      "y": 1,
      "z": -2,
      "name": "Wood_Gumboab_Trunk"
    },
    {
      "x": 5,
      "y": 2,
      "z": -2,
      "name": "Wood_Gumboab_Trunk"
    },
    {
      "x": 5,
      "y": 3,
      "z": -2,
      "name": "Wood_Gumboab_Trunk"
    },
    {
      "x": 5,
      "y": 4,
      "z": -2,
      "name": "Wood_Gumboab_Trunk"
    },
    {
      "x": 5,
      "y": 5,
      "z": -2,
      "name": "Wood_Gumboab_Trunk"
    },
    {
      "x": 5,
      "y": 6,
      "z": -2,
      "name": "Wood_Gumboab_Trunk"
    },
    {
      "x": 5,
      "y": 7,
      "z": -2,
      "name": "Wood_Gumboab_Trunk"
    },
    {
      "x": 5,
      "y": 8,
      "z": -2,
      "name": "Wood_Gumboab_Trunk"
    },
    {
      "x": 5,
      "y": 9,
      "z": -2,
      "name": "Wood_Gumboab_Trunk"
    },
    {
      "x": 5,
      "y": 10,
      "z": -2,
      "name": "Wood_Gumboab_Trunk"
    },
    {
      "x": 5,
      "y": 11,
      "z": -2,
      "name": "Wood_Gumboab_Trunk_Full"
    },
    {
      "x": 5,
      "y": 1,
      "z": -1,
      "name": "Wood_Gumboab_Trunk"
    },
    {
      "x": 5,
      "y": 2,
      "z": -1,
      "name": "Wood_Gumboab_Trunk"
    },
    {
      "x": 5,
      "y": 3,
      "z": -1,
      "name": "Wood_Gumboab_Trunk"
    },
    {
      "x": 5,
      "y": 4,
      "z": -1,
      "name": "Wood_Gumboab_Trunk"
    },
    {
      "x": 5,
      "y": 5,
      "z": -1,
      "name": "Wood_Gumboab_Trunk"
    },
    {
      "x": 5,
      "y": 6,
      "z": -1,
      "name": "Wood_Gumboab_Trunk"
    },
    {
      "x": 5,
      "y": 7,
      "z": -1,
      "name": "Wood_Gumboab_Trunk"
    },
    {
      "x": 5,
      "y": 8,
      "z": -1,
      "name": "Wood_Gumboab_Trunk"
    },
    {
      "x": 5,
      "y": 9,
      "z": -1,
      "name": "Wood_Gumboab_Trunk"
    },
    {
      "x": 5,
      "y": 10,
      "z": -1,
      "name": "Wood_Gumboab_Trunk"
    },
    {
      "x": 5,
      "y": 11,
      "z": -1,
      "name": "Wood_Gumboab_Trunk_Full"
    },
    {
      "x": 5,
      "y": 15,
      "z": -1,
      "name": "Plant_Leaves_Beech"
    },
    {
      "x": 5,
      "y": 16,
      "z": -1,
      "name": "Plant_Leaves_Beech"
    },
    {
      "x": 5,
      "y": 1,
      "z": 0,
      "name": "Wood_Gumboab_Trunk"
    },
    {
      "x": 5,
      "y": 2,
      "z": 0,
      "name": "Wood_Gumboab_Trunk_Full"
    },
    {
      "x": 5,
      "y": 3,
      "z": 0,
      "name": "Wood_Gumboab_Branch_Long"
    },
    {
      "x": 5,
      "y": 4,
      "z": 0,
      "name": "Wood_Gumboab_Branch_Long"
    },
    {
      "x": 5,
      "y": 5,
      "z": 0,
      "name": "Wood_Gumboab_Branch_Long"
    },
    {
      "x": 5,
      "y": 6,
      "z": 0,
      "name": "Wood_Gumboab_Branch_Corner",
      "rotation": 10
    },
    {
      "x": 5,
      "y": 10,
      "z": 0,
      "name": "Wood_Gumboab_Trunk_Full"
    },
    {
      "x": 5,
      "y": 11,
      "z": 0,
      "name": "Wood_Gumboab_Trunk_Full"
    },
    {
      "x": 5,
      "y": 15,
      "z": 0,
      "name": "Plant_Leaves_Beech"
    },
    {
      "x": 5,
      "y": 16,
      "z": 0,
      "name": "Plant_Leaves_Beech"
    },
    {
      "x": 5,
      "y": 14,
      "z": 1,
      "name": "Plant_Leaves_Beech"
    },
    {
      "x": 5,
      "y": 15,
      "z": 1,
      "name": "Plant_Leaves_Beech"
    },
    {
      "x": 5,
      "y": 19,
      "z": 1,
      "name": "Plant_Leaves_Beech"
    },
    {
      "x": 5,
      "y": 19,
      "z": 2,
      "name": "Plant_Leaves_Beech"
    },
    {
      "x": 5,
      "y": 20,
      "z": 4,
      "name": "Plant_Leaves_Beech"
    },
    {
      "x": 5,
      "y": 21,
      "z": 4,
      "name": "Plant_Leaves_Beech"
    },
    {
      "x": 5,
      "y": 16,
      "z": 5,
      "name": "Wood_Gumboab_Trunk_Full"
    },
    {
      "x": 5,
      "y": 17,
      "z": 5,
      "name": "Wood_Gumboab_Trunk_Full"
    },
    {
      "x": 5,
      "y": 20,
      "z": 5,
      "name": "Plant_Leaves_Beech"
    },
    {
      "x": 5,
      "y": 21,
      "z": 5,
      "name": "Plant_Leaves_Beech"
    },
    {
      "x": 5,
      "y": 17,
      "z": 6,
      "name": "Wood_Gumboab_Trunk_Full"
    },
    {
      "x": 5,
      "y": 20,
      "z": 6,
      "name": "Plant_Leaves_Beech"
    },
    {
      "x": 5,
      "y": 14,
      "z": 7,
      "name": "Plant_Leaves_Beech"
    },
    {
      "x": 5,
      "y": 17,
      "z": 7,
      "name": "Wood_Gumboab_Branch_Long",
      "rotation": 4
    },
    {
      "x": 5,
      "y": 20,
      "z": 7,
      "name": "Plant_Leaves_Beech"
    },
    {
      "x": 5,
      "y": 14,
      "z": 8,
      "name": "Plant_Leaves_Beech"
    },
    {
      "x": 5,
      "y": 15,
      "z": 8,
      "name": "Plant_Leaves_Beech"
    },
    {
      "x": 5,
      "y": 16,
      "z": 8,
      "name": "Plant_Leaves_Beech"
    },
    {
      "x": 5,
      "y": 17,
      "z": 8,
      "name": "Wood_Gumboab_Branch_Corner"
    },
    {
      "x": 5,
      "y": 18,
      "z": 8,
      "name": "Plant_Leaves_Beech"
    },
    {
      "x": 5,
      "y": 19,
      "z": 8,
      "name": "Plant_Leaves_Beech"
    },
    {
      "x": 5,
      "y": 17,
      "z": 9,
      "name": "Plant_Leaves_Beech"
    },
    {
      "x": 5,
      "y": 18,
      "z": 9,
      "name": "Plant_Leaves_Beech"
    },
    {
      "x": 6,
      "y": 1,
      "z": -3,
      "name": "Wood_Gumboab_Trunk"
    },
    {
      "x": 6,
      "y": 2,
      "z": -3,
      "name": "Wood_Gumboab_Trunk_Full"
    },
    {
      "x": 6,
      "y": 3,
      "z": -3,
      "name": "Wood_Gumboab_Branch_Long"
    },
    {
      "x": 6,
      "y": 4,
      "z": -3,
      "name": "Wood_Gumboab_Branch_Corner",
      "rotation": 8
    },
    {
      "x": 6,
      "y": 15,
      "z": -3,
      "name": "Plant_Leaves_Beech"
    },
    {
      "x": 6,
      "y": 1,
      "z": -2,
      "name": "Wood_Gumboab_Trunk"
    },
    {
      "x": 6,
      "y": 2,
      "z": -2,
      "name": "Wood_Gumboab_Trunk"
    },
    {
      "x": 6,
      "y": 3,
      "z": -2,
      "name": "Wood_Gumboab_Trunk"
    },
    {
      "x": 6,
      "y": 4,
      "z": -2,
      "name": "Wood_Gumboab_Trunk"
    },
    {
      "x": 6,
      "y": 5,
      "z": -2,
      "name": "Wood_Gumboab_Trunk"
    },
    {
      "x": 6,
      "y": 6,
      "z": -2,
      "name": "Wood_Gumboab_Trunk_Full"
    },
    {
      "x": 6,
      "y": 10,
      "z": -2,
      "name": "Wood_Gumboab_Trunk_Full"
    },
    {
      "x": 6,
      "y": 11,
      "z": -2,
      "name": "Wood_Gumboab_Trunk"
    },
    {
      "x": 6,
      "y": 12,
      "z": -2,
      "name": "Wood_Gumboab_Trunk_Full"
    },
    {
      "x": 6,
      "y": 15,
      "z": -2,
      "name": "Plant_Leaves_Beech"
    },
    {
      "x": 6,
      "y": 16,
      "z": -2,
      "name": "Plant_Leaves_Beech"
    },
    {
      "x": 6,
      "y": 1,
      "z": -1,
      "name": "Wood_Gumboab_Trunk"
    },
    {
      "x": 6,
      "y": 2,
      "z": -1,
      "name": "Wood_Gumboab_Trunk"
    },
    {
      "x": 6,
      "y": 3,
      "z": -1,
      "name": "Wood_Gumboab_Trunk"
    },
    {
      "x": 6,
      "y": 4,
      "z": -1,
      "name": "Wood_Gumboab_Trunk"
    },
    {
      "x": 6,
      "y": 5,
      "z": -1,
      "name": "Wood_Gumboab_Trunk"
    },
    {
      "x": 6,
      "y": 6,
      "z": -1,
      "name": "Wood_Gumboab_Trunk"
    },
    {
      "x": 6,
      "y": 7,
      "z": -1,
      "name": "Wood_Gumboab_Trunk_Full"
    },
    {
      "x": 6,
      "y": 16,
      "z": -1,
      "name": "Plant_Leaves_Beech"
    },
    {
      "x": 6,
      "y": 1,
      "z": 0,
      "name": "Wood_Gumboab_Trunk"
    },
    {
      "x": 6,
      "y": 2,
      "z": 0,
      "name": "Wood_Gumboab_Trunk"
    },
    {
      "x": 6,
      "y": 3,
      "z": 0,
      "name": "Wood_Gumboab_Trunk_Full"
    },
    {
      "x": 6,
      "y": 4,
      "z": 0,
      "name": "Wood_Gumboab_Branch_Long"
    },
    {
      "x": 6,
      "y": 5,
      "z": 0,
      "name": "Wood_Gumboab_Branch_Long"
    },
    {
      "x": 6,
      "y": 6,
      "z": 0,
      "name": "Wood_Gumboab_Branch_Long"
    },
    {
      "x": 6,
      "y": 7,
      "z": 0,
      "name": "Wood_Gumboab_Branch_Corner",
      "rotation": 10
    },
    {
      "x": 6,
      "y": 16,
      "z": 0,
      "name": "Plant_Leaves_Beech"
    },
    {
      "x": 6,
      "y": 15,
      "z": 1,
      "name": "Plant_Leaves_Beech"
    },
    {
      "x": 6,
      "y": 17,
      "z": 1,
      "name": "Plant_Leaves_Beech"
    },
    {
      "x": 6,
      "y": 15,
      "z": 2,
      "name": "Plant_Leaves_Beech"
    },
    {
      "x": 6,
      "y": 16,
      "z": 2,
      "name": "Plant_Leaves_Beech"
    },
    {
      "x": 6,
      "y": 19,
      "z": 2,
      "name": "Plant_Leaves_Beech"
    },
    {
      "x": 6,
      "y": 19,
      "z": 3,
      "name": "Plant_Leaves_Beech"
    },
    {
      "x": 6,
      "y": 20,
      "z": 3,
      "name": "Plant_Leaves_Beech"
    },
    {
      "x": 6,
      "y": 19,
      "z": 4,
      "name": "Plant_Leaves_Beech"
    },
    {
      "x": 6,
      "y": 20,
      "z": 4,
      "name": "Plant_Leaves_Beech"
    },
    {
      "x": 6,
      "y": 19,
      "z": 5,
      "name": "Plant_Leaves_Beech"
    },
    {
      "x": 6,
      "y": 17,
      "z": 6,
      "name": "Wood_Gumboab_Branch_Long",
      "rotation": 5
    },
    {
      "x": 6,
      "y": 19,
      "z": 6,
      "name": "Plant_Leaves_Beech"
    },
    {
      "x": 6,
      "y": 20,
      "z": 6,
      "name": "Plant_Leaves_Beech"
    },
    {
      "x": 6,
      "y": 14,
      "z": 7,
      "name": "Plant_Leaves_Beech"
    },
    {
      "x": 6,
      "y": 18,
      "z": 7,
      "name": "Plant_Leaves_Beech"
    },
    {
      "x": 6,
      "y": 19,
      "z": 7,
      "name": "Plant_Leaves_Beech"
    },
    {
      "x": 6,
      "y": 15,
      "z": 8,
      "name": "Plant_Leaves_Beech"
    },
    {
      "x": 6,
      "y": 16,
      "z": 8,
      "name": "Plant_Leaves_Beech"
    },
    {
      "x": 6,
      "y": 17,
      "z": 8,
      "name": "Plant_Leaves_Beech"
    },
    {
      "x": 6,
      "y": 18,
      "z": 8,
      "name": "Plant_Leaves_Beech"
    },
    {
      "x": 6,
      "y": 19,
      "z": 8,
      "name": "Plant_Leaves_Beech"
    },
    {
      "x": 7,
      "y": 14,
      "z": -4,
      "name": "Plant_Leaves_Beech"
    },
    {
      "x": 7,
      "y": 15,
      "z": -4,
      "name": "Plant_Leaves_Beech"
    },
    {
      "x": 7,
      "y": 13,
      "z": -3,
      "name": "Plant_Leaves_Beech"
    },
    {
      "x": 7,
      "y": 14,
      "z": -3,
      "name": "Plant_Leaves_Beech"
    },
    {
      "x": 7,
      "y": 15,
      "z": -3,
      "name": "Plant_Leaves_Beech"
    },
    {
      "x": 7,
      "y": 1,
      "z": -2,
      "name": "Wood_Gumboab_Trunk"
    },
    {
      "x": 7,
      "y": 2,
      "z": -2,
      "name": "Wood_Gumboab_Trunk"
    },
    {
      "x": 7,
      "y": 3,
      "z": -2,
      "name": "Wood_Gumboab_Trunk_Full"
    },
    {
      "x": 7,
      "y": 4,
      "z": -2,
      "name": "Wood_Gumboab_Branch_Long"
    },
    {
      "x": 7,
      "y": 5,
      "z": -2,
      "name": "Wood_Gumboab_Branch_Long"
    },
    {
      "x": 7,
      "y": 6,
      "z": -2,
      "name": "Wood_Gumboab_Branch_Corner",
      "rotation": 11
    },
    {
      "x": 7,
      "y": 12,
      "z": -2,
      "name": "Wood_Gumboab_Trunk_Full"
    },
    {
      "x": 7,
      "y": 13,
      "z": -2,
      "name": "Wood_Gumboab_Trunk_Full"
    },
    {
      "x": 7,
      "y": 14,
      "z": -2,
      "name": "Wood_Gumboab_Trunk_Full"
    },
    {
      "x": 7,
      "y": 1,
      "z": -1,
      "name": "Wood_Gumboab_Trunk"
    },
    {
      "x": 7,
      "y": 2,
      "z": -1,
      "name": "Wood_Gumboab_Trunk_Full"
    },
    {
      "x": 7,
      "y": 3,
      "z": -1,
      "name": "Wood_Gumboab_Branch_Long"
    },
    {
      "x": 7,
      "y": 4,
      "z": -1,
      "name": "Wood_Gumboab_Branch_Long"
    },
    {
      "x": 7,
      "y": 5,
      "z": -1,
      "name": "Wood_Gumboab_Branch_Corner",
      "rotation": 11
    },
    {
      "x": 7,
      "y": 14,
      "z": -1,
      "name": "Wood_Gumboab_Trunk_Full"
    },
    {
      "x": 7,
      "y": 15,
      "z": -1,
      "name": "Wood_Gumboab_Trunk_Full"
    },
    {
      "x": 7,
      "y": 17,
      "z": -1,
      "name": "Plant_Leaves_Beech"
    },
    {
      "x": 7,
      "y": 17,
      "z": 0,
      "name": "Plant_Leaves_Beech"
    },
    {
      "x": 7,
      "y": 18,
      "z": 0,
      "name": "Plant_Leaves_Beech"
    },
    {
      "x": 7,
      "y": 17,
      "z": 1,
      "name": "Plant_Leaves_Beech"
    },
    {
      "x": 7,
      "y": 14,
      "z": 2,
      "name": "Plant_Leaves_Beech"
    },
    {
      "x": 7,
      "y": 15,
      "z": 2,
      "name": "Plant_Leaves_Beech"
    },
    {
      "x": 7,
      "y": 16,
      "z": 2,
      "name": "Plant_Leaves_Beech"
    },
    {
      "x": 7,
      "y": 17,
      "z": 2,
      "name": "Plant_Leaves_Beech"
    },
    {
      "x": 7,
      "y": 14,
      "z": 3,
      "name": "Plant_Leaves_Beech"
    },
    {
      "x": 7,
      "y": 15,
      "z": 3,
      "name": "Plant_Leaves_Beech"
    },
    {
      "x": 7,
      "y": 15,
      "z": 4,
      "name": "Plant_Leaves_Beech"
    },
    {
      "x": 7,
      "y": 19,
      "z": 4,
      "name": "Plant_Leaves_Beech"
    },
    {
      "x": 7,
      "y": 19,
      "z": 5,
      "name": "Plant_Leaves_Beech"
    },
    {
      "x": 7,
      "y": 17,
      "z": 6,
      "name": "Wood_Gumboab_Branch_Corner",
      "rotation": 1
    },
    {
      "x": 7,
      "y": 18,
      "z": 6,
      "name": "Plant_Leaves_Beech"
    },
    {
      "x": 7,
      "y": 19,
      "z": 6,
      "name": "Plant_Leaves_Beech"
    },
    {
      "x": 7,
      "y": 14,
      "z": 7,
      "name": "Plant_Leaves_Beech"
    },
    {
      "x": 7,
      "y": 15,
      "z": 7,
      "name": "Plant_Leaves_Beech"
    },
    {
      "x": 7,
      "y": 17,
      "z": 7,
      "name": "Plant_Leaves_Beech"
    },
    {
      "x": 7,
      "y": 15,
      "z": 8,
      "name": "Plant_Leaves_Beech"
    },
    {
      "x": 7,
      "y": 17,
      "z": 8,
      "name": "Plant_Leaves_Beech"
    },
    {
      "x": 7,
      "y": 18,
      "z": 8,
      "name": "Plant_Leaves_Beech"
    },
    {
      "x": 8,
      "y": 13,
      "z": -4,
      "name": "Plant_Leaves_Beech"
    },
    {
      "x": 8,
      "y": 14,
      "z": -4,
      "name": "Plant_Leaves_Beech"
    },
    {
      "x": 8,
      "y": 15,
      "z": -4,
      "name": "Plant_Leaves_Beech"
    },
    {
      "x": 8,
      "y": 15,
      "z": -3,
      "name": "Plant_Leaves_Beech"
    },
    {
      "x": 8,
      "y": 16,
      "z": -3,
      "name": "Plant_Leaves_Beech"
    },
    {
      "x": 8,
      "y": 17,
      "z": -3,
      "name": "Plant_Leaves_Beech"
    },
    {
      "x": 8,
      "y": 15,
      "z": -1,
      "name": "Wood_Gumboab_Trunk_Full"
    },
    {
      "x": 8,
      "y": 17,
      "z": -1,
      "name": "Plant_Leaves_Beech"
    },
    {
      "x": 8,
      "y": 18,
      "z": -1,
      "name": "Plant_Leaves_Beech"
    },
    {
      "x": 8,
      "y": 18,
      "z": 0,
      "name": "Plant_Leaves_Beech"
    },
    {
      "x": 8,
      "y": 17,
      "z": 1,
      "name": "Plant_Leaves_Beech"
    },
    {
      "x": 8,
      "y": 18,
      "z": 1,
      "name": "Plant_Leaves_Beech"
    },
    {
      "x": 8,
      "y": 15,
      "z": 2,
      "name": "Plant_Leaves_Beech"
    },
    {
      "x": 8,
      "y": 17,
      "z": 2,
      "name": "Plant_Leaves_Beech"
    },
    {
      "x": 8,
      "y": 13,
      "z": 3,
      "name": "Plant_Leaves_Beech"
    },
    {
      "x": 8,
      "y": 14,
      "z": 3,
      "name": "Plant_Leaves_Beech"
    },
    {
      "x": 8,
      "y": 15,
      "z": 3,
      "name": "Plant_Leaves_Beech"
    },
    {
      "x": 8,
      "y": 16,
      "z": 3,
      "name": "Plant_Leaves_Beech"
    },
    {
      "x": 8,
      "y": 14,
      "z": 4,
      "name": "Plant_Leaves_Beech"
    },
    {
      "x": 8,
      "y": 15,
      "z": 4,
      "name": "Plant_Leaves_Beech"
    },
    {
      "x": 8,
      "y": 17,
      "z": 6,
      "name": "Plant_Leaves_Beech"
    },
    {
      "x": 8,
      "y": 18,
      "z": 6,
      "name": "Plant_Leaves_Beech"
    },
    {
      "x": 8,
      "y": 17,
      "z": 7,
      "name": "Plant_Leaves_Beech"
    },
    {
      "x": 9,
      "y": 14,
      "z": -4,
      "name": "Plant_Leaves_Beech"
    },
    {
      "x": 9,
      "y": 15,
      "z": -4,
      "name": "Plant_Leaves_Beech"
    },
    {
      "x": 9,
      "y": 16,
      "z": -4,
      "name": "Plant_Leaves_Beech"
    },
    {
      "x": 9,
      "y": 14,
      "z": -3,
      "name": "Plant_Leaves_Beech"
    },
    {
      "x": 9,
      "y": 15,
      "z": -3,
      "name": "Plant_Leaves_Beech"
    },
    {
      "x": 9,
      "y": 16,
      "z": -3,
      "name": "Plant_Leaves_Beech"
    },
    {
      "x": 9,
      "y": 15,
      "z": -2,
      "name": "Wood_Gumboab_Branch_Corner",
      "rotation": 2
    },
    {
      "x": 9,
      "y": 16,
      "z": -2,
      "name": "Plant_Leaves_Beech"
    },
    {
      "x": 9,
      "y": 17,
      "z": -2,
      "name": "Plant_Leaves_Beech"
    },
    {
      "x": 9,
      "y": 15,
      "z": -1,
      "name": "Wood_Gumboab_Trunk_Full"
    },
    {
      "x": 9,
      "y": 17,
      "z": -1,
      "name": "Plant_Leaves_Beech"
    },
    {
      "x": 9,
      "y": 18,
      "z": -1,
      "name": "Plant_Leaves_Beech"
    },
    {
      "x": 9,
      "y": 15,
      "z": 0,
      "name": "Wood_Gumboab_Trunk_Full"
    },
    {
      "x": 9,
      "y": 16,
      "z": 0,
      "name": "Wood_Gumboab_Branch_Long"
    },
    {
      "x": 9,
      "y": 17,
      "z": 0,
      "name": "Wood_Gumboab_Branch_Long"
    },
    {
      "x": 9,
      "y": 18,
      "z": 0,
      "name": "Plant_Leaves_Beech"
    },
    {
      "x": 9,
      "y": 15,
      "z": 1,
      "name": "Wood_Gumboab_Branch_Long",
      "rotation": 4
    },
    {
      "x": 9,
      "y": 17,
      "z": 1,
      "name": "Plant_Leaves_Beech"
    },
    {
      "x": 9,
      "y": 18,
      "z": 1,
      "name": "Plant_Leaves_Beech"
    },
    {
      "x": 9,
      "y": 15,
      "z": 2,
      "name": "Wood_Gumboab_Branch_Corner"
    },
    {
      "x": 9,
      "y": 16,
      "z": 2,
      "name": "Plant_Leaves_Beech"
    },
    {
      "x": 9,
      "y": 17,
      "z": 2,
      "name": "Plant_Leaves_Beech"
    },
    {
      "x": 9,
      "y": 15,
      "z": 3,
      "name": "Plant_Leaves_Beech"
    },
    {
      "x": 9,
      "y": 16,
      "z": 3,
      "name": "Plant_Leaves_Beech"
    },
    {
      "x": 9,
      "y": 17,
      "z": 3,
      "name": "Plant_Leaves_Beech"
    },
    {
      "x": 9,
      "y": 14,
      "z": 4,
      "name": "Plant_Leaves_Beech"
    },
    {
      "x": 9,
      "y": 15,
      "z": 4,
      "name": "Plant_Leaves_Beech"
    },
    {
      "x": 9,
      "y": 16,
      "z": 4,
      "name": "Plant_Leaves_Beech"
    },
    {
      "x": 10,
      "y": 13,
      "z": -3,
      "name": "Plant_Leaves_Beech"
    },
    {
      "x": 10,
      "y": 14,
      "z": -3,
      "name": "Plant_Leaves_Beech"
    },
    {
      "x": 10,
      "y": 15,
      "z": -3,
      "name": "Plant_Leaves_Beech"
    },
    {
      "x": 10,
      "y": 16,
      "z": -2,
      "name": "Plant_Leaves_Beech"
    },
    {
      "x": 10,
      "y": 17,
      "z": -2,
      "name": "Plant_Leaves_Beech"
    },
    {
      "x": 10,
      "y": 14,
      "z": -1,
      "name": "Plant_Leaves_Beech"
    },
    {
      "x": 10,
      "y": 18,
      "z": -1,
      "name": "Plant_Leaves_Beech"
    },
    {
      "x": 10,
      "y": 15,
      "z": 0,
      "name": "Wood_Gumboab_Branch_Long",
      "rotation": 5
    },
    {
      "x": 10,
      "y": 18,
      "z": 0,
      "name": "Plant_Leaves_Beech"
    },
    {
      "x": 10,
      "y": 18,
      "z": 1,
      "name": "Plant_Leaves_Beech"
    },
    {
      "x": 10,
      "y": 16,
      "z": 2,
      "name": "Plant_Leaves_Beech"
    },
    {
      "x": 10,
      "y": 14,
      "z": 3,
      "name": "Plant_Leaves_Beech"
    },
    {
      "x": 10,
      "y": 15,
      "z": 3,
      "name": "Plant_Leaves_Beech"
    },
    {
      "x": 10,
      "y": 16,
      "z": 3,
      "name": "Plant_Leaves_Beech"
    },
    {
      "x": 10,
      "y": 17,
      "z": 3,
      "name": "Plant_Leaves_Beech"
    },
    {
      "x": 10,
      "y": 15,
      "z": 4,
      "name": "Plant_Leaves_Beech"
    },
    {
      "x": 11,
      "y": 15,
      "z": -3,
      "name": "Plant_Leaves_Beech"
    },
    {
      "x": 11,
      "y": 13,
      "z": -2,
      "name": "Plant_Leaves_Beech"
    },
    {
      "x": 11,
      "y": 14,
      "z": -2,
      "name": "Plant_Leaves_Beech"
    },
    {
      "x": 11,
      "y": 15,
      "z": -2,
      "name": "Plant_Leaves_Beech"
    },
    {
      "x": 11,
      "y": 16,
      "z": -2,
      "name": "Plant_Leaves_Beech"
    },
    {
      "x": 11,
      "y": 14,
      "z": -1,
      "name": "Plant_Leaves_Beech"
    },
    {
      "x": 11,
      "y": 15,
      "z": -1,
      "name": "Plant_Leaves_Beech"
    },
    {
      "x": 11,
      "y": 16,
      "z": -1,
      "name": "Plant_Leaves_Beech"
    },
    {
      "x": 11,
      "y": 17,
      "z": -1,
      "name": "Plant_Leaves_Beech"
    },
    {
      "x": 11,
      "y": 15,
      "z": 0,
      "name": "Wood_Gumboab_Branch_Long",
      "rotation": 5
    },
    {
      "x": 11,
      "y": 17,
      "z": 1,
      "name": "Plant_Leaves_Beech"
    },
    {
      "x": 11,
      "y": 13,
      "z": 2,
      "name": "Plant_Leaves_Beech"
    },
    {
      "x": 11,
      "y": 14,
      "z": 2,
      "name": "Plant_Leaves_Beech"
    },
    {
      "x": 11,
      "y": 15,
      "z": 2,
      "name": "Plant_Leaves_Beech"
    },
    {
      "x": 11,
      "y": 16,
      "z": 2,
      "name": "Plant_Leaves_Beech"
    },
    {
      "x": 11,
      "y": 17,
      "z": 2,
      "name": "Plant_Leaves_Beech"
    },
    {
      "x": 11,
      "y": 15,
      "z": 3,
      "name": "Plant_Leaves_Beech"
    },
    {
      "x": 11,
      "y": 16,
      "z": 3,
      "name": "Plant_Leaves_Beech"
    },
    {
      "x": 12,
      "y": 15,
      "z": -2,
      "name": "Plant_Leaves_Beech"
    },
    {
      "x": 12,
      "y": 14,
      "z": -1,
      "name": "Plant_Leaves_Beech"
    },
    {
      "x": 12,
      "y": 15,
      "z": -1,
      "name": "Plant_Leaves_Beech"
    },
    {
      "x": 12,
      "y": 16,
      "z": -1,
      "name": "Plant_Leaves_Beech"
    },
    {
      "x": 12,
      "y": 15,
      "z": 0,
      "name": "Wood_Gumboab_Branch_Corner",
      "rotation": 1
    },
    {
      "x": 12,
      "y": 16,
      "z": 0,
      "name": "Plant_Leaves_Beech"
    },
    {
      "x": 12,
      "y": 17,
      "z": 0,
      "name": "Plant_Leaves_Beech"
    },
    {
      "x": 12,
      "y": 13,
      "z": 2,
      "name": "Plant_Leaves_Beech"
    },
    {
      "x": 12,
      "y": 14,
      "z": 2,
      "name": "Plant_Leaves_Beech"
    },
    {
      "x": 12,
      "y": 15,
      "z": 2,
      "name": "Plant_Leaves_Beech"
    },
    {
      "x": 12,
      "y": 16,
      "z": 2,
      "name": "Plant_Leaves_Beech"
    },
    {
      "x": 12,
      "y": 15,
      "z": 3,
      "name": "Plant_Leaves_Beech"
    },
    {
      "x": 13,
      "y": 15,
      "z": -1,
      "name": "Plant_Leaves_Beech"
    },
    {
      "x": 13,
      "y": 13,
      "z": 0,
      "name": "Plant_Leaves_Beech"
    },
    {
      "x": 13,
      "y": 14,
      "z": 0,
      "name": "Plant_Leaves_Beech"
    },
    {
      "x": 13,
      "y": 15,
      "z": 0,
      "name": "Plant_Leaves_Beech"
    },
    {
      "x": 13,
      "y": 16,
      "z": 0,
      "name": "Plant_Leaves_Beech"
    },
    {
      "x": 13,
      "y": 14,
      "z": 1,
      "name": "Plant_Leaves_Beech"
    },
    {
      "x": 13,
      "y": 15,
      "z": 1,
      "name": "Plant_Leaves_Beech"
    }
  ]
}