{
  "version": 8,
  "blockIdVersion": 8,
  "anchorX": 0,
  "anchorY": 0,
  "anchorZ": 0,
  "blocks": [
    {
      "x": -21,
      "y": -2,
      "z": -17,
      "name": "Rock_Marble"
    },
    {
      "x": -21,
      "y": -1,
      "z": -17,
      "name": "Rock_Marble"
    },
    {
      "x": -21,
      "y": 0,
      "z": -17,
      "name": "Rock_Marble"
    },
    {
      "x": -21,
      "y": -2,
      "z": -16,
      "name": "Rock_Marble"
    },
    {
      "x": -21,
      "y": -1,
      "z": -16,
      "name": "Rock_Marble"
    },
    {
      "x": -21,
      "y": 0,
      "z": -16,
      "name": "Rock_Marble"
    },
    {
      "x": -21,
      "y": -2,
      "z": -15,
      "name": "Rock_Marble"
    },
    {
      "x": -21,
      "y": -1,
      "z": -15,
      "name": "Rock_Marble"
    },
    {
      "x": -21,
      "y": 0,
      "z": -15,
      "name": "Rock_Marble"
    },
    {
      "x": -21,
      "y": -2,
      "z": -14,
      "name": "Rock_Marble"
    },
    {
      "x": -21,
      "y": -1,
      "z": -14,
      "name": "Rock_Marble"
    },
    {
      "x": -21,
      "y": 0,
      "z": -14,
      "name": "Rock_Marble"
    },
    {
      "x": -21,
      "y": -2,
      "z": -13,
      "name": "Rock_Marble"
    },
    {
      "x": -21,
      "y": -1,
      "z": -13,
      "name": "Rock_Marble"
    },
    {
      "x": -21,
      "y": 0,
      "z": -13,
      "name": "Rock_Marble"
    },
    {
      "x": -21,
      "y": -2,
      "z": -12,
      "name": "Rock_Marble"
    },
    {
      "x": -21,
      "y": -1,
      "z": -12,
      "name": "Rock_Marble"
    },
    {
      "x": -21,
      "y": 0,
      "z": -12,
      "name": "Rock_Marble"
    },
    {
      "x": -21,
      "y": -2,
      "z": -11,
      "name": "Rock_Chalk"
    },
    {
      "x": -21,
      "y": -1,
      "z": -11,
      "name": "Rock_Chalk"
    },
    {
      "x": -21,
      "y": 0,
      "z": -11,
      "name": "Rock_Chalk"
    },
    {
      "x": -21,
      "y": -2,
      "z": -10,
      "name": "Rock_Chalk"
    },
    {
      "x": -21,
      "y": 0,
      "z": -10,
      "name": "Rock_Chalk"
    },
    {
      "x": -20,
      "y": -2,
      "z": -18,
      "name": "Rock_Marble"
    },
    {
      "x": -20,
      "y": -1,
      "z": -18,
      "name": "Rock_Marble"
    },
    {
      "x": -20,
      "y": 0,
      "z": -18,
      "name": "Rock_Marble"
    },
    {
      "x": -20,
      "y": 1,
      "z": -18,
      "name": "Rock_Marble"
    },
    {
      "x": -20,
      "y": -4,
      "z": -17,
      "name": "Rock_Marble"
    },
    {
      "x": -20,
      "y": -3,
      "z": -17,
      "name": "Rock_Marble"
    },
    {
      "x": -20,
      "y": -2,
      "z": -17,
      "name": "Rock_Marble"
    },
    {
      "x": -20,
      "y": -1,
      "z": -17,
      "name": "Rock_Marble"
    },
    {
      "x": -20,
      "y": 0,
      "z": -17,
      "name": "Rock_Marble"
    },
    {
      "x": -20,
      "y": 1,
      "z": -17,
      "name": "Rock_Marble"
    },
    {
      "x": -20,
      "y": -5,
      "z": -16,
      "name": "Rock_Marble"
    },
    {
      "x": -20,
      "y": -4,
      "z": -16,
      "name": "Rock_Marble"
    },
    {
      "x": -20,
      "y": -3,
      "z": -16,
      "name": "Rock_Marble"
    },
    {
      "x": -20,
      "y": -2,
      "z": -16,
      "name": "Rock_Marble"
    },
    {
      "x": -20,
      "y": -1,
      "z": -16,
      "name": "Rock_Marble"
    },
    {
      "x": -20,
      "y": 0,
      "z": -16,
      "name": "Rock_Marble"
    },
    {
      "x": -20,
      "y": 1,
      "z": -16,
      "name": "Rock_Marble"
    },
    {
      "x": -20,
      "y": -6,
      "z": -15,
      "name": "Rock_Marble"
    },
    {
      "x": -20,
      "y": -5,
      "z": -15,
      "name": "Rock_Marble"
    },
    {
      "x": -20,
      "y": -4,
      "z": -15,
      "name": "Rock_Marble"
    },
    {
      "x": -20,
      "y": -3,
      "z": -15,
      "name": "Rock_Marble"
    },
    {
      "x": -20,
      "y": -2,
      "z": -15,
      "name": "Rock_Marble"
    },
    {
      "x": -20,
      "y": -1,
      "z": -15,
      "name": "Rock_Marble"
    },
    {
      "x": -20,
      "y": 0,
      "z": -15,
      "name": "Rock_Marble"
    },
    {
      "x": -20,
      "y": 1,
      "z": -15,
      "name": "Rock_Marble"
    },
    {
      "x": -20,
      "y": -6,
      "z": -14,
      "name": "Rock_Marble"
    },
    {
      "x": -20,
      "y": -5,
      "z": -14,
      "name": "Rock_Marble"
    },
    {
      "x": -20,
      "y": -4,
      "z": -14,
      "name": "Rock_Marble"
    },
    {
      "x": -20,
      "y": -3,
      "z": -14,
      "name": "Rock_Marble"
    },
    {
      "x": -20,
      "y": -2,
      "z": -14,
      "name": "Rock_Marble"
    },
    {
      "x": -20,
      "y": -1,
      "z": -14,
      "name": "Rock_Marble"
    },
    {
      "x": -20,
      "y": 0,
      "z": -14,
      "name": "Rock_Marble"
    },
    {
      "x": -20,
      "y": 1,
      "z": -14,
      "name": "Rock_Marble"
    },
    {
      "x": -20,
      "y": -6,
      "z": -13,
      "name": "Rock_Marble"
    },
    {
      "x": -20,
      "y": -5,
      "z": -13,
      "name": "Rock_Marble"
    },
    {
      "x": -20,
      "y": -4,
      "z": -13,
      "name": "Rock_Marble"
    },
    {
      "x": -20,
      "y": -3,
      "z": -13,
      "name": "Rock_Marble"
    },
    {
      "x": -20,
      "y": -2,
      "z": -13,
      "name": "Rock_Marble"
    },
    {
      "x": -20,
      "y": -1,
      "z": -13,
      "name": "Rock_Marble"
    },
    {
      "x": -20,
      "y": 0,
      "z": -13,
      "name": "Rock_Marble"
    },
    {
      "x": -20,
      "y": 1,
      "z": -13,
      "name": "Rock_Marble"
    },
    {
      "x": -20,
      "y": -6,
      "z": -12,
      "name": "Rock_Marble"
    },
    {
      "x": -20,
      "y": -5,
      "z": -12,
      "name": "Rock_Marble"
    },
    {
      "x": -20,
      "y": -4,
      "z": -12,
      "name": "Rock_Marble"
    },
    {
      "x": -20,
      "y": -3,
      "z": -12,
      "name": "Rock_Marble"
    },
    {
      "x": -20,
      "y": -2,
      "z": -12,
      "name": "Rock_Marble"
    },
    {
      "x": -20,
      "y": -1,
      "z": -12,
      "name": "Rock_Marble"
    },
    {
      "x": -20,
      "y": 0,
      "z": -12,
      "name": "Rock_Marble"
    },
    {
      "x": -20,
      "y": 1,
      "z": -12,
      "name": "Rock_Marble"
    },
    {
      "x": -20,
      "y": -6,
      "z": -11,
      "name": "Rock_Chalk"
    },
    {
      "x": -20,
      "y": -5,
      "z": -11,
      "name": "Rock_Chalk"
    },
    {
      "x": -20,
      "y": 1,
      "z": -11,
      "name": "Rock_Chalk"
    },
    {
      "x": -20,
      "y": 10,
      "z": -11,
      "name": "Rock_Chalk"
    },
    {
      "x": -19,
      "y": -2,
      "z": -19,
      "name": "Rock_Marble"
    },
    {
      "x": -19,
      "y": -1,
      "z": -19,
      "name": "Rock_Marble"
    },
    {
      "x": -19,
      "y": 0,
      "z": -19,
      "name": "Rock_Marble"
    },
    {
      "x": -19,
      "y": 1,
      "z": -19,
      "name": "Rock_Marble"
    },
    {
      "x": -19,
      "y": -4,
      "z": -18,
      "name": "Rock_Marble"
    },
    {
      "x": -19,
      "y": -3,
      "z": -18,
      "name": "Rock_Marble"
    },
    {
      "x": -19,
      "y": -2,
      "z": -18,
      "name": "Rock_Marble"
    },
    {
      "x": -19,
      "y": -1,
      "z": -18,
      "name": "Rock_Marble"
    },
    {
      "x": -19,
      "y": 0,
      "z": -18,
      "name": "Rock_Marble"
    },
    {
      "x": -19,
      "y": 1,
      "z": -18,
      "name": "Rock_Marble"
    },
    {
      "x": -19,
      "y": 2,
      "z": -18,
      "name": "Rock_Marble"
    },
    {
      "x": -19,
      "y": 3,
      "z": -18,
      "name": "Rock_Marble"
    },
    {
      "x": -19,
      "y": -5,
      "z": -17,
      "name": "Rock_Marble"
    },
    {
      "x": -19,
      "y": -4,
      "z": -17,
      "name": "Rock_Marble"
    },
    {
      "x": -19,
      "y": -3,
      "z": -17,
      "name": "Rock_Marble"
    },
    {
      "x": -19,
      "y": -2,
      "z": -17,
      "name": "Rock_Marble"
    },
    {
      "x": -19,
      "y": -1,
      "z": -17,
      "name": "Rock_Marble"
    },
    {
      "x": -19,
      "y": 0,
      "z": -17,
      "name": "Rock_Marble"
    },
    {
      "x": -19,
      "y": 1,
      "z": -17,
      "name": "Rock_Marble"
    },
    {
      "x": -19,
      "y": 2,
      "z": -17,
      "name": "Rock_Marble"
    },
    {
      "x": -19,
      "y": 3,
      "z": -17,
      "name": "Rock_Marble"
    },
    {
      "x": -19,
      "y": -6,
      "z": -16,
      "name": "Rock_Marble"
    },
    {
      "x": -19,
      "y": -5,
      "z": -16,
      "name": "Rock_Marble"
    },
    {
      "x": -19,
      "y": -4,
      "z": -16,
      "name": "Rock_Marble"
    },
    {
      "x": -19,
      "y": -3,
      "z": -16,
      "name": "Rock_Marble"
    },
    {
      "x": -19,
      "y": -2,
      "z": -16,
      "name": "Rock_Marble"
    },
    {
      "x": -19,
      "y": -1,
      "z": -16,
      "name": "Rock_Marble"
    },
    {
      "x": -19,
      "y": 0,
      "z": -16,
      "name": "Rock_Marble"
    },
    {
      "x": -19,
      "y": 1,
      "z": -16,
      "name": "Rock_Marble"
    },
    {
      "x": -19,
      "y": 2,
      "z": -16,
      "name": "Rock_Marble"
    },
    {
      "x": -19,
      "y": 3,
      "z": -16,
      "name": "Rock_Marble"
    },
    {
      "x": -19,
      "y": -7,
      "z": -15,
      "name": "Rock_Marble"
    },
    {
      "x": -19,
      "y": -6,
      "z": -15,
      "name": "Rock_Marble"
    },
    {
      "x": -19,
      "y": -5,
      "z": -15,
      "name": "Rock_Marble"
    },
    {
      "x": -19,
      "y": -4,
      "z": -15,
      "name": "Rock_Marble"
    },
    {
      "x": -19,
      "y": -3,
      "z": -15,
      "name": "Rock_Shale"
    },
    {
      "x": -19,
      "y": -2,
      "z": -15,
      "name": "Rock_Shale"
    },
    {
      "x": -19,
      "y": -1,
      "z": -15,
      "name": "Rock_Shale"
    },
    {
      "x": -19,
      "y": 0,
      "z": -15,
      "name": "Rock_Marble"
    },
    {
      "x": -19,
      "y": 1,
      "z": -15,
      "name": "Rock_Marble"
    },
    {
      "x": -19,
      "y": 2,
      "z": -15,
      "name": "Rock_Marble"
    },
    {
      "x": -19,
      "y": 3,
      "z": -15,
      "name": "Rock_Marble"
    },
    {
      "x": -19,
      "y": -8,
      "z": -14,
      "name": "Rock_Marble"
    },
    {
      "x": -19,
      "y": -7,
      "z": -14,
      "name": "Rock_Marble"
    },
    {
      "x": -19,
      "y": -6,
      "z": -14,
      "name": "Rock_Marble"
    },
    {
      "x": -19,
      "y": -5,
      "z": -14,
      "name": "Rock_Marble"
    },
    {
      "x": -19,
      "y": -4,
      "z": -14,
      "name": "Rock_Shale"
    },
    {
      "x": -19,
      "y": -3,
      "z": -14,
      "name": "Rock_Shale"
    },
    {
      "x": -19,
      "y": -2,
      "z": -14,
      "name": "Rock_Shale"
    },
    {
      "x": -19,
      "y": -1,
      "z": -14,
      "name": "Rock_Shale"
    },
    {
      "x": -19,
      "y": 0,
      "z": -14,
      "name": "Rock_Shale"
    },
    {
      "x": -19,
      "y": 1,
      "z": -14,
      "name": "Rock_Marble"
    },
    {
      "x": -19,
      "y": 2,
      "z": -14,
      "name": "Rock_Marble"
    },
    {
      "x": -19,
      "y": 3,
      "z": -14,
      "name": "Rock_Marble"
    },
    {
      "x": -19,
      "y": -9,
      "z": -13,
      "name": "Rock_Marble"
    },
    {
      "x": -19,
      "y": -8,
      "z": -13,
      "name": "Rock_Marble"
    },
    {
      "x": -19,
      "y": -7,
      "z": -13,
      "name": "Rock_Marble"
    },
    {
      "x": -19,
      "y": -6,
      "z": -13,
      "name": "Rock_Marble"
    },
    {
      "x": -19,
      "y": -5,
      "z": -13,
      "name": "Rock_Marble"
    },
    {
      "x": -19,
      "y": -4,
      "z": -13,
      "name": "Rock_Shale"
    },
    {
      "x": -19,
      "y": 0,
      "z": -13,
      "name": "Rock_Shale"
    },
    {
      "x": -19,
      "y": 1,
      "z": -13,
      "name": "Rock_Marble"
    },
    {
      "x": -19,
      "y": 2,
      "z": -13,
      "name": "Rock_Marble"
    },
    {
      "x": -19,
      "y": 3,
      "z": -13,
      "name": "Rock_Marble"
    },
    {
      "x": -19,
      "y": -9,
      "z": -12,
      "name": "Rock_Marble"
    },
    {
      "x": -19,
      "y": -8,
      "z": -12,
      "name": "Rock_Marble"
    },
    {
      "x": -19,
      "y": -7,
      "z": -12,
      "name": "Rock_Marble"
    },
    {
      "x": -19,
      "y": -6,
      "z": -12,
      "name": "Rock_Marble"
    },
    {
      "x": -19,
      "y": 1,
      "z": -12,
      "name": "Rock_Marble"
    },
    {
      "x": -19,
      "y": 2,
      "z": -12,
      "name": "Rock_Marble"
    },
    {
      "x": -19,
      "y": 3,
      "z": -12,
      "name": "Rock_Marble"
    },
    {
      "x": -19,
      "y": 11,
      "z": -12,
      "name": "Rock_Chalk"
    },
    {
      "x": -19,
      "y": -9,
      "z": -11,
      "name": "Rock_Marble"
    },
    {
      "x": -19,
      "y": -8,
      "z": -11,
      "name": "Rock_Chalk"
    },
    {
      "x": -19,
      "y": 2,
      "z": -11,
      "name": "Rock_Chalk"
    },
    {
      "x": -19,
      "y": 3,
      "z": -11,
      "name": "Rock_Chalk"
    },
    {
      "x": -19,
      "y": 11,
      "z": -11,
      "name": "Rock_Chalk"
    },
    {
      "x": -19,
      "y": 12,
      "z": -11,
      "name": "Rock_Chalk"
    },
    {
      "x": -19,
      "y": 3,
      "z": -10,
      "name": "Rock_Chalk"
    },
    {
      "x": -19,
      "y": 12,
      "z": -10,
      "name": "Rock_Chalk"
    },
    {
      "x": -18,
      "y": -2,
      "z": -20,
      "name": "Rock_Calcite"
    },
    {
      "x": -18,
      "y": -1,
      "z": -20,
      "name": "Rock_Calcite"
    },
    {
      "x": -18,
      "y": 0,
      "z": -20,
      "name": "Rock_Calcite"
    },
    {
      "x": -18,
      "y": 1,
      "z": -20,
      "name": "Rock_Calcite"
    },
    {
      "x": -18,
      "y": -4,
      "z": -19,
      "name": "Rock_Marble"
    },
    {
      "x": -18,
      "y": -3,
      "z": -19,
      "name": "Rock_Marble"
    },
    {
      "x": -18,
      "y": -2,
      "z": -19,
      "name": "Rock_Marble"
    },
    {
      "x": -18,
      "y": -1,
      "z": -19,
      "name": "Rock_Marble"
    },
    {
      "x": -18,
      "y": 0,
      "z": -19,
      "name": "Rock_Marble"
    },
    {
      "x": -18,
      "y": 1,
      "z": -19,
      "name": "Rock_Marble"
    },
    {
      "x": -18,
      "y": 2,
      "z": -19,
      "name": "Rock_Marble"
    },
    {
      "x": -18,
      "y": 3,
      "z": -19,
      "name": "Rock_Marble"
    },
    {
      "x": -18,
      "y": 4,
      "z": -19,
      "name": "Rock_Marble"
    },
    {
      "x": -18,
      "y": -5,
      "z": -18,
      "name": "Rock_Marble"
    },
    {
      "x": -18,
      "y": -4,
      "z": -18,
      "name": "Rock_Marble"
    },
    {
      "x": -18,
      "y": -3,
      "z": -18,
      "name": "Rock_Marble"
    },
    {
      "x": -18,
      "y": -2,
      "z": -18,
      "name": "Rock_Marble"
    },
    {
      "x": -18,
      "y": -1,
      "z": -18,
      "name": "Rock_Marble"
    },
    {
      "x": -18,
      "y": 0,
      "z": -18,
      "name": "Rock_Marble"
    },
    {
      "x": -18,
      "y": 1,
      "z": -18,
      "name": "Rock_Marble"
    },
    {
      "x": -18,
      "y": 2,
      "z": -18,
      "name": "Rock_Marble"
    },
    {
      "x": -18,
      "y": 3,
      "z": -18,
      "name": "Rock_Marble"
    },
    {
      "x": -18,
      "y": 4,
      "z": -18,
      "name": "Rock_Marble"
    },
    {
      "x": -18,
      "y": 5,
      "z": -18,
      "name": "Rock_Marble"
    },
    {
      "x": -18,
      "y": 6,
      "z": -18,
      "name": "Rock_Marble"
    },
    {
      "x": -18,
      "y": -6,
      "z": -17,
      "name": "Rock_Marble"
    },
    {
      "x": -18,
      "y": -5,
      "z": -17,
      "name": "Rock_Marble"
    },
    {
      "x": -18,
      "y": -4,
      "z": -17,
      "name": "Rock_Marble"
    },
    {
      "x": -18,
      "y": -3,
      "z": -17,
      "name": "Rock_Marble"
    },
    {
      "x": -18,
      "y": -2,
      "z": -17,
      "name": "Rock_Marble"
    },
    {
      "x": -18,
      "y": -1,
      "z": -17,
      "name": "Rock_Marble"
    },
    {
      "x": -18,
      "y": 0,
      "z": -17,
      "name": "Rock_Marble"
    },
    {
      "x": -18,
      "y": 1,
      "z": -17,
      "name": "Rock_Marble"
    },
    {
      "x": -18,
      "y": 2,
      "z": -17,
      "name": "Rock_Marble"
    },
    {
      "x": -18,
      "y": 3,
      "z": -17,
      "name": "Rock_Marble"
    },
    {
      "x": -18,
      "y": 4,
      "z": -17,
      "name": "Rock_Marble"
    },
    {
      "x": -18,
      "y": 5,
      "z": -17,
      "name": "Rock_Marble"
    },
    {
      "x": -18,
      "y": 6,
      "z": -17,
      "name": "Rock_Marble"
    },
    {
      "x": -18,
      "y": 7,
      "z": -17,
      "name": "Rock_Stone"
    },
    {
      "x": -18,
      "y": -7,
      "z": -16,
      "name": "Rock_Marble"
    },
    {
      "x": -18,
      "y": -6,
      "z": -16,
      "name": "Rock_Marble"
    },
    {
      "x": -18,
      "y": -5,
      "z": -16,
      "name": "Rock_Marble"
    },
    {
      "x": -18,
      "y": -4,
      "z": -16,
      "name": "Rock_Shale"
    },
    {
      "x": -18,
      "y": -3,
      "z": -16,
      "name": "Rock_Shale"
    },
    {
      "x": -18,
      "y": -2,
      "z": -16,
      "name": "Rock_Shale"
    },
    {
      "x": -18,
      "y": -1,
      "z": -16,
      "name": "Rock_Shale"
    },
    {
      "x": -18,
      "y": 0,
      "z": -16,
      "name": "Rock_Marble"
    },
    {
      "x": -18,
      "y": 1,
      "z": -16,
      "name": "Rock_Marble"
    },
    {
      "x": -18,
      "y": 2,
      "z": -16,
      "name": "Rock_Marble"
    },
    {
      "x": -18,
      "y": 3,
      "z": -16,
      "name": "Rock_Marble"
    },
    {
      "x": -18,
      "y": 4,
      "z": -16,
      "name": "Rock_Marble"
    },
    {
      "x": -18,
      "y": 5,
      "z": -16,
      "name": "Rock_Marble"
    },
    {
      "x": -18,
      "y": 6,
      "z": -16,
      "name": "Rock_Marble"
    },
    {
      "x": -18,
      "y": 7,
      "z": -16,
      "name": "Rock_Stone"
    },
    {
      "x": -18,
      "y": -8,
      "z": -15,
      "name": "Rock_Marble"
    },
    {
      "x": -18,
      "y": -7,
      "z": -15,
      "name": "Rock_Marble"
    },
    {
      "x": -18,
      "y": -6,
      "z": -15,
      "name": "Rock_Marble"
    },
    {
      "x": -18,
      "y": -5,
      "z": -15,
      "name": "Rock_Shale"
    },
    {
      "x": -18,
      "y": -4,
      "z": -15,
      "name": "Rock_Shale"
    },
    {
      "x": -18,
      "y": -3,
      "z": -15,
      "name": "Rock_Shale"
    },
    {
      "x": -18,
      "y": -2,
      "z": -15,
      "name": "Rock_Shale"
    },
    {
      "x": -18,
      "y": -1,
      "z": -15,
      "name": "Rock_Shale"
    },
    {
      "x": -18,
      "y": 0,
      "z": -15,
      "name": "Rock_Shale"
    },
    {
      "x": -18,
      "y": 1,
      "z": -15,
      "name": "Rock_Marble"
    },
    {
      "x": -18,
      "y": 2,
      "z": -15,
      "name": "Rock_Marble"
    },
    {
      "x": -18,
      "y": 3,
      "z": -15,
      "name": "Rock_Marble"
    },
    {
      "x": -18,
      "y": 4,
      "z": -15,
      "name": "Rock_Marble"
    },
    {
      "x": -18,
      "y": 5,
      "z": -15,
      "name": "Rock_Marble"
    },
    {
      "x": -18,
      "y": 6,
      "z": -15,
      "name": "Rock_Marble"
    },
    {
      "x": -18,
      "y": 7,
      "z": -15,
      "name": "Rock_Stone"
    },
    {
      "x": -18,
      "y": -9,
      "z": -14,
      "name": "Rock_Marble"
    },
    {
      "x": -18,
      "y": -8,
      "z": -14,
      "name": "Rock_Marble"
    },
    {
      "x": -18,
      "y": -7,
      "z": -14,
      "name": "Rock_Marble"
    },
    {
      "x": -18,
      "y": -6,
      "z": -14,
      "name": "Rock_Shale"
    },
    {
      "x": -18,
      "y": -5,
      "z": -14,
      "name": "Rock_Shale"
    },
    {
      "x": -18,
      "y": 0,
      "z": -14,
      "name": "Rock_Shale"
    },
    {
      "x": -18,
      "y": 1,
      "z": -14,
      "name": "Rock_Shale"
    },
    {
      "x": -18,
      "y": 2,
      "z": -14,
      "name": "Rock_Marble"
    },
    {
      "x": -18,
      "y": 3,
      "z": -14,
      "name": "Rock_Marble"
    },
    {
      "x": -18,
      "y": 4,
      "z": -14,
      "name": "Rock_Marble"
    },
    {
      "x": -18,
      "y": 5,
      "z": -14,
      "name": "Rock_Marble"
    },
    {
      "x": -18,
      "y": 6,
      "z": -14,
      "name": "Rock_Marble"
    },
    {
      "x": -18,
      "y": 7,
      "z": -14,
      "name": "Rock_Stone"
    },
    {
      "x": -18,
      "y": -10,
      "z": -13,
      "name": "Rock_Stone"
    },
    {
      "x": -18,
      "y": -9,
      "z": -13,
      "name": "Rock_Marble"
    },
    {
      "x": -18,
      "y": -8,
      "z": -13,
      "name": "Rock_Marble"
    },
    {
      "x": -18,
      "y": -7,
      "z": -13,
      "name": "Rock_Marble"
    },
    {
      "x": -18,
      "y": -6,
      "z": -13,
      "name": "Rock_Shale"
    },
    {
      "x": -18,
      "y": 1,
      "z": -13,
      "name": "Rock_Shale"
    },
    {
      "x": -18,
      "y": 2,
      "z": -13,
      "name": "Rock_Marble"
    },
    {
      "x": -18,
      "y": 3,
      "z": -13,
      "name": "Rock_Marble"
    },
    {
      "x": -18,
      "y": 4,
      "z": -13,
      "name": "Rock_Marble"
    },
    {
      "x": -18,
      "y": 5,
      "z": -13,
      "name": "Rock_Marble"
    },
    {
      "x": -18,
      "y": 6,
      "z": -13,
      "name": "Rock_Marble"
    },
    {
      "x": -18,
      "y": 7,
      "z": -13,
      "name": "Rock_Stone"
    },
    {
      "x": -18,
      "y": 12,
      "z": -13,
      "name": "Rock_Stone"
    },
    {
      "x": -18,
      "y": -10,
      "z": -12,
      "name": "Rock_Shale"
    },
    {
      "x": -18,
      "y": -9,
      "z": -12,
      "name": "Rock_Marble"
    },
    {
      "x": -18,
      "y": -8,
      "z": -12,
      "name": "Rock_Marble"
    },
    {
      "x": -18,
      "y": 2,
      "z": -12,
      "name": "Rock_Marble"
    },
    {
      "x": -18,
      "y": 3,
      "z": -12,
      "name": "Rock_Chalk"
    },
    {
      "x": -18,
      "y": 4,
      "z": -12,
      "name": "Rock_Chalk"
    },
    {
      "x": -18,
      "y": 5,
      "z": -12,
      "name": "Rock_Chalk"
    },
    {
      "x": -18,
      "y": 6,
      "z": -12,
      "name": "Rock_Chalk"
    },
    {
      "x": -18,
      "y": 7,
      "z": -12,
      "name": "Rock_Shale"
    },
    {
      "x": -18,
      "y": 12,
      "z": -12,
      "name": "Rock_Shale"
    },
    {
      "x": -18,
      "y": -10,
      "z": -11,
      "name": "Rock_Shale"
    },
    {
      "x": -18,
      "y": 3,
      "z": -11,
      "name": "Rock_Chalk"
    },
    {
      "x": -18,
      "y": 4,
      "z": -11,
      "name": "Rock_Chalk"
    },
    {
      "x": -18,
      "y": 5,
      "z": -11,
      "name": "Rock_Chalk"
    },
    {
      "x": -18,
      "y": 6,
      "z": -11,
      "name": "Rock_Chalk"
    },
    {
      "x": -18,
      "y": 7,
      "z": -11,
      "name": "Rock_Shale"
    },
    {
      "x": -18,
      "y": 12,
      "z": -11,
      "name": "Rock_Shale"
    },
    {
      "x": -17,
      "y": 0,
      "z": -21,
      "name": "Rock_Calcite"
    },
    {
      "x": -17,
      "y": 1,
      "z": -21,
      "name": "Rock_Calcite"
    },
    {
      "x": -17,
      "y": -4,
      "z": -20,
      "name": "Rock_Calcite"
    },
    {
      "x": -17,
      "y": -3,
      "z": -20,
      "name": "Rock_Calcite"
    },
    {
      "x": -17,
      "y": -2,
      "z": -20,
      "name": "Rock_Calcite"
    },
    {
      "x": -17,
      "y": -1,
      "z": -20,
      "name": "Rock_Calcite"
    },
    {
      "x": -17,
      "y": 0,
      "z": -20,
      "name": "Rock_Calcite"
    },
    {
      "x": -17,
      "y": 1,
      "z": -20,
      "name": "Rock_Calcite"
    },
    {
      "x": -17,
      "y": 2,
      "z": -20,
      "name": "Rock_Marble"
    },
    {
      "x": -17,
      "y": 3,
      "z": -20,
      "name": "Rock_Marble"
    },
    {
      "x": -17,
      "y": 4,
      "z": -20,
      "name": "Rock_Marble"
    },
    {
      "x": -17,
      "y": 5,
      "z": -20,
      "name": "Rock_Marble"
    },
    {
      "x": -17,
      "y": -5,
      "z": -19,
      "name": "Rock_Marble"
    },
    {
      "x": -17,
      "y": -4,
      "z": -19,
      "name": "Rock_Marble"
    },
    {
      "x": -17,
      "y": -3,
      "z": -19,
      "name": "Rock_Marble"
    },
    {
      "x": -17,
      "y": -2,
      "z": -19,
      "name": "Rock_Marble"
    },
    {
      "x": -17,
      "y": -1,
      "z": -19,
      "name": "Rock_Marble"
    },
    {
      "x": -17,
      "y": 0,
      "z": -19,
      "name": "Rock_Marble"
    },
    {
      "x": -17,
      "y": 1,
      "z": -19,
      "name": "Rock_Marble"
    },
    {
      "x": -17,
      "y": 2,
      "z": -19,
      "name": "Rock_Marble"
    },
    {
      "x": -17,
      "y": 3,
      "z": -19,
      "name": "Rock_Marble"
    },
    {
      "x": -17,
      "y": 4,
      "z": -19,
      "name": "Rock_Marble"
    },
    {
      "x": -17,
      "y": 5,
      "z": -19,
      "name": "Rock_Marble"
    },
    {
      "x": -17,
      "y": 6,
      "z": -19,
      "name": "Rock_Marble"
    },
    {
      "x": -17,
      "y": 7,
      "z": -19,
      "name": "Rock_Marble"
    },
    {
      "x": -17,
      "y": -6,
      "z": -18,
      "name": "Rock_Marble"
    },
    {
      "x": -17,
      "y": -5,
      "z": -18,
      "name": "Rock_Marble"
    },
    {
      "x": -17,
      "y": -4,
      "z": -18,
      "name": "Rock_Marble"
    },
    {
      "x": -17,
      "y": -3,
      "z": -18,
      "name": "Rock_Marble"
    },
    {
      "x": -17,
      "y": -2,
      "z": -18,
      "name": "Rock_Marble"
    },
    {
      "x": -17,
      "y": -1,
      "z": -18,
      "name": "Rock_Marble"
    },
    {
      "x": -17,
      "y": 0,
      "z": -18,
      "name": "Rock_Marble"
    },
    {
      "x": -17,
      "y": 1,
      "z": -18,
      "name": "Rock_Marble"
    },
    {
      "x": -17,
      "y": 2,
      "z": -18,
      "name": "Rock_Marble"
    },
    {
      "x": -17,
      "y": 3,
      "z": -18,
      "name": "Rock_Marble"
    },
    {
      "x": -17,
      "y": 4,
      "z": -18,
      "name": "Rock_Marble"
    },
    {
      "x": -17,
      "y": 5,
      "z": -18,
      "name": "Rock_Marble"
    },
    {
      "x": -17,
      "y": 6,
      "z": -18,
      "name": "Rock_Marble"
    },
    {
      "x": -17,
      "y": 7,
      "z": -18,
      "name": "Rock_Marble"
    },
    {
      "x": -17,
      "y": 8,
      "z": -18,
      "name": "Rock_Stone"
    },
    {
      "x": -17,
      "y": -7,
      "z": -17,
      "name": "Rock_Marble"
    },
    {
      "x": -17,
      "y": -6,
      "z": -17,
      "name": "Rock_Marble"
    },
    {
      "x": -17,
      "y": -5,
      "z": -17,
      "name": "Rock_Marble"
    },
    {
      "x": -17,
      "y": -4,
      "z": -17,
      "name": "Rock_Marble"
    },
    {
      "x": -17,
      "y": -3,
      "z": -17,
      "name": "Rock_Shale"
    },
    {
      "x": -17,
      "y": -2,
      "z": -17,
      "name": "Rock_Shale"
    },
    {
      "x": -17,
      "y": -1,
      "z": -17,
      "name": "Rock_Shale"
    },
    {
      "x": -17,
      "y": 0,
      "z": -17,
      "name": "Rock_Marble"
    },
    {
      "x": -17,
      "y": 1,
      "z": -17,
      "name": "Rock_Marble"
    },
    {
      "x": -17,
      "y": 2,
      "z": -17,
      "name": "Rock_Marble"
    },
    {
      "x": -17,
      "y": 3,
      "z": -17,
      "name": "Rock_Marble"
    },
    {
      "x": -17,
      "y": 4,
      "z": -17,
      "name": "Rock_Marble"
    },
    {
      "x": -17,
      "y": 5,
      "z": -17,
      "name": "Rock_Marble"
    },
    {
      "x": -17,
      "y": 6,
      "z": -17,
      "name": "Rock_Marble"
    },
    {
      "x": -17,
      "y": 7,
      "z": -17,
      "name": "Rock_Marble"
    },
    {
      "x": -17,
      "y": 8,
      "z": -17,
      "name": "Rock_Stone"
    },
    {
      "x": -17,
      "y": -8,
      "z": -16,
      "name": "Rock_Marble"
    },
    {
      "x": -17,
      "y": -7,
      "z": -16,
      "name": "Rock_Marble"
    },
    {
      "x": -17,
      "y": -6,
      "z": -16,
      "name": "Rock_Marble"
    },
    {
      "x": -17,
      "y": -5,
      "z": -16,
      "name": "Rock_Shale"
    },
    {
      "x": -17,
      "y": -4,
      "z": -16,
      "name": "Rock_Shale"
    },
    {
      "x": -17,
      "y": -3,
      "z": -16,
      "name": "Rock_Shale"
    },
    {
      "x": -17,
      "y": -2,
      "z": -16,
      "name": "Rock_Shale"
    },
    {
      "x": -17,
      "y": -1,
      "z": -16,
      "name": "Rock_Shale"
    },
    {
      "x": -17,
      "y": 0,
      "z": -16,
      "name": "Rock_Shale"
    },
    {
      "x": -17,
      "y": 1,
      "z": -16,
      "name": "Rock_Marble"
    },
    {
      "x": -17,
      "y": 2,
      "z": -16,
      "name": "Rock_Marble"
    },
    {
      "x": -17,
      "y": 3,
      "z": -16,
      "name": "Rock_Marble"
    },
    {
      "x": -17,
      "y": 4,
      "z": -16,
      "name": "Rock_Marble"
    },
    {
      "x": -17,
      "y": 5,
      "z": -16,
      "name": "Rock_Marble"
    },
    {
      "x": -17,
      "y": 6,
      "z": -16,
      "name": "Rock_Marble"
    },
    {
      "x": -17,
      "y": 7,
      "z": -16,
      "name": "Rock_Marble"
    },
    {
      "x": -17,
      "y": 8,
      "z": -16,
      "name": "Rock_Stone"
    },
    {
      "x": -17,
      "y": -9,
      "z": -15,
      "name": "Rock_Marble"
    },
    {
      "x": -17,
      "y": -8,
      "z": -15,
      "name": "Rock_Marble"
    },
    {
      "x": -17,
      "y": -7,
      "z": -15,
      "name": "Rock_Marble"
    },
    {
      "x": -17,
      "y": -6,
      "z": -15,
      "name": "Rock_Shale"
    },
    {
      "x": -17,
      "y": -5,
      "z": -15,
      "name": "Rock_Shale"
    },
    {
      "x": -17,
      "y": -4,
      "z": -15,
      "name": "Rock_Shale"
    },
    {
      "x": -17,
      "y": 0,
      "z": -15,
      "name": "Rock_Shale"
    },
    {
      "x": -17,
      "y": 1,
      "z": -15,
      "name": "Rock_Shale"
    },
    {
      "x": -17,
      "y": 2,
      "z": -15,
      "name": "Rock_Marble"
    },
    {
      "x": -17,
      "y": 3,
      "z": -15,
      "name": "Rock_Marble"
    },
    {
      "x": -17,
      "y": 4,
      "z": -15,
      "name": "Rock_Marble"
    },
    {
      "x": -17,
      "y": 5,
      "z": -15,
      "name": "Rock_Marble"
    },
    {
      "x": -17,
      "y": 6,
      "z": -15,
      "name": "Rock_Marble"
    },
    {
      "x": -17,
      "y": 7,
      "z": -15,
      "name": "Rock_Marble"
    },
    {
      "x": -17,
      "y": 8,
      "z": -15,
      "name": "Rock_Stone"
    },
    {
      "x": -17,
      "y": -10,
      "z": -14,
      "name": "Rock_Stone"
    },
    {
      "x": -17,
      "y": -9,
      "z": -14,
      "name": "Rock_Marble"
    },
    {
      "x": -17,
      "y": -8,
      "z": -14,
      "name": "Rock_Marble"
    },
    {
      "x": -17,
      "y": -7,
      "z": -14,
      "name": "Rock_Shale"
    },
    {
      "x": -17,
      "y": -6,
      "z": -14,
      "name": "Rock_Shale"
    },
    {
      "x": -17,
      "y": 1,
      "z": -14,
      "name": "Rock_Shale"
    },
    {
      "x": -17,
      "y": 2,
      "z": -14,
      "name": "Rock_Shale"
    },
    {
      "x": -17,
      "y": 3,
      "z": -14,
      "name": "Rock_Marble"
    },
    {
      "x": -17,
      "y": 4,
      "z": -14,
      "name": "Rock_Marble"
    },
    {
      "x": -17,
      "y": 5,
      "z": -14,
      "name": "Rock_Marble"
    },
    {
      "x": -17,
      "y": 6,
      "z": -14,
      "name": "Rock_Marble"
    },
    {
      "x": -17,
      "y": 7,
      "z": -14,
      "name": "Rock_Shale"
    },
    {
      "x": -17,
      "y": 8,
      "z": -14,
      "name": "Rock_Shale"
    },
    {
      "x": -17,
      "y": -10,
      "z": -13,
      "name": "Rock_Shale"
    },
    {
      "x": -17,
      "y": -9,
      "z": -13,
      "name": "Rock_Marble"
    },
    {
      "x": -17,
      "y": -8,
      "z": -13,
      "name": "Rock_Marble"
    },
    {
      "x": -17,
      "y": -7,
      "z": -13,
      "name": "Rock_Shale"
    },
    {
      "x": -17,
      "y": 2,
      "z": -13,
      "name": "Rock_Shale"
    },
    {
      "x": -17,
      "y": 3,
      "z": -13,
      "name": "Rock_Marble"
    },
    {
      "x": -17,
      "y": 4,
      "z": -13,
      "name": "Rock_Marble"
    },
    {
      "x": -17,
      "y": 5,
      "z": -13,
      "name": "Rock_Marble"
    },
    {
      "x": -17,
      "y": 6,
      "z": -13,
      "name": "Rock_Marble"
    },
    {
      "x": -17,
      "y": 7,
      "z": -13,
      "name": "Rock_Shale"
    },
    {
      "x": -17,
      "y": 8,
      "z": -13,
      "name": "Rock_Shale"
    },
    {
      "x": -17,
      "y": -10,
      "z": -12,
      "name": "Rock_Shale"
    },
    {
      "x": -17,
      "y": -9,
      "z": -12,
      "name": "Rock_Marble"
    },
    {
      "x": -17,
      "y": 4,
      "z": -12,
      "name": "Rock_Chalk"
    },
    {
      "x": -17,
      "y": 5,
      "z": -12,
      "name": "Rock_Chalk"
    },
    {
      "x": -16,
      "y": -3,
      "z": -21,
      "name": "Rock_Calcite"
    },
    {
      "x": -16,
      "y": -2,
      "z": -21,
      "name": "Rock_Calcite"
    },
    {
      "x": -16,
      "y": -1,
      "z": -21,
      "name": "Rock_Calcite"
    },
    {
      "x": -16,
      "y": 0,
      "z": -21,
      "name": "Rock_Calcite"
    },
    {
      "x": -16,
      "y": 1,
      "z": -21,
      "name": "Rock_Calcite"
    },
    {
      "x": -16,
      "y": 2,
      "z": -21,
      "name": "Rock_Calcite"
    },
    {
      "x": -16,
      "y": 3,
      "z": -21,
      "name": "Rock_Calcite"
    },
    {
      "x": -16,
      "y": 4,
      "z": -21,
      "name": "Rock_Calcite"
    },
    {
      "x": -16,
      "y": 5,
      "z": -21,
      "name": "Rock_Calcite"
    },
    {
      "x": -16,
      "y": 6,
      "z": -21,
      "name": "Rock_Calcite"
    },
    {
      "x": -16,
      "y": -5,
      "z": -20,
      "name": "Rock_Calcite"
    },
    {
      "x": -16,
      "y": -4,
      "z": -20,
      "name": "Rock_Calcite"
    },
    {
      "x": -16,
      "y": -3,
      "z": -20,
      "name": "Rock_Calcite"
    },
    {
      "x": -16,
      "y": -2,
      "z": -20,
      "name": "Rock_Calcite"
    },
    {
      "x": -16,
      "y": -1,
      "z": -20,
      "name": "Rock_Calcite"
    },
    {
      "x": -16,
      "y": 0,
      "z": -20,
      "name": "Rock_Marble"
    },
    {
      "x": -16,
      "y": 1,
      "z": -20,
      "name": "Rock_Marble"
    },
    {
      "x": -16,
      "y": 2,
      "z": -20,
      "name": "Rock_Marble"
    },
    {
      "x": -16,
      "y": 3,
      "z": -20,
      "name": "Rock_Marble"
    },
    {
      "x": -16,
      "y": 4,
      "z": -20,
      "name": "Rock_Marble"
    },
    {
      "x": -16,
      "y": 5,
      "z": -20,
      "name": "Rock_Marble"
    },
    {
      "x": -16,
      "y": 6,
      "z": -20,
      "name": "Rock_Marble"
    },
    {
      "x": -16,
      "y": 7,
      "z": -20,
      "name": "Rock_Marble"
    },
    {
      "x": -16,
      "y": 8,
      "z": -20,
      "name": "Rock_Marble"
    },
    {
      "x": -16,
      "y": 9,
      "z": -20,
      "name": "Rock_Stone"
    },
    {
      "x": -16,
      "y": -6,
      "z": -19,
      "name": "Rock_Marble"
    },
    {
      "x": -16,
      "y": -5,
      "z": -19,
      "name": "Rock_Marble"
    },
    {
      "x": -16,
      "y": -4,
      "z": -19,
      "name": "Rock_Marble"
    },
    {
      "x": -16,
      "y": -3,
      "z": -19,
      "name": "Rock_Marble"
    },
    {
      "x": -16,
      "y": -2,
      "z": -19,
      "name": "Rock_Marble"
    },
    {
      "x": -16,
      "y": -1,
      "z": -19,
      "name": "Rock_Marble"
    },
    {
      "x": -16,
      "y": 0,
      "z": -19,
      "name": "Rock_Marble"
    },
    {
      "x": -16,
      "y": 1,
      "z": -19,
      "name": "Rock_Marble"
    },
    {
      "x": -16,
      "y": 2,
      "z": -19,
      "name": "Rock_Marble"
    },
    {
      "x": -16,
      "y": 3,
      "z": -19,
      "name": "Rock_Marble"
    },
    {
      "x": -16,
      "y": 4,
      "z": -19,
      "name": "Rock_Marble"
    },
    {
      "x": -16,
      "y": 5,
      "z": -19,
      "name": "Rock_Marble"
    },
    {
      "x": -16,
      "y": 6,
      "z": -19,
      "name": "Rock_Marble"
    },
    {
      "x": -16,
      "y": 7,
      "z": -19,
      "name": "Rock_Marble"
    },
    {
      "x": -16,
      "y": 8,
      "z": -19,
      "name": "Rock_Marble"
    },
    {
      "x": -16,
      "y": 9,
      "z": -19,
      "name": "Rock_Stone"
    },
    {
      "x": -16,
      "y": -7,
      "z": -18,
      "name": "Rock_Marble"
    },
    {
      "x": -16,
      "y": -6,
      "z": -18,
      "name": "Rock_Marble"
    },
    {
      "x": -16,
      "y": -5,
      "z": -18,
      "name": "Rock_Marble"
    },
    {
      "x": -16,
      "y": -4,
      "z": -18,
      "name": "Rock_Marble"
    },
    {
      "x": -16,
      "y": -3,
      "z": -18,
      "name": "Rock_Marble"
    },
    {
      "x": -16,
      "y": -2,
      "z": -18,
      "name": "Rock_Marble"
    },
    {
      "x": -16,
      "y": -1,
      "z": -18,
      "name": "Rock_Marble"
    },
    {
      "x": -16,
      "y": 0,
      "z": -18,
      "name": "Rock_Marble"
    },
    {
      "x": -16,
      "y": 1,
      "z": -18,
      "name": "Rock_Marble"
    },
    {
      "x": -16,
      "y": 2,
      "z": -18,
      "name": "Rock_Marble"
    },
    {
      "x": -16,
      "y": 3,
      "z": -18,
      "name": "Rock_Marble"
    },
    {
      "x": -16,
      "y": 4,
      "z": -18,
      "name": "Rock_Marble"
    },
    {
      "x": -16,
      "y": 5,
      "z": -18,
      "name": "Rock_Marble"
    },
    {
      "x": -16,
      "y": 6,
      "z": -18,
      "name": "Rock_Marble"
    },
    {
      "x": -16,
      "y": 7,
      "z": -18,
      "name": "Rock_Marble"
    },
    {
      "x": -16,
      "y": 8,
      "z": -18,
      "name": "Rock_Marble"
    },
    {
      "x": -16,
      "y": 9,
      "z": -18,
      "name": "Rock_Stone"
    },
    {
      "x": -16,
      "y": -8,
      "z": -17,
      "name": "Rock_Marble"
    },
    {
      "x": -16,
      "y": -7,
      "z": -17,
      "name": "Rock_Marble"
    },
    {
      "x": -16,
      "y": -6,
      "z": -17,
      "name": "Rock_Marble"
    },
    {
      "x": -16,
      "y": -5,
      "z": -17,
      "name": "Rock_Marble"
    },
    {
      "x": -16,
      "y": -4,
      "z": -17,
      "name": "Rock_Shale"
    },
    {
      "x": -16,
      "y": -3,
      "z": -17,
      "name": "Rock_Shale"
    },
    {
      "x": -16,
      "y": -2,
      "z": -17,
      "name": "Rock_Shale"
    },
    {
      "x": -16,
      "y": -1,
      "z": -17,
      "name": "Rock_Shale"
    },
    {
      "x": -16,
      "y": 0,
      "z": -17,
      "name": "Rock_Shale"
    },
    {
      "x": -16,
      "y": 1,
      "z": -17,
      "name": "Rock_Marble"
    },
    {
      "x": -16,
      "y": 2,
      "z": -17,
      "name": "Rock_Marble"
    },
    {
      "x": -16,
      "y": 3,
      "z": -17,
      "name": "Rock_Marble"
    },
    {
      "x": -16,
      "y": 4,
      "z": -17,
      "name": "Rock_Marble"
    },
    {
      "x": -16,
      "y": 5,
      "z": -17,
      "name": "Rock_Marble"
    },
    {
      "x": -16,
      "y": 6,
      "z": -17,
      "name": "Rock_Marble"
    },
    {
      "x": -16,
      "y": 7,
      "z": -17,
      "name": "Rock_Marble"
    },
    {
      "x": -16,
      "y": 8,
      "z": -17,
      "name": "Rock_Marble"
    },
    {
      "x": -16,
      "y": 9,
      "z": -17,
      "name": "Rock_Stone"
    },
    {
      "x": -16,
      "y": -9,
      "z": -16,
      "name": "Rock_Marble"
    },
    {
      "x": -16,
      "y": -8,
      "z": -16,
      "name": "Rock_Marble"
    },
    {
      "x": -16,
      "y": -7,
      "z": -16,
      "name": "Rock_Marble"
    },
    {
      "x": -16,
      "y": -6,
      "z": -16,
      "name": "Rock_Shale"
    },
    {
      "x": -16,
      "y": -5,
      "z": -16,
      "name": "Rock_Shale"
    },
    {
      "x": -16,
      "y": -4,
      "z": -16,
      "name": "Rock_Shale"
    },
    {
      "x": -16,
      "y": -3,
      "z": -16,
      "name": "Rock_Shale"
    },
    {
      "x": -16,
      "y": -2,
      "z": -16,
      "name": "Rock_Shale"
    },
    {
      "x": -16,
      "y": -1,
      "z": -16,
      "name": "Rock_Shale"
    },
    {
      "x": -16,
      "y": 0,
      "z": -16,
      "name": "Rock_Shale"
    },
    {
      "x": -16,
      "y": 1,
      "z": -16,
      "name": "Rock_Shale"
    },
    {
      "x": -16,
      "y": 2,
      "z": -16,
      "name": "Rock_Marble"
    },
    {
      "x": -16,
      "y": 3,
      "z": -16,
      "name": "Rock_Marble"
    },
    {
      "x": -16,
      "y": 4,
      "z": -16,
      "name": "Rock_Marble"
    },
    {
      "x": -16,
      "y": 5,
      "z": -16,
      "name": "Rock_Marble"
    },
    {
      "x": -16,
      "y": 6,
      "z": -16,
      "name": "Rock_Marble"
    },
    {
      "x": -16,
      "y": 7,
      "z": -16,
      "name": "Rock_Marble"
    },
    {
      "x": -16,
      "y": 8,
      "z": -16,
      "name": "Rock_Marble"
    },
    {
      "x": -16,
      "y": 9,
      "z": -16,
      "name": "Rock_Stone"
    },
    {
      "x": -16,
      "y": -10,
      "z": -15,
      "name": "Rock_Stone"
    },
    {
      "x": -16,
      "y": -9,
      "z": -15,
      "name": "Rock_Marble"
    },
    {
      "x": -16,
      "y": -8,
      "z": -15,
      "name": "Rock_Shale"
    },
    {
      "x": -16,
      "y": -7,
      "z": -15,
      "name": "Rock_Shale"
    },
    {
      "x": -16,
      "y": -6,
      "z": -15,
      "name": "Rock_Shale"
    },
    {
      "x": -16,
      "y": -5,
      "z": -15,
      "name": "Rock_Shale"
    },
    {
      "x": -16,
      "y": 1,
      "z": -15,
      "name": "Rock_Shale"
    },
    {
      "x": -16,
      "y": 2,
      "z": -15,
      "name": "Rock_Shale"
    },
    {
      "x": -16,
      "y": 3,
      "z": -15,
      "name": "Rock_Shale"
    },
    {
      "x": -16,
      "y": 4,
      "z": -15,
      "name": "Rock_Marble"
    },
    {
      "x": -16,
      "y": 5,
      "z": -15,
      "name": "Rock_Shale"
    },
    {
      "x": -16,
      "y": 6,
      "z": -15,
      "name": "Rock_Shale"
    },
    {
      "x": -16,
      "y": 7,
      "z": -15,
      "name": "Rock_Shale"
    },
    {
      "x": -16,
      "y": 8,
      "z": -15,
      "name": "Rock_Shale"
    },
    {
      "x": -16,
      "y": 9,
      "z": -15,
      "name": "Rock_Shale"
    },
    {
      "x": -16,
      "y": -10,
      "z": -14,
      "name": "Rock_Stone"
    },
    {
      "x": -16,
      "y": -9,
      "z": -14,
      "name": "Rock_Shale"
    },
    {
      "x": -16,
      "y": -8,
      "z": -14,
      "name": "Rock_Shale"
    },
    {
      "x": -16,
      "y": -7,
      "z": -14,
      "name": "Rock_Shale"
    },
    {
      "x": -16,
      "y": 2,
      "z": -14,
      "name": "Rock_Shale"
    },
    {
      "x": -16,
      "y": 3,
      "z": -14,
      "name": "Rock_Shale"
    },
    {
      "x": -16,
      "y": 4,
      "z": -14,
      "name": "Rock_Shale"
    },
    {
      "x": -16,
      "y": 5,
      "z": -14,
      "name": "Rock_Shale"
    },
    {
      "x": -16,
      "y": 6,
      "z": -14,
      "name": "Rock_Shale"
    },
    {
      "x": -16,
      "y": 7,
      "z": -14,
      "name": "Rock_Shale"
    },
    {
      "x": -16,
      "y": 8,
      "z": -14,
      "name": "Rock_Shale"
    },
    {
      "x": -16,
      "y": 9,
      "z": -14,
      "name": "Rock_Shale"
    },
    {
      "x": -16,
      "y": -10,
      "z": -13,
      "name": "Rock_Shale"
    },
    {
      "x": -16,
      "y": -9,
      "z": -13,
      "name": "Rock_Shale"
    },
    {
      "x": -16,
      "y": 4,
      "z": -13,
      "name": "Rock_Shale"
    },
    {
      "x": -16,
      "y": -10,
      "z": -12,
      "name": "Rock_Shale"
    },
    {
      "x": -15,
      "y": -2,
      "z": -22,
      "name": "Rock_Marble"
    },
    {
      "x": -15,
      "y": -1,
      "z": -22,
      "name": "Rock_Calcite"
    },
    {
      "x": -15,
      "y": 0,
      "z": -22,
      "name": "Rock_Calcite"
    },
    {
      "x": -15,
      "y": 1,
      "z": -22,
      "name": "Rock_Calcite"
    },
    {
      "x": -15,
      "y": 2,
      "z": -22,
      "name": "Rock_Calcite"
    },
    {
      "x": -15,
      "y": 3,
      "z": -22,
      "name": "Rock_Marble"
    },
    {
      "x": -15,
      "y": 4,
      "z": -22,
      "name": "Rock_Marble"
    },
    {
      "x": -15,
      "y": 5,
      "z": -22,
      "name": "Rock_Marble"
    },
    {
      "x": -15,
      "y": 6,
      "z": -22,
      "name": "Rock_Marble"
    },
    {
      "x": -15,
      "y": 7,
      "z": -22,
      "name": "Rock_Marble"
    },
    {
      "x": -15,
      "y": 8,
      "z": -22,
      "name": "Rock_Marble"
    },
    {
      "x": -15,
      "y": -4,
      "z": -21,
      "name": "Rock_Calcite"
    },
    {
      "x": -15,
      "y": -3,
      "z": -21,
      "name": "Rock_Calcite"
    },
    {
      "x": -15,
      "y": -2,
      "z": -21,
      "name": "Rock_Calcite"
    },
    {
      "x": -15,
      "y": -1,
      "z": -21,
      "name": "Rock_Calcite"
    },
    {
      "x": -15,
      "y": 0,
      "z": -21,
      "name": "Rock_Calcite"
    },
    {
      "x": -15,
      "y": 1,
      "z": -21,
      "name": "Rock_Calcite"
    },
    {
      "x": -15,
      "y": 2,
      "z": -21,
      "name": "Rock_Calcite"
    },
    {
      "x": -15,
      "y": 3,
      "z": -21,
      "name": "Rock_Calcite"
    },
    {
      "x": -15,
      "y": 4,
      "z": -21,
      "name": "Rock_Calcite"
    },
    {
      "x": -15,
      "y": 5,
      "z": -21,
      "name": "Rock_Calcite"
    },
    {
      "x": -15,
      "y": 6,
      "z": -21,
      "name": "Rock_Calcite"
    },
    {
      "x": -15,
      "y": 7,
      "z": -21,
      "name": "Rock_Calcite"
    },
    {
      "x": -15,
      "y": 8,
      "z": -21,
      "name": "Rock_Calcite"
    },
    {
      "x": -15,
      "y": 9,
      "z": -21,
      "name": "Rock_Calcite"
    },
    {
      "x": -15,
      "y": 10,
      "z": -21,
      "name": "Rock_Stone"
    },
    {
      "x": -15,
      "y": -6,
      "z": -20,
      "name": "Rock_Calcite"
    },
    {
      "x": -15,
      "y": -5,
      "z": -20,
      "name": "Rock_Calcite"
    },
    {
      "x": -15,
      "y": -4,
      "z": -20,
      "name": "Rock_Calcite"
    },
    {
      "x": -15,
      "y": -3,
      "z": -20,
      "name": "Rock_Calcite"
    },
    {
      "x": -15,
      "y": -2,
      "z": -20,
      "name": "Rock_Calcite"
    },
    {
      "x": -15,
      "y": -1,
      "z": -20,
      "name": "Rock_Marble"
    },
    {
      "x": -15,
      "y": 0,
      "z": -20,
      "name": "Rock_Marble"
    },
    {
      "x": -15,
      "y": 1,
      "z": -20,
      "name": "Rock_Marble"
    },
    {
      "x": -15,
      "y": 2,
      "z": -20,
      "name": "Rock_Marble"
    },
    {
      "x": -15,
      "y": 3,
      "z": -20,
      "name": "Rock_Marble"
    },
    {
      "x": -15,
      "y": 4,
      "z": -20,
      "name": "Rock_Marble"
    },
    {
      "x": -15,
      "y": 5,
      "z": -20,
      "name": "Rock_Marble"
    },
    {
      "x": -15,
      "y": 6,
      "z": -20,
      "name": "Rock_Marble"
    },
    {
      "x": -15,
      "y": 7,
      "z": -20,
      "name": "Rock_Marble"
    },
    {
      "x": -15,
      "y": 8,
      "z": -20,
      "name": "Rock_Marble"
    },
    {
      "x": -15,
      "y": 9,
      "z": -20,
      "name": "Rock_Marble"
    },
    {
      "x": -15,
      "y": 10,
      "z": -20,
      "name": "Rock_Stone"
    },
    {
      "x": -15,
      "y": -7,
      "z": -19,
      "name": "Rock_Marble"
    },
    {
      "x": -15,
      "y": -6,
      "z": -19,
      "name": "Rock_Marble"
    },
    {
      "x": -15,
      "y": -5,
      "z": -19,
      "name": "Rock_Marble"
    },
    {
      "x": -15,
      "y": -4,
      "z": -19,
      "name": "Rock_Marble"
    },
    {
      "x": -15,
      "y": -3,
      "z": -19,
      "name": "Rock_Marble"
    },
    {
      "x": -15,
      "y": -2,
      "z": -19,
      "name": "Rock_Marble"
    },
    {
      "x": -15,
      "y": -1,
      "z": -19,
      "name": "Rock_Marble"
    },
    {
      "x": -15,
      "y": 0,
      "z": -19,
      "name": "Rock_Marble"
    },
    {
      "x": -15,
      "y": 1,
      "z": -19,
      "name": "Rock_Marble"
    },
    {
      "x": -15,
      "y": 2,
      "z": -19,
      "name": "Rock_Marble"
    },
    {
      "x": -15,
      "y": 3,
      "z": -19,
      "name": "Rock_Marble"
    },
    {
      "x": -15,
      "y": 4,
      "z": -19,
      "name": "Rock_Marble"
    },
    {
      "x": -15,
      "y": 5,
      "z": -19,
      "name": "Rock_Marble"
    },
    {
      "x": -15,
      "y": 6,
      "z": -19,
      "name": "Rock_Marble"
    },
    {
      "x": -15,
      "y": 7,
      "z": -19,
      "name": "Rock_Marble"
    },
    {
      "x": -15,
      "y": 8,
      "z": -19,
      "name": "Rock_Marble"
    },
    {
      "x": -15,
      "y": 9,
      "z": -19,
      "name": "Rock_Marble"
    },
    {
      "x": -15,
      "y": 10,
      "z": -19,
      "name": "Rock_Stone"
    },
    {
      "x": -15,
      "y": -8,
      "z": -18,
      "name": "Rock_Marble"
    },
    {
      "x": -15,
      "y": -7,
      "z": -18,
      "name": "Rock_Marble"
    },
    {
      "x": -15,
      "y": -6,
      "z": -18,
      "name": "Rock_Marble"
    },
    {
      "x": -15,
      "y": -5,
      "z": -18,
      "name": "Rock_Marble"
    },
    {
      "x": -15,
      "y": -4,
      "z": -18,
      "name": "Rock_Marble"
    },
    {
      "x": -15,
      "y": -3,
      "z": -18,
      "name": "Rock_Marble"
    },
    {
      "x": -15,
      "y": -2,
      "z": -18,
      "name": "Rock_Shale"
    },
    {
      "x": -15,
      "y": -1,
      "z": -18,
      "name": "Rock_Shale"
    },
    {
      "x": -15,
      "y": 0,
      "z": -18,
      "name": "Rock_Marble"
    },
    {
      "x": -15,
      "y": 1,
      "z": -18,
      "name": "Rock_Marble"
    },
    {
      "x": -15,
      "y": 2,
      "z": -18,
      "name": "Rock_Marble"
    },
    {
      "x": -15,
      "y": 3,
      "z": -18,
      "name": "Rock_Marble"
    },
    {
      "x": -15,
      "y": 4,
      "z": -18,
      "name": "Rock_Marble"
    },
    {
      "x": -15,
      "y": 5,
      "z": -18,
      "name": "Rock_Marble"
    },
    {
      "x": -15,
      "y": 6,
      "z": -18,
      "name": "Rock_Marble"
    },
    {
      "x": -15,
      "y": 7,
      "z": -18,
      "name": "Rock_Marble"
    },
    {
      "x": -15,
      "y": 8,
      "z": -18,
      "name": "Rock_Marble"
    },
    {
      "x": -15,
      "y": 9,
      "z": -18,
      "name": "Rock_Marble"
    },
    {
      "x": -15,
      "y": 10,
      "z": -18,
      "name": "Rock_Stone"
    },
    {
      "x": -15,
      "y": -9,
      "z": -17,
      "name": "Rock_Marble"
    },
    {
      "x": -15,
      "y": -8,
      "z": -17,
      "name": "Rock_Marble"
    },
    {
      "x": -15,
      "y": -7,
      "z": -17,
      "name": "Rock_Marble"
    },
    {
      "x": -15,
      "y": -6,
      "z": -17,
      "name": "Rock_Marble"
    },
    {
      "x": -15,
      "y": -5,
      "z": -17,
      "name": "Rock_Marble"
    },
    {
      "x": -15,
      "y": -4,
      "z": -17,
      "name": "Rock_Shale"
    },
    {
      "x": -15,
      "y": -3,
      "z": -17,
      "name": "Rock_Shale"
    },
    {
      "x": -15,
      "y": -2,
      "z": -17,
      "name": "Rock_Shale"
    },
    {
      "x": -15,
      "y": -1,
      "z": -17,
      "name": "Rock_Shale"
    },
    {
      "x": -15,
      "y": 0,
      "z": -17,
      "name": "Rock_Shale"
    },
    {
      "x": -15,
      "y": 1,
      "z": -17,
      "name": "Rock_Shale"
    },
    {
      "x": -15,
      "y": 2,
      "z": -17,
      "name": "Rock_Marble"
    },
    {
      "x": -15,
      "y": 3,
      "z": -17,
      "name": "Rock_Marble"
    },
    {
      "x": -15,
      "y": 4,
      "z": -17,
      "name": "Rock_Marble"
    },
    {
      "x": -15,
      "y": 5,
      "z": -17,
      "name": "Rock_Marble"
    },
    {
      "x": -15,
      "y": 6,
      "z": -17,
      "name": "Rock_Marble"
    },
    {
      "x": -15,
      "y": 7,
      "z": -17,
      "name": "Rock_Marble"
    },
    {
      "x": -15,
      "y": 8,
      "z": -17,
      "name": "Rock_Marble"
    },
    {
      "x": -15,
      "y": 9,
      "z": -17,
      "name": "Rock_Marble"
    },
    {
      "x": -15,
      "y": 10,
      "z": -17,
      "name": "Rock_Stone"
    },
    {
      "x": -15,
      "y": 14,
      "z": -17,
      "name": "Rock_Stone"
    },
    {
      "x": -15,
      "y": -10,
      "z": -16,
      "name": "Rock_Stone"
    },
    {
      "x": -15,
      "y": -9,
      "z": -16,
      "name": "Rock_Marble"
    },
    {
      "x": -15,
      "y": -8,
      "z": -16,
      "name": "Rock_Marble"
    },
    {
      "x": -15,
      "y": -7,
      "z": -16,
      "name": "Rock_Shale"
    },
    {
      "x": -15,
      "y": -6,
      "z": -16,
      "name": "Rock_Shale"
    },
    {
      "x": -15,
      "y": -5,
      "z": -16,
      "name": "Rock_Shale"
    },
    {
      "x": -15,
      "y": -4,
      "z": -16,
      "name": "Rock_Shale"
    },
    {
      "x": -15,
      "y": -3,
      "z": -16,
      "name": "Rock_Shale"
    },
    {
      "x": -15,
      "y": 0,
      "z": -16,
      "name": "Rock_Shale"
    },
    {
      "x": -15,
      "y": 1,
      "z": -16,
      "name": "Rock_Shale"
    },
    {
      "x": -15,
      "y": 2,
      "z": -16,
      "name": "Rock_Shale"
    },
    {
      "x": -15,
      "y": 3,
      "z": -16,
      "name": "Rock_Marble"
    },
    {
      "x": -15,
      "y": 4,
      "z": -16,
      "name": "Rock_Marble"
    },
    {
      "x": -15,
      "y": 5,
      "z": -16,
      "name": "Rock_Shale"
    },
    {
      "x": -15,
      "y": 6,
      "z": -16,
      "name": "Rock_Shale"
    },
    {
      "x": -15,
      "y": 7,
      "z": -16,
      "name": "Rock_Shale"
    },
    {
      "x": -15,
      "y": 8,
      "z": -16,
      "name": "Rock_Shale"
    },
    {
      "x": -15,
      "y": 9,
      "z": -16,
      "name": "Rock_Shale"
    },
    {
      "x": -15,
      "y": -10,
      "z": -15,
      "name": "Rock_Stone"
    },
    {
      "x": -15,
      "y": -9,
      "z": -15,
      "name": "Rock_Shale"
    },
    {
      "x": -15,
      "y": -8,
      "z": -15,
      "name": "Rock_Shale"
    },
    {
      "x": -15,
      "y": -7,
      "z": -15,
      "name": "Rock_Shale"
    },
    {
      "x": -15,
      "y": -6,
      "z": -15,
      "name": "Rock_Shale"
    },
    {
      "x": -15,
      "y": -5,
      "z": -15,
      "name": "Rock_Shale"
    },
    {
      "x": -15,
      "y": 2,
      "z": -15,
      "name": "Rock_Shale"
    },
    {
      "x": -15,
      "y": 3,
      "z": -15,
      "name": "Rock_Shale"
    },
    {
      "x": -15,
      "y": 4,
      "z": -15,
      "name": "Rock_Shale"
    },
    {
      "x": -15,
      "y": 5,
      "z": -15,
      "name": "Rock_Shale"
    },
    {
      "x": -15,
      "y": 6,
      "z": -15,
      "name": "Rock_Shale"
    },
    {
      "x": -15,
      "y": 7,
      "z": -15,
      "name": "Rock_Shale"
    },
    {
      "x": -15,
      "y": 8,
      "z": -15,
      "name": "Rock_Shale"
    },
    {
      "x": -15,
      "y": 9,
      "z": -15,
      "name": "Rock_Shale"
    },
    {
      "x": -15,
      "y": -10,
      "z": -14,
      "name": "Rock_Shale"
    },
    {
      "x": -15,
      "y": -9,
      "z": -14,
      "name": "Rock_Shale"
    },
    {
      "x": -15,
      "y": -8,
      "z": -14,
      "name": "Rock_Shale"
    },
    {
      "x": -15,
      "y": 3,
      "z": -14,
      "name": "Rock_Shale"
    },
    {
      "x": -15,
      "y": 4,
      "z": -14,
      "name": "Rock_Shale"
    },
    {
      "x": -15,
      "y": -10,
      "z": -13,
      "name": "Rock_Shale"
    },
    {
      "x": -14,
      "y": 1,
      "z": -23,
      "name": "Rock_Marble"
    },
    {
      "x": -14,
      "y": 2,
      "z": -23,
      "name": "Rock_Marble"
    },
    {
      "x": -14,
      "y": 3,
      "z": -23,
      "name": "Rock_Marble"
    },
    {
      "x": -14,
      "y": 4,
      "z": -23,
      "name": "Rock_Marble"
    },
    {
      "x": -14,
      "y": 5,
      "z": -23,
      "name": "Rock_Marble"
    },
    {
      "x": -14,
      "y": 6,
      "z": -23,
      "name": "Rock_Marble"
    },
    {
      "x": -14,
      "y": 7,
      "z": -23,
      "name": "Rock_Marble"
    },
    {
      "x": -14,
      "y": 8,
      "z": -23,
      "name": "Rock_Marble"
    },
    {
      "x": -14,
      "y": 9,
      "z": -23,
      "name": "Rock_Marble"
    },
    {
      "x": -14,
      "y": -3,
      "z": -22,
      "name": "Rock_Marble"
    },
    {
      "x": -14,
      "y": -2,
      "z": -22,
      "name": "Rock_Marble"
    },
    {
      "x": -14,
      "y": -1,
      "z": -22,
      "name": "Rock_Calcite"
    },
    {
      "x": -14,
      "y": 0,
      "z": -22,
      "name": "Rock_Calcite"
    },
    {
      "x": -14,
      "y": 1,
      "z": -22,
      "name": "Rock_Marble"
    },
    {
      "x": -14,
      "y": 2,
      "z": -22,
      "name": "Rock_Marble"
    },
    {
      "x": -14,
      "y": 3,
      "z": -22,
      "name": "Rock_Marble"
    },
    {
      "x": -14,
      "y": 4,
      "z": -22,
      "name": "Rock_Marble"
    },
    {
      "x": -14,
      "y": 5,
      "z": -22,
      "name": "Rock_Marble"
    },
    {
      "x": -14,
      "y": 6,
      "z": -22,
      "name": "Rock_Marble"
    },
    {
      "x": -14,
      "y": 7,
      "z": -22,
      "name": "Rock_Marble"
    },
    {
      "x": -14,
      "y": 8,
      "z": -22,
      "name": "Rock_Marble"
    },
    {
      "x": -14,
      "y": 9,
      "z": -22,
      "name": "Rock_Marble"
    },
    {
      "x": -14,
      "y": 10,
      "z": -22,
      "name": "Rock_Stone"
    },
    {
      "x": -14,
      "y": -5,
      "z": -21,
      "name": "Rock_Marble"
    },
    {
      "x": -14,
      "y": -4,
      "z": -21,
      "name": "Rock_Marble"
    },
    {
      "x": -14,
      "y": -3,
      "z": -21,
      "name": "Rock_Marble"
    },
    {
      "x": -14,
      "y": -2,
      "z": -21,
      "name": "Rock_Calcite"
    },
    {
      "x": -14,
      "y": -1,
      "z": -21,
      "name": "Rock_Calcite"
    },
    {
      "x": -14,
      "y": 0,
      "z": -21,
      "name": "Rock_Calcite"
    },
    {
      "x": -14,
      "y": 1,
      "z": -21,
      "name": "Rock_Calcite"
    },
    {
      "x": -14,
      "y": 2,
      "z": -21,
      "name": "Rock_Calcite"
    },
    {
      "x": -14,
      "y": 3,
      "z": -21,
      "name": "Rock_Calcite"
    },
    {
      "x": -14,
      "y": 4,
      "z": -21,
      "name": "Rock_Calcite"
    },
    {
      "x": -14,
      "y": 5,
      "z": -21,
      "name": "Rock_Calcite"
    },
    {
      "x": -14,
      "y": 6,
      "z": -21,
      "name": "Rock_Calcite"
    },
    {
      "x": -14,
      "y": 7,
      "z": -21,
      "name": "Rock_Calcite"
    },
    {
      "x": -14,
      "y": 8,
      "z": -21,
      "name": "Rock_Calcite"
    },
    {
      "x": -14,
      "y": 9,
      "z": -21,
      "name": "Rock_Marble"
    },
    {
      "x": -14,
      "y": 10,
      "z": -21,
      "name": "Rock_Stone"
    },
    {
      "x": -14,
      "y": -7,
      "z": -20,
      "name": "Rock_Calcite"
    },
    {
      "x": -14,
      "y": -6,
      "z": -20,
      "name": "Rock_Calcite"
    },
    {
      "x": -14,
      "y": -5,
      "z": -20,
      "name": "Rock_Calcite"
    },
    {
      "x": -14,
      "y": -4,
      "z": -20,
      "name": "Rock_Calcite"
    },
    {
      "x": -14,
      "y": -3,
      "z": -20,
      "name": "Rock_Calcite"
    },
    {
      "x": -14,
      "y": -2,
      "z": -20,
      "name": "Rock_Marble"
    },
    {
      "x": -14,
      "y": -1,
      "z": -20,
      "name": "Rock_Marble"
    },
    {
      "x": -14,
      "y": 0,
      "z": -20,
      "name": "Rock_Marble"
    },
    {
      "x": -14,
      "y": 1,
      "z": -20,
      "name": "Rock_Marble"
    },
    {
      "x": -14,
      "y": 2,
      "z": -20,
      "name": "Rock_Marble"
    },
    {
      "x": -14,
      "y": 3,
      "z": -20,
      "name": "Rock_Marble"
    },
    {
      "x": -14,
      "y": 4,
      "z": -20,
      "name": "Rock_Marble"
    },
    {
      "x": -14,
      "y": 5,
      "z": -20,
      "name": "Rock_Marble"
    },
    {
      "x": -14,
      "y": 6,
      "z": -20,
      "name": "Rock_Marble"
    },
    {
      "x": -14,
      "y": 7,
      "z": -20,
      "name": "Rock_Marble"
    },
    {
      "x": -14,
      "y": 8,
      "z": -20,
      "name": "Rock_Marble"
    },
    {
      "x": -14,
      "y": 9,
      "z": -20,
      "name": "Rock_Marble"
    },
    {
      "x": -14,
      "y": 10,
      "z": -20,
      "name": "Rock_Stone"
    },
    {
      "x": -14,
      "y": 13,
      "z": -20,
      "name": "Rock_Stone"
    },
    {
      "x": -14,
      "y": -8,
      "z": -19,
      "name": "Rock_Marble"
    },
    {
      "x": -14,
      "y": -7,
      "z": -19,
      "name": "Rock_Marble"
    },
    {
      "x": -14,
      "y": -6,
      "z": -19,
      "name": "Rock_Marble"
    },
    {
      "x": -14,
      "y": -5,
      "z": -19,
      "name": "Rock_Marble"
    },
    {
      "x": -14,
      "y": -4,
      "z": -19,
      "name": "Rock_Marble"
    },
    {
      "x": -14,
      "y": -3,
      "z": -19,
      "name": "Rock_Marble"
    },
    {
      "x": -14,
      "y": -2,
      "z": -19,
      "name": "Rock_Marble"
    },
    {
      "x": -14,
      "y": -1,
      "z": -19,
      "name": "Rock_Marble"
    },
    {
      "x": -14,
      "y": 0,
      "z": -19,
      "name": "Rock_Marble"
    },
    {
      "x": -14,
      "y": 1,
      "z": -19,
      "name": "Rock_Marble"
    },
    {
      "x": -14,
      "y": 2,
      "z": -19,
      "name": "Rock_Marble"
    },
    {
      "x": -14,
      "y": 3,
      "z": -19,
      "name": "Rock_Marble"
    },
    {
      "x": -14,
      "y": 4,
      "z": -19,
      "name": "Rock_Marble"
    },
    {
      "x": -14,
      "y": 5,
      "z": -19,
      "name": "Rock_Marble"
    },
    {
      "x": -14,
      "y": 6,
      "z": -19,
      "name": "Rock_Marble"
    },
    {
      "x": -14,
      "y": 7,
      "z": -19,
      "name": "Rock_Marble"
    },
    {
      "x": -14,
      "y": 8,
      "z": -19,
      "name": "Rock_Marble"
    },
    {
      "x": -14,
      "y": 9,
      "z": -19,
      "name": "Rock_Marble"
    },
    {
      "x": -14,
      "y": 10,
      "z": -19,
      "name": "Rock_Stone"
    },
    {
      "x": -14,
      "y": 13,
      "z": -19,
      "name": "Rock_Stone"
    },
    {
      "x": -14,
      "y": -9,
      "z": -18,
      "name": "Rock_Marble"
    },
    {
      "x": -14,
      "y": -8,
      "z": -18,
      "name": "Rock_Marble"
    },
    {
      "x": -14,
      "y": -7,
      "z": -18,
      "name": "Rock_Marble"
    },
    {
      "x": -14,
      "y": -6,
      "z": -18,
      "name": "Rock_Marble"
    },
    {
      "x": -14,
      "y": -5,
      "z": -18,
      "name": "Rock_Marble"
    },
    {
      "x": -14,
      "y": -4,
      "z": -18,
      "name": "Rock_Marble"
    },
    {
      "x": -14,
      "y": -3,
      "z": -18,
      "name": "Rock_Marble"
    },
    {
      "x": -14,
      "y": -2,
      "z": -18,
      "name": "Rock_Shale"
    },
    {
      "x": -14,
      "y": -1,
      "z": -18,
      "name": "Rock_Shale"
    },
    {
      "x": -14,
      "y": 0,
      "z": -18,
      "name": "Rock_Shale"
    },
    {
      "x": -14,
      "y": 1,
      "z": -18,
      "name": "Rock_Marble"
    },
    {
      "x": -14,
      "y": 2,
      "z": -18,
      "name": "Rock_Marble"
    },
    {
      "x": -14,
      "y": 3,
      "z": -18,
      "name": "Rock_Marble"
    },
    {
      "x": -14,
      "y": 4,
      "z": -18,
      "name": "Rock_Marble"
    },
    {
      "x": -14,
      "y": 5,
      "z": -18,
      "name": "Rock_Marble"
    },
    {
      "x": -14,
      "y": 6,
      "z": -18,
      "name": "Rock_Marble"
    },
    {
      "x": -14,
      "y": 7,
      "z": -18,
      "name": "Rock_Marble"
    },
    {
      "x": -14,
      "y": 8,
      "z": -18,
      "name": "Rock_Marble"
    },
    {
      "x": -14,
      "y": 9,
      "z": -18,
      "name": "Rock_Marble"
    },
    {
      "x": -14,
      "y": 10,
      "z": -18,
      "name": "Rock_Stone"
    },
    {
      "x": -14,
      "y": 14,
      "z": -18,
      "name": "Rock_Stone"
    },
    {
      "x": -14,
      "y": -10,
      "z": -17,
      "name": "Rock_Stone"
    },
    {
      "x": -14,
      "y": -9,
      "z": -17,
      "name": "Rock_Marble"
    },
    {
      "x": -14,
      "y": -8,
      "z": -17,
      "name": "Rock_Marble"
    },
    {
      "x": -14,
      "y": -7,
      "z": -17,
      "name": "Rock_Marble"
    },
    {
      "x": -14,
      "y": -6,
      "z": -17,
      "name": "Rock_Marble"
    },
    {
      "x": -14,
      "y": -5,
      "z": -17,
      "name": "Rock_Marble"
    },
    {
      "x": -14,
      "y": -4,
      "z": -17,
      "name": "Rock_Shale"
    },
    {
      "x": -14,
      "y": -3,
      "z": -17,
      "name": "Rock_Shale"
    },
    {
      "x": -14,
      "y": -2,
      "z": -17,
      "name": "Rock_Shale"
    },
    {
      "x": -14,
      "y": -1,
      "z": -17,
      "name": "Rock_Shale"
    },
    {
      "x": -14,
      "y": 0,
      "z": -17,
      "name": "Rock_Shale"
    },
    {
      "x": -14,
      "y": 1,
      "z": -17,
      "name": "Rock_Shale"
    },
    {
      "x": -14,
      "y": 2,
      "z": -17,
      "name": "Rock_Shale"
    },
    {
      "x": -14,
      "y": 3,
      "z": -17,
      "name": "Rock_Marble"
    },
    {
      "x": -14,
      "y": 4,
      "z": -17,
      "name": "Rock_Marble"
    },
    {
      "x": -14,
      "y": 5,
      "z": -17,
      "name": "Rock_Marble"
    },
    {
      "x": -14,
      "y": 6,
      "z": -17,
      "name": "Rock_Shale"
    },
    {
      "x": -14,
      "y": 7,
      "z": -17,
      "name": "Rock_Shale"
    },
    {
      "x": -14,
      "y": 8,
      "z": -17,
      "name": "Rock_Marble"
    },
    {
      "x": -14,
      "y": 9,
      "z": -17,
      "name": "Rock_Marble"
    },
    {
      "x": -14,
      "y": 14,
      "z": -17,
      "name": "Rock_Stone"
    },
    {
      "x": -14,
      "y": 15,
      "z": -17,
      "name": "Rock_Marble"
    },
    {
      "x": -14,
      "y": -9,
      "z": -16,
      "name": "Rock_Shale"
    },
    {
      "x": -14,
      "y": -8,
      "z": -16,
      "name": "Rock_Shale"
    },
    {
      "x": -14,
      "y": -7,
      "z": -16,
      "name": "Rock_Shale"
    },
    {
      "x": -14,
      "y": -6,
      "z": -16,
      "name": "Rock_Shale"
    },
    {
      "x": -14,
      "y": -5,
      "z": -16,
      "name": "Rock_Shale"
    },
    {
      "x": -14,
      "y": -4,
      "z": -16,
      "name": "Rock_Shale"
    },
    {
      "x": -14,
      "y": -3,
      "z": -16,
      "name": "Rock_Shale"
    },
    {
      "x": -14,
      "y": 1,
      "z": -16,
      "name": "Rock_Shale"
    },
    {
      "x": -14,
      "y": 2,
      "z": -16,
      "name": "Rock_Shale"
    },
    {
      "x": -14,
      "y": 3,
      "z": -16,
      "name": "Rock_Shale"
    },
    {
      "x": -14,
      "y": 4,
      "z": -16,
      "name": "Rock_Shale"
    },
    {
      "x": -14,
      "y": 5,
      "z": -16,
      "name": "Rock_Shale"
    },
    {
      "x": -14,
      "y": 6,
      "z": -16,
      "name": "Rock_Shale"
    },
    {
      "x": -14,
      "y": 7,
      "z": -16,
      "name": "Rock_Shale"
    },
    {
      "x": -14,
      "y": 8,
      "z": -16,
      "name": "Rock_Shale"
    },
    {
      "x": -14,
      "y": 9,
      "z": -16,
      "name": "Rock_Shale"
    },
    {
      "x": -14,
      "y": 14,
      "z": -16,
      "name": "Rock_Stone"
    },
    {
      "x": -14,
      "y": 15,
      "z": -16,
      "name": "Rock_Marble"
    },
    {
      "x": -14,
      "y": -9,
      "z": -15,
      "name": "Rock_Shale"
    },
    {
      "x": -14,
      "y": -8,
      "z": -15,
      "name": "Rock_Shale"
    },
    {
      "x": -14,
      "y": -7,
      "z": -15,
      "name": "Rock_Shale"
    },
    {
      "x": -14,
      "y": -6,
      "z": -15,
      "name": "Rock_Shale"
    },
    {
      "x": -14,
      "y": -5,
      "z": -15,
      "name": "Rock_Shale"
    },
    {
      "x": -14,
      "y": 3,
      "z": -15,
      "name": "Rock_Shale"
    },
    {
      "x": -14,
      "y": 4,
      "z": -15,
      "name": "Rock_Shale"
    },
    {
      "x": -14,
      "y": 5,
      "z": -15,
      "name": "Rock_Shale"
    },
    {
      "x": -14,
      "y": 8,
      "z": -15,
      "name": "Rock_Shale"
    },
    {
      "x": -14,
      "y": 9,
      "z": -15,
      "name": "Rock_Shale"
    },
    {
      "x": -14,
      "y": 14,
      "z": -15,
      "name": "Rock_Stone"
    },
    {
      "x": -14,
      "y": 15,
      "z": -15,
      "name": "Rock_Marble"
    },
    {
      "x": -14,
      "y": 14,
      "z": -14,
      "name": "Rock_Stone"
    },
    {
      "x": -14,
      "y": 15,
      "z": -14,
      "name": "Rock_Marble"
    },
    {
      "x": -14,
      "y": 14,
      "z": -13,
      "name": "Rock_Shale"
    },
    {
      "x": -14,
      "y": 15,
      "z": -13,
      "name": "Rock_Chalk"
    },
    {
      "x": -14,
      "y": 14,
      "z": -12,
      "name": "Rock_Shale"
    },
    {
      "x": -14,
      "y": 15,
      "z": -12,
      "name": "Rock_Chalk"
    },
    {
      "x": -14,
      "y": 15,
      "z": -11,
      "name": "Rock_Chalk"
    },
    {
      "x": -13,
      "y": 2,
      "z": -24,
      "name": "Rock_Marble"
    },
    {
      "x": -13,
      "y": 3,
      "z": -24,
      "name": "Rock_Marble"
    },
    {
      "x": -13,
      "y": 4,
      "z": -24,
      "name": "Rock_Marble"
    },
    {
      "x": -13,
      "y": 5,
      "z": -24,
      "name": "Rock_Marble"
    },
    {
      "x": -13,
      "y": 6,
      "z": -24,
      "name": "Rock_Marble"
    },
    {
      "x": -13,
      "y": 7,
      "z": -24,
      "name": "Rock_Marble"
    },
    {
      "x": -13,
      "y": 8,
      "z": -24,
      "name": "Rock_Marble"
    },
    {
      "x": -13,
      "y": 9,
      "z": -24,
      "name": "Rock_Stone"
    },
    {
      "x": -13,
      "y": -1,
      "z": -23,
      "name": "Rock_Marble"
    },
    {
      "x": -13,
      "y": 0,
      "z": -23,
      "name": "Rock_Marble"
    },
    {
      "x": -13,
      "y": 1,
      "z": -23,
      "name": "Rock_Marble"
    },
    {
      "x": -13,
      "y": 2,
      "z": -23,
      "name": "Rock_Marble"
    },
    {
      "x": -13,
      "y": 3,
      "z": -23,
      "name": "Rock_Marble"
    },
    {
      "x": -13,
      "y": 4,
      "z": -23,
      "name": "Rock_Marble"
    },
    {
      "x": -13,
      "y": 5,
      "z": -23,
      "name": "Rock_Marble"
    },
    {
      "x": -13,
      "y": 6,
      "z": -23,
      "name": "Rock_Marble"
    },
    {
      "x": -13,
      "y": 7,
      "z": -23,
      "name": "Rock_Marble"
    },
    {
      "x": -13,
      "y": 8,
      "z": -23,
      "name": "Rock_Marble"
    },
    {
      "x": -13,
      "y": 9,
      "z": -23,
      "name": "Rock_Stone"
    },
    {
      "x": -13,
      "y": -4,
      "z": -22,
      "name": "Rock_Marble"
    },
    {
      "x": -13,
      "y": -3,
      "z": -22,
      "name": "Rock_Marble"
    },
    {
      "x": -13,
      "y": -2,
      "z": -22,
      "name": "Rock_Marble"
    },
    {
      "x": -13,
      "y": -1,
      "z": -22,
      "name": "Rock_Marble"
    },
    {
      "x": -13,
      "y": 0,
      "z": -22,
      "name": "Rock_Marble"
    },
    {
      "x": -13,
      "y": 1,
      "z": -22,
      "name": "Rock_Marble"
    },
    {
      "x": -13,
      "y": 2,
      "z": -22,
      "name": "Rock_Marble"
    },
    {
      "x": -13,
      "y": 3,
      "z": -22,
      "name": "Rock_Marble"
    },
    {
      "x": -13,
      "y": 4,
      "z": -22,
      "name": "Rock_Marble"
    },
    {
      "x": -13,
      "y": 5,
      "z": -22,
      "name": "Rock_Marble"
    },
    {
      "x": -13,
      "y": 6,
      "z": -22,
      "name": "Rock_Marble"
    },
    {
      "x": -13,
      "y": 7,
      "z": -22,
      "name": "Rock_Marble"
    },
    {
      "x": -13,
      "y": 8,
      "z": -22,
      "name": "Rock_Marble"
    },
    {
      "x": -13,
      "y": 9,
      "z": -22,
      "name": "Rock_Stone"
    },
    {
      "x": -13,
      "y": 12,
      "z": -22,
      "name": "Rock_Stone"
    },
    {
      "x": -13,
      "y": -6,
      "z": -21,
      "name": "Rock_Marble"
    },
    {
      "x": -13,
      "y": -5,
      "z": -21,
      "name": "Rock_Marble"
    },
    {
      "x": -13,
      "y": -4,
      "z": -21,
      "name": "Rock_Marble"
    },
    {
      "x": -13,
      "y": -3,
      "z": -21,
      "name": "Rock_Marble"
    },
    {
      "x": -13,
      "y": -2,
      "z": -21,
      "name": "Rock_Calcite"
    },
    {
      "x": -13,
      "y": -1,
      "z": -21,
      "name": "Rock_Calcite"
    },
    {
      "x": -13,
      "y": 0,
      "z": -21,
      "name": "Rock_Calcite"
    },
    {
      "x": -13,
      "y": 1,
      "z": -21,
      "name": "Rock_Calcite"
    },
    {
      "x": -13,
      "y": 2,
      "z": -21,
      "name": "Rock_Calcite"
    },
    {
      "x": -13,
      "y": 3,
      "z": -21,
      "name": "Rock_Calcite"
    },
    {
      "x": -13,
      "y": 4,
      "z": -21,
      "name": "Rock_Calcite"
    },
    {
      "x": -13,
      "y": 5,
      "z": -21,
      "name": "Rock_Calcite"
    },
    {
      "x": -13,
      "y": 6,
      "z": -21,
      "name": "Rock_Calcite"
    },
    {
      "x": -13,
      "y": 7,
      "z": -21,
      "name": "Rock_Marble"
    },
    {
      "x": -13,
      "y": 8,
      "z": -21,
      "name": "Rock_Marble"
    },
    {
      "x": -13,
      "y": 9,
      "z": -21,
      "name": "Rock_Stone"
    },
    {
      "x": -13,
      "y": 12,
      "z": -21,
      "name": "Rock_Stone"
    },
    {
      "x": -13,
      "y": 13,
      "z": -21,
      "name": "Rock_Stone"
    },
    {
      "x": -13,
      "y": -7,
      "z": -20,
      "name": "Rock_Calcite"
    },
    {
      "x": -13,
      "y": -6,
      "z": -20,
      "name": "Rock_Calcite"
    },
    {
      "x": -13,
      "y": -5,
      "z": -20,
      "name": "Rock_Calcite"
    },
    {
      "x": -13,
      "y": -4,
      "z": -20,
      "name": "Rock_Calcite"
    },
    {
      "x": -13,
      "y": -3,
      "z": -20,
      "name": "Rock_Calcite"
    },
    {
      "x": -13,
      "y": -2,
      "z": -20,
      "name": "Rock_Marble"
    },
    {
      "x": -13,
      "y": -1,
      "z": -20,
      "name": "Rock_Marble"
    },
    {
      "x": -13,
      "y": 0,
      "z": -20,
      "name": "Rock_Marble"
    },
    {
      "x": -13,
      "y": 1,
      "z": -20,
      "name": "Rock_Marble"
    },
    {
      "x": -13,
      "y": 2,
      "z": -20,
      "name": "Rock_Marble"
    },
    {
      "x": -13,
      "y": 3,
      "z": -20,
      "name": "Rock_Marble"
    },
    {
      "x": -13,
      "y": 4,
      "z": -20,
      "name": "Rock_Marble"
    },
    {
      "x": -13,
      "y": 5,
      "z": -20,
      "name": "Rock_Marble"
    },
    {
      "x": -13,
      "y": 6,
      "z": -20,
      "name": "Rock_Marble"
    },
    {
      "x": -13,
      "y": 7,
      "z": -20,
      "name": "Rock_Marble"
    },
    {
      "x": -13,
      "y": 8,
      "z": -20,
      "name": "Rock_Marble"
    },
    {
      "x": -13,
      "y": 9,
      "z": -20,
      "name": "Rock_Stone"
    },
    {
      "x": -13,
      "y": 12,
      "z": -20,
      "name": "Rock_Stone"
    },
    {
      "x": -13,
      "y": 13,
      "z": -20,
      "name": "Rock_Stone"
    },
    {
      "x": -13,
      "y": 14,
      "z": -20,
      "name": "Rock_Marble"
    },
    {
      "x": -13,
      "y": -8,
      "z": -19,
      "name": "Rock_Marble"
    },
    {
      "x": -13,
      "y": -7,
      "z": -19,
      "name": "Rock_Marble"
    },
    {
      "x": -13,
      "y": -6,
      "z": -19,
      "name": "Rock_Marble"
    },
    {
      "x": -13,
      "y": -5,
      "z": -19,
      "name": "Rock_Marble"
    },
    {
      "x": -13,
      "y": -4,
      "z": -19,
      "name": "Rock_Marble"
    },
    {
      "x": -13,
      "y": -3,
      "z": -19,
      "name": "Rock_Marble"
    },
    {
      "x": -13,
      "y": -2,
      "z": -19,
      "name": "Rock_Marble"
    },
    {
      "x": -13,
      "y": -1,
      "z": -19,
      "name": "Rock_Marble"
    },
    {
      "x": -13,
      "y": 0,
      "z": -19,
      "name": "Rock_Marble"
    },
    {
      "x": -13,
      "y": 1,
      "z": -19,
      "name": "Rock_Marble"
    },
    {
      "x": -13,
      "y": 2,
      "z": -19,
      "name": "Rock_Marble"
    },
    {
      "x": -13,
      "y": 3,
      "z": -19,
      "name": "Rock_Marble"
    },
    {
      "x": -13,
      "y": 4,
      "z": -19,
      "name": "Rock_Marble"
    },
    {
      "x": -13,
      "y": 5,
      "z": -19,
      "name": "Rock_Marble"
    },
    {
      "x": -13,
      "y": 6,
      "z": -19,
      "name": "Rock_Marble"
    },
    {
      "x": -13,
      "y": 7,
      "z": -19,
      "name": "Rock_Marble"
    },
    {
      "x": -13,
      "y": 8,
      "z": -19,
      "name": "Rock_Marble"
    },
    {
      "x": -13,
      "y": 9,
      "z": -19,
      "name": "Rock_Stone"
    },
    {
      "x": -13,
      "y": 13,
      "z": -19,
      "name": "Rock_Stone"
    },
    {
      "x": -13,
      "y": 14,
      "z": -19,
      "name": "Rock_Marble"
    },
    {
      "x": -13,
      "y": -9,
      "z": -18,
      "name": "Rock_Stone"
    },
    {
      "x": -13,
      "y": -8,
      "z": -18,
      "name": "Rock_Marble"
    },
    {
      "x": -13,
      "y": -7,
      "z": -18,
      "name": "Rock_Marble"
    },
    {
      "x": -13,
      "y": -6,
      "z": -18,
      "name": "Rock_Marble"
    },
    {
      "x": -13,
      "y": -5,
      "z": -18,
      "name": "Rock_Marble"
    },
    {
      "x": -13,
      "y": -4,
      "z": -18,
      "name": "Rock_Marble"
    },
    {
      "x": -13,
      "y": -3,
      "z": -18,
      "name": "Rock_Marble"
    },
    {
      "x": -13,
      "y": -2,
      "z": -18,
      "name": "Rock_Marble"
    },
    {
      "x": -13,
      "y": -1,
      "z": -18,
      "name": "Rock_Shale"
    },
    {
      "x": -13,
      "y": 0,
      "z": -18,
      "name": "Rock_Shale"
    },
    {
      "x": -13,
      "y": 1,
      "z": -18,
      "name": "Rock_Shale"
    },
    {
      "x": -13,
      "y": 2,
      "z": -18,
      "name": "Rock_Marble"
    },
    {
      "x": -13,
      "y": 3,
      "z": -18,
      "name": "Rock_Marble"
    },
    {
      "x": -13,
      "y": 4,
      "z": -18,
      "name": "Rock_Marble"
    },
    {
      "x": -13,
      "y": 5,
      "z": -18,
      "name": "Rock_Marble"
    },
    {
      "x": -13,
      "y": 6,
      "z": -18,
      "name": "Rock_Marble"
    },
    {
      "x": -13,
      "y": 7,
      "z": -18,
      "name": "Rock_Marble"
    },
    {
      "x": -13,
      "y": 8,
      "z": -18,
      "name": "Rock_Marble"
    },
    {
      "x": -13,
      "y": 9,
      "z": -18,
      "name": "Rock_Stone"
    },
    {
      "x": -13,
      "y": 13,
      "z": -18,
      "name": "Rock_Stone"
    },
    {
      "x": -13,
      "y": 14,
      "z": -18,
      "name": "Rock_Marble"
    },
    {
      "x": -13,
      "y": 15,
      "z": -18,
      "name": "Rock_Marble"
    },
    {
      "x": -13,
      "y": -9,
      "z": -17,
      "name": "Rock_Shale"
    },
    {
      "x": -13,
      "y": -8,
      "z": -17,
      "name": "Rock_Shale"
    },
    {
      "x": -13,
      "y": -7,
      "z": -17,
      "name": "Rock_Marble"
    },
    {
      "x": -13,
      "y": -6,
      "z": -17,
      "name": "Rock_Marble"
    },
    {
      "x": -13,
      "y": -5,
      "z": -17,
      "name": "Rock_Marble"
    },
    {
      "x": -13,
      "y": -4,
      "z": -17,
      "name": "Rock_Marble"
    },
    {
      "x": -13,
      "y": -3,
      "z": -17,
      "name": "Rock_Shale"
    },
    {
      "x": -13,
      "y": -2,
      "z": -17,
      "name": "Rock_Shale"
    },
    {
      "x": -13,
      "y": -1,
      "z": -17,
      "name": "Rock_Shale"
    },
    {
      "x": -13,
      "y": 0,
      "z": -17,
      "name": "Rock_Shale"
    },
    {
      "x": -13,
      "y": 1,
      "z": -17,
      "name": "Rock_Shale"
    },
    {
      "x": -13,
      "y": 2,
      "z": -17,
      "name": "Rock_Shale"
    },
    {
      "x": -13,
      "y": 3,
      "z": -17,
      "name": "Rock_Shale"
    },
    {
      "x": -13,
      "y": 4,
      "z": -17,
      "name": "Rock_Shale"
    },
    {
      "x": -13,
      "y": 5,
      "z": -17,
      "name": "Rock_Shale"
    },
    {
      "x": -13,
      "y": 6,
      "z": -17,
      "name": "Rock_Shale"
    },
    {
      "x": -13,
      "y": 7,
      "z": -17,
      "name": "Rock_Shale"
    },
    {
      "x": -13,
      "y": 8,
      "z": -17,
      "name": "Rock_Shale"
    },
    {
      "x": -13,
      "y": 13,
      "z": -17,
      "name": "Rock_Stone"
    },
    {
      "x": -13,
      "y": 14,
      "z": -17,
      "name": "Rock_Marble"
    },
    {
      "x": -13,
      "y": 15,
      "z": -17,
      "name": "Rock_Marble"
    },
    {
      "x": -13,
      "y": 16,
      "z": -17,
      "name": "Rock_Marble"
    },
    {
      "x": -13,
      "y": -9,
      "z": -16,
      "name": "Rock_Shale"
    },
    {
      "x": -13,
      "y": -8,
      "z": -16,
      "name": "Rock_Shale"
    },
    {
      "x": -13,
      "y": -7,
      "z": -16,
      "name": "Rock_Shale"
    },
    {
      "x": -13,
      "y": -6,
      "z": -16,
      "name": "Rock_Shale"
    },
    {
      "x": -13,
      "y": -5,
      "z": -16,
      "name": "Rock_Shale"
    },
    {
      "x": -13,
      "y": -4,
      "z": -16,
      "name": "Rock_Shale"
    },
    {
      "x": -13,
      "y": -3,
      "z": -16,
      "name": "Rock_Shale"
    },
    {
      "x": -13,
      "y": -2,
      "z": -16,
      "name": "Rock_Shale"
    },
    {
      "x": -13,
      "y": 2,
      "z": -16,
      "name": "Rock_Shale"
    },
    {
      "x": -13,
      "y": 3,
      "z": -16,
      "name": "Rock_Shale"
    },
    {
      "x": -13,
      "y": 4,
      "z": -16,
      "name": "Rock_Shale"
    },
    {
      "x": -13,
      "y": 5,
      "z": -16,
      "name": "Rock_Shale"
    },
    {
      "x": -13,
      "y": 6,
      "z": -16,
      "name": "Rock_Shale"
    },
    {
      "x": -13,
      "y": 7,
      "z": -16,
      "name": "Rock_Shale"
    },
    {
      "x": -13,
      "y": 8,
      "z": -16,
      "name": "Rock_Shale"
    },
    {
      "x": -13,
      "y": 13,
      "z": -16,
      "name": "Rock_Stone"
    },
    {
      "x": -13,
      "y": 14,
      "z": -16,
      "name": "Rock_Marble"
    },
    {
      "x": -13,
      "y": 15,
      "z": -16,
      "name": "Rock_Marble"
    },
    {
      "x": -13,
      "y": 16,
      "z": -16,
      "name": "Rock_Marble"
    },
    {
      "x": -13,
      "y": -7,
      "z": -15,
      "name": "Rock_Shale"
    },
    {
      "x": -13,
      "y": -6,
      "z": -15,
      "name": "Rock_Shale"
    },
    {
      "x": -13,
      "y": -5,
      "z": -15,
      "name": "Rock_Shale"
    },
    {
      "x": -13,
      "y": -4,
      "z": -15,
      "name": "Rock_Shale"
    },
    {
      "x": -13,
      "y": 13,
      "z": -15,
      "name": "Rock_Shale"
    },
    {
      "x": -13,
      "y": 14,
      "z": -15,
      "name": "Rock_Marble"
    },
    {
      "x": -13,
      "y": 15,
      "z": -15,
      "name": "Rock_Marble"
    },
    {
      "x": -13,
      "y": 16,
      "z": -15,
      "name": "Rock_Marble"
    },
    {
      "x": -13,
      "y": 13,
      "z": -14,
      "name": "Rock_Shale"
    },
    {
      "x": -13,
      "y": 14,
      "z": -14,
      "name": "Rock_Marble"
    },
    {
      "x": -13,
      "y": 15,
      "z": -14,
      "name": "Rock_Marble"
    },
    {
      "x": -13,
      "y": 16,
      "z": -14,
      "name": "Rock_Marble"
    },
    {
      "x": -13,
      "y": 14,
      "z": -13,
      "name": "Rock_Chalk"
    },
    {
      "x": -13,
      "y": 15,
      "z": -13,
      "name": "Rock_Chalk"
    },
    {
      "x": -13,
      "y": 16,
      "z": -13,
      "name": "Rock_Chalk"
    },
    {
      "x": -13,
      "y": 15,
      "z": -12,
      "name": "Rock_Chalk"
    },
    {
      "x": -13,
      "y": 16,
      "z": -12,
      "name": "Rock_Chalk"
    },
    {
      "x": -13,
      "y": 16,
      "z": -11,
      "name": "Rock_Chalk"
    },
    {
      "x": -12,
      "y": 4,
      "z": -25,
      "name": "Rock_Marble"
    },
    {
      "x": -12,
      "y": 5,
      "z": -25,
      "name": "Rock_Marble"
    },
    {
      "x": -12,
      "y": 6,
      "z": -25,
      "name": "Rock_Chalk"
    },
    {
      "x": -12,
      "y": 7,
      "z": -25,
      "name": "Rock_Chalk"
    },
    {
      "x": -12,
      "y": 8,
      "z": -25,
      "name": "Rock_Stone"
    },
    {
      "x": -12,
      "y": 9,
      "z": -25,
      "name": "Rock_Stone"
    },
    {
      "x": -12,
      "y": 0,
      "z": -24,
      "name": "Rock_Marble"
    },
    {
      "x": -12,
      "y": 1,
      "z": -24,
      "name": "Rock_Marble"
    },
    {
      "x": -12,
      "y": 2,
      "z": -24,
      "name": "Rock_Marble"
    },
    {
      "x": -12,
      "y": 3,
      "z": -24,
      "name": "Rock_Marble"
    },
    {
      "x": -12,
      "y": 4,
      "z": -24,
      "name": "Rock_Marble"
    },
    {
      "x": -12,
      "y": 5,
      "z": -24,
      "name": "Rock_Marble"
    },
    {
      "x": -12,
      "y": 6,
      "z": -24,
      "name": "Rock_Marble"
    },
    {
      "x": -12,
      "y": 7,
      "z": -24,
      "name": "Rock_Marble"
    },
    {
      "x": -12,
      "y": 8,
      "z": -24,
      "name": "Rock_Stone"
    },
    {
      "x": -12,
      "y": 9,
      "z": -24,
      "name": "Rock_Stone"
    },
    {
      "x": -12,
      "y": -2,
      "z": -23,
      "name": "Rock_Marble"
    },
    {
      "x": -12,
      "y": -1,
      "z": -23,
      "name": "Rock_Marble"
    },
    {
      "x": -12,
      "y": 0,
      "z": -23,
      "name": "Rock_Marble"
    },
    {
      "x": -12,
      "y": 1,
      "z": -23,
      "name": "Rock_Marble"
    },
    {
      "x": -12,
      "y": 2,
      "z": -23,
      "name": "Rock_Marble"
    },
    {
      "x": -12,
      "y": 3,
      "z": -23,
      "name": "Rock_Marble"
    },
    {
      "x": -12,
      "y": 4,
      "z": -23,
      "name": "Rock_Marble"
    },
    {
      "x": -12,
      "y": 5,
      "z": -23,
      "name": "Rock_Marble"
    },
    {
      "x": -12,
      "y": 6,
      "z": -23,
      "name": "Rock_Marble"
    },
    {
      "x": -12,
      "y": 7,
      "z": -23,
      "name": "Rock_Marble"
    },
    {
      "x": -12,
      "y": 8,
      "z": -23,
      "name": "Rock_Stone"
    },
    {
      "x": -12,
      "y": 9,
      "z": -23,
      "name": "Rock_Stone"
    },
    {
      "x": -12,
      "y": 12,
      "z": -23,
      "name": "Rock_Stone"
    },
    {
      "x": -12,
      "y": -4,
      "z": -22,
      "name": "Rock_Marble"
    },
    {
      "x": -12,
      "y": -3,
      "z": -22,
      "name": "Rock_Marble"
    },
    {
      "x": -12,
      "y": -2,
      "z": -22,
      "name": "Rock_Marble"
    },
    {
      "x": -12,
      "y": -1,
      "z": -22,
      "name": "Rock_Marble"
    },
    {
      "x": -12,
      "y": 0,
      "z": -22,
      "name": "Rock_Marble"
    },
    {
      "x": -12,
      "y": 1,
      "z": -22,
      "name": "Rock_Marble"
    },
    {
      "x": -12,
      "y": 2,
      "z": -22,
      "name": "Rock_Marble"
    },
    {
      "x": -12,
      "y": 3,
      "z": -22,
      "name": "Rock_Marble"
    },
    {
      "x": -12,
      "y": 4,
      "z": -22,
      "name": "Rock_Marble"
    },
    {
      "x": -12,
      "y": 5,
      "z": -22,
      "name": "Rock_Marble"
    },
    {
      "x": -12,
      "y": 6,
      "z": -22,
      "name": "Rock_Marble"
    },
    {
      "x": -12,
      "y": 7,
      "z": -22,
      "name": "Rock_Marble"
    },
    {
      "x": -12,
      "y": 8,
      "z": -22,
      "name": "Rock_Stone"
    },
    {
      "x": -12,
      "y": 9,
      "z": -22,
      "name": "Rock_Stone"
    },
    {
      "x": -12,
      "y": 12,
      "z": -22,
      "name": "Rock_Stone"
    },
    {
      "x": -12,
      "y": 13,
      "z": -22,
      "name": "Rock_Marble"
    },
    {
      "x": -12,
      "y": -6,
      "z": -21,
      "name": "Rock_Marble"
    },
    {
      "x": -12,
      "y": -5,
      "z": -21,
      "name": "Rock_Marble"
    },
    {
      "x": -12,
      "y": -4,
      "z": -21,
      "name": "Rock_Marble"
    },
    {
      "x": -12,
      "y": -3,
      "z": -21,
      "name": "Rock_Marble"
    },
    {
      "x": -12,
      "y": -2,
      "z": -21,
      "name": "Rock_Calcite"
    },
    {
      "x": -12,
      "y": -1,
      "z": -21,
      "name": "Rock_Calcite"
    },
    {
      "x": -12,
      "y": 0,
      "z": -21,
      "name": "Rock_Calcite"
    },
    {
      "x": -12,
      "y": 1,
      "z": -21,
      "name": "Rock_Calcite"
    },
    {
      "x": -12,
      "y": 2,
      "z": -21,
      "name": "Rock_Calcite"
    },
    {
      "x": -12,
      "y": 3,
      "z": -21,
      "name": "Rock_Calcite"
    },
    {
      "x": -12,
      "y": 4,
      "z": -21,
      "name": "Rock_Calcite"
    },
    {
      "x": -12,
      "y": 5,
      "z": -21,
      "name": "Rock_Calcite"
    },
    {
      "x": -12,
      "y": 6,
      "z": -21,
      "name": "Rock_Marble"
    },
    {
      "x": -12,
      "y": 7,
      "z": -21,
      "name": "Rock_Marble"
    },
    {
      "x": -12,
      "y": 8,
      "z": -21,
      "name": "Rock_Stone"
    },
    {
      "x": -12,
      "y": 12,
      "z": -21,
      "name": "Rock_Stone"
    },
    {
      "x": -12,
      "y": 13,
      "z": -21,
      "name": "Rock_Marble"
    },
    {
      "x": -12,
      "y": 14,
      "z": -21,
      "name": "Rock_Marble"
    },
    {
      "x": -12,
      "y": -8,
      "z": -20,
      "name": "Rock_Stone"
    },
    {
      "x": -12,
      "y": -7,
      "z": -20,
      "name": "Rock_Calcite"
    },
    {
      "x": -12,
      "y": -6,
      "z": -20,
      "name": "Rock_Calcite"
    },
    {
      "x": -12,
      "y": -5,
      "z": -20,
      "name": "Rock_Calcite"
    },
    {
      "x": -12,
      "y": -4,
      "z": -20,
      "name": "Rock_Calcite"
    },
    {
      "x": -12,
      "y": -3,
      "z": -20,
      "name": "Rock_Calcite"
    },
    {
      "x": -12,
      "y": -2,
      "z": -20,
      "name": "Rock_Marble"
    },
    {
      "x": -12,
      "y": -1,
      "z": -20,
      "name": "Rock_Marble"
    },
    {
      "x": -12,
      "y": 0,
      "z": -20,
      "name": "Rock_Marble"
    },
    {
      "x": -12,
      "y": 1,
      "z": -20,
      "name": "Rock_Marble"
    },
    {
      "x": -12,
      "y": 2,
      "z": -20,
      "name": "Rock_Marble"
    },
    {
      "x": -12,
      "y": 3,
      "z": -20,
      "name": "Rock_Marble"
    },
    {
      "x": -12,
      "y": 4,
      "z": -20,
      "name": "Rock_Marble"
    },
    {
      "x": -12,
      "y": 5,
      "z": -20,
      "name": "Rock_Marble"
    },
    {
      "x": -12,
      "y": 6,
      "z": -20,
      "name": "Rock_Marble"
    },
    {
      "x": -12,
      "y": 7,
      "z": -20,
      "name": "Rock_Marble"
    },
    {
      "x": -12,
      "y": 8,
      "z": -20,
      "name": "Rock_Stone"
    },
    {
      "x": -12,
      "y": 12,
      "z": -20,
      "name": "Rock_Stone"
    },
    {
      "x": -12,
      "y": 13,
      "z": -20,
      "name": "Rock_Marble"
    },
    {
      "x": -12,
      "y": 14,
      "z": -20,
      "name": "Rock_Marble"
    },
    {
      "x": -12,
      "y": -9,
      "z": -19,
      "name": "Rock_Stone"
    },
    {
      "x": -12,
      "y": -8,
      "z": -19,
      "name": "Rock_Stone"
    },
    {
      "x": -12,
      "y": -7,
      "z": -19,
      "name": "Rock_Marble"
    },
    {
      "x": -12,
      "y": -6,
      "z": -19,
      "name": "Rock_Marble"
    },
    {
      "x": -12,
      "y": -5,
      "z": -19,
      "name": "Rock_Marble"
    },
    {
      "x": -12,
      "y": -4,
      "z": -19,
      "name": "Rock_Marble"
    },
    {
      "x": -12,
      "y": -3,
      "z": -19,
      "name": "Rock_Marble"
    },
    {
      "x": -12,
      "y": -2,
      "z": -19,
      "name": "Rock_Marble"
    },
    {
      "x": -12,
      "y": -1,
      "z": -19,
      "name": "Rock_Marble"
    },
    {
      "x": -12,
      "y": 0,
      "z": -19,
      "name": "Rock_Marble"
    },
    {
      "x": -12,
      "y": 1,
      "z": -19,
      "name": "Rock_Marble"
    },
    {
      "x": -12,
      "y": 2,
      "z": -19,
      "name": "Rock_Marble"
    },
    {
      "x": -12,
      "y": 3,
      "z": -19,
      "name": "Rock_Marble"
    },
    {
      "x": -12,
      "y": 4,
      "z": -19,
      "name": "Rock_Marble"
    },
    {
      "x": -12,
      "y": 5,
      "z": -19,
      "name": "Rock_Marble"
    },
    {
      "x": -12,
      "y": 6,
      "z": -19,
      "name": "Rock_Marble"
    },
    {
      "x": -12,
      "y": 7,
      "z": -19,
      "name": "Rock_Marble"
    },
    {
      "x": -12,
      "y": 8,
      "z": -19,
      "name": "Rock_Stone"
    },
    {
      "x": -12,
      "y": 12,
      "z": -19,
      "name": "Rock_Stone"
    },
    {
      "x": -12,
      "y": 13,
      "z": -19,
      "name": "Rock_Marble"
    },
    {
      "x": -12,
      "y": 14,
      "z": -19,
      "name": "Rock_Marble"
    },
    {
      "x": -12,
      "y": 15,
      "z": -19,
      "name": "Rock_Marble"
    },
    {
      "x": -12,
      "y": -8,
      "z": -18,
      "name": "Rock_Shale"
    },
    {
      "x": -12,
      "y": -7,
      "z": -18,
      "name": "Rock_Marble"
    },
    {
      "x": -12,
      "y": -6,
      "z": -18,
      "name": "Rock_Marble"
    },
    {
      "x": -12,
      "y": -5,
      "z": -18,
      "name": "Rock_Marble"
    },
    {
      "x": -12,
      "y": -4,
      "z": -18,
      "name": "Rock_Marble"
    },
    {
      "x": -12,
      "y": -3,
      "z": -18,
      "name": "Rock_Marble"
    },
    {
      "x": -12,
      "y": -2,
      "z": -18,
      "name": "Rock_Marble"
    },
    {
      "x": -12,
      "y": -1,
      "z": -18,
      "name": "Rock_Shale"
    },
    {
      "x": -12,
      "y": 0,
      "z": -18,
      "name": "Rock_Shale"
    },
    {
      "x": -12,
      "y": 1,
      "z": -18,
      "name": "Rock_Shale"
    },
    {
      "x": -12,
      "y": 2,
      "z": -18,
      "name": "Rock_Shale"
    },
    {
      "x": -12,
      "y": 3,
      "z": -18,
      "name": "Rock_Marble"
    },
    {
      "x": -12,
      "y": 4,
      "z": -18,
      "name": "Rock_Marble"
    },
    {
      "x": -12,
      "y": 5,
      "z": -18,
      "name": "Rock_Marble"
    },
    {
      "x": -12,
      "y": 6,
      "z": -18,
      "name": "Rock_Marble"
    },
    {
      "x": -12,
      "y": 7,
      "z": -18,
      "name": "Rock_Marble"
    },
    {
      "x": -12,
      "y": 8,
      "z": -18,
      "name": "Rock_Stone"
    },
    {
      "x": -12,
      "y": 12,
      "z": -18,
      "name": "Rock_Stone"
    },
    {
      "x": -12,
      "y": 13,
      "z": -18,
      "name": "Rock_Marble"
    },
    {
      "x": -12,
      "y": 14,
      "z": -18,
      "name": "Rock_Marble"
    },
    {
      "x": -12,
      "y": 15,
      "z": -18,
      "name": "Rock_Marble"
    },
    {
      "x": -12,
      "y": 16,
      "z": -18,
      "name": "Rock_Marble"
    },
    {
      "x": -12,
      "y": -8,
      "z": -17,
      "name": "Rock_Shale"
    },
    {
      "x": -12,
      "y": -7,
      "z": -17,
      "name": "Rock_Shale"
    },
    {
      "x": -12,
      "y": -6,
      "z": -17,
      "name": "Rock_Shale"
    },
    {
      "x": -12,
      "y": -5,
      "z": -17,
      "name": "Rock_Marble"
    },
    {
      "x": -12,
      "y": -4,
      "z": -17,
      "name": "Rock_Marble"
    },
    {
      "x": -12,
      "y": -3,
      "z": -17,
      "name": "Rock_Shale"
    },
    {
      "x": -12,
      "y": -2,
      "z": -17,
      "name": "Rock_Shale"
    },
    {
      "x": -12,
      "y": -1,
      "z": -17,
      "name": "Rock_Shale"
    },
    {
      "x": -12,
      "y": 0,
      "z": -17,
      "name": "Rock_Shale"
    },
    {
      "x": -12,
      "y": 1,
      "z": -17,
      "name": "Rock_Shale"
    },
    {
      "x": -12,
      "y": 2,
      "z": -17,
      "name": "Rock_Shale"
    },
    {
      "x": -12,
      "y": 3,
      "z": -17,
      "name": "Rock_Shale"
    },
    {
      "x": -12,
      "y": 4,
      "z": -17,
      "name": "Rock_Shale"
    },
    {
      "x": -12,
      "y": 5,
      "z": -17,
      "name": "Rock_Shale"
    },
    {
      "x": -12,
      "y": 6,
      "z": -17,
      "name": "Rock_Shale"
    },
    {
      "x": -12,
      "y": 7,
      "z": -17,
      "name": "Rock_Shale"
    },
    {
      "x": -12,
      "y": 8,
      "z": -17,
      "name": "Rock_Shale"
    },
    {
      "x": -12,
      "y": 13,
      "z": -17,
      "name": "Rock_Marble"
    },
    {
      "x": -12,
      "y": 14,
      "z": -17,
      "name": "Rock_Marble"
    },
    {
      "x": -12,
      "y": 15,
      "z": -17,
      "name": "Rock_Marble"
    },
    {
      "x": -12,
      "y": 16,
      "z": -17,
      "name": "Rock_Marble"
    },
    {
      "x": -12,
      "y": -7,
      "z": -16,
      "name": "Rock_Shale"
    },
    {
      "x": -12,
      "y": -6,
      "z": -16,
      "name": "Rock_Shale"
    },
    {
      "x": -12,
      "y": -5,
      "z": -16,
      "name": "Rock_Shale"
    },
    {
      "x": -12,
      "y": -4,
      "z": -16,
      "name": "Rock_Shale"
    },
    {
      "x": -12,
      "y": -3,
      "z": -16,
      "name": "Rock_Shale"
    },
    {
      "x": -12,
      "y": -2,
      "z": -16,
      "name": "Rock_Shale"
    },
    {
      "x": -12,
      "y": 3,
      "z": -16,
      "name": "Rock_Shale"
    },
    {
      "x": -12,
      "y": 4,
      "z": -16,
      "name": "Rock_Shale"
    },
    {
      "x": -12,
      "y": 5,
      "z": -16,
      "name": "Rock_Shale"
    },
    {
      "x": -12,
      "y": 6,
      "z": -16,
      "name": "Rock_Shale"
    },
    {
      "x": -12,
      "y": 7,
      "z": -16,
      "name": "Rock_Shale"
    },
    {
      "x": -12,
      "y": 8,
      "z": -16,
      "name": "Rock_Shale"
    },
    {
      "x": -12,
      "y": 13,
      "z": -16,
      "name": "Rock_Marble"
    },
    {
      "x": -12,
      "y": 14,
      "z": -16,
      "name": "Rock_Marble"
    },
    {
      "x": -12,
      "y": 15,
      "z": -16,
      "name": "Rock_Marble"
    },
    {
      "x": -12,
      "y": 16,
      "z": -16,
