{
  "version": 8,
  "blockIdVersion": 8,
  "anchorX": 6,
  "anchorY": 8,
  "anchorZ": 8,
  "blocks": [
    {
      "x": 3,
      "y": 14,
      "z": 7,
      "name": "Plant_Leaves_Beech"
    },
    {
      "x": 3,
      "y": 15,
      "z": 7,
      "name": "Plant_Leaves_Beech"
    },
    {
      "x": 3,
      "y": 13,
      "z": 8,
      "name": "Plant_Leaves_Beech"
    },
    {
      "x": 3,
      "y": 14,
      "z": 8,
      "name": "Plant_Leaves_Beech"
    },
    {
      "x": 3,
      "y": 15,
      "z": 8,
      "name": "Plant_Leaves_Beech"
    },
    {
      "x": 3,
      "y": 13,
      "z": 9,
      "name": "Plant_Leaves_Beech"
    },
    {
      "x": 3,
      "y": 14,
      "z": 9,
      "name": "Plant_Leaves_Beech"
    },
    {
      "x": 4,
      "y": 13,
      "z": 7,
      "name": "Plant_Leaves_Beech"
    },
    {
      "x": 4,
      "y": 14,
      "z": 7,
      "name": "Plant_Leaves_Beech"
    },
    {
      "x": 4,
      "y": 15,
      "z": 7,
      "name": "Plant_Leaves_Beech"
    },
    {
      "x": 4,
      "y": 16,
      "z": 7,
      "name": "Plant_Leaves_Beech"
    },
    {
      "x": 4,
      "y": 18,
      "z": 7,
      "name": "Plant_Leaves_Beech"
    },
    {
      "x": 4,
      "y": 14,
      "z": 8,
      "name": "Wood_Beech_Branch_Long",
      "rotation": 5
    },
    {
      "x": 4,
      "y": 15,
      "z": 8,
      "name": "Plant_Leaves_Beech"
    },
    {
      "x": 4,
      "y": 16,
      "z": 8,
      "name": "Plant_Leaves_Beech"
    },
    {
      "x": 4,
      "y": 18,
      "z": 8,
      "name": "Plant_Leaves_Beech"
    },
    {
      "x": 4,
      "y": 19,
      "z": 8,
      "name": "Plant_Leaves_Beech"
    },
    {
      "x": 4,
      "y": 13,
      "z": 9,
      "name": "Plant_Leaves_Beech"
    },
    {
      "x": 4,
      "y": 14,
      "z": 9,
      "name": "Plant_Leaves_Beech"
    },
    {
      "x": 4,
      "y": 15,
      "z": 9,
      "name": "Plant_Leaves_Beech"
    },
    {
      "x": 4,
      "y": 16,
      "z": 9,
      "name": "Plant_Leaves_Beech"
    },
    {
      "x": 4,
      "y": 17,
      "z": 9,
      "name": "Plant_Leaves_Beech"
    },
    {
      "x": 4,
      "y": 18,
      "z": 9,
      "name": "Plant_Leaves_Beech"
    },
    {
      "x": 4,
      "y": 19,
      "z": 9,
      "name": "Plant_Leaves_Beech"
    },
    {
      "x": 4,
      "y": 14,
      "z": 10,
      "name": "Plant_Leaves_Beech"
    },
    {
      "x": 4,
      "y": 15,
      "z": 10,
      "name": "Plant_Leaves_Beech"
    },
    {
      "x": 4,
      "y": 17,
      "z": 10,
      "name": "Plant_Leaves_Beech"
    },
    {
      "x": 4,
      "y": 14,
      "z": 11,
      "name": "Plant_Leaves_Beech"
    },
    {
      "x": 5,
      "y": 12,
      "z": 5,
      "name": "Plant_Leaves_Beech"
    },
    {
      "x": 5,
      "y": 13,
      "z": 5,
      "name": "Plant_Leaves_Beech"
    },
    {
      "x": 5,
      "y": 14,
      "z": 5,
      "name": "Plant_Leaves_Beech"
    },
    {
      "x": 5,
      "y": 12,
      "z": 6,
      "name": "Plant_Leaves_Beech"
    },
    {
      "x": 5,
      "y": 13,
      "z": 6,
      "name": "Plant_Leaves_Beech"
    },
    {
      "x": 5,
      "y": 14,
      "z": 6,
      "name": "Plant_Leaves_Beech"
    },
    {
      "x": 5,
      "y": 15,
      "z": 6,
      "name": "Plant_Leaves_Beech"
    },
    {
      "x": 5,
      "y": 16,
      "z": 6,
      "name": "Plant_Leaves_Beech"
    },
    {
      "x": 5,
      "y": 18,
      "z": 6,
      "name": "Plant_Leaves_Beech"
    },
    {
      "x": 5,
      "y": 19,
      "z": 7,
      "name": "Plant_Leaves_Beech"
    },
    {
      "x": 5,
      "y": 14,
      "z": 8,
      "name": "Wood_Beech_Trunk_Full"
    },
    {
      "x": 5,
      "y": 19,
      "z": 8,
      "name": "Plant_Leaves_Beech"
    },
    {
      "x": 5,
      "y": 20,
      "z": 8,
      "name": "Plant_Leaves_Beech"
    },
    {
      "x": 5,
      "y": 19,
      "z": 9,
      "name": "Plant_Leaves_Beech"
    },
    {
      "x": 5,
      "y": 14,
      "z": 10,
      "name": "Plant_Leaves_Beech"
    },
    {
      "x": 5,
      "y": 15,
      "z": 10,
      "name": "Plant_Leaves_Beech"
    },
    {
      "x": 5,
      "y": 16,
      "z": 10,
      "name": "Plant_Leaves_Beech"
    },
    {
      "x": 5,
      "y": 17,
      "z": 10,
      "name": "Plant_Leaves_Beech"
    },
    {
      "x": 5,
      "y": 18,
      "z": 10,
      "name": "Plant_Leaves_Beech"
    },
    {
      "x": 5,
      "y": 14,
      "z": 11,
      "name": "Plant_Leaves_Beech"
    },
    {
      "x": 5,
      "y": 15,
      "z": 11,
      "name": "Plant_Leaves_Beech"
    },
    {
      "x": 5,
      "y": 16,
      "z": 11,
      "name": "Plant_Leaves_Beech"
    },
    {
      "x": 5,
      "y": 17,
      "z": 11,
      "name": "Plant_Leaves_Beech"
    },
    {
      "x": 5,
      "y": 18,
      "z": 11,
      "name": "Plant_Leaves_Beech"
    },
    {
      "x": 6,
      "y": 12,
      "z": 5,
      "name": "Plant_Leaves_Beech"
    },
    {
      "x": 6,
      "y": 13,
      "z": 5,
      "name": "Plant_Leaves_Beech"
    },
    {
      "x": 6,
      "y": 14,
      "z": 5,
      "name": "Plant_Leaves_Beech"
    },
    {
      "x": 6,
      "y": 15,
      "z": 5,
      "name": "Plant_Leaves_Beech"
    },
    {
      "x": 6,
      "y": 13,
      "z": 6,
      "name": "Wood_Beech_Branch_Long",
      "rotation": 4
    },
    {
      "x": 6,
      "y": 14,
      "z": 6,
      "name": "Plant_Leaves_Beech"
    },
    {
      "x": 6,
      "y": 15,
      "z": 6,
      "name": "Plant_Leaves_Beech"
    },
    {
      "x": 6,
      "y": 16,
      "z": 6,
      "name": "Plant_Leaves_Beech"
    },
    {
      "x": 6,
      "y": 17,
      "z": 6,
      "name": "Plant_Leaves_Beech"
    },
    {
      "x": 6,
      "y": 18,
      "z": 6,
      "name": "Plant_Leaves_Beech"
    },
    {
      "x": 6,
      "y": 13,
      "z": 7,
      "name": "Wood_Beech_Trunk_Full"
    },
    {
      "x": 6,
      "y": 17,
      "z": 7,
      "name": "Wood_Beech_Branch_Corner",
      "rotation": 2
    },
    {
      "x": 6,
      "y": 18,
      "z": 7,
      "name": "Wood_Beech_Branch_Corner",
      "rotation": 10
    },
    {
      "x": 6,
      "y": 19,
      "z": 7,
      "name": "Plant_Leaves_Beech"
    },
    {
      "x": 6,
      "y": 6,
      "z": 8,
      "name": "Wood_Beech_Trunk"
    },
    {
      "x": 6,
      "y": 7,
      "z": 8,
      "name": "Wood_Beech_Trunk"
    },
    {
      "x": 6,
      "y": 8,
      "z": 8,
      "name": "Wood_Beech_Trunk"
    },
    {
      "x": 6,
      "y": 9,
      "z": 8,
      "name": "Wood_Beech_Trunk"
    },
    {
      "x": 6,
      "y": 10,
      "z": 8,
      "name": "Wood_Beech_Trunk"
    },
    {
      "x": 6,
      "y": 11,
      "z": 8,
      "name": "Wood_Beech_Trunk"
    },
    {
      "x": 6,
      "y": 12,
      "z": 8,
      "name": "Wood_Beech_Trunk"
    },
    {
      "x": 6,
      "y": 13,
      "z": 8,
      "name": "Wood_Beech_Trunk"
    },
    {
      "x": 6,
      "y": 14,
      "z": 8,
      "name": "Wood_Beech_Trunk"
    },
    {
      "x": 6,
      "y": 15,
      "z": 8,
      "name": "Wood_Beech_Trunk"
    },
    {
      "x": 6,
      "y": 16,
      "z": 8,
      "name": "Wood_Beech_Trunk"
    },
    {
      "x": 6,
      "y": 17,
      "z": 8,
      "name": "Wood_Beech_Trunk_Full"
    },
    {
      "x": 6,
      "y": 18,
      "z": 8,
      "name": "Wood_Beech_Branch_Long"
    },
    {
      "x": 6,
      "y": 19,
      "z": 8,
      "name": "Wood_Beech_Branch_Long"
    },
    {
      "x": 6,
      "y": 20,
      "z": 8,
      "name": "Plant_Leaves_Beech"
    },
    {
      "x": 6,
      "y": 14,
      "z": 9,
      "name": "Wood_Beech_Trunk_Full"
    },
    {
      "x": 6,
      "y": 17,
      "z": 9,
      "name": "Wood_Beech_Branch_Corner"
    },
    {
      "x": 6,
      "y": 18,
      "z": 9,
      "name": "Wood_Beech_Branch_Corner",
      "rotation": 8
    },
    {
      "x": 6,
      "y": 19,
      "z": 9,
      "name": "Plant_Leaves_Beech"
    },
    {
      "x": 6,
      "y": 20,
      "z": 9,
      "name": "Plant_Leaves_Beech"
    },
    {
      "x": 6,
      "y": 14,
      "z": 10,
      "name": "Wood_Beech_Branch_Long",
      "rotation": 4
    },
    {
      "x": 6,
      "y": 15,
      "z": 10,
      "name": "Plant_Leaves_Beech"
    },
    {
      "x": 6,
      "y": 16,
      "z": 10,
      "name": "Plant_Leaves_Beech"
    },
    {
      "x": 6,
      "y": 17,
      "z": 10,
      "name": "Plant_Leaves_Beech"
    },
    {
      "x": 6,
      "y": 18,
      "z": 10,
      "name": "Wood_Beech_Branch_Long",
      "rotation": 4
    },
    {
      "x": 6,
      "y": 19,
      "z": 10,
      "name": "Plant_Leaves_Beech"
    },
    {
      "x": 6,
      "y": 14,
      "z": 11,
      "name": "Plant_Leaves_Beech"
    },
    {
      "x": 6,
      "y": 15,
      "z": 11,
      "name": "Plant_Leaves_Beech"
    },
    {
      "x": 6,
      "y": 16,
      "z": 11,
      "name": "Plant_Leaves_Beech"
    },
    {
      "x": 6,
      "y": 17,
      "z": 11,
      "name": "Plant_Leaves_Beech"
    },
    {
      "x": 6,
      "y": 18,
      "z": 11,
      "name": "Plant_Leaves_Beech"
    },
    {
      "x": 7,
      "y": 13,
      "z": 5,
      "name": "Plant_Leaves_Beech"
    },
    {
      "x": 7,
      "y": 14,
      "z": 5,
      "name": "Plant_Leaves_Beech"
    },
    {
      "x": 7,
      "y": 12,
      "z": 6,
      "name": "Plant_Leaves_Beech"
    },
    {
      "x": 7,
      "y": 13,
      "z": 6,
      "name": "Plant_Leaves_Beech"
    },
    {
      "x": 7,
      "y": 14,
      "z": 6,
      "name": "Plant_Leaves_Beech"
    },
    {
      "x": 7,
      "y": 15,
      "z": 6,
      "name": "Plant_Leaves_Beech"
    },
    {
      "x": 7,
      "y": 17,
      "z": 6,
      "name": "Plant_Leaves_Beech"
    },
    {
      "x": 7,
      "y": 18,
      "z": 6,
      "name": "Plant_Leaves_Beech"
    },
    {
      "x": 7,
      "y": 19,
      "z": 7,
      "name": "Plant_Leaves_Beech"
    },
    {
      "x": 7,
      "y": 13,
      "z": 8,
      "name": "Wood_Beech_Trunk_Full"
    },
    {
      "x": 7,
      "y": 19,
      "z": 8,
      "name": "Plant_Leaves_Beech"
    },
    {
      "x": 7,
      "y": 20,
      "z": 8,
      "name": "Plant_Leaves_Beech"
    },
    {
      "x": 7,
      "y": 19,
      "z": 9,
      "name": "Plant_Leaves_Beech"
    },
    {
      "x": 7,
      "y": 20,
      "z": 9,
      "name": "Plant_Leaves_Beech"
    },
    {
      "x": 7,
      "y": 13,
      "z": 10,
      "name": "Plant_Leaves_Beech"
    },
    {
      "x": 7,
      "y": 14,
      "z": 10,
      "name": "Plant_Leaves_Beech"
    },
    {
      "x": 7,
      "y": 15,
      "z": 10,
      "name": "Plant_Leaves_Beech"
    },
    {
      "x": 7,
      "y": 16,
      "z": 10,
      "name": "Plant_Leaves_Beech"
    },
    {
      "x": 7,
      "y": 18,
      "z": 10,
      "name": "Plant_Leaves_Beech"
    },
    {
      "x": 7,
      "y": 19,
      "z": 10,
      "name": "Plant_Leaves_Beech"
    },
    {
      "x": 7,
      "y": 14,
      "z": 11,
      "name": "Plant_Leaves_Beech"
    },
    {
      "x": 7,
      "y": 15,
      "z": 11,
      "name": "Plant_Leaves_Beech"
    },
    {
      "x": 8,
      "y": 13,
      "z": 6,
      "name": "Plant_Leaves_Beech"
    },
    {
      "x": 8,
      "y": 13,
      "z": 7,
      "name": "Plant_Leaves_Beech"
    },
    {
      "x": 8,
      "y": 14,
      "z": 7,
      "name": "Plant_Leaves_Beech"
    },
    {
      "x": 8,
      "y": 15,
      "z": 7,
      "name": "Plant_Leaves_Beech"
    },
    {
      "x": 8,
      "y": 17,
      "z": 7,
      "name": "Plant_Leaves_Beech"
    },
    {
      "x": 8,
      "y": 13,
      "z": 8,
      "name": "Wood_Beech_Branch_Long",
      "rotation": 5
    },
    {
      "x": 8,
      "y": 14,
      "z": 8,
      "name": "Plant_Leaves_Beech"
    },
    {
      "x": 8,
      "y": 15,
      "z": 8,
      "name": "Plant_Leaves_Beech"
    },
    {
      "x": 8,
      "y": 17,
      "z": 8,
      "name": "Plant_Leaves_Beech"
    },
    {
      "x": 8,
      "y": 18,
      "z": 8,
      "name": "Plant_Leaves_Beech"
    },
    {
      "x": 8,
      "y": 19,
      "z": 8,
      "name": "Plant_Leaves_Beech"
    },
    {
      "x": 8,
      "y": 13,
      "z": 9,
      "name": "Plant_Leaves_Beech"
    },
    {
      "x": 8,
      "y": 14,
      "z": 9,
      "name": "Plant_Leaves_Beech"
    },
    {
      "x": 8,
      "y": 15,
      "z": 9,
      "name": "Plant_Leaves_Beech"
    },
    {
      "x": 8,
      "y": 16,
      "z": 9,
      "name": "Plant_Leaves_Beech"
    },
    {
      "x": 8,
      "y": 18,
      "z": 9,
      "name": "Plant_Leaves_Beech"
    },
    {
      "x": 8,
      "y": 19,
      "z": 9,
      "name": "Plant_Leaves_Beech"
    },
    {
      "x": 8,
      "y": 13,
      "z": 10,
      "name": "Plant_Leaves_Beech"
    },
    {
      "x": 8,
      "y": 14,
      "z": 10,
      "name": "Plant_Leaves_Beech"
    },
    {
      "x": 9,
      "y": 13,
      "z": 7,
      "name": "Plant_Leaves_Beech"
    },
    {
      "x": 9,
      "y": 14,
      "z": 7,
      "name": "Plant_Leaves_Beech"
    },
    {
      "x": 9,
      "y": 13,
      "z": 8,
      "name": "Plant_Leaves_Beech"
    },
    {
      "x": 9,
      "y": 14,
      "z": 8,
      "name": "Plant_Leaves_Beech"
    },
    {
      "x": 9,
      "y": 15,
      "z": 8,
      "name": "Plant_Leaves_Beech"
    },
    {
      "x": 9,
      "y": 13,
      "z": 9,
      "name": "Plant_Leaves_Beech"
    },
    {
      "x": 9,
      "y": 14,
      "z": 9,
      "name": "Plant_Leaves_Beech"
    },
    {
      "x": 9,
      "y": 15,
      "z": 9,
      "name": "Plant_Leaves_Beech"
    },
    {
      "x": 9,
      "y": 13,
      "z": 10,
      "name": "Plant_Leaves_Beech"
    }
  ]
}