{
  "version": 8,
  "blockIdVersion": 8,
  "anchorX": 11,
  "anchorY": 9,
  "anchorZ": 7,
  "blocks": [
    {
      "x": 7,
      "y": 7,
      "z": 6,
      "name": "Rock_Shale"
    },
    {
      "x": 7,
      "y": 8,
      "z": 6,
      "name": "Rock_Shale"
    },
    {
      "x": 7,
      "y": 9,
      "z": 6,
      "name": "Rock_Shale"
    },
    {
      "x": 7,
      "y": 10,
      "z": 6,
      "name": "Soil_Snow"
    },
    {
      "x": 8,
      "y": 8,
      "z": 5,
      "name": "Rock_Shale"
    },
    {
      "x": 8,
      "y": 9,
      "z": 5,
      "name": "Rock_Shale"
    },
    {
      "x": 8,
      "y": 10,
      "z": 5,
      "name": "Rock_Shale"
    },
    {
      "x": 8,
      "y": 11,
      "z": 5,
      "name": "Soil_Snow"
    },
    {
      "x": 8,
      "y": 12,
      "z": 5,
      "name": "Soil_Snow"
    },
    {
      "x": 8,
      "y": 7,
      "z": 6,
      "name": "Rock_Shale"
    },
    {
      "x": 8,
      "y": 8,
      "z": 6,
      "name": "Rock_Shale"
    },
    {
      "x": 8,
      "y": 9,
      "z": 6,
      "name": "Rock_Shale"
    },
    {
      "x": 8,
      "y": 10,
      "z": 6,
      "name": "Soil_Snow"
    },
    {
      "x": 8,
      "y": 11,
      "z": 6,
      "name": "Soil_Snow"
    },
    {
      "x": 9,
      "y": 14,
      "z": 7,
      "name": "Rock_Shale"
    },
    {
      "x": 9,
      "y": 15,
      "z": 7,
      "name": "Rock_Shale"
    },
    {
      "x": 9,
      "y": 16,
      "z": 7,
      "name": "Rock_Shale"
    },
    {
      "x": 9,
      "y": 17,
      "z": 7,
      "name": "Rock_Shale"
    },
    {
      "x": 9,
      "y": 18,
      "z": 7,
      "name": "Soil_Snow"
    },
    {
      "x": 9,
      "y": 19,
      "z": 7,
      "name": "Soil_Snow"
    },
    {
      "x": 9,
      "y": 13,
      "z": 8,
      "name": "Rock_Shale"
    },
    {
      "x": 9,
      "y": 14,
      "z": 8,
      "name": "Rock_Shale"
    },
    {
      "x": 9,
      "y": 15,
      "z": 8,
      "name": "Rock_Shale"
    },
    {
      "x": 9,
      "y": 16,
      "z": 8,
      "name": "Rock_Shale"
    },
    {
      "x": 9,
      "y": 17,
      "z": 8,
      "name": "Rock_Shale"
    },
    {
      "x": 9,
      "y": 18,
      "z": 8,
      "name": "Rock_Shale"
    },
    {
      "x": 9,
      "y": 19,
      "z": 8,
      "name": "Soil_Snow"
    },
    {
      "x": 9,
      "y": 20,
      "z": 8,
      "name": "Soil_Snow"
    },
    {
      "x": 9,
      "y": 13,
      "z": 9,
      "name": "Rock_Shale"
    },
    {
      "x": 9,
      "y": 14,
      "z": 9,
      "name": "Rock_Shale"
    },
    {
      "x": 9,
      "y": 15,
      "z": 9,
      "name": "Rock_Shale"
    },
    {
      "x": 9,
      "y": 16,
      "z": 9,
      "name": "Rock_Shale"
    },
    {
      "x": 9,
      "y": 17,
      "z": 9,
      "name": "Rock_Shale"
    },
    {
      "x": 9,
      "y": 18,
      "z": 9,
      "name": "Rock_Shale"
    },
    {
      "x": 9,
      "y": 19,
      "z": 9,
      "name": "Soil_Snow"
    },
    {
      "x": 9,
      "y": 20,
      "z": 9,
      "name": "Soil_Snow"
    },
    {
      "x": 9,
      "y": 16,
      "z": 10,
      "name": "Rock_Shale"
    },
    {
      "x": 9,
      "y": 17,
      "z": 10,
      "name": "Rock_Shale"
    },
    {
      "x": 9,
      "y": 18,
      "z": 10,
      "name": "Soil_Snow"
    },
    {
      "x": 10,
      "y": 7,
      "z": 6,
      "name": "Rock_Shale"
    },
    {
      "x": 10,
      "y": 8,
      "z": 6,
      "name": "Rock_Shale"
    },
    {
      "x": 10,
      "y": 9,
      "z": 6,
      "name": "Rock_Shale"
    },
    {
      "x": 10,
      "y": 10,
      "z": 6,
      "name": "Rock_Shale"
    },
    {
      "x": 10,
      "y": 11,
      "z": 6,
      "name": "Rock_Shale"
    },
    {
      "x": 10,
      "y": 12,
      "z": 6,
      "name": "Rock_Shale"
    },
    {
      "x": 10,
      "y": 13,
      "z": 6,
      "name": "Rock_Shale"
    },
    {
      "x": 10,
      "y": 14,
      "z": 6,
      "name": "Rock_Shale"
    },
    {
      "x": 10,
      "y": 15,
      "z": 6,
      "name": "Soil_Snow"
    },
    {
      "x": 10,
      "y": 16,
      "z": 6,
      "name": "Soil_Snow"
    },
    {
      "x": 10,
      "y": 17,
      "z": 6,
      "name": "Soil_Snow"
    },
    {
      "x": 10,
      "y": 6,
      "z": 7,
      "name": "Rock_Shale"
    },
    {
      "x": 10,
      "y": 7,
      "z": 7,
      "name": "Rock_Shale"
    },
    {
      "x": 10,
      "y": 8,
      "z": 7,
      "name": "Rock_Shale"
    },
    {
      "x": 10,
      "y": 9,
      "z": 7,
      "name": "Rock_Shale"
    },
    {
      "x": 10,
      "y": 10,
      "z": 7,
      "name": "Rock_Shale"
    },
    {
      "x": 10,
      "y": 11,
      "z": 7,
      "name": "Rock_Shale"
    },
    {
      "x": 10,
      "y": 12,
      "z": 7,
      "name": "Rock_Shale"
    },
    {
      "x": 10,
      "y": 13,
      "z": 7,
      "name": "Rock_Shale"
    },
    {
      "x": 10,
      "y": 14,
      "z": 7,
      "name": "Rock_Shale"
    },
    {
      "x": 10,
      "y": 15,
      "z": 7,
      "name": "Rock_Shale"
    },
    {
      "x": 10,
      "y": 16,
      "z": 7,
      "name": "Rock_Shale"
    },
    {
      "x": 10,
      "y": 17,
      "z": 7,
      "name": "Rock_Shale"
    },
    {
      "x": 10,
      "y": 18,
      "z": 7,
      "name": "Rock_Shale"
    },
    {
      "x": 10,
      "y": 19,
      "z": 7,
      "name": "Soil_Snow"
    },
    {
      "x": 10,
      "y": 6,
      "z": 8,
      "name": "Rock_Shale"
    },
    {
      "x": 10,
      "y": 7,
      "z": 8,
      "name": "Rock_Shale"
    },
    {
      "x": 10,
      "y": 8,
      "z": 8,
      "name": "Rock_Shale"
    },
    {
      "x": 10,
      "y": 9,
      "z": 8,
      "name": "Rock_Shale"
    },
    {
      "x": 10,
      "y": 10,
      "z": 8,
      "name": "Rock_Shale"
    },
    {
      "x": 10,
      "y": 11,
      "z": 8,
      "name": "Rock_Shale"
    },
    {
      "x": 10,
      "y": 12,
      "z": 8,
      "name": "Rock_Shale"
    },
    {
      "x": 10,
      "y": 13,
      "z": 8,
      "name": "Rock_Shale"
    },
    {
      "x": 10,
      "y": 14,
      "z": 8,
      "name": "Rock_Shale"
    },
    {
      "x": 10,
      "y": 15,
      "z": 8,
      "name": "Rock_Shale"
    },
    {
      "x": 10,
      "y": 16,
      "z": 8,
      "name": "Rock_Shale"
    },
    {
      "x": 10,
      "y": 17,
      "z": 8,
      "name": "Rock_Shale"
    },
    {
      "x": 10,
      "y": 18,
      "z": 8,
      "name": "Rock_Shale"
    },
    {
      "x": 10,
      "y": 19,
      "z": 8,
      "name": "Soil_Snow"
    },
    {
      "x": 10,
      "y": 20,
      "z": 8,
      "name": "Soil_Snow"
    },
    {
      "x": 10,
      "y": 8,
      "z": 9,
      "name": "Rock_Shale"
    },
    {
      "x": 10,
      "y": 9,
      "z": 9,
      "name": "Rock_Shale"
    },
    {
      "x": 10,
      "y": 10,
      "z": 9,
      "name": "Rock_Shale"
    },
    {
      "x": 10,
      "y": 11,
      "z": 9,
      "name": "Rock_Shale"
    },
    {
      "x": 10,
      "y": 12,
      "z": 9,
      "name": "Rock_Shale"
    },
    {
      "x": 10,
      "y": 13,
      "z": 9,
      "name": "Rock_Shale"
    },
    {
      "x": 10,
      "y": 14,
      "z": 9,
      "name": "Rock_Shale"
    },
    {
      "x": 10,
      "y": 15,
      "z": 9,
      "name": "Rock_Shale"
    },
    {
      "x": 10,
      "y": 16,
      "z": 9,
      "name": "Rock_Shale"
    },
    {
      "x": 10,
      "y": 17,
      "z": 9,
      "name": "Rock_Shale"
    },
    {
      "x": 10,
      "y": 18,
      "z": 9,
      "name": "Rock_Shale"
    },
    {
      "x": 10,
      "y": 19,
      "z": 9,
      "name": "Soil_Snow"
    },
    {
      "x": 10,
      "y": 20,
      "z": 9,
      "name": "Soil_Snow"
    },
    {
      "x": 10,
      "y": 15,
      "z": 10,
      "name": "Rock_Shale"
    },
    {
      "x": 10,
      "y": 16,
      "z": 10,
      "name": "Rock_Shale"
    },
    {
      "x": 10,
      "y": 17,
      "z": 10,
      "name": "Rock_Shale"
    },
    {
      "x": 10,
      "y": 18,
      "z": 10,
      "name": "Rock_Shale"
    },
    {
      "x": 10,
      "y": 19,
      "z": 10,
      "name": "Soil_Snow"
    },
    {
      "x": 10,
      "y": 20,
      "z": 10,
      "name": "Soil_Snow"
    },
    {
      "x": 11,
      "y": 6,
      "z": 6,
      "name": "Rock_Shale"
    },
    {
      "x": 11,
      "y": 7,
      "z": 6,
      "name": "Rock_Shale"
    },
    {
      "x": 11,
      "y": 8,
      "z": 6,
      "name": "Rock_Shale"
    },
    {
      "x": 11,
      "y": 9,
      "z": 6,
      "name": "Rock_Shale"
    },
    {
      "x": 11,
      "y": 10,
      "z": 6,
      "name": "Rock_Shale"
    },
    {
      "x": 11,
      "y": 11,
      "z": 6,
      "name": "Rock_Shale"
    },
    {
      "x": 11,
      "y": 12,
      "z": 6,
      "name": "Rock_Shale"
    },
    {
      "x": 11,
      "y": 13,
      "z": 6,
      "name": "Rock_Shale"
    },
    {
      "x": 11,
      "y": 14,
      "z": 6,
      "name": "Rock_Shale"
    },
    {
      "x": 11,
      "y": 15,
      "z": 6,
      "name": "Rock_Shale"
    },
    {
      "x": 11,
      "y": 16,
      "z": 6,
      "name": "Rock_Shale"
    },
    {
      "x": 11,
      "y": 17,
      "z": 6,
      "name": "Soil_Snow"
    },
    {
      "x": 11,
      "y": 18,
      "z": 6,
      "name": "Soil_Snow"
    },
    {
      "x": 11,
      "y": 6,
      "z": 7,
      "name": "Rock_Shale"
    },
    {
      "x": 11,
      "y": 7,
      "z": 7,
      "name": "Rock_Shale"
    },
    {
      "x": 11,
      "y": 8,
      "z": 7,
      "name": "Rock_Shale"
    },
    {
      "x": 11,
      "y": 9,
      "z": 7,
      "name": "Rock_Shale"
    },
    {
      "x": 11,
      "y": 10,
      "z": 7,
      "name": "Rock_Ice_Permafrost"
    },
    {
      "x": 11,
      "y": 11,
      "z": 7,
      "name": "Rock_Ice_Permafrost"
    },
    {
      "x": 11,
      "y": 12,
      "z": 7,
      "name": "Rock_Ice_Permafrost"
    },
    {
      "x": 11,
      "y": 13,
      "z": 7,
      "name": "Rock_Ice_Permafrost"
    },
    {
      "x": 11,
      "y": 14,
      "z": 7,
      "name": "Rock_Ice_Permafrost"
    },
    {
      "x": 11,
      "y": 15,
      "z": 7,
      "name": "Rock_Ice_Permafrost"
    },
    {
      "x": 11,
      "y": 16,
      "z": 7,
      "name": "Rock_Ice_Permafrost"
    },
    {
      "x": 11,
      "y": 17,
      "z": 7,
      "name": "Rock_Shale"
    },
    {
      "x": 11,
      "y": 18,
      "z": 7,
      "name": "Rock_Shale"
    },
    {
      "x": 11,
      "y": 19,
      "z": 7,
      "name": "Soil_Snow"
    },
    {
      "x": 11,
      "y": 6,
      "z": 8,
      "name": "Rock_Shale"
    },
    {
      "x": 11,
      "y": 7,
      "z": 8,
      "name": "Rock_Shale"
    },
    {
      "x": 11,
      "y": 8,
      "z": 8,
      "name": "Rock_Shale"
    },
    {
      "x": 11,
      "y": 9,
      "z": 8,
      "name": "Rock_Shale"
    },
    {
      "x": 11,
      "y": 10,
      "z": 8,
      "name": "Rock_Ice_Permafrost"
    },
    {
      "x": 11,
      "y": 11,
      "z": 8,
      "name": "Rock_Ice_Permafrost"
    },
    {
      "x": 11,
      "y": 12,
      "z": 8,
      "name": "Rock_Ice_Permafrost"
    },
    {
      "x": 11,
      "y": 13,
      "z": 8,
      "name": "Rock_Ice_Permafrost"
    },
    {
      "x": 11,
      "y": 14,
      "z": 8,
      "name": "Rock_Ice_Permafrost"
    },
    {
      "x": 11,
      "y": 15,
      "z": 8,
      "name": "Rock_Ice_Permafrost"
    },
    {
      "x": 11,
      "y": 16,
      "z": 8,
      "name": "Rock_Ice_Permafrost"
    },
    {
      "x": 11,
      "y": 17,
      "z": 8,
      "name": "Rock_Ice_Permafrost"
    },
    {
      "x": 11,
      "y": 18,
      "z": 8,
      "name": "Rock_Shale"
    },
    {
      "x": 11,
      "y": 19,
      "z": 8,
      "name": "Soil_Snow"
    },
    {
      "x": 11,
      "y": 20,
      "z": 8,
      "name": "Soil_Snow"
    },
    {
      "x": 11,
      "y": 6,
      "z": 9,
      "name": "Rock_Shale"
    },
    {
      "x": 11,
      "y": 7,
      "z": 9,
      "name": "Rock_Shale"
    },
    {
      "x": 11,
      "y": 8,
      "z": 9,
      "name": "Rock_Shale"
    },
    {
      "x": 11,
      "y": 9,
      "z": 9,
      "name": "Rock_Shale"
    },
    {
      "x": 11,
      "y": 10,
      "z": 9,
      "name": "Rock_Shale"
    },
    {
      "x": 11,
      "y": 11,
      "z": 9,
      "name": "Rock_Shale"
    },
    {
      "x": 11,
      "y": 12,
      "z": 9,
      "name": "Rock_Ice_Permafrost"
    },
    {
      "x": 11,
      "y": 13,
      "z": 9,
      "name": "Rock_Ice_Permafrost"
    },
    {
      "x": 11,
      "y": 14,
      "z": 9,
      "name": "Rock_Ice_Permafrost"
    },
    {
      "x": 11,
      "y": 15,
      "z": 9,
      "name": "Rock_Ice_Permafrost"
    },
    {
      "x": 11,
      "y": 16,
      "z": 9,
      "name": "Rock_Ice_Permafrost"
    },
    {
      "x": 11,
      "y": 17,
      "z": 9,
      "name": "Rock_Ice_Permafrost"
    },
    {
      "x": 11,
      "y": 18,
      "z": 9,
      "name": "Rock_Shale"
    },
    {
      "x": 11,
      "y": 19,
      "z": 9,
      "name": "Soil_Snow"
    },
    {
      "x": 11,
      "y": 20,
      "z": 9,
      "name": "Soil_Snow"
    },
    {
      "x": 11,
      "y": 12,
      "z": 10,
      "name": "Rock_Shale"
    },
    {
      "x": 11,
      "y": 13,
      "z": 10,
      "name": "Rock_Shale"
    },
    {
      "x": 11,
      "y": 14,
      "z": 10,
      "name": "Rock_Shale"
    },
    {
      "x": 11,
      "y": 15,
      "z": 10,
      "name": "Rock_Shale"
    },
    {
      "x": 11,
      "y": 16,
      "z": 10,
      "name": "Rock_Shale"
    },
    {
      "x": 11,
      "y": 17,
      "z": 10,
      "name": "Rock_Shale"
    },
    {
      "x": 11,
      "y": 18,
      "z": 10,
      "name": "Rock_Shale"
    },
    {
      "x": 11,
      "y": 19,
      "z": 10,
      "name": "Soil_Snow"
    },
    {
      "x": 11,
      "y": 20,
      "z": 10,
      "name": "Soil_Snow"
    },
    {
      "x": 12,
      "y": 6,
      "z": 6,
      "name": "Rock_Shale"
    },
    {
      "x": 12,
      "y": 7,
      "z": 6,
      "name": "Rock_Shale"
    },
    {
      "x": 12,
      "y": 8,
      "z": 6,
      "name": "Rock_Shale"
    },
    {
      "x": 12,
      "y": 9,
      "z": 6,
      "name": "Rock_Shale"
    },
    {
      "x": 12,
      "y": 10,
      "z": 6,
      "name": "Rock_Shale"
    },
    {
      "x": 12,
      "y": 11,
      "z": 6,
      "name": "Rock_Shale"
    },
    {
      "x": 12,
      "y": 12,
      "z": 6,
      "name": "Rock_Shale"
    },
    {
      "x": 12,
      "y": 13,
      "z": 6,
      "name": "Rock_Shale"
    },
    {
      "x": 12,
      "y": 14,
      "z": 6,
      "name": "Rock_Shale"
    },
    {
      "x": 12,
      "y": 15,
      "z": 6,
      "name": "Rock_Shale"
    },
    {
      "x": 12,
      "y": 16,
      "z": 6,
      "name": "Rock_Shale"
    },
    {
      "x": 12,
      "y": 17,
      "z": 6,
      "name": "Soil_Snow"
    },
    {
      "x": 12,
      "y": 18,
      "z": 6,
      "name": "Soil_Snow"
    },
    {
      "x": 12,
      "y": 6,
      "z": 7,
      "name": "Rock_Shale"
    },
    {
      "x": 12,
      "y": 7,
      "z": 7,
      "name": "Rock_Shale"
    },
    {
      "x": 12,
      "y": 8,
      "z": 7,
      "name": "Rock_Shale"
    },
    {
      "x": 12,
      "y": 9,
      "z": 7,
      "name": "Rock_Shale"
    },
    {
      "x": 12,
      "y": 10,
      "z": 7,
      "name": "Rock_Shale"
    },
    {
      "x": 12,
      "y": 11,
      "z": 7,
      "name": "Rock_Shale"
    },
    {
      "x": 12,
      "y": 12,
      "z": 7,
      "name": "Rock_Shale"
    },
    {
      "x": 12,
      "y": 13,
      "z": 7,
      "name": "Rock_Shale"
    },
    {
      "x": 12,
      "y": 14,
      "z": 7,
      "name": "Rock_Shale"
    },
    {
      "x": 12,
      "y": 15,
      "z": 7,
      "name": "Rock_Shale"
    },
    {
      "x": 12,
      "y": 16,
      "z": 7,
      "name": "Rock_Shale"
    },
    {
      "x": 12,
      "y": 17,
      "z": 7,
      "name": "Rock_Shale"
    },
    {
      "x": 12,
      "y": 18,
      "z": 7,
      "name": "Rock_Shale"
    },
    {
      "x": 12,
      "y": 19,
      "z": 7,
      "name": "Soil_Snow"
    },
    {
      "x": 12,
      "y": 6,
      "z": 8,
      "name": "Rock_Shale"
    },
    {
      "x": 12,
      "y": 7,
      "z": 8,
      "name": "Rock_Shale"
    },
    {
      "x": 12,
      "y": 8,
      "z": 8,
      "name": "Rock_Shale"
    },
    {
      "x": 12,
      "y": 9,
      "z": 8,
      "name": "Rock_Shale"
    },
    {
      "x": 12,
      "y": 10,
      "z": 8,
      "name": "Rock_Ice_Permafrost"
    },
    {
      "x": 12,
      "y": 11,
      "z": 8,
      "name": "Rock_Ice_Permafrost"
    },
    {
      "x": 12,
      "y": 12,
      "z": 8,
      "name": "Rock_Ice_Permafrost"
    },
    {
      "x": 12,
      "y": 13,
      "z": 8,
      "name": "Rock_Ice_Permafrost"
    },
    {
      "x": 12,
      "y": 14,
      "z": 8,
      "name": "Rock_Ice_Permafrost"
    },
    {
      "x": 12,
      "y": 15,
      "z": 8,
      "name": "Rock_Ice_Permafrost"
    },
    {
      "x": 12,
      "y": 16,
      "z": 8,
      "name": "Rock_Shale"
    },
    {
      "x": 12,
      "y": 17,
      "z": 8,
      "name": "Rock_Shale"
    },
    {
      "x": 12,
      "y": 18,
      "z": 8,
      "name": "Rock_Shale"
    },
    {
      "x": 12,
      "y": 19,
      "z": 8,
      "name": "Soil_Snow"
    },
    {
      "x": 12,
      "y": 20,
      "z": 8,
      "name": "Soil_Snow"
    },
    {
      "x": 12,
      "y": 6,
      "z": 9,
      "name": "Rock_Shale"
    },
    {
      "x": 12,
      "y": 7,
      "z": 9,
      "name": "Rock_Shale"
    },
    {
      "x": 12,
      "y": 8,
      "z": 9,
      "name": "Rock_Shale"
    },
    {
      "x": 12,
      "y": 9,
      "z": 9,
      "name": "Rock_Shale"
    },
    {
      "x": 12,
      "y": 10,
      "z": 9,
      "name": "Rock_Shale"
    },
    {
      "x": 12,
      "y": 11,
      "z": 9,
      "name": "Rock_Shale"
    },
    {
      "x": 12,
      "y": 12,
      "z": 9,
      "name": "Rock_Shale"
    },
    {
      "x": 12,
      "y": 13,
      "z": 9,
      "name": "Rock_Shale"
    },
    {
      "x": 12,
      "y": 14,
      "z": 9,
      "name": "Rock_Shale"
    },
    {
      "x": 12,
      "y": 15,
      "z": 9,
      "name": "Rock_Shale"
    },
    {
      "x": 12,
      "y": 16,
      "z": 9,
      "name": "Rock_Shale"
    },
    {
      "x": 12,
      "y": 17,
      "z": 9,
      "name": "Rock_Shale"
    },
    {
      "x": 12,
      "y": 18,
      "z": 9,
      "name": "Rock_Shale"
    },
    {
      "x": 12,
      "y": 19,
      "z": 9,
      "name": "Soil_Snow"
    },
    {
      "x": 12,
      "y": 20,
      "z": 9,
      "name": "Soil_Snow"
    },
    {
      "x": 12,
      "y": 12,
      "z": 10,
      "name": "Rock_Shale"
    },
    {
      "x": 12,
      "y": 13,
      "z": 10,
      "name": "Rock_Shale"
    },
    {
      "x": 12,
      "y": 14,
      "z": 10,
      "name": "Rock_Shale"
    },
    {
      "x": 12,
      "y": 15,
      "z": 10,
      "name": "Rock_Shale"
    },
    {
      "x": 12,
      "y": 16,
      "z": 10,
      "name": "Rock_Shale"
    },
    {
      "x": 12,
      "y": 17,
      "z": 10,
      "name": "Rock_Shale"
    },
    {
      "x": 12,
      "y": 18,
      "z": 10,
      "name": "Soil_Snow"
    },
    {
      "x": 12,
      "y": 19,
      "z": 10,
      "name": "Soil_Snow"
    },
    {
      "x": 13,
      "y": 6,
      "z": 6,
      "name": "Rock_Shale"
    },
    {
      "x": 13,
      "y": 7,
      "z": 6,
      "name": "Rock_Shale"
    },
    {
      "x": 13,
      "y": 8,
      "z": 6,
      "name": "Rock_Shale"
    },
    {
      "x": 13,
      "y": 9,
      "z": 6,
      "name": "Rock_Shale"
    },
    {
      "x": 13,
      "y": 10,
      "z": 6,
      "name": "Rock_Shale"
    },
    {
      "x": 13,
      "y": 11,
      "z": 6,
      "name": "Rock_Shale"
    },
    {
      "x": 13,
      "y": 12,
      "z": 6,
      "name": "Rock_Shale"
    },
    {
      "x": 13,
      "y": 13,
      "z": 6,
      "name": "Rock_Shale"
    },
    {
      "x": 13,
      "y": 14,
      "z": 6,
      "name": "Soil_Snow"
    },
    {
      "x": 13,
      "y": 15,
      "z": 6,
      "name": "Soil_Snow"
    },
    {
      "x": 13,
      "y": 16,
      "z": 6,
      "name": "Soil_Snow"
    },
    {
      "x": 13,
      "y": 6,
      "z": 7,
      "name": "Rock_Shale"
    },
    {
      "x": 13,
      "y": 7,
      "z": 7,
      "name": "Rock_Shale"
    },
    {
      "x": 13,
      "y": 8,
      "z": 7,
      "name": "Rock_Shale"
    },
    {
      "x": 13,
      "y": 9,
      "z": 7,
      "name": "Rock_Shale"
    },
    {
      "x": 13,
      "y": 10,
      "z": 7,
      "name": "Rock_Shale"
    },
    {
      "x": 13,
      "y": 11,
      "z": 7,
      "name": "Rock_Shale"
    },
    {
      "x": 13,
      "y": 12,
      "z": 7,
      "name": "Rock_Shale"
    },
    {
      "x": 13,
      "y": 13,
      "z": 7,
      "name": "Rock_Shale"
    },
    {
      "x": 13,
      "y": 14,
      "z": 7,
      "name": "Rock_Shale"
    },
    {
      "x": 13,
      "y": 15,
      "z": 7,
      "name": "Rock_Shale"
    },
    {
      "x": 13,
      "y": 16,
      "z": 7,
      "name": "Soil_Snow"
    },
    {
      "x": 13,
      "y": 17,
      "z": 7,
      "name": "Soil_Snow"
    },
    {
      "x": 13,
      "y": 6,
      "z": 8,
      "name": "Rock_Shale"
    },
    {
      "x": 13,
      "y": 7,
      "z": 8,
      "name": "Rock_Shale"
    },
    {
      "x": 13,
      "y": 8,
      "z": 8,
      "name": "Rock_Shale"
    },
    {
      "x": 13,
      "y": 9,
      "z": 8,
      "name": "Rock_Shale"
    },
    {
      "x": 13,
      "y": 10,
      "z": 8,
      "name": "Rock_Shale"
    },
    {
      "x": 13,
      "y": 11,
      "z": 8,
      "name": "Rock_Shale"
    },
    {
      "x": 13,
      "y": 12,
      "z": 8,
      "name": "Rock_Shale"
    },
    {
      "x": 13,
      "y": 13,
      "z": 8,
      "name": "Rock_Shale"
    },
    {
      "x": 13,
      "y": 14,
      "z": 8,
      "name": "Rock_Shale"
    },
    {
      "x": 13,
      "y": 15,
      "z": 8,
      "name": "Rock_Shale"
    },
    {
      "x": 13,
      "y": 16,
      "z": 8,
      "name": "Soil_Snow"
    },
    {
      "x": 13,
      "y": 17,
      "z": 8,
      "name": "Soil_Snow"
    },
    {
      "x": 13,
      "y": 7,
      "z": 9,
      "name": "Rock_Shale"
    },
    {
      "x": 13,
      "y": 8,
      "z": 9,
      "name": "Rock_Shale"
    },
    {
      "x": 13,
      "y": 9,
      "z": 9,
      "name": "Rock_Shale"
    },
    {
      "x": 13,
      "y": 10,
      "z": 9,
      "name": "Rock_Shale"
    },
    {
      "x": 13,
      "y": 11,
      "z": 9,
      "name": "Rock_Shale"
    },
    {
      "x": 13,
      "y": 12,
      "z": 9,
      "name": "Rock_Shale"
    },
    {
      "x": 13,
      "y": 13,
      "z": 9,
      "name": "Rock_Shale"
    },
    {
      "x": 13,
      "y": 14,
      "z": 9,
      "name": "Rock_Shale"
    },
    {
      "x": 13,
      "y": 15,
      "z": 9,
      "name": "Soil_Snow"
    },
    {
      "x": 14,
      "y": 7,
      "z": 7,
      "name": "Rock_Shale"
    },
    {
      "x": 14,
      "y": 8,
      "z": 7,
      "name": "Rock_Shale"
    },
    {
      "x": 14,
      "y": 9,
      "z": 7,
      "name": "Rock_Shale"
    },
    {
      "x": 14,
      "y": 10,
      "z": 7,
      "name": "Rock_Shale"
    },
    {
      "x": 14,
      "y": 6,
      "z": 8,
      "name": "Rock_Shale"
    },
    {
      "x": 14,
      "y": 7,
      "z": 8,
      "name": "Rock_Shale"
    },
    {
      "x": 14,
      "y": 8,
      "z": 8,
      "name": "Rock_Shale"
    },
    {
      "x": 14,
      "y": 9,
      "z": 8,
      "name": "Rock_Shale"
    }
  ]
}