{
  "version": 8,
  "blockIdVersion": 8,
  "anchorX": 0,
  "anchorY": 5,
  "anchorZ": -2,
  "blocks": [
    {
      "x": -1,
      "y": 2,
      "z": -2,
      "name": "Wood_Dry_Trunk"
    },
    {
      "x": -1,
      "y": 3,
      "z": -2,
      "name": "Wood_Dry_Trunk"
    },
    {
      "x": -1,
      "y": 4,
      "z": -2,
      "name": "Wood_Dry_Trunk"
    },
    {
      "x": -1,
      "y": 5,
      "z": -2,
      "name": "Wood_Dry_Trunk"
    },
    {
      "x": -1,
      "y": 6,
      "z": -2,
      "name": "Wood_Dry_Trunk_Full"
    },
    {
      "x": -1,
      "y": 3,
      "z": -1,
      "name": "Wood_Dry_Trunk"
    },
    {
      "x": -1,
      "y": 4,
      "z": -1,
      "name": "Wood_Dry_Trunk"
    },
    {
      "x": -1,
      "y": 5,
      "z": -1,
      "name": "Wood_Dry_Trunk_Full"
    },
    {
      "x": 0,
      "y": 2,
      "z": -3,
      "name": "Wood_Dry_Trunk"
    },
    {
      "x": 0,
      "y": 3,
      "z": -3,
      "name": "Wood_Dry_Trunk"
    },
    {
      "x": 0,
      "y": 4,
      "z": -3,
      "name": "Wood_Dry_Trunk"
    },
    {
      "x": 0,
      "y": 5,
      "z": -3,
      "name": "Wood_Dry_Trunk"
    },
    {
      "x": 0,
      "y": 6,
      "z": -3,
      "name": "Wood_Dry_Trunk_Full"
    },
    {
      "x": 0,
      "y": 11,
      "z": -3,
      "name": "Wood_Dry_Branch_Corner",
      "rotation": 2
    },
    {
      "x": 0,
      "y": 12,
      "z": -3,
      "name": "Wood_Dry_Branch_Long"
    },
    {
      "x": 0,
      "y": 13,
      "z": -3,
      "name": "Wood_Dry_Branch_Long"
    },
    {
      "x": 0,
      "y": 2,
      "z": -2,
      "name": "Wood_Dry_Trunk"
    },
    {
      "x": 0,
      "y": 3,
      "z": -2,
      "name": "Wood_Dry_Trunk"
    },
    {
      "x": 0,
      "y": 4,
      "z": -2,
      "name": "Wood_Dry_Trunk"
    },
    {
      "x": 0,
      "y": 5,
      "z": -2,
      "name": "Wood_Dry_Trunk"
    },
    {
      "x": 0,
      "y": 6,
      "z": -2,
      "name": "Wood_Dry_Trunk"
    },
    {
      "x": 0,
      "y": 7,
      "z": -2,
      "name": "Wood_Dry_Trunk"
    },
    {
      "x": 0,
      "y": 8,
      "z": -2,
      "name": "Wood_Dry_Trunk"
    },
    {
      "x": 0,
      "y": 9,
      "z": -2,
      "name": "Wood_Dry_Trunk"
    },
    {
      "x": 0,
      "y": 10,
      "z": -2,
      "name": "Wood_Dry_Trunk"
    },
    {
      "x": 0,
      "y": 11,
      "z": -2,
      "name": "Wood_Dry_Trunk"
    },
    {
      "x": 0,
      "y": 2,
      "z": -1,
      "name": "Wood_Dry_Trunk"
    },
    {
      "x": 0,
      "y": 3,
      "z": -1,
      "name": "Wood_Dry_Trunk"
    },
    {
      "x": 0,
      "y": 4,
      "z": -1,
      "name": "Wood_Dry_Trunk"
    },
    {
      "x": 0,
      "y": 5,
      "z": -1,
      "name": "Wood_Dry_Trunk"
    },
    {
      "x": 0,
      "y": 6,
      "z": -1,
      "name": "Wood_Dry_Trunk"
    },
    {
      "x": 0,
      "y": 7,
      "z": -1,
      "name": "Wood_Dry_Trunk"
    },
    {
      "x": 0,
      "y": 8,
      "z": -1,
      "name": "Wood_Dry_Trunk"
    },
    {
      "x": 0,
      "y": 9,
      "z": -1,
      "name": "Wood_Dry_Trunk"
    },
    {
      "x": 0,
      "y": 4,
      "z": 0,
      "name": "Wood_Dry_Trunk"
    },
    {
      "x": 0,
      "y": 5,
      "z": 0,
      "name": "Wood_Dry_Trunk_Full"
    },
    {
      "x": 1,
      "y": 4,
      "z": -3,
      "name": "Wood_Dry_Trunk"
    },
    {
      "x": 1,
      "y": 5,
      "z": -3,
      "name": "Wood_Dry_Trunk_Full"
    },
    {
      "x": 1,
      "y": 2,
      "z": -2,
      "name": "Wood_Dry_Trunk"
    },
    {
      "x": 1,
      "y": 3,
      "z": -2,
      "name": "Wood_Dry_Trunk"
    },
    {
      "x": 1,
      "y": 4,
      "z": -2,
      "name": "Wood_Dry_Trunk"
    },
    {
      "x": 1,
      "y": 5,
      "z": -2,
      "name": "Wood_Dry_Trunk"
    },
    {
      "x": 1,
      "y": 6,
      "z": -2,
      "name": "Wood_Dry_Trunk"
    },
    {
      "x": 1,
      "y": 7,
      "z": -2,
      "name": "Wood_Dry_Trunk"
    },
    {
      "x": 1,
      "y": 8,
      "z": -2,
      "name": "Wood_Dry_Trunk"
    },
    {
      "x": 1,
      "y": 9,
      "z": -2,
      "name": "Wood_Dry_Trunk"
    },
    {
      "x": 1,
      "y": 10,
      "z": -2,
      "name": "Wood_Dry_Trunk"
    },
    {
      "x": 1,
      "y": 3,
      "z": -1,
      "name": "Wood_Dry_Trunk"
    },
    {
      "x": 1,
      "y": 4,
      "z": -1,
      "name": "Wood_Dry_Trunk"
    },
    {
      "x": 1,
      "y": 5,
      "z": -1,
      "name": "Wood_Dry_Trunk"
    },
    {
      "x": 1,
      "y": 6,
      "z": -1,
      "name": "Wood_Dry_Trunk"
    },
    {
      "x": 1,
      "y": 7,
      "z": -1,
      "name": "Wood_Dry_Trunk"
    },
    {
      "x": 1,
      "y": 8,
      "z": -1,
      "name": "Wood_Dry_Trunk"
    },
    {
      "x": 2,
      "y": 8,
      "z": -1,
      "name": "Wood_Dry_Branch_Corner",
      "rotation": 1
    },
    {
      "x": 2,
      "y": 9,
      "z": -1,
      "name": "Wood_Dry_Branch_Long"
    },
    {
      "x": 2,
      "y": 10,
      "z": -1,
      "name": "Wood_Dry_Branch_Long"
    }
  ]
}