{
  "version": 8,
  "blockIdVersion": 8,
  "anchorX": 0,
  "anchorY": 0,
  "anchorZ": 0,
  "blocks": [
    {
      "x": -8,
      "y": 0,
      "z": -25,
      "name": "Rock_Basalt"
    },
    {
      "x": -8,
      "y": 1,
      "z": -25,
      "name": "Rock_Basalt"
    },
    {
      "x": -8,
      "y": 2,
      "z": -25,
      "name": "Rock_Basalt"
    },
    {
      "x": -8,
      "y": 3,
      "z": -25,
      "name": "Rock_Basalt"
    },
    {
      "x": -8,
      "y": 4,
      "z": -25,
      "name": "Rock_Basalt"
    },
    {
      "x": -8,
      "y": 5,
      "z": -25,
      "name": "Rock_Basalt"
    },
    {
      "x": -8,
      "y": 6,
      "z": -25,
      "name": "Rock_Basalt"
    },
    {
      "x": -8,
      "y": 7,
      "z": -25,
      "name": "Rock_Basalt"
    },
    {
      "x": -8,
      "y": 8,
      "z": -25,
      "name": "Rock_Basalt"
    },
    {
      "x": -8,
      "y": 9,
      "z": -25,
      "name": "Rock_Basalt"
    },
    {
      "x": -8,
      "y": 10,
      "z": -25,
      "name": "Rock_Basalt"
    },
    {
      "x": -8,
      "y": 0,
      "z": -24,
      "name": "Rock_Basalt"
    },
    {
      "x": -8,
      "y": 1,
      "z": -24,
      "name": "Rock_Basalt"
    },
    {
      "x": -8,
      "y": 2,
      "z": -24,
      "name": "Rock_Basalt"
    },
    {
      "x": -8,
      "y": 3,
      "z": -24,
      "name": "Rock_Basalt"
    },
    {
      "x": -8,
      "y": 4,
      "z": -24,
      "name": "Rock_Basalt"
    },
    {
      "x": -8,
      "y": 5,
      "z": -24,
      "name": "Rock_Basalt"
    },
    {
      "x": -8,
      "y": 6,
      "z": -24,
      "name": "Rock_Basalt"
    },
    {
      "x": -8,
      "y": 7,
      "z": -24,
      "name": "Rock_Basalt"
    },
    {
      "x": -8,
      "y": 8,
      "z": -24,
      "name": "Rock_Basalt"
    },
    {
      "x": -8,
      "y": 9,
      "z": -24,
      "name": "Rock_Basalt"
    },
    {
      "x": -8,
      "y": 10,
      "z": -24,
      "name": "Rock_Basalt"
    },
    {
      "x": -8,
      "y": 0,
      "z": -23,
      "name": "Rock_Basalt"
    },
    {
      "x": -8,
      "y": 1,
      "z": -23,
      "name": "Rock_Basalt"
    },
    {
      "x": -8,
      "y": 2,
      "z": -23,
      "name": "Rock_Basalt"
    },
    {
      "x": -8,
      "y": 3,
      "z": -23,
      "name": "Rock_Basalt"
    },
    {
      "x": -8,
      "y": 4,
      "z": -23,
      "name": "Rock_Basalt"
    },
    {
      "x": -8,
      "y": 5,
      "z": -23,
      "name": "Rock_Basalt"
    },
    {
      "x": -8,
      "y": 6,
      "z": -23,
      "name": "Rock_Basalt"
    },
    {
      "x": -8,
      "y": 7,
      "z": -23,
      "name": "Rock_Basalt"
    },
    {
      "x": -8,
      "y": 8,
      "z": -23,
      "name": "Rock_Basalt"
    },
    {
      "x": -8,
      "y": 9,
      "z": -23,
      "name": "Rock_Basalt"
    },
    {
      "x": -8,
      "y": 10,
      "z": -23,
      "name": "Rock_Basalt"
    },
    {
      "x": -8,
      "y": 0,
      "z": -22,
      "name": "Rock_Basalt"
    },
    {
      "x": -8,
      "y": 1,
      "z": -22,
      "name": "Rock_Basalt"
    },
    {
      "x": -8,
      "y": 2,
      "z": -22,
      "name": "Rock_Basalt"
    },
    {
      "x": -8,
      "y": 3,
      "z": -22,
      "name": "Rock_Basalt"
    },
    {
      "x": -8,
      "y": 4,
      "z": -22,
      "name": "Rock_Basalt"
    },
    {
      "x": -8,
      "y": 5,
      "z": -22,
      "name": "Rock_Basalt"
    },
    {
      "x": -8,
      "y": 6,
      "z": -22,
      "name": "Rock_Basalt"
    },
    {
      "x": -8,
      "y": 7,
      "z": -22,
      "name": "Rock_Basalt"
    },
    {
      "x": -8,
      "y": 8,
      "z": -22,
      "name": "Rock_Basalt"
    },
    {
      "x": -8,
      "y": 9,
      "z": -22,
      "name": "Rock_Basalt"
    },
    {
      "x": -8,
      "y": 10,
      "z": -22,
      "name": "Rock_Basalt"
    },
    {
      "x": -8,
      "y": 0,
      "z": -21,
      "name": "Rock_Basalt"
    },
    {
      "x": -8,
      "y": 1,
      "z": -21,
      "name": "Rock_Basalt"
    },
    {
      "x": -8,
      "y": 2,
      "z": -21,
      "name": "Rock_Basalt"
    },
    {
      "x": -8,
      "y": 3,
      "z": -21,
      "name": "Rock_Basalt"
    },
    {
      "x": -8,
      "y": 4,
      "z": -21,
      "name": "Rock_Basalt"
    },
    {
      "x": -8,
      "y": 5,
      "z": -21,
      "name": "Rock_Basalt"
    },
    {
      "x": -8,
      "y": 6,
      "z": -21,
      "name": "Rock_Basalt"
    },
    {
      "x": -8,
      "y": 7,
      "z": -21,
      "name": "Rock_Basalt"
    },
    {
      "x": -8,
      "y": 8,
      "z": -21,
      "name": "Rock_Basalt"
    },
    {
      "x": -8,
      "y": 9,
      "z": -21,
      "name": "Rock_Basalt"
    },
    {
      "x": -8,
      "y": 10,
      "z": -21,
      "name": "Rock_Basalt"
    },
    {
      "x": -8,
      "y": 0,
      "z": -20,
      "name": "Rock_Basalt"
    },
    {
      "x": -8,
      "y": 1,
      "z": -20,
      "name": "Rock_Basalt"
    },
    {
      "x": -8,
      "y": 2,
      "z": -20,
      "name": "Rock_Basalt"
    },
    {
      "x": -8,
      "y": 3,
      "z": -20,
      "name": "Rock_Basalt"
    },
    {
      "x": -8,
      "y": 4,
      "z": -20,
      "name": "Rock_Basalt"
    },
    {
      "x": -8,
      "y": 5,
      "z": -20,
      "name": "Rock_Basalt"
    },
    {
      "x": -8,
      "y": 6,
      "z": -20,
      "name": "Rock_Basalt"
    },
    {
      "x": -8,
      "y": 7,
      "z": -20,
      "name": "Rock_Basalt"
    },
    {
      "x": -8,
      "y": 8,
      "z": -20,
      "name": "Rock_Basalt"
    },
    {
      "x": -8,
      "y": 9,
      "z": -20,
      "name": "Rock_Basalt"
    },
    {
      "x": -8,
      "y": 10,
      "z": -20,
      "name": "Rock_Basalt"
    },
    {
      "x": -8,
      "y": 0,
      "z": -19,
      "name": "Rock_Basalt"
    },
    {
      "x": -8,
      "y": 1,
      "z": -19,
      "name": "Rock_Basalt"
    },
    {
      "x": -8,
      "y": 2,
      "z": -19,
      "name": "Rock_Basalt"
    },
    {
      "x": -8,
      "y": 3,
      "z": -19,
      "name": "Rock_Basalt"
    },
    {
      "x": -8,
      "y": 4,
      "z": -19,
      "name": "Rock_Basalt"
    },
    {
      "x": -8,
      "y": 5,
      "z": -19,
      "name": "Rock_Basalt"
    },
    {
      "x": -8,
      "y": 6,
      "z": -19,
      "name": "Rock_Basalt"
    },
    {
      "x": -8,
      "y": 7,
      "z": -19,
      "name": "Rock_Basalt"
    },
    {
      "x": -8,
      "y": 8,
      "z": -19,
      "name": "Rock_Basalt"
    },
    {
      "x": -8,
      "y": 9,
      "z": -19,
      "name": "Rock_Basalt"
    },
    {
      "x": -8,
      "y": 10,
      "z": -19,
      "name": "Rock_Basalt"
    },
    {
      "x": -8,
      "y": 0,
      "z": -18,
      "name": "Rock_Basalt"
    },
    {
      "x": -8,
      "y": 1,
      "z": -18,
      "name": "Rock_Basalt"
    },
    {
      "x": -8,
      "y": 2,
      "z": -18,
      "name": "Rock_Basalt"
    },
    {
      "x": -8,
      "y": 3,
      "z": -18,
      "name": "Rock_Basalt"
    },
    {
      "x": -8,
      "y": 4,
      "z": -18,
      "name": "Rock_Basalt"
    },
    {
      "x": -8,
      "y": 5,
      "z": -18,
      "name": "Rock_Basalt"
    },
    {
      "x": -8,
      "y": 6,
      "z": -18,
      "name": "Rock_Basalt"
    },
    {
      "x": -8,
      "y": 7,
      "z": -18,
      "name": "Rock_Basalt"
    },
    {
      "x": -8,
      "y": 8,
      "z": -18,
      "name": "Rock_Basalt"
    },
    {
      "x": -8,
      "y": 9,
      "z": -18,
      "name": "Rock_Basalt"
    },
    {
      "x": -8,
      "y": 10,
      "z": -18,
      "name": "Rock_Basalt"
    },
    {
      "x": -8,
      "y": 0,
      "z": -17,
      "name": "Rock_Basalt"
    },
    {
      "x": -8,
      "y": 1,
      "z": -17,
      "name": "Rock_Basalt"
    },
    {
      "x": -8,
      "y": 2,
      "z": -17,
      "name": "Rock_Basalt"
    },
    {
      "x": -8,
      "y": 3,
      "z": -17,
      "name": "Rock_Basalt"
    },
    {
      "x": -8,
      "y": 4,
      "z": -17,
      "name": "Rock_Basalt"
    },
    {
      "x": -8,
      "y": 5,
      "z": -17,
      "name": "Rock_Basalt"
    },
    {
      "x": -8,
      "y": 6,
      "z": -17,
      "name": "Rock_Basalt"
    },
    {
      "x": -8,
      "y": 7,
      "z": -17,
      "name": "Rock_Basalt"
    },
    {
      "x": -8,
      "y": 8,
      "z": -17,
      "name": "Rock_Basalt"
    },
    {
      "x": -8,
      "y": 9,
      "z": -17,
      "name": "Rock_Basalt"
    },
    {
      "x": -8,
      "y": 10,
      "z": -17,
      "name": "Rock_Basalt"
    },
    {
      "x": -8,
      "y": 0,
      "z": -16,
      "name": "Rock_Basalt"
    },
    {
      "x": -8,
      "y": 1,
      "z": -16,
      "name": "Rock_Basalt"
    },
    {
      "x": -8,
      "y": 2,
      "z": -16,
      "name": "Rock_Basalt"
    },
    {
      "x": -8,
      "y": 3,
      "z": -16,
      "name": "Rock_Basalt"
    },
    {
      "x": -8,
      "y": 4,
      "z": -16,
      "name": "Rock_Basalt"
    },
    {
      "x": -8,
      "y": 5,
      "z": -16,
      "name": "Rock_Basalt"
    },
    {
      "x": -8,
      "y": 6,
      "z": -16,
      "name": "Rock_Basalt"
    },
    {
      "x": -8,
      "y": 7,
      "z": -16,
      "name": "Rock_Basalt"
    },
    {
      "x": -8,
      "y": 8,
      "z": -16,
      "name": "Rock_Basalt"
    },
    {
      "x": -8,
      "y": 9,
      "z": -16,
      "name": "Rock_Basalt"
    },
    {
      "x": -8,
      "y": 10,
      "z": -16,
      "name": "Rock_Basalt"
    },
    {
      "x": -8,
      "y": 0,
      "z": -15,
      "name": "Rock_Basalt"
    },
    {
      "x": -8,
      "y": 1,
      "z": -15,
      "name": "Rock_Basalt"
    },
    {
      "x": -8,
      "y": 2,
      "z": -15,
      "name": "Rock_Basalt"
    },
    {
      "x": -8,
      "y": 3,
      "z": -15,
      "name": "Rock_Basalt"
    },
    {
      "x": -8,
      "y": 4,
      "z": -15,
      "name": "Rock_Basalt"
    },
    {
      "x": -8,
      "y": 5,
      "z": -15,
      "name": "Rock_Basalt"
    },
    {
      "x": -8,
      "y": 6,
      "z": -15,
      "name": "Rock_Basalt"
    },
    {
      "x": -8,
      "y": 7,
      "z": -15,
      "name": "Rock_Basalt"
    },
    {
      "x": -8,
      "y": 8,
      "z": -15,
      "name": "Rock_Basalt"
    },
    {
      "x": -8,
      "y": 9,
      "z": -15,
      "name": "Rock_Basalt"
    },
    {
      "x": -8,
      "y": 10,
      "z": -15,
      "name": "Rock_Basalt"
    },
    {
      "x": -8,
      "y": 0,
      "z": -14,
      "name": "Rock_Basalt"
    },
    {
      "x": -8,
      "y": 1,
      "z": -14,
      "name": "Rock_Basalt"
    },
    {
      "x": -8,
      "y": 2,
      "z": -14,
      "name": "Rock_Basalt"
    },
    {
      "x": -8,
      "y": 3,
      "z": -14,
      "name": "Rock_Basalt"
    },
    {
      "x": -8,
      "y": 4,
      "z": -14,
      "name": "Rock_Basalt"
    },
    {
      "x": -8,
      "y": 5,
      "z": -14,
      "name": "Rock_Basalt"
    },
    {
      "x": -8,
      "y": 6,
      "z": -14,
      "name": "Rock_Basalt"
    },
    {
      "x": -8,
      "y": 7,
      "z": -14,
      "name": "Rock_Basalt"
    },
    {
      "x": -8,
      "y": 8,
      "z": -14,
      "name": "Rock_Basalt"
    },
    {
      "x": -8,
      "y": 9,
      "z": -14,
      "name": "Rock_Basalt"
    },
    {
      "x": -8,
      "y": 10,
      "z": -14,
      "name": "Rock_Basalt"
    },
    {
      "x": -8,
      "y": 0,
      "z": -13,
      "name": "Rock_Basalt"
    },
    {
      "x": -8,
      "y": 1,
      "z": -13,
      "name": "Rock_Basalt"
    },
    {
      "x": -8,
      "y": 2,
      "z": -13,
      "name": "Rock_Basalt"
    },
    {
      "x": -8,
      "y": 3,
      "z": -13,
      "name": "Rock_Basalt"
    },
    {
      "x": -8,
      "y": 4,
      "z": -13,
      "name": "Rock_Basalt"
    },
    {
      "x": -8,
      "y": 5,
      "z": -13,
      "name": "Rock_Basalt"
    },
    {
      "x": -8,
      "y": 6,
      "z": -13,
      "name": "Rock_Basalt"
    },
    {
      "x": -8,
      "y": 7,
      "z": -13,
      "name": "Rock_Basalt"
    },
    {
      "x": -8,
      "y": 8,
      "z": -13,
      "name": "Rock_Basalt"
    },
    {
      "x": -8,
      "y": 9,
      "z": -13,
      "name": "Rock_Basalt"
    },
    {
      "x": -8,
      "y": 10,
      "z": -13,
      "name": "Rock_Basalt"
    },
    {
      "x": -8,
      "y": 0,
      "z": -12,
      "name": "Rock_Basalt"
    },
    {
      "x": -8,
      "y": 1,
      "z": -12,
      "name": "Rock_Basalt"
    },
    {
      "x": -8,
      "y": 2,
      "z": -12,
      "name": "Rock_Basalt"
    },
    {
      "x": -8,
      "y": 3,
      "z": -12,
      "name": "Rock_Basalt"
    },
    {
      "x": -8,
      "y": 4,
      "z": -12,
      "name": "Rock_Basalt"
    },
    {
      "x": -8,
      "y": 5,
      "z": -12,
      "name": "Rock_Basalt"
    },
    {
      "x": -8,
      "y": 6,
      "z": -12,
      "name": "Rock_Basalt"
    },
    {
      "x": -8,
      "y": 7,
      "z": -12,
      "name": "Rock_Basalt"
    },
    {
      "x": -8,
      "y": 8,
      "z": -12,
      "name": "Rock_Basalt"
    },
    {
      "x": -8,
      "y": 9,
      "z": -12,
      "name": "Rock_Basalt"
    },
    {
      "x": -8,
      "y": 10,
      "z": -12,
      "name": "Rock_Basalt"
    },
    {
      "x": -8,
      "y": 0,
      "z": -11,
      "name": "Rock_Basalt"
    },
    {
      "x": -8,
      "y": 1,
      "z": -11,
      "name": "Rock_Basalt"
    },
    {
      "x": -8,
      "y": 2,
      "z": -11,
      "name": "Rock_Basalt"
    },
    {
      "x": -8,
      "y": 3,
      "z": -11,
      "name": "Rock_Basalt"
    },
    {
      "x": -8,
      "y": 4,
      "z": -11,
      "name": "Rock_Basalt"
    },
    {
      "x": -8,
      "y": 5,
      "z": -11,
      "name": "Rock_Basalt"
    },
    {
      "x": -8,
      "y": 6,
      "z": -11,
      "name": "Rock_Basalt"
    },
    {
      "x": -8,
      "y": 7,
      "z": -11,
      "name": "Rock_Basalt"
    },
    {
      "x": -8,
      "y": 8,
      "z": -11,
      "name": "Rock_Basalt"
    },
    {
      "x": -8,
      "y": 9,
      "z": -11,
      "name": "Rock_Basalt"
    },
    {
      "x": -8,
      "y": 10,
      "z": -11,
      "name": "Rock_Basalt"
    },
    {
      "x": -8,
      "y": 0,
      "z": -10,
      "name": "Rock_Basalt"
    },
    {
      "x": -8,
      "y": 1,
      "z": -10,
      "name": "Rock_Basalt"
    },
    {
      "x": -8,
      "y": 2,
      "z": -10,
      "name": "Rock_Basalt"
    },
    {
      "x": -8,
      "y": 3,
      "z": -10,
      "name": "Rock_Basalt"
    },
    {
      "x": -8,
      "y": 4,
      "z": -10,
      "name": "Rock_Basalt"
    },
    {
      "x": -8,
      "y": 5,
      "z": -10,
      "name": "Rock_Basalt"
    },
    {
      "x": -8,
      "y": 6,
      "z": -10,
      "name": "Rock_Basalt"
    },
    {
      "x": -8,
      "y": 7,
      "z": -10,
      "name": "Rock_Basalt"
    },
    {
      "x": -8,
      "y": 8,
      "z": -10,
      "name": "Rock_Basalt"
    },
    {
      "x": -8,
      "y": 9,
      "z": -10,
      "name": "Rock_Basalt"
    },
    {
      "x": -8,
      "y": 10,
      "z": -10,
      "name": "Rock_Basalt"
    },
    {
      "x": -8,
      "y": 0,
      "z": -9,
      "name": "Rock_Basalt"
    },
    {
      "x": -8,
      "y": 1,
      "z": -9,
      "name": "Rock_Basalt"
    },
    {
      "x": -8,
      "y": 2,
      "z": -9,
      "name": "Rock_Basalt"
    },
    {
      "x": -8,
      "y": 3,
      "z": -9,
      "name": "Rock_Basalt"
    },
    {
      "x": -8,
      "y": 4,
      "z": -9,
      "name": "Rock_Basalt"
    },
    {
      "x": -8,
      "y": 5,
      "z": -9,
      "name": "Rock_Basalt"
    },
    {
      "x": -8,
      "y": 6,
      "z": -9,
      "name": "Rock_Basalt"
    },
    {
      "x": -8,
      "y": 7,
      "z": -9,
      "name": "Rock_Basalt"
    },
    {
      "x": -8,
      "y": 8,
      "z": -9,
      "name": "Rock_Basalt"
    },
    {
      "x": -8,
      "y": 9,
      "z": -9,
      "name": "Rock_Basalt"
    },
    {
      "x": -8,
      "y": 10,
      "z": -9,
      "name": "Rock_Basalt"
    },
    {
      "x": -8,
      "y": 0,
      "z": -8,
      "name": "Rock_Basalt"
    },
    {
      "x": -8,
      "y": 1,
      "z": -8,
      "name": "Rock_Basalt"
    },
    {
      "x": -8,
      "y": 2,
      "z": -8,
      "name": "Rock_Basalt"
    },
    {
      "x": -8,
      "y": 3,
      "z": -8,
      "name": "Rock_Basalt"
    },
    {
      "x": -8,
      "y": 4,
      "z": -8,
      "name": "Rock_Basalt"
    },
    {
      "x": -8,
      "y": 5,
      "z": -8,
      "name": "Rock_Basalt"
    },
    {
      "x": -8,
      "y": 6,
      "z": -8,
      "name": "Rock_Basalt"
    },
    {
      "x": -8,
      "y": 7,
      "z": -8,
      "name": "Rock_Basalt"
    },
    {
      "x": -8,
      "y": 8,
      "z": -8,
      "name": "Rock_Basalt"
    },
    {
      "x": -8,
      "y": 9,
      "z": -8,
      "name": "Rock_Basalt"
    },
    {
      "x": -8,
      "y": 10,
      "z": -8,
      "name": "Rock_Basalt"
    },
    {
      "x": -8,
      "y": 0,
      "z": -7,
      "name": "Rock_Basalt"
    },
    {
      "x": -8,
      "y": 1,
      "z": -7,
      "name": "Rock_Basalt"
    },
    {
      "x": -8,
      "y": 2,
      "z": -7,
      "name": "Rock_Basalt"
    },
    {
      "x": -8,
      "y": 3,
      "z": -7,
      "name": "Rock_Basalt"
    },
    {
      "x": -8,
      "y": 4,
      "z": -7,
      "name": "Rock_Basalt"
    },
    {
      "x": -8,
      "y": 5,
      "z": -7,
      "name": "Rock_Basalt"
    },
    {
      "x": -8,
      "y": 6,
      "z": -7,
      "name": "Rock_Basalt"
    },
    {
      "x": -8,
      "y": 7,
      "z": -7,
      "name": "Rock_Basalt"
    },
    {
      "x": -8,
      "y": 8,
      "z": -7,
      "name": "Rock_Basalt"
    },
    {
      "x": -8,
      "y": 9,
      "z": -7,
      "name": "Rock_Basalt"
    },
    {
      "x": -8,
      "y": 10,
      "z": -7,
      "name": "Rock_Basalt"
    },
    {
      "x": -8,
      "y": 0,
      "z": -6,
      "name": "Rock_Basalt"
    },
    {
      "x": -8,
      "y": 1,
      "z": -6,
      "name": "Rock_Basalt"
    },
    {
      "x": -8,
      "y": 2,
      "z": -6,
      "name": "Rock_Basalt"
    },
    {
      "x": -8,
      "y": 3,
      "z": -6,
      "name": "Rock_Basalt"
    },
    {
      "x": -8,
      "y": 4,
      "z": -6,
      "name": "Rock_Basalt"
    },
    {
      "x": -8,
      "y": 5,
      "z": -6,
      "name": "Rock_Basalt"
    },
    {
      "x": -8,
      "y": 6,
      "z": -6,
      "name": "Rock_Basalt"
    },
    {
      "x": -8,
      "y": 7,
      "z": -6,
      "name": "Rock_Basalt"
    },
    {
      "x": -8,
      "y": 8,
      "z": -6,
      "name": "Rock_Basalt"
    },
    {
      "x": -8,
      "y": 9,
      "z": -6,
      "name": "Rock_Basalt"
    },
    {
      "x": -8,
      "y": 10,
      "z": -6,
      "name": "Rock_Basalt"
    },
    {
      "x": -7,
      "y": 0,
      "z": -25,
      "name": "Rock_Basalt"
    },
    {
      "x": -7,
      "y": 1,
      "z": -25,
      "name": "Rock_Basalt"
    },
    {
      "x": -7,
      "y": 2,
      "z": -25,
      "name": "Rock_Basalt"
    },
    {
      "x": -7,
      "y": 3,
      "z": -25,
      "name": "Rock_Basalt"
    },
    {
      "x": -7,
      "y": 4,
      "z": -25,
      "name": "Rock_Basalt"
    },
    {
      "x": -7,
      "y": 5,
      "z": -25,
      "name": "Rock_Basalt"
    },
    {
      "x": -7,
      "y": 6,
      "z": -25,
      "name": "Rock_Basalt"
    },
    {
      "x": -7,
      "y": 7,
      "z": -25,
      "name": "Rock_Basalt"
    },
    {
      "x": -7,
      "y": 8,
      "z": -25,
      "name": "Rock_Basalt"
    },
    {
      "x": -7,
      "y": 9,
      "z": -25,
      "name": "Rock_Basalt"
    },
    {
      "x": -7,
      "y": 10,
      "z": -25,
      "name": "Rock_Basalt"
    },
    {
      "x": -7,
      "y": 0,
      "z": -24,
      "name": "Rock_Basalt_Cobble"
    },
    {
      "x": -7,
      "y": 1,
      "z": -24,
      "name": "Empty"
    },
    {
      "x": -7,
      "y": 2,
      "z": -24,
      "name": "Empty"
    },
    {
      "x": -7,
      "y": 3,
      "z": -24,
      "name": "Empty"
    },
    {
      "x": -7,
      "y": 4,
      "z": -24,
      "name": "Empty"
    },
    {
      "x": -7,
      "y": 5,
      "z": -24,
      "name": "Empty"
    },
    {
      "x": -7,
      "y": 6,
      "z": -24,
      "name": "Empty"
    },
    {
      "x": -7,
      "y": 7,
      "z": -24,
      "name": "Empty"
    },
    {
      "x": -7,
      "y": 8,
      "z": -24,
      "name": "Empty"
    },
    {
      "x": -7,
      "y": 9,
      "z": -24,
      "name": "Empty"
    },
    {
      "x": -7,
      "y": 10,
      "z": -24,
      "name": "Rock_Basalt"
    },
    {
      "x": -7,
      "y": 0,
      "z": -23,
      "name": "Rock_Basalt_Cobble"
    },
    {
      "x": -7,
      "y": 1,
      "z": -23,
      "name": "Empty"
    },
    {
      "x": -7,
      "y": 2,
      "z": -23,
      "name": "Empty"
    },
    {
      "x": -7,
      "y": 3,
      "z": -23,
      "name": "Empty"
    },
    {
      "x": -7,
      "y": 4,
      "z": -23,
      "name": "Empty"
    },
    {
      "x": -7,
      "y": 5,
      "z": -23,
      "name": "Empty"
    },
    {
      "x": -7,
      "y": 6,
      "z": -23,
      "name": "Empty"
    },
    {
      "x": -7,
      "y": 7,
      "z": -23,
      "name": "Empty"
    },
    {
      "x": -7,
      "y": 8,
      "z": -23,
      "name": "Empty"
    },
    {
      "x": -7,
      "y": 9,
      "z": -23,
      "name": "Empty"
    },
    {
      "x": -7,
      "y": 10,
      "z": -23,
      "name": "Rock_Basalt"
    },
    {
      "x": -7,
      "y": 0,
      "z": -22,
      "name": "Rock_Basalt_Cobble"
    },
    {
      "x": -7,
      "y": 1,
      "z": -22,
      "name": "Empty"
    },
    {
      "x": -7,
      "y": 2,
      "z": -22,
      "name": "Empty"
    },
    {
      "x": -7,
      "y": 3,
      "z": -22,
      "name": "Empty"
    },
    {
      "x": -7,
      "y": 4,
      "z": -22,
      "name": "Empty"
    },
    {
      "x": -7,
      "y": 5,
      "z": -22,
      "name": "Empty"
    },
    {
      "x": -7,
      "y": 6,
      "z": -22,
      "name": "Empty"
    },
    {
      "x": -7,
      "y": 7,
      "z": -22,
      "name": "Empty"
    },
    {
      "x": -7,
      "y": 8,
      "z": -22,
      "name": "Empty"
    },
    {
      "x": -7,
      "y": 9,
      "z": -22,
      "name": "Empty"
    },
    {
      "x": -7,
      "y": 10,
      "z": -22,
      "name": "Rock_Basalt"
    },
    {
      "x": -7,
      "y": 0,
      "z": -21,
      "name": "Rock_Basalt_Cobble"
    },
    {
      "x": -7,
      "y": 1,
      "z": -21,
      "name": "Empty"
    },
    {
      "x": -7,
      "y": 2,
      "z": -21,
      "name": "Empty"
    },
    {
      "x": -7,
      "y": 3,
      "z": -21,
      "name": "Empty"
    },
    {
      "x": -7,
      "y": 4,
      "z": -21,
      "name": "Empty"
    },
    {
      "x": -7,
      "y": 5,
      "z": -21,
      "name": "Empty"
    },
    {
      "x": -7,
      "y": 6,
      "z": -21,
      "name": "Empty"
    },
    {
      "x": -7,
      "y": 7,
      "z": -21,
      "name": "Empty"
    },
    {
      "x": -7,
      "y": 8,
      "z": -21,
      "name": "Empty"
    },
    {
      "x": -7,
      "y": 9,
      "z": -21,
      "name": "Empty"
    },
    {
      "x": -7,
      "y": 10,
      "z": -21,
      "name": "Rock_Basalt"
    },
    {
      "x": -7,
      "y": 0,
      "z": -20,
      "name": "Rock_Basalt_Cobble"
    },
    {
      "x": -7,
      "y": 1,
      "z": -20,
      "name": "Empty"
    },
    {
      "x": -7,
      "y": 2,
      "z": -20,
      "name": "Empty"
    },
    {
      "x": -7,
      "y": 3,
      "z": -20,
      "name": "Empty"
    },
    {
      "x": -7,
      "y": 4,
      "z": -20,
      "name": "Empty"
    },
    {
      "x": -7,
      "y": 5,
      "z": -20,
      "name": "Empty"
    },
    {
      "x": -7,
      "y": 6,
      "z": -20,
      "name": "Empty"
    },
    {
      "x": -7,
      "y": 7,
      "z": -20,
      "name": "Empty"
    },
    {
      "x": -7,
      "y": 8,
      "z": -20,
      "name": "Empty"
    },
    {
      "x": -7,
      "y": 9,
      "z": -20,
      "name": "Empty"
    },
    {
      "x": -7,
      "y": 10,
      "z": -20,
      "name": "Rock_Basalt"
    },
    {
      "x": -7,
      "y": 0,
      "z": -19,
      "name": "Rock_Basalt_Cobble"
    },
    {
      "x": -7,
      "y": 1,
      "z": -19,
      "name": "Empty"
    },
    {
      "x": -7,
      "y": 2,
      "z": -19,
      "name": "Empty"
    },
    {
      "x": -7,
      "y": 3,
      "z": -19,
      "name": "Empty"
    },
    {
      "x": -7,
      "y": 4,
      "z": -19,
      "name": "Empty"
    },
    {
      "x": -7,
      "y": 5,
      "z": -19,
      "name": "Empty"
    },
    {
      "x": -7,
      "y": 6,
      "z": -19,
      "name": "Empty"
    },
    {
      "x": -7,
      "y": 7,
      "z": -19,
      "name": "Empty"
    },
    {
      "x": -7,
      "y": 8,
      "z": -19,
      "name": "Empty"
    },
    {
      "x": -7,
      "y": 9,
      "z": -19,
      "name": "Empty"
    },
    {
      "x": -7,
      "y": 10,
      "z": -19,
      "name": "Rock_Basalt"
    },
    {
      "x": -7,
      "y": 0,
      "z": -18,
      "name": "Rock_Basalt_Cobble"
    },
    {
      "x": -7,
      "y": 1,
      "z": -18,
      "name": "Empty"
    },
    {
      "x": -7,
      "y": 2,
      "z": -18,
      "name": "Empty"
    },
    {
      "x": -7,
      "y": 3,
      "z": -18,
      "name": "Empty"
    },
    {
      "x": -7,
      "y": 4,
      "z": -18,
      "name": "Empty"
    },
    {
      "x": -7,
      "y": 5,
      "z": -18,
      "name": "Empty"
    },
    {
      "x": -7,
      "y": 6,
      "z": -18,
      "name": "Empty"
    },
    {
      "x": -7,
      "y": 7,
      "z": -18,
      "name": "Empty"
    },
    {
      "x": -7,
      "y": 8,
      "z": -18,
      "name": "Empty"
    },
    {
      "x": -7,
      "y": 9,
      "z": -18,
      "name": "Empty"
    },
    {
      "x": -7,
      "y": 10,
      "z": -18,
      "name": "Rock_Basalt"
    },
    {
      "x": -7,
      "y": 0,
      "z": -17,
      "name": "Rock_Basalt_Cobble"
    },
    {
      "x": -7,
      "y": 1,
      "z": -17,
      "name": "Empty"
    },
    {
      "x": -7,
      "y": 2,
      "z": -17,
      "name": "Empty"
    },
    {
      "x": -7,
      "y": 3,
      "z": -17,
      "name": "Empty"
    },
    {
      "x": -7,
      "y": 4,
      "z": -17,
      "name": "Empty"
    },
    {
      "x": -7,
      "y": 5,
      "z": -17,
      "name": "Empty"
    },
    {
      "x": -7,
      "y": 6,
      "z": -17,
      "name": "Empty"
    },
    {
      "x": -7,
      "y": 7,
      "z": -17,
      "name": "Empty"
    },
    {
      "x": -7,
      "y": 8,
      "z": -17,
      "name": "Empty"
    },
    {
      "x": -7,
      "y": 9,
      "z": -17,
      "name": "Empty"
    },
    {
      "x": -7,
      "y": 10,
      "z": -17,
      "name": "Rock_Basalt"
    },
    {
      "x": -7,
      "y": 0,
      "z": -16,
      "name": "Rock_Basalt_Cobble"
    },
    {
      "x": -7,
      "y": 1,
      "z": -16,
      "name": "Empty"
    },
    {
      "x": -7,
      "y": 2,
      "z": -16,
      "name": "Empty"
    },
    {
      "x": -7,
      "y": 3,
      "z": -16,
      "name": "Empty"
    },
    {
      "x": -7,
      "y": 4,
      "z": -16,
      "name": "Empty"
    },
    {
      "x": -7,
      "y": 5,
      "z": -16,
      "name": "Empty"
    },
    {
      "x": -7,
      "y": 6,
      "z": -16,
      "name": "Empty"
    },
    {
      "x": -7,
      "y": 7,
      "z": -16,
      "name": "Empty"
    },
    {
      "x": -7,
      "y": 8,
      "z": -16,
      "name": "Empty"
    },
    {
      "x": -7,
      "y": 9,
      "z": -16,
      "name": "Empty"
    },
    {
      "x": -7,
      "y": 10,
      "z": -16,
      "name": "Rock_Basalt"
    },
    {
      "x": -7,
      "y": 0,
      "z": -15,
      "name": "Rock_Basalt_Cobble"
    },
    {
      "x": -7,
      "y": 1,
      "z": -15,
      "name": "Empty"
    },
    {
      "x": -7,
      "y": 2,
      "z": -15,
      "name": "Empty"
    },
    {
      "x": -7,
      "y": 3,
      "z": -15,
      "name": "Wood_Torch_Wall",
      "rotation": 1
    },
    {
      "x": -7,
      "y": 4,
      "z": -15,
      "name": "Empty"
    },
    {
      "x": -7,
      "y": 5,
      "z": -15,
      "name": "Empty"
    },
    {
      "x": -7,
      "y": 6,
      "z": -15,
      "name": "Empty"
    },
    {
      "x": -7,
      "y": 7,
      "z": -15,
      "name": "Empty"
    },
    {
      "x": -7,
      "y": 8,
      "z": -15,
      "name": "Empty"
    },
    {
      "x": -7,
      "y": 9,
      "z": -15,
      "name": "Empty"
    },
    {
      "x": -7,
      "y": 10,
      "z": -15,
      "name": "Rock_Basalt"
    },
    {
      "x": -7,
      "y": 0,
      "z": -14,
      "name": "Rock_Basalt_Cobble"
    },
    {
      "x": -7,
      "y": 1,
      "z": -14,
      "name": "Wood_Deadwood_Stairs",
      "rotation": 2
    },
    {
      "x": -7,
      "y": 2,
      "z": -14,
      "name": "Empty"
    },
    {
      "x": -7,
      "y": 3,
      "z": -14,
      "name": "Empty"
    },
    {
      "x": -7,
      "y": 4,
      "z": -14,
      "name": "Empty"
    },
    {
      "x": -7,
      "y": 5,
      "z": -14,
      "name": "Empty"
    },
    {
      "x": -7,
      "y": 6,
      "z": -14,
      "name": "Empty"
    },
    {
      "x": -7,
      "y": 7,
      "z": -14,
      "name": "Empty"
    },
    {
      "x": -7,
      "y": 8,
      "z": -14,
      "name": "Empty"
    },
    {
      "x": -7,
      "y": 9,
      "z": -14,
      "name": "Empty"
    },
    {
      "x": -7,
      "y": 10,
      "z": -14,
      "name": "Rock_Basalt"
    },
    {
      "x": -7,
      "y": 0,
      "z": -13,
      "name": "Rock_Basalt_Cobble"
    },
    {
      "x": -7,
      "y": 1,
      "z": -13,
      "name": "Wood_Deadwood_Planks"
    },
    {
      "x": -7,
      "y": 2,
      "z": -13,
      "name": "Wood_Deadwood_Stairs",
      "rotation": 2
    },
    {
      "x": -7,
      "y": 3,
      "z": -13,
      "name": "Empty"
    },
    {
      "x": -7,
      "y": 4,
      "z": -13,
      "name": "Empty"
    },
    {
      "x": -7,
      "y": 5,
      "z": -13,
      "name": "Empty"
    },
    {
      "x": -7,
      "y": 6,
      "z": -13,
      "name": "Empty"
    },
    {
      "x": -7,
      "y": 7,
      "z": -13,
      "name": "Empty"
    },
    {
      "x": -7,
      "y": 8,
      "z": -13,
      "name": "Empty"
    },
    {
      "x": -7,
      "y": 9,
      "z": -13,
      "name": "Empty"
    },
    {
      "x": -7,
      "y": 10,
      "z": -13,
      "name": "Rock_Basalt"
    },
    {
      "x": -7,
      "y": 0,
      "z": -12,
      "name": "Rock_Basalt_Cobble"
    },
    {
      "x": -7,
      "y": 1,
      "z": -12,
      "name": "Empty"
    },
    {
      "x": -7,
      "y": 2,
      "z": -12,
      "name": "Wood_Deadwood_Planks"
    },
    {
      "x": -7,
      "y": 3,
      "z": -12,
      "name": "Wood_Deadwood_Stairs",
      "rotation": 2
    },
    {
      "x": -7,
      "y": 4,
      "z": -12,
      "name": "Empty"
    },
    {
      "x": -7,
      "y": 5,
      "z": -12,
      "name": "Empty"
    },
    {
      "x": -7,
      "y": 6,
      "z": -12,
      "name": "Empty"
    },
    {
      "x": -7,
      "y": 7,
      "z": -12,
      "name": "Empty"
    },
    {
      "x": -7,
      "y": 8,
      "z": -12,
      "name": "Empty"
    },
    {
      "x": -7,
      "y": 9,
      "z": -12,
      "name": "Empty"
    },
    {
      "x": -7,
      "y": 10,
      "z": -12,
      "name": "Rock_Basalt"
    },
    {
      "x": -7,
      "y": 0,
      "z": -11,
      "name": "Rock_Basalt_Cobble"
    },
    {
      "x": -7,
      "y": 1,
      "z": -11,
      "name": "Empty"
    },
    {
      "x": -7,
      "y": 2,
      "z": -11,
      "name": "Empty"
    },
    {
      "x": -7,
      "y": 3,
      "z": -11,
      "name": "Wood_Deadwood_Planks"
    },
    {
      "x": -7,
      "y": 4,
      "z": -11,
      "name": "Wood_Deadwood_Stairs",
      "rotation": 2
    },
    {
      "x": -7,
      "y": 5,
      "z": -11,
      "name": "Empty"
    },
    {
      "x": -7,
      "y": 6,
      "z": -11,
      "name": "Empty"
    },
    {
      "x": -7,
      "y": 7,
      "z": -11,
      "name": "Empty"
    },
    {
      "x": -7,
      "y": 8,
      "z": -11,
      "name": "Empty"
    },
    {
      "x": -7,
      "y": 9,
      "z": -11,
      "name": "Empty"
    },
    {
      "x": -7,
      "y": 10,
      "z": -11,
      "name": "Rock_Basalt"
    },
    {
      "x": -7,
      "y": 0,
      "z": -10,
      "name": "Rock_Basalt_Cobble"
    },
    {
      "x": -7,
      "y": 1,
      "z": -10,
      "name": "Empty"
    },
    {
      "x": -7,
      "y": 2,
      "z": -10,
      "name": "Empty"
    },
    {
      "x": -7,
      "y": 3,
      "z": -10,
      "name": "Empty"
    },
    {
      "x": -7,
      "y": 4,
      "z": -10,
      "name": "Wood_Deadwood_Planks"
    },
    {
      "x": -7,
      "y": 5,
      "z": -10,
      "name": "Wood_Deadwood_Stairs",
      "rotation": 2
    },
    {
      "x": -7,
      "y": 6,
      "z": -10,
      "name": "Empty"
    },
    {
      "x": -7,
      "y": 7,
      "z": -10,
      "name": "Empty"
    },
    {
      "x": -7,
      "y": 8,
      "z": -10,
      "name": "Empty"
    },
    {
      "x": -7,
      "y": 9,
      "z": -10,
      "name": "Empty"
    },
    {
      "x": -7,
      "y": 10,
      "z": -10,
      "name": "Rock_Basalt"
    },
    {
      "x": -7,
      "y": 0,
      "z": -9,
      "name": "Rock_Basalt_Cobble"
    },
    {
      "x": -7,
      "y": 1,
      "z": -9,
      "name": "Furniture_Ancient_Crate",
      "rotation": 1
    },
    {
      "x": -7,
      "y": 2,
      "z": -9,
      "name": "Furniture_Ancient_Barrel"
    },
    {
      "x": -7,
      "y": 3,
      "z": -9,
      "name": "Empty"
    },
    {
      "x": -7,
      "y": 4,
      "z": -9,
      "name": "Empty"
    },
    {
      "x": -7,
      "y": 5,
      "z": -9,
      "name": "Wood_Deadwood_Planks"
    },
    {
      "x": -7,
      "y": 6,
      "z": -9,
      "name": "Empty"
    },
    {
      "x": -7,
      "y": 7,
      "z": -9,
      "name": "Empty"
    },
    {
      "x": -7,
      "y": 8,
      "z": -9,
      "name": "Empty"
    },
    {
      "x": -7,
      "y": 9,
      "z": -9,
      "name": "Empty"
    },
    {
      "x": -7,
      "y": 10,
      "z": -9,
      "name": "Rock_Basalt"
    },
    {
      "x": -7,
      "y": 0,
      "z": -8,
      "name": "Rock_Basalt_Cobble"
    },
    {
      "x": -7,
      "y": 1,
      "z": -8,
      "name": "Furniture_Ancient_Crate",
      "rotation": 1
    },
    {
      "x": -7,
      "y": 2,
      "z": -8,
      "name": "Furniture_Ancient_Barrel"
    },
    {
      "x": -7,
      "y": 3,
      "z": -8,
      "name": "Empty"
    },
    {
      "x": -7,
      "y": 4,
      "z": -8,
      "name": "Empty"
    },
    {
      "x": -7,
      "y": 5,
      "z": -8,
      "name": "Wood_Deadwood_Planks"
    },
    {
      "x": -7,
      "y": 6,
      "z": -8,
      "name": "Empty"
    },
    {
      "x": -7,
      "y": 7,
      "z": -8,
      "name": "Wood_Torch_Wall",
      "rotation": 1
    },
    {
      "x": -7,
      "y": 8,
      "z": -8,
      "name": "Empty"
    },
    {
      "x": -7,
      "y": 9,
      "z": -8,
      "name": "Empty"
    },
    {
      "x": -7,
      "y": 10,
      "z": -8,
      "name": "Rock_Basalt"
    },
    {
      "x": -7,
      "y": 0,
      "z": -7,
      "name": "Rock_Basalt_Cobble"
    },
    {
      "x": -7,
      "y": 1,
      "z": -7,
      "name": "Empty"
    },
    {
      "x": -7,
      "y": 2,
      "z": -7,
      "name": "Empty"
    },
    {
      "x": -7,
      "y": 3,
      "z": -7,
      "name": "Empty"
    },
    {
      "x": -7,
      "y": 4,
      "z": -7,
      "name": "Empty"
    },
    {
      "x": -7,
      "y": 5,
      "z": -7,
      "name": "Wood_Deadwood_Planks"
    },
    {
      "x": -7,
      "y": 6,
      "z": -7,
      "name": "Empty"
    },
    {
      "x": -7,
      "y": 7,
      "z": -7,
      "name": "Empty"
    },
    {
      "x": -7,
      "y": 8,
      "z": -7,
      "name": "Empty"
    },
    {
      "x": -7,
      "y": 9,
      "z": -7,
      "name": "Empty"
    },
    {
      "x": -7,
      "y": 10,
      "z": -7,
      "name": "Rock_Basalt"
    },
    {
      "x": -7,
      "y": 0,
      "z": -6,
      "name": "Rock_Basalt"
    },
    {
      "x": -7,
      "y": 1,
      "z": -6,
      "name": "Rock_Basalt"
    },
    {
      "x": -7,
      "y": 2,
      "z": -6,
      "name": "Rock_Basalt"
    },
    {
      "x": -7,
      "y": 3,
      "z": -6,
      "name": "Rock_Basalt"
    },
    {
      "x": -7,
      "y": 4,
      "z": -6,
      "name": "Rock_Basalt"
    },
    {
      "x": -7,
      "y": 5,
      "z": -6,
      "name": "Rock_Basalt"
    },
    {
      "x": -7,
      "y": 6,
      "z": -6,
      "name": "Rock_Basalt"
    },
    {
      "x": -7,
      "y": 7,
      "z": -6,
      "name": "Rock_Basalt"
    },
    {
      "x": -7,
      "y": 8,
      "z": -6,
      "name": "Rock_Basalt"
    },
    {
      "x": -7,
      "y": 9,
      "z": -6,
      "name": "Rock_Basalt"
    },
    {
      "x": -7,
      "y": 10,
      "z": -6,
      "name": "Rock_Basalt"
    },
    {
      "x": -7,
      "y": 0,
      "z": -5,
      "name": "Rock_Basalt"
    },
    {
      "x": -7,
      "y": 1,
      "z": -5,
      "name": "Rock_Basalt"
    },
    {
      "x": -7,
      "y": 2,
      "z": -5,
      "name": "Rock_Basalt"
    },
    {
      "x": -7,
      "y": 3,
      "z": -5,
      "name": "Rock_Basalt"
    },
    {
      "x": -7,
      "y": 4,
      "z": -5,
      "name": "Rock_Basalt"
    },
    {
      "x": -7,
      "y": 5,
      "z": -5,
      "name": "Rock_Basalt"
    },
    {
      "x": -7,
      "y": 6,
      "z": -5,
      "name": "Rock_Basalt"
    },
    {
      "x": -7,
      "y": 7,
      "z": -5,
      "name": "Rock_Basalt"
    },
    {
      "x": -7,
      "y": 8,
      "z": -5,
      "name": "Rock_Basalt"
    },
    {
      "x": -7,
      "y": 9,
      "z": -5,
      "name": "Rock_Basalt"
    },
    {
      "x": -7,
      "y": 0,
      "z": -4,
      "name": "Rock_Basalt"
    },
    {
      "x": -7,
      "y": 1,
      "z": -4,
      "name": "Rock_Basalt"
    },
    {
      "x": -7,
      "y": 2,
      "z": -4,
      "name": "Rock_Basalt"
    },
    {
      "x": -7,
      "y": 3,
      "z": -4,
      "name": "Rock_Basalt"
    },
    {
      "x": -7,
      "y": 4,
      "z": -4,
      "name": "Rock_Basalt"
    },
    {
      "x": -7,
      "y": 5,
      "z": -4,
      "name": "Rock_Basalt"
    },
    {
      "x": -7,
      "y": 6,
      "z": -4,
      "name": "Rock_Basalt"
    },
    {
      "x": -7,
      "y": 7,
      "z": -4,
      "name": "Rock_Basalt"
    },
    {
      "x": -7,
      "y": 8,
      "z": -4,
      "name": "Rock_Basalt"
    },
    {
      "x": -7,
      "y": 9,
      "z": -4,
      "name": "Rock_Basalt"
    },
    {
      "x": -7,
      "y": 0,
      "z": -3,
      "name": "Rock_Basalt"
    },
    {
      "x": -7,
      "y": 1,
      "z": -3,
      "name": "Rock_Basalt"
    },
    {
      "x": -7,
      "y": 2,
      "z": -3,
      "name": "Rock_Basalt"
    },
    {
      "x": -7,
      "y": 3,
      "z": -3,
      "name": "Rock_Basalt"
    },
    {
      "x": -7,
      "y": 4,
      "z": -3,
      "name": "Rock_Basalt"
    },
    {
      "x": -7,
      "y": 5,
      "z": -3,
      "name": "Rock_Basalt"
    },
    {
      "x": -7,
      "y": 6,
      "z": -3,
      "name": "Rock_Basalt"
    },
    {
      "x": -7,
      "y": 7,
      "z": -3,
      "name": "Rock_Basalt"
    },
    {
      "x": -7,
      "y": 8,
      "z": -3,
      "name": "Rock_Basalt"
    },
    {
      "x": -7,
      "y": 9,
      "z": -3,
      "name": "Rock_Basalt"
    },
    {
      "x": -7,
      "y": 0,
      "z": -2,
      "name": "Rock_Basalt"
    },
    {
      "x": -7,
      "y": 1,
      "z": -2,
      "name": "Rock_Basalt"
    },
    {
      "x": -7,
      "y": 2,
      "z": -2,
      "name": "Rock_Basalt"
    },
    {
      "x": -7,
      "y": 3,
      "z": -2,
      "name": "Rock_Basalt"
    },
    {
      "x": -7,
      "y": 4,
      "z": -2,
      "name": "Rock_Basalt"
    },
    {
      "x": -7,
      "y": 5,
      "z": -2,
      "name": "Rock_Basalt"
    },
    {
      "x": -7,
      "y": 6,
      "z": -2,
      "name": "Rock_Basalt"
    },
    {
      "x": -7,
      "y": 7,
      "z": -2,
      "name": "Rock_Basalt"
    },
    {
      "x": -7,
      "y": 8,
      "z": -2,
      "name": "Rock_Basalt"
    },
    {
      "x": -7,
      "y": 9,
      "z": -2,
      "name": "Rock_Basalt"
    },
    {
      "x": -7,
      "y": 0,
      "z": -1,
      "name": "Rock_Basalt"
    },
    {
      "x": -7,
      "y": 1,
      "z": -1,
      "name": "Rock_Basalt"
    },
    {
      "x": -7,
      "y": 2,
      "z": -1,
      "name": "Rock_Basalt"
    },
    {
      "x": -7,
      "y": 3,
      "z": -1,
      "name": "Rock_Basalt"
    },
    {
      "x": -7,
      "y": 4,
      "z": -1,
      "name": "Rock_Basalt"
    },
    {
      "x": -7,
      "y": 5,
      "z": -1,
      "name": "Rock_Basalt"
    },
    {
      "x": -7,
      "y": 6,
      "z": -1,
      "name": "Rock_Basalt"
    },
    {
      "x": -7,
      "y": 7,
      "z": -1,
      "name": "Rock_Basalt"
    },
    {
      "x": -7,
      "y": 8,
      "z": -1,
      "name": "Rock_Basalt"
    },
    {
      "x": -7,
      "y": 9,
      "z": -1,
      "name": "Rock_Basalt"
    },
    {
      "x": -7,
      "y": 0,
      "z": 0,
      "name": "Rock_Basalt"
    },
    {
      "x": -7,
      "y": 1,
      "z": 0,
      "name": "Rock_Basalt"
    },
    {
      "x": -7,
      "y": 2,
      "z": 0,
      "name": "Rock_Basalt"
    },
    {
      "x": -7,
      "y": 3,
      "z": 0,
      "name": "Rock_Basalt"
    },
    {
      "x": -7,
      "y": 4,
      "z": 0,
      "name": "Rock_Basalt"
    },
    {
      "x": -7,
      "y": 5,
      "z": 0,
      "name": "Rock_Basalt"
    },
    {
      "x": -7,
      "y": 6,
      "z": 0,
      "name": "Rock_Basalt"
    },
    {
      "x": -7,
      "y": 7,
      "z": 0,
      "name": "Rock_Basalt"
    },
    {
      "x": -7,
      "y": 8,
      "z": 0,
      "name": "Rock_Basalt"
    },
    {
      "x": -7,
      "y": 9,
      "z": 0,
      "name": "Rock_Basalt"
    },
    {
      "x": -6,
      "y": 0,
      "z": -25,
      "name": "Rock_Basalt"
    },
    {
      "x": -6,
      "y": 1,
      "z": -25,
      "name": "Rock_Basalt"
    },
    {
      "x": -6,
      "y": 2,
      "z": -25,
      "name": "Rock_Basalt"
    },
    {
      "x": -6,
      "y": 3,
      "z": -25,
      "name": "Rock_Basalt"
    },
    {
      "x": -6,
      "y": 4,
      "z": -25,
      "name": "Rock_Basalt"
    },
    {
      "x": -6,
      "y": 5,
      "z": -25,
      "name": "Rock_Basalt"
    },
    {
      "x": -6,
      "y": 6,
      "z": -25,
      "name": "Rock_Basalt"
    },
    {
      "x": -6,
      "y": 7,
      "z": -25,
      "name": "Rock_Basalt"
    },
    {
      "x": -6,
      "y": 8,
      "z": -25,
      "name": "Rock_Basalt"
    },
    {
      "x": -6,
      "y": 9,
      "z": -25,
      "name": "Rock_Basalt"
    },
    {
      "x": -6,
      "y": 10,
      "z": -25,
      "name": "Rock_Basalt"
    },
    {
      "x": -6,
      "y": 0,
      "z": -24,
      "name": "Rock_Basalt_Cobble"
    },
    {
      "x": -6,
      "y": 1,
      "z": -24,
      "name": "Empty"
    },
    {
      "x": -6,
      "y": 2,
      "z": -24,
      "name": "Empty"
    },
    {
      "x": -6,
      "y": 3,
      "z": -24,
      "name": "Empty"
    },
    {
      "x": -6,
      "y": 4,
      "z": -24,
      "name": "Empty"
    },
    {
      "x": -6,
      "y": 5,
      "z": -24,
      "name": "Empty"
    },
    {
      "x": -6,
      "y": 6,
      "z": -24,
      "name": "Empty"
    },
    {
      "x": -6,
      "y": 7,
      "z": -24,
      "name": "Empty"
    },
    {
      "x": -6,
      "y": 8,
      "z": -24,
      "name": "Empty"
    },
    {
      "x": -6,
      "y": 9,
      "z": -24,
      "name": "Empty"
    },
    {
      "x": -6,
      "y": 10,
      "z": -24,
      "name": "Rock_Basalt"
    },
    {
      "x": -6,
      "y": 0,
      "z": -23,
      "name": "Rock_Basalt_Cobble"
    },
    {
      "x": -6,
      "y": 1,
      "z": -23,
      "name": "Empty"
    },
    {
      "x": -6,
      "y": 2,
      "z": -23,
      "name": "Empty"
    },
    {
      "x": -6,
      "y": 3,
      "z": -23,
      "name": "Empty"
    },
    {
      "x": -6,
      "y": 4,
      "z": -23,
      "name": "Empty"
    },
    {
      "x": -6,
      "y": 5,
      "z": -23,
      "name": "Empty"
    },
    {
      "x": -6,
      "y": 6,
      "z": -23,
      "name": "Empty"
    },
    {
      "x": -6,
      "y": 7,
      "z": -23,
      "name": "Empty"
    },
    {
      "x": -6,
      "y": 8,
      "z": -23,
      "name": "Empty"
    },
    {
      "x": -6,
      "y": 9,
      "z": -23,
      "name": "Empty"
    },
    {
      "x": -6,
      "y": 10,
      "z": -23,
      "name": "Rock_Basalt"
    },
    {
      "x": -6,
      "y": 0,
      "z": -22,
      "name": "Rock_Basalt_Cobble"
    },
    {
      "x": -6,
      "y": 1,
      "z": -22,
      "name": "Empty"
    },
    {
      "x": -6,
      "y": 2,
      "z": -22,
      "name": "Empty"
    },
    {
      "x": -6,
      "y": 3,
      "z": -22,
      "name": "Empty"
    },
    {
      "x": -6,
      "y": 4,
      "z": -22,
      "name": "Empty"
    },
    {
      "x": -6,
      "y": 5,
      "z": -22,
      "name": "Empty"
    },
    {
      "x": -6,
      "y": 6,
      "z": -22,
      "name": "Empty"
    },
    {
      "x": -6,
      "y": 7,
      "z": -22,
      "name": "Empty"
    },
    {
      "x": -6,
      "y": 8,
      "z": -22,
      "name": "Empty"
    },
    {
      "x": -6,
      "y": 9,
      "z": -22,
      "name": "Empty"
    },
    {
      "x": -6,
      "y": 10,
      "z": -22,
      "name": "Rock_Basalt"
    },
    {
      "x": -6,
      "y": 0,
      "z": -21,
      "name": "Rock_Basalt_Cobble"
    },
    {
      "x": -6,
      "y": 1,
      "z": -21,
      "name": "Empty"
    },
    {
      "x": -6,
      "y": 2,
      "z": -21,
      "name": "Empty"
    },
    {
      "x": -6,
      "y": 3,
      "z": -21,
      "name": "Empty"
    },
    {
      "x": -6,
      "y": 4,
      "z": -21,
      "name": "Empty"
    },
    {
      "x": -6,
      "y": 5,
      "z": -21,
      "name": "Empty"
    },
    {
      "x": -6,
      "y": 6,
      "z": -21,
      "name": "Empty"
    },
    {
      "x": -6,
      "y": 7,
      "z": -21,
      "name": "Empty"
    },
    {
      "x": -6,
      "y": 8,
      "z": -21,
      "name": "Empty"
    },
    {
      "x": -6,
      "y": 9,
      "z": -21,
      "name": "Empty"
    },
    {
      "x": -6,
      "y": 10,
      "z": -21,
      "name": "Rock_Basalt"
    },
    {
      "x": -6,
      "y": 0,
      "z": -20,
      "name": "Rock_Basalt_Cobble"
    },
    {
      "x": -6,
      "y": 1,
      "z": -20,
      "name": "Empty"
    },
    {
      "x": -6,
      "y": 2,
      "z": -20,
      "name": "Empty"
    },
    {
      "x": -6,
      "y": 3,
      "z": -20,
      "name": "Empty"
    },
    {
      "x": -6,
      "y": 4,
      "z": -20,
      "name": "Empty"
    },
    {
      "x": -6,
      "y": 5,
      "z": -20,
      "name": "Empty"
    },
    {
      "x": -6,
      "y": 6,
      "z": -20,
      "name": "Empty"
    },
    {
      "x": -6,
      "y": 7,
      "z": -20,
      "name": "Empty"
    },
    {
      "x": -6,
      "y": 8,
      "z": -20,
      "name": "Empty"
    },
    {
      "x": -6,
      "y": 9,
      "z": -20,
      "name": "Empty"
    },
    {
      "x": -6,
      "y": 10,
      "z": -20,
      "name": "Rock_Basalt"
    },
    {
      "x": -6,
      "y": 0,
      "z": -19,
      "name": "Rock_Basalt_Cobble"
    },
    {
      "x": -6,
      "y": 1,
      "z": -19,
      "name": "Empty"
    },
    {
      "x": -6,
      "y": 2,
      "z": -19,
      "name": "Empty"
    },
    {
      "x": -6,
      "y": 3,
      "z": -19,
      "name": "Empty"
    },
    {
      "x": -6,
      "y": 4,
      "z": -19,
      "name": "Empty"
    },
    {
      "x": -6,
      "y": 5,
      "z": -19,
      "name": "Empty"
    },
    {
      "x": -6,
      "y": 6,
      "z": -19,
      "name": "Empty"
    },
    {
      "x": -6,
      "y": 7,
      "z": -19,
      "name": "Empty"
    },
    {
      "x": -6,
      "y": 8,
      "z": -19,
      "name": "Empty"
    },
    {
      "x": -6,
      "y": 9,
      "z": -19,
      "name": "Empty"
    },
    {
      "x": -6,
      "y": 10,
      "z": -19,
      "name": "Rock_Basalt"
    },
    {
      "x": -6,
      "y": 0,
      "z": -18,
      "name": "Rock_Basalt_Cobble"
    },
    {
      "x": -6,
      "y": 1,
      "z": -18,
      "name": "Empty"
    },
    {
      "x": -6,
      "y": 2,
      "z": -18,
      "name": "Empty"
    },
    {
      "x": -6,
      "y": 3,
      "z": -18,
      "name": "Empty"
    },
    {
      "x": -6,
      "y": 4,
      "z": -18,
      "name": "Empty"
    },
    {
      "x": -6,
      "y": 5,
      "z": -18,
      "name": "Empty"
    },
    {
      "x": -6,
      "y": 6,
      "z": -18,
      "name": "Empty"
    },
    {
      "x": -6,
      "y": 7,
      "z": -18,
      "name": "Empty"
    },
    {
      "x": -6,
      "y": 8,
      "z": -18,
      "name": "Empty"
    },
    {
      "x": -6,
      "y": 9,
      "z": -18,
      "name": "Empty"
    },
    {
      "x": -6,
      "y": 10,
      "z": -18,
      "name": "Rock_Basalt"
    },
    {
      "x": -6,
      "y": 0,
      "z": -17,
      "name": "Rock_Basalt_Cobble"
    },
    {
      "x": -6,
      "y": 1,
      "z": -17,
      "name": "Empty"
    },
    {
      "x": -6,
      "y": 2,
      "z": -17,
      "name": "Empty"
    },
    {
      "x": -6,
      "y": 3,
      "z": -17,
      "name": "Empty"
    },
    {
      "x": -6,
      "y": 4,
      "z": -17,
      "name": "Empty"
    },
    {
      "x": -6,
      "y": 5,
      "z": -17,
      "name": "Empty"
    },
    {
      "x": -6,
      "y": 6,
      "z": -17,
      "name": "Empty"
    },
    {
      "x": -6,
      "y": 7,
      "z": -17,
      "name": "Empty"
    },
    {
      "x": -6,
      "y": 8,
      "z": -17,
      "name": "Empty"
    },
    {
      "x": -6,
      "y": 9,
      "z": -17,
      "name": "Empty"
    },
    {
      "x": -6,
      "y": 10,
      "z": -17,
      "name": "Rock_Basalt"
    },
    {
      "x": -6,
      "y": 0,
      "z": -16,
      "name": "Rock_Basalt_Cobble"
    },
    {
      "x": -6,
      "y": 1,
      "z": -16,
      "name": "Empty"
    },
    {
      "x": -6,
      "y": 2,
      "z": -16,
      "name": "Empty"
    },
    {
      "x": -6,
      "y": 3,
      "z": -16,
      "name": "Empty"
    },
    {
      "x": -6,
      "y": 4,
      "z": -16,
      "name": "Empty"
    },
    {
      "x": -6,
      "y": 5,
      "z": -16,
      "name": "Empty"
    },
    {
      "x": -6,
      "y": 6,
      "z": -16,
      "name": "Empty"
    },
    {
      "x": -6,
      "y": 7,
      "z": -16,
      "name": "Empty"
    },
    {
      "x": -6,
      "y": 8,
      "z": -16,
      "name": "Empty"
    },
    {
      "x": -6,
      "y": 9,
      "z": -16,
      "name": "Empty"
    },
    {
      "x": -6,
      "y": 10,
      "z": -16,
      "name": "Rock_Basalt"
    },
    {
      "x": -6,
      "y": 0,
      "z": -15,
      "name": "Rock_Basalt_Cobble"
    },
    {
      "x": -6,
      "y": 1,
      "z": -15,
      "name": "Empty"
    },
    {
      "x": -6,
      "y": 2,
      "z": -15,
      "name": "Empty"
    },
    {
      "x": -6,
      "y": 3,
      "z": -15,
      "name": "Empty"
    },
    {
      "x": -6,
      "y": 4,
      "z": -15,
      "name": "Empty"
    },
    {
      "x": -6,
      "y": 5,
      "z": -15,
      "name": "Empty"
    },
    {
      "x": -6,
      "y": 6,
      "z": -15,
      "name": "Empty"
    },
    {
      "x": -6,
      "y": 7,
      "z": -15,
      "name": "Empty"
    },
    {
      "x": -6,
      "y": 8,
      "z": -15,
      "name": "Empty"
    },
    {
      "x": -6,
      "y": 9,
      "z": -15,
      "name": "Empty"
    },
    {
      "x": -6,
      "y": 10,
      "z": -15,
      "name": "Rock_Basalt"
    },
    {
      "x": -6,
      "y": 0,
      "z": -14,
      "name": "Rock_Basalt_Cobble"
    },
    {
      "x": -6,
      "y": 1,
      "z": -14,
      "name": "Wood_Deadwood_Stairs",
      "rotation": 2
    },
    {
      "x": -6,
      "y": 2,
      "z": -14,
      "name": "Empty"
    },
    {
      "x": -6,
      "y": 3,
      "z": -14,
      "name": "Empty"
    },
    {
      "x": -6,
      "y": 4,
      "z": -14,
      "name": "Empty"
    },
    {
      "x": -6,
      "y": 5,
      "z": -14,
      "name": "Empty"
    },
    {
      "x": -6,
      "y": 6,
      "z": -14,
      "name": "Empty"
    },
    {
      "x": -6,
      "y": 7,
      "z": -14,
      "name": "Empty"
    },
    {
      "x": -6,
      "y": 8,
      "z": -14,
      "name": "Empty"
    },
    {
      "x": -6,
      "y": 9,
      "z": -14,
      "name": "Empty"
    },
    {
      "x": -6,
      "y": 10,
      "z": -14,
      "name": "Rock_Basalt"
    },
    {
      "x": -6,
      "y": 0,
      "z": -13,
      "name": "Rock_Basalt_Cobble"
    },
    {
      "x": -6,
      "y": 1,
      "z": -13,
      "name": "Wood_Deadwood_Planks"
    },
    {
      "x": -6,
      "y": 2,
      "z": -13,
      "name": "Wood_Deadwood_Stairs",
      "rotation": 2
    },
    {
      "x": -6,
      "y": 3,
      "z": -13,
      "name": "Empty"
    },
    {
      "x": -6,
      "y": 4,
      "z": -13,
      "name": "Empty"
    },
    {
      "x": -6,
      "y": 5,
      "z": -13,
      "name": "Empty"
    },
    {
      "x": -6,
      "y": 6,
      "z": -13,
      "name": "Empty"
    },
    {
      "x": -6,
      "y": 7,
      "z": -13,
      "name": "Empty"
    },
    {
      "x": -6,
      "y": 8,
      "z": -13,
      "name": "Empty"
    },
    {
      "x": -6,
      "y": 9,
      "z": -13,
      "name": "Empty"
    },
    {
      "x": -6,
      "y": 10,
      "z": -13,
      "name": "Rock_Basalt"
    },
    {
      "x": -6,
      "y": 0,
      "z": -12,
      "name": "Rock_Basalt_Cobble"
    },
    {
      "x": -6,
      "y": 1,
      "z": -12,
      "name": "Empty"
    },
    {
      "x": -6,
      "y": 2,
      "z": -12,
      "name": "Wood_Deadwood_Planks"
    },
    {
      "x": -6,
      "y": 3,
      "z": -12,
      "name": "Wood_Deadwood_Stairs",
      "rotation": 2
    },
    {
      "x": -6,
      "y": 4,
      "z": -12,
      "name": "Empty"
    },
    {
      "x": -6,
      "y": 5,
      "z": -12,
      "name": "Empty"
    },
    {
      "x": -6,
      "y": 6,
      "z": -12,
      "name": "Empty"
    },
    {
      "x": -6,
      "y": 7,
      "z": -12,
      "name": "Empty"
    },
    {
      "x": -6,
      "y": 8,
      "z": -12,
      "name": "Empty"
    },
    {
      "x": -6,
      "y": 9,
      "z": -12,
      "name": "Empty"
    },
    {
      "x": -6,
      "y": 10,
      "z": -12,
      "name": "Rock_Basalt"
    },
    {
      "x": -6,
      "y": 0,
      "z": -11,
      "name": "Rock_Basalt_Cobble"
    },
    {
      "x": -6,
      "y": 1,
      "z": -11,
      "name": "Empty"
    },
    {
      "x": -6,
      "y": 2,
      "z": -11,
      "name": "Empty"
    },
    {
      "x": -6,
      "y": 3,
      "z": -11,
      "name": "Wood_Deadwood_Planks"
    },
    {
      "x": -6,
      "y": 4,
      "z": -11,
      "name": "Wood_Deadwood_Stairs",
      "rotation": 2
    },
    {
      "x": -6,
      "y": 5,
      "z": -11,
      "name": "Empty"
    },
    {
      "x": -6,
      "y": 6,
      "z": -11,
      "name": "Empty"
    },
    {
      "x": -6,
      "y": 7,
      "z": -11,
      "name": "Empty"
    },
    {
      "x": -6,
      "y": 8,
      "z": -11,
      "name": "Empty"
    },
    {
      "x": -6,
      "y": 9,
      "z": -11,
      "name": "Empty"
    },
    {
      "x": -6,
      "y": 10,
      "z": -11,
      "name": "Rock_Basalt"
    },
    {
      "x": -6,
      "y": 0,
      "z": -10,
      "name": "Rock_Basalt_Cobble"
    },
    {
      "x": -6,
      "y": 1,
      "z": -10,
      "name": "Empty"
    },
    {
      "x": -6,
      "y": 2,
      "z": -10,
      "name": "Empty"
    },
    {
      "x": -6,
      "y": 3,
      "z": -10,
      "name": "Empty"
    },
    {
      "x": -6,
      "y": 4,
      "z": -10,
      "name": "Wood_Deadwood_Planks"
    },
    {
      "x": -6,
      "y": 5,
      "z": -10,
      "name": "Wood_Deadwood_Stairs",
      "rotation": 2
    },
    {
      "x": -6,
      "y": 6,
      "z": -10,
      "name": "Empty"
    },
    {
      "x": -6,
      "y": 7,
      "z": -10,
      "name": "Empty"
    },
    {
      "x": -6,
      "y": 8,
      "z": -10,
      "name": "Empty"
    },
    {
      "x": -6,
      "y": 9,
      "z": -10,
      "name": "Empty"
    },
    {
      "x": -6,
      "y": 10,
      "z": -10,
      "name": "Rock_Basalt"
    },
    {
      "x": -6,
      "y": 0,
      "z": -9,
      "name": "Rock_Basalt_Cobble"
    },
    {
      "x": -6,
      "y": 1,
      "z": -9,
      "name": "Furniture_Ancient_Crate",
      "rotation": 1
    },
    {
      "x": -6,
      "y": 2,
      "z": -9,
      "name": "Empty"
    },
    {
      "x": -6,
      "y": 3,
      "z": -9,
      "name": "Empty"
    },
    {
      "x": -6,
      "y": 4,
      "z": -9,
      "name": "Empty"
    },
    {
      "x": -6,
      "y": 5,
      "z": -9,
      "name": "Wood_Deadwood_Planks"
    },
    {
      "x": -6,
      "y": 6,
      "z": -9,
      "name": "Empty"
    },
    {
      "x": -6,
      "y": 7,
      "z": -9,
      "name": "Empty"
    },
    {
      "x": -6,
      "y": 8,
      "z": -9,
      "name": "Empty"
    },
    {
      "x": -6,
      "y": 9,
      "z": -9,
      "name": "Empty"
    },
    {
      "x": -6,
      "y": 10,
      "z": -9,
      "name": "Rock_Basalt"
    },
    {
      "x": -6,
      "y": 0,
      "z": -8,
      "name": "Rock_Basalt_Cobble"
    },
    {
      "x": -6,
      "y": 1,
      "z": -8,
      "name": "Empty"
    },
    {
      "x": -6,
      "y": 2,
      "z": -8,
      "name": "Empty"
    },
    {
      "x": -6,
      "y": 3,
      "z": -8,
      "name": "Empty"
    },
    {
      "x": -6,
      "y": 4,
      "z": -8,
      "name": "Empty"
    },
    {
      "x": -6,
      "y": 5,
      "z": -8,
      "name": "Wood_Deadwood_Planks"
    },
    {
      "x": -6,
      "y": 6,
      "z": -8,
      "name": "Empty"
    },
    {
      "x": -6,
      "y": 7,
      "z": -8,
      "name": "Empty"
    },
    {
      "x": -6,
      "y": 8,
      "z": -8,
      "name": "Empty"
    },
    {
      "x": -6,
      "y": 9,
      "z": -8,
      "name": "Empty"
    },
    {
      "x": -6,
      "y": 10,
      "z": -8,
      "name": "Rock_Basalt"
    },
    {
      "x": -6,
      "y": 0,
      "z": -7,
      "name": "Rock_Basalt_Cobble"
    },
    {
      "x": -6,
      "y": 1,
      "z": -7,
      "name": "Furniture_Ancient_Barrel"
    },
    {
      "x": -6,
      "y": 2,
      "z": -7,
      "name": "Empty"
    },
    {
      "x": -6,
      "y": 3,
      "z": -7,
      "name": "Empty"
    },
    {
      "x": -6,
      "y": 4,
      "z": -7,
      "name": "Empty"
    },
    {
      "x": -6,
      "y": 5,
      "z": -7,
      "name": "Wood_Deadwood_Planks"
    },
    {
      "x": -6,
      "y": 6,
      "z": -7,
      "name": "Empty"
    },
    {
      "x": -6,
      "y": 7,
      "z": -7,
      "name": "Empty"
    },
    {
      "x": -6,
      "y": 8,
      "z": -7,
      "name": "Empty"
    },
    {
      "x": -6,
      "y": 9,
      "z": -7,
      "name": "Empty"
    },
    {
      "x": -6,
      "y": 10,
      "z": -7,
      "name": "Rock_Basalt"
    },
    {
      "x": -6,
      "y": 0,
      "z": -6,
      "name": "Rock_Basalt_Cobble"
    },
    {
      "x": -6,
      "y": 1,
      "z": -6,
      "name": "Rock_Basalt"
    },
    {
      "x": -6,
      "y": 2,
      "z": -6,
      "name": "Rock_Basalt"
    },
    {
      "x": -6,
      "y": 3,
      "z": -6,
      "name": "Rock_Basalt"
    },
    {
      "x": -6,
      "y": 4,
      "z": -6,
      "name": "Rock_Basalt"
    },
    {
      "x": -6,
      "y": 5,
      "z": -6,
      "name": "Rock_Basalt"
    },
    {
      "x": -6,
      "y": 6,
      "z": -6,
      "name": "Rock_Basalt"
    },
    {
      "x": -6,
      "y": 7,
      "z": -6,
      "name": "Rock_Basalt"
    },
    {
      "x": -6,
      "y": 8,
      "z": -6,
      "name": "Rock_Basalt"
    },
    {
      "x": -6,
      "y": 9,
      "z": -6,
      "name": "Rock_Basalt"
    },
    {
      "x": -6,
      "y": 10,
      "z": -6,
      "name": "Rock_Basalt"
    },
    {
      "x": -6,
      "y": 0,
      "z": -5,
      "name": "Rock_Basalt_Cobble"
    },
    {
      "x": -6,
      "y": 1,
      "z": -5,
      "name": "Rock_Basalt_Brick_Smooth"
    },
    {
      "x": -6,
      "y": 2,
      "z": -5,
      "name": "Rock_Basalt_Cobble"
    },
    {
      "x": -6,
      "y": 3,
      "z": -5,
      "name": "Rock_Basalt_Cobble"
    },
    {
      "x": -6,
      "y": 4,
      "z": -5,
      "name": "Rock_Basalt_Cobble"
    },
    {
      "x": -6,
      "y": 5,
      "z": -5,
      "name": "Rock_Basalt_Cobble"
    },
    {
      "x": -6,
      "y": 6,
      "z": -5,
      "name": "Rock_Basalt_Cobble"
    },
    {
      "x": -6,
      "y": 7,
      "z": -5,
      "name": "Rock_Basalt_Cobble"
    },
    {
      "x": -6,
      "y": 8,
      "z": -5,
      "name": "Rock_Basalt_Cobble"
    },
    {
      "x": -6,
      "y": 9,
      "z": -5,
      "name": "Rock_Basalt"
    },
    {
      "x": -6,
      "y": 0,
      "z": -4,
      "name": "Rock_Basalt_Cobble"
    },
    {
      "x": -6,
      "y": 1,
      "z": -4,
      "name": "Rock_Basalt_Brick_Smooth"
    },
    {
      "x": -6,
      "y": 2,
      "z": -4,
      "name": "Rock_Basalt_Cobble"
    },
    {
      "x": -6,
      "y": 3,
      "z": -4,
      "name": "Rock_Basalt_Cobble"
    },
    {
      "x": -6,
      "y": 4,
      "z": -4,
      "name": "Rock_Basalt_Cobble"
    },
    {
      "x": -6,
      "y": 5,
      "z": -4,
      "name": "Rock_Basalt_Cobble"
    },
    {
      "x": -6,
      "y": 6,
      "z": -4,
      "name": "Rock_Basalt_Cobble"
    },
    {
      "x": -6,
      "y": 7,
      "z": -4,
      "name": "Rock_Basalt_Cobble"
    },
    {
      "x": -6,
      "y": 8,
      "z": -4,
      "name": "Rock_Basalt_Cobble"
    },
    {
      "x": -6,
      "y": 9,
      "z": -4,
      "name": "Rock_Basalt"
    },
    {
      "x": -6,
      "y": 0,
      "z": -3,
      "name": "Rock_Basalt_Cobble"
    },
    {
      "x": -6,
      "y": 1,
      "z": -3,
      "name": "Rock_Basalt_Brick_Smooth"
    },
    {
      "x": -6,
      "y": 2,
      "z": -3,
      "name": "Rock_Basalt_Cobble_Half",
      "rotation": 5
    },
    {
      "x": -6,
      "y": 3,
      "z": -3,
      "name": "Rock_Basalt_Cobble_Half",
      "rotation": 5
    },
    {
      "x": -6,
      "y": 4,
      "z": -3,
      "name": "Rock_Basalt_Cobble_Half",
      "rotation": 5
    },
    {
      "x": -6,
      "y": 5,
      "z": -3,
      "name": "Rock_Basalt_Cobble_Half",
      "rotation": 5
    },
    {
      "x": -6,
      "y": 6,
      "z": -3,
      "name": "Rock_Basalt_Cobble_Half",
      "rotation": 5
    },
    {
      "x": -6,
      "y": 7,
      "z": -3,
      "name": "Rock_Basalt_Cobble"
    },
    {
      "x": -6,
      "y": 8,
      "z": -3,
      "name": "Rock_Basalt_Cobble"
    },
    {
      "x": -6,
      "y": 9,
      "z": -3,
      "name": "Rock_Basalt"
    },
    {
      "x": -6,
      "y": 0,
      "z": -2,
      "name": "Rock_Basalt_Cobble"
    },
    {
      "x": -6,
      "y": 1,
      "z": -2,
      "name": "Rock_Basalt_Brick_Smooth"
    },
    {
      "x": -6,
      "y": 2,
      "z": -2,
      "name": "Rock_Basalt_Cobble"
    },
    {
      "x": -6,
      "y": 3,
      "z": -2,
      "name": "Rock_Basalt_Cobble"
    },
    {
      "x": -6,
      "y": 4,
      "z": -2,
      "name": "Rock_Basalt_Cobble"
    },
    {
      "x": -6,
      "y": 5,
      "z": -2,
      "name": "Rock_Basalt_Cobble"
    },
    {
      "x": -6,
      "y": 6,
      "z": -2,
      "name": "Rock_Basalt_Cobble"
    },
    {
      "x": -6,
      "y": 7,
      "z": -2,
      "name": "Rock_Basalt_Cobble"
    },
    {
      "x": -6,
      "y": 8,
      "z": -2,
      "name": "Rock_Basalt_Cobble"
    },
    {
      "x": -6,
      "y": 9,
      "z": -2,
      "name": "Rock_Basalt"
    },
    {
      "x": -6,
      "y": 0,
      "z": -1,
      "name": "Rock_Basalt_Cobble"
    },
    {
      "x": -6,
      "y": 1,
      "z": -1,
      "name": "Rock_Basalt_Brick_Smooth"
    },
    {
      "x": -6,
      "y": 2,
      "z": -1,
      "name": "Rock_Basalt_Cobble"
    },
    {
      "x": -6,
      "y": 3,
      "z": -1,
      "name": "Rock_Basalt_Cobble"
    },
    {
      "x": -6,
      "y": 4,
      "z": -1,
      "name": "Rock_Basalt_Cobble"
    },
    {
      "x": -6,
      "y": 5,
      "z": -1,
      "name": "Rock_Basalt_Cobble"
    },
    {
      "x": -6,
      "y": 6,
      "z": -1,
      "name": "Rock_Basalt_Cobble"
    },
    {
      "x": -6,
      "y": 7,
      "z": -1,
      "name": "Rock_Basalt_Cobble"
    },
    {
      "x": -6,
      "y": 8,
      "z": -1,
      "name": "Rock_Basalt_Cobble"
    },
    {
      "x": -6,
      "y": 9,
      "z": -1,
      "name": "Rock_Basalt"
    },
    {
      "x": -6,
      "y": 0,
      "z": 0,
      "name": "Rock_Basalt"
    },
    {
      "x": -6,
      "y": 1,
      "z": 0,
      "name": "Rock_Basalt"
    },
    {
      "x": -6,
      "y": 2,
      "z": 0,
      "name": "Rock_Basalt"
    },
    {
      "x": -6,
      "y": 3,
      "z": 0,
      "name": "Rock_Basalt"
    },
    {
      "x": -6,
      "y": 4,
      "z": 0,
      "name": "Rock_Basalt"
    },
    {
      "x": -6,
      "y": 5,
      "z": 0,
      "name": "Rock_Basalt"
    },
    {
      "x": -6,
      "y": 6,
      "z": 0,
      "name": "Rock_Basalt"
    },
    {
      "x": -6,
      "y": 7,
      "z": 0,
      "name": "Rock_Basalt"
    },
    {
      "x": -6,
      "y": 8,
      "z": 0,
      "name": "Rock_Basalt"
    },
    {
      "x": -6,
      "y": 9,
      "z": 0,
      "name": "Rock_Basalt"
    },
    {
      "x": -5,
      "y": 0,
      "z": -25,
      "name": "Rock_Basalt"
    },
    {
      "x": -5,
      "y": 1,
      "z": -25,
      "name": "Rock_Basalt"
    },
    {
      "x": -5,
      "y": 2,
      "z": -25,
      "name": "Rock_Basalt"
    },
    {
      "x": -5,
      "y": 3,
      "z": -25,
      "name": "Rock_Basalt"
    },
    {
      "x": -5,
      "y": 4,
      "z": -25,
      "name": "Rock_Basalt"
    },
    {
      "x": -5,
      "y": 5,
      "z": -25,
      "name": "Rock_Basalt"
    },
    {
      "x": -5,
      "y": 6,
      "z": -25,
      "name": "Rock_Basalt"
    },
    {
      "x": -5,
      "y": 7,
      "z": -25,
      "name": "Rock_Basalt"
    },
    {
      "x": -5,
      "y": 8,
      "z": -25,
      "name": "Rock_Basalt"
    },
    {
      "x": -5,
      "y": 9,
      "z": -25,
      "name": "Rock_Basalt"
    },
    {
      "x": -5,
      "y": 10,
      "z": -25,
      "name": "Rock_Basalt"
    },
    {
      "x": -5,
      "y": 0,
      "z": -24,
      "name": "Rock_Basalt_Cobble"
    },
    {
      "x": -5,
      "y": 1,
      "z": -24,
      "name": "Empty"
    },
    {
      "x": -5,
      "y": 2,
      "z": -24,
      "name": "Empty"
    },
    {
      "x": -5,
      "y": 3,
      "z": -24,
      "name": "Empty"
    },
    {
      "x": -5,
      "y": 4,
      "z": -24,
      "name": "Empty"
    },
    {
      "x": -5,
      "y": 5,
      "z": -24,
      "name": "Empty"
    },
    {
      "x": -5,
      "y": 6,
      "z": -24,
      "name": "Empty"
    },
    {
      "x": -5,
      "y": 7,
      "z": -24,
      "name": "Empty"
    },
    {
      "x": -5,
      "y": 8,
      "z": -24,
      "name": "Empty"
    },
    {
      "x": -5,
      "y": 9,
      "z": -24,
      "name": "Empty"
    },
    {
      "x": -5,
      "y": 10,
      "z": -24,
      "name": "Rock_Basalt"
    },
    {
      "x": -5,
      "y": 0,
      "z": -23,
      "name": "Rock_Basalt_Cobble"
    },
    {
      "x": -5,
      "y": 1,
      "z": -23,
      "name": "Empty"
    },
    {
      "x": -5,
      "y": 2,
      "z": -23,
      "name": "Empty"
    },
    {
      "x": -5,
      "y": 3,
      "z": -23,
      "name": "Empty"
    },
    {
      "x": -5,
      "y": 4,
      "z": -23,
      "name": "Empty"
    },
    {
      "x": -5,
      "y": 5,
      "z": -23,
      "name": "Empty"
    },
    {
      "x": -5,
      "y": 6,
      "z": -23,
      "name": "Empty"
    },
    {
      "x": -5,
      "y": 7,
      "z": -23,
      "name": "Empty"
    },
    {
      "x": -5,
      "y": 8,
      "z": -23,
      "name": "Empty"
    },
    {
      "x": -5,
      "y": 9,
      "z": -23,
      "name": "Empty"
    },
    {
      "x": -5,
      "y": 10,
      "z": -23,
      "name": "Rock_Basalt"
    },
    {
      "x": -5,
      "y": 0,
      "z": -22,
      "name": "Rock_Basalt_Cobble"
    },
    {
      "x": -5,
      "y": 1,
      "z": -22,
      "name": "Empty"
    },
    {
      "x": -5,
      "y": 2,
      "z": -22,
      "name": "Empty"
    },
    {
      "x": -5,
      "y": 3,
      "z": -22,
      "name": "Empty"
    },
    {
      "x": -5,
      "y": 4,
      "z": -22,
      "name": "Empty"
    },
    {
      "x": -5,
      "y": 5,
      "z": -22,
      "name": "Empty"
    },
    {
      "x": -5,
      "y": 6,
      "z": -22,
      "name": "Empty"
    },
    {
      "x": -5,
      "y": 7,
      "z": -22,
      "name": "Empty"
    },
    {
      "x": -5,
      "y": 8,
      "z": -22,
      "name": "Empty"
    },
    {
      "x": -5,
      "y": 9,
      "z": -22,
      "name": "Empty"
    },
    {
      "x": -5,
      "y": 10,
      "z": -22,
      "name": "Rock_Basalt"
    },
    {
      "x": -5,
      "y": 0,
      "z": -21,
      "name": "Rock_Basalt_Cobble"
    },
    {
      "x": -5,
      "y": 1,
      "z": -21,
      "name": "Empty"
    },
    {
      "x": -5,
      "y": 2,
      "z": -21,
      "name": "Empty"
    },
    {
      "x": -5,
      "y": 3,
      "z": -21,
      "name": "Empty"
    },
    {
      "x": -5,
      "y": 4,
      "z": -21,
      "name": "Empty"
    },
    {
      "x": -5,
      "y": 5,
      "z": -21,
      "name": "Empty"
    },
    {
      "x": -5,
      "y": 6,
      "z": -21,
      "name": "Empty"
    },
    {
      "x": -5,
      "y": 7,
      "z": -21,
      "name": "Empty"
    },
    {
      "x": -5,
      "y": 8,
      "z": -21,
      "name": "Empty"
    },
    {
      "x": -5,
      "y": 9,
      "z": -21,
      "name": "Empty"
    },
    {
      "x": -5,
      "y": 10,
      "z": -21,
      "name": "Rock_Basalt"
    },
    {
      "x": -5,
      "y": 0,
      "z": -20,
      "name": "Rock_Basalt_Cobble"
    },
    {
      "x": -5,
      "y": 1,
      "z": -20,
      "name": "Empty"
    },
    {
      "x": -5,
      "y": 2,
      "z": -20,
      "name": "Empty"
    },
    {
      "x": -5,
      "y": 3,
      "z": -20,
      "name": "Empty"
    },
    {
      "x": -5,
      "y": 4,
      "z": -20,
      "name": "Empty"
    },
    {
      "x": -5,
      "y": 5,
      "z": -20,
      "name": "Empty"
    },
    {
      "x": -5,
      "y": 6,
      "z": -20,
      "name": "Empty"
    },
    {
      "x": -5,
      "y": 7,
      "z": -20,
      "name": "Empty"
    },
    {
      "x": -5,
      "y": 8,
      "z": -20,
      "name": "Empty"
    },
    {
      "x": -5,
      "y": 9,
      "z": -20,
      "name": "Empty"
    },
    {
      "x": -5,
      "y": 10,
      "z": -20,
      "name": "Rock_Basalt"
    },
    {
      "x": -5,
      "y": 0,
      "z": -19,
      "name": "Rock_Basalt_Cobble"
    },
    {
      "x": -5,
      "y": 1,
      "z": -19,
      "name": "Empty"
    },
    {
      "x": -5,
      "y": 2,
      "z": -19,
      "name": "Empty"
    },
    {
      "x": -5,
      "y": 3,
      "z": -19,
      "name": "Empty"
    },
    {
      "x": -5,
      "y": 4,
      "z": -19,
      "name": "Empty"
    },
    {
      "x": -5,
      "y": 5,
      "z": -19,
      "name": "Empty"
    },
    {
      "x": -5,
      "y": 6,
      "z": -19,
      "name": "Empty"
    },
    {
      "x": -5,
      "y": 7,
      "z": -19,
      "name": "Empty"
    },
    {
      "x": -5,
      "y": 8,
      "z": -19,
      "name": "Empty"
    },
    {
      "x": -5,
      "y": 9,
      "z": -19,
      "name": "Empty"
    },
    {
      "x": -5,
      "y": 10,
      "z": -19,
      "name": "Rock_Basalt"
    },
    {
      "x": -5,
      "y": 0,
      "z": -18,
      "name": "Rock_Basalt_Cobble"
    },
    {
      "x": -5,
      "y": 1,
      "z": -18,
      "name": "Empty"
    },
    {
      "x": -5,
      "y": 2,
      "z": -18,
      "name": "Empty"
    },
    {
      "x": -5,
      "y": 3,
      "z": -18,
      "name": "Empty"
    },
    {
      "x": -5,
      "y": 4,
      "z": -18,
      "name": "Empty"
    },
    {
      "x": -5,
      "y": 5,
      "z": -18,
      "name": "Empty"
    },
    {
      "x": -5,
      "y": 6,
      "z": -18,
      "name": "Empty"
    },
    {
      "x": -5,
      "y": 7,
      "z": -18,
      "name": "Empty"
    },
    {
      "x": -5,
      "y": 8,
      "z": -18,
      "name": "Empty"
    },
    {
      "x": -5,
      "y": 9,
      "z": -18,
      "name": "Empty"
    },
    {
      "x": -5,
      "y": 10,
      "z": -18,
      "name": "Rock_Basalt"
    },
    {
      "x": -5,
      "y": 0,
      "z": -17,
      "name": "Rock_Basalt_Cobble"
    },
    {
      "x": -5,
      "y": 1,
      "z": -17,
      "name": "Empty"
    },
    {
      "x": -5,
      "y": 2,
      "z": -17,
      "name": "Empty"
    },
    {
      "x": -5,
      "y": 3,
      "z": -17,
      "name": "Empty"
    },
    {
      "x": -5,
      "y": 4,
      "z": -17,
      "name": "Empty"
    },
    {
      "x": -5,
      "y": 5,
      "z": -17,
      "name": "Empty"
    },
    {
      "x": -5,
      "y": 6,
      "z": -17,
      "name": "Empty"
    },
    {
      "x": -5,
      "y": 7,
      "z": -17,
      "name": "Empty"
    },
    {
      "x": -5,
      "y": 8,
      "z": -17,
      "name": "Empty"
    },
    {
      "x": -5,
      "y": 9,
      "z": -17,
      "name": "Empty"
    },
    {
      "x": -5,
      "y": 10,
      "z": -17,
      "name": "Rock_Basalt"
    },
    {
      "x": -5,
      "y": 0,
      "z": -16,
      "name": "Rock_Basalt_Cobble"
    },
    {
      "x": -5,
      "y": 1,
      "z": -16,
      "name": "Empty"
    },
    {
      "x": -5,
      "y": 2,
      "z": -16,
      "name": "Empty"
    },
    {
      "x": -5,
      "y": 3,
      "z": -16,
      "name": "Empty"
    },
    {
      "x": -5,
      "y": 4,
      "z": -16,
      "name": "Empty"
    },
    {
      "x": -5,
      "y": 5,
      "z": -16,
      "name": "Empty"
    },
    {
      "x": -5,
      "y": 6,
      "z": -16,
      "name": "Empty"
    },
    {
      "x": -5,
      "y": 7,
      "z": -16,
      "name": "Empty"
    },
    {
      "x": -5,
      "y": 8,
      "z": -16,
      "name": "Empty"
    },
    {
      "x": -5,
      "y": 9,
      "z": -16,
      "name": "Empty"
    },
    {
      "x": -5,
      "y": 10,
      "z": -16,
      "name": "Rock_Basalt"
    },
    {
      "x": -5,
      "y": 0,
      "z": -15,
      "name": "Rock_Basalt_Cobble"
    },
    {
      "x": -5,
      "y": 1,
      "z": -15,
      "name": "Empty"
    },
    {
      "x": -5,
      "y": 2,
      "z": -15,
      "name": "Empty"
    },
    {
      "x": -5,
      "y": 3,
      "z": -15,
      "name": "Empty"
    },
    {
      "x": -5,
      "y": 4,
      "z": -15,
      "name": "Empty"
    },
    {
      "x": -5,
      "y": 5,
      "z": -15,
      "name": "Empty"
    },
    {
      "x": -5,
      "y": 6,
      "z": -15,
      "name": "Empty"
    },
    {
      "x": -5,
      "y": 7,
      "z": -15,
      "name": "Empty"
    },
    {
      "x": -5,
      "y": 8,
      "z": -15,
      "name": "Empty"
    },
    {
      "x": -5,
      "y": 9,
      "z": -15,
      "name": "Empty"
    },
    {
      "x": -5,
      "y": 10,
      "z": -15,
      "name": "Rock_Basalt"
    },
    {
      "x": -5,
      "y": 0,
      "z": -14,
      "name": "Rock_Basalt_Cobble"
    },
    {
      "x": -5,
      "y": 1,
      "z": -14,
      "name": "Wood_Deadwood_Stairs",
      "rotation": 2
    },
    {
      "x": -5,
      "y": 2,
      "z": -14,
      "name": "Empty"
    },
    {
      "x": -5,
      "y": 3,
      "z": -14,
      "name": "Empty"
    },
    {
      "x": -5,
      "y": 4,
      "z": -14,
      "name": "Empty"
    },
    {
      "x": -5,
      "y": 5,
      "z": -14,
      "name": "Empty"
    },
    {
      "x": -5,
      "y": 6,
      "z": -14,
      "name": "Empty"
    },
    {
      "x": -5,
      "y": 7,
      "z": -14,
      "name": "Empty"
    },
    {
      "x": -5,
      "y": 8,
      "z": -14,
      "name": "Empty"
    },
    {
      "x": -5,
      "y": 9,
      "z": -14,
      "name": "Empty"
    },
    {
      "x": -5,
      "y": 10,
      "z": -14,
      "name": "Rock_Basalt"
    },
    {
      "x": -5,
      "y": 0,
      "z": -13,
      "name": "Rock_Basalt_Cobble"
    },
    {
      "x": -5,
      "y": 1,
      "z": -13,
      "name": "Wood_Deadwood_Planks"
    },
    {
      "x": -5,
      "y": 2,
      "z": -13,
      "name": "Wood_Deadwood_Stairs",
      "rotation": 2
    },
    {
      "x": -5,
      "y": 3,
      "z": -13,
      "name": "Empty"
    },
    {
      "x": -5,
      "y": 4,
      "z": -13,
      "name": "Empty"
    },
    {
      "x": -5,
      "y": 5,
      "z": -13,
      "name": "Empty"
    },
    {
      "x": -5,
      "y": 6,
      "z": -13,
      "name": "Empty"
    },
    {
      "x": -5,
      "y": 7,
      "z": -13,
      "name": "Empty"
    },
    {
      "x": -5,
      "y": 8,
      "z": -13,
      "name": "Empty"
    },
    {
      "x": -5,
      "y": 9,
      "z": -13,
      "name": "Empty"
    },
    {
      "x": -5,
      "y": 10,
      "z": -13,
      "name": "Rock_Basalt"
    },
    {
      "x": -5,
      "y": 0,
      "z": -12,
      "name": "Rock_Basalt_Cobble"
    },
    {
      "x": -5,
      "y": 1,
      "z": -12,
      "name": "Empty"
    },
    {
      "x": -5,
      "y": 2,
      "z": -12,
      "name": "Wood_Deadwood_Planks"
    },
    {
      "x": -5,
      "y": 3,
      "z": -12,
      "name": "Wood_Deadwood_Stairs",
      "rotation": 2
    },
    {
      "x": -5,
      "y": 4,
      "z": -12,
      "name": "Empty"
    },
    {
      "x": -5,
      "y": 5,
      "z": -12,
      "name": "Empty"
    },
    {
      "x": -5,
      "y": 6,
      "z": -12,
      "name": "Empty"
    },
    {
      "x": -5,
      "y": 7,
      "z": -12,
      "name": "Empty"
    },
    {
      "x": -5,
      "y": 8,
      "z": -12,
      "name": "Empty"
    },
    {
      "x": -5,
      "y": 9,
      "z": -12,
      "name": "Empty"
    },
    {
      "x": -5,
      "y": 10,
      "z": -12,
      "name": "Rock_Basalt"
    },
    {
      "x": -5,
      "y": 0,
      "z": -11,
      "name": "Rock_Basalt_Cobble"
    },
    {
      "x": -5,
      "y": 1,
      "z": -11,
      "name": "Empty"
    },
    {
      "x": -5,
      "y": 2,
      "z": -11,
      "name": "Empty"
    },
    {
      "x": -5,
      "y": 3,
      "z": -11,
      "name": "Wood_Deadwood_Planks"
    },
    {
      "x": -5,
      "y": 4,
      "z": -11,
      "name": "Wood_Deadwood_Stairs",
      "rotation": 2
    },
    {
      "x": -5,
      "y": 5,
      "z": -11,
      "name": "Empty"
    },
    {
      "x": -5,
      "y": 6,
      "z": -11,
      "name": "Empty"
    },
    {
      "x": -5,
      "y": 7,
      "z": -11,
      "name": "Empty"
    },
    {
      "x": -5,
      "y": 8,
      "z": -11,
      "name": "Empty"
    },
    {
      "x": -5,
      "y": 9,
      "z": -11,
      "name": "Empty"
    },
    {
      "x": -5,
      "y": 10,
      "z": -11,
      "name": "Rock_Basalt"
    },
    {
      "x": -5,
      "y": 0,
      "z": -10,
      "name": "Rock_Basalt_Cobble"
    },
    {
      "x": -5,
      "y": 1,
      "z": -10,
      "name": "Empty"
    },
    {
      "x": -5,
      "y": 2,
      "z": -10,
      "name": "Empty"
    },
    {
      "x": -5,
      "y": 3,
      "z": -10,
      "name": "Empty"
    },
    {
      "x": -5,
      "y": 4,
      "z": -10,
      "name": "Wood_Deadwood_Planks"
    },
    {
      "x": -5,
      "y": 5,
      "z": -10,
      "name": "Wood_Deadwood_Stairs",
      "rotation": 2
    },
    {
      "x": -5,
      "y": 6,
      "z": -10,
      "name": "Empty"
    },
    {
      "x": -5,
      "y": 7,
      "z": -10,
      "name": "Empty"
    },
    {
      "x": -5,
      "y": 8,
      "z": -10,
      "name": "Empty"
    },
    {
      "x": -5,
      "y": 9,
      "z": -10,
      "name": "Empty"
    },
    {
      "x": -5,
      "y": 10,
      "z": -10,
      "name": "Rock_Basalt"
    },
    {
      "x": -5,
      "y": 0,
      "z": -9,
      "name": "Rock_Basalt_Cobble"
    },
    {
      "x": -5,
      "y": 1,
      "z": -9,
      "name": "Empty"
    },
    {
      "x": -5,
      "y": 2,
      "z": -9,
      "name": "Empty"
    },
    {
      "x": -5,
      "y": 3,
      "z": -9,
      "name": "Empty"
    },
    {
      "x": -5,
      "y": 4,
      "z": -9,
      "name": "Empty"
    },
    {
      "x": -5,
      "y": 5,
      "z": -9,
      "name": "Wood_Deadwood_Planks"
    },
    {
      "x": -5,
      "y": 6,
      "z": -9,
      "name": "Empty"
    },
    {
      "x": -5,
      "y": 7,
      "z": -9,
      "name": "Empty"
    },
    {
      "x": -5,
      "y": 8,
      "z": -9,
      "name": "Empty"
    },
    {
      "x": -5,
      "y": 9,
      "z": -9,
      "name": "Empty"
    },
    {
      "x": -5,
      "y": 10,
      "z": -9,
      "name": "Rock_Basalt"
    },
    {
      "x": -5,
      "y": 0,
      "z": -8,
      "name": "Rock_Basalt_Cobble"
    },
    {
      "x": -5,
      "y": 1,
      "z": -8,
      "name": "Empty"
    },
    {
      "x": -5,
      "y": 2,
      "z": -8,
      "name": "Empty"
    },
    {
      "x": -5,
      "y": 3,
      "z": -8,
      "name": "Empty"
    },
    {
      "x": -5,
      "y": 4,
      "z": -8,
      "name": "Empty"
    },
    {
      "x": -5,
      "y": 5,
      "z": -8,
      "name": "Wood_Deadwood_Planks"
    },
    {
      "x": -5,
      "y": 6,
      "z": -8,
      "name": "Empty"
    },
    {
      "x": -5,
      "y": 7,
      "z": -8,
      "name": "Empty"
    },
    {
      "x": -5,
      "y": 8,
      "z": -8,
      "name": "Empty"
    },
    {
      "x": -5,
      "y": 9,
      "z": -8,
      "name": "Empty"
    },
    {
      "x": -5,
      "y": 10,
      "z": -8,
      "name": "Rock_Basalt"
    },
    {
      "x": -5,
      "y": 0,
      "z": -7,
      "name": "Rock_Basalt_Cobble"
    },
    {
      "x": -5,
      "y": 1,
      "z": -7,
      "name": "Empty"
    },
    {
      "x": -5,
      "y": 2,
      "z": -7,
      "name": "Empty"
    },
    {
      "x": -5,
      "y": 3,
      "z": -7,
      "name": "Empty"
    },
    {
      "x": -5,
      "y": 4,
      "z": -7,
      "name": "Empty"
    },
    {
      "x": -5,
      "y": 5,
      "z": -7,
      "name": "Wood_Deadwood_Planks"
    },
    {
      "x": -5,
      "y": 6,
      "z": -7,
      "name": "Empty"
    },
    {
      "x": -5,
      "y": 7,
      "z": -7,
      "name": "Empty"
    },
    {
      "x": -5,
      "y": 8,
      "z": -7,
      "name": "Empty"
    },
    {
      "x": -5,
      "y": 9,
      "z": -7,
      "name": "Empty"
    },
    {
      "x": -5,
      "y": 10,
      "z": -7,
      "name": "Rock_Basalt"
    },
    {
      "x": -5,
      "y": 0,
      "z": -6,
      "name": "Rock_Basalt_Cobble"
    },
    {
      "x": -5,
      "y": 1,
      "z": -6,
      "name": "Rock_Basalt"
    },
    {
      "x": -5,
      "y": 2,
      "z": -6,
      "name": "Rock_Basalt"
    },
    {
      "x": -5,
      "y": 3,
      "z": -6,
      "name": "Rock_Basalt"
    },
    {
      "x": -5,
      "y": 4,
      "z": -6,
      "name": "Rock_Basalt"
    },
    {
      "x": -5,
      "y": 5,
      "z": -6,
      "name": "Rock_Basalt"
    },
    {
      "x": -5,
      "y": 6,
      "z": -6,
      "name": "Rock_Basalt"
    },
    {
      "x": -5,
      "y": 7,
      "z": -6,
      "name": "Rock_Basalt"
    },
    {
      "x": -5,
      "y": 8,
      "z": -6,
      "name": "Rock_Basalt"
    },
    {
      "x": -5,
      "y": 9,
      "z": -6,
      "name": "Rock_Basalt"
    },
    {
      "x": -5,
      "y": 10,
      "z": -6,
      "name": "Rock_Basalt"
    },
    {
      "x": -5,
      "y": 0,
      "z": -5,
      "name": "Rock_Basalt_Cobble"
    },
    {
      "x": -5,
      "y": 1,
      "z": -5,
      "name": "Rock_Basalt_Brick_Smooth"
    },
    {
      "x": -5,
      "y": 2,
      "z": -5,
      "name": "Rock_Basalt_Cobble"
    },
    {
      "x": -5,
      "y": 3,
      "z": -5,
      "name": "Rock_Basalt_Cobble"
    },
    {
      "x": -5,
      "y": 4,
      "z": -5,
      "name": "Rock_Basalt_Cobble"
    },
    {
      "x": -5,
      "y": 5,
      "z": -5,
      "name": "Rock_Basalt_Cobble"
    },
    {
      "x": -5,
      "y": 6,
      "z": -5,
      "name": "Rock_Basalt_Cobble"
    },
    {
      "x": -5,
      "y": 7,
      "z": -5,
      "name": "Rock_Basalt_Cobble"
    },
    {
      "x": -5,
      "y": 8,
      "z": -5,
      "name": "Rock_Basalt_Cobble"
    },
    {
      "x": -5,
      "y": 9,
      "z": -5,
      "name": "Rock_Basalt"
    },
    {
      "x": -5,
      "y": 0,
      "z": -4,
      "name": "Rock_Basalt_Cobble"
    },
    {
      "x": -5,
      "y": 1,
      "z": -4,
      "name": "Rock_Basalt_Brick_Smooth"
    },
    {
      "x": -5,
      "y": 2,
      "z": -4,
      "name": "Empty"
    },
    {
      "x": -5,
      "y": 3,
      "z": -4,
      "name": "Empty"
    },
    {
      "x": -5,
      "y": 4,
      "z": -4,
      "name": "Empty"
    },
    {
      "x": -5,
      "y": 5,
      "z": -4,
      "name": "Empty"
    },
    {
      "x": -5,
      "y": 6,
      "z": -4,
      "name": "Rock_Basalt_Cobble_Half",
      "rotation": 5
    },
    {
      "x": -5,
      "y": 7,
      "z": -4,
      "name": "Rock_Basalt_Cobble"
    },
    {
      "x": -5,
      "y": 8,
      "z": -4,
      "name": "Rock_Basalt_Cobble"
    },
    {
      "x": -5,
      "y": 9,
      "z": -4,
      "name": "Rock_Basalt"
    },
    {
      "x": -5,
      "y": 0,
      "z": -3,
      "name": "Rock_Basalt_Cobble"
    },
    {
      "x": -5,
      "y": 1,
      "z": -3,
      "name": "Rock_Basalt_Brick_Smooth"
    },
    {
      "x": -5,
      "y": 2,
      "z": -3,
      "name": "Rock_Basalt_Brick_Smooth"
    },
    {
      "x": -5,
      "y": 3,
      "z": -3,
      "name": "Furniture_Temple_Dark_Statue",
      "rotation": 1
    },
    {
      "x": -5,
      "y": 4,
      "z": -3,
      "name": "Furniture_Temple_Dark_Statue",
      "filler": 1024,
      "rotation": 1
    },
    {
      "x": -5,
      "y": 5,
      "z": -3,
      "name": "Empty"
    },
    {
      "x": -5,
      "y": 6,
      "z": -3,
      "name": "Empty"
    },
    {
      "x": -5,
      "y": 7,
      "z": -3,
      "name": "Empty"
    },
    {
      "x": -5,
      "y": 8,
      "z": -3,
      "name": "Rock_Basalt_Cobble"
    },
    {
      "x": -5,
      "y": 9,
      "z": -3,
      "name": "Rock_Basalt"
    },
    {
      "x": -5,
      "y": 0,
      "z": -2,
      "name": "Rock_Basalt_Cobble"
    },
    {
      "x": -5,
      "y": 1,
      "z": -2,
      "name": "Rock_Basalt_Brick_Smooth"
    },
    {
      "x": -5,
      "y": 2,
      "z": -2,
      "name": "Deco_Bone_Pile"
    },
    {
      "x": -5,
      "y": 3,
      "z": -2,
      "name": "Empty"
    },
    {
      "x": -5,
      "y": 4,
      "z": -2,
      "name": "Empty"
    },
    {
      "x": -5,
      "y": 5,
      "z": -2,
      "name": "Empty"
    },
    {
      "x": -5,
      "y": 6,
      "z": -2,
      "name": "Rock_Basalt_Cobble_Half",
      "rotation": 5
    },
    {
      "x": -5,
      "y": 7,
      "z": -2,
      "name": "Rock_Basalt_Cobble"
    },
    {
      "x": -5,
      "y": 8,
      "z": -2,
      "name": "Rock_Basalt_Cobble"
    },
    {
      "x": -5,
      "y": 9,
      "z": -2,
      "name": "Rock_Basalt"
    },
    {
      "x": -5,
      "y": 0,
      "z": -1,
      "name": "Rock_Basalt_Cobble"
    },
    {
      "x": -5,
      "y": 1,
      "z": -1,
      "name": "Rock_Basalt_Brick_Smooth"
    },
    {
      "x": -5,
      "y": 2,
      "z": -1,
      "name": "Rock_Basalt_Cobble"
    },
    {
      "x": -5,
      "y": 3,
      "z": -1,
      "name": "Rock_Basalt_Cobble"
    },
    {
      "x": -5,
      "y": 4,
      "z": -1,
      "name": "Rock_Basalt_Cobble"
    },
    {
      "x": -5,
      "y": 5,
      "z": -1,
      "name": "Rock_Basalt_Cobble"
    },
    {
      "x": -5,
      "y": 6,
      "z": -1,
      "name": "Rock_Basalt_Cobble"
    },
    {
      "x": -5,
      "y": 7,
      "z": -1,
      "name": "Rock_Basalt_Cobble"
    },
    {
      "x": -5,
      "y": 8,
      "z": -1,
      "name": "Rock_Basalt_Cobble"
    },
    {
      "x": -5,
      "y": 9,
      "z": -1,
      "name": "Rock_Basalt"
    },
    {
      "x": -5,
      "y": 0,
      "z": 0,
      "name": "Rock_Basalt"
    },
    {
      "x": -5,
      "y": 1,
      "z": 0,
      "name": "Rock_Basalt"
    },
    {
      "x": -5,
      "y": 2,
      "z": 0,
      "name": "Rock_Basalt"
    },
    {
      "x": -5,
      "y": 3,
      "z": 0,
      "name": "Rock_Basalt"
    },
    {
      "x": -5,
      "y": 4,
      "z": 0,
      "name": "Rock_Basalt"
    },
    {
      "x": -5,
      "y": 5,
      "z": 0,
      "name": "Rock_Basalt"
    },
    {
      "x": -5,
      "y": 6,
      "z": 0,
      "name": "Rock_Basalt"
    },
    {
      "x": -5,
      "y": 7,
      "z": 0,
      "name": "Rock_Basalt"
    },
    {
      "x": -5,
      "y": 8,
      "z": 0,
      "name": "Rock_Basalt"
    },
    {
      "x": -5,
      "y": 9,
      "z": 0,
      "name": "Rock_Basalt"
    },
    {
      "x": -4,
      "y": 0,
      "z": -25,
      "name": "Rock_Basalt"
    },
    {
      "x": -4,
      "y": 1,
      "z": -25,
      "name": "Rock_Basalt"
    },
    {
      "x": -4,
      "y": 2,
      "z": -25,
      "name": "Rock_Basalt"
    },
    {
      "x": -4,
      "y": 3,
      "z": -25,
      "name": "Rock_Basalt"
    },
    {
      "x": -4,
      "y": 4,
      "z": -25,
      "name": "Rock_Basalt"
    },
    {
      "x": -4,
      "y": 5,
      "z": -25,
      "name": "Rock_Basalt"
    },
    {
      "x": -4,
      "y": 6,
      "z": -25,
      "name": "Rock_Basalt"
    },
    {
      "x": -4,
      "y": 7,
      "z": -25,
      "name": "Rock_Basalt"
    },
    {
      "x": -4,
      "y": 8,
      "z": -25,
      "name": "Rock_Basalt"
    },
    {
      "x": -4,
      "y": 9,
      "z": -25,
      "name": "Rock_Basalt"
    },
    {
      "x": -4,
      "y": 10,
      "z": -25,
      "name": "Rock_Basalt"
    },
    {
      "x": -4,
      "y": 0,
      "z": -24,
      "name": "Rock_Basalt_Cobble"
    },
    {
      "x": -4,
      "y": 1,
      "z": -24,
      "name": "Empty"
    },
    {
      "x": -4,
      "y": 2,
      "z": -24,
      "name": "Empty"
    },
    {
      "x": -4,
      "y": 3,
      "z": -24,
      "name": "Empty"
    },
    {
      "x": -4,
      "y": 4,
      "z": -24,
      "name": "Empty"
    },
    {
      "x": -4,
      "y": 5,
      "z": -24,
      "name": "Empty"
    },
    {
      "x": -4,
      "y": 6,
      "z": -24,
      "name": "Empty"
    },
    {
      "x": -4,
      "y": 7,
      "z": -24,
      "name": "Empty"
    },
    {
      "x": -4,
      "y": 8,
      "z": -24,
      "name": "Empty"
    },
    {
      "x": -4,
      "y": 9,
      "z": -24,
      "name": "Empty"
    },
    {
      "x": -4,
      "y": 10,
      "z": -24,
      "name": "Rock_Basalt"
    },
    {
      "x": -4,
      "y": 0,
      "z": -23,
      "name": "Rock_Basalt_Cobble"
    },
    {
      "x": -4,
      "y": 1,
      "z": -23,
      "name": "Empty"
    },
    {
      "x": -4,
      "y": 2,
      "z": -23,
      "name": "Empty"
    },
    {
      "x": -4,
      "y": 3,
      "z": -23,
      "name": "Empty"
    },
    {
      "x": -4,
      "y": 4,
      "z": -23,
      "name": "Empty"
    },
    {
      "x": -4,
      "y": 5,
      "z": -23,
      "name": "Empty"
    },
    {
      "x": -4,
      "y": 6,
      "z": -23,
      "name": "Empty"
    },
    {
      "x": -4,
      "y": 7,
      "z": -23,
      "name": "Empty"
    },
    {
      "x": -4,
      "y": 8,
      "z": -23,
      "name": "Empty"
    },
    {
      "x": -4,
      "y": 9,
      "z": -23,
      "name": "Empty"
    },
    {
      "x": -4,
      "y": 10,
      "z": -23,
      "name": "Rock_Basalt"
    },
    {
      "x": -4,
      "y": 0,
      "z": -22,
      "name": "Rock_Basalt_Cobble"
    },
    {
      "x": -4,
      "y": 1,
      "z": -22,
      "name": "Empty"
    },
    {
      "x": -4,
      "y": 2,
      "z": -22,
      "name": "Empty"
    },
    {
      "x": -4,
      "y": 3,
      "z": -22,
      "name": "Empty"
    },
    {
      "x": -4,
      "y": 4,
      "z": -22,
      "name": "Empty"
    },
    {
      "x": -4,
      "y": 5,
      "z": -22,
      "name": "Empty"
    },
    {
      "x": -4,
      "y": 6,
      "z": -22,
      "name": "Empty"
    },
    {
      "x": -4,
      "y": 7,
      "z": -22,
      "name": "Empty"
    },
    {
      "x": -4,
      "y": 8,
      "z": -22,
      "name": "Empty"
    },
    {
      "x": -4,
      "y": 9,
      "z": -22,
      "name": "Empty"
    },
    {
      "x": -4,
      "y": 10,
      "z": -22,
      "name": "Rock_Basalt"
    },
    {
      "x": -4,
      "y": 0,
      "z": -21,
      "name": "Rock_Basalt_Cobble"
    },
    {
      "x": -4,
      "y": 1,
      "z": -21,
      "name": "Furniture_Ancient_Chair"
    },
    {
      "x": -4,
      "y": 2,
      "z": -21,
      "name": "Empty"
    },
    {
      "x": -4,
      "y": 3,
      "z": -21,
      "name": "Empty"
    },
    {
      "x": -4,
      "y": 4,
      "z": -21,
      "name": "Empty"
    },
    {
      "x": -4,
      "y": 5,
      "z": -21,
      "name": "Empty"
    },
    {
      "x": -4,
      "y": 6,
      "z": -21,
      "name": "Empty"
    },
    {
      "x": -4,
      "y": 7,
      "z": -21,
      "name": "Empty"
    },
    {
      "x": -4,
      "y": 8,
      "z": -21,
      "name": "Empty"
    },
    {
      "x": -4,
      "y": 9,
      "z": -21,
      "name": "Empty"
    },
    {
      "x": -4,
      "y": 10,
      "z": -21,
      "name": "Rock_Basalt"
    },
    {
      "x": -4,
      "y": 0,
      "z": -20,
      "name": "Rock_Basalt_Cobble"
    },
    {
      "x": -4,
      "y": 1,
      "z": -20,
      "name": "Furniture_Ancient_Table"
    },
    {
      "x": -4,
      "y": 2,
      "z": -20,
      "name": "Empty"
    },
    {
      "x": -4,
      "y": 3,
      "z": -20,
      "name": "Empty"
    },
    {
      "x": -4,
      "y": 4,
      "z": -20,
      "name": "Empty"
    },
    {
      "x": -4,
      "y": 5,
      "z": -20,
      "name": "Empty"
    },
    {
      "x": -4,
      "y": 6,
      "z": -20,
      "name": "Empty"
    },
    {
      "x": -4,
      "y": 7,
      "z": -20,
      "name": "Empty"
    },
    {
      "x": -4,
      "y": 8,
      "z": -20,
      "name": "Empty"
    },
    {
      "x": -4,
      "y": 9,
      "z": -20,
      "name": "Empty"
    },
    {
      "x": -4,
      "y": 10,
      "z": -20,
      "name": "Rock_Basalt"
    },
    {
      "x": -4,
      "y": 0,
      "z": -19,
      "name": "Rock_Basalt_Cobble"
    },
    {
      "x": -4,
      "y": 1,
      "z": -19,
      "name": "Furniture_Ancient_Table",
      "filler": 32
    },
    {
      "x": -4,
      "y": 2,
      "z": -19,
      "name": "Empty"
    },
    {
      "x": -4,
      "y": 3,
      "z": -19,
      "name": "Empty"
    },
    {
      "x": -4,
      "y": 4,
      "z": -19,
      "name": "Empty"
    },
    {
      "x": -4,
      "y": 5,
      "z": -19,
      "name": "Empty"
    },
    {
      "x": -4,
      "y": 6,
      "z": -19,
      "name": "Empty"
    },
    {
      "x": -4,
      "y": 7,
      "z": -19,
      "name": "Empty"
    },
    {
      "x": -4,
      "y": 8,
      "z": -19,
      "name": "Empty"
    },
    {
      "x": -4,
      "y": 9,
      "z": -19,
      "name": "Empty"
    },
    {
      "x": -4,
      "y": 10,
      "z": -19,
      "name": "Rock_Basalt"
    },
    {
      "x": -4,
      "y": 0,
      "z": -18,
      "name": "Rock_Basalt_Cobble"
    },
    {
      "x": -4,
      "y": 1,
      "z": -18,
      "name": "Empty"
    },
    {
      "x": -4,
      "y": 2,
      "z": -18,
      "name": "Empty"
    },
    {
      "x": -4,
      "y": 3,
      "z": -18,
      "name": "Empty"
    },
    {
      "x": -4,
      "y": 4,
      "z": -18,
      "name": "Empty"
    },
    {
      "x": -4,
      "y": 5,
      "z": -18,
      "name": "Empty"
    },
    {
      "x": -4,
      "y": 6,
      "z": -18,
      "name": "Empty"
    },
    {
      "x": -4,
      "y": 7,
      "z": -18,
      "name": "Empty"
    },
    {
      "x": -4,
      "y": 8,
      "z": -18,
      "name": "Empty"
    },
    {
      "x": -4,
      "y": 9,
      "z": -18,
      "name": "Empty"
    },
    {
      "x": -4,
      "y": 10,
      "z": -18,
      "name": "Rock_Basalt"
    },
    {
      "x": -4,
      "y": 0,
      "z": -17,
      "name": "Rock_Basalt_Cobble"
    },
    {
      "x": -4,
      "y": 1,
      "z": -17,
      "name": "Empty"
    },
    {
      "x": -4,
      "y": 2,
      "z": -17,
      "name": "Empty"
    },
    {
      "x": -4,
      "y": 3,
      "z": -17,
      "name": "Empty"
    },
    {
      "x": -4,
      "y": 4,
      "z": -17,
      "name": "Empty"
    },
    {
      "x": -4,
      "y": 5,
      "z": -17,
      "name": "Empty"
    },
    {
      "x": -4,
      "y": 6,
      "z": -17,
      "name": "Empty"
    },
    {
      "x": -4,
      "y": 7,
      "z": -17,
      "name": "Empty"
    },
    {
      "x": -4,
      "y": 8,
      "z": -17,
      "name": "Empty"
    },
    {
      "x": -4,
      "y": 9,
      "z": -17,
      "name": "Empty"
    },
    {
      "x": -4,
      "y": 10,
      "z": -17,
      "name": "Rock_Basalt"
    },
    {
      "x": -4,
      "y": 0,
      "z": -16,
      "name": "Rock_Basalt_Cobble"
    },
    {
      "x": -4,
      "y": 1,
      "z": -16,
      "name": "Empty"
    },
    {
      "x": -4,
      "y": 2,
      "z": -16,
      "name": "Empty"
    },
    {
      "x": -4,
      "y": 3,
      "z": -16,
      "name": "Empty"
    },
    {
      "x": -4,
      "y": 4,
      "z": -16,
      "name": "Empty"
    },
    {
      "x": -4,
      "y": 5,
      "z": -16,
      "name": "Empty"
    },
    {
      "x": -4,
      "y": 6,
      "z": -16,
      "name": "Empty"
    },
    {
      "x": -4,
      "y": 7,
      "z": -16,
      "name": "Empty"
    },
    {
      "x": -4,
      "y": 8,
      "z": -16,
      "name": "Empty"
    },
    {
      "x": -4,
      "y": 9,
      "z": -16,
      "name": "Empty"
    },
    {
      "x": -4,
      "y": 10,
      "z": -16,
      "name": "Rock_Basalt"
    },
    {
      "x": -4,
      "y": 0,
      "z": -15,
      "name": "Rock_Basalt_Cobble"
    },
    {
      "x": -4,
      "y": 1,
      "z": -15,
      "name": "Empty"
    },
    {
      "x": -4,
      "y": 2,
      "z": -15,
      "name": "Empty"
    },
    {
      "x": -4,
      "y": 3,
      "z": -15,
      "name": "Empty"
    },
    {
      "x": -4,
      "y": 4,
      "z": -15,
      "name": "Empty"
    },
    {
      "x": -4,
      "y": 5,
      "z": -15,
      "name": "Empty"
    },
    {
      "x": -4,
