{
  "version": 8,
  "blockIdVersion": 8,
  "anchorX": 12,
  "anchorY": 8,
  "anchorZ": 7,
  "blocks": [
    {
      "x": 3,
      "y": 21,
      "z": 9,
      "name": "Plant_Crop_Mushroom_Block_Green"
    },
    {
      "x": 3,
      "y": 20,
      "z": 10,
      "name": "Plant_Crop_Mushroom_Block_Green"
    },
    {
      "x": 3,
      "y": 21,
      "z": 10,
      "name": "Plant_Crop_Mushroom_Block_Green"
    },
    {
      "x": 3,
      "y": 20,
      "z": 11,
      "name": "Plant_Crop_Mushroom_Block_Green"
    },
    {
      "x": 4,
      "y": 21,
      "z": 6,
      "name": "Plant_Crop_Mushroom_Block_Green"
    },
    {
      "x": 4,
      "y": 22,
      "z": 6,
      "name": "Plant_Crop_Mushroom_Block_Green"
    },
    {
      "x": 4,
      "y": 21,
      "z": 7,
      "name": "Plant_Crop_Mushroom_Block_Green"
    },
    {
      "x": 4,
      "y": 22,
      "z": 7,
      "name": "Plant_Crop_Mushroom_Block_Green"
    },
    {
      "x": 4,
      "y": 23,
      "z": 7,
      "name": "Plant_Crop_Mushroom_Block_Green"
    },
    {
      "x": 4,
      "y": 22,
      "z": 8,
      "name": "Plant_Crop_Mushroom_Block_Green"
    },
    {
      "x": 4,
      "y": 21,
      "z": 9,
      "name": "Plant_Crop_Mushroom_Block_Green"
    },
    {
      "x": 4,
      "y": 22,
      "z": 9,
      "name": "Plant_Crop_Mushroom_Block_Green"
    },
    {
      "x": 4,
      "y": 23,
      "z": 9,
      "name": "Plant_Crop_Mushroom_Block_Green"
    },
    {
      "x": 4,
      "y": 20,
      "z": 10,
      "name": "Plant_Crop_Mushroom_Block_Green"
    },
    {
      "x": 4,
      "y": 21,
      "z": 10,
      "name": "Plant_Crop_Mushroom_Block_Green"
    },
    {
      "x": 4,
      "y": 22,
      "z": 10,
      "name": "Plant_Crop_Mushroom_Block_Green"
    },
    {
      "x": 4,
      "y": 23,
      "z": 10,
      "name": "Plant_Crop_Mushroom_Block_Green"
    },
    {
      "x": 4,
      "y": 20,
      "z": 11,
      "name": "Plant_Crop_Mushroom_Block_Green"
    },
    {
      "x": 4,
      "y": 21,
      "z": 11,
      "name": "Plant_Crop_Mushroom_Block_Green"
    },
    {
      "x": 4,
      "y": 22,
      "z": 11,
      "name": "Plant_Crop_Mushroom_Block_Green"
    },
    {
      "x": 5,
      "y": 21,
      "z": 5,
      "name": "Plant_Crop_Mushroom_Block_Green"
    },
    {
      "x": 5,
      "y": 21,
      "z": 6,
      "name": "Plant_Crop_Mushroom_Block_Green"
    },
    {
      "x": 5,
      "y": 22,
      "z": 6,
      "name": "Plant_Crop_Mushroom_Block_Green"
    },
    {
      "x": 5,
      "y": 23,
      "z": 6,
      "name": "Plant_Crop_Mushroom_Block_Green"
    },
    {
      "x": 5,
      "y": 22,
      "z": 7,
      "name": "Rock_Crystal_Green_Block"
    },
    {
      "x": 5,
      "y": 23,
      "z": 7,
      "name": "Plant_Crop_Mushroom_Block_Green"
    },
    {
      "x": 5,
      "y": 24,
      "z": 7,
      "name": "Plant_Crop_Mushroom_Block_Green"
    },
    {
      "x": 5,
      "y": 22,
      "z": 8,
      "name": "Rock_Crystal_Green_Block"
    },
    {
      "x": 5,
      "y": 23,
      "z": 8,
      "name": "Plant_Crop_Mushroom_Block_Green"
    },
    {
      "x": 5,
      "y": 24,
      "z": 8,
      "name": "Plant_Crop_Mushroom_Block_Green"
    },
    {
      "x": 5,
      "y": 22,
      "z": 9,
      "name": "Rock_Crystal_Green_Block"
    },
    {
      "x": 5,
      "y": 23,
      "z": 9,
      "name": "Plant_Crop_Mushroom_Block_Green"
    },
    {
      "x": 5,
      "y": 24,
      "z": 9,
      "name": "Plant_Crop_Mushroom_Block_Green"
    },
    {
      "x": 5,
      "y": 22,
      "z": 10,
      "name": "Rock_Crystal_Green_Block"
    },
    {
      "x": 5,
      "y": 23,
      "z": 10,
      "name": "Plant_Crop_Mushroom_Block_Green"
    },
    {
      "x": 5,
      "y": 24,
      "z": 10,
      "name": "Plant_Crop_Mushroom_Block_Green"
    },
    {
      "x": 5,
      "y": 21,
      "z": 11,
      "name": "Plant_Crop_Mushroom_Block_Green"
    },
    {
      "x": 5,
      "y": 22,
      "z": 11,
      "name": "Plant_Crop_Mushroom_Block_Green"
    },
    {
      "x": 5,
      "y": 23,
      "z": 11,
      "name": "Plant_Crop_Mushroom_Block_Green"
    },
    {
      "x": 5,
      "y": 21,
      "z": 12,
      "name": "Plant_Crop_Mushroom_Block_Green"
    },
    {
      "x": 5,
      "y": 22,
      "z": 12,
      "name": "Plant_Crop_Mushroom_Block_Green"
    },
    {
      "x": 6,
      "y": 21,
      "z": 5,
      "name": "Plant_Crop_Mushroom_Block_Green"
    },
    {
      "x": 6,
      "y": 22,
      "z": 5,
      "name": "Plant_Crop_Mushroom_Block_Green"
    },
    {
      "x": 6,
      "y": 23,
      "z": 5,
      "name": "Plant_Crop_Mushroom_Block_Green"
    },
    {
      "x": 6,
      "y": 22,
      "z": 6,
      "name": "Plant_Crop_Mushroom_Block_Green"
    },
    {
      "x": 6,
      "y": 23,
      "z": 6,
      "name": "Plant_Crop_Mushroom_Block_Green"
    },
    {
      "x": 6,
      "y": 24,
      "z": 6,
      "name": "Plant_Crop_Mushroom_Block_Green"
    },
    {
      "x": 6,
      "y": 25,
      "z": 6,
      "name": "Plant_Crop_Mushroom_Block_Green"
    },
    {
      "x": 6,
      "y": 23,
      "z": 7,
      "name": "Rock_Crystal_Green_Block"
    },
    {
      "x": 6,
      "y": 24,
      "z": 7,
      "name": "Plant_Crop_Mushroom_Block_Green"
    },
    {
      "x": 6,
      "y": 25,
      "z": 7,
      "name": "Plant_Crop_Mushroom_Block_Green"
    },
    {
      "x": 6,
      "y": 23,
      "z": 8,
      "name": "Rock_Crystal_Green_Block"
    },
    {
      "x": 6,
      "y": 24,
      "z": 8,
      "name": "Plant_Crop_Mushroom_Block_Green"
    },
    {
      "x": 6,
      "y": 25,
      "z": 8,
      "name": "Plant_Crop_Mushroom_Block_Green"
    },
    {
      "x": 6,
      "y": 23,
      "z": 9,
      "name": "Rock_Crystal_Green_Block"
    },
    {
      "x": 6,
      "y": 24,
      "z": 9,
      "name": "Plant_Crop_Mushroom_Block_Green"
    },
    {
      "x": 6,
      "y": 25,
      "z": 9,
      "name": "Plant_Crop_Mushroom_Block_Green"
    },
    {
      "x": 6,
      "y": 22,
      "z": 10,
      "name": "Rock_Crystal_Green_Block"
    },
    {
      "x": 6,
      "y": 23,
      "z": 10,
      "name": "Plant_Crop_Mushroom_Block_Green"
    },
    {
      "x": 6,
      "y": 24,
      "z": 10,
      "name": "Plant_Crop_Mushroom_Block_Green"
    },
    {
      "x": 6,
      "y": 25,
      "z": 10,
      "name": "Plant_Crop_Mushroom_Block_Green"
    },
    {
      "x": 6,
      "y": 22,
      "z": 11,
      "name": "Rock_Crystal_Green_Block"
    },
    {
      "x": 6,
      "y": 23,
      "z": 11,
      "name": "Plant_Crop_Mushroom_Block_Green"
    },
    {
      "x": 6,
      "y": 24,
      "z": 11,
      "name": "Plant_Crop_Mushroom_Block_Green"
    },
    {
      "x": 6,
      "y": 22,
      "z": 12,
      "name": "Plant_Crop_Mushroom_Block_Green"
    },
    {
      "x": 6,
      "y": 23,
      "z": 12,
      "name": "Plant_Crop_Mushroom_Block_Green"
    },
    {
      "x": 6,
      "y": 24,
      "z": 12,
      "name": "Plant_Crop_Mushroom_Block_Green"
    },
    {
      "x": 6,
      "y": 20,
      "z": 13,
      "name": "Plant_Crop_Mushroom_Block_Green"
    },
    {
      "x": 6,
      "y": 21,
      "z": 13,
      "name": "Plant_Crop_Mushroom_Block_Green"
    },
    {
      "x": 6,
      "y": 22,
      "z": 13,
      "name": "Plant_Crop_Mushroom_Block_Green"
    },
    {
      "x": 6,
      "y": 20,
      "z": 14,
      "name": "Plant_Crop_Mushroom_Block_Green"
    },
    {
      "x": 7,
      "y": 22,
      "z": 4,
      "name": "Plant_Crop_Mushroom_Block_Green"
    },
    {
      "x": 7,
      "y": 22,
      "z": 5,
      "name": "Plant_Crop_Mushroom_Block_Green"
    },
    {
      "x": 7,
      "y": 23,
      "z": 5,
      "name": "Plant_Crop_Mushroom_Block_Green"
    },
    {
      "x": 7,
      "y": 24,
      "z": 5,
      "name": "Plant_Crop_Mushroom_Block_Green"
    },
    {
      "x": 7,
      "y": 23,
      "z": 6,
      "name": "Rock_Crystal_Green_Block"
    },
    {
      "x": 7,
      "y": 24,
      "z": 6,
      "name": "Plant_Crop_Mushroom_Block_Green"
    },
    {
      "x": 7,
      "y": 25,
      "z": 6,
      "name": "Plant_Crop_Mushroom_Block_Green"
    },
    {
      "x": 7,
      "y": 23,
      "z": 7,
      "name": "Rock_Crystal_Green_Block"
    },
    {
      "x": 7,
      "y": 24,
      "z": 7,
      "name": "Plant_Crop_Mushroom_Block_Green"
    },
    {
      "x": 7,
      "y": 25,
      "z": 7,
      "name": "Plant_Crop_Mushroom_Block_Green"
    },
    {
      "x": 7,
      "y": 26,
      "z": 7,
      "name": "Plant_Crop_Mushroom_Block_Green"
    },
    {
      "x": 7,
      "y": 23,
      "z": 8,
      "name": "Rock_Crystal_Green_Block"
    },
    {
      "x": 7,
      "y": 24,
      "z": 8,
      "name": "Plant_Crop_Mushroom_Block_Green"
    },
    {
      "x": 7,
      "y": 25,
      "z": 8,
      "name": "Plant_Crop_Mushroom_Block_Green"
    },
    {
      "x": 7,
      "y": 26,
      "z": 8,
      "name": "Plant_Crop_Mushroom_Block_Green"
    },
    {
      "x": 7,
      "y": 23,
      "z": 9,
      "name": "Rock_Crystal_Green_Block"
    },
    {
      "x": 7,
      "y": 24,
      "z": 9,
      "name": "Plant_Crop_Mushroom_Block_Green"
    },
    {
      "x": 7,
      "y": 25,
      "z": 9,
      "name": "Plant_Crop_Mushroom_Block_Green"
    },
    {
      "x": 7,
      "y": 26,
      "z": 9,
      "name": "Plant_Crop_Mushroom_Block_Green"
    },
    {
      "x": 7,
      "y": 23,
      "z": 10,
      "name": "Rock_Crystal_Green_Block"
    },
    {
      "x": 7,
      "y": 24,
      "z": 10,
      "name": "Plant_Crop_Mushroom_Block_Green"
    },
    {
      "x": 7,
      "y": 25,
      "z": 10,
      "name": "Plant_Crop_Mushroom_Block_Green"
    },
    {
      "x": 7,
      "y": 26,
      "z": 10,
      "name": "Plant_Crop_Mushroom_Block_Green"
    },
    {
      "x": 7,
      "y": 22,
      "z": 11,
      "name": "Rock_Crystal_Green_Block"
    },
    {
      "x": 7,
      "y": 23,
      "z": 11,
      "name": "Rock_Crystal_Green_Block"
    },
    {
      "x": 7,
      "y": 24,
      "z": 11,
      "name": "Plant_Crop_Mushroom_Block_Green"
    },
    {
      "x": 7,
      "y": 25,
      "z": 11,
      "name": "Plant_Crop_Mushroom_Block_Green"
    },
    {
      "x": 7,
      "y": 22,
      "z": 12,
      "name": "Rock_Crystal_Green_Block"
    },
    {
      "x": 7,
      "y": 23,
      "z": 12,
      "name": "Plant_Crop_Mushroom_Block_Green"
    },
    {
      "x": 7,
      "y": 24,
      "z": 12,
      "name": "Plant_Crop_Mushroom_Block_Green"
    },
    {
      "x": 7,
      "y": 25,
      "z": 12,
      "name": "Plant_Crop_Mushroom_Block_Green"
    },
    {
      "x": 7,
      "y": 20,
      "z": 13,
      "name": "Plant_Crop_Mushroom_Block_Green"
    },
    {
      "x": 7,
      "y": 21,
      "z": 13,
      "name": "Plant_Crop_Mushroom_Block_Green"
    },
    {
      "x": 7,
      "y": 22,
      "z": 13,
      "name": "Plant_Crop_Mushroom_Block_Green"
    },
    {
      "x": 7,
      "y": 23,
      "z": 13,
      "name": "Plant_Crop_Mushroom_Block_Green"
    },
    {
      "x": 7,
      "y": 24,
      "z": 13,
      "name": "Plant_Crop_Mushroom_Block_Green"
    },
    {
      "x": 7,
      "y": 20,
      "z": 14,
      "name": "Plant_Crop_Mushroom_Block_Green"
    },
    {
      "x": 7,
      "y": 21,
      "z": 14,
      "name": "Plant_Crop_Mushroom_Block_Green"
    },
    {
      "x": 8,
      "y": 22,
      "z": 4,
      "name": "Plant_Crop_Mushroom_Block_Green"
    },
    {
      "x": 8,
      "y": 23,
      "z": 4,
      "name": "Plant_Crop_Mushroom_Block_Green"
    },
    {
      "x": 8,
      "y": 24,
      "z": 4,
      "name": "Plant_Crop_Mushroom_Block_Green"
    },
    {
      "x": 8,
      "y": 23,
      "z": 5,
      "name": "Rock_Crystal_Green_Block"
    },
    {
      "x": 8,
      "y": 24,
      "z": 5,
      "name": "Plant_Crop_Mushroom_Block_Green"
    },
    {
      "x": 8,
      "y": 25,
      "z": 5,
      "name": "Plant_Crop_Mushroom_Block_Green"
    },
    {
      "x": 8,
      "y": 23,
      "z": 6,
      "name": "Rock_Crystal_Green_Block"
    },
    {
      "x": 8,
      "y": 24,
      "z": 6,
      "name": "Plant_Crop_Mushroom_Block_Green"
    },
    {
      "x": 8,
      "y": 25,
      "z": 6,
      "name": "Plant_Crop_Mushroom_Block_Green"
    },
    {
      "x": 8,
      "y": 26,
      "z": 6,
      "name": "Plant_Crop_Mushroom_Block_Green"
    },
    {
      "x": 8,
      "y": 24,
      "z": 7,
      "name": "Rock_Crystal_Green_Block"
    },
    {
      "x": 8,
      "y": 25,
      "z": 7,
      "name": "Plant_Crop_Mushroom_Block_Green"
    },
    {
      "x": 8,
      "y": 26,
      "z": 7,
      "name": "Plant_Crop_Mushroom_Block_Green"
    },
    {
      "x": 8,
      "y": 24,
      "z": 8,
      "name": "Rock_Crystal_Green_Block"
    },
    {
      "x": 8,
      "y": 25,
      "z": 8,
      "name": "Plant_Crop_Mushroom_Block_Green"
    },
    {
      "x": 8,
      "y": 26,
      "z": 8,
      "name": "Plant_Crop_Mushroom_Block_Green"
    },
    {
      "x": 8,
      "y": 23,
      "z": 9,
      "name": "Rock_Crystal_Green_Block"
    },
    {
      "x": 8,
      "y": 24,
      "z": 9,
      "name": "Plant_Crop_Mushroom_Block_Green"
    },
    {
      "x": 8,
      "y": 25,
      "z": 9,
      "name": "Plant_Crop_Mushroom_Block_Green"
    },
    {
      "x": 8,
      "y": 26,
      "z": 9,
      "name": "Plant_Crop_Mushroom_Block_Green"
    },
    {
      "x": 8,
      "y": 23,
      "z": 10,
      "name": "Rock_Crystal_Green_Block"
    },
    {
      "x": 8,
      "y": 24,
      "z": 10,
      "name": "Plant_Crop_Mushroom_Block_Green"
    },
    {
      "x": 8,
      "y": 25,
      "z": 10,
      "name": "Plant_Crop_Mushroom_Block_Green"
    },
    {
      "x": 8,
      "y": 26,
      "z": 10,
      "name": "Plant_Crop_Mushroom_Block_Green"
    },
    {
      "x": 8,
      "y": 23,
      "z": 11,
      "name": "Rock_Crystal_Green_Block"
    },
    {
      "x": 8,
      "y": 24,
      "z": 11,
      "name": "Plant_Crop_Mushroom_Block_Green"
    },
    {
      "x": 8,
      "y": 25,
      "z": 11,
      "name": "Plant_Crop_Mushroom_Block_Green"
    },
    {
      "x": 8,
      "y": 26,
      "z": 11,
      "name": "Plant_Crop_Mushroom_Block_Green"
    },
    {
      "x": 8,
      "y": 23,
      "z": 12,
      "name": "Rock_Crystal_Green_Block"
    },
    {
      "x": 8,
      "y": 24,
      "z": 12,
      "name": "Plant_Crop_Mushroom_Block_Green"
    },
    {
      "x": 8,
      "y": 25,
      "z": 12,
      "name": "Plant_Crop_Mushroom_Block_Green"
    },
    {
      "x": 8,
      "y": 22,
      "z": 13,
      "name": "Plant_Crop_Mushroom_Block_Green"
    },
    {
      "x": 8,
      "y": 23,
      "z": 13,
      "name": "Plant_Crop_Mushroom_Block_Green"
    },
    {
      "x": 8,
      "y": 24,
      "z": 13,
      "name": "Plant_Crop_Mushroom_Block_Green"
    },
    {
      "x": 8,
      "y": 20,
      "z": 14,
      "name": "Plant_Crop_Mushroom_Block_Green"
    },
    {
      "x": 8,
      "y": 21,
      "z": 14,
      "name": "Plant_Crop_Mushroom_Block_Green"
    },
    {
      "x": 8,
      "y": 22,
      "z": 14,
      "name": "Plant_Crop_Mushroom_Block_Green"
    },
    {
      "x": 8,
      "y": 23,
      "z": 14,
      "name": "Plant_Crop_Mushroom_Block_Green"
    },
    {
      "x": 9,
      "y": 22,
      "z": 4,
      "name": "Plant_Crop_Mushroom_Block_Green"
    },
    {
      "x": 9,
      "y": 23,
      "z": 4,
      "name": "Plant_Crop_Mushroom_Block_Green"
    },
    {
      "x": 9,
      "y": 24,
      "z": 4,
      "name": "Plant_Crop_Mushroom_Block_Green"
    },
    {
      "x": 9,
      "y": 23,
      "z": 5,
      "name": "Rock_Crystal_Green_Block"
    },
    {
      "x": 9,
      "y": 24,
      "z": 5,
      "name": "Plant_Crop_Mushroom_Block_Green"
    },
    {
      "x": 9,
      "y": 25,
      "z": 5,
      "name": "Plant_Crop_Mushroom_Block_Green"
    },
    {
      "x": 9,
      "y": 24,
      "z": 6,
      "name": "Rock_Crystal_Green_Block"
    },
    {
      "x": 9,
      "y": 25,
      "z": 6,
      "name": "Plant_Crop_Mushroom_Block_Green"
    },
    {
      "x": 9,
      "y": 26,
      "z": 6,
      "name": "Plant_Crop_Mushroom_Block_Green"
    },
    {
      "x": 9,
      "y": 24,
      "z": 7,
      "name": "Rock_Crystal_Green_Block"
    },
    {
      "x": 9,
      "y": 25,
      "z": 7,
      "name": "Plant_Crop_Mushroom_Block_Green"
    },
    {
      "x": 9,
      "y": 26,
      "z": 7,
      "name": "Plant_Crop_Mushroom_Block_Green"
    },
    {
      "x": 9,
      "y": 19,
      "z": 8,
      "name": "Wood_Fir_Trunk_Full",
      "rotation": 4
    },
    {
      "x": 9,
      "y": 20,
      "z": 8,
      "name": "Wood_Fir_Trunk_Full"
    },
    {
      "x": 9,
      "y": 21,
      "z": 8,
      "name": "Wood_Fir_Trunk_Full"
    },
    {
      "x": 9,
      "y": 22,
      "z": 8,
      "name": "Wood_Fir_Trunk_Full"
    },
    {
      "x": 9,
      "y": 23,
      "z": 8,
      "name": "Wood_Fir_Trunk_Full"
    },
    {
      "x": 9,
      "y": 24,
      "z": 8,
      "name": "Rock_Crystal_Green_Block"
    },
    {
      "x": 9,
      "y": 25,
      "z": 8,
      "name": "Plant_Crop_Mushroom_Block_Green"
    },
    {
      "x": 9,
      "y": 26,
      "z": 8,
      "name": "Plant_Crop_Mushroom_Block_Green"
    },
    {
      "x": 9,
      "y": 17,
      "z": 9,
      "name": "Wood_Fir_Trunk_Full"
    },
    {
      "x": 9,
      "y": 18,
      "z": 9,
      "name": "Wood_Fir_Trunk_Full",
      "rotation": 5
    },
    {
      "x": 9,
      "y": 19,
      "z": 9,
      "name": "Wood_Fir_Trunk_Full",
      "rotation": 5
    },
    {
      "x": 9,
      "y": 20,
      "z": 9,
      "name": "Wood_Fir_Trunk_Full"
    },
    {
      "x": 9,
      "y": 21,
      "z": 9,
      "name": "Wood_Fir_Trunk_Full"
    },
    {
      "x": 9,
      "y": 22,
      "z": 9,
      "name": "Wood_Fir_Trunk_Full"
    },
    {
      "x": 9,
      "y": 23,
      "z": 9,
      "name": "Wood_Fir_Trunk_Full"
    },
    {
      "x": 9,
      "y": 24,
      "z": 9,
      "name": "Rock_Crystal_Green_Block"
    },
    {
      "x": 9,
      "y": 25,
      "z": 9,
      "name": "Plant_Crop_Mushroom_Block_Green"
    },
    {
      "x": 9,
      "y": 26,
      "z": 9,
      "name": "Plant_Crop_Mushroom_Block_Green"
    },
    {
      "x": 9,
      "y": 18,
      "z": 10,
      "name": "Wood_Fir_Trunk_Full"
    },
    {
      "x": 9,
      "y": 19,
      "z": 10,
      "name": "Wood_Fir_Trunk_Full"
    },
    {
      "x": 9,
      "y": 20,
      "z": 10,
      "name": "Wood_Fir_Trunk_Full"
    },
    {
      "x": 9,
      "y": 21,
      "z": 10,
      "name": "Wood_Fir_Trunk_Full"
    },
    {
      "x": 9,
      "y": 23,
      "z": 10,
      "name": "Rock_Crystal_Green_Block"
    },
    {
      "x": 9,
      "y": 24,
      "z": 10,
      "name": "Plant_Crop_Mushroom_Block_Green"
    },
    {
      "x": 9,
      "y": 25,
      "z": 10,
      "name": "Plant_Crop_Mushroom_Block_Green"
    },
    {
      "x": 9,
      "y": 26,
      "z": 10,
      "name": "Plant_Crop_Mushroom_Block_Green"
    },
    {
      "x": 9,
      "y": 23,
      "z": 11,
      "name": "Rock_Crystal_Green_Block"
    },
    {
      "x": 9,
      "y": 24,
      "z": 11,
      "name": "Plant_Crop_Mushroom_Block_Green"
    },
    {
      "x": 9,
      "y": 25,
      "z": 11,
      "name": "Plant_Crop_Mushroom_Block_Green"
    },
    {
      "x": 9,
      "y": 26,
      "z": 11,
      "name": "Plant_Crop_Mushroom_Block_Green"
    },
    {
      "x": 9,
      "y": 23,
      "z": 12,
      "name": "Rock_Crystal_Green_Block"
    },
    {
      "x": 9,
      "y": 24,
      "z": 12,
      "name": "Plant_Crop_Mushroom_Block_Green"
    },
    {
      "x": 9,
      "y": 25,
      "z": 12,
      "name": "Plant_Crop_Mushroom_Block_Green"
    },
    {
      "x": 9,
      "y": 22,
      "z": 13,
      "name": "Plant_Crop_Mushroom_Block_Green"
    },
    {
      "x": 9,
      "y": 23,
      "z": 13,
      "name": "Plant_Crop_Mushroom_Block_Green"
    },
    {
      "x": 9,
      "y": 24,
      "z": 13,
      "name": "Plant_Crop_Mushroom_Block_Green"
    },
    {
      "x": 9,
      "y": 21,
      "z": 14,
      "name": "Plant_Crop_Mushroom_Block_Green"
    },
    {
      "x": 9,
      "y": 22,
      "z": 14,
      "name": "Plant_Crop_Mushroom_Block_Green"
    },
    {
      "x": 9,
      "y": 23,
      "z": 14,
      "name": "Plant_Crop_Mushroom_Block_Green"
    },
    {
      "x": 10,
      "y": 22,
      "z": 4,
      "name": "Plant_Crop_Mushroom_Block_Green"
    },
    {
      "x": 10,
      "y": 23,
      "z": 4,
      "name": "Plant_Crop_Mushroom_Block_Green"
    },
    {
      "x": 10,
      "y": 23,
      "z": 5,
      "name": "Plant_Crop_Mushroom_Block_Green"
    },
    {
      "x": 10,
      "y": 24,
      "z": 5,
      "name": "Plant_Crop_Mushroom_Block_Green"
    },
    {
      "x": 10,
      "y": 25,
      "z": 5,
      "name": "Plant_Crop_Mushroom_Block_Green"
    },
    {
      "x": 10,
      "y": 24,
      "z": 6,
      "name": "Rock_Crystal_Green_Block"
    },
    {
      "x": 10,
      "y": 25,
      "z": 6,
      "name": "Plant_Crop_Mushroom_Block_Green"
    },
    {
      "x": 10,
      "y": 26,
      "z": 6,
      "name": "Plant_Crop_Mushroom_Block_Green"
    },
    {
      "x": 10,
      "y": 5,
      "z": 7,
      "name": "Wood_Fir_Trunk_Full",
      "rotation": 5
    },
    {
      "x": 10,
      "y": 24,
      "z": 7,
      "name": "Rock_Crystal_Green_Block"
    },
    {
      "x": 10,
      "y": 25,
      "z": 7,
      "name": "Plant_Crop_Mushroom_Block_Green"
    },
    {
      "x": 10,
      "y": 26,
      "z": 7,
      "name": "Plant_Crop_Mushroom_Block_Green"
    },
    {
      "x": 10,
      "y": 7,
      "z": 8,
      "name": "Wood_Fir_Trunk_Full",
      "rotation": 5
    },
    {
      "x": 10,
      "y": 8,
      "z": 8,
      "name": "Wood_Fir_Trunk_Full",
      "rotation": 5
    },
    {
      "x": 10,
      "y": 14,
      "z": 8,
      "name": "Wood_Fir_Trunk_Full"
    },
    {
      "x": 10,
      "y": 15,
      "z": 8,
      "name": "Wood_Fir_Trunk_Full"
    },
    {
      "x": 10,
      "y": 20,
      "z": 8,
      "name": "Wood_Fir_Trunk_Full",
      "rotation": 5
    },
    {
      "x": 10,
      "y": 21,
      "z": 8,
      "name": "Wood_Fir_Trunk_Full"
    },
    {
      "x": 10,
      "y": 22,
      "z": 8,
      "name": "Wood_Fir_Trunk_Full"
    },
    {
      "x": 10,
      "y": 23,
      "z": 8,
      "name": "Wood_Fir_Trunk_Full"
    },
    {
      "x": 10,
      "y": 24,
      "z": 8,
      "name": "Rock_Crystal_Green_Block"
    },
    {
      "x": 10,
      "y": 25,
      "z": 8,
      "name": "Plant_Crop_Mushroom_Block_Green"
    },
    {
      "x": 10,
      "y": 26,
      "z": 8,
      "name": "Plant_Crop_Mushroom_Block_Green"
    },
    {
      "x": 10,
      "y": 13,
      "z": 9,
      "name": "Wood_Fir_Trunk_Full"
    },
    {
      "x": 10,
      "y": 14,
      "z": 9,
      "name": "Wood_Fir_Trunk_Full"
    },
    {
      "x": 10,
      "y": 15,
      "z": 9,
      "name": "Wood_Fir_Trunk_Full"
    },
    {
      "x": 10,
      "y": 16,
      "z": 9,
      "name": "Wood_Fir_Trunk_Full",
      "rotation": 5
    },
    {
      "x": 10,
      "y": 17,
      "z": 9,
      "name": "Wood_Fir_Trunk_Full"
    },
    {
      "x": 10,
      "y": 18,
      "z": 9,
      "name": "Wood_Fir_Trunk_Full"
    },
    {
      "x": 10,
      "y": 19,
      "z": 9,
      "name": "Wood_Fir_Trunk_Full"
    },
    {
      "x": 10,
      "y": 20,
      "z": 9,
      "name": "Wood_Fir_Trunk_Full"
    },
    {
      "x": 10,
      "y": 21,
      "z": 9,
      "name": "Wood_Fir_Trunk_Full"
    },
    {
      "x": 10,
      "y": 22,
      "z": 9,
      "name": "Wood_Fir_Trunk_Full"
    },
    {
      "x": 10,
      "y": 23,
      "z": 9,
      "name": "Wood_Fir_Trunk_Full"
    },
    {
      "x": 10,
      "y": 24,
      "z": 9,
      "name": "Rock_Crystal_Green_Block"
    },
    {
      "x": 10,
      "y": 25,
      "z": 9,
      "name": "Plant_Crop_Mushroom_Block_Green"
    },
    {
      "x": 10,
      "y": 26,
      "z": 9,
      "name": "Plant_Crop_Mushroom_Block_Green"
    },
    {
      "x": 10,
      "y": 15,
      "z": 10,
      "name": "Wood_Fir_Trunk_Full"
    },
    {
      "x": 10,
      "y": 16,
      "z": 10,
      "name": "Wood_Fir_Trunk_Full"
    },
    {
      "x": 10,
      "y": 17,
      "z": 10,
      "name": "Wood_Fir_Trunk_Full"
    },
    {
      "x": 10,
      "y": 18,
      "z": 10,
      "name": "Wood_Fir_Trunk_Full"
    },
    {
      "x": 10,
      "y": 19,
      "z": 10,
      "name": "Wood_Fir_Trunk_Full",
      "rotation": 4
    },
    {
      "x": 10,
      "y": 23,
      "z": 10,
      "name": "Rock_Crystal_Green_Block"
    },
    {
      "x": 10,
      "y": 24,
      "z": 10,
      "name": "Plant_Crop_Mushroom_Block_Green"
    },
    {
      "x": 10,
      "y": 25,
      "z": 10,
      "name": "Plant_Crop_Mushroom_Block_Green"
    },
    {
      "x": 10,
      "y": 26,
      "z": 10,
      "name": "Plant_Crop_Mushroom_Block_Green"
    },
    {
      "x": 10,
      "y": 23,
      "z": 11,
      "name": "Rock_Crystal_Green_Block"
    },
    {
      "x": 10,
      "y": 24,
      "z": 11,
      "name": "Plant_Crop_Mushroom_Block_Green"
    },
    {
      "x": 10,
      "y": 25,
      "z": 11,
      "name": "Plant_Crop_Mushroom_Block_Green"
    },
    {
      "x": 10,
      "y": 26,
      "z": 11,
      "name": "Plant_Crop_Mushroom_Block_Green"
    },
    {
      "x": 10,
      "y": 23,
      "z": 12,
      "name": "Rock_Crystal_Green_Block"
    },
    {
      "x": 10,
      "y": 24,
      "z": 12,
      "name": "Plant_Crop_Mushroom_Block_Green"
    },
    {
      "x": 10,
      "y": 25,
      "z": 12,
      "name": "Plant_Crop_Mushroom_Block_Green"
    },
    {
      "x": 10,
      "y": 22,
      "z": 13,
      "name": "Plant_Crop_Mushroom_Block_Green"
    },
    {
      "x": 10,
      "y": 23,
      "z": 13,
      "name": "Plant_Crop_Mushroom_Block_Green"
    },
    {
      "x": 10,
      "y": 24,
      "z": 13,
      "name": "Plant_Crop_Mushroom_Block_Green"
    },
    {
      "x": 10,
      "y": 21,
      "z": 14,
      "name": "Plant_Crop_Mushroom_Block_Green"
    },
    {
      "x": 10,
      "y": 22,
      "z": 14,
      "name": "Plant_Crop_Mushroom_Block_Green"
    },
    {
      "x": 11,
      "y": 23,
      "z": 5,
      "name": "Plant_Crop_Mushroom_Block_Green"
    },
    {
      "x": 11,
      "y": 24,
      "z": 5,
      "name": "Plant_Crop_Mushroom_Block_Green"
    },
    {
      "x": 11,
      "y": 25,
      "z": 5,
      "name": "Plant_Crop_Mushroom_Block_Green"
    },
    {
      "x": 11,
      "y": 24,
      "z": 6,
      "name": "Rock_Crystal_Green_Block"
    },
    {
      "x": 11,
      "y": 25,
      "z": 6,
      "name": "Plant_Crop_Mushroom_Block_Green"
    },
    {
      "x": 11,
      "y": 26,
      "z": 6,
      "name": "Plant_Crop_Mushroom_Block_Green"
    },
    {
      "x": 11,
      "y": 1,
      "z": 7,
      "name": "Wood_Fir_Trunk_Full"
    },
    {
      "x": 11,
      "y": 2,
      "z": 7,
      "name": "Wood_Fir_Trunk_Full",
      "rotation": 4
    },
    {
      "x": 11,
      "y": 4,
      "z": 7,
      "name": "Wood_Fir_Trunk_Full"
    },
    {
      "x": 11,
      "y": 5,
      "z": 7,
      "name": "Wood_Fir_Trunk_Full"
    },
    {
      "x": 11,
      "y": 6,
      "z": 7,
      "name": "Wood_Fir_Trunk_Full"
    },
    {
      "x": 11,
      "y": 7,
      "z": 7,
      "name": "Wood_Fir_Trunk_Full",
      "rotation": 4
    },
    {
      "x": 11,
      "y": 9,
      "z": 7,
      "name": "Wood_Fir_Trunk_Full",
      "rotation": 5
    },
    {
      "x": 11,
      "y": 10,
      "z": 7,
      "name": "Wood_Fir_Trunk_Full"
    },
    {
      "x": 11,
      "y": 11,
      "z": 7,
      "name": "Wood_Fir_Trunk_Full"
    },
    {
      "x": 11,
      "y": 12,
      "z": 7,
      "name": "Wood_Fir_Trunk_Full"
    },
    {
      "x": 11,
      "y": 24,
      "z": 7,
      "name": "Rock_Crystal_Green_Block"
    },
    {
      "x": 11,
      "y": 25,
      "z": 7,
      "name": "Plant_Crop_Mushroom_Block_Green"
    },
    {
      "x": 11,
      "y": 26,
      "z": 7,
      "name": "Plant_Crop_Mushroom_Block_Green"
    },
    {
      "x": 11,
      "y": 2,
      "z": 8,
      "name": "Wood_Fir_Trunk_Full"
    },
    {
      "x": 11,
      "y": 3,
      "z": 8,
      "name": "Wood_Fir_Trunk_Full"
    },
    {
      "x": 11,
      "y": 4,
      "z": 8,
      "name": "Wood_Fir_Trunk_Full",
      "rotation": 4
    },
    {
      "x": 11,
      "y": 7,
      "z": 8,
      "name": "Wood_Fir_Trunk_Full"
    },
    {
      "x": 11,
      "y": 8,
      "z": 8,
      "name": "Wood_Fir_Trunk_Full"
    },
    {
      "x": 11,
      "y": 9,
      "z": 8,
      "name": "Wood_Fir_Trunk_Full"
    },
    {
      "x": 11,
      "y": 10,
      "z": 8,
      "name": "Wood_Fir_Trunk_Full"
    },
    {
      "x": 11,
      "y": 11,
      "z": 8,
      "name": "Wood_Fir_Trunk_Full"
    },
    {
      "x": 11,
      "y": 12,
      "z": 8,
      "name": "Wood_Fir_Trunk_Full",
      "rotation": 5
    },
    {
      "x": 11,
      "y": 13,
      "z": 8,
      "name": "Wood_Fir_Trunk_Full"
    },
    {
      "x": 11,
      "y": 14,
      "z": 8,
      "name": "Wood_Fir_Trunk_Full"
    },
    {
      "x": 11,
      "y": 15,
      "z": 8,
      "name": "Wood_Fir_Trunk_Full"
    },
    {
      "x": 11,
      "y": 16,
      "z": 8,
      "name": "Wood_Fir_Trunk_Full"
    },
    {
      "x": 11,
      "y": 24,
      "z": 8,
      "name": "Rock_Crystal_Green_Block"
    },
    {
      "x": 11,
      "y": 25,
      "z": 8,
      "name": "Plant_Crop_Mushroom_Block_Green"
    },
    {
      "x": 11,
      "y": 26,
      "z": 8,
      "name": "Plant_Crop_Mushroom_Block_Green"
    },
    {
      "x": 11,
      "y": 8,
      "z": 9,
      "name": "Wood_Fir_Trunk_Full",
      "rotation": 4
    },
    {
      "x": 11,
      "y": 9,
      "z": 9,
      "name": "Wood_Fir_Trunk_Full"
    },
    {
      "x": 11,
      "y": 11,
      "z": 9,
      "name": "Wood_Fir_Trunk_Full",
      "rotation": 4
    },
    {
      "x": 11,
      "y": 12,
      "z": 9,
      "name": "Wood_Fir_Trunk_Full"
    },
    {
      "x": 11,
      "y": 13,
      "z": 9,
      "name": "Wood_Fir_Trunk_Full",
      "rotation": 4
    },
    {
      "x": 11,
      "y": 14,
      "z": 9,
      "name": "Wood_Fir_Trunk_Full"
    },
    {
      "x": 11,
      "y": 15,
      "z": 9,
      "name": "Wood_Fir_Trunk_Full"
    },
    {
      "x": 11,
      "y": 16,
      "z": 9,
      "name": "Wood_Fir_Trunk_Full"
    },
    {
      "x": 11,
      "y": 17,
      "z": 9,
      "name": "Wood_Fir_Trunk_Full"
    },
    {
      "x": 11,
      "y": 24,
      "z": 9,
      "name": "Rock_Crystal_Green_Block"
    },
    {
      "x": 11,
      "y": 25,
      "z": 9,
      "name": "Plant_Crop_Mushroom_Block_Green"
    },
    {
      "x": 11,
      "y": 26,
      "z": 9,
      "name": "Plant_Crop_Mushroom_Block_Green"
    },
    {
      "x": 11,
      "y": 13,
      "z": 10,
      "name": "Wood_Fir_Trunk_Full"
    },
    {
      "x": 11,
      "y": 14,
      "z": 10,
      "name": "Wood_Fir_Trunk_Full"
    },
    {
      "x": 11,
      "y": 15,
      "z": 10,
      "name": "Wood_Fir_Trunk_Full",
      "rotation": 4
    },
    {
      "x": 11,
      "y": 16,
      "z": 10,
      "name": "Wood_Fir_Trunk_Full"
    },
    {
      "x": 11,
      "y": 24,
      "z": 10,
      "name": "Rock_Crystal_Green_Block"
    },
    {
      "x": 11,
      "y": 25,
      "z": 10,
      "name": "Plant_Crop_Mushroom_Block_Green"
    },
    {
      "x": 11,
      "y": 26,
      "z": 10,
      "name": "Plant_Crop_Mushroom_Block_Green"
    },
    {
      "x": 11,
      "y": 23,
      "z": 11,
      "name": "Rock_Crystal_Green_Block"
    },
    {
      "x": 11,
      "y": 24,
      "z": 11,
      "name": "Plant_Crop_Mushroom_Block_Green"
    },
    {
      "x": 11,
      "y": 25,
      "z": 11,
      "name": "Plant_Crop_Mushroom_Block_Green"
    },
    {
      "x": 11,
      "y": 26,
      "z": 11,
      "name": "Plant_Crop_Mushroom_Block_Green"
    },
    {
      "x": 11,
      "y": 22,
      "z": 12,
      "name": "Plant_Crop_Mushroom_Block_Green"
    },
    {
      "x": 11,
      "y": 23,
      "z": 12,
      "name": "Plant_Crop_Mushroom_Block_Green"
    },
    {
      "x": 11,
      "y": 24,
      "z": 12,
      "name": "Plant_Crop_Mushroom_Block_Green"
    },
    {
      "x": 11,
      "y": 25,
      "z": 12,
      "name": "Plant_Crop_Mushroom_Block_Green"
    },
    {
      "x": 11,
      "y": 22,
      "z": 13,
      "name": "Plant_Crop_Mushroom_Block_Green"
    },
    {
      "x": 11,
      "y": 23,
      "z": 13,
      "name": "Plant_Crop_Mushroom_Block_Green"
    },
    {
      "x": 12,
      "y": 8,
      "z": 5,
      "name": "Wood_Fir_Trunk_Full",
      "rotation": 4
    },
    {
      "x": 12,
      "y": 22,
      "z": 5,
      "name": "Plant_Crop_Mushroom_Block_Green"
    },
    {
      "x": 12,
      "y": 23,
      "z": 5,
      "name": "Plant_Crop_Mushroom_Block_Green"
    },
    {
      "x": 12,
      "y": 24,
      "z": 5,
      "name": "Plant_Crop_Mushroom_Block_Green"
    },
    {
      "x": 12,
      "y": 6,
      "z": 6,
      "name": "Wood_Fir_Trunk_Full",
      "rotation": 4
    },
    {
      "x": 12,
      "y": 8,
      "z": 6,
      "name": "Wood_Fir_Trunk_Full",
      "rotation": 5
    },
    {
      "x": 12,
      "y": 23,
      "z": 6,
      "name": "Plant_Crop_Mushroom_Block_Green"
    },
    {
      "x": 12,
      "y": 24,
      "z": 6,
      "name": "Plant_Crop_Mushroom_Block_Green"
    },
    {
      "x": 12,
      "y": 25,
      "z": 6,
      "name": "Plant_Crop_Mushroom_Block_Green"
    },
    {
      "x": 12,
      "y": 5,
      "z": 7,
      "name": "Wood_Fir_Trunk_Full"
    },
    {
      "x": 12,
      "y": 6,
      "z": 7,
      "name": "Wood_Fir_Trunk_Full",
      "rotation": 4
    },
    {
      "x": 12,
      "y": 8,
      "z": 7,
      "name": "Wood_Fir_Trunk_Full"
    },
    {
      "x": 12,
      "y": 9,
      "z": 7,
      "name": "Wood_Fir_Trunk_Full"
    },
    {
      "x": 12,
      "y": 10,
      "z": 7,
      "name": "Wood_Fir_Trunk_Full"
    },
    {
      "x": 12,
      "y": 11,
      "z": 7,
      "name": "Wood_Fir_Trunk_Full"
    },
    {
      "x": 12,
      "y": 24,
      "z": 7,
      "name": "Rock_Crystal_Green_Block"
    },
    {
      "x": 12,
      "y": 25,
      "z": 7,
      "name": "Plant_Crop_Mushroom_Block_Green"
    },
    {
      "x": 12,
      "y": 26,
      "z": 7,
      "name": "Plant_Crop_Mushroom_Block_Green"
    },
    {
      "x": 12,
      "y": 6,
      "z": 8,
      "name": "Wood_Fir_Trunk_Full"
    },
    {
      "x": 12,
      "y": 7,
      "z": 8,
      "name": "Wood_Fir_Trunk_Full"
    },
    {
      "x": 12,
      "y": 8,
      "z": 8,
      "name": "Wood_Fir_Trunk_Full"
    },
    {
      "x": 12,
      "y": 9,
      "z": 8,
      "name": "Wood_Fir_Trunk_Full",
      "rotation": 4
    },
    {
      "x": 12,
      "y": 10,
      "z": 8,
      "name": "Wood_Fir_Trunk_Full",
      "rotation": 4
    },
    {
      "x": 12,
      "y": 11,
      "z": 8,
      "name": "Wood_Fir_Trunk_Full"
    },
    {
      "x": 12,
      "y": 12,
      "z": 8,
      "name": "Wood_Fir_Trunk_Full",
      "rotation": 4
    },
    {
      "x": 12,
      "y": 13,
      "z": 8,
      "name": "Wood_Fir_Trunk_Full",
      "rotation": 4
    },
    {
      "x": 12,
      "y": 14,
      "z": 8,
      "name": "Wood_Fir_Trunk_Full",
      "rotation": 4
    },
    {
      "x": 12,
      "y": 24,
      "z": 8,
      "name": "Rock_Crystal_Green_Block"
    },
    {
      "x": 12,
      "y": 25,
      "z": 8,
      "name": "Plant_Crop_Mushroom_Block_Green"
    },
    {
      "x": 12,
      "y": 26,
      "z": 8,
      "name": "Plant_Crop_Mushroom_Block_Green"
    },
    {
      "x": 12,
      "y": 5,
      "z": 9,
      "name": "Wood_Fir_Trunk_Full"
    },
    {
      "x": 12,
      "y": 6,
      "z": 9,
      "name": "Wood_Fir_Trunk_Full"
    },
    {
      "x": 12,
      "y": 7,
      "z": 9,
      "name": "Wood_Fir_Trunk_Full",
      "rotation": 4
    },
    {
      "x": 12,
      "y": 8,
      "z": 9,
      "name": "Wood_Fir_Trunk_Full"
    },
    {
      "x": 12,
      "y": 9,
      "z": 9,
      "name": "Wood_Fir_Trunk_Full"
    },
    {
      "x": 12,
      "y": 10,
      "z": 9,
      "name": "Wood_Fir_Trunk_Full"
    },
    {
      "x": 12,
      "y": 11,
      "z": 9,
      "name": "Wood_Fir_Trunk_Full"
    },
    {
      "x": 12,
      "y": 12,
      "z": 9,
      "name": "Wood_Fir_Trunk_Full"
    },
    {
      "x": 12,
      "y": 13,
      "z": 9,
      "name": "Wood_Fir_Trunk_Full"
    },
    {
      "x": 12,
      "y": 14,
      "z": 9,
      "name": "Wood_Fir_Trunk_Full"
    },
    {
      "x": 12,
      "y": 15,
      "z": 9,
      "name": "Wood_Fir_Trunk_Full",
      "rotation": 4
    },
    {
      "x": 12,
      "y": 24,
      "z": 9,
      "name": "Rock_Crystal_Green_Block"
    },
    {
      "x": 12,
      "y": 25,
      "z": 9,
      "name": "Plant_Crop_Mushroom_Block_Green"
    },
    {
      "x": 12,
      "y": 26,
      "z": 9,
      "name": "Plant_Crop_Mushroom_Block_Green"
    },
    {
      "x": 12,
      "y": 23,
      "z": 10,
      "name": "Rock_Crystal_Green_Block"
    },
    {
      "x": 12,
      "y": 24,
      "z": 10,
      "name": "Plant_Crop_Mushroom_Block_Green"
    },
    {
      "x": 12,
      "y": 25,
      "z": 10,
      "name": "Plant_Crop_Mushroom_Block_Green"
    },
    {
      "x": 12,
      "y": 26,
      "z": 10,
      "name": "Plant_Crop_Mushroom_Block_Green"
    },
    {
      "x": 12,
      "y": 23,
      "z": 11,
      "name": "Rock_Crystal_Green_Block"
    },
    {
      "x": 12,
      "y": 24,
      "z": 11,
      "name": "Plant_Crop_Mushroom_Block_Green"
    },
    {
      "x": 12,
      "y": 25,
      "z": 11,
      "name": "Plant_Crop_Mushroom_Block_Green"
    },
    {
      "x": 12,
      "y": 21,
      "z": 12,
      "name": "Plant_Crop_Mushroom_Block_Green"
    },
    {
      "x": 12,
      "y": 22,
      "z": 12,
      "name": "Plant_Crop_Mushroom_Block_Green"
    },
    {
      "x": 12,
      "y": 23,
      "z": 12,
      "name": "Plant_Crop_Mushroom_Block_Green"
    },
    {
      "x": 12,
      "y": 24,
      "z": 12,
      "name": "Plant_Crop_Mushroom_Block_Green"
    },
    {
      "x": 12,
      "y": 21,
      "z": 13,
      "name": "Plant_Crop_Mushroom_Block_Green"
    },
    {
      "x": 12,
      "y": 22,
      "z": 13,
      "name": "Plant_Crop_Mushroom_Block_Green"
    },
    {
      "x": 13,
      "y": 6,
      "z": 5,
      "name": "Wood_Fir_Trunk_Full"
    },
    {
      "x": 13,
      "y": 7,
      "z": 5,
      "name": "Wood_Fir_Trunk_Full"
    },
    {
      "x": 13,
      "y": 8,
      "z": 5,
      "name": "Wood_Fir_Trunk_Full",
      "rotation": 4
    },
    {
      "x": 13,
      "y": 22,
      "z": 5,
      "name": "Plant_Crop_Mushroom_Block_Green"
    },
    {
      "x": 13,
      "y": 4,
      "z": 6,
      "name": "Wood_Fir_Trunk_Full",
      "rotation": 4
    },
    {
      "x": 13,
      "y": 7,
      "z": 6,
      "name": "Wood_Fir_Trunk_Full"
    },
    {
      "x": 13,
      "y": 8,
      "z": 6,
      "name": "Wood_Fir_Trunk_Full"
    },
    {
      "x": 13,
      "y": 9,
      "z": 6,
      "name": "Wood_Fir_Trunk_Full"
    },
    {
      "x": 13,
      "y": 10,
      "z": 6,
      "name": "Wood_Fir_Trunk_Full"
    },
    {
      "x": 13,
      "y": 11,
      "z": 6,
      "name": "Wood_Fir_Trunk_Full"
    },
    {
      "x": 13,
      "y": 12,
      "z": 6,
      "name": "Wood_Fir_Trunk_Full",
      "rotation": 4
    },
    {
      "x": 13,
      "y": 18,
      "z": 6,
      "name": "Plant_Crop_Mushroom_Block_Green"
    },
    {
      "x": 13,
      "y": 22,
      "z": 6,
      "name": "Plant_Crop_Mushroom_Block_Green"
    },
    {
      "x": 13,
      "y": 23,
      "z": 6,
      "name": "Plant_Crop_Mushroom_Block_Green"
    },
    {
      "x": 13,
      "y": 24,
      "z": 6,
      "name": "Plant_Crop_Mushroom_Block_Green"
    },
    {
      "x": 13,
      "y": 3,
      "z": 7,
      "name": "Wood_Fir_Trunk_Full"
    },
    {
      "x": 13,
      "y": 4,
      "z": 7,
      "name": "Wood_Fir_Trunk_Full"
    },
    {
      "x": 13,
      "y": 5,
      "z": 7,
      "name": "Wood_Fir_Trunk_Full",
      "rotation": 5
    },
    {
      "x": 13,
      "y": 6,
      "z": 7,
      "name": "Wood_Fir_Trunk_Full",
      "rotation": 5
    },
    {
      "x": 13,
      "y": 8,
      "z": 7,
      "name": "Wood_Fir_Trunk_Full"
    },
    {
      "x": 13,
      "y": 9,
      "z": 7,
      "name": "Wood_Fir_Trunk_Full"
    },
    {
      "x": 13,
      "y": 10,
      "z": 7,
      "name": "Wood_Fir_Trunk_Full"
    },
    {
      "x": 13,
      "y": 11,
      "z": 7,
      "name": "Wood_Fir_Trunk_Full",
      "rotation": 4
    },
    {
      "x": 13,
      "y": 12,
      "z": 7,
      "name": "Wood_Fir_Trunk_Full"
    },
    {
      "x": 13,
      "y": 13,
      "z": 7,
      "name": "Wood_Fir_Trunk_Full"
    },
    {
      "x": 13,
      "y": 18,
      "z": 7,
      "name": "Plant_Crop_Mushroom_Block_Green"
    },
    {
      "x": 13,
      "y": 19,
      "z": 7,
      "name": "Plant_Crop_Mushroom_Block_Green"
    },
    {
      "x": 13,
      "y": 23,
      "z": 7,
      "name": "Plant_Crop_Mushroom_Block_Green"
    },
    {
      "x": 13,
      "y": 24,
      "z": 7,
      "name": "Plant_Crop_Mushroom_Block_Green"
    },
    {
      "x": 13,
      "y": 25,
      "z": 7,
      "name": "Plant_Crop_Mushroom_Block_Green"
    },
    {
      "x": 13,
      "y": 7,
      "z": 8,
      "name": "Wood_Fir_Trunk_Full",
      "rotation": 5
    },
    {
      "x": 13,
      "y": 9,
      "z": 8,
      "name": "Wood_Fir_Trunk_Full"
    },
    {
      "x": 13,
      "y": 10,
      "z": 8,
      "name": "Wood_Fir_Trunk_Full",
      "rotation": 5
    },
    {
      "x": 13,
      "y": 11,
      "z": 8,
      "name": "Wood_Fir_Trunk_Full",
      "rotation": 5
    },
    {
      "x": 13,
      "y": 12,
      "z": 8,
      "name": "Wood_Fir_Trunk_Full"
    },
    {
      "x": 13,
      "y": 18,
      "z": 8,
      "name": "Plant_Crop_Mushroom_Block_Green"
    },
    {
      "x": 13,
      "y": 19,
      "z": 8,
      "name": "Plant_Crop_Mushroom_Block_Green"
    },
    {
      "x": 13,
      "y": 24,
      "z": 8,
      "name": "Plant_Crop_Mushroom_Block_Green"
    },
    {
      "x": 13,
      "y": 25,
      "z": 8,
      "name": "Plant_Crop_Mushroom_Block_Green"
    },
    {
      "x": 13,
      "y": 18,
      "z": 9,
      "name": "Plant_Crop_Mushroom_Block_Green"
    },
    {
      "x": 13,
      "y": 24,
      "z": 9,
      "name": "Plant_Crop_Mushroom_Block_Green"
    },
    {
      "x": 13,
      "y": 25,
      "z": 9,
      "name": "Plant_Crop_Mushroom_Block_Green"
    },
    {
      "x": 13,
      "y": 22,
      "z": 10,
      "name": "Plant_Crop_Mushroom_Block_Green"
    },
    {
      "x": 13,
      "y": 23,
      "z": 10,
      "name": "Plant_Crop_Mushroom_Block_Green"
    },
    {
      "x": 13,
      "y": 24,
      "z": 10,
      "name": "Plant_Crop_Mushroom_Block_Green"
    },
    {
      "x": 13,
      "y": 25,
      "z": 10,
      "name": "Plant_Crop_Mushroom_Block_Green"
    },
    {
      "x": 13,
      "y": 22,
      "z": 11,
      "name": "Plant_Crop_Mushroom_Block_Green"
    },
    {
      "x": 13,
      "y": 23,
      "z": 11,
      "name": "Plant_Crop_Mushroom_Block_Green"
    },
    {
      "x": 13,
      "y": 24,
      "z": 11,
      "name": "Plant_Crop_Mushroom_Block_Green"
    },
    {
      "x": 13,
      "y": 21,
      "z": 12,
      "name": "Plant_Crop_Mushroom_Block_Green"
    },
    {
      "x": 13,
      "y": 22,
      "z": 12,
      "name": "Plant_Crop_Mushroom_Block_Green"
    },
    {
      "x": 13,
      "y": 23,
      "z": 12,
      "name": "Plant_Crop_Mushroom_Block_Green"
    },
    {
      "x": 13,
      "y": 21,
      "z": 13,
      "name": "Plant_Crop_Mushroom_Block_Green"
    },
    {
      "x": 14,
      "y": 9,
      "z": 5,
      "name": "Wood_Fir_Trunk_Full",
      "rotation": 4
    },
    {
      "x": 14,
      "y": 7,
      "z": 6,
      "name": "Wood_Fir_Trunk_Full"
    },
    {
      "x": 14,
      "y": 8,
      "z": 6,
      "name": "Wood_Fir_Trunk_Full"
    },
    {
      "x": 14,
      "y": 9,
      "z": 6,
      "name": "Wood_Fir_Trunk_Full"
    },
    {
      "x": 14,
      "y": 10,
      "z": 6,
      "name": "Wood_Fir_Trunk_Full"
    },
    {
      "x": 14,
      "y": 11,
      "z": 6,
      "name": "Wood_Fir_Trunk_Full"
    },
    {
      "x": 14,
      "y": 12,
      "z": 6,
      "name": "Wood_Fir_Trunk_Full",
      "rotation": 5
    },
    {
      "x": 14,
      "y": 13,
      "z": 6,
      "name": "Wood_Fir_Trunk_Full"
    },
    {
      "x": 14,
      "y": 14,
      "z": 6,
      "name": "Wood_Fir_Trunk_Full"
    },
    {
      "x": 14,
      "y": 15,
      "z": 6,
      "name": "Wood_Fir_Trunk_Full"
    },
    {
      "x": 14,
      "y": 18,
      "z": 6,
      "name": "Plant_Crop_Mushroom_Block_Green"
    },
    {
      "x": 14,
      "y": 19,
      "z": 6,
      "name": "Plant_Crop_Mushroom_Block_Green"
    },
    {
      "x": 14,
      "y": 20,
      "z": 6,
      "name": "Plant_Crop_Mushroom_Block_Green"
    },
    {
      "x": 14,
      "y": 6,
      "z": 7,
      "name": "Wood_Fir_Trunk_Full",
      "rotation": 5
    },
    {
      "x": 14,
      "y": 8,
      "z": 7,
      "name": "Wood_Fir_Trunk_Full"
    },
    {
      "x": 14,
      "y": 9,
      "z": 7,
      "name": "Wood_Fir_Trunk_Full"
    },
    {
      "x": 14,
      "y": 10,
      "z": 7,
      "name": "Wood_Fir_Trunk_Full"
    },
    {
      "x": 14,
      "y": 11,
      "z": 7,
      "name": "Wood_Fir_Trunk_Full"
    },
    {
      "x": 14,
      "y": 12,
      "z": 7,
      "name": "Wood_Fir_Trunk_Full",
      "rotation": 5
    },
    {
      "x": 14,
      "y": 13,
      "z": 7,
      "name": "Wood_Fir_Trunk_Full"
    },
    {
      "x": 14,
      "y": 14,
      "z": 7,
      "name": "Wood_Fir_Trunk_Full"
    },
    {
      "x": 14,
      "y": 15,
      "z": 7,
      "name": "Wood_Fir_Trunk_Full"
    },
    {
      "x": 14,
      "y": 16,
      "z": 7,
      "name": "Wood_Fir_Trunk_Full"
    },
    {
      "x": 14,
      "y": 19,
      "z": 7,
      "name": "Plant_Crop_Mushroom_Block_Green"
    },
    {
      "x": 14,
      "y": 20,
      "z": 7,
      "name": "Plant_Crop_Mushroom_Block_Green"
    },
    {
      "x": 14,
      "y": 19,
      "z": 8,
      "name": "Plant_Crop_Mushroom_Block_Green"
    },
    {
      "x": 14,
      "y": 20,
      "z": 8,
      "name": "Plant_Crop_Mushroom_Block_Green"
    },
    {
      "x": 14,
      "y": 23,
      "z": 8,
      "name": "Plant_Crop_Mushroom_Block_Green"
    },
    {
      "x": 14,
      "y": 24,
      "z": 8,
      "name": "Plant_Crop_Mushroom_Block_Green"
    },
    {
      "x": 14,
      "y": 18,
      "z": 9,
      "name": "Plant_Crop_Mushroom_Block_Green"
    },
    {
      "x": 14,
      "y": 19,
      "z": 9,
      "name": "Plant_Crop_Mushroom_Block_Green"
    },
    {
      "x": 14,
      "y": 20,
      "z": 9,
      "name": "Plant_Crop_Mushroom_Block_Green"
    },
    {
      "x": 14,
      "y": 23,
      "z": 9,
      "name": "Plant_Crop_Mushroom_Block_Green"
    },
    {
      "x": 14,
      "y": 24,
      "z": 9,
      "name": "Plant_Crop_Mushroom_Block_Green"
    },
    {
      "x": 14,
      "y": 22,
      "z": 10,
      "name": "Plant_Crop_Mushroom_Block_Green"
    },
    {
      "x": 14,
      "y": 23,
      "z": 10,
      "name": "Plant_Crop_Mushroom_Block_Green"
    },
    {
      "x": 14,
      "y": 22,
      "z": 11,
      "name": "Plant_Crop_Mushroom_Block_Green"
    },
    {
      "x": 14,
      "y": 23,
      "z": 11,
      "name": "Plant_Crop_Mushroom_Block_Green"
    },
    {
      "x": 14,
      "y": 22,
      "z": 12,
      "name": "Plant_Crop_Mushroom_Block_Green"
    },
    {
      "x": 15,
      "y": 18,
      "z": 5,
      "name": "Plant_Crop_Mushroom_Block_Green"
    },
    {
      "x": 15,
      "y": 19,
      "z": 5,
      "name": "Plant_Crop_Mushroom_Block_Green"
    },
    {
      "x": 15,
      "y": 18,
      "z": 6,
      "name": "Plant_Crop_Mushroom_Block_Green"
    },
    {
      "x": 15,
      "y": 19,
      "z": 6,
      "name": "Plant_Crop_Mushroom_Block_Green"
    },
    {
      "x": 15,
      "y": 20,
      "z": 6,
      "name": "Plant_Crop_Mushroom_Block_Green"
    },
    {
      "x": 15,
      "y": 15,
      "z": 7,
      "name": "Wood_Fir_Trunk_Full"
    },
    {
      "x": 15,
      "y": 16,
      "z": 7,
      "name": "Wood_Fir_Trunk_Full"
    },
    {
      "x": 15,
      "y": 17,
      "z": 7,
      "name": "Wood_Fir_Trunk_Full"
    },
    {
      "x": 15,
      "y": 18,
      "z": 7,
      "name": "Wood_Fir_Trunk_Full"
    },
    {
      "x": 15,
      "y": 19,
      "z": 7,
      "name": "Rock_Crystal_Green_Block"
    },
    {
      "x": 15,
      "y": 20,
      "z": 7,
      "name": "Plant_Crop_Mushroom_Block_Green"
    },
    {
      "x": 15,
      "y": 19,
      "z": 8,
      "name": "Rock_Crystal_Green_Block"
    },
    {
      "x": 15,
      "y": 20,
      "z": 8,
      "name": "Plant_Crop_Mushroom_Block_Green"
    },
    {
      "x": 15,
      "y": 19,
      "z": 9,
      "name": "Plant_Crop_Mushroom_Block_Green"
    },
    {
      "x": 15,
      "y": 20,
      "z": 9,
      "name": "Plant_Crop_Mushroom_Block_Green"
    },
    {
      "x": 15,
      "y": 18,
      "z": 10,
      "name": "Plant_Crop_Mushroom_Block_Green"
    },
    {
      "x": 15,
      "y": 19,
      "z": 10,
      "name": "Plant_Crop_Mushroom_Block_Green"
    },
    {
      "x": 16,
      "y": 17,
      "z": 5,
      "name": "Plant_Crop_Mushroom_Block_Green"
    },
    {
      "x": 16,
      "y": 18,
      "z": 5,
      "name": "Plant_Crop_Mushroom_Block_Green"
    },
    {
      "x": 16,
      "y": 19,
      "z": 5,
      "name": "Plant_Crop_Mushroom_Block_Green"
    },
    {
      "x": 16,
      "y": 18,
      "z": 6,
      "name": "Plant_Crop_Mushroom_Block_Green"
    },
    {
      "x": 16,
      "y": 19,
      "z": 6,
      "name": "Plant_Crop_Mushroom_Block_Green"
    },
    {
      "x": 16,
      "y": 20,
      "z": 6,
      "name": "Plant_Crop_Mushroom_Block_Green"
    },
    {
      "x": 16,
      "y": 19,
      "z": 7,
      "name": "Rock_Crystal_Green_Block"
    },
    {
      "x": 16,
      "y": 20,
      "z": 7,
      "name": "Plant_Crop_Mushroom_Block_Green"
    },
    {
      "x": 16,
      "y": 19,
      "z": 8,
      "name": "Rock_Crystal_Green_Block"
    },
    {
      "x": 16,
      "y": 20,
      "z": 8,
      "name": "Plant_Crop_Mushroom_Block_Green"
    },
    {
      "x": 16,
      "y": 19,
      "z": 9,
      "name": "Plant_Crop_Mushroom_Block_Green"
    },
    {
      "x": 16,
      "y": 20,
      "z": 9,
      "name": "Plant_Crop_Mushroom_Block_Green"
    },
    {
      "x": 16,
      "y": 18,
      "z": 10,
      "name": "Plant_Crop_Mushroom_Block_Green"
    },
    {
      "x": 16,
      "y": 19,
      "z": 10,
      "name": "Plant_Crop_Mushroom_Block_Green"
    },
    {
      "x": 17,
      "y": 17,
      "z": 5,
      "name": "Plant_Crop_Mushroom_Block_Green"
    },
    {
      "x": 17,
      "y": 18,
      "z": 5,
      "name": "Plant_Crop_Mushroom_Block_Green"
    },
    {
      "x": 17,
      "y": 18,
      "z": 6,
      "name": "Plant_Crop_Mushroom_Block_Green"
    },
    {
      "x": 17,
      "y": 19,
      "z": 6,
      "name": "Plant_Crop_Mushroom_Block_Green"
    },
    {
      "x": 17,
      "y": 19,
      "z": 7,
      "name": "Plant_Crop_Mushroom_Block_Green"
    },
    {
      "x": 17,
      "y": 20,
      "z": 7,
      "name": "Plant_Crop_Mushroom_Block_Green"
    },
    {
      "x": 17,
      "y": 19,
      "z": 8,
      "name": "Plant_Crop_Mushroom_Block_Green"
    },
    {
      "x": 17,
      "y": 18,
      "z": 9,
      "name": "Plant_Crop_Mushroom_Block_Green"
    },
    {
      "x": 17,
      "y": 19,
      "z": 9,
      "name": "Plant_Crop_Mushroom_Block_Green"
    },
    {
      "x": 17,
      "y": 17,
      "z": 10,
      "name": "Plant_Crop_Mushroom_Block_Green"
    },
    {
      "x": 17,
      "y": 18,
      "z": 10,
      "name": "Plant_Crop_Mushroom_Block_Green"
    },
    {
      "x": 18,
      "y": 17,
      "z": 6,
      "name": "Plant_Crop_Mushroom_Block_Green"
    },
    {
      "x": 18,
      "y": 17,
      "z": 7,
      "name": "Plant_Crop_Mushroom_Block_Green"
    },
    {
      "x": 18,
      "y": 18,
      "z": 7,
      "name": "Plant_Crop_Mushroom_Block_Green"
    },
    {
      "x": 18,
      "y": 17,
      "z": 8,
      "name": "Plant_Crop_Mushroom_Block_Green"
    },
    {
      "x": 18,
      "y": 18,
      "z": 8,
      "name": "Plant_Crop_Mushroom_Block_Green"
    },
    {
      "x": 18,
      "y": 19,
      "z": 8,
      "name": "Plant_Crop_Mushroom_Block_Green"
    },
    {
      "x": 18,
      "y": 17,
      "z": 9,
      "name": "Plant_Crop_Mushroom_Block_Green"
    },
    {
      "x": 18,
      "y": 18,
      "z": 9,
      "name": "Plant_Crop_Mushroom_Block_Green"
    },
    {
      "x": 18,
      "y": 17,
      "z": 10,
      "name": "Plant_Crop_Mushroom_Block_Green"
    }
  ]
}