{
  "version": 8,
  "blockIdVersion": 8,
  "anchorX": 9,
  "anchorY": 10,
  "anchorZ": 8,
  "blocks": [
    {
      "x": 2,
      "y": 28,
      "z": 9,
      "name": "Plant_Crop_Mushroom_Block_Green"
    },
    {
      "x": 2,
      "y": 28,
      "z": 10,
      "name": "Plant_Crop_Mushroom_Block_Green"
    },
    {
      "x": 3,
      "y": 28,
      "z": 5,
      "name": "Plant_Crop_Mushroom_Block_Green"
    },
    {
      "x": 3,
      "y": 28,
      "z": 6,
      "name": "Plant_Crop_Mushroom_Block_Green"
    },
    {
      "x": 3,
      "y": 29,
      "z": 8,
      "name": "Plant_Crop_Mushroom_Block_Green"
    },
    {
      "x": 3,
      "y": 28,
      "z": 9,
      "name": "Plant_Crop_Mushroom_Block_Green"
    },
    {
      "x": 3,
      "y": 29,
      "z": 9,
      "name": "Plant_Crop_Mushroom_Block_Green"
    },
    {
      "x": 3,
      "y": 30,
      "z": 9,
      "name": "Plant_Crop_Mushroom_Block_Green"
    },
    {
      "x": 3,
      "y": 28,
      "z": 10,
      "name": "Plant_Crop_Mushroom_Block_Green"
    },
    {
      "x": 3,
      "y": 29,
      "z": 10,
      "name": "Plant_Crop_Mushroom_Block_Green"
    },
    {
      "x": 3,
      "y": 30,
      "z": 10,
      "name": "Plant_Crop_Mushroom_Block_Green"
    },
    {
      "x": 3,
      "y": 28,
      "z": 11,
      "name": "Plant_Crop_Mushroom_Block_Green"
    },
    {
      "x": 3,
      "y": 29,
      "z": 11,
      "name": "Plant_Crop_Mushroom_Block_Green"
    },
    {
      "x": 3,
      "y": 27,
      "z": 12,
      "name": "Plant_Crop_Mushroom_Block_Green"
    },
    {
      "x": 3,
      "y": 28,
      "z": 12,
      "name": "Plant_Crop_Mushroom_Block_Green"
    },
    {
      "x": 3,
      "y": 27,
      "z": 13,
      "name": "Plant_Crop_Mushroom_Block_Green"
    },
    {
      "x": 4,
      "y": 28,
      "z": 4,
      "name": "Plant_Crop_Mushroom_Block_Green"
    },
    {
      "x": 4,
      "y": 28,
      "z": 5,
      "name": "Plant_Crop_Mushroom_Block_Green"
    },
    {
      "x": 4,
      "y": 29,
      "z": 5,
      "name": "Plant_Crop_Mushroom_Block_Green"
    },
    {
      "x": 4,
      "y": 30,
      "z": 5,
      "name": "Plant_Crop_Mushroom_Block_Green"
    },
    {
      "x": 4,
      "y": 28,
      "z": 6,
      "name": "Plant_Crop_Mushroom_Block_Green"
    },
    {
      "x": 4,
      "y": 29,
      "z": 6,
      "name": "Plant_Crop_Mushroom_Block_Green"
    },
    {
      "x": 4,
      "y": 30,
      "z": 6,
      "name": "Plant_Crop_Mushroom_Block_Green"
    },
    {
      "x": 4,
      "y": 31,
      "z": 6,
      "name": "Plant_Crop_Mushroom_Block_Green"
    },
    {
      "x": 4,
      "y": 29,
      "z": 7,
      "name": "Plant_Crop_Mushroom_Block_Green"
    },
    {
      "x": 4,
      "y": 30,
      "z": 7,
      "name": "Plant_Crop_Mushroom_Block_Green"
    },
    {
      "x": 4,
      "y": 31,
      "z": 7,
      "name": "Plant_Crop_Mushroom_Block_Green"
    },
    {
      "x": 4,
      "y": 32,
      "z": 7,
      "name": "Plant_Crop_Mushroom_Block_Green"
    },
    {
      "x": 4,
      "y": 30,
      "z": 8,
      "name": "Plant_Crop_Mushroom_Block_Green"
    },
    {
      "x": 4,
      "y": 31,
      "z": 8,
      "name": "Plant_Crop_Mushroom_Block_Green"
    },
    {
      "x": 4,
      "y": 32,
      "z": 8,
      "name": "Plant_Crop_Mushroom_Block_Green"
    },
    {
      "x": 4,
      "y": 30,
      "z": 9,
      "name": "Plant_Crop_Mushroom_Block_Green"
    },
    {
      "x": 4,
      "y": 31,
      "z": 9,
      "name": "Plant_Crop_Mushroom_Block_Green"
    },
    {
      "x": 4,
      "y": 32,
      "z": 9,
      "name": "Plant_Crop_Mushroom_Block_Green"
    },
    {
      "x": 4,
      "y": 29,
      "z": 10,
      "name": "Plant_Crop_Mushroom_Block_Green"
    },
    {
      "x": 4,
      "y": 30,
      "z": 10,
      "name": "Plant_Crop_Mushroom_Block_Green"
    },
    {
      "x": 4,
      "y": 31,
      "z": 10,
      "name": "Plant_Crop_Mushroom_Block_Green"
    },
    {
      "x": 4,
      "y": 28,
      "z": 11,
      "name": "Plant_Crop_Mushroom_Block_Green"
    },
    {
      "x": 4,
      "y": 29,
      "z": 11,
      "name": "Plant_Crop_Mushroom_Block_Green"
    },
    {
      "x": 4,
      "y": 30,
      "z": 11,
      "name": "Plant_Crop_Mushroom_Block_Green"
    },
    {
      "x": 4,
      "y": 31,
      "z": 11,
      "name": "Plant_Crop_Mushroom_Block_Green"
    },
    {
      "x": 4,
      "y": 27,
      "z": 12,
      "name": "Plant_Crop_Mushroom_Block_Green"
    },
    {
      "x": 4,
      "y": 28,
      "z": 12,
      "name": "Plant_Crop_Mushroom_Block_Green"
    },
    {
      "x": 4,
      "y": 29,
      "z": 12,
      "name": "Plant_Crop_Mushroom_Block_Green"
    },
    {
      "x": 4,
      "y": 27,
      "z": 13,
      "name": "Plant_Crop_Mushroom_Block_Green"
    },
    {
      "x": 4,
      "y": 28,
      "z": 13,
      "name": "Plant_Crop_Mushroom_Block_Green"
    },
    {
      "x": 5,
      "y": 28,
      "z": 4,
      "name": "Plant_Crop_Mushroom_Block_Green"
    },
    {
      "x": 5,
      "y": 29,
      "z": 4,
      "name": "Plant_Crop_Mushroom_Block_Green"
    },
    {
      "x": 5,
      "y": 29,
      "z": 5,
      "name": "Plant_Crop_Mushroom_Block_Green"
    },
    {
      "x": 5,
      "y": 30,
      "z": 5,
      "name": "Plant_Crop_Mushroom_Block_Green"
    },
    {
      "x": 5,
      "y": 31,
      "z": 5,
      "name": "Plant_Crop_Mushroom_Block_Green"
    },
    {
      "x": 5,
      "y": 32,
      "z": 5,
      "name": "Plant_Crop_Mushroom_Block_Green"
    },
    {
      "x": 5,
      "y": 30,
      "z": 6,
      "name": "Plant_Crop_Mushroom_Block_Green"
    },
    {
      "x": 5,
      "y": 31,
      "z": 6,
      "name": "Plant_Crop_Mushroom_Block_Green"
    },
    {
      "x": 5,
      "y": 32,
      "z": 6,
      "name": "Plant_Crop_Mushroom_Block_Green"
    },
    {
      "x": 5,
      "y": 30,
      "z": 7,
      "name": "Plant_Crop_Mushroom_Block_Green"
    },
    {
      "x": 5,
      "y": 31,
      "z": 7,
      "name": "Plant_Crop_Mushroom_Block_Green"
    },
    {
      "x": 5,
      "y": 32,
      "z": 7,
      "name": "Plant_Crop_Mushroom_Block_Green"
    },
    {
      "x": 5,
      "y": 33,
      "z": 7,
      "name": "Plant_Crop_Mushroom_Block_Green"
    },
    {
      "x": 5,
      "y": 31,
      "z": 8,
      "name": "Rock_Crystal_Green_Block"
    },
    {
      "x": 5,
      "y": 32,
      "z": 8,
      "name": "Plant_Crop_Mushroom_Block_Green"
    },
    {
      "x": 5,
      "y": 33,
      "z": 8,
      "name": "Plant_Crop_Mushroom_Block_Green"
    },
    {
      "x": 5,
      "y": 31,
      "z": 9,
      "name": "Rock_Crystal_Green_Block"
    },
    {
      "x": 5,
      "y": 32,
      "z": 9,
      "name": "Plant_Crop_Mushroom_Block_Green"
    },
    {
      "x": 5,
      "y": 33,
      "z": 9,
      "name": "Plant_Crop_Mushroom_Block_Green"
    },
    {
      "x": 5,
      "y": 31,
      "z": 10,
      "name": "Rock_Crystal_Green_Block"
    },
    {
      "x": 5,
      "y": 32,
      "z": 10,
      "name": "Plant_Crop_Mushroom_Block_Green"
    },
    {
      "x": 5,
      "y": 33,
      "z": 10,
      "name": "Plant_Crop_Mushroom_Block_Green"
    },
    {
      "x": 5,
      "y": 30,
      "z": 11,
      "name": "Plant_Crop_Mushroom_Block_Green"
    },
    {
      "x": 5,
      "y": 31,
      "z": 11,
      "name": "Plant_Crop_Mushroom_Block_Green"
    },
    {
      "x": 5,
      "y": 32,
      "z": 11,
      "name": "Plant_Crop_Mushroom_Block_Green"
    },
    {
      "x": 5,
      "y": 33,
      "z": 11,
      "name": "Plant_Crop_Mushroom_Block_Green"
    },
    {
      "x": 5,
      "y": 29,
      "z": 12,
      "name": "Plant_Crop_Mushroom_Block_Green"
    },
    {
      "x": 5,
      "y": 30,
      "z": 12,
      "name": "Plant_Crop_Mushroom_Block_Green"
    },
    {
      "x": 5,
      "y": 31,
      "z": 12,
      "name": "Plant_Crop_Mushroom_Block_Green"
    },
    {
      "x": 5,
      "y": 32,
      "z": 12,
      "name": "Plant_Crop_Mushroom_Block_Green"
    },
    {
      "x": 5,
      "y": 29,
      "z": 13,
      "name": "Plant_Crop_Mushroom_Block_Green"
    },
    {
      "x": 5,
      "y": 30,
      "z": 13,
      "name": "Plant_Crop_Mushroom_Block_Green"
    },
    {
      "x": 5,
      "y": 31,
      "z": 13,
      "name": "Plant_Crop_Mushroom_Block_Green"
    },
    {
      "x": 5,
      "y": 28,
      "z": 14,
      "name": "Plant_Crop_Mushroom_Block_Green"
    },
    {
      "x": 5,
      "y": 29,
      "z": 14,
      "name": "Plant_Crop_Mushroom_Block_Green"
    },
    {
      "x": 6,
      "y": 29,
      "z": 3,
      "name": "Plant_Crop_Mushroom_Block_Green"
    },
    {
      "x": 6,
      "y": 30,
      "z": 3,
      "name": "Plant_Crop_Mushroom_Block_Green"
    },
    {
      "x": 6,
      "y": 29,
      "z": 4,
      "name": "Plant_Crop_Mushroom_Block_Green"
    },
    {
      "x": 6,
      "y": 30,
      "z": 4,
      "name": "Plant_Crop_Mushroom_Block_Green"
    },
    {
      "x": 6,
      "y": 31,
      "z": 4,
      "name": "Plant_Crop_Mushroom_Block_Green"
    },
    {
      "x": 6,
      "y": 32,
      "z": 4,
      "name": "Plant_Crop_Mushroom_Block_Green"
    },
    {
      "x": 6,
      "y": 30,
      "z": 5,
      "name": "Plant_Crop_Mushroom_Block_Green"
    },
    {
      "x": 6,
      "y": 31,
      "z": 5,
      "name": "Plant_Crop_Mushroom_Block_Green"
    },
    {
      "x": 6,
      "y": 32,
      "z": 5,
      "name": "Plant_Crop_Mushroom_Block_Green"
    },
    {
      "x": 6,
      "y": 33,
      "z": 5,
      "name": "Plant_Crop_Mushroom_Block_Green"
    },
    {
      "x": 6,
      "y": 31,
      "z": 6,
      "name": "Rock_Crystal_Green_Block"
    },
    {
      "x": 6,
      "y": 32,
      "z": 6,
      "name": "Plant_Crop_Mushroom_Block_Green"
    },
    {
      "x": 6,
      "y": 33,
      "z": 6,
      "name": "Plant_Crop_Mushroom_Block_Green"
    },
    {
      "x": 6,
      "y": 34,
      "z": 6,
      "name": "Plant_Crop_Mushroom_Block_Green"
    },
    {
      "x": 6,
      "y": 31,
      "z": 7,
      "name": "Rock_Crystal_Green_Block"
    },
    {
      "x": 6,
      "y": 32,
      "z": 7,
      "name": "Plant_Crop_Mushroom_Block_Green"
    },
    {
      "x": 6,
      "y": 33,
      "z": 7,
      "name": "Plant_Crop_Mushroom_Block_Green"
    },
    {
      "x": 6,
      "y": 34,
      "z": 7,
      "name": "Plant_Crop_Mushroom_Block_Green"
    },
    {
      "x": 6,
      "y": 16,
      "z": 8,
      "name": "Wood_Fir_Trunk_Full"
    },
    {
      "x": 6,
      "y": 17,
      "z": 8,
      "name": "Wood_Fir_Trunk_Full"
    },
    {
      "x": 6,
      "y": 18,
      "z": 8,
      "name": "Wood_Fir_Trunk_Full"
    },
    {
      "x": 6,
      "y": 19,
      "z": 8,
      "name": "Wood_Fir_Trunk_Full"
    },
    {
      "x": 6,
      "y": 31,
      "z": 8,
      "name": "Rock_Crystal_Green_Block"
    },
    {
      "x": 6,
      "y": 32,
      "z": 8,
      "name": "Plant_Crop_Mushroom_Block_Green"
    },
    {
      "x": 6,
      "y": 33,
      "z": 8,
      "name": "Plant_Crop_Mushroom_Block_Green"
    },
    {
      "x": 6,
      "y": 34,
      "z": 8,
      "name": "Plant_Crop_Mushroom_Block_Green"
    },
    {
      "x": 6,
      "y": 6,
      "z": 9,
      "name": "Wood_Fir_Trunk_Full",
      "rotation": 5
    },
    {
      "x": 6,
      "y": 17,
      "z": 9,
      "name": "Wood_Fir_Trunk_Full"
    },
    {
      "x": 6,
      "y": 18,
      "z": 9,
      "name": "Wood_Fir_Trunk_Full"
    },
    {
      "x": 6,
      "y": 19,
      "z": 9,
      "name": "Wood_Fir_Trunk_Full"
    },
    {
      "x": 6,
      "y": 20,
      "z": 9,
      "name": "Wood_Fir_Trunk_Full"
    },
    {
      "x": 6,
      "y": 21,
      "z": 9,
      "name": "Wood_Fir_Trunk_Full"
    },
    {
      "x": 6,
      "y": 22,
      "z": 9,
      "name": "Wood_Fir_Trunk_Full"
    },
    {
      "x": 6,
      "y": 31,
      "z": 9,
      "name": "Rock_Crystal_Green_Block"
    },
    {
      "x": 6,
      "y": 32,
      "z": 9,
      "name": "Plant_Crop_Mushroom_Block_Green"
    },
    {
      "x": 6,
      "y": 33,
      "z": 9,
      "name": "Plant_Crop_Mushroom_Block_Green"
    },
    {
      "x": 6,
      "y": 34,
      "z": 9,
      "name": "Plant_Crop_Mushroom_Block_Green"
    },
    {
      "x": 6,
      "y": 20,
      "z": 10,
      "name": "Wood_Fir_Trunk_Full"
    },
    {
      "x": 6,
      "y": 21,
      "z": 10,
      "name": "Wood_Fir_Trunk_Full"
    },
    {
      "x": 6,
      "y": 22,
      "z": 10,
      "name": "Wood_Fir_Trunk_Full",
      "rotation": 5
    },
    {
      "x": 6,
      "y": 31,
      "z": 10,
      "name": "Rock_Crystal_Green_Block"
    },
    {
      "x": 6,
      "y": 32,
      "z": 10,
      "name": "Plant_Crop_Mushroom_Block_Green"
    },
    {
      "x": 6,
      "y": 33,
      "z": 10,
      "name": "Plant_Crop_Mushroom_Block_Green"
    },
    {
      "x": 6,
      "y": 34,
      "z": 10,
      "name": "Plant_Crop_Mushroom_Block_Green"
    },
    {
      "x": 6,
      "y": 31,
      "z": 11,
      "name": "Rock_Crystal_Green_Block"
    },
    {
      "x": 6,
      "y": 32,
      "z": 11,
      "name": "Plant_Crop_Mushroom_Block_Green"
    },
    {
      "x": 6,
      "y": 33,
      "z": 11,
      "name": "Plant_Crop_Mushroom_Block_Green"
    },
    {
      "x": 6,
      "y": 34,
      "z": 11,
      "name": "Plant_Crop_Mushroom_Block_Green"
    },
    {
      "x": 6,
      "y": 31,
      "z": 12,
      "name": "Rock_Crystal_Green_Block"
    },
    {
      "x": 6,
      "y": 32,
      "z": 12,
      "name": "Plant_Crop_Mushroom_Block_Green"
    },
    {
      "x": 6,
      "y": 33,
      "z": 12,
      "name": "Plant_Crop_Mushroom_Block_Green"
    },
    {
      "x": 6,
      "y": 30,
      "z": 13,
      "name": "Plant_Crop_Mushroom_Block_Green"
    },
    {
      "x": 6,
      "y": 31,
      "z": 13,
      "name": "Plant_Crop_Mushroom_Block_Green"
    },
    {
      "x": 6,
      "y": 32,
      "z": 13,
      "name": "Plant_Crop_Mushroom_Block_Green"
    },
    {
      "x": 6,
      "y": 29,
      "z": 14,
      "name": "Plant_Crop_Mushroom_Block_Green"
    },
    {
      "x": 6,
      "y": 30,
      "z": 14,
      "name": "Plant_Crop_Mushroom_Block_Green"
    },
    {
      "x": 6,
      "y": 31,
      "z": 14,
      "name": "Plant_Crop_Mushroom_Block_Green"
    },
    {
      "x": 7,
      "y": 28,
      "z": 2,
      "name": "Plant_Crop_Mushroom_Block_Green"
    },
    {
      "x": 7,
      "y": 29,
      "z": 2,
      "name": "Plant_Crop_Mushroom_Block_Green"
    },
    {
      "x": 7,
      "y": 29,
      "z": 3,
      "name": "Plant_Crop_Mushroom_Block_Green"
    },
    {
      "x": 7,
      "y": 30,
      "z": 3,
      "name": "Plant_Crop_Mushroom_Block_Green"
    },
    {
      "x": 7,
      "y": 31,
      "z": 3,
      "name": "Plant_Crop_Mushroom_Block_Green"
    },
    {
      "x": 7,
      "y": 29,
      "z": 4,
      "name": "Plant_Crop_Mushroom_Block_Green"
    },
    {
      "x": 7,
      "y": 30,
      "z": 4,
      "name": "Plant_Crop_Mushroom_Block_Green"
    },
    {
      "x": 7,
      "y": 31,
      "z": 4,
      "name": "Plant_Crop_Mushroom_Block_Green"
    },
    {
      "x": 7,
      "y": 32,
      "z": 4,
      "name": "Plant_Crop_Mushroom_Block_Green"
    },
    {
      "x": 7,
      "y": 33,
      "z": 4,
      "name": "Plant_Crop_Mushroom_Block_Green"
    },
    {
      "x": 7,
      "y": 31,
      "z": 5,
      "name": "Rock_Crystal_Green_Block"
    },
    {
      "x": 7,
      "y": 32,
      "z": 5,
      "name": "Plant_Crop_Mushroom_Block_Green"
    },
    {
      "x": 7,
      "y": 33,
      "z": 5,
      "name": "Plant_Crop_Mushroom_Block_Green"
    },
    {
      "x": 7,
      "y": 34,
      "z": 5,
      "name": "Plant_Crop_Mushroom_Block_Green"
    },
    {
      "x": 7,
      "y": 3,
      "z": 6,
      "name": "Wood_Fir_Trunk_Full",
      "rotation": 4
    },
    {
      "x": 7,
      "y": 31,
      "z": 6,
      "name": "Rock_Crystal_Green_Block"
    },
    {
      "x": 7,
      "y": 32,
      "z": 6,
      "name": "Plant_Crop_Mushroom_Block_Green"
    },
    {
      "x": 7,
      "y": 33,
      "z": 6,
      "name": "Plant_Crop_Mushroom_Block_Green"
    },
    {
      "x": 7,
      "y": 34,
      "z": 6,
      "name": "Plant_Crop_Mushroom_Block_Green"
    },
    {
      "x": 7,
      "y": 1,
      "z": 7,
      "name": "Wood_Fir_Trunk_Full",
      "rotation": 5
    },
    {
      "x": 7,
      "y": 3,
      "z": 7,
      "name": "Wood_Fir_Trunk_Full"
    },
    {
      "x": 7,
      "y": 4,
      "z": 7,
      "name": "Wood_Fir_Trunk_Full"
    },
    {
      "x": 7,
      "y": 5,
      "z": 7,
      "name": "Wood_Fir_Trunk_Full",
      "rotation": 5
    },
    {
      "x": 7,
      "y": 6,
      "z": 7,
      "name": "Wood_Fir_Trunk_Full",
      "rotation": 5
    },
    {
      "x": 7,
      "y": 14,
      "z": 7,
      "name": "Wood_Fir_Trunk_Full"
    },
    {
      "x": 7,
      "y": 15,
      "z": 7,
      "name": "Wood_Fir_Trunk_Full"
    },
    {
      "x": 7,
      "y": 16,
      "z": 7,
      "name": "Wood_Fir_Trunk_Full"
    },
    {
      "x": 7,
      "y": 17,
      "z": 7,
      "name": "Wood_Fir_Trunk_Full"
    },
    {
      "x": 7,
      "y": 18,
      "z": 7,
      "name": "Wood_Fir_Trunk_Full"
    },
    {
      "x": 7,
      "y": 31,
      "z": 7,
      "name": "Rock_Crystal_Green_Block"
    },
    {
      "x": 7,
      "y": 32,
      "z": 7,
      "name": "Plant_Crop_Mushroom_Block_Green"
    },
    {
      "x": 7,
      "y": 33,
      "z": 7,
      "name": "Plant_Crop_Mushroom_Block_Green"
    },
    {
      "x": 7,
      "y": 34,
      "z": 7,
      "name": "Plant_Crop_Mushroom_Block_Green"
    },
    {
      "x": 7,
      "y": 35,
      "z": 7,
      "name": "Plant_Crop_Mushroom_Block_Green"
    },
    {
      "x": 7,
      "y": 8,
      "z": 8,
      "name": "Wood_Fir_Trunk_Full",
      "rotation": 5
    },
    {
      "x": 7,
      "y": 13,
      "z": 8,
      "name": "Wood_Fir_Trunk_Full"
    },
    {
      "x": 7,
      "y": 14,
      "z": 8,
      "name": "Wood_Fir_Trunk_Full"
    },
    {
      "x": 7,
      "y": 15,
      "z": 8,
      "name": "Wood_Fir_Trunk_Full",
      "rotation": 5
    },
    {
      "x": 7,
      "y": 16,
      "z": 8,
      "name": "Wood_Fir_Trunk_Full"
    },
    {
      "x": 7,
      "y": 17,
      "z": 8,
      "name": "Wood_Fir_Trunk_Full"
    },
    {
      "x": 7,
      "y": 18,
      "z": 8,
      "name": "Wood_Fir_Trunk_Full"
    },
    {
      "x": 7,
      "y": 19,
      "z": 8,
      "name": "Wood_Fir_Trunk_Full"
    },
    {
      "x": 7,
      "y": 20,
      "z": 8,
      "name": "Wood_Fir_Trunk_Full"
    },
    {
      "x": 7,
      "y": 21,
      "z": 8,
      "name": "Wood_Fir_Trunk_Full"
    },
    {
      "x": 7,
      "y": 31,
      "z": 8,
      "name": "Rock_Crystal_Green_Block"
    },
    {
      "x": 7,
      "y": 32,
      "z": 8,
      "name": "Plant_Crop_Mushroom_Block_Green"
    },
    {
      "x": 7,
      "y": 33,
      "z": 8,
      "name": "Plant_Crop_Mushroom_Block_Green"
    },
    {
      "x": 7,
      "y": 34,
      "z": 8,
      "name": "Plant_Crop_Mushroom_Block_Green"
    },
    {
      "x": 7,
      "y": 35,
      "z": 8,
      "name": "Plant_Crop_Mushroom_Block_Green"
    },
    {
      "x": 7,
      "y": 6,
      "z": 9,
      "name": "Wood_Fir_Trunk_Full"
    },
    {
      "x": 7,
      "y": 7,
      "z": 9,
      "name": "Wood_Fir_Trunk_Full",
      "rotation": 5
    },
    {
      "x": 7,
      "y": 9,
      "z": 9,
      "name": "Wood_Fir_Trunk_Full",
      "rotation": 5
    },
    {
      "x": 7,
      "y": 13,
      "z": 9,
      "name": "Wood_Fir_Trunk_Full",
      "rotation": 5
    },
    {
      "x": 7,
      "y": 14,
      "z": 9,
      "name": "Wood_Fir_Trunk_Full"
    },
    {
      "x": 7,
      "y": 15,
      "z": 9,
      "name": "Wood_Fir_Trunk_Full"
    },
    {
      "x": 7,
      "y": 16,
      "z": 9,
      "name": "Wood_Fir_Trunk_Full"
    },
    {
      "x": 7,
      "y": 17,
      "z": 9,
      "name": "Wood_Fir_Trunk_Full"
    },
    {
      "x": 7,
      "y": 18,
      "z": 9,
      "name": "Wood_Fir_Trunk_Full"
    },
    {
      "x": 7,
      "y": 19,
      "z": 9,
      "name": "Wood_Fir_Trunk_Full"
    },
    {
      "x": 7,
      "y": 20,
      "z": 9,
      "name": "Wood_Fir_Trunk_Full"
    },
    {
      "x": 7,
      "y": 21,
      "z": 9,
      "name": "Wood_Fir_Trunk_Full"
    },
    {
      "x": 7,
      "y": 22,
      "z": 9,
      "name": "Wood_Fir_Trunk_Full"
    },
    {
      "x": 7,
      "y": 23,
      "z": 9,
      "name": "Wood_Fir_Trunk_Full"
    },
    {
      "x": 7,
      "y": 24,
      "z": 9,
      "name": "Wood_Fir_Trunk_Full"
    },
    {
      "x": 7,
      "y": 25,
      "z": 9,
      "name": "Wood_Fir_Trunk_Full"
    },
    {
      "x": 7,
      "y": 26,
      "z": 9,
      "name": "Wood_Fir_Trunk_Full"
    },
    {
      "x": 7,
      "y": 31,
      "z": 9,
      "name": "Rock_Crystal_Green_Block"
    },
    {
      "x": 7,
      "y": 32,
      "z": 9,
      "name": "Plant_Crop_Mushroom_Block_Green"
    },
    {
      "x": 7,
      "y": 33,
      "z": 9,
      "name": "Plant_Crop_Mushroom_Block_Green"
    },
    {
      "x": 7,
      "y": 34,
      "z": 9,
      "name": "Plant_Crop_Mushroom_Block_Green"
    },
    {
      "x": 7,
      "y": 35,
      "z": 9,
      "name": "Plant_Crop_Mushroom_Block_Green"
    },
    {
      "x": 7,
      "y": 8,
      "z": 10,
      "name": "Wood_Fir_Trunk_Full",
      "rotation": 5
    },
    {
      "x": 7,
      "y": 17,
      "z": 10,
      "name": "Wood_Fir_Trunk_Full"
    },
    {
      "x": 7,
      "y": 18,
      "z": 10,
      "name": "Wood_Fir_Trunk_Full"
    },
    {
      "x": 7,
      "y": 19,
      "z": 10,
      "name": "Wood_Fir_Trunk_Full"
    },
    {
      "x": 7,
      "y": 20,
      "z": 10,
      "name": "Wood_Fir_Trunk_Full"
    },
    {
      "x": 7,
      "y": 21,
      "z": 10,
      "name": "Wood_Fir_Trunk_Full"
    },
    {
      "x": 7,
      "y": 22,
      "z": 10,
      "name": "Wood_Fir_Trunk_Full"
    },
    {
      "x": 7,
      "y": 23,
      "z": 10,
      "name": "Wood_Fir_Trunk_Full",
      "rotation": 5
    },
    {
      "x": 7,
      "y": 24,
      "z": 10,
      "name": "Wood_Fir_Trunk_Full"
    },
    {
      "x": 7,
      "y": 25,
      "z": 10,
      "name": "Wood_Fir_Trunk_Full"
    },
    {
      "x": 7,
      "y": 31,
      "z": 10,
      "name": "Rock_Crystal_Green_Block"
    },
    {
      "x": 7,
      "y": 32,
      "z": 10,
      "name": "Plant_Crop_Mushroom_Block_Green"
    },
    {
      "x": 7,
      "y": 33,
      "z": 10,
      "name": "Plant_Crop_Mushroom_Block_Green"
    },
    {
      "x": 7,
      "y": 34,
      "z": 10,
      "name": "Plant_Crop_Mushroom_Block_Green"
    },
    {
      "x": 7,
      "y": 35,
      "z": 10,
      "name": "Plant_Crop_Mushroom_Block_Green"
    },
    {
      "x": 7,
      "y": 22,
      "z": 11,
      "name": "Wood_Fir_Trunk_Full"
    },
    {
      "x": 7,
      "y": 23,
      "z": 11,
      "name": "Wood_Fir_Trunk_Full"
    },
    {
      "x": 7,
      "y": 24,
      "z": 11,
      "name": "Wood_Fir_Trunk_Full",
      "rotation": 4
    },
    {
      "x": 7,
      "y": 31,
      "z": 11,
      "name": "Rock_Crystal_Green_Block"
    },
    {
      "x": 7,
      "y": 32,
      "z": 11,
      "name": "Plant_Crop_Mushroom_Block_Green"
    },
    {
      "x": 7,
      "y": 33,
      "z": 11,
      "name": "Plant_Crop_Mushroom_Block_Green"
    },
    {
      "x": 7,
      "y": 34,
      "z": 11,
      "name": "Plant_Crop_Mushroom_Block_Green"
    },
    {
      "x": 7,
      "y": 31,
      "z": 12,
      "name": "Rock_Crystal_Green_Block"
    },
    {
      "x": 7,
      "y": 32,
      "z": 12,
      "name": "Plant_Crop_Mushroom_Block_Green"
    },
    {
      "x": 7,
      "y": 33,
      "z": 12,
      "name": "Plant_Crop_Mushroom_Block_Green"
    },
    {
      "x": 7,
      "y": 34,
      "z": 12,
      "name": "Plant_Crop_Mushroom_Block_Green"
    },
    {
      "x": 7,
      "y": 31,
      "z": 13,
      "name": "Plant_Crop_Mushroom_Block_Green"
    },
    {
      "x": 7,
      "y": 32,
      "z": 13,
      "name": "Plant_Crop_Mushroom_Block_Green"
    },
    {
      "x": 7,
      "y": 33,
      "z": 13,
      "name": "Plant_Crop_Mushroom_Block_Green"
    },
    {
      "x": 7,
      "y": 30,
      "z": 14,
      "name": "Plant_Crop_Mushroom_Block_Green"
    },
    {
      "x": 7,
      "y": 31,
      "z": 14,
      "name": "Plant_Crop_Mushroom_Block_Green"
    },
    {
      "x": 7,
      "y": 32,
      "z": 14,
      "name": "Plant_Crop_Mushroom_Block_Green"
    },
    {
      "x": 7,
      "y": 28,
      "z": 15,
      "name": "Plant_Crop_Mushroom_Block_Green"
    },
    {
      "x": 7,
      "y": 29,
      "z": 15,
      "name": "Plant_Crop_Mushroom_Block_Green"
    },
    {
      "x": 8,
      "y": 28,
      "z": 1,
      "name": "Plant_Crop_Mushroom_Block_Green"
    },
    {
      "x": 8,
      "y": 28,
      "z": 2,
      "name": "Plant_Crop_Mushroom_Block_Green"
    },
    {
      "x": 8,
      "y": 29,
      "z": 2,
      "name": "Plant_Crop_Mushroom_Block_Green"
    },
    {
      "x": 8,
      "y": 29,
      "z": 3,
      "name": "Plant_Crop_Mushroom_Block_Green"
    },
    {
      "x": 8,
      "y": 30,
      "z": 3,
      "name": "Plant_Crop_Mushroom_Block_Green"
    },
    {
      "x": 8,
      "y": 31,
      "z": 3,
      "name": "Plant_Crop_Mushroom_Block_Green"
    },
    {
      "x": 8,
      "y": 31,
      "z": 4,
      "name": "Plant_Crop_Mushroom_Block_Green"
    },
    {
      "x": 8,
      "y": 32,
      "z": 4,
      "name": "Plant_Crop_Mushroom_Block_Green"
    },
    {
      "x": 8,
      "y": 33,
      "z": 4,
      "name": "Plant_Crop_Mushroom_Block_Green"
    },
    {
      "x": 8,
      "y": 31,
      "z": 5,
      "name": "Rock_Crystal_Green_Block"
    },
    {
      "x": 8,
      "y": 32,
      "z": 5,
      "name": "Plant_Crop_Mushroom_Block_Green"
    },
    {
      "x": 8,
      "y": 33,
      "z": 5,
      "name": "Plant_Crop_Mushroom_Block_Green"
    },
    {
      "x": 8,
      "y": 34,
      "z": 5,
      "name": "Plant_Crop_Mushroom_Block_Green"
    },
    {
      "x": 8,
      "y": 35,
      "z": 5,
      "name": "Plant_Crop_Mushroom_Block_Green"
    },
    {
      "x": 8,
      "y": 6,
      "z": 6,
      "name": "Wood_Fir_Trunk_Full",
      "rotation": 4
    },
    {
      "x": 8,
      "y": 7,
      "z": 6,
      "name": "Wood_Fir_Trunk_Full",
      "rotation": 4
    },
    {
      "x": 8,
      "y": 31,
      "z": 6,
      "name": "Rock_Crystal_Green_Block"
    },
    {
      "x": 8,
      "y": 32,
      "z": 6,
      "name": "Plant_Crop_Mushroom_Block_Green"
    },
    {
      "x": 8,
      "y": 33,
      "z": 6,
      "name": "Plant_Crop_Mushroom_Block_Green"
    },
    {
      "x": 8,
      "y": 34,
      "z": 6,
      "name": "Plant_Crop_Mushroom_Block_Green"
    },
    {
      "x": 8,
      "y": 35,
      "z": 6,
      "name": "Plant_Crop_Mushroom_Block_Green"
    },
    {
      "x": 8,
      "y": 1,
      "z": 7,
      "name": "Wood_Fir_Trunk_Full"
    },
    {
      "x": 8,
      "y": 2,
      "z": 7,
      "name": "Wood_Fir_Trunk_Full"
    },
    {
      "x": 8,
      "y": 3,
      "z": 7,
      "name": "Wood_Fir_Trunk_Full",
      "rotation": 5
    },
    {
      "x": 8,
      "y": 5,
      "z": 7,
      "name": "Wood_Fir_Trunk_Full"
    },
    {
      "x": 8,
      "y": 6,
      "z": 7,
      "name": "Wood_Fir_Trunk_Full"
    },
    {
      "x": 8,
      "y": 7,
      "z": 7,
      "name": "Wood_Fir_Trunk_Full"
    },
    {
      "x": 8,
      "y": 8,
      "z": 7,
      "name": "Wood_Fir_Trunk_Full",
      "rotation": 4
    },
    {
      "x": 8,
      "y": 10,
      "z": 7,
      "name": "Wood_Fir_Trunk_Full",
      "rotation": 4
    },
    {
      "x": 8,
      "y": 11,
      "z": 7,
      "name": "Wood_Fir_Trunk_Full",
      "rotation": 4
    },
    {
      "x": 8,
      "y": 12,
      "z": 7,
      "name": "Wood_Fir_Trunk_Full"
    },
    {
      "x": 8,
      "y": 13,
      "z": 7,
      "name": "Wood_Fir_Trunk_Full"
    },
    {
      "x": 8,
      "y": 14,
      "z": 7,
      "name": "Wood_Fir_Trunk_Full"
    },
    {
      "x": 8,
      "y": 15,
      "z": 7,
      "name": "Wood_Fir_Trunk_Full"
    },
    {
      "x": 8,
      "y": 16,
      "z": 7,
      "name": "Wood_Fir_Trunk_Full"
    },
    {
      "x": 8,
      "y": 31,
      "z": 7,
      "name": "Rock_Crystal_Green_Block"
    },
    {
      "x": 8,
      "y": 32,
      "z": 7,
      "name": "Plant_Crop_Mushroom_Block_Green"
    },
    {
      "x": 8,
      "y": 33,
      "z": 7,
      "name": "Plant_Crop_Mushroom_Block_Green"
    },
    {
      "x": 8,
      "y": 34,
      "z": 7,
      "name": "Plant_Crop_Mushroom_Block_Green"
    },
    {
      "x": 8,
      "y": 35,
      "z": 7,
      "name": "Plant_Crop_Mushroom_Block_Green"
    },
    {
      "x": 8,
      "y": 8,
      "z": 8,
      "name": "Wood_Fir_Trunk_Full"
    },
    {
      "x": 8,
      "y": 9,
      "z": 8,
      "name": "Wood_Fir_Trunk_Full",
      "rotation": 4
    },
    {
      "x": 8,
      "y": 10,
      "z": 8,
      "name": "Wood_Fir_Trunk_Full",
      "rotation": 4
    },
    {
      "x": 8,
      "y": 11,
      "z": 8,
      "name": "Wood_Fir_Trunk_Full",
      "rotation": 4
    },
    {
      "x": 8,
      "y": 12,
      "z": 8,
      "name": "Wood_Fir_Trunk_Full"
    },
    {
      "x": 8,
      "y": 13,
      "z": 8,
      "name": "Wood_Fir_Trunk_Full"
    },
    {
      "x": 8,
      "y": 14,
      "z": 8,
      "name": "Wood_Fir_Trunk_Full"
    },
    {
      "x": 8,
      "y": 15,
      "z": 8,
      "name": "Wood_Fir_Trunk_Full"
    },
    {
      "x": 8,
      "y": 16,
      "z": 8,
      "name": "Wood_Fir_Trunk_Full"
    },
    {
      "x": 8,
      "y": 17,
      "z": 8,
      "name": "Wood_Fir_Trunk_Full"
    },
    {
      "x": 8,
      "y": 18,
      "z": 8,
      "name": "Wood_Fir_Trunk_Full"
    },
    {
      "x": 8,
      "y": 19,
      "z": 8,
      "name": "Wood_Fir_Trunk_Full"
    },
    {
      "x": 8,
      "y": 20,
      "z": 8,
      "name": "Wood_Fir_Trunk_Full"
    },
    {
      "x": 8,
      "y": 32,
      "z": 8,
      "name": "Rock_Crystal_Green_Block"
    },
    {
      "x": 8,
      "y": 33,
      "z": 8,
      "name": "Plant_Crop_Mushroom_Block_Green"
    },
    {
      "x": 8,
      "y": 34,
      "z": 8,
      "name": "Plant_Crop_Mushroom_Block_Green"
    },
    {
      "x": 8,
      "y": 35,
      "z": 8,
      "name": "Plant_Crop_Mushroom_Block_Green"
    },
    {
      "x": 8,
      "y": 7,
      "z": 9,
      "name": "Wood_Fir_Trunk_Full"
    },
    {
      "x": 8,
      "y": 8,
      "z": 9,
      "name": "Wood_Fir_Trunk_Full"
    },
    {
      "x": 8,
      "y": 9,
      "z": 9,
      "name": "Wood_Fir_Trunk_Full",
      "rotation": 5
    },
    {
      "x": 8,
      "y": 10,
      "z": 9,
      "name": "Wood_Fir_Trunk_Full",
      "rotation": 5
    },
    {
      "x": 8,
      "y": 11,
      "z": 9,
      "name": "Wood_Fir_Trunk_Full"
    },
    {
      "x": 8,
      "y": 12,
      "z": 9,
      "name": "Wood_Fir_Trunk_Full",
      "rotation": 5
    },
    {
      "x": 8,
      "y": 13,
      "z": 9,
      "name": "Wood_Fir_Trunk_Full",
      "rotation": 5
    },
    {
      "x": 8,
      "y": 14,
      "z": 9,
      "name": "Wood_Fir_Trunk_Full"
    },
    {
      "x": 8,
      "y": 15,
      "z": 9,
      "name": "Wood_Fir_Trunk_Full"
    },
    {
      "x": 8,
      "y": 16,
      "z": 9,
      "name": "Wood_Fir_Trunk_Full"
    },
    {
      "x": 8,
      "y": 17,
      "z": 9,
      "name": "Wood_Fir_Trunk_Full"
    },
    {
      "x": 8,
      "y": 18,
      "z": 9,
      "name": "Wood_Fir_Trunk_Full"
    },
    {
      "x": 8,
      "y": 19,
      "z": 9,
      "name": "Wood_Fir_Trunk_Full"
    },
    {
      "x": 8,
      "y": 20,
      "z": 9,
      "name": "Wood_Fir_Trunk_Full"
    },
    {
      "x": 8,
      "y": 21,
      "z": 9,
      "name": "Wood_Fir_Trunk_Full"
    },
    {
      "x": 8,
      "y": 22,
      "z": 9,
      "name": "Wood_Fir_Trunk_Full"
    },
    {
      "x": 8,
      "y": 23,
      "z": 9,
      "name": "Wood_Fir_Trunk_Full"
    },
    {
      "x": 8,
      "y": 24,
      "z": 9,
      "name": "Wood_Fir_Trunk_Full"
    },
    {
      "x": 8,
      "y": 25,
      "z": 9,
      "name": "Wood_Fir_Trunk_Full",
      "rotation": 5
    },
    {
      "x": 8,
      "y": 26,
      "z": 9,
      "name": "Wood_Fir_Trunk_Full"
    },
    {
      "x": 8,
      "y": 27,
      "z": 9,
      "name": "Wood_Fir_Trunk_Full"
    },
    {
      "x": 8,
      "y": 28,
      "z": 9,
      "name": "Wood_Fir_Trunk_Full"
    },
    {
      "x": 8,
      "y": 32,
      "z": 9,
      "name": "Rock_Crystal_Green_Block"
    },
    {
      "x": 8,
      "y": 33,
      "z": 9,
      "name": "Plant_Crop_Mushroom_Block_Green"
    },
    {
      "x": 8,
      "y": 34,
      "z": 9,
      "name": "Plant_Crop_Mushroom_Block_Green"
    },
    {
      "x": 8,
      "y": 35,
      "z": 9,
      "name": "Plant_Crop_Mushroom_Block_Green"
    },
    {
      "x": 8,
      "y": 6,
      "z": 10,
      "name": "Wood_Fir_Trunk_Full"
    },
    {
      "x": 8,
      "y": 7,
      "z": 10,
      "name": "Wood_Fir_Trunk_Full",
      "rotation": 4
    },
    {
      "x": 8,
      "y": 8,
      "z": 10,
      "name": "Wood_Fir_Trunk_Full",
      "rotation": 4
    },
    {
      "x": 8,
      "y": 15,
      "z": 10,
      "name": "Wood_Fir_Trunk_Full"
    },
    {
      "x": 8,
      "y": 16,
      "z": 10,
      "name": "Wood_Fir_Trunk_Full",
      "rotation": 4
    },
    {
      "x": 8,
      "y": 17,
      "z": 10,
      "name": "Wood_Fir_Trunk_Full"
    },
    {
      "x": 8,
      "y": 18,
      "z": 10,
      "name": "Wood_Fir_Trunk_Full"
    },
    {
      "x": 8,
      "y": 19,
      "z": 10,
      "name": "Wood_Fir_Trunk_Full"
    },
    {
      "x": 8,
      "y": 20,
      "z": 10,
      "name": "Wood_Fir_Trunk_Full"
    },
    {
      "x": 8,
      "y": 21,
      "z": 10,
      "name": "Wood_Fir_Trunk_Full"
    },
    {
      "x": 8,
      "y": 22,
      "z": 10,
      "name": "Wood_Fir_Trunk_Full"
    },
    {
      "x": 8,
      "y": 23,
      "z": 10,
      "name": "Wood_Fir_Trunk_Full"
    },
    {
      "x": 8,
      "y": 24,
      "z": 10,
      "name": "Wood_Fir_Trunk_Full"
    },
    {
      "x": 8,
      "y": 25,
      "z": 10,
      "name": "Wood_Fir_Trunk_Full"
    },
    {
      "x": 8,
      "y": 26,
      "z": 10,
      "name": "Wood_Fir_Trunk_Full"
    },
    {
      "x": 8,
      "y": 27,
      "z": 10,
      "name": "Wood_Fir_Trunk_Full"
    },
    {
      "x": 8,
      "y": 28,
      "z": 10,
      "name": "Wood_Fir_Trunk_Full"
    },
    {
      "x": 8,
      "y": 32,
      "z": 10,
      "name": "Rock_Crystal_Green_Block"
    },
    {
      "x": 8,
      "y": 33,
      "z": 10,
      "name": "Plant_Crop_Mushroom_Block_Green"
    },
    {
      "x": 8,
      "y": 34,
      "z": 10,
      "name": "Plant_Crop_Mushroom_Block_Green"
    },
    {
      "x": 8,
      "y": 35,
      "z": 10,
      "name": "Plant_Crop_Mushroom_Block_Green"
    },
    {
      "x": 8,
      "y": 4,
      "z": 11,
      "name": "Wood_Fir_Trunk_Full"
    },
    {
      "x": 8,
      "y": 5,
      "z": 11,
      "name": "Wood_Fir_Trunk_Full"
    },
    {
      "x": 8,
      "y": 6,
      "z": 11,
      "name": "Wood_Fir_Trunk_Full",
      "rotation": 4
    },
    {
      "x": 8,
      "y": 20,
      "z": 11,
      "name": "Wood_Fir_Trunk_Full"
    },
    {
      "x": 8,
      "y": 21,
      "z": 11,
      "name": "Wood_Fir_Trunk_Full",
      "rotation": 4
    },
    {
      "x": 8,
      "y": 22,
      "z": 11,
      "name": "Wood_Fir_Trunk_Full",
      "rotation": 4
    },
    {
      "x": 8,
      "y": 23,
      "z": 11,
      "name": "Wood_Fir_Trunk_Full"
    },
    {
      "x": 8,
      "y": 24,
      "z": 11,
      "name": "Wood_Fir_Trunk_Full"
    },
    {
      "x": 8,
      "y": 25,
      "z": 11,
      "name": "Wood_Fir_Trunk_Full"
    },
    {
      "x": 8,
      "y": 26,
      "z": 11,
      "name": "Wood_Fir_Trunk_Full",
      "rotation": 4
    },
    {
      "x": 8,
      "y": 31,
      "z": 11,
      "name": "Rock_Crystal_Green_Block"
    },
    {
      "x": 8,
      "y": 32,
      "z": 11,
      "name": "Plant_Crop_Mushroom_Block_Green"
    },
    {
      "x": 8,
      "y": 33,
      "z": 11,
      "name": "Plant_Crop_Mushroom_Block_Green"
    },
    {
      "x": 8,
      "y": 34,
      "z": 11,
      "name": "Plant_Crop_Mushroom_Block_Green"
    },
    {
      "x": 8,
      "y": 35,
      "z": 11,
      "name": "Plant_Crop_Mushroom_Block_Green"
    },
    {
      "x": 8,
      "y": 31,
      "z": 12,
      "name": "Rock_Crystal_Green_Block"
    },
    {
      "x": 8,
      "y": 32,
      "z": 12,
      "name": "Plant_Crop_Mushroom_Block_Green"
    },
    {
      "x": 8,
      "y": 33,
      "z": 12,
      "name": "Plant_Crop_Mushroom_Block_Green"
    },
    {
      "x": 8,
      "y": 34,
      "z": 12,
      "name": "Plant_Crop_Mushroom_Block_Green"
    },
    {
      "x": 8,
      "y": 31,
      "z": 13,
      "name": "Rock_Crystal_Green_Block"
    },
    {
      "x": 8,
      "y": 32,
      "z": 13,
      "name": "Plant_Crop_Mushroom_Block_Green"
    },
    {
      "x": 8,
      "y": 33,
      "z": 13,
      "name": "Plant_Crop_Mushroom_Block_Green"
    },
    {
      "x": 8,
      "y": 34,
      "z": 13,
      "name": "Plant_Crop_Mushroom_Block_Green"
    },
    {
      "x": 8,
      "y": 30,
      "z": 14,
      "name": "Plant_Crop_Mushroom_Block_Green"
    },
    {
      "x": 8,
      "y": 31,
      "z": 14,
      "name": "Plant_Crop_Mushroom_Block_Green"
    },
    {
      "x": 8,
      "y": 32,
      "z": 14,
      "name": "Plant_Crop_Mushroom_Block_Green"
    },
    {
      "x": 8,
      "y": 29,
      "z": 15,
      "name": "Plant_Crop_Mushroom_Block_Green"
    },
    {
      "x": 8,
      "y": 30,
      "z": 15,
      "name": "Plant_Crop_Mushroom_Block_Green"
    },
    {
      "x": 8,
      "y": 27,
      "z": 16,
      "name": "Plant_Crop_Mushroom_Block_Green"
    },
    {
      "x": 8,
      "y": 28,
      "z": 16,
      "name": "Plant_Crop_Mushroom_Block_Green"
    },
    {
      "x": 9,
      "y": 28,
      "z": 1,
      "name": "Plant_Crop_Mushroom_Block_Green"
    },
    {
      "x": 9,
      "y": 29,
      "z": 1,
      "name": "Plant_Crop_Mushroom_Block_Green"
    },
    {
      "x": 9,
      "y": 28,
      "z": 2,
      "name": "Plant_Crop_Mushroom_Block_Green"
    },
    {
      "x": 9,
      "y": 29,
      "z": 2,
      "name": "Plant_Crop_Mushroom_Block_Green"
    },
    {
      "x": 9,
      "y": 30,
      "z": 2,
      "name": "Plant_Crop_Mushroom_Block_Green"
    },
    {
      "x": 9,
      "y": 29,
      "z": 3,
      "name": "Plant_Crop_Mushroom_Block_Green"
    },
    {
      "x": 9,
      "y": 30,
      "z": 3,
      "name": "Plant_Crop_Mushroom_Block_Green"
    },
    {
      "x": 9,
      "y": 31,
      "z": 3,
      "name": "Plant_Crop_Mushroom_Block_Green"
    },
    {
      "x": 9,
      "y": 32,
      "z": 3,
      "name": "Plant_Crop_Mushroom_Block_Green"
    },
    {
      "x": 9,
      "y": 31,
      "z": 4,
      "name": "Plant_Crop_Mushroom_Block_Green"
    },
    {
      "x": 9,
      "y": 32,
      "z": 4,
      "name": "Plant_Crop_Mushroom_Block_Green"
    },
    {
      "x": 9,
      "y": 33,
      "z": 4,
      "name": "Plant_Crop_Mushroom_Block_Green"
    },
    {
      "x": 9,
      "y": 34,
      "z": 4,
      "name": "Plant_Crop_Mushroom_Block_Green"
    },
    {
      "x": 9,
      "y": 5,
      "z": 5,
      "name": "Wood_Fir_Trunk_Full"
    },
    {
      "x": 9,
      "y": 6,
      "z": 5,
      "name": "Wood_Fir_Trunk_Full",
      "rotation": 5
    },
    {
      "x": 9,
      "y": 32,
      "z": 5,
      "name": "Rock_Crystal_Green_Block"
    },
    {
      "x": 9,
      "y": 33,
      "z": 5,
      "name": "Plant_Crop_Mushroom_Block_Green"
    },
    {
      "x": 9,
      "y": 34,
      "z": 5,
      "name": "Plant_Crop_Mushroom_Block_Green"
    },
    {
      "x": 9,
      "y": 35,
      "z": 5,
      "name": "Plant_Crop_Mushroom_Block_Green"
    },
    {
      "x": 9,
      "y": 8,
      "z": 6,
      "name": "Wood_Fir_Trunk_Full"
    },
    {
      "x": 9,
      "y": 9,
      "z": 6,
      "name": "Wood_Fir_Trunk_Full",
      "rotation": 4
    },
    {
      "x": 9,
      "y": 10,
      "z": 6,
      "name": "Wood_Fir_Trunk_Full",
      "rotation": 4
    },
    {
      "x": 9,
      "y": 31,
      "z": 6,
      "name": "Rock_Crystal_Green_Block"
    },
    {
      "x": 9,
      "y": 32,
      "z": 6,
      "name": "Rock_Crystal_Green_Block"
    },
    {
      "x": 9,
      "y": 33,
      "z": 6,
      "name": "Plant_Crop_Mushroom_Block_Green"
    },
    {
      "x": 9,
      "y": 34,
      "z": 6,
      "name": "Plant_Crop_Mushroom_Block_Green"
    },
    {
      "x": 9,
      "y": 35,
      "z": 6,
      "name": "Plant_Crop_Mushroom_Block_Green"
    },
    {
      "x": 9,
      "y": 9,
      "z": 7,
      "name": "Wood_Fir_Trunk_Full"
    },
    {
      "x": 9,
      "y": 10,
      "z": 7,
      "name": "Wood_Fir_Trunk_Full",
      "rotation": 4
    },
    {
      "x": 9,
      "y": 11,
      "z": 7,
      "name": "Wood_Fir_Trunk_Full",
      "rotation": 4
    },
    {
      "x": 9,
      "y": 12,
      "z": 7,
      "name": "Wood_Fir_Trunk_Full"
    },
    {
      "x": 9,
      "y": 13,
      "z": 7,
      "name": "Wood_Fir_Trunk_Full"
    },
    {
      "x": 9,
      "y": 32,
      "z": 7,
      "name": "Rock_Crystal_Green_Block"
    },
    {
      "x": 9,
      "y": 33,
      "z": 7,
      "name": "Plant_Crop_Mushroom_Block_Green"
    },
    {
      "x": 9,
      "y": 34,
      "z": 7,
      "name": "Plant_Crop_Mushroom_Block_Green"
    },
    {
      "x": 9,
      "y": 35,
      "z": 7,
      "name": "Plant_Crop_Mushroom_Block_Green"
    },
    {
      "x": 9,
      "y": 9,
      "z": 8,
      "name": "Wood_Fir_Trunk_Full"
    },
    {
      "x": 9,
      "y": 10,
      "z": 8,
      "name": "Wood_Fir_Trunk_Full",
      "rotation": 4
    },
    {
      "x": 9,
      "y": 11,
      "z": 8,
      "name": "Wood_Fir_Trunk_Full"
    },
    {
      "x": 9,
      "y": 12,
      "z": 8,
      "name": "Wood_Fir_Trunk_Full",
      "rotation": 4
    },
    {
      "x": 9,
      "y": 13,
      "z": 8,
      "name": "Wood_Fir_Trunk_Full"
    },
    {
      "x": 9,
      "y": 14,
      "z": 8,
      "name": "Wood_Fir_Trunk_Full"
    },
    {
      "x": 9,
      "y": 15,
      "z": 8,
      "name": "Wood_Fir_Trunk_Full"
    },
    {
      "x": 9,
      "y": 16,
      "z": 8,
      "name": "Wood_Fir_Trunk_Full"
    },
    {
      "x": 9,
      "y": 17,
      "z": 8,
      "name": "Wood_Fir_Trunk_Full"
    },
    {
      "x": 9,
      "y": 32,
      "z": 8,
      "name": "Rock_Crystal_Green_Block"
    },
    {
      "x": 9,
      "y": 33,
      "z": 8,
      "name": "Plant_Crop_Mushroom_Block_Green"
    },
    {
      "x": 9,
      "y": 34,
      "z": 8,
      "name": "Plant_Crop_Mushroom_Block_Green"
    },
    {
      "x": 9,
      "y": 35,
      "z": 8,
      "name": "Plant_Crop_Mushroom_Block_Green"
    },
    {
      "x": 9,
      "y": 8,
      "z": 9,
      "name": "Wood_Fir_Trunk_Full"
    },
    {
      "x": 9,
      "y": 9,
      "z": 9,
      "name": "Wood_Fir_Trunk_Full",
      "rotation": 4
    },
    {
      "x": 9,
      "y": 10,
      "z": 9,
      "name": "Wood_Fir_Trunk_Full",
      "rotation": 4
    },
    {
      "x": 9,
      "y": 11,
      "z": 9,
      "name": "Wood_Fir_Trunk_Full"
    },
    {
      "x": 9,
      "y": 12,
      "z": 9,
      "name": "Wood_Fir_Trunk_Full"
    },
    {
      "x": 9,
      "y": 13,
      "z": 9,
      "name": "Wood_Fir_Trunk_Full"
    },
    {
      "x": 9,
      "y": 14,
      "z": 9,
      "name": "Wood_Fir_Trunk_Full"
    },
    {
      "x": 9,
      "y": 15,
      "z": 9,
      "name": "Wood_Fir_Trunk_Full"
    },
    {
      "x": 9,
      "y": 16,
      "z": 9,
      "name": "Wood_Fir_Trunk_Full"
    },
    {
      "x": 9,
      "y": 17,
      "z": 9,
      "name": "Wood_Fir_Trunk_Full"
    },
    {
      "x": 9,
      "y": 18,
      "z": 9,
      "name": "Wood_Fir_Trunk_Full"
    },
    {
      "x": 9,
      "y": 19,
      "z": 9,
      "name": "Wood_Fir_Trunk_Full"
    },
    {
      "x": 9,
      "y": 25,
      "z": 9,
      "name": "Wood_Fir_Trunk_Full"
    },
    {
      "x": 9,
      "y": 26,
      "z": 9,
      "name": "Wood_Fir_Trunk_Full"
    },
    {
      "x": 9,
      "y": 27,
      "z": 9,
      "name": "Wood_Fir_Trunk_Full"
    },
    {
      "x": 9,
      "y": 28,
      "z": 9,
      "name": "Wood_Fir_Trunk_Full"
    },
    {
      "x": 9,
      "y": 29,
      "z": 9,
      "name": "Wood_Fir_Trunk_Full"
    },
    {
      "x": 9,
      "y": 30,
      "z": 9,
      "name": "Wood_Fir_Trunk_Full"
    },
    {
      "x": 9,
      "y": 32,
      "z": 9,
      "name": "Rock_Crystal_Green_Block"
    },
    {
      "x": 9,
      "y": 33,
      "z": 9,
      "name": "Plant_Crop_Mushroom_Block_Green"
    },
    {
      "x": 9,
      "y": 34,
      "z": 9,
      "name": "Plant_Crop_Mushroom_Block_Green"
    },
    {
      "x": 9,
      "y": 35,
      "z": 9,
      "name": "Plant_Crop_Mushroom_Block_Green"
    },
    {
      "x": 9,
      "y": 9,
      "z": 10,
      "name": "Wood_Fir_Trunk_Full",
      "rotation": 4
    },
    {
      "x": 9,
      "y": 14,
      "z": 10,
      "name": "Wood_Fir_Trunk_Full"
    },
    {
      "x": 9,
      "y": 15,
      "z": 10,
      "name": "Wood_Fir_Trunk_Full"
    },
    {
      "x": 9,
      "y": 16,
      "z": 10,
      "name": "Wood_Fir_Trunk_Full"
    },
    {
      "x": 9,
      "y": 17,
      "z": 10,
      "name": "Wood_Fir_Trunk_Full"
    },
    {
      "x": 9,
      "y": 24,
      "z": 10,
      "name": "Wood_Fir_Trunk_Full"
    },
    {
      "x": 9,
      "y": 25,
      "z": 10,
      "name": "Wood_Fir_Trunk_Full",
      "rotation": 5
    },
    {
      "x": 9,
      "y": 26,
      "z": 10,
      "name": "Wood_Fir_Trunk_Full"
    },
    {
      "x": 9,
      "y": 27,
      "z": 10,
      "name": "Wood_Fir_Trunk_Full"
    },
    {
      "x": 9,
      "y": 28,
      "z": 10,
      "name": "Wood_Fir_Trunk_Full"
    },
    {
      "x": 9,
      "y": 29,
      "z": 10,
      "name": "Wood_Fir_Trunk_Full"
    },
    {
      "x": 9,
      "y": 30,
      "z": 10,
      "name": "Wood_Fir_Trunk_Full"
    },
    {
      "x": 9,
      "y": 32,
      "z": 10,
      "name": "Rock_Crystal_Green_Block"
    },
    {
      "x": 9,
      "y": 33,
      "z": 10,
      "name": "Plant_Crop_Mushroom_Block_Green"
    },
    {
      "x": 9,
      "y": 34,
      "z": 10,
      "name": "Plant_Crop_Mushroom_Block_Green"
    },
    {
      "x": 9,
      "y": 35,
      "z": 10,
      "name": "Plant_Crop_Mushroom_Block_Green"
    },
    {
      "x": 9,
      "y": 25,
      "z": 11,
      "name": "Wood_Fir_Trunk_Full"
    },
    {
      "x": 9,
      "y": 26,
      "z": 11,
      "name": "Wood_Fir_Trunk_Full"
    },
    {
      "x": 9,
      "y": 27,
      "z": 11,
      "name": "Wood_Fir_Trunk_Full"
    },
    {
      "x": 9,
      "y": 28,
      "z": 11,
      "name": "Wood_Fir_Trunk_Full"
    },
    {
      "x": 9,
      "y": 31,
      "z": 11,
      "name": "Rock_Crystal_Green_Block"
    },
    {
      "x": 9,
      "y": 32,
      "z": 11,
      "name": "Plant_Crop_Mushroom_Block_Green"
    },
    {
      "x": 9,
      "y": 33,
      "z": 11,
      "name": "Plant_Crop_Mushroom_Block_Green"
    },
    {
      "x": 9,
      "y": 34,
      "z": 11,
      "name": "Plant_Crop_Mushroom_Block_Green"
    },
    {
      "x": 9,
      "y": 35,
      "z": 11,
      "name": "Plant_Crop_Mushroom_Block_Green"
    },
    {
      "x": 9,
      "y": 31,
      "z": 12,
      "name": "Rock_Crystal_Green_Block"
    },
    {
      "x": 9,
      "y": 32,
      "z": 12,
      "name": "Plant_Crop_Mushroom_Block_Green"
    },
    {
      "x": 9,
      "y": 33,
      "z": 12,
      "name": "Plant_Crop_Mushroom_Block_Green"
    },
    {
      "x": 9,
      "y": 34,
      "z": 12,
      "name": "Plant_Crop_Mushroom_Block_Green"
    },
    {
      "x": 9,
      "y": 31,
      "z": 13,
      "name": "Rock_Crystal_Green_Block"
    },
    {
      "x": 9,
      "y": 32,
      "z": 13,
      "name": "Plant_Crop_Mushroom_Block_Green"
    },
    {
      "x": 9,
      "y": 33,
      "z": 13,
      "name": "Plant_Crop_Mushroom_Block_Green"
    },
    {
      "x": 9,
      "y": 34,
      "z": 13,
      "name": "Plant_Crop_Mushroom_Block_Green"
    },
    {
      "x": 9,
      "y": 30,
      "z": 14,
      "name": "Plant_Crop_Mushroom_Block_Green"
    },
    {
      "x": 9,
      "y": 31,
      "z": 14,
      "name": "Plant_Crop_Mushroom_Block_Green"
    },
    {
      "x": 9,
      "y": 32,
      "z": 14,
      "name": "Plant_Crop_Mushroom_Block_Green"
    },
    {
      "x": 9,
      "y": 33,
      "z": 14,
      "name": "Plant_Crop_Mushroom_Block_Green"
    },
    {
      "x": 9,
      "y": 29,
      "z": 15,
      "name": "Plant_Crop_Mushroom_Block_Green"
    },
    {
      "x": 9,
      "y": 30,
      "z": 15,
      "name": "Plant_Crop_Mushroom_Block_Green"
    },
    {
      "x": 9,
      "y": 31,
      "z": 15,
      "name": "Plant_Crop_Mushroom_Block_Green"
    },
    {
      "x": 9,
      "y": 27,
      "z": 16,
      "name": "Plant_Crop_Mushroom_Block_Green"
    },
    {
      "x": 9,
      "y": 28,
      "z": 16,
      "name": "Plant_Crop_Mushroom_Block_Green"
    },
    {
      "x": 9,
      "y": 29,
      "z": 16,
      "name": "Plant_Crop_Mushroom_Block_Green"
    },
    {
      "x": 9,
      "y": 27,
      "z": 17,
      "name": "Plant_Crop_Mushroom_Block_Green"
    },
    {
      "x": 10,
      "y": 29,
      "z": 1,
      "name": "Plant_Crop_Mushroom_Block_Green"
    },
    {
      "x": 10,
      "y": 30,
      "z": 2,
      "name": "Plant_Crop_Mushroom_Block_Green"
    },
    {
      "x": 10,
      "y": 31,
      "z": 3,
      "name": "Plant_Crop_Mushroom_Block_Green"
    },
    {
      "x": 10,
      "y": 32,
      "z": 3,
      "name": "Plant_Crop_Mushroom_Block_Green"
    },
    {
      "x": 10,
      "y": 31,
      "z": 4,
      "name": "Plant_Crop_Mushroom_Block_Green"
    },
    {
      "x": 10,
      "y": 32,
      "z": 4,
      "name": "Plant_Crop_Mushroom_Block_Green"
    },
    {
      "x": 10,
      "y": 33,
      "z": 4,
      "name": "Plant_Crop_Mushroom_Block_Green"
    },
    {
      "x": 10,
      "y": 34,
      "z": 4,
      "name": "Plant_Crop_Mushroom_Block_Green"
    },
    {
      "x": 10,
      "y": 6,
      "z": 5,
      "name": "Wood_Fir_Trunk_Full"
    },
    {
      "x": 10,
      "y": 7,
      "z": 5,
      "name": "Wood_Fir_Trunk_Full",
      "rotation": 4
    },
    {
      "x": 10,
      "y": 8,
      "z": 5,
      "name": "Wood_Fir_Trunk_Full"
    },
    {
      "x": 10,
      "y": 9,
      "z": 5,
      "name": "Wood_Fir_Trunk_Full"
    },
    {
      "x": 10,
      "y": 10,
      "z": 5,
      "name": "Wood_Fir_Trunk_Full"
    },
    {
      "x": 10,
      "y": 11,
      "z": 5,
      "name": "Wood_Fir_Trunk_Full",
      "rotation": 4
    },
    {
      "x": 10,
      "y": 12,
      "z": 5,
      "name": "Wood_Fir_Trunk_Full"
    },
    {
      "x": 10,
      "y": 13,
      "z": 5,
      "name": "Wood_Fir_Trunk_Full"
    },
    {
      "x": 10,
      "y": 14,
      "z": 5,
      "name": "Wood_Fir_Trunk_Full",
      "rotation": 5
    },
    {
      "x": 10,
      "y": 32,
      "z": 5,
      "name": "Rock_Crystal_Green_Block"
    },
    {
      "x": 10,
      "y": 33,
      "z": 5,
      "name": "Plant_Crop_Mushroom_Block_Green"
    },
    {
      "x": 10,
      "y": 34,
      "z": 5,
      "name": "Plant_Crop_Mushroom_Block_Green"
    },
    {
      "x": 10,
      "y": 35,
      "z": 5,
      "name": "Plant_Crop_Mushroom_Block_Green"
    },
    {
      "x": 10,
      "y": 2,
      "z": 6,
      "name": "Wood_Fir_Trunk_Full",
      "rotation": 4
    },
    {
      "x": 10,
      "y": 7,
      "z": 6,
      "name": "Wood_Fir_Trunk_Full"
    },
    {
      "x": 10,
      "y": 8,
      "z": 6,
      "name": "Wood_Fir_Trunk_Full",
      "rotation": 4
    },
    {
      "x": 10,
      "y": 9,
      "z": 6,
      "name": "Wood_Fir_Trunk_Full"
    },
    {
      "x": 10,
      "y": 10,
      "z": 6,
      "name": "Wood_Fir_Trunk_Full"
    },
    {
      "x": 10,
      "y": 11,
      "z": 6,
      "name": "Wood_Fir_Trunk_Full",
      "rotation": 4
    },
    {
      "x": 10,
      "y": 12,
      "z": 6,
      "name": "Wood_Fir_Trunk_Full",
      "rotation": 4
    },
    {
      "x": 10,
      "y": 32,
      "z": 6,
      "name": "Rock_Crystal_Green_Block"
    },
    {
      "x": 10,
      "y": 33,
      "z": 6,
      "name": "Plant_Crop_Mushroom_Block_Green"
    },
    {
      "x": 10,
      "y": 34,
      "z": 6,
      "name": "Plant_Crop_Mushroom_Block_Green"
    },
    {
      "x": 10,
      "y": 35,
      "z": 6,
      "name": "Plant_Crop_Mushroom_Block_Green"
    },
    {
      "x": 10,
      "y": 2,
      "z": 7,
      "name": "Wood_Fir_Trunk_Full"
    },
    {
      "x": 10,
      "y": 3,
      "z": 7,
      "name": "Wood_Fir_Trunk_Full",
      "rotation": 5
    },
    {
      "x": 10,
      "y": 8,
      "z": 7,
      "name": "Wood_Fir_Trunk_Full"
    },
    {
      "x": 10,
      "y": 9,
      "z": 7,
      "name": "Wood_Fir_Trunk_Full"
    },
    {
      "x": 10,
      "y": 10,
      "z": 7,
      "name": "Wood_Fir_Trunk_Full",
      "rotation": 4
    },
    {
      "x": 10,
      "y": 11,
      "z": 7,
      "name": "Wood_Fir_Trunk_Full"
    },
    {
      "x": 10,
      "y": 12,
      "z": 7,
      "name": "Wood_Fir_Trunk_Full"
    },
    {
      "x": 10,
      "y": 32,
      "z": 7,
      "name": "Rock_Crystal_Green_Block"
    },
    {
      "x": 10,
      "y": 33,
      "z": 7,
      "name": "Plant_Crop_Mushroom_Block_Green"
    },
    {
      "x": 10,
      "y": 34,
      "z": 7,
      "name": "Plant_Crop_Mushroom_Block_Green"
    },
    {
      "x": 10,
      "y": 35,
      "z": 7,
      "name": "Plant_Crop_Mushroom_Block_Green"
    },
    {
      "x": 10,
      "y": 9,
      "z": 8,
      "name": "Wood_Fir_Trunk_Full"
    },
    {
      "x": 10,
      "y": 10,
      "z": 8,
      "name": "Wood_Fir_Trunk_Full"
    },
    {
      "x": 10,
      "y": 11,
      "z": 8,
      "name": "Wood_Fir_Trunk_Full"
    },
    {
      "x": 10,
      "y": 12,
      "z": 8,
      "name": "Wood_Fir_Trunk_Full"
    },
    {
      "x": 10,
      "y": 13,
      "z": 8,
      "name": "Wood_Fir_Trunk_Full"
    },
    {
      "x": 10,
      "y": 14,
      "z": 8,
      "name": "Wood_Fir_Trunk_Full"
    },
    {
      "x": 10,
      "y": 32,
      "z": 8,
      "name": "Rock_Crystal_Green_Block"
    },
    {
      "x": 10,
      "y": 33,
      "z": 8,
      "name": "Plant_Crop_Mushroom_Block_Green"
    },
    {
      "x": 10,
      "y": 34,
      "z": 8,
      "name": "Plant_Crop_Mushroom_Block_Green"
    },
    {
      "x": 10,
      "y": 35,
      "z": 8,
      "name": "Plant_Crop_Mushroom_Block_Green"
    },
    {
      "x": 10,
      "y": 7,
      "z": 9,
      "name": "Wood_Fir_Trunk_Full"
    },
    {
      "x": 10,
      "y": 8,
      "z": 9,
      "name": "Wood_Fir_Trunk_Full",
      "rotation": 5
    },
    {
      "x": 10,
      "y": 9,
      "z": 9,
      "name": "Wood_Fir_Trunk_Full"
    },
    {
      "x": 10,
      "y": 10,
      "z": 9,
      "name": "Wood_Fir_Trunk_Full"
    },
    {
      "x": 10,
      "y": 11,
      "z": 9,
      "name": "Wood_Fir_Trunk_Full"
    },
    {
      "x": 10,
      "y": 12,
      "z": 9,
      "name": "Wood_Fir_Trunk_Full"
    },
    {
      "x": 10,
      "y": 13,
      "z": 9,
      "name": "Wood_Fir_Trunk_Full"
    },
    {
      "x": 10,
      "y": 14,
      "z": 9,
      "name": "Wood_Fir_Trunk_Full"
    },
    {
      "x": 10,
      "y": 15,
      "z": 9,
      "name": "Wood_Fir_Trunk_Full"
    },
    {
      "x": 10,
      "y": 28,
      "z": 9,
      "name": "Wood_Fir_Trunk_Full"
    },
    {
      "x": 10,
      "y": 29,
      "z": 9,
      "name": "Wood_Fir_Trunk_Full",
      "rotation": 5
    },
    {
      "x": 10,
      "y": 30,
      "z": 9,
      "name": "Wood_Fir_Trunk_Full"
    },
    {
      "x": 10,
      "y": 31,
      "z": 9,
      "name": "Wood_Fir_Trunk_Full"
    },
    {
      "x": 10,
      "y": 32,
      "z": 9,
      "name": "Rock_Crystal_Green_Block"
    },
    {
      "x": 10,
      "y": 33,
      "z": 9,
      "name": "Plant_Crop_Mushroom_Block_Green"
    },
    {
      "x": 10,
      "y": 34,
      "z": 9,
      "name": "Plant_Crop_Mushroom_Block_Green"
    },
    {
      "x": 10,
      "y": 35,
      "z": 9,
      "name": "Plant_Crop_Mushroom_Block_Green"
    },
    {
      "x": 10,
      "y": 7,
      "z": 10,
      "name": "Wood_Fir_Trunk_Full",
      "rotation": 4
    },
    {
      "x": 10,
      "y": 8,
      "z": 10,
      "name": "Wood_Fir_Trunk_Full",
      "rotation": 4
    },
    {
      "x": 10,
      "y": 28,
      "z": 10,
      "name": "Wood_Fir_Trunk_Full"
    },
    {
      "x": 10,
      "y": 29,
      "z": 10,
      "name": "Wood_Fir_Trunk_Full"
    },
    {
      "x": 10,
      "y": 30,
      "z": 10,
      "name": "Wood_Fir_Trunk_Full"
    },
    {
      "x": 10,
      "y": 31,
      "z": 10,
      "name": "Wood_Fir_Trunk_Full"
    },
    {
      "x": 10,
      "y": 32,
      "z": 10,
      "name": "Rock_Crystal_Green_Block"
    },
    {
      "x": 10,
      "y": 33,
      "z": 10,
      "name": "Plant_Crop_Mushroom_Block_Green"
    },
    {
      "x": 10,
      "y": 34,
      "z": 10,
      "name": "Plant_Crop_Mushroom_Block_Green"
    },
    {
      "x": 10,
      "y": 35,
      "z": 10,
      "name": "Plant_Crop_Mushroom_Block_Green"
    },
    {
      "x": 10,
      "y": 31,
      "z": 11,
      "name": "Rock_Crystal_Green_Block"
    },
    {
      "x": 10,
      "y": 32,
      "z": 11,
      "name": "Plant_Crop_Mushroom_Block_Green"
    },
    {
      "x": 10,
      "y": 33,
      "z": 11,
      "name": "Plant_Crop_Mushroom_Block_Green"
    },
    {
      "x": 10,
      "y": 34,
      "z": 11,
      "name": "Plant_Crop_Mushroom_Block_Green"
    },
    {
      "x": 10,
      "y": 31,
      "z": 12,
      "name": "Rock_Crystal_Green_Block"
    },
    {
      "x": 10,
      "y": 32,
      "z": 12,
      "name": "Plant_Crop_Mushroom_Block_Green"
    },
    {
      "x": 10,
      "y": 33,
      "z": 12,
      "name": "Plant_Crop_Mushroom_Block_Green"
    },
    {
      "x": 10,
      "y": 34,
      "z": 12,
      "name": "Plant_Crop_Mushroom_Block_Green"
    },
    {
      "x": 10,
      "y": 31,
      "z": 13,
      "name": "Rock_Crystal_Green_Block"
    },
    {
      "x": 10,
      "y": 32,
      "z": 13,
      "name": "Plant_Crop_Mushroom_Block_Green"
    },
    {
      "x": 10,
      "y": 33,
      "z": 13,
      "name": "Plant_Crop_Mushroom_Block_Green"
    },
    {
      "x": 10,
      "y": 34,
      "z": 13,
      "name": "Plant_Crop_Mushroom_Block_Green"
    },
    {
      "x": 10,
      "y": 30,
      "z": 14,
      "name": "Rock_Crystal_Green_Block"
    },
    {
      "x": 10,
      "y": 31,
      "z": 14,
      "name": "Plant_Crop_Mushroom_Block_Green"
    },
    {
      "x": 10,
      "y": 32,
      "z": 14,
      "name": "Plant_Crop_Mushroom_Block_Green"
    },
    {
      "x": 10,
      "y": 33,
      "z": 14,
      "name": "Plant_Crop_Mushroom_Block_Green"
    },
    {
      "x": 10,
      "y": 28,
      "z": 15,
      "name": "Plant_Crop_Mushroom_Block_Green"
    },
    {
      "x": 10,
      "y": 29,
      "z": 15,
      "name": "Plant_Crop_Mushroom_Block_Green"
    },
    {
      "x": 10,
      "y": 30,
      "z": 15,
      "name": "Plant_Crop_Mushroom_Block_Green"
    },
    {
      "x": 10,
      "y": 31,
      "z": 15,
      "name": "Plant_Crop_Mushroom_Block_Green"
    },
    {
      "x": 10,
      "y": 27,
      "z": 16,
      "name": "Plant_Crop_Mushroom_Block_Green"
    },
    {
      "x": 10,
      "y": 28,
      "z": 16,
      "name": "Plant_Crop_Mushroom_Block_Green"
    },
    {
      "x": 10,
      "y": 29,
      "z": 16,
      "name": "Plant_Crop_Mushroom_Block_Green"
    },
    {
      "x": 10,
      "y": 27,
      "z": 17,
      "name": "Plant_Crop_Mushroom_Block_Green"
    },
    {
      "x": 10,
      "y": 28,
      "z": 17,
      "name": "Plant_Crop_Mushroom_Block_Green"
    },
    {
      "x": 11,
      "y": 30,
      "z": 2,
      "name": "Plant_Crop_Mushroom_Block_Green"
    },
    {
      "x": 11,
      "y": 31,
      "z": 2,
      "name": "Plant_Crop_Mushroom_Block_Green"
    },
    {
      "x": 11,
      "y": 31,
      "z": 3,
      "name": "Plant_Crop_Mushroom_Block_Green"
    },
    {
      "x": 11,
      "y": 32,
      "z": 3,
      "name": "Plant_Crop_Mushroom_Block_Green"
    },
    {
      "x": 11,
      "y": 31,
      "z": 4,
      "name": "Plant_Crop_Mushroom_Block_Green"
    },
    {
      "x": 11,
      "y": 32,
      "z": 4,
      "name": "Plant_Crop_Mushroom_Block_Green"
    },
    {
      "x": 11,
      "y": 33,
      "z": 4,
      "name": "Plant_Crop_Mushroom_Block_Green"
    },
    {
      "x": 11,
      "y": 34,
      "z": 4,
      "name": "Plant_Crop_Mushroom_Block_Green"
    },
    {
      "x": 11,
      "y": 9,
      "z": 5,
      "name": "Wood_Fir_Trunk_Full"
    },
    {
      "x": 11,
      "y": 10,
      "z": 5,
      "name": "Wood_Fir_Trunk_Full"
    },
    {
      "x": 11,
      "y": 11,
      "z": 5,
      "name": "Wood_Fir_Trunk_Full"
    },
    {
      "x": 11,
      "y": 12,
      "z": 5,
      "name": "Wood_Fir_Trunk_Full",
      "rotation": 4
    },
    {
      "x": 11,
      "y": 13,
      "z": 5,
      "name": "Wood_Fir_Trunk_Full"
    },
    {
      "x": 11,
      "y": 14,
      "z": 5,
      "name": "Wood_Fir_Trunk_Full"
    },
    {
      "x": 11,
      "y": 15,
      "z": 5,
      "name": "Wood_Fir_Trunk_Full"
    },
    {
      "x": 11,
      "y": 32,
      "z": 5,
      "name": "Rock_Crystal_Green_Block"
    },
    {
      "x": 11,
      "y": 33,
      "z": 5,
      "name": "Plant_Crop_Mushroom_Block_Green"
    },
    {
      "x": 11,
      "y": 34,
      "z": 5,
      "name": "Plant_Crop_Mushroom_Block_Green"
    },
    {
      "x": 11,
      "y": 4,
      "z": 6,
      "name": "Wood_Fir_Trunk_Full",
      "rotation": 4
    },
    {
      "x": 11,
      "y": 6,
      "z": 6,
      "name": "Wood_Fir_Trunk_Full"
    },
    {
      "x": 11,
      "y": 7,
      "z": 6,
      "name": "Wood_Fir_Trunk_Full"
    },
    {
      "x": 11,
      "y": 8,
      "z": 6,
      "name": "Wood_Fir_Trunk_Full",
      "rotation": 5
    },
    {
      "x": 11,
      "y": 9,
      "z": 6,
      "name": "Wood_Fir_Trunk_Full",
      "rotation": 5
    },
    {
      "x": 11,
      "y": 10,
      "z": 6,
      "name": "Wood_Fir_Trunk_Full",
      "rotation": 5
    },
    {
      "x": 11,
      "y": 11,
      "z": 6,
      "name": "Wood_Fir_Trunk_Full"
    },
    {
      "x": 11,
      "y": 12,
      "z": 6,
      "name": "Wood_Fir_Trunk_Full"
    },
    {
      "x": 11,
      "y": 13,
      "z": 6,
      "name": "Wood_Fir_Trunk_Full"
    },
    {
      "x": 11,
      "y": 32,
      "z": 6,
      "name": "Rock_Crystal_Green_Block"
    },
    {
      "x": 11,
      "y": 33,
      "z": 6,
      "name": "Plant_Crop_Mushroom_Block_Green"
    },
    {
      "x": 11,
      "y": 34,
      "z": 6,
      "name": "Plant_Crop_Mushroom_Block_Green"
    },
    {
      "x": 11,
      "y": 35,
      "z": 6,
      "name": "Plant_Crop_Mushroom_Block_Green"
    },
    {
      "x": 11,
      "y": 3,
      "z": 7,
      "name": "Wood_Fir_Trunk_Full"
    },
    {
      "x": 11,
      "y": 4,
      "z": 7,
      "name": "Wood_Fir_Trunk_Full"
    },
    {
      "x": 11,
      "y": 5,
      "z": 7,
      "name": "Wood_Fir_Trunk_Full",
      "rotation": 4
    },
    {
      "x": 11,
      "y": 8,
      "z": 7,
      "name": "Wood_Fir_Trunk_Full",
      "rotation": 5
    },
    {
      "x": 11,
      "y": 10,
      "z": 7,
      "name": "Wood_Fir_Trunk_Full",
      "rotation": 5
    },
    {
      "x": 11,
      "y": 32,
      "z": 7,
      "name": "Rock_Crystal_Green_Block"
    },
    {
      "x": 11,
      "y": 33,
      "z": 7,
      "name": "Plant_Crop_Mushroom_Block_Green"
    },
    {
      "x": 11,
      "y": 34,
      "z": 7,
      "name": "Plant_Crop_Mushroom_Block_Green"
    },
    {
      "x": 11,
      "y": 35,
      "z": 7,
      "name": "Plant_Crop_Mushroom_Block_Green"
    },
    {
      "x": 11,
      "y": 5,
      "z": 8,
      "name": "Wood_Fir_Trunk_Full",
      "rotation": 5
    },
    {
      "x": 11,
      "y": 7,
      "z": 8,
      "name": "Wood_Fir_Trunk_Full"
    },
    {
      "x": 11,
      "y": 8,
      "z": 8,
      "name": "Wood_Fir_Trunk_Full",
      "rotation": 4
    },
    {
      "x": 11,
      "y": 9,
      "z": 8,
      "name": "Wood_Fir_Trunk_Full",
      "rotation": 5
    },
    {
      "x": 11,
      "y": 32,
      "z": 8,
      "name": "Rock_Crystal_Green_Block"
    },
    {
      "x": 11,
      "y": 33,
      "z": 8,
      "name": "Plant_Crop_Mushroom_Block_Green"
    },
    {
      "x": 11,
      "y": 34,
      "z": 8,
      "name": "Plant_Crop_Mushroom_Block_Green"
    },
    {
      "x": 11,
      "y": 35,
      "z": 8,
      "name": "Plant_Crop_Mushroom_Block_Green"
    },
    {
      "x": 11,
      "y": 7,
      "z": 9,
      "name": "Wood_Fir_Trunk_Full",
      "rotation": 5
    },
    {
      "x": 11,
      "y": 30,
      "z": 9,
      "name": "Wood_Fir_Trunk_Full"
    },
    {
      "x": 11,
      "y": 31,
      "z": 9,
      "name": "Wood_Fir_Trunk_Full"
    },
    {
      "x": 11,
      "y": 32,
      "z": 9,
      "name": "Rock_Crystal_Green_Block"
    },
    {
      "x": 11,
      "y": 33,
      "z": 9,
      "name": "Plant_Crop_Mushroom_Block_Green"
    },
    {
      "x": 11,
      "y": 34,
      "z": 9,
      "name": "Plant_Crop_Mushroom_Block_Green"
    },
    {
      "x": 11,
      "y": 35,
      "z": 9,
      "name": "Plant_Crop_Mushroom_Block_Green"
    },
    {
      "x": 11,
      "y": 6,
      "z": 10,
      "name": "Wood_Fir_Trunk_Full"
    },
    {
      "x": 11,
      "y": 7,
      "z": 10,
      "name": "Wood_Fir_Trunk_Full",
      "rotation": 5
    },
    {
      "x": 11,
      "y": 29,
      "z": 10,
      "name": "Wood_Fir_Trunk_Full",
      "rotation": 4
    },
    {
      "x": 11,
      "y": 30,
      "z": 10,
      "name": "Wood_Fir_Trunk_Full"
    },
    {
      "x": 11,
      "y": 31,
      "z": 10,
      "name": "Wood_Fir_Trunk_Full"
    },
    {
      "x": 11,
      "y": 32,
      "z": 10,
      "name": "Rock_Crystal_Green_Block"
    },
    {
      "x": 11,
      "y": 33,
      "z": 10,
      "name": "Plant_Crop_Mushroom_Block_Green"
    },
    {
      "x": 11,
      "y": 34,
      "z": 10,
      "name": "Plant_Crop_Mushroom_Block_Green"
    },
    {
      "x": 11,
      "y": 31,
      "z": 11,
      "name": "Rock_Crystal_Green_Block"
    },
    {
      "x": 11,
      "y": 32,
      "z": 11,
      "name": "Plant_Crop_Mushroom_Block_Green"
    },
    {
      "x": 11,
      "y": 33,
      "z": 11,
      "name": "Plant_Crop_Mushroom_Block_Green"
    },
    {
      "x": 11,
      "y": 34,
      "z": 11,
      "name": "Plant_Crop_Mushroom_Block_Green"
    },
    {
      "x": 11,
      "y": 31,
      "z": 12,
      "name": "Rock_Crystal_Green_Block"
    },
    {
      "x": 11,
      "y": 32,
      "z": 12,
      "name": "Plant_Crop_Mushroom_Block_Green"
    },
    {
      "x": 11,
      "y": 33,
      "z": 12,
      "name": "Plant_Crop_Mushroom_Block_Green"
    },
    {
      "x": 11,
      "y": 34,
      "z": 12,
      "name": "Plant_Crop_Mushroom_Block_Green"
    },
    {
      "x": 11,
      "y": 31,
      "z": 13,
      "name": "Rock_Crystal_Green_Block"
    },
    {
      "x": 11,
      "y": 32,
      "z": 13,
      "name": "Plant_Crop_Mushroom_Block_Green"
    },
    {
      "x": 11,
      "y": 33,
      "z": 13,
      "name": "Plant_Crop_Mushroom_Block_Green"
    },
    {
      "x": 11,
      "y": 30,
      "z": 14,
      "name": "Rock_Crystal_Green_Block"
    },
    {
      "x": 11,
      "y": 31,
      "z": 14,
      "name": "Plant_Crop_Mushroom_Block_Green"
    },
    {
      "x": 11,
      "y": 32,
      "z": 14,
      "name": "Plant_Crop_Mushroom_Block_Green"
    },
    {
      "x": 11,
      "y": 33,
      "z": 14,
      "name": "Plant_Crop_Mushroom_Block_Green"
    },
    {
      "x": 11,
      "y": 28,
      "z": 15,
      "name": "Plant_Crop_Mushroom_Block_Green"
    },
    {
      "x": 11,
      "y": 29,
      "z": 15,
      "name": "Plant_Crop_Mushroom_Block_Green"
    },
    {
      "x": 11,
      "y": 30,
      "z": 15,
      "name": "Plant_Crop_Mushroom_Block_Green"
    },
    {
      "x": 11,
      "y": 31,
      "z": 15,
      "name": "Plant_Crop_Mushroom_Block_Green"
    },
    {
      "x": 11,
      "y": 28,
      "z": 16,
      "name": "Plant_Crop_Mushroom_Block_Green"
    },
    {
      "x": 11,
      "y": 28,
      "z": 17,
      "name": "Plant_Crop_Mushroom_Block_Green"
    },
    {
      "x": 12,
      "y": 29,
      "z": 2,
      "name": "Plant_Crop_Mushroom_Block_Green"
    },
    {
      "x": 12,
      "y": 30,
      "z": 2,
      "name": "Plant_Crop_Mushroom_Block_Green"
    },
    {
      "x": 12,
      "y": 30,
      "z": 3,
      "name": "Plant_Crop_Mushroom_Block_Green"
    },
    {
      "x": 12,
      "y": 31,
      "z": 3,
      "name": "Plant_Crop_Mushroom_Block_Green"
    },
    {
      "x": 12,
      "y": 32,
      "z": 3,
      "name": "Plant_Crop_Mushroom_Block_Green"
    },
    {
      "x": 12,
      "y": 16,
      "z": 4,
      "name": "Wood_Fir_Trunk_Full",
      "rotation": 4
    },
    {
      "x": 12,
      "y": 17,
      "z": 4,
      "name": "Wood_Fir_Trunk_Full"
    },
    {
      "x": 12,
      "y": 18,
      "z": 4,
      "name": "Wood_Fir_Trunk_Full"
    },
    {
      "x": 12,
      "y": 19,
      "z": 4,
      "name": "Wood_Fir_Trunk_Full"
    },
    {
      "x": 12,
      "y": 31,
      "z": 4,
      "name": "Plant_Crop_Mushroom_Block_Green"
    },
    {
      "x": 12,
      "y": 32,
      "z": 4,
      "name": "Plant_Crop_Mushroom_Block_Green"
    },
    {
      "x": 12,
      "y": 33,
      "z": 4,
      "name": "Plant_Crop_Mushroom_Block_Green"
    },
    {
      "x": 12,
      "y": 14,
      "z": 5,
      "name": "Wood_Fir_Trunk_Full"
    },
    {
      "x": 12,
      "y": 15,
      "z": 5,
      "name": "Wood_Fir_Trunk_Full"
    },
    {
      "x": 12,
      "y": 16,
      "z": 5,
      "name": "Wood_Fir_Trunk_Full"
    },
    {
      "x": 12,
      "y": 17,
      "z": 5,
      "name": "Wood_Fir_Trunk_Full"
    },
    {
      "x": 12,
      "y": 32,
      "z": 5,
      "name": "Rock_Crystal_Green_Block"
    },
    {
      "x": 12,
      "y": 33,
      "z": 5,
      "name": "Plant_Crop_Mushroom_Block_Green"
    },
    {
      "x": 12,
      "y": 34,
      "z": 5,
      "name": "Plant_Crop_Mushroom_Block_Green"
    },
    {
      "x": 12,
      "y": 6,
      "z": 6,
      "name": "Wood_Fir_Trunk_Full",
      "rotation": 5
    },
    {
      "x": 12,
      "y": 32,
      "z": 6,
      "name": "Rock_Crystal_Green_Block"
    },
    {
      "x": 12,
      "y": 33,
      "z": 6,
      "name": "Plant_Crop_Mushroom_Block_Green"
    },
    {
      "x": 12,
      "y": 34,
      "z": 6,
      "name": "Plant_Crop_Mushroom_Block_Green"
    },
    {
      "x": 12,
      "y": 32,
      "z": 7,
      "name": "Rock_Crystal_Green_Block"
    },
    {
      "x": 12,
      "y": 33,
      "z": 7,
      "name": "Plant_Crop_Mushroom_Block_Green"
    },
    {
      "x": 12,
      "y": 34,
      "z": 7,
      "name": "Plant_Crop_Mushroom_Block_Green"
    },
    {
      "x": 12,
      "y": 5,
      "z": 8,
      "name": "Wood_Fir_Trunk_Full"
    },
    {
      "x": 12,
      "y": 6,
      "z": 8,
      "name": "Wood_Fir_Trunk_Full"
    },
    {
      "x": 12,
      "y": 7,
      "z": 8,
      "name": "Wood_Fir_Trunk_Full",
      "rotation": 5
    },
    {
      "x": 12,
      "y": 32,
      "z": 8,
      "name": "Rock_Crystal_Green_Block"
    },
    {
      "x": 12,
      "y": 33,
      "z": 8,
      "name": "Plant_Crop_Mushroom_Block_Green"
    },
    {
      "x": 12,
      "y": 34,
      "z": 8,
      "name": "Plant_Crop_Mushroom_Block_Green"
    },
    {
      "x": 12,
      "y": 4,
      "z": 9,
      "name": "Wood_Fir_Trunk_Full"
    },
    {
      "x": 12,
      "y": 5,
      "z": 9,
      "name": "Wood_Fir_Trunk_Full",
      "rotation": 4
    },
    {
      "x": 12,
      "y": 31,
      "z": 9,
      "name": "Rock_Crystal_Green_Block"
    },
    {
      "x": 12,
      "y": 32,
      "z": 9,
      "name": "Rock_Crystal_Green_Block"
    },
    {
      "x": 12,
      "y": 33,
      "z": 9,
      "name": "Plant_Crop_Mushroom_Block_Green"
    },
    {
      "x": 12,
      "y": 34,
      "z": 9,
      "name": "Plant_Crop_Mushroom_Block_Green"
    },
    {
      "x": 12,
      "y": 7,
      "z": 10,
      "name": "Wood_Fir_Trunk_Full",
      "rotation": 5
    },
    {
      "x": 12,
      "y": 31,
      "z": 10,
      "name": "Rock_Crystal_Green_Block"
    },
    {
      "x": 12,
      "y": 32,
      "z": 10,
      "name": "Rock_Crystal_Green_Block"
    },
    {
      "x": 12,
      "y": 33,
      "z": 10,
      "name": "Plant_Crop_Mushroom_Block_Green"
    },
    {
      "x": 12,
      "y": 34,
      "z": 10,
      "name": "Plant_Crop_Mushroom_Block_Green"
    },
    {
      "x": 12,
      "y": 31,
      "z": 11,
      "name": "Rock_Crystal_Green_Block"
    },
    {
      "x": 12,
      "y": 32,
      "z": 11,
      "name": "Plant_Crop_Mushroom_Block_Green"
    },
    {
      "x": 12,
      "y": 33,
      "z": 11,
      "name": "Plant_Crop_Mushroom_Block_Green"
    },
    {
      "x": 12,
      "y": 34,
      "z": 11,
      "name": "Plant_Crop_Mushroom_Block_Green"
    },
    {
      "x": 12,
      "y": 31,
      "z": 12,
      "name": "Rock_Crystal_Green_Block"
    },
    {
      "x": 12,
      "y": 32,
      "z": 12,
      "name": "Plant_Crop_Mushroom_Block_Green"
    },
    {
      "x": 12,
      "y": 33,
      "z": 12,
      "name": "Plant_Crop_Mushroom_Block_Green"
    },
    {
      "x": 12,
      "y": 30,
      "z": 13,
      "name": "Rock_Crystal_Green_Block"
    },
    {
      "x": 12,
      "y": 31,
      "z": 13,
      "name": "Plant_Crop_Mushroom_Block_Green"
    },
    {
      "x": 12,
      "y": 32,
      "z": 13,
      "name": "Plant_Crop_Mushroom_Block_Green"
    },
    {
      "x": 12,
      "y": 33,
      "z": 13,
      "name": "Plant_Crop_Mushroom_Block_Green"
    },
    {
      "x": 12,
      "y": 30,
      "z": 14,
      "name": "Rock_Crystal_Green_Block"
    },
    {
      "x": 12,
      "y": 31,
      "z": 14,
      "name": "Plant_Crop_Mushroom_Block_Green"
    },
    {
      "x": 12,
      "y": 32,
      "z": 14,
      "name": "Plant_Crop_Mushroom_Block_Green"
    },
    {
      "x": 12,
      "y": 29,
      "z": 15,
      "name": "Plant_Crop_Mushroom_Block_Green"
    },
    {
      "x": 12,
      "y": 30,
      "z": 15,
      "name": "Plant_Crop_Mushroom_Block_Green"
    },
    {
      "x": 12,
      "y": 31,
      "z": 15,
      "name": "Plant_Crop_Mushroom_Block_Green"
    },
    {
      "x": 13,
      "y": 28,
      "z": 2,
      "name": "Plant_Crop_Mushroom_Block_Green"
    },
    {
      "x": 13,
      "y": 28,
      "z": 3,
      "name": "Plant_Crop_Mushroom_Block_Green"
    },
    {
      "x": 13,
      "y": 29,
      "z": 3,
      "name": "Plant_Crop_Mushroom_Block_Green"
    },
    {
      "x": 13,
      "y": 30,
      "z": 3,
      "name": "Plant_Crop_Mushroom_Block_Green"
    },
    {
      "x": 13,
      "y": 31,
      "z": 3,
      "name": "Plant_Crop_Mushroom_Block_Green"
    },
    {
      "x": 13,
      "y": 31,
      "z": 4,
      "name": "Plant_Crop_Mushroom_Block_Green"
    },
    {
      "x": 13,
      "y": 32,
      "z": 4,
      "name": "Plant_Crop_Mushroom_Block_Green"
    },
    {
      "x": 13,
      "y": 33,
      "z": 4,
      "name": "Plant_Crop_Mushroom_Block_Green"
    },
    {
      "x": 13,
      "y": 32,
      "z": 5,
      "name": "Plant_Crop_Mushroom_Block_Green"
    },
    {
      "x": 13,
      "y": 33,
      "z": 5,
      "name": "Plant_Crop_Mushroom_Block_Green"
    },
    {
      "x": 13,
      "y": 34,
      "z": 5,
      "name": "Plant_Crop_Mushroom_Block_Green"
    },
    {
      "x": 13,
      "y": 32,
      "z": 6,
      "name": "Rock_Crystal_Green_Block"
    },
    {
      "x": 13,
      "y": 33,
      "z": 6,
      "name": "Plant_Crop_Mushroom_Block_Green"
    },
    {
      "x": 13,
      "y": 34,
      "z": 6,
      "name": "Plant_Crop_Mushroom_Block_Green"
    },
    {
      "x": 13,
      "y": 32,
      "z": 7,
      "name": "Rock_Crystal_Green_Block"
    },
    {
      "x": 13,
      "y": 33,
      "z": 7,
      "name": "Plant_Crop_Mushroom_Block_Green"
    },
    {
      "x": 13,
      "y": 34,
      "z": 7,
      "name": "Plant_Crop_Mushroom_Block_Green"
    },
    {
      "x": 13,
      "y": 6,
      "z": 8,
      "name": "Wood_Fir_Trunk_Full",
      "rotation": 5
    },
    {
      "x": 13,
      "y": 31,
      "z": 8,
      "name": "Rock_Crystal_Green_Block"
    },
    {
      "x": 13,
      "y": 32,
      "z": 8,
      "name": "Plant_Crop_Mushroom_Block_Green"
    },
    {
      "x": 13,
      "y": 33,
      "z": 8,
      "name": "Plant_Crop_Mushroom_Block_Green"
    },
    {
      "x": 13,
      "y": 34,
      "z": 8,
      "name": "Plant_Crop_Mushroom_Block_Green"
    },
    {
      "x": 13,
      "y": 31,
      "z": 9,
      "name": "Rock_Crystal_Green_Block"
    },
    {
      "x": 13,
      "y": 32,
      "z": 9,
      "name": "Plant_Crop_Mushroom_Block_Green"
    },
    {
      "x": 13,
      "y": 33,
      "z": 9,
      "name": "Plant_Crop_Mushroom_Block_Green"
    },
    {
      "x": 13,
      "y": 34,
      "z": 9,
      "name": "Plant_Crop_Mushroom_Block_Green"
    },
    {
      "x": 13,
      "y": 31,
      "z": 10,
      "name": "Rock_Crystal_Green_Block"
    },
    {
      "x": 13,
      "y": 32,
      "z": 10,
      "name": "Plant_Crop_Mushroom_Block_Green"
    },
    {
      "x": 13,
      "y": 33,
      "z": 10,
      "name": "Plant_Crop_Mushroom_Block_Green"
    },
    {
      "x": 13,
      "y": 31,
      "z": 11,
      "name": "Rock_Crystal_Green_Block"
    },
    {
      "x": 13,
      "y": 32,
      "z": 11,
      "name": "Plant_Crop_Mushroom_Block_Green"
    },
    {
      "x": 13,
      "y": 33,
      "z": 11,
      "name": "Plant_Crop_Mushroom_Block_Green"
    },
    {
      "x": 13,
      "y": 30,
      "z": 12,
      "name": "Rock_Crystal_Green_Block"
    },
    {
      "x": 13,
      "y": 31,
      "z": 12,
      "name": "Plant_Crop_Mushroom_Block_Green"
    },
    {
      "x": 13,
      "y": 32,
      "z": 12,
      "name": "Plant_Crop_Mushroom_Block_Green"
    },
    {
      "x": 13,
      "y": 33,
      "z": 12,
      "name": "Plant_Crop_Mushroom_Block_Green"
    },
    {
      "x": 13,
      "y": 30,
      "z": 13,
      "name": "Rock_Crystal_Green_Block"
    },
    {
      "x": 13,
      "y": 31,
      "z": 13,
      "name": "Plant_Crop_Mushroom_Block_Green"
    },
    {
      "x": 13,
      "y": 32,
      "z": 13,
      "name": "Plant_Crop_Mushroom_Block_Green"
    },
    {
      "x": 13,
      "y": 33,
      "z": 13,
      "name": "Plant_Crop_Mushroom_Block_Green"
    },
    {
      "x": 13,
      "y": 30,
      "z": 14,
      "name": "Rock_Crystal_Green_Block"
    },
    {
      "x": 13,
      "y": 31,
      "z": 14,
      "name": "Plant_Crop_Mushroom_Block_Green"
    },
    {
      "x": 13,
      "y": 32,
      "z": 14,
      "name": "Plant_Crop_Mushroom_Block_Green"
    },
    {
      "x": 13,
      "y": 29,
      "z": 15,
      "name": "Plant_Crop_Mushroom_Block_Green"
    },
    {
      "x": 13,
      "y": 30,
      "z": 15,
      "name": "Plant_Crop_Mushroom_Block_Green"
    },
    {
      "x": 14,
      "y": 28,
      "z": 2,
      "name": "Plant_Crop_Mushroom_Block_Green"
    },
    {
      "x": 14,
      "y": 28,
      "z": 3,
      "name": "Plant_Crop_Mushroom_Block_Green"
    },
    {
      "x": 14,
      "y": 29,
      "z": 3,
      "name": "Plant_Crop_Mushroom_Block_Green"
    },
    {
      "x": 14,
      "y": 30,
      "z": 3,
      "name": "Plant_Crop_Mushroom_Block_Green"
    },
    {
      "x": 14,
      "y": 29,
      "z": 4,
      "name": "Plant_Crop_Mushroom_Block_Green"
    },
    {
      "x": 14,
      "y": 30,
      "z": 4,
      "name": "Plant_Crop_Mushroom_Block_Green"
    },
    {
      "x": 14,
      "y": 31,
      "z": 4,
      "name": "Plant_Crop_Mushroom_Block_Green"
    },
    {
      "x": 14,
      "y": 32,
      "z": 4,
      "name": "Plant_Crop_Mushroom_Block_Green"
    },
    {
      "x": 14,
      "y": 30,
      "z": 5,
      "name": "Plant_Crop_Mushroom_Block_Green"
    },
    {
      "x": 14,
      "y": 31,
      "z": 5,
      "name": "Plant_Crop_Mushroom_Block_Green"
    },
    {
      "x": 14,
      "y": 32,
      "z": 5,
      "name": "Plant_Crop_Mushroom_Block_Green"
    },
    {
      "x": 14,
      "y": 30,
      "z": 6,
      "name": "Plant_Crop_Mushroom_Block_Green"
    },
    {
      "x": 14,
      "y": 31,
      "z": 6,
      "name": "Plant_Crop_Mushroom_Block_Green"
    },
    {
      "x": 14,
      "y": 32,
      "z": 6,
      "name": "Plant_Crop_Mushroom_Block_Green"
    },
    {
      "x": 14,
      "y": 33,
      "z": 6,
      "name": "Plant_Crop_Mushroom_Block_Green"
    },
    {
      "x": 14,
      "y": 31,
      "z": 7,
      "name": "Rock_Crystal_Green_Block"
    },
    {
      "x": 14,
      "y": 32,
      "z": 7,
      "name": "Plant_Crop_Mushroom_Block_Green"
    },
    {
      "x": 14,
      "y": 33,
      "z": 7,
      "name": "Plant_Crop_Mushroom_Block_Green"
    },
    {
      "x": 14,
      "y": 34,
      "z": 7,
      "name": "Plant_Crop_Mushroom_Block_Green"
    },
    {
      "x": 14,
      "y": 31,
      "z": 8,
      "name": "Rock_Crystal_Green_Block"
    },
    {
      "x": 14,
      "y": 32,
      "z": 8,
      "name": "Plant_Crop_Mushroom_Block_Green"
    },
    {
      "x": 14,
      "y": 33,
      "z": 8,
      "name": "Plant_Crop_Mushroom_Block_Green"
    },
    {
      "x": 14,
      "y": 34,
      "z": 8,
      "name": "Plant_Crop_Mushroom_Block_Green"
    },
    {
      "x": 14,
      "y": 30,
      "z": 9,
      "name": "Rock_Crystal_Green_Block"
    },
    {
      "x": 14,
      "y": 31,
      "z": 9,
      "name": "Rock_Crystal_Green_Block"
    },
    {
      "x": 14,
      "y": 32,
      "z": 9,
      "name": "Plant_Crop_Mushroom_Block_Green"
    },
    {
      "x": 14,
      "y": 33,
      "z": 9,
      "name": "Plant_Crop_Mushroom_Block_Green"
    },
    {
      "x": 14,
      "y": 30,
      "z": 10,
      "name": "Rock_Crystal_Green_Block"
    },
    {
      "x": 14,
      "y": 31,
      "z": 10,
      "name": "Plant_Crop_Mushroom_Block_Green"
    },
    {
      "x": 14,
      "y": 32,
      "z": 10,
      "name": "Plant_Crop_Mushroom_Block_Green"
    },
    {
      "x": 14,
      "y": 33,
      "z": 10,
      "name": "Plant_Crop_Mushroom_Block_Green"
    },
    {
      "x": 14,
      "y": 30,
      "z": 11,
      "name": "Rock_Crystal_Green_Block"
    },
    {
      "x": 14,
      "y": 31,
      "z": 11,
      "name": "Plant_Crop_Mushroom_Block_Green"
    },
    {
      "x": 14,
      "y": 32,
      "z": 11,
      "name": "Plant_Crop_Mushroom_Block_Green"
    },
    {
      "x": 14,
      "y": 33,
      "z": 11,
      "name": "Plant_Crop_Mushroom_Block_Green"
    },
    {
      "x": 14,
      "y": 30,
      "z": 12,
      "name": "Rock_Crystal_Green_Block"
    },
    {
      "x": 14,
      "y": 31,
      "z": 12,
      "name": "Plant_Crop_Mushroom_Block_Green"
    },
    {
      "x": 14,
      "y": 32,
      "z": 12,
      "name": "Plant_Crop_Mushroom_Block_Green"
    },
    {
      "x": 14,
      "y": 33,
      "z": 12,
      "name": "Plant_Crop_Mushroom_Block_Green"
    },
    {
      "x": 14,
      "y": 30,
      "z": 13,
      "name": "Rock_Crystal_Green_Block"
    },
    {
      "x": 14,
      "y": 31,
      "z": 13,
      "name": "Plant_Crop_Mushroom_Block_Green"
    },
    {
      "x": 14,
      "y": 32,
      "z": 13,
      "name": "Plant_Crop_Mushroom_Block_Green"
    },
    {
      "x": 14,
      "y": 29,
      "z": 14,
      "name": "Plant_Crop_Mushroom_Block_Green"
    },
    {
      "x": 14,
      "y": 30,
      "z": 14,
      "name": "Plant_Crop_Mushroom_Block_Green"
    },
    {
      "x": 14,
      "y": 31,
      "z": 14,
      "name": "Plant_Crop_Mushroom_Block_Green"
    },
    {
      "x": 14,
      "y": 28,
      "z": 15,
      "name": "Plant_Crop_Mushroom_Block_Green"
    },
    {
      "x": 14,
      "y": 29,
      "z": 15,
      "name": "Plant_Crop_Mushroom_Block_Green"
    },
    {
      "x": 15,
      "y": 29,
      "z": 3,
      "name": "Plant_Crop_Mushroom_Block_Green"
    },
    {
      "x": 15,
      "y": 29,
      "z": 4,
      "name": "Plant_Crop_Mushroom_Block_Green"
    },
    {
      "x": 15,
      "y": 30,
      "z": 4,
      "name": "Plant_Crop_Mushroom_Block_Green"
    },
    {
      "x": 15,
      "y": 30,
      "z": 5,
      "name": "Plant_Crop_Mushroom_Block_Green"
    },
    {
      "x": 15,
      "y": 31,
      "z": 5,
      "name": "Plant_Crop_Mushroom_Block_Green"
    },
    {
      "x": 15,
      "y": 30,
      "z": 6,
      "name": "Plant_Crop_Mushroom_Block_Green"
    },
    {
      "x": 15,
      "y": 31,
      "z": 6,
      "name": "Plant_Crop_Mushroom_Block_Green"
    },
    {
      "x": 15,
      "y": 32,
      "z": 6,
      "name": "Plant_Crop_Mushroom_Block_Green"
    },
    {
      "x": 15,
      "y": 30,
      "z": 7,
      "name": "Plant_Crop_Mushroom_Block_Green"
    },
    {
      "x": 15,
      "y": 31,
      "z": 7,
      "name": "Plant_Crop_Mushroom_Block_Green"
    },
    {
      "x": 15,
      "y": 32,
      "z": 7,
      "name": "Plant_Crop_Mushroom_Block_Green"
    },
    {
      "x": 15,
      "y": 30,
      "z": 8,
      "name": "Plant_Crop_Mushroom_Block_Green"
    },
    {
      "x": 15,
      "y": 31,
      "z": 8,
      "name": "Plant_Crop_Mushroom_Block_Green"
    },
    {
      "x": 15,
      "y": 32,
      "z": 8,
      "name": "Plant_Crop_Mushroom_Block_Green"
    },
    {
      "x": 15,
      "y": 33,
      "z": 8,
      "name": "Plant_Crop_Mushroom_Block_Green"
    },
    {
      "x": 15,
      "y": 30,
      "z": 9,
      "name": "Plant_Crop_Mushroom_Block_Green"
    },
    {
      "x": 15,
      "y": 31,
      "z": 9,
      "name": "Plant_Crop_Mushroom_Block_Green"
    },
    {
      "x": 15,
      "y": 32,
      "z": 9,
      "name": "Plant_Crop_Mushroom_Block_Green"
    },
    {
      "x": 15,
      "y": 33,
      "z": 9,
      "name": "Plant_Crop_Mushroom_Block_Green"
    },
    {
      "x": 15,
      "y": 30,
      "z": 10,
      "name": "Plant_Crop_Mushroom_Block_Green"
    },
    {
      "x": 15,
      "y": 31,
      "z": 10,
      "name": "Plant_Crop_Mushroom_Block_Green"
    },
    {
      "x": 15,
      "y": 32,
      "z": 10,
      "name": "Plant_Crop_Mushroom_Block_Green"
    },
    {
      "x": 15,
      "y": 33,
      "z": 10,
      "name": "Plant_Crop_Mushroom_Block_Green"
    },
    {
      "x": 15,
      "y": 30,
      "z": 11,
      "name": "Plant_Crop_Mushroom_Block_Green"
    },
    {
      "x": 15,
      "y": 31,
      "z": 11,
      "name": "Plant_Crop_Mushroom_Block_Green"
    },
    {
      "x": 15,
      "y": 32,
      "z": 11,
      "name": "Plant_Crop_Mushroom_Block_Green"
    },
    {
      "x": 15,
      "y": 29,
      "z": 12,
      "name": "Plant_Crop_Mushroom_Block_Green"
    },
    {
      "x": 15,
      "y": 30,
      "z": 12,
      "name": "Plant_Crop_Mushroom_Block_Green"
    },
    {
      "x": 15,
      "y": 31,
      "z": 12,
      "name": "Plant_Crop_Mushroom_Block_Green"
    },
    {
      "x": 15,
      "y": 32,
      "z": 12,
      "name": "Plant_Crop_Mushroom_Block_Green"
    },
    {
      "x": 15,
      "y": 28,
      "z": 13,
      "name": "Plant_Crop_Mushroom_Block_Green"
    },
    {
      "x": 15,
      "y": 29,
      "z": 13,
      "name": "Plant_Crop_Mushroom_Block_Green"
    },
    {
      "x": 15,
      "y": 30,
      "z": 13,
      "name": "Plant_Crop_Mushroom_Block_Green"
    },
    {
      "x": 15,
      "y": 31,
      "z": 13,
      "name": "Plant_Crop_Mushroom_Block_Green"
    },
    {
      "x": 15,
      "y": 27,
      "z": 14,
      "name": "Plant_Crop_Mushroom_Block_Green"
    },
    {
      "x": 15,
      "y": 28,
      "z": 14,
      "name": "Plant_Crop_Mushroom_Block_Green"
    },
    {
      "x": 15,
      "y": 29,
      "z": 14,
      "name": "Plant_Crop_Mushroom_Block_Green"
    },
    {
      "x": 15,
      "y": 30,
      "z": 14,
      "name": "Plant_Crop_Mushroom_Block_Green"
    },
    {
      "x": 15,
      "y": 28,
      "z": 15,
      "name": "Plant_Crop_Mushroom_Block_Green"
    },
    {
      "x": 16,
      "y": 30,
      "z": 6,
      "name": "Plant_Crop_Mushroom_Block_Green"
    },
    {
      "x": 16,
      "y": 29,
      "z": 7,
      "name": "Plant_Crop_Mushroom_Block_Green"
    },
    {
      "x": 16,
      "y": 30,
      "z": 7,
      "name": "Plant_Crop_Mushroom_Block_Green"
    },
    {
      "x": 16,
      "y": 31,
      "z": 7,
      "name": "Plant_Crop_Mushroom_Block_Green"
    },
    {
      "x": 16,
      "y": 28,
      "z": 8,
      "name": "Plant_Crop_Mushroom_Block_Green"
    },
    {
      "x": 16,
      "y": 29,
      "z": 8,
      "name": "Plant_Crop_Mushroom_Block_Green"
    },
    {
      "x": 16,
      "y": 30,
      "z": 8,
      "name": "Plant_Crop_Mushroom_Block_Green"
    },
    {
      "x": 16,
      "y": 31,
      "z": 8,
      "name": "Plant_Crop_Mushroom_Block_Green"
    },
    {
      "x": 16,
      "y": 32,
      "z": 8,
      "name": "Plant_Crop_Mushroom_Block_Green"
    },
    {
      "x": 16,
      "y": 29,
      "z": 9,
      "name": "Plant_Crop_Mushroom_Block_Green"
    },
    {
      "x": 16,
      "y": 30,
      "z": 9,
      "name": "Plant_Crop_Mushroom_Block_Green"
    },
    {
      "x": 16,
      "y": 31,
      "z": 9,
      "name": "Plant_Crop_Mushroom_Block_Green"
    },
    {
      "x": 16,
      "y": 32,
      "z": 9,
      "name": "Plant_Crop_Mushroom_Block_Green"
    },
    {
      "x": 16,
      "y": 29,
      "z": 10,
      "name": "Plant_Crop_Mushroom_Block_Green"
    },
    {
      "x": 16,
      "y": 30,
      "z": 10,
      "name": "Plant_Crop_Mushroom_Block_Green"
    },
    {
      "x": 16,
      "y": 31,
      "z": 10,
      "name": "Plant_Crop_Mushroom_Block_Green"
    },
    {
      "x": 16,
      "y": 32,
      "z": 10,
      "name": "Plant_Crop_Mushroom_Block_Green"
    },
    {
      "x": 16,
      "y": 29,
      "z": 11,
      "name": "Plant_Crop_Mushroom_Block_Green"
    },
    {
      "x": 16,
      "y": 30,
      "z": 11,
      "name": "Plant_Crop_Mushroom_Block_Green"
    },
    {
      "x": 16,
      "y": 31,
      "z": 11,
      "name": "Plant_Crop_Mushroom_Block_Green"
    },
    {
      "x": 16,
      "y": 27,
      "z": 12,
      "name": "Plant_Crop_Mushroom_Block_Green"
    },
    {
      "x": 16,
      "y": 28,
      "z": 12,
      "name": "Plant_Crop_Mushroom_Block_Green"
    },
    {
      "x": 16,
      "y": 29,
      "z": 12,
      "name": "Plant_Crop_Mushroom_Block_Green"
    },
    {
      "x": 16,
      "y": 30,
      "z": 12,
      "name": "Plant_Crop_Mushroom_Block_Green"
    },
    {
      "x": 16,
      "y": 27,
      "z": 13,
      "name": "Plant_Crop_Mushroom_Block_Green"
    },
    {
      "x": 16,
      "y": 28,
      "z": 13,
      "name": "Plant_Crop_Mushroom_Block_Green"
    },
    {
      "x": 16,
      "y": 29,
      "z": 13,
      "name": "Plant_Crop_Mushroom_Block_Green"
    },
    {
      "x": 16,
      "y": 27,
      "z": 14,
      "name": "Plant_Crop_Mushroom_Block_Green"
    },
    {
      "x": 17,
      "y": 28,
      "z": 8,
      "name": "Plant_Crop_Mushroom_Block_Green"
    },
    {
      "x": 17,
      "y": 28,
      "z": 9,
      "name": "Plant_Crop_Mushroom_Block_Green"
    },
    {
      "x": 17,
      "y": 29,
      "z": 9,
      "name": "Plant_Crop_Mushroom_Block_Green"
    },
    {
      "x": 17,
      "y": 30,
      "z": 9,
      "name": "Plant_Crop_Mushroom_Block_Green"
    },
    {
      "x": 17,
      "y": 28,
      "z": 10,
      "name": "Plant_Crop_Mushroom_Block_Green"
    },
    {
      "x": 17,
      "y": 29,
      "z": 10,
      "name": "Plant_Crop_Mushroom_Block_Green"
    }
  ]
}