{
  "version": 8,
  "blockIdVersion": 8,
  "anchorX": 0,
  "anchorY": 9,
  "anchorZ": 1,
  "blocks": [
    {
      "x": -5,
      "y": 14,
      "z": -3,
      "name": "Wood_Deadwood_Roof_Flat"
    },
    {
      "x": -5,
      "y": 13,
      "z": -2,
      "name": "Wood_Hardwood_Planks_Half",
      "rotation": 8
    },
    {
      "x": -5,
      "y": 14,
      "z": -2,
      "name": "Wood_Deadwood_Roof",
      "rotation": 2
    },
    {
      "x": -5,
      "y": 11,
      "z": -1,
      "name": "Plant_Moss_Wall_Green",
      "rotation": 3
    },
    {
      "x": -5,
      "y": 14,
      "z": -1,
      "name": "Wood_Hardwood_Stairs",
      "rotation": 10
    },
    {
      "x": -5,
      "y": 15,
      "z": -1,
      "name": "Wood_Deadwood_Roof",
      "rotation": 2
    },
    {
      "x": -5,
      "y": 12,
      "z": 0,
      "name": "Plant_Moss_Wall_Green",
      "rotation": 3
    },
    {
      "x": -4,
      "y": 14,
      "z": -3,
      "name": "Wood_Deadwood_Roof_Flat"
    },
    {
      "x": -4,
      "y": 0,
      "z": -2,
      "name": "Wood_Softwood_Beam"
    },
    {
      "x": -4,
      "y": 1,
      "z": -2,
      "name": "Wood_Softwood_Beam"
    },
    {
      "x": -4,
      "y": 2,
      "z": -2,
      "name": "Wood_Softwood_Beam"
    },
    {
      "x": -4,
      "y": 3,
      "z": -2,
      "name": "Wood_Softwood_Beam"
    },
    {
      "x": -4,
      "y": 4,
      "z": -2,
      "name": "Wood_Softwood_Beam"
    },
    {
      "x": -4,
      "y": 5,
      "z": -2,
      "name": "Wood_Softwood_Beam"
    },
    {
      "x": -4,
      "y": 6,
      "z": -2,
      "name": "Wood_Softwood_Beam"
    },
    {
      "x": -4,
      "y": 7,
      "z": -2,
      "name": "Wood_Softwood_Beam"
    },
    {
      "x": -4,
      "y": 8,
      "z": -2,
      "name": "Wood_Softwood_Beam"
    },
    {
      "x": -4,
      "y": 9,
      "z": -2,
      "name": "Wood_Softwood_Beam"
    },
    {
      "x": -4,
      "y": 10,
      "z": -2,
      "name": "Wood_Softwood_Beam"
    },
    {
      "x": -4,
      "y": 11,
      "z": -2,
      "name": "Wood_Softwood_Planks"
    },
    {
      "x": -4,
      "y": 12,
      "z": -2,
      "name": "Wood_Hardwood_Planks"
    },
    {
      "x": -4,
      "y": 13,
      "z": -2,
      "name": "Wood_Hardwood_Planks"
    },
    {
      "x": -4,
      "y": 14,
      "z": -2,
      "name": "Wood_Deadwood_Roof",
      "rotation": 2
    },
    {
      "x": -4,
      "y": 10,
      "z": -1,
      "name": "Plant_Moss_Cave_Green",
      "rotation": 8
    },
    {
      "x": -4,
      "y": 11,
      "z": -1,
      "name": "Wood_Softwood_Planks"
    },
    {
      "x": -4,
      "y": 12,
      "z": -1,
      "name": "Wood_Hardwood_Planks"
    },
    {
      "x": -4,
      "y": 13,
      "z": -1,
      "name": "Wood_Hardwood_Planks"
    },
    {
      "x": -4,
      "y": 14,
      "z": -1,
      "name": "Wood_Hardwood_Planks"
    },
    {
      "x": -4,
      "y": 15,
      "z": -1,
      "name": "Wood_Deadwood_Roof",
      "rotation": 2
    },
    {
      "x": -4,
      "y": 11,
      "z": 0,
      "name": "Wood_Softwood_Planks"
    },
    {
      "x": -4,
      "y": 12,
      "z": 0,
      "name": "Wood_Hardwood_Planks"
    },
    {
      "x": -4,
      "y": 13,
      "z": 0,
      "name": "Plant_Moss_Rug_Green"
    },
    {
      "x": -4,
      "y": 14,
      "z": 0,
      "name": "Empty"
    },
    {
      "x": -4,
      "y": 15,
      "z": 0,
      "name": "Plant_Vine_Hanging"
    },
    {
      "x": -4,
      "y": 16,
      "z": 0,
      "name": "Wood_Deadwood_Roof_Flat"
    },
    {
      "x": -4,
      "y": 10,
      "z": 1,
      "name": "Plant_Vine_Hanging"
    },
    {
      "x": -4,
      "y": 11,
      "z": 1,
      "name": "Wood_Softwood_Planks"
    },
    {
      "x": -4,
      "y": 12,
      "z": 1,
      "name": "Plant_Moss_Rug_Green"
    },
    {
      "x": -4,
      "y": 13,
      "z": 1,
      "name": "Empty"
    },
    {
      "x": -4,
      "y": 13,
      "z": 2,
      "name": "Plant_Moss_Wall_Green",
      "rotation": 3
    },
    {
      "x": -4,
      "y": 0,
      "z": 4,
      "name": "Wood_Softwood_Beam"
    },
    {
      "x": -4,
      "y": 1,
      "z": 4,
      "name": "Wood_Softwood_Beam"
    },
    {
      "x": -4,
      "y": 2,
      "z": 4,
      "name": "Wood_Softwood_Beam"
    },
    {
      "x": -4,
      "y": 3,
      "z": 4,
      "name": "Wood_Softwood_Beam"
    },
    {
      "x": -4,
      "y": 4,
      "z": 4,
      "name": "Wood_Softwood_Beam"
    },
    {
      "x": -4,
      "y": 5,
      "z": 4,
      "name": "Wood_Softwood_Beam"
    },
    {
      "x": -4,
      "y": 6,
      "z": 4,
      "name": "Wood_Softwood_Beam"
    },
    {
      "x": -4,
      "y": 7,
      "z": 4,
      "name": "Wood_Softwood_Beam"
    },
    {
      "x": -4,
      "y": 8,
      "z": 4,
      "name": "Wood_Softwood_Beam"
    },
    {
      "x": -4,
      "y": 9,
      "z": 4,
      "name": "Wood_Softwood_Beam"
    },
    {
      "x": -4,
      "y": 10,
      "z": 4,
      "name": "Wood_Softwood_Beam"
    },
    {
      "x": -4,
      "y": 11,
      "z": 4,
      "name": "Wood_Softwood_Planks_Half"
    },
    {
      "x": -3,
      "y": 14,
      "z": -3,
      "name": "Wood_Deadwood_Roof_Flat"
    },
    {
      "x": -3,
      "y": 11,
      "z": -2,
      "name": "Wood_Softwood_Planks"
    },
    {
      "x": -3,
      "y": 12,
      "z": -2,
      "name": "Wood_Hardwood_Planks"
    },
    {
      "x": -3,
      "y": 13,
      "z": -2,
      "name": "Wood_Hardwood_Planks"
    },
    {
      "x": -3,
      "y": 14,
      "z": -2,
      "name": "Wood_Deadwood_Roof",
      "rotation": 2
    },
    {
      "x": -3,
      "y": 11,
      "z": -1,
      "name": "Wood_Softwood_Planks"
    },
    {
      "x": -3,
      "y": 12,
      "z": -1,
      "name": "Furniture_Village_Crate"
    },
    {
      "x": -3,
      "y": 13,
      "z": -1,
      "name": "Furniture_Tavern_Barrel"
    },
    {
      "x": -3,
      "y": 14,
      "z": -1,
      "name": "Empty"
    },
    {
      "x": -3,
      "y": 15,
      "z": -1,
      "name": "Wood_Deadwood_Roof",
      "rotation": 2
    },
    {
      "x": -3,
      "y": 11,
      "z": 0,
      "name": "Wood_Softwood_Planks"
    },
    {
      "x": -3,
      "y": 12,
      "z": 0,
      "name": "Alchemy_Cauldron",
      "rotation": 1
    },
    {
      "x": -3,
      "y": 13,
      "z": 0,
      "name": "Empty"
    },
    {
      "x": -3,
      "y": 14,
      "z": 0,
      "name": "Empty"
    },
    {
      "x": -3,
      "y": 15,
      "z": 0,
      "name": "Empty"
    },
    {
      "x": -3,
      "y": 16,
      "z": 0,
      "name": "Wood_Deadwood_Roof_Flat"
    },
    {
      "x": -3,
      "y": 11,
      "z": 1,
      "name": "Wood_Softwood_Planks"
    },
    {
      "x": -3,
      "y": 12,
      "z": 1,
      "name": "Plant_Moss_Rug_Green"
    },
    {
      "x": -3,
      "y": 13,
      "z": 1,
      "name": "Empty"
    },
    {
      "x": -3,
      "y": 14,
      "z": 1,
      "name": "Empty"
    },
    {
      "x": -3,
      "y": 15,
      "z": 1,
      "name": "Wood_Deadwood_Roof"
    },
    {
      "x": -3,
      "y": 10,
      "z": 2,
      "name": "Plant_Moss_Cave_Green",
      "rotation": 8
    },
    {
      "x": -3,
      "y": 11,
      "z": 2,
      "name": "Wood_Softwood_Planks"
    },
    {
      "x": -3,
      "y": 12,
      "z": 2,
      "name": "Wood_Hardwood_Planks"
    },
    {
      "x": -3,
      "y": 13,
      "z": 2,
      "name": "Wood_Hardwood_Planks"
    },
    {
      "x": -3,
      "y": 14,
      "z": 2,
      "name": "Wood_Deadwood_Roof"
    },
    {
      "x": -3,
      "y": 13,
      "z": 3,
      "name": "Plant_Vine_Hanging"
    },
    {
      "x": -3,
      "y": 14,
      "z": 3,
      "name": "Wood_Deadwood_Roof_Flat"
    },
    {
      "x": -3,
      "y": 11,
      "z": 4,
      "name": "Wood_Softwood_Planks_Half"
    },
    {
      "x": -2,
      "y": 14,
      "z": -3,
      "name": "Wood_Deadwood_Roof_Flat"
    },
    {
      "x": -2,
      "y": 11,
      "z": -2,
      "name": "Wood_Softwood_Planks"
    },
    {
      "x": -2,
      "y": 12,
      "z": -2,
      "name": "Wood_Hardwood_Planks"
    },
    {
      "x": -2,
      "y": 13,
      "z": -2,
      "name": "Furniture_Crude_Window"
    },
    {
      "x": -2,
      "y": 14,
      "z": -2,
      "name": "Wood_Deadwood_Roof",
      "rotation": 2
    },
    {
      "x": -2,
      "y": 11,
      "z": -1,
      "name": "Wood_Softwood_Planks"
    },
    {
      "x": -2,
      "y": 12,
      "z": -1,
      "name": "Furniture_Tavern_Barrel"
    },
    {
      "x": -2,
      "y": 13,
      "z": -1,
      "name": "Furniture_Crude_Candle"
    },
    {
      "x": -2,
      "y": 14,
      "z": -1,
      "name": "Empty"
    },
    {
      "x": -2,
      "y": 15,
      "z": -1,
      "name": "Wood_Deadwood_Roof",
      "rotation": 2
    },
    {
      "x": -2,
      "y": 11,
      "z": 0,
      "name": "Wood_Softwood_Planks"
    },
    {
      "x": -2,
      "y": 12,
      "z": 0,
      "name": "Empty"
    },
    {
      "x": -2,
      "y": 13,
      "z": 0,
      "name": "Empty"
    },
    {
      "x": -2,
      "y": 14,
      "z": 0,
      "name": "Empty"
    },
    {
      "x": -2,
      "y": 15,
      "z": 0,
      "name": "Empty"
    },
    {
      "x": -2,
      "y": 16,
      "z": 0,
      "name": "Wood_Deadwood_Roof_Flat"
    },
    {
      "x": -2,
      "y": 11,
      "z": 1,
      "name": "Wood_Softwood_Planks"
    },
    {
      "x": -2,
      "y": 12,
      "z": 1,
      "name": "Empty"
    },
    {
      "x": -2,
      "y": 13,
      "z": 1,
      "name": "Empty"
    },
    {
      "x": -2,
      "y": 14,
      "z": 1,
      "name": "Empty"
    },
    {
      "x": -2,
      "y": 15,
      "z": 1,
      "name": "Wood_Deadwood_Roof"
    },
    {
      "x": -2,
      "y": 11,
      "z": 2,
      "name": "Wood_Softwood_Planks"
    },
    {
      "x": -2,
      "y": 12,
      "z": 2,
      "name": "*Furniture_Crude_Door_State_Definitions_CloseDoorOut"
    },
    {
      "x": -2,
      "y": 13,
      "z": 2,
      "name": "*Furniture_Crude_Door_State_Definitions_CloseDoorOut",
      "filler": 1024
    },
    {
      "x": -2,
      "y": 14,
      "z": 2,
      "name": "Wood_Deadwood_Roof"
    },
    {
      "x": -2,
      "y": 11,
      "z": 3,
      "name": "Wood_Softwood_Stairs"
    },
    {
      "x": -2,
      "y": 14,
      "z": 3,
      "name": "Wood_Deadwood_Roof_Flat"
    },
    {
      "x": -2,
      "y": 11,
      "z": 4,
      "name": "Wood_Softwood_Planks_Half"
    },
    {
      "x": -1,
      "y": 11,
      "z": -2,
      "name": "Wood_Softwood_Planks"
    },
    {
      "x": -1,
      "y": 12,
      "z": -2,
      "name": "Wood_Hardwood_Planks"
    },
    {
      "x": -1,
      "y": 13,
      "z": -2,
      "name": "Wood_Hardwood_Planks"
    },
    {
      "x": -1,
      "y": 14,
      "z": -2,
      "name": "Wood_Deadwood_Roof",
      "rotation": 2
    },
    {
      "x": -1,
      "y": 11,
      "z": -1,
      "name": "Wood_Softwood_Planks"
    },
    {
      "x": -1,
      "y": 12,
      "z": -1,
      "name": "Empty"
    },
    {
      "x": -1,
      "y": 13,
      "z": -1,
      "name": "Empty"
    },
    {
      "x": -1,
      "y": 14,
      "z": -1,
      "name": "Empty"
    },
    {
      "x": -1,
      "y": 15,
      "z": -1,
      "name": "Wood_Deadwood_Roof",
      "rotation": 2
    },
    {
      "x": -1,
      "y": 11,
      "z": 0,
      "name": "Wood_Softwood_Planks"
    },
    {
      "x": -1,
      "y": 12,
      "z": 0,
      "name": "Empty"
    },
    {
      "x": -1,
      "y": 13,
      "z": 0,
      "name": "Empty"
    },
    {
      "x": -1,
      "y": 14,
      "z": 0,
      "name": "Empty"
    },
    {
      "x": -1,
      "y": 15,
      "z": 0,
      "name": "Empty"
    },
    {
      "x": -1,
      "y": 16,
      "z": 0,
      "name": "Wood_Deadwood_Roof_Flat"
    },
    {
      "x": -1,
      "y": 11,
      "z": 1,
      "name": "Wood_Softwood_Planks"
    },
    {
      "x": -1,
      "y": 12,
      "z": 1,
      "name": "Empty"
    },
    {
      "x": -1,
      "y": 13,
      "z": 1,
      "name": "Empty"
    },
    {
      "x": -1,
      "y": 14,
      "z": 1,
      "name": "Empty"
    },
    {
      "x": -1,
      "y": 11,
      "z": 2,
      "name": "Wood_Softwood_Planks"
    },
    {
      "x": -1,
      "y": 12,
      "z": 2,
      "name": "Wood_Hardwood_Planks"
    },
    {
      "x": -1,
      "y": 13,
      "z": 2,
      "name": "Wood_Hardwood_Planks"
    },
    {
      "x": -1,
      "y": 14,
      "z": 2,
      "name": "Plant_Moss_Rug_Green"
    },
    {
      "x": -1,
      "y": 11,
      "z": 3,
      "name": "Wood_Softwood_Stairs"
    },
    {
      "x": -1,
      "y": 13,
      "z": 3,
      "name": "Plant_Moss_Wall_Green"
    },
    {
      "x": -1,
      "y": 11,
      "z": 4,
      "name": "Wood_Softwood_Planks_Half"
    },
    {
      "x": 0,
      "y": 0,
      "z": -2,
      "name": "Wood_Softwood_Beam"
    },
    {
      "x": 0,
      "y": 1,
      "z": -2,
      "name": "Wood_Softwood_Beam"
    },
    {
      "x": 0,
      "y": 2,
      "z": -2,
      "name": "Wood_Softwood_Beam"
    },
    {
      "x": 0,
      "y": 3,
      "z": -2,
      "name": "Wood_Softwood_Beam"
    },
    {
      "x": 0,
      "y": 4,
      "z": -2,
      "name": "Wood_Softwood_Beam"
    },
    {
      "x": 0,
      "y": 5,
      "z": -2,
      "name": "Wood_Softwood_Beam"
    },
    {
      "x": 0,
      "y": 6,
      "z": -2,
      "name": "Wood_Softwood_Beam"
    },
    {
      "x": 0,
      "y": 7,
      "z": -2,
      "name": "Wood_Softwood_Beam"
    },
    {
      "x": 0,
      "y": 8,
      "z": -2,
      "name": "Wood_Softwood_Beam"
    },
    {
      "x": 0,
      "y": 9,
      "z": -2,
      "name": "Wood_Softwood_Beam"
    },
    {
      "x": 0,
      "y": 10,
      "z": -2,
      "name": "Wood_Softwood_Beam"
    },
    {
      "x": 0,
      "y": 11,
      "z": -2,
      "name": "Wood_Softwood_Planks"
    },
    {
      "x": 0,
      "y": 12,
      "z": -2,
      "name": "Wood_Hardwood_Planks"
    },
    {
      "x": 0,
      "y": 11,
      "z": -1,
      "name": "Wood_Softwood_Planks_Half"
    },
    {
      "x": 0,
      "y": 12,
      "z": -1,
      "name": "Empty"
    },
    {
      "x": 0,
      "y": 13,
      "z": -1,
      "name": "Empty"
    },
    {
      "x": 0,
      "y": 14,
      "z": -1,
      "name": "Empty"
    },
    {
      "x": 0,
      "y": 11,
      "z": 0,
      "name": "Wood_Softwood_Planks_Half"
    },
    {
      "x": 0,
      "y": 12,
      "z": 0,
      "name": "Empty"
    },
    {
      "x": 0,
      "y": 13,
      "z": 0,
      "name": "Empty"
    },
    {
      "x": 0,
      "y": 14,
      "z": 0,
      "name": "Empty"
    },
    {
      "x": 0,
      "y": 15,
      "z": 0,
      "name": "Empty"
    },
    {
      "x": 0,
      "y": 11,
      "z": 1,
      "name": "Wood_Softwood_Planks"
    },
    {
      "x": 0,
      "y": 12,
      "z": 1,
      "name": "Empty"
    },
    {
      "x": 0,
      "y": 13,
      "z": 1,
      "name": "Empty"
    },
    {
      "x": 0,
      "y": 14,
      "z": 1,
      "name": "Empty"
    },
    {
      "x": 0,
      "y": 11,
      "z": 2,
      "name": "Wood_Softwood_Planks"
    },
    {
      "x": 0,
      "y": 12,
      "z": 2,
      "name": "Wood_Hardwood_Planks"
    },
    {
      "x": 0,
      "y": 13,
      "z": 2,
      "name": "Plant_Moss_Rug_Green"
    },
    {
      "x": 0,
      "y": 11,
      "z": 3,
      "name": "Wood_Softwood_Planks_Half"
    },
    {
      "x": 0,
      "y": 12,
      "z": 3,
      "name": "Plant_Moss_Wall_Green"
    },
    {
      "x": 0,
      "y": 0,
      "z": 4,
      "name": "Wood_Softwood_Beam"
    },
    {
      "x": 0,
      "y": 1,
      "z": 4,
      "name": "Wood_Softwood_Beam"
    },
    {
      "x": 0,
      "y": 2,
      "z": 4,
      "name": "Wood_Softwood_Beam"
    },
    {
      "x": 0,
      "y": 3,
      "z": 4,
      "name": "Wood_Softwood_Beam"
    },
    {
      "x": 0,
      "y": 4,
      "z": 4,
      "name": "Wood_Softwood_Beam"
    },
    {
      "x": 0,
      "y": 5,
      "z": 4,
      "name": "Wood_Softwood_Beam"
    },
    {
      "x": 0,
      "y": 6,
      "z": 4,
      "name": "Wood_Softwood_Beam"
    },
    {
      "x": 0,
      "y": 7,
      "z": 4,
      "name": "Wood_Softwood_Beam"
    },
    {
      "x": 0,
      "y": 8,
      "z": 4,
      "name": "Wood_Softwood_Beam"
    },
    {
      "x": 0,
      "y": 9,
      "z": 4,
      "name": "Wood_Softwood_Beam"
    },
    {
      "x": 0,
      "y": 10,
      "z": 4,
      "name": "Wood_Softwood_Beam"
    },
    {
      "x": 0,
      "y": 11,
      "z": 4,
      "name": "Wood_Softwood_Planks_Half"
    },
    {
      "x": 1,
      "y": 12,
      "z": -1,
      "name": "Empty"
    },
    {
      "x": 1,
      "y": 13,
      "z": -1,
      "name": "Empty"
    },
    {
      "x": 1,
      "y": 14,
      "z": -1,
      "name": "Empty"
    },
    {
      "x": 1,
      "y": 15,
      "z": -1,
      "name": "Wood_Deadwood_Roof",
      "rotation": 2
    },
    {
      "x": 1,
      "y": 11,
      "z": 0,
      "name": "Wood_Softwood_Planks_Half"
    },
    {
      "x": 1,
      "y": 12,
      "z": 0,
      "name": "Empty"
    },
    {
      "x": 1,
      "y": 13,
      "z": 0,
      "name": "Empty"
    },
    {
      "x": 1,
      "y": 14,
      "z": 0,
      "name": "Empty"
    },
    {
      "x": 1,
      "y": 15,
      "z": 0,
      "name": "Empty"
    },
    {
      "x": 1,
      "y": 16,
      "z": 0,
      "name": "Wood_Deadwood_Roof_Flat"
    },
    {
      "x": 1,
      "y": 11,
      "z": 1,
      "name": "Wood_Softwood_Planks"
    },
    {
      "x": 1,
      "y": 12,
      "z": 1,
      "name": "Empty"
    },
    {
      "x": 1,
      "y": 13,
      "z": 1,
      "name": "Empty"
    },
    {
      "x": 1,
      "y": 14,
      "z": 1,
      "name": "Empty"
    },
    {
      "x": 1,
      "y": 15,
      "z": 1,
      "name": "Wood_Deadwood_Roof"
    },
    {
      "x": 1,
      "y": 11,
      "z": 2,
      "name": "Wood_Softwood_Planks"
    },
    {
      "x": 1,
      "y": 12,
      "z": 2,
      "name": "Wood_Hardwood_Planks"
    },
    {
      "x": 1,
      "y": 13,
      "z": 2,
      "name": "Furniture_Crude_Window"
    },
    {
      "x": 1,
      "y": 11,
      "z": 3,
      "name": "Wood_Softwood_Planks_Half"
    },
    {
      "x": 1,
      "y": 11,
      "z": 4,
      "name": "Wood_Softwood_Planks_Half"
    },
    {
      "x": 2,
      "y": 11,
      "z": -2,
      "name": "Plant_Moss_Wall_Green",
      "rotation": 3
    },
    {
      "x": 2,
      "y": 12,
      "z": -2,
      "name": "Plant_Moss_Wall_Green",
      "rotation": 3
    },
    {
      "x": 2,
      "y": 10,
      "z": -1,
      "name": "Plant_Moss_Cave_Green",
      "rotation": 8
    },
    {
      "x": 2,
      "y": 11,
      "z": -1,
      "name": "Wood_Softwood_Planks_Half"
    },
    {
      "x": 2,
      "y": 12,
      "z": -1,
      "name": "Empty"
    },
    {
      "x": 2,
      "y": 13,
      "z": -1,
      "name": "Empty"
    },
    {
      "x": 2,
      "y": 14,
      "z": -1,
      "name": "Empty"
    },
    {
      "x": 2,
      "y": 15,
      "z": -1,
      "name": "Wood_Deadwood_Roof",
      "rotation": 2
    },
    {
      "x": 2,
      "y": 11,
      "z": 0,
      "name": "Wood_Softwood_Planks"
    },
    {
      "x": 2,
      "y": 12,
      "z": 0,
      "name": "Plant_Moss_Rug_Green"
    },
    {
      "x": 2,
      "y": 13,
      "z": 0,
      "name": "Empty"
    },
    {
      "x": 2,
      "y": 14,
      "z": 0,
      "name": "Empty"
    },
    {
      "x": 2,
      "y": 15,
      "z": 0,
      "name": "Empty"
    },
    {
      "x": 2,
      "y": 16,
      "z": 0,
      "name": "Wood_Deadwood_Roof_Flat"
    },
    {
      "x": 2,
      "y": 11,
      "z": 1,
      "name": "Wood_Softwood_Planks"
    },
    {
      "x": 2,
      "y": 12,
      "z": 1,
      "name": "Empty"
    },
    {
      "x": 2,
      "y": 14,
      "z": 1,
      "name": "Empty"
    },
    {
      "x": 2,
      "y": 15,
      "z": 1,
      "name": "Wood_Deadwood_Roof"
    },
    {
      "x": 2,
      "y": 11,
      "z": 2,
      "name": "Wood_Softwood_Planks"
    },
    {
      "x": 2,
      "y": 12,
      "z": 2,
      "name": "Wood_Hardwood_Planks"
    },
    {
      "x": 2,
      "y": 13,
      "z": 2,
      "name": "Furniture_Crude_Window"
    },
    {
      "x": 2,
      "y": 14,
      "z": 2,
      "name": "Wood_Deadwood_Roof"
    },
    {
      "x": 2,
      "y": 11,
      "z": 3,
      "name": "Wood_Softwood_Planks_Half"
    },
    {
      "x": 2,
      "y": 14,
      "z": 3,
      "name": "Wood_Deadwood_Roof_Flat"
    },
    {
      "x": 2,
      "y": 11,
      "z": 4,
      "name": "Wood_Softwood_Planks_Half"
    },
    {
      "x": 2,
      "y": 13,
      "z": 4,
      "name": "Plant_Vine_Hanging"
    },
    {
      "x": 2,
      "y": 14,
      "z": 4,
      "name": "Wood_Deadwood_Roof_Flat"
    },
    {
      "x": 3,
      "y": 11,
      "z": -3,
      "name": "Plant_Moss_Wall_Green",
      "rotation": 2
    },
    {
      "x": 3,
      "y": 10,
      "z": -2,
      "name": "Plant_Moss_Cave_Green",
      "rotation": 8
    },
    {
      "x": 3,
      "y": 11,
      "z": -2,
      "name": "Wood_Softwood_Planks"
    },
    {
      "x": 3,
      "y": 12,
      "z": -2,
      "name": "Wood_Hardwood_Planks"
    },
    {
      "x": 3,
      "y": 13,
      "z": -2,
      "name": "Wood_Hardwood_Planks"
    },
    {
      "x": 3,
      "y": 14,
      "z": -2,
      "name": "Wood_Deadwood_Roof",
      "rotation": 2
    },
    {
      "x": 3,
      "y": 11,
      "z": -1,
      "name": "Wood_Softwood_Planks"
    },
    {
      "x": 3,
      "y": 12,
      "z": -1,
      "name": "Plant_Moss_Rug_Green"
    },
    {
      "x": 3,
      "y": 13,
      "z": -1,
      "name": "Empty"
    },
    {
      "x": 3,
      "y": 14,
      "z": -1,
      "name": "Plant_Moss_Cave_Green",
      "rotation": 8
    },
    {
      "x": 3,
      "y": 15,
      "z": -1,
      "name": "Wood_Deadwood_Roof",
      "rotation": 2
    },
    {
      "x": 3,
      "y": 11,
      "z": 0,
      "name": "Wood_Softwood_Planks"
    },
    {
      "x": 3,
      "y": 12,
      "z": 0,
      "name": "Block_Spawner_Block",
      "components": {
        "Components": {
          "PlacedByInteraction": {
            "WhoPlacedUuid": {
              "$binary": "x9M0GYCLPG+IqIodoDzEcQ==",
              "$type": "04"
            }
          },
          "BlockSpawner": {
            "BlockSpawnerId": "Zone1_Encounters_Tier2"
          }
        }
      },
      "rotation": 3
    },
    {
      "x": 3,
      "y": 13,
      "z": 0,
      "name": "Empty"
    },
    {
      "x": 3,
      "y": 14,
      "z": 0,
      "name": "Empty"
    },
    {
      "x": 3,
      "y": 15,
      "z": 0,
      "name": "Empty"
    },
    {
      "x": 3,
      "y": 16,
      "z": 0,
      "name": "Wood_Deadwood_Roof_Flat"
    },
    {
      "x": 3,
      "y": 10,
      "z": 1,
      "name": "Plant_Vine_Hanging"
    },
    {
      "x": 3,
      "y": 11,
      "z": 1,
      "name": "Wood_Softwood_Planks"
    },
    {
      "x": 3,
      "y": 12,
      "z": 1,
      "name": "Empty"
    },
    {
      "x": 3,
      "y": 13,
      "z": 1,
      "name": "Empty"
    },
    {
      "x": 3,
      "y": 14,
      "z": 1,
      "name": "Empty"
    },
    {
      "x": 3,
      "y": 15,
      "z": 1,
      "name": "Wood_Deadwood_Roof"
    },
    {
      "x": 3,
      "y": 11,
      "z": 2,
      "name": "Wood_Softwood_Planks"
    },
    {
      "x": 3,
      "y": 12,
      "z": 2,
      "name": "Wood_Hardwood_Planks"
    },
    {
      "x": 3,
      "y": 13,
      "z": 2,
      "name": "Wood_Hardwood_Planks"
    },
    {
      "x": 3,
      "y": 14,
      "z": 2,
      "name": "Wood_Deadwood_Roof"
    },
    {
      "x": 3,
      "y": 11,
      "z": 3,
      "name": "Wood_Softwood_Planks_Half"
    },
    {
      "x": 3,
      "y": 13,
      "z": 3,
      "name": "Plant_Moss_Wall_Green"
    },
    {
      "x": 3,
      "y": 14,
      "z": 3,
      "name": "Wood_Deadwood_Roof_Flat"
    },
    {
      "x": 3,
      "y": 10,
      "z": 4,
      "name": "Plant_Moss_Cave_Green",
      "rotation": 8
    },
    {
      "x": 3,
      "y": 11,
      "z": 4,
      "name": "Wood_Softwood_Planks_Half"
    },
    {
      "x": 3,
      "y": 14,
      "z": 4,
      "name": "Wood_Deadwood_Roof_Flat"
    },
    {
      "x": 4,
      "y": 0,
      "z": -2,
      "name": "Wood_Softwood_Beam"
    },
    {
      "x": 4,
      "y": 1,
      "z": -2,
      "name": "Wood_Softwood_Beam"
    },
    {
      "x": 4,
      "y": 2,
      "z": -2,
      "name": "Wood_Softwood_Beam"
    },
    {
      "x": 4,
      "y": 3,
      "z": -2,
      "name": "Wood_Softwood_Beam"
    },
    {
      "x": 4,
      "y": 4,
      "z": -2,
      "name": "Wood_Softwood_Beam"
    },
    {
      "x": 4,
      "y": 5,
      "z": -2,
      "name": "Wood_Softwood_Beam"
    },
    {
      "x": 4,
      "y": 6,
      "z": -2,
      "name": "Wood_Softwood_Beam"
    },
    {
      "x": 4,
      "y": 7,
      "z": -2,
      "name": "Wood_Softwood_Beam"
    },
    {
      "x": 4,
      "y": 8,
      "z": -2,
      "name": "Wood_Softwood_Beam"
    },
    {
      "x": 4,
      "y": 9,
      "z": -2,
      "name": "Wood_Softwood_Beam"
    },
    {
      "x": 4,
      "y": 10,
      "z": -2,
      "name": "Wood_Softwood_Beam"
    },
    {
      "x": 4,
      "y": 11,
      "z": -2,
      "name": "Wood_Softwood_Planks"
    },
    {
      "x": 4,
      "y": 12,
      "z": -2,
      "name": "Wood_Hardwood_Planks"
    },
    {
      "x": 4,
      "y": 13,
      "z": -2,
      "name": "Wood_Hardwood_Planks"
    },
    {
      "x": 4,
      "y": 14,
      "z": -2,
      "name": "Wood_Deadwood_Roof",
      "rotation": 2
    },
    {
      "x": 4,
      "y": 11,
      "z": -1,
      "name": "Wood_Softwood_Planks"
    },
    {
      "x": 4,
      "y": 12,
      "z": -1,
      "name": "Wood_Hardwood_Planks"
    },
    {
      "x": 4,
      "y": 13,
      "z": -1,
      "name": "Wood_Hardwood_Planks"
    },
    {
      "x": 4,
      "y": 14,
      "z": -1,
      "name": "Wood_Hardwood_Planks"
    },
    {
      "x": 4,
      "y": 15,
      "z": -1,
      "name": "Plant_Moss_Rug_Green"
    },
    {
      "x": 4,
      "y": 11,
      "z": 0,
      "name": "Wood_Softwood_Planks"
    },
    {
      "x": 4,
      "y": 12,
      "z": 0,
      "name": "Wood_Hardwood_Planks"
    },
    {
      "x": 4,
      "y": 13,
      "z": 0,
      "name": "Wood_Hardwood_Planks"
    },
    {
      "x": 4,
      "y": 14,
      "z": 0,
      "name": "Empty"
    },
    {
      "x": 4,
      "y": 15,
      "z": 0,
      "name": "Empty"
    },
    {
      "x": 4,
      "y": 11,
      "z": 1,
      "name": "Wood_Softwood_Planks"
    },
    {
      "x": 4,
      "y": 12,
      "z": 1,
      "name": "Wood_Hardwood_Planks"
    },
    {
      "x": 4,
      "y": 13,
      "z": 1,
      "name": "Wood_Hardwood_Planks"
    },
    {
      "x": 4,
      "y": 14,
      "z": 1,
      "name": "Wood_Hardwood_Planks"
    },
    {
      "x": 4,
      "y": 15,
      "z": 1,
      "name": "Wood_Deadwood_Roof"
    },
    {
      "x": 4,
      "y": 10,
      "z": 2,
      "name": "Plant_Moss_Cave_Green",
      "rotation": 8
    },
    {
      "x": 4,
      "y": 11,
      "z": 2,
      "name": "Wood_Softwood_Planks"
    },
    {
      "x": 4,
      "y": 12,
      "z": 2,
      "name": "Wood_Hardwood_Planks"
    },
    {
      "x": 4,
      "y": 13,
      "z": 2,
      "name": "Wood_Hardwood_Planks"
    },
    {
      "x": 4,
      "y": 14,
      "z": 2,
      "name": "Wood_Deadwood_Roof"
    },
    {
      "x": 4,
      "y": 11,
      "z": 3,
      "name": "Wood_Softwood_Planks_Half"
    },
    {
      "x": 4,
      "y": 14,
      "z": 3,
      "name": "Wood_Deadwood_Roof_Flat"
    },
    {
      "x": 4,
      "y": 0,
      "z": 4,
      "name": "Wood_Softwood_Beam"
    },
    {
      "x": 4,
      "y": 1,
      "z": 4,
      "name": "Wood_Softwood_Beam"
    },
    {
      "x": 4,
      "y": 2,
      "z": 4,
      "name": "Wood_Softwood_Beam"
    },
    {
      "x": 4,
      "y": 3,
      "z": 4,
      "name": "Wood_Softwood_Beam"
    },
    {
      "x": 4,
      "y": 4,
      "z": 4,
      "name": "Wood_Softwood_Beam"
    },
    {
      "x": 4,
      "y": 5,
      "z": 4,
      "name": "Wood_Softwood_Beam"
    },
    {
      "x": 4,
      "y": 6,
      "z": 4,
      "name": "Wood_Softwood_Beam"
    },
    {
      "x": 4,
      "y": 7,
      "z": 4,
      "name": "Wood_Softwood_Beam"
    },
    {
      "x": 4,
      "y": 8,
      "z": 4,
      "name": "Wood_Softwood_Beam"
    },
    {
      "x": 4,
      "y": 9,
      "z": 4,
      "name": "Wood_Softwood_Beam"
    },
    {
      "x": 4,
      "y": 10,
      "z": 4,
      "name": "Wood_Softwood_Beam"
    },
    {
      "x": 4,
      "y": 11,
      "z": 4,
      "name": "Wood_Softwood_Planks_Half"
    },
    {
      "x": 4,
      "y": 14,
      "z": 4,
      "name": "Wood_Deadwood_Roof_Flat"
    },
    {
      "x": 5,
      "y": 13,
      "z": -2,
      "name": "Wood_Hardwood_Planks_Half",
      "rotation": 8
    },
    {
      "x": 5,
      "y": 14,
      "z": -2,
      "name": "Plant_Moss_Rug_Green"
    },
    {
      "x": 5,
      "y": 14,
      "z": -1,
      "name": "Plant_Moss_Wall_Green",
      "rotation": 1
    },
    {
      "x": 5,
      "y": 12,
      "z": 1,
      "name": "Plant_Moss_Wall_Green",
      "rotation": 1
    },
    {
      "x": 5,
      "y": 14,
      "z": 1,
      "name": "Wood_Hardwood_Stairs",
      "rotation": 8
    },
    {
      "x": 5,
      "y": 15,
      "z": 1,
      "name": "Wood_Deadwood_Roof"
    },
    {
      "x": 5,
      "y": 11,
      "z": 2,
      "name": "Plant_Moss_Wall_Green",
      "rotation": 1
    },
    {
      "x": 5,
      "y": 13,
      "z": 2,
      "name": "Wood_Hardwood_Planks_Half",
      "rotation": 8
    },
    {
      "x": 5,
      "y": 14,
      "z": 2,
      "name": "Wood_Deadwood_Roof"
    },
    {
      "x": 5,
      "y": 13,
      "z": 3,
      "name": "Plant_Vine_Hanging"
    },
    {
      "x": 5,
      "y": 14,
      "z": 3,
      "name": "Wood_Deadwood_Roof_Flat"
    },
    {
      "x": 6,
      "y": 13,
      "z": -2,
      "name": "Plant_Moss_Wall_Green",
      "rotation": 1
    }
  ]
}