{
  "version": 8,
  "blockIdVersion": 8,
  "anchorX": 8,
  "anchorY": 6,
  "anchorZ": 4,
  "blocks": [
    {
      "x": 5,
      "y": 6,
      "z": 4,
      "name": "Rock_Stone"
    },
    {
      "x": 5,
      "y": 7,
      "z": 4,
      "name": "Rock_Stone"
    },
    {
      "x": 5,
      "y": 8,
      "z": 4,
      "name": "Rock_Stone"
    },
    {
      "x": 5,
      "y": 9,
      "z": 4,
      "name": "Rock_Stone"
    },
    {
      "x": 5,
      "y": 6,
      "z": 5,
      "name": "Rock_Stone"
    },
    {
      "x": 5,
      "y": 7,
      "z": 5,
      "name": "Rock_Stone"
    },
    {
      "x": 5,
      "y": 8,
      "z": 5,
      "name": "Rock_Stone"
    },
    {
      "x": 5,
      "y": 9,
      "z": 5,
      "name": "Soil_Gravel"
    },
    {
      "x": 5,
      "y": 7,
      "z": 6,
      "name": "Rock_Stone"
    },
    {
      "x": 5,
      "y": 8,
      "z": 6,
      "name": "Soil_Gravel"
    },
    {
      "x": 6,
      "y": 5,
      "z": 2,
      "name": "Rock_Stone"
    },
    {
      "x": 6,
      "y": 6,
      "z": 2,
      "name": "Rock_Stone"
    },
    {
      "x": 6,
      "y": 7,
      "z": 2,
      "name": "Soil_Gravel"
    },
    {
      "x": 6,
      "y": 4,
      "z": 3,
      "name": "Rock_Stone"
    },
    {
      "x": 6,
      "y": 5,
      "z": 3,
      "name": "Rock_Stone"
    },
    {
      "x": 6,
      "y": 6,
      "z": 3,
      "name": "Rock_Stone"
    },
    {
      "x": 6,
      "y": 7,
      "z": 3,
      "name": "Rock_Stone"
    },
    {
      "x": 6,
      "y": 8,
      "z": 3,
      "name": "Rock_Stone"
    },
    {
      "x": 6,
      "y": 4,
      "z": 4,
      "name": "Rock_Stone"
    },
    {
      "x": 6,
      "y": 5,
      "z": 4,
      "name": "Rock_Stone"
    },
    {
      "x": 6,
      "y": 6,
      "z": 4,
      "name": "Rock_Stone"
    },
    {
      "x": 6,
      "y": 7,
      "z": 4,
      "name": "Rock_Stone"
    },
    {
      "x": 6,
      "y": 8,
      "z": 4,
      "name": "Rock_Stone"
    },
    {
      "x": 6,
      "y": 9,
      "z": 4,
      "name": "Rock_Stone"
    },
    {
      "x": 6,
      "y": 4,
      "z": 5,
      "name": "Rock_Stone"
    },
    {
      "x": 6,
      "y": 5,
      "z": 5,
      "name": "Rock_Stone"
    },
    {
      "x": 6,
      "y": 6,
      "z": 5,
      "name": "Rock_Stone"
    },
    {
      "x": 6,
      "y": 7,
      "z": 5,
      "name": "Rock_Stone"
    },
    {
      "x": 6,
      "y": 8,
      "z": 5,
      "name": "Rock_Stone"
    },
    {
      "x": 6,
      "y": 9,
      "z": 5,
      "name": "Rock_Stone"
    },
    {
      "x": 6,
      "y": 10,
      "z": 5,
      "name": "Rock_Stone"
    },
    {
      "x": 6,
      "y": 5,
      "z": 6,
      "name": "Rock_Stone"
    },
    {
      "x": 6,
      "y": 6,
      "z": 6,
      "name": "Rock_Stone"
    },
    {
      "x": 6,
      "y": 7,
      "z": 6,
      "name": "Rock_Stone"
    },
    {
      "x": 6,
      "y": 8,
      "z": 6,
      "name": "Rock_Stone"
    },
    {
      "x": 6,
      "y": 9,
      "z": 6,
      "name": "Rock_Stone"
    },
    {
      "x": 6,
      "y": 10,
      "z": 6,
      "name": "Rock_Stone_Mossy"
    },
    {
      "x": 6,
      "y": 8,
      "z": 7,
      "name": "Rock_Stone"
    },
    {
      "x": 6,
      "y": 9,
      "z": 7,
      "name": "Rock_Stone"
    },
    {
      "x": 6,
      "y": 10,
      "z": 7,
      "name": "Rock_Stone_Mossy"
    },
    {
      "x": 7,
      "y": 4,
      "z": 2,
      "name": "Rock_Stone"
    },
    {
      "x": 7,
      "y": 5,
      "z": 2,
      "name": "Rock_Stone"
    },
    {
      "x": 7,
      "y": 6,
      "z": 2,
      "name": "Rock_Stone"
    },
    {
      "x": 7,
      "y": 7,
      "z": 2,
      "name": "Rock_Stone"
    },
    {
      "x": 7,
      "y": 8,
      "z": 2,
      "name": "Rock_Stone_Mossy"
    },
    {
      "x": 7,
      "y": 4,
      "z": 3,
      "name": "Rock_Stone"
    },
    {
      "x": 7,
      "y": 5,
      "z": 3,
      "name": "Rock_Stone"
    },
    {
      "x": 7,
      "y": 6,
      "z": 3,
      "name": "Rock_Stone"
    },
    {
      "x": 7,
      "y": 7,
      "z": 3,
      "name": "Rock_Stone"
    },
    {
      "x": 7,
      "y": 8,
      "z": 3,
      "name": "Rock_Stone"
    },
    {
      "x": 7,
      "y": 9,
      "z": 3,
      "name": "Rock_Stone"
    },
    {
      "x": 7,
      "y": 3,
      "z": 4,
      "name": "Rock_Stone"
    },
    {
      "x": 7,
      "y": 4,
      "z": 4,
      "name": "Rock_Stone"
    },
    {
      "x": 7,
      "y": 5,
      "z": 4,
      "name": "Rock_Stone"
    },
    {
      "x": 7,
      "y": 6,
      "z": 4,
      "name": "Rock_Stone"
    },
    {
      "x": 7,
      "y": 7,
      "z": 4,
      "name": "Rock_Stone"
    },
    {
      "x": 7,
      "y": 8,
      "z": 4,
      "name": "Rock_Stone"
    },
    {
      "x": 7,
      "y": 9,
      "z": 4,
      "name": "Rock_Stone"
    },
    {
      "x": 7,
      "y": 3,
      "z": 5,
      "name": "Rock_Stone"
    },
    {
      "x": 7,
      "y": 4,
      "z": 5,
      "name": "Rock_Stone"
    },
    {
      "x": 7,
      "y": 5,
      "z": 5,
      "name": "Rock_Stone"
    },
    {
      "x": 7,
      "y": 6,
      "z": 5,
      "name": "Rock_Stone"
    },
    {
      "x": 7,
      "y": 7,
      "z": 5,
      "name": "Rock_Stone"
    },
    {
      "x": 7,
      "y": 8,
      "z": 5,
      "name": "Rock_Stone"
    },
    {
      "x": 7,
      "y": 9,
      "z": 5,
      "name": "Rock_Stone"
    },
    {
      "x": 7,
      "y": 10,
      "z": 5,
      "name": "Rock_Stone"
    },
    {
      "x": 7,
      "y": 4,
      "z": 6,
      "name": "Rock_Stone"
    },
    {
      "x": 7,
      "y": 5,
      "z": 6,
      "name": "Rock_Stone"
    },
    {
      "x": 7,
      "y": 6,
      "z": 6,
      "name": "Rock_Stone"
    },
    {
      "x": 7,
      "y": 7,
      "z": 6,
      "name": "Rock_Stone"
    },
    {
      "x": 7,
      "y": 8,
      "z": 6,
      "name": "Rock_Stone"
    },
    {
      "x": 7,
      "y": 9,
      "z": 6,
      "name": "Rock_Stone"
    },
    {
      "x": 7,
      "y": 10,
      "z": 6,
      "name": "Rock_Stone"
    },
    {
      "x": 7,
      "y": 11,
      "z": 6,
      "name": "Rubble_Stone_Mossy"
    },
    {
      "x": 7,
      "y": 6,
      "z": 7,
      "name": "Rock_Stone"
    },
    {
      "x": 7,
      "y": 7,
      "z": 7,
      "name": "Rock_Stone"
    },
    {
      "x": 7,
      "y": 8,
      "z": 7,
      "name": "Rock_Stone"
    },
    {
      "x": 7,
      "y": 9,
      "z": 7,
      "name": "Rock_Stone"
    },
    {
      "x": 8,
      "y": 5,
      "z": 1,
      "name": "Rock_Stone"
    },
    {
      "x": 8,
      "y": 6,
      "z": 1,
      "name": "Rock_Stone"
    },
    {
      "x": 8,
      "y": 7,
      "z": 1,
      "name": "Rock_Stone"
    },
    {
      "x": 8,
      "y": 4,
      "z": 2,
      "name": "Rock_Stone"
    },
    {
      "x": 8,
      "y": 5,
      "z": 2,
      "name": "Rock_Stone"
    },
    {
      "x": 8,
      "y": 6,
      "z": 2,
      "name": "Rock_Stone"
    },
    {
      "x": 8,
      "y": 7,
      "z": 2,
      "name": "Rock_Stone"
    },
    {
      "x": 8,
      "y": 8,
      "z": 2,
      "name": "Rock_Stone_Mossy"
    },
    {
      "x": 8,
      "y": 3,
      "z": 3,
      "name": "Rock_Stone"
    },
    {
      "x": 8,
      "y": 4,
      "z": 3,
      "name": "Rock_Stone"
    },
    {
      "x": 8,
      "y": 5,
      "z": 3,
      "name": "Rock_Stone"
    },
    {
      "x": 8,
      "y": 6,
      "z": 3,
      "name": "Rock_Stone"
    },
    {
      "x": 8,
      "y": 7,
      "z": 3,
      "name": "Rock_Stone"
    },
    {
      "x": 8,
      "y": 8,
      "z": 3,
      "name": "Rock_Stone"
    },
    {
      "x": 8,
      "y": 9,
      "z": 3,
      "name": "Rock_Stone"
    },
    {
      "x": 8,
      "y": 3,
      "z": 4,
      "name": "Rock_Stone"
    },
    {
      "x": 8,
      "y": 4,
      "z": 4,
      "name": "Rock_Stone"
    },
    {
      "x": 8,
      "y": 5,
      "z": 4,
      "name": "Rock_Stone"
    },
    {
      "x": 8,
      "y": 6,
      "z": 4,
      "name": "Rock_Stone"
    },
    {
      "x": 8,
      "y": 7,
      "z": 4,
      "name": "Rock_Stone"
    },
    {
      "x": 8,
      "y": 8,
      "z": 4,
      "name": "Rock_Stone"
    },
    {
      "x": 8,
      "y": 9,
      "z": 4,
      "name": "Rock_Stone"
    },
    {
      "x": 8,
      "y": 3,
      "z": 5,
      "name": "Rock_Stone"
    },
    {
      "x": 8,
      "y": 4,
      "z": 5,
      "name": "Rock_Stone"
    },
    {
      "x": 8,
      "y": 5,
      "z": 5,
      "name": "Rock_Stone"
    },
    {
      "x": 8,
      "y": 6,
      "z": 5,
      "name": "Rock_Stone"
    },
    {
      "x": 8,
      "y": 7,
      "z": 5,
      "name": "Rock_Stone"
    },
    {
      "x": 8,
      "y": 8,
      "z": 5,
      "name": "Rock_Stone"
    },
    {
      "x": 8,
      "y": 9,
      "z": 5,
      "name": "Rock_Stone"
    },
    {
      "x": 8,
      "y": 10,
      "z": 5,
      "name": "Rock_Stone"
    },
    {
      "x": 8,
      "y": 4,
      "z": 6,
      "name": "Rock_Stone"
    },
    {
      "x": 8,
      "y": 5,
      "z": 6,
      "name": "Rock_Stone"
    },
    {
      "x": 8,
      "y": 6,
      "z": 6,
      "name": "Rock_Stone"
    },
    {
      "x": 8,
      "y": 7,
      "z": 6,
      "name": "Rock_Stone"
    },
    {
      "x": 8,
      "y": 8,
      "z": 6,
      "name": "Rock_Stone"
    },
    {
      "x": 8,
      "y": 9,
      "z": 6,
      "name": "Rock_Stone"
    },
    {
      "x": 8,
      "y": 10,
      "z": 6,
      "name": "Soil_Gravel"
    },
    {
      "x": 8,
      "y": 7,
      "z": 7,
      "name": "Rock_Stone"
    },
    {
      "x": 8,
      "y": 8,
      "z": 7,
      "name": "Rock_Stone"
    },
    {
      "x": 8,
      "y": 9,
      "z": 7,
      "name": "Soil_Gravel"
    },
    {
      "x": 8,
      "y": 10,
      "z": 7,
      "name": "Rubble_Stone"
    },
    {
      "x": 9,
      "y": 6,
      "z": 1,
      "name": "Rock_Stone"
    },
    {
      "x": 9,
      "y": 7,
      "z": 1,
      "name": "Rock_Stone"
    },
    {
      "x": 9,
      "y": 8,
      "z": 1,
      "name": "Rubble_Stone"
    },
    {
      "x": 9,
      "y": 4,
      "z": 2,
      "name": "Rock_Stone"
    },
    {
      "x": 9,
      "y": 5,
      "z": 2,
      "name": "Rock_Stone"
    },
    {
      "x": 9,
      "y": 6,
      "z": 2,
      "name": "Rock_Stone"
    },
    {
      "x": 9,
      "y": 7,
      "z": 2,
      "name": "Rock_Stone"
    },
    {
      "x": 9,
      "y": 8,
      "z": 2,
      "name": "Rock_Stone"
    },
    {
      "x": 9,
      "y": 9,
      "z": 2,
      "name": "Rubble_Stone"
    },
    {
      "x": 9,
      "y": 3,
      "z": 3,
      "name": "Rock_Stone"
    },
    {
      "x": 9,
      "y": 4,
      "z": 3,
      "name": "Rock_Stone"
    },
    {
      "x": 9,
      "y": 5,
      "z": 3,
      "name": "Rock_Stone"
    },
    {
      "x": 9,
      "y": 6,
      "z": 3,
      "name": "Rock_Stone"
    },
    {
      "x": 9,
      "y": 7,
      "z": 3,
      "name": "Rock_Stone"
    },
    {
      "x": 9,
      "y": 8,
      "z": 3,
      "name": "Rock_Stone"
    },
    {
      "x": 9,
      "y": 9,
      "z": 3,
      "name": "Soil_Gravel"
    },
    {
      "x": 9,
      "y": 3,
      "z": 4,
      "name": "Rock_Stone"
    },
    {
      "x": 9,
      "y": 4,
      "z": 4,
      "name": "Rock_Stone"
    },
    {
      "x": 9,
      "y": 5,
      "z": 4,
      "name": "Rock_Stone"
    },
    {
      "x": 9,
      "y": 6,
      "z": 4,
      "name": "Rock_Stone"
    },
    {
      "x": 9,
      "y": 7,
      "z": 4,
      "name": "Rock_Stone"
    },
    {
      "x": 9,
      "y": 8,
      "z": 4,
      "name": "Rock_Stone"
    },
    {
      "x": 9,
      "y": 9,
      "z": 4,
      "name": "Rock_Stone"
    },
    {
      "x": 9,
      "y": 4,
      "z": 5,
      "name": "Rock_Stone"
    },
    {
      "x": 9,
      "y": 5,
      "z": 5,
      "name": "Rock_Stone"
    },
    {
      "x": 9,
      "y": 6,
      "z": 5,
      "name": "Rock_Stone"
    },
    {
      "x": 9,
      "y": 7,
      "z": 5,
      "name": "Rock_Stone"
    },
    {
      "x": 9,
      "y": 8,
      "z": 5,
      "name": "Rock_Stone"
    },
    {
      "x": 9,
      "y": 9,
      "z": 5,
      "name": "Rock_Stone_Mossy"
    },
    {
      "x": 9,
      "y": 10,
      "z": 5,
      "name": "Rubble_Stone"
    },
    {
      "x": 9,
      "y": 4,
      "z": 6,
      "name": "Rock_Stone"
    },
    {
      "x": 9,
      "y": 5,
      "z": 6,
      "name": "Rock_Stone"
    },
    {
      "x": 9,
      "y": 6,
      "z": 6,
      "name": "Rock_Stone"
    },
    {
      "x": 9,
      "y": 7,
      "z": 6,
      "name": "Rock_Stone"
    },
    {
      "x": 9,
      "y": 8,
      "z": 6,
      "name": "Rock_Stone"
    },
    {
      "x": 9,
      "y": 9,
      "z": 6,
      "name": "Soil_Gravel"
    },
    {
      "x": 10,
      "y": 4,
      "z": 2,
      "name": "Rock_Stone"
    },
    {
      "x": 10,
      "y": 5,
      "z": 2,
      "name": "Rock_Stone"
    },
    {
      "x": 10,
      "y": 6,
      "z": 2,
      "name": "Rock_Stone"
    },
    {
      "x": 10,
      "y": 7,
      "z": 2,
      "name": "Soil_Gravel"
    },
    {
      "x": 10,
      "y": 4,
      "z": 3,
      "name": "Rock_Stone"
    },
    {
      "x": 10,
      "y": 5,
      "z": 3,
      "name": "Rock_Stone"
    },
    {
      "x": 10,
      "y": 6,
      "z": 3,
      "name": "Rock_Stone"
    },
    {
      "x": 10,
      "y": 7,
      "z": 3,
      "name": "Soil_Gravel"
    },
    {
      "x": 10,
      "y": 8,
      "z": 3,
      "name": "Soil_Gravel"
    },
    {
      "x": 10,
      "y": 9,
      "z": 3,
      "name": "Rubble_Stone"
    },
    {
      "x": 10,
      "y": 4,
      "z": 4,
      "name": "Rock_Stone"
    },
    {
      "x": 10,
      "y": 5,
      "z": 4,
      "name": "Rock_Stone"
    },
    {
      "x": 10,
      "y": 6,
      "z": 4,
      "name": "Rock_Stone"
    },
    {
      "x": 10,
      "y": 7,
      "z": 4,
      "name": "Rock_Stone"
    },
    {
      "x": 10,
      "y": 8,
      "z": 4,
      "name": "Rock_Stone"
    },
    {
      "x": 10,
      "y": 9,
      "z": 4,
      "name": "Rock_Stone_Mossy"
    },
    {
      "x": 10,
      "y": 4,
      "z": 5,
      "name": "Rock_Stone"
    },
    {
      "x": 10,
      "y": 5,
      "z": 5,
      "name": "Rock_Stone"
    },
    {
      "x": 10,
      "y": 6,
      "z": 5,
      "name": "Rock_Stone"
    },
    {
      "x": 10,
      "y": 7,
      "z": 5,
      "name": "Rock_Stone"
    },
    {
      "x": 10,
      "y": 8,
      "z": 5,
      "name": "Rock_Stone"
    },
    {
      "x": 10,
      "y": 9,
      "z": 5,
      "name": "Rock_Stone_Mossy"
    },
    {
      "x": 10,
      "y": 5,
      "z": 6,
      "name": "Rock_Stone"
    },
    {
      "x": 10,
      "y": 6,
      "z": 6,
      "name": "Rock_Stone"
    },
    {
      "x": 10,
      "y": 7,
      "z": 6,
      "name": "Rock_Stone"
    },
    {
      "x": 10,
      "y": 8,
      "z": 6,
      "name": "Rock_Stone"
    },
    {
      "x": 11,
      "y": 5,
      "z": 3,
      "name": "Rock_Stone"
    },
    {
      "x": 11,
      "y": 6,
      "z": 3,
      "name": "Rock_Stone"
    },
    {
      "x": 11,
      "y": 7,
      "z": 3,
      "name": "Soil_Gravel"
    },
    {
      "x": 11,
      "y": 5,
      "z": 4,
      "name": "Rock_Stone"
    },
    {
      "x": 11,
      "y": 6,
      "z": 4,
      "name": "Rock_Stone"
    },
    {
      "x": 11,
      "y": 7,
      "z": 4,
      "name": "Soil_Gravel"
    },
    {
      "x": 11,
      "y": 8,
      "z": 4,
      "name": "Soil_Gravel"
    },
    {
      "x": 11,
      "y": 5,
      "z": 5,
      "name": "Rock_Stone"
    },
    {
      "x": 11,
      "y": 6,
      "z": 5,
      "name": "Rock_Stone"
    },
    {
      "x": 11,
      "y": 7,
      "z": 5,
      "name": "Rock_Stone"
    },
    {
      "x": 11,
      "y": 8,
      "z": 5,
      "name": "Rock_Stone"
    }
  ]
}