{
  "version": 8,
  "blockIdVersion": 8,
  "anchorX": 2,
  "anchorY": 38,
  "anchorZ": 10,
  "blocks": [
    {
      "x": -4,
      "y": 44,
      "z": -3,
      "name": "Rock_Volcanic"
    },
    {
      "x": -4,
      "y": 45,
      "z": -3,
      "name": "Rock_Volcanic"
    },
    {
      "x": -4,
      "y": 43,
      "z": -2,
      "name": "Rock_Volcanic"
    },
    {
      "x": -4,
      "y": 44,
      "z": -2,
      "name": "Rock_Volcanic"
    },
    {
      "x": -4,
      "y": 45,
      "z": -2,
      "name": "Rock_Volcanic"
    },
    {
      "x": -4,
      "y": 42,
      "z": -1,
      "name": "Rock_Volcanic"
    },
    {
      "x": -4,
      "y": 43,
      "z": -1,
      "name": "Rock_Volcanic"
    },
    {
      "x": -4,
      "y": 44,
      "z": -1,
      "name": "Rock_Volcanic"
    },
    {
      "x": -4,
      "y": 40,
      "z": 0,
      "name": "Rock_Volcanic"
    },
    {
      "x": -4,
      "y": 41,
      "z": 0,
      "name": "Rock_Volcanic"
    },
    {
      "x": -4,
      "y": 42,
      "z": 0,
      "name": "Rock_Volcanic"
    },
    {
      "x": -4,
      "y": 43,
      "z": 0,
      "name": "Rock_Volcanic"
    },
    {
      "x": -4,
      "y": 39,
      "z": 1,
      "name": "Rock_Volcanic"
    },
    {
      "x": -4,
      "y": 40,
      "z": 1,
      "name": "Rock_Volcanic"
    },
    {
      "x": -4,
      "y": 41,
      "z": 1,
      "name": "Rock_Volcanic"
    },
    {
      "x": -4,
      "y": 42,
      "z": 1,
      "name": "Rock_Volcanic"
    },
    {
      "x": -4,
      "y": 43,
      "z": 1,
      "name": "Rock_Volcanic"
    },
    {
      "x": -4,
      "y": 38,
      "z": 2,
      "name": "Rock_Volcanic"
    },
    {
      "x": -4,
      "y": 39,
      "z": 2,
      "name": "Rock_Volcanic"
    },
    {
      "x": -4,
      "y": 40,
      "z": 2,
      "name": "Rock_Volcanic"
    },
    {
      "x": -4,
      "y": 41,
      "z": 2,
      "name": "Rock_Volcanic"
    },
    {
      "x": -4,
      "y": 35,
      "z": 3,
      "name": "Rock_Volcanic"
    },
    {
      "x": -4,
      "y": 36,
      "z": 3,
      "name": "Rock_Volcanic"
    },
    {
      "x": -4,
      "y": 37,
      "z": 3,
      "name": "Rock_Volcanic"
    },
    {
      "x": -4,
      "y": 38,
      "z": 3,
      "name": "Rock_Volcanic"
    },
    {
      "x": -4,
      "y": 39,
      "z": 3,
      "name": "Rock_Volcanic"
    },
    {
      "x": -4,
      "y": 40,
      "z": 3,
      "name": "Rock_Volcanic"
    },
    {
      "x": -4,
      "y": 41,
      "z": 3,
      "name": "Rock_Volcanic"
    },
    {
      "x": -4,
      "y": 34,
      "z": 4,
      "name": "Rock_Volcanic"
    },
    {
      "x": -4,
      "y": 35,
      "z": 4,
      "name": "Rock_Volcanic"
    },
    {
      "x": -4,
      "y": 36,
      "z": 4,
      "name": "Rock_Volcanic"
    },
    {
      "x": -4,
      "y": 37,
      "z": 4,
      "name": "Rock_Volcanic"
    },
    {
      "x": -4,
      "y": 38,
      "z": 4,
      "name": "Rock_Volcanic"
    },
    {
      "x": -4,
      "y": 39,
      "z": 4,
      "name": "Rock_Volcanic"
    },
    {
      "x": -4,
      "y": 40,
      "z": 4,
      "name": "Rock_Volcanic"
    },
    {
      "x": -4,
      "y": 35,
      "z": 5,
      "name": "Rock_Volcanic"
    },
    {
      "x": -4,
      "y": 36,
      "z": 5,
      "name": "Rock_Volcanic"
    },
    {
      "x": -4,
      "y": 37,
      "z": 5,
      "name": "Rock_Volcanic"
    },
    {
      "x": -4,
      "y": 38,
      "z": 5,
      "name": "Rock_Volcanic"
    },
    {
      "x": -3,
      "y": 46,
      "z": -4,
      "name": "Rock_Volcanic"
    },
    {
      "x": -3,
      "y": 43,
      "z": -3,
      "name": "Rock_Volcanic"
    },
    {
      "x": -3,
      "y": 44,
      "z": -3,
      "name": "Rock_Volcanic"
    },
    {
      "x": -3,
      "y": 45,
      "z": -3,
      "name": "Rock_Volcanic"
    },
    {
      "x": -3,
      "y": 46,
      "z": -3,
      "name": "Rock_Volcanic_Cracked_Lava"
    },
    {
      "x": -3,
      "y": 47,
      "z": -3,
      "name": "Rock_Volcanic_Cracked_Lava"
    },
    {
      "x": -3,
      "y": 41,
      "z": -2,
      "name": "Rock_Volcanic"
    },
    {
      "x": -3,
      "y": 42,
      "z": -2,
      "name": "Rock_Volcanic"
    },
    {
      "x": -3,
      "y": 43,
      "z": -2,
      "name": "Rock_Volcanic"
    },
    {
      "x": -3,
      "y": 44,
      "z": -2,
      "name": "Rock_Volcanic"
    },
    {
      "x": -3,
      "y": 45,
      "z": -2,
      "name": "Rock_Volcanic"
    },
    {
      "x": -3,
      "y": 46,
      "z": -2,
      "name": "Rock_Volcanic_Cracked_Lava"
    },
    {
      "x": -3,
      "y": 39,
      "z": -1,
      "name": "Rock_Volcanic"
    },
    {
      "x": -3,
      "y": 40,
      "z": -1,
      "name": "Rock_Volcanic"
    },
    {
      "x": -3,
      "y": 41,
      "z": -1,
      "name": "Rock_Volcanic"
    },
    {
      "x": -3,
      "y": 42,
      "z": -1,
      "name": "Rock_Volcanic"
    },
    {
      "x": -3,
      "y": 43,
      "z": -1,
      "name": "Rock_Volcanic"
    },
    {
      "x": -3,
      "y": 44,
      "z": -1,
      "name": "Rock_Volcanic"
    },
    {
      "x": -3,
      "y": 45,
      "z": -1,
      "name": "Rock_Volcanic"
    },
    {
      "x": -3,
      "y": 46,
      "z": -1,
      "name": "Rock_Volcanic_Cracked_Lava"
    },
    {
      "x": -3,
      "y": 38,
      "z": 0,
      "name": "Rock_Volcanic"
    },
    {
      "x": -3,
      "y": 39,
      "z": 0,
      "name": "Rock_Volcanic"
    },
    {
      "x": -3,
      "y": 40,
      "z": 0,
      "name": "Rock_Volcanic"
    },
    {
      "x": -3,
      "y": 41,
      "z": 0,
      "name": "Rock_Volcanic"
    },
    {
      "x": -3,
      "y": 42,
      "z": 0,
      "name": "Rock_Volcanic"
    },
    {
      "x": -3,
      "y": 43,
      "z": 0,
      "name": "Rock_Volcanic"
    },
    {
      "x": -3,
      "y": 44,
      "z": 0,
      "name": "Rock_Volcanic_Cracked_Lava"
    },
    {
      "x": -3,
      "y": 45,
      "z": 0,
      "name": "Rock_Volcanic"
    },
    {
      "x": -3,
      "y": 37,
      "z": 1,
      "name": "Rock_Volcanic"
    },
    {
      "x": -3,
      "y": 38,
      "z": 1,
      "name": "Rock_Volcanic"
    },
    {
      "x": -3,
      "y": 39,
      "z": 1,
      "name": "Rock_Volcanic"
    },
    {
      "x": -3,
      "y": 40,
      "z": 1,
      "name": "Rock_Volcanic"
    },
    {
      "x": -3,
      "y": 41,
      "z": 1,
      "name": "Rock_Volcanic"
    },
    {
      "x": -3,
      "y": 42,
      "z": 1,
      "name": "Rock_Volcanic"
    },
    {
      "x": -3,
      "y": 43,
      "z": 1,
      "name": "Rock_Volcanic_Cracked_Lava"
    },
    {
      "x": -3,
      "y": 44,
      "z": 1,
      "name": "Rock_Volcanic_Cracked_Lava"
    },
    {
      "x": -3,
      "y": 36,
      "z": 2,
      "name": "Rock_Volcanic"
    },
    {
      "x": -3,
      "y": 37,
      "z": 2,
      "name": "Rock_Volcanic"
    },
    {
      "x": -3,
      "y": 38,
      "z": 2,
      "name": "Rock_Volcanic"
    },
    {
      "x": -3,
      "y": 39,
      "z": 2,
      "name": "Rock_Volcanic"
    },
    {
      "x": -3,
      "y": 40,
      "z": 2,
      "name": "Rock_Volcanic"
    },
    {
      "x": -3,
      "y": 41,
      "z": 2,
      "name": "Rock_Volcanic"
    },
    {
      "x": -3,
      "y": 42,
      "z": 2,
      "name": "Rock_Volcanic"
    },
    {
      "x": -3,
      "y": 43,
      "z": 2,
      "name": "Rock_Volcanic_Cracked_Lava"
    },
    {
      "x": -3,
      "y": 34,
      "z": 3,
      "name": "Rock_Volcanic"
    },
    {
      "x": -3,
      "y": 35,
      "z": 3,
      "name": "Rock_Volcanic"
    },
    {
      "x": -3,
      "y": 36,
      "z": 3,
      "name": "Rock_Volcanic"
    },
    {
      "x": -3,
      "y": 37,
      "z": 3,
      "name": "Rock_Volcanic"
    },
    {
      "x": -3,
      "y": 38,
      "z": 3,
      "name": "Rock_Volcanic"
    },
    {
      "x": -3,
      "y": 39,
      "z": 3,
      "name": "Rock_Volcanic"
    },
    {
      "x": -3,
      "y": 40,
      "z": 3,
      "name": "Rock_Volcanic"
    },
    {
      "x": -3,
      "y": 41,
      "z": 3,
      "name": "Rock_Volcanic"
    },
    {
      "x": -3,
      "y": 42,
      "z": 3,
      "name": "Rock_Volcanic"
    },
    {
      "x": -3,
      "y": 33,
      "z": 4,
      "name": "Rock_Volcanic"
    },
    {
      "x": -3,
      "y": 34,
      "z": 4,
      "name": "Rock_Volcanic"
    },
    {
      "x": -3,
      "y": 35,
      "z": 4,
      "name": "Rock_Volcanic"
    },
    {
      "x": -3,
      "y": 36,
      "z": 4,
      "name": "Rock_Volcanic"
    },
    {
      "x": -3,
      "y": 37,
      "z": 4,
      "name": "Rock_Volcanic"
    },
    {
      "x": -3,
      "y": 38,
      "z": 4,
      "name": "Rock_Volcanic"
    },
    {
      "x": -3,
      "y": 39,
      "z": 4,
      "name": "Rock_Volcanic"
    },
    {
      "x": -3,
      "y": 40,
      "z": 4,
      "name": "Rock_Volcanic"
    },
    {
      "x": -3,
      "y": 41,
      "z": 4,
      "name": "Rock_Volcanic"
    },
    {
      "x": -3,
      "y": 42,
      "z": 4,
      "name": "Rock_Volcanic"
    },
    {
      "x": -3,
      "y": 31,
      "z": 5,
      "name": "Rock_Volcanic"
    },
    {
      "x": -3,
      "y": 32,
      "z": 5,
      "name": "Rock_Volcanic"
    },
    {
      "x": -3,
      "y": 33,
      "z": 5,
      "name": "Rock_Volcanic"
    },
    {
      "x": -3,
      "y": 34,
      "z": 5,
      "name": "Rock_Volcanic"
    },
    {
      "x": -3,
      "y": 35,
      "z": 5,
      "name": "Rock_Volcanic"
    },
    {
      "x": -3,
      "y": 36,
      "z": 5,
      "name": "Rock_Volcanic"
    },
    {
      "x": -3,
      "y": 37,
      "z": 5,
      "name": "Rock_Volcanic"
    },
    {
      "x": -3,
      "y": 38,
      "z": 5,
      "name": "Rock_Volcanic"
    },
    {
      "x": -3,
      "y": 39,
      "z": 5,
      "name": "Rock_Volcanic"
    },
    {
      "x": -3,
      "y": 40,
      "z": 5,
      "name": "Rock_Volcanic"
    },
    {
      "x": -3,
      "y": 30,
      "z": 6,
      "name": "Rock_Volcanic"
    },
    {
      "x": -3,
      "y": 31,
      "z": 6,
      "name": "Rock_Volcanic"
    },
    {
      "x": -3,
      "y": 32,
      "z": 6,
      "name": "Rock_Volcanic"
    },
    {
      "x": -3,
      "y": 33,
      "z": 6,
      "name": "Rock_Volcanic"
    },
    {
      "x": -3,
      "y": 34,
      "z": 6,
      "name": "Rock_Volcanic"
    },
    {
      "x": -3,
      "y": 35,
      "z": 6,
      "name": "Rock_Volcanic"
    },
    {
      "x": -3,
      "y": 36,
      "z": 6,
      "name": "Rock_Volcanic"
    },
    {
      "x": -3,
      "y": 37,
      "z": 6,
      "name": "Rock_Volcanic"
    },
    {
      "x": -3,
      "y": 38,
      "z": 6,
      "name": "Rock_Volcanic"
    },
    {
      "x": -3,
      "y": 39,
      "z": 6,
      "name": "Rock_Volcanic"
    },
    {
      "x": -3,
      "y": 30,
      "z": 7,
      "name": "Rock_Volcanic"
    },
    {
      "x": -3,
      "y": 31,
      "z": 7,
      "name": "Rock_Volcanic"
    },
    {
      "x": -3,
      "y": 32,
      "z": 7,
      "name": "Rock_Volcanic"
    },
    {
      "x": -3,
      "y": 33,
      "z": 7,
      "name": "Rock_Volcanic"
    },
    {
      "x": -3,
      "y": 34,
      "z": 7,
      "name": "Rock_Volcanic"
    },
    {
      "x": -3,
      "y": 35,
      "z": 7,
      "name": "Rock_Volcanic"
    },
    {
      "x": -3,
      "y": 36,
      "z": 7,
      "name": "Rock_Volcanic"
    },
    {
      "x": -3,
      "y": 37,
      "z": 7,
      "name": "Rock_Volcanic"
    },
    {
      "x": -3,
      "y": 29,
      "z": 8,
      "name": "Rock_Volcanic"
    },
    {
      "x": -3,
      "y": 30,
      "z": 8,
      "name": "Rock_Volcanic"
    },
    {
      "x": -3,
      "y": 31,
      "z": 8,
      "name": "Rock_Volcanic"
    },
    {
      "x": -3,
      "y": 32,
      "z": 8,
      "name": "Rock_Volcanic"
    },
    {
      "x": -3,
      "y": 33,
      "z": 8,
      "name": "Rock_Volcanic"
    },
    {
      "x": -3,
      "y": 34,
      "z": 8,
      "name": "Rock_Volcanic"
    },
    {
      "x": -3,
      "y": 35,
      "z": 8,
      "name": "Rock_Volcanic"
    },
    {
      "x": -3,
      "y": 29,
      "z": 9,
      "name": "Rock_Volcanic"
    },
    {
      "x": -3,
      "y": 30,
      "z": 9,
      "name": "Rock_Volcanic"
    },
    {
      "x": -3,
      "y": 31,
      "z": 9,
      "name": "Rock_Volcanic"
    },
    {
      "x": -3,
      "y": 32,
      "z": 9,
      "name": "Rock_Volcanic"
    },
    {
      "x": -3,
      "y": 33,
      "z": 9,
      "name": "Rock_Volcanic"
    },
    {
      "x": -3,
      "y": 34,
      "z": 9,
      "name": "Rock_Volcanic"
    },
    {
      "x": -3,
      "y": 29,
      "z": 10,
      "name": "Rock_Volcanic"
    },
    {
      "x": -3,
      "y": 30,
      "z": 10,
      "name": "Rock_Volcanic"
    },
    {
      "x": -3,
      "y": 31,
      "z": 10,
      "name": "Rock_Volcanic"
    },
    {
      "x": -3,
      "y": 32,
      "z": 10,
      "name": "Rock_Volcanic"
    },
    {
      "x": -3,
      "y": 33,
      "z": 10,
      "name": "Rock_Volcanic"
    },
    {
      "x": -3,
      "y": 30,
      "z": 11,
      "name": "Rock_Volcanic"
    },
    {
      "x": -3,
      "y": 31,
      "z": 11,
      "name": "Rock_Volcanic"
    },
    {
      "x": -2,
      "y": 49,
      "z": -7,
      "name": "Rock_Volcanic"
    },
    {
      "x": -2,
      "y": 50,
      "z": -7,
      "name": "Rock_Volcanic"
    },
    {
      "x": -2,
      "y": 46,
      "z": -6,
      "name": "Rock_Volcanic"
    },
    {
      "x": -2,
      "y": 47,
      "z": -6,
      "name": "Rock_Volcanic"
    },
    {
      "x": -2,
      "y": 48,
      "z": -6,
      "name": "Rock_Volcanic"
    },
    {
      "x": -2,
      "y": 49,
      "z": -6,
      "name": "Rock_Volcanic"
    },
    {
      "x": -2,
      "y": 50,
      "z": -6,
      "name": "Rock_Volcanic"
    },
    {
      "x": -2,
      "y": 51,
      "z": -6,
      "name": "Rock_Volcanic"
    },
    {
      "x": -2,
      "y": 44,
      "z": -5,
      "name": "Rock_Volcanic"
    },
    {
      "x": -2,
      "y": 45,
      "z": -5,
      "name": "Rock_Volcanic"
    },
    {
      "x": -2,
      "y": 46,
      "z": -5,
      "name": "Rock_Volcanic"
    },
    {
      "x": -2,
      "y": 47,
      "z": -5,
      "name": "Rock_Volcanic"
    },
    {
      "x": -2,
      "y": 48,
      "z": -5,
      "name": "Rock_Volcanic"
    },
    {
      "x": -2,
      "y": 49,
      "z": -5,
      "name": "Rock_Volcanic"
    },
    {
      "x": -2,
      "y": 50,
      "z": -5,
      "name": "Rock_Volcanic"
    },
    {
      "x": -2,
      "y": 51,
      "z": -5,
      "name": "Rock_Volcanic"
    },
    {
      "x": -2,
      "y": 44,
      "z": -4,
      "name": "Rock_Volcanic"
    },
    {
      "x": -2,
      "y": 45,
      "z": -4,
      "name": "Rock_Volcanic"
    },
    {
      "x": -2,
      "y": 46,
      "z": -4,
      "name": "Rock_Volcanic"
    },
    {
      "x": -2,
      "y": 47,
      "z": -4,
      "name": "Rock_Volcanic_Cracked_Lava"
    },
    {
      "x": -2,
      "y": 48,
      "z": -4,
      "name": "Rock_Volcanic"
    },
    {
      "x": -2,
      "y": 49,
      "z": -4,
      "name": "Rock_Volcanic"
    },
    {
      "x": -2,
      "y": 50,
      "z": -4,
      "name": "Rock_Volcanic"
    },
    {
      "x": -2,
      "y": 42,
      "z": -3,
      "name": "Rock_Volcanic"
    },
    {
      "x": -2,
      "y": 43,
      "z": -3,
      "name": "Rock_Volcanic"
    },
    {
      "x": -2,
      "y": 44,
      "z": -3,
      "name": "Rock_Volcanic"
    },
    {
      "x": -2,
      "y": 45,
      "z": -3,
      "name": "Rock_Volcanic"
    },
    {
      "x": -2,
      "y": 46,
      "z": -3,
      "name": "Rock_Volcanic_Cracked_Lava"
    },
    {
      "x": -2,
      "y": 47,
      "z": -3,
      "name": "Rock_Volcanic_Cracked_Lava"
    },
    {
      "x": -2,
      "y": 48,
      "z": -3,
      "name": "Rock_Volcanic_Cracked_Lava"
    },
    {
      "x": -2,
      "y": 49,
      "z": -3,
      "name": "Rock_Volcanic"
    },
    {
      "x": -2,
      "y": 40,
      "z": -2,
      "name": "Rock_Volcanic"
    },
    {
      "x": -2,
      "y": 41,
      "z": -2,
      "name": "Rock_Volcanic"
    },
    {
      "x": -2,
      "y": 42,
      "z": -2,
      "name": "Rock_Volcanic"
    },
    {
      "x": -2,
      "y": 43,
      "z": -2,
      "name": "Rock_Volcanic"
    },
    {
      "x": -2,
      "y": 44,
      "z": -2,
      "name": "Rock_Volcanic"
    },
    {
      "x": -2,
      "y": 45,
      "z": -2,
      "name": "Rock_Volcanic"
    },
    {
      "x": -2,
      "y": 46,
      "z": -2,
      "name": "Rock_Volcanic_Cracked_Lava"
    },
    {
      "x": -2,
      "y": 47,
      "z": -2,
      "name": "Rock_Volcanic_Cracked_Lava"
    },
    {
      "x": -2,
      "y": 48,
      "z": -2,
      "name": "Rock_Volcanic_Cracked_Lava"
    },
    {
      "x": -2,
      "y": 38,
      "z": -1,
      "name": "Rock_Volcanic"
    },
    {
      "x": -2,
      "y": 39,
      "z": -1,
      "name": "Rock_Volcanic"
    },
    {
      "x": -2,
      "y": 40,
      "z": -1,
      "name": "Rock_Volcanic"
    },
    {
      "x": -2,
      "y": 41,
      "z": -1,
      "name": "Rock_Volcanic"
    },
    {
      "x": -2,
      "y": 42,
      "z": -1,
      "name": "Rock_Volcanic"
    },
    {
      "x": -2,
      "y": 43,
      "z": -1,
      "name": "Rock_Volcanic"
    },
    {
      "x": -2,
      "y": 44,
      "z": -1,
      "name": "Rock_Volcanic"
    },
    {
      "x": -2,
      "y": 45,
      "z": -1,
      "name": "Rock_Volcanic"
    },
    {
      "x": -2,
      "y": 46,
      "z": -1,
      "name": "Rock_Volcanic_Cracked_Lava"
    },
    {
      "x": -2,
      "y": 37,
      "z": 0,
      "name": "Rock_Volcanic"
    },
    {
      "x": -2,
      "y": 38,
      "z": 0,
      "name": "Rock_Volcanic"
    },
    {
      "x": -2,
      "y": 39,
      "z": 0,
      "name": "Rock_Volcanic"
    },
    {
      "x": -2,
      "y": 40,
      "z": 0,
      "name": "Rock_Volcanic"
    },
    {
      "x": -2,
      "y": 41,
      "z": 0,
      "name": "Rock_Volcanic"
    },
    {
      "x": -2,
      "y": 42,
      "z": 0,
      "name": "Rock_Volcanic"
    },
    {
      "x": -2,
      "y": 43,
      "z": 0,
      "name": "Rock_Volcanic"
    },
    {
      "x": -2,
      "y": 44,
      "z": 0,
      "name": "Rock_Volcanic_Cracked_Lava"
    },
    {
      "x": -2,
      "y": 45,
      "z": 0,
      "name": "Rock_Volcanic_Cracked_Lava"
    },
    {
      "x": -2,
      "y": 46,
      "z": 0,
      "name": "Rock_Volcanic"
    },
    {
      "x": -2,
      "y": 36,
      "z": 1,
      "name": "Rock_Volcanic"
    },
    {
      "x": -2,
      "y": 37,
      "z": 1,
      "name": "Rock_Volcanic"
    },
    {
      "x": -2,
      "y": 38,
      "z": 1,
      "name": "Rock_Volcanic"
    },
    {
      "x": -2,
      "y": 39,
      "z": 1,
      "name": "Rock_Volcanic"
    },
    {
      "x": -2,
      "y": 40,
      "z": 1,
      "name": "Rock_Volcanic"
    },
    {
      "x": -2,
      "y": 41,
      "z": 1,
      "name": "Rock_Volcanic"
    },
    {
      "x": -2,
      "y": 42,
      "z": 1,
      "name": "Rock_Volcanic"
    },
    {
      "x": -2,
      "y": 43,
      "z": 1,
      "name": "Rock_Volcanic_Cracked_Lava"
    },
    {
      "x": -2,
      "y": 44,
      "z": 1,
      "name": "Rock_Volcanic_Cracked_Lava"
    },
    {
      "x": -2,
      "y": 45,
      "z": 1,
      "name": "Rock_Volcanic_Cracked_Lava"
    },
    {
      "x": -2,
      "y": 34,
      "z": 2,
      "name": "Rock_Volcanic"
    },
    {
      "x": -2,
      "y": 35,
      "z": 2,
      "name": "Rock_Volcanic"
    },
    {
      "x": -2,
      "y": 36,
      "z": 2,
      "name": "Rock_Volcanic"
    },
    {
      "x": -2,
      "y": 37,
      "z": 2,
      "name": "Rock_Volcanic"
    },
    {
      "x": -2,
      "y": 38,
      "z": 2,
      "name": "Rock_Volcanic"
    },
    {
      "x": -2,
      "y": 39,
      "z": 2,
      "name": "Rock_Volcanic"
    },
    {
      "x": -2,
      "y": 40,
      "z": 2,
      "name": "Rock_Volcanic"
    },
    {
      "x": -2,
      "y": 41,
      "z": 2,
      "name": "Rock_Volcanic"
    },
    {
      "x": -2,
      "y": 42,
      "z": 2,
      "name": "Rock_Volcanic"
    },
    {
      "x": -2,
      "y": 43,
      "z": 2,
      "name": "Rock_Volcanic_Cracked_Lava"
    },
    {
      "x": -2,
      "y": 44,
      "z": 2,
      "name": "Rock_Volcanic_Cracked_Lava"
    },
    {
      "x": -2,
      "y": 45,
      "z": 2,
      "name": "Rock_Volcanic_Cracked_Lava"
    },
    {
      "x": -2,
      "y": 33,
      "z": 3,
      "name": "Rock_Volcanic"
    },
    {
      "x": -2,
      "y": 34,
      "z": 3,
      "name": "Rock_Volcanic"
    },
    {
      "x": -2,
      "y": 35,
      "z": 3,
      "name": "Rock_Volcanic"
    },
    {
      "x": -2,
      "y": 36,
      "z": 3,
      "name": "Rock_Volcanic"
    },
    {
      "x": -2,
      "y": 37,
      "z": 3,
      "name": "Rock_Volcanic"
    },
    {
      "x": -2,
      "y": 38,
      "z": 3,
      "name": "Rock_Volcanic"
    },
    {
      "x": -2,
      "y": 39,
      "z": 3,
      "name": "Rock_Volcanic"
    },
    {
      "x": -2,
      "y": 40,
      "z": 3,
      "name": "Rock_Volcanic"
    },
    {
      "x": -2,
      "y": 41,
      "z": 3,
      "name": "Rock_Volcanic"
    },
    {
      "x": -2,
      "y": 42,
      "z": 3,
      "name": "Rock_Volcanic"
    },
    {
      "x": -2,
      "y": 43,
      "z": 3,
      "name": "Rock_Volcanic_Cracked_Lava"
    },
    {
      "x": -2,
      "y": 31,
      "z": 4,
      "name": "Rock_Volcanic"
    },
    {
      "x": -2,
      "y": 32,
      "z": 4,
      "name": "Rock_Volcanic"
    },
    {
      "x": -2,
      "y": 33,
      "z": 4,
      "name": "Rock_Volcanic"
    },
    {
      "x": -2,
      "y": 34,
      "z": 4,
      "name": "Rock_Volcanic"
    },
    {
      "x": -2,
      "y": 35,
      "z": 4,
      "name": "Rock_Volcanic"
    },
    {
      "x": -2,
      "y": 36,
      "z": 4,
      "name": "Rock_Volcanic"
    },
    {
      "x": -2,
      "y": 37,
      "z": 4,
      "name": "Rock_Volcanic"
    },
    {
      "x": -2,
      "y": 38,
      "z": 4,
      "name": "Rock_Volcanic"
    },
    {
      "x": -2,
      "y": 39,
      "z": 4,
      "name": "Rock_Volcanic"
    },
    {
      "x": -2,
      "y": 40,
      "z": 4,
      "name": "Rock_Volcanic"
    },
    {
      "x": -2,
      "y": 41,
      "z": 4,
      "name": "Rock_Volcanic"
    },
    {
      "x": -2,
      "y": 42,
      "z": 4,
      "name": "Rock_Volcanic"
    },
    {
      "x": -2,
      "y": 31,
      "z": 5,
      "name": "Rock_Volcanic"
    },
    {
      "x": -2,
      "y": 32,
      "z": 5,
      "name": "Rock_Volcanic"
    },
    {
      "x": -2,
      "y": 33,
      "z": 5,
      "name": "Rock_Volcanic"
    },
    {
      "x": -2,
      "y": 34,
      "z": 5,
      "name": "Rock_Volcanic"
    },
    {
      "x": -2,
      "y": 35,
      "z": 5,
      "name": "Rock_Volcanic"
    },
    {
      "x": -2,
      "y": 36,
      "z": 5,
      "name": "Rock_Volcanic"
    },
    {
      "x": -2,
      "y": 37,
      "z": 5,
      "name": "Rock_Volcanic"
    },
    {
      "x": -2,
      "y": 38,
      "z": 5,
      "name": "Rock_Volcanic"
    },
    {
      "x": -2,
      "y": 39,
      "z": 5,
      "name": "Rock_Volcanic"
    },
    {
      "x": -2,
      "y": 40,
      "z": 5,
      "name": "Rock_Volcanic"
    },
    {
      "x": -2,
      "y": 41,
      "z": 5,
      "name": "Rock_Volcanic"
    },
    {
      "x": -2,
      "y": 30,
      "z": 6,
      "name": "Rock_Volcanic"
    },
    {
      "x": -2,
      "y": 31,
      "z": 6,
      "name": "Rock_Volcanic"
    },
    {
      "x": -2,
      "y": 32,
      "z": 6,
      "name": "Rock_Volcanic"
    },
    {
      "x": -2,
      "y": 33,
      "z": 6,
      "name": "Rock_Volcanic"
    },
    {
      "x": -2,
      "y": 34,
      "z": 6,
      "name": "Rock_Volcanic"
    },
    {
      "x": -2,
      "y": 35,
      "z": 6,
      "name": "Rock_Volcanic"
    },
    {
      "x": -2,
      "y": 36,
      "z": 6,
      "name": "Rock_Volcanic"
    },
    {
      "x": -2,
      "y": 37,
      "z": 6,
      "name": "Rock_Volcanic"
    },
    {
      "x": -2,
      "y": 38,
      "z": 6,
      "name": "Rock_Volcanic"
    },
    {
      "x": -2,
      "y": 39,
      "z": 6,
      "name": "Rock_Volcanic"
    },
    {
      "x": -2,
      "y": 40,
      "z": 6,
      "name": "Rock_Volcanic"
    },
    {
      "x": -2,
      "y": 29,
      "z": 7,
      "name": "Rock_Volcanic"
    },
    {
      "x": -2,
      "y": 30,
      "z": 7,
      "name": "Rock_Volcanic"
    },
    {
      "x": -2,
      "y": 31,
      "z": 7,
      "name": "Rock_Volcanic"
    },
    {
      "x": -2,
      "y": 32,
      "z": 7,
      "name": "Rock_Volcanic"
    },
    {
      "x": -2,
      "y": 33,
      "z": 7,
      "name": "Rock_Volcanic"
    },
    {
      "x": -2,
      "y": 34,
      "z": 7,
      "name": "Rock_Volcanic"
    },
    {
      "x": -2,
      "y": 35,
      "z": 7,
      "name": "Rock_Volcanic"
    },
    {
      "x": -2,
      "y": 36,
      "z": 7,
      "name": "Rock_Volcanic"
    },
    {
      "x": -2,
      "y": 37,
      "z": 7,
      "name": "Rock_Volcanic"
    },
    {
      "x": -2,
      "y": 38,
      "z": 7,
      "name": "Rock_Volcanic"
    },
    {
      "x": -2,
      "y": 39,
      "z": 7,
      "name": "Rock_Volcanic"
    },
    {
      "x": -2,
      "y": 28,
      "z": 8,
      "name": "Rock_Volcanic"
    },
    {
      "x": -2,
      "y": 29,
      "z": 8,
      "name": "Rock_Volcanic"
    },
    {
      "x": -2,
      "y": 30,
      "z": 8,
      "name": "Rock_Volcanic"
    },
    {
      "x": -2,
      "y": 31,
      "z": 8,
      "name": "Rock_Volcanic"
    },
    {
      "x": -2,
      "y": 32,
      "z": 8,
      "name": "Rock_Volcanic"
    },
    {
      "x": -2,
      "y": 33,
      "z": 8,
      "name": "Rock_Volcanic"
    },
    {
      "x": -2,
      "y": 34,
      "z": 8,
      "name": "Rock_Volcanic"
    },
    {
      "x": -2,
      "y": 35,
      "z": 8,
      "name": "Rock_Volcanic"
    },
    {
      "x": -2,
      "y": 36,
      "z": 8,
      "name": "Rock_Volcanic"
    },
    {
      "x": -2,
      "y": 37,
      "z": 8,
      "name": "Rock_Volcanic"
    },
    {
      "x": -2,
      "y": 38,
      "z": 8,
      "name": "Rock_Volcanic"
    },
    {
      "x": -2,
      "y": 28,
      "z": 9,
      "name": "Rock_Volcanic"
    },
    {
      "x": -2,
      "y": 29,
      "z": 9,
      "name": "Rock_Volcanic"
    },
    {
      "x": -2,
      "y": 30,
      "z": 9,
      "name": "Rock_Volcanic"
    },
    {
      "x": -2,
      "y": 31,
      "z": 9,
      "name": "Rock_Volcanic"
    },
    {
      "x": -2,
      "y": 32,
      "z": 9,
      "name": "Rock_Volcanic"
    },
    {
      "x": -2,
      "y": 33,
      "z": 9,
      "name": "Rock_Volcanic"
    },
    {
      "x": -2,
      "y": 34,
      "z": 9,
      "name": "Rock_Volcanic"
    },
    {
      "x": -2,
      "y": 35,
      "z": 9,
      "name": "Rock_Volcanic"
    },
    {
      "x": -2,
      "y": 26,
      "z": 10,
      "name": "Rock_Volcanic"
    },
    {
      "x": -2,
      "y": 27,
      "z": 10,
      "name": "Rock_Volcanic"
    },
    {
      "x": -2,
      "y": 28,
      "z": 10,
      "name": "Rock_Volcanic"
    },
    {
      "x": -2,
      "y": 29,
      "z": 10,
      "name": "Rock_Volcanic"
    },
    {
      "x": -2,
      "y": 30,
      "z": 10,
      "name": "Rock_Volcanic"
    },
    {
      "x": -2,
      "y": 31,
      "z": 10,
      "name": "Rock_Volcanic"
    },
    {
      "x": -2,
      "y": 32,
      "z": 10,
      "name": "Rock_Volcanic"
    },
    {
      "x": -2,
      "y": 33,
      "z": 10,
      "name": "Rock_Volcanic"
    },
    {
      "x": -2,
      "y": 34,
      "z": 10,
      "name": "Rock_Volcanic"
    },
    {
      "x": -2,
      "y": 26,
      "z": 11,
      "name": "Rock_Volcanic"
    },
    {
      "x": -2,
      "y": 27,
      "z": 11,
      "name": "Rock_Volcanic"
    },
    {
      "x": -2,
      "y": 28,
      "z": 11,
      "name": "Rock_Volcanic"
    },
    {
      "x": -2,
      "y": 29,
      "z": 11,
      "name": "Rock_Volcanic"
    },
    {
      "x": -2,
      "y": 30,
      "z": 11,
      "name": "Rock_Volcanic"
    },
    {
      "x": -2,
      "y": 31,
      "z": 11,
      "name": "Rock_Volcanic"
    },
    {
      "x": -2,
      "y": 32,
      "z": 11,
      "name": "Rock_Volcanic"
    },
    {
      "x": -2,
      "y": 33,
      "z": 11,
      "name": "Rock_Volcanic"
    },
    {
      "x": -2,
      "y": 25,
      "z": 12,
      "name": "Rock_Volcanic"
    },
    {
      "x": -2,
      "y": 26,
      "z": 12,
      "name": "Rock_Volcanic"
    },
    {
      "x": -2,
      "y": 27,
      "z": 12,
      "name": "Rock_Volcanic"
    },
    {
      "x": -2,
      "y": 28,
      "z": 12,
      "name": "Rock_Volcanic"
    },
    {
      "x": -2,
      "y": 29,
      "z": 12,
      "name": "Rock_Volcanic"
    },
    {
      "x": -2,
      "y": 30,
      "z": 12,
      "name": "Rock_Volcanic"
    },
    {
      "x": -2,
      "y": 31,
      "z": 12,
      "name": "Rock_Volcanic"
    },
    {
      "x": -2,
      "y": 32,
      "z": 12,
      "name": "Rock_Volcanic"
    },
    {
      "x": -2,
      "y": 33,
      "z": 12,
      "name": "Rock_Volcanic"
    },
    {
      "x": -2,
      "y": 24,
      "z": 13,
      "name": "Rock_Volcanic"
    },
    {
      "x": -2,
      "y": 25,
      "z": 13,
      "name": "Rock_Volcanic"
    },
    {
      "x": -2,
      "y": 26,
      "z": 13,
      "name": "Rock_Volcanic"
    },
    {
      "x": -2,
      "y": 27,
      "z": 13,
      "name": "Rock_Volcanic"
    },
    {
      "x": -2,
      "y": 28,
      "z": 13,
      "name": "Rock_Volcanic"
    },
    {
      "x": -2,
      "y": 29,
      "z": 13,
      "name": "Rock_Volcanic"
    },
    {
      "x": -2,
      "y": 30,
      "z": 13,
      "name": "Rock_Volcanic"
    },
    {
      "x": -2,
      "y": 31,
      "z": 13,
      "name": "Rock_Volcanic"
    },
    {
      "x": -2,
      "y": 23,
      "z": 14,
      "name": "Rock_Volcanic"
    },
    {
      "x": -2,
      "y": 24,
      "z": 14,
      "name": "Rock_Volcanic"
    },
    {
      "x": -2,
      "y": 25,
      "z": 14,
      "name": "Rock_Volcanic"
    },
    {
      "x": -2,
      "y": 26,
      "z": 14,
      "name": "Rock_Volcanic"
    },
    {
      "x": -2,
      "y": 27,
      "z": 14,
      "name": "Rock_Volcanic"
    },
    {
      "x": -2,
      "y": 28,
      "z": 14,
      "name": "Rock_Volcanic"
    },
    {
      "x": -2,
      "y": 29,
      "z": 14,
      "name": "Rock_Volcanic"
    },
    {
      "x": -2,
      "y": 22,
      "z": 15,
      "name": "Rock_Volcanic"
    },
    {
      "x": -2,
      "y": 23,
      "z": 15,
      "name": "Rock_Volcanic"
    },
    {
      "x": -2,
      "y": 24,
      "z": 15,
      "name": "Rock_Volcanic"
    },
    {
      "x": -2,
      "y": 25,
      "z": 15,
      "name": "Rock_Volcanic"
    },
    {
      "x": -2,
      "y": 26,
      "z": 15,
      "name": "Rock_Volcanic"
    },
    {
      "x": -2,
      "y": 27,
      "z": 15,
      "name": "Rock_Volcanic"
    },
    {
      "x": -2,
      "y": 28,
      "z": 15,
      "name": "Rock_Volcanic"
    },
    {
      "x": -2,
      "y": 20,
      "z": 16,
      "name": "Rock_Volcanic"
    },
    {
      "x": -2,
      "y": 21,
      "z": 16,
      "name": "Rock_Volcanic"
    },
    {
      "x": -2,
      "y": 22,
      "z": 16,
      "name": "Rock_Volcanic"
    },
    {
      "x": -2,
      "y": 23,
      "z": 16,
      "name": "Rock_Volcanic"
    },
    {
      "x": -2,
      "y": 19,
      "z": 17,
      "name": "Rock_Volcanic"
    },
    {
      "x": -2,
      "y": 20,
      "z": 17,
      "name": "Rock_Volcanic"
    },
    {
      "x": -2,
      "y": 21,
      "z": 17,
      "name": "Rock_Volcanic"
    },
    {
      "x": -2,
      "y": 19,
      "z": 18,
      "name": "Rock_Volcanic"
    },
    {
      "x": -1,
      "y": 47,
      "z": -7,
      "name": "Rock_Volcanic"
    },
    {
      "x": -1,
      "y": 48,
      "z": -7,
      "name": "Rock_Volcanic"
    },
    {
      "x": -1,
      "y": 49,
      "z": -7,
      "name": "Rock_Volcanic"
    },
    {
      "x": -1,
      "y": 50,
      "z": -7,
      "name": "Rock_Volcanic"
    },
    {
      "x": -1,
      "y": 51,
      "z": -7,
      "name": "Rock_Volcanic"
    },
    {
      "x": -1,
      "y": 52,
      "z": -7,
      "name": "Rock_Volcanic"
    },
    {
      "x": -1,
      "y": 45,
      "z": -6,
      "name": "Rock_Volcanic"
    },
    {
      "x": -1,
      "y": 46,
      "z": -6,
      "name": "Rock_Volcanic"
    },
    {
      "x": -1,
      "y": 47,
      "z": -6,
      "name": "Rock_Volcanic"
    },
    {
      "x": -1,
      "y": 48,
      "z": -6,
      "name": "Rock_Volcanic"
    },
    {
      "x": -1,
      "y": 49,
      "z": -6,
      "name": "Rock_Volcanic"
    },
    {
      "x": -1,
      "y": 50,
      "z": -6,
      "name": "Rock_Volcanic"
    },
    {
      "x": -1,
      "y": 51,
      "z": -6,
      "name": "Rock_Volcanic"
    },
    {
      "x": -1,
      "y": 52,
      "z": -6,
      "name": "Rock_Volcanic"
    },
    {
      "x": -1,
      "y": 44,
      "z": -5,
      "name": "Rock_Volcanic"
    },
    {
      "x": -1,
      "y": 45,
      "z": -5,
      "name": "Rock_Volcanic"
    },
    {
      "x": -1,
      "y": 46,
      "z": -5,
      "name": "Rock_Volcanic"
    },
    {
      "x": -1,
      "y": 47,
      "z": -5,
      "name": "Rock_Volcanic"
    },
    {
      "x": -1,
      "y": 48,
      "z": -5,
      "name": "Rock_Volcanic"
    },
    {
      "x": -1,
      "y": 49,
      "z": -5,
      "name": "Rock_Volcanic"
    },
    {
      "x": -1,
      "y": 50,
      "z": -5,
      "name": "Rock_Volcanic"
    },
    {
      "x": -1,
      "y": 51,
      "z": -5,
      "name": "Rock_Volcanic"
    },
    {
      "x": -1,
      "y": 44,
      "z": -4,
      "name": "Rock_Volcanic"
    },
    {
      "x": -1,
      "y": 45,
      "z": -4,
      "name": "Rock_Volcanic"
    },
    {
      "x": -1,
      "y": 46,
      "z": -4,
      "name": "Rock_Volcanic"
    },
    {
      "x": -1,
      "y": 47,
      "z": -4,
      "name": "Rock_Volcanic_Cracked_Lava"
    },
    {
      "x": -1,
      "y": 48,
      "z": -4,
      "name": "Rock_Volcanic"
    },
    {
      "x": -1,
      "y": 49,
      "z": -4,
      "name": "Rock_Volcanic"
    },
    {
      "x": -1,
      "y": 50,
      "z": -4,
      "name": "Rock_Volcanic"
    },
    {
      "x": -1,
      "y": 51,
      "z": -4,
      "name": "Rock_Volcanic"
    },
    {
      "x": -1,
      "y": 41,
      "z": -3,
      "name": "Rock_Volcanic"
    },
    {
      "x": -1,
      "y": 42,
      "z": -3,
      "name": "Rock_Volcanic"
    },
    {
      "x": -1,
      "y": 43,
      "z": -3,
      "name": "Rock_Volcanic"
    },
    {
      "x": -1,
      "y": 44,
      "z": -3,
      "name": "Rock_Volcanic"
    },
    {
      "x": -1,
      "y": 45,
      "z": -3,
      "name": "Rock_Volcanic"
    },
    {
      "x": -1,
      "y": 46,
      "z": -3,
      "name": "Rock_Volcanic_Cracked_Lava"
    },
    {
      "x": -1,
      "y": 47,
      "z": -3,
      "name": "Rock_Volcanic_Cracked_Lava"
    },
    {
      "x": -1,
      "y": 48,
      "z": -3,
      "name": "Rock_Volcanic_Cracked_Lava"
    },
    {
      "x": -1,
      "y": 49,
      "z": -3,
      "name": "Rock_Volcanic"
    },
    {
      "x": -1,
      "y": 50,
      "z": -3,
      "name": "Rock_Volcanic"
    },
    {
      "x": -1,
      "y": 39,
      "z": -2,
      "name": "Rock_Volcanic"
    },
    {
      "x": -1,
      "y": 40,
      "z": -2,
      "name": "Rock_Volcanic"
    },
    {
      "x": -1,
      "y": 41,
      "z": -2,
      "name": "Rock_Volcanic"
    },
    {
      "x": -1,
      "y": 42,
      "z": -2,
      "name": "Rock_Volcanic"
    },
    {
      "x": -1,
      "y": 43,
      "z": -2,
      "name": "Rock_Volcanic"
    },
    {
      "x": -1,
      "y": 44,
      "z": -2,
      "name": "Rock_Volcanic"
    },
    {
      "x": -1,
      "y": 45,
      "z": -2,
      "name": "Rock_Volcanic"
    },
    {
      "x": -1,
      "y": 46,
      "z": -2,
      "name": "Rock_Volcanic_Cracked_Lava"
    },
    {
      "x": -1,
      "y": 47,
      "z": -2,
      "name": "Rock_Volcanic_Cracked_Lava"
    },
    {
      "x": -1,
      "y": 48,
      "z": -2,
      "name": "Rock_Volcanic_Cracked_Lava"
    },
    {
      "x": -1,
      "y": 49,
      "z": -2,
      "name": "Rock_Volcanic"
    },
    {
      "x": -1,
      "y": 38,
      "z": -1,
      "name": "Rock_Volcanic"
    },
    {
      "x": -1,
      "y": 39,
      "z": -1,
      "name": "Rock_Volcanic"
    },
    {
      "x": -1,
      "y": 40,
      "z": -1,
      "name": "Rock_Volcanic"
    },
    {
      "x": -1,
      "y": 41,
      "z": -1,
      "name": "Rock_Volcanic"
    },
    {
      "x": -1,
      "y": 42,
      "z": -1,
      "name": "Rock_Volcanic"
    },
    {
      "x": -1,
      "y": 43,
      "z": -1,
      "name": "Rock_Volcanic"
    },
    {
      "x": -1,
      "y": 44,
      "z": -1,
      "name": "Rock_Volcanic"
    },
    {
      "x": -1,
      "y": 45,
      "z": -1,
      "name": "Rock_Volcanic"
    },
    {
      "x": -1,
      "y": 46,
      "z": -1,
      "name": "Rock_Volcanic_Cracked_Lava"
    },
    {
      "x": -1,
      "y": 47,
      "z": -1,
      "name": "Rock_Volcanic_Cracked_Lava"
    },
    {
      "x": -1,
      "y": 36,
      "z": 0,
      "name": "Rock_Volcanic"
    },
    {
      "x": -1,
      "y": 37,
      "z": 0,
      "name": "Rock_Volcanic"
    },
    {
      "x": -1,
      "y": 38,
      "z": 0,
      "name": "Rock_Volcanic"
    },
    {
      "x": -1,
      "y": 39,
      "z": 0,
      "name": "Rock_Volcanic"
    },
    {
      "x": -1,
      "y": 40,
      "z": 0,
      "name": "Rock_Volcanic"
    },
    {
      "x": -1,
      "y": 41,
      "z": 0,
      "name": "Rock_Volcanic"
    },
    {
      "x": -1,
      "y": 42,
      "z": 0,
      "name": "Rock_Volcanic"
    },
    {
      "x": -1,
      "y": 43,
      "z": 0,
      "name": "Rock_Volcanic"
    },
    {
      "x": -1,
      "y": 44,
      "z": 0,
      "name": "Rock_Volcanic_Cracked_Lava"
    },
    {
      "x": -1,
      "y": 45,
      "z": 0,
      "name": "Rock_Volcanic_Cracked_Lava"
    },
    {
      "x": -1,
      "y": 46,
      "z": 0,
      "name": "Rock_Volcanic"
    },
    {
      "x": -1,
      "y": 35,
      "z": 1,
      "name": "Rock_Volcanic"
    },
    {
      "x": -1,
      "y": 36,
      "z": 1,
      "name": "Rock_Volcanic"
    },
    {
      "x": -1,
      "y": 37,
      "z": 1,
      "name": "Rock_Volcanic"
    },
    {
      "x": -1,
      "y": 38,
      "z": 1,
      "name": "Rock_Volcanic"
    },
    {
      "x": -1,
      "y": 39,
      "z": 1,
      "name": "Rock_Volcanic"
    },
    {
      "x": -1,
      "y": 40,
      "z": 1,
      "name": "Rock_Volcanic"
    },
    {
      "x": -1,
      "y": 41,
      "z": 1,
      "name": "Rock_Volcanic"
    },
    {
      "x": -1,
      "y": 42,
      "z": 1,
      "name": "Rock_Volcanic"
    },
    {
      "x": -1,
      "y": 43,
      "z": 1,
      "name": "Rock_Volcanic"
    },
    {
      "x": -1,
      "y": 44,
      "z": 1,
      "name": "Rock_Volcanic_Cracked_Lava"
    },
    {
      "x": -1,
      "y": 45,
      "z": 1,
      "name": "Rock_Volcanic_Cracked_Lava"
    },
    {
      "x": -1,
      "y": 33,
      "z": 2,
      "name": "Rock_Volcanic"
    },
    {
      "x": -1,
      "y": 34,
      "z": 2,
      "name": "Rock_Volcanic"
    },
    {
      "x": -1,
      "y": 35,
      "z": 2,
      "name": "Rock_Volcanic"
    },
    {
      "x": -1,
      "y": 36,
      "z": 2,
      "name": "Rock_Volcanic"
    },
    {
      "x": -1,
      "y": 37,
      "z": 2,
      "name": "Rock_Volcanic"
    },
    {
      "x": -1,
      "y": 38,
      "z": 2,
      "name": "Rock_Volcanic"
    },
    {
      "x": -1,
      "y": 39,
      "z": 2,
      "name": "Rock_Volcanic"
    },
    {
      "x": -1,
      "y": 40,
      "z": 2,
      "name": "Rock_Volcanic"
    },
    {
      "x": -1,
      "y": 41,
      "z": 2,
      "name": "Rock_Volcanic"
    },
    {
      "x": -1,
      "y": 42,
      "z": 2,
      "name": "Rock_Volcanic"
    },
    {
      "x": -1,
      "y": 43,
      "z": 2,
      "name": "Rock_Volcanic_Cracked_Lava"
    },
    {
      "x": -1,
      "y": 44,
      "z": 2,
      "name": "Rock_Volcanic_Cracked_Lava"
    },
    {
      "x": -1,
      "y": 45,
      "z": 2,
      "name": "Rock_Volcanic_Cracked_Lava"
    },
    {
      "x": -1,
      "y": 32,
      "z": 3,
      "name": "Rock_Volcanic"
    },
    {
      "x": -1,
      "y": 33,
      "z": 3,
      "name": "Rock_Volcanic"
    },
    {
      "x": -1,
      "y": 34,
      "z": 3,
      "name": "Rock_Volcanic"
    },
    {
      "x": -1,
      "y": 35,
      "z": 3,
      "name": "Rock_Volcanic"
    },
    {
      "x": -1,
      "y": 36,
      "z": 3,
      "name": "Rock_Volcanic"
    },
    {
      "x": -1,
      "y": 37,
      "z": 3,
      "name": "Rock_Volcanic"
    },
    {
      "x": -1,
      "y": 38,
      "z": 3,
      "name": "Rock_Volcanic"
    },
    {
      "x": -1,
      "y": 39,
      "z": 3,
      "name": "Rock_Volcanic"
    },
    {
      "x": -1,
      "y": 40,
      "z": 3,
      "name": "Rock_Volcanic"
    },
    {
      "x": -1,
      "y": 41,
      "z": 3,
      "name": "Rock_Volcanic"
    },
    {
      "x": -1,
      "y": 42,
      "z": 3,
      "name": "Rock_Volcanic_Cracked_Lava"
    },
    {
      "x": -1,
      "y": 43,
      "z": 3,
      "name": "Rock_Volcanic_Cracked_Lava"
    },
    {
      "x": -1,
      "y": 44,
      "z": 3,
      "name": "Rock_Volcanic_Cracked_Lava"
    },
    {
      "x": -1,
      "y": 31,
      "z": 4,
      "name": "Rock_Volcanic"
    },
    {
      "x": -1,
      "y": 32,
      "z": 4,
      "name": "Rock_Volcanic"
    },
    {
      "x": -1,
      "y": 33,
      "z": 4,
      "name": "Rock_Volcanic"
    },
    {
      "x": -1,
      "y": 34,
      "z": 4,
      "name": "Rock_Volcanic"
    },
    {
      "x": -1,
      "y": 35,
      "z": 4,
      "name": "Rock_Volcanic"
    },
    {
      "x": -1,
      "y": 36,
      "z": 4,
      "name": "Rock_Volcanic"
    },
    {
      "x": -1,
      "y": 37,
      "z": 4,
      "name": "Rock_Volcanic"
    },
    {
      "x": -1,
      "y": 38,
      "z": 4,
      "name": "Rock_Volcanic"
    },
    {
      "x": -1,
      "y": 39,
      "z": 4,
      "name": "Rock_Volcanic"
    },
    {
      "x": -1,
      "y": 40,
      "z": 4,
      "name": "Rock_Volcanic"
    },
    {
      "x": -1,
      "y": 41,
      "z": 4,
      "name": "Rock_Volcanic"
    },
    {
      "x": -1,
      "y": 42,
      "z": 4,
      "name": "Rock_Volcanic_Cracked_Lava"
    },
    {
      "x": -1,
      "y": 43,
      "z": 4,
      "name": "Rock_Volcanic_Cracked_Lava"
    },
    {
      "x": -1,
      "y": 29,
      "z": 5,
      "name": "Rock_Volcanic"
    },
    {
      "x": -1,
      "y": 30,
      "z": 5,
      "name": "Rock_Volcanic"
    },
    {
      "x": -1,
      "y": 31,
      "z": 5,
      "name": "Rock_Volcanic"
    },
    {
      "x": -1,
      "y": 32,
      "z": 5,
      "name": "Rock_Volcanic"
    },
    {
      "x": -1,
      "y": 33,
      "z": 5,
      "name": "Rock_Volcanic"
    },
    {
      "x": -1,
      "y": 34,
      "z": 5,
      "name": "Rock_Volcanic"
    },
    {
      "x": -1,
      "y": 35,
      "z": 5,
      "name": "Rock_Volcanic"
    },
    {
      "x": -1,
      "y": 36,
      "z": 5,
      "name": "Rock_Volcanic"
    },
    {
      "x": -1,
      "y": 37,
      "z": 5,
      "name": "Rock_Volcanic"
    },
    {
      "x": -1,
      "y": 38,
      "z": 5,
      "name": "Rock_Volcanic"
    },
    {
      "x": -1,
      "y": 39,
      "z": 5,
      "name": "Rock_Volcanic"
    },
    {
      "x": -1,
      "y": 40,
      "z": 5,
      "name": "Rock_Volcanic"
    },
    {
      "x": -1,
      "y": 41,
      "z": 5,
      "name": "Rock_Volcanic"
    },
    {
      "x": -1,
      "y": 29,
      "z": 6,
      "name": "Rock_Volcanic"
    },
    {
      "x": -1,
      "y": 30,
      "z": 6,
      "name": "Rock_Volcanic"
    },
    {
      "x": -1,
      "y": 31,
      "z": 6,
      "name": "Rock_Volcanic"
    },
    {
      "x": -1,
      "y": 32,
      "z": 6,
      "name": "Rock_Volcanic"
    },
    {
      "x": -1,
      "y": 33,
      "z": 6,
      "name": "Rock_Volcanic"
    },
    {
      "x": -1,
      "y": 34,
      "z": 6,
      "name": "Rock_Volcanic"
    },
    {
      "x": -1,
      "y": 35,
      "z": 6,
      "name": "Rock_Volcanic"
    },
    {
      "x": -1,
      "y": 36,
      "z": 6,
      "name": "Rock_Volcanic"
    },
    {
      "x": -1,
      "y": 37,
      "z": 6,
      "name": "Rock_Volcanic"
    },
    {
      "x": -1,
      "y": 38,
      "z": 6,
      "name": "Rock_Volcanic"
    },
    {
      "x": -1,
      "y": 39,
      "z": 6,
      "name": "Rock_Volcanic"
    },
    {
      "x": -1,
      "y": 40,
      "z": 6,
      "name": "Rock_Volcanic"
    },
    {
      "x": -1,
      "y": 41,
      "z": 6,
      "name": "Rock_Volcanic"
    },
    {
      "x": -1,
      "y": 28,
      "z": 7,
      "name": "Rock_Volcanic"
    },
    {
      "x": -1,
      "y": 29,
      "z": 7,
      "name": "Rock_Volcanic"
    },
    {
      "x": -1,
      "y": 30,
      "z": 7,
      "name": "Rock_Volcanic"
    },
    {
      "x": -1,
      "y": 31,
      "z": 7,
      "name": "Rock_Volcanic"
    },
    {
      "x": -1,
      "y": 32,
      "z": 7,
      "name": "Rock_Volcanic"
    },
    {
      "x": -1,
      "y": 33,
      "z": 7,
      "name": "Rock_Volcanic"
    },
    {
      "x": -1,
      "y": 34,
      "z": 7,
      "name": "Rock_Volcanic"
    },
    {
      "x": -1,
      "y": 35,
      "z": 7,
      "name": "Rock_Volcanic"
    },
    {
      "x": -1,
      "y": 36,
      "z": 7,
      "name": "Rock_Volcanic"
    },
    {
      "x": -1,
      "y": 37,
      "z": 7,
      "name": "Rock_Volcanic"
    },
    {
      "x": -1,
      "y": 38,
      "z": 7,
      "name": "Rock_Volcanic"
    },
    {
      "x": -1,
      "y": 39,
      "z": 7,
      "name": "Rock_Volcanic"
    },
    {
      "x": -1,
      "y": 40,
      "z": 7,
      "name": "Rock_Volcanic"
    },
    {
      "x": -1,
      "y": 27,
      "z": 8,
      "name": "Rock_Volcanic"
    },
    {
      "x": -1,
      "y": 28,
      "z": 8,
      "name": "Rock_Volcanic"
    },
    {
      "x": -1,
      "y": 29,
      "z": 8,
      "name": "Rock_Volcanic"
    },
    {
      "x": -1,
      "y": 30,
      "z": 8,
      "name": "Rock_Volcanic"
    },
    {
      "x": -1,
      "y": 31,
      "z": 8,
      "name": "Rock_Volcanic"
    },
    {
      "x": -1,
      "y": 32,
      "z": 8,
      "name": "Rock_Volcanic"
    },
    {
      "x": -1,
      "y": 33,
      "z": 8,
      "name": "Rock_Volcanic"
    },
    {
      "x": -1,
      "y": 34,
      "z": 8,
      "name": "Rock_Volcanic"
    },
    {
      "x": -1,
      "y": 35,
      "z": 8,
      "name": "Rock_Volcanic"
    },
    {
      "x": -1,
      "y": 36,
      "z": 8,
      "name": "Rock_Volcanic"
    },
    {
      "x": -1,
      "y": 37,
      "z": 8,
      "name": "Rock_Volcanic"
    },
    {
      "x": -1,
      "y": 38,
      "z": 8,
      "name": "Rock_Volcanic"
    },
    {
      "x": -1,
      "y": 39,
      "z": 8,
      "name": "Rock_Volcanic"
    },
    {
      "x": -1,
      "y": 26,
      "z": 9,
      "name": "Rock_Volcanic"
    },
    {
      "x": -1,
      "y": 27,
      "z": 9,
      "name": "Rock_Volcanic"
    },
    {
      "x": -1,
      "y": 28,
      "z": 9,
      "name": "Rock_Volcanic"
    },
    {
      "x": -1,
      "y": 29,
      "z": 9,
      "name": "Rock_Volcanic"
    },
    {
      "x": -1,
      "y": 30,
      "z": 9,
      "name": "Rock_Volcanic"
    },
    {
      "x": -1,
      "y": 31,
      "z": 9,
      "name": "Rock_Volcanic"
    },
    {
      "x": -1,
      "y": 32,
      "z": 9,
      "name": "Rock_Volcanic"
    },
    {
      "x": -1,
      "y": 33,
      "z": 9,
      "name": "Rock_Volcanic"
    },
    {
      "x": -1,
      "y": 34,
      "z": 9,
      "name": "Rock_Volcanic"
    },
    {
      "x": -1,
      "y": 35,
      "z": 9,
      "name": "Rock_Volcanic"
    },
    {
      "x": -1,
      "y": 36,
      "z": 9,
      "name": "Rock_Volcanic"
    },
    {
      "x": -1,
      "y": 37,
      "z": 9,
      "name": "Rock_Volcanic"
    },
    {
      "x": -1,
      "y": 25,
      "z": 10,
      "name": "Rock_Volcanic"
    },
    {
      "x": -1,
      "y": 26,
      "z": 10,
      "name": "Rock_Volcanic"
    },
    {
      "x": -1,
      "y": 27,
      "z": 10,
      "name": "Rock_Volcanic"
    },
    {
      "x": -1,
      "y": 28,
      "z": 10,
      "name": "Rock_Volcanic"
    },
    {
      "x": -1,
      "y": 29,
      "z": 10,
      "name": "Rock_Volcanic"
    },
    {
      "x": -1,
      "y": 30,
      "z": 10,
      "name": "Rock_Volcanic"
    },
    {
      "x": -1,
      "y": 31,
      "z": 10,
      "name": "Rock_Volcanic"
    },
    {
      "x": -1,
      "y": 32,
      "z": 10,
      "name": "Rock_Volcanic"
    },
    {
      "x": -1,
      "y": 33,
      "z": 10,
      "name": "Rock_Volcanic"
    },
    {
      "x": -1,
      "y": 34,
      "z": 10,
      "name": "Rock_Volcanic"
    },
    {
      "x": -1,
      "y": 35,
      "z": 10,
      "name": "Rock_Volcanic"
    },
    {
      "x": -1,
      "y": 36,
      "z": 10,
      "name": "Rock_Volcanic"
    },
    {
      "x": -1,
      "y": 37,
      "z": 10,
      "name": "Rock_Volcanic"
    },
    {
      "x": -1,
      "y": 24,
      "z": 11,
      "name": "Rock_Volcanic"
    },
    {
      "x": -1,
      "y": 25,
      "z": 11,
      "name": "Rock_Volcanic"
    },
    {
      "x": -1,
      "y": 26,
      "z": 11,
      "name": "Rock_Volcanic"
    },
    {
      "x": -1,
      "y": 27,
      "z": 11,
      "name": "Rock_Volcanic"
    },
    {
      "x": -1,
      "y": 28,
      "z": 11,
      "name": "Rock_Volcanic"
    },
    {
      "x": -1,
      "y": 29,
      "z": 11,
      "name": "Rock_Volcanic"
    },
    {
      "x": -1,
      "y": 30,
      "z": 11,
      "name": "Rock_Volcanic"
    },
    {
      "x": -1,
      "y": 31,
      "z": 11,
      "name": "Rock_Volcanic"
    },
    {
      "x": -1,
      "y": 32,
      "z": 11,
      "name": "Rock_Volcanic"
    },
    {
      "x": -1,
      "y": 33,
      "z": 11,
      "name": "Rock_Volcanic"
    },
    {
      "x": -1,
      "y": 34,
      "z": 11,
      "name": "Rock_Volcanic"
    },
    {
      "x": -1,
      "y": 35,
      "z": 11,
      "name": "Rock_Volcanic"
    },
    {
      "x": -1,
      "y": 22,
      "z": 12,
      "name": "Rock_Volcanic"
    },
    {
      "x": -1,
      "y": 23,
      "z": 12,
      "name": "Rock_Volcanic"
    },
    {
      "x": -1,
      "y": 24,
      "z": 12,
      "name": "Rock_Volcanic"
    },
    {
      "x": -1,
      "y": 25,
      "z": 12,
      "name": "Rock_Volcanic"
    },
    {
      "x": -1,
      "y": 26,
      "z": 12,
      "name": "Rock_Volcanic"
    },
    {
      "x": -1,
      "y": 27,
      "z": 12,
      "name": "Rock_Volcanic"
    },
    {
      "x": -1,
      "y": 28,
      "z": 12,
      "name": "Rock_Volcanic"
    },
    {
      "x": -1,
      "y": 29,
      "z": 12,
      "name": "Rock_Volcanic"
    },
    {
      "x": -1,
      "y": 30,
      "z": 12,
      "name": "Rock_Volcanic"
    },
    {
      "x": -1,
      "y": 31,
      "z": 12,
      "name": "Rock_Volcanic"
    },
    {
      "x": -1,
      "y": 32,
      "z": 12,
      "name": "Rock_Volcanic"
    },
    {
      "x": -1,
      "y": 33,
      "z": 12,
      "name": "Rock_Volcanic"
    },
    {
      "x": -1,
      "y": 34,
      "z": 12,
      "name": "Rock_Volcanic"
    },
    {
      "x": -1,
      "y": 22,
      "z": 13,
      "name": "Rock_Volcanic"
    },
    {
      "x": -1,
      "y": 23,
      "z": 13,
      "name": "Rock_Volcanic"
    },
    {
      "x": -1,
      "y": 24,
      "z": 13,
      "name": "Rock_Volcanic"
    },
    {
      "x": -1,
      "y": 25,
      "z": 13,
      "name": "Rock_Volcanic"
    },
    {
      "x": -1,
      "y": 26,
      "z": 13,
      "name": "Rock_Volcanic"
    },
    {
      "x": -1,
      "y": 27,
      "z": 13,
      "name": "Rock_Volcanic"
    },
    {
      "x": -1,
      "y": 28,
      "z": 13,
      "name": "Rock_Volcanic"
    },
    {
      "x": -1,
      "y": 29,
      "z": 13,
      "name": "Rock_Volcanic"
    },
    {
      "x": -1,
      "y": 30,
      "z": 13,
      "name": "Rock_Volcanic"
    },
    {
      "x": -1,
      "y": 31,
      "z": 13,
      "name": "Rock_Volcanic"
    },
    {
      "x": -1,
      "y": 32,
      "z": 13,
      "name": "Rock_Volcanic"
    },
    {
      "x": -1,
      "y": 33,
      "z": 13,
      "name": "Rock_Volcanic"
    },
    {
      "x": -1,
      "y": 20,
      "z": 14,
      "name": "Rock_Volcanic"
    },
    {
      "x": -1,
      "y": 21,
      "z": 14,
      "name": "Rock_Volcanic"
    },
    {
      "x": -1,
      "y": 22,
      "z": 14,
      "name": "Rock_Volcanic"
    },
    {
      "x": -1,
      "y": 23,
      "z": 14,
      "name": "Rock_Volcanic"
    },
    {
      "x": -1,
      "y": 24,
      "z": 14,
      "name": "Rock_Volcanic"
    },
    {
      "x": -1,
      "y": 25,
      "z": 14,
      "name": "Rock_Volcanic"
    },
    {
      "x": -1,
      "y": 26,
      "z": 14,
      "name": "Rock_Volcanic"
    },
    {
      "x": -1,
      "y": 27,
      "z": 14,
      "name": "Rock_Volcanic"
    },
    {
      "x": -1,
      "y": 28,
      "z": 14,
      "name": "Rock_Volcanic"
    },
    {
      "x": -1,
      "y": 29,
      "z": 14,
      "name": "Rock_Volcanic"
    },
    {
      "x": -1,
      "y": 30,
      "z": 14,
      "name": "Rock_Volcanic"
    },
    {
      "x": -1,
      "y": 31,
      "z": 14,
      "name": "Rock_Volcanic"
    },
    {
      "x": -1,
      "y": 19,
      "z": 15,
      "name": "Rock_Volcanic"
    },
    {
      "x": -1,
      "y": 20,
      "z": 15,
      "name": "Rock_Volcanic"
    },
    {
      "x": -1,
      "y": 21,
      "z": 15,
      "name": "Rock_Volcanic"
    },
    {
      "x": -1,
      "y": 22,
      "z": 15,
      "name": "Rock_Volcanic"
    },
    {
      "x": -1,
      "y": 23,
      "z": 15,
      "name": "Rock_Volcanic"
    },
    {
      "x": -1,
      "y": 24,
      "z": 15,
      "name": "Rock_Volcanic"
    },
    {
      "x": -1,
      "y": 25,
      "z": 15,
      "name": "Rock_Volcanic"
    },
    {
      "x": -1,
      "y": 26,
      "z": 15,
      "name": "Rock_Volcanic"
    },
    {
      "x": -1,
      "y": 27,
      "z": 15,
      "name": "Rock_Volcanic"
    },
    {
      "x": -1,
      "y": 28,
      "z": 15,
      "name": "Rock_Volcanic"
    },
    {
      "x": -1,
      "y": 29,
      "z": 15,
      "name": "Rock_Volcanic"
    },
    {
      "x": -1,
      "y": 18,
      "z": 16,
      "name": "Rock_Volcanic"
    },
    {
      "x": -1,
      "y": 19,
      "z": 16,
      "name": "Rock_Volcanic"
    },
    {
      "x": -1,
      "y": 20,
      "z": 16,
      "name": "Rock_Volcanic"
    },
    {
      "x": -1,
      "y": 21,
      "z": 16,
      "name": "Rock_Volcanic"
    },
    {
      "x": -1,
      "y": 22,
      "z": 16,
      "name": "Rock_Volcanic"
    },
    {
      "x": -1,
      "y": 23,
      "z": 16,
      "name": "Rock_Volcanic"
    },
    {
      "x": -1,
      "y": 24,
      "z": 16,
      "name": "Rock_Volcanic"
    },
    {
      "x": -1,
      "y": 25,
      "z": 16,
      "name": "Rock_Volcanic"
    },
    {
      "x": -1,
      "y": 26,
      "z": 16,
      "name": "Rock_Volcanic"
    },
    {
      "x": -1,
      "y": 27,
      "z": 16,
      "name": "Rock_Volcanic"
    },
    {
      "x": -1,
      "y": 28,
      "z": 16,
      "name": "Rock_Volcanic"
    },
    {
      "x": -1,
      "y": 17,
      "z": 17,
      "name": "Rock_Volcanic"
    },
    {
      "x": -1,
      "y": 18,
      "z": 17,
      "name": "Rock_Volcanic"
    },
    {
      "x": -1,
      "y": 19,
      "z": 17,
      "name": "Rock_Volcanic"
    },
    {
      "x": -1,
      "y": 20,
      "z": 17,
      "name": "Rock_Volcanic"
    },
    {
      "x": -1,
      "y": 21,
      "z": 17,
      "name": "Rock_Volcanic"
    },
    {
      "x": -1,
      "y": 22,
      "z": 17,
      "name": "Rock_Volcanic"
    },
    {
      "x": -1,
      "y": 23,
      "z": 17,
      "name": "Rock_Volcanic"
    },
    {
      "x": -1,
      "y": 24,
      "z": 17,
      "name": "Rock_Volcanic"
    },
    {
      "x": -1,
      "y": 25,
      "z": 17,
      "name": "Rock_Volcanic"
    },
    {
      "x": -1,
      "y": 17,
      "z": 18,
      "name": "Rock_Volcanic"
    },
    {
      "x": -1,
      "y": 18,
      "z": 18,
      "name": "Rock_Volcanic"
    },
    {
      "x": -1,
      "y": 19,
      "z": 18,
      "name": "Rock_Volcanic"
    },
    {
      "x": -1,
      "y": 20,
      "z": 18,
      "name": "Rock_Volcanic"
    },
    {
      "x": -1,
      "y": 21,
      "z": 18,
      "name": "Rock_Volcanic"
    },
    {
      "x": -1,
      "y": 22,
      "z": 18,
      "name": "Rock_Volcanic"
    },
    {
      "x": -1,
      "y": 23,
      "z": 18,
      "name": "Rock_Volcanic"
    },
    {
      "x": -1,
      "y": 17,
      "z": 19,
      "name": "Rock_Volcanic"
    },
    {
      "x": -1,
      "y": 18,
      "z": 19,
      "name": "Rock_Volcanic"
    },
    {
      "x": -1,
      "y": 19,
      "z": 19,
      "name": "Rock_Volcanic"
    },
    {
      "x": -1,
      "y": 20,
      "z": 19,
      "name": "Rock_Volcanic"
    },
    {
      "x": -1,
      "y": 21,
      "z": 19,
      "name": "Rock_Volcanic"
    },
    {
      "x": 0,
      "y": 57,
      "z": -11,
      "name": "Rock_Volcanic_Cracked_Lava"
    },
    {
      "x": 0,
      "y": 58,
      "z": -11,
      "name": "Rock_Volcanic_Cracked_Lava"
    },
    {
      "x": 0,
      "y": 59,
      "z": -11,
      "name": "Rock_Volcanic_Cracked_Lava"
    },
    {
      "x": 0,
      "y": 54,
      "z": -10,
      "name": "Rock_Volcanic"
    },
    {
      "x": 0,
      "y": 55,
      "z": -10,
      "name": "Rock_Volcanic"
    },
    {
      "x": 0,
      "y": 56,
      "z": -10,
      "name": "Rock_Volcanic"
    },
    {
      "x": 0,
      "y": 57,
      "z": -10,
      "name": "Rock_Volcanic_Cracked_Lava"
    },
    {
      "x": 0,
      "y": 58,
      "z": -10,
      "name": "Rock_Volcanic_Cracked_Lava"
    },
    {
      "x": 0,
      "y": 50,
      "z": -9,
      "name": "Rock_Volcanic"
    },
    {
      "x": 0,
      "y": 51,
      "z": -9,
      "name": "Rock_Volcanic"
    },
    {
      "x": 0,
      "y": 52,
      "z": -9,
      "name": "Rock_Volcanic"
    },
    {
      "x": 0,
      "y": 53,
      "z": -9,
      "name": "Rock_Volcanic"
    },
    {
      "x": 0,
      "y": 54,
      "z": -9,
      "name": "Rock_Volcanic"
    },
    {
      "x": 0,
      "y": 55,
      "z": -9,
      "name": "Rock_Volcanic"
    },
    {
      "x": 0,
      "y": 56,
      "z": -9,
      "name": "Rock_Volcanic"
    },
    {
      "x": 0,
      "y": 57,
      "z": -9,
      "name": "Rock_Volcanic_Cracked_Lava"
    },
    {
      "x": 0,
      "y": 50,
      "z": -8,
      "name": "Rock_Volcanic"
    },
    {
      "x": 0,
      "y": 51,
      "z": -8,
      "name": "Rock_Volcanic"
    },
    {
      "x": 0,
      "y": 52,
      "z": -8,
      "name": "Rock_Volcanic"
    },
    {
      "x": 0,
      "y": 53,
      "z": -8,
      "name": "Rock_Volcanic"
    },
    {
      "x": 0,
      "y": 54,
      "z": -8,
      "name": "Rock_Volcanic"
    },
    {
      "x": 0,
      "y": 55,
      "z": -8,
      "name": "Rock_Volcanic"
    },
    {
      "x": 0,
      "y": 56,
      "z": -8,
      "name": "Rock_Volcanic"
    },
    {
      "x": 0,
      "y": 46,
      "z": -7,
      "name": "Rock_Volcanic"
    },
    {
      "x": 0,
      "y": 47,
      "z": -7,
      "name": "Rock_Volcanic"
    },
    {
      "x": 0,
      "y": 48,
      "z": -7,
      "name": "Rock_Volcanic"
    },
    {
      "x": 0,
      "y": 49,
      "z": -7,
      "name": "Rock_Volcanic"
    },
    {
      "x": 0,
      "y": 50,
      "z": -7,
      "name": "Rock_Volcanic"
    },
    {
      "x": 0,
      "y": 51,
      "z": -7,
      "name": "Rock_Volcanic"
    },
    {
      "x": 0,
      "y": 52,
      "z": -7,
      "name": "Rock_Volcanic"
    },
    {
      "x": 0,
      "y": 53,
      "z": -7,
      "name": "Rock_Volcanic"
    },
    {
      "x": 0,
      "y": 54,
      "z": -7,
      "name": "Rock_Volcanic"
    },
    {
      "x": 0,
      "y": 45,
      "z": -6,
      "name": "Rock_Volcanic"
    },
    {
      "x": 0,
      "y": 46,
      "z": -6,
      "name": "Rock_Volcanic"
    },
    {
      "x": 0,
      "y": 47,
      "z": -6,
      "name": "Rock_Volcanic"
    },
    {
      "x": 0,
      "y": 48,
      "z": -6,
      "name": "Rock_Volcanic"
    },
    {
      "x": 0,
      "y": 49,
      "z": -6,
      "name": "Rock_Volcanic"
    },
    {
      "x": 0,
      "y": 50,
      "z": -6,
      "name": "Rock_Volcanic"
    },
    {
      "x": 0,
      "y": 51,
      "z": -6,
      "name": "Rock_Volcanic"
    },
    {
      "x": 0,
      "y": 52,
      "z": -6,
      "name": "Rock_Volcanic"
    },
    {
      "x": 0,
      "y": 53,
      "z": -6,
      "name": "Rock_Volcanic"
    },
    {
      "x": 0,
      "y": 54,
      "z": -6,
      "name": "Rock_Volcanic"
    },
    {
      "x": 0,
      "y": 44,
      "z": -5,
      "name": "Rock_Volcanic"
    },
    {
      "x": 0,
      "y": 45,
      "z": -5,
      "name": "Rock_Volcanic"
    },
    {
      "x": 0,
      "y": 46,
      "z": -5,
      "name": "Rock_Volcanic"
    },
    {
      "x": 0,
      "y": 47,
      "z": -5,
      "name": "Rock_Volcanic"
    },
    {
      "x": 0,
      "y": 48,
      "z": -5,
      "name": "Rock_Volcanic"
    },
    {
      "x": 0,
      "y": 49,
      "z": -5,
      "name": "Rock_Volcanic"
    },
    {
      "x": 0,
      "y": 50,
      "z": -5,
      "name": "Rock_Volcanic"
    },
    {
      "x": 0,
      "y": 51,
      "z": -5,
      "name": "Rock_Volcanic"
    },
    {
      "x": 0,
      "y": 52,
      "z": -5,
      "name": "Rock_Volcanic"
    },
    {
      "x": 0,
      "y": 53,
      "z": -5,
      "name": "Rock_Volcanic"
    },
    {
      "x": 0,
      "y": 42,
      "z": -4,
      "name": "Rock_Volcanic"
    },
    {
      "x": 0,
      "y": 43,
      "z": -4,
      "name": "Rock_Volcanic"
    },
    {
      "x": 0,
      "y": 44,
      "z": -4,
      "name": "Rock_Volcanic"
    },
    {
      "x": 0,
      "y": 45,
      "z": -4,
      "name": "Rock_Volcanic"
    },
    {
      "x": 0,
      "y": 46,
      "z": -4,
      "name": "Rock_Volcanic"
    },
    {
      "x": 0,
      "y": 47,
      "z": -4,
      "name": "Rock_Volcanic"
    },
    {
      "x": 0,
      "y": 48,
      "z": -4,
      "name": "Rock_Volcanic"
    },
    {
      "x": 0,
      "y": 49,
      "z": -4,
      "name": "Rock_Volcanic"
    },
    {
      "x": 0,
      "y": 50,
      "z": -4,
      "name": "Rock_Volcanic"
    },
    {
      "x": 0,
      "y": 51,
      "z": -4,
      "name": "Rock_Volcanic_Cracked_Lava"
    },
    {
      "x": 0,
      "y": 40,
      "z": -3,
      "name": "Rock_Volcanic"
    },
    {
      "x": 0,
      "y": 41,
      "z": -3,
      "name": "Rock_Volcanic"
    },
    {
      "x": 0,
      "y": 42,
      "z": -3,
      "name": "Rock_Volcanic"
    },
    {
      "x": 0,
      "y": 43,
      "z": -3,
      "name": "Rock_Volcanic"
    },
    {
      "x": 0,
      "y": 44,
      "z": -3,
      "name": "Rock_Volcanic"
    },
    {
      "x": 0,
      "y": 45,
      "z": -3,
      "name": "Rock_Volcanic"
    },
    {
      "x": 0,
      "y": 46,
      "z": -3,
      "name": "Rock_Volcanic"
    },
    {
      "x": 0,
      "y": 47,
      "z": -3,
      "name": "Rock_Volcanic_Cracked_Lava"
    },
    {
      "x": 0,
      "y": 48,
      "z": -3,
      "name": "Rock_Volcanic"
    },
    {
      "x": 0,
      "y": 49,
      "z": -3,
      "name": "Rock_Volcanic"
    },
    {
      "x": 0,
      "y": 50,
      "z": -3,
      "name": "Rock_Volcanic"
    },
    {
      "x": 0,
      "y": 51,
      "z": -3,
      "name": "Rock_Volcanic_Cracked_Lava"
    },
    {
      "x": 0,
      "y": 39,
      "z": -2,
      "name": "Rock_Volcanic"
    },
    {
      "x": 0,
      "y": 40,
      "z": -2,
      "name": "Rock_Volcanic"
    },
    {
      "x": 0,
      "y": 41,
      "z": -2,
      "name": "Rock_Volcanic"
    },
    {
      "x": 0,
      "y": 42,
      "z": -2,
      "name": "Rock_Volcanic"
    },
    {
      "x": 0,
      "y": 43,
      "z": -2,
      "name": "Rock_Volcanic"
    },
    {
      "x": 0,
      "y": 44,
      "z": -2,
      "name": "Rock_Volcanic"
    },
    {
      "x": 0,
      "y": 45,
      "z": -2,
      "name": "Rock_Volcanic"
    },
    {
      "x": 0,
      "y": 46,
      "z": -2,
      "name": "Rock_Volcanic"
    },
    {
      "x": 0,
      "y": 47,
      "z": -2,
      "name": "Rock_Volcanic_Cracked_Lava"
    },
    {
      "x": 0,
      "y": 48,
      "z": -2,
      "name": "Rock_Volcanic"
    },
    {
      "x": 0,
      "y": 49,
      "z": -2,
      "name": "Rock_Volcanic"
    },
    {
      "x": 0,
      "y": 50,
      "z": -2,
      "name": "Rock_Volcanic"
    },
    {
      "x": 0,
      "y": 37,
      "z": -1,
      "name": "Rock_Volcanic"
    },
    {
      "x": 0,
      "y": 38,
      "z": -1,
      "name": "Rock_Volcanic"
    },
    {
      "x": 0,
      "y": 39,
      "z": -1,
      "name": "Rock_Volcanic"
    },
    {
      "x": 0,
      "y": 40,
      "z": -1,
      "name": "Rock_Volcanic"
    },
    {
      "x": 0,
      "y": 41,
      "z": -1,
      "name": "Rock_Volcanic"
    },
    {
      "x": 0,
      "y": 42,
      "z": -1,
      "name": "Rock_Volcanic"
    },
    {
      "x": 0,
      "y": 43,
      "z": -1,
      "name": "Rock_Volcanic"
    },
    {
      "x": 0,
      "y": 44,
      "z": -1,
      "name": "Rock_Volcanic"
    },
    {
      "x": 0,
      "y": 45,
      "z": -1,
      "name": "Rock_Volcanic"
    },
    {
      "x": 0,
      "y": 46,
      "z": -1,
      "name": "Rock_Volcanic"
    },
    {
      "x": 0,
      "y": 47,
      "z": -1,
      "name": "Rock_Volcanic_Cracked_Lava"
    },
    {
      "x": 0,
      "y": 48,
      "z": -1,
      "name": "Rock_Volcanic"
    },
    {
      "x": 0,
      "y": 36,
      "z": 0,
      "name": "Rock_Volcanic"
    },
    {
      "x": 0,
      "y": 37,
      "z": 0,
      "name": "Rock_Volcanic"
    },
    {
      "x": 0,
      "y": 38,
      "z": 0,
      "name": "Rock_Volcanic"
    },
    {
      "x": 0,
      "y": 39,
      "z": 0,
      "name": "Rock_Volcanic"
    },
    {
      "x": 0,
      "y": 40,
      "z": 0,
      "name": "Rock_Volcanic"
    },
    {
      "x": 0,
      "y": 41,
      "z": 0,
      "name": "Rock_Volcanic"
    },
    {
      "x": 0,
      "y": 42,
      "z": 0,
      "name": "Rock_Volcanic"
    },
    {
      "x": 0,
      "y": 43,
      "z": 0,
      "name": "Rock_Volcanic"
    },
    {
      "x": 0,
      "y": 44,
      "z": 0,
      "name": "Rock_Volcanic"
    },
    {
      "x": 0,
      "y": 45,
      "z": 0,
      "name": "Rock_Volcanic_Cracked_Lava"
    },
    {
      "x": 0,
      "y": 46,
      "z": 0,
      "name": "Rock_Volcanic"
    },
    {
      "x": 0,
      "y": 47,
      "z": 0,
      "name": "Rock_Volcanic"
    },
    {
      "x": 0,
      "y": 48,
      "z": 0,
      "name": "Rock_Volcanic"
    },
    {
      "x": 0,
      "y": 34,
      "z": 1,
      "name": "Rock_Volcanic"
    },
    {
      "x": 0,
      "y": 35,
      "z": 1,
      "name": "Rock_Volcanic"
    },
    {
      "x": 0,
      "y": 36,
      "z": 1,
      "name": "Rock_Volcanic"
    },
    {
      "x": 0,
      "y": 37,
      "z": 1,
      "name": "Rock_Volcanic"
    },
    {
      "x": 0,
      "y": 38,
      "z": 1,
      "name": "Rock_Volcanic"
    },
    {
      "x": 0,
      "y": 39,
      "z": 1,
      "name": "Rock_Volcanic"
    },
    {
      "x": 0,
      "y": 40,
      "z": 1,
      "name": "Rock_Volcanic"
    },
    {
      "x": 0,
      "y": 41,
      "z": 1,
      "name": "Rock_Volcanic"
    },
    {
      "x": 0,
      "y": 42,
      "z": 1,
      "name": "Rock_Volcanic"
    },
    {
      "x": 0,
      "y": 43,
      "z": 1,
      "name": "Rock_Volcanic"
    },
    {
      "x": 0,
      "y": 44,
      "z": 1,
      "name": "Rock_Volcanic_Cracked_Lava"
    },
    {
      "x": 0,
      "y": 45,
      "z": 1,
      "name": "Rock_Volcanic_Cracked_Lava"
    },
    {
      "x": 0,
      "y": 46,
      "z": 1,
      "name": "Rock_Volcanic_Cracked_Lava"
    },
    {
      "x": 0,
      "y": 47,
      "z": 1,
      "name": "Rock_Volcanic"
    },
    {
      "x": 0,
      "y": 33,
      "z": 2,
      "name": "Rock_Volcanic"
    },
    {
      "x": 0,
      "y": 34,
      "z": 2,
      "name": "Rock_Volcanic"
    },
    {
      "x": 0,
      "y": 35,
      "z": 2,
      "name": "Rock_Volcanic"
    },
    {
      "x": 0,
      "y": 36,
      "z": 2,
      "name": "Rock_Volcanic"
    },
    {
      "x": 0,
      "y": 37,
      "z": 2,
      "name": "Rock_Volcanic"
    },
    {
      "x": 0,
      "y": 38,
      "z": 2,
      "name": "Rock_Volcanic"
    },
    {
      "x": 0,
      "y": 39,
      "z": 2,
      "name": "Rock_Volcanic"
    },
    {
      "x": 0,
      "y": 40,
      "z": 2,
      "name": "Rock_Volcanic"
    },
    {
      "x": 0,
      "y": 41,
      "z": 2,
      "name": "Rock_Volcanic"
    },
    {
      "x": 0,
      "y": 42,
      "z": 2,
      "name": "Rock_Volcanic"
    },
    {
      "x": 0,
      "y": 43,
      "z": 2,
      "name": "Rock_Volcanic_Cracked_Lava"
    },
    {
      "x": 0,
      "y": 44,
      "z": 2,
      "name": "Rock_Volcanic_Cracked_Lava"
    },
    {
      "x": 0,
      "y": 45,
      "z": 2,
      "name": "Rock_Volcanic_Cracked_Lava"
    },
    {
      "x": 0,
      "y": 32,
      "z": 3,
      "name": "Rock_Volcanic"
    },
    {
      "x": 0,
      "y": 33,
      "z": 3,
      "name": "Rock_Volcanic"
    },
    {
      "x": 0,
      "y": 34,
      "z": 3,
      "name": "Rock_Volcanic"
    },
    {
      "x": 0,
      "y": 35,
      "z": 3,
      "name": "Rock_Volcanic"
    },
    {
      "x": 0,
      "y": 36,
      "z": 3,
      "name": "Rock_Volcanic"
    },
    {
      "x": 0,
      "y": 37,
      "z": 3,
      "name": "Rock_Volcanic"
    },
    {
      "x": 0,
      "y": 38,
      "z": 3,
      "name": "Rock_Volcanic"
    },
    {
      "x": 0,
      "y": 39,
      "z": 3,
      "name": "Rock_Volcanic"
    },
    {
      "x": 0,
      "y": 40,
      "z": 3,
      "name": "Rock_Volcanic"
    },
    {
      "x": 0,
      "y": 41,
      "z": 3,
      "name": "Rock_Volcanic"
    },
    {
      "x": 0,
      "y": 42,
      "z": 3,
      "name": "Rock_Volcanic_Cracked_Lava"
    },
    {
      "x": 0,
      "y": 43,
      "z": 3,
      "name": "Rock_Volcanic_Cracked_Lava"
    },
    {
      "x": 0,
      "y": 44,
      "z": 3,
      "name": "Rock_Volcanic_Cracked_Lava"
    },
    {
      "x": 0,
      "y": 30,
      "z": 4,
      "name": "Rock_Volcanic"
    },
    {
      "x": 0,
      "y": 31,
      "z": 4,
      "name": "Rock_Volcanic"
    },
    {
      "x": 0,
      "y": 32,
      "z": 4,
      "name": "Rock_Volcanic"
    },
    {
      "x": 0,
      "y": 33,
      "z": 4,
      "name": "Rock_Volcanic"
    },
    {
      "x": 0,
      "y": 34,
      "z": 4,
      "name": "Rock_Volcanic"
    },
    {
      "x": 0,
      "y": 35,
      "z": 4,
      "name": "Rock_Volcanic"
    },
    {
      "x": 0,
      "y": 36,
      "z": 4,
      "name": "Rock_Volcanic"
    },
    {
      "x": 0,
      "y": 37,
      "z": 4,
      "name": "Rock_Volcanic"
    },
    {
      "x": 0,
      "y": 38,
      "z": 4,
      "name": "Rock_Volcanic"
    },
    {
      "x": 0,
      "y": 39,
      "z": 4,
      "name": "Rock_Volcanic"
    },
    {
      "x": 0,
      "y": 40,
      "z": 4,
      "name": "Rock_Volcanic"
    },
    {
      "x": 0,
      "y": 41,
      "z": 4,
      "name": "Rock_Volcanic"
    },
    {
      "x": 0,
      "y": 42,
      "z": 4,
      "name": "Rock_Volcanic_Cracked_Lava"
    },
    {
      "x": 0,
      "y": 43,
      "z": 4,
      "name": "Rock_Volcanic_Cracked_Lava"
    },
    {
      "x": 0,
      "y": 29,
      "z": 5,
      "name": "Rock_Volcanic"
    },
    {
      "x": 0,
      "y": 30,
      "z": 5,
      "name": "Rock_Volcanic"
    },
    {
      "x": 0,
      "y": 31,
      "z": 5,
      "name": "Rock_Volcanic"
    },
    {
      "x": 0,
      "y": 32,
      "z": 5,
      "name": "Rock_Volcanic"
    },
    {
      "x": 0,
      "y": 33,
      "z": 5,
      "name": "Rock_Volcanic"
    },
    {
      "x": 0,
      "y": 34,
      "z": 5,
      "name": "Rock_Volcanic"
    },
    {
      "x": 0,
      "y": 35,
      "z": 5,
      "name": "Rock_Volcanic"
    },
    {
      "x": 0,
      "y": 36,
      "z": 5,
      "name": "Rock_Volcanic"
    },
    {
      "x": 0,
      "y": 37,
      "z": 5,
      "name": "Rock_Volcanic"
    },
    {
      "x": 0,
      "y": 38,
      "z": 5,
      "name": "Rock_Volcanic"
    },
    {
      "x": 0,
      "y": 39,
      "z": 5,
      "name": "Rock_Volcanic"
    },
    {
      "x": 0,
      "y": 40,
      "z": 5,
      "name": "Rock_Volcanic"
    },
    {
      "x": 0,
      "y": 41,
      "z": 5,
      "name": "Rock_Volcanic"
    },
    {
      "x": 0,
      "y": 42,
      "z": 5,
      "name": "Rock_Volcanic_Cracked_Lava"
    },
    {
      "x": 0,
      "y": 28,
      "z": 6,
      "name": "Rock_Volcanic"
    },
    {
      "x": 0,
      "y": 29,
      "z": 6,
      "name": "Rock_Volcanic"
    },
    {
      "x": 0,
      "y": 30,
      "z": 6,
      "name": "Rock_Volcanic"
    },
    {
      "x": 0,
      "y": 31,
      "z": 6,
      "name": "Rock_Volcanic"
    },
    {
      "x": 0,
      "y": 32,
      "z": 6,
      "name": "Rock_Volcanic"
    },
    {
      "x": 0,
      "y": 33,
      "z": 6,
      "name": "Rock_Volcanic"
    },
    {
      "x": 0,
      "y": 34,
      "z": 6,
      "name": "Rock_Volcanic"
    },
    {
      "x": 0,
      "y": 35,
      "z": 6,
      "name": "Rock_Volcanic"
    },
    {
      "x": 0,
      "y": 36,
      "z": 6,
      "name": "Rock_Volcanic"
    },
    {
      "x": 0,
      "y": 37,
      "z": 6,
      "name": "Rock_Volcanic"
    },
    {
      "x": 0,
      "y": 38,
      "z": 6,
      "name": "Rock_Volcanic"
    },
    {
      "x": 0,
      "y": 39,
      "z": 6,
      "name": "Rock_Volcanic"
    },
    {
      "x": 0,
      "y": 40,
      "z": 6,
      "name": "Rock_Volcanic"
    },
    {
      "x": 0,
      "y": 41,
      "z": 6,
      "name": "Rock_Volcanic"
    },
    {
      "x": 0,
      "y": 27,
      "z": 7,
      "name": "Rock_Volcanic"
    },
    {
      "x": 0,
      "y": 28,
      "z": 7,
      "name": "Rock_Volcanic"
    },
    {
      "x": 0,
      "y": 29,
      "z": 7,
      "name": "Rock_Volcanic"
    },
    {
      "x": 0,
      "y": 30,
      "z": 7,
      "name": "Rock_Volcanic"
    },
    {
      "x": 0,
      "y": 31,
      "z": 7,
      "name": "Rock_Volcanic"
    },
    {
      "x": 0,
      "y": 32,
      "z": 7,
      "name": "Rock_Volcanic"
    },
    {
      "x": 0,
      "y": 33,
      "z": 7,
      "name": "Rock_Volcanic"
    },
    {
      "x": 0,
      "y": 34,
      "z": 7,
      "name": "Rock_Volcanic"
    },
    {
      "x": 0,
      "y": 35,
      "z": 7,
      "name": "Rock_Volcanic"
    },
    {
      "x": 0,
      "y": 36,
      "z": 7,
      "name": "Rock_Volcanic"
    },
    {
      "x": 0,
      "y": 37,
      "z": 7,
      "name": "Rock_Volcanic"
    },
    {
      "x": 0,
      "y": 38,
      "z": 7,
      "name": "Rock_Volcanic"
    },
    {
      "x": 0,
      "y": 39,
      "z": 7,
      "name": "Rock_Volcanic"
    },
    {
      "x": 0,
      "y": 40,
      "z": 7,
      "name": "Rock_Volcanic"
    },
    {
      "x": 0,
      "y": 26,
      "z": 8,
      "name": "Rock_Volcanic"
    },
    {
      "x": 0,
      "y": 27,
      "z": 8,
      "name": "Rock_Volcanic"
    },
    {
      "x": 0,
      "y": 28,
      "z": 8,
      "name": "Rock_Volcanic"
    },
    {
      "x": 0,
      "y": 29,
      "z": 8,
      "name": "Rock_Volcanic"
    },
    {
      "x": 0,
      "y": 30,
      "z": 8,
      "name": "Rock_Volcanic"
    },
    {
      "x": 0,
      "y": 31,
      "z": 8,
      "name": "Rock_Volcanic"
    },
    {
      "x": 0,
      "y": 32,
      "z": 8,
      "name": "Rock_Volcanic"
    },
    {
      "x": 0,
      "y": 33,
      "z": 8,
      "name": "Rock_Volcanic"
    },
    {
      "x": 0,
      "y": 34,
      "z": 8,
      "name": "Rock_Volcanic"
    },
    {
      "x": 0,
      "y": 35,
      "z": 8,
      "name": "Rock_Volcanic"
    },
    {
      "x": 0,
      "y": 36,
      "z": 8,
      "name": "Rock_Volcanic"
    },
    {
      "x": 0,
      "y": 37,
      "z": 8,
      "name": "Rock_Volcanic"
    },
    {
      "x": 0,
      "y": 38,
      "z": 8,
      "name": "Rock_Volcanic"
    },
    {
      "x": 0,
      "y": 39,
      "z": 8,
      "name": "Rock_Volcanic"
    },
    {
      "x": 0,
      "y": 40,
      "z": 8,
      "name": "Rock_Volcanic"
    },
    {
      "x": 0,
      "y": 25,
      "z": 9,
      "name": "Rock_Volcanic"
    },
    {
      "x": 0,
      "y": 26,
      "z": 9,
      "name": "Rock_Volcanic"
    },
    {
      "x": 0,
      "y": 27,
      "z": 9,
      "name": "Rock_Volcanic"
    },
    {
      "x": 0,
      "y": 28,
      "z": 9,
      "name": "Rock_Volcanic"
    },
    {
      "x": 0,
      "y": 29,
      "z": 9,
      "name": "Rock_Volcanic"
    },
    {
      "x": 0,
      "y": 30,
      "z": 9,
      "name": "Rock_Volcanic"
    },
    {
      "x": 0,
      "y": 31,
      "z": 9,
      "name": "Rock_Volcanic"
    },
    {
      "x": 0,
      "y": 32,
      "z": 9,
      "name": "Rock_Volcanic"
    },
    {
      "x": 0,
      "y": 33,
      "z": 9,
      "name": "Rock_Volcanic"
    },
    {
      "x": 0,
      "y": 34,
      "z": 9,
      "name": "Rock_Volcanic"
    },
    {
      "x": 0,
      "y": 35,
      "z": 9,
      "name": "Rock_Volcanic"
    },
    {
      "x": 0,
      "y": 36,
      "z": 9,
      "name": "Rock_Volcanic"
    },
    {
      "x": 0,
      "y": 37,
      "z": 9,
      "name": "Rock_Volcanic"
    },
    {
      "x": 0,
      "y": 38,
      "z": 9,
      "name": "Rock_Volcanic"
    },
    {
      "x": 0,
      "y": 24,
      "z": 10,
      "name": "Rock_Volcanic"
    },
    {
      "x": 0,
      "y": 25,
      "z": 10,
      "name": "Rock_Volcanic"
    },
    {
      "x": 0,
      "y": 26,
      "z": 10,
      "name": "Rock_Volcanic"
    },
    {
      "x": 0,
      "y": 27,
      "z": 10,
      "name": "Rock_Volcanic"
    },
    {
      "x": 0,
      "y": 28,
      "z": 10,
      "name": "Rock_Volcanic"
    },
    {
      "x": 0,
      "y": 29,
      "z": 10,
      "name": "Rock_Volcanic"
    },
    {
      "x": 0,
      "y": 30,
      "z": 10,
      "name": "Rock_Volcanic"
    },
    {
      "x": 0,
      "y": 31,
      "z": 10,
      "name": "Rock_Volcanic"
    },
    {
      "x": 0,
      "y": 32,
      "z": 10,
      "name": "Rock_Volcanic"
    },
    {
      "x": 0,
      "y": 33,
      "z": 10,
      "name": "Rock_Volcanic"
    },
    {
      "x": 0,
      "y": 34,
      "z": 10,
      "name": "Rock_Volcanic"
    },
    {
      "x": 0,
      "y": 35,
      "z": 10,
      "name": "Rock_Volcanic"
    },
    {
      "x": 0,
      "y": 36,
      "z": 10,
      "name": "Rock_Volcanic"
    },
    {
      "x": 0,
      "y": 37,
      "z": 10,
      "name": "Rock_Volcanic"
    },
    {
      "x": 0,
      "y": 23,
      "z": 11,
      "name": "Rock_Volcanic"
    },
    {
      "x": 0,
      "y": 24,
      "z": 11,
      "name": "Rock_Volcanic"
    },
    {
      "x": 0,
      "y": 25,
      "z": 11,
      "name": "Rock_Volcanic"
    },
    {
      "x": 0,
      "y": 26,
      "z": 11,
      "name": "Rock_Volcanic"
    },
    {
      "x": 0,
      "y": 27,
      "z": 11,
      "name": "Rock_Volcanic"
    },
    {
      "x": 0,
      "y": 28,
      "z": 11,
      "name": "Rock_Volcanic"
    },
    {
      "x": 0,
      "y": 29,
      "z": 11,
      "name": "Rock_Volcanic"
    },
    {
      "x": 0,
      "y": 30,
      "z": 11,
      "name": "Rock_Volcanic"
    },
    {
      "x": 0,
      "y": 31,
      "z": 11,
      "name": "Rock_Volcanic"
    },
    {
      "x": 0,
      "y": 32,
      "z": 11,
      "name": "Rock_Volcanic"
    },
    {
      "x": 0,
      "y": 33,
      "z": 11,
      "name": "Rock_Volcanic"
    },
    {
      "x": 0,
      "y": 34,
      "z": 11,
      "name": "Rock_Volcanic"
    },
    {
      "x": 0,
      "y": 35,
      "z": 11,
      "name": "Rock_Volcanic"
    },
    {
      "x": 0,
      "y": 22,
      "z": 12,
      "name": "Rock_Volcanic"
    },
    {
      "x": 0,
      "y": 23,
      "z": 12,
      "name": "Rock_Volcanic"
    },
    {
      "x": 0,
      "y": 24,
      "z": 12,
      "name": "Rock_Volcanic"
    },
    {
      "x": 0,
      "y": 25,
      "z": 12,
      "name": "Rock_Volcanic"
    },
    {
      "x": 0,
      "y": 26,
      "z": 12,
      "name": "Rock_Volcanic"
    },
    {
      "x": 0,
      "y": 27,
      "z": 12,
      "name": "Rock_Volcanic"
    },
    {
      "x": 0,
      "y": 28,
      "z": 12,
      "name": "Rock_Volcanic"
    },
    {
      "x": 0,
      "y": 29,
      "z": 12,
      "name": "Rock_Volcanic"
    },
    {
      "x": 0,
      "y": 30,
      "z": 12,
      "name": "Rock_Volcanic"
    },
    {
      "x": 0,
      "y": 31,
      "z": 12,
      "name": "Rock_Volcanic"
    },
    {
      "x": 0,
      "y": 32,
      "z": 12,
      "name": "Rock_Volcanic"
    },
    {
      "x": 0,
      "y": 33,
      "z": 12,
      "name": "Rock_Volcanic"
    },
    {
      "x": 0,
      "y": 34,
      "z": 12,
      "name": "Rock_Volcanic"
    },
    {
      "x": 0,
      "y": 35,
      "z": 12,
      "name": "Rock_Volcanic"
    },
    {
      "x": 0,
      "y": 20,
      "z": 13,
      "name": "Rock_Volcanic"
    },
    {
      "x": 0,
      "y": 21,
      "z": 13,
      "name": "Rock_Volcanic"
    },
    {
      "x": 0,
      "y": 22,
      "z": 13,
      "name": "Rock_Volcanic"
    },
    {
      "x": 0,
      "y": 23,
      "z": 13,
      "name": "Rock_Volcanic"
    },
    {
      "x": 0,
      "y": 24,
      "z": 13,
      "name": "Rock_Volcanic"
    },
    {
      "x": 0,
      "y": 25,
      "z": 13,
      "name": "Rock_Volcanic"
    },
    {
      "x": 0,
      "y": 26,
      "z": 13,
      "name": "Rock_Volcanic"
    },
    {
      "x": 0,
      "y": 27,
      "z": 13,
      "name": "Rock_Volcanic"
    },
    {
      "x": 0,
      "y": 28,
      "z": 13,
      "name": "Rock_Volcanic"
    },
    {
      "x": 0,
      "y": 29,
      "z": 13,
      "name": "Rock_Volcanic"
    },
    {
      "x": 0,
      "y": 30,
      "z": 13,
      "name": "Rock_Volcanic"
    },
    {
      "x": 0,
      "y": 31,
      "z": 13,
      "name": "Rock_Volcanic"
    },
    {
      "x": 0,
      "y": 32,
      "z": 13,
      "name": "Rock_Volcanic"
    },
    {
      "x": 0,
      "y": 33,
      "z": 13,
      "name": "Rock_Volcanic"
    },
    {
      "x": 0,
      "y": 19,
      "z": 14,
      "name": "Rock_Volcanic"
    },
    {
      "x": 0,
      "y": 20,
      "z": 14,
      "name": "Rock_Volcanic"
    },
    {
      "x": 0,
      "y": 21,
      "z": 14,
      "name": "Rock_Volcanic"
    },
    {
      "x": 0,
      "y": 22,
      "z": 14,
      "name": "Rock_Volcanic"
    },
    {
      "x": 0,
      "y": 23,
      "z": 14,
      "name": "Rock_Volcanic"
    },
    {
      "x": 0,
      "y": 24,
      "z": 14,
      "name": "Rock_Volcanic"
    },
    {
      "x": 0,
      "y": 25,
      "z": 14,
      "name": "Rock_Volcanic"
    },
    {
      "x": 0,
      "y": 26,
      "z": 14,
      "name": "Rock_Volcanic"
    },
    {
      "x": 0,
      "y": 27,
      "z": 14,
      "name": "Rock_Volcanic"
    },
    {
      "x": 0,
      "y": 28,
      "z": 14,
      "name": "Rock_Volcanic"
    },
    {
      "x": 0,
      "y": 29,
      "z": 14,
      "name": "Rock_Volcanic"
    },
    {
      "x": 0,
      "y": 30,
      "z": 14,
      "name": "Rock_Volcanic"
    },
    {
      "x": 0,
      "y": 31,
      "z": 14,
      "name": "Rock_Volcanic"
    },
    {
      "x": 0,
      "y": 32,
      "z": 14,
      "name": "Rock_Volcanic"
    },
    {
      "x": 0,
      "y": 18,
      "z": 15,
      "name": "Rock_Volcanic"
    },
    {
      "x": 0,
      "y": 19,
      "z": 15,
      "name": "Rock_Volcanic"
    },
    {
      "x": 0,
      "y": 20,
      "z": 15,
      "name": "Rock_Volcanic"
    },
    {
      "x": 0,
      "y": 21,
      "z": 15,
      "name": "Rock_Volcanic"
    },
    {
      "x": 0,
      "y": 22,
      "z": 15,
      "name": "Rock_Volcanic"
    },
    {
      "x": 0,
      "y": 23,
      "z": 15,
      "name": "Rock_Volcanic"
    },
    {
      "x": 0,
      "y": 24,
      "z": 15,
      "name": "Rock_Volcanic"
    },
    {
      "x": 0,
      "y": 25,
      "z": 15,
      "name": "Rock_Volcanic"
    },
    {
      "x": 0,
      "y": 26,
      "z": 15,
      "name": "Rock_Volcanic"
    },
    {
      "x": 0,
      "y": 27,
      "z": 15,
      "name": "Rock_Volcanic"
    },
    {
      "x": 0,
      "y": 28,
      "z": 15,
      "name": "Rock_Volcanic"
    },
    {
      "x": 0,
      "y": 29,
      "z": 15,
      "name": "Rock_Volcanic"
    },
    {
      "x": 0,
      "y": 30,
      "z": 15,
      "name": "Rock_Volcanic"
    },
    {
      "x": 0,
      "y": 31,
      "z": 15,
      "name": "Rock_Volcanic"
    },
    {
      "x": 0,
      "y": 17,
      "z": 16,
      "name": "Rock_Volcanic"
    },
    {
      "x": 0,
      "y": 18,
      "z": 16,
      "name": "Rock_Volcanic"
    },
    {
      "x": 0,
      "y": 19,
      "z": 16,
      "name": "Rock_Volcanic"
    },
    {
      "x": 0,
      "y": 20,
      "z": 16,
      "name": "Rock_Volcanic"
    },
    {
      "x": 0,
      "y": 21,
      "z": 16,
      "name": "Rock_Volcanic"
    },
    {
      "x": 0,
      "y": 22,
      "z": 16,
      "name": "Rock_Volcanic"
    },
    {
      "x": 0,
      "y": 23,
      "z": 16,
      "name": "Rock_Volcanic"
    },
    {
      "x": 0,
      "y": 24,
      "z": 16,
      "name": "Rock_Volcanic"
    },
    {
      "x": 0,
      "y": 25,
      "z": 16,
      "name": "Rock_Volcanic"
    },
    {
      "x": 0,
      "y": 26,
      "z": 16,
      "name": "Rock_Volcanic"
    },
    {
      "x": 0,
      "y": 27,
      "z": 16,
      "name": "Rock_Volcanic"
    },
    {
      "x": 0,
      "y": 28,
      "z": 16,
      "name": "Rock_Volcanic"
    },
    {
      "x": 0,
      "y": 29,
      "z": 16,
      "name": "Rock_Volcanic"
    },
    {
      "x": 0,
      "y": 16,
      "z": 17,
      "name": "Rock_Volcanic"
    },
    {
      "x": 0,
      "y": 17,
      "z": 17,
      "name": "Rock_Volcanic"
    },
    {
      "x": 0,
      "y": 18,
      "z": 17,
      "name": "Rock_Volcanic"
    },
    {
      "x": 0,
      "y": 19,
      "z": 17,
      "name": "Rock_Volcanic"
    },
    {
      "x": 0,
      "y": 20,
      "z": 17,
      "name": "Rock_Volcanic"
    },
    {
      "x": 0,
      "y": 21,
      "z": 17,
      "name": "Rock_Volcanic"
    },
    {
      "x": 0,
      "y": 22,
      "z": 17,
      "name": "Rock_Volcanic"
    },
    {
      "x": 0,
      "y": 23,
      "z": 17,
      "name": "Rock_Volcanic"
    },
    {
      "x": 0,
      "y": 24,
      "z": 17,
      "name": "Rock_Volcanic"
    },
    {
      "x": 0,
      "y": 25,
      "z": 17,
      "name": "Rock_Volcanic"
    },
    {
      "x": 0,
      "y": 26,
      "z": 17,
      "name": "Rock_Volcanic"
    },
    {
      "x": 0,
      "y": 27,
      "z": 17,
      "name": "Rock_Volcanic"
    },
    {
      "x": 0,
      "y": 16,
      "z": 18,
      "name": "Rock_Volcanic"
    },
    {
      "x": 0,
      "y": 17,
      "z": 18,
      "name": "Rock_Volcanic"
    },
    {
      "x": 0,
      "y": 18,
      "z": 18,
      "name": "Rock_Volcanic"
    },
    {
      "x": 0,
      "y": 19,
      "z": 18,
      "name": "Rock_Volcanic"
    },
    {
      "x": 0,
      "y": 20,
      "z": 18,
      "name": "Rock_Volcanic"
    },
    {
      "x": 0,
      "y": 21,
      "z": 18,
      "name": "Rock_Volcanic"
    },
    {
      "x": 0,
      "y": 22,
      "z": 18,
      "name": "Rock_Volcanic"
    },
    {
      "x": 0,
      "y": 23,
      "z": 18,
      "name": "Rock_Volcanic"
    },
    {
      "x": 0,
      "y": 24,
      "z": 18,
      "name": "Rock_Volcanic"
    },
    {
      "x": 0,
      "y": 25,
      "z": 18,
      "name": "Rock_Volcanic"
    },
    {
      "x": 0,
      "y": 16,
      "z": 19,
      "name": "Rock_Volcanic"
    },
    {
      "x": 0,
      "y": 17,
      "z": 19,
      "name": "Rock_Volcanic"
    },
    {
      "x": 0,
      "y": 18,
      "z": 19,
      "name": "Rock_Volcanic"
    },
    {
      "x": 0,
      "y": 19,
      "z": 19,
      "name": "Rock_Volcanic"
    },
    {
      "x": 0,
      "y": 20,
      "z": 19,
      "name": "Rock_Volcanic"
    },
    {
      "x": 0,
      "y": 21,
      "z": 19,
      "name": "Rock_Volcanic"
    },
    {
      "x": 0,
      "y": 22,
      "z": 19,
      "name": "Rock_Volcanic"
    },
    {
      "x": 0,
      "y": 17,
      "z": 20,
      "name": "Rock_Volcanic"
    },
    {
      "x": 0,
      "y": 18,
      "z": 20,
      "name": "Rock_Volcanic"
    },
    {
      "x": 0,
      "y": 19,
      "z": 20,
      "name": "Rock_Volcanic"
    },
    {
      "x": 0,
      "y": 20,
      "z": 20,
      "name": "Rock_Volcanic"
    },
    {
      "x": 1,
      "y": 60,
      "z": -14,
      "name": "Rock_Volcanic_Cracked_Lava"
    },
    {
      "x": 1,
      "y": 59,
      "z": -13,
      "name": "Rock_Volcanic_Cracked_Lava"
    },
    {
      "x": 1,
      "y": 60,
      "z": -13,
      "name": "Rock_Volcanic_Cracked_Lava"
    },
    {
      "x": 1,
      "y": 61,
      "z": -13,
      "name": "Rock_Volcanic_Cracked_Lava"
    },
    {
      "x": 1,
      "y": 57,
      "z": -12,
      "name": "Rock_Volcanic"
    },
    {
      "x": 1,
      "y": 58,
      "z": -12,
      "name": "Rock_Volcanic_Cracked_Lava"
    },
    {
      "x": 1,
      "y": 59,
      "z": -12,
      "name": "Rock_Volcanic_Cracked_Lava"
    },
    {
      "x": 1,
      "y": 60,
      "z": -12,
      "name": "Rock_Volcanic_Cracked_Lava"
    },
    {
      "x": 1,
      "y": 55,
      "z": -11,
      "name": "Rock_Volcanic"
    },
    {
      "x": 1,
      "y": 56,
      "z": -11,
      "name": "Rock_Volcanic"
    },
    {
      "x": 1,
      "y": 57,
      "z": -11,
      "name": "Rock_Volcanic_Cracked_Lava"
    },
    {
      "x": 1,
      "y": 58,
      "z": -11,
      "name": "Rock_Volcanic_Cracked_Lava"
    },
    {
      "x": 1,
      "y": 59,
      "z": -11,
      "name": "Rock_Volcanic_Cracked_Lava"
    },
    {
      "x": 1,
      "y": 60,
      "z": -11,
      "name": "Rock_Volcanic_Cracked_Lava"
    },
    {
      "x": 1,
      "y": 53,
      "z": -10,
      "name": "Rock_Volcanic"
    },
    {
      "x": 1,
      "y": 54,
      "z": -10,
      "name": "Rock_Volcanic"
    },
    {
      "x": 1,
      "y": 55,
      "z": -10,
      "name": "Rock_Volcanic"
    },
    {
      "x": 1,
      "y": 56,
      "z": -10,
      "name": "Rock_Volcanic"
    },
    {
      "x": 1,
      "y": 57,
      "z": -10,
      "name": "Rock_Volcanic_Cracked_Lava"
    },
    {
      "x": 1,
      "y": 58,
      "z": -10,
      "name": "Rock_Volcanic_Cracked_Lava"
    },
    {
      "x": 1,
      "y": 59,
      "z": -10,
      "name": "Rock_Volcanic_Cracked_Lava"
    },
    {
      "x": 1,
      "y": 60,
      "z": -10,
      "name": "Rock_Volcanic_Cracked_Lava"
    },
    {
      "x": 1,
      "y": 50,
      "z": -9,
      "name": "Rock_Volcanic"
    },
    {
      "x": 1,
      "y": 51,
      "z": -9,
      "name": "Rock_Volcanic"
    },
    {
      "x": 1,
      "y": 52,
      "z": -9,
      "name": "Rock_Volcanic"
    },
    {
      "x": 1,
      "y": 53,
      "z": -9,
      "name": "Rock_Volcanic"
    },
    {
      "x": 1,
      "y": 54,
      "z": -9,
      "name": "Rock_Volcanic"
    },
    {
      "x": 1,
      "y": 55,
      "z": -9,
      "name": "Rock_Volcanic"
    },
    {
      "x": 1,
      "y": 56,
      "z": -9,
      "name": "Rock_Volcanic"
    },
    {
      "x": 1,
      "y": 57,
      "z": -9,
      "name": "Rock_Volcanic_Cracked_Lava"
    },
    {
      "x": 1,
      "y": 58,
      "z": -9,
      "name": "Rock_Volcanic_Cracked_Lava"
    },
    {
      "x": 1,
      "y": 50,
      "z": -8,
      "name": "Rock_Volcanic"
    },
    {
      "x": 1,
      "y": 51,
      "z": -8,
      "name": "Rock_Volcanic"
    },
    {
      "x": 1,
      "y": 52,
      "z": -8,
      "name": "Rock_Volcanic"
    },
    {
      "x": 1,
      "y": 53,
      "z": -8,
      "name": "Rock_Volcanic"
    },
    {
      "x": 1,
      "y": 54,
      "z": -8,
      "name": "Rock_Volcanic"
    },
    {
      "x": 1,
      "y": 55,
      "z": -8,
      "name": "Rock_Volcanic"
    },
    {
      "x": 1,
      "y": 56,
      "z": -8,
      "name": "Rock_Volcanic"
    },
    {
      "x": 1,
      "y": 57,
      "z": -8,
      "name": "Rock_Volcanic_Cracked_Lava"
    },
    {
      "x": 1,
      "y": 58,
      "z": -8,
      "name": "Rock_Volcanic_Cracked_Lava"
    },
    {
      "x": 1,
      "y": 46,
      "z": -7,
      "name": "Rock_Volcanic"
    },
    {
      "x": 1,
      "y": 47,
      "z": -7,
      "name": "Rock_Volcanic"
    },
    {
      "x": 1,
      "y": 48,
      "z": -7,
      "name": "Rock_Volcanic"
    },
    {
      "x": 1,
      "y": 49,
      "z": -7,
      "name": "Rock_Volcanic"
    },
    {
      "x": 1,
      "y": 50,
      "z": -7,
      "name": "Rock_Volcanic"
    },
    {
      "x": 1,
      "y": 51,
      "z": -7,
      "name": "Rock_Volcanic"
    },
    {
      "x": 1,
      "y": 52,
      "z": -7,
      "name": "Rock_Volcanic"
    },
    {
      "x": 1,
      "y": 53,
      "z": -7,
      "name": "Rock_Volcanic"
    },
    {
      "x": 1,
      "y": 54,
      "z": -7,
      "name": "Rock_Volcanic"
    },
    {
      "x": 1,
      "y": 55,
      "z": -7,
      "name": "Rock_Volcanic"
    },
    {
      "x": 1,
      "y": 45,
      "z": -6,
      "name": "Rock_Volcanic"
    },
    {
      "x": 1,
      "y": 46,
      "z": -6,
      "name": "Rock_Volcanic"
    },
    {
      "x": 1,
      "y": 47,
      "z": -6,
      "name": "Rock_Volcanic"
    },
    {
      "x": 1,
      "y": 48,
      "z": -6,
      "name": "Rock_Volcanic"
    },
    {
      "x": 1,
      "y": 49,
      "z": -6,
      "name": "Rock_Volcanic"
    },
    {
      "x": 1,
      "y": 50,
      "z": -6,
      "name": "Rock_Volcanic"
    },
    {
      "x": 1,
      "y": 51,
      "z": -6,
      "name": "Rock_Volcanic"
    },
    {
      "x": 1,
      "y": 52,
      "z": -6,
      "name": "Rock_Volcanic"
    },
    {
      "x": 1,
      "y": 53,
      "z": -6,
      "name": "Rock_Volcanic"
    },
    {
      "x": 1,
      "y": 54,
      "z": -6,
      "name": "Rock_Volcanic"
    },
    {
      "x": 1,
      "y": 55,
      "z": -6,
      "name": "Rock_Volcanic"
    },
    {
      "x": 1,
      "y": 44,
      "z": -5,
      "name": "Rock_Volcanic"
    },
    {
      "x": 1,
      "y": 45,
      "z": -5,
      "name": "Rock_Volcanic"
    },
    {
      "x": 1,
      "y": 46,
      "z": -5,
      "name": "Rock_Volcanic"
    },
    {
      "x": 1,
      "y": 47,
      "z": -5,
      "name": "Rock_Volcanic"
    },
    {
      "x": 1,
      "y": 48,
      "z": -5,
      "name": "Rock_Volcanic"
    },
    {
      "x": 1,
      "y": 49,
      "z": -5,
      "name": "Rock_Volcanic"
    },
    {
      "x": 1,
      "y": 50,
      "z": -5,
      "name": "Rock_Volcanic"
    },
    {
      "x": 1,
      "y": 51,
      "z": -5,
      "name": "Rock_Volcanic_Cracked_Lava"
    },
    {
      "x": 1,
      "y": 52,
      "z": -5,
      "name": "Rock_Volcanic"
    },
    {
      "x": 1,
      "y": 53,
      "z": -5,
      "name": "Rock_Volcanic"
    },
    {
      "x": 1,
      "y": 54,
      "z": -5,
      "name": "Rock_Volcanic"
    },
    {
      "x": 1,
      "y": 55,
      "z": -5,
      "name": "Rock_Volcanic"
    },
    {
      "x": 1,
      "y": 42,
      "z": -4,
      "name": "Rock_Volcanic"
    },
    {
      "x": 1,
      "y": 43,
      "z": -4,
      "name": "Rock_Volcanic"
    },
    {
      "x": 1,
      "y": 44,
      "z": -4,
      "name": "Rock_Volcanic"
    },
    {
      "x": 1,
      "y": 45,
      "z": -4,
      "name": "Rock_Volcanic"
    },
    {
      "x": 1,
      "y": 46,
      "z": -4,
      "name": "Rock_Volcanic"
    },
    {
      "x": 1,
      "y": 47,
      "z": -4,
      "name": "Rock_Volcanic"
    },
    {
      "x": 1,
      "y": 48,
      "z": -4,
      "name": "Rock_Volcanic"
    },
    {
      "x": 1,
      "y": 49,
      "z": -4,
      "name": "Rock_Volcanic"
    },
    {
      "x": 1,
      "y": 50,
      "z": -4,
      "name": "Rock_Volcanic_Cracked_Lava"
    },
    {
      "x": 1,
      "y": 51,
      "z": -4,
      "name": "Rock_Volcanic_Cracked_Lava"
    },
    {
      "x": 1,
      "y": 52,
      "z": -4,
      "name": "Rock_Volcanic_Cracked_Lava"
    },
    {
      "x": 1,
      "y": 40,
      "z": -3,
      "name": "Rock_Volcanic"
    },
    {
      "x": 1,
      "y": 41,
      "z": -3,
      "name": "Rock_Volcanic"
    },
    {
      "x": 1,
      "y": 42,
      "z": -3,
      "name": "Rock_Volcanic"
    },
    {
      "x": 1,
      "y": 43,
      "z": -3,
      "name": "Rock_Volcanic"
    },
    {
      "x": 1,
      "y": 44,
      "z": -3,
      "name": "Rock_Volcanic"
    },
    {
      "x": 1,
      "y": 45,
      "z": -3,
      "name": "Rock_Volcanic"
    },
    {
      "x": 1,
      "y": 46,
      "z": -3,
      "name": "Rock_Volcanic"
    },
    {
      "x": 1,
      "y": 47,
      "z": -3,
      "name": "Rock_Volcanic"
    },
    {
      "x": 1,
      "y": 48,
      "z": -3,
      "name": "Rock_Volcanic"
    },
    {
      "x": 1,
      "y": 49,
      "z": -3,
      "name": "Rock_Volcanic"
    },
    {
      "x": 1,
      "y": 50,
      "z": -3,
      "name": "Rock_Volcanic_Cracked_Lava"
    },
    {
      "x": 1,
      "y": 51,
      "z": -3,
      "name": "Rock_Volcanic_Cracked_Lava"
    },
    {
      "x": 1,
      "y": 39,
      "z": -2,
      "name": "Rock_Volcanic"
    },
    {
      "x": 1,
      "y": 40,
      "z": -2,
      "name": "Rock_Volcanic"
    },
    {
      "x": 1,
      "y": 41,
      "z": -2,
      "name": "Rock_Volcanic"
    },
    {
      "x": 1,
      "y": 42,
      "z": -2,
      "name": "Rock_Volcanic"
    },
    {
      "x": 1,
      "y": 43,
      "z": -2,
      "name": "Rock_Volcanic"
    },
    {
      "x": 1,
      "y": 44,
      "z": -2,
      "name": "Rock_Volcanic"
    },
    {
      "x": 1,
      "y": 45,
      "z": -2,
      "name": "Rock_Volcanic"
    },
    {
      "x": 1,
      "y": 46,
      "z": -2,
      "name": "Rock_Volcanic"
    },
    {
      "x": 1,
      "y": 47,
      "z": -2,
      "name": "Rock_Volcanic"
    },
    {
      "x": 1,
      "y": 48,
      "z": -2,
      "name": "Rock_Volcanic"
    },
    {
      "x": 1,
      "y": 49,
      "z": -2,
      "name": "Rock_Volcanic"
    },
    {
      "x": 1,
      "y": 50,
      "z": -2,
      "name": "Rock_Volcanic_Cracked_Lava"
    },
    {
      "x": 1,
      "y": 51,
      "z": -2,
      "name": "Rock_Volcanic_Cracked_Lava"
    },
    {
      "x": 1,
      "y": 37,
      "z": -1,
      "name": "Rock_Volcanic"
    },
    {
      "x": 1,
      "y": 38,
      "z": -1,
      "name": "Rock_Volcanic"
    },
    {
      "x": 1,
      "y": 39,
      "z": -1,
      "name": "Rock_Volcanic"
    },
    {
      "x": 1,
      "y": 40,
      "z": -1,
      "name": "Rock_Volcanic"
    },
    {
      "x": 1,
      "y": 41,
