{
  "version": 8,
  "blockIdVersion": 8,
  "anchorX": 4,
  "anchorY": 7,
  "anchorZ": 4,
  "blocks": [
    {
      "x": 1,
      "y": 6,
      "z": 4,
      "name": "Rock_Slate"
    },
    {
      "x": 1,
      "y": 7,
      "z": 4,
      "name": "Rock_Slate"
    },
    {
      "x": 2,
      "y": 6,
      "z": 3,
      "name": "Rock_Slate"
    },
    {
      "x": 2,
      "y": 7,
      "z": 3,
      "name": "Rock_Slate"
    },
    {
      "x": 2,
      "y": 5,
      "z": 4,
      "name": "Rock_Slate"
    },
    {
      "x": 2,
      "y": 6,
      "z": 4,
      "name": "Rock_Slate"
    },
    {
      "x": 2,
      "y": 7,
      "z": 4,
      "name": "Rock_Slate"
    },
    {
      "x": 2,
      "y": 8,
      "z": 4,
      "name": "Rock_Slate"
    },
    {
      "x": 2,
      "y": 5,
      "z": 5,
      "name": "Rock_Slate"
    },
    {
      "x": 2,
      "y": 6,
      "z": 5,
      "name": "Rock_Slate"
    },
    {
      "x": 2,
      "y": 7,
      "z": 5,
      "name": "Rock_Slate"
    },
    {
      "x": 2,
      "y": 8,
      "z": 5,
      "name": "Rock_Slate"
    },
    {
      "x": 2,
      "y": 6,
      "z": 6,
      "name": "Rock_Slate"
    },
    {
      "x": 2,
      "y": 7,
      "z": 6,
      "name": "Rock_Slate"
    },
    {
      "x": 3,
      "y": 6,
      "z": 2,
      "name": "Rock_Slate"
    },
    {
      "x": 3,
      "y": 7,
      "z": 2,
      "name": "Rock_Slate"
    },
    {
      "x": 3,
      "y": 8,
      "z": 2,
      "name": "Rock_Slate"
    },
    {
      "x": 3,
      "y": 4,
      "z": 3,
      "name": "Rock_Slate"
    },
    {
      "x": 3,
      "y": 5,
      "z": 3,
      "name": "Rock_Slate"
    },
    {
      "x": 3,
      "y": 6,
      "z": 3,
      "name": "Rock_Slate"
    },
    {
      "x": 3,
      "y": 7,
      "z": 3,
      "name": "Rock_Slate"
    },
    {
      "x": 3,
      "y": 8,
      "z": 3,
      "name": "Rock_Slate"
    },
    {
      "x": 3,
      "y": 9,
      "z": 3,
      "name": "Rock_Slate"
    },
    {
      "x": 3,
      "y": 3,
      "z": 4,
      "name": "Rock_Slate"
    },
    {
      "x": 3,
      "y": 4,
      "z": 4,
      "name": "Rock_Slate"
    },
    {
      "x": 3,
      "y": 5,
      "z": 4,
      "name": "Rock_Slate"
    },
    {
      "x": 3,
      "y": 6,
      "z": 4,
      "name": "Rock_Slate"
    },
    {
      "x": 3,
      "y": 7,
      "z": 4,
      "name": "Rock_Slate"
    },
    {
      "x": 3,
      "y": 8,
      "z": 4,
      "name": "Rock_Slate"
    },
    {
      "x": 3,
      "y": 9,
      "z": 4,
      "name": "Rock_Slate"
    },
    {
      "x": 3,
      "y": 3,
      "z": 5,
      "name": "Rock_Slate"
    },
    {
      "x": 3,
      "y": 4,
      "z": 5,
      "name": "Rock_Slate"
    },
    {
      "x": 3,
      "y": 5,
      "z": 5,
      "name": "Rock_Slate"
    },
    {
      "x": 3,
      "y": 6,
      "z": 5,
      "name": "Rock_Slate"
    },
    {
      "x": 3,
      "y": 7,
      "z": 5,
      "name": "Rock_Slate"
    },
    {
      "x": 3,
      "y": 8,
      "z": 5,
      "name": "Rock_Slate"
    },
    {
      "x": 3,
      "y": 9,
      "z": 5,
      "name": "Rock_Slate"
    },
    {
      "x": 3,
      "y": 5,
      "z": 6,
      "name": "Rock_Slate"
    },
    {
      "x": 3,
      "y": 6,
      "z": 6,
      "name": "Rock_Slate"
    },
    {
      "x": 3,
      "y": 7,
      "z": 6,
      "name": "Rock_Slate"
    },
    {
      "x": 3,
      "y": 8,
      "z": 6,
      "name": "Rock_Slate"
    },
    {
      "x": 3,
      "y": 7,
      "z": 7,
      "name": "Rock_Slate"
    },
    {
      "x": 3,
      "y": 8,
      "z": 7,
      "name": "Rock_Slate"
    },
    {
      "x": 4,
      "y": 5,
      "z": 2,
      "name": "Rock_Slate"
    },
    {
      "x": 4,
      "y": 6,
      "z": 2,
      "name": "Rock_Slate"
    },
    {
      "x": 4,
      "y": 7,
      "z": 2,
      "name": "Rock_Slate"
    },
    {
      "x": 4,
      "y": 8,
      "z": 2,
      "name": "Rock_Slate"
    },
    {
      "x": 4,
      "y": 4,
      "z": 3,
      "name": "Rock_Slate"
    },
    {
      "x": 4,
      "y": 5,
      "z": 3,
      "name": "Rock_Slate"
    },
    {
      "x": 4,
      "y": 6,
      "z": 3,
      "name": "Rock_Slate"
    },
    {
      "x": 4,
      "y": 7,
      "z": 3,
      "name": "Rock_Slate"
    },
    {
      "x": 4,
      "y": 8,
      "z": 3,
      "name": "Rock_Slate"
    },
    {
      "x": 4,
      "y": 9,
      "z": 3,
      "name": "Rock_Slate"
    },
    {
      "x": 4,
      "y": 3,
      "z": 4,
      "name": "Rock_Slate"
    },
    {
      "x": 4,
      "y": 4,
      "z": 4,
      "name": "Rock_Slate"
    },
    {
      "x": 4,
      "y": 5,
      "z": 4,
      "name": "Rock_Slate"
    },
    {
      "x": 4,
      "y": 6,
      "z": 4,
      "name": "Rock_Slate"
    },
    {
      "x": 4,
      "y": 7,
      "z": 4,
      "name": "Rock_Slate"
    },
    {
      "x": 4,
      "y": 8,
      "z": 4,
      "name": "Rock_Slate"
    },
    {
      "x": 4,
      "y": 9,
      "z": 4,
      "name": "Rock_Slate"
    },
    {
      "x": 4,
      "y": 4,
      "z": 5,
      "name": "Rock_Slate"
    },
    {
      "x": 4,
      "y": 5,
      "z": 5,
      "name": "Rock_Slate"
    },
    {
      "x": 4,
      "y": 6,
      "z": 5,
      "name": "Rock_Slate"
    },
    {
      "x": 4,
      "y": 7,
      "z": 5,
      "name": "Rock_Slate"
    },
    {
      "x": 4,
      "y": 8,
      "z": 5,
      "name": "Rock_Slate"
    },
    {
      "x": 4,
      "y": 9,
      "z": 5,
      "name": "Rock_Slate"
    },
    {
      "x": 4,
      "y": 4,
      "z": 6,
      "name": "Rock_Slate"
    },
    {
      "x": 4,
      "y": 5,
      "z": 6,
      "name": "Rock_Slate"
    },
    {
      "x": 4,
      "y": 6,
      "z": 6,
      "name": "Rock_Slate"
    },
    {
      "x": 4,
      "y": 7,
      "z": 6,
      "name": "Rock_Slate"
    },
    {
      "x": 4,
      "y": 8,
      "z": 6,
      "name": "Rock_Slate"
    },
    {
      "x": 4,
      "y": 6,
      "z": 7,
      "name": "Rock_Slate"
    },
    {
      "x": 4,
      "y": 7,
      "z": 7,
      "name": "Rock_Slate"
    },
    {
      "x": 5,
      "y": 6,
      "z": 2,
      "name": "Rock_Slate"
    },
    {
      "x": 5,
      "y": 7,
      "z": 2,
      "name": "Rock_Slate"
    },
    {
      "x": 5,
      "y": 8,
      "z": 2,
      "name": "Rock_Slate"
    },
    {
      "x": 5,
      "y": 4,
      "z": 3,
      "name": "Rock_Slate"
    },
    {
      "x": 5,
      "y": 5,
      "z": 3,
      "name": "Rock_Slate"
    },
    {
      "x": 5,
      "y": 6,
      "z": 3,
      "name": "Rock_Slate"
    },
    {
      "x": 5,
      "y": 7,
      "z": 3,
      "name": "Rock_Slate"
    },
    {
      "x": 5,
      "y": 8,
      "z": 3,
      "name": "Rock_Slate"
    },
    {
      "x": 5,
      "y": 9,
      "z": 3,
      "name": "Rock_Slate"
    },
    {
      "x": 5,
      "y": 3,
      "z": 4,
      "name": "Rock_Slate"
    },
    {
      "x": 5,
      "y": 4,
      "z": 4,
      "name": "Rock_Slate"
    },
    {
      "x": 5,
      "y": 5,
      "z": 4,
      "name": "Rock_Slate"
    },
    {
      "x": 5,
      "y": 6,
      "z": 4,
      "name": "Rock_Slate"
    },
    {
      "x": 5,
      "y": 7,
      "z": 4,
      "name": "Rock_Slate"
    },
    {
      "x": 5,
      "y": 8,
      "z": 4,
      "name": "Rock_Slate"
    },
    {
      "x": 5,
      "y": 9,
      "z": 4,
      "name": "Rock_Slate"
    },
    {
      "x": 5,
      "y": 4,
      "z": 5,
      "name": "Rock_Slate"
    },
    {
      "x": 5,
      "y": 5,
      "z": 5,
      "name": "Rock_Slate"
    },
    {
      "x": 5,
      "y": 6,
      "z": 5,
      "name": "Rock_Slate"
    },
    {
      "x": 5,
      "y": 7,
      "z": 5,
      "name": "Rock_Slate"
    },
    {
      "x": 5,
      "y": 8,
      "z": 5,
      "name": "Rock_Slate"
    },
    {
      "x": 5,
      "y": 9,
      "z": 5,
      "name": "Rock_Slate"
    },
    {
      "x": 5,
      "y": 5,
      "z": 6,
      "name": "Rock_Slate"
    },
    {
      "x": 5,
      "y": 6,
      "z": 6,
      "name": "Rock_Slate"
    },
    {
      "x": 5,
      "y": 7,
      "z": 6,
      "name": "Rock_Slate"
    },
    {
      "x": 6,
      "y": 7,
      "z": 2,
      "name": "Rock_Slate"
    },
    {
      "x": 6,
      "y": 5,
      "z": 3,
      "name": "Rock_Slate"
    },
    {
      "x": 6,
      "y": 6,
      "z": 3,
      "name": "Rock_Slate"
    },
    {
      "x": 6,
      "y": 7,
      "z": 3,
      "name": "Rock_Slate"
    },
    {
      "x": 6,
      "y": 8,
      "z": 3,
      "name": "Rock_Slate"
    },
    {
      "x": 6,
      "y": 5,
      "z": 4,
      "name": "Rock_Slate"
    },
    {
      "x": 6,
      "y": 6,
      "z": 4,
      "name": "Rock_Slate"
    },
    {
      "x": 6,
      "y": 7,
      "z": 4,
      "name": "Rock_Slate"
    },
    {
      "x": 6,
      "y": 8,
      "z": 4,
      "name": "Rock_Slate"
    },
    {
      "x": 6,
      "y": 9,
      "z": 4,
      "name": "Rock_Slate"
    },
    {
      "x": 6,
      "y": 6,
      "z": 5,
      "name": "Rock_Slate"
    },
    {
      "x": 6,
      "y": 7,
      "z": 5,
      "name": "Rock_Slate"
    },
    {
      "x": 6,
      "y": 8,
      "z": 5,
      "name": "Rock_Slate"
    },
    {
      "x": 7,
      "y": 7,
      "z": 3,
      "name": "Rock_Slate"
    },
    {
      "x": 7,
      "y": 8,
      "z": 3,
      "name": "Rock_Slate"
    },
    {
      "x": 7,
      "y": 6,
      "z": 4,
      "name": "Rock_Slate"
    },
    {
      "x": 7,
      "y": 7,
      "z": 4,
      "name": "Rock_Slate"
    },
    {
      "x": 7,
      "y": 8,
      "z": 4,
      "name": "Rock_Slate"
    }
  ]
}