{
  "version": 8,
  "blockIdVersion": 8,
  "anchorX": -2,
  "anchorY": 7,
  "anchorZ": 2,
  "blocks": [
    {
      "x": -17,
      "y": 5,
      "z": -2,
      "name": "Soil_Dirt_Dry"
    },
    {
      "x": -17,
      "y": 5,
      "z": -1,
      "name": "Soil_Dirt_Dry"
    },
    {
      "x": -17,
      "y": 4,
      "z": 0,
      "name": "Rock_Sandstone"
    },
    {
      "x": -17,
      "y": 5,
      "z": 0,
      "name": "Soil_Dirt_Dry"
    },
    {
      "x": -17,
      "y": 3,
      "z": 1,
      "name": "Rock_Sandstone_Stalactite_Small",
      "rotation": 8
    },
    {
      "x": -17,
      "y": 4,
      "z": 1,
      "name": "Rock_Sandstone"
    },
    {
      "x": -17,
      "y": 5,
      "z": 1,
      "name": "Soil_Dirt_Dry"
    },
    {
      "x": -17,
      "y": 4,
      "z": 2,
      "name": "Rock_Sandstone"
    },
    {
      "x": -17,
      "y": 5,
      "z": 2,
      "name": "Soil_Dirt_Dry"
    },
    {
      "x": -17,
      "y": 5,
      "z": 3,
      "name": "Soil_Dirt_Dry"
    },
    {
      "x": -16,
      "y": 5,
      "z": -4,
      "name": "Soil_Dirt_Dry"
    },
    {
      "x": -16,
      "y": 5,
      "z": -3,
      "name": "Soil_Dirt_Dry"
    },
    {
      "x": -16,
      "y": 5,
      "z": -2,
      "name": "Soil_Dirt_Dry"
    },
    {
      "x": -16,
      "y": 5,
      "z": -1,
      "name": "Soil_Dirt_Dry"
    },
    {
      "x": -16,
      "y": 5,
      "z": 0,
      "name": "Soil_Dirt_Dry"
    },
    {
      "x": -16,
      "y": 4,
      "z": 1,
      "name": "Rock_Sandstone"
    },
    {
      "x": -16,
      "y": 5,
      "z": 1,
      "name": "Soil_Dirt_Dry"
    },
    {
      "x": -16,
      "y": 1,
      "z": 2,
      "name": "Rock_Sandstone_Stalactite_Large",
      "filler": 31744,
      "rotation": 8
    },
    {
      "x": -16,
      "y": 2,
      "z": 2,
      "name": "Rock_Sandstone_Stalactite_Large",
      "rotation": 8
    },
    {
      "x": -16,
      "y": 3,
      "z": 2,
      "name": "Rock_Sandstone"
    },
    {
      "x": -16,
      "y": 4,
      "z": 2,
      "name": "Rock_Sandstone"
    },
    {
      "x": -16,
      "y": 5,
      "z": 2,
      "name": "Soil_Dirt_Dry"
    },
    {
      "x": -16,
      "y": 4,
      "z": 3,
      "name": "Rock_Sandstone"
    },
    {
      "x": -16,
      "y": 5,
      "z": 3,
      "name": "Soil_Dirt_Dry"
    },
    {
      "x": -16,
      "y": 4,
      "z": 4,
      "name": "Rock_Sandstone"
    },
    {
      "x": -16,
      "y": 5,
      "z": 4,
      "name": "Soil_Dirt_Dry"
    },
    {
      "x": -15,
      "y": 5,
      "z": -6,
      "name": "Soil_Dirt_Dry"
    },
    {
      "x": -15,
      "y": 5,
      "z": -5,
      "name": "Soil_Dirt_Dry"
    },
    {
      "x": -15,
      "y": 5,
      "z": -4,
      "name": "Soil_Dirt_Dry"
    },
    {
      "x": -15,
      "y": 6,
      "z": -4,
      "name": "Rubble_Sandstone"
    },
    {
      "x": -15,
      "y": 5,
      "z": -3,
      "name": "Soil_Dirt_Dry"
    },
    {
      "x": -15,
      "y": 5,
      "z": -2,
      "name": "Soil_Dirt_Dry"
    },
    {
      "x": -15,
      "y": 5,
      "z": -1,
      "name": "Soil_Dirt_Dry"
    },
    {
      "x": -15,
      "y": 6,
      "z": -1,
      "name": "Soil_Dirt_Dry"
    },
    {
      "x": -15,
      "y": 5,
      "z": 0,
      "name": "Soil_Dirt_Dry"
    },
    {
      "x": -15,
      "y": 6,
      "z": 0,
      "name": "Soil_Dirt_Dry"
    },
    {
      "x": -15,
      "y": 5,
      "z": 1,
      "name": "Soil_Dirt_Dry"
    },
    {
      "x": -15,
      "y": 6,
      "z": 1,
      "name": "Soil_Dirt_Dry"
    },
    {
      "x": -15,
      "y": 4,
      "z": 2,
      "name": "Rock_Sandstone"
    },
    {
      "x": -15,
      "y": 5,
      "z": 2,
      "name": "Soil_Dirt_Dry"
    },
    {
      "x": -15,
      "y": 6,
      "z": 2,
      "name": "Soil_Sand_White"
    },
    {
      "x": -15,
      "y": 3,
      "z": 3,
      "name": "Rock_Sandstone"
    },
    {
      "x": -15,
      "y": 4,
      "z": 3,
      "name": "Rock_Sandstone"
    },
    {
      "x": -15,
      "y": 5,
      "z": 3,
      "name": "Soil_Dirt_Dry"
    },
    {
      "x": -15,
      "y": 6,
      "z": 3,
      "name": "Soil_Sand_White"
    },
    {
      "x": -15,
      "y": 2,
      "z": 4,
      "name": "Rock_Sandstone_Stalactite_Small",
      "rotation": 8
    },
    {
      "x": -15,
      "y": 3,
      "z": 4,
      "name": "Rock_Sandstone"
    },
    {
      "x": -15,
      "y": 4,
      "z": 4,
      "name": "Rock_Sandstone"
    },
    {
      "x": -15,
      "y": 5,
      "z": 4,
      "name": "Soil_Dirt_Dry"
    },
    {
      "x": -15,
      "y": 6,
      "z": 4,
      "name": "Soil_Sand_White"
    },
    {
      "x": -15,
      "y": 4,
      "z": 5,
      "name": "Rock_Sandstone"
    },
    {
      "x": -15,
      "y": 5,
      "z": 5,
      "name": "Soil_Dirt_Dry"
    },
    {
      "x": -15,
      "y": 4,
      "z": 6,
      "name": "Rock_Sandstone"
    },
    {
      "x": -15,
      "y": 5,
      "z": 6,
      "name": "Soil_Dirt_Dry"
    },
    {
      "x": -14,
      "y": 5,
      "z": -7,
      "name": "Soil_Dirt_Dry"
    },
    {
      "x": -14,
      "y": 5,
      "z": -6,
      "name": "Soil_Dirt_Dry"
    },
    {
      "x": -14,
      "y": 5,
      "z": -5,
      "name": "Soil_Dirt_Dry"
    },
    {
      "x": -14,
      "y": 5,
      "z": -4,
      "name": "Soil_Dirt_Dry"
    },
    {
      "x": -14,
      "y": 5,
      "z": -3,
      "name": "Soil_Dirt_Dry"
    },
    {
      "x": -14,
      "y": 6,
      "z": -3,
      "name": "Rubble_Sandstone_Medium"
    },
    {
      "x": -14,
      "y": 5,
      "z": -2,
      "name": "Soil_Dirt_Dry"
    },
    {
      "x": -14,
      "y": 6,
      "z": -2,
      "name": "Soil_Sand_White"
    },
    {
      "x": -14,
      "y": 5,
      "z": -1,
      "name": "Soil_Dirt_Dry"
    },
    {
      "x": -14,
      "y": 6,
      "z": -1,
      "name": "Soil_Sand_White"
    },
    {
      "x": -14,
      "y": 7,
      "z": -1,
      "name": "Rubble_Sandstone_White"
    },
    {
      "x": -14,
      "y": 5,
      "z": 0,
      "name": "Soil_Dirt_Dry"
    },
    {
      "x": -14,
      "y": 6,
      "z": 0,
      "name": "Soil_Dirt_Dry"
    },
    {
      "x": -14,
      "y": 5,
      "z": 1,
      "name": "Soil_Dirt_Dry"
    },
    {
      "x": -14,
      "y": 6,
      "z": 1,
      "name": "Soil_Sand_White"
    },
    {
      "x": -14,
      "y": 5,
      "z": 2,
      "name": "Soil_Dirt_Dry"
    },
    {
      "x": -14,
      "y": 6,
      "z": 2,
      "name": "Soil_Sand_White"
    },
    {
      "x": -14,
      "y": 5,
      "z": 3,
      "name": "Soil_Dirt_Dry"
    },
    {
      "x": -14,
      "y": 6,
      "z": 3,
      "name": "Soil_Sand_White"
    },
    {
      "x": -14,
      "y": 3,
      "z": 4,
      "name": "Rock_Sandstone"
    },
    {
      "x": -14,
      "y": 4,
      "z": 4,
      "name": "Rock_Sandstone"
    },
    {
      "x": -14,
      "y": 5,
      "z": 4,
      "name": "Soil_Dirt_Dry"
    },
    {
      "x": -14,
      "y": 6,
      "z": 4,
      "name": "Soil_Sand_White"
    },
    {
      "x": -14,
      "y": 4,
      "z": 5,
      "name": "Rock_Sandstone"
    },
    {
      "x": -14,
      "y": 5,
      "z": 5,
      "name": "Soil_Dirt_Dry"
    },
    {
      "x": -14,
      "y": 6,
      "z": 5,
      "name": "Soil_Sand_White"
    },
    {
      "x": -14,
      "y": 4,
      "z": 6,
      "name": "Rock_Sandstone"
    },
    {
      "x": -14,
      "y": 5,
      "z": 6,
      "name": "Soil_Dirt_Dry"
    },
    {
      "x": -14,
      "y": 6,
      "z": 6,
      "name": "Soil_Dirt_Dry"
    },
    {
      "x": -14,
      "y": 4,
      "z": 7,
      "name": "Rock_Sandstone"
    },
    {
      "x": -14,
      "y": 5,
      "z": 7,
      "name": "Soil_Dirt_Dry"
    },
    {
      "x": -13,
      "y": 5,
      "z": -8,
      "name": "Soil_Dirt_Dry"
    },
    {
      "x": -13,
      "y": 5,
      "z": -7,
      "name": "Soil_Dirt_Dry"
    },
    {
      "x": -13,
      "y": 5,
      "z": -6,
      "name": "Soil_Dirt_Dry"
    },
    {
      "x": -13,
      "y": 5,
      "z": -5,
      "name": "Soil_Dirt_Dry"
    },
    {
      "x": -13,
      "y": 6,
      "z": -5,
      "name": "Rock_Sandstone"
    },
    {
      "x": -13,
      "y": 5,
      "z": -4,
      "name": "Soil_Dirt_Dry"
    },
    {
      "x": -13,
      "y": 6,
      "z": -4,
      "name": "Rock_Sandstone"
    },
    {
      "x": -13,
      "y": 5,
      "z": -3,
      "name": "Soil_Dirt_Dry"
    },
    {
      "x": -13,
      "y": 6,
      "z": -3,
      "name": "Rock_Sandstone"
    },
    {
      "x": -13,
      "y": 5,
      "z": -2,
      "name": "Soil_Dirt_Dry"
    },
    {
      "x": -13,
      "y": 6,
      "z": -2,
      "name": "Soil_Sand_White"
    },
    {
      "x": -13,
      "y": 5,
      "z": -1,
      "name": "Soil_Dirt_Dry"
    },
    {
      "x": -13,
      "y": 6,
      "z": -1,
      "name": "Soil_Sand_White"
    },
    {
      "x": -13,
      "y": 5,
      "z": 0,
      "name": "Soil_Dirt_Dry"
    },
    {
      "x": -13,
      "y": 6,
      "z": 0,
      "name": "Soil_Sand_White"
    },
    {
      "x": -13,
      "y": 5,
      "z": 1,
      "name": "Soil_Dirt_Dry"
    },
    {
      "x": -13,
      "y": 6,
      "z": 1,
      "name": "Soil_Sand_White"
    },
    {
      "x": -13,
      "y": 5,
      "z": 2,
      "name": "Soil_Dirt_Dry"
    },
    {
      "x": -13,
      "y": 6,
      "z": 2,
      "name": "Soil_Sand_White"
    },
    {
      "x": -13,
      "y": 5,
      "z": 3,
      "name": "Soil_Dirt_Dry"
    },
    {
      "x": -13,
      "y": 6,
      "z": 3,
      "name": "Soil_Sand_White"
    },
    {
      "x": -13,
      "y": 5,
      "z": 4,
      "name": "Soil_Dirt_Dry"
    },
    {
      "x": -13,
      "y": 6,
      "z": 4,
      "name": "Soil_Sand_White"
    },
    {
      "x": -13,
      "y": 5,
      "z": 5,
      "name": "Soil_Dirt_Dry"
    },
    {
      "x": -13,
      "y": 6,
      "z": 5,
      "name": "Soil_Sand_White"
    },
    {
      "x": -13,
      "y": 5,
      "z": 6,
      "name": "Soil_Dirt_Dry"
    },
    {
      "x": -13,
      "y": 6,
      "z": 6,
      "name": "Soil_Sand_White"
    },
    {
      "x": -13,
      "y": 5,
      "z": 7,
      "name": "Soil_Dirt_Dry"
    },
    {
      "x": -13,
      "y": 6,
      "z": 7,
      "name": "Soil_Dirt_Dry"
    },
    {
      "x": -13,
      "y": 3,
      "z": 8,
      "name": "Rock_Sandstone_Stalactite_Large",
      "filler": 31744,
      "rotation": 8
    },
    {
      "x": -13,
      "y": 4,
      "z": 8,
      "name": "Rock_Sandstone_Stalactite_Large",
      "rotation": 8
    },
    {
      "x": -13,
      "y": 5,
      "z": 8,
      "name": "Soil_Dirt_Dry"
    },
    {
      "x": -13,
      "y": 6,
      "z": 8,
      "name": "Soil_Dirt_Dry"
    },
    {
      "x": -12,
      "y": 5,
      "z": -8,
      "name": "Soil_Dirt_Dry"
    },
    {
      "x": -12,
      "y": 5,
      "z": -7,
      "name": "Soil_Dirt_Dry"
    },
    {
      "x": -12,
      "y": 5,
      "z": -6,
      "name": "Soil_Dirt_Dry"
    },
    {
      "x": -12,
      "y": 6,
      "z": -6,
      "name": "Soil_Dirt_Dry"
    },
    {
      "x": -12,
      "y": 7,
      "z": -6,
      "name": "Rubble_Sandstone"
    },
    {
      "x": -12,
      "y": 5,
      "z": -5,
      "name": "Soil_Dirt_Dry"
    },
    {
      "x": -12,
      "y": 6,
      "z": -5,
      "name": "Soil_Sand_White"
    },
    {
      "x": -12,
      "y": 5,
      "z": -4,
      "name": "Soil_Dirt_Dry"
    },
    {
      "x": -12,
      "y": 6,
      "z": -4,
      "name": "Rock_Sandstone"
    },
    {
      "x": -12,
      "y": 5,
      "z": -3,
      "name": "Soil_Dirt_Dry"
    },
    {
      "x": -12,
      "y": 6,
      "z": -3,
      "name": "Rock_Sandstone"
    },
    {
      "x": -12,
      "y": 7,
      "z": -3,
      "name": "Rubble_Sandstone"
    },
    {
      "x": -12,
      "y": 5,
      "z": -2,
      "name": "Soil_Dirt_Dry"
    },
    {
      "x": -12,
      "y": 6,
      "z": -2,
      "name": "Rock_Sandstone"
    },
    {
      "x": -12,
      "y": 5,
      "z": -1,
      "name": "Soil_Dirt_Dry"
    },
    {
      "x": -12,
      "y": 6,
      "z": -1,
      "name": "Soil_Sand_White"
    },
    {
      "x": -12,
      "y": 5,
      "z": 0,
      "name": "Soil_Dirt_Dry"
    },
    {
      "x": -12,
      "y": 6,
      "z": 0,
      "name": "Soil_Sand_White"
    },
    {
      "x": -12,
      "y": 5,
      "z": 1,
      "name": "Soil_Dirt_Dry"
    },
    {
      "x": -12,
      "y": 6,
      "z": 1,
      "name": "Soil_Sand_White"
    },
    {
      "x": -12,
      "y": 5,
      "z": 2,
      "name": "Soil_Dirt_Dry"
    },
    {
      "x": -12,
      "y": 6,
      "z": 2,
      "name": "Soil_Sand_White"
    },
    {
      "x": -12,
      "y": 5,
      "z": 3,
      "name": "Soil_Dirt_Dry"
    },
    {
      "x": -12,
      "y": 6,
      "z": 3,
      "name": "Soil_Sand_White"
    },
    {
      "x": -12,
      "y": 5,
      "z": 4,
      "name": "Soil_Dirt_Dry"
    },
    {
      "x": -12,
      "y": 6,
      "z": 4,
      "name": "Soil_Sand_White"
    },
    {
      "x": -12,
      "y": 5,
      "z": 5,
      "name": "Soil_Dirt_Dry"
    },
    {
      "x": -12,
      "y": 6,
      "z": 5,
      "name": "Soil_Sand_White"
    },
    {
      "x": -12,
      "y": 5,
      "z": 6,
      "name": "Soil_Dirt_Dry"
    },
    {
      "x": -12,
      "y": 6,
      "z": 6,
      "name": "Soil_Sand_White"
    },
    {
      "x": -12,
      "y": 5,
      "z": 7,
      "name": "Soil_Dirt_Dry"
    },
    {
      "x": -12,
      "y": 6,
      "z": 7,
      "name": "Soil_Sand_White"
    },
    {
      "x": -12,
      "y": 5,
      "z": 8,
      "name": "Soil_Dirt_Dry"
    },
    {
      "x": -12,
      "y": 6,
      "z": 8,
      "name": "Soil_Dirt_Dry"
    },
    {
      "x": -12,
      "y": 5,
      "z": 9,
      "name": "Soil_Dirt_Dry"
    },
    {
      "x": -12,
      "y": 6,
      "z": 9,
      "name": "Soil_Dirt_Dry"
    },
    {
      "x": -11,
      "y": 5,
      "z": -8,
      "name": "Soil_Dirt_Dry"
    },
    {
      "x": -11,
      "y": 5,
      "z": -7,
      "name": "Soil_Dirt_Dry"
    },
    {
      "x": -11,
      "y": 6,
      "z": -7,
      "name": "Soil_Dirt_Dry"
    },
    {
      "x": -11,
      "y": 5,
      "z": -6,
      "name": "Soil_Dirt_Dry"
    },
    {
      "x": -11,
      "y": 6,
      "z": -6,
      "name": "Soil_Sand_White"
    },
    {
      "x": -11,
      "y": 5,
      "z": -5,
      "name": "Soil_Dirt_Dry"
    },
    {
      "x": -11,
      "y": 6,
      "z": -5,
      "name": "Soil_Sand_White"
    },
    {
      "x": -11,
      "y": 5,
      "z": -4,
      "name": "Soil_Dirt_Dry"
    },
    {
      "x": -11,
      "y": 6,
      "z": -4,
      "name": "Soil_Sand_White"
    },
    {
      "x": -11,
      "y": 5,
      "z": -3,
      "name": "Rock_Sandstone"
    },
    {
      "x": -11,
      "y": 6,
      "z": -3,
      "name": "Rock_Sandstone"
    },
    {
      "x": -11,
      "y": 5,
      "z": -2,
      "name": "Soil_Dirt_Dry"
    },
    {
      "x": -11,
      "y": 6,
      "z": -2,
      "name": "Rock_Sandstone"
    },
    {
      "x": -11,
      "y": 5,
      "z": -1,
      "name": "Soil_Dirt_Dry"
    },
    {
      "x": -11,
      "y": 6,
      "z": -1,
      "name": "Soil_Sand_White"
    },
    {
      "x": -11,
      "y": 5,
      "z": 0,
      "name": "Soil_Dirt_Dry"
    },
    {
      "x": -11,
      "y": 6,
      "z": 0,
      "name": "Soil_Sand_White"
    },
    {
      "x": -11,
      "y": 5,
      "z": 1,
      "name": "Soil_Dirt_Dry"
    },
    {
      "x": -11,
      "y": 6,
      "z": 1,
      "name": "Soil_Sand_White"
    },
    {
      "x": -11,
      "y": 5,
      "z": 2,
      "name": "Soil_Dirt_Dry"
    },
    {
      "x": -11,
      "y": 6,
      "z": 2,
      "name": "Soil_Sand_White"
    },
    {
      "x": -11,
      "y": 5,
      "z": 3,
      "name": "Soil_Dirt_Dry"
    },
    {
      "x": -11,
      "y": 6,
      "z": 3,
      "name": "Soil_Sand_White"
    },
    {
      "x": -11,
      "y": 5,
      "z": 4,
      "name": "Soil_Dirt_Dry"
    },
    {
      "x": -11,
      "y": 6,
      "z": 4,
      "name": "Soil_Sand_White"
    },
    {
      "x": -11,
      "y": 5,
      "z": 5,
      "name": "Soil_Dirt_Dry"
    },
    {
      "x": -11,
      "y": 6,
      "z": 5,
      "name": "Soil_Sand_White"
    },
    {
      "x": -11,
      "y": 5,
      "z": 6,
      "name": "Soil_Dirt_Dry"
    },
    {
      "x": -11,
      "y": 6,
      "z": 6,
      "name": "Soil_Sand_White"
    },
    {
      "x": -11,
      "y": 5,
      "z": 7,
      "name": "Rock_Sandstone"
    },
    {
      "x": -11,
      "y": 6,
      "z": 7,
      "name": "Soil_Sand_White"
    },
    {
      "x": -11,
      "y": 5,
      "z": 8,
      "name": "Soil_Dirt_Dry"
    },
    {
      "x": -11,
      "y": 6,
      "z": 8,
      "name": "Soil_Sand_White"
    },
    {
      "x": -11,
      "y": 5,
      "z": 9,
      "name": "Soil_Dirt_Dry"
    },
    {
      "x": -11,
      "y": 6,
      "z": 9,
      "name": "Soil_Dirt_Dry"
    },
    {
      "x": -11,
      "y": 5,
      "z": 10,
      "name": "Soil_Dirt_Dry"
    },
    {
      "x": -11,
      "y": 6,
      "z": 10,
      "name": "Soil_Dirt_Dry"
    },
    {
      "x": -10,
      "y": 6,
      "z": -8,
      "name": "Soil_Dirt_Dry"
    },
    {
      "x": -10,
      "y": 6,
      "z": -7,
      "name": "Soil_Sand_White"
    },
    {
      "x": -10,
      "y": 5,
      "z": -6,
      "name": "Soil_Dirt_Dry"
    },
    {
      "x": -10,
      "y": 6,
      "z": -6,
      "name": "Soil_Sand_White"
    },
    {
      "x": -10,
      "y": 5,
      "z": -5,
      "name": "Soil_Dirt_Dry"
    },
    {
      "x": -10,
      "y": 6,
      "z": -5,
      "name": "Soil_Sand_White"
    },
    {
      "x": -10,
      "y": 5,
      "z": -4,
      "name": "Rock_Sandstone"
    },
    {
      "x": -10,
      "y": 6,
      "z": -4,
      "name": "Soil_Sand_White"
    },
    {
      "x": -10,
      "y": 5,
      "z": -3,
      "name": "Rock_Sandstone"
    },
    {
      "x": -10,
      "y": 6,
      "z": -3,
      "name": "Soil_Sand_White"
    },
    {
      "x": -10,
      "y": 5,
      "z": -2,
      "name": "Rock_Sandstone"
    },
    {
      "x": -10,
      "y": 6,
      "z": -2,
      "name": "Soil_Sand_White"
    },
    {
      "x": -10,
      "y": 5,
      "z": -1,
      "name": "Soil_Dirt_Dry"
    },
    {
      "x": -10,
      "y": 6,
      "z": -1,
      "name": "Soil_Sand_White"
    },
    {
      "x": -10,
      "y": 5,
      "z": 0,
      "name": "Soil_Dirt_Dry"
    },
    {
      "x": -10,
      "y": 6,
      "z": 0,
      "name": "Soil_Sand_White"
    },
    {
      "x": -10,
      "y": 5,
      "z": 1,
      "name": "Soil_Dirt_Dry"
    },
    {
      "x": -10,
      "y": 6,
      "z": 1,
      "name": "Soil_Sand_White"
    },
    {
      "x": -10,
      "y": 5,
      "z": 2,
      "name": "Soil_Dirt_Dry"
    },
    {
      "x": -10,
      "y": 6,
      "z": 2,
      "name": "Soil_Sand_White"
    },
    {
      "x": -10,
      "y": 5,
      "z": 3,
      "name": "Soil_Dirt_Dry"
    },
    {
      "x": -10,
      "y": 6,
      "z": 3,
      "name": "Soil_Sand_White"
    },
    {
      "x": -10,
      "y": 5,
      "z": 4,
      "name": "Soil_Dirt_Dry"
    },
    {
      "x": -10,
      "y": 6,
      "z": 4,
      "name": "Soil_Sand_White"
    },
    {
      "x": -10,
      "y": 5,
      "z": 5,
      "name": "Soil_Dirt_Dry"
    },
    {
      "x": -10,
      "y": 6,
      "z": 5,
      "name": "Soil_Sand_White"
    },
    {
      "x": -10,
      "y": 5,
      "z": 6,
      "name": "Rock_Sandstone"
    },
    {
      "x": -10,
      "y": 6,
      "z": 6,
      "name": "Soil_Dirt_Dry"
    },
    {
      "x": -10,
      "y": 7,
      "z": 6,
      "name": "Soil_Sand_White"
    },
    {
      "x": -10,
      "y": 5,
      "z": 7,
      "name": "Rock_Sandstone"
    },
    {
      "x": -10,
      "y": 6,
      "z": 7,
      "name": "Rock_Sandstone"
    },
    {
      "x": -10,
      "y": 7,
      "z": 7,
      "name": "Soil_Sand_White"
    },
    {
      "x": -10,
      "y": 5,
      "z": 8,
      "name": "Rock_Sandstone"
    },
    {
      "x": -10,
      "y": 6,
      "z": 8,
      "name": "Soil_Sand_White"
    },
    {
      "x": -10,
      "y": 5,
      "z": 9,
      "name": "Soil_Dirt_Dry"
    },
    {
      "x": -10,
      "y": 6,
      "z": 9,
      "name": "Soil_Sand_White"
    },
    {
      "x": -10,
      "y": 5,
      "z": 10,
      "name": "Soil_Dirt_Dry"
    },
    {
      "x": -10,
      "y": 6,
      "z": 10,
      "name": "Soil_Dirt_Dry"
    },
    {
      "x": -9,
      "y": 6,
      "z": -9,
      "name": "Soil_Dirt_Dry"
    },
    {
      "x": -9,
      "y": 6,
      "z": -8,
      "name": "Soil_Sand_White"
    },
    {
      "x": -9,
      "y": 6,
      "z": -7,
      "name": "Soil_Sand_White"
    },
    {
      "x": -9,
      "y": 6,
      "z": -6,
      "name": "Soil_Sand_White"
    },
    {
      "x": -9,
      "y": 6,
      "z": -5,
      "name": "Soil_Sand_White"
    },
    {
      "x": -9,
      "y": 6,
      "z": -4,
      "name": "Soil_Sand_White"
    },
    {
      "x": -9,
      "y": 5,
      "z": -3,
      "name": "Rock_Sandstone"
    },
    {
      "x": -9,
      "y": 6,
      "z": -3,
      "name": "Soil_Sand_White"
    },
    {
      "x": -9,
      "y": 5,
      "z": -2,
      "name": "Rock_Sandstone"
    },
    {
      "x": -9,
      "y": 6,
      "z": -2,
      "name": "Soil_Sand_White"
    },
    {
      "x": -9,
      "y": 5,
      "z": -1,
      "name": "Soil_Dirt_Dry"
    },
    {
      "x": -9,
      "y": 6,
      "z": -1,
      "name": "Soil_Sand_White"
    },
    {
      "x": -9,
      "y": 5,
      "z": 0,
      "name": "Soil_Dirt_Dry"
    },
    {
      "x": -9,
      "y": 6,
      "z": 0,
      "name": "Soil_Sand_White"
    },
    {
      "x": -9,
      "y": 5,
      "z": 1,
      "name": "Soil_Dirt_Dry"
    },
    {
      "x": -9,
      "y": 6,
      "z": 1,
      "name": "Soil_Sand_White"
    },
    {
      "x": -9,
      "y": 6,
      "z": 2,
      "name": "Soil_Dirt_Dry"
    },
    {
      "x": -9,
      "y": 7,
      "z": 2,
      "name": "Soil_Sand_White"
    },
    {
      "x": -9,
      "y": 6,
      "z": 3,
      "name": "Soil_Dirt_Dry"
    },
    {
      "x": -9,
      "y": 7,
      "z": 3,
      "name": "Soil_Sand_White"
    },
    {
      "x": -9,
      "y": 5,
      "z": 4,
      "name": "Soil_Dirt_Dry"
    },
    {
      "x": -9,
      "y": 6,
      "z": 4,
      "name": "Soil_Dirt_Dry"
    },
    {
      "x": -9,
      "y": 7,
      "z": 4,
      "name": "Soil_Sand_White"
    },
    {
      "x": -9,
      "y": 5,
      "z": 5,
      "name": "Soil_Dirt_Dry"
    },
    {
      "x": -9,
      "y": 6,
      "z": 5,
      "name": "Soil_Dirt_Dry"
    },
    {
      "x": -9,
      "y": 7,
      "z": 5,
      "name": "Soil_Sand_White"
    },
    {
      "x": -9,
      "y": 5,
      "z": 6,
      "name": "Rock_Sandstone"
    },
    {
      "x": -9,
      "y": 6,
      "z": 6,
      "name": "Soil_Dirt_Dry"
    },
    {
      "x": -9,
      "y": 7,
      "z": 6,
      "name": "Soil_Sand_White"
    },
    {
      "x": -9,
      "y": 5,
      "z": 7,
      "name": "Rock_Sandstone"
    },
    {
      "x": -9,
      "y": 6,
      "z": 7,
      "name": "Soil_Dirt_Dry"
    },
    {
      "x": -9,
      "y": 7,
      "z": 7,
      "name": "Soil_Sand_White"
    },
    {
      "x": -9,
      "y": 5,
      "z": 8,
      "name": "Soil_Dirt_Dry"
    },
    {
      "x": -9,
      "y": 6,
      "z": 8,
      "name": "Soil_Dirt_Dry"
    },
    {
      "x": -9,
      "y": 7,
      "z": 8,
      "name": "Soil_Sand_White"
    },
    {
      "x": -9,
      "y": 5,
      "z": 9,
      "name": "Soil_Dirt_Dry"
    },
    {
      "x": -9,
      "y": 6,
      "z": 9,
      "name": "Soil_Dirt_Dry"
    },
    {
      "x": -9,
      "y": 7,
      "z": 9,
      "name": "Soil_Sand_White"
    },
    {
      "x": -9,
      "y": 5,
      "z": 10,
      "name": "Rock_Sandstone"
    },
    {
      "x": -9,
      "y": 6,
      "z": 10,
      "name": "Soil_Sand_White"
    },
    {
      "x": -9,
      "y": 6,
      "z": 11,
      "name": "Soil_Dirt_Dry"
    },
    {
      "x": -8,
      "y": 6,
      "z": -10,
      "name": "Soil_Dirt_Dry"
    },
    {
      "x": -8,
      "y": 6,
      "z": -9,
      "name": "Soil_Dirt_Dry"
    },
    {
      "x": -8,
      "y": 6,
      "z": -8,
      "name": "Soil_Sand_White"
    },
    {
      "x": -8,
      "y": 6,
      "z": -7,
      "name": "Soil_Dirt_Dry"
    },
    {
      "x": -8,
      "y": 7,
      "z": -7,
      "name": "Soil_Sand_White"
    },
    {
      "x": -8,
      "y": 6,
      "z": -6,
      "name": "Soil_Dirt_Dry"
    },
    {
      "x": -8,
      "y": 7,
      "z": -6,
      "name": "Soil_Sand_White"
    },
    {
      "x": -8,
      "y": 6,
      "z": -5,
      "name": "Soil_Sand_White"
    },
    {
      "x": -8,
      "y": 6,
      "z": -4,
      "name": "Soil_Sand_White"
    },
    {
      "x": -8,
      "y": 6,
      "z": -3,
      "name": "Soil_Sand_White"
    },
    {
      "x": -8,
      "y": 6,
      "z": -2,
      "name": "Soil_Sand_White"
    },
    {
      "x": -8,
      "y": 6,
      "z": -1,
      "name": "Soil_Dirt_Dry"
    },
    {
      "x": -8,
      "y": 7,
      "z": -1,
      "name": "Soil_Sand_White"
    },
    {
      "x": -8,
      "y": 6,
      "z": 0,
      "name": "Soil_Dirt_Dry"
    },
    {
      "x": -8,
      "y": 7,
      "z": 0,
      "name": "Soil_Sand_White"
    },
    {
      "x": -8,
      "y": 6,
      "z": 1,
      "name": "Soil_Dirt_Dry"
    },
    {
      "x": -8,
      "y": 7,
      "z": 1,
      "name": "Soil_Sand_White"
    },
    {
      "x": -8,
      "y": 6,
      "z": 2,
      "name": "Soil_Dirt_Dry"
    },
    {
      "x": -8,
      "y": 7,
      "z": 2,
      "name": "Soil_Sand_White"
    },
    {
      "x": -8,
      "y": 6,
      "z": 3,
      "name": "Soil_Dirt_Dry"
    },
    {
      "x": -8,
      "y": 7,
      "z": 3,
      "name": "Soil_Sand_White"
    },
    {
      "x": -8,
      "y": 6,
      "z": 4,
      "name": "Soil_Dirt_Dry"
    },
    {
      "x": -8,
      "y": 7,
      "z": 4,
      "name": "Soil_Dirt_Dry"
    },
    {
      "x": -8,
      "y": 8,
      "z": 4,
      "name": "Soil_Sand_White"
    },
    {
      "x": -8,
      "y": 5,
      "z": 5,
      "name": "Soil_Dirt_Dry"
    },
    {
      "x": -8,
      "y": 6,
      "z": 5,
      "name": "Soil_Dirt_Dry"
    },
    {
      "x": -8,
      "y": 7,
      "z": 5,
      "name": "Soil_Dirt_Dry"
    },
    {
      "x": -8,
      "y": 8,
      "z": 5,
      "name": "Soil_Sand_White"
    },
    {
      "x": -8,
      "y": 5,
      "z": 6,
      "name": "Rock_Sandstone"
    },
    {
      "x": -8,
      "y": 6,
      "z": 6,
      "name": "Soil_Dirt_Dry"
    },
    {
      "x": -8,
      "y": 7,
      "z": 6,
      "name": "Soil_Sand_White"
    },
    {
      "x": -8,
      "y": 5,
      "z": 7,
      "name": "Soil_Dirt_Dry"
    },
    {
      "x": -8,
      "y": 6,
      "z": 7,
      "name": "Soil_Dirt_Dry"
    },
    {
      "x": -8,
      "y": 7,
      "z": 7,
      "name": "Soil_Sand_White"
    },
    {
      "x": -8,
      "y": 2,
      "z": 8,
      "name": "Rock_Sandstone_Stalactite_Large",
      "filler": 31744,
      "rotation": 8
    },
    {
      "x": -8,
      "y": 3,
      "z": 8,
      "name": "Rock_Sandstone_Stalactite_Large",
      "rotation": 8
    },
    {
      "x": -8,
      "y": 4,
      "z": 8,
      "name": "Rock_Sandstone"
    },
    {
      "x": -8,
      "y": 5,
      "z": 8,
      "name": "Soil_Dirt_Dry"
    },
    {
      "x": -8,
      "y": 6,
      "z": 8,
      "name": "Soil_Dirt_Dry"
    },
    {
      "x": -8,
      "y": 7,
      "z": 8,
      "name": "Soil_Sand_White"
    },
    {
      "x": -8,
      "y": 4,
      "z": 9,
      "name": "Rock_Sandstone"
    },
    {
      "x": -8,
      "y": 5,
      "z": 9,
      "name": "Soil_Dirt_Dry"
    },
    {
      "x": -8,
      "y": 6,
      "z": 9,
      "name": "Soil_Dirt_Dry"
    },
    {
      "x": -8,
      "y": 7,
      "z": 9,
      "name": "Soil_Sand_White"
    },
    {
      "x": -8,
      "y": 5,
      "z": 10,
      "name": "Rock_Sandstone"
    },
    {
      "x": -8,
      "y": 6,
      "z": 10,
      "name": "Soil_Sand_White"
    },
    {
      "x": -8,
      "y": 6,
      "z": 11,
      "name": "Soil_Dirt_Dry"
    },
    {
      "x": -8,
      "y": 6,
      "z": 12,
      "name": "Soil_Dirt_Dry"
    },
    {
      "x": -7,
      "y": 6,
      "z": -10,
      "name": "Soil_Dirt_Dry"
    },
    {
      "x": -7,
      "y": 6,
      "z": -9,
      "name": "Soil_Dirt_Dry"
    },
    {
      "x": -7,
      "y": 6,
      "z": -8,
      "name": "Soil_Dirt_Dry"
    },
    {
      "x": -7,
      "y": 7,
      "z": -8,
      "name": "Soil_Sand_White"
    },
    {
      "x": -7,
      "y": 6,
      "z": -7,
      "name": "Soil_Dirt_Dry"
    },
    {
      "x": -7,
      "y": 7,
      "z": -7,
      "name": "Soil_Sand_White"
    },
    {
      "x": -7,
      "y": 6,
      "z": -6,
      "name": "Soil_Dirt_Dry"
    },
    {
      "x": -7,
      "y": 7,
      "z": -6,
      "name": "Soil_Sand_White"
    },
    {
      "x": -7,
      "y": 6,
      "z": -5,
      "name": "Soil_Dirt_Dry"
    },
    {
      "x": -7,
      "y": 7,
      "z": -5,
      "name": "Soil_Sand_White"
    },
    {
      "x": -7,
      "y": 6,
      "z": -4,
      "name": "Soil_Sand_White"
    },
    {
      "x": -7,
      "y": 6,
      "z": -3,
      "name": "Soil_Sand_White"
    },
    {
      "x": -7,
      "y": 6,
      "z": -2,
      "name": "Soil_Dirt_Dry"
    },
    {
      "x": -7,
      "y": 7,
      "z": -2,
      "name": "Soil_Sand_White"
    },
    {
      "x": -7,
      "y": 6,
      "z": -1,
      "name": "Soil_Dirt_Dry"
    },
    {
      "x": -7,
      "y": 7,
      "z": -1,
      "name": "Soil_Sand_White"
    },
    {
      "x": -7,
      "y": 6,
      "z": 0,
      "name": "Soil_Dirt_Dry"
    },
    {
      "x": -7,
      "y": 7,
      "z": 0,
      "name": "Soil_Sand_White"
    },
    {
      "x": -7,
      "y": 6,
      "z": 1,
      "name": "Soil_Dirt_Dry"
    },
    {
      "x": -7,
      "y": 7,
      "z": 1,
      "name": "Soil_Sand_White"
    },
    {
      "x": -7,
      "y": 6,
      "z": 2,
      "name": "Soil_Dirt_Dry"
    },
    {
      "x": -7,
      "y": 7,
      "z": 2,
      "name": "Soil_Sand_White"
    },
    {
      "x": -7,
      "y": 6,
      "z": 3,
      "name": "Soil_Dirt_Dry"
    },
    {
      "x": -7,
      "y": 7,
      "z": 3,
      "name": "Soil_Dirt_Dry"
    },
    {
      "x": -7,
      "y": 8,
      "z": 3,
      "name": "Soil_Sand_White"
    },
    {
      "x": -7,
      "y": 6,
      "z": 4,
      "name": "Soil_Dirt_Dry"
    },
    {
      "x": -7,
      "y": 7,
      "z": 4,
      "name": "Soil_Dirt_Dry"
    },
    {
      "x": -7,
      "y": 8,
      "z": 4,
      "name": "Soil_Sand_White"
    },
    {
      "x": -7,
      "y": 5,
      "z": 5,
      "name": "Rock_Sandstone"
    },
    {
      "x": -7,
      "y": 6,
      "z": 5,
      "name": "Soil_Dirt_Dry"
    },
    {
      "x": -7,
      "y": 7,
      "z": 5,
      "name": "Soil_Dirt_Dry"
    },
    {
      "x": -7,
      "y": 8,
      "z": 5,
      "name": "Soil_Sand_White"
    },
    {
      "x": -7,
      "y": 5,
      "z": 6,
      "name": "Rock_Sandstone"
    },
    {
      "x": -7,
      "y": 6,
      "z": 6,
      "name": "Soil_Dirt_Dry"
    },
    {
      "x": -7,
      "y": 7,
      "z": 6,
      "name": "Soil_Dirt_Dry"
    },
    {
      "x": -7,
      "y": 8,
      "z": 6,
      "name": "Soil_Sand_White"
    },
    {
      "x": -7,
      "y": 5,
      "z": 7,
      "name": "Soil_Dirt_Dry"
    },
    {
      "x": -7,
      "y": 6,
      "z": 7,
      "name": "Soil_Dirt_Dry"
    },
    {
      "x": -7,
      "y": 7,
      "z": 7,
      "name": "Soil_Dirt_Dry"
    },
    {
      "x": -7,
      "y": 8,
      "z": 7,
      "name": "Soil_Sand_White"
    },
    {
      "x": -7,
      "y": 4,
      "z": 8,
      "name": "Rock_Sandstone"
    },
    {
      "x": -7,
      "y": 5,
      "z": 8,
      "name": "Soil_Dirt_Dry"
    },
    {
      "x": -7,
      "y": 6,
      "z": 8,
      "name": "Soil_Dirt_Dry"
    },
    {
      "x": -7,
      "y": 7,
      "z": 8,
      "name": "Soil_Sand_White"
    },
    {
      "x": -7,
      "y": 3,
      "z": 9,
      "name": "Rock_Sandstone_Stalactite_Large",
      "filler": 31744,
      "rotation": 8
    },
    {
      "x": -7,
      "y": 4,
      "z": 9,
      "name": "Rock_Sandstone_Stalactite_Large",
      "rotation": 8
    },
    {
      "x": -7,
      "y": 5,
      "z": 9,
      "name": "Rock_Sandstone"
    },
    {
      "x": -7,
      "y": 6,
      "z": 9,
      "name": "Soil_Dirt_Dry"
    },
    {
      "x": -7,
      "y": 7,
      "z": 9,
      "name": "Soil_Sand_White"
    },
    {
      "x": -7,
      "y": 6,
      "z": 10,
      "name": "Soil_Dirt_Dry"
    },
    {
      "x": -7,
      "y": 7,
      "z": 10,
      "name": "Soil_Sand_White"
    },
    {
      "x": -7,
      "y": 6,
      "z": 11,
      "name": "Soil_Dirt_Dry"
    },
    {
      "x": -7,
      "y": 6,
      "z": 12,
      "name": "Soil_Dirt_Dry"
    },
    {
      "x": -6,
      "y": 6,
      "z": -11,
      "name": "Soil_Dirt_Dry"
    },
    {
      "x": -6,
      "y": 6,
      "z": -10,
      "name": "Soil_Dirt_Dry"
    },
    {
      "x": -6,
      "y": 6,
      "z": -9,
      "name": "Soil_Dirt_Dry"
    },
    {
      "x": -6,
      "y": 6,
      "z": -8,
      "name": "Soil_Dirt_Dry"
    },
    {
      "x": -6,
      "y": 7,
      "z": -8,
      "name": "Soil_Sand_White"
    },
    {
      "x": -6,
      "y": 6,
      "z": -7,
      "name": "Soil_Dirt_Dry"
    },
    {
      "x": -6,
      "y": 7,
      "z": -7,
      "name": "Soil_Sand_White"
    },
    {
      "x": -6,
      "y": 6,
      "z": -6,
      "name": "Soil_Dirt_Dry"
    },
    {
      "x": -6,
      "y": 7,
      "z": -6,
      "name": "Soil_Sand_White"
    },
    {
      "x": -6,
      "y": 6,
      "z": -5,
      "name": "Soil_Dirt_Dry"
    },
    {
      "x": -6,
      "y": 7,
      "z": -5,
      "name": "Soil_Sand_White"
    },
    {
      "x": -6,
      "y": 6,
      "z": -4,
      "name": "Soil_Dirt_Dry"
    },
    {
      "x": -6,
      "y": 7,
      "z": -4,
      "name": "Soil_Sand_White"
    },
    {
      "x": -6,
      "y": 6,
      "z": -3,
      "name": "Soil_Dirt_Dry"
    },
    {
      "x": -6,
      "y": 7,
      "z": -3,
      "name": "Soil_Sand_White"
    },
    {
      "x": -6,
      "y": 6,
      "z": -2,
      "name": "Soil_Dirt_Dry"
    },
    {
      "x": -6,
      "y": 7,
      "z": -2,
      "name": "Soil_Sand_White"
    },
    {
      "x": -6,
      "y": 6,
      "z": -1,
      "name": "Soil_Dirt_Dry"
    },
    {
      "x": -6,
      "y": 7,
      "z": -1,
      "name": "Soil_Sand_White"
    },
    {
      "x": -6,
      "y": 6,
      "z": 0,
      "name": "Soil_Dirt_Dry"
    },
    {
      "x": -6,
      "y": 7,
      "z": 0,
      "name": "Soil_Dirt_Dry"
    },
    {
      "x": -6,
      "y": 8,
      "z": 0,
      "name": "Soil_Sand_White"
    },
    {
      "x": -6,
      "y": 6,
      "z": 1,
      "name": "Soil_Dirt_Dry"
    },
    {
      "x": -6,
      "y": 7,
      "z": 1,
      "name": "Soil_Dirt_Dry"
    },
    {
      "x": -6,
      "y": 8,
      "z": 1,
      "name": "Soil_Sand_White"
    },
    {
      "x": -6,
      "y": 6,
      "z": 2,
      "name": "Soil_Dirt_Dry"
    },
    {
      "x": -6,
      "y": 7,
      "z": 2,
      "name": "Soil_Dirt_Dry"
    },
    {
      "x": -6,
      "y": 8,
      "z": 2,
      "name": "Soil_Sand_White"
    },
    {
      "x": -6,
      "y": 6,
      "z": 3,
      "name": "Soil_Dirt_Dry"
    },
    {
      "x": -6,
      "y": 7,
      "z": 3,
      "name": "Soil_Dirt_Dry"
    },
    {
      "x": -6,
      "y": 8,
      "z": 3,
      "name": "Soil_Sand_White"
    },
    {
      "x": -6,
      "y": 6,
      "z": 4,
      "name": "Soil_Dirt_Dry"
    },
    {
      "x": -6,
      "y": 7,
      "z": 4,
      "name": "Soil_Dirt_Dry"
    },
    {
      "x": -6,
      "y": 8,
      "z": 4,
      "name": "Soil_Sand_White"
    },
    {
      "x": -6,
      "y": 6,
      "z": 5,
      "name": "Soil_Dirt_Dry"
    },
    {
      "x": -6,
      "y": 7,
      "z": 5,
      "name": "Soil_Dirt_Dry"
    },
    {
      "x": -6,
      "y": 8,
      "z": 5,
      "name": "Soil_Sand_White"
    },
    {
      "x": -6,
      "y": 6,
      "z": 6,
      "name": "Soil_Dirt_Dry"
    },
    {
      "x": -6,
      "y": 7,
      "z": 6,
      "name": "Soil_Dirt_Dry"
    },
    {
      "x": -6,
      "y": 8,
      "z": 6,
      "name": "Soil_Sand_White"
    },
    {
      "x": -6,
      "y": 5,
      "z": 7,
      "name": "Rock_Sandstone"
    },
    {
      "x": -6,
      "y": 6,
      "z": 7,
      "name": "Soil_Dirt_Dry"
    },
    {
      "x": -6,
      "y": 7,
      "z": 7,
      "name": "Soil_Dirt_Dry"
    },
    {
      "x": -6,
      "y": 8,
      "z": 7,
      "name": "Soil_Sand_White"
    },
    {
      "x": -6,
      "y": 5,
      "z": 8,
      "name": "Rock_Sandstone"
    },
    {
      "x": -6,
      "y": 6,
      "z": 8,
      "name": "Soil_Dirt_Dry"
    },
    {
      "x": -6,
      "y": 7,
      "z": 8,
      "name": "Soil_Dirt_Dry"
    },
    {
      "x": -6,
      "y": 8,
      "z": 8,
      "name": "Soil_Sand_White"
    },
    {
      "x": -6,
      "y": 5,
      "z": 9,
      "name": "Rock_Sandstone"
    },
    {
      "x": -6,
      "y": 6,
      "z": 9,
      "name": "Soil_Dirt_Dry"
    },
    {
      "x": -6,
      "y": 7,
      "z": 9,
      "name": "Soil_Sand_White"
    },
    {
      "x": -6,
      "y": 6,
      "z": 10,
      "name": "Soil_Dirt_Dry"
    },
    {
      "x": -6,
      "y": 7,
      "z": 10,
      "name": "Soil_Sand_White"
    },
    {
      "x": -6,
      "y": 6,
      "z": 11,
      "name": "Soil_Dirt_Dry"
    },
    {
      "x": -6,
      "y": 7,
      "z": 11,
      "name": "Soil_Sand_White"
    },
    {
      "x": -6,
      "y": 6,
      "z": 12,
      "name": "Soil_Dirt_Dry"
    },
    {
      "x": -5,
      "y": 6,
      "z": -11,
      "name": "Soil_Dirt_Dry"
    },
    {
      "x": -5,
      "y": 6,
      "z": -10,
      "name": "Soil_Dirt_Dry"
    },
    {
      "x": -5,
      "y": 7,
      "z": -10,
      "name": "Soil_Sand_White"
    },
    {
      "x": -5,
      "y": 6,
      "z": -9,
      "name": "Soil_Dirt_Dry"
    },
    {
      "x": -5,
      "y": 7,
      "z": -9,
      "name": "Soil_Sand_White"
    },
    {
      "x": -5,
      "y": 6,
      "z": -8,
      "name": "Soil_Dirt_Dry"
    },
    {
      "x": -5,
      "y": 7,
      "z": -8,
      "name": "Soil_Sand_White"
    },
    {
      "x": -5,
      "y": 6,
      "z": -7,
      "name": "Soil_Dirt_Dry"
    },
    {
      "x": -5,
      "y": 7,
      "z": -7,
      "name": "Soil_Sand_White"
    },
    {
      "x": -5,
      "y": 6,
      "z": -6,
      "name": "Soil_Dirt_Dry"
    },
    {
      "x": -5,
      "y": 7,
      "z": -6,
      "name": "Soil_Sand_White"
    },
    {
      "x": -5,
      "y": 6,
      "z": -5,
      "name": "Soil_Dirt_Dry"
    },
    {
      "x": -5,
      "y": 7,
      "z": -5,
      "name": "Soil_Sand_White"
    },
    {
      "x": -5,
      "y": 6,
      "z": -4,
      "name": "Soil_Dirt_Dry"
    },
    {
      "x": -5,
      "y": 7,
      "z": -4,
      "name": "Soil_Sand_White"
    },
    {
      "x": -5,
      "y": 6,
      "z": -3,
      "name": "Soil_Dirt_Dry"
    },
    {
      "x": -5,
      "y": 7,
      "z": -3,
      "name": "Soil_Dirt_Dry"
    },
    {
      "x": -5,
      "y": 8,
      "z": -3,
      "name": "Soil_Sand_White"
    },
    {
      "x": -5,
      "y": 6,
      "z": -2,
      "name": "Soil_Dirt_Dry"
    },
    {
      "x": -5,
      "y": 7,
      "z": -2,
      "name": "Soil_Dirt_Dry"
    },
    {
      "x": -5,
      "y": 8,
      "z": -2,
      "name": "Soil_Sand_White"
    },
    {
      "x": -5,
      "y": 6,
      "z": -1,
      "name": "Soil_Dirt_Dry"
    },
    {
      "x": -5,
      "y": 7,
      "z": -1,
      "name": "Soil_Dirt_Dry"
    },
    {
      "x": -5,
      "y": 8,
      "z": -1,
      "name": "Soil_Sand_White"
    },
    {
      "x": -5,
      "y": 6,
      "z": 0,
      "name": "Soil_Dirt_Dry"
    },
    {
      "x": -5,
      "y": 7,
      "z": 0,
      "name": "Soil_Dirt_Dry"
    },
    {
      "x": -5,
      "y": 8,
      "z": 0,
      "name": "Soil_Sand_White"
    },
    {
      "x": -5,
      "y": 6,
      "z": 1,
      "name": "Soil_Dirt_Dry"
    },
    {
      "x": -5,
      "y": 7,
      "z": 1,
      "name": "Soil_Dirt_Dry"
    },
    {
      "x": -5,
      "y": 8,
      "z": 1,
      "name": "Soil_Sand_White"
    },
    {
      "x": -5,
      "y": 6,
      "z": 2,
      "name": "Soil_Dirt_Dry"
    },
    {
      "x": -5,
      "y": 7,
      "z": 2,
      "name": "Soil_Dirt_Dry"
    },
    {
      "x": -5,
      "y": 8,
      "z": 2,
      "name": "Soil_Sand_White"
    },
    {
      "x": -5,
      "y": 6,
      "z": 3,
      "name": "Soil_Dirt_Dry"
    },
    {
      "x": -5,
      "y": 7,
      "z": 3,
      "name": "Soil_Dirt_Dry"
    },
    {
      "x": -5,
      "y": 8,
      "z": 3,
      "name": "Soil_Sand_White"
    },
    {
      "x": -5,
      "y": 6,
      "z": 4,
      "name": "Soil_Dirt_Dry"
    },
    {
      "x": -5,
      "y": 7,
      "z": 4,
      "name": "Soil_Dirt_Dry"
    },
    {
      "x": -5,
      "y": 8,
      "z": 4,
      "name": "Soil_Sand_White"
    },
    {
      "x": -5,
      "y": 6,
      "z": 5,
      "name": "Soil_Dirt_Dry"
    },
    {
      "x": -5,
      "y": 7,
      "z": 5,
      "name": "Soil_Dirt_Dry"
    },
    {
      "x": -5,
      "y": 8,
      "z": 5,
      "name": "Soil_Sand_White"
    },
    {
      "x": -5,
      "y": 6,
      "z": 6,
      "name": "Soil_Dirt_Dry"
    },
    {
      "x": -5,
      "y": 7,
      "z": 6,
      "name": "Soil_Dirt_Dry"
    },
    {
      "x": -5,
      "y": 8,
      "z": 6,
      "name": "Soil_Sand_White"
    },
    {
      "x": -5,
      "y": 6,
      "z": 7,
      "name": "Soil_Dirt_Dry"
    },
    {
      "x": -5,
      "y": 7,
      "z": 7,
      "name": "Soil_Dirt_Dry"
    },
    {
      "x": -5,
      "y": 8,
      "z": 7,
      "name": "Soil_Sand_White"
    },
    {
      "x": -5,
      "y": 5,
      "z": 8,
      "name": "Rock_Sandstone"
    },
    {
      "x": -5,
      "y": 6,
      "z": 8,
      "name": "Soil_Dirt_Dry"
    },
    {
      "x": -5,
      "y": 7,
      "z": 8,
      "name": "Soil_Dirt_Dry"
    },
    {
      "x": -5,
      "y": 8,
      "z": 8,
      "name": "Soil_Sand_White"
    },
    {
      "x": -5,
      "y": 4,
      "z": 9,
      "name": "Rock_Sandstone_Stalactite_Small",
      "rotation": 8
    },
    {
      "x": -5,
      "y": 5,
      "z": 9,
      "name": "Rock_Sandstone"
    },
    {
      "x": -5,
      "y": 6,
      "z": 9,
      "name": "Soil_Dirt_Dry"
    },
    {
      "x": -5,
      "y": 7,
      "z": 9,
      "name": "Soil_Sand_White"
    },
    {
      "x": -5,
      "y": 6,
      "z": 10,
      "name": "Soil_Dirt_Dry"
    },
    {
      "x": -5,
      "y": 7,
      "z": 10,
      "name": "Soil_Sand_White"
    },
    {
      "x": -5,
      "y": 6,
      "z": 11,
      "name": "Soil_Dirt_Dry"
    },
    {
      "x": -5,
      "y": 7,
      "z": 11,
      "name": "Soil_Sand_White"
    },
    {
      "x": -5,
      "y": 6,
      "z": 12,
      "name": "Soil_Dirt_Dry"
    },
    {
      "x": -5,
      "y": 6,
      "z": 13,
      "name": "Soil_Dirt_Dry"
    },
    {
      "x": -4,
      "y": 6,
      "z": -12,
      "name": "Soil_Dirt_Dry"
    },
    {
      "x": -4,
      "y": 6,
      "z": -11,
      "name": "Soil_Dirt_Dry"
    },
    {
      "x": -4,
      "y": 6,
      "z": -10,
      "name": "Soil_Dirt_Dry"
    },
    {
      "x": -4,
      "y": 7,
      "z": -10,
      "name": "Soil_Sand_White"
    },
    {
      "x": -4,
      "y": 6,
      "z": -9,
      "name": "Soil_Dirt_Dry"
    },
    {
      "x": -4,
      "y": 7,
      "z": -9,
      "name": "Soil_Sand_White"
    },
    {
      "x": -4,
      "y": 6,
      "z": -8,
      "name": "Soil_Dirt_Dry"
    },
    {
      "x": -4,
      "y": 7,
      "z": -8,
      "name": "Soil_Sand_White"
    },
    {
      "x": -4,
      "y": 6,
      "z": -7,
      "name": "Soil_Dirt_Dry"
    },
    {
      "x": -4,
      "y": 7,
      "z": -7,
      "name": "Soil_Sand_White"
    },
    {
      "x": -4,
      "y": 6,
      "z": -6,
      "name": "Soil_Dirt_Dry"
    },
    {
      "x": -4,
      "y": 7,
      "z": -6,
      "name": "Soil_Sand_White"
    },
    {
      "x": -4,
      "y": 6,
      "z": -5,
      "name": "Soil_Dirt_Dry"
    },
    {
      "x": -4,
      "y": 7,
      "z": -5,
      "name": "Soil_Dirt_Dry"
    },
    {
      "x": -4,
      "y": 8,
      "z": -5,
      "name": "Soil_Sand_White"
    },
    {
      "x": -4,
      "y": 6,
      "z": -4,
      "name": "Soil_Dirt_Dry"
    },
    {
      "x": -4,
      "y": 7,
      "z": -4,
      "name": "Soil_Dirt_Dry"
    },
    {
      "x": -4,
      "y": 8,
      "z": -4,
      "name": "Soil_Sand_White"
    },
    {
      "x": -4,
      "y": 6,
      "z": -3,
      "name": "Soil_Dirt_Dry"
    },
    {
      "x": -4,
      "y": 7,
      "z": -3,
      "name": "Soil_Dirt_Dry"
    },
    {
      "x": -4,
      "y": 8,
      "z": -3,
      "name": "Soil_Sand_White"
    },
    {
      "x": -4,
      "y": 6,
      "z": -2,
      "name": "Soil_Dirt_Dry"
    },
    {
      "x": -4,
      "y": 7,
      "z": -2,
      "name": "Soil_Dirt_Dry"
    },
    {
      "x": -4,
      "y": 8,
      "z": -2,
      "name": "Soil_Sand_White"
    },
    {
      "x": -4,
      "y": 6,
      "z": -1,
      "name": "Soil_Dirt_Dry"
    },
    {
      "x": -4,
      "y": 7,
      "z": -1,
      "name": "Soil_Dirt_Dry"
    },
    {
      "x": -4,
      "y": 8,
      "z": -1,
      "name": "Soil_Sand_White"
    },
    {
      "x": -4,
      "y": 6,
      "z": 0,
      "name": "Soil_Dirt_Dry"
    },
    {
      "x": -4,
      "y": 7,
      "z": 0,
      "name": "Soil_Dirt_Dry"
    },
    {
      "x": -4,
      "y": 8,
      "z": 0,
      "name": "Soil_Sand_White"
    },
    {
      "x": -4,
      "y": 6,
      "z": 1,
      "name": "Soil_Dirt_Dry"
    },
    {
      "x": -4,
      "y": 7,
      "z": 1,
      "name": "Soil_Dirt_Dry"
    },
    {
      "x": -4,
      "y": 8,
      "z": 1,
      "name": "Soil_Sand_White"
    },
    {
      "x": -4,
      "y": 6,
      "z": 2,
      "name": "Soil_Dirt_Dry"
    },
    {
      "x": -4,
      "y": 7,
      "z": 2,
      "name": "Soil_Dirt_Dry"
    },
    {
      "x": -4,
      "y": 8,
      "z": 2,
      "name": "Soil_Sand_White"
    },
    {
      "x": -4,
      "y": 6,
      "z": 3,
      "name": "Soil_Dirt_Dry"
    },
    {
      "x": -4,
      "y": 7,
      "z": 3,
      "name": "Soil_Dirt_Dry"
    },
    {
      "x": -4,
      "y": 8,
      "z": 3,
      "name": "Soil_Sand_White"
    },
    {
      "x": -4,
      "y": 6,
      "z": 4,
      "name": "Soil_Dirt_Dry"
    },
    {
      "x": -4,
      "y": 7,
      "z": 4,
      "name": "Soil_Dirt_Dry"
    },
    {
      "x": -4,
      "y": 8,
      "z": 4,
      "name": "Soil_Sand_White"
    },
    {
      "x": -4,
      "y": 6,
      "z": 5,
      "name": "Soil_Dirt_Dry"
    },
    {
      "x": -4,
      "y": 7,
      "z": 5,
      "name": "Soil_Dirt_Dry"
    },
    {
      "x": -4,
      "y": 8,
      "z": 5,
      "name": "Soil_Sand_White"
    },
    {
      "x": -4,
      "y": 6,
      "z": 6,
      "name": "Soil_Dirt_Dry"
    },
    {
      "x": -4,
      "y": 7,
      "z": 6,
      "name": "Soil_Dirt_Dry"
    },
    {
      "x": -4,
      "y": 8,
      "z": 6,
      "name": "Soil_Sand_White"
    },
    {
      "x": -4,
      "y": 6,
      "z": 7,
      "name": "Soil_Dirt_Dry"
    },
    {
      "x": -4,
      "y": 7,
      "z": 7,
      "name": "Soil_Dirt_Dry"
    },
    {
      "x": -4,
      "y": 8,
      "z": 7,
      "name": "Soil_Sand_White"
    },
    {
      "x": -4,
      "y": 6,
      "z": 8,
      "name": "Soil_Dirt_Dry"
    },
    {
      "x": -4,
      "y": 7,
      "z": 8,
      "name": "Soil_Dirt_Dry"
    },
    {
      "x": -4,
      "y": 8,
      "z": 8,
      "name": "Soil_Sand_White"
    },
    {
      "x": -4,
      "y": 5,
      "z": 9,
      "name": "Rock_Sandstone"
    },
    {
      "x": -4,
      "y": 6,
      "z": 9,
      "name": "Soil_Dirt_Dry"
    },
    {
      "x": -4,
      "y": 7,
      "z": 9,
      "name": "Soil_Sand_White"
    },
    {
      "x": -4,
      "y": 6,
      "z": 10,
      "name": "Soil_Dirt_Dry"
    },
    {
      "x": -4,
      "y": 7,
      "z": 10,
      "name": "Soil_Sand_White"
    },
    {
      "x": -4,
      "y": 6,
      "z": 11,
      "name": "Soil_Dirt_Dry"
    },
    {
      "x": -4,
      "y": 7,
      "z": 11,
      "name": "Soil_Sand_White"
    },
    {
      "x": -4,
      "y": 6,
      "z": 12,
      "name": "Soil_Dirt_Dry"
    },
    {
      "x": -4,
      "y": 7,
      "z": 12,
      "name": "Soil_Sand_White"
    },
    {
      "x": -4,
      "y": 6,
      "z": 13,
      "name": "Soil_Dirt_Dry"
    },
    {
      "x": -4,
      "y": 6,
      "z": 14,
      "name": "Soil_Dirt_Dry"
    },
    {
      "x": -3,
      "y": 6,
      "z": -13,
      "name": "Soil_Dirt_Dry"
    },
    {
      "x": -3,
      "y": 6,
      "z": -12,
      "name": "Soil_Dirt_Dry"
    },
    {
      "x": -3,
      "y": 6,
      "z": -11,
      "name": "Soil_Dirt_Dry"
    },
    {
      "x": -3,
      "y": 7,
      "z": -11,
      "name": "Rock_Sandstone"
    },
    {
      "x": -3,
      "y": 6,
      "z": -10,
      "name": "Soil_Dirt_Dry"
    },
    {
      "x": -3,
      "y": 7,
      "z": -10,
      "name": "Soil_Sand_White"
    },
    {
      "x": -3,
      "y": 6,
      "z": -9,
      "name": "Soil_Dirt_Dry"
    },
    {
      "x": -3,
      "y": 7,
      "z": -9,
      "name": "Soil_Sand_White"
    },
    {
      "x": -3,
      "y": 6,
      "z": -8,
      "name": "Soil_Dirt_Dry"
    },
    {
      "x": -3,
      "y": 7,
      "z": -8,
      "name": "Soil_Sand_White"
    },
    {
      "x": -3,
      "y": 6,
      "z": -7,
      "name": "Soil_Dirt_Dry"
    },
    {
      "x": -3,
      "y": 7,
      "z": -7,
      "name": "Soil_Sand_White"
    },
    {
      "x": -3,
      "y": 6,
      "z": -6,
      "name": "Soil_Dirt_Dry"
    },
    {
      "x": -3,
      "y": 7,
      "z": -6,
      "name": "Soil_Sand_White"
    },
    {
      "x": -3,
      "y": 6,
      "z": -5,
      "name": "Soil_Dirt_Dry"
    },
    {
      "x": -3,
      "y": 7,
      "z": -5,
      "name": "Soil_Dirt_Dry"
    },
    {
      "x": -3,
      "y": 8,
      "z": -5,
      "name": "Soil_Sand_White"
    },
    {
      "x": -3,
      "y": 6,
      "z": -4,
      "name": "Soil_Dirt_Dry"
    },
    {
      "x": -3,
      "y": 7,
      "z": -4,
      "name": "Soil_Dirt_Dry"
    },
    {
      "x": -3,
      "y": 8,
      "z": -4,
      "name": "Soil_Sand_White"
    },
    {
      "x": -3,
      "y": 6,
      "z": -3,
      "name": "Soil_Dirt_Dry"
    },
    {
      "x": -3,
      "y": 7,
      "z": -3,
      "name": "Soil_Dirt_Dry"
    },
    {
      "x": -3,
      "y": 8,
      "z": -3,
      "name": "Soil_Sand_White"
    },
    {
      "x": -3,
      "y": 6,
      "z": -2,
      "name": "Soil_Dirt_Dry"
    },
    {
      "x": -3,
      "y": 7,
      "z": -2,
      "name": "Soil_Dirt_Dry"
    },
    {
      "x": -3,
      "y": 8,
      "z": -2,
      "name": "Soil_Sand_White"
    },
    {
      "x": -3,
      "y": 6,
      "z": -1,
      "name": "Soil_Dirt_Dry"
    },
    {
      "x": -3,
      "y": 7,
      "z": -1,
      "name": "Soil_Dirt_Dry"
    },
    {
      "x": -3,
      "y": 8,
      "z": -1,
      "name": "Soil_Sand_White"
    },
    {
      "x": -3,
      "y": 6,
      "z": 0,
      "name": "Soil_Dirt_Dry"
    },
    {
      "x": -3,
      "y": 7,
      "z": 0,
      "name": "Soil_Dirt_Dry"
    },
    {
      "x": -3,
      "y": 8,
      "z": 0,
      "name": "Soil_Sand_White"
    },
    {
      "x": -3,
      "y": 6,
      "z": 1,
      "name": "Soil_Dirt_Dry"
    },
    {
      "x": -3,
      "y": 7,
      "z": 1,
      "name": "Soil_Dirt_Dry"
    },
    {
      "x": -3,
      "y": 8,
      "z": 1,
      "name": "Soil_Sand_White"
    },
    {
      "x": -3,
      "y": 6,
      "z": 2,
      "name": "Soil_Dirt_Dry"
    },
    {
      "x": -3,
      "y": 7,
      "z": 2,
      "name": "Soil_Dirt_Dry"
    },
    {
      "x": -3,
      "y": 8,
      "z": 2,
      "name": "Soil_Sand_White"
    },
    {
      "x": -3,
      "y": 6,
      "z": 3,
      "name": "Soil_Dirt_Dry"
    },
    {
      "x": -3,
      "y": 7,
      "z": 3,
      "name": "Soil_Dirt_Dry"
    },
    {
      "x": -3,
      "y": 8,
      "z": 3,
      "name": "Soil_Sand_White"
    },
    {
      "x": -3,
      "y": 6,
      "z": 4,
      "name": "Soil_Dirt_Dry"
    },
    {
      "x": -3,
      "y": 7,
      "z": 4,
      "name": "Soil_Dirt_Dry"
    },
    {
      "x": -3,
      "y": 8,
      "z": 4,
      "name": "Soil_Sand_White"
    },
    {
      "x": -3,
      "y": 6,
      "z": 5,
      "name": "Soil_Dirt_Dry"
    },
    {
      "x": -3,
      "y": 7,
      "z": 5,
      "name": "Soil_Dirt_Dry"
    },
    {
      "x": -3,
      "y": 8,
      "z": 5,
      "name": "Soil_Sand_White"
    },
    {
      "x": -3,
      "y": 6,
      "z": 6,
      "name": "Soil_Dirt_Dry"
    },
    {
      "x": -3,
      "y": 7,
      "z": 6,
      "name": "Soil_Dirt_Dry"
    },
    {
      "x": -3,
      "y": 8,
      "z": 6,
      "name": "Soil_Sand_White"
    },
    {
      "x": -3,
      "y": 6,
      "z": 7,
      "name": "Soil_Dirt_Dry"
    },
    {
      "x": -3,
      "y": 7,
      "z": 7,
      "name": "Soil_Dirt_Dry"
    },
    {
      "x": -3,
      "y": 8,
      "z": 7,
      "name": "Soil_Sand_White"
    },
    {
      "x": -3,
      "y": 6,
      "z": 8,
      "name": "Soil_Dirt_Dry"
    },
    {
      "x": -3,
      "y": 7,
      "z": 8,
      "name": "Soil_Dirt_Dry"
    },
    {
      "x": -3,
      "y": 8,
      "z": 8,
      "name": "Soil_Sand_White"
    },
    {
      "x": -3,
      "y": 6,
      "z": 9,
      "name": "Soil_Dirt_Dry"
    },
    {
      "x": -3,
      "y": 7,
      "z": 9,
      "name": "Soil_Dirt_Dry"
    },
    {
      "x": -3,
      "y": 8,
      "z": 9,
      "name": "Soil_Sand_White"
    },
    {
      "x": -3,
      "y": 6,
      "z": 10,
      "name": "Soil_Dirt_Dry"
    },
    {
      "x": -3,
      "y": 7,
      "z": 10,
      "name": "Soil_Sand_White"
    },
    {
      "x": -3,
      "y": 6,
      "z": 11,
      "name": "Soil_Dirt_Dry"
    },
    {
      "x": -3,
      "y": 7,
      "z": 11,
      "name": "Soil_Sand_White"
    },
    {
      "x": -3,
      "y": 6,
      "z": 12,
      "name": "Soil_Dirt_Dry"
    },
    {
      "x": -3,
      "y": 7,
      "z": 12,
      "name": "Soil_Sand_White"
    },
    {
      "x": -3,
      "y": 6,
      "z": 13,
      "name": "Soil_Dirt_Dry"
    },
    {
      "x": -3,
      "y": 6,
      "z": 14,
      "name": "Soil_Dirt_Dry"
    },
    {
      "x": -2,
      "y": 6,
      "z": -13,
      "name": "Soil_Dirt_Dry"
    },
    {
      "x": -2,
      "y": 6,
      "z": -12,
      "name": "Soil_Dirt_Dry"
    },
    {
      "x": -2,
      "y": 6,
      "z": -11,
      "name": "Soil_Dirt_Dry"
    },
    {
      "x": -2,
      "y": 7,
      "z": -11,
      "name": "Rock_Sandstone"
    },
    {
      "x": -2,
      "y": 6,
      "z": -10,
      "name": "Soil_Dirt_Dry"
    },
    {
      "x": -2,
      "y": 7,
      "z": -10,
      "name": "Rock_Sandstone"
    },
    {
      "x": -2,
      "y": 8,
      "z": -10,
      "name": "Rubble_Sandstone"
    },
    {
      "x": -2,
      "y": 6,
      "z": -9,
      "name": "Soil_Dirt_Dry"
    },
    {
      "x": -2,
      "y": 7,
      "z": -9,
      "name": "Soil_Sand_White"
    },
    {
      "x": -2,
      "y": 6,
      "z": -8,
      "name": "Soil_Dirt_Dry"
    },
    {
      "x": -2,
      "y": 7,
      "z": -8,
      "name": "Soil_Sand_White"
    },
    {
      "x": -2,
      "y": 6,
      "z": -7,
      "name": "Soil_Dirt_Dry"
    },
    {
      "x": -2,
      "y": 7,
      "z": -7,
      "name": "Soil_Sand_White"
    },
    {
      "x": -2,
      "y": 6,
      "z": -6,
      "name": "Soil_Dirt_Dry"
    },
    {
      "x": -2,
      "y": 7,
      "z": -6,
      "name": "Soil_Dirt_Dry"
    },
    {
      "x": -2,
      "y": 8,
      "z": -6,
      "name": "Soil_Sand_White"
    },
    {
      "x": -2,
      "y": 6,
      "z": -5,
      "name": "Soil_Dirt_Dry"
    },
    {
      "x": -2,
      "y": 7,
      "z": -5,
      "name": "Soil_Dirt_Dry"
    },
    {
      "x": -2,
      "y": 8,
      "z": -5,
      "name": "Soil_Sand_White"
    },
    {
      "x": -2,
      "y": 6,
      "z": -4,
      "name": "Soil_Dirt_Dry"
    },
    {
      "x": -2,
      "y": 7,
      "z": -4,
      "name": "Soil_Dirt_Dry"
    },
    {
      "x": -2,
      "y": 8,
      "z": -4,
      "name": "Soil_Sand_White"
    },
    {
      "x": -2,
      "y": 6,
      "z": -3,
      "name": "Soil_Dirt_Dry"
    },
    {
      "x": -2,
      "y": 7,
      "z": -3,
      "name": "Soil_Dirt_Dry"
    },
    {
      "x": -2,
      "y": 8,
      "z": -3,
      "name": "Soil_Sand_White"
    },
    {
      "x": -2,
      "y": 6,
      "z": -2,
      "name": "Soil_Dirt_Dry"
    },
    {
      "x": -2,
      "y": 7,
      "z": -2,
      "name": "Soil_Dirt_Dry"
    },
    {
      "x": -2,
      "y": 8,
      "z": -2,
      "name": "Soil_Sand_White"
    },
    {
      "x": -2,
      "y": 6,
      "z": -1,
      "name": "Soil_Dirt_Dry"
    },
    {
      "x": -2,
      "y": 7,
      "z": -1,
      "name": "Soil_Dirt_Dry"
    },
    {
      "x": -2,
      "y": 8,
      "z": -1,
      "name": "Soil_Sand_White"
    },
    {
      "x": -2,
      "y": 6,
      "z": 0,
      "name": "Soil_Dirt_Dry"
    },
    {
      "x": -2,
      "y": 7,
      "z": 0,
      "name": "Soil_Dirt_Dry"
    },
    {
      "x": -2,
      "y": 8,
      "z": 0,
      "name": "Soil_Sand_White"
    },
    {
      "x": -2,
      "y": 6,
      "z": 1,
      "name": "Soil_Dirt_Dry"
    },
    {
      "x": -2,
      "y": 7,
      "z": 1,
      "name": "Soil_Dirt_Dry"
    },
    {
      "x": -2,
      "y": 8,
      "z": 1,
      "name": "Soil_Sand_White"
    },
    {
      "x": -2,
      "y": 6,
      "z": 2,
      "name": "Soil_Dirt_Dry"
    },
    {
      "x": -2,
      "y": 7,
      "z": 2,
      "name": "Soil_Dirt_Dry"
    },
    {
      "x": -2,
      "y": 8,
      "z": 2,
      "name": "Soil_Sand_White"
    },
    {
      "x": -2,
      "y": 6,
      "z": 3,
      "name": "Soil_Dirt_Dry"
    },
    {
      "x": -2,
      "y": 7,
      "z": 3,
      "name": "Soil_Dirt_Dry"
    },
    {
      "x": -2,
      "y": 8,
      "z": 3,
      "name": "Soil_Sand_White"
    },
    {
      "x": -2,
      "y": 6,
      "z": 4,
      "name": "Soil_Dirt_Dry"
    },
    {
      "x": -2,
      "y": 7,
      "z": 4,
      "name": "Soil_Dirt_Dry"
    },
    {
      "x": -2,
      "y": 8,
      "z": 4,
      "name": "Soil_Sand_White"
    },
    {
      "x": -2,
      "y": 6,
      "z": 5,
      "name": "Soil_Dirt_Dry"
    },
    {
      "x": -2,
      "y": 7,
      "z": 5,
      "name": "Soil_Dirt_Dry"
    },
    {
      "x": -2,
      "y": 8,
      "z": 5,
      "name": "Soil_Sand_White"
    },
    {
      "x": -2,
      "y": 6,
      "z": 6,
      "name": "Soil_Dirt_Dry"
    },
    {
      "x": -2,
      "y": 7,
      "z": 6,
      "name": "Soil_Dirt_Dry"
    },
    {
      "x": -2,
      "y": 8,
      "z": 6,
      "name": "Soil_Sand_White"
    },
    {
      "x": -2,
      "y": 6,
      "z": 7,
      "name": "Soil_Dirt_Dry"
    },
    {
      "x": -2,
      "y": 7,
      "z": 7,
      "name": "Soil_Dirt_Dry"
    },
    {
      "x": -2,
      "y": 8,
      "z": 7,
      "name": "Soil_Sand_White"
    },
    {
      "x": -2,
      "y": 6,
      "z": 8,
      "name": "Soil_Dirt_Dry"
    },
    {
      "x": -2,
      "y": 7,
      "z": 8,
      "name": "Soil_Dirt_Dry"
    },
    {
      "x": -2,
      "y": 8,
      "z": 8,
      "name": "Rock_Sandstone"
    },
    {
      "x": -2,
      "y": 6,
      "z": 9,
      "name": "Soil_Dirt_Dry"
    },
    {
      "x": -2,
      "y": 7,
      "z": 9,
      "name": "Soil_Dirt_Dry"
    },
    {
      "x": -2,
      "y": 8,
      "z": 9,
      "name": "Soil_Sand_White"
    },
    {
      "x": -2,
      "y": 6,
      "z": 10,
      "name": "Soil_Dirt_Dry"
    },
    {
      "x": -2,
      "y": 7,
      "z": 10,
      "name": "Soil_Sand_White"
    },
    {
      "x": -2,
      "y": 6,
      "z": 11,
      "name": "Soil_Dirt_Dry"
    },
    {
      "x": -2,
      "y": 7,
      "z": 11,
      "name": "Soil_Sand_White"
    },
    {
      "x": -2,
      "y": 6,
      "z": 12,
      "name": "Soil_Dirt_Dry"
    },
    {
      "x": -2,
      "y": 7,
      "z": 12,
      "name": "Soil_Sand_White"
    },
    {
      "x": -2,
      "y": 6,
      "z": 13,
      "name": "Soil_Dirt_Dry"
    },
    {
      "x": -2,
      "y": 7,
      "z": 13,
      "name": "Soil_Sand_White"
    },
    {
      "x": -2,
      "y": 6,
      "z": 14,
      "name": "Soil_Dirt_Dry"
    },
    {
      "x": -1,
      "y": 6,
      "z": -13,
      "name": "Soil_Dirt_Dry"
    },
    {
      "x": -1,
      "y": 6,
      "z": -12,
      "name": "Soil_Dirt_Dry"
    },
    {
      "x": -1,
      "y": 6,
      "z": -11,
      "name": "Soil_Dirt_Dry"
    },
    {
      "x": -1,
      "y": 7,
      "z": -11,
      "name": "Rubble_Sandstone_Medium"
    },
    {
      "x": -1,
      "y": 6,
      "z": -10,
      "name": "Soil_Dirt_Dry"
    },
    {
      "x": -1,
      "y": 7,
      "z": -10,
      "name": "Rock_Sandstone"
    },
    {
      "x": -1,
      "y": 6,
      "z": -9,
      "name": "Soil_Dirt_Dry"
    },
    {
      "x": -1,
      "y": 7,
      "z": -9,
      "name": "Soil_Sand_White"
    },
    {
      "x": -1,
      "y": 6,
      "z": -8,
      "name": "Rock_Sandstone"
    },
    {
      "x": -1,
      "y": 7,
      "z": -8,
      "name": "Soil_Sand_White"
    },
    {
      "x": -1,
      "y": 6,
      "z": -7,
      "name": "Rock_Sandstone"
    },
    {
      "x": -1,
      "y": 7,
      "z": -7,
      "name": "Soil_Sand_White"
    },
    {
      "x": -1,
      "y": 6,
      "z": -6,
      "name": "Soil_Dirt_Dry"
    },
    {
      "x": -1,
      "y": 7,
      "z": -6,
      "name": "Soil_Dirt_Dry"
    },
    {
      "x": -1,
      "y": 8,
      "z": -6,
      "name": "Soil_Sand_White"
    },
    {
      "x": -1,
      "y": 6,
      "z": -5,
      "name": "Rock_Sandstone"
    },
    {
      "x": -1,
      "y": 7,
      "z": -5,
      "name": "Soil_Dirt_Dry"
    },
    {
      "x": -1,
      "y": 8,
      "z": -5,
      "name": "Soil_Sand_White"
    },
    {
      "x": -1,
      "y": 6,
      "z": -4,
      "name": "Soil_Dirt_Dry"
    },
    {
      "x": -1,
      "y": 7,
      "z": -4,
      "name": "Soil_Dirt_Dry"
    },
    {
      "x": -1,
      "y": 8,
      "z": -4,
      "name": "Soil_Sand_White"
    },
    {
      "x": -1,
      "y": 6,
      "z": -3,
      "name": "Soil_Dirt_Dry"
    },
    {
      "x": -1,
      "y": 7,
      "z": -3,
      "name": "Soil_Dirt_Dry"
    },
    {
      "x": -1,
      "y": 8,
      "z": -3,
      "name": "Soil_Sand_White"
    },
    {
      "x": -1,
      "y": 6,
      "z": -2,
      "name": "Soil_Dirt_Dry"
    },
    {
      "x": -1,
      "y": 7,
      "z": -2,
      "name": "Soil_Dirt_Dry"
    },
    {
      "x": -1,
      "y": 8,
      "z": -2,
      "name": "Soil_Sand_White"
    },
    {
      "x": -1,
      "y": 6,
      "z": -1,
      "name": "Soil_Dirt_Dry"
    },
    {
      "x": -1,
      "y": 7,
      "z": -1,
      "name": "Soil_Dirt_Dry"
    },
    {
      "x": -1,
      "y": 8,
      "z": -1,
      "name": "Soil_Sand_White"
    },
    {
      "x": -1,
      "y": 6,
      "z": 0,
      "name": "Soil_Dirt_Dry"
    },
    {
      "x": -1,
      "y": 7,
      "z": 0,
      "name": "Soil_Dirt_Dry"
    },
    {
      "x": -1,
      "y": 8,
      "z": 0,
      "name": "Soil_Sand_White"
    },
    {
      "x": -1,
      "y": 6,
      "z": 1,
      "name": "Soil_Dirt_Dry"
    },
    {
      "x": -1,
      "y": 7,
      "z": 1,
      "name": "Soil_Dirt_Dry"
    },
    {
      "x": -1,
      "y": 8,
      "z": 1,
      "name": "Soil_Sand_White"
    },
    {
      "x": -1,
      "y": 6,
      "z": 2,
      "name": "Soil_Dirt_Dry"
    },
    {
      "x": -1,
      "y": 7,
      "z": 2,
      "name": "Soil_Dirt_Dry"
    },
    {
      "x": -1,
      "y": 8,
      "z": 2,
      "name": "Soil_Sand_White"
    },
    {
      "x": -1,
      "y": 6,
      "z": 3,
      "name": "Soil_Dirt_Dry"
    },
    {
      "x": -1,
      "y": 7,
      "z": 3,
      "name": "Soil_Dirt_Dry"
    },
    {
      "x": -1,
      "y": 8,
      "z": 3,
      "name": "Soil_Sand_White"
    },
    {
      "x": -1,
      "y": 6,
      "z": 4,
      "name": "Soil_Dirt_Dry"
    },
    {
      "x": -1,
      "y": 7,
      "z": 4,
      "name": "Soil_Dirt_Dry"
    },
    {
      "x": -1,
      "y": 8,
      "z": 4,
      "name": "Soil_Sand_White"
    },
    {
      "x": -1,
      "y": 6,
      "z": 5,
      "name": "Soil_Dirt_Dry"
    },
    {
      "x": -1,
      "y": 7,
      "z": 5,
      "name": "Soil_Dirt_Dry"
    },
    {
      "x": -1,
      "y": 8,
      "z": 5,
      "name": "Soil_Sand_White"
    },
    {
      "x": -1,
      "y": 6,
      "z": 6,
      "name": "Soil_Dirt_Dry"
    },
    {
      "x": -1,
      "y": 7,
      "z": 6,
      "name": "Soil_Dirt_Dry"
    },
    {
      "x": -1,
      "y": 8,
      "z": 6,
      "name": "Soil_Sand_White"
    },
    {
      "x": -1,
      "y": 6,
      "z": 7,
      "name": "Soil_Dirt_Dry"
    },
    {
      "x": -1,
      "y": 7,
      "z": 7,
      "name": "Soil_Dirt_Dry"
    },
    {
      "x": -1,
      "y": 8,
      "z": 7,
      "name": "Rock_Sandstone"
    },
    {
      "x": -1,
      "y": 6,
      "z": 8,
      "name": "Soil_Dirt_Dry"
    },
    {
      "x": -1,
      "y": 7,
      "z": 8,
      "name": "Soil_Dirt_Dry"
    },
    {
      "x": -1,
      "y": 8,
      "z": 8,
      "name": "Rock_Sandstone"
    },
    {
      "x": -1,
      "y": 9,
      "z": 8,
      "name": "Rubble_Sandstone"
    },
    {
      "x": -1,
      "y": 6,
      "z": 9,
      "name": "Soil_Dirt_Dry"
    },
    {
      "x": -1,
      "y": 7,
      "z": 9,
      "name": "Rock_Sandstone"
    },
    {
      "x": -1,
      "y": 8,
      "z": 9,
      "name": "Rock_Sandstone"
    },
    {
      "x": -1,
      "y": 6,
      "z": 10,
      "name": "Soil_Dirt_Dry"
    },
    {
      "x": -1,
      "y": 7,
      "z": 10,
      "name": "Soil_Sand_White"
    },
    {
      "x": -1,
      "y": 6,
      "z": 11,
      "name": "Soil_Dirt_Dry"
    },
    {
      "x": -1,
      "y": 7,
      "z": 11,
      "name": "Soil_Sand_White"
    },
    {
      "x": -1,
      "y": 6,
      "z": 12,
      "name": "Soil_Dirt_Dry"
    },
    {
      "x": -1,
      "y": 7,
      "z": 12,
      "name": "Soil_Sand_White"
    },
    {
      "x": -1,
      "y": 6,
      "z": 13,
      "name": "Soil_Dirt_Dry"
    },
    {
      "x": -1,
      "y": 7,
      "z": 13,
      "name": "Soil_Sand_White"
    },
    {
      "x": -1,
      "y": 6,
      "z": 14,
      "name": "Soil_Dirt_Dry"
    },
    {
      "x": 0,
      "y": 6,
      "z": -13,
      "name": "Soil_Dirt_Dry"
    },
    {
      "x": 0,
      "y": 6,
      "z": -12,
      "name": "Soil_Dirt_Dry"
    },
    {
      "x": 0,
      "y": 6,
      "z": -11,
      "name": "Soil_Dirt_Dry"
    },
    {
      "x": 0,
      "y": 6,
      "z": -10,
      "name": "Soil_Dirt_Dry"
    },
    {
      "x": 0,
      "y": 7,
      "z": -10,
      "name": "Soil_Sand_White"
    },
    {
      "x": 0,
      "y": 6,
      "z": -9,
      "name": "Rock_Sandstone"
    },
    {
      "x": 0,
      "y": 7,
      "z": -9,
      "name": "Soil_Sand_White"
    },
    {
      "x": 0,
      "y": 6,
      "z": -8,
      "name": "Rock_Sandstone"
    },
    {
      "x": 0,
      "y": 7,
      "z": -8,
      "name": "Soil_Sand_White"
    },
    {
      "x": 0,
      "y": 6,
      "z": -7,
      "name": "Rock_Sandstone"
    },
    {
      "x": 0,
      "y": 7,
      "z": -7,
      "name": "Soil_Sand_White"
    },
    {
      "x": 0,
      "y": 6,
      "z": -6,
      "name": "Rock_Sandstone"
    },
    {
      "x": 0,
      "y": 7,
      "z": -6,
      "name": "Soil_Dirt_Dry"
    },
    {
      "x": 0,
      "y": 8,
      "z": -6,
      "name": "Soil_Sand_White"
    },
    {
      "x": 0,
      "y": 6,
      "z": -5,
      "name": "Soil_Dirt_Dry"
    },
    {
      "x": 0,
      "y": 7,
      "z": -5,
      "name": "Soil_Dirt_Dry"
    },
    {
      "x": 0,
      "y": 8,
      "z": -5,
      "name": "Soil_Sand_White"
    },
    {
      "x": 0,
      "y": 6,
      "z": -4,
      "name": "Soil_Dirt_Dry"
    },
    {
      "x": 0,
      "y": 7,
      "z": -4,
      "name": "Soil_Dirt_Dry"
    },
    {
      "x": 0,
      "y": 8,
      "z": -4,
      "name": "Rock_Sandstone"
    },
    {
      "x": 0,
      "y": 6,
      "z": -3,
      "name": "Soil_Dirt_Dry"
    },
    {
      "x": 0,
      "y": 7,
      "z": -3,
      "name": "Soil_Dirt_Dry"
    },
    {
      "x": 0,
      "y": 8,
      "z": -3,
      "name": "Rock_Sandstone"
    },
    {
      "x": 0,
      "y": 6,
      "z": -2,
      "name": "Soil_Dirt_Dry"
    },
    {
      "x": 0,
      "y": 7,
      "z": -2,
      "name": "Soil_Dirt_Dry"
    },
    {
      "x": 0,
      "y": 8,
      "z": -2,
      "name": "Rock_Sandstone"
    },
    {
      "x": 0,
      "y": 9,
      "z": -2,
      "name": "Rubble_Sandstone"
    },
    {
      "x": 0,
      "y": 6,
      "z": -1,
      "name": "Soil_Dirt_Dry"
    },
    {
      "x": 0,
      "y": 7,
      "z": -1,
      "name": "Soil_Dirt_Dry"
    },
    {
      "x": 0,
      "y": 8,
      "z": -1,
      "name": "Soil_Sand_White"
    },
    {
      "x": 0,
      "y": 6,
      "z": 0,
      "name": "Soil_Dirt_Dry"
    },
    {
      "x": 0,
      "y": 7,
      "z": 0,
      "name": "Soil_Dirt_Dry"
    },
    {
      "x": 0,
      "y": 8,
      "z": 0,
      "name": "Soil_Sand_White"
    },
    {
      "x": 0,
      "y": 6,
      "z": 1,
      "name": "Soil_Dirt_Dry"
    },
    {
      "x": 0,
      "y": 7,
      "z": 1,
      "name": "Soil_Dirt_Dry"
    },
    {
      "x": 0,
      "y": 8,
      "z": 1,
      "name": "Soil_Sand_White"
    },
    {
      "x": 0,
      "y": 6,
      "z": 2,
      "name": "Soil_Dirt_Dry"
    },
    {
      "x": 0,
      "y": 7,
      "z": 2,
      "name": "Soil_Dirt_Dry"
    },
    {
      "x": 0,
      "y": 8,
      "z": 2,
      "name": "Soil_Sand_White"
    },
    {
      "x": 0,
      "y": 6,
      "z": 3,
      "name": "Soil_Dirt_Dry"
    },
    {
      "x": 0,
      "y": 7,
      "z": 3,
      "name": "Soil_Dirt_Dry"
    },
    {
      "x": 0,
      "y": 8,
      "z": 3,
      "name": "Soil_Sand_White"
    },
    {
      "x": 0,
      "y": 6,
      "z": 4,
      "name": "Soil_Dirt_Dry"
    },
    {
      "x": 0,
      "y": 7,
      "z": 4,
      "name": "Soil_Dirt_Dry"
    },
    {
      "x": 0,
      "y": 8,
      "z": 4,
      "name": "Soil_Sand_White"
    },
    {
      "x": 0,
      "y": 6,
      "z": 5,
      "name": "Soil_Dirt_Dry"
    },
    {
      "x": 0,
      "y": 7,
      "z": 5,
      "name": "Soil_Dirt_Dry"
    },
    {
      "x": 0,
      "y": 8,
      "z": 5,
      "name": "Soil_Sand_White"
    },
    {
      "x": 0,
      "y": 6,
      "z": 6,
      "name": "Soil_Dirt_Dry"
    },
    {
      "x": 0,
      "y": 7,
      "z": 6,
      "name": "Soil_Dirt_Dry"
    },
    {
      "x": 0,
      "y": 8,
      "z": 6,
      "name": "Soil_Sand_White"
    },
    {
      "x": 0,
      "y": 6,
      "z": 7,
      "name": "Soil_Dirt_Dry"
    },
    {
      "x": 0,
      "y": 7,
      "z": 7,
      "name": "Soil_Dirt_Dry"
    },
    {
      "x": 0,
      "y": 8,
      "z": 7,
      "name": "Soil_Sand_White"
    },
    {
      "x": 0,
      "y": 9,
      "z": 7,
      "name": "Rubble_Sandstone_White"
    },
    {
      "x": 0,
      "y": 6,
      "z": 8,
      "name": "Soil_Dirt_Dry"
    },
    {
      "x": 0,
      "y": 7,
      "z": 8,
      "name": "Soil_Dirt_Dry"
    },
    {
      "x": 0,
      "y": 8,
      "z": 8,
      "name": "Rock_Sandstone"
    },
    {
      "x": 0,
      "y": 6,
      "z": 9,
      "name": "Soil_Dirt_Dry"
    },
    {
      "x": 0,
      "y": 7,
      "z": 9,
      "name": "Rock_Sandstone"
    },
    {
      "x": 0,
      "y": 6,
      "z": 10,
      "name": "Soil_Dirt_Dry"
    },
    {
      "x": 0,
      "y": 7,
      "z": 10,
      "name": "Rock_Sandstone"
    },
    {
      "x": 0,
      "y": 6,
      "z": 11,
      "name": "Soil_Dirt_Dry"
    },
    {
      "x": 0,
      "y": 7,
      "z": 11,
      "name": "Rock_Sandstone"
    },
    {
      "x": 0,
      "y": 6,
      "z": 12,
      "name": "Soil_Dirt_Dry"
    },
    {
      "x": 0,
      "y": 7,
      "z": 12,
      "name": "Soil_Sand_White"
    },
    {
      "x": 0,
      "y": 6,
      "z": 13,
      "name": "Soil_Dirt_Dry"
    },
    {
      "x": 0,
      "y": 7,
      "z": 13,
      "name": "Soil_Sand_White"
    },
    {
      "x": 0,
      "y": 6,
      "z": 14,
      "name": "Soil_Dirt_Dry"
    },
    {
      "x": 0,
      "y": 7,
      "z": 14,
      "name": "Soil_Sand_White"
    },
    {
      "x": 0,
      "y": 6,
      "z": 15,
      "name": "Soil_Dirt_Dry"
    },
    {
      "x": 1,
      "y": 6,
      "z": -12,
      "name": "Soil_Dirt_Dry"
    },
    {
      "x": 1,
      "y": 7,
      "z": -12,
      "name": "Rubble_Sandstone"
    },
    {
      "x": 1,
      "y": 6,
      "z": -11,
      "name": "Soil_Dirt_Dry"
    },
    {
      "x": 1,
      "y": 6,
      "z": -10,
      "name": "Soil_Dirt_Dry"
    },
    {
      "x": 1,
      "y": 7,
      "z": -10,
      "name": "Soil_Sand_White"
    },
    {
      "x": 1,
      "y": 6,
      "z": -9,
      "name": "Soil_Dirt_Dry"
    },
    {
      "x": 1,
      "y": 7,
      "z": -9,
      "name": "Soil_Sand_White"
    },
    {
      "x": 1,
      "y": 6,
      "z": -8,
      "name": "Rock_Sandstone"
    },
    {
      "x": 1,
      "y": 7,
      "z": -8,
      "name": "Soil_Sand_White"
    },
    {
      "x": 1,
      "y": 6,
      "z": -7,
      "name": "Rock_Sandstone"
    },
    {
      "x": 1,
      "y": 7,
      "z": -7,
      "name": "Soil_Sand_White"
    },
    {
      "x": 1,
      "y": 6,
      "z": -6,
      "name": "Soil_Dirt_Dry"
    },
    {
      "x": 1,
      "y": 7,
      "z": -6,
      "name": "Rock_Sandstone"
    },
    {
      "x": 1,
      "y": 6,
      "z": -5,
      "name": "Soil_Dirt_Dry"
    },
    {
      "x": 1,
      "y": 7,
      "z": -5,
      "name": "Rock_Sandstone"
    },
    {
      "x": 1,
      "y": 8,
      "z": -5,
      "name": "Rock_Sandstone"
    },
    {
      "x": 1,
      "y": 6,
      "z": -4,
      "name": "Soil_Dirt_Dry"
    },
    {
      "x": 1,
      "y": 7,
      "z": -4,
      "name": "Soil_Dirt_Dry"
    },
    {
      "x": 1,
      "y": 8,
      "z": -4,
      "name": "Rock_Sandstone"
    },
    {
      "x": 1,
      "y": 6,
      "z": -3,
      "name": "Soil_Dirt_Dry"
    },
    {
      "x": 1,
      "y": 7,
      "z": -3,
      "name": "Soil_Dirt_Dry"
    },
    {
      "x": 1,
      "y": 8,
      "z": -3,
      "name": "Rock_Sandstone"
    },
    {
      "x": 1,
      "y": 9,
      "z": -3,
      "name": "Rubble_Sandstone_Medium"
    },
    {
      "x": 1,
      "y": 6,
      "z": -2,
      "name": "Soil_Dirt_Dry"
    },
    {
      "x": 1,
      "y": 7,
      "z": -2,
      "name": "Soil_Dirt_Dry"
    },
    {
      "x": 1,
      "y": 8,
      "z": -2,
      "name": "Soil_Sand_White"
    },
    {
      "x": 1,
      "y": 9,
      "z": -2,
      "name": "Rubble_Sandstone_White_Medium"
    },
    {
      "x": 1,
      "y": 6,
      "z": -1,
      "name": "Soil_Dirt_Dry"
    },
    {
      "x": 1,
      "y": 7,
      "z": -1,
      "name": "Soil_Dirt_Dry"
    },
    {
      "x": 1,
      "y": 8,
      "z": -1,
      "name": "Soil_Sand_White"
    },
    {
      "x": 1,
      "y": 6,
      "z": 0,
      "name": "Soil_Dirt_Dry"
    },
    {
      "x": 1,
      "y": 7,
      "z": 0,
      "name": "Soil_Dirt_Dry"
    },
    {
      "x": 1,
      "y": 8,
      "z": 0,
      "name": "Soil_Sand_White"
    },
    {
      "x": 1,
      "y": 6,
      "z": 1,
      "name": "Soil_Dirt_Dry"
    },
    {
      "x": 1,
      "y": 7,
      "z": 1,
      "name": "Soil_Dirt_Dry"
    },
    {
      "x": 1,
      "y": 8,
      "z": 1,
      "name": "Soil_Sand_White"
    },
    {
      "x": 1,
      "y": 6,
      "z": 2,
      "name": "Soil_Dirt_Dry"
    },
    {
      "x": 1,
      "y": 7,
      "z": 2,
      "name": "Soil_Dirt_Dry"
    },
    {
      "x": 1,
      "y": 8,
      "z": 2,
      "name": "Soil_Sand_White"
    },
    {
      "x": 1,
      "y": 6,
      "z": 3,
      "name": "Soil_Dirt_Dry"
    },
    {
      "x": 1,
      "y": 7,
      "z": 3,
      "name": "Soil_Dirt_Dry"
    },
    {
      "x": 1,
      "y": 8,
      "z": 3,
      "name": "Soil_Sand_White"
    },
    {
      "x": 1,
      "y": 6,
      "z": 4,
      "name": "Soil_Dirt_Dry"
    },
    {
      "x": 1,
      "y": 7,
      "z": 4,
      "name": "Soil_Dirt_Dry"
    },
    {
      "x": 1,
      "y": 8,
      "z": 4,
      "name": "Soil_Sand_White"
    },
    {
      "x": 1,
      "y": 6,
      "z": 5,
      "name": "Soil_Dirt_Dry"
    },
    {
      "x": 1,
      "y": 7,
      "z": 5,
      "name": "Soil_Dirt_Dry"
    },
    {
      "x": 1,
      "y": 8,
      "z": 5,
      "name": "Soil_Sand_White"
    },
    {
      "x": 1,
      "y": 6,
      "z": 6,
      "name": "Soil_Dirt_Dry"
    },
    {
      "x": 1,
      "y": 7,
      "z": 6,
      "name": "Soil_Dirt_Dry"
    },
    {
      "x": 1,
      "y": 8,
      "z": 6,
      "name": "Soil_Sand_White"
    },
    {
      "x": 1,
      "y": 6,
      "z": 7,
      "name": "Soil_Dirt_Dry"
    },
    {
      "x": 1,
      "y": 7,
      "z": 7,
      "name": "Soil_Dirt_Dry"
    },
    {
      "x": 1,
      "y": 8,
      "z": 7,
      "name": "Soil_Sand_White"
    },
    {
      "x": 1,
      "y": 6,
      "z": 8,
      "name": "Soil_Dirt_Dry"
    },
    {
      "x": 1,
      "y": 7,
      "z": 8,
      "name": "Soil_Dirt_Dry"
    },
    {
      "x": 1,
      "y": 8,
      "z": 8,
      "name": "Rock_Sandstone"
    },
    {
      "x": 1,
      "y": 6,
      "z": 9,
      "name": "Soil_Dirt_Dry"
    },
    {
      "x": 1,
      "y": 7,
      "z": 9,
      "name": "Rock_Sandstone"
    },
    {
      "x": 1,
      "y": 8,
      "z": 9,
      "name": "Rubble_Sandstone_Medium"
    },
    {
      "x": 1,
      "y": 6,
      "z": 10,
      "name": "Soil_Dirt_Dry"
    },
    {
      "x": 1,
      "y": 7,
      "z": 10,
      "name": "Rock_Sandstone"
    },
    {
      "x": 1,
      "y": 6,
      "z": 11,
      "name": "Soil_Dirt_Dry"
    },
    {
      "x": 1,
      "y": 7,
      "z": 11,
      "name": "Soil_Sand_White"
    },
    {
      "x": 1,
      "y": 5,
      "z": 12,
      "name": "Soil_Dirt_Dry"
    },
    {
      "x": 1,
      "y": 6,
      "z": 12,
      "name": "Soil_Dirt_Dry"
    },
    {
      "x": 1,
      "y": 7,
      "z": 12,
      "name": "Soil_Sand_White"
    },
    {
      "x": 1,
      "y": 5,
      "z": 13,
      "name": "Soil_Dirt_Dry"
    },
    {
      "x": 1,
      "y": 6,
      "z": 13,
      "name": "Soil_Dirt_Dry"
    },
    {
      "x": 1,
      "y": 7,
      "z": 13,
      "name": "Soil_Sand_White"
    },
    {
      "x": 1,
      "y": 5,
      "z": 14,
      "name": "Soil_Dirt_Dry"
    },
    {
      "x": 1,
      "y": 6,
      "z": 14,
      "name": "Soil_Dirt_Dry"
    },
    {
      "x": 1,
      "y": 7,
      "z": 14,
      "name": "Soil_Sand_White"
    },
    {
      "x": 1,
      "y": 6,
      "z": 15,
      "name": "Soil_Dirt_Dry"
    },
    {
      "x": 2,
      "y": 6,
      "z": -12,
      "name": "Soil_Dirt_Dry"
    },
    {
      "x": 2,
      "y": 6,
      "z": -11,
      "name": "Soil_Dirt_Dry"
    },
    {
      "x": 2,
      "y": 6,
      "z": -10,
      "name": "Soil_Dirt_Dry"
    },
    {
      "x": 2,
      "y": 6,
      "z": -9,
      "name": "Soil_Dirt_Dry"
    },
    {
      "x": 2,
      "y": 7,
      "z": -9,
      "name": "Soil_Sand_White"
    },
    {
      "x": 2,
      "y": 6,
      "z": -8,
      "name": "Soil_Dirt_Dry"
    },
    {
      "x": 2,
      "y": 7,
      "z": -8,
      "name": "Soil_Sand_White"
    },
    {
      "x": 2,
      "y": 6,
      "z": -7,
      "name": "Soil_Dirt_Dry"
    },
    {
      "x": 2,
      "y": 7,
      "z": -7,
      "name": "Soil_Sand_White"
    },
    {
      "x": 2,
      "y": 6,
      "z": -6,
      "name": "Soil_Dirt_Dry"
    },
    {
      "x": 2,
      "y": 7,
      "z": -6,
      "name": "Soil_Sand_White"
    },
    {
      "x": 2,
      "y": 6,
      "z": -5,
      "name": "Soil_Dirt_Dry"
    },
    {
      "x": 2,
      "y": 7,
      "z": -5,
      "name": "Rock_Sandstone"
    },
    {
      "x": 2,
      "y": 8,
      "z": -5,
      "name": "Rubble_Sandstone_Medium"
    },
    {
      "x": 2,
      "y": 6,
      "z": -4,
      "name": "Soil_Dirt_Dry"
    },
    {
      "x": 2,
      "y": 7,
      "z": -4,
      "name": "Soil_Dirt_Dry"
    },
    {
      "x": 2,
      "y": 8,
      "z": -4,
      "name": "Rock_Sandstone"
    },
    {
      "x": 2,
      "y": 6,
      "z": -3,
      "name": "Soil_Dirt_Dry"
    },
    {
      "x": 2,
      "y": 7,
      "z": -3,
      "name": "Soil_Dirt_Dry"
    },
    {
      "x": 2,
      "y": 8,
      "z": -3,
      "name": "Rock_Sandstone"
    },
    {
      "x": 2,
      "y": 6,
      "z": -2,
      "name": "Soil_Dirt_Dry"
    },
    {
      "x": 2,
      "y": 7,
      "z": -2,
      "name": "Soil_Dirt_Dry"
    },
    {
      "x": 2,
      "y": 8,
      "z": -2,
      "name": "Soil_Sand_White"
    },
    {
      "x": 2,
      "y": 6,
      "z": -1,
      "name": "Soil_Dirt_Dry"
    },
    {
      "x": 2,
      "y": 7,
      "z": -1,
      "name": "Soil_Dirt_Dry"
    },
    {
      "x": 2,
      "y": 8,
      "z": -1,
      "name": "Soil_Sand_White"
    },
    {
      "x": 2,
      "y": 6,
      "z": 0,
      "name": "Soil_Dirt_Dry"
    },
    {
      "x": 2,
      "y": 7,
      "z": 0,
      "name": "Soil_Dirt_Dry"
    },
    {
      "x": 2,
      "y": 8,
      "z": 0,
      "name": "Soil_Sand_White"
    },
    {
      "x": 2,
      "y": 6,
      "z": 1,
      "name": "Soil_Dirt_Dry"
    },
    {
      "x": 2,
      "y": 7,
      "z": 1,
      "name": "Soil_Dirt_Dry"
    },
    {
      "x": 2,
      "y": 8,
      "z": 1,
      "name": "Soil_Sand_White"
    },
    {
      "x": 2,
      "y": 5,
      "z": 2,
      "name": "Soil_Dirt_Dry"
    },
    {
      "x": 2,
      "y": 6,
      "z": 2,
      "name": "Soil_Dirt_Dry"
    },
    {
      "x": 2,
      "y": 7,
      "z": 2,
      "name": "Soil_Dirt_Dry"
    },
    {
      "x": 2,
      "y": 8,
      "z": 2,
      "name": "Soil_Sand_White"
    },
    {
      "x": 2,
      "y": 6,
      "z": 3,
      "name": "Soil_Dirt_Dry"
    },
    {
      "x": 2,
      "y": 7,
      "z": 3,
      "name": "Soil_Dirt_Dry"
    },
    {
      "x": 2,
      "y": 8,
      "z": 3,
      "name": "Soil_Sand_White"
    },
    {
      "x": 2,
      "y": 6,
      "z": 4,
      "name": "Soil_Dirt_Dry"
    },
    {
      "x": 2,
      "y": 7,
      "z": 4,
      "name": "Soil_Dirt_Dry"
    },
    {
      "x": 2,
      "y": 8,
      "z": 4,
      "name": "Soil_Sand_White"
    },
    {
      "x": 2,
      "y": 6,
      "z": 5,
      "name": "Soil_Dirt_Dry"
    },
    {
      "x": 2,
      "y": 7,
      "z": 5,
      "name": "Soil_Dirt_Dry"
    },
    {
      "x": 2,
      "y": 8,
      "z": 5,
      "name": "Soil_Sand_White"
    },
    {
      "x": 2,
      "y": 6,
      "z": 6,
      "name": "Soil_Dirt_Dry"
    },
    {
      "x": 2,
      "y": 7,
      "z": 6,
      "name": "Soil_Dirt_Dry"
    },
    {
      "x": 2,
      "y": 8,
      "z": 6,
      "name": "Soil_Sand_White"
    },
    {
      "x": 2,
      "y": 6,
      "z": 7,
      "name": "Soil_Dirt_Dry"
    },
    {
      "x": 2,
      "y": 7,
      "z": 7,
      "name": "Soil_Dirt_Dry"
    },
    {
      "x": 2,
      "y": 8,
      "z": 7,
      "name": "Soil_Sand_White"
    },
    {
      "x": 2,
      "y": 6,
      "z": 8,
      "name": "Soil_Dirt_Dry"
    },
    {
      "x": 2,
      "y": 7,
      "z": 8,
      "name": "Soil_Sand_White"
    },
    {
      "x": 2,
      "y": 6,
      "z": 9,
      "name": "Soil_Dirt_Dry"
    },
    {
      "x": 2,
      "y": 7,
      "z": 9,
      "name": "Soil_Sand_White"
    },
    {
      "x": 2,
      "y": 6,
      "z": 10,
      "name": "Soil_Dirt_Dry"
    },
    {
      "x": 2,
      "y": 7,
      "z": 10,
      "name": "Soil_Sand_White"
    },
    {
      "x": 2,
      "y": 5,
      "z": 11,
      "name": "Soil_Dirt_Dry"
    },
    {
      "x": 2,
      "y": 6,
      "z": 11,
      "name": "Soil_Dirt_Dry"
    },
    {
      "x": 2,
      "y": 7,
      "z": 11,
      "name": "Soil_Sand_White"
    },
    {
      "x": 2,
      "y": 5,
      "z": 12,
      "name": "Soil_Dirt_Dry"
    },
    {
      "x": 2,
      "y": 6,
      "z": 12,
      "name": "Soil_Dirt_Dry"
    },
    {
      "x": 2,
      "y": 7,
      "z": 12,
      "name": "Soil_Sand_White"
    },
    {
      "x": 2,
      "y": 5,
      "z": 13,
      "name": "Soil_Dirt_Dry"
    },
    {
      "x": 2,
      "y": 6,
      "z": 13,
      "name": "Soil_Dirt_Dry"
    },
    {
      "x": 2,
      "y": 7,
      "z": 13,
      "name": "Soil_Sand_White"
    },
    {
      "x": 2,
      "y": 5,
      "z": 14,
      "name": "Soil_Dirt_Dry"
    },
    {
      "x": 2,
      "y": 6,
      "z": 14,
      "name": "Soil_Dirt_Dry"
    },
    {
      "x": 2,
      "y": 5,
      "z": 15,
      "name": "Soil_Dirt_Dry"
    },
    {
      "x": 2,
      "y": 6,
      "z": 15,
      "name": "Soil_Dirt_Dry"
    },
    {
      "x": 3,
      "y": 6,
      "z": -11,
      "name": "Soil_Dirt_Dry"
    },
    {
      "x": 3,
      "y": 6,
      "z": -10,
      "name": "Soil_Dirt_Dry"
    },
    {
      "x": 3,
      "y": 6,
      "z": -9,
      "name": "Soil_Dirt_Dry"
    },
    {
      "x": 3,
      "y": 7,
      "z": -9,
      "name": "Soil_Sand_White"
    },
    {
      "x": 3,
      "y": 6,
      "z": -8,
      "name": "Soil_Dirt_Dry"
    },
    {
      "x": 3,
      "y": 7,
      "z": -8,
      "name": "Soil_Sand_White"
    },
    {
      "x": 3,
      "y": 6,
      "z": -7,
      "name": "Soil_Dirt_Dry"
    },
    {
      "x": 3,
      "y": 7,
      "z": -7,
      "name": "Soil_Sand_White"
    },
    {
      "x": 3,
      "y": 6,
      "z": -6,
      "name": "Soil_Dirt_Dry"
    },
    {
      "x": 3,
      "y": 7,
      "z": -6,
      "name": "Soil_Sand_White"
    },
    {
      "x": 3,
      "y": 6,
      "z": -5,
      "name": "Soil_Dirt_Dry"
    },
    {
      "x": 3,
      "y": 7,
      "z": -5,
      "name": "Rock_Sandstone"
    },
    {
      "x": 3,
      "y": 6,
      "z": -4,
      "name": "Soil_Dirt_Dry"
    },
    {
      "x": 3,
      "y": 7,
      "z": -4,
      "name": "Soil_Sand_White"
    },
    {
      "x": 3,
      "y": 6,
      "z": -3,
      "name": "Soil_Dirt_Dry"
    },
    {
      "x": 3,
      "y": 7,
      "z": -3,
      "name": "Soil_Sand_White"
    },
    {
      "x": 3,
      "y": 6,
      "z": -2,
      "name": "Soil_Dirt_Dry"
    },
    {
      "x": 3,
      "y": 7,
      "z": -2,
      "name": "Soil_Dirt_Dry"
    },
    {
      "x": 3,
      "y": 8,
      "z": -2,
      "name": "Soil_Sand_White"
    },
    {
      "x": 3,
      "y": 6,
      "z": -1,
      "name": "Soil_Dirt_Dry"
    },
    {
      "x": 3,
      "y": 7,
      "z": -1,
      "name": "Soil_Dirt_Dry"
    },
    {
      "x": 3,
      "y": 8,
      "z": -1,
      "name": "Soil_Sand_White"
    },
    {
      "x": 3,
      "y": 6,
      "z": 0,
      "name": "Soil_Dirt_Dry"
    },
    {
      "x": 3,
      "y": 7,
      "z": 0,
      "name": "Soil_Dirt_Dry"
    },
    {
      "x": 3,
      "y": 8,
      "z": 0,
      "name": "Soil_Sand_White"
    },
    {
      "x": 3,
      "y": 5,
      "z": 1,
      "name": "Soil_Dirt_Dry"
    },
    {
      "x": 3,
      "y": 6,
      "z": 1,
      "name": "Soil_Dirt_Dry"
    },
    {
      "x": 3,
      "y": 7,
      "z": 1,
      "name": "Soil_Dirt_Dry"
    },
    {
      "x": 3,
      "y": 8,
      "z": 1,
      "name": "Soil_Sand_White"
    },
    {
      "x": 3,
      "y": 5,
      "z": 2,
      "name": "Soil_Dirt_Dry"
    },
    {
      "x": 3,
      "y": 6,
      "z": 2,
      "name": "Soil_Dirt_Dry"
    },
    {
      "x": 3,
      "y": 7,
      "z": 2,
      "name": "Soil_Dirt_Dry"
    },
    {
      "x": 3,
      "y": 8,
      "z": 2,
      "name": "Soil_Sand_White"
    },
    {
      "x": 3,
      "y": 5,
      "z": 3,
      "name": "Soil_Dirt_Dry"
    },
    {
      "x": 3,
      "y": 6,
      "z": 3,
      "name": "Soil_Dirt_Dry"
    },
    {
      "x": 3,
      "y": 7,
      "z": 3,
      "name": "Soil_Dirt_Dry"
    },
    {
      "x": 3,
      "y": 8,
      "z": 3,
      "name": "Soil_Sand_White"
    },
    {
      "x": 3,
      "y": 5,
      "z": 4,
      "name": "Soil_Dirt_Dry"
    },
    {
      "x": 3,
      "y": 6,
      "z": 4,
      "name": "Soil_Dirt_Dry"
    },
    {
      "x": 3,
      "y": 7,
      "z": 4,
      "name": "Soil_Dirt_Dry"
    },
    {
      "x": 3,
      "y": 8,
      "z": 4,
      "name": "Soil_Sand_White"
    },
    {
      "x": 3,
      "y": 6,
      "z": 5,
      "name": "Soil_Dirt_Dry"
    },
    {
      "x": 3,
      "y": 7,
      "z": 5,
      "name": "Soil_Dirt_Dry"
    },
    {
      "x": 3,
      "y": 8,
      "z": 5,
      "name": "Soil_Sand_White"
    },
    {
      "x": 3,
      "y": 6,
      "z": 6,
      "name": "Soil_Dirt_Dry"
    },
    {
      "x": 3,
      "y": 7,
      "z": 6,
      "name": "Soil_Dirt_Dry"
    },
    {
      "x": 3,
      "y": 8,
      "z": 6,
      "name": "Soil_Sand_White"
    },
    {
      "x": 3,
      "y": 6,
      "z": 7,
      "name": "Soil_Dirt_Dry"
    },
    {
      "x": 3,
      "y": 7,
      "z": 7,
      "name": "Soil_Sand_White"
    },
    {
      "x": 3,
      "y": 6,
      "z": 8,
      "name": "Soil_Dirt_Dry"
    },
    {
      "x": 3,
      "y": 7,
      "z": 8,
      "name": "Soil_Sand_White"
    },
    {
      "x": 3,
      "y": 5,
      "z": 9,
      "name": "Soil_Dirt_Dry"
    },
    {
      "x": 3,
      "y": 6,
      "z": 9,
      "name": "Soil_Dirt_Dry"
    },
    {
      "x": 3,
      "y": 7,
      "z": 9,
      "name": "Soil_Sand_White"
    },
    {
      "x": 3,
      "y": 5,
      "z": 10,
      "name": "Soil_Dirt_Dry"
    },
    {
      "x": 3,
      "y": 6,
      "z": 10,
      "name": "Soil_Dirt_Dry"
    },
    {
      "x": 3,
      "y": 7,
      "z": 10,
      "name": "Soil_Sand_White"
    },
    {
      "x": 3,
      "y": 5,
      "z": 11,
      "name": "Soil_Dirt_Dry"
    },
    {
      "x": 3,
      "y": 6,
      "z": 11,
      "name": "Soil_Dirt_Dry"
    },
    {
      "x": 3,
      "y": 7,
      "z": 11,
      "name": "Soil_Sand_White"
    },
    {
      "x": 3,
      "y": 5,
      "z": 12,
      "name": "Soil_Dirt_Dry"
    },
    {
      "x": 3,
      "y": 6,
      "z": 12,
      "name": "Soil_Dirt_Dry"
    },
    {
      "x": 3,
      "y": 7,
      "z": 12,
      "name": "Soil_Sand_White"
    },
    {
      "x": 3,
      "y": 5,
      "z": 13,
      "name": "Soil_Dirt_Dry"
    },
    {
      "x": 3,
      "y": 6,
      "z": 13,
      "name": "Soil_Sand_White"
    },
    {
      "x": 3,
      "y": 7,
      "z": 13,
      "name": "Rubble_Sandstone_White_Medium"
    },
    {
      "x": 3,
      "y": 5,
      "z": 14,
      "name": "Soil_Dirt_Dry"
    },
    {
      "x": 3,
      "y": 6,
      "z": 14,
      "name": "Soil_Dirt_Dry"
    },
    {
      "x": 3,
      "y": 5,
      "z": 15,
      "name": "Soil_Dirt_Dry"
    },
    {
      "x": 3,
      "y": 6,
      "z": 15,
      "name": "Soil_Dirt_Dry"
    },
    {
      "x": 3,
      "y": 5,
      "z": 16,
      "name": "Soil_Dirt_Dry"
    },
    {
      "x": 4,
      "y": 6,
      "z": -11,
      "name": "Soil_Dirt_Dry"
    },
    {
      "x": 4,
      "y": 6,
      "z": -10,
      "name": "Soil_Dirt_Dry"
    },
    {
      "x": 4,
      "y": 6,
      "z": -9,
      "name": "Soil_Dirt_Dry"
    },
    {
      "x": 4,
      "y": 6,
      "z": -8,
      "name": "Soil_Dirt_Dry"
    },
    {
      "x": 4,
      "y": 7,
      "z": -8,
      "name": "Soil_Sand_White"
    },
    {
      "x": 4,
      "y": 6,
      "z": -7,
      "name": "Soil_Dirt_Dry"
    },
    {
      "x": 4,
      "y": 7,
      "z": -7,
      "name": "Soil_Sand_White"
    },
    {
      "x": 4,
      "y": 5,
      "z": -6,
      "name": "Soil_Dirt_Dry"
    },
    {
      "x": 4,
      "y": 6,
      "z": -6,
      "name": "Soil_Dirt_Dry"
    },
    {
      "x": 4,
      "y": 7,
      "z": -6,
      "name": "Soil_Sand_White"
    },
    {
      "x": 4,
      "y": 6,
      "z": -5,
      "name": "Soil_Dirt_Dry"
    },
    {
      "x": 4,
      "y": 7,
      "z": -5,
      "name": "Soil_Sand_White"
    },
    {
      "x": 4,
      "y": 5,
      "z": -4,
      "name": "Soil_Dirt_Dry"
    },
    {
      "x": 4,
      "y": 6,
      "z": -4,
      "name": "Soil_Dirt_Dry"
    },
    {
      "x": 4,
      "y": 7,
      "z": -4,
      "name": "Soil_Sand_White"
    },
    {
      "x": 4,
      "y": 5,
      "z": -3,
      "name": "Soil_Dirt_Dry"
    },
    {
      "x": 4,
      "y": 6,
      "z": -3,
      "name": "Soil_Dirt_Dry"
    },
    {
      "x": 4,
      "y": 7,
      "z": -3,
      "name": "Soil_Sand_White"
    },
    {
      "x": 4,
      "y": 5,
      "z": -2,
      "name": "Soil_Dirt_Dry"
    },
    {
      "x": 4,
      "y": 6,
      "z": -2,
      "name": "Soil_Dirt_Dry"
    },
    {
      "x": 4,
      "y": 7,
      "z": -2,
      "name": "Soil_Sand_White"
    },
    {
      "x": 4,
      "y": 5,
      "z": -1,
      "name": "Soil_Dirt_Dry"
    },
    {
      "x": 4,
      "y": 6,
      "z": -1,
      "name": "Soil_Dirt_Dry"
    },
    {
      "x": 4,
      "y": 7,
      "z": -1,
      "name": "Soil_Sand_White"
    },
    {
      "x": 4,
      "y": 5,
      "z": 0,
      "name": "Soil_Dirt_Dry"
    },
    {
      "x": 4,
      "y": 6,
      "z": 0,
      "name": "Soil_Dirt_Dry"
    },
    {
      "x": 4,
      "y": 7,
      "z": 0,
      "name": "Soil_Sand_White"
    },
    {
      "x": 4,
      "y": 5,
      "z": 1,
      "name": "Soil_Dirt_Dry"
    },
    {
      "x": 4,
      "y": 6,
      "z": 1,
      "name": "Soil_Dirt_Dry"
    },
    {
      "x": 4,
      "y": 7,
      "z": 1,
      "name": "Soil_Dirt_Dry"
    },
    {
      "x": 4,
      "y": 8,
      "z": 1,
      "name": "Soil_Sand_White"
    },
    {
      "x": 4,
      "y": 5,
      "z": 2,
      "name": "Soil_Dirt_Dry"
    },
    {
      "x": 4,
      "y": 6,
      "z": 2,
      "name": "Soil_Dirt_Dry"
    },
    {
      "x": 4,
      "y": 7,
      "z": 2,
      "name": "Soil_Dirt_Dry"
    },
    {
      "x": 4,
      "y": 8,
      "z": 2,
      "name": "Soil_Sand_White"
    },
    {
      "x": 4,
      "y": 5,
      "z": 3,
      "name": "Soil_Dirt_Dry"
    },
    {
      "x": 4,
      "y": 6,
      "z": 3,
      "name": "Soil_Dirt_Dry"
    },
    {
      "x": 4,
      "y": 7,
      "z": 3,
      "name": "Soil_Dirt_Dry"
    },
    {
      "x": 4,
      "y": 8,
      "z": 3,
      "name": "Soil_Sand_White"
    },
    {
      "x": 4,
      "y": 5,
      "z": 4,
      "name": "Soil_Dirt_Dry"
    },
    {
      "x": 4,
      "y": 6,
      "z": 4,
      "name": "Soil_Dirt_Dry"
    },
    {
      "x": 4,
      "y": 7,
      "z": 4,
      "name": "Soil_Dirt_Dry"
    },
    {
      "x": 4,
      "y": 8,
      "z": 4,
      "name": "Soil_Sand_White"
    },
    {
      "x": 4,
      "y": 5,
      "z": 5,
      "name": "Soil_Dirt_Dry"
    },
    {
      "x": 4,
      "y": 6,
      "z": 5,
      "name": "Soil_Dirt_Dry"
    },
    {
      "x": 4,
      "y": 7,
      "z": 5,
      "name": "Soil_Sand_White"
    },
    {
      "x": 4,
      "y": 5,
      "z": 6,
      "name": "Soil_Dirt_Dry"
    },
    {
      "x": 4,
      "y": 6,
      "z": 6,
      "name": "Soil_Dirt_Dry"
    },
    {
      "x": 4,
      "y": 7,
      "z": 6,
      "name": "Soil_Sand_White"
    },
    {
      "x": 4,
      "y": 5,
      "z": 7,
      "name": "Soil_Dirt_Dry"
    },
    {
      "x": 4,
      "y": 6,
      "z": 7,
      "name": "Soil_Dirt_Dry"
    },
    {
      "x": 4,
      "y": 7,
      "z": 7,
      "name": "Soil_Sand_White"
    },
    {
      "x": 4,
      "y": 5,
      "z": 8,
      "name": "Soil_Dirt_Dry"
    },
    {
      "x": 4,
      "y": 6,
      "z": 8,
      "name": "Soil_Dirt_Dry"
    },
    {
      "x": 4,
      "y": 7,
      "z": 8,
      "name": "Soil_Sand_White"
    },
    {
      "x": 4,
      "y": 5,
      "z": 9,
      "name": "Soil_Dirt_Dry"
    },
    {
      "x": 4,
      "y": 6,
      "z": 9,
      "name": "Soil_Dirt_Dry"
    },
    {
      "x": 4,
      "y": 7,
      "z": 9,
      "name": "Soil_Sand_White"
    },
    {
      "x": 4,
      "y": 5,
      "z": 10,
      "name": "Soil_Dirt_Dry"
    },
    {
      "x": 4,
      "y": 6,
      "z": 10,
      "name": "Soil_Dirt_Dry"
    },
    {
      "x": 4,
      "y": 7,
      "z": 10,
      "name": "Soil_Sand_White"
    },
    {
      "x": 4,
      "y": 5,
      "z": 11,
      "name": "Soil_Dirt_Dry"
    },
    {
      "x": 4,
      "y": 6,
      "z": 11,
      "name": "Soil_Dirt_Dry"
    },
    {
      "x": 4,
      "y": 7,
      "z": 11,
      "name": "Soil_Sand_White"
    },
    {
      "x": 4,
      "y": 5,
      "z": 12,
      "name": "Soil_Dirt_Dry"
    },
    {
      "x": 4,
      "y": 6,
      "z": 12,
      "name": "Soil_Sand_White"
    },
    {
      "x": 4,
      "y": 5,
      "z": 13,
      "name": "Soil_Dirt_Dry"
    },
    {
      "x": 4,
      "y": 6,
      "z": 13,
      "name": "Soil_Dirt_Dry"
    },
    {
      "x": 4,
      "y": 5,
      "z": 14,
      "name": "Soil_Dirt_Dry"
    },
    {
      "x": 4,
      "y": 6,
      "z": 14,
      "name": "Soil_Dirt_Dry"
    },
    {
      "x": 4,
      "y": 5,
      "z": 15,
      "name": "Soil_Dirt_Dry"
    },
    {
      "x": 4,
      "y": 6,
      "z": 15,
      "name": "Soil_Dirt_Dry"
    },
    {
      "x": 4,
      "y": 5,
      "z": 16,
      "name": "Soil_Dirt_Dry"
    },
    {
      "x": 5,
      "y": 6,
      "z": -9,
      "name": "Soil_Dirt_Dry"
    },
    {
      "x": 5,
      "y": 6,
      "z": -8,
      "name": "Soil_Sand_White"
    },
    {
      "x": 5,
      "y": 6,
      "z": -7,
      "name": "Soil_Dirt_Dry"
    },
    {
      "x": 5,
      "y": 7,
      "z": -7,
      "name": "Soil_Sand_White"
    },
    {
      "x": 5,
      "y": 5,
      "z": -6,
      "name": "Soil_Dirt_Dry"
    },
    {
      "x": 5,
      "y": 6,
      "z": -6,
      "name": "Soil_Dirt_Dry"
    },
    {
      "x": 5,
      "y": 7,
      "z": -6,
      "name": "Soil_Sand_White"
    },
    {
      "x": 5,
      "y": 5,
      "z": -5,
      "name": "Soil_Dirt_Dry"
    },
    {
      "x": 5,
      "y": 6,
      "z": -5,
      "name": "Soil_Dirt_Dry"
    },
    {
      "x": 5,
      "y": 7,
      "z": -5,
      "name": "Soil_Sand_White"
    },
    {
      "x": 5,
      "y": 5,
      "z": -4,
      "name": "Soil_Dirt_Dry"
    },
    {
      "x": 5,
      "y": 6,
      "z": -4,
      "name": "Soil_Dirt_Dry"
    },
    {
      "x": 5,
      "y": 7,
      "z": -4,
      "name": "Soil_Sand_White"
    },
    {
      "x": 5,
      "y": 5,
      "z": -3,
      "name": "Soil_Dirt_Dry"
    },
    {
      "x": 5,
      "y": 6,
      "z": -3,
      "name": "Soil_Dirt_Dry"
    },
    {
      "x": 5,
      "y": 7,
      "z": -3,
      "name": "Soil_Sand_White"
    },
    {
      "x": 5,
      "y": 5,
      "z": -2,
      "name": "Soil_Dirt_Dry"
    },
    {
      "x": 5,
      "y": 6,
      "z": -2,
      "name": "Soil_Dirt_Dry"
    },
    {
      "x": 5,
      "y": 7,
      "z": -2,
      "name": "Soil_Sand_White"
    },
    {
      "x": 5,
      "y": 5,
