{
  "version": 8,
  "blockIdVersion": 8,
  "anchorX": 0,
  "anchorY": 9,
  "anchorZ": 0,
  "blocks": [
    {
      "x": -12,
      "y": 7,
      "z": -3,
      "name": "Plant_Coral_Block_Red"
    },
    {
      "x": -12,
      "y": 8,
      "z": -3,
      "name": "Plant_Coral_Block_Red"
    },
    {
      "x": -12,
      "y": 6,
      "z": -2,
      "name": "Plant_Coral_Block_Yellow"
    },
    {
      "x": -12,
      "y": 7,
      "z": -2,
      "name": "Plant_Coral_Block_Yellow"
    },
    {
      "x": -12,
      "y": 8,
      "z": -2,
      "name": "Plant_Coral_Block_Red"
    },
    {
      "x": -12,
      "y": 9,
      "z": -2,
      "name": "Plant_Coral_Block_Red"
    },
    {
      "x": -12,
      "y": 6,
      "z": -1,
      "name": "Plant_Coral_Block_Yellow"
    },
    {
      "x": -12,
      "y": 7,
      "z": -1,
      "name": "Plant_Coral_Block_Yellow"
    },
    {
      "x": -12,
      "y": 8,
      "z": -1,
      "name": "Plant_Coral_Block_Red"
    },
    {
      "x": -12,
      "y": 9,
      "z": -1,
      "name": "Plant_Coral_Block_Red"
    },
    {
      "x": -12,
      "y": 6,
      "z": 0,
      "name": "Plant_Coral_Block_Yellow"
    },
    {
      "x": -12,
      "y": 7,
      "z": 0,
      "name": "Plant_Coral_Block_Yellow"
    },
    {
      "x": -12,
      "y": 8,
      "z": 0,
      "name": "Plant_Coral_Block_Red"
    },
    {
      "x": -12,
      "y": 9,
      "z": 0,
      "name": "Plant_Coral_Block_Red"
    },
    {
      "x": -12,
      "y": 6,
      "z": 1,
      "name": "Plant_Coral_Block_Yellow"
    },
    {
      "x": -12,
      "y": 7,
      "z": 1,
      "name": "Plant_Coral_Block_Yellow"
    },
    {
      "x": -12,
      "y": 8,
      "z": 1,
      "name": "Plant_Coral_Block_Red"
    },
    {
      "x": -12,
      "y": 9,
      "z": 1,
      "name": "Plant_Coral_Block_Red"
    },
    {
      "x": -12,
      "y": 6,
      "z": 2,
      "name": "Plant_Coral_Block_Yellow"
    },
    {
      "x": -12,
      "y": 7,
      "z": 2,
      "name": "Plant_Coral_Block_Yellow"
    },
    {
      "x": -12,
      "y": 8,
      "z": 2,
      "name": "Plant_Coral_Block_Yellow"
    },
    {
      "x": -12,
      "y": 7,
      "z": 3,
      "name": "Plant_Coral_Block_Yellow"
    },
    {
      "x": -11,
      "y": 6,
      "z": -5,
      "name": "Plant_Coral_Block_Yellow"
    },
    {
      "x": -11,
      "y": 7,
      "z": -5,
      "name": "Plant_Coral_Block_Yellow"
    },
    {
      "x": -11,
      "y": 8,
      "z": -5,
      "name": "Plant_Coral_Block_Yellow"
    },
    {
      "x": -11,
      "y": 6,
      "z": -4,
      "name": "Plant_Coral_Block_Yellow"
    },
    {
      "x": -11,
      "y": 7,
      "z": -4,
      "name": "Plant_Coral_Block_Yellow"
    },
    {
      "x": -11,
      "y": 8,
      "z": -4,
      "name": "Plant_Coral_Block_Yellow"
    },
    {
      "x": -11,
      "y": 5,
      "z": -3,
      "name": "Plant_Coral_Block_Yellow"
    },
    {
      "x": -11,
      "y": 6,
      "z": -3,
      "name": "Plant_Coral_Block_Yellow"
    },
    {
      "x": -11,
      "y": 7,
      "z": -3,
      "name": "Plant_Coral_Block_Yellow"
    },
    {
      "x": -11,
      "y": 8,
      "z": -3,
      "name": "Plant_Coral_Block_Yellow"
    },
    {
      "x": -11,
      "y": 9,
      "z": -3,
      "name": "Plant_Coral_Block_Red"
    },
    {
      "x": -11,
      "y": 10,
      "z": -3,
      "name": "Plant_Coral_Block_Red"
    },
    {
      "x": -11,
      "y": 5,
      "z": -2,
      "name": "Plant_Coral_Block_Yellow"
    },
    {
      "x": -11,
      "y": 6,
      "z": -2,
      "name": "Plant_Coral_Block_Yellow"
    },
    {
      "x": -11,
      "y": 7,
      "z": -2,
      "name": "Plant_Coral_Block_Yellow"
    },
    {
      "x": -11,
      "y": 8,
      "z": -2,
      "name": "Plant_Coral_Block_Yellow"
    },
    {
      "x": -11,
      "y": 9,
      "z": -2,
      "name": "Plant_Coral_Block_Yellow"
    },
    {
      "x": -11,
      "y": 5,
      "z": -1,
      "name": "Plant_Coral_Block_Yellow"
    },
    {
      "x": -11,
      "y": 6,
      "z": -1,
      "name": "Plant_Coral_Block_Yellow"
    },
    {
      "x": -11,
      "y": 7,
      "z": -1,
      "name": "Plant_Coral_Block_Yellow"
    },
    {
      "x": -11,
      "y": 8,
      "z": -1,
      "name": "Plant_Coral_Block_Yellow"
    },
    {
      "x": -11,
      "y": 9,
      "z": -1,
      "name": "Plant_Coral_Block_Yellow"
    },
    {
      "x": -11,
      "y": 5,
      "z": 0,
      "name": "Plant_Coral_Block_Yellow"
    },
    {
      "x": -11,
      "y": 6,
      "z": 0,
      "name": "Plant_Coral_Block_Yellow"
    },
    {
      "x": -11,
      "y": 7,
      "z": 0,
      "name": "Plant_Coral_Block_Yellow"
    },
    {
      "x": -11,
      "y": 8,
      "z": 0,
      "name": "Plant_Coral_Block_Yellow"
    },
    {
      "x": -11,
      "y": 9,
      "z": 0,
      "name": "Plant_Coral_Block_Yellow"
    },
    {
      "x": -11,
      "y": 5,
      "z": 1,
      "name": "Plant_Coral_Block_Yellow"
    },
    {
      "x": -11,
      "y": 6,
      "z": 1,
      "name": "Plant_Coral_Block_Yellow"
    },
    {
      "x": -11,
      "y": 7,
      "z": 1,
      "name": "Plant_Coral_Block_Yellow"
    },
    {
      "x": -11,
      "y": 8,
      "z": 1,
      "name": "Plant_Coral_Block_Yellow"
    },
    {
      "x": -11,
      "y": 9,
      "z": 1,
      "name": "Plant_Coral_Block_Yellow"
    },
    {
      "x": -11,
      "y": 5,
      "z": 2,
      "name": "Plant_Coral_Block_Yellow"
    },
    {
      "x": -11,
      "y": 6,
      "z": 2,
      "name": "Plant_Coral_Block_Yellow"
    },
    {
      "x": -11,
      "y": 7,
      "z": 2,
      "name": "Plant_Coral_Block_Yellow"
    },
    {
      "x": -11,
      "y": 8,
      "z": 2,
      "name": "Plant_Coral_Block_Yellow"
    },
    {
      "x": -11,
      "y": 9,
      "z": 2,
      "name": "Plant_Coral_Block_Yellow"
    },
    {
      "x": -11,
      "y": 5,
      "z": 3,
      "name": "Plant_Coral_Block_Yellow"
    },
    {
      "x": -11,
      "y": 6,
      "z": 3,
      "name": "Plant_Coral_Block_Yellow"
    },
    {
      "x": -11,
      "y": 7,
      "z": 3,
      "name": "Plant_Coral_Block_Yellow"
    },
    {
      "x": -11,
      "y": 8,
      "z": 3,
      "name": "Plant_Coral_Block_Red"
    },
    {
      "x": -11,
      "y": 9,
      "z": 3,
      "name": "Plant_Coral_Block_Red"
    },
    {
      "x": -11,
      "y": 10,
      "z": 3,
      "name": "Plant_Coral_Block_Red"
    },
    {
      "x": -11,
      "y": 6,
      "z": 4,
      "name": "Plant_Coral_Block_Yellow"
    },
    {
      "x": -11,
      "y": 7,
      "z": 4,
      "name": "Plant_Coral_Block_Yellow"
    },
    {
      "x": -11,
      "y": 8,
      "z": 4,
      "name": "Plant_Coral_Block_Red"
    },
    {
      "x": -11,
      "y": 9,
      "z": 4,
      "name": "Plant_Coral_Block_Red"
    },
    {
      "x": -11,
      "y": 6,
      "z": 5,
      "name": "Plant_Coral_Block_Yellow"
    },
    {
      "x": -11,
      "y": 7,
      "z": 5,
      "name": "Plant_Coral_Block_Yellow"
    },
    {
      "x": -11,
      "y": 8,
      "z": 5,
      "name": "Plant_Coral_Block_Red"
    },
    {
      "x": -11,
      "y": 9,
      "z": 5,
      "name": "Plant_Coral_Block_Red"
    },
    {
      "x": -10,
      "y": 7,
      "z": -7,
      "name": "Plant_Coral_Block_Yellow"
    },
    {
      "x": -10,
      "y": 6,
      "z": -6,
      "name": "Plant_Coral_Block_Yellow"
    },
    {
      "x": -10,
      "y": 7,
      "z": -6,
      "name": "Plant_Coral_Block_Yellow"
    },
    {
      "x": -10,
      "y": 8,
      "z": -6,
      "name": "Plant_Coral_Block_Red"
    },
    {
      "x": -10,
      "y": 9,
      "z": -6,
      "name": "Plant_Coral_Block_Red"
    },
    {
      "x": -10,
      "y": 5,
      "z": -5,
      "name": "Plant_Coral_Block_Yellow"
    },
    {
      "x": -10,
      "y": 6,
      "z": -5,
      "name": "Plant_Coral_Block_Yellow"
    },
    {
      "x": -10,
      "y": 7,
      "z": -5,
      "name": "Plant_Coral_Block_Yellow"
    },
    {
      "x": -10,
      "y": 8,
      "z": -5,
      "name": "Plant_Coral_Block_Yellow"
    },
    {
      "x": -10,
      "y": 9,
      "z": -5,
      "name": "Plant_Coral_Block_Red"
    },
    {
      "x": -10,
      "y": 10,
      "z": -5,
      "name": "Plant_Coral_Block_Red"
    },
    {
      "x": -10,
      "y": 5,
      "z": -4,
      "name": "Plant_Coral_Block_Yellow"
    },
    {
      "x": -10,
      "y": 6,
      "z": -4,
      "name": "Plant_Coral_Block_Yellow"
    },
    {
      "x": -10,
      "y": 7,
      "z": -4,
      "name": "Plant_Coral_Block_Yellow"
    },
    {
      "x": -10,
      "y": 8,
      "z": -4,
      "name": "Plant_Coral_Block_Yellow"
    },
    {
      "x": -10,
      "y": 9,
      "z": -4,
      "name": "Plant_Coral_Block_Red"
    },
    {
      "x": -10,
      "y": 10,
      "z": -4,
      "name": "Plant_Coral_Block_Red"
    },
    {
      "x": -10,
      "y": 5,
      "z": -3,
      "name": "Plant_Coral_Block_Yellow"
    },
    {
      "x": -10,
      "y": 6,
      "z": -3,
      "name": "Plant_Coral_Block_Yellow"
    },
    {
      "x": -10,
      "y": 7,
      "z": -3,
      "name": "Plant_Coral_Block_Yellow"
    },
    {
      "x": -10,
      "y": 8,
      "z": -3,
      "name": "Plant_Coral_Block_Yellow"
    },
    {
      "x": -10,
      "y": 9,
      "z": -3,
      "name": "Plant_Coral_Block_Red"
    },
    {
      "x": -10,
      "y": 10,
      "z": -3,
      "name": "Plant_Coral_Block_Red"
    },
    {
      "x": -10,
      "y": 4,
      "z": -2,
      "name": "Plant_Coral_Block_Yellow"
    },
    {
      "x": -10,
      "y": 5,
      "z": -2,
      "name": "Plant_Coral_Block_Yellow"
    },
    {
      "x": -10,
      "y": 6,
      "z": -2,
      "name": "Plant_Coral_Block_Yellow"
    },
    {
      "x": -10,
      "y": 7,
      "z": -2,
      "name": "Plant_Coral_Block_Yellow"
    },
    {
      "x": -10,
      "y": 8,
      "z": -2,
      "name": "Plant_Coral_Block_Yellow"
    },
    {
      "x": -10,
      "y": 9,
      "z": -2,
      "name": "Plant_Coral_Block_Yellow"
    },
    {
      "x": -10,
      "y": 10,
      "z": -2,
      "name": "Plant_Coral_Block_Red"
    },
    {
      "x": -10,
      "y": 11,
      "z": -2,
      "name": "Plant_Coral_Block_Red"
    },
    {
      "x": -10,
      "y": 4,
      "z": -1,
      "name": "Plant_Coral_Block_Yellow"
    },
    {
      "x": -10,
      "y": 5,
      "z": -1,
      "name": "Plant_Coral_Block_Yellow"
    },
    {
      "x": -10,
      "y": 6,
      "z": -1,
      "name": "Plant_Coral_Block_Yellow"
    },
    {
      "x": -10,
      "y": 7,
      "z": -1,
      "name": "Plant_Coral_Block_Yellow"
    },
    {
      "x": -10,
      "y": 8,
      "z": -1,
      "name": "Plant_Coral_Block_Yellow"
    },
    {
      "x": -10,
      "y": 9,
      "z": -1,
      "name": "Plant_Coral_Block_Yellow"
    },
    {
      "x": -10,
      "y": 10,
      "z": -1,
      "name": "Plant_Coral_Block_Red"
    },
    {
      "x": -10,
      "y": 11,
      "z": -1,
      "name": "Plant_Coral_Block_Red"
    },
    {
      "x": -10,
      "y": 4,
      "z": 0,
      "name": "Plant_Coral_Block_Yellow"
    },
    {
      "x": -10,
      "y": 5,
      "z": 0,
      "name": "Plant_Coral_Block_Yellow"
    },
    {
      "x": -10,
      "y": 6,
      "z": 0,
      "name": "Plant_Coral_Block_Yellow"
    },
    {
      "x": -10,
      "y": 7,
      "z": 0,
      "name": "Plant_Coral_Block_Yellow"
    },
    {
      "x": -10,
      "y": 8,
      "z": 0,
      "name": "Plant_Coral_Block_Yellow"
    },
    {
      "x": -10,
      "y": 9,
      "z": 0,
      "name": "Plant_Coral_Block_Yellow"
    },
    {
      "x": -10,
      "y": 10,
      "z": 0,
      "name": "Plant_Coral_Block_Red"
    },
    {
      "x": -10,
      "y": 11,
      "z": 0,
      "name": "Plant_Coral_Block_Red"
    },
    {
      "x": -10,
      "y": 4,
      "z": 1,
      "name": "Plant_Coral_Block_Yellow"
    },
    {
      "x": -10,
      "y": 5,
      "z": 1,
      "name": "Plant_Coral_Block_Yellow"
    },
    {
      "x": -10,
      "y": 6,
      "z": 1,
      "name": "Plant_Coral_Block_Yellow"
    },
    {
      "x": -10,
      "y": 7,
      "z": 1,
      "name": "Plant_Coral_Block_Yellow"
    },
    {
      "x": -10,
      "y": 8,
      "z": 1,
      "name": "Plant_Coral_Block_Yellow"
    },
    {
      "x": -10,
      "y": 9,
      "z": 1,
      "name": "Plant_Coral_Block_Yellow"
    },
    {
      "x": -10,
      "y": 10,
      "z": 1,
      "name": "Plant_Coral_Block_Red"
    },
    {
      "x": -10,
      "y": 11,
      "z": 1,
      "name": "Plant_Coral_Block_Red"
    },
    {
      "x": -10,
      "y": 4,
      "z": 2,
      "name": "Plant_Coral_Block_Yellow"
    },
    {
      "x": -10,
      "y": 5,
      "z": 2,
      "name": "Plant_Coral_Block_Yellow"
    },
    {
      "x": -10,
      "y": 6,
      "z": 2,
      "name": "Plant_Coral_Block_Yellow"
    },
    {
      "x": -10,
      "y": 7,
      "z": 2,
      "name": "Plant_Coral_Block_Yellow"
    },
    {
      "x": -10,
      "y": 8,
      "z": 2,
      "name": "Plant_Coral_Block_Yellow"
    },
    {
      "x": -10,
      "y": 9,
      "z": 2,
      "name": "Plant_Coral_Block_Yellow"
    },
    {
      "x": -10,
      "y": 10,
      "z": 2,
      "name": "Plant_Coral_Block_Yellow"
    },
    {
      "x": -10,
      "y": 5,
      "z": 3,
      "name": "Plant_Coral_Block_Yellow"
    },
    {
      "x": -10,
      "y": 6,
      "z": 3,
      "name": "Plant_Coral_Block_Yellow"
    },
    {
      "x": -10,
      "y": 7,
      "z": 3,
      "name": "Plant_Coral_Block_Yellow"
    },
    {
      "x": -10,
      "y": 8,
      "z": 3,
      "name": "Plant_Coral_Block_Yellow"
    },
    {
      "x": -10,
      "y": 9,
      "z": 3,
      "name": "Plant_Coral_Block_Red"
    },
    {
      "x": -10,
      "y": 10,
      "z": 3,
      "name": "Plant_Coral_Block_Red"
    },
    {
      "x": -10,
      "y": 5,
      "z": 4,
      "name": "Plant_Coral_Block_Yellow"
    },
    {
      "x": -10,
      "y": 6,
      "z": 4,
      "name": "Plant_Coral_Block_Yellow"
    },
    {
      "x": -10,
      "y": 7,
      "z": 4,
      "name": "Plant_Coral_Block_Yellow"
    },
    {
      "x": -10,
      "y": 8,
      "z": 4,
      "name": "Plant_Coral_Block_Yellow"
    },
    {
      "x": -10,
      "y": 9,
      "z": 4,
      "name": "Plant_Coral_Block_Yellow"
    },
    {
      "x": -10,
      "y": 5,
      "z": 5,
      "name": "Plant_Coral_Block_Yellow"
    },
    {
      "x": -10,
      "y": 6,
      "z": 5,
      "name": "Plant_Coral_Block_Yellow"
    },
    {
      "x": -10,
      "y": 7,
      "z": 5,
      "name": "Plant_Coral_Block_Yellow"
    },
    {
      "x": -10,
      "y": 8,
      "z": 5,
      "name": "Plant_Coral_Block_Yellow"
    },
    {
      "x": -10,
      "y": 9,
      "z": 5,
      "name": "Plant_Coral_Block_Yellow"
    },
    {
      "x": -10,
      "y": 6,
      "z": 6,
      "name": "Plant_Coral_Block_Yellow"
    },
    {
      "x": -10,
      "y": 7,
      "z": 6,
      "name": "Plant_Coral_Block_Yellow"
    },
    {
      "x": -10,
      "y": 8,
      "z": 6,
      "name": "Plant_Coral_Block_Red"
    },
    {
      "x": -10,
      "y": 9,
      "z": 6,
      "name": "Plant_Coral_Block_Red"
    },
    {
      "x": -10,
      "y": 7,
      "z": 7,
      "name": "Plant_Coral_Block_Red"
    },
    {
      "x": -10,
      "y": 8,
      "z": 7,
      "name": "Plant_Coral_Block_Red"
    },
    {
      "x": -10,
      "y": 7,
      "z": 8,
      "name": "Plant_Coral_Block_Red"
    },
    {
      "x": -9,
      "y": 7,
      "z": -9,
      "name": "Plant_Coral_Block_Red"
    },
    {
      "x": -9,
      "y": 6,
      "z": -8,
      "name": "Plant_Coral_Block_Yellow"
    },
    {
      "x": -9,
      "y": 7,
      "z": -8,
      "name": "Plant_Coral_Block_Red"
    },
    {
      "x": -9,
      "y": 8,
      "z": -8,
      "name": "Plant_Coral_Block_Red"
    },
    {
      "x": -9,
      "y": 9,
      "z": -8,
      "name": "Plant_Coral_Block_Red"
    },
    {
      "x": -9,
      "y": 5,
      "z": -7,
      "name": "Plant_Coral_Block_Yellow"
    },
    {
      "x": -9,
      "y": 6,
      "z": -7,
      "name": "Plant_Coral_Block_Yellow"
    },
    {
      "x": -9,
      "y": 7,
      "z": -7,
      "name": "Plant_Coral_Block_Yellow"
    },
    {
      "x": -9,
      "y": 8,
      "z": -7,
      "name": "Plant_Coral_Block_Red"
    },
    {
      "x": -9,
      "y": 9,
      "z": -7,
      "name": "Plant_Coral_Block_Red"
    },
    {
      "x": -9,
      "y": 10,
      "z": -7,
      "name": "Plant_Coral_Block_Red"
    },
    {
      "x": -9,
      "y": 5,
      "z": -6,
      "name": "Plant_Coral_Block_Yellow"
    },
    {
      "x": -9,
      "y": 6,
      "z": -6,
      "name": "Plant_Coral_Block_Yellow"
    },
    {
      "x": -9,
      "y": 7,
      "z": -6,
      "name": "Plant_Coral_Block_Yellow"
    },
    {
      "x": -9,
      "y": 8,
      "z": -6,
      "name": "Plant_Coral_Block_Yellow"
    },
    {
      "x": -9,
      "y": 9,
      "z": -6,
      "name": "Plant_Coral_Block_Red"
    },
    {
      "x": -9,
      "y": 10,
      "z": -6,
      "name": "Plant_Coral_Block_Red"
    },
    {
      "x": -9,
      "y": 4,
      "z": -5,
      "name": "Plant_Coral_Block_Yellow"
    },
    {
      "x": -9,
      "y": 5,
      "z": -5,
      "name": "Plant_Coral_Block_Yellow"
    },
    {
      "x": -9,
      "y": 6,
      "z": -5,
      "name": "Plant_Coral_Block_Yellow"
    },
    {
      "x": -9,
      "y": 7,
      "z": -5,
      "name": "Plant_Coral_Block_Yellow"
    },
    {
      "x": -9,
      "y": 8,
      "z": -5,
      "name": "Plant_Coral_Block_Yellow"
    },
    {
      "x": -9,
      "y": 9,
      "z": -5,
      "name": "Plant_Coral_Block_Yellow"
    },
    {
      "x": -9,
      "y": 10,
      "z": -5,
      "name": "Plant_Coral_Block_Yellow"
    },
    {
      "x": -9,
      "y": 4,
      "z": -4,
      "name": "Plant_Coral_Block_Yellow"
    },
    {
      "x": -9,
      "y": 5,
      "z": -4,
      "name": "Plant_Coral_Block_Yellow"
    },
    {
      "x": -9,
      "y": 6,
      "z": -4,
      "name": "Plant_Coral_Block_Yellow"
    },
    {
      "x": -9,
      "y": 7,
      "z": -4,
      "name": "Plant_Coral_Block_Yellow"
    },
    {
      "x": -9,
      "y": 8,
      "z": -4,
      "name": "Plant_Coral_Block_Yellow"
    },
    {
      "x": -9,
      "y": 9,
      "z": -4,
      "name": "Plant_Coral_Block_Yellow"
    },
    {
      "x": -9,
      "y": 10,
      "z": -4,
      "name": "Plant_Coral_Block_Yellow"
    },
    {
      "x": -9,
      "y": 4,
      "z": -3,
      "name": "Plant_Coral_Block_Yellow"
    },
    {
      "x": -9,
      "y": 5,
      "z": -3,
      "name": "Plant_Coral_Block_Yellow"
    },
    {
      "x": -9,
      "y": 6,
      "z": -3,
      "name": "Plant_Coral_Block_Yellow"
    },
    {
      "x": -9,
      "y": 7,
      "z": -3,
      "name": "Plant_Coral_Block_Yellow"
    },
    {
      "x": -9,
      "y": 8,
      "z": -3,
      "name": "Plant_Coral_Block_Yellow"
    },
    {
      "x": -9,
      "y": 9,
      "z": -3,
      "name": "Plant_Coral_Block_Yellow"
    },
    {
      "x": -9,
      "y": 10,
      "z": -3,
      "name": "Plant_Coral_Block_Yellow"
    },
    {
      "x": -9,
      "y": 11,
      "z": -3,
      "name": "Plant_Coral_Bush_Orange"
    },
    {
      "x": -9,
      "y": 4,
      "z": -2,
      "name": "Plant_Coral_Block_Yellow"
    },
    {
      "x": -9,
      "y": 5,
      "z": -2,
      "name": "Plant_Coral_Block_Yellow"
    },
    {
      "x": -9,
      "y": 6,
      "z": -2,
      "name": "Plant_Coral_Block_Yellow"
    },
    {
      "x": -9,
      "y": 7,
      "z": -2,
      "name": "Plant_Coral_Block_Yellow"
    },
    {
      "x": -9,
      "y": 8,
      "z": -2,
      "name": "Plant_Coral_Block_Yellow"
    },
    {
      "x": -9,
      "y": 9,
      "z": -2,
      "name": "Plant_Coral_Block_Yellow"
    },
    {
      "x": -9,
      "y": 10,
      "z": -2,
      "name": "Plant_Coral_Block_Yellow"
    },
    {
      "x": -9,
      "y": 4,
      "z": -1,
      "name": "Plant_Coral_Block_Yellow"
    },
    {
      "x": -9,
      "y": 5,
      "z": -1,
      "name": "Plant_Coral_Block_Yellow"
    },
    {
      "x": -9,
      "y": 6,
      "z": -1,
      "name": "Plant_Coral_Block_Yellow"
    },
    {
      "x": -9,
      "y": 7,
      "z": -1,
      "name": "Plant_Coral_Block_Yellow"
    },
    {
      "x": -9,
      "y": 8,
      "z": -1,
      "name": "Plant_Coral_Block_Yellow"
    },
    {
      "x": -9,
      "y": 9,
      "z": -1,
      "name": "Plant_Coral_Block_Yellow"
    },
    {
      "x": -9,
      "y": 10,
      "z": -1,
      "name": "Plant_Coral_Block_Yellow"
    },
    {
      "x": -9,
      "y": 11,
      "z": -1,
      "name": "Plant_Coral_Bush_Orange"
    },
    {
      "x": -9,
      "y": 4,
      "z": 0,
      "name": "Plant_Coral_Block_Yellow"
    },
    {
      "x": -9,
      "y": 5,
      "z": 0,
      "name": "Plant_Coral_Block_Yellow"
    },
    {
      "x": -9,
      "y": 6,
      "z": 0,
      "name": "Plant_Coral_Block_Yellow"
    },
    {
      "x": -9,
      "y": 7,
      "z": 0,
      "name": "Plant_Coral_Block_Yellow"
    },
    {
      "x": -9,
      "y": 8,
      "z": 0,
      "name": "Plant_Coral_Block_Yellow"
    },
    {
      "x": -9,
      "y": 9,
      "z": 0,
      "name": "Plant_Coral_Block_Yellow"
    },
    {
      "x": -9,
      "y": 10,
      "z": 0,
      "name": "Plant_Coral_Block_Yellow"
    },
    {
      "x": -9,
      "y": 11,
      "z": 0,
      "name": "Plant_Coral_Bush_Orange"
    },
    {
      "x": -9,
      "y": 4,
      "z": 1,
      "name": "Plant_Coral_Block_Yellow"
    },
    {
      "x": -9,
      "y": 5,
      "z": 1,
      "name": "Plant_Coral_Block_Yellow"
    },
    {
      "x": -9,
      "y": 6,
      "z": 1,
      "name": "Plant_Coral_Block_Yellow"
    },
    {
      "x": -9,
      "y": 7,
      "z": 1,
      "name": "Plant_Coral_Block_Yellow"
    },
    {
      "x": -9,
      "y": 8,
      "z": 1,
      "name": "Plant_Coral_Block_Yellow"
    },
    {
      "x": -9,
      "y": 9,
      "z": 1,
      "name": "Plant_Coral_Block_Yellow"
    },
    {
      "x": -9,
      "y": 10,
      "z": 1,
      "name": "Plant_Coral_Block_Red"
    },
    {
      "x": -9,
      "y": 11,
      "z": 1,
      "name": "Plant_Coral_Block_Red"
    },
    {
      "x": -9,
      "y": 4,
      "z": 2,
      "name": "Plant_Coral_Block_Yellow"
    },
    {
      "x": -9,
      "y": 5,
      "z": 2,
      "name": "Plant_Coral_Block_Yellow"
    },
    {
      "x": -9,
      "y": 6,
      "z": 2,
      "name": "Plant_Coral_Block_Yellow"
    },
    {
      "x": -9,
      "y": 7,
      "z": 2,
      "name": "Plant_Coral_Block_Yellow"
    },
    {
      "x": -9,
      "y": 8,
      "z": 2,
      "name": "Plant_Coral_Block_Yellow"
    },
    {
      "x": -9,
      "y": 9,
      "z": 2,
      "name": "Plant_Coral_Block_Yellow"
    },
    {
      "x": -9,
      "y": 10,
      "z": 2,
      "name": "Plant_Coral_Block_Yellow"
    },
    {
      "x": -9,
      "y": 4,
      "z": 3,
      "name": "Plant_Coral_Block_Yellow"
    },
    {
      "x": -9,
      "y": 5,
      "z": 3,
      "name": "Plant_Coral_Block_Yellow"
    },
    {
      "x": -9,
      "y": 6,
      "z": 3,
      "name": "Plant_Coral_Block_Yellow"
    },
    {
      "x": -9,
      "y": 7,
      "z": 3,
      "name": "Plant_Coral_Block_Yellow"
    },
    {
      "x": -9,
      "y": 8,
      "z": 3,
      "name": "Plant_Coral_Block_Yellow"
    },
    {
      "x": -9,
      "y": 9,
      "z": 3,
      "name": "Plant_Coral_Block_Yellow"
    },
    {
      "x": -9,
      "y": 10,
      "z": 3,
      "name": "Plant_Coral_Block_Red"
    },
    {
      "x": -9,
      "y": 11,
      "z": 3,
      "name": "Plant_Coral_Block_Red"
    },
    {
      "x": -9,
      "y": 4,
      "z": 4,
      "name": "Plant_Coral_Block_Yellow"
    },
    {
      "x": -9,
      "y": 5,
      "z": 4,
      "name": "Plant_Coral_Block_Yellow"
    },
    {
      "x": -9,
      "y": 6,
      "z": 4,
      "name": "Plant_Coral_Block_Yellow"
    },
    {
      "x": -9,
      "y": 7,
      "z": 4,
      "name": "Plant_Coral_Block_Yellow"
    },
    {
      "x": -9,
      "y": 8,
      "z": 4,
      "name": "Plant_Coral_Block_Yellow"
    },
    {
      "x": -9,
      "y": 9,
      "z": 4,
      "name": "Plant_Coral_Block_Yellow"
    },
    {
      "x": -9,
      "y": 10,
      "z": 4,
      "name": "Plant_Coral_Block_Red"
    },
    {
      "x": -9,
      "y": 11,
      "z": 4,
      "name": "Plant_Coral_Block_Red"
    },
    {
      "x": -9,
      "y": 4,
      "z": 5,
      "name": "Plant_Coral_Block_Yellow"
    },
    {
      "x": -9,
      "y": 5,
      "z": 5,
      "name": "Plant_Coral_Block_Yellow"
    },
    {
      "x": -9,
      "y": 6,
      "z": 5,
      "name": "Plant_Coral_Block_Yellow"
    },
    {
      "x": -9,
      "y": 7,
      "z": 5,
      "name": "Plant_Coral_Block_Yellow"
    },
    {
      "x": -9,
      "y": 8,
      "z": 5,
      "name": "Plant_Coral_Block_Yellow"
    },
    {
      "x": -9,
      "y": 9,
      "z": 5,
      "name": "Plant_Coral_Block_Yellow"
    },
    {
      "x": -9,
      "y": 10,
      "z": 5,
      "name": "Plant_Coral_Block_Red"
    },
    {
      "x": -9,
      "y": 11,
      "z": 5,
      "name": "Plant_Coral_Block_Red"
    },
    {
      "x": -9,
      "y": 5,
      "z": 6,
      "name": "Plant_Coral_Block_Yellow"
    },
    {
      "x": -9,
      "y": 6,
      "z": 6,
      "name": "Plant_Coral_Block_Yellow"
    },
    {
      "x": -9,
      "y": 7,
      "z": 6,
      "name": "Plant_Coral_Block_Yellow"
    },
    {
      "x": -9,
      "y": 8,
      "z": 6,
      "name": "Plant_Coral_Block_Yellow"
    },
    {
      "x": -9,
      "y": 9,
      "z": 6,
      "name": "Plant_Coral_Block_Yellow"
    },
    {
      "x": -9,
      "y": 10,
      "z": 6,
      "name": "Plant_Coral_Model_Yellow"
    },
    {
      "x": -9,
      "y": 5,
      "z": 7,
      "name": "Plant_Coral_Block_Yellow"
    },
    {
      "x": -9,
      "y": 6,
      "z": 7,
      "name": "Plant_Coral_Block_Yellow"
    },
    {
      "x": -9,
      "y": 7,
      "z": 7,
      "name": "Plant_Coral_Block_Yellow"
    },
    {
      "x": -9,
      "y": 8,
      "z": 7,
      "name": "Plant_Coral_Block_Yellow"
    },
    {
      "x": -9,
      "y": 9,
      "z": 7,
      "name": "Plant_Coral_Block_Yellow"
    },
    {
      "x": -9,
      "y": 10,
      "z": 7,
      "name": "Plant_Coral_Model_Yellow"
    },
    {
      "x": -9,
      "y": 6,
      "z": 8,
      "name": "Plant_Coral_Block_Yellow"
    },
    {
      "x": -9,
      "y": 7,
      "z": 8,
      "name": "Plant_Coral_Block_Red"
    },
    {
      "x": -9,
      "y": 8,
      "z": 8,
      "name": "Plant_Coral_Block_Yellow"
    },
    {
      "x": -9,
      "y": 7,
      "z": 9,
      "name": "Plant_Coral_Block_Red"
    },
    {
      "x": -8,
      "y": 7,
      "z": -10,
      "name": "Plant_Coral_Block_Red"
    },
    {
      "x": -8,
      "y": 6,
      "z": -9,
      "name": "Plant_Coral_Block_Yellow"
    },
    {
      "x": -8,
      "y": 7,
      "z": -9,
      "name": "Plant_Coral_Block_Red"
    },
    {
      "x": -8,
      "y": 8,
      "z": -9,
      "name": "Plant_Coral_Block_Yellow"
    },
    {
      "x": -8,
      "y": 5,
      "z": -8,
      "name": "Plant_Coral_Block_Yellow"
    },
    {
      "x": -8,
      "y": 6,
      "z": -8,
      "name": "Plant_Coral_Block_Yellow"
    },
    {
      "x": -8,
      "y": 7,
      "z": -8,
      "name": "Plant_Coral_Block_Yellow"
    },
    {
      "x": -8,
      "y": 8,
      "z": -8,
      "name": "Plant_Coral_Block_Yellow"
    },
    {
      "x": -8,
      "y": 9,
      "z": -8,
      "name": "Plant_Coral_Block_Yellow"
    },
    {
      "x": -8,
      "y": 5,
      "z": -7,
      "name": "Plant_Coral_Block_Yellow"
    },
    {
      "x": -8,
      "y": 6,
      "z": -7,
      "name": "Plant_Coral_Block_Yellow"
    },
    {
      "x": -8,
      "y": 7,
      "z": -7,
      "name": "Plant_Coral_Block_Yellow"
    },
    {
      "x": -8,
      "y": 8,
      "z": -7,
      "name": "Plant_Coral_Block_Yellow"
    },
    {
      "x": -8,
      "y": 9,
      "z": -7,
      "name": "Plant_Coral_Block_Yellow"
    },
    {
      "x": -8,
      "y": 10,
      "z": -7,
      "name": "Plant_Coral_Model_Yellow"
    },
    {
      "x": -8,
      "y": 4,
      "z": -6,
      "name": "Plant_Coral_Block_Yellow"
    },
    {
      "x": -8,
      "y": 5,
      "z": -6,
      "name": "Plant_Coral_Block_Yellow"
    },
    {
      "x": -8,
      "y": 6,
      "z": -6,
      "name": "Plant_Coral_Block_Yellow"
    },
    {
      "x": -8,
      "y": 7,
      "z": -6,
      "name": "Plant_Coral_Block_Yellow"
    },
    {
      "x": -8,
      "y": 8,
      "z": -6,
      "name": "Plant_Coral_Block_Yellow"
    },
    {
      "x": -8,
      "y": 9,
      "z": -6,
      "name": "Plant_Coral_Block_Yellow"
    },
    {
      "x": -8,
      "y": 10,
      "z": -6,
      "name": "Plant_Coral_Block_Yellow"
    },
    {
      "x": -8,
      "y": 11,
      "z": -6,
      "name": "Plant_Coral_Model_Yellow"
    },
    {
      "x": -8,
      "y": 4,
      "z": -5,
      "name": "Plant_Coral_Block_Yellow"
    },
    {
      "x": -8,
      "y": 5,
      "z": -5,
      "name": "Plant_Coral_Block_Yellow"
    },
    {
      "x": -8,
      "y": 6,
      "z": -5,
      "name": "Plant_Coral_Block_Yellow"
    },
    {
      "x": -8,
      "y": 7,
      "z": -5,
      "name": "Plant_Coral_Block_Yellow"
    },
    {
      "x": -8,
      "y": 8,
      "z": -5,
      "name": "Plant_Coral_Block_Yellow"
    },
    {
      "x": -8,
      "y": 9,
      "z": -5,
      "name": "Plant_Coral_Block_Yellow"
    },
    {
      "x": -8,
      "y": 10,
      "z": -5,
      "name": "Plant_Coral_Block_Yellow"
    },
    {
      "x": -8,
      "y": 11,
      "z": -5,
      "name": "Plant_Coral_Bush_Orange"
    },
    {
      "x": -8,
      "y": 4,
      "z": -4,
      "name": "Plant_Coral_Block_Yellow"
    },
    {
      "x": -8,
      "y": 5,
      "z": -4,
      "name": "Plant_Coral_Block_Yellow"
    },
    {
      "x": -8,
      "y": 6,
      "z": -4,
      "name": "Plant_Coral_Block_Yellow"
    },
    {
      "x": -8,
      "y": 7,
      "z": -4,
      "name": "Plant_Coral_Block_Yellow"
    },
    {
      "x": -8,
      "y": 8,
      "z": -4,
      "name": "Plant_Coral_Block_Yellow"
    },
    {
      "x": -8,
      "y": 9,
      "z": -4,
      "name": "Plant_Coral_Block_Yellow"
    },
    {
      "x": -8,
      "y": 10,
      "z": -4,
      "name": "Plant_Coral_Block_Red"
    },
    {
      "x": -8,
      "y": 11,
      "z": -4,
      "name": "Plant_Coral_Block_Red"
    },
    {
      "x": -8,
      "y": 4,
      "z": -3,
      "name": "Plant_Coral_Block_Yellow"
    },
    {
      "x": -8,
      "y": 5,
      "z": -3,
      "name": "Plant_Coral_Block_Yellow"
    },
    {
      "x": -8,
      "y": 6,
      "z": -3,
      "name": "Plant_Coral_Block_Yellow"
    },
    {
      "x": -8,
      "y": 7,
      "z": -3,
      "name": "Plant_Coral_Block_Yellow"
    },
    {
      "x": -8,
      "y": 8,
      "z": -3,
      "name": "Plant_Coral_Block_Yellow"
    },
    {
      "x": -8,
      "y": 9,
      "z": -3,
      "name": "Plant_Coral_Block_Yellow"
    },
    {
      "x": -8,
      "y": 10,
      "z": -3,
      "name": "Plant_Coral_Block_Red"
    },
    {
      "x": -8,
      "y": 11,
      "z": -3,
      "name": "Plant_Coral_Block_Red"
    },
    {
      "x": -8,
      "y": 3,
      "z": -2,
      "name": "Plant_Coral_Block_Yellow"
    },
    {
      "x": -8,
      "y": 4,
      "z": -2,
      "name": "Plant_Coral_Block_Yellow"
    },
    {
      "x": -8,
      "y": 5,
      "z": -2,
      "name": "Plant_Coral_Block_Yellow"
    },
    {
      "x": -8,
      "y": 6,
      "z": -2,
      "name": "Plant_Coral_Block_Yellow"
    },
    {
      "x": -8,
      "y": 7,
      "z": -2,
      "name": "Plant_Coral_Block_Yellow"
    },
    {
      "x": -8,
      "y": 8,
      "z": -2,
      "name": "Plant_Coral_Block_Yellow"
    },
    {
      "x": -8,
      "y": 9,
      "z": -2,
      "name": "Plant_Coral_Block_Yellow"
    },
    {
      "x": -8,
      "y": 10,
      "z": -2,
      "name": "Plant_Coral_Block_Yellow"
    },
    {
      "x": -8,
      "y": 11,
      "z": -2,
      "name": "Plant_Coral_Block_Red"
    },
    {
      "x": -8,
      "y": 12,
      "z": -2,
      "name": "Plant_Coral_Block_Red"
    },
    {
      "x": -8,
      "y": 3,
      "z": -1,
      "name": "Plant_Coral_Block_Yellow"
    },
    {
      "x": -8,
      "y": 4,
      "z": -1,
      "name": "Plant_Coral_Block_Yellow"
    },
    {
      "x": -8,
      "y": 5,
      "z": -1,
      "name": "Plant_Coral_Block_Yellow"
    },
    {
      "x": -8,
      "y": 6,
      "z": -1,
      "name": "Plant_Coral_Block_Yellow"
    },
    {
      "x": -8,
      "y": 7,
      "z": -1,
      "name": "Plant_Coral_Block_Yellow"
    },
    {
      "x": -8,
      "y": 8,
      "z": -1,
      "name": "Plant_Coral_Block_Yellow"
    },
    {
      "x": -8,
      "y": 9,
      "z": -1,
      "name": "Plant_Coral_Block_Yellow"
    },
    {
      "x": -8,
      "y": 10,
      "z": -1,
      "name": "Plant_Coral_Block_Yellow"
    },
    {
      "x": -8,
      "y": 11,
      "z": -1,
      "name": "Plant_Coral_Block_Red"
    },
    {
      "x": -8,
      "y": 12,
      "z": -1,
      "name": "Plant_Coral_Block_Red"
    },
    {
      "x": -8,
      "y": 3,
      "z": 0,
      "name": "Plant_Coral_Block_Yellow"
    },
    {
      "x": -8,
      "y": 4,
      "z": 0,
      "name": "Plant_Coral_Block_Yellow"
    },
    {
      "x": -8,
      "y": 5,
      "z": 0,
      "name": "Plant_Coral_Block_Yellow"
    },
    {
      "x": -8,
      "y": 6,
      "z": 0,
      "name": "Plant_Coral_Block_Yellow"
    },
    {
      "x": -8,
      "y": 7,
      "z": 0,
      "name": "Plant_Coral_Block_Yellow"
    },
    {
      "x": -8,
      "y": 8,
      "z": 0,
      "name": "Plant_Coral_Block_Yellow"
    },
    {
      "x": -8,
      "y": 9,
      "z": 0,
      "name": "Plant_Coral_Block_Yellow"
    },
    {
      "x": -8,
      "y": 10,
      "z": 0,
      "name": "Plant_Coral_Block_Yellow"
    },
    {
      "x": -8,
      "y": 11,
      "z": 0,
      "name": "Plant_Coral_Block_Yellow"
    },
    {
      "x": -8,
      "y": 3,
      "z": 1,
      "name": "Plant_Coral_Block_Yellow"
    },
    {
      "x": -8,
      "y": 4,
      "z": 1,
      "name": "Plant_Coral_Block_Yellow"
    },
    {
      "x": -8,
      "y": 5,
      "z": 1,
      "name": "Plant_Coral_Block_Yellow"
    },
    {
      "x": -8,
      "y": 6,
      "z": 1,
      "name": "Plant_Coral_Block_Yellow"
    },
    {
      "x": -8,
      "y": 7,
      "z": 1,
      "name": "Plant_Coral_Block_Yellow"
    },
    {
      "x": -8,
      "y": 8,
      "z": 1,
      "name": "Plant_Coral_Block_Yellow"
    },
    {
      "x": -8,
      "y": 9,
      "z": 1,
      "name": "Plant_Coral_Block_Yellow"
    },
    {
      "x": -8,
      "y": 10,
      "z": 1,
      "name": "Plant_Coral_Block_Yellow"
    },
    {
      "x": -8,
      "y": 11,
      "z": 1,
      "name": "Plant_Coral_Block_Red"
    },
    {
      "x": -8,
      "y": 12,
      "z": 1,
      "name": "Plant_Coral_Block_Red"
    },
    {
      "x": -8,
      "y": 3,
      "z": 2,
      "name": "Plant_Coral_Block_Yellow"
    },
    {
      "x": -8,
      "y": 4,
      "z": 2,
      "name": "Plant_Coral_Block_Yellow"
    },
    {
      "x": -8,
      "y": 5,
      "z": 2,
      "name": "Plant_Coral_Block_Yellow"
    },
    {
      "x": -8,
      "y": 6,
      "z": 2,
      "name": "Plant_Coral_Block_Yellow"
    },
    {
      "x": -8,
      "y": 7,
      "z": 2,
      "name": "Plant_Coral_Block_Yellow"
    },
    {
      "x": -8,
      "y": 8,
      "z": 2,
      "name": "Plant_Coral_Block_Yellow"
    },
    {
      "x": -8,
      "y": 9,
      "z": 2,
      "name": "Plant_Coral_Block_Yellow"
    },
    {
      "x": -8,
      "y": 10,
      "z": 2,
      "name": "Plant_Coral_Block_Yellow"
    },
    {
      "x": -8,
      "y": 11,
      "z": 2,
      "name": "Plant_Coral_Block_Yellow"
    },
    {
      "x": -8,
      "y": 4,
      "z": 3,
      "name": "Plant_Coral_Block_Yellow"
    },
    {
      "x": -8,
      "y": 5,
      "z": 3,
      "name": "Plant_Coral_Block_Yellow"
    },
    {
      "x": -8,
      "y": 6,
      "z": 3,
      "name": "Plant_Coral_Block_Yellow"
    },
    {
      "x": -8,
      "y": 7,
      "z": 3,
      "name": "Plant_Coral_Block_Yellow"
    },
    {
      "x": -8,
      "y": 8,
      "z": 3,
      "name": "Plant_Coral_Block_Yellow"
    },
    {
      "x": -8,
      "y": 9,
      "z": 3,
      "name": "Plant_Coral_Block_Yellow"
    },
    {
      "x": -8,
      "y": 10,
      "z": 3,
      "name": "Plant_Coral_Block_Yellow"
    },
    {
      "x": -8,
      "y": 4,
      "z": 4,
      "name": "Plant_Coral_Block_Yellow"
    },
    {
      "x": -8,
      "y": 5,
      "z": 4,
      "name": "Plant_Coral_Block_Yellow"
    },
    {
      "x": -8,
      "y": 6,
      "z": 4,
      "name": "Plant_Coral_Block_Yellow"
    },
    {
      "x": -8,
      "y": 7,
      "z": 4,
      "name": "Plant_Coral_Block_Yellow"
    },
    {
      "x": -8,
      "y": 8,
      "z": 4,
      "name": "Plant_Coral_Block_Yellow"
    },
    {
      "x": -8,
      "y": 9,
      "z": 4,
      "name": "Plant_Coral_Block_Yellow"
    },
    {
      "x": -8,
      "y": 10,
      "z": 4,
      "name": "Plant_Coral_Block_Yellow"
    },
    {
      "x": -8,
      "y": 4,
      "z": 5,
      "name": "Plant_Coral_Block_Yellow"
    },
    {
      "x": -8,
      "y": 5,
      "z": 5,
      "name": "Plant_Coral_Block_Yellow"
    },
    {
      "x": -8,
      "y": 6,
      "z": 5,
      "name": "Plant_Coral_Block_Yellow"
    },
    {
      "x": -8,
      "y": 7,
      "z": 5,
      "name": "Plant_Coral_Block_Yellow"
    },
    {
      "x": -8,
      "y": 8,
      "z": 5,
      "name": "Plant_Coral_Block_Yellow"
    },
    {
      "x": -8,
      "y": 9,
      "z": 5,
      "name": "Plant_Coral_Block_Yellow"
    },
    {
      "x": -8,
      "y": 10,
      "z": 5,
      "name": "Plant_Coral_Block_Red"
    },
    {
      "x": -8,
      "y": 11,
      "z": 5,
      "name": "Plant_Coral_Block_Red"
    },
    {
      "x": -8,
      "y": 4,
      "z": 6,
      "name": "Plant_Coral_Block_Yellow"
    },
    {
      "x": -8,
      "y": 5,
      "z": 6,
      "name": "Plant_Coral_Block_Yellow"
    },
    {
      "x": -8,
      "y": 6,
      "z": 6,
      "name": "Plant_Coral_Block_Yellow"
    },
    {
      "x": -8,
      "y": 7,
      "z": 6,
      "name": "Plant_Coral_Block_Yellow"
    },
    {
      "x": -8,
      "y": 8,
      "z": 6,
      "name": "Plant_Coral_Block_Yellow"
    },
    {
      "x": -8,
      "y": 9,
      "z": 6,
      "name": "Plant_Coral_Block_Yellow"
    },
    {
      "x": -8,
      "y": 10,
      "z": 6,
      "name": "Plant_Coral_Block_Red"
    },
    {
      "x": -8,
      "y": 11,
      "z": 6,
      "name": "Plant_Coral_Block_Red"
    },
    {
      "x": -8,
      "y": 5,
      "z": 7,
      "name": "Plant_Coral_Block_Yellow"
    },
    {
      "x": -8,
      "y": 6,
      "z": 7,
      "name": "Plant_Coral_Block_Yellow"
    },
    {
      "x": -8,
      "y": 7,
      "z": 7,
      "name": "Plant_Coral_Block_Yellow"
    },
    {
      "x": -8,
      "y": 8,
      "z": 7,
      "name": "Plant_Coral_Block_Yellow"
    },
    {
      "x": -8,
      "y": 9,
      "z": 7,
      "name": "Plant_Coral_Block_Yellow"
    },
    {
      "x": -8,
      "y": 10,
      "z": 7,
      "name": "Plant_Coral_Model_Yellow"
    },
    {
      "x": -8,
      "y": 5,
      "z": 8,
      "name": "Plant_Coral_Block_Yellow"
    },
    {
      "x": -8,
      "y": 6,
      "z": 8,
      "name": "Plant_Coral_Block_Yellow"
    },
    {
      "x": -8,
      "y": 7,
      "z": 8,
      "name": "Plant_Coral_Block_Yellow"
    },
    {
      "x": -8,
      "y": 8,
      "z": 8,
      "name": "Plant_Coral_Block_Yellow"
    },
    {
      "x": -8,
      "y": 9,
      "z": 8,
      "name": "Plant_Coral_Block_Yellow"
    },
    {
      "x": -8,
      "y": 6,
      "z": 9,
      "name": "Plant_Coral_Block_Yellow"
    },
    {
      "x": -8,
      "y": 7,
      "z": 9,
      "name": "Plant_Coral_Block_Red"
    },
    {
      "x": -8,
      "y": 8,
      "z": 9,
      "name": "Plant_Coral_Block_Yellow"
    },
    {
      "x": -8,
      "y": 7,
      "z": 10,
      "name": "Plant_Coral_Block_Red"
    },
    {
      "x": -7,
      "y": 7,
      "z": -10,
      "name": "Plant_Coral_Block_Red"
    },
    {
      "x": -7,
      "y": 5,
      "z": -9,
      "name": "Plant_Coral_Block_Yellow"
    },
    {
      "x": -7,
      "y": 6,
      "z": -9,
      "name": "Plant_Coral_Block_Yellow"
    },
    {
      "x": -7,
      "y": 7,
      "z": -9,
      "name": "Plant_Coral_Block_Yellow"
    },
    {
      "x": -7,
      "y": 8,
      "z": -9,
      "name": "Plant_Coral_Block_Yellow"
    },
    {
      "x": -7,
      "y": 9,
      "z": -9,
      "name": "Plant_Coral_Block_Red"
    },
    {
      "x": -7,
      "y": 10,
      "z": -9,
      "name": "Plant_Coral_Block_Red"
    },
    {
      "x": -7,
      "y": 5,
      "z": -8,
      "name": "Plant_Coral_Block_Yellow"
    },
    {
      "x": -7,
      "y": 6,
      "z": -8,
      "name": "Plant_Coral_Block_Yellow"
    },
    {
      "x": -7,
      "y": 7,
      "z": -8,
      "name": "Plant_Coral_Block_Yellow"
    },
    {
      "x": -7,
      "y": 8,
      "z": -8,
      "name": "Plant_Coral_Block_Yellow"
    },
    {
      "x": -7,
      "y": 9,
      "z": -8,
      "name": "Plant_Coral_Block_Red"
    },
    {
      "x": -7,
      "y": 10,
      "z": -8,
      "name": "Plant_Coral_Block_Red"
    },
    {
      "x": -7,
      "y": 11,
      "z": -8,
      "name": "Plant_Coral_Bush_Orange"
    },
    {
      "x": -7,
      "y": 4,
      "z": -7,
      "name": "Plant_Coral_Block_Yellow"
    },
    {
      "x": -7,
      "y": 5,
      "z": -7,
      "name": "Plant_Coral_Block_Yellow"
    },
    {
      "x": -7,
      "y": 6,
      "z": -7,
      "name": "Plant_Coral_Block_Yellow"
    },
    {
      "x": -7,
      "y": 7,
      "z": -7,
      "name": "Plant_Coral_Block_Yellow"
    },
    {
      "x": -7,
      "y": 8,
      "z": -7,
      "name": "Plant_Coral_Block_Yellow"
    },
    {
      "x": -7,
      "y": 9,
      "z": -7,
      "name": "Plant_Coral_Block_Yellow"
    },
    {
      "x": -7,
      "y": 10,
      "z": -7,
      "name": "Plant_Coral_Block_Red"
    },
    {
      "x": -7,
      "y": 11,
      "z": -7,
      "name": "Plant_Coral_Block_Red"
    },
    {
      "x": -7,
      "y": 4,
      "z": -6,
      "name": "Plant_Coral_Block_Yellow"
    },
    {
      "x": -7,
      "y": 5,
      "z": -6,
      "name": "Plant_Coral_Block_Yellow"
    },
    {
      "x": -7,
      "y": 6,
      "z": -6,
      "name": "Plant_Coral_Block_Yellow"
    },
    {
      "x": -7,
      "y": 7,
      "z": -6,
      "name": "Plant_Coral_Block_Yellow"
    },
    {
      "x": -7,
      "y": 8,
      "z": -6,
      "name": "Plant_Coral_Block_Yellow"
    },
    {
      "x": -7,
      "y": 9,
      "z": -6,
      "name": "Plant_Coral_Block_Yellow"
    },
    {
      "x": -7,
      "y": 10,
      "z": -6,
      "name": "Plant_Coral_Block_Yellow"
    },
    {
      "x": -7,
      "y": 11,
      "z": -6,
      "name": "Plant_Coral_Model_Yellow"
    },
    {
      "x": -7,
      "y": 4,
      "z": -5,
      "name": "Plant_Coral_Block_Yellow"
    },
    {
      "x": -7,
      "y": 5,
      "z": -5,
      "name": "Plant_Coral_Block_Yellow"
    },
    {
      "x": -7,
      "y": 6,
      "z": -5,
      "name": "Plant_Coral_Block_Yellow"
    },
    {
      "x": -7,
      "y": 7,
      "z": -5,
      "name": "Plant_Coral_Block_Yellow"
    },
    {
      "x": -7,
      "y": 8,
      "z": -5,
      "name": "Plant_Coral_Block_Yellow"
    },
    {
      "x": -7,
      "y": 9,
      "z": -5,
      "name": "Plant_Coral_Block_Yellow"
    },
    {
      "x": -7,
      "y": 10,
      "z": -5,
      "name": "Plant_Coral_Block_Yellow"
    },
    {
      "x": -7,
      "y": 11,
      "z": -5,
      "name": "Plant_Coral_Bush_Orange"
    },
    {
      "x": -7,
      "y": 3,
      "z": -4,
      "name": "Plant_Coral_Block_Yellow"
    },
    {
      "x": -7,
      "y": 4,
      "z": -4,
      "name": "Plant_Coral_Block_Yellow"
    },
    {
      "x": -7,
      "y": 5,
      "z": -4,
      "name": "Plant_Coral_Block_Yellow"
    },
    {
      "x": -7,
      "y": 6,
      "z": -4,
      "name": "Plant_Coral_Block_Yellow"
    },
    {
      "x": -7,
      "y": 7,
      "z": -4,
      "name": "Plant_Coral_Block_Yellow"
    },
    {
      "x": -7,
      "y": 8,
      "z": -4,
      "name": "Plant_Coral_Block_Yellow"
    },
    {
      "x": -7,
      "y": 9,
      "z": -4,
      "name": "Plant_Coral_Block_Yellow"
    },
    {
      "x": -7,
      "y": 10,
      "z": -4,
      "name": "Plant_Coral_Block_Yellow"
    },
    {
      "x": -7,
      "y": 11,
      "z": -4,
      "name": "Plant_Coral_Block_Yellow"
    },
    {
      "x": -7,
      "y": 3,
      "z": -3,
      "name": "Plant_Coral_Block_Yellow"
    },
    {
      "x": -7,
      "y": 4,
      "z": -3,
      "name": "Plant_Coral_Block_Yellow"
    },
    {
      "x": -7,
      "y": 5,
      "z": -3,
      "name": "Plant_Coral_Block_Yellow"
    },
    {
      "x": -7,
      "y": 6,
      "z": -3,
      "name": "Plant_Coral_Block_Yellow"
    },
    {
      "x": -7,
      "y": 7,
      "z": -3,
      "name": "Plant_Coral_Block_Yellow"
    },
    {
      "x": -7,
      "y": 8,
      "z": -3,
      "name": "Plant_Coral_Block_Yellow"
    },
    {
      "x": -7,
      "y": 9,
      "z": -3,
      "name": "Plant_Coral_Block_Yellow"
    },
    {
      "x": -7,
      "y": 10,
      "z": -3,
      "name": "Plant_Coral_Block_Yellow"
    },
    {
      "x": -7,
      "y": 11,
      "z": -3,
      "name": "Plant_Coral_Block_Yellow"
    },
    {
      "x": -7,
      "y": 3,
      "z": -2,
      "name": "Plant_Coral_Block_Yellow"
    },
    {
      "x": -7,
      "y": 4,
      "z": -2,
      "name": "Plant_Coral_Block_Yellow"
    },
    {
      "x": -7,
      "y": 5,
      "z": -2,
      "name": "Plant_Coral_Block_Yellow"
    },
    {
      "x": -7,
      "y": 6,
      "z": -2,
      "name": "Plant_Coral_Block_Yellow"
    },
    {
      "x": -7,
      "y": 7,
      "z": -2,
      "name": "Plant_Coral_Block_Yellow"
    },
    {
      "x": -7,
      "y": 8,
      "z": -2,
      "name": "Plant_Coral_Block_Yellow"
    },
    {
      "x": -7,
      "y": 9,
      "z": -2,
      "name": "Plant_Coral_Block_Yellow"
    },
    {
      "x": -7,
      "y": 10,
      "z": -2,
      "name": "Plant_Coral_Block_Yellow"
    },
    {
      "x": -7,
      "y": 11,
      "z": -2,
      "name": "Plant_Coral_Block_Yellow"
    },
    {
      "x": -7,
      "y": 3,
      "z": -1,
      "name": "Plant_Coral_Block_Yellow"
    },
    {
      "x": -7,
      "y": 4,
      "z": -1,
      "name": "Plant_Coral_Block_Yellow"
    },
    {
      "x": -7,
      "y": 5,
      "z": -1,
      "name": "Plant_Coral_Block_Yellow"
    },
    {
      "x": -7,
      "y": 6,
      "z": -1,
      "name": "Plant_Coral_Block_Yellow"
    },
    {
      "x": -7,
      "y": 7,
      "z": -1,
      "name": "Plant_Coral_Block_Yellow"
    },
    {
      "x": -7,
      "y": 8,
      "z": -1,
      "name": "Plant_Coral_Block_Yellow"
    },
    {
      "x": -7,
      "y": 9,
      "z": -1,
      "name": "Plant_Coral_Block_Yellow"
    },
    {
      "x": -7,
      "y": 10,
      "z": -1,
      "name": "Plant_Coral_Block_Yellow"
    },
    {
      "x": -7,
      "y": 11,
      "z": -1,
      "name": "Plant_Coral_Block_Red"
    },
    {
      "x": -7,
      "y": 12,
      "z": -1,
      "name": "Plant_Coral_Block_Red"
    },
    {
      "x": -7,
      "y": 3,
      "z": 0,
      "name": "Plant_Coral_Block_Yellow"
    },
    {
      "x": -7,
      "y": 4,
      "z": 0,
      "name": "Plant_Coral_Block_Yellow"
    },
    {
      "x": -7,
      "y": 5,
      "z": 0,
      "name": "Plant_Coral_Block_Yellow"
    },
    {
      "x": -7,
      "y": 6,
      "z": 0,
      "name": "Plant_Coral_Block_Yellow"
    },
    {
      "x": -7,
      "y": 7,
      "z": 0,
      "name": "Plant_Coral_Block_Yellow"
    },
    {
      "x": -7,
      "y": 8,
      "z": 0,
      "name": "Plant_Coral_Block_Yellow"
    },
    {
      "x": -7,
      "y": 9,
      "z": 0,
      "name": "Plant_Coral_Block_Yellow"
    },
    {
      "x": -7,
      "y": 10,
      "z": 0,
      "name": "Plant_Coral_Block_Yellow"
    },
    {
      "x": -7,
      "y": 11,
      "z": 0,
      "name": "Plant_Coral_Block_Yellow"
    },
    {
      "x": -7,
      "y": 12,
      "z": 0,
      "name": "Plant_Coral_Bush_Orange"
    },
    {
      "x": -7,
      "y": 3,
      "z": 1,
      "name": "Plant_Coral_Block_Yellow"
    },
    {
      "x": -7,
      "y": 4,
      "z": 1,
      "name": "Plant_Coral_Block_Yellow"
    },
    {
      "x": -7,
      "y": 5,
      "z": 1,
      "name": "Plant_Coral_Block_Yellow"
    },
    {
      "x": -7,
      "y": 6,
      "z": 1,
      "name": "Plant_Coral_Block_Yellow"
    },
    {
      "x": -7,
      "y": 7,
      "z": 1,
      "name": "Plant_Coral_Block_Yellow"
    },
    {
      "x": -7,
      "y": 8,
      "z": 1,
      "name": "Plant_Coral_Block_Yellow"
    },
    {
      "x": -7,
      "y": 9,
      "z": 1,
      "name": "Plant_Coral_Block_Yellow"
    },
    {
      "x": -7,
      "y": 10,
      "z": 1,
      "name": "Plant_Coral_Block_Yellow"
    },
    {
      "x": -7,
      "y": 11,
      "z": 1,
      "name": "Plant_Coral_Block_Red"
    },
    {
      "x": -7,
      "y": 12,
      "z": 1,
      "name": "Plant_Coral_Block_Red"
    },
    {
      "x": -7,
      "y": 3,
      "z": 2,
      "name": "Plant_Coral_Block_Yellow"
    },
    {
      "x": -7,
      "y": 4,
      "z": 2,
      "name": "Plant_Coral_Block_Yellow"
    },
    {
      "x": -7,
      "y": 5,
      "z": 2,
      "name": "Plant_Coral_Block_Yellow"
    },
    {
      "x": -7,
      "y": 6,
      "z": 2,
      "name": "Plant_Coral_Block_Yellow"
    },
    {
      "x": -7,
      "y": 7,
      "z": 2,
      "name": "Plant_Coral_Block_Yellow"
    },
    {
      "x": -7,
      "y": 8,
      "z": 2,
      "name": "Plant_Coral_Block_Yellow"
    },
    {
      "x": -7,
      "y": 9,
      "z": 2,
      "name": "Plant_Coral_Block_Yellow"
    },
    {
      "x": -7,
      "y": 10,
      "z": 2,
      "name": "Plant_Coral_Block_Yellow"
    },
    {
      "x": -7,
      "y": 11,
      "z": 2,
      "name": "Plant_Coral_Block_Red"
    },
    {
      "x": -7,
      "y": 12,
      "z": 2,
      "name": "Plant_Coral_Block_Red"
    },
    {
      "x": -7,
      "y": 3,
      "z": 3,
      "name": "Plant_Coral_Block_Yellow"
    },
    {
      "x": -7,
      "y": 4,
      "z": 3,
      "name": "Plant_Coral_Block_Yellow"
    },
    {
      "x": -7,
      "y": 5,
      "z": 3,
      "name": "Plant_Coral_Block_Yellow"
    },
    {
      "x": -7,
      "y": 6,
      "z": 3,
      "name": "Plant_Coral_Block_Yellow"
    },
    {
      "x": -7,
      "y": 7,
      "z": 3,
      "name": "Plant_Coral_Block_Yellow"
    },
    {
      "x": -7,
      "y": 8,
      "z": 3,
      "name": "Plant_Coral_Block_Yellow"
    },
    {
      "x": -7,
      "y": 9,
      "z": 3,
      "name": "Plant_Coral_Block_Yellow"
    },
    {
      "x": -7,
      "y": 10,
      "z": 3,
      "name": "Plant_Coral_Block_Yellow"
    },
    {
      "x": -7,
      "y": 11,
      "z": 3,
      "name": "Plant_Coral_Block_Red"
    },
    {
      "x": -7,
      "y": 12,
      "z": 3,
      "name": "Plant_Coral_Block_Red"
    },
    {
      "x": -7,
      "y": 3,
      "z": 4,
      "name": "Plant_Coral_Block_Yellow"
    },
    {
      "x": -7,
      "y": 4,
      "z": 4,
      "name": "Plant_Coral_Block_Yellow"
    },
    {
      "x": -7,
      "y": 5,
      "z": 4,
      "name": "Plant_Coral_Block_Yellow"
    },
    {
      "x": -7,
      "y": 6,
      "z": 4,
      "name": "Plant_Coral_Block_Yellow"
    },
    {
      "x": -7,
      "y": 7,
      "z": 4,
      "name": "Plant_Coral_Block_Yellow"
    },
    {
      "x": -7,
      "y": 8,
      "z": 4,
      "name": "Plant_Coral_Block_Yellow"
    },
    {
      "x": -7,
      "y": 9,
      "z": 4,
      "name": "Plant_Coral_Block_Yellow"
    },
    {
      "x": -7,
      "y": 10,
      "z": 4,
      "name": "Plant_Coral_Block_Yellow"
    },
    {
      "x": -7,
      "y": 11,
      "z": 4,
      "name": "Plant_Coral_Block_Yellow"
    },
    {
      "x": -7,
      "y": 4,
      "z": 5,
      "name": "Plant_Coral_Block_Yellow"
    },
    {
      "x": -7,
      "y": 5,
      "z": 5,
      "name": "Plant_Coral_Block_Yellow"
    },
    {
      "x": -7,
      "y": 6,
      "z": 5,
      "name": "Plant_Coral_Block_Yellow"
    },
    {
      "x": -7,
      "y": 7,
      "z": 5,
      "name": "Plant_Coral_Block_Yellow"
    },
    {
      "x": -7,
      "y": 8,
      "z": 5,
      "name": "Plant_Coral_Block_Yellow"
    },
    {
      "x": -7,
      "y": 9,
      "z": 5,
      "name": "Plant_Coral_Block_Yellow"
    },
    {
      "x": -7,
      "y": 10,
      "z": 5,
      "name": "Plant_Coral_Block_Yellow"
    },
    {
      "x": -7,
      "y": 4,
      "z": 6,
      "name": "Plant_Coral_Block_Yellow"
    },
    {
      "x": -7,
      "y": 5,
      "z": 6,
      "name": "Plant_Coral_Block_Yellow"
    },
    {
      "x": -7,
      "y": 6,
      "z": 6,
      "name": "Plant_Coral_Block_Yellow"
    },
    {
      "x": -7,
      "y": 7,
      "z": 6,
      "name": "Plant_Coral_Block_Yellow"
    },
    {
      "x": -7,
      "y": 8,
      "z": 6,
      "name": "Plant_Coral_Block_Yellow"
    },
    {
      "x": -7,
      "y": 9,
      "z": 6,
      "name": "Plant_Coral_Block_Yellow"
    },
    {
      "x": -7,
      "y": 10,
      "z": 6,
      "name": "Plant_Coral_Block_Red"
    },
    {
      "x": -7,
      "y": 11,
      "z": 6,
      "name": "Plant_Coral_Block_Red"
    },
    {
      "x": -7,
      "y": 4,
      "z": 7,
      "name": "Plant_Coral_Block_Yellow"
    },
    {
      "x": -7,
      "y": 5,
      "z": 7,
      "name": "Plant_Coral_Block_Yellow"
    },
    {
      "x": -7,
      "y": 6,
      "z": 7,
      "name": "Plant_Coral_Block_Yellow"
    },
    {
      "x": -7,
      "y": 7,
      "z": 7,
      "name": "Plant_Coral_Block_Yellow"
    },
    {
      "x": -7,
      "y": 8,
      "z": 7,
      "name": "Plant_Coral_Block_Yellow"
    },
    {
      "x": -7,
      "y": 9,
      "z": 7,
      "name": "Plant_Coral_Block_Yellow"
    },
    {
      "x": -7,
      "y": 10,
      "z": 7,
      "name": "Plant_Coral_Block_Red"
    },
    {
      "x": -7,
      "y": 11,
      "z": 7,
      "name": "Plant_Coral_Block_Red"
    },
    {
      "x": -7,
      "y": 5,
      "z": 8,
      "name": "Plant_Coral_Block_Yellow"
    },
    {
      "x": -7,
      "y": 6,
      "z": 8,
      "name": "Plant_Coral_Block_Yellow"
    },
    {
      "x": -7,
      "y": 7,
      "z": 8,
      "name": "Plant_Coral_Block_Yellow"
    },
    {
      "x": -7,
      "y": 8,
      "z": 8,
      "name": "Plant_Coral_Block_Yellow"
    },
    {
      "x": -7,
      "y": 9,
      "z": 8,
      "name": "Plant_Coral_Block_Red"
    },
    {
      "x": -7,
      "y": 10,
      "z": 8,
      "name": "Plant_Coral_Block_Red"
    },
    {
      "x": -7,
      "y": 5,
      "z": 9,
      "name": "Plant_Coral_Block_Yellow"
    },
    {
      "x": -7,
      "y": 6,
      "z": 9,
      "name": "Plant_Coral_Block_Yellow"
    },
    {
      "x": -7,
      "y": 7,
      "z": 9,
      "name": "Plant_Coral_Block_Yellow"
    },
    {
      "x": -7,
      "y": 8,
      "z": 9,
      "name": "Plant_Coral_Block_Yellow"
    },
    {
      "x": -7,
      "y": 9,
      "z": 9,
      "name": "Plant_Coral_Block_Red"
    },
    {
      "x": -7,
      "y": 10,
      "z": 9,
      "name": "Plant_Coral_Block_Red"
    },
    {
      "x": -7,
      "y": 7,
      "z": 10,
      "name": "Plant_Coral_Block_Red"
    },
    {
      "x": -7,
      "y": 7,
      "z": 11,
      "name": "Plant_Coral_Block_Red"
    },
    {
      "x": -6,
      "y": 7,
      "z": -11,
      "name": "Plant_Coral_Block_Red"
    },
    {
      "x": -6,
      "y": 6,
      "z": -10,
      "name": "Plant_Coral_Block_Yellow"
    },
    {
      "x": -6,
      "y": 7,
      "z": -10,
      "name": "Plant_Coral_Block_Red"
    },
    {
      "x": -6,
      "y": 8,
      "z": -10,
      "name": "Plant_Coral_Block_Yellow"
    },
    {
      "x": -6,
      "y": 5,
      "z": -9,
      "name": "Plant_Coral_Block_Yellow"
    },
    {
      "x": -6,
      "y": 6,
      "z": -9,
      "name": "Plant_Coral_Block_Yellow"
    },
    {
      "x": -6,
      "y": 7,
      "z": -9,
      "name": "Plant_Coral_Block_Yellow"
    },
    {
      "x": -6,
      "y": 8,
      "z": -9,
      "name": "Plant_Coral_Block_Yellow"
    },
    {
      "x": -6,
      "y": 9,
      "z": -9,
      "name": "Plant_Coral_Block_Red"
    },
    {
      "x": -6,
      "y": 10,
      "z": -9,
      "name": "Plant_Coral_Block_Red"
    },
    {
      "x": -6,
      "y": 4,
      "z": -8,
      "name": "Plant_Coral_Block_Yellow"
    },
    {
      "x": -6,
      "y": 5,
      "z": -8,
      "name": "Plant_Coral_Block_Yellow"
    },
    {
      "x": -6,
      "y": 6,
      "z": -8,
      "name": "Plant_Coral_Block_Yellow"
    },
    {
      "x": -6,
      "y": 7,
      "z": -8,
      "name": "Plant_Coral_Block_Yellow"
    },
    {
      "x": -6,
      "y": 8,
      "z": -8,
      "name": "Plant_Coral_Block_Yellow"
    },
    {
      "x": -6,
      "y": 9,
      "z": -8,
      "name": "Plant_Coral_Block_Yellow"
    },
    {
      "x": -6,
      "y": 10,
      "z": -8,
      "name": "Plant_Coral_Block_Yellow"
    },
    {
      "x": -6,
      "y": 11,
      "z": -8,
      "name": "Plant_Coral_Bush_Orange"
    },
    {
      "x": -6,
      "y": 4,
      "z": -7,
      "name": "Plant_Coral_Block_Yellow"
    },
    {
      "x": -6,
      "y": 5,
      "z": -7,
      "name": "Plant_Coral_Block_Yellow"
    },
    {
      "x": -6,
      "y": 6,
      "z": -7,
      "name": "Plant_Coral_Block_Yellow"
    },
    {
      "x": -6,
      "y": 7,
      "z": -7,
      "name": "Plant_Coral_Block_Yellow"
    },
    {
      "x": -6,
      "y": 8,
      "z": -7,
      "name": "Plant_Coral_Block_Yellow"
    },
    {
      "x": -6,
      "y": 9,
      "z": -7,
      "name": "Plant_Coral_Block_Yellow"
    },
    {
      "x": -6,
      "y": 10,
      "z": -7,
      "name": "Plant_Coral_Block_Red"
    },
    {
      "x": -6,
      "y": 11,
      "z": -7,
      "name": "Plant_Coral_Block_Red"
    },
    {
      "x": -6,
      "y": 4,
      "z": -6,
      "name": "Plant_Coral_Block_Yellow"
    },
    {
      "x": -6,
      "y": 5,
      "z": -6,
      "name": "Plant_Coral_Block_Yellow"
    },
    {
      "x": -6,
      "y": 6,
      "z": -6,
      "name": "Plant_Coral_Block_Yellow"
    },
    {
      "x": -6,
      "y": 7,
      "z": -6,
      "name": "Plant_Coral_Block_Yellow"
    },
    {
      "x": -6,
      "y": 8,
      "z": -6,
      "name": "Plant_Coral_Block_Yellow"
    },
    {
      "x": -6,
      "y": 9,
      "z": -6,
      "name": "Plant_Coral_Block_Yellow"
    },
    {
      "x": -6,
      "y": 10,
      "z": -6,
      "name": "Plant_Coral_Block_Yellow"
    },
    {
      "x": -6,
      "y": 3,
      "z": -5,
      "name": "Plant_Coral_Block_Yellow"
    },
    {
      "x": -6,
      "y": 4,
      "z": -5,
      "name": "Plant_Coral_Block_Yellow"
    },
    {
      "x": -6,
      "y": 5,
      "z": -5,
      "name": "Plant_Coral_Block_Yellow"
    },
    {
      "x": -6,
      "y": 6,
      "z": -5,
      "name": "Plant_Coral_Block_Yellow"
    },
    {
      "x": -6,
      "y": 7,
      "z": -5,
      "name": "Plant_Coral_Block_Yellow"
    },
    {
      "x": -6,
      "y": 8,
      "z": -5,
      "name": "Plant_Coral_Block_Yellow"
    },
    {
      "x": -6,
      "y": 9,
      "z": -5,
      "name": "Plant_Coral_Block_Yellow"
    },
    {
      "x": -6,
      "y": 10,
      "z": -5,
      "name": "Plant_Coral_Block_Yellow"
    },
    {
      "x": -6,
      "y": 11,
      "z": -5,
      "name": "Plant_Coral_Block_Red"
    },
    {
      "x": -6,
      "y": 12,
      "z": -5,
      "name": "Plant_Coral_Block_Red"
    },
    {
      "x": -6,
      "y": 3,
      "z": -4,
      "name": "Plant_Coral_Block_Yellow"
    },
    {
      "x": -6,
      "y": 4,
      "z": -4,
      "name": "Plant_Coral_Block_Yellow"
    },
    {
      "x": -6,
      "y": 5,
      "z": -4,
      "name": "Plant_Coral_Block_Yellow"
    },
    {
      "x": -6,
      "y": 6,
      "z": -4,
      "name": "Plant_Coral_Block_Yellow"
    },
    {
      "x": -6,
      "y": 7,
      "z": -4,
      "name": "Plant_Coral_Block_Yellow"
    },
    {
      "x": -6,
      "y": 8,
      "z": -4,
      "name": "Plant_Coral_Block_Yellow"
    },
    {
      "x": -6,
      "y": 9,
      "z": -4,
      "name": "Plant_Coral_Block_Yellow"
    },
    {
      "x": -6,
      "y": 10,
      "z": -4,
      "name": "Plant_Coral_Block_Yellow"
    },
    {
      "x": -6,
      "y": 11,
      "z": -4,
      "name": "Plant_Coral_Block_Red"
    },
    {
      "x": -6,
      "y": 12,
      "z": -4,
      "name": "Plant_Coral_Block_Red"
    },
    {
      "x": -6,
      "y": 3,
      "z": -3,
      "name": "Plant_Coral_Block_Yellow"
    },
    {
      "x": -6,
      "y": 4,
      "z": -3,
      "name": "Plant_Coral_Block_Yellow"
    },
    {
      "x": -6,
      "y": 5,
      "z": -3,
      "name": "Plant_Coral_Block_Yellow"
    },
    {
      "x": -6,
      "y": 6,
      "z": -3,
      "name": "Plant_Coral_Block_Yellow"
    },
    {
      "x": -6,
      "y": 7,
      "z": -3,
      "name": "Plant_Coral_Block_Yellow"
    },
    {
      "x": -6,
      "y": 8,
      "z": -3,
      "name": "Plant_Coral_Block_Yellow"
    },
    {
      "x": -6,
      "y": 9,
      "z": -3,
      "name": "Plant_Coral_Block_Yellow"
    },
    {
      "x": -6,
      "y": 10,
      "z": -3,
      "name": "Plant_Coral_Block_Yellow"
    },
    {
      "x": -6,
      "y": 11,
      "z": -3,
      "name": "Plant_Coral_Block_Red"
    },
    {
      "x": -6,
      "y": 12,
      "z": -3,
      "name": "Plant_Coral_Block_Red"
    },
    {
      "x": -6,
      "y": 3,
      "z": -2,
      "name": "Plant_Coral_Block_Yellow"
    },
    {
      "x": -6,
      "y": 4,
      "z": -2,
      "name": "Plant_Coral_Block_Yellow"
    },
    {
      "x": -6,
      "y": 5,
      "z": -2,
      "name": "Plant_Coral_Block_Yellow"
    },
    {
      "x": -6,
      "y": 6,
      "z": -2,
      "name": "Plant_Coral_Block_Yellow"
    },
    {
      "x": -6,
      "y": 7,
      "z": -2,
      "name": "Plant_Coral_Block_Yellow"
    },
    {
      "x": -6,
      "y": 8,
      "z": -2,
      "name": "Plant_Coral_Block_Yellow"
    },
    {
      "x": -6,
      "y": 9,
      "z": -2,
      "name": "Plant_Coral_Block_Yellow"
    },
    {
      "x": -6,
      "y": 10,
      "z": -2,
      "name": "Plant_Coral_Block_Yellow"
    },
    {
      "x": -6,
      "y": 11,
      "z": -2,
      "name": "Plant_Coral_Block_Yellow"
    },
    {
      "x": -6,
      "y": 3,
      "z": -1,
      "name": "Plant_Coral_Block_Yellow"
    },
    {
      "x": -6,
      "y": 4,
      "z": -1,
      "name": "Plant_Coral_Block_Yellow"
    },
    {
      "x": -6,
      "y": 5,
      "z": -1,
      "name": "Plant_Coral_Block_Yellow"
    },
    {
      "x": -6,
      "y": 6,
      "z": -1,
      "name": "Plant_Coral_Block_Yellow"
    },
    {
      "x": -6,
      "y": 7,
      "z": -1,
      "name": "Plant_Coral_Block_Yellow"
    },
    {
      "x": -6,
      "y": 8,
      "z": -1,
      "name": "Plant_Coral_Block_Yellow"
    },
    {
      "x": -6,
      "y": 9,
      "z": -1,
      "name": "Plant_Coral_Block_Yellow"
    },
    {
      "x": -6,
      "y": 10,
      "z": -1,
      "name": "Plant_Coral_Block_Yellow"
    },
    {
      "x": -6,
      "y": 11,
      "z": -1,
      "name": "Plant_Coral_Block_Red"
    },
    {
      "x": -6,
      "y": 12,
      "z": -1,
      "name": "Plant_Coral_Block_Red"
    },
    {
      "x": -6,
      "y": 3,
      "z": 0,
      "name": "Plant_Coral_Block_Yellow"
    },
    {
      "x": -6,
      "y": 4,
      "z": 0,
      "name": "Plant_Coral_Block_Yellow"
    },
    {
      "x": -6,
      "y": 5,
      "z": 0,
      "name": "Plant_Coral_Block_Yellow"
    },
    {
      "x": -6,
      "y": 6,
      "z": 0,
      "name": "Plant_Coral_Block_Yellow"
    },
    {
      "x": -6,
      "y": 7,
      "z": 0,
      "name": "Plant_Coral_Block_Yellow"
    },
    {
      "x": -6,
      "y": 8,
      "z": 0,
      "name": "Plant_Coral_Block_Yellow"
    },
    {
      "x": -6,
      "y": 9,
      "z": 0,
      "name": "Plant_Coral_Block_Yellow"
    },
    {
      "x": -6,
      "y": 10,
      "z": 0,
      "name": "Plant_Coral_Block_Yellow"
    },
    {
      "x": -6,
      "y": 11,
      "z": 0,
      "name": "Plant_Coral_Block_Yellow"
    },
    {
      "x": -6,
      "y": 12,
      "z": 0,
      "name": "Plant_Coral_Bush_Orange"
    },
    {
      "x": -6,
      "y": 3,
      "z": 1,
      "name": "Plant_Coral_Block_Yellow"
    },
    {
      "x": -6,
      "y": 4,
      "z": 1,
      "name": "Plant_Coral_Block_Yellow"
    },
    {
      "x": -6,
      "y": 5,
      "z": 1,
      "name": "Plant_Coral_Block_Yellow"
    },
    {
      "x": -6,
      "y": 6,
      "z": 1,
      "name": "Plant_Coral_Block_Yellow"
    },
    {
      "x": -6,
      "y": 7,
      "z": 1,
      "name": "Plant_Coral_Block_Yellow"
    },
    {
      "x": -6,
      "y": 8,
      "z": 1,
      "name": "Plant_Coral_Block_Yellow"
    },
    {
      "x": -6,
      "y": 9,
      "z": 1,
      "name": "Plant_Coral_Block_Yellow"
    },
    {
      "x": -6,
      "y": 10,
      "z": 1,
      "name": "Plant_Coral_Block_Yellow"
    },
    {
      "x": -6,
      "y": 11,
      "z": 1,
      "name": "Plant_Coral_Block_Yellow"
    },
    {
      "x": -6,
      "y": 12,
      "z": 1,
      "name": "Plant_Coral_Bush_Orange"
    },
    {
      "x": -6,
      "y": 3,
      "z": 2,
      "name": "Plant_Coral_Block_Yellow"
    },
    {
      "x": -6,
      "y": 4,
      "z": 2,
      "name": "Plant_Coral_Block_Yellow"
    },
    {
      "x": -6,
      "y": 5,
      "z": 2,
      "name": "Plant_Coral_Block_Yellow"
    },
    {
      "x": -6,
      "y": 6,
      "z": 2,
      "name": "Plant_Coral_Block_Yellow"
    },
    {
      "x": -6,
      "y": 7,
      "z": 2,
      "name": "Plant_Coral_Block_Yellow"
    },
    {
      "x": -6,
      "y": 8,
      "z": 2,
      "name": "Plant_Coral_Block_Yellow"
    },
    {
      "x": -6,
      "y": 9,
      "z": 2,
      "name": "Plant_Coral_Block_Yellow"
    },
    {
      "x": -6,
      "y": 10,
      "z": 2,
      "name": "Plant_Coral_Block_Yellow"
    },
    {
      "x": -6,
      "y": 11,
      "z": 2,
      "name": "Plant_Coral_Block_Yellow"
    },
    {
      "x": -6,
      "y": 3,
      "z": 3,
      "name": "Plant_Coral_Block_Yellow"
    },
    {
      "x": -6,
      "y": 4,
      "z": 3,
      "name": "Plant_Coral_Block_Yellow"
    },
    {
      "x": -6,
      "y": 5,
      "z": 3,
      "name": "Plant_Coral_Block_Yellow"
    },
    {
      "x": -6,
      "y": 6,
      "z": 3,
      "name": "Plant_Coral_Block_Yellow"
    },
    {
      "x": -6,
      "y": 7,
      "z": 3,
      "name": "Plant_Coral_Block_Yellow"
    },
    {
      "x": -6,
      "y": 8,
      "z": 3,
      "name": "Plant_Coral_Block_Yellow"
    },
    {
      "x": -6,
      "y": 9,
      "z": 3,
      "name": "Plant_Coral_Block_Yellow"
    },
    {
      "x": -6,
      "y": 10,
      "z": 3,
      "name": "Plant_Coral_Block_Yellow"
    },
    {
      "x": -6,
      "y": 11,
      "z": 3,
      "name": "Plant_Coral_Block_Red"
    },
    {
      "x": -6,
      "y": 12,
      "z": 3,
      "name": "Plant_Coral_Block_Red"
    },
    {
      "x": -6,
      "y": 3,
      "z": 4,
      "name": "Plant_Coral_Block_Yellow"
    },
    {
      "x": -6,
      "y": 4,
      "z": 4,
      "name": "Plant_Coral_Block_Yellow"
    },
    {
      "x": -6,
      "y": 5,
      "z": 4,
      "name": "Plant_Coral_Block_Yellow"
    },
    {
      "x": -6,
      "y": 6,
      "z": 4,
      "name": "Plant_Coral_Block_Yellow"
    },
    {
      "x": -6,
      "y": 7,
      "z": 4,
      "name": "Plant_Coral_Block_Yellow"
    },
    {
      "x": -6,
      "y": 8,
      "z": 4,
      "name": "Plant_Coral_Block_Yellow"
    },
    {
      "x": -6,
      "y": 9,
      "z": 4,
      "name": "Plant_Coral_Block_Yellow"
    },
    {
      "x": -6,
      "y": 10,
      "z": 4,
      "name": "Plant_Coral_Block_Yellow"
    },
    {
      "x": -6,
      "y": 11,
      "z": 4,
      "name": "Plant_Coral_Block_Red"
    },
    {
      "x": -6,
      "y": 12,
      "z": 4,
      "name": "Plant_Coral_Block_Red"
    },
    {
      "x": -6,
      "y": 3,
      "z": 5,
      "name": "Plant_Coral_Block_Yellow"
    },
    {
      "x": -6,
      "y": 4,
      "z": 5,
      "name": "Plant_Coral_Block_Yellow"
    },
    {
      "x": -6,
      "y": 5,
      "z": 5,
      "name": "Plant_Coral_Block_Yellow"
    },
    {
      "x": -6,
      "y": 6,
      "z": 5,
      "name": "Plant_Coral_Block_Yellow"
    },
    {
      "x": -6,
      "y": 7,
      "z": 5,
      "name": "Plant_Coral_Block_Yellow"
    },
    {
      "x": -6,
      "y": 8,
      "z": 5,
      "name": "Plant_Coral_Block_Yellow"
    },
    {
      "x": -6,
      "y": 9,
      "z": 5,
      "name": "Plant_Coral_Block_Yellow"
    },
    {
      "x": -6,
      "y": 10,
      "z": 5,
      "name": "Plant_Coral_Block_Yellow"
    },
    {
      "x": -6,
      "y": 11,
      "z": 5,
      "name": "Plant_Coral_Block_Yellow"
    },
    {
      "x": -6,
      "y": 4,
      "z": 6,
      "name": "Plant_Coral_Block_Yellow"
    },
    {
      "x": -6,
      "y": 5,
      "z": 6,
      "name": "Plant_Coral_Block_Yellow"
    },
    {
      "x": -6,
      "y": 6,
      "z": 6,
      "name": "Plant_Coral_Block_Yellow"
    },
    {
      "x": -6,
      "y": 7,
      "z": 6,
      "name": "Plant_Coral_Block_Yellow"
    },
    {
      "x": -6,
      "y": 8,
      "z": 6,
      "name": "Plant_Coral_Block_Yellow"
    },
    {
      "x": -6,
      "y": 9,
      "z": 6,
      "name": "Plant_Coral_Block_Yellow"
    },
    {
      "x": -6,
      "y": 10,
      "z": 6,
      "name": "Plant_Coral_Block_Yellow"
    },
    {
      "x": -6,
      "y": 4,
      "z": 7,
      "name": "Plant_Coral_Block_Yellow"
    },
    {
      "x": -6,
      "y": 5,
      "z": 7,
      "name": "Plant_Coral_Block_Yellow"
    },
    {
      "x": -6,
      "y": 6,
      "z": 7,
      "name": "Plant_Coral_Block_Yellow"
    },
    {
      "x": -6,
      "y": 7,
      "z": 7,
      "name": "Plant_Coral_Block_Yellow"
    },
    {
      "x": -6,
      "y": 8,
      "z": 7,
      "name": "Plant_Coral_Block_Yellow"
    },
    {
      "x": -6,
      "y": 9,
      "z": 7,
      "name": "Plant_Coral_Block_Yellow"
    },
    {
      "x": -6,
      "y": 10,
      "z": 7,
      "name": "Plant_Coral_Block_Yellow"
    },
    {
      "x": -6,
      "y": 4,
      "z": 8,
      "name": "Plant_Coral_Block_Yellow"
    },
    {
      "x": -6,
      "y": 5,
      "z": 8,
      "name": "Plant_Coral_Block_Yellow"
    },
    {
      "x": -6,
      "y": 6,
      "z": 8,
      "name": "Plant_Coral_Block_Yellow"
    },
    {
      "x": -6,
      "y": 7,
      "z": 8,
      "name": "Plant_Coral_Block_Yellow"
    },
    {
      "x": -6,
      "y": 8,
      "z": 8,
      "name": "Plant_Coral_Block_Yellow"
    },
    {
      "x": -6,
      "y": 9,
      "z": 8,
      "name": "Plant_Coral_Block_Yellow"
    },
    {
      "x": -6,
      "y": 10,
      "z": 8,
      "name": "Plant_Coral_Block_Yellow"
    },
    {
      "x": -6,
      "y": 5,
      "z": 9,
      "name": "Plant_Coral_Block_Yellow"
    },
    {
      "x": -6,
      "y": 6,
      "z": 9,
      "name": "Plant_Coral_Block_Yellow"
    },
    {
      "x": -6,
      "y": 7,
      "z": 9,
      "name": "Plant_Coral_Block_Yellow"
    },
    {
      "x": -6,
      "y": 8,
      "z": 9,
      "name": "Plant_Coral_Block_Yellow"
    },
    {
      "x": -6,
      "y": 9,
      "z": 9,
      "name": "Plant_Coral_Block_Red"
    },
    {
      "x": -6,
      "y": 10,
      "z": 9,
      "name": "Plant_Coral_Block_Red"
    },
    {
      "x": -6,
      "y": 6,
      "z": 10,
      "name": "Plant_Coral_Block_Yellow"
    },
    {
      "x": -6,
      "y": 7,
      "z": 10,
      "name": "Plant_Coral_Block_Red"
    },
    {
      "x": -6,
      "y": 8,
      "z": 10,
      "name": "Plant_Coral_Block_Yellow"
    },
    {
      "x": -6,
      "y": 9,
      "z": 10,
      "name": "Plant_Coral_Bush_Orange"
    },
    {
      "x": -6,
      "y": 7,
      "z": 11,
      "name": "Plant_Coral_Block_Red"
    },
    {
      "x": -5,
      "y": 7,
      "z": -12,
      "name": "Plant_Coral_Block_Red"
    },
    {
      "x": -5,
      "y": 8,
      "z": -12,
      "name": "Plant_Coral_Block_Red"
    },
    {
      "x": -5,
      "y": 6,
      "z": -11,
      "name": "Plant_Coral_Block_Yellow"
    },
    {
      "x": -5,
      "y": 7,
      "z": -11,
      "name": "Plant_Coral_Block_Red"
    },
    {
      "x": -5,
      "y": 8,
      "z": -11,
      "name": "Plant_Coral_Block_Red"
    },
    {
      "x": -5,
      "y": 5,
      "z": -10,
      "name": "Plant_Coral_Block_Yellow"
    },
    {
      "x": -5,
      "y": 6,
      "z": -10,
      "name": "Plant_Coral_Block_Yellow"
    },
    {
      "x": -5,
      "y": 7,
      "z": -10,
      "name": "Plant_Coral_Block_Yellow"
    },
    {
      "x": -5,
      "y": 8,
      "z": -10,
      "name": "Plant_Coral_Block_Yellow"
    },
    {
      "x": -5,
      "y": 9,
      "z": -10,
      "name": "Plant_Coral_Block_Yellow"
    },
    {
      "x": -5,
      "y": 4,
      "z": -9,
      "name": "Plant_Coral_Block_Yellow"
    },
    {
      "x": -5,
      "y": 5,
      "z": -9,
      "name": "Plant_Coral_Block_Yellow"
    },
    {
      "x": -5,
      "y": 6,
      "z": -9,
      "name": "Plant_Coral_Block_Yellow"
    },
    {
      "x": -5,
      "y": 7,
      "z": -9,
      "name": "Plant_Coral_Block_Yellow"
    },
    {
      "x": -5,
      "y": 8,
      "z": -9,
      "name": "Plant_Coral_Block_Yellow"
    },
    {
      "x": -5,
      "y": 9,
      "z": -9,
      "name": "Plant_Coral_Block_Yellow"
    },
    {
      "x": -5,
      "y": 10,
      "z": -9,
      "name": "Plant_Coral_Block_Red"
    },
    {
      "x": -5,
      "y": 11,
      "z": -9,
      "name": "Plant_Coral_Block_Red"
    },
    {
      "x": -5,
      "y": 4,
      "z": -8,
      "name": "Plant_Coral_Block_Yellow"
    },
    {
      "x": -5,
      "y": 5,
      "z": -8,
      "name": "Plant_Coral_Block_Yellow"
    },
    {
      "x": -5,
      "y": 6,
      "z": -8,
      "name": "Plant_Coral_Block_Yellow"
    },
    {
      "x": -5,
      "y": 7,
      "z": -8,
      "name": "Plant_Coral_Block_Yellow"
    },
    {
      "x": -5,
      "y": 8,
      "z": -8,
      "name": "Plant_Coral_Block_Yellow"
    },
    {
      "x": -5,
      "y": 9,
      "z": -8,
      "name": "Plant_Coral_Block_Yellow"
    },
    {
      "x": -5,
      "y": 10,
      "z": -8,
      "name": "Plant_Coral_Block_Yellow"
    },
    {
      "x": -5,
      "y": 4,
      "z": -7,
      "name": "Plant_Coral_Block_Yellow"
    },
    {
      "x": -5,
      "y": 5,
      "z": -7,
      "name": "Plant_Coral_Block_Yellow"
    },
    {
      "x": -5,
      "y": 6,
      "z": -7,
      "name": "Plant_Coral_Block_Yellow"
    },
    {
      "x": -5,
      "y": 7,
      "z": -7,
      "name": "Plant_Coral_Block_Yellow"
    },
    {
      "x": -5,
      "y": 8,
      "z": -7,
      "name": "Plant_Coral_Block_Yellow"
    },
    {
      "x": -5,
      "y": 9,
      "z": -7,
      "name": "Plant_Coral_Block_Yellow"
    },
    {
      "x": -5,
      "y": 10,
      "z": -7,
      "name": "Plant_Coral_Block_Red"
    },
    {
      "x": -5,
      "y": 11,
      "z": -7,
      "name": "Plant_Coral_Block_Red"
    },
    {
      "x": -5,
      "y": 3,
      "z": -6,
      "name": "Plant_Coral_Block_Yellow"
    },
    {
      "x": -5,
      "y": 4,
      "z": -6,
      "name": "Plant_Coral_Block_Yellow"
    },
    {
      "x": -5,
      "y": 5,
      "z": -6,
      "name": "Plant_Coral_Block_Yellow"
    },
    {
      "x": -5,
      "y": 6,
      "z": -6,
      "name": "Plant_Coral_Block_Yellow"
    },
    {
      "x": -5,
      "y": 7,
      "z": -6,
      "name": "Plant_Coral_Block_Yellow"
    },
    {
      "x": -5,
      "y": 8,
      "z": -6,
      "name": "Plant_Coral_Block_Yellow"
    },
    {
      "x": -5,
      "y": 9,
      "z": -6,
      "name": "Plant_Coral_Block_Yellow"
    },
    {
      "x": -5,
      "y": 10,
      "z": -6,
      "name": "Plant_Coral_Block_Yellow"
    },
    {
      "x": -5,
      "y": 11,
      "z": -6,
      "name": "Plant_Coral_Block_Yellow"
    },
    {
      "x": -5,
      "y": 12,
      "z": -6,
      "name": "Plant_Coral_Bush_Orange"
    },
    {
      "x": -5,
      "y": 3,
      "z": -5,
      "name": "Plant_Coral_Block_Yellow"
    },
    {
      "x": -5,
      "y": 4,
      "z": -5,
      "name": "Plant_Coral_Block_Yellow"
    },
    {
      "x": -5,
      "y": 5,
      "z": -5,
      "name": "Plant_Coral_Block_Yellow"
    },
    {
      "x": -5,
      "y": 6,
      "z": -5,
      "name": "Plant_Coral_Block_Yellow"
    },
    {
      "x": -5,
      "y": 7,
      "z": -5,
      "name": "Plant_Coral_Block_Yellow"
    },
    {
      "x": -5,
      "y": 8,
      "z": -5,
      "name": "Plant_Coral_Block_Yellow"
    },
    {
      "x": -5,
      "y": 9,
      "z": -5,
      "name": "Plant_Coral_Block_Yellow"
    },
    {
      "x": -5,
      "y": 10,
      "z": -5,
      "name": "Plant_Coral_Block_Yellow"
    },
    {
      "x": -5,
      "y": 11,
      "z": -5,
      "name": "Plant_Coral_Block_Red"
    },
    {
      "x": -5,
      "y": 12,
      "z": -5,
      "name": "Plant_Coral_Block_Red"
    },
    {
      "x": -5,
      "y": 3,
      "z": -4,
      "name": "Plant_Coral_Block_Yellow"
    },
    {
      "x": -5,
      "y": 4,
      "z": -4,
      "name": "Plant_Coral_Block_Yellow"
    },
    {
      "x": -5,
      "y": 5,
      "z": -4,
      "name": "Plant_Coral_Block_Yellow"
    },
    {
      "x": -5,
      "y": 6,
      "z": -4,
      "name": "Plant_Coral_Block_Yellow"
    },
    {
      "x": -5,
      "y": 7,
      "z": -4,
      "name": "Plant_Coral_Block_Yellow"
    },
    {
      "x": -5,
      "y": 8,
      "z": -4,
      "name": "Plant_Coral_Block_Yellow"
    },
    {
      "x": -5,
      "y": 9,
      "z": -4,
      "name": "Plant_Coral_Block_Yellow"
    },
    {
      "x": -5,
      "y": 10,
      "z": -4,
      "name": "Plant_Coral_Block_Yellow"
    },
    {
      "x": -5,
      "y": 11,
      "z": -4,
      "name": "Plant_Coral_Block_Yellow"
    },
    {
      "x": -5,
      "y": 3,
      "z": -3,
      "name": "Plant_Coral_Block_Yellow"
    },
    {
      "x": -5,
      "y": 4,
      "z": -3,
      "name": "Plant_Coral_Block_Yellow"
    },
    {
      "x": -5,
      "y": 5,
      "z": -3,
      "name": "Plant_Coral_Block_Yellow"
    },
    {
      "x": -5,
      "y": 6,
      "z": -3,
      "name": "Plant_Coral_Block_Yellow"
    },
    {
      "x": -5,
      "y": 7,
      "z": -3,
      "name": "Plant_Coral_Block_Yellow"
    },
    {
      "x": -5,
      "y": 8,
      "z": -3,
      "name": "Plant_Coral_Block_Yellow"
    },
    {
      "x": -5,
      "y": 9,
      "z": -3,
      "name": "Plant_Coral_Block_Yellow"
    },
    {
      "x": -5,
      "y": 10,
      "z": -3,
      "name": "Plant_Coral_Block_Yellow"
    },
    {
      "x": -5,
      "y": 11,
      "z": -3,
      "name": "Plant_Coral_Block_Red"
    },
    {
      "x": -5,
      "y": 12,
      "z": -3,
      "name": "Plant_Coral_Block_Red"
    },
    {
      "x": -5,
      "y": 3,
      "z": -2,
      "name": "Plant_Coral_Block_Yellow"
    },
    {
      "x": -5,
      "y": 4,
      "z": -2,
      "name": "Plant_Coral_Block_Yellow"
    },
    {
      "x": -5,
      "y": 5,
      "z": -2,
      "name": "Plant_Coral_Block_Yellow"
    },
    {
      "x": -5,
      "y": 6,
      "z": -2,
      "name": "Plant_Coral_Block_Yellow"
    },
    {
      "x": -5,
      "y": 7,
      "z": -2,
      "name": "Plant_Coral_Block_Yellow"
    },
    {
      "x": -5,
      "y": 8,
      "z": -2,
      "name": "Plant_Coral_Block_Yellow"
    },
    {
      "x": -5,
      "y": 9,
      "z": -2,
      "name": "Plant_Coral_Block_Yellow"
    },
    {
      "x": -5,
      "y": 10,
      "z": -2,
      "name": "Plant_Coral_Block_Yellow"
    },
    {
      "x": -5,
      "y": 11,
      "z": -2,
      "name": "Plant_Coral_Block_Yellow"
    },
    {
      "x": -5,
      "y": 3,
      "z": -1,
      "name": "Plant_Coral_Block_Yellow"
    },
    {
      "x": -5,
      "y": 4,
      "z": -1,
      "name": "Plant_Coral_Block_Yellow"
    },
    {
      "x": -5,
      "y": 5,
      "z": -1,
      "name": "Plant_Coral_Block_Yellow"
    },
    {
      "x": -5,
      "y": 6,
      "z": -1,
      "name": "Plant_Coral_Block_Yellow"
    },
    {
      "x": -5,
      "y": 7,
      "z": -1,
      "name": "Plant_Coral_Block_Yellow"
    },
    {
      "x": -5,
      "y": 8,
      "z": -1,
      "name": "Plant_Coral_Block_Yellow"
    },
    {
      "x": -5,
      "y": 9,
      "z": -1,
      "name": "Plant_Coral_Block_Yellow"
    },
    {
      "x": -5,
      "y": 10,
      "z": -1,
      "name": "Plant_Coral_Block_Yellow"
    },
    {
      "x": -5,
      "y": 11,
      "z": -1,
      "name": "Plant_Coral_Block_Red"
    },
    {
      "x": -5,
      "y": 12,
      "z": -1,
      "name": "Plant_Coral_Block_Red"
    },
    {
      "x": -5,
      "y": 3,
      "z": 0,
      "name": "Plant_Coral_Block_Yellow"
    },
    {
      "x": -5,
      "y": 4,
      "z": 0,
      "name": "Plant_Coral_Block_Yellow"
    },
    {
      "x": -5,
      "y": 5,
      "z": 0,
      "name": "Plant_Coral_Block_Yellow"
    },
    {
      "x": -5,
      "y": 6,
      "z": 0,
      "name": "Plant_Coral_Block_Yellow"
    },
    {
      "x": -5,
      "y": 7,
      "z": 0,
      "name": "Plant_Coral_Block_Yellow"
    },
    {
      "x": -5,
      "y": 8,
      "z": 0,
      "name": "Plant_Coral_Block_Yellow"
    },
    {
      "x": -5,
      "y": 9,
      "z": 0,
      "name": "Plant_Coral_Block_Yellow"
    },
    {
      "x": -5,
      "y": 10,
      "z": 0,
      "name": "Plant_Coral_Block_Yellow"
    },
    {
      "x": -5,
      "y": 11,
      "z": 0,
      "name": "Plant_Coral_Block_Red"
    },
    {
      "x": -5,
      "y": 12,
      "z": 0,
      "name": "Plant_Coral_Block_Red"
    },
    {
      "x": -5,
      "y": 3,
      "z": 1,
      "name": "Plant_Coral_Block_Yellow"
    },
    {
      "x": -5,
      "y": 4,
      "z": 1,
      "name": "Plant_Coral_Block_Yellow"
    },
    {
      "x": -5,
      "y": 5,
      "z": 1,
      "name": "Plant_Coral_Block_Yellow"
    },
    {
      "x": -5,
      "y": 6,
      "z": 1,
      "name": "Plant_Coral_Block_Yellow"
    },
    {
      "x": -5,
      "y": 7,
      "z": 1,
      "name": "Plant_Coral_Block_Yellow"
    },
    {
      "x": -5,
      "y": 8,
      "z": 1,
      "name": "Plant_Coral_Block_Yellow"
    },
    {
      "x": -5,
      "y": 9,
      "z": 1,
      "name": "Plant_Coral_Block_Yellow"
    },
    {
      "x": -5,
      "y": 10,
      "z": 1,
      "name": "Plant_Coral_Block_Yellow"
    },
    {
      "x": -5,
      "y": 11,
      "z": 1,
      "name": "Plant_Coral_Block_Red"
    },
    {
      "x": -5,
      "y": 12,
      "z": 1,
      "name": "Plant_Coral_Block_Red"
    },
    {
      "x": -5,
      "y": 3,
      "z": 2,
      "name": "Plant_Coral_Block_Yellow"
    },
    {
      "x": -5,
      "y": 4,
      "z": 2,
      "name": "Plant_Coral_Block_Yellow"
    },
    {
      "x": -5,
      "y": 5,
      "z": 2,
      "name": "Plant_Coral_Block_Yellow"
    },
    {
      "x": -5,
      "y": 6,
      "z": 2,
      "name": "Plant_Coral_Block_Yellow"
    },
    {
      "x": -5,
      "y": 7,
      "z": 2,
      "name": "Plant_Coral_Block_Yellow"
    },
    {
      "x": -5,
      "y": 8,
      "z": 2,
      "name": "Plant_Coral_Block_Yellow"
    },
    {
      "x": -5,
      "y": 9,
      "z": 2,
      "name": "Plant_Coral_Block_Yellow"
    },
    {
      "x": -5,
      "y": 10,
      "z": 2,
      "name": "Plant_Coral_Block_Yellow"
    },
    {
      "x": -5,
      "y": 11,
      "z": 2,
      "name": "Plant_Coral_Block_Yellow"
    },
    {
      "x": -5,
      "y": 3,
      "z": 3,
      "name": "Plant_Coral_Block_Yellow"
    },
    {
      "x": -5,
      "y": 4,
      "z": 3,
      "name": "Plant_Coral_Block_Yellow"
    },
    {
      "x": -5,
      "y": 5,
      "z": 3,
      "name": "Plant_Coral_Block_Yellow"
    },
    {
      "x": -5,
      "y": 6,
      "z": 3,
      "name": "Plant_Coral_Block_Yellow"
    },
    {
      "x": -5,
      "y": 7,
      "z": 3,
      "name": "Plant_Coral_Block_Yellow"
    },
    {
      "x": -5,
      "y": 8,
      "z": 3,
      "name": "Plant_Coral_Block_Yellow"
    },
    {
      "x": -5,
      "y": 9,
      "z": 3,
      "name": "Plant_Coral_Block_Yellow"
    },
    {
      "x": -5,
      "y": 10,
      "z": 3,
      "name": "Plant_Coral_Block_Yellow"
    },
    {
      "x": -5,
      "y": 11,
      "z": 3,
      "name": "Plant_Coral_Block_Yellow"
    },
    {
      "x": -5,
      "y": 3,
      "z": 4,
      "name": "Plant_Coral_Block_Yellow"
    },
    {
      "x": -5,
      "y": 4,
      "z": 4,
      "name": "Plant_Coral_Block_Yellow"
    },
    {
      "x": -5,
      "y": 5,
      "z": 4,
      "name": "Plant_Coral_Block_Yellow"
    },
    {
      "x": -5,
      "y": 6,
      "z": 4,
      "name": "Plant_Coral_Block_Yellow"
    },
    {
      "x": -5,
      "y": 7,
      "z": 4,
      "name": "Plant_Coral_Block_Yellow"
    },
    {
      "x": -5,
      "y": 8,
      "z": 4,
      "name": "Plant_Coral_Block_Yellow"
    },
    {
      "x": -5,
      "y": 9,
      "z": 4,
      "name": "Plant_Coral_Block_Yellow"
    },
    {
      "x": -5,
      "y": 10,
      "z": 4,
      "name": "Plant_Coral_Block_Yellow"
    },
    {
      "x": -5,
      "y": 11,
      "z": 4,
      "name": "Plant_Coral_Block_Red"
    },
    {
      "x": -5,
      "y": 12,
      "z": 4,
      "name": "Plant_Coral_Block_Red"
    },
    {
      "x": -5,
      "y": 3,
      "z": 5,
      "name": "Plant_Coral_Block_Yellow"
    },
    {
      "x": -5,
      "y": 4,
      "z": 5,
      "name": "Plant_Coral_Block_Yellow"
    },
    {
      "x": -5,
      "y": 5,
      "z": 5,
      "name": "Plant_Coral_Block_Yellow"
    },
    {
      "x": -5,
      "y": 6,
      "z": 5,
      "name": "Plant_Coral_Block_Yellow"
    },
    {
      "x": -5,
      "y": 7,
      "z": 5,
      "name": "Plant_Coral_Block_Yellow"
    },
    {
      "x": -5,
      "y": 8,
      "z": 5,
      "name": "Plant_Coral_Block_Yellow"
    },
    {
      "x": -5,
      "y": 9,
      "z": 5,
      "name": "Plant_Coral_Block_Yellow"
    },
    {
      "x": -5,
      "y": 10,
      "z": 5,
      "name": "Plant_Coral_Block_Yellow"
    },
    {
      "x": -5,
      "y": 11,
      "z": 5,
      "name": "Plant_Coral_Block_Yellow"
    },
    {
      "x": -5,
      "y": 3,
      "z": 6,
      "name": "Plant_Coral_Block_Yellow"
    },
    {
      "x": -5,
      "y": 4,
      "z": 6,
      "name": "Plant_Coral_Block_Yellow"
    },
    {
      "x": -5,
      "y": 5,
      "z": 6,
      "name": "Plant_Coral_Block_Yellow"
    },
    {
      "x": -5,
      "y": 6,
      "z": 6,
      "name": "Plant_Coral_Block_Yellow"
    },
    {
      "x": -5,
      "y": 7,
      "z": 6,
      "name": "Plant_Coral_Block_Yellow"
    },
    {
      "x": -5,
      "y": 8,
      "z": 6,
      "name": "Plant_Coral_Block_Yellow"
    },
    {
      "x": -5,
      "y": 9,
      "z": 6,
      "name": "Plant_Coral_Block_Yellow"
    },
    {
      "x": -5,
      "y": 10,
      "z": 6,
      "name": "Plant_Coral_Block_Yellow"
    },
    {
      "x": -5,
      "y": 11,
      "z": 6,
      "name": "Plant_Coral_Block_Red"
    },
    {
      "x": -5,
      "y": 12,
      "z": 6,
      "name": "Plant_Coral_Block_Red"
    },
    {
      "x": -5,
      "y": 4,
      "z": 7,
      "name": "Plant_Coral_Block_Yellow"
    },
    {
      "x": -5,
      "y": 5,
      "z": 7,
      "name": "Plant_Coral_Block_Yellow"
    },
    {
      "x": -5,
      "y": 6,
      "z": 7,
      "name": "Plant_Coral_Block_Yellow"
    },
    {
      "x": -5,
      "y": 7,
      "z": 7,
      "name": "Plant_Coral_Block_Yellow"
    },
    {
      "x": -5,
      "y": 8,
      "z": 7,
      "name": "Plant_Coral_Block_Yellow"
    },
    {
      "x": -5,
      "y": 9,
      "z": 7,
      "name": "Plant_Coral_Block_Yellow"
    },
    {
      "x": -5,
      "y": 10,
      "z": 7,
      "name": "Plant_Coral_Block_Red"
    },
    {
      "x": -5,
      "y": 11,
      "z": 7,
      "name": "Plant_Coral_Block_Red"
    },
    {
      "x": -5,
      "y": 4,
      "z": 8,
      "name": "Plant_Coral_Block_Yellow"
    },
    {
      "x": -5,
      "y": 5,
      "z": 8,
      "name": "Plant_Coral_Block_Yellow"
    },
    {
      "x": -5,
      "y": 6,
      "z": 8,
      "name": "Plant_Coral_Block_Yellow"
    },
    {
      "x": -5,
      "y": 7,
      "z": 8,
      "name": "Plant_Coral_Block_Yellow"
    },
    {
      "x": -5,
      "y": 8,
      "z": 8,
      "name": "Plant_Coral_Block_Yellow"
    },
    {
      "x": -5,
      "y": 9,
      "z": 8,
      "name": "Plant_Coral_Block_Yellow"
    },
    {
      "x": -5,
      "y": 10,
      "z": 8,
      "name": "Plant_Coral_Block_Red"
    },
    {
      "x": -5,
      "y": 11,
      "z": 8,
      "name": "Plant_Coral_Block_Red"
    },
    {
      "x": -5,
      "y": 4,
      "z": 9,
      "name": "Plant_Coral_Block_Yellow"
    },
    {
      "x": -5,
      "y": 5,
      "z": 9,
      "name": "Plant_Coral_Block_Yellow"
    },
    {
      "x": -5,
      "y": 6,
      "z": 9,
      "name": "Plant_Coral_Block_Yellow"
    },
    {
      "x": -5,
      "y": 7,
      "z": 9,
      "name": "Plant_Coral_Block_Yellow"
    },
    {
      "x": -5,
      "y": 8,
      "z": 9,
      "name": "Plant_Coral_Block_Yellow"
    },
    {
      "x": -5,
      "y": 9,
      "z": 9,
      "name": "Plant_Coral_Block_Yellow"
    },
    {
      "x": -5,
      "y": 10,
      "z": 9,
      "name": "Plant_Coral_Block_Red"
    },
    {
      "x": -5,
      "y": 11,
      "z": 9,
      "name": "Plant_Coral_Block_Red"
    },
    {
      "x": -5,
      "y": 5,
      "z": 10,
      "name": "Plant_Coral_Block_Yellow"
    },
    {
      "x": -5,
      "y": 6,
      "z": 10,
      "name": "Plant_Coral_Block_Yellow"
    },
    {
      "x": -5,
      "y": 7,
      "z": 10,
      "name": "Plant_Coral_Block_Yellow"
    },
    {
      "x": -5,
      "y": 8,
      "z": 10,
      "name": "Plant_Coral_Block_Yellow"
    },
    {
      "x": -5,
      "y": 9,
      "z": 10,
      "name": "Plant_Coral_Block_Yellow"
    },
    {
      "x": -5,
      "y": 6,
      "z": 11,
      "name": "Plant_Coral_Block_Yellow"
    },
    {
      "x": -5,
      "y": 7,
      "z": 11,
      "name": "Plant_Coral_Block_Red"
    },
    {
      "x": -5,
      "y": 8,
      "z": 11,
      "name": "Plant_Coral_Block_Red"
    },
    {
      "x": -5,
      "y": 9,
      "z": 11,
      "name": "Plant_Coral_Block_Red"
    },
    {
      "x": -4,
      "y": 8,
      "z": -12,
      "name": "Plant_Coral_Block_Red"
    },
    {
      "x": -4,
      "y": 6,
      "z": -11,
      "name": "Plant_Coral_Block_Yellow"
    },
    {
      "x": -4,
      "y": 7,
      "z": -11,
      "name": "Plant_Coral_Block_Yellow"
    },
    {
      "x": -4,
      "y": 8,
      "z": -11,
      "name": "Plant_Coral_Block_Red"
    },
    {
      "x": -4,
      "y": 9,
      "z": -11,
      "name": "Plant_Coral_Block_Red"
    },
    {
      "x": -4,
      "y": 5,
      "z": -10,
      "name": "Plant_Coral_Block_Yellow"
    },
    {
      "x": -4,
      "y": 6,
      "z": -10,
      "name": "Plant_Coral_Block_Yellow"
    },
    {
      "x": -4,
      "y": 7,
      "z": -10,
      "name": "Plant_Coral_Block_Yellow"
    },
    {
      "x": -4,
      "y": 8,
      "z": -10,
      "name": "Plant_Coral_Block_Yellow"
    },
    {
      "x": -4,
      "y": 9,
      "z": -10,
      "name": "Plant_Coral_Block_Red"
    },
    {
      "x": -4,
      "y": 10,
      "z": -10,
      "name": "Plant_Coral_Block_Red"
    },
    {
      "x": -4,
      "y": 4,
      "z": -9,
      "name": "Plant_Coral_Block_Yellow"
    },
    {
      "x": -4,
      "y": 5,
      "z": -9,
      "name": "Plant_Coral_Block_Yellow"
    },
    {
      "x": -4,
      "y": 6,
      "z": -9,
      "name": "Plant_Coral_Block_Yellow"
    },
    {
      "x": -4,
      "y": 7,
      "z": -9,
      "name": "Plant_Coral_Block_Yellow"
    },
    {
      "x": -4,
      "y": 8,
      "z": -9,
      "name": "Plant_Coral_Block_Yellow"
    },
    {
      "x": -4,
      "y": 9,
      "z": -9,
      "name": "Plant_Coral_Block_Yellow"
    },
    {
      "x": -4,
      "y": 10,
      "z": -9,
      "name": "Plant_Coral_Block_Red"
    },
    {
      "x": -4,
      "y": 11,
      "z": -9,
      "name": "Plant_Coral_Block_Red"
    },
    {
      "x": -4,
      "y": 4,
      "z": -8,
      "name": "Plant_Coral_Block_Yellow"
    },
    {
      "x": -4,
      "y": 5,
      "z": -8,
      "name": "Plant_Coral_Block_Yellow"
    },
    {
      "x": -4,
      "y": 6,
      "z": -8,
      "name": "Plant_Coral_Block_Yellow"
    },
    {
      "x": -4,
      "y": 7,
      "z": -8,
      "name": "Plant_Coral_Block_Yellow"
    },
    {
      "x": -4,
      "y": 8,
      "z": -8,
      "name": "Plant_Coral_Block_Yellow"
    },
    {
      "x": -4,
      "y": 9,
      "z": -8,
      "name": "Plant_Coral_Block_Yellow"
    },
    {
      "x": -4,
      "y": 10,
      "z": -8,
      "name": "Plant_Coral_Block_Yellow"
    },
    {
      "x": -4,
      "y": 12,
      "z": -8,
      "name": "Plant_Coral_Bush_Orange"
    },
    {
      "x": -4,
      "y": 3,
      "z": -7,
      "name": "Plant_Coral_Block_Yellow"
    },
    {
      "x": -4,
      "y": 4,
      "z": -7,
      "name": "Plant_Coral_Block_Yellow"
    },
    {
      "x": -4,
      "y": 5,
      "z": -7,
      "name": "Plant_Coral_Block_Yellow"
    },
    {
      "x": -4,
      "y": 6,
      "z": -7,
      "name": "Plant_Coral_Block_Yellow"
    },
    {
      "x": -4,
      "y": 7,
      "z": -7,
      "name": "Plant_Coral_Block_Yellow"
    },
    {
      "x": -4,
      "y": 8,
      "z": -7,
      "name": "Plant_Coral_Block_Yellow"
    },
    {
      "x": -4,
      "y": 9,
      "z": -7,
      "name": "Plant_Coral_Block_Yellow"
    },
    {
      "x": -4,
      "y": 10,
      "z": -7,
      "name": "Plant_Coral_Block_Yellow"
    },
    {
      "x": -4,
      "y": 11,
      "z": -7,
      "name": "Plant_Coral_Block_Red"
    },
    {
      "x": -4,
      "y": 12,
      "z": -7,
      "name": "Plant_Coral_Block_Red"
    },
    {
      "x": -4,
      "y": 3,
      "z": -6,
      "name": "Plant_Coral_Block_Yellow"
    },
    {
      "x": -4,
      "y": 4,
      "z": -6,
      "name": "Plant_Coral_Block_Yellow"
    },
    {
      "x": -4,
      "y": 5,
      "z": -6,
      "name": "Plant_Coral_Block_Yellow"
    },
    {
      "x": -4,
      "y": 6,
      "z": -6,
      "name": "Plant_Coral_Block_Yellow"
    },
    {
      "x": -4,
      "y": 7,
      "z": -6,
      "name": "Plant_Coral_Block_Yellow"
    },
    {
      "x": -4,
      "y": 8,
      "z": -6,
      "name": "Plant_Coral_Block_Yellow"
    },
    {
      "x": -4,
      "y": 9,
      "z": -6,
      "name": "Plant_Coral_Block_Yellow"
    },
    {
      "x": -4,
      "y": 10,
      "z": -6,
      "name": "Plant_Coral_Block_Yellow"
    },
    {
      "x": -4,
      "y": 11,
      "z": -6,
      "name": "Plant_Coral_Block_Yellow"
    },
    {
      "x": -4,
      "y": 3,
      "z": -5,
      "name": "Plant_Coral_Block_Yellow"
    },
    {
      "x": -4,
      "y": 4,
      "z": -5,
      "name": "Plant_Coral_Block_Yellow"
    },
    {
      "x": -4,
      "y": 5,
      "z": -5,
      "name": "Plant_Coral_Block_Yellow"
    },
    {
      "x": -4,
      "y": 6,
      "z": -5,
      "name": "Plant_Coral_Block_Yellow"
    },
    {
      "x": -4,
      "y": 7,
      "z": -5,
      "name": "Plant_Coral_Block_Yellow"
    },
    {
      "x": -4,
      "y": 8,
      "z": -5,
      "name": "Plant_Coral_Block_Yellow"
    },
    {
      "x": -4,
      "y": 9,
      "z": -5,
      "name": "Plant_Coral_Block_Yellow"
    },
    {
      "x": -4,
      "y": 10,
      "z": -5,
      "name": "Plant_Coral_Block_Yellow"
    },
    {
      "x": -4,
      "y": 11,
      "z": -5,
      "name": "Plant_Coral_Block_Red"
    },
    {
      "x": -4,
      "y": 12,
      "z": -5,
      "name": "Plant_Coral_Block_Red"
    },
    {
      "x": -4,
      "y": 3,
      "z": -4,
      "name": "Plant_Coral_Block_Yellow"
    },
    {
      "x": -4,
      "y": 4,
      "z": -4,
      "name": "Plant_Coral_Block_Yellow"
    },
    {
      "x": -4,
      "y": 5,
      "z": -4,
      "name": "Plant_Coral_Block_Yellow"
    },
    {
      "x": -4,
      "y": 6,
      "z": -4,
      "name": "Plant_Coral_Block_Yellow"
    },
    {
      "x": -4,
      "y": 7,
      "z": -4,
      "name": "Plant_Coral_Block_Yellow"
    },
    {
      "x": -4,
      "y": 8,
      "z": -4,
      "name": "Plant_Coral_Block_Yellow"
    },
    {
      "x": -4,
      "y": 9,
      "z": -4,
      "name": "Plant_Coral_Block_Yellow"
    },
    {
      "x": -4,
      "y": 10,
      "z": -4,
      "name": "Plant_Coral_Block_Yellow"
    },
    {
      "x": -4,
      "y": 11,
      "z": -4,
      "name": "Plant_Coral_Block_Yellow"
    },
    {
      "x": -4,
      "y": 3,
      "z": -3,
      "name": "Plant_Coral_Block_Yellow"
    },
    {
      "x": -4,
      "y": 4,
      "z": -3,
      "name": "Plant_Coral_Block_Yellow"
    },
    {
      "x": -4,
      "y": 5,
      "z": -3,
      "name": "Plant_Coral_Block_Yellow"
    },
    {
      "x": -4,
      "y": 6,
      "z": -3,
      "name": "Plant_Coral_Block_Yellow"
    },
    {
      "x": -4,
      "y": 7,
      "z": -3,
      "name": "Plant_Coral_Block_Yellow"
    },
    {
      "x": -4,
      "y": 8,
      "z": -3,
      "name": "Plant_Coral_Block_Yellow"
    },
    {
      "x": -4,
      "y": 9,
      "z": -3,
      "name": "Plant_Coral_Block_Yellow"
    },
    {
      "x": -4,
      "y": 10,
      "z": -3,
      "name": "Plant_Coral_Block_Yellow"
    },
    {
      "x": -4,
      "y": 11,
      "z": -3,
      "name": "Plant_Coral_Block_Red"
    },
    {
      "x": -4,
      "y": 12,
      "z": -3,
      "name": "Plant_Coral_Block_Red"
    },
    {
      "x": -4,
      "y": 2,
      "z": -2,
      "name": "Plant_Coral_Block_Yellow"
    },
    {
      "x": -4,
      "y": 3,
      "z": -2,
      "name": "Plant_Coral_Block_Yellow"
    },
    {
      "x": -4,
      "y": 4,
      "z": -2,
      "name": "Plant_Coral_Block_Yellow"
    },
    {
      "x": -4,
      "y": 5,
      "z": -2,
      "name": "Plant_Coral_Block_Yellow"
    },
    {
      "x": -4,
      "y": 6,
      "z": -2,
      "name": "Plant_Coral_Block_Yellow"
    },
    {
      "x": -4,
      "y": 7,
      "z": -2,
      "name": "Plant_Coral_Block_Yellow"
    },
    {
      "x": -4,
      "y": 8,
      "z": -2,
      "name": "Plant_Coral_Block_Yellow"
    },
    {
      "x": -4,
      "y": 9,
      "z": -2,
      "name": "Plant_Coral_Block_Yellow"
    },
    {
      "x": -4,
      "y": 10,
      "z": -2,
      "name": "Plant_Coral_Block_Yellow"
    },
    {
      "x": -4,
      "y": 11,
      "z": -2,
      "name": "Plant_Coral_Block_Yellow"
    },
    {
      "x": -4,
      "y": 12,
      "z": -2,
      "name": "Plant_Coral_Block_Red"
    },
    {
      "x": -4,
      "y": 13,
      "z": -2,
