{
  "version": 8,
  "blockIdVersion": 8,
  "anchorX": 12,
  "anchorY": 16,
  "anchorZ": 11,
  "blocks": [
    {
      "x": 0,
      "y": 21,
      "z": 22,
      "name": "Deco_Bone_Full"
    },
    {
      "x": 0,
      "y": 21,
      "z": 23,
      "name": "Deco_Bone_Full"
    },
    {
      "x": 1,
      "y": 22,
      "z": 14,
      "name": "Deco_Bone_Full"
    },
    {
      "x": 1,
      "y": 23,
      "z": 14,
      "name": "Deco_Bone_Full"
    },
    {
      "x": 1,
      "y": 24,
      "z": 14,
      "name": "Deco_Bone_Full"
    },
    {
      "x": 1,
      "y": 25,
      "z": 14,
      "name": "Deco_Bone_Full"
    },
    {
      "x": 1,
      "y": 26,
      "z": 14,
      "name": "Deco_Bone_Full"
    },
    {
      "x": 1,
      "y": 20,
      "z": 15,
      "name": "Deco_Bone_Full"
    },
    {
      "x": 1,
      "y": 21,
      "z": 15,
      "name": "Deco_Bone_Full"
    },
    {
      "x": 1,
      "y": 22,
      "z": 15,
      "name": "Deco_Bone_Full"
    },
    {
      "x": 1,
      "y": 19,
      "z": 16,
      "name": "Deco_Bone_Full"
    },
    {
      "x": 1,
      "y": 20,
      "z": 16,
      "name": "Deco_Bone_Full"
    },
    {
      "x": 1,
      "y": 18,
      "z": 17,
      "name": "Deco_Bone_Full"
    },
    {
      "x": 1,
      "y": 19,
      "z": 17,
      "name": "Deco_Bone_Full"
    },
    {
      "x": 1,
      "y": 20,
      "z": 21,
      "name": "Deco_Bone_Full"
    },
    {
      "x": 1,
      "y": 20,
      "z": 22,
      "name": "Deco_Bone_Full"
    },
    {
      "x": 1,
      "y": 21,
      "z": 22,
      "name": "Deco_Bone_Full"
    },
    {
      "x": 1,
      "y": 21,
      "z": 23,
      "name": "Deco_Bone_Full"
    },
    {
      "x": 2,
      "y": 26,
      "z": 15,
      "name": "Deco_Bone_Full"
    },
    {
      "x": 2,
      "y": 27,
      "z": 15,
      "name": "Deco_Bone_Full"
    },
    {
      "x": 2,
      "y": 28,
      "z": 15,
      "name": "Deco_Bone_Full"
    },
    {
      "x": 2,
      "y": 18,
      "z": 16,
      "name": "Deco_Bone_Full"
    },
    {
      "x": 2,
      "y": 19,
      "z": 16,
      "name": "Deco_Bone_Full"
    },
    {
      "x": 2,
      "y": 18,
      "z": 17,
      "name": "Deco_Bone_Full"
    },
    {
      "x": 2,
      "y": 19,
      "z": 17,
      "name": "Deco_Bone_Full"
    },
    {
      "x": 2,
      "y": 18,
      "z": 18,
      "name": "Deco_Bone_Full"
    },
    {
      "x": 2,
      "y": 20,
      "z": 20,
      "name": "Deco_Bone_Full"
    },
    {
      "x": 2,
      "y": 20,
      "z": 21,
      "name": "Deco_Bone_Full"
    },
    {
      "x": 2,
      "y": 20,
      "z": 22,
      "name": "Deco_Bone_Full"
    },
    {
      "x": 3,
      "y": 28,
      "z": 16,
      "name": "Deco_Bone_Full"
    },
    {
      "x": 3,
      "y": 29,
      "z": 16,
      "name": "Deco_Bone_Full"
    },
    {
      "x": 3,
      "y": 18,
      "z": 17,
      "name": "Deco_Bone_Full"
    },
    {
      "x": 3,
      "y": 19,
      "z": 17,
      "name": "Deco_Bone_Full"
    },
    {
      "x": 3,
      "y": 17,
      "z": 18,
      "name": "Deco_Bone_Full"
    },
    {
      "x": 3,
      "y": 18,
      "z": 18,
      "name": "Deco_Bone_Full"
    },
    {
      "x": 3,
      "y": 19,
      "z": 18,
      "name": "Deco_Bone_Full"
    },
    {
      "x": 3,
      "y": 18,
      "z": 19,
      "name": "Deco_Bone_Full"
    },
    {
      "x": 3,
      "y": 19,
      "z": 19,
      "name": "Deco_Bone_Full"
    },
    {
      "x": 3,
      "y": 19,
      "z": 20,
      "name": "Deco_Bone_Full"
    },
    {
      "x": 3,
      "y": 20,
      "z": 21,
      "name": "Deco_Bone_Full"
    },
    {
      "x": 4,
      "y": 19,
      "z": 9,
      "name": "Deco_Bone_Full"
    },
    {
      "x": 4,
      "y": 20,
      "z": 9,
      "name": "Deco_Bone_Full"
    },
    {
      "x": 4,
      "y": 21,
      "z": 9,
      "name": "Deco_Bone_Full"
    },
    {
      "x": 4,
      "y": 22,
      "z": 9,
      "name": "Deco_Bone_Full"
    },
    {
      "x": 4,
      "y": 18,
      "z": 16,
      "name": "Deco_Bone_Full"
    },
    {
      "x": 4,
      "y": 18,
      "z": 17,
      "name": "Deco_Bone_Full"
    },
    {
      "x": 4,
      "y": 17,
      "z": 18,
      "name": "Deco_Bone_Full"
    },
    {
      "x": 4,
      "y": 18,
      "z": 18,
      "name": "Deco_Bone_Full"
    },
    {
      "x": 4,
      "y": 19,
      "z": 18,
      "name": "Deco_Bone_Full"
    },
    {
      "x": 4,
      "y": 16,
      "z": 19,
      "name": "Deco_Bone_Full"
    },
    {
      "x": 4,
      "y": 17,
      "z": 19,
      "name": "Deco_Bone_Full"
    },
    {
      "x": 4,
      "y": 18,
      "z": 19,
      "name": "Deco_Bone_Full"
    },
    {
      "x": 4,
      "y": 19,
      "z": 19,
      "name": "Deco_Bone_Full"
    },
    {
      "x": 4,
      "y": 18,
      "z": 20,
      "name": "Deco_Bone_Full"
    },
    {
      "x": 4,
      "y": 19,
      "z": 20,
      "name": "Deco_Bone_Full"
    },
    {
      "x": 5,
      "y": 22,
      "z": 8,
      "name": "Deco_Bone_Full"
    },
    {
      "x": 5,
      "y": 23,
      "z": 8,
      "name": "Deco_Bone_Full"
    },
    {
      "x": 5,
      "y": 24,
      "z": 8,
      "name": "Deco_Bone_Full"
    },
    {
      "x": 5,
      "y": 25,
      "z": 8,
      "name": "Deco_Bone_Full"
    },
    {
      "x": 5,
      "y": 26,
      "z": 8,
      "name": "Deco_Bone_Full"
    },
    {
      "x": 5,
      "y": 17,
      "z": 10,
      "name": "Deco_Bone_Full"
    },
    {
      "x": 5,
      "y": 18,
      "z": 10,
      "name": "Deco_Bone_Full"
    },
    {
      "x": 5,
      "y": 19,
      "z": 10,
      "name": "Deco_Bone_Full"
    },
    {
      "x": 5,
      "y": 17,
      "z": 11,
      "name": "Deco_Bone_Full"
    },
    {
      "x": 5,
      "y": 17,
      "z": 17,
      "name": "Deco_Bone_Full"
    },
    {
      "x": 5,
      "y": 15,
      "z": 18,
      "name": "Deco_Bone_Full"
    },
    {
      "x": 5,
      "y": 16,
      "z": 18,
      "name": "Deco_Bone_Full"
    },
    {
      "x": 5,
      "y": 17,
      "z": 18,
      "name": "Deco_Bone_Full"
    },
    {
      "x": 5,
      "y": 18,
      "z": 18,
      "name": "Deco_Bone_Full"
    },
    {
      "x": 5,
      "y": 17,
      "z": 19,
      "name": "Deco_Bone_Full"
    },
    {
      "x": 5,
      "y": 18,
      "z": 19,
      "name": "Deco_Bone_Full"
    },
    {
      "x": 5,
      "y": 19,
      "z": 19,
      "name": "Deco_Bone_Full"
    },
    {
      "x": 5,
      "y": 17,
      "z": 20,
      "name": "Deco_Bone_Full"
    },
    {
      "x": 5,
      "y": 18,
      "z": 20,
      "name": "Deco_Bone_Full"
    },
    {
      "x": 5,
      "y": 19,
      "z": 20,
      "name": "Deco_Bone_Full"
    },
    {
      "x": 5,
      "y": 18,
      "z": 21,
      "name": "Deco_Bone_Full"
    },
    {
      "x": 6,
      "y": 26,
      "z": 8,
      "name": "Deco_Bone_Full"
    },
    {
      "x": 6,
      "y": 27,
      "z": 8,
      "name": "Deco_Bone_Full"
    },
    {
      "x": 6,
      "y": 28,
      "z": 8,
      "name": "Deco_Bone_Full"
    },
    {
      "x": 6,
      "y": 17,
      "z": 10,
      "name": "Deco_Bone_Full"
    },
    {
      "x": 6,
      "y": 16,
      "z": 11,
      "name": "Deco_Bone_Full"
    },
    {
      "x": 6,
      "y": 17,
      "z": 11,
      "name": "Deco_Bone_Full"
    },
    {
      "x": 6,
      "y": 16,
      "z": 12,
      "name": "Deco_Bone_Full"
    },
    {
      "x": 6,
      "y": 16,
      "z": 16,
      "name": "Deco_Bone_Full"
    },
    {
      "x": 6,
      "y": 16,
      "z": 17,
      "name": "Deco_Bone_Full"
    },
    {
      "x": 6,
      "y": 17,
      "z": 18,
      "name": "Deco_Bone_Full"
    },
    {
      "x": 6,
      "y": 18,
      "z": 19,
      "name": "Deco_Bone_Full"
    },
    {
      "x": 6,
      "y": 18,
      "z": 20,
      "name": "Deco_Bone_Full"
    },
    {
      "x": 6,
      "y": 19,
      "z": 20,
      "name": "Deco_Bone_Full"
    },
    {
      "x": 6,
      "y": 18,
      "z": 21,
      "name": "Deco_Bone_Full"
    },
    {
      "x": 6,
      "y": 19,
      "z": 21,
      "name": "Deco_Bone_Full"
    },
    {
      "x": 6,
      "y": 18,
      "z": 22,
      "name": "Deco_Bone_Full"
    },
    {
      "x": 6,
      "y": 19,
      "z": 22,
      "name": "Deco_Bone_Full"
    },
    {
      "x": 7,
      "y": 28,
      "z": 9,
      "name": "Deco_Bone_Full"
    },
    {
      "x": 7,
      "y": 29,
      "z": 9,
      "name": "Deco_Bone_Full"
    },
    {
      "x": 7,
      "y": 30,
      "z": 9,
      "name": "Deco_Bone_Full"
    },
    {
      "x": 7,
      "y": 16,
      "z": 11,
      "name": "Deco_Bone_Full"
    },
    {
      "x": 7,
      "y": 15,
      "z": 12,
      "name": "Deco_Bone_Full"
    },
    {
      "x": 7,
      "y": 16,
      "z": 12,
      "name": "Deco_Bone_Full"
    },
    {
      "x": 7,
      "y": 15,
      "z": 13,
      "name": "Deco_Bone_Full"
    },
    {
      "x": 7,
      "y": 16,
      "z": 13,
      "name": "Deco_Bone_Full"
    },
    {
      "x": 7,
      "y": 15,
      "z": 15,
      "name": "Deco_Bone_Full"
    },
    {
      "x": 7,
      "y": 15,
      "z": 16,
      "name": "Deco_Bone_Full"
    },
    {
      "x": 7,
      "y": 16,
      "z": 17,
      "name": "Deco_Bone_Full"
    },
    {
      "x": 7,
      "y": 18,
      "z": 19,
      "name": "Deco_Bone_Full"
    },
    {
      "x": 7,
      "y": 28,
      "z": 20,
      "name": "Deco_Bone_Full"
    },
    {
      "x": 7,
      "y": 29,
      "z": 20,
      "name": "Deco_Bone_Full"
    },
    {
      "x": 7,
      "y": 18,
      "z": 21,
      "name": "Deco_Bone_Full"
    },
    {
      "x": 7,
      "y": 19,
      "z": 21,
      "name": "Deco_Bone_Full"
    },
    {
      "x": 7,
      "y": 19,
      "z": 22,
      "name": "Deco_Bone_Full"
    },
    {
      "x": 7,
      "y": 20,
      "z": 22,
      "name": "Deco_Bone_Full"
    },
    {
      "x": 8,
      "y": 15,
      "z": 12,
      "name": "Deco_Bone_Full"
    },
    {
      "x": 8,
      "y": 15,
      "z": 13,
      "name": "Deco_Bone_Full"
    },
    {
      "x": 8,
      "y": 16,
      "z": 13,
      "name": "Deco_Bone_Full"
    },
    {
      "x": 8,
      "y": 14,
      "z": 14,
      "name": "Deco_Bone_Full"
    },
    {
      "x": 8,
      "y": 15,
      "z": 14,
      "name": "Deco_Bone_Full"
    },
    {
      "x": 8,
      "y": 16,
      "z": 14,
      "name": "Deco_Bone_Full"
    },
    {
      "x": 8,
      "y": 15,
      "z": 15,
      "name": "Deco_Bone_Full"
    },
    {
      "x": 8,
      "y": 16,
      "z": 15,
      "name": "Deco_Bone_Full"
    },
    {
      "x": 8,
      "y": 15,
      "z": 16,
      "name": "Deco_Bone_Full"
    },
    {
      "x": 8,
      "y": 26,
      "z": 21,
      "name": "Deco_Bone_Full"
    },
    {
      "x": 8,
      "y": 27,
      "z": 21,
      "name": "Deco_Bone_Full"
    },
    {
      "x": 8,
      "y": 28,
      "z": 21,
      "name": "Deco_Bone_Full"
    },
    {
      "x": 8,
      "y": 20,
      "z": 22,
      "name": "Deco_Bone_Full"
    },
    {
      "x": 8,
      "y": 21,
      "z": 22,
      "name": "Deco_Bone_Full"
    },
    {
      "x": 8,
      "y": 22,
      "z": 22,
      "name": "Deco_Bone_Full"
    },
    {
      "x": 9,
      "y": 19,
      "z": 3,
      "name": "Deco_Bone_Full"
    },
    {
      "x": 9,
      "y": 20,
      "z": 3,
      "name": "Deco_Bone_Full"
    },
    {
      "x": 9,
      "y": 21,
      "z": 3,
      "name": "Deco_Bone_Full"
    },
    {
      "x": 9,
      "y": 17,
      "z": 4,
      "name": "Deco_Bone_Full"
    },
    {
      "x": 9,
      "y": 18,
      "z": 4,
      "name": "Deco_Bone_Full"
    },
    {
      "x": 9,
      "y": 14,
      "z": 11,
      "name": "Deco_Bone_Full"
    },
    {
      "x": 9,
      "y": 14,
      "z": 12,
      "name": "Deco_Bone_Full"
    },
    {
      "x": 9,
      "y": 13,
      "z": 13,
      "name": "Deco_Bone_Full"
    },
    {
      "x": 9,
      "y": 14,
      "z": 13,
      "name": "Deco_Bone_Full"
    },
    {
      "x": 9,
      "y": 15,
      "z": 13,
      "name": "Deco_Bone_Full"
    },
    {
      "x": 9,
      "y": 12,
      "z": 14,
      "name": "Deco_Bone_Full"
    },
    {
      "x": 9,
      "y": 13,
      "z": 14,
      "name": "Deco_Bone_Full"
    },
    {
      "x": 9,
      "y": 14,
      "z": 14,
      "name": "Deco_Bone_Full"
    },
    {
      "x": 9,
      "y": 15,
      "z": 14,
      "name": "Deco_Bone_Full"
    },
    {
      "x": 9,
      "y": 16,
      "z": 14,
      "name": "Deco_Bone_Full"
    },
    {
      "x": 9,
      "y": 14,
      "z": 15,
      "name": "Deco_Bone_Full"
    },
    {
      "x": 9,
      "y": 15,
      "z": 15,
      "name": "Deco_Bone_Full"
    },
    {
      "x": 9,
      "y": 16,
      "z": 15,
      "name": "Deco_Bone_Full"
    },
    {
      "x": 9,
      "y": 22,
      "z": 22,
      "name": "Deco_Bone_Full"
    },
    {
      "x": 9,
      "y": 23,
      "z": 22,
      "name": "Deco_Bone_Full"
    },
    {
      "x": 9,
      "y": 24,
      "z": 22,
      "name": "Deco_Bone_Full"
    },
    {
      "x": 9,
      "y": 25,
      "z": 22,
      "name": "Deco_Bone_Full"
    },
    {
      "x": 9,
      "y": 26,
      "z": 22,
      "name": "Deco_Bone_Full"
    },
    {
      "x": 10,
      "y": 21,
      "z": 2,
      "name": "Deco_Bone_Full"
    },
    {
      "x": 10,
      "y": 22,
      "z": 2,
      "name": "Deco_Bone_Full"
    },
    {
      "x": 10,
      "y": 23,
      "z": 2,
      "name": "Deco_Bone_Full"
    },
    {
      "x": 10,
      "y": 24,
      "z": 2,
      "name": "Deco_Bone_Full"
    },
    {
      "x": 10,
      "y": 25,
      "z": 2,
      "name": "Deco_Bone_Full"
    },
    {
      "x": 10,
      "y": 15,
      "z": 5,
      "name": "Deco_Bone_Full"
    },
    {
      "x": 10,
      "y": 16,
      "z": 5,
      "name": "Deco_Bone_Full"
    },
    {
      "x": 10,
      "y": 17,
      "z": 5,
      "name": "Deco_Bone_Full"
    },
    {
      "x": 10,
      "y": 14,
      "z": 6,
      "name": "Deco_Bone_Full"
    },
    {
      "x": 10,
      "y": 15,
      "z": 6,
      "name": "Deco_Bone_Full"
    },
    {
      "x": 10,
      "y": 14,
      "z": 7,
      "name": "Deco_Bone_Full"
    },
    {
      "x": 10,
      "y": 13,
      "z": 12,
      "name": "Deco_Bone_Full"
    },
    {
      "x": 10,
      "y": 11,
      "z": 13,
      "name": "Deco_Bone_Full"
    },
    {
      "x": 10,
      "y": 12,
      "z": 13,
      "name": "Deco_Bone_Full"
    },
    {
      "x": 10,
      "y": 13,
      "z": 13,
      "name": "Deco_Bone_Full"
    },
    {
      "x": 10,
      "y": 14,
      "z": 13,
      "name": "Deco_Bone_Full"
    },
    {
      "x": 10,
      "y": 13,
      "z": 14,
      "name": "Deco_Bone_Full"
    },
    {
      "x": 10,
      "y": 14,
      "z": 14,
      "name": "Deco_Bone_Full"
    },
    {
      "x": 10,
      "y": 15,
      "z": 14,
      "name": "Deco_Bone_Full"
    },
    {
      "x": 10,
      "y": 15,
      "z": 15,
      "name": "Deco_Bone_Full"
    },
    {
      "x": 10,
      "y": 16,
      "z": 15,
      "name": "Deco_Bone_Full"
    },
    {
      "x": 10,
      "y": 15,
      "z": 16,
      "name": "Deco_Bone_Full"
    },
    {
      "x": 10,
      "y": 16,
      "z": 16,
      "name": "Deco_Bone_Full"
    },
    {
      "x": 11,
      "y": 25,
      "z": 3,
      "name": "Deco_Bone_Full"
    },
    {
      "x": 11,
      "y": 26,
      "z": 3,
      "name": "Deco_Bone_Full"
    },
    {
      "x": 11,
      "y": 27,
      "z": 3,
      "name": "Deco_Bone_Full"
    },
    {
      "x": 11,
      "y": 14,
      "z": 6,
      "name": "Deco_Bone_Full"
    },
    {
      "x": 11,
      "y": 13,
      "z": 7,
      "name": "Deco_Bone_Full"
    },
    {
      "x": 11,
      "y": 14,
      "z": 7,
      "name": "Deco_Bone_Full"
    },
    {
      "x": 11,
      "y": 14,
      "z": 8,
      "name": "Deco_Bone_Full"
    },
    {
      "x": 11,
      "y": 13,
      "z": 11,
      "name": "Deco_Bone_Full"
    },
    {
      "x": 11,
      "y": 13,
      "z": 12,
      "name": "Deco_Bone_Full"
    },
    {
      "x": 11,
      "y": 13,
      "z": 13,
      "name": "Deco_Bone_Full"
    },
    {
      "x": 11,
      "y": 14,
      "z": 14,
      "name": "Deco_Bone_Full"
    },
    {
      "x": 11,
      "y": 15,
      "z": 15,
      "name": "Deco_Bone_Full"
    },
    {
      "x": 11,
      "y": 16,
      "z": 15,
      "name": "Deco_Bone_Full"
    },
    {
      "x": 11,
      "y": 15,
      "z": 16,
      "name": "Deco_Bone_Full"
    },
    {
      "x": 11,
      "y": 16,
      "z": 16,
      "name": "Deco_Bone_Full"
    },
    {
      "x": 11,
      "y": 16,
      "z": 17,
      "name": "Deco_Bone_Full"
    },
    {
      "x": 12,
      "y": 27,
      "z": 4,
      "name": "Deco_Bone_Full"
    },
    {
      "x": 12,
      "y": 28,
      "z": 4,
      "name": "Deco_Bone_Full"
    },
    {
      "x": 12,
      "y": 14,
      "z": 7,
      "name": "Deco_Bone_Full"
    },
    {
      "x": 12,
      "y": 13,
      "z": 8,
      "name": "Deco_Bone_Full"
    },
    {
      "x": 12,
      "y": 14,
      "z": 8,
      "name": "Deco_Bone_Full"
    },
    {
      "x": 12,
      "y": 13,
      "z": 9,
      "name": "Deco_Bone_Full"
    },
    {
      "x": 12,
      "y": 12,
      "z": 10,
      "name": "Deco_Bone_Full"
    },
    {
      "x": 12,
      "y": 13,
      "z": 10,
      "name": "Deco_Bone_Full"
    },
    {
      "x": 12,
      "y": 14,
      "z": 10,
      "name": "Deco_Bone_Full"
    },
    {
      "x": 12,
      "y": 12,
      "z": 11,
      "name": "Deco_Bone_Full"
    },
    {
      "x": 12,
      "y": 13,
      "z": 11,
      "name": "Deco_Bone_Full"
    },
    {
      "x": 12,
      "y": 13,
      "z": 12,
      "name": "Deco_Bone_Full"
    },
    {
      "x": 12,
      "y": 14,
      "z": 14,
      "name": "Deco_Bone_Full"
    },
    {
      "x": 12,
      "y": 16,
      "z": 16,
      "name": "Deco_Bone_Full"
    },
    {
      "x": 12,
      "y": 16,
      "z": 17,
      "name": "Deco_Bone_Full"
    },
    {
      "x": 12,
      "y": 17,
      "z": 17,
      "name": "Deco_Bone_Full"
    },
    {
      "x": 12,
      "y": 17,
      "z": 18,
      "name": "Deco_Bone_Full"
    },
    {
      "x": 13,
      "y": 17,
      "z": 0,
      "name": "Deco_Bone_Full"
    },
    {
      "x": 13,
      "y": 18,
      "z": 0,
      "name": "Deco_Bone_Full"
    },
    {
      "x": 13,
      "y": 19,
      "z": 0,
      "name": "Deco_Bone_Full"
    },
    {
      "x": 13,
      "y": 20,
      "z": 0,
      "name": "Deco_Bone_Full"
    },
    {
      "x": 13,
      "y": 21,
      "z": 0,
      "name": "Deco_Bone_Full"
    },
    {
      "x": 13,
      "y": 22,
      "z": 0,
      "name": "Deco_Bone_Full"
    },
    {
      "x": 13,
      "y": 23,
      "z": 0,
      "name": "Deco_Bone_Full"
    },
    {
      "x": 13,
      "y": 24,
      "z": 0,
      "name": "Deco_Bone_Full"
    },
    {
      "x": 13,
      "y": 13,
      "z": 7,
      "name": "Deco_Bone_Full"
    },
    {
      "x": 13,
      "y": 13,
      "z": 8,
      "name": "Deco_Bone_Full"
    },
    {
      "x": 13,
      "y": 12,
      "z": 9,
      "name": "Deco_Bone_Full"
    },
    {
      "x": 13,
      "y": 13,
      "z": 9,
      "name": "Deco_Bone_Full"
    },
    {
      "x": 13,
      "y": 14,
      "z": 9,
      "name": "Deco_Bone_Full"
    },
    {
      "x": 13,
      "y": 11,
      "z": 10,
      "name": "Deco_Bone_Full"
    },
    {
      "x": 13,
      "y": 12,
      "z": 10,
      "name": "Deco_Bone_Full"
    },
    {
      "x": 13,
      "y": 13,
      "z": 10,
      "name": "Deco_Bone_Full"
    },
    {
      "x": 13,
      "y": 14,
      "z": 10,
      "name": "Deco_Bone_Full"
    },
    {
      "x": 13,
      "y": 12,
      "z": 11,
      "name": "Deco_Bone_Full"
    },
    {
      "x": 13,
      "y": 13,
      "z": 11,
      "name": "Deco_Bone_Full"
    },
    {
      "x": 13,
      "y": 14,
      "z": 11,
      "name": "Deco_Bone_Full"
    },
    {
      "x": 13,
      "y": 17,
      "z": 17,
      "name": "Deco_Bone_Full"
    },
    {
      "x": 13,
      "y": 17,
      "z": 18,
      "name": "Deco_Bone_Full"
    },
    {
      "x": 13,
      "y": 18,
      "z": 18,
      "name": "Deco_Bone_Full"
    },
    {
      "x": 13,
      "y": 19,
      "z": 18,
      "name": "Deco_Bone_Full"
    },
    {
      "x": 14,
      "y": 15,
      "z": 1,
      "name": "Deco_Bone_Full"
    },
    {
      "x": 14,
      "y": 16,
      "z": 1,
      "name": "Deco_Bone_Full"
    },
    {
      "x": 14,
      "y": 17,
      "z": 1,
      "name": "Deco_Bone_Full"
    },
    {
      "x": 14,
      "y": 24,
      "z": 1,
      "name": "Deco_Bone_Full"
    },
    {
      "x": 14,
      "y": 25,
      "z": 1,
      "name": "Deco_Bone_Full"
    },
    {
      "x": 14,
      "y": 26,
      "z": 1,
      "name": "Deco_Bone_Full"
    },
    {
      "x": 14,
      "y": 12,
      "z": 8,
      "name": "Deco_Bone_Full"
    },
    {
      "x": 14,
      "y": 10,
      "z": 9,
      "name": "Deco_Bone_Full"
    },
    {
      "x": 14,
      "y": 11,
      "z": 9,
      "name": "Deco_Bone_Full"
    },
    {
      "x": 14,
      "y": 12,
      "z": 9,
      "name": "Deco_Bone_Full"
    },
    {
      "x": 14,
      "y": 13,
      "z": 9,
      "name": "Deco_Bone_Full"
    },
    {
      "x": 14,
      "y": 14,
      "z": 9,
      "name": "Deco_Bone_Full"
    },
    {
      "x": 14,
      "y": 12,
      "z": 10,
      "name": "Deco_Bone_Full"
    },
    {
      "x": 14,
      "y": 13,
      "z": 10,
      "name": "Deco_Bone_Full"
    },
    {
      "x": 14,
      "y": 14,
      "z": 10,
      "name": "Deco_Bone_Full"
    },
    {
      "x": 14,
      "y": 13,
      "z": 11,
      "name": "Deco_Bone_Full"
    },
    {
      "x": 14,
      "y": 28,
      "z": 16,
      "name": "Deco_Bone_Full"
    },
    {
      "x": 14,
      "y": 29,
      "z": 16,
      "name": "Deco_Bone_Full"
    },
    {
      "x": 14,
      "y": 30,
      "z": 16,
      "name": "Deco_Bone_Full"
    },
    {
      "x": 14,
      "y": 19,
      "z": 19,
      "name": "Deco_Bone_Full"
    },
    {
      "x": 14,
      "y": 20,
      "z": 19,
      "name": "Deco_Bone_Full"
    },
    {
      "x": 14,
      "y": 21,
      "z": 19,
      "name": "Deco_Bone_Full"
    },
    {
      "x": 14,
      "y": 22,
      "z": 19,
      "name": "Deco_Bone_Full"
    },
    {
      "x": 15,
      "y": 13,
      "z": 2,
      "name": "Deco_Bone_Full"
    },
    {
      "x": 15,
      "y": 14,
      "z": 2,
      "name": "Deco_Bone_Full"
    },
    {
      "x": 15,
      "y": 15,
      "z": 2,
      "name": "Deco_Bone_Full"
    },
    {
      "x": 15,
      "y": 26,
      "z": 2,
      "name": "Deco_Bone_Full"
    },
    {
      "x": 15,
      "y": 27,
      "z": 2,
      "name": "Deco_Bone_Full"
    },
    {
      "x": 15,
      "y": 13,
      "z": 3,
      "name": "Deco_Bone_Full"
    },
    {
      "x": 15,
      "y": 12,
      "z": 7,
      "name": "Deco_Bone_Full"
    },
    {
      "x": 15,
      "y": 12,
      "z": 8,
      "name": "Deco_Bone_Full"
    },
    {
      "x": 15,
      "y": 12,
      "z": 9,
      "name": "Deco_Bone_Full"
    },
    {
      "x": 15,
      "y": 13,
      "z": 10,
      "name": "Deco_Bone_Full"
    },
    {
      "x": 15,
      "y": 13,
      "z": 11,
      "name": "Deco_Bone_Full"
    },
    {
      "x": 15,
      "y": 14,
      "z": 11,
      "name": "Deco_Bone_Full"
    },
    {
      "x": 15,
      "y": 14,
      "z": 12,
      "name": "Deco_Bone_Full"
    },
    {
      "x": 15,
      "y": 26,
      "z": 17,
      "name": "Deco_Bone_Full"
    },
    {
      "x": 15,
      "y": 27,
      "z": 17,
      "name": "Deco_Bone_Full"
    },
    {
      "x": 15,
      "y": 28,
      "z": 17,
      "name": "Deco_Bone_Full"
    },
    {
      "x": 15,
      "y": 22,
      "z": 18,
      "name": "Deco_Bone_Full"
    },
    {
      "x": 15,
      "y": 23,
      "z": 18,
      "name": "Deco_Bone_Full"
    },
    {
      "x": 15,
      "y": 24,
      "z": 18,
      "name": "Deco_Bone_Full"
    },
    {
      "x": 15,
      "y": 25,
      "z": 18,
      "name": "Deco_Bone_Full"
    },
    {
      "x": 15,
      "y": 26,
      "z": 18,
      "name": "Deco_Bone_Full"
    },
    {
      "x": 16,
      "y": 13,
      "z": 2,
      "name": "Deco_Bone_Full"
    },
    {
      "x": 16,
      "y": 12,
      "z": 3,
      "name": "Deco_Bone_Full"
    },
    {
      "x": 16,
      "y": 13,
      "z": 3,
      "name": "Deco_Bone_Full"
    },
    {
      "x": 16,
      "y": 14,
      "z": 3,
      "name": "Deco_Bone_Full"
    },
    {
      "x": 16,
      "y": 12,
      "z": 4,
      "name": "Deco_Bone_Full"
    },
    {
      "x": 16,
      "y": 13,
      "z": 4,
      "name": "Deco_Bone_Full"
    },
    {
      "x": 16,
      "y": 12,
      "z": 5,
      "name": "Deco_Bone_Full"
    },
    {
      "x": 16,
      "y": 11,
      "z": 6,
      "name": "Deco_Bone_Full"
    },
    {
      "x": 16,
      "y": 12,
      "z": 6,
      "name": "Deco_Bone_Full"
    },
    {
      "x": 16,
      "y": 12,
      "z": 7,
      "name": "Deco_Bone_Full"
    },
    {
      "x": 16,
      "y": 12,
      "z": 8,
      "name": "Deco_Bone_Full"
    },
    {
      "x": 16,
      "y": 13,
      "z": 10,
      "name": "Deco_Bone_Full"
    },
    {
      "x": 16,
      "y": 14,
      "z": 11,
      "name": "Deco_Bone_Full"
    },
    {
      "x": 16,
      "y": 13,
      "z": 12,
      "name": "Deco_Bone_Full"
    },
    {
      "x": 16,
      "y": 14,
      "z": 12,
      "name": "Deco_Bone_Full"
    },
    {
      "x": 16,
      "y": 14,
      "z": 13,
      "name": "Deco_Bone_Full"
    },
    {
      "x": 17,
      "y": 12,
      "z": 3,
      "name": "Deco_Bone_Full"
    },
    {
      "x": 17,
      "y": 13,
      "z": 3,
      "name": "Deco_Bone_Full"
    },
    {
      "x": 17,
      "y": 12,
      "z": 4,
      "name": "Deco_Bone_Full"
    },
    {
      "x": 17,
      "y": 13,
      "z": 4,
      "name": "Deco_Bone_Full"
    },
    {
      "x": 17,
      "y": 11,
      "z": 5,
      "name": "Deco_Bone_Full"
    },
    {
      "x": 17,
      "y": 12,
      "z": 5,
      "name": "Deco_Bone_Full"
    },
    {
      "x": 17,
      "y": 13,
      "z": 5,
      "name": "Deco_Bone_Full"
    },
    {
      "x": 17,
      "y": 10,
      "z": 6,
      "name": "Deco_Bone_Full"
    },
    {
      "x": 17,
      "y": 11,
      "z": 6,
      "name": "Deco_Bone_Full"
    },
    {
      "x": 17,
      "y": 12,
      "z": 6,
      "name": "Deco_Bone_Full"
    },
    {
      "x": 17,
      "y": 13,
      "z": 6,
      "name": "Deco_Bone_Full"
    },
    {
      "x": 17,
      "y": 11,
      "z": 7,
      "name": "Deco_Bone_Full"
    },
    {
      "x": 17,
      "y": 12,
      "z": 7,
      "name": "Deco_Bone_Full"
    },
    {
      "x": 17,
      "y": 14,
      "z": 12,
      "name": "Deco_Bone_Full"
    },
    {
      "x": 17,
      "y": 14,
      "z": 13,
      "name": "Deco_Bone_Full"
    },
    {
      "x": 17,
      "y": 15,
      "z": 13,
      "name": "Deco_Bone_Full"
    },
    {
      "x": 18,
      "y": 11,
      "z": 4,
      "name": "Deco_Bone_Full"
    },
    {
      "x": 18,
      "y": 12,
      "z": 4,
      "name": "Deco_Bone_Full"
    },
    {
      "x": 18,
      "y": 13,
      "z": 4,
      "name": "Deco_Bone_Full"
    },
    {
      "x": 18,
      "y": 9,
      "z": 5,
      "name": "Deco_Bone_Full"
    },
    {
      "x": 18,
      "y": 10,
      "z": 5,
      "name": "Deco_Bone_Full"
    },
    {
      "x": 18,
      "y": 11,
      "z": 5,
      "name": "Deco_Bone_Full"
    },
    {
      "x": 18,
      "y": 12,
      "z": 5,
      "name": "Deco_Bone_Full"
    },
    {
      "x": 18,
      "y": 13,
      "z": 5,
      "name": "Deco_Bone_Full"
    },
    {
      "x": 18,
      "y": 11,
      "z": 6,
      "name": "Deco_Bone_Full"
    },
    {
      "x": 18,
      "y": 12,
      "z": 6,
      "name": "Deco_Bone_Full"
    },
    {
      "x": 18,
      "y": 13,
      "z": 6,
      "name": "Deco_Bone_Full"
    },
    {
      "x": 18,
      "y": 12,
      "z": 7,
      "name": "Deco_Bone_Full"
    },
    {
      "x": 18,
      "y": 15,
      "z": 13,
      "name": "Deco_Bone_Full"
    },
    {
      "x": 18,
      "y": 16,
      "z": 13,
      "name": "Deco_Bone_Full"
    },
    {
      "x": 18,
      "y": 17,
      "z": 13,
      "name": "Deco_Bone_Full"
    },
    {
      "x": 19,
      "y": 12,
      "z": 3,
      "name": "Deco_Bone_Full"
    },
    {
      "x": 19,
      "y": 12,
      "z": 4,
      "name": "Deco_Bone_Full"
    },
    {
      "x": 19,
      "y": 11,
      "z": 5,
      "name": "Deco_Bone_Full"
    },
    {
      "x": 19,
      "y": 12,
      "z": 5,
      "name": "Deco_Bone_Full"
    },
    {
      "x": 19,
      "y": 13,
      "z": 5,
      "name": "Deco_Bone_Full"
    },
    {
      "x": 19,
      "y": 12,
      "z": 6,
      "name": "Deco_Bone_Full"
    },
    {
      "x": 19,
      "y": 13,
      "z": 6,
      "name": "Deco_Bone_Full"
    },
    {
      "x": 19,
      "y": 12,
      "z": 7,
      "name": "Deco_Bone_Full"
    },
    {
      "x": 19,
      "y": 13,
      "z": 7,
      "name": "Deco_Bone_Full"
    },
    {
      "x": 19,
      "y": 27,
      "z": 11,
      "name": "Deco_Bone_Full"
    },
    {
      "x": 19,
      "y": 28,
      "z": 11,
      "name": "Deco_Bone_Full"
    },
    {
      "x": 19,
      "y": 17,
      "z": 14,
      "name": "Deco_Bone_Full"
    },
    {
      "x": 19,
      "y": 18,
      "z": 14,
      "name": "Deco_Bone_Full"
    },
    {
      "x": 20,
      "y": 12,
      "z": 4,
      "name": "Deco_Bone_Full"
    },
    {
      "x": 20,
      "y": 12,
      "z": 6,
      "name": "Deco_Bone_Full"
    },
    {
      "x": 20,
      "y": 13,
      "z": 6,
      "name": "Deco_Bone_Full"
    },
    {
      "x": 20,
      "y": 12,
      "z": 7,
      "name": "Deco_Bone_Full"
    },
    {
      "x": 20,
      "y": 13,
      "z": 7,
      "name": "Deco_Bone_Full"
    },
    {
      "x": 20,
      "y": 14,
      "z": 7,
      "name": "Deco_Bone_Full"
    },
    {
      "x": 20,
      "y": 13,
      "z": 8,
      "name": "Deco_Bone_Full"
    },
    {
      "x": 20,
      "y": 25,
      "z": 12,
      "name": "Deco_Bone_Full"
    },
    {
      "x": 20,
      "y": 26,
      "z": 12,
      "name": "Deco_Bone_Full"
    },
    {
      "x": 20,
      "y": 27,
      "z": 12,
      "name": "Deco_Bone_Full"
    },
    {
      "x": 20,
      "y": 18,
      "z": 14,
      "name": "Deco_Bone_Full"
    },
    {
      "x": 20,
      "y": 19,
      "z": 14,
      "name": "Deco_Bone_Full"
    },
    {
      "x": 20,
      "y": 20,
      "z": 14,
      "name": "Deco_Bone_Full"
    },
    {
      "x": 20,
      "y": 21,
      "z": 14,
      "name": "Deco_Bone_Full"
    },
    {
      "x": 21,
      "y": 13,
      "z": 7,
      "name": "Deco_Bone_Full"
    },
    {
      "x": 21,
      "y": 13,
      "z": 8,
      "name": "Deco_Bone_Full"
    },
    {
      "x": 21,
      "y": 14,
      "z": 8,
      "name": "Deco_Bone_Full"
    },
    {
      "x": 21,
      "y": 15,
      "z": 8,
      "name": "Deco_Bone_Full"
    },
    {
      "x": 21,
      "y": 26,
      "z": 8,
      "name": "Deco_Bone_Full"
    },
    {
      "x": 21,
      "y": 27,
      "z": 8,
      "name": "Deco_Bone_Full"
    },
    {
      "x": 21,
      "y": 21,
      "z": 13,
      "name": "Deco_Bone_Full"
    },
    {
      "x": 21,
      "y": 22,
      "z": 13,
      "name": "Deco_Bone_Full"
    },
    {
      "x": 21,
      "y": 23,
      "z": 13,
      "name": "Deco_Bone_Full"
    },
    {
      "x": 21,
      "y": 24,
      "z": 13,
      "name": "Deco_Bone_Full"
    },
    {
      "x": 21,
      "y": 25,
      "z": 13,
      "name": "Deco_Bone_Full"
    },
    {
      "x": 22,
      "y": 15,
      "z": 9,
      "name": "Deco_Bone_Full"
    },
    {
      "x": 22,
      "y": 16,
      "z": 9,
      "name": "Deco_Bone_Full"
    },
    {
      "x": 22,
      "y": 17,
      "z": 9,
      "name": "Deco_Bone_Full"
    },
    {
      "x": 22,
      "y": 24,
      "z": 9,
      "name": "Deco_Bone_Full"
    },
    {
      "x": 22,
      "y": 25,
      "z": 9,
      "name": "Deco_Bone_Full"
    },
    {
      "x": 22,
      "y": 26,
      "z": 9,
      "name": "Deco_Bone_Full"
    },
    {
      "x": 23,
      "y": 17,
      "z": 10,
      "name": "Deco_Bone_Full"
    },
    {
      "x": 23,
      "y": 18,
      "z": 10,
      "name": "Deco_Bone_Full"
    },
    {
      "x": 23,
      "y": 19,
      "z": 10,
      "name": "Deco_Bone_Full"
    },
    {
      "x": 23,
      "y": 20,
      "z": 10,
      "name": "Deco_Bone_Full"
    },
    {
      "x": 23,
      "y": 21,
      "z": 10,
      "name": "Deco_Bone_Full"
    },
    {
      "x": 23,
      "y": 22,
      "z": 10,
      "name": "Deco_Bone_Full"
    },
    {
      "x": 23,
      "y": 23,
      "z": 10,
      "name": "Deco_Bone_Full"
    },
    {
      "x": 23,
      "y": 24,
      "z": 10,
      "name": "Deco_Bone_Full"
    }
  ]
}