{
  "version": 8,
  "blockIdVersion": 8,
  "anchorX": 12,
  "anchorY": 14,
  "anchorZ": 13,
  "blocks": [
    {
      "x": 0,
      "y": 13,
      "z": 17,
      "name": "Deco_Bone_Full"
    },
    {
      "x": 0,
      "y": 14,
      "z": 17,
      "name": "Deco_Bone_Full"
    },
    {
      "x": 0,
      "y": 15,
      "z": 17,
      "name": "Deco_Bone_Full"
    },
    {
      "x": 0,
      "y": 16,
      "z": 17,
      "name": "Deco_Bone_Full"
    },
    {
      "x": 0,
      "y": 17,
      "z": 17,
      "name": "Deco_Bone_Full"
    },
    {
      "x": 0,
      "y": 18,
      "z": 17,
      "name": "Deco_Bone_Full"
    },
    {
      "x": 0,
      "y": 13,
      "z": 18,
      "name": "Deco_Bone_Full"
    },
    {
      "x": 1,
      "y": 13,
      "z": 17,
      "name": "Deco_Bone_Full"
    },
    {
      "x": 1,
      "y": 11,
      "z": 18,
      "name": "Deco_Bone_Full"
    },
    {
      "x": 1,
      "y": 12,
      "z": 18,
      "name": "Deco_Bone_Full"
    },
    {
      "x": 1,
      "y": 13,
      "z": 18,
      "name": "Deco_Bone_Full"
    },
    {
      "x": 1,
      "y": 18,
      "z": 18,
      "name": "Deco_Bone_Full"
    },
    {
      "x": 1,
      "y": 19,
      "z": 18,
      "name": "Deco_Bone_Full"
    },
    {
      "x": 1,
      "y": 20,
      "z": 18,
      "name": "Deco_Bone_Full"
    },
    {
      "x": 1,
      "y": 21,
      "z": 18,
      "name": "Deco_Bone_Full"
    },
    {
      "x": 1,
      "y": 12,
      "z": 19,
      "name": "Deco_Bone_Full"
    },
    {
      "x": 1,
      "y": 10,
      "z": 23,
      "name": "Deco_Bone_Full"
    },
    {
      "x": 2,
      "y": 12,
      "z": 18,
      "name": "Deco_Bone_Full"
    },
    {
      "x": 2,
      "y": 10,
      "z": 19,
      "name": "Deco_Bone_Full"
    },
    {
      "x": 2,
      "y": 11,
      "z": 19,
      "name": "Deco_Bone_Full"
    },
    {
      "x": 2,
      "y": 12,
      "z": 19,
      "name": "Deco_Bone_Full"
    },
    {
      "x": 2,
      "y": 21,
      "z": 19,
      "name": "Deco_Bone_Full"
    },
    {
      "x": 2,
      "y": 22,
      "z": 19,
      "name": "Deco_Bone_Full"
    },
    {
      "x": 2,
      "y": 10,
      "z": 20,
      "name": "Deco_Bone_Full"
    },
    {
      "x": 2,
      "y": 11,
      "z": 20,
      "name": "Deco_Bone_Full"
    },
    {
      "x": 2,
      "y": 10,
      "z": 22,
      "name": "Deco_Bone_Full"
    },
    {
      "x": 2,
      "y": 10,
      "z": 23,
      "name": "Deco_Bone_Full"
    },
    {
      "x": 3,
      "y": 10,
      "z": 19,
      "name": "Deco_Bone_Full"
    },
    {
      "x": 3,
      "y": 11,
      "z": 19,
      "name": "Deco_Bone_Full"
    },
    {
      "x": 3,
      "y": 10,
      "z": 20,
      "name": "Deco_Bone_Full"
    },
    {
      "x": 3,
      "y": 11,
      "z": 20,
      "name": "Deco_Bone_Full"
    },
    {
      "x": 3,
      "y": 8,
      "z": 21,
      "name": "Deco_Bone_Full"
    },
    {
      "x": 3,
      "y": 9,
      "z": 21,
      "name": "Deco_Bone_Full"
    },
    {
      "x": 3,
      "y": 10,
      "z": 21,
      "name": "Deco_Bone_Full"
    },
    {
      "x": 3,
      "y": 11,
      "z": 21,
      "name": "Deco_Bone_Full"
    },
    {
      "x": 3,
      "y": 7,
      "z": 22,
      "name": "Deco_Bone_Full"
    },
    {
      "x": 3,
      "y": 8,
      "z": 22,
      "name": "Deco_Bone_Full"
    },
    {
      "x": 3,
      "y": 9,
      "z": 22,
      "name": "Deco_Bone_Full"
    },
    {
      "x": 3,
      "y": 10,
      "z": 22,
      "name": "Deco_Bone_Full"
    },
    {
      "x": 3,
      "y": 11,
      "z": 22,
      "name": "Deco_Bone_Full"
    },
    {
      "x": 3,
      "y": 10,
      "z": 23,
      "name": "Deco_Bone_Full"
    },
    {
      "x": 4,
      "y": 10,
      "z": 19,
      "name": "Deco_Bone_Full"
    },
    {
      "x": 4,
      "y": 9,
      "z": 20,
      "name": "Deco_Bone_Full"
    },
    {
      "x": 4,
      "y": 10,
      "z": 20,
      "name": "Deco_Bone_Full"
    },
    {
      "x": 4,
      "y": 11,
      "z": 20,
      "name": "Deco_Bone_Full"
    },
    {
      "x": 4,
      "y": 5,
      "z": 21,
      "name": "Deco_Bone_Full"
    },
    {
      "x": 4,
      "y": 6,
      "z": 21,
      "name": "Deco_Bone_Full"
    },
    {
      "x": 4,
      "y": 7,
      "z": 21,
      "name": "Deco_Bone_Full"
    },
    {
      "x": 4,
      "y": 8,
      "z": 21,
      "name": "Deco_Bone_Full"
    },
    {
      "x": 4,
      "y": 9,
      "z": 21,
      "name": "Deco_Bone_Full"
    },
    {
      "x": 4,
      "y": 10,
      "z": 21,
      "name": "Deco_Bone_Full"
    },
    {
      "x": 4,
      "y": 11,
      "z": 21,
      "name": "Deco_Bone_Full"
    },
    {
      "x": 4,
      "y": 12,
      "z": 21,
      "name": "Deco_Bone_Full"
    },
    {
      "x": 4,
      "y": 8,
      "z": 22,
      "name": "Deco_Bone_Full"
    },
    {
      "x": 4,
      "y": 9,
      "z": 22,
      "name": "Deco_Bone_Full"
    },
    {
      "x": 4,
      "y": 10,
      "z": 22,
      "name": "Deco_Bone_Full"
    },
    {
      "x": 4,
      "y": 11,
      "z": 22,
      "name": "Deco_Bone_Full"
    },
    {
      "x": 5,
      "y": 10,
      "z": 19,
      "name": "Deco_Bone_Full"
    },
    {
      "x": 5,
      "y": 4,
      "z": 20,
      "name": "Deco_Bone_Full"
    },
    {
      "x": 5,
      "y": 5,
      "z": 20,
      "name": "Deco_Bone_Full"
    },
    {
      "x": 5,
      "y": 6,
      "z": 20,
      "name": "Deco_Bone_Full"
    },
    {
      "x": 5,
      "y": 7,
      "z": 20,
      "name": "Deco_Bone_Full"
    },
    {
      "x": 5,
      "y": 8,
      "z": 20,
      "name": "Deco_Bone_Full"
    },
    {
      "x": 5,
      "y": 9,
      "z": 20,
      "name": "Deco_Bone_Full"
    },
    {
      "x": 5,
      "y": 10,
      "z": 20,
      "name": "Deco_Bone_Full"
    },
    {
      "x": 5,
      "y": 9,
      "z": 21,
      "name": "Deco_Bone_Full"
    },
    {
      "x": 5,
      "y": 10,
      "z": 21,
      "name": "Deco_Bone_Full"
    },
    {
      "x": 5,
      "y": 11,
      "z": 21,
      "name": "Deco_Bone_Full"
    },
    {
      "x": 5,
      "y": 10,
      "z": 22,
      "name": "Deco_Bone_Full"
    },
    {
      "x": 5,
      "y": 11,
      "z": 22,
      "name": "Deco_Bone_Full"
    },
    {
      "x": 5,
      "y": 10,
      "z": 23,
      "name": "Deco_Bone_Full"
    },
    {
      "x": 5,
      "y": 11,
      "z": 23,
      "name": "Deco_Bone_Full"
    },
    {
      "x": 6,
      "y": 13,
      "z": 13,
      "name": "Deco_Bone_Full"
    },
    {
      "x": 6,
      "y": 14,
      "z": 13,
      "name": "Deco_Bone_Full"
    },
    {
      "x": 6,
      "y": 15,
      "z": 13,
      "name": "Deco_Bone_Full"
    },
    {
      "x": 6,
      "y": 16,
      "z": 13,
      "name": "Deco_Bone_Full"
    },
    {
      "x": 6,
      "y": 17,
      "z": 13,
      "name": "Deco_Bone_Full"
    },
    {
      "x": 6,
      "y": 18,
      "z": 13,
      "name": "Deco_Bone_Full"
    },
    {
      "x": 6,
      "y": 19,
      "z": 13,
      "name": "Deco_Bone_Full"
    },
    {
      "x": 6,
      "y": 13,
      "z": 14,
      "name": "Deco_Bone_Full"
    },
    {
      "x": 6,
      "y": 10,
      "z": 18,
      "name": "Deco_Bone_Full"
    },
    {
      "x": 6,
      "y": 9,
      "z": 19,
      "name": "Deco_Bone_Full"
    },
    {
      "x": 6,
      "y": 10,
      "z": 19,
      "name": "Deco_Bone_Full"
    },
    {
      "x": 6,
      "y": 10,
      "z": 20,
      "name": "Deco_Bone_Full"
    },
    {
      "x": 6,
      "y": 10,
      "z": 21,
      "name": "Deco_Bone_Full"
    },
    {
      "x": 6,
      "y": 10,
      "z": 22,
      "name": "Deco_Bone_Full"
    },
    {
      "x": 6,
      "y": 11,
      "z": 22,
      "name": "Deco_Bone_Full"
    },
    {
      "x": 6,
      "y": 10,
      "z": 23,
      "name": "Deco_Bone_Full"
    },
    {
      "x": 6,
      "y": 11,
      "z": 23,
      "name": "Deco_Bone_Full"
    },
    {
      "x": 6,
      "y": 12,
      "z": 23,
      "name": "Deco_Bone_Full"
    },
    {
      "x": 6,
      "y": 21,
      "z": 23,
      "name": "Deco_Bone_Full"
    },
    {
      "x": 6,
      "y": 22,
      "z": 23,
      "name": "Deco_Bone_Full"
    },
    {
      "x": 6,
      "y": 12,
      "z": 24,
      "name": "Deco_Bone_Full"
    },
    {
      "x": 7,
      "y": 13,
      "z": 13,
      "name": "Deco_Bone_Full"
    },
    {
      "x": 7,
      "y": 12,
      "z": 14,
      "name": "Deco_Bone_Full"
    },
    {
      "x": 7,
      "y": 13,
      "z": 14,
      "name": "Deco_Bone_Full"
    },
    {
      "x": 7,
      "y": 19,
      "z": 14,
      "name": "Deco_Bone_Full"
    },
    {
      "x": 7,
      "y": 20,
      "z": 14,
      "name": "Deco_Bone_Full"
    },
    {
      "x": 7,
      "y": 11,
      "z": 15,
      "name": "Deco_Bone_Full"
    },
    {
      "x": 7,
      "y": 12,
      "z": 15,
      "name": "Deco_Bone_Full"
    },
    {
      "x": 7,
      "y": 11,
      "z": 17,
      "name": "Deco_Bone_Full"
    },
    {
      "x": 7,
      "y": 10,
      "z": 18,
      "name": "Deco_Bone_Full"
    },
    {
      "x": 7,
      "y": 11,
      "z": 18,
      "name": "Deco_Bone_Full"
    },
    {
      "x": 7,
      "y": 10,
      "z": 19,
      "name": "Deco_Bone_Full"
    },
    {
      "x": 7,
      "y": 12,
      "z": 23,
      "name": "Deco_Bone_Full"
    },
    {
      "x": 7,
      "y": 11,
      "z": 24,
      "name": "Deco_Bone_Full"
    },
    {
      "x": 7,
      "y": 12,
      "z": 24,
      "name": "Deco_Bone_Full"
    },
    {
      "x": 7,
      "y": 13,
      "z": 24,
      "name": "Deco_Bone_Full"
    },
    {
      "x": 7,
      "y": 18,
      "z": 24,
      "name": "Deco_Bone_Full"
    },
    {
      "x": 7,
      "y": 19,
      "z": 24,
      "name": "Deco_Bone_Full"
    },
    {
      "x": 7,
      "y": 20,
      "z": 24,
      "name": "Deco_Bone_Full"
    },
    {
      "x": 7,
      "y": 21,
      "z": 24,
      "name": "Deco_Bone_Full"
    },
    {
      "x": 7,
      "y": 13,
      "z": 25,
      "name": "Deco_Bone_Full"
    },
    {
      "x": 8,
      "y": 11,
      "z": 14,
      "name": "Deco_Bone_Full"
    },
    {
      "x": 8,
      "y": 12,
      "z": 14,
      "name": "Deco_Bone_Full"
    },
    {
      "x": 8,
      "y": 11,
      "z": 15,
      "name": "Deco_Bone_Full"
    },
    {
      "x": 8,
      "y": 12,
      "z": 15,
      "name": "Deco_Bone_Full"
    },
    {
      "x": 8,
      "y": 9,
      "z": 16,
      "name": "Deco_Bone_Full"
    },
    {
      "x": 8,
      "y": 10,
      "z": 16,
      "name": "Deco_Bone_Full"
    },
    {
      "x": 8,
      "y": 11,
      "z": 16,
      "name": "Deco_Bone_Full"
    },
    {
      "x": 8,
      "y": 12,
      "z": 16,
      "name": "Deco_Bone_Full"
    },
    {
      "x": 8,
      "y": 8,
      "z": 17,
      "name": "Deco_Bone_Full"
    },
    {
      "x": 8,
      "y": 9,
      "z": 17,
      "name": "Deco_Bone_Full"
    },
    {
      "x": 8,
      "y": 10,
      "z": 17,
      "name": "Deco_Bone_Full"
    },
    {
      "x": 8,
      "y": 11,
      "z": 17,
      "name": "Deco_Bone_Full"
    },
    {
      "x": 8,
      "y": 12,
      "z": 17,
      "name": "Deco_Bone_Full"
    },
    {
      "x": 8,
      "y": 11,
      "z": 18,
      "name": "Deco_Bone_Full"
    },
    {
      "x": 8,
      "y": 13,
      "z": 24,
      "name": "Deco_Bone_Full"
    },
    {
      "x": 8,
      "y": 13,
      "z": 25,
      "name": "Deco_Bone_Full"
    },
    {
      "x": 8,
      "y": 14,
      "z": 25,
      "name": "Deco_Bone_Full"
    },
    {
      "x": 8,
      "y": 15,
      "z": 25,
      "name": "Deco_Bone_Full"
    },
    {
      "x": 8,
      "y": 16,
      "z": 25,
      "name": "Deco_Bone_Full"
    },
    {
      "x": 8,
      "y": 17,
      "z": 25,
      "name": "Deco_Bone_Full"
    },
    {
      "x": 8,
      "y": 18,
      "z": 25,
      "name": "Deco_Bone_Full"
    },
    {
      "x": 9,
      "y": 11,
      "z": 14,
      "name": "Deco_Bone_Full"
    },
    {
      "x": 9,
      "y": 10,
      "z": 15,
      "name": "Deco_Bone_Full"
    },
    {
      "x": 9,
      "y": 11,
      "z": 15,
      "name": "Deco_Bone_Full"
    },
    {
      "x": 9,
      "y": 12,
      "z": 15,
      "name": "Deco_Bone_Full"
    },
    {
      "x": 9,
      "y": 6,
      "z": 16,
      "name": "Deco_Bone_Full"
    },
    {
      "x": 9,
      "y": 7,
      "z": 16,
      "name": "Deco_Bone_Full"
    },
    {
      "x": 9,
      "y": 8,
      "z": 16,
      "name": "Deco_Bone_Full"
    },
    {
      "x": 9,
      "y": 9,
      "z": 16,
      "name": "Deco_Bone_Full"
    },
    {
      "x": 9,
      "y": 10,
      "z": 16,
      "name": "Deco_Bone_Full"
    },
    {
      "x": 9,
      "y": 11,
      "z": 16,
      "name": "Deco_Bone_Full"
    },
    {
      "x": 9,
      "y": 12,
      "z": 16,
      "name": "Deco_Bone_Full"
    },
    {
      "x": 9,
      "y": 13,
      "z": 16,
      "name": "Deco_Bone_Full"
    },
    {
      "x": 9,
      "y": 9,
      "z": 17,
      "name": "Deco_Bone_Full"
    },
    {
      "x": 9,
      "y": 10,
      "z": 17,
      "name": "Deco_Bone_Full"
    },
    {
      "x": 9,
      "y": 11,
      "z": 17,
      "name": "Deco_Bone_Full"
    },
    {
      "x": 9,
      "y": 12,
      "z": 17,
      "name": "Deco_Bone_Full"
    },
    {
      "x": 10,
      "y": 11,
      "z": 14,
      "name": "Deco_Bone_Full"
    },
    {
      "x": 10,
      "y": 5,
      "z": 15,
      "name": "Deco_Bone_Full"
    },
    {
      "x": 10,
      "y": 6,
      "z": 15,
      "name": "Deco_Bone_Full"
    },
    {
      "x": 10,
      "y": 7,
      "z": 15,
      "name": "Deco_Bone_Full"
    },
    {
      "x": 10,
      "y": 8,
      "z": 15,
      "name": "Deco_Bone_Full"
    },
    {
      "x": 10,
      "y": 9,
      "z": 15,
      "name": "Deco_Bone_Full"
    },
    {
      "x": 10,
      "y": 10,
      "z": 15,
      "name": "Deco_Bone_Full"
    },
    {
      "x": 10,
      "y": 11,
      "z": 15,
      "name": "Deco_Bone_Full"
    },
    {
      "x": 10,
      "y": 10,
      "z": 16,
      "name": "Deco_Bone_Full"
    },
    {
      "x": 10,
      "y": 11,
      "z": 16,
      "name": "Deco_Bone_Full"
    },
    {
      "x": 10,
      "y": 12,
      "z": 16,
      "name": "Deco_Bone_Full"
    },
    {
      "x": 10,
      "y": 11,
      "z": 17,
      "name": "Deco_Bone_Full"
    },
    {
      "x": 10,
      "y": 12,
      "z": 17,
      "name": "Deco_Bone_Full"
    },
    {
      "x": 10,
      "y": 11,
      "z": 18,
      "name": "Deco_Bone_Full"
    },
    {
      "x": 10,
      "y": 12,
      "z": 18,
      "name": "Deco_Bone_Full"
    },
    {
      "x": 11,
      "y": 14,
      "z": 8,
      "name": "Deco_Bone_Full"
    },
    {
      "x": 11,
      "y": 15,
      "z": 8,
      "name": "Deco_Bone_Full"
    },
    {
      "x": 11,
      "y": 16,
      "z": 8,
      "name": "Deco_Bone_Full"
    },
    {
      "x": 11,
      "y": 17,
      "z": 8,
      "name": "Deco_Bone_Full"
    },
    {
      "x": 11,
      "y": 18,
      "z": 8,
      "name": "Deco_Bone_Full"
    },
    {
      "x": 11,
      "y": 19,
      "z": 8,
      "name": "Deco_Bone_Full"
    },
    {
      "x": 11,
      "y": 14,
      "z": 9,
      "name": "Deco_Bone_Full"
    },
    {
      "x": 11,
      "y": 11,
      "z": 13,
      "name": "Deco_Bone_Full"
    },
    {
      "x": 11,
      "y": 10,
      "z": 14,
      "name": "Deco_Bone_Full"
    },
    {
      "x": 11,
      "y": 11,
      "z": 14,
      "name": "Deco_Bone_Full"
    },
    {
      "x": 11,
      "y": 11,
      "z": 15,
      "name": "Deco_Bone_Full"
    },
    {
      "x": 11,
      "y": 11,
      "z": 16,
      "name": "Deco_Bone_Full"
    },
    {
      "x": 11,
      "y": 11,
      "z": 17,
      "name": "Deco_Bone_Full"
    },
    {
      "x": 11,
      "y": 12,
      "z": 17,
      "name": "Deco_Bone_Full"
    },
    {
      "x": 11,
      "y": 12,
      "z": 18,
      "name": "Deco_Bone_Full"
    },
    {
      "x": 11,
      "y": 13,
      "z": 18,
      "name": "Deco_Bone_Full"
    },
    {
      "x": 11,
      "y": 19,
      "z": 18,
      "name": "Deco_Bone_Full"
    },
    {
      "x": 11,
      "y": 20,
      "z": 18,
      "name": "Deco_Bone_Full"
    },
    {
      "x": 11,
      "y": 13,
      "z": 19,
      "name": "Deco_Bone_Full"
    },
    {
      "x": 12,
      "y": 14,
      "z": 8,
      "name": "Deco_Bone_Full"
    },
    {
      "x": 12,
      "y": 13,
      "z": 9,
      "name": "Deco_Bone_Full"
    },
    {
      "x": 12,
      "y": 14,
      "z": 9,
      "name": "Deco_Bone_Full"
    },
    {
      "x": 12,
      "y": 19,
      "z": 9,
      "name": "Deco_Bone_Full"
    },
    {
      "x": 12,
      "y": 20,
      "z": 9,
      "name": "Deco_Bone_Full"
    },
    {
      "x": 12,
      "y": 12,
      "z": 10,
      "name": "Deco_Bone_Full"
    },
    {
      "x": 12,
      "y": 13,
      "z": 10,
      "name": "Deco_Bone_Full"
    },
    {
      "x": 12,
      "y": 12,
      "z": 12,
      "name": "Deco_Bone_Full"
    },
    {
      "x": 12,
      "y": 10,
      "z": 13,
      "name": "Deco_Bone_Full"
    },
    {
      "x": 12,
      "y": 11,
      "z": 13,
      "name": "Deco_Bone_Full"
    },
    {
      "x": 12,
      "y": 12,
      "z": 13,
      "name": "Deco_Bone_Full"
    },
    {
      "x": 12,
      "y": 11,
      "z": 14,
      "name": "Deco_Bone_Full"
    },
    {
      "x": 12,
      "y": 13,
      "z": 18,
      "name": "Deco_Bone_Full"
    },
    {
      "x": 12,
      "y": 13,
      "z": 19,
      "name": "Deco_Bone_Full"
    },
    {
      "x": 12,
      "y": 14,
      "z": 19,
      "name": "Deco_Bone_Full"
    },
    {
      "x": 12,
      "y": 15,
      "z": 19,
      "name": "Deco_Bone_Full"
    },
    {
      "x": 12,
      "y": 16,
      "z": 19,
      "name": "Deco_Bone_Full"
    },
    {
      "x": 12,
      "y": 17,
      "z": 19,
      "name": "Deco_Bone_Full"
    },
    {
      "x": 12,
      "y": 18,
      "z": 19,
      "name": "Deco_Bone_Full"
    },
    {
      "x": 12,
      "y": 19,
      "z": 19,
      "name": "Deco_Bone_Full"
    },
    {
      "x": 13,
      "y": 12,
      "z": 9,
      "name": "Deco_Bone_Full"
    },
    {
      "x": 13,
      "y": 13,
      "z": 9,
      "name": "Deco_Bone_Full"
    },
    {
      "x": 13,
      "y": 12,
      "z": 10,
      "name": "Deco_Bone_Full"
    },
    {
      "x": 13,
      "y": 13,
      "z": 10,
      "name": "Deco_Bone_Full"
    },
    {
      "x": 13,
      "y": 10,
      "z": 11,
      "name": "Deco_Bone_Full"
    },
    {
      "x": 13,
      "y": 11,
      "z": 11,
      "name": "Deco_Bone_Full"
    },
    {
      "x": 13,
      "y": 12,
      "z": 11,
      "name": "Deco_Bone_Full"
    },
    {
      "x": 13,
      "y": 13,
      "z": 11,
      "name": "Deco_Bone_Full"
    },
    {
      "x": 13,
      "y": 9,
      "z": 12,
      "name": "Deco_Bone_Full"
    },
    {
      "x": 13,
      "y": 10,
      "z": 12,
      "name": "Deco_Bone_Full"
    },
    {
      "x": 13,
      "y": 11,
      "z": 12,
      "name": "Deco_Bone_Full"
    },
    {
      "x": 13,
      "y": 12,
      "z": 12,
      "name": "Deco_Bone_Full"
    },
    {
      "x": 13,
      "y": 13,
      "z": 12,
      "name": "Deco_Bone_Full"
    },
    {
      "x": 13,
      "y": 12,
      "z": 13,
      "name": "Deco_Bone_Full"
    },
    {
      "x": 14,
      "y": 12,
      "z": 9,
      "name": "Deco_Bone_Full"
    },
    {
      "x": 14,
      "y": 11,
      "z": 10,
      "name": "Deco_Bone_Full"
    },
    {
      "x": 14,
      "y": 12,
      "z": 10,
      "name": "Deco_Bone_Full"
    },
    {
      "x": 14,
      "y": 13,
      "z": 10,
      "name": "Deco_Bone_Full"
    },
    {
      "x": 14,
      "y": 8,
      "z": 11,
      "name": "Deco_Bone_Full"
    },
    {
      "x": 14,
      "y": 9,
      "z": 11,
      "name": "Deco_Bone_Full"
    },
    {
      "x": 14,
      "y": 10,
      "z": 11,
      "name": "Deco_Bone_Full"
    },
    {
      "x": 14,
      "y": 11,
      "z": 11,
      "name": "Deco_Bone_Full"
    },
    {
      "x": 14,
      "y": 12,
      "z": 11,
      "name": "Deco_Bone_Full"
    },
    {
      "x": 14,
      "y": 13,
      "z": 11,
      "name": "Deco_Bone_Full"
    },
    {
      "x": 14,
      "y": 14,
      "z": 11,
      "name": "Deco_Bone_Full"
    },
    {
      "x": 14,
      "y": 10,
      "z": 12,
      "name": "Deco_Bone_Full"
    },
    {
      "x": 14,
      "y": 11,
      "z": 12,
      "name": "Deco_Bone_Full"
    },
    {
      "x": 14,
      "y": 12,
      "z": 12,
      "name": "Deco_Bone_Full"
    },
    {
      "x": 14,
      "y": 13,
      "z": 12,
      "name": "Deco_Bone_Full"
    },
    {
      "x": 15,
      "y": 12,
      "z": 9,
      "name": "Deco_Bone_Full"
    },
    {
      "x": 15,
      "y": 7,
      "z": 10,
      "name": "Deco_Bone_Full"
    },
    {
      "x": 15,
      "y": 8,
      "z": 10,
      "name": "Deco_Bone_Full"
    },
    {
      "x": 15,
      "y": 9,
      "z": 10,
      "name": "Deco_Bone_Full"
    },
    {
      "x": 15,
      "y": 10,
      "z": 10,
      "name": "Deco_Bone_Full"
    },
    {
      "x": 15,
      "y": 11,
      "z": 10,
      "name": "Deco_Bone_Full"
    },
    {
      "x": 15,
      "y": 12,
      "z": 10,
      "name": "Deco_Bone_Full"
    },
    {
      "x": 15,
      "y": 11,
      "z": 11,
      "name": "Deco_Bone_Full"
    },
    {
      "x": 15,
      "y": 12,
      "z": 11,
      "name": "Deco_Bone_Full"
    },
    {
      "x": 15,
      "y": 13,
      "z": 11,
      "name": "Deco_Bone_Full"
    },
    {
      "x": 15,
      "y": 12,
      "z": 12,
      "name": "Deco_Bone_Full"
    },
    {
      "x": 15,
      "y": 13,
      "z": 12,
      "name": "Deco_Bone_Full"
    },
    {
      "x": 15,
      "y": 12,
      "z": 13,
      "name": "Deco_Bone_Full"
    },
    {
      "x": 15,
      "y": 13,
      "z": 13,
      "name": "Deco_Bone_Full"
    },
    {
      "x": 16,
      "y": 15,
      "z": 3,
      "name": "Deco_Bone_Full"
    },
    {
      "x": 16,
      "y": 16,
      "z": 3,
      "name": "Deco_Bone_Full"
    },
    {
      "x": 16,
      "y": 17,
      "z": 3,
      "name": "Deco_Bone_Full"
    },
    {
      "x": 16,
      "y": 18,
      "z": 3,
      "name": "Deco_Bone_Full"
    },
    {
      "x": 16,
      "y": 19,
      "z": 3,
      "name": "Deco_Bone_Full"
    },
    {
      "x": 16,
      "y": 15,
      "z": 4,
      "name": "Deco_Bone_Full"
    },
    {
      "x": 16,
      "y": 13,
      "z": 8,
      "name": "Deco_Bone_Full"
    },
    {
      "x": 16,
      "y": 12,
      "z": 9,
      "name": "Deco_Bone_Full"
    },
    {
      "x": 16,
      "y": 13,
      "z": 9,
      "name": "Deco_Bone_Full"
    },
    {
      "x": 16,
      "y": 12,
      "z": 10,
      "name": "Deco_Bone_Full"
    },
    {
      "x": 16,
      "y": 12,
      "z": 11,
      "name": "Deco_Bone_Full"
    },
    {
      "x": 16,
      "y": 12,
      "z": 12,
      "name": "Deco_Bone_Full"
    },
    {
      "x": 16,
      "y": 13,
      "z": 12,
      "name": "Deco_Bone_Full"
    },
    {
      "x": 16,
      "y": 13,
      "z": 13,
      "name": "Deco_Bone_Full"
    },
    {
      "x": 16,
      "y": 14,
      "z": 13,
      "name": "Deco_Bone_Full"
    },
    {
      "x": 16,
      "y": 19,
      "z": 13,
      "name": "Deco_Bone_Full"
    },
    {
      "x": 16,
      "y": 20,
      "z": 13,
      "name": "Deco_Bone_Full"
    },
    {
      "x": 16,
      "y": 14,
      "z": 14,
      "name": "Deco_Bone_Full"
    },
    {
      "x": 17,
      "y": 15,
      "z": 3,
      "name": "Deco_Bone_Full"
    },
    {
      "x": 17,
      "y": 14,
      "z": 4,
      "name": "Deco_Bone_Full"
    },
    {
      "x": 17,
      "y": 15,
      "z": 4,
      "name": "Deco_Bone_Full"
    },
    {
      "x": 17,
      "y": 19,
      "z": 4,
      "name": "Deco_Bone_Full"
    },
    {
      "x": 17,
      "y": 20,
      "z": 4,
      "name": "Deco_Bone_Full"
    },
    {
      "x": 17,
      "y": 13,
      "z": 5,
      "name": "Deco_Bone_Full"
    },
    {
      "x": 17,
      "y": 14,
      "z": 5,
      "name": "Deco_Bone_Full"
    },
    {
      "x": 17,
      "y": 13,
      "z": 7,
      "name": "Deco_Bone_Full"
    },
    {
      "x": 17,
      "y": 12,
      "z": 8,
      "name": "Deco_Bone_Full"
    },
    {
      "x": 17,
      "y": 13,
      "z": 8,
      "name": "Deco_Bone_Full"
    },
    {
      "x": 17,
      "y": 13,
      "z": 9,
      "name": "Deco_Bone_Full"
    },
    {
      "x": 17,
      "y": 14,
      "z": 13,
      "name": "Deco_Bone_Full"
    },
    {
      "x": 17,
      "y": 14,
      "z": 14,
      "name": "Deco_Bone_Full"
    },
    {
      "x": 17,
      "y": 15,
      "z": 14,
      "name": "Deco_Bone_Full"
    },
    {
      "x": 17,
      "y": 16,
      "z": 14,
      "name": "Deco_Bone_Full"
    },
    {
      "x": 17,
      "y": 17,
      "z": 14,
      "name": "Deco_Bone_Full"
    },
    {
      "x": 17,
      "y": 18,
      "z": 14,
      "name": "Deco_Bone_Full"
    },
    {
      "x": 17,
      "y": 19,
      "z": 14,
      "name": "Deco_Bone_Full"
    },
    {
      "x": 18,
      "y": 13,
      "z": 4,
      "name": "Deco_Bone_Full"
    },
    {
      "x": 18,
      "y": 14,
      "z": 4,
      "name": "Deco_Bone_Full"
    },
    {
      "x": 18,
      "y": 13,
      "z": 5,
      "name": "Deco_Bone_Full"
    },
    {
      "x": 18,
      "y": 14,
      "z": 5,
      "name": "Deco_Bone_Full"
    },
    {
      "x": 18,
      "y": 11,
      "z": 6,
      "name": "Deco_Bone_Full"
    },
    {
      "x": 18,
      "y": 12,
      "z": 6,
      "name": "Deco_Bone_Full"
    },
    {
      "x": 18,
      "y": 13,
      "z": 6,
      "name": "Deco_Bone_Full"
    },
    {
      "x": 18,
      "y": 14,
      "z": 6,
      "name": "Deco_Bone_Full"
    },
    {
      "x": 18,
      "y": 10,
      "z": 7,
      "name": "Deco_Bone_Full"
    },
    {
      "x": 18,
      "y": 11,
      "z": 7,
      "name": "Deco_Bone_Full"
    },
    {
      "x": 18,
      "y": 12,
      "z": 7,
      "name": "Deco_Bone_Full"
    },
    {
      "x": 18,
      "y": 13,
      "z": 7,
      "name": "Deco_Bone_Full"
    },
    {
      "x": 18,
      "y": 14,
      "z": 7,
      "name": "Deco_Bone_Full"
    },
    {
      "x": 18,
      "y": 13,
      "z": 8,
      "name": "Deco_Bone_Full"
    },
    {
      "x": 19,
      "y": 13,
      "z": 4,
      "name": "Deco_Bone_Full"
    },
    {
      "x": 19,
      "y": 12,
      "z": 5,
      "name": "Deco_Bone_Full"
    },
    {
      "x": 19,
      "y": 13,
      "z": 5,
      "name": "Deco_Bone_Full"
    },
    {
      "x": 19,
      "y": 14,
      "z": 5,
      "name": "Deco_Bone_Full"
    },
    {
      "x": 19,
      "y": 9,
      "z": 6,
      "name": "Deco_Bone_Full"
    },
    {
      "x": 19,
      "y": 10,
      "z": 6,
      "name": "Deco_Bone_Full"
    },
    {
      "x": 19,
      "y": 11,
      "z": 6,
      "name": "Deco_Bone_Full"
    },
    {
      "x": 19,
      "y": 12,
      "z": 6,
      "name": "Deco_Bone_Full"
    },
    {
      "x": 19,
      "y": 13,
      "z": 6,
      "name": "Deco_Bone_Full"
    },
    {
      "x": 19,
      "y": 14,
      "z": 6,
      "name": "Deco_Bone_Full"
    },
    {
      "x": 19,
      "y": 15,
      "z": 6,
      "name": "Deco_Bone_Full"
    },
    {
      "x": 19,
      "y": 11,
      "z": 7,
      "name": "Deco_Bone_Full"
    },
    {
      "x": 19,
      "y": 12,
      "z": 7,
      "name": "Deco_Bone_Full"
    },
    {
      "x": 19,
      "y": 13,
      "z": 7,
      "name": "Deco_Bone_Full"
    },
    {
      "x": 19,
      "y": 14,
      "z": 7,
      "name": "Deco_Bone_Full"
    },
    {
      "x": 20,
      "y": 14,
      "z": 4,
      "name": "Deco_Bone_Full"
    },
    {
      "x": 20,
      "y": 9,
      "z": 5,
      "name": "Deco_Bone_Full"
    },
    {
      "x": 20,
      "y": 10,
      "z": 5,
      "name": "Deco_Bone_Full"
    },
    {
      "x": 20,
      "y": 11,
      "z": 5,
      "name": "Deco_Bone_Full"
    },
    {
      "x": 20,
      "y": 12,
      "z": 5,
      "name": "Deco_Bone_Full"
    },
    {
      "x": 20,
      "y": 13,
      "z": 5,
      "name": "Deco_Bone_Full"
    },
    {
      "x": 20,
      "y": 14,
      "z": 5,
      "name": "Deco_Bone_Full"
    },
    {
      "x": 20,
      "y": 12,
      "z": 6,
      "name": "Deco_Bone_Full"
    },
    {
      "x": 20,
      "y": 13,
      "z": 6,
      "name": "Deco_Bone_Full"
    },
    {
      "x": 20,
      "y": 14,
      "z": 6,
      "name": "Deco_Bone_Full"
    },
    {
      "x": 20,
      "y": 13,
      "z": 7,
      "name": "Deco_Bone_Full"
    },
    {
      "x": 20,
      "y": 14,
      "z": 7,
      "name": "Deco_Bone_Full"
    },
    {
      "x": 20,
      "y": 13,
      "z": 8,
      "name": "Deco_Bone_Full"
    },
    {
      "x": 20,
      "y": 14,
      "z": 8,
      "name": "Deco_Bone_Full"
    },
    {
      "x": 21,
      "y": 14,
      "z": 3,
      "name": "Deco_Bone_Full"
    },
    {
      "x": 21,
      "y": 13,
      "z": 4,
      "name": "Deco_Bone_Full"
    },
    {
      "x": 21,
      "y": 14,
      "z": 4,
      "name": "Deco_Bone_Full"
    },
    {
      "x": 21,
      "y": 14,
      "z": 5,
      "name": "Deco_Bone_Full"
    },
    {
      "x": 21,
      "y": 13,
      "z": 6,
      "name": "Deco_Bone_Full"
    },
    {
      "x": 21,
      "y": 13,
      "z": 7,
      "name": "Deco_Bone_Full"
    },
    {
      "x": 21,
      "y": 14,
      "z": 7,
      "name": "Deco_Bone_Full"
    },
    {
      "x": 21,
      "y": 14,
      "z": 8,
      "name": "Deco_Bone_Full"
    },
    {
      "x": 21,
      "y": 15,
      "z": 8,
      "name": "Deco_Bone_Full"
    },
    {
      "x": 21,
      "y": 19,
      "z": 8,
      "name": "Deco_Bone_Full"
    },
    {
      "x": 21,
      "y": 20,
      "z": 8,
      "name": "Deco_Bone_Full"
    },
    {
      "x": 21,
      "y": 15,
      "z": 9,
      "name": "Deco_Bone_Full"
    },
    {
      "x": 22,
      "y": 14,
      "z": 2,
      "name": "Deco_Bone_Full"
    },
    {
      "x": 22,
      "y": 13,
      "z": 3,
      "name": "Deco_Bone_Full"
    },
    {
      "x": 22,
      "y": 14,
      "z": 3,
      "name": "Deco_Bone_Full"
    },
    {
      "x": 22,
      "y": 14,
      "z": 4,
      "name": "Deco_Bone_Full"
    },
    {
      "x": 22,
      "y": 15,
      "z": 8,
      "name": "Deco_Bone_Full"
    },
    {
      "x": 22,
      "y": 15,
      "z": 9,
      "name": "Deco_Bone_Full"
    },
    {
      "x": 22,
      "y": 16,
      "z": 9,
      "name": "Deco_Bone_Full"
    },
    {
      "x": 22,
      "y": 17,
      "z": 9,
      "name": "Deco_Bone_Full"
    },
    {
      "x": 22,
      "y": 18,
      "z": 9,
      "name": "Deco_Bone_Full"
    },
    {
      "x": 22,
      "y": 19,
      "z": 9,
      "name": "Deco_Bone_Full"
    },
    {
      "x": 23,
      "y": 15,
      "z": 1,
      "name": "Deco_Bone_Full"
    },
    {
      "x": 23,
      "y": 14,
      "z": 2,
      "name": "Deco_Bone_Full"
    },
    {
      "x": 23,
      "y": 15,
      "z": 2,
      "name": "Deco_Bone_Full"
    },
    {
      "x": 23,
      "y": 14,
      "z": 3,
      "name": "Deco_Bone_Full"
    },
    {
      "x": 24,
      "y": 15,
      "z": 0,
      "name": "Deco_Bone_Full"
    },
    {
      "x": 24,
      "y": 14,
      "z": 1,
      "name": "Deco_Bone_Full"
    },
    {
      "x": 24,
      "y": 15,
      "z": 1,
      "name": "Deco_Bone_Full"
    },
    {
      "x": 24,
      "y": 15,
      "z": 2,
      "name": "Deco_Bone_Full"
    },
    {
      "x": 25,
      "y": 15,
      "z": 0,
      "name": "Deco_Bone_Full"
    },
    {
      "x": 25,
      "y": 15,
      "z": 1,
      "name": "Deco_Bone_Full"
    }
  ]
}