{
  "version": 8,
  "blockIdVersion": 8,
  "anchorX": 4,
  "anchorY": 6,
  "anchorZ": -1,
  "blocks": [
    {
      "x": -5,
      "y": 9,
      "z": -1,
      "name": "Empty"
    },
    {
      "x": -5,
      "y": 10,
      "z": -1,
      "name": "Empty"
    },
    {
      "x": -5,
      "y": 5,
      "z": 3,
      "name": "Rock_Shale"
    },
    {
      "x": -5,
      "y": 6,
      "z": 3,
      "name": "Rock_Shale"
    },
    {
      "x": -5,
      "y": 6,
      "z": 4,
      "name": "Rock_Shale"
    },
    {
      "x": -5,
      "y": 7,
      "z": 4,
      "name": "Rock_Shale"
    },
    {
      "x": -4,
      "y": 9,
      "z": -1,
      "name": "Plant_Crop_Health3",
      "rotation": 3
    },
    {
      "x": -4,
      "y": 10,
      "z": -1,
      "name": "Plant_Crop_Health3",
      "filler": 1024,
      "rotation": 3
    },
    {
      "x": -4,
      "y": 6,
      "z": 3,
      "name": "Rock_Shale"
    },
    {
      "x": -4,
      "y": 7,
      "z": 3,
      "name": "Rock_Shale"
    },
    {
      "x": -3,
      "y": 2,
      "z": -1,
      "name": "Rock_Shale"
    },
    {
      "x": -3,
      "y": 3,
      "z": -1,
      "name": "Rock_Shale"
    },
    {
      "x": -3,
      "y": 4,
      "z": -1,
      "name": "Rock_Shale"
    },
    {
      "x": -3,
      "y": 5,
      "z": -1,
      "name": "Rock_Shale"
    },
    {
      "x": -3,
      "y": 6,
      "z": -1,
      "name": "Rock_Shale"
    },
    {
      "x": -3,
      "y": 7,
      "z": -1,
      "name": "Rock_Shale"
    },
    {
      "x": -3,
      "y": 8,
      "z": -1,
      "name": "Rock_Shale"
    },
    {
      "x": -3,
      "y": 9,
      "z": -1,
      "name": "Rock_Shale"
    },
    {
      "x": -3,
      "y": 10,
      "z": -1,
      "name": "Rock_Shale"
    },
    {
      "x": -3,
      "y": 11,
      "z": -1,
      "name": "Rock_Shale"
    },
    {
      "x": -3,
      "y": 12,
      "z": -1,
      "name": "Rock_Shale"
    },
    {
      "x": -3,
      "y": 2,
      "z": 0,
      "name": "Rock_Shale"
    },
    {
      "x": -3,
      "y": 3,
      "z": 0,
      "name": "Rock_Shale"
    },
    {
      "x": -3,
      "y": 4,
      "z": 0,
      "name": "Rock_Shale"
    },
    {
      "x": -3,
      "y": 5,
      "z": 0,
      "name": "Rock_Shale"
    },
    {
      "x": -3,
      "y": 6,
      "z": 0,
      "name": "Rock_Shale"
    },
    {
      "x": -3,
      "y": 7,
      "z": 0,
      "name": "Rock_Shale"
    },
    {
      "x": -3,
      "y": 8,
      "z": 0,
      "name": "Rock_Shale"
    },
    {
      "x": -3,
      "y": 9,
      "z": 0,
      "name": "Rock_Shale"
    },
    {
      "x": -3,
      "y": 10,
      "z": 0,
      "name": "Rock_Shale"
    },
    {
      "x": -3,
      "y": 11,
      "z": 0,
      "name": "Rock_Shale"
    },
    {
      "x": -3,
      "y": 12,
      "z": 0,
      "name": "Rock_Shale"
    },
    {
      "x": -3,
      "y": 13,
      "z": 0,
      "name": "Rock_Shale"
    },
    {
      "x": -3,
      "y": 2,
      "z": 1,
      "name": "Rock_Shale"
    },
    {
      "x": -3,
      "y": 3,
      "z": 1,
      "name": "Rock_Shale"
    },
    {
      "x": -3,
      "y": 4,
      "z": 1,
      "name": "Rock_Shale"
    },
    {
      "x": -3,
      "y": 5,
      "z": 1,
      "name": "Rock_Shale"
    },
    {
      "x": -3,
      "y": 6,
      "z": 1,
      "name": "Rock_Shale"
    },
    {
      "x": -3,
      "y": 8,
      "z": 1,
      "name": "Rock_Shale"
    },
    {
      "x": -3,
      "y": 9,
      "z": 1,
      "name": "Rock_Shale"
    },
    {
      "x": -3,
      "y": 10,
      "z": 1,
      "name": "Rock_Shale"
    },
    {
      "x": -3,
      "y": 11,
      "z": 1,
      "name": "Rock_Shale"
    },
    {
      "x": -3,
      "y": 12,
      "z": 1,
      "name": "Rock_Shale"
    },
    {
      "x": -3,
      "y": 13,
      "z": 1,
      "name": "Rock_Shale"
    },
    {
      "x": -3,
      "y": 2,
      "z": 2,
      "name": "Rock_Shale"
    },
    {
      "x": -3,
      "y": 3,
      "z": 2,
      "name": "Rock_Shale"
    },
    {
      "x": -3,
      "y": 4,
      "z": 2,
      "name": "Rock_Shale"
    },
    {
      "x": -3,
      "y": 5,
      "z": 2,
      "name": "Rock_Shale"
    },
    {
      "x": -3,
      "y": 9,
      "z": 2,
      "name": "Rock_Shale"
    },
    {
      "x": -3,
      "y": 10,
      "z": 2,
      "name": "Rock_Shale"
    },
    {
      "x": -3,
      "y": 11,
      "z": 2,
      "name": "Rock_Shale"
    },
    {
      "x": -3,
      "y": 12,
      "z": 2,
      "name": "Rock_Shale"
    },
    {
      "x": -3,
      "y": 13,
      "z": 2,
      "name": "Rock_Shale"
    },
    {
      "x": -2,
      "y": 2,
      "z": -1,
      "name": "Rock_Shale"
    },
    {
      "x": -2,
      "y": 3,
      "z": -1,
      "name": "Rock_Shale"
    },
    {
      "x": -2,
      "y": 4,
      "z": -1,
      "name": "Rock_Shale"
    },
    {
      "x": -2,
      "y": 5,
      "z": -1,
      "name": "Rock_Shale"
    },
    {
      "x": -2,
      "y": 6,
      "z": -1,
      "name": "Rock_Shale"
    },
    {
      "x": -2,
      "y": 7,
      "z": -1,
      "name": "Rock_Shale"
    },
    {
      "x": -2,
      "y": 8,
      "z": -1,
      "name": "Rock_Shale"
    },
    {
      "x": -2,
      "y": 9,
      "z": -1,
      "name": "Rock_Shale"
    },
    {
      "x": -2,
      "y": 10,
      "z": -1,
      "name": "Rock_Shale"
    },
    {
      "x": -2,
      "y": 11,
      "z": -1,
      "name": "Rock_Shale"
    },
    {
      "x": -2,
      "y": 2,
      "z": 0,
      "name": "Rock_Shale"
    },
    {
      "x": -2,
      "y": 3,
      "z": 0,
      "name": "Rock_Ice_Permafrost"
    },
    {
      "x": -2,
      "y": 4,
      "z": 0,
      "name": "Rock_Ice_Permafrost"
    },
    {
      "x": -2,
      "y": 5,
      "z": 0,
      "name": "Rock_Ice_Permafrost"
    },
    {
      "x": -2,
      "y": 6,
      "z": 0,
      "name": "Rock_Ice_Permafrost"
    },
    {
      "x": -2,
      "y": 7,
      "z": 0,
      "name": "Rock_Ice_Permafrost"
    },
    {
      "x": -2,
      "y": 8,
      "z": 0,
      "name": "Rock_Ice_Permafrost"
    },
    {
      "x": -2,
      "y": 9,
      "z": 0,
      "name": "Rock_Ice_Permafrost"
    },
    {
      "x": -2,
      "y": 10,
      "z": 0,
      "name": "Rock_Ice_Permafrost"
    },
    {
      "x": -2,
      "y": 11,
      "z": 0,
      "name": "Rock_Ice_Permafrost"
    },
    {
      "x": -2,
      "y": 2,
      "z": 1,
      "name": "Rock_Shale"
    },
    {
      "x": -2,
      "y": 3,
      "z": 1,
      "name": "Rock_Ice_Permafrost"
    },
    {
      "x": -2,
      "y": 4,
      "z": 1,
      "name": "Rock_Ice_Permafrost"
    },
    {
      "x": -2,
      "y": 5,
      "z": 1,
      "name": "Rock_Ice_Permafrost"
    },
    {
      "x": -2,
      "y": 6,
      "z": 1,
      "name": "Rock_Ice_Permafrost"
    },
    {
      "x": -2,
      "y": 7,
      "z": 1,
      "name": "Rock_Ice_Permafrost"
    },
    {
      "x": -2,
      "y": 8,
      "z": 1,
      "name": "Rock_Ice_Permafrost"
    },
    {
      "x": -2,
      "y": 9,
      "z": 1,
      "name": "Rock_Crystal_Blue_Block"
    },
    {
      "x": -2,
      "y": 10,
      "z": 1,
      "name": "Rock_Ice_Permafrost"
    },
    {
      "x": -2,
      "y": 11,
      "z": 1,
      "name": "Rock_Ice_Permafrost"
    },
    {
      "x": -2,
      "y": 12,
      "z": 1,
      "name": "Rock_Ice_Permafrost"
    },
    {
      "x": -2,
      "y": 13,
      "z": 1,
      "name": "Rock_Ice_Permafrost"
    },
    {
      "x": -2,
      "y": 2,
      "z": 2,
      "name": "Rock_Shale"
    },
    {
      "x": -2,
      "y": 3,
      "z": 2,
      "name": "Rock_Shale"
    },
    {
      "x": -2,
      "y": 4,
      "z": 2,
      "name": "Rock_Shale"
    },
    {
      "x": -2,
      "y": 5,
      "z": 2,
      "name": "Rock_Shale"
    },
    {
      "x": -2,
      "y": 6,
      "z": 2,
      "name": "Rock_Shale"
    },
    {
      "x": -2,
      "y": 7,
      "z": 2,
      "name": "Rock_Shale"
    },
    {
      "x": -2,
      "y": 8,
      "z": 2,
      "name": "Rock_Shale"
    },
    {
      "x": -2,
      "y": 9,
      "z": 2,
      "name": "Rock_Shale"
    },
    {
      "x": -2,
      "y": 10,
      "z": 2,
      "name": "Rock_Shale"
    },
    {
      "x": -2,
      "y": 11,
      "z": 2,
      "name": "Rock_Shale"
    },
    {
      "x": -2,
      "y": 12,
      "z": 2,
      "name": "Rock_Shale"
    },
    {
      "x": -2,
      "y": 13,
      "z": 2,
      "name": "Rock_Shale"
    },
    {
      "x": -2,
      "y": 7,
      "z": 3,
      "name": "Plant_Crop_Health3"
    },
    {
      "x": -2,
      "y": 8,
      "z": 3,
      "name": "Plant_Crop_Health3",
      "filler": 1024
    },
    {
      "x": -2,
      "y": 7,
      "z": 4,
      "name": "Empty"
    },
    {
      "x": -2,
      "y": 8,
      "z": 4,
      "name": "Empty"
    },
    {
      "x": -1,
      "y": 3,
      "z": -1,
      "name": "Rock_Shale"
    },
    {
      "x": -1,
      "y": 4,
      "z": -1,
      "name": "Rock_Shale"
    },
    {
      "x": -1,
      "y": 5,
      "z": -1,
      "name": "Rock_Shale"
    },
    {
      "x": -1,
      "y": 6,
      "z": -1,
      "name": "Rock_Shale"
    },
    {
      "x": -1,
      "y": 7,
      "z": -1,
      "name": "Rock_Shale"
    },
    {
      "x": -1,
      "y": 8,
      "z": -1,
      "name": "Rock_Shale"
    },
    {
      "x": -1,
      "y": 9,
      "z": -1,
      "name": "Rock_Shale"
    },
    {
      "x": -1,
      "y": 10,
      "z": -1,
      "name": "Rock_Shale"
    },
    {
      "x": -1,
      "y": 2,
      "z": 0,
      "name": "Rock_Shale"
    },
    {
      "x": -1,
      "y": 3,
      "z": 0,
      "name": "Rock_Shale"
    },
    {
      "x": -1,
      "y": 4,
      "z": 0,
      "name": "Rock_Shale"
    },
    {
      "x": -1,
      "y": 5,
      "z": 0,
      "name": "Rock_Shale"
    },
    {
      "x": -1,
      "y": 6,
      "z": 0,
      "name": "Rock_Shale"
    },
    {
      "x": -1,
      "y": 7,
      "z": 0,
      "name": "Rock_Shale"
    },
    {
      "x": -1,
      "y": 8,
      "z": 0,
      "name": "Rock_Ice_Permafrost"
    },
    {
      "x": -1,
      "y": 9,
      "z": 0,
      "name": "Rock_Ice_Permafrost"
    },
    {
      "x": -1,
      "y": 2,
      "z": 1,
      "name": "Rock_Shale"
    },
    {
      "x": -1,
      "y": 3,
      "z": 1,
      "name": "Rock_Shale"
    },
    {
      "x": -1,
      "y": 4,
      "z": 1,
      "name": "Rock_Ice_Permafrost"
    },
    {
      "x": -1,
      "y": 5,
      "z": 1,
      "name": "Rock_Ice_Permafrost"
    },
    {
      "x": -1,
      "y": 6,
      "z": 1,
      "name": "Rock_Ice_Permafrost"
    },
    {
      "x": -1,
      "y": 7,
      "z": 1,
      "name": "Rock_Ice_Permafrost"
    },
    {
      "x": -1,
      "y": 8,
      "z": 1,
      "name": "Rock_Ice_Permafrost"
    },
    {
      "x": -1,
      "y": 9,
      "z": 1,
      "name": "Rock_Ice_Permafrost"
    },
    {
      "x": -1,
      "y": 10,
      "z": 1,
      "name": "Rock_Ice_Permafrost"
    },
    {
      "x": -1,
      "y": 11,
      "z": 1,
      "name": "Rock_Ice_Permafrost"
    },
    {
      "x": -1,
      "y": 12,
      "z": 1,
      "name": "Rock_Ice_Permafrost"
    },
    {
      "x": -1,
      "y": 2,
      "z": 2,
      "name": "Rock_Shale"
    },
    {
      "x": -1,
      "y": 3,
      "z": 2,
      "name": "Rock_Shale"
    },
    {
      "x": -1,
      "y": 4,
      "z": 2,
      "name": "Rock_Shale"
    },
    {
      "x": -1,
      "y": 5,
      "z": 2,
      "name": "Rock_Shale"
    },
    {
      "x": -1,
      "y": 6,
      "z": 2,
      "name": "Rock_Shale"
    },
    {
      "x": -1,
      "y": 7,
      "z": 2,
      "name": "Rock_Shale"
    },
    {
      "x": -1,
      "y": 8,
      "z": 2,
      "name": "Rock_Shale"
    },
    {
      "x": -1,
      "y": 9,
      "z": 2,
      "name": "Rock_Shale"
    },
    {
      "x": -1,
      "y": 10,
      "z": 2,
      "name": "Rock_Shale"
    },
    {
      "x": -1,
      "y": 11,
      "z": 2,
      "name": "Rock_Shale"
    },
    {
      "x": -1,
      "y": 12,
      "z": 2,
      "name": "Rock_Shale"
    },
    {
      "x": -1,
      "y": 13,
      "z": 2,
      "name": "Rock_Shale"
    },
    {
      "x": 0,
      "y": 5,
      "z": -1,
      "name": "Rock_Shale"
    },
    {
      "x": 0,
      "y": 6,
      "z": -1,
      "name": "Rock_Shale"
    },
    {
      "x": 0,
      "y": 7,
      "z": -1,
      "name": "Rock_Shale"
    },
    {
      "x": 0,
      "y": 8,
      "z": -1,
      "name": "Rock_Shale"
    },
    {
      "x": 0,
      "y": 9,
      "z": -1,
      "name": "Rock_Shale"
    },
    {
      "x": 0,
      "y": 4,
      "z": 0,
      "name": "Rock_Shale"
    },
    {
      "x": 0,
      "y": 5,
      "z": 0,
      "name": "Rock_Shale"
    },
    {
      "x": 0,
      "y": 6,
      "z": 0,
      "name": "Rock_Shale"
    },
    {
      "x": 0,
      "y": 7,
      "z": 0,
      "name": "Rock_Shale"
    },
    {
      "x": 0,
      "y": 8,
      "z": 0,
      "name": "Rock_Shale"
    },
    {
      "x": 0,
      "y": 9,
      "z": 0,
      "name": "Rock_Shale"
    },
    {
      "x": 0,
      "y": 10,
      "z": 0,
      "name": "Rock_Shale"
    },
    {
      "x": 0,
      "y": 2,
      "z": 1,
      "name": "Rock_Shale"
    },
    {
      "x": 0,
      "y": 3,
      "z": 1,
      "name": "Rock_Shale"
    },
    {
      "x": 0,
      "y": 4,
      "z": 1,
      "name": "Rock_Shale"
    },
    {
      "x": 0,
      "y": 5,
      "z": 1,
      "name": "Rock_Shale"
    },
    {
      "x": 0,
      "y": 6,
      "z": 1,
      "name": "Rock_Shale"
    },
    {
      "x": 0,
      "y": 7,
      "z": 1,
      "name": "Rock_Shale"
    },
    {
      "x": 0,
      "y": 8,
      "z": 1,
      "name": "Rock_Shale"
    },
    {
      "x": 0,
      "y": 9,
      "z": 1,
      "name": "Rock_Shale"
    },
    {
      "x": 0,
      "y": 10,
      "z": 1,
      "name": "Rock_Shale"
    },
    {
      "x": 0,
      "y": 11,
      "z": 1,
      "name": "Rock_Shale"
    },
    {
      "x": 0,
      "y": 2,
      "z": 2,
      "name": "Rock_Shale"
    },
    {
      "x": 0,
      "y": 3,
      "z": 2,
      "name": "Rock_Shale"
    },
    {
      "x": 0,
      "y": 4,
      "z": 2,
      "name": "Rock_Shale"
    },
    {
      "x": 0,
      "y": 5,
      "z": 2,
      "name": "Rock_Shale"
    },
    {
      "x": 0,
      "y": 6,
      "z": 2,
      "name": "Rock_Shale"
    },
    {
      "x": 0,
      "y": 7,
      "z": 2,
      "name": "Rock_Shale"
    },
    {
      "x": 0,
      "y": 8,
      "z": 2,
      "name": "Rock_Shale"
    },
    {
      "x": 0,
      "y": 9,
      "z": 2,
      "name": "Rock_Shale"
    },
    {
      "x": 0,
      "y": 10,
      "z": 2,
      "name": "Rock_Shale"
    },
    {
      "x": 0,
      "y": 11,
      "z": 2,
      "name": "Rock_Shale"
    },
    {
      "x": 1,
      "y": 7,
      "z": -2,
      "name": "Rock_Shale"
    },
    {
      "x": 2,
      "y": 6,
      "z": -2,
      "name": "Rock_Shale"
    },
    {
      "x": 2,
      "y": 7,
      "z": -2,
      "name": "Rock_Shale"
    },
    {
      "x": 2,
      "y": 8,
      "z": -2,
      "name": "Rock_Shale"
    },
    {
      "x": 2,
      "y": 9,
      "z": -2,
      "name": "Rock_Shale"
    },
    {
      "x": 2,
      "y": 7,
      "z": -1,
      "name": "Rock_Shale"
    },
    {
      "x": 2,
      "y": 8,
      "z": -1,
      "name": "Rock_Shale"
    },
    {
      "x": 3,
      "y": 6,
      "z": -2,
      "name": "Rock_Shale"
    },
    {
      "x": 3,
      "y": 7,
      "z": -2,
      "name": "Rock_Shale"
    },
    {
      "x": 3,
      "y": 8,
      "z": -2,
      "name": "Rock_Shale"
    },
    {
      "x": 3,
      "y": 9,
      "z": -2,
      "name": "Rock_Shale"
    },
    {
      "x": 3,
      "y": 6,
      "z": -1,
      "name": "Rock_Shale"
    },
    {
      "x": 3,
      "y": 7,
      "z": -1,
      "name": "Rock_Shale"
    },
    {
      "x": 3,
      "y": 8,
      "z": -1,
      "name": "Rock_Shale"
    },
    {
      "x": 3,
      "y": 9,
      "z": -1,
      "name": "Rock_Ice_Permafrost"
    },
    {
      "x": 3,
      "y": 6,
      "z": 0,
      "name": "Rock_Shale"
    },
    {
      "x": 3,
      "y": 7,
      "z": 0,
      "name": "Rock_Shale"
    },
    {
      "x": 3,
      "y": 7,
      "z": 1,
      "name": "Rock_Shale"
    },
    {
      "x": 4,
      "y": 7,
      "z": -2,
      "name": "Rock_Shale"
    },
    {
      "x": 4,
      "y": 8,
      "z": -2,
      "name": "Rock_Shale"
    },
    {
      "x": 4,
      "y": 9,
      "z": -2,
      "name": "Rock_Shale"
    },
    {
      "x": 4,
      "y": 6,
      "z": -1,
      "name": "Rock_Shale"
    },
    {
      "x": 4,
      "y": 7,
      "z": -1,
      "name": "Rock_Shale"
    },
    {
      "x": 4,
      "y": 8,
      "z": -1,
      "name": "Rock_Shale"
    },
    {
      "x": 4,
      "y": 9,
      "z": -1,
      "name": "Rock_Ice_Permafrost"
    },
    {
      "x": 4,
      "y": 10,
      "z": -1,
      "name": "Rock_Shale"
    },
    {
      "x": 4,
      "y": 6,
      "z": 0,
      "name": "Rock_Shale"
    },
    {
      "x": 4,
      "y": 7,
      "z": 0,
      "name": "Rock_Shale"
    },
    {
      "x": 4,
      "y": 8,
      "z": 0,
      "name": "Rock_Ice_Permafrost"
    },
    {
      "x": 4,
      "y": 9,
      "z": 0,
      "name": "Rock_Ice_Permafrost"
    },
    {
      "x": 4,
      "y": 6,
      "z": 1,
      "name": "Rock_Shale"
    },
    {
      "x": 4,
      "y": 7,
      "z": 1,
      "name": "Rock_Shale"
    },
    {
      "x": 4,
      "y": 8,
      "z": 1,
      "name": "Rock_Shale"
    },
    {
      "x": 5,
      "y": 7,
      "z": -2,
      "name": "Rock_Shale"
    },
    {
      "x": 5,
      "y": 8,
      "z": -2,
      "name": "Rock_Shale"
    },
    {
      "x": 5,
      "y": 9,
      "z": -2,
      "name": "Rock_Shale"
    },
    {
      "x": 5,
      "y": 10,
      "z": -2,
      "name": "Rock_Shale"
    },
    {
      "x": 5,
      "y": 6,
      "z": -1,
      "name": "Rock_Shale"
    },
    {
      "x": 5,
      "y": 7,
      "z": -1,
      "name": "Rock_Shale"
    },
    {
      "x": 5,
      "y": 8,
      "z": -1,
      "name": "Rock_Crystal_Blue_Block"
    },
    {
      "x": 5,
      "y": 9,
      "z": -1,
      "name": "Rock_Ice_Permafrost"
    },
    {
      "x": 5,
      "y": 10,
      "z": -1,
      "name": "Rock_Shale"
    },
    {
      "x": 5,
      "y": 6,
      "z": 0,
      "name": "Rock_Shale"
    },
    {
      "x": 5,
      "y": 7,
      "z": 0,
      "name": "Rock_Shale"
    },
    {
      "x": 5,
      "y": 8,
      "z": 0,
      "name": "Rock_Ice_Permafrost"
    },
    {
      "x": 5,
      "y": 9,
      "z": 0,
      "name": "Rock_Ice_Permafrost"
    },
    {
      "x": 5,
      "y": 6,
      "z": 1,
      "name": "Rock_Shale"
    },
    {
      "x": 5,
      "y": 7,
      "z": 1,
      "name": "Rock_Shale"
    },
    {
      "x": 5,
      "y": 8,
      "z": 1,
      "name": "Rock_Shale"
    },
    {
      "x": 5,
      "y": 8,
      "z": 2,
      "name": "Plant_Crop_Health3"
    },
    {
      "x": 5,
      "y": 9,
      "z": 2,
      "name": "Plant_Crop_Health3",
      "filler": 1024
    },
    {
      "x": 5,
      "y": 8,
      "z": 3,
      "name": "Empty"
    },
    {
      "x": 5,
      "y": 9,
      "z": 3,
      "name": "Empty"
    },
    {
      "x": 6,
      "y": 7,
      "z": -2,
      "name": "Rock_Shale"
    },
    {
      "x": 6,
      "y": 8,
      "z": -2,
      "name": "Rock_Shale"
    },
    {
      "x": 6,
      "y": 9,
      "z": -2,
      "name": "Rock_Shale"
    },
    {
      "x": 6,
      "y": 10,
      "z": -2,
      "name": "Rock_Shale"
    },
    {
      "x": 6,
      "y": 6,
      "z": -1,
      "name": "Rock_Shale"
    },
    {
      "x": 6,
      "y": 7,
      "z": -1,
      "name": "Rock_Shale"
    },
    {
      "x": 6,
      "y": 8,
      "z": -1,
      "name": "Rock_Shale"
    },
    {
      "x": 6,
      "y": 9,
      "z": -1,
      "name": "Rock_Ice_Permafrost"
    },
    {
      "x": 6,
      "y": 10,
      "z": -1,
      "name": "Rock_Shale"
    },
    {
      "x": 6,
      "y": 6,
      "z": 0,
      "name": "Rock_Shale"
    },
    {
      "x": 6,
      "y": 7,
      "z": 0,
      "name": "Rock_Shale"
    },
    {
      "x": 6,
      "y": 8,
      "z": 0,
      "name": "Rock_Shale"
    },
    {
      "x": 6,
      "y": 9,
      "z": 0,
      "name": "Rock_Ice_Permafrost"
    },
    {
      "x": 6,
      "y": 10,
      "z": 0,
      "name": "Rock_Shale"
    },
    {
      "x": 6,
      "y": 6,
      "z": 1,
      "name": "Rock_Shale"
    },
    {
      "x": 6,
      "y": 7,
      "z": 1,
      "name": "Rock_Shale"
    },
    {
      "x": 6,
      "y": 8,
      "z": 1,
      "name": "Rock_Shale"
    },
    {
      "x": 6,
      "y": 9,
      "z": 1,
      "name": "Rock_Shale"
    },
    {
      "x": 6,
      "y": 10,
      "z": 1,
      "name": "Rock_Shale"
    },
    {
      "x": 7,
      "y": 7,
      "z": -2,
      "name": "Rock_Shale"
    },
    {
      "x": 7,
      "y": 8,
      "z": -2,
      "name": "Rock_Shale"
    },
    {
      "x": 7,
      "y": 9,
      "z": -2,
      "name": "Rock_Shale"
    },
    {
      "x": 7,
      "y": 10,
      "z": -2,
      "name": "Rock_Shale"
    },
    {
      "x": 7,
      "y": 7,
      "z": -1,
      "name": "Rock_Shale"
    },
    {
      "x": 7,
      "y": 8,
      "z": -1,
      "name": "Rock_Shale"
    },
    {
      "x": 7,
      "y": 7,
      "z": 0,
      "name": "Rock_Shale"
    },
    {
      "x": 7,
      "y": 8,
      "z": 0,
      "name": "Rock_Shale"
    },
    {
      "x": 7,
      "y": 9,
      "z": 0,
      "name": "Rock_Shale"
    },
    {
      "x": 7,
      "y": 10,
      "z": 0,
      "name": "Rock_Shale"
    },
    {
      "x": 7,
      "y": 7,
      "z": 1,
      "name": "Rock_Shale"
    },
    {
      "x": 7,
      "y": 8,
      "z": 1,
      "name": "Rock_Shale"
    },
    {
      "x": 7,
      "y": 9,
      "z": 1,
      "name": "Rock_Shale"
    },
    {
      "x": 7,
      "y": 10,
      "z": 1,
      "name": "Rock_Shale"
    }
  ]
}