{
  "version": 8,
  "blockIdVersion": 8,
  "anchorX": 23,
  "anchorY": 9,
  "anchorZ": 17,
  "blocks": [
    {
      "x": 13,
      "y": 10,
      "z": 21,
      "name": "Rock_Basalt"
    },
    {
      "x": 13,
      "y": 11,
      "z": 21,
      "name": "Soil_Grass_Burnt"
    },
    {
      "x": 14,
      "y": 11,
      "z": 20,
      "name": "Rock_Basalt"
    },
    {
      "x": 14,
      "y": 12,
      "z": 20,
      "name": "Rock_Basalt"
    },
    {
      "x": 14,
      "y": 13,
      "z": 20,
      "name": "Soil_Grass_Burnt"
    },
    {
      "x": 14,
      "y": 8,
      "z": 21,
      "name": "Rock_Basalt"
    },
    {
      "x": 14,
      "y": 9,
      "z": 21,
      "name": "Rock_Basalt"
    },
    {
      "x": 14,
      "y": 10,
      "z": 21,
      "name": "Rock_Basalt"
    },
    {
      "x": 14,
      "y": 11,
      "z": 21,
      "name": "Rock_Basalt"
    },
    {
      "x": 14,
      "y": 12,
      "z": 21,
      "name": "Rock_Basalt"
    },
    {
      "x": 14,
      "y": 13,
      "z": 21,
      "name": "Soil_Grass_Burnt"
    },
    {
      "x": 14,
      "y": 14,
      "z": 21,
      "name": "Plant_Grass_Sharp"
    },
    {
      "x": 14,
      "y": 9,
      "z": 22,
      "name": "Rock_Basalt"
    },
    {
      "x": 14,
      "y": 10,
      "z": 22,
      "name": "Rock_Basalt"
    },
    {
      "x": 14,
      "y": 11,
      "z": 22,
      "name": "Rock_Basalt"
    },
    {
      "x": 14,
      "y": 12,
      "z": 22,
      "name": "Rock_Basalt"
    },
    {
      "x": 14,
      "y": 13,
      "z": 22,
      "name": "Soil_Grass_Burnt"
    },
    {
      "x": 14,
      "y": 14,
      "z": 22,
      "name": "Plant_Grass_Sharp"
    },
    {
      "x": 14,
      "y": 12,
      "z": 23,
      "name": "Soil_Grass_Burnt"
    },
    {
      "x": 14,
      "y": 13,
      "z": 23,
      "name": "Plant_Grass_Sharp"
    },
    {
      "x": 15,
      "y": 26,
      "z": 10,
      "name": "Plant_Leaves_Dead",
      "support": 15
    },
    {
      "x": 15,
      "y": 27,
      "z": 10,
      "name": "Plant_Leaves_Dead",
      "support": 15
    },
    {
      "x": 15,
      "y": 28,
      "z": 10,
      "name": "Plant_Leaves_Dead",
      "support": 15
    },
    {
      "x": 15,
      "y": 29,
      "z": 10,
      "name": "Plant_Leaves_Dead",
      "support": 15
    },
    {
      "x": 15,
      "y": 27,
      "z": 11,
      "name": "Plant_Leaves_Dead",
      "support": 15
    },
    {
      "x": 15,
      "y": 28,
      "z": 11,
      "name": "Plant_Leaves_Dead",
      "support": 15
    },
    {
      "x": 15,
      "y": 29,
      "z": 11,
      "name": "Plant_Leaves_Dead",
      "support": 15
    },
    {
      "x": 15,
      "y": 28,
      "z": 12,
      "name": "Plant_Leaves_Dead",
      "support": 15
    },
    {
      "x": 15,
      "y": 14,
      "z": 18,
      "name": "Soil_Grass_Burnt"
    },
    {
      "x": 15,
      "y": 7,
      "z": 19,
      "name": "Rock_Basalt"
    },
    {
      "x": 15,
      "y": 8,
      "z": 19,
      "name": "Rock_Basalt"
    },
    {
      "x": 15,
      "y": 9,
      "z": 19,
      "name": "Rock_Basalt"
    },
    {
      "x": 15,
      "y": 10,
      "z": 19,
      "name": "Rock_Basalt"
    },
    {
      "x": 15,
      "y": 11,
      "z": 19,
      "name": "Rock_Basalt"
    },
    {
      "x": 15,
      "y": 12,
      "z": 19,
      "name": "Rock_Basalt"
    },
    {
      "x": 15,
      "y": 13,
      "z": 19,
      "name": "Rock_Basalt"
    },
    {
      "x": 15,
      "y": 14,
      "z": 19,
      "name": "Rock_Basalt"
    },
    {
      "x": 15,
      "y": 15,
      "z": 19,
      "name": "Soil_Grass_Burnt"
    },
    {
      "x": 15,
      "y": 16,
      "z": 19,
      "name": "Plant_Grass_Sharp"
    },
    {
      "x": 15,
      "y": 5,
      "z": 20,
      "name": "Rock_Basalt"
    },
    {
      "x": 15,
      "y": 6,
      "z": 20,
      "name": "Rock_Basalt"
    },
    {
      "x": 15,
      "y": 7,
      "z": 20,
      "name": "Rock_Basalt"
    },
    {
      "x": 15,
      "y": 8,
      "z": 20,
      "name": "Rock_Basalt"
    },
    {
      "x": 15,
      "y": 9,
      "z": 20,
      "name": "Rock_Basalt"
    },
    {
      "x": 15,
      "y": 10,
      "z": 20,
      "name": "Rock_Basalt"
    },
    {
      "x": 15,
      "y": 11,
      "z": 20,
      "name": "Rock_Basalt"
    },
    {
      "x": 15,
      "y": 12,
      "z": 20,
      "name": "Rock_Basalt"
    },
    {
      "x": 15,
      "y": 13,
      "z": 20,
      "name": "Rock_Basalt"
    },
    {
      "x": 15,
      "y": 14,
      "z": 20,
      "name": "Rock_Basalt"
    },
    {
      "x": 15,
      "y": 15,
      "z": 20,
      "name": "Soil_Grass_Burnt"
    },
    {
      "x": 15,
      "y": 16,
      "z": 20,
      "name": "Plant_Grass_Sharp"
    },
    {
      "x": 15,
      "y": 5,
      "z": 21,
      "name": "Rock_Basalt"
    },
    {
      "x": 15,
      "y": 6,
      "z": 21,
      "name": "Rock_Basalt"
    },
    {
      "x": 15,
      "y": 7,
      "z": 21,
      "name": "Rock_Basalt"
    },
    {
      "x": 15,
      "y": 8,
      "z": 21,
      "name": "Rock_Basalt"
    },
    {
      "x": 15,
      "y": 9,
      "z": 21,
      "name": "Rock_Basalt"
    },
    {
      "x": 15,
      "y": 10,
      "z": 21,
      "name": "Rock_Basalt"
    },
    {
      "x": 15,
      "y": 11,
      "z": 21,
      "name": "Rock_Basalt"
    },
    {
      "x": 15,
      "y": 12,
      "z": 21,
      "name": "Rock_Basalt"
    },
    {
      "x": 15,
      "y": 13,
      "z": 21,
      "name": "Rock_Basalt"
    },
    {
      "x": 15,
      "y": 14,
      "z": 21,
      "name": "Rock_Basalt"
    },
    {
      "x": 15,
      "y": 15,
      "z": 21,
      "name": "Soil_Grass_Burnt"
    },
    {
      "x": 15,
      "y": 16,
      "z": 21,
      "name": "Plant_Grass_Gnarled_Short"
    },
    {
      "x": 15,
      "y": 6,
      "z": 22,
      "name": "Rock_Basalt"
    },
    {
      "x": 15,
      "y": 7,
      "z": 22,
      "name": "Rock_Basalt"
    },
    {
      "x": 15,
      "y": 8,
      "z": 22,
      "name": "Rock_Basalt"
    },
    {
      "x": 15,
      "y": 9,
      "z": 22,
      "name": "Rock_Basalt"
    },
    {
      "x": 15,
      "y": 10,
      "z": 22,
      "name": "Rock_Basalt"
    },
    {
      "x": 15,
      "y": 11,
      "z": 22,
      "name": "Rock_Basalt"
    },
    {
      "x": 15,
      "y": 12,
      "z": 22,
      "name": "Rock_Basalt"
    },
    {
      "x": 15,
      "y": 13,
      "z": 22,
      "name": "Soil_Dirt_Burnt"
    },
    {
      "x": 15,
      "y": 14,
      "z": 22,
      "name": "Soil_Grass_Burnt"
    },
    {
      "x": 15,
      "y": 8,
      "z": 23,
      "name": "Rock_Basalt"
    },
    {
      "x": 15,
      "y": 9,
      "z": 23,
      "name": "Rock_Basalt"
    },
    {
      "x": 15,
      "y": 10,
      "z": 23,
      "name": "Rock_Basalt"
    },
    {
      "x": 15,
      "y": 11,
      "z": 23,
      "name": "Rock_Basalt"
    },
    {
      "x": 15,
      "y": 12,
      "z": 23,
      "name": "Soil_Dirt_Burnt"
    },
    {
      "x": 15,
      "y": 13,
      "z": 23,
      "name": "Soil_Dirt_Burnt"
    },
    {
      "x": 15,
      "y": 14,
      "z": 23,
      "name": "Soil_Grass_Burnt"
    },
    {
      "x": 15,
      "y": 15,
      "z": 23,
      "name": "Plant_Grass_Sharp"
    },
    {
      "x": 15,
      "y": 10,
      "z": 24,
      "name": "Rock_Basalt"
    },
    {
      "x": 15,
      "y": 11,
      "z": 24,
      "name": "Soil_Dirt_Burnt"
    },
    {
      "x": 15,
      "y": 12,
      "z": 24,
      "name": "Soil_Grass_Burnt"
    },
    {
      "x": 16,
      "y": 28,
      "z": 8,
      "name": "Plant_Leaves_Dead",
      "support": 15
    },
    {
      "x": 16,
      "y": 32,
      "z": 8,
      "name": "Plant_Leaves_Dead",
      "support": 15
    },
    {
      "x": 16,
      "y": 27,
      "z": 9,
      "name": "Plant_Leaves_Dead",
      "support": 15
    },
    {
      "x": 16,
      "y": 28,
      "z": 9,
      "name": "Plant_Leaves_Dead",
      "support": 15
    },
    {
      "x": 16,
      "y": 29,
      "z": 9,
      "name": "Plant_Leaves_Dead",
      "support": 15
    },
    {
      "x": 16,
      "y": 28,
      "z": 10,
      "name": "Plant_Leaves_Dead",
      "support": 15
    },
    {
      "x": 16,
      "y": 29,
      "z": 10,
      "name": "Plant_Leaves_Dead",
      "support": 15
    },
    {
      "x": 16,
      "y": 30,
      "z": 10,
      "name": "Plant_Leaves_Dead",
      "support": 15
    },
    {
      "x": 16,
      "y": 28,
      "z": 11,
      "name": "Wood_Ash_Trunk_Full",
      "support": 15
    },
    {
      "x": 16,
      "y": 29,
      "z": 11,
      "name": "Plant_Leaves_Dead",
      "support": 15
    },
    {
      "x": 16,
      "y": 30,
      "z": 11,
      "name": "Plant_Leaves_Dead",
      "support": 15
    },
    {
      "x": 16,
      "y": 27,
      "z": 12,
      "name": "Plant_Leaves_Dead",
      "support": 15
    },
    {
      "x": 16,
      "y": 28,
      "z": 12,
      "name": "Plant_Leaves_Dead",
      "support": 15
    },
    {
      "x": 16,
      "y": 29,
      "z": 12,
      "name": "Plant_Leaves_Dead",
      "support": 15
    },
    {
      "x": 16,
      "y": 27,
      "z": 13,
      "name": "Plant_Leaves_Dead",
      "support": 15
    },
    {
      "x": 16,
      "y": 28,
      "z": 13,
      "name": "Plant_Leaves_Dead",
      "support": 15
    },
    {
      "x": 16,
      "y": 27,
      "z": 15,
      "name": "Plant_Leaves_Dead",
      "support": 15
    },
    {
      "x": 16,
      "y": 25,
      "z": 16,
      "name": "Plant_Leaves_Dead",
      "support": 15
    },
    {
      "x": 16,
      "y": 26,
      "z": 16,
      "name": "Plant_Leaves_Dead",
      "support": 15
    },
    {
      "x": 16,
      "y": 27,
      "z": 16,
      "name": "Plant_Leaves_Dead",
      "support": 15
    },
    {
      "x": 16,
      "y": 28,
      "z": 16,
      "name": "Plant_Leaves_Dead",
      "support": 15
    },
    {
      "x": 16,
      "y": 29,
      "z": 16,
      "name": "Plant_Leaves_Dead",
      "support": 15
    },
    {
      "x": 16,
      "y": 14,
      "z": 17,
      "name": "Rock_Basalt"
    },
    {
      "x": 16,
      "y": 15,
      "z": 17,
      "name": "Soil_Dirt_Poisoned"
    },
    {
      "x": 16,
      "y": 16,
      "z": 17,
      "name": "Soil_Dirt_Poisoned"
    },
    {
      "x": 16,
      "y": 26,
      "z": 17,
      "name": "Plant_Leaves_Dead",
      "support": 15
    },
    {
      "x": 16,
      "y": 27,
      "z": 17,
      "name": "Plant_Leaves_Dead",
      "support": 15
    },
    {
      "x": 16,
      "y": 28,
      "z": 17,
      "name": "Plant_Leaves_Dead",
      "support": 15
    },
    {
      "x": 16,
      "y": 3,
      "z": 18,
      "name": "Rock_Basalt"
    },
    {
      "x": 16,
      "y": 13,
      "z": 18,
      "name": "Rock_Basalt"
    },
    {
      "x": 16,
      "y": 14,
      "z": 18,
      "name": "Soil_Dirt_Poisoned"
    },
    {
      "x": 16,
      "y": 15,
      "z": 18,
      "name": "Soil_Dirt_Poisoned"
    },
    {
      "x": 16,
      "y": 16,
      "z": 18,
      "name": "Soil_Dirt_Poisoned"
    },
    {
      "x": 16,
      "y": 17,
      "z": 18,
      "name": "Soil_Dirt_Poisoned"
    },
    {
      "x": 16,
      "y": 27,
      "z": 18,
      "name": "Plant_Leaves_Dead",
      "support": 15
    },
    {
      "x": 16,
      "y": 2,
      "z": 19,
      "name": "Rock_Basalt"
    },
    {
      "x": 16,
      "y": 3,
      "z": 19,
      "name": "Rock_Basalt"
    },
    {
      "x": 16,
      "y": 4,
      "z": 19,
      "name": "Rock_Basalt"
    },
    {
      "x": 16,
      "y": 5,
      "z": 19,
      "name": "Rock_Basalt"
    },
    {
      "x": 16,
      "y": 6,
      "z": 19,
      "name": "Rock_Basalt"
    },
    {
      "x": 16,
      "y": 7,
      "z": 19,
      "name": "Rock_Basalt"
    },
    {
      "x": 16,
      "y": 11,
      "z": 19,
      "name": "Rock_Basalt"
    },
    {
      "x": 16,
      "y": 12,
      "z": 19,
      "name": "Rock_Basalt"
    },
    {
      "x": 16,
      "y": 13,
      "z": 19,
      "name": "Rock_Basalt"
    },
    {
      "x": 16,
      "y": 14,
      "z": 19,
      "name": "Rock_Basalt"
    },
    {
      "x": 16,
      "y": 15,
      "z": 19,
      "name": "Soil_Dirt_Poisoned"
    },
    {
      "x": 16,
      "y": 16,
      "z": 19,
      "name": "Soil_Dirt_Poisoned"
    },
    {
      "x": 16,
      "y": 17,
      "z": 19,
      "name": "Soil_Dirt_Poisoned"
    },
    {
      "x": 16,
      "y": 2,
      "z": 20,
      "name": "Rock_Basalt"
    },
    {
      "x": 16,
      "y": 3,
      "z": 20,
      "name": "Rock_Basalt"
    },
    {
      "x": 16,
      "y": 4,
      "z": 20,
      "name": "Rock_Basalt"
    },
    {
      "x": 16,
      "y": 5,
      "z": 20,
      "name": "Rock_Basalt"
    },
    {
      "x": 16,
      "y": 6,
      "z": 20,
      "name": "Rock_Basalt"
    },
    {
      "x": 16,
      "y": 7,
      "z": 20,
      "name": "Rock_Basalt"
    },
    {
      "x": 16,
      "y": 8,
      "z": 20,
      "name": "Rock_Basalt"
    },
    {
      "x": 16,
      "y": 9,
      "z": 20,
      "name": "Rock_Basalt"
    },
    {
      "x": 16,
      "y": 10,
      "z": 20,
      "name": "Rock_Basalt"
    },
    {
      "x": 16,
      "y": 11,
      "z": 20,
      "name": "Rock_Basalt"
    },
    {
      "x": 16,
      "y": 12,
      "z": 20,
      "name": "Rock_Basalt"
    },
    {
      "x": 16,
      "y": 13,
      "z": 20,
      "name": "Rock_Basalt"
    },
    {
      "x": 16,
      "y": 14,
      "z": 20,
      "name": "Rock_Basalt"
    },
    {
      "x": 16,
      "y": 15,
      "z": 20,
      "name": "Rock_Basalt"
    },
    {
      "x": 16,
      "y": 16,
      "z": 20,
      "name": "Soil_Grass_Burnt"
    },
    {
      "x": 16,
      "y": 17,
      "z": 20,
      "name": "Plant_Grass_Sharp"
    },
    {
      "x": 16,
      "y": 3,
      "z": 21,
      "name": "Rock_Basalt"
    },
    {
      "x": 16,
      "y": 4,
      "z": 21,
      "name": "Rock_Basalt"
    },
    {
      "x": 16,
      "y": 5,
      "z": 21,
      "name": "Rock_Basalt"
    },
    {
      "x": 16,
      "y": 6,
      "z": 21,
      "name": "Rock_Basalt"
    },
    {
      "x": 16,
      "y": 7,
      "z": 21,
      "name": "Rock_Basalt"
    },
    {
      "x": 16,
      "y": 8,
      "z": 21,
      "name": "Rock_Basalt"
    },
    {
      "x": 16,
      "y": 9,
      "z": 21,
      "name": "Rock_Basalt"
    },
    {
      "x": 16,
      "y": 10,
      "z": 21,
      "name": "Rock_Basalt"
    },
    {
      "x": 16,
      "y": 11,
      "z": 21,
      "name": "Rock_Basalt"
    },
    {
      "x": 16,
      "y": 12,
      "z": 21,
      "name": "Rock_Basalt"
    },
    {
      "x": 16,
      "y": 13,
      "z": 21,
      "name": "Rock_Basalt"
    },
    {
      "x": 16,
      "y": 14,
      "z": 21,
      "name": "Rock_Basalt"
    },
    {
      "x": 16,
      "y": 15,
      "z": 21,
      "name": "Soil_Grass_Burnt"
    },
    {
      "x": 16,
      "y": 16,
      "z": 21,
      "name": "Plant_Grass_Sharp"
    },
    {
      "x": 16,
      "y": 6,
      "z": 22,
      "name": "Rock_Basalt"
    },
    {
      "x": 16,
      "y": 7,
      "z": 22,
      "name": "Rock_Basalt"
    },
    {
      "x": 16,
      "y": 8,
      "z": 22,
      "name": "Rock_Basalt"
    },
    {
      "x": 16,
      "y": 9,
      "z": 22,
      "name": "Rock_Basalt"
    },
    {
      "x": 16,
      "y": 10,
      "z": 22,
      "name": "Rock_Basalt"
    },
    {
      "x": 16,
      "y": 11,
      "z": 22,
      "name": "Rock_Basalt"
    },
    {
      "x": 16,
      "y": 12,
      "z": 22,
      "name": "Soil_Dirt_Burnt"
    },
    {
      "x": 16,
      "y": 13,
      "z": 22,
      "name": "Soil_Dirt_Burnt"
    },
    {
      "x": 16,
      "y": 14,
      "z": 22,
      "name": "Soil_Dirt_Burnt"
    },
    {
      "x": 16,
      "y": 15,
      "z": 22,
      "name": "Soil_Grass_Burnt"
    },
    {
      "x": 16,
      "y": 9,
      "z": 23,
      "name": "Rock_Basalt"
    },
    {
      "x": 16,
      "y": 10,
      "z": 23,
      "name": "Rock_Basalt"
    },
    {
      "x": 16,
      "y": 11,
      "z": 23,
      "name": "Soil_Dirt_Burnt"
    },
    {
      "x": 16,
      "y": 12,
      "z": 23,
      "name": "Soil_Dirt_Burnt"
    },
    {
      "x": 16,
      "y": 13,
      "z": 23,
      "name": "Soil_Dirt_Burnt"
    },
    {
      "x": 16,
      "y": 14,
      "z": 23,
      "name": "Soil_Grass_Burnt"
    },
    {
      "x": 16,
      "y": 15,
      "z": 23,
      "name": "Plant_Grass_Gnarled_Short"
    },
    {
      "x": 16,
      "y": 11,
      "z": 24,
      "name": "Soil_Dirt_Burnt"
    },
    {
      "x": 16,
      "y": 12,
      "z": 24,
      "name": "Soil_Dirt_Burnt"
    },
    {
      "x": 16,
      "y": 13,
      "z": 24,
      "name": "Soil_Grass_Burnt"
    },
    {
      "x": 16,
      "y": 14,
      "z": 24,
      "name": "Plant_Grass_Sharp"
    },
    {
      "x": 17,
      "y": 32,
      "z": 7,
      "name": "Plant_Leaves_Dead",
      "support": 15
    },
    {
      "x": 17,
      "y": 30,
      "z": 8,
      "name": "Plant_Leaves_Dead",
      "support": 15
    },
    {
      "x": 17,
      "y": 31,
      "z": 8,
      "name": "Plant_Leaves_Dead",
      "support": 15
    },
    {
      "x": 17,
      "y": 32,
      "z": 8,
      "name": "Plant_Leaves_Dead",
      "support": 15
    },
    {
      "x": 17,
      "y": 33,
      "z": 8,
      "name": "Plant_Leaves_Dead",
      "support": 15
    },
    {
      "x": 17,
      "y": 27,
      "z": 9,
      "name": "Plant_Leaves_Dead",
      "support": 15
    },
    {
      "x": 17,
      "y": 28,
      "z": 9,
      "name": "Plant_Leaves_Dead",
      "support": 15
    },
    {
      "x": 17,
      "y": 29,
      "z": 9,
      "name": "Plant_Leaves_Dead",
      "support": 15
    },
    {
      "x": 17,
      "y": 31,
      "z": 9,
      "name": "Plant_Leaves_Dead",
      "support": 15
    },
    {
      "x": 17,
      "y": 32,
      "z": 9,
      "name": "Plant_Leaves_Dead",
      "support": 15
    },
    {
      "x": 17,
      "y": 33,
      "z": 9,
      "name": "Plant_Leaves_Dead",
      "support": 15
    },
    {
      "x": 17,
      "y": 28,
      "z": 10,
      "name": "Plant_Leaves_Dead",
      "support": 15
    },
    {
      "x": 17,
      "y": 31,
      "z": 10,
      "name": "Plant_Leaves_Dead",
      "support": 15
    },
    {
      "x": 17,
      "y": 28,
      "z": 11,
      "name": "Wood_Ash_Trunk_Full",
      "support": 15
    },
    {
      "x": 17,
      "y": 29,
      "z": 11,
      "name": "Plant_Leaves_Dead",
      "support": 15
    },
    {
      "x": 17,
      "y": 30,
      "z": 11,
      "name": "Plant_Leaves_Dead",
      "support": 15
    },
    {
      "x": 17,
      "y": 31,
      "z": 11,
      "name": "Plant_Leaves_Dead",
      "support": 15
    },
    {
      "x": 17,
      "y": 32,
      "z": 11,
      "name": "Plant_Leaves_Dead",
      "support": 15
    },
    {
      "x": 17,
      "y": 28,
      "z": 12,
      "name": "Plant_Leaves_Dead",
      "support": 15
    },
    {
      "x": 17,
      "y": 29,
      "z": 12,
      "name": "Plant_Leaves_Dead",
      "support": 15
    },
    {
      "x": 17,
      "y": 31,
      "z": 12,
      "name": "Plant_Leaves_Dead",
      "support": 15
    },
    {
      "x": 17,
      "y": 32,
      "z": 12,
      "name": "Plant_Leaves_Dead",
      "support": 15
    },
    {
      "x": 17,
      "y": 33,
      "z": 12,
      "name": "Plant_Leaves_Dead",
      "support": 15
    },
    {
      "x": 17,
      "y": 26,
      "z": 13,
      "name": "Plant_Leaves_Dead",
      "support": 15
    },
    {
      "x": 17,
      "y": 27,
      "z": 13,
      "name": "Plant_Leaves_Dead",
      "support": 15
    },
    {
      "x": 17,
      "y": 28,
      "z": 13,
      "name": "Plant_Leaves_Dead",
      "support": 15
    },
    {
      "x": 17,
      "y": 31,
      "z": 13,
      "name": "Plant_Leaves_Dead",
      "support": 15
    },
    {
      "x": 17,
      "y": 32,
      "z": 13,
      "name": "Plant_Leaves_Dead",
      "support": 15
    },
    {
      "x": 17,
      "y": 28,
      "z": 14,
      "name": "Plant_Leaves_Dead",
      "support": 15
    },
    {
      "x": 17,
      "y": 25,
      "z": 15,
      "name": "Plant_Leaves_Dead",
      "support": 15
    },
    {
      "x": 17,
      "y": 26,
      "z": 15,
      "name": "Plant_Leaves_Dead",
      "support": 15
    },
    {
      "x": 17,
      "y": 27,
      "z": 15,
      "name": "Plant_Leaves_Dead",
      "support": 15
    },
    {
      "x": 17,
      "y": 28,
      "z": 15,
      "name": "Plant_Leaves_Dead",
      "support": 15
    },
    {
      "x": 17,
      "y": 14,
      "z": 16,
      "name": "Rock_Basalt"
    },
    {
      "x": 17,
      "y": 15,
      "z": 16,
      "name": "Rock_Basalt"
    },
    {
      "x": 17,
      "y": 16,
      "z": 16,
      "name": "Rock_Basalt"
    },
    {
      "x": 17,
      "y": 17,
      "z": 16,
      "name": "Soil_Dirt_Burnt"
    },
    {
      "x": 17,
      "y": 27,
      "z": 16,
      "name": "Plant_Leaves_Dead",
      "support": 15
    },
    {
      "x": 17,
      "y": 28,
      "z": 16,
      "name": "Plant_Leaves_Dead",
      "support": 15
    },
    {
      "x": 17,
      "y": 29,
      "z": 16,
      "name": "Plant_Leaves_Dead",
      "support": 15
    },
    {
      "x": 17,
      "y": 0,
      "z": 17,
      "name": "Rock_Basalt"
    },
    {
      "x": 17,
      "y": 1,
      "z": 17,
      "name": "Rock_Basalt"
    },
    {
      "x": 17,
      "y": 2,
      "z": 17,
      "name": "Rock_Basalt"
    },
    {
      "x": 17,
      "y": 3,
      "z": 17,
      "name": "Rock_Basalt"
    },
    {
      "x": 17,
      "y": 14,
      "z": 17,
      "name": "Rock_Basalt"
    },
    {
      "x": 17,
      "y": 15,
      "z": 17,
      "name": "Rock_Basalt"
    },
    {
      "x": 17,
      "y": 16,
      "z": 17,
      "name": "Rock_Basalt"
    },
    {
      "x": 17,
      "y": 17,
      "z": 17,
      "name": "Rock_Basalt"
    },
    {
      "x": 17,
      "y": 18,
      "z": 17,
      "name": "Soil_Dirt_Burnt"
    },
    {
      "x": 17,
      "y": 26,
      "z": 17,
      "name": "Plant_Leaves_Dead",
      "support": 15
    },
    {
      "x": 17,
      "y": 27,
      "z": 17,
      "name": "Wood_Ash_Trunk_Full",
      "support": 15
    },
    {
      "x": 17,
      "y": 28,
      "z": 17,
      "name": "Plant_Leaves_Dead",
      "support": 15
    },
    {
      "x": 17,
      "y": 29,
      "z": 17,
      "name": "Plant_Leaves_Dead",
      "support": 15
    },
    {
      "x": 17,
      "y": 1,
      "z": 18,
      "name": "Rock_Basalt"
    },
    {
      "x": 17,
      "y": 2,
      "z": 18,
      "name": "Rock_Basalt"
    },
    {
      "x": 17,
      "y": 3,
      "z": 18,
      "name": "Rock_Basalt"
    },
    {
      "x": 17,
      "y": 13,
      "z": 18,
      "name": "Rock_Basalt"
    },
    {
      "x": 17,
      "y": 14,
      "z": 18,
      "name": "Rock_Basalt"
    },
    {
      "x": 17,
      "y": 15,
      "z": 18,
      "name": "Soil_Dirt_Poisoned"
    },
    {
      "x": 17,
      "y": 16,
      "z": 18,
      "name": "Soil_Dirt_Poisoned"
    },
    {
      "x": 17,
      "y": 17,
      "z": 18,
      "name": "Soil_Dirt_Poisoned"
    },
    {
      "x": 17,
      "y": 18,
      "z": 18,
      "name": "Soil_Dirt_Poisoned"
    },
    {
      "x": 17,
      "y": 19,
      "z": 18,
      "name": "Plant_Crop_Mushroom_Cap_Brown",
      "components": {
        "Components": {
          "FarmingBlock": {}
        }
      }
    },
    {
      "x": 17,
      "y": 25,
      "z": 18,
      "name": "Plant_Leaves_Dead",
      "support": 15
    },
    {
      "x": 17,
      "y": 26,
      "z": 18,
      "name": "Plant_Leaves_Dead",
      "support": 15
    },
    {
      "x": 17,
      "y": 27,
      "z": 18,
      "name": "Plant_Leaves_Dead",
      "support": 15
    },
    {
      "x": 17,
      "y": 28,
      "z": 18,
      "name": "Plant_Leaves_Dead",
      "support": 15
    },
    {
      "x": 17,
      "y": 1,
      "z": 19,
      "name": "Rock_Basalt"
    },
    {
      "x": 17,
      "y": 2,
      "z": 19,
      "name": "Rock_Basalt"
    },
    {
      "x": 17,
      "y": 3,
      "z": 19,
      "name": "Rock_Basalt"
    },
    {
      "x": 17,
      "y": 4,
      "z": 19,
      "name": "Rock_Basalt"
    },
    {
      "x": 17,
      "y": 5,
      "z": 19,
      "name": "Rock_Basalt"
    },
    {
      "x": 17,
      "y": 12,
      "z": 19,
      "name": "Rock_Basalt"
    },
    {
      "x": 17,
      "y": 13,
      "z": 19,
      "name": "Rock_Basalt"
    },
    {
      "x": 17,
      "y": 14,
      "z": 19,
      "name": "Soil_Dirt_Poisoned"
    },
    {
      "x": 17,
      "y": 15,
      "z": 19,
      "name": "Soil_Dirt_Poisoned"
    },
    {
      "x": 17,
      "y": 16,
      "z": 19,
      "name": "Soil_Dirt_Poisoned"
    },
    {
      "x": 17,
      "y": 17,
      "z": 19,
      "name": "Soil_Dirt_Poisoned"
    },
    {
      "x": 17,
      "y": 2,
      "z": 20,
      "name": "Rock_Basalt"
    },
    {
      "x": 17,
      "y": 3,
      "z": 20,
      "name": "Rock_Basalt"
    },
    {
      "x": 17,
      "y": 4,
      "z": 20,
      "name": "Rock_Basalt"
    },
    {
      "x": 17,
      "y": 5,
      "z": 20,
      "name": "Rock_Basalt"
    },
    {
      "x": 17,
      "y": 6,
      "z": 20,
      "name": "Rock_Basalt"
    },
    {
      "x": 17,
      "y": 10,
      "z": 20,
      "name": "Rock_Basalt"
    },
    {
      "x": 17,
      "y": 11,
      "z": 20,
      "name": "Rock_Basalt"
    },
    {
      "x": 17,
      "y": 12,
      "z": 20,
      "name": "Rock_Basalt"
    },
    {
      "x": 17,
      "y": 13,
      "z": 20,
      "name": "Rock_Basalt"
    },
    {
      "x": 17,
      "y": 14,
      "z": 20,
      "name": "Rock_Basalt"
    },
    {
      "x": 17,
      "y": 15,
      "z": 20,
      "name": "Soil_Dirt_Poisoned"
    },
    {
      "x": 17,
      "y": 16,
      "z": 20,
      "name": "Soil_Dirt_Poisoned"
    },
    {
      "x": 17,
      "y": 17,
      "z": 20,
      "name": "Soil_Dirt_Poisoned"
    },
    {
      "x": 17,
      "y": 3,
      "z": 21,
      "name": "Rock_Basalt"
    },
    {
      "x": 17,
      "y": 4,
      "z": 21,
      "name": "Rock_Basalt"
    },
    {
      "x": 17,
      "y": 5,
      "z": 21,
      "name": "Rock_Basalt"
    },
    {
      "x": 17,
      "y": 6,
      "z": 21,
      "name": "Rock_Basalt"
    },
    {
      "x": 17,
      "y": 10,
      "z": 21,
      "name": "Rock_Basalt"
    },
    {
      "x": 17,
      "y": 11,
      "z": 21,
      "name": "Rock_Basalt"
    },
    {
      "x": 17,
      "y": 12,
      "z": 21,
      "name": "Rock_Basalt"
    },
    {
      "x": 17,
      "y": 13,
      "z": 21,
      "name": "Rock_Basalt"
    },
    {
      "x": 17,
      "y": 14,
      "z": 21,
      "name": "Rock_Basalt"
    },
    {
      "x": 17,
      "y": 15,
      "z": 21,
      "name": "Soil_Dirt_Burnt"
    },
    {
      "x": 17,
      "y": 16,
      "z": 21,
      "name": "Soil_Grass_Burnt"
    },
    {
      "x": 17,
      "y": 17,
      "z": 21,
      "name": "Plant_Grass_Sharp"
    },
    {
      "x": 17,
      "y": 11,
      "z": 22,
      "name": "Rock_Basalt"
    },
    {
      "x": 17,
      "y": 12,
      "z": 22,
      "name": "Rock_Basalt"
    },
    {
      "x": 17,
      "y": 13,
      "z": 22,
      "name": "Soil_Dirt_Burnt"
    },
    {
      "x": 17,
      "y": 14,
      "z": 22,
      "name": "Soil_Dirt_Burnt"
    },
    {
      "x": 17,
      "y": 15,
      "z": 22,
      "name": "Soil_Dirt_Burnt"
    },
    {
      "x": 17,
      "y": 16,
      "z": 22,
      "name": "Soil_Grass_Burnt"
    },
    {
      "x": 17,
      "y": 17,
      "z": 22,
      "name": "Plant_Crop_Mushroom_Cap_Brown",
      "components": {
        "Components": {
          "FarmingBlock": {}
        }
      }
    },
    {
      "x": 17,
      "y": 11,
      "z": 23,
      "name": "Rock_Basalt"
    },
    {
      "x": 17,
      "y": 12,
      "z": 23,
      "name": "Soil_Dirt_Burnt"
    },
    {
      "x": 17,
      "y": 13,
      "z": 23,
      "name": "Soil_Dirt_Burnt"
    },
    {
      "x": 17,
      "y": 14,
      "z": 23,
      "name": "Soil_Grass_Burnt"
    },
    {
      "x": 17,
      "y": 15,
      "z": 23,
      "name": "Plant_Grass_Gnarled"
    },
    {
      "x": 18,
      "y": 31,
      "z": 7,
      "name": "Plant_Leaves_Dead",
      "support": 15
    },
    {
      "x": 18,
      "y": 32,
      "z": 7,
      "name": "Plant_Leaves_Dead",
      "support": 15
    },
    {
      "x": 18,
      "y": 33,
      "z": 7,
      "name": "Plant_Leaves_Dead",
      "support": 15
    },
    {
      "x": 18,
      "y": 28,
      "z": 8,
      "name": "Plant_Leaves_Dead",
      "support": 15
    },
    {
      "x": 18,
      "y": 30,
      "z": 8,
      "name": "Plant_Leaves_Dead",
      "support": 15
    },
    {
      "x": 18,
      "y": 31,
      "z": 8,
      "name": "Plant_Leaves_Dead",
      "support": 15
    },
    {
      "x": 18,
      "y": 32,
      "z": 8,
      "name": "Wood_Ash_Trunk_Full",
      "support": 15
    },
    {
      "x": 18,
      "y": 33,
      "z": 8,
      "name": "Plant_Leaves_Dead",
      "support": 15
    },
    {
      "x": 18,
      "y": 28,
      "z": 9,
      "name": "Plant_Leaves_Dead",
      "support": 15
    },
    {
      "x": 18,
      "y": 32,
      "z": 9,
      "name": "Plant_Leaves_Dead",
      "support": 15
    },
    {
      "x": 18,
      "y": 33,
      "z": 9,
      "name": "Plant_Leaves_Dead",
      "support": 15
    },
    {
      "x": 18,
      "y": 28,
      "z": 10,
      "name": "Plant_Leaves_Dead",
      "support": 15
    },
    {
      "x": 18,
      "y": 32,
      "z": 10,
      "name": "Plant_Leaves_Dead",
      "support": 15
    },
    {
      "x": 18,
      "y": 28,
      "z": 11,
      "name": "Wood_Ash_Trunk_Full",
      "support": 15
    },
    {
      "x": 18,
      "y": 31,
      "z": 11,
      "name": "Plant_Leaves_Dead",
      "support": 15
    },
    {
      "x": 18,
      "y": 32,
      "z": 11,
      "name": "Plant_Leaves_Dead",
      "support": 15
    },
    {
      "x": 18,
      "y": 33,
      "z": 11,
      "name": "Plant_Leaves_Dead",
      "support": 15
    },
    {
      "x": 18,
      "y": 31,
      "z": 12,
      "name": "Plant_Leaves_Dead",
      "support": 15
    },
    {
      "x": 18,
      "y": 32,
      "z": 12,
      "name": "Wood_Ash_Trunk_Full",
      "support": 15
    },
    {
      "x": 18,
      "y": 33,
      "z": 12,
      "name": "Plant_Leaves_Dead",
      "support": 15
    },
    {
      "x": 18,
      "y": 31,
      "z": 13,
      "name": "Plant_Leaves_Dead",
      "support": 15
    },
    {
      "x": 18,
      "y": 32,
      "z": 13,
      "name": "Plant_Leaves_Dead",
      "support": 15
    },
    {
      "x": 18,
      "y": 33,
      "z": 13,
      "name": "Plant_Leaves_Dead",
      "support": 15
    },
    {
      "x": 18,
      "y": 30,
      "z": 14,
      "name": "Plant_Leaves_Dead",
      "support": 15
    },
    {
      "x": 18,
      "y": 31,
      "z": 14,
      "name": "Plant_Leaves_Dead",
      "support": 15
    },
    {
      "x": 18,
      "y": 32,
      "z": 14,
      "name": "Plant_Leaves_Dead",
      "support": 15
    },
    {
      "x": 18,
      "y": 16,
      "z": 15,
      "name": "Soil_Dirt_Burnt"
    },
    {
      "x": 18,
      "y": 17,
      "z": 15,
      "name": "Soil_Dirt_Burnt"
    },
    {
      "x": 18,
      "y": 18,
      "z": 15,
      "name": "Soil_Grass_Burnt"
    },
    {
      "x": 18,
      "y": 19,
      "z": 15,
      "name": "Plant_Grass_Sharp"
    },
    {
      "x": 18,
      "y": 28,
      "z": 15,
      "name": "Plant_Leaves_Dead",
      "support": 15
    },
    {
      "x": 18,
      "y": 31,
      "z": 15,
      "name": "Plant_Leaves_Dead",
      "support": 15
    },
    {
      "x": 18,
      "y": 14,
      "z": 16,
      "name": "Rock_Basalt"
    },
    {
      "x": 18,
      "y": 15,
      "z": 16,
      "name": "Rock_Basalt"
    },
    {
      "x": 18,
      "y": 16,
      "z": 16,
      "name": "Soil_Dirt_Burnt"
    },
    {
      "x": 18,
      "y": 17,
      "z": 16,
      "name": "Soil_Dirt_Burnt"
    },
    {
      "x": 18,
      "y": 18,
      "z": 16,
      "name": "Soil_Dirt_Burnt"
    },
    {
      "x": 18,
      "y": 19,
      "z": 16,
      "name": "Soil_Grass_Burnt"
    },
    {
      "x": 18,
      "y": 20,
      "z": 16,
      "name": "Plant_Crop_Mushroom_Cap_Green",
      "components": {
        "Components": {
          "FarmingBlock": {}
        }
      }
    },
    {
      "x": 18,
      "y": 27,
      "z": 16,
      "name": "Wood_Ash_Trunk_Full",
      "support": 15
    },
    {
      "x": 18,
      "y": 0,
      "z": 17,
      "name": "Rock_Basalt"
    },
    {
      "x": 18,
      "y": 1,
      "z": 17,
      "name": "Rock_Basalt"
    },
    {
      "x": 18,
      "y": 14,
      "z": 17,
      "name": "Rock_Basalt"
    },
    {
      "x": 18,
      "y": 15,
      "z": 17,
      "name": "Rock_Basalt"
    },
    {
      "x": 18,
      "y": 16,
      "z": 17,
      "name": "Rock_Basalt"
    },
    {
      "x": 18,
      "y": 17,
      "z": 17,
      "name": "Soil_Dirt_Burnt"
    },
    {
      "x": 18,
      "y": 18,
      "z": 17,
      "name": "Soil_Dirt_Burnt"
    },
    {
      "x": 18,
      "y": 19,
      "z": 17,
      "name": "Soil_Grass_Burnt"
    },
    {
      "x": 18,
      "y": 27,
      "z": 17,
      "name": "Wood_Ash_Trunk_Full",
      "support": 15
    },
    {
      "x": 18,
      "y": 28,
      "z": 17,
      "name": "Plant_Leaves_Dead",
      "support": 15
    },
    {
      "x": 18,
      "y": 29,
      "z": 17,
      "name": "Plant_Leaves_Dead",
      "support": 15
    },
    {
      "x": 18,
      "y": 0,
      "z": 18,
      "name": "Rock_Basalt"
    },
    {
      "x": 18,
      "y": 1,
      "z": 18,
      "name": "Rock_Basalt"
    },
    {
      "x": 18,
      "y": 2,
      "z": 18,
      "name": "Rock_Basalt"
    },
    {
      "x": 18,
      "y": 13,
      "z": 18,
      "name": "Rock_Basalt"
    },
    {
      "x": 18,
      "y": 14,
      "z": 18,
      "name": "Rock_Basalt"
    },
    {
      "x": 18,
      "y": 15,
      "z": 18,
      "name": "Rock_Basalt"
    },
    {
      "x": 18,
      "y": 16,
      "z": 18,
      "name": "Rock_Basalt"
    },
    {
      "x": 18,
      "y": 17,
      "z": 18,
      "name": "Rock_Basalt"
    },
    {
      "x": 18,
      "y": 18,
      "z": 18,
      "name": "Rock_Basalt"
    },
    {
      "x": 18,
      "y": 19,
      "z": 18,
      "name": "Soil_Grass_Burnt"
    },
    {
      "x": 18,
      "y": 20,
      "z": 18,
      "name": "Plant_Grass_Sharp"
    },
    {
      "x": 18,
      "y": 25,
      "z": 18,
      "name": "Plant_Leaves_Dead",
      "support": 15
    },
    {
      "x": 18,
      "y": 26,
      "z": 18,
      "name": "Plant_Leaves_Dead",
      "support": 15
    },
    {
      "x": 18,
      "y": 27,
      "z": 18,
      "name": "Plant_Leaves_Dead",
      "support": 15
    },
    {
      "x": 18,
      "y": 28,
      "z": 18,
      "name": "Plant_Leaves_Dead",
      "support": 15
    },
    {
      "x": 18,
      "y": 0,
      "z": 19,
      "name": "Rock_Basalt"
    },
    {
      "x": 18,
      "y": 1,
      "z": 19,
      "name": "Rock_Basalt"
    },
    {
      "x": 18,
      "y": 2,
      "z": 19,
      "name": "Rock_Basalt"
    },
    {
      "x": 18,
      "y": 12,
      "z": 19,
      "name": "Rock_Basalt"
    },
    {
      "x": 18,
      "y": 13,
      "z": 19,
      "name": "Rock_Basalt"
    },
    {
      "x": 18,
      "y": 14,
      "z": 19,
      "name": "Rock_Basalt"
    },
    {
      "x": 18,
      "y": 15,
      "z": 19,
      "name": "Soil_Dirt_Poisoned"
    },
    {
      "x": 18,
      "y": 16,
      "z": 19,
      "name": "Soil_Dirt_Poisoned"
    },
    {
      "x": 18,
      "y": 17,
      "z": 19,
      "name": "Soil_Dirt_Poisoned"
    },
    {
      "x": 18,
      "y": 26,
      "z": 19,
      "name": "Plant_Leaves_Dead",
      "support": 15
    },
    {
      "x": 18,
      "y": 27,
      "z": 19,
      "name": "Plant_Leaves_Dead",
      "support": 15
    },
    {
      "x": 18,
      "y": 1,
      "z": 20,
      "name": "Rock_Basalt"
    },
    {
      "x": 18,
      "y": 2,
      "z": 20,
      "name": "Rock_Basalt"
    },
    {
      "x": 18,
      "y": 3,
      "z": 20,
      "name": "Rock_Basalt"
    },
    {
      "x": 18,
      "y": 4,
      "z": 20,
      "name": "Rock_Basalt"
    },
    {
      "x": 18,
      "y": 12,
      "z": 20,
      "name": "Rock_Basalt"
    },
    {
      "x": 18,
      "y": 13,
      "z": 20,
      "name": "Rock_Basalt"
    },
    {
      "x": 18,
      "y": 14,
      "z": 20,
      "name": "Rock_Basalt"
    },
    {
      "x": 18,
      "y": 15,
      "z": 20,
      "name": "Soil_Dirt_Burnt"
    },
    {
      "x": 18,
      "y": 16,
      "z": 20,
      "name": "Soil_Dirt_Burnt"
    },
    {
      "x": 18,
      "y": 17,
      "z": 20,
      "name": "Soil_Grass_Burnt"
    },
    {
      "x": 18,
      "y": 18,
      "z": 20,
      "name": "Plant_Grass_Sharp"
    },
    {
      "x": 18,
      "y": 12,
      "z": 21,
      "name": "Rock_Basalt"
    },
    {
      "x": 18,
      "y": 13,
      "z": 21,
      "name": "Rock_Basalt"
    },
    {
      "x": 18,
      "y": 14,
      "z": 21,
      "name": "Soil_Dirt_Burnt"
    },
    {
      "x": 18,
      "y": 15,
      "z": 21,
      "name": "Soil_Dirt_Burnt"
    },
    {
      "x": 18,
      "y": 16,
      "z": 21,
      "name": "Soil_Dirt_Burnt"
    },
    {
      "x": 18,
      "y": 17,
      "z": 21,
      "name": "Soil_Grass_Burnt"
    },
    {
      "x": 18,
      "y": 13,
      "z": 22,
      "name": "Soil_Dirt_Burnt"
    },
    {
      "x": 18,
      "y": 14,
      "z": 22,
      "name": "Soil_Dirt_Burnt"
    },
    {
      "x": 18,
      "y": 15,
      "z": 22,
      "name": "Soil_Dirt_Burnt"
    },
    {
      "x": 18,
      "y": 16,
      "z": 22,
      "name": "Soil_Grass_Burnt"
    },
    {
      "x": 18,
      "y": 17,
      "z": 22,
      "name": "Plant_Grass_Gnarled"
    },
    {
      "x": 18,
      "y": 14,
      "z": 23,
      "name": "Soil_Grass_Burnt"
    },
    {
      "x": 19,
      "y": 32,
      "z": 6,
      "name": "Plant_Leaves_Dead",
      "support": 15
    },
    {
      "x": 19,
      "y": 26,
      "z": 7,
      "name": "Plant_Leaves_Dead",
      "support": 15
    },
    {
      "x": 19,
      "y": 27,
      "z": 7,
      "name": "Plant_Leaves_Dead",
      "support": 15
    },
    {
      "x": 19,
      "y": 28,
      "z": 7,
      "name": "Plant_Leaves_Dead",
      "support": 15
    },
    {
      "x": 19,
      "y": 29,
      "z": 7,
      "name": "Plant_Leaves_Dead",
      "support": 15
    },
    {
      "x": 19,
      "y": 30,
      "z": 7,
      "name": "Plant_Leaves_Dead",
      "support": 15
    },
    {
      "x": 19,
      "y": 31,
      "z": 7,
      "name": "Plant_Leaves_Dead",
      "support": 15
    },
    {
      "x": 19,
      "y": 32,
      "z": 7,
      "name": "Plant_Leaves_Dead",
      "support": 15
    },
    {
      "x": 19,
      "y": 33,
      "z": 7,
      "name": "Plant_Leaves_Dead",
      "support": 15
    },
    {
      "x": 19,
      "y": 27,
      "z": 8,
      "name": "Plant_Leaves_Dead",
      "support": 15
    },
    {
      "x": 19,
      "y": 28,
      "z": 8,
      "name": "Plant_Leaves_Dead",
      "support": 15
    },
    {
      "x": 19,
      "y": 29,
      "z": 8,
      "name": "Plant_Leaves_Dead",
      "support": 15
    },
    {
      "x": 19,
      "y": 32,
      "z": 8,
      "name": "Wood_Ash_Trunk_Full",
      "support": 15
    },
    {
      "x": 19,
      "y": 34,
      "z": 8,
      "name": "Plant_Leaves_Dead",
      "support": 15
    },
    {
      "x": 19,
      "y": 33,
      "z": 9,
      "name": "Plant_Leaves_Dead",
      "support": 15
    },
    {
      "x": 19,
      "y": 34,
      "z": 9,
      "name": "Plant_Leaves_Dead",
      "support": 15
    },
    {
      "x": 19,
      "y": 34,
      "z": 10,
      "name": "Plant_Leaves_Dead",
      "support": 15
    },
    {
      "x": 19,
      "y": 28,
      "z": 11,
      "name": "Wood_Ash_Trunk_Full",
      "support": 15
    },
    {
      "x": 19,
      "y": 32,
      "z": 11,
      "name": "Plant_Leaves_Dead",
      "support": 15
    },
    {
      "x": 19,
      "y": 32,
      "z": 12,
      "name": "Wood_Ash_Trunk_Full",
      "support": 15
    },
    {
      "x": 19,
      "y": 33,
      "z": 12,
      "name": "Plant_Leaves_Dead",
      "support": 15
    },
    {
      "x": 19,
      "y": 32,
      "z": 13,
      "name": "Plant_Leaves_Dead",
      "support": 15
    },
    {
      "x": 19,
      "y": 33,
      "z": 13,
      "name": "Plant_Leaves_Dead",
      "support": 15
    },
    {
      "x": 19,
      "y": 15,
      "z": 14,
      "name": "Rock_Basalt"
    },
    {
      "x": 19,
      "y": 16,
      "z": 14,
      "name": "Soil_Grass_Burnt"
    },
    {
      "x": 19,
      "y": 32,
      "z": 14,
      "name": "Plant_Leaves_Dead",
      "support": 15
    },
    {
      "x": 19,
      "y": 33,
      "z": 14,
      "name": "Plant_Leaves_Dead",
      "support": 15
    },
    {
      "x": 19,
      "y": 15,
      "z": 15,
      "name": "Rock_Basalt"
    },
    {
      "x": 19,
      "y": 16,
      "z": 15,
      "name": "Soil_Dirt_Burnt"
    },
    {
      "x": 19,
      "y": 17,
      "z": 15,
      "name": "Soil_Dirt_Burnt"
    },
    {
      "x": 19,
      "y": 18,
      "z": 15,
      "name": "Soil_Dirt_Burnt"
    },
    {
      "x": 19,
      "y": 19,
      "z": 15,
      "name": "Soil_Grass_Burnt"
    },
    {
      "x": 19,
      "y": 20,
      "z": 15,
      "name": "Plant_Grass_Sharp"
    },
    {
      "x": 19,
      "y": 32,
      "z": 15,
      "name": "Plant_Leaves_Dead",
      "support": 15
    },
    {
      "x": 19,
      "y": 14,
      "z": 16,
      "name": "Rock_Basalt"
    },
    {
      "x": 19,
      "y": 15,
      "z": 16,
      "name": "Rock_Basalt"
    },
    {
      "x": 19,
      "y": 16,
      "z": 16,
      "name": "Rock_Basalt"
    },
    {
      "x": 19,
      "y": 17,
      "z": 16,
      "name": "Soil_Dirt_Burnt"
    },
    {
      "x": 19,
      "y": 18,
      "z": 16,
      "name": "Soil_Dirt_Burnt"
    },
    {
      "x": 19,
      "y": 19,
      "z": 16,
      "name": "Soil_Grass_Burnt"
    },
    {
      "x": 19,
      "y": 20,
      "z": 16,
      "name": "Plant_Grass_Gnarled"
    },
    {
      "x": 19,
      "y": 27,
      "z": 16,
      "name": "Wood_Ash_Trunk_Full",
      "support": 15
    },
    {
      "x": 19,
      "y": 14,
      "z": 17,
      "name": "Rock_Basalt"
    },
    {
      "x": 19,
      "y": 15,
      "z": 17,
      "name": "Rock_Basalt"
    },
    {
      "x": 19,
      "y": 16,
      "z": 17,
      "name": "Rock_Basalt"
    },
    {
      "x": 19,
      "y": 17,
      "z": 17,
      "name": "Rock_Basalt"
    },
    {
      "x": 19,
      "y": 18,
      "z": 17,
      "name": "Soil_Dirt_Poisoned"
    },
    {
      "x": 19,
      "y": 19,
      "z": 17,
      "name": "Soil_Dirt_Poisoned"
    },
    {
      "x": 19,
      "y": 0,
      "z": 18,
      "name": "Rock_Basalt"
    },
    {
      "x": 19,
      "y": 13,
      "z": 18,
      "name": "Rock_Basalt"
    },
    {
      "x": 19,
      "y": 14,
      "z": 18,
      "name": "Rock_Basalt"
    },
    {
      "x": 19,
      "y": 15,
      "z": 18,
      "name": "Rock_Basalt"
    },
    {
      "x": 19,
      "y": 16,
      "z": 18,
      "name": "Soil_Dirt_Poisoned"
    },
    {
      "x": 19,
      "y": 17,
      "z": 18,
      "name": "Soil_Dirt_Poisoned"
    },
    {
      "x": 19,
      "y": 18,
      "z": 18,
      "name": "Soil_Dirt_Poisoned"
    },
    {
      "x": 19,
      "y": 19,
      "z": 18,
      "name": "Soil_Dirt_Poisoned"
    },
    {
      "x": 19,
      "y": 20,
      "z": 18,
      "name": "Plant_Crop_Mushroom_Cap_Brown",
      "components": {
        "Components": {
          "FarmingBlock": {}
        }
      }
    },
    {
      "x": 19,
      "y": 28,
      "z": 18,
      "name": "Plant_Leaves_Dead",
      "support": 15
    },
    {
      "x": 19,
      "y": 0,
      "z": 19,
      "name": "Rock_Basalt"
    },
    {
      "x": 19,
      "y": 1,
      "z": 19,
      "name": "Rock_Basalt"
    },
    {
      "x": 19,
      "y": 12,
      "z": 19,
      "name": "Rock_Basalt"
    },
    {
      "x": 19,
      "y": 13,
      "z": 19,
      "name": "Rock_Basalt"
    },
    {
      "x": 19,
      "y": 14,
      "z": 19,
      "name": "Rock_Basalt"
    },
    {
      "x": 19,
      "y": 15,
      "z": 19,
      "name": "Soil_Dirt_Poisoned"
    },
    {
      "x": 19,
      "y": 16,
      "z": 19,
      "name": "Soil_Dirt_Poisoned"
    },
    {
      "x": 19,
      "y": 17,
      "z": 19,
      "name": "Soil_Dirt_Poisoned"
    },
    {
      "x": 19,
      "y": 18,
      "z": 19,
      "name": "Soil_Dirt_Poisoned"
    },
    {
      "x": 19,
      "y": 12,
      "z": 20,
      "name": "Rock_Basalt"
    },
    {
      "x": 19,
      "y": 13,
      "z": 20,
      "name": "Rock_Basalt"
    },
    {
      "x": 19,
      "y": 14,
      "z": 20,
      "name": "Soil_Dirt_Burnt"
    },
    {
      "x": 19,
      "y": 15,
      "z": 20,
      "name": "Soil_Dirt_Burnt"
    },
    {
      "x": 19,
      "y": 16,
      "z": 20,
      "name": "Soil_Dirt_Poisoned"
    },
    {
      "x": 19,
      "y": 17,
      "z": 20,
      "name": "Soil_Dirt_Poisoned"
    },
    {
      "x": 19,
      "y": 18,
      "z": 20,
      "name": "Soil_Dirt_Poisoned"
    },
    {
      "x": 19,
      "y": 13,
      "z": 21,
      "name": "Soil_Dirt_Burnt"
    },
    {
      "x": 19,
      "y": 14,
      "z": 21,
      "name": "Soil_Dirt_Burnt"
    },
    {
      "x": 19,
      "y": 15,
      "z": 21,
      "name": "Soil_Dirt_Burnt"
    },
    {
      "x": 19,
      "y": 16,
      "z": 21,
      "name": "Soil_Dirt_Burnt"
    },
    {
      "x": 19,
      "y": 17,
      "z": 21,
      "name": "Soil_Grass_Burnt"
    },
    {
      "x": 19,
      "y": 18,
      "z": 21,
      "name": "Plant_Grass_Sharp"
    },
    {
      "x": 19,
      "y": 13,
      "z": 22,
      "name": "Soil_Dirt_Burnt"
    },
    {
      "x": 19,
      "y": 14,
      "z": 22,
      "name": "Soil_Dirt_Burnt"
    },
    {
      "x": 19,
      "y": 15,
      "z": 22,
      "name": "Soil_Dirt_Burnt"
    },
    {
      "x": 19,
      "y": 16,
      "z": 22,
      "name": "Soil_Grass_Burnt"
    },
    {
      "x": 20,
      "y": 28,
      "z": 6,
      "name": "Plant_Leaves_Dead",
      "support": 15
    },
    {
      "x": 20,
      "y": 31,
      "z": 6,
      "name": "Plant_Leaves_Dead",
      "support": 15
    },
    {
      "x": 20,
      "y": 32,
      "z": 6,
      "name": "Plant_Leaves_Dead",
      "support": 15
    },
    {
      "x": 20,
      "y": 33,
      "z": 6,
      "name": "Plant_Leaves_Dead",
      "support": 15
    },
    {
      "x": 20,
      "y": 26,
      "z": 7,
      "name": "Plant_Leaves_Dead",
      "support": 15
    },
    {
      "x": 20,
      "y": 27,
      "z": 7,
      "name": "Plant_Leaves_Dead",
      "support": 15
    },
    {
      "x": 20,
      "y": 28,
      "z": 7,
      "name": "Plant_Leaves_Dead",
      "support": 15
    },
    {
      "x": 20,
      "y": 29,
      "z": 7,
      "name": "Plant_Leaves_Dead",
      "support": 15
    },
    {
      "x": 20,
      "y": 32,
      "z": 7,
      "name": "Plant_Leaves_Dead",
      "support": 15
    },
    {
      "x": 20,
      "y": 33,
      "z": 7,
      "name": "Plant_Leaves_Dead",
      "support": 15
    },
    {
      "x": 20,
      "y": 27,
      "z": 8,
      "name": "Plant_Leaves_Dead",
      "support": 15
    },
    {
      "x": 20,
      "y": 28,
      "z": 8,
      "name": "Plant_Leaves_Dead",
      "support": 15
    },
    {
      "x": 20,
      "y": 29,
      "z": 8,
      "name": "Plant_Leaves_Dead",
      "support": 15
    },
    {
      "x": 20,
      "y": 30,
      "z": 8,
      "name": "Plant_Leaves_Dead",
      "support": 15
    },
    {
      "x": 20,
      "y": 32,
      "z": 8,
      "name": "Wood_Ash_Trunk_Full",
      "support": 15
    },
    {
      "x": 20,
      "y": 33,
      "z": 8,
      "name": "Plant_Leaves_Dead",
      "support": 15
    },
    {
      "x": 20,
      "y": 34,
      "z": 8,
      "name": "Plant_Leaves_Dead",
      "support": 15
    },
    {
      "x": 20,
      "y": 32,
      "z": 9,
      "name": "Wood_Ash_Trunk_Full",
      "support": 15
    },
    {
      "x": 20,
      "y": 33,
      "z": 9,
      "name": "Plant_Leaves_Dead",
      "support": 15
    },
    {
      "x": 20,
      "y": 34,
      "z": 9,
      "name": "Plant_Leaves_Dead",
      "support": 15
    },
    {
      "x": 20,
      "y": 34,
      "z": 10,
      "name": "Plant_Leaves_Dead",
      "support": 15
    },
    {
      "x": 20,
      "y": 28,
      "z": 11,
      "name": "Wood_Ash_Trunk_Full",
      "support": 15
    },
    {
      "x": 20,
      "y": 31,
      "z": 12,
      "name": "Wood_Ash_Trunk_Full",
      "support": 15
    },
    {
      "x": 20,
      "y": 32,
      "z": 12,
      "name": "Wood_Ash_Trunk_Full",
      "support": 15
    },
    {
      "x": 20,
      "y": 35,
      "z": 12,
      "name": "Plant_Leaves_Dead",
      "support": 15
    },
    {
      "x": 20,
      "y": 16,
      "z": 13,
      "name": "Rock_Basalt"
    },
    {
      "x": 20,
      "y": 17,
      "z": 13,
      "name": "Soil_Dirt_Burnt"
    },
    {
      "x": 20,
      "y": 18,
      "z": 13,
      "name": "Soil_Grass_Burnt"
    },
    {
      "x": 20,
      "y": 35,
      "z": 13,
      "name": "Plant_Leaves_Dead",
      "support": 15
    },
    {
      "x": 20,
      "y": 15,
      "z": 14,
      "name": "Rock_Basalt"
    },
    {
      "x": 20,
      "y": 16,
      "z": 14,
      "name": "Rock_Basalt"
    },
    {
      "x": 20,
      "y": 17,
      "z": 14,
      "name": "Rock_Basalt"
    },
    {
      "x": 20,
      "y": 18,
      "z": 14,
      "name": "Soil_Dirt_Burnt"
    },
    {
      "x": 20,
      "y": 19,
      "z": 14,
      "name": "Soil_Dirt_Burnt"
    },
    {
      "x": 20,
      "y": 20,
      "z": 14,
      "name": "Soil_Grass_Burnt"
    },
    {
      "x": 20,
      "y": 21,
      "z": 14,
      "name": "Plant_Grass_Sharp"
    },
    {
      "x": 20,
      "y": 15,
      "z": 15,
      "name": "Rock_Basalt"
    },
    {
      "x": 20,
      "y": 16,
      "z": 15,
      "name": "Rock_Basalt"
    },
    {
      "x": 20,
      "y": 17,
      "z": 15,
      "name": "Soil_Dirt_Burnt"
    },
    {
      "x": 20,
      "y": 18,
      "z": 15,
      "name": "Soil_Dirt_Burnt"
    },
    {
      "x": 20,
      "y": 19,
      "z": 15,
      "name": "Soil_Dirt_Burnt"
    },
    {
      "x": 20,
      "y": 20,
      "z": 15,
      "name": "Soil_Grass_Burnt"
    },
    {
      "x": 20,
      "y": 21,
      "z": 15,
      "name": "Plant_Grass_Sharp"
    },
    {
      "x": 20,
      "y": 27,
      "z": 15,
      "name": "Wood_Ash_Trunk_Full",
      "support": 15
    },
    {
      "x": 20,
      "y": 14,
      "z": 16,
      "name": "Rock_Basalt"
    },
    {
      "x": 20,
      "y": 15,
      "z": 16,
      "name": "Rock_Basalt"
    },
    {
      "x": 20,
      "y": 16,
      "z": 16,
      "name": "Rock_Basalt"
    },
    {
      "x": 20,
      "y": 17,
      "z": 16,
      "name": "Rock_Basalt"
    },
    {
      "x": 20,
      "y": 18,
      "z": 16,
      "name": "Soil_Dirt_Poisoned"
    },
    {
      "x": 20,
      "y": 19,
      "z": 16,
      "name": "Soil_Dirt_Poisoned"
    },
    {
      "x": 20,
      "y": 20,
      "z": 16,
      "name": "Soil_Dirt_Poisoned"
    },
    {
      "x": 20,
      "y": 21,
      "z": 16,
      "name": "Plant_Crop_Mushroom_Cap_Brown",
      "components": {
        "Components": {
          "FarmingBlock": {}
        }
      }
    },
    {
      "x": 20,
      "y": 27,
      "z": 16,
      "name": "Wood_Ash_Trunk_Full",
      "support": 15
    },
    {
      "x": 20,
      "y": 30,
      "z": 16,
      "name": "Plant_Leaves_Dead",
      "support": 15
    },
    {
      "x": 20,
      "y": 31,
      "z": 16,
      "name": "Plant_Leaves_Dead",
      "support": 15
    },
    {
      "x": 20,
      "y": 32,
      "z": 16,
      "name": "Plant_Leaves_Dead",
      "support": 15
    },
    {
      "x": 20,
      "y": 14,
      "z": 17,
      "name": "Rock_Basalt"
    },
    {
      "x": 20,
      "y": 15,
      "z": 17,
      "name": "Rock_Basalt"
    },
    {
      "x": 20,
      "y": 16,
      "z": 17,
      "name": "Rock_Basalt"
    },
    {
      "x": 20,
      "y": 17,
      "z": 17,
      "name": "Soil_Dirt_Poisoned"
    },
    {
      "x": 20,
      "y": 18,
      "z": 17,
      "name": "Soil_Dirt_Poisoned"
    },
    {
      "x": 20,
      "y": 19,
      "z": 17,
      "name": "Soil_Dirt_Poisoned"
    },
    {
      "x": 20,
      "y": 20,
      "z": 17,
      "name": "Soil_Dirt_Poisoned"
    },
    {
      "x": 20,
      "y": 32,
      "z": 17,
      "name": "Plant_Leaves_Dead",
      "support": 15
    },
    {
      "x": 20,
      "y": 13,
      "z": 18,
      "name": "Rock_Basalt"
    },
    {
      "x": 20,
      "y": 14,
      "z": 18,
      "name": "Rock_Basalt"
    },
    {
      "x": 20,
      "y": 15,
      "z": 18,
      "name": "Rock_Basalt"
    },
    {
      "x": 20,
      "y": 16,
      "z": 18,
      "name": "Soil_Dirt_Burnt"
    },
    {
      "x": 20,
      "y": 17,
      "z": 18,
      "name": "Soil_Dirt_Poisoned"
    },
    {
      "x": 20,
      "y": 18,
      "z": 18,
      "name": "Soil_Dirt_Poisoned"
    },
    {
      "x": 20,
      "y": 19,
      "z": 18,
      "name": "Soil_Dirt_Poisoned"
    },
    {
      "x": 20,
      "y": 28,
      "z": 18,
      "name": "Plant_Leaves_Dead",
      "support": 15
    },
    {
      "x": 20,
      "y": 13,
      "z": 19,
      "name": "Rock_Basalt"
    },
    {
      "x": 20,
      "y": 14,
      "z": 19,
      "name": "Rock_Basalt"
    },
    {
      "x": 20,
      "y": 15,
      "z": 19,
      "name": "Soil_Dirt_Burnt"
    },
    {
      "x": 20,
      "y": 16,
      "z": 19,
      "name": "Soil_Dirt_Poisoned"
    },
    {
      "x": 20,
      "y": 17,
      "z": 19,
      "name": "Soil_Dirt_Poisoned"
    },
    {
      "x": 20,
      "y": 18,
      "z": 19,
      "name": "Soil_Dirt_Poisoned"
    },
    {
      "x": 20,
      "y": 19,
      "z": 19,
      "name": "Soil_Dirt_Poisoned"
    },
    {
      "x": 20,
      "y": 26,
      "z": 19,
      "name": "Plant_Leaves_Dead",
      "support": 15
    },
    {
      "x": 20,
      "y": 27,
      "z": 19,
      "name": "Plant_Leaves_Dead",
      "support": 15
    },
    {
      "x": 20,
      "y": 28,
      "z": 19,
      "name": "Plant_Leaves_Dead",
      "support": 15
    },
    {
      "x": 20,
      "y": 29,
      "z": 19,
      "name": "Plant_Leaves_Dead",
      "support": 15
    },
    {
      "x": 20,
      "y": 14,
      "z": 20,
      "name": "Rock_Basalt"
    },
    {
      "x": 20,
      "y": 15,
      "z": 20,
      "name": "Soil_Dirt_Burnt"
    },
    {
      "x": 20,
      "y": 16,
      "z": 20,
      "name": "Soil_Dirt_Burnt"
    },
    {
      "x": 20,
      "y": 17,
      "z": 20,
      "name": "Soil_Dirt_Poisoned"
    },
    {
      "x": 20,
      "y": 18,
      "z": 20,
      "name": "Soil_Dirt_Poisoned"
    },
    {
      "x": 20,
      "y": 19,
      "z": 20,
      "name": "Soil_Dirt_Poisoned"
    },
    {
      "x": 20,
      "y": 14,
      "z": 21,
      "name": "Soil_Dirt_Burnt"
    },
    {
      "x": 20,
      "y": 15,
      "z": 21,
      "name": "Soil_Dirt_Burnt"
    },
    {
      "x": 20,
      "y": 16,
      "z": 21,
      "name": "Soil_Grass_Burnt"
    },
    {
      "x": 20,
      "y": 17,
      "z": 21,
      "name": "Plant_Grass_Gnarled"
    },
    {
      "x": 21,
      "y": 27,
      "z": 6,
      "name": "Plant_Leaves_Dead",
      "support": 15
    },
    {
      "x": 21,
      "y": 28,
      "z": 6,
      "name": "Plant_Leaves_Dead",
      "support": 15
    },
    {
      "x": 21,
      "y": 32,
      "z": 6,
      "name": "Plant_Leaves_Dead",
      "support": 15
    },
    {
      "x": 21,
      "y": 27,
      "z": 7,
      "name": "Plant_Leaves_Dead",
      "support": 15
    },
    {
      "x": 21,
      "y": 28,
      "z": 7,
      "name": "Wood_Ash_Trunk_Full",
      "support": 15
    },
    {
      "x": 21,
      "y": 29,
      "z": 7,
      "name": "Plant_Leaves_Dead",
      "support": 15
    },
    {
      "x": 21,
      "y": 30,
      "z": 7,
      "name": "Plant_Leaves_Dead",
      "support": 15
    },
    {
      "x": 21,
      "y": 32,
      "z": 7,
      "name": "Plant_Leaves_Dead",
      "support": 15
    },
    {
      "x": 21,
      "y": 28,
      "z": 8,
      "name": "Wood_Ash_Trunk_Full",
      "support": 15
    },
    {
      "x": 21,
      "y": 29,
      "z": 8,
      "name": "Plant_Leaves_Dead",
      "support": 15
    },
    {
      "x": 21,
      "y": 30,
      "z": 8,
      "name": "Plant_Leaves_Dead",
      "support": 15
    },
    {
      "x": 21,
      "y": 32,
      "z": 8,
      "name": "Plant_Leaves_Dead",
      "support": 15
    },
    {
      "x": 21,
      "y": 34,
      "z": 8,
      "name": "Plant_Leaves_Dead",
      "support": 15
    },
    {
      "x": 21,
      "y": 28,
      "z": 9,
      "name": "Wood_Ash_Trunk_Full",
      "support": 15
    },
    {
      "x": 21,
      "y": 31,
      "z": 9,
      "name": "Wood_Ash_Trunk_Full",
      "support": 15
    },
    {
      "x": 21,
      "y": 32,
      "z": 9,
      "name": "Wood_Ash_Trunk_Full",
      "support": 15
    },
    {
      "x": 21,
      "y": 34,
      "z": 9,
      "name": "Plant_Leaves_Dead",
      "support": 15
    },
    {
      "x": 21,
      "y": 28,
      "z": 10,
      "name": "Wood_Ash_Trunk_Full",
      "support": 15
    },
    {
      "x": 21,
      "y": 31,
      "z": 10,
      "name": "Wood_Ash_Trunk_Full",
      "support": 15
    },
    {
      "x": 21,
      "y": 34,
      "z": 10,
      "name": "Plant_Leaves_Dead",
      "support": 15
    },
    {
      "x": 21,
      "y": 35,
      "z": 10,
      "name": "Plant_Leaves_Dead",
      "support": 15
    },
    {
      "x": 21,
      "y": 18,
      "z": 11,
      "name": "Wood_Ash_Roots"
    },
    {
      "x": 21,
      "y": 19,
      "z": 11,
      "name": "Wood_Ash_Trunk_Full",
      "support": 15
    },
    {
      "x": 21,
      "y": 20,
      "z": 11,
      "name": "Wood_Ash_Trunk_Full",
      "support": 15
    },
    {
      "x": 21,
      "y": 28,
      "z": 11,
      "name": "Wood_Ash_Trunk_Full",
      "support": 15
    },
    {
      "x": 21,
      "y": 35,
      "z": 11,
      "name": "Plant_Leaves_Dead",
      "support": 15
    },
    {
      "x": 21,
      "y": 36,
      "z": 11,
      "name": "Plant_Leaves_Dead",
      "support": 15
    },
    {
      "x": 21,
      "y": 27,
      "z": 12,
      "name": "Wood_Ash_Trunk_Full",
      "support": 15
    },
    {
      "x": 21,
      "y": 31,
      "z": 12,
      "name": "Wood_Ash_Trunk_Full",
      "support": 15
    },
    {
      "x": 21,
      "y": 35,
      "z": 12,
      "name": "Plant_Leaves_Dead",
      "support": 15
    },
    {
      "x": 21,
      "y": 36,
      "z": 12,
      "name": "Plant_Leaves_Dead",
      "support": 15
    },
    {
      "x": 21,
      "y": 16,
      "z": 13,
      "name": "Rock_Basalt"
    },
    {
      "x": 21,
      "y": 17,
      "z": 13,
      "name": "Soil_Dirt_Burnt"
    },
    {
      "x": 21,
      "y": 18,
      "z": 13,
      "name": "Soil_Dirt_Burnt"
    },
    {
      "x": 21,
      "y": 19,
      "z": 13,
      "name": "Soil_Dirt_Burnt"
    },
    {
      "x": 21,
      "y": 20,
      "z": 13,
      "name": "Soil_Grass_Burnt"
    },
    {
      "x": 21,
      "y": 35,
      "z": 13,
      "name": "Plant_Leaves_Dead",
      "support": 15
    },
    {
      "x": 21,
      "y": 36,
      "z": 13,
      "name": "Plant_Leaves_Dead",
      "support": 15
    },
    {
      "x": 21,
      "y": 15,
      "z": 14,
      "name": "Rock_Basalt"
    },
    {
      "x": 21,
      "y": 16,
      "z": 14,
      "name": "Rock_Basalt"
    },
    {
      "x": 21,
      "y": 17,
      "z": 14,
      "name": "Soil_Dirt_Burnt"
    },
    {
      "x": 21,
      "y": 18,
      "z": 14,
      "name": "Soil_Dirt_Burnt"
    },
    {
      "x": 21,
      "y": 19,
      "z": 14,
      "name": "Soil_Dirt_Burnt"
    },
    {
      "x": 21,
      "y": 20,
      "z": 14,
      "name": "Soil_Grass_Burnt"
    },
    {
      "x": 21,
      "y": 21,
      "z": 14,
      "name": "Plant_Grass_Gnarled"
    },
    {
      "x": 21,
      "y": 35,
      "z": 14,
      "name": "Plant_Leaves_Dead",
      "support": 15
    },
    {
      "x": 21,
      "y": 15,
      "z": 15,
      "name": "Rock_Basalt"
    },
    {
      "x": 21,
      "y": 16,
      "z": 15,
      "name": "Rock_Basalt"
    },
    {
      "x": 21,
      "y": 17,
      "z": 15,
      "name": "Rock_Basalt"
    },
    {
      "x": 21,
      "y": 18,
      "z": 15,
      "name": "Soil_Dirt_Burnt"
    },
    {
      "x": 21,
      "y": 19,
      "z": 15,
      "name": "Soil_Dirt_Burnt"
    },
    {
      "x": 21,
      "y": 20,
      "z": 15,
      "name": "Soil_Grass_Burnt"
    },
    {
      "x": 21,
      "y": 21,
      "z": 15,
      "name": "Plant_Crop_Mushroom_Cap_Brown",
      "components": {
        "Components": {
          "FarmingBlock": {}
        }
      }
    },
    {
      "x": 21,
      "y": 27,
      "z": 15,
      "name": "Wood_Ash_Trunk_Full",
      "support": 15
    },
    {
      "x": 21,
      "y": 14,
      "z": 16,
      "name": "Rock_Basalt"
    },
    {
      "x": 21,
      "y": 15,
      "z": 16,
      "name": "Rock_Basalt"
    },
    {
      "x": 21,
      "y": 16,
      "z": 16,
      "name": "Rock_Basalt"
    },
    {
      "x": 21,
      "y": 17,
      "z": 16,
      "name": "Rock_Basalt"
    },
    {
      "x": 21,
      "y": 18,
      "z": 16,
      "name": "Rock_Basalt"
    },
    {
      "x": 21,
      "y": 19,
      "z": 16,
      "name": "Rock_Basalt"
    },
    {
      "x": 21,
      "y": 20,
      "z": 16,
      "name": "Soil_Grass_Burnt"
    },
    {
      "x": 21,
      "y": 31,
      "z": 16,
      "name": "Plant_Leaves_Dead",
      "support": 15
    },
    {
      "x": 21,
      "y": 32,
      "z": 16,
      "name": "Plant_Leaves_Dead",
      "support": 15
    },
    {
      "x": 21,
      "y": 33,
      "z": 16,
      "name": "Plant_Leaves_Dead",
      "support": 15
    },
    {
      "x": 21,
      "y": 34,
      "z": 16,
      "name": "Plant_Leaves_Dead",
      "support": 15
    },
    {
      "x": 21,
      "y": 14,
      "z": 17,
      "name": "Rock_Basalt"
    },
    {
      "x": 21,
      "y": 15,
      "z": 17,
      "name": "Rock_Basalt"
    },
    {
      "x": 21,
      "y": 16,
      "z": 17,
      "name": "Rock_Basalt"
    },
    {
      "x": 21,
      "y": 17,
      "z": 17,
      "name": "Soil_Dirt_Poisoned"
    },
    {
      "x": 21,
      "y": 18,
      "z": 17,
      "name": "Soil_Dirt_Poisoned"
    },
    {
      "x": 21,
      "y": 19,
      "z": 17,
      "name": "Soil_Dirt_Poisoned"
    },
    {
      "x": 21,
      "y": 20,
      "z": 17,
      "name": "Soil_Dirt_Poisoned"
    },
    {
      "x": 21,
      "y": 32,
      "z": 17,
      "name": "Plant_Leaves_Dead",
      "support": 15
    },
    {
      "x": 21,
      "y": 33,
      "z": 17,
      "name": "Plant_Leaves_Dead",
      "support": 15
    },
    {
      "x": 21,
      "y": 14,
      "z": 18,
      "name": "Rock_Basalt"
    },
    {
      "x": 21,
      "y": 15,
      "z": 18,
      "name": "Rock_Basalt"
    },
    {
      "x": 21,
      "y": 16,
      "z": 18,
      "name": "Soil_Dirt_Poisoned"
    },
    {
      "x": 21,
      "y": 17,
      "z": 18,
      "name": "Soil_Dirt_Poisoned"
    },
    {
      "x": 21,
      "y": 18,
      "z": 18,
      "name": "Soil_Dirt_Poisoned"
    },
    {
      "x": 21,
      "y": 19,
      "z": 18,
      "name": "Soil_Dirt_Poisoned"
    },
    {
      "x": 21,
      "y": 28,
      "z": 18,
      "name": "Plant_Leaves_Dead",
      "support": 15
    },
    {
      "x": 21,
      "y": 29,
      "z": 18,
      "name": "Plant_Leaves_Dead",
      "support": 15
    },
    {
      "x": 21,
      "y": 14,
      "z": 19,
      "name": "Rock_Basalt"
    },
    {
      "x": 21,
      "y": 15,
      "z": 19,
      "name": "Rock_Basalt"
    },
    {
      "x": 21,
      "y": 16,
      "z": 19,
      "name": "Soil_Dirt_Burnt"
    },
    {
      "x": 21,
      "y": 17,
      "z": 19,
      "name": "Soil_Dirt_Poisoned"
    },
    {
      "x": 21,
      "y": 18,
      "z": 19,
      "name": "Soil_Dirt_Poisoned"
    },
    {
      "x": 21,
      "y": 19,
      "z": 19,
      "name": "Soil_Dirt_Poisoned"
    },
    {
      "x": 21,
      "y": 27,
      "z": 19,
      "name": "Plant_Leaves_Dead",
      "support": 15
    },
    {
      "x": 21,
      "y": 28,
      "z": 19,
      "name": "Plant_Leaves_Dead",
      "support": 15
    },
    {
      "x": 21,
      "y": 29,
      "z": 19,
      "name": "Plant_Leaves_Dead",
      "support": 15
    },
    {
      "x": 21,
      "y": 14,
      "z": 20,
      "name": "Rock_Basalt"
    },
    {
      "x": 21,
      "y": 15,
      "z": 20,
      "name": "Soil_Dirt_Burnt"
    },
    {
      "x": 21,
      "y": 16,
      "z": 20,
      "name": "Soil_Dirt_Burnt"
    },
    {
      "x": 21,
      "y": 17,
      "z": 20,
      "name": "Soil_Dirt_Burnt"
    },
    {
      "x": 21,
      "y": 18,
      "z": 20,
      "name": "Soil_Dirt_Burnt"
    },
    {
      "x": 21,
      "y": 19,
      "z": 20,
      "name": "Soil_Grass_Burnt"
    },
    {
      "x": 21,
      "y": 20,
      "z": 20,
      "name": "Plant_Grass_Sharp"
    },
    {
      "x": 21,
      "y": 27,
      "z": 20,
      "name": "Plant_Leaves_Dead",
      "support": 15
    },
    {
      "x": 21,
      "y": 28,
      "z": 20,
      "name": "Plant_Leaves_Dead",
      "support": 15
    },
    {
      "x": 21,
      "y": 15,
      "z": 21,
      "name": "Soil_Dirt_Burnt"
    },
    {
      "x": 21,
      "y": 16,
      "z": 21,
      "name": "Soil_Grass_Burnt"
    },
    {
      "x": 22,
      "y": 27,
      "z": 6,
      "name": "Plant_Leaves_Dead",
      "support": 15
    },
    {
      "x": 22,
      "y": 28,
      "z": 6,
      "name": "Plant_Leaves_Dead",
      "support": 15
    },
    {
      "x": 22,
      "y": 26,
      "z": 7,
      "name": "Plant_Leaves_Dead",
      "support": 15
    },
    {
      "x": 22,
      "y": 27,
      "z": 7,
      "name": "Plant_Leaves_Dead",
      "support": 15
    },
    {
      "x": 22,
      "y": 28,
      "z": 7,
      "name": "Plant_Leaves_Dead",
      "support": 15
    },
    {
      "x": 22,
      "y": 29,
      "z": 7,
      "name": "Plant_Leaves_Dead",
      "support": 15
    },
    {
      "x": 22,
      "y": 27,
      "z": 8,
      "name": "Plant_Leaves_Dead",
      "support": 15
    },
    {
      "x": 22,
      "y": 28,
      "z": 8,
      "name": "Plant_Leaves_Dead",
      "support": 15
    },
    {
      "x": 22,
      "y": 29,
      "z": 8,
      "name": "Plant_Leaves_Dead",
      "support": 15
    },
    {
      "x": 22,
      "y": 34,
      "z": 9,
      "name": "Plant_Leaves_Dead",
      "support": 15
    },
    {
      "x": 22,
      "y": 30,
      "z": 10,
      "name": "Wood_Ash_Trunk_Full",
      "support": 15
    },
    {
      "x": 22,
      "y": 31,
      "z": 10,
      "name": "Wood_Ash_Trunk_Full",
      "support": 15
    },
    {
      "x": 22,
      "y": 35,
      "z": 10,
      "name": "Plant_Leaves_Dead",
      "support": 15
    },
    {
      "x": 22,
      "y": 36,
      "z": 10,
      "name": "Plant_Leaves_Dead",
      "support": 15
    },
    {
      "x": 22,
      "y": 18,
      "z": 11,
      "name": "Soil_Grass_Burnt"
    },
    {
      "x": 22,
      "y": 19,
      "z": 11,
      "name": "Wood_Ash_Roots"
    },
    {
      "x": 22,
      "y": 20,
      "z": 11,
      "name": "Wood_Ash_Trunk_Full",
      "support": 15
    },
    {
      "x": 22,
      "y": 21,
      "z": 11,
      "name": "Wood_Ash_Trunk",
      "support": 15
    },
    {
      "x": 22,
      "y": 22,
      "z": 11,
      "name": "Wood_Ash_Trunk_Full",
      "support": 15
    },
    {
      "x": 22,
      "y": 26,
      "z": 11,
      "name": "Wood_Ash_Trunk_Full",
      "support": 15
    },
    {
      "x": 22,
      "y": 27,
      "z": 11,
      "name": "Wood_Ash_Trunk_Full",
      "support": 15
    },
    {
      "x": 22,
      "y": 28,
      "z": 11,
      "name": "Wood_Ash_Trunk",
      "support": 15
    },
    {
      "x": 22,
      "y": 29,
      "z": 11,
      "name": "Wood_Ash_Trunk",
      "support": 15
    },
    {
      "x": 22,
      "y": 30,
      "z": 11,
      "name": "Wood_Ash_Trunk_Full",
      "support": 15
    },
    {
      "x": 22,
      "y": 35,
      "z": 11,
      "name": "Plant_Leaves_Dead",
      "support": 15
    },
    {
      "x": 22,
      "y": 36,
      "z": 11,
      "name": "Plant_Leaves_Dead",
      "support": 15
    },
    {
      "x": 22,
      "y": 17,
      "z": 12,
      "name": "Rock_Basalt"
    },
    {
      "x": 22,
      "y": 18,
      "z": 12,
      "name": "Soil_Grass_Burnt"
    },
    {
      "x": 22,
      "y": 21,
      "z": 12,
      "name": "Wood_Ash_Roots"
    },
    {
      "x": 22,
      "y": 22,
      "z": 12,
      "name": "Wood_Ash_Trunk_Full",
      "support": 15
    },
    {
      "x": 22,
      "y": 26,
      "z": 12,
      "name": "Wood_Ash_Trunk_Full",
      "support": 15
    },
    {
      "x": 22,
      "y": 27,
      "z": 12,
      "name": "Wood_Ash_Trunk_Full",
      "support": 15
    },
    {
      "x": 22,
      "y": 30,
      "z": 12,
      "name": "Wood_Ash_Trunk_Full",
      "support": 15
    },
    {
      "x": 22,
      "y": 31,
      "z": 12,
      "name": "Wood_Ash_Trunk_Full",
      "support": 15
    },
    {
      "x": 22,
      "y": 35,
      "z": 12,
      "name": "Plant_Leaves_Dead",
      "support": 15
    },
    {
      "x": 22,
      "y": 36,
      "z": 12,
      "name": "Plant_Leaves_Dead",
      "support": 15
    },
    {
      "x": 22,
      "y": 37,
      "z": 12,
      "name": "Plant_Leaves_Dead",
      "support": 15
    },
    {
      "x": 22,
      "y": 15,
      "z": 13,
      "name": "Rock_Basalt"
    },
    {
      "x": 22,
      "y": 16,
      "z": 13,
      "name": "Rock_Basalt"
    },
    {
      "x": 22,
      "y": 17,
      "z": 13,
      "name": "Soil_Dirt_Burnt"
    },
    {
      "x": 22,
      "y": 18,
      "z": 13,
      "name": "Soil_Dirt_Burnt"
    },
    {
      "x": 22,
      "y": 19,
      "z": 13,
      "name": "Soil_Dirt_Burnt"
    },
    {
      "x": 22,
      "y": 20,
      "z": 13,
      "name": "Soil_Grass_Burnt"
    },
    {
      "x": 22,
      "y": 21,
      "z": 13,
      "name": "Plant_Grass_Sharp"
    },
    {
      "x": 22,
      "y": 25,
      "z": 13,
      "name": "Wood_Ash_Trunk_Full",
      "support": 15
    },
    {
      "x": 22,
      "y": 26,
      "z": 13,
      "name": "Wood_Ash_Trunk_Full",
      "support": 15
    },
    {
      "x": 22,
      "y": 35,
      "z": 13,
      "name": "Plant_Leaves_Dead",
      "support": 15
    },
    {
      "x": 22,
      "y": 36,
      "z": 13,
      "name": "Plant_Leaves_Dead",
      "support": 15
    },
    {
      "x": 22,
      "y": 37,
      "z": 13,
      "name": "Plant_Leaves_Dead",
      "support": 15
    },
    {
      "x": 22,
      "y": 15,
      "z": 14,
      "name": "Rock_Basalt"
    },
    {
      "x": 22,
      "y": 16,
      "z": 14,
      "name": "Rock_Basalt"
    },
    {
      "x": 22,
      "y": 17,
      "z": 14,
      "name": "Rock_Basalt"
    },
    {
      "x": 22,
      "y": 18,
      "z": 14,
      "name": "Soil_Dirt_Burnt"
    },
    {
      "x": 22,
      "y": 19,
      "z": 14,
      "name": "Soil_Dirt_Burnt"
    },
    {
      "x": 22,
      "y": 20,
      "z": 14,
      "name": "Soil_Grass_Burnt"
    },
    {
      "x": 22,
      "y": 26,
      "z": 14,
      "name": "Wood_Ash_Trunk_Full",
      "support": 15
    },
    {
      "x": 22,
      "y": 27,
      "z": 14,
      "name": "Wood_Ash_Trunk",
      "support": 15
    },
    {
      "x": 22,
      "y": 28,
      "z": 14,
      "name": "Wood_Ash_Trunk",
      "support": 15
    },
    {
      "x": 22,
      "y": 29,
      "z": 14,
      "name": "Wood_Ash_Trunk",
      "support": 15
    },
    {
      "x": 22,
      "y": 30,
      "z": 14,
      "name": "Wood_Ash_Trunk_Full",
      "support": 15
    },
    {
      "x": 22,
      "y": 35,
      "z": 14,
      "name": "Plant_Leaves_Dead",
      "support": 15
    },
    {
      "x": 22,
      "y": 36,
      "z": 14,
      "name": "Plant_Leaves_Dead",
      "support": 15
    },
    {
      "x": 22,
      "y": 15,
      "z": 15,
      "name": "Rock_Basalt"
    },
    {
      "x": 22,
      "y": 16,
      "z": 15,
      "name": "Rock_Basalt"
    },
    {
      "x": 22,
      "y": 17,
      "z": 15,
      "name": "Rock_Basalt"
    },
    {
      "x": 22,
      "y": 18,
      "z": 15,
      "name": "Rock_Basalt"
    },
    {
      "x": 22,
      "y": 19,
      "z": 15,
      "name": "Soil_Dirt_Burnt"
    },
    {
      "x": 22,
      "y": 20,
      "z": 15,
      "name": "Soil_Grass_Burnt"
    },
    {
      "x": 22,
      "y": 21,
      "z": 15,
      "name": "Plant_Grass_Sharp"
    },
    {
      "x": 22,
      "y": 27,
      "z": 15,
      "name": "Wood_Ash_Trunk_Full",
      "support": 15
    },
    {
      "x": 22,
      "y": 30,
      "z": 15,
      "name": "Wood_Ash_Trunk_Full",
      "support": 15
    },
    {
      "x": 22,
      "y": 31,
      "z": 15,
      "name": "Wood_Ash_Trunk",
      "support": 15
    },
    {
      "x": 22,
      "y": 32,
      "z": 15,
      "name": "Wood_Ash_Trunk_Full",
      "support": 15
    },
    {
      "x": 22,
      "y": 14,
      "z": 16,
      "name": "Rock_Basalt"
    },
    {
      "x": 22,
      "y": 15,
      "z": 16,
      "name": "Rock_Basalt"
    },
    {
      "x": 22,
      "y": 16,
      "z": 16,
      "name": "Rock_Basalt"
    },
    {
      "x": 22,
      "y": 17,
      "z": 16,
      "name": "Rock_Basalt"
    },
    {
      "x": 22,
      "y": 18,
      "z": 16,
      "name": "Soil_Dirt_Poisoned"
    },
    {
      "x": 22,
      "y": 19,
      "z": 16,
      "name": "Soil_Dirt_Poisoned"
    },
    {
      "x": 22,
      "y": 20,
      "z": 16,
      "name": "Soil_Dirt_Poisoned"
    },
    {
      "x": 22,
      "y": 27,
      "z": 16,
      "name": "Wood_Ash_Trunk_Full",
      "support": 15
    },
    {
      "x": 22,
      "y": 28,
      "z": 16,
      "name": "Wood_Ash_Trunk_Full",
      "support": 15
    },
    {
      "x": 22,
      "y": 32,
      "z": 16,
      "name": "Wood_Ash_Trunk_Full",
      "support": 15
    },
    {
      "x": 22,
      "y": 33,
      "z": 16,
      "name": "Wood_Ash_Trunk_Full",
      "support": 15
    },
    {
      "x": 22,
      "y": 34,
      "z": 16,
      "name": "Plant_Leaves_Dead",
      "support": 15
    },
    {
      "x": 22,
      "y": 14,
      "z": 17,
      "name": "Rock_Basalt"
    },
    {
      "x": 22,
      "y": 15,
      "z": 17,
      "name": "Rock_Basalt"
    },
    {
      "x": 22,
      "y": 16,
      "z": 17,
      "name": "Rock_Basalt"
    },
    {
      "x": 22,
      "y": 17,
      "z": 17,
      "name": "Soil_Dirt_Poisoned"
    },
    {
      "x": 22,
      "y": 18,
      "z": 17,
      "name": "Soil_Dirt_Poisoned"
    },
    {
      "x": 22,
      "y": 19,
      "z": 17,
      "name": "Soil_Dirt_Poisoned"
    },
    {
      "x": 22,
      "y": 20,
      "z": 17,
      "name": "Soil_Dirt_Poisoned"
    },
    {
      "x": 22,
      "y": 28,
      "z": 17,
      "name": "Wood_Ash_Trunk_Full",
      "support": 15
    },
    {
      "x": 22,
      "y": 30,
      "z": 17,
      "name": "Plant_Leaves_Dead",
      "support": 15
    },
    {
      "x": 22,
      "y": 31,
      "z": 17,
      "name": "Plant_Leaves_Dead",
      "support": 15
    },
    {
      "x": 22,
      "y": 32,
      "z": 17,
      "name": "Plant_Leaves_Dead",
      "support": 15
    },
    {
      "x": 22,
      "y": 33,
      "z": 17,
      "name": "Plant_Leaves_Dead",
      "support": 15
    },
    {
      "x": 22,
      "y": 34,
      "z": 17,
      "name": "Plant_Leaves_Dead",
      "support": 15
    },
    {
      "x": 22,
      "y": 14,
      "z": 18,
      "name": "Rock_Basalt"
    },
    {
      "x": 22,
      "y": 15,
      "z": 18,
      "name": "Rock_Basalt"
    },
    {
      "x": 22,
      "y": 16,
      "z": 18,
      "name": "Rock_Basalt"
    },
    {
      "x": 22,
      "y": 17,
      "z": 18,
      "name": "Soil_Dirt_Poisoned"
    },
    {
      "x": 22,
      "y": 18,
      "z": 18,
      "name": "Soil_Dirt_Poisoned"
    },
    {
      "x": 22,
      "y": 19,
      "z": 18,
      "name": "Soil_Dirt_Poisoned"
    },
    {
      "x": 22,
      "y": 28,
      "z": 18,
      "name": "Wood_Ash_Trunk_Full",
      "support": 15
    },
    {
      "x": 22,
      "y": 29,
      "z": 18,
      "name": "Plant_Leaves_Dead",
      "support": 15
    },
    {
      "x": 22,
      "y": 14,
      "z": 19,
      "name": "Rock_Basalt"
    },
    {
      "x": 22,
      "y": 15,
      "z": 19,
      "name": "Rock_Basalt"
    },
    {
      "x": 22,
      "y": 16,
      "z": 19,
      "name": "Rock_Basalt"
    },
    {
      "x": 22,
      "y": 17,
      "z": 19,
      "name": "Soil_Dirt_Poisoned"
    },
    {
      "x": 22,
      "y": 18,
      "z": 19,
      "name": "Soil_Dirt_Poisoned"
    },
    {
      "x": 22,
      "y": 19,
      "z": 19,
      "name": "Soil_Dirt_Poisoned"
    },
    {
      "x": 22,
      "y": 26,
      "z": 19,
      "name": "Plant_Leaves_Dead",
      "support": 15
    },
    {
      "x": 22,
      "y": 27,
      "z": 19,
      "name": "Plant_Leaves_Dead",
      "support": 15
    },
    {
      "x": 22,
      "y": 28,
      "z": 19,
      "name": "Wood_Ash_Trunk_Full",
      "support": 15
    },
    {
      "x": 22,
      "y": 29,
      "z": 19,
      "name": "Plant_Leaves_Dead",
      "support": 15
    },
    {
      "x": 22,
      "y": 14,
      "z": 20,
      "name": "Rock_Basalt"
    },
    {
      "x": 22,
      "y": 15,
      "z": 20,
      "name": "Rock_Basalt"
    },
    {
      "x": 22,
      "y": 16,
      "z": 20,
      "name": "Soil_Dirt_Burnt"
    },
    {
      "x": 22,
      "y": 17,
      "z": 20,
      "name": "Soil_Dirt_Burnt"
    },
    {
      "x": 22,
      "y": 18,
      "z": 20,
      "name": "Soil_Grass_Burnt"
    },
    {
      "x": 22,
      "y": 19,
      "z": 20,
      "name": "Plant_Grass_Sharp"
    },
    {
      "x": 22,
      "y": 26,
      "z": 20,
      "name": "Plant_Leaves_Dead",
      "support": 15
    },
    {
      "x": 22,
      "y": 27,
      "z": 20,
      "name": "Plant_Leaves_Dead",
      "support": 15
    },
    {
      "x": 22,
      "y": 28,
      "z": 20,
      "name": "Plant_Leaves_Dead",
      "support": 15
    },
    {
      "x": 23,
      "y": 30,
      "z": 6,
      "name": "Plant_Leaves_Dead",
      "support": 15
    },
    {
      "x": 23,
      "y": 29,
      "z": 7,
      "name": "Plant_Leaves_Dead",
      "support": 15
    },
    {
      "x": 23,
      "y": 33,
      "z": 7,
      "name": "Plant_Leaves_Dead",
      "support": 15
    },
    {
      "x": 23,
      "y": 33,
      "z": 8,
      "name": "Plant_Leaves_Dead",
      "support": 15
    },
    {
      "x": 23,
      "y": 34,
      "z": 8,
      "name": "Plant_Leaves_Dead",
      "support": 15
    },
    {
      "x": 23,
      "y": 34,
      "z": 9,
      "name": "Plant_Leaves_Dead",
      "support": 15
    },
    {
      "x": 23,
      "y": 35,
      "z": 9,
      "name": "Plant_Leaves_Dead",
      "support": 15
    },
    {
      "x": 23,
      "y": 36,
      "z": 10,
      "name": "Plant_Leaves_Dead",
      "support": 15
    },
    {
      "x": 23,
      "y": 17,
      "z": 11,
      "name": "Soil_Dirt_Burnt"
    },
    {
      "x": 23,
      "y": 18,
      "z": 11,
      "name": "Soil_Dirt_Burnt"
    },
    {
      "x": 23,
      "y": 19,
      "z": 11,
      "name": "Soil_Grass_Burnt"
    },
    {
      "x": 23,
      "y": 22,
      "z": 11,
      "name": "Wood_Ash_Trunk_Full",
      "support": 15
    },
    {
      "x": 23,
      "y": 36,
      "z": 11,
      "name": "Plant_Leaves_Dead",
      "support": 15
    },
    {
      "x": 23,
      "y": 37,
      "z": 11,
      "name": "Plant_Leaves_Dead",
      "support": 15
    },
    {
      "x": 23,
      "y": 17,
      "z": 12,
      "name": "Rock_Basalt"
    },
    {
      "x": 23,
      "y": 18,
      "z": 12,
      "name": "Soil_Dirt_Burnt"
    },
    {
      "x": 23,
      "y": 19,
      "z": 12,
      "name": "Soil_Dirt_Burnt"
    },
    {
      "x": 23,
      "y": 20,
      "z": 12,
      "name": "Soil_Grass_Burnt"
    },
    {
      "x": 23,
      "y": 21,
      "z": 12,
      "name": "Wood_Ash_Roots"
    },
    {
      "x": 23,
      "y": 22,
      "z": 12,
      "name": "Wood_Ash_Trunk_Full",
      "support": 15
    },
    {
      "x": 23,
      "y": 23,
      "z": 12,
      "name": "Wood_Ash_Trunk",
      "support": 15
    },
    {
      "x": 23,
      "y": 24,
      "z": 12,
      "name": "Wood_Ash_Trunk",
      "support": 15
    },
    {
      "x": 23,
      "y": 25,
      "z": 12,
      "name": "Wood_Ash_Trunk",
      "support": 15
    },
    {
      "x": 23,
      "y": 26,
      "z": 12,
      "name": "Wood_Ash_Trunk_Full",
      "support": 15
    },
    {
      "x": 23,
      "y": 31,
      "z": 12,
      "name": "Wood_Ash_Trunk_Full",
      "support": 15
    },
    {
      "x": 23,
      "y": 32,
      "z": 12,
      "name": "Wood_Ash_Trunk",
      "support": 15
    },
    {
      "x": 23,
      "y": 33,
      "z": 12,
      "name": "Wood_Ash_Trunk",
      "support": 15
    },
    {
      "x": 23,
      "y": 34,
      "z": 12,
      "name": "Wood_Ash_Trunk",
      "support": 15
    },
    {
      "x": 23,
      "y": 35,
      "z": 12,
      "name": "Wood_Ash_Trunk",
      "support": 15
    },
    {
      "x": 23,
      "y": 36,
      "z": 12,
      "name": "Wood_Ash_Trunk",
      "support": 15
    },
    {
      "x": 23,
      "y": 37,
      "z": 12,
      "name": "Plant_Leaves_Dead",
      "support": 15
    },
    {
      "x": 23,
      "y": 15,
      "z": 13,
      "name": "Rock_Basalt"
    },
    {
      "x": 23,
      "y": 16,
      "z": 13,
      "name": "Rock_Basalt"
    },
    {
      "x": 23,
      "y": 17,
      "z": 13,
      "name": "Rock_Basalt"
    },
    {
      "x": 23,
      "y": 18,
      "z": 13,
      "name": "Soil_Dirt_Burnt"
    },
    {
      "x": 23,
      "y": 19,
      "z": 13,
      "name": "Soil_Dirt_Burnt"
    },
    {
      "x": 23,
      "y": 20,
      "z": 13,
      "name": "Soil_Grass_Burnt"
    },
    {
      "x": 23,
      "y": 21,
      "z": 13,
      "name": "Plant_Grass_Sharp"
    },
    {
      "x": 23,
      "y": 22,
      "z": 13,
      "name": "Wood_Ash_Trunk_Full",
      "support": 15
    },
    {
      "x": 23,
      "y": 23,
      "z": 13,
      "name": "Wood_Ash_Trunk",
      "support": 15
    },
    {
      "x": 23,
      "y": 24,
      "z": 13,
      "name": "Wood_Ash_Trunk",
      "support": 15
    },
    {
      "x": 23,
      "y": 25,
      "z": 13,
      "name": "Wood_Ash_Trunk_Full",
      "support": 15
    },
    {
      "x": 23,
      "y": 36,
      "z": 13,
      "name": "Plant_Leaves_Dead",
      "support": 15
    },
    {
      "x": 23,
      "y": 37,
      "z": 13,
      "name": "Plant_Leaves_Dead",
      "support": 15
    },
    {
      "x": 23,
      "y": 15,
      "z": 14,
      "name": "Rock_Basalt"
    },
    {
      "x": 23,
      "y": 16,
      "z": 14,
      "name": "Rock_Basalt"
    },
    {
      "x": 23,
      "y": 17,
      "z": 14,
      "name": "Rock_Basalt"
    },
    {
      "x": 23,
      "y": 18,
      "z": 14,
      "name": "Rock_Basalt"
    },
    {
      "x": 23,
      "y": 19,
      "z": 14,
      "name": "Soil_Dirt_Burnt"
    },
    {
      "x": 23,
      "y": 20,
      "z": 14,
      "name": "Soil_Grass_Burnt"
    },
    {
      "x": 23,
      "y": 36,
      "z": 14,
      "name": "Plant_Leaves_Dead",
      "support": 15
    },
    {
      "x": 23,
      "y": 15,
      "z": 15,
      "name": "Rock_Basalt"
    },
    {
      "x": 23,
      "y": 16,
      "z": 15,
      "name": "Rock_Basalt"
    },
    {
      "x": 23,
      "y": 17,
      "z": 15,
      "name": "Rock_Basalt"
    },
    {
      "x": 23,
      "y": 18,
      "z": 15,
      "name": "Rock_Basalt"
    },
    {
      "x": 23,
      "y": 19,
      "z": 15,
      "name": "Rock_Basalt"
    },
    {
      "x": 23,
      "y": 20,
      "z": 15,
      "name": "Soil_Grass_Burnt"
    },
    {
      "x": 23,
      "y": 21,
      "z": 15,
      "name": "Plant_Grass_Sharp"
    },
    {
      "x": 23,
      "y": 31,
      "z": 15,
      "name": "Wood_Ash_Trunk_Full",
      "support": 15
    },
    {
      "x": 23,
      "y": 15,
      "z": 16,
      "name": "Rock_Basalt"
    },
    {
      "x": 23,
      "y": 16,
      "z": 16,
      "name": "Rock_Basalt"
    },
    {
      "x": 23,
      "y": 17,
      "z": 16,
      "name": "Rock_Basalt"
    },
    {
      "x": 23,
      "y": 18,
      "z": 16,
      "name": "Soil_Dirt_Poisoned"
    },
    {
      "x": 23,
      "y": 19,
      "z": 16,
      "name": "Soil_Dirt_Poisoned"
    },
    {
      "x": 23,
      "y": 20,
      "z": 16,
      "name": "Soil_Dirt_Poisoned"
    },
    {
      "x": 23,
      "y": 32,
      "z": 16,
      "name": "Plant_Leaves_Dead",
      "support": 15
    },
    {
      "x": 23,
      "y": 33,
      "z": 16,
      "name": "Plant_Leaves_Dead",
      "support": 15
    },
    {
      "x": 23,
      "y": 34,
      "z": 16,
      "name": "Plant_Leaves_Dead",
      "support": 15
    },
    {
      "x": 23,
      "y": 14,
      "z": 17,
      "name": "Rock_Basalt"
    },
    {
      "x": 23,
      "y": 15,
      "z": 17,
      "name": "Rock_Basalt"
    },
    {
      "x": 23,
      "y": 16,
      "z": 17,
      "name": "Rock_Basalt"
    },
    {
      "x": 23,
      "y": 17,
      "z": 17,
      "name": "Soil_Dirt_Poisoned"
    },
    {
      "x": 23,
      "y": 18,
      "z": 17,
      "name": "Soil_Dirt_Poisoned"
    },
    {
      "x": 23,
      "y": 19,
      "z": 17,
      "name": "Soil_Dirt_Poisoned"
    },
    {
      "x": 23,
      "y": 20,
      "z": 17,
      "name": "Soil_Dirt_Poisoned"
    },
    {
      "x": 23,
      "y": 30,
      "z": 17,
      "name": "Plant_Leaves_Dead",
      "support": 15
    },
    {
      "x": 23,
      "y": 31,
      "z": 17,
      "name": "Plant_Leaves_Dead",
      "support": 15
    },
    {
      "x": 23,
      "y": 32,
      "z": 17,
      "name": "Plant_Leaves_Dead",
      "support": 15
    },
    {
      "x": 23,
      "y": 33,
      "z": 17,
      "name": "Plant_Leaves_Dead",
      "support": 15
    },
    {
      "x": 23,
      "y": 14,
      "z": 18,
      "name": "Rock_Basalt"
    },
    {
      "x": 23,
      "y": 15,
      "z": 18,
      "name": "Rock_Basalt"
    },
    {
      "x": 23,
      "y": 16,
      "z": 18,
      "name": "Soil_Dirt_Poisoned"
    },
    {
      "x": 23,
      "y": 17,
      "z": 18,
      "name": "Soil_Dirt_Poisoned"
    },
    {
      "x": 23,
      "y": 18,
      "z": 18,
      "name": "Soil_Dirt_Poisoned"
    },
    {
      "x": 23,
      "y": 19,
      "z": 18,
      "name": "Soil_Dirt_Poisoned"
    },
    {
      "x": 23,
      "y": 28,
      "z": 18,
      "name": "Plant_Leaves_Dead",
      "support": 15
    },
    {
      "x": 23,
      "y": 29,
      "z": 18,
      "name": "Plant_Leaves_Dead",
      "support": 15
    },
    {
      "x": 23,
      "y": 14,
      "z": 19,
      "name": "Rock_Basalt"
    },
    {
      "x": 23,
      "y": 15,
      "z": 19,
      "name": "Rock_Basalt"
    },
    {
      "x": 23,
      "y": 16,
      "z": 19,
      "name": "Soil_Dirt_Poisoned"
    },
    {
      "x": 23,
      "y": 17,
      "z": 19,
      "name": "Soil_Dirt_Poisoned"
    },
    {
      "x": 23,
      "y": 18,
      "z": 19,
      "name": "Soil_Dirt_Poisoned"
    },
    {
      "x": 23,
      "y": 19,
      "z": 19,
      "name": "Soil_Dirt_Poisoned"
    },
    {
      "x": 23,
      "y": 27,
      "z": 19,
      "name": "Plant_Leaves_Dead",
      "support": 15
    },
    {
      "x": 23,
      "y": 28,
      "z": 19,
      "name": "Plant_Leaves_Dead",
      "support": 15
    },
    {
      "x": 23,
      "y": 29,
      "z": 19,
      "name": "Plant_Leaves_Dead",
      "support": 15
    },
    {
      "x": 23,
      "y": 16,
      "z": 20,
      "name": "Rock_Basalt"
    },
    {
      "x": 23,
      "y": 17,
      "z": 20,
      "name": "Soil_Dirt_Poisoned"
    },
    {
      "x": 23,
      "y": 27,
      "z": 20,
      "name": "Plant_Leaves_Dead",
      "support": 15
    },
    {
      "x": 23,
      "y": 28,
      "z": 20,
      "name": "Plant_Leaves_Dead",
      "support": 15
    },
    {
      "x": 24,
      "y": 28,
      "z": 5,
      "name": "Plant_Leaves_Dead",
      "support": 15
    },
    {
      "x": 24,
      "y": 29,
      "z": 5,
      "name": "Plant_Leaves_Dead",
      "support": 15
    },
    {
      "x": 24,
      "y": 30,
      "z": 5,
      "name": "Plant_Leaves_Dead",
      "support": 15
    },
    {
      "x": 24,
      "y": 31,
      "z": 5,
      "name": "Plant_Leaves_Dead",
      "support": 15
    },
    {
      "x": 24,
      "y": 24,
      "z": 6,
      "name": "Plant_Leaves_Dead",
      "support": 15
    },
    {
      "x": 24,
      "y": 25,
      "z": 6,
      "name": "Plant_Leaves_Dead",
      "support": 15
    },
    {
      "x": 24,
      "y": 30,
      "z": 6,
      "name": "Plant_Leaves_Dead",
      "support": 15
    },
    {
      "x": 24,
      "y": 31,
      "z": 6,
      "name": "Plant_Leaves_Dead",
      "support": 15
    },
    {
      "x": 24,
      "y": 25,
      "z": 7,
      "name": "Plant_Leaves_Dead",
      "support": 15
    },
    {
      "x": 24,
      "y": 33,
      "z": 7,
      "name": "Plant_Leaves_Dead",
      "support": 15
    },
    {
      "x": 24,
      "y": 34,
      "z": 7,
      "name": "Plant_Leaves_Dead",
      "support": 15
    },
    {
      "x": 24,
      "y": 33,
      "z": 8,
      "name": "Wood_Ash_Trunk_Full",
      "support": 15
    },
    {
      "x": 24,
      "y": 34,
      "z": 8,
      "name": "Plant_Leaves_Dead",
      "support": 15
    },
    {
      "x": 24,
      "y": 35,
      "z": 8,
      "name": "Plant_Leaves_Dead",
      "support": 15
    },
    {
      "x": 24,
      "y": 32,
      "z": 9,
      "name": "Wood_Ash_Trunk_Full",
      "support": 15
    },
    {
      "x": 24,
      "y": 33,
      "z": 9,
      "name": "Wood_Ash_Trunk_Full",
      "support": 15
    },
    {
      "x": 24,
      "y": 34,
      "z": 9,
      "name": "Plant_Leaves_Dead",
      "support": 15
    },
    {
      "x": 24,
      "y": 35,
      "z": 9,
      "name": "Plant_Leaves_Dead",
      "support": 15
    },
    {
      "x": 24,
      "y": 16,
      "z": 11,
      "name": "Rock_Basalt"
    },
    {
      "x": 24,
      "y": 17,
      "z": 11,
      "name": "Soil_Dirt_Burnt"
    },
    {
      "x": 24,
      "y": 18,
      "z": 11,
      "name": "Soil_Dirt_Burnt"
    },
    {
      "x": 24,
      "y": 19,
      "z": 11,
      "name": "Soil_Grass_Burnt"
    },
    {
      "x": 24,
      "y": 36,
      "z": 11,
      "name": "Plant_Leaves_Dead",
      "support": 15
    },
    {
      "x": 24,
      "y": 37,
      "z": 11,
      "name": "Plant_Leaves_Dead",
      "support": 15
    },
    {
      "x": 24,
      "y": 16,
      "z": 12,
      "name": "Rock_Basalt"
    },
    {
      "x": 24,
      "y": 17,
      "z": 12,
      "name": "Soil_Dirt_Burnt"
    },
    {
      "x": 24,
      "y": 18,
      "z": 12,
      "name": "Soil_Dirt_Burnt"
    },
    {
      "x": 24,
      "y": 19,
      "z": 12,
      "name": "Soil_Dirt_Burnt"
    },
    {
      "x": 24,
      "y": 20,
      "z": 12,
      "name": "Soil_Grass_Burnt"
    },
    {
      "x": 24,
      "y": 21,
      "z": 12,
      "name": "Plant_Grass_Sharp"
    },
    {
      "x": 24,
      "y": 22,
      "z": 12,
      "name": "Wood_Ash_Trunk_Full",
      "support": 15
    },
    {
      "x": 24,
      "y": 36,
      "z": 12,
      "name": "Plant_Leaves_Dead",
      "support": 15
    },
    {
      "x": 24,
      "y": 15,
      "z": 13,
      "name": "Rock_Basalt"
    },
    {
      "x": 24,
      "y": 16,
      "z": 13,
      "name": "Rock_Basalt"
    },
    {
      "x": 24,
      "y": 17,
      "z": 13,
      "name": "Rock_Basalt"
    },
    {
      "x": 24,
      "y": 18,
      "z": 13,
      "name": "Soil_Dirt_Burnt"
    },
    {
      "x": 24,
      "y": 19,
      "z": 13,
      "name": "Soil_Dirt_Burnt"
    },
    {
      "x": 24,
      "y": 20,
      "z": 13,
      "name": "Soil_Grass_Burnt"
    },
    {
      "x": 24,
      "y": 21,
      "z": 13,
      "name": "Plant_Grass_Sharp"
    },
    {
      "x": 24,
      "y": 23,
      "z": 13,
      "name": "Wood_Ash_Trunk_Full",
      "support": 15
    },
    {
      "x": 24,
      "y": 36,
      "z": 13,
      "name": "Plant_Leaves_Dead",
      "support": 15
    },
    {
      "x": 24,
      "y": 15,
      "z": 14,
      "name": "Rock_Basalt"
    },
    {
      "x": 24,
      "y": 16,
      "z": 14,
      "name": "Rock_Basalt"
    },
    {
      "x": 24,
      "y": 17,
      "z": 14,
      "name": "Rock_Basalt"
    },
    {
      "x": 24,
      "y": 18,
      "z": 14,
      "name": "Rock_Basalt"
    },
    {
      "x": 24,
      "y": 19,
      "z": 14,
      "name": "Rock_Basalt"
    },
    {
      "x": 24,
      "y": 20,
      "z": 14,
      "name": "Wood_Ash_Roots"
    },
    {
      "x": 24,
      "y": 21,
      "z": 14,
      "name": "Wood_Ash_Trunk_Full",
      "support": 15
    },
    {
      "x": 24,
      "y": 22,
      "z": 14,
      "name": "Wood_Ash_Trunk_Full",
      "support": 15
    },
    {
      "x": 24,
      "y": 15,
      "z": 15,
      "name": "Rock_Basalt"
    },
    {
      "x": 24,
      "y": 16,
      "z": 15,
      "name": "Rock_Basalt"
    },
    {
      "x": 24,
      "y": 17,
      "z": 15,
      "name": "Rock_Basalt"
    },
    {
      "x": 24,
      "y": 18,
      "z": 15,
      "name": "Wood_Ash_Roots"
    },
    {
      "x": 24,
      "y": 19,
      "z": 15,
      "name": "Wood_Ash_Trunk_Full",
      "support": 15
    },
    {
      "x": 24,
      "y": 20,
      "z": 15,
      "name": "Wood_Ash_Trunk",
      "support": 15
    },
    {
      "x": 24,
      "y": 21,
      "z": 15,
      "name": "Wood_Ash_Trunk_Full",
      "support": 15
    },
    {
      "x": 24,
      "y": 31,
      "z": 15,
      "name": "Wood_Ash_Trunk_Full",
      "support": 15
    },
    {
      "x": 24,
      "y": 15,
      "z": 16,
      "name": "Rock_Basalt"
    },
    {
      "x": 24,
      "y": 16,
      "z": 16,
      "name": "Rock_Basalt"
    },
    {
      "x": 24,
      "y": 17,
      "z": 16,
      "name": "Rock_Basalt"
    },
    {
      "x": 24,
      "y": 18,
      "z": 16,
      "name": "Rock_Basalt"
    },
    {
      "x": 24,
      "y": 19,
      "z": 16,
      "name": "Soil_Dirt_Burnt"
    },
    {
      "x": 24,
      "y": 20,
      "z": 16,
      "name": "Soil_Grass_Burnt"
    },
    {
      "x": 24,
      "y": 31,
      "z": 16,
      "name": "Wood_Ash_Trunk_Full",
      "support": 15
    },
    {
      "x": 24,
      "y": 33,
      "z": 16,
      "name": "Plant_Leaves_Dead",
      "support": 15
    },
    {
      "x": 24,
      "y": 15,
      "z": 17,
      "name": "Rock_Basalt"
    },
    {
      "x": 24,
      "y": 16,
      "z": 17,
      "name": "Rock_Basalt"
    },
    {
      "x": 24,
      "y": 17,
      "z": 17,
      "name": "Rock_Basalt"
    },
    {
      "x": 24,
      "y": 18,
      "z": 17,
      "name": "Soil_Dirt_Poisoned"
    },
    {
      "x": 24,
      "y": 19,
      "z": 17,
      "name": "Soil_Dirt_Poisoned"
    },
    {
      "x": 24,
      "y": 20,
      "z": 17,
      "name": "Soil_Dirt_Poisoned"
    },
    {
      "x": 24,
      "y": 32,
      "z": 17,
      "name": "Plant_Leaves_Dead",
      "support": 15
    },
    {
      "x": 24,
      "y": 33,
      "z": 17,
      "name": "Plant_Leaves_Dead",
      "support": 15
    },
    {
      "x": 24,
      "y": 15,
      "z": 18,
      "name": "Rock_Basalt"
    },
    {
      "x": 24,
      "y": 16,
      "z": 18,
      "name": "Rock_Basalt"
    },
    {
      "x": 24,
      "y": 17,
      "z": 18,
      "name": "Soil_Dirt_Poisoned"
    },
    {
      "x": 24,
      "y": 18,
      "z": 18,
      "name": "Soil_Dirt_Poisoned"
    },
    {
      "x": 24,
      "y": 19,
      "z": 18,
      "name": "Soil_Dirt_Poisoned"
    },
    {
      "x": 24,
      "y": 26,
      "z": 18,
      "name": "Plant_Leaves_Dead",
      "support": 15
    },
    {
      "x": 24,
      "y": 27,
      "z": 18,
      "name": "Plant_Leaves_Dead",
      "support": 15
    },
    {
      "x": 24,
      "y": 28,
      "z": 18,
      "name": "Plant_Leaves_Dead",
      "support": 15
    },
    {
      "x": 24,
      "y": 29,
      "z": 18,
      "name": "Plant_Leaves_Dead",
      "support": 15
    },
    {
      "x": 24,
      "y": 16,
      "z": 19,
      "name": "Rock_Basalt"
    },
    {
      "x": 24,
      "y": 17,
      "z": 19,
      "name": "Soil_Dirt_Poisoned"
    },
    {
      "x": 24,
      "y": 18,
      "z": 19,
      "name": "Soil_Dirt_Poisoned"
    },
    {
      "x": 24,
      "y": 19,
      "z": 19,
      "name": "Soil_Dirt_Poisoned"
    },
    {
      "x": 24,
      "y": 27,
      "z": 19,
      "name": "Plant_Leaves_Dead",
      "support": 15
    },
    {
      "x": 24,
      "y": 16,
      "z": 20,
      "name": "Soil_Grass_Burnt"
    },
    {
      "x": 25,
      "y": 30,
      "z": 4,
      "name": "Plant_Leaves_Dead",
      "support": 15
    },
    {
      "x": 25,
      "y": 25,
      "z": 5,
      "name": "Plant_Leaves_Dead",
      "support": 15
    },
    {
      "x": 25,
      "y": 28,
      "z": 5,
      "name": "Plant_Leaves_Dead",
      "support": 15
    },
    {
      "x": 25,
      "y": 29,
      "z": 5,
      "name": "Plant_Leaves_Dead",
      "support": 15
    },
    {
      "x": 25,
      "y": 30,
      "z": 5,
      "name": "Wood_Ash_Trunk_Full",
      "support": 15
    },
    {
      "x": 25,
      "y": 31,
      "z": 5,
      "name": "Plant_Leaves_Dead",
      "support": 15
    },
    {
      "x": 25,
      "y": 23,
      "z": 6,
      "name": "Plant_Leaves_Dead",
      "support": 15
    },
    {
      "x": 25,
      "y": 24,
      "z": 6,
      "name": "Plant_Leaves_Dead",
      "support": 15
    },
    {
      "x": 25,
      "y": 25,
      "z": 6,
      "name": "Plant_Leaves_Dead",
      "support": 15
    },
    {
      "x": 25,
      "y": 26,
      "z": 6,
      "name": "Plant_Leaves_Dead",
      "support": 15
    },
    {
      "x": 25,
      "y": 30,
      "z": 6,
      "name": "Wood_Ash_Trunk_Full",
      "support": 15
    },
    {
      "x": 25,
      "y": 31,
      "z": 6,
      "name": "Plant_Leaves_Dead",
      "support": 15
    },
    {
      "x": 25,
      "y": 25,
      "z": 7,
      "name": "Plant_Leaves_Dead",
      "support": 15
    },
    {
      "x": 25,
      "y": 26,
      "z": 7,
      "name": "Plant_Leaves_Dead",
      "support": 15
    },
    {
      "x": 25,
      "y": 30,
      "z": 7,
      "name": "Wood_Ash_Trunk_Full",
      "support": 15
    },
    {
      "x": 25,
      "y": 33,
      "z": 7,
      "name": "Plant_Leaves_Dead",
      "support": 15
    },
    {
      "x": 25,
      "y": 34,
      "z": 7,
      "name": "Plant_Leaves_Dead",
      "support": 15
    },
    {
      "x": 25,
      "y": 33,
      "z": 8,
      "name": "Plant_Leaves_Dead",
      "support": 15
    },
    {
      "x": 25,
      "y": 34,
      "z": 8,
      "name": "Plant_Leaves_Dead",
      "support": 15
    },
    {
      "x": 25,
      "y": 18,
      "z": 9,
      "name": "Rock_Basalt"
    },
    {
      "x": 25,
      "y": 19,
      "z": 9,
      "name": "Soil_Grass_Burnt"
    },
    {
      "x": 25,
      "y": 30,
      "z": 9,
