{
  "version": 8,
  "blockIdVersion": 8,
  "anchorX": 5,
  "anchorY": -76,
  "anchorZ": 4,
  "blocks": [
    {
      "x": 3,
      "y": 6,
      "z": 2,
      "name": "Rock_Calcite"
    },
    {
      "x": 3,
      "y": 5,
      "z": 3,
      "name": "Rock_Calcite"
    },
    {
      "x": 3,
      "y": 6,
      "z": 3,
      "name": "Rock_Calcite"
    },
    {
      "x": 3,
      "y": 7,
      "z": 3,
      "name": "Rock_Calcite"
    },
    {
      "x": 3,
      "y": 6,
      "z": 4,
      "name": "Rock_Calcite"
    },
    {
      "x": 3,
      "y": 7,
      "z": 4,
      "name": "Rock_Calcite"
    },
    {
      "x": 3,
      "y": 6,
      "z": 5,
      "name": "Rock_Calcite"
    },
    {
      "x": 4,
      "y": 5,
      "z": 1,
      "name": "Rock_Calcite"
    },
    {
      "x": 4,
      "y": 6,
      "z": 1,
      "name": "Rock_Calcite"
    },
    {
      "x": 4,
      "y": 4,
      "z": 2,
      "name": "Rock_Calcite"
    },
    {
      "x": 4,
      "y": 5,
      "z": 2,
      "name": "Rock_Calcite"
    },
    {
      "x": 4,
      "y": 6,
      "z": 2,
      "name": "Rock_Calcite"
    },
    {
      "x": 4,
      "y": 7,
      "z": 2,
      "name": "Rock_Calcite"
    },
    {
      "x": 4,
      "y": 4,
      "z": 3,
      "name": "Rock_Calcite"
    },
    {
      "x": 4,
      "y": 5,
      "z": 3,
      "name": "Rock_Calcite"
    },
    {
      "x": 4,
      "y": 6,
      "z": 3,
      "name": "Rock_Calcite"
    },
    {
      "x": 4,
      "y": 7,
      "z": 3,
      "name": "Rock_Calcite"
    },
    {
      "x": 4,
      "y": 8,
      "z": 3,
      "name": "Rock_Calcite"
    },
    {
      "x": 4,
      "y": 3,
      "z": 4,
      "name": "Rock_Calcite"
    },
    {
      "x": 4,
      "y": 4,
      "z": 4,
      "name": "Rock_Calcite"
    },
    {
      "x": 4,
      "y": 5,
      "z": 4,
      "name": "Rock_Calcite"
    },
    {
      "x": 4,
      "y": 6,
      "z": 4,
      "name": "Rock_Calcite"
    },
    {
      "x": 4,
      "y": 7,
      "z": 4,
      "name": "Rock_Calcite"
    },
    {
      "x": 4,
      "y": 8,
      "z": 4,
      "name": "Rock_Calcite"
    },
    {
      "x": 4,
      "y": 4,
      "z": 5,
      "name": "Rock_Calcite"
    },
    {
      "x": 4,
      "y": 5,
      "z": 5,
      "name": "Rock_Calcite"
    },
    {
      "x": 4,
      "y": 6,
      "z": 5,
      "name": "Rock_Calcite"
    },
    {
      "x": 4,
      "y": 7,
      "z": 5,
      "name": "Rock_Calcite"
    },
    {
      "x": 4,
      "y": 5,
      "z": 6,
      "name": "Rock_Calcite"
    },
    {
      "x": 5,
      "y": 5,
      "z": 1,
      "name": "Rock_Calcite"
    },
    {
      "x": 5,
      "y": 6,
      "z": 1,
      "name": "Rock_Calcite"
    },
    {
      "x": 5,
      "y": 7,
      "z": 1,
      "name": "Rock_Calcite"
    },
    {
      "x": 5,
      "y": 4,
      "z": 2,
      "name": "Rock_Calcite"
    },
    {
      "x": 5,
      "y": 5,
      "z": 2,
      "name": "Rock_Calcite"
    },
    {
      "x": 5,
      "y": 6,
      "z": 2,
      "name": "Rock_Calcite"
    },
    {
      "x": 5,
      "y": 7,
      "z": 2,
      "name": "Rock_Calcite"
    },
    {
      "x": 5,
      "y": 8,
      "z": 2,
      "name": "Rock_Calcite"
    },
    {
      "x": 5,
      "y": 3,
      "z": 3,
      "name": "Rock_Calcite"
    },
    {
      "x": 5,
      "y": 4,
      "z": 3,
      "name": "Rock_Calcite"
    },
    {
      "x": 5,
      "y": 5,
      "z": 3,
      "name": "Rock_Calcite"
    },
    {
      "x": 5,
      "y": 6,
      "z": 3,
      "name": "Rock_Calcite"
    },
    {
      "x": 5,
      "y": 7,
      "z": 3,
      "name": "Rock_Calcite"
    },
    {
      "x": 5,
      "y": 8,
      "z": 3,
      "name": "Rock_Calcite"
    },
    {
      "x": 5,
      "y": 2,
      "z": 4,
      "name": "Rock_Calcite"
    },
    {
      "x": 5,
      "y": 3,
      "z": 4,
      "name": "Rock_Calcite"
    },
    {
      "x": 5,
      "y": 4,
      "z": 4,
      "name": "Rock_Calcite"
    },
    {
      "x": 5,
      "y": 5,
      "z": 4,
      "name": "Rock_Calcite"
    },
    {
      "x": 5,
      "y": 6,
      "z": 4,
      "name": "Rock_Calcite"
    },
    {
      "x": 5,
      "y": 7,
      "z": 4,
      "name": "Rock_Calcite"
    },
    {
      "x": 5,
      "y": 8,
      "z": 4,
      "name": "Rock_Calcite"
    },
    {
      "x": 5,
      "y": 2,
      "z": 5,
      "name": "Rock_Calcite"
    },
    {
      "x": 5,
      "y": 3,
      "z": 5,
      "name": "Rock_Calcite"
    },
    {
      "x": 5,
      "y": 4,
      "z": 5,
      "name": "Rock_Calcite"
    },
    {
      "x": 5,
      "y": 5,
      "z": 5,
      "name": "Rock_Calcite"
    },
    {
      "x": 5,
      "y": 6,
      "z": 5,
      "name": "Rock_Calcite"
    },
    {
      "x": 5,
      "y": 7,
      "z": 5,
      "name": "Rock_Calcite"
    },
    {
      "x": 5,
      "y": 8,
      "z": 5,
      "name": "Rock_Calcite"
    },
    {
      "x": 5,
      "y": 3,
      "z": 6,
      "name": "Rock_Calcite"
    },
    {
      "x": 5,
      "y": 4,
      "z": 6,
      "name": "Rock_Calcite"
    },
    {
      "x": 5,
      "y": 5,
      "z": 6,
      "name": "Rock_Calcite"
    },
    {
      "x": 5,
      "y": 6,
      "z": 6,
      "name": "Rock_Calcite"
    },
    {
      "x": 5,
      "y": 7,
      "z": 6,
      "name": "Rock_Calcite"
    },
    {
      "x": 5,
      "y": 6,
      "z": 7,
      "name": "Rock_Calcite"
    },
    {
      "x": 6,
      "y": 6,
      "z": 1,
      "name": "Rock_Calcite"
    },
    {
      "x": 6,
      "y": 5,
      "z": 2,
      "name": "Rock_Calcite"
    },
    {
      "x": 6,
      "y": 6,
      "z": 2,
      "name": "Rock_Calcite"
    },
    {
      "x": 6,
      "y": 7,
      "z": 2,
      "name": "Rock_Calcite"
    },
    {
      "x": 6,
      "y": 8,
      "z": 2,
      "name": "Rock_Calcite"
    },
    {
      "x": 6,
      "y": 4,
      "z": 3,
      "name": "Rock_Calcite"
    },
    {
      "x": 6,
      "y": 5,
      "z": 3,
      "name": "Rock_Calcite"
    },
    {
      "x": 6,
      "y": 6,
      "z": 3,
      "name": "Rock_Calcite"
    },
    {
      "x": 6,
      "y": 7,
      "z": 3,
      "name": "Rock_Calcite"
    },
    {
      "x": 6,
      "y": 8,
      "z": 3,
      "name": "Rock_Calcite"
    },
    {
      "x": 6,
      "y": 9,
      "z": 3,
      "name": "Rock_Calcite"
    },
    {
      "x": 6,
      "y": 3,
      "z": 4,
      "name": "Rock_Calcite"
    },
    {
      "x": 6,
      "y": 4,
      "z": 4,
      "name": "Rock_Calcite"
    },
    {
      "x": 6,
      "y": 5,
      "z": 4,
      "name": "Rock_Calcite"
    },
    {
      "x": 6,
      "y": 6,
      "z": 4,
      "name": "Rock_Calcite"
    },
    {
      "x": 6,
      "y": 7,
      "z": 4,
      "name": "Rock_Calcite"
    },
    {
      "x": 6,
      "y": 8,
      "z": 4,
      "name": "Rock_Calcite"
    },
    {
      "x": 6,
      "y": 9,
      "z": 4,
      "name": "Rock_Calcite"
    },
    {
      "x": 6,
      "y": 2,
      "z": 5,
      "name": "Rock_Calcite"
    },
    {
      "x": 6,
      "y": 3,
      "z": 5,
      "name": "Rock_Calcite"
    },
    {
      "x": 6,
      "y": 4,
      "z": 5,
      "name": "Rock_Calcite"
    },
    {
      "x": 6,
      "y": 5,
      "z": 5,
      "name": "Rock_Calcite"
    },
    {
      "x": 6,
      "y": 6,
      "z": 5,
      "name": "Rock_Calcite"
    },
    {
      "x": 6,
      "y": 7,
      "z": 5,
      "name": "Rock_Calcite"
    },
    {
      "x": 6,
      "y": 8,
      "z": 5,
      "name": "Rock_Calcite"
    },
    {
      "x": 6,
      "y": 4,
      "z": 6,
      "name": "Rock_Calcite"
    },
    {
      "x": 6,
      "y": 5,
      "z": 6,
      "name": "Rock_Calcite"
    },
    {
      "x": 6,
      "y": 6,
      "z": 6,
      "name": "Rock_Calcite"
    },
    {
      "x": 6,
      "y": 7,
      "z": 6,
      "name": "Rock_Calcite"
    },
    {
      "x": 6,
      "y": 6,
      "z": 7,
      "name": "Rock_Calcite"
    },
    {
      "x": 7,
      "y": 6,
      "z": 2,
      "name": "Rock_Calcite"
    },
    {
      "x": 7,
      "y": 5,
      "z": 3,
      "name": "Rock_Calcite"
    },
    {
      "x": 7,
      "y": 6,
      "z": 3,
      "name": "Rock_Calcite"
    },
    {
      "x": 7,
      "y": 7,
      "z": 3,
      "name": "Rock_Calcite"
    },
    {
      "x": 7,
      "y": 8,
      "z": 3,
      "name": "Rock_Calcite"
    },
    {
      "x": 7,
      "y": 9,
      "z": 3,
      "name": "Rock_Calcite"
    },
    {
      "x": 7,
      "y": 4,
      "z": 4,
      "name": "Rock_Calcite"
    },
    {
      "x": 7,
      "y": 5,
      "z": 4,
      "name": "Rock_Calcite"
    },
    {
      "x": 7,
      "y": 6,
      "z": 4,
      "name": "Rock_Calcite"
    },
    {
      "x": 7,
      "y": 7,
      "z": 4,
      "name": "Rock_Calcite"
    },
    {
      "x": 7,
      "y": 8,
      "z": 4,
      "name": "Rock_Calcite"
    },
    {
      "x": 7,
      "y": 9,
      "z": 4,
      "name": "Rock_Calcite"
    },
    {
      "x": 7,
      "y": 3,
      "z": 5,
      "name": "Rock_Calcite"
    },
    {
      "x": 7,
      "y": 4,
      "z": 5,
      "name": "Rock_Calcite"
    },
    {
      "x": 7,
      "y": 5,
      "z": 5,
      "name": "Rock_Calcite"
    },
    {
      "x": 7,
      "y": 6,
      "z": 5,
      "name": "Rock_Calcite"
    },
    {
      "x": 7,
      "y": 7,
      "z": 5,
      "name": "Rock_Calcite"
    },
    {
      "x": 7,
      "y": 8,
      "z": 5,
      "name": "Rock_Calcite"
    },
    {
      "x": 7,
      "y": 9,
      "z": 5,
      "name": "Rock_Calcite"
    },
    {
      "x": 7,
      "y": 5,
      "z": 6,
      "name": "Rock_Calcite"
    },
    {
      "x": 7,
      "y": 6,
      "z": 6,
      "name": "Rock_Calcite"
    },
    {
      "x": 7,
      "y": 7,
      "z": 6,
      "name": "Rock_Calcite"
    },
    {
      "x": 7,
      "y": 8,
      "z": 6,
      "name": "Rock_Calcite"
    },
    {
      "x": 8,
      "y": 6,
      "z": 3,
      "name": "Rock_Calcite"
    },
    {
      "x": 8,
      "y": 7,
      "z": 3,
      "name": "Rock_Calcite"
    },
    {
      "x": 8,
      "y": 5,
      "z": 4,
      "name": "Rock_Calcite"
    },
    {
      "x": 8,
      "y": 6,
      "z": 4,
      "name": "Rock_Calcite"
    },
    {
      "x": 8,
      "y": 7,
      "z": 4,
      "name": "Rock_Calcite"
    },
    {
      "x": 8,
      "y": 8,
      "z": 4,
      "name": "Rock_Calcite"
    },
    {
      "x": 8,
      "y": 9,
      "z": 4,
      "name": "Rock_Calcite"
    },
    {
      "x": 8,
      "y": 5,
      "z": 5,
      "name": "Rock_Calcite"
    },
    {
      "x": 8,
      "y": 6,
      "z": 5,
      "name": "Rock_Calcite"
    },
    {
      "x": 8,
      "y": 7,
      "z": 5,
      "name": "Rock_Calcite"
    },
    {
      "x": 8,
      "y": 8,
      "z": 5,
      "name": "Rock_Calcite"
    },
    {
      "x": 8,
      "y": 6,
      "z": 6,
      "name": "Rock_Calcite"
    },
    {
      "x": 9,
      "y": 5,
      "z": 4,
      "name": "Rock_Calcite"
    },
    {
      "x": 9,
      "y": 6,
      "z": 4,
      "name": "Rock_Calcite"
    },
    {
      "x": 9,
      "y": 7,
      "z": 4,
      "name": "Rock_Calcite"
    },
    {
      "x": 9,
      "y": 6,
      "z": 5,
      "name": "Rock_Calcite"
    },
    {
      "x": 9,
      "y": 7,
      "z": 5,
      "name": "Rock_Calcite"
    }
  ]
}