{
  "version": 8,
  "blockIdVersion": 8,
  "anchorX": -1,
  "anchorY": 35,
  "anchorZ": 21,
  "blocks": [
    {
      "x": -8,
      "y": 35,
      "z": 7,
      "name": "Rock_Shale_Cobble"
    },
    {
      "x": -8,
      "y": 36,
      "z": 7,
      "name": "Rock_Shale"
    },
    {
      "x": -8,
      "y": 37,
      "z": 7,
      "name": "Rock_Shale"
    },
    {
      "x": -8,
      "y": 38,
      "z": 7,
      "name": "Rock_Shale"
    },
    {
      "x": -8,
      "y": 39,
      "z": 7,
      "name": "Rock_Shale"
    },
    {
      "x": -8,
      "y": 40,
      "z": 7,
      "name": "Rock_Shale"
    },
    {
      "x": -8,
      "y": 41,
      "z": 7,
      "name": "Rock_Shale"
    },
    {
      "x": -8,
      "y": 42,
      "z": 7,
      "name": "Rock_Basalt"
    },
    {
      "x": -8,
      "y": 35,
      "z": 8,
      "name": "Rock_Shale_Cobble"
    },
    {
      "x": -8,
      "y": 36,
      "z": 8,
      "name": "Rock_Shale"
    },
    {
      "x": -8,
      "y": 37,
      "z": 8,
      "name": "Rock_Shale"
    },
    {
      "x": -8,
      "y": 38,
      "z": 8,
      "name": "Rock_Shale"
    },
    {
      "x": -8,
      "y": 39,
      "z": 8,
      "name": "Rock_Shale"
    },
    {
      "x": -8,
      "y": 40,
      "z": 8,
      "name": "Rock_Shale"
    },
    {
      "x": -8,
      "y": 41,
      "z": 8,
      "name": "Rock_Shale"
    },
    {
      "x": -8,
      "y": 42,
      "z": 8,
      "name": "Rock_Basalt"
    },
    {
      "x": -8,
      "y": 35,
      "z": 9,
      "name": "Rock_Shale_Cobble"
    },
    {
      "x": -8,
      "y": 36,
      "z": 9,
      "name": "Rock_Shale"
    },
    {
      "x": -8,
      "y": 37,
      "z": 9,
      "name": "Rock_Shale"
    },
    {
      "x": -8,
      "y": 38,
      "z": 9,
      "name": "Rock_Shale"
    },
    {
      "x": -8,
      "y": 39,
      "z": 9,
      "name": "Rock_Shale"
    },
    {
      "x": -8,
      "y": 40,
      "z": 9,
      "name": "Rock_Shale"
    },
    {
      "x": -8,
      "y": 41,
      "z": 9,
      "name": "Rock_Shale"
    },
    {
      "x": -8,
      "y": 42,
      "z": 9,
      "name": "Rock_Basalt"
    },
    {
      "x": -8,
      "y": 35,
      "z": 10,
      "name": "Rock_Shale_Cobble"
    },
    {
      "x": -8,
      "y": 36,
      "z": 10,
      "name": "Rock_Shale"
    },
    {
      "x": -8,
      "y": 37,
      "z": 10,
      "name": "Rock_Shale"
    },
    {
      "x": -8,
      "y": 38,
      "z": 10,
      "name": "Rock_Shale"
    },
    {
      "x": -8,
      "y": 39,
      "z": 10,
      "name": "Rock_Shale"
    },
    {
      "x": -8,
      "y": 40,
      "z": 10,
      "name": "Rock_Shale"
    },
    {
      "x": -8,
      "y": 41,
      "z": 10,
      "name": "Rock_Shale"
    },
    {
      "x": -8,
      "y": 42,
      "z": 10,
      "name": "Rock_Basalt"
    },
    {
      "x": -8,
      "y": 35,
      "z": 11,
      "name": "Rock_Shale_Cobble"
    },
    {
      "x": -8,
      "y": 36,
      "z": 11,
      "name": "Rock_Shale"
    },
    {
      "x": -8,
      "y": 37,
      "z": 11,
      "name": "Rock_Shale"
    },
    {
      "x": -8,
      "y": 38,
      "z": 11,
      "name": "Rock_Shale"
    },
    {
      "x": -8,
      "y": 39,
      "z": 11,
      "name": "Rock_Shale"
    },
    {
      "x": -8,
      "y": 40,
      "z": 11,
      "name": "Rock_Shale"
    },
    {
      "x": -8,
      "y": 41,
      "z": 11,
      "name": "Rock_Shale"
    },
    {
      "x": -8,
      "y": 42,
      "z": 11,
      "name": "Rock_Basalt"
    },
    {
      "x": -8,
      "y": 35,
      "z": 12,
      "name": "Rock_Shale_Cobble"
    },
    {
      "x": -8,
      "y": 36,
      "z": 12,
      "name": "Rock_Shale"
    },
    {
      "x": -8,
      "y": 37,
      "z": 12,
      "name": "Rock_Shale"
    },
    {
      "x": -8,
      "y": 38,
      "z": 12,
      "name": "Rock_Shale"
    },
    {
      "x": -8,
      "y": 39,
      "z": 12,
      "name": "Rock_Shale"
    },
    {
      "x": -8,
      "y": 40,
      "z": 12,
      "name": "Rock_Basalt"
    },
    {
      "x": -8,
      "y": 41,
      "z": 12,
      "name": "Rock_Basalt"
    },
    {
      "x": -8,
      "y": 42,
      "z": 12,
      "name": "Rock_Basalt"
    },
    {
      "x": -8,
      "y": 35,
      "z": 13,
      "name": "Rock_Shale_Cobble"
    },
    {
      "x": -8,
      "y": 36,
      "z": 13,
      "name": "Rock_Shale"
    },
    {
      "x": -8,
      "y": 37,
      "z": 13,
      "name": "Rock_Shale"
    },
    {
      "x": -8,
      "y": 38,
      "z": 13,
      "name": "Rock_Shale"
    },
    {
      "x": -8,
      "y": 39,
      "z": 13,
      "name": "Rock_Shale"
    },
    {
      "x": -8,
      "y": 40,
      "z": 13,
      "name": "Rock_Basalt"
    },
    {
      "x": -8,
      "y": 41,
      "z": 13,
      "name": "Rock_Basalt"
    },
    {
      "x": -8,
      "y": 42,
      "z": 13,
      "name": "Rock_Basalt"
    },
    {
      "x": -8,
      "y": 35,
      "z": 14,
      "name": "Rock_Shale_Cobble"
    },
    {
      "x": -8,
      "y": 36,
      "z": 14,
      "name": "Rock_Shale"
    },
    {
      "x": -8,
      "y": 37,
      "z": 14,
      "name": "Rock_Shale"
    },
    {
      "x": -8,
      "y": 38,
      "z": 14,
      "name": "Rock_Shale"
    },
    {
      "x": -8,
      "y": 39,
      "z": 14,
      "name": "Rock_Shale"
    },
    {
      "x": -8,
      "y": 40,
      "z": 14,
      "name": "Rock_Shale"
    },
    {
      "x": -8,
      "y": 41,
      "z": 14,
      "name": "Rock_Basalt"
    },
    {
      "x": -8,
      "y": 42,
      "z": 14,
      "name": "Rock_Basalt"
    },
    {
      "x": -8,
      "y": 35,
      "z": 15,
      "name": "Rock_Shale_Cobble"
    },
    {
      "x": -8,
      "y": 36,
      "z": 15,
      "name": "Rock_Shale"
    },
    {
      "x": -8,
      "y": 37,
      "z": 15,
      "name": "Rock_Shale"
    },
    {
      "x": -8,
      "y": 38,
      "z": 15,
      "name": "Rock_Shale"
    },
    {
      "x": -8,
      "y": 39,
      "z": 15,
      "name": "Rock_Shale"
    },
    {
      "x": -8,
      "y": 40,
      "z": 15,
      "name": "Rock_Shale"
    },
    {
      "x": -8,
      "y": 41,
      "z": 15,
      "name": "Rock_Shale"
    },
    {
      "x": -8,
      "y": 42,
      "z": 15,
      "name": "Rock_Basalt"
    },
    {
      "x": -8,
      "y": 35,
      "z": 16,
      "name": "Rock_Shale_Cobble"
    },
    {
      "x": -8,
      "y": 36,
      "z": 16,
      "name": "Rock_Shale"
    },
    {
      "x": -8,
      "y": 37,
      "z": 16,
      "name": "Rock_Shale"
    },
    {
      "x": -8,
      "y": 38,
      "z": 16,
      "name": "Rock_Shale"
    },
    {
      "x": -8,
      "y": 39,
      "z": 16,
      "name": "Rock_Shale"
    },
    {
      "x": -8,
      "y": 40,
      "z": 16,
      "name": "Rock_Shale"
    },
    {
      "x": -8,
      "y": 41,
      "z": 16,
      "name": "Rock_Shale"
    },
    {
      "x": -8,
      "y": 42,
      "z": 16,
      "name": "Rock_Basalt"
    },
    {
      "x": -8,
      "y": 35,
      "z": 17,
      "name": "Rock_Shale_Cobble"
    },
    {
      "x": -8,
      "y": 36,
      "z": 17,
      "name": "Rock_Shale"
    },
    {
      "x": -8,
      "y": 37,
      "z": 17,
      "name": "Rock_Shale"
    },
    {
      "x": -8,
      "y": 38,
      "z": 17,
      "name": "Rock_Shale"
    },
    {
      "x": -8,
      "y": 39,
      "z": 17,
      "name": "Rock_Shale"
    },
    {
      "x": -8,
      "y": 40,
      "z": 17,
      "name": "Rock_Shale"
    },
    {
      "x": -8,
      "y": 41,
      "z": 17,
      "name": "Rock_Basalt"
    },
    {
      "x": -8,
      "y": 42,
      "z": 17,
      "name": "Rock_Basalt"
    },
    {
      "x": -8,
      "y": 35,
      "z": 18,
      "name": "Rock_Shale_Cobble"
    },
    {
      "x": -8,
      "y": 36,
      "z": 18,
      "name": "Rock_Shale"
    },
    {
      "x": -8,
      "y": 37,
      "z": 18,
      "name": "Rock_Shale"
    },
    {
      "x": -8,
      "y": 38,
      "z": 18,
      "name": "Rock_Shale"
    },
    {
      "x": -8,
      "y": 39,
      "z": 18,
      "name": "Rock_Basalt"
    },
    {
      "x": -8,
      "y": 40,
      "z": 18,
      "name": "Rock_Basalt"
    },
    {
      "x": -8,
      "y": 41,
      "z": 18,
      "name": "Rock_Basalt"
    },
    {
      "x": -8,
      "y": 42,
      "z": 18,
      "name": "Rock_Basalt"
    },
    {
      "x": -8,
      "y": 35,
      "z": 19,
      "name": "Rock_Shale_Cobble"
    },
    {
      "x": -8,
      "y": 36,
      "z": 19,
      "name": "Rock_Shale"
    },
    {
      "x": -8,
      "y": 37,
      "z": 19,
      "name": "Rock_Shale"
    },
    {
      "x": -8,
      "y": 38,
      "z": 19,
      "name": "Rock_Shale"
    },
    {
      "x": -8,
      "y": 39,
      "z": 19,
      "name": "Rock_Basalt"
    },
    {
      "x": -8,
      "y": 40,
      "z": 19,
      "name": "Rock_Basalt"
    },
    {
      "x": -8,
      "y": 41,
      "z": 19,
      "name": "Rock_Basalt"
    },
    {
      "x": -8,
      "y": 42,
      "z": 19,
      "name": "Rock_Basalt"
    },
    {
      "x": -8,
      "y": 35,
      "z": 20,
      "name": "Rock_Shale_Cobble"
    },
    {
      "x": -8,
      "y": 36,
      "z": 20,
      "name": "Rock_Shale"
    },
    {
      "x": -8,
      "y": 37,
      "z": 20,
      "name": "Rock_Shale"
    },
    {
      "x": -8,
      "y": 38,
      "z": 20,
      "name": "Rock_Shale"
    },
    {
      "x": -8,
      "y": 39,
      "z": 20,
      "name": "Rock_Basalt"
    },
    {
      "x": -8,
      "y": 40,
      "z": 20,
      "name": "Rock_Basalt"
    },
    {
      "x": -8,
      "y": 41,
      "z": 20,
      "name": "Rock_Basalt"
    },
    {
      "x": -8,
      "y": 42,
      "z": 20,
      "name": "Rock_Basalt"
    },
    {
      "x": -8,
      "y": 35,
      "z": 21,
      "name": "Rock_Shale_Cobble"
    },
    {
      "x": -8,
      "y": 36,
      "z": 21,
      "name": "Rock_Shale"
    },
    {
      "x": -8,
      "y": 37,
      "z": 21,
      "name": "Rock_Shale"
    },
    {
      "x": -8,
      "y": 38,
      "z": 21,
      "name": "Rock_Shale"
    },
    {
      "x": -8,
      "y": 39,
      "z": 21,
      "name": "Rock_Shale"
    },
    {
      "x": -8,
      "y": 40,
      "z": 21,
      "name": "Rock_Basalt"
    },
    {
      "x": -8,
      "y": 41,
      "z": 21,
      "name": "Rock_Basalt"
    },
    {
      "x": -8,
      "y": 42,
      "z": 21,
      "name": "Rock_Basalt"
    },
    {
      "x": -7,
      "y": 35,
      "z": 7,
      "name": "Rock_Shale_Cobble"
    },
    {
      "x": -7,
      "y": 36,
      "z": 7,
      "name": "Rock_Shale"
    },
    {
      "x": -7,
      "y": 37,
      "z": 7,
      "name": "Rock_Shale"
    },
    {
      "x": -7,
      "y": 38,
      "z": 7,
      "name": "Rock_Shale"
    },
    {
      "x": -7,
      "y": 39,
      "z": 7,
      "name": "Rock_Shale"
    },
    {
      "x": -7,
      "y": 40,
      "z": 7,
      "name": "Rock_Shale"
    },
    {
      "x": -7,
      "y": 41,
      "z": 7,
      "name": "Rock_Shale"
    },
    {
      "x": -7,
      "y": 42,
      "z": 7,
      "name": "Rock_Basalt"
    },
    {
      "x": -7,
      "y": 35,
      "z": 8,
      "name": "Rock_Shale_Cobble"
    },
    {
      "x": -7,
      "y": 36,
      "z": 8,
      "name": "Rock_Shale_Brick"
    },
    {
      "x": -7,
      "y": 37,
      "z": 8,
      "name": "Rock_Shale_Brick_Pillar_Base"
    },
    {
      "x": -7,
      "y": 38,
      "z": 8,
      "name": "Rock_Shale_Brick_Pillar_Middle"
    },
    {
      "x": -7,
      "y": 39,
      "z": 8,
      "name": "Rock_Shale_Brick_Pillar_Middle"
    },
    {
      "x": -7,
      "y": 40,
      "z": 8,
      "name": "Rock_Shale_Brick_Pillar_Middle"
    },
    {
      "x": -7,
      "y": 41,
      "z": 8,
      "name": "Rock_Shale_Brick_Pillar_Base",
      "rotation": 8
    },
    {
      "x": -7,
      "y": 42,
      "z": 8,
      "name": "Rock_Basalt"
    },
    {
      "x": -7,
      "y": 35,
      "z": 9,
      "name": "Rock_Shale_Cobble"
    },
    {
      "x": -7,
      "y": 36,
      "z": 9,
      "name": "Rock_Shale_Brick"
    },
    {
      "x": -7,
      "y": 37,
      "z": 9,
      "name": "Rock_Shale_Brick_Pillar_Base"
    },
    {
      "x": -7,
      "y": 38,
      "z": 9,
      "name": "Rock_Shale_Brick_Pillar_Middle"
    },
    {
      "x": -7,
      "y": 39,
      "z": 9,
      "name": "Rock_Shale_Brick_Pillar_Middle"
    },
    {
      "x": -7,
      "y": 40,
      "z": 9,
      "name": "Rock_Shale_Brick_Pillar_Middle"
    },
    {
      "x": -7,
      "y": 41,
      "z": 9,
      "name": "Rock_Shale_Brick_Pillar_Base",
      "rotation": 8
    },
    {
      "x": -7,
      "y": 42,
      "z": 9,
      "name": "Rock_Basalt"
    },
    {
      "x": -7,
      "y": 35,
      "z": 10,
      "name": "Rock_Shale_Cobble"
    },
    {
      "x": -7,
      "y": 36,
      "z": 10,
      "name": "Furniture_Ancient_Ladder",
      "rotation": 1
    },
    {
      "x": -7,
      "y": 37,
      "z": 10,
      "name": "Furniture_Ancient_Ladder",
      "rotation": 1
    },
    {
      "x": -7,
      "y": 38,
      "z": 10,
      "name": "Furniture_Ancient_Ladder",
      "rotation": 1
    },
    {
      "x": -7,
      "y": 39,
      "z": 10,
      "name": "Furniture_Ancient_Ladder",
      "rotation": 1
    },
    {
      "x": -7,
      "y": 40,
      "z": 10,
      "name": "Furniture_Ancient_Ladder",
      "rotation": 1
    },
    {
      "x": -7,
      "y": 41,
      "z": 10,
      "name": "Furniture_Ancient_Ladder",
      "rotation": 1
    },
    {
      "x": -7,
      "y": 42,
      "z": 10,
      "name": "Rock_Basalt"
    },
    {
      "x": -7,
      "y": 35,
      "z": 11,
      "name": "Rock_Shale_Cobble"
    },
    {
      "x": -7,
      "y": 36,
      "z": 11,
      "name": "Empty"
    },
    {
      "x": -7,
      "y": 37,
      "z": 11,
      "name": "Empty"
    },
    {
      "x": -7,
      "y": 38,
      "z": 11,
      "name": "Empty"
    },
    {
      "x": -7,
      "y": 39,
      "z": 11,
      "name": "Empty"
    },
    {
      "x": -7,
      "y": 40,
      "z": 11,
      "name": "Furniture_Ancient_Shelf",
      "rotation": 1
    },
    {
      "x": -7,
      "y": 41,
      "z": 11,
      "name": "Empty"
    },
    {
      "x": -7,
      "y": 42,
      "z": 11,
      "name": "Rock_Basalt"
    },
    {
      "x": -7,
      "y": 35,
      "z": 12,
      "name": "Rock_Shale_Cobble"
    },
    {
      "x": -7,
      "y": 36,
      "z": 12,
      "name": "Furniture_Ancient_Bookshelf",
      "rotation": 1
    },
    {
      "x": -7,
      "y": 37,
      "z": 12,
      "name": "Furniture_Ancient_Bookshelf",
      "rotation": 1
    },
    {
      "x": -7,
      "y": 38,
      "z": 12,
      "name": "Furniture_Ancient_Bookshelf",
      "rotation": 1
    },
    {
      "x": -7,
      "y": 39,
      "z": 12,
      "name": "Furniture_Ancient_Bookshelf",
      "rotation": 1
    },
    {
      "x": -7,
      "y": 40,
      "z": 12,
      "name": "Furniture_Ancient_Shelf",
      "rotation": 1
    },
    {
      "x": -7,
      "y": 41,
      "z": 12,
      "name": "Empty"
    },
    {
      "x": -7,
      "y": 42,
      "z": 12,
      "name": "Rock_Basalt"
    },
    {
      "x": -7,
      "y": 35,
      "z": 13,
      "name": "Rock_Shale_Cobble"
    },
    {
      "x": -7,
      "y": 36,
      "z": 13,
      "name": "Furniture_Ancient_Bookshelf",
      "rotation": 1
    },
    {
      "x": -7,
      "y": 37,
      "z": 13,
      "name": "Furniture_Ancient_Bookshelf",
      "rotation": 1
    },
    {
      "x": -7,
      "y": 38,
      "z": 13,
      "name": "Furniture_Ancient_Bookshelf",
      "rotation": 1
    },
    {
      "x": -7,
      "y": 39,
      "z": 13,
      "name": "Furniture_Ancient_Bookshelf",
      "rotation": 1
    },
    {
      "x": -7,
      "y": 40,
      "z": 13,
      "name": "Furniture_Ancient_Shelf",
      "rotation": 1
    },
    {
      "x": -7,
      "y": 41,
      "z": 13,
      "name": "Empty"
    },
    {
      "x": -7,
      "y": 42,
      "z": 13,
      "name": "Rock_Basalt"
    },
    {
      "x": -7,
      "y": 35,
      "z": 14,
      "name": "Rock_Shale_Cobble"
    },
    {
      "x": -7,
      "y": 36,
      "z": 14,
      "name": "Rock_Shale_Brick"
    },
    {
      "x": -7,
      "y": 37,
      "z": 14,
      "name": "Rock_Shale_Brick"
    },
    {
      "x": -7,
      "y": 38,
      "z": 14,
      "name": "Rock_Shale_Brick"
    },
    {
      "x": -7,
      "y": 39,
      "z": 14,
      "name": "Rock_Shale_Brick"
    },
    {
      "x": -7,
      "y": 40,
      "z": 14,
      "name": "Rock_Shale_Brick"
    },
    {
      "x": -7,
      "y": 41,
      "z": 14,
      "name": "Rock_Shale_Brick"
    },
    {
      "x": -7,
      "y": 42,
      "z": 14,
      "name": "Rock_Basalt"
    },
    {
      "x": -7,
      "y": 35,
      "z": 15,
      "name": "Rock_Shale_Cobble"
    },
    {
      "x": -7,
      "y": 36,
      "z": 15,
      "name": "Rock_Shale_Brick_Smooth"
    },
    {
      "x": -7,
      "y": 37,
      "z": 15,
      "name": "Deco_Pot_Clay_Broken",
      "components": {
        "Components": {
          "container": {
            "Position": {
              "X": -6,
              "Y": 2,
              "Z": -6
            },
            "Custom": false,
            "AllowViewing": true,
            "ItemContainer": {
              "Capacity": 20,
              "Items": {}
            }
          }
        }
      }
    },
    {
      "x": -7,
      "y": 38,
      "z": 15,
      "name": "Rock_Shale_Brick_Smooth"
    },
    {
      "x": -7,
      "y": 39,
      "z": 15,
      "name": "Furniture_Temple_Dark_Pot"
    },
    {
      "x": -7,
      "y": 40,
      "z": 15,
      "name": "Rock_Shale_Brick_Smooth"
    },
    {
      "x": -7,
      "y": 41,
      "z": 15,
      "name": "Furniture_Temple_Dark_Pot"
    },
    {
      "x": -7,
      "y": 42,
      "z": 15,
      "name": "Rock_Basalt"
    },
    {
      "x": -7,
      "y": 35,
      "z": 16,
      "name": "Rock_Shale_Cobble"
    },
    {
      "x": -7,
      "y": 36,
      "z": 16,
      "name": "Rock_Shale_Brick_Smooth"
    },
    {
      "x": -7,
      "y": 37,
      "z": 16,
      "name": "Furniture_Temple_Dark_Pot"
    },
    {
      "x": -7,
      "y": 38,
      "z": 16,
      "name": "Rock_Shale_Brick_Smooth"
    },
    {
      "x": -7,
      "y": 39,
      "z": 16,
      "name": "Potion_Regen_Mana"
    },
    {
      "x": -7,
      "y": 40,
      "z": 16,
      "name": "Rock_Shale_Brick_Smooth"
    },
    {
      "x": -7,
      "y": 41,
      "z": 16,
      "name": "Furniture_Temple_Dark_Pot"
    },
    {
      "x": -7,
      "y": 42,
      "z": 16,
      "name": "Rock_Basalt"
    },
    {
      "x": -7,
      "y": 35,
      "z": 17,
      "name": "Rock_Shale_Cobble"
    },
    {
      "x": -7,
      "y": 36,
      "z": 17,
      "name": "Rock_Shale_Brick_Smooth"
    },
    {
      "x": -7,
      "y": 37,
      "z": 17,
      "name": "Potion_Mana_Large"
    },
    {
      "x": -7,
      "y": 38,
      "z": 17,
      "name": "Rock_Shale_Brick_Smooth"
    },
    {
      "x": -7,
      "y": 39,
      "z": 17,
      "name": "Empty"
    },
    {
      "x": -7,
      "y": 40,
      "z": 17,
      "name": "Rock_Shale_Brick_Smooth"
    },
    {
      "x": -7,
      "y": 41,
      "z": 17,
      "name": "Deco_Pot_Clay_Broken",
      "components": {
        "Components": {
          "container": {
            "Position": {
              "X": -6,
              "Y": 6,
              "Z": -4
            },
            "Custom": false,
            "AllowViewing": true,
            "ItemContainer": {
              "Capacity": 20,
              "Items": {}
            }
          }
        }
      }
    },
    {
      "x": -7,
      "y": 42,
      "z": 17,
      "name": "Rock_Basalt"
    },
    {
      "x": -7,
      "y": 35,
      "z": 18,
      "name": "Rock_Shale_Cobble"
    },
    {
      "x": -7,
      "y": 36,
      "z": 18,
      "name": "Rock_Shale_Brick_Smooth"
    },
    {
      "x": -7,
      "y": 37,
      "z": 18,
      "name": "Empty"
    },
    {
      "x": -7,
      "y": 38,
      "z": 18,
      "name": "Rock_Shale_Brick_Smooth"
    },
    {
      "x": -7,
      "y": 39,
      "z": 18,
      "name": "Furniture_Temple_Dark_Pot"
    },
    {
      "x": -7,
      "y": 40,
      "z": 18,
      "name": "Rock_Shale_Brick_Smooth"
    },
    {
      "x": -7,
      "y": 41,
      "z": 18,
      "name": "Empty"
    },
    {
      "x": -7,
      "y": 42,
      "z": 18,
      "name": "Rock_Basalt"
    },
    {
      "x": -7,
      "y": 35,
      "z": 19,
      "name": "Rock_Shale_Brick"
    },
    {
      "x": -7,
      "y": 36,
      "z": 19,
      "name": "Rock_Shale_Brick"
    },
    {
      "x": -7,
      "y": 37,
      "z": 19,
      "name": "Rock_Shale_Brick"
    },
    {
      "x": -7,
      "y": 38,
      "z": 19,
      "name": "Rock_Shale_Brick"
    },
    {
      "x": -7,
      "y": 39,
      "z": 19,
      "name": "Rock_Shale_Brick"
    },
    {
      "x": -7,
      "y": 40,
      "z": 19,
      "name": "Rock_Shale_Brick"
    },
    {
      "x": -7,
      "y": 41,
      "z": 19,
      "name": "Rock_Shale_Brick"
    },
    {
      "x": -7,
      "y": 42,
      "z": 19,
      "name": "Rock_Basalt"
    },
    {
      "x": -7,
      "y": 35,
      "z": 20,
      "name": "Rock_Shale_Brick"
    },
    {
      "x": -7,
      "y": 36,
      "z": 20,
      "name": "Rock_Shale_Brick"
    },
    {
      "x": -7,
      "y": 37,
      "z": 20,
      "name": "Rock_Shale_Brick"
    },
    {
      "x": -7,
      "y": 38,
      "z": 20,
      "name": "Rock_Shale_Brick"
    },
    {
      "x": -7,
      "y": 39,
      "z": 20,
      "name": "Rock_Shale_Brick"
    },
    {
      "x": -7,
      "y": 40,
      "z": 20,
      "name": "Rock_Shale_Brick"
    },
    {
      "x": -7,
      "y": 41,
      "z": 20,
      "name": "Rock_Shale_Brick"
    },
    {
      "x": -7,
      "y": 42,
      "z": 20,
      "name": "Rock_Basalt"
    },
    {
      "x": -7,
      "y": 35,
      "z": 21,
      "name": "Rock_Shale_Cobble"
    },
    {
      "x": -7,
      "y": 36,
      "z": 21,
      "name": "Rock_Shale"
    },
    {
      "x": -7,
      "y": 37,
      "z": 21,
      "name": "Rock_Shale"
    },
    {
      "x": -7,
      "y": 38,
      "z": 21,
      "name": "Rock_Shale"
    },
    {
      "x": -7,
      "y": 39,
      "z": 21,
      "name": "Rock_Shale"
    },
    {
      "x": -7,
      "y": 40,
      "z": 21,
      "name": "Rock_Shale"
    },
    {
      "x": -7,
      "y": 41,
      "z": 21,
      "name": "Rock_Basalt"
    },
    {
      "x": -7,
      "y": 42,
      "z": 21,
      "name": "Rock_Basalt"
    },
    {
      "x": -6,
      "y": 35,
      "z": 7,
      "name": "Rock_Shale_Cobble"
    },
    {
      "x": -6,
      "y": 36,
      "z": 7,
      "name": "Rock_Shale"
    },
    {
      "x": -6,
      "y": 37,
      "z": 7,
      "name": "Rock_Shale"
    },
    {
      "x": -6,
      "y": 38,
      "z": 7,
      "name": "Rock_Shale"
    },
    {
      "x": -6,
      "y": 39,
      "z": 7,
      "name": "Rock_Shale"
    },
    {
      "x": -6,
      "y": 40,
      "z": 7,
      "name": "Rock_Shale"
    },
    {
      "x": -6,
      "y": 41,
      "z": 7,
      "name": "Rock_Basalt"
    },
    {
      "x": -6,
      "y": 42,
      "z": 7,
      "name": "Rock_Basalt"
    },
    {
      "x": -6,
      "y": 35,
      "z": 8,
      "name": "Rock_Shale_Cobble"
    },
    {
      "x": -6,
      "y": 36,
      "z": 8,
      "name": "Rock_Shale_Brick"
    },
    {
      "x": -6,
      "y": 37,
      "z": 8,
      "name": "Rock_Shale_Brick_Pillar_Base"
    },
    {
      "x": -6,
      "y": 38,
      "z": 8,
      "name": "Rock_Shale_Brick_Pillar_Middle"
    },
    {
      "x": -6,
      "y": 39,
      "z": 8,
      "name": "Rock_Shale_Brick_Pillar_Middle"
    },
    {
      "x": -6,
      "y": 40,
      "z": 8,
      "name": "Rock_Shale_Brick_Pillar_Middle"
    },
    {
      "x": -6,
      "y": 41,
      "z": 8,
      "name": "Rock_Shale_Brick_Pillar_Base",
      "rotation": 8
    },
    {
      "x": -6,
      "y": 42,
      "z": 8,
      "name": "Rock_Basalt"
    },
    {
      "x": -6,
      "y": 35,
      "z": 9,
      "name": "Rock_Shale_Cobble"
    },
    {
      "x": -6,
      "y": 36,
      "z": 9,
      "name": "Rock_Shale_Brick"
    },
    {
      "x": -6,
      "y": 37,
      "z": 9,
      "name": "Rock_Shale_Brick_Pillar_Base"
    },
    {
      "x": -6,
      "y": 38,
      "z": 9,
      "name": "Rock_Shale_Brick_Pillar_Middle"
    },
    {
      "x": -6,
      "y": 39,
      "z": 9,
      "name": "Rock_Shale_Brick_Pillar_Middle"
    },
    {
      "x": -6,
      "y": 40,
      "z": 9,
      "name": "Rock_Shale_Brick_Pillar_Middle"
    },
    {
      "x": -6,
      "y": 41,
      "z": 9,
      "name": "Rock_Shale_Brick_Pillar_Base",
      "rotation": 8
    },
    {
      "x": -6,
      "y": 42,
      "z": 9,
      "name": "Rock_Basalt"
    },
    {
      "x": -6,
      "y": 35,
      "z": 10,
      "name": "Soil_Dirt_Cold"
    },
    {
      "x": -6,
      "y": 36,
      "z": 10,
      "name": "Empty"
    },
    {
      "x": -6,
      "y": 37,
      "z": 10,
      "name": "Empty"
    },
    {
      "x": -6,
      "y": 38,
      "z": 10,
      "name": "Empty"
    },
    {
      "x": -6,
      "y": 39,
      "z": 10,
      "name": "Empty"
    },
    {
      "x": -6,
      "y": 40,
      "z": 10,
      "name": "Empty"
    },
    {
      "x": -6,
      "y": 41,
      "z": 10,
      "name": "Empty"
    },
    {
      "x": -6,
      "y": 42,
      "z": 10,
      "name": "Rock_Basalt"
    },
    {
      "x": -6,
      "y": 35,
      "z": 11,
      "name": "Rock_Shale_Cobble"
    },
    {
      "x": -6,
      "y": 36,
      "z": 11,
      "name": "Empty"
    },
    {
      "x": -6,
      "y": 37,
      "z": 11,
      "name": "Empty"
    },
    {
      "x": -6,
      "y": 38,
      "z": 11,
      "name": "Empty"
    },
    {
      "x": -6,
      "y": 39,
      "z": 11,
      "name": "Empty"
    },
    {
      "x": -6,
      "y": 40,
      "z": 11,
      "name": "Empty"
    },
    {
      "x": -6,
      "y": 41,
      "z": 11,
      "name": "Empty"
    },
    {
      "x": -6,
      "y": 42,
      "z": 11,
      "name": "Rock_Basalt"
    },
    {
      "x": -6,
      "y": 35,
      "z": 12,
      "name": "Rock_Shale_Cobble"
    },
    {
      "x": -6,
      "y": 36,
      "z": 12,
      "name": "Empty"
    },
    {
      "x": -6,
      "y": 37,
      "z": 12,
      "name": "Empty"
    },
    {
      "x": -6,
      "y": 38,
      "z": 12,
      "name": "Empty"
    },
    {
      "x": -6,
      "y": 39,
      "z": 12,
      "name": "Empty"
    },
    {
      "x": -6,
      "y": 40,
      "z": 12,
      "name": "Empty"
    },
    {
      "x": -6,
      "y": 41,
      "z": 12,
      "name": "Empty"
    },
    {
      "x": -6,
      "y": 42,
      "z": 12,
      "name": "Rock_Basalt"
    },
    {
      "x": -6,
      "y": 35,
      "z": 13,
      "name": "Rock_Shale_Cobble"
    },
    {
      "x": -6,
      "y": 36,
      "z": 13,
      "name": "Block_Spawner_Block",
      "components": {
        "Components": {
          "PlacedByInteraction": {
            "WhoPlacedUuid": {
              "$binary": "x9M0GYCLPG+IqIodoDzEcQ==",
              "$type": "04"
            }
          },
          "BlockSpawner": {
            "BlockSpawnerId": "Zone3_Encounters_Tier2"
          }
        }
      },
      "rotation": 1
    },
    {
      "x": -6,
      "y": 37,
      "z": 13,
      "name": "Empty"
    },
    {
      "x": -6,
      "y": 38,
      "z": 13,
      "name": "Empty"
    },
    {
      "x": -6,
      "y": 39,
      "z": 13,
      "name": "Empty"
    },
    {
      "x": -6,
      "y": 40,
      "z": 13,
      "name": "Empty"
    },
    {
      "x": -6,
      "y": 41,
      "z": 13,
      "name": "Empty"
    },
    {
      "x": -6,
      "y": 42,
      "z": 13,
      "name": "Rock_Basalt"
    },
    {
      "x": -6,
      "y": 35,
      "z": 14,
      "name": "Rock_Shale_Cobble"
    },
    {
      "x": -6,
      "y": 36,
      "z": 14,
      "name": "Furniture_Temple_Dark_Pot"
    },
    {
      "x": -6,
      "y": 37,
      "z": 14,
      "name": "Empty"
    },
    {
      "x": -6,
      "y": 38,
      "z": 14,
      "name": "Empty"
    },
    {
      "x": -6,
      "y": 39,
      "z": 14,
      "name": "Rock_Stone_Stalactite_Large",
      "filler": 31744,
      "rotation": 8
    },
    {
      "x": -6,
      "y": 40,
      "z": 14,
      "name": "Rock_Stone_Stalactite_Large",
      "rotation": 8
    },
    {
      "x": -6,
      "y": 41,
      "z": 14,
      "name": "Rock_Basalt"
    },
    {
      "x": -6,
      "y": 42,
      "z": 14,
      "name": "Rock_Basalt"
    },
    {
      "x": -6,
      "y": 35,
      "z": 15,
      "name": "Rock_Shale_Cobble"
    },
    {
      "x": -6,
      "y": 36,
      "z": 15,
      "name": "Furniture_Ancient_Pot"
    },
    {
      "x": -6,
      "y": 38,
      "z": 15,
      "name": "Empty"
    },
    {
      "x": -6,
      "y": 39,
      "z": 15,
      "name": "Empty"
    },
    {
      "x": -6,
      "y": 40,
      "z": 15,
      "name": "Empty"
    },
    {
      "x": -6,
      "y": 41,
      "z": 15,
      "name": "Empty"
    },
    {
      "x": -6,
      "y": 42,
      "z": 15,
      "name": "Rock_Basalt"
    },
    {
      "x": -6,
      "y": 35,
      "z": 16,
      "name": "Rock_Shale_Cobble"
    },
    {
      "x": -6,
      "y": 36,
      "z": 16,
      "name": "Empty"
    },
    {
      "x": -6,
      "y": 37,
      "z": 16,
      "name": "Empty"
    },
    {
      "x": -6,
      "y": 38,
      "z": 16,
      "name": "Empty"
    },
    {
      "x": -6,
      "y": 39,
      "z": 16,
      "name": "Empty"
    },
    {
      "x": -6,
      "y": 40,
      "z": 16,
      "name": "Empty"
    },
    {
      "x": -6,
      "y": 41,
      "z": 16,
      "name": "Empty"
    },
    {
      "x": -6,
      "y": 42,
      "z": 16,
      "name": "Rock_Basalt"
    },
    {
      "x": -6,
      "y": 35,
      "z": 17,
      "name": "Rock_Shale_Cobble"
    },
    {
      "x": -6,
      "y": 36,
      "z": 17,
      "name": "Empty"
    },
    {
      "x": -6,
      "y": 37,
      "z": 17,
      "name": "Empty"
    },
    {
      "x": -6,
      "y": 38,
      "z": 17,
      "name": "Empty"
    },
    {
      "x": -6,
      "y": 39,
      "z": 17,
      "name": "Empty"
    },
    {
      "x": -6,
      "y": 40,
      "z": 17,
      "name": "Empty"
    },
    {
      "x": -6,
      "y": 41,
      "z": 17,
      "name": "Empty"
    },
    {
      "x": -6,
      "y": 42,
      "z": 17,
      "name": "Rock_Basalt"
    },
    {
      "x": -6,
      "y": 35,
      "z": 18,
      "name": "Rock_Shale_Cobble"
    },
    {
      "x": -6,
      "y": 36,
      "z": 18,
      "name": "Empty"
    },
    {
      "x": -6,
      "y": 37,
      "z": 18,
      "name": "Empty"
    },
    {
      "x": -6,
      "y": 38,
      "z": 18,
      "name": "Empty"
    },
    {
      "x": -6,
      "y": 39,
      "z": 18,
      "name": "Empty"
    },
    {
      "x": -6,
      "y": 40,
      "z": 18,
      "name": "Empty"
    },
    {
      "x": -6,
      "y": 41,
      "z": 18,
      "name": "Empty"
    },
    {
      "x": -6,
      "y": 42,
      "z": 18,
      "name": "Rock_Basalt"
    },
    {
      "x": -6,
      "y": 35,
      "z": 19,
      "name": "Rock_Shale_Brick"
    },
    {
      "x": -6,
      "y": 36,
      "z": 19,
      "name": "Rock_Shale_Brick"
    },
    {
      "x": -6,
      "y": 37,
      "z": 19,
      "name": "Rock_Shale_Brick"
    },
    {
      "x": -6,
      "y": 38,
      "z": 19,
      "name": "Rock_Shale_Brick"
    },
    {
      "x": -6,
      "y": 39,
      "z": 19,
      "name": "Rock_Shale_Brick"
    },
    {
      "x": -6,
      "y": 40,
      "z": 19,
      "name": "Rock_Shale_Brick"
    },
    {
      "x": -6,
      "y": 41,
      "z": 19,
      "name": "Rock_Shale_Brick"
    },
    {
      "x": -6,
      "y": 42,
      "z": 19,
      "name": "Rock_Basalt"
    },
    {
      "x": -6,
      "y": 35,
      "z": 20,
      "name": "Rock_Shale_Brick"
    },
    {
      "x": -6,
      "y": 36,
      "z": 20,
      "name": "Rock_Shale_Brick"
    },
    {
      "x": -6,
      "y": 37,
      "z": 20,
      "name": "Rock_Shale_Brick"
    },
    {
      "x": -6,
      "y": 38,
      "z": 20,
      "name": "Rock_Shale_Brick"
    },
    {
      "x": -6,
      "y": 39,
      "z": 20,
      "name": "Rock_Shale_Brick"
    },
    {
      "x": -6,
      "y": 40,
      "z": 20,
      "name": "Rock_Shale_Brick"
    },
    {
      "x": -6,
      "y": 41,
      "z": 20,
      "name": "Rock_Shale_Brick"
    },
    {
      "x": -6,
      "y": 42,
      "z": 20,
      "name": "Rock_Basalt"
    },
    {
      "x": -6,
      "y": 35,
      "z": 21,
      "name": "Rock_Shale_Cobble"
    },
    {
      "x": -6,
      "y": 36,
      "z": 21,
      "name": "Rock_Shale"
    },
    {
      "x": -6,
      "y": 37,
      "z": 21,
      "name": "Rock_Shale"
    },
    {
      "x": -6,
      "y": 38,
      "z": 21,
      "name": "Rock_Shale"
    },
    {
      "x": -6,
      "y": 39,
      "z": 21,
      "name": "Rock_Shale"
    },
    {
      "x": -6,
      "y": 40,
      "z": 21,
      "name": "Rock_Shale"
    },
    {
      "x": -6,
      "y": 41,
      "z": 21,
      "name": "Rock_Shale"
    },
    {
      "x": -6,
      "y": 42,
      "z": 21,
      "name": "Rock_Basalt"
    },
    {
      "x": -5,
      "y": 35,
      "z": 7,
      "name": "Rock_Shale_Cobble"
    },
    {
      "x": -5,
      "y": 36,
      "z": 7,
      "name": "Rock_Shale"
    },
    {
      "x": -5,
      "y": 37,
      "z": 7,
      "name": "Rock_Shale"
    },
    {
      "x": -5,
      "y": 38,
      "z": 7,
      "name": "Rock_Shale"
    },
    {
      "x": -5,
      "y": 39,
      "z": 7,
      "name": "Rock_Shale"
    },
    {
      "x": -5,
      "y": 40,
      "z": 7,
      "name": "Rock_Basalt"
    },
    {
      "x": -5,
      "y": 41,
      "z": 7,
      "name": "Rock_Basalt"
    },
    {
      "x": -5,
      "y": 42,
      "z": 7,
      "name": "Rock_Basalt"
    },
    {
      "x": -5,
      "y": 35,
      "z": 8,
      "name": "Rock_Shale_Cobble"
    },
    {
      "x": -5,
      "y": 36,
      "z": 8,
      "name": "Rock_Basalt_Brick"
    },
    {
      "x": -5,
      "y": 37,
      "z": 8,
      "name": "Rock_Basalt_Brick"
    },
    {
      "x": -5,
      "y": 38,
      "z": 8,
      "name": "Rock_Basalt_Brick"
    },
    {
      "x": -5,
      "y": 39,
      "z": 8,
      "name": "Rock_Basalt_Brick"
    },
    {
      "x": -5,
      "y": 40,
      "z": 8,
      "name": "Rock_Basalt_Brick"
    },
    {
      "x": -5,
      "y": 41,
      "z": 8,
      "name": "Rock_Basalt_Brick"
    },
    {
      "x": -5,
      "y": 42,
      "z": 8,
      "name": "Rock_Basalt"
    },
    {
      "x": -5,
      "y": 35,
      "z": 9,
      "name": "Rock_Shale_Cobble"
    },
    {
      "x": -5,
      "y": 36,
      "z": 9,
      "name": "Rock_Basalt_Brick"
    },
    {
      "x": -5,
      "y": 37,
      "z": 9,
      "name": "Rock_Basalt_Brick"
    },
    {
      "x": -5,
      "y": 38,
      "z": 9,
      "name": "Rock_Basalt_Brick"
    },
    {
      "x": -5,
      "y": 39,
      "z": 9,
      "name": "Rock_Basalt_Brick"
    },
    {
      "x": -5,
      "y": 40,
      "z": 9,
      "name": "Rock_Basalt_Brick"
    },
    {
      "x": -5,
      "y": 41,
      "z": 9,
      "name": "Rock_Basalt_Brick"
    },
    {
      "x": -5,
      "y": 42,
      "z": 9,
      "name": "Rock_Basalt"
    },
    {
      "x": -5,
      "y": 35,
      "z": 10,
      "name": "Soil_Dirt_Cold"
    },
    {
      "x": -5,
      "y": 36,
      "z": 10,
      "name": "Rubble_Basalt_Medium"
    },
    {
      "x": -5,
      "y": 37,
      "z": 10,
      "name": "Empty"
    },
    {
      "x": -5,
      "y": 38,
      "z": 10,
      "name": "Empty"
    },
    {
      "x": -5,
      "y": 39,
      "z": 10,
      "name": "Empty"
    },
    {
      "x": -5,
      "y": 40,
      "z": 10,
      "name": "Empty"
    },
    {
      "x": -5,
      "y": 41,
      "z": 10,
      "name": "Empty"
    },
    {
      "x": -5,
      "y": 42,
      "z": 10,
      "name": "Rock_Basalt"
    },
    {
      "x": -5,
      "y": 35,
      "z": 11,
      "name": "Soil_Dirt_Cold"
    },
    {
      "x": -5,
      "y": 36,
      "z": 11,
      "name": "Empty"
    },
    {
      "x": -5,
      "y": 37,
      "z": 11,
      "name": "Empty"
    },
    {
      "x": -5,
      "y": 38,
      "z": 11,
      "name": "Empty"
    },
    {
      "x": -5,
      "y": 39,
      "z": 11,
      "name": "Empty"
    },
    {
      "x": -5,
      "y": 40,
      "z": 11,
      "name": "Empty"
    },
    {
      "x": -5,
      "y": 41,
      "z": 11,
      "name": "Empty"
    },
    {
      "x": -5,
      "y": 42,
      "z": 11,
      "name": "Rock_Basalt"
    },
    {
      "x": -5,
      "y": 35,
      "z": 12,
      "name": "Soil_Dirt_Cold"
    },
    {
      "x": -5,
      "y": 36,
      "z": 12,
      "name": "Empty"
    },
    {
      "x": -5,
      "y": 37,
      "z": 12,
      "name": "Empty"
    },
    {
      "x": -5,
      "y": 38,
      "z": 12,
      "name": "Empty"
    },
    {
      "x": -5,
      "y": 39,
      "z": 12,
      "name": "Empty"
    },
    {
      "x": -5,
      "y": 40,
      "z": 12,
      "name": "Empty"
    },
    {
      "x": -5,
      "y": 41,
      "z": 12,
      "name": "Empty"
    },
    {
      "x": -5,
      "y": 42,
      "z": 12,
      "name": "Rock_Basalt"
    },
    {
      "x": -5,
      "y": 35,
      "z": 13,
      "name": "Rock_Basalt"
    },
    {
      "x": -5,
      "y": 36,
      "z": 13,
      "name": "Empty"
    },
    {
      "x": -5,
      "y": 37,
      "z": 13,
      "name": "Empty"
    },
    {
      "x": -5,
      "y": 38,
      "z": 13,
      "name": "Empty"
    },
    {
      "x": -5,
      "y": 39,
      "z": 13,
      "name": "Empty"
    },
    {
      "x": -5,
      "y": 40,
      "z": 13,
      "name": "Rock_Stone_Stalactite_Small",
      "rotation": 8
    },
    {
      "x": -5,
      "y": 41,
      "z": 13,
      "name": "Rock_Basalt"
    },
    {
      "x": -5,
      "y": 42,
      "z": 13,
      "name": "Rock_Basalt"
    },
    {
      "x": -5,
      "y": 35,
      "z": 14,
      "name": "Rock_Basalt"
    },
    {
      "x": -5,
      "y": 36,
      "z": 14,
      "name": "Rubble_Basalt"
    },
    {
      "x": -5,
      "y": 37,
      "z": 14,
      "name": "Empty"
    },
    {
      "x": -5,
      "y": 38,
      "z": 14,
      "name": "Empty"
    },
    {
      "x": -5,
      "y": 39,
      "z": 14,
      "name": "Empty"
    },
    {
      "x": -5,
      "y": 40,
      "z": 14,
      "name": "Empty"
    },
    {
      "x": -5,
      "y": 41,
      "z": 14,
      "name": "Rock_Basalt"
    },
    {
      "x": -5,
      "y": 42,
      "z": 14,
      "name": "Rock_Basalt"
    },
    {
      "x": -5,
      "y": 35,
      "z": 15,
      "name": "Rock_Shale_Cobble"
    },
    {
      "x": -5,
      "y": 36,
      "z": 15,
      "name": "Empty"
    },
    {
      "x": -5,
      "y": 37,
      "z": 15,
      "name": "Empty"
    },
    {
      "x": -5,
      "y": 38,
      "z": 15,
      "name": "Empty"
    },
    {
      "x": -5,
      "y": 39,
      "z": 15,
      "name": "Empty"
    },
    {
      "x": -5,
      "y": 40,
      "z": 15,
      "name": "Empty"
    },
    {
      "x": -5,
      "y": 41,
      "z": 15,
      "name": "Rock_Basalt"
    },
    {
      "x": -5,
      "y": 42,
      "z": 15,
      "name": "Rock_Basalt"
    },
    {
      "x": -5,
      "y": 35,
      "z": 16,
      "name": "Rock_Shale_Cobble"
    },
    {
      "x": -5,
      "y": 36,
      "z": 16,
      "name": "Empty"
    },
    {
      "x": -5,
      "y": 37,
      "z": 16,
      "name": "Empty"
    },
    {
      "x": -5,
      "y": 38,
      "z": 16,
      "name": "Empty"
    },
    {
      "x": -5,
      "y": 39,
      "z": 16,
      "name": "Empty"
    },
    {
      "x": -5,
      "y": 40,
      "z": 16,
      "name": "Empty"
    },
    {
      "x": -5,
      "y": 41,
      "z": 16,
      "name": "Plant_Bush_Dead_Hanging"
    },
    {
      "x": -5,
      "y": 42,
      "z": 16,
      "name": "Rock_Basalt"
    },
    {
      "x": -5,
      "y": 35,
      "z": 17,
      "name": "Rock_Shale_Cobble"
    },
    {
      "x": -5,
      "y": 36,
      "z": 17,
      "name": "Empty"
    },
    {
      "x": -5,
      "y": 37,
      "z": 17,
      "name": "Empty"
    },
    {
      "x": -5,
      "y": 38,
      "z": 17,
      "name": "Empty"
    },
    {
      "x": -5,
      "y": 39,
      "z": 17,
      "name": "Empty"
    },
    {
      "x": -5,
      "y": 40,
      "z": 17,
      "name": "Empty"
    },
    {
      "x": -5,
      "y": 41,
      "z": 17,
      "name": "Empty"
    },
    {
      "x": -5,
      "y": 42,
      "z": 17,
      "name": "Rock_Basalt"
    },
    {
      "x": -5,
      "y": 35,
      "z": 18,
      "name": "Rock_Shale_Cobble"
    },
    {
      "x": -5,
      "y": 36,
      "z": 18,
      "name": "Empty"
    },
    {
      "x": -5,
      "y": 37,
      "z": 18,
      "name": "Empty"
    },
    {
      "x": -5,
      "y": 38,
      "z": 18,
      "name": "Empty"
    },
    {
      "x": -5,
      "y": 39,
      "z": 18,
      "name": "Empty"
    },
    {
      "x": -5,
      "y": 40,
      "z": 18,
      "name": "Empty"
    },
    {
      "x": -5,
      "y": 41,
      "z": 18,
      "name": "Empty"
    },
    {
      "x": -5,
      "y": 42,
      "z": 18,
      "name": "Rock_Basalt"
    },
    {
      "x": -5,
      "y": 35,
      "z": 19,
      "name": "Rock_Shale_Cobble"
    },
    {
      "x": -5,
      "y": 36,
      "z": 19,
      "name": "Empty"
    },
    {
      "x": -5,
      "y": 37,
      "z": 19,
      "name": "Empty"
    },
    {
      "x": -5,
      "y": 38,
      "z": 19,
      "name": "Empty"
    },
    {
      "x": -5,
      "y": 39,
      "z": 19,
      "name": "Empty"
    },
    {
      "x": -5,
      "y": 40,
      "z": 19,
      "name": "Empty"
    },
    {
      "x": -5,
      "y": 41,
      "z": 19,
      "name": "Rock_Shale_Brick_Stairs",
      "rotation": 8
    },
    {
      "x": -5,
      "y": 42,
      "z": 19,
      "name": "Rock_Basalt"
    },
    {
      "x": -5,
      "y": 35,
      "z": 20,
      "name": "Rock_Shale_Cobble"
    },
    {
      "x": -5,
      "y": 36,
      "z": 20,
      "name": "Rock_Shale_Brick"
    },
    {
      "x": -5,
      "y": 37,
      "z": 20,
      "name": "Rock_Shale_Brick"
    },
    {
      "x": -5,
      "y": 38,
      "z": 20,
      "name": "Rock_Shale_Brick"
    },
    {
      "x": -5,
      "y": 39,
      "z": 20,
      "name": "Rock_Shale_Brick"
    },
    {
      "x": -5,
      "y": 40,
      "z": 20,
      "name": "Rock_Shale_Brick"
    },
    {
      "x": -5,
      "y": 41,
      "z": 20,
      "name": "Rock_Shale_Brick"
    },
    {
      "x": -5,
      "y": 42,
      "z": 20,
      "name": "Rock_Basalt"
    },
    {
      "x": -5,
      "y": 35,
      "z": 21,
      "name": "Rock_Shale_Cobble"
    },
    {
      "x": -5,
      "y": 36,
      "z": 21,
      "name": "Rock_Shale"
    },
    {
      "x": -5,
      "y": 37,
      "z": 21,
      "name": "Rock_Shale"
    },
    {
      "x": -5,
      "y": 38,
      "z": 21,
      "name": "Rock_Shale"
    },
    {
      "x": -5,
      "y": 39,
      "z": 21,
      "name": "Rock_Shale"
    },
    {
      "x": -5,
      "y": 40,
      "z": 21,
      "name": "Rock_Shale"
    },
    {
      "x": -5,
      "y": 41,
      "z": 21,
      "name": "Rock_Shale"
    },
    {
      "x": -5,
      "y": 42,
      "z": 21,
      "name": "Rock_Basalt"
    },
    {
      "x": -4,
      "y": 35,
      "z": 7,
      "name": "Rock_Basalt"
    },
    {
      "x": -4,
      "y": 36,
      "z": 7,
      "name": "Rock_Basalt"
    },
    {
      "x": -4,
      "y": 37,
      "z": 7,
      "name": "Rock_Basalt"
    },
    {
      "x": -4,
      "y": 38,
      "z": 7,
      "name": "Rock_Basalt"
    },
    {
      "x": -4,
      "y": 39,
      "z": 7,
      "name": "Rock_Basalt"
    },
    {
      "x": -4,
      "y": 40,
      "z": 7,
      "name": "Rock_Basalt"
    },
    {
      "x": -4,
      "y": 41,
      "z": 7,
      "name": "Rock_Basalt"
    },
    {
      "x": -4,
      "y": 42,
      "z": 7,
      "name": "Rock_Basalt"
    },
    {
      "x": -4,
      "y": 35,
      "z": 8,
      "name": "Rock_Shale_Brick_Smooth"
    },
    {
      "x": -4,
      "y": 36,
      "z": 8,
      "name": "Rock_Basalt_Brick"
    },
    {
      "x": -4,
      "y": 37,
      "z": 8,
      "name": "Deco_Bone_Skulls"
    },
    {
      "x": -4,
      "y": 38,
      "z": 8,
      "name": "Rock_Basalt_Brick"
    },
    {
      "x": -4,
      "y": 39,
      "z": 8,
      "name": "Deco_Bone_Skulls"
    },
    {
      "x": -4,
      "y": 40,
      "z": 8,
      "name": "Rock_Basalt_Brick"
    },
    {
      "x": -4,
      "y": 41,
      "z": 8,
      "name": "Rock_Basalt_Brick"
    },
    {
      "x": -4,
      "y": 42,
      "z": 8,
      "name": "Rock_Basalt"
    },
    {
      "x": -4,
      "y": 35,
      "z": 9,
      "name": "Soil_Dirt_Cold"
    },
    {
      "x": -4,
      "y": 36,
      "z": 9,
      "name": "Rubble_Basalt"
    },
    {
      "x": -4,
      "y": 37,
      "z": 9,
      "name": "Empty"
    },
    {
      "x": -4,
      "y": 38,
      "z": 9,
      "name": "Empty"
    },
    {
      "x": -4,
      "y": 39,
      "z": 9,
      "name": "Empty"
    },
    {
      "x": -4,
      "y": 40,
      "z": 9,
      "name": "Empty"
    },
    {
      "x": -4,
      "y": 41,
      "z": 9,
      "name": "Empty"
    },
    {
      "x": -4,
      "y": 42,
      "z": 9,
      "name": "Rock_Basalt"
    },
    {
      "x": -4,
      "y": 35,
      "z": 10,
      "name": "Soil_Dirt_Cold"
    },
    {
      "x": -4,
      "y": 36,
      "z": 10,
      "name": "*Plant_Crop_Berry_Winter_Block_State_Definitions_StageFinal",
      "components": {
        "Components": {
          "FarmingBlock": {}
        }
      }
    },
    {
      "x": -4,
      "y": 37,
      "z": 10,
      "name": "Empty"
    },
    {
      "x": -4,
      "y": 38,
      "z": 10,
      "name": "Empty"
    },
    {
      "x": -4,
      "y": 39,
      "z": 10,
      "name": "Empty"
    },
    {
      "x": -4,
      "y": 40,
      "z": 10,
      "name": "Empty"
    },
    {
      "x": -4,
      "y": 41,
      "z": 10,
      "name": "Empty"
    },
    {
      "x": -4,
      "y": 42,
      "z": 10,
      "name": "Rock_Basalt"
    },
    {
      "x": -4,
      "y": 35,
      "z": 11,
      "name": "Soil_Dirt_Cold"
    },
    {
      "x": -4,
      "y": 36,
      "z": 11,
      "name": "Empty"
    },
    {
      "x": -4,
      "y": 37,
      "z": 11,
      "name": "Empty"
    },
    {
      "x": -4,
      "y": 38,
      "z": 11,
      "name": "Empty"
    },
    {
      "x": -4,
      "y": 39,
      "z": 11,
      "name": "Empty"
    },
    {
      "x": -4,
      "y": 40,
      "z": 11,
      "name": "Empty"
    },
    {
      "x": -4,
      "y": 41,
      "z": 11,
      "name": "Empty"
    },
    {
      "x": -4,
      "y": 42,
      "z": 11,
      "name": "Rock_Basalt"
    },
    {
      "x": -4,
      "y": 35,
      "z": 12,
      "name": "Soil_Dirt_Cold"
    },
    {
      "x": -4,
      "y": 36,
      "z": 12,
      "name": "Empty"
    },
    {
      "x": -4,
      "y": 37,
      "z": 12,
      "name": "Empty"
    },
    {
      "x": -4,
      "y": 38,
      "z": 12,
      "name": "Empty"
    },
    {
      "x": -4,
      "y": 39,
      "z": 12,
      "name": "Empty"
    },
    {
      "x": -4,
      "y": 40,
      "z": 12,
      "name": "Empty"
    },
    {
      "x": -4,
      "y": 41,
      "z": 12,
      "name": "Empty"
    },
    {
      "x": -4,
      "y": 42,
      "z": 12,
      "name": "Rock_Basalt"
    },
    {
      "x": -4,
      "y": 35,
      "z": 13,
      "name": "Rock_Basalt"
    },
    {
      "x": -4,
      "y": 36,
      "z": 13,
      "name": "Empty"
    },
    {
      "x": -4,
      "y": 37,
      "z": 13,
      "name": "Empty"
    },
    {
      "x": -4,
      "y": 38,
      "z": 13,
      "name": "Empty"
    },
    {
      "x": -4,
      "y": 39,
      "z": 13,
      "name": "Empty"
    },
    {
      "x": -4,
      "y": 40,
      "z": 13,
      "name": "Empty"
    },
    {
      "x": -4,
      "y": 41,
      "z": 13,
      "name": "Rock_Basalt"
    },
    {
      "x": -4,
      "y": 42,
      "z": 13,
      "name": "Rock_Basalt"
    },
    {
      "x": -4,
      "y": 35,
      "z": 14,
      "name": "Rock_Basalt"
    },
    {
      "x": -4,
      "y": 36,
      "z": 14,
      "name": "Empty"
    },
    {
      "x": -4,
      "y": 37,
      "z": 14,
      "name": "Empty"
    },
    {
      "x": -4,
      "y": 38,
      "z": 14,
      "name": "Empty"
    },
    {
      "x": -4,
      "y": 39,
      "z": 14,
      "name": "Empty"
    },
    {
      "x": -4,
      "y": 40,
      "z": 14,
      "name": "Empty"
    },
    {
      "x": -4,
      "y": 41,
      "z": 14,
      "name": "Plant_Bush_Dead_Hanging"
    },
    {
      "x": -4,
      "y": 42,
      "z": 14,
      "name": "Rock_Basalt"
    },
    {
      "x": -4,
      "y": 35,
      "z": 15,
      "name": "Rock_Shale_Brick_Smooth"
    },
    {
      "x": -4,
      "y": 36,
      "z": 15,
      "name": "Empty"
    },
    {
      "x": -4,
      "y": 37,
      "z": 15,
      "name": "Empty"
    },
    {
      "x": -4,
      "y": 38,
      "z": 15,
      "name": "Empty"
    },
    {
      "x": -4,
      "y": 39,
      "z": 15,
      "name": "Empty"
    },
    {
      "x": -4,
      "y": 40,
      "z": 15,
      "name": "Empty"
    },
    {
      "x": -4,
      "y": 41,
      "z": 15,
      "name": "Empty"
    },
    {
      "x": -4,
      "y": 42,
      "z": 15,
      "name": "Rock_Basalt"
    },
    {
      "x": -4,
      "y": 35,
      "z": 16,
      "name": "Rock_Shale_Brick_Smooth"
    },
    {
      "x": -4,
      "y": 36,
      "z": 16,
      "name": "Furniture_Ancient_Table"
    },
    {
      "x": -4,
      "y": 37,
      "z": 16,
      "name": "Empty"
    },
    {
      "x": -4,
      "y": 38,
      "z": 16,
      "name": "Empty"
    },
    {
      "x": -4,
      "y": 39,
      "z": 16,
      "name": "Empty"
    },
    {
      "x": -4,
      "y": 40,
      "z": 16,
      "name": "Empty"
    },
    {
      "x": -4,
      "y": 41,
      "z": 16,
      "name": "Empty"
    },
    {
      "x": -4,
      "y": 42,
      "z": 16,
      "name": "Rock_Basalt"
    },
    {
      "x": -4,
      "y": 35,
      "z": 17,
      "name": "Rock_Shale_Brick_Smooth"
    },
    {
      "x": -4,
      "y": 36,
      "z": 17,
      "name": "Furniture_Ancient_Table",
      "filler": 32
    },
    {
      "x": -4,
      "y": 37,
      "z": 17,
      "name": "Empty"
    },
    {
      "x": -4,
      "y": 38,
      "z": 17,
      "name": "Empty"
    },
    {
      "x": -4,
      "y": 39,
      "z": 17,
      "name": "Empty"
    },
    {
      "x": -4,
      "y": 40,
      "z": 17,
      "name": "Empty"
    },
    {
      "x": -4,
      "y": 41,
      "z": 17,
      "name": "Empty"
    },
    {
      "x": -4,
      "y": 42,
      "z": 17,
      "name": "Rock_Basalt"
    },
    {
      "x": -4,
      "y": 35,
      "z": 18,
      "name": "Rock_Shale_Brick_Smooth"
    },
    {
      "x": -4,
      "y": 36,
      "z": 18,
      "name": "Furniture_Ancient_Chair",
      "rotation": 2
    },
    {
      "x": -4,
      "y": 37,
      "z": 18,
      "name": "Empty"
    },
    {
      "x": -4,
      "y": 38,
      "z": 18,
      "name": "Empty"
    },
    {
      "x": -4,
      "y": 39,
      "z": 18,
      "name": "Empty"
    },
    {
      "x": -4,
      "y": 40,
      "z": 18,
      "name": "Empty"
    },
    {
      "x": -4,
      "y": 41,
      "z": 18,
      "name": "Empty"
    },
    {
      "x": -4,
      "y": 42,
      "z": 18,
      "name": "Rock_Basalt"
    },
    {
      "x": -4,
      "y": 35,
      "z": 19,
      "name": "Soil_Dirt_Cold"
    },
    {
      "x": -4,
      "y": 36,
      "z": 19,
      "name": "Plant_Bush_Dead_Twisted"
    },
    {
      "x": -4,
      "y": 37,
      "z": 19,
      "name": "Empty"
    },
    {
      "x": -4,
      "y": 38,
      "z": 19,
      "name": "Empty"
    },
    {
      "x": -4,
      "y": 39,
      "z": 19,
      "name": "Empty"
    },
    {
      "x": -4,
      "y": 40,
      "z": 19,
      "name": "Empty"
    },
    {
      "x": -4,
      "y": 41,
      "z": 19,
      "name": "Empty"
    },
    {
      "x": -4,
      "y": 42,
      "z": 19,
      "name": "Rock_Basalt"
    },
    {
      "x": -4,
      "y": 35,
      "z": 20,
      "name": "Rock_Shale_Brick_Smooth"
    },
    {
      "x": -4,
      "y": 36,
      "z": 20,
      "name": "Rock_Shale_Brick_Pillar_Base"
    },
    {
      "x": -4,
      "y": 37,
      "z": 20,
      "name": "Rock_Shale_Brick_Pillar_Middle"
    },
    {
      "x": -4,
      "y": 38,
      "z": 20,
      "name": "Rock_Shale_Brick_Pillar_Middle"
    },
    {
      "x": -4,
      "y": 39,
      "z": 20,
      "name": "Rock_Shale_Brick_Pillar_Middle"
    },
    {
      "x": -4,
      "y": 40,
      "z": 20,
      "name": "Rock_Shale_Brick_Pillar_Base",
      "rotation": 8
    },
    {
      "x": -4,
      "y": 41,
      "z": 20,
      "name": "Rock_Basalt_Brick"
    },
    {
      "x": -4,
      "y": 42,
      "z": 20,
      "name": "Rock_Basalt"
    },
    {
      "x": -4,
      "y": 35,
      "z": 21,
      "name": "Rock_Shale_Brick_Smooth"
    },
    {
      "x": -4,
      "y": 36,
      "z": 21,
      "name": "Rock_Shale_Brick"
    },
    {
      "x": -4,
      "y": 37,
      "z": 21,
      "name": "Rock_Shale_Brick"
    },
    {
      "x": -4,
      "y": 38,
      "z": 21,
      "name": "Rock_Shale_Brick"
    },
    {
      "x": -4,
      "y": 39,
      "z": 21,
      "name": "Rock_Shale_Brick"
    },
    {
      "x": -4,
      "y": 40,
      "z": 21,
      "name": "Rock_Shale_Brick"
    },
    {
      "x": -4,
      "y": 41,
      "z": 21,
      "name": "Rock_Shale_Brick"
    },
    {
      "x": -4,
      "y": 42,
      "z": 21,
      "name": "Rock_Basalt"
    },
    {
      "x": -3,
      "y": 35,
      "z": 7,
      "name": "Rock_Basalt"
    },
    {
      "x": -3,
      "y": 36,
      "z": 7,
      "name": "Rock_Basalt"
    },
    {
      "x": -3,
      "y": 37,
      "z": 7,
      "name": "Rock_Basalt"
    },
    {
      "x": -3,
      "y": 38,
      "z": 7,
      "name": "Rock_Basalt"
    },
    {
      "x": -3,
      "y": 39,
      "z": 7,
      "name": "Rock_Basalt"
    },
    {
      "x": -3,
      "y": 40,
      "z": 7,
      "name": "Rock_Basalt"
    },
    {
      "x": -3,
      "y": 41,
      "z": 7,
      "name": "Rock_Basalt"
    },
    {
      "x": -3,
      "y": 42,
      "z": 7,
      "name": "Rock_Basalt"
    },
    {
      "x": -3,
      "y": 35,
      "z": 8,
      "name": "Rock_Shale_Brick_Smooth"
    },
    {
      "x": -3,
      "y": 36,
      "z": 8,
      "name": "Rock_Basalt_Brick"
    },
    {
      "x": -3,
      "y": 37,
      "z": 8,
      "name": "Deco_Bone_Pile"
    },
    {
      "x": -3,
      "y": 38,
      "z": 8,
      "name": "Rock_Basalt_Brick"
    },
    {
      "x": -3,
      "y": 39,
      "z": 8,
      "name": "Deco_Bone_Pile"
    },
    {
      "x": -3,
      "y": 40,
      "z": 8,
      "name": "Rock_Basalt_Brick"
    },
    {
      "x": -3,
      "y": 41,
      "z": 8,
      "name": "Rock_Basalt_Brick"
    },
    {
      "x": -3,
      "y": 42,
      "z": 8,
      "name": "Rock_Basalt"
    },
    {
      "x": -3,
      "y": 35,
      "z": 9,
      "name": "Rock_Shale_Brick_Smooth"
    },
    {
      "x": -3,
      "y": 36,
      "z": 9,
      "name": "Empty"
    },
    {
      "x": -3,
      "y": 37,
      "z": 9,
      "name": "Empty"
    },
    {
      "x": -3,
      "y": 38,
      "z": 9,
      "name": "Empty"
    },
    {
      "x": -3,
      "y": 39,
      "z": 9,
      "name": "Empty"
    },
    {
      "x": -3,
      "y": 40,
      "z": 9,
      "name": "Empty"
    },
    {
      "x": -3,
      "y": 41,
      "z": 9,
      "name": "Empty"
    },
    {
      "x": -3,
      "y": 42,
      "z": 9,
      "name": "Rock_Basalt"
    },
    {
      "x": -3,
      "y": 35,
      "z": 10,
      "name": "Rock_Shale_Brick_Smooth"
    },
    {
      "x": -3,
      "y": 36,
      "z": 10,
      "name": "Empty"
    },
    {
      "x": -3,
      "y": 37,
      "z": 10,
      "name": "Empty"
    },
    {
      "x": -3,
      "y": 38,
      "z": 10,
      "name": "Empty"
    },
    {
      "x": -3,
      "y": 39,
      "z": 10,
      "name": "Empty"
    },
    {
      "x": -3,
      "y": 40,
      "z": 10,
      "name": "Empty"
    },
    {
      "x": -3,
      "y": 41,
      "z": 10,
      "name": "Empty"
    },
    {
      "x": -3,
      "y": 42,
      "z": 10,
      "name": "Rock_Basalt"
    },
    {
      "x": -3,
      "y": 35,
      "z": 11,
      "name": "Rock_Shale_Brick_Smooth"
    },
    {
      "x": -3,
      "y": 36,
      "z": 11,
      "name": "Empty"
    },
    {
      "x": -3,
      "y": 37,
      "z": 11,
      "name": "Empty"
    },
    {
      "x": -3,
      "y": 38,
      "z": 11,
      "name": "Empty"
    },
    {
      "x": -3,
      "y": 39,
      "z": 11,
      "name": "Empty"
    },
    {
      "x": -3,
      "y": 40,
      "z": 11,
      "name": "Empty"
    },
    {
      "x": -3,
      "y": 41,
      "z": 11,
      "name": "Empty"
    },
    {
      "x": -3,
      "y": 42,
      "z": 11,
      "name": "Rock_Basalt"
    },
    {
      "x": -3,
      "y": 35,
      "z": 12,
      "name": "Rock_Shale_Brick_Smooth"
    },
    {
      "x": -3,
      "y": 36,
      "z": 12,
      "name": "Empty"
    },
    {
      "x": -3,
      "y": 37,
      "z": 12,
      "name": "Empty"
    },
    {
      "x": -3,
      "y": 38,
      "z": 12,
      "name": "Empty"
    },
    {
      "x": -3,
      "y": 39,
      "z": 12,
      "name": "Empty"
    },
    {
      "x": -3,
      "y": 40,
      "z": 12,
      "name": "Empty"
    },
    {
      "x": -3,
      "y": 41,
      "z": 12,
      "name": "Empty"
    },
    {
      "x": -3,
      "y": 42,
      "z": 12,
      "name": "Rock_Basalt"
    },
    {
      "x": -3,
      "y": 35,
      "z": 13,
      "name": "Rock_Basalt"
    },
    {
      "x": -3,
      "y": 36,
      "z": 13,
      "name": "Empty"
    },
    {
      "x": -3,
      "y": 37,
      "z": 13,
      "name": "Empty"
    },
    {
      "x": -3,
      "y": 38,
      "z": 13,
      "name": "Empty"
    },
    {
      "x": -3,
      "y": 39,
      "z": 13,
      "name": "Empty"
    },
    {
      "x": -3,
      "y": 40,
      "z": 13,
      "name": "Empty"
    },
    {
      "x": -3,
      "y": 41,
      "z": 13,
      "name": "Empty"
    },
    {
      "x": -3,
      "y": 42,
      "z": 13,
      "name": "Rock_Basalt"
    },
    {
      "x": -3,
      "y": 35,
      "z": 14,
      "name": "Rock_Shale_Brick_Smooth"
    },
    {
      "x": -3,
      "y": 36,
      "z": 14,
      "name": "Empty"
    },
    {
      "x": -3,
      "y": 37,
      "z": 14,
      "name": "Empty"
    },
    {
      "x": -3,
      "y": 38,
      "z": 14,
      "name": "Empty"
    },
    {
      "x": -3,
      "y": 39,
      "z": 14,
      "name": "Empty"
    },
    {
      "x": -3,
      "y": 40,
      "z": 14,
      "name": "Empty"
    },
    {
      "x": -3,
      "y": 41,
      "z": 14,
      "name": "Empty"
    },
    {
      "x": -3,
      "y": 42,
      "z": 14,
      "name": "Rock_Basalt"
    },
    {
      "x": -3,
      "y": 35,
      "z": 15,
      "name": "Rock_Shale_Brick_Smooth"
    },
    {
      "x": -3,
      "y": 36,
      "z": 15,
      "name": "Empty"
    },
    {
      "x": -3,
      "y": 37,
      "z": 15,
      "name": "Empty"
    },
    {
      "x": -3,
      "y": 38,
      "z": 15,
      "name": "Empty"
    },
    {
      "x": -3,
      "y": 39,
      "z": 15,
      "name": "Empty"
    },
    {
      "x": -3,
      "y": 40,
      "z": 15,
      "name": "Empty"
    },
    {
      "x": -3,
      "y": 41,
      "z": 15,
      "name": "Empty"
    },
    {
      "x": -3,
      "y": 42,
      "z": 15,
      "name": "Rock_Basalt"
    },
    {
      "x": -3,
      "y": 35,
      "z": 16,
      "name": "Rock_Shale_Brick_Smooth"
    },
    {
      "x": -3,
      "y": 36,
      "z": 16,
      "name": "Furniture_Ancient_Table",
      "filler": 1
    },
    {
      "x": -3,
      "y": 37,
      "z": 16,
      "name": "Empty"
    },
    {
      "x": -3,
      "y": 38,
      "z": 16,
      "name": "Empty"
    },
    {
      "x": -3,
      "y": 39,
      "z": 16,
      "name": "Empty"
    },
    {
      "x": -3,
      "y": 40,
      "z": 16,
      "name": "Empty"
    },
    {
      "x": -3,
      "y": 41,
      "z": 16,
      "name": "Empty"
    },
    {
      "x": -3,
      "y": 42,
      "z": 16,
      "name": "Rock_Basalt"
    },
    {
      "x": -3,
      "y": 35,
      "z": 17,
      "name": "Rock_Shale_Brick_Smooth"
    },
    {
      "x": -3,
      "y": 36,
      "z": 17,
      "name": "Furniture_Ancient_Table",
      "filler": 33
    },
    {
      "x": -3,
      "y": 37,
      "z": 17,
      "name": "Empty"
    },
    {
      "x": -3,
      "y": 38,
      "z": 17,
      "name": "Empty"
    },
    {
      "x": -3,
      "y": 39,
      "z": 17,
      "name": "Empty"
    },
    {
      "x": -3,
      "y": 40,
      "z": 17,
      "name": "Empty"
    },
    {
      "x": -3,
      "y": 41,
      "z": 17,
      "name": "Empty"
    },
    {
      "x": -3,
      "y": 42,
      "z": 17,
      "name": "Rock_Basalt"
    },
    {
      "x": -3,
      "y": 35,
      "z": 18,
      "name": "Soil_Dirt_Cold"
    },
    {
      "x": -3,
      "y": 36,
      "z": 18,
      "name": "Empty"
    },
    {
      "x": -3,
      "y": 37,
      "z": 18,
      "name": "Empty"
    },
    {
      "x": -3,
      "y": 38,
      "z": 18,
      "name": "Empty"
    },
    {
      "x": -3,
      "y": 39,
      "z": 18,
      "name": "Empty"
    },
    {
      "x": -3,
      "y": 40,
      "z": 18,
      "name": "Empty"
    },
    {
      "x": -3,
      "y": 41,
      "z": 18,
      "name": "Empty"
    },
    {
      "x": -3,
      "y": 42,
      "z": 18,
      "name": "Rock_Basalt"
    },
    {
      "x": -3,
      "y": 35,
      "z": 19,
      "name": "Soil_Dirt_Cold"
    },
    {
      "x": -3,
      "y": 36,
      "z": 19,
      "name": "Empty"
    },
    {
      "x": -3,
      "y": 37,
      "z": 19,
      "name": "Empty"
    },
    {
      "x": -3,
      "y": 38,
      "z": 19,
      "name": "Empty"
    },
    {
      "x": -3,
      "y": 39,
      "z": 19,
      "name": "Empty"
    },
    {
      "x": -3,
      "y": 40,
      "z": 19,
      "name": "Empty"
    },
    {
      "x": -3,
      "y": 41,
      "z": 19,
      "name": "Empty"
    },
    {
      "x": -3,
      "y": 42,
      "z": 19,
      "name": "Rock_Basalt"
    },
    {
      "x": -3,
      "y": 35,
      "z": 20,
      "name": "Soil_Dirt_Cold"
    },
    {
      "x": -3,
      "y": 36,
      "z": 20,
      "name": "Rubble_Basalt"
    },
    {
      "x": -3,
      "y": 37,
      "z": 20,
      "name": "Empty"
    },
    {
      "x": -3,
      "y": 38,
      "z": 20,
      "name": "Empty"
    },
    {
      "x": -3,
      "y": 39,
      "z": 20,
      "name": "Empty"
    },
    {
      "x": -3,
      "y": 40,
      "z": 20,
      "name": "Empty"
    },
    {
      "x": -3,
      "y": 41,
      "z": 20,
      "name": "Rock_Basalt_Brick"
    },
    {
      "x": -3,
      "y": 42,
      "z": 20,
      "name": "Rock_Basalt"
    },
    {
      "x": -3,
      "y": 35,
      "z": 21,
      "name": "Rock_Shale_Brick_Smooth"
    },
    {
      "x": -3,
      "y": 36,
      "z": 21,
      "name": "Empty"
    },
    {
      "x": -3,
      "y": 37,
      "z": 21,
      "name": "Empty"
    },
    {
      "x": -3,
      "y": 38,
      "z": 21,
      "name": "Empty"
    },
    {
      "x": -3,
      "y": 39,
      "z": 21,
      "name": "Empty"
    },
    {
      "x": -3,
      "y": 40,
      "z": 21,
      "name": "Empty"
    },
    {
      "x": -3,
      "y": 41,
      "z": 21,
      "name": "Rock_Shale_Brick"
    },
    {
      "x": -3,
      "y": 42,
      "z": 21,
      "name": "Rock_Basalt"
    },
    {
      "x": -2,
      "y": 35,
      "z": 7,
      "name": "Rock_Basalt"
    },
    {
      "x": -2,
      "y": 36,
      "z": 7,
      "name": "Rock_Basalt"
    },
    {
      "x": -2,
      "y": 37,
      "z": 7,
      "name": "Rock_Basalt"
    },
    {
      "x": -2,
      "y": 38,
      "z": 7,
      "name": "Rock_Basalt"
    },
    {
      "x": -2,
      "y": 39,
      "z": 7,
      "name": "Rock_Basalt"
    },
    {
      "x": -2,
      "y": 40,
      "z": 7,
      "name": "Rock_Basalt"
    },
    {
      "x": -2,
      "y": 41,
      "z": 7,
      "name": "Rock_Basalt"
    },
    {
      "x": -2,
      "y": 42,
      "z": 7,
      "name": "Rock_Basalt"
    },
    {
      "x": -2,
      "y": 35,
      "z": 8,
      "name": "Rock_Shale"
    },
    {
      "x": -2,
      "y": 36,
      "z": 8,
      "name": "Rock_Basalt_Brick"
    },
    {
      "x": -2,
      "y": 37,
      "z": 8,
      "name": "Deco_Bone_Pile"
    },
    {
      "x": -2,
      "y": 38,
      "z": 8,
      "name": "Rock_Basalt_Brick"
    },
    {
      "x": -2,
      "y": 39,
      "z": 8,
      "name": "Deco_Bone_Skulls"
    },
    {
      "x": -2,
      "y": 40,
      "z": 8,
      "name": "Rock_Basalt_Brick"
    },
    {
      "x": -2,
      "y": 41,
      "z": 8,
      "name": "Rock_Basalt_Brick"
    },
    {
      "x": -2,
      "y": 42,
      "z": 8,
      "name": "Rock_Basalt"
    },
    {
      "x": -2,
      "y": 35,
      "z": 9,
      "name": "Rock_Shale"
    },
    {
      "x": -2,
      "y": 36,
      "z": 9,
      "name": "Empty"
    },
    {
      "x": -2,
      "y": 37,
      "z": 9,
      "name": "Empty"
    },
    {
      "x": -2,
      "y": 38,
      "z": 9,
      "name": "Empty"
    },
    {
      "x": -2,
      "y": 39,
      "z": 9,
      "name": "Empty"
    },
    {
      "x": -2,
      "y": 40,
      "z": 9,
      "name": "Empty"
    },
    {
      "x": -2,
      "y": 41,
      "z": 9,
      "name": "Empty"
    },
    {
      "x": -2,
      "y": 42,
      "z": 9,
      "name": "Rock_Basalt"
    },
    {
      "x": -2,
      "y": 35,
      "z": 10,
      "name": "Rock_Shale"
    },
    {
      "x": -2,
      "y": 36,
      "z": 10,
      "name": "Empty"
    },
    {
      "x": -2,
      "y": 37,
      "z": 10,
      "name": "Empty"
    },
    {
      "x": -2,
      "y": 38,
      "z": 10,
      "name": "Empty"
    },
    {
      "x": -2,
      "y": 39,
      "z": 10,
      "name": "Empty"
    },
    {
      "x": -2,
      "y": 40,
      "z": 10,
      "name": "Empty"
    },
    {
      "x": -2,
      "y": 41,
      "z": 10,
      "name": "Empty"
    },
    {
      "x": -2,
      "y": 42,
      "z": 10,
      "name": "Rock_Basalt"
    },
    {
      "x": -2,
      "y": 35,
      "z": 11,
      "name": "Rock_Shale"
    },
    {
      "x": -2,
      "y": 36,
      "z": 11,
      "name": "Empty"
    },
    {
      "x": -2,
      "y": 37,
      "z": 11,
      "name": "Empty"
    },
    {
      "x": -2,
      "y": 38,
      "z": 11,
      "name": "Empty"
    },
    {
      "x": -2,
      "y": 39,
      "z": 11,
      "name": "Empty"
    },
    {
      "x": -2,
      "y": 40,
      "z": 11,
      "name": "Empty"
    },
    {
      "x": -2,
      "y": 41,
      "z": 11,
      "name": "Empty"
    },
    {
      "x": -2,
      "y": 42,
      "z": 11,
      "name": "Rock_Basalt"
    },
    {
      "x": -2,
      "y": 35,
      "z": 12,
      "name": "Rock_Shale"
    },
    {
      "x": -2,
      "y": 36,
      "z": 12,
      "name": "Empty"
    },
    {
      "x": -2,
      "y": 37,
      "z": 12,
      "name": "Empty"
    },
    {
      "x": -2,
      "y": 38,
      "z": 12,
      "name": "Empty"
    },
    {
      "x": -2,
      "y": 39,
      "z": 12,
      "name": "Empty"
    },
    {
      "x": -2,
      "y": 40,
      "z": 12,
      "name": "Empty"
    },
    {
      "x": -2,
      "y": 41,
      "z": 12,
      "name": "Empty"
    },
    {
      "x": -2,
      "y": 42,
      "z": 12,
      "name": "Rock_Basalt"
    },
    {
      "x": -2,
      "y": 35,
      "z": 13,
      "name": "Rock_Shale"
    },
    {
      "x": -2,
      "y": 36,
      "z": 13,
      "name": "Empty"
    },
    {
      "x": -2,
      "y": 37,
      "z": 13,
      "name": "Empty"
    },
    {
      "x": -2,
      "y": 38,
      "z": 13,
      "name": "Empty"
    },
    {
      "x": -2,
      "y": 39,
      "z": 13,
      "name": "Empty"
    },
    {
      "x": -2,
      "y": 40,
      "z": 13,
      "name": "Empty"
    },
    {
      "x": -2,
      "y": 41,
      "z": 13,
      "name": "Empty"
    },
    {
      "x": -2,
      "y": 42,
      "z": 13,
      "name": "Rock_Basalt"
    },
    {
      "x": -2,
      "y": 35,
      "z": 14,
      "name": "Rock_Shale"
    },
    {
      "x": -2,
      "y": 36,
      "z": 14,
      "name": "Empty"
    },
    {
      "x": -2,
      "y": 37,
      "z": 14,
      "name": "Empty"
    },
    {
      "x": -2,
      "y": 38,
      "z": 14,
      "name": "Empty"
    },
    {
      "x": -2,
      "y": 39,
      "z": 14,
      "name": "Empty"
    },
    {
      "x": -2,
      "y": 40,
      "z": 14,
      "name": "Empty"
    },
    {
      "x": -2,
      "y": 41,
      "z": 14,
      "name": "Empty"
    },
    {
      "x": -2,
      "y": 42,
      "z": 14,
      "name": "Rock_Basalt"
    },
    {
      "x": -2,
      "y": 35,
      "z": 15,
      "name": "Rock_Shale"
    },
    {
      "x": -2,
      "y": 36,
      "z": 15,
      "name": "Empty"
    },
    {
      "x": -2,
      "y": 37,
      "z": 15,
      "name": "Empty"
    },
    {
      "x": -2,
      "y": 38,
      "z": 15,
      "name": "Empty"
    },
    {
      "x": -2,
      "y": 39,
      "z": 15,
      "name": "Empty"
    },
    {
      "x": -2,
      "y": 40,
      "z": 15,
      "name": "Empty"
    },
    {
      "x": -2,
      "y": 41,
      "z": 15,
      "name": "Empty"
    },
    {
      "x": -2,
      "y": 42,
      "z": 15,
      "name": "Rock_Basalt"
    },
    {
      "x": -2,
      "y": 35,
      "z": 16,
      "name": "Rock_Shale"
    },
    {
      "x": -2,
      "y": 36,
      "z": 16,
      "name": "Empty"
    },
    {
      "x": -2,
      "y": 37,
      "z": 16,
      "name": "Empty"
    },
    {
      "x": -2,
      "y": 38,
      "z": 16,
      "name": "Empty"
    },
    {
      "x": -2,
      "y": 39,
      "z": 16,
      "name": "Empty"
    },
    {
      "x": -2,
      "y": 40,
      "z": 16,
      "name": "Empty"
    },
    {
      "x": -2,
      "y": 41,
      "z": 16,
      "name": "Empty"
    },
    {
      "x": -2,
      "y": 42,
      "z": 16,
      "name": "Rock_Basalt"
    },
    {
      "x": -2,
      "y": 35,
      "z": 17,
      "name": "Rock_Shale"
    },
    {
      "x": -2,
      "y": 36,
      "z": 17,
      "name": "Empty"
    },
    {
      "x": -2,
      "y": 37,
      "z": 17,
      "name": "Empty"
    },
    {
      "x": -2,
      "y": 38,
      "z": 17,
      "name": "Empty"
    },
    {
      "x": -2,
      "y": 39,
      "z": 17,
      "name": "Empty"
    },
    {
      "x": -2,
      "y": 40,
      "z": 17,
      "name": "Empty"
    },
    {
      "x": -2,
      "y": 41,
      "z": 17,
      "name": "Empty"
    },
    {
      "x": -2,
      "y": 42,
      "z": 17,
      "name": "Rock_Basalt"
    },
    {
      "x": -2,
      "y": 35,
      "z": 18,
      "name": "Rock_Shale"
    },
    {
      "x": -2,
      "y": 36,
      "z": 18,
      "name": "Empty"
    },
    {
      "x": -2,
      "y": 37,
      "z": 18,
      "name": "Empty"
    },
    {
      "x": -2,
      "y": 38,
      "z": 18,
      "name": "Empty"
    },
    {
      "x": -2,
      "y": 39,
      "z": 18,
      "name": "Empty"
    },
    {
      "x": -2,
      "y": 40,
      "z": 18,
      "name": "Empty"
    },
    {
      "x": -2,
      "y": 41,
      "z": 18,
      "name": "Empty"
    },
    {
      "x": -2,
      "y": 42,
      "z": 18,
      "name": "Rock_Basalt"
    },
    {
      "x": -2,
      "y": 35,
      "z": 19,
      "name": "Rock_Shale"
    },
    {
      "x": -2,
      "y": 36,
      "z": 19,
      "name": "Empty"
    },
    {
      "x": -2,
      "y": 37,
      "z": 19,
      "name": "Empty"
    },
    {
      "x": -2,
      "y": 38,
      "z": 19,
      "name": "Empty"
    },
    {
      "x": -2,
      "y": 39,
      "z": 19,
      "name": "Empty"
    },
    {
      "x": -2,
      "y": 40,
      "z": 19,
      "name": "Empty"
    },
    {
      "x": -2,
      "y": 41,
      "z": 19,
      "name": "Empty"
    },
    {
      "x": -2,
      "y": 42,
      "z": 19,
      "name": "Rock_Basalt"
    },
    {
      "x": -2,
      "y": 35,
      "z": 20,
      "name": "Rock_Shale"
    },
    {
      "x": -2,
      "y": 36,
      "z": 20,
      "name": "Empty"
    },
    {
      "x": -2,
      "y": 37,
      "z": 20,
      "name": "Empty"
    },
    {
      "x": -2,
      "y": 38,
      "z": 20,
      "name": "Empty"
    },
    {
      "x": -2,
      "y": 39,
      "z": 20,
      "name": "Empty"
    },
    {
      "x": -2,
      "y": 40,
      "z": 20,
      "name": "Empty"
    },
    {
      "x": -2,
      "y": 41,
      "z": 20,
      "name": "Rock_Basalt_Brick"
    },
    {
      "x": -2,
      "y": 42,
      "z": 20,
      "name": "Rock_Basalt"
    },
    {
      "x": -2,
      "y": 35,
      "z": 21,
      "name": "Rock_Shale"
    },
    {
      "x": -2,
      "y": 36,
      "z": 21,
      "name": "Empty"
    },
    {
      "x": -2,
      "y": 37,
      "z": 21,
      "name": "Empty"
    },
    {
      "x": -2,
      "y": 38,
      "z": 21,
      "name": "Empty"
    },
    {
      "x": -2,
      "y": 39,
      "z": 21,
      "name": "Empty"
    },
    {
      "x": -2,
      "y": 40,
      "z": 21,
      "name": "Empty"
    },
    {
      "x": -2,
      "y": 41,
      "z": 21,
      "name": "Rock_Shale_Brick"
    },
    {
      "x": -2,
      "y": 42,
      "z": 21,
      "name": "Rock_Basalt"
    },
    {
      "x": -1,
      "y": 35,
      "z": 7,
      "name": "Rock_Basalt"
    },
    {
      "x": -1,
      "y": 36,
      "z": 7,
      "name": "Rock_Basalt"
    },
    {
      "x": -1,
      "y": 37,
      "z": 7,
      "name": "Rock_Basalt"
    },
    {
      "x": -1,
      "y": 38,
      "z": 7,
      "name": "Rock_Basalt"
    },
    {
      "x": -1,
      "y": 39,
      "z": 7,
      "name": "Rock_Basalt"
    },
    {
      "x": -1,
      "y": 40,
      "z": 7,
      "name": "Rock_Basalt"
    },
    {
      "x": -1,
      "y": 41,
      "z": 7,
      "name": "Rock_Basalt"
    },
    {
      "x": -1,
      "y": 42,
      "z": 7,
      "name": "Rock_Basalt"
    },
    {
      "x": -1,
      "y": 35,
      "z": 8,
      "name": "Rock_Shale"
    },
    {
      "x": -1,
      "y": 36,
      "z": 8,
      "name": "Rock_Basalt_Brick"
    },
    {
      "x": -1,
      "y": 37,
      "z": 8,
      "name": "Rock_Basalt_Brick"
    },
    {
      "x": -1,
      "y": 38,
      "z": 8,
      "name": "Rock_Basalt_Brick"
    },
    {
      "x": -1,
      "y": 39,
      "z": 8,
      "name": "Rock_Basalt_Brick"
    },
    {
      "x": -1,
      "y": 40,
      "z": 8,
      "name": "Rock_Basalt_Brick"
    },
    {
      "x": -1,
      "y": 41,
      "z": 8,
      "name": "Rock_Basalt_Brick"
    },
    {
      "x": -1,
      "y": 42,
      "z": 8,
      "name": "Rock_Basalt"
    },
    {
      "x": -1,
      "y": 35,
      "z": 9,
      "name": "Rock_Shale"
    },
    {
      "x": -1,
      "y": 36,
      "z": 9,
      "name": "Rock_Basalt_Brick"
    },
    {
      "x": -1,
      "y": 37,
      "z": 9,
      "name": "Rock_Basalt_Brick"
    },
    {
      "x": -1,
      "y": 38,
      "z": 9,
      "name": "Rock_Basalt_Brick"
    },
    {
      "x": -1,
      "y": 39,
      "z": 9,
      "name": "Rock_Basalt_Brick"
    },
    {
      "x": -1,
      "y": 40,
      "z": 9,
      "name": "Rock_Basalt_Brick"
    },
    {
      "x": -1,
      "y": 41,
      "z": 9,
      "name": "Rock_Basalt_Brick"
    },
    {
      "x": -1,
      "y": 42,
      "z": 9,
      "name": "Rock_Basalt"
    },
    {
      "x": -1,
      "y": 35,
      "z": 10,
      "name": "Rock_Shale"
    },
    {
      "x": -1,
      "y": 36,
      "z": 10,
      "name": "Block_Spawner_Block",
      "components": {
        "Components": {
          "PlacedByInteraction": {
            "WhoPlacedUuid": {
              "$binary": "x9M0GYCLPG+IqIodoDzEcQ==",
              "$type": "04"
            }
          },
          "BlockSpawner": {
            "BlockSpawnerId": "Zone3_Encounters_Tier3"
          }
        }
      }
    },
    {
      "x": -1,
      "y": 37,
      "z": 10,
      "name": "Empty"
    },
    {
      "x": -1,
      "y": 38,
      "z": 10,
      "name": "Empty"
    },
    {
      "x": -1,
      "y": 39,
      "z": 10,
      "name": "Empty"
    },
    {
      "x": -1,
      "y": 40,
      "z": 10,
      "name": "Empty"
    },
    {
      "x": -1,
      "y": 41,
      "z": 10,
      "name": "Empty"
    },
    {
      "x": -1,
      "y": 42,
      "z": 10,
      "name": "Rock_Basalt"
    },
    {
      "x": -1,
      "y": 35,
      "z": 11,
      "name": "Rock_Shale"
    },
    {
      "x": -1,
      "y": 36,
      "z": 11,
      "name": "Empty"
    },
    {
      "x": -1,
      "y": 37,
      "z": 11,
      "name": "Empty"
    },
    {
      "x": -1,
      "y": 38,
      "z": 11,
      "name": "Empty"
    },
    {
      "x": -1,
      "y": 39,
      "z": 11,
      "name": "Empty"
    },
    {
      "x": -1,
      "y": 40,
      "z": 11,
      "name": "Empty"
    },
    {
      "x": -1,
      "y": 41,
      "z": 11,
      "name": "Empty"
    },
    {
      "x": -1,
      "y": 42,
      "z": 11,
      "name": "Rock_Basalt"
    },
    {
      "x": -1,
      "y": 35,
      "z": 12,
      "name": "Rock_Shale"
    },
    {
      "x": -1,
      "y": 36,
      "z": 12,
      "name": "Empty"
    },
    {
      "x": -1,
      "y": 37,
      "z": 12,
      "name": "Empty"
    },
    {
      "x": -1,
      "y": 38,
      "z": 12,
      "name": "Empty"
    },
    {
      "x": -1,
      "y": 39,
      "z": 12,
      "name": "Empty"
    },
    {
      "x": -1,
      "y": 40,
      "z": 12,
      "name": "Empty"
    },
    {
      "x": -1,
      "y": 41,
      "z": 12,
      "name": "Empty"
    },
    {
      "x": -1,
      "y": 42,
      "z": 12,
      "name": "Rock_Basalt"
    },
    {
      "x": -1,
      "y": 35,
      "z": 13,
      "name": "Rock_Shale"
    },
    {
      "x": -1,
      "y": 36,
      "z": 13,
      "name": "Empty"
    },
    {
      "x": -1,
      "y": 37,
      "z": 13,
      "name": "Empty"
    },
    {
      "x": -1,
      "y": 38,
      "z": 13,
      "name": "Empty"
    },
    {
      "x": -1,
      "y": 39,
      "z": 13,
      "name": "Empty"
    },
    {
      "x": -1,
      "y": 40,
      "z": 13,
      "name": "Empty"
    },
    {
      "x": -1,
      "y": 41,
      "z": 13,
      "name": "Empty"
    },
    {
      "x": -1,
      "y": 42,
      "z": 13,
      "name": "Rock_Basalt"
    },
    {
      "x": -1,
      "y": 35,
      "z": 14,
      "name": "Rock_Shale"
    },
    {
      "x": -1,
      "y": 36,
      "z": 14,
      "name": "Empty"
    },
    {
      "x": -1,
      "y": 37,
      "z": 14,
      "name": "Empty"
    },
    {
      "x": -1,
      "y": 38,
      "z": 14,
      "name": "Empty"
    },
    {
      "x": -1,
      "y": 39,
      "z": 14,
      "name": "Empty"
    },
    {
      "x": -1,
      "y": 40,
      "z": 14,
      "name": "Empty"
    },
    {
      "x": -1,
      "y": 41,
      "z": 14,
      "name": "Empty"
    },
    {
      "x": -1,
      "y": 42,
      "z": 14,
      "name": "Rock_Basalt"
    },
    {
      "x": -1,
      "y": 35,
      "z": 15,
      "name": "Rock_Shale"
    },
    {
      "x": -1,
      "y": 36,
      "z": 15,
      "name": "Empty"
    },
    {
      "x": -1,
      "y": 37,
      "z": 15,
      "name": "Empty"
    },
    {
      "x": -1,
      "y": 38,
      "z": 15,
      "name": "Empty"
    },
    {
      "x": -1,
      "y": 39,
      "z": 15,
      "name": "Empty"
    },
    {
      "x": -1,
      "y": 40,
      "z": 15,
      "name": "Empty"
    },
    {
      "x": -1,
      "y": 41,
      "z": 15,
      "name": "Empty"
    },
    {
      "x": -1,
      "y": 42,
      "z": 15,
      "name": "Rock_Basalt"
    },
    {
      "x": -1,
      "y": 35,
      "z": 16,
      "name": "Rock_Shale"
    },
    {
      "x": -1,
      "y": 36,
      "z": 16,
      "name": "Empty"
    },
    {
      "x": -1,
      "y": 37,
      "z": 16,
      "name": "Empty"
    },
    {
      "x": -1,
      "y": 38,
      "z": 16,
      "name": "Empty"
    },
    {
      "x": -1,
      "y": 39,
      "z": 16,
      "name": "Empty"
    },
    {
      "x": -1,
      "y": 40,
      "z": 16,
      "name": "Empty"
    },
    {
      "x": -1,
      "y": 41,
      "z": 16,
      "name": "Empty"
    },
    {
      "x": -1,
      "y": 42,
      "z": 16,
      "name": "Rock_Basalt"
    },
    {
      "x": -1,
      "y": 35,
      "z": 17,
      "name": "Rock_Shale"
    },
    {
      "x": -1,
      "y": 36,
      "z": 17,
      "name": "Empty"
    },
    {
      "x": -1,
      "y": 37,
      "z": 17,
      "name": "Empty"
    },
    {
      "x": -1,
      "y": 38,
      "z": 17,
      "name": "Empty"
    },
    {
      "x": -1,
      "y": 39,
      "z": 17,
      "name": "Empty"
    },
    {
      "x": -1,
      "y": 40,
      "z": 17,
      "name": "Empty"
    },
    {
      "x": -1,
      "y": 41,
      "z": 17,
      "name": "Empty"
    },
    {
      "x": -1,
      "y": 42,
      "z": 17,
      "name": "Rock_Basalt"
    },
    {
      "x": -1,
      "y": 35,
      "z": 18,
      "name": "Rock_Shale"
    },
    {
      "x": -1,
      "y": 36,
      "z": 18,
      "name": "Empty"
    },
    {
      "x": -1,
      "y": 37,
      "z": 18,
      "name": "Empty"
    },
    {
      "x": -1,
      "y": 38,
      "z": 18,
      "name": "Empty"
    },
    {
      "x": -1,
      "y": 39,
      "z": 18,
      "name": "Empty"
    },
    {
      "x": -1,
      "y": 40,
      "z": 18,
      "name": "Empty"
    },
    {
      "x": -1,
      "y": 41,
      "z": 18,
      "name": "Empty"
    },
    {
      "x": -1,
      "y": 42,
      "z": 18,
      "name": "Rock_Basalt"
    },
    {
      "x": -1,
      "y": 35,
      "z": 19,
      "name": "Rock_Shale"
    },
    {
      "x": -1,
      "y": 36,
      "z": 19,
      "name": "Empty"
    },
    {
      "x": -1,
      "y": 37,
      "z": 19,
      "name": "Empty"
    },
    {
      "x": -1,
      "y": 38,
      "z": 19,
      "name": "Empty"
    },
    {
      "x": -1,
      "y": 39,
      "z": 19,
      "name": "Empty"
    },
    {
      "x": -1,
      "y": 40,
      "z": 19,
      "name": "Empty"
    },
    {
      "x": -1,
      "y": 41,
      "z": 19,
      "name": "Empty"
    },
    {
      "x": -1,
      "y": 42,
      "z": 19,
      "name": "Rock_Basalt"
    },
    {
      "x": -1,
      "y": 35,
      "z": 20,
      "name": "Rock_Shale"
    },
    {
      "x": -1,
      "y": 36,
      "z": 20,
      "name": "Empty"
    },
    {
      "x": -1,
      "y": 37,
      "z": 20,
      "name": "Empty"
    },
    {
      "x": -1,
      "y": 38,
      "z": 20,
      "name": "Empty"
    },
    {
      "x": -1,
      "y": 39,
      "z": 20,
      "name": "Empty"
    },
    {
      "x": -1,
      "y": 40,
      "z": 20,
      "name": "Empty"
    },
    {
      "x": -1,
      "y": 41,
      "z": 20,
      "name": "Rock_Basalt_Brick"
    },
    {
      "x": -1,
      "y": 42,
      "z": 20,
      "name": "Rock_Basalt"
    },
    {
      "x": -1,
      "y": 35,
      "z": 21,
      "name": "Rock_Shale"
    },
    {
      "x": -1,
      "y": 36,
      "z": 21,
      "name": "Empty"
    },
    {
      "x": -1,
      "y": 37,
      "z": 21,
      "name": "Empty"
    },
    {
      "x": -1,
      "y": 38,
      "z": 21,
      "name": "Empty"
    },
    {
      "x": -1,
      "y": 39,
      "z": 21,
      "name": "Empty"
    },
    {
      "x": -1,
      "y": 40,
      "z": 21,
      "name": "Empty"
    },
    {
      "x": -1,
      "y": 41,
      "z": 21,
      "name": "Rock_Shale_Brick"
    },
    {
      "x": -1,
      "y": 42,
      "z": 21,
      "name": "Rock_Basalt"
    },
    {
      "x": 0,
      "y": 35,
      "z": 7,
      "name": "Rock_Basalt"
    },
    {
      "x": 0,
      "y": 36,
      "z": 7,
      "name": "Rock_Basalt"
    },
    {
      "x": 0,
      "y": 37,
      "z": 7,
      "name": "Rock_Basalt"
    },
    {
      "x": 0,
      "y": 38,
      "z": 7,
      "name": "Rock_Basalt"
    },
    {
      "x": 0,
      "y": 39,
      "z": 7,
      "name": "Rock_Basalt"
    },
    {
      "x": 0,
      "y": 40,
      "z": 7,
      "name": "Rock_Basalt"
    },
    {
      "x": 0,
      "y": 41,
      "z": 7,
      "name": "Rock_Basalt"
    },
    {
      "x": 0,
      "y": 42,
      "z": 7,
      "name": "Rock_Basalt"
    },
    {
      "x": 0,
      "y": 35,
      "z": 8,
      "name": "Rock_Shale"
    },
    {
      "x": 0,
      "y": 36,
      "z": 8,
      "name": "Rock_Basalt_Brick"
    },
    {
      "x": 0,
      "y": 37,
      "z": 8,
      "name": "Deco_Bone_Skulls"
    },
    {
      "x": 0,
      "y": 38,
      "z": 8,
      "name": "Rock_Basalt_Brick"
    },
    {
      "x": 0,
      "y": 39,
      "z": 8,
      "name": "Empty"
    },
    {
      "x": 0,
      "y": 40,
      "z": 8,
      "name": "Rock_Basalt_Brick"
    },
    {
      "x": 0,
      "y": 41,
      "z": 8,
      "name": "Rock_Basalt_Brick"
    },
    {
      "x": 0,
      "y": 42,
      "z": 8,
      "name": "Rock_Basalt"
    },
    {
      "x": 0,
      "y": 35,
      "z": 9,
      "name": "Rock_Shale"
    },
    {
      "x": 0,
      "y": 36,
      "z": 9,
      "name": "Empty"
    },
    {
      "x": 0,
      "y": 37,
      "z": 9,
      "name": "Empty"
    },
    {
      "x": 0,
      "y": 38,
      "z": 9,
      "name": "Empty"
    },
    {
      "x": 0,
      "y": 39,
      "z": 9,
      "name": "Empty"
    },
    {
      "x": 0,
      "y": 40,
      "z": 9,
      "name": "Empty"
    },
    {
      "x": 0,
      "y": 41,
      "z": 9,
      "name": "Empty"
    },
    {
      "x": 0,
      "y": 42,
      "z": 9,
      "name": "Rock_Basalt"
    },
    {
      "x": 0,
      "y": 35,
      "z": 10,
      "name": "Rock_Shale"
    },
    {
      "x": 0,
      "y": 36,
      "z": 10,
      "name": "Empty"
    },
    {
      "x": 0,
      "y": 37,
      "z": 10,
      "name": "Empty"
    },
    {
      "x": 0,
      "y": 38,
      "z": 10,
      "name": "Empty"
    },
    {
      "x": 0,
      "y": 39,
      "z": 10,
      "name": "Empty"
    },
    {
      "x": 0,
      "y": 40,
      "z": 10,
      "name": "Empty"
    },
    {
      "x": 0,
      "y": 41,
      "z": 10,
      "name": "Empty"
    },
    {
      "x": 0,
      "y": 42,
      "z": 10,
      "name": "Rock_Basalt"
    },
    {
      "x": 0,
      "y": 35,
      "z": 11,
      "name": "Rock_Shale"
    },
    {
      "x": 0,
      "y": 36,
      "z": 11,
      "name": "Empty"
    },
    {
      "x": 0,
      "y": 37,
      "z": 11,
      "name": "Empty"
    },
    {
      "x": 0,
      "y": 38,
      "z": 11,
      "name": "Empty"
    },
    {
      "x": 0,
      "y": 39,
      "z": 11,
      "name": "Empty"
    },
    {
      "x": 0,
      "y": 40,
      "z": 11,
      "name": "Empty"
    },
    {
      "x": 0,
      "y": 41,
      "z": 11,
      "name": "Empty"
    },
    {
      "x": 0,
      "y": 42,
      "z": 11,
      "name": "Rock_Basalt"
    },
    {
      "x": 0,
      "y": 35,
      "z": 12,
      "name": "Rock_Shale"
    },
    {
      "x": 0,
      "y": 36,
      "z": 12,
      "name": "Empty"
    },
    {
      "x": 0,
      "y": 37,
      "z": 12,
      "name": "Empty"
    },
    {
      "x": 0,
      "y": 38,
      "z": 12,
      "name": "Empty"
    },
    {
      "x": 0,
      "y": 39,
      "z": 12,
      "name": "Empty"
    },
    {
      "x": 0,
      "y": 40,
      "z": 12,
      "name": "Empty"
    },
    {
      "x": 0,
      "y": 41,
      "z": 12,
      "name": "Empty"
    },
    {
      "x": 0,
      "y": 42,
      "z": 12,
      "name": "Rock_Basalt"
    },
    {
      "x": 0,
      "y": 35,
      "z": 13,
      "name": "Rock_Shale"
    },
    {
      "x": 0,
      "y": 36,
      "z": 13,
      "name": "Empty"
    },
    {
      "x": 0,
      "y": 37,
      "z": 13,
      "name": "Empty"
    },
    {
      "x": 0,
      "y": 38,
      "z": 13,
      "name": "Empty"
    },
    {
      "x": 0,
      "y": 39,
      "z": 13,
      "name": "Empty"
    },
    {
      "x": 0,
      "y": 40,
      "z": 13,
      "name": "Empty"
    },
    {
      "x": 0,
      "y": 41,
      "z": 13,
      "name": "Empty"
    },
    {
      "x": 0,
      "y": 42,
      "z": 13,
      "name": "Rock_Basalt"
    },
    {
      "x": 0,
      "y": 35,
      "z": 14,
      "name": "Rock_Shale"
    },
    {
      "x": 0,
      "y": 36,
      "z": 14,
      "name": "Empty"
    },
    {
      "x": 0,
      "y": 37,
      "z": 14,
      "name": "Empty"
    },
    {
      "x": 0,
      "y": 38,
      "z": 14,
      "name": "Empty"
    },
    {
      "x": 0,
      "y": 39,
      "z": 14,
      "name": "Empty"
    },
    {
      "x": 0,
      "y": 40,
      "z": 14,
      "name": "Empty"
    },
    {
      "x": 0,
      "y": 41,
      "z": 14,
      "name": "Empty"
    },
    {
      "x": 0,
      "y": 42,
      "z": 14,
      "name": "Rock_Basalt"
    },
    {
      "x": 0,
      "y": 35,
      "z": 15,
      "name": "Rock_Shale"
    },
    {
      "x": 0,
      "y": 36,
      "z": 15,
      "name": "Empty"
    },
    {
      "x": 0,
      "y": 37,
      "z": 15,
      "name": "Empty"
    },
    {
      "x": 0,
      "y": 38,
      "z": 15,
      "name": "Empty"
    },
    {
      "x": 0,
      "y": 39,
      "z": 15,
      "name": "Empty"
    },
    {
      "x": 0,
      "y": 40,
      "z": 15,
      "name": "Empty"
    },
    {
      "x": 0,
      "y": 41,
      "z": 15,
      "name": "Empty"
    },
    {
      "x": 0,
      "y": 42,
      "z": 15,
      "name": "Rock_Basalt"
    },
    {
      "x": 0,
      "y": 35,
      "z": 16,
      "name": "Rock_Shale"
    },
    {
      "x": 0,
      "y": 36,
      "z": 16,
      "name": "Empty"
    },
    {
      "x": 0,
      "y": 37,
      "z": 16,
      "name": "Empty"
    },
    {
      "x": 0,
      "y": 38,
      "z": 16,
      "name": "Empty"
    },
    {
      "x": 0,
      "y": 39,
      "z": 16,
      "name": "Empty"
    },
    {
      "x": 0,
      "y": 40,
      "z": 16,
      "name": "Empty"
    },
    {
      "x": 0,
      "y": 41,
      "z": 16,
      "name": "Empty"
    },
    {
      "x": 0,
      "y": 42,
      "z": 16,
      "name": "Rock_Basalt"
    },
    {
      "x": 0,
      "y": 35,
      "z": 17,
      "name": "Rock_Shale"
    },
    {
      "x": 0,
      "y": 36,
      "z": 17,
      "name": "Empty"
    },
    {
      "x": 0,
      "y": 37,
      "z": 17,
      "name": "Empty"
    },
    {
      "x": 0,
      "y": 38,
      "z": 17,
      "name": "Empty"
    },
    {
      "x": 0,
      "y": 39,
      "z": 17,
      "name": "Empty"
    },
    {
      "x": 0,
      "y": 40,
      "z": 17,
      "name": "Empty"
    },
    {
      "x": 0,
      "y": 41,
      "z": 17,
      "name": "Empty"
    },
    {
      "x": 0,
      "y": 42,
      "z": 17,
      "name": "Rock_Basalt"
    },
    {
      "x": 0,
      "y": 35,
      "z": 18,
      "name": "Rock_Shale"
    },
    {
      "x": 0,
      "y": 36,
      "z": 18,
      "name": "Empty"
    },
    {
      "x": 0,
      "y": 37,
      "z": 18,
      "name": "Empty"
    },
    {
      "x": 0,
      "y": 38,
      "z": 18,
      "name": "Empty"
    },
    {
      "x": 0,
      "y": 39,
      "z": 18,
      "name": "Empty"
    },
    {
      "x": 0,
      "y": 40,
      "z": 18,
      "name": "Empty"
    },
    {
      "x": 0,
      "y": 41,
      "z": 18,
      "name": "Empty"
    },
    {
      "x": 0,
      "y": 42,
      "z": 18,
      "name": "Rock_Basalt"
    },
    {
      "x": 0,
      "y": 35,
      "z": 19,
      "name": "Rock_Shale"
    },
    {
      "x": 0,
      "y": 36,
      "z": 19,
      "name": "Empty"
    },
    {
      "x": 0,
      "y": 37,
      "z": 19,
      "name": "Empty"
    },
    {
      "x": 0,
      "y": 38,
      "z": 19,
      "name": "Empty"
    },
    {
      "x": 0,
      "y": 39,
      "z": 19,
      "name": "Empty"
    },
    {
      "x": 0,
      "y": 40,
      "z": 19,
      "name": "Empty"
    },
    {
      "x": 0,
      "y": 41,
      "z": 19,
      "name": "Empty"
    },
    {
      "x": 0,
      "y": 42,
      "z": 19,
      "name": "Rock_Basalt"
    },
    {
      "x": 0,
      "y": 35,
      "z": 20,
      "name": "Rock_Shale"
    },
    {
      "x": 0,
      "y": 36,
      "z": 20,
      "name": "Empty"
    },
    {
      "x": 0,
      "y": 37,
      "z": 20,
      "name": "Empty"
    },
    {
      "x": 0,
      "y": 38,
      "z": 20,
      "name": "Empty"
    },
    {
      "x": 0,
      "y": 39,
      "z": 20,
      "name": "Empty"
    },
    {
      "x": 0,
      "y": 40,
      "z": 20,
      "name": "Empty"
    },
    {
      "x": 0,
      "y": 41,
      "z": 20,
      "name": "Rock_Basalt_Brick"
    },
    {
      "x": 0,
      "y": 42,
      "z": 20,
      "name": "Rock_Basalt"
    },
    {
      "x": 0,
      "y": 35,
      "z": 21,
      "name": "Rock_Shale"
    },
    {
      "x": 0,
      "y": 36,
      "z": 21,
      "name": "Empty"
    },
    {
      "x": 0,
      "y": 37,
      "z": 21,
      "name": "Empty"
    },
    {
      "x": 0,
      "y": 38,
      "z": 21,
      "name": "Empty"
    },
    {
      "x": 0,
      "y": 39,
      "z": 21,
      "name": "Empty"
    },
    {
      "x": 0,
      "y": 40,
      "z": 21,
      "name": "Empty"
    },
    {
      "x": 0,
      "y": 41,
      "z": 21,
      "name": "Rock_Shale_Brick"
    },
    {
      "x": 0,
      "y": 42,
      "z": 21,
      "name": "Rock_Basalt"
    },
    {
      "x": 1,
      "y": 35,
      "z": 7,
      "name": "Rock_Basalt"
    },
    {
      "x": 1,
      "y": 36,
      "z": 7,
      "name": "Rock_Basalt"
    },
    {
      "x": 1,
      "y": 37,
      "z": 7,
      "name": "Rock_Basalt"
    },
    {
      "x": 1,
      "y": 38,
      "z": 7,
      "name": "Rock_Basalt"
    },
    {
      "x": 1,
      "y": 39,
      "z": 7,
      "name": "Rock_Basalt"
    },
    {
      "x": 1,
      "y": 40,
      "z": 7,
      "name": "Rock_Basalt"
    },
    {
      "x": 1,
      "y": 41,
      "z": 7,
      "name": "Rock_Basalt"
    },
    {
      "x": 1,
      "y": 42,
      "z": 7,
      "name": "Rock_Basalt"
    },
    {
      "x": 1,
      "y": 35,
      "z": 8,
      "name": "Rock_Shale_Brick_Smooth"
    },
    {
      "x": 1,
      "y": 36,
      "z": 8,
      "name": "Rock_Basalt_Brick"
    },
    {
      "x": 1,
      "y": 37,
      "z": 8,
      "name": "Deco_Bone_Pile"
    },
    {
      "x": 1,
      "y": 38,
      "z": 8,
      "name": "Rock_Basalt_Brick"
    },
    {
      "x": 1,
      "y": 39,
      "z": 8,
      "name": "Deco_Bone_Skulls"
    },
    {
      "x": 1,
      "y": 40,
      "z": 8,
      "name": "Rock_Basalt_Brick"
    },
    {
      "x": 1,
      "y": 41,
      "z": 8,
      "name": "Rock_Basalt_Brick"
    },
    {
      "x": 1,
      "y": 42,
      "z": 8,
      "name": "Rock_Basalt"
    },
    {
      "x": 1,
      "y": 35,
      "z": 9,
      "name": "Rock_Shale_Brick_Smooth"
    },
    {
      "x": 1,
      "y": 36,
      "z": 9,
      "name": "Empty"
    },
    {
      "x": 1,
      "y": 37,
      "z": 9,
      "name": "Empty"
    },
    {
      "x": 1,
      "y": 38,
      "z": 9,
      "name": "Empty"
    },
    {
      "x": 1,
      "y": 39,
      "z": 9,
      "name": "Empty"
    },
    {
      "x": 1,
      "y": 40,
      "z": 9,
      "name": "Empty"
    },
    {
      "x": 1,
      "y": 41,
      "z": 9,
      "name": "Empty"
    },
    {
      "x": 1,
      "y": 42,
      "z": 9,
      "name": "Rock_Basalt"
    },
    {
      "x": 1,
      "y": 35,
      "z": 10,
      "name": "Rock_Shale_Brick_Smooth"
    },
    {
      "x": 1,
      "y": 36,
      "z": 10,
      "name": "Rock_Shale_Brick_Beam"
    },
    {
      "x": 1,
      "y": 37,
      "z": 10,
      "name": "Furniture_Human_Ruins_Torch"
    },
    {
      "x": 1,
      "y": 38,
      "z": 10,
      "name": "Empty"
    },
    {
      "x": 1,
      "y": 39,
      "z": 10,
      "name": "Empty"
    },
    {
      "x": 1,
      "y": 40,
      "z": 10,
      "name": "Empty"
    },
    {
      "x": 1,
      "y": 41,
      "z": 10,
      "name": "Empty"
    },
    {
      "x": 1,
      "y": 42,
      "z": 10,
      "name": "Rock_Basalt"
    },
    {
      "x": 1,
      "y": 35,
      "z": 11,
      "name": "Rock_Shale_Brick_Smooth"
    },
    {
      "x": 1,
      "y": 36,
      "z": 11,
      "name": "Empty"
    },
    {
      "x": 1,
      "y": 37,
      "z": 11,
      "name": "Empty"
    },
    {
      "x": 1,
      "y": 38,
      "z": 11,
      "name": "Empty"
    },
    {
      "x": 1,
      "y": 39,
      "z": 11,
      "name": "Empty"
    },
    {
      "x": 1,
      "y": 40,
      "z": 11,
      "name": "Empty"
    },
    {
      "x": 1,
      "y": 41,
      "z": 11,
      "name": "Empty"
    },
    {
      "x": 1,
      "y": 42,
      "z": 11,
      "name": "Rock_Basalt"
    },
    {
      "x": 1,
      "y": 35,
      "z": 12,
      "name": "Rock_Shale_Brick_Smooth"
    },
    {
      "x": 1,
      "y": 36,
      "z": 12,
      "name": "Empty"
    },
    {
      "x": 1,
      "y": 37,
      "z": 12,
      "name": "Empty"
    },
    {
      "x": 1,
      "y": 38,
      "z": 12,
      "name": "Empty"
    },
    {
      "x": 1,
      "y": 39,
      "z": 12,
      "name": "Empty"
    },
    {
      "x": 1,
      "y": 40,
      "z": 12,
      "name": "Empty"
    },
    {
      "x": 1,
      "y": 41,
      "z": 12,
      "name": "Empty"
    },
    {
      "x": 1,
      "y": 42,
      "z": 12,
      "name": "Rock_Basalt"
    },
    {
      "x": 1,
      "y": 35,
      "z": 13,
      "name": "Rock_Shale_Brick_Smooth"
    },
    {
      "x": 1,
      "y": 36,
      "z": 13,
      "name": "Empty"
    },
    {
      "x": 1,
      "y": 37,
      "z": 13,
      "name": "Empty"
    },
    {
      "x": 1,
      "y": 38,
      "z": 13,
      "name": "Empty"
    },
    {
      "x": 1,
      "y": 39,
      "z": 13,
      "name": "Empty"
    },
    {
      "x": 1,
      "y": 40,
      "z": 13,
      "name": "Empty"
    },
    {
      "x": 1,
      "y": 41,
      "z": 13,
      "name": "Empty"
    },
    {
      "x": 1,
      "y": 42,
      "z": 13,
      "name": "Rock_Basalt"
    },
    {
      "x": 1,
      "y": 35,
      "z": 14,
      "name": "Soil_Dirt_Cold"
    },
    {
      "x": 1,
      "y": 36,
      "z": 14,
      "name": "Empty"
    },
    {
      "x": 1,
      "y": 37,
      "z": 14,
      "name": "Empty"
    },
    {
      "x": 1,
      "y": 38,
      "z": 14,
      "name": "Empty"
    },
    {
      "x": 1,
      "y": 39,
      "z": 14,
      "name": "Empty"
    },
    {
      "x": 1,
      "y": 40,
      "z": 14,
      "name": "Empty"
    },
    {
      "x": 1,
      "y": 41,
      "z": 14,
      "name": "Empty"
    },
    {
      "x": 1,
      "y": 42,
      "z": 14,
      "name": "Rock_Basalt"
    },
    {
      "x": 1,
      "y": 35,
      "z": 15,
      "name": "Soil_Dirt_Cold"
    },
    {
      "x": 1,
      "y": 36,
      "z": 15,
      "name": "Empty"
    },
    {
      "x": 1,
      "y": 37,
      "z": 15,
      "name": "Empty"
    },
    {
      "x": 1,
      "y": 38,
      "z": 15,
      "name": "Empty"
    },
    {
      "x": 1,
      "y": 39,
      "z": 15,
      "name": "Empty"
    },
    {
      "x": 1,
      "y": 40,
      "z": 15,
      "name": "Empty"
    },
    {
      "x": 1,
      "y": 41,
