{
  "version": 8,
  "blockIdVersion": 8,
  "anchorX": -1,
  "anchorY": 4,
  "anchorZ": 0,
  "blocks": [
    {
      "x": -3,
      "y": 5,
      "z": 0,
      "name": "Plant_Moss_Wall_Yellow",
      "rotation": 3
    },
    {
      "x": -2,
      "y": 5,
      "z": -2,
      "name": "Plant_Moss_Wall_Yellow",
      "rotation": 2
    },
    {
      "x": -2,
      "y": 3,
      "z": -1,
      "name": "Rock_Quartzite"
    },
    {
      "x": -2,
      "y": 4,
      "z": -1,
      "name": "Rock_Quartzite"
    },
    {
      "x": -2,
      "y": 5,
      "z": -1,
      "name": "Plant_Moss_Block_Yellow"
    },
    {
      "x": -2,
      "y": 4,
      "z": 0,
      "name": "Rock_Quartzite"
    },
    {
      "x": -2,
      "y": 5,
      "z": 0,
      "name": "Plant_Moss_Block_Yellow"
    },
    {
      "x": -2,
      "y": 6,
      "z": 0,
      "name": "Plant_Moss_Yellow"
    },
    {
      "x": -1,
      "y": 5,
      "z": -2,
      "name": "Plant_Moss_Wall_Yellow",
      "rotation": 2
    },
    {
      "x": -1,
      "y": 4,
      "z": -1,
      "name": "Rock_Quartzite"
    },
    {
      "x": -1,
      "y": 5,
      "z": -1,
      "name": "Plant_Moss_Block_Yellow"
    },
    {
      "x": -1,
      "y": 6,
      "z": -1,
      "name": "Plant_Moss_Yellow"
    },
    {
      "x": -1,
      "y": 2,
      "z": 0,
      "name": "Rock_Quartzite"
    },
    {
      "x": -1,
      "y": 3,
      "z": 0,
      "name": "Rock_Quartzite"
    },
    {
      "x": -1,
      "y": 4,
      "z": 0,
      "name": "Rock_Quartzite"
    },
    {
      "x": -1,
      "y": 5,
      "z": 0,
      "name": "Rock_Quartzite"
    },
    {
      "x": -1,
      "y": 6,
      "z": 0,
      "name": "Plant_Moss_Block_Yellow"
    },
    {
      "x": -1,
      "y": 7,
      "z": 0,
      "name": "Plant_Moss_Rug_Yellow"
    },
    {
      "x": -1,
      "y": 3,
      "z": 1,
      "name": "Rock_Quartzite"
    },
    {
      "x": -1,
      "y": 4,
      "z": 1,
      "name": "Rock_Quartzite"
    },
    {
      "x": 0,
      "y": 5,
      "z": -1,
      "name": "Plant_Moss_Wall_Yellow",
      "rotation": 2
    },
    {
      "x": 0,
      "y": 6,
      "z": -1,
      "name": "Plant_Moss_Wall_Yellow",
      "rotation": 2
    },
    {
      "x": 0,
      "y": 3,
      "z": 0,
      "name": "Rock_Quartzite"
    },
    {
      "x": 0,
      "y": 4,
      "z": 0,
      "name": "Rock_Quartzite"
    },
    {
      "x": 0,
      "y": 5,
      "z": 0,
      "name": "Rock_Quartzite"
    },
    {
      "x": 0,
      "y": 6,
      "z": 0,
      "name": "Plant_Moss_Block_Yellow"
    },
    {
      "x": 0,
      "y": 4,
      "z": 1,
      "name": "Rock_Quartzite"
    },
    {
      "x": 0,
      "y": 5,
      "z": 1,
      "name": "Rock_Quartzite"
    },
    {
      "x": 0,
      "y": 6,
      "z": 1,
      "name": "Plant_Moss_Block_Yellow"
    },
    {
      "x": 0,
      "y": 6,
      "z": 2,
      "name": "Plant_Moss_Wall_Yellow"
    },
    {
      "x": 1,
      "y": 6,
      "z": 0,
      "name": "Plant_Moss_Wall_Yellow",
      "rotation": 1
    },
    {
      "x": 1,
      "y": 4,
      "z": 1,
      "name": "Rock_Quartzite"
    },
    {
      "x": 1,
      "y": 5,
      "z": 1,
      "name": "Plant_Crop_Health3",
      "rotation": 1
    },
    {
      "x": 1,
      "y": 6,
      "z": 1,
      "name": "Plant_Crop_Health3",
      "filler": 1024,
      "rotation": 1
    },
    {
      "x": 2,
      "y": 5,
      "z": 1,
      "name": "Empty"
    },
    {
      "x": 2,
      "y": 6,
      "z": 1,
      "name": "Empty"
    }
  ]
}