{
  "version": 8,
  "blockIdVersion": 8,
  "anchorX": 21,
  "anchorY": 15,
  "anchorZ": 17,
  "blocks": [
    {
      "x": 7,
      "y": 22,
      "z": 9,
      "name": "Rock_Volcanic_Cracked_Poisoned"
    },
    {
      "x": 7,
      "y": 22,
      "z": 10,
      "name": "Rock_Volcanic_Cracked_Poisoned"
    },
    {
      "x": 7,
      "y": 22,
      "z": 11,
      "name": "Rock_Volcanic_Cracked_Poisoned"
    },
    {
      "x": 7,
      "y": 29,
      "z": 20,
      "name": "Rock_Volcanic_Cracked_Poisoned"
    },
    {
      "x": 7,
      "y": 29,
      "z": 21,
      "name": "Rock_Volcanic_Cracked_Poisoned"
    },
    {
      "x": 8,
      "y": 22,
      "z": 7,
      "name": "Rock_Volcanic_Cracked_Poisoned"
    },
    {
      "x": 8,
      "y": 22,
      "z": 8,
      "name": "Rock_Volcanic_Cracked_Poisoned"
    },
    {
      "x": 8,
      "y": 22,
      "z": 9,
      "name": "Rock_Volcanic_Cracked_Poisoned"
    },
    {
      "x": 8,
      "y": 22,
      "z": 10,
      "name": "Rock_Volcanic_Cracked_Poisoned"
    },
    {
      "x": 8,
      "y": 22,
      "z": 11,
      "name": "Rock_Volcanic_Cracked_Poisoned"
    },
    {
      "x": 8,
      "y": 28,
      "z": 19,
      "name": "Rock_Slate"
    },
    {
      "x": 8,
      "y": 28,
      "z": 20,
      "name": "Rock_Slate"
    },
    {
      "x": 8,
      "y": 29,
      "z": 20,
      "name": "Rock_Volcanic_Cracked_Poisoned"
    },
    {
      "x": 8,
      "y": 29,
      "z": 21,
      "name": "Rock_Volcanic_Cracked_Poisoned"
    },
    {
      "x": 8,
      "y": 29,
      "z": 22,
      "name": "Rock_Volcanic_Cracked_Poisoned"
    },
    {
      "x": 8,
      "y": 29,
      "z": 23,
      "name": "Rock_Volcanic_Cracked_Poisoned"
    },
    {
      "x": 9,
      "y": 22,
      "z": 7,
      "name": "Rock_Volcanic_Cracked_Poisoned"
    },
    {
      "x": 9,
      "y": 22,
      "z": 8,
      "name": "Rock_Volcanic_Cracked_Poisoned"
    },
    {
      "x": 9,
      "y": 21,
      "z": 9,
      "name": "Rock_Slate"
    },
    {
      "x": 9,
      "y": 22,
      "z": 9,
      "name": "Rock_Slate"
    },
    {
      "x": 9,
      "y": 21,
      "z": 10,
      "name": "Rock_Volcanic"
    },
    {
      "x": 9,
      "y": 22,
      "z": 10,
      "name": "Rock_Slate"
    },
    {
      "x": 9,
      "y": 22,
      "z": 11,
      "name": "Rock_Volcanic_Cracked_Poisoned"
    },
    {
      "x": 9,
      "y": 22,
      "z": 12,
      "name": "Rock_Slate"
    },
    {
      "x": 9,
      "y": 28,
      "z": 18,
      "name": "Rock_Volcanic_Cracked_Poisoned"
    },
    {
      "x": 9,
      "y": 27,
      "z": 19,
      "name": "Rock_Slate"
    },
    {
      "x": 9,
      "y": 28,
      "z": 19,
      "name": "Rock_Volcanic_Cracked_Poisoned"
    },
    {
      "x": 9,
      "y": 28,
      "z": 20,
      "name": "Rock_Slate"
    },
    {
      "x": 9,
      "y": 29,
      "z": 20,
      "name": "Rock_Slate"
    },
    {
      "x": 9,
      "y": 28,
      "z": 21,
      "name": "Rock_Slate"
    },
    {
      "x": 9,
      "y": 29,
      "z": 21,
      "name": "Rock_Slate"
    },
    {
      "x": 9,
      "y": 28,
      "z": 22,
      "name": "Rock_Slate"
    },
    {
      "x": 9,
      "y": 29,
      "z": 22,
      "name": "Rock_Volcanic_Cracked_Poisoned"
    },
    {
      "x": 9,
      "y": 29,
      "z": 23,
      "name": "Rock_Volcanic_Cracked_Poisoned"
    },
    {
      "x": 10,
      "y": 21,
      "z": 8,
      "name": "Rock_Volcanic"
    },
    {
      "x": 10,
      "y": 22,
      "z": 8,
      "name": "Rock_Slate"
    },
    {
      "x": 10,
      "y": 21,
      "z": 9,
      "name": "Rock_Slate"
    },
    {
      "x": 10,
      "y": 22,
      "z": 9,
      "name": "Rock_Slate"
    },
    {
      "x": 10,
      "y": 21,
      "z": 10,
      "name": "Rock_Volcanic"
    },
    {
      "x": 10,
      "y": 22,
      "z": 10,
      "name": "Rock_Slate"
    },
    {
      "x": 10,
      "y": 21,
      "z": 11,
      "name": "Rock_Volcanic"
    },
    {
      "x": 10,
      "y": 22,
      "z": 11,
      "name": "Rock_Slate"
    },
    {
      "x": 10,
      "y": 21,
      "z": 12,
      "name": "Rock_Slate"
    },
    {
      "x": 10,
      "y": 22,
      "z": 12,
      "name": "Rock_Slate"
    },
    {
      "x": 10,
      "y": 27,
      "z": 17,
      "name": "Rock_Slate"
    },
    {
      "x": 10,
      "y": 27,
      "z": 18,
      "name": "Rock_Slate"
    },
    {
      "x": 10,
      "y": 28,
      "z": 18,
      "name": "Rock_Volcanic_Cracked_Poisoned"
    },
    {
      "x": 10,
      "y": 27,
      "z": 19,
      "name": "Rock_Volcanic"
    },
    {
      "x": 10,
      "y": 28,
      "z": 19,
      "name": "Rock_Slate"
    },
    {
      "x": 10,
      "y": 27,
      "z": 20,
      "name": "Rock_Slate"
    },
    {
      "x": 10,
      "y": 28,
      "z": 20,
      "name": "Rock_Slate"
    },
    {
      "x": 10,
      "y": 27,
      "z": 21,
      "name": "Rock_Slate"
    },
    {
      "x": 10,
      "y": 28,
      "z": 21,
      "name": "Rock_Slate"
    },
    {
      "x": 10,
      "y": 28,
      "z": 22,
      "name": "Rock_Slate"
    },
    {
      "x": 10,
      "y": 29,
      "z": 22,
      "name": "Rock_Slate"
    },
    {
      "x": 10,
      "y": 28,
      "z": 23,
      "name": "Rock_Volcanic"
    },
    {
      "x": 10,
      "y": 29,
      "z": 23,
      "name": "Rock_Slate"
    },
    {
      "x": 11,
      "y": 21,
      "z": 8,
      "name": "Rock_Slate"
    },
    {
      "x": 11,
      "y": 22,
      "z": 8,
      "name": "Rock_Slate"
    },
    {
      "x": 11,
      "y": 21,
      "z": 9,
      "name": "Rock_Volcanic"
    },
    {
      "x": 11,
      "y": 22,
      "z": 9,
      "name": "Rock_Slate"
    },
    {
      "x": 11,
      "y": 21,
      "z": 10,
      "name": "Rock_Volcanic"
    },
    {
      "x": 11,
      "y": 21,
      "z": 11,
      "name": "Rock_Volcanic"
    },
    {
      "x": 11,
      "y": 21,
      "z": 12,
      "name": "Rock_Slate"
    },
    {
      "x": 11,
      "y": 21,
      "z": 13,
      "name": "Rock_Slate"
    },
    {
      "x": 11,
      "y": 27,
      "z": 17,
      "name": "Rock_Slate"
    },
    {
      "x": 11,
      "y": 27,
      "z": 18,
      "name": "Rock_Slate"
    },
    {
      "x": 11,
      "y": 27,
      "z": 19,
      "name": "Rock_Slate"
    },
    {
      "x": 11,
      "y": 28,
      "z": 19,
      "name": "Rock_Slate"
    },
    {
      "x": 11,
      "y": 27,
      "z": 20,
      "name": "Rock_Volcanic"
    },
    {
      "x": 11,
      "y": 28,
      "z": 20,
      "name": "Rock_Slate"
    },
    {
      "x": 11,
      "y": 27,
      "z": 21,
      "name": "Rock_Slate"
    },
    {
      "x": 11,
      "y": 28,
      "z": 21,
      "name": "Rock_Slate"
    },
    {
      "x": 11,
      "y": 27,
      "z": 22,
      "name": "Rock_Slate"
    },
    {
      "x": 11,
      "y": 28,
      "z": 22,
      "name": "Rock_Slate"
    },
    {
      "x": 11,
      "y": 28,
      "z": 23,
      "name": "Rock_Slate"
    },
    {
      "x": 12,
      "y": 22,
      "z": 5,
      "name": "Rock_Volcanic_Cracked_Poisoned"
    },
    {
      "x": 12,
      "y": 22,
      "z": 6,
      "name": "Rock_Volcanic_Cracked_Poisoned"
    },
    {
      "x": 12,
      "y": 21,
      "z": 8,
      "name": "Rock_Volcanic"
    },
    {
      "x": 12,
      "y": 22,
      "z": 8,
      "name": "Rock_Slate"
    },
    {
      "x": 12,
      "y": 21,
      "z": 9,
      "name": "Rock_Volcanic"
    },
    {
      "x": 12,
      "y": 21,
      "z": 10,
      "name": "Rock_Volcanic"
    },
    {
      "x": 12,
      "y": 20,
      "z": 11,
      "name": "Rock_Volcanic"
    },
    {
      "x": 12,
      "y": 21,
      "z": 11,
      "name": "Rock_Volcanic"
    },
    {
      "x": 12,
      "y": 20,
      "z": 12,
      "name": "Rock_Volcanic"
    },
    {
      "x": 12,
      "y": 21,
      "z": 12,
      "name": "Rock_Volcanic"
    },
    {
      "x": 12,
      "y": 20,
      "z": 13,
      "name": "Rock_Slate"
    },
    {
      "x": 12,
      "y": 21,
      "z": 13,
      "name": "Rock_Slate"
    },
    {
      "x": 12,
      "y": 20,
      "z": 14,
      "name": "Rock_Slate"
    },
    {
      "x": 12,
      "y": 27,
      "z": 16,
      "name": "Rock_Slate"
    },
    {
      "x": 12,
      "y": 27,
      "z": 17,
      "name": "Rock_Slate"
    },
    {
      "x": 12,
      "y": 27,
      "z": 18,
      "name": "Rock_Slate"
    },
    {
      "x": 12,
      "y": 26,
      "z": 19,
      "name": "Rock_Volcanic"
    },
    {
      "x": 12,
      "y": 27,
      "z": 19,
      "name": "Rock_Volcanic"
    },
    {
      "x": 12,
      "y": 26,
      "z": 20,
      "name": "Rock_Volcanic"
    },
    {
      "x": 12,
      "y": 27,
      "z": 20,
      "name": "Rock_Volcanic"
    },
    {
      "x": 12,
      "y": 27,
      "z": 21,
      "name": "Rock_Volcanic"
    },
    {
      "x": 12,
      "y": 28,
      "z": 21,
      "name": "Rock_Slate"
    },
    {
      "x": 12,
      "y": 27,
      "z": 22,
      "name": "Rock_Slate"
    },
    {
      "x": 12,
      "y": 28,
      "z": 22,
      "name": "Rock_Slate"
    },
    {
      "x": 12,
      "y": 28,
      "z": 23,
      "name": "Rock_Slate"
    },
    {
      "x": 13,
      "y": 22,
      "z": 4,
      "name": "Rock_Volcanic_Cracked_Poisoned"
    },
    {
      "x": 13,
      "y": 22,
      "z": 5,
      "name": "Rock_Volcanic_Cracked_Poisoned"
    },
    {
      "x": 13,
      "y": 21,
      "z": 6,
      "name": "Rock_Volcanic"
    },
    {
      "x": 13,
      "y": 22,
      "z": 6,
      "name": "Rock_Slate"
    },
    {
      "x": 13,
      "y": 21,
      "z": 7,
      "name": "Rock_Volcanic"
    },
    {
      "x": 13,
      "y": 21,
      "z": 8,
      "name": "Rock_Volcanic"
    },
    {
      "x": 13,
      "y": 20,
      "z": 9,
      "name": "Rock_Volcanic"
    },
    {
      "x": 13,
      "y": 21,
      "z": 9,
      "name": "Rock_Volcanic"
    },
    {
      "x": 13,
      "y": 20,
      "z": 10,
      "name": "Rock_Volcanic"
    },
    {
      "x": 13,
      "y": 21,
      "z": 10,
      "name": "Rock_Volcanic"
    },
    {
      "x": 13,
      "y": 20,
      "z": 11,
      "name": "Rock_Volcanic"
    },
    {
      "x": 13,
      "y": 21,
      "z": 11,
      "name": "Rock_Volcanic"
    },
    {
      "x": 13,
      "y": 20,
      "z": 12,
      "name": "Rock_Volcanic"
    },
    {
      "x": 13,
      "y": 21,
      "z": 12,
      "name": "Rock_Volcanic"
    },
    {
      "x": 13,
      "y": 20,
      "z": 13,
      "name": "Rock_Volcanic"
    },
    {
      "x": 13,
      "y": 21,
      "z": 13,
      "name": "Rock_Volcanic"
    },
    {
      "x": 13,
      "y": 34,
      "z": 13,
      "name": "Rock_Volcanic_Cracked_Poisoned"
    },
    {
      "x": 13,
      "y": 20,
      "z": 14,
      "name": "Rock_Slate"
    },
    {
      "x": 13,
      "y": 34,
      "z": 14,
      "name": "Rock_Volcanic_Cracked_Poisoned"
    },
    {
      "x": 13,
      "y": 33,
      "z": 15,
      "name": "Rock_Volcanic"
    },
    {
      "x": 13,
      "y": 34,
      "z": 15,
      "name": "Rock_Volcanic_Cracked_Poisoned"
    },
    {
      "x": 13,
      "y": 27,
      "z": 16,
      "name": "Rock_Slate"
    },
    {
      "x": 13,
      "y": 26,
      "z": 17,
      "name": "Rock_Volcanic"
    },
    {
      "x": 13,
      "y": 27,
      "z": 17,
      "name": "Rock_Slate"
    },
    {
      "x": 13,
      "y": 26,
      "z": 18,
      "name": "Rock_Volcanic"
    },
    {
      "x": 13,
      "y": 27,
      "z": 18,
      "name": "Rock_Volcanic"
    },
    {
      "x": 13,
      "y": 26,
      "z": 19,
      "name": "Rock_Volcanic"
    },
    {
      "x": 13,
      "y": 27,
      "z": 19,
      "name": "Rock_Volcanic"
    },
    {
      "x": 13,
      "y": 26,
      "z": 20,
      "name": "Rock_Volcanic"
    },
    {
      "x": 13,
      "y": 27,
      "z": 20,
      "name": "Rock_Volcanic"
    },
    {
      "x": 13,
      "y": 27,
      "z": 21,
      "name": "Rock_Volcanic"
    },
    {
      "x": 13,
      "y": 27,
      "z": 22,
      "name": "Rock_Slate"
    },
    {
      "x": 13,
      "y": 33,
      "z": 22,
      "name": "Rock_Slate"
    },
    {
      "x": 13,
      "y": 34,
      "z": 22,
      "name": "Rock_Slate"
    },
    {
      "x": 13,
      "y": 27,
      "z": 23,
      "name": "Rock_Slate"
    },
    {
      "x": 13,
      "y": 28,
      "z": 23,
      "name": "Rock_Slate"
    },
    {
      "x": 13,
      "y": 34,
      "z": 23,
      "name": "Rock_Volcanic_Cracked_Poisoned"
    },
    {
      "x": 13,
      "y": 34,
      "z": 24,
      "name": "Rock_Volcanic_Cracked_Poisoned"
    },
    {
      "x": 14,
      "y": 22,
      "z": 4,
      "name": "Rock_Volcanic_Cracked_Poisoned"
    },
    {
      "x": 14,
      "y": 22,
      "z": 5,
      "name": "Rock_Volcanic_Cracked_Poisoned"
    },
    {
      "x": 14,
      "y": 21,
      "z": 6,
      "name": "Rock_Slate"
    },
    {
      "x": 14,
      "y": 22,
      "z": 6,
      "name": "Rock_Slate"
    },
    {
      "x": 14,
      "y": 20,
      "z": 7,
      "name": "Rock_Volcanic"
    },
    {
      "x": 14,
      "y": 21,
      "z": 7,
      "name": "Rock_Volcanic"
    },
    {
      "x": 14,
      "y": 20,
      "z": 8,
      "name": "Rock_Volcanic"
    },
    {
      "x": 14,
      "y": 21,
      "z": 8,
      "name": "Rock_Volcanic"
    },
    {
      "x": 14,
      "y": 29,
      "z": 8,
      "name": "Rock_Volcanic_Cracked_Poisoned"
    },
    {
      "x": 14,
      "y": 20,
      "z": 9,
      "name": "Rock_Volcanic"
    },
    {
      "x": 14,
      "y": 21,
      "z": 9,
      "name": "Rock_Volcanic"
    },
    {
      "x": 14,
      "y": 29,
      "z": 9,
      "name": "Rock_Volcanic_Cracked_Poisoned"
    },
    {
      "x": 14,
      "y": 20,
      "z": 10,
      "name": "Rock_Volcanic"
    },
    {
      "x": 14,
      "y": 21,
      "z": 10,
      "name": "Rock_Volcanic"
    },
    {
      "x": 14,
      "y": 29,
      "z": 10,
      "name": "Rock_Volcanic_Cracked_Poisoned"
    },
    {
      "x": 14,
      "y": 19,
      "z": 11,
      "name": "Rock_Volcanic"
    },
    {
      "x": 14,
      "y": 20,
      "z": 11,
      "name": "Soil_Dirt_Burnt"
    },
    {
      "x": 14,
      "y": 29,
      "z": 11,
      "name": "Rock_Volcanic_Cracked_Poisoned"
    },
    {
      "x": 14,
      "y": 19,
      "z": 12,
      "name": "Rock_Volcanic"
    },
    {
      "x": 14,
      "y": 20,
      "z": 12,
      "name": "Rock_Volcanic"
    },
    {
      "x": 14,
      "y": 34,
      "z": 12,
      "name": "Rock_Volcanic_Cracked_Poisoned"
    },
    {
      "x": 14,
      "y": 20,
      "z": 13,
      "name": "Rock_Volcanic"
    },
    {
      "x": 14,
      "y": 34,
      "z": 13,
      "name": "Rock_Volcanic_Cracked_Poisoned"
    },
    {
      "x": 14,
      "y": 20,
      "z": 14,
      "name": "Rock_Volcanic"
    },
    {
      "x": 14,
      "y": 33,
      "z": 14,
      "name": "Rock_Slate"
    },
    {
      "x": 14,
      "y": 34,
      "z": 14,
      "name": "Rock_Volcanic_Cracked_Poisoned"
    },
    {
      "x": 14,
      "y": 20,
      "z": 15,
      "name": "Rock_Volcanic"
    },
    {
      "x": 14,
      "y": 27,
      "z": 15,
      "name": "Rock_Volcanic"
    },
    {
      "x": 14,
      "y": 33,
      "z": 15,
      "name": "Rock_Slate"
    },
    {
      "x": 14,
      "y": 34,
      "z": 15,
      "name": "Rock_Slate"
    },
    {
      "x": 14,
      "y": 27,
      "z": 16,
      "name": "Rock_Volcanic"
    },
    {
      "x": 14,
      "y": 33,
      "z": 16,
      "name": "Rock_Slate"
    },
    {
      "x": 14,
      "y": 26,
      "z": 17,
      "name": "Rock_Volcanic"
    },
    {
      "x": 14,
      "y": 27,
      "z": 17,
      "name": "Rock_Volcanic"
    },
    {
      "x": 14,
      "y": 26,
      "z": 18,
      "name": "Rock_Volcanic"
    },
    {
      "x": 14,
      "y": 27,
      "z": 18,
      "name": "Soil_Grass_Burnt"
    },
    {
      "x": 14,
      "y": 26,
      "z": 19,
      "name": "Rock_Volcanic"
    },
    {
      "x": 14,
      "y": 27,
      "z": 19,
      "name": "Soil_Grass_Burnt"
    },
    {
      "x": 14,
      "y": 26,
      "z": 20,
      "name": "Rock_Volcanic"
    },
    {
      "x": 14,
      "y": 27,
      "z": 20,
      "name": "Rock_Volcanic"
    },
    {
      "x": 14,
      "y": 33,
      "z": 20,
      "name": "Rock_Slate"
    },
    {
      "x": 14,
      "y": 26,
      "z": 21,
      "name": "Rock_Volcanic"
    },
    {
      "x": 14,
      "y": 27,
      "z": 21,
      "name": "Rock_Slate"
    },
    {
      "x": 14,
      "y": 33,
      "z": 21,
      "name": "Rock_Slate"
    },
    {
      "x": 14,
      "y": 27,
      "z": 22,
      "name": "Rock_Slate"
    },
    {
      "x": 14,
      "y": 33,
      "z": 22,
      "name": "Rock_Slate"
    },
    {
      "x": 14,
      "y": 27,
      "z": 23,
      "name": "Rock_Slate"
    },
    {
      "x": 14,
      "y": 33,
      "z": 23,
      "name": "Rock_Slate"
    },
    {
      "x": 14,
      "y": 34,
      "z": 23,
      "name": "Rock_Slate"
    },
    {
      "x": 14,
      "y": 33,
      "z": 24,
      "name": "Rock_Slate"
    },
    {
      "x": 14,
      "y": 34,
      "z": 24,
      "name": "Rock_Volcanic_Cracked_Poisoned"
    },
    {
      "x": 14,
      "y": 34,
      "z": 25,
      "name": "Rock_Volcanic_Cracked_Poisoned"
    },
    {
      "x": 15,
      "y": 22,
      "z": 4,
      "name": "Rock_Volcanic_Cracked_Poisoned"
    },
    {
      "x": 15,
      "y": 22,
      "z": 5,
      "name": "Rock_Volcanic_Cracked_Poisoned"
    },
    {
      "x": 15,
      "y": 21,
      "z": 6,
      "name": "Rock_Slate"
    },
    {
      "x": 15,
      "y": 20,
      "z": 7,
      "name": "Rock_Volcanic"
    },
    {
      "x": 15,
      "y": 21,
      "z": 7,
      "name": "Rock_Slate"
    },
    {
      "x": 15,
      "y": 29,
      "z": 7,
      "name": "Rock_Volcanic_Cracked_Poisoned"
    },
    {
      "x": 15,
      "y": 20,
      "z": 8,
      "name": "Rock_Volcanic"
    },
    {
      "x": 15,
      "y": 21,
      "z": 8,
      "name": "Rock_Volcanic"
    },
    {
      "x": 15,
      "y": 29,
      "z": 8,
      "name": "Rock_Volcanic_Cracked_Poisoned"
    },
    {
      "x": 15,
      "y": 19,
      "z": 9,
      "name": "Rock_Volcanic"
    },
    {
      "x": 15,
      "y": 20,
      "z": 9,
      "name": "Rock_Volcanic"
    },
    {
      "x": 15,
      "y": 21,
      "z": 9,
      "name": "Rock_Volcanic"
    },
    {
      "x": 15,
      "y": 29,
      "z": 9,
      "name": "Rock_Volcanic_Cracked_Poisoned"
    },
    {
      "x": 15,
      "y": 19,
      "z": 10,
      "name": "Rock_Volcanic"
    },
    {
      "x": 15,
      "y": 20,
      "z": 10,
      "name": "Soil_Dirt_Burnt"
    },
    {
      "x": 15,
      "y": 21,
      "z": 10,
      "name": "Rock_Volcanic"
    },
    {
      "x": 15,
      "y": 29,
      "z": 10,
      "name": "Rock_Volcanic_Cracked_Poisoned"
    },
    {
      "x": 15,
      "y": 19,
      "z": 11,
      "name": "Soil_Dirt_Burnt"
    },
    {
      "x": 15,
      "y": 20,
      "z": 11,
      "name": "Soil_Dirt_Burnt"
    },
    {
      "x": 15,
      "y": 29,
      "z": 11,
      "name": "Rock_Slate"
    },
    {
      "x": 15,
      "y": 19,
      "z": 12,
      "name": "Rock_Volcanic"
    },
    {
      "x": 15,
      "y": 20,
      "z": 12,
      "name": "Soil_Grass_Burnt"
    },
    {
      "x": 15,
      "y": 28,
      "z": 12,
      "name": "Rock_Volcanic"
    },
    {
      "x": 15,
      "y": 34,
      "z": 12,
      "name": "Rock_Volcanic_Cracked_Poisoned"
    },
    {
      "x": 15,
      "y": 19,
      "z": 13,
      "name": "Rock_Volcanic"
    },
    {
      "x": 15,
      "y": 20,
      "z": 13,
      "name": "Soil_Dirt_Burnt"
    },
    {
      "x": 15,
      "y": 33,
      "z": 13,
      "name": "Rock_Volcanic"
    },
    {
      "x": 15,
      "y": 34,
      "z": 13,
      "name": "Rock_Slate"
    },
    {
      "x": 15,
      "y": 19,
      "z": 14,
      "name": "Rock_Volcanic"
    },
    {
      "x": 15,
      "y": 20,
      "z": 14,
      "name": "Rock_Volcanic"
    },
    {
      "x": 15,
      "y": 33,
      "z": 14,
      "name": "Rock_Volcanic"
    },
    {
      "x": 15,
      "y": 34,
      "z": 14,
      "name": "Rock_Slate"
    },
    {
      "x": 15,
      "y": 33,
      "z": 15,
      "name": "Rock_Slate"
    },
    {
      "x": 15,
      "y": 26,
      "z": 16,
      "name": "Rock_Volcanic"
    },
    {
      "x": 15,
      "y": 27,
      "z": 16,
      "name": "Rock_Volcanic"
    },
    {
      "x": 15,
      "y": 33,
      "z": 16,
      "name": "Rock_Slate"
    },
    {
      "x": 15,
      "y": 26,
      "z": 17,
      "name": "Rock_Volcanic"
    },
    {
      "x": 15,
      "y": 27,
      "z": 17,
      "name": "Soil_Grass_Burnt"
    },
    {
      "x": 15,
      "y": 26,
      "z": 18,
      "name": "Soil_Dirt_Burnt"
    },
    {
      "x": 15,
      "y": 27,
      "z": 18,
      "name": "Soil_Grass_Burnt"
    },
    {
      "x": 15,
      "y": 26,
      "z": 19,
      "name": "Soil_Dirt_Burnt"
    },
    {
      "x": 15,
      "y": 27,
      "z": 19,
      "name": "Soil_Grass_Burnt"
    },
    {
      "x": 15,
      "y": 28,
      "z": 19,
      "name": "Plant_Flower_Bushy_Violet"
    },
    {
      "x": 15,
      "y": 33,
      "z": 19,
      "name": "Rock_Slate"
    },
    {
      "x": 15,
      "y": 26,
      "z": 20,
      "name": "Rock_Volcanic"
    },
    {
      "x": 15,
      "y": 27,
      "z": 20,
      "name": "Soil_Grass_Burnt"
    },
    {
      "x": 15,
      "y": 33,
      "z": 20,
      "name": "Rock_Slate"
    },
    {
      "x": 15,
      "y": 26,
      "z": 21,
      "name": "Rock_Volcanic"
    },
    {
      "x": 15,
      "y": 27,
      "z": 21,
      "name": "Rock_Volcanic"
    },
    {
      "x": 15,
      "y": 33,
      "z": 21,
      "name": "Rock_Slate"
    },
    {
      "x": 15,
      "y": 27,
      "z": 22,
      "name": "Rock_Slate"
    },
    {
      "x": 15,
      "y": 33,
      "z": 22,
      "name": "Rock_Slate"
    },
    {
      "x": 15,
      "y": 27,
      "z": 23,
      "name": "Rock_Slate"
    },
    {
      "x": 15,
      "y": 33,
      "z": 23,
      "name": "Rock_Volcanic"
    },
    {
      "x": 15,
      "y": 34,
      "z": 23,
      "name": "Rock_Slate"
    },
    {
      "x": 15,
      "y": 33,
      "z": 24,
      "name": "Rock_Volcanic"
    },
    {
      "x": 15,
      "y": 34,
      "z": 24,
      "name": "Rock_Volcanic_Cracked_Poisoned"
    },
    {
      "x": 15,
      "y": 34,
      "z": 25,
      "name": "Rock_Volcanic_Cracked_Poisoned"
    },
    {
      "x": 16,
      "y": 21,
      "z": 6,
      "name": "Rock_Slate"
    },
    {
      "x": 16,
      "y": 20,
      "z": 7,
      "name": "Rock_Slate"
    },
    {
      "x": 16,
      "y": 21,
      "z": 7,
      "name": "Rock_Slate"
    },
    {
      "x": 16,
      "y": 29,
      "z": 7,
      "name": "Rock_Volcanic_Cracked_Poisoned"
    },
    {
      "x": 16,
      "y": 20,
      "z": 8,
      "name": "Rock_Volcanic"
    },
    {
      "x": 16,
      "y": 21,
      "z": 8,
      "name": "Rock_Slate"
    },
    {
      "x": 16,
      "y": 29,
      "z": 8,
      "name": "Rock_Volcanic_Cracked_Poisoned"
    },
    {
      "x": 16,
      "y": 19,
      "z": 9,
      "name": "Rock_Volcanic"
    },
    {
      "x": 16,
      "y": 20,
      "z": 9,
      "name": "Rock_Volcanic"
    },
    {
      "x": 16,
      "y": 29,
      "z": 9,
      "name": "Rock_Slate"
    },
    {
      "x": 16,
      "y": 19,
      "z": 10,
      "name": "Rock_Volcanic"
    },
    {
      "x": 16,
      "y": 20,
      "z": 10,
      "name": "Soil_Dirt_Burnt"
    },
    {
      "x": 16,
      "y": 28,
      "z": 10,
      "name": "Rock_Volcanic"
    },
    {
      "x": 16,
      "y": 29,
      "z": 10,
      "name": "Rock_Volcanic"
    },
    {
      "x": 16,
      "y": 19,
      "z": 11,
      "name": "Soil_Dirt_Burnt"
    },
    {
      "x": 16,
      "y": 20,
      "z": 11,
      "name": "Soil_Grass_Burnt"
    },
    {
      "x": 16,
      "y": 21,
      "z": 11,
      "name": "Plant_Flower_Bushy_Violet"
    },
    {
      "x": 16,
      "y": 28,
      "z": 11,
      "name": "Rock_Volcanic"
    },
    {
      "x": 16,
      "y": 29,
      "z": 11,
      "name": "Rock_Slate"
    },
    {
      "x": 16,
      "y": 18,
      "z": 12,
      "name": "Rock_Volcanic"
    },
    {
      "x": 16,
      "y": 19,
      "z": 12,
      "name": "Rock_Volcanic"
    },
    {
      "x": 16,
      "y": 20,
      "z": 12,
      "name": "Soil_Grass_Burnt"
    },
    {
      "x": 16,
      "y": 28,
      "z": 12,
      "name": "Rock_Volcanic"
    },
    {
      "x": 16,
      "y": 33,
      "z": 12,
      "name": "Rock_Slate"
    },
    {
      "x": 16,
      "y": 18,
      "z": 13,
      "name": "Rock_Volcanic"
    },
    {
      "x": 16,
      "y": 19,
      "z": 13,
      "name": "Soil_Dirt_Burnt"
    },
    {
      "x": 16,
      "y": 20,
      "z": 13,
      "name": "Soil_Grass_Burnt"
    },
    {
      "x": 16,
      "y": 28,
      "z": 13,
      "name": "Rock_Volcanic"
    },
    {
      "x": 16,
      "y": 33,
      "z": 13,
      "name": "Rock_Slate"
    },
    {
      "x": 16,
      "y": 19,
      "z": 14,
      "name": "Rock_Volcanic"
    },
    {
      "x": 16,
      "y": 20,
      "z": 14,
      "name": "Soil_Dirt_Burnt"
    },
    {
      "x": 16,
      "y": 28,
      "z": 14,
      "name": "Rock_Volcanic"
    },
    {
      "x": 16,
      "y": 33,
      "z": 14,
      "name": "Rock_Volcanic"
    },
    {
      "x": 16,
      "y": 19,
      "z": 15,
      "name": "Rock_Volcanic"
    },
    {
      "x": 16,
      "y": 32,
      "z": 15,
      "name": "Rock_Volcanic"
    },
    {
      "x": 16,
      "y": 33,
      "z": 15,
      "name": "Rock_Volcanic"
    },
    {
      "x": 16,
      "y": 19,
      "z": 16,
      "name": "Rock_Volcanic"
    },
    {
      "x": 16,
      "y": 26,
      "z": 16,
      "name": "Rock_Volcanic"
    },
    {
      "x": 16,
      "y": 27,
      "z": 16,
      "name": "Rock_Volcanic"
    },
    {
      "x": 16,
      "y": 32,
      "z": 16,
      "name": "Rock_Volcanic"
    },
    {
      "x": 16,
      "y": 33,
      "z": 16,
      "name": "Rock_Slate"
    },
    {
      "x": 16,
      "y": 26,
      "z": 17,
      "name": "Rock_Volcanic"
    },
    {
      "x": 16,
      "y": 27,
      "z": 17,
      "name": "Rock_Volcanic"
    },
    {
      "x": 16,
      "y": 28,
      "z": 17,
      "name": "Soil_Grass_Burnt"
    },
    {
      "x": 16,
      "y": 25,
      "z": 18,
      "name": "Rock_Volcanic"
    },
    {
      "x": 16,
      "y": 26,
      "z": 18,
      "name": "Rock_Volcanic"
    },
    {
      "x": 16,
      "y": 27,
      "z": 18,
      "name": "Soil_Dirt_Burnt"
    },
    {
      "x": 16,
      "y": 28,
      "z": 18,
      "name": "Soil_Grass_Burnt"
    },
    {
      "x": 16,
      "y": 26,
      "z": 19,
      "name": "Soil_Dirt_Burnt"
    },
    {
      "x": 16,
      "y": 27,
      "z": 19,
      "name": "Soil_Grass_Burnt"
    },
    {
      "x": 16,
      "y": 28,
      "z": 19,
      "name": "Plant_Flower_Bushy_Violet"
    },
    {
      "x": 16,
      "y": 33,
      "z": 19,
      "name": "Rock_Slate"
    },
    {
      "x": 16,
      "y": 26,
      "z": 20,
      "name": "Rock_Volcanic"
    },
    {
      "x": 16,
      "y": 27,
      "z": 20,
      "name": "Soil_Grass_Burnt"
    },
    {
      "x": 16,
      "y": 33,
      "z": 20,
      "name": "Rock_Volcanic"
    },
    {
      "x": 16,
      "y": 21,
      "z": 21,
      "name": "Rock_Volcanic"
    },
    {
      "x": 16,
      "y": 26,
      "z": 21,
      "name": "Rock_Volcanic"
    },
    {
      "x": 16,
      "y": 27,
      "z": 21,
      "name": "Rock_Volcanic"
    },
    {
      "x": 16,
      "y": 33,
      "z": 21,
      "name": "Rock_Volcanic"
    },
    {
      "x": 16,
      "y": 21,
      "z": 22,
      "name": "Rock_Volcanic"
    },
    {
      "x": 16,
      "y": 32,
      "z": 22,
      "name": "Rock_Volcanic"
    },
    {
      "x": 16,
      "y": 33,
      "z": 22,
      "name": "Rock_Volcanic"
    },
    {
      "x": 16,
      "y": 32,
      "z": 23,
      "name": "Rock_Volcanic"
    },
    {
      "x": 16,
      "y": 33,
      "z": 23,
      "name": "Rock_Volcanic"
    },
    {
      "x": 16,
      "y": 34,
      "z": 23,
      "name": "Rock_Volcanic"
    },
    {
      "x": 16,
      "y": 33,
      "z": 24,
      "name": "Rock_Volcanic"
    },
    {
      "x": 16,
      "y": 34,
      "z": 24,
      "name": "Rock_Volcanic_Cracked_Poisoned"
    },
    {
      "x": 16,
      "y": 33,
      "z": 25,
      "name": "Rock_Volcanic_Cracked_Poisoned"
    },
    {
      "x": 16,
      "y": 34,
      "z": 25,
      "name": "Rock_Volcanic_Cracked_Poisoned"
    },
    {
      "x": 17,
      "y": 20,
      "z": 7,
      "name": "Rock_Slate"
    },
    {
      "x": 17,
      "y": 21,
      "z": 7,
      "name": "Rock_Slate"
    },
    {
      "x": 17,
      "y": 29,
      "z": 7,
      "name": "Rock_Volcanic_Cracked_Poisoned"
    },
    {
      "x": 17,
      "y": 20,
      "z": 8,
      "name": "Rock_Volcanic"
    },
    {
      "x": 17,
      "y": 21,
      "z": 8,
      "name": "Rock_Slate"
    },
    {
      "x": 17,
      "y": 29,
      "z": 8,
      "name": "Rock_Slate"
    },
    {
      "x": 17,
      "y": 19,
      "z": 9,
      "name": "Rock_Volcanic"
    },
    {
      "x": 17,
      "y": 20,
      "z": 9,
      "name": "Soil_Dirt_Burnt"
    },
    {
      "x": 17,
      "y": 28,
      "z": 9,
      "name": "Rock_Volcanic"
    },
    {
      "x": 17,
      "y": 29,
      "z": 9,
      "name": "Rock_Slate"
    },
    {
      "x": 17,
      "y": 19,
      "z": 10,
      "name": "Soil_Dirt_Burnt"
    },
    {
      "x": 17,
      "y": 20,
      "z": 10,
      "name": "Soil_Grass_Burnt"
    },
    {
      "x": 17,
      "y": 28,
      "z": 10,
      "name": "Rock_Volcanic"
    },
    {
      "x": 17,
      "y": 29,
      "z": 10,
      "name": "Rock_Volcanic"
    },
    {
      "x": 17,
      "y": 18,
      "z": 11,
      "name": "Rock_Volcanic"
    },
    {
      "x": 17,
      "y": 19,
      "z": 11,
      "name": "Rock_Volcanic"
    },
    {
      "x": 17,
      "y": 20,
      "z": 11,
      "name": "Soil_Grass_Burnt"
    },
    {
      "x": 17,
      "y": 28,
      "z": 11,
      "name": "Rock_Volcanic"
    },
    {
      "x": 17,
      "y": 18,
      "z": 12,
      "name": "Rock_Volcanic"
    },
    {
      "x": 17,
      "y": 19,
      "z": 12,
      "name": "Soil_Dirt_Burnt"
    },
    {
      "x": 17,
      "y": 20,
      "z": 12,
      "name": "Soil_Grass_Burnt"
    },
    {
      "x": 17,
      "y": 21,
      "z": 12,
      "name": "Plant_Flower_Bushy_Violet"
    },
    {
      "x": 17,
      "y": 28,
      "z": 12,
      "name": "Rock_Volcanic"
    },
    {
      "x": 17,
      "y": 33,
      "z": 12,
      "name": "Rock_Slate"
    },
    {
      "x": 17,
      "y": 18,
      "z": 13,
      "name": "Rock_Volcanic"
    },
    {
      "x": 17,
      "y": 19,
      "z": 13,
      "name": "Rock_Volcanic"
    },
    {
      "x": 17,
      "y": 20,
      "z": 13,
      "name": "Soil_Grass_Burnt"
    },
    {
      "x": 17,
      "y": 28,
      "z": 13,
      "name": "Rock_Volcanic"
    },
    {
      "x": 17,
      "y": 32,
      "z": 13,
      "name": "Rock_Slate"
    },
    {
      "x": 17,
      "y": 33,
      "z": 13,
      "name": "Rock_Slate"
    },
    {
      "x": 17,
      "y": 18,
      "z": 14,
      "name": "Rock_Volcanic"
    },
    {
      "x": 17,
      "y": 19,
      "z": 14,
      "name": "Soil_Dirt_Burnt"
    },
    {
      "x": 17,
      "y": 20,
      "z": 14,
      "name": "Soil_Grass_Burnt"
    },
    {
      "x": 17,
      "y": 28,
      "z": 14,
      "name": "Rock_Volcanic"
    },
    {
      "x": 17,
      "y": 29,
      "z": 14,
      "name": "Rock_Volcanic"
    },
    {
      "x": 17,
      "y": 32,
      "z": 14,
      "name": "Rock_Volcanic"
    },
    {
      "x": 17,
      "y": 33,
      "z": 14,
      "name": "Rock_Slate"
    },
    {
      "x": 17,
      "y": 19,
      "z": 15,
      "name": "Rock_Volcanic"
    },
    {
      "x": 17,
      "y": 26,
      "z": 15,
      "name": "Rock_Volcanic"
    },
    {
      "x": 17,
      "y": 27,
      "z": 15,
      "name": "Rock_Volcanic"
    },
    {
      "x": 17,
      "y": 28,
      "z": 15,
      "name": "Rock_Volcanic"
    },
    {
      "x": 17,
      "y": 31,
      "z": 15,
      "name": "Rock_Volcanic"
    },
    {
      "x": 17,
      "y": 32,
      "z": 15,
      "name": "Rock_Volcanic"
    },
    {
      "x": 17,
      "y": 33,
      "z": 15,
      "name": "Rock_Volcanic"
    },
    {
      "x": 17,
      "y": 19,
      "z": 16,
      "name": "Rock_Volcanic"
    },
    {
      "x": 17,
      "y": 25,
      "z": 16,
      "name": "Rock_Volcanic"
    },
    {
      "x": 17,
      "y": 26,
      "z": 16,
      "name": "Rock_Volcanic"
    },
    {
      "x": 17,
      "y": 27,
      "z": 16,
      "name": "Rock_Volcanic"
    },
    {
      "x": 17,
      "y": 28,
      "z": 16,
      "name": "Rock_Volcanic"
    },
    {
      "x": 17,
      "y": 32,
      "z": 16,
      "name": "Rock_Volcanic"
    },
    {
      "x": 17,
      "y": 33,
      "z": 16,
      "name": "Rock_Volcanic"
    },
    {
      "x": 17,
      "y": 19,
      "z": 17,
      "name": "Rock_Volcanic"
    },
    {
      "x": 17,
      "y": 25,
      "z": 17,
      "name": "Rock_Volcanic"
    },
    {
      "x": 17,
      "y": 26,
      "z": 17,
      "name": "Rock_Volcanic"
    },
    {
      "x": 17,
      "y": 27,
      "z": 17,
      "name": "Rock_Volcanic"
    },
    {
      "x": 17,
      "y": 28,
      "z": 17,
      "name": "Rock_Volcanic"
    },
    {
      "x": 17,
      "y": 29,
      "z": 17,
      "name": "Plant_Flower_Bushy_Violet"
    },
    {
      "x": 17,
      "y": 32,
      "z": 17,
      "name": "Rock_Volcanic"
    },
    {
      "x": 17,
      "y": 33,
      "z": 17,
      "name": "Rock_Volcanic"
    },
    {
      "x": 17,
      "y": 19,
      "z": 18,
      "name": "Rock_Volcanic"
    },
    {
      "x": 17,
      "y": 25,
      "z": 18,
      "name": "Rock_Volcanic"
    },
    {
      "x": 17,
      "y": 26,
      "z": 18,
      "name": "Rock_Volcanic"
    },
    {
      "x": 17,
      "y": 27,
      "z": 18,
      "name": "Rock_Volcanic"
    },
    {
      "x": 17,
      "y": 28,
      "z": 18,
      "name": "Soil_Grass_Burnt"
    },
    {
      "x": 17,
      "y": 21,
      "z": 19,
      "name": "Rock_Volcanic"
    },
    {
      "x": 17,
      "y": 25,
      "z": 19,
      "name": "Rock_Volcanic"
    },
    {
      "x": 17,
      "y": 26,
      "z": 19,
      "name": "Rock_Volcanic"
    },
    {
      "x": 17,
      "y": 27,
      "z": 19,
      "name": "Soil_Grass_Burnt"
    },
    {
      "x": 17,
      "y": 33,
      "z": 19,
      "name": "Soil_Grass_Burnt"
    },
    {
      "x": 17,
      "y": 21,
      "z": 20,
      "name": "Rock_Volcanic"
    },
    {
      "x": 17,
      "y": 25,
      "z": 20,
      "name": "Rock_Volcanic"
    },
    {
      "x": 17,
      "y": 26,
      "z": 20,
      "name": "Rock_Volcanic"
    },
    {
      "x": 17,
      "y": 27,
      "z": 20,
      "name": "Rock_Volcanic"
    },
    {
      "x": 17,
      "y": 33,
      "z": 20,
      "name": "Soil_Dirt_Burnt"
    },
    {
      "x": 17,
      "y": 21,
      "z": 21,
      "name": "Rock_Volcanic"
    },
    {
      "x": 17,
      "y": 26,
      "z": 21,
      "name": "Rock_Volcanic"
    },
    {
      "x": 17,
      "y": 27,
      "z": 21,
      "name": "Rock_Volcanic"
    },
    {
      "x": 17,
      "y": 32,
      "z": 21,
      "name": "Rock_Volcanic"
    },
    {
      "x": 17,
      "y": 33,
      "z": 21,
      "name": "Rock_Volcanic"
    },
    {
      "x": 17,
      "y": 21,
      "z": 22,
      "name": "Rock_Volcanic"
    },
    {
      "x": 17,
      "y": 32,
      "z": 22,
      "name": "Rock_Volcanic"
    },
    {
      "x": 17,
      "y": 33,
      "z": 22,
      "name": "Rock_Volcanic"
    },
    {
      "x": 17,
      "y": 21,
      "z": 23,
      "name": "Rock_Volcanic"
    },
    {
      "x": 17,
      "y": 22,
      "z": 23,
      "name": "Rock_Slate"
    },
    {
      "x": 17,
      "y": 32,
      "z": 23,
      "name": "Rock_Volcanic"
    },
    {
      "x": 17,
      "y": 33,
      "z": 23,
      "name": "Rock_Slate"
    },
    {
      "x": 17,
      "y": 21,
      "z": 24,
      "name": "Rock_Slate"
    },
    {
      "x": 17,
      "y": 22,
      "z": 24,
      "name": "Rock_Slate"
    },
    {
      "x": 17,
      "y": 33,
      "z": 24,
      "name": "Rock_Slate"
    },
    {
      "x": 17,
      "y": 34,
      "z": 24,
      "name": "Rock_Slate"
    },
    {
      "x": 18,
      "y": 20,
      "z": 7,
      "name": "Rock_Slate"
    },
    {
      "x": 18,
      "y": 29,
      "z": 7,
      "name": "Rock_Slate"
    },
    {
      "x": 18,
      "y": 20,
      "z": 8,
      "name": "Rock_Slate"
    },
    {
      "x": 18,
      "y": 29,
      "z": 8,
      "name": "Rock_Slate"
    },
    {
      "x": 18,
      "y": 19,
      "z": 9,
      "name": "Rock_Volcanic"
    },
    {
      "x": 18,
      "y": 20,
      "z": 9,
      "name": "Soil_Grass_Burnt"
    },
    {
      "x": 18,
      "y": 28,
      "z": 9,
      "name": "Rock_Volcanic"
    },
    {
      "x": 18,
      "y": 29,
      "z": 9,
      "name": "Rock_Slate"
    },
    {
      "x": 18,
      "y": 19,
      "z": 10,
      "name": "Rock_Volcanic"
    },
    {
      "x": 18,
      "y": 20,
      "z": 10,
      "name": "Soil_Grass_Burnt"
    },
    {
      "x": 18,
      "y": 21,
      "z": 10,
      "name": "Plant_Flower_Bushy_Violet"
    },
    {
      "x": 18,
      "y": 28,
      "z": 10,
      "name": "Rock_Volcanic"
    },
    {
      "x": 18,
      "y": 29,
      "z": 10,
      "name": "Rock_Volcanic"
    },
    {
      "x": 18,
      "y": 18,
      "z": 11,
      "name": "Rock_Volcanic"
    },
    {
      "x": 18,
      "y": 19,
      "z": 11,
      "name": "Soil_Dirt_Burnt"
    },
    {
      "x": 18,
      "y": 20,
      "z": 11,
      "name": "Soil_Grass_Burnt"
    },
    {
      "x": 18,
      "y": 28,
      "z": 11,
      "name": "Rock_Volcanic"
    },
    {
      "x": 18,
      "y": 18,
      "z": 12,
      "name": "Rock_Volcanic"
    },
    {
      "x": 18,
      "y": 19,
      "z": 12,
      "name": "Rock_Volcanic"
    },
    {
      "x": 18,
      "y": 20,
      "z": 12,
      "name": "Soil_Grass_Burnt"
    },
    {
      "x": 18,
      "y": 21,
      "z": 12,
      "name": "Plant_Flower_Bushy_Violet"
    },
    {
      "x": 18,
      "y": 27,
      "z": 12,
      "name": "Rock_Volcanic"
    },
    {
      "x": 18,
      "y": 28,
      "z": 12,
      "name": "Rock_Volcanic"
    },
    {
      "x": 18,
      "y": 18,
      "z": 13,
      "name": "Rock_Volcanic"
    },
    {
      "x": 18,
      "y": 19,
      "z": 13,
      "name": "Soil_Dirt_Burnt"
    },
    {
      "x": 18,
      "y": 20,
      "z": 13,
      "name": "Soil_Grass_Burnt"
    },
    {
      "x": 18,
      "y": 27,
      "z": 13,
      "name": "Rock_Volcanic"
    },
    {
      "x": 18,
      "y": 28,
      "z": 13,
      "name": "Rock_Volcanic"
    },
    {
      "x": 18,
      "y": 32,
      "z": 13,
      "name": "Rock_Slate"
    },
    {
      "x": 18,
      "y": 33,
      "z": 13,
      "name": "Rock_Slate"
    },
    {
      "x": 18,
      "y": 18,
      "z": 14,
      "name": "Rock_Volcanic"
    },
    {
      "x": 18,
      "y": 19,
      "z": 14,
      "name": "Soil_Dirt_Burnt"
    },
    {
      "x": 18,
      "y": 20,
      "z": 14,
      "name": "Soil_Grass_Burnt"
    },
    {
      "x": 18,
      "y": 25,
      "z": 14,
      "name": "Rock_Volcanic"
    },
    {
      "x": 18,
      "y": 26,
      "z": 14,
      "name": "Rock_Volcanic"
    },
    {
      "x": 18,
      "y": 27,
      "z": 14,
      "name": "Rock_Volcanic"
    },
    {
      "x": 18,
      "y": 28,
      "z": 14,
      "name": "Rock_Volcanic"
    },
    {
      "x": 18,
      "y": 29,
      "z": 14,
      "name": "Rock_Volcanic"
    },
    {
      "x": 18,
      "y": 30,
      "z": 14,
      "name": "Rock_Volcanic"
    },
    {
      "x": 18,
      "y": 31,
      "z": 14,
      "name": "Rock_Volcanic"
    },
    {
      "x": 18,
      "y": 32,
      "z": 14,
      "name": "Rock_Volcanic"
    },
    {
      "x": 18,
      "y": 33,
      "z": 14,
      "name": "Rock_Slate"
    },
    {
      "x": 18,
      "y": 19,
      "z": 15,
      "name": "Rock_Volcanic"
    },
    {
      "x": 18,
      "y": 20,
      "z": 15,
      "name": "Soil_Dirt_Burnt"
    },
    {
      "x": 18,
      "y": 25,
      "z": 15,
      "name": "Rock_Volcanic"
    },
    {
      "x": 18,
      "y": 26,
      "z": 15,
      "name": "Rock_Volcanic"
    },
    {
      "x": 18,
      "y": 27,
      "z": 15,
      "name": "Rock_Volcanic"
    },
    {
      "x": 18,
      "y": 28,
      "z": 15,
      "name": "Rock_Volcanic"
    },
    {
      "x": 18,
      "y": 29,
      "z": 15,
      "name": "Rock_Volcanic"
    },
    {
      "x": 18,
      "y": 30,
      "z": 15,
      "name": "Rock_Volcanic"
    },
    {
      "x": 18,
      "y": 31,
      "z": 15,
      "name": "Rock_Volcanic"
    },
    {
      "x": 18,
      "y": 32,
      "z": 15,
      "name": "Rock_Volcanic"
    },
    {
      "x": 18,
      "y": 33,
      "z": 15,
      "name": "Rock_Volcanic"
    },
    {
      "x": 18,
      "y": 19,
      "z": 16,
      "name": "Rock_Volcanic"
    },
    {
      "x": 18,
      "y": 25,
      "z": 16,
      "name": "Rock_Volcanic"
    },
    {
      "x": 18,
      "y": 26,
      "z": 16,
      "name": "Rock_Volcanic"
    },
    {
      "x": 18,
      "y": 27,
      "z": 16,
      "name": "Rock_Volcanic"
    },
    {
      "x": 18,
      "y": 28,
      "z": 16,
      "name": "Rock_Volcanic"
    },
    {
      "x": 18,
      "y": 29,
      "z": 16,
      "name": "Rock_Volcanic"
    },
    {
      "x": 18,
      "y": 30,
      "z": 16,
      "name": "Rock_Volcanic"
    },
    {
      "x": 18,
      "y": 31,
      "z": 16,
      "name": "Rock_Volcanic"
    },
    {
      "x": 18,
      "y": 32,
      "z": 16,
      "name": "Rock_Volcanic"
    },
    {
      "x": 18,
      "y": 33,
      "z": 16,
      "name": "Rock_Volcanic"
    },
    {
      "x": 18,
      "y": 19,
      "z": 17,
      "name": "Rock_Volcanic"
    },
    {
      "x": 18,
      "y": 21,
      "z": 17,
      "name": "Rock_Volcanic"
    },
    {
      "x": 18,
      "y": 22,
      "z": 17,
      "name": "Rock_Volcanic"
    },
    {
      "x": 18,
      "y": 23,
      "z": 17,
      "name": "Rock_Volcanic"
    },
    {
      "x": 18,
      "y": 24,
      "z": 17,
      "name": "Rock_Volcanic"
    },
    {
      "x": 18,
      "y": 25,
      "z": 17,
      "name": "Rock_Volcanic"
    },
    {
      "x": 18,
      "y": 26,
      "z": 17,
      "name": "Rock_Volcanic"
    },
    {
      "x": 18,
      "y": 27,
      "z": 17,
      "name": "Rock_Volcanic"
    },
    {
      "x": 18,
      "y": 28,
      "z": 17,
      "name": "Rock_Volcanic"
    },
    {
      "x": 18,
      "y": 29,
      "z": 17,
      "name": "Rock_Volcanic"
    },
    {
      "x": 18,
      "y": 30,
      "z": 17,
      "name": "Rock_Volcanic"
    },
    {
      "x": 18,
      "y": 31,
      "z": 17,
      "name": "Rock_Volcanic"
    },
    {
      "x": 18,
      "y": 32,
      "z": 17,
      "name": "Rock_Volcanic"
    },
    {
      "x": 18,
      "y": 33,
      "z": 17,
      "name": "Soil_Grass_Burnt"
    },
    {
      "x": 18,
      "y": 19,
      "z": 18,
      "name": "Rock_Volcanic"
    },
    {
      "x": 18,
      "y": 20,
      "z": 18,
      "name": "Rock_Volcanic"
    },
    {
      "x": 18,
      "y": 21,
      "z": 18,
      "name": "Rock_Volcanic"
    },
    {
      "x": 18,
      "y": 23,
      "z": 18,
      "name": "Rock_Volcanic"
    },
    {
      "x": 18,
      "y": 24,
      "z": 18,
      "name": "Rock_Volcanic"
    },
    {
      "x": 18,
      "y": 25,
      "z": 18,
      "name": "Rock_Volcanic"
    },
    {
      "x": 18,
      "y": 26,
      "z": 18,
      "name": "Rock_Volcanic"
    },
    {
      "x": 18,
      "y": 27,
      "z": 18,
      "name": "Rock_Volcanic"
    },
    {
      "x": 18,
      "y": 28,
      "z": 18,
      "name": "Rock_Volcanic"
    },
    {
      "x": 18,
      "y": 29,
      "z": 18,
      "name": "Rock_Volcanic"
    },
    {
      "x": 18,
      "y": 30,
      "z": 18,
      "name": "Rock_Volcanic"
    },
    {
      "x": 18,
      "y": 31,
      "z": 18,
      "name": "Rock_Volcanic"
    },
    {
      "x": 18,
      "y": 32,
      "z": 18,
      "name": "Rock_Volcanic"
    },
    {
      "x": 18,
      "y": 33,
      "z": 18,
      "name": "Soil_Grass_Burnt"
    },
    {
      "x": 18,
      "y": 19,
      "z": 19,
      "name": "Rock_Volcanic"
    },
    {
      "x": 18,
      "y": 20,
      "z": 19,
      "name": "Rock_Volcanic"
    },
    {
      "x": 18,
      "y": 21,
      "z": 19,
      "name": "Rock_Volcanic"
    },
    {
      "x": 18,
      "y": 25,
      "z": 19,
      "name": "Rock_Volcanic"
    },
    {
      "x": 18,
      "y": 26,
      "z": 19,
      "name": "Rock_Volcanic"
    },
    {
      "x": 18,
      "y": 27,
      "z": 19,
      "name": "Rock_Volcanic"
    },
    {
      "x": 18,
      "y": 32,
      "z": 19,
      "name": "Soil_Dirt_Burnt"
    },
    {
      "x": 18,
      "y": 33,
      "z": 19,
      "name": "Soil_Grass_Burnt"
    },
    {
      "x": 18,
      "y": 21,
      "z": 20,
      "name": "Soil_Grass_Burnt"
    },
    {
      "x": 18,
      "y": 25,
      "z": 20,
      "name": "Rock_Volcanic"
    },
    {
      "x": 18,
      "y": 26,
      "z": 20,
      "name": "Rock_Volcanic"
    },
    {
      "x": 18,
      "y": 27,
      "z": 20,
      "name": "Rock_Volcanic"
    },
    {
      "x": 18,
      "y": 33,
      "z": 20,
      "name": "Soil_Grass_Burnt"
    },
    {
      "x": 18,
      "y": 21,
      "z": 21,
      "name": "Rock_Volcanic"
    },
    {
      "x": 18,
      "y": 32,
      "z": 21,
      "name": "Rock_Volcanic"
    },
    {
      "x": 18,
      "y": 33,
      "z": 21,
      "name": "Soil_Dirt_Burnt"
    },
    {
      "x": 18,
      "y": 21,
      "z": 22,
      "name": "Rock_Volcanic"
    },
    {
      "x": 18,
      "y": 32,
      "z": 22,
      "name": "Rock_Volcanic"
    },
    {
      "x": 18,
      "y": 33,
      "z": 22,
      "name": "Rock_Slate"
    },
    {
      "x": 18,
      "y": 21,
      "z": 23,
      "name": "Rock_Volcanic"
    },
    {
      "x": 18,
      "y": 22,
      "z": 23,
      "name": "Rock_Volcanic"
    },
    {
      "x": 18,
      "y": 33,
      "z": 23,
      "name": "Rock_Slate"
    },
    {
      "x": 18,
      "y": 21,
      "z": 24,
      "name": "Rock_Volcanic"
    },
    {
      "x": 18,
      "y": 22,
      "z": 24,
      "name": "Rock_Slate"
    },
    {
      "x": 18,
      "y": 33,
      "z": 24,
      "name": "Rock_Slate"
    },
    {
      "x": 18,
      "y": 22,
      "z": 25,
      "name": "Rock_Volcanic_Cracked_Poisoned"
    },
    {
      "x": 18,
      "y": 22,
      "z": 26,
      "name": "Rock_Volcanic_Cracked_Poisoned"
    },
    {
      "x": 19,
      "y": 29,
      "z": 8,
      "name": "Rock_Slate"
    },
    {
      "x": 19,
      "y": 19,
      "z": 9,
      "name": "Rock_Volcanic"
    },
    {
      "x": 19,
      "y": 20,
      "z": 9,
      "name": "Rock_Volcanic"
    },
    {
      "x": 19,
      "y": 29,
      "z": 9,
      "name": "Rock_Slate"
    },
    {
      "x": 19,
      "y": 19,
      "z": 10,
      "name": "Rock_Volcanic"
    },
    {
      "x": 19,
      "y": 20,
      "z": 10,
      "name": "Soil_Grass_Burnt"
    },
    {
      "x": 19,
      "y": 28,
      "z": 10,
      "name": "Rock_Volcanic"
    },
    {
      "x": 19,
      "y": 29,
      "z": 10,
      "name": "Rock_Volcanic"
    },
    {
      "x": 19,
      "y": 19,
      "z": 11,
      "name": "Rock_Volcanic"
    },
    {
      "x": 19,
      "y": 20,
      "z": 11,
      "name": "Soil_Grass_Burnt"
    },
    {
      "x": 19,
      "y": 28,
      "z": 11,
      "name": "Rock_Volcanic"
    },
    {
      "x": 19,
      "y": 18,
      "z": 12,
      "name": "Rock_Volcanic"
    },
    {
      "x": 19,
      "y": 19,
      "z": 12,
      "name": "Rock_Volcanic"
    },
    {
      "x": 19,
      "y": 20,
      "z": 12,
      "name": "Soil_Grass_Burnt"
    },
    {
      "x": 19,
      "y": 27,
      "z": 12,
      "name": "Rock_Volcanic"
    },
    {
      "x": 19,
      "y": 28,
      "z": 12,
      "name": "Rock_Volcanic"
    },
    {
      "x": 19,
      "y": 17,
      "z": 13,
      "name": "Rock_Volcanic"
    },
    {
      "x": 19,
      "y": 18,
      "z": 13,
      "name": "Rock_Volcanic"
    },
    {
      "x": 19,
      "y": 19,
      "z": 13,
      "name": "Rock_Volcanic"
    },
    {
      "x": 19,
      "y": 20,
      "z": 13,
      "name": "Soil_Grass_Burnt"
    },
    {
      "x": 19,
      "y": 27,
      "z": 13,
      "name": "Rock_Volcanic"
    },
    {
      "x": 19,
      "y": 28,
      "z": 13,
      "name": "Rock_Volcanic"
    },
    {
      "x": 19,
      "y": 29,
      "z": 13,
      "name": "Rock_Volcanic"
    },
    {
      "x": 19,
      "y": 30,
      "z": 13,
      "name": "Rock_Volcanic"
    },
    {
      "x": 19,
      "y": 14,
      "z": 14,
      "name": "Rock_Volcanic"
    },
    {
      "x": 19,
      "y": 15,
      "z": 14,
      "name": "Rock_Volcanic"
    },
    {
      "x": 19,
      "y": 16,
      "z": 14,
      "name": "Rock_Volcanic"
    },
    {
      "x": 19,
      "y": 17,
      "z": 14,
      "name": "Rock_Volcanic"
    },
    {
      "x": 19,
      "y": 18,
      "z": 14,
      "name": "Rock_Volcanic"
    },
    {
      "x": 19,
      "y": 19,
      "z": 14,
      "name": "Rock_Volcanic"
    },
    {
      "x": 19,
      "y": 20,
      "z": 14,
      "name": "Soil_Dirt_Burnt"
    },
    {
      "x": 19,
      "y": 25,
      "z": 14,
      "name": "Rock_Volcanic"
    },
    {
      "x": 19,
      "y": 26,
      "z": 14,
      "name": "Rock_Volcanic"
    },
    {
      "x": 19,
      "y": 27,
      "z": 14,
      "name": "Rock_Volcanic"
    },
    {
      "x": 19,
      "y": 28,
      "z": 14,
      "name": "Rock_Volcanic"
    },
    {
      "x": 19,
      "y": 29,
      "z": 14,
      "name": "Rock_Volcanic"
    },
    {
      "x": 19,
      "y": 30,
      "z": 14,
      "name": "Rock_Volcanic"
    },
    {
      "x": 19,
      "y": 31,
      "z": 14,
      "name": "Rock_Volcanic"
    },
    {
      "x": 19,
      "y": 32,
      "z": 14,
      "name": "Rock_Volcanic"
    },
    {
      "x": 19,
      "y": 11,
      "z": 15,
      "name": "Rock_Volcanic"
    },
    {
      "x": 19,
      "y": 12,
      "z": 15,
      "name": "Rock_Volcanic"
    },
    {
      "x": 19,
      "y": 13,
      "z": 15,
      "name": "Rock_Volcanic"
    },
    {
      "x": 19,
      "y": 14,
      "z": 15,
      "name": "Rock_Volcanic"
    },
    {
      "x": 19,
      "y": 15,
      "z": 15,
      "name": "Rock_Volcanic"
    },
    {
      "x": 19,
      "y": 16,
      "z": 15,
      "name": "Rock_Volcanic"
    },
    {
      "x": 19,
      "y": 17,
      "z": 15,
      "name": "Rock_Volcanic"
    },
    {
      "x": 19,
      "y": 18,
      "z": 15,
      "name": "Rock_Volcanic"
    },
    {
      "x": 19,
      "y": 19,
      "z": 15,
      "name": "Rock_Volcanic"
    },
    {
      "x": 19,
      "y": 20,
      "z": 15,
      "name": "Rock_Volcanic"
    },
    {
      "x": 19,
      "y": 21,
      "z": 15,
      "name": "Rock_Volcanic"
    },
    {
      "x": 19,
      "y": 22,
      "z": 15,
      "name": "Rock_Volcanic"
    },
    {
      "x": 19,
      "y": 25,
      "z": 15,
      "name": "Rock_Volcanic"
    },
    {
      "x": 19,
      "y": 26,
      "z": 15,
      "name": "Rock_Volcanic"
    },
    {
      "x": 19,
      "y": 27,
      "z": 15,
      "name": "Rock_Volcanic"
    },
    {
      "x": 19,
      "y": 28,
      "z": 15,
      "name": "Rock_Volcanic"
    },
    {
      "x": 19,
      "y": 29,
      "z": 15,
      "name": "Rock_Volcanic"
    },
    {
      "x": 19,
      "y": 30,
      "z": 15,
      "name": "Rock_Volcanic"
    },
    {
      "x": 19,
      "y": 31,
      "z": 15,
      "name": "Rock_Volcanic"
    },
    {
      "x": 19,
      "y": 32,
      "z": 15,
      "name": "Rock_Volcanic"
    },
    {
      "x": 19,
      "y": 33,
      "z": 15,
      "name": "Rock_Volcanic"
    },
    {
      "x": 19,
      "y": 11,
      "z": 16,
      "name": "Rock_Volcanic"
    },
    {
      "x": 19,
      "y": 12,
      "z": 16,
      "name": "Rock_Volcanic"
    },
    {
      "x": 19,
      "y": 13,
      "z": 16,
      "name": "Rock_Volcanic"
    },
    {
      "x": 19,
      "y": 14,
      "z": 16,
      "name": "Rock_Volcanic"
    },
    {
      "x": 19,
      "y": 15,
      "z": 16,
      "name": "Rock_Volcanic"
    },
    {
      "x": 19,
      "y": 16,
      "z": 16,
      "name": "Rock_Volcanic"
    },
    {
      "x": 19,
      "y": 17,
      "z": 16,
      "name": "Rock_Volcanic"
    },
    {
      "x": 19,
      "y": 18,
      "z": 16,
      "name": "Rock_Volcanic"
    },
    {
      "x": 19,
      "y": 19,
      "z": 16,
      "name": "Rock_Volcanic"
    },
    {
      "x": 19,
      "y": 20,
      "z": 16,
      "name": "Rock_Volcanic"
    },
    {
      "x": 19,
      "y": 21,
      "z": 16,
      "name": "Rock_Volcanic"
    },
    {
      "x": 19,
      "y": 22,
      "z": 16,
      "name": "Rock_Volcanic"
    },
    {
      "x": 19,
      "y": 23,
      "z": 16,
      "name": "Rock_Volcanic"
    },
    {
      "x": 19,
      "y": 24,
      "z": 16,
      "name": "Rock_Volcanic"
    },
    {
      "x": 19,
      "y": 25,
      "z": 16,
      "name": "Rock_Volcanic"
    },
    {
      "x": 19,
      "y": 26,
      "z": 16,
      "name": "Rock_Volcanic"
    },
    {
      "x": 19,
      "y": 27,
      "z": 16,
      "name": "Rock_Volcanic"
    },
    {
      "x": 19,
      "y": 28,
      "z": 16,
      "name": "Rock_Volcanic"
    },
    {
      "x": 19,
      "y": 29,
      "z": 16,
      "name": "Rock_Volcanic"
    },
    {
      "x": 19,
      "y": 30,
      "z": 16,
      "name": "Rock_Volcanic"
    },
    {
      "x": 19,
      "y": 31,
      "z": 16,
      "name": "Rock_Volcanic"
    },
    {
      "x": 19,
      "y": 32,
      "z": 16,
      "name": "Rock_Volcanic"
    },
    {
      "x": 19,
      "y": 33,
      "z": 16,
      "name": "Soil_Grass_Burnt"
    },
    {
      "x": 19,
      "y": 34,
      "z": 16,
      "name": "Rock_Crystal_Purple_Large"
    },
    {
      "x": 19,
      "y": 11,
      "z": 17,
      "name": "Rock_Volcanic"
    },
    {
      "x": 19,
      "y": 12,
      "z": 17,
      "name": "Rock_Volcanic"
    },
    {
      "x": 19,
      "y": 13,
      "z": 17,
      "name": "Rock_Volcanic"
    },
    {
      "x": 19,
      "y": 14,
      "z": 17,
      "name": "Rock_Volcanic"
    },
    {
      "x": 19,
      "y": 15,
      "z": 17,
      "name": "Rock_Volcanic"
    },
    {
      "x": 19,
      "y": 16,
      "z": 17,
      "name": "Rock_Volcanic"
    },
    {
      "x": 19,
      "y": 17,
      "z": 17,
      "name": "Rock_Volcanic"
    },
    {
      "x": 19,
      "y": 18,
      "z": 17,
      "name": "Rock_Volcanic"
    },
    {
      "x": 19,
      "y": 19,
      "z": 17,
      "name": "Rock_Volcanic"
    },
    {
      "x": 19,
      "y": 20,
      "z": 17,
      "name": "Rock_Volcanic"
    },
    {
      "x": 19,
      "y": 21,
      "z": 17,
      "name": "Rock_Volcanic"
    },
    {
      "x": 19,
      "y": 22,
      "z": 17,
      "name": "Rock_Volcanic"
    },
    {
      "x": 19,
      "y": 23,
      "z": 17,
      "name": "Rock_Volcanic"
    },
    {
      "x": 19,
      "y": 24,
      "z": 17,
      "name": "Rock_Volcanic"
    },
    {
      "x": 19,
      "y": 25,
      "z": 17,
      "name": "Rock_Volcanic"
    },
    {
      "x": 19,
      "y": 26,
      "z": 17,
      "name": "Rock_Volcanic"
    },
    {
      "x": 19,
      "y": 27,
      "z": 17,
      "name": "Rock_Volcanic"
    },
    {
      "x": 19,
      "y": 28,
      "z": 17,
      "name": "Rock_Volcanic"
    },
    {
      "x": 19,
      "y": 29,
      "z": 17,
      "name": "Rock_Volcanic"
    },
    {
      "x": 19,
      "y": 30,
      "z": 17,
      "name": "Rock_Volcanic"
    },
    {
      "x": 19,
      "y": 31,
      "z": 17,
      "name": "Rock_Volcanic"
    },
    {
      "x": 19,
      "y": 32,
      "z": 17,
      "name": "Soil_Dirt_Burnt"
    },
    {
      "x": 19,
      "y": 33,
      "z": 17,
      "name": "Soil_Grass_Burnt"
    },
    {
      "x": 19,
      "y": 34,
      "z": 17,
      "name": "Plant_Flower_Bushy_Violet"
    },
    {
      "x": 19,
      "y": 11,
      "z": 18,
      "name": "Rock_Volcanic"
    },
    {
      "x": 19,
      "y": 12,
      "z": 18,
      "name": "Rock_Volcanic"
    },
    {
      "x": 19,
      "y": 13,
      "z": 18,
      "name": "Rock_Volcanic"
    },
    {
      "x": 19,
      "y": 14,
      "z": 18,
      "name": "Rock_Volcanic"
    },
    {
      "x": 19,
      "y": 15,
      "z": 18,
      "name": "Rock_Volcanic"
    },
    {
      "x": 19,
      "y": 16,
      "z": 18,
      "name": "Rock_Volcanic"
    },
    {
      "x": 19,
      "y": 17,
      "z": 18,
      "name": "Rock_Volcanic"
    },
    {
      "x": 19,
      "y": 18,
      "z": 18,
      "name": "Rock_Volcanic"
    },
    {
      "x": 19,
      "y": 19,
      "z": 18,
      "name": "Rock_Volcanic"
    },
    {
      "x": 19,
      "y": 20,
      "z": 18,
      "name": "Rock_Volcanic"
    },
    {
      "x": 19,
      "y": 21,
      "z": 18,
      "name": "Rock_Volcanic"
    },
    {
      "x": 19,
      "y": 22,
      "z": 18,
      "name": "Rock_Volcanic"
    },
    {
      "x": 19,
      "y": 23,
      "z": 18,
      "name": "Rock_Volcanic"
    },
    {
      "x": 19,
      "y": 24,
      "z": 18,
      "name": "Rock_Volcanic"
    },
    {
      "x": 19,
      "y": 25,
      "z": 18,
      "name": "Rock_Volcanic"
    },
    {
      "x": 19,
      "y": 26,
      "z": 18,
      "name": "Rock_Volcanic"
    },
    {
      "x": 19,
      "y": 27,
      "z": 18,
      "name": "Rock_Volcanic"
    },
    {
      "x": 19,
      "y": 28,
      "z": 18,
      "name": "Rock_Volcanic"
    },
    {
      "x": 19,
      "y": 29,
      "z": 18,
      "name": "Rock_Volcanic"
    },
    {
      "x": 19,
      "y": 30,
      "z": 18,
      "name": "Rock_Volcanic"
    },
    {
      "x": 19,
      "y": 31,
      "z": 18,
      "name": "Rock_Volcanic"
    },
    {
      "x": 19,
      "y": 32,
      "z": 18,
      "name": "Rock_Volcanic"
    },
    {
      "x": 19,
      "y": 33,
      "z": 18,
      "name": "Soil_Grass_Burnt"
    },
    {
      "x": 19,
      "y": 17,
      "z": 19,
      "name": "Rock_Volcanic"
    },
    {
      "x": 19,
      "y": 18,
      "z": 19,
      "name": "Rock_Volcanic"
    },
    {
      "x": 19,
      "y": 19,
      "z": 19,
      "name": "Rock_Volcanic"
    },
    {
      "x": 19,
      "y": 20,
      "z": 19,
      "name": "Rock_Volcanic"
    },
    {
      "x": 19,
      "y": 21,
      "z": 19,
      "name": "Soil_Dirt_Burnt"
    },
    {
      "x": 19,
      "y": 22,
      "z": 19,
      "name": "Rock_Volcanic"
    },
    {
      "x": 19,
      "y": 23,
      "z": 19,
      "name": "Rock_Volcanic"
    },
    {
      "x": 19,
      "y": 24,
      "z": 19,
      "name": "Rock_Volcanic"
    },
    {
      "x": 19,
      "y": 25,
      "z": 19,
      "name": "Rock_Volcanic"
    },
    {
      "x": 19,
      "y": 26,
      "z": 19,
      "name": "Rock_Volcanic"
    },
    {
      "x": 19,
      "y": 27,
      "z": 19,
      "name": "Rock_Volcanic"
    },
    {
      "x": 19,
      "y": 28,
      "z": 19,
      "name": "Rock_Volcanic"
    },
    {
      "x": 19,
      "y": 29,
      "z": 19,
      "name": "Rock_Volcanic"
    },
    {
      "x": 19,
      "y": 30,
      "z": 19,
      "name": "Rock_Volcanic"
    },
    {
      "x": 19,
      "y": 31,
      "z": 19,
      "name": "Rock_Volcanic"
    },
    {
      "x": 19,
      "y": 32,
      "z": 19,
      "name": "Soil_Dirt_Burnt"
    },
    {
      "x": 19,
      "y": 33,
      "z": 19,
      "name": "Soil_Grass_Burnt"
    },
    {
      "x": 19,
      "y": 18,
      "z": 20,
      "name": "Rock_Volcanic"
    },
    {
      "x": 19,
      "y": 19,
      "z": 20,
      "name": "Rock_Volcanic"
    },
    {
      "x": 19,
      "y": 20,
      "z": 20,
      "name": "Soil_Dirt_Burnt"
    },
    {
      "x": 19,
      "y": 21,
      "z": 20,
      "name": "Soil_Grass_Burnt"
    },
    {
      "x": 19,
      "y": 22,
      "z": 20,
      "name": "Plant_Flower_Bushy_Violet"
    },
    {
      "x": 19,
      "y": 25,
      "z": 20,
      "name": "Rock_Volcanic"
    },
    {
      "x": 19,
      "y": 26,
      "z": 20,
      "name": "Rock_Volcanic"
    },
    {
      "x": 19,
      "y": 27,
      "z": 20,
      "name": "Rock_Volcanic"
    },
    {
      "x": 19,
      "y": 32,
      "z": 20,
      "name": "Soil_Dirt_Burnt"
    },
    {
      "x": 19,
      "y": 33,
      "z": 20,
      "name": "Soil_Grass_Burnt"
    },
    {
      "x": 19,
      "y": 20,
      "z": 21,
      "name": "Rock_Volcanic"
    },
    {
      "x": 19,
      "y": 21,
      "z": 21,
      "name": "Soil_Grass_Burnt"
    },
    {
      "x": 19,
      "y": 25,
      "z": 21,
      "name": "Rock_Volcanic"
    },
    {
      "x": 19,
      "y": 26,
      "z": 21,
      "name": "Rock_Volcanic"
    },
    {
      "x": 19,
      "y": 32,
      "z": 21,
      "name": "Rock_Volcanic"
    },
    {
      "x": 19,
      "y": 33,
      "z": 21,
      "name": "Soil_Grass_Burnt"
    },
    {
      "x": 19,
      "y": 21,
      "z": 22,
      "name": "Rock_Volcanic"
    },
    {
      "x": 19,
      "y": 22,
      "z": 22,
      "name": "Soil_Grass_Burnt"
    },
    {
      "x": 19,
      "y": 33,
      "z": 22,
      "name": "Rock_Volcanic"
    },
    {
      "x": 19,
      "y": 21,
      "z": 23,
      "name": "Rock_Volcanic"
    },
    {
      "x": 19,
      "y": 22,
      "z": 23,
      "name": "Soil_Grass_Burnt"
    },
    {
      "x": 19,
      "y": 23,
      "z": 23,
      "name": "Rock_Crystal_Purple_Large"
    },
    {
      "x": 19,
      "y": 33,
      "z": 23,
      "name": "Rock_Slate"
    },
    {
      "x": 19,
      "y": 21,
      "z": 24,
      "name": "Rock_Volcanic"
    },
    {
      "x": 19,
      "y": 22,
      "z": 24,
      "name": "Rock_Slate"
    },
    {
      "x": 19,
      "y": 21,
      "z": 25,
      "name": "Rock_Slate"
    },
    {
      "x": 19,
      "y": 22,
      "z": 25,
      "name": "Rock_Slate"
    },
    {
      "x": 19,
      "y": 21,
      "z": 26,
      "name": "Rock_Slate"
    },
    {
      "x": 19,
      "y": 22,
      "z": 26,
      "name": "Rock_Volcanic_Cracked_Poisoned"
    },
    {
      "x": 20,
      "y": 20,
      "z": 9,
      "name": "Rock_Volcanic"
    },
    {
      "x": 20,
      "y": 19,
      "z": 10,
      "name": "Rock_Volcanic"
    },
    {
      "x": 20,
      "y": 20,
      "z": 10,
      "name": "Rock_Volcanic"
    },
    {
      "x": 20,
      "y": 28,
      "z": 10,
      "name": "Rock_Volcanic"
    },
    {
      "x": 20,
      "y": 19,
      "z": 11,
      "name": "Rock_Volcanic"
    },
    {
      "x": 20,
      "y": 20,
      "z": 11,
      "name": "Soil_Grass_Burnt"
    },
    {
      "x": 20,
      "y": 28,
      "z": 11,
      "name": "Rock_Volcanic"
    },
    {
      "x": 20,
      "y": 19,
      "z": 12,
      "name": "Soil_Dirt_Burnt"
    },
    {
      "x": 20,
      "y": 20,
      "z": 12,
      "name": "Soil_Grass_Burnt"
    },
    {
      "x": 20,
      "y": 21,
      "z": 12,
      "name": "Rock_Crystal_Purple_Large"
    },
    {
      "x": 20,
      "y": 28,
      "z": 12,
      "name": "Rock_Volcanic"
    },
    {
      "x": 20,
      "y": 17,
      "z": 13,
      "name": "Rock_Volcanic"
    },
    {
      "x": 20,
      "y": 18,
      "z": 13,
      "name": "Rock_Volcanic"
    },
    {
      "x": 20,
      "y": 19,
      "z": 13,
      "name": "Rock_Volcanic"
    },
    {
      "x": 20,
      "y": 20,
      "z": 13,
      "name": "Soil_Grass_Burnt"
    },
    {
      "x": 20,
      "y": 27,
      "z": 13,
      "name": "Rock_Volcanic"
    },
    {
      "x": 20,
      "y": 28,
      "z": 13,
      "name": "Rock_Volcanic"
    },
    {
      "x": 20,
      "y": 29,
      "z": 13,
      "name": "Rock_Volcanic"
    },
    {
      "x": 20,
      "y": 30,
      "z": 13,
      "name": "Rock_Volcanic"
    },
    {
      "x": 20,
      "y": 31,
      "z": 13,
      "name": "Rock_Volcanic"
    },
    {
      "x": 20,
      "y": 32,
      "z": 13,
      "name": "Rock_Volcanic"
    },
    {
      "x": 20,
      "y": 12,
      "z": 14,
      "name": "Rock_Volcanic"
    },
    {
      "x": 20,
      "y": 13,
      "z": 14,
      "name": "Rock_Volcanic"
    },
    {
      "x": 20,
      "y": 14,
      "z": 14,
      "name": "Rock_Volcanic"
    },
    {
      "x": 20,
      "y": 15,
      "z": 14,
      "name": "Rock_Volcanic"
    },
    {
      "x": 20,
      "y": 16,
      "z": 14,
      "name": "Rock_Volcanic"
    },
    {
      "x": 20,
      "y": 17,
      "z": 14,
      "name": "Rock_Volcanic"
    },
    {
      "x": 20,
      "y": 18,
      "z": 14,
      "name": "Rock_Volcanic"
    },
    {
      "x": 20,
      "y": 19,
      "z": 14,
      "name": "Rock_Volcanic"
    },
    {
      "x": 20,
      "y": 20,
      "z": 14,
      "name": "Rock_Volcanic"
    },
    {
      "x": 20,
      "y": 21,
      "z": 14,
      "name": "Rock_Volcanic"
    },
    {
      "x": 20,
      "y": 25,
      "z": 14,
      "name": "Rock_Volcanic"
    },
    {
      "x": 20,
      "y": 26,
      "z": 14,
      "name": "Rock_Volcanic"
    },
    {
      "x": 20,
      "y": 27,
      "z": 14,
      "name": "Rock_Volcanic"
    },
    {
      "x": 20,
      "y": 28,
      "z": 14,
      "name": "Rock_Volcanic"
    },
    {
      "x": 20,
      "y": 29,
      "z": 14,
      "name": "Rock_Volcanic"
    },
    {
      "x": 20,
      "y": 30,
      "z": 14,
      "name": "Rock_Volcanic"
    },
    {
      "x": 20,
      "y": 31,
      "z": 14,
      "name": "Rock_Volcanic"
    },
    {
      "x": 20,
      "y": 32,
      "z": 14,
      "name": "Rock_Volcanic"
    },
    {
      "x": 20,
      "y": 10,
      "z": 15,
      "name": "Rock_Volcanic"
    },
    {
      "x": 20,
      "y": 11,
      "z": 15,
      "name": "Rock_Volcanic"
    },
    {
      "x": 20,
      "y": 12,
      "z": 15,
      "name": "Rock_Volcanic"
    },
    {
      "x": 20,
      "y": 13,
      "z": 15,
      "name": "Rock_Volcanic"
    },
    {
      "x": 20,
      "y": 14,
      "z": 15,
      "name": "Rock_Volcanic"
    },
    {
      "x": 20,
      "y": 15,
      "z": 15,
      "name": "Rock_Volcanic"
    },
    {
      "x": 20,
      "y": 16,
      "z": 15,
      "name": "Rock_Volcanic"
    },
    {
      "x": 20,
      "y": 17,
      "z": 15,
      "name": "Rock_Volcanic"
    },
    {
      "x": 20,
      "y": 18,
      "z": 15,
      "name": "Rock_Volcanic"
    },
    {
      "x": 20,
      "y": 19,
      "z": 15,
      "name": "Rock_Volcanic"
    },
    {
      "x": 20,
      "y": 20,
      "z": 15,
      "name": "Rock_Volcanic"
    },
    {
      "x": 20,
      "y": 21,
      "z": 15,
      "name": "Rock_Volcanic"
    },
    {
      "x": 20,
      "y": 22,
      "z": 15,
      "name": "Rock_Volcanic"
    },
    {
      "x": 20,
      "y": 23,
      "z": 15,
      "name": "Rock_Volcanic"
    },
    {
      "x": 20,
      "y": 24,
      "z": 15,
      "name": "Rock_Volcanic"
    },
    {
      "x": 20,
      "y": 25,
      "z": 15,
      "name": "Rock_Volcanic"
    },
    {
      "x": 20,
      "y": 26,
      "z": 15,
      "name": "Rock_Volcanic"
    },
    {
      "x": 20,
      "y": 27,
      "z": 15,
      "name": "Rock_Volcanic"
    },
    {
      "x": 20,
      "y": 28,
      "z": 15,
      "name": "Rock_Volcanic"
    },
    {
      "x": 20,
      "y": 29,
      "z": 15,
      "name": "Rock_Volcanic"
    },
    {
      "x": 20,
      "y": 30,
      "z": 15,
      "name": "Rock_Volcanic"
    },
    {
      "x": 20,
      "y": 31,
      "z": 15,
      "name": "Rock_Volcanic"
    },
    {
      "x": 20,
      "y": 32,
      "z": 15,
      "name": "Rock_Volcanic"
    },
    {
      "x": 20,
      "y": 10,
      "z": 16,
      "name": "Rock_Volcanic"
    },
    {
      "x": 20,
      "y": 11,
      "z": 16,
      "name": "Rock_Volcanic"
    },
    {
      "x": 20,
      "y": 12,
      "z": 16,
      "name": "Rock_Volcanic"
    },
    {
      "x": 20,
      "y": 13,
      "z": 16,
      "name": "Rock_Volcanic"
    },
    {
      "x": 20,
      "y": 14,
      "z": 16,
      "name": "Rock_Volcanic"
    },
    {
      "x": 20,
      "y": 15,
      "z": 16,
      "name": "Rock_Volcanic"
    },
    {
      "x": 20,
      "y": 16,
      "z": 16,
      "name": "Rock_Volcanic"
    },
    {
      "x": 20,
      "y": 17,
      "z": 16,
      "name": "Rock_Volcanic"
    },
    {
      "x": 20,
      "y": 18,
      "z": 16,
      "name": "Rock_Volcanic"
    },
    {
      "x": 20,
      "y": 19,
      "z": 16,
      "name": "Rock_Volcanic"
    },
    {
      "x": 20,
      "y": 20,
      "z": 16,
      "name": "Rock_Volcanic"
    },
    {
      "x": 20,
      "y": 21,
      "z": 16,
      "name": "Rock_Volcanic"
    },
    {
      "x": 20,
      "y": 22,
      "z": 16,
      "name": "Rock_Volcanic"
    },
    {
      "x": 20,
      "y": 23,
      "z": 16,
      "name": "Rock_Volcanic"
    },
    {
      "x": 20,
      "y": 24,
      "z": 16,
      "name": "Rock_Volcanic"
    },
    {
      "x": 20,
      "y": 25,
      "z": 16,
      "name": "Rock_Volcanic"
    },
    {
      "x": 20,
      "y": 26,
      "z": 16,
      "name": "Rock_Volcanic"
    },
    {
      "x": 20,
      "y": 27,
      "z": 16,
      "name": "Rock_Volcanic"
    },
    {
      "x": 20,
      "y": 28,
      "z": 16,
      "name": "Rock_Volcanic"
    },
    {
      "x": 20,
      "y": 29,
      "z": 16,
      "name": "Rock_Volcanic"
    },
    {
      "x": 20,
      "y": 30,
      "z": 16,
      "name": "Rock_Volcanic"
    },
    {
      "x": 20,
      "y": 31,
      "z": 16,
      "name": "Rock_Volcanic"
    },
    {
      "x": 20,
      "y": 32,
      "z": 16,
      "name": "Rock_Volcanic"
    },
    {
      "x": 20,
      "y": 33,
      "z": 16,
      "name": "Soil_Grass_Burnt"
    },
    {
      "x": 20,
      "y": 10,
      "z": 17,
      "name": "Rock_Volcanic"
    },
    {
      "x": 20,
      "y": 11,
      "z": 17,
      "name": "Rock_Volcanic"
    },
    {
      "x": 20,
      "y": 12,
      "z": 17,
      "name": "Rock_Volcanic"
    },
    {
      "x": 20,
      "y": 13,
      "z": 17,
      "name": "Rock_Volcanic"
    },
    {
      "x": 20,
      "y": 14,
      "z": 17,
      "name": "Rock_Volcanic"
    },
    {
      "x": 20,
      "y": 15,
      "z": 17,
      "name": "Rock_Volcanic"
    },
    {
      "x": 20,
      "y": 16,
      "z": 17,
      "name": "Rock_Volcanic"
    },
    {
      "x": 20,
      "y": 17,
      "z": 17,
      "name": "Rock_Volcanic"
    },
    {
      "x": 20,
      "y": 18,
      "z": 17,
      "name": "Rock_Volcanic"
    },
    {
      "x": 20,
      "y": 19,
      "z": 17,
      "name": "Rock_Volcanic"
    },
    {
      "x": 20,
      "y": 20,
      "z": 17,
      "name": "Rock_Volcanic"
    },
    {
      "x": 20,
      "y": 21,
      "z": 17,
      "name": "Rock_Volcanic"
    },
    {
      "x": 20,
      "y": 22,
      "z": 17,
      "name": "Rock_Volcanic"
    },
    {
      "x": 20,
      "y": 23,
      "z": 17,
      "name": "Rock_Volcanic"
    },
    {
      "x": 20,
      "y": 24,
      "z": 17,
      "name": "Rock_Volcanic"
    },
    {
      "x": 20,
      "y": 25,
      "z": 17,
      "name": "Rock_Volcanic"
    },
    {
      "x": 20,
      "y": 26,
      "z": 17,
      "name": "Rock_Volcanic"
    },
    {
      "x": 20,
      "y": 27,
      "z": 17,
      "name": "Rock_Volcanic"
    },
    {
      "x": 20,
      "y": 28,
      "z": 17,
      "name": "Rock_Volcanic"
    },
    {
      "x": 20,
      "y": 29,
      "z": 17,
      "name": "Rock_Volcanic"
    },
    {
      "x": 20,
      "y": 30,
      "z": 17,
      "name": "Rock_Volcanic"
    },
    {
      "x": 20,
      "y": 31,
      "z": 17,
      "name": "Rock_Volcanic"
    },
    {
      "x": 20,
      "y": 32,
      "z": 17,
      "name": "Soil_Dirt_Burnt"
    },
    {
      "x": 20,
      "y": 33,
      "z": 17,
      "name": "Soil_Grass_Burnt"
    },
    {
      "x": 20,
      "y": 34,
      "z": 17,
      "name": "Plant_Flower_Bushy_Violet"
    },
    {
      "x": 20,
      "y": 10,
      "z": 18,
      "name": "Rock_Volcanic"
    },
    {
      "x": 20,
      "y": 11,
      "z": 18,
      "name": "Rock_Volcanic"
    },
    {
      "x": 20,
      "y": 12,
      "z": 18,
      "name": "Rock_Volcanic"
    },
    {
      "x": 20,
      "y": 13,
      "z": 18,
      "name": "Rock_Volcanic"
    },
    {
      "x": 20,
      "y": 14,
      "z": 18,
      "name": "Rock_Volcanic"
    },
    {
      "x": 20,
      "y": 15,
      "z": 18,
      "name": "Rock_Volcanic"
    },
    {
      "x": 20,
      "y": 16,
      "z": 18,
      "name": "Rock_Volcanic"
    },
    {
      "x": 20,
      "y": 17,
      "z": 18,
      "name": "Rock_Volcanic"
    },
    {
      "x": 20,
      "y": 18,
      "z": 18,
      "name": "Rock_Volcanic"
    },
    {
      "x": 20,
      "y": 19,
      "z": 18,
      "name": "Rock_Volcanic"
    },
    {
      "x": 20,
      "y": 20,
      "z": 18,
      "name": "Rock_Volcanic"
    },
    {
      "x": 20,
      "y": 21,
      "z": 18,
      "name": "Rock_Volcanic"
    },
    {
      "x": 20,
      "y": 22,
      "z": 18,
      "name": "Rock_Volcanic"
    },
    {
      "x": 20,
      "y": 23,
      "z": 18,
      "name": "Rock_Volcanic"
    },
    {
      "x": 20,
      "y": 24,
      "z": 18,
      "name": "Rock_Volcanic"
    },
    {
      "x": 20,
      "y": 25,
      "z": 18,
      "name": "Rock_Volcanic"
    },
    {
      "x": 20,
      "y": 26,
      "z": 18,
      "name": "Rock_Volcanic"
    },
    {
      "x": 20,
      "y": 27,
      "z": 18,
      "name": "Rock_Volcanic"
    },
    {
      "x": 20,
      "y": 28,
      "z": 18,
      "name": "Rock_Volcanic"
    },
    {
      "x": 20,
      "y": 29,
      "z": 18,
      "name": "Rock_Volcanic"
    },
    {
      "x": 20,
      "y": 30,
      "z": 18,
      "name": "Rock_Volcanic"
    },
    {
      "x": 20,
      "y": 31,
      "z": 18,
      "name": "Rock_Volcanic"
    },
    {
      "x": 20,
      "y": 32,
      "z": 18,
      "name": "Rock_Volcanic"
    },
    {
      "x": 20,
      "y": 33,
      "z": 18,
      "name": "Soil_Grass_Burnt"
    },
    {
      "x": 20,
      "y": 34,
      "z": 18,
      "name": "Plant_Flower_Bushy_Violet"
    },
    {
      "x": 20,
      "y": 13,
      "z": 19,
      "name": "Rock_Volcanic"
    },
    {
      "x": 20,
      "y": 14,
      "z": 19,
      "name": "Rock_Volcanic"
    },
    {
      "x": 20,
      "y": 15,
      "z": 19,
      "name": "Rock_Volcanic"
    },
    {
      "x": 20,
      "y": 16,
      "z": 19,
      "name": "Rock_Volcanic"
    },
    {
      "x": 20,
      "y": 17,
      "z": 19,
      "name": "Rock_Volcanic"
    },
    {
      "x": 20,
      "y": 18,
      "z": 19,
      "name": "Rock_Volcanic"
    },
    {
      "x": 20,
      "y": 19,
      "z": 19,
      "name": "Rock_Volcanic"
    },
    {
      "x": 20,
      "y": 20,
      "z": 19,
      "name": "Rock_Volcanic"
    },
    {
      "x": 20,
      "y": 21,
      "z": 19,
      "name": "Rock_Volcanic"
    },
    {
      "x": 20,
      "y": 22,
      "z": 19,
      "name": "Rock_Volcanic"
    },
    {
      "x": 20,
      "y": 23,
      "z": 19,
      "name": "Rock_Volcanic"
    },
    {
      "x": 20,
      "y": 24,
      "z": 19,
      "name": "Rock_Volcanic"
    },
    {
      "x": 20,
      "y": 25,
      "z": 19,
      "name": "Rock_Volcanic"
    },
    {
      "x": 20,
      "y": 26,
      "z": 19,
      "name": "Rock_Volcanic"
    },
    {
      "x": 20,
      "y": 27,
      "z": 19,
      "name": "Rock_Volcanic"
    },
    {
      "x": 20,
      "y": 28,
      "z": 19,
      "name": "Rock_Volcanic"
    },
    {
      "x": 20,
      "y": 29,
      "z": 19,
      "name": "Rock_Volcanic"
    },
    {
      "x": 20,
      "y": 30,
      "z": 19,
      "name": "Rock_Volcanic"
    },
    {
      "x": 20,
      "y": 31,
      "z": 19,
      "name": "Rock_Volcanic"
    },
    {
      "x": 20,
      "y": 32,
      "z": 19,
      "name": "Soil_Dirt_Burnt"
    },
    {
      "x": 20,
      "y": 33,
      "z": 19,
      "name": "Soil_Grass_Burnt"
    },
    {
      "x": 20,
      "y": 20,
      "z": 20,
      "name": "Rock_Volcanic"
    },
    {
      "x": 20,
      "y": 21,
      "z": 20,
      "name": "Soil_Grass_Burnt"
    },
    {
      "x": 20,
      "y": 25,
      "z": 20,
      "name": "Rock_Volcanic"
    },
    {
      "x": 20,
      "y": 26,
      "z": 20,
      "name": "Rock_Volcanic"
    },
    {
      "x": 20,
      "y": 27,
      "z": 20,
      "name": "Rock_Volcanic"
    },
    {
      "x": 20,
      "y": 31,
      "z": 20,
      "name": "Rock_Volcanic"
    },
    {
      "x": 20,
      "y": 32,
      "z": 20,
      "name": "Rock_Volcanic"
    },
    {
      "x": 20,
      "y": 33,
      "z": 20,
      "name": "Soil_Grass_Burnt"
    },
    {
      "x": 20,
      "y": 20,
      "z": 21,
      "name": "Soil_Dirt_Burnt"
    },
    {
      "x": 20,
      "y": 21,
      "z": 21,
      "name": "Soil_Grass_Burnt"
    },
    {
      "x": 20,
      "y": 27,
      "z": 21,
      "name": "Rock_Volcanic"
    },
    {
      "x": 20,
      "y": 31,
      "z": 21,
      "name": "Rock_Volcanic"
    },
    {
      "x": 20,
      "y": 32,
      "z": 21,
      "name": "Rock_Volcanic"
    },
    {
      "x": 20,
      "y": 33,
      "z": 21,
      "name": "Rock_Volcanic"
    },
    {
      "x": 20,
      "y": 21,
      "z": 22,
      "name": "Soil_Dirt_Burnt"
    },
    {
      "x": 20,
      "y": 22,
      "z": 22,
      "name": "Soil_Grass_Burnt"
    },
    {
      "x": 20,
      "y": 23,
      "z": 22,
      "name": "Plant_Flower_Bushy_Violet"
    },
    {
      "x": 20,
      "y": 33,
      "z": 22,
      "name": "Rock_Volcanic"
    },
    {
      "x": 20,
      "y": 21,
      "z": 23,
      "name": "Soil_Dirt_Burnt"
    },
    {
      "x": 20,
      "y": 22,
      "z": 23,
      "name": "Soil_Grass_Burnt"
    },
    {
      "x": 20,
      "y": 33,
      "z": 23,
      "name": "Rock_Volcanic"
    },
    {
      "x": 20,
      "y": 21,
      "z": 24,
      "name": "Rock_Volcanic"
    },
    {
      "x": 20,
      "y": 22,
      "z": 24,
      "name": "Soil_Grass_Burnt"
    },
    {
      "x": 20,
      "y": 21,
      "z": 25,
      "name": "Rock_Volcanic"
    },
    {
      "x": 20,
      "y": 22,
      "z": 25,
      "name": "Rock_Slate"
    },
    {
      "x": 20,
      "y": 21,
      "z": 26,
      "name": "Rock_Slate"
    },
    {
      "x": 20,
      "y": 22,
      "z": 26,
      "name": "Rock_Slate"
    },
    {
      "x": 20,
      "y": 22,
      "z": 27,
      "name": "Rock_Slate"
    },
    {
      "x": 20,
      "y": 22,
      "z": 28,
      "name": "Rock_Volcanic_Cracked_Poisoned"
    },
    {
      "x": 20,
      "y": 23,
      "z": 28,
      "name": "Rock_Volcanic_Cracked_Poisoned"
    },
    {
      "x": 20,
      "y": 23,
      "z": 29,
      "name": "Rock_Volcanic_Cracked_Poisoned"
    },
    {
      "x": 21,
      "y": 33,
      "z": 8,
      "name": "Rock_Slate"
    },
    {
      "x": 21,
      "y": 33,
      "z": 9,
      "name": "Rock_Slate"
    },
    {
      "x": 21,
      "y": 20,
      "z": 10,
      "name": "Rock_Volcanic"
    },
    {
      "x": 21,
      "y": 32,
      "z": 10,
      "name": "Rock_Volcanic"
    },
    {
      "x": 21,
      "y": 33,
      "z": 10,
      "name": "Rock_Slate"
    },
    {
      "x": 21,
      "y": 20,
      "z": 11,
      "name": "Rock_Volcanic"
    },
    {
      "x": 21,
      "y": 31,
      "z": 11,
      "name": "Rock_Volcanic"
    },
    {
      "x": 21,
      "y": 32,
      "z": 11,
      "name": "Rock_Volcanic"
    },
    {
      "x": 21,
      "y": 19,
      "z": 12,
      "name": "Rock_Volcanic"
    },
    {
      "x": 21,
      "y": 20,
      "z": 12,
      "name": "Soil_Grass_Burnt"
    },
    {
      "x": 21,
      "y": 28,
      "z": 12,
      "name": "Rock_Volcanic"
    },
    {
      "x": 21,
      "y": 31,
      "z": 12,
      "name": "Rock_Volcanic"
    },
    {
      "x": 21,
      "y": 32,
      "z": 12,
      "name": "Rock_Volcanic"
    },
    {
      "x": 21,
      "y": 20,
      "z": 13,
      "name": "Rock_Volcanic"
    },
    {
      "x": 21,
      "y": 28,
      "z": 13,
      "name": "Rock_Volcanic"
    },
    {
      "x": 21,
      "y": 29,
      "z": 13,
      "name": "Rock_Volcanic"
    },
    {
      "x": 21,
      "y": 30,
      "z": 13,
      "name": "Rock_Volcanic"
    },
    {
      "x": 21,
      "y": 31,
      "z": 13,
      "name": "Rock_Volcanic"
    },
    {
      "x": 21,
      "y": 32,
      "z": 13,
      "name": "Rock_Volcanic"
    },
    {
      "x": 21,
      "y": 11,
      "z": 14,
      "name": "Rock_Volcanic"
    },
    {
      "x": 21,
      "y": 12,
      "z": 14,
      "name": "Rock_Volcanic"
    },
    {
      "x": 21,
      "y": 13,
      "z": 14,
      "name": "Rock_Volcanic"
    },
    {
      "x": 21,
      "y": 14,
      "z": 14,
      "name": "Rock_Volcanic"
    },
    {
      "x": 21,
      "y": 15,
      "z": 14,
      "name": "Rock_Volcanic"
    },
    {
      "x": 21,
      "y": 16,
      "z": 14,
      "name": "Rock_Volcanic"
    },
    {
      "x": 21,
      "y": 17,
      "z": 14,
      "name": "Rock_Volcanic"
    },
    {
      "x": 21,
      "y": 18,
      "z": 14,
      "name": "Rock_Volcanic"
    },
    {
      "x": 21,
      "y": 19,
      "z": 14,
      "name": "Rock_Volcanic"
    },
    {
      "x": 21,
      "y": 20,
      "z": 14,
      "name": "Rock_Volcanic"
    },
    {
      "x": 21,
      "y": 21,
      "z": 14,
      "name": "Rock_Volcanic"
    },
    {
      "x": 21,
      "y": 22,
      "z": 14,
      "name": "Rock_Volcanic"
    },
    {
      "x": 21,
      "y": 24,
      "z": 14,
      "name": "Rock_Volcanic"
    },
    {
      "x": 21,
      "y": 25,
      "z": 14,
      "name": "Rock_Volcanic"
    },
    {
      "x": 21,
      "y": 26,
      "z": 14,
      "name": "Rock_Volcanic"
    },
    {
      "x": 21,
      "y": 27,
      "z": 14,
      "name": "Rock_Volcanic"
    },
    {
      "x": 21,
      "y": 28,
      "z": 14,
      "name": "Rock_Volcanic"
    },
    {
      "x": 21,
      "y": 29,
      "z": 14,
      "name": "Rock_Volcanic"
    },
    {
      "x": 21,
      "y": 30,
      "z": 14,
      "name": "Rock_Volcanic"
    },
    {
      "x": 21,
      "y": 31,
      "z": 14,
      "name": "Rock_Volcanic"
    },
    {
      "x": 21,
      "y": 32,
      "z": 14,
      "name": "Rock_Volcanic"
    },
    {
      "x": 21,
      "y": 10,
      "z": 15,
      "name": "Rock_Volcanic"
    },
    {
      "x": 21,
      "y": 11,
      "z": 15,
      "name": "Rock_Volcanic"
    },
    {
      "x": 21,
      "y": 12,
      "z": 15,
      "name": "Rock_Volcanic"
    },
    {
      "x": 21,
      "y": 13,
      "z": 15,
      "name": "Rock_Volcanic"
    },
    {
      "x": 21,
      "y": 14,
      "z": 15,
      "name": "Rock_Volcanic"
    },
    {
      "x": 21,
      "y": 15,
      "z": 15,
      "name": "Rock_Volcanic"
    },
    {
      "x": 21,
      "y": 16,
      "z": 15,
      "name": "Rock_Volcanic"
    },
    {
      "x": 21,
      "y": 17,
      "z": 15,
      "name": "Rock_Volcanic"
    },
    {
      "x": 21,
      "y": 18,
      "z": 15,
      "name": "Rock_Volcanic"
    },
    {
      "x": 21,
      "y": 19,
      "z": 15,
      "name": "Rock_Volcanic"
    },
    {
      "x": 21,
      "y": 20,
      "z": 15,
      "name": "Rock_Volcanic"
    },
    {
      "x": 21,
      "y": 21,
      "z": 15,
      "name": "Rock_Volcanic"
    },
    {
      "x": 21,
      "y": 22,
      "z": 15,
      "name": "Rock_Volcanic"
    },
    {
      "x": 21,
      "y": 23,
      "z": 15,
      "name": "Rock_Volcanic"
    },
    {
      "x": 21,
      "y": 24,
      "z": 15,
      "name": "Rock_Volcanic"
    },
    {
      "x": 21,
      "y": 25,
      "z": 15,
      "name": "Rock_Volcanic"
    },
    {
      "x": 21,
      "y": 26,
      "z": 15,
      "name": "Rock_Volcanic"
    },
    {
      "x": 21,
      "y": 27,
      "z": 15,
      "name": "Rock_Volcanic"
    },
    {
      "x": 21,
      "y": 28,
      "z": 15,
      "name": "Rock_Volcanic"
    },
    {
      "x": 21,
      "y": 29,
      "z": 15,
      "name": "Rock_Volcanic"
    },
    {
      "x": 21,
      "y": 30,
      "z": 15,
      "name": "Rock_Volcanic"
    },
    {
      "x": 21,
      "y": 31,
      "z": 15,
      "name": "Rock_Volcanic"
    },
    {
      "x": 21,
      "y": 32,
      "z": 15,
      "name": "Rock_Volcanic"
    },
    {
      "x": 21,
      "y": 10,
      "z": 16,
      "name": "Rock_Volcanic"
    },
    {
      "x": 21,
      "y": 11,
      "z": 16,
      "name": "Rock_Volcanic"
    },
    {
      "x": 21,
      "y": 12,
      "z": 16,
      "name": "Rock_Volcanic"
    },
    {
      "x": 21,
      "y": 13,
      "z": 16,
      "name": "Rock_Volcanic"
    },
    {
      "x": 21,
      "y": 14,
      "z": 16,
      "name": "Rock_Volcanic"
    },
    {
      "x": 21,
      "y": 15,
      "z": 16,
      "name": "Rock_Volcanic"
    },
    {
      "x": 21,
      "y": 16,
      "z": 16,
      "name": "Rock_Volcanic"
    },
    {
      "x": 21,
      "y": 17,
      "z": 16,
      "name": "Rock_Volcanic"
    },
    {
      "x": 21,
      "y": 18,
      "z": 16,
      "name": "Rock_Volcanic"
    },
    {
      "x": 21,
      "y": 19,
      "z": 16,
      "name": "Rock_Volcanic"
    },
    {
      "x": 21,
      "y": 20,
      "z": 16,
      "name": "Rock_Volcanic"
    },
    {
      "x": 21,
      "y": 21,
      "z": 16,
      "name": "Rock_Volcanic"
    },
    {
      "x": 21,
      "y": 22,
      "z": 16,
      "name": "Rock_Volcanic"
    },
    {
      "x": 21,
      "y": 23,
      "z": 16,
      "name": "Rock_Volcanic"
    },
    {
      "x": 21,
      "y": 24,
      "z": 16,
      "name": "Rock_Volcanic"
    },
    {
      "x": 21,
      "y": 25,
      "z": 16,
      "name": "Rock_Volcanic"
    },
    {
      "x": 21,
      "y": 26,
      "z": 16,
      "name": "Rock_Volcanic"
    },
    {
      "x": 21,
      "y": 27,
      "z": 16,
      "name": "Rock_Volcanic"
    },
    {
      "x": 21,
      "y": 28,
      "z": 16,
      "name": "Rock_Volcanic"
    },
    {
      "x": 21,
      "y": 29,
      "z": 16,
      "name": "Rock_Volcanic"
    },
    {
      "x": 21,
      "y": 30,
      "z": 16,
      "name": "Rock_Volcanic"
    },
    {
      "x": 21,
      "y": 31,
      "z": 16,
      "name": "Rock_Volcanic"
    },
    {
      "x": 21,
      "y": 32,
      "z": 16,
      "name": "Rock_Volcanic"
    },
    {
      "x": 21,
      "y": 9,
      "z": 17,
      "name": "Rock_Volcanic"
    },
    {
      "x": 21,
      "y": 10,
      "z": 17,
      "name": "Rock_Volcanic"
    },
    {
      "x": 21,
      "y": 11,
      "z": 17,
      "name": "Rock_Volcanic"
    },
    {
      "x": 21,
      "y": 12,
      "z": 17,
      "name": "Rock_Volcanic"
    },
    {
      "x": 21,
      "y": 13,
      "z": 17,
      "name": "Rock_Volcanic"
    },
    {
      "x": 21,
      "y": 14,
      "z": 17,
      "name": "Rock_Volcanic"
    },
    {
      "x": 21,
      "y": 15,
      "z": 17,
      "name": "Rock_Volcanic"
    },
    {
      "x": 21,
      "y": 16,
      "z": 17,
      "name": "Rock_Volcanic"
    },
    {
      "x": 21,
      "y": 17,
      "z": 17,
      "name": "Rock_Volcanic"
    },
    {
      "x": 21,
      "y": 18,
      "z": 17,
      "name": "Rock_Volcanic"
    },
    {
      "x": 21,
      "y": 19,
      "z": 17,
      "name": "Rock_Volcanic"
    },
    {
      "x": 21,
      "y": 20,
      "z": 17,
      "name": "Rock_Volcanic"
    },
    {
      "x": 21,
      "y": 21,
      "z": 17,
      "name": "Rock_Volcanic"
    },
    {
      "x": 21,
      "y": 22,
      "z": 17,
      "name": "Rock_Volcanic"
    },
    {
      "x": 21,
      "y": 23,
      "z": 17,
      "name": "Rock_Volcanic"
    },
    {
      "x": 21,
      "y": 24,
      "z": 17,
      "name": "Rock_Volcanic"
    },
    {
      "x": 21,
      "y": 25,
      "z": 17,
      "name": "Rock_Volcanic"
    },
    {
      "x": 21,
      "y": 26,
      "z": 17,
      "name": "Rock_Volcanic"
    },
    {
      "x": 21,
      "y": 27,
      "z": 17,
      "name": "Rock_Volcanic"
    },
    {
      "x": 21,
      "y": 28,
      "z": 17,
      "name": "Rock_Volcanic"
    },
    {
      "x": 21,
      "y": 29,
      "z": 17,
      "name": "Rock_Volcanic"
    },
    {
      "x": 21,
      "y": 30,
      "z": 17,
      "name": "Rock_Volcanic"
    },
    {
      "x": 21,
      "y": 31,
      "z": 17,
      "name": "Rock_Volcanic"
    },
    {
      "x": 21,
      "y": 32,
      "z": 17,
      "name": "Rock_Volcanic"
    },
    {
      "x": 21,
      "y": 33,
      "z": 17,
      "name": "Soil_Dirt_Burnt"
    },
    {
      "x": 21,
      "y": 34,
      "z": 17,
      "name": "Rock_Volcanic"
    },
    {
      "x": 21,
      "y": 35,
      "z": 17,
      "name": "Soil_Grass_Burnt"
    },
    {
      "x": 21,
      "y": 10,
      "z": 18,
      "name": "Rock_Volcanic"
    },
    {
      "x": 21,
      "y": 11,
      "z": 18,
      "name": "Rock_Volcanic"
    },
    {
      "x": 21,
      "y": 12,
      "z": 18,
      "name": "Rock_Volcanic"
    },
    {
      "x": 21,
      "y": 13,
      "z": 18,
      "name": "Rock_Volcanic"
    },
    {
      "x": 21,
      "y": 14,
      "z": 18,
      "name": "Rock_Volcanic"
    },
    {
      "x": 21,
      "y": 15,
      "z": 18,
      "name": "Rock_Volcanic"
    },
    {
      "x": 21,
      "y": 16,
      "z": 18,
      "name": "Rock_Volcanic"
    },
    {
      "x": 21,
      "y": 17,
      "z": 18,
      "name": "Rock_Volcanic"
    },
    {
      "x": 21,
      "y": 18,
      "z": 18,
      "name": "Rock_Volcanic"
    },
    {
      "x": 21,
      "y": 19,
      "z": 18,
      "name": "Rock_Volcanic"
    },
    {
      "x": 21,
      "y": 20,
      "z": 18,
      "name": "Rock_Volcanic"
    },
    {
      "x": 21,
      "y": 21,
      "z": 18,
      "name": "Rock_Volcanic"
    },
    {
      "x": 21,
      "y": 22,
      "z": 18,
      "name": "Rock_Volcanic"
    },
    {
      "x": 21,
      "y": 23,
      "z": 18,
      "name": "Rock_Volcanic"
    },
    {
      "x": 21,
      "y": 24,
      "z": 18,
      "name": "Rock_Volcanic"
    },
    {
      "x": 21,
      "y": 25,
      "z": 18,
      "name": "Rock_Volcanic"
    },
    {
      "x": 21,
      "y": 26,
      "z": 18,
      "name": "Rock_Volcanic"
    },
    {
      "x": 21,
      "y": 27,
      "z": 18,
      "name": "Rock_Volcanic"
    },
    {
      "x": 21,
      "y": 28,
      "z": 18,
      "name": "Rock_Volcanic"
    },
    {
      "x": 21,
      "y": 29,
      "z": 18,
      "name": "Rock_Volcanic"
    },
    {
      "x": 21,
      "y": 30,
      "z": 18,
      "name": "Rock_Volcanic"
    },
    {
      "x": 21,
      "y": 31,
      "z": 18,
      "name": "Rock_Volcanic"
    },
    {
      "x": 21,
      "y": 32,
      "z": 18,
      "name": "Rock_Volcanic"
    },
    {
      "x": 21,
      "y": 33,
      "z": 18,
      "name": "Rock_Volcanic"
    },
    {
      "x": 21,
      "y": 34,
      "z": 18,
      "name": "Rock_Volcanic"
    },
    {
      "x": 21,
      "y": 35,
      "z": 18,
      "name": "Rock_Volcanic"
    },
    {
      "x": 21,
      "y": 13,
      "z": 19,
      "name": "Rock_Volcanic"
    },
    {
      "x": 21,
      "y": 14,
      "z": 19,
      "name": "Rock_Volcanic"
    },
    {
      "x": 21,
      "y": 15,
      "z": 19,
      "name": "Rock_Volcanic"
    },
    {
      "x": 21,
      "y": 16,
      "z": 19,
      "name": "Rock_Volcanic"
    },
    {
      "x": 21,
      "y": 17,
      "z": 19,
      "name": "Rock_Volcanic"
    },
    {
      "x": 21,
      "y": 18,
      "z": 19,
      "name": "Rock_Volcanic"
    },
    {
      "x": 21,
      "y": 19,
      "z": 19,
      "name": "Rock_Volcanic"
    },
    {
      "x": 21,
      "y": 20,
      "z": 19,
      "name": "Rock_Volcanic"
    },
    {
      "x": 21,
      "y": 21,
      "z": 19,
      "name": "Rock_Volcanic"
    },
    {
      "x": 21,
      "y": 22,
      "z": 19,
      "name": "Rock_Volcanic"
    },
    {
      "x": 21,
      "y": 23,
      "z": 19,
      "name": "Rock_Volcanic"
    },
    {
      "x": 21,
      "y": 24,
      "z": 19,
      "name": "Rock_Volcanic"
    },
    {
      "x": 21,
      "y": 25,
      "z": 19,
      "name": "Rock_Volcanic"
    },
    {
      "x": 21,
      "y": 26,
      "z": 19,
      "name": "Rock_Volcanic"
    },
    {
      "x": 21,
      "y": 27,
      "z": 19,
      "name": "Rock_Volcanic"
    },
    {
      "x": 21,
      "y": 28,
      "z": 19,
      "name": "Rock_Volcanic"
    },
    {
      "x": 21,
      "y": 29,
      "z": 19,
      "name": "Rock_Volcanic"
    },
    {
      "x": 21,
      "y": 30,
      "z": 19,
      "name": "Rock_Volcanic"
    },
    {
      "x": 21,
      "y": 31,
      "z": 19,
      "name": "Rock_Volcanic"
    },
    {
      "x": 21,
      "y": 32,
      "z": 19,
      "name": "Rock_Volcanic"
    },
    {
      "x": 21,
      "y": 33,
      "z": 19,
      "name": "Soil_Dirt_Burnt"
    },
    {
      "x": 21,
      "y": 34,
      "z": 19,
      "name": "Rock_Volcanic"
    },
    {
      "x": 21,
      "y": 21,
      "z": 20,
      "name": "Soil_Grass_Burnt"
    },
    {
      "x": 21,
      "y": 25,
      "z": 20,
      "name": "Rock_Volcanic"
    },
    {
      "x": 21,
      "y": 26,
      "z": 20,
      "name": "Rock_Volcanic"
    },
    {
      "x": 21,
      "y": 27,
      "z": 20,
      "name": "Rock_Volcanic"
    },
    {
      "x": 21,
      "y": 28,
      "z": 20,
      "name": "Rock_Volcanic"
    },
    {
      "x": 21,
      "y": 29,
      "z": 20,
      "name": "Rock_Volcanic"
    },
    {
      "x": 21,
      "y": 31,
      "z": 20,
      "name": "Rock_Volcanic"
    },
    {
      "x": 21,
      "y": 32,
      "z": 20,
      "name": "Rock_Volcanic"
    },
    {
      "x": 21,
      "y": 33,
      "z": 20,
      "name": "Rock_Volcanic"
    },
    {
      "x": 21,
      "y": 34,
      "z": 20,
      "name": "Rock_Volcanic"
    },
    {
      "x": 21,
      "y": 21,
      "z": 21,
      "name": "Soil_Dirt_Burnt"
    },
    {
      "x": 21,
      "y": 27,
      "z": 21,
      "name": "Rock_Volcanic"
    },
    {
      "x": 21,
      "y": 31,
      "z": 21,
      "name": "Rock_Volcanic"
    },
    {
      "x": 21,
      "y": 32,
      "z": 21,
      "name": "Rock_Volcanic"
    },
    {
      "x": 21,
      "y": 33,
      "z": 21,
      "name": "Rock_Volcanic"
    },
    {
      "x": 21,
      "y": 21,
      "z": 22,
      "name": "Soil_Dirt_Burnt"
    },
    {
      "x": 21,
      "y": 22,
      "z": 22,
      "name": "Soil_Grass_Burnt"
    },
    {
      "x": 21,
      "y": 23,
      "z": 22,
      "name": "Plant_Flower_Bushy_Violet"
    },
    {
      "x": 21,
      "y": 27,
      "z": 22,
      "name": "Rock_Volcanic"
    },
    {
      "x": 21,
      "y": 33,
      "z": 22,
      "name": "Rock_Volcanic"
    },
    {
      "x": 21,
      "y": 21,
      "z": 23,
      "name": "Soil_Dirt_Burnt"
    },
    {
      "x": 21,
      "y": 22,
      "z": 23,
      "name": "Soil_Grass_Burnt"
    },
    {
      "x": 21,
      "y": 23,
      "z": 23,
      "name": "Rock_Crystal_Purple_Large"
    },
    {
      "x": 21,
      "y": 21,
      "z": 24,
      "name": "Rock_Volcanic"
    },
    {
      "x": 21,
      "y": 22,
      "z": 24,
      "name": "Soil_Dirt_Burnt"
    },
    {
      "x": 21,
      "y": 21,
      "z": 25,
      "name": "Rock_Volcanic"
    },
    {
      "x": 21,
      "y": 22,
      "z": 25,
      "name": "Rock_Volcanic"
    },
    {
      "x": 21,
      "y": 22,
      "z": 26,
      "name": "Rock_Slate"
    },
    {
      "x": 21,
      "y": 22,
      "z": 27,
      "name": "Rock_Slate"
    },
    {
      "x": 21,
      "y": 23,
      "z": 27,
      "name": "Rock_Slate"
    },
    {
      "x": 21,
      "y": 22,
      "z": 28,
      "name": "Rock_Slate"
    },
    {
      "x": 21,
      "y": 23,
      "z": 28,
      "name": "Rock_Volcanic_Cracked_Poisoned"
    },
    {
      "x": 21,
      "y": 23,
      "z": 29,
      "name": "Rock_Volcanic_Cracked_Poisoned"
    },
    {
      "x": 22,
      "y": 33,
      "z": 8,
      "name": "Rock_Slate"
    },
    {
      "x": 22,
      "y": 33,
      "z": 9,
      "name": "Rock_Slate"
    },
    {
      "x": 22,
      "y": 20,
      "z": 10,
      "name": "Rock_Volcanic"
    },
    {
      "x": 22,
      "y": 32,
      "z": 10,
      "name": "Rock_Volcanic"
    },
    {
      "x": 22,
      "y": 33,
      "z": 10,
      "name": "Rock_Volcanic"
    },
    {
      "x": 22,
      "y": 20,
      "z": 11,
      "name": "Rock_Volcanic"
    },
    {
      "x": 22,
      "y": 31,
      "z": 11,
      "name": "Rock_Volcanic"
    },
    {
      "x": 22,
      "y": 32,
      "z": 11,
      "name": "Rock_Volcanic"
    },
    {
      "x": 22,
      "y": 33,
      "z": 11,
      "name": "Rock_Volcanic"
    },
    {
      "x": 22,
      "y": 20,
      "z": 12,
      "name": "Rock_Volcanic"
    },
    {
      "x": 22,
      "y": 22,
      "z": 12,
      "name": "Rock_Volcanic"
    },
    {
      "x": 22,
      "y": 30,
      "z": 12,
      "name": "Rock_Volcanic"
    },
    {
      "x": 22,
      "y": 31,
      "z": 12,
      "name": "Rock_Volcanic"
    },
    {
      "x": 22,
      "y": 32,
      "z": 12,
      "name": "Rock_Volcanic"
    },
    {
      "x": 22,
      "y": 20,
      "z": 13,
      "name": "Rock_Volcanic"
    },
    {
      "x": 22,
      "y": 22,
      "z": 13,
      "name": "Rock_Volcanic"
    },
    {
      "x": 22,
      "y": 28,
      "z": 13,
      "name": "Rock_Volcanic"
    },
    {
      "x": 22,
      "y": 29,
      "z": 13,
      "name": "Rock_Volcanic"
    },
    {
      "x": 22,
      "y": 30,
      "z": 13,
      "name": "Rock_Volcanic"
    },
    {
      "x": 22,
      "y": 31,
      "z": 13,
      "name": "Rock_Volcanic"
    },
    {
      "x": 22,
      "y": 32,
      "z": 13,
      "name": "Rock_Volcanic"
    },
    {
      "x": 22,
      "y": 11,
      "z": 14,
      "name": "Rock_Volcanic"
    },
    {
      "x": 22,
      "y": 12,
      "z": 14,
      "name": "Rock_Volcanic"
    },
    {
      "x": 22,
      "y": 13,
      "z": 14,
      "name": "Rock_Volcanic"
    },
    {
      "x": 22,
      "y": 14,
      "z": 14,
      "name": "Rock_Volcanic"
    },
    {
      "x": 22,
      "y": 15,
      "z": 14,
      "name": "Rock_Volcanic"
    },
    {
      "x": 22,
      "y": 16,
      "z": 14,
      "name": "Rock_Volcanic"
    },
    {
      "x": 22,
      "y": 17,
      "z": 14,
      "name": "Rock_Volcanic"
    },
    {
      "x": 22,
      "y": 18,
      "z": 14,
      "name": "Rock_Volcanic"
    },
    {
      "x": 22,
      "y": 19,
      "z": 14,
      "name": "Rock_Volcanic"
    },
    {
      "x": 22,
      "y": 20,
      "z": 14,
      "name": "Rock_Volcanic"
    },
    {
      "x": 22,
      "y": 21,
      "z": 14,
      "name": "Rock_Volcanic"
    },
    {
      "x": 22,
      "y": 22,
      "z": 14,
      "name": "Rock_Volcanic"
    },
    {
      "x": 22,
      "y": 23,
      "z": 14,
      "name": "Rock_Volcanic"
    },
    {
      "x": 22,
      "y": 25,
      "z": 14,
      "name": "Rock_Volcanic"
    },
    {
      "x": 22,
      "y": 26,
      "z": 14,
      "name": "Rock_Volcanic"
    },
    {
      "x": 22,
      "y": 27,
      "z": 14,
      "name": "Rock_Volcanic"
    },
    {
      "x": 22,
      "y": 28,
      "z": 14,
      "name": "Rock_Volcanic"
    },
    {
      "x": 22,
      "y": 29,
      "z": 14,
