{
  "version": 8,
  "blockIdVersion": 8,
  "anchorX": 0,
  "anchorY": 5,
  "anchorZ": -1,
  "blocks": [
    {
      "x": -1,
      "y": 7,
      "z": -2,
      "name": "Plant_Crop_Mushroom_Block_Red_Mycelium"
    },
    {
      "x": -1,
      "y": 8,
      "z": -2,
      "name": "Plant_Crop_Mushroom_Block_Red"
    },
    {
      "x": -1,
      "y": 9,
      "z": -2,
      "name": "Plant_Crop_Mushroom_Block_Red"
    },
    {
      "x": -1,
      "y": 8,
      "z": -1,
      "name": "Plant_Crop_Mushroom_Block_Red"
    },
    {
      "x": -1,
      "y": 9,
      "z": -1,
      "name": "Plant_Crop_Mushroom_Block_Red"
    },
    {
      "x": -1,
      "y": 10,
      "z": -1,
      "name": "Plant_Crop_Mushroom_Block_Red"
    },
    {
      "x": -1,
      "y": 8,
      "z": 0,
      "name": "Plant_Crop_Mushroom_Block_Red"
    },
    {
      "x": -1,
      "y": 9,
      "z": 0,
      "name": "Plant_Crop_Mushroom_Block_Red"
    },
    {
      "x": 0,
      "y": 7,
      "z": -2,
      "name": "Plant_Crop_Mushroom_Block_Red_Mycelium"
    },
    {
      "x": 0,
      "y": 8,
      "z": -2,
      "name": "Plant_Crop_Mushroom_Block_Red"
    },
    {
      "x": 0,
      "y": 9,
      "z": -2,
      "name": "Plant_Crop_Mushroom_Block_Red"
    },
    {
      "x": 0,
      "y": 10,
      "z": -2,
      "name": "Plant_Crop_Mushroom_Block_Red"
    },
    {
      "x": 0,
      "y": 3,
      "z": -1,
      "name": "Plant_Crop_Mushroom_Block_Brown_Trunk"
    },
    {
      "x": 0,
      "y": 4,
      "z": -1,
      "name": "Plant_Crop_Mushroom_Block_Brown_Trunk"
    },
    {
      "x": 0,
      "y": 5,
      "z": -1,
      "name": "Plant_Crop_Mushroom_Block_Brown_Trunk"
    },
    {
      "x": 0,
      "y": 6,
      "z": -1,
      "name": "Plant_Crop_Mushroom_Block_Brown_Trunk"
    },
    {
      "x": 0,
      "y": 7,
      "z": -1,
      "name": "Plant_Crop_Mushroom_Block_Brown_Trunk"
    },
    {
      "x": 0,
      "y": 8,
      "z": -1,
      "name": "Plant_Crop_Mushroom_Block_Brown_Trunk"
    },
    {
      "x": 0,
      "y": 9,
      "z": -1,
      "name": "Plant_Crop_Mushroom_Block_Red"
    },
    {
      "x": 0,
      "y": 10,
      "z": -1,
      "name": "Plant_Crop_Mushroom_Block_Red"
    },
    {
      "x": 0,
      "y": 7,
      "z": 0,
      "name": "Plant_Crop_Mushroom_Block_Red_Mycelium"
    },
    {
      "x": 0,
      "y": 8,
      "z": 0,
      "name": "Plant_Crop_Mushroom_Block_Red"
    },
    {
      "x": 0,
      "y": 9,
      "z": 0,
      "name": "Plant_Crop_Mushroom_Block_Red"
    },
    {
      "x": 0,
      "y": 10,
      "z": 0,
      "name": "Plant_Crop_Mushroom_Block_Red"
    },
    {
      "x": 1,
      "y": 8,
      "z": -2,
      "name": "Plant_Crop_Mushroom_Block_Red"
    },
    {
      "x": 1,
      "y": 9,
      "z": -2,
      "name": "Plant_Crop_Mushroom_Block_Red"
    },
    {
      "x": 1,
      "y": 7,
      "z": -1,
      "name": "Plant_Crop_Mushroom_Block_Red_Mycelium"
    },
    {
      "x": 1,
      "y": 8,
      "z": -1,
      "name": "Plant_Crop_Mushroom_Block_Red"
    },
    {
      "x": 1,
      "y": 9,
      "z": -1,
      "name": "Plant_Crop_Mushroom_Block_Red"
    },
    {
      "x": 1,
      "y": 10,
      "z": -1,
      "name": "Plant_Crop_Mushroom_Block_Red"
    },
    {
      "x": 1,
      "y": 7,
      "z": 0,
      "name": "Plant_Crop_Mushroom_Block_Red_Mycelium"
    },
    {
      "x": 1,
      "y": 8,
      "z": 0,
      "name": "Plant_Crop_Mushroom_Block_Red"
    },
    {
      "x": 1,
      "y": 9,
      "z": 0,
      "name": "Plant_Crop_Mushroom_Block_Red"
    }
  ]
}