{
  "version": 8,
  "blockIdVersion": 8,
  "anchorX": 6,
  "anchorY": 2,
  "anchorZ": 6,
  "blocks": [
    {
      "x": 0,
      "y": 0,
      "z": 2,
      "name": "Rock_Sandstone"
    },
    {
      "x": 0,
      "y": 1,
      "z": 2,
      "name": "Rock_Sandstone"
    },
    {
      "x": 0,
      "y": 2,
      "z": 2,
      "name": "Soil_Sand_White"
    },
    {
      "x": 0,
      "y": 0,
      "z": 3,
      "name": "Rock_Sandstone"
    },
    {
      "x": 0,
      "y": 1,
      "z": 3,
      "name": "Rock_Sandstone"
    },
    {
      "x": 0,
      "y": 2,
      "z": 3,
      "name": "Soil_Sand_White"
    },
    {
      "x": 0,
      "y": 3,
      "z": 3,
      "name": "Soil_Sand_White"
    },
    {
      "x": 0,
      "y": 0,
      "z": 4,
      "name": "Rock_Sandstone"
    },
    {
      "x": 0,
      "y": 1,
      "z": 4,
      "name": "Rock_Sandstone"
    },
    {
      "x": 0,
      "y": 2,
      "z": 4,
      "name": "Soil_Sand_White"
    },
    {
      "x": 0,
      "y": 3,
      "z": 4,
      "name": "Soil_Sand_White"
    },
    {
      "x": 0,
      "y": 0,
      "z": 5,
      "name": "Rock_Sandstone"
    },
    {
      "x": 0,
      "y": 1,
      "z": 5,
      "name": "Rock_Sandstone"
    },
    {
      "x": 0,
      "y": 2,
      "z": 5,
      "name": "Rock_Sandstone"
    },
    {
      "x": 0,
      "y": 3,
      "z": 5,
      "name": "Rock_Sandstone"
    },
    {
      "x": 0,
      "y": 0,
      "z": 6,
      "name": "Rock_Sandstone"
    },
    {
      "x": 0,
      "y": 1,
      "z": 6,
      "name": "Rock_Sandstone"
    },
    {
      "x": 0,
      "y": 2,
      "z": 6,
      "name": "Rock_Sandstone"
    },
    {
      "x": 0,
      "y": 0,
      "z": 7,
      "name": "Rock_Sandstone"
    },
    {
      "x": 0,
      "y": 1,
      "z": 7,
      "name": "Rock_Sandstone"
    },
    {
      "x": 1,
      "y": 0,
      "z": 0,
      "name": "Rock_Sandstone"
    },
    {
      "x": 1,
      "y": 0,
      "z": 1,
      "name": "Rock_Sandstone"
    },
    {
      "x": 1,
      "y": 1,
      "z": 1,
      "name": "Rock_Sandstone"
    },
    {
      "x": 1,
      "y": 2,
      "z": 1,
      "name": "Rock_Sandstone"
    },
    {
      "x": 1,
      "y": 0,
      "z": 2,
      "name": "Rock_Sandstone"
    },
    {
      "x": 1,
      "y": 1,
      "z": 2,
      "name": "Rock_Sandstone"
    },
    {
      "x": 1,
      "y": 2,
      "z": 2,
      "name": "Rock_Sandstone"
    },
    {
      "x": 1,
      "y": 3,
      "z": 2,
      "name": "Rock_Sandstone"
    },
    {
      "x": 1,
      "y": 4,
      "z": 2,
      "name": "Rock_Sandstone_White"
    },
    {
      "x": 1,
      "y": 0,
      "z": 3,
      "name": "Rock_Sandstone"
    },
    {
      "x": 1,
      "y": 1,
      "z": 3,
      "name": "Rock_Sandstone"
    },
    {
      "x": 1,
      "y": 2,
      "z": 3,
      "name": "Rock_Sandstone"
    },
    {
      "x": 1,
      "y": 3,
      "z": 3,
      "name": "Rock_Sandstone"
    },
    {
      "x": 1,
      "y": 4,
      "z": 3,
      "name": "Rock_Sandstone_White"
    },
    {
      "x": 1,
      "y": 0,
      "z": 4,
      "name": "Rock_Sandstone"
    },
    {
      "x": 1,
      "y": 1,
      "z": 4,
      "name": "Rock_Sandstone"
    },
    {
      "x": 1,
      "y": 2,
      "z": 4,
      "name": "Rock_Sandstone"
    },
    {
      "x": 1,
      "y": 3,
      "z": 4,
      "name": "Rock_Sandstone"
    },
    {
      "x": 1,
      "y": 4,
      "z": 4,
      "name": "Rock_Sandstone_White"
    },
    {
      "x": 1,
      "y": 0,
      "z": 5,
      "name": "Rock_Sandstone"
    },
    {
      "x": 1,
      "y": 1,
      "z": 5,
      "name": "Rock_Sandstone"
    },
    {
      "x": 1,
      "y": 2,
      "z": 5,
      "name": "Rock_Sandstone"
    },
    {
      "x": 1,
      "y": 3,
      "z": 5,
      "name": "Rock_Sandstone"
    },
    {
      "x": 1,
      "y": 4,
      "z": 5,
      "name": "Rock_Sandstone_White"
    },
    {
      "x": 1,
      "y": 0,
      "z": 6,
      "name": "Rock_Sandstone"
    },
    {
      "x": 1,
      "y": 1,
      "z": 6,
      "name": "Rock_Sandstone"
    },
    {
      "x": 1,
      "y": 2,
      "z": 6,
      "name": "Rock_Sandstone"
    },
    {
      "x": 1,
      "y": 3,
      "z": 6,
      "name": "Rock_Sandstone"
    },
    {
      "x": 1,
      "y": 4,
      "z": 6,
      "name": "Rock_Sandstone_White"
    },
    {
      "x": 1,
      "y": 0,
      "z": 7,
      "name": "Rock_Sandstone"
    },
    {
      "x": 1,
      "y": 1,
      "z": 7,
      "name": "Rock_Sandstone"
    },
    {
      "x": 1,
      "y": 2,
      "z": 7,
      "name": "Rock_Sandstone"
    },
    {
      "x": 1,
      "y": 3,
      "z": 7,
      "name": "Rock_Sandstone"
    },
    {
      "x": 1,
      "y": 4,
      "z": 7,
      "name": "Rock_Sandstone_White"
    },
    {
      "x": 1,
      "y": 0,
      "z": 8,
      "name": "Rock_Sandstone"
    },
    {
      "x": 1,
      "y": 1,
      "z": 8,
      "name": "Rock_Sandstone"
    },
    {
      "x": 1,
      "y": 2,
      "z": 8,
      "name": "Soil_Sand_White"
    },
    {
      "x": 1,
      "y": 0,
      "z": 9,
      "name": "Rock_Sandstone"
    },
    {
      "x": 1,
      "y": 1,
      "z": 9,
      "name": "Rock_Sandstone"
    },
    {
      "x": 1,
      "y": 2,
      "z": 9,
      "name": "Soil_Sand_White"
    },
    {
      "x": 2,
      "y": 0,
      "z": 0,
      "name": "Rock_Sandstone"
    },
    {
      "x": 2,
      "y": 1,
      "z": 0,
      "name": "Rock_Sandstone"
    },
    {
      "x": 2,
      "y": 2,
      "z": 0,
      "name": "Soil_Sand_White"
    },
    {
      "x": 2,
      "y": 0,
      "z": 1,
      "name": "Rock_Sandstone"
    },
    {
      "x": 2,
      "y": 1,
      "z": 1,
      "name": "Rock_Sandstone"
    },
    {
      "x": 2,
      "y": 2,
      "z": 1,
      "name": "Rock_Sandstone"
    },
    {
      "x": 2,
      "y": 3,
      "z": 1,
      "name": "Rock_Sandstone"
    },
    {
      "x": 2,
      "y": 4,
      "z": 1,
      "name": "Rock_Sandstone_White"
    },
    {
      "x": 2,
      "y": 0,
      "z": 2,
      "name": "Rock_Sandstone"
    },
    {
      "x": 2,
      "y": 1,
      "z": 2,
      "name": "Rock_Sandstone"
    },
    {
      "x": 2,
      "y": 2,
      "z": 2,
      "name": "Rock_Sandstone"
    },
    {
      "x": 2,
      "y": 3,
      "z": 2,
      "name": "Soil_Sand_White"
    },
    {
      "x": 2,
      "y": 0,
      "z": 3,
      "name": "Rock_Sandstone"
    },
    {
      "x": 2,
      "y": 1,
      "z": 3,
      "name": "Rock_Sandstone"
    },
    {
      "x": 2,
      "y": 2,
      "z": 3,
      "name": "Rock_Sandstone"
    },
    {
      "x": 2,
      "y": 3,
      "z": 3,
      "name": "Soil_Sand_White"
    },
    {
      "x": 2,
      "y": 0,
      "z": 4,
      "name": "Rock_Sandstone"
    },
    {
      "x": 2,
      "y": 1,
      "z": 4,
      "name": "Rock_Sandstone"
    },
    {
      "x": 2,
      "y": 2,
      "z": 4,
      "name": "Rock_Sandstone"
    },
    {
      "x": 2,
      "y": 3,
      "z": 4,
      "name": "Soil_Sand_White"
    },
    {
      "x": 2,
      "y": 0,
      "z": 5,
      "name": "Rock_Sandstone"
    },
    {
      "x": 2,
      "y": 1,
      "z": 5,
      "name": "Rock_Sandstone"
    },
    {
      "x": 2,
      "y": 2,
      "z": 5,
      "name": "Rock_Sandstone"
    },
    {
      "x": 2,
      "y": 3,
      "z": 5,
      "name": "Soil_Sand_White"
    },
    {
      "x": 2,
      "y": 0,
      "z": 6,
      "name": "Rock_Sandstone"
    },
    {
      "x": 2,
      "y": 1,
      "z": 6,
      "name": "Rock_Sandstone"
    },
    {
      "x": 2,
      "y": 2,
      "z": 6,
      "name": "Rock_Sandstone"
    },
    {
      "x": 2,
      "y": 3,
      "z": 6,
      "name": "Soil_Sand_White"
    },
    {
      "x": 2,
      "y": 0,
      "z": 7,
      "name": "Rock_Sandstone"
    },
    {
      "x": 2,
      "y": 1,
      "z": 7,
      "name": "Rock_Sandstone"
    },
    {
      "x": 2,
      "y": 2,
      "z": 7,
      "name": "Rock_Sandstone"
    },
    {
      "x": 2,
      "y": 3,
      "z": 7,
      "name": "Soil_Sand_White"
    },
    {
      "x": 2,
      "y": 0,
      "z": 8,
      "name": "Rock_Sandstone"
    },
    {
      "x": 2,
      "y": 1,
      "z": 8,
      "name": "Rock_Sandstone"
    },
    {
      "x": 2,
      "y": 2,
      "z": 8,
      "name": "Rock_Sandstone"
    },
    {
      "x": 2,
      "y": 3,
      "z": 8,
      "name": "Rock_Sandstone"
    },
    {
      "x": 2,
      "y": 4,
      "z": 8,
      "name": "Rock_Sandstone_White"
    },
    {
      "x": 2,
      "y": 0,
      "z": 9,
      "name": "Rock_Sandstone"
    },
    {
      "x": 2,
      "y": 1,
      "z": 9,
      "name": "Rock_Sandstone"
    },
    {
      "x": 2,
      "y": 2,
      "z": 9,
      "name": "Soil_Sand_White"
    },
    {
      "x": 2,
      "y": 3,
      "z": 9,
      "name": "Rock_Sandstone"
    },
    {
      "x": 2,
      "y": 4,
      "z": 9,
      "name": "Rock_Sandstone_White"
    },
    {
      "x": 3,
      "y": 0,
      "z": 0,
      "name": "Rock_Sandstone"
    },
    {
      "x": 3,
      "y": 1,
      "z": 0,
      "name": "Rock_Sandstone"
    },
    {
      "x": 3,
      "y": 2,
      "z": 0,
      "name": "Soil_Sand_White"
    },
    {
      "x": 3,
      "y": 0,
      "z": 1,
      "name": "Rock_Sandstone"
    },
    {
      "x": 3,
      "y": 1,
      "z": 1,
      "name": "Rock_Sandstone"
    },
    {
      "x": 3,
      "y": 2,
      "z": 1,
      "name": "Rock_Sandstone"
    },
    {
      "x": 3,
      "y": 3,
      "z": 1,
      "name": "Soil_Sand_White"
    },
    {
      "x": 3,
      "y": 4,
      "z": 1,
      "name": "Rock_Sandstone_White"
    },
    {
      "x": 3,
      "y": 0,
      "z": 2,
      "name": "Rock_Sandstone"
    },
    {
      "x": 3,
      "y": 1,
      "z": 2,
      "name": "Rock_Sandstone"
    },
    {
      "x": 3,
      "y": 2,
      "z": 2,
      "name": "Rock_Sandstone"
    },
    {
      "x": 3,
      "y": 3,
      "z": 2,
      "name": "Soil_Sand_White"
    },
    {
      "x": 3,
      "y": 0,
      "z": 3,
      "name": "Rock_Sandstone"
    },
    {
      "x": 3,
      "y": 1,
      "z": 3,
      "name": "Rock_Sandstone"
    },
    {
      "x": 3,
      "y": 2,
      "z": 3,
      "name": "Rock_Sandstone"
    },
    {
      "x": 3,
      "y": 3,
      "z": 3,
      "name": "Soil_Sand_White"
    },
    {
      "x": 3,
      "y": 0,
      "z": 4,
      "name": "Rock_Sandstone"
    },
    {
      "x": 3,
      "y": 1,
      "z": 4,
      "name": "Rock_Sandstone"
    },
    {
      "x": 3,
      "y": 2,
      "z": 4,
      "name": "Rock_Sandstone"
    },
    {
      "x": 3,
      "y": 3,
      "z": 4,
      "name": "Soil_Sand_White"
    },
    {
      "x": 3,
      "y": 0,
      "z": 5,
      "name": "Rock_Sandstone"
    },
    {
      "x": 3,
      "y": 1,
      "z": 5,
      "name": "Rock_Sandstone"
    },
    {
      "x": 3,
      "y": 2,
      "z": 5,
      "name": "Rock_Sandstone"
    },
    {
      "x": 3,
      "y": 3,
      "z": 5,
      "name": "Soil_Sand_White"
    },
    {
      "x": 3,
      "y": 0,
      "z": 6,
      "name": "Rock_Sandstone"
    },
    {
      "x": 3,
      "y": 1,
      "z": 6,
      "name": "Rock_Sandstone"
    },
    {
      "x": 3,
      "y": 2,
      "z": 6,
      "name": "Rock_Sandstone"
    },
    {
      "x": 3,
      "y": 3,
      "z": 6,
      "name": "Soil_Sand_White"
    },
    {
      "x": 3,
      "y": 0,
      "z": 7,
      "name": "Rock_Sandstone"
    },
    {
      "x": 3,
      "y": 1,
      "z": 7,
      "name": "Rock_Sandstone"
    },
    {
      "x": 3,
      "y": 2,
      "z": 7,
      "name": "Rock_Sandstone"
    },
    {
      "x": 3,
      "y": 3,
      "z": 7,
      "name": "Soil_Sand_White"
    },
    {
      "x": 3,
      "y": 0,
      "z": 8,
      "name": "Rock_Sandstone"
    },
    {
      "x": 3,
      "y": 1,
      "z": 8,
      "name": "Rock_Sandstone"
    },
    {
      "x": 3,
      "y": 2,
      "z": 8,
      "name": "Rock_Sandstone"
    },
    {
      "x": 3,
      "y": 3,
      "z": 8,
      "name": "Soil_Sand_White"
    },
    {
      "x": 3,
      "y": 0,
      "z": 9,
      "name": "Rock_Sandstone"
    },
    {
      "x": 3,
      "y": 1,
      "z": 9,
      "name": "Rock_Sandstone"
    },
    {
      "x": 3,
      "y": 2,
      "z": 9,
      "name": "Soil_Sand_White"
    },
    {
      "x": 3,
      "y": 3,
      "z": 9,
      "name": "Soil_Sand_White"
    },
    {
      "x": 3,
      "y": 4,
      "z": 9,
      "name": "Rock_Sandstone_White"
    },
    {
      "x": 3,
      "y": 0,
      "z": 10,
      "name": "Rock_Sandstone"
    },
    {
      "x": 3,
      "y": 1,
      "z": 10,
      "name": "Rock_Sandstone"
    },
    {
      "x": 3,
      "y": 2,
      "z": 10,
      "name": "Soil_Sand_White"
    },
    {
      "x": 3,
      "y": 3,
      "z": 10,
      "name": "Soil_Sand_White"
    },
    {
      "x": 4,
      "y": 0,
      "z": 0,
      "name": "Rock_Sandstone"
    },
    {
      "x": 4,
      "y": 1,
      "z": 0,
      "name": "Rock_Sandstone"
    },
    {
      "x": 4,
      "y": 2,
      "z": 0,
      "name": "Soil_Sand_White"
    },
    {
      "x": 4,
      "y": 3,
      "z": 0,
      "name": "Soil_Sand_White"
    },
    {
      "x": 4,
      "y": 4,
      "z": 0,
      "name": "Rock_Sandstone_White"
    },
    {
      "x": 4,
      "y": 0,
      "z": 1,
      "name": "Rock_Sandstone"
    },
    {
      "x": 4,
      "y": 1,
      "z": 1,
      "name": "Rock_Sandstone"
    },
    {
      "x": 4,
      "y": 2,
      "z": 1,
      "name": "Rock_Sandstone"
    },
    {
      "x": 4,
      "y": 3,
      "z": 1,
      "name": "Soil_Sand_White"
    },
    {
      "x": 4,
      "y": 0,
      "z": 2,
      "name": "Rock_Sandstone"
    },
    {
      "x": 4,
      "y": 1,
      "z": 2,
      "name": "Rock_Sandstone"
    },
    {
      "x": 4,
      "y": 2,
      "z": 2,
      "name": "Rock_Sandstone"
    },
    {
      "x": 4,
      "y": 3,
      "z": 2,
      "name": "Soil_Sand_White"
    },
    {
      "x": 4,
      "y": 0,
      "z": 3,
      "name": "Rock_Sandstone"
    },
    {
      "x": 4,
      "y": 1,
      "z": 3,
      "name": "Rock_Sandstone"
    },
    {
      "x": 4,
      "y": 2,
      "z": 3,
      "name": "Rock_Sandstone"
    },
    {
      "x": 4,
      "y": 3,
      "z": 3,
      "name": "Soil_Sand_White"
    },
    {
      "x": 4,
      "y": 0,
      "z": 4,
      "name": "Rock_Sandstone"
    },
    {
      "x": 4,
      "y": 1,
      "z": 4,
      "name": "Rock_Sandstone"
    },
    {
      "x": 4,
      "y": 2,
      "z": 4,
      "name": "Rock_Sandstone"
    },
    {
      "x": 4,
      "y": 3,
      "z": 4,
      "name": "Soil_Sand_White"
    },
    {
      "x": 4,
      "y": 0,
      "z": 5,
      "name": "Rock_Sandstone"
    },
    {
      "x": 4,
      "y": 1,
      "z": 5,
      "name": "Rock_Sandstone"
    },
    {
      "x": 4,
      "y": 2,
      "z": 5,
      "name": "Rock_Sandstone"
    },
    {
      "x": 4,
      "y": 3,
      "z": 5,
      "name": "Soil_Sand_White"
    },
    {
      "x": 4,
      "y": 0,
      "z": 6,
      "name": "Rock_Sandstone"
    },
    {
      "x": 4,
      "y": 1,
      "z": 6,
      "name": "Rock_Sandstone"
    },
    {
      "x": 4,
      "y": 2,
      "z": 6,
      "name": "Rock_Sandstone"
    },
    {
      "x": 4,
      "y": 3,
      "z": 6,
      "name": "Soil_Sand_White"
    },
    {
      "x": 4,
      "y": 0,
      "z": 7,
      "name": "Rock_Sandstone"
    },
    {
      "x": 4,
      "y": 1,
      "z": 7,
      "name": "Rock_Sandstone"
    },
    {
      "x": 4,
      "y": 2,
      "z": 7,
      "name": "Rock_Sandstone"
    },
    {
      "x": 4,
      "y": 3,
      "z": 7,
      "name": "Soil_Sand_White"
    },
    {
      "x": 4,
      "y": 0,
      "z": 8,
      "name": "Rock_Sandstone"
    },
    {
      "x": 4,
      "y": 1,
      "z": 8,
      "name": "Rock_Sandstone"
    },
    {
      "x": 4,
      "y": 2,
      "z": 8,
      "name": "Rock_Sandstone"
    },
    {
      "x": 4,
      "y": 3,
      "z": 8,
      "name": "Soil_Sand_White"
    },
    {
      "x": 4,
      "y": 0,
      "z": 9,
      "name": "Rock_Sandstone"
    },
    {
      "x": 4,
      "y": 1,
      "z": 9,
      "name": "Rock_Sandstone"
    },
    {
      "x": 4,
      "y": 2,
      "z": 9,
      "name": "Rock_Sandstone"
    },
    {
      "x": 4,
      "y": 3,
      "z": 9,
      "name": "Rock_Sandstone"
    },
    {
      "x": 4,
      "y": 4,
      "z": 9,
      "name": "Rock_Sandstone_White"
    },
    {
      "x": 4,
      "y": 0,
      "z": 10,
      "name": "Rock_Sandstone"
    },
    {
      "x": 4,
      "y": 1,
      "z": 10,
      "name": "Rock_Sandstone"
    },
    {
      "x": 4,
      "y": 2,
      "z": 10,
      "name": "Rock_Sandstone"
    },
    {
      "x": 4,
      "y": 3,
      "z": 10,
      "name": "Soil_Sand_White"
    },
    {
      "x": 5,
      "y": 0,
      "z": 0,
      "name": "Rock_Sandstone"
    },
    {
      "x": 5,
      "y": 1,
      "z": 0,
      "name": "Rock_Sandstone"
    },
    {
      "x": 5,
      "y": 2,
      "z": 0,
      "name": "Rock_Sandstone"
    },
    {
      "x": 5,
      "y": 3,
      "z": 0,
      "name": "Soil_Sand_White"
    },
    {
      "x": 5,
      "y": 4,
      "z": 0,
      "name": "Rock_Sandstone_White"
    },
    {
      "x": 5,
      "y": 0,
      "z": 1,
      "name": "Rock_Sandstone"
    },
    {
      "x": 5,
      "y": 1,
      "z": 1,
      "name": "Rock_Sandstone"
    },
    {
      "x": 5,
      "y": 2,
      "z": 1,
      "name": "Rock_Sandstone"
    },
    {
      "x": 5,
      "y": 3,
      "z": 1,
      "name": "Soil_Sand_White"
    },
    {
      "x": 5,
      "y": 0,
      "z": 2,
      "name": "Rock_Sandstone"
    },
    {
      "x": 5,
      "y": 1,
      "z": 2,
      "name": "Rock_Sandstone"
    },
    {
      "x": 5,
      "y": 2,
      "z": 2,
      "name": "Rock_Sandstone"
    },
    {
      "x": 5,
      "y": 3,
      "z": 2,
      "name": "Soil_Sand_White"
    },
    {
      "x": 5,
      "y": 0,
      "z": 3,
      "name": "Rock_Sandstone"
    },
    {
      "x": 5,
      "y": 1,
      "z": 3,
      "name": "Rock_Sandstone"
    },
    {
      "x": 5,
      "y": 2,
      "z": 3,
      "name": "Rock_Sandstone"
    },
    {
      "x": 5,
      "y": 3,
      "z": 3,
      "name": "Soil_Sand_White"
    },
    {
      "x": 5,
      "y": 0,
      "z": 4,
      "name": "Rock_Sandstone"
    },
    {
      "x": 5,
      "y": 1,
      "z": 4,
      "name": "Rock_Sandstone"
    },
    {
      "x": 5,
      "y": 2,
      "z": 4,
      "name": "Rock_Sandstone"
    },
    {
      "x": 5,
      "y": 3,
      "z": 4,
      "name": "Soil_Sand_White"
    },
    {
      "x": 5,
      "y": 0,
      "z": 5,
      "name": "Rock_Sandstone"
    },
    {
      "x": 5,
      "y": 1,
      "z": 5,
      "name": "Rock_Sandstone"
    },
    {
      "x": 5,
      "y": 2,
      "z": 5,
      "name": "Rock_Sandstone"
    },
    {
      "x": 5,
      "y": 3,
      "z": 5,
      "name": "Soil_Sand_White"
    },
    {
      "x": 5,
      "y": 0,
      "z": 6,
      "name": "Rock_Sandstone"
    },
    {
      "x": 5,
      "y": 1,
      "z": 6,
      "name": "Rock_Sandstone"
    },
    {
      "x": 5,
      "y": 2,
      "z": 6,
      "name": "Rock_Sandstone"
    },
    {
      "x": 5,
      "y": 3,
      "z": 6,
      "name": "Soil_Sand_White"
    },
    {
      "x": 5,
      "y": 0,
      "z": 7,
      "name": "Rock_Sandstone"
    },
    {
      "x": 5,
      "y": 1,
      "z": 7,
      "name": "Rock_Sandstone"
    },
    {
      "x": 5,
      "y": 2,
      "z": 7,
      "name": "Rock_Sandstone"
    },
    {
      "x": 5,
      "y": 3,
      "z": 7,
      "name": "Soil_Sand_White"
    },
    {
      "x": 5,
      "y": 0,
      "z": 8,
      "name": "Rock_Sandstone"
    },
    {
      "x": 5,
      "y": 1,
      "z": 8,
      "name": "Rock_Sandstone"
    },
    {
      "x": 5,
      "y": 2,
      "z": 8,
      "name": "Rock_Sandstone"
    },
    {
      "x": 5,
      "y": 3,
      "z": 8,
      "name": "Soil_Sand_White"
    },
    {
      "x": 5,
      "y": 0,
      "z": 9,
      "name": "Rock_Sandstone"
    },
    {
      "x": 5,
      "y": 1,
      "z": 9,
      "name": "Rock_Sandstone"
    },
    {
      "x": 5,
      "y": 2,
      "z": 9,
      "name": "Rock_Sandstone"
    },
    {
      "x": 5,
      "y": 3,
      "z": 9,
      "name": "Soil_Sand_White"
    },
    {
      "x": 5,
      "y": 0,
      "z": 10,
      "name": "Rock_Sandstone"
    },
    {
      "x": 5,
      "y": 1,
      "z": 10,
      "name": "Rock_Sandstone"
    },
    {
      "x": 5,
      "y": 2,
      "z": 10,
      "name": "Rock_Sandstone"
    },
    {
      "x": 5,
      "y": 3,
      "z": 10,
      "name": "Soil_Sand_White"
    },
    {
      "x": 5,
      "y": 4,
      "z": 10,
      "name": "Rock_Sandstone_White"
    },
    {
      "x": 5,
      "y": 0,
      "z": 11,
      "name": "Rock_Sandstone"
    },
    {
      "x": 5,
      "y": 1,
      "z": 11,
      "name": "Rock_Sandstone"
    },
    {
      "x": 5,
      "y": 2,
      "z": 11,
      "name": "Soil_Sand_White"
    },
    {
      "x": 6,
      "y": 0,
      "z": 0,
      "name": "Rock_Sandstone"
    },
    {
      "x": 6,
      "y": 1,
      "z": 0,
      "name": "Rock_Sandstone"
    },
    {
      "x": 6,
      "y": 2,
      "z": 0,
      "name": "Rock_Sandstone"
    },
    {
      "x": 6,
      "y": 3,
      "z": 0,
      "name": "Soil_Sand_White"
    },
    {
      "x": 6,
      "y": 4,
      "z": 0,
      "name": "Rock_Sandstone_White"
    },
    {
      "x": 6,
      "y": 0,
      "z": 1,
      "name": "Rock_Sandstone"
    },
    {
      "x": 6,
      "y": 1,
      "z": 1,
      "name": "Rock_Sandstone"
    },
    {
      "x": 6,
      "y": 2,
      "z": 1,
      "name": "Rock_Sandstone"
    },
    {
      "x": 6,
      "y": 3,
      "z": 1,
      "name": "Soil_Sand_White"
    },
    {
      "x": 6,
      "y": 0,
      "z": 2,
      "name": "Rock_Sandstone"
    },
    {
      "x": 6,
      "y": 1,
      "z": 2,
      "name": "Rock_Sandstone"
    },
    {
      "x": 6,
      "y": 2,
      "z": 2,
      "name": "Rock_Sandstone"
    },
    {
      "x": 6,
      "y": 3,
      "z": 2,
      "name": "Soil_Sand_White"
    },
    {
      "x": 6,
      "y": 0,
      "z": 3,
      "name": "Rock_Sandstone"
    },
    {
      "x": 6,
      "y": 1,
      "z": 3,
      "name": "Rock_Sandstone"
    },
    {
      "x": 6,
      "y": 2,
      "z": 3,
      "name": "Rock_Sandstone"
    },
    {
      "x": 6,
      "y": 3,
      "z": 3,
      "name": "Soil_Sand_White"
    },
    {
      "x": 6,
      "y": 0,
      "z": 4,
      "name": "Rock_Sandstone"
    },
    {
      "x": 6,
      "y": 1,
      "z": 4,
      "name": "Rock_Sandstone"
    },
    {
      "x": 6,
      "y": 2,
      "z": 4,
      "name": "Rock_Sandstone"
    },
    {
      "x": 6,
      "y": 3,
      "z": 4,
      "name": "Soil_Sand_White"
    },
    {
      "x": 6,
      "y": 0,
      "z": 5,
      "name": "Rock_Sandstone"
    },
    {
      "x": 6,
      "y": 1,
      "z": 5,
      "name": "Rock_Sandstone"
    },
    {
      "x": 6,
      "y": 2,
      "z": 5,
      "name": "Rock_Sandstone"
    },
    {
      "x": 6,
      "y": 3,
      "z": 5,
      "name": "Soil_Sand_White"
    },
    {
      "x": 6,
      "y": 0,
      "z": 6,
      "name": "Rock_Sandstone"
    },
    {
      "x": 6,
      "y": 1,
      "z": 6,
      "name": "Rock_Sandstone"
    },
    {
      "x": 6,
      "y": 2,
      "z": 6,
      "name": "Rock_Sandstone"
    },
    {
      "x": 6,
      "y": 3,
      "z": 6,
      "name": "Soil_Sand_White"
    },
    {
      "x": 6,
      "y": 0,
      "z": 7,
      "name": "Rock_Sandstone"
    },
    {
      "x": 6,
      "y": 1,
      "z": 7,
      "name": "Rock_Sandstone"
    },
    {
      "x": 6,
      "y": 2,
      "z": 7,
      "name": "Rock_Sandstone"
    },
    {
      "x": 6,
      "y": 3,
      "z": 7,
      "name": "Soil_Sand_White"
    },
    {
      "x": 6,
      "y": 0,
      "z": 8,
      "name": "Rock_Sandstone"
    },
    {
      "x": 6,
      "y": 1,
      "z": 8,
      "name": "Rock_Sandstone"
    },
    {
      "x": 6,
      "y": 2,
      "z": 8,
      "name": "Rock_Sandstone"
    },
    {
      "x": 6,
      "y": 3,
      "z": 8,
      "name": "Soil_Sand_White"
    },
    {
      "x": 6,
      "y": 0,
      "z": 9,
      "name": "Rock_Sandstone"
    },
    {
      "x": 6,
      "y": 1,
      "z": 9,
      "name": "Rock_Sandstone"
    },
    {
      "x": 6,
      "y": 2,
      "z": 9,
      "name": "Rock_Sandstone"
    },
    {
      "x": 6,
      "y": 3,
      "z": 9,
      "name": "Soil_Sand_White"
    },
    {
      "x": 6,
      "y": 0,
      "z": 10,
      "name": "Rock_Sandstone"
    },
    {
      "x": 6,
      "y": 1,
      "z": 10,
      "name": "Rock_Sandstone"
    },
    {
      "x": 6,
      "y": 2,
      "z": 10,
      "name": "Rock_Sandstone"
    },
    {
      "x": 6,
      "y": 3,
      "z": 10,
      "name": "Rock_Sandstone"
    },
    {
      "x": 6,
      "y": 4,
      "z": 10,
      "name": "Rock_Sandstone_White"
    },
    {
      "x": 6,
      "y": 0,
      "z": 11,
      "name": "Rock_Sandstone"
    },
    {
      "x": 6,
      "y": 1,
      "z": 11,
      "name": "Rock_Sandstone"
    },
    {
      "x": 6,
      "y": 2,
      "z": 11,
      "name": "Rock_Sandstone"
    },
    {
      "x": 6,
      "y": 3,
      "z": 11,
      "name": "Soil_Sand_White"
    },
    {
      "x": 7,
      "y": 0,
      "z": 0,
      "name": "Rock_Sandstone"
    },
    {
      "x": 7,
      "y": 1,
      "z": 0,
      "name": "Rock_Sandstone"
    },
    {
      "x": 7,
      "y": 2,
      "z": 0,
      "name": "Rock_Sandstone"
    },
    {
      "x": 7,
      "y": 3,
      "z": 0,
      "name": "Rock_Sandstone"
    },
    {
      "x": 7,
      "y": 0,
      "z": 1,
      "name": "Rock_Sandstone"
    },
    {
      "x": 7,
      "y": 1,
      "z": 1,
      "name": "Rock_Sandstone"
    },
    {
      "x": 7,
      "y": 2,
      "z": 1,
      "name": "Rock_Sandstone"
    },
    {
      "x": 7,
      "y": 3,
      "z": 1,
      "name": "Rock_Sandstone"
    },
    {
      "x": 7,
      "y": 4,
      "z": 1,
      "name": "Rock_Sandstone_White"
    },
    {
      "x": 7,
      "y": 0,
      "z": 2,
      "name": "Rock_Sandstone"
    },
    {
      "x": 7,
      "y": 1,
      "z": 2,
      "name": "Rock_Sandstone"
    },
    {
      "x": 7,
      "y": 2,
      "z": 2,
      "name": "Rock_Sandstone"
    },
    {
      "x": 7,
      "y": 3,
      "z": 2,
      "name": "Soil_Sand_White"
    },
    {
      "x": 7,
      "y": 0,
      "z": 3,
      "name": "Rock_Sandstone"
    },
    {
      "x": 7,
      "y": 1,
      "z": 3,
      "name": "Rock_Sandstone"
    },
    {
      "x": 7,
      "y": 2,
      "z": 3,
      "name": "Rock_Sandstone"
    },
    {
      "x": 7,
      "y": 3,
      "z": 3,
      "name": "Soil_Sand_White"
    },
    {
      "x": 7,
      "y": 0,
      "z": 4,
      "name": "Rock_Sandstone"
    },
    {
      "x": 7,
      "y": 1,
      "z": 4,
      "name": "Rock_Sandstone"
    },
    {
      "x": 7,
      "y": 2,
      "z": 4,
      "name": "Rock_Sandstone"
    },
    {
      "x": 7,
      "y": 3,
      "z": 4,
      "name": "Soil_Sand_White"
    },
    {
      "x": 7,
      "y": 0,
      "z": 5,
      "name": "Rock_Sandstone"
    },
    {
      "x": 7,
      "y": 1,
      "z": 5,
      "name": "Rock_Sandstone"
    },
    {
      "x": 7,
      "y": 2,
      "z": 5,
      "name": "Rock_Sandstone"
    },
    {
      "x": 7,
      "y": 3,
      "z": 5,
      "name": "Soil_Sand_White"
    },
    {
      "x": 7,
      "y": 0,
      "z": 6,
      "name": "Rock_Sandstone"
    },
    {
      "x": 7,
      "y": 1,
      "z": 6,
      "name": "Rock_Sandstone"
    },
    {
      "x": 7,
      "y": 2,
      "z": 6,
      "name": "Rock_Sandstone"
    },
    {
      "x": 7,
      "y": 3,
      "z": 6,
      "name": "Soil_Sand_White"
    },
    {
      "x": 7,
      "y": 0,
      "z": 7,
      "name": "Rock_Sandstone"
    },
    {
      "x": 7,
      "y": 1,
      "z": 7,
      "name": "Rock_Sandstone"
    },
    {
      "x": 7,
      "y": 2,
      "z": 7,
      "name": "Rock_Sandstone"
    },
    {
      "x": 7,
      "y": 3,
      "z": 7,
      "name": "Soil_Sand_White"
    },
    {
      "x": 7,
      "y": 0,
      "z": 8,
      "name": "Rock_Sandstone"
    },
    {
      "x": 7,
      "y": 1,
      "z": 8,
      "name": "Rock_Sandstone"
    },
    {
      "x": 7,
      "y": 2,
      "z": 8,
      "name": "Rock_Sandstone"
    },
    {
      "x": 7,
      "y": 3,
      "z": 8,
      "name": "Rock_Sandstone"
    },
    {
      "x": 7,
      "y": 4,
      "z": 8,
      "name": "Rock_Sandstone"
    },
    {
      "x": 7,
      "y": 5,
      "z": 8,
      "name": "Soil_Dirt_Dry"
    },
    {
      "x": 7,
      "y": 0,
      "z": 9,
      "name": "Rock_Sandstone"
    },
    {
      "x": 7,
      "y": 1,
      "z": 9,
      "name": "Rock_Sandstone"
    },
    {
      "x": 7,
      "y": 2,
      "z": 9,
      "name": "Rock_Sandstone"
    },
    {
      "x": 7,
      "y": 3,
      "z": 9,
      "name": "Rock_Sandstone"
    },
    {
      "x": 7,
      "y": 4,
      "z": 9,
      "name": "Rock_Sandstone"
    },
    {
      "x": 7,
      "y": 5,
      "z": 9,
      "name": "Soil_Dirt_Dry"
    },
    {
      "x": 7,
      "y": 6,
      "z": 9,
      "name": "Rock_Sandstone_White"
    },
    {
      "x": 7,
      "y": 0,
      "z": 10,
      "name": "Rock_Sandstone"
    },
    {
      "x": 7,
      "y": 1,
      "z": 10,
      "name": "Rock_Sandstone"
    },
    {
      "x": 7,
      "y": 2,
      "z": 10,
      "name": "Rock_Sandstone"
    },
    {
      "x": 7,
      "y": 3,
      "z": 10,
      "name": "Rock_Sandstone"
    },
    {
      "x": 7,
      "y": 4,
      "z": 10,
      "name": "Rock_Sandstone"
    },
    {
      "x": 7,
      "y": 5,
      "z": 10,
      "name": "Soil_Dirt_Dry"
    },
    {
      "x": 7,
      "y": 6,
      "z": 10,
      "name": "Rock_Sandstone_White"
    },
    {
      "x": 7,
      "y": 0,
      "z": 11,
      "name": "Rock_Sandstone"
    },
    {
      "x": 7,
      "y": 1,
      "z": 11,
      "name": "Rock_Sandstone"
    },
    {
      "x": 7,
      "y": 2,
      "z": 11,
      "name": "Rock_Sandstone"
    },
    {
      "x": 7,
      "y": 3,
      "z": 11,
      "name": "Soil_Sand_White"
    },
    {
      "x": 8,
      "y": 0,
      "z": 1,
      "name": "Rock_Sandstone"
    },
    {
      "x": 8,
      "y": 1,
      "z": 1,
      "name": "Rock_Sandstone"
    },
    {
      "x": 8,
      "y": 2,
      "z": 1,
      "name": "Rock_Sandstone"
    },
    {
      "x": 8,
      "y": 3,
      "z": 1,
      "name": "Rock_Sandstone"
    },
    {
      "x": 8,
      "y": 4,
      "z": 1,
      "name": "Rock_Sandstone_White"
    },
    {
      "x": 8,
      "y": 0,
      "z": 2,
      "name": "Rock_Sandstone"
    },
    {
      "x": 8,
      "y": 1,
      "z": 2,
      "name": "Rock_Sandstone"
    },
    {
      "x": 8,
      "y": 2,
      "z": 2,
      "name": "Rock_Sandstone"
    },
    {
      "x": 8,
      "y": 3,
      "z": 2,
      "name": "Soil_Sand_White"
    },
    {
      "x": 8,
      "y": 0,
      "z": 3,
      "name": "Rock_Sandstone"
    },
    {
      "x": 8,
      "y": 1,
      "z": 3,
      "name": "Rock_Sandstone"
    },
    {
      "x": 8,
      "y": 2,
      "z": 3,
      "name": "Rock_Sandstone"
    },
    {
      "x": 8,
      "y": 3,
      "z": 3,
      "name": "Soil_Sand_White"
    },
    {
      "x": 8,
      "y": 0,
      "z": 4,
      "name": "Rock_Sandstone"
    },
    {
      "x": 8,
      "y": 1,
      "z": 4,
      "name": "Rock_Sandstone"
    },
    {
      "x": 8,
      "y": 2,
      "z": 4,
      "name": "Rock_Sandstone"
    },
    {
      "x": 8,
      "y": 3,
      "z": 4,
      "name": "Soil_Sand_White"
    },
    {
      "x": 8,
      "y": 0,
      "z": 5,
      "name": "Rock_Sandstone"
    },
    {
      "x": 8,
      "y": 1,
      "z": 5,
      "name": "Rock_Sandstone"
    },
    {
      "x": 8,
      "y": 2,
      "z": 5,
      "name": "Rock_Sandstone"
    },
    {
      "x": 8,
      "y": 3,
      "z": 5,
      "name": "Soil_Sand_White"
    },
    {
      "x": 8,
      "y": 0,
      "z": 6,
      "name": "Rock_Sandstone"
    },
    {
      "x": 8,
      "y": 1,
      "z": 6,
      "name": "Rock_Sandstone"
    },
    {
      "x": 8,
      "y": 2,
      "z": 6,
      "name": "Rock_Sandstone"
    },
    {
      "x": 8,
      "y": 3,
      "z": 6,
      "name": "Rock_Sandstone"
    },
    {
      "x": 8,
      "y": 4,
      "z": 6,
      "name": "Rock_Sandstone"
    },
    {
      "x": 8,
      "y": 5,
      "z": 6,
      "name": "Soil_Dirt_Dry"
    },
    {
      "x": 8,
      "y": 0,
      "z": 7,
      "name": "Rock_Sandstone"
    },
    {
      "x": 8,
      "y": 1,
      "z": 7,
      "name": "Rock_Sandstone"
    },
    {
      "x": 8,
      "y": 2,
      "z": 7,
      "name": "Rock_Sandstone"
    },
    {
      "x": 8,
      "y": 3,
      "z": 7,
      "name": "Rock_Sandstone"
    },
    {
      "x": 8,
      "y": 4,
      "z": 7,
      "name": "Rock_Sandstone"
    },
    {
      "x": 8,
      "y": 5,
      "z": 7,
      "name": "Soil_Dirt_Dry"
    },
    {
      "x": 8,
      "y": 6,
      "z": 7,
      "name": "Rock_Sandstone_White"
    },
    {
      "x": 8,
      "y": 0,
      "z": 8,
      "name": "Rock_Sandstone"
    },
    {
      "x": 8,
      "y": 1,
      "z": 8,
      "name": "Rock_Sandstone"
    },
    {
      "x": 8,
      "y": 2,
      "z": 8,
      "name": "Rock_Sandstone"
    },
    {
      "x": 8,
      "y": 3,
      "z": 8,
      "name": "Rock_Sandstone"
    },
    {
      "x": 8,
      "y": 4,
      "z": 8,
      "name": "Rock_Sandstone"
    },
    {
      "x": 8,
      "y": 5,
      "z": 8,
      "name": "Rock_Sandstone"
    },
    {
      "x": 8,
      "y": 6,
      "z": 8,
      "name": "Rock_Sandstone_White"
    },
    {
      "x": 8,
      "y": 0,
      "z": 9,
      "name": "Rock_Sandstone"
    },
    {
      "x": 8,
      "y": 1,
      "z": 9,
      "name": "Rock_Sandstone"
    },
    {
      "x": 8,
      "y": 2,
      "z": 9,
      "name": "Rock_Sandstone"
    },
    {
      "x": 8,
      "y": 3,
      "z": 9,
      "name": "Rock_Sandstone"
    },
    {
      "x": 8,
      "y": 4,
      "z": 9,
      "name": "Rock_Sandstone"
    },
    {
      "x": 8,
      "y": 5,
      "z": 9,
      "name": "Soil_Sand_White"
    },
    {
      "x": 8,
      "y": 0,
      "z": 10,
      "name": "Rock_Sandstone"
    },
    {
      "x": 8,
      "y": 1,
      "z": 10,
      "name": "Rock_Sandstone"
    },
    {
      "x": 8,
      "y": 2,
      "z": 10,
      "name": "Rock_Sandstone"
    },
    {
      "x": 8,
      "y": 3,
      "z": 10,
      "name": "Rock_Sandstone"
    },
    {
      "x": 8,
      "y": 4,
      "z": 10,
      "name": "Rock_Sandstone"
    },
    {
      "x": 8,
      "y": 5,
      "z": 10,
      "name": "Soil_Sand_White"
    },
    {
      "x": 8,
      "y": 0,
      "z": 11,
      "name": "Rock_Sandstone"
    },
    {
      "x": 8,
      "y": 1,
      "z": 11,
      "name": "Rock_Sandstone"
    },
    {
      "x": 8,
      "y": 2,
      "z": 11,
      "name": "Rock_Sandstone"
    },
    {
      "x": 8,
      "y": 3,
      "z": 11,
      "name": "Rock_Sandstone"
    },
    {
      "x": 8,
      "y": 4,
      "z": 11,
      "name": "Rock_Sandstone"
    },
    {
      "x": 8,
      "y": 5,
      "z": 11,
      "name": "Soil_Dirt_Dry"
    },
    {
      "x": 8,
      "y": 6,
      "z": 11,
      "name": "Rock_Sandstone_White"
    },
    {
      "x": 8,
      "y": 0,
      "z": 12,
      "name": "Rock_Sandstone"
    },
    {
      "x": 8,
      "y": 1,
      "z": 12,
      "name": "Rock_Sandstone"
    },
    {
      "x": 8,
      "y": 2,
      "z": 12,
      "name": "Rock_Sandstone"
    },
    {
      "x": 8,
      "y": 3,
      "z": 12,
      "name": "Rock_Sandstone"
    },
    {
      "x": 8,
      "y": 4,
      "z": 12,
      "name": "Rock_Sandstone"
    },
    {
      "x": 9,
      "y": 0,
      "z": 1,
      "name": "Rock_Sandstone"
    },
    {
      "x": 9,
      "y": 1,
      "z": 1,
      "name": "Rock_Sandstone"
    },
    {
      "x": 9,
      "y": 2,
      "z": 1,
      "name": "Rock_Sandstone"
    },
    {
      "x": 9,
      "y": 0,
      "z": 2,
      "name": "Rock_Sandstone"
    },
    {
      "x": 9,
      "y": 1,
      "z": 2,
      "name": "Rock_Sandstone"
    },
    {
      "x": 9,
      "y": 2,
      "z": 2,
      "name": "Rock_Sandstone"
    },
    {
      "x": 9,
      "y": 3,
      "z": 2,
      "name": "Rock_Sandstone"
    },
    {
      "x": 9,
      "y": 4,
      "z": 2,
      "name": "Rock_Sandstone_White"
    },
    {
      "x": 9,
      "y": 0,
      "z": 3,
      "name": "Rock_Sandstone"
    },
    {
      "x": 9,
      "y": 1,
      "z": 3,
      "name": "Rock_Sandstone"
    },
    {
      "x": 9,
      "y": 2,
      "z": 3,
      "name": "Rock_Sandstone"
    },
    {
      "x": 9,
      "y": 3,
      "z": 3,
      "name": "Rock_Sandstone"
    },
    {
      "x": 9,
      "y": 4,
      "z": 3,
      "name": "Rock_Sandstone_White"
    },
    {
      "x": 9,
      "y": 0,
      "z": 4,
      "name": "Rock_Sandstone"
    },
    {
      "x": 9,
      "y": 1,
      "z": 4,
      "name": "Rock_Sandstone"
    },
    {
      "x": 9,
      "y": 2,
      "z": 4,
      "name": "Rock_Sandstone"
    },
    {
      "x": 9,
      "y": 3,
      "z": 4,
      "name": "Rock_Sandstone"
    },
    {
      "x": 9,
      "y": 4,
      "z": 4,
      "name": "Rock_Sandstone_White"
    },
    {
      "x": 9,
      "y": 0,
      "z": 5,
      "name": "Rock_Sandstone"
    },
    {
      "x": 9,
      "y": 1,
      "z": 5,
      "name": "Rock_Sandstone"
    },
    {
      "x": 9,
      "y": 2,
      "z": 5,
      "name": "Rock_Sandstone"
    },
    {
      "x": 9,
      "y": 3,
      "z": 5,
      "name": "Rock_Sandstone"
    },
    {
      "x": 9,
      "y": 4,
      "z": 5,
      "name": "Rock_Sandstone_White"
    },
    {
      "x": 9,
      "y": 0,
      "z": 6,
      "name": "Rock_Sandstone"
    },
    {
      "x": 9,
      "y": 1,
      "z": 6,
      "name": "Rock_Sandstone"
    },
    {
      "x": 9,
      "y": 2,
      "z": 6,
      "name": "Rock_Sandstone"
    },
    {
      "x": 9,
      "y": 3,
      "z": 6,
      "name": "Rock_Sandstone"
    },
    {
      "x": 9,
      "y": 4,
      "z": 6,
      "name": "Rock_Sandstone"
    },
    {
      "x": 9,
      "y": 5,
      "z": 6,
      "name": "Soil_Dirt_Dry"
    },
    {
      "x": 9,
      "y": 6,
      "z": 6,
      "name": "Rock_Sandstone_White"
    },
    {
      "x": 9,
      "y": 0,
      "z": 7,
      "name": "Rock_Sandstone"
    },
    {
      "x": 9,
      "y": 1,
      "z": 7,
      "name": "Rock_Sandstone"
    },
    {
      "x": 9,
      "y": 2,
      "z": 7,
      "name": "Rock_Sandstone"
    },
    {
      "x": 9,
      "y": 3,
      "z": 7,
      "name": "Rock_Sandstone"
    },
    {
      "x": 9,
      "y": 4,
      "z": 7,
      "name": "Rock_Sandstone"
    },
    {
      "x": 9,
      "y": 5,
      "z": 7,
      "name": "Soil_Sand_White"
    },
    {
      "x": 9,
      "y": 0,
      "z": 8,
      "name": "Rock_Sandstone"
    },
    {
      "x": 9,
      "y": 1,
      "z": 8,
      "name": "Rock_Sandstone"
    },
    {
      "x": 9,
      "y": 2,
      "z": 8,
      "name": "Rock_Sandstone"
    },
    {
      "x": 9,
      "y": 3,
      "z": 8,
      "name": "Rock_Sandstone"
    },
    {
      "x": 9,
      "y": 4,
      "z": 8,
      "name": "Rock_Sandstone"
    },
    {
      "x": 9,
      "y": 5,
      "z": 8,
      "name": "Soil_Sand_White"
    },
    {
      "x": 9,
      "y": 0,
      "z": 9,
      "name": "Rock_Sandstone"
    },
    {
      "x": 9,
      "y": 1,
      "z": 9,
      "name": "Rock_Sandstone"
    },
    {
      "x": 9,
      "y": 2,
      "z": 9,
      "name": "Rock_Sandstone"
    },
    {
      "x": 9,
      "y": 3,
      "z": 9,
      "name": "Rock_Sandstone"
    },
    {
      "x": 9,
      "y": 4,
      "z": 9,
      "name": "Rock_Sandstone"
    },
    {
      "x": 9,
      "y": 5,
      "z": 9,
      "name": "Soil_Sand_White"
    },
    {
      "x": 9,
      "y": 0,
      "z": 10,
      "name": "Rock_Sandstone"
    },
    {
      "x": 9,
      "y": 1,
      "z": 10,
      "name": "Rock_Sandstone"
    },
    {
      "x": 9,
      "y": 2,
      "z": 10,
      "name": "Rock_Sandstone"
    },
    {
      "x": 9,
      "y": 3,
      "z": 10,
      "name": "Rock_Sandstone"
    },
    {
      "x": 9,
      "y": 4,
      "z": 10,
      "name": "Rock_Sandstone"
    },
    {
      "x": 9,
      "y": 5,
      "z": 10,
      "name": "Soil_Sand_White"
    },
    {
      "x": 9,
      "y": 0,
      "z": 11,
      "name": "Rock_Sandstone"
    },
    {
      "x": 9,
      "y": 1,
      "z": 11,
      "name": "Rock_Sandstone"
    },
    {
      "x": 9,
      "y": 2,
      "z": 11,
      "name": "Rock_Sandstone"
    },
    {
      "x": 9,
      "y": 3,
      "z": 11,
      "name": "Rock_Sandstone"
    },
    {
      "x": 9,
      "y": 4,
      "z": 11,
      "name": "Rock_Sandstone"
    },
    {
      "x": 9,
      "y": 5,
      "z": 11,
      "name": "Soil_Sand_White"
    },
    {
      "x": 9,
      "y": 0,
      "z": 12,
      "name": "Rock_Sandstone"
    },
    {
      "x": 9,
      "y": 1,
      "z": 12,
      "name": "Rock_Sandstone"
    },
    {
      "x": 9,
      "y": 2,
      "z": 12,
      "name": "Rock_Sandstone"
    },
    {
      "x": 9,
      "y": 3,
      "z": 12,
      "name": "Rock_Sandstone"
    },
    {
      "x": 9,
      "y": 4,
      "z": 12,
      "name": "Rock_Sandstone"
    },
    {
      "x": 9,
      "y": 5,
      "z": 12,
      "name": "Soil_Dirt_Dry"
    },
    {
      "x": 9,
      "y": 6,
      "z": 12,
      "name": "Rock_Sandstone_White"
    },
    {
      "x": 9,
      "y": 0,
      "z": 13,
      "name": "Rock_Sandstone"
    },
    {
      "x": 9,
      "y": 1,
      "z": 13,
      "name": "Rock_Sandstone"
    },
    {
      "x": 9,
      "y": 2,
      "z": 13,
      "name": "Rock_Sandstone"
    },
    {
      "x": 9,
      "y": 3,
      "z": 13,
      "name": "Soil_Sand_White"
    },
    {
      "x": 10,
      "y": 0,
      "z": 2,
      "name": "Rock_Sandstone"
    },
    {
      "x": 10,
      "y": 1,
      "z": 2,
      "name": "Rock_Sandstone"
    },
    {
      "x": 10,
      "y": 2,
      "z": 2,
      "name": "Soil_Sand_White"
    },
    {
      "x": 10,
      "y": 0,
      "z": 3,
      "name": "Rock_Sandstone"
    },
    {
      "x": 10,
      "y": 1,
      "z": 3,
      "name": "Rock_Sandstone"
    },
    {
      "x": 10,
      "y": 2,
      "z": 3,
      "name": "Rock_Sandstone"
    },
    {
      "x": 10,
      "y": 3,
      "z": 3,
      "name": "Soil_Sand_White"
    },
    {
      "x": 10,
      "y": 0,
      "z": 4,
      "name": "Rock_Sandstone"
    },
    {
      "x": 10,
      "y": 1,
      "z": 4,
      "name": "Rock_Sandstone"
    },
    {
      "x": 10,
      "y": 2,
      "z": 4,
      "name": "Rock_Sandstone"
    },
    {
      "x": 10,
      "y": 3,
      "z": 4,
      "name": "Soil_Sand_White"
    },
    {
      "x": 10,
      "y": 0,
      "z": 5,
      "name": "Rock_Sandstone"
    },
    {
      "x": 10,
      "y": 1,
      "z": 5,
      "name": "Rock_Sandstone"
    },
    {
      "x": 10,
      "y": 2,
      "z": 5,
      "name": "Rock_Sandstone"
    },
    {
      "x": 10,
      "y": 3,
      "z": 5,
      "name": "Rock_Sandstone"
    },
    {
      "x": 10,
      "y": 4,
      "z": 5,
      "name": "Rock_Sandstone"
    },
    {
      "x": 10,
      "y": 0,
      "z": 6,
      "name": "Rock_Sandstone"
    },
    {
      "x": 10,
      "y": 1,
      "z": 6,
      "name": "Rock_Sandstone"
    },
    {
      "x": 10,
      "y": 2,
      "z": 6,
      "name": "Rock_Sandstone"
    },
    {
      "x": 10,
      "y": 3,
      "z": 6,
      "name": "Rock_Sandstone"
    },
    {
      "x": 10,
      "y": 4,
      "z": 6,
      "name": "Rock_Sandstone"
    },
    {
      "x": 10,
      "y": 5,
      "z": 6,
      "name": "Soil_Dirt_Dry"
    },
    {
      "x": 10,
      "y": 6,
      "z": 6,
      "name": "Rock_Sandstone_White"
    },
    {
      "x": 10,
      "y": 0,
      "z": 7,
      "name": "Rock_Sandstone"
    },
    {
      "x": 10,
      "y": 1,
      "z": 7,
      "name": "Rock_Sandstone"
    },
    {
      "x": 10,
      "y": 2,
      "z": 7,
      "name": "Rock_Sandstone"
    },
    {
      "x": 10,
      "y": 3,
      "z": 7,
      "name": "Rock_Sandstone"
    },
    {
      "x": 10,
      "y": 4,
      "z": 7,
      "name": "Rock_Sandstone"
    },
    {
      "x": 10,
      "y": 5,
      "z": 7,
      "name": "Soil_Sand_White"
    },
    {
      "x": 10,
      "y": 0,
      "z": 8,
      "name": "Rock_Sandstone"
    },
    {
      "x": 10,
      "y": 1,
      "z": 8,
      "name": "Rock_Sandstone"
    },
    {
      "x": 10,
      "y": 2,
      "z": 8,
      "name": "Rock_Sandstone"
    },
    {
      "x": 10,
      "y": 3,
      "z": 8,
      "name": "Rock_Sandstone"
    },
    {
      "x": 10,
      "y": 4,
      "z": 8,
      "name": "Rock_Sandstone"
    },
    {
      "x": 10,
      "y": 5,
      "z": 8,
      "name": "Soil_Sand_White"
    },
    {
      "x": 10,
      "y": 0,
      "z": 9,
      "name": "Rock_Sandstone"
    },
    {
      "x": 10,
      "y": 1,
      "z": 9,
      "name": "Rock_Sandstone"
    },
    {
      "x": 10,
      "y": 2,
      "z": 9,
      "name": "Rock_Sandstone"
    },
    {
      "x": 10,
      "y": 3,
      "z": 9,
      "name": "Rock_Sandstone"
    },
    {
      "x": 10,
      "y": 4,
      "z": 9,
      "name": "Rock_Sandstone"
    },
    {
      "x": 10,
      "y": 5,
      "z": 9,
      "name": "Soil_Sand_White"
    },
    {
      "x": 10,
      "y": 0,
      "z": 10,
      "name": "Rock_Sandstone"
    },
    {
      "x": 10,
      "y": 1,
      "z": 10,
      "name": "Rock_Sandstone"
    },
    {
      "x": 10,
      "y": 2,
      "z": 10,
      "name": "Rock_Sandstone"
    },
    {
      "x": 10,
      "y": 3,
      "z": 10,
      "name": "Rock_Sandstone"
    },
    {
      "x": 10,
      "y": 4,
      "z": 10,
      "name": "Rock_Sandstone"
    },
    {
      "x": 10,
      "y": 5,
      "z": 10,
      "name": "Soil_Sand_White"
    },
    {
      "x": 10,
      "y": 0,
      "z": 11,
      "name": "Rock_Sandstone"
    },
    {
      "x": 10,
      "y": 1,
      "z": 11,
      "name": "Rock_Sandstone"
    },
    {
      "x": 10,
      "y": 2,
      "z": 11,
      "name": "Rock_Sandstone"
    },
    {
      "x": 10,
      "y": 3,
      "z": 11,
      "name": "Rock_Sandstone"
    },
    {
      "x": 10,
      "y": 4,
      "z": 11,
      "name": "Rock_Sandstone"
    },
    {
      "x": 10,
      "y": 5,
      "z": 11,
      "name": "Soil_Sand_White"
    },
    {
      "x": 10,
      "y": 0,
      "z": 12,
      "name": "Rock_Sandstone"
    },
    {
      "x": 10,
      "y": 1,
      "z": 12,
      "name": "Rock_Sandstone"
    },
    {
      "x": 10,
      "y": 2,
      "z": 12,
      "name": "Rock_Sandstone"
    },
    {
      "x": 10,
      "y": 3,
      "z": 12,
      "name": "Rock_Sandstone"
    },
    {
      "x": 10,
      "y": 4,
      "z": 12,
      "name": "Rock_Sandstone"
    },
    {
      "x": 10,
      "y": 5,
      "z": 12,
      "name": "Soil_Dirt_Dry"
    },
    {
      "x": 10,
      "y": 6,
      "z": 12,
      "name": "Rock_Sandstone_White"
    },
    {
      "x": 10,
      "y": 0,
      "z": 13,
      "name": "Rock_Sandstone"
    },
    {
      "x": 10,
      "y": 1,
      "z": 13,
      "name": "Rock_Sandstone"
    },
    {
      "x": 10,
      "y": 2,
      "z": 13,
      "name": "Rock_Sandstone"
    },
    {
      "x": 10,
      "y": 3,
      "z": 13,
      "name": "Soil_Sand_White"
    },
    {
      "x": 11,
      "y": 0,
      "z": 5,
      "name": "Rock_Sandstone"
    },
    {
      "x": 11,
      "y": 1,
      "z": 5,
      "name": "Rock_Sandstone"
    },
    {
      "x": 11,
      "y": 2,
      "z": 5,
      "name": "Rock_Sandstone"
    },
    {
      "x": 11,
      "y": 3,
      "z": 5,
      "name": "Soil_Sand_White"
    },
    {
      "x": 11,
      "y": 0,
      "z": 6,
      "name": "Rock_Sandstone"
    },
    {
      "x": 11,
      "y": 1,
      "z": 6,
      "name": "Rock_Sandstone"
    },
    {
      "x": 11,
      "y": 2,
      "z": 6,
      "name": "Rock_Sandstone"
    },
    {
      "x": 11,
      "y": 3,
      "z": 6,
      "name": "Rock_Sandstone"
    },
    {
      "x": 11,
      "y": 4,
      "z": 6,
      "name": "Rock_Sandstone"
    },
    {
      "x": 11,
      "y": 5,
      "z": 6,
      "name": "Soil_Dirt_Dry"
    },
    {
      "x": 11,
      "y": 6,
      "z": 6,
      "name": "Rock_Sandstone_White"
    },
    {
      "x": 11,
      "y": 0,
      "z": 7,
      "name": "Rock_Sandstone"
    },
    {
      "x": 11,
      "y": 1,
      "z": 7,
      "name": "Rock_Sandstone"
    },
    {
      "x": 11,
      "y": 2,
      "z": 7,
      "name": "Rock_Sandstone"
    },
    {
      "x": 11,
      "y": 3,
      "z": 7,
      "name": "Rock_Sandstone"
    },
    {
      "x": 11,
      "y": 4,
      "z": 7,
      "name": "Rock_Sandstone"
    },
    {
      "x": 11,
      "y": 5,
      "z": 7,
      "name": "Soil_Sand_White"
    },
    {
      "x": 11,
      "y": 0,
      "z": 8,
      "name": "Rock_Sandstone"
    },
    {
      "x": 11,
      "y": 1,
      "z": 8,
      "name": "Rock_Sandstone"
    },
    {
      "x": 11,
      "y": 2,
      "z": 8,
      "name": "Rock_Sandstone"
    },
    {
      "x": 11,
      "y": 3,
      "z": 8,
      "name": "Rock_Sandstone"
    },
    {
      "x": 11,
      "y": 4,
      "z": 8,
      "name": "Rock_Sandstone"
    },
    {
      "x": 11,
      "y": 5,
      "z": 8,
      "name": "Soil_Sand_White"
    },
    {
      "x": 11,
      "y": 0,
      "z": 9,
      "name": "Rock_Sandstone"
    },
    {
      "x": 11,
      "y": 1,
      "z": 9,
      "name": "Rock_Sandstone"
    },
    {
      "x": 11,
      "y": 2,
      "z": 9,
      "name": "Rock_Sandstone"
    },
    {
      "x": 11,
      "y": 3,
      "z": 9,
      "name": "Rock_Sandstone"
    },
    {
      "x": 11,
      "y": 4,
      "z": 9,
      "name": "Rock_Sandstone"
    },
    {
      "x": 11,
      "y": 5,
      "z": 9,
      "name": "Soil_Sand_White"
    },
    {
      "x": 11,
      "y": 0,
      "z": 10,
      "name": "Rock_Sandstone"
    },
    {
      "x": 11,
      "y": 1,
      "z": 10,
      "name": "Rock_Sandstone"
    },
    {
      "x": 11,
      "y": 2,
      "z": 10,
      "name": "Rock_Sandstone"
    },
    {
      "x": 11,
      "y": 3,
      "z": 10,
      "name": "Rock_Sandstone"
    },
    {
      "x": 11,
      "y": 4,
      "z": 10,
      "name": "Rock_Sandstone"
    },
    {
      "x": 11,
      "y": 5,
      "z": 10,
      "name": "Soil_Sand_White"
    },
    {
      "x": 11,
      "y": 0,
      "z": 11,
      "name": "Rock_Sandstone"
    },
    {
      "x": 11,
      "y": 1,
      "z": 11,
      "name": "Rock_Sandstone"
    },
    {
      "x": 11,
      "y": 2,
      "z": 11,
      "name": "Rock_Sandstone"
    },
    {
      "x": 11,
      "y": 3,
      "z": 11,
      "name": "Rock_Sandstone"
    },
    {
      "x": 11,
      "y": 4,
      "z": 11,
      "name": "Soil_Dirt_Dry"
    },
    {
      "x": 11,
      "y": 5,
      "z": 11,
      "name": "Soil_Dirt_Dry"
    },
    {
      "x": 11,
      "y": 6,
      "z": 11,
      "name": "Rock_Sandstone_White"
    },
    {
      "x": 11,
      "y": 0,
      "z": 12,
      "name": "Rock_Sandstone"
    },
    {
      "x": 11,
      "y": 1,
      "z": 12,
      "name": "Rock_Sandstone"
    },
    {
      "x": 11,
      "y": 2,
      "z": 12,
      "name": "Rock_Sandstone"
    },
    {
      "x": 11,
      "y": 3,
      "z": 12,
      "name": "Soil_Sand_White"
    },
    {
      "x": 11,
      "y": 4,
      "z": 12,
      "name": "Soil_Sand_White"
    },
    {
      "x": 12,
      "y": 0,
      "z": 6,
      "name": "Rock_Sandstone"
    },
    {
      "x": 12,
      "y": 1,
      "z": 6,
      "name": "Rock_Sandstone"
    },
    {
      "x": 12,
      "y": 2,
      "z": 6,
      "name": "Soil_Sand_White"
    },
    {
      "x": 12,
      "y": 3,
      "z": 6,
      "name": "Soil_Sand_White"
    },
    {
      "x": 12,
      "y": 4,
      "z": 6,
      "name": "Rock_Sandstone"
    },
    {
      "x": 12,
      "y": 0,
      "z": 7,
      "name": "Rock_Sandstone"
    },
    {
      "x": 12,
      "y": 1,
      "z": 7,
      "name": "Rock_Sandstone"
    },
    {
      "x": 12,
      "y": 2,
      "z": 7,
      "name": "Soil_Sand_White"
    },
    {
      "x": 12,
      "y": 3,
      "z": 7,
      "name": "Soil_Sand_White"
    },
    {
      "x": 12,
      "y": 4,
      "z": 7,
      "name": "Rock_Sandstone"
    },
    {
      "x": 12,
      "y": 5,
      "z": 7,
      "name": "Soil_Dirt_Dry"
    },
    {
      "x": 12,
      "y": 6,
      "z": 7,
      "name": "Rock_Sandstone_White"
    },
    {
      "x": 12,
      "y": 0,
      "z": 8,
      "name": "Rock_Sandstone"
    },
    {
      "x": 12,
      "y": 1,
      "z": 8,
      "name": "Rock_Sandstone"
    },
    {
      "x": 12,
      "y": 2,
      "z": 8,
      "name": "Rock_Sandstone"
    },
    {
      "x": 12,
      "y": 3,
      "z": 8,
      "name": "Rock_Sandstone"
    },
    {
      "x": 12,
      "y": 4,
      "z": 8,
      "name": "Rock_Sandstone"
    },
    {
      "x": 12,
      "y": 5,
      "z": 8,
      "name": "Soil_Sand_White"
    },
    {
      "x": 12,
      "y": 0,
      "z": 9,
      "name": "Rock_Sandstone"
    },
    {
      "x": 12,
      "y": 1,
      "z": 9,
      "name": "Rock_Sandstone"
    },
    {
      "x": 12,
      "y": 2,
      "z": 9,
      "name": "Rock_Sandstone"
    },
    {
      "x": 12,
      "y": 3,
      "z": 9,
      "name": "Rock_Sandstone"
    },
    {
      "x": 12,
      "y": 4,
      "z": 9,
      "name": "Rock_Sandstone"
    },
    {
      "x": 12,
      "y": 5,
      "z": 9,
      "name": "Soil_Sand_White"
    },
    {
      "x": 12,
      "y": 0,
      "z": 10,
      "name": "Rock_Sandstone"
    },
    {
      "x": 12,
      "y": 1,
      "z": 10,
      "name": "Rock_Sandstone"
    },
    {
      "x": 12,
      "y": 2,
      "z": 10,
      "name": "Rock_Sandstone"
    },
    {
      "x": 12,
      "y": 3,
      "z": 10,
      "name": "Rock_Sandstone"
    },
    {
      "x": 12,
      "y": 4,
      "z": 10,
      "name": "Rock_Sandstone"
    },
    {
      "x": 12,
      "y": 5,
      "z": 10,
      "name": "Soil_Sand_White"
    },
    {
      "x": 12,
      "y": 0,
      "z": 11,
      "name": "Rock_Sandstone"
    },
    {
      "x": 12,
      "y": 1,
      "z": 11,
      "name": "Rock_Sandstone"
    },
    {
      "x": 12,
      "y": 2,
      "z": 11,
      "name": "Rock_Sandstone"
    },
    {
      "x": 12,
      "y": 3,
      "z": 11,
      "name": "Soil_Sand_White"
    },
    {
      "x": 12,
      "y": 4,
      "z": 11,
      "name": "Soil_Dirt_Dry"
    },
    {
      "x": 12,
      "y": 5,
      "z": 11,
      "name": "Soil_Dirt_Dry"
    },
    {
      "x": 12,
      "y": 6,
      "z": 11,
      "name": "Rock_Sandstone_White"
    },
    {
      "x": 12,
      "y": 0,
      "z": 12,
      "name": "Rock_Sandstone"
    },
    {
      "x": 12,
      "y": 1,
      "z": 12,
      "name": "Rock_Sandstone"
    },
    {
      "x": 12,
      "y": 2,
      "z": 12,
      "name": "Rock_Sandstone"
    },
    {
      "x": 12,
      "y": 3,
      "z": 12,
      "name": "Soil_Sand_White"
    },
    {
      "x": 13,
      "y": 1,
      "z": 7,
      "name": "Rock_Sandstone"
    },
    {
      "x": 13,
      "y": 2,
      "z": 7,
      "name": "Soil_Sand_White"
    },
    {
      "x": 13,
      "y": 3,
      "z": 7,
      "name": "Soil_Sand_White"
    },
    {
      "x": 13,
      "y": 0,
      "z": 8,
      "name": "Rock_Sandstone"
    },
    {
      "x": 13,
      "y": 1,
      "z": 8,
      "name": "Rock_Sandstone"
    },
    {
      "x": 13,
      "y": 2,
      "z": 8,
      "name": "Soil_Sand_White"
    },
    {
      "x": 13,
      "y": 3,
      "z": 8,
      "name": "Soil_Sand_White"
    },
    {
      "x": 13,
      "y": 4,
      "z": 8,
      "name": "Rock_Sandstone"
    },
    {
      "x": 13,
      "y": 5,
      "z": 8,
      "name": "Soil_Dirt_Dry"
    },
    {
      "x": 13,
      "y": 6,
      "z": 8,
      "name": "Rock_Sandstone_White"
    },
    {
      "x": 13,
      "y": 0,
      "z": 9,
      "name": "Rock_Sandstone"
    },
    {
      "x": 13,
      "y": 1,
      "z": 9,
      "name": "Rock_Sandstone"
    },
    {
      "x": 13,
      "y": 2,
      "z": 9,
      "name": "Soil_Sand_White"
    },
    {
      "x": 13,
      "y": 3,
      "z": 9,
      "name": "Soil_Sand_White"
    },
    {
      "x": 13,
      "y": 4,
      "z": 9,
      "name": "Soil_Dirt_Dry"
    },
    {
      "x": 13,
      "y": 5,
      "z": 9,
      "name": "Soil_Dirt_Dry"
    },
    {
      "x": 13,
      "y": 6,
      "z": 9,
      "name": "Rock_Sandstone_White"
    },
    {
      "x": 13,
      "y": 0,
      "z": 10,
      "name": "Rock_Sandstone"
    },
    {
      "x": 13,
      "y": 1,
      "z": 10,
      "name": "Rock_Sandstone"
    },
    {
      "x": 13,
      "y": 2,
      "z": 10,
      "name": "Rock_Sandstone"
    },
    {
      "x": 13,
      "y": 3,
      "z": 10,
      "name": "Rock_Sandstone"
    },
    {
      "x": 13,
      "y": 4,
      "z": 10,
      "name": "Soil_Dirt_Dry"
    },
    {
      "x": 13,
      "y": 5,
      "z": 10,
      "name": "Soil_Dirt_Dry"
    },
    {
      "x": 13,
      "y": 6,
      "z": 10,
      "name": "Rock_Sandstone_White"
    }
  ],
  "fluids": [
    {
      "x": 2,
      "y": 4,
      "z": 2,
      "name": "Water_Source",
      "level": 1
    },
    {
      "x": 2,
      "y": 4,
      "z": 3,
      "name": "Water_Source",
      "level": 1
    },
    {
      "x": 2,
      "y": 4,
      "z": 4,
      "name": "Water_Source",
      "level": 1
    },
    {
      "x": 2,
      "y": 4,
      "z": 5,
      "name": "Water_Source",
      "level": 1
    },
    {
      "x": 2,
      "y": 4,
      "z": 6,
      "name": "Water_Source",
      "level": 1
    },
    {
      "x": 2,
      "y": 4,
      "z": 7,
      "name": "Water_Source",
      "level": 1
    },
    {
      "x": 3,
      "y": 4,
      "z": 2,
      "name": "Water_Source",
      "level": 1
    },
    {
      "x": 3,
      "y": 4,
      "z": 3,
      "name": "Water_Source",
      "level": 1
    },
    {
      "x": 3,
      "y": 4,
      "z": 4,
      "name": "Water_Source",
      "level": 1
    },
    {
      "x": 3,
      "y": 4,
      "z": 5,
      "name": "Water_Source",
      "level": 1
    },
    {
      "x": 3,
      "y": 4,
      "z": 6,
      "name": "Water_Source",
      "level": 1
    },
    {
      "x": 3,
      "y": 4,
      "z": 7,
      "name": "Water_Source",
      "level": 1
    },
    {
      "x": 3,
      "y": 4,
      "z": 8,
      "name": "Water_Source",
      "level": 1
    },
    {
      "x": 4,
      "y": 4,
      "z": 1,
      "name": "Water_Source",
      "level": 1
    },
    {
      "x": 4,
      "y": 4,
      "z": 2,
      "name": "Water_Source",
      "level": 1
    },
    {
      "x": 4,
      "y": 4,
      "z": 3,
      "name": "Water_Source",
      "level": 1
    },
    {
      "x": 4,
      "y": 4,
      "z": 4,
      "name": "Water_Source",
      "level": 1
    },
    {
      "x": 4,
      "y": 4,
      "z": 5,
      "name": "Water_Source",
      "level": 1
    },
    {
      "x": 4,
      "y": 4,
      "z": 6,
      "name": "Water_Source",
      "level": 1
    },
    {
      "x": 4,
      "y": 4,
      "z": 7,
      "name": "Water_Source",
      "level": 1
    },
    {
      "x": 4,
      "y": 4,
      "z": 8,
      "name": "Water_Source",
      "level": 1
    },
    {
      "x": 5,
      "y": 4,
      "z": 1,
      "name": "Water_Source",
      "level": 1
    },
    {
      "x": 5,
      "y": 4,
      "z": 2,
      "name": "Water_Source",
      "level": 1
    },
    {
      "x": 5,
      "y": 4,
      "z": 3,
      "name": "Water_Source",
      "level": 1
    },
    {
      "x": 5,
      "y": 4,
      "z": 4,
      "name": "Water_Source",
      "level": 1
    },
    {
      "x": 5,
      "y": 4,
      "z": 5,
      "name": "Water_Source",
      "level": 1
    },
    {
      "x": 5,
      "y": 4,
      "z": 6,
      "name": "Water_Source",
      "level": 1
    },
    {
      "x": 5,
      "y": 4,
      "z": 7,
      "name": "Water_Source",
      "level": 1
    },
    {
      "x": 5,
      "y": 4,
      "z": 8,
      "name": "Water_Source",
      "level": 1
    },
    {
      "x": 5,
      "y": 4,
      "z": 9,
      "name": "Water_Source",
      "level": 1
    },
    {
      "x": 6,
      "y": 4,
      "z": 1,
      "name": "Water_Source",
      "level": 1
    },
    {
      "x": 6,
      "y": 4,
      "z": 2,
      "name": "Water_Source",
      "level": 1
    },
    {
      "x": 6,
      "y": 4,
      "z": 3,
      "name": "Water_Source",
      "level": 1
    },
    {
      "x": 6,
      "y": 4,
      "z": 4,
      "name": "Water_Source",
      "level": 1
    },
    {
      "x": 6,
      "y": 4,
      "z": 5,
      "name": "Water_Source",
      "level": 1
    },
    {
      "x": 6,
      "y": 4,
      "z": 6,
      "name": "Water_Source",
      "level": 1
    },
    {
      "x": 6,
      "y": 4,
      "z": 7,
      "name": "Water_Source",
      "level": 1
    },
    {
      "x": 6,
      "y": 4,
      "z": 8,
      "name": "Water_Source",
      "level": 1
    },
    {
      "x": 6,
      "y": 4,
      "z": 9,
      "name": "Water_Source",
      "level": 1
    },
    {
      "x": 7,
      "y": 4,
      "z": 2,
      "name": "Water_Source",
      "level": 1
    },
    {
      "x": 7,
      "y": 4,
      "z": 3,
      "name": "Water_Source",
      "level": 1
    },
    {
      "x": 7,
      "y": 4,
      "z": 4,
      "name": "Water_Source",
      "level": 1
    },
    {
      "x": 7,
      "y": 4,
      "z": 5,
      "name": "Water_Source",
      "level": 1
    },
    {
      "x": 7,
      "y": 4,
      "z": 6,
      "name": "Water_Source",
      "level": 1
    },
    {
      "x": 7,
      "y": 4,
      "z": 7,
      "name": "Water_Source",
      "level": 1
    },
    {
      "x": 8,
      "y": 4,
      "z": 2,
      "name": "Water_Source",
      "level": 1
    },
    {
      "x": 8,
      "y": 4,
      "z": 3,
      "name": "Water_Source",
      "level": 1
    },
    {
      "x": 8,
      "y": 4,
      "z": 4,
      "name": "Water_Source",
      "level": 1
    },
    {
      "x": 8,
      "y": 4,
      "z": 5,
      "name": "Water_Source",
      "level": 1
    },
    {
      "x": 8,
      "y": 6,
      "z": 9,
      "name": "Water_Source",
      "level": 1
    },
    {
      "x": 8,
      "y": 6,
      "z": 10,
      "name": "Water_Source",
      "level": 1
    },
    {
      "x": 9,
      "y": 6,
      "z": 7,
      "name": "Water_Source",
      "level": 1
    },
    {
      "x": 9,
      "y": 6,
      "z": 8,
      "name": "Water_Source",
      "level": 1
    },
    {
      "x": 9,
      "y": 6,
      "z": 9,
      "name": "Water_Source",
      "level": 1
    },
    {
      "x": 9,
      "y": 6,
      "z": 10,
      "name": "Water_Source",
      "level": 1
    },
    {
      "x": 9,
      "y": 6,
      "z": 11,
      "name": "Water_Source",
      "level": 1
    },
    {
      "x": 10,
      "y": 6,
      "z": 7,
      "name": "Water_Source",
      "level": 1
    },
    {
      "x": 10,
      "y": 6,
      "z": 8,
      "name": "Water_Source",
      "level": 1
    },
    {
      "x": 10,
      "y": 6,
      "z": 9,
      "name": "Water_Source",
      "level": 1
    },
    {
      "x": 10,
      "y": 6,
      "z": 10,
      "name": "Water_Source",
      "level": 1
    },
    {
      "x": 10,
      "y": 6,
      "z": 11,
      "name": "Water_Source",
      "level": 1
    },
    {
      "x": 11,
      "y": 6,
      "z": 7,
      "name": "Water_Source",
      "level": 1
    },
    {
      "x": 11,
      "y": 6,
      "z": 8,
      "name": "Water_Source",
      "level": 1
    },
    {
      "x": 11,
      "y": 6,
      "z": 9,
      "name": "Water_Source",
      "level": 1
    },
    {
      "x": 11,
      "y": 6,
      "z": 10,
      "name": "Water_Source",
      "level": 1
    },
    {
      "x": 12,
      "y": 6,
      "z": 8,
      "name": "Water_Source",
      "level": 1
    },
    {
      "x": 12,
      "y": 6,
      "z": 9,
      "name": "Water_Source",
      "level": 1
    },
    {
      "x": 12,
      "y": 6,
      "z": 10,
      "name": "Water_Source",
      "level": 1
    }
  ]
}