{
  "version": 8,
  "blockIdVersion": 8,
  "anchorX": 27,
  "anchorY": 29,
  "anchorZ": 14,
  "blocks": [
    {
      "x": 4,
      "y": 33,
      "z": 13,
      "name": "Rock_Stone"
    },
    {
      "x": 4,
      "y": 34,
      "z": 13,
      "name": "Rock_Stone"
    },
    {
      "x": 4,
      "y": 35,
      "z": 13,
      "name": "Rock_Stone"
    },
    {
      "x": 4,
      "y": 36,
      "z": 13,
      "name": "Rock_Stone"
    },
    {
      "x": 4,
      "y": 37,
      "z": 13,
      "name": "Soil_Dirt"
    },
    {
      "x": 4,
      "y": 34,
      "z": 14,
      "name": "Rock_Stone"
    },
    {
      "x": 4,
      "y": 35,
      "z": 14,
      "name": "Rock_Stone"
    },
    {
      "x": 4,
      "y": 36,
      "z": 14,
      "name": "Rock_Stone"
    },
    {
      "x": 4,
      "y": 37,
      "z": 14,
      "name": "Soil_Dirt"
    },
    {
      "x": 4,
      "y": 38,
      "z": 14,
      "name": "Soil_Grass"
    },
    {
      "x": 4,
      "y": 34,
      "z": 15,
      "name": "Rock_Stone"
    },
    {
      "x": 4,
      "y": 35,
      "z": 15,
      "name": "Rock_Stone"
    },
    {
      "x": 4,
      "y": 36,
      "z": 15,
      "name": "Rock_Stone"
    },
    {
      "x": 4,
      "y": 37,
      "z": 15,
      "name": "Soil_Dirt"
    },
    {
      "x": 4,
      "y": 38,
      "z": 15,
      "name": "Soil_Grass"
    },
    {
      "x": 4,
      "y": 39,
      "z": 15,
      "name": "Plant_Grass_Sharp"
    },
    {
      "x": 5,
      "y": 34,
      "z": 11,
      "name": "Rock_Stone"
    },
    {
      "x": 5,
      "y": 35,
      "z": 11,
      "name": "Rock_Stone"
    },
    {
      "x": 5,
      "y": 36,
      "z": 11,
      "name": "Rock_Stone"
    },
    {
      "x": 5,
      "y": 37,
      "z": 11,
      "name": "Soil_Dirt"
    },
    {
      "x": 5,
      "y": 38,
      "z": 11,
      "name": "Soil_Dirt"
    },
    {
      "x": 5,
      "y": 33,
      "z": 12,
      "name": "Rock_Stone"
    },
    {
      "x": 5,
      "y": 34,
      "z": 12,
      "name": "Rock_Stone"
    },
    {
      "x": 5,
      "y": 35,
      "z": 12,
      "name": "Rock_Stone"
    },
    {
      "x": 5,
      "y": 36,
      "z": 12,
      "name": "Rock_Stone"
    },
    {
      "x": 5,
      "y": 37,
      "z": 12,
      "name": "Soil_Dirt"
    },
    {
      "x": 5,
      "y": 38,
      "z": 12,
      "name": "Soil_Dirt"
    },
    {
      "x": 5,
      "y": 30,
      "z": 13,
      "name": "Rock_Stone"
    },
    {
      "x": 5,
      "y": 31,
      "z": 13,
      "name": "Rock_Stone"
    },
    {
      "x": 5,
      "y": 32,
      "z": 13,
      "name": "Rock_Stone"
    },
    {
      "x": 5,
      "y": 33,
      "z": 13,
      "name": "Rock_Stone"
    },
    {
      "x": 5,
      "y": 34,
      "z": 13,
      "name": "Rock_Stone"
    },
    {
      "x": 5,
      "y": 35,
      "z": 13,
      "name": "Rock_Stone"
    },
    {
      "x": 5,
      "y": 36,
      "z": 13,
      "name": "Soil_Dirt"
    },
    {
      "x": 5,
      "y": 37,
      "z": 13,
      "name": "Soil_Dirt"
    },
    {
      "x": 5,
      "y": 38,
      "z": 13,
      "name": "Soil_Dirt"
    },
    {
      "x": 5,
      "y": 39,
      "z": 13,
      "name": "Soil_Grass"
    },
    {
      "x": 5,
      "y": 40,
      "z": 13,
      "name": "Plant_Grass_Sharp"
    },
    {
      "x": 5,
      "y": 30,
      "z": 14,
      "name": "Rock_Stone"
    },
    {
      "x": 5,
      "y": 31,
      "z": 14,
      "name": "Rock_Stone"
    },
    {
      "x": 5,
      "y": 32,
      "z": 14,
      "name": "Rock_Stone"
    },
    {
      "x": 5,
      "y": 33,
      "z": 14,
      "name": "Rock_Stone"
    },
    {
      "x": 5,
      "y": 34,
      "z": 14,
      "name": "Rock_Stone"
    },
    {
      "x": 5,
      "y": 35,
      "z": 14,
      "name": "Rock_Stone"
    },
    {
      "x": 5,
      "y": 36,
      "z": 14,
      "name": "Soil_Dirt"
    },
    {
      "x": 5,
      "y": 37,
      "z": 14,
      "name": "Soil_Dirt"
    },
    {
      "x": 5,
      "y": 38,
      "z": 14,
      "name": "Soil_Dirt"
    },
    {
      "x": 5,
      "y": 39,
      "z": 14,
      "name": "Soil_Grass"
    },
    {
      "x": 5,
      "y": 32,
      "z": 15,
      "name": "Rock_Stone"
    },
    {
      "x": 5,
      "y": 33,
      "z": 15,
      "name": "Rock_Stone"
    },
    {
      "x": 5,
      "y": 34,
      "z": 15,
      "name": "Rock_Stone"
    },
    {
      "x": 5,
      "y": 35,
      "z": 15,
      "name": "Rock_Stone"
    },
    {
      "x": 5,
      "y": 36,
      "z": 15,
      "name": "Rock_Stone"
    },
    {
      "x": 5,
      "y": 37,
      "z": 15,
      "name": "Soil_Dirt"
    },
    {
      "x": 5,
      "y": 38,
      "z": 15,
      "name": "Soil_Grass"
    },
    {
      "x": 5,
      "y": 35,
      "z": 16,
      "name": "Rock_Stone"
    },
    {
      "x": 5,
      "y": 36,
      "z": 16,
      "name": "Rock_Stone"
    },
    {
      "x": 5,
      "y": 37,
      "z": 16,
      "name": "Soil_Dirt"
    },
    {
      "x": 6,
      "y": 37,
      "z": 10,
      "name": "Rock_Stone"
    },
    {
      "x": 6,
      "y": 38,
      "z": 10,
      "name": "Soil_Dirt"
    },
    {
      "x": 6,
      "y": 39,
      "z": 10,
      "name": "Soil_Grass"
    },
    {
      "x": 6,
      "y": 31,
      "z": 11,
      "name": "Rock_Stone"
    },
    {
      "x": 6,
      "y": 32,
      "z": 11,
      "name": "Rock_Stone"
    },
    {
      "x": 6,
      "y": 33,
      "z": 11,
      "name": "Rock_Stone"
    },
    {
      "x": 6,
      "y": 34,
      "z": 11,
      "name": "Rock_Stone"
    },
    {
      "x": 6,
      "y": 35,
      "z": 11,
      "name": "Rock_Stone"
    },
    {
      "x": 6,
      "y": 36,
      "z": 11,
      "name": "Rock_Stone"
    },
    {
      "x": 6,
      "y": 37,
      "z": 11,
      "name": "Soil_Dirt"
    },
    {
      "x": 6,
      "y": 38,
      "z": 11,
      "name": "Soil_Dirt"
    },
    {
      "x": 6,
      "y": 39,
      "z": 11,
      "name": "Soil_Dirt"
    },
    {
      "x": 6,
      "y": 40,
      "z": 11,
      "name": "Soil_Grass"
    },
    {
      "x": 6,
      "y": 28,
      "z": 12,
      "name": "Rock_Stone"
    },
    {
      "x": 6,
      "y": 29,
      "z": 12,
      "name": "Rock_Stone"
    },
    {
      "x": 6,
      "y": 30,
      "z": 12,
      "name": "Rock_Stone"
    },
    {
      "x": 6,
      "y": 31,
      "z": 12,
      "name": "Rock_Stone"
    },
    {
      "x": 6,
      "y": 32,
      "z": 12,
      "name": "Rock_Stone"
    },
    {
      "x": 6,
      "y": 33,
      "z": 12,
      "name": "Rock_Stone"
    },
    {
      "x": 6,
      "y": 34,
      "z": 12,
      "name": "Rock_Stone"
    },
    {
      "x": 6,
      "y": 35,
      "z": 12,
      "name": "Rock_Stone"
    },
    {
      "x": 6,
      "y": 36,
      "z": 12,
      "name": "Rock_Stone"
    },
    {
      "x": 6,
      "y": 37,
      "z": 12,
      "name": "Soil_Dirt"
    },
    {
      "x": 6,
      "y": 38,
      "z": 12,
      "name": "Soil_Dirt"
    },
    {
      "x": 6,
      "y": 39,
      "z": 12,
      "name": "Soil_Dirt"
    },
    {
      "x": 6,
      "y": 40,
      "z": 12,
      "name": "Soil_Dirt"
    },
    {
      "x": 6,
      "y": 41,
      "z": 12,
      "name": "Soil_Grass"
    },
    {
      "x": 6,
      "y": 28,
      "z": 13,
      "name": "Rock_Stone"
    },
    {
      "x": 6,
      "y": 29,
      "z": 13,
      "name": "Rock_Stone"
    },
    {
      "x": 6,
      "y": 30,
      "z": 13,
      "name": "Rock_Stone"
    },
    {
      "x": 6,
      "y": 31,
      "z": 13,
      "name": "Rock_Stone"
    },
    {
      "x": 6,
      "y": 32,
      "z": 13,
      "name": "Rock_Stone"
    },
    {
      "x": 6,
      "y": 33,
      "z": 13,
      "name": "Rock_Stone"
    },
    {
      "x": 6,
      "y": 34,
      "z": 13,
      "name": "Rock_Stone"
    },
    {
      "x": 6,
      "y": 35,
      "z": 13,
      "name": "Rock_Stone"
    },
    {
      "x": 6,
      "y": 36,
      "z": 13,
      "name": "Rock_Stone"
    },
    {
      "x": 6,
      "y": 37,
      "z": 13,
      "name": "Soil_Dirt"
    },
    {
      "x": 6,
      "y": 38,
      "z": 13,
      "name": "Soil_Dirt"
    },
    {
      "x": 6,
      "y": 39,
      "z": 13,
      "name": "Soil_Dirt"
    },
    {
      "x": 6,
      "y": 40,
      "z": 13,
      "name": "Soil_Dirt"
    },
    {
      "x": 6,
      "y": 41,
      "z": 13,
      "name": "Soil_Grass"
    },
    {
      "x": 6,
      "y": 29,
      "z": 14,
      "name": "Rock_Stone"
    },
    {
      "x": 6,
      "y": 30,
      "z": 14,
      "name": "Rock_Stone"
    },
    {
      "x": 6,
      "y": 31,
      "z": 14,
      "name": "Rock_Stone"
    },
    {
      "x": 6,
      "y": 32,
      "z": 14,
      "name": "Rock_Stone"
    },
    {
      "x": 6,
      "y": 33,
      "z": 14,
      "name": "Rock_Stone"
    },
    {
      "x": 6,
      "y": 34,
      "z": 14,
      "name": "Rock_Stone"
    },
    {
      "x": 6,
      "y": 35,
      "z": 14,
      "name": "Rock_Stone"
    },
    {
      "x": 6,
      "y": 36,
      "z": 14,
      "name": "Rock_Stone"
    },
    {
      "x": 6,
      "y": 37,
      "z": 14,
      "name": "Soil_Dirt"
    },
    {
      "x": 6,
      "y": 38,
      "z": 14,
      "name": "Soil_Dirt"
    },
    {
      "x": 6,
      "y": 39,
      "z": 14,
      "name": "Soil_Dirt"
    },
    {
      "x": 6,
      "y": 40,
      "z": 14,
      "name": "Soil_Dirt"
    },
    {
      "x": 6,
      "y": 41,
      "z": 14,
      "name": "Soil_Grass"
    },
    {
      "x": 6,
      "y": 42,
      "z": 14,
      "name": "Plant_Grass_Sharp"
    },
    {
      "x": 6,
      "y": 30,
      "z": 15,
      "name": "Rock_Stone"
    },
    {
      "x": 6,
      "y": 31,
      "z": 15,
      "name": "Rock_Stone"
    },
    {
      "x": 6,
      "y": 32,
      "z": 15,
      "name": "Rock_Stone"
    },
    {
      "x": 6,
      "y": 33,
      "z": 15,
      "name": "Rock_Stone"
    },
    {
      "x": 6,
      "y": 34,
      "z": 15,
      "name": "Rock_Stone"
    },
    {
      "x": 6,
      "y": 35,
      "z": 15,
      "name": "Rock_Stone"
    },
    {
      "x": 6,
      "y": 36,
      "z": 15,
      "name": "Rock_Stone"
    },
    {
      "x": 6,
      "y": 37,
      "z": 15,
      "name": "Soil_Dirt"
    },
    {
      "x": 6,
      "y": 38,
      "z": 15,
      "name": "Soil_Dirt"
    },
    {
      "x": 6,
      "y": 39,
      "z": 15,
      "name": "Soil_Dirt"
    },
    {
      "x": 6,
      "y": 40,
      "z": 15,
      "name": "Soil_Dirt"
    },
    {
      "x": 6,
      "y": 41,
      "z": 15,
      "name": "Soil_Grass"
    },
    {
      "x": 6,
      "y": 42,
      "z": 15,
      "name": "Plant_Grass_Sharp"
    },
    {
      "x": 6,
      "y": 31,
      "z": 16,
      "name": "Rock_Stone"
    },
    {
      "x": 6,
      "y": 32,
      "z": 16,
      "name": "Rock_Stone"
    },
    {
      "x": 6,
      "y": 33,
      "z": 16,
      "name": "Rock_Stone"
    },
    {
      "x": 6,
      "y": 34,
      "z": 16,
      "name": "Rock_Stone"
    },
    {
      "x": 6,
      "y": 35,
      "z": 16,
      "name": "Rock_Stone"
    },
    {
      "x": 6,
      "y": 36,
      "z": 16,
      "name": "Rock_Stone"
    },
    {
      "x": 6,
      "y": 37,
      "z": 16,
      "name": "Soil_Dirt"
    },
    {
      "x": 6,
      "y": 38,
      "z": 16,
      "name": "Soil_Dirt"
    },
    {
      "x": 6,
      "y": 39,
      "z": 16,
      "name": "Soil_Dirt"
    },
    {
      "x": 6,
      "y": 40,
      "z": 16,
      "name": "Soil_Grass"
    },
    {
      "x": 6,
      "y": 36,
      "z": 17,
      "name": "Rock_Stone"
    },
    {
      "x": 6,
      "y": 37,
      "z": 17,
      "name": "Rock_Stone"
    },
    {
      "x": 6,
      "y": 38,
      "z": 17,
      "name": "Soil_Dirt"
    },
    {
      "x": 6,
      "y": 39,
      "z": 17,
      "name": "Soil_Grass"
    },
    {
      "x": 7,
      "y": 37,
      "z": 10,
      "name": "Rock_Stone"
    },
    {
      "x": 7,
      "y": 38,
      "z": 10,
      "name": "Soil_Dirt"
    },
    {
      "x": 7,
      "y": 39,
      "z": 10,
      "name": "Soil_Dirt"
    },
    {
      "x": 7,
      "y": 40,
      "z": 10,
      "name": "Soil_Grass"
    },
    {
      "x": 7,
      "y": 41,
      "z": 10,
      "name": "Plant_Grass_Sharp"
    },
    {
      "x": 7,
      "y": 27,
      "z": 11,
      "name": "Rock_Stone"
    },
    {
      "x": 7,
      "y": 28,
      "z": 11,
      "name": "Rock_Stone"
    },
    {
      "x": 7,
      "y": 29,
      "z": 11,
      "name": "Rock_Stone"
    },
    {
      "x": 7,
      "y": 30,
      "z": 11,
      "name": "Rock_Stone"
    },
    {
      "x": 7,
      "y": 31,
      "z": 11,
      "name": "Rock_Stone"
    },
    {
      "x": 7,
      "y": 32,
      "z": 11,
      "name": "Rock_Stone"
    },
    {
      "x": 7,
      "y": 33,
      "z": 11,
      "name": "Rock_Stone"
    },
    {
      "x": 7,
      "y": 34,
      "z": 11,
      "name": "Rock_Stone"
    },
    {
      "x": 7,
      "y": 35,
      "z": 11,
      "name": "Rock_Stone"
    },
    {
      "x": 7,
      "y": 36,
      "z": 11,
      "name": "Rock_Stone"
    },
    {
      "x": 7,
      "y": 37,
      "z": 11,
      "name": "Soil_Dirt"
    },
    {
      "x": 7,
      "y": 38,
      "z": 11,
      "name": "Soil_Dirt"
    },
    {
      "x": 7,
      "y": 39,
      "z": 11,
      "name": "Soil_Dirt"
    },
    {
      "x": 7,
      "y": 40,
      "z": 11,
      "name": "Soil_Grass"
    },
    {
      "x": 7,
      "y": 26,
      "z": 12,
      "name": "Rock_Stone"
    },
    {
      "x": 7,
      "y": 27,
      "z": 12,
      "name": "Rock_Stone"
    },
    {
      "x": 7,
      "y": 28,
      "z": 12,
      "name": "Rock_Stone"
    },
    {
      "x": 7,
      "y": 29,
      "z": 12,
      "name": "Rock_Stone"
    },
    {
      "x": 7,
      "y": 30,
      "z": 12,
      "name": "Rock_Stone"
    },
    {
      "x": 7,
      "y": 31,
      "z": 12,
      "name": "Rock_Stone"
    },
    {
      "x": 7,
      "y": 32,
      "z": 12,
      "name": "Rock_Stone"
    },
    {
      "x": 7,
      "y": 33,
      "z": 12,
      "name": "Rock_Stone"
    },
    {
      "x": 7,
      "y": 34,
      "z": 12,
      "name": "Rock_Stone"
    },
    {
      "x": 7,
      "y": 35,
      "z": 12,
      "name": "Rock_Stone"
    },
    {
      "x": 7,
      "y": 36,
      "z": 12,
      "name": "Rock_Stone"
    },
    {
      "x": 7,
      "y": 37,
      "z": 12,
      "name": "Soil_Dirt"
    },
    {
      "x": 7,
      "y": 38,
      "z": 12,
      "name": "Soil_Dirt"
    },
    {
      "x": 7,
      "y": 39,
      "z": 12,
      "name": "Soil_Dirt"
    },
    {
      "x": 7,
      "y": 40,
      "z": 12,
      "name": "Soil_Dirt"
    },
    {
      "x": 7,
      "y": 41,
      "z": 12,
      "name": "Soil_Grass"
    },
    {
      "x": 7,
      "y": 42,
      "z": 12,
      "name": "Plant_Grass_Sharp"
    },
    {
      "x": 7,
      "y": 26,
      "z": 13,
      "name": "Rock_Stone"
    },
    {
      "x": 7,
      "y": 27,
      "z": 13,
      "name": "Rock_Stone"
    },
    {
      "x": 7,
      "y": 28,
      "z": 13,
      "name": "Rock_Stone"
    },
    {
      "x": 7,
      "y": 29,
      "z": 13,
      "name": "Rock_Stone"
    },
    {
      "x": 7,
      "y": 30,
      "z": 13,
      "name": "Rock_Stone"
    },
    {
      "x": 7,
      "y": 31,
      "z": 13,
      "name": "Rock_Stone"
    },
    {
      "x": 7,
      "y": 32,
      "z": 13,
      "name": "Rock_Stone"
    },
    {
      "x": 7,
      "y": 33,
      "z": 13,
      "name": "Rock_Stone"
    },
    {
      "x": 7,
      "y": 34,
      "z": 13,
      "name": "Rock_Stone"
    },
    {
      "x": 7,
      "y": 35,
      "z": 13,
      "name": "Rock_Stone"
    },
    {
      "x": 7,
      "y": 36,
      "z": 13,
      "name": "Rock_Stone"
    },
    {
      "x": 7,
      "y": 37,
      "z": 13,
      "name": "Soil_Dirt"
    },
    {
      "x": 7,
      "y": 38,
      "z": 13,
      "name": "Soil_Dirt"
    },
    {
      "x": 7,
      "y": 39,
      "z": 13,
      "name": "Soil_Dirt"
    },
    {
      "x": 7,
      "y": 40,
      "z": 13,
      "name": "Soil_Dirt"
    },
    {
      "x": 7,
      "y": 41,
      "z": 13,
      "name": "Soil_Grass"
    },
    {
      "x": 7,
      "y": 42,
      "z": 13,
      "name": "Plant_Grass_Lush_Tall"
    },
    {
      "x": 7,
      "y": 29,
      "z": 14,
      "name": "Rock_Stone"
    },
    {
      "x": 7,
      "y": 30,
      "z": 14,
      "name": "Rock_Stone"
    },
    {
      "x": 7,
      "y": 31,
      "z": 14,
      "name": "Rock_Stone"
    },
    {
      "x": 7,
      "y": 32,
      "z": 14,
      "name": "Rock_Stone"
    },
    {
      "x": 7,
      "y": 33,
      "z": 14,
      "name": "Rock_Stone"
    },
    {
      "x": 7,
      "y": 34,
      "z": 14,
      "name": "Rock_Stone"
    },
    {
      "x": 7,
      "y": 35,
      "z": 14,
      "name": "Rock_Stone"
    },
    {
      "x": 7,
      "y": 36,
      "z": 14,
      "name": "Rock_Stone"
    },
    {
      "x": 7,
      "y": 37,
      "z": 14,
      "name": "Soil_Dirt"
    },
    {
      "x": 7,
      "y": 38,
      "z": 14,
      "name": "Soil_Dirt"
    },
    {
      "x": 7,
      "y": 39,
      "z": 14,
      "name": "Soil_Dirt"
    },
    {
      "x": 7,
      "y": 40,
      "z": 14,
      "name": "Soil_Dirt"
    },
    {
      "x": 7,
      "y": 41,
      "z": 14,
      "name": "Soil_Dirt"
    },
    {
      "x": 7,
      "y": 42,
      "z": 14,
      "name": "Soil_Grass"
    },
    {
      "x": 7,
      "y": 43,
      "z": 14,
      "name": "Plant_Grass_Sharp"
    },
    {
      "x": 7,
      "y": 29,
      "z": 15,
      "name": "Rock_Stone"
    },
    {
      "x": 7,
      "y": 30,
      "z": 15,
      "name": "Rock_Stone"
    },
    {
      "x": 7,
      "y": 31,
      "z": 15,
      "name": "Rock_Stone"
    },
    {
      "x": 7,
      "y": 32,
      "z": 15,
      "name": "Rock_Stone"
    },
    {
      "x": 7,
      "y": 33,
      "z": 15,
      "name": "Rock_Stone"
    },
    {
      "x": 7,
      "y": 34,
      "z": 15,
      "name": "Rock_Stone"
    },
    {
      "x": 7,
      "y": 35,
      "z": 15,
      "name": "Rock_Stone"
    },
    {
      "x": 7,
      "y": 36,
      "z": 15,
      "name": "Rock_Stone"
    },
    {
      "x": 7,
      "y": 37,
      "z": 15,
      "name": "Soil_Dirt"
    },
    {
      "x": 7,
      "y": 38,
      "z": 15,
      "name": "Soil_Dirt"
    },
    {
      "x": 7,
      "y": 39,
      "z": 15,
      "name": "Soil_Dirt"
    },
    {
      "x": 7,
      "y": 40,
      "z": 15,
      "name": "Soil_Dirt"
    },
    {
      "x": 7,
      "y": 41,
      "z": 15,
      "name": "Soil_Dirt"
    },
    {
      "x": 7,
      "y": 42,
      "z": 15,
      "name": "Soil_Grass"
    },
    {
      "x": 7,
      "y": 31,
      "z": 16,
      "name": "Rock_Stone"
    },
    {
      "x": 7,
      "y": 32,
      "z": 16,
      "name": "Rock_Stone"
    },
    {
      "x": 7,
      "y": 33,
      "z": 16,
      "name": "Rock_Stone"
    },
    {
      "x": 7,
      "y": 34,
      "z": 16,
      "name": "Rock_Stone"
    },
    {
      "x": 7,
      "y": 35,
      "z": 16,
      "name": "Rock_Stone"
    },
    {
      "x": 7,
      "y": 36,
      "z": 16,
      "name": "Rock_Stone"
    },
    {
      "x": 7,
      "y": 37,
      "z": 16,
      "name": "Soil_Dirt"
    },
    {
      "x": 7,
      "y": 38,
      "z": 16,
      "name": "Soil_Dirt"
    },
    {
      "x": 7,
      "y": 39,
      "z": 16,
      "name": "Soil_Dirt"
    },
    {
      "x": 7,
      "y": 40,
      "z": 16,
      "name": "Soil_Dirt"
    },
    {
      "x": 7,
      "y": 41,
      "z": 16,
      "name": "Soil_Dirt"
    },
    {
      "x": 7,
      "y": 42,
      "z": 16,
      "name": "Soil_Grass"
    },
    {
      "x": 7,
      "y": 43,
      "z": 16,
      "name": "Plant_Grass_Sharp"
    },
    {
      "x": 7,
      "y": 36,
      "z": 17,
      "name": "Rock_Stone"
    },
    {
      "x": 7,
      "y": 37,
      "z": 17,
      "name": "Rock_Stone"
    },
    {
      "x": 7,
      "y": 38,
      "z": 17,
      "name": "Soil_Dirt"
    },
    {
      "x": 7,
      "y": 39,
      "z": 17,
      "name": "Soil_Dirt"
    },
    {
      "x": 7,
      "y": 40,
      "z": 17,
      "name": "Soil_Dirt"
    },
    {
      "x": 7,
      "y": 41,
      "z": 17,
      "name": "Soil_Grass"
    },
    {
      "x": 8,
      "y": 26,
      "z": 9,
      "name": "Rock_Stone"
    },
    {
      "x": 8,
      "y": 27,
      "z": 9,
      "name": "Rock_Stone"
    },
    {
      "x": 8,
      "y": 25,
      "z": 10,
      "name": "Rock_Stone"
    },
    {
      "x": 8,
      "y": 26,
      "z": 10,
      "name": "Rock_Stone"
    },
    {
      "x": 8,
      "y": 27,
      "z": 10,
      "name": "Rock_Stone"
    },
    {
      "x": 8,
      "y": 28,
      "z": 10,
      "name": "Rock_Stone"
    },
    {
      "x": 8,
      "y": 29,
      "z": 10,
      "name": "Rock_Stone"
    },
    {
      "x": 8,
      "y": 37,
      "z": 10,
      "name": "Rock_Stone"
    },
    {
      "x": 8,
      "y": 38,
      "z": 10,
      "name": "Rock_Stone"
    },
    {
      "x": 8,
      "y": 39,
      "z": 10,
      "name": "Soil_Dirt"
    },
    {
      "x": 8,
      "y": 40,
      "z": 10,
      "name": "Soil_Dirt"
    },
    {
      "x": 8,
      "y": 41,
      "z": 10,
      "name": "Soil_Dirt"
    },
    {
      "x": 8,
      "y": 42,
      "z": 10,
      "name": "Soil_Grass"
    },
    {
      "x": 8,
      "y": 25,
      "z": 11,
      "name": "Rock_Stone"
    },
    {
      "x": 8,
      "y": 26,
      "z": 11,
      "name": "Rock_Stone"
    },
    {
      "x": 8,
      "y": 27,
      "z": 11,
      "name": "Rock_Stone"
    },
    {
      "x": 8,
      "y": 28,
      "z": 11,
      "name": "Rock_Stone"
    },
    {
      "x": 8,
      "y": 29,
      "z": 11,
      "name": "Rock_Stone"
    },
    {
      "x": 8,
      "y": 30,
      "z": 11,
      "name": "Rock_Stone"
    },
    {
      "x": 8,
      "y": 31,
      "z": 11,
      "name": "Rock_Stone"
    },
    {
      "x": 8,
      "y": 32,
      "z": 11,
      "name": "Rock_Stone"
    },
    {
      "x": 8,
      "y": 35,
      "z": 11,
      "name": "Rock_Stone"
    },
    {
      "x": 8,
      "y": 36,
      "z": 11,
      "name": "Rock_Stone"
    },
    {
      "x": 8,
      "y": 37,
      "z": 11,
      "name": "Rock_Stone"
    },
    {
      "x": 8,
      "y": 38,
      "z": 11,
      "name": "Soil_Dirt"
    },
    {
      "x": 8,
      "y": 39,
      "z": 11,
      "name": "Soil_Dirt"
    },
    {
      "x": 8,
      "y": 40,
      "z": 11,
      "name": "Soil_Dirt"
    },
    {
      "x": 8,
      "y": 41,
      "z": 11,
      "name": "Soil_Dirt"
    },
    {
      "x": 8,
      "y": 42,
      "z": 11,
      "name": "Soil_Dirt"
    },
    {
      "x": 8,
      "y": 43,
      "z": 11,
      "name": "Soil_Grass"
    },
    {
      "x": 8,
      "y": 25,
      "z": 12,
      "name": "Rock_Stone"
    },
    {
      "x": 8,
      "y": 26,
      "z": 12,
      "name": "Rock_Stone"
    },
    {
      "x": 8,
      "y": 27,
      "z": 12,
      "name": "Rock_Stone"
    },
    {
      "x": 8,
      "y": 28,
      "z": 12,
      "name": "Rock_Stone"
    },
    {
      "x": 8,
      "y": 29,
      "z": 12,
      "name": "Rock_Stone"
    },
    {
      "x": 8,
      "y": 30,
      "z": 12,
      "name": "Rock_Stone"
    },
    {
      "x": 8,
      "y": 31,
      "z": 12,
      "name": "Rock_Stone"
    },
    {
      "x": 8,
      "y": 32,
      "z": 12,
      "name": "Rock_Stone"
    },
    {
      "x": 8,
      "y": 33,
      "z": 12,
      "name": "Rock_Stone"
    },
    {
      "x": 8,
      "y": 34,
      "z": 12,
      "name": "Rock_Stone"
    },
    {
      "x": 8,
      "y": 35,
      "z": 12,
      "name": "Rock_Stone"
    },
    {
      "x": 8,
      "y": 36,
      "z": 12,
      "name": "Rock_Stone"
    },
    {
      "x": 8,
      "y": 37,
      "z": 12,
      "name": "Rock_Stone"
    },
    {
      "x": 8,
      "y": 38,
      "z": 12,
      "name": "Soil_Dirt"
    },
    {
      "x": 8,
      "y": 39,
      "z": 12,
      "name": "Soil_Dirt"
    },
    {
      "x": 8,
      "y": 40,
      "z": 12,
      "name": "Soil_Dirt"
    },
    {
      "x": 8,
      "y": 41,
      "z": 12,
      "name": "Soil_Dirt"
    },
    {
      "x": 8,
      "y": 42,
      "z": 12,
      "name": "Soil_Dirt"
    },
    {
      "x": 8,
      "y": 43,
      "z": 12,
      "name": "Soil_Grass"
    },
    {
      "x": 8,
      "y": 44,
      "z": 12,
      "name": "Plant_Grass_Lush"
    },
    {
      "x": 8,
      "y": 25,
      "z": 13,
      "name": "Rock_Stone"
    },
    {
      "x": 8,
      "y": 26,
      "z": 13,
      "name": "Rock_Stone"
    },
    {
      "x": 8,
      "y": 27,
      "z": 13,
      "name": "Rock_Stone"
    },
    {
      "x": 8,
      "y": 28,
      "z": 13,
      "name": "Rock_Stone"
    },
    {
      "x": 8,
      "y": 29,
      "z": 13,
      "name": "Rock_Stone"
    },
    {
      "x": 8,
      "y": 30,
      "z": 13,
      "name": "Rock_Stone"
    },
    {
      "x": 8,
      "y": 31,
      "z": 13,
      "name": "Rock_Stone"
    },
    {
      "x": 8,
      "y": 32,
      "z": 13,
      "name": "Rock_Stone"
    },
    {
      "x": 8,
      "y": 33,
      "z": 13,
      "name": "Rock_Stone"
    },
    {
      "x": 8,
      "y": 34,
      "z": 13,
      "name": "Rock_Stone"
    },
    {
      "x": 8,
      "y": 35,
      "z": 13,
      "name": "Rock_Stone"
    },
    {
      "x": 8,
      "y": 36,
      "z": 13,
      "name": "Rock_Stone"
    },
    {
      "x": 8,
      "y": 37,
      "z": 13,
      "name": "Rock_Stone"
    },
    {
      "x": 8,
      "y": 38,
      "z": 13,
      "name": "Soil_Dirt"
    },
    {
      "x": 8,
      "y": 39,
      "z": 13,
      "name": "Soil_Dirt"
    },
    {
      "x": 8,
      "y": 40,
      "z": 13,
      "name": "Soil_Dirt"
    },
    {
      "x": 8,
      "y": 41,
      "z": 13,
      "name": "Soil_Dirt"
    },
    {
      "x": 8,
      "y": 42,
      "z": 13,
      "name": "Soil_Dirt"
    },
    {
      "x": 8,
      "y": 43,
      "z": 13,
      "name": "Soil_Grass"
    },
    {
      "x": 8,
      "y": 28,
      "z": 14,
      "name": "Rock_Stone"
    },
    {
      "x": 8,
      "y": 29,
      "z": 14,
      "name": "Rock_Stone"
    },
    {
      "x": 8,
      "y": 30,
      "z": 14,
      "name": "Rock_Stone"
    },
    {
      "x": 8,
      "y": 31,
      "z": 14,
      "name": "Rock_Stone"
    },
    {
      "x": 8,
      "y": 32,
      "z": 14,
      "name": "Rock_Stone"
    },
    {
      "x": 8,
      "y": 33,
      "z": 14,
      "name": "Rock_Stone"
    },
    {
      "x": 8,
      "y": 34,
      "z": 14,
      "name": "Rock_Stone"
    },
    {
      "x": 8,
      "y": 35,
      "z": 14,
      "name": "Rock_Stone"
    },
    {
      "x": 8,
      "y": 36,
      "z": 14,
      "name": "Rock_Stone"
    },
    {
      "x": 8,
      "y": 37,
      "z": 14,
      "name": "Rock_Stone"
    },
    {
      "x": 8,
      "y": 38,
      "z": 14,
      "name": "Soil_Dirt"
    },
    {
      "x": 8,
      "y": 39,
      "z": 14,
      "name": "Soil_Dirt"
    },
    {
      "x": 8,
      "y": 40,
      "z": 14,
      "name": "Soil_Dirt"
    },
    {
      "x": 8,
      "y": 41,
      "z": 14,
      "name": "Soil_Dirt"
    },
    {
      "x": 8,
      "y": 42,
      "z": 14,
      "name": "Soil_Dirt"
    },
    {
      "x": 8,
      "y": 43,
      "z": 14,
      "name": "Soil_Grass"
    },
    {
      "x": 8,
      "y": 44,
      "z": 14,
      "name": "Plant_Grass_Lush"
    },
    {
      "x": 8,
      "y": 29,
      "z": 15,
      "name": "Rock_Stone"
    },
    {
      "x": 8,
      "y": 30,
      "z": 15,
      "name": "Rock_Stone"
    },
    {
      "x": 8,
      "y": 31,
      "z": 15,
      "name": "Rock_Stone"
    },
    {
      "x": 8,
      "y": 32,
      "z": 15,
      "name": "Rock_Stone"
    },
    {
      "x": 8,
      "y": 33,
      "z": 15,
      "name": "Rock_Stone"
    },
    {
      "x": 8,
      "y": 34,
      "z": 15,
      "name": "Rock_Stone"
    },
    {
      "x": 8,
      "y": 35,
      "z": 15,
      "name": "Rock_Stone"
    },
    {
      "x": 8,
      "y": 36,
      "z": 15,
      "name": "Rock_Stone"
    },
    {
      "x": 8,
      "y": 37,
      "z": 15,
      "name": "Rock_Stone"
    },
    {
      "x": 8,
      "y": 38,
      "z": 15,
      "name": "Soil_Dirt"
    },
    {
      "x": 8,
      "y": 39,
      "z": 15,
      "name": "Soil_Dirt"
    },
    {
      "x": 8,
      "y": 40,
      "z": 15,
      "name": "Soil_Dirt"
    },
    {
      "x": 8,
      "y": 41,
      "z": 15,
      "name": "Soil_Dirt"
    },
    {
      "x": 8,
      "y": 42,
      "z": 15,
      "name": "Soil_Dirt"
    },
    {
      "x": 8,
      "y": 43,
      "z": 15,
      "name": "Soil_Grass"
    },
    {
      "x": 8,
      "y": 33,
      "z": 16,
      "name": "Rock_Stone"
    },
    {
      "x": 8,
      "y": 34,
      "z": 16,
      "name": "Rock_Stone"
    },
    {
      "x": 8,
      "y": 35,
      "z": 16,
      "name": "Rock_Stone"
    },
    {
      "x": 8,
      "y": 36,
      "z": 16,
      "name": "Rock_Stone"
    },
    {
      "x": 8,
      "y": 37,
      "z": 16,
      "name": "Rock_Stone"
    },
    {
      "x": 8,
      "y": 38,
      "z": 16,
      "name": "Soil_Dirt"
    },
    {
      "x": 8,
      "y": 39,
      "z": 16,
      "name": "Soil_Dirt"
    },
    {
      "x": 8,
      "y": 40,
      "z": 16,
      "name": "Soil_Dirt"
    },
    {
      "x": 8,
      "y": 41,
      "z": 16,
      "name": "Soil_Dirt"
    },
    {
      "x": 8,
      "y": 42,
      "z": 16,
      "name": "Soil_Grass"
    },
    {
      "x": 8,
      "y": 43,
      "z": 16,
      "name": "Plant_Grass_Sharp"
    },
    {
      "x": 8,
      "y": 37,
      "z": 17,
      "name": "Rock_Stone"
    },
    {
      "x": 8,
      "y": 38,
      "z": 17,
      "name": "Rock_Stone"
    },
    {
      "x": 8,
      "y": 39,
      "z": 17,
      "name": "Soil_Dirt"
    },
    {
      "x": 8,
      "y": 40,
      "z": 17,
      "name": "Soil_Dirt"
    },
    {
      "x": 8,
      "y": 41,
      "z": 17,
      "name": "Soil_Grass"
    },
    {
      "x": 8,
      "y": 42,
      "z": 17,
      "name": "Plant_Bush"
    },
    {
      "x": 8,
      "y": 38,
      "z": 18,
      "name": "Rock_Stone"
    },
    {
      "x": 8,
      "y": 39,
      "z": 18,
      "name": "Soil_Dirt"
    },
    {
      "x": 8,
      "y": 40,
      "z": 18,
      "name": "Soil_Dirt"
    },
    {
      "x": 9,
      "y": 24,
      "z": 8,
      "name": "Rock_Stone"
    },
    {
      "x": 9,
      "y": 25,
      "z": 8,
      "name": "Rock_Stone"
    },
    {
      "x": 9,
      "y": 26,
      "z": 8,
      "name": "Rock_Stone"
    },
    {
      "x": 9,
      "y": 24,
      "z": 9,
      "name": "Rock_Stone"
    },
    {
      "x": 9,
      "y": 25,
      "z": 9,
      "name": "Rock_Stone"
    },
    {
      "x": 9,
      "y": 26,
      "z": 9,
      "name": "Rock_Stone"
    },
    {
      "x": 9,
      "y": 27,
      "z": 9,
      "name": "Rock_Stone"
    },
    {
      "x": 9,
      "y": 28,
      "z": 9,
      "name": "Rock_Stone"
    },
    {
      "x": 9,
      "y": 23,
      "z": 10,
      "name": "Rock_Stone"
    },
    {
      "x": 9,
      "y": 24,
      "z": 10,
      "name": "Rock_Stone"
    },
    {
      "x": 9,
      "y": 25,
      "z": 10,
      "name": "Rock_Stone"
    },
    {
      "x": 9,
      "y": 26,
      "z": 10,
      "name": "Rock_Stone"
    },
    {
      "x": 9,
      "y": 27,
      "z": 10,
      "name": "Rock_Stone"
    },
    {
      "x": 9,
      "y": 28,
      "z": 10,
      "name": "Rock_Stone"
    },
    {
      "x": 9,
      "y": 29,
      "z": 10,
      "name": "Rock_Stone"
    },
    {
      "x": 9,
      "y": 37,
      "z": 10,
      "name": "Rock_Stone"
    },
    {
      "x": 9,
      "y": 38,
      "z": 10,
      "name": "Rock_Stone"
    },
    {
      "x": 9,
      "y": 39,
      "z": 10,
      "name": "Rock_Stone"
    },
    {
      "x": 9,
      "y": 40,
      "z": 10,
      "name": "Soil_Dirt"
    },
    {
      "x": 9,
      "y": 41,
      "z": 10,
      "name": "Soil_Dirt"
    },
    {
      "x": 9,
      "y": 42,
      "z": 10,
      "name": "Soil_Grass"
    },
    {
      "x": 9,
      "y": 23,
      "z": 11,
      "name": "Rock_Stone"
    },
    {
      "x": 9,
      "y": 24,
      "z": 11,
      "name": "Rock_Stone"
    },
    {
      "x": 9,
      "y": 25,
      "z": 11,
      "name": "Rock_Stone"
    },
    {
      "x": 9,
      "y": 26,
      "z": 11,
      "name": "Rock_Stone"
    },
    {
      "x": 9,
      "y": 27,
      "z": 11,
      "name": "Rock_Stone"
    },
    {
      "x": 9,
      "y": 28,
      "z": 11,
      "name": "Rock_Stone"
    },
    {
      "x": 9,
      "y": 29,
      "z": 11,
      "name": "Rock_Stone"
    },
    {
      "x": 9,
      "y": 30,
      "z": 11,
      "name": "Rock_Stone"
    },
    {
      "x": 9,
      "y": 31,
      "z": 11,
      "name": "Rock_Stone"
    },
    {
      "x": 9,
      "y": 36,
      "z": 11,
      "name": "Rock_Stone"
    },
    {
      "x": 9,
      "y": 37,
      "z": 11,
      "name": "Rock_Stone"
    },
    {
      "x": 9,
      "y": 38,
      "z": 11,
      "name": "Rock_Stone"
    },
    {
      "x": 9,
      "y": 39,
      "z": 11,
      "name": "Soil_Dirt"
    },
    {
      "x": 9,
      "y": 40,
      "z": 11,
      "name": "Soil_Dirt"
    },
    {
      "x": 9,
      "y": 41,
      "z": 11,
      "name": "Soil_Dirt"
    },
    {
      "x": 9,
      "y": 42,
      "z": 11,
      "name": "Soil_Dirt"
    },
    {
      "x": 9,
      "y": 43,
      "z": 11,
      "name": "Soil_Grass"
    },
    {
      "x": 9,
      "y": 44,
      "z": 11,
      "name": "Plant_Grass_Lush"
    },
    {
      "x": 9,
      "y": 24,
      "z": 12,
      "name": "Rock_Stone"
    },
    {
      "x": 9,
      "y": 25,
      "z": 12,
      "name": "Rock_Stone"
    },
    {
      "x": 9,
      "y": 26,
      "z": 12,
      "name": "Rock_Stone"
    },
    {
      "x": 9,
      "y": 27,
      "z": 12,
      "name": "Rock_Stone"
    },
    {
      "x": 9,
      "y": 28,
      "z": 12,
      "name": "Rock_Stone"
    },
    {
      "x": 9,
      "y": 29,
      "z": 12,
      "name": "Rock_Stone"
    },
    {
      "x": 9,
      "y": 30,
      "z": 12,
      "name": "Rock_Stone"
    },
    {
      "x": 9,
      "y": 31,
      "z": 12,
      "name": "Rock_Stone"
    },
    {
      "x": 9,
      "y": 32,
      "z": 12,
      "name": "Rock_Stone"
    },
    {
      "x": 9,
      "y": 33,
      "z": 12,
      "name": "Rock_Stone"
    },
    {
      "x": 9,
      "y": 34,
      "z": 12,
      "name": "Rock_Stone"
    },
    {
      "x": 9,
      "y": 35,
      "z": 12,
      "name": "Rock_Stone"
    },
    {
      "x": 9,
      "y": 36,
      "z": 12,
      "name": "Rock_Stone"
    },
    {
      "x": 9,
      "y": 37,
      "z": 12,
      "name": "Rock_Stone"
    },
    {
      "x": 9,
      "y": 38,
      "z": 12,
      "name": "Rock_Stone"
    },
    {
      "x": 9,
      "y": 39,
      "z": 12,
      "name": "Soil_Dirt"
    },
    {
      "x": 9,
      "y": 40,
      "z": 12,
      "name": "Soil_Dirt"
    },
    {
      "x": 9,
      "y": 41,
      "z": 12,
      "name": "Soil_Dirt"
    },
    {
      "x": 9,
      "y": 42,
      "z": 12,
      "name": "Soil_Dirt"
    },
    {
      "x": 9,
      "y": 43,
      "z": 12,
      "name": "Soil_Grass"
    },
    {
      "x": 9,
      "y": 26,
      "z": 13,
      "name": "Rock_Stone"
    },
    {
      "x": 9,
      "y": 27,
      "z": 13,
      "name": "Rock_Stone"
    },
    {
      "x": 9,
      "y": 28,
      "z": 13,
      "name": "Rock_Stone"
    },
    {
      "x": 9,
      "y": 29,
      "z": 13,
      "name": "Rock_Stone"
    },
    {
      "x": 9,
      "y": 30,
      "z": 13,
      "name": "Rock_Stone"
    },
    {
      "x": 9,
      "y": 31,
      "z": 13,
      "name": "Rock_Stone"
    },
    {
      "x": 9,
      "y": 32,
      "z": 13,
      "name": "Rock_Stone"
    },
    {
      "x": 9,
      "y": 33,
      "z": 13,
      "name": "Rock_Stone"
    },
    {
      "x": 9,
      "y": 34,
      "z": 13,
      "name": "Rock_Stone"
    },
    {
      "x": 9,
      "y": 35,
      "z": 13,
      "name": "Rock_Stone"
    },
    {
      "x": 9,
      "y": 36,
      "z": 13,
      "name": "Rock_Stone"
    },
    {
      "x": 9,
      "y": 37,
      "z": 13,
      "name": "Rock_Stone"
    },
    {
      "x": 9,
      "y": 38,
      "z": 13,
      "name": "Rock_Stone"
    },
    {
      "x": 9,
      "y": 39,
      "z": 13,
      "name": "Soil_Dirt"
    },
    {
      "x": 9,
      "y": 40,
      "z": 13,
      "name": "Soil_Dirt"
    },
    {
      "x": 9,
      "y": 41,
      "z": 13,
      "name": "Soil_Dirt"
    },
    {
      "x": 9,
      "y": 42,
      "z": 13,
      "name": "Soil_Dirt"
    },
    {
      "x": 9,
      "y": 43,
      "z": 13,
      "name": "Soil_Grass"
    },
    {
      "x": 9,
      "y": 44,
      "z": 13,
      "name": "Plant_Grass_Sharp"
    },
    {
      "x": 9,
      "y": 28,
      "z": 14,
      "name": "Rock_Stone"
    },
    {
      "x": 9,
      "y": 29,
      "z": 14,
      "name": "Rock_Stone"
    },
    {
      "x": 9,
      "y": 30,
      "z": 14,
      "name": "Rock_Stone"
    },
    {
      "x": 9,
      "y": 31,
      "z": 14,
      "name": "Rock_Stone"
    },
    {
      "x": 9,
      "y": 32,
      "z": 14,
      "name": "Rock_Stone"
    },
    {
      "x": 9,
      "y": 33,
      "z": 14,
      "name": "Rock_Stone"
    },
    {
      "x": 9,
      "y": 34,
      "z": 14,
      "name": "Rock_Stone"
    },
    {
      "x": 9,
      "y": 35,
      "z": 14,
      "name": "Rock_Stone"
    },
    {
      "x": 9,
      "y": 36,
      "z": 14,
      "name": "Rock_Stone"
    },
    {
      "x": 9,
      "y": 37,
      "z": 14,
      "name": "Rock_Stone"
    },
    {
      "x": 9,
      "y": 38,
      "z": 14,
      "name": "Rock_Stone"
    },
    {
      "x": 9,
      "y": 39,
      "z": 14,
      "name": "Soil_Dirt"
    },
    {
      "x": 9,
      "y": 40,
      "z": 14,
      "name": "Soil_Dirt"
    },
    {
      "x": 9,
      "y": 41,
      "z": 14,
      "name": "Soil_Dirt"
    },
    {
      "x": 9,
      "y": 42,
      "z": 14,
      "name": "Soil_Dirt"
    },
    {
      "x": 9,
      "y": 43,
      "z": 14,
      "name": "Soil_Grass"
    },
    {
      "x": 9,
      "y": 44,
      "z": 14,
      "name": "Plant_Grass_Lush"
    },
    {
      "x": 9,
      "y": 30,
      "z": 15,
      "name": "Rock_Stone"
    },
    {
      "x": 9,
      "y": 31,
      "z": 15,
      "name": "Rock_Stone"
    },
    {
      "x": 9,
      "y": 36,
      "z": 15,
      "name": "Rock_Stone"
    },
    {
      "x": 9,
      "y": 37,
      "z": 15,
      "name": "Rock_Stone"
    },
    {
      "x": 9,
      "y": 38,
      "z": 15,
      "name": "Rock_Stone"
    },
    {
      "x": 9,
      "y": 39,
      "z": 15,
      "name": "Soil_Dirt"
    },
    {
      "x": 9,
      "y": 40,
      "z": 15,
      "name": "Soil_Dirt"
    },
    {
      "x": 9,
      "y": 41,
      "z": 15,
      "name": "Soil_Dirt"
    },
    {
      "x": 9,
      "y": 42,
      "z": 15,
      "name": "Soil_Dirt"
    },
    {
      "x": 9,
      "y": 43,
      "z": 15,
      "name": "Soil_Grass"
    },
    {
      "x": 9,
      "y": 38,
      "z": 16,
      "name": "Rock_Stone"
    },
    {
      "x": 9,
      "y": 39,
      "z": 16,
      "name": "Soil_Dirt"
    },
    {
      "x": 9,
      "y": 40,
      "z": 16,
      "name": "Soil_Dirt"
    },
    {
      "x": 9,
      "y": 41,
      "z": 16,
      "name": "Soil_Dirt"
    },
    {
      "x": 9,
      "y": 42,
      "z": 16,
      "name": "Soil_Dirt"
    },
    {
      "x": 9,
      "y": 43,
      "z": 16,
      "name": "Soil_Grass"
    },
    {
      "x": 9,
      "y": 44,
      "z": 16,
      "name": "Plant_Grass_Sharp"
    },
    {
      "x": 9,
      "y": 38,
      "z": 17,
      "name": "Rock_Stone"
    },
    {
      "x": 9,
      "y": 39,
      "z": 17,
      "name": "Soil_Dirt"
    },
    {
      "x": 9,
      "y": 40,
      "z": 17,
      "name": "Soil_Dirt"
    },
    {
      "x": 9,
      "y": 41,
      "z": 17,
      "name": "Soil_Dirt"
    },
    {
      "x": 9,
      "y": 42,
      "z": 17,
      "name": "Soil_Dirt"
    },
    {
      "x": 9,
      "y": 43,
      "z": 17,
      "name": "Soil_Grass"
    },
    {
      "x": 9,
      "y": 44,
      "z": 17,
      "name": "Plant_Grass_Sharp"
    },
    {
      "x": 9,
      "y": 38,
      "z": 18,
      "name": "Rock_Stone"
    },
    {
      "x": 9,
      "y": 39,
      "z": 18,
      "name": "Soil_Dirt"
    },
    {
      "x": 9,
      "y": 40,
      "z": 18,
      "name": "Soil_Dirt"
    },
    {
      "x": 9,
      "y": 41,
      "z": 18,
      "name": "Soil_Dirt"
    },
    {
      "x": 9,
      "y": 42,
      "z": 18,
      "name": "Soil_Dirt"
    },
    {
      "x": 9,
      "y": 43,
      "z": 18,
      "name": "Soil_Grass"
    },
    {
      "x": 10,
      "y": 25,
      "z": 7,
      "name": "Rock_Stone"
    },
    {
      "x": 10,
      "y": 26,
      "z": 7,
      "name": "Rock_Stone"
    },
    {
      "x": 10,
      "y": 22,
      "z": 8,
      "name": "Rock_Stone"
    },
    {
      "x": 10,
      "y": 23,
      "z": 8,
      "name": "Rock_Stone"
    },
    {
      "x": 10,
      "y": 24,
      "z": 8,
      "name": "Rock_Stone"
    },
    {
      "x": 10,
      "y": 25,
      "z": 8,
      "name": "Rock_Stone"
    },
    {
      "x": 10,
      "y": 26,
      "z": 8,
      "name": "Rock_Stone"
    },
    {
      "x": 10,
      "y": 22,
      "z": 9,
      "name": "Rock_Stone"
    },
    {
      "x": 10,
      "y": 23,
      "z": 9,
      "name": "Rock_Stone"
    },
    {
      "x": 10,
      "y": 24,
      "z": 9,
      "name": "Rock_Stone"
    },
    {
      "x": 10,
      "y": 25,
      "z": 9,
      "name": "Rock_Stone"
    },
    {
      "x": 10,
      "y": 26,
      "z": 9,
      "name": "Rock_Stone"
    },
    {
      "x": 10,
      "y": 27,
      "z": 9,
      "name": "Rock_Stone"
    },
    {
      "x": 10,
      "y": 28,
      "z": 9,
      "name": "Rock_Stone"
    },
    {
      "x": 10,
      "y": 22,
      "z": 10,
      "name": "Rock_Stone"
    },
    {
      "x": 10,
      "y": 23,
      "z": 10,
      "name": "Rock_Stone"
    },
    {
      "x": 10,
      "y": 24,
      "z": 10,
      "name": "Rock_Stone"
    },
    {
      "x": 10,
      "y": 25,
      "z": 10,
      "name": "Rock_Stone"
    },
    {
      "x": 10,
      "y": 26,
      "z": 10,
      "name": "Rock_Stone"
    },
    {
      "x": 10,
      "y": 27,
      "z": 10,
      "name": "Rock_Stone"
    },
    {
      "x": 10,
      "y": 28,
      "z": 10,
      "name": "Rock_Stone"
    },
    {
      "x": 10,
      "y": 38,
      "z": 10,
      "name": "Rock_Stone"
    },
    {
      "x": 10,
      "y": 39,
      "z": 10,
      "name": "Rock_Stone"
    },
    {
      "x": 10,
      "y": 40,
      "z": 10,
      "name": "Rock_Stone"
    },
    {
      "x": 10,
      "y": 41,
      "z": 10,
      "name": "Soil_Dirt"
    },
    {
      "x": 10,
      "y": 42,
      "z": 10,
      "name": "Soil_Dirt"
    },
    {
      "x": 10,
      "y": 43,
      "z": 10,
      "name": "Soil_Grass"
    },
    {
      "x": 10,
      "y": 23,
      "z": 11,
      "name": "Rock_Stone"
    },
    {
      "x": 10,
      "y": 24,
      "z": 11,
      "name": "Rock_Stone"
    },
    {
      "x": 10,
      "y": 25,
      "z": 11,
      "name": "Rock_Stone"
    },
    {
      "x": 10,
      "y": 26,
      "z": 11,
      "name": "Rock_Stone"
    },
    {
      "x": 10,
      "y": 27,
      "z": 11,
      "name": "Rock_Stone"
    },
    {
      "x": 10,
      "y": 28,
      "z": 11,
      "name": "Rock_Stone"
    },
    {
      "x": 10,
      "y": 29,
      "z": 11,
      "name": "Rock_Stone"
    },
    {
      "x": 10,
      "y": 30,
      "z": 11,
      "name": "Rock_Stone"
    },
    {
      "x": 10,
      "y": 36,
      "z": 11,
      "name": "Rock_Stone"
    },
    {
      "x": 10,
      "y": 37,
      "z": 11,
      "name": "Rock_Stone"
    },
    {
      "x": 10,
      "y": 38,
      "z": 11,
      "name": "Rock_Stone"
    },
    {
      "x": 10,
      "y": 39,
      "z": 11,
      "name": "Rock_Stone"
    },
    {
      "x": 10,
      "y": 40,
      "z": 11,
      "name": "Soil_Dirt"
    },
    {
      "x": 10,
      "y": 41,
      "z": 11,
      "name": "Soil_Dirt"
    },
    {
      "x": 10,
      "y": 42,
      "z": 11,
      "name": "Soil_Dirt"
    },
    {
      "x": 10,
      "y": 43,
      "z": 11,
      "name": "Soil_Grass"
    },
    {
      "x": 10,
      "y": 24,
      "z": 12,
      "name": "Rock_Stone"
    },
    {
      "x": 10,
      "y": 25,
      "z": 12,
      "name": "Rock_Stone"
    },
    {
      "x": 10,
      "y": 26,
      "z": 12,
      "name": "Rock_Stone"
    },
    {
      "x": 10,
      "y": 27,
      "z": 12,
      "name": "Rock_Stone"
    },
    {
      "x": 10,
      "y": 28,
      "z": 12,
      "name": "Rock_Stone"
    },
    {
      "x": 10,
      "y": 29,
      "z": 12,
      "name": "Rock_Stone"
    },
    {
      "x": 10,
      "y": 30,
      "z": 12,
      "name": "Rock_Stone"
    },
    {
      "x": 10,
      "y": 31,
      "z": 12,
      "name": "Rock_Stone"
    },
    {
      "x": 10,
      "y": 36,
      "z": 12,
      "name": "Rock_Stone"
    },
    {
      "x": 10,
      "y": 37,
      "z": 12,
      "name": "Rock_Stone"
    },
    {
      "x": 10,
      "y": 38,
      "z": 12,
      "name": "Rock_Stone"
    },
    {
      "x": 10,
      "y": 39,
      "z": 12,
      "name": "Rock_Stone"
    },
    {
      "x": 10,
      "y": 40,
      "z": 12,
      "name": "Soil_Dirt"
    },
    {
      "x": 10,
      "y": 41,
      "z": 12,
      "name": "Soil_Dirt"
    },
    {
      "x": 10,
      "y": 42,
      "z": 12,
      "name": "Soil_Dirt"
    },
    {
      "x": 10,
      "y": 43,
      "z": 12,
      "name": "Soil_Grass"
    },
    {
      "x": 10,
      "y": 44,
      "z": 12,
      "name": "Plant_Moss_Rug_Green"
    },
    {
      "x": 10,
      "y": 27,
      "z": 13,
      "name": "Rock_Stone"
    },
    {
      "x": 10,
      "y": 28,
      "z": 13,
      "name": "Rock_Stone"
    },
    {
      "x": 10,
      "y": 29,
      "z": 13,
      "name": "Rock_Stone"
    },
    {
      "x": 10,
      "y": 30,
      "z": 13,
      "name": "Rock_Stone"
    },
    {
      "x": 10,
      "y": 31,
      "z": 13,
      "name": "Rock_Stone"
    },
    {
      "x": 10,
      "y": 36,
      "z": 13,
      "name": "Rock_Stone"
    },
    {
      "x": 10,
      "y": 37,
      "z": 13,
      "name": "Rock_Stone"
    },
    {
      "x": 10,
      "y": 38,
      "z": 13,
      "name": "Rock_Stone"
    },
    {
      "x": 10,
      "y": 39,
      "z": 13,
      "name": "Rock_Stone"
    },
    {
      "x": 10,
      "y": 40,
      "z": 13,
      "name": "Soil_Dirt"
    },
    {
      "x": 10,
      "y": 41,
      "z": 13,
      "name": "Soil_Dirt"
    },
    {
      "x": 10,
      "y": 42,
      "z": 13,
      "name": "Soil_Dirt"
    },
    {
      "x": 10,
      "y": 43,
      "z": 13,
      "name": "Soil_Grass"
    },
    {
      "x": 10,
      "y": 44,
      "z": 13,
      "name": "Plant_Moss_Rug_Green"
    },
    {
      "x": 10,
      "y": 37,
      "z": 14,
      "name": "Rock_Stone"
    },
    {
      "x": 10,
      "y": 38,
      "z": 14,
      "name": "Rock_Stone"
    },
    {
      "x": 10,
      "y": 39,
      "z": 14,
      "name": "Rock_Stone"
    },
    {
      "x": 10,
      "y": 40,
      "z": 14,
      "name": "Soil_Dirt"
    },
    {
      "x": 10,
      "y": 41,
      "z": 14,
      "name": "Soil_Dirt"
    },
    {
      "x": 10,
      "y": 42,
      "z": 14,
      "name": "Soil_Dirt"
    },
    {
      "x": 10,
      "y": 43,
      "z": 14,
      "name": "Soil_Dirt"
    },
    {
      "x": 10,
      "y": 44,
      "z": 14,
      "name": "Soil_Grass"
    },
    {
      "x": 10,
      "y": 38,
      "z": 15,
      "name": "Rock_Stone"
    },
    {
      "x": 10,
      "y": 39,
      "z": 15,
      "name": "Rock_Stone"
    },
    {
      "x": 10,
      "y": 40,
      "z": 15,
      "name": "Soil_Dirt"
    },
    {
      "x": 10,
      "y": 41,
      "z": 15,
      "name": "Soil_Dirt"
    },
    {
      "x": 10,
      "y": 42,
      "z": 15,
      "name": "Soil_Dirt"
    },
    {
      "x": 10,
      "y": 43,
      "z": 15,
      "name": "Soil_Dirt"
    },
    {
      "x": 10,
      "y": 44,
      "z": 15,
      "name": "Soil_Grass"
    },
    {
      "x": 10,
      "y": 45,
      "z": 15,
      "name": "Plant_Grass_Sharp"
    },
    {
      "x": 10,
      "y": 38,
      "z": 16,
      "name": "Rock_Stone"
    },
    {
      "x": 10,
      "y": 39,
      "z": 16,
      "name": "Rock_Stone"
    },
    {
      "x": 10,
      "y": 40,
      "z": 16,
      "name": "Soil_Dirt"
    },
    {
      "x": 10,
      "y": 41,
      "z": 16,
      "name": "Soil_Dirt"
    },
    {
      "x": 10,
      "y": 42,
      "z": 16,
      "name": "Soil_Dirt"
    },
    {
      "x": 10,
      "y": 43,
      "z": 16,
      "name": "Soil_Dirt"
    },
    {
      "x": 10,
      "y": 44,
      "z": 16,
      "name": "Soil_Grass"
    },
    {
      "x": 10,
      "y": 38,
      "z": 17,
      "name": "Rock_Stone"
    },
    {
      "x": 10,
      "y": 39,
      "z": 17,
      "name": "Rock_Stone"
    },
    {
      "x": 10,
      "y": 40,
      "z": 17,
      "name": "Soil_Dirt"
    },
    {
      "x": 10,
      "y": 41,
      "z": 17,
      "name": "Soil_Dirt"
    },
    {
      "x": 10,
      "y": 42,
      "z": 17,
      "name": "Soil_Dirt"
    },
    {
      "x": 10,
      "y": 43,
      "z": 17,
      "name": "Soil_Dirt"
    },
    {
      "x": 10,
      "y": 44,
      "z": 17,
      "name": "Soil_Dirt"
    },
    {
      "x": 10,
      "y": 45,
      "z": 17,
      "name": "Soil_Grass"
    },
    {
      "x": 10,
      "y": 46,
      "z": 17,
      "name": "Plant_Grass_Sharp"
    },
    {
      "x": 10,
      "y": 39,
      "z": 18,
      "name": "Rock_Stone"
    },
    {
      "x": 10,
      "y": 40,
      "z": 18,
      "name": "Soil_Dirt"
    },
    {
      "x": 10,
      "y": 41,
      "z": 18,
      "name": "Soil_Dirt"
    },
    {
      "x": 10,
      "y": 42,
      "z": 18,
      "name": "Soil_Dirt"
    },
    {
      "x": 10,
      "y": 43,
      "z": 18,
      "name": "Soil_Dirt"
    },
    {
      "x": 10,
      "y": 44,
      "z": 18,
      "name": "Soil_Grass"
    },
    {
      "x": 10,
      "y": 40,
      "z": 19,
      "name": "Rock_Stone"
    },
    {
      "x": 10,
      "y": 41,
      "z": 19,
      "name": "Soil_Dirt"
    },
    {
      "x": 11,
      "y": 22,
      "z": 7,
      "name": "Rock_Stone"
    },
    {
      "x": 11,
      "y": 23,
      "z": 7,
      "name": "Rock_Stone"
    },
    {
      "x": 11,
      "y": 24,
      "z": 7,
      "name": "Rock_Stone"
    },
    {
      "x": 11,
      "y": 25,
      "z": 7,
      "name": "Rock_Stone"
    },
    {
      "x": 11,
      "y": 26,
      "z": 7,
      "name": "Rock_Stone"
    },
    {
      "x": 11,
      "y": 22,
      "z": 8,
      "name": "Rock_Stone"
    },
    {
      "x": 11,
      "y": 23,
      "z": 8,
      "name": "Rock_Stone"
    },
    {
      "x": 11,
      "y": 24,
      "z": 8,
      "name": "Rock_Stone"
    },
    {
      "x": 11,
      "y": 25,
      "z": 8,
      "name": "Rock_Stone"
    },
    {
      "x": 11,
      "y": 26,
      "z": 8,
      "name": "Rock_Stone"
    },
    {
      "x": 11,
      "y": 21,
      "z": 9,
      "name": "Rock_Stone"
    },
    {
      "x": 11,
      "y": 22,
      "z": 9,
      "name": "Rock_Stone"
    },
    {
      "x": 11,
      "y": 23,
      "z": 9,
      "name": "Rock_Stone"
    },
    {
      "x": 11,
      "y": 24,
      "z": 9,
      "name": "Rock_Stone"
    },
    {
      "x": 11,
      "y": 25,
      "z": 9,
      "name": "Rock_Stone"
    },
    {
      "x": 11,
      "y": 26,
      "z": 9,
      "name": "Rock_Stone"
    },
    {
      "x": 11,
      "y": 27,
      "z": 9,
      "name": "Rock_Stone"
    },
    {
      "x": 11,
      "y": 28,
      "z": 9,
      "name": "Rock_Stone"
    },
    {
      "x": 11,
      "y": 41,
      "z": 9,
      "name": "Soil_Dirt"
    },
    {
      "x": 11,
      "y": 42,
      "z": 9,
      "name": "Soil_Dirt"
    },
    {
      "x": 11,
      "y": 43,
      "z": 9,
      "name": "Soil_Grass"
    },
    {
      "x": 11,
      "y": 22,
      "z": 10,
      "name": "Rock_Stone"
    },
    {
      "x": 11,
      "y": 23,
      "z": 10,
      "name": "Rock_Stone"
    },
    {
      "x": 11,
      "y": 24,
      "z": 10,
      "name": "Rock_Stone"
    },
    {
      "x": 11,
      "y": 25,
      "z": 10,
      "name": "Rock_Stone"
    },
    {
      "x": 11,
      "y": 26,
      "z": 10,
      "name": "Rock_Stone"
    },
    {
      "x": 11,
      "y": 27,
      "z": 10,
      "name": "Rock_Stone"
    },
    {
      "x": 11,
      "y": 28,
      "z": 10,
      "name": "Rock_Stone"
    },
    {
      "x": 11,
      "y": 38,
      "z": 10,
      "name": "Rock_Stone"
    },
    {
      "x": 11,
      "y": 39,
      "z": 10,
      "name": "Rock_Stone"
    },
    {
      "x": 11,
      "y": 40,
      "z": 10,
      "name": "Rock_Stone"
    },
    {
      "x": 11,
      "y": 41,
      "z": 10,
      "name": "Soil_Dirt"
    },
    {
      "x": 11,
      "y": 42,
      "z": 10,
      "name": "Soil_Dirt"
    },
    {
      "x": 11,
      "y": 43,
      "z": 10,
      "name": "Soil_Grass"
    },
    {
      "x": 11,
      "y": 44,
      "z": 10,
      "name": "Plant_Moss_Rug_Green"
    },
    {
      "x": 11,
      "y": 24,
      "z": 11,
      "name": "Rock_Stone"
    },
    {
      "x": 11,
      "y": 25,
      "z": 11,
      "name": "Rock_Stone"
    },
    {
      "x": 11,
      "y": 26,
      "z": 11,
      "name": "Rock_Stone"
    },
    {
      "x": 11,
      "y": 27,
      "z": 11,
      "name": "Rock_Stone"
    },
    {
      "x": 11,
      "y": 28,
      "z": 11,
      "name": "Rock_Stone"
    },
    {
      "x": 11,
      "y": 29,
      "z": 11,
      "name": "Rock_Stone"
    },
    {
      "x": 11,
      "y": 38,
      "z": 11,
      "name": "Rock_Stone"
    },
    {
      "x": 11,
      "y": 39,
      "z": 11,
      "name": "Rock_Stone"
    },
    {
      "x": 11,
      "y": 40,
      "z": 11,
      "name": "Rock_Stone"
    },
    {
      "x": 11,
      "y": 41,
      "z": 11,
      "name": "Soil_Dirt"
    },
    {
      "x": 11,
      "y": 42,
      "z": 11,
      "name": "Soil_Dirt"
    },
    {
      "x": 11,
      "y": 43,
      "z": 11,
      "name": "Soil_Dirt"
    },
    {
      "x": 11,
      "y": 44,
      "z": 11,
      "name": "Soil_Grass"
    },
    {
      "x": 11,
      "y": 45,
      "z": 11,
      "name": "Plant_Moss_Rug_Green"
    },
    {
      "x": 11,
      "y": 24,
      "z": 12,
      "name": "Rock_Stone"
    },
    {
      "x": 11,
      "y": 25,
      "z": 12,
      "name": "Rock_Stone"
    },
    {
      "x": 11,
      "y": 26,
      "z": 12,
      "name": "Rock_Stone"
    },
    {
      "x": 11,
      "y": 27,
      "z": 12,
      "name": "Rock_Stone"
    },
    {
      "x": 11,
      "y": 28,
      "z": 12,
      "name": "Rock_Stone"
    },
    {
      "x": 11,
      "y": 29,
      "z": 12,
      "name": "Rock_Stone"
    },
    {
      "x": 11,
      "y": 38,
      "z": 12,
      "name": "Rock_Stone"
    },
    {
      "x": 11,
      "y": 39,
      "z": 12,
      "name": "Rock_Stone"
    },
    {
      "x": 11,
      "y": 40,
      "z": 12,
      "name": "Rock_Stone"
    },
    {
      "x": 11,
      "y": 41,
      "z": 12,
      "name": "Soil_Dirt"
    },
    {
      "x": 11,
      "y": 42,
      "z": 12,
      "name": "Soil_Dirt"
    },
    {
      "x": 11,
      "y": 43,
      "z": 12,
      "name": "Soil_Dirt"
    },
    {
      "x": 11,
      "y": 44,
      "z": 12,
      "name": "Soil_Grass"
    },
    {
      "x": 11,
      "y": 45,
      "z": 12,
      "name": "Plant_Bush"
    },
    {
      "x": 11,
      "y": 27,
      "z": 13,
      "name": "Rock_Stone"
    },
    {
      "x": 11,
      "y": 28,
      "z": 13,
      "name": "Rock_Stone"
    },
    {
      "x": 11,
      "y": 38,
      "z": 13,
      "name": "Rock_Stone"
    },
    {
      "x": 11,
      "y": 39,
      "z": 13,
      "name": "Rock_Stone"
    },
    {
      "x": 11,
      "y": 40,
      "z": 13,
      "name": "Rock_Stone"
    },
    {
      "x": 11,
      "y": 41,
      "z": 13,
      "name": "Soil_Dirt"
    },
    {
      "x": 11,
      "y": 42,
      "z": 13,
      "name": "Soil_Dirt"
    },
    {
      "x": 11,
      "y": 43,
      "z": 13,
      "name": "Soil_Dirt"
    },
    {
      "x": 11,
      "y": 44,
      "z": 13,
      "name": "Soil_Grass"
    },
    {
      "x": 11,
      "y": 38,
      "z": 14,
      "name": "Rock_Stone"
    },
    {
      "x": 11,
      "y": 39,
      "z": 14,
      "name": "Rock_Stone"
    },
    {
      "x": 11,
      "y": 40,
      "z": 14,
      "name": "Rock_Stone"
    },
    {
      "x": 11,
      "y": 41,
      "z": 14,
      "name": "Soil_Dirt"
    },
    {
      "x": 11,
      "y": 42,
      "z": 14,
      "name": "Soil_Dirt"
    },
    {
      "x": 11,
      "y": 43,
      "z": 14,
      "name": "Soil_Dirt"
    },
    {
      "x": 11,
      "y": 44,
      "z": 14,
      "name": "Soil_Dirt"
    },
    {
      "x": 11,
      "y": 45,
      "z": 14,
      "name": "Soil_Grass"
    },
    {
      "x": 11,
      "y": 46,
      "z": 14,
      "name": "Plant_Grass_Lush"
    },
    {
      "x": 11,
      "y": 38,
      "z": 15,
      "name": "Rock_Stone"
    },
    {
      "x": 11,
      "y": 39,
      "z": 15,
      "name": "Rock_Stone"
    },
    {
      "x": 11,
      "y": 40,
      "z": 15,
      "name": "Rock_Stone"
    },
    {
      "x": 11,
      "y": 41,
      "z": 15,
      "name": "Soil_Dirt"
    },
    {
      "x": 11,
      "y": 42,
      "z": 15,
      "name": "Soil_Dirt"
    },
    {
      "x": 11,
      "y": 43,
      "z": 15,
      "name": "Soil_Dirt"
    },
    {
      "x": 11,
      "y": 44,
      "z": 15,
      "name": "Soil_Dirt"
    },
    {
      "x": 11,
      "y": 45,
      "z": 15,
      "name": "Soil_Grass"
    },
    {
      "x": 11,
      "y": 38,
      "z": 16,
      "name": "Rock_Stone"
    },
    {
      "x": 11,
      "y": 39,
      "z": 16,
      "name": "Rock_Stone"
    },
    {
      "x": 11,
      "y": 40,
      "z": 16,
      "name": "Rock_Stone"
    },
    {
      "x": 11,
      "y": 41,
      "z": 16,
      "name": "Soil_Dirt"
    },
    {
      "x": 11,
      "y": 42,
      "z": 16,
      "name": "Soil_Dirt"
    },
    {
      "x": 11,
      "y": 43,
      "z": 16,
      "name": "Soil_Dirt"
    },
    {
      "x": 11,
      "y": 44,
      "z": 16,
      "name": "Soil_Dirt"
    },
    {
      "x": 11,
      "y": 45,
      "z": 16,
      "name": "Soil_Grass"
    },
    {
      "x": 11,
      "y": 46,
      "z": 16,
      "name": "Plant_Grass_Lush"
    },
    {
      "x": 11,
      "y": 38,
      "z": 17,
      "name": "Rock_Stone"
    },
    {
      "x": 11,
      "y": 39,
      "z": 17,
      "name": "Rock_Stone"
    },
    {
      "x": 11,
      "y": 40,
      "z": 17,
      "name": "Rock_Stone"
    },
    {
      "x": 11,
      "y": 41,
      "z": 17,
      "name": "Soil_Dirt"
    },
    {
      "x": 11,
      "y": 42,
      "z": 17,
      "name": "Soil_Dirt"
    },
    {
      "x": 11,
      "y": 43,
      "z": 17,
      "name": "Soil_Dirt"
    },
    {
      "x": 11,
      "y": 44,
      "z": 17,
      "name": "Soil_Dirt"
    },
    {
      "x": 11,
      "y": 45,
      "z": 17,
      "name": "Soil_Grass"
    },
    {
      "x": 11,
      "y": 39,
      "z": 18,
      "name": "Rock_Stone"
    },
    {
      "x": 11,
      "y": 40,
      "z": 18,
      "name": "Rock_Stone"
    },
    {
      "x": 11,
      "y": 41,
      "z": 18,
      "name": "Soil_Dirt"
    },
    {
      "x": 11,
      "y": 42,
      "z": 18,
      "name": "Soil_Dirt"
    },
    {
      "x": 11,
      "y": 43,
      "z": 18,
      "name": "Soil_Dirt"
    },
    {
      "x": 11,
      "y": 44,
      "z": 18,
      "name": "Soil_Dirt"
    },
    {
      "x": 11,
      "y": 45,
      "z": 18,
      "name": "Soil_Grass"
    },
    {
      "x": 11,
      "y": 40,
      "z": 19,
      "name": "Rock_Stone"
    },
    {
      "x": 11,
      "y": 41,
      "z": 19,
      "name": "Rock_Stone"
    },
    {
      "x": 11,
      "y": 42,
      "z": 19,
      "name": "Rock_Stone"
    },
    {
      "x": 11,
      "y": 43,
      "z": 19,
      "name": "Soil_Grass"
    },
    {
      "x": 11,
      "y": 44,
      "z": 19,
      "name": "Plant_Moss_Rug_Green"
    },
    {
      "x": 12,
      "y": 24,
      "z": 6,
      "name": "Rock_Stone"
    },
    {
      "x": 12,
      "y": 21,
      "z": 7,
      "name": "Rock_Stone"
    },
    {
      "x": 12,
      "y": 22,
      "z": 7,
      "name": "Rock_Stone"
    },
    {
      "x": 12,
      "y": 23,
      "z": 7,
      "name": "Rock_Stone"
    },
    {
      "x": 12,
      "y": 24,
      "z": 7,
      "name": "Rock_Stone"
    },
    {
      "x": 12,
      "y": 25,
      "z": 7,
      "name": "Rock_Stone"
    },
    {
      "x": 12,
      "y": 26,
      "z": 7,
      "name": "Rock_Stone"
    },
    {
      "x": 12,
      "y": 20,
      "z": 8,
      "name": "Rock_Stone"
    },
    {
      "x": 12,
      "y": 21,
      "z": 8,
      "name": "Rock_Stone"
    },
    {
      "x": 12,
      "y": 22,
      "z": 8,
      "name": "Rock_Stone"
    },
    {
      "x": 12,
      "y": 23,
      "z": 8,
      "name": "Rock_Stone"
    },
    {
      "x": 12,
      "y": 24,
      "z": 8,
      "name": "Rock_Stone"
    },
    {
      "x": 12,
      "y": 25,
      "z": 8,
      "name": "Rock_Stone"
    },
    {
      "x": 12,
      "y": 26,
      "z": 8,
      "name": "Rock_Stone"
    },
    {
      "x": 12,
      "y": 21,
      "z": 9,
      "name": "Rock_Stone"
    },
    {
      "x": 12,
      "y": 22,
      "z": 9,
      "name": "Rock_Stone"
    },
    {
      "x": 12,
      "y": 23,
      "z": 9,
      "name": "Rock_Stone"
    },
    {
      "x": 12,
      "y": 24,
      "z": 9,
      "name": "Rock_Stone"
    },
    {
      "x": 12,
      "y": 25,
      "z": 9,
      "name": "Rock_Stone"
    },
    {
      "x": 12,
      "y": 26,
      "z": 9,
      "name": "Rock_Stone"
    },
    {
      "x": 12,
      "y": 27,
      "z": 9,
      "name": "Rock_Stone"
    },
    {
      "x": 12,
      "y": 41,
      "z": 9,
      "name": "Soil_Dirt"
    },
    {
      "x": 12,
      "y": 42,
      "z": 9,
      "name": "Soil_Dirt"
    },
    {
      "x": 12,
      "y": 43,
      "z": 9,
      "name": "Soil_Dirt"
    },
    {
      "x": 12,
      "y": 44,
      "z": 9,
      "name": "Soil_Grass"
    },
    {
      "x": 12,
      "y": 23,
      "z": 10,
      "name": "Rock_Stone"
    },
    {
      "x": 12,
      "y": 24,
      "z": 10,
      "name": "Rock_Stone"
    },
    {
      "x": 12,
      "y": 25,
      "z": 10,
      "name": "Rock_Stone"
    },
    {
      "x": 12,
      "y": 26,
      "z": 10,
      "name": "Rock_Stone"
    },
    {
      "x": 12,
      "y": 27,
      "z": 10,
      "name": "Rock_Stone"
    },
    {
      "x": 12,
      "y": 28,
      "z": 10,
      "name": "Rock_Stone"
    },
    {
      "x": 12,
      "y": 39,
      "z": 10,
      "name": "Rock_Stone"
    },
    {
      "x": 12,
      "y": 40,
      "z": 10,
      "name": "Rock_Stone"
    },
    {
      "x": 12,
      "y": 41,
      "z": 10,
      "name": "Soil_Dirt"
    },
    {
      "x": 12,
      "y": 42,
      "z": 10,
      "name": "Soil_Dirt"
    },
    {
      "x": 12,
      "y": 43,
      "z": 10,
      "name": "Soil_Dirt"
    },
    {
      "x": 12,
      "y": 44,
      "z": 10,
      "name": "Soil_Grass"
    },
    {
      "x": 12,
      "y": 24,
      "z": 11,
      "name": "Rock_Stone"
    },
    {
      "x": 12,
      "y": 25,
      "z": 11,
      "name": "Rock_Stone"
    },
    {
      "x": 12,
      "y": 26,
      "z": 11,
      "name": "Rock_Stone"
    },
    {
      "x": 12,
      "y": 27,
      "z": 11,
      "name": "Rock_Stone"
    },
    {
      "x": 12,
      "y": 28,
      "z": 11,
      "name": "Rock_Stone"
    },
    {
      "x": 12,
      "y": 39,
      "z": 11,
      "name": "Rock_Stone"
    },
    {
      "x": 12,
      "y": 40,
      "z": 11,
      "name": "Rock_Stone"
    },
    {
      "x": 12,
      "y": 41,
      "z": 11,
      "name": "Soil_Dirt"
    },
    {
      "x": 12,
      "y": 42,
      "z": 11,
      "name": "Soil_Dirt"
    },
    {
      "x": 12,
      "y": 43,
      "z": 11,
      "name": "Soil_Dirt"
    },
    {
      "x": 12,
      "y": 44,
      "z": 11,
      "name": "Soil_Grass"
    },
    {
      "x": 12,
      "y": 45,
      "z": 11,
      "name": "Plant_Moss_Rug_Green"
    },
    {
      "x": 12,
      "y": 26,
      "z": 12,
      "name": "Rock_Stone"
    },
    {
      "x": 12,
      "y": 27,
      "z": 12,
      "name": "Rock_Stone"
    },
    {
      "x": 12,
      "y": 38,
      "z": 12,
      "name": "Rock_Stone"
    },
    {
      "x": 12,
      "y": 39,
      "z": 12,
      "name": "Rock_Stone"
    },
    {
      "x": 12,
      "y": 40,
      "z": 12,
      "name": "Rock_Stone"
    },
    {
      "x": 12,
      "y": 41,
      "z": 12,
      "name": "Soil_Dirt"
    },
    {
      "x": 12,
      "y": 42,
      "z": 12,
      "name": "Soil_Dirt"
    },
    {
      "x": 12,
      "y": 43,
      "z": 12,
      "name": "Soil_Dirt"
    },
    {
      "x": 12,
      "y": 44,
      "z": 12,
      "name": "Soil_Grass"
    },
    {
      "x": 12,
      "y": 38,
      "z": 13,
      "name": "Rock_Stone"
    },
    {
      "x": 12,
      "y": 39,
      "z": 13,
      "name": "Rock_Stone"
    },
    {
      "x": 12,
      "y": 40,
      "z": 13,
      "name": "Rock_Stone"
    },
    {
      "x": 12,
      "y": 41,
      "z": 13,
      "name": "Soil_Dirt"
    },
    {
      "x": 12,
      "y": 42,
      "z": 13,
      "name": "Soil_Dirt"
    },
    {
      "x": 12,
      "y": 43,
      "z": 13,
      "name": "Soil_Dirt"
    },
    {
      "x": 12,
      "y": 44,
      "z": 13,
      "name": "Soil_Grass"
    },
    {
      "x": 12,
      "y": 38,
      "z": 14,
      "name": "Rock_Stone"
    },
    {
      "x": 12,
      "y": 39,
      "z": 14,
      "name": "Rock_Stone"
    },
    {
      "x": 12,
      "y": 40,
      "z": 14,
      "name": "Rock_Stone"
    },
    {
      "x": 12,
      "y": 41,
      "z": 14,
      "name": "Soil_Dirt"
    },
    {
      "x": 12,
      "y": 42,
      "z": 14,
      "name": "Soil_Dirt"
    },
    {
      "x": 12,
      "y": 43,
      "z": 14,
      "name": "Soil_Dirt"
    },
    {
      "x": 12,
      "y": 44,
      "z": 14,
      "name": "Soil_Dirt"
    },
    {
      "x": 12,
      "y": 45,
      "z": 14,
      "name": "Soil_Dirt"
    },
    {
      "x": 12,
      "y": 46,
      "z": 14,
      "name": "Soil_Grass"
    },
    {
      "x": 12,
      "y": 47,
      "z": 14,
      "name": "Plant_Bush"
    },
    {
      "x": 12,
      "y": 38,
      "z": 15,
      "name": "Rock_Stone"
    },
    {
      "x": 12,
      "y": 39,
      "z": 15,
      "name": "Rock_Stone"
    },
    {
      "x": 12,
      "y": 40,
      "z": 15,
      "name": "Rock_Stone"
    },
    {
      "x": 12,
      "y": 41,
      "z": 15,
      "name": "Rock_Stone"
    },
    {
      "x": 12,
      "y": 42,
      "z": 15,
      "name": "Soil_Dirt"
    },
    {
      "x": 12,
      "y": 43,
      "z": 15,
      "name": "Soil_Dirt"
    },
    {
      "x": 12,
      "y": 44,
      "z": 15,
      "name": "Soil_Dirt"
    },
    {
      "x": 12,
      "y": 45,
      "z": 15,
      "name": "Soil_Dirt"
    },
    {
      "x": 12,
      "y": 46,
      "z": 15,
      "name": "Soil_Grass"
    },
    {
      "x": 12,
      "y": 38,
      "z": 16,
      "name": "Rock_Stone"
    },
    {
      "x": 12,
      "y": 39,
      "z": 16,
      "name": "Rock_Stone"
    },
    {
      "x": 12,
      "y": 40,
      "z": 16,
      "name": "Rock_Stone"
    },
    {
      "x": 12,
      "y": 41,
      "z": 16,
      "name": "Rock_Stone"
    },
    {
      "x": 12,
      "y": 42,
      "z": 16,
      "name": "Soil_Dirt"
    },
    {
      "x": 12,
      "y": 43,
      "z": 16,
      "name": "Soil_Dirt"
    },
    {
      "x": 12,
      "y": 44,
      "z": 16,
      "name": "Soil_Dirt"
    },
    {
      "x": 12,
      "y": 45,
      "z": 16,
      "name": "Soil_Dirt"
    },
    {
      "x": 12,
      "y": 46,
      "z": 16,
      "name": "Soil_Grass"
    },
    {
      "x": 12,
      "y": 39,
      "z": 17,
      "name": "Rock_Stone"
    },
    {
      "x": 12,
      "y": 40,
      "z": 17,
      "name": "Rock_Stone"
    },
    {
      "x": 12,
      "y": 41,
      "z": 17,
      "name": "Rock_Stone"
    },
    {
      "x": 12,
      "y": 42,
      "z": 17,
      "name": "Rock_Stone"
    },
    {
      "x": 12,
      "y": 43,
      "z": 17,
      "name": "Soil_Dirt"
    },
    {
      "x": 12,
      "y": 44,
      "z": 17,
      "name": "Soil_Dirt"
    },
    {
      "x": 12,
      "y": 45,
      "z": 17,
      "name": "Soil_Grass"
    },
    {
      "x": 12,
      "y": 46,
      "z": 17,
      "name": "Plant_Grass_Lush"
    },
    {
      "x": 12,
      "y": 39,
      "z": 18,
      "name": "Rock_Stone"
    },
    {
      "x": 12,
      "y": 40,
      "z": 18,
      "name": "Rock_Stone"
    },
    {
      "x": 12,
      "y": 41,
      "z": 18,
      "name": "Rock_Stone"
    },
    {
      "x": 12,
      "y": 42,
      "z": 18,
      "name": "Rock_Stone"
    },
    {
      "x": 12,
      "y": 43,
      "z": 18,
      "name": "Soil_Dirt"
    },
    {
      "x": 12,
      "y": 44,
      "z": 18,
      "name": "Soil_Dirt"
    },
    {
      "x": 12,
      "y": 45,
      "z": 18,
      "name": "Soil_Grass"
    },
    {
      "x": 12,
      "y": 46,
      "z": 18,
      "name": "Plant_Moss_Rug_Green"
    },
    {
      "x": 12,
      "y": 39,
      "z": 19,
      "name": "Rock_Stone"
    },
    {
      "x": 12,
      "y": 40,
      "z": 19,
      "name": "Rock_Stone"
    },
    {
      "x": 12,
      "y": 41,
      "z": 19,
      "name": "Rock_Stone"
    },
    {
      "x": 12,
      "y": 42,
      "z": 19,
      "name": "Rock_Stone"
    },
    {
      "x": 12,
      "y": 43,
      "z": 19,
      "name": "Soil_Dirt"
    },
    {
      "x": 12,
      "y": 44,
      "z": 19,
      "name": "Soil_Dirt"
    },
    {
      "x": 12,
      "y": 45,
      "z": 19,
      "name": "Soil_Grass"
    },
    {
      "x": 12,
      "y": 46,
      "z": 19,
      "name": "Plant_Moss_Rug_Green"
    },
    {
      "x": 12,
      "y": 42,
      "z": 20,
      "name": "Rock_Stone"
    },
    {
      "x": 12,
      "y": 43,
      "z": 20,
      "name": "Soil_Dirt"
    },
    {
      "x": 12,
      "y": 44,
      "z": 20,
      "name": "Soil_Grass"
    },
    {
      "x": 13,
      "y": 22,
      "z": 6,
      "name": "Rock_Stone"
    },
    {
      "x": 13,
      "y": 23,
      "z": 6,
      "name": "Rock_Stone"
    },
    {
      "x": 13,
      "y": 24,
      "z": 6,
      "name": "Rock_Stone"
    },
    {
      "x": 13,
      "y": 21,
      "z": 7,
      "name": "Rock_Stone"
    },
    {
      "x": 13,
      "y": 22,
      "z": 7,
      "name": "Rock_Stone"
    },
    {
      "x": 13,
      "y": 23,
      "z": 7,
      "name": "Rock_Stone"
    },
    {
      "x": 13,
      "y": 24,
      "z": 7,
      "name": "Rock_Stone"
    },
    {
      "x": 13,
      "y": 25,
      "z": 7,
      "name": "Rock_Stone"
    },
    {
      "x": 13,
      "y": 20,
      "z": 8,
      "name": "Rock_Stone"
    },
    {
      "x": 13,
      "y": 21,
      "z": 8,
      "name": "Rock_Stone"
    },
    {
      "x": 13,
      "y": 22,
      "z": 8,
      "name": "Rock_Stone"
    },
    {
      "x": 13,
      "y": 23,
      "z": 8,
      "name": "Rock_Stone"
    },
    {
      "x": 13,
      "y": 24,
      "z": 8,
      "name": "Rock_Stone"
    },
    {
      "x": 13,
      "y": 25,
      "z": 8,
      "name": "Rock_Stone"
    },
    {
      "x": 13,
      "y": 26,
      "z": 8,
      "name": "Rock_Stone"
    },
    {
      "x": 13,
      "y": 42,
      "z": 8,
      "name": "Soil_Dirt"
    },
    {
      "x": 13,
      "y": 43,
      "z": 8,
      "name": "Soil_Grass"
    },
    {
      "x": 13,
      "y": 44,
      "z": 8,
      "name": "Plant_Grass_Lush_Tall"
    },
    {
      "x": 13,
      "y": 20,
      "z": 9,
      "name": "Rock_Stone"
    },
    {
      "x": 13,
      "y": 21,
      "z": 9,
      "name": "Rock_Stone"
    },
    {
      "x": 13,
      "y": 22,
      "z": 9,
      "name": "Rock_Stone"
    },
    {
      "x": 13,
      "y": 23,
      "z": 9,
      "name": "Rock_Stone"
    },
    {
      "x": 13,
      "y": 24,
      "z": 9,
      "name": "Rock_Stone"
    },
    {
      "x": 13,
      "y": 25,
      "z": 9,
      "name": "Rock_Stone"
    },
    {
      "x": 13,
      "y": 26,
      "z": 9,
      "name": "Rock_Stone"
    },
    {
      "x": 13,
      "y": 40,
      "z": 9,
      "name": "Rock_Stone"
    },
    {
      "x": 13,
      "y": 41,
      "z": 9,
      "name": "Soil_Dirt"
    },
    {
      "x": 13,
      "y": 42,
      "z": 9,
      "name": "Soil_Dirt"
    },
    {
      "x": 13,
      "y": 43,
      "z": 9,
      "name": "Soil_Dirt"
    },
    {
      "x": 13,
      "y": 44,
      "z": 9,
      "name": "Soil_Grass"
    },
    {
      "x": 13,
      "y": 45,
      "z": 9,
      "name": "Plant_Moss_Rug_Green"
    },
    {
      "x": 13,
      "y": 23,
      "z": 10,
      "name": "Rock_Stone"
    },
    {
      "x": 13,
      "y": 24,
      "z": 10,
      "name": "Rock_Stone"
    },
    {
      "x": 13,
      "y": 25,
      "z": 10,
      "name": "Rock_Stone"
    },
    {
      "x": 13,
      "y": 26,
      "z": 10,
      "name": "Rock_Stone"
    },
    {
      "x": 13,
      "y": 39,
      "z": 10,
      "name": "Rock_Stone"
    },
    {
      "x": 13,
      "y": 40,
      "z": 10,
      "name": "Rock_Stone"
    },
    {
      "x": 13,
      "y": 41,
      "z": 10,
      "name": "Soil_Dirt"
    },
    {
      "x": 13,
      "y": 42,
      "z": 10,
      "name": "Soil_Dirt"
    },
    {
      "x": 13,
      "y": 43,
      "z": 10,
      "name": "Soil_Dirt"
    },
    {
      "x": 13,
      "y": 44,
      "z": 10,
      "name": "Soil_Grass"
    },
    {
      "x": 13,
      "y": 24,
      "z": 11,
      "name": "Rock_Stone"
    },
    {
      "x": 13,
      "y": 25,
      "z": 11,
      "name": "Rock_Stone"
    },
    {
      "x": 13,
      "y": 39,
      "z": 11,
      "name": "Rock_Stone"
    },
    {
      "x": 13,
      "y": 40,
      "z": 11,
      "name": "Rock_Stone"
    },
    {
      "x": 13,
      "y": 41,
      "z": 11,
      "name": "Soil_Dirt"
    },
    {
      "x": 13,
      "y": 42,
      "z": 11,
      "name": "Soil_Dirt"
    },
    {
      "x": 13,
      "y": 43,
      "z": 11,
      "name": "Soil_Dirt"
    },
    {
      "x": 13,
      "y": 44,
      "z": 11,
      "name": "Soil_Grass"
    },
    {
      "x": 13,
      "y": 45,
      "z": 11,
      "name": "Plant_Moss_Rug_Green"
    },
    {
      "x": 13,
      "y": 39,
      "z": 12,
      "name": "Rock_Stone"
    },
    {
      "x": 13,
      "y": 40,
      "z": 12,
      "name": "Rock_Stone"
    },
    {
      "x": 13,
      "y": 41,
      "z": 12,
      "name": "Rock_Stone"
    },
    {
      "x": 13,
      "y": 42,
      "z": 12,
      "name": "Soil_Dirt"
    },
    {
      "x": 13,
      "y": 43,
      "z": 12,
      "name": "Soil_Dirt"
    },
    {
      "x": 13,
      "y": 44,
      "z": 12,
      "name": "Soil_Dirt"
    },
    {
      "x": 13,
      "y": 45,
      "z": 12,
      "name": "Soil_Grass"
    },
    {
      "x": 13,
      "y": 39,
      "z": 13,
      "name": "Rock_Stone"
    },
    {
      "x": 13,
      "y": 40,
      "z": 13,
      "name": "Rock_Stone"
    },
    {
      "x": 13,
      "y": 41,
      "z": 13,
      "name": "Rock_Stone"
    },
    {
      "x": 13,
      "y": 42,
      "z": 13,
      "name": "Soil_Dirt"
    },
    {
      "x": 13,
      "y": 43,
      "z": 13,
      "name": "Soil_Dirt"
    },
    {
      "x": 13,
      "y": 44,
      "z": 13,
      "name": "Soil_Dirt"
    },
    {
      "x": 13,
      "y": 45,
      "z": 13,
      "name": "Soil_Grass"
    },
    {
      "x": 13,
      "y": 39,
      "z": 14,
      "name": "Rock_Stone"
    },
    {
      "x": 13,
      "y": 40,
      "z": 14,
      "name": "Rock_Stone"
    },
    {
      "x": 13,
      "y": 41,
      "z": 14,
      "name": "Rock_Stone"
    },
    {
      "x": 13,
      "y": 42,
      "z": 14,
      "name": "Soil_Dirt"
    },
    {
      "x": 13,
      "y": 43,
      "z": 14,
      "name": "Soil_Dirt"
    },
    {
      "x": 13,
      "y": 44,
      "z": 14,
      "name": "Soil_Dirt"
    },
    {
      "x": 13,
      "y": 45,
      "z": 14,
      "name": "Soil_Dirt"
    },
    {
      "x": 13,
      "y": 46,
      "z": 14,
      "name": "Soil_Grass"
    },
    {
      "x": 13,
      "y": 47,
      "z": 14,
      "name": "Plant_Grass_Lush"
    },
    {
      "x": 13,
      "y": 40,
      "z": 15,
      "name": "Rock_Stone"
    },
    {
      "x": 13,
      "y": 41,
      "z": 15,
      "name": "Rock_Stone"
    },
    {
      "x": 13,
      "y": 42,
      "z": 15,
      "name": "Rock_Stone"
    },
    {
      "x": 13,
      "y": 43,
      "z": 15,
      "name": "Rock_Stone"
    },
    {
      "x": 13,
      "y": 44,
      "z": 15,
      "name": "Soil_Dirt"
    },
    {
      "x": 13,
      "y": 45,
      "z": 15,
      "name": "Soil_Dirt"
    },
    {
      "x": 13,
      "y": 46,
      "z": 15,
      "name": "Soil_Grass"
    },
    {
      "x": 13,
      "y": 47,
      "z": 15,
      "name": "Plant_Grass_Lush"
    },
    {
      "x": 13,
      "y": 40,
      "z": 16,
      "name": "Rock_Stone"
    },
    {
      "x": 13,
      "y": 41,
      "z": 16,
      "name": "Rock_Stone"
    },
    {
      "x": 13,
      "y": 42,
      "z": 16,
      "name": "Rock_Stone"
    },
    {
      "x": 13,
      "y": 43,
      "z": 16,
      "name": "Soil_Dirt"
    },
    {
      "x": 13,
      "y": 44,
      "z": 16,
      "name": "Soil_Dirt"
    },
    {
      "x": 13,
      "y": 45,
      "z": 16,
      "name": "Soil_Dirt"
    },
    {
      "x": 13,
      "y": 46,
      "z": 16,
      "name": "Soil_Grass"
    },
    {
      "x": 13,
      "y": 40,
      "z": 17,
      "name": "Rock_Stone"
    },
    {
      "x": 13,
      "y": 41,
      "z": 17,
      "name": "Rock_Stone"
    },
    {
      "x": 13,
      "y": 42,
      "z": 17,
      "name": "Rock_Stone"
    },
    {
      "x": 13,
      "y": 43,
      "z": 17,
      "name": "Soil_Dirt"
    },
    {
      "x": 13,
      "y": 44,
      "z": 17,
      "name": "Soil_Dirt"
    },
    {
      "x": 13,
      "y": 45,
      "z": 17,
      "name": "Soil_Dirt"
    },
    {
      "x": 13,
      "y": 46,
      "z": 17,
      "name": "Soil_Grass"
    },
    {
      "x": 13,
      "y": 39,
      "z": 18,
      "name": "Rock_Stone"
    },
    {
      "x": 13,
      "y": 40,
      "z": 18,
      "name": "Rock_Stone"
    },
    {
      "x": 13,
      "y": 41,
      "z": 18,
      "name": "Rock_Stone"
    },
    {
      "x": 13,
      "y": 42,
      "z": 18,
      "name": "Rock_Stone"
    },
    {
      "x": 13,
      "y": 43,
      "z": 18,
      "name": "Soil_Dirt"
    },
    {
      "x": 13,
      "y": 44,
      "z": 18,
      "name": "Soil_Dirt"
    },
    {
      "x": 13,
      "y": 45,
      "z": 18,
      "name": "Soil_Dirt"
    },
    {
      "x": 13,
      "y": 46,
      "z": 18,
      "name": "Soil_Grass"
    },
    {
      "x": 13,
      "y": 39,
      "z": 19,
      "name": "Rock_Stone"
    },
    {
      "x": 13,
      "y": 40,
      "z": 19,
      "name": "Rock_Stone"
    },
    {
      "x": 13,
      "y": 41,
      "z": 19,
      "name": "Rock_Stone"
    },
    {
      "x": 13,
      "y": 42,
      "z": 19,
      "name": "Rock_Stone"
    },
    {
      "x": 13,
      "y": 43,
      "z": 19,
      "name": "Soil_Dirt"
    },
    {
      "x": 13,
      "y": 44,
      "z": 19,
      "name": "Soil_Dirt"
    },
    {
      "x": 13,
      "y": 45,
      "z": 19,
      "name": "Soil_Grass"
    },
    {
      "x": 13,
      "y": 46,
      "z": 19,
      "name": "Plant_Moss_Rug_Green"
    },
    {
      "x": 13,
      "y": 42,
      "z": 20,
      "name": "Rock_Stone"
    },
    {
      "x": 13,
      "y": 43,
      "z": 20,
      "name": "Soil_Dirt"
    },
    {
      "x": 13,
      "y": 44,
      "z": 20,
      "name": "Soil_Dirt"
    },
    {
      "x": 13,
      "y": 45,
      "z": 20,
      "name": "Soil_Grass"
    },
    {
      "x": 13,
      "y": 46,
      "z": 20,
      "name": "Plant_Grass_Lush"
    },
    {
      "x": 14,
      "y": 22,
      "z": 6,
      "name": "Rock_Stone"
    },
    {
      "x": 14,
      "y": 23,
      "z": 6,
      "name": "Rock_Stone"
    },
    {
      "x": 14,
      "y": 24,
      "z": 6,
      "name": "Rock_Stone"
    },
    {
      "x": 14,
      "y": 20,
      "z": 7,
      "name": "Rock_Stone"
    },
    {
      "x": 14,
      "y": 21,
      "z": 7,
      "name": "Rock_Stone"
    },
    {
      "x": 14,
      "y": 22,
      "z": 7,
      "name": "Rock_Stone"
    },
    {
      "x": 14,
      "y": 23,
      "z": 7,
      "name": "Rock_Stone"
    },
    {
      "x": 14,
      "y": 24,
      "z": 7,
      "name": "Rock_Stone"
    },
    {
      "x": 14,
      "y": 20,
      "z": 8,
      "name": "Rock_Stone"
    },
    {
      "x": 14,
      "y": 21,
      "z": 8,
      "name": "Rock_Stone"
    },
    {
      "x": 14,
      "y": 22,
      "z": 8,
      "name": "Rock_Stone"
    },
    {
      "x": 14,
      "y": 23,
      "z": 8,
      "name": "Rock_Stone"
    },
    {
      "x": 14,
      "y": 24,
      "z": 8,
      "name": "Rock_Stone"
    },
    {
      "x": 14,
      "y": 25,
      "z": 8,
      "name": "Rock_Stone"
    },
    {
      "x": 14,
      "y": 42,
      "z": 8,
      "name": "Soil_Dirt"
    },
    {
      "x": 14,
      "y": 43,
      "z": 8,
      "name": "Soil_Grass"
    },
    {
      "x": 14,
      "y": 19,
      "z": 9,
      "name": "Rock_Stone"
    },
    {
      "x": 14,
      "y": 20,
      "z": 9,
      "name": "Rock_Stone"
    },
    {
      "x": 14,
      "y": 21,
      "z": 9,
      "name": "Rock_Stone"
    },
    {
      "x": 14,
      "y": 22,
      "z": 9,
      "name": "Rock_Stone"
    },
    {
      "x": 14,
      "y": 23,
      "z": 9,
      "name": "Rock_Stone"
    },
    {
      "x": 14,
      "y": 24,
      "z": 9,
      "name": "Rock_Stone"
    },
    {
      "x": 14,
      "y": 25,
      "z": 9,
      "name": "Rock_Stone"
    },
    {
      "x": 14,
      "y": 40,
      "z": 9,
      "name": "Rock_Stone"
    },
    {
      "x": 14,
      "y": 41,
      "z": 9,
      "name": "Rock_Stone"
    },
    {
      "x": 14,
      "y": 42,
      "z": 9,
      "name": "Soil_Dirt"
    },
    {
      "x": 14,
      "y": 43,
      "z": 9,
      "name": "Soil_Dirt"
    },
    {
      "x": 14,
      "y": 44,
      "z": 9,
      "name": "Soil_Grass"
    },
    {
      "x": 14,
      "y": 19,
      "z": 10,
      "name": "Rock_Stone"
    },
    {
      "x": 14,
      "y": 20,
      "z": 10,
      "name": "Rock_Stone"
    },
    {
      "x": 14,
      "y": 21,
      "z": 10,
      "name": "Rock_Stone"
    },
    {
      "x": 14,
      "y": 40,
      "z": 10,
      "name": "Rock_Stone"
    },
    {
      "x": 14,
      "y": 41,
      "z": 10,
      "name": "Rock_Stone"
    },
    {
      "x": 14,
      "y": 42,
      "z": 10,
      "name": "Soil_Dirt"
    },
    {
      "x": 14,
      "y": 43,
      "z": 10,
      "name": "Soil_Dirt"
    },
    {
      "x": 14,
      "y": 44,
      "z": 10,
      "name": "Soil_Dirt"
    },
    {
      "x": 14,
      "y": 45,
      "z": 10,
      "name": "Soil_Leaves"
    },
    {
      "x": 14,
      "y": 20,
      "z": 11,
      "name": "Rock_Stone"
    },
    {
      "x": 14,
      "y": 21,
      "z": 11,
      "name": "Rock_Stone"
    },
    {
      "x": 14,
      "y": 40,
      "z": 11,
      "name": "Rock_Stone"
    },
    {
      "x": 14,
      "y": 41,
      "z": 11,
      "name": "Rock_Stone"
    },
    {
      "x": 14,
      "y": 42,
      "z": 11,
      "name": "Soil_Dirt"
    },
    {
      "x": 14,
      "y": 43,
      "z": 11,
      "name": "Soil_Dirt"
    },
    {
      "x": 14,
      "y": 44,
      "z": 11,
      "name": "Soil_Dirt"
    },
    {
      "x": 14,
      "y": 45,
      "z": 11,
      "name": "Soil_Leaves"
    },
    {
      "x": 14,
      "y": 40,
      "z": 12,
      "name": "Rock_Stone"
    },
    {
      "x": 14,
      "y": 41,
      "z": 12,
      "name": "Rock_Stone"
    },
    {
      "x": 14,
      "y": 42,
      "z": 12,
      "name": "Rock_Stone"
    },
    {
      "x": 14,
      "y": 43,
      "z": 12,
      "name": "Soil_Dirt"
    },
    {
      "x": 14,
      "y": 44,
      "z": 12,
      "name": "Soil_Dirt"
    },
    {
      "x": 14,
      "y": 45,
      "z": 12,
      "name": "Soil_Grass"
    },
    {
      "x": 14,
      "y": 46,
      "z": 12,
      "name": "Plant_Moss_Rug_Green"
    },
    {
      "x": 14,
      "y": 40,
      "z": 13,
      "name": "Rock_Stone"
    },
    {
      "x": 14,
      "y": 41,
      "z": 13,
      "name": "Rock_Stone"
    },
    {
      "x": 14,
      "y": 42,
      "z": 13,
      "name": "Rock_Stone"
    },
    {
      "x": 14,
      "y": 43,
      "z": 13,
      "name": "Rock_Stone"
    },
    {
      "x": 14,
      "y": 44,
      "z": 13,
      "name": "Soil_Dirt"
    },
    {
      "x": 14,
      "y": 45,
      "z": 13,
      "name": "Soil_Dirt"
    },
    {
      "x": 14,
      "y": 46,
      "z": 13,
      "name": "Soil_Grass"
    },
    {
      "x": 14,
      "y": 40,
      "z": 14,
      "name": "Rock_Stone"
    },
    {
      "x": 14,
      "y": 41,
      "z": 14,
      "name": "Rock_Stone"
    },
    {
      "x": 14,
      "y": 42,
      "z": 14,
      "name": "Rock_Stone"
    },
    {
      "x": 14,
      "y": 43,
      "z": 14,
      "name": "Rock_Stone"
    },
    {
      "x": 14,
      "y": 44,
      "z": 14,
      "name": "Soil_Dirt"
    },
    {
      "x": 14,
      "y": 45,
      "z": 14,
      "name": "Soil_Dirt"
    },
    {
      "x": 14,
      "y": 46,
      "z": 14,
      "name": "Soil_Grass"
    },
    {
      "x": 14,
      "y": 40,
      "z": 15,
      "name": "Rock_Stone"
    },
    {
      "x": 14,
      "y": 41,
      "z": 15,
      "name": "Rock_Stone"
    },
    {
      "x": 14,
      "y": 42,
      "z": 15,
      "name": "Rock_Stone"
    },
    {
      "x": 14,
      "y": 43,
      "z": 15,
      "name": "Rock_Stone"
    },
    {
      "x": 14,
      "y": 44,
      "z": 15,
      "name": "Soil_Dirt"
    },
    {
      "x": 14,
      "y": 45,
      "z": 15,
      "name": "Soil_Dirt"
    },
    {
      "x": 14,
      "y": 46,
      "z": 15,
      "name": "Soil_Grass"
    },
    {
      "x": 14,
      "y": 40,
      "z": 16,
      "name": "Rock_Stone"
    },
    {
      "x": 14,
      "y": 41,
      "z": 16,
      "name": "Rock_Stone"
    },
    {
      "x": 14,
      "y": 42,
      "z": 16,
      "name": "Rock_Stone"
    },
    {
      "x": 14,
      "y": 43,
      "z": 16,
      "name": "Rock_Stone"
    },
    {
      "x": 14,
      "y": 44,
      "z": 16,
      "name": "Soil_Dirt"
    },
    {
      "x": 14,
      "y": 45,
      "z": 16,
      "name": "Soil_Dirt"
    },
    {
      "x": 14,
      "y": 46,
      "z": 16,
      "name": "Soil_Grass"
    },
    {
      "x": 14,
      "y": 47,
      "z": 16,
      "name": "Plant_Grass_Lush"
    },
    {
      "x": 14,
      "y": 40,
      "z": 17,
      "name": "Rock_Stone"
    },
    {
      "x": 14,
      "y": 41,
      "z": 17,
      "name": "Rock_Stone"
    },
    {
      "x": 14,
      "y": 42,
      "z": 17,
      "name": "Rock_Stone"
    },
    {
      "x": 14,
      "y": 43,
      "z": 17,
      "name": "Rock_Stone"
    },
    {
      "x": 14,
      "y": 44,
      "z": 17,
      "name": "Soil_Dirt"
    },
    {
      "x": 14,
      "y": 45,
      "z": 17,
      "name": "Soil_Dirt"
    },
    {
      "x": 14,
      "y": 46,
      "z": 17,
      "name": "Soil_Grass"
    },
    {
      "x": 14,
      "y": 40,
      "z": 18,
      "name": "Rock_Stone"
    },
    {
      "x": 14,
      "y": 41,
      "z": 18,
      "name": "Rock_Stone"
    },
    {
      "x": 14,
      "y": 42,
      "z": 18,
      "name": "Rock_Stone"
    },
    {
      "x": 14,
      "y": 43,
      "z": 18,
      "name": "Rock_Stone"
    },
    {
      "x": 14,
      "y": 44,
      "z": 18,
      "name": "Soil_Dirt"
    },
    {
      "x": 14,
      "y": 45,
      "z": 18,
      "name": "Soil_Dirt"
    },
    {
      "x": 14,
      "y": 46,
      "z": 18,
      "name": "Soil_Grass"
    },
    {
      "x": 14,
      "y": 47,
      "z": 18,
      "name": "Plant_Moss_Rug_Green"
    },
    {
      "x": 14,
      "y": 40,
      "z": 19,
      "name": "Rock_Stone"
    },
    {
      "x": 14,
      "y": 41,
      "z": 19,
      "name": "Rock_Stone"
    },
    {
      "x": 14,
      "y": 42,
      "z": 19,
      "name": "Rock_Stone"
    },
    {
      "x": 14,
      "y": 43,
      "z": 19,
      "name": "Rock_Stone"
    },
    {
      "x": 14,
      "y": 44,
      "z": 19,
      "name": "Soil_Dirt"
    },
    {
      "x": 14,
      "y": 45,
      "z": 19,
      "name": "Soil_Dirt"
    },
    {
      "x": 14,
      "y": 46,
      "z": 19,
      "name": "Soil_Grass"
    },
    {
      "x": 14,
      "y": 47,
      "z": 19,
      "name": "Plant_Moss_Rug_Green"
    },
    {
      "x": 14,
      "y": 41,
      "z": 20,
      "name": "Rock_Stone"
    },
    {
      "x": 14,
      "y": 42,
      "z": 20,
      "name": "Rock_Stone"
    },
    {
      "x": 14,
      "y": 43,
      "z": 20,
      "name": "Soil_Dirt"
    },
    {
      "x": 14,
      "y": 44,
      "z": 20,
      "name": "Soil_Dirt"
    },
    {
      "x": 14,
      "y": 45,
      "z": 20,
      "name": "Soil_Dirt"
    },
    {
      "x": 14,
      "y": 46,
      "z": 20,
      "name": "Soil_Grass"
    },
    {
      "x": 14,
      "y": 43,
      "z": 21,
      "name": "Rock_Stone"
    },
    {
      "x": 14,
      "y": 44,
      "z": 21,
      "name": "Soil_Grass"
    },
    {
      "x": 14,
      "y": 45,
      "z": 21,
      "name": "Plant_Grass_Lush_Tall"
    },
    {
      "x": 15,
      "y": 23,
      "z": 6,
      "name": "Rock_Stone"
    },
    {
      "x": 15,
      "y": 21,
      "z": 7,
      "name": "Rock_Stone"
    },
    {
      "x": 15,
      "y": 22,
      "z": 7,
      "name": "Rock_Stone"
    },
    {
      "x": 15,
      "y": 23,
      "z": 7,
      "name": "Rock_Stone"
    },
    {
      "x": 15,
      "y": 24,
      "z": 7,
      "name": "Rock_Stone"
    },
    {
      "x": 15,
      "y": 19,
      "z": 8,
      "name": "Rock_Stone"
    },
    {
      "x": 15,
      "y": 20,
      "z": 8,
      "name": "Rock_Stone"
    },
    {
      "x": 15,
      "y": 21,
      "z": 8,
      "name": "Rock_Stone"
    },
    {
      "x": 15,
      "y": 22,
      "z": 8,
      "name": "Rock_Stone"
    },
    {
      "x": 15,
      "y": 23,
      "z": 8,
      "name": "Rock_Stone"
    },
    {
      "x": 15,
      "y": 24,
      "z": 8,
      "name": "Rock_Stone"
    },
    {
      "x": 15,
      "y": 41,
      "z": 8,
      "name": "Rock_Stone"
    },
    {
      "x": 15,
      "y": 42,
      "z": 8,
      "name": "Soil_Dirt"
    },
    {
      "x": 15,
      "y": 43,
      "z": 8,
      "name": "Soil_Grass"
    },
    {
      "x": 15,
      "y": 18,
      "z": 9,
      "name": "Rock_Stone"
    },
    {
      "x": 15,
      "y": 19,
      "z": 9,
      "name": "Rock_Stone"
    },
    {
      "x": 15,
      "y": 20,
      "z": 9,
      "name": "Rock_Stone"
    },
    {
      "x": 15,
      "y": 21,
      "z": 9,
      "name": "Rock_Stone"
    },
    {
      "x": 15,
      "y": 22,
      "z": 9,
      "name": "Rock_Stone"
    },
    {
      "x": 15,
      "y": 23,
      "z": 9,
      "name": "Rock_Stone"
    },
    {
      "x": 15,
      "y": 24,
      "z": 9,
      "name": "Rock_Stone"
    },
    {
      "x": 15,
      "y": 40,
      "z": 9,
      "name": "Rock_Stone"
    },
    {
      "x": 15,
      "y": 41,
      "z": 9,
      "name": "Soil_Dirt"
    },
    {
      "x": 15,
      "y": 42,
      "z": 9,
      "name": "Soil_Dirt"
    },
    {
      "x": 15,
      "y": 43,
      "z": 9,
      "name": "Soil_Dirt"
    },
    {
      "x": 15,
      "y": 44,
      "z": 9,
      "name": "Soil_Leaves"
    },
    {
      "x": 15,
      "y": 45,
      "z": 9,
      "name": "Plant_Grass_Sharp"
    },
    {
      "x": 15,
      "y": 18,
      "z": 10,
      "name": "Rock_Stone"
    },
    {
      "x": 15,
      "y": 19,
      "z": 10,
      "name": "Rock_Stone"
    },
    {
      "x": 15,
      "y": 20,
      "z": 10,
      "name": "Rock_Stone"
    },
    {
      "x": 15,
      "y": 21,
      "z": 10,
      "name": "Rock_Stone"
    },
    {
      "x": 15,
      "y": 40,
      "z": 10,
      "name": "Rock_Stone"
    },
    {
      "x": 15,
      "y": 41,
      "z": 10,
      "name": "Rock_Stone"
    },
    {
      "x": 15,
      "y": 42,
      "z": 10,
      "name": "Soil_Dirt"
    },
    {
      "x": 15,
      "y": 43,
      "z": 10,
      "name": "Soil_Dirt"
    },
    {
      "x": 15,
      "y": 44,
      "z": 10,
      "name": "Soil_Dirt"
    },
    {
      "x": 15,
      "y": 45,
      "z": 10,
      "name": "Soil_Leaves"
    },
    {
      "x": 15,
      "y": 18,
      "z": 11,
      "name": "Rock_Stone"
    },
    {
      "x": 15,
      "y": 19,
      "z": 11,
      "name": "Rock_Stone"
    },
    {
      "x": 15,
      "y": 20,
      "z": 11,
      "name": "Rock_Stone"
    },
    {
      "x": 15,
      "y": 21,
      "z": 11,
      "name": "Rock_Stone"
    },
    {
      "x": 15,
      "y": 40,
      "z": 11,
      "name": "Rock_Stone"
    },
    {
      "x": 15,
      "y": 41,
      "z": 11,
      "name": "Rock_Stone"
    },
    {
      "x": 15,
      "y": 42,
      "z": 11,
      "name": "Soil_Dirt"
    },
    {
      "x": 15,
      "y": 43,
      "z": 11,
      "name": "Soil_Dirt"
    },
    {
      "x": 15,
      "y": 44,
      "z": 11,
      "name": "Soil_Dirt"
    },
    {
      "x": 15,
      "y": 45,
      "z": 11,
      "name": "Soil_Grass"
    },
    {
      "x": 15,
      "y": 46,
      "z": 11,
      "name": "Plant_Moss_Rug_Green"
    },
    {
      "x": 15,
      "y": 40,
      "z": 12,
      "name": "Rock_Stone"
    },
    {
      "x": 15,
      "y": 41,
      "z": 12,
      "name": "Rock_Stone"
    },
    {
      "x": 15,
      "y": 42,
      "z": 12,
      "name": "Rock_Stone"
    },
    {
      "x": 15,
      "y": 43,
      "z": 12,
      "name": "Soil_Dirt"
    },
    {
      "x": 15,
      "y": 44,
      "z": 12,
      "name": "Soil_Dirt"
    },
    {
      "x": 15,
      "y": 45,
      "z": 12,
      "name": "Soil_Grass"
    },
    {
      "x": 15,
      "y": 46,
      "z": 12,
      "name": "Plant_Moss_Rug_Green"
    },
    {
      "x": 15,
      "y": 40,
      "z": 13,
      "name": "Rock_Stone"
    },
    {
      "x": 15,
      "y": 41,
      "z": 13,
      "name": "Rock_Stone"
    },
    {
      "x": 15,
      "y": 42,
      "z": 13,
      "name": "Rock_Stone"
    },
    {
      "x": 15,
      "y": 43,
      "z": 13,
      "name": "Rock_Stone"
    },
    {
      "x": 15,
      "y": 44,
      "z": 13,
      "name": "Soil_Dirt"
    },
    {
      "x": 15,
      "y": 45,
      "z": 13,
      "name": "Soil_Dirt"
    },
    {
      "x": 15,
      "y": 46,
      "z": 13,
      "name": "Soil_Grass"
    },
    {
      "x": 15,
      "y": 40,
      "z": 14,
      "name": "Rock_Stone"
    },
    {
      "x": 15,
      "y": 41,
      "z": 14,
      "name": "Rock_Stone"
    },
    {
      "x": 15,
      "y": 42,
      "z": 14,
      "name": "Rock_Stone"
    },
    {
      "x": 15,
      "y": 43,
      "z": 14,
      "name": "Soil_Dirt"
    },
    {
      "x": 15,
      "y": 44,
      "z": 14,
      "name": "Soil_Dirt"
    },
    {
      "x": 15,
      "y": 45,
      "z": 14,
      "name": "Soil_Dirt"
    },
    {
      "x": 15,
      "y": 46,
      "z": 14,
      "name": "Soil_Grass"
    },
    {
      "x": 15,
      "y": 40,
      "z": 15,
      "name": "Rock_Stone"
    },
    {
      "x": 15,
      "y": 41,
      "z": 15,
      "name": "Rock_Stone"
    },
    {
      "x": 15,
      "y": 42,
      "z": 15,
      "name": "Rock_Stone"
    },
    {
      "x": 15,
      "y": 43,
      "z": 15,
      "name": "Soil_Dirt"
    },
    {
      "x": 15,
      "y": 44,
      "z": 15,
      "name": "Soil_Dirt"
    },
    {
      "x": 15,
      "y": 45,
      "z": 15,
      "name": "Soil_Dirt"
    },
    {
      "x": 15,
      "y": 46,
      "z": 15,
      "name": "Soil_Grass"
    },
    {
      "x": 15,
      "y": 47,
      "z": 15,
      "name": "Plant_Grass_Lush"
    },
    {
      "x": 15,
      "y": 40,
      "z": 16,
      "name": "Rock_Stone"
    },
    {
      "x": 15,
      "y": 41,
      "z": 16,
      "name": "Rock_Stone"
    },
    {
      "x": 15,
      "y": 42,
      "z": 16,
      "name": "Rock_Stone"
    },
    {
      "x": 15,
      "y": 43,
      "z": 16,
      "name": "Rock_Stone"
    },
    {
      "x": 15,
      "y": 44,
      "z": 16,
      "name": "Soil_Dirt"
    },
    {
      "x": 15,
      "y": 45,
      "z": 16,
      "name": "Soil_Dirt"
    },
    {
      "x": 15,
      "y": 46,
      "z": 16,
      "name": "Soil_Grass"
    },
    {
      "x": 15,
      "y": 40,
      "z": 17,
      "name": "Rock_Stone"
    },
    {
      "x": 15,
      "y": 41,
      "z": 17,
      "name": "Rock_Stone"
    },
    {
      "x": 15,
      "y": 42,
      "z": 17,
      "name": "Rock_Stone"
    },
    {
      "x": 15,
      "y": 43,
      "z": 17,
      "name": "Rock_Stone"
    },
    {
      "x": 15,
      "y": 44,
      "z": 17,
      "name": "Soil_Dirt"
    },
    {
      "x": 15,
      "y": 45,
      "z": 17,
      "name": "Soil_Dirt"
    },
    {
      "x": 15,
      "y": 46,
      "z": 17,
      "name": "Soil_Grass"
    },
    {
      "x": 15,
      "y": 41,
      "z": 18,
      "name": "Rock_Stone"
    },
    {
      "x": 15,
      "y": 42,
      "z": 18,
      "name": "Rock_Stone"
    },
    {
      "x": 15,
      "y": 43,
      "z": 18,
      "name": "Rock_Stone"
    },
    {
      "x": 15,
      "y": 44,
      "z": 18,
      "name": "Soil_Dirt"
    },
    {
      "x": 15,
      "y": 45,
      "z": 18,
      "name": "Soil_Dirt"
    },
    {
      "x": 15,
      "y": 46,
      "z": 18,
      "name": "Soil_Grass"
    },
    {
      "x": 15,
      "y": 47,
      "z": 18,
      "name": "Plant_Moss_Rug_Green"
    },
    {
      "x": 15,
      "y": 41,
      "z": 19,
      "name": "Rock_Stone"
    },
    {
      "x": 15,
      "y": 42,
      "z": 19,
      "name": "Rock_Stone"
    },
    {
      "x": 15,
      "y": 43,
      "z": 19,
      "name": "Rock_Stone"
    },
    {
      "x": 15,
      "y": 44,
      "z": 19,
      "name": "Soil_Dirt"
    },
    {
      "x": 15,
      "y": 45,
      "z": 19,
      "name": "Soil_Dirt"
    },
    {
      "x": 15,
      "y": 46,
      "z": 19,
      "name": "Soil_Grass"
    },
    {
      "x": 15,
      "y": 47,
      "z": 19,
      "name": "Plant_Moss_Rug_Green"
    },
    {
      "x": 15,
      "y": 41,
      "z": 20,
      "name": "Rock_Stone"
    },
    {
      "x": 15,
      "y": 42,
      "z": 20,
      "name": "Rock_Stone"
    },
    {
      "x": 15,
      "y": 43,
      "z": 20,
      "name": "Rock_Stone"
    },
    {
      "x": 15,
      "y": 44,
      "z": 20,
      "name": "Soil_Dirt"
    },
    {
      "x": 15,
      "y": 45,
      "z": 20,
      "name": "Soil_Dirt"
    },
    {
      "x": 15,
      "y": 46,
      "z": 20,
      "name": "Soil_Grass"
    },
    {
      "x": 15,
      "y": 47,
      "z": 20,
      "name": "Plant_Moss_Rug_Green"
    },
    {
      "x": 15,
      "y": 43,
      "z": 21,
      "name": "Rock_Stone"
    },
    {
      "x": 15,
      "y": 44,
      "z": 21,
      "name": "Soil_Dirt"
