{
  "version": 8,
  "blockIdVersion": 10,
  "anchorX": 3,
  "anchorY": 9,
  "anchorZ": -1,
  "blocks": [
    {
      "x": -6,
      "y": 1,
      "z": -2,
      "name": "Rock_Sandstone_Cobble"
    },
    {
      "x": -6,
      "y": 2,
      "z": -2,
      "name": "Rock_Sandstone_Cobble"
    },
    {
      "x": -6,
      "y": 3,
      "z": -2,
      "name": "Rock_Sandstone_Cobble"
    },
    {
      "x": -6,
      "y": 4,
      "z": -2,
      "name": "Rock_Sandstone_Cobble"
    },
    {
      "x": -6,
      "y": 5,
      "z": -2,
      "name": "Rock_Sandstone_Cobble"
    },
    {
      "x": -6,
      "y": 6,
      "z": -2,
      "name": "Rock_Sandstone_Cobble"
    },
    {
      "x": -6,
      "y": 1,
      "z": -1,
      "name": "Rock_Sandstone_Cobble"
    },
    {
      "x": -6,
      "y": 2,
      "z": -1,
      "name": "Rock_Sandstone_Cobble"
    },
    {
      "x": -6,
      "y": 3,
      "z": -1,
      "name": "Rock_Sandstone_Cobble"
    },
    {
      "x": -6,
      "y": 4,
      "z": -1,
      "name": "Rock_Sandstone_Cobble"
    },
    {
      "x": -6,
      "y": 5,
      "z": -1,
      "name": "Rock_Sandstone_Cobble"
    },
    {
      "x": -6,
      "y": 6,
      "z": -1,
      "name": "Rock_Sandstone_Cobble"
    },
    {
      "x": -6,
      "y": 7,
      "z": -1,
      "name": "Rock_Sandstone_Cobble"
    },
    {
      "x": -6,
      "y": 1,
      "z": 0,
      "name": "Rock_Sandstone_Cobble"
    },
    {
      "x": -6,
      "y": 2,
      "z": 0,
      "name": "Rock_Sandstone_Cobble"
    },
    {
      "x": -6,
      "y": 3,
      "z": 0,
      "name": "Rock_Sandstone_Cobble"
    },
    {
      "x": -6,
      "y": 4,
      "z": 0,
      "name": "Rock_Sandstone_Cobble"
    },
    {
      "x": -6,
      "y": 5,
      "z": 0,
      "name": "Rock_Sandstone_Cobble"
    },
    {
      "x": -6,
      "y": 6,
      "z": 0,
      "name": "Rock_Sandstone_Cobble"
    },
    {
      "x": -6,
      "y": 7,
      "z": 0,
      "name": "Rock_Sandstone_Cobble"
    },
    {
      "x": -6,
      "y": 1,
      "z": 1,
      "name": "Rock_Sandstone_Cobble"
    },
    {
      "x": -6,
      "y": 2,
      "z": 1,
      "name": "Rock_Sandstone_Cobble"
    },
    {
      "x": -6,
      "y": 3,
      "z": 1,
      "name": "Rock_Sandstone_Cobble"
    },
    {
      "x": -6,
      "y": 4,
      "z": 1,
      "name": "Rock_Sandstone_Cobble"
    },
    {
      "x": -6,
      "y": 5,
      "z": 1,
      "name": "Rock_Sandstone_Cobble"
    },
    {
      "x": -6,
      "y": 6,
      "z": 1,
      "name": "Rock_Sandstone_Cobble"
    },
    {
      "x": -6,
      "y": 7,
      "z": 1,
      "name": "Rock_Sandstone_Cobble"
    },
    {
      "x": -6,
      "y": 1,
      "z": 2,
      "name": "Rock_Sandstone_Cobble"
    },
    {
      "x": -6,
      "y": 2,
      "z": 2,
      "name": "Rock_Sandstone_Cobble"
    },
    {
      "x": -6,
      "y": 3,
      "z": 2,
      "name": "Rock_Sandstone_Cobble"
    },
    {
      "x": -6,
      "y": 4,
      "z": 2,
      "name": "Rock_Sandstone_Cobble"
    },
    {
      "x": -6,
      "y": 5,
      "z": 2,
      "name": "Rock_Sandstone_Cobble"
    },
    {
      "x": -6,
      "y": 6,
      "z": 2,
      "name": "Rock_Sandstone_Cobble"
    },
    {
      "x": -5,
      "y": 1,
      "z": -4,
      "name": "Wood_Dry_Trunk"
    },
    {
      "x": -5,
      "y": 2,
      "z": -4,
      "name": "Wood_Dry_Trunk"
    },
    {
      "x": -5,
      "y": 3,
      "z": -4,
      "name": "Wood_Dry_Trunk"
    },
    {
      "x": -5,
      "y": 4,
      "z": -4,
      "name": "Wood_Dry_Trunk"
    },
    {
      "x": -5,
      "y": 5,
      "z": -4,
      "name": "Wood_Dry_Trunk"
    },
    {
      "x": -5,
      "y": 6,
      "z": -4,
      "name": "Wood_Dry_Trunk"
    },
    {
      "x": -5,
      "y": 7,
      "z": -4,
      "name": "Wood_Dry_Trunk"
    },
    {
      "x": -5,
      "y": 8,
      "z": -4,
      "name": "Wood_Dry_Trunk"
    },
    {
      "x": -5,
      "y": 9,
      "z": -4,
      "name": "Wood_Dry_Trunk"
    },
    {
      "x": -5,
      "y": 10,
      "z": -4,
      "name": "Wood_Dry_Trunk"
    },
    {
      "x": -5,
      "y": 11,
      "z": -4,
      "name": "Wood_Dry_Branch_Long"
    },
    {
      "x": -5,
      "y": 12,
      "z": -4,
      "name": "Survival_Trap_Spike_Wood_Large"
    },
    {
      "x": -5,
      "y": 1,
      "z": -3,
      "name": "Rock_Sandstone_Cobble"
    },
    {
      "x": -5,
      "y": 2,
      "z": -3,
      "name": "Rock_Sandstone_Cobble"
    },
    {
      "x": -5,
      "y": 3,
      "z": -3,
      "name": "Rock_Sandstone_Cobble"
    },
    {
      "x": -5,
      "y": 4,
      "z": -3,
      "name": "Rock_Sandstone_Cobble"
    },
    {
      "x": -5,
      "y": 5,
      "z": -3,
      "name": "Rock_Sandstone_Cobble"
    },
    {
      "x": -5,
      "y": 6,
      "z": -3,
      "name": "Rock_Sandstone_Cobble"
    },
    {
      "x": -5,
      "y": 7,
      "z": -3,
      "name": "Rock_Sandstone_Cobble"
    },
    {
      "x": -5,
      "y": 8,
      "z": -3,
      "name": "Rock_Sandstone_Cobble"
    },
    {
      "x": -5,
      "y": 9,
      "z": -3,
      "name": "Rock_Sandstone_Cobble"
    },
    {
      "x": -5,
      "y": 10,
      "z": -3,
      "name": "Rock_Sandstone_Cobble"
    },
    {
      "x": -5,
      "y": 1,
      "z": -2,
      "name": "Rock_Sandstone_Cobble"
    },
    {
      "x": -5,
      "y": 2,
      "z": -2,
      "name": "Rock_Sandstone_Cobble"
    },
    {
      "x": -5,
      "y": 3,
      "z": -2,
      "name": "Rock_Sandstone_Cobble"
    },
    {
      "x": -5,
      "y": 4,
      "z": -2,
      "name": "Rock_Sandstone_Cobble"
    },
    {
      "x": -5,
      "y": 5,
      "z": -2,
      "name": "Rock_Sandstone_Cobble"
    },
    {
      "x": -5,
      "y": 6,
      "z": -2,
      "name": "Rock_Sandstone_Cobble"
    },
    {
      "x": -5,
      "y": 7,
      "z": -2,
      "name": "Rock_Sandstone_Cobble"
    },
    {
      "x": -5,
      "y": 8,
      "z": -2,
      "name": "Rock_Sandstone_Cobble"
    },
    {
      "x": -5,
      "y": 9,
      "z": -2,
      "name": "Rock_Sandstone_Cobble"
    },
    {
      "x": -5,
      "y": 10,
      "z": -2,
      "name": "Rock_Sandstone_Cobble"
    },
    {
      "x": -5,
      "y": 1,
      "z": -1,
      "name": "Soil_Gravel_Sand"
    },
    {
      "x": -5,
      "y": 2,
      "z": -1,
      "name": "Soil_Gravel_Sand"
    },
    {
      "x": -5,
      "y": 3,
      "z": -1,
      "name": "Soil_Gravel_Sand"
    },
    {
      "x": -5,
      "y": 4,
      "z": -1,
      "name": "Soil_Gravel_Sand"
    },
    {
      "x": -5,
      "y": 5,
      "z": -1,
      "name": "Soil_Gravel_Sand"
    },
    {
      "x": -5,
      "y": 6,
      "z": -1,
      "name": "Soil_Gravel_Sand"
    },
    {
      "x": -5,
      "y": 7,
      "z": -1,
      "name": "Soil_Gravel_Sand"
    },
    {
      "x": -5,
      "y": 8,
      "z": -1,
      "name": "Soil_Gravel_Sand"
    },
    {
      "x": -5,
      "y": 1,
      "z": 0,
      "name": "Soil_Gravel_Sand"
    },
    {
      "x": -5,
      "y": 2,
      "z": 0,
      "name": "Soil_Gravel_Sand"
    },
    {
      "x": -5,
      "y": 3,
      "z": 0,
      "name": "Soil_Gravel_Sand"
    },
    {
      "x": -5,
      "y": 4,
      "z": 0,
      "name": "Soil_Gravel_Sand"
    },
    {
      "x": -5,
      "y": 5,
      "z": 0,
      "name": "Soil_Gravel_Sand"
    },
    {
      "x": -5,
      "y": 6,
      "z": 0,
      "name": "Soil_Gravel_Sand"
    },
    {
      "x": -5,
      "y": 7,
      "z": 0,
      "name": "Soil_Gravel_Sand"
    },
    {
      "x": -5,
      "y": 8,
      "z": 0,
      "name": "Soil_Gravel_Sand"
    },
    {
      "x": -5,
      "y": 1,
      "z": 1,
      "name": "Soil_Gravel_Sand"
    },
    {
      "x": -5,
      "y": 2,
      "z": 1,
      "name": "Soil_Gravel_Sand"
    },
    {
      "x": -5,
      "y": 3,
      "z": 1,
      "name": "Soil_Gravel_Sand"
    },
    {
      "x": -5,
      "y": 4,
      "z": 1,
      "name": "Soil_Gravel_Sand"
    },
    {
      "x": -5,
      "y": 5,
      "z": 1,
      "name": "Soil_Gravel_Sand"
    },
    {
      "x": -5,
      "y": 6,
      "z": 1,
      "name": "Soil_Gravel_Sand"
    },
    {
      "x": -5,
      "y": 7,
      "z": 1,
      "name": "Soil_Gravel_Sand"
    },
    {
      "x": -5,
      "y": 8,
      "z": 1,
      "name": "Soil_Gravel_Sand"
    },
    {
      "x": -5,
      "y": 1,
      "z": 2,
      "name": "Rock_Sandstone_Cobble"
    },
    {
      "x": -5,
      "y": 2,
      "z": 2,
      "name": "Rock_Sandstone_Cobble"
    },
    {
      "x": -5,
      "y": 3,
      "z": 2,
      "name": "Rock_Sandstone_Cobble"
    },
    {
      "x": -5,
      "y": 4,
      "z": 2,
      "name": "Rock_Sandstone_Cobble"
    },
    {
      "x": -5,
      "y": 5,
      "z": 2,
      "name": "Rock_Sandstone_Cobble"
    },
    {
      "x": -5,
      "y": 6,
      "z": 2,
      "name": "Rock_Sandstone_Cobble"
    },
    {
      "x": -5,
      "y": 7,
      "z": 2,
      "name": "Rock_Sandstone_Cobble"
    },
    {
      "x": -5,
      "y": 1,
      "z": 3,
      "name": "Rock_Sandstone_Cobble"
    },
    {
      "x": -5,
      "y": 2,
      "z": 3,
      "name": "Rock_Sandstone_Cobble"
    },
    {
      "x": -5,
      "y": 3,
      "z": 3,
      "name": "Rock_Sandstone_Cobble"
    },
    {
      "x": -5,
      "y": 4,
      "z": 3,
      "name": "Rock_Sandstone_Cobble"
    },
    {
      "x": -5,
      "y": 5,
      "z": 3,
      "name": "Rock_Sandstone_Cobble"
    },
    {
      "x": -5,
      "y": 6,
      "z": 3,
      "name": "Rock_Sandstone_Cobble"
    },
    {
      "x": -5,
      "y": 7,
      "z": 3,
      "name": "Rock_Sandstone_Cobble"
    },
    {
      "x": -5,
      "y": 1,
      "z": 4,
      "name": "Rock_Sandstone_Cobble"
    },
    {
      "x": -5,
      "y": 2,
      "z": 4,
      "name": "Rock_Sandstone_Cobble"
    },
    {
      "x": -5,
      "y": 3,
      "z": 4,
      "name": "Rock_Sandstone_Cobble"
    },
    {
      "x": -5,
      "y": 4,
      "z": 4,
      "name": "Rock_Sandstone_Cobble"
    },
    {
      "x": -5,
      "y": 5,
      "z": 4,
      "name": "Rock_Sandstone_Cobble"
    },
    {
      "x": -5,
      "y": 6,
      "z": 4,
      "name": "Rock_Sandstone_Cobble"
    },
    {
      "x": -5,
      "y": 7,
      "z": 4,
      "name": "Rock_Sandstone_Cobble"
    },
    {
      "x": -4,
      "y": 1,
      "z": -7,
      "name": "Rock_Sandstone_Cobble"
    },
    {
      "x": -4,
      "y": 2,
      "z": -7,
      "name": "Rock_Sandstone_Cobble"
    },
    {
      "x": -4,
      "y": 3,
      "z": -7,
      "name": "Rock_Sandstone_Cobble"
    },
    {
      "x": -4,
      "y": 4,
      "z": -7,
      "name": "Rock_Sandstone_Cobble"
    },
    {
      "x": -4,
      "y": 5,
      "z": -7,
      "name": "Rock_Sandstone_Cobble"
    },
    {
      "x": -4,
      "y": 6,
      "z": -7,
      "name": "Rock_Sandstone_Cobble"
    },
    {
      "x": -4,
      "y": 7,
      "z": -7,
      "name": "Rock_Sandstone_Cobble"
    },
    {
      "x": -4,
      "y": 1,
      "z": -6,
      "name": "Rock_Sandstone_Cobble"
    },
    {
      "x": -4,
      "y": 2,
      "z": -6,
      "name": "Rock_Sandstone_Cobble"
    },
    {
      "x": -4,
      "y": 3,
      "z": -6,
      "name": "Rock_Sandstone_Cobble"
    },
    {
      "x": -4,
      "y": 4,
      "z": -6,
      "name": "Rock_Sandstone_Cobble"
    },
    {
      "x": -4,
      "y": 5,
      "z": -6,
      "name": "Rock_Sandstone_Cobble"
    },
    {
      "x": -4,
      "y": 6,
      "z": -6,
      "name": "Rock_Sandstone_Cobble"
    },
    {
      "x": -4,
      "y": 7,
      "z": -6,
      "name": "Rock_Sandstone_Cobble"
    },
    {
      "x": -4,
      "y": 8,
      "z": -6,
      "name": "Rock_Sandstone_Cobble"
    },
    {
      "x": -4,
      "y": 9,
      "z": -6,
      "name": "Rock_Sandstone_Cobble"
    },
    {
      "x": -4,
      "y": 10,
      "z": -6,
      "name": "Rock_Sandstone_Cobble"
    },
    {
      "x": -4,
      "y": 11,
      "z": -6,
      "name": "Rock_Sandstone_Cobble"
    },
    {
      "x": -4,
      "y": 1,
      "z": -5,
      "name": "Rock_Sandstone_Cobble"
    },
    {
      "x": -4,
      "y": 2,
      "z": -5,
      "name": "Rock_Sandstone_Cobble"
    },
    {
      "x": -4,
      "y": 3,
      "z": -5,
      "name": "Rock_Sandstone_Cobble"
    },
    {
      "x": -4,
      "y": 4,
      "z": -5,
      "name": "Rock_Sandstone_Cobble"
    },
    {
      "x": -4,
      "y": 5,
      "z": -5,
      "name": "Rock_Sandstone_Cobble"
    },
    {
      "x": -4,
      "y": 6,
      "z": -5,
      "name": "Rock_Sandstone_Cobble"
    },
    {
      "x": -4,
      "y": 7,
      "z": -5,
      "name": "Rock_Sandstone_Cobble"
    },
    {
      "x": -4,
      "y": 8,
      "z": -5,
      "name": "Rock_Sandstone_Cobble"
    },
    {
      "x": -4,
      "y": 9,
      "z": -5,
      "name": "Rock_Sandstone_Cobble"
    },
    {
      "x": -4,
      "y": 10,
      "z": -5,
      "name": "Rock_Sandstone_Cobble"
    },
    {
      "x": -4,
      "y": 11,
      "z": -5,
      "name": "Rock_Sandstone_Cobble"
    },
    {
      "x": -4,
      "y": 1,
      "z": -4,
      "name": "Rock_Sandstone_Cobble"
    },
    {
      "x": -4,
      "y": 2,
      "z": -4,
      "name": "Rock_Sandstone_Cobble"
    },
    {
      "x": -4,
      "y": 3,
      "z": -4,
      "name": "Rock_Sandstone_Cobble"
    },
    {
      "x": -4,
      "y": 4,
      "z": -4,
      "name": "Rock_Sandstone_Cobble"
    },
    {
      "x": -4,
      "y": 5,
      "z": -4,
      "name": "Rock_Sandstone_Cobble"
    },
    {
      "x": -4,
      "y": 6,
      "z": -4,
      "name": "Rock_Sandstone_Cobble"
    },
    {
      "x": -4,
      "y": 7,
      "z": -4,
      "name": "Rock_Sandstone_Cobble"
    },
    {
      "x": -4,
      "y": 8,
      "z": -4,
      "name": "Rock_Sandstone_Cobble"
    },
    {
      "x": -4,
      "y": 9,
      "z": -4,
      "name": "Rock_Sandstone_Cobble"
    },
    {
      "x": -4,
      "y": 10,
      "z": -4,
      "name": "Rock_Sandstone_Cobble"
    },
    {
      "x": -4,
      "y": 11,
      "z": -4,
      "name": "Rock_Sandstone_Cobble"
    },
    {
      "x": -4,
      "y": 1,
      "z": -3,
      "name": "Soil_Gravel_Sand"
    },
    {
      "x": -4,
      "y": 2,
      "z": -3,
      "name": "Soil_Gravel_Sand"
    },
    {
      "x": -4,
      "y": 3,
      "z": -3,
      "name": "Soil_Gravel_Sand"
    },
    {
      "x": -4,
      "y": 4,
      "z": -3,
      "name": "Soil_Gravel_Sand"
    },
    {
      "x": -4,
      "y": 5,
      "z": -3,
      "name": "Soil_Gravel_Sand"
    },
    {
      "x": -4,
      "y": 6,
      "z": -3,
      "name": "Soil_Gravel_Sand"
    },
    {
      "x": -4,
      "y": 7,
      "z": -3,
      "name": "Soil_Gravel_Sand"
    },
    {
      "x": -4,
      "y": 8,
      "z": -3,
      "name": "Soil_Gravel_Sand"
    },
    {
      "x": -4,
      "y": 9,
      "z": -3,
      "name": "Soil_Gravel_Sand"
    },
    {
      "x": -4,
      "y": 10,
      "z": -3,
      "name": "Empty"
    },
    {
      "x": -4,
      "y": 11,
      "z": -3,
      "name": "Empty"
    },
    {
      "x": -4,
      "y": 12,
      "z": -3,
      "name": "Empty"
    },
    {
      "x": -4,
      "y": 13,
      "z": -3,
      "name": "Empty"
    },
    {
      "x": -4,
      "y": 14,
      "z": -3,
      "name": "Empty"
    },
    {
      "x": -4,
      "y": 15,
      "z": -3,
      "name": "Empty"
    },
    {
      "x": -4,
      "y": 16,
      "z": -3,
      "name": "Empty"
    },
    {
      "x": -4,
      "y": 1,
      "z": -2,
      "name": "Soil_Gravel_Sand"
    },
    {
      "x": -4,
      "y": 2,
      "z": -2,
      "name": "Soil_Gravel_Sand"
    },
    {
      "x": -4,
      "y": 3,
      "z": -2,
      "name": "Soil_Gravel_Sand"
    },
    {
      "x": -4,
      "y": 4,
      "z": -2,
      "name": "Soil_Gravel_Sand"
    },
    {
      "x": -4,
      "y": 5,
      "z": -2,
      "name": "Soil_Gravel_Sand"
    },
    {
      "x": -4,
      "y": 6,
      "z": -2,
      "name": "Soil_Gravel_Sand"
    },
    {
      "x": -4,
      "y": 7,
      "z": -2,
      "name": "Soil_Gravel_Sand"
    },
    {
      "x": -4,
      "y": 8,
      "z": -2,
      "name": "Soil_Gravel_Sand"
    },
    {
      "x": -4,
      "y": 9,
      "z": -2,
      "name": "Soil_Gravel_Sand"
    },
    {
      "x": -4,
      "y": 10,
      "z": -2,
      "name": "Empty"
    },
    {
      "x": -4,
      "y": 11,
      "z": -2,
      "name": "Empty"
    },
    {
      "x": -4,
      "y": 12,
      "z": -2,
      "name": "Empty"
    },
    {
      "x": -4,
      "y": 13,
      "z": -2,
      "name": "Empty"
    },
    {
      "x": -4,
      "y": 14,
      "z": -2,
      "name": "Empty"
    },
    {
      "x": -4,
      "y": 15,
      "z": -2,
      "name": "Empty"
    },
    {
      "x": -4,
      "y": 16,
      "z": -2,
      "name": "Empty"
    },
    {
      "x": -4,
      "y": 1,
      "z": -1,
      "name": "Soil_Gravel_Sand"
    },
    {
      "x": -4,
      "y": 2,
      "z": -1,
      "name": "Soil_Gravel_Sand"
    },
    {
      "x": -4,
      "y": 3,
      "z": -1,
      "name": "Soil_Gravel_Sand"
    },
    {
      "x": -4,
      "y": 4,
      "z": -1,
      "name": "Soil_Gravel_Sand"
    },
    {
      "x": -4,
      "y": 5,
      "z": -1,
      "name": "Soil_Gravel_Sand"
    },
    {
      "x": -4,
      "y": 6,
      "z": -1,
      "name": "Soil_Gravel_Sand"
    },
    {
      "x": -4,
      "y": 7,
      "z": -1,
      "name": "Soil_Gravel_Sand"
    },
    {
      "x": -4,
      "y": 8,
      "z": -1,
      "name": "Soil_Gravel_Sand"
    },
    {
      "x": -4,
      "y": 9,
      "z": -1,
      "name": "Soil_Gravel_Sand"
    },
    {
      "x": -4,
      "y": 10,
      "z": -1,
      "name": "Empty"
    },
    {
      "x": -4,
      "y": 11,
      "z": -1,
      "name": "Empty"
    },
    {
      "x": -4,
      "y": 12,
      "z": -1,
      "name": "Empty"
    },
    {
      "x": -4,
      "y": 13,
      "z": -1,
      "name": "Empty"
    },
    {
      "x": -4,
      "y": 14,
      "z": -1,
      "name": "Empty"
    },
    {
      "x": -4,
      "y": 15,
      "z": -1,
      "name": "Empty"
    },
    {
      "x": -4,
      "y": 16,
      "z": -1,
      "name": "Empty"
    },
    {
      "x": -4,
      "y": 1,
      "z": 0,
      "name": "Soil_Gravel_Sand"
    },
    {
      "x": -4,
      "y": 2,
      "z": 0,
      "name": "Soil_Gravel_Sand"
    },
    {
      "x": -4,
      "y": 3,
      "z": 0,
      "name": "Soil_Gravel_Sand"
    },
    {
      "x": -4,
      "y": 4,
      "z": 0,
      "name": "Soil_Gravel_Sand"
    },
    {
      "x": -4,
      "y": 5,
      "z": 0,
      "name": "Soil_Gravel_Sand"
    },
    {
      "x": -4,
      "y": 6,
      "z": 0,
      "name": "Soil_Gravel_Sand"
    },
    {
      "x": -4,
      "y": 7,
      "z": 0,
      "name": "Soil_Gravel_Sand"
    },
    {
      "x": -4,
      "y": 8,
      "z": 0,
      "name": "Soil_Gravel_Sand"
    },
    {
      "x": -4,
      "y": 9,
      "z": 0,
      "name": "Soil_Gravel_Sand"
    },
    {
      "x": -4,
      "y": 10,
      "z": 0,
      "name": "Empty"
    },
    {
      "x": -4,
      "y": 11,
      "z": 0,
      "name": "Empty"
    },
    {
      "x": -4,
      "y": 12,
      "z": 0,
      "name": "Empty"
    },
    {
      "x": -4,
      "y": 13,
      "z": 0,
      "name": "Empty"
    },
    {
      "x": -4,
      "y": 14,
      "z": 0,
      "name": "Empty"
    },
    {
      "x": -4,
      "y": 15,
      "z": 0,
      "name": "Empty"
    },
    {
      "x": -4,
      "y": 16,
      "z": 0,
      "name": "Empty"
    },
    {
      "x": -4,
      "y": 1,
      "z": 1,
      "name": "Soil_Gravel_Sand"
    },
    {
      "x": -4,
      "y": 2,
      "z": 1,
      "name": "Soil_Gravel_Sand"
    },
    {
      "x": -4,
      "y": 3,
      "z": 1,
      "name": "Soil_Gravel_Sand"
    },
    {
      "x": -4,
      "y": 4,
      "z": 1,
      "name": "Soil_Gravel_Sand"
    },
    {
      "x": -4,
      "y": 5,
      "z": 1,
      "name": "Soil_Gravel_Sand"
    },
    {
      "x": -4,
      "y": 6,
      "z": 1,
      "name": "Soil_Gravel_Sand"
    },
    {
      "x": -4,
      "y": 7,
      "z": 1,
      "name": "Soil_Gravel_Sand"
    },
    {
      "x": -4,
      "y": 8,
      "z": 1,
      "name": "Soil_Gravel_Sand"
    },
    {
      "x": -4,
      "y": 9,
      "z": 1,
      "name": "Soil_Gravel_Sand"
    },
    {
      "x": -4,
      "y": 10,
      "z": 1,
      "name": "Empty"
    },
    {
      "x": -4,
      "y": 11,
      "z": 1,
      "name": "Empty"
    },
    {
      "x": -4,
      "y": 12,
      "z": 1,
      "name": "Empty"
    },
    {
      "x": -4,
      "y": 13,
      "z": 1,
      "name": "Empty"
    },
    {
      "x": -4,
      "y": 14,
      "z": 1,
      "name": "Empty"
    },
    {
      "x": -4,
      "y": 15,
      "z": 1,
      "name": "Empty"
    },
    {
      "x": -4,
      "y": 16,
      "z": 1,
      "name": "Empty"
    },
    {
      "x": -4,
      "y": 1,
      "z": 2,
      "name": "Soil_Gravel_Sand"
    },
    {
      "x": -4,
      "y": 2,
      "z": 2,
      "name": "Soil_Gravel_Sand"
    },
    {
      "x": -4,
      "y": 3,
      "z": 2,
      "name": "Soil_Gravel_Sand"
    },
    {
      "x": -4,
      "y": 4,
      "z": 2,
      "name": "Soil_Gravel_Sand"
    },
    {
      "x": -4,
      "y": 5,
      "z": 2,
      "name": "Soil_Gravel_Sand"
    },
    {
      "x": -4,
      "y": 6,
      "z": 2,
      "name": "Soil_Gravel_Sand"
    },
    {
      "x": -4,
      "y": 7,
      "z": 2,
      "name": "Soil_Gravel_Sand"
    },
    {
      "x": -4,
      "y": 8,
      "z": 2,
      "name": "Soil_Gravel_Sand"
    },
    {
      "x": -4,
      "y": 1,
      "z": 3,
      "name": "Soil_Gravel_Sand"
    },
    {
      "x": -4,
      "y": 2,
      "z": 3,
      "name": "Soil_Gravel_Sand"
    },
    {
      "x": -4,
      "y": 3,
      "z": 3,
      "name": "Soil_Gravel_Sand"
    },
    {
      "x": -4,
      "y": 4,
      "z": 3,
      "name": "Soil_Gravel_Sand"
    },
    {
      "x": -4,
      "y": 5,
      "z": 3,
      "name": "Soil_Gravel_Sand"
    },
    {
      "x": -4,
      "y": 6,
      "z": 3,
      "name": "Soil_Gravel_Sand"
    },
    {
      "x": -4,
      "y": 7,
      "z": 3,
      "name": "Soil_Gravel_Sand"
    },
    {
      "x": -4,
      "y": 8,
      "z": 3,
      "name": "Soil_Gravel_Sand"
    },
    {
      "x": -4,
      "y": 1,
      "z": 4,
      "name": "Soil_Gravel_Sand"
    },
    {
      "x": -4,
      "y": 2,
      "z": 4,
      "name": "Soil_Gravel_Sand"
    },
    {
      "x": -4,
      "y": 3,
      "z": 4,
      "name": "Soil_Gravel_Sand"
    },
    {
      "x": -4,
      "y": 4,
      "z": 4,
      "name": "Soil_Gravel_Sand"
    },
    {
      "x": -4,
      "y": 5,
      "z": 4,
      "name": "Soil_Gravel_Sand"
    },
    {
      "x": -4,
      "y": 6,
      "z": 4,
      "name": "Soil_Gravel_Sand"
    },
    {
      "x": -4,
      "y": 7,
      "z": 4,
      "name": "Soil_Gravel_Sand"
    },
    {
      "x": -4,
      "y": 8,
      "z": 4,
      "name": "Soil_Gravel_Sand"
    },
    {
      "x": -4,
      "y": 1,
      "z": 5,
      "name": "Rock_Sandstone_Cobble"
    },
    {
      "x": -4,
      "y": 2,
      "z": 5,
      "name": "Rock_Sandstone_Cobble"
    },
    {
      "x": -4,
      "y": 3,
      "z": 5,
      "name": "Rock_Sandstone_Cobble"
    },
    {
      "x": -4,
      "y": 4,
      "z": 5,
      "name": "Rock_Sandstone_Cobble"
    },
    {
      "x": -4,
      "y": 5,
      "z": 5,
      "name": "Rock_Sandstone_Cobble"
    },
    {
      "x": -4,
      "y": 6,
      "z": 5,
      "name": "Rock_Sandstone_Cobble"
    },
    {
      "x": -4,
      "y": 7,
      "z": 5,
      "name": "Rock_Sandstone_Cobble"
    },
    {
      "x": -4,
      "y": 1,
      "z": 6,
      "name": "Rock_Sandstone_Cobble"
    },
    {
      "x": -4,
      "y": 2,
      "z": 6,
      "name": "Rock_Sandstone_Cobble"
    },
    {
      "x": -4,
      "y": 3,
      "z": 6,
      "name": "Rock_Sandstone_Cobble"
    },
    {
      "x": -4,
      "y": 4,
      "z": 6,
      "name": "Rock_Sandstone_Cobble"
    },
    {
      "x": -4,
      "y": 5,
      "z": 6,
      "name": "Rock_Sandstone_Cobble"
    },
    {
      "x": -4,
      "y": 6,
      "z": 6,
      "name": "Rock_Sandstone_Cobble"
    },
    {
      "x": -3,
      "y": 1,
      "z": -8,
      "name": "Rock_Sandstone_Cobble"
    },
    {
      "x": -3,
      "y": 2,
      "z": -8,
      "name": "Rock_Sandstone_Cobble"
    },
    {
      "x": -3,
      "y": 3,
      "z": -8,
      "name": "Rock_Sandstone_Cobble"
    },
    {
      "x": -3,
      "y": 4,
      "z": -8,
      "name": "Rock_Sandstone_Cobble"
    },
    {
      "x": -3,
      "y": 5,
      "z": -8,
      "name": "Rock_Sandstone_Cobble"
    },
    {
      "x": -3,
      "y": 6,
      "z": -8,
      "name": "Rock_Sandstone_Cobble"
    },
    {
      "x": -3,
      "y": 7,
      "z": -8,
      "name": "Rock_Sandstone_Cobble"
    },
    {
      "x": -3,
      "y": 8,
      "z": -8,
      "name": "Rock_Sandstone_Cobble"
    },
    {
      "x": -3,
      "y": 9,
      "z": -8,
      "name": "Rock_Sandstone_Cobble"
    },
    {
      "x": -3,
      "y": 10,
      "z": -8,
      "name": "Rock_Sandstone_Cobble"
    },
    {
      "x": -3,
      "y": 1,
      "z": -7,
      "name": "Rock_Sandstone_Cobble"
    },
    {
      "x": -3,
      "y": 2,
      "z": -7,
      "name": "Rock_Sandstone_Cobble"
    },
    {
      "x": -3,
      "y": 3,
      "z": -7,
      "name": "Rock_Sandstone_Cobble"
    },
    {
      "x": -3,
      "y": 4,
      "z": -7,
      "name": "Rock_Sandstone_Cobble"
    },
    {
      "x": -3,
      "y": 5,
      "z": -7,
      "name": "Rock_Sandstone_Cobble"
    },
    {
      "x": -3,
      "y": 6,
      "z": -7,
      "name": "Rock_Sandstone_Cobble"
    },
    {
      "x": -3,
      "y": 7,
      "z": -7,
      "name": "Deco_Bone_Full"
    },
    {
      "x": -3,
      "y": 8,
      "z": -7,
      "name": "Rock_Sandstone_Cobble"
    },
    {
      "x": -3,
      "y": 9,
      "z": -7,
      "name": "Rock_Sandstone_Cobble"
    },
    {
      "x": -3,
      "y": 10,
      "z": -7,
      "name": "Rock_Sandstone_Cobble"
    },
    {
      "x": -3,
      "y": 11,
      "z": -7,
      "name": "Rock_Sandstone_Cobble"
    },
    {
      "x": -3,
      "y": 12,
      "z": -7,
      "name": "Rock_Sandstone_Cobble"
    },
    {
      "x": -3,
      "y": 1,
      "z": -6,
      "name": "Soil_Gravel_Sand"
    },
    {
      "x": -3,
      "y": 2,
      "z": -6,
      "name": "Soil_Gravel_Sand"
    },
    {
      "x": -3,
      "y": 3,
      "z": -6,
      "name": "Soil_Gravel_Sand"
    },
    {
      "x": -3,
      "y": 4,
      "z": -6,
      "name": "Soil_Gravel_Sand"
    },
    {
      "x": -3,
      "y": 5,
      "z": -6,
      "name": "Soil_Gravel_Sand"
    },
    {
      "x": -3,
      "y": 6,
      "z": -6,
      "name": "Deco_Bone_Full"
    },
    {
      "x": -3,
      "y": 7,
      "z": -6,
      "name": "Deco_Bone_Full"
    },
    {
      "x": -3,
      "y": 8,
      "z": -6,
      "name": "Soil_Gravel_Sand"
    },
    {
      "x": -3,
      "y": 9,
      "z": -6,
      "name": "Rock_Sandstone_Cobble"
    },
    {
      "x": -3,
      "y": 10,
      "z": -6,
      "name": "Rock_Sandstone_Cobble"
    },
    {
      "x": -3,
      "y": 11,
      "z": -6,
      "name": "Rock_Sandstone_Cobble"
    },
    {
      "x": -3,
      "y": 12,
      "z": -6,
      "name": "Rock_Sandstone_Cobble"
    },
    {
      "x": -3,
      "y": 1,
      "z": -5,
      "name": "Soil_Gravel_Sand"
    },
    {
      "x": -3,
      "y": 2,
      "z": -5,
      "name": "Soil_Gravel_Sand"
    },
    {
      "x": -3,
      "y": 3,
      "z": -5,
      "name": "Soil_Gravel_Sand"
    },
    {
      "x": -3,
      "y": 4,
      "z": -5,
      "name": "Soil_Gravel_Sand"
    },
    {
      "x": -3,
      "y": 5,
      "z": -5,
      "name": "Soil_Gravel_Sand"
    },
    {
      "x": -3,
      "y": 6,
      "z": -5,
      "name": "Soil_Gravel_Sand"
    },
    {
      "x": -3,
      "y": 7,
      "z": -5,
      "name": "Soil_Gravel_Sand"
    },
    {
      "x": -3,
      "y": 8,
      "z": -5,
      "name": "Soil_Gravel_Sand"
    },
    {
      "x": -3,
      "y": 9,
      "z": -5,
      "name": "Soil_Gravel_Sand"
    },
    {
      "x": -3,
      "y": 10,
      "z": -5,
      "name": "Empty"
    },
    {
      "x": -3,
      "y": 11,
      "z": -5,
      "name": "Empty"
    },
    {
      "x": -3,
      "y": 12,
      "z": -5,
      "name": "Empty"
    },
    {
      "x": -3,
      "y": 13,
      "z": -5,
      "name": "Empty"
    },
    {
      "x": -3,
      "y": 14,
      "z": -5,
      "name": "Empty"
    },
    {
      "x": -3,
      "y": 15,
      "z": -5,
      "name": "Empty"
    },
    {
      "x": -3,
      "y": 16,
      "z": -5,
      "name": "Empty"
    },
    {
      "x": -3,
      "y": 1,
      "z": -4,
      "name": "Soil_Gravel_Sand"
    },
    {
      "x": -3,
      "y": 2,
      "z": -4,
      "name": "Soil_Gravel_Sand"
    },
    {
      "x": -3,
      "y": 3,
      "z": -4,
      "name": "Soil_Gravel_Sand"
    },
    {
      "x": -3,
      "y": 4,
      "z": -4,
      "name": "Soil_Gravel_Sand"
    },
    {
      "x": -3,
      "y": 5,
      "z": -4,
      "name": "Soil_Gravel_Sand"
    },
    {
      "x": -3,
      "y": 6,
      "z": -4,
      "name": "Soil_Gravel_Sand"
    },
    {
      "x": -3,
      "y": 7,
      "z": -4,
      "name": "Soil_Gravel_Sand"
    },
    {
      "x": -3,
      "y": 8,
      "z": -4,
      "name": "Soil_Gravel_Sand"
    },
    {
      "x": -3,
      "y": 9,
      "z": -4,
      "name": "Soil_Gravel_Sand"
    },
    {
      "x": -3,
      "y": 10,
      "z": -4,
      "name": "Empty"
    },
    {
      "x": -3,
      "y": 11,
      "z": -4,
      "name": "Empty"
    },
    {
      "x": -3,
      "y": 12,
      "z": -4,
      "name": "Empty"
    },
    {
      "x": -3,
      "y": 13,
      "z": -4,
      "name": "Empty"
    },
    {
      "x": -3,
      "y": 14,
      "z": -4,
      "name": "Empty"
    },
    {
      "x": -3,
      "y": 15,
      "z": -4,
      "name": "Empty"
    },
    {
      "x": -3,
      "y": 16,
      "z": -4,
      "name": "Empty"
    },
    {
      "x": -3,
      "y": 1,
      "z": -3,
      "name": "Soil_Gravel_Sand"
    },
    {
      "x": -3,
      "y": 2,
      "z": -3,
      "name": "Soil_Gravel_Sand"
    },
    {
      "x": -3,
      "y": 3,
      "z": -3,
      "name": "Soil_Gravel_Sand"
    },
    {
      "x": -3,
      "y": 4,
      "z": -3,
      "name": "Soil_Gravel_Sand"
    },
    {
      "x": -3,
      "y": 5,
      "z": -3,
      "name": "Soil_Gravel_Sand"
    },
    {
      "x": -3,
      "y": 6,
      "z": -3,
      "name": "Soil_Gravel_Sand"
    },
    {
      "x": -3,
      "y": 7,
      "z": -3,
      "name": "Soil_Gravel_Sand"
    },
    {
      "x": -3,
      "y": 8,
      "z": -3,
      "name": "Soil_Gravel_Sand"
    },
    {
      "x": -3,
      "y": 9,
      "z": -3,
      "name": "Soil_Gravel_Sand"
    },
    {
      "x": -3,
      "y": 10,
      "z": -3,
      "name": "Deco_Rope_Diagonal",
      "rotation": 3
    },
    {
      "x": -3,
      "y": 11,
      "z": -3,
      "name": "Empty"
    },
    {
      "x": -3,
      "y": 12,
      "z": -3,
      "name": "Empty"
    },
    {
      "x": -3,
      "y": 13,
      "z": -3,
      "name": "Empty"
    },
    {
      "x": -3,
      "y": 14,
      "z": -3,
      "name": "Empty"
    },
    {
      "x": -3,
      "y": 15,
      "z": -3,
      "name": "Empty"
    },
    {
      "x": -3,
      "y": 16,
      "z": -3,
      "name": "Empty"
    },
    {
      "x": -3,
      "y": 17,
      "z": -3,
      "name": "Empty"
    },
    {
      "x": -3,
      "y": 1,
      "z": -2,
      "name": "Soil_Gravel_Sand"
    },
    {
      "x": -3,
      "y": 2,
      "z": -2,
      "name": "Soil_Gravel_Sand"
    },
    {
      "x": -3,
      "y": 3,
      "z": -2,
      "name": "Soil_Gravel_Sand"
    },
    {
      "x": -3,
      "y": 4,
      "z": -2,
      "name": "Soil_Gravel_Sand"
    },
    {
      "x": -3,
      "y": 5,
      "z": -2,
      "name": "Soil_Gravel_Sand"
    },
    {
      "x": -3,
      "y": 6,
      "z": -2,
      "name": "Soil_Gravel_Sand"
    },
    {
      "x": -3,
      "y": 7,
      "z": -2,
      "name": "Soil_Gravel_Sand"
    },
    {
      "x": -3,
      "y": 8,
      "z": -2,
      "name": "Soil_Gravel_Sand"
    },
    {
      "x": -3,
      "y": 9,
      "z": -2,
      "name": "Soil_Gravel_Sand"
    },
    {
      "x": -3,
      "y": 10,
      "z": -2,
      "name": "Empty"
    },
    {
      "x": -3,
      "y": 11,
      "z": -2,
      "name": "Empty"
    },
    {
      "x": -3,
      "y": 12,
      "z": -2,
      "name": "Empty"
    },
    {
      "x": -3,
      "y": 13,
      "z": -2,
      "name": "Empty"
    },
    {
      "x": -3,
      "y": 14,
      "z": -2,
      "name": "Empty"
    },
    {
      "x": -3,
      "y": 15,
      "z": -2,
      "name": "Empty"
    },
    {
      "x": -3,
      "y": 16,
      "z": -2,
      "name": "Empty"
    },
    {
      "x": -3,
      "y": 17,
      "z": -2,
      "name": "Empty"
    },
    {
      "x": -3,
      "y": 1,
      "z": -1,
      "name": "Soil_Gravel_Sand"
    },
    {
      "x": -3,
      "y": 2,
      "z": -1,
      "name": "Soil_Gravel_Sand"
    },
    {
      "x": -3,
      "y": 3,
      "z": -1,
      "name": "Soil_Gravel_Sand"
    },
    {
      "x": -3,
      "y": 4,
      "z": -1,
      "name": "Soil_Gravel_Sand"
    },
    {
      "x": -3,
      "y": 5,
      "z": -1,
      "name": "Soil_Gravel_Sand"
    },
    {
      "x": -3,
      "y": 6,
      "z": -1,
      "name": "Soil_Gravel_Sand"
    },
    {
      "x": -3,
      "y": 7,
      "z": -1,
      "name": "Soil_Gravel_Sand"
    },
    {
      "x": -3,
      "y": 8,
      "z": -1,
      "name": "Soil_Gravel_Sand"
    },
    {
      "x": -3,
      "y": 9,
      "z": -1,
      "name": "Soil_Gravel_Sand"
    },
    {
      "x": -3,
      "y": 10,
      "z": -1,
      "name": "Empty"
    },
    {
      "x": -3,
      "y": 11,
      "z": -1,
      "name": "Empty"
    },
    {
      "x": -3,
      "y": 12,
      "z": -1,
      "name": "Empty"
    },
    {
      "x": -3,
      "y": 13,
      "z": -1,
      "name": "Empty"
    },
    {
      "x": -3,
      "y": 14,
      "z": -1,
      "name": "Empty"
    },
    {
      "x": -3,
      "y": 15,
      "z": -1,
      "name": "Empty"
    },
    {
      "x": -3,
      "y": 16,
      "z": -1,
      "name": "Empty"
    },
    {
      "x": -3,
      "y": 17,
      "z": -1,
      "name": "Empty"
    },
    {
      "x": -3,
      "y": 1,
      "z": 0,
      "name": "Soil_Gravel_Sand"
    },
    {
      "x": -3,
      "y": 2,
      "z": 0,
      "name": "Soil_Gravel_Sand"
    },
    {
      "x": -3,
      "y": 3,
      "z": 0,
      "name": "Soil_Gravel_Sand"
    },
    {
      "x": -3,
      "y": 4,
      "z": 0,
      "name": "Soil_Gravel_Sand"
    },
    {
      "x": -3,
      "y": 5,
      "z": 0,
      "name": "Soil_Gravel_Sand"
    },
    {
      "x": -3,
      "y": 6,
      "z": 0,
      "name": "Soil_Gravel_Sand"
    },
    {
      "x": -3,
      "y": 7,
      "z": 0,
      "name": "Soil_Gravel_Sand"
    },
    {
      "x": -3,
      "y": 8,
      "z": 0,
      "name": "Soil_Gravel_Sand"
    },
    {
      "x": -3,
      "y": 9,
      "z": 0,
      "name": "Soil_Gravel_Sand"
    },
    {
      "x": -3,
      "y": 10,
      "z": 0,
      "name": "Empty"
    },
    {
      "x": -3,
      "y": 11,
      "z": 0,
      "name": "Empty"
    },
    {
      "x": -3,
      "y": 12,
      "z": 0,
      "name": "Empty"
    },
    {
      "x": -3,
      "y": 13,
      "z": 0,
      "name": "Empty"
    },
    {
      "x": -3,
      "y": 14,
      "z": 0,
      "name": "Empty"
    },
    {
      "x": -3,
      "y": 15,
      "z": 0,
      "name": "Empty"
    },
    {
      "x": -3,
      "y": 16,
      "z": 0,
      "name": "Empty"
    },
    {
      "x": -3,
      "y": 17,
      "z": 0,
      "name": "Empty"
    },
    {
      "x": -3,
      "y": 1,
      "z": 1,
      "name": "Soil_Gravel_Sand"
    },
    {
      "x": -3,
      "y": 2,
      "z": 1,
      "name": "Soil_Gravel_Sand"
    },
    {
      "x": -3,
      "y": 3,
      "z": 1,
      "name": "Soil_Gravel_Sand"
    },
    {
      "x": -3,
      "y": 4,
      "z": 1,
      "name": "Soil_Gravel_Sand"
    },
    {
      "x": -3,
      "y": 5,
      "z": 1,
      "name": "Soil_Gravel_Sand"
    },
    {
      "x": -3,
      "y": 6,
      "z": 1,
      "name": "Soil_Gravel_Sand"
    },
    {
      "x": -3,
      "y": 7,
      "z": 1,
      "name": "Soil_Gravel_Sand"
    },
    {
      "x": -3,
      "y": 8,
      "z": 1,
      "name": "Soil_Gravel_Sand"
    },
    {
      "x": -3,
      "y": 9,
      "z": 1,
      "name": "Soil_Gravel_Sand"
    },
    {
      "x": -3,
      "y": 10,
      "z": 1,
      "name": "Deco_Rope_Diagonal",
      "rotation": 3
    },
    {
      "x": -3,
      "y": 11,
      "z": 1,
      "name": "Empty"
    },
    {
      "x": -3,
      "y": 12,
      "z": 1,
      "name": "Empty"
    },
    {
      "x": -3,
      "y": 13,
      "z": 1,
      "name": "Empty"
    },
    {
      "x": -3,
      "y": 14,
      "z": 1,
      "name": "Empty"
    },
    {
      "x": -3,
      "y": 15,
      "z": 1,
      "name": "Empty"
    },
    {
      "x": -3,
      "y": 16,
      "z": 1,
      "name": "Empty"
    },
    {
      "x": -3,
      "y": 17,
      "z": 1,
      "name": "Empty"
    },
    {
      "x": -3,
      "y": 1,
      "z": 2,
      "name": "Soil_Gravel_Sand"
    },
    {
      "x": -3,
      "y": 2,
      "z": 2,
      "name": "Soil_Gravel_Sand"
    },
    {
      "x": -3,
      "y": 3,
      "z": 2,
      "name": "Soil_Gravel_Sand"
    },
    {
      "x": -3,
      "y": 4,
      "z": 2,
      "name": "Soil_Gravel_Sand"
    },
    {
      "x": -3,
      "y": 5,
      "z": 2,
      "name": "Soil_Gravel_Sand"
    },
    {
      "x": -3,
      "y": 6,
      "z": 2,
      "name": "Soil_Gravel_Sand"
    },
    {
      "x": -3,
      "y": 7,
      "z": 2,
      "name": "Soil_Gravel_Sand"
    },
    {
      "x": -3,
      "y": 8,
      "z": 2,
      "name": "Soil_Gravel_Sand"
    },
    {
      "x": -3,
      "y": 9,
      "z": 2,
      "name": "Soil_Gravel_Sand"
    },
    {
      "x": -3,
      "y": 10,
      "z": 2,
      "name": "Empty"
    },
    {
      "x": -3,
      "y": 11,
      "z": 2,
      "name": "Empty"
    },
    {
      "x": -3,
      "y": 12,
      "z": 2,
      "name": "Empty"
    },
    {
      "x": -3,
      "y": 13,
      "z": 2,
      "name": "Empty"
    },
    {
      "x": -3,
      "y": 14,
      "z": 2,
      "name": "Empty"
    },
    {
      "x": -3,
      "y": 15,
      "z": 2,
      "name": "Empty"
    },
    {
      "x": -3,
      "y": 16,
      "z": 2,
      "name": "Empty"
    },
    {
      "x": -3,
      "y": 1,
      "z": 3,
      "name": "Soil_Gravel_Sand"
    },
    {
      "x": -3,
      "y": 2,
      "z": 3,
      "name": "Soil_Gravel_Sand"
    },
    {
      "x": -3,
      "y": 3,
      "z": 3,
      "name": "Soil_Gravel_Sand"
    },
    {
      "x": -3,
      "y": 4,
      "z": 3,
      "name": "Soil_Gravel_Sand"
    },
    {
      "x": -3,
      "y": 5,
      "z": 3,
      "name": "Soil_Gravel_Sand"
    },
    {
      "x": -3,
      "y": 6,
      "z": 3,
      "name": "Soil_Gravel_Sand"
    },
    {
      "x": -3,
      "y": 7,
      "z": 3,
      "name": "Soil_Gravel_Sand"
    },
    {
      "x": -3,
      "y": 8,
      "z": 3,
      "name": "Soil_Gravel_Sand"
    },
    {
      "x": -3,
      "y": 9,
      "z": 3,
      "name": "Soil_Gravel_Sand"
    },
    {
      "x": -3,
      "y": 10,
      "z": 3,
      "name": "Empty"
    },
    {
      "x": -3,
      "y": 11,
      "z": 3,
      "name": "Empty"
    },
    {
      "x": -3,
      "y": 12,
      "z": 3,
      "name": "Empty"
    },
    {
      "x": -3,
      "y": 13,
      "z": 3,
      "name": "Empty"
    },
    {
      "x": -3,
      "y": 14,
      "z": 3,
      "name": "Empty"
    },
    {
      "x": -3,
      "y": 15,
      "z": 3,
      "name": "Empty"
    },
    {
      "x": -3,
      "y": 16,
      "z": 3,
      "name": "Empty"
    },
    {
      "x": -3,
      "y": 1,
      "z": 4,
      "name": "Soil_Gravel_Sand"
    },
    {
      "x": -3,
      "y": 2,
      "z": 4,
      "name": "Soil_Gravel_Sand"
    },
    {
      "x": -3,
      "y": 3,
      "z": 4,
      "name": "Soil_Gravel_Sand"
    },
    {
      "x": -3,
      "y": 4,
      "z": 4,
      "name": "Soil_Gravel_Sand"
    },
    {
      "x": -3,
      "y": 5,
      "z": 4,
      "name": "Soil_Gravel_Sand"
    },
    {
      "x": -3,
      "y": 6,
      "z": 4,
      "name": "Wood_Dry_Trunk"
    },
    {
      "x": -3,
      "y": 7,
      "z": 4,
      "name": "Wood_Dry_Trunk"
    },
    {
      "x": -3,
      "y": 8,
      "z": 4,
      "name": "Soil_Gravel_Sand"
    },
    {
      "x": -3,
      "y": 1,
      "z": 5,
      "name": "Soil_Gravel_Sand"
    },
    {
      "x": -3,
      "y": 2,
      "z": 5,
      "name": "Soil_Gravel_Sand"
    },
    {
      "x": -3,
      "y": 3,
      "z": 5,
      "name": "Soil_Gravel_Sand"
    },
    {
      "x": -3,
      "y": 4,
      "z": 5,
      "name": "Soil_Gravel_Sand"
    },
    {
      "x": -3,
      "y": 5,
      "z": 5,
      "name": "Soil_Gravel_Sand"
    },
    {
      "x": -3,
      "y": 6,
      "z": 5,
      "name": "Soil_Gravel_Sand"
    },
    {
      "x": -3,
      "y": 7,
      "z": 5,
      "name": "Soil_Gravel_Sand"
    },
    {
      "x": -3,
      "y": 8,
      "z": 5,
      "name": "Soil_Gravel_Sand"
    },
    {
      "x": -3,
      "y": 1,
      "z": 6,
      "name": "Rock_Sandstone_Cobble"
    },
    {
      "x": -3,
      "y": 2,
      "z": 6,
      "name": "Rock_Sandstone_Cobble"
    },
    {
      "x": -3,
      "y": 3,
      "z": 6,
      "name": "Rock_Sandstone_Cobble"
    },
    {
      "x": -3,
      "y": 4,
      "z": 6,
      "name": "Rock_Sandstone_Cobble"
    },
    {
      "x": -3,
      "y": 5,
      "z": 6,
      "name": "Rock_Sandstone_Cobble"
    },
    {
      "x": -3,
      "y": 6,
      "z": 6,
      "name": "Rock_Sandstone_Cobble"
    },
    {
      "x": -3,
      "y": 7,
      "z": 6,
      "name": "Rock_Sandstone_Cobble"
    },
    {
      "x": -2,
      "y": 1,
      "z": -8,
      "name": "Rock_Sandstone_Cobble"
    },
    {
      "x": -2,
      "y": 2,
      "z": -8,
      "name": "Rock_Sandstone_Cobble"
    },
    {
      "x": -2,
      "y": 3,
      "z": -8,
      "name": "Rock_Sandstone_Cobble"
    },
    {
      "x": -2,
      "y": 4,
      "z": -8,
      "name": "Rock_Sandstone_Cobble"
    },
    {
      "x": -2,
      "y": 5,
      "z": -8,
      "name": "Rock_Sandstone_Cobble"
    },
    {
      "x": -2,
      "y": 6,
      "z": -8,
      "name": "Rock_Sandstone_Cobble"
    },
    {
      "x": -2,
      "y": 7,
      "z": -8,
      "name": "Rock_Sandstone_Cobble"
    },
    {
      "x": -2,
      "y": 8,
      "z": -8,
      "name": "Rock_Sandstone_Cobble"
    },
    {
      "x": -2,
      "y": 9,
      "z": -8,
      "name": "Rock_Sandstone_Cobble"
    },
    {
      "x": -2,
      "y": 10,
      "z": -8,
      "name": "Rock_Sandstone_Cobble"
    },
    {
      "x": -2,
      "y": 11,
      "z": -8,
      "name": "Rock_Sandstone_Cobble"
    },
    {
      "x": -2,
      "y": 12,
      "z": -8,
      "name": "Rock_Sandstone_Cobble"
    },
    {
      "x": -2,
      "y": 1,
      "z": -7,
      "name": "Soil_Gravel_Sand"
    },
    {
      "x": -2,
      "y": 2,
      "z": -7,
      "name": "Soil_Gravel_Sand"
    },
    {
      "x": -2,
      "y": 3,
      "z": -7,
      "name": "Soil_Gravel_Sand"
    },
    {
      "x": -2,
      "y": 4,
      "z": -7,
      "name": "Soil_Gravel_Sand"
    },
    {
      "x": -2,
      "y": 5,
      "z": -7,
      "name": "Soil_Gravel_Sand"
    },
    {
      "x": -2,
      "y": 6,
      "z": -7,
      "name": "Deco_Bone_Full"
    },
    {
      "x": -2,
      "y": 7,
      "z": -7,
      "name": "Deco_Bone_Full"
    },
    {
      "x": -2,
      "y": 8,
      "z": -7,
      "name": "Soil_Gravel_Sand"
    },
    {
      "x": -2,
      "y": 9,
      "z": -7,
      "name": "Rock_Sandstone_Cobble"
    },
    {
      "x": -2,
      "y": 10,
      "z": -7,
      "name": "Rock_Sandstone_Cobble"
    },
    {
      "x": -2,
      "y": 1,
      "z": -6,
      "name": "Soil_Gravel_Sand"
    },
    {
      "x": -2,
      "y": 2,
      "z": -6,
      "name": "Soil_Gravel_Sand"
    },
    {
      "x": -2,
      "y": 3,
      "z": -6,
      "name": "Soil_Gravel_Sand"
    },
    {
      "x": -2,
      "y": 4,
      "z": -6,
      "name": "Soil_Gravel_Sand"
    },
    {
      "x": -2,
      "y": 5,
      "z": -6,
      "name": "Soil_Gravel_Sand"
    },
    {
      "x": -2,
      "y": 6,
      "z": -6,
      "name": "Deco_Bone_Full"
    },
    {
      "x": -2,
      "y": 7,
      "z": -6,
      "name": "Deco_Bone_Full"
    },
    {
      "x": -2,
      "y": 8,
      "z": -6,
      "name": "Soil_Gravel_Sand"
    },
    {
      "x": -2,
      "y": 9,
      "z": -6,
      "name": "Soil_Gravel_Sand"
    },
    {
      "x": -2,
      "y": 10,
      "z": -6,
      "name": "Empty"
    },
    {
      "x": -2,
      "y": 11,
      "z": -6,
      "name": "Empty"
    },
    {
      "x": -2,
      "y": 12,
      "z": -6,
      "name": "Empty"
    },
    {
      "x": -2,
      "y": 13,
      "z": -6,
      "name": "Empty"
    },
    {
      "x": -2,
      "y": 14,
      "z": -6,
      "name": "Empty"
    },
    {
      "x": -2,
      "y": 15,
      "z": -6,
      "name": "Empty"
    },
    {
      "x": -2,
      "y": 16,
      "z": -6,
      "name": "Empty"
    },
    {
      "x": -2,
      "y": 1,
      "z": -5,
      "name": "Soil_Gravel_Sand"
    },
    {
      "x": -2,
      "y": 2,
      "z": -5,
      "name": "Soil_Gravel_Sand"
    },
    {
      "x": -2,
      "y": 3,
      "z": -5,
      "name": "Soil_Gravel_Sand"
    },
    {
      "x": -2,
      "y": 4,
      "z": -5,
      "name": "Soil_Gravel_Sand"
    },
    {
      "x": -2,
      "y": 5,
      "z": -5,
      "name": "Soil_Gravel_Sand"
    },
    {
      "x": -2,
      "y": 6,
      "z": -5,
      "name": "Soil_Gravel_Sand"
    },
    {
      "x": -2,
      "y": 7,
      "z": -5,
      "name": "Soil_Gravel_Sand"
    },
    {
      "x": -2,
      "y": 8,
      "z": -5,
      "name": "Soil_Gravel_Sand"
    },
    {
      "x": -2,
      "y": 9,
      "z": -5,
      "name": "Soil_Gravel_Sand"
    },
    {
      "x": -2,
      "y": 10,
      "z": -5,
      "name": "Empty"
    },
    {
      "x": -2,
      "y": 11,
      "z": -5,
      "name": "Empty"
    },
    {
      "x": -2,
      "y": 12,
      "z": -5,
      "name": "Empty"
    },
    {
      "x": -2,
      "y": 13,
      "z": -5,
      "name": "Empty"
    },
    {
      "x": -2,
      "y": 14,
      "z": -5,
      "name": "Empty"
    },
    {
      "x": -2,
      "y": 15,
      "z": -5,
      "name": "Empty"
    },
    {
      "x": -2,
      "y": 16,
      "z": -5,
      "name": "Empty"
    },
    {
      "x": -2,
      "y": 17,
      "z": -5,
      "name": "Empty"
    },
    {
      "x": -2,
      "y": 1,
      "z": -4,
      "name": "Soil_Gravel_Sand"
    },
    {
      "x": -2,
      "y": 2,
      "z": -4,
      "name": "Soil_Gravel_Sand"
    },
    {
      "x": -2,
      "y": 3,
      "z": -4,
      "name": "Soil_Gravel_Sand"
    },
    {
      "x": -2,
      "y": 4,
      "z": -4,
      "name": "Soil_Gravel_Sand"
    },
    {
      "x": -2,
      "y": 5,
      "z": -4,
      "name": "Soil_Gravel_Sand"
    },
    {
      "x": -2,
      "y": 6,
      "z": -4,
      "name": "Soil_Gravel_Sand"
    },
    {
      "x": -2,
      "y": 7,
      "z": -4,
      "name": "Soil_Gravel_Sand"
    },
    {
      "x": -2,
      "y": 8,
      "z": -4,
      "name": "Soil_Gravel_Sand"
    },
    {
      "x": -2,
      "y": 9,
      "z": -4,
      "name": "Soil_Gravel_Sand"
    },
    {
      "x": -2,
      "y": 10,
      "z": -4,
      "name": "Empty"
    },
    {
      "x": -2,
      "y": 11,
      "z": -4,
      "name": "Empty"
    },
    {
      "x": -2,
      "y": 12,
      "z": -4,
      "name": "Empty"
    },
    {
      "x": -2,
      "y": 13,
      "z": -4,
      "name": "Empty"
    },
    {
      "x": -2,
      "y": 14,
      "z": -4,
      "name": "Empty"
    },
    {
      "x": -2,
      "y": 15,
      "z": -4,
      "name": "Empty"
    },
    {
      "x": -2,
      "y": 16,
      "z": -4,
      "name": "Empty"
    },
    {
      "x": -2,
      "y": 17,
      "z": -4,
      "name": "Empty"
    },
    {
      "x": -2,
      "y": 1,
      "z": -3,
      "name": "Soil_Gravel_Sand"
    },
    {
      "x": -2,
      "y": 2,
      "z": -3,
      "name": "Soil_Gravel_Sand"
    },
    {
      "x": -2,
      "y": 3,
      "z": -3,
      "name": "Soil_Gravel_Sand"
    },
    {
      "x": -2,
      "y": 4,
      "z": -3,
      "name": "Soil_Gravel_Sand"
    },
    {
      "x": -2,
      "y": 5,
      "z": -3,
      "name": "Soil_Gravel_Sand"
    },
    {
      "x": -2,
      "y": 6,
      "z": -3,
      "name": "Soil_Gravel_Sand"
    },
    {
      "x": -2,
      "y": 7,
      "z": -3,
      "name": "Soil_Gravel_Sand"
    },
    {
      "x": -2,
      "y": 8,
      "z": -3,
      "name": "Soil_Gravel_Sand"
    },
    {
      "x": -2,
      "y": 9,
      "z": -3,
      "name": "Soil_Gravel_Sand"
    },
    {
      "x": -2,
      "y": 10,
      "z": -3,
      "name": "Empty"
    },
    {
      "x": -2,
      "y": 11,
      "z": -3,
      "name": "Deco_Rope_Diagonal",
      "rotation": 3
    },
    {
      "x": -2,
      "y": 12,
      "z": -3,
      "name": "Empty"
    },
    {
      "x": -2,
      "y": 13,
      "z": -3,
      "name": "Empty"
    },
    {
      "x": -2,
      "y": 14,
      "z": -3,
      "name": "Empty"
    },
    {
      "x": -2,
      "y": 15,
      "z": -3,
      "name": "Empty"
    },
    {
      "x": -2,
      "y": 16,
      "z": -3,
      "name": "Empty"
    },
    {
      "x": -2,
      "y": 17,
      "z": -3,
      "name": "Empty"
    },
    {
      "x": -2,
      "y": 18,
      "z": -3,
      "name": "Empty"
    },
    {
      "x": -2,
      "y": 1,
      "z": -2,
      "name": "Soil_Gravel_Sand"
    },
    {
      "x": -2,
      "y": 2,
      "z": -2,
      "name": "Soil_Gravel_Sand"
    },
    {
      "x": -2,
      "y": 3,
      "z": -2,
      "name": "Soil_Gravel_Sand"
    },
    {
      "x": -2,
      "y": 4,
      "z": -2,
      "name": "Soil_Gravel_Sand"
    },
    {
      "x": -2,
      "y": 5,
      "z": -2,
      "name": "Soil_Gravel_Sand"
    },
    {
      "x": -2,
      "y": 6,
      "z": -2,
      "name": "Soil_Gravel_Sand"
    },
    {
      "x": -2,
      "y": 7,
      "z": -2,
      "name": "Soil_Gravel_Sand"
    },
    {
      "x": -2,
      "y": 8,
      "z": -2,
      "name": "Soil_Gravel_Sand"
    },
    {
      "x": -2,
      "y": 9,
      "z": -2,
      "name": "Soil_Gravel_Sand"
    },
    {
      "x": -2,
      "y": 10,
      "z": -2,
      "name": "Cloth_Roof_Hide_Vertical",
      "rotation": 3
    },
    {
      "x": -2,
      "y": 11,
      "z": -2,
      "name": "Cloth_Roof_Hide_Vertical",
      "rotation": 3
    },
    {
      "x": -2,
      "y": 12,
      "z": -2,
      "name": "Wood_Drywood_Planks_Half",
      "rotation": 7
    },
    {
      "x": -2,
      "y": 13,
      "z": -2,
      "name": "Empty"
    },
    {
      "x": -2,
      "y": 14,
      "z": -2,
      "name": "Empty"
    },
    {
      "x": -2,
      "y": 15,
      "z": -2,
      "name": "Empty"
    },
    {
      "x": -2,
      "y": 16,
      "z": -2,
      "name": "Empty"
    },
    {
      "x": -2,
      "y": 17,
      "z": -2,
      "name": "Empty"
    },
    {
      "x": -2,
      "y": 18,
      "z": -2,
      "name": "Empty"
    },
    {
      "x": -2,
      "y": 1,
      "z": -1,
      "name": "Soil_Gravel_Sand"
    },
    {
      "x": -2,
      "y": 2,
      "z": -1,
      "name": "Soil_Gravel_Sand"
    },
    {
      "x": -2,
      "y": 3,
      "z": -1,
      "name": "Soil_Gravel_Sand"
    },
    {
      "x": -2,
      "y": 4,
      "z": -1,
      "name": "Soil_Gravel_Sand"
    },
    {
      "x": -2,
      "y": 5,
      "z": -1,
      "name": "Soil_Gravel_Sand"
    },
    {
      "x": -2,
      "y": 6,
      "z": -1,
      "name": "Soil_Gravel_Sand"
    },
    {
      "x": -2,
      "y": 7,
      "z": -1,
      "name": "Soil_Gravel_Sand"
    },
    {
      "x": -2,
      "y": 8,
      "z": -1,
      "name": "Soil_Gravel_Sand"
    },
    {
      "x": -2,
      "y": 9,
      "z": -1,
      "name": "Soil_Gravel_Sand"
    },
    {
      "x": -2,
      "y": 10,
      "z": -1,
      "name": "Cloth_Roof_Hide_Vertical",
      "rotation": 3
    },
    {
      "x": -2,
      "y": 11,
      "z": -1,
      "name": "Cloth_Roof_Hide_Flap",
      "rotation": 3
    },
    {
      "x": -2,
      "y": 12,
      "z": -1,
      "name": "Wood_Drywood_Planks_Half",
      "rotation": 7
    },
    {
      "x": -2,
      "y": 13,
      "z": -1,
      "name": "Empty"
    },
    {
      "x": -2,
      "y": 14,
      "z": -1,
      "name": "Empty"
    },
    {
      "x": -2,
      "y": 15,
      "z": -1,
      "name": "Empty"
    },
    {
      "x": -2,
      "y": 16,
      "z": -1,
      "name": "Empty"
    },
    {
      "x": -2,
      "y": 17,
      "z": -1,
      "name": "Empty"
    },
    {
      "x": -2,
      "y": 18,
      "z": -1,
      "name": "Empty"
    },
    {
      "x": -2,
      "y": 1,
      "z": 0,
      "name": "Soil_Gravel_Sand"
    },
    {
      "x": -2,
      "y": 2,
      "z": 0,
      "name": "Soil_Gravel_Sand"
    },
    {
      "x": -2,
      "y": 3,
      "z": 0,
      "name": "Soil_Gravel_Sand"
    },
    {
      "x": -2,
      "y": 4,
      "z": 0,
      "name": "Soil_Gravel_Sand"
    },
    {
      "x": -2,
      "y": 5,
      "z": 0,
      "name": "Soil_Gravel_Sand"
    },
    {
      "x": -2,
      "y": 6,
      "z": 0,
      "name": "Soil_Gravel_Sand"
    },
    {
      "x": -2,
      "y": 7,
      "z": 0,
      "name": "Soil_Gravel_Sand"
    },
    {
      "x": -2,
      "y": 8,
      "z": 0,
      "name": "Soil_Gravel_Sand"
    },
    {
      "x": -2,
      "y": 9,
      "z": 0,
      "name": "Soil_Gravel_Sand"
    },
    {
      "x": -2,
      "y": 10,
      "z": 0,
      "name": "Cloth_Roof_Hide_Vertical",
      "rotation": 3
    },
    {
      "x": -2,
      "y": 11,
      "z": 0,
      "name": "Cloth_Roof_Hide_Vertical",
      "rotation": 3
    },
    {
      "x": -2,
      "y": 12,
      "z": 0,
      "name": "Wood_Drywood_Planks_Half",
      "rotation": 7
    },
    {
      "x": -2,
      "y": 13,
      "z": 0,
      "name": "Empty"
    },
    {
      "x": -2,
      "y": 14,
      "z": 0,
      "name": "Empty"
    },
    {
      "x": -2,
      "y": 15,
      "z": 0,
      "name": "Empty"
    },
    {
      "x": -2,
      "y": 16,
      "z": 0,
      "name": "Empty"
    },
    {
      "x": -2,
      "y": 17,
      "z": 0,
      "name": "Empty"
    },
    {
      "x": -2,
      "y": 18,
      "z": 0,
      "name": "Empty"
    },
    {
      "x": -2,
      "y": 1,
      "z": 1,
      "name": "Soil_Gravel_Sand"
    },
    {
      "x": -2,
      "y": 2,
      "z": 1,
      "name": "Soil_Gravel_Sand"
    },
    {
      "x": -2,
      "y": 3,
      "z": 1,
      "name": "Soil_Gravel_Sand"
    },
    {
      "x": -2,
      "y": 4,
      "z": 1,
      "name": "Soil_Gravel_Sand"
    },
    {
      "x": -2,
      "y": 5,
      "z": 1,
      "name": "Soil_Gravel_Sand"
    },
    {
      "x": -2,
      "y": 6,
      "z": 1,
      "name": "Soil_Gravel_Sand"
    },
    {
      "x": -2,
      "y": 7,
      "z": 1,
      "name": "Soil_Gravel_Sand"
    },
    {
      "x": -2,
      "y": 8,
      "z": 1,
      "name": "Soil_Gravel_Sand"
    },
    {
      "x": -2,
      "y": 9,
      "z": 1,
      "name": "Soil_Gravel_Sand"
    },
    {
      "x": -2,
      "y": 10,
      "z": 1,
      "name": "Empty"
    },
    {
      "x": -2,
      "y": 11,
      "z": 1,
      "name": "Deco_Rope_Diagonal",
      "rotation": 3
    },
    {
      "x": -2,
      "y": 12,
      "z": 1,
      "name": "Empty"
    },
    {
      "x": -2,
      "y": 13,
      "z": 1,
      "name": "Empty"
    },
    {
      "x": -2,
      "y": 14,
      "z": 1,
      "name": "Empty"
    },
    {
      "x": -2,
      "y": 15,
      "z": 1,
      "name": "Empty"
    },
    {
      "x": -2,
      "y": 16,
      "z": 1,
      "name": "Empty"
    },
    {
      "x": -2,
      "y": 17,
      "z": 1,
      "name": "Empty"
    },
    {
      "x": -2,
      "y": 18,
      "z": 1,
      "name": "Empty"
    },
    {
      "x": -2,
      "y": 1,
      "z": 2,
      "name": "Soil_Gravel_Sand"
    },
    {
      "x": -2,
      "y": 2,
      "z": 2,
      "name": "Soil_Gravel_Sand"
    },
    {
      "x": -2,
      "y": 3,
      "z": 2,
      "name": "Soil_Gravel_Sand"
    },
    {
      "x": -2,
      "y": 4,
      "z": 2,
      "name": "Soil_Gravel_Sand"
    },
    {
      "x": -2,
      "y": 5,
      "z": 2,
      "name": "Soil_Gravel_Sand"
    },
    {
      "x": -2,
      "y": 6,
      "z": 2,
      "name": "Soil_Gravel_Sand"
    },
    {
      "x": -2,
      "y": 7,
      "z": 2,
      "name": "Soil_Gravel_Sand"
    },
    {
      "x": -2,
      "y": 8,
      "z": 2,
      "name": "Soil_Gravel_Sand"
    },
    {
      "x": -2,
      "y": 9,
      "z": 2,
      "name": "Soil_Gravel_Sand"
    },
    {
      "x": -2,
      "y": 10,
      "z": 2,
      "name": "Empty"
    },
    {
      "x": -2,
      "y": 11,
      "z": 2,
      "name": "Empty"
    },
    {
      "x": -2,
      "y": 12,
      "z": 2,
      "name": "Empty"
    },
    {
      "x": -2,
      "y": 13,
      "z": 2,
      "name": "Empty"
    },
    {
      "x": -2,
      "y": 14,
      "z": 2,
      "name": "Empty"
    },
    {
      "x": -2,
      "y": 15,
      "z": 2,
      "name": "Empty"
    },
    {
      "x": -2,
      "y": 16,
      "z": 2,
      "name": "Empty"
    },
    {
      "x": -2,
      "y": 17,
      "z": 2,
      "name": "Empty"
    },
    {
      "x": -2,
      "y": 1,
      "z": 3,
      "name": "Soil_Gravel_Sand"
    },
    {
      "x": -2,
      "y": 2,
      "z": 3,
      "name": "Soil_Gravel_Sand"
    },
    {
      "x": -2,
      "y": 3,
      "z": 3,
      "name": "Soil_Gravel_Sand"
    },
    {
      "x": -2,
      "y": 4,
      "z": 3,
      "name": "Soil_Gravel_Sand"
    },
    {
      "x": -2,
      "y": 5,
      "z": 3,
      "name": "Soil_Gravel_Sand"
    },
    {
      "x": -2,
      "y": 6,
      "z": 3,
      "name": "Soil_Gravel_Sand"
    },
    {
      "x": -2,
      "y": 7,
      "z": 3,
      "name": "Soil_Gravel_Sand"
    },
    {
      "x": -2,
      "y": 8,
      "z": 3,
      "name": "Soil_Gravel_Sand"
    },
    {
      "x": -2,
      "y": 9,
      "z": 3,
      "name": "Soil_Gravel_Sand"
    },
    {
      "x": -2,
      "y": 10,
      "z": 3,
      "name": "Empty"
    },
    {
      "x": -2,
      "y": 11,
      "z": 3,
      "name": "Empty"
    },
    {
      "x": -2,
      "y": 12,
      "z": 3,
      "name": "Empty"
    },
    {
      "x": -2,
      "y": 13,
      "z": 3,
      "name": "Empty"
    },
    {
      "x": -2,
      "y": 14,
      "z": 3,
      "name": "Empty"
    },
    {
      "x": -2,
      "y": 15,
      "z": 3,
      "name": "Empty"
    },
    {
      "x": -2,
      "y": 16,
      "z": 3,
      "name": "Empty"
    },
    {
      "x": -2,
      "y": 17,
      "z": 3,
      "name": "Empty"
    },
    {
      "x": -2,
      "y": 1,
      "z": 4,
      "name": "Soil_Gravel_Sand"
    },
    {
      "x": -2,
      "y": 2,
      "z": 4,
      "name": "Soil_Gravel_Sand"
    },
    {
      "x": -2,
      "y": 3,
      "z": 4,
      "name": "Soil_Gravel_Sand"
    },
    {
      "x": -2,
      "y": 4,
      "z": 4,
      "name": "Soil_Gravel_Sand"
    },
    {
      "x": -2,
      "y": 5,
      "z": 4,
      "name": "Soil_Gravel_Sand"
    },
    {
      "x": -2,
      "y": 6,
      "z": 4,
      "name": "Soil_Gravel_Sand"
    },
    {
      "x": -2,
      "y": 7,
      "z": 4,
      "name": "Soil_Gravel_Sand"
    },
    {
      "x": -2,
      "y": 8,
      "z": 4,
      "name": "Soil_Gravel_Sand"
    },
    {
      "x": -2,
      "y": 9,
      "z": 4,
      "name": "Soil_Dirt_Dry"
    },
    {
      "x": -2,
      "y": 10,
      "z": 4,
      "name": "Empty"
    },
    {
      "x": -2,
      "y": 11,
      "z": 4,
      "name": "Empty"
    },
    {
      "x": -2,
      "y": 12,
      "z": 4,
      "name": "Empty"
    },
    {
      "x": -2,
      "y": 13,
      "z": 4,
      "name": "Empty"
    },
    {
      "x": -2,
      "y": 14,
      "z": 4,
      "name": "Empty"
    },
    {
      "x": -2,
      "y": 15,
      "z": 4,
      "name": "Empty"
    },
    {
      "x": -2,
      "y": 16,
      "z": 4,
      "name": "Empty"
    },
    {
      "x": -2,
      "y": 1,
      "z": 5,
      "name": "Soil_Gravel_Sand"
    },
    {
      "x": -2,
      "y": 2,
      "z": 5,
      "name": "Soil_Gravel_Sand"
    },
    {
      "x": -2,
      "y": 3,
      "z": 5,
      "name": "Soil_Gravel_Sand"
    },
    {
      "x": -2,
      "y": 4,
      "z": 5,
      "name": "Soil_Gravel_Sand"
    },
    {
      "x": -2,
      "y": 5,
      "z": 5,
      "name": "Soil_Gravel_Sand"
    },
    {
      "x": -2,
      "y": 6,
      "z": 5,
      "name": "Soil_Gravel_Sand"
    },
    {
      "x": -2,
      "y": 7,
      "z": 5,
      "name": "Soil_Gravel_Sand"
    },
    {
      "x": -2,
      "y": 8,
      "z": 5,
      "name": "Soil_Gravel_Sand"
    },
    {
      "x": -2,
      "y": 1,
      "z": 6,
      "name": "Soil_Gravel_Sand"
    },
    {
      "x": -2,
      "y": 2,
      "z": 6,
      "name": "Soil_Gravel_Sand"
    },
    {
      "x": -2,
      "y": 3,
      "z": 6,
      "name": "Soil_Gravel_Sand"
    },
    {
      "x": -2,
      "y": 4,
      "z": 6,
      "name": "Soil_Gravel_Sand"
    },
    {
      "x": -2,
      "y": 5,
      "z": 6,
      "name": "Soil_Gravel_Sand"
    },
    {
      "x": -2,
      "y": 6,
      "z": 6,
      "name": "Soil_Gravel_Sand"
    },
    {
      "x": -2,
      "y": 7,
      "z": 6,
      "name": "Soil_Gravel_Sand"
    },
    {
      "x": -2,
      "y": 8,
      "z": 6,
      "name": "Soil_Gravel_Sand"
    },
    {
      "x": -2,
      "y": 1,
      "z": 7,
      "name": "Rock_Sandstone_Cobble"
    },
    {
      "x": -2,
      "y": 2,
      "z": 7,
      "name": "Rock_Sandstone_Cobble"
    },
    {
      "x": -2,
      "y": 3,
      "z": 7,
      "name": "Rock_Sandstone_Cobble"
    },
    {
      "x": -2,
      "y": 4,
      "z": 7,
      "name": "Rock_Sandstone_Cobble"
    },
    {
      "x": -2,
      "y": 5,
      "z": 7,
      "name": "Rock_Sandstone_Cobble"
    },
    {
      "x": -2,
      "y": 6,
      "z": 7,
      "name": "Rock_Sandstone_Cobble"
    },
    {
      "x": -2,
      "y": 7,
      "z": 7,
      "name": "Rock_Sandstone_Cobble"
    },
    {
      "x": -1,
      "y": 1,
      "z": -9,
      "name": "Rock_Sandstone_Cobble"
    },
    {
      "x": -1,
      "y": 2,
      "z": -9,
      "name": "Rock_Sandstone_Cobble"
    },
    {
      "x": -1,
      "y": 3,
      "z": -9,
      "name": "Rock_Sandstone_Cobble"
    },
    {
      "x": -1,
      "y": 4,
      "z": -9,
      "name": "Rock_Sandstone_Cobble"
    },
    {
      "x": -1,
      "y": 5,
      "z": -9,
      "name": "Rock_Sandstone_Cobble"
    },
    {
      "x": -1,
      "y": 6,
      "z": -9,
      "name": "Rock_Sandstone_Cobble"
    },
    {
      "x": -1,
      "y": 7,
      "z": -9,
      "name": "Rock_Sandstone_Cobble"
    },
    {
      "x": -1,
      "y": 8,
      "z": -9,
      "name": "Rock_Sandstone_Cobble"
    },
    {
      "x": -1,
      "y": 9,
      "z": -9,
      "name": "Rock_Sandstone_Cobble"
    },
    {
      "x": -1,
      "y": 10,
      "z": -9,
      "name": "Rock_Sandstone_Cobble"
    },
    {
      "x": -1,
      "y": 1,
      "z": -8,
      "name": "Rock_Sandstone_Cobble"
    },
    {
      "x": -1,
      "y": 2,
      "z": -8,
      "name": "Rock_Sandstone_Cobble"
    },
    {
      "x": -1,
      "y": 3,
      "z": -8,
      "name": "Rock_Sandstone_Cobble"
    },
    {
      "x": -1,
      "y": 4,
      "z": -8,
      "name": "Rock_Sandstone_Cobble"
    },
    {
      "x": -1,
      "y": 5,
      "z": -8,
      "name": "Rock_Sandstone_Cobble"
    },
    {
      "x": -1,
      "y": 6,
      "z": -8,
      "name": "Rock_Sandstone_Cobble"
    },
    {
      "x": -1,
      "y": 7,
      "z": -8,
      "name": "Rock_Sandstone_Cobble"
    },
    {
      "x": -1,
      "y": 8,
      "z": -8,
      "name": "Rock_Sandstone_Cobble"
    },
    {
      "x": -1,
      "y": 9,
      "z": -8,
      "name": "Rock_Sandstone_Cobble"
    },
    {
      "x": -1,
      "y": 10,
      "z": -8,
      "name": "Rock_Sandstone_Cobble"
    },
    {
      "x": -1,
      "y": 11,
      "z": -8,
      "name": "Rock_Sandstone_Cobble"
    },
    {
      "x": -1,
      "y": 1,
      "z": -7,
      "name": "Soil_Gravel_Sand"
    },
    {
      "x": -1,
      "y": 2,
      "z": -7,
      "name": "Soil_Gravel_Sand"
    },
    {
      "x": -1,
      "y": 3,
      "z": -7,
      "name": "Soil_Gravel_Sand"
    },
    {
      "x": -1,
      "y": 4,
      "z": -7,
      "name": "Soil_Gravel_Sand"
    },
    {
      "x": -1,
      "y": 5,
      "z": -7,
      "name": "Soil_Gravel_Sand"
    },
    {
      "x": -1,
      "y": 6,
      "z": -7,
      "name": "Soil_Gravel_Sand"
    },
    {
      "x": -1,
      "y": 7,
      "z": -7,
      "name": "Soil_Gravel_Sand"
    },
    {
      "x": -1,
      "y": 8,
      "z": -7,
      "name": "Soil_Gravel_Sand"
    },
    {
      "x": -1,
      "y": 9,
      "z": -7,
      "name": "Soil_Gravel_Sand"
    },
    {
      "x": -1,
      "y": 10,
      "z": -7,
      "name": "Empty"
    },
    {
      "x": -1,
      "y": 11,
      "z": -7,
      "name": "Empty"
    },
    {
      "x": -1,
      "y": 12,
      "z": -7,
      "name": "Empty"
    },
    {
      "x": -1,
      "y": 13,
      "z": -7,
      "name": "Empty"
    },
    {
      "x": -1,
      "y": 14,
      "z": -7,
      "name": "Empty"
    },
    {
      "x": -1,
      "y": 15,
      "z": -7,
      "name": "Empty"
    },
    {
      "x": -1,
      "y": 16,
      "z": -7,
      "name": "Empty"
    },
    {
      "x": -1,
      "y": 1,
      "z": -6,
      "name": "Soil_Gravel_Sand"
    },
    {
      "x": -1,
      "y": 2,
      "z": -6,
      "name": "Soil_Gravel_Sand"
    },
    {
      "x": -1,
      "y": 3,
      "z": -6,
      "name": "Soil_Gravel_Sand"
    },
    {
      "x": -1,
      "y": 4,
      "z": -6,
      "name": "Soil_Gravel_Sand"
    },
    {
      "x": -1,
      "y": 5,
      "z": -6,
      "name": "Soil_Gravel_Sand"
    },
    {
      "x": -1,
      "y": 6,
      "z": -6,
      "name": "Soil_Gravel_Sand"
    },
    {
      "x": -1,
      "y": 7,
      "z": -6,
      "name": "Soil_Gravel_Sand"
    },
    {
      "x": -1,
      "y": 8,
      "z": -6,
      "name": "Soil_Gravel_Sand"
    },
    {
      "x": -1,
      "y": 9,
      "z": -6,
      "name": "Soil_Gravel_Sand"
    },
    {
      "x": -1,
      "y": 10,
      "z": -6,
      "name": "Empty"
    },
    {
      "x": -1,
      "y": 11,
      "z": -6,
      "name": "Empty"
    },
    {
      "x": -1,
      "y": 12,
      "z": -6,
      "name": "Empty"
    },
    {
      "x": -1,
      "y": 13,
      "z": -6,
      "name": "Empty"
    },
    {
      "x": -1,
      "y": 14,
      "z": -6,
      "name": "Empty"
    },
    {
      "x": -1,
      "y": 15,
      "z": -6,
      "name": "Empty"
    },
    {
      "x": -1,
      "y": 16,
      "z": -6,
      "name": "Empty"
    },
    {
      "x": -1,
      "y": 17,
      "z": -6,
      "name": "Empty"
    },
    {
      "x": -1,
      "y": 1,
      "z": -5,
      "name": "Soil_Gravel_Sand"
    },
    {
      "x": -1,
      "y": 2,
      "z": -5,
      "name": "Soil_Gravel_Sand"
    },
    {
      "x": -1,
      "y": 3,
      "z": -5,
      "name": "Soil_Gravel_Sand"
    },
    {
      "x": -1,
      "y": 4,
      "z": -5,
      "name": "Soil_Gravel_Sand"
    },
    {
      "x": -1,
      "y": 5,
      "z": -5,
      "name": "Soil_Gravel_Sand"
    },
    {
      "x": -1,
      "y": 6,
      "z": -5,
      "name": "Soil_Gravel_Sand"
    },
    {
      "x": -1,
      "y": 7,
      "z": -5,
      "name": "Soil_Gravel_Sand"
    },
    {
      "x": -1,
      "y": 8,
      "z": -5,
      "name": "Soil_Gravel_Sand"
    },
    {
      "x": -1,
      "y": 9,
      "z": -5,
      "name": "Soil_Gravel_Sand"
    },
    {
      "x": -1,
      "y": 10,
      "z": -5,
      "name": "Empty"
    },
    {
      "x": -1,
      "y": 11,
      "z": -5,
      "name": "Empty"
    },
    {
      "x": -1,
      "y": 12,
      "z": -5,
      "name": "Empty"
    },
    {
      "x": -1,
      "y": 13,
      "z": -5,
      "name": "Empty"
    },
    {
      "x": -1,
      "y": 14,
      "z": -5,
      "name": "Empty"
    },
    {
      "x": -1,
      "y": 15,
      "z": -5,
      "name": "Empty"
    },
    {
      "x": -1,
      "y": 16,
      "z": -5,
      "name": "Empty"
    },
    {
      "x": -1,
      "y": 17,
      "z": -5,
      "name": "Empty"
    },
    {
      "x": -1,
      "y": 1,
      "z": -4,
      "name": "Soil_Gravel_Sand"
    },
    {
      "x": -1,
      "y": 2,
      "z": -4,
      "name": "Soil_Gravel_Sand"
    },
    {
      "x": -1,
      "y": 3,
      "z": -4,
      "name": "Soil_Gravel_Sand"
    },
    {
      "x": -1,
      "y": 4,
      "z": -4,
      "name": "Soil_Gravel_Sand"
    },
    {
      "x": -1,
      "y": 5,
      "z": -4,
      "name": "Soil_Gravel_Sand"
    },
    {
      "x": -1,
      "y": 6,
      "z": -4,
      "name": "Soil_Gravel_Sand"
    },
    {
      "x": -1,
      "y": 7,
      "z": -4,
      "name": "Soil_Gravel_Sand"
    },
    {
      "x": -1,
      "y": 8,
      "z": -4,
      "name": "Soil_Gravel_Sand"
    },
    {
      "x": -1,
      "y": 9,
      "z": -4,
      "name": "Soil_Gravel_Sand"
    },
    {
      "x": -1,
      "y": 10,
      "z": -4,
      "name": "Cloth_Roof_Hide_Vertical",
      "rotation": 3
    },
    {
      "x": -1,
      "y": 11,
      "z": -4,
      "name": "Cloth_Roof_Hide_Vertical",
      "rotation": 3
    },
    {
      "x": -1,
      "y": 12,
      "z": -4,
      "name": "Wood_Drywood_Planks_Half",
      "rotation": 7
    },
    {
      "x": -1,
      "y": 13,
      "z": -4,
      "name": "Empty"
    },
    {
      "x": -1,
      "y": 14,
      "z": -4,
      "name": "Empty"
    },
    {
      "x": -1,
      "y": 15,
      "z": -4,
      "name": "Empty"
    },
    {
      "x": -1,
      "y": 16,
      "z": -4,
      "name": "Empty"
    },
    {
      "x": -1,
      "y": 17,
      "z": -4,
      "name": "Empty"
    },
    {
      "x": -1,
      "y": 18,
      "z": -4,
      "name": "Empty"
    },
    {
      "x": -1,
      "y": 1,
      "z": -3,
      "name": "Soil_Gravel_Sand"
    },
    {
      "x": -1,
      "y": 2,
      "z": -3,
      "name": "Soil_Gravel_Sand"
    },
    {
      "x": -1,
      "y": 3,
      "z": -3,
      "name": "Soil_Gravel_Sand"
    },
    {
      "x": -1,
      "y": 4,
      "z": -3,
      "name": "Soil_Gravel_Sand"
    },
    {
      "x": -1,
      "y": 5,
      "z": -3,
      "name": "Soil_Gravel_Sand"
    },
    {
      "x": -1,
      "y": 6,
      "z": -3,
      "name": "Soil_Gravel_Sand"
    },
    {
      "x": -1,
      "y": 7,
      "z": -3,
      "name": "Soil_Gravel_Sand"
    },
    {
      "x": -1,
      "y": 8,
      "z": -3,
      "name": "Soil_Gravel_Sand"
    },
    {
      "x": -1,
      "y": 9,
      "z": -3,
      "name": "Soil_Dirt_Dry"
    },
    {
      "x": -1,
      "y": 10,
      "z": -3,
      "name": "Wood_Dry_Branch_Long",
      "support": 15
    },
    {
      "x": -1,
      "y": 11,
      "z": -3,
      "name": "Wood_Dry_Branch_Long",
      "support": 15
    },
    {
      "x": -1,
      "y": 12,
      "z": -3,
      "name": "Wood_Drywood_Planks"
    },
    {
      "x": -1,
      "y": 13,
      "z": -3,
      "name": "Empty"
    },
    {
      "x": -1,
      "y": 14,
      "z": -3,
      "name": "Empty"
    },
    {
      "x": -1,
      "y": 15,
      "z": -3,
      "name": "Empty"
    },
    {
      "x": -1,
      "y": 16,
      "z": -3,
      "name": "Empty"
    },
    {
      "x": -1,
      "y": 17,
      "z": -3,
      "name": "Empty"
    },
    {
      "x": -1,
      "y": 18,
      "z": -3,
      "name": "Empty"
    },
    {
      "x": -1,
      "y": 1,
      "z": -2,
      "name": "Soil_Gravel_Sand"
    },
    {
      "x": -1,
      "y": 2,
      "z": -2,
      "name": "Soil_Gravel_Sand"
    },
    {
      "x": -1,
      "y": 3,
      "z": -2,
      "name": "Soil_Gravel_Sand"
    },
    {
      "x": -1,
      "y": 4,
      "z": -2,
      "name": "Soil_Gravel_Sand"
    },
    {
      "x": -1,
      "y": 5,
      "z": -2,
      "name": "Soil_Gravel_Sand"
    },
    {
      "x": -1,
      "y": 6,
      "z": -2,
      "name": "Soil_Gravel_Sand"
    },
    {
      "x": -1,
      "y": 7,
      "z": -2,
      "name": "Soil_Gravel_Sand"
    },
    {
      "x": -1,
      "y": 8,
      "z": -2,
      "name": "Soil_Gravel_Sand"
    },
    {
      "x": -1,
      "y": 9,
      "z": -2,
      "name": "Soil_Dirt_Dry"
    },
    {
      "x": -1,
      "y": 10,
      "z": -2,
      "name": "Cloth_Roof_Hide_Vertical"
    },
    {
      "x": -1,
      "y": 11,
      "z": -2,
      "name": "Cloth_Roof_Hide_Vertical"
    },
    {
      "x": -1,
      "y": 12,
      "z": -2,
      "name": "Wood_Drywood_Planks"
    },
    {
      "x": -1,
      "y": 13,
      "z": -2,
      "name": "*Cloth_Roof_Hide_State_Definitions_Corner_Right",
      "rotation": 3
    },
    {
      "x": -1,
      "y": 14,
      "z": -2,
      "name": "Empty"
    },
    {
      "x": -1,
      "y": 15,
      "z": -2,
      "name": "Empty"
    },
    {
      "x": -1,
      "y": 16,
      "z": -2,
      "name": "Empty"
    },
    {
      "x": -1,
      "y": 17,
      "z": -2,
      "name": "Empty"
    },
    {
      "x": -1,
      "y": 18,
      "z": -2,
      "name": "Empty"
    },
    {
      "x": -1,
      "y": 1,
      "z": -1,
      "name": "Soil_Gravel_Sand"
    },
    {
      "x": -1,
      "y": 2,
      "z": -1,
      "name": "Soil_Gravel_Sand"
    },
    {
      "x": -1,
      "y": 3,
      "z": -1,
      "name": "Soil_Gravel_Sand"
    },
    {
      "x": -1,
      "y": 4,
      "z": -1,
      "name": "Soil_Gravel_Sand"
    },
    {
      "x": -1,
      "y": 5,
      "z": -1,
      "name": "Soil_Gravel_Sand"
    },
    {
      "x": -1,
      "y": 6,
      "z": -1,
      "name": "Soil_Gravel_Sand"
    },
    {
      "x": -1,
      "y": 7,
      "z": -1,
      "name": "Soil_Gravel_Sand"
    },
    {
      "x": -1,
      "y": 8,
      "z": -1,
      "name": "Soil_Gravel_Sand"
    },
    {
      "x": -1,
      "y": 9,
      "z": -1,
      "name": "Soil_Dirt_Dry"
    },
    {
      "x": -1,
      "y": 10,
      "z": -1,
      "name": "Empty"
    },
    {
      "x": -1,
      "y": 11,
      "z": -1,
      "name": "Empty"
    },
    {
      "x": -1,
      "y": 12,
      "z": -1,
      "name": "Wood_Drywood_Planks_Half",
      "rotation": 5
    },
    {
      "x": -1,
      "y": 13,
      "z": -1,
      "name": "Cloth_Roof_Hide",
      "rotation": 3
    },
    {
      "x": -1,
      "y": 14,
      "z": -1,
      "name": "Empty"
    },
    {
      "x": -1,
      "y": 15,
      "z": -1,
      "name": "Empty"
    },
    {
      "x": -1,
      "y": 16,
      "z": -1,
      "name": "Empty"
    },
    {
      "x": -1,
      "y": 17,
      "z": -1,
      "name": "Empty"
    },
    {
      "x": -1,
      "y": 18,
      "z": -1,
      "name": "Empty"
    },
    {
      "x": -1,
      "y": 1,
      "z": 0,
      "name": "Soil_Gravel_Sand"
    },
    {
      "x": -1,
      "y": 2,
      "z": 0,
      "name": "Soil_Gravel_Sand"
    },
    {
      "x": -1,
      "y": 3,
      "z": 0,
      "name": "Soil_Gravel_Sand"
    },
    {
      "x": -1,
      "y": 4,
      "z": 0,
      "name": "Soil_Gravel_Sand"
    },
    {
      "x": -1,
      "y": 5,
      "z": 0,
      "name": "Soil_Gravel_Sand"
    },
    {
      "x": -1,
      "y": 6,
      "z": 0,
      "name": "Soil_Gravel_Sand"
    },
    {
      "x": -1,
      "y": 7,
      "z": 0,
      "name": "Soil_Gravel_Sand"
    },
    {
      "x": -1,
      "y": 8,
      "z": 0,
      "name": "Soil_Gravel_Sand"
    },
    {
      "x": -1,
      "y": 9,
      "z": 0,
      "name": "Soil_Dirt_Dry"
    },
    {
      "x": -1,
      "y": 10,
      "z": 0,
      "name": "Cloth_Roof_Hide_Vertical",
      "rotation": 2
    },
    {
      "x": -1,
      "y": 11,
      "z": 0,
      "name": "Cloth_Roof_Hide_Vertical",
      "rotation": 2
    },
    {
      "x": -1,
      "y": 12,
      "z": 0,
      "name": "Wood_Drywood_Planks"
    },
    {
      "x": -1,
      "y": 13,
      "z": 0,
      "name": "*Cloth_Roof_Hide_State_Definitions_Corner_Right"
    },
    {
      "x": -1,
      "y": 14,
      "z": 0,
      "name": "Empty"
    },
    {
      "x": -1,
      "y": 15,
      "z": 0,
      "name": "Empty"
    },
    {
      "x": -1,
      "y": 16,
      "z": 0,
      "name": "Empty"
    },
    {
      "x": -1,
      "y": 17,
      "z": 0,
      "name": "Empty"
    },
    {
      "x": -1,
      "y": 18,
      "z": 0,
      "name": "Empty"
    },
    {
      "x": -1,
      "y": 1,
      "z": 1,
      "name": "Soil_Gravel_Sand"
    },
    {
      "x": -1,
      "y": 2,
      "z": 1,
      "name": "Soil_Gravel_Sand"
    },
    {
      "x": -1,
      "y": 3,
      "z": 1,
      "name": "Soil_Gravel_Sand"
    },
    {
      "x": -1,
      "y": 4,
      "z": 1,
      "name": "Soil_Gravel_Sand"
    },
    {
      "x": -1,
      "y": 5,
      "z": 1,
      "name": "Soil_Gravel_Sand"
    },
    {
      "x": -1,
      "y": 6,
      "z": 1,
      "name": "Soil_Gravel_Sand"
    },
    {
      "x": -1,
      "y": 7,
      "z": 1,
      "name": "Soil_Gravel_Sand"
    },
    {
      "x": -1,
      "y": 8,
      "z": 1,
      "name": "Soil_Gravel_Sand"
    },
    {
      "x": -1,
      "y": 9,
      "z": 1,
      "name": "Soil_Dirt_Dry"
    },
    {
      "x": -1,
      "y": 10,
      "z": 1,
      "name": "Wood_Dry_Branch_Long",
      "support": 15
    },
    {
      "x": -1,
      "y": 11,
      "z": 1,
      "name": "Wood_Dry_Branch_Long",
      "support": 15
    },
    {
      "x": -1,
      "y": 12,
      "z": 1,
      "name": "Wood_Drywood_Planks"
    },
    {
      "x": -1,
      "y": 13,
      "z": 1,
      "name": "Empty"
    },
    {
      "x": -1,
      "y": 14,
      "z": 1,
      "name": "Empty"
    },
    {
      "x": -1,
      "y": 15,
      "z": 1,
      "name": "Empty"
    },
    {
      "x": -1,
      "y": 16,
      "z": 1,
      "name": "Empty"
    },
    {
      "x": -1,
      "y": 17,
      "z": 1,
      "name": "Empty"
    },
    {
      "x": -1,
      "y": 18,
      "z": 1,
      "name": "Empty"
    },
    {
      "x": -1,
      "y": 1,
      "z": 2,
      "name": "Soil_Gravel_Sand"
    },
    {
      "x": -1,
      "y": 2,
      "z": 2,
      "name": "Soil_Gravel_Sand"
    },
    {
      "x": -1,
      "y": 3,
      "z": 2,
      "name": "Soil_Gravel_Sand"
    },
    {
      "x": -1,
      "y": 4,
      "z": 2,
      "name": "Soil_Gravel_Sand"
    },
    {
      "x": -1,
      "y": 5,
      "z": 2,
      "name": "Soil_Gravel_Sand"
    },
    {
      "x": -1,
      "y": 6,
      "z": 2,
      "name": "Soil_Gravel_Sand"
    },
    {
      "x": -1,
      "y": 7,
      "z": 2,
      "name": "Soil_Gravel_Sand"
    },
    {
      "x": -1,
      "y": 8,
      "z": 2,
      "name": "Soil_Gravel_Sand"
    },
    {
      "x": -1,
      "y": 9,
      "z": 2,
      "name": "Soil_Gravel_Sand"
    },
    {
      "x": -1,
      "y": 10,
      "z": 2,
      "name": "Cloth_Roof_Hide_Vertical",
      "rotation": 3
    },
    {
      "x": -1,
      "y": 11,
      "z": 2,
      "name": "Cloth_Roof_Hide_Vertical",
      "rotation": 3
    },
    {
      "x": -1,
      "y": 12,
      "z": 2,
      "name": "Empty"
    },
    {
      "x": -1,
      "y": 13,
      "z": 2,
      "name": "Empty"
    },
    {
      "x": -1,
      "y": 14,
      "z": 2,
      "name": "Empty"
    },
    {
      "x": -1,
      "y": 15,
      "z": 2,
      "name": "Empty"
    },
    {
      "x": -1,
      "y": 16,
      "z": 2,
      "name": "Empty"
    },
    {
      "x": -1,
      "y": 17,
      "z": 2,
      "name": "Empty"
    },
    {
      "x": -1,
      "y": 18,
      "z": 2,
      "name": "Empty"
    },
    {
      "x": -1,
      "y": 1,
      "z": 3,
      "name": "Soil_Gravel_Sand"
    },
    {
      "x": -1,
      "y": 2,
      "z": 3,
      "name": "Soil_Gravel_Sand"
    },
    {
      "x": -1,
      "y": 3,
      "z": 3,
      "name": "Soil_Gravel_Sand"
    },
    {
      "x": -1,
      "y": 4,
      "z": 3,
      "name": "Soil_Gravel_Sand"
    },
    {
      "x": -1,
      "y": 5,
      "z": 3,
      "name": "Soil_Gravel_Sand"
    },
    {
      "x": -1,
      "y": 6,
      "z": 3,
      "name": "Soil_Gravel_Sand"
    },
    {
      "x": -1,
      "y": 7,
      "z": 3,
      "name": "Soil_Gravel_Sand"
    },
    {
      "x": -1,
      "y": 8,
      "z": 3,
      "name": "Soil_Gravel_Sand"
    },
    {
      "x": -1,
      "y": 9,
      "z": 3,
      "name": "Soil_Dirt_Dry"
    },
    {
      "x": -1,
      "y": 10,
      "z": 3,
      "name": "Empty"
    },
    {
      "x": -1,
      "y": 11,
      "z": 3,
      "name": "Empty"
    },
    {
      "x": -1,
      "y": 12,
      "z": 3,
      "name": "Empty"
    },
    {
      "x": -1,
      "y": 13,
      "z": 3,
      "name": "Empty"
    },
    {
      "x": -1,
      "y": 14,
      "z": 3,
      "name": "Empty"
    },
    {
      "x": -1,
      "y": 15,
      "z": 3,
      "name": "Empty"
    },
    {
      "x": -1,
      "y": 16,
      "z": 3,
      "name": "Empty"
    },
    {
      "x": -1,
      "y": 17,
      "z": 3,
      "name": "Empty"
    },
    {
      "x": -1,
      "y": 1,
      "z": 4,
      "name": "Soil_Gravel_Sand"
    },
    {
      "x": -1,
      "y": 2,
      "z": 4,
      "name": "Soil_Gravel_Sand"
    },
    {
      "x": -1,
      "y": 3,
      "z": 4,
      "name": "Soil_Gravel_Sand"
    },
    {
      "x": -1,
      "y": 4,
      "z": 4,
      "name": "Soil_Gravel_Sand"
    },
    {
      "x": -1,
      "y": 5,
      "z": 4,
      "name": "Soil_Gravel_Sand"
    },
    {
      "x": -1,
      "y": 6,
      "z": 4,
      "name": "Soil_Gravel_Sand"
    },
    {
      "x": -1,
      "y": 7,
      "z": 4,
      "name": "Soil_Gravel_Sand"
    },
    {
      "x": -1,
      "y": 8,
      "z": 4,
      "name": "Soil_Dirt_Dry"
    },
    {
      "x": -1,
      "y": 9,
      "z": 4,
      "name": "Soil_Dirt_Dry"
    },
    {
      "x": -1,
      "y": 10,
      "z": 4,
      "name": "Empty"
    },
    {
      "x": -1,
      "y": 11,
      "z": 4,
      "name": "Empty"
    },
    {
      "x": -1,
      "y": 12,
      "z": 4,
      "name": "Empty"
    },
    {
      "x": -1,
      "y": 13,
      "z": 4,
      "name": "Empty"
    },
    {
      "x": -1,
      "y": 14,
      "z": 4,
      "name": "Empty"
    },
    {
      "x": -1,
      "y": 15,
      "z": 4,
      "name": "Empty"
    },
    {
      "x": -1,
      "y": 16,
      "z": 4,
      "name": "Empty"
    },
    {
      "x": -1,
      "y": 17,
      "z": 4,
      "name": "Empty"
    },
    {
      "x": -1,
      "y": 1,
      "z": 5,
      "name": "Soil_Gravel_Sand"
    },
    {
      "x": -1,
      "y": 2,
      "z": 5,
      "name": "Soil_Gravel_Sand"
    },
    {
      "x": -1,
      "y": 3,
      "z": 5,
      "name": "Soil_Gravel_Sand"
    },
    {
      "x": -1,
      "y": 4,
      "z": 5,
      "name": "Soil_Gravel_Sand"
    },
    {
      "x": -1,
      "y": 5,
      "z": 5,
      "name": "Soil_Gravel_Sand"
    },
    {
      "x": -1,
      "y": 6,
      "z": 5,
      "name": "Soil_Gravel_Sand"
    },
    {
      "x": -1,
      "y": 7,
      "z": 5,
      "name": "Soil_Gravel_Sand"
    },
    {
      "x": -1,
      "y": 8,
      "z": 5,
      "name": "Soil_Dirt_Dry"
    },
    {
      "x": -1,
      "y": 9,
      "z": 5,
      "name": "Soil_Dirt_Dry"
    },
    {
      "x": -1,
      "y": 10,
      "z": 5,
      "name": "Empty"
    },
    {
      "x": -1,
      "y": 11,
      "z": 5,
      "name": "Empty"
    },
    {
      "x": -1,
      "y": 12,
      "z": 5,
      "name": "Empty"
    },
    {
      "x": -1,
      "y": 13,
      "z": 5,
      "name": "Empty"
    },
    {
      "x": -1,
      "y": 14,
      "z": 5,
      "name": "Empty"
    },
    {
      "x": -1,
      "y": 15,
      "z": 5,
      "name": "Empty"
    },
    {
      "x": -1,
      "y": 16,
      "z": 5,
      "name": "Empty"
    },
    {
      "x": -1,
      "y": 1,
      "z": 6,
      "name": "Soil_Gravel_Sand"
    },
    {
      "x": -1,
      "y": 2,
      "z": 6,
      "name": "Soil_Gravel_Sand"
    },
    {
      "x": -1,
      "y": 3,
      "z": 6,
      "name": "Soil_Gravel_Sand"
    },
    {
      "x": -1,
      "y": 4,
      "z": 6,
      "name": "Soil_Gravel_Sand"
    },
    {
      "x": -1,
      "y": 5,
      "z": 6,
      "name": "Soil_Gravel_Sand"
    },
    {
      "x": -1,
      "y": 6,
      "z": 6,
      "name": "Soil_Gravel_Sand"
    },
    {
      "x": -1,
      "y": 7,
      "z": 6,
      "name": "Soil_Gravel_Sand"
    },
    {
      "x": -1,
      "y": 8,
      "z": 6,
      "name": "Soil_Dirt_Dry"
    },
    {
      "x": -1,
      "y": 1,
      "z": 7,
      "name": "Rock_Sandstone_Cobble"
    },
    {
      "x": -1,
      "y": 2,
      "z": 7,
      "name": "Rock_Sandstone_Cobble"
    },
    {
      "x": -1,
      "y": 3,
      "z": 7,
      "name": "Rock_Sandstone_Cobble"
    },
    {
      "x": -1,
      "y": 4,
      "z": 7,
      "name": "Rock_Sandstone_Cobble"
    },
    {
      "x": -1,
      "y": 5,
      "z": 7,
      "name": "Rock_Sandstone_Cobble"
    },
    {
      "x": -1,
      "y": 6,
      "z": 7,
      "name": "Rock_Sandstone_Cobble"
    },
    {
      "x": -1,
      "y": 7,
      "z": 7,
      "name": "Rock_Sandstone_Cobble"
    },
    {
      "x": -1,
      "y": 1,
      "z": 8,
      "name": "Rock_Sandstone_Cobble"
    },
    {
      "x": -1,
      "y": 2,
      "z": 8,
      "name": "Rock_Sandstone_Cobble"
    },
    {
      "x": -1,
      "y": 3,
      "z": 8,
      "name": "Rock_Sandstone_Cobble"
    },
    {
      "x": -1,
      "y": 4,
      "z": 8,
      "name": "Rock_Sandstone_Cobble"
    },
    {
      "x": -1,
      "y": 5,
      "z": 8,
      "name": "Rock_Sandstone_Cobble"
    },
    {
      "x": -1,
      "y": 6,
      "z": 8,
      "name": "Rock_Sandstone_Cobble"
    },
    {
      "x": 0,
      "y": 1,
      "z": -9,
      "name": "Wood_Dry_Trunk"
    },
    {
      "x": 0,
      "y": 2,
      "z": -9,
      "name": "Wood_Dry_Trunk"
    },
    {
      "x": 0,
      "y": 3,
      "z": -9,
      "name": "Wood_Dry_Trunk"
    },
    {
      "x": 0,
      "y": 4,
      "z": -9,
      "name": "Wood_Dry_Trunk"
    },
    {
      "x": 0,
      "y": 5,
      "z": -9,
      "name": "Wood_Dry_Trunk"
    },
    {
      "x": 0,
      "y": 6,
      "z": -9,
      "name": "Wood_Dry_Trunk"
    },
    {
      "x": 0,
      "y": 7,
      "z": -9,
      "name": "Wood_Dry_Trunk"
    },
    {
      "x": 0,
      "y": 8,
      "z": -9,
      "name": "Wood_Dry_Trunk"
    },
    {
      "x": 0,
      "y": 9,
      "z": -9,
      "name": "Wood_Dry_Trunk"
    },
    {
      "x": 0,
      "y": 10,
      "z": -9,
      "name": "Wood_Dry_Trunk"
    },
    {
      "x": 0,
      "y": 11,
      "z": -9,
      "name": "Wood_Dry_Trunk"
    },
    {
      "x": 0,
      "y": 12,
      "z": -9,
      "name": "Wood_Dry_Branch_Long"
    },
    {
      "x": 0,
      "y": 13,
      "z": -9,
      "name": "Survival_Trap_Spike_Wood_Large"
    },
    {
      "x": 0,
      "y": 1,
      "z": -8,
      "name": "Soil_Gravel_Sand"
    },
    {
      "x": 0,
      "y": 2,
      "z": -8,
      "name": "Soil_Gravel_Sand"
    },
    {
      "x": 0,
      "y": 3,
      "z": -8,
      "name": "Soil_Gravel_Sand"
    },
    {
      "x": 0,
      "y": 4,
      "z": -8,
      "name": "Soil_Gravel_Sand"
    },
    {
      "x": 0,
      "y": 5,
      "z": -8,
      "name": "Soil_Gravel_Sand"
    },
    {
      "x": 0,
      "y": 6,
      "z": -8,
      "name": "Soil_Gravel_Sand"
    },
    {
      "x": 0,
      "y": 7,
      "z": -8,
      "name": "Soil_Gravel_Sand"
    },
    {
      "x": 0,
      "y": 8,
      "z": -8,
      "name": "Soil_Gravel_Sand"
    },
    {
      "x": 0,
      "y": 9,
      "z": -8,
      "name": "Rock_Sandstone_Cobble"
    },
    {
      "x": 0,
      "y": 1,
      "z": -7,
      "name": "Soil_Gravel_Sand"
    },
    {
      "x": 0,
      "y": 2,
      "z": -7,
      "name": "Soil_Gravel_Sand"
    },
    {
      "x": 0,
      "y": 3,
      "z": -7,
      "name": "Soil_Gravel_Sand"
    },
    {
      "x": 0,
      "y": 4,
      "z": -7,
      "name": "Soil_Gravel_Sand"
    },
    {
      "x": 0,
      "y": 5,
      "z": -7,
      "name": "Soil_Gravel_Sand"
    },
    {
      "x": 0,
      "y": 6,
      "z": -7,
      "name": "Soil_Gravel_Sand"
    },
    {
      "x": 0,
      "y": 7,
      "z": -7,
      "name": "Soil_Gravel_Sand"
    },
    {
      "x": 0,
      "y": 8,
      "z": -7,
      "name": "Soil_Gravel_Sand"
    },
    {
      "x": 0,
      "y": 9,
      "z": -7,
      "name": "Soil_Gravel_Sand"
    },
    {
      "x": 0,
      "y": 10,
      "z": -7,
      "name": "Empty"
    },
    {
      "x": 0,
      "y": 11,
      "z": -7,
      "name": "Empty"
    },
    {
      "x": 0,
      "y": 12,
      "z": -7,
      "name": "Empty"
    },
    {
      "x": 0,
      "y": 13,
      "z": -7,
      "name": "Empty"
    },
    {
      "x": 0,
      "y": 14,
      "z": -7,
      "name": "Empty"
    },
    {
      "x": 0,
      "y": 15,
      "z": -7,
      "name": "Empty"
    },
    {
      "x": 0,
      "y": 16,
      "z": -7,
      "name": "Empty"
    },
    {
      "x": 0,
      "y": 1,
      "z": -6,
      "name": "Soil_Gravel_Sand"
    },
    {
      "x": 0,
      "y": 2,
      "z": -6,
      "name": "Soil_Gravel_Sand"
    },
    {
      "x": 0,
      "y": 3,
      "z": -6,
      "name": "Soil_Gravel_Sand"
    },
    {
      "x": 0,
      "y": 4,
      "z": -6,
      "name": "Soil_Gravel_Sand"
    },
    {
      "x": 0,
      "y": 5,
      "z": -6,
      "name": "Soil_Gravel_Sand"
    },
    {
      "x": 0,
      "y": 6,
      "z": -6,
      "name": "Soil_Gravel_Sand"
    },
    {
      "x": 0,
      "y": 7,
      "z": -6,
      "name": "Soil_Gravel_Sand"
    },
    {
      "x": 0,
      "y": 8,
      "z": -6,
      "name": "Soil_Gravel_Sand"
    },
    {
      "x": 0,
      "y": 9,
      "z": -6,
      "name": "Soil_Gravel_Sand"
    },
    {
      "x": 0,
      "y": 10,
      "z": -6,
      "name": "Empty"
    },
    {
      "x": 0,
      "y": 11,
      "z": -6,
      "name": "Empty"
    },
    {
      "x": 0,
      "y": 12,
      "z": -6,
      "name": "Empty"
    },
    {
      "x": 0,
      "y": 13,
      "z": -6,
      "name": "Empty"
    },
    {
      "x": 0,
      "y": 14,
      "z": -6,
      "name": "Empty"
    },
    {
      "x": 0,
      "y": 15,
      "z": -6,
      "name": "Empty"
    },
    {
      "x": 0,
      "y": 16,
      "z": -6,
      "name": "Empty"
    },
    {
      "x": 0,
      "y": 17,
      "z": -6,
      "name": "Empty"
    },
    {
      "x": 0,
      "y": 1,
      "z": -5,
      "name": "Soil_Gravel_Sand"
    },
    {
      "x": 0,
      "y": 2,
      "z": -5,
      "name": "Soil_Gravel_Sand"
    },
    {
      "x": 0,
      "y": 3,
      "z": -5,
      "name": "Soil_Gravel_Sand"
    },
    {
      "x": 0,
      "y": 4,
      "z": -5,
      "name": "Soil_Gravel_Sand"
    },
    {
      "x": 0,
      "y": 5,
      "z": -5,
      "name": "Soil_Gravel_Sand"
    },
    {
      "x": 0,
      "y": 6,
      "z": -5,
      "name": "Soil_Gravel_Sand"
    },
    {
      "x": 0,
      "y": 7,
      "z": -5,
      "name": "Soil_Gravel_Sand"
    },
    {
      "x": 0,
      "y": 8,
      "z": -5,
      "name": "Soil_Gravel_Sand"
    },
    {
      "x": 0,
      "y": 9,
      "z": -5,
      "name": "Soil_Gravel_Sand"
    },
    {
      "x": 0,
      "y": 10,
      "z": -5,
      "name": "Cloth_Roof_Hide_Vertical",
      "rotation": 2
    },
    {
      "x": 0,
      "y": 11,
      "z": -5,
      "name": "Cloth_Roof_Hide_Vertical",
      "rotation": 2
    },
    {
      "x": 0,
      "y": 12,
      "z": -5,
      "name": "Wood_Drywood_Planks_Half",
      "rotation": 6
    },
    {
      "x": 0,
      "y": 13,
      "z": -5,
      "name": "Empty"
    },
    {
      "x": 0,
      "y": 14,
      "z": -5,
      "name": "Empty"
    },
    {
      "x": 0,
      "y": 15,
      "z": -5,
      "name": "Empty"
    },
    {
      "x": 0,
      "y": 16,
      "z": -5,
      "name": "Empty"
    },
    {
      "x": 0,
      "y": 17,
      "z": -5,
      "name": "Empty"
    },
    {
      "x": 0,
      "y": 18,
      "z": -5,
      "name": "Empty"
    },
    {
      "x": 0,
      "y": 1,
      "z": -4,
      "name": "Soil_Gravel_Sand"
    },
    {
      "x": 0,
      "y": 2,
      "z": -4,
      "name": "Soil_Gravel_Sand"
    },
    {
      "x": 0,
      "y": 3,
      "z": -4,
      "name": "Soil_Gravel_Sand"
    },
    {
      "x": 0,
      "y": 4,
      "z": -4,
      "name": "Soil_Gravel_Sand"
    },
    {
      "x": 0,
      "y": 5,
      "z": -4,
      "name": "Soil_Gravel_Sand"
    },
    {
      "x": 0,
      "y": 6,
      "z": -4,
      "name": "Soil_Gravel_Sand"
    },
    {
      "x": 0,
      "y": 7,
      "z": -4,
      "name": "Soil_Gravel_Sand"
    },
    {
      "x": 0,
      "y": 8,
      "z": -4,
      "name": "Soil_Gravel_Sand"
    },
    {
      "x": 0,
      "y": 9,
      "z": -4,
      "name": "Soil_Dirt_Dry"
    },
    {
      "x": 0,
      "y": 10,
      "z": -4,
      "name": "Empty"
    },
    {
      "x": 0,
      "y": 11,
      "z": -4,
      "name": "Empty"
    },
    {
      "x": 0,
      "y": 12,
      "z": -4,
      "name": "Wood_Drywood_Planks"
    },
    {
      "x": 0,
      "y": 13,
      "z": -4,
      "name": "*Cloth_Roof_Hide_State_Definitions_Corner_Right",
      "rotation": 3
    },
    {
      "x": 0,
      "y": 14,
      "z": -4,
      "name": "Empty"
    },
    {
      "x": 0,
      "y": 15,
      "z": -4,
      "name": "Empty"
    },
    {
      "x": 0,
      "y": 16,
      "z": -4,
      "name": "Empty"
    },
    {
      "x": 0,
      "y": 17,
      "z": -4,
      "name": "Empty"
    },
    {
      "x": 0,
      "y": 18,
      "z": -4,
      "name": "Empty"
    },
    {
      "x": 0,
      "y": 1,
      "z": -3,
      "name": "Soil_Gravel_Sand"
    },
    {
      "x": 0,
      "y": 2,
      "z": -3,
      "name": "Soil_Gravel_Sand"
    },
    {
      "x": 0,
      "y": 3,
      "z": -3,
      "name": "Soil_Gravel_Sand"
    },
    {
      "x": 0,
      "y": 4,
      "z": -3,
      "name": "Soil_Gravel_Sand"
    },
    {
      "x": 0,
      "y": 5,
      "z": -3,
      "name": "Soil_Gravel_Sand"
    },
    {
      "x": 0,
      "y": 6,
      "z": -3,
      "name": "Soil_Gravel_Sand"
    },
    {
      "x": 0,
      "y": 7,
      "z": -3,
      "name": "Soil_Gravel_Sand"
    },
    {
      "x": 0,
      "y": 8,
      "z": -3,
      "name": "Soil_Gravel_Sand"
    },
    {
      "x": 0,
      "y": 9,
      "z": -3,
      "name": "Soil_Dirt_Dry"
    },
    {
      "x": 0,
      "y": 10,
      "z": -3,
      "name": "Cloth_Roof_Hide_Vertical",
      "rotation": 1
    },
    {
      "x": 0,
      "y": 11,
      "z": -3,
      "name": "Cloth_Roof_Hide_Vertical",
      "rotation": 1
    },
    {
      "x": 0,
      "y": 12,
      "z": -3,
      "name": "Wood_Drywood_Planks_Half",
      "rotation": 5
    },
    {
      "x": 0,
      "y": 13,
      "z": -3,
      "name": "Cloth_Roof_Hide",
      "rotation": 3
    },
    {
      "x": 0,
      "y": 14,
      "z": -3,
      "name": "Empty"
    },
    {
      "x": 0,
      "y": 15,
      "z": -3,
      "name": "Empty"
    },
    {
      "x": 0,
      "y": 16,
      "z": -3,
      "name": "Empty"
    },
    {
      "x": 0,
      "y": 17,
      "z": -3,
      "name": "Empty"
    },
    {
      "x": 0,
      "y": 18,
      "z": -3,
      "name": "Empty"
    },
    {
      "x": 0,
      "y": 1,
      "z": -2,
      "name": "Soil_Gravel_Sand"
    },
    {
      "x": 0,
      "y": 2,
      "z": -2,
      "name": "Soil_Gravel_Sand"
    },
    {
      "x": 0,
      "y": 3,
      "z": -2,
      "name": "Soil_Gravel_Sand"
    },
    {
      "x": 0,
      "y": 4,
      "z": -2,
      "name": "Soil_Gravel_Sand"
    },
    {
      "x": 0,
      "y": 5,
      "z": -2,
      "name": "Soil_Gravel_Sand"
    },
    {
      "x": 0,
      "y": 6,
      "z": -2,
      "name": "Soil_Gravel_Sand"
    },
    {
      "x": 0,
      "y": 7,
      "z": -2,
      "name": "Soil_Gravel_Sand"
    },
    {
      "x": 0,
      "y": 8,
      "z": -2,
      "name": "Soil_Gravel_Sand"
    },
    {
      "x": 0,
      "y": 9,
      "z": -2,
      "name": "Soil_Dirt_Dry"
    },
    {
      "x": 0,
      "y": 10,
      "z": -2,
      "name": "Bench_Tannery",
      "components": {
        "Components": {
          "processingBench": {
            "Position": {
              "X": -3,
              "Y": 1,
              "Z": -1
            },
            "TierLevel": 1,
            "UpgradeItems": [],
            "InputContainer": {
              "Id": "Simple",
              "Capacity": 2,
              "Items": {}
            },
            "FuelContainer": {
              "Id": "Empty"
            },
            "OutputContainer": {
              "Id": "Simple",
              "Capacity": 2,
              "Items": {}
            },
            "Progress": 0.0,
            "FuelTime": 0.0,
            "Active": true,
            "NextExtra": 0
          }
        }
      },
      "rotation": 1
    },
    {
      "x": 0,
      "y": 11,
      "z": -2,
      "name": "Bench_Tannery",
      "filler": 1024,
      "rotation": 1
    },
    {
      "x": 0,
      "y": 12,
      "z": -2,
      "name": "Empty"
    },
    {
      "x": 0,
      "y": 13,
      "z": -2,
      "name": "*Cloth_Roof_Hide_State_Definitions_Corner_Right",
      "rotation": 10
    },
    {
      "x": 0,
      "y": 14,
      "z": -2,
      "name": "Wood_Drywood_Planks_Half",
      "rotation": 7
    },
    {
      "x": 0,
      "y": 15,
      "z": -2,
      "name": "Empty"
    },
    {
      "x": 0,
      "y": 16,
      "z": -2,
      "name": "Empty"
    },
    {
      "x": 0,
      "y": 17,
      "z": -2,
      "name": "Empty"
    },
    {
      "x": 0,
      "y": 18,
      "z": -2,
      "name": "Empty"
    },
    {
      "x": 0,
      "y": 1,
      "z": -1,
      "name": "Soil_Gravel_Sand"
    },
    {
      "x": 0,
      "y": 2,
      "z": -1,
      "name": "Soil_Gravel_Sand"
    },
    {
      "x": 0,
      "y": 3,
      "z": -1,
      "name": "Soil_Gravel_Sand"
    },
    {
      "x": 0,
      "y": 4,
      "z": -1,
      "name": "Soil_Gravel_Sand"
    },
    {
      "x": 0,
      "y": 5,
      "z": -1,
      "name": "Soil_Gravel_Sand"
    },
    {
      "x": 0,
      "y": 6,
      "z": -1,
      "name": "Soil_Gravel_Sand"
    },
    {
      "x": 0,
      "y": 7,
      "z": -1,
      "name": "Soil_Gravel_Sand"
    },
    {
      "x": 0,
      "y": 8,
      "z": -1,
      "name": "Soil_Dirt_Dry"
    },
    {
      "x": 0,
      "y": 9,
      "z": -1,
      "name": "Soil_Dirt_Dry"
    },
    {
      "x": 0,
      "y": 10,
      "z": -1,
      "name": "Bench_Tannery",
      "filler": 32,
      "rotation": 1
    },
    {
      "x": 0,
      "y": 11,
      "z": -1,
      "name": "Bench_Tannery",
      "filler": 1056,
      "rotation": 1
    },
    {
      "x": 0,
      "y": 12,
      "z": -1,
      "name": "Empty"
    },
    {
      "x": 0,
      "y": 13,
      "z": -1,
      "name": "Cloth_Roof_Hide_Flat",
      "rotation": 8
    },
    {
