{
  "version": 8,
  "blockIdVersion": 8,
  "anchorX": -3,
  "anchorY": 2,
  "anchorZ": 1,
  "blocks": [
    {
      "x": -6,
      "y": 8,
      "z": 0,
      "name": "Plant_Coral_Block_Yellow"
    },
    {
      "x": -6,
      "y": 9,
      "z": 0,
      "name": "Plant_Coral_Block_Yellow"
    },
    {
      "x": -6,
      "y": 10,
      "z": 0,
      "name": "Plant_Coral_Block_Yellow"
    },
    {
      "x": -6,
      "y": 11,
      "z": 0,
      "name": "Plant_Coral_Block_Yellow"
    },
    {
      "x": -5,
      "y": 5,
      "z": 0,
      "name": "Plant_Coral_Block_Yellow"
    },
    {
      "x": -5,
      "y": 6,
      "z": 0,
      "name": "Plant_Coral_Block_Yellow"
    },
    {
      "x": -5,
      "y": 7,
      "z": 0,
      "name": "Plant_Coral_Block_Yellow"
    },
    {
      "x": -5,
      "y": 8,
      "z": 0,
      "name": "Plant_Coral_Block_Yellow"
    },
    {
      "x": -5,
      "y": 8,
      "z": 3,
      "name": "Plant_Coral_Block_Yellow"
    },
    {
      "x": -5,
      "y": 9,
      "z": 3,
      "name": "Plant_Coral_Block_Yellow"
    },
    {
      "x": -5,
      "y": 10,
      "z": 3,
      "name": "Plant_Coral_Block_Yellow"
    },
    {
      "x": -4,
      "y": 3,
      "z": -1,
      "name": "Plant_Coral_Block_Yellow"
    },
    {
      "x": -4,
      "y": 4,
      "z": -1,
      "name": "Plant_Coral_Block_Yellow"
    },
    {
      "x": -4,
      "y": 5,
      "z": -1,
      "name": "Plant_Coral_Block_Yellow"
    },
    {
      "x": -4,
      "y": 2,
      "z": 0,
      "name": "Plant_Coral_Block_Yellow"
    },
    {
      "x": -4,
      "y": 3,
      "z": 0,
      "name": "Plant_Coral_Block_Yellow"
    },
    {
      "x": -4,
      "y": 4,
      "z": 0,
      "name": "Plant_Coral_Block_Yellow"
    },
    {
      "x": -4,
      "y": 5,
      "z": 0,
      "name": "Plant_Coral_Block_Yellow"
    },
    {
      "x": -4,
      "y": 0,
      "z": 1,
      "name": "Plant_Coral_Block_Yellow"
    },
    {
      "x": -4,
      "y": 1,
      "z": 1,
      "name": "Plant_Coral_Block_Yellow"
    },
    {
      "x": -4,
      "y": 2,
      "z": 1,
      "name": "Plant_Coral_Block_Yellow"
    },
    {
      "x": -4,
      "y": 3,
      "z": 1,
      "name": "Plant_Coral_Block_Yellow"
    },
    {
      "x": -4,
      "y": 4,
      "z": 1,
      "name": "Plant_Coral_Block_Yellow"
    },
    {
      "x": -4,
      "y": 5,
      "z": 1,
      "name": "Plant_Coral_Block_Yellow"
    },
    {
      "x": -4,
      "y": 5,
      "z": 2,
      "name": "Plant_Coral_Block_Yellow"
    },
    {
      "x": -4,
      "y": 6,
      "z": 2,
      "name": "Plant_Coral_Block_Yellow"
    },
    {
      "x": -4,
      "y": 7,
      "z": 2,
      "name": "Plant_Coral_Block_Yellow"
    },
    {
      "x": -4,
      "y": 8,
      "z": 2,
      "name": "Plant_Coral_Block_Yellow"
    },
    {
      "x": -3,
      "y": 7,
      "z": -3,
      "name": "Plant_Coral_Block_Yellow"
    },
    {
      "x": -3,
      "y": 8,
      "z": -3,
      "name": "Plant_Coral_Block_Yellow"
    },
    {
      "x": -3,
      "y": 9,
      "z": -3,
      "name": "Plant_Coral_Block_Yellow"
    },
    {
      "x": -3,
      "y": 5,
      "z": -2,
      "name": "Plant_Coral_Block_Yellow"
    },
    {
      "x": -3,
      "y": 6,
      "z": -2,
      "name": "Plant_Coral_Block_Yellow"
    },
    {
      "x": -3,
      "y": 7,
      "z": -2,
      "name": "Plant_Coral_Block_Yellow"
    },
    {
      "x": -3,
      "y": 0,
      "z": 0,
      "name": "Plant_Coral_Block_Yellow"
    },
    {
      "x": -3,
      "y": 1,
      "z": 0,
      "name": "Plant_Coral_Block_Yellow"
    },
    {
      "x": -3,
      "y": 2,
      "z": 0,
      "name": "Plant_Coral_Block_Yellow"
    },
    {
      "x": -3,
      "y": 3,
      "z": 0,
      "name": "Plant_Coral_Block_Yellow"
    },
    {
      "x": -3,
      "y": 4,
      "z": 0,
      "name": "Plant_Coral_Block_Yellow"
    },
    {
      "x": -3,
      "y": 5,
      "z": 0,
      "name": "Plant_Coral_Block_Yellow"
    },
    {
      "x": -3,
      "y": 6,
      "z": 0,
      "name": "Plant_Coral_Block_Yellow"
    },
    {
      "x": -3,
      "y": 0,
      "z": 1,
      "name": "Plant_Coral_Block_Yellow"
    },
    {
      "x": -3,
      "y": 1,
      "z": 1,
      "name": "Plant_Coral_Block_Yellow"
    },
    {
      "x": -3,
      "y": 2,
      "z": 1,
      "name": "Plant_Coral_Block_Yellow"
    },
    {
      "x": -3,
      "y": 3,
      "z": 1,
      "name": "Plant_Coral_Block_Yellow"
    },
    {
      "x": -3,
      "y": 4,
      "z": 1,
      "name": "Plant_Coral_Block_Yellow"
    },
    {
      "x": -3,
      "y": 0,
      "z": 2,
      "name": "Plant_Coral_Block_Yellow"
    },
    {
      "x": -3,
      "y": 1,
      "z": 2,
      "name": "Plant_Coral_Block_Yellow"
    },
    {
      "x": -3,
      "y": 2,
      "z": 2,
      "name": "Plant_Coral_Block_Yellow"
    },
    {
      "x": -3,
      "y": 3,
      "z": 2,
      "name": "Plant_Coral_Block_Yellow"
    },
    {
      "x": -3,
      "y": 2,
      "z": 3,
      "name": "Plant_Coral_Block_Yellow"
    },
    {
      "x": -3,
      "y": 3,
      "z": 3,
      "name": "Plant_Coral_Block_Yellow"
    },
    {
      "x": -3,
      "y": 4,
      "z": 3,
      "name": "Plant_Coral_Block_Yellow"
    },
    {
      "x": -3,
      "y": 5,
      "z": 3,
      "name": "Plant_Coral_Block_Yellow"
    },
    {
      "x": -3,
      "y": 5,
      "z": 4,
      "name": "Plant_Coral_Block_Yellow"
    },
    {
      "x": -3,
      "y": 6,
      "z": 4,
      "name": "Plant_Coral_Block_Yellow"
    },
    {
      "x": -3,
      "y": 7,
      "z": 4,
      "name": "Plant_Coral_Block_Yellow"
    },
    {
      "x": -3,
      "y": 7,
      "z": 5,
      "name": "Plant_Coral_Block_Yellow"
    },
    {
      "x": -3,
      "y": 8,
      "z": 5,
      "name": "Plant_Coral_Block_Yellow"
    },
    {
      "x": -3,
      "y": 9,
      "z": 5,
      "name": "Plant_Coral_Block_Yellow"
    },
    {
      "x": -2,
      "y": 0,
      "z": 0,
      "name": "Plant_Coral_Block_Yellow"
    },
    {
      "x": -2,
      "y": 1,
      "z": 0,
      "name": "Plant_Coral_Block_Yellow"
    },
    {
      "x": -2,
      "y": 2,
      "z": 0,
      "name": "Plant_Coral_Block_Yellow"
    },
    {
      "x": -2,
      "y": 6,
      "z": 0,
      "name": "Plant_Coral_Block_Yellow"
    },
    {
      "x": -2,
      "y": 7,
      "z": 0,
      "name": "Plant_Coral_Block_Yellow"
    },
    {
      "x": -2,
      "y": 8,
      "z": 0,
      "name": "Plant_Coral_Block_Yellow"
    },
    {
      "x": -2,
      "y": 9,
      "z": 0,
      "name": "Plant_Coral_Block_Yellow"
    },
    {
      "x": -2,
      "y": 10,
      "z": 0,
      "name": "Plant_Coral_Block_Yellow"
    },
    {
      "x": -2,
      "y": 0,
      "z": 1,
      "name": "Plant_Coral_Block_Yellow"
    },
    {
      "x": -2,
      "y": 1,
      "z": 1,
      "name": "Plant_Coral_Block_Yellow"
    },
    {
      "x": -2,
      "y": 2,
      "z": 1,
      "name": "Plant_Coral_Block_Yellow"
    },
    {
      "x": -2,
      "y": 3,
      "z": 1,
      "name": "Plant_Coral_Block_Yellow"
    },
    {
      "x": -2,
      "y": 4,
      "z": 1,
      "name": "Plant_Coral_Block_Yellow"
    },
    {
      "x": -2,
      "y": 0,
      "z": 2,
      "name": "Plant_Coral_Block_Yellow"
    },
    {
      "x": -2,
      "y": 1,
      "z": 2,
      "name": "Plant_Coral_Block_Yellow"
    },
    {
      "x": -2,
      "y": 2,
      "z": 2,
      "name": "Plant_Coral_Block_Yellow"
    },
    {
      "x": -2,
      "y": 3,
      "z": 2,
      "name": "Plant_Coral_Block_Yellow"
    },
    {
      "x": -2,
      "y": 4,
      "z": 2,
      "name": "Plant_Coral_Block_Yellow"
    },
    {
      "x": -2,
      "y": 5,
      "z": 2,
      "name": "Plant_Coral_Block_Yellow"
    },
    {
      "x": -2,
      "y": 6,
      "z": 2,
      "name": "Plant_Coral_Block_Yellow"
    },
    {
      "x": -2,
      "y": 7,
      "z": 2,
      "name": "Plant_Coral_Block_Yellow"
    },
    {
      "x": -2,
      "y": 8,
      "z": 2,
      "name": "Plant_Coral_Block_Yellow"
    },
    {
      "x": -2,
      "y": 2,
      "z": 3,
      "name": "Plant_Coral_Block_Yellow"
    },
    {
      "x": -2,
      "y": 3,
      "z": 3,
      "name": "Plant_Coral_Block_Yellow"
    },
    {
      "x": -1,
      "y": 5,
      "z": -3,
      "name": "Plant_Coral_Block_Yellow"
    },
    {
      "x": -1,
      "y": 6,
      "z": -3,
      "name": "Plant_Coral_Block_Yellow"
    },
    {
      "x": -1,
      "y": 7,
      "z": -3,
      "name": "Plant_Coral_Block_Yellow"
    },
    {
      "x": -1,
      "y": 3,
      "z": -2,
      "name": "Plant_Coral_Block_Yellow"
    },
    {
      "x": -1,
      "y": 4,
      "z": -2,
      "name": "Plant_Coral_Block_Yellow"
    },
    {
      "x": -1,
      "y": 5,
      "z": -2,
      "name": "Plant_Coral_Block_Yellow"
    },
    {
      "x": -1,
      "y": 2,
      "z": -1,
      "name": "Plant_Coral_Block_Yellow"
    },
    {
      "x": -1,
      "y": 3,
      "z": -1,
      "name": "Plant_Coral_Block_Yellow"
    },
    {
      "x": -1,
      "y": 0,
      "z": 0,
      "name": "Plant_Coral_Block_Yellow"
    },
    {
      "x": -1,
      "y": 1,
      "z": 0,
      "name": "Plant_Coral_Block_Yellow"
    },
    {
      "x": -1,
      "y": 2,
      "z": 0,
      "name": "Plant_Coral_Block_Yellow"
    },
    {
      "x": -1,
      "y": 3,
      "z": 0,
      "name": "Plant_Coral_Block_Yellow"
    },
    {
      "x": -1,
      "y": 4,
      "z": 0,
      "name": "Plant_Coral_Block_Yellow"
    },
    {
      "x": -1,
      "y": 0,
      "z": 1,
      "name": "Plant_Coral_Block_Yellow"
    },
    {
      "x": -1,
      "y": 1,
      "z": 1,
      "name": "Plant_Coral_Block_Yellow"
    },
    {
      "x": -1,
      "y": 2,
      "z": 1,
      "name": "Plant_Coral_Block_Yellow"
    },
    {
      "x": -1,
      "y": 3,
      "z": 1,
      "name": "Plant_Coral_Block_Yellow"
    },
    {
      "x": -1,
      "y": 4,
      "z": 1,
      "name": "Plant_Coral_Block_Yellow"
    },
    {
      "x": -1,
      "y": 2,
      "z": 2,
      "name": "Plant_Coral_Block_Yellow"
    },
    {
      "x": -1,
      "y": 3,
      "z": 2,
      "name": "Plant_Coral_Block_Yellow"
    },
    {
      "x": -1,
      "y": 3,
      "z": 3,
      "name": "Plant_Coral_Block_Yellow"
    },
    {
      "x": -1,
      "y": 4,
      "z": 3,
      "name": "Plant_Coral_Block_Yellow"
    },
    {
      "x": -1,
      "y": 8,
      "z": 3,
      "name": "Plant_Coral_Block_Yellow"
    },
    {
      "x": -1,
      "y": 9,
      "z": 3,
      "name": "Plant_Coral_Block_Yellow"
    },
    {
      "x": -1,
      "y": 10,
      "z": 3,
      "name": "Plant_Coral_Block_Yellow"
    },
    {
      "x": -1,
      "y": 11,
      "z": 3,
      "name": "Plant_Coral_Block_Yellow"
    },
    {
      "x": -1,
      "y": 4,
      "z": 4,
      "name": "Plant_Coral_Block_Yellow"
    },
    {
      "x": -1,
      "y": 5,
      "z": 4,
      "name": "Plant_Coral_Block_Yellow"
    },
    {
      "x": -1,
      "y": 6,
      "z": 4,
      "name": "Plant_Coral_Block_Yellow"
    },
    {
      "x": -1,
      "y": 6,
      "z": 5,
      "name": "Plant_Coral_Block_Yellow"
    },
    {
      "x": -1,
      "y": 7,
      "z": 5,
      "name": "Plant_Coral_Block_Yellow"
    },
    {
      "x": -1,
      "y": 8,
      "z": 5,
      "name": "Plant_Coral_Block_Yellow"
    },
    {
      "x": 0,
      "y": 4,
      "z": -1,
      "name": "Plant_Coral_Block_Yellow"
    },
    {
      "x": 0,
      "y": 5,
      "z": -1,
      "name": "Plant_Coral_Block_Yellow"
    },
    {
      "x": 0,
      "y": 6,
      "z": -1,
      "name": "Plant_Coral_Block_Yellow"
    },
    {
      "x": 0,
      "y": 4,
      "z": 1,
      "name": "Plant_Coral_Block_Yellow"
    },
    {
      "x": 0,
      "y": 5,
      "z": 1,
      "name": "Plant_Coral_Block_Yellow"
    },
    {
      "x": 0,
      "y": 6,
      "z": 1,
      "name": "Plant_Coral_Block_Yellow"
    },
    {
      "x": 0,
      "y": 7,
      "z": 1,
      "name": "Plant_Coral_Block_Yellow"
    },
    {
      "x": 1,
      "y": 6,
      "z": -1,
      "name": "Plant_Coral_Block_Yellow"
    },
    {
      "x": 1,
      "y": 7,
      "z": -1,
      "name": "Plant_Coral_Block_Yellow"
    },
    {
      "x": 1,
      "y": 8,
      "z": -1,
      "name": "Plant_Coral_Block_Yellow"
    },
    {
      "x": 1,
      "y": 7,
      "z": 1,
      "name": "Plant_Coral_Block_Yellow"
    },
    {
      "x": 1,
      "y": 8,
      "z": 1,
      "name": "Plant_Coral_Block_Yellow"
    },
    {
      "x": 1,
      "y": 9,
      "z": 1,
      "name": "Plant_Coral_Block_Yellow"
    }
  ]
}