{
  "version": 8,
  "blockIdVersion": 8,
  "anchorX": 4,
  "anchorY": 7,
  "anchorZ": 5,
  "blocks": [
    {
      "x": 2,
      "y": 10,
      "z": 5,
      "name": "Plant_Leaves_Dead"
    },
    {
      "x": 3,
      "y": 3,
      "z": 4,
      "name": "Wood_Fir_Roots"
    },
    {
      "x": 3,
      "y": 4,
      "z": 4,
      "name": "Wood_Fir_Trunk"
    },
    {
      "x": 3,
      "y": 5,
      "z": 4,
      "name": "Wood_Fir_Trunk_Full"
    },
    {
      "x": 3,
      "y": 10,
      "z": 4,
      "name": "Plant_Leaves_Dead"
    },
    {
      "x": 3,
      "y": 13,
      "z": 4,
      "name": "Plant_Leaves_Dead"
    },
    {
      "x": 3,
      "y": 5,
      "z": 5,
      "name": "Wood_Fir_Trunk_Full"
    },
    {
      "x": 3,
      "y": 10,
      "z": 5,
      "name": "Wood_Fir_Branch_Long",
      "rotation": 5
    },
    {
      "x": 3,
      "y": 11,
      "z": 5,
      "name": "Plant_Leaves_Dead"
    },
    {
      "x": 3,
      "y": 13,
      "z": 5,
      "name": "Wood_Fir_Branch_Corner",
      "rotation": 3
    },
    {
      "x": 3,
      "y": 14,
      "z": 5,
      "name": "Plant_Leaves_Dead"
    },
    {
      "x": 3,
      "y": 16,
      "z": 5,
      "name": "Plant_Leaves_Dead"
    },
    {
      "x": 3,
      "y": 17,
      "z": 5,
      "name": "Plant_Leaves_Dead"
    },
    {
      "x": 3,
      "y": 11,
      "z": 6,
      "name": "Plant_Leaves_Dead"
    },
    {
      "x": 3,
      "y": 12,
      "z": 6,
      "name": "Plant_Leaves_Dead"
    },
    {
      "x": 3,
      "y": 10,
      "z": 7,
      "name": "Plant_Leaves_Dead"
    },
    {
      "x": 4,
      "y": 10,
      "z": 3,
      "name": "Plant_Leaves_Dead"
    },
    {
      "x": 4,
      "y": 10,
      "z": 4,
      "name": "Plant_Leaves_Dead"
    },
    {
      "x": 4,
      "y": 11,
      "z": 4,
      "name": "Plant_Leaves_Dead"
    },
    {
      "x": 4,
      "y": 13,
      "z": 4,
      "name": "Plant_Leaves_Dead"
    },
    {
      "x": 4,
      "y": 14,
      "z": 4,
      "name": "Plant_Leaves_Dead"
    },
    {
      "x": 4,
      "y": 16,
      "z": 4,
      "name": "Plant_Leaves_Dead"
    },
    {
      "x": 4,
      "y": 17,
      "z": 4,
      "name": "Plant_Leaves_Dead"
    },
    {
      "x": 4,
      "y": 5,
      "z": 5,
      "name": "Wood_Fir_Trunk"
    },
    {
      "x": 4,
      "y": 6,
      "z": 5,
      "name": "Wood_Fir_Trunk"
    },
    {
      "x": 4,
      "y": 7,
      "z": 5,
      "name": "Wood_Fir_Trunk"
    },
    {
      "x": 4,
      "y": 8,
      "z": 5,
      "name": "Wood_Fir_Trunk"
    },
    {
      "x": 4,
      "y": 9,
      "z": 5,
      "name": "Wood_Fir_Trunk"
    },
    {
      "x": 4,
      "y": 10,
      "z": 5,
      "name": "Wood_Fir_Trunk"
    },
    {
      "x": 4,
      "y": 11,
      "z": 5,
      "name": "Wood_Fir_Trunk"
    },
    {
      "x": 4,
      "y": 12,
      "z": 5,
      "name": "Wood_Fir_Trunk"
    },
    {
      "x": 4,
      "y": 13,
      "z": 5,
      "name": "Wood_Fir_Trunk"
    },
    {
      "x": 4,
      "y": 14,
      "z": 5,
      "name": "Wood_Fir_Trunk"
    },
    {
      "x": 4,
      "y": 15,
      "z": 5,
      "name": "Wood_Fir_Trunk_Full"
    },
    {
      "x": 4,
      "y": 16,
      "z": 5,
      "name": "Wood_Fir_Trunk_Full"
    },
    {
      "x": 4,
      "y": 17,
      "z": 5,
      "name": "Plant_Leaves_Dead"
    },
    {
      "x": 4,
      "y": 18,
      "z": 5,
      "name": "Plant_Leaves_Dead"
    },
    {
      "x": 4,
      "y": 19,
      "z": 5,
      "name": "Plant_Leaves_Dead"
    },
    {
      "x": 4,
      "y": 20,
      "z": 5,
      "name": "Plant_Leaves_Dead"
    },
    {
      "x": 4,
      "y": 21,
      "z": 5,
      "name": "Plant_Leaves_Dead"
    },
    {
      "x": 4,
      "y": 5,
      "z": 6,
      "name": "Wood_Fir_Trunk_Full"
    },
    {
      "x": 4,
      "y": 10,
      "z": 6,
      "name": "Plant_Leaves_Dead"
    },
    {
      "x": 4,
      "y": 11,
      "z": 6,
      "name": "Plant_Leaves_Dead"
    },
    {
      "x": 4,
      "y": 13,
      "z": 6,
      "name": "Plant_Leaves_Dead"
    },
    {
      "x": 4,
      "y": 15,
      "z": 6,
      "name": "Plant_Leaves_Dead"
    },
    {
      "x": 4,
      "y": 16,
      "z": 6,
      "name": "Plant_Leaves_Dead"
    },
    {
      "x": 4,
      "y": 17,
      "z": 6,
      "name": "Plant_Leaves_Dead"
    },
    {
      "x": 4,
      "y": 18,
      "z": 6,
      "name": "Plant_Leaves_Dead"
    },
    {
      "x": 4,
      "y": 10,
      "z": 7,
      "name": "Plant_Leaves_Dead"
    },
    {
      "x": 5,
      "y": 10,
      "z": 4,
      "name": "Plant_Leaves_Dead"
    },
    {
      "x": 5,
      "y": 13,
      "z": 4,
      "name": "Plant_Leaves_Dead"
    },
    {
      "x": 5,
      "y": 9,
      "z": 5,
      "name": "Plant_Leaves_Dead"
    },
    {
      "x": 5,
      "y": 10,
      "z": 5,
      "name": "Plant_Leaves_Dead"
    },
    {
      "x": 5,
      "y": 11,
      "z": 5,
      "name": "Wood_Fir_Branch_Corner",
      "rotation": 1
    },
    {
      "x": 5,
      "y": 12,
      "z": 5,
      "name": "Plant_Leaves_Dead"
    },
    {
      "x": 5,
      "y": 13,
      "z": 5,
      "name": "Plant_Leaves_Dead"
    },
    {
      "x": 5,
      "y": 14,
      "z": 5,
      "name": "Plant_Leaves_Dead"
    },
    {
      "x": 5,
      "y": 16,
      "z": 5,
      "name": "Plant_Leaves_Dead"
    },
    {
      "x": 5,
      "y": 17,
      "z": 5,
      "name": "Plant_Leaves_Dead"
    },
    {
      "x": 5,
      "y": 1,
      "z": 6,
      "name": "Wood_Fir_Roots"
    },
    {
      "x": 5,
      "y": 2,
      "z": 6,
      "name": "Wood_Fir_Trunk"
    },
    {
      "x": 5,
      "y": 3,
      "z": 6,
      "name": "Wood_Fir_Trunk"
    },
    {
      "x": 5,
      "y": 4,
      "z": 6,
      "name": "Wood_Fir_Trunk"
    },
    {
      "x": 5,
      "y": 5,
      "z": 6,
      "name": "Wood_Fir_Trunk_Full"
    },
    {
      "x": 5,
      "y": 10,
      "z": 6,
      "name": "Plant_Leaves_Dead"
    },
    {
      "x": 5,
      "y": 11,
      "z": 6,
      "name": "Plant_Leaves_Dead"
    },
    {
      "x": 5,
      "y": 13,
      "z": 6,
      "name": "Plant_Leaves_Dead"
    },
    {
      "x": 5,
      "y": 16,
      "z": 6,
      "name": "Plant_Leaves_Dead"
    },
    {
      "x": 6,
      "y": 9,
      "z": 5,
      "name": "Plant_Leaves_Dead"
    },
    {
      "x": 6,
      "y": 9,
      "z": 6,
      "name": "Plant_Leaves_Dead"
    }
  ]
}