{
  "version": 8,
  "blockIdVersion": 8,
  "anchorX": 3,
  "anchorY": 6,
  "anchorZ": -2,
  "blocks": [
    {
      "x": -5,
      "y": 5,
      "z": -9,
      "name": "Rock_Quartzite"
    },
    {
      "x": -5,
      "y": 6,
      "z": -9,
      "name": "Rock_Quartzite"
    },
    {
      "x": -5,
      "y": 3,
      "z": -8,
      "name": "Rock_Quartzite"
    },
    {
      "x": -5,
      "y": 4,
      "z": -8,
      "name": "Rock_Quartzite"
    },
    {
      "x": -5,
      "y": 5,
      "z": -8,
      "name": "Rock_Quartzite"
    },
    {
      "x": -5,
      "y": 6,
      "z": -8,
      "name": "Rock_Quartzite"
    },
    {
      "x": -5,
      "y": 2,
      "z": -7,
      "name": "Rock_Quartzite"
    },
    {
      "x": -5,
      "y": 3,
      "z": -7,
      "name": "Rock_Quartzite"
    },
    {
      "x": -5,
      "y": 4,
      "z": -7,
      "name": "Rock_Quartzite_Cobble"
    },
    {
      "x": -5,
      "y": 5,
      "z": -7,
      "name": "Rock_Quartzite_Cobble"
    },
    {
      "x": -5,
      "y": 6,
      "z": -7,
      "name": "Rock_Quartzite_Cobble"
    },
    {
      "x": -5,
      "y": 1,
      "z": -6,
      "name": "Rock_Quartzite"
    },
    {
      "x": -5,
      "y": 2,
      "z": -6,
      "name": "Rock_Quartzite"
    },
    {
      "x": -5,
      "y": 3,
      "z": -6,
      "name": "Rock_Quartzite_Cobble"
    },
    {
      "x": -5,
      "y": 4,
      "z": -6,
      "name": "Rock_Quartzite_Cobble"
    },
    {
      "x": -5,
      "y": 5,
      "z": -6,
      "name": "Rock_Quartzite_Cobble"
    },
    {
      "x": -5,
      "y": 6,
      "z": -6,
      "name": "Rock_Quartzite_Cobble"
    },
    {
      "x": -5,
      "y": 1,
      "z": -5,
      "name": "Rock_Quartzite"
    },
    {
      "x": -5,
      "y": 2,
      "z": -5,
      "name": "Rock_Quartzite"
    },
    {
      "x": -5,
      "y": 3,
      "z": -5,
      "name": "Rock_Quartzite"
    },
    {
      "x": -5,
      "y": 4,
      "z": -5,
      "name": "Rock_Quartzite"
    },
    {
      "x": -5,
      "y": 5,
      "z": -5,
      "name": "Rock_Quartzite"
    },
    {
      "x": -5,
      "y": 6,
      "z": -5,
      "name": "Rock_Quartzite"
    },
    {
      "x": -5,
      "y": 1,
      "z": -4,
      "name": "Rock_Quartzite"
    },
    {
      "x": -5,
      "y": 2,
      "z": -4,
      "name": "Rock_Quartzite"
    },
    {
      "x": -5,
      "y": 3,
      "z": -4,
      "name": "Rock_Quartzite"
    },
    {
      "x": -5,
      "y": 4,
      "z": -4,
      "name": "Rock_Quartzite"
    },
    {
      "x": -5,
      "y": 5,
      "z": -4,
      "name": "Rock_Quartzite"
    },
    {
      "x": -5,
      "y": 6,
      "z": -4,
      "name": "Rock_Quartzite"
    },
    {
      "x": -5,
      "y": 2,
      "z": -3,
      "name": "Rock_Quartzite"
    },
    {
      "x": -5,
      "y": 3,
      "z": -3,
      "name": "Rock_Quartzite"
    },
    {
      "x": -5,
      "y": 4,
      "z": -3,
      "name": "Rock_Quartzite"
    },
    {
      "x": -5,
      "y": 5,
      "z": -3,
      "name": "Rock_Quartzite"
    },
    {
      "x": -5,
      "y": 6,
      "z": -3,
      "name": "Rock_Quartzite"
    },
    {
      "x": -5,
      "y": 2,
      "z": -2,
      "name": "Rock_Quartzite"
    },
    {
      "x": -5,
      "y": 3,
      "z": -2,
      "name": "Rock_Quartzite"
    },
    {
      "x": -5,
      "y": 4,
      "z": -2,
      "name": "Rock_Quartzite"
    },
    {
      "x": -5,
      "y": 5,
      "z": -2,
      "name": "Rock_Quartzite"
    },
    {
      "x": -5,
      "y": 6,
      "z": -2,
      "name": "Rock_Quartzite"
    },
    {
      "x": -5,
      "y": 7,
      "z": -2,
      "name": "Rock_Quartzite_Brick"
    },
    {
      "x": -5,
      "y": 8,
      "z": -2,
      "name": "Rock_Quartzite_Brick_Half",
      "rotation": 7
    },
    {
      "x": -5,
      "y": 9,
      "z": -2,
      "name": "Rock_Quartzite_Brick_Half",
      "rotation": 7
    },
    {
      "x": -5,
      "y": 10,
      "z": -2,
      "name": "Rock_Quartzite_Brick_Half",
      "rotation": 7
    },
    {
      "x": -5,
      "y": 11,
      "z": -2,
      "name": "Rock_Quartzite_Brick_Half",
      "rotation": 7
    },
    {
      "x": -5,
      "y": 3,
      "z": -1,
      "name": "Rock_Quartzite"
    },
    {
      "x": -5,
      "y": 4,
      "z": -1,
      "name": "Rock_Quartzite"
    },
    {
      "x": -5,
      "y": 5,
      "z": -1,
      "name": "Rock_Quartzite"
    },
    {
      "x": -5,
      "y": 6,
      "z": -1,
      "name": "Rock_Quartzite"
    },
    {
      "x": -5,
      "y": 2,
      "z": 0,
      "name": "Rock_Quartzite"
    },
    {
      "x": -5,
      "y": 3,
      "z": 0,
      "name": "Rock_Quartzite"
    },
    {
      "x": -5,
      "y": 4,
      "z": 0,
      "name": "Rock_Quartzite"
    },
    {
      "x": -5,
      "y": 5,
      "z": 0,
      "name": "Rock_Quartzite"
    },
    {
      "x": -5,
      "y": 6,
      "z": 0,
      "name": "Rock_Quartzite"
    },
    {
      "x": -5,
      "y": 2,
      "z": 1,
      "name": "Rock_Quartzite"
    },
    {
      "x": -5,
      "y": 3,
      "z": 1,
      "name": "Rock_Quartzite"
    },
    {
      "x": -5,
      "y": 4,
      "z": 1,
      "name": "Rock_Quartzite"
    },
    {
      "x": -5,
      "y": 5,
      "z": 1,
      "name": "Rock_Quartzite"
    },
    {
      "x": -5,
      "y": 6,
      "z": 1,
      "name": "Rock_Quartzite"
    },
    {
      "x": -5,
      "y": 11,
      "z": 1,
      "name": "Plant_Vine_Wall",
      "rotation": 3
    },
    {
      "x": -5,
      "y": 2,
      "z": 2,
      "name": "Rock_Quartzite"
    },
    {
      "x": -5,
      "y": 3,
      "z": 2,
      "name": "Rock_Quartzite"
    },
    {
      "x": -5,
      "y": 4,
      "z": 2,
      "name": "Rock_Quartzite"
    },
    {
      "x": -5,
      "y": 5,
      "z": 2,
      "name": "Rock_Quartzite"
    },
    {
      "x": -5,
      "y": 6,
      "z": 2,
      "name": "Rock_Quartzite"
    },
    {
      "x": -5,
      "y": 9,
      "z": 2,
      "name": "Plant_Vine_Wall",
      "rotation": 3
    },
    {
      "x": -5,
      "y": 10,
      "z": 2,
      "name": "Plant_Vine",
      "rotation": 3
    },
    {
      "x": -5,
      "y": 11,
      "z": 2,
      "name": "Plant_Vine",
      "rotation": 3
    },
    {
      "x": -5,
      "y": 1,
      "z": 3,
      "name": "Rock_Quartzite"
    },
    {
      "x": -5,
      "y": 2,
      "z": 3,
      "name": "Rock_Quartzite"
    },
    {
      "x": -5,
      "y": 3,
      "z": 3,
      "name": "Rock_Quartzite"
    },
    {
      "x": -5,
      "y": 4,
      "z": 3,
      "name": "Rock_Quartzite"
    },
    {
      "x": -5,
      "y": 5,
      "z": 3,
      "name": "Rock_Quartzite"
    },
    {
      "x": -5,
      "y": 6,
      "z": 3,
      "name": "Rock_Quartzite"
    },
    {
      "x": -5,
      "y": 7,
      "z": 3,
      "name": "Rock_Quartzite_Brick"
    },
    {
      "x": -5,
      "y": 8,
      "z": 3,
      "name": "Rock_Quartzite_Brick_Half",
      "rotation": 7
    },
    {
      "x": -5,
      "y": 9,
      "z": 3,
      "name": "Rock_Quartzite_Brick_Half",
      "rotation": 7
    },
    {
      "x": -5,
      "y": 10,
      "z": 3,
      "name": "Rock_Quartzite_Brick_Half",
      "rotation": 7
    },
    {
      "x": -5,
      "y": 11,
      "z": 3,
      "name": "Rock_Quartzite_Brick_Half",
      "rotation": 7
    },
    {
      "x": -5,
      "y": 1,
      "z": 4,
      "name": "Rock_Quartzite"
    },
    {
      "x": -5,
      "y": 2,
      "z": 4,
      "name": "Rock_Quartzite"
    },
    {
      "x": -5,
      "y": 3,
      "z": 4,
      "name": "Rock_Quartzite"
    },
    {
      "x": -5,
      "y": 4,
      "z": 4,
      "name": "Rock_Quartzite"
    },
    {
      "x": -5,
      "y": 5,
      "z": 4,
      "name": "Rock_Quartzite"
    },
    {
      "x": -5,
      "y": 6,
      "z": 4,
      "name": "Rock_Quartzite"
    },
    {
      "x": -5,
      "y": 12,
      "z": 4,
      "name": "Rock_Quartzite_Brick_Stairs",
      "rotation": 9
    },
    {
      "x": -5,
      "y": 1,
      "z": 5,
      "name": "Rock_Quartzite"
    },
    {
      "x": -5,
      "y": 2,
      "z": 5,
      "name": "Rock_Quartzite"
    },
    {
      "x": -5,
      "y": 3,
      "z": 5,
      "name": "Rock_Quartzite"
    },
    {
      "x": -5,
      "y": 4,
      "z": 5,
      "name": "Rock_Quartzite"
    },
    {
      "x": -5,
      "y": 5,
      "z": 5,
      "name": "Rock_Quartzite"
    },
    {
      "x": -5,
      "y": 6,
      "z": 5,
      "name": "Rock_Quartzite"
    },
    {
      "x": -5,
      "y": 12,
      "z": 5,
      "name": "Rock_Quartzite_Brick_Stairs",
      "rotation": 9
    },
    {
      "x": -5,
      "y": 1,
      "z": 6,
      "name": "Rock_Quartzite"
    },
    {
      "x": -5,
      "y": 2,
      "z": 6,
      "name": "Rock_Quartzite"
    },
    {
      "x": -5,
      "y": 3,
      "z": 6,
      "name": "Rock_Quartzite"
    },
    {
      "x": -5,
      "y": 4,
      "z": 6,
      "name": "Rock_Quartzite"
    },
    {
      "x": -5,
      "y": 5,
      "z": 6,
      "name": "Rock_Quartzite"
    },
    {
      "x": -5,
      "y": 6,
      "z": 6,
      "name": "Rock_Quartzite"
    },
    {
      "x": -5,
      "y": 12,
      "z": 6,
      "name": "Rock_Quartzite_Brick_Stairs",
      "rotation": 9
    },
    {
      "x": -5,
      "y": 3,
      "z": 7,
      "name": "Rock_Quartzite"
    },
    {
      "x": -5,
      "y": 4,
      "z": 7,
      "name": "Rock_Quartzite"
    },
    {
      "x": -5,
      "y": 5,
      "z": 7,
      "name": "Rock_Quartzite"
    },
    {
      "x": -5,
      "y": 6,
      "z": 7,
      "name": "Rock_Quartzite"
    },
    {
      "x": -5,
      "y": 12,
      "z": 7,
      "name": "Rock_Quartzite_Brick_Stairs",
      "rotation": 9
    },
    {
      "x": -5,
      "y": 4,
      "z": 8,
      "name": "Rock_Quartzite"
    },
    {
      "x": -5,
      "y": 5,
      "z": 8,
      "name": "Rock_Quartzite"
    },
    {
      "x": -5,
      "y": 6,
      "z": 8,
      "name": "Rock_Quartzite"
    },
    {
      "x": -5,
      "y": 7,
      "z": 8,
      "name": "Rock_Quartzite_Brick"
    },
    {
      "x": -5,
      "y": 8,
      "z": 8,
      "name": "Rock_Quartzite_Brick_Half",
      "rotation": 7
    },
    {
      "x": -5,
      "y": 9,
      "z": 8,
      "name": "Rock_Quartzite_Brick_Half",
      "rotation": 7
    },
    {
      "x": -5,
      "y": 10,
      "z": 8,
      "name": "Rock_Quartzite_Brick_Half",
      "rotation": 7
    },
    {
      "x": -5,
      "y": 11,
      "z": 8,
      "name": "Rock_Quartzite_Brick_Half",
      "rotation": 7
    },
    {
      "x": -5,
      "y": 12,
      "z": 8,
      "name": "Rock_Quartzite_Brick"
    },
    {
      "x": -5,
      "y": 4,
      "z": 9,
      "name": "Rock_Quartzite"
    },
    {
      "x": -5,
      "y": 5,
      "z": 9,
      "name": "Rock_Quartzite"
    },
    {
      "x": -5,
      "y": 6,
      "z": 9,
      "name": "Rock_Quartzite"
    },
    {
      "x": -4,
      "y": 2,
      "z": -9,
      "name": "Rock_Quartzite"
    },
    {
      "x": -4,
      "y": 3,
      "z": -9,
      "name": "Rock_Quartzite"
    },
    {
      "x": -4,
      "y": 4,
      "z": -9,
      "name": "Rock_Quartzite"
    },
    {
      "x": -4,
      "y": 5,
      "z": -9,
      "name": "Rock_Quartzite"
    },
    {
      "x": -4,
      "y": 6,
      "z": -9,
      "name": "Rock_Quartzite"
    },
    {
      "x": -4,
      "y": 0,
      "z": -8,
      "name": "Rock_Quartzite"
    },
    {
      "x": -4,
      "y": 1,
      "z": -8,
      "name": "Rock_Quartzite"
    },
    {
      "x": -4,
      "y": 2,
      "z": -8,
      "name": "Rock_Quartzite"
    },
    {
      "x": -4,
      "y": 3,
      "z": -8,
      "name": "Rock_Quartzite"
    },
    {
      "x": -4,
      "y": 4,
      "z": -8,
      "name": "Rock_Quartzite"
    },
    {
      "x": -4,
      "y": 5,
      "z": -8,
      "name": "Rock_Quartzite"
    },
    {
      "x": -4,
      "y": 6,
      "z": -8,
      "name": "Rock_Quartzite"
    },
    {
      "x": -4,
      "y": 7,
      "z": -8,
      "name": "Rock_Quartzite_Brick_Stairs",
      "rotation": 2
    },
    {
      "x": -4,
      "y": 0,
      "z": -7,
      "name": "Rock_Quartzite"
    },
    {
      "x": -4,
      "y": 1,
      "z": -7,
      "name": "Rock_Quartzite"
    },
    {
      "x": -4,
      "y": 2,
      "z": -7,
      "name": "Rock_Quartzite"
    },
    {
      "x": -4,
      "y": 3,
      "z": -7,
      "name": "Rock_Quartzite"
    },
    {
      "x": -4,
      "y": 4,
      "z": -7,
      "name": "Rock_Quartzite"
    },
    {
      "x": -4,
      "y": 5,
      "z": -7,
      "name": "Rock_Quartzite"
    },
    {
      "x": -4,
      "y": 6,
      "z": -7,
      "name": "Rock_Quartzite"
    },
    {
      "x": -4,
      "y": 7,
      "z": -7,
      "name": "Rock_Quartzite_Brick"
    },
    {
      "x": -4,
      "y": 8,
      "z": -7,
      "name": "Rock_Quartzite_Brick_Stairs",
      "rotation": 2
    },
    {
      "x": -4,
      "y": 0,
      "z": -6,
      "name": "Rock_Quartzite"
    },
    {
      "x": -4,
      "y": 1,
      "z": -6,
      "name": "Rock_Quartzite"
    },
    {
      "x": -4,
      "y": 2,
      "z": -6,
      "name": "Rock_Quartzite"
    },
    {
      "x": -4,
      "y": 3,
      "z": -6,
      "name": "Rock_Quartzite"
    },
    {
      "x": -4,
      "y": 4,
      "z": -6,
      "name": "Rock_Quartzite"
    },
    {
      "x": -4,
      "y": 5,
      "z": -6,
      "name": "Rock_Quartzite"
    },
    {
      "x": -4,
      "y": 6,
      "z": -6,
      "name": "Rock_Quartzite_Cobble"
    },
    {
      "x": -4,
      "y": 8,
      "z": -6,
      "name": "Rock_Quartzite_Brick"
    },
    {
      "x": -4,
      "y": 9,
      "z": -6,
      "name": "Rock_Quartzite_Brick_Stairs",
      "rotation": 2
    },
    {
      "x": -4,
      "y": 0,
      "z": -5,
      "name": "Rock_Quartzite"
    },
    {
      "x": -4,
      "y": 1,
      "z": -5,
      "name": "Rock_Quartzite"
    },
    {
      "x": -4,
      "y": 2,
      "z": -5,
      "name": "Rock_Quartzite"
    },
    {
      "x": -4,
      "y": 3,
      "z": -5,
      "name": "Rock_Quartzite"
    },
    {
      "x": -4,
      "y": 4,
      "z": -5,
      "name": "Rock_Quartzite"
    },
    {
      "x": -4,
      "y": 5,
      "z": -5,
      "name": "Rock_Quartzite"
    },
    {
      "x": -4,
      "y": 6,
      "z": -5,
      "name": "Rock_Quartzite"
    },
    {
      "x": -4,
      "y": 9,
      "z": -5,
      "name": "Rock_Quartzite_Brick"
    },
    {
      "x": -4,
      "y": 10,
      "z": -5,
      "name": "Rock_Quartzite_Brick_Stairs",
      "rotation": 2
    },
    {
      "x": -4,
      "y": 0,
      "z": -4,
      "name": "Rock_Quartzite"
    },
    {
      "x": -4,
      "y": 1,
      "z": -4,
      "name": "Rock_Quartzite"
    },
    {
      "x": -4,
      "y": 2,
      "z": -4,
      "name": "Rock_Quartzite"
    },
    {
      "x": -4,
      "y": 3,
      "z": -4,
      "name": "Rock_Quartzite"
    },
    {
      "x": -4,
      "y": 4,
      "z": -4,
      "name": "Rock_Quartzite"
    },
    {
      "x": -4,
      "y": 5,
      "z": -4,
      "name": "Rock_Quartzite"
    },
    {
      "x": -4,
      "y": 6,
      "z": -4,
      "name": "Rock_Quartzite"
    },
    {
      "x": -4,
      "y": 10,
      "z": -4,
      "name": "Rock_Quartzite_Brick"
    },
    {
      "x": -4,
      "y": 11,
      "z": -4,
      "name": "Rock_Quartzite_Brick_Stairs",
      "rotation": 2
    },
    {
      "x": -4,
      "y": 0,
      "z": -3,
      "name": "Rock_Quartzite"
    },
    {
      "x": -4,
      "y": 1,
      "z": -3,
      "name": "Rock_Quartzite"
    },
    {
      "x": -4,
      "y": 2,
      "z": -3,
      "name": "Rock_Quartzite"
    },
    {
      "x": -4,
      "y": 3,
      "z": -3,
      "name": "Rock_Quartzite"
    },
    {
      "x": -4,
      "y": 4,
      "z": -3,
      "name": "Rock_Quartzite"
    },
    {
      "x": -4,
      "y": 5,
      "z": -3,
      "name": "Rock_Quartzite"
    },
    {
      "x": -4,
      "y": 6,
      "z": -3,
      "name": "Rock_Quartzite"
    },
    {
      "x": -4,
      "y": 7,
      "z": -3,
      "name": "Rock_Quartzite_Brick"
    },
    {
      "x": -4,
      "y": 8,
      "z": -3,
      "name": "Rock_Quartzite_Cobble"
    },
    {
      "x": -4,
      "y": 9,
      "z": -3,
      "name": "Rock_Quartzite_Cobble"
    },
    {
      "x": -4,
      "y": 10,
      "z": -3,
      "name": "Rock_Quartzite_Cobble"
    },
    {
      "x": -4,
      "y": 11,
      "z": -3,
      "name": "Rock_Quartzite_Brick"
    },
    {
      "x": -4,
      "y": 12,
      "z": -3,
      "name": "Rock_Quartzite_Brick_Half"
    },
    {
      "x": -4,
      "y": 0,
      "z": -2,
      "name": "Rock_Quartzite"
    },
    {
      "x": -4,
      "y": 1,
      "z": -2,
      "name": "Rock_Quartzite"
    },
    {
      "x": -4,
      "y": 2,
      "z": -2,
      "name": "Rock_Quartzite"
    },
    {
      "x": -4,
      "y": 3,
      "z": -2,
      "name": "Rock_Quartzite"
    },
    {
      "x": -4,
      "y": 4,
      "z": -2,
      "name": "Rock_Quartzite"
    },
    {
      "x": -4,
      "y": 5,
      "z": -2,
      "name": "Rock_Quartzite"
    },
    {
      "x": -4,
      "y": 6,
      "z": -2,
      "name": "Rock_Quartzite"
    },
    {
      "x": -4,
      "y": 7,
      "z": -2,
      "name": "Rock_Quartzite"
    },
    {
      "x": -4,
      "y": 8,
      "z": -2,
      "name": "Rock_Quartzite"
    },
    {
      "x": -4,
      "y": 9,
      "z": -2,
      "name": "Rock_Quartzite"
    },
    {
      "x": -4,
      "y": 10,
      "z": -2,
      "name": "Soil_Dirt"
    },
    {
      "x": -4,
      "y": 11,
      "z": -2,
      "name": "Soil_Grass"
    },
    {
      "x": -4,
      "y": 12,
      "z": -2,
      "name": "Plant_Grass_Lush"
    },
    {
      "x": -4,
      "y": 1,
      "z": -1,
      "name": "Rock_Quartzite"
    },
    {
      "x": -4,
      "y": 2,
      "z": -1,
      "name": "Rock_Quartzite"
    },
    {
      "x": -4,
      "y": 3,
      "z": -1,
      "name": "Rock_Quartzite"
    },
    {
      "x": -4,
      "y": 4,
      "z": -1,
      "name": "Rock_Quartzite"
    },
    {
      "x": -4,
      "y": 5,
      "z": -1,
      "name": "Rock_Quartzite"
    },
    {
      "x": -4,
      "y": 6,
      "z": -1,
      "name": "Rock_Quartzite"
    },
    {
      "x": -4,
      "y": 7,
      "z": -1,
      "name": "Rock_Quartzite_Brick"
    },
    {
      "x": -4,
      "y": 8,
      "z": -1,
      "name": "Rock_Quartzite"
    },
    {
      "x": -4,
      "y": 9,
      "z": -1,
      "name": "Rock_Quartzite"
    },
    {
      "x": -4,
      "y": 10,
      "z": -1,
      "name": "Rock_Quartzite"
    },
    {
      "x": -4,
      "y": 0,
      "z": 0,
      "name": "Rock_Quartzite"
    },
    {
      "x": -4,
      "y": 1,
      "z": 0,
      "name": "Rock_Quartzite"
    },
    {
      "x": -4,
      "y": 2,
      "z": 0,
      "name": "Rock_Quartzite"
    },
    {
      "x": -4,
      "y": 3,
      "z": 0,
      "name": "Rock_Quartzite"
    },
    {
      "x": -4,
      "y": 4,
      "z": 0,
      "name": "Rock_Quartzite"
    },
    {
      "x": -4,
      "y": 5,
      "z": 0,
      "name": "Rock_Quartzite"
    },
    {
      "x": -4,
      "y": 6,
      "z": 0,
      "name": "Rock_Quartzite"
    },
    {
      "x": -4,
      "y": 7,
      "z": 0,
      "name": "Rock_Quartzite_Brick"
    },
    {
      "x": -4,
      "y": 8,
      "z": 0,
      "name": "Rock_Quartzite"
    },
    {
      "x": -4,
      "y": 0,
      "z": 1,
      "name": "Rock_Quartzite"
    },
    {
      "x": -4,
      "y": 1,
      "z": 1,
      "name": "Rock_Quartzite"
    },
    {
      "x": -4,
      "y": 2,
      "z": 1,
      "name": "Rock_Quartzite"
    },
    {
      "x": -4,
      "y": 3,
      "z": 1,
      "name": "Rock_Quartzite"
    },
    {
      "x": -4,
      "y": 4,
      "z": 1,
      "name": "Rock_Quartzite"
    },
    {
      "x": -4,
      "y": 5,
      "z": 1,
      "name": "Rock_Quartzite"
    },
    {
      "x": -4,
      "y": 6,
      "z": 1,
      "name": "Rock_Quartzite"
    },
    {
      "x": -4,
      "y": 7,
      "z": 1,
      "name": "Rock_Quartzite_Brick"
    },
    {
      "x": -4,
      "y": 8,
      "z": 1,
      "name": "Rock_Quartzite_Cobble_Stairs",
      "rotation": 3
    },
    {
      "x": -4,
      "y": 9,
      "z": 1,
      "name": "Rock_Quartzite_Cobble"
    },
    {
      "x": -4,
      "y": 10,
      "z": 1,
      "name": "Soil_Dirt"
    },
    {
      "x": -4,
      "y": 11,
      "z": 1,
      "name": "Soil_Grass"
    },
    {
      "x": -4,
      "y": 12,
      "z": 1,
      "name": "Plant_Grass_Lush_Short"
    },
    {
      "x": -4,
      "y": 0,
      "z": 2,
      "name": "Rock_Quartzite"
    },
    {
      "x": -4,
      "y": 1,
      "z": 2,
      "name": "Rock_Quartzite"
    },
    {
      "x": -4,
      "y": 2,
      "z": 2,
      "name": "Rock_Quartzite"
    },
    {
      "x": -4,
      "y": 3,
      "z": 2,
      "name": "Rock_Quartzite"
    },
    {
      "x": -4,
      "y": 4,
      "z": 2,
      "name": "Rock_Quartzite"
    },
    {
      "x": -4,
      "y": 5,
      "z": 2,
      "name": "Rock_Quartzite"
    },
    {
      "x": -4,
      "y": 6,
      "z": 2,
      "name": "Rock_Quartzite"
    },
    {
      "x": -4,
      "y": 7,
      "z": 2,
      "name": "Rock_Quartzite_Cobble"
    },
    {
      "x": -4,
      "y": 8,
      "z": 2,
      "name": "Rock_Quartzite_Cobble"
    },
    {
      "x": -4,
      "y": 9,
      "z": 2,
      "name": "Rock_Quartzite_Cobble"
    },
    {
      "x": -4,
      "y": 10,
      "z": 2,
      "name": "Soil_Dirt"
    },
    {
      "x": -4,
      "y": 11,
      "z": 2,
      "name": "Soil_Grass"
    },
    {
      "x": -4,
      "y": 12,
      "z": 2,
      "name": "Plant_Moss_Rug_Green"
    },
    {
      "x": -4,
      "y": 0,
      "z": 3,
      "name": "Rock_Quartzite"
    },
    {
      "x": -4,
      "y": 1,
      "z": 3,
      "name": "Rock_Quartzite"
    },
    {
      "x": -4,
      "y": 2,
      "z": 3,
      "name": "Rock_Quartzite"
    },
    {
      "x": -4,
      "y": 3,
      "z": 3,
      "name": "Rock_Quartzite"
    },
    {
      "x": -4,
      "y": 4,
      "z": 3,
      "name": "Rock_Quartzite"
    },
    {
      "x": -4,
      "y": 5,
      "z": 3,
      "name": "Rock_Quartzite"
    },
    {
      "x": -4,
      "y": 6,
      "z": 3,
      "name": "Rock_Quartzite"
    },
    {
      "x": -4,
      "y": 7,
      "z": 3,
      "name": "Rock_Quartzite_Brick"
    },
    {
      "x": -4,
      "y": 8,
      "z": 3,
      "name": "Rock_Quartzite"
    },
    {
      "x": -4,
      "y": 9,
      "z": 3,
      "name": "Rock_Quartzite"
    },
    {
      "x": -4,
      "y": 10,
      "z": 3,
      "name": "Rock_Quartzite"
    },
    {
      "x": -4,
      "y": 11,
      "z": 3,
      "name": "Rock_Quartzite"
    },
    {
      "x": -4,
      "y": 12,
      "z": 3,
      "name": "Soil_Grass"
    },
    {
      "x": -4,
      "y": 0,
      "z": 4,
      "name": "Rock_Quartzite"
    },
    {
      "x": -4,
      "y": 1,
      "z": 4,
      "name": "Rock_Quartzite"
    },
    {
      "x": -4,
      "y": 2,
      "z": 4,
      "name": "Rock_Quartzite"
    },
    {
      "x": -4,
      "y": 3,
      "z": 4,
      "name": "Rock_Quartzite"
    },
    {
      "x": -4,
      "y": 4,
      "z": 4,
      "name": "Rock_Quartzite"
    },
    {
      "x": -4,
      "y": 5,
      "z": 4,
      "name": "Rock_Quartzite"
    },
    {
      "x": -4,
      "y": 6,
      "z": 4,
      "name": "Rock_Quartzite"
    },
    {
      "x": -4,
      "y": 7,
      "z": 4,
      "name": "Rock_Quartzite_Brick"
    },
    {
      "x": -4,
      "y": 8,
      "z": 4,
      "name": "Rock_Quartzite"
    },
    {
      "x": -4,
      "y": 9,
      "z": 4,
      "name": "Rock_Quartzite"
    },
    {
      "x": -4,
      "y": 10,
      "z": 4,
      "name": "Rock_Quartzite"
    },
    {
      "x": -4,
      "y": 11,
      "z": 4,
      "name": "Rock_Quartzite"
    },
    {
      "x": -4,
      "y": 12,
      "z": 4,
      "name": "Soil_Grass"
    },
    {
      "x": -4,
      "y": 0,
      "z": 5,
      "name": "Rock_Quartzite"
    },
    {
      "x": -4,
      "y": 1,
      "z": 5,
      "name": "Rock_Quartzite"
    },
    {
      "x": -4,
      "y": 2,
      "z": 5,
      "name": "Rock_Quartzite"
    },
    {
      "x": -4,
      "y": 3,
      "z": 5,
      "name": "Rock_Quartzite"
    },
    {
      "x": -4,
      "y": 4,
      "z": 5,
      "name": "Rock_Quartzite"
    },
    {
      "x": -4,
      "y": 5,
      "z": 5,
      "name": "Rock_Quartzite"
    },
    {
      "x": -4,
      "y": 6,
      "z": 5,
      "name": "Rock_Quartzite"
    },
    {
      "x": -4,
      "y": 7,
      "z": 5,
      "name": "Rock_Quartzite_Brick"
    },
    {
      "x": -4,
      "y": 8,
      "z": 5,
      "name": "Rock_Quartzite"
    },
    {
      "x": -4,
      "y": 9,
      "z": 5,
      "name": "Rock_Quartzite"
    },
    {
      "x": -4,
      "y": 10,
      "z": 5,
      "name": "Rock_Quartzite"
    },
    {
      "x": -4,
      "y": 11,
      "z": 5,
      "name": "Rock_Quartzite"
    },
    {
      "x": -4,
      "y": 12,
      "z": 5,
      "name": "Soil_Grass"
    },
    {
      "x": -4,
      "y": 0,
      "z": 6,
      "name": "Rock_Quartzite"
    },
    {
      "x": -4,
      "y": 1,
      "z": 6,
      "name": "Rock_Quartzite"
    },
    {
      "x": -4,
      "y": 2,
      "z": 6,
      "name": "Rock_Quartzite"
    },
    {
      "x": -4,
      "y": 3,
      "z": 6,
      "name": "Rock_Quartzite"
    },
    {
      "x": -4,
      "y": 4,
      "z": 6,
      "name": "Rock_Quartzite"
    },
    {
      "x": -4,
      "y": 5,
      "z": 6,
      "name": "Rock_Quartzite"
    },
    {
      "x": -4,
      "y": 6,
      "z": 6,
      "name": "Rock_Quartzite"
    },
    {
      "x": -4,
      "y": 7,
      "z": 6,
      "name": "Rock_Quartzite_Cobble"
    },
    {
      "x": -4,
      "y": 8,
      "z": 6,
      "name": "Rock_Quartzite_Cobble"
    },
    {
      "x": -4,
      "y": 9,
      "z": 6,
      "name": "Rock_Quartzite"
    },
    {
      "x": -4,
      "y": 10,
      "z": 6,
      "name": "Rock_Quartzite"
    },
    {
      "x": -4,
      "y": 11,
      "z": 6,
      "name": "Rock_Quartzite"
    },
    {
      "x": -4,
      "y": 12,
      "z": 6,
      "name": "Soil_Grass"
    },
    {
      "x": -4,
      "y": 13,
      "z": 6,
      "name": "Plant_Grass_Lush_Short"
    },
    {
      "x": -4,
      "y": 0,
      "z": 7,
      "name": "Rock_Quartzite"
    },
    {
      "x": -4,
      "y": 1,
      "z": 7,
      "name": "Rock_Quartzite"
    },
    {
      "x": -4,
      "y": 2,
      "z": 7,
      "name": "Rock_Quartzite"
    },
    {
      "x": -4,
      "y": 3,
      "z": 7,
      "name": "Rock_Quartzite"
    },
    {
      "x": -4,
      "y": 4,
      "z": 7,
      "name": "Rock_Quartzite"
    },
    {
      "x": -4,
      "y": 5,
      "z": 7,
      "name": "Rock_Quartzite"
    },
    {
      "x": -4,
      "y": 6,
      "z": 7,
      "name": "Rock_Quartzite"
    },
    {
      "x": -4,
      "y": 7,
      "z": 7,
      "name": "Rock_Quartzite_Cobble"
    },
    {
      "x": -4,
      "y": 8,
      "z": 7,
      "name": "Rock_Quartzite_Cobble"
    },
    {
      "x": -4,
      "y": 9,
      "z": 7,
      "name": "Rock_Quartzite_Cobble"
    },
    {
      "x": -4,
      "y": 10,
      "z": 7,
      "name": "Rock_Quartzite"
    },
    {
      "x": -4,
      "y": 11,
      "z": 7,
      "name": "Rock_Quartzite"
    },
    {
      "x": -4,
      "y": 12,
      "z": 7,
      "name": "Soil_Grass"
    },
    {
      "x": -4,
      "y": 1,
      "z": 8,
      "name": "Rock_Quartzite"
    },
    {
      "x": -4,
      "y": 2,
      "z": 8,
      "name": "Rock_Quartzite"
    },
    {
      "x": -4,
      "y": 3,
      "z": 8,
      "name": "Rock_Quartzite"
    },
    {
      "x": -4,
      "y": 4,
      "z": 8,
      "name": "Rock_Quartzite"
    },
    {
      "x": -4,
      "y": 5,
      "z": 8,
      "name": "Rock_Quartzite"
    },
    {
      "x": -4,
      "y": 6,
      "z": 8,
      "name": "Rock_Quartzite"
    },
    {
      "x": -4,
      "y": 7,
      "z": 8,
      "name": "Rock_Quartzite_Brick"
    },
    {
      "x": -4,
      "y": 8,
      "z": 8,
      "name": "Rock_Quartzite"
    },
    {
      "x": -4,
      "y": 9,
      "z": 8,
      "name": "Rock_Quartzite"
    },
    {
      "x": -4,
      "y": 10,
      "z": 8,
      "name": "Rock_Quartzite"
    },
    {
      "x": -4,
      "y": 11,
      "z": 8,
      "name": "Rock_Quartzite"
    },
    {
      "x": -4,
      "y": 12,
      "z": 8,
      "name": "Soil_Grass"
    },
    {
      "x": -4,
      "y": 13,
      "z": 8,
      "name": "Plant_Fern_Winter"
    },
    {
      "x": -4,
      "y": 3,
      "z": 9,
      "name": "Rock_Quartzite"
    },
    {
      "x": -4,
      "y": 4,
      "z": 9,
      "name": "Rock_Quartzite"
    },
    {
      "x": -4,
      "y": 5,
      "z": 9,
      "name": "Rock_Quartzite"
    },
    {
      "x": -4,
      "y": 6,
      "z": 9,
      "name": "Rock_Quartzite"
    },
    {
      "x": -4,
      "y": 7,
      "z": 9,
      "name": "Rock_Quartzite_Brick"
    },
    {
      "x": -4,
      "y": 8,
      "z": 9,
      "name": "Rock_Quartzite_Brick_Half",
      "rotation": 4
    },
    {
      "x": -4,
      "y": 9,
      "z": 9,
      "name": "Rock_Quartzite_Brick_Half",
      "rotation": 4
    },
    {
      "x": -4,
      "y": 12,
      "z": 9,
      "name": "Plant_Vine"
    },
    {
      "x": -3,
      "y": 0,
      "z": -9,
      "name": "Rock_Quartzite"
    },
    {
      "x": -3,
      "y": 1,
      "z": -9,
      "name": "Rock_Quartzite"
    },
    {
      "x": -3,
      "y": 2,
      "z": -9,
      "name": "Rock_Quartzite"
    },
    {
      "x": -3,
      "y": 3,
      "z": -9,
      "name": "Rock_Quartzite"
    },
    {
      "x": -3,
      "y": 4,
      "z": -9,
      "name": "Rock_Quartzite"
    },
    {
      "x": -3,
      "y": 5,
      "z": -9,
      "name": "Rock_Quartzite"
    },
    {
      "x": -3,
      "y": 6,
      "z": -9,
      "name": "Rock_Quartzite"
    },
    {
      "x": -3,
      "y": 0,
      "z": -8,
      "name": "Rock_Quartzite"
    },
    {
      "x": -3,
      "y": 1,
      "z": -8,
      "name": "Rock_Quartzite"
    },
    {
      "x": -3,
      "y": 2,
      "z": -8,
      "name": "Rock_Quartzite"
    },
    {
      "x": -3,
      "y": 3,
      "z": -8,
      "name": "Rock_Quartzite"
    },
    {
      "x": -3,
      "y": 4,
      "z": -8,
      "name": "Rock_Quartzite"
    },
    {
      "x": -3,
      "y": 5,
      "z": -8,
      "name": "Rock_Quartzite"
    },
    {
      "x": -3,
      "y": 6,
      "z": -8,
      "name": "Rock_Quartzite"
    },
    {
      "x": -3,
      "y": 7,
      "z": -8,
      "name": "Rock_Quartzite_Brick_Stairs",
      "rotation": 2
    },
    {
      "x": -3,
      "y": 0,
      "z": -7,
      "name": "Rock_Quartzite"
    },
    {
      "x": -3,
      "y": 1,
      "z": -7,
      "name": "Rock_Quartzite"
    },
    {
      "x": -3,
      "y": 2,
      "z": -7,
      "name": "Rock_Quartzite"
    },
    {
      "x": -3,
      "y": 3,
      "z": -7,
      "name": "Rock_Quartzite"
    },
    {
      "x": -3,
      "y": 4,
      "z": -7,
      "name": "Rock_Quartzite"
    },
    {
      "x": -3,
      "y": 5,
      "z": -7,
      "name": "Rock_Quartzite"
    },
    {
      "x": -3,
      "y": 6,
      "z": -7,
      "name": "Rock_Quartzite"
    },
    {
      "x": -3,
      "y": 7,
      "z": -7,
      "name": "Rock_Quartzite_Brick"
    },
    {
      "x": -3,
      "y": 8,
      "z": -7,
      "name": "Rock_Quartzite_Brick_Stairs",
      "rotation": 2
    },
    {
      "x": -3,
      "y": 0,
      "z": -6,
      "name": "Rock_Quartzite"
    },
    {
      "x": -3,
      "y": 1,
      "z": -6,
      "name": "Rock_Quartzite"
    },
    {
      "x": -3,
      "y": 2,
      "z": -6,
      "name": "Rock_Quartzite"
    },
    {
      "x": -3,
      "y": 3,
      "z": -6,
      "name": "Rock_Quartzite"
    },
    {
      "x": -3,
      "y": 4,
      "z": -6,
      "name": "Rock_Quartzite"
    },
    {
      "x": -3,
      "y": 5,
      "z": -6,
      "name": "Rock_Quartzite"
    },
    {
      "x": -3,
      "y": 6,
      "z": -6,
      "name": "Rock_Quartzite_Cobble"
    },
    {
      "x": -3,
      "y": 8,
      "z": -6,
      "name": "Rock_Quartzite_Brick"
    },
    {
      "x": -3,
      "y": 9,
      "z": -6,
      "name": "Rock_Quartzite_Brick_Stairs",
      "rotation": 2
    },
    {
      "x": -3,
      "y": 0,
      "z": -5,
      "name": "Rock_Quartzite"
    },
    {
      "x": -3,
      "y": 1,
      "z": -5,
      "name": "Rock_Quartzite"
    },
    {
      "x": -3,
      "y": 2,
      "z": -5,
      "name": "Rock_Quartzite"
    },
    {
      "x": -3,
      "y": 3,
      "z": -5,
      "name": "Rock_Quartzite"
    },
    {
      "x": -3,
      "y": 4,
      "z": -5,
      "name": "Rock_Quartzite"
    },
    {
      "x": -3,
      "y": 5,
      "z": -5,
      "name": "Rock_Quartzite"
    },
    {
      "x": -3,
      "y": 6,
      "z": -5,
      "name": "Rock_Quartzite"
    },
    {
      "x": -3,
      "y": 9,
      "z": -5,
      "name": "Rock_Quartzite_Brick_Half",
      "rotation": 8
    },
    {
      "x": -3,
      "y": 0,
      "z": -4,
      "name": "Rock_Quartzite"
    },
    {
      "x": -3,
      "y": 1,
      "z": -4,
      "name": "Rock_Quartzite"
    },
    {
      "x": -3,
      "y": 2,
      "z": -4,
      "name": "Rock_Quartzite"
    },
    {
      "x": -3,
      "y": 3,
      "z": -4,
      "name": "Rock_Quartzite"
    },
    {
      "x": -3,
      "y": 4,
      "z": -4,
      "name": "Rock_Quartzite"
    },
    {
      "x": -3,
      "y": 5,
      "z": -4,
      "name": "Rock_Quartzite"
    },
    {
      "x": -3,
      "y": 6,
      "z": -4,
      "name": "Rock_Quartzite"
    },
    {
      "x": -3,
      "y": 11,
      "z": -4,
      "name": "Rock_Quartzite_Brick_Stairs",
      "rotation": 2
    },
    {
      "x": -3,
      "y": 0,
      "z": -3,
      "name": "Rock_Quartzite"
    },
    {
      "x": -3,
      "y": 1,
      "z": -3,
      "name": "Rock_Quartzite"
    },
    {
      "x": -3,
      "y": 2,
      "z": -3,
      "name": "Rock_Quartzite"
    },
    {
      "x": -3,
      "y": 3,
      "z": -3,
      "name": "Rock_Quartzite"
    },
    {
      "x": -3,
      "y": 4,
      "z": -3,
      "name": "Rock_Quartzite"
    },
    {
      "x": -3,
      "y": 5,
      "z": -3,
      "name": "Rock_Quartzite"
    },
    {
      "x": -3,
      "y": 6,
      "z": -3,
      "name": "Rock_Quartzite"
    },
    {
      "x": -3,
      "y": 7,
      "z": -3,
      "name": "Rock_Quartzite_Brick"
    },
    {
      "x": -3,
      "y": 8,
      "z": -3,
      "name": "Rock_Quartzite_Cobble"
    },
    {
      "x": -3,
      "y": 9,
      "z": -3,
      "name": "Rock_Quartzite_Cobble_Stairs",
      "rotation": 2
    },
    {
      "x": -3,
      "y": 11,
      "z": -3,
      "name": "Rock_Quartzite_Brick_Half",
      "rotation": 8
    },
    {
      "x": -3,
      "y": 0,
      "z": -2,
      "name": "Rock_Quartzite"
    },
    {
      "x": -3,
      "y": 1,
      "z": -2,
      "name": "Rock_Quartzite"
    },
    {
      "x": -3,
      "y": 2,
      "z": -2,
      "name": "Rock_Quartzite"
    },
    {
      "x": -3,
      "y": 3,
      "z": -2,
      "name": "Rock_Quartzite"
    },
    {
      "x": -3,
      "y": 4,
      "z": -2,
      "name": "Rock_Quartzite"
    },
    {
      "x": -3,
      "y": 5,
      "z": -2,
      "name": "Rock_Quartzite"
    },
    {
      "x": -3,
      "y": 6,
      "z": -2,
      "name": "Rock_Quartzite"
    },
    {
      "x": -3,
      "y": 7,
      "z": -2,
      "name": "Rock_Quartzite"
    },
    {
      "x": -3,
      "y": 8,
      "z": -2,
      "name": "Rock_Quartzite"
    },
    {
      "x": -3,
      "y": 9,
      "z": -2,
      "name": "Rock_Quartzite"
    },
    {
      "x": -3,
      "y": 10,
      "z": -2,
      "name": "Soil_Dirt"
    },
    {
      "x": -3,
      "y": 11,
      "z": -2,
      "name": "Soil_Grass"
    },
    {
      "x": -3,
      "y": 12,
      "z": -2,
      "name": "Plant_Grass_Sharp"
    },
    {
      "x": -3,
      "y": 1,
      "z": -1,
      "name": "Rock_Quartzite"
    },
    {
      "x": -3,
      "y": 2,
      "z": -1,
      "name": "Rock_Quartzite"
    },
    {
      "x": -3,
      "y": 3,
      "z": -1,
      "name": "Rock_Quartzite"
    },
    {
      "x": -3,
      "y": 4,
      "z": -1,
      "name": "Rock_Quartzite"
    },
    {
      "x": -3,
      "y": 5,
      "z": -1,
      "name": "Rock_Quartzite"
    },
    {
      "x": -3,
      "y": 6,
      "z": -1,
      "name": "Rock_Quartzite"
    },
    {
      "x": -3,
      "y": 7,
      "z": -1,
      "name": "Rock_Quartzite"
    },
    {
      "x": -3,
      "y": 8,
      "z": -1,
      "name": "Rock_Quartzite"
    },
    {
      "x": -3,
      "y": 9,
      "z": -1,
      "name": "Soil_Dirt"
    },
    {
      "x": -3,
      "y": 10,
      "z": -1,
      "name": "Soil_Grass"
    },
    {
      "x": -3,
      "y": 11,
      "z": -1,
      "name": "Plant_Fern_Winter"
    },
    {
      "x": -3,
      "y": 0,
      "z": 0,
      "name": "Rock_Quartzite"
    },
    {
      "x": -3,
      "y": 1,
      "z": 0,
      "name": "Rock_Quartzite"
    },
    {
      "x": -3,
      "y": 2,
      "z": 0,
      "name": "Rock_Quartzite"
    },
    {
      "x": -3,
      "y": 3,
      "z": 0,
      "name": "Rock_Quartzite"
    },
    {
      "x": -3,
      "y": 4,
      "z": 0,
      "name": "Rock_Quartzite"
    },
    {
      "x": -3,
      "y": 5,
      "z": 0,
      "name": "Rock_Quartzite"
    },
    {
      "x": -3,
      "y": 6,
      "z": 0,
      "name": "Rock_Quartzite"
    },
    {
      "x": -3,
      "y": 7,
      "z": 0,
      "name": "Rock_Quartzite"
    },
    {
      "x": -3,
      "y": 8,
      "z": 0,
      "name": "Rock_Quartzite"
    },
    {
      "x": -3,
      "y": 0,
      "z": 1,
      "name": "Rock_Quartzite"
    },
    {
      "x": -3,
      "y": 1,
      "z": 1,
      "name": "Rock_Quartzite"
    },
    {
      "x": -3,
      "y": 2,
      "z": 1,
      "name": "Rock_Quartzite"
    },
    {
      "x": -3,
      "y": 3,
      "z": 1,
      "name": "Rock_Quartzite"
    },
    {
      "x": -3,
      "y": 4,
      "z": 1,
      "name": "Rock_Quartzite"
    },
    {
      "x": -3,
      "y": 5,
      "z": 1,
      "name": "Rock_Quartzite"
    },
    {
      "x": -3,
      "y": 6,
      "z": 1,
      "name": "Rock_Quartzite"
    },
    {
      "x": -3,
      "y": 7,
      "z": 1,
      "name": "Rock_Quartzite"
    },
    {
      "x": -3,
      "y": 8,
      "z": 1,
      "name": "Rock_Quartzite"
    },
    {
      "x": -3,
      "y": 9,
      "z": 1,
      "name": "Rock_Quartzite_Cobble"
    },
    {
      "x": -3,
      "y": 10,
      "z": 1,
      "name": "Rock_Quartzite_Cobble_Half",
      "rotation": 6
    },
    {
      "x": -3,
      "y": 0,
      "z": 2,
      "name": "Rock_Quartzite"
    },
    {
      "x": -3,
      "y": 1,
      "z": 2,
      "name": "Rock_Quartzite"
    },
    {
      "x": -3,
      "y": 2,
      "z": 2,
      "name": "Rock_Quartzite"
    },
    {
      "x": -3,
      "y": 3,
      "z": 2,
      "name": "Rock_Quartzite"
    },
    {
      "x": -3,
      "y": 4,
      "z": 2,
      "name": "Rock_Quartzite"
    },
    {
      "x": -3,
      "y": 5,
      "z": 2,
      "name": "Rock_Quartzite"
    },
    {
      "x": -3,
      "y": 6,
      "z": 2,
      "name": "Rock_Quartzite"
    },
    {
      "x": -3,
      "y": 7,
      "z": 2,
      "name": "Rock_Quartzite"
    },
    {
      "x": -3,
      "y": 8,
      "z": 2,
      "name": "Rock_Quartzite"
    },
    {
      "x": -3,
      "y": 9,
      "z": 2,
      "name": "Rock_Quartzite"
    },
    {
      "x": -3,
      "y": 10,
      "z": 2,
      "name": "Soil_Dirt"
    },
    {
      "x": -3,
      "y": 11,
      "z": 2,
      "name": "Soil_Grass"
    },
    {
      "x": -3,
      "y": 12,
      "z": 2,
      "name": "Plant_Grass_Lush"
    },
    {
      "x": -3,
      "y": 0,
      "z": 3,
      "name": "Rock_Quartzite"
    },
    {
      "x": -3,
      "y": 1,
      "z": 3,
      "name": "Rock_Quartzite"
    },
    {
      "x": -3,
      "y": 2,
      "z": 3,
      "name": "Rock_Quartzite"
    },
    {
      "x": -3,
      "y": 3,
      "z": 3,
      "name": "Rock_Quartzite"
    },
    {
      "x": -3,
      "y": 4,
      "z": 3,
      "name": "Rock_Quartzite"
    },
    {
      "x": -3,
      "y": 5,
      "z": 3,
      "name": "Rock_Quartzite"
    },
    {
      "x": -3,
      "y": 6,
      "z": 3,
      "name": "Rock_Quartzite"
    },
    {
      "x": -3,
      "y": 7,
      "z": 3,
      "name": "Rock_Quartzite"
    },
    {
      "x": -3,
      "y": 8,
      "z": 3,
      "name": "Rock_Quartzite"
    },
    {
      "x": -3,
      "y": 9,
      "z": 3,
      "name": "Rock_Quartzite"
    },
    {
      "x": -3,
      "y": 10,
      "z": 3,
      "name": "Rock_Quartzite"
    },
    {
      "x": -3,
      "y": 11,
      "z": 3,
      "name": "Rock_Quartzite"
    },
    {
      "x": -3,
      "y": 12,
      "z": 3,
      "name": "Soil_Grass"
    },
    {
      "x": -3,
      "y": 13,
      "z": 3,
      "name": "Plant_Grass_Lush_Short"
    },
    {
      "x": -3,
      "y": 0,
      "z": 4,
      "name": "Rock_Quartzite"
    },
    {
      "x": -3,
      "y": 1,
      "z": 4,
      "name": "Rock_Quartzite"
    },
    {
      "x": -3,
      "y": 2,
      "z": 4,
      "name": "Rock_Quartzite"
    },
    {
      "x": -3,
      "y": 3,
      "z": 4,
      "name": "Rock_Quartzite"
    },
    {
      "x": -3,
      "y": 4,
      "z": 4,
      "name": "Rock_Quartzite"
    },
    {
      "x": -3,
      "y": 5,
      "z": 4,
      "name": "Rock_Quartzite"
    },
    {
      "x": -3,
      "y": 6,
      "z": 4,
      "name": "Rock_Quartzite"
    },
    {
      "x": -3,
      "y": 7,
      "z": 4,
      "name": "Rock_Quartzite"
    },
    {
      "x": -3,
      "y": 8,
      "z": 4,
      "name": "Rock_Quartzite"
    },
    {
      "x": -3,
      "y": 9,
      "z": 4,
      "name": "Rock_Quartzite"
    },
    {
      "x": -3,
      "y": 10,
      "z": 4,
      "name": "Rock_Quartzite"
    },
    {
      "x": -3,
      "y": 11,
      "z": 4,
      "name": "Rock_Quartzite"
    },
    {
      "x": -3,
      "y": 12,
      "z": 4,
      "name": "Soil_Grass"
    },
    {
      "x": -3,
      "y": 13,
      "z": 4,
      "name": "Plant_Grass_Sharp"
    },
    {
      "x": -3,
      "y": 0,
      "z": 5,
      "name": "Rock_Quartzite"
    },
    {
      "x": -3,
      "y": 1,
      "z": 5,
      "name": "Rock_Quartzite"
    },
    {
      "x": -3,
      "y": 2,
      "z": 5,
      "name": "Rock_Quartzite"
    },
    {
      "x": -3,
      "y": 3,
      "z": 5,
      "name": "Rock_Quartzite"
    },
    {
      "x": -3,
      "y": 4,
      "z": 5,
      "name": "Rock_Quartzite"
    },
    {
      "x": -3,
      "y": 5,
      "z": 5,
      "name": "Rock_Quartzite"
    },
    {
      "x": -3,
      "y": 6,
      "z": 5,
      "name": "Rock_Quartzite"
    },
    {
      "x": -3,
      "y": 7,
      "z": 5,
      "name": "Rock_Quartzite"
    },
    {
      "x": -3,
      "y": 8,
      "z": 5,
      "name": "Rock_Quartzite"
    },
    {
      "x": -3,
      "y": 9,
      "z": 5,
      "name": "Rock_Quartzite"
    },
    {
      "x": -3,
      "y": 10,
      "z": 5,
      "name": "Rock_Quartzite"
    },
    {
      "x": -3,
      "y": 11,
      "z": 5,
      "name": "Rock_Quartzite"
    },
    {
      "x": -3,
      "y": 12,
      "z": 5,
      "name": "Soil_Grass"
    },
    {
      "x": -3,
      "y": 0,
      "z": 6,
      "name": "Rock_Quartzite"
    },
    {
      "x": -3,
      "y": 1,
      "z": 6,
      "name": "Rock_Quartzite"
    },
    {
      "x": -3,
      "y": 2,
      "z": 6,
      "name": "Rock_Quartzite"
    },
    {
      "x": -3,
      "y": 3,
      "z": 6,
      "name": "Rock_Quartzite"
    },
    {
      "x": -3,
      "y": 4,
      "z": 6,
      "name": "Rock_Quartzite"
    },
    {
      "x": -3,
      "y": 5,
      "z": 6,
      "name": "Rock_Quartzite"
    },
    {
      "x": -3,
      "y": 6,
      "z": 6,
      "name": "Rock_Quartzite"
    },
    {
      "x": -3,
      "y": 7,
      "z": 6,
      "name": "Rock_Quartzite"
    },
    {
      "x": -3,
      "y": 8,
      "z": 6,
      "name": "Rock_Quartzite"
    },
    {
      "x": -3,
      "y": 9,
      "z": 6,
      "name": "Rock_Quartzite"
    },
    {
      "x": -3,
      "y": 10,
      "z": 6,
      "name": "Rock_Quartzite"
    },
    {
      "x": -3,
      "y": 11,
      "z": 6,
      "name": "Rock_Quartzite"
    },
    {
      "x": -3,
      "y": 12,
      "z": 6,
      "name": "Soil_Grass"
    },
    {
      "x": -3,
      "y": 13,
      "z": 6,
      "name": "Plant_Grass_Lush_Short"
    },
    {
      "x": -3,
      "y": 0,
      "z": 7,
      "name": "Rock_Quartzite"
    },
    {
      "x": -3,
      "y": 1,
      "z": 7,
      "name": "Rock_Quartzite"
    },
    {
      "x": -3,
      "y": 2,
      "z": 7,
      "name": "Rock_Quartzite"
    },
    {
      "x": -3,
      "y": 3,
      "z": 7,
      "name": "Rock_Quartzite"
    },
    {
      "x": -3,
      "y": 4,
      "z": 7,
      "name": "Rock_Quartzite"
    },
    {
      "x": -3,
      "y": 5,
      "z": 7,
      "name": "Rock_Quartzite"
    },
    {
      "x": -3,
      "y": 6,
      "z": 7,
      "name": "Rock_Quartzite"
    },
    {
      "x": -3,
      "y": 7,
      "z": 7,
      "name": "Rock_Quartzite"
    },
    {
      "x": -3,
      "y": 8,
      "z": 7,
      "name": "Rock_Quartzite"
    },
    {
      "x": -3,
      "y": 9,
      "z": 7,
      "name": "Rock_Quartzite"
    },
    {
      "x": -3,
      "y": 10,
      "z": 7,
      "name": "Rock_Quartzite"
    },
    {
      "x": -3,
      "y": 11,
      "z": 7,
      "name": "Rock_Quartzite"
    },
    {
      "x": -3,
      "y": 12,
      "z": 7,
      "name": "Soil_Grass"
    },
    {
      "x": -3,
      "y": 13,
      "z": 7,
      "name": "Plant_Grass_Lush_Short"
    },
    {
      "x": -3,
      "y": 0,
      "z": 8,
      "name": "Rock_Quartzite"
    },
    {
      "x": -3,
      "y": 1,
      "z": 8,
      "name": "Rock_Quartzite"
    },
    {
      "x": -3,
      "y": 2,
      "z": 8,
      "name": "Rock_Quartzite"
    },
    {
      "x": -3,
      "y": 3,
      "z": 8,
      "name": "Rock_Quartzite"
    },
    {
      "x": -3,
      "y": 4,
      "z": 8,
      "name": "Rock_Quartzite"
    },
    {
      "x": -3,
      "y": 5,
      "z": 8,
      "name": "Rock_Quartzite"
    },
    {
      "x": -3,
      "y": 6,
      "z": 8,
      "name": "Rock_Quartzite"
    },
    {
      "x": -3,
      "y": 7,
      "z": 8,
      "name": "Rock_Quartzite_Cobble"
    },
    {
      "x": -3,
      "y": 8,
      "z": 8,
      "name": "Rock_Quartzite_Cobble"
    },
    {
      "x": -3,
      "y": 9,
      "z": 8,
      "name": "Rock_Quartzite_Cobble"
    },
    {
      "x": -3,
      "y": 10,
      "z": 8,
      "name": "Rock_Quartzite_Cobble"
    },
    {
      "x": -3,
      "y": 11,
      "z": 8,
      "name": "Rock_Quartzite_Cobble_Stairs",
      "rotation": 10
    },
    {
      "x": -3,
      "y": 12,
      "z": 8,
      "name": "Soil_Grass"
    },
    {
      "x": -3,
      "y": 13,
      "z": 8,
      "name": "Plant_Moss_Rug_Green"
    },
    {
      "x": -3,
      "y": 3,
      "z": 9,
      "name": "Rock_Quartzite"
    },
    {
      "x": -3,
      "y": 4,
      "z": 9,
      "name": "Rock_Quartzite"
    },
    {
      "x": -3,
      "y": 5,
      "z": 9,
      "name": "Rock_Quartzite_Cobble"
    },
    {
      "x": -3,
      "y": 6,
      "z": 9,
      "name": "Rock_Quartzite_Cobble"
    },
    {
      "x": -3,
      "y": 10,
      "z": 9,
      "name": "Plant_Vine_Wall"
    },
    {
      "x": -3,
      "y": 11,
      "z": 9,
      "name": "Plant_Vine"
    },
    {
      "x": -3,
      "y": 12,
      "z": 9,
      "name": "Plant_Vine"
    },
    {
      "x": -2,
      "y": 0,
      "z": -9,
      "name": "Rock_Quartzite"
    },
    {
      "x": -2,
      "y": 1,
      "z": -9,
      "name": "Rock_Quartzite"
    },
    {
      "x": -2,
      "y": 2,
      "z": -9,
      "name": "Rock_Quartzite"
    },
    {
      "x": -2,
      "y": 3,
      "z": -9,
      "name": "Rock_Quartzite"
    },
    {
      "x": -2,
      "y": 4,
      "z": -9,
      "name": "Rock_Quartzite"
    },
    {
      "x": -2,
      "y": 5,
      "z": -9,
      "name": "Rock_Quartzite"
    },
    {
      "x": -2,
      "y": 6,
      "z": -9,
      "name": "Rock_Quartzite"
    },
    {
      "x": -2,
      "y": 0,
      "z": -8,
      "name": "Rock_Quartzite"
    },
    {
      "x": -2,
      "y": 1,
      "z": -8,
      "name": "Rock_Quartzite"
    },
    {
      "x": -2,
      "y": 2,
      "z": -8,
      "name": "Rock_Quartzite"
    },
    {
      "x": -2,
      "y": 3,
      "z": -8,
      "name": "Rock_Quartzite"
    },
    {
      "x": -2,
      "y": 4,
      "z": -8,
      "name": "Rock_Quartzite"
    },
    {
      "x": -2,
      "y": 5,
      "z": -8,
      "name": "Rock_Quartzite"
    },
    {
      "x": -2,
      "y": 6,
      "z": -8,
      "name": "Rock_Quartzite"
    },
    {
      "x": -2,
      "y": 7,
      "z": -8,
      "name": "Rock_Quartzite_Brick_Stairs",
      "rotation": 2
    },
    {
      "x": -2,
      "y": 0,
      "z": -7,
      "name": "Rock_Quartzite"
    },
    {
      "x": -2,
      "y": 1,
      "z": -7,
      "name": "Rock_Quartzite"
    },
    {
      "x": -2,
      "y": 2,
      "z": -7,
      "name": "Rock_Quartzite"
    },
    {
      "x": -2,
      "y": 3,
      "z": -7,
      "name": "Rock_Quartzite"
    },
    {
      "x": -2,
      "y": 4,
      "z": -7,
      "name": "Rock_Quartzite"
    },
    {
      "x": -2,
      "y": 5,
      "z": -7,
      "name": "Rock_Quartzite"
    },
    {
      "x": -2,
      "y": 6,
      "z": -7,
      "name": "Rock_Quartzite"
    },
    {
      "x": -2,
      "y": 7,
      "z": -7,
      "name": "Rock_Quartzite_Brick"
    },
    {
      "x": -2,
      "y": 0,
      "z": -6,
      "name": "Rock_Quartzite"
    },
    {
      "x": -2,
      "y": 1,
      "z": -6,
      "name": "Rock_Quartzite"
    },
    {
      "x": -2,
      "y": 2,
      "z": -6,
      "name": "Rock_Quartzite"
    },
    {
      "x": -2,
      "y": 3,
      "z": -6,
      "name": "Rock_Quartzite"
    },
    {
      "x": -2,
      "y": 4,
      "z": -6,
      "name": "Rock_Quartzite"
    },
    {
      "x": -2,
      "y": 5,
      "z": -6,
      "name": "Rock_Quartzite"
    },
    {
      "x": -2,
      "y": 6,
      "z": -6,
      "name": "Rock_Quartzite_Cobble"
    },
    {
      "x": -2,
      "y": 8,
      "z": -6,
      "name": "Rock_Quartzite_Brick_Half",
      "rotation": 5
    },
    {
      "x": -2,
      "y": 0,
      "z": -5,
      "name": "Rock_Quartzite"
    },
    {
      "x": -2,
      "y": 1,
      "z": -5,
      "name": "Rock_Quartzite"
    },
    {
      "x": -2,
      "y": 2,
      "z": -5,
      "name": "Rock_Quartzite"
    },
    {
      "x": -2,
      "y": 3,
      "z": -5,
      "name": "Rock_Quartzite"
    },
    {
      "x": -2,
      "y": 4,
      "z": -5,
      "name": "Rock_Quartzite"
    },
    {
      "x": -2,
      "y": 5,
      "z": -5,
      "name": "Rock_Quartzite"
    },
    {
      "x": -2,
      "y": 6,
      "z": -5,
      "name": "Rock_Quartzite"
    },
    {
      "x": -2,
      "y": 0,
      "z": -4,
      "name": "Rock_Quartzite"
    },
    {
      "x": -2,
      "y": 1,
      "z": -4,
      "name": "Rock_Quartzite"
    },
    {
      "x": -2,
      "y": 2,
      "z": -4,
      "name": "Rock_Quartzite"
    },
    {
      "x": -2,
      "y": 3,
      "z": -4,
      "name": "Rock_Quartzite"
    },
    {
      "x": -2,
      "y": 4,
      "z": -4,
      "name": "Rock_Quartzite"
    },
    {
      "x": -2,
      "y": 5,
      "z": -4,
      "name": "Rock_Quartzite"
    },
    {
      "x": -2,
      "y": 6,
      "z": -4,
      "name": "Rock_Quartzite"
    },
    {
      "x": -2,
      "y": 7,
      "z": -4,
      "name": "Rock_Quartzite_Brick"
    },
    {
      "x": -2,
      "y": 8,
      "z": -4,
      "name": "Rock_Quartzite"
    },
    {
      "x": -2,
      "y": 9,
      "z": -4,
      "name": "Rock_Quartzite"
    },
    {
      "x": -2,
      "y": 10,
      "z": -4,
      "name": "Soil_Grass"
    },
    {
      "x": -2,
      "y": 11,
      "z": -4,
      "name": "Plant_Grass_Lush"
    },
    {
      "x": -2,
      "y": 0,
      "z": -3,
      "name": "Rock_Quartzite"
    },
    {
      "x": -2,
      "y": 1,
      "z": -3,
      "name": "Rock_Quartzite"
    },
    {
      "x": -2,
      "y": 2,
      "z": -3,
      "name": "Rock_Quartzite"
    },
    {
      "x": -2,
      "y": 3,
      "z": -3,
      "name": "Rock_Quartzite"
    },
    {
      "x": -2,
      "y": 4,
      "z": -3,
      "name": "Rock_Quartzite"
    },
    {
      "x": -2,
      "y": 5,
      "z": -3,
      "name": "Rock_Quartzite"
    },
    {
      "x": -2,
      "y": 6,
      "z": -3,
      "name": "Rock_Quartzite"
    },
    {
      "x": -2,
      "y": 7,
      "z": -3,
      "name": "Rock_Quartzite_Brick"
    },
    {
      "x": -2,
      "y": 8,
      "z": -3,
      "name": "Rock_Quartzite"
    },
    {
      "x": -2,
      "y": 9,
      "z": -3,
      "name": "Soil_Dirt"
    },
    {
      "x": -2,
      "y": 10,
      "z": -3,
      "name": "Soil_Grass"
    },
    {
      "x": -2,
      "y": 11,
      "z": -3,
      "name": "Plant_Moss_Rug_Green"
    },
    {
      "x": -2,
      "y": 0,
      "z": -2,
      "name": "Rock_Quartzite"
    },
    {
      "x": -2,
      "y": 1,
      "z": -2,
      "name": "Rock_Quartzite"
    },
    {
      "x": -2,
      "y": 2,
      "z": -2,
      "name": "Rock_Quartzite"
    },
    {
      "x": -2,
      "y": 3,
      "z": -2,
      "name": "Rock_Quartzite"
    },
    {
      "x": -2,
      "y": 4,
      "z": -2,
      "name": "Rock_Quartzite"
    },
    {
      "x": -2,
      "y": 5,
      "z": -2,
      "name": "Rock_Quartzite"
    },
    {
      "x": -2,
      "y": 6,
      "z": -2,
      "name": "Rock_Quartzite"
    },
    {
      "x": -2,
      "y": 7,
      "z": -2,
      "name": "Rock_Quartzite_Cobble"
    },
    {
      "x": -2,
      "y": 8,
      "z": -2,
      "name": "Rock_Quartzite_Cobble"
    },
    {
      "x": -2,
      "y": 9,
      "z": -2,
      "name": "Rock_Quartzite_Cobble"
    },
    {
      "x": -2,
      "y": 10,
      "z": -2,
      "name": "Rock_Quartzite_Cobble"
    },
    {
      "x": -2,
      "y": 11,
      "z": -2,
      "name": "Soil_Grass"
    },
    {
      "x": -2,
      "y": 2,
      "z": -1,
      "name": "Rock_Quartzite"
    },
    {
      "x": -2,
      "y": 3,
      "z": -1,
      "name": "Rock_Quartzite"
    },
    {
      "x": -2,
      "y": 4,
      "z": -1,
      "name": "Rock_Quartzite"
    },
    {
      "x": -2,
      "y": 5,
      "z": -1,
      "name": "Rock_Quartzite_Cobble"
    },
    {
      "x": -2,
      "y": 6,
      "z": -1,
      "name": "Rock_Quartzite_Cobble"
    },
    {
      "x": -2,
      "y": 7,
      "z": -1,
      "name": "Rock_Quartzite_Brick"
    },
    {
      "x": -2,
      "y": 8,
      "z": -1,
      "name": "Rock_Quartzite"
    },
    {
      "x": -2,
      "y": 9,
      "z": -1,
      "name": "Soil_Dirt"
    },
    {
      "x": -2,
      "y": 10,
      "z": -1,
      "name": "Soil_Grass"
    },
    {
      "x": -2,
      "y": 11,
      "z": -1,
      "name": "Plant_Fern_Winter"
    },
    {
      "x": -2,
      "y": 0,
      "z": 0,
      "name": "Rock_Quartzite"
    },
    {
      "x": -2,
      "y": 1,
      "z": 0,
      "name": "Rock_Quartzite"
    },
    {
      "x": -2,
      "y": 2,
      "z": 0,
      "name": "Rock_Quartzite"
    },
    {
      "x": -2,
      "y": 3,
      "z": 0,
      "name": "Rock_Quartzite"
    },
    {
      "x": -2,
      "y": 4,
      "z": 0,
      "name": "Rock_Quartzite"
    },
    {
      "x": -2,
      "y": 5,
      "z": 0,
      "name": "Rock_Quartzite"
    },
    {
      "x": -2,
      "y": 6,
      "z": 0,
      "name": "Rock_Quartzite"
    },
    {
      "x": -2,
      "y": 7,
      "z": 0,
      "name": "Rock_Quartzite_Brick"
    },
    {
      "x": -2,
      "y": 10,
      "z": 0,
      "name": "Rock_Quartzite_Cobble_Beam",
      "rotation": 4
    },
    {
      "x": -2,
      "y": 0,
      "z": 1,
      "name": "Rock_Quartzite"
    },
    {
      "x": -2,
      "y": 1,
      "z": 1,
      "name": "Rock_Quartzite"
    },
    {
      "x": -2,
      "y": 2,
      "z": 1,
      "name": "Rock_Quartzite"
    },
    {
      "x": -2,
      "y": 3,
      "z": 1,
      "name": "Rock_Quartzite"
    },
    {
      "x": -2,
      "y": 4,
      "z": 1,
      "name": "Rock_Quartzite"
    },
    {
      "x": -2,
      "y": 5,
      "z": 1,
      "name": "Rock_Quartzite"
    },
    {
      "x": -2,
      "y": 6,
      "z": 1,
      "name": "Rock_Quartzite"
    },
    {
      "x": -2,
      "y": 7,
      "z": 1,
      "name": "Rock_Quartzite_Brick"
    },
    {
      "x": -2,
      "y": 10,
      "z": 1,
      "name": "Rock_Quartzite_Cobble_Beam",
      "rotation": 4
    },
    {
      "x": -2,
      "y": 0,
      "z": 2,
      "name": "Rock_Quartzite"
    },
    {
      "x": -2,
      "y": 1,
      "z": 2,
      "name": "Rock_Quartzite"
    },
    {
      "x": -2,
      "y": 2,
      "z": 2,
      "name": "Rock_Quartzite"
    },
    {
      "x": -2,
      "y": 3,
      "z": 2,
      "name": "Rock_Quartzite"
    },
    {
      "x": -2,
      "y": 4,
      "z": 2,
      "name": "Rock_Quartzite"
    },
    {
      "x": -2,
      "y": 5,
      "z": 2,
      "name": "Rock_Quartzite"
    },
    {
      "x": -2,
      "y": 6,
      "z": 2,
      "name": "Rock_Quartzite"
    },
    {
      "x": -2,
      "y": 7,
      "z": 2,
      "name": "Rock_Quartzite_Brick"
    },
    {
      "x": -2,
      "y": 8,
      "z": 2,
      "name": "Rock_Quartzite"
    },
    {
      "x": -2,
      "y": 9,
      "z": 2,
      "name": "Rock_Quartzite"
    },
    {
      "x": -2,
      "y": 10,
      "z": 2,
      "name": "Rock_Quartzite_Cobble"
    },
    {
      "x": -2,
      "y": 0,
      "z": 3,
      "name": "Rock_Quartzite"
    },
    {
      "x": -2,
      "y": 1,
      "z": 3,
      "name": "Rock_Quartzite"
    },
    {
      "x": -2,
      "y": 2,
      "z": 3,
      "name": "Rock_Quartzite"
    },
    {
      "x": -2,
      "y": 3,
      "z": 3,
      "name": "Rock_Quartzite"
    },
    {
      "x": -2,
      "y": 4,
      "z": 3,
      "name": "Rock_Quartzite"
    },
    {
      "x": -2,
      "y": 5,
      "z": 3,
      "name": "Rock_Quartzite"
    },
    {
      "x": -2,
      "y": 6,
      "z": 3,
      "name": "Rock_Quartzite"
    },
    {
      "x": -2,
      "y": 7,
      "z": 3,
      "name": "Rock_Quartzite_Brick"
    },
    {
      "x": -2,
      "y": 8,
      "z": 3,
      "name": "Rock_Quartzite"
    },
    {
      "x": -2,
      "y": 9,
      "z": 3,
      "name": "Rock_Quartzite_Cobble_Stairs",
      "rotation": 11
    },
    {
      "x": -2,
      "y": 10,
      "z": 3,
      "name": "Rock_Quartzite_Cobble"
    },
    {
      "x": -2,
      "y": 11,
      "z": 3,
      "name": "Soil_Dirt"
    },
    {
      "x": -2,
      "y": 12,
      "z": 3,
      "name": "Soil_Grass"
    },
    {
      "x": -2,
      "y": 13,
      "z": 3,
      "name": "Plant_Grass_Lush"
    },
    {
      "x": -2,
      "y": 0,
      "z": 4,
      "name": "Rock_Quartzite"
    },
    {
      "x": -2,
      "y": 1,
      "z": 4,
      "name": "Rock_Quartzite"
    },
    {
      "x": -2,
      "y": 2,
      "z": 4,
      "name": "Rock_Quartzite"
    },
    {
      "x": -2,
      "y": 3,
      "z": 4,
      "name": "Rock_Quartzite"
    },
    {
      "x": -2,
      "y": 4,
      "z": 4,
      "name": "Rock_Quartzite"
    },
    {
      "x": -2,
      "y": 5,
      "z": 4,
      "name": "Rock_Quartzite"
    },
    {
      "x": -2,
      "y": 6,
      "z": 4,
      "name": "Rock_Quartzite"
    },
    {
      "x": -2,
      "y": 7,
      "z": 4,
      "name": "Rock_Quartzite_Brick"
    },
    {
      "x": -2,
      "y": 8,
      "z": 4,
      "name": "Rock_Quartzite"
    },
    {
      "x": -2,
      "y": 9,
      "z": 4,
      "name": "Rock_Quartzite_Cobble_Stairs",
      "rotation": 11
    },
    {
      "x": -2,
      "y": 10,
      "z": 4,
      "name": "Rock_Quartzite_Cobble"
    },
    {
      "x": -2,
      "y": 11,
      "z": 4,
      "name": "Soil_Dirt"
    },
    {
      "x": -2,
      "y": 12,
      "z": 4,
      "name": "Soil_Grass"
    },
    {
      "x": -2,
      "y": 0,
      "z": 5,
      "name": "Rock_Quartzite"
    },
    {
      "x": -2,
      "y": 1,
      "z": 5,
      "name": "Rock_Quartzite"
    },
    {
      "x": -2,
      "y": 2,
      "z": 5,
      "name": "Rock_Quartzite"
    },
    {
      "x": -2,
      "y": 3,
      "z": 5,
      "name": "Rock_Quartzite"
    },
    {
      "x": -2,
      "y": 4,
      "z": 5,
      "name": "Rock_Quartzite"
    },
    {
      "x": -2,
      "y": 5,
      "z": 5,
      "name": "Rock_Quartzite"
    },
    {
      "x": -2,
      "y": 6,
      "z": 5,
      "name": "Rock_Quartzite"
    },
    {
      "x": -2,
      "y": 7,
      "z": 5,
      "name": "Rock_Quartzite_Brick"
    },
    {
      "x": -2,
      "y": 8,
      "z": 5,
      "name": "Rock_Quartzite"
    },
    {
      "x": -2,
      "y": 9,
      "z": 5,
      "name": "Rock_Quartzite"
    },
    {
      "x": -2,
      "y": 10,
      "z": 5,
      "name": "Rock_Quartzite"
    },
    {
      "x": -2,
      "y": 11,
      "z": 5,
      "name": "Rock_Quartzite"
    },
    {
      "x": -2,
      "y": 12,
      "z": 5,
      "name": "Soil_Grass"
    },
    {
      "x": -2,
      "y": 13,
      "z": 5,
      "name": "Plant_Grass_Sharp"
    },
    {
      "x": -2,
      "y": 0,
      "z": 6,
      "name": "Rock_Quartzite"
    },
    {
      "x": -2,
      "y": 1,
      "z": 6,
      "name": "Rock_Quartzite"
    },
    {
      "x": -2,
      "y": 2,
      "z": 6,
      "name": "Rock_Quartzite"
    },
    {
      "x": -2,
      "y": 3,
      "z": 6,
      "name": "Rock_Quartzite"
    },
    {
      "x": -2,
      "y": 4,
      "z": 6,
      "name": "Rock_Quartzite"
    },
    {
      "x": -2,
      "y": 5,
      "z": 6,
      "name": "Rock_Quartzite"
    },
    {
      "x": -2,
      "y": 6,
      "z": 6,
      "name": "Rock_Quartzite"
    },
    {
      "x": -2,
      "y": 7,
      "z": 6,
      "name": "Rock_Quartzite_Brick"
    },
    {
      "x": -2,
      "y": 8,
      "z": 6,
      "name": "Rock_Quartzite"
    },
    {
      "x": -2,
      "y": 9,
      "z": 6,
      "name": "Rock_Quartzite"
    },
    {
      "x": -2,
      "y": 10,
      "z": 6,
      "name": "Rock_Quartzite"
    },
    {
      "x": -2,
      "y": 11,
      "z": 6,
      "name": "Rock_Quartzite"
    },
    {
      "x": -2,
      "y": 12,
      "z": 6,
      "name": "Soil_Grass"
    },
    {
      "x": -2,
      "y": 13,
      "z": 6,
      "name": "Plant_Bush"
    },
    {
      "x": -2,
      "y": 0,
      "z": 7,
      "name": "Rock_Quartzite"
    },
    {
      "x": -2,
      "y": 1,
      "z": 7,
      "name": "Rock_Quartzite"
    },
    {
      "x": -2,
      "y": 2,
      "z": 7,
      "name": "Rock_Quartzite"
    },
    {
      "x": -2,
      "y": 3,
      "z": 7,
      "name": "Rock_Quartzite"
    },
    {
      "x": -2,
      "y": 4,
      "z": 7,
      "name": "Rock_Quartzite"
    },
    {
      "x": -2,
      "y": 5,
      "z": 7,
      "name": "Rock_Quartzite"
    },
    {
      "x": -2,
      "y": 6,
      "z": 7,
      "name": "Rock_Quartzite"
    },
    {
      "x": -2,
      "y": 7,
      "z": 7,
      "name": "Rock_Quartzite"
    },
    {
      "x": -2,
      "y": 8,
      "z": 7,
      "name": "Rock_Quartzite"
    },
    {
      "x": -2,
      "y": 9,
      "z": 7,
      "name": "Rock_Quartzite"
    },
    {
      "x": -2,
      "y": 10,
      "z": 7,
      "name": "Rock_Quartzite"
    },
    {
      "x": -2,
      "y": 11,
      "z": 7,
      "name": "Rock_Quartzite"
    },
    {
      "x": -2,
      "y": 12,
      "z": 7,
      "name": "Soil_Grass"
    },
    {
      "x": -2,
      "y": 0,
      "z": 8,
      "name": "Rock_Quartzite"
    },
    {
      "x": -2,
      "y": 1,
      "z": 8,
      "name": "Rock_Quartzite"
    },
    {
      "x": -2,
      "y": 2,
      "z": 8,
      "name": "Rock_Quartzite"
    },
    {
      "x": -2,
      "y": 3,
      "z": 8,
      "name": "Rock_Quartzite"
    },
    {
      "x": -2,
      "y": 4,
      "z": 8,
      "name": "Rock_Quartzite"
    },
    {
      "x": -2,
      "y": 5,
      "z": 8,
      "name": "Rock_Quartzite"
    },
    {
      "x": -2,
      "y": 6,
      "z": 8,
      "name": "Rock_Quartzite"
    },
    {
      "x": -2,
      "y": 7,
      "z": 8,
      "name": "Rock_Quartzite_Cobble"
    },
    {
      "x": -2,
      "y": 8,
      "z": 8,
      "name": "Rock_Quartzite"
    },
    {
      "x": -2,
      "y": 9,
      "z": 8,
      "name": "Rock_Quartzite_Cobble_Half",
      "rotation": 4
    },
    {
      "x": -2,
      "y": 10,
      "z": 8,
      "name": "Rock_Quartzite_Cobble_Half",
      "rotation": 4
    },
    {
      "x": -2,
      "y": 11,
      "z": 8,
      "name": "Rock_Quartzite_Cobble_Stairs",
      "rotation": 10
    },
    {
      "x": -2,
      "y": 12,
      "z": 8,
      "name": "Soil_Grass"
    },
    {
      "x": -2,
      "y": 13,
      "z": 8,
      "name": "Plant_Moss_Rug_Green"
    },
    {
      "x": -2,
      "y": 2,
      "z": 9,
      "name": "Rock_Quartzite"
    },
    {
      "x": -2,
      "y": 3,
      "z": 9,
      "name": "Rock_Quartzite"
    },
    {
      "x": -2,
      "y": 4,
      "z": 9,
      "name": "Rock_Quartzite"
    },
    {
      "x": -2,
      "y": 5,
      "z": 9,
      "name": "Rock_Quartzite"
    },
    {
      "x": -2,
      "y": 6,
      "z": 9,
      "name": "Rock_Quartzite_Cobble"
    },
    {
      "x": -2,
      "y": 12,
      "z": 9,
      "name": "Plant_Vine_Wall"
    },
    {
      "x": -1,
      "y": 4,
      "z": -9,
      "name": "Rock_Quartzite"
    },
    {
      "x": -1,
      "y": 5,
      "z": -9,
      "name": "Rock_Quartzite"
    },
    {
      "x": -1,
      "y": 6,
      "z": -9,
      "name": "Rock_Quartzite"
    },
    {
      "x": -1,
      "y": 3,
      "z": -8,
      "name": "Rock_Quartzite"
    },
    {
      "x": -1,
      "y": 4,
      "z": -8,
      "name": "Rock_Quartzite"
    },
    {
      "x": -1,
      "y": 5,
      "z": -8,
      "name": "Rock_Quartzite"
    },
    {
      "x": -1,
      "y": 6,
      "z": -8,
      "name": "Rock_Quartzite"
    },
    {
      "x": -1,
      "y": 0,
      "z": -7,
      "name": "Rock_Quartzite"
    },
    {
      "x": -1,
      "y": 1,
      "z": -7,
      "name": "Rock_Quartzite"
    },
    {
      "x": -1,
      "y": 2,
      "z": -7,
      "name": "Rock_Quartzite"
    },
    {
      "x": -1,
      "y": 3,
      "z": -7,
      "name": "Rock_Quartzite"
    },
    {
      "x": -1,
      "y": 4,
      "z": -7,
      "name": "Rock_Quartzite"
    },
    {
      "x": -1,
      "y": 5,
      "z": -7,
      "name": "Rock_Quartzite"
    },
    {
      "x": -1,
      "y": 6,
      "z": -7,
      "name": "Rock_Quartzite"
    },
    {
      "x": -1,
      "y": 0,
      "z": -6,
      "name": "Rock_Quartzite"
    },
    {
      "x": -1,
      "y": 1,
      "z": -6,
      "name": "Rock_Quartzite"
    },
    {
      "x": -1,
      "y": 2,
      "z": -6,
      "name": "Rock_Quartzite_Cobble"
    },
    {
      "x": -1,
      "y": 3,
      "z": -6,
      "name": "Rock_Quartzite_Cobble"
    },
    {
      "x": -1,
      "y": 4,
      "z": -6,
      "name": "Rock_Quartzite_Cobble"
    },
    {
      "x": -1,
      "y": 5,
      "z": -6,
      "name": "Rock_Quartzite_Cobble"
    },
    {
      "x": -1,
      "y": 6,
      "z": -6,
      "name": "Rock_Quartzite_Cobble"
    },
    {
      "x": -1,
      "y": 0,
      "z": -5,
      "name": "Rock_Quartzite"
    },
    {
      "x": -1,
      "y": 1,
      "z": -5,
      "name": "Rock_Quartzite"
    },
    {
      "x": -1,
      "y": 2,
      "z": -5,
      "name": "Rock_Quartzite"
    },
    {
      "x": -1,
      "y": 3,
      "z": -5,
      "name": "Rock_Quartzite"
    },
    {
      "x": -1,
      "y": 4,
      "z": -5,
      "name": "Rock_Quartzite"
    },
    {
      "x": -1,
      "y": 5,
      "z": -5,
      "name": "Rock_Quartzite_Cobble"
    },
    {
      "x": -1,
      "y": 6,
      "z": -5,
      "name": "Rock_Quartzite"
    },
    {
      "x": -1,
      "y": 0,
      "z": -4,
      "name": "Rock_Quartzite"
    },
    {
      "x": -1,
      "y": 1,
      "z": -4,
      "name": "Rock_Quartzite"
    },
    {
      "x": -1,
      "y": 2,
      "z": -4,
      "name": "Rock_Quartzite"
    },
    {
      "x": -1,
      "y": 3,
      "z": -4,
      "name": "Rock_Quartzite"
    },
    {
      "x": -1,
      "y": 4,
      "z": -4,
      "name": "Rock_Quartzite"
    },
    {
      "x": -1,
      "y": 5,
      "z": -4,
      "name": "Rock_Quartzite"
    },
    {
      "x": -1,
      "y": 6,
      "z": -4,
      "name": "Rock_Quartzite"
    },
    {
      "x": -1,
      "y": 7,
      "z": -4,
      "name": "Rock_Quartzite_Brick"
    },
    {
      "x": -1,
      "y": 8,
      "z": -4,
      "name": "Rock_Quartzite_Brick_Half",
      "rotation": 5
    },
    {
      "x": -1,
      "y": 9,
      "z": -4,
      "name": "Rock_Quartzite_Brick_Half",
      "rotation": 5
    },
    {
      "x": -1,
      "y": 1,
      "z": -3,
      "name": "Rock_Quartzite"
    },
    {
      "x": -1,
      "y": 2,
      "z": -3,
      "name": "Rock_Quartzite"
    },
    {
      "x": -1,
      "y": 3,
      "z": -3,
      "name": "Rock_Quartzite"
    },
    {
      "x": -1,
      "y": 4,
      "z": -3,
      "name": "Rock_Quartzite"
    },
    {
      "x": -1,
      "y": 5,
      "z": -3,
      "name": "Rock_Quartzite"
    },
    {
      "x": -1,
      "y": 6,
      "z": -3,
      "name": "Rock_Quartzite"
    },
    {
      "x": -1,
      "y": 2,
      "z": -2,
      "name": "Rock_Quartzite"
    },
    {
      "x": -1,
      "y": 3,
      "z": -2,
      "name": "Rock_Quartzite"
    },
    {
      "x": -1,
      "y": 4,
      "z": -2,
      "name": "Rock_Quartzite"
    },
    {
      "x": -1,
      "y": 5,
      "z": -2,
      "name": "Rock_Quartzite"
    },
    {
      "x": -1,
      "y": 6,
      "z": -2,
      "name": "Rock_Quartzite"
    },
    {
      "x": -1,
      "y": 7,
      "z": -2,
      "name": "Rock_Quartzite_Brick"
    },
    {
      "x": -1,
      "y": 8,
      "z": -2,
      "name": "Rock_Quartzite_Brick_Half",
      "rotation": 5
    },
    {
      "x": -1,
      "y": 9,
      "z": -2,
      "name": "Rock_Quartzite_Brick_Half",
      "rotation": 5
    },
    {
      "x": -1,
      "y": 10,
      "z": -2,
      "name": "Rock_Quartzite_Brick_Half",
      "rotation": 5
    },
    {
      "x": -1,
      "y": 3,
      "z": -1,
      "name": "Rock_Quartzite"
    },
    {
      "x": -1,
      "y": 4,
      "z": -1,
      "name": "Rock_Quartzite"
    },
    {
      "x": -1,
      "y": 5,
      "z": -1,
      "name": "Rock_Quartzite"
    },
    {
      "x": -1,
      "y": 6,
      "z": -1,
      "name": "Rock_Quartzite_Cobble"
    },
    {
      "x": -1,
      "y": 1,
      "z": 0,
      "name": "Rock_Quartzite"
    },
    {
      "x": -1,
      "y": 2,
      "z": 0,
      "name": "Rock_Quartzite"
    },
    {
      "x": -1,
      "y": 3,
      "z": 0,
      "name": "Rock_Quartzite"
    },
    {
      "x": -1,
      "y": 4,
      "z": 0,
      "name": "Rock_Quartzite"
    },
    {
      "x": -1,
      "y": 0,
      "z": 1,
      "name": "Rock_Quartzite"
    },
    {
      "x": -1,
      "y": 1,
      "z": 1,
      "name": "Rock_Quartzite"
    },
    {
      "x": -1,
      "y": 2,
      "z": 1,
      "name": "Rock_Quartzite"
    },
    {
      "x": -1,
      "y": 3,
      "z": 1,
      "name": "Rock_Quartzite"
    },
    {
      "x": -1,
      "y": 4,
      "z": 1,
      "name": "Rock_Quartzite"
    },
    {
      "x": -1,
      "y": 0,
      "z": 2,
      "name": "Rock_Quartzite"
    },
    {
      "x": -1,
      "y": 1,
      "z": 2,
      "name": "Rock_Quartzite"
    },
    {
      "x": -1,
      "y": 2,
      "z": 2,
      "name": "Rock_Quartzite"
    },
    {
      "x": -1,
      "y": 3,
      "z": 2,
      "name": "Rock_Quartzite"
    },
    {
      "x": -1,
      "y": 4,
      "z": 2,
      "name": "Rock_Quartzite"
    },
    {
      "x": -1,
      "y": 5,
      "z": 2,
      "name": "Rock_Quartzite"
    },
    {
      "x": -1,
      "y": 6,
      "z": 2,
      "name": "Rock_Quartzite"
    },
    {
      "x": -1,
      "y": 0,
      "z": 3,
      "name": "Rock_Quartzite"
    },
    {
      "x": -1,
      "y": 1,
      "z": 3,
      "name": "Rock_Quartzite"
    },
    {
      "x": -1,
      "y": 2,
      "z": 3,
      "name": "Rock_Quartzite"
    },
    {
      "x": -1,
      "y": 3,
      "z": 3,
      "name": "Rock_Quartzite"
    },
    {
      "x": -1,
      "y": 4,
      "z": 3,
      "name": "Rock_Quartzite"
    },
    {
      "x": -1,
      "y": 5,
      "z": 3,
      "name": "Rock_Quartzite"
    },
    {
      "x": -1,
      "y": 6,
      "z": 3,
      "name": "Rock_Quartzite"
    },
    {
      "x": -1,
      "y": 0,
      "z": 4,
      "name": "Rock_Quartzite"
    },
    {
      "x": -1,
      "y": 1,
      "z": 4,
      "name": "Rock_Quartzite"
    },
    {
      "x": -1,
      "y": 2,
      "z": 4,
      "name": "Rock_Quartzite"
    },
    {
      "x": -1,
      "y": 3,
      "z": 4,
      "name": "Rock_Quartzite"
    },
    {
      "x": -1,
      "y": 4,
      "z": 4,
      "name": "Rock_Quartzite"
    },
    {
      "x": -1,
      "y": 5,
      "z": 4,
      "name": "Rock_Quartzite"
    },
    {
      "x": -1,
      "y": 6,
      "z": 4,
      "name": "Rock_Quartzite"
    },
    {
      "x": -1,
      "y": 12,
      "z": 4,
      "name": "Rock_Quartzite_Brick_Stairs",
      "rotation": 11
    },
    {
      "x": -1,
      "y": 0,
      "z": 5,
      "name": "Rock_Quartzite"
    },
    {
      "x": -1,
      "y": 1,
      "z": 5,
      "name": "Rock_Quartzite"
    },
    {
      "x": -1,
      "y": 2,
      "z": 5,
      "name": "Rock_Quartzite"
    },
    {
      "x": -1,
      "y": 3,
      "z": 5,
      "name": "Rock_Quartzite"
    },
    {
      "x": -1,
      "y": 4,
      "z": 5,
      "name": "Rock_Quartzite"
    },
    {
      "x": -1,
      "y": 5,
      "z": 5,
      "name": "Rock_Quartzite"
    },
    {
      "x": -1,
      "y": 6,
      "z": 5,
      "name": "Rock_Quartzite"
    },
    {
      "x": -1,
      "y": 7,
      "z": 5,
      "name": "Rock_Quartzite_Brick"
    },
    {
      "x": -1,
      "y": 8,
      "z": 5,
      "name": "Rock_Quartzite_Brick"
    },
    {
      "x": -1,
      "y": 9,
      "z": 5,
      "name": "Rock_Quartzite_Brick"
    },
    {
      "x": -1,
      "y": 10,
      "z": 5,
      "name": "Rock_Quartzite_Brick"
    },
    {
      "x": -1,
      "y": 11,
      "z": 5,
      "name": "Rock_Quartzite_Brick"
    },
    {
      "x": -1,
      "y": 12,
      "z": 5,
      "name": "Rock_Quartzite_Brick"
    },
    {
      "x": -1,
      "y": 0,
      "z": 6,
      "name": "Rock_Quartzite"
    },
    {
      "x": -1,
      "y": 1,
      "z": 6,
      "name": "Rock_Quartzite"
    },
    {
      "x": -1,
      "y": 2,
      "z": 6,
      "name": "Rock_Quartzite"
    },
    {
      "x": -1,
      "y": 3,
      "z": 6,
      "name": "Rock_Quartzite"
    },
    {
      "x": -1,
      "y": 4,
      "z": 6,
      "name": "Rock_Quartzite"
    },
    {
      "x": -1,
      "y": 5,
      "z": 6,
      "name": "Rock_Quartzite"
    },
    {
      "x": -1,
      "y": 6,
      "z": 6,
      "name": "Rock_Quartzite"
    },
    {
      "x": -1,
      "y": 7,
      "z": 6,
      "name": "Rock_Quartzite_Brick"
    },
    {
      "x": -1,
      "y": 8,
      "z": 6,
      "name": "Rock_Quartzite"
    },
    {
      "x": -1,
      "y": 9,
      "z": 6,
      "name": "Rock_Quartzite"
    },
    {
      "x": -1,
      "y": 10,
      "z": 6,
      "name": "Rock_Quartzite"
    },
    {
      "x": -1,
      "y": 11,
      "z": 6,
      "name": "Rock_Quartzite"
    },
    {
      "x": -1,
      "y": 12,
      "z": 6,
      "name": "Soil_Grass"
    },
    {
      "x": -1,
      "y": 13,
      "z": 6,
      "name": "Plant_Bush"
    },
    {
      "x": -1,
      "y": 0,
      "z": 7,
      "name": "Rock_Quartzite"
    },
    {
      "x": -1,
      "y": 1,
      "z": 7,
      "name": "Rock_Quartzite"
    },
    {
      "x": -1,
      "y": 2,
      "z": 7,
      "name": "Rock_Quartzite"
    },
    {
      "x": -1,
      "y": 3,
      "z": 7,
      "name": "Rock_Quartzite"
    },
    {
      "x": -1,
      "y": 4,
      "z": 7,
      "name": "Rock_Quartzite"
    },
    {
      "x": -1,
      "y": 5,
      "z": 7,
      "name": "Rock_Quartzite"
    },
    {
      "x": -1,
      "y": 6,
      "z": 7,
      "name": "Rock_Quartzite"
    },
    {
      "x": -1,
      "y": 7,
      "z": 7,
      "name": "Rock_Quartzite"
    },
    {
      "x": -1,
      "y": 8,
      "z": 7,
      "name": "Rock_Quartzite"
    },
    {
      "x": -1,
      "y": 9,
      "z": 7,
      "name": "Rock_Quartzite"
    },
    {
      "x": -1,
      "y": 10,
      "z": 7,
      "name": "Rock_Quartzite"
    },
    {
      "x": -1,
      "y": 11,
      "z": 7,
      "name": "Rock_Quartzite"
    },
    {
      "x": -1,
      "y": 12,
      "z": 7,
      "name": "Soil_Grass"
    },
    {
      "x": -1,
      "y": 13,
      "z": 7,
      "name": "Plant_Bush"
    },
    {
      "x": -1,
      "y": 0,
      "z": 8,
      "name": "Rock_Quartzite"
    },
    {
      "x": -1,
      "y": 1,
      "z": 8,
      "name": "Rock_Quartzite"
    },
    {
      "x": -1,
      "y": 2,
      "z": 8,
      "name": "Rock_Quartzite"
    },
    {
      "x": -1,
      "y": 3,
      "z": 8,
      "name": "Rock_Quartzite"
    },
    {
      "x": -1,
      "y": 4,
      "z": 8,
      "name": "Rock_Quartzite"
    },
    {
      "x": -1,
      "y": 5,
      "z": 8,
      "name": "Rock_Quartzite"
    },
    {
      "x": -1,
      "y": 6,
      "z": 8,
      "name": "Rock_Quartzite"
    },
    {
      "x": -1,
      "y": 7,
      "z": 8,
      "name": "Rock_Quartzite_Brick"
    },
    {
      "x": -1,
      "y": 8,
      "z": 8,
      "name": "Rock_Quartzite"
    },
    {
      "x": -1,
      "y": 9,
      "z": 8,
      "name": "Rock_Quartzite"
    },
    {
      "x": -1,
      "y": 10,
      "z": 8,
      "name": "Rock_Quartzite"
    },
    {
      "x": -1,
      "y": 11,
      "z": 8,
      "name": "Rock_Quartzite"
    },
    {
      "x": -1,
      "y": 12,
      "z": 8,
      "name": "Soil_Grass"
    },
    {
      "x": -1,
      "y": 13,
      "z": 8,
      "name": "Plant_Grass_Lush"
    },
    {
      "x": -1,
      "y": 1,
      "z": 9,
      "name": "Rock_Quartzite"
    },
    {
      "x": -1,
      "y": 2,
      "z": 9,
      "name": "Rock_Quartzite"
    },
    {
      "x": -1,
      "y": 3,
      "z": 9,
      "name": "Rock_Quartzite"
    },
    {
      "x": -1,
      "y": 4,
      "z": 9,
      "name": "Rock_Quartzite"
    },
    {
      "x": -1,
      "y": 12,
      "z": 9,
      "name": "Rock_Quartzite_Brick_Stairs",
      "rotation": 10
    },
    {
      "x": -1,
      "y": 13,
      "z": 9,
      "name": "Plant_Moss_Rug_Green"
    },
    {
      "x": 0,
      "y": 0,
      "z": 5,
      "name": "Rock_Quartzite"
    },
    {
      "x": 0,
      "y": 1,
      "z": 5,
      "name": "Rock_Quartzite"
    },
    {
      "x": 0,
      "y": 2,
      "z": 5,
      "name": "Rock_Quartzite"
    },
    {
      "x": 0,
      "y": 3,
      "z": 5,
      "name": "Rock_Quartzite"
    },
    {
      "x": 0,
      "y": 4,
      "z": 5,
      "name": "Rock_Quartzite"
    },
    {
      "x": 0,
      "y": 5,
      "z": 5,
      "name": "Rock_Quartzite"
    },
    {
      "x": 0,
      "y": 12,
      "z": 5,
      "name": "Rock_Quartzite_Brick_Stairs",
      "rotation": 8
    },
    {
      "x": 0,
      "y": 0,
      "z": 6,
      "name": "Rock_Quartzite"
    },
    {
      "x": 0,
      "y": 1,
      "z": 6,
      "name": "Rock_Quartzite"
    },
    {
      "x": 0,
      "y": 2,
      "z": 6,
      "name": "Rock_Quartzite"
    },
    {
      "x": 0,
      "y": 3,
      "z": 6,
      "name": "Rock_Quartzite"
    },
    {
      "x": 0,
      "y": 4,
      "z": 6,
      "name": "Rock_Quartzite"
    },
    {
      "x": 0,
      "y": 5,
      "z": 6,
      "name": "Rock_Quartzite"
    },
    {
      "x": 0,
      "y": 6,
      "z": 6,
      "name": "Rock_Quartzite"
    },
    {
      "x": 0,
      "y": 7,
      "z": 6,
      "name": "Rock_Quartzite_Brick"
    },
    {
      "x": 0,
      "y": 8,
      "z": 6,
      "name": "Rock_Quartzite"
    },
    {
      "x": 0,
      "y": 9,
      "z": 6,
      "name": "Rock_Quartzite"
    },
    {
      "x": 0,
      "y": 10,
      "z": 6,
      "name": "Rock_Quartzite"
    },
    {
      "x": 0,
      "y": 11,
      "z": 6,
      "name": "Soil_Dirt"
    },
    {
      "x": 0,
      "y": 12,
      "z": 6,
      "name": "Soil_Grass"
    },
    {
      "x": 0,
      "y": 13,
      "z": 6,
      "name": "Plant_Grass_Sharp"
    },
    {
      "x": 0,
      "y": 0,
      "z": 7,
      "name": "Rock_Quartzite"
    },
    {
      "x": 0,
      "y": 1,
      "z": 7,
      "name": "Rock_Quartzite"
    },
    {
      "x": 0,
      "y": 2,
      "z": 7,
      "name": "Rock_Quartzite"
    },
    {
      "x": 0,
      "y": 3,
      "z": 7,
      "name": "Rock_Quartzite"
    },
    {
      "x": 0,
      "y": 4,
      "z": 7,
      "name": "Rock_Quartzite"
    },
    {
      "x": 0,
      "y": 5,
      "z": 7,
      "name": "Rock_Quartzite"
    },
    {
      "x": 0,
      "y": 6,
      "z": 7,
      "name": "Rock_Quartzite"
    },
    {
      "x": 0,
      "y": 7,
      "z": 7,
      "name": "Rock_Quartzite"
    },
    {
      "x": 0,
      "y": 8,
      "z": 7,
      "name": "Rock_Quartzite"
    },
    {
      "x": 0,
      "y": 9,
      "z": 7,
      "name": "Rock_Quartzite"
    },
    {
      "x": 0,
      "y": 10,
      "z": 7,
      "name": "Rock_Quartzite"
    },
    {
      "x": 0,
      "y": 11,
      "z": 7,
      "name": "Rock_Quartzite"
    },
    {
      "x": 0,
      "y": 12,
      "z": 7,
      "name": "Soil_Grass"
    },
    {
      "x": 0,
      "y": 13,
      "z": 7,
      "name": "Plant_Grass_Sharp_Tall"
    },
    {
      "x": 0,
      "y": 14,
      "z": 7,
      "name": "Plant_Grass_Sharp_Tall",
      "filler": 1024
    },
    {
      "x": 0,
      "y": 0,
      "z": 8,
      "name": "Rock_Quartzite"
    },
    {
      "x": 0,
      "y": 1,
      "z": 8,
      "name": "Rock_Quartzite"
    },
    {
      "x": 0,
      "y": 2,
      "z": 8,
      "name": "Rock_Quartzite"
    },
    {
      "x": 0,
      "y": 3,
      "z": 8,
      "name": "Rock_Quartzite"
    },
    {
      "x": 0,
      "y": 4,
      "z": 8,
      "name": "Rock_Quartzite"
    },
    {
      "x": 0,
      "y": 5,
      "z": 8,
      "name": "Rock_Quartzite_Cobble"
    },
    {
      "x": 0,
      "y": 6,
      "z": 8,
      "name": "Rock_Quartzite"
    },
    {
      "x": 0,
      "y": 7,
      "z": 8,
      "name": "Rock_Quartzite_Brick"
    },
    {
      "x": 0,
      "y": 8,
      "z": 8,
      "name": "Rock_Quartzite"
    },
    {
      "x": 0,
      "y": 9,
      "z": 8,
      "name": "Rock_Quartzite"
    },
    {
      "x": 0,
      "y": 10,
      "z": 8,
      "name": "Rock_Quartzite"
    },
    {
      "x": 0,
      "y": 11,
      "z": 8,
      "name": "Rock_Quartzite"
    },
    {
      "x": 0,
      "y": 12,
      "z": 8,
      "name": "Soil_Grass"
    },
    {
      "x": 0,
      "y": 13,
      "z": 8,
      "name": "Plant_Grass_Lush_Short"
    },
    {
      "x": 0,
      "y": 1,
      "z": 9,
      "name": "Rock_Quartzite"
    },
    {
      "x": 0,
      "y": 2,
      "z": 9,
      "name": "Rock_Quartzite"
    },
    {
      "x": 0,
      "y": 3,
      "z": 9,
      "name": "Rock_Quartzite"
    },
    {
      "x": 0,
      "y": 12,
      "z": 9,
      "name": "Rock_Quartzite_Brick_Stairs",
      "rotation": 10
    },
    {
      "x": 1,
      "y": 0,
      "z": 5,
      "name": "Rock_Quartzite"
    },
    {
      "x": 1,
      "y": 1,
      "z": 5,
      "name": "Rock_Quartzite"
    },
    {
      "x": 1,
      "y": 2,
      "z": 5,
      "name": "Rock_Quartzite"
    },
    {
      "x": 1,
      "y": 3,
      "z": 5,
      "name": "Rock_Quartzite"
    },
    {
      "x": 1,
      "y": 0,
      "z": 6,
      "name": "Rock_Quartzite"
    },
    {
      "x": 1,
      "y": 1,
      "z": 6,
      "name": "Rock_Quartzite"
    },
    {
      "x": 1,
      "y": 2,
      "z": 6,
      "name": "Rock_Quartzite"
    },
    {
      "x": 1,
      "y": 3,
      "z": 6,
      "name": "Rock_Quartzite"
    },
    {
      "x": 1,
      "y": 4,
      "z": 6,
      "name": "Rock_Quartzite"
    },
    {
      "x": 1,
      "y": 5,
      "z": 6,
      "name": "Rock_Quartzite"
    },
    {
      "x": 1,
      "y": 6,
      "z": 6,
      "name": "Rock_Quartzite"
    },
    {
      "x": 1,
      "y": 7,
      "z": 6,
      "name": "Rock_Quartzite_Brick"
    },
    {
      "x": 1,
      "y": 8,
      "z": 6,
      "name": "Rock_Quartzite"
    },
    {
      "x": 1,
      "y": 9,
      "z": 6,
      "name": "Rock_Quartzite"
    },
    {
      "x": 1,
      "y": 10,
      "z": 6,
      "name": "Rock_Quartzite"
    },
    {
      "x": 1,
      "y": 11,
      "z": 6,
      "name": "Soil_Grass"
    },
    {
      "x": 1,
      "y": 12,
      "z": 6,
      "name": "Plant_Grass_Lush_Short"
    },
    {
      "x": 1,
      "y": 0,
      "z": 7,
      "name": "Rock_Quartzite"
    },
    {
      "x": 1,
      "y": 1,
      "z": 7,
      "name": "Rock_Quartzite"
    },
    {
      "x": 1,
      "y": 2,
      "z": 7,
      "name": "Rock_Quartzite"
    },
    {
      "x": 1,
      "y": 3,
      "z": 7,
      "name": "Rock_Quartzite"
    },
    {
      "x": 1,
      "y": 4,
      "z": 7,
      "name": "Rock_Quartzite"
    },
    {
      "x": 1,
      "y": 5,
      "z": 7,
      "name": "Rock_Quartzite"
    },
    {
      "x": 1,
      "y": 6,
      "z": 7,
      "name": "Rock_Quartzite_Cobble"
    },
    {
      "x": 1,
      "y": 7,
      "z": 7,
      "name": "Rock_Quartzite_Cobble"
    },
    {
      "x": 1,
      "y": 8,
      "z": 7,
      "name": "Rock_Quartzite_Cobble"
    },
    {
      "x": 1,
      "y": 9,
      "z": 7,
      "name": "Rock_Quartzite"
    },
    {
      "x": 1,
      "y": 10,
      "z": 7,
      "name": "Rock_Quartzite"
    },
    {
      "x": 1,
      "y": 11,
      "z": 7,
      "name": "Soil_Grass"
    },
    {
      "x": 1,
      "y": 12,
      "z": 7,
      "name": "Plant_Grass_Lush"
    },
    {
      "x": 1,
      "y": 0,
      "z": 8,
      "name": "Rock_Quartzite"
    },
    {
      "x": 1,
      "y": 1,
      "z": 8,
      "name": "Rock_Quartzite"
    },
    {
      "x": 1,
      "y": 2,
      "z": 8,
      "name": "Rock_Quartzite"
    },
    {
      "x": 1,
      "y": 3,
      "z": 8,
      "name": "Rock_Quartzite"
    },
    {
      "x": 1,
      "y": 4,
      "z": 8,
      "name": "Rock_Quartzite"
    },
    {
      "x": 1,
      "y": 5,
      "z": 8,
      "name": "Rock_Quartzite_Cobble"
    },
    {
      "x": 1,
      "y": 6,
      "z": 8,
      "name": "Rock_Quartzite_Cobble"
    },
    {
      "x": 1,
      "y": 9,
      "z": 8,
      "name": "Rock_Quartzite"
    },
    {
      "x": 1,
      "y": 10,
      "z": 8,
      "name": "Rock_Quartzite"
    },
    {
      "x": 1,
      "y": 11,
      "z": 8,
      "name": "Rock_Quartzite"
    },
    {
      "x": 1,
      "y": 12,
      "z": 8,
      "name": "Soil_Grass"
    },
    {
      "x": 1,
      "y": 1,
      "z": 9,
      "name": "Rock_Quartzite"
    },
    {
      "x": 1,
      "y": 2,
      "z": 9,
      "name": "Rock_Quartzite"
    },
    {
      "x": 1,
      "y": 10,
      "z": 9,
      "name": "Rock_Quartzite_Brick_Half",
      "rotation": 4
    },
    {
      "x": 1,
      "y": 11,
      "z": 9,
      "name": "Rock_Quartzite_Brick_Half",
      "rotation": 4
    },
    {
      "x": 1,
      "y": 12,
      "z": 9,
      "name": "Rock_Quartzite_Brick"
    },
    {
      "x": 2,
      "y": 0,
      "z": 5,
      "name": "Rock_Quartzite"
    },
    {
      "x": 2,
      "y": 1,
      "z": 5,
      "name": "Rock_Quartzite"
    },
    {
      "x": 2,
      "y": 2,
      "z": 5,
      "name": "Rock_Quartzite"
    },
    {
      "x": 2,
      "y": 3,
      "z": 5,
      "name": "Rock_Quartzite"
    },
    {
      "x": 2,
      "y": 0,
      "z": 6,
      "name": "Rock_Quartzite"
    },
    {
      "x": 2,
      "y": 1,
      "z": 6,
      "name": "Rock_Quartzite"
    },
    {
      "x": 2,
      "y": 2,
      "z": 6,
      "name": "Rock_Quartzite"
    },
    {
      "x": 2,
      "y": 3,
      "z": 6,
      "name": "Rock_Quartzite"
    },
    {
      "x": 2,
      "y": 4,
      "z": 6,
      "name": "Rock_Quartzite"
    },
    {
      "x": 2,
      "y": 5,
      "z": 6,
      "name": "Rock_Quartzite"
    },
    {
      "x": 2,
      "y": 6,
      "z": 6,
      "name": "Rock_Quartzite"
    },
    {
      "x": 2,
      "y": 7,
      "z": 6,
      "name": "Rock_Quartzite_Brick"
    },
    {
      "x": 2,
      "y": 8,
      "z": 6,
      "name": "Rock_Quartzite"
    },
    {
      "x": 2,
      "y": 9,
      "z": 6,
      "name": "Rock_Quartzite"
    },
    {
      "x": 2,
      "y": 10,
      "z": 6,
      "name": "Rock_Quartzite"
    },
    {
      "x": 2,
      "y": 11,
      "z": 6,
      "name": "Soil_Grass"
    },
    {
      "x": 2,
      "y": 0,
      "z": 7,
      "name": "Rock_Quartzite"
    },
    {
      "x": 2,
      "y": 1,
      "z": 7,
      "name": "Rock_Quartzite"
    },
    {
      "x": 2,
      "y": 2,
      "z": 7,
      "name": "Rock_Quartzite"
    },
    {
      "x": 2,
      "y": 3,
      "z": 7,
      "name": "Rock_Quartzite"
    },
    {
      "x": 2,
      "y": 4,
      "z": 7,
      "name": "Rock_Quartzite"
    },
    {
      "x": 2,
      "y": 5,
      "z": 7,
      "name": "Rock_Quartzite_Cobble"
    },
    {
      "x": 2,
      "y": 6,
      "z": 7,
      "name": "Rock_Quartzite_Cobble"
    },
    {
      "x": 2,
      "y": 7,
      "z": 7,
      "name": "Rock_Quartzite_Cobble"
    },
    {
      "x": 2,
      "y": 8,
      "z": 7,
      "name": "Rock_Quartzite_Cobble"
    },
    {
      "x": 2,
      "y": 9,
      "z": 7,
      "name": "Rock_Quartzite_Cobble"
    },
    {
      "x": 2,
      "y": 10,
      "z": 7,
      "name": "Rock_Quartzite_Cobble"
    },
    {
      "x": 2,
      "y": 11,
      "z": 7,
      "name": "Soil_Grass"
    },
    {
      "x": 2,
      "y": 12,
      "z": 7,
      "name": "Plant_Grass_Sharp"
    },
    {
      "x": 2,
      "y": 0,
      "z": 8,
      "name": "Rock_Quartzite"
    },
    {
      "x": 2,
      "y": 1,
      "z": 8,
      "name": "Rock_Quartzite"
    },
    {
      "x": 2,
      "y": 2,
      "z": 8,
      "name": "Rock_Quartzite"
    },
    {
      "x": 2,
      "y": 3,
      "z": 8,
      "name": "Rock_Quartzite_Cobble"
    },
    {
      "x": 2,
      "y": 4,
      "z": 8,
      "name": "Rock_Quartzite_Cobble"
    },
    {
      "x": 2,
      "y": 5,
      "z": 8,
      "name": "Rock_Quartzite_Cobble"
    },
    {
      "x": 2,
      "y": 6,
      "z": 8,
      "name": "Rock_Quartzite_Cobble"
    },
    {
      "x": 2,
      "y": 9,
      "z": 8,
      "name": "Rock_Quartzite_Cobble_Half",
      "rotation": 4
    },
    {
      "x": 2,
      "y": 10,
      "z": 8,
      "name": "Rock_Quartzite_Cobble_Stairs",
      "rotation": 10
    },
    {
      "x": 2,
      "y": 11,
      "z": 8,
      "name": "Rock_Quartzite_Cobble"
    },
    {
      "x": 2,
      "y": 12,
      "z": 8,
      "name": "Soil_Grass"
    },
    {
      "x": 2,
      "y": 12,
      "z": 9,
      "name": "Rock_Quartzite_Brick_Stairs",
      "rotation": 10
    },
    {
      "x": 3,
      "y": 1,
      "z": 5,
      "name": "Rock_Quartzite"
    },
    {
      "x": 3,
      "y": 2,
      "z": 5,
      "name": "Rock_Quartzite"
    },
    {
      "x": 3,
      "y": 3,
      "z": 5,
      "name": "Rock_Quartzite"
    },
    {
      "x": 3,
      "y": 4,
      "z": 5,
      "name": "Rock_Quartzite"
    },
    {
      "x": 3,
      "y": 10,
      "z": 5,
      "name": "Plant_Vine_Wall",
      "rotation": 2
    },
    {
      "x": 3,
      "y": 11,
      "z": 5,
      "name": "Plant_Vine",
      "rotation": 2
    },
    {
      "x": 3,
      "y": 12,
      "z": 5,
      "name": "Plant_Vine",
      "rotation": 2
    },
    {
      "x": 3,
      "y": 0,
      "z": 6,
      "name": "Rock_Quartzite"
    },
    {
      "x": 3,
      "y": 1,
      "z": 6,
      "name": "Rock_Quartzite"
    },
    {
      "x": 3,
      "y": 2,
      "z": 6,
      "name": "Rock_Quartzite"
    },
    {
      "x": 3,
      "y": 3,
      "z": 6,
      "name": "Rock_Quartzite"
    },
    {
      "x": 3,
      "y": 4,
      "z": 6,
      "name": "Rock_Quartzite"
    },
    {
      "x": 3,
      "y": 5,
      "z": 6,
      "name": "Rock_Quartzite"
    },
    {
      "x": 3,
      "y": 6,
      "z": 6,
      "name": "Rock_Quartzite"
    },
    {
      "x": 3,
      "y": 7,
      "z": 6,
      "name": "Rock_Quartzite_Brick"
    },
    {
      "x": 3,
      "y": 8,
      "z": 6,
      "name": "Rock_Quartzite"
    },
    {
      "x": 3,
      "y": 9,
      "z": 6,
      "name": "Rock_Quartzite"
    },
    {
      "x": 3,
      "y": 10,
      "z": 6,
      "name": "Rock_Quartzite"
    },
    {
      "x": 3,
      "y": 11,
      "z": 6,
      "name": "Soil_Dirt"
    },
    {
      "x": 3,
      "y": 12,
      "z": 6,
      "name": "Soil_Grass"
    },
    {
      "x": 3,
      "y": 13,
      "z": 6,
      "name": "Plant_Moss_Rug_Green"
    },
    {
      "x": 3,
      "y": 0,
      "z": 7,
      "name": "Rock_Quartzite"
    },
    {
      "x": 3,
      "y": 1,
      "z": 7,
      "name": "Rock_Quartzite"
    },
    {
      "x": 3,
      "y": 2,
      "z": 7,
      "name": "Rock_Quartzite"
    },
    {
      "x": 3,
      "y": 3,
      "z": 7,
      "name": "Rock_Quartzite"
    },
    {
      "x": 3,
      "y": 4,
      "z": 7,
      "name": "Rock_Quartzite"
    },
    {
      "x": 3,
      "y": 5,
      "z": 7,
      "name": "Rock_Quartzite"
    },
    {
      "x": 3,
      "y": 6,
      "z": 7,
      "name": "Rock_Quartzite"
    },
    {
      "x": 3,
      "y": 7,
      "z": 7,
      "name": "Rock_Quartzite"
    },
    {
      "x": 3,
      "y": 8,
      "z": 7,
      "name": "Rock_Quartzite"
    },
    {
      "x": 3,
      "y": 9,
      "z": 7,
      "name": "Rock_Quartzite"
    },
    {
      "x": 3,
      "y": 10,
      "z": 7,
      "name": "Rock_Quartzite"
    },
    {
      "x": 3,
      "y": 11,
      "z": 7,
      "name": "Rock_Quartzite"
    },
    {
      "x": 3,
      "y": 12,
      "z": 7,
      "name": "Soil_Grass"
    },
    {
      "x": 3,
      "y": 0,
      "z": 8,
      "name": "Rock_Quartzite"
    },
    {
      "x": 3,
      "y": 1,
      "z": 8,
      "name": "Rock_Quartzite"
    },
    {
      "x": 3,
      "y": 2,
      "z": 8,
      "name": "Rock_Quartzite"
    },
    {
      "x": 3,
      "y": 3,
      "z": 8,
      "name": "Rock_Quartzite"
    },
    {
      "x": 3,
      "y": 4,
      "z": 8,
      "name": "Rock_Quartzite"
    },
    {
      "x": 3,
      "y": 5,
      "z": 8,
      "name": "Rock_Quartzite"
    },
    {
      "x": 3,
      "y": 6,
      "z": 8,
      "name": "Rock_Quartzite"
    },
    {
      "x": 3,
      "y": 7,
      "z": 8,
      "name": "Rock_Quartzite_Brick"
    },
    {
      "x": 3,
      "y": 8,
      "z": 8,
      "name": "Rock_Quartzite"
    },
    {
      "x": 3,
      "y": 9,
      "z": 8,
      "name": "Rock_Quartzite"
    },
    {
      "x": 3,
      "y": 10,
      "z": 8,
      "name": "Rock_Quartzite"
    },
    {
      "x": 3,
      "y": 11,
      "z": 8,
      "name": "Rock_Quartzite_Cobble"
    },
    {
      "x": 3,
      "y": 12,
      "z": 8,
      "name": "Soil_Grass"
    },
    {
      "x": 3,
      "y": 1,
      "z": 9,
      "name": "Rock_Quartzite"
    },
    {
      "x": 3,
      "y": 2,
      "z": 9,
      "name": "Rock_Quartzite"
    },
    {
      "x": 3,
      "y": 3,
      "z": 9,
      "name": "Rock_Quartzite"
    },
    {
      "x": 3,
      "y": 4,
      "z": 9,
      "name": "Rock_Quartzite"
    },
    {
      "x": 3,
      "y": 5,
      "z": 9,
      "name": "Rock_Quartzite"
    },
    {
      "x": 3,
      "y": 6,
      "z": 9,
      "name": "Rock_Quartzite"
    },
    {
      "x": 3,
      "y": 12,
      "z": 9,
      "name": "Rock_Quartzite_Brick_Stairs",
      "rotation": 10
    },
    {
      "x": 4,
      "y": 2,
      "z": 5,
      "name": "Rock_Quartzite"
    },
    {
      "x": 4,
      "y": 3,
      "z": 5,
      "name": "Rock_Quartzite"
    },
    {
      "x": 4,
      "y": 4,
      "z": 5,
      "name": "Rock_Quartzite"
    },
    {
      "x": 4,
      "y": 5,
      "z": 5,
      "name": "Rock_Quartzite_Cobble"
    },
    {
      "x": 4,
      "y": 6,
      "z": 5,
      "name": "Rock_Quartzite_Cobble"
    },
    {
      "x": 4,
      "y": 11,
      "z": 5,
      "name": "Plant_Vine_Wall",
      "rotation": 2
    },
    {
      "x": 4,
      "y": 12,
      "z": 5,
      "name": "Rock_Quartzite_Brick_Stairs",
      "rotation": 8
    },
    {
      "x": 4,
      "y": 0,
      "z": 6,
      "name": "Rock_Quartzite"
    },
    {
      "x": 4,
      "y": 1,
      "z": 6,
      "name": "Rock_Quartzite"
    },
    {
      "x": 4,
      "y": 2,
      "z": 6,
      "name": "Rock_Quartzite"
    },
    {
      "x": 4,
      "y": 3,
      "z": 6,
      "name": "Rock_Quartzite"
    },
    {
      "x": 4,
      "y": 4,
      "z": 6,
      "name": "Rock_Quartzite"
    },
    {
      "x": 4,
      "y": 5,
      "z": 6,
      "name": "Rock_Quartzite"
    },
    {
      "x": 4,
      "y": 6,
      "z": 6,
      "name": "Rock_Quartzite"
    },
    {
      "x": 4,
      "y": 7,
      "z": 6,
      "name": "Rock_Quartzite_Brick"
    },
    {
      "x": 4,
      "y": 8,
      "z": 6,
      "name": "Rock_Quartzite_Cobble_Half",
      "rotation": 6
    },
    {
      "x": 4,
      "y": 9,
      "z": 6,
      "name": "Rock_Quartzite_Cobble_Half",
      "rotation": 6
    },
    {
      "x": 4,
      "y": 10,
      "z": 6,
      "name": "Rock_Quartzite_Cobble"
    },
    {
      "x": 4,
      "y": 11,
      "z": 6,
      "name": "Soil_Dirt"
    },
    {
      "x": 4,
      "y": 12,
      "z": 6,
      "name": "Soil_Grass"
    },
    {
      "x": 4,
      "y": 13,
      "z": 6,
      "name": "Plant_Fern_Winter"
    },
    {
      "x": 4,
      "y": 0,
      "z": 7,
      "name": "Rock_Quartzite"
    },
    {
      "x": 4,
      "y": 1,
      "z": 7,
      "name": "Rock_Quartzite"
    },
    {
      "x": 4,
      "y": 2,
      "z": 7,
      "name": "Rock_Quartzite"
    },
    {
      "x": 4,
      "y": 3,
      "z": 7,
      "name": "Rock_Quartzite"
    },
    {
      "x": 4,
      "y": 4,
      "z": 7,
      "name": "Rock_Quartzite"
    },
    {
      "x": 4,
      "y": 5,
      "z": 7,
      "name": "Rock_Quartzite"
    },
    {
      "x": 4,
      "y": 6,
      "z": 7,
      "name": "Rock_Quartzite"
    },
    {
      "x": 4,
      "y": 7,
      "z": 7,
      "name": "Rock_Quartzite"
    },
    {
      "x": 4,
      "y": 8,
      "z": 7,
      "name": "Rock_Quartzite"
    },
    {
      "x": 4,
      "y": 9,
      "z": 7,
      "name": "Rock_Quartzite"
    },
    {
      "x": 4,
      "y": 10,
      "z": 7,
      "name": "Rock_Quartzite"
    },
    {
      "x": 4,
      "y": 11,
      "z": 7,
      "name": "Rock_Quartzite"
    },
    {
      "x": 4,
      "y": 12,
      "z": 7,
      "name": "Soil_Grass"
    },
    {
      "x": 4,
      "y": 13,
      "z": 7,
      "name": "Plant_Grass_Lush"
    },
    {
      "x": 4,
      "y": 0,
      "z": 8,
      "name": "Rock_Quartzite"
    },
    {
      "x": 4,
      "y": 1,
      "z": 8,
