{
  "version": 8,
  "blockIdVersion": 8,
  "anchorX": 0,
  "anchorY": 7,
  "anchorZ": 0,
  "blocks": [
    {
      "x": -4,
      "y": 1,
      "z": -2,
      "name": "Rock_Basalt"
    },
    {
      "x": -4,
      "y": 2,
      "z": -2,
      "name": "Rock_Basalt"
    },
    {
      "x": -4,
      "y": 3,
      "z": -2,
      "name": "Rock_Basalt"
    },
    {
      "x": -4,
      "y": 4,
      "z": -2,
      "name": "Rock_Basalt_Cobble"
    },
    {
      "x": -4,
      "y": 5,
      "z": -2,
      "name": "Rock_Basalt_Cobble"
    },
    {
      "x": -4,
      "y": 6,
      "z": -2,
      "name": "Rock_Basalt_Cobble"
    },
    {
      "x": -4,
      "y": 7,
      "z": -2,
      "name": "Rock_Basalt_Brick"
    },
    {
      "x": -4,
      "y": 8,
      "z": -2,
      "name": "Rock_Basalt_Brick"
    },
    {
      "x": -4,
      "y": 9,
      "z": -2,
      "name": "Rock_Basalt_Brick"
    },
    {
      "x": -4,
      "y": 10,
      "z": -2,
      "name": "Rock_Basalt_Brick"
    },
    {
      "x": -4,
      "y": 11,
      "z": -2,
      "name": "Wood_Blackwood_Roof",
      "rotation": 3
    },
    {
      "x": -4,
      "y": 2,
      "z": -1,
      "name": "Rock_Basalt"
    },
    {
      "x": -4,
      "y": 3,
      "z": -1,
      "name": "Rock_Basalt"
    },
    {
      "x": -4,
      "y": 4,
      "z": -1,
      "name": "Rock_Basalt_Cobble"
    },
    {
      "x": -4,
      "y": 5,
      "z": -1,
      "name": "Rock_Basalt_Cobble"
    },
    {
      "x": -4,
      "y": 6,
      "z": -1,
      "name": "Rock_Basalt_Cobble"
    },
    {
      "x": -4,
      "y": 7,
      "z": -1,
      "name": "Rock_Basalt_Brick"
    },
    {
      "x": -4,
      "y": 8,
      "z": -1,
      "name": "Rock_Basalt_Cobble"
    },
    {
      "x": -4,
      "y": 9,
      "z": -1,
      "name": "Rock_Basalt_Cobble"
    },
    {
      "x": -4,
      "y": 10,
      "z": -1,
      "name": "Rock_Basalt_Brick"
    },
    {
      "x": -4,
      "y": 4,
      "z": 2,
      "name": "Rock_Basalt_Cobble"
    },
    {
      "x": -4,
      "y": 5,
      "z": 2,
      "name": "Rock_Basalt_Cobble"
    },
    {
      "x": -4,
      "y": 6,
      "z": 2,
      "name": "Rock_Basalt_Brick"
    },
    {
      "x": -4,
      "y": 7,
      "z": 2,
      "name": "Rock_Basalt_Brick"
    },
    {
      "x": -4,
      "y": 8,
      "z": 2,
      "name": "Rock_Basalt_Brick"
    },
    {
      "x": -3,
      "y": 15,
      "z": -5,
      "name": "Rock_Basalt_Brick_Half",
      "rotation": 7
    },
    {
      "x": -3,
      "y": 15,
      "z": -3,
      "name": "Rock_Basalt_Brick_Half",
      "rotation": 7
    },
    {
      "x": -3,
      "y": 0,
      "z": -2,
      "name": "Rock_Basalt"
    },
    {
      "x": -3,
      "y": 1,
      "z": -2,
      "name": "Rock_Basalt"
    },
    {
      "x": -3,
      "y": 2,
      "z": -2,
      "name": "Rock_Basalt"
    },
    {
      "x": -3,
      "y": 3,
      "z": -2,
      "name": "Rock_Basalt_Cobble"
    },
    {
      "x": -3,
      "y": 4,
      "z": -2,
      "name": "Rock_Basalt_Cobble"
    },
    {
      "x": -3,
      "y": 5,
      "z": -2,
      "name": "Rock_Basalt_Cobble"
    },
    {
      "x": -3,
      "y": 6,
      "z": -2,
      "name": "Rock_Basalt_Cobble"
    },
    {
      "x": -3,
      "y": 7,
      "z": -2,
      "name": "Rock_Basalt_Brick"
    },
    {
      "x": -3,
      "y": 8,
      "z": -2,
      "name": "Rock_Basalt_Cobble"
    },
    {
      "x": -3,
      "y": 9,
      "z": -2,
      "name": "Rock_Basalt_Cobble"
    },
    {
      "x": -3,
      "y": 10,
      "z": -2,
      "name": "Rock_Basalt_Brick"
    },
    {
      "x": -3,
      "y": 11,
      "z": -2,
      "name": "Wood_Blackwood_Planks"
    },
    {
      "x": -3,
      "y": 12,
      "z": -2,
      "name": "Wood_Blackwood_Roof",
      "rotation": 3
    },
    {
      "x": -3,
      "y": 8,
      "z": -1,
      "name": "Empty"
    },
    {
      "x": -3,
      "y": 9,
      "z": -1,
      "name": "Empty"
    },
    {
      "x": -3,
      "y": 10,
      "z": -1,
      "name": "Empty"
    },
    {
      "x": -3,
      "y": 11,
      "z": -1,
      "name": "Empty"
    },
    {
      "x": -3,
      "y": 12,
      "z": -1,
      "name": "Wood_Blackwood_Roof",
      "rotation": 3
    },
    {
      "x": -3,
      "y": 15,
      "z": -1,
      "name": "Rock_Basalt_Brick_Half",
      "rotation": 7
    },
    {
      "x": -3,
      "y": 4,
      "z": 2,
      "name": "Rock_Basalt_Cobble"
    },
    {
      "x": -3,
      "y": 5,
      "z": 2,
      "name": "Rock_Basalt_Cobble"
    },
    {
      "x": -3,
      "y": 6,
      "z": 2,
      "name": "Rock_Basalt_Brick"
    },
    {
      "x": -3,
      "y": 7,
      "z": 2,
      "name": "Rock_Basalt_Brick"
    },
    {
      "x": -3,
      "y": 8,
      "z": 2,
      "name": "Rock_Basalt_Cobble"
    },
    {
      "x": -2,
      "y": 15,
      "z": -6,
      "name": "Rock_Basalt_Brick_Half",
      "rotation": 6
    },
    {
      "x": -2,
      "y": 16,
      "z": -6,
      "name": "Wood_Blackwood_Roof",
      "rotation": 3
    },
    {
      "x": -2,
      "y": 1,
      "z": -5,
      "name": "Rock_Basalt"
    },
    {
      "x": -2,
      "y": 2,
      "z": -5,
      "name": "Rock_Basalt"
    },
    {
      "x": -2,
      "y": 3,
      "z": -5,
      "name": "Rock_Basalt_Cobble"
    },
    {
      "x": -2,
      "y": 4,
      "z": -5,
      "name": "Rock_Basalt_Cobble"
    },
    {
      "x": -2,
      "y": 5,
      "z": -5,
      "name": "Rock_Basalt_Cobble"
    },
    {
      "x": -2,
      "y": 6,
      "z": -5,
      "name": "Rock_Basalt_Cobble"
    },
    {
      "x": -2,
      "y": 7,
      "z": -5,
      "name": "Rock_Basalt_Brick"
    },
    {
      "x": -2,
      "y": 8,
      "z": -5,
      "name": "Rock_Basalt_Brick_Pillar_Base"
    },
    {
      "x": -2,
      "y": 9,
      "z": -5,
      "name": "Rock_Basalt_Brick_Pillar_Middle"
    },
    {
      "x": -2,
      "y": 10,
      "z": -5,
      "name": "Rock_Basalt_Brick_Pillar_Base",
      "rotation": 8
    },
    {
      "x": -2,
      "y": 11,
      "z": -5,
      "name": "Rock_Basalt_Brick_Decorative"
    },
    {
      "x": -2,
      "y": 12,
      "z": -5,
      "name": "Rock_Basalt_Brick"
    },
    {
      "x": -2,
      "y": 13,
      "z": -5,
      "name": "Rock_Basalt_Brick"
    },
    {
      "x": -2,
      "y": 14,
      "z": -5,
      "name": "Rock_Basalt_Brick"
    },
    {
      "x": -2,
      "y": 15,
      "z": -5,
      "name": "Rock_Basalt_Brick"
    },
    {
      "x": -2,
      "y": 16,
      "z": -5,
      "name": "Empty"
    },
    {
      "x": -2,
      "y": 0,
      "z": -4,
      "name": "Rock_Basalt"
    },
    {
      "x": -2,
      "y": 1,
      "z": -4,
      "name": "Rock_Basalt"
    },
    {
      "x": -2,
      "y": 2,
      "z": -4,
      "name": "Rock_Basalt_Cobble"
    },
    {
      "x": -2,
      "y": 3,
      "z": -4,
      "name": "Rock_Basalt_Cobble"
    },
    {
      "x": -2,
      "y": 4,
      "z": -4,
      "name": "Rock_Basalt_Cobble"
    },
    {
      "x": -2,
      "y": 5,
      "z": -4,
      "name": "Rock_Basalt_Cobble"
    },
    {
      "x": -2,
      "y": 6,
      "z": -4,
      "name": "Rock_Basalt_Cobble"
    },
    {
      "x": -2,
      "y": 7,
      "z": -4,
      "name": "Rock_Basalt_Brick"
    },
    {
      "x": -2,
      "y": 11,
      "z": -4,
      "name": "Rock_Basalt_Brick"
    },
    {
      "x": -2,
      "y": 12,
      "z": -4,
      "name": "Rock_Basalt_Cobble"
    },
    {
      "x": -2,
      "y": 13,
      "z": -4,
      "name": "Rock_Basalt_Cobble"
    },
    {
      "x": -2,
      "y": 14,
      "z": -4,
      "name": "Empty"
    },
    {
      "x": -2,
      "y": 15,
      "z": -4,
      "name": "Empty"
    },
    {
      "x": -2,
      "y": 16,
      "z": -4,
      "name": "Empty"
    },
    {
      "x": -2,
      "y": 3,
      "z": -3,
      "name": "Rock_Basalt_Cobble"
    },
    {
      "x": -2,
      "y": 4,
      "z": -3,
      "name": "Rock_Basalt_Cobble"
    },
    {
      "x": -2,
      "y": 5,
      "z": -3,
      "name": "Rock_Basalt_Cobble"
    },
    {
      "x": -2,
      "y": 6,
      "z": -3,
      "name": "Rock_Basalt_Cobble"
    },
    {
      "x": -2,
      "y": 7,
      "z": -3,
      "name": "Rock_Basalt_Brick"
    },
    {
      "x": -2,
      "y": 11,
      "z": -3,
      "name": "Rock_Basalt_Brick"
    },
    {
      "x": -2,
      "y": 12,
      "z": -3,
      "name": "Furniture_Human_Ruins_Window",
      "rotation": 1
    },
    {
      "x": -2,
      "y": 13,
      "z": -3,
      "name": "Furniture_Human_Ruins_Window",
      "rotation": 1
    },
    {
      "x": -2,
      "y": 14,
      "z": -3,
      "name": "Rock_Basalt_Cobble"
    },
    {
      "x": -2,
      "y": 15,
      "z": -3,
      "name": "Rock_Basalt_Brick"
    },
    {
      "x": -2,
      "y": 16,
      "z": -3,
      "name": "Wood_Blackwood_Roof",
      "rotation": 3
    },
    {
      "x": -2,
      "y": 0,
      "z": -2,
      "name": "Rock_Basalt"
    },
    {
      "x": -2,
      "y": 1,
      "z": -2,
      "name": "Rock_Basalt"
    },
    {
      "x": -2,
      "y": 2,
      "z": -2,
      "name": "Rock_Basalt"
    },
    {
      "x": -2,
      "y": 3,
      "z": -2,
      "name": "Rock_Basalt_Cobble"
    },
    {
      "x": -2,
      "y": 4,
      "z": -2,
      "name": "Rock_Basalt_Cobble"
    },
    {
      "x": -2,
      "y": 5,
      "z": -2,
      "name": "Rock_Basalt_Cobble"
    },
    {
      "x": -2,
      "y": 6,
      "z": -2,
      "name": "Rock_Basalt_Cobble"
    },
    {
      "x": -2,
      "y": 7,
      "z": -2,
      "name": "Rock_Basalt_Brick"
    },
    {
      "x": -2,
      "y": 8,
      "z": -2,
      "name": "Rock_Basalt_Cobble"
    },
    {
      "x": -2,
      "y": 9,
      "z": -2,
      "name": "Rock_Basalt_Cobble"
    },
    {
      "x": -2,
      "y": 10,
      "z": -2,
      "name": "Rock_Basalt_Brick"
    },
    {
      "x": -2,
      "y": 11,
      "z": -2,
      "name": "Rock_Basalt_Brick"
    },
    {
      "x": -2,
      "y": 12,
      "z": -2,
      "name": "Rock_Basalt_Cobble"
    },
    {
      "x": -2,
      "y": 13,
      "z": -2,
      "name": "Rock_Basalt_Cobble"
    },
    {
      "x": -2,
      "y": 14,
      "z": -2,
      "name": "Rock_Basalt_Cobble"
    },
    {
      "x": -2,
      "y": 15,
      "z": -2,
      "name": "Rock_Basalt_Brick"
    },
    {
      "x": -2,
      "y": 16,
      "z": -2,
      "name": "Wood_Blackwood_Roof",
      "rotation": 3
    },
    {
      "x": -2,
      "y": 8,
      "z": -1,
      "name": "Empty"
    },
    {
      "x": -2,
      "y": 9,
      "z": -1,
      "name": "Empty"
    },
    {
      "x": -2,
      "y": 10,
      "z": -1,
      "name": "Empty"
    },
    {
      "x": -2,
      "y": 11,
      "z": -1,
      "name": "Wood_Blackwood_Planks"
    },
    {
      "x": -2,
      "y": 12,
      "z": -1,
      "name": "Rock_Basalt_Cobble"
    },
    {
      "x": -2,
      "y": 13,
      "z": -1,
      "name": "Rock_Basalt_Cobble"
    },
    {
      "x": -2,
      "y": 14,
      "z": -1,
      "name": "Rock_Basalt_Cobble"
    },
    {
      "x": -2,
      "y": 15,
      "z": -1,
      "name": "Rock_Basalt_Brick"
    },
    {
      "x": -2,
      "y": 16,
      "z": -1,
      "name": "Wood_Blackwood_Beam",
      "rotation": 4
    },
    {
      "x": -2,
      "y": 8,
      "z": 0,
      "name": "Empty"
    },
    {
      "x": -2,
      "y": 9,
      "z": 0,
      "name": "Empty"
    },
    {
      "x": -2,
      "y": 10,
      "z": 0,
      "name": "Empty"
    },
    {
      "x": -2,
      "y": 11,
      "z": 0,
      "name": "Empty"
    },
    {
      "x": -2,
      "y": 12,
      "z": 0,
      "name": "Rock_Basalt_Cobble"
    },
    {
      "x": -2,
      "y": 13,
      "z": 0,
      "name": "Empty"
    },
    {
      "x": -2,
      "y": 14,
      "z": 0,
      "name": "Rock_Basalt_Cobble"
    },
    {
      "x": -2,
      "y": 15,
      "z": 0,
      "name": "Empty"
    },
    {
      "x": -2,
      "y": 16,
      "z": 0,
      "name": "Wood_Blackwood_Beam",
      "rotation": 4
    },
    {
      "x": -2,
      "y": 8,
      "z": 1,
      "name": "Empty"
    },
    {
      "x": -2,
      "y": 9,
      "z": 1,
      "name": "Empty"
    },
    {
      "x": -2,
      "y": 10,
      "z": 1,
      "name": "Empty"
    },
    {
      "x": -2,
      "y": 11,
      "z": 1,
      "name": "Empty"
    },
    {
      "x": -2,
      "y": 12,
      "z": 1,
      "name": "Empty"
    },
    {
      "x": -2,
      "y": 13,
      "z": 1,
      "name": "Empty"
    },
    {
      "x": -2,
      "y": 14,
      "z": 1,
      "name": "Empty"
    },
    {
      "x": -2,
      "y": 15,
      "z": 1,
      "name": "Empty"
    },
    {
      "x": -2,
      "y": 4,
      "z": 2,
      "name": "Rock_Basalt_Cobble"
    },
    {
      "x": -2,
      "y": 5,
      "z": 2,
      "name": "Rock_Basalt_Cobble"
    },
    {
      "x": -2,
      "y": 6,
      "z": 2,
      "name": "Rock_Basalt_Cobble"
    },
    {
      "x": -2,
      "y": 7,
      "z": 2,
      "name": "Rock_Basalt_Brick"
    },
    {
      "x": -2,
      "y": 8,
      "z": 2,
      "name": "Rock_Basalt_Cobble"
    },
    {
      "x": -2,
      "y": 9,
      "z": 2,
      "name": "Rock_Basalt_Cobble"
    },
    {
      "x": -2,
      "y": 10,
      "z": 2,
      "name": "Rock_Basalt_Brick"
    },
    {
      "x": -2,
      "y": 11,
      "z": 2,
      "name": "Empty"
    },
    {
      "x": -2,
      "y": 12,
      "z": 2,
      "name": "Empty"
    },
    {
      "x": -2,
      "y": 13,
      "z": 2,
      "name": "Empty"
    },
    {
      "x": -2,
      "y": 14,
      "z": 2,
      "name": "Empty"
    },
    {
      "x": -2,
      "y": 15,
      "z": 2,
      "name": "Empty"
    },
    {
      "x": -2,
      "y": 3,
      "z": 3,
      "name": "Rock_Basalt"
    },
    {
      "x": -2,
      "y": 4,
      "z": 3,
      "name": "Rock_Basalt_Cobble"
    },
    {
      "x": -2,
      "y": 5,
      "z": 3,
      "name": "Rock_Basalt_Cobble"
    },
    {
      "x": -2,
      "y": 6,
      "z": 3,
      "name": "Rock_Basalt_Cobble"
    },
    {
      "x": -2,
      "y": 7,
      "z": 3,
      "name": "Rock_Basalt_Brick"
    },
    {
      "x": -2,
      "y": 11,
      "z": 3,
      "name": "Rock_Basalt_Brick"
    },
    {
      "x": -2,
      "y": 12,
      "z": 3,
      "name": "Empty"
    },
    {
      "x": -2,
      "y": 13,
      "z": 3,
      "name": "Empty"
    },
    {
      "x": -2,
      "y": 14,
      "z": 3,
      "name": "Empty"
    },
    {
      "x": -2,
      "y": 15,
      "z": 3,
      "name": "Empty"
    },
    {
      "x": -2,
      "y": 2,
      "z": 4,
      "name": "Rock_Basalt"
    },
    {
      "x": -2,
      "y": 3,
      "z": 4,
      "name": "Rock_Basalt"
    },
    {
      "x": -2,
      "y": 4,
      "z": 4,
      "name": "Rock_Basalt_Cobble"
    },
    {
      "x": -2,
      "y": 5,
      "z": 4,
      "name": "Rock_Basalt_Cobble"
    },
    {
      "x": -2,
      "y": 6,
      "z": 4,
      "name": "Rock_Basalt_Cobble"
    },
    {
      "x": -2,
      "y": 7,
      "z": 4,
      "name": "Rock_Basalt_Brick"
    },
    {
      "x": -2,
      "y": 11,
      "z": 4,
      "name": "Rock_Basalt_Brick"
    },
    {
      "x": -2,
      "y": 12,
      "z": 4,
      "name": "Rock_Basalt_Cobble"
    },
    {
      "x": -2,
      "y": 13,
      "z": 4,
      "name": "Furniture_Human_Ruins_Torch",
      "rotation": 1
    },
    {
      "x": -2,
      "y": 14,
      "z": 4,
      "name": "Empty"
    },
    {
      "x": -2,
      "y": 15,
      "z": 4,
      "name": "Empty"
    },
    {
      "x": -2,
      "y": 1,
      "z": 5,
      "name": "Rock_Basalt"
    },
    {
      "x": -2,
      "y": 2,
      "z": 5,
      "name": "Rock_Basalt"
    },
    {
      "x": -2,
      "y": 3,
      "z": 5,
      "name": "Rock_Basalt_Cobble"
    },
    {
      "x": -2,
      "y": 4,
      "z": 5,
      "name": "Rock_Basalt_Cobble"
    },
    {
      "x": -2,
      "y": 5,
      "z": 5,
      "name": "Rock_Basalt_Cobble"
    },
    {
      "x": -2,
      "y": 6,
      "z": 5,
      "name": "Rock_Basalt_Brick"
    },
    {
      "x": -2,
      "y": 7,
      "z": 5,
      "name": "Rock_Basalt_Brick"
    },
    {
      "x": -2,
      "y": 8,
      "z": 5,
      "name": "Rock_Basalt_Brick_Pillar_Base"
    },
    {
      "x": -2,
      "y": 9,
      "z": 5,
      "name": "Rock_Basalt_Brick_Pillar_Middle"
    },
    {
      "x": -2,
      "y": 10,
      "z": 5,
      "name": "Rock_Basalt_Brick_Pillar_Base",
      "rotation": 8
    },
    {
      "x": -2,
      "y": 11,
      "z": 5,
      "name": "Rock_Basalt_Brick_Decorative"
    },
    {
      "x": -2,
      "y": 12,
      "z": 5,
      "name": "Rock_Basalt_Brick"
    },
    {
      "x": -2,
      "y": 13,
      "z": 5,
      "name": "Rock_Basalt_Brick"
    },
    {
      "x": -2,
      "y": 14,
      "z": 5,
      "name": "Empty"
    },
    {
      "x": -2,
      "y": 15,
      "z": 5,
      "name": "Empty"
    },
    {
      "x": -2,
      "y": 11,
      "z": 6,
      "name": "Wood_Burnt_Branch_Long",
      "rotation": 4
    },
    {
      "x": -2,
      "y": 11,
      "z": 7,
      "name": "Wood_Burnt_Branch_Long",
      "rotation": 4
    },
    {
      "x": -1,
      "y": 15,
      "z": -6,
      "name": "Rock_Basalt_Brick_Half",
      "rotation": 6
    },
    {
      "x": -1,
      "y": 16,
      "z": -6,
      "name": "Wood_Blackwood_Planks"
    },
    {
      "x": -1,
      "y": 17,
      "z": -6,
      "name": "Wood_Blackwood_Roof",
      "rotation": 3
    },
    {
      "x": -1,
      "y": 0,
      "z": -5,
      "name": "Rock_Basalt"
    },
    {
      "x": -1,
      "y": 1,
      "z": -5,
      "name": "Rock_Basalt"
    },
    {
      "x": -1,
      "y": 2,
      "z": -5,
      "name": "Rock_Basalt"
    },
    {
      "x": -1,
      "y": 3,
      "z": -5,
      "name": "Rock_Basalt"
    },
    {
      "x": -1,
      "y": 4,
      "z": -5,
      "name": "Rock_Basalt_Cobble"
    },
    {
      "x": -1,
      "y": 5,
      "z": -5,
      "name": "Rock_Basalt_Cobble"
    },
    {
      "x": -1,
      "y": 6,
      "z": -5,
      "name": "Rock_Basalt_Cobble"
    },
    {
      "x": -1,
      "y": 8,
      "z": -5,
      "name": "Empty"
    },
    {
      "x": -1,
      "y": 9,
      "z": -5,
      "name": "Empty"
    },
    {
      "x": -1,
      "y": 10,
      "z": -5,
      "name": "Empty"
    },
    {
      "x": -1,
      "y": 11,
      "z": -5,
      "name": "Rock_Basalt_Brick"
    },
    {
      "x": -1,
      "y": 12,
      "z": -5,
      "name": "Wood_Deadwood_Decorative"
    },
    {
      "x": -1,
      "y": 13,
      "z": -5,
      "name": "Wood_Deadwood_Decorative"
    },
    {
      "x": -1,
      "y": 14,
      "z": -5,
      "name": "Wood_Deadwood_Decorative"
    },
    {
      "x": -1,
      "y": 15,
      "z": -5,
      "name": "Rock_Basalt_Brick"
    },
    {
      "x": -1,
      "y": 16,
      "z": -5,
      "name": "Wood_Blackwood_Planks"
    },
    {
      "x": -1,
      "y": 17,
      "z": -5,
      "name": "Wood_Blackwood_Roof",
      "rotation": 3
    },
    {
      "x": -1,
      "y": 0,
      "z": -4,
      "name": "Rock_Basalt"
    },
    {
      "x": -1,
      "y": 1,
      "z": -4,
      "name": "Rock_Basalt"
    },
    {
      "x": -1,
      "y": 2,
      "z": -4,
      "name": "Rock_Basalt"
    },
    {
      "x": -1,
      "y": 3,
      "z": -4,
      "name": "Rock_Basalt_Cobble"
    },
    {
      "x": -1,
      "y": 4,
      "z": -4,
      "name": "Rock_Basalt_Cobble"
    },
    {
      "x": -1,
      "y": 5,
      "z": -4,
      "name": "Rock_Basalt_Cobble"
    },
    {
      "x": -1,
      "y": 6,
      "z": -4,
      "name": "Rock_Basalt_Cobble"
    },
    {
      "x": -1,
      "y": 7,
      "z": -4,
      "name": "Rock_Basalt_Cobble"
    },
    {
      "x": -1,
      "y": 8,
      "z": -4,
      "name": "Empty"
    },
    {
      "x": -1,
      "y": 9,
      "z": -4,
      "name": "Rock_Basalt_Cobble"
    },
    {
      "x": -1,
      "y": 10,
      "z": -4,
      "name": "Rock_Basalt_Cobble"
    },
    {
      "x": -1,
      "y": 11,
      "z": -4,
      "name": "Wood_Blackwood_Planks"
    },
    {
      "x": -1,
      "y": 12,
      "z": -4,
      "name": "Furniture_Ancient_Crate"
    },
    {
      "x": -1,
      "y": 13,
      "z": -4,
      "name": "Empty"
    },
    {
      "x": -1,
      "y": 14,
      "z": -4,
      "name": "Empty"
    },
    {
      "x": -1,
      "y": 15,
      "z": -4,
      "name": "Empty"
    },
    {
      "x": -1,
      "y": 16,
      "z": -4,
      "name": "Empty"
    },
    {
      "x": -1,
      "y": 17,
      "z": -4,
      "name": "Wood_Blackwood_Beam",
      "rotation": 4
    },
    {
      "x": -1,
      "y": 0,
      "z": -3,
      "name": "Rock_Basalt"
    },
    {
      "x": -1,
      "y": 1,
      "z": -3,
      "name": "Rock_Basalt"
    },
    {
      "x": -1,
      "y": 2,
      "z": -3,
      "name": "Rock_Basalt"
    },
    {
      "x": -1,
      "y": 3,
      "z": -3,
      "name": "Rock_Basalt_Cobble"
    },
    {
      "x": -1,
      "y": 4,
      "z": -3,
      "name": "Rock_Basalt_Cobble"
    },
    {
      "x": -1,
      "y": 5,
      "z": -3,
      "name": "Rock_Basalt_Cobble"
    },
    {
      "x": -1,
      "y": 6,
      "z": -3,
      "name": "Rock_Basalt_Cobble"
    },
    {
      "x": -1,
      "y": 7,
      "z": -3,
      "name": "Rock_Basalt_Brick"
    },
    {
      "x": -1,
      "y": 8,
      "z": -3,
      "name": "Rock_Basalt_Cobble"
    },
    {
      "x": -1,
      "y": 9,
      "z": -3,
      "name": "Rock_Basalt_Cobble"
    },
    {
      "x": -1,
      "y": 10,
      "z": -3,
      "name": "Rock_Basalt_Cobble"
    },
    {
      "x": -1,
      "y": 11,
      "z": -3,
      "name": "Wood_Blackwood_Planks"
    },
    {
      "x": -1,
      "y": 12,
      "z": -3,
      "name": "Furniture_Ancient_Barrel"
    },
    {
      "x": -1,
      "y": 13,
      "z": -3,
      "name": "Empty"
    },
    {
      "x": -1,
      "y": 14,
      "z": -3,
      "name": "Empty"
    },
    {
      "x": -1,
      "y": 15,
      "z": -3,
      "name": "Empty"
    },
    {
      "x": -1,
      "y": 16,
      "z": -3,
      "name": "Empty"
    },
    {
      "x": -1,
      "y": 17,
      "z": -3,
      "name": "Wood_Blackwood_Beam",
      "rotation": 4
    },
    {
      "x": -1,
      "y": 0,
      "z": -2,
      "name": "Rock_Basalt"
    },
    {
      "x": -1,
      "y": 1,
      "z": -2,
      "name": "Rock_Basalt"
    },
    {
      "x": -1,
      "y": 2,
      "z": -2,
      "name": "Rock_Basalt"
    },
    {
      "x": -1,
      "y": 3,
      "z": -2,
      "name": "Rock_Basalt"
    },
    {
      "x": -1,
      "y": 4,
      "z": -2,
      "name": "Rock_Basalt_Cobble"
    },
    {
      "x": -1,
      "y": 5,
      "z": -2,
      "name": "Rock_Basalt_Cobble"
    },
    {
      "x": -1,
      "y": 6,
      "z": -2,
      "name": "Rock_Basalt_Cobble"
    },
    {
      "x": -1,
      "y": 7,
      "z": -2,
      "name": "Rock_Basalt_Brick"
    },
    {
      "x": -1,
      "y": 8,
      "z": -2,
      "name": "Empty"
    },
    {
      "x": -1,
      "y": 9,
      "z": -2,
      "name": "Empty"
    },
    {
      "x": -1,
      "y": 10,
      "z": -2,
      "name": "Empty"
    },
    {
      "x": -1,
      "y": 11,
      "z": -2,
      "name": "Wood_Blackwood_Planks"
    },
    {
      "x": -1,
      "y": 12,
      "z": -2,
      "name": "Empty"
    },
    {
      "x": -1,
      "y": 13,
      "z": -2,
      "name": "Empty"
    },
    {
      "x": -1,
      "y": 14,
      "z": -2,
      "name": "Empty"
    },
    {
      "x": -1,
      "y": 15,
      "z": -2,
      "name": "Empty"
    },
    {
      "x": -1,
      "y": 8,
      "z": -1,
      "name": "Empty"
    },
    {
      "x": -1,
      "y": 9,
      "z": -1,
      "name": "Empty"
    },
    {
      "x": -1,
      "y": 10,
      "z": -1,
      "name": "Empty"
    },
    {
      "x": -1,
      "y": 11,
      "z": -1,
      "name": "Empty"
    },
    {
      "x": -1,
      "y": 12,
      "z": -1,
      "name": "Empty"
    },
    {
      "x": -1,
      "y": 13,
      "z": -1,
      "name": "Empty"
    },
    {
      "x": -1,
      "y": 14,
      "z": -1,
      "name": "Empty"
    },
    {
      "x": -1,
      "y": 15,
      "z": -1,
      "name": "Empty"
    },
    {
      "x": -1,
      "y": 16,
      "z": -1,
      "name": "Empty"
    },
    {
      "x": -1,
      "y": 8,
      "z": 0,
      "name": "Empty"
    },
    {
      "x": -1,
      "y": 9,
      "z": 0,
      "name": "Empty"
    },
    {
      "x": -1,
      "y": 10,
      "z": 0,
      "name": "Empty"
    },
    {
      "x": -1,
      "y": 11,
      "z": 0,
      "name": "Empty"
    },
    {
      "x": -1,
      "y": 12,
      "z": 0,
      "name": "Empty"
    },
    {
      "x": -1,
      "y": 13,
      "z": 0,
      "name": "Empty"
    },
    {
      "x": -1,
      "y": 14,
      "z": 0,
      "name": "Empty"
    },
    {
      "x": -1,
      "y": 15,
      "z": 0,
      "name": "Empty"
    },
    {
      "x": -1,
      "y": 16,
      "z": 0,
      "name": "Empty"
    },
    {
      "x": -1,
      "y": 8,
      "z": 1,
      "name": "Empty"
    },
    {
      "x": -1,
      "y": 9,
      "z": 1,
      "name": "Empty"
    },
    {
      "x": -1,
      "y": 10,
      "z": 1,
      "name": "Empty"
    },
    {
      "x": -1,
      "y": 11,
      "z": 1,
      "name": "Empty"
    },
    {
      "x": -1,
      "y": 12,
      "z": 1,
      "name": "Empty"
    },
    {
      "x": -1,
      "y": 13,
      "z": 1,
      "name": "Empty"
    },
    {
      "x": -1,
      "y": 14,
      "z": 1,
      "name": "Empty"
    },
    {
      "x": -1,
      "y": 15,
      "z": 1,
      "name": "Empty"
    },
    {
      "x": -1,
      "y": 16,
      "z": 1,
      "name": "Empty"
    },
    {
      "x": -1,
      "y": 8,
      "z": 2,
      "name": "Empty"
    },
    {
      "x": -1,
      "y": 9,
      "z": 2,
      "name": "Empty"
    },
    {
      "x": -1,
      "y": 10,
      "z": 2,
      "name": "Empty"
    },
    {
      "x": -1,
      "y": 11,
      "z": 2,
      "name": "Empty"
    },
    {
      "x": -1,
      "y": 12,
      "z": 2,
      "name": "Empty"
    },
    {
      "x": -1,
      "y": 13,
      "z": 2,
      "name": "Empty"
    },
    {
      "x": -1,
      "y": 14,
      "z": 2,
      "name": "Empty"
    },
    {
      "x": -1,
      "y": 15,
      "z": 2,
      "name": "Empty"
    },
    {
      "x": -1,
      "y": 16,
      "z": 2,
      "name": "Empty"
    },
    {
      "x": -1,
      "y": 5,
      "z": 3,
      "name": "Rock_Basalt_Cobble"
    },
    {
      "x": -1,
      "y": 6,
      "z": 3,
      "name": "Rock_Basalt_Cobble"
    },
    {
      "x": -1,
      "y": 7,
      "z": 3,
      "name": "Rock_Basalt_Brick"
    },
    {
      "x": -1,
      "y": 8,
      "z": 3,
      "name": "Rock_Basalt_Cobble"
    },
    {
      "x": -1,
      "y": 9,
      "z": 3,
      "name": "Rock_Basalt_Cobble"
    },
    {
      "x": -1,
      "y": 10,
      "z": 3,
      "name": "Rock_Basalt_Cobble"
    },
    {
      "x": -1,
      "y": 11,
      "z": 3,
      "name": "Wood_Blackwood_Planks"
    },
    {
      "x": -1,
      "y": 12,
      "z": 3,
      "name": "Empty"
    },
    {
      "x": -1,
      "y": 13,
      "z": 3,
      "name": "Empty"
    },
    {
      "x": -1,
      "y": 14,
      "z": 3,
      "name": "Empty"
    },
    {
      "x": -1,
      "y": 15,
      "z": 3,
      "name": "Empty"
    },
    {
      "x": -1,
      "y": 16,
      "z": 3,
      "name": "Empty"
    },
    {
      "x": -1,
      "y": 2,
      "z": 4,
      "name": "Rock_Basalt_Cobble"
    },
    {
      "x": -1,
      "y": 3,
      "z": 4,
      "name": "Rock_Basalt_Cobble"
    },
    {
      "x": -1,
      "y": 4,
      "z": 4,
      "name": "Rock_Basalt_Cobble"
    },
    {
      "x": -1,
      "y": 5,
      "z": 4,
      "name": "Rock_Basalt_Cobble"
    },
    {
      "x": -1,
      "y": 6,
      "z": 4,
      "name": "Rock_Basalt_Cobble"
    },
    {
      "x": -1,
      "y": 7,
      "z": 4,
      "name": "Rock_Basalt_Cobble"
    },
    {
      "x": -1,
      "y": 8,
      "z": 4,
      "name": "Rock_Basalt_Cobble"
    },
    {
      "x": -1,
      "y": 9,
      "z": 4,
      "name": "Rock_Basalt_Cobble"
    },
    {
      "x": -1,
      "y": 10,
      "z": 4,
      "name": "Rock_Basalt_Cobble"
    },
    {
      "x": -1,
      "y": 11,
      "z": 4,
      "name": "Wood_Blackwood_Planks"
    },
    {
      "x": -1,
      "y": 12,
      "z": 4,
      "name": "Block_Spawner_Block",
      "components": {
        "Components": {
          "PlacedByInteraction": {
            "WhoPlacedUuid": {
              "$binary": "aUCWNEUFMdyp6PAeBilfUQ==",
              "$type": "04"
            }
          },
          "BlockSpawner": {
            "BlockSpawnerId": "Zone4_Undead_Tier2"
          }
        }
      },
      "rotation": 2
    },
    {
      "x": -1,
      "y": 13,
      "z": 4,
      "name": "Empty"
    },
    {
      "x": -1,
      "y": 14,
      "z": 4,
      "name": "Empty"
    },
    {
      "x": -1,
      "y": 15,
      "z": 4,
      "name": "Empty"
    },
    {
      "x": -1,
      "y": 16,
      "z": 4,
      "name": "Empty"
    },
    {
      "x": -1,
      "y": 1,
      "z": 5,
      "name": "Rock_Basalt"
    },
    {
      "x": -1,
      "y": 2,
      "z": 5,
      "name": "Rock_Basalt"
    },
    {
      "x": -1,
      "y": 3,
      "z": 5,
      "name": "Rock_Basalt"
    },
    {
      "x": -1,
      "y": 4,
      "z": 5,
      "name": "Rock_Basalt_Cobble"
    },
    {
      "x": -1,
      "y": 5,
      "z": 5,
      "name": "Rock_Basalt_Cobble"
    },
    {
      "x": -1,
      "y": 6,
      "z": 5,
      "name": "Rock_Basalt_Brick"
    },
    {
      "x": -1,
      "y": 7,
      "z": 5,
      "name": "Rock_Basalt_Brick"
    },
    {
      "x": -1,
      "y": 11,
      "z": 5,
      "name": "Rock_Basalt_Brick"
    },
    {
      "x": -1,
      "y": 12,
      "z": 5,
      "name": "Wood_Deadwood_Decorative"
    },
    {
      "x": -1,
      "y": 13,
      "z": 5,
      "name": "Wood_Deadwood_Decorative"
    },
    {
      "x": -1,
      "y": 14,
      "z": 5,
      "name": "Empty"
    },
    {
      "x": -1,
      "y": 15,
      "z": 5,
      "name": "Empty"
    },
    {
      "x": 0,
      "y": 15,
      "z": -6,
      "name": "Rock_Basalt_Brick_Half",
      "rotation": 6
    },
    {
      "x": 0,
      "y": 16,
      "z": -6,
      "name": "Wood_Blackwood_Planks"
    },
    {
      "x": 0,
      "y": 17,
      "z": -6,
      "name": "Wood_Blackwood_Planks"
    },
    {
      "x": 0,
      "y": 18,
      "z": -6,
      "name": "Wood_Blackwood_Roof",
      "rotation": 3
    },
    {
      "x": 0,
      "y": 8,
      "z": -5,
      "name": "Empty"
    },
    {
      "x": 0,
      "y": 9,
      "z": -5,
      "name": "Empty"
    },
    {
      "x": 0,
      "y": 10,
      "z": -5,
      "name": "Empty"
    },
    {
      "x": 0,
      "y": 11,
      "z": -5,
      "name": "Rock_Basalt_Brick"
    },
    {
      "x": 0,
      "y": 12,
      "z": -5,
      "name": "Furniture_Human_Ruins_Window"
    },
    {
      "x": 0,
      "y": 13,
      "z": -5,
      "name": "Furniture_Human_Ruins_Window"
    },
    {
      "x": 0,
      "y": 14,
      "z": -5,
      "name": "Wood_Deadwood_Decorative"
    },
    {
      "x": 0,
      "y": 15,
      "z": -5,
      "name": "Rock_Basalt_Brick"
    },
    {
      "x": 0,
      "y": 16,
      "z": -5,
      "name": "Wood_Blackwood_Planks"
    },
    {
      "x": 0,
      "y": 17,
      "z": -5,
      "name": "Wood_Blackwood_Planks"
    },
    {
      "x": 0,
      "y": 18,
      "z": -5,
      "name": "Wood_Blackwood_Roof",
      "rotation": 3
    },
    {
      "x": 0,
      "y": 8,
      "z": -4,
      "name": "Empty"
    },
    {
      "x": 0,
      "y": 9,
      "z": -4,
      "name": "Empty"
    },
    {
      "x": 0,
      "y": 10,
      "z": -4,
      "name": "Rock_Basalt_Cobble"
    },
    {
      "x": 0,
      "y": 11,
      "z": -4,
      "name": "Wood_Blackwood_Planks"
    },
    {
      "x": 0,
      "y": 12,
      "z": -4,
      "name": "Furniture_Ancient_Barrel"
    },
    {
      "x": 0,
      "y": 13,
      "z": -4,
      "name": "Empty"
    },
    {
      "x": 0,
      "y": 14,
      "z": -4,
      "name": "Empty"
    },
    {
      "x": 0,
      "y": 15,
      "z": -4,
      "name": "Empty"
    },
    {
      "x": 0,
      "y": 16,
      "z": -4,
      "name": "Empty"
    },
    {
      "x": 0,
      "y": 18,
      "z": -4,
      "name": "Wood_Blackwood_Roof_Hollow",
      "rotation": 3
    },
    {
      "x": 0,
      "y": 8,
      "z": -3,
      "name": "Empty"
    },
    {
      "x": 0,
      "y": 9,
      "z": -3,
      "name": "Empty"
    },
    {
      "x": 0,
      "y": 10,
      "z": -3,
      "name": "Empty"
    },
    {
      "x": 0,
      "y": 11,
      "z": -3,
      "name": "Wood_Deadwood_Planks"
    },
    {
      "x": 0,
      "y": 12,
      "z": -3,
      "name": "Empty"
    },
    {
      "x": 0,
      "y": 13,
      "z": -3,
      "name": "Empty"
    },
    {
      "x": 0,
      "y": 14,
      "z": -3,
      "name": "Empty"
    },
    {
      "x": 0,
      "y": 15,
      "z": -3,
      "name": "Empty"
    },
    {
      "x": 0,
      "y": 16,
      "z": -3,
      "name": "Empty"
    },
    {
      "x": 0,
      "y": 17,
      "z": -3,
      "name": "Empty"
    },
    {
      "x": 0,
      "y": 18,
      "z": -3,
      "name": "Wood_Blackwood_Beam",
      "rotation": 4
    },
    {
      "x": 0,
      "y": 8,
      "z": -2,
      "name": "Empty"
    },
    {
      "x": 0,
      "y": 9,
      "z": -2,
      "name": "Empty"
    },
    {
      "x": 0,
      "y": 10,
      "z": -2,
      "name": "Empty"
    },
    {
      "x": 0,
      "y": 11,
      "z": -2,
      "name": "Empty"
    },
    {
      "x": 0,
      "y": 12,
      "z": -2,
      "name": "Empty"
    },
    {
      "x": 0,
      "y": 13,
      "z": -2,
      "name": "Empty"
    },
    {
      "x": 0,
      "y": 14,
      "z": -2,
      "name": "Empty"
    },
    {
      "x": 0,
      "y": 15,
      "z": -2,
      "name": "Empty"
    },
    {
      "x": 0,
      "y": 16,
      "z": -2,
      "name": "Empty"
    },
    {
      "x": 0,
      "y": 17,
      "z": -2,
      "name": "Empty"
    },
    {
      "x": 0,
      "y": 8,
      "z": -1,
      "name": "Empty"
    },
    {
      "x": 0,
      "y": 9,
      "z": -1,
      "name": "Empty"
    },
    {
      "x": 0,
      "y": 10,
      "z": -1,
      "name": "Empty"
    },
    {
      "x": 0,
      "y": 11,
      "z": -1,
      "name": "Empty"
    },
    {
      "x": 0,
      "y": 12,
      "z": -1,
      "name": "Empty"
    },
    {
      "x": 0,
      "y": 13,
      "z": -1,
      "name": "Empty"
    },
    {
      "x": 0,
      "y": 14,
      "z": -1,
      "name": "Empty"
    },
    {
      "x": 0,
      "y": 15,
      "z": -1,
      "name": "Empty"
    },
    {
      "x": 0,
      "y": 16,
      "z": -1,
      "name": "Empty"
    },
    {
      "x": 0,
      "y": 17,
      "z": -1,
      "name": "Empty"
    },
    {
      "x": 0,
      "y": 8,
      "z": 0,
      "name": "Empty"
    },
    {
      "x": 0,
      "y": 9,
      "z": 0,
      "name": "Empty"
    },
    {
      "x": 0,
      "y": 10,
      "z": 0,
      "name": "Empty"
    },
    {
      "x": 0,
      "y": 11,
      "z": 0,
      "name": "Empty"
    },
    {
      "x": 0,
      "y": 12,
      "z": 0,
      "name": "Empty"
    },
    {
      "x": 0,
      "y": 13,
      "z": 0,
      "name": "Empty"
    },
    {
      "x": 0,
      "y": 14,
      "z": 0,
      "name": "Empty"
    },
    {
      "x": 0,
      "y": 15,
      "z": 0,
      "name": "Empty"
    },
    {
      "x": 0,
      "y": 16,
      "z": 0,
      "name": "Empty"
    },
    {
      "x": 0,
      "y": 17,
      "z": 0,
      "name": "Empty"
    },
    {
      "x": 0,
      "y": 8,
      "z": 1,
      "name": "Empty"
    },
    {
      "x": 0,
      "y": 9,
      "z": 1,
      "name": "Empty"
    },
    {
      "x": 0,
      "y": 10,
      "z": 1,
      "name": "Empty"
    },
    {
      "x": 0,
      "y": 11,
      "z": 1,
      "name": "Empty"
    },
    {
      "x": 0,
      "y": 12,
      "z": 1,
      "name": "Empty"
    },
    {
      "x": 0,
      "y": 13,
      "z": 1,
      "name": "Empty"
    },
    {
      "x": 0,
      "y": 14,
      "z": 1,
      "name": "Empty"
    },
    {
      "x": 0,
      "y": 15,
      "z": 1,
      "name": "Empty"
    },
    {
      "x": 0,
      "y": 16,
      "z": 1,
      "name": "Empty"
    },
    {
      "x": 0,
      "y": 17,
      "z": 1,
      "name": "Empty"
    },
    {
      "x": 0,
      "y": 8,
      "z": 2,
      "name": "Furniture_Human_Ruins_Ladder",
      "rotation": 2
    },
    {
      "x": 0,
      "y": 9,
      "z": 2,
      "name": "Furniture_Human_Ruins_Ladder",
      "rotation": 2
    },
    {
      "x": 0,
      "y": 10,
      "z": 2,
      "name": "Furniture_Human_Ruins_Ladder",
      "rotation": 2
    },
    {
      "x": 0,
      "y": 11,
      "z": 2,
      "name": "Furniture_Human_Ruins_Ladder",
      "rotation": 2
    },
    {
      "x": 0,
      "y": 12,
      "z": 2,
      "name": "Empty"
    },
    {
      "x": 0,
      "y": 13,
      "z": 2,
      "name": "Empty"
    },
    {
      "x": 0,
      "y": 14,
      "z": 2,
      "name": "Empty"
    },
    {
      "x": 0,
      "y": 15,
      "z": 2,
      "name": "Empty"
    },
    {
      "x": 0,
      "y": 16,
      "z": 2,
      "name": "Empty"
    },
    {
      "x": 0,
      "y": 17,
      "z": 2,
      "name": "Empty"
    },
    {
      "x": 0,
      "y": 8,
      "z": 3,
      "name": "Empty"
    },
    {
      "x": 0,
      "y": 9,
      "z": 3,
      "name": "Empty"
    },
    {
      "x": 0,
      "y": 10,
      "z": 3,
      "name": "Empty"
    },
    {
      "x": 0,
      "y": 11,
      "z": 3,
      "name": "Wood_Blackwood_Planks"
    },
    {
      "x": 0,
      "y": 12,
      "z": 3,
      "name": "Empty"
    },
    {
      "x": 0,
      "y": 13,
      "z": 3,
      "name": "Empty"
    },
    {
      "x": 0,
      "y": 14,
      "z": 3,
      "name": "Empty"
    },
    {
      "x": 0,
      "y": 15,
      "z": 3,
      "name": "Empty"
    },
    {
      "x": 0,
      "y": 16,
      "z": 3,
      "name": "Empty"
    },
    {
      "x": 0,
      "y": 17,
      "z": 3,
      "name": "Empty"
    },
    {
      "x": 0,
      "y": 2,
      "z": 4,
      "name": "Rock_Basalt_Cobble"
    },
    {
      "x": 0,
      "y": 3,
      "z": 4,
      "name": "Rock_Basalt_Cobble"
    },
    {
      "x": 0,
      "y": 4,
      "z": 4,
      "name": "Rock_Basalt_Cobble"
    },
    {
      "x": 0,
      "y": 5,
      "z": 4,
      "name": "Rock_Basalt_Cobble"
    },
    {
      "x": 0,
      "y": 6,
      "z": 4,
      "name": "Rock_Basalt_Cobble"
    },
    {
      "x": 0,
      "y": 7,
      "z": 4,
      "name": "Rock_Basalt_Cobble"
    },
    {
      "x": 0,
      "y": 8,
      "z": 4,
      "name": "Rock_Basalt_Cobble"
    },
    {
      "x": 0,
      "y": 9,
      "z": 4,
      "name": "Rock_Basalt_Cobble"
    },
    {
      "x": 0,
      "y": 10,
      "z": 4,
      "name": "Rock_Basalt_Cobble"
    },
    {
      "x": 0,
      "y": 11,
      "z": 4,
      "name": "Wood_Blackwood_Planks"
    },
    {
      "x": 0,
      "y": 12,
      "z": 4,
      "name": "Empty"
    },
    {
      "x": 0,
      "y": 13,
      "z": 4,
      "name": "Empty"
    },
    {
      "x": 0,
      "y": 14,
      "z": 4,
      "name": "Empty"
    },
    {
      "x": 0,
      "y": 15,
      "z": 4,
      "name": "Empty"
    },
    {
      "x": 0,
      "y": 16,
      "z": 4,
      "name": "Empty"
    },
    {
      "x": 0,
      "y": 17,
      "z": 4,
      "name": "Empty"
    },
    {
      "x": 0,
      "y": 1,
      "z": 5,
      "name": "Rock_Basalt"
    },
    {
      "x": 0,
      "y": 2,
      "z": 5,
      "name": "Rock_Basalt"
    },
    {
      "x": 0,
      "y": 3,
      "z": 5,
      "name": "Rock_Basalt"
    },
    {
      "x": 0,
      "y": 4,
      "z": 5,
      "name": "Rock_Basalt_Cobble"
    },
    {
      "x": 0,
      "y": 5,
      "z": 5,
      "name": "Rock_Basalt_Cobble"
    },
    {
      "x": 0,
      "y": 6,
      "z": 5,
      "name": "Rock_Basalt_Cobble"
    },
    {
      "x": 0,
      "y": 7,
      "z": 5,
      "name": "Rock_Basalt_Brick"
    },
    {
      "x": 0,
      "y": 11,
      "z": 5,
      "name": "Rock_Basalt_Brick"
    },
    {
      "x": 0,
      "y": 12,
      "z": 5,
      "name": "Wood_Deadwood_Decorative"
    },
    {
      "x": 0,
      "y": 13,
      "z": 5,
      "name": "Wood_Deadwood_Decorative"
    },
    {
      "x": 0,
      "y": 14,
      "z": 5,
      "name": "Wood_Deadwood_Decorative"
    },
    {
      "x": 0,
      "y": 15,
      "z": 5,
      "name": "Rock_Basalt_Brick"
    },
    {
      "x": 0,
      "y": 16,
      "z": 5,
      "name": "Wood_Blackwood_Planks"
    },
    {
      "x": 0,
      "y": 17,
      "z": 5,
      "name": "Wood_Blackwood_Planks"
    },
    {
      "x": 0,
      "y": 15,
      "z": 6,
      "name": "Rock_Basalt_Brick_Half",
      "rotation": 4
    },
    {
      "x": 0,
      "y": 16,
      "z": 6,
      "name": "Wood_Blackwood_Planks"
    },
    {
      "x": 1,
      "y": 15,
      "z": -6,
      "name": "Rock_Basalt_Brick_Half",
      "rotation": 6
    },
    {
      "x": 1,
      "y": 16,
      "z": -6,
      "name": "Wood_Blackwood_Planks"
    },
    {
      "x": 1,
      "y": 17,
      "z": -6,
      "name": "Wood_Blackwood_Planks"
    },
    {
      "x": 1,
      "y": 18,
      "z": -6,
      "name": "Wood_Blackwood_Planks"
    },
    {
      "x": 1,
      "y": 19,
      "z": -6,
      "name": "Wood_Blackwood_Roof_Flat",
      "rotation": 3
    },
    {
      "x": 1,
      "y": 8,
      "z": -5,
      "name": "Empty"
    },
    {
      "x": 1,
      "y": 9,
      "z": -5,
      "name": "Empty"
    },
    {
      "x": 1,
      "y": 10,
      "z": -5,
      "name": "Empty"
    },
    {
      "x": 1,
      "y": 11,
      "z": -5,
      "name": "Rock_Basalt_Brick_Decorative"
    },
    {
      "x": 1,
      "y": 12,
      "z": -5,
      "name": "Wood_Deadwood_Decorative"
    },
    {
      "x": 1,
      "y": 13,
      "z": -5,
      "name": "Wood_Deadwood_Decorative"
    },
    {
      "x": 1,
      "y": 14,
      "z": -5,
      "name": "Wood_Deadwood_Decorative"
    },
    {
      "x": 1,
      "y": 15,
      "z": -5,
      "name": "Rock_Basalt_Brick"
    },
    {
      "x": 1,
      "y": 16,
      "z": -5,
      "name": "Wood_Blackwood_Planks"
    },
    {
      "x": 1,
      "y": 17,
      "z": -5,
      "name": "Wood_Blackwood_Planks"
    },
    {
      "x": 1,
      "y": 18,
      "z": -5,
      "name": "Wood_Blackwood_Planks"
    },
    {
      "x": 1,
      "y": 19,
      "z": -5,
      "name": "Wood_Blackwood_Roof_Flat",
      "rotation": 3
    },
    {
      "x": 1,
      "y": 8,
      "z": -4,
      "name": "Empty"
    },
    {
      "x": 1,
      "y": 9,
      "z": -4,
      "name": "Empty"
    },
    {
      "x": 1,
      "y": 10,
      "z": -4,
      "name": "Empty"
    },
    {
      "x": 1,
      "y": 11,
      "z": -4,
      "name": "Wood_Blackwood_Planks"
    },
    {
      "x": 1,
      "y": 12,
      "z": -4,
      "name": "Empty"
    },
    {
      "x": 1,
      "y": 13,
      "z": -4,
      "name": "Empty"
    },
    {
      "x": 1,
      "y": 14,
      "z": -4,
      "name": "Empty"
    },
    {
      "x": 1,
      "y": 15,
      "z": -4,
      "name": "Empty"
    },
    {
      "x": 1,
      "y": 16,
      "z": -4,
      "name": "Empty"
    },
    {
      "x": 1,
      "y": 18,
      "z": -4,
      "name": "Wood_Burnt_Branch_Long",
      "rotation": 4
    },
    {
      "x": 1,
      "y": 19,
      "z": -4,
      "name": "Wood_Blackwood_Roof_Flat",
      "rotation": 1
    },
    {
      "x": 1,
      "y": 8,
      "z": -3,
      "name": "Empty"
    },
    {
      "x": 1,
      "y": 9,
      "z": -3,
      "name": "Empty"
    },
    {
      "x": 1,
      "y": 10,
      "z": -3,
      "name": "Empty"
    },
    {
      "x": 1,
      "y": 11,
      "z": -3,
      "name": "Wood_Deadwood_Planks"
    },
    {
      "x": 1,
      "y": 12,
      "z": -3,
      "name": "Empty"
    },
    {
      "x": 1,
      "y": 13,
      "z": -3,
      "name": "Empty"
    },
    {
      "x": 1,
      "y": 14,
      "z": -3,
      "name": "Empty"
    },
    {
      "x": 1,
      "y": 15,
      "z": -3,
      "name": "Empty"
    },
    {
      "x": 1,
      "y": 16,
      "z": -3,
      "name": "Empty"
    },
    {
      "x": 1,
      "y": 17,
      "z": -3,
      "name": "Empty"
    },
    {
      "x": 1,
      "y": 18,
      "z": -3,
      "name": "Wood_Burnt_Branch_Long",
      "rotation": 4
    },
    {
      "x": 1,
      "y": 8,
      "z": -2,
      "name": "Empty"
    },
    {
      "x": 1,
      "y": 9,
      "z": -2,
      "name": "Empty"
    },
    {
      "x": 1,
      "y": 10,
      "z": -2,
      "name": "Empty"
    },
    {
      "x": 1,
      "y": 11,
      "z": -2,
      "name": "Furniture_Ancient_Platform"
    },
    {
      "x": 1,
      "y": 12,
      "z": -2,
      "name": "Empty"
    },
    {
      "x": 1,
      "y": 13,
      "z": -2,
      "name": "Empty"
    },
    {
      "x": 1,
      "y": 14,
      "z": -2,
      "name": "Empty"
    },
    {
      "x": 1,
      "y": 15,
      "z": -2,
      "name": "Empty"
    },
    {
      "x": 1,
      "y": 16,
      "z": -2,
      "name": "Empty"
    },
    {
      "x": 1,
      "y": 17,
      "z": -2,
      "name": "Empty"
    },
    {
      "x": 1,
      "y": 18,
      "z": -2,
      "name": "Wood_Burnt_Branch_Long",
      "rotation": 4
    },
    {
      "x": 1,
      "y": 8,
      "z": -1,
      "name": "Empty"
    },
    {
      "x": 1,
      "y": 9,
      "z": -1,
      "name": "Empty"
    },
    {
      "x": 1,
      "y": 10,
      "z": -1,
      "name": "Empty"
    },
    {
      "x": 1,
      "y": 11,
      "z": -1,
      "name": "Furniture_Ancient_Platform"
    },
    {
      "x": 1,
      "y": 12,
      "z": -1,
      "name": "Empty"
    },
    {
      "x": 1,
      "y": 13,
      "z": -1,
      "name": "Empty"
    },
    {
      "x": 1,
      "y": 14,
      "z": -1,
      "name": "Empty"
    },
    {
      "x": 1,
      "y": 15,
      "z": -1,
      "name": "Empty"
    },
    {
      "x": 1,
      "y": 16,
      "z": -1,
      "name": "Empty"
    },
    {
      "x": 1,
      "y": 17,
      "z": -1,
      "name": "Empty"
    },
    {
      "x": 1,
      "y": 18,
      "z": -1,
      "name": "Wood_Burnt_Branch_Long",
      "rotation": 4
    },
    {
      "x": 1,
      "y": 8,
      "z": 0,
      "name": "Empty"
    },
    {
      "x": 1,
      "y": 9,
      "z": 0,
      "name": "Empty"
    },
    {
      "x": 1,
      "y": 10,
      "z": 0,
      "name": "Empty"
    },
    {
      "x": 1,
      "y": 11,
      "z": 0,
      "name": "Furniture_Ancient_Platform"
    },
    {
      "x": 1,
      "y": 12,
      "z": 0,
      "name": "Empty"
    },
    {
      "x": 1,
      "y": 13,
      "z": 0,
      "name": "Empty"
    },
    {
      "x": 1,
      "y": 14,
      "z": 0,
      "name": "Empty"
    },
    {
      "x": 1,
      "y": 15,
      "z": 0,
      "name": "Empty"
    },
    {
      "x": 1,
      "y": 16,
      "z": 0,
      "name": "Empty"
    },
    {
      "x": 1,
      "y": 17,
      "z": 0,
      "name": "Empty"
    },
    {
      "x": 1,
      "y": 8,
      "z": 1,
      "name": "Empty"
    },
    {
      "x": 1,
      "y": 9,
      "z": 1,
      "name": "Empty"
    },
    {
      "x": 1,
      "y": 10,
      "z": 1,
      "name": "Empty"
    },
    {
      "x": 1,
      "y": 11,
      "z": 1,
      "name": "Empty"
    },
    {
      "x": 1,
      "y": 12,
      "z": 1,
      "name": "Empty"
    },
    {
      "x": 1,
      "y": 13,
      "z": 1,
      "name": "Empty"
    },
    {
      "x": 1,
      "y": 14,
      "z": 1,
      "name": "Empty"
    },
    {
      "x": 1,
      "y": 15,
      "z": 1,
      "name": "Empty"
    },
    {
      "x": 1,
      "y": 16,
      "z": 1,
      "name": "Empty"
    },
    {
      "x": 1,
      "y": 17,
      "z": 1,
      "name": "Empty"
    },
    {
      "x": 1,
      "y": 8,
      "z": 2,
      "name": "Empty"
    },
    {
      "x": 1,
      "y": 9,
      "z": 2,
      "name": "Empty"
    },
    {
      "x": 1,
      "y": 10,
      "z": 2,
      "name": "Empty"
    },
    {
      "x": 1,
      "y": 11,
      "z": 2,
      "name": "Wood_Deadwood_Planks"
    },
    {
      "x": 1,
      "y": 12,
      "z": 2,
      "name": "Empty"
    },
    {
      "x": 1,
      "y": 13,
      "z": 2,
      "name": "Empty"
    },
    {
      "x": 1,
      "y": 14,
      "z": 2,
      "name": "Empty"
    },
    {
      "x": 1,
      "y": 15,
      "z": 2,
      "name": "Empty"
    },
    {
      "x": 1,
      "y": 16,
      "z": 2,
      "name": "Empty"
    },
    {
      "x": 1,
      "y": 17,
      "z": 2,
      "name": "Empty"
    },
    {
      "x": 1,
      "y": 19,
      "z": 2,
      "name": "Wood_Blackwood_Roof_Flat",
      "rotation": 1
    },
    {
      "x": 1,
      "y": 8,
      "z": 3,
      "name": "Empty"
    },
    {
      "x": 1,
      "y": 9,
      "z": 3,
      "name": "Empty"
    },
    {
      "x": 1,
      "y": 10,
      "z": 3,
      "name": "Empty"
    },
    {
      "x": 1,
      "y": 11,
      "z": 3,
      "name": "Wood_Blackwood_Planks"
    },
    {
      "x": 1,
      "y": 12,
      "z": 3,
      "name": "Empty"
    },
    {
      "x": 1,
      "y": 13,
      "z": 3,
      "name": "Empty"
    },
    {
      "x": 1,
      "y": 14,
      "z": 3,
      "name": "Empty"
    },
    {
      "x": 1,
      "y": 15,
      "z": 3,
      "name": "Empty"
    },
    {
      "x": 1,
      "y": 16,
      "z": 3,
      "name": "Empty"
    },
    {
      "x": 1,
      "y": 17,
      "z": 3,
      "name": "Empty"
    },
    {
      "x": 1,
      "y": 19,
      "z": 3,
      "name": "Wood_Blackwood_Roof_Flat",
      "rotation": 1
    },
    {
      "x": 1,
      "y": 2,
      "z": 4,
      "name": "Rock_Basalt_Cobble"
    },
    {
      "x": 1,
      "y": 3,
      "z": 4,
      "name": "Rock_Basalt_Cobble"
    },
    {
      "x": 1,
      "y": 4,
      "z": 4,
      "name": "Rock_Basalt_Cobble"
    },
    {
      "x": 1,
      "y": 5,
      "z": 4,
      "name": "Rock_Basalt_Cobble"
    },
    {
      "x": 1,
      "y": 6,
      "z": 4,
      "name": "Rock_Basalt_Cobble"
    },
    {
      "x": 1,
      "y": 7,
      "z": 4,
      "name": "Rock_Basalt_Brick"
    },
    {
      "x": 1,
      "y": 8,
      "z": 4,
      "name": "Rock_Basalt_Cobble"
    },
    {
      "x": 1,
      "y": 9,
      "z": 4,
      "name": "Rock_Basalt_Cobble"
    },
    {
      "x": 1,
      "y": 10,
      "z": 4,
      "name": "Rock_Basalt_Cobble"
    },
    {
      "x": 1,
      "y": 11,
      "z": 4,
      "name": "Wood_Blackwood_Planks"
    },
    {
      "x": 1,
      "y": 12,
      "z": 4,
      "name": "Empty"
    },
    {
      "x": 1,
      "y": 13,
      "z": 4,
      "name": "Empty"
    },
    {
      "x": 1,
      "y": 14,
      "z": 4,
      "name": "Empty"
    },
    {
      "x": 1,
      "y": 15,
      "z": 4,
      "name": "Empty"
    },
    {
      "x": 1,
      "y": 16,
      "z": 4,
      "name": "Empty"
    },
    {
      "x": 1,
      "y": 17,
      "z": 4,
      "name": "Empty"
    },
    {
      "x": 1,
      "y": 19,
      "z": 4,
      "name": "Wood_Blackwood_Roof_Flat",
      "rotation": 1
    },
    {
      "x": 1,
      "y": 0,
      "z": 5,
      "name": "Rock_Basalt"
    },
    {
      "x": 1,
      "y": 1,
      "z": 5,
      "name": "Rock_Basalt"
    },
    {
      "x": 1,
      "y": 2,
      "z": 5,
      "name": "Rock_Basalt"
    },
    {
      "x": 1,
      "y": 3,
      "z": 5,
      "name": "Rock_Basalt"
    },
    {
      "x": 1,
      "y": 4,
      "z": 5,
      "name": "Rock_Basalt_Cobble"
    },
    {
      "x": 1,
      "y": 5,
      "z": 5,
      "name": "Rock_Basalt_Cobble"
    },
    {
      "x": 1,
      "y": 6,
      "z": 5,
      "name": "Rock_Basalt_Cobble"
    },
    {
      "x": 1,
      "y": 7,
      "z": 5,
      "name": "Rock_Basalt_Cobble"
    },
    {
      "x": 1,
      "y": 8,
      "z": 5,
      "name": "Rock_Basalt_Brick_Pillar_Base"
    },
    {
      "x": 1,
      "y": 9,
      "z": 5,
      "name": "Rock_Basalt_Brick_Pillar_Middle"
    },
    {
      "x": 1,
      "y": 10,
      "z": 5,
      "name": "Rock_Basalt_Brick_Pillar_Base",
      "rotation": 8
    },
    {
      "x": 1,
      "y": 11,
      "z": 5,
      "name": "Rock_Basalt_Brick_Decorative"
    },
    {
      "x": 1,
      "y": 12,
      "z": 5,
      "name": "Wood_Deadwood_Decorative"
    },
    {
      "x": 1,
      "y": 13,
      "z": 5,
      "name": "Wood_Deadwood_Decorative"
    },
    {
      "x": 1,
      "y": 14,
      "z": 5,
      "name": "Wood_Deadwood_Decorative"
    },
    {
      "x": 1,
      "y": 15,
      "z": 5,
      "name": "Rock_Basalt_Brick"
    },
    {
      "x": 1,
      "y": 16,
      "z": 5,
      "name": "Wood_Blackwood_Planks"
    },
    {
      "x": 1,
      "y": 17,
      "z": 5,
      "name": "Wood_Blackwood_Planks"
    },
    {
      "x": 1,
      "y": 19,
      "z": 5,
      "name": "Wood_Blackwood_Roof_Flat",
      "rotation": 3
    },
    {
      "x": 1,
      "y": 11,
      "z": 6,
      "name": "Wood_Burnt_Branch_Long",
      "rotation": 4
    },
    {
      "x": 1,
      "y": 15,
      "z": 6,
      "name": "Rock_Basalt_Brick_Half",
      "rotation": 4
    },
    {
      "x": 1,
      "y": 16,
      "z": 6,
      "name": "Wood_Blackwood_Planks"
    },
    {
      "x": 1,
      "y": 17,
      "z": 6,
      "name": "Wood_Blackwood_Planks"
    },
    {
      "x": 1,
      "y": 19,
      "z": 6,
      "name": "Wood_Blackwood_Roof_Flat",
      "rotation": 3
    },
    {
      "x": 1,
      "y": 11,
      "z": 7,
      "name": "Wood_Burnt_Branch_Long",
      "rotation": 4
    },
    {
      "x": 2,
      "y": 15,
      "z": -6,
      "name": "Rock_Basalt_Brick_Half",
      "rotation": 6
    },
    {
      "x": 2,
      "y": 16,
      "z": -6,
      "name": "Wood_Blackwood_Planks"
    },
    {
      "x": 2,
      "y": 17,
      "z": -6,
      "name": "Wood_Blackwood_Planks"
    },
    {
      "x": 2,
      "y": 18,
      "z": -6,
      "name": "Wood_Blackwood_Roof",
      "rotation": 1
    },
    {
      "x": 2,
      "y": 8,
      "z": -5,
      "name": "Empty"
    },
    {
      "x": 2,
      "y": 9,
      "z": -5,
      "name": "Empty"
    },
    {
      "x": 2,
      "y": 10,
      "z": -5,
      "name": "Empty"
    },
    {
      "x": 2,
      "y": 11,
      "z": -5,
      "name": "Empty"
    },
    {
      "x": 2,
      "y": 12,
      "z": -5,
      "name": "Empty"
    },
    {
      "x": 2,
      "y": 13,
      "z": -5,
      "name": "Empty"
    },
    {
      "x": 2,
      "y": 14,
      "z": -5,
      "name": "Wood_Deadwood_Decorative"
    },
    {
      "x": 2,
      "y": 15,
      "z": -5,
      "name": "Rock_Basalt_Brick"
    },
    {
      "x": 2,
      "y": 16,
      "z": -5,
      "name": "Wood_Blackwood_Planks"
    },
    {
      "x": 2,
      "y": 17,
      "z": -5,
      "name": "Wood_Blackwood_Planks"
    },
    {
      "x": 2,
      "y": 18,
      "z": -5,
      "name": "Wood_Blackwood_Roof",
      "rotation": 1
    },
    {
      "x": 2,
      "y": 2,
      "z": -4,
      "name": "Rock_Basalt"
    },
    {
      "x": 2,
      "y": 3,
      "z": -4,
      "name": "Rock_Basalt_Cobble"
    },
    {
      "x": 2,
      "y": 4,
      "z": -4,
      "name": "Rock_Basalt_Cobble"
    },
    {
      "x": 2,
      "y": 5,
      "z": -4,
      "name": "Rock_Basalt_Cobble"
    },
    {
      "x": 2,
      "y": 6,
      "z": -4,
      "name": "Rock_Basalt_Cobble"
    },
    {
      "x": 2,
      "y": 7,
      "z": -4,
      "name": "Rock_Basalt_Cobble"
    },
    {
      "x": 2,
      "y": 8,
      "z": -4,
      "name": "Empty"
    },
    {
      "x": 2,
      "y": 9,
      "z": -4,
      "name": "Empty"
    },
    {
      "x": 2,
      "y": 10,
      "z": -4,
      "name": "Rock_Basalt_Cobble"
    },
    {
      "x": 2,
      "y": 11,
      "z": -4,
      "name": "Wood_Blackwood_Planks"
    },
    {
      "x": 2,
      "y": 12,
      "z": -4,
      "name": "Empty"
    },
    {
      "x": 2,
      "y": 13,
      "z": -4,
      "name": "Empty"
    },
    {
      "x": 2,
      "y": 14,
      "z": -4,
      "name": "Empty"
    },
    {
      "x": 2,
      "y": 15,
      "z": -4,
      "name": "Empty"
    },
    {
      "x": 2,
      "y": 16,
      "z": -4,
      "name": "Empty"
    },
    {
      "x": 2,
      "y": 18,
      "z": -4,
      "name": "Wood_Blackwood_Roof_Hollow",
      "rotation": 1
    },
    {
      "x": 2,
      "y": 8,
      "z": -3,
      "name": "Empty"
    },
    {
      "x": 2,
      "y": 9,
      "z": -3,
      "name": "Empty"
    },
    {
      "x": 2,
      "y": 10,
      "z": -3,
      "name": "Empty"
    },
    {
      "x": 2,
      "y": 11,
      "z": -3,
      "name": "Wood_Blackwood_Planks"
    },
    {
      "x": 2,
      "y": 12,
      "z": -3,
      "name": "Empty"
    },
    {
      "x": 2,
      "y": 13,
      "z": -3,
      "name": "Empty"
    },
    {
      "x": 2,
      "y": 14,
      "z": -3,
      "name": "Empty"
    },
    {
      "x": 2,
      "y": 15,
      "z": -3,
      "name": "Empty"
    },
    {
      "x": 2,
      "y": 16,
      "z": -3,
      "name": "Empty"
    },
    {
      "x": 2,
      "y": 17,
      "z": -3,
      "name": "Empty"
    },
    {
      "x": 2,
      "y": 18,
      "z": -3,
      "name": "Wood_Blackwood_Roof_Hollow",
      "rotation": 1
    },
    {
      "x": 2,
      "y": 8,
      "z": -2,
      "name": "Empty"
    },
    {
      "x": 2,
      "y": 9,
      "z": -2,
      "name": "Empty"
    },
    {
      "x": 2,
      "y": 10,
      "z": -2,
      "name": "Empty"
    },
    {
      "x": 2,
      "y": 11,
      "z": -2,
      "name": "Wood_Deadwood_Planks"
    },
    {
      "x": 2,
      "y": 12,
      "z": -2,
      "name": "Empty"
    },
    {
      "x": 2,
      "y": 13,
      "z": -2,
      "name": "Empty"
    },
    {
      "x": 2,
      "y": 14,
      "z": -2,
      "name": "Empty"
    },
    {
      "x": 2,
      "y": 15,
      "z": -2,
      "name": "Empty"
    },
    {
      "x": 2,
      "y": 16,
      "z": -2,
      "name": "Empty"
    },
    {
      "x": 2,
      "y": 17,
      "z": -2,
      "name": "Empty"
    },
    {
      "x": 2,
      "y": 8,
      "z": -1,
      "name": "Empty"
    },
    {
      "x": 2,
      "y": 9,
      "z": -1,
      "name": "Empty"
    },
    {
      "x": 2,
      "y": 10,
      "z": -1,
      "name": "Empty"
    },
    {
      "x": 2,
      "y": 11,
      "z": -1,
      "name": "Furniture_Ancient_Platform"
    },
    {
      "x": 2,
      "y": 12,
      "z": -1,
      "name": "Empty"
    },
    {
      "x": 2,
      "y": 13,
      "z": -1,
      "name": "Empty"
    },
    {
      "x": 2,
      "y": 14,
      "z": -1,
      "name": "Empty"
    },
    {
      "x": 2,
      "y": 15,
      "z": -1,
      "name": "Empty"
    },
    {
      "x": 2,
      "y": 16,
      "z": -1,
      "name": "Empty"
    },
    {
      "x": 2,
      "y": 17,
      "z": -1,
      "name": "Empty"
    },
    {
      "x": 2,
      "y": 8,
      "z": 0,
      "name": "Empty"
    },
    {
      "x": 2,
      "y": 9,
      "z": 0,
      "name": "Empty"
    },
    {
      "x": 2,
      "y": 10,
      "z": 0,
      "name": "Empty"
    },
    {
      "x": 2,
      "y": 11,
      "z": 0,
      "name": "Furniture_Ancient_Platform"
    },
    {
      "x": 2,
      "y": 12,
      "z": 0,
      "name": "Empty"
    },
    {
      "x": 2,
      "y": 13,
      "z": 0,
      "name": "Empty"
    },
    {
      "x": 2,
      "y": 14,
      "z": 0,
      "name": "Empty"
    },
    {
      "x": 2,
      "y": 15,
      "z": 0,
      "name": "Empty"
    },
    {
      "x": 2,
      "y": 16,
      "z": 0,
      "name": "Empty"
    },
    {
      "x": 2,
      "y": 17,
      "z": 0,
      "name": "Empty"
    },
    {
      "x": 2,
      "y": 18,
      "z": 0,
      "name": "Wood_Blackwood_Beam",
      "rotation": 4
    },
    {
      "x": 2,
      "y": 8,
      "z": 1,
      "name": "Empty"
    },
    {
      "x": 2,
      "y": 9,
      "z": 1,
      "name": "Empty"
    },
    {
      "x": 2,
      "y": 10,
      "z": 1,
      "name": "Empty"
    },
    {
      "x": 2,
      "y": 11,
      "z": 1,
      "name": "Furniture_Ancient_Platform"
    },
    {
      "x": 2,
      "y": 12,
      "z": 1,
      "name": "Empty"
    },
    {
      "x": 2,
      "y": 13,
      "z": 1,
      "name": "Empty"
    },
    {
      "x": 2,
      "y": 14,
      "z": 1,
      "name": "Empty"
    },
    {
      "x": 2,
      "y": 15,
      "z": 1,
      "name": "Empty"
    },
    {
      "x": 2,
      "y": 16,
      "z": 1,
      "name": "Empty"
    },
    {
      "x": 2,
      "y": 17,
      "z": 1,
      "name": "Empty"
    },
    {
      "x": 2,
      "y": 18,
      "z": 1,
      "name": "Wood_Blackwood_Roof_Hollow",
      "rotation": 1
    },
    {
      "x": 2,
      "y": 8,
      "z": 2,
      "name": "Empty"
    },
    {
      "x": 2,
      "y": 9,
      "z": 2,
      "name": "Empty"
    },
    {
      "x": 2,
      "y": 10,
      "z": 2,
      "name": "Empty"
    },
    {
      "x": 2,
      "y": 11,
      "z": 2,
      "name": "Wood_Deadwood_Planks"
    },
    {
      "x": 2,
      "y": 12,
      "z": 2,
      "name": "Empty"
    },
    {
      "x": 2,
      "y": 13,
      "z": 2,
      "name": "Empty"
    },
    {
      "x": 2,
      "y": 14,
      "z": 2,
      "name": "Empty"
    },
    {
      "x": 2,
      "y": 15,
      "z": 2,
      "name": "Empty"
    },
    {
      "x": 2,
      "y": 16,
      "z": 2,
      "name": "Empty"
    },
    {
      "x": 2,
      "y": 17,
      "z": 2,
      "name": "Empty"
    },
    {
      "x": 2,
      "y": 18,
      "z": 2,
      "name": "Wood_Blackwood_Roof_Hollow",
      "rotation": 1
    },
    {
      "x": 2,
      "y": 8,
      "z": 3,
      "name": "Empty"
    },
    {
      "x": 2,
      "y": 9,
      "z": 3,
      "name": "Empty"
    },
    {
      "x": 2,
      "y": 10,
      "z": 3,
      "name": "Empty"
    },
    {
      "x": 2,
      "y": 11,
      "z": 3,
      "name": "Wood_Blackwood_Planks"
    },
    {
      "x": 2,
      "y": 12,
      "z": 3,
      "name": "Empty"
    },
    {
      "x": 2,
      "y": 13,
      "z": 3,
      "name": "Empty"
    },
    {
      "x": 2,
      "y": 14,
      "z": 3,
      "name": "Empty"
    },
    {
      "x": 2,
      "y": 15,
      "z": 3,
      "name": "Empty"
    },
    {
      "x": 2,
      "y": 16,
      "z": 3,
      "name": "Empty"
    },
    {
      "x": 2,
      "y": 17,
      "z": 3,
      "name": "Empty"
    },
    {
      "x": 2,
      "y": 18,
      "z": 3,
      "name": "Wood_Blackwood_Roof_Hollow",
      "rotation": 1
    },
    {
      "x": 2,
      "y": 1,
      "z": 4,
      "name": "Rock_Basalt_Cobble"
    },
    {
      "x": 2,
      "y": 2,
      "z": 4,
      "name": "Rock_Basalt_Cobble"
    },
    {
      "x": 2,
      "y": 3,
      "z": 4,
      "name": "Rock_Basalt_Cobble"
    },
    {
      "x": 2,
      "y": 4,
      "z": 4,
      "name": "Rock_Basalt_Cobble"
    },
    {
      "x": 2,
      "y": 5,
      "z": 4,
      "name": "Rock_Basalt_Cobble"
    },
    {
      "x": 2,
      "y": 6,
      "z": 4,
      "name": "Rock_Basalt_Cobble"
    },
    {
      "x": 2,
      "y": 7,
      "z": 4,
      "name": "Rock_Basalt_Brick"
    },
    {
      "x": 2,
      "y": 8,
      "z": 4,
      "name": "Rock_Basalt_Cobble"
    },
    {
      "x": 2,
      "y": 9,
      "z": 4,
      "name": "Rock_Basalt_Cobble"
    },
    {
      "x": 2,
      "y": 10,
      "z": 4,
      "name": "Rock_Basalt_Cobble"
    },
    {
      "x": 2,
      "y": 11,
      "z": 4,
      "name": "Wood_Blackwood_Planks"
    },
    {
      "x": 2,
      "y": 12,
      "z": 4,
      "name": "Furniture_Human_Ruins_Desk",
      "rotation": 2
    },
    {
      "x": 2,
      "y": 13,
      "z": 4,
      "name": "Empty"
    },
    {
      "x": 2,
      "y": 14,
      "z": 4,
      "name": "Empty"
    },
    {
      "x": 2,
      "y": 15,
      "z": 4,
      "name": "Empty"
    },
    {
      "x": 2,
      "y": 16,
      "z": 4,
      "name": "Empty"
    },
    {
      "x": 2,
      "y": 17,
      "z": 4,
      "name": "Empty"
    },
    {
      "x": 2,
      "y": 18,
      "z": 4,
      "name": "Wood_Blackwood_Roof_Hollow",
      "rotation": 1
    },
    {
      "x": 2,
      "y": 0,
      "z": 5,
      "name": "Rock_Basalt"
    },
    {
      "x": 2,
      "y": 1,
      "z": 5,
      "name": "Rock_Basalt"
    },
    {
      "x": 2,
      "y": 2,
      "z": 5,
      "name": "Rock_Basalt"
    },
    {
      "x": 2,
      "y": 3,
      "z": 5,
      "name": "Rock_Basalt"
    },
    {
      "x": 2,
      "y": 4,
      "z": 5,
      "name": "Rock_Basalt"
    },
    {
      "x": 2,
      "y": 5,
      "z": 5,
      "name": "Rock_Basalt_Cobble"
    },
    {
      "x": 2,
      "y": 6,
      "z": 5,
      "name": "Rock_Basalt_Cobble"
    },
    {
      "x": 2,
      "y": 7,
      "z": 5,
      "name": "Rock_Basalt_Cobble"
    },
    {
      "x": 2,
      "y": 11,
      "z": 5,
      "name": "Rock_Basalt_Brick"
    },
    {
      "x": 2,
      "y": 12,
      "z": 5,
      "name": "Wood_Deadwood_Decorative"
    },
    {
      "x": 2,
      "y": 13,
      "z": 5,
      "name": "Wood_Deadwood_Decorative"
    },
    {
      "x": 2,
      "y": 14,
      "z": 5,
      "name": "Wood_Deadwood_Decorative"
    },
    {
      "x": 2,
      "y": 15,
      "z": 5,
      "name": "Rock_Basalt_Brick"
    },
    {
      "x": 2,
      "y": 16,
      "z": 5,
      "name": "Wood_Blackwood_Planks"
    },
    {
      "x": 2,
      "y": 17,
      "z": 5,
      "name": "Wood_Blackwood_Planks"
    },
    {
      "x": 2,
      "y": 18,
      "z": 5,
      "name": "Wood_Blackwood_Roof",
      "rotation": 1
    },
    {
      "x": 2,
      "y": 15,
      "z": 6,
      "name": "Rock_Basalt_Brick_Half",
      "rotation": 4
    },
    {
      "x": 2,
      "y": 16,
      "z": 6,
      "name": "Wood_Blackwood_Planks"
    },
    {
      "x": 2,
      "y": 17,
      "z": 6,
      "name": "Wood_Blackwood_Planks"
    },
    {
      "x": 2,
      "y": 18,
      "z": 6,
      "name": "Wood_Blackwood_Roof",
      "rotation": 1
    },
    {
      "x": 3,
      "y": 16,
      "z": -6,
      "name": "Wood_Blackwood_Planks"
    },
    {
      "x": 3,
      "y": 17,
      "z": -6,
      "name": "Wood_Blackwood_Roof",
      "rotation": 1
    },
    {
      "x": 3,
      "y": 8,
      "z": -5,
      "name": "Empty"
    },
    {
      "x": 3,
      "y": 9,
      "z": -5,
      "name": "Empty"
    },
    {
      "x": 3,
      "y": 10,
      "z": -5,
      "name": "Empty"
    },
    {
      "x": 3,
      "y": 11,
      "z": -5,
      "name": "Empty"
    },
    {
      "x": 3,
      "y": 12,
      "z": -5,
      "name": "Empty"
    },
    {
      "x": 3,
      "y": 13,
      "z": -5,
      "name": "Wood_Deadwood_Decorative"
    },
    {
      "x": 3,
      "y": 14,
      "z": -5,
      "name": "Wood_Deadwood_Decorative"
    },
    {
      "x": 3,
      "y": 15,
      "z": -5,
      "name": "Rock_Basalt_Brick"
    },
    {
      "x": 3,
      "y": 16,
      "z": -5,
      "name": "Wood_Blackwood_Planks"
    },
    {
      "x": 3,
      "y": 17,
      "z": -5,
      "name": "Wood_Blackwood_Roof",
      "rotation": 1
    },
    {
      "x": 3,
      "y": 1,
      "z": -4,
      "name": "Rock_Basalt"
    },
    {
      "x": 3,
      "y": 2,
      "z": -4,
      "name": "Rock_Basalt"
    },
    {
      "x": 3,
      "y": 3,
      "z": -4,
      "name": "Rock_Basalt_Cobble"
    },
    {
      "x": 3,
      "y": 4,
      "z": -4,
      "name": "Rock_Basalt_Cobble"
    },
    {
      "x": 3,
      "y": 5,
      "z": -4,
      "name": "Rock_Basalt_Cobble"
    },
    {
      "x": 3,
      "y": 6,
      "z": -4,
      "name": "Rock_Basalt_Cobble"
    },
    {
      "x": 3,
      "y": 7,
      "z": -4,
      "name": "Rock_Basalt_Brick"
    },
    {
      "x": 3,
      "y": 8,
      "z": -4,
      "name": "Rock_Basalt_Cobble"
    },
    {
      "x": 3,
      "y": 9,
      "z": -4,
      "name": "Rock_Basalt_Cobble"
    },
    {
      "x": 3,
      "y": 10,
      "z": -4,
      "name": "Rock_Basalt_Cobble"
    },
    {
      "x": 3,
      "y": 11,
      "z": -4,
      "name": "Wood_Blackwood_Planks"
    },
    {
      "x": 3,
      "y": 12,
      "z": -4,
      "name": "Empty"
    },
    {
      "x": 3,
      "y": 13,
      "z": -4,
      "name": "Empty"
    },
    {
      "x": 3,
      "y": 14,
      "z": -4,
      "name": "Empty"
    },
    {
      "x": 3,
      "y": 15,
      "z": -4,
      "name": "Empty"
    },
    {
      "x": 3,
      "y": 16,
      "z": -4,
      "name": "Empty"
    },
    {
      "x": 3,
      "y": 17,
      "z": -4,
      "name": "Wood_Blackwood_Roof_Hollow",
      "rotation": 1
    },
    {
      "x": 3,
      "y": 1,
      "z": -3,
      "name": "Rock_Basalt"
    },
    {
      "x": 3,
      "y": 2,
      "z": -3,
      "name": "Rock_Basalt"
    },
    {
      "x": 3,
      "y": 3,
      "z": -3,
      "name": "Rock_Basalt"
    },
    {
      "x": 3,
      "y": 4,
      "z": -3,
      "name": "Rock_Basalt_Cobble"
    },
    {
      "x": 3,
      "y": 5,
      "z": -3,
      "name": "Rock_Basalt_Cobble"
    },
    {
      "x": 3,
      "y": 6,
      "z": -3,
      "name": "Rock_Basalt_Cobble"
    },
    {
      "x": 3,
      "y": 7,
      "z": -3,
      "name": "Rock_Basalt_Brick"
    },
    {
      "x": 3,
      "y": 8,
      "z": -3,
      "name": "Rock_Basalt_Cobble"
    },
    {
      "x": 3,
      "y": 9,
      "z": -3,
      "name": "Rock_Basalt_Cobble"
    },
    {
      "x": 3,
      "y": 10,
      "z": -3,
      "name": "Rock_Basalt_Cobble"
    },
    {
      "x": 3,
      "y": 11,
      "z": -3,
      "name": "Wood_Blackwood_Planks"
    },
    {
      "x": 3,
      "y": 12,
      "z": -3,
      "name": "Empty"
    },
    {
      "x": 3,
      "y": 13,
      "z": -3,
      "name": "Empty"
    },
    {
      "x": 3,
      "y": 14,
      "z": -3,
      "name": "Empty"
    },
    {
      "x": 3,
      "y": 15,
      "z": -3,
      "name": "Empty"
    },
    {
      "x": 3,
      "y": 16,
      "z": -3,
      "name": "Empty"
    },
    {
      "x": 3,
      "y": 17,
      "z": -3,
      "name": "Wood_Blackwood_Beam",
      "rotation": 4
    },
    {
      "x": 3,
      "y": 2,
      "z": -2,
      "name": "Rock_Basalt"
    },
    {
      "x": 3,
      "y": 3,
      "z": -2,
      "name": "Rock_Basalt"
    },
    {
      "x": 3,
      "y": 4,
      "z": -2,
      "name": "Rock_Basalt_Cobble"
    },
    {
      "x": 3,
      "y": 5,
      "z": -2,
      "name": "Rock_Basalt_Cobble"
    },
    {
      "x": 3,
      "y": 6,
      "z": -2,
      "name": "Rock_Basalt_Cobble"
    },
    {
      "x": 3,
      "y": 7,
      "z": -2,
      "name": "Rock_Basalt_Brick"
    },
    {
      "x": 3,
      "y": 8,
      "z": -2,
      "name": "Rock_Basalt_Cobble"
    },
    {
      "x": 3,
      "y": 9,
      "z": -2,
      "name": "Rock_Basalt_Cobble"
    },
    {
      "x": 3,
      "y": 10,
      "z": -2,
      "name": "Rock_Basalt_Cobble"
    },
    {
      "x": 3,
      "y": 11,
      "z": -2,
      "name": "Wood_Deadwood_Planks"
    },
    {
      "x": 3,
      "y": 12,
      "z": -2,
      "name": "Empty"
    },
    {
      "x": 3,
      "y": 13,
      "z": -2,
      "name": "Empty"
    },
    {
      "x": 3,
      "y": 14,
      "z": -2,
      "name": "Empty"
    },
    {
      "x": 3,
      "y": 15,
      "z": -2,
      "name": "Empty"
    },
    {
      "x": 3,
      "y": 16,
      "z": -2,
      "name": "Empty"
    },
    {
      "x": 3,
      "y": 17,
      "z": -2,
      "name": "Wood_Blackwood_Beam",
      "rotation": 4
    },
    {
      "x": 3,
      "y": 5,
      "z": -1,
      "name": "Rock_Basalt_Cobble"
    },
    {
      "x": 3,
      "y": 6,
      "z": -1,
      "name": "Rock_Basalt_Cobble"
    },
    {
      "x": 3,
      "y": 7,
      "z": -1,
      "name": "Rock_Basalt_Brick"
    },
    {
      "x": 3,
      "y": 8,
      "z": -1,
      "name": "Rock_Basalt_Cobble"
    },
    {
      "x": 3,
      "y": 9,
      "z": -1,
      "name": "Rock_Basalt_Cobble"
    },
    {
      "x": 3,
      "y": 10,
      "z": -1,
      "name": "Empty"
    },
    {
      "x": 3,
      "y": 11,
      "z": -1,
      "name": "Furniture_Ancient_Platform"
    },
    {
      "x": 3,
      "y": 12,
      "z": -1,
      "name": "Empty"
    },
    {
      "x": 3,
      "y": 13,
      "z": -1,
      "name": "Empty"
    },
    {
      "x": 3,
      "y": 14,
      "z": -1,
      "name": "Empty"
    },
    {
      "x": 3,
      "y": 15,
      "z": -1,
      "name": "Empty"
    },
    {
      "x": 3,
      "y": 16,
      "z": -1,
      "name": "Empty"
    },
    {
      "x": 3,
      "y": 8,
      "z": 0,
      "name": "Empty"
    },
    {
      "x": 3,
      "y": 9,
      "z": 0,
      "name": "Empty"
    },
    {
      "x": 3,
      "y": 10,
      "z": 0,
      "name": "Empty"
    },
    {
      "x": 3,
      "y": 11,
      "z": 0,
      "name": "Furniture_Ancient_Platform"
    },
    {
      "x": 3,
      "y": 12,
      "z": 0,
      "name": "Empty"
    },
    {
      "x": 3,
      "y": 13,
      "z": 0,
      "name": "Empty"
    },
    {
      "x": 3,
      "y": 14,
      "z": 0,
      "name": "Empty"
    },
    {
      "x": 3,
      "y": 15,
      "z": 0,
      "name": "Empty"
    },
    {
      "x": 3,
      "y": 16,
      "z": 0,
      "name": "Empty"
    },
    {
      "x": 3,
      "y": 2,
      "z": 1,
      "name": "Rock_Basalt"
    },
    {
      "x": 3,
      "y": 3,
      "z": 1,
      "name": "Rock_Basalt"
    },
    {
      "x": 3,
      "y": 4,
      "z": 1,
      "name": "Rock_Basalt_Cobble"
    },
    {
      "x": 3,
      "y": 5,
      "z": 1,
      "name": "Rock_Basalt_Cobble"
    },
    {
      "x": 3,
      "y": 6,
      "z": 1,
      "name": "Rock_Basalt_Brick"
    },
    {
      "x": 3,
      "y": 7,
      "z": 1,
      "name": "Rock_Basalt_Brick"
    },
    {
      "x": 3,
      "y": 8,
      "z": 1,
      "name": "Rock_Basalt_Cobble"
    },
    {
      "x": 3,
      "y": 9,
      "z": 1,
      "name": "Empty"
    },
    {
      "x": 3,
      "y": 10,
      "z": 1,
      "name": "Empty"
    },
    {
      "x": 3,
      "y": 11,
      "z": 1,
      "name": "Furniture_Ancient_Platform"
    },
    {
      "x": 3,
      "y": 12,
      "z": 1,
      "name": "Empty"
    },
    {
      "x": 3,
      "y": 13,
      "z": 1,
      "name": "Empty"
    },
    {
      "x": 3,
      "y": 14,
      "z": 1,
      "name": "Empty"
    },
    {
      "x": 3,
      "y": 15,
      "z": 1,
      "name": "Empty"
    },
    {
      "x": 3,
      "y": 16,
      "z": 1,
      "name": "Empty"
    },
    {
      "x": 3,
      "y": 2,
      "z": 2,
      "name": "Rock_Basalt"
    },
    {
      "x": 3,
      "y": 3,
      "z": 2,
      "name": "Rock_Basalt"
    },
    {
      "x": 3,
      "y": 4,
      "z": 2,
      "name": "Rock_Basalt_Cobble"
    },
    {
      "x": 3,
      "y": 5,
      "z": 2,
      "name": "Rock_Basalt_Cobble"
    },
    {
      "x": 3,
      "y": 6,
      "z": 2,
      "name": "Rock_Basalt_Brick"
    },
    {
      "x": 3,
      "y": 7,
      "z": 2,
      "name": "Rock_Basalt_Brick"
    },
    {
      "x": 3,
      "y": 8,
      "z": 2,
      "name": "Rock_Basalt_Cobble"
    },
    {
      "x": 3,
      "y": 9,
      "z": 2,
      "name": "Rock_Basalt_Cobble"
    },
    {
      "x": 3,
      "y": 10,
      "z": 2,
      "name": "Rock_Basalt_Cobble"
    },
    {
      "x": 3,
      "y": 11,
      "z": 2,
      "name": "Wood_Blackwood_Planks"
    },
    {
      "x": 3,
      "y": 12,
      "z": 2,
      "name": "Empty"
    },
    {
      "x": 3,
      "y": 13,
      "z": 2,
      "name": "Empty"
    },
    {
      "x": 3,
      "y": 14,
      "z": 2,
      "name": "Empty"
    },
    {
      "x": 3,
      "y": 15,
      "z": 2,
      "name": "Empty"
    },
    {
      "x": 3,
      "y": 16,
      "z": 2,
      "name": "Empty"
    },
    {
      "x": 3,
      "y": 17,
      "z": 2,
      "name": "Wood_Blackwood_Roof_Hollow",
      "rotation": 1
    },
    {
      "x": 3,
      "y": 1,
      "z": 3,
      "name": "Rock_Basalt"
    },
    {
      "x": 3,
      "y": 2,
      "z": 3,
      "name": "Rock_Basalt"
    },
    {
      "x": 3,
      "y": 3,
      "z": 3,
      "name": "Rock_Basalt"
    },
    {
      "x": 3,
      "y": 4,
      "z": 3,
      "name": "Rock_Basalt_Cobble"
    },
    {
      "x": 3,
      "y": 5,
      "z": 3,
      "name": "Rock_Basalt_Cobble"
    },
    {
      "x": 3,
      "y": 6,
      "z": 3,
      "name": "Rock_Basalt_Cobble"
    },
    {
      "x": 3,
      "y": 7,
      "z": 3,
      "name": "Rock_Basalt_Brick"
    },
    {
      "x": 3,
      "y": 8,
      "z": 3,
      "name": "Rock_Basalt_Cobble"
    },
    {
      "x": 3,
      "y": 9,
      "z": 3,
      "name": "Rock_Basalt_Cobble"
    },
    {
      "x": 3,
      "y": 10,
      "z": 3,
      "name": "Rock_Basalt_Cobble"
    },
    {
      "x": 3,
      "y": 11,
      "z": 3,
      "name": "Wood_Blackwood_Planks"
    },
    {
      "x": 3,
      "y": 12,
      "z": 3,
      "name": "Empty"
    },
    {
      "x": 3,
      "y": 13,
      "z": 3,
      "name": "Empty"
    },
    {
      "x": 3,
      "y": 14,
      "z": 3,
      "name": "Empty"
    },
    {
      "x": 3,
      "y": 15,
      "z": 3,
      "name": "Empty"
    },
    {
      "x": 3,
      "y": 16,
      "z": 3,
      "name": "Empty"
    },
    {
      "x": 3,
      "y": 17,
      "z": 3,
      "name": "Wood_Blackwood_Roof_Hollow",
      "rotation": 1
    },
    {
      "x": 3,
      "y": 0,
      "z": 4,
      "name": "Rock_Basalt"
    },
    {
      "x": 3,
      "y": 1,
      "z": 4,
      "name": "Rock_Basalt"
    },
    {
      "x": 3,
      "y": 2,
      "z": 4,
      "name": "Rock_Basalt"
    },
    {
      "x": 3,
      "y": 3,
      "z": 4,
      "name": "Rock_Basalt"
    },
    {
      "x": 3,
      "y": 4,
      "z": 4,
      "name": "Rock_Basalt"
    },
    {
      "x": 3,
      "y": 5,
      "z": 4,
      "name": "Rock_Basalt_Cobble"
    },
    {
      "x": 3,
      "y": 6,
      "z": 4,
      "name": "Rock_Basalt_Cobble"
    },
    {
      "x": 3,
      "y": 7,
      "z": 4,
      "name": "Rock_Basalt_Brick"
    },
    {
      "x": 3,
      "y": 8,
      "z": 4,
      "name": "Rock_Basalt_Cobble"
    },
    {
      "x": 3,
      "y": 9,
      "z": 4,
      "name": "Rock_Basalt_Cobble"
    },
    {
      "x": 3,
      "y": 10,
      "z": 4,
      "name": "Rock_Basalt_Cobble"
    },
    {
      "x": 3,
      "y": 11,
      "z": 4,
      "name": "Wood_Blackwood_Planks"
    },
    {
      "x": 3,
      "y": 12,
      "z": 4,
      "name": "Furniture_Human_Ruins_Desk",
      "filler": 1,
      "rotation": 2
    },
    {
      "x": 3,
      "y": 13,
      "z": 4,
      "name": "Empty"
    },
    {
      "x": 3,
      "y": 14,
      "z": 4,
      "name": "Empty"
    },
    {
      "x": 3,
      "y": 15,
      "z": 4,
      "name": "Empty"
    },
    {
      "x": 3,
      "y": 16,
      "z": 4,
      "name": "Empty"
    },
    {
      "x": 3,
      "y": 17,
      "z": 4,
      "name": "Wood_Blackwood_Roof_Hollow",
      "rotation": 1
    },
    {
      "x": 3,
      "y": 0,
      "z": 5,
      "name": "Rock_Basalt"
    },
    {
      "x": 3,
      "y": 1,
      "z": 5,
      "name": "Rock_Basalt"
    },
    {
      "x": 3,
      "y": 2,
      "z": 5,
      "name": "Rock_Basalt"
    },
    {
      "x": 3,
      "y": 3,
      "z": 5,
      "name": "Rock_Basalt"
    },
    {
      "x": 3,
      "y": 4,
      "z": 5,
      "name": "Rock_Basalt"
    },
    {
      "x": 3,
      "y": 5,
      "z": 5,
      "name": "Rock_Basalt_Cobble"
    },
    {
      "x": 3,
      "y": 6,
      "z": 5,
      "name": "Rock_Basalt_Cobble"
    },
    {
      "x": 3,
      "y": 7,
      "z": 5,
      "name": "Rock_Basalt_Brick"
    },
    {
      "x": 3,
      "y": 11,
      "z": 5,
      "name": "Rock_Basalt_Brick"
    },
    {
      "x": 3,
      "y": 12,
      "z": 5,
      "name": "Wood_Deadwood_Decorative"
    },
    {
      "x": 3,
      "y": 13,
      "z": 5,
      "name": "Wood_Deadwood_Decorative"
    },
    {
      "x": 3,
      "y": 14,
      "z": 5,
      "name": "Wood_Deadwood_Decorative"
    },
    {
      "x": 3,
      "y": 15,
      "z": 5,
      "name": "Rock_Basalt_Brick"
    },
    {
      "x": 3,
      "y": 16,
      "z": 5,
      "name": "Wood_Blackwood_Planks"
    },
    {
      "x": 3,
      "y": 17,
      "z": 5,
      "name": "Wood_Blackwood_Roof",
      "rotation": 1
    },
    {
      "x": 3,
      "y": 15,
      "z": 6,
      "name": "Rock_Basalt_Brick_Half",
      "rotation": 4
    },
    {
      "x": 3,
      "y": 16,
      "z": 6,
      "name": "Wood_Blackwood_Planks"
    },
    {
      "x": 3,
      "y": 17,
      "z": 6,
      "name": "Wood_Blackwood_Roof",
      "rotation": 1
    },
    {
      "x": 4,
      "y": 6,
      "z": -5,
      "name": "Rock_Basalt_Cobble"
    },
    {
      "x": 4,
      "y": 7,
      "z": -5,
      "name": "Rock_Basalt_Cobble"
    },
    {
      "x": 4,
      "y": 8,
      "z": -5,
      "name": "Rock_Basalt_Brick_Pillar_Base"
    },
    {
      "x": 4,
      "y": 9,
      "z": -5,
      "name": "Rock_Basalt_Brick_Pillar_Middle"
    },
    {
      "x": 4,
      "y": 10,
      "z": -5,
      "name": "Rock_Basalt_Brick_Pillar_Base",
      "rotation": 8
    },
    {
      "x": 4,
      "y": 11,
      "z": -5,
      "name": "Rock_Basalt_Brick_Decorative"
    },
    {
      "x": 4,
      "y": 12,
      "z": -5,
      "name": "Rock_Basalt_Brick"
    },
    {
      "x": 4,
      "y": 13,
      "z": -5,
      "name": "Rock_Basalt_Brick"
    },
    {
      "x": 4,
      "y": 14,
      "z": -5,
      "name": "Rock_Basalt_Brick"
    },
    {
      "x": 4,
      "y": 15,
      "z": -5,
      "name": "Empty"
    },
    {
      "x": 4,
      "y": 16,
      "z": -5,
      "name": "Wood_Blackwood_Roof",
      "rotation": 1
    },
    {
      "x": 4,
      "y": 11,
      "z": -4,
      "name": "Rock_Basalt_Brick"
    },
    {
      "x": 4,
      "y": 12,
      "z": -4,
      "name": "Rock_Basalt_Cobble"
    },
    {
      "x": 4,
      "y": 13,
      "z": -4,
      "name": "Rock_Basalt_Cobble"
    },
    {
      "x": 4,
      "y": 14,
      "z": -4,
      "name": "Rock_Basalt_Cobble"
    },
    {
      "x": 4,
      "y": 15,
      "z": -4,
      "name": "Rock_Basalt_Brick"
    },
    {
      "x": 4,
      "y": 16,
      "z": -4,
      "name": "Wood_Blackwood_Roof",
      "rotation": 1
    },
    {
      "x": 4,
      "y": 11,
      "z": -3,
      "name": "Rock_Basalt_Brick"
    },
    {
      "x": 4,
      "y": 12,
      "z": -3,
      "name": "Rock_Basalt_Cobble"
    },
    {
      "x": 4,
      "y": 13,
      "z": -3,
      "name": "Rock_Basalt_Cobble"
    },
    {
      "x": 4,
      "y": 14,
      "z": -3,
      "name": "Rock_Basalt_Cobble"
    },
    {
      "x": 4,
      "y": 15,
      "z": -3,
      "name": "Empty"
    },
    {
      "x": 4,
      "y": 16,
      "z": -3,
      "name": "Wood_Blackwood_Roof",
      "rotation": 1
    },
    {
      "x": 4,
      "y": 6,
      "z": -2,
      "name": "Rock_Basalt_Cobble"
    },
    {
      "x": 4,
      "y": 7,
      "z": -2,
      "name": "Rock_Basalt_Brick"
    },
    {
      "x": 4,
      "y": 8,
      "z": -2,
      "name": "Rock_Basalt_Brick_Pillar_Base"
    },
    {
      "x": 4,
      "y": 9,
      "z": -2,
      "name": "Rock_Basalt_Brick_Pillar_Middle"
    },
    {
      "x": 4,
      "y": 10,
      "z": -2,
      "name": "Rock_Basalt_Brick_Pillar_Base",
      "rotation": 8
    },
    {
      "x": 4,
      "y": 11,
      "z": -2,
      "name": "Rock_Basalt_Brick_Decorative"
    },
    {
      "x": 4,
      "y": 12,
      "z": -2,
      "name": "Empty"
    },
    {
      "x": 4,
      "y": 13,
      "z": -2,
      "name": "Empty"
    },
    {
      "x": 4,
      "y": 14,
      "z": -2,
      "name": "Empty"
    },
    {
      "x": 4,
      "y": 15,
      "z": -2,
      "name": "Empty"
    },
    {
      "x": 4,
      "y": 16,
      "z": -2,
      "name": "Empty"
    },
    {
      "x": 4,
      "y": 8,
      "z": -1,
      "name": "Empty"
    },
    {
      "x": 4,
      "y": 9,
      "z": -1,
      "name": "Empty"
    },
    {
      "x": 4,
      "y": 10,
      "z": -1,
      "name": "Empty"
    },
    {
      "x": 4,
      "y": 11,
      "z": -1,
      "name": "Empty"
    },
    {
      "x": 4,
      "y": 12,
      "z": -1,
      "name": "Empty"
    },
    {
      "x": 4,
      "y": 13,
      "z": -1,
      "name": "Empty"
    },
    {
      "x": 4,
      "y": 14,
      "z": -1,
      "name": "Empty"
    },
    {
      "x": 4,
      "y": 15,
      "z": -1,
      "name": "Empty"
    },
    {
      "x": 4,
      "y": 16,
      "z": -1,
      "name": "Empty"
    },
    {
      "x": 4,
      "y": 8,
      "z": 0,
      "name": "Empty"
    },
    {
      "x": 4,
      "y": 9,
      "z": 0,
      "name": "Empty"
    },
    {
      "x": 4,
      "y": 10,
      "z": 0,
      "name": "Empty"
    },
    {
      "x": 4,
      "y": 11,
      "z": 0,
      "name": "Empty"
    },
    {
      "x": 4,
      "y": 12,
      "z": 0,
      "name": "Empty"
    },
    {
      "x": 4,
      "y": 13,
      "z": 0,
      "name": "Empty"
    },
    {
      "x": 4,
      "y": 14,
      "z": 0,
      "name": "Empty"
    },
    {
      "x": 4,
      "y": 15,
      "z": 0,
      "name": "Empty"
    },
    {
      "x": 4,
      "y": 16,
      "z": 0,
      "name": "Wood_Blackwood_Beam",
      "rotation": 4
    },
    {
      "x": 4,
      "y": 8,
      "z": 1,
      "name": "Empty"
    },
    {
      "x": 4,
      "y": 9,
      "z": 1,
      "name": "Empty"
    },
    {
      "x": 4,
      "y": 10,
      "z": 1,
      "name": "Empty"
    },
    {
      "x": 4,
      "y": 11,
      "z": 1,
      "name": "Empty"
    },
    {
      "x": 4,
      "y": 12,
      "z": 1,
      "name": "Empty"
    },
    {
      "x": 4,
      "y": 13,
      "z": 1,
      "name": "Rock_Basalt_Cobble"
    },
    {
      "x": 4,
      "y": 14,
      "z": 1,
      "name": "Rock_Basalt_Cobble"
    },
    {
      "x": 4,
      "y": 15,
      "z": 1,
      "name": "Rock_Basalt_Brick"
    },
    {
      "x": 4,
      "y": 16,
      "z": 1,
      "name": "Wood_Blackwood_Beam",
      "rotation": 4
    },
    {
      "x": 4,
      "y": 4,
      "z": 2,
      "name": "Rock_Basalt"
    },
    {
      "x": 4,
      "y": 5,
      "z": 2,
      "name": "Rock_Basalt_Cobble"
    },
    {
      "x": 4,
      "y": 6,
      "z": 2,
      "name": "Rock_Basalt_Cobble"
    },
    {
      "x": 4,
      "y": 7,
      "z": 2,
      "name": "Rock_Basalt_Brick"
    },
    {
      "x": 4,
      "y": 8,
      "z": 2,
      "name": "Rock_Basalt_Brick_Pillar_Base"
    },
    {
      "x": 4,
      "y": 9,
      "z": 2,
      "name": "Rock_Basalt_Brick_Pillar_Middle"
    },
    {
      "x": 4,
      "y": 10,
      "z": 2,
      "name": "Rock_Basalt_Brick_Pillar_Base",
      "rotation": 8
    },
    {
      "x": 4,
      "y": 11,
      "z": 2,
      "name": "Rock_Basalt_Brick_Decorative"
    },
    {
      "x": 4,
      "y": 12,
      "z": 2,
      "name": "Rock_Basalt_Cobble"
    },
    {
      "x": 4,
      "y": 13,
      "z": 2,
      "name": "Rock_Basalt_Cobble"
    },
    {
      "x": 4,
      "y": 14,
      "z": 2,
      "name": "Rock_Basalt_Cobble"
    },
    {
      "x": 4,
      "y": 15,
      "z": 2,
      "name": "Rock_Basalt_Brick"
    },
    {
      "x": 4,
      "y": 16,
      "z": 2,
      "name": "Wood_Blackwood_Roof",
      "rotation": 1
    },
    {
      "x": 4,
      "y": 11,
      "z": 3,
      "name": "Rock_Basalt_Brick"
    },
    {
      "x": 4,
      "y": 12,
      "z": 3,
      "name": "Furniture_Human_Ruins_Window",
      "rotation": 1
    },
    {
      "x": 4,
      "y": 13,
      "z": 3,
      "name": "Furniture_Human_Ruins_Window",
      "rotation": 1
    },
    {
      "x": 4,
      "y": 14,
      "z": 3,
      "name": "Rock_Basalt_Cobble"
    },
    {
      "x": 4,
      "y": 15,
      "z": 3,
      "name": "Rock_Basalt_Brick"
    },
    {
      "x": 4,
      "y": 16,
      "z": 3,
      "name": "Wood_Blackwood_Roof",
      "rotation": 1
    },
    {
      "x": 4,
      "y": 11,
      "z": 4,
      "name": "Rock_Basalt_Brick"
    },
    {
      "x": 4,
      "y": 12,
      "z": 4,
      "name": "Rock_Basalt_Cobble"
    },
    {
      "x": 4,
      "y": 13,
      "z": 4,
      "name": "Rock_Basalt_Cobble"
    },
    {
      "x": 4,
      "y": 14,
      "z": 4,
      "name": "Rock_Basalt_Cobble"
    },
    {
      "x": 4,
      "y": 15,
      "z": 4,
      "name": "Rock_Basalt_Brick"
    },
    {
      "x": 4,
      "y": 16,
      "z": 4,
      "name": "Wood_Blackwood_Roof",
      "rotation": 1
    },
    {
      "x": 4,
      "y": 2,
      "z": 5,
      "name": "Rock_Basalt"
    },
    {
      "x": 4,
      "y": 3,
      "z": 5,
      "name": "Rock_Basalt"
    },
    {
      "x": 4,
      "y": 4,
      "z": 5,
      "name": "Rock_Basalt"
    },
    {
      "x": 4,
      "y": 5,
      "z": 5,
      "name": "Rock_Basalt_Cobble"
    },
    {
      "x": 4,
      "y": 6,
      "z": 5,
      "name": "Rock_Basalt_Cobble"
    },
    {
      "x": 4,
      "y": 7,
      "z": 5,
      "name": "Rock_Basalt_Brick"
    },
    {
      "x": 4,
      "y": 8,
      "z": 5,
      "name": "Rock_Basalt_Brick_Pillar_Base"
    },
    {
      "x": 4,
      "y": 9,
      "z": 5,
      "name": "Rock_Basalt_Brick_Pillar_Middle"
    },
    {
      "x": 4,
      "y": 10,
      "z": 5,
      "name": "Rock_Basalt_Brick_Pillar_Base",
      "rotation": 8
    },
    {
      "x": 4,
      "y": 11,
      "z": 5,
      "name": "Rock_Basalt_Brick_Decorative"
    },
    {
      "x": 4,
      "y": 12,
      "z": 5,
      "name": "Rock_Basalt_Brick"
    },
    {
      "x": 4,
      "y": 13,
      "z": 5,
      "name": "Rock_Basalt_Brick"
    },
    {
      "x": 4,
      "y": 14,
      "z": 5,
      "name": "Rock_Basalt_Brick"
    },
    {
      "x": 4,
      "y": 15,
      "z": 5,
      "name": "Rock_Basalt_Brick"
    },
    {
      "x": 4,
      "y": 16,
      "z": 5,
      "name": "Wood_Blackwood_Roof",
      "rotation": 1
    },
    {
      "x": 4,
      "y": 11,
      "z": 6,
      "name": "Wood_Burnt_Branch_Long",
      "rotation": 4
    },
    {
      "x": 4,
      "y": 15,
      "z": 6,
      "name": "Rock_Basalt_Brick_Half",
      "rotation": 4
    },
    {
      "x": 4,
      "y": 16,
      "z": 6,
      "name": "Wood_Blackwood_Roof",
      "rotation": 1
    },
    {
      "x": 5,
      "y": 15,
      "z": -4,
      "name": "Rock_Basalt_Brick_Half",
      "rotation": 5
    },
    {
      "x": 5,
      "y": 15,
      "z": 1,
      "name": "Rock_Basalt_Brick_Half",
      "rotation": 5
    },
    {
      "x": 5,
      "y": 15,
      "z": 2,
      "name": "Rock_Basalt_Brick_Half",
      "rotation": 5
    },
    {
      "x": 5,
      "y": 15,
      "z": 3,
      "name": "Rock_Basalt_Brick_Half",
      "rotation": 5
    },
    {
      "x": 5,
      "y": 15,
      "z": 4,
      "name": "Rock_Basalt_Brick_Half",
      "rotation": 5
    },
    {
      "x": 5,
      "y": 15,
      "z": 5,
      "name": "Rock_Basalt_Brick_Half",
      "rotation": 5
    }
  ],
  "entities": [
    {
      "Components": {
        "Nameplate": {
          "Text": "Skeleton_Archer"
        },
        "HiddenFromAdventurePlayer": {},
        "SpawnMarkerComponent": {
          "SpawnMarker": "Skeleton_Archer",
          "RespawnTime": 0.0,
          "SpawnCount": 0,
          "PersistedFlock": {},
          "SpawnPosition": {
            "X": 0.0,
            "Y": 0.0,
            "Z": 0.0
          }
        },
        "Transform": {
          "Position": {
            "X": 2.485595703125,
            "Y": 12.280281066894531,
            "Z": 0.1748504638671875
          },
          "Rotation": {
            "Pitch": 0.0,
            "Yaw": -1.1660411357879639,
            "Roll": 0.0
          }
        },
        "Intangible": {},
        "Model": {
          "Model": {
            "Id": "NPC_Spawn_Marker",
            "Scale": 1.0
          }
        },
        "UUID": {
          "UUID": {
            "$binary": "+ybJHCfqMrGeaQz2DHRLfA==",
            "$type": "04"
          }
        },
        "HeadRotation": {
          "Rotation": {
            "Pitch": 0.0,
            "Yaw": 1.9755516052246094,
            "Roll": 0.0
          }
        }
      }
    }
  ]
}
