{
  "version": 8,
  "blockIdVersion": 8,
  "anchorX": 4,
  "anchorY": 5,
  "anchorZ": 4,
  "blocks": [
    {
      "x": 1,
      "y": 5,
      "z": 4,
      "name": "Rock_Quartzite"
    },
    {
      "x": 1,
      "y": 6,
      "z": 4,
      "name": "Rock_Quartzite"
    },
    {
      "x": 1,
      "y": 4,
      "z": 5,
      "name": "Rock_Quartzite"
    },
    {
      "x": 1,
      "y": 5,
      "z": 5,
      "name": "Rock_Quartzite"
    },
    {
      "x": 1,
      "y": 6,
      "z": 5,
      "name": "Rock_Quartzite"
    },
    {
      "x": 2,
      "y": 4,
      "z": 3,
      "name": "Rock_Quartzite"
    },
    {
      "x": 2,
      "y": 5,
      "z": 3,
      "name": "Rock_Quartzite"
    },
    {
      "x": 2,
      "y": 6,
      "z": 3,
      "name": "Rock_Quartzite"
    },
    {
      "x": 2,
      "y": 3,
      "z": 4,
      "name": "Rock_Quartzite"
    },
    {
      "x": 2,
      "y": 4,
      "z": 4,
      "name": "Rock_Quartzite"
    },
    {
      "x": 2,
      "y": 5,
      "z": 4,
      "name": "Rock_Quartzite"
    },
    {
      "x": 2,
      "y": 6,
      "z": 4,
      "name": "Rock_Quartzite"
    },
    {
      "x": 2,
      "y": 7,
      "z": 4,
      "name": "Soil_Gravel"
    },
    {
      "x": 2,
      "y": 3,
      "z": 5,
      "name": "Rock_Quartzite"
    },
    {
      "x": 2,
      "y": 4,
      "z": 5,
      "name": "Rock_Quartzite"
    },
    {
      "x": 2,
      "y": 5,
      "z": 5,
      "name": "Rock_Quartzite"
    },
    {
      "x": 2,
      "y": 6,
      "z": 5,
      "name": "Rock_Quartzite"
    },
    {
      "x": 2,
      "y": 7,
      "z": 5,
      "name": "Rock_Quartzite"
    },
    {
      "x": 2,
      "y": 5,
      "z": 6,
      "name": "Rock_Quartzite"
    },
    {
      "x": 2,
      "y": 6,
      "z": 6,
      "name": "Rock_Quartzite"
    },
    {
      "x": 3,
      "y": 4,
      "z": 2,
      "name": "Rock_Quartzite"
    },
    {
      "x": 3,
      "y": 5,
      "z": 2,
      "name": "Rock_Quartzite"
    },
    {
      "x": 3,
      "y": 6,
      "z": 2,
      "name": "Rock_Quartzite"
    },
    {
      "x": 3,
      "y": 3,
      "z": 3,
      "name": "Rock_Quartzite"
    },
    {
      "x": 3,
      "y": 4,
      "z": 3,
      "name": "Rock_Quartzite"
    },
    {
      "x": 3,
      "y": 5,
      "z": 3,
      "name": "Rock_Quartzite"
    },
    {
      "x": 3,
      "y": 6,
      "z": 3,
      "name": "Soil_Gravel"
    },
    {
      "x": 3,
      "y": 7,
      "z": 3,
      "name": "Soil_Gravel"
    },
    {
      "x": 3,
      "y": 3,
      "z": 4,
      "name": "Rock_Quartzite"
    },
    {
      "x": 3,
      "y": 4,
      "z": 4,
      "name": "Rock_Quartzite"
    },
    {
      "x": 3,
      "y": 5,
      "z": 4,
      "name": "Rock_Quartzite"
    },
    {
      "x": 3,
      "y": 6,
      "z": 4,
      "name": "Rock_Quartzite"
    },
    {
      "x": 3,
      "y": 7,
      "z": 4,
      "name": "Soil_Gravel"
    },
    {
      "x": 3,
      "y": 2,
      "z": 5,
      "name": "Rock_Quartzite"
    },
    {
      "x": 3,
      "y": 3,
      "z": 5,
      "name": "Rock_Quartzite"
    },
    {
      "x": 3,
      "y": 4,
      "z": 5,
      "name": "Rock_Quartzite"
    },
    {
      "x": 3,
      "y": 5,
      "z": 5,
      "name": "Rock_Quartzite"
    },
    {
      "x": 3,
      "y": 6,
      "z": 5,
      "name": "Rock_Quartzite"
    },
    {
      "x": 3,
      "y": 7,
      "z": 5,
      "name": "Soil_Gravel"
    },
    {
      "x": 3,
      "y": 5,
      "z": 6,
      "name": "Rock_Quartzite"
    },
    {
      "x": 3,
      "y": 6,
      "z": 6,
      "name": "Soil_Gravel"
    },
    {
      "x": 3,
      "y": 5,
      "z": 7,
      "name": "Rock_Quartzite"
    },
    {
      "x": 4,
      "y": 4,
      "z": 2,
      "name": "Rock_Quartzite"
    },
    {
      "x": 4,
      "y": 5,
      "z": 2,
      "name": "Rock_Quartzite"
    },
    {
      "x": 4,
      "y": 6,
      "z": 2,
      "name": "Rock_Quartzite"
    },
    {
      "x": 4,
      "y": 7,
      "z": 2,
      "name": "Rock_Quartzite"
    },
    {
      "x": 4,
      "y": 3,
      "z": 3,
      "name": "Rock_Quartzite"
    },
    {
      "x": 4,
      "y": 4,
      "z": 3,
      "name": "Rock_Quartzite"
    },
    {
      "x": 4,
      "y": 5,
      "z": 3,
      "name": "Rock_Quartzite"
    },
    {
      "x": 4,
      "y": 6,
      "z": 3,
      "name": "Rock_Quartzite"
    },
    {
      "x": 4,
      "y": 7,
      "z": 3,
      "name": "Soil_Gravel"
    },
    {
      "x": 4,
      "y": 3,
      "z": 4,
      "name": "Rock_Quartzite"
    },
    {
      "x": 4,
      "y": 4,
      "z": 4,
      "name": "Rock_Quartzite"
    },
    {
      "x": 4,
      "y": 5,
      "z": 4,
      "name": "Rock_Quartzite"
    },
    {
      "x": 4,
      "y": 6,
      "z": 4,
      "name": "Soil_Gravel"
    },
    {
      "x": 4,
      "y": 7,
      "z": 4,
      "name": "Soil_Gravel"
    },
    {
      "x": 4,
      "y": 2,
      "z": 5,
      "name": "Rock_Quartzite"
    },
    {
      "x": 4,
      "y": 3,
      "z": 5,
      "name": "Rock_Quartzite"
    },
    {
      "x": 4,
      "y": 4,
      "z": 5,
      "name": "Rock_Quartzite"
    },
    {
      "x": 4,
      "y": 5,
      "z": 5,
      "name": "Rock_Quartzite"
    },
    {
      "x": 4,
      "y": 6,
      "z": 5,
      "name": "Rock_Quartzite"
    },
    {
      "x": 4,
      "y": 7,
      "z": 5,
      "name": "Rock_Quartzite"
    },
    {
      "x": 4,
      "y": 3,
      "z": 6,
      "name": "Rock_Quartzite"
    },
    {
      "x": 4,
      "y": 4,
      "z": 6,
      "name": "Rock_Quartzite"
    },
    {
      "x": 4,
      "y": 5,
      "z": 6,
      "name": "Soil_Gravel"
    },
    {
      "x": 4,
      "y": 6,
      "z": 6,
      "name": "Soil_Gravel"
    },
    {
      "x": 4,
      "y": 5,
      "z": 7,
      "name": "Rock_Quartzite"
    },
    {
      "x": 4,
      "y": 6,
      "z": 7,
      "name": "Rock_Quartzite"
    },
    {
      "x": 5,
      "y": 5,
      "z": 2,
      "name": "Rock_Quartzite"
    },
    {
      "x": 5,
      "y": 6,
      "z": 2,
      "name": "Rock_Quartzite"
    },
    {
      "x": 5,
      "y": 3,
      "z": 3,
      "name": "Rock_Quartzite"
    },
    {
      "x": 5,
      "y": 4,
      "z": 3,
      "name": "Rock_Quartzite"
    },
    {
      "x": 5,
      "y": 5,
      "z": 3,
      "name": "Rock_Quartzite"
    },
    {
      "x": 5,
      "y": 6,
      "z": 3,
      "name": "Rock_Quartzite"
    },
    {
      "x": 5,
      "y": 7,
      "z": 3,
      "name": "Rock_Quartzite"
    },
    {
      "x": 5,
      "y": 2,
      "z": 4,
      "name": "Rock_Quartzite"
    },
    {
      "x": 5,
      "y": 3,
      "z": 4,
      "name": "Rock_Quartzite"
    },
    {
      "x": 5,
      "y": 4,
      "z": 4,
      "name": "Rock_Quartzite"
    },
    {
      "x": 5,
      "y": 5,
      "z": 4,
      "name": "Rock_Quartzite"
    },
    {
      "x": 5,
      "y": 6,
      "z": 4,
      "name": "Soil_Gravel"
    },
    {
      "x": 5,
      "y": 7,
      "z": 4,
      "name": "Soil_Gravel"
    },
    {
      "x": 5,
      "y": 2,
      "z": 5,
      "name": "Rock_Quartzite"
    },
    {
      "x": 5,
      "y": 3,
      "z": 5,
      "name": "Rock_Quartzite"
    },
    {
      "x": 5,
      "y": 4,
      "z": 5,
      "name": "Rock_Quartzite"
    },
    {
      "x": 5,
      "y": 5,
      "z": 5,
      "name": "Rock_Quartzite"
    },
    {
      "x": 5,
      "y": 6,
      "z": 5,
      "name": "Rock_Quartzite"
    },
    {
      "x": 5,
      "y": 4,
      "z": 6,
      "name": "Rock_Quartzite"
    },
    {
      "x": 5,
      "y": 5,
      "z": 6,
      "name": "Rock_Quartzite"
    },
    {
      "x": 5,
      "y": 6,
      "z": 6,
      "name": "Rock_Quartzite"
    },
    {
      "x": 6,
      "y": 4,
      "z": 3,
      "name": "Rock_Quartzite"
    },
    {
      "x": 6,
      "y": 5,
      "z": 3,
      "name": "Rock_Quartzite"
    },
    {
      "x": 6,
      "y": 6,
      "z": 3,
      "name": "Rock_Quartzite"
    },
    {
      "x": 6,
      "y": 4,
      "z": 4,
      "name": "Rock_Quartzite"
    },
    {
      "x": 6,
      "y": 5,
      "z": 4,
      "name": "Rock_Quartzite"
    },
    {
      "x": 6,
      "y": 6,
      "z": 4,
      "name": "Rock_Quartzite"
    },
    {
      "x": 6,
      "y": 3,
      "z": 5,
      "name": "Rock_Quartzite"
    },
    {
      "x": 6,
      "y": 4,
      "z": 5,
      "name": "Rock_Quartzite"
    },
    {
      "x": 6,
      "y": 5,
      "z": 5,
      "name": "Rock_Quartzite"
    }
  ]
}