{
  "version": 8,
  "blockIdVersion": 8,
  "anchorX": 8,
  "anchorY": 12,
  "anchorZ": 0,
  "blocks": [
    {
      "x": -7,
      "y": 10,
      "z": 1,
      "name": "Rock_Basalt"
    },
    {
      "x": -7,
      "y": 11,
      "z": 1,
      "name": "Rock_Basalt"
    },
    {
      "x": -7,
      "y": 12,
      "z": 1,
      "name": "Rock_Basalt"
    },
    {
      "x": -7,
      "y": 13,
      "z": 1,
      "name": "Rock_Basalt"
    },
    {
      "x": -7,
      "y": 14,
      "z": 1,
      "name": "Rock_Stone"
    },
    {
      "x": -7,
      "y": 15,
      "z": 1,
      "name": "Rock_Stone_Mossy"
    },
    {
      "x": -7,
      "y": 10,
      "z": 2,
      "name": "Rock_Basalt"
    },
    {
      "x": -7,
      "y": 11,
      "z": 2,
      "name": "Rock_Basalt"
    },
    {
      "x": -7,
      "y": 12,
      "z": 2,
      "name": "Rock_Basalt"
    },
    {
      "x": -7,
      "y": 13,
      "z": 2,
      "name": "Rock_Basalt"
    },
    {
      "x": -7,
      "y": 14,
      "z": 2,
      "name": "Rock_Stone"
    },
    {
      "x": -7,
      "y": 15,
      "z": 2,
      "name": "Rock_Stone_Mossy"
    },
    {
      "x": -7,
      "y": 10,
      "z": 3,
      "name": "Rock_Basalt"
    },
    {
      "x": -7,
      "y": 11,
      "z": 3,
      "name": "Rock_Basalt"
    },
    {
      "x": -7,
      "y": 12,
      "z": 3,
      "name": "Rock_Basalt"
    },
    {
      "x": -7,
      "y": 13,
      "z": 3,
      "name": "Rock_Basalt"
    },
    {
      "x": -7,
      "y": 14,
      "z": 3,
      "name": "Rock_Basalt"
    },
    {
      "x": -7,
      "y": 15,
      "z": 3,
      "name": "Rock_Stone"
    },
    {
      "x": -7,
      "y": 16,
      "z": 3,
      "name": "Plant_Moss_Block_Green_Dark"
    },
    {
      "x": -7,
      "y": 10,
      "z": 4,
      "name": "Rock_Basalt"
    },
    {
      "x": -7,
      "y": 11,
      "z": 4,
      "name": "Rock_Basalt"
    },
    {
      "x": -7,
      "y": 12,
      "z": 4,
      "name": "Rock_Basalt"
    },
    {
      "x": -7,
      "y": 13,
      "z": 4,
      "name": "Rock_Basalt"
    },
    {
      "x": -7,
      "y": 14,
      "z": 4,
      "name": "Rock_Basalt"
    },
    {
      "x": -7,
      "y": 15,
      "z": 4,
      "name": "Rock_Stone"
    },
    {
      "x": -7,
      "y": 16,
      "z": 4,
      "name": "Plant_Moss_Block_Green_Dark"
    },
    {
      "x": -7,
      "y": 11,
      "z": 5,
      "name": "Rock_Basalt"
    },
    {
      "x": -7,
      "y": 12,
      "z": 5,
      "name": "Rock_Basalt"
    },
    {
      "x": -7,
      "y": 13,
      "z": 5,
      "name": "Rock_Basalt"
    },
    {
      "x": -7,
      "y": 14,
      "z": 5,
      "name": "Rock_Basalt"
    },
    {
      "x": -7,
      "y": 15,
      "z": 5,
      "name": "Rock_Basalt"
    },
    {
      "x": -6,
      "y": 9,
      "z": -1,
      "name": "Rock_Basalt"
    },
    {
      "x": -6,
      "y": 10,
      "z": -1,
      "name": "Rock_Basalt"
    },
    {
      "x": -6,
      "y": 11,
      "z": -1,
      "name": "Rock_Basalt"
    },
    {
      "x": -6,
      "y": 12,
      "z": -1,
      "name": "Rock_Basalt"
    },
    {
      "x": -6,
      "y": 13,
      "z": -1,
      "name": "Rock_Basalt"
    },
    {
      "x": -6,
      "y": 14,
      "z": -1,
      "name": "Rock_Stone"
    },
    {
      "x": -6,
      "y": 15,
      "z": -1,
      "name": "Rock_Stone_Mossy"
    },
    {
      "x": -6,
      "y": 9,
      "z": 0,
      "name": "Rock_Basalt"
    },
    {
      "x": -6,
      "y": 10,
      "z": 0,
      "name": "Rock_Basalt"
    },
    {
      "x": -6,
      "y": 11,
      "z": 0,
      "name": "Rock_Basalt"
    },
    {
      "x": -6,
      "y": 12,
      "z": 0,
      "name": "Rock_Basalt"
    },
    {
      "x": -6,
      "y": 13,
      "z": 0,
      "name": "Rock_Basalt"
    },
    {
      "x": -6,
      "y": 14,
      "z": 0,
      "name": "Rock_Stone"
    },
    {
      "x": -6,
      "y": 15,
      "z": 0,
      "name": "Rock_Stone_Mossy"
    },
    {
      "x": -6,
      "y": 16,
      "z": 0,
      "name": "Plant_Moss_Block_Green_Dark"
    },
    {
      "x": -6,
      "y": 9,
      "z": 1,
      "name": "Rock_Basalt"
    },
    {
      "x": -6,
      "y": 10,
      "z": 1,
      "name": "Rock_Basalt"
    },
    {
      "x": -6,
      "y": 11,
      "z": 1,
      "name": "Rock_Basalt"
    },
    {
      "x": -6,
      "y": 12,
      "z": 1,
      "name": "Rock_Basalt"
    },
    {
      "x": -6,
      "y": 13,
      "z": 1,
      "name": "Rock_Basalt"
    },
    {
      "x": -6,
      "y": 14,
      "z": 1,
      "name": "Rock_Stone"
    },
    {
      "x": -6,
      "y": 15,
      "z": 1,
      "name": "Rock_Stone"
    },
    {
      "x": -6,
      "y": 16,
      "z": 1,
      "name": "Plant_Moss_Block_Green_Dark"
    },
    {
      "x": -6,
      "y": 9,
      "z": 2,
      "name": "Rock_Basalt"
    },
    {
      "x": -6,
      "y": 10,
      "z": 2,
      "name": "Rock_Basalt"
    },
    {
      "x": -6,
      "y": 11,
      "z": 2,
      "name": "Rock_Basalt"
    },
    {
      "x": -6,
      "y": 12,
      "z": 2,
      "name": "Rock_Basalt"
    },
    {
      "x": -6,
      "y": 13,
      "z": 2,
      "name": "Rock_Basalt"
    },
    {
      "x": -6,
      "y": 14,
      "z": 2,
      "name": "Rock_Stone"
    },
    {
      "x": -6,
      "y": 15,
      "z": 2,
      "name": "Rock_Stone"
    },
    {
      "x": -6,
      "y": 16,
      "z": 2,
      "name": "Plant_Moss_Block_Green_Dark"
    },
    {
      "x": -6,
      "y": 9,
      "z": 3,
      "name": "Rock_Basalt"
    },
    {
      "x": -6,
      "y": 10,
      "z": 3,
      "name": "Rock_Basalt"
    },
    {
      "x": -6,
      "y": 11,
      "z": 3,
      "name": "Rock_Basalt"
    },
    {
      "x": -6,
      "y": 12,
      "z": 3,
      "name": "Rock_Basalt"
    },
    {
      "x": -6,
      "y": 13,
      "z": 3,
      "name": "Rock_Basalt"
    },
    {
      "x": -6,
      "y": 14,
      "z": 3,
      "name": "Rock_Basalt"
    },
    {
      "x": -6,
      "y": 15,
      "z": 3,
      "name": "Rock_Stone"
    },
    {
      "x": -6,
      "y": 16,
      "z": 3,
      "name": "Plant_Moss_Block_Green_Dark"
    },
    {
      "x": -6,
      "y": 8,
      "z": 4,
      "name": "Rock_Basalt"
    },
    {
      "x": -6,
      "y": 9,
      "z": 4,
      "name": "Rock_Basalt"
    },
    {
      "x": -6,
      "y": 10,
      "z": 4,
      "name": "Rock_Basalt"
    },
    {
      "x": -6,
      "y": 11,
      "z": 4,
      "name": "Rock_Basalt"
    },
    {
      "x": -6,
      "y": 12,
      "z": 4,
      "name": "Rock_Basalt"
    },
    {
      "x": -6,
      "y": 13,
      "z": 4,
      "name": "Rock_Basalt"
    },
    {
      "x": -6,
      "y": 14,
      "z": 4,
      "name": "Rock_Basalt"
    },
    {
      "x": -6,
      "y": 15,
      "z": 4,
      "name": "Rock_Stone"
    },
    {
      "x": -6,
      "y": 16,
      "z": 4,
      "name": "Plant_Moss_Block_Green_Dark"
    },
    {
      "x": -6,
      "y": 9,
      "z": 5,
      "name": "Rock_Basalt"
    },
    {
      "x": -6,
      "y": 11,
      "z": 5,
      "name": "Rock_Basalt"
    },
    {
      "x": -6,
      "y": 12,
      "z": 5,
      "name": "Rock_Basalt"
    },
    {
      "x": -6,
      "y": 13,
      "z": 5,
      "name": "Rock_Basalt"
    },
    {
      "x": -6,
      "y": 14,
      "z": 5,
      "name": "Rock_Basalt"
    },
    {
      "x": -6,
      "y": 15,
      "z": 5,
      "name": "Rock_Basalt"
    },
    {
      "x": -6,
      "y": 16,
      "z": 5,
      "name": "Plant_Moss_Block_Green_Dark"
    },
    {
      "x": -6,
      "y": 12,
      "z": 6,
      "name": "Rock_Basalt"
    },
    {
      "x": -6,
      "y": 13,
      "z": 6,
      "name": "Rock_Basalt"
    },
    {
      "x": -6,
      "y": 14,
      "z": 6,
      "name": "Rock_Basalt"
    },
    {
      "x": -6,
      "y": 15,
      "z": 6,
      "name": "Rock_Basalt"
    },
    {
      "x": -5,
      "y": 10,
      "z": -2,
      "name": "Rock_Basalt"
    },
    {
      "x": -5,
      "y": 11,
      "z": -2,
      "name": "Rock_Basalt"
    },
    {
      "x": -5,
      "y": 12,
      "z": -2,
      "name": "Rock_Basalt"
    },
    {
      "x": -5,
      "y": 13,
      "z": -2,
      "name": "Rock_Basalt"
    },
    {
      "x": -5,
      "y": 14,
      "z": -2,
      "name": "Rock_Stone"
    },
    {
      "x": -5,
      "y": 15,
      "z": -2,
      "name": "Rock_Stone"
    },
    {
      "x": -5,
      "y": 16,
      "z": -2,
      "name": "Plant_Moss_Block_Green_Dark"
    },
    {
      "x": -5,
      "y": 5,
      "z": -1,
      "name": "Rock_Basalt"
    },
    {
      "x": -5,
      "y": 6,
      "z": -1,
      "name": "Rock_Basalt"
    },
    {
      "x": -5,
      "y": 7,
      "z": -1,
      "name": "Rock_Basalt"
    },
    {
      "x": -5,
      "y": 8,
      "z": -1,
      "name": "Rock_Basalt"
    },
    {
      "x": -5,
      "y": 9,
      "z": -1,
      "name": "Rock_Basalt"
    },
    {
      "x": -5,
      "y": 10,
      "z": -1,
      "name": "Rock_Basalt"
    },
    {
      "x": -5,
      "y": 11,
      "z": -1,
      "name": "Rock_Basalt"
    },
    {
      "x": -5,
      "y": 12,
      "z": -1,
      "name": "Rock_Basalt"
    },
    {
      "x": -5,
      "y": 13,
      "z": -1,
      "name": "Rock_Basalt"
    },
    {
      "x": -5,
      "y": 14,
      "z": -1,
      "name": "Rock_Stone"
    },
    {
      "x": -5,
      "y": 15,
      "z": -1,
      "name": "Rock_Stone"
    },
    {
      "x": -5,
      "y": 16,
      "z": -1,
      "name": "Plant_Moss_Block_Green_Dark"
    },
    {
      "x": -5,
      "y": 5,
      "z": 0,
      "name": "Rock_Basalt"
    },
    {
      "x": -5,
      "y": 6,
      "z": 0,
      "name": "Rock_Basalt"
    },
    {
      "x": -5,
      "y": 7,
      "z": 0,
      "name": "Rock_Basalt"
    },
    {
      "x": -5,
      "y": 8,
      "z": 0,
      "name": "Rock_Basalt"
    },
    {
      "x": -5,
      "y": 9,
      "z": 0,
      "name": "Rock_Basalt"
    },
    {
      "x": -5,
      "y": 10,
      "z": 0,
      "name": "Rock_Basalt"
    },
    {
      "x": -5,
      "y": 11,
      "z": 0,
      "name": "Rock_Basalt"
    },
    {
      "x": -5,
      "y": 12,
      "z": 0,
      "name": "Rock_Basalt"
    },
    {
      "x": -5,
      "y": 13,
      "z": 0,
      "name": "Rock_Basalt"
    },
    {
      "x": -5,
      "y": 14,
      "z": 0,
      "name": "Rock_Stone"
    },
    {
      "x": -5,
      "y": 15,
      "z": 0,
      "name": "Soil_Dirt_Burnt"
    },
    {
      "x": -5,
      "y": 16,
      "z": 0,
      "name": "Plant_Moss_Block_Green_Dark"
    },
    {
      "x": -5,
      "y": 5,
      "z": 1,
      "name": "Rock_Basalt"
    },
    {
      "x": -5,
      "y": 6,
      "z": 1,
      "name": "Rock_Basalt"
    },
    {
      "x": -5,
      "y": 7,
      "z": 1,
      "name": "Rock_Basalt"
    },
    {
      "x": -5,
      "y": 8,
      "z": 1,
      "name": "Rock_Basalt"
    },
    {
      "x": -5,
      "y": 9,
      "z": 1,
      "name": "Rock_Basalt"
    },
    {
      "x": -5,
      "y": 10,
      "z": 1,
      "name": "Rock_Basalt"
    },
    {
      "x": -5,
      "y": 11,
      "z": 1,
      "name": "Rock_Basalt"
    },
    {
      "x": -5,
      "y": 12,
      "z": 1,
      "name": "Rock_Basalt"
    },
    {
      "x": -5,
      "y": 13,
      "z": 1,
      "name": "Rock_Basalt"
    },
    {
      "x": -5,
      "y": 14,
      "z": 1,
      "name": "Soil_Dirt_Burnt"
    },
    {
      "x": -5,
      "y": 15,
      "z": 1,
      "name": "Soil_Dirt_Burnt"
    },
    {
      "x": -5,
      "y": 6,
      "z": 2,
      "name": "Rock_Basalt"
    },
    {
      "x": -5,
      "y": 7,
      "z": 2,
      "name": "Rock_Basalt"
    },
    {
      "x": -5,
      "y": 8,
      "z": 2,
      "name": "Rock_Basalt"
    },
    {
      "x": -5,
      "y": 9,
      "z": 2,
      "name": "Rock_Basalt"
    },
    {
      "x": -5,
      "y": 10,
      "z": 2,
      "name": "Rock_Basalt"
    },
    {
      "x": -5,
      "y": 11,
      "z": 2,
      "name": "Rock_Basalt"
    },
    {
      "x": -5,
      "y": 12,
      "z": 2,
      "name": "Rock_Basalt"
    },
    {
      "x": -5,
      "y": 13,
      "z": 2,
      "name": "Rock_Basalt"
    },
    {
      "x": -5,
      "y": 14,
      "z": 2,
      "name": "Soil_Dirt_Burnt"
    },
    {
      "x": -5,
      "y": 15,
      "z": 2,
      "name": "Soil_Dirt_Burnt"
    },
    {
      "x": -5,
      "y": 6,
      "z": 3,
      "name": "Rock_Basalt"
    },
    {
      "x": -5,
      "y": 7,
      "z": 3,
      "name": "Rock_Basalt"
    },
    {
      "x": -5,
      "y": 8,
      "z": 3,
      "name": "Rock_Basalt"
    },
    {
      "x": -5,
      "y": 9,
      "z": 3,
      "name": "Rock_Basalt"
    },
    {
      "x": -5,
      "y": 10,
      "z": 3,
      "name": "Rock_Basalt"
    },
    {
      "x": -5,
      "y": 11,
      "z": 3,
      "name": "Rock_Basalt"
    },
    {
      "x": -5,
      "y": 12,
      "z": 3,
      "name": "Rock_Basalt"
    },
    {
      "x": -5,
      "y": 13,
      "z": 3,
      "name": "Rock_Basalt"
    },
    {
      "x": -5,
      "y": 14,
      "z": 3,
      "name": "Soil_Dirt_Burnt"
    },
    {
      "x": -5,
      "y": 15,
      "z": 3,
      "name": "Soil_Dirt_Burnt"
    },
    {
      "x": -5,
      "y": 7,
      "z": 4,
      "name": "Rock_Basalt"
    },
    {
      "x": -5,
      "y": 8,
      "z": 4,
      "name": "Rock_Basalt"
    },
    {
      "x": -5,
      "y": 9,
      "z": 4,
      "name": "Rock_Basalt"
    },
    {
      "x": -5,
      "y": 10,
      "z": 4,
      "name": "Rock_Basalt"
    },
    {
      "x": -5,
      "y": 11,
      "z": 4,
      "name": "Rock_Basalt"
    },
    {
      "x": -5,
      "y": 12,
      "z": 4,
      "name": "Rock_Basalt"
    },
    {
      "x": -5,
      "y": 13,
      "z": 4,
      "name": "Rock_Basalt"
    },
    {
      "x": -5,
      "y": 14,
      "z": 4,
      "name": "Rock_Basalt"
    },
    {
      "x": -5,
      "y": 15,
      "z": 4,
      "name": "Soil_Dirt_Burnt"
    },
    {
      "x": -5,
      "y": 16,
      "z": 4,
      "name": "Plant_Moss_Block_Green_Dark"
    },
    {
      "x": -5,
      "y": 8,
      "z": 5,
      "name": "Rock_Basalt"
    },
    {
      "x": -5,
      "y": 9,
      "z": 5,
      "name": "Rock_Basalt"
    },
    {
      "x": -5,
      "y": 10,
      "z": 5,
      "name": "Rock_Basalt"
    },
    {
      "x": -5,
      "y": 11,
      "z": 5,
      "name": "Rock_Basalt"
    },
    {
      "x": -5,
      "y": 12,
      "z": 5,
      "name": "Rock_Basalt"
    },
    {
      "x": -5,
      "y": 13,
      "z": 5,
      "name": "Rock_Basalt"
    },
    {
      "x": -5,
      "y": 14,
      "z": 5,
      "name": "Rock_Basalt"
    },
    {
      "x": -5,
      "y": 15,
      "z": 5,
      "name": "Rock_Basalt"
    },
    {
      "x": -5,
      "y": 16,
      "z": 5,
      "name": "Plant_Moss_Block_Green_Dark"
    },
    {
      "x": -5,
      "y": 10,
      "z": 6,
      "name": "Rock_Basalt"
    },
    {
      "x": -5,
      "y": 11,
      "z": 6,
      "name": "Rock_Basalt"
    },
    {
      "x": -5,
      "y": 12,
      "z": 6,
      "name": "Rock_Basalt"
    },
    {
      "x": -5,
      "y": 13,
      "z": 6,
      "name": "Rock_Basalt"
    },
    {
      "x": -5,
      "y": 14,
      "z": 6,
      "name": "Rock_Basalt"
    },
    {
      "x": -5,
      "y": 15,
      "z": 6,
      "name": "Rock_Basalt"
    },
    {
      "x": -5,
      "y": 16,
      "z": 6,
      "name": "Plant_Moss_Block_Green_Dark"
    },
    {
      "x": -4,
      "y": 10,
      "z": -4,
      "name": "Rock_Basalt"
    },
    {
      "x": -4,
      "y": 11,
      "z": -4,
      "name": "Rock_Basalt"
    },
    {
      "x": -4,
      "y": 12,
      "z": -4,
      "name": "Rock_Basalt"
    },
    {
      "x": -4,
      "y": 13,
      "z": -4,
      "name": "Rock_Basalt"
    },
    {
      "x": -4,
      "y": 14,
      "z": -4,
      "name": "Rock_Stone"
    },
    {
      "x": -4,
      "y": 15,
      "z": -4,
      "name": "Rock_Stone"
    },
    {
      "x": -4,
      "y": 7,
      "z": -3,
      "name": "Rock_Basalt"
    },
    {
      "x": -4,
      "y": 8,
      "z": -3,
      "name": "Rock_Basalt"
    },
    {
      "x": -4,
      "y": 9,
      "z": -3,
      "name": "Rock_Basalt"
    },
    {
      "x": -4,
      "y": 10,
      "z": -3,
      "name": "Rock_Basalt"
    },
    {
      "x": -4,
      "y": 11,
      "z": -3,
      "name": "Rock_Basalt"
    },
    {
      "x": -4,
      "y": 12,
      "z": -3,
      "name": "Rock_Basalt"
    },
    {
      "x": -4,
      "y": 13,
      "z": -3,
      "name": "Rock_Basalt"
    },
    {
      "x": -4,
      "y": 14,
      "z": -3,
      "name": "Rock_Stone"
    },
    {
      "x": -4,
      "y": 15,
      "z": -3,
      "name": "Rock_Stone"
    },
    {
      "x": -4,
      "y": 16,
      "z": -3,
      "name": "Plant_Moss_Block_Green_Dark"
    },
    {
      "x": -4,
      "y": 5,
      "z": -2,
      "name": "Rock_Basalt"
    },
    {
      "x": -4,
      "y": 6,
      "z": -2,
      "name": "Rock_Basalt"
    },
    {
      "x": -4,
      "y": 7,
      "z": -2,
      "name": "Rock_Basalt"
    },
    {
      "x": -4,
      "y": 8,
      "z": -2,
      "name": "Rock_Basalt"
    },
    {
      "x": -4,
      "y": 9,
      "z": -2,
      "name": "Rock_Basalt"
    },
    {
      "x": -4,
      "y": 10,
      "z": -2,
      "name": "Rock_Basalt"
    },
    {
      "x": -4,
      "y": 11,
      "z": -2,
      "name": "Rock_Basalt"
    },
    {
      "x": -4,
      "y": 12,
      "z": -2,
      "name": "Rock_Basalt"
    },
    {
      "x": -4,
      "y": 13,
      "z": -2,
      "name": "Rock_Basalt"
    },
    {
      "x": -4,
      "y": 14,
      "z": -2,
      "name": "Rock_Stone"
    },
    {
      "x": -4,
      "y": 15,
      "z": -2,
      "name": "Rock_Stone"
    },
    {
      "x": -4,
      "y": 16,
      "z": -2,
      "name": "Plant_Moss_Block_Green_Dark"
    },
    {
      "x": -4,
      "y": 17,
      "z": -2,
      "name": "Plant_Moss_Block_Green_Dark"
    },
    {
      "x": -4,
      "y": 5,
      "z": -1,
      "name": "Rock_Basalt"
    },
    {
      "x": -4,
      "y": 6,
      "z": -1,
      "name": "Rock_Basalt"
    },
    {
      "x": -4,
      "y": 7,
      "z": -1,
      "name": "Rock_Basalt"
    },
    {
      "x": -4,
      "y": 8,
      "z": -1,
      "name": "Rock_Basalt"
    },
    {
      "x": -4,
      "y": 9,
      "z": -1,
      "name": "Rock_Basalt"
    },
    {
      "x": -4,
      "y": 10,
      "z": -1,
      "name": "Rock_Basalt"
    },
    {
      "x": -4,
      "y": 11,
      "z": -1,
      "name": "Rock_Basalt"
    },
    {
      "x": -4,
      "y": 12,
      "z": -1,
      "name": "Rock_Basalt"
    },
    {
      "x": -4,
      "y": 13,
      "z": -1,
      "name": "Rock_Basalt"
    },
    {
      "x": -4,
      "y": 14,
      "z": -1,
      "name": "Rock_Stone"
    },
    {
      "x": -4,
      "y": 15,
      "z": -1,
      "name": "Soil_Dirt_Burnt"
    },
    {
      "x": -4,
      "y": 5,
      "z": 0,
      "name": "Rock_Basalt"
    },
    {
      "x": -4,
      "y": 6,
      "z": 0,
      "name": "Rock_Basalt"
    },
    {
      "x": -4,
      "y": 7,
      "z": 0,
      "name": "Rock_Basalt"
    },
    {
      "x": -4,
      "y": 8,
      "z": 0,
      "name": "Rock_Basalt"
    },
    {
      "x": -4,
      "y": 9,
      "z": 0,
      "name": "Rock_Basalt"
    },
    {
      "x": -4,
      "y": 10,
      "z": 0,
      "name": "Rock_Basalt"
    },
    {
      "x": -4,
      "y": 11,
      "z": 0,
      "name": "Rock_Basalt"
    },
    {
      "x": -4,
      "y": 12,
      "z": 0,
      "name": "Rock_Basalt"
    },
    {
      "x": -4,
      "y": 13,
      "z": 0,
      "name": "Rock_Basalt"
    },
    {
      "x": -4,
      "y": 14,
      "z": 0,
      "name": "Soil_Dirt_Burnt"
    },
    {
      "x": -4,
      "y": 15,
      "z": 0,
      "name": "Soil_Dirt_Burnt"
    },
    {
      "x": -4,
      "y": 5,
      "z": 1,
      "name": "Rock_Basalt"
    },
    {
      "x": -4,
      "y": 6,
      "z": 1,
      "name": "Rock_Basalt"
    },
    {
      "x": -4,
      "y": 7,
      "z": 1,
      "name": "Rock_Basalt"
    },
    {
      "x": -4,
      "y": 8,
      "z": 1,
      "name": "Rock_Basalt"
    },
    {
      "x": -4,
      "y": 9,
      "z": 1,
      "name": "Rock_Basalt"
    },
    {
      "x": -4,
      "y": 10,
      "z": 1,
      "name": "Rock_Basalt"
    },
    {
      "x": -4,
      "y": 11,
      "z": 1,
      "name": "Rock_Basalt"
    },
    {
      "x": -4,
      "y": 12,
      "z": 1,
      "name": "Rock_Basalt"
    },
    {
      "x": -4,
      "y": 13,
      "z": 1,
      "name": "Soil_Dirt_Burnt"
    },
    {
      "x": -4,
      "y": 14,
      "z": 1,
      "name": "Soil_Dirt_Burnt"
    },
    {
      "x": -4,
      "y": 15,
      "z": 1,
      "name": "Soil_Dirt_Burnt"
    },
    {
      "x": -4,
      "y": 5,
      "z": 2,
      "name": "Rock_Basalt"
    },
    {
      "x": -4,
      "y": 6,
      "z": 2,
      "name": "Rock_Basalt"
    },
    {
      "x": -4,
      "y": 7,
      "z": 2,
      "name": "Rock_Basalt"
    },
    {
      "x": -4,
      "y": 8,
      "z": 2,
      "name": "Rock_Basalt"
    },
    {
      "x": -4,
      "y": 9,
      "z": 2,
      "name": "Rock_Basalt"
    },
    {
      "x": -4,
      "y": 10,
      "z": 2,
      "name": "Rock_Basalt"
    },
    {
      "x": -4,
      "y": 11,
      "z": 2,
      "name": "Rock_Basalt"
    },
    {
      "x": -4,
      "y": 12,
      "z": 2,
      "name": "Rock_Basalt"
    },
    {
      "x": -4,
      "y": 13,
      "z": 2,
      "name": "Soil_Dirt_Burnt"
    },
    {
      "x": -4,
      "y": 14,
      "z": 2,
      "name": "Soil_Dirt_Burnt"
    },
    {
      "x": -4,
      "y": 15,
      "z": 2,
      "name": "Soil_Dirt_Burnt"
    },
    {
      "x": -4,
      "y": 5,
      "z": 3,
      "name": "Rock_Basalt"
    },
    {
      "x": -4,
      "y": 6,
      "z": 3,
      "name": "Rock_Basalt"
    },
    {
      "x": -4,
      "y": 7,
      "z": 3,
      "name": "Rock_Basalt"
    },
    {
      "x": -4,
      "y": 8,
      "z": 3,
      "name": "Rock_Basalt"
    },
    {
      "x": -4,
      "y": 9,
      "z": 3,
      "name": "Rock_Basalt"
    },
    {
      "x": -4,
      "y": 10,
      "z": 3,
      "name": "Rock_Basalt"
    },
    {
      "x": -4,
      "y": 11,
      "z": 3,
      "name": "Rock_Basalt"
    },
    {
      "x": -4,
      "y": 12,
      "z": 3,
      "name": "Rock_Basalt"
    },
    {
      "x": -4,
      "y": 13,
      "z": 3,
      "name": "Soil_Dirt_Burnt"
    },
    {
      "x": -4,
      "y": 14,
      "z": 3,
      "name": "Soil_Dirt_Burnt"
    },
    {
      "x": -4,
      "y": 15,
      "z": 3,
      "name": "Soil_Dirt_Burnt"
    },
    {
      "x": -4,
      "y": 6,
      "z": 4,
      "name": "Rock_Basalt"
    },
    {
      "x": -4,
      "y": 7,
      "z": 4,
      "name": "Rock_Basalt"
    },
    {
      "x": -4,
      "y": 8,
      "z": 4,
      "name": "Rock_Basalt"
    },
    {
      "x": -4,
      "y": 9,
      "z": 4,
      "name": "Rock_Basalt"
    },
    {
      "x": -4,
      "y": 10,
      "z": 4,
      "name": "Rock_Basalt"
    },
    {
      "x": -4,
      "y": 11,
      "z": 4,
      "name": "Rock_Basalt"
    },
    {
      "x": -4,
      "y": 12,
      "z": 4,
      "name": "Rock_Basalt"
    },
    {
      "x": -4,
      "y": 13,
      "z": 4,
      "name": "Rock_Basalt"
    },
    {
      "x": -4,
      "y": 14,
      "z": 4,
      "name": "Soil_Dirt_Burnt"
    },
    {
      "x": -4,
      "y": 15,
      "z": 4,
      "name": "Soil_Dirt_Burnt"
    },
    {
      "x": -4,
      "y": 7,
      "z": 5,
      "name": "Rock_Basalt"
    },
    {
      "x": -4,
      "y": 8,
      "z": 5,
      "name": "Rock_Basalt"
    },
    {
      "x": -4,
      "y": 9,
      "z": 5,
      "name": "Rock_Basalt"
    },
    {
      "x": -4,
      "y": 10,
      "z": 5,
      "name": "Rock_Basalt"
    },
    {
      "x": -4,
      "y": 11,
      "z": 5,
      "name": "Rock_Basalt"
    },
    {
      "x": -4,
      "y": 12,
      "z": 5,
      "name": "Rock_Basalt"
    },
    {
      "x": -4,
      "y": 13,
      "z": 5,
      "name": "Rock_Basalt"
    },
    {
      "x": -4,
      "y": 14,
      "z": 5,
      "name": "Rock_Basalt"
    },
    {
      "x": -4,
      "y": 15,
      "z": 5,
      "name": "Soil_Dirt_Burnt"
    },
    {
      "x": -4,
      "y": 7,
      "z": 6,
      "name": "Rock_Basalt"
    },
    {
      "x": -4,
      "y": 8,
      "z": 6,
      "name": "Rock_Basalt"
    },
    {
      "x": -4,
      "y": 9,
      "z": 6,
      "name": "Rock_Basalt"
    },
    {
      "x": -4,
      "y": 10,
      "z": 6,
      "name": "Rock_Basalt"
    },
    {
      "x": -4,
      "y": 11,
      "z": 6,
      "name": "Rock_Basalt"
    },
    {
      "x": -4,
      "y": 12,
      "z": 6,
      "name": "Rock_Basalt"
    },
    {
      "x": -4,
      "y": 13,
      "z": 6,
      "name": "Rock_Basalt"
    },
    {
      "x": -4,
      "y": 14,
      "z": 6,
      "name": "Rock_Basalt"
    },
    {
      "x": -4,
      "y": 15,
      "z": 6,
      "name": "Rock_Basalt"
    },
    {
      "x": -4,
      "y": 16,
      "z": 6,
      "name": "Plant_Moss_Block_Green_Dark"
    },
    {
      "x": -3,
      "y": 10,
      "z": -4,
      "name": "Rock_Basalt"
    },
    {
      "x": -3,
      "y": 11,
      "z": -4,
      "name": "Rock_Basalt"
    },
    {
      "x": -3,
      "y": 12,
      "z": -4,
      "name": "Rock_Basalt"
    },
    {
      "x": -3,
      "y": 13,
      "z": -4,
      "name": "Rock_Basalt"
    },
    {
      "x": -3,
      "y": 14,
      "z": -4,
      "name": "Rock_Stone"
    },
    {
      "x": -3,
      "y": 15,
      "z": -4,
      "name": "Rock_Stone"
    },
    {
      "x": -3,
      "y": 5,
      "z": -3,
      "name": "Rock_Basalt"
    },
    {
      "x": -3,
      "y": 6,
      "z": -3,
      "name": "Rock_Basalt"
    },
    {
      "x": -3,
      "y": 7,
      "z": -3,
      "name": "Rock_Basalt"
    },
    {
      "x": -3,
      "y": 8,
      "z": -3,
      "name": "Rock_Basalt"
    },
    {
      "x": -3,
      "y": 9,
      "z": -3,
      "name": "Rock_Basalt"
    },
    {
      "x": -3,
      "y": 10,
      "z": -3,
      "name": "Rock_Basalt"
    },
    {
      "x": -3,
      "y": 11,
      "z": -3,
      "name": "Rock_Basalt"
    },
    {
      "x": -3,
      "y": 12,
      "z": -3,
      "name": "Rock_Basalt"
    },
    {
      "x": -3,
      "y": 13,
      "z": -3,
      "name": "Rock_Basalt"
    },
    {
      "x": -3,
      "y": 14,
      "z": -3,
      "name": "Rock_Basalt"
    },
    {
      "x": -3,
      "y": 15,
      "z": -3,
      "name": "Rock_Stone"
    },
    {
      "x": -3,
      "y": 16,
      "z": -3,
      "name": "Plant_Moss_Block_Green_Dark"
    },
    {
      "x": -3,
      "y": 17,
      "z": -3,
      "name": "Plant_Moss_Block_Green_Dark"
    },
    {
      "x": -3,
      "y": 5,
      "z": -2,
      "name": "Rock_Basalt"
    },
    {
      "x": -3,
      "y": 6,
      "z": -2,
      "name": "Rock_Basalt"
    },
    {
      "x": -3,
      "y": 7,
      "z": -2,
      "name": "Rock_Basalt"
    },
    {
      "x": -3,
      "y": 8,
      "z": -2,
      "name": "Rock_Basalt"
    },
    {
      "x": -3,
      "y": 9,
      "z": -2,
      "name": "Rock_Basalt"
    },
    {
      "x": -3,
      "y": 10,
      "z": -2,
      "name": "Rock_Basalt"
    },
    {
      "x": -3,
      "y": 11,
      "z": -2,
      "name": "Rock_Basalt"
    },
    {
      "x": -3,
      "y": 12,
      "z": -2,
      "name": "Rock_Basalt"
    },
    {
      "x": -3,
      "y": 13,
      "z": -2,
      "name": "Rock_Basalt"
    },
    {
      "x": -3,
      "y": 14,
      "z": -2,
      "name": "Rock_Stone"
    },
    {
      "x": -3,
      "y": 15,
      "z": -2,
      "name": "Rock_Stone"
    },
    {
      "x": -3,
      "y": 16,
      "z": -2,
      "name": "Plant_Moss_Block_Green_Dark"
    },
    {
      "x": -3,
      "y": 17,
      "z": -2,
      "name": "Plant_Moss_Block_Green_Dark"
    },
    {
      "x": -3,
      "y": 5,
      "z": -1,
      "name": "Rock_Basalt"
    },
    {
      "x": -3,
      "y": 6,
      "z": -1,
      "name": "Rock_Basalt"
    },
    {
      "x": -3,
      "y": 7,
      "z": -1,
      "name": "Rock_Basalt"
    },
    {
      "x": -3,
      "y": 8,
      "z": -1,
      "name": "Rock_Basalt"
    },
    {
      "x": -3,
      "y": 9,
      "z": -1,
      "name": "Rock_Basalt"
    },
    {
      "x": -3,
      "y": 10,
      "z": -1,
      "name": "Rock_Basalt"
    },
    {
      "x": -3,
      "y": 11,
      "z": -1,
      "name": "Rock_Basalt"
    },
    {
      "x": -3,
      "y": 12,
      "z": -1,
      "name": "Rock_Basalt"
    },
    {
      "x": -3,
      "y": 13,
      "z": -1,
      "name": "Rock_Basalt"
    },
    {
      "x": -3,
      "y": 14,
      "z": -1,
      "name": "Soil_Dirt_Burnt"
    },
    {
      "x": -3,
      "y": 15,
      "z": -1,
      "name": "Soil_Dirt_Burnt"
    },
    {
      "x": -3,
      "y": 5,
      "z": 0,
      "name": "Rock_Basalt"
    },
    {
      "x": -3,
      "y": 6,
      "z": 0,
      "name": "Rock_Basalt"
    },
    {
      "x": -3,
      "y": 7,
      "z": 0,
      "name": "Rock_Basalt"
    },
    {
      "x": -3,
      "y": 8,
      "z": 0,
      "name": "Rock_Basalt"
    },
    {
      "x": -3,
      "y": 9,
      "z": 0,
      "name": "Rock_Basalt"
    },
    {
      "x": -3,
      "y": 10,
      "z": 0,
      "name": "Rock_Basalt"
    },
    {
      "x": -3,
      "y": 11,
      "z": 0,
      "name": "Rock_Basalt"
    },
    {
      "x": -3,
      "y": 12,
      "z": 0,
      "name": "Rock_Basalt"
    },
    {
      "x": -3,
      "y": 13,
      "z": 0,
      "name": "Soil_Dirt_Burnt"
    },
    {
      "x": -3,
      "y": 14,
      "z": 0,
      "name": "Soil_Dirt_Burnt"
    },
    {
      "x": -3,
      "y": 15,
      "z": 0,
      "name": "Soil_Dirt_Burnt"
    },
    {
      "x": -3,
      "y": 5,
      "z": 1,
      "name": "Rock_Basalt"
    },
    {
      "x": -3,
      "y": 6,
      "z": 1,
      "name": "Rock_Basalt"
    },
    {
      "x": -3,
      "y": 7,
      "z": 1,
      "name": "Rock_Basalt"
    },
    {
      "x": -3,
      "y": 8,
      "z": 1,
      "name": "Rock_Basalt"
    },
    {
      "x": -3,
      "y": 9,
      "z": 1,
      "name": "Rock_Basalt"
    },
    {
      "x": -3,
      "y": 10,
      "z": 1,
      "name": "Rock_Basalt"
    },
    {
      "x": -3,
      "y": 11,
      "z": 1,
      "name": "Rock_Basalt"
    },
    {
      "x": -3,
      "y": 12,
      "z": 1,
      "name": "Rock_Basalt"
    },
    {
      "x": -3,
      "y": 13,
      "z": 1,
      "name": "Soil_Dirt_Burnt"
    },
    {
      "x": -3,
      "y": 14,
      "z": 1,
      "name": "Soil_Dirt_Burnt"
    },
    {
      "x": -3,
      "y": 15,
      "z": 1,
      "name": "Soil_Dirt_Burnt"
    },
    {
      "x": -3,
      "y": 5,
      "z": 2,
      "name": "Rock_Basalt"
    },
    {
      "x": -3,
      "y": 6,
      "z": 2,
      "name": "Rock_Basalt"
    },
    {
      "x": -3,
      "y": 7,
      "z": 2,
      "name": "Rock_Basalt"
    },
    {
      "x": -3,
      "y": 8,
      "z": 2,
      "name": "Rock_Basalt"
    },
    {
      "x": -3,
      "y": 9,
      "z": 2,
      "name": "Rock_Basalt"
    },
    {
      "x": -3,
      "y": 10,
      "z": 2,
      "name": "Rock_Basalt"
    },
    {
      "x": -3,
      "y": 11,
      "z": 2,
      "name": "Rock_Basalt"
    },
    {
      "x": -3,
      "y": 12,
      "z": 2,
      "name": "Rock_Basalt"
    },
    {
      "x": -3,
      "y": 13,
      "z": 2,
      "name": "Soil_Dirt_Burnt"
    },
    {
      "x": -3,
      "y": 14,
      "z": 2,
      "name": "Soil_Dirt_Burnt"
    },
    {
      "x": -3,
      "y": 15,
      "z": 2,
      "name": "Soil_Dirt_Burnt"
    },
    {
      "x": -3,
      "y": 5,
      "z": 3,
      "name": "Rock_Basalt"
    },
    {
      "x": -3,
      "y": 6,
      "z": 3,
      "name": "Rock_Basalt"
    },
    {
      "x": -3,
      "y": 7,
      "z": 3,
      "name": "Rock_Basalt"
    },
    {
      "x": -3,
      "y": 8,
      "z": 3,
      "name": "Rock_Basalt"
    },
    {
      "x": -3,
      "y": 9,
      "z": 3,
      "name": "Rock_Basalt"
    },
    {
      "x": -3,
      "y": 10,
      "z": 3,
      "name": "Rock_Basalt"
    },
    {
      "x": -3,
      "y": 11,
      "z": 3,
      "name": "Rock_Basalt"
    },
    {
      "x": -3,
      "y": 12,
      "z": 3,
      "name": "Rock_Basalt"
    },
    {
      "x": -3,
      "y": 13,
      "z": 3,
      "name": "Soil_Dirt_Burnt"
    },
    {
      "x": -3,
      "y": 14,
      "z": 3,
      "name": "Soil_Dirt_Burnt"
    },
    {
      "x": -3,
      "y": 15,
      "z": 3,
      "name": "Soil_Dirt_Burnt"
    },
    {
      "x": -3,
      "y": 5,
      "z": 4,
      "name": "Rock_Basalt"
    },
    {
      "x": -3,
      "y": 6,
      "z": 4,
      "name": "Rock_Basalt"
    },
    {
      "x": -3,
      "y": 7,
      "z": 4,
      "name": "Rock_Basalt"
    },
    {
      "x": -3,
      "y": 8,
      "z": 4,
      "name": "Rock_Basalt"
    },
    {
      "x": -3,
      "y": 9,
      "z": 4,
      "name": "Rock_Basalt"
    },
    {
      "x": -3,
      "y": 10,
      "z": 4,
      "name": "Rock_Basalt"
    },
    {
      "x": -3,
      "y": 11,
      "z": 4,
      "name": "Rock_Basalt"
    },
    {
      "x": -3,
      "y": 12,
      "z": 4,
      "name": "Rock_Basalt"
    },
    {
      "x": -3,
      "y": 13,
      "z": 4,
      "name": "Soil_Dirt_Burnt"
    },
    {
      "x": -3,
      "y": 14,
      "z": 4,
      "name": "Soil_Dirt_Burnt"
    },
    {
      "x": -3,
      "y": 15,
      "z": 4,
      "name": "Soil_Dirt_Burnt"
    },
    {
      "x": -3,
      "y": 6,
      "z": 5,
      "name": "Rock_Basalt"
    },
    {
      "x": -3,
      "y": 7,
      "z": 5,
      "name": "Rock_Basalt"
    },
    {
      "x": -3,
      "y": 8,
      "z": 5,
      "name": "Rock_Basalt"
    },
    {
      "x": -3,
      "y": 9,
      "z": 5,
      "name": "Rock_Basalt"
    },
    {
      "x": -3,
      "y": 10,
      "z": 5,
      "name": "Rock_Basalt"
    },
    {
      "x": -3,
      "y": 11,
      "z": 5,
      "name": "Rock_Basalt"
    },
    {
      "x": -3,
      "y": 12,
      "z": 5,
      "name": "Rock_Basalt"
    },
    {
      "x": -3,
      "y": 13,
      "z": 5,
      "name": "Rock_Basalt"
    },
    {
      "x": -3,
      "y": 14,
      "z": 5,
      "name": "Soil_Dirt_Burnt"
    },
    {
      "x": -3,
      "y": 15,
      "z": 5,
      "name": "Soil_Dirt_Burnt"
    },
    {
      "x": -3,
      "y": 6,
      "z": 6,
      "name": "Rock_Basalt"
    },
    {
      "x": -3,
      "y": 7,
      "z": 6,
      "name": "Rock_Basalt"
    },
    {
      "x": -3,
      "y": 8,
      "z": 6,
      "name": "Rock_Basalt"
    },
    {
      "x": -3,
      "y": 9,
      "z": 6,
      "name": "Rock_Basalt"
    },
    {
      "x": -3,
      "y": 10,
      "z": 6,
      "name": "Rock_Basalt"
    },
    {
      "x": -3,
      "y": 11,
      "z": 6,
      "name": "Rock_Basalt"
    },
    {
      "x": -3,
      "y": 12,
      "z": 6,
      "name": "Rock_Basalt"
    },
    {
      "x": -3,
      "y": 13,
      "z": 6,
      "name": "Rock_Basalt"
    },
    {
      "x": -3,
      "y": 14,
      "z": 6,
      "name": "Rock_Basalt"
    },
    {
      "x": -3,
      "y": 15,
      "z": 6,
      "name": "Rock_Basalt"
    },
    {
      "x": -3,
      "y": 16,
      "z": 6,
      "name": "Plant_Moss_Block_Green_Dark"
    },
    {
      "x": -3,
      "y": 7,
      "z": 7,
      "name": "Rock_Basalt"
    },
    {
      "x": -3,
      "y": 8,
      "z": 7,
      "name": "Rock_Basalt"
    },
    {
      "x": -3,
      "y": 9,
      "z": 7,
      "name": "Rock_Basalt"
    },
    {
      "x": -3,
      "y": 10,
      "z": 7,
      "name": "Rock_Basalt"
    },
    {
      "x": -3,
      "y": 11,
      "z": 7,
      "name": "Rock_Basalt"
    },
    {
      "x": -3,
      "y": 12,
      "z": 7,
      "name": "Rock_Basalt"
    },
    {
      "x": -3,
      "y": 13,
      "z": 7,
      "name": "Rock_Basalt"
    },
    {
      "x": -3,
      "y": 14,
      "z": 7,
      "name": "Rock_Basalt"
    },
    {
      "x": -3,
      "y": 15,
      "z": 7,
      "name": "Rock_Basalt"
    },
    {
      "x": -3,
      "y": 16,
      "z": 7,
      "name": "Plant_Moss_Block_Green_Dark"
    },
    {
      "x": -2,
      "y": 11,
      "z": -5,
      "name": "Rock_Basalt"
    },
    {
      "x": -2,
      "y": 12,
      "z": -5,
      "name": "Rock_Basalt"
    },
    {
      "x": -2,
      "y": 13,
      "z": -5,
      "name": "Rock_Basalt"
    },
    {
      "x": -2,
      "y": 8,
      "z": -4,
      "name": "Rock_Basalt"
    },
    {
      "x": -2,
      "y": 9,
      "z": -4,
      "name": "Rock_Basalt"
    },
    {
      "x": -2,
      "y": 10,
      "z": -4,
      "name": "Rock_Basalt"
    },
    {
      "x": -2,
      "y": 11,
      "z": -4,
      "name": "Rock_Basalt"
    },
    {
      "x": -2,
      "y": 12,
      "z": -4,
      "name": "Rock_Basalt"
    },
    {
      "x": -2,
      "y": 13,
      "z": -4,
      "name": "Rock_Basalt"
    },
    {
      "x": -2,
      "y": 14,
      "z": -4,
      "name": "Rock_Basalt"
    },
    {
      "x": -2,
      "y": 15,
      "z": -4,
      "name": "Rock_Stone"
    },
    {
      "x": -2,
      "y": 16,
      "z": -4,
      "name": "Rock_Stone"
    },
    {
      "x": -2,
      "y": 5,
      "z": -3,
      "name": "Rock_Basalt"
    },
    {
      "x": -2,
      "y": 6,
      "z": -3,
      "name": "Rock_Basalt"
    },
    {
      "x": -2,
      "y": 7,
      "z": -3,
      "name": "Rock_Basalt"
    },
    {
      "x": -2,
      "y": 8,
      "z": -3,
      "name": "Rock_Basalt"
    },
    {
      "x": -2,
      "y": 9,
      "z": -3,
      "name": "Rock_Basalt"
    },
    {
      "x": -2,
      "y": 10,
      "z": -3,
      "name": "Rock_Basalt"
    },
    {
      "x": -2,
      "y": 11,
      "z": -3,
      "name": "Rock_Basalt"
    },
    {
      "x": -2,
      "y": 12,
      "z": -3,
      "name": "Rock_Basalt"
    },
    {
      "x": -2,
      "y": 13,
      "z": -3,
      "name": "Rock_Basalt"
    },
    {
      "x": -2,
      "y": 14,
      "z": -3,
      "name": "Rock_Basalt"
    },
    {
      "x": -2,
      "y": 15,
      "z": -3,
      "name": "Rock_Stone"
    },
    {
      "x": -2,
      "y": 16,
      "z": -3,
      "name": "Plant_Moss_Block_Green_Dark"
    },
    {
      "x": -2,
      "y": 17,
      "z": -3,
      "name": "Plant_Moss_Block_Green_Dark"
    },
    {
      "x": -2,
      "y": 5,
      "z": -2,
      "name": "Rock_Basalt"
    },
    {
      "x": -2,
      "y": 6,
      "z": -2,
      "name": "Rock_Basalt"
    },
    {
      "x": -2,
      "y": 7,
      "z": -2,
      "name": "Rock_Basalt"
    },
    {
      "x": -2,
      "y": 8,
      "z": -2,
      "name": "Rock_Basalt"
    },
    {
      "x": -2,
      "y": 9,
      "z": -2,
      "name": "Rock_Basalt"
    },
    {
      "x": -2,
      "y": 10,
      "z": -2,
      "name": "Rock_Basalt"
    },
    {
      "x": -2,
      "y": 11,
      "z": -2,
      "name": "Rock_Basalt"
    },
    {
      "x": -2,
      "y": 12,
      "z": -2,
      "name": "Rock_Basalt"
    },
    {
      "x": -2,
      "y": 13,
      "z": -2,
      "name": "Rock_Basalt"
    },
    {
      "x": -2,
      "y": 14,
      "z": -2,
      "name": "Rock_Basalt"
    },
    {
      "x": -2,
      "y": 15,
      "z": -2,
      "name": "Rock_Stone"
    },
    {
      "x": -2,
      "y": 16,
      "z": -2,
      "name": "Plant_Moss_Block_Green_Dark"
    },
    {
      "x": -2,
      "y": 5,
      "z": -1,
      "name": "Rock_Basalt"
    },
    {
      "x": -2,
      "y": 6,
      "z": -1,
      "name": "Rock_Basalt"
    },
    {
      "x": -2,
      "y": 7,
      "z": -1,
      "name": "Rock_Basalt"
    },
    {
      "x": -2,
      "y": 8,
      "z": -1,
      "name": "Rock_Basalt"
    },
    {
      "x": -2,
      "y": 9,
      "z": -1,
      "name": "Rock_Basalt"
    },
    {
      "x": -2,
      "y": 10,
      "z": -1,
      "name": "Rock_Basalt"
    },
    {
      "x": -2,
      "y": 11,
      "z": -1,
      "name": "Rock_Basalt"
    },
    {
      "x": -2,
      "y": 12,
      "z": -1,
      "name": "Rock_Basalt"
    },
    {
      "x": -2,
      "y": 13,
      "z": -1,
      "name": "Rock_Basalt"
    },
    {
      "x": -2,
      "y": 14,
      "z": -1,
      "name": "Rock_Basalt"
    },
    {
      "x": -2,
      "y": 15,
      "z": -1,
      "name": "Soil_Dirt_Burnt"
    },
    {
      "x": -2,
      "y": 5,
      "z": 0,
      "name": "Rock_Basalt"
    },
    {
      "x": -2,
      "y": 6,
      "z": 0,
      "name": "Rock_Basalt"
    },
    {
      "x": -2,
      "y": 7,
      "z": 0,
      "name": "Rock_Basalt"
    },
    {
      "x": -2,
      "y": 8,
      "z": 0,
      "name": "Rock_Basalt"
    },
    {
      "x": -2,
      "y": 9,
      "z": 0,
      "name": "Rock_Basalt"
    },
    {
      "x": -2,
      "y": 10,
      "z": 0,
      "name": "Rock_Basalt"
    },
    {
      "x": -2,
      "y": 11,
      "z": 0,
      "name": "Rock_Basalt"
    },
    {
      "x": -2,
      "y": 12,
      "z": 0,
      "name": "Rock_Basalt"
    },
    {
      "x": -2,
      "y": 13,
      "z": 0,
      "name": "Rock_Basalt"
    },
    {
      "x": -2,
      "y": 14,
      "z": 0,
      "name": "Soil_Dirt_Burnt"
    },
    {
      "x": -2,
      "y": 15,
      "z": 0,
      "name": "Soil_Dirt_Burnt"
    },
    {
      "x": -2,
      "y": 5,
      "z": 1,
      "name": "Rock_Basalt"
    },
    {
      "x": -2,
      "y": 6,
      "z": 1,
      "name": "Rock_Basalt"
    },
    {
      "x": -2,
      "y": 7,
      "z": 1,
      "name": "Rock_Basalt"
    },
    {
      "x": -2,
      "y": 8,
      "z": 1,
      "name": "Rock_Basalt"
    },
    {
      "x": -2,
      "y": 9,
      "z": 1,
      "name": "Rock_Basalt"
    },
    {
      "x": -2,
      "y": 10,
      "z": 1,
      "name": "Rock_Basalt"
    },
    {
      "x": -2,
      "y": 11,
      "z": 1,
      "name": "Rock_Basalt"
    },
    {
      "x": -2,
      "y": 12,
      "z": 1,
      "name": "Rock_Basalt"
    },
    {
      "x": -2,
      "y": 13,
      "z": 1,
      "name": "Soil_Dirt_Burnt"
    },
    {
      "x": -2,
      "y": 14,
      "z": 1,
      "name": "Soil_Dirt_Burnt"
    },
    {
      "x": -2,
      "y": 15,
      "z": 1,
      "name": "Soil_Dirt_Burnt"
    },
    {
      "x": -2,
      "y": 5,
      "z": 2,
      "name": "Rock_Basalt"
    },
    {
      "x": -2,
      "y": 6,
      "z": 2,
      "name": "Rock_Basalt"
    },
    {
      "x": -2,
      "y": 7,
      "z": 2,
      "name": "Rock_Basalt"
    },
    {
      "x": -2,
      "y": 8,
      "z": 2,
      "name": "Rock_Basalt"
    },
    {
      "x": -2,
      "y": 9,
      "z": 2,
      "name": "Rock_Basalt"
    },
    {
      "x": -2,
      "y": 10,
      "z": 2,
      "name": "Rock_Basalt"
    },
    {
      "x": -2,
      "y": 11,
      "z": 2,
      "name": "Rock_Basalt"
    },
    {
      "x": -2,
      "y": 12,
      "z": 2,
      "name": "Rock_Basalt"
    },
    {
      "x": -2,
      "y": 13,
      "z": 2,
      "name": "Soil_Dirt_Burnt"
    },
    {
      "x": -2,
      "y": 14,
      "z": 2,
      "name": "Soil_Dirt_Burnt"
    },
    {
      "x": -2,
      "y": 15,
      "z": 2,
      "name": "Soil_Dirt_Burnt"
    },
    {
      "x": -2,
      "y": 4,
      "z": 3,
      "name": "Rock_Basalt"
    },
    {
      "x": -2,
      "y": 5,
      "z": 3,
      "name": "Rock_Basalt"
    },
    {
      "x": -2,
      "y": 6,
      "z": 3,
      "name": "Rock_Basalt"
    },
    {
      "x": -2,
      "y": 7,
      "z": 3,
      "name": "Rock_Basalt"
    },
    {
      "x": -2,
      "y": 8,
      "z": 3,
      "name": "Rock_Basalt"
    },
    {
      "x": -2,
      "y": 9,
      "z": 3,
      "name": "Rock_Basalt"
    },
    {
      "x": -2,
      "y": 10,
      "z": 3,
      "name": "Rock_Basalt"
    },
    {
      "x": -2,
      "y": 11,
      "z": 3,
      "name": "Rock_Basalt"
    },
    {
      "x": -2,
      "y": 12,
      "z": 3,
      "name": "Rock_Basalt"
    },
    {
      "x": -2,
      "y": 13,
      "z": 3,
      "name": "Soil_Dirt_Burnt"
    },
    {
      "x": -2,
      "y": 14,
      "z": 3,
      "name": "Soil_Dirt_Burnt"
    },
    {
      "x": -2,
      "y": 15,
      "z": 3,
      "name": "Soil_Dirt_Burnt"
    },
    {
      "x": -2,
      "y": 4,
      "z": 4,
      "name": "Rock_Basalt"
    },
    {
      "x": -2,
      "y": 5,
      "z": 4,
      "name": "Rock_Basalt"
    },
    {
      "x": -2,
      "y": 6,
      "z": 4,
      "name": "Rock_Basalt"
    },
    {
      "x": -2,
      "y": 7,
      "z": 4,
      "name": "Rock_Basalt"
    },
    {
      "x": -2,
      "y": 8,
      "z": 4,
      "name": "Rock_Basalt"
    },
    {
      "x": -2,
      "y": 9,
      "z": 4,
      "name": "Rock_Basalt"
    },
    {
      "x": -2,
      "y": 10,
      "z": 4,
      "name": "Rock_Basalt"
    },
    {
      "x": -2,
      "y": 11,
      "z": 4,
      "name": "Rock_Basalt"
    },
    {
      "x": -2,
      "y": 12,
      "z": 4,
      "name": "Rock_Basalt"
    },
    {
      "x": -2,
      "y": 13,
      "z": 4,
      "name": "Soil_Dirt_Burnt"
    },
    {
      "x": -2,
      "y": 14,
      "z": 4,
      "name": "Soil_Dirt_Burnt"
    },
    {
      "x": -2,
      "y": 15,
      "z": 4,
      "name": "Soil_Dirt_Burnt"
    },
    {
      "x": -2,
      "y": 5,
      "z": 5,
      "name": "Rock_Basalt"
    },
    {
      "x": -2,
      "y": 6,
      "z": 5,
      "name": "Rock_Basalt"
    },
    {
      "x": -2,
      "y": 7,
      "z": 5,
      "name": "Rock_Basalt"
    },
    {
      "x": -2,
      "y": 8,
      "z": 5,
      "name": "Rock_Basalt"
    },
    {
      "x": -2,
      "y": 9,
      "z": 5,
      "name": "Rock_Basalt"
    },
    {
      "x": -2,
      "y": 10,
      "z": 5,
      "name": "Rock_Basalt"
    },
    {
      "x": -2,
      "y": 11,
      "z": 5,
      "name": "Rock_Basalt"
    },
    {
      "x": -2,
      "y": 12,
      "z": 5,
      "name": "Rock_Basalt"
    },
    {
      "x": -2,
      "y": 13,
      "z": 5,
      "name": "Rock_Basalt"
    },
    {
      "x": -2,
      "y": 14,
      "z": 5,
      "name": "Soil_Dirt_Burnt"
    },
    {
      "x": -2,
      "y": 15,
      "z": 5,
      "name": "Soil_Dirt_Burnt"
    },
    {
      "x": -2,
      "y": 5,
      "z": 6,
      "name": "Rock_Basalt"
    },
    {
      "x": -2,
      "y": 6,
      "z": 6,
      "name": "Rock_Basalt"
    },
    {
      "x": -2,
      "y": 7,
      "z": 6,
      "name": "Rock_Basalt"
    },
    {
      "x": -2,
      "y": 8,
      "z": 6,
      "name": "Rock_Basalt"
    },
    {
      "x": -2,
      "y": 9,
      "z": 6,
      "name": "Rock_Basalt"
    },
    {
      "x": -2,
      "y": 10,
      "z": 6,
      "name": "Rock_Basalt"
    },
    {
      "x": -2,
      "y": 11,
      "z": 6,
      "name": "Rock_Basalt"
    },
    {
      "x": -2,
      "y": 12,
      "z": 6,
      "name": "Rock_Basalt"
    },
    {
      "x": -2,
      "y": 13,
      "z": 6,
      "name": "Rock_Basalt"
    },
    {
      "x": -2,
      "y": 14,
      "z": 6,
      "name": "Rock_Basalt"
    },
    {
      "x": -2,
      "y": 15,
      "z": 6,
      "name": "Soil_Dirt_Burnt"
    },
    {
      "x": -2,
      "y": 6,
      "z": 7,
      "name": "Rock_Basalt"
    },
    {
      "x": -2,
      "y": 7,
      "z": 7,
      "name": "Rock_Basalt"
    },
    {
      "x": -2,
      "y": 8,
      "z": 7,
      "name": "Rock_Basalt"
    },
    {
      "x": -2,
      "y": 9,
      "z": 7,
      "name": "Rock_Basalt"
    },
    {
      "x": -2,
      "y": 10,
      "z": 7,
      "name": "Rock_Basalt"
    },
    {
      "x": -2,
      "y": 11,
      "z": 7,
      "name": "Rock_Basalt"
    },
    {
      "x": -2,
      "y": 12,
      "z": 7,
      "name": "Rock_Basalt"
    },
    {
      "x": -2,
      "y": 13,
      "z": 7,
      "name": "Rock_Basalt"
    },
    {
      "x": -2,
      "y": 14,
      "z": 7,
      "name": "Rock_Basalt"
    },
    {
      "x": -2,
      "y": 15,
      "z": 7,
      "name": "Rock_Basalt"
    },
    {
      "x": -2,
      "y": 16,
      "z": 7,
      "name": "Plant_Moss_Block_Green_Dark"
    },
    {
      "x": -2,
      "y": 8,
      "z": 8,
      "name": "Rock_Basalt"
    },
    {
      "x": -2,
      "y": 9,
      "z": 8,
      "name": "Rock_Basalt"
    },
    {
      "x": -2,
      "y": 10,
      "z": 8,
      "name": "Rock_Basalt"
    },
    {
      "x": -2,
      "y": 11,
      "z": 8,
      "name": "Rock_Basalt"
    },
    {
      "x": -2,
      "y": 12,
      "z": 8,
      "name": "Rock_Basalt"
    },
    {
      "x": -2,
      "y": 13,
      "z": 8,
      "name": "Rock_Basalt"
    },
    {
      "x": -2,
      "y": 14,
      "z": 8,
      "name": "Rock_Basalt"
    },
    {
      "x": -2,
      "y": 15,
      "z": 8,
      "name": "Rock_Stone"
    },
    {
      "x": -1,
      "y": 12,
      "z": -6,
      "name": "Rock_Basalt"
    },
    {
      "x": -1,
      "y": 13,
      "z": -6,
      "name": "Rock_Basalt"
    },
    {
      "x": -1,
      "y": 14,
      "z": -6,
      "name": "Rock_Basalt"
    },
    {
      "x": -1,
      "y": 9,
      "z": -5,
      "name": "Rock_Basalt"
    },
    {
      "x": -1,
      "y": 10,
      "z": -5,
      "name": "Rock_Basalt"
    },
    {
      "x": -1,
      "y": 11,
      "z": -5,
      "name": "Rock_Basalt"
    },
    {
      "x": -1,
      "y": 12,
      "z": -5,
      "name": "Rock_Basalt"
    },
    {
      "x": -1,
      "y": 13,
      "z": -5,
      "name": "Rock_Basalt"
    },
    {
      "x": -1,
      "y": 14,
      "z": -5,
      "name": "Rock_Basalt"
    },
    {
      "x": -1,
      "y": 15,
      "z": -5,
      "name": "Rock_Basalt"
    },
    {
      "x": -1,
      "y": 6,
      "z": -4,
      "name": "Rock_Basalt"
    },
    {
      "x": -1,
      "y": 7,
      "z": -4,
      "name": "Rock_Basalt"
    },
    {
      "x": -1,
      "y": 8,
      "z": -4,
      "name": "Rock_Basalt"
    },
    {
      "x": -1,
      "y": 9,
      "z": -4,
      "name": "Rock_Basalt"
    },
    {
      "x": -1,
      "y": 10,
      "z": -4,
      "name": "Rock_Basalt"
    },
    {
      "x": -1,
      "y": 11,
      "z": -4,
      "name": "Rock_Basalt"
    },
    {
      "x": -1,
      "y": 12,
      "z": -4,
      "name": "Rock_Basalt"
    },
    {
      "x": -1,
      "y": 13,
      "z": -4,
      "name": "Rock_Basalt"
    },
    {
      "x": -1,
      "y": 14,
      "z": -4,
      "name": "Rock_Basalt"
    },
    {
      "x": -1,
      "y": 15,
      "z": -4,
      "name": "Rock_Basalt"
    },
    {
      "x": -1,
      "y": 16,
      "z": -4,
      "name": "Rock_Basalt"
    },
    {
      "x": -1,
      "y": 17,
      "z": -4,
      "name": "Rock_Basalt"
    },
    {
      "x": -1,
      "y": 5,
      "z": -3,
      "name": "Rock_Basalt"
    },
    {
      "x": -1,
      "y": 6,
      "z": -3,
      "name": "Rock_Basalt"
    },
    {
      "x": -1,
      "y": 7,
      "z": -3,
      "name": "Rock_Basalt"
    },
    {
      "x": -1,
      "y": 8,
      "z": -3,
      "name": "Rock_Basalt"
    },
    {
      "x": -1,
      "y": 9,
      "z": -3,
      "name": "Rock_Basalt"
    },
    {
      "x": -1,
      "y": 10,
      "z": -3,
      "name": "Rock_Basalt"
    },
    {
      "x": -1,
      "y": 11,
      "z": -3,
      "name": "Rock_Basalt"
    },
    {
      "x": -1,
      "y": 12,
      "z": -3,
      "name": "Rock_Basalt"
    },
    {
      "x": -1,
      "y": 13,
      "z": -3,
      "name": "Rock_Basalt"
    },
    {
      "x": -1,
      "y": 14,
      "z": -3,
      "name": "Rock_Basalt"
    },
    {
      "x": -1,
      "y": 15,
      "z": -3,
      "name": "Rock_Basalt"
    },
    {
      "x": -1,
      "y": 16,
      "z": -3,
      "name": "Plant_Moss_Block_Green_Dark"
    },
    {
      "x": -1,
      "y": 17,
      "z": -3,
      "name": "Rock_Basalt"
    },
    {
      "x": -1,
      "y": 5,
      "z": -2,
      "name": "Rock_Basalt"
    },
    {
      "x": -1,
      "y": 6,
      "z": -2,
      "name": "Rock_Basalt"
    },
    {
      "x": -1,
      "y": 7,
      "z": -2,
      "name": "Rock_Basalt"
    },
    {
      "x": -1,
      "y": 8,
      "z": -2,
      "name": "Rock_Basalt"
    },
    {
      "x": -1,
      "y": 9,
      "z": -2,
      "name": "Rock_Basalt"
    },
    {
      "x": -1,
      "y": 10,
      "z": -2,
      "name": "Rock_Basalt"
    },
    {
      "x": -1,
      "y": 11,
      "z": -2,
      "name": "Rock_Basalt"
    },
    {
      "x": -1,
      "y": 12,
      "z": -2,
      "name": "Rock_Basalt"
    },
    {
      "x": -1,
      "y": 13,
      "z": -2,
      "name": "Rock_Basalt"
    },
    {
      "x": -1,
      "y": 14,
      "z": -2,
      "name": "Rock_Basalt"
    },
    {
      "x": -1,
      "y": 15,
      "z": -2,
      "name": "Rock_Stone"
    },
    {
      "x": -1,
      "y": 16,
      "z": -2,
      "name": "Plant_Moss_Block_Green_Dark"
    },
    {
      "x": -1,
      "y": 17,
      "z": -2,
      "name": "Plant_Moss_Block_Green_Dark"
    },
    {
      "x": -1,
      "y": 5,
      "z": -1,
      "name": "Rock_Basalt"
    },
    {
      "x": -1,
      "y": 6,
      "z": -1,
      "name": "Rock_Basalt"
    },
    {
      "x": -1,
      "y": 7,
      "z": -1,
      "name": "Rock_Basalt"
    },
    {
      "x": -1,
      "y": 8,
      "z": -1,
      "name": "Rock_Basalt"
    },
    {
      "x": -1,
      "y": 9,
      "z": -1,
      "name": "Rock_Basalt"
    },
    {
      "x": -1,
      "y": 10,
      "z": -1,
      "name": "Rock_Basalt"
    },
    {
      "x": -1,
      "y": 11,
      "z": -1,
      "name": "Rock_Basalt"
    },
    {
      "x": -1,
      "y": 12,
      "z": -1,
      "name": "Rock_Basalt"
    },
    {
      "x": -1,
      "y": 13,
      "z": -1,
      "name": "Rock_Basalt"
    },
    {
      "x": -1,
      "y": 14,
      "z": -1,
      "name": "Rock_Basalt"
    },
    {
      "x": -1,
      "y": 15,
      "z": -1,
      "name": "Rock_Stone"
    },
    {
      "x": -1,
      "y": 16,
      "z": -1,
      "name": "Plant_Moss_Block_Green_Dark"
    },
    {
      "x": -1,
      "y": 17,
      "z": -1,
      "name": "Plant_Moss_Block_Green_Dark"
    },
    {
      "x": -1,
      "y": 5,
      "z": 0,
      "name": "Rock_Basalt"
    },
    {
      "x": -1,
      "y": 6,
      "z": 0,
      "name": "Rock_Basalt"
    },
    {
      "x": -1,
      "y": 7,
      "z": 0,
      "name": "Rock_Basalt"
    },
    {
      "x": -1,
      "y": 8,
      "z": 0,
      "name": "Rock_Basalt"
    },
    {
      "x": -1,
      "y": 9,
      "z": 0,
      "name": "Rock_Basalt"
    },
    {
      "x": -1,
      "y": 10,
      "z": 0,
      "name": "Rock_Basalt"
    },
    {
      "x": -1,
      "y": 11,
      "z": 0,
      "name": "Rock_Basalt"
    },
    {
      "x": -1,
      "y": 12,
      "z": 0,
      "name": "Rock_Basalt"
    },
    {
      "x": -1,
      "y": 13,
      "z": 0,
      "name": "Rock_Basalt"
    },
    {
      "x": -1,
      "y": 14,
      "z": 0,
      "name": "Rock_Basalt"
    },
    {
      "x": -1,
      "y": 15,
      "z": 0,
      "name": "Soil_Dirt_Burnt"
    },
    {
      "x": -1,
      "y": 16,
      "z": 0,
      "name": "Plant_Moss_Block_Green_Dark"
    },
    {
      "x": -1,
      "y": 17,
      "z": 0,
      "name": "Plant_Crop_Mushroom_Shelve_Brown"
    },
    {
      "x": -1,
      "y": 5,
      "z": 1,
      "name": "Rock_Basalt"
    },
    {
      "x": -1,
      "y": 6,
      "z": 1,
      "name": "Rock_Basalt"
    },
    {
      "x": -1,
      "y": 7,
      "z": 1,
      "name": "Rock_Basalt"
    },
    {
      "x": -1,
      "y": 8,
      "z": 1,
      "name": "Rock_Basalt"
    },
    {
      "x": -1,
      "y": 9,
      "z": 1,
      "name": "Rock_Basalt"
    },
    {
      "x": -1,
      "y": 10,
      "z": 1,
      "name": "Rock_Basalt"
    },
    {
      "x": -1,
      "y": 11,
      "z": 1,
      "name": "Rock_Basalt"
    },
    {
      "x": -1,
      "y": 12,
      "z": 1,
      "name": "Rock_Basalt"
    },
    {
      "x": -1,
      "y": 13,
      "z": 1,
      "name": "Rock_Basalt"
    },
    {
      "x": -1,
      "y": 14,
      "z": 1,
      "name": "Soil_Dirt_Burnt"
    },
    {
      "x": -1,
      "y": 15,
      "z": 1,
      "name": "Soil_Dirt_Burnt"
    },
    {
      "x": -1,
      "y": 16,
      "z": 1,
      "name": "Plant_Moss_Block_Green_Dark"
    },
    {
      "x": -1,
      "y": 4,
      "z": 2,
      "name": "Rock_Basalt"
    },
    {
      "x": -1,
      "y": 5,
      "z": 2,
      "name": "Rock_Basalt"
    },
    {
      "x": -1,
      "y": 6,
      "z": 2,
      "name": "Rock_Basalt"
    },
    {
      "x": -1,
      "y": 7,
      "z": 2,
      "name": "Rock_Basalt"
    },
    {
      "x": -1,
      "y": 8,
      "z": 2,
      "name": "Rock_Basalt"
    },
    {
      "x": -1,
      "y": 9,
      "z": 2,
      "name": "Rock_Basalt"
    },
    {
      "x": -1,
      "y": 10,
      "z": 2,
      "name": "Rock_Basalt"
    },
    {
      "x": -1,
      "y": 11,
      "z": 2,
      "name": "Rock_Basalt"
    },
    {
      "x": -1,
      "y": 12,
      "z": 2,
      "name": "Rock_Basalt"
    },
    {
      "x": -1,
      "y": 13,
      "z": 2,
      "name": "Rock_Basalt"
    },
    {
      "x": -1,
      "y": 14,
      "z": 2,
      "name": "Soil_Dirt_Burnt"
    },
    {
      "x": -1,
      "y": 15,
      "z": 2,
      "name": "Soil_Dirt_Burnt"
    },
    {
      "x": -1,
      "y": 4,
      "z": 3,
      "name": "Rock_Basalt"
    },
    {
      "x": -1,
      "y": 5,
      "z": 3,
      "name": "Rock_Basalt"
    },
    {
      "x": -1,
      "y": 6,
      "z": 3,
      "name": "Rock_Basalt"
    },
    {
      "x": -1,
      "y": 7,
      "z": 3,
      "name": "Rock_Basalt"
    },
    {
      "x": -1,
      "y": 8,
      "z": 3,
      "name": "Rock_Basalt"
    },
    {
      "x": -1,
      "y": 9,
      "z": 3,
      "name": "Rock_Basalt"
    },
    {
      "x": -1,
      "y": 10,
      "z": 3,
      "name": "Rock_Basalt"
    },
    {
      "x": -1,
      "y": 11,
      "z": 3,
      "name": "Rock_Basalt"
    },
    {
      "x": -1,
      "y": 12,
      "z": 3,
      "name": "Rock_Basalt"
    },
    {
      "x": -1,
      "y": 13,
      "z": 3,
      "name": "Soil_Dirt_Burnt"
    },
    {
      "x": -1,
      "y": 14,
      "z": 3,
      "name": "Soil_Dirt_Burnt"
    },
    {
      "x": -1,
      "y": 15,
      "z": 3,
      "name": "Soil_Dirt_Burnt"
    },
    {
      "x": -1,
      "y": 4,
      "z": 4,
      "name": "Rock_Basalt"
    },
    {
      "x": -1,
      "y": 5,
      "z": 4,
      "name": "Rock_Basalt"
    },
    {
      "x": -1,
      "y": 6,
      "z": 4,
      "name": "Rock_Basalt"
    },
    {
      "x": -1,
      "y": 7,
      "z": 4,
      "name": "Rock_Basalt"
    },
    {
      "x": -1,
      "y": 8,
      "z": 4,
      "name": "Rock_Basalt"
    },
    {
      "x": -1,
      "y": 9,
      "z": 4,
      "name": "Rock_Basalt"
    },
    {
      "x": -1,
      "y": 10,
      "z": 4,
      "name": "Rock_Basalt"
    },
    {
      "x": -1,
      "y": 11,
      "z": 4,
      "name": "Rock_Basalt"
    },
    {
      "x": -1,
      "y": 12,
      "z": 4,
      "name": "Rock_Basalt"
    },
    {
      "x": -1,
      "y": 13,
      "z": 4,
      "name": "Rock_Basalt"
    },
    {
      "x": -1,
      "y": 14,
      "z": 4,
      "name": "Soil_Dirt_Burnt"
    },
    {
      "x": -1,
      "y": 15,
      "z": 4,
      "name": "Soil_Dirt_Burnt"
    },
    {
      "x": -1,
      "y": 4,
      "z": 5,
      "name": "Rock_Basalt"
    },
    {
      "x": -1,
      "y": 5,
      "z": 5,
      "name": "Rock_Basalt"
    },
    {
      "x": -1,
      "y": 6,
      "z": 5,
      "name": "Rock_Basalt"
    },
    {
      "x": -1,
      "y": 7,
      "z": 5,
      "name": "Rock_Basalt"
    },
    {
      "x": -1,
      "y": 8,
      "z": 5,
      "name": "Rock_Basalt"
    },
    {
      "x": -1,
      "y": 9,
      "z": 5,
      "name": "Rock_Basalt"
    },
    {
      "x": -1,
      "y": 10,
      "z": 5,
      "name": "Rock_Basalt"
    },
    {
      "x": -1,
      "y": 11,
      "z": 5,
      "name": "Rock_Basalt"
    },
    {
      "x": -1,
      "y": 12,
      "z": 5,
      "name": "Rock_Basalt"
    },
    {
      "x": -1,
      "y": 13,
      "z": 5,
      "name": "Rock_Basalt"
    },
    {
      "x": -1,
      "y": 14,
      "z": 5,
      "name": "Soil_Dirt_Burnt"
    },
    {
      "x": -1,
      "y": 15,
      "z": 5,
      "name": "Soil_Dirt_Burnt"
    },
    {
      "x": -1,
      "y": 4,
      "z": 6,
      "name": "Rock_Basalt"
    },
    {
      "x": -1,
      "y": 5,
      "z": 6,
      "name": "Rock_Basalt"
    },
    {
      "x": -1,
      "y": 6,
      "z": 6,
      "name": "Rock_Basalt"
    },
    {
      "x": -1,
      "y": 7,
      "z": 6,
      "name": "Rock_Basalt"
    },
    {
      "x": -1,
      "y": 8,
      "z": 6,
      "name": "Rock_Basalt"
    },
    {
      "x": -1,
      "y": 9,
      "z": 6,
      "name": "Rock_Basalt"
    },
    {
      "x": -1,
      "y": 10,
      "z": 6,
      "name": "Rock_Basalt"
    },
    {
      "x": -1,
      "y": 11,
      "z": 6,
      "name": "Rock_Basalt"
    },
    {
      "x": -1,
      "y": 12,
      "z": 6,
      "name": "Rock_Basalt"
    },
    {
      "x": -1,
      "y": 13,
      "z": 6,
      "name": "Rock_Basalt"
    },
    {
      "x": -1,
      "y": 14,
      "z": 6,
      "name": "Soil_Dirt_Burnt"
    },
    {
      "x": -1,
      "y": 15,
      "z": 6,
      "name": "Soil_Dirt_Burnt"
    },
    {
      "x": -1,
      "y": 5,
      "z": 7,
      "name": "Rock_Basalt"
    },
    {
      "x": -1,
      "y": 6,
      "z": 7,
      "name": "Rock_Basalt"
    },
    {
      "x": -1,
      "y": 7,
      "z": 7,
      "name": "Rock_Basalt"
    },
    {
      "x": -1,
      "y": 8,
      "z": 7,
      "name": "Rock_Basalt"
    },
    {
      "x": -1,
      "y": 9,
      "z": 7,
      "name": "Rock_Basalt"
    },
    {
      "x": -1,
      "y": 10,
      "z": 7,
      "name": "Rock_Basalt"
    },
    {
      "x": -1,
      "y": 11,
      "z": 7,
      "name": "Rock_Basalt"
    },
    {
      "x": -1,
      "y": 12,
      "z": 7,
      "name": "Rock_Basalt"
    },
    {
      "x": -1,
      "y": 13,
      "z": 7,
      "name": "Rock_Basalt"
    },
    {
      "x": -1,
      "y": 14,
      "z": 7,
      "name": "Rock_Basalt"
    },
    {
      "x": -1,
      "y": 15,
      "z": 7,
      "name": "Rock_Basalt"
    },
    {
      "x": -1,
      "y": 16,
      "z": 7,
      "name": "Plant_Moss_Block_Green_Dark"
    },
    {
      "x": -1,
      "y": 7,
      "z": 8,
      "name": "Rock_Basalt"
    },
    {
      "x": -1,
      "y": 8,
      "z": 8,
      "name": "Rock_Basalt"
    },
    {
      "x": -1,
      "y": 9,
      "z": 8,
      "name": "Rock_Basalt"
    },
    {
      "x": -1,
      "y": 10,
      "z": 8,
      "name": "Rock_Basalt"
    },
    {
      "x": -1,
      "y": 11,
      "z": 8,
      "name": "Rock_Basalt"
    },
    {
      "x": -1,
      "y": 12,
      "z": 8,
      "name": "Rock_Basalt"
    },
    {
      "x": -1,
      "y": 13,
      "z": 8,
      "name": "Rock_Basalt"
    },
    {
      "x": -1,
      "y": 14,
      "z": 8,
      "name": "Rock_Stone"
    },
    {
      "x": -1,
      "y": 15,
      "z": 8,
      "name": "Rock_Stone"
    },
    {
      "x": -1,
      "y": 16,
      "z": 8,
      "name": "Plant_Moss_Block_Green_Dark"
    },
    {
      "x": 0,
      "y": 12,
      "z": -7,
      "name": "Rock_Basalt"
    },
    {
      "x": 0,
      "y": 13,
      "z": -7,
      "name": "Rock_Basalt"
    },
    {
      "x": 0,
      "y": 14,
      "z": -7,
      "name": "Rock_Basalt"
    },
    {
      "x": 0,
      "y": 9,
      "z": -6,
      "name": "Rock_Basalt"
    },
    {
      "x": 0,
      "y": 10,
      "z": -6,
      "name": "Rock_Basalt"
    },
    {
      "x": 0,
      "y": 11,
      "z": -6,
      "name": "Rock_Basalt"
    },
    {
      "x": 0,
      "y": 12,
      "z": -6,
      "name": "Rock_Basalt"
    },
    {
      "x": 0,
      "y": 13,
      "z": -6,
      "name": "Rock_Basalt"
    },
    {
      "x": 0,
      "y": 14,
      "z": -6,
      "name": "Rock_Basalt"
    },
    {
      "x": 0,
      "y": 15,
      "z": -6,
      "name": "Rock_Basalt"
    },
    {
      "x": 0,
      "y": 7,
      "z": -5,
      "name": "Rock_Basalt"
    },
    {
      "x": 0,
      "y": 8,
      "z": -5,
      "name": "Rock_Basalt"
    },
    {
      "x": 0,
      "y": 9,
      "z": -5,
      "name": "Rock_Basalt"
    },
    {
      "x": 0,
      "y": 10,
      "z": -5,
      "name": "Rock_Basalt"
    },
    {
      "x": 0,
      "y": 11,
      "z": -5,
      "name": "Rock_Basalt"
    },
    {
      "x": 0,
      "y": 12,
      "z": -5,
      "name": "Rock_Basalt"
    },
    {
      "x": 0,
      "y": 13,
      "z": -5,
      "name": "Rock_Basalt"
    },
    {
      "x": 0,
      "y": 14,
      "z": -5,
      "name": "Rock_Basalt"
    },
    {
      "x": 0,
      "y": 15,
      "z": -5,
      "name": "Rock_Basalt"
    },
    {
      "x": 0,
      "y": 16,
      "z": -5,
      "name": "Rock_Basalt"
    },
    {
      "x": 0,
      "y": 6,
      "z": -4,
      "name": "Rock_Basalt"
    },
    {
      "x": 0,
      "y": 7,
      "z": -4,
      "name": "Rock_Basalt"
    },
    {
      "x": 0,
      "y": 8,
      "z": -4,
      "name": "Rock_Basalt"
    },
    {
      "x": 0,
      "y": 9,
      "z": -4,
      "name": "Rock_Basalt"
    },
    {
      "x": 0,
      "y": 10,
      "z": -4,
      "name": "Rock_Basalt"
    },
    {
      "x": 0,
      "y": 11,
      "z": -4,
      "name": "Rock_Basalt"
    },
    {
      "x": 0,
      "y": 12,
      "z": -4,
      "name": "Rock_Basalt"
    },
    {
      "x": 0,
      "y": 13,
      "z": -4,
      "name": "Rock_Basalt"
    },
    {
      "x": 0,
      "y": 14,
      "z": -4,
      "name": "Rock_Basalt"
    },
    {
      "x": 0,
      "y": 15,
      "z": -4,
      "name": "Rock_Basalt"
    },
    {
      "x": 0,
      "y": 16,
      "z": -4,
      "name": "Rock_Basalt"
    },
    {
      "x": 0,
      "y": 5,
      "z": -3,
      "name": "Rock_Basalt"
    },
    {
      "x": 0,
      "y": 6,
      "z": -3,
      "name": "Rock_Basalt"
    },
    {
      "x": 0,
      "y": 7,
      "z": -3,
      "name": "Rock_Basalt"
    },
    {
      "x": 0,
      "y": 8,
      "z": -3,
      "name": "Rock_Basalt"
    },
    {
      "x": 0,
      "y": 9,
      "z": -3,
      "name": "Rock_Basalt"
    },
    {
      "x": 0,
      "y": 10,
      "z": -3,
      "name": "Rock_Basalt"
    },
    {
      "x": 0,
      "y": 11,
      "z": -3,
      "name": "Rock_Basalt"
    },
    {
      "x": 0,
      "y": 12,
      "z": -3,
      "name": "Rock_Basalt"
    },
    {
      "x": 0,
      "y": 13,
      "z": -3,
      "name": "Rock_Basalt"
    },
    {
      "x": 0,
      "y": 14,
      "z": -3,
      "name": "Rock_Basalt"
    },
    {
      "x": 0,
      "y": 15,
      "z": -3,
      "name": "Rock_Basalt"
    },
    {
      "x": 0,
      "y": 16,
      "z": -3,
      "name": "Rock_Basalt"
    },
    {
      "x": 0,
      "y": 17,
      "z": -3,
      "name": "Rock_Basalt"
    },
    {
      "x": 0,
      "y": 5,
      "z": -2,
      "name": "Rock_Basalt"
    },
    {
      "x": 0,
      "y": 6,
      "z": -2,
      "name": "Rock_Basalt"
    },
    {
      "x": 0,
      "y": 7,
      "z": -2,
      "name": "Rock_Basalt"
    },
    {
      "x": 0,
      "y": 8,
      "z": -2,
      "name": "Rock_Basalt"
    },
    {
      "x": 0,
      "y": 9,
      "z": -2,
      "name": "Rock_Basalt"
    },
    {
      "x": 0,
      "y": 10,
      "z": -2,
      "name": "Rock_Basalt"
    },
    {
      "x": 0,
      "y": 11,
      "z": -2,
      "name": "Rock_Basalt"
    },
    {
      "x": 0,
      "y": 12,
      "z": -2,
      "name": "Rock_Basalt"
    },
    {
      "x": 0,
      "y": 13,
      "z": -2,
      "name": "Rock_Basalt"
    },
    {
      "x": 0,
      "y": 14,
      "z": -2,
      "name": "Rock_Basalt"
    },
    {
      "x": 0,
      "y": 15,
      "z": -2,
      "name": "Rock_Basalt"
    },
    {
      "x": 0,
      "y": 16,
      "z": -2,
      "name": "Rock_Stone"
    },
    {
      "x": 0,
      "y": 17,
      "z": -2,
      "name": "Rock_Basalt"
    },
    {
      "x": 0,
      "y": 18,
      "z": -2,
      "name": "Plant_Crop_Mushroom_Cap_Green",
      "components": {
        "Components": {
          "FarmingBlock": {}
        }
      }
    },
    {
      "x": 0,
      "y": 5,
      "z": -1,
      "name": "Rock_Basalt"
    },
    {
      "x": 0,
      "y": 6,
      "z": -1,
      "name": "Rock_Basalt"
    },
    {
      "x": 0,
      "y": 7,
      "z": -1,
      "name": "Rock_Basalt"
    },
    {
      "x": 0,
      "y": 8,
      "z": -1,
      "name": "Rock_Basalt"
    },
    {
      "x": 0,
      "y": 9,
      "z": -1,
      "name": "Rock_Basalt"
    },
    {
      "x": 0,
      "y": 10,
      "z": -1,
      "name": "Rock_Basalt"
    },
    {
      "x": 0,
      "y": 11,
      "z": -1,
      "name": "Rock_Basalt"
    },
    {
      "x": 0,
      "y": 12,
      "z": -1,
      "name": "Rock_Basalt"
    },
    {
      "x": 0,
      "y": 13,
      "z": -1,
      "name": "Rock_Basalt"
    },
    {
      "x": 0,
      "y": 14,
      "z": -1,
      "name": "Rock_Basalt"
    },
    {
      "x": 0,
      "y": 15,
      "z": -1,
      "name": "Rock_Basalt"
    },
    {
      "x": 0,
      "y": 16,
      "z": -1,
      "name": "Rock_Stone"
    },
    {
      "x": 0,
      "y": 17,
      "z": -1,
      "name": "Rock_Basalt"
    },
    {
      "x": 0,
      "y": 5,
      "z": 0,
      "name": "Rock_Basalt"
    },
    {
      "x": 0,
      "y": 6,
      "z": 0,
      "name": "Rock_Basalt"
    },
    {
      "x": 0,
      "y": 7,
      "z": 0,
      "name": "Rock_Basalt"
    },
    {
      "x": 0,
      "y": 8,
      "z": 0,
      "name": "Rock_Basalt"
    },
    {
      "x": 0,
      "y": 9,
      "z": 0,
      "name": "Rock_Basalt"
    },
    {
      "x": 0,
      "y": 10,
      "z": 0,
      "name": "Rock_Basalt"
    },
    {
      "x": 0,
      "y": 11,
      "z": 0,
      "name": "Rock_Basalt"
    },
    {
      "x": 0,
      "y": 12,
      "z": 0,
      "name": "Rock_Basalt"
    },
    {
      "x": 0,
      "y": 13,
      "z": 0,
      "name": "Rock_Basalt"
    },
    {
      "x": 0,
      "y": 14,
      "z": 0,
      "name": "Rock_Basalt"
    },
    {
      "x": 0,
      "y": 15,
      "z": 0,
      "name": "Rock_Basalt"
    },
    {
      "x": 0,
      "y": 16,
      "z": 0,
      "name": "Rock_Stone"
    },
    {
      "x": 0,
      "y": 17,
      "z": 0,
      "name": "Rock_Basalt"
    },
    {
      "x": 0,
      "y": 18,
      "z": 0,
      "name": "Rock_Basalt"
    },
    {
      "x": 0,
      "y": 3,
      "z": 1,
      "name": "Rock_Basalt"
    },
    {
      "x": 0,
      "y": 4,
      "z": 1,
      "name": "Rock_Basalt"
    },
    {
      "x": 0,
      "y": 5,
      "z": 1,
      "name": "Rock_Basalt"
    },
    {
      "x": 0,
      "y": 6,
      "z": 1,
      "name": "Rock_Basalt"
    },
    {
      "x": 0,
      "y": 7,
      "z": 1,
      "name": "Rock_Basalt"
    },
    {
      "x": 0,
      "y": 8,
      "z": 1,
      "name": "Rock_Basalt"
    },
    {
      "x": 0,
      "y": 9,
      "z": 1,
      "name": "Rock_Basalt"
    },
    {
      "x": 0,
      "y": 10,
      "z": 1,
      "name": "Rock_Basalt"
    },
    {
      "x": 0,
      "y": 11,
      "z": 1,
      "name": "Rock_Basalt"
    },
    {
      "x": 0,
      "y": 12,
      "z": 1,
      "name": "Rock_Basalt"
    },
    {
      "x": 0,
      "y": 13,
      "z": 1,
      "name": "Rock_Basalt"
    },
    {
      "x": 0,
      "y": 14,
      "z": 1,
      "name": "Rock_Basalt"
    },
    {
      "x": 0,
      "y": 15,
      "z": 1,
      "name": "Rock_Basalt"
    },
    {
      "x": 0,
      "y": 16,
      "z": 1,
      "name": "Rock_Stone"
    },
    {
      "x": 0,
      "y": 17,
      "z": 1,
      "name": "Rock_Basalt"
    },
    {
      "x": 0,
      "y": 18,
      "z": 1,
      "name": "Rock_Basalt"
    },
    {
      "x": 0,
      "y": 3,
      "z": 2,
      "name": "Rock_Basalt"
    },
    {
      "x": 0,
      "y": 4,
      "z": 2,
      "name": "Rock_Basalt"
    },
    {
      "x": 0,
      "y": 5,
      "z": 2,
      "name": "Rock_Basalt"
    },
    {
      "x": 0,
      "y": 6,
      "z": 2,
      "name": "Rock_Basalt"
    },
    {
      "x": 0,
      "y": 7,
      "z": 2,
      "name": "Rock_Basalt"
    },
    {
      "x": 0,
      "y": 8,
      "z": 2,
      "name": "Rock_Basalt"
    },
    {
      "x": 0,
      "y": 9,
      "z": 2,
      "name": "Rock_Basalt"
    },
    {
      "x": 0,
      "y": 10,
      "z": 2,
      "name": "Rock_Basalt"
    },
    {
      "x": 0,
      "y": 11,
      "z": 2,
      "name": "Rock_Basalt"
    },
    {
      "x": 0,
      "y": 12,
      "z": 2,
      "name": "Rock_Basalt"
    },
    {
      "x": 0,
      "y": 13,
      "z": 2,
      "name": "Rock_Basalt"
    },
    {
      "x": 0,
      "y": 14,
      "z": 2,
      "name": "Rock_Basalt"
    },
    {
      "x": 0,
      "y": 15,
      "z": 2,
      "name": "Soil_Dirt_Burnt"
    },
    {
      "x": 0,
      "y": 16,
      "z": 2,
      "name": "Rock_Stone"
    },
    {
      "x": 0,
      "y": 17,
      "z": 2,
      "name": "Rock_Basalt"
    },
    {
      "x": 0,
      "y": 4,
      "z": 3,
      "name": "Rock_Basalt"
    },
    {
      "x": 0,
      "y": 5,
      "z": 3,
      "name": "Rock_Basalt"
    },
    {
      "x": 0,
      "y": 6,
      "z": 3,
      "name": "Rock_Basalt"
    },
    {
      "x": 0,
      "y": 7,
      "z": 3,
      "name": "Rock_Basalt"
    },
    {
      "x": 0,
      "y": 8,
      "z": 3,
      "name": "Rock_Basalt"
    },
    {
      "x": 0,
      "y": 9,
      "z": 3,
      "name": "Rock_Basalt"
    },
    {
      "x": 0,
      "y": 10,
      "z": 3,
      "name": "Rock_Basalt"
    },
    {
      "x": 0,
      "y": 11,
      "z": 3,
      "name": "Rock_Basalt"
    },
    {
      "x": 0,
      "y": 12,
      "z": 3,
      "name": "Rock_Basalt"
    },
    {
      "x": 0,
      "y": 13,
      "z": 3,
      "name": "Rock_Basalt"
    },
    {
      "x": 0,
      "y": 14,
      "z": 3,
      "name": "Soil_Dirt_Burnt"
    },
    {
      "x": 0,
      "y": 15,
      "z": 3,
      "name": "Soil_Dirt_Burnt"
    },
    {
      "x": 0,
      "y": 4,
      "z": 4,
      "name": "Rock_Basalt"
    },
    {
      "x": 0,
      "y": 5,
      "z": 4,
      "name": "Rock_Basalt"
    },
    {
      "x": 0,
      "y": 6,
      "z": 4,
      "name": "Rock_Basalt"
    },
    {
      "x": 0,
      "y": 7,
      "z": 4,
      "name": "Rock_Basalt"
    },
    {
      "x": 0,
      "y": 8,
      "z": 4,
      "name": "Rock_Basalt"
    },
    {
      "x": 0,
      "y": 9,
      "z": 4,
      "name": "Rock_Basalt"
    },
    {
      "x": 0,
      "y": 10,
      "z": 4,
      "name": "Rock_Basalt"
    },
    {
      "x": 0,
      "y": 11,
      "z": 4,
      "name": "Rock_Basalt"
    },
    {
      "x": 0,
      "y": 12,
      "z": 4,
      "name": "Rock_Basalt"
    },
    {
      "x": 0,
      "y": 13,
      "z": 4,
      "name": "Rock_Basalt"
    },
    {
      "x": 0,
      "y": 14,
      "z": 4,
      "name": "Rock_Basalt"
    },
    {
      "x": 0,
      "y": 15,
      "z": 4,
      "name": "Soil_Dirt_Burnt"
    },
    {
      "x": 0,
      "y": 4,
      "z": 5,
      "name": "Rock_Basalt"
    },
    {
      "x": 0,
      "y": 5,
      "z": 5,
      "name": "Rock_Basalt"
    },
    {
      "x": 0,
      "y": 6,
      "z": 5,
      "name": "Rock_Basalt"
    },
    {
      "x": 0,
      "y": 7,
      "z": 5,
      "name": "Rock_Basalt"
    },
    {
      "x": 0,
      "y": 8,
      "z": 5,
      "name": "Rock_Basalt"
    },
    {
      "x": 0,
      "y": 9,
      "z": 5,
      "name": "Rock_Basalt"
    },
    {
      "x": 0,
      "y": 10,
      "z": 5,
      "name": "Rock_Basalt"
    },
    {
      "x": 0,
      "y": 11,
      "z": 5,
      "name": "Rock_Basalt"
    },
    {
      "x": 0,
      "y": 12,
      "z": 5,
      "name": "Rock_Basalt"
    },
    {
      "x": 0,
      "y": 13,
      "z": 5,
      "name": "Rock_Basalt"
    },
    {
      "x": 0,
      "y": 14,
      "z": 5,
      "name": "Rock_Basalt"
    },
    {
      "x": 0,
      "y": 15,
      "z": 5,
      "name": "Soil_Dirt_Burnt"
    },
    {
      "x": 0,
      "y": 4,
      "z": 6,
      "name": "Rock_Basalt"
    },
    {
      "x": 0,
      "y": 5,
      "z": 6,
      "name": "Rock_Basalt"
    },
    {
      "x": 0,
      "y": 6,
      "z": 6,
      "name": "Rock_Basalt"
    },
    {
      "x": 0,
      "y": 7,
      "z": 6,
      "name": "Rock_Basalt"
    },
    {
      "x": 0,
      "y": 8,
      "z": 6,
      "name": "Rock_Basalt"
    },
    {
      "x": 0,
      "y": 9,
      "z": 6,
      "name": "Rock_Basalt"
    },
    {
      "x": 0,
      "y": 10,
      "z": 6,
      "name": "Rock_Basalt"
    },
    {
      "x": 0,
      "y": 11,
      "z": 6,
      "name": "Rock_Basalt"
    },
    {
      "x": 0,
      "y": 12,
      "z": 6,
      "name": "Rock_Basalt"
    },
    {
      "x": 0,
      "y": 13,
      "z": 6,
      "name": "Rock_Basalt"
    },
    {
      "x": 0,
      "y": 14,
      "z": 6,
      "name": "Rock_Basalt"
    },
    {
      "x": 0,
      "y": 15,
      "z": 6,
      "name": "Soil_Dirt_Burnt"
    },
    {
      "x": 0,
      "y": 5,
      "z": 7,
      "name": "Rock_Basalt"
    },
    {
      "x": 0,
      "y": 6,
      "z": 7,
      "name": "Rock_Basalt"
    },
    {
      "x": 0,
      "y": 7,
      "z": 7,
      "name": "Rock_Basalt"
    },
    {
      "x": 0,
      "y": 8,
      "z": 7,
      "name": "Rock_Basalt"
    },
    {
      "x": 0,
      "y": 9,
      "z": 7,
      "name": "Rock_Basalt"
    },
    {
      "x": 0,
      "y": 10,
      "z": 7,
      "name": "Rock_Basalt"
    },
    {
      "x": 0,
      "y": 11,
      "z": 7,
      "name": "Rock_Basalt"
    },
    {
      "x": 0,
      "y": 12,
      "z": 7,
      "name": "Rock_Basalt"
    },
    {
      "x": 0,
      "y": 13,
      "z": 7,
      "name": "Rock_Basalt"
    },
    {
      "x": 0,
      "y": 14,
      "z": 7,
      "name": "Rock_Basalt"
    },
    {
      "x": 0,
      "y": 15,
      "z": 7,
      "name": "Rock_Basalt"
    },
    {
      "x": 0,
      "y": 16,
      "z": 7,
      "name": "Plant_Moss_Block_Green_Dark"
    },
    {
      "x": 0,
      "y": 17,
      "z": 7,
      "name": "Plant_Moss_Block_Green_Dark"
    },
    {
      "x": 0,
      "y": 6,
      "z": 8,
      "name": "Rock_Basalt"
    },
    {
      "x": 0,
      "y": 7,
      "z": 8,
      "name": "Rock_Basalt"
    },
    {
      "x": 0,
      "y": 8,
      "z": 8,
      "name": "Rock_Basalt"
    },
    {
      "x": 0,
      "y": 9,
      "z": 8,
      "name": "Rock_Basalt"
    },
    {
      "x": 0,
      "y": 10,
      "z": 8,
      "name": "Rock_Basalt"
    },
    {
      "x": 0,
      "y": 11,
      "z": 8,
      "name": "Rock_Basalt"
    },
    {
      "x": 0,
      "y": 12,
      "z": 8,
      "name": "Rock_Basalt"
    },
    {
      "x": 0,
      "y": 13,
      "z": 8,
      "name": "Rock_Basalt"
    },
    {
      "x": 0,
      "y": 14,
      "z": 8,
      "name": "Rock_Basalt"
    },
    {
      "x": 0,
      "y": 15,
      "z": 8,
      "name": "Rock_Basalt"
    },
    {
      "x": 0,
      "y": 16,
      "z": 8,
      "name": "Plant_Moss_Block_Green_Dark"
    },
    {
      "x": 0,
      "y": 17,
      "z": 8,
      "name": "Plant_Crop_Mushroom_Shelve_Green"
    },
    {
      "x": 0,
      "y": 8,
      "z": 9,
      "name": "Rock_Basalt"
    },
    {
      "x": 0,
      "y": 9,
      "z": 9,
      "name": "Rock_Basalt"
    },
    {
      "x": 0,
      "y": 10,
      "z": 9,
      "name": "Rock_Basalt"
    },
    {
      "x": 0,
      "y": 11,
      "z": 9,
      "name": "Rock_Basalt"
    },
    {
      "x": 0,
      "y": 12,
      "z": 9,
      "name": "Rock_Basalt"
    },
    {
      "x": 0,
      "y": 13,
      "z": 9,
      "name": "Rock_Basalt"
    },
    {
      "x": 0,
      "y": 14,
      "z": 9,
      "name": "Rock_Stone"
    },
    {
      "x": 0,
      "y": 15,
      "z": 9,
      "name": "Rock_Stone"
    },
    {
      "x": 0,
      "y": 16,
      "z": 9,
      "name": "Plant_Moss_Block_Green_Dark"
    },
    {
      "x": 1,
      "y": 12,
      "z": -8,
      "name": "Rock_Basalt"
    },
    {
      "x": 1,
      "y": 13,
      "z": -8,
      "name": "Rock_Basalt"
    },
    {
      "x": 1,
      "y": 14,
      "z": -8,
      "name": "Rock_Basalt"
    },
    {
      "x": 1,
      "y": 9,
      "z": -7,
      "name": "Rock_Basalt"
    },
    {
      "x": 1,
      "y": 10,
      "z": -7,
      "name": "Rock_Basalt"
    },
    {
      "x": 1,
      "y": 11,
      "z": -7,
      "name": "Rock_Basalt"
    },
    {
      "x": 1,
      "y": 12,
      "z": -7,
      "name": "Rock_Basalt"
    },
    {
      "x": 1,
      "y": 13,
      "z": -7,
      "name": "Rock_Basalt"
    },
    {
      "x": 1,
      "y": 14,
      "z": -7,
      "name": "Rock_Basalt"
    },
    {
      "x": 1,
      "y": 15,
      "z": -7,
      "name": "Rock_Basalt"
    },
    {
      "x": 1,
      "y": 16,
      "z": -7,
      "name": "Rock_Basalt"
    },
    {
      "x": 1,
      "y": 7,
      "z": -6,
      "name": "Rock_Basalt"
    },
    {
      "x": 1,
      "y": 8,
      "z": -6,
      "name": "Rock_Basalt"
    },
    {
      "x": 1,
      "y": 9,
      "z": -6,
      "name": "Rock_Basalt"
    },
    {
      "x": 1,
      "y": 10,
      "z": -6,
      "name": "Rock_Basalt"
    },
    {
      "x": 1,
      "y": 11,
      "z": -6,
      "name": "Rock_Basalt"
    },
    {
      "x": 1,
      "y": 12,
      "z": -6,
      "name": "Rock_Basalt"
    },
    {
      "x": 1,
      "y": 13,
      "z": -6,
      "name": "Rock_Basalt"
    },
    {
      "x": 1,
      "y": 14,
      "z": -6,
      "name": "Rock_Basalt"
    },
    {
      "x": 1,
      "y": 15,
      "z": -6,
      "name": "Rock_Basalt"
    },
    {
      "x": 1,
      "y": 16,
      "z": -6,
      "name": "Rock_Basalt"
    },
    {
      "x": 1,
      "y": 17,
      "z": -6,
      "name": "Plant_Moss_Block_Green_Dark"
    },
    {
      "x": 1,
      "y": 6,
      "z": -5,
      "name": "Rock_Basalt"
    },
    {
      "x": 1,
      "y": 7,
      "z": -5,
      "name": "Rock_Basalt"
    },
    {
      "x": 1,
      "y": 8,
      "z": -5,
      "name": "Rock_Basalt"
    },
    {
      "x": 1,
      "y": 9,
      "z": -5,
      "name": "Rock_Basalt"
    },
    {
      "x": 1,
      "y": 10,
      "z": -5,
      "name": "Rock_Basalt"
    },
    {
      "x": 1,
      "y": 11,
      "z": -5,
      "name": "Rock_Basalt"
    },
    {
      "x": 1,
      "y": 12,
      "z": -5,
      "name": "Rock_Basalt"
    },
    {
      "x": 1,
      "y": 13,
      "z": -5,
      "name": "Rock_Basalt"
    },
    {
      "x": 1,
      "y": 14,
      "z": -5,
      "name": "Rock_Basalt"
    },
    {
      "x": 1,
      "y": 15,
      "z": -5,
      "name": "Rock_Basalt"
    },
    {
      "x": 1,
      "y": 16,
      "z": -5,
      "name": "Rock_Basalt"
    },
    {
      "x": 1,
      "y": 17,
      "z": -5,
      "name": "Plant_Moss_Block_Green_Dark"
    },
    {
      "x": 1,
      "y": 5,
      "z": -4,
      "name": "Rock_Basalt"
    },
    {
      "x": 1,
      "y": 6,
      "z": -4,
      "name": "Rock_Basalt"
    },
    {
      "x": 1,
      "y": 7,
      "z": -4,
      "name": "Rock_Basalt"
    },
    {
      "x": 1,
      "y": 8,
      "z": -4,
      "name": "Rock_Basalt"
    },
    {
      "x": 1,
      "y": 9,
      "z": -4,
      "name": "Rock_Basalt"
    },
    {
      "x": 1,
      "y": 10,
      "z": -4,
      "name": "Rock_Basalt"
    },
    {
      "x": 1,
      "y": 11,
      "z": -4,
      "name": "Rock_Basalt"
    },
    {
      "x": 1,
      "y": 12,
      "z": -4,
      "name": "Rock_Basalt"
    },
    {
      "x": 1,
      "y": 13,
      "z": -4,
      "name": "Rock_Basalt"
    },
    {
      "x": 1,
      "y": 14,
      "z": -4,
      "name": "Rock_Basalt"
    },
    {
      "x": 1,
      "y": 15,
      "z": -4,
      "name": "Rock_Basalt"
    },
    {
      "x": 1,
      "y": 16,
      "z": -4,
      "name": "Rock_Basalt"
    },
    {
      "x": 1,
      "y": 17,
      "z": -4,
      "name": "Rock_Basalt"
    },
    {
      "x": 1,
      "y": 5,
      "z": -3,
      "name": "Rock_Basalt"
    },
    {
      "x": 1,
      "y": 6,
      "z": -3,
      "name": "Rock_Basalt"
    },
    {
      "x": 1,
      "y": 7,
      "z": -3,
      "name": "Rock_Basalt"
    },
    {
      "x": 1,
      "y": 8,
      "z": -3,
      "name": "Rock_Basalt"
    },
    {
      "x": 1,
      "y": 9,
      "z": -3,
      "name": "Rock_Basalt"
    },
    {
      "x": 1,
      "y": 10,
      "z": -3,
      "name": "Rock_Basalt"
    },
    {
      "x": 1,
      "y": 11,
      "z": -3,
      "name": "Rock_Basalt"
    },
    {
      "x": 1,
      "y": 12,
      "z": -3,
      "name": "Rock_Basalt"
    },
    {
      "x": 1,
      "y": 13,
      "z": -3,
      "name": "Rock_Basalt"
    },
    {
      "x": 1,
      "y": 14,
      "z": -3,
      "name": "Rock_Basalt"
    },
    {
      "x": 1,
      "y": 15,
      "z": -3,
      "name": "Rock_Basalt"
    },
    {
      "x": 1,
      "y": 16,
      "z": -3,
      "name": "Rock_Basalt"
    },
    {
      "x": 1,
      "y": 17,
      "z": -3,
      "name": "Rock_Basalt"
    },
    {
      "x": 1,
      "y": 5,
      "z": -2,
      "name": "Rock_Basalt"
    },
    {
      "x": 1,
      "y": 6,
      "z": -2,
      "name": "Rock_Basalt"
    },
    {
      "x": 1,
      "y": 7,
      "z": -2,
      "name": "Rock_Basalt"
    },
    {
      "x": 1,
      "y": 8,
      "z": -2,
      "name": "Rock_Basalt"
    },
    {
      "x": 1,
      "y": 9,
      "z": -2,
      "name": "Rock_Basalt"
    },
    {
      "x": 1,
      "y": 10,
      "z": -2,
      "name": "Rock_Basalt"
    },
    {
      "x": 1,
      "y": 11,
      "z": -2,
      "name": "Rock_Basalt"
    },
    {
      "x": 1,
      "y": 12,
      "z": -2,
      "name": "Rock_Basalt"
    },
    {
      "x": 1,
      "y": 13,
      "z": -2,
      "name": "Rock_Basalt"
    },
    {
      "x": 1,
      "y": 14,
      "z": -2,
      "name": "Rock_Basalt"
    },
    {
      "x": 1,
      "y": 15,
      "z": -2,
      "name": "Rock_Basalt"
    },
    {
      "x": 1,
      "y": 16,
      "z": -2,
      "name": "Rock_Basalt"
    },
    {
      "x": 1,
      "y": 17,
      "z": -2,
      "name": "Rock_Basalt"
    },
    {
      "x": 1,
      "y": 5,
      "z": -1,
      "name": "Rock_Basalt"
    },
    {
      "x": 1,
      "y": 6,
      "z": -1,
      "name": "Rock_Basalt"
    },
    {
      "x": 1,
      "y": 7,
      "z": -1,
      "name": "Rock_Basalt"
    },
    {
      "x": 1,
      "y": 8,
      "z": -1,
      "name": "Rock_Basalt"
    },
    {
      "x": 1,
      "y": 9,
      "z": -1,
      "name": "Rock_Basalt"
    },
    {
      "x": 1,
      "y": 10,
      "z": -1,
      "name": "Rock_Basalt"
    },
    {
      "x": 1,
      "y": 11,
      "z": -1,
      "name": "Rock_Basalt"
    },
    {
      "x": 1,
      "y": 12,
      "z": -1,
      "name": "Rock_Basalt"
    },
    {
      "x": 1,
      "y": 13,
      "z": -1,
      "name": "Rock_Basalt"
    },
    {
      "x": 1,
      "y": 14,
      "z": -1,
      "name": "Rock_Basalt"
    },
    {
      "x": 1,
      "y": 15,
      "z": -1,
      "name": "Rock_Basalt"
    },
    {
      "x": 1,
      "y": 16,
      "z": -1,
      "name": "Rock_Basalt"
    },
    {
      "x": 1,
      "y": 17,
      "z": -1,
      "name": "Soil_Dirt_Burnt"
    },
    {
      "x": 1,
      "y": 18,
      "z": -1,
      "name": "Rock_Basalt"
    },
    {
      "x": 1,
      "y": 3,
      "z": 0,
      "name": "Rock_Basalt"
    },
    {
      "x": 1,
      "y": 4,
      "z": 0,
      "name": "Rock_Basalt"
    },
    {
      "x": 1,
      "y": 5,
      "z": 0,
      "name": "Rock_Basalt"
    },
    {
      "x": 1,
      "y": 6,
      "z": 0,
      "name": "Rock_Basalt"
    },
    {
      "x": 1,
      "y": 7,
      "z": 0,
      "name": "Rock_Basalt"
    },
    {
      "x": 1,
      "y": 8,
      "z": 0,
      "name": "Rock_Basalt"
    },
    {
      "x": 1,
      "y": 9,
      "z": 0,
      "name": "Rock_Basalt"
    },
    {
      "x": 1,
      "y": 10,
      "z": 0,
      "name": "Rock_Basalt"
    },
    {
      "x": 1,
      "y": 11,
      "z": 0,
      "name": "Rock_Basalt"
    },
    {
      "x": 1,
      "y": 12,
      "z": 0,
      "name": "Rock_Basalt"
    },
    {
      "x": 1,
      "y": 13,
      "z": 0,
      "name": "Rock_Basalt"
    },
    {
      "x": 1,
      "y": 14,
      "z": 0,
      "name": "Rock_Basalt"
    },
    {
      "x": 1,
      "y": 15,
      "z": 0,
      "name": "Rock_Basalt"
    },
    {
      "x": 1,
      "y": 16,
      "z": 0,
      "name": "Rock_Basalt"
    },
    {
      "x": 1,
      "y": 17,
      "z": 0,
      "name": "Rock_Basalt"
    },
    {
      "x": 1,
      "y": 18,
      "z": 0,
      "name": "Rock_Basalt"
    },
    {
      "x": 1,
      "y": 19,
      "z": 0,
      "name": "Rock_Basalt"
    },
    {
      "x": 1,
      "y": 3,
      "z": 1,
      "name": "Rock_Basalt"
    },
    {
      "x": 1,
      "y": 4,
      "z": 1,
      "name": "Rock_Basalt"
    },
    {
      "x": 1,
      "y": 5,
      "z": 1,
      "name": "Rock_Basalt"
    },
    {
      "x": 1,
      "y": 6,
      "z": 1,
      "name": "Rock_Basalt"
    },
    {
      "x": 1,
      "y": 7,
      "z": 1,
      "name": "Rock_Basalt"
    },
    {
      "x": 1,
      "y": 8,
      "z": 1,
      "name": "Rock_Basalt"
    },
    {
      "x": 1,
      "y": 9,
      "z": 1,
      "name": "Rock_Basalt"
    },
    {
      "x": 1,
      "y": 10,
      "z": 1,
      "name": "Rock_Basalt"
    },
    {
      "x": 1,
      "y": 11,
      "z": 1,
      "name": "Rock_Basalt"
    },
    {
      "x": 1,
      "y": 12,
      "z": 1,
      "name": "Rock_Basalt"
    },
    {
      "x": 1,
      "y": 13,
      "z": 1,
      "name": "Rock_Basalt"
    },
    {
      "x": 1,
      "y": 14,
      "z": 1,
      "name": "Rock_Basalt"
    },
    {
      "x": 1,
      "y": 15,
      "z": 1,
      "name": "Rock_Basalt"
    },
    {
      "x": 1,
      "y": 16,
      "z": 1,
      "name": "Rock_Basalt"
    },
    {
      "x": 1,
      "y": 17,
      "z": 1,
      "name": "Rock_Basalt"
    },
    {
      "x": 1,
      "y": 18,
      "z": 1,
      "name": "Rock_Basalt"
    },
    {
      "x": 1,
      "y": 19,
      "z": 1,
      "name": "Rock_Basalt"
    },
    {
      "x": 1,
      "y": 3,
      "z": 2,
      "name": "Rock_Basalt"
    },
    {
      "x": 1,
      "y": 4,
      "z": 2,
      "name": "Rock_Basalt"
    },
    {
      "x": 1,
      "y": 5,
      "z": 2,
      "name": "Rock_Basalt"
    },
    {
      "x": 1,
      "y": 6,
      "z": 2,
      "name": "Rock_Basalt"
    },
    {
      "x": 1,
      "y": 7,
      "z": 2,
      "name": "Rock_Basalt"
    },
    {
      "x": 1,
      "y": 8,
      "z": 2,
      "name": "Rock_Basalt"
    },
    {
      "x": 1,
      "y": 9,
      "z": 2,
      "name": "Rock_Basalt"
    },
    {
      "x": 1,
      "y": 10,
      "z": 2,
      "name": "Rock_Basalt"
    },
    {
      "x": 1,
      "y": 11,
      "z": 2,
      "name": "Rock_Basalt"
    },
    {
      "x": 1,
      "y": 12,
      "z": 2,
      "name": "Rock_Basalt"
    },
    {
      "x": 1,
      "y": 13,
      "z": 2,
      "name": "Rock_Basalt"
    },
    {
      "x": 1,
      "y": 14,
      "z": 2,
      "name": "Rock_Basalt"
    },
    {
      "x": 1,
      "y": 15,
      "z": 2,
      "name": "Rock_Basalt"
    },
    {
      "x": 1,
      "y": 16,
      "z": 2,
      "name": "Rock_Basalt"
    },
    {
      "x": 1,
      "y": 17,
      "z": 2,
      "name": "Rock_Basalt"
    },
    {
      "x": 1,
      "y": 18,
      "z": 2,
      "name": "Rock_Basalt"
    },
    {
      "x": 1,
      "y": 3,
      "z": 3,
      "name": "Rock_Basalt"
    },
    {
      "x": 1,
      "y": 4,
      "z": 3,
      "name": "Rock_Basalt"
    },
    {
      "x": 1,
      "y": 5,
      "z": 3,
      "name": "Rock_Basalt"
    },
    {
      "x": 1,
      "y": 6,
      "z": 3,
      "name": "Rock_Basalt"
    },
    {
      "x": 1,
      "y": 7,
      "z": 3,
      "name": "Rock_Basalt"
    },
    {
      "x": 1,
      "y": 8,
      "z": 3,
      "name": "Rock_Basalt"
    },
    {
      "x": 1,
      "y": 9,
      "z": 3,
      "name": "Rock_Basalt"
    },
    {
      "x": 1,
      "y": 10,
      "z": 3,
      "name": "Rock_Basalt"
    },
    {
      "x": 1,
      "y": 11,
      "z": 3,
      "name": "Rock_Basalt"
    },
    {
      "x": 1,
      "y": 12,
      "z": 3,
      "name": "Rock_Basalt"
    },
    {
      "x": 1,
      "y": 13,
      "z": 3,
      "name": "Rock_Basalt"
    },
    {
      "x": 1,
      "y": 14,
      "z": 3,
      "name": "Rock_Basalt"
    },
    {
      "x": 1,
      "y": 15,
      "z": 3,
      "name": "Rock_Basalt"
    },
    {
      "x": 1,
      "y": 16,
      "z": 3,
      "name": "Rock_Basalt"
    },
    {
      "x": 1,
      "y": 17,
      "z": 3,
      "name": "Rock_Basalt"
    },
    {
      "x": 1,
      "y": 3,
      "z": 4,
      "name": "Rock_Basalt"
    },
    {
      "x": 1,
      "y": 4,
      "z": 4,
      "name": "Rock_Basalt"
    },
    {
      "x": 1,
      "y": 5,
      "z": 4,
      "name": "Rock_Basalt"
    },
    {
      "x": 1,
      "y": 6,
      "z": 4,
      "name": "Rock_Basalt"
    },
    {
      "x": 1,
      "y": 7,
      "z": 4,
      "name": "Rock_Basalt"
    },
    {
      "x": 1,
      "y": 8,
      "z": 4,
      "name": "Rock_Basalt"
    },
    {
      "x": 1,
      "y": 9,
      "z": 4,
      "name": "Rock_Basalt"
    },
    {
      "x": 1,
      "y": 10,
      "z": 4,
      "name": "Rock_Basalt"
    },
    {
      "x": 1,
      "y": 11,
      "z": 4,
      "name": "Rock_Basalt"
    },
    {
      "x": 1,
      "y": 12,
      "z": 4,
      "name": "Rock_Basalt"
    },
    {
      "x": 1,
      "y": 13,
      "z": 4,
      "name": "Rock_Basalt"
    },
    {
      "x": 1,
      "y": 14,
      "z": 4,
      "name": "Rock_Basalt"
    },
    {
      "x": 1,
      "y": 15,
      "z": 4,
      "name": "Rock_Basalt"
    },
    {
      "x": 1,
      "y": 16,
      "z": 4,
      "name": "Rock_Basalt"
    },
    {
      "x": 1,
      "y": 17,
      "z": 4,
      "name": "Rock_Basalt"
    },
    {
      "x": 1,
      "y": 4,
      "z": 5,
      "name": "Rock_Basalt"
    },
    {
      "x": 1,
      "y": 5,
      "z": 5,
      "name": "Rock_Basalt"
    },
    {
      "x": 1,
      "y": 6,
      "z": 5,
      "name": "Rock_Basalt"
    },
    {
      "x": 1,
      "y": 7,
      "z": 5,
      "name": "Rock_Basalt"
    },
    {
      "x": 1,
      "y": 8,
      "z": 5,
      "name": "Rock_Basalt"
    },
    {
      "x": 1,
      "y": 9,
      "z": 5,
      "name": "Rock_Basalt"
    },
    {
      "x": 1,
      "y": 10,
      "z": 5,
      "name": "Rock_Basalt"
    },
    {
      "x": 1,
      "y": 11,
      "z": 5,
      "name": "Rock_Basalt"
    },
    {
      "x": 1,
      "y": 12,
      "z": 5,
      "name": "Rock_Basalt"
    },
    {
      "x": 1,
      "y": 13,
      "z": 5,
      "name": "Rock_Basalt"
    },
    {
      "x": 1,
      "y": 14,
      "z": 5,
      "name": "Rock_Basalt"
    },
    {
      "x": 1,
      "y": 15,
      "z": 5,
      "name": "Rock_Basalt"
    },
    {
      "x": 1,
      "y": 16,
      "z": 5,
      "name": "Soil_Dirt_Burnt"
    },
    {
      "x": 1,
      "y": 4,
      "z": 6,
      "name": "Rock_Basalt"
    },
    {
      "x": 1,
      "y": 5,
      "z": 6,
      "name": "Rock_Basalt"
    },
    {
      "x": 1,
      "y": 6,
      "z": 6,
      "name": "Rock_Basalt"
    },
    {
      "x": 1,
      "y": 7,
      "z": 6,
      "name": "Rock_Basalt"
    },
    {
      "x": 1,
      "y": 8,
      "z": 6,
      "name": "Rock_Basalt"
    },
    {
      "x": 1,
      "y": 9,
      "z": 6,
      "name": "Rock_Basalt"
    },
    {
      "x": 1,
      "y": 10,
      "z": 6,
      "name": "Rock_Basalt"
    },
    {
      "x": 1,
      "y": 11,
      "z": 6,
      "name": "Rock_Basalt"
    },
    {
      "x": 1,
      "y": 12,
      "z": 6,
      "name": "Rock_Basalt"
    },
    {
      "x": 1,
      "y": 13,
      "z": 6,
      "name": "Rock_Basalt"
    },
    {
      "x": 1,
      "y": 14,
      "z": 6,
      "name": "Rock_Basalt"
    },
    {
      "x": 1,
      "y": 15,
      "z": 6,
      "name": "Rock_Basalt"
    },
    {
      "x": 1,
      "y": 16,
      "z": 6,
      "name": "Soil_Dirt_Burnt"
    },
    {
      "x": 1,
      "y": 5,
      "z": 7,
      "name": "Rock_Basalt"
    },
    {
      "x": 1,
      "y": 6,
      "z": 7,
      "name": "Rock_Basalt"
    },
    {
      "x": 1,
      "y": 7,
      "z": 7,
      "name": "Rock_Basalt"
    },
    {
      "x": 1,
      "y": 8,
      "z": 7,
      "name": "Rock_Basalt"
    },
    {
      "x": 1,
      "y": 9,
      "z": 7,
      "name": "Rock_Basalt"
    },
    {
      "x": 1,
      "y": 10,
      "z": 7,
      "name": "Rock_Basalt"
    },
    {
      "x": 1,
      "y": 11,
      "z": 7,
      "name": "Rock_Basalt"
    },
    {
      "x": 1,
      "y": 12,
      "z": 7,
      "name": "Rock_Basalt"
    },
    {
      "x": 1,
      "y": 13,
      "z": 7,
      "name": "Rock_Basalt"
    },
    {
      "x": 1,
      "y": 14,
      "z": 7,
      "name": "Rock_Basalt"
    },
    {
      "x": 1,
      "y": 15,
      "z": 7,
      "name": "Rock_Basalt"
    },
    {
      "x": 1,
      "y": 16,
      "z": 7,
      "name": "Rock_Basalt"
    },
    {
      "x": 1,
      "y": 17,
      "z": 7,
      "name": "Plant_Moss_Block_Green_Dark"
    },
    {
      "x": 1,
      "y": 5,
      "z": 8,
      "name": "Rock_Basalt"
    },
    {
      "x": 1,
      "y": 6,
      "z": 8,
      "name": "Rock_Basalt"
    },
    {
      "x": 1,
      "y": 7,
      "z": 8,
      "name": "Rock_Basalt"
    },
    {
      "x": 1,
      "y": 8,
      "z": 8,
      "name": "Rock_Basalt"
    },
    {
      "x": 1,
      "y": 9,
      "z": 8,
      "name": "Rock_Basalt"
    },
    {
      "x": 1,
      "y": 10,
      "z": 8,
      "name": "Rock_Basalt"
    },
    {
      "x": 1,
      "y": 11,
      "z": 8,
      "name": "Rock_Basalt"
    },
    {
      "x": 1,
      "y": 12,
      "z": 8,
      "name": "Rock_Basalt"
    },
    {
      "x": 1,
      "y": 13,
      "z": 8,
      "name": "Rock_Basalt"
    },
    {
      "x": 1,
      "y": 14,
      "z": 8,
      "name": "Rock_Basalt"
    },
    {
      "x": 1,
      "y": 15,
      "z": 8,
      "name": "Rock_Basalt"
    },
    {
      "x": 1,
      "y": 16,
      "z": 8,
      "name": "Rock_Basalt"
    },
    {
      "x": 1,
      "y": 17,
      "z": 8,
      "name": "Plant_Moss_Block_Green_Dark"
    },
    {
      "x": 1,
      "y": 7,
      "z": 9,
      "name": "Rock_Basalt"
    },
    {
      "x": 1,
      "y": 8,
      "z": 9,
      "name": "Rock_Basalt"
    },
    {
      "x": 1,
      "y": 9,
      "z": 9,
      "name": "Rock_Basalt"
    },
    {
      "x": 1,
      "y": 10,
      "z": 9,
      "name": "Rock_Basalt"
    },
    {
      "x": 1,
      "y": 11,
      "z": 9,
      "name": "Rock_Basalt"
    },
    {
      "x": 1,
      "y": 12,
      "z": 9,
      "name": "Rock_Basalt"
    },
    {
      "x": 1,
      "y": 13,
      "z": 9,
      "name": "Rock_Basalt"
    },
    {
      "x": 1,
      "y": 14,
      "z": 9,
      "name": "Rock_Stone"
    },
    {
      "x": 1,
      "y": 15,
      "z": 9,
      "name": "Rock_Stone"
    },
    {
      "x": 1,
      "y": 16,
      "z": 9,
      "name": "Plant_Moss_Block_Green_Dark"
    },
    {
      "x": 1,
      "y": 17,
      "z": 9,
      "name": "Plant_Moss_Block_Green_Dark"
    },
    {
      "x": 2,
      "y": 11,
      "z": -9,
      "name": "Rock_Basalt"
    },
    {
      "x": 2,
      "y": 12,
      "z": -9,
      "name": "Rock_Basalt"
    },
    {
      "x": 2,
      "y": 13,
      "z": -9,
      "name": "Rock_Basalt"
    },
    {
      "x": 2,
      "y": 9,
      "z": -8,
      "name": "Rock_Basalt"
    },
    {
      "x": 2,
      "y": 10,
      "z": -8,
