{
  "version": 8,
  "blockIdVersion": 8,
  "anchorX": -2,
  "anchorY": 14,
  "anchorZ": -1,
  "blocks": [
    {
      "x": -10,
      "y": 16,
      "z": -4,
      "name": "Rock_Calcite"
    },
    {
      "x": -10,
      "y": 17,
      "z": -4,
      "name": "Rock_Calcite"
    },
    {
      "x": -10,
      "y": 18,
      "z": -4,
      "name": "Rock_Calcite"
    },
    {
      "x": -10,
      "y": 19,
      "z": -4,
      "name": "Rock_Calcite"
    },
    {
      "x": -10,
      "y": 20,
      "z": -4,
      "name": "Rock_Calcite"
    },
    {
      "x": -10,
      "y": 14,
      "z": -3,
      "name": "Rock_Calcite"
    },
    {
      "x": -10,
      "y": 15,
      "z": -3,
      "name": "Rock_Calcite"
    },
    {
      "x": -10,
      "y": 16,
      "z": -3,
      "name": "Rock_Calcite"
    },
    {
      "x": -10,
      "y": 17,
      "z": -3,
      "name": "Rock_Calcite"
    },
    {
      "x": -10,
      "y": 18,
      "z": -3,
      "name": "Rock_Calcite"
    },
    {
      "x": -10,
      "y": 19,
      "z": -3,
      "name": "Rock_Calcite"
    },
    {
      "x": -10,
      "y": 20,
      "z": -3,
      "name": "Rock_Calcite"
    },
    {
      "x": -10,
      "y": 16,
      "z": -2,
      "name": "Rock_Calcite"
    },
    {
      "x": -10,
      "y": 17,
      "z": -2,
      "name": "Rock_Calcite"
    },
    {
      "x": -10,
      "y": 18,
      "z": -2,
      "name": "Rock_Calcite"
    },
    {
      "x": -10,
      "y": 19,
      "z": -2,
      "name": "Rock_Calcite"
    },
    {
      "x": -10,
      "y": 20,
      "z": -2,
      "name": "Rock_Calcite"
    },
    {
      "x": -10,
      "y": 21,
      "z": -2,
      "name": "Rock_Calcite"
    },
    {
      "x": -10,
      "y": 15,
      "z": -1,
      "name": "Rock_Calcite"
    },
    {
      "x": -10,
      "y": 16,
      "z": -1,
      "name": "Rock_Calcite"
    },
    {
      "x": -10,
      "y": 17,
      "z": -1,
      "name": "Rock_Calcite"
    },
    {
      "x": -10,
      "y": 18,
      "z": -1,
      "name": "Rock_Calcite"
    },
    {
      "x": -10,
      "y": 19,
      "z": -1,
      "name": "Rock_Calcite"
    },
    {
      "x": -10,
      "y": 20,
      "z": -1,
      "name": "Rock_Calcite"
    },
    {
      "x": -10,
      "y": 21,
      "z": -1,
      "name": "Rock_Calcite"
    },
    {
      "x": -10,
      "y": 17,
      "z": 0,
      "name": "Rock_Calcite"
    },
    {
      "x": -10,
      "y": 18,
      "z": 0,
      "name": "Rock_Calcite"
    },
    {
      "x": -10,
      "y": 19,
      "z": 0,
      "name": "Rock_Calcite"
    },
    {
      "x": -10,
      "y": 20,
      "z": 0,
      "name": "Rock_Calcite"
    },
    {
      "x": -10,
      "y": 21,
      "z": 0,
      "name": "Rock_Calcite"
    },
    {
      "x": -10,
      "y": 51,
      "z": 3,
      "name": "Plant_Leaves_Wisteria_Wild"
    },
    {
      "x": -9,
      "y": 16,
      "z": -5,
      "name": "Rock_Calcite"
    },
    {
      "x": -9,
      "y": 17,
      "z": -5,
      "name": "Rock_Calcite"
    },
    {
      "x": -9,
      "y": 18,
      "z": -5,
      "name": "Rock_Calcite"
    },
    {
      "x": -9,
      "y": 19,
      "z": -5,
      "name": "Rock_Calcite"
    },
    {
      "x": -9,
      "y": 20,
      "z": -5,
      "name": "Rock_Calcite"
    },
    {
      "x": -9,
      "y": 13,
      "z": -4,
      "name": "Rock_Calcite"
    },
    {
      "x": -9,
      "y": 14,
      "z": -4,
      "name": "Rock_Calcite"
    },
    {
      "x": -9,
      "y": 15,
      "z": -4,
      "name": "Rock_Calcite"
    },
    {
      "x": -9,
      "y": 16,
      "z": -4,
      "name": "Rock_Calcite"
    },
    {
      "x": -9,
      "y": 17,
      "z": -4,
      "name": "Rock_Calcite"
    },
    {
      "x": -9,
      "y": 18,
      "z": -4,
      "name": "Rock_Calcite"
    },
    {
      "x": -9,
      "y": 19,
      "z": -4,
      "name": "Rock_Calcite"
    },
    {
      "x": -9,
      "y": 20,
      "z": -4,
      "name": "Rock_Calcite"
    },
    {
      "x": -9,
      "y": 21,
      "z": -4,
      "name": "Rock_Calcite"
    },
    {
      "x": -9,
      "y": 22,
      "z": -4,
      "name": "Rock_Calcite"
    },
    {
      "x": -9,
      "y": 13,
      "z": -3,
      "name": "Rock_Calcite"
    },
    {
      "x": -9,
      "y": 14,
      "z": -3,
      "name": "Rock_Calcite"
    },
    {
      "x": -9,
      "y": 15,
      "z": -3,
      "name": "Rock_Calcite"
    },
    {
      "x": -9,
      "y": 16,
      "z": -3,
      "name": "Rock_Calcite"
    },
    {
      "x": -9,
      "y": 17,
      "z": -3,
      "name": "Rock_Calcite"
    },
    {
      "x": -9,
      "y": 18,
      "z": -3,
      "name": "Rock_Calcite"
    },
    {
      "x": -9,
      "y": 19,
      "z": -3,
      "name": "Rock_Calcite"
    },
    {
      "x": -9,
      "y": 20,
      "z": -3,
      "name": "Rock_Calcite"
    },
    {
      "x": -9,
      "y": 21,
      "z": -3,
      "name": "Rock_Calcite"
    },
    {
      "x": -9,
      "y": 22,
      "z": -3,
      "name": "Rock_Calcite"
    },
    {
      "x": -9,
      "y": 23,
      "z": -3,
      "name": "Rock_Calcite"
    },
    {
      "x": -9,
      "y": 24,
      "z": -3,
      "name": "Rock_Calcite"
    },
    {
      "x": -9,
      "y": 12,
      "z": -2,
      "name": "Rock_Calcite"
    },
    {
      "x": -9,
      "y": 13,
      "z": -2,
      "name": "Rock_Calcite"
    },
    {
      "x": -9,
      "y": 14,
      "z": -2,
      "name": "Rock_Calcite"
    },
    {
      "x": -9,
      "y": 15,
      "z": -2,
      "name": "Rock_Calcite"
    },
    {
      "x": -9,
      "y": 16,
      "z": -2,
      "name": "Rock_Calcite"
    },
    {
      "x": -9,
      "y": 17,
      "z": -2,
      "name": "Rock_Calcite"
    },
    {
      "x": -9,
      "y": 18,
      "z": -2,
      "name": "Rock_Calcite"
    },
    {
      "x": -9,
      "y": 19,
      "z": -2,
      "name": "Rock_Calcite"
    },
    {
      "x": -9,
      "y": 20,
      "z": -2,
      "name": "Rock_Calcite"
    },
    {
      "x": -9,
      "y": 21,
      "z": -2,
      "name": "Rock_Calcite"
    },
    {
      "x": -9,
      "y": 22,
      "z": -2,
      "name": "Rock_Calcite"
    },
    {
      "x": -9,
      "y": 23,
      "z": -2,
      "name": "Rock_Calcite"
    },
    {
      "x": -9,
      "y": 24,
      "z": -2,
      "name": "Rock_Calcite"
    },
    {
      "x": -9,
      "y": 25,
      "z": -2,
      "name": "Rock_Calcite"
    },
    {
      "x": -9,
      "y": 26,
      "z": -2,
      "name": "Rock_Calcite"
    },
    {
      "x": -9,
      "y": 27,
      "z": -2,
      "name": "Rock_Calcite"
    },
    {
      "x": -9,
      "y": 13,
      "z": -1,
      "name": "Rock_Calcite"
    },
    {
      "x": -9,
      "y": 14,
      "z": -1,
      "name": "Rock_Calcite"
    },
    {
      "x": -9,
      "y": 15,
      "z": -1,
      "name": "Rock_Calcite"
    },
    {
      "x": -9,
      "y": 16,
      "z": -1,
      "name": "Rock_Calcite"
    },
    {
      "x": -9,
      "y": 17,
      "z": -1,
      "name": "Rock_Calcite"
    },
    {
      "x": -9,
      "y": 18,
      "z": -1,
      "name": "Rock_Calcite"
    },
    {
      "x": -9,
      "y": 19,
      "z": -1,
      "name": "Rock_Calcite"
    },
    {
      "x": -9,
      "y": 20,
      "z": -1,
      "name": "Rock_Calcite"
    },
    {
      "x": -9,
      "y": 21,
      "z": -1,
      "name": "Rock_Calcite"
    },
    {
      "x": -9,
      "y": 22,
      "z": -1,
      "name": "Rock_Calcite"
    },
    {
      "x": -9,
      "y": 23,
      "z": -1,
      "name": "Rock_Calcite"
    },
    {
      "x": -9,
      "y": 24,
      "z": -1,
      "name": "Rock_Calcite"
    },
    {
      "x": -9,
      "y": 25,
      "z": -1,
      "name": "Rock_Calcite"
    },
    {
      "x": -9,
      "y": 26,
      "z": -1,
      "name": "Rock_Calcite"
    },
    {
      "x": -9,
      "y": 27,
      "z": -1,
      "name": "Rock_Calcite"
    },
    {
      "x": -9,
      "y": 13,
      "z": 0,
      "name": "Rock_Calcite"
    },
    {
      "x": -9,
      "y": 14,
      "z": 0,
      "name": "Rock_Calcite"
    },
    {
      "x": -9,
      "y": 15,
      "z": 0,
      "name": "Rock_Calcite"
    },
    {
      "x": -9,
      "y": 16,
      "z": 0,
      "name": "Rock_Calcite"
    },
    {
      "x": -9,
      "y": 17,
      "z": 0,
      "name": "Rock_Calcite"
    },
    {
      "x": -9,
      "y": 18,
      "z": 0,
      "name": "Rock_Calcite"
    },
    {
      "x": -9,
      "y": 19,
      "z": 0,
      "name": "Rock_Calcite"
    },
    {
      "x": -9,
      "y": 20,
      "z": 0,
      "name": "Rock_Calcite"
    },
    {
      "x": -9,
      "y": 21,
      "z": 0,
      "name": "Rock_Calcite"
    },
    {
      "x": -9,
      "y": 22,
      "z": 0,
      "name": "Rock_Calcite"
    },
    {
      "x": -9,
      "y": 23,
      "z": 0,
      "name": "Rock_Calcite"
    },
    {
      "x": -9,
      "y": 24,
      "z": 0,
      "name": "Rock_Calcite"
    },
    {
      "x": -9,
      "y": 25,
      "z": 0,
      "name": "Rock_Calcite"
    },
    {
      "x": -9,
      "y": 17,
      "z": 1,
      "name": "Rock_Calcite"
    },
    {
      "x": -9,
      "y": 18,
      "z": 1,
      "name": "Rock_Calcite"
    },
    {
      "x": -9,
      "y": 19,
      "z": 1,
      "name": "Rock_Calcite"
    },
    {
      "x": -9,
      "y": 20,
      "z": 1,
      "name": "Rock_Calcite"
    },
    {
      "x": -9,
      "y": 21,
      "z": 1,
      "name": "Rock_Calcite"
    },
    {
      "x": -9,
      "y": 22,
      "z": 1,
      "name": "Rock_Calcite"
    },
    {
      "x": -9,
      "y": 48,
      "z": 1,
      "name": "Plant_Bush_Hanging"
    },
    {
      "x": -9,
      "y": 49,
      "z": 1,
      "name": "Plant_Bush_Hanging"
    },
    {
      "x": -9,
      "y": 50,
      "z": 1,
      "name": "Plant_Bush_Hanging"
    },
    {
      "x": -9,
      "y": 16,
      "z": 2,
      "name": "Rock_Calcite"
    },
    {
      "x": -9,
      "y": 17,
      "z": 2,
      "name": "Rock_Calcite"
    },
    {
      "x": -9,
      "y": 18,
      "z": 2,
      "name": "Rock_Calcite"
    },
    {
      "x": -9,
      "y": 19,
      "z": 2,
      "name": "Rock_Calcite"
    },
    {
      "x": -9,
      "y": 20,
      "z": 2,
      "name": "Rock_Calcite"
    },
    {
      "x": -9,
      "y": 21,
      "z": 2,
      "name": "Rock_Calcite"
    },
    {
      "x": -9,
      "y": 22,
      "z": 2,
      "name": "Rock_Calcite"
    },
    {
      "x": -9,
      "y": 23,
      "z": 2,
      "name": "Rock_Calcite"
    },
    {
      "x": -9,
      "y": 24,
      "z": 2,
      "name": "Rock_Calcite"
    },
    {
      "x": -9,
      "y": 46,
      "z": 2,
      "name": "Plant_Bush_Hanging"
    },
    {
      "x": -9,
      "y": 47,
      "z": 2,
      "name": "Plant_Bush_Hanging"
    },
    {
      "x": -9,
      "y": 49,
      "z": 2,
      "name": "Plant_Bush_Hanging"
    },
    {
      "x": -9,
      "y": 51,
      "z": 2,
      "name": "Plant_Leaves_Wisteria_Wild"
    },
    {
      "x": -9,
      "y": 18,
      "z": 3,
      "name": "Rock_Calcite"
    },
    {
      "x": -9,
      "y": 19,
      "z": 3,
      "name": "Rock_Calcite"
    },
    {
      "x": -9,
      "y": 20,
      "z": 3,
      "name": "Rock_Calcite"
    },
    {
      "x": -9,
      "y": 21,
      "z": 3,
      "name": "Rock_Calcite"
    },
    {
      "x": -9,
      "y": 22,
      "z": 3,
      "name": "Rock_Calcite"
    },
    {
      "x": -9,
      "y": 49,
      "z": 3,
      "name": "Plant_Bush_Hanging"
    },
    {
      "x": -9,
      "y": 50,
      "z": 3,
      "name": "Plant_Bush_Hanging"
    },
    {
      "x": -9,
      "y": 51,
      "z": 3,
      "name": "Wood_Wisteria_Wild_Branch_Corner",
      "rotation": 3
    },
    {
      "x": -9,
      "y": 52,
      "z": 3,
      "name": "Plant_Leaves_Wisteria_Wild"
    },
    {
      "x": -9,
      "y": 51,
      "z": 4,
      "name": "Plant_Leaves_Wisteria_Wild"
    },
    {
      "x": -8,
      "y": 14,
      "z": -6,
      "name": "Rock_Calcite"
    },
    {
      "x": -8,
      "y": 15,
      "z": -6,
      "name": "Rock_Calcite"
    },
    {
      "x": -8,
      "y": 16,
      "z": -6,
      "name": "Rock_Calcite"
    },
    {
      "x": -8,
      "y": 17,
      "z": -6,
      "name": "Rock_Calcite"
    },
    {
      "x": -8,
      "y": 18,
      "z": -6,
      "name": "Rock_Calcite"
    },
    {
      "x": -8,
      "y": 19,
      "z": -6,
      "name": "Rock_Calcite"
    },
    {
      "x": -8,
      "y": 20,
      "z": -6,
      "name": "Rock_Calcite"
    },
    {
      "x": -8,
      "y": 13,
      "z": -5,
      "name": "Rock_Calcite"
    },
    {
      "x": -8,
      "y": 14,
      "z": -5,
      "name": "Rock_Calcite"
    },
    {
      "x": -8,
      "y": 15,
      "z": -5,
      "name": "Rock_Calcite"
    },
    {
      "x": -8,
      "y": 16,
      "z": -5,
      "name": "Rock_Calcite"
    },
    {
      "x": -8,
      "y": 17,
      "z": -5,
      "name": "Rock_Calcite"
    },
    {
      "x": -8,
      "y": 18,
      "z": -5,
      "name": "Rock_Calcite"
    },
    {
      "x": -8,
      "y": 19,
      "z": -5,
      "name": "Rock_Calcite"
    },
    {
      "x": -8,
      "y": 20,
      "z": -5,
      "name": "Rock_Calcite"
    },
    {
      "x": -8,
      "y": 21,
      "z": -5,
      "name": "Rock_Calcite"
    },
    {
      "x": -8,
      "y": 22,
      "z": -5,
      "name": "Rock_Calcite"
    },
    {
      "x": -8,
      "y": 12,
      "z": -4,
      "name": "Rock_Calcite"
    },
    {
      "x": -8,
      "y": 13,
      "z": -4,
      "name": "Rock_Calcite"
    },
    {
      "x": -8,
      "y": 14,
      "z": -4,
      "name": "Rock_Calcite"
    },
    {
      "x": -8,
      "y": 15,
      "z": -4,
      "name": "Rock_Calcite"
    },
    {
      "x": -8,
      "y": 16,
      "z": -4,
      "name": "Rock_Calcite"
    },
    {
      "x": -8,
      "y": 17,
      "z": -4,
      "name": "Rock_Calcite"
    },
    {
      "x": -8,
      "y": 18,
      "z": -4,
      "name": "Rock_Calcite"
    },
    {
      "x": -8,
      "y": 19,
      "z": -4,
      "name": "Rock_Calcite"
    },
    {
      "x": -8,
      "y": 20,
      "z": -4,
      "name": "Rock_Calcite"
    },
    {
      "x": -8,
      "y": 21,
      "z": -4,
      "name": "Rock_Calcite"
    },
    {
      "x": -8,
      "y": 22,
      "z": -4,
      "name": "Rock_Calcite"
    },
    {
      "x": -8,
      "y": 23,
      "z": -4,
      "name": "Rock_Calcite"
    },
    {
      "x": -8,
      "y": 24,
      "z": -4,
      "name": "Rock_Calcite"
    },
    {
      "x": -8,
      "y": 25,
      "z": -4,
      "name": "Rock_Calcite"
    },
    {
      "x": -8,
      "y": 26,
      "z": -4,
      "name": "Rock_Calcite"
    },
    {
      "x": -8,
      "y": 27,
      "z": -4,
      "name": "Rock_Calcite"
    },
    {
      "x": -8,
      "y": 12,
      "z": -3,
      "name": "Rock_Calcite"
    },
    {
      "x": -8,
      "y": 13,
      "z": -3,
      "name": "Rock_Calcite"
    },
    {
      "x": -8,
      "y": 14,
      "z": -3,
      "name": "Rock_Calcite"
    },
    {
      "x": -8,
      "y": 15,
      "z": -3,
      "name": "Rock_Calcite"
    },
    {
      "x": -8,
      "y": 16,
      "z": -3,
      "name": "Rock_Calcite"
    },
    {
      "x": -8,
      "y": 17,
      "z": -3,
      "name": "Rock_Calcite"
    },
    {
      "x": -8,
      "y": 18,
      "z": -3,
      "name": "Rock_Calcite"
    },
    {
      "x": -8,
      "y": 19,
      "z": -3,
      "name": "Rock_Calcite"
    },
    {
      "x": -8,
      "y": 20,
      "z": -3,
      "name": "Rock_Calcite"
    },
    {
      "x": -8,
      "y": 21,
      "z": -3,
      "name": "Rock_Calcite"
    },
    {
      "x": -8,
      "y": 22,
      "z": -3,
      "name": "Rock_Calcite"
    },
    {
      "x": -8,
      "y": 23,
      "z": -3,
      "name": "Rock_Calcite"
    },
    {
      "x": -8,
      "y": 24,
      "z": -3,
      "name": "Rock_Calcite"
    },
    {
      "x": -8,
      "y": 25,
      "z": -3,
      "name": "Rock_Calcite"
    },
    {
      "x": -8,
      "y": 26,
      "z": -3,
      "name": "Rock_Calcite"
    },
    {
      "x": -8,
      "y": 27,
      "z": -3,
      "name": "Rock_Calcite"
    },
    {
      "x": -8,
      "y": 28,
      "z": -3,
      "name": "Rock_Calcite"
    },
    {
      "x": -8,
      "y": 29,
      "z": -3,
      "name": "Rock_Calcite"
    },
    {
      "x": -8,
      "y": 30,
      "z": -3,
      "name": "Rock_Calcite"
    },
    {
      "x": -8,
      "y": 31,
      "z": -3,
      "name": "Rock_Calcite"
    },
    {
      "x": -8,
      "y": 11,
      "z": -2,
      "name": "Rock_Calcite"
    },
    {
      "x": -8,
      "y": 12,
      "z": -2,
      "name": "Rock_Calcite"
    },
    {
      "x": -8,
      "y": 13,
      "z": -2,
      "name": "Rock_Calcite"
    },
    {
      "x": -8,
      "y": 14,
      "z": -2,
      "name": "Rock_Calcite"
    },
    {
      "x": -8,
      "y": 15,
      "z": -2,
      "name": "Rock_Calcite"
    },
    {
      "x": -8,
      "y": 16,
      "z": -2,
      "name": "Rock_Calcite"
    },
    {
      "x": -8,
      "y": 17,
      "z": -2,
      "name": "Rock_Calcite"
    },
    {
      "x": -8,
      "y": 18,
      "z": -2,
      "name": "Rock_Calcite"
    },
    {
      "x": -8,
      "y": 19,
      "z": -2,
      "name": "Rock_Calcite"
    },
    {
      "x": -8,
      "y": 20,
      "z": -2,
      "name": "Rock_Calcite"
    },
    {
      "x": -8,
      "y": 21,
      "z": -2,
      "name": "Rock_Calcite"
    },
    {
      "x": -8,
      "y": 22,
      "z": -2,
      "name": "Rock_Calcite"
    },
    {
      "x": -8,
      "y": 23,
      "z": -2,
      "name": "Rock_Calcite"
    },
    {
      "x": -8,
      "y": 24,
      "z": -2,
      "name": "Rock_Calcite"
    },
    {
      "x": -8,
      "y": 25,
      "z": -2,
      "name": "Rock_Calcite"
    },
    {
      "x": -8,
      "y": 26,
      "z": -2,
      "name": "Rock_Calcite"
    },
    {
      "x": -8,
      "y": 27,
      "z": -2,
      "name": "Rock_Calcite"
    },
    {
      "x": -8,
      "y": 28,
      "z": -2,
      "name": "Rock_Calcite"
    },
    {
      "x": -8,
      "y": 29,
      "z": -2,
      "name": "Rock_Calcite"
    },
    {
      "x": -8,
      "y": 30,
      "z": -2,
      "name": "Rock_Calcite"
    },
    {
      "x": -8,
      "y": 31,
      "z": -2,
      "name": "Rock_Calcite"
    },
    {
      "x": -8,
      "y": 11,
      "z": -1,
      "name": "Rock_Calcite"
    },
    {
      "x": -8,
      "y": 12,
      "z": -1,
      "name": "Rock_Calcite"
    },
    {
      "x": -8,
      "y": 13,
      "z": -1,
      "name": "Rock_Calcite"
    },
    {
      "x": -8,
      "y": 14,
      "z": -1,
      "name": "Rock_Calcite"
    },
    {
      "x": -8,
      "y": 15,
      "z": -1,
      "name": "Rock_Calcite"
    },
    {
      "x": -8,
      "y": 16,
      "z": -1,
      "name": "Rock_Calcite"
    },
    {
      "x": -8,
      "y": 17,
      "z": -1,
      "name": "Rock_Calcite"
    },
    {
      "x": -8,
      "y": 18,
      "z": -1,
      "name": "Rock_Calcite"
    },
    {
      "x": -8,
      "y": 19,
      "z": -1,
      "name": "Rock_Calcite"
    },
    {
      "x": -8,
      "y": 20,
      "z": -1,
      "name": "Rock_Calcite"
    },
    {
      "x": -8,
      "y": 21,
      "z": -1,
      "name": "Rock_Calcite"
    },
    {
      "x": -8,
      "y": 22,
      "z": -1,
      "name": "Rock_Calcite"
    },
    {
      "x": -8,
      "y": 23,
      "z": -1,
      "name": "Rock_Calcite"
    },
    {
      "x": -8,
      "y": 24,
      "z": -1,
      "name": "Rock_Calcite"
    },
    {
      "x": -8,
      "y": 25,
      "z": -1,
      "name": "Rock_Calcite"
    },
    {
      "x": -8,
      "y": 26,
      "z": -1,
      "name": "Rock_Calcite"
    },
    {
      "x": -8,
      "y": 27,
      "z": -1,
      "name": "Rock_Calcite"
    },
    {
      "x": -8,
      "y": 28,
      "z": -1,
      "name": "Rock_Calcite"
    },
    {
      "x": -8,
      "y": 29,
      "z": -1,
      "name": "Rock_Calcite"
    },
    {
      "x": -8,
      "y": 30,
      "z": -1,
      "name": "Rock_Calcite"
    },
    {
      "x": -8,
      "y": 31,
      "z": -1,
      "name": "Rock_Calcite"
    },
    {
      "x": -8,
      "y": 32,
      "z": -1,
      "name": "Rock_Calcite"
    },
    {
      "x": -8,
      "y": 12,
      "z": 0,
      "name": "Rock_Calcite"
    },
    {
      "x": -8,
      "y": 13,
      "z": 0,
      "name": "Rock_Calcite"
    },
    {
      "x": -8,
      "y": 14,
      "z": 0,
      "name": "Rock_Calcite"
    },
    {
      "x": -8,
      "y": 15,
      "z": 0,
      "name": "Rock_Calcite"
    },
    {
      "x": -8,
      "y": 16,
      "z": 0,
      "name": "Rock_Calcite"
    },
    {
      "x": -8,
      "y": 17,
      "z": 0,
      "name": "Rock_Calcite"
    },
    {
      "x": -8,
      "y": 18,
      "z": 0,
      "name": "Rock_Calcite"
    },
    {
      "x": -8,
      "y": 19,
      "z": 0,
      "name": "Rock_Calcite"
    },
    {
      "x": -8,
      "y": 20,
      "z": 0,
      "name": "Rock_Calcite"
    },
    {
      "x": -8,
      "y": 21,
      "z": 0,
      "name": "Rock_Calcite"
    },
    {
      "x": -8,
      "y": 22,
      "z": 0,
      "name": "Rock_Calcite"
    },
    {
      "x": -8,
      "y": 23,
      "z": 0,
      "name": "Rock_Calcite"
    },
    {
      "x": -8,
      "y": 24,
      "z": 0,
      "name": "Rock_Calcite"
    },
    {
      "x": -8,
      "y": 25,
      "z": 0,
      "name": "Rock_Calcite"
    },
    {
      "x": -8,
      "y": 26,
      "z": 0,
      "name": "Rock_Calcite"
    },
    {
      "x": -8,
      "y": 27,
      "z": 0,
      "name": "Rock_Calcite"
    },
    {
      "x": -8,
      "y": 28,
      "z": 0,
      "name": "Rock_Calcite"
    },
    {
      "x": -8,
      "y": 29,
      "z": 0,
      "name": "Rock_Calcite"
    },
    {
      "x": -8,
      "y": 30,
      "z": 0,
      "name": "Rock_Calcite"
    },
    {
      "x": -8,
      "y": 31,
      "z": 0,
      "name": "Rock_Calcite"
    },
    {
      "x": -8,
      "y": 45,
      "z": 0,
      "name": "Plant_Bush_Hanging"
    },
    {
      "x": -8,
      "y": 46,
      "z": 0,
      "name": "Plant_Bush_Hanging"
    },
    {
      "x": -8,
      "y": 47,
      "z": 0,
      "name": "Plant_Bush_Hanging"
    },
    {
      "x": -8,
      "y": 48,
      "z": 0,
      "name": "Plant_Bush_Hanging"
    },
    {
      "x": -8,
      "y": 49,
      "z": 0,
      "name": "Plant_Bush_Hanging"
    },
    {
      "x": -8,
      "y": 50,
      "z": 0,
      "name": "Plant_Bush_Hanging"
    },
    {
      "x": -8,
      "y": 51,
      "z": 0,
      "name": "Plant_Bush_Hanging"
    },
    {
      "x": -8,
      "y": 52,
      "z": 0,
      "name": "Plant_Bush_Hanging"
    },
    {
      "x": -8,
      "y": 53,
      "z": 0,
      "name": "Plant_Bush_Hanging"
    },
    {
      "x": -8,
      "y": 10,
      "z": 1,
      "name": "Rock_Calcite"
    },
    {
      "x": -8,
      "y": 11,
      "z": 1,
      "name": "Rock_Calcite"
    },
    {
      "x": -8,
      "y": 12,
      "z": 1,
      "name": "Rock_Calcite"
    },
    {
      "x": -8,
      "y": 13,
      "z": 1,
      "name": "Rock_Calcite"
    },
    {
      "x": -8,
      "y": 14,
      "z": 1,
      "name": "Rock_Calcite"
    },
    {
      "x": -8,
      "y": 15,
      "z": 1,
      "name": "Rock_Calcite"
    },
    {
      "x": -8,
      "y": 16,
      "z": 1,
      "name": "Rock_Calcite"
    },
    {
      "x": -8,
      "y": 17,
      "z": 1,
      "name": "Rock_Calcite"
    },
    {
      "x": -8,
      "y": 18,
      "z": 1,
      "name": "Rock_Calcite"
    },
    {
      "x": -8,
      "y": 19,
      "z": 1,
      "name": "Rock_Calcite"
    },
    {
      "x": -8,
      "y": 20,
      "z": 1,
      "name": "Rock_Calcite"
    },
    {
      "x": -8,
      "y": 21,
      "z": 1,
      "name": "Rock_Calcite"
    },
    {
      "x": -8,
      "y": 22,
      "z": 1,
      "name": "Rock_Calcite"
    },
    {
      "x": -8,
      "y": 23,
      "z": 1,
      "name": "Rock_Calcite"
    },
    {
      "x": -8,
      "y": 24,
      "z": 1,
      "name": "Rock_Calcite"
    },
    {
      "x": -8,
      "y": 25,
      "z": 1,
      "name": "Rock_Calcite"
    },
    {
      "x": -8,
      "y": 26,
      "z": 1,
      "name": "Rock_Calcite"
    },
    {
      "x": -8,
      "y": 37,
      "z": 1,
      "name": "Plant_Bush_Hanging"
    },
    {
      "x": -8,
      "y": 39,
      "z": 1,
      "name": "Plant_Bush_Hanging"
    },
    {
      "x": -8,
      "y": 40,
      "z": 1,
      "name": "Plant_Bush_Hanging"
    },
    {
      "x": -8,
      "y": 41,
      "z": 1,
      "name": "Plant_Bush_Hanging"
    },
    {
      "x": -8,
      "y": 43,
      "z": 1,
      "name": "Plant_Bush_Hanging"
    },
    {
      "x": -8,
      "y": 44,
      "z": 1,
      "name": "Plant_Bush_Hanging"
    },
    {
      "x": -8,
      "y": 46,
      "z": 1,
      "name": "Plant_Bush_Hanging"
    },
    {
      "x": -8,
      "y": 47,
      "z": 1,
      "name": "Plant_Bush_Hanging"
    },
    {
      "x": -8,
      "y": 48,
      "z": 1,
      "name": "Plant_Bush_Hanging"
    },
    {
      "x": -8,
      "y": 49,
      "z": 1,
      "name": "Plant_Bush_Hanging"
    },
    {
      "x": -8,
      "y": 50,
      "z": 1,
      "name": "Plant_Bush_Hanging"
    },
    {
      "x": -8,
      "y": 51,
      "z": 1,
      "name": "Plant_Bush_Hanging"
    },
    {
      "x": -8,
      "y": 53,
      "z": 1,
      "name": "Plant_Bush_Hanging"
    },
    {
      "x": -8,
      "y": 9,
      "z": 2,
      "name": "Rock_Calcite"
    },
    {
      "x": -8,
      "y": 10,
      "z": 2,
      "name": "Rock_Calcite"
    },
    {
      "x": -8,
      "y": 11,
      "z": 2,
      "name": "Rock_Calcite"
    },
    {
      "x": -8,
      "y": 12,
      "z": 2,
      "name": "Rock_Calcite"
    },
    {
      "x": -8,
      "y": 13,
      "z": 2,
      "name": "Rock_Calcite"
    },
    {
      "x": -8,
      "y": 14,
      "z": 2,
      "name": "Rock_Calcite"
    },
    {
      "x": -8,
      "y": 15,
      "z": 2,
      "name": "Rock_Calcite"
    },
    {
      "x": -8,
      "y": 16,
      "z": 2,
      "name": "Rock_Calcite"
    },
    {
      "x": -8,
      "y": 17,
      "z": 2,
      "name": "Rock_Calcite"
    },
    {
      "x": -8,
      "y": 18,
      "z": 2,
      "name": "Rock_Calcite"
    },
    {
      "x": -8,
      "y": 19,
      "z": 2,
      "name": "Rock_Calcite"
    },
    {
      "x": -8,
      "y": 20,
      "z": 2,
      "name": "Rock_Calcite"
    },
    {
      "x": -8,
      "y": 21,
      "z": 2,
      "name": "Rock_Calcite"
    },
    {
      "x": -8,
      "y": 22,
      "z": 2,
      "name": "Rock_Calcite"
    },
    {
      "x": -8,
      "y": 23,
      "z": 2,
      "name": "Rock_Calcite"
    },
    {
      "x": -8,
      "y": 24,
      "z": 2,
      "name": "Rock_Calcite"
    },
    {
      "x": -8,
      "y": 25,
      "z": 2,
      "name": "Rock_Calcite"
    },
    {
      "x": -8,
      "y": 26,
      "z": 2,
      "name": "Rock_Calcite"
    },
    {
      "x": -8,
      "y": 41,
      "z": 2,
      "name": "Plant_Bush_Hanging"
    },
    {
      "x": -8,
      "y": 42,
      "z": 2,
      "name": "Plant_Bush_Hanging"
    },
    {
      "x": -8,
      "y": 43,
      "z": 2,
      "name": "Plant_Bush_Hanging"
    },
    {
      "x": -8,
      "y": 45,
      "z": 2,
      "name": "Plant_Bush_Hanging"
    },
    {
      "x": -8,
      "y": 46,
      "z": 2,
      "name": "Plant_Bush_Hanging"
    },
    {
      "x": -8,
      "y": 47,
      "z": 2,
      "name": "Plant_Bush_Hanging"
    },
    {
      "x": -8,
      "y": 48,
      "z": 2,
      "name": "Plant_Bush_Hanging"
    },
    {
      "x": -8,
      "y": 49,
      "z": 2,
      "name": "Plant_Bush_Hanging"
    },
    {
      "x": -8,
      "y": 50,
      "z": 2,
      "name": "Plant_Bush_Hanging"
    },
    {
      "x": -8,
      "y": 52,
      "z": 2,
      "name": "Plant_Bush_Hanging"
    },
    {
      "x": -8,
      "y": 14,
      "z": 3,
      "name": "Rock_Calcite"
    },
    {
      "x": -8,
      "y": 15,
      "z": 3,
      "name": "Rock_Calcite"
    },
    {
      "x": -8,
      "y": 16,
      "z": 3,
      "name": "Rock_Calcite"
    },
    {
      "x": -8,
      "y": 17,
      "z": 3,
      "name": "Rock_Calcite"
    },
    {
      "x": -8,
      "y": 18,
      "z": 3,
      "name": "Rock_Calcite"
    },
    {
      "x": -8,
      "y": 19,
      "z": 3,
      "name": "Rock_Calcite"
    },
    {
      "x": -8,
      "y": 20,
      "z": 3,
      "name": "Rock_Calcite"
    },
    {
      "x": -8,
      "y": 21,
      "z": 3,
      "name": "Rock_Calcite"
    },
    {
      "x": -8,
      "y": 22,
      "z": 3,
      "name": "Rock_Calcite"
    },
    {
      "x": -8,
      "y": 23,
      "z": 3,
      "name": "Rock_Calcite"
    },
    {
      "x": -8,
      "y": 24,
      "z": 3,
      "name": "Rock_Calcite"
    },
    {
      "x": -8,
      "y": 25,
      "z": 3,
      "name": "Rock_Calcite"
    },
    {
      "x": -8,
      "y": 26,
      "z": 3,
      "name": "Rock_Calcite"
    },
    {
      "x": -8,
      "y": 44,
      "z": 3,
      "name": "Plant_Bush_Hanging"
    },
    {
      "x": -8,
      "y": 45,
      "z": 3,
      "name": "Plant_Bush_Hanging"
    },
    {
      "x": -8,
      "y": 46,
      "z": 3,
      "name": "Plant_Bush_Hanging"
    },
    {
      "x": -8,
      "y": 47,
      "z": 3,
      "name": "Plant_Bush_Hanging"
    },
    {
      "x": -8,
      "y": 48,
      "z": 3,
      "name": "Plant_Bush_Hanging"
    },
    {
      "x": -8,
      "y": 49,
      "z": 3,
      "name": "Plant_Bush_Hanging"
    },
    {
      "x": -8,
      "y": 50,
      "z": 3,
      "name": "Plant_Bush_Hanging"
    },
    {
      "x": -8,
      "y": 51,
      "z": 3,
      "name": "Wood_Wisteria_Wild_Branch_Long",
      "rotation": 5
    },
    {
      "x": -8,
      "y": 18,
      "z": 4,
      "name": "Rock_Calcite"
    },
    {
      "x": -8,
      "y": 19,
      "z": 4,
      "name": "Rock_Calcite"
    },
    {
      "x": -8,
      "y": 20,
      "z": 4,
      "name": "Rock_Calcite"
    },
    {
      "x": -8,
      "y": 21,
      "z": 4,
      "name": "Rock_Calcite"
    },
    {
      "x": -8,
      "y": 22,
      "z": 4,
      "name": "Rock_Calcite"
    },
    {
      "x": -8,
      "y": 47,
      "z": 4,
      "name": "Plant_Bush_Hanging"
    },
    {
      "x": -8,
      "y": 48,
      "z": 4,
      "name": "Plant_Bush_Hanging"
    },
    {
      "x": -8,
      "y": 50,
      "z": 4,
      "name": "Plant_Bush_Hanging"
    },
    {
      "x": -7,
      "y": 57,
      "z": -8,
      "name": "Plant_Leaves_Wisteria_Wild"
    },
    {
      "x": -7,
      "y": 12,
      "z": -7,
      "name": "Rock_Calcite"
    },
    {
      "x": -7,
      "y": 15,
      "z": -7,
      "name": "Rock_Calcite"
    },
    {
      "x": -7,
      "y": 16,
      "z": -7,
      "name": "Rock_Calcite"
    },
    {
      "x": -7,
      "y": 17,
      "z": -7,
      "name": "Rock_Calcite"
    },
    {
      "x": -7,
      "y": 18,
      "z": -7,
      "name": "Rock_Calcite"
    },
    {
      "x": -7,
      "y": 19,
      "z": -7,
      "name": "Rock_Calcite"
    },
    {
      "x": -7,
      "y": 20,
      "z": -7,
      "name": "Rock_Calcite"
    },
    {
      "x": -7,
      "y": 13,
      "z": -6,
      "name": "Rock_Calcite"
    },
    {
      "x": -7,
      "y": 14,
      "z": -6,
      "name": "Rock_Calcite"
    },
    {
      "x": -7,
      "y": 15,
      "z": -6,
      "name": "Rock_Calcite"
    },
    {
      "x": -7,
      "y": 16,
      "z": -6,
      "name": "Rock_Calcite"
    },
    {
      "x": -7,
      "y": 17,
      "z": -6,
      "name": "Rock_Calcite"
    },
    {
      "x": -7,
      "y": 18,
      "z": -6,
      "name": "Rock_Calcite"
    },
    {
      "x": -7,
      "y": 19,
      "z": -6,
      "name": "Rock_Calcite"
    },
    {
      "x": -7,
      "y": 20,
      "z": -6,
      "name": "Rock_Calcite"
    },
    {
      "x": -7,
      "y": 21,
      "z": -6,
      "name": "Rock_Calcite"
    },
    {
      "x": -7,
      "y": 22,
      "z": -6,
      "name": "Rock_Calcite"
    },
    {
      "x": -7,
      "y": 11,
      "z": -5,
      "name": "Rock_Calcite"
    },
    {
      "x": -7,
      "y": 12,
      "z": -5,
      "name": "Rock_Calcite"
    },
    {
      "x": -7,
      "y": 13,
      "z": -5,
      "name": "Rock_Calcite"
    },
    {
      "x": -7,
      "y": 14,
      "z": -5,
      "name": "Rock_Calcite"
    },
    {
      "x": -7,
      "y": 15,
      "z": -5,
      "name": "Rock_Calcite"
    },
    {
      "x": -7,
      "y": 16,
      "z": -5,
      "name": "Rock_Calcite"
    },
    {
      "x": -7,
      "y": 17,
      "z": -5,
      "name": "Rock_Calcite"
    },
    {
      "x": -7,
      "y": 18,
      "z": -5,
      "name": "Rock_Calcite"
    },
    {
      "x": -7,
      "y": 19,
      "z": -5,
      "name": "Rock_Calcite"
    },
    {
      "x": -7,
      "y": 20,
      "z": -5,
      "name": "Rock_Calcite"
    },
    {
      "x": -7,
      "y": 21,
      "z": -5,
      "name": "Rock_Calcite"
    },
    {
      "x": -7,
      "y": 22,
      "z": -5,
      "name": "Rock_Calcite"
    },
    {
      "x": -7,
      "y": 23,
      "z": -5,
      "name": "Rock_Calcite"
    },
    {
      "x": -7,
      "y": 24,
      "z": -5,
      "name": "Rock_Calcite"
    },
    {
      "x": -7,
      "y": 25,
      "z": -5,
      "name": "Rock_Calcite"
    },
    {
      "x": -7,
      "y": 26,
      "z": -5,
      "name": "Rock_Calcite"
    },
    {
      "x": -7,
      "y": 27,
      "z": -5,
      "name": "Rock_Calcite"
    },
    {
      "x": -7,
      "y": 10,
      "z": -4,
      "name": "Rock_Calcite"
    },
    {
      "x": -7,
      "y": 11,
      "z": -4,
      "name": "Rock_Calcite"
    },
    {
      "x": -7,
      "y": 12,
      "z": -4,
      "name": "Rock_Calcite"
    },
    {
      "x": -7,
      "y": 13,
      "z": -4,
      "name": "Rock_Calcite"
    },
    {
      "x": -7,
      "y": 14,
      "z": -4,
      "name": "Rock_Calcite"
    },
    {
      "x": -7,
      "y": 15,
      "z": -4,
      "name": "Rock_Calcite"
    },
    {
      "x": -7,
      "y": 16,
      "z": -4,
      "name": "Rock_Calcite"
    },
    {
      "x": -7,
      "y": 17,
      "z": -4,
      "name": "Rock_Calcite"
    },
    {
      "x": -7,
      "y": 18,
      "z": -4,
      "name": "Rock_Calcite"
    },
    {
      "x": -7,
      "y": 19,
      "z": -4,
      "name": "Rock_Calcite"
    },
    {
      "x": -7,
      "y": 20,
      "z": -4,
      "name": "Rock_Calcite"
    },
    {
      "x": -7,
      "y": 21,
      "z": -4,
      "name": "Rock_Calcite"
    },
    {
      "x": -7,
      "y": 22,
      "z": -4,
      "name": "Rock_Calcite"
    },
    {
      "x": -7,
      "y": 23,
      "z": -4,
      "name": "Rock_Calcite"
    },
    {
      "x": -7,
      "y": 24,
      "z": -4,
      "name": "Rock_Calcite"
    },
    {
      "x": -7,
      "y": 25,
      "z": -4,
      "name": "Rock_Calcite"
    },
    {
      "x": -7,
      "y": 26,
      "z": -4,
      "name": "Rock_Calcite"
    },
    {
      "x": -7,
      "y": 27,
      "z": -4,
      "name": "Rock_Calcite"
    },
    {
      "x": -7,
      "y": 28,
      "z": -4,
      "name": "Rock_Calcite"
    },
    {
      "x": -7,
      "y": 29,
      "z": -4,
      "name": "Rock_Calcite"
    },
    {
      "x": -7,
      "y": 30,
      "z": -4,
      "name": "Rock_Calcite"
    },
    {
      "x": -7,
      "y": 31,
      "z": -4,
      "name": "Rock_Calcite"
    },
    {
      "x": -7,
      "y": 32,
      "z": -4,
      "name": "Plant_Bush_Hanging"
    },
    {
      "x": -7,
      "y": 33,
      "z": -4,
      "name": "Plant_Bush_Hanging"
    },
    {
      "x": -7,
      "y": 34,
      "z": -4,
      "name": "Plant_Bush_Hanging"
    },
    {
      "x": -7,
      "y": 35,
      "z": -4,
      "name": "Plant_Bush_Hanging"
    },
    {
      "x": -7,
      "y": 36,
      "z": -4,
      "name": "Plant_Bush_Hanging"
    },
    {
      "x": -7,
      "y": 37,
      "z": -4,
      "name": "Plant_Bush_Hanging"
    },
    {
      "x": -7,
      "y": 39,
      "z": -4,
      "name": "Plant_Bush_Hanging"
    },
    {
      "x": -7,
      "y": 41,
      "z": -4,
      "name": "Plant_Bush_Hanging"
    },
    {
      "x": -7,
      "y": 42,
      "z": -4,
      "name": "Plant_Bush_Hanging"
    },
    {
      "x": -7,
      "y": 43,
      "z": -4,
      "name": "Plant_Bush_Hanging"
    },
    {
      "x": -7,
      "y": 44,
      "z": -4,
      "name": "Plant_Bush_Hanging"
    },
    {
      "x": -7,
      "y": 45,
      "z": -4,
      "name": "Plant_Bush_Hanging"
    },
    {
      "x": -7,
      "y": 46,
      "z": -4,
      "name": "Plant_Bush_Hanging"
    },
    {
      "x": -7,
      "y": 10,
      "z": -3,
      "name": "Rock_Calcite"
    },
    {
      "x": -7,
      "y": 11,
      "z": -3,
      "name": "Rock_Calcite"
    },
    {
      "x": -7,
      "y": 12,
      "z": -3,
      "name": "Rock_Calcite"
    },
    {
      "x": -7,
      "y": 13,
      "z": -3,
      "name": "Rock_Calcite"
    },
    {
      "x": -7,
      "y": 14,
      "z": -3,
      "name": "Rock_Calcite"
    },
    {
      "x": -7,
      "y": 15,
      "z": -3,
      "name": "Rock_Calcite"
    },
    {
      "x": -7,
      "y": 16,
      "z": -3,
      "name": "Rock_Calcite"
    },
    {
      "x": -7,
      "y": 17,
      "z": -3,
      "name": "Rock_Calcite"
    },
    {
      "x": -7,
      "y": 18,
      "z": -3,
      "name": "Rock_Calcite"
    },
    {
      "x": -7,
      "y": 19,
      "z": -3,
      "name": "Rock_Calcite"
    },
    {
      "x": -7,
      "y": 20,
      "z": -3,
      "name": "Rock_Calcite"
    },
    {
      "x": -7,
      "y": 21,
      "z": -3,
      "name": "Rock_Calcite"
    },
    {
      "x": -7,
      "y": 22,
      "z": -3,
      "name": "Rock_Calcite"
    },
    {
      "x": -7,
      "y": 23,
      "z": -3,
      "name": "Rock_Calcite"
    },
    {
      "x": -7,
      "y": 24,
      "z": -3,
      "name": "Rock_Calcite"
    },
    {
      "x": -7,
      "y": 25,
      "z": -3,
      "name": "Rock_Calcite"
    },
    {
      "x": -7,
      "y": 26,
      "z": -3,
      "name": "Rock_Calcite"
    },
    {
      "x": -7,
      "y": 27,
      "z": -3,
      "name": "Rock_Calcite"
    },
    {
      "x": -7,
      "y": 28,
      "z": -3,
      "name": "Rock_Calcite"
    },
    {
      "x": -7,
      "y": 29,
      "z": -3,
      "name": "Rock_Calcite"
    },
    {
      "x": -7,
      "y": 30,
      "z": -3,
      "name": "Rock_Calcite"
    },
    {
      "x": -7,
      "y": 31,
      "z": -3,
      "name": "Rock_Calcite"
    },
    {
      "x": -7,
      "y": 32,
      "z": -3,
      "name": "Rock_Calcite"
    },
    {
      "x": -7,
      "y": 33,
      "z": -3,
      "name": "Rock_Calcite"
    },
    {
      "x": -7,
      "y": 40,
      "z": -3,
      "name": "Plant_Bush_Hanging"
    },
    {
      "x": -7,
      "y": 41,
      "z": -3,
      "name": "Plant_Bush_Hanging"
    },
    {
      "x": -7,
      "y": 43,
      "z": -3,
      "name": "Plant_Bush_Hanging"
    },
    {
      "x": -7,
      "y": 44,
      "z": -3,
      "name": "Plant_Bush_Hanging"
    },
    {
      "x": -7,
      "y": 45,
      "z": -3,
      "name": "Plant_Bush_Hanging"
    },
    {
      "x": -7,
      "y": 46,
      "z": -3,
      "name": "Plant_Bush_Hanging"
    },
    {
      "x": -7,
      "y": 47,
      "z": -3,
      "name": "Plant_Bush_Hanging"
    },
    {
      "x": -7,
      "y": 48,
      "z": -3,
      "name": "Plant_Bush_Hanging"
    },
    {
      "x": -7,
      "y": 49,
      "z": -3,
      "name": "Plant_Bush_Hanging"
    },
    {
      "x": -7,
      "y": 50,
      "z": -3,
      "name": "Plant_Bush_Hanging"
    },
    {
      "x": -7,
      "y": 51,
      "z": -3,
      "name": "Plant_Bush_Hanging"
    },
    {
      "x": -7,
      "y": 52,
      "z": -3,
      "name": "Plant_Bush_Hanging"
    },
    {
      "x": -7,
      "y": 53,
      "z": -3,
      "name": "Plant_Bush_Hanging"
    },
    {
      "x": -7,
      "y": 10,
      "z": -2,
      "name": "Rock_Calcite"
    },
    {
      "x": -7,
      "y": 11,
      "z": -2,
      "name": "Rock_Calcite"
    },
    {
      "x": -7,
      "y": 12,
      "z": -2,
      "name": "Rock_Calcite"
    },
    {
      "x": -7,
      "y": 13,
      "z": -2,
      "name": "Rock_Calcite"
    },
    {
      "x": -7,
      "y": 14,
      "z": -2,
      "name": "Rock_Calcite"
    },
    {
      "x": -7,
      "y": 15,
      "z": -2,
      "name": "Rock_Calcite"
    },
    {
      "x": -7,
      "y": 16,
      "z": -2,
      "name": "Rock_Calcite"
    },
    {
      "x": -7,
      "y": 17,
      "z": -2,
      "name": "Rock_Calcite"
    },
    {
      "x": -7,
      "y": 18,
      "z": -2,
      "name": "Rock_Calcite"
    },
    {
      "x": -7,
      "y": 19,
      "z": -2,
      "name": "Rock_Calcite"
    },
    {
      "x": -7,
      "y": 20,
      "z": -2,
      "name": "Rock_Calcite"
    },
    {
      "x": -7,
      "y": 21,
      "z": -2,
      "name": "Rock_Calcite"
    },
    {
      "x": -7,
      "y": 22,
      "z": -2,
      "name": "Rock_Calcite"
    },
    {
      "x": -7,
      "y": 23,
      "z": -2,
      "name": "Rock_Calcite"
    },
    {
      "x": -7,
      "y": 24,
      "z": -2,
      "name": "Rock_Calcite"
    },
    {
      "x": -7,
      "y": 25,
      "z": -2,
      "name": "Rock_Calcite"
    },
    {
      "x": -7,
      "y": 26,
      "z": -2,
      "name": "Rock_Calcite"
    },
    {
      "x": -7,
      "y": 27,
      "z": -2,
      "name": "Rock_Calcite"
    },
    {
      "x": -7,
      "y": 28,
      "z": -2,
      "name": "Rock_Calcite"
    },
    {
      "x": -7,
      "y": 29,
      "z": -2,
      "name": "Rock_Calcite"
    },
    {
      "x": -7,
      "y": 30,
      "z": -2,
      "name": "Rock_Calcite"
    },
    {
      "x": -7,
      "y": 31,
      "z": -2,
      "name": "Rock_Calcite"
    },
    {
      "x": -7,
      "y": 32,
      "z": -2,
      "name": "Rock_Calcite"
    },
    {
      "x": -7,
      "y": 33,
      "z": -2,
      "name": "Rock_Calcite"
    },
    {
      "x": -7,
      "y": 34,
      "z": -2,
      "name": "Rock_Calcite"
    },
    {
      "x": -7,
      "y": 48,
      "z": -2,
      "name": "Plant_Bush_Hanging"
    },
    {
      "x": -7,
      "y": 49,
      "z": -2,
      "name": "Plant_Bush_Hanging"
    },
    {
      "x": -7,
      "y": 50,
      "z": -2,
      "name": "Plant_Bush_Hanging"
    },
    {
      "x": -7,
      "y": 51,
      "z": -2,
      "name": "Plant_Bush_Hanging"
    },
    {
      "x": -7,
      "y": 53,
      "z": -2,
      "name": "Plant_Bush_Hanging"
    },
    {
      "x": -7,
      "y": 54,
      "z": -2,
      "name": "Plant_Bush_Hanging"
    },
    {
      "x": -7,
      "y": 10,
      "z": -1,
      "name": "Rock_Calcite"
    },
    {
      "x": -7,
      "y": 11,
      "z": -1,
      "name": "Rock_Calcite"
    },
    {
      "x": -7,
      "y": 12,
      "z": -1,
      "name": "Rock_Calcite"
    },
    {
      "x": -7,
      "y": 13,
      "z": -1,
      "name": "Rock_Calcite"
    },
    {
      "x": -7,
      "y": 14,
      "z": -1,
      "name": "Rock_Calcite"
    },
    {
      "x": -7,
      "y": 15,
      "z": -1,
      "name": "Rock_Calcite"
    },
    {
      "x": -7,
      "y": 16,
      "z": -1,
      "name": "Rock_Calcite"
    },
    {
      "x": -7,
      "y": 17,
      "z": -1,
      "name": "Rock_Calcite"
    },
    {
      "x": -7,
      "y": 18,
      "z": -1,
      "name": "Rock_Calcite"
    },
    {
      "x": -7,
      "y": 19,
      "z": -1,
      "name": "Rock_Calcite"
    },
    {
      "x": -7,
      "y": 20,
      "z": -1,
      "name": "Rock_Calcite"
    },
    {
      "x": -7,
      "y": 21,
      "z": -1,
      "name": "Rock_Calcite"
    },
    {
      "x": -7,
      "y": 22,
      "z": -1,
      "name": "Rock_Calcite"
    },
    {
      "x": -7,
      "y": 23,
      "z": -1,
      "name": "Rock_Calcite"
    },
    {
      "x": -7,
      "y": 24,
      "z": -1,
      "name": "Rock_Calcite"
    },
    {
      "x": -7,
      "y": 25,
      "z": -1,
      "name": "Rock_Calcite"
    },
    {
      "x": -7,
      "y": 26,
      "z": -1,
      "name": "Rock_Calcite"
    },
    {
      "x": -7,
      "y": 27,
      "z": -1,
      "name": "Rock_Calcite"
    },
    {
      "x": -7,
      "y": 28,
      "z": -1,
      "name": "Rock_Calcite"
    },
    {
      "x": -7,
      "y": 29,
      "z": -1,
      "name": "Rock_Calcite"
    },
    {
      "x": -7,
      "y": 30,
      "z": -1,
      "name": "Rock_Calcite"
    },
    {
      "x": -7,
      "y": 31,
      "z": -1,
      "name": "Rock_Calcite"
    },
    {
      "x": -7,
      "y": 32,
      "z": -1,
      "name": "Rock_Calcite"
    },
    {
      "x": -7,
      "y": 33,
      "z": -1,
      "name": "Rock_Calcite"
    },
    {
      "x": -7,
      "y": 34,
      "z": -1,
      "name": "Rock_Calcite"
    },
    {
      "x": -7,
      "y": 35,
      "z": -1,
      "name": "Rock_Calcite"
    },
    {
      "x": -7,
      "y": 50,
      "z": -1,
      "name": "Plant_Bush_Hanging"
    },
    {
      "x": -7,
      "y": 51,
      "z": -1,
      "name": "Plant_Bush_Hanging"
    },
    {
      "x": -7,
      "y": 52,
      "z": -1,
      "name": "Plant_Bush_Hanging"
    },
    {
      "x": -7,
      "y": 53,
      "z": -1,
      "name": "Plant_Bush_Hanging"
    },
    {
      "x": -7,
      "y": 54,
      "z": -1,
      "name": "Plant_Bush_Hanging"
    },
    {
      "x": -7,
      "y": 55,
      "z": -1,
      "name": "Plant_Bush_Hanging"
    },
    {
      "x": -7,
      "y": 8,
      "z": 0,
      "name": "Rock_Calcite"
    },
    {
      "x": -7,
      "y": 9,
      "z": 0,
      "name": "Rock_Calcite"
    },
    {
      "x": -7,
      "y": 10,
      "z": 0,
      "name": "Rock_Calcite"
    },
    {
      "x": -7,
      "y": 11,
      "z": 0,
      "name": "Rock_Calcite"
    },
    {
      "x": -7,
      "y": 12,
      "z": 0,
      "name": "Rock_Calcite"
    },
    {
      "x": -7,
      "y": 13,
      "z": 0,
      "name": "Rock_Calcite"
    },
    {
      "x": -7,
      "y": 14,
      "z": 0,
      "name": "Rock_Calcite"
    },
    {
      "x": -7,
      "y": 15,
      "z": 0,
      "name": "Rock_Calcite"
    },
    {
      "x": -7,
      "y": 16,
      "z": 0,
      "name": "Rock_Calcite"
    },
    {
      "x": -7,
      "y": 17,
      "z": 0,
      "name": "Rock_Calcite"
    },
    {
      "x": -7,
      "y": 18,
      "z": 0,
      "name": "Rock_Calcite"
    },
    {
      "x": -7,
      "y": 19,
      "z": 0,
      "name": "Rock_Calcite"
    },
    {
      "x": -7,
      "y": 20,
      "z": 0,
      "name": "Rock_Calcite"
    },
    {
      "x": -7,
      "y": 21,
      "z": 0,
      "name": "Rock_Calcite"
    },
    {
      "x": -7,
      "y": 22,
      "z": 0,
      "name": "Rock_Calcite"
    },
    {
      "x": -7,
      "y": 23,
      "z": 0,
      "name": "Rock_Calcite"
    },
    {
      "x": -7,
      "y": 24,
      "z": 0,
      "name": "Rock_Calcite"
    },
    {
      "x": -7,
      "y": 25,
      "z": 0,
      "name": "Rock_Calcite"
    },
    {
      "x": -7,
      "y": 26,
      "z": 0,
      "name": "Rock_Calcite"
    },
    {
      "x": -7,
      "y": 27,
      "z": 0,
      "name": "Rock_Calcite"
    },
    {
      "x": -7,
      "y": 28,
      "z": 0,
      "name": "Rock_Calcite"
    },
    {
      "x": -7,
      "y": 29,
      "z": 0,
      "name": "Rock_Calcite"
    },
    {
      "x": -7,
      "y": 30,
      "z": 0,
      "name": "Rock_Calcite"
    },
    {
      "x": -7,
      "y": 31,
      "z": 0,
      "name": "Rock_Calcite"
    },
    {
      "x": -7,
      "y": 32,
      "z": 0,
      "name": "Rock_Calcite"
    },
    {
      "x": -7,
      "y": 33,
      "z": 0,
      "name": "Rock_Calcite"
    },
    {
      "x": -7,
      "y": 34,
      "z": 0,
      "name": "Rock_Calcite"
    },
    {
      "x": -7,
      "y": 35,
      "z": 0,
      "name": "Rock_Calcite"
    },
    {
      "x": -7,
      "y": 36,
      "z": 0,
      "name": "Rock_Calcite"
    },
    {
      "x": -7,
      "y": 37,
      "z": 0,
      "name": "Rock_Calcite"
    },
    {
      "x": -7,
      "y": 38,
      "z": 0,
      "name": "Rock_Calcite"
    },
    {
      "x": -7,
      "y": 39,
      "z": 0,
      "name": "Rock_Calcite"
    },
    {
      "x": -7,
      "y": 40,
      "z": 0,
      "name": "Rock_Calcite"
    },
    {
      "x": -7,
      "y": 41,
      "z": 0,
      "name": "Rock_Calcite"
    },
    {
      "x": -7,
      "y": 42,
      "z": 0,
      "name": "Rock_Calcite"
    },
    {
      "x": -7,
      "y": 43,
      "z": 0,
      "name": "Rock_Calcite"
    },
    {
      "x": -7,
      "y": 44,
      "z": 0,
      "name": "Rock_Calcite"
    },
    {
      "x": -7,
      "y": 45,
      "z": 0,
      "name": "Rock_Calcite"
    },
    {
      "x": -7,
      "y": 46,
      "z": 0,
      "name": "Rock_Calcite"
    },
    {
      "x": -7,
      "y": 47,
      "z": 0,
      "name": "Rock_Calcite"
    },
    {
      "x": -7,
      "y": 48,
      "z": 0,
      "name": "Rock_Marble"
    },
    {
      "x": -7,
      "y": 49,
      "z": 0,
      "name": "Rock_Marble"
    },
    {
      "x": -7,
      "y": 50,
      "z": 0,
      "name": "Rock_Marble"
    },
    {
      "x": -7,
      "y": 51,
      "z": 0,
      "name": "Rock_Calcite"
    },
    {
      "x": -7,
      "y": 52,
      "z": 0,
      "name": "Soil_Clay_Red"
    },
    {
      "x": -7,
      "y": 53,
      "z": 0,
      "name": "Soil_Grass_Wet"
    },
    {
      "x": -7,
      "y": 54,
      "z": 0,
      "name": "Plant_Bush_Lush"
    },
    {
      "x": -7,
      "y": 7,
      "z": 1,
      "name": "Rock_Calcite"
    },
    {
      "x": -7,
      "y": 8,
      "z": 1,
      "name": "Rock_Calcite"
    },
    {
      "x": -7,
      "y": 9,
      "z": 1,
      "name": "Rock_Calcite"
    },
    {
      "x": -7,
      "y": 10,
      "z": 1,
      "name": "Rock_Calcite"
    },
    {
      "x": -7,
      "y": 11,
      "z": 1,
      "name": "Rock_Calcite"
    },
    {
      "x": -7,
      "y": 12,
      "z": 1,
      "name": "Rock_Calcite"
    },
    {
      "x": -7,
      "y": 13,
      "z": 1,
      "name": "Rock_Calcite"
    },
    {
      "x": -7,
      "y": 14,
      "z": 1,
      "name": "Rock_Calcite"
    },
    {
      "x": -7,
      "y": 15,
      "z": 1,
      "name": "Rock_Calcite"
    },
    {
      "x": -7,
      "y": 16,
      "z": 1,
      "name": "Rock_Calcite"
    },
    {
      "x": -7,
      "y": 17,
      "z": 1,
      "name": "Rock_Calcite"
    },
    {
      "x": -7,
      "y": 18,
      "z": 1,
      "name": "Rock_Calcite"
    },
    {
      "x": -7,
      "y": 19,
      "z": 1,
      "name": "Rock_Calcite"
    },
    {
      "x": -7,
      "y": 20,
      "z": 1,
      "name": "Rock_Calcite"
    },
    {
      "x": -7,
      "y": 21,
      "z": 1,
      "name": "Rock_Calcite"
    },
    {
      "x": -7,
      "y": 22,
      "z": 1,
      "name": "Rock_Calcite"
    },
    {
      "x": -7,
      "y": 23,
      "z": 1,
      "name": "Rock_Calcite"
    },
    {
      "x": -7,
      "y": 24,
      "z": 1,
      "name": "Rock_Calcite"
    },
    {
      "x": -7,
      "y": 25,
      "z": 1,
      "name": "Rock_Calcite"
    },
    {
      "x": -7,
      "y": 26,
      "z": 1,
      "name": "Rock_Calcite"
    },
    {
      "x": -7,
      "y": 27,
      "z": 1,
      "name": "Rock_Calcite"
    },
    {
      "x": -7,
      "y": 28,
      "z": 1,
      "name": "Rock_Calcite"
    },
    {
      "x": -7,
      "y": 29,
      "z": 1,
      "name": "Rock_Calcite"
    },
    {
      "x": -7,
      "y": 30,
      "z": 1,
      "name": "Rock_Calcite"
    },
    {
      "x": -7,
      "y": 31,
      "z": 1,
      "name": "Rock_Calcite"
    },
    {
      "x": -7,
      "y": 32,
      "z": 1,
      "name": "Rock_Calcite"
    },
    {
      "x": -7,
      "y": 33,
      "z": 1,
      "name": "Rock_Calcite"
    },
    {
      "x": -7,
      "y": 34,
      "z": 1,
      "name": "Rock_Calcite"
    },
    {
      "x": -7,
      "y": 35,
      "z": 1,
      "name": "Rock_Calcite"
    },
    {
      "x": -7,
      "y": 36,
      "z": 1,
      "name": "Rock_Calcite"
    },
    {
      "x": -7,
      "y": 37,
      "z": 1,
      "name": "Rock_Calcite"
    },
    {
      "x": -7,
      "y": 38,
      "z": 1,
      "name": "Rock_Calcite"
    },
    {
      "x": -7,
      "y": 39,
      "z": 1,
      "name": "Rock_Calcite"
    },
    {
      "x": -7,
      "y": 40,
      "z": 1,
      "name": "Rock_Calcite"
    },
    {
      "x": -7,
      "y": 41,
      "z": 1,
      "name": "Rock_Calcite"
    },
    {
      "x": -7,
      "y": 42,
      "z": 1,
      "name": "Rock_Calcite"
    },
    {
      "x": -7,
      "y": 43,
      "z": 1,
      "name": "Rock_Calcite"
    },
    {
      "x": -7,
      "y": 44,
      "z": 1,
      "name": "Rock_Calcite"
    },
    {
      "x": -7,
      "y": 45,
      "z": 1,
      "name": "Rock_Calcite"
    },
    {
      "x": -7,
      "y": 46,
      "z": 1,
      "name": "Rock_Calcite"
    },
    {
      "x": -7,
      "y": 47,
      "z": 1,
      "name": "Rock_Calcite"
    },
    {
      "x": -7,
      "y": 48,
      "z": 1,
      "name": "Rock_Marble"
    },
    {
      "x": -7,
      "y": 49,
      "z": 1,
      "name": "Rock_Marble"
    },
    {
      "x": -7,
      "y": 50,
      "z": 1,
      "name": "Rock_Marble"
    },
    {
      "x": -7,
      "y": 51,
      "z": 1,
      "name": "Rock_Calcite"
    },
    {
      "x": -7,
      "y": 52,
      "z": 1,
      "name": "Soil_Clay_Red"
    },
    {
      "x": -7,
      "y": 53,
      "z": 1,
      "name": "Soil_Grass_Wet"
    },
    {
      "x": -7,
      "y": 54,
      "z": 1,
      "name": "Plant_Bush_Lush"
    },
    {
      "x": -7,
      "y": 7,
      "z": 2,
      "name": "Rock_Calcite"
    },
    {
      "x": -7,
      "y": 8,
      "z": 2,
      "name": "Rock_Calcite"
    },
    {
      "x": -7,
      "y": 9,
      "z": 2,
      "name": "Rock_Calcite"
    },
    {
      "x": -7,
      "y": 10,
      "z": 2,
      "name": "Rock_Calcite"
    },
    {
      "x": -7,
      "y": 11,
      "z": 2,
      "name": "Rock_Calcite"
    },
    {
      "x": -7,
      "y": 12,
      "z": 2,
      "name": "Rock_Calcite"
    },
    {
      "x": -7,
      "y": 13,
      "z": 2,
      "name": "Rock_Calcite"
    },
    {
      "x": -7,
      "y": 14,
      "z": 2,
      "name": "Rock_Calcite"
    },
    {
      "x": -7,
      "y": 15,
      "z": 2,
      "name": "Rock_Calcite"
    },
    {
      "x": -7,
      "y": 16,
      "z": 2,
      "name": "Rock_Calcite"
    },
    {
      "x": -7,
      "y": 17,
      "z": 2,
      "name": "Rock_Calcite"
    },
    {
      "x": -7,
      "y": 18,
      "z": 2,
      "name": "Rock_Calcite"
    },
    {
      "x": -7,
      "y": 19,
      "z": 2,
      "name": "Rock_Calcite"
    },
    {
      "x": -7,
      "y": 20,
      "z": 2,
      "name": "Rock_Calcite"
    },
    {
      "x": -7,
      "y": 21,
      "z": 2,
      "name": "Rock_Calcite"
    },
    {
      "x": -7,
      "y": 22,
      "z": 2,
      "name": "Rock_Calcite"
    },
    {
      "x": -7,
      "y": 23,
      "z": 2,
      "name": "Rock_Calcite"
    },
    {
      "x": -7,
      "y": 24,
      "z": 2,
      "name": "Rock_Calcite"
    },
    {
      "x": -7,
      "y": 25,
      "z": 2,
      "name": "Rock_Calcite"
    },
    {
      "x": -7,
      "y": 26,
      "z": 2,
      "name": "Rock_Calcite"
    },
    {
      "x": -7,
      "y": 27,
      "z": 2,
      "name": "Rock_Calcite"
    },
    {
      "x": -7,
      "y": 30,
      "z": 2,
      "name": "Rock_Calcite"
    },
    {
      "x": -7,
      "y": 31,
      "z": 2,
      "name": "Rock_Calcite"
    },
    {
      "x": -7,
      "y": 32,
      "z": 2,
      "name": "Rock_Calcite"
    },
    {
      "x": -7,
      "y": 33,
      "z": 2,
      "name": "Rock_Calcite"
    },
    {
      "x": -7,
      "y": 34,
      "z": 2,
      "name": "Rock_Calcite"
    },
    {
      "x": -7,
      "y": 35,
      "z": 2,
      "name": "Rock_Calcite"
    },
    {
      "x": -7,
      "y": 36,
      "z": 2,
      "name": "Rock_Calcite"
    },
    {
      "x": -7,
      "y": 37,
      "z": 2,
      "name": "Rock_Calcite"
    },
    {
      "x": -7,
      "y": 38,
      "z": 2,
      "name": "Rock_Calcite"
    },
    {
      "x": -7,
      "y": 39,
      "z": 2,
      "name": "Rock_Calcite"
    },
    {
      "x": -7,
      "y": 40,
      "z": 2,
      "name": "Rock_Calcite"
    },
    {
      "x": -7,
      "y": 41,
      "z": 2,
      "name": "Rock_Calcite"
    },
    {
      "x": -7,
      "y": 42,
      "z": 2,
      "name": "Rock_Calcite"
    },
    {
      "x": -7,
      "y": 43,
      "z": 2,
      "name": "Rock_Calcite"
    },
    {
      "x": -7,
      "y": 44,
      "z": 2,
      "name": "Rock_Calcite"
    },
    {
      "x": -7,
      "y": 45,
      "z": 2,
      "name": "Rock_Calcite"
    },
    {
      "x": -7,
      "y": 46,
      "z": 2,
      "name": "Rock_Calcite"
    },
    {
      "x": -7,
      "y": 47,
      "z": 2,
      "name": "Rock_Calcite"
    },
    {
      "x": -7,
      "y": 48,
      "z": 2,
      "name": "Rock_Marble"
    },
    {
      "x": -7,
      "y": 49,
      "z": 2,
      "name": "Rock_Marble"
    },
    {
      "x": -7,
      "y": 50,
      "z": 2,
      "name": "Rock_Marble"
    },
    {
      "x": -7,
      "y": 51,
      "z": 2,
      "name": "Rock_Calcite"
    },
    {
      "x": -7,
      "y": 52,
      "z": 2,
      "name": "Soil_Clay_Red"
    },
    {
      "x": -7,
      "y": 53,
      "z": 2,
      "name": "Soil_Grass_Wet"
    },
    {
      "x": -7,
      "y": 7,
      "z": 3,
      "name": "Rock_Calcite"
    },
    {
      "x": -7,
      "y": 8,
      "z": 3,
      "name": "Rock_Calcite"
    },
    {
      "x": -7,
      "y": 9,
      "z": 3,
      "name": "Rock_Calcite"
    },
    {
      "x": -7,
      "y": 10,
      "z": 3,
      "name": "Rock_Calcite"
    },
    {
      "x": -7,
      "y": 11,
      "z": 3,
      "name": "Rock_Calcite"
    },
    {
      "x": -7,
      "y": 12,
      "z": 3,
      "name": "Rock_Calcite"
    },
    {
      "x": -7,
      "y": 13,
      "z": 3,
      "name": "Rock_Calcite"
    },
    {
      "x": -7,
      "y": 14,
      "z": 3,
      "name": "Rock_Calcite"
    },
    {
      "x": -7,
      "y": 15,
      "z": 3,
      "name": "Rock_Calcite"
    },
    {
      "x": -7,
      "y": 16,
      "z": 3,
      "name": "Rock_Calcite"
    },
    {
      "x": -7,
      "y": 17,
      "z": 3,
      "name": "Rock_Calcite"
    },
    {
      "x": -7,
      "y": 18,
      "z": 3,
      "name": "Rock_Calcite"
    },
    {
      "x": -7,
      "y": 19,
      "z": 3,
      "name": "Rock_Calcite"
    },
    {
      "x": -7,
      "y": 20,
      "z": 3,
      "name": "Rock_Calcite"
    },
    {
      "x": -7,
      "y": 21,
      "z": 3,
      "name": "Rock_Calcite"
    },
    {
      "x": -7,
      "y": 22,
      "z": 3,
      "name": "Rock_Calcite"
    },
    {
      "x": -7,
      "y": 23,
      "z": 3,
      "name": "Rock_Calcite"
    },
    {
      "x": -7,
      "y": 24,
      "z": 3,
      "name": "Rock_Calcite"
    },
    {
      "x": -7,
      "y": 25,
      "z": 3,
      "name": "Rock_Calcite"
    },
    {
      "x": -7,
      "y": 26,
      "z": 3,
      "name": "Rock_Calcite"
    },
    {
      "x": -7,
      "y": 43,
      "z": 3,
      "name": "Rock_Calcite"
    },
    {
      "x": -7,
      "y": 44,
      "z": 3,
      "name": "Rock_Calcite"
    },
    {
      "x": -7,
      "y": 45,
      "z": 3,
      "name": "Rock_Calcite"
    },
    {
      "x": -7,
      "y": 46,
      "z": 3,
      "name": "Rock_Calcite"
    },
    {
      "x": -7,
      "y": 47,
      "z": 3,
      "name": "Rock_Calcite"
    },
    {
      "x": -7,
      "y": 48,
      "z": 3,
      "name": "Rock_Marble"
    },
    {
      "x": -7,
      "y": 49,
      "z": 3,
      "name": "Rock_Marble"
    },
    {
      "x": -7,
      "y": 50,
      "z": 3,
      "name": "Rock_Marble"
    },
    {
      "x": -7,
      "y": 51,
      "z": 3,
      "name": "Rock_Calcite"
    },
    {
      "x": -7,
      "y": 52,
      "z": 3,
      "name": "Soil_Clay_Red"
    },
    {
      "x": -7,
      "y": 53,
      "z": 3,
      "name": "Soil_Grass_Wet"
    },
    {
      "x": -7,
      "y": 14,
      "z": 4,
      "name": "Rock_Calcite"
    },
    {
      "x": -7,
      "y": 15,
      "z": 4,
      "name": "Rock_Calcite"
    },
    {
      "x": -7,
      "y": 16,
      "z": 4,
      "name": "Rock_Calcite"
    },
    {
      "x": -7,
      "y": 17,
      "z": 4,
      "name": "Rock_Calcite"
    },
    {
      "x": -7,
      "y": 18,
      "z": 4,
      "name": "Rock_Calcite"
    },
    {
      "x": -7,
      "y": 19,
      "z": 4,
      "name": "Rock_Calcite"
    },
    {
      "x": -7,
      "y": 20,
      "z": 4,
      "name": "Rock_Calcite"
    },
    {
      "x": -7,
      "y": 21,
      "z": 4,
      "name": "Rock_Calcite"
    },
    {
      "x": -7,
      "y": 22,
      "z": 4,
      "name": "Rock_Calcite"
    },
    {
      "x": -7,
      "y": 23,
      "z": 4,
      "name": "Rock_Calcite"
    },
    {
      "x": -7,
      "y": 24,
      "z": 4,
      "name": "Rock_Calcite"
    },
    {
      "x": -7,
      "y": 44,
      "z": 4,
      "name": "Plant_Bush_Hanging"
    },
    {
      "x": -7,
      "y": 45,
      "z": 4,
      "name": "Plant_Bush_Hanging"
    },
    {
      "x": -7,
      "y": 47,
      "z": 4,
      "name": "Plant_Bush_Hanging"
    },
    {
      "x": -7,
      "y": 48,
      "z": 4,
      "name": "Plant_Bush_Hanging"
    },
    {
      "x": -7,
      "y": 49,
      "z": 4,
      "name": "Plant_Bush_Hanging"
    },
    {
      "x": -7,
      "y": 50,
      "z": 4,
      "name": "Plant_Bush_Hanging"
    },
    {
      "x": -7,
      "y": 51,
      "z": 4,
      "name": "Plant_Bush_Hanging"
    },
    {
      "x": -7,
      "y": 52,
      "z": 4,
      "name": "Plant_Bush_Hanging"
    },
    {
      "x": -7,
      "y": 53,
      "z": 4,
      "name": "Plant_Bush_Hanging"
    },
    {
      "x": -7,
      "y": 16,
      "z": 5,
      "name": "Rock_Calcite"
    },
    {
      "x": -7,
      "y": 17,
      "z": 5,
      "name": "Rock_Calcite"
    },
    {
      "x": -7,
      "y": 18,
      "z": 5,
      "name": "Rock_Calcite"
    },
    {
      "x": -7,
      "y": 19,
      "z": 5,
      "name": "Rock_Calcite"
    },
    {
      "x": -7,
      "y": 20,
      "z": 5,
      "name": "Rock_Calcite"
    },
    {
      "x": -7,
      "y": 21,
      "z": 5,
      "name": "Rock_Calcite"
    },
    {
      "x": -7,
      "y": 22,
      "z": 5,
      "name": "Rock_Calcite"
    },
    {
      "x": -7,
      "y": 23,
      "z": 5,
      "name": "Rock_Calcite"
    },
    {
      "x": -7,
      "y": 49,
      "z": 5,
      "name": "Plant_Bush_Hanging"
    },
    {
      "x": -7,
      "y": 50,
      "z": 5,
      "name": "Plant_Bush_Hanging"
    },
    {
      "x": -6,
      "y": 57,
      "z": -9,
      "name": "Plant_Leaves_Wisteria_Wild"
    },
    {
      "x": -6,
      "y": 64,
      "z": -9,
      "name": "Plant_Leaves_Wisteria_Wild"
    },
    {
      "x": -6,
      "y": 65,
      "z": -9,
      "name": "Plant_Leaves_Wisteria_Wild"
    },
    {
      "x": -6,
      "y": 15,
      "z": -8,
      "name": "Rock_Calcite"
    },
    {
      "x": -6,
      "y": 16,
      "z": -8,
      "name": "Rock_Calcite"
    },
    {
      "x": -6,
      "y": 17,
      "z": -8,
      "name": "Rock_Calcite"
    },
    {
      "x": -6,
      "y": 18,
      "z": -8,
      "name": "Rock_Calcite"
    },
    {
      "x": -6,
      "y": 19,
      "z": -8,
      "name": "Rock_Calcite"
    },
    {
      "x": -6,
      "y": 57,
      "z": -8,
      "name": "Wood_Wisteria_Wild_Branch_Corner",
      "rotation": 3
    },
    {
      "x": -6,
      "y": 58,
      "z": -8,
      "name": "Plant_Leaves_Wisteria_Wild"
    },
    {
      "x": -6,
      "y": 13,
      "z": -7,
      "name": "Rock_Calcite"
    },
    {
      "x": -6,
      "y": 14,
      "z": -7,
      "name": "Rock_Calcite"
    },
    {
      "x": -6,
      "y": 15,
      "z": -7,
      "name": "Rock_Calcite"
    },
    {
      "x": -6,
      "y": 16,
      "z": -7,
      "name": "Rock_Calcite"
    },
    {
      "x": -6,
      "y": 17,
      "z": -7,
      "name": "Rock_Calcite"
    },
    {
      "x": -6,
      "y": 18,
      "z": -7,
      "name": "Rock_Calcite"
    },
    {
      "x": -6,
      "y": 19,
      "z": -7,
      "name": "Rock_Calcite"
    },
    {
      "x": -6,
      "y": 20,
      "z": -7,
      "name": "Rock_Calcite"
    },
    {
      "x": -6,
      "y": 21,
      "z": -7,
      "name": "Rock_Calcite"
    },
    {
      "x": -6,
      "y": 22,
      "z": -7,
      "name": "Rock_Calcite"
    },
    {
      "x": -6,
      "y": 11,
      "z": -6,
      "name": "Rock_Calcite"
    },
    {
      "x": -6,
      "y": 12,
      "z": -6,
      "name": "Rock_Calcite"
    },
    {
      "x": -6,
      "y": 13,
      "z": -6,
      "name": "Rock_Calcite"
    },
    {
      "x": -6,
      "y": 14,
      "z": -6,
      "name": "Rock_Calcite"
    },
    {
      "x": -6,
      "y": 15,
      "z": -6,
      "name": "Rock_Calcite"
    },
    {
      "x": -6,
      "y": 16,
      "z": -6,
      "name": "Rock_Calcite"
    },
    {
      "x": -6,
      "y": 17,
      "z": -6,
      "name": "Rock_Calcite"
    },
    {
      "x": -6,
      "y": 18,
      "z": -6,
      "name": "Rock_Calcite"
    },
    {
      "x": -6,
      "y": 19,
      "z": -6,
      "name": "Rock_Calcite"
    },
    {
      "x": -6,
      "y": 20,
      "z": -6,
      "name": "Rock_Calcite"
    },
    {
      "x": -6,
      "y": 21,
      "z": -6,
      "name": "Rock_Calcite"
    },
    {
      "x": -6,
      "y": 22,
      "z": -6,
      "name": "Rock_Calcite"
    },
    {
      "x": -6,
      "y": 23,
      "z": -6,
      "name": "Rock_Calcite"
    },
    {
      "x": -6,
      "y": 24,
      "z": -6,
      "name": "Rock_Calcite"
    },
    {
      "x": -6,
      "y": 25,
      "z": -6,
      "name": "Rock_Calcite"
    },
    {
      "x": -6,
      "y": 26,
      "z": -6,
      "name": "Rock_Calcite"
    },
    {
      "x": -6,
      "y": 9,
      "z": -5,
      "name": "Rock_Calcite"
    },
    {
      "x": -6,
      "y": 10,
      "z": -5,
      "name": "Rock_Calcite"
    },
    {
      "x": -6,
      "y": 11,
      "z": -5,
      "name": "Rock_Calcite"
    },
    {
      "x": -6,
      "y": 12,
      "z": -5,
      "name": "Rock_Calcite"
    },
    {
      "x": -6,
      "y": 13,
      "z": -5,
      "name": "Rock_Calcite"
    },
    {
      "x": -6,
      "y": 14,
      "z": -5,
      "name": "Rock_Calcite"
    },
    {
      "x": -6,
      "y": 15,
      "z": -5,
      "name": "Rock_Calcite"
    },
    {
      "x": -6,
      "y": 16,
      "z": -5,
      "name": "Rock_Calcite"
    },
    {
      "x": -6,
      "y": 17,
      "z": -5,
      "name": "Rock_Calcite"
    },
    {
      "x": -6,
      "y": 18,
      "z": -5,
      "name": "Rock_Calcite"
    },
    {
      "x": -6,
      "y": 19,
      "z": -5,
      "name": "Rock_Calcite"
    },
    {
      "x": -6,
      "y": 20,
      "z": -5,
      "name": "Rock_Calcite"
    },
    {
      "x": -6,
      "y": 21,
      "z": -5,
      "name": "Rock_Calcite"
    },
    {
      "x": -6,
      "y": 22,
      "z": -5,
      "name": "Rock_Calcite"
    },
    {
      "x": -6,
      "y": 23,
      "z": -5,
      "name": "Rock_Calcite"
    },
    {
      "x": -6,
      "y": 24,
      "z": -5,
      "name": "Rock_Calcite"
    },
    {
      "x": -6,
      "y": 25,
      "z": -5,
      "name": "Rock_Calcite"
    },
    {
      "x": -6,
      "y": 26,
      "z": -5,
      "name": "Rock_Calcite"
    },
    {
      "x": -6,
      "y": 27,
      "z": -5,
      "name": "Rock_Calcite"
    },
    {
      "x": -6,
      "y": 28,
      "z": -5,
      "name": "Rock_Calcite"
    },
    {
      "x": -6,
      "y": 29,
      "z": -5,
      "name": "Rock_Calcite"
    },
    {
      "x": -6,
      "y": 30,
      "z": -5,
      "name": "Rock_Calcite"
    },
    {
      "x": -6,
      "y": 31,
      "z": -5,
      "name": "Rock_Calcite"
    },
    {
      "x": -6,
      "y": 32,
      "z": -5,
      "name": "Rock_Calcite"
    },
    {
      "x": -6,
      "y": 33,
      "z": -5,
      "name": "Plant_Bush_Hanging"
    },
    {
      "x": -6,
      "y": 34,
      "z": -5,
      "name": "Plant_Bush_Hanging"
    },
    {
      "x": -6,
      "y": 36,
      "z": -5,
      "name": "Plant_Bush_Hanging"
    },
    {
      "x": -6,
      "y": 37,
      "z": -5,
      "name": "Plant_Bush_Hanging"
    },
    {
      "x": -6,
      "y": 38,
      "z": -5,
      "name": "Plant_Bush_Hanging"
    },
    {
      "x": -6,
      "y": 39,
      "z": -5,
      "name": "Plant_Bush_Hanging"
    },
    {
      "x": -6,
      "y": 45,
      "z": -5,
      "name": "Plant_Bush_Hanging"
    },
    {
      "x": -6,
      "y": 46,
      "z": -5,
      "name": "Plant_Bush_Hanging"
    },
    {
      "x": -6,
      "y": 47,
      "z": -5,
      "name": "Plant_Bush_Hanging"
    },
    {
      "x": -6,
      "y": 48,
      "z": -5,
      "name": "Plant_Bush_Hanging"
    },
    {
      "x": -6,
      "y": 49,
      "z": -5,
      "name": "Plant_Bush_Hanging"
    },
    {
      "x": -6,
      "y": 50,
      "z": -5,
      "name": "Plant_Bush_Hanging"
    },
    {
      "x": -6,
      "y": 51,
      "z": -5,
      "name": "Plant_Bush_Hanging"
    },
    {
      "x": -6,
      "y": 52,
      "z": -5,
      "name": "Plant_Bush_Hanging"
    },
    {
      "x": -6,
      "y": 8,
      "z": -4,
      "name": "Rock_Calcite"
    },
    {
      "x": -6,
      "y": 9,
      "z": -4,
      "name": "Rock_Calcite"
    },
    {
      "x": -6,
      "y": 10,
      "z": -4,
      "name": "Rock_Calcite"
    },
    {
      "x": -6,
      "y": 11,
      "z": -4,
      "name": "Rock_Calcite"
    },
    {
      "x": -6,
      "y": 12,
      "z": -4,
      "name": "Rock_Calcite"
    },
    {
      "x": -6,
      "y": 13,
      "z": -4,
      "name": "Rock_Calcite"
    },
    {
      "x": -6,
      "y": 14,
      "z": -4,
      "name": "Rock_Calcite"
    },
    {
      "x": -6,
      "y": 15,
      "z": -4,
      "name": "Rock_Calcite"
    },
    {
      "x": -6,
      "y": 16,
      "z": -4,
      "name": "Rock_Calcite"
    },
    {
      "x": -6,
      "y": 17,
      "z": -4,
      "name": "Rock_Calcite"
    },
    {
      "x": -6,
      "y": 18,
      "z": -4,
      "name": "Rock_Calcite"
    },
    {
      "x": -6,
      "y": 19,
      "z": -4,
      "name": "Rock_Calcite"
    },
    {
      "x": -6,
      "y": 20,
      "z": -4,
      "name": "Rock_Calcite"
    },
    {
      "x": -6,
      "y": 21,
      "z": -4,
      "name": "Rock_Calcite"
    },
    {
      "x": -6,
      "y": 22,
      "z": -4,
      "name": "Rock_Calcite"
    },
    {
      "x": -6,
      "y": 23,
      "z": -4,
      "name": "Rock_Calcite"
    },
    {
      "x": -6,
      "y": 24,
      "z": -4,
      "name": "Rock_Calcite"
    },
    {
      "x": -6,
      "y": 25,
      "z": -4,
      "name": "Rock_Calcite"
    },
    {
      "x": -6,
      "y": 26,
      "z": -4,
      "name": "Rock_Calcite"
    },
    {
      "x": -6,
      "y": 27,
      "z": -4,
      "name": "Rock_Calcite"
    },
    {
      "x": -6,
      "y": 28,
      "z": -4,
      "name": "Rock_Calcite"
    },
    {
      "x": -6,
      "y": 29,
      "z": -4,
      "name": "Rock_Calcite"
    },
    {
      "x": -6,
      "y": 30,
      "z": -4,
      "name": "Rock_Calcite"
    },
    {
      "x": -6,
      "y": 31,
      "z": -4,
      "name": "Rock_Calcite"
    },
    {
      "x": -6,
      "y": 32,
      "z": -4,
      "name": "Rock_Calcite"
    },
    {
      "x": -6,
      "y": 33,
      "z": -4,
      "name": "Rock_Calcite"
    },
    {
      "x": -6,
      "y": 34,
      "z": -4,
      "name": "Rock_Calcite"
    },
    {
      "x": -6,
      "y": 35,
      "z": -4,
      "name": "Rock_Calcite"
    },
    {
      "x": -6,
      "y": 36,
      "z": -4,
      "name": "Plant_Bush_Hanging"
    },
    {
      "x": -6,
      "y": 37,
      "z": -4,
      "name": "Plant_Bush_Hanging"
    },
    {
      "x": -6,
      "y": 38,
      "z": -4,
      "name": "Plant_Bush_Hanging"
    },
    {
      "x": -6,
      "y": 39,
      "z": -4,
      "name": "Plant_Bush_Hanging"
    },
    {
      "x": -6,
      "y": 40,
      "z": -4,
      "name": "Plant_Bush_Hanging"
    },
    {
      "x": -6,
      "y": 41,
      "z": -4,
      "name": "Plant_Bush_Hanging"
    },
    {
      "x": -6,
      "y": 42,
      "z": -4,
      "name": "Plant_Bush_Hanging"
    },
    {
      "x": -6,
      "y": 43,
      "z": -4,
      "name": "Plant_Bush_Hanging"
    },
    {
      "x": -6,
      "y": 44,
      "z": -4,
      "name": "Plant_Bush_Hanging"
    },
    {
      "x": -6,
      "y": 45,
      "z": -4,
      "name": "Plant_Bush_Hanging"
    },
    {
      "x": -6,
      "y": 46,
      "z": -4,
      "name": "Plant_Bush_Hanging"
    },
    {
      "x": -6,
      "y": 47,
      "z": -4,
      "name": "Plant_Bush_Hanging"
    },
    {
      "x": -6,
      "y": 48,
      "z": -4,
      "name": "Plant_Bush_Hanging"
    },
    {
      "x": -6,
      "y": 49,
      "z": -4,
      "name": "Plant_Bush_Hanging"
    },
    {
      "x": -6,
      "y": 50,
      "z": -4,
      "name": "Plant_Bush_Hanging"
    },
    {
      "x": -6,
      "y": 51,
      "z": -4,
      "name": "Plant_Bush_Hanging"
    },
    {
      "x": -6,
      "y": 52,
      "z": -4,
      "name": "Plant_Bush_Hanging"
    },
    {
      "x": -6,
      "y": 53,
      "z": -4,
      "name": "Plant_Bush_Hanging"
    },
    {
      "x": -6,
      "y": 54,
      "z": -4,
      "name": "Plant_Bush_Hanging"
    },
    {
      "x": -6,
      "y": 8,
      "z": -3,
      "name": "Rock_Calcite"
    },
    {
      "x": -6,
      "y": 9,
      "z": -3,
      "name": "Rock_Calcite"
    },
    {
      "x": -6,
      "y": 10,
      "z": -3,
      "name": "Rock_Calcite"
    },
    {
      "x": -6,
      "y": 11,
      "z": -3,
      "name": "Rock_Calcite"
    },
    {
      "x": -6,
      "y": 12,
      "z": -3,
      "name": "Rock_Calcite"
    },
    {
      "x": -6,
      "y": 13,
      "z": -3,
      "name": "Rock_Calcite"
    },
    {
      "x": -6,
      "y": 14,
      "z": -3,
      "name": "Rock_Calcite"
    },
    {
      "x": -6,
      "y": 15,
      "z": -3,
      "name": "Rock_Calcite"
    },
    {
      "x": -6,
      "y": 16,
      "z": -3,
      "name": "Rock_Calcite"
    },
    {
      "x": -6,
      "y": 17,
      "z": -3,
      "name": "Rock_Calcite"
    },
    {
      "x": -6,
      "y": 18,
      "z": -3,
      "name": "Rock_Calcite"
    },
    {
      "x": -6,
      "y": 19,
      "z": -3,
      "name": "Rock_Calcite"
    },
    {
      "x": -6,
      "y": 20,
      "z": -3,
      "name": "Rock_Calcite"
    },
    {
      "x": -6,
      "y": 21,
      "z": -3,
      "name": "Rock_Calcite"
    },
    {
      "x": -6,
      "y": 22,
      "z": -3,
      "name": "Rock_Calcite"
    },
    {
      "x": -6,
      "y": 23,
      "z": -3,
      "name": "Rock_Calcite"
    },
    {
      "x": -6,
      "y": 24,
      "z": -3,
      "name": "Rock_Calcite"
    },
    {
      "x": -6,
      "y": 25,
      "z": -3,
      "name": "Rock_Calcite"
    },
    {
      "x": -6,
      "y": 26,
      "z": -3,
      "name": "Rock_Calcite"
    },
    {
      "x": -6,
      "y": 27,
      "z": -3,
      "name": "Rock_Calcite"
    },
    {
      "x": -6,
      "y": 28,
      "z": -3,
      "name": "Rock_Calcite"
    },
    {
      "x": -6,
      "y": 29,
      "z": -3,
      "name": "Rock_Calcite"
    },
    {
      "x": -6,
      "y": 30,
      "z": -3,
      "name": "Rock_Calcite"
    },
    {
      "x": -6,
      "y": 31,
      "z": -3,
      "name": "Rock_Calcite"
    },
    {
      "x": -6,
      "y": 32,
      "z": -3,
      "name": "Rock_Calcite"
    },
    {
      "x": -6,
      "y": 33,
      "z": -3,
      "name": "Rock_Calcite"
    },
    {
      "x": -6,
      "y": 34,
      "z": -3,
      "name": "Rock_Calcite"
    },
    {
      "x": -6,
      "y": 35,
      "z": -3,
      "name": "Rock_Calcite"
    },
    {
      "x": -6,
      "y": 36,
      "z": -3,
      "name": "Rock_Calcite"
    },
    {
      "x": -6,
      "y": 37,
      "z": -3,
      "name": "Rock_Calcite"
    },
    {
      "x": -6,
      "y": 38,
      "z": -3,
      "name": "Rock_Calcite"
    },
    {
      "x": -6,
      "y": 39,
      "z": -3,
      "name": "Rock_Calcite"
    },
    {
      "x": -6,
      "y": 40,
      "z": -3,
      "name": "Rock_Calcite"
    },
    {
      "x": -6,
      "y": 41,
      "z": -3,
      "name": "Rock_Calcite"
    },
    {
      "x": -6,
      "y": 42,
      "z": -3,
      "name": "Rock_Calcite"
    },
    {
      "x": -6,
      "y": 43,
      "z": -3,
      "name": "Rock_Calcite"
    },
    {
      "x": -6,
      "y": 44,
      "z": -3,
      "name": "Rock_Calcite"
    },
    {
      "x": -6,
      "y": 45,
      "z": -3,
      "name": "Rock_Calcite"
    },
    {
      "x": -6,
      "y": 46,
      "z": -3,
      "name": "Rock_Calcite"
    },
    {
      "x": -6,
      "y": 47,
      "z": -3,
      "name": "Rock_Calcite"
    },
    {
      "x": -6,
      "y": 48,
      "z": -3,
      "name": "Rock_Marble"
    },
    {
      "x": -6,
      "y": 49,
      "z": -3,
      "name": "Rock_Marble"
    },
    {
      "x": -6,
      "y": 50,
      "z": -3,
      "name": "Rock_Marble"
    },
    {
      "x": -6,
      "y": 51,
      "z": -3,
      "name": "Rock_Calcite"
    },
    {
      "x": -6,
      "y": 52,
      "z": -3,
      "name": "Rock_Calcite"
    },
    {
      "x": -6,
      "y": 53,
      "z": -3,
      "name": "Rock_Marble"
    },
    {
      "x": -6,
      "y": 54,
      "z": -3,
      "name": "Rock_Marble"
    },
    {
      "x": -6,
      "y": 55,
      "z": -3,
      "name": "Rock_Marble"
    },
    {
      "x": -6,
      "y": 56,
      "z": -3,
      "name": "Rock_Marble"
    },
    {
      "x": -6,
      "y": 57,
      "z": -3,
      "name": "Rock_Marble"
    },
    {
      "x": -6,
      "y": 58,
      "z": -3,
      "name": "Soil_Clay_Red"
    },
    {
      "x": -6,
      "y": 59,
      "z": -3,
      "name": "Soil_Grass_Wet"
    },
    {
      "x": -6,
      "y": 60,
      "z": -3,
      "name": "Plant_Bush_Lush"
    },
    {
      "x": -6,
      "y": 61,
      "z": -3,
      "name": "Plant_Bush_Hanging"
    },
    {
      "x": -6,
      "y": 62,
      "z": -3,
      "name": "Plant_Bush_Hanging"
    },
    {
      "x": -6,
      "y": 63,
      "z": -3,
      "name": "Plant_Bush_Hanging"
    },
    {
      "x": -6,
      "y": 64,
      "z": -3,
      "name": "Plant_Bush_Hanging"
    },
    {
      "x": -6,
      "y": 65,
      "z": -3,
      "name": "Plant_Bush_Hanging"
    },
    {
      "x": -6,
      "y": 8,
      "z": -2,
      "name": "Rock_Calcite"
    },
    {
      "x": -6,
      "y": 9,
      "z": -2,
      "name": "Rock_Calcite"
    },
    {
      "x": -6,
      "y": 10,
      "z": -2,
      "name": "Rock_Calcite"
    },
    {
      "x": -6,
      "y": 11,
      "z": -2,
      "name": "Rock_Calcite"
    },
    {
      "x": -6,
      "y": 12,
      "z": -2,
      "name": "Rock_Calcite"
    },
    {
      "x": -6,
      "y": 13,
      "z": -2,
      "name": "Rock_Calcite"
    },
    {
      "x": -6,
      "y": 14,
      "z": -2,
      "name": "Rock_Calcite"
    },
    {
      "x": -6,
      "y": 15,
      "z": -2,
      "name": "Rock_Calcite"
    },
    {
      "x": -6,
      "y": 16,
      "z": -2,
      "name": "Rock_Calcite"
    },
    {
      "x": -6,
      "y": 17,
      "z": -2,
      "name": "Rock_Calcite"
    },
    {
      "x": -6,
      "y": 18,
      "z": -2,
      "name": "Rock_Calcite"
    },
    {
      "x": -6,
      "y": 19,
      "z": -2,
      "name": "Rock_Calcite"
    },
    {
      "x": -6,
      "y": 20,
      "z": -2,
      "name": "Rock_Calcite"
    },
    {
      "x": -6,
      "y": 21,
      "z": -2,
      "name": "Rock_Calcite"
    },
    {
      "x": -6,
      "y": 22,
      "z": -2,
      "name": "Rock_Calcite"
    },
    {
      "x": -6,
      "y": 23,
      "z": -2,
      "name": "Rock_Calcite"
    },
    {
      "x": -6,
      "y": 24,
      "z": -2,
      "name": "Rock_Calcite"
    },
    {
      "x": -6,
      "y": 25,
      "z": -2,
      "name": "Rock_Calcite"
    },
    {
      "x": -6,
      "y": 26,
      "z": -2,
      "name": "Rock_Calcite"
    },
    {
      "x": -6,
      "y": 27,
      "z": -2,
      "name": "Rock_Calcite"
    },
    {
      "x": -6,
      "y": 28,
      "z": -2,
      "name": "Rock_Calcite"
    },
    {
      "x": -6,
      "y": 29,
      "z": -2,
      "name": "Rock_Calcite"
    },
    {
      "x": -6,
      "y": 30,
      "z": -2,
      "name": "Rock_Calcite"
    },
    {
      "x": -6,
      "y": 31,
      "z": -2,
      "name": "Rock_Calcite"
    },
    {
      "x": -6,
      "y": 32,
      "z": -2,
      "name": "Rock_Calcite"
    },
    {
      "x": -6,
      "y": 33,
      "z": -2,
      "name": "Rock_Calcite"
    },
    {
      "x": -6,
      "y": 34,
      "z": -2,
      "name": "Rock_Calcite"
    },
    {
      "x": -6,
      "y": 35,
      "z": -2,
      "name": "Rock_Calcite"
    },
    {
      "x": -6,
      "y": 36,
      "z": -2,
      "name": "Rock_Calcite"
    },
    {
      "x": -6,
      "y": 37,
      "z": -2,
      "name": "Rock_Calcite"
    },
    {
      "x": -6,
      "y": 38,
      "z": -2,
      "name": "Rock_Calcite"
    },
    {
      "x": -6,
      "y": 39,
      "z": -2,
      "name": "Rock_Calcite"
    },
    {
      "x": -6,
      "y": 40,
      "z": -2,
      "name": "Rock_Calcite"
    },
    {
      "x": -6,
      "y": 41,
      "z": -2,
      "name": "Rock_Calcite"
    },
    {
      "x": -6,
      "y": 42,
      "z": -2,
      "name": "Rock_Calcite"
    },
    {
      "x": -6,
      "y": 43,
      "z": -2,
      "name": "Rock_Calcite"
    },
    {
      "x": -6,
      "y": 44,
      "z": -2,
      "name": "Rock_Calcite"
    },
    {
      "x": -6,
      "y": 45,
      "z": -2,
      "name": "Rock_Calcite"
    },
    {
      "x": -6,
      "y": 46,
      "z": -2,
      "name": "Rock_Calcite"
    },
    {
      "x": -6,
      "y": 47,
      "z": -2,
      "name": "Rock_Calcite"
    },
    {
      "x": -6,
      "y": 48,
      "z": -2,
      "name": "Rock_Marble"
    },
    {
      "x": -6,
      "y": 49,
      "z": -2,
      "name": "Rock_Marble"
    },
    {
      "x": -6,
      "y": 50,
      "z": -2,
      "name": "Rock_Marble"
    },
    {
      "x": -6,
      "y": 51,
      "z": -2,
      "name": "Rock_Calcite"
    },
    {
      "x": -6,
      "y": 52,
      "z": -2,
      "name": "Plant_Bush_Hanging"
    },
    {
      "x": -6,
      "y": 53,
      "z": -2,
      "name": "Plant_Bush_Hanging"
    },
    {
      "x": -6,
      "y": 54,
      "z": -2,
      "name": "Plant_Bush_Hanging"
    },
    {
      "x": -6,
      "y": 55,
      "z": -2,
      "name": "Plant_Bush_Hanging"
    },
    {
      "x": -6,
      "y": 56,
      "z": -2,
      "name": "Plant_Bush_Hanging"
    },
    {
      "x": -6,
      "y": 57,
      "z": -2,
      "name": "Plant_Bush_Hanging"
    },
    {
      "x": -6,
      "y": 58,
      "z": -2,
      "name": "Plant_Bush_Hanging"
    },
    {
      "x": -6,
      "y": 59,
      "z": -2,
      "name": "Plant_Bush_Hanging"
    },
    {
      "x": -6,
      "y": 60,
      "z": -2,
      "name": "Plant_Bush_Hanging"
    },
    {
      "x": -6,
      "y": 61,
      "z": -2,
      "name": "Plant_Bush_Hanging"
    },
    {
      "x": -6,
      "y": 62,
      "z": -2,
      "name": "Plant_Bush_Hanging"
    },
    {
      "x": -6,
      "y": 63,
      "z": -2,
      "name": "Plant_Bush_Hanging"
    },
    {
      "x": -6,
      "y": 64,
      "z": -2,
      "name": "Plant_Bush_Hanging"
    },
    {
      "x": -6,
      "y": 65,
      "z": -2,
      "name": "Plant_Bush_Hanging"
    },
    {
      "x": -6,
      "y": 66,
      "z": -2,
      "name": "Plant_Bush_Hanging"
    },
    {
      "x": -6,
      "y": 8,
      "z": -1,
      "name": "Rock_Calcite"
    },
    {
      "x": -6,
      "y": 9,
      "z": -1,
      "name": "Rock_Calcite"
    },
    {
      "x": -6,
      "y": 10,
      "z": -1,
      "name": "Rock_Calcite"
    },
    {
      "x": -6,
      "y": 11,
      "z": -1,
      "name": "Rock_Calcite"
    },
    {
      "x": -6,
      "y": 12,
      "z": -1,
      "name": "Rock_Calcite"
    },
    {
      "x": -6,
      "y": 13,
      "z": -1,
      "name": "Rock_Calcite"
    },
    {
      "x": -6,
      "y": 14,
      "z": -1,
      "name": "Rock_Calcite"
    },
    {
      "x": -6,
      "y": 15,
      "z": -1,
      "name": "Rock_Calcite"
    },
    {
      "x": -6,
      "y": 16,
      "z": -1,
      "name": "Rock_Calcite"
    },
    {
      "x": -6,
      "y": 17,
      "z": -1,
      "name": "Rock_Calcite"
    },
    {
      "x": -6,
      "y": 18,
      "z": -1,
      "name": "Rock_Calcite"
    },
    {
      "x": -6,
      "y": 19,
      "z": -1,
      "name": "Rock_Calcite"
    },
    {
      "x": -6,
      "y": 20,
      "z": -1,
      "name": "Rock_Calcite"
    },
    {
      "x": -6,
      "y": 21,
      "z": -1,
      "name": "Rock_Calcite"
    },
    {
      "x": -6,
      "y": 22,
      "z": -1,
      "name": "Rock_Calcite"
    },
    {
      "x": -6,
      "y": 23,
      "z": -1,
      "name": "Rock_Calcite"
    },
    {
      "x": -6,
      "y": 24,
      "z": -1,
      "name": "Rock_Calcite"
    },
    {
      "x": -6,
      "y": 25,
      "z": -1,
      "name": "Rock_Calcite"
    },
    {
      "x": -6,
      "y": 26,
      "z": -1,
      "name": "Rock_Calcite"
    },
    {
      "x": -6,
      "y": 27,
      "z": -1,
      "name": "Rock_Calcite"
    },
    {
      "x": -6,
      "y": 28,
      "z": -1,
      "name": "Rock_Calcite"
    },
    {
      "x": -6,
      "y": 29,
      "z": -1,
      "name": "Rock_Calcite"
    },
    {
      "x": -6,
      "y": 30,
      "z": -1,
      "name": "Rock_Calcite"
    },
    {
      "x": -6,
      "y": 31,
      "z": -1,
      "name": "Rock_Calcite"
    },
    {
      "x": -6,
      "y": 32,
      "z": -1,
      "name": "Rock_Calcite"
    },
    {
      "x": -6,
      "y": 33,
      "z": -1,
      "name": "Rock_Calcite"
    },
    {
      "x": -6,
      "y": 34,
      "z": -1,
      "name": "Rock_Calcite"
    },
    {
      "x": -6,
      "y": 35,
      "z": -1,
      "name": "Rock_Calcite"
    },
    {
      "x": -6,
      "y": 36,
      "z": -1,
      "name": "Rock_Calcite"
    },
    {
      "x": -6,
      "y": 37,
      "z": -1,
      "name": "Rock_Calcite"
    },
    {
      "x": -6,
      "y": 38,
      "z": -1,
      "name": "Rock_Calcite"
    },
    {
      "x": -6,
      "y": 39,
      "z": -1,
      "name": "Rock_Calcite"
    },
    {
      "x": -6,
      "y": 40,
      "z": -1,
      "name": "Rock_Calcite"
    },
    {
      "x": -6,
      "y": 41,
      "z": -1,
      "name": "Rock_Calcite"
    },
    {
      "x": -6,
      "y": 42,
      "z": -1,
      "name": "Rock_Calcite"
    },
    {
      "x": -6,
      "y": 43,
      "z": -1,
      "name": "Rock_Calcite"
    },
    {
      "x": -6,
      "y": 44,
      "z": -1,
      "name": "Rock_Calcite"
    },
    {
      "x": -6,
      "y": 45,
      "z": -1,
      "name": "Rock_Calcite"
    },
    {
      "x": -6,
      "y": 46,
      "z": -1,
      "name": "Rock_Calcite"
    },
    {
      "x": -6,
      "y": 47,
      "z": -1,
      "name": "Rock_Calcite"
    },
    {
      "x": -6,
      "y": 48,
      "z": -1,
      "name": "Rock_Marble"
    },
    {
      "x": -6,
      "y": 49,
      "z": -1,
      "name": "Rock_Marble"
    },
    {
      "x": -6,
      "y": 50,
      "z": -1,
      "name": "Rock_Marble"
    },
    {
      "x": -6,
      "y": 51,
      "z": -1,
      "name": "Rock_Calcite"
    },
    {
      "x": -6,
      "y": 52,
      "z": -1,
      "name": "Rock_Calcite"
    },
    {
      "x": -6,
      "y": 53,
      "z": -1,
      "name": "Rock_Marble"
    },
    {
      "x": -6,
      "y": 54,
      "z": -1,
      "name": "Soil_Clay_Red"
    },
    {
      "x": -6,
      "y": 55,
      "z": -1,
      "name": "Soil_Grass_Wet"
    },
    {
      "x": -6,
      "y": 58,
      "z": -1,
      "name": "Plant_Bush_Hanging"
    },
    {
      "x": -6,
      "y": 59,
      "z": -1,
      "name": "Plant_Bush_Hanging"
    },
    {
      "x": -6,
      "y": 60,
      "z": -1,
      "name": "Plant_Bush_Hanging"
    },
    {
      "x": -6,
      "y": 61,
      "z": -1,
      "name": "Plant_Bush_Hanging"
    },
    {
      "x": -6,
      "y": 63,
      "z": -1,
      "name": "Plant_Bush_Hanging"
    },
    {
      "x": -6,
      "y": 65,
      "z": -1,
      "name": "Plant_Bush_Hanging"
    },
    {
      "x": -6,
      "y": 66,
      "z": -1,
      "name": "Plant_Bush_Hanging"
    },
    {
      "x": -6,
      "y": 7,
      "z": 0,
      "name": "Rock_Calcite"
    },
    {
      "x": -6,
      "y": 8,
      "z": 0,
      "name": "Rock_Calcite"
    },
    {
      "x": -6,
      "y": 9,
      "z": 0,
      "name": "Rock_Calcite"
    },
    {
      "x": -6,
      "y": 10,
      "z": 0,
      "name": "Rock_Calcite"
    },
    {
      "x": -6,
      "y": 11,
      "z": 0,
      "name": "Rock_Calcite"
    },
    {
      "x": -6,
      "y": 12,
      "z": 0,
      "name": "Rock_Calcite"
    },
    {
      "x": -6,
      "y": 13,
      "z": 0,
      "name": "Rock_Calcite"
    },
    {
      "x": -6,
      "y": 14,
      "z": 0,
      "name": "Rock_Calcite"
    },
    {
      "x": -6,
      "y": 15,
      "z": 0,
      "name": "Rock_Calcite"
    },
    {
      "x": -6,
      "y": 16,
      "z": 0,
      "name": "Rock_Calcite"
    },
    {
      "x": -6,
      "y": 17,
      "z": 0,
      "name": "Rock_Calcite"
    },
    {
      "x": -6,
      "y": 18,
      "z": 0,
      "name": "Rock_Calcite"
    },
    {
      "x": -6,
      "y": 19,
      "z": 0,
      "name": "Rock_Calcite"
    },
    {
      "x": -6,
      "y": 20,
      "z": 0,
      "name": "Rock_Calcite"
    },
    {
      "x": -6,
      "y": 21,
      "z": 0,
      "name": "Rock_Calcite"
    },
    {
      "x": -6,
      "y": 22,
      "z": 0,
      "name": "Rock_Calcite"
    },
    {
      "x": -6,
      "y": 23,
      "z": 0,
      "name": "Rock_Calcite"
    },
    {
      "x": -6,
      "y": 24,
      "z": 0,
      "name": "Rock_Calcite"
    },
    {
      "x": -6,
      "y": 25,
      "z": 0,
      "name": "Rock_Calcite"
    },
    {
      "x": -6,
      "y": 26,
      "z": 0,
      "name": "Rock_Calcite"
    },
    {
      "x": -6,
      "y": 27,
      "z": 0,
      "name": "Rock_Calcite"
    },
    {
      "x": -6,
      "y": 28,
      "z": 0,
      "name": "Rock_Calcite"
    },
    {
      "x": -6,
      "y": 29,
      "z": 0,
      "name": "Rock_Calcite"
    },
    {
      "x": -6,
      "y": 30,
      "z": 0,
      "name": "Rock_Calcite"
    },
    {
      "x": -6,
      "y": 31,
      "z": 0,
      "name": "Rock_Calcite"
    },
    {
      "x": -6,
      "y": 32,
      "z": 0,
      "name": "Rock_Calcite"
    },
    {
      "x": -6,
      "y": 33,
      "z": 0,
      "name": "Rock_Calcite"
    },
    {
      "x": -6,
      "y": 34,
      "z": 0,
      "name": "Rock_Calcite"
    },
    {
      "x": -6,
      "y": 35,
      "z": 0,
      "name": "Rock_Calcite"
    },
    {
      "x": -6,
      "y": 36,
      "z": 0,
      "name": "Rock_Calcite"
    },
    {
      "x": -6,
      "y": 37,
      "z": 0,
      "name": "Rock_Calcite"
    },
    {
      "x": -6,
      "y": 38,
      "z": 0,
      "name": "Rock_Calcite"
    },
    {
      "x": -6,
      "y": 39,
      "z": 0,
      "name": "Rock_Calcite"
    },
    {
      "x": -6,
      "y": 40,
      "z": 0,
      "name": "Rock_Calcite"
    },
    {
      "x": -6,
      "y": 41,
      "z": 0,
      "name": "Rock_Calcite"
    },
    {
      "x": -6,
      "y": 42,
      "z": 0,
      "name": "Rock_Calcite"
    },
    {
      "x": -6,
      "y": 43,
      "z": 0,
      "name": "Rock_Calcite"
    },
    {
      "x": -6,
      "y": 44,
      "z": 0,
      "name": "Rock_Calcite"
    },
    {
      "x": -6,
      "y": 45,
      "z": 0,
      "name": "Rock_Calcite"
    },
    {
      "x": -6,
      "y": 46,
      "z": 0,
      "name": "Rock_Calcite"
    },
    {
      "x": -6,
      "y": 47,
      "z": 0,
      "name": "Rock_Calcite"
    },
    {
      "x": -6,
      "y": 48,
      "z": 0,
      "name": "Rock_Marble"
    },
    {
      "x": -6,
      "y": 49,
      "z": 0,
      "name": "Rock_Marble"
    },
    {
      "x": -6,
      "y": 50,
      "z": 0,
      "name": "Rock_Marble"
    },
    {
      "x": -6,
      "y": 51,
      "z": 0,
      "name": "Rock_Calcite"
    },
    {
      "x": -6,
      "y": 52,
      "z": 0,
      "name": "Rock_Calcite"
    },
    {
      "x": -6,
      "y": 53,
      "z": 0,
      "name": "Rock_Marble"
    },
    {
      "x": -6,
      "y": 54,
      "z": 0,
      "name": "Soil_Clay_Red"
    },
    {
      "x": -6,
      "y": 55,
      "z": 0,
      "name": "Soil_Grass_Wet"
    },
    {
      "x": -6,
      "y": 6,
      "z": 1,
      "name": "Rock_Calcite"
    },
    {
      "x": -6,
      "y": 7,
      "z": 1,
      "name": "Rock_Calcite"
    },
    {
      "x": -6,
      "y": 8,
      "z": 1,
      "name": "Rock_Calcite"
    },
    {
      "x": -6,
      "y": 9,
      "z": 1,
      "name": "Rock_Calcite"
    },
    {
      "x": -6,
      "y": 10,
      "z": 1,
      "name": "Rock_Calcite"
    },
    {
      "x": -6,
      "y": 11,
      "z": 1,
      "name": "Rock_Calcite"
    },
    {
      "x": -6,
      "y": 12,
      "z": 1,
      "name": "Rock_Calcite"
    },
    {
      "x": -6,
      "y": 13,
      "z": 1,
      "name": "Rock_Calcite"
    },
    {
      "x": -6,
      "y": 14,
      "z": 1,
      "name": "Rock_Calcite"
    },
    {
      "x": -6,
      "y": 15,
      "z": 1,
      "name": "Rock_Calcite"
    },
    {
      "x": -6,
      "y": 16,
      "z": 1,
      "name": "Rock_Calcite"
    },
    {
      "x": -6,
      "y": 17,
      "z": 1,
      "name": "Rock_Calcite"
    },
    {
      "x": -6,
      "y": 18,
      "z": 1,
      "name": "Rock_Calcite"
    },
    {
      "x": -6,
      "y": 19,
      "z": 1,
      "name": "Rock_Calcite"
    },
    {
      "x": -6,
      "y": 20,
      "z": 1,
      "name": "Rock_Calcite"
    },
    {
      "x": -6,
      "y": 21,
      "z": 1,
      "name": "Rock_Calcite"
    },
    {
      "x": -6,
      "y": 22,
      "z": 1,
      "name": "Rock_Calcite"
    },
    {
      "x": -6,
      "y": 23,
      "z": 1,
      "name": "Rock_Calcite"
    },
    {
      "x": -6,
      "y": 24,
      "z": 1,
      "name": "Rock_Calcite"
    },
    {
      "x": -6,
      "y": 25,
      "z": 1,
      "name": "Rock_Calcite"
    },
    {
      "x": -6,
      "y": 26,
      "z": 1,
      "name": "Rock_Calcite"
    },
    {
      "x": -6,
      "y": 27,
      "z": 1,
      "name": "Rock_Calcite"
    },
    {
      "x": -6,
      "y": 28,
      "z": 1,
      "name": "Rock_Calcite"
    },
    {
      "x": -6,
      "y": 29,
      "z": 1,
      "name": "Rock_Calcite"
    },
    {
      "x": -6,
      "y": 30,
      "z": 1,
      "name": "Rock_Calcite"
    },
    {
      "x": -6,
      "y": 31,
      "z": 1,
      "name": "Rock_Calcite"
    },
    {
      "x": -6,
      "y": 32,
      "z": 1,
      "name": "Rock_Calcite"
    },
    {
      "x": -6,
      "y": 33,
      "z": 1,
      "name": "Rock_Calcite"
    },
    {
      "x": -6,
      "y": 34,
      "z": 1,
      "name": "Rock_Calcite"
    },
    {
      "x": -6,
      "y": 35,
      "z": 1,
      "name": "Rock_Calcite"
    },
    {
      "x": -6,
      "y": 36,
      "z": 1,
      "name": "Rock_Calcite"
    },
    {
      "x": -6,
      "y": 37,
      "z": 1,
      "name": "Rock_Calcite"
    },
    {
      "x": -6,
      "y": 38,
      "z": 1,
      "name": "Rock_Calcite"
    },
    {
      "x": -6,
      "y": 39,
      "z": 1,
      "name": "Rock_Calcite"
    },
    {
      "x": -6,
      "y": 40,
      "z": 1,
      "name": "Rock_Calcite"
    },
    {
      "x": -6,
      "y": 41,
      "z": 1,
      "name": "Rock_Calcite"
    },
    {
      "x": -6,
      "y": 42,
      "z": 1,
      "name": "Rock_Calcite"
    },
    {
      "x": -6,
      "y": 43,
      "z": 1,
      "name": "Rock_Calcite"
    },
    {
      "x": -6,
      "y": 44,
      "z": 1,
      "name": "Rock_Calcite"
    },
    {
      "x": -6,
      "y": 45,
      "z": 1,
      "name": "Rock_Calcite"
    },
    {
      "x": -6,
      "y": 46,
      "z": 1,
      "name": "Rock_Calcite"
    },
    {
      "x": -6,
      "y": 47,
      "z": 1,
      "name": "Rock_Calcite"
    },
    {
      "x": -6,
      "y": 48,
      "z": 1,
      "name": "Rock_Marble"
    },
    {
      "x": -6,
      "y": 49,
      "z": 1,
      "name": "Rock_Marble"
    },
    {
      "x": -6,
      "y": 50,
      "z": 1,
      "name": "Rock_Marble"
    },
    {
      "x": -6,
      "y": 51,
      "z": 1,
      "name": "Rock_Calcite"
    },
    {
      "x": -6,
      "y": 52,
      "z": 1,
      "name": "Rock_Calcite"
    },
    {
      "x": -6,
      "y": 53,
      "z": 1,
      "name": "Soil_Clay_Red"
    },
    {
      "x": -6,
      "y": 54,
      "z": 1,
      "name": "Soil_Grass_Wet"
    },
    {
      "x": -6,
      "y": 55,
      "z": 1,
      "name": "Plant_Bush_Lush"
    },
    {
      "x": -6,
      "y": 6,
      "z": 2,
      "name": "Rock_Calcite"
    },
    {
      "x": -6,
      "y": 7,
      "z": 2,
      "name": "Rock_Calcite"
    },
    {
      "x": -6,
      "y": 8,
      "z": 2,
      "name": "Rock_Calcite"
    },
    {
      "x": -6,
      "y": 9,
      "z": 2,
      "name": "Rock_Calcite"
    },
    {
      "x": -6,
      "y": 10,
      "z": 2,
      "name": "Rock_Calcite"
    },
    {
      "x": -6,
      "y": 11,
      "z": 2,
      "name": "Rock_Calcite"
    },
    {
      "x": -6,
      "y": 12,
      "z": 2,
      "name": "Rock_Calcite"
    },
    {
      "x": -6,
      "y": 13,
      "z": 2,
      "name": "Rock_Calcite"
    },
    {
      "x": -6,
      "y": 14,
      "z": 2,
      "name": "Rock_Calcite"
    },
    {
      "x": -6,
      "y": 15,
      "z": 2,
      "name": "Rock_Calcite"
    },
    {
      "x": -6,
      "y": 16,
      "z": 2,
      "name": "Rock_Calcite"
    },
    {
      "x": -6,
      "y": 17,
      "z": 2,
      "name": "Rock_Calcite"
    },
    {
      "x": -6,
      "y": 18,
      "z": 2,
      "name": "Rock_Calcite"
    },
    {
      "x": -6,
      "y": 19,
      "z": 2,
      "name": "Rock_Calcite"
    },
    {
      "x": -6,
      "y": 20,
      "z": 2,
      "name": "Rock_Calcite"
    },
    {
      "x": -6,
      "y": 21,
      "z": 2,
      "name": "Rock_Calcite"
    },
    {
      "x": -6,
      "y": 22,
      "z": 2,
      "name": "Rock_Calcite"
    },
    {
      "x": -6,
      "y": 23,
      "z": 2,
      "name": "Rock_Calcite"
    },
    {
      "x": -6,
      "y": 24,
      "z": 2,
      "name": "Rock_Calcite"
    },
    {
      "x": -6,
      "y": 25,
      "z": 2,
      "name": "Rock_Calcite"
    },
    {
      "x": -6,
      "y": 26,
      "z": 2,
      "name": "Rock_Calcite"
    },
    {
      "x": -6,
      "y": 27,
      "z": 2,
      "name": "Rock_Calcite"
    },
    {
      "x": -6,
      "y": 28,
      "z": 2,
      "name": "Rock_Calcite"
    },
    {
      "x": -6,
      "y": 29,
      "z": 2,
      "name": "Rock_Calcite"
    },
    {
      "x": -6,
      "y": 30,
      "z": 2,
      "name": "Rock_Calcite"
    },
    {
      "x": -6,
      "y": 31,
      "z": 2,
      "name": "Rock_Calcite"
    },
    {
      "x": -6,
      "y": 32,
      "z": 2,
      "name": "Rock_Calcite"
    },
    {
      "x": -6,
      "y": 33,
      "z": 2,
      "name": "Rock_Calcite"
    },
    {
      "x": -6,
      "y": 34,
      "z": 2,
      "name": "Rock_Calcite"
    },
    {
      "x": -6,
      "y": 35,
      "z": 2,
      "name": "Rock_Calcite"
    },
    {
      "x": -6,
      "y": 36,
      "z": 2,
      "name": "Rock_Calcite"
    },
    {
