{
  "version": 8,
  "blockIdVersion": 8,
  "anchorX": 2,
  "anchorY": 16,
  "anchorZ": -3,
  "blocks": [
    {
      "x": -3,
      "y": 13,
      "z": -5,
      "name": "Rock_Stone"
    },
    {
      "x": -3,
      "y": 14,
      "z": -5,
      "name": "Rock_Stone"
    },
    {
      "x": -3,
      "y": 15,
      "z": -5,
      "name": "Rock_Stone"
    },
    {
      "x": -3,
      "y": 16,
      "z": -5,
      "name": "Rock_Stone"
    },
    {
      "x": -3,
      "y": 12,
      "z": -4,
      "name": "Rock_Stone"
    },
    {
      "x": -3,
      "y": 13,
      "z": -4,
      "name": "Rock_Stone"
    },
    {
      "x": -3,
      "y": 14,
      "z": -4,
      "name": "Rock_Stone"
    },
    {
      "x": -3,
      "y": 15,
      "z": -4,
      "name": "Rock_Stone"
    },
    {
      "x": -3,
      "y": 16,
      "z": -4,
      "name": "Rock_Stone"
    },
    {
      "x": -3,
      "y": 17,
      "z": -4,
      "name": "Rock_Stone"
    },
    {
      "x": -3,
      "y": 18,
      "z": -4,
      "name": "Soil_Dirt"
    },
    {
      "x": -3,
      "y": 19,
      "z": -4,
      "name": "Soil_Dirt"
    },
    {
      "x": -3,
      "y": 20,
      "z": -4,
      "name": "Soil_Grass"
    },
    {
      "x": -3,
      "y": 12,
      "z": -3,
      "name": "Rock_Stone"
    },
    {
      "x": -3,
      "y": 13,
      "z": -3,
      "name": "Rock_Stone"
    },
    {
      "x": -3,
      "y": 14,
      "z": -3,
      "name": "Rock_Stone"
    },
    {
      "x": -3,
      "y": 15,
      "z": -3,
      "name": "Rock_Stone"
    },
    {
      "x": -3,
      "y": 16,
      "z": -3,
      "name": "Rock_Stone"
    },
    {
      "x": -3,
      "y": 17,
      "z": -3,
      "name": "Rock_Stone_Mossy"
    },
    {
      "x": -3,
      "y": 18,
      "z": -3,
      "name": "Rock_Stone_Mossy"
    },
    {
      "x": -3,
      "y": 19,
      "z": -3,
      "name": "Soil_Dirt"
    },
    {
      "x": -3,
      "y": 20,
      "z": -3,
      "name": "Soil_Grass"
    },
    {
      "x": -3,
      "y": 12,
      "z": -2,
      "name": "Rock_Stone"
    },
    {
      "x": -3,
      "y": 13,
      "z": -2,
      "name": "Rock_Stone"
    },
    {
      "x": -3,
      "y": 14,
      "z": -2,
      "name": "Rock_Stone"
    },
    {
      "x": -3,
      "y": 15,
      "z": -2,
      "name": "Rock_Stone"
    },
    {
      "x": -3,
      "y": 16,
      "z": -2,
      "name": "Rock_Stone"
    },
    {
      "x": -3,
      "y": 17,
      "z": -2,
      "name": "Rock_Stone_Mossy"
    },
    {
      "x": -3,
      "y": 18,
      "z": -2,
      "name": "Rock_Stone_Mossy"
    },
    {
      "x": -3,
      "y": 19,
      "z": -2,
      "name": "Rock_Stone_Mossy"
    },
    {
      "x": -3,
      "y": 20,
      "z": -2,
      "name": "Soil_Dirt"
    },
    {
      "x": -3,
      "y": 21,
      "z": -2,
      "name": "Soil_Dirt"
    },
    {
      "x": -3,
      "y": 22,
      "z": -2,
      "name": "Soil_Grass"
    },
    {
      "x": -3,
      "y": 13,
      "z": -1,
      "name": "Rock_Stone"
    },
    {
      "x": -3,
      "y": 14,
      "z": -1,
      "name": "Rock_Stone"
    },
    {
      "x": -3,
      "y": 15,
      "z": -1,
      "name": "Rock_Stone"
    },
    {
      "x": -3,
      "y": 16,
      "z": -1,
      "name": "Rock_Stone_Mossy"
    },
    {
      "x": -3,
      "y": 17,
      "z": -1,
      "name": "Rock_Stone_Mossy"
    },
    {
      "x": -3,
      "y": 18,
      "z": -1,
      "name": "Rock_Stone_Mossy"
    },
    {
      "x": -3,
      "y": 19,
      "z": -1,
      "name": "Rock_Stone_Mossy"
    },
    {
      "x": -3,
      "y": 20,
      "z": -1,
      "name": "Soil_Dirt"
    },
    {
      "x": -3,
      "y": 21,
      "z": -1,
      "name": "Soil_Dirt"
    },
    {
      "x": -3,
      "y": 22,
      "z": -1,
      "name": "Soil_Grass"
    },
    {
      "x": -3,
      "y": 18,
      "z": 0,
      "name": "Rock_Stone"
    },
    {
      "x": -3,
      "y": 19,
      "z": 0,
      "name": "Rock_Stone_Mossy"
    },
    {
      "x": -3,
      "y": 20,
      "z": 0,
      "name": "Rock_Stone_Mossy"
    },
    {
      "x": -3,
      "y": 21,
      "z": 0,
      "name": "Soil_Dirt"
    },
    {
      "x": -3,
      "y": 22,
      "z": 0,
      "name": "Soil_Grass"
    },
    {
      "x": -3,
      "y": 23,
      "z": 0,
      "name": "Plant_Grass_Sharp"
    },
    {
      "x": -3,
      "y": 15,
      "z": 1,
      "name": "Soil_Dirt"
    },
    {
      "x": -3,
      "y": 16,
      "z": 1,
      "name": "Soil_Grass"
    },
    {
      "x": -3,
      "y": 20,
      "z": 1,
      "name": "Rock_Stone"
    },
    {
      "x": -3,
      "y": 21,
      "z": 1,
      "name": "Soil_Dirt"
    },
    {
      "x": -3,
      "y": 22,
      "z": 1,
      "name": "Soil_Grass"
    },
    {
      "x": -3,
      "y": 14,
      "z": 2,
      "name": "Soil_Dirt"
    },
    {
      "x": -3,
      "y": 15,
      "z": 2,
      "name": "Soil_Dirt"
    },
    {
      "x": -3,
      "y": 16,
      "z": 2,
      "name": "Soil_Grass"
    },
    {
      "x": -3,
      "y": 14,
      "z": 3,
      "name": "Soil_Dirt"
    },
    {
      "x": -3,
      "y": 15,
      "z": 3,
      "name": "Soil_Dirt"
    },
    {
      "x": -3,
      "y": 16,
      "z": 3,
      "name": "Soil_Grass"
    },
    {
      "x": -3,
      "y": 17,
      "z": 3,
      "name": "Plant_Grass_Sharp"
    },
    {
      "x": -2,
      "y": 12,
      "z": -6,
      "name": "Rock_Stone"
    },
    {
      "x": -2,
      "y": 13,
      "z": -6,
      "name": "Rock_Stone"
    },
    {
      "x": -2,
      "y": 14,
      "z": -6,
      "name": "Rock_Stone"
    },
    {
      "x": -2,
      "y": 15,
      "z": -6,
      "name": "Rock_Stone"
    },
    {
      "x": -2,
      "y": 16,
      "z": -6,
      "name": "Rock_Stone"
    },
    {
      "x": -2,
      "y": 17,
      "z": -6,
      "name": "Rock_Stone"
    },
    {
      "x": -2,
      "y": 18,
      "z": -6,
      "name": "Soil_Dirt"
    },
    {
      "x": -2,
      "y": 19,
      "z": -6,
      "name": "Soil_Grass"
    },
    {
      "x": -2,
      "y": 12,
      "z": -5,
      "name": "Rock_Stone"
    },
    {
      "x": -2,
      "y": 13,
      "z": -5,
      "name": "Rock_Stone"
    },
    {
      "x": -2,
      "y": 14,
      "z": -5,
      "name": "Rock_Stone"
    },
    {
      "x": -2,
      "y": 15,
      "z": -5,
      "name": "Rock_Stone"
    },
    {
      "x": -2,
      "y": 16,
      "z": -5,
      "name": "Rock_Stone"
    },
    {
      "x": -2,
      "y": 17,
      "z": -5,
      "name": "Rock_Stone"
    },
    {
      "x": -2,
      "y": 18,
      "z": -5,
      "name": "Soil_Dirt"
    },
    {
      "x": -2,
      "y": 19,
      "z": -5,
      "name": "Soil_Dirt"
    },
    {
      "x": -2,
      "y": 20,
      "z": -5,
      "name": "Soil_Dirt"
    },
    {
      "x": -2,
      "y": 21,
      "z": -5,
      "name": "Soil_Grass"
    },
    {
      "x": -2,
      "y": 12,
      "z": -4,
      "name": "Rock_Stone"
    },
    {
      "x": -2,
      "y": 13,
      "z": -4,
      "name": "Rock_Stone"
    },
    {
      "x": -2,
      "y": 14,
      "z": -4,
      "name": "Rock_Stone"
    },
    {
      "x": -2,
      "y": 15,
      "z": -4,
      "name": "Rock_Stone"
    },
    {
      "x": -2,
      "y": 16,
      "z": -4,
      "name": "Rock_Stone"
    },
    {
      "x": -2,
      "y": 17,
      "z": -4,
      "name": "Rock_Stone"
    },
    {
      "x": -2,
      "y": 18,
      "z": -4,
      "name": "Soil_Dirt"
    },
    {
      "x": -2,
      "y": 19,
      "z": -4,
      "name": "Soil_Dirt"
    },
    {
      "x": -2,
      "y": 20,
      "z": -4,
      "name": "Soil_Dirt"
    },
    {
      "x": -2,
      "y": 21,
      "z": -4,
      "name": "Soil_Grass"
    },
    {
      "x": -2,
      "y": 11,
      "z": -3,
      "name": "Rock_Stone"
    },
    {
      "x": -2,
      "y": 12,
      "z": -3,
      "name": "Rock_Stone"
    },
    {
      "x": -2,
      "y": 13,
      "z": -3,
      "name": "Rock_Stone"
    },
    {
      "x": -2,
      "y": 14,
      "z": -3,
      "name": "Rock_Stone"
    },
    {
      "x": -2,
      "y": 15,
      "z": -3,
      "name": "Rock_Stone"
    },
    {
      "x": -2,
      "y": 16,
      "z": -3,
      "name": "Rock_Stone"
    },
    {
      "x": -2,
      "y": 17,
      "z": -3,
      "name": "Rock_Stone"
    },
    {
      "x": -2,
      "y": 18,
      "z": -3,
      "name": "Rock_Stone_Mossy"
    },
    {
      "x": -2,
      "y": 19,
      "z": -3,
      "name": "Soil_Dirt"
    },
    {
      "x": -2,
      "y": 20,
      "z": -3,
      "name": "Soil_Dirt"
    },
    {
      "x": -2,
      "y": 21,
      "z": -3,
      "name": "Soil_Dirt"
    },
    {
      "x": -2,
      "y": 22,
      "z": -3,
      "name": "Soil_Grass"
    },
    {
      "x": -2,
      "y": 10,
      "z": -2,
      "name": "Rock_Stone"
    },
    {
      "x": -2,
      "y": 11,
      "z": -2,
      "name": "Rock_Stone"
    },
    {
      "x": -2,
      "y": 12,
      "z": -2,
      "name": "Rock_Stone_Mossy"
    },
    {
      "x": -2,
      "y": 13,
      "z": -2,
      "name": "Rock_Stone"
    },
    {
      "x": -2,
      "y": 14,
      "z": -2,
      "name": "Rock_Stone"
    },
    {
      "x": -2,
      "y": 15,
      "z": -2,
      "name": "Rock_Stone"
    },
    {
      "x": -2,
      "y": 16,
      "z": -2,
      "name": "Rock_Stone"
    },
    {
      "x": -2,
      "y": 17,
      "z": -2,
      "name": "Rock_Stone"
    },
    {
      "x": -2,
      "y": 18,
      "z": -2,
      "name": "Rock_Stone"
    },
    {
      "x": -2,
      "y": 19,
      "z": -2,
      "name": "Rock_Stone"
    },
    {
      "x": -2,
      "y": 20,
      "z": -2,
      "name": "Soil_Dirt"
    },
    {
      "x": -2,
      "y": 21,
      "z": -2,
      "name": "Soil_Dirt"
    },
    {
      "x": -2,
      "y": 22,
      "z": -2,
      "name": "Soil_Grass"
    },
    {
      "x": -2,
      "y": 10,
      "z": -1,
      "name": "Rock_Stone"
    },
    {
      "x": -2,
      "y": 11,
      "z": -1,
      "name": "Rock_Stone_Mossy"
    },
    {
      "x": -2,
      "y": 12,
      "z": -1,
      "name": "Rock_Stone_Mossy"
    },
    {
      "x": -2,
      "y": 13,
      "z": -1,
      "name": "Rock_Stone_Mossy"
    },
    {
      "x": -2,
      "y": 14,
      "z": -1,
      "name": "Rock_Stone"
    },
    {
      "x": -2,
      "y": 15,
      "z": -1,
      "name": "Rock_Stone"
    },
    {
      "x": -2,
      "y": 16,
      "z": -1,
      "name": "Rock_Stone"
    },
    {
      "x": -2,
      "y": 17,
      "z": -1,
      "name": "Rock_Stone_Mossy"
    },
    {
      "x": -2,
      "y": 18,
      "z": -1,
      "name": "Rock_Stone"
    },
    {
      "x": -2,
      "y": 19,
      "z": -1,
      "name": "Rock_Stone_Mossy"
    },
    {
      "x": -2,
      "y": 20,
      "z": -1,
      "name": "Soil_Dirt"
    },
    {
      "x": -2,
      "y": 21,
      "z": -1,
      "name": "Soil_Dirt"
    },
    {
      "x": -2,
      "y": 22,
      "z": -1,
      "name": "Soil_Grass"
    },
    {
      "x": -2,
      "y": 23,
      "z": -1,
      "name": "Plant_Grass_Sharp_Tall"
    },
    {
      "x": -2,
      "y": 24,
      "z": -1,
      "name": "Plant_Grass_Sharp_Tall",
      "filler": 1024
    },
    {
      "x": -2,
      "y": 12,
      "z": 0,
      "name": "Rock_Stone_Mossy"
    },
    {
      "x": -2,
      "y": 13,
      "z": 0,
      "name": "Rock_Stone_Mossy"
    },
    {
      "x": -2,
      "y": 14,
      "z": 0,
      "name": "Rock_Stone"
    },
    {
      "x": -2,
      "y": 15,
      "z": 0,
      "name": "Rock_Stone"
    },
    {
      "x": -2,
      "y": 16,
      "z": 0,
      "name": "Rock_Stone"
    },
    {
      "x": -2,
      "y": 17,
      "z": 0,
      "name": "Rock_Stone"
    },
    {
      "x": -2,
      "y": 18,
      "z": 0,
      "name": "Rock_Stone"
    },
    {
      "x": -2,
      "y": 19,
      "z": 0,
      "name": "Rock_Stone"
    },
    {
      "x": -2,
      "y": 20,
      "z": 0,
      "name": "Rock_Stone"
    },
    {
      "x": -2,
      "y": 21,
      "z": 0,
      "name": "Soil_Dirt"
    },
    {
      "x": -2,
      "y": 22,
      "z": 0,
      "name": "Soil_Grass"
    },
    {
      "x": -2,
      "y": 23,
      "z": 0,
      "name": "Plant_Grass_Sharp"
    },
    {
      "x": -2,
      "y": 13,
      "z": 1,
      "name": "Rock_Stone_Mossy"
    },
    {
      "x": -2,
      "y": 14,
      "z": 1,
      "name": "Rock_Stone_Mossy"
    },
    {
      "x": -2,
      "y": 15,
      "z": 1,
      "name": "Soil_Dirt"
    },
    {
      "x": -2,
      "y": 16,
      "z": 1,
      "name": "Rock_Stone"
    },
    {
      "x": -2,
      "y": 17,
      "z": 1,
      "name": "Rock_Stone"
    },
    {
      "x": -2,
      "y": 18,
      "z": 1,
      "name": "Rock_Stone"
    },
    {
      "x": -2,
      "y": 19,
      "z": 1,
      "name": "Rock_Stone"
    },
    {
      "x": -2,
      "y": 20,
      "z": 1,
      "name": "Soil_Dirt"
    },
    {
      "x": -2,
      "y": 21,
      "z": 1,
      "name": "Soil_Dirt"
    },
    {
      "x": -2,
      "y": 22,
      "z": 1,
      "name": "Soil_Grass"
    },
    {
      "x": -2,
      "y": 13,
      "z": 2,
      "name": "Rock_Stone_Mossy"
    },
    {
      "x": -2,
      "y": 14,
      "z": 2,
      "name": "Soil_Dirt"
    },
    {
      "x": -2,
      "y": 15,
      "z": 2,
      "name": "Soil_Dirt"
    },
    {
      "x": -2,
      "y": 16,
      "z": 2,
      "name": "Soil_Grass"
    },
    {
      "x": -2,
      "y": 17,
      "z": 2,
      "name": "Plant_Grass_Sharp"
    },
    {
      "x": -2,
      "y": 19,
      "z": 2,
      "name": "Rock_Stone"
    },
    {
      "x": -2,
      "y": 20,
      "z": 2,
      "name": "Soil_Dirt"
    },
    {
      "x": -2,
      "y": 21,
      "z": 2,
      "name": "Soil_Dirt"
    },
    {
      "x": -2,
      "y": 22,
      "z": 2,
      "name": "Soil_Grass"
    },
    {
      "x": -2,
      "y": 14,
      "z": 3,
      "name": "Soil_Dirt"
    },
    {
      "x": -2,
      "y": 15,
      "z": 3,
      "name": "Soil_Dirt"
    },
    {
      "x": -2,
      "y": 16,
      "z": 3,
      "name": "Soil_Grass"
    },
    {
      "x": -1,
      "y": 17,
      "z": -7,
      "name": "Rock_Stone"
    },
    {
      "x": -1,
      "y": 18,
      "z": -7,
      "name": "Soil_Dirt"
    },
    {
      "x": -1,
      "y": 19,
      "z": -7,
      "name": "Soil_Dirt"
    },
    {
      "x": -1,
      "y": 20,
      "z": -7,
      "name": "Soil_Grass"
    },
    {
      "x": -1,
      "y": 12,
      "z": -6,
      "name": "Rock_Stone"
    },
    {
      "x": -1,
      "y": 13,
      "z": -6,
      "name": "Rock_Stone"
    },
    {
      "x": -1,
      "y": 14,
      "z": -6,
      "name": "Rock_Stone"
    },
    {
      "x": -1,
      "y": 15,
      "z": -6,
      "name": "Rock_Stone"
    },
    {
      "x": -1,
      "y": 16,
      "z": -6,
      "name": "Rock_Stone"
    },
    {
      "x": -1,
      "y": 17,
      "z": -6,
      "name": "Rock_Stone"
    },
    {
      "x": -1,
      "y": 18,
      "z": -6,
      "name": "Soil_Dirt"
    },
    {
      "x": -1,
      "y": 19,
      "z": -6,
      "name": "Soil_Dirt"
    },
    {
      "x": -1,
      "y": 20,
      "z": -6,
      "name": "Soil_Dirt"
    },
    {
      "x": -1,
      "y": 21,
      "z": -6,
      "name": "Soil_Grass"
    },
    {
      "x": -1,
      "y": 11,
      "z": -5,
      "name": "Rock_Stone"
    },
    {
      "x": -1,
      "y": 12,
      "z": -5,
      "name": "Rock_Stone"
    },
    {
      "x": -1,
      "y": 13,
      "z": -5,
      "name": "Rock_Stone"
    },
    {
      "x": -1,
      "y": 14,
      "z": -5,
      "name": "Rock_Stone"
    },
    {
      "x": -1,
      "y": 15,
      "z": -5,
      "name": "Rock_Stone"
    },
    {
      "x": -1,
      "y": 16,
      "z": -5,
      "name": "Rock_Stone"
    },
    {
      "x": -1,
      "y": 17,
      "z": -5,
      "name": "Rock_Stone"
    },
    {
      "x": -1,
      "y": 18,
      "z": -5,
      "name": "Soil_Dirt"
    },
    {
      "x": -1,
      "y": 19,
      "z": -5,
      "name": "Soil_Dirt"
    },
    {
      "x": -1,
      "y": 20,
      "z": -5,
      "name": "Soil_Dirt"
    },
    {
      "x": -1,
      "y": 21,
      "z": -5,
      "name": "Soil_Grass"
    },
    {
      "x": -1,
      "y": 10,
      "z": -4,
      "name": "Rock_Stone_Mossy"
    },
    {
      "x": -1,
      "y": 11,
      "z": -4,
      "name": "Rock_Stone_Mossy"
    },
    {
      "x": -1,
      "y": 12,
      "z": -4,
      "name": "Rock_Stone"
    },
    {
      "x": -1,
      "y": 13,
      "z": -4,
      "name": "Rock_Stone"
    },
    {
      "x": -1,
      "y": 14,
      "z": -4,
      "name": "Rock_Stone"
    },
    {
      "x": -1,
      "y": 15,
      "z": -4,
      "name": "Rock_Stone"
    },
    {
      "x": -1,
      "y": 16,
      "z": -4,
      "name": "Rock_Stone"
    },
    {
      "x": -1,
      "y": 17,
      "z": -4,
      "name": "Rock_Stone"
    },
    {
      "x": -1,
      "y": 18,
      "z": -4,
      "name": "Soil_Dirt"
    },
    {
      "x": -1,
      "y": 19,
      "z": -4,
      "name": "Soil_Dirt"
    },
    {
      "x": -1,
      "y": 20,
      "z": -4,
      "name": "Soil_Dirt"
    },
    {
      "x": -1,
      "y": 21,
      "z": -4,
      "name": "Soil_Grass"
    },
    {
      "x": -1,
      "y": 22,
      "z": -4,
      "name": "Plant_Grass_Sharp"
    },
    {
      "x": -1,
      "y": 10,
      "z": -3,
      "name": "Rock_Stone_Mossy"
    },
    {
      "x": -1,
      "y": 11,
      "z": -3,
      "name": "Rock_Stone"
    },
    {
      "x": -1,
      "y": 12,
      "z": -3,
      "name": "Rock_Stone"
    },
    {
      "x": -1,
      "y": 13,
      "z": -3,
      "name": "Rock_Stone"
    },
    {
      "x": -1,
      "y": 14,
      "z": -3,
      "name": "Rock_Stone"
    },
    {
      "x": -1,
      "y": 15,
      "z": -3,
      "name": "Rock_Stone"
    },
    {
      "x": -1,
      "y": 16,
      "z": -3,
      "name": "Rock_Stone"
    },
    {
      "x": -1,
      "y": 17,
      "z": -3,
      "name": "Rock_Stone"
    },
    {
      "x": -1,
      "y": 18,
      "z": -3,
      "name": "Rock_Stone"
    },
    {
      "x": -1,
      "y": 19,
      "z": -3,
      "name": "Soil_Dirt"
    },
    {
      "x": -1,
      "y": 20,
      "z": -3,
      "name": "Soil_Dirt"
    },
    {
      "x": -1,
      "y": 21,
      "z": -3,
      "name": "Soil_Dirt"
    },
    {
      "x": -1,
      "y": 22,
      "z": -3,
      "name": "Soil_Grass"
    },
    {
      "x": -1,
      "y": 10,
      "z": -2,
      "name": "Rock_Stone"
    },
    {
      "x": -1,
      "y": 11,
      "z": -2,
      "name": "Rock_Stone"
    },
    {
      "x": -1,
      "y": 12,
      "z": -2,
      "name": "Rock_Stone"
    },
    {
      "x": -1,
      "y": 13,
      "z": -2,
      "name": "Rock_Stone"
    },
    {
      "x": -1,
      "y": 14,
      "z": -2,
      "name": "Rock_Stone"
    },
    {
      "x": -1,
      "y": 15,
      "z": -2,
      "name": "Rock_Stone"
    },
    {
      "x": -1,
      "y": 16,
      "z": -2,
      "name": "Rock_Stone"
    },
    {
      "x": -1,
      "y": 17,
      "z": -2,
      "name": "Rock_Stone"
    },
    {
      "x": -1,
      "y": 18,
      "z": -2,
      "name": "Rock_Stone"
    },
    {
      "x": -1,
      "y": 19,
      "z": -2,
      "name": "Rock_Stone"
    },
    {
      "x": -1,
      "y": 20,
      "z": -2,
      "name": "Rock_Stone"
    },
    {
      "x": -1,
      "y": 21,
      "z": -2,
      "name": "Soil_Dirt"
    },
    {
      "x": -1,
      "y": 22,
      "z": -2,
      "name": "Soil_Grass"
    },
    {
      "x": -1,
      "y": 10,
      "z": -1,
      "name": "Rock_Stone"
    },
    {
      "x": -1,
      "y": 11,
      "z": -1,
      "name": "Rock_Stone"
    },
    {
      "x": -1,
      "y": 12,
      "z": -1,
      "name": "Rock_Stone_Mossy"
    },
    {
      "x": -1,
      "y": 13,
      "z": -1,
      "name": "Rock_Stone"
    },
    {
      "x": -1,
      "y": 14,
      "z": -1,
      "name": "Rock_Stone"
    },
    {
      "x": -1,
      "y": 15,
      "z": -1,
      "name": "Rock_Stone"
    },
    {
      "x": -1,
      "y": 16,
      "z": -1,
      "name": "Rock_Stone"
    },
    {
      "x": -1,
      "y": 17,
      "z": -1,
      "name": "Rock_Stone"
    },
    {
      "x": -1,
      "y": 18,
      "z": -1,
      "name": "Rock_Stone"
    },
    {
      "x": -1,
      "y": 19,
      "z": -1,
      "name": "Rock_Stone"
    },
    {
      "x": -1,
      "y": 20,
      "z": -1,
      "name": "Rock_Stone"
    },
    {
      "x": -1,
      "y": 21,
      "z": -1,
      "name": "Soil_Dirt"
    },
    {
      "x": -1,
      "y": 22,
      "z": -1,
      "name": "Soil_Grass"
    },
    {
      "x": -1,
      "y": 23,
      "z": -1,
      "name": "Plant_Bush"
    },
    {
      "x": -1,
      "y": 10,
      "z": 0,
      "name": "Rock_Stone"
    },
    {
      "x": -1,
      "y": 11,
      "z": 0,
      "name": "Rock_Stone"
    },
    {
      "x": -1,
      "y": 12,
      "z": 0,
      "name": "Rock_Stone"
    },
    {
      "x": -1,
      "y": 13,
      "z": 0,
      "name": "Rock_Stone"
    },
    {
      "x": -1,
      "y": 14,
      "z": 0,
      "name": "Rock_Stone"
    },
    {
      "x": -1,
      "y": 15,
      "z": 0,
      "name": "Rock_Stone"
    },
    {
      "x": -1,
      "y": 16,
      "z": 0,
      "name": "Rock_Stone"
    },
    {
      "x": -1,
      "y": 17,
      "z": 0,
      "name": "Rock_Stone"
    },
    {
      "x": -1,
      "y": 18,
      "z": 0,
      "name": "Rock_Stone"
    },
    {
      "x": -1,
      "y": 19,
      "z": 0,
      "name": "Rock_Stone"
    },
    {
      "x": -1,
      "y": 20,
      "z": 0,
      "name": "Rock_Stone"
    },
    {
      "x": -1,
      "y": 21,
      "z": 0,
      "name": "Soil_Dirt"
    },
    {
      "x": -1,
      "y": 22,
      "z": 0,
      "name": "Soil_Grass"
    },
    {
      "x": -1,
      "y": 23,
      "z": 0,
      "name": "Plant_Grass_Sharp"
    },
    {
      "x": -1,
      "y": 11,
      "z": 1,
      "name": "Rock_Stone"
    },
    {
      "x": -1,
      "y": 12,
      "z": 1,
      "name": "Rock_Stone"
    },
    {
      "x": -1,
      "y": 13,
      "z": 1,
      "name": "Rock_Stone_Mossy"
    },
    {
      "x": -1,
      "y": 14,
      "z": 1,
      "name": "Rock_Stone"
    },
    {
      "x": -1,
      "y": 15,
      "z": 1,
      "name": "Rock_Stone"
    },
    {
      "x": -1,
      "y": 16,
      "z": 1,
      "name": "Rock_Stone"
    },
    {
      "x": -1,
      "y": 17,
      "z": 1,
      "name": "Rock_Stone"
    },
    {
      "x": -1,
      "y": 18,
      "z": 1,
      "name": "Rock_Stone"
    },
    {
      "x": -1,
      "y": 19,
      "z": 1,
      "name": "Rock_Stone"
    },
    {
      "x": -1,
      "y": 20,
      "z": 1,
      "name": "Soil_Dirt"
    },
    {
      "x": -1,
      "y": 21,
      "z": 1,
      "name": "Soil_Dirt"
    },
    {
      "x": -1,
      "y": 22,
      "z": 1,
      "name": "Soil_Grass"
    },
    {
      "x": -1,
      "y": 23,
      "z": 1,
      "name": "Plant_Grass_Sharp"
    },
    {
      "x": -1,
      "y": 11,
      "z": 2,
      "name": "Rock_Stone"
    },
    {
      "x": -1,
      "y": 12,
      "z": 2,
      "name": "Rock_Stone"
    },
    {
      "x": -1,
      "y": 13,
      "z": 2,
      "name": "Rock_Stone"
    },
    {
      "x": -1,
      "y": 14,
      "z": 2,
      "name": "Soil_Dirt"
    },
    {
      "x": -1,
      "y": 15,
      "z": 2,
      "name": "Soil_Dirt"
    },
    {
      "x": -1,
      "y": 16,
      "z": 2,
      "name": "Rock_Stone"
    },
    {
      "x": -1,
      "y": 17,
      "z": 2,
      "name": "Rock_Stone"
    },
    {
      "x": -1,
      "y": 18,
      "z": 2,
      "name": "Rock_Stone"
    },
    {
      "x": -1,
      "y": 19,
      "z": 2,
      "name": "Rock_Stone"
    },
    {
      "x": -1,
      "y": 20,
      "z": 2,
      "name": "Soil_Dirt"
    },
    {
      "x": -1,
      "y": 21,
      "z": 2,
      "name": "Soil_Dirt"
    },
    {
      "x": -1,
      "y": 22,
      "z": 2,
      "name": "Soil_Grass"
    },
    {
      "x": -1,
      "y": 11,
      "z": 3,
      "name": "Rock_Stone"
    },
    {
      "x": -1,
      "y": 12,
      "z": 3,
      "name": "Rock_Stone"
    },
    {
      "x": -1,
      "y": 13,
      "z": 3,
      "name": "Soil_Dirt"
    },
    {
      "x": -1,
      "y": 14,
      "z": 3,
      "name": "Soil_Dirt"
    },
    {
      "x": -1,
      "y": 15,
      "z": 3,
      "name": "Soil_Dirt"
    },
    {
      "x": -1,
      "y": 16,
      "z": 3,
      "name": "Soil_Grass"
    },
    {
      "x": -1,
      "y": 17,
      "z": 3,
      "name": "Plant_Grass_Sharp"
    },
    {
      "x": -1,
      "y": 12,
      "z": 4,
      "name": "Rock_Stone"
    },
    {
      "x": -1,
      "y": 13,
      "z": 4,
      "name": "Soil_Dirt"
    },
    {
      "x": -1,
      "y": 14,
      "z": 4,
      "name": "Soil_Dirt"
    },
    {
      "x": -1,
      "y": 15,
      "z": 4,
      "name": "Soil_Dirt"
    },
    {
      "x": -1,
      "y": 16,
      "z": 4,
      "name": "Soil_Grass"
    },
    {
      "x": -1,
      "y": 17,
      "z": 4,
      "name": "Plant_Grass_Sharp"
    },
    {
      "x": -1,
      "y": 14,
      "z": 5,
      "name": "Soil_Dirt"
    },
    {
      "x": -1,
      "y": 15,
      "z": 5,
      "name": "Soil_Dirt"
    },
    {
      "x": -1,
      "y": 16,
      "z": 5,
      "name": "Soil_Grass"
    },
    {
      "x": 0,
      "y": 19,
      "z": -8,
      "name": "Soil_Dirt"
    },
    {
      "x": 0,
      "y": 20,
      "z": -8,
      "name": "Soil_Grass"
    },
    {
      "x": 0,
      "y": 13,
      "z": -7,
      "name": "Rock_Stone"
    },
    {
      "x": 0,
      "y": 14,
      "z": -7,
      "name": "Rock_Stone"
    },
    {
      "x": 0,
      "y": 15,
      "z": -7,
      "name": "Rock_Stone"
    },
    {
      "x": 0,
      "y": 16,
      "z": -7,
      "name": "Rock_Stone"
    },
    {
      "x": 0,
      "y": 17,
      "z": -7,
      "name": "Rock_Stone"
    },
    {
      "x": 0,
      "y": 18,
      "z": -7,
      "name": "Rock_Stone"
    },
    {
      "x": 0,
      "y": 19,
      "z": -7,
      "name": "Soil_Dirt"
    },
    {
      "x": 0,
      "y": 20,
      "z": -7,
      "name": "Soil_Grass"
    },
    {
      "x": 0,
      "y": 11,
      "z": -6,
      "name": "Rock_Stone"
    },
    {
      "x": 0,
      "y": 12,
      "z": -6,
      "name": "Rock_Stone"
    },
    {
      "x": 0,
      "y": 13,
      "z": -6,
      "name": "Rock_Stone"
    },
    {
      "x": 0,
      "y": 14,
      "z": -6,
      "name": "Rock_Stone"
    },
    {
      "x": 0,
      "y": 15,
      "z": -6,
      "name": "Rock_Stone"
    },
    {
      "x": 0,
      "y": 16,
      "z": -6,
      "name": "Rock_Stone"
    },
    {
      "x": 0,
      "y": 17,
      "z": -6,
      "name": "Rock_Stone"
    },
    {
      "x": 0,
      "y": 18,
      "z": -6,
      "name": "Rock_Stone"
    },
    {
      "x": 0,
      "y": 19,
      "z": -6,
      "name": "Soil_Dirt"
    },
    {
      "x": 0,
      "y": 20,
      "z": -6,
      "name": "Soil_Dirt"
    },
    {
      "x": 0,
      "y": 21,
      "z": -6,
      "name": "Soil_Grass"
    },
    {
      "x": 0,
      "y": 22,
      "z": -6,
      "name": "Plant_Grass_Sharp"
    },
    {
      "x": 0,
      "y": 10,
      "z": -5,
      "name": "Rock_Stone"
    },
    {
      "x": 0,
      "y": 11,
      "z": -5,
      "name": "Rock_Stone"
    },
    {
      "x": 0,
      "y": 12,
      "z": -5,
      "name": "Rock_Stone"
    },
    {
      "x": 0,
      "y": 13,
      "z": -5,
      "name": "Rock_Stone"
    },
    {
      "x": 0,
      "y": 14,
      "z": -5,
      "name": "Rock_Stone"
    },
    {
      "x": 0,
      "y": 15,
      "z": -5,
      "name": "Rock_Stone"
    },
    {
      "x": 0,
      "y": 16,
      "z": -5,
      "name": "Rock_Stone"
    },
    {
      "x": 0,
      "y": 17,
      "z": -5,
      "name": "Rock_Stone"
    },
    {
      "x": 0,
      "y": 18,
      "z": -5,
      "name": "Rock_Stone"
    },
    {
      "x": 0,
      "y": 19,
      "z": -5,
      "name": "Soil_Dirt"
    },
    {
      "x": 0,
      "y": 20,
      "z": -5,
      "name": "Soil_Dirt"
    },
    {
      "x": 0,
      "y": 21,
      "z": -5,
      "name": "Soil_Grass"
    },
    {
      "x": 0,
      "y": 22,
      "z": -5,
      "name": "Plant_Grass_Sharp"
    },
    {
      "x": 0,
      "y": 10,
      "z": -4,
      "name": "Rock_Stone_Mossy"
    },
    {
      "x": 0,
      "y": 11,
      "z": -4,
      "name": "Rock_Stone"
    },
    {
      "x": 0,
      "y": 12,
      "z": -4,
      "name": "Rock_Stone"
    },
    {
      "x": 0,
      "y": 13,
      "z": -4,
      "name": "Rock_Stone"
    },
    {
      "x": 0,
      "y": 14,
      "z": -4,
      "name": "Rock_Stone"
    },
    {
      "x": 0,
      "y": 15,
      "z": -4,
      "name": "Rock_Stone"
    },
    {
      "x": 0,
      "y": 16,
      "z": -4,
      "name": "Rock_Stone"
    },
    {
      "x": 0,
      "y": 17,
      "z": -4,
      "name": "Rock_Stone"
    },
    {
      "x": 0,
      "y": 18,
      "z": -4,
      "name": "Rock_Stone"
    },
    {
      "x": 0,
      "y": 19,
      "z": -4,
      "name": "Soil_Dirt"
    },
    {
      "x": 0,
      "y": 20,
      "z": -4,
      "name": "Soil_Dirt"
    },
    {
      "x": 0,
      "y": 21,
      "z": -4,
      "name": "Soil_Dirt"
    },
    {
      "x": 0,
      "y": 22,
      "z": -4,
      "name": "Soil_Grass"
    },
    {
      "x": 0,
      "y": 9,
      "z": -3,
      "name": "Rock_Stone"
    },
    {
      "x": 0,
      "y": 10,
      "z": -3,
      "name": "Rock_Stone"
    },
    {
      "x": 0,
      "y": 11,
      "z": -3,
      "name": "Rock_Stone"
    },
    {
      "x": 0,
      "y": 12,
      "z": -3,
      "name": "Rock_Stone"
    },
    {
      "x": 0,
      "y": 13,
      "z": -3,
      "name": "Rock_Stone"
    },
    {
      "x": 0,
      "y": 14,
      "z": -3,
      "name": "Rock_Stone"
    },
    {
      "x": 0,
      "y": 15,
      "z": -3,
      "name": "Rock_Stone"
    },
    {
      "x": 0,
      "y": 16,
      "z": -3,
      "name": "Rock_Stone"
    },
    {
      "x": 0,
      "y": 17,
      "z": -3,
      "name": "Rock_Stone"
    },
    {
      "x": 0,
      "y": 18,
      "z": -3,
      "name": "Rock_Stone"
    },
    {
      "x": 0,
      "y": 19,
      "z": -3,
      "name": "Rock_Stone"
    },
    {
      "x": 0,
      "y": 20,
      "z": -3,
      "name": "Rock_Stone"
    },
    {
      "x": 0,
      "y": 21,
      "z": -3,
      "name": "Soil_Dirt"
    },
    {
      "x": 0,
      "y": 22,
      "z": -3,
      "name": "Soil_Grass"
    },
    {
      "x": 0,
      "y": 9,
      "z": -2,
      "name": "Rock_Stone"
    },
    {
      "x": 0,
      "y": 10,
      "z": -2,
      "name": "Rock_Stone"
    },
    {
      "x": 0,
      "y": 11,
      "z": -2,
      "name": "Rock_Stone"
    },
    {
      "x": 0,
      "y": 12,
      "z": -2,
      "name": "Rock_Stone"
    },
    {
      "x": 0,
      "y": 13,
      "z": -2,
      "name": "Rock_Stone"
    },
    {
      "x": 0,
      "y": 14,
      "z": -2,
      "name": "Rock_Stone"
    },
    {
      "x": 0,
      "y": 15,
      "z": -2,
      "name": "Rock_Stone"
    },
    {
      "x": 0,
      "y": 16,
      "z": -2,
      "name": "Rock_Stone"
    },
    {
      "x": 0,
      "y": 17,
      "z": -2,
      "name": "Rock_Stone"
    },
    {
      "x": 0,
      "y": 18,
      "z": -2,
      "name": "Rock_Stone"
    },
    {
      "x": 0,
      "y": 19,
      "z": -2,
      "name": "Rock_Stone"
    },
    {
      "x": 0,
      "y": 20,
      "z": -2,
      "name": "Rock_Stone"
    },
    {
      "x": 0,
      "y": 21,
      "z": -2,
      "name": "Rock_Stone"
    },
    {
      "x": 0,
      "y": 22,
      "z": -2,
      "name": "Soil_Grass"
    },
    {
      "x": 0,
      "y": 23,
      "z": -2,
      "name": "Plant_Bush"
    },
    {
      "x": 0,
      "y": 9,
      "z": -1,
      "name": "Rock_Stone"
    },
    {
      "x": 0,
      "y": 10,
      "z": -1,
      "name": "Rock_Stone"
    },
    {
      "x": 0,
      "y": 11,
      "z": -1,
      "name": "Rock_Stone"
    },
    {
      "x": 0,
      "y": 12,
      "z": -1,
      "name": "Rock_Stone"
    },
    {
      "x": 0,
      "y": 13,
      "z": -1,
      "name": "Rock_Stone"
    },
    {
      "x": 0,
      "y": 14,
      "z": -1,
      "name": "Rock_Stone"
    },
    {
      "x": 0,
      "y": 15,
      "z": -1,
      "name": "Rock_Stone"
    },
    {
      "x": 0,
      "y": 16,
      "z": -1,
      "name": "Rock_Stone"
    },
    {
      "x": 0,
      "y": 17,
      "z": -1,
      "name": "Rock_Stone"
    },
    {
      "x": 0,
      "y": 18,
      "z": -1,
      "name": "Rock_Stone"
    },
    {
      "x": 0,
      "y": 19,
      "z": -1,
      "name": "Rock_Stone"
    },
    {
      "x": 0,
      "y": 20,
      "z": -1,
      "name": "Rock_Stone"
    },
    {
      "x": 0,
      "y": 21,
      "z": -1,
      "name": "Rock_Stone"
    },
    {
      "x": 0,
      "y": 22,
      "z": -1,
      "name": "Soil_Grass"
    },
    {
      "x": 0,
      "y": 23,
      "z": -1,
      "name": "Plant_Grass_Sharp"
    },
    {
      "x": 0,
      "y": 10,
      "z": 0,
      "name": "Rock_Stone"
    },
    {
      "x": 0,
      "y": 11,
      "z": 0,
      "name": "Rock_Stone"
    },
    {
      "x": 0,
      "y": 12,
      "z": 0,
      "name": "Rock_Stone"
    },
    {
      "x": 0,
      "y": 13,
      "z": 0,
      "name": "Rock_Stone"
    },
    {
      "x": 0,
      "y": 14,
      "z": 0,
      "name": "Rock_Stone"
    },
    {
      "x": 0,
      "y": 15,
      "z": 0,
      "name": "Rock_Stone"
    },
    {
      "x": 0,
      "y": 16,
      "z": 0,
      "name": "Rock_Stone"
    },
    {
      "x": 0,
      "y": 17,
      "z": 0,
      "name": "Rock_Stone"
    },
    {
      "x": 0,
      "y": 18,
      "z": 0,
      "name": "Rock_Stone"
    },
    {
      "x": 0,
      "y": 19,
      "z": 0,
      "name": "Rock_Stone"
    },
    {
      "x": 0,
      "y": 20,
      "z": 0,
      "name": "Rock_Stone"
    },
    {
      "x": 0,
      "y": 21,
      "z": 0,
      "name": "Soil_Dirt"
    },
    {
      "x": 0,
      "y": 22,
      "z": 0,
      "name": "Soil_Grass"
    },
    {
      "x": 0,
      "y": 23,
      "z": 0,
      "name": "*Plant_Crop_Berry_Block_State_Definitions_StageFinal",
      "components": {
        "Components": {
          "FarmingBlock": {}
        }
      }
    },
    {
      "x": 0,
      "y": 10,
      "z": 1,
      "name": "Rock_Stone"
    },
    {
      "x": 0,
      "y": 11,
      "z": 1,
      "name": "Rock_Stone"
    },
    {
      "x": 0,
      "y": 12,
      "z": 1,
      "name": "Rock_Stone"
    },
    {
      "x": 0,
      "y": 13,
      "z": 1,
      "name": "Rock_Stone"
    },
    {
      "x": 0,
      "y": 14,
      "z": 1,
      "name": "Rock_Stone"
    },
    {
      "x": 0,
      "y": 15,
      "z": 1,
      "name": "Rock_Stone"
    },
    {
      "x": 0,
      "y": 16,
      "z": 1,
      "name": "Rock_Stone"
    },
    {
      "x": 0,
      "y": 17,
      "z": 1,
      "name": "Rock_Stone"
    },
    {
      "x": 0,
      "y": 18,
      "z": 1,
      "name": "Rock_Stone"
    },
    {
      "x": 0,
      "y": 19,
      "z": 1,
      "name": "Rock_Stone"
    },
    {
      "x": 0,
      "y": 20,
      "z": 1,
      "name": "Soil_Dirt"
    },
    {
      "x": 0,
      "y": 21,
      "z": 1,
      "name": "Soil_Dirt"
    },
    {
      "x": 0,
      "y": 22,
      "z": 1,
      "name": "Soil_Grass"
    },
    {
      "x": 0,
      "y": 23,
      "z": 1,
      "name": "Plant_Grass_Sharp"
    },
    {
      "x": 0,
      "y": 10,
      "z": 2,
      "name": "Rock_Stone"
    },
    {
      "x": 0,
      "y": 11,
      "z": 2,
      "name": "Rock_Stone"
    },
    {
      "x": 0,
      "y": 12,
      "z": 2,
      "name": "Rock_Stone"
    },
    {
      "x": 0,
      "y": 13,
      "z": 2,
      "name": "Rock_Stone"
    },
    {
      "x": 0,
      "y": 14,
      "z": 2,
      "name": "Soil_Dirt"
    },
    {
      "x": 0,
      "y": 15,
      "z": 2,
      "name": "Rock_Stone"
    },
    {
      "x": 0,
      "y": 16,
      "z": 2,
      "name": "Rock_Stone"
    },
    {
      "x": 0,
      "y": 17,
      "z": 2,
      "name": "Rock_Stone"
    },
    {
      "x": 0,
      "y": 18,
      "z": 2,
      "name": "Rock_Stone"
    },
    {
      "x": 0,
      "y": 19,
      "z": 2,
      "name": "Rock_Stone"
    },
    {
      "x": 0,
      "y": 20,
      "z": 2,
      "name": "Soil_Dirt"
    },
    {
      "x": 0,
      "y": 21,
      "z": 2,
      "name": "Soil_Dirt"
    },
    {
      "x": 0,
      "y": 22,
      "z": 2,
      "name": "Soil_Grass"
    },
    {
      "x": 0,
      "y": 10,
      "z": 3,
      "name": "Rock_Stone"
    },
    {
      "x": 0,
      "y": 11,
      "z": 3,
      "name": "Rock_Stone"
    },
    {
      "x": 0,
      "y": 12,
      "z": 3,
      "name": "Rock_Stone"
    },
    {
      "x": 0,
      "y": 13,
      "z": 3,
      "name": "Soil_Dirt"
    },
    {
      "x": 0,
      "y": 14,
      "z": 3,
      "name": "Soil_Dirt"
    },
    {
      "x": 0,
      "y": 15,
      "z": 3,
      "name": "Soil_Dirt"
    },
    {
      "x": 0,
      "y": 16,
      "z": 3,
      "name": "Soil_Grass"
    },
    {
      "x": 0,
      "y": 10,
      "z": 4,
      "name": "Rock_Stone"
    },
    {
      "x": 0,
      "y": 11,
      "z": 4,
      "name": "Rock_Stone"
    },
    {
      "x": 0,
      "y": 12,
      "z": 4,
      "name": "Rock_Stone"
    },
    {
      "x": 0,
      "y": 13,
      "z": 4,
      "name": "Soil_Dirt"
    },
    {
      "x": 0,
      "y": 14,
      "z": 4,
      "name": "Soil_Dirt"
    },
    {
      "x": 0,
      "y": 15,
      "z": 4,
      "name": "Soil_Dirt"
    },
    {
      "x": 0,
      "y": 16,
      "z": 4,
      "name": "Soil_Grass"
    },
    {
      "x": 0,
      "y": 12,
      "z": 5,
      "name": "Rock_Stone"
    },
    {
      "x": 0,
      "y": 13,
      "z": 5,
      "name": "Soil_Dirt"
    },
    {
      "x": 0,
      "y": 14,
      "z": 5,
      "name": "Soil_Dirt"
    },
    {
      "x": 0,
      "y": 15,
      "z": 5,
      "name": "Soil_Dirt"
    },
    {
      "x": 0,
      "y": 16,
      "z": 5,
      "name": "Soil_Grass"
    },
    {
      "x": 0,
      "y": 16,
      "z": 6,
      "name": "Soil_Grass"
    },
    {
      "x": 1,
      "y": 17,
      "z": -9,
      "name": "Rock_Stone"
    },
    {
      "x": 1,
      "y": 18,
      "z": -9,
      "name": "Rock_Stone"
    },
    {
      "x": 1,
      "y": 19,
      "z": -9,
      "name": "Soil_Dirt"
    },
    {
      "x": 1,
      "y": 20,
      "z": -9,
      "name": "Soil_Grass"
    },
    {
      "x": 1,
      "y": 15,
      "z": -8,
      "name": "Rock_Stone"
    },
    {
      "x": 1,
      "y": 16,
      "z": -8,
      "name": "Rock_Stone"
    },
    {
      "x": 1,
      "y": 17,
      "z": -8,
      "name": "Rock_Stone"
    },
    {
      "x": 1,
      "y": 18,
      "z": -8,
      "name": "Rock_Stone"
    },
    {
      "x": 1,
      "y": 19,
      "z": -8,
      "name": "Soil_Dirt"
    },
    {
      "x": 1,
      "y": 20,
      "z": -8,
      "name": "Soil_Grass"
    },
    {
      "x": 1,
      "y": 12,
      "z": -7,
      "name": "Rock_Stone"
    },
    {
      "x": 1,
      "y": 13,
      "z": -7,
      "name": "Rock_Stone"
    },
    {
      "x": 1,
      "y": 14,
      "z": -7,
      "name": "Rock_Stone"
    },
    {
      "x": 1,
      "y": 15,
      "z": -7,
      "name": "Rock_Stone"
    },
    {
      "x": 1,
      "y": 16,
      "z": -7,
      "name": "Rock_Stone"
    },
    {
      "x": 1,
      "y": 17,
      "z": -7,
      "name": "Rock_Stone"
    },
    {
      "x": 1,
      "y": 18,
      "z": -7,
      "name": "Rock_Stone"
    },
    {
      "x": 1,
      "y": 19,
      "z": -7,
      "name": "Soil_Dirt"
    },
    {
      "x": 1,
      "y": 20,
      "z": -7,
      "name": "Soil_Grass"
    },
    {
      "x": 1,
      "y": 11,
      "z": -6,
      "name": "Rock_Stone"
    },
    {
      "x": 1,
      "y": 12,
      "z": -6,
      "name": "Rock_Stone"
    },
    {
      "x": 1,
      "y": 13,
      "z": -6,
      "name": "Rock_Stone"
    },
    {
      "x": 1,
      "y": 14,
      "z": -6,
      "name": "Rock_Stone"
    },
    {
      "x": 1,
      "y": 15,
      "z": -6,
      "name": "Rock_Stone"
    },
    {
      "x": 1,
      "y": 16,
      "z": -6,
      "name": "Rock_Stone"
    },
    {
      "x": 1,
      "y": 17,
      "z": -6,
      "name": "Rock_Stone"
    },
    {
      "x": 1,
      "y": 18,
      "z": -6,
      "name": "Rock_Stone"
    },
    {
      "x": 1,
      "y": 19,
      "z": -6,
      "name": "Rock_Stone"
    },
    {
      "x": 1,
      "y": 20,
      "z": -6,
      "name": "Soil_Dirt"
    },
    {
      "x": 1,
      "y": 21,
      "z": -6,
      "name": "Soil_Grass"
    },
    {
      "x": 1,
      "y": 22,
      "z": -6,
      "name": "Plant_Grass_Sharp"
    },
    {
      "x": 1,
      "y": 10,
      "z": -5,
      "name": "Rock_Stone"
    },
    {
      "x": 1,
      "y": 11,
      "z": -5,
      "name": "Rock_Stone"
    },
    {
      "x": 1,
      "y": 12,
      "z": -5,
      "name": "Rock_Stone"
    },
    {
      "x": 1,
      "y": 13,
      "z": -5,
      "name": "Rock_Stone"
    },
    {
      "x": 1,
      "y": 14,
      "z": -5,
      "name": "Rock_Stone"
    },
    {
      "x": 1,
      "y": 15,
      "z": -5,
      "name": "Rock_Stone"
    },
    {
      "x": 1,
      "y": 16,
      "z": -5,
      "name": "Rock_Stone"
    },
    {
      "x": 1,
      "y": 17,
      "z": -5,
      "name": "Rock_Stone"
    },
    {
      "x": 1,
      "y": 18,
      "z": -5,
      "name": "Rock_Stone"
    },
    {
      "x": 1,
      "y": 19,
      "z": -5,
      "name": "Rock_Stone"
    },
    {
      "x": 1,
      "y": 20,
      "z": -5,
      "name": "Soil_Dirt"
    },
    {
      "x": 1,
      "y": 21,
      "z": -5,
      "name": "Soil_Grass"
    },
    {
      "x": 1,
      "y": 22,
      "z": -5,
      "name": "Plant_Grass_Sharp_Tall"
    },
    {
      "x": 1,
      "y": 23,
      "z": -5,
      "name": "Plant_Grass_Sharp_Tall",
      "filler": 1024
    },
    {
      "x": 1,
      "y": 9,
      "z": -4,
      "name": "Rock_Stone"
    },
    {
      "x": 1,
      "y": 10,
      "z": -4,
      "name": "Rock_Stone"
    },
    {
      "x": 1,
      "y": 11,
      "z": -4,
      "name": "Rock_Stone"
    },
    {
      "x": 1,
      "y": 12,
      "z": -4,
      "name": "Rock_Stone"
    },
    {
      "x": 1,
      "y": 13,
      "z": -4,
      "name": "Rock_Stone"
    },
    {
      "x": 1,
      "y": 14,
      "z": -4,
      "name": "Rock_Stone"
    },
    {
      "x": 1,
      "y": 15,
      "z": -4,
      "name": "Rock_Stone"
    },
    {
      "x": 1,
      "y": 16,
      "z": -4,
      "name": "Rock_Stone"
    },
    {
      "x": 1,
      "y": 17,
      "z": -4,
      "name": "Rock_Stone"
    },
    {
      "x": 1,
      "y": 18,
      "z": -4,
      "name": "Rock_Stone"
    },
    {
      "x": 1,
      "y": 19,
      "z": -4,
      "name": "Rock_Stone"
    },
    {
      "x": 1,
      "y": 20,
      "z": -4,
      "name": "Soil_Dirt"
    },
    {
      "x": 1,
      "y": 21,
      "z": -4,
      "name": "Soil_Dirt"
    },
    {
      "x": 1,
      "y": 22,
      "z": -4,
      "name": "Soil_Grass"
    },
    {
      "x": 1,
      "y": 9,
      "z": -3,
      "name": "Rock_Stone"
    },
    {
      "x": 1,
      "y": 10,
      "z": -3,
      "name": "Rock_Stone"
    },
    {
      "x": 1,
      "y": 11,
      "z": -3,
      "name": "Rock_Stone"
    },
    {
      "x": 1,
      "y": 12,
      "z": -3,
      "name": "Rock_Stone"
    },
    {
      "x": 1,
      "y": 13,
      "z": -3,
      "name": "Rock_Stone"
    },
    {
      "x": 1,
      "y": 14,
      "z": -3,
      "name": "Rock_Stone"
    },
    {
      "x": 1,
      "y": 15,
      "z": -3,
      "name": "Rock_Stone"
    },
    {
      "x": 1,
      "y": 16,
      "z": -3,
      "name": "Rock_Stone"
    },
    {
      "x": 1,
      "y": 17,
      "z": -3,
      "name": "Rock_Stone"
    },
    {
      "x": 1,
      "y": 18,
      "z": -3,
      "name": "Rock_Stone"
    },
    {
      "x": 1,
      "y": 19,
      "z": -3,
      "name": "Rock_Stone"
    },
    {
      "x": 1,
      "y": 20,
      "z": -3,
      "name": "Rock_Stone"
    },
    {
      "x": 1,
      "y": 21,
      "z": -3,
      "name": "Soil_Dirt"
    },
    {
      "x": 1,
      "y": 22,
      "z": -3,
      "name": "Soil_Grass"
    },
    {
      "x": 1,
      "y": 9,
      "z": -2,
      "name": "Rock_Stone"
    },
    {
      "x": 1,
      "y": 10,
      "z": -2,
      "name": "Rock_Stone"
    },
    {
      "x": 1,
      "y": 11,
      "z": -2,
      "name": "Rock_Stone"
    },
    {
      "x": 1,
      "y": 12,
      "z": -2,
      "name": "Rock_Stone"
    },
    {
      "x": 1,
      "y": 13,
      "z": -2,
      "name": "Rock_Stone"
    },
    {
      "x": 1,
      "y": 14,
      "z": -2,
      "name": "Rock_Stone"
    },
    {
      "x": 1,
      "y": 15,
      "z": -2,
      "name": "Rock_Stone"
    },
    {
      "x": 1,
      "y": 16,
      "z": -2,
      "name": "Rock_Stone"
    },
    {
      "x": 1,
      "y": 17,
      "z": -2,
      "name": "Rock_Stone"
    },
    {
      "x": 1,
      "y": 18,
      "z": -2,
      "name": "Rock_Stone"
    },
    {
      "x": 1,
      "y": 19,
      "z": -2,
      "name": "Rock_Stone"
    },
    {
      "x": 1,
      "y": 20,
      "z": -2,
      "name": "Rock_Stone"
    },
    {
      "x": 1,
      "y": 21,
      "z": -2,
      "name": "Soil_Dirt"
    },
    {
      "x": 1,
      "y": 22,
      "z": -2,
      "name": "Soil_Grass"
    },
    {
      "x": 1,
      "y": 23,
      "z": -2,
      "name": "Plant_Grass_Sharp"
    },
    {
      "x": 1,
      "y": 9,
      "z": -1,
      "name": "Rock_Stone"
    },
    {
      "x": 1,
      "y": 10,
      "z": -1,
      "name": "Rock_Stone"
    },
    {
      "x": 1,
      "y": 11,
      "z": -1,
      "name": "Rock_Stone"
    },
    {
      "x": 1,
      "y": 12,
      "z": -1,
      "name": "Rock_Stone"
    },
    {
      "x": 1,
      "y": 13,
      "z": -1,
      "name": "Rock_Stone"
    },
    {
      "x": 1,
      "y": 14,
      "z": -1,
      "name": "Rock_Stone"
    },
    {
      "x": 1,
      "y": 15,
      "z": -1,
      "name": "Rock_Stone"
    },
    {
      "x": 1,
      "y": 16,
      "z": -1,
      "name": "Rock_Stone"
    },
    {
      "x": 1,
      "y": 17,
      "z": -1,
      "name": "Rock_Stone"
    },
    {
      "x": 1,
      "y": 18,
      "z": -1,
      "name": "Rock_Stone"
    },
    {
      "x": 1,
      "y": 19,
      "z": -1,
      "name": "Rock_Stone"
    },
    {
      "x": 1,
      "y": 20,
      "z": -1,
      "name": "Rock_Stone"
    },
    {
      "x": 1,
      "y": 21,
      "z": -1,
      "name": "Soil_Dirt"
    },
    {
      "x": 1,
      "y": 22,
      "z": -1,
      "name": "Soil_Grass"
    },
    {
      "x": 1,
      "y": 23,
      "z": -1,
      "name": "Plant_Grass_Sharp"
    },
    {
      "x": 1,
      "y": 9,
      "z": 0,
      "name": "Rock_Stone"
    },
    {
      "x": 1,
      "y": 10,
      "z": 0,
      "name": "Rock_Stone"
    },
    {
      "x": 1,
      "y": 11,
      "z": 0,
      "name": "Rock_Stone"
    },
    {
      "x": 1,
      "y": 12,
      "z": 0,
      "name": "Rock_Stone"
    },
    {
      "x": 1,
      "y": 13,
      "z": 0,
      "name": "Rock_Stone"
    },
    {
      "x": 1,
      "y": 14,
      "z": 0,
      "name": "Rock_Stone"
    },
    {
      "x": 1,
      "y": 15,
      "z": 0,
      "name": "Rock_Stone"
    },
    {
      "x": 1,
      "y": 16,
      "z": 0,
      "name": "Rock_Stone"
    },
    {
      "x": 1,
      "y": 17,
      "z": 0,
      "name": "Rock_Stone"
    },
    {
      "x": 1,
      "y": 18,
      "z": 0,
      "name": "Rock_Stone"
    },
    {
      "x": 1,
      "y": 19,
      "z": 0,
      "name": "Rock_Stone"
    },
    {
      "x": 1,
      "y": 20,
      "z": 0,
      "name": "Rock_Stone"
    },
    {
      "x": 1,
      "y": 21,
      "z": 0,
      "name": "Soil_Dirt"
    },
    {
      "x": 1,
      "y": 22,
      "z": 0,
      "name": "Soil_Grass"
    },
    {
      "x": 1,
      "y": 10,
      "z": 1,
      "name": "Rock_Stone"
    },
    {
      "x": 1,
      "y": 11,
      "z": 1,
      "name": "Rock_Stone"
    },
    {
      "x": 1,
      "y": 12,
      "z": 1,
      "name": "Rock_Stone"
    },
    {
      "x": 1,
      "y": 13,
      "z": 1,
      "name": "Rock_Stone"
    },
    {
      "x": 1,
      "y": 14,
      "z": 1,
      "name": "Rock_Stone"
    },
    {
      "x": 1,
      "y": 15,
      "z": 1,
      "name": "Rock_Stone"
    },
    {
      "x": 1,
      "y": 16,
      "z": 1,
      "name": "Rock_Stone"
    },
    {
      "x": 1,
      "y": 17,
      "z": 1,
      "name": "Rock_Stone"
    },
    {
      "x": 1,
      "y": 18,
      "z": 1,
      "name": "Rock_Stone"
    },
    {
      "x": 1,
      "y": 19,
      "z": 1,
      "name": "Rock_Stone"
    },
    {
      "x": 1,
      "y": 20,
      "z": 1,
      "name": "Rock_Stone"
    },
    {
      "x": 1,
      "y": 21,
      "z": 1,
      "name": "Soil_Dirt"
    },
    {
      "x": 1,
      "y": 22,
      "z": 1,
      "name": "Soil_Grass"
    },
    {
      "x": 1,
      "y": 10,
      "z": 2,
      "name": "Rock_Stone"
    },
    {
      "x": 1,
      "y": 11,
      "z": 2,
      "name": "Rock_Stone"
    },
    {
      "x": 1,
      "y": 12,
      "z": 2,
      "name": "Rock_Stone"
    },
    {
      "x": 1,
      "y": 13,
      "z": 2,
      "name": "Rock_Stone"
    },
    {
      "x": 1,
      "y": 14,
      "z": 2,
      "name": "Rock_Stone"
    },
    {
      "x": 1,
      "y": 15,
      "z": 2,
      "name": "Rock_Stone"
    },
    {
      "x": 1,
      "y": 16,
      "z": 2,
      "name": "Rock_Stone"
    },
    {
      "x": 1,
      "y": 17,
      "z": 2,
      "name": "Soil_Grass"
    },
    {
      "x": 1,
      "y": 21,
      "z": 2,
      "name": "Soil_Dirt"
    },
    {
      "x": 1,
      "y": 22,
      "z": 2,
      "name": "Soil_Grass"
    },
    {
      "x": 1,
      "y": 10,
      "z": 3,
      "name": "Rock_Stone"
    },
    {
      "x": 1,
      "y": 11,
      "z": 3,
      "name": "Rock_Stone"
    },
    {
      "x": 1,
      "y": 12,
      "z": 3,
      "name": "Rock_Stone"
    },
    {
      "x": 1,
      "y": 13,
      "z": 3,
      "name": "Rock_Stone"
    },
    {
      "x": 1,
      "y": 14,
      "z": 3,
      "name": "Soil_Dirt"
    },
    {
      "x": 1,
      "y": 15,
      "z": 3,
      "name": "Rock_Stone"
    },
    {
      "x": 1,
      "y": 16,
      "z": 3,
      "name": "Rock_Stone"
    },
    {
      "x": 1,
      "y": 17,
      "z": 3,
      "name": "Soil_Grass"
    },
    {
      "x": 1,
      "y": 10,
      "z": 4,
      "name": "Rock_Stone"
    },
    {
      "x": 1,
      "y": 11,
      "z": 4,
      "name": "Rock_Stone"
    },
    {
      "x": 1,
      "y": 12,
      "z": 4,
      "name": "Rock_Stone"
    },
    {
      "x": 1,
      "y": 13,
      "z": 4,
      "name": "Soil_Dirt"
    },
    {
      "x": 1,
      "y": 14,
      "z": 4,
      "name": "Soil_Dirt"
    },
    {
      "x": 1,
      "y": 15,
      "z": 4,
      "name": "Soil_Dirt"
    },
    {
      "x": 1,
      "y": 16,
      "z": 4,
      "name": "Soil_Dirt"
    },
    {
      "x": 1,
      "y": 17,
      "z": 4,
      "name": "Soil_Grass"
    },
    {
      "x": 1,
      "y": 18,
      "z": 4,
      "name": "*Plant_Crop_Berry_Block_State_Definitions_StageFinal",
      "components": {
        "Components": {
          "FarmingBlock": {}
        }
      }
    },
    {
      "x": 1,
      "y": 11,
      "z": 5,
      "name": "Rock_Stone"
    },
    {
      "x": 1,
      "y": 12,
      "z": 5,
      "name": "Rock_Stone"
    },
    {
      "x": 1,
      "y": 13,
      "z": 5,
      "name": "Soil_Dirt"
    },
    {
      "x": 1,
      "y": 14,
      "z": 5,
      "name": "Soil_Dirt"
    },
    {
      "x": 1,
      "y": 15,
      "z": 5,
      "name": "Soil_Dirt"
    },
    {
      "x": 1,
      "y": 16,
      "z": 5,
      "name": "Soil_Grass"
    },
    {
      "x": 1,
      "y": 17,
      "z": 5,
      "name": "Plant_Bush"
    },
    {
      "x": 1,
      "y": 13,
      "z": 6,
      "name": "Soil_Dirt"
    },
    {
      "x": 1,
      "y": 14,
      "z": 6,
      "name": "Soil_Dirt"
    },
    {
      "x": 1,
      "y": 15,
      "z": 6,
      "name": "Soil_Dirt"
    },
    {
      "x": 1,
      "y": 16,
      "z": 6,
      "name": "Soil_Grass"
    },
    {
      "x": 2,
      "y": 16,
      "z": -9,
      "name": "Rock_Stone"
    },
    {
      "x": 2,
      "y": 17,
      "z": -9,
      "name": "Rock_Stone"
    },
    {
      "x": 2,
      "y": 18,
      "z": -9,
      "name": "Rock_Stone"
    },
    {
      "x": 2,
      "y": 19,
      "z": -9,
      "name": "Soil_Dirt"
    },
    {
      "x": 2,
      "y": 20,
      "z": -9,
      "name": "Soil_Grass"
    },
    {
      "x": 2,
      "y": 13,
      "z": -8,
      "name": "Rock_Stone"
    },
    {
      "x": 2,
      "y": 14,
      "z": -8,
      "name": "Rock_Stone"
    },
    {
      "x": 2,
      "y": 15,
      "z": -8,
      "name": "Rock_Stone"
    },
    {
      "x": 2,
      "y": 16,
      "z": -8,
      "name": "Rock_Stone"
    },
    {
      "x": 2,
      "y": 17,
      "z": -8,
      "name": "Rock_Stone"
    },
    {
      "x": 2,
      "y": 18,
      "z": -8,
      "name": "Rock_Stone"
    },
    {
      "x": 2,
      "y": 19,
      "z": -8,
      "name": "Soil_Dirt"
    },
    {
      "x": 2,
      "y": 20,
      "z": -8,
      "name": "Soil_Grass"
    },
    {
      "x": 2,
      "y": 12,
      "z": -7,
      "name": "Rock_Stone"
    },
    {
      "x": 2,
      "y": 13,
      "z": -7,
      "name": "Rock_Stone"
    },
    {
      "x": 2,
      "y": 14,
      "z": -7,
      "name": "Rock_Stone"
    },
    {
      "x": 2,
      "y": 15,
      "z": -7,
      "name": "Rock_Stone"
    },
    {
      "x": 2,
      "y": 16,
      "z": -7,
      "name": "Rock_Stone"
    },
    {
      "x": 2,
      "y": 17,
      "z": -7,
      "name": "Rock_Stone"
    },
    {
      "x": 2,
      "y": 18,
      "z": -7,
      "name": "Rock_Stone"
    },
    {
      "x": 2,
      "y": 19,
      "z": -7,
      "name": "Soil_Dirt"
    },
    {
      "x": 2,
      "y": 20,
      "z": -7,
      "name": "Soil_Grass"
    },
    {
      "x": 2,
      "y": 10,
      "z": -6,
      "name": "Rock_Stone"
    },
    {
      "x": 2,
      "y": 11,
      "z": -6,
      "name": "Rock_Stone"
    },
    {
      "x": 2,
      "y": 12,
      "z": -6,
      "name": "Rock_Stone"
    },
    {
      "x": 2,
      "y": 13,
      "z": -6,
      "name": "Rock_Stone"
    },
    {
      "x": 2,
      "y": 14,
      "z": -6,
      "name": "Rock_Stone"
    },
    {
      "x": 2,
      "y": 15,
      "z": -6,
      "name": "Rock_Stone"
    },
    {
      "x": 2,
      "y": 16,
      "z": -6,
      "name": "Rock_Stone"
    },
    {
      "x": 2,
      "y": 17,
      "z": -6,
      "name": "Rock_Stone"
    },
    {
      "x": 2,
      "y": 18,
      "z": -6,
      "name": "Rock_Stone"
    },
    {
      "x": 2,
      "y": 19,
      "z": -6,
      "name": "Rock_Stone"
    },
    {
      "x": 2,
      "y": 20,
      "z": -6,
      "name": "Soil_Dirt"
    },
    {
      "x": 2,
      "y": 21,
      "z": -6,
      "name": "Soil_Grass"
    },
    {
      "x": 2,
      "y": 10,
      "z": -5,
      "name": "Rock_Stone"
    },
    {
      "x": 2,
      "y": 11,
      "z": -5,
      "name": "Rock_Stone"
    },
    {
      "x": 2,
      "y": 12,
      "z": -5,
      "name": "Rock_Stone"
    },
    {
      "x": 2,
      "y": 13,
      "z": -5,
      "name": "Rock_Stone"
    },
    {
      "x": 2,
      "y": 14,
      "z": -5,
      "name": "Rock_Stone"
    },
    {
      "x": 2,
      "y": 15,
      "z": -5,
      "name": "Rock_Stone"
    },
    {
      "x": 2,
      "y": 16,
      "z": -5,
      "name": "Rock_Stone"
    },
    {
      "x": 2,
      "y": 17,
      "z": -5,
      "name": "Rock_Stone"
    },
    {
      "x": 2,
      "y": 18,
      "z": -5,
      "name": "Rock_Stone"
    },
    {
      "x": 2,
      "y": 19,
      "z": -5,
      "name": "Rock_Stone"
    },
    {
      "x": 2,
      "y": 20,
      "z": -5,
      "name": "Soil_Dirt"
    },
    {
      "x": 2,
      "y": 21,
      "z": -5,
      "name": "Soil_Grass"
    },
    {
      "x": 2,
      "y": 22,
      "z": -5,
      "name": "Plant_Grass_Sharp_Tall"
    },
    {
      "x": 2,
      "y": 23,
      "z": -5,
      "name": "Plant_Grass_Sharp_Tall",
      "filler": 1024
    },
    {
      "x": 2,
      "y": 9,
      "z": -4,
      "name": "Rock_Stone"
    },
    {
      "x": 2,
      "y": 10,
      "z": -4,
      "name": "Rock_Stone"
    },
    {
      "x": 2,
      "y": 11,
      "z": -4,
      "name": "Rock_Stone"
    },
    {
      "x": 2,
      "y": 12,
      "z": -4,
      "name": "Rock_Stone"
    },
    {
      "x": 2,
      "y": 13,
      "z": -4,
      "name": "Rock_Stone"
    },
    {
      "x": 2,
      "y": 14,
      "z": -4,
      "name": "Rock_Stone"
    },
    {
      "x": 2,
      "y": 15,
      "z": -4,
      "name": "Rock_Stone"
    },
    {
      "x": 2,
      "y": 16,
      "z": -4,
      "name": "Rock_Stone"
    },
    {
      "x": 2,
      "y": 17,
      "z": -4,
      "name": "Rock_Stone"
    },
    {
      "x": 2,
      "y": 18,
      "z": -4,
      "name": "Rock_Stone"
    },
    {
      "x": 2,
      "y": 19,
      "z": -4,
      "name": "Rock_Stone"
    },
    {
      "x": 2,
      "y": 20,
      "z": -4,
      "name": "Soil_Dirt"
    },
    {
      "x": 2,
      "y": 21,
      "z": -4,
      "name": "Soil_Grass"
    },
    {
      "x": 2,
      "y": 22,
      "z": -4,
      "name": "Plant_Grass_Sharp_Tall"
    },
    {
      "x": 2,
      "y": 23,
      "z": -4,
      "name": "Plant_Grass_Sharp_Tall",
      "filler": 1024
    },
    {
      "x": 2,
      "y": 9,
      "z": -3,
      "name": "Rock_Stone"
    },
    {
      "x": 2,
      "y": 10,
      "z": -3,
      "name": "Rock_Stone"
    },
    {
      "x": 2,
      "y": 11,
      "z": -3,
      "name": "Rock_Stone"
    },
    {
      "x": 2,
      "y": 12,
      "z": -3,
      "name": "Rock_Stone"
    },
    {
      "x": 2,
      "y": 13,
      "z": -3,
      "name": "Rock_Stone"
    },
    {
      "x": 2,
      "y": 14,
      "z": -3,
      "name": "Rock_Stone"
    },
    {
      "x": 2,
      "y": 15,
      "z": -3,
      "name": "Rock_Stone"
    },
    {
      "x": 2,
      "y": 16,
      "z": -3,
      "name": "Rock_Stone"
    },
    {
      "x": 2,
      "y": 17,
      "z": -3,
      "name": "Rock_Stone"
    },
    {
      "x": 2,
      "y": 18,
      "z": -3,
      "name": "Rock_Stone"
    },
    {
      "x": 2,
      "y": 19,
      "z": -3,
      "name": "Rock_Stone"
    },
    {
      "x": 2,
      "y": 20,
      "z": -3,
      "name": "Soil_Dirt"
    },
    {
      "x": 2,
      "y": 21,
      "z": -3,
      "name": "Soil_Dirt"
    },
    {
      "x": 2,
      "y": 22,
      "z": -3,
      "name": "Soil_Grass"
    },
    {
      "x": 2,
      "y": 9,
      "z": -2,
      "name": "Rock_Stone"
    },
    {
      "x": 2,
      "y": 10,
      "z": -2,
      "name": "Rock_Stone"
    },
    {
      "x": 2,
      "y": 11,
      "z": -2,
      "name": "Rock_Stone"
    },
    {
      "x": 2,
      "y": 12,
      "z": -2,
      "name": "Rock_Stone"
    },
    {
      "x": 2,
      "y": 13,
      "z": -2,
      "name": "Rock_Stone"
    },
    {
      "x": 2,
      "y": 14,
      "z": -2,
      "name": "Rock_Stone"
    },
    {
      "x": 2,
      "y": 15,
      "z": -2,
      "name": "Rock_Stone"
    },
    {
      "x": 2,
      "y": 16,
      "z": -2,
      "name": "Rock_Stone"
    },
    {
      "x": 2,
      "y": 17,
      "z": -2,
      "name": "Rock_Stone"
    },
    {
      "x": 2,
      "y": 18,
      "z": -2,
      "name": "Soil_Dirt"
    },
    {
      "x": 2,
      "y": 19,
      "z": -2,
      "name": "Rock_Stone"
    },
    {
      "x": 2,
      "y": 20,
      "z": -2,
      "name": "Rock_Stone"
    },
    {
      "x": 2,
      "y": 21,
      "z": -2,
      "name": "Soil_Dirt"
    },
    {
      "x": 2,
      "y": 22,
      "z": -2,
      "name": "Soil_Grass"
    },
    {
      "x": 2,
      "y": 9,
      "z": -1,
      "name": "Rock_Stone"
    },
    {
      "x": 2,
      "y": 10,
      "z": -1,
      "name": "Rock_Stone"
    },
    {
      "x": 2,
      "y": 11,
      "z": -1,
      "name": "Rock_Stone"
    },
    {
      "x": 2,
      "y": 12,
      "z": -1,
      "name": "Rock_Stone"
    },
    {
      "x": 2,
      "y": 13,
      "z": -1,
      "name": "Rock_Stone"
    },
    {
      "x": 2,
      "y": 14,
      "z": -1,
      "name": "Rock_Stone"
    },
    {
      "x": 2,
      "y": 15,
      "z": -1,
      "name": "Rock_Stone"
    },
    {
      "x": 2,
      "y": 16,
      "z": -1,
      "name": "Rock_Stone"
    },
    {
      "x": 2,
      "y": 17,
      "z": -1,
      "name": "Rock_Stone"
    },
    {
      "x": 2,
      "y": 18,
      "z": -1,
      "name": "Rock_Stone"
    },
    {
      "x": 2,
      "y": 19,
      "z": -1,
      "name": "Rock_Stone"
    },
    {
      "x": 2,
      "y": 20,
      "z": -1,
      "name": "Rock_Stone"
    },
    {
      "x": 2,
      "y": 21,
      "z": -1,
      "name": "Soil_Dirt"
    },
    {
      "x": 2,
      "y": 22,
      "z": -1,
      "name": "Soil_Grass"
    },
    {
      "x": 2,
      "y": 9,
      "z": 0,
      "name": "Rock_Stone"
    },
    {
      "x": 2,
      "y": 10,
      "z": 0,
      "name": "Rock_Stone"
    },
    {
      "x": 2,
      "y": 11,
      "z": 0,
      "name": "Rock_Stone"
    },
    {
      "x": 2,
      "y": 12,
      "z": 0,
      "name": "Rock_Stone"
    },
    {
      "x": 2,
      "y": 13,
      "z": 0,
      "name": "Rock_Stone"
    },
    {
      "x": 2,
      "y": 14,
      "z": 0,
      "name": "Rock_Stone"
    },
    {
      "x": 2,
      "y": 15,
      "z": 0,
      "name": "Rock_Stone"
    },
    {
      "x": 2,
      "y": 16,
      "z": 0,
      "name": "Rock_Stone"
    },
    {
      "x": 2,
      "y": 17,
      "z": 0,
      "name": "Rock_Stone"
    },
    {
      "x": 2,
      "y": 18,
      "z": 0,
      "name": "Rock_Stone"
    },
    {
      "x": 2,
      "y": 19,
      "z": 0,
      "name": "Rock_Stone"
    },
    {
      "x": 2,
      "y": 20,
      "z": 0,
      "name": "Rock_Stone"
    },
    {
      "x": 2,
      "y": 21,
      "z": 0,
      "name": "Soil_Dirt"
    },
    {
      "x": 2,
      "y": 22,
      "z": 0,
      "name": "Soil_Grass"
    },
    {
      "x": 2,
      "y": 23,
      "z": 0,
      "name": "Plant_Grass_Sharp"
    },
    {
      "x": 2,
      "y": 10,
      "z": 1,
      "name": "Rock_Stone"
    },
    {
      "x": 2,
      "y": 11,
      "z": 1,
      "name": "Rock_Stone"
    },
    {
      "x": 2,
      "y": 12,
      "z": 1,
      "name": "Rock_Stone"
    },
    {
      "x": 2,
      "y": 13,
      "z": 1,
      "name": "Rock_Stone"
    },
    {
      "x": 2,
      "y": 14,
      "z": 1,
      "name": "Rock_Stone"
    },
    {
      "x": 2,
      "y": 15,
      "z": 1,
      "name": "Rock_Stone"
    },
    {
      "x": 2,
      "y": 16,
      "z": 1,
      "name": "Rock_Stone"
    },
    {
      "x": 2,
      "y": 17,
      "z": 1,
      "name": "Rock_Stone"
    },
    {
      "x": 2,
      "y": 18,
      "z": 1,
      "name": "Rock_Stone"
    },
    {
      "x": 2,
      "y": 19,
      "z": 1,
      "name": "Rock_Stone"
    },
    {
      "x": 2,
      "y": 20,
      "z": 1,
      "name": "Rock_Stone"
    },
    {
      "x": 2,
      "y": 21,
      "z": 1,
      "name": "Rock_Stone"
    },
    {
      "x": 2,
      "y": 10,
      "z": 2,
      "name": "Rock_Stone"
    },
    {
      "x": 2,
      "y": 11,
      "z": 2,
      "name": "Rock_Stone"
    },
    {
      "x": 2,
      "y": 12,
      "z": 2,
      "name": "Rock_Stone"
    },
    {
      "x": 2,
      "y": 13,
      "z": 2,
      "name": "Rock_Stone"
    },
    {
      "x": 2,
      "y": 14,
      "z": 2,
      "name": "Rock_Stone"
    },
    {
      "x": 2,
      "y": 15,
      "z": 2,
      "name": "Rock_Stone"
    },
    {
      "x": 2,
      "y": 16,
      "z": 2,
      "name": "Rock_Stone"
    },
    {
      "x": 2,
      "y": 17,
      "z": 2,
      "name": "Soil_Grass"
    },
    {
      "x": 2,
      "y": 10,
      "z": 3,
      "name": "Rock_Stone"
    },
    {
      "x": 2,
      "y": 11,
      "z": 3,
      "name": "Rock_Stone"
    },
    {
      "x": 2,
      "y": 12,
      "z": 3,
      "name": "Rock_Stone"
    },
    {
      "x": 2,
      "y": 13,
      "z": 3,
      "name": "Rock_Stone"
    },
    {
      "x": 2,
      "y": 14,
      "z": 3,
      "name": "Rock_Stone"
    },
    {
      "x": 2,
      "y": 15,
      "z": 3,
      "name": "Rock_Stone"
    },
    {
      "x": 2,
      "y": 16,
      "z": 3,
      "name": "Rock_Stone"
    },
    {
      "x": 2,
      "y": 17,
      "z": 3,
      "name": "Soil_Grass"
    },
    {
      "x": 2,
      "y": 10,
      "z": 4,
      "name": "Rock_Stone"
    },
    {
      "x": 2,
      "y": 11,
      "z": 4,
      "name": "Rock_Stone"
    },
    {
      "x": 2,
      "y": 12,
      "z": 4,
      "name": "Rock_Stone"
    },
    {
      "x": 2,
      "y": 13,
      "z": 4,
      "name": "Rock_Stone"
    },
    {
      "x": 2,
      "y": 14,
      "z": 4,
      "name": "Soil_Dirt"
    },
    {
      "x": 2,
      "y": 15,
      "z": 4,
      "name": "Rock_Stone"
    },
    {
      "x": 2,
      "y": 16,
      "z": 4,
      "name": "Soil_Dirt"
    },
    {
      "x": 2,
      "y": 17,
      "z": 4,
      "name": "Soil_Grass"
    },
    {
      "x": 2,
      "y": 18,
      "z": 4,
      "name": "*Plant_Crop_Berry_Block_State_Definitions_StageFinal",
      "components": {
        "Components": {
          "FarmingBlock": {}
        }
      }
    },
    {
      "x": 2,
      "y": 11,
      "z": 5,
      "name": "Rock_Stone"
    },
    {
      "x": 2,
      "y": 12,
      "z": 5,
      "name": "Rock_Stone"
    },
    {
      "x": 2,
      "y": 13,
      "z": 5,
      "name": "Rock_Stone"
    },
    {
      "x": 2,
      "y": 14,
      "z": 5,
      "name": "Soil_Dirt"
    },
    {
      "x": 2,
      "y": 15,
      "z": 5,
      "name": "Soil_Dirt"
    },
    {
      "x": 2,
      "y": 16,
      "z": 5,
      "name": "Soil_Grass"
    },
    {
      "x": 2,
      "y": 12,
      "z": 6,
      "name": "Rock_Stone"
    },
    {
      "x": 2,
      "y": 13,
      "z": 6,
      "name": "Rock_Stone"
    },
    {
      "x": 2,
      "y": 14,
      "z": 6,
      "name": "Soil_Dirt"
    },
    {
      "x": 2,
      "y": 15,
      "z": 6,
      "name": "Soil_Dirt"
    },
    {
      "x": 2,
      "y": 16,
      "z": 6,
      "name": "Soil_Grass"
    },
    {
      "x": 3,
      "y": 18,
      "z": -9,
      "name": "Soil_Dirt"
    },
    {
      "x": 3,
      "y": 19,
      "z": -9,
      "name": "Soil_Dirt"
    },
    {
      "x": 3,
      "y": 20,
      "z": -9,
      "name": "Soil_Grass"
    },
    {
      "x": 3,
      "y": 13,
      "z": -8,
      "name": "Rock_Stone"
    },
    {
      "x": 3,
      "y": 14,
      "z": -8,
      "name": "Rock_Stone"
    },
    {
      "x": 3,
      "y": 15,
      "z": -8,
      "name": "Rock_Stone"
    },
    {
      "x": 3,
      "y": 16,
      "z": -8,
      "name": "Rock_Stone"
    },
    {
      "x": 3,
      "y": 17,
      "z": -8,
      "name": "Rock_Stone_Mossy"
    },
    {
      "x": 3,
      "y": 18,
      "z": -8,
      "name": "Soil_Dirt"
    },
    {
      "x": 3,
      "y": 19,
      "z": -8,
      "name": "Soil_Dirt"
    },
    {
      "x": 3,
      "y": 20,
      "z": -8,
      "name": "Soil_Grass"
    },
    {
      "x": 3,
      "y": 12,
      "z": -7,
      "name": "Rock_Stone"
    },
    {
      "x": 3,
      "y": 13,
      "z": -7,
      "name": "Rock_Stone"
    },
    {
      "x": 3,
      "y": 14,
      "z": -7,
      "name": "Rock_Stone"
    },
    {
      "x": 3,
      "y": 15,
      "z": -7,
      "name": "Rock_Stone"
    },
    {
      "x": 3,
      "y": 16,
      "z": -7,
      "name": "Rock_Stone"
    },
    {
      "x": 3,
      "y": 17,
      "z": -7,
      "name": "Rock_Stone"
    },
    {
      "x": 3,
      "y": 18,
      "z": -7,
      "name": "Soil_Dirt"
    },
    {
      "x": 3,
      "y": 19,
      "z": -7,
      "name": "Soil_Dirt"
    },
    {
      "x": 3,
      "y": 20,
      "z": -7,
      "name": "Soil_Grass"
    },
    {
      "x": 3,
      "y": 11,
      "z": -6,
      "name": "Rock_Stone"
    },
    {
      "x": 3,
      "y": 12,
      "z": -6,
      "name": "Rock_Stone"
    },
    {
      "x": 3,
      "y": 13,
      "z": -6,
      "name": "Rock_Stone"
    },
    {
      "x": 3,
      "y": 14,
      "z": -6,
      "name": "Rock_Stone"
    },
    {
      "x": 3,
      "y": 15,
      "z": -6,
      "name": "Rock_Stone"
    },
    {
      "x": 3,
      "y": 16,
      "z": -6,
      "name": "Rock_Stone"
    },
    {
      "x": 3,
      "y": 17,
      "z": -6,
      "name": "Rock_Stone"
    },
    {
      "x": 3,
      "y": 18,
      "z": -6,
      "name": "Rock_Stone"
    },
    {
      "x": 3,
      "y": 19,
      "z": -6,
      "name": "Soil_Dirt"
    },
    {
      "x": 3,
      "y": 20,
      "z": -6,
      "name": "Soil_Grass"
    },
    {
      "x": 3,
      "y": 21,
      "z": -6,
      "name": "Plant_Grass_Sharp"
    },
    {
      "x": 3,
      "y": 10,
      "z": -5,
      "name": "Rock_Stone"
    },
    {
      "x": 3,
      "y": 11,
      "z": -5,
      "name": "Rock_Stone"
    },
    {
      "x": 3,
      "y": 12,
      "z": -5,
      "name": "Rock_Stone"
    },
    {
      "x": 3,
      "y": 13,
      "z": -5,
      "name": "Rock_Stone"
    },
    {
      "x": 3,
      "y": 14,
      "z": -5,
      "name": "Rock_Stone"
    },
    {
      "x": 3,
      "y": 15,
      "z": -5,
      "name": "Rock_Stone"
    },
    {
      "x": 3,
      "y": 16,
      "z": -5,
      "name": "Rock_Stone"
    },
    {
      "x": 3,
      "y": 17,
      "z": -5,
      "name": "Rock_Stone"
    },
    {
      "x": 3,
      "y": 18,
      "z": -5,
      "name": "Rock_Stone"
    },
    {
      "x": 3,
      "y": 19,
      "z": -5,
      "name": "Soil_Dirt"
    },
    {
      "x": 3,
      "y": 20,
      "z": -5,
      "name": "Soil_Dirt"
    },
    {
      "x": 3,
      "y": 21,
      "z": -5,
      "name": "Soil_Grass"
    },
    {
      "x": 3,
      "y": 9,
      "z": -4,
      "name": "Rock_Stone"
    },
    {
      "x": 3,
      "y": 10,
      "z": -4,
      "name": "Rock_Stone"
    },
    {
      "x": 3,
      "y": 11,
      "z": -4,
      "name": "Rock_Stone"
    },
    {
      "x": 3,
      "y": 12,
      "z": -4,
      "name": "Rock_Stone"
    },
    {
      "x": 3,
      "y": 13,
      "z": -4,
      "name": "Rock_Stone"
    },
    {
      "x": 3,
      "y": 14,
      "z": -4,
      "name": "Rock_Stone"
    },
    {
      "x": 3,
      "y": 15,
      "z": -4,
      "name": "Rock_Stone"
    },
    {
      "x": 3,
      "y": 16,
      "z": -4,
      "name": "Rock_Stone"
    },
    {
      "x": 3,
      "y": 17,
      "z": -4,
      "name": "Rock_Stone"
    },
    {
      "x": 3,
      "y": 18,
      "z": -4,
      "name": "Rock_Stone"
    },
    {
      "x": 3,
      "y": 19,
      "z": -4,
      "name": "Soil_Dirt"
    },
    {
      "x": 3,
      "y": 20,
      "z": -4,
      "name": "Soil_Dirt"
    },
    {
      "x": 3,
      "y": 21,
      "z": -4,
      "name": "Soil_Grass"
    },
    {
      "x": 3,
      "y": 9,
      "z": -3,
      "name": "Rock_Stone"
    },
    {
      "x": 3,
      "y": 10,
      "z": -3,
      "name": "Rock_Stone"
    },
    {
      "x": 3,
      "y": 11,
      "z": -3,
      "name": "Rock_Stone"
    },
    {
      "x": 3,
      "y": 12,
      "z": -3,
      "name": "Rock_Stone"
    },
    {
      "x": 3,
      "y": 13,
      "z": -3,
      "name": "Rock_Stone"
    },
    {
      "x": 3,
      "y": 14,
      "z": -3,
      "name": "Rock_Stone"
    },
    {
      "x": 3,
      "y": 15,
      "z": -3,
      "name": "Rock_Stone"
    },
    {
      "x": 3,
      "y": 16,
      "z": -3,
      "name": "Rock_Stone"
    },
    {
      "x": 3,
      "y": 17,
      "z": -3,
      "name": "Rock_Stone"
    },
    {
      "x": 3,
      "y": 18,
      "z": -3,
      "name": "Soil_Dirt"
    },
    {
      "x": 3,
      "y": 19,
      "z": -3,
      "name": "Soil_Dirt"
    },
    {
      "x": 3,
      "y": 20,
      "z": -3,
      "name": "Soil_Grass"
    },
    {
      "x": 3,
      "y": 9,
      "z": -2,
      "name": "Rock_Stone"
    },
    {
      "x": 3,
      "y": 10,
      "z": -2,
      "name": "Rock_Stone"
    },
    {
      "x": 3,
      "y": 11,
      "z": -2,
      "name": "Rock_Stone"
    },
    {
      "x": 3,
      "y": 12,
      "z": -2,
      "name": "Rock_Stone"
    },
    {
      "x": 3,
      "y": 13,
      "z": -2,
      "name": "Rock_Stone"
    },
    {
      "x": 3,
      "y": 14,
      "z": -2,
      "name": "Rock_Stone"
    },
    {
      "x": 3,
      "y": 15,
      "z": -2,
      "name": "Rock_Stone"
    },
    {
      "x": 3,
      "y": 16,
      "z": -2,
      "name": "Rock_Stone"
    },
    {
      "x": 3,
      "y": 17,
      "z": -2,
      "name": "Soil_Dirt"
    },
    {
      "x": 3,
      "y": 18,
      "z": -2,
      "name": "Soil_Dirt"
    },
    {
      "x": 3,
      "y": 19,
      "z": -2,
      "name": "Soil_Dirt"
    },
    {
      "x": 3,
      "y": 20,
      "z": -2,
      "name": "Soil_Grass"
    },
    {
      "x": 3,
      "y": 9,
      "z": -1,
      "name": "Rock_Stone"
    },
    {
      "x": 3,
      "y": 10,
      "z": -1,
      "name": "Rock_Stone"
    },
    {
      "x": 3,
      "y": 11,
      "z": -1,
      "name": "Rock_Stone"
    },
    {
      "x": 3,
      "y": 12,
      "z": -1,
      "name": "Rock_Stone"
    },
    {
      "x": 3,
      "y": 13,
      "z": -1,
      "name": "Rock_Stone"
    },
    {
      "x": 3,
      "y": 14,
      "z": -1,
      "name": "Rock_Stone"
    },
    {
      "x": 3,
      "y": 15,
      "z": -1,
      "name": "Rock_Stone"
    },
    {
      "x": 3,
      "y": 16,
      "z": -1,
      "name": "Rock_Stone"
    },
    {
      "x": 3,
      "y": 17,
      "z": -1,
      "name": "Soil_Dirt"
    },
    {
      "x": 3,
      "y": 18,
      "z": -1,
      "name": "Rock_Stone"
    },
    {
      "x": 3,
      "y": 19,
      "z": -1,
      "name": "Rock_Stone"
    },
    {
      "x": 3,
      "y": 20,
      "z": -1,
      "name": "Rock_Stone"
    },
    {
      "x": 3,
      "y": 21,
      "z": -1,
      "name": "Soil_Dirt"
    },
    {
      "x": 3,
      "y": 22,
      "z": -1,
      "name": "Soil_Grass"
    },
    {
      "x": 3,
      "y": 9,
      "z": 0,
      "name": "Rock_Stone"
    },
    {
      "x": 3,
      "y": 10,
      "z": 0,
      "name": "Rock_Stone"
    },
    {
      "x": 3,
      "y": 11,
      "z": 0,
      "name": "Rock_Stone"
    },
    {
      "x": 3,
      "y": 12,
      "z": 0,
      "name": "Rock_Stone"
    },
    {
      "x": 3,
      "y": 13,
      "z": 0,
      "name": "Rock_Stone"
    },
    {
      "x": 3,
      "y": 14,
      "z": 0,
      "name": "Rock_Stone"
    },
    {
      "x": 3,
      "y": 15,
      "z": 0,
      "name": "Rock_Stone"
    },
    {
      "x": 3,
      "y": 16,
      "z": 0,
      "name": "Rock_Stone"
    },
    {
      "x": 3,
      "y": 17,
      "z": 0,
      "name": "Soil_Dirt"
    },
    {
      "x": 3,
      "y": 18,
      "z": 0,
      "name": "Rock_Stone"
    },
    {
      "x": 3,
      "y": 19,
      "z": 0,
      "name": "Rock_Stone"
    },
    {
      "x": 3,
      "y": 20,
      "z": 0,
      "name": "Rock_Stone"
    },
    {
      "x": 3,
      "y": 21,
      "z": 0,
      "name": "Soil_Dirt"
    },
    {
      "x": 3,
      "y": 22,
      "z": 0,
      "name": "Soil_Grass"
    },
    {
      "x": 3,
      "y": 10,
      "z": 1,
      "name": "Rock_Stone"
    },
    {
      "x": 3,
      "y": 11,
      "z": 1,
      "name": "Rock_Stone"
    },
    {
      "x": 3,
      "y": 12,
      "z": 1,
      "name": "Rock_Stone"
    },
    {
      "x": 3,
      "y": 13,
      "z": 1,
      "name": "Rock_Stone"
    },
    {
      "x": 3,
      "y": 14,
      "z": 1,
      "name": "Rock_Stone"
    },
    {
      "x": 3,
      "y": 15,
      "z": 1,
      "name": "Rock_Stone"
    },
    {
      "x": 3,
      "y": 16,
      "z": 1,
      "name": "Rock_Stone"
    },
    {
      "x": 3,
      "y": 17,
      "z": 1,
      "name": "Soil_Dirt"
    },
    {
      "x": 3,
      "y": 18,
      "z": 1,
      "name": "Soil_Dirt"
    },
    {
      "x": 3,
      "y": 19,
      "z": 1,
      "name": "Rock_Stone"
    },
    {
      "x": 3,
      "y": 20,
      "z": 1,
      "name": "Rock_Stone"
    },
    {
      "x": 3,
      "y": 10,
      "z": 2,
      "name": "Rock_Stone"
    },
    {
      "x": 3,
      "y": 11,
      "z": 2,
      "name": "Rock_Stone"
    },
    {
      "x": 3,
      "y": 12,
      "z": 2,
      "name": "Rock_Stone"
    },
    {
      "x": 3,
      "y": 13,
      "z": 2,
      "name": "Rock_Stone"
    },
    {
      "x": 3,
      "y": 14,
      "z": 2,
      "name": "Rock_Stone"
    },
    {
      "x": 3,
      "y": 15,
      "z": 2,
      "name": "Rock_Stone"
    },
    {
      "x": 3,
      "y": 16,
      "z": 2,
      "name": "Soil_Dirt"
    },
    {
      "x": 3,
      "y": 17,
      "z": 2,
      "name": "Soil_Dirt"
    },
    {
      "x": 3,
      "y": 18,
      "z": 2,
      "name": "Soil_Grass"
    },
    {
      "x": 3,
      "y": 10,
      "z": 3,
      "name": "Rock_Stone"
    },
    {
      "x": 3,
      "y": 11,
      "z": 3,
      "name": "Rock_Stone"
    },
    {
      "x": 3,
      "y": 12,
      "z": 3,
      "name": "Rock_Stone"
    },
    {
      "x": 3,
      "y": 13,
      "z": 3,
      "name": "Rock_Stone"
    },
    {
      "x": 3,
      "y": 14,
      "z": 3,
      "name": "Rock_Stone"
    },
    {
      "x": 3,
      "y": 15,
      "z": 3,
      "name": "Rock_Stone"
    },
    {
      "x": 3,
      "y": 16,
      "z": 3,
      "name": "Soil_Dirt"
    },
    {
      "x": 3,
      "y": 17,
      "z": 3,
      "name": "Soil_Grass"
    },
    {
      "x": 3,
      "y": 10,
      "z": 4,
      "name": "Rock_Stone"
    },
    {
      "x": 3,
      "y": 11,
      "z": 4,
      "name": "Rock_Stone"
    },
    {
      "x": 3,
      "y": 12,
      "z": 4,
      "name": "Rock_Stone"
    },
    {
      "x": 3,
      "y": 13,
      "z": 4,
      "name": "Rock_Stone"
    },
    {
      "x": 3,
      "y": 14,
      "z": 4,
      "name": "Rock_Stone"
    },
    {
      "x": 3,
      "y": 15,
      "z": 4,
      "name": "Rock_Stone"
    },
    {
      "x": 3,
      "y": 16,
      "z": 4,
      "name": "Soil_Dirt"
    },
    {
      "x": 3,
      "y": 17,
      "z": 4,
      "name": "Soil_Grass"
    },
    {
      "x": 3,
      "y": 18,
      "z": 4,
      "name": "Plant_Grass_Sharp"
    },
    {
      "x": 3,
      "y": 11,
      "z": 5,
      "name": "Rock_Stone"
    },
    {
      "x": 3,
      "y": 12,
      "z": 5,
      "name": "Rock_Stone"
    },
    {
      "x": 3,
      "y": 13,
      "z": 5,
      "name": "Rock_Stone"
    },
    {
      "x": 3,
      "y": 14,
      "z": 5,
      "name": "Rock_Stone"
    },
    {
      "x": 3,
      "y": 15,
      "z": 5,
      "name": "Soil_Dirt"
    },
    {
      "x": 3,
      "y": 16,
      "z": 5,
      "name": "Soil_Dirt"
    },
    {
      "x": 3,
      "y": 17,
      "z": 5,
      "name": "Soil_Grass"
    },
    {
      "x": 3,
      "y": 18,
      "z": 5,
      "name": "Plant_Grass_Sharp"
    },
    {
      "x": 3,
      "y": 12,
      "z": 6,
      "name": "Rock_Stone"
    },
    {
      "x": 3,
      "y": 13,
      "z": 6,
      "name": "Rock_Stone"
    },
    {
      "x": 3,
      "y": 14,
      "z": 6,
      "name": "Rock_Stone"
    },
    {
      "x": 3,
      "y": 15,
      "z": 6,
      "name": "Soil_Dirt"
    },
    {
      "x": 3,
      "y": 16,
      "z": 6,
      "name": "Soil_Grass"
    },
    {
      "x": 4,
      "y": 13,
      "z": -8,
      "name": "Rock_Stone"
    },
    {
      "x": 4,
      "y": 14,
      "z": -8,
      "name": "Rock_Stone"
    },
    {
      "x": 4,
      "y": 15,
      "z": -8,
      "name": "Rock_Stone"
    },
    {
      "x": 4,
      "y": 16,
      "z": -8,
      "name": "Rock_Stone_Mossy"
    },
    {
      "x": 4,
      "y": 17,
      "z": -8,
      "name": "Rock_Stone_Mossy"
    },
    {
      "x": 4,
      "y": 18,
      "z": -8,
      "name": "Soil_Dirt"
    },
    {
      "x": 4,
      "y": 19,
      "z": -8,
      "name": "Soil_Dirt"
    },
    {
      "x": 4,
      "y": 20,
      "z": -8,
      "name": "Soil_Grass"
    },
    {
      "x": 4,
      "y": 13,
      "z": -7,
      "name": "Rock_Stone"
    },
    {
      "x": 4,
      "y": 14,
      "z": -7,
      "name": "Rock_Stone"
    },
    {
      "x": 4,
      "y": 15,
      "z": -7,
      "name": "Rock_Stone"
    },
    {
      "x": 4,
      "y": 16,
      "z": -7,
      "name": "Rock_Stone"
    },
    {
      "x": 4,
      "y": 17,
      "z": -7,
      "name": "Rock_Stone_Mossy"
    },
    {
      "x": 4,
      "y": 18,
      "z": -7,
      "name": "Soil_Dirt"
    },
    {
      "x": 4,
      "y": 19,
      "z": -7,
      "name": "Soil_Dirt"
    },
    {
      "x": 4,
      "y": 20,
      "z": -7,
      "name": "Soil_Grass"
    },
    {
      "x": 4,
      "y": 12,
      "z": -6,
      "name": "Rock_Stone"
    },
    {
      "x": 4,
      "y": 13,
      "z": -6,
      "name": "Rock_Stone"
    },
    {
      "x": 4,
      "y": 14,
      "z": -6,
      "name": "Rock_Stone"
    },
    {
      "x": 4,
      "y": 15,
      "z": -6,
      "name": "Rock_Stone"
    },
    {
      "x": 4,
      "y": 16,
      "z": -6,
      "name": "Rock_Stone"
    },
    {
      "x": 4,
      "y": 17,
      "z": -6,
      "name": "Rock_Stone"
    },
    {
      "x": 4,
      "y": 18,
      "z": -6,
      "name": "Rock_Stone"
    },
    {
      "x": 4,
      "y": 19,
      "z": -6,
      "name": "Soil_Dirt"
    },
    {
      "x": 4,
      "y": 20,
      "z": -6,
      "name": "Soil_Grass"
    },
    {
      "x": 4,
      "y": 21,
      "z": -6,
      "name": "Plant_Grass_Sharp"
    },
    {
      "x": 4,
      "y": 10,
      "z": -5,
      "name": "Rock_Stone"
    },
    {
      "x": 4,
      "y": 11,
      "z": -5,
      "name": "Rock_Stone"
    },
    {
      "x": 4,
      "y": 12,
      "z": -5,
      "name": "Rock_Stone_Mossy"
    },
    {
      "x": 4,
      "y": 13,
      "z": -5,
      "name": "Rock_Stone"
    },
    {
      "x": 4,
      "y": 14,
      "z": -5,
      "name": "Rock_Stone"
    },
    {
      "x": 4,
      "y": 15,
      "z": -5,
      "name": "Rock_Stone"
    },
    {
      "x": 4,
      "y": 16,
      "z": -5,
      "name": "Rock_Stone"
    },
    {
      "x": 4,
      "y": 17,
      "z": -5,
      "name": "Rock_Stone"
    },
    {
      "x": 4,
      "y": 18,
      "z": -5,
      "name": "Rock_Stone"
    },
    {
      "x": 4,
      "y": 19,
      "z": -5,
      "name": "Soil_Dirt"
    },
    {
      "x": 4,
      "y": 20,
      "z": -5,
      "name": "Soil_Grass"
    },
    {
      "x": 4,
      "y": 21,
      "z": -5,
      "name": "Plant_Grass_Sharp"
    },
    {
      "x": 4,
      "y": 10,
      "z": -4,
      "name": "Rock_Stone"
    },
    {
      "x": 4,
      "y": 11,
      "z": -4,
      "name": "Rock_Stone"
    },
    {
      "x": 4,
      "y": 12,
      "z": -4,
      "name": "Rock_Stone"
    },
    {
      "x": 4,
      "y": 13,
      "z": -4,
      "name": "Rock_Stone"
    },
    {
      "x": 4,
      "y": 14,
      "z": -4,
      "name": "Rock_Stone"
    },
    {
      "x": 4,
      "y": 15,
      "z": -4,
      "name": "Rock_Stone"
    },
    {
      "x": 4,
      "y": 16,
      "z": -4,
      "name": "Rock_Stone"
    },
    {
      "x": 4,
      "y": 17,
      "z": -4,
      "name": "Rock_Stone"
    },
    {
      "x": 4,
      "y": 18,
      "z": -4,
      "name": "Rock_Stone"
    },
    {
      "x": 4,
      "y": 19,
      "z": -4,
      "name": "Soil_Dirt"
    },
    {
      "x": 4,
      "y": 20,
      "z": -4,
      "name": "Soil_Grass"
    },
    {
      "x": 4,
      "y": 9,
      "z": -3,
      "name": "Rock_Stone"
    },
    {
      "x": 4,
      "y": 10,
      "z": -3,
      "name": "Rock_Stone"
    },
    {
      "x": 4,
      "y": 11,
      "z": -3,
      "name": "Rock_Stone"
    },
    {
      "x": 4,
      "y": 12,
      "z": -3,
      "name": "Rock_Stone"
    },
    {
      "x": 4,
      "y": 13,
      "z": -3,
      "name": "Rock_Stone"
    },
    {
      "x": 4,
      "y": 14,
      "z": -3,
      "name": "Rock_Stone"
    },
    {
      "x": 4,
      "y": 15,
      "z": -3,
      "name": "Rock_Stone"
    },
    {
      "x": 4,
      "y": 16,
      "z": -3,
      "name": "Rock_Stone"
    },
    {
      "x": 4,
      "y": 17,
      "z": -3,
      "name": "Rock_Stone"
    },
    {
      "x": 4,
      "y": 18,
      "z": -3,
      "name": "Soil_Dirt"
    },
    {
      "x": 4,
      "y": 19,
      "z": -3,
      "name": "Soil_Dirt"
    },
    {
      "x": 4,
      "y": 20,
      "z": -3,
      "name": "Soil_Grass"
    },
    {
      "x": 4,
      "y": 9,
      "z": -2,
      "name": "Rock_Stone"
    },
    {
      "x": 4,
      "y": 10,
      "z": -2,
      "name": "Rock_Stone"
    },
    {
      "x": 4,
      "y": 11,
      "z": -2,
      "name": "Rock_Stone"
    },
    {
      "x": 4,
      "y": 12,
      "z": -2,
      "name": "Rock_Stone"
    },
    {
      "x": 4,
      "y": 13,
      "z": -2,
      "name": "Rock_Stone"
    },
    {
      "x": 4,
      "y": 14,
      "z": -2,
      "name": "Rock_Stone"
    },
    {
      "x": 4,
      "y": 15,
      "z": -2,
      "name": "Rock_Stone"
    },
    {
      "x": 4,
      "y": 16,
      "z": -2,
      "name": "Rock_Stone"
    },
    {
      "x": 4,
      "y": 17,
      "z": -2,
      "name": "Soil_Dirt"
    },
    {
      "x": 4,
      "y": 18,
      "z": -2,
      "name": "Soil_Dirt"
    },
    {
      "x": 4,
      "y": 19,
      "z": -2,
      "name": "Soil_Grass"
    },
    {
      "x": 4,
      "y": 9,
      "z": -1,
      "name": "Rock_Stone"
    },
    {
      "x": 4,
      "y": 10,
      "z": -1,
      "name": "Rock_Stone"
    },
    {
      "x": 4,
      "y": 11,
      "z": -1,
      "name": "Rock_Stone"
    },
    {
      "x": 4,
      "y": 12,
      "z": -1,
      "name": "Rock_Stone"
    },
    {
      "x": 4,
      "y": 13,
      "z": -1,
      "name": "Rock_Stone"
    },
    {
      "x": 4,
      "y": 14,
      "z": -1,
      "name": "Rock_Stone"
    },
    {
      "x": 4,
      "y": 15,
      "z": -1,
      "name": "Rock_Stone"
    },
    {
      "x": 4,
      "y": 16,
      "z": -1,
      "name": "Rock_Stone"
    },
    {
      "x": 4,
      "y": 17,
      "z": -1,
      "name": "Soil_Dirt"
    },
    {
      "x": 4,
      "y": 18,
      "z": -1,
      "name": "Soil_Grass"
    },
    {
      "x": 4,
      "y": 10,
      "z": 0,
      "name": "Rock_Stone"
    },
    {
      "x": 4,
      "y": 11,
      "z": 0,
      "name": "Rock_Stone"
    },
    {
      "x": 4,
      "y": 12,
      "z": 0,
      "name": "Rock_Stone"
    },
    {
      "x": 4,
      "y": 13,
      "z": 0,
      "name": "Rock_Stone"
    },
    {
      "x": 4,
      "y": 14,
      "z": 0,
      "name": "Rock_Stone"
    },
    {
      "x": 4,
      "y": 15,
      "z": 0,
      "name": "Rock_Stone"
    },
    {
      "x": 4,
      "y": 16,
      "z": 0,
      "name": "Rock_Stone"
    },
    {
      "x": 4,
      "y": 17,
      "z": 0,
      "name": "Soil_Dirt"
    },
    {
      "x": 4,
      "y": 18,
      "z": 0,
      "name": "Soil_Grass"
    },
    {
      "x": 4,
      "y": 10,
      "z": 1,
      "name": "Rock_Stone"
    },
    {
      "x": 4,
      "y": 11,
      "z": 1,
      "name": "Rock_Stone"
    },
    {
      "x": 4,
      "y": 12,
      "z": 1,
      "name": "Rock_Stone"
    },
    {
      "x": 4,
      "y": 13,
      "z": 1,
      "name": "Rock_Stone"
    },
    {
      "x": 4,
      "y": 14,
      "z": 1,
      "name": "Rock_Stone"
    },
    {
      "x": 4,
      "y": 15,
      "z": 1,
      "name": "Rock_Stone"
    },
    {
      "x": 4,
      "y": 16,
      "z": 1,
      "name": "Rock_Stone"
    },
    {
      "x": 4,
      "y": 17,
      "z": 1,
      "name": "Soil_Dirt"
    },
    {
      "x": 4,
      "y": 18,
      "z": 1,
      "name": "Soil_Grass"
    },
    {
      "x": 4,
      "y": 19,
      "z": 1,
      "name": "Plant_Grass_Sharp"
    },
    {
      "x": 4,
      "y": 10,
      "z": 2,
      "name": "Rock_Stone"
    },
    {
      "x": 4,
      "y": 11,
      "z": 2,
      "name": "Rock_Stone"
    },
    {
      "x": 4,
      "y": 12,
      "z": 2,
      "name": "Rock_Stone"
    },
    {
      "x": 4,
      "y": 13,
      "z": 2,
      "name": "Rock_Stone"
    },
    {
      "x": 4,
      "y": 14,
      "z": 2,
      "name": "Rock_Stone"
    },
    {
      "x": 4,
      "y": 15,
      "z": 2,
      "name": "Rock_Stone"
    },
    {
      "x": 4,
      "y": 16,
      "z": 2,
      "name": "Soil_Dirt"
    },
    {
      "x": 4,
      "y": 17,
      "z": 2,
      "name": "Soil_Dirt"
    },
    {
      "x": 4,
      "y": 18,
      "z": 2,
      "name": "Soil_Grass"
    },
    {
      "x": 4,
      "y": 19,
      "z": 2,
      "name": "Plant_Grass_Sharp"
    },
    {
      "x": 4,
      "y": 10,
      "z": 3,
      "name": "Rock_Stone"
    },
    {
      "x": 4,
      "y": 11,
      "z": 3,
      "name": "Rock_Stone"
    },
    {
      "x": 4,
      "y": 12,
      "z": 3,
      "name": "Rock_Stone"
    },
    {
      "x": 4,
      "y": 13,
      "z": 3,
      "name": "Rock_Stone"
    },
    {
      "x": 4,
      "y": 14,
      "z": 3,
      "name": "Rock_Stone"
    },
    {
      "x": 4,
      "y": 15,
      "z": 3,
      "name": "Rock_Stone"
    },
    {
      "x": 4,
      "y": 16,
      "z": 3,
      "name": "Soil_Dirt"
    },
    {
      "x": 4,
      "y": 17,
      "z": 3,
      "name": "Soil_Grass"
    },
    {
      "x": 4,
      "y": 10,
      "z": 4,
      "name": "Rock_Stone"
    },
    {
      "x": 4,
      "y": 11,
      "z": 4,
      "name": "Rock_Stone"
    },
    {
      "x": 4,
      "y": 12,
      "z": 4,
      "name": "Rock_Stone"
    },
    {
      "x": 4,
      "y": 13,
      "z": 4,
      "name": "Rock_Stone"
    },
    {
      "x": 4,
      "y": 14,
      "z": 4,
      "name": "Rock_Stone"
    },
    {
      "x": 4,
      "y": 15,
      "z": 4,
      "name": "Rock_Stone"
    },
    {
      "x": 4,
      "y": 16,
      "z": 4,
      "name": "Soil_Dirt"
    },
    {
      "x": 4,
      "y": 17,
      "z": 4,
      "name": "Soil_Grass"
    },
    {
      "x": 4,
      "y": 11,
      "z": 5,
      "name": "Rock_Stone"
    },
    {
      "x": 4,
      "y": 12,
      "z": 5,
      "name": "Rock_Stone"
    },
    {
      "x": 4,
      "y": 13,
      "z": 5,
      "name": "Rock_Stone"
    },
    {
      "x": 4,
      "y": 14,
      "z": 5,
      "name": "Rock_Stone"
    },
    {
      "x": 4,
      "y": 15,
      "z": 5,
      "name": "Soil_Dirt"
    },
    {
      "x": 4,
      "y": 16,
      "z": 5,
      "name": "Soil_Dirt"
    },
    {
      "x": 4,
      "y": 17,
      "z": 5,
      "name": "Soil_Grass"
    },
    {
      "x": 4,
      "y": 18,
      "z": 5,
      "name": "Plant_Grass_Sharp"
    },
    {
      "x": 4,
      "y": 13,
      "z": 6,
      "name": "Rock_Stone"
    },
    {
      "x": 4,
      "y": 14,
      "z": 6,
      "name": "Rock_Stone"
    },
    {
      "x": 4,
      "y": 15,
      "z": 6,
      "name": "Soil_Dirt"
    },
    {
      "x": 4,
      "y": 16,
      "z": 6,
      "name": "Soil_Grass"
    },
    {
      "x": 5,
      "y": 15,
      "z": -8,
      "name": "Rock_Stone"
    },
    {
      "x": 5,
      "y": 16,
      "z": -8,
      "name": "Rock_Stone"
    },
    {
      "x": 5,
      "y": 17,
      "z": -8,
      "name": "Rock_Stone_Mossy"
    },
    {
      "x": 5,
      "y": 18,
      "z": -8,
      "name": "Soil_Dirt"
    },
    {
      "x": 5,
      "y": 19,
      "z": -8,
      "name": "Soil_Dirt"
    },
    {
      "x": 5,
      "y": 20,
      "z": -8,
      "name": "Soil_Grass"
    },
    {
      "x": 5,
      "y": 13,
      "z": -7,
      "name": "Rock_Stone"
    },
    {
      "x": 5,
      "y": 14,
      "z": -7,
      "name": "Rock_Stone_Mossy"
    },
    {
      "x": 5,
      "y": 15,
      "z": -7,
      "name": "Rock_Stone"
    },
    {
      "x": 5,
      "y": 16,
      "z": -7,
      "name": "Rock_Stone"
    },
    {
      "x": 5,
      "y": 17,
      "z": -7,
      "name": "Rock_Stone"
    },
    {
      "x": 5,
      "y": 18,
      "z": -7,
      "name": "Soil_Dirt"
    },
    {
      "x": 5,
      "y": 19,
      "z": -7,
      "name": "Soil_Dirt"
    },
    {
      "x": 5,
      "y": 20,
      "z": -7,
      "name": "Soil_Grass"
    },
    {
      "x": 5,
      "y": 21,
      "z": -7,
      "name": "Plant_Grass_Sharp_Tall"
    },
    {
      "x": 5,
      "y": 22,
      "z": -7,
      "name": "Plant_Grass_Sharp_Tall",
      "filler": 1024
    },
    {
      "x": 5,
      "y": 13,
      "z": -6,
      "name": "Rock_Stone"
    },
    {
      "x": 5,
      "y": 14,
      "z": -6,
      "name": "Rock_Stone"
    },
    {
      "x": 5,
      "y": 15,
      "z": -6,
      "name": "Rock_Stone"
    },
    {
      "x": 5,
      "y": 16,
      "z": -6,
      "name": "Rock_Stone"
    },
    {
      "x": 5,
      "y": 17,
      "z": -6,
      "name": "Rock_Stone"
    },
    {
      "x": 5,
      "y": 18,
      "z": -6,
      "name": "Soil_Dirt"
    },
    {
      "x": 5,
      "y": 19,
      "z": -6,
      "name": "Soil_Dirt"
    },
    {
      "x": 5,
      "y": 20,
      "z": -6,
      "name": "Soil_Grass"
    },
    {
      "x": 5,
      "y": 21,
      "z": -6,
      "name": "Plant_Grass_Sharp"
    },
    {
      "x": 5,
      "y": 11,
      "z": -5,
      "name": "Rock_Stone_Mossy"
    },
    {
      "x": 5,
      "y": 12,
      "z": -5,
      "name": "Rock_Stone_Mossy"
    },
    {
      "x": 5,
      "y": 13,
      "z": -5,
      "name": "Rock_Stone_Mossy"
    },
    {
      "x": 5,
      "y": 14,
      "z": -5,
      "name": "Rock_Stone"
    },
    {
      "x": 5,
      "y": 15,
      "z": -5,
      "name": "Rock_Stone"
    },
    {
      "x": 5,
      "y": 16,
      "z": -5,
      "name": "Rock_Stone"
    },
    {
      "x": 5,
      "y": 17,
      "z": -5,
      "name": "Rock_Stone"
    },
    {
      "x": 5,
      "y": 18,
      "z": -5,
      "name": "Soil_Dirt"
    },
    {
      "x": 5,
      "y": 19,
      "z": -5,
      "name": "Soil_Dirt"
    },
    {
      "x": 5,
      "y": 20,
      "z": -5,
      "name": "Soil_Grass"
    },
    {
      "x": 5,
      "y": 10,
      "z": -4,
      "name": "Rock_Stone"
    },
    {
      "x": 5,
      "y": 11,
      "z": -4,
      "name": "Rock_Stone"
    },
    {
      "x": 5,
      "y": 12,
      "z": -4,
      "name": "Rock_Stone_Mossy"
    },
    {
      "x": 5,
      "y": 13,
      "z": -4,
      "name": "Rock_Stone"
    },
    {
      "x": 5,
      "y": 14,
      "z": -4,
      "name": "Rock_Stone"
    },
    {
      "x": 5,
      "y": 15,
      "z": -4,
      "name": "Rock_Stone"
    },
    {
      "x": 5,
      "y": 16,
      "z": -4,
      "name": "Rock_Stone"
    },
    {
      "x": 5,
      "y": 17,
      "z": -4,
      "name": "Rock_Stone"
    },
    {
      "x": 5,
      "y": 18,
      "z": -4,
      "name": "Rock_Stone"
    },
    {
      "x": 5,
      "y": 19,
      "z": -4,
      "name": "Soil_Dirt"
    },
    {
      "x": 5,
      "y": 20,
      "z": -4,
      "name": "Soil_Grass"
    },
    {
      "x": 5,
      "y": 10,
      "z": -3,
      "name": "Rock_Stone"
    },
    {
      "x": 5,
      "y": 11,
      "z": -3,
      "name": "Rock_Stone"
    },
    {
      "x": 5,
      "y": 12,
      "z": -3,
      "name": "Rock_Stone"
    },
    {
      "x": 5,
      "y": 13,
      "z": -3,
      "name": "Rock_Stone"
    },
    {
      "x": 5,
      "y": 14,
      "z": -3,
      "name": "Rock_Stone"
    },
    {
      "x": 5,
      "y": 15,
      "z": -3,
      "name": "Rock_Stone"
    },
    {
      "x": 5,
      "y": 16,
      "z": -3,
      "name": "Rock_Stone"
    },
    {
      "x": 5,
      "y": 17,
      "z": -3,
      "name": "Rock_Stone"
    },
    {
      "x": 5,
      "y": 18,
      "z": -3,
      "name": "Soil_Dirt"
    },
    {
      "x": 5,
      "y": 19,
      "z": -3,
      "name": "Soil_Dirt"
    },
    {
      "x": 5,
      "y": 20,
      "z": -3,
      "name": "Soil_Grass"
    },
    {
      "x": 5,
      "y": 10,
      "z": -2,
      "name": "Rock_Stone"
    },
    {
      "x": 5,
      "y": 11,
      "z": -2,
      "name": "Rock_Stone"
    },
    {
      "x": 5,
      "y": 12,
      "z": -2,
      "name": "Rock_Stone"
    },
    {
      "x": 5,
      "y": 13,
      "z": -2,
      "name": "Rock_Stone"
    },
    {
      "x": 5,
      "y": 14,
      "z": -2,
      "name": "Rock_Stone"
    },
    {
      "x": 5,
      "y": 15,
      "z": -2,
      "name": "Rock_Stone"
    },
    {
      "x": 5,
      "y": 16,
      "z": -2,
      "name": "Rock_Stone"
    },
    {
      "x": 5,
      "y": 17,
      "z": -2,
      "name": "Soil_Dirt"
    },
    {
      "x": 5,
      "y": 18,
      "z": -2,
      "name": "Soil_Dirt"
    },
    {
      "x": 5,
      "y": 19,
      "z": -2,
      "name": "Soil_Grass"
    },
    {
      "x": 5,
      "y": 10,
      "z": -1,
      "name": "Rock_Stone"
    },
    {
      "x": 5,
      "y": 11,
      "z": -1,
      "name": "Rock_Stone"
    },
    {
      "x": 5,
      "y": 12,
      "z": -1,
      "name": "Rock_Stone"
    },
    {
      "x": 5,
      "y": 13,
      "z": -1,
      "name": "Rock_Stone"
    },
    {
      "x": 5,
      "y": 14,
      "z": -1,
      "name": "Rock_Stone"
    },
    {
      "x": 5,
      "y": 15,
      "z": -1,
      "name": "Rock_Stone"
    },
    {
      "x": 5,
      "y": 16,
      "z": -1,
      "name": "Rock_Stone"
    },
    {
      "x": 5,
      "y": 17,
      "z": -1,
      "name": "Soil_Dirt"
    },
    {
      "x": 5,
      "y": 18,
      "z": -1,
      "name": "Soil_Dirt"
    },
    {
      "x": 5,
      "y": 19,
      "z": -1,
      "name": "Soil_Grass"
    },
    {
      "x": 5,
      "y": 10,
      "z": 0,
      "name": "Rock_Stone"
    },
    {
      "x": 5,
      "y": 11,
      "z": 0,
      "name": "Rock_Stone"
    },
    {
      "x": 5,
      "y": 12,
      "z": 0,
      "name": "Rock_Stone"
    },
    {
      "x": 5,
      "y": 13,
      "z": 0,
      "name": "Rock_Stone"
    },
    {
      "x": 5,
      "y": 14,
      "z": 0,
      "name": "Rock_Stone"
    },
    {
      "x": 5,
      "y": 15,
      "z": 0,
      "name": "Rock_Stone"
    },
    {
      "x": 5,
      "y": 16,
      "z": 0,
      "name": "Rock_Stone"
    },
    {
      "x": 5,
      "y": 17,
      "z": 0,
      "name": "Soil_Dirt"
    },
    {
      "x": 5,
      "y": 18,
      "z": 0,
      "name": "Soil_Grass"
    },
    {
      "x": 5,
      "y": 19,
      "z": 0,
      "name": "Plant_Grass_Sharp_Tall"
    },
    {
      "x": 5,
      "y": 20,
      "z": 0,
      "name": "Plant_Grass_Sharp_Tall",
      "filler": 1024
    },
    {
      "x": 5,
      "y": 10,
      "z": 1,
      "name": "Rock_Stone"
    },
    {
      "x": 5,
      "y": 11,
      "z": 1,
      "name": "Rock_Stone"
    },
    {
      "x": 5,
      "y": 12,
      "z": 1,
      "name": "Rock_Stone"
    },
    {
      "x": 5,
      "y": 13,
      "z": 1,
      "name": "Rock_Stone"
    },
    {
      "x": 5,
      "y": 14,
      "z": 1,
      "name": "Rock_Stone"
    },
    {
      "x": 5,
      "y": 15,
      "z": 1,
      "name": "Rock_Stone"
    },
    {
      "x": 5,
      "y": 16,
      "z": 1,
      "name": "Rock_Stone"
    },
    {
      "x": 5,
      "y": 17,
      "z": 1,
      "name": "Soil_Dirt"
    },
    {
      "x": 5,
      "y": 18,
      "z": 1,
      "name": "Soil_Grass"
    },
    {
      "x": 5,
      "y": 19,
      "z": 1,
      "name": "Plant_Grass_Sharp_Tall"
    },
    {
      "x": 5,
