{
  "version": 8,
  "blockIdVersion": 10,
  "anchorX": -2,
  "anchorY": 11,
  "anchorZ": 0,
  "blocks": [
    {
      "x": -7,
      "y": 24,
      "z": -2,
      "name": "Plant_Leaves_Fire"
    },
    {
      "x": -7,
      "y": 22,
      "z": -1,
      "name": "Plant_Leaves_Fire"
    },
    {
      "x": -7,
      "y": 23,
      "z": -1,
      "name": "Plant_Leaves_Fire"
    },
    {
      "x": -7,
      "y": 24,
      "z": -1,
      "name": "Plant_Leaves_Fire"
    },
    {
      "x": -7,
      "y": 25,
      "z": -1,
      "name": "Plant_Leaves_Fire"
    },
    {
      "x": -7,
      "y": 22,
      "z": 0,
      "name": "Plant_Leaves_Fire"
    },
    {
      "x": -7,
      "y": 23,
      "z": 0,
      "name": "Plant_Leaves_Fire"
    },
    {
      "x": -7,
      "y": 24,
      "z": 0,
      "name": "Plant_Leaves_Fire"
    },
    {
      "x": -7,
      "y": 25,
      "z": 0,
      "name": "Plant_Leaves_Fire"
    },
    {
      "x": -7,
      "y": 24,
      "z": 1,
      "name": "Plant_Leaves_Fire"
    },
    {
      "x": -6,
      "y": 26,
      "z": -5,
      "name": "Plant_Leaves_Fire"
    },
    {
      "x": -6,
      "y": 27,
      "z": -5,
      "name": "Plant_Leaves_Fire"
    },
    {
      "x": -6,
      "y": 25,
      "z": -4,
      "name": "Plant_Leaves_Fire"
    },
    {
      "x": -6,
      "y": 26,
      "z": -4,
      "name": "Plant_Leaves_Fire"
    },
    {
      "x": -6,
      "y": 27,
      "z": -4,
      "name": "Plant_Leaves_Fire"
    },
    {
      "x": -6,
      "y": 23,
      "z": -3,
      "name": "Plant_Leaves_Fire"
    },
    {
      "x": -6,
      "y": 24,
      "z": -3,
      "name": "Plant_Leaves_Fire"
    },
    {
      "x": -6,
      "y": 19,
      "z": -2,
      "name": "Plant_Leaves_Fire"
    },
    {
      "x": -6,
      "y": 20,
      "z": -2,
      "name": "Plant_Leaves_Fire"
    },
    {
      "x": -6,
      "y": 22,
      "z": -2,
      "name": "Plant_Leaves_Fire"
    },
    {
      "x": -6,
      "y": 23,
      "z": -2,
      "name": "Plant_Leaves_Fire"
    },
    {
      "x": -6,
      "y": 24,
      "z": -2,
      "name": "Plant_Leaves_Fire"
    },
    {
      "x": -6,
      "y": 25,
      "z": -2,
      "name": "Plant_Leaves_Fire"
    },
    {
      "x": -6,
      "y": 19,
      "z": -1,
      "name": "Plant_Leaves_Fire"
    },
    {
      "x": -6,
      "y": 20,
      "z": -1,
      "name": "Plant_Leaves_Fire"
    },
    {
      "x": -6,
      "y": 21,
      "z": -1,
      "name": "Plant_Leaves_Fire"
    },
    {
      "x": -6,
      "y": 23,
      "z": -1,
      "name": "Plant_Leaves_Fire"
    },
    {
      "x": -6,
      "y": 24,
      "z": -1,
      "name": "Wood_Fire_Trunk_Full"
    },
    {
      "x": -6,
      "y": 25,
      "z": -1,
      "name": "Plant_Leaves_Fire"
    },
    {
      "x": -6,
      "y": 19,
      "z": 0,
      "name": "Plant_Leaves_Fire"
    },
    {
      "x": -6,
      "y": 20,
      "z": 0,
      "name": "Plant_Leaves_Fire"
    },
    {
      "x": -6,
      "y": 23,
      "z": 0,
      "name": "Plant_Leaves_Fire"
    },
    {
      "x": -6,
      "y": 24,
      "z": 0,
      "name": "Plant_Leaves_Fire"
    },
    {
      "x": -6,
      "y": 25,
      "z": 0,
      "name": "Plant_Leaves_Fire"
    },
    {
      "x": -6,
      "y": 23,
      "z": 1,
      "name": "Plant_Leaves_Fire"
    },
    {
      "x": -6,
      "y": 24,
      "z": 1,
      "name": "Plant_Leaves_Fire"
    },
    {
      "x": -6,
      "y": 25,
      "z": 1,
      "name": "Plant_Leaves_Fire"
    },
    {
      "x": -5,
      "y": 26,
      "z": -6,
      "name": "Plant_Leaves_Fire"
    },
    {
      "x": -5,
      "y": 27,
      "z": -6,
      "name": "Plant_Leaves_Fire"
    },
    {
      "x": -5,
      "y": 24,
      "z": -5,
      "name": "Plant_Leaves_Fire"
    },
    {
      "x": -5,
      "y": 25,
      "z": -5,
      "name": "Plant_Leaves_Fire"
    },
    {
      "x": -5,
      "y": 26,
      "z": -5,
      "name": "Plant_Leaves_Fire"
    },
    {
      "x": -5,
      "y": 27,
      "z": -5,
      "name": "Plant_Leaves_Fire"
    },
    {
      "x": -5,
      "y": 28,
      "z": -5,
      "name": "Plant_Leaves_Fire"
    },
    {
      "x": -5,
      "y": 27,
      "z": -4,
      "name": "Plant_Leaves_Fire"
    },
    {
      "x": -5,
      "y": 19,
      "z": -3,
      "name": "Plant_Leaves_Fire"
    },
    {
      "x": -5,
      "y": 20,
      "z": -3,
      "name": "Plant_Leaves_Fire"
    },
    {
      "x": -5,
      "y": 19,
      "z": -2,
      "name": "Plant_Leaves_Fire"
    },
    {
      "x": -5,
      "y": 20,
      "z": -2,
      "name": "Plant_Leaves_Fire"
    },
    {
      "x": -5,
      "y": 21,
      "z": -2,
      "name": "Plant_Leaves_Fire"
    },
    {
      "x": -5,
      "y": 23,
      "z": -2,
      "name": "Plant_Leaves_Fire"
    },
    {
      "x": -5,
      "y": 24,
      "z": -2,
      "name": "Plant_Leaves_Fire"
    },
    {
      "x": -5,
      "y": 21,
      "z": -1,
      "name": "Wood_Fire_Trunk_Full"
    },
    {
      "x": -5,
      "y": 22,
      "z": -1,
      "name": "Deco_Fire"
    },
    {
      "x": -5,
      "y": 24,
      "z": -1,
      "name": "Wood_Fire_Trunk_Full"
    },
    {
      "x": -5,
      "y": 25,
      "z": -1,
      "name": "Deco_Fire"
    },
    {
      "x": -5,
      "y": 21,
      "z": 0,
      "name": "Plant_Leaves_Fire"
    },
    {
      "x": -5,
      "y": 27,
      "z": 0,
      "name": "Plant_Leaves_Fire"
    },
    {
      "x": -5,
      "y": 28,
      "z": 0,
      "name": "Plant_Leaves_Fire"
    },
    {
      "x": -5,
      "y": 26,
      "z": 1,
      "name": "Plant_Leaves_Fire"
    },
    {
      "x": -5,
      "y": 27,
      "z": 1,
      "name": "Plant_Leaves_Fire"
    },
    {
      "x": -5,
      "y": 22,
      "z": 3,
      "name": "Plant_Leaves_Fire"
    },
    {
      "x": -5,
      "y": 23,
      "z": 3,
      "name": "Plant_Leaves_Fire"
    },
    {
      "x": -5,
      "y": 24,
      "z": 3,
      "name": "Plant_Leaves_Fire"
    },
    {
      "x": -5,
      "y": 21,
      "z": 4,
      "name": "Plant_Leaves_Fire"
    },
    {
      "x": -5,
      "y": 22,
      "z": 4,
      "name": "Plant_Leaves_Fire"
    },
    {
      "x": -5,
      "y": 23,
      "z": 4,
      "name": "Plant_Leaves_Fire"
    },
    {
      "x": -5,
      "y": 24,
      "z": 4,
      "name": "Plant_Leaves_Fire"
    },
    {
      "x": -5,
      "y": 25,
      "z": 4,
      "name": "Plant_Leaves_Fire"
    },
    {
      "x": -5,
      "y": 23,
      "z": 5,
      "name": "Plant_Leaves_Fire"
    },
    {
      "x": -5,
      "y": 24,
      "z": 5,
      "name": "Plant_Leaves_Fire"
    },
    {
      "x": -4,
      "y": 25,
      "z": -6,
      "name": "Plant_Leaves_Fire"
    },
    {
      "x": -4,
      "y": 26,
      "z": -6,
      "name": "Plant_Leaves_Fire"
    },
    {
      "x": -4,
      "y": 27,
      "z": -6,
      "name": "Plant_Leaves_Fire"
    },
    {
      "x": -4,
      "y": 25,
      "z": -5,
      "name": "Plant_Leaves_Fire"
    },
    {
      "x": -4,
      "y": 26,
      "z": -5,
      "name": "Wood_Fire_Trunk_Full"
    },
    {
      "x": -4,
      "y": 27,
      "z": -5,
      "name": "Plant_Leaves_Fire"
    },
    {
      "x": -4,
      "y": 28,
      "z": -5,
      "name": "Plant_Leaves_Fire"
    },
    {
      "x": -4,
      "y": 20,
      "z": -4,
      "name": "Plant_Leaves_Fire"
    },
    {
      "x": -4,
      "y": 21,
      "z": -4,
      "name": "Plant_Leaves_Fire"
    },
    {
      "x": -4,
      "y": 26,
      "z": -4,
      "name": "Wood_Fire_Trunk_Full"
    },
    {
      "x": -4,
      "y": 27,
      "z": -4,
      "name": "Deco_Fire"
    },
    {
      "x": -4,
      "y": 19,
      "z": -3,
      "name": "Plant_Leaves_Fire"
    },
    {
      "x": -4,
      "y": 20,
      "z": -3,
      "name": "Plant_Leaves_Fire"
    },
    {
      "x": -4,
      "y": 21,
      "z": -3,
      "name": "Plant_Leaves_Fire"
    },
    {
      "x": -4,
      "y": 26,
      "z": -3,
      "name": "Wood_Fire_Trunk_Full"
    },
    {
      "x": -4,
      "y": 27,
      "z": -3,
      "name": "Deco_Fire"
    },
    {
      "x": -4,
      "y": 20,
      "z": -2,
      "name": "Plant_Leaves_Fire"
    },
    {
      "x": -4,
      "y": 20,
      "z": -1,
      "name": "Plant_Leaves_Fire"
    },
    {
      "x": -4,
      "y": 21,
      "z": -1,
      "name": "Wood_Fire_Trunk_Full"
    },
    {
      "x": -4,
      "y": 22,
      "z": -1,
      "name": "Deco_Fire"
    },
    {
      "x": -4,
      "y": 24,
      "z": -1,
      "name": "Wood_Fire_Trunk_Full"
    },
    {
      "x": -4,
      "y": 25,
      "z": -1,
      "name": "Deco_Fire"
    },
    {
      "x": -4,
      "y": 27,
      "z": -1,
      "name": "Plant_Leaves_Fire"
    },
    {
      "x": -4,
      "y": 28,
      "z": -1,
      "name": "Plant_Leaves_Fire"
    },
    {
      "x": -4,
      "y": 29,
      "z": -1,
      "name": "Plant_Leaves_Fire"
    },
    {
      "x": -4,
      "y": 9,
      "z": 0,
      "name": "Wood_Fire_Trunk_Full"
    },
    {
      "x": -4,
      "y": 10,
      "z": 0,
      "name": "Wood_Fire_Trunk"
    },
    {
      "x": -4,
      "y": 11,
      "z": 0,
      "name": "Wood_Fire_Trunk"
    },
    {
      "x": -4,
      "y": 12,
      "z": 0,
      "name": "Wood_Fire_Trunk"
    },
    {
      "x": -4,
      "y": 13,
      "z": 0,
      "name": "Wood_Fire_Trunk_Full"
    },
    {
      "x": -4,
      "y": 21,
      "z": 0,
      "name": "Plant_Leaves_Fire"
    },
    {
      "x": -4,
      "y": 24,
      "z": 0,
      "name": "Wood_Fire_Trunk_Full"
    },
    {
      "x": -4,
      "y": 25,
      "z": 0,
      "name": "Deco_Fire"
    },
    {
      "x": -4,
      "y": 27,
      "z": 0,
      "name": "Plant_Leaves_Fire"
    },
    {
      "x": -4,
      "y": 28,
      "z": 0,
      "name": "Plant_Leaves_Fire"
    },
    {
      "x": -4,
      "y": 29,
      "z": 0,
      "name": "Plant_Leaves_Fire"
    },
    {
      "x": -4,
      "y": 27,
      "z": 1,
      "name": "Plant_Leaves_Fire"
    },
    {
      "x": -4,
      "y": 28,
      "z": 1,
      "name": "Plant_Leaves_Fire"
    },
    {
      "x": -4,
      "y": 27,
      "z": 2,
      "name": "Plant_Leaves_Fire"
    },
    {
      "x": -4,
      "y": 24,
      "z": 3,
      "name": "Plant_Leaves_Fire"
    },
    {
      "x": -4,
      "y": 22,
      "z": 4,
      "name": "Plant_Leaves_Fire"
    },
    {
      "x": -4,
      "y": 24,
      "z": 4,
      "name": "Wood_Fire_Trunk_Full"
    },
    {
      "x": -4,
      "y": 25,
      "z": 4,
      "name": "Plant_Leaves_Fire"
    },
    {
      "x": -4,
      "y": 21,
      "z": 5,
      "name": "Plant_Leaves_Fire"
    },
    {
      "x": -4,
      "y": 22,
      "z": 5,
      "name": "Plant_Leaves_Fire"
    },
    {
      "x": -4,
      "y": 23,
      "z": 5,
      "name": "Plant_Leaves_Fire"
    },
    {
      "x": -4,
      "y": 24,
      "z": 5,
      "name": "Plant_Leaves_Fire"
    },
    {
      "x": -4,
      "y": 25,
      "z": 5,
      "name": "Plant_Leaves_Fire"
    },
    {
      "x": -3,
      "y": 24,
      "z": -6,
      "name": "Plant_Leaves_Fire"
    },
    {
      "x": -3,
      "y": 25,
      "z": -6,
      "name": "Plant_Leaves_Fire"
    },
    {
      "x": -3,
      "y": 26,
      "z": -6,
      "name": "Plant_Leaves_Fire"
    },
    {
      "x": -3,
      "y": 24,
      "z": -5,
      "name": "Plant_Leaves_Fire"
    },
    {
      "x": -3,
      "y": 25,
      "z": -5,
      "name": "Plant_Leaves_Fire"
    },
    {
      "x": -3,
      "y": 26,
      "z": -5,
      "name": "Plant_Leaves_Fire"
    },
    {
      "x": -3,
      "y": 27,
      "z": -5,
      "name": "Plant_Leaves_Fire"
    },
    {
      "x": -3,
      "y": 17,
      "z": -4,
      "name": "Plant_Leaves_Fire"
    },
    {
      "x": -3,
      "y": 18,
      "z": -4,
      "name": "Plant_Leaves_Fire"
    },
    {
      "x": -3,
      "y": 19,
      "z": -4,
      "name": "Plant_Leaves_Fire"
    },
    {
      "x": -3,
      "y": 20,
      "z": -4,
      "name": "Plant_Leaves_Fire"
    },
    {
      "x": -3,
      "y": 21,
      "z": -4,
      "name": "Plant_Leaves_Fire"
    },
    {
      "x": -3,
      "y": 19,
      "z": -3,
      "name": "Plant_Leaves_Fire"
    },
    {
      "x": -3,
      "y": 20,
      "z": -3,
      "name": "Wood_Fire_Trunk_Full"
    },
    {
      "x": -3,
      "y": 21,
      "z": -3,
      "name": "Deco_Fire"
    },
    {
      "x": -3,
      "y": 26,
      "z": -3,
      "name": "Wood_Fire_Trunk_Full"
    },
    {
      "x": -3,
      "y": 27,
      "z": -3,
      "name": "Deco_Fire"
    },
    {
      "x": -3,
      "y": 29,
      "z": -3,
      "name": "Plant_Leaves_Fire"
    },
    {
      "x": -3,
      "y": 20,
      "z": -2,
      "name": "Wood_Fire_Trunk_Full"
    },
    {
      "x": -3,
      "y": 21,
      "z": -2,
      "name": "Deco_Fire"
    },
    {
      "x": -3,
      "y": 29,
      "z": -2,
      "name": "Plant_Leaves_Fire"
    },
    {
      "x": -3,
      "y": 20,
      "z": -1,
      "name": "Wood_Fire_Trunk_Full"
    },
    {
      "x": -3,
      "y": 21,
      "z": -1,
      "name": "Wood_Fire_Trunk_Full"
    },
    {
      "x": -3,
      "y": 8,
      "z": 0,
      "name": "Wood_Fire_Trunk_Full"
    },
    {
      "x": -3,
      "y": 9,
      "z": 0,
      "name": "Wood_Fire_Trunk_Full"
    },
    {
      "x": -3,
      "y": 13,
      "z": 0,
      "name": "Wood_Fire_Trunk_Full"
    },
    {
      "x": -3,
      "y": 14,
      "z": 0,
      "name": "Wood_Fire_Trunk_Full"
    },
    {
      "x": -3,
      "y": 20,
      "z": 0,
      "name": "Wood_Fire_Trunk_Full"
    },
    {
      "x": -3,
      "y": 24,
      "z": 0,
      "name": "Wood_Fire_Trunk_Full"
    },
    {
      "x": -3,
      "y": 27,
      "z": 0,
      "name": "Wood_Fire_Trunk_Full"
    },
    {
      "x": -3,
      "y": 28,
      "z": 0,
      "name": "Wood_Fire_Trunk_Full"
    },
    {
      "x": -3,
      "y": 29,
      "z": 0,
      "name": "Deco_Fire"
    },
    {
      "x": -3,
      "y": 26,
      "z": 1,
      "name": "Plant_Leaves_Fire"
    },
    {
      "x": -3,
      "y": 27,
      "z": 1,
      "name": "Plant_Leaves_Fire"
    },
    {
      "x": -3,
      "y": 28,
      "z": 1,
      "name": "Plant_Leaves_Fire"
    },
    {
      "x": -3,
      "y": 29,
      "z": 1,
      "name": "Plant_Leaves_Fire"
    },
    {
      "x": -3,
      "y": 26,
      "z": 2,
      "name": "Plant_Leaves_Fire"
    },
    {
      "x": -3,
      "y": 27,
      "z": 2,
      "name": "Plant_Leaves_Fire"
    },
    {
      "x": -3,
      "y": 28,
      "z": 2,
      "name": "Plant_Leaves_Fire"
    },
    {
      "x": -3,
      "y": 24,
      "z": 3,
      "name": "Wood_Fire_Trunk_Full"
    },
    {
      "x": -3,
      "y": 25,
      "z": 3,
      "name": "Deco_Fire"
    },
    {
      "x": -3,
      "y": 24,
      "z": 4,
      "name": "Wood_Fire_Trunk_Full"
    },
    {
      "x": -3,
      "y": 25,
      "z": 4,
      "name": "Deco_Fire"
    },
    {
      "x": -3,
      "y": 22,
      "z": 5,
      "name": "Plant_Leaves_Fire"
    },
    {
      "x": -3,
      "y": 23,
      "z": 5,
      "name": "Plant_Leaves_Fire"
    },
    {
      "x": -3,
      "y": 24,
      "z": 5,
      "name": "Plant_Leaves_Fire"
    },
    {
      "x": -3,
      "y": 25,
      "z": 5,
      "name": "Plant_Leaves_Fire"
    },
    {
      "x": -2,
      "y": 27,
      "z": -5,
      "name": "Plant_Leaves_Fire"
    },
    {
      "x": -2,
      "y": 28,
      "z": -5,
      "name": "Plant_Leaves_Fire"
    },
    {
      "x": -2,
      "y": 20,
      "z": -4,
      "name": "Plant_Leaves_Fire"
    },
    {
      "x": -2,
      "y": 21,
      "z": -4,
      "name": "Plant_Leaves_Fire"
    },
    {
      "x": -2,
      "y": 28,
      "z": -4,
      "name": "Plant_Leaves_Fire"
    },
    {
      "x": -2,
      "y": 29,
      "z": -4,
      "name": "Plant_Leaves_Fire"
    },
    {
      "x": -2,
      "y": 18,
      "z": -3,
      "name": "Plant_Leaves_Fire"
    },
    {
      "x": -2,
      "y": 19,
      "z": -3,
      "name": "Plant_Leaves_Fire"
    },
    {
      "x": -2,
      "y": 20,
      "z": -3,
      "name": "Plant_Leaves_Fire"
    },
    {
      "x": -2,
      "y": 21,
      "z": -3,
      "name": "Plant_Leaves_Fire"
    },
    {
      "x": -2,
      "y": 26,
      "z": -3,
      "name": "Wood_Fire_Trunk_Full"
    },
    {
      "x": -2,
      "y": 29,
      "z": -3,
      "name": "Plant_Leaves_Fire"
    },
    {
      "x": -2,
      "y": 30,
      "z": -3,
      "name": "Plant_Leaves_Fire"
    },
    {
      "x": -2,
      "y": 26,
      "z": -2,
      "name": "Wood_Fire_Trunk_Full"
    },
    {
      "x": -2,
      "y": 30,
      "z": -2,
      "name": "Plant_Leaves_Fire"
    },
    {
      "x": -2,
      "y": 31,
      "z": -2,
      "name": "Plant_Leaves_Fire"
    },
    {
      "x": -2,
      "y": 8,
      "z": 0,
      "name": "Wood_Fire_Trunk_Full"
    },
    {
      "x": -2,
      "y": 11,
      "z": 0,
      "name": "Wood_Fire_Trunk_Full"
    },
    {
      "x": -2,
      "y": 14,
      "z": 0,
      "name": "Wood_Fire_Trunk_Full"
    },
    {
      "x": -2,
      "y": 20,
      "z": 0,
      "name": "Wood_Fire_Trunk_Full"
    },
    {
      "x": -2,
      "y": 24,
      "z": 0,
      "name": "Wood_Fire_Trunk_Full"
    },
    {
      "x": -2,
      "y": 25,
      "z": 0,
      "name": "Wood_Fire_Trunk"
    },
    {
      "x": -2,
      "y": 26,
      "z": 0,
      "name": "Wood_Fire_Trunk"
    },
    {
      "x": -2,
      "y": 27,
      "z": 0,
      "name": "Wood_Fire_Trunk_Full"
    },
    {
      "x": -2,
      "y": 31,
      "z": 0,
      "name": "Plant_Leaves_Fire"
    },
    {
      "x": -2,
      "y": 10,
      "z": 1,
      "name": "Wood_Fire_Trunk_Full"
    },
    {
      "x": -2,
      "y": 11,
      "z": 1,
      "name": "Wood_Fire_Trunk_Full"
    },
    {
      "x": -2,
      "y": 14,
      "z": 1,
      "name": "Wood_Fire_Trunk_Full"
    },
    {
      "x": -2,
      "y": 15,
      "z": 1,
      "name": "Wood_Fire_Trunk"
    },
    {
      "x": -2,
      "y": 16,
      "z": 1,
      "name": "Wood_Fire_Trunk_Full"
    },
    {
      "x": -2,
      "y": 27,
      "z": 1,
      "name": "Plant_Leaves_Fire"
    },
    {
      "x": -2,
      "y": 29,
      "z": 1,
      "name": "Plant_Leaves_Fire"
    },
    {
      "x": -2,
      "y": 30,
      "z": 1,
      "name": "Plant_Leaves_Fire"
    },
    {
      "x": -2,
      "y": 31,
      "z": 1,
      "name": "Plant_Leaves_Fire"
    },
    {
      "x": -2,
      "y": 11,
      "z": 2,
      "name": "Wood_Fire_Trunk_Full"
    },
    {
      "x": -2,
      "y": 12,
      "z": 2,
      "name": "Wood_Fire_Trunk"
    },
    {
      "x": -2,
      "y": 13,
      "z": 2,
      "name": "Wood_Fire_Trunk"
    },
    {
      "x": -2,
      "y": 14,
      "z": 2,
      "name": "Wood_Fire_Trunk"
    },
    {
      "x": -2,
      "y": 15,
      "z": 2,
      "name": "Wood_Fire_Trunk_Full"
    },
    {
      "x": -2,
      "y": 27,
      "z": 2,
      "name": "Plant_Leaves_Fire"
    },
    {
      "x": -2,
      "y": 28,
      "z": 2,
      "name": "Plant_Leaves_Fire"
    },
    {
      "x": -2,
      "y": 29,
      "z": 2,
      "name": "Plant_Leaves_Fire"
    },
    {
      "x": -2,
      "y": 30,
      "z": 2,
      "name": "Plant_Leaves_Fire"
    },
    {
      "x": -2,
      "y": 24,
      "z": 3,
      "name": "Wood_Fire_Trunk_Full"
    },
    {
      "x": -2,
      "y": 25,
      "z": 3,
      "name": "Deco_Fire"
    },
    {
      "x": -2,
      "y": 27,
      "z": 3,
      "name": "Plant_Leaves_Fire"
    },
    {
      "x": -2,
      "y": 28,
      "z": 3,
      "name": "Plant_Leaves_Fire"
    },
    {
      "x": -2,
      "y": 23,
      "z": 6,
      "name": "Plant_Leaves_Fire"
    },
    {
      "x": -1,
      "y": 28,
      "z": -7,
      "name": "Plant_Leaves_Fire"
    },
    {
      "x": -1,
      "y": 28,
      "z": -6,
      "name": "Plant_Leaves_Fire"
    },
    {
      "x": -1,
      "y": 28,
      "z": -5,
      "name": "Plant_Leaves_Fire"
    },
    {
      "x": -1,
      "y": 29,
      "z": -5,
      "name": "Plant_Leaves_Fire"
    },
    {
      "x": -1,
      "y": 28,
      "z": -4,
      "name": "Wood_Fire_Trunk_Full"
    },
    {
      "x": -1,
      "y": 29,
      "z": -4,
      "name": "Deco_Fire"
    },
    {
      "x": -1,
      "y": 28,
      "z": -3,
      "name": "Wood_Fire_Trunk_Full"
    },
    {
      "x": -1,
      "y": 29,
      "z": -3,
      "name": "Wood_Fire_Trunk_Full"
    },
    {
      "x": -1,
      "y": 30,
      "z": -3,
      "name": "Plant_Leaves_Fire"
    },
    {
      "x": -1,
      "y": 31,
      "z": -3,
      "name": "Plant_Leaves_Fire"
    },
    {
      "x": -1,
      "y": 23,
      "z": -2,
      "name": "Wood_Fire_Trunk_Full"
    },
    {
      "x": -1,
      "y": 24,
      "z": -2,
      "name": "Wood_Fire_Trunk"
    },
    {
      "x": -1,
      "y": 25,
      "z": -2,
      "name": "Wood_Fire_Trunk"
    },
    {
      "x": -1,
      "y": 26,
      "z": -2,
      "name": "Wood_Fire_Trunk"
    },
    {
      "x": -1,
      "y": 27,
      "z": -2,
      "name": "Wood_Fire_Trunk"
    },
    {
      "x": -1,
      "y": 28,
      "z": -2,
      "name": "Wood_Fire_Trunk_Full"
    },
    {
      "x": -1,
      "y": 30,
      "z": -2,
      "name": "Plant_Leaves_Fire"
    },
    {
      "x": -1,
      "y": 31,
      "z": -2,
      "name": "Plant_Leaves_Fire"
    },
    {
      "x": -1,
      "y": 23,
      "z": -1,
      "name": "Wood_Fire_Trunk_Full"
    },
    {
      "x": -1,
      "y": 30,
      "z": -1,
      "name": "Plant_Leaves_Fire"
    },
    {
      "x": -1,
      "y": 14,
      "z": 0,
      "name": "Wood_Fire_Trunk_Full"
    },
    {
      "x": -1,
      "y": 15,
      "z": 0,
      "name": "Wood_Fire_Trunk"
    },
    {
      "x": -1,
      "y": 16,
      "z": 0,
      "name": "Wood_Fire_Trunk"
    },
    {
      "x": -1,
      "y": 17,
      "z": 0,
      "name": "Wood_Fire_Trunk"
    },
    {
      "x": -1,
      "y": 18,
      "z": 0,
      "name": "Wood_Fire_Trunk"
    },
    {
      "x": -1,
      "y": 19,
      "z": 0,
      "name": "Wood_Fire_Trunk"
    },
    {
      "x": -1,
      "y": 20,
      "z": 0,
      "name": "Wood_Fire_Trunk"
    },
    {
      "x": -1,
      "y": 21,
      "z": 0,
      "name": "Wood_Fire_Trunk"
    },
    {
      "x": -1,
      "y": 22,
      "z": 0,
      "name": "Wood_Fire_Trunk"
    },
    {
      "x": -1,
      "y": 23,
      "z": 0,
      "name": "Wood_Fire_Trunk"
    },
    {
      "x": -1,
      "y": 24,
      "z": 0,
      "name": "Wood_Fire_Trunk_Full"
    },
    {
      "x": -1,
      "y": 27,
      "z": 0,
      "name": "Wood_Fire_Trunk_Full"
    },
    {
      "x": -1,
      "y": 28,
      "z": 0,
      "name": "Wood_Fire_Trunk_Full"
    },
    {
      "x": -1,
      "y": 29,
      "z": 0,
      "name": "Wood_Fire_Trunk_Full"
    },
    {
      "x": -1,
      "y": 30,
      "z": 0,
      "name": "Deco_Fire"
    },
    {
      "x": -1,
      "y": 31,
      "z": 0,
      "name": "Plant_Leaves_Fire"
    },
    {
      "x": -1,
      "y": 14,
      "z": 1,
      "name": "Wood_Fire_Trunk_Full"
    },
    {
      "x": -1,
      "y": 15,
      "z": 1,
      "name": "Wood_Fire_Trunk"
    },
    {
      "x": -1,
      "y": 16,
      "z": 1,
      "name": "Wood_Fire_Trunk"
    },
    {
      "x": -1,
      "y": 17,
      "z": 1,
      "name": "Wood_Fire_Trunk"
    },
    {
      "x": -1,
      "y": 18,
      "z": 1,
      "name": "Wood_Fire_Trunk"
    },
    {
      "x": -1,
      "y": 19,
      "z": 1,
      "name": "Wood_Fire_Trunk"
    },
    {
      "x": -1,
      "y": 20,
      "z": 1,
      "name": "Wood_Fire_Trunk"
    },
    {
      "x": -1,
      "y": 21,
      "z": 1,
      "name": "Wood_Fire_Trunk"
    },
    {
      "x": -1,
      "y": 22,
      "z": 1,
      "name": "Wood_Fire_Trunk"
    },
    {
      "x": -1,
      "y": 23,
      "z": 1,
      "name": "Wood_Fire_Trunk_Full"
    },
    {
      "x": -1,
      "y": 29,
      "z": 1,
      "name": "Wood_Fire_Trunk_Full"
    },
    {
      "x": -1,
      "y": 30,
      "z": 1,
      "name": "Wood_Fire_Trunk_Full"
    },
    {
      "x": -1,
      "y": 31,
      "z": 1,
      "name": "Deco_Fire"
    },
    {
      "x": -1,
      "y": 14,
      "z": 2,
      "name": "Wood_Fire_Trunk_Full"
    },
    {
      "x": -1,
      "y": 15,
      "z": 2,
      "name": "Wood_Fire_Trunk_Full"
    },
    {
      "x": -1,
      "y": 23,
      "z": 2,
      "name": "Wood_Fire_Trunk_Full"
    },
    {
      "x": -1,
      "y": 29,
      "z": 2,
      "name": "Plant_Leaves_Fire"
    },
    {
      "x": -1,
      "y": 30,
      "z": 2,
      "name": "Plant_Leaves_Fire"
    },
    {
      "x": -1,
      "y": 31,
      "z": 2,
      "name": "Plant_Leaves_Fire"
    },
    {
      "x": -1,
      "y": 23,
      "z": 3,
      "name": "Wood_Fire_Trunk_Full"
    },
    {
      "x": -1,
      "y": 24,
      "z": 3,
      "name": "Wood_Fire_Trunk_Full"
    },
    {
      "x": -1,
      "y": 29,
      "z": 3,
      "name": "Plant_Leaves_Fire"
    },
    {
      "x": -1,
      "y": 22,
      "z": 6,
      "name": "Plant_Leaves_Fire"
    },
    {
      "x": -1,
      "y": 23,
      "z": 6,
      "name": "Plant_Leaves_Fire"
    },
    {
      "x": -1,
      "y": 24,
      "z": 6,
      "name": "Plant_Leaves_Fire"
    },
    {
      "x": -1,
      "y": 23,
      "z": 7,
      "name": "Plant_Leaves_Fire"
    },
    {
      "x": 0,
      "y": 26,
      "z": -7,
      "name": "Plant_Leaves_Fire"
    },
    {
      "x": 0,
      "y": 27,
      "z": -7,
      "name": "Plant_Leaves_Fire"
    },
    {
      "x": 0,
      "y": 28,
      "z": -7,
      "name": "Plant_Leaves_Fire"
    },
    {
      "x": 0,
      "y": 27,
      "z": -6,
      "name": "Plant_Leaves_Fire"
    },
    {
      "x": 0,
      "y": 28,
      "z": -6,
      "name": "Plant_Leaves_Fire"
    },
    {
      "x": 0,
      "y": 29,
      "z": -6,
      "name": "Plant_Leaves_Fire"
    },
    {
      "x": 0,
      "y": 21,
      "z": -5,
      "name": "Plant_Leaves_Fire"
    },
    {
      "x": 0,
      "y": 22,
      "z": -5,
      "name": "Plant_Leaves_Fire"
    },
    {
      "x": 0,
      "y": 23,
      "z": -5,
      "name": "Plant_Leaves_Fire"
    },
    {
      "x": 0,
      "y": 28,
      "z": -5,
      "name": "Plant_Leaves_Fire"
    },
    {
      "x": 0,
      "y": 29,
      "z": -5,
      "name": "Plant_Leaves_Fire"
    },
    {
      "x": 0,
      "y": 21,
      "z": -4,
      "name": "Plant_Leaves_Fire"
    },
    {
      "x": 0,
      "y": 22,
      "z": -4,
      "name": "Plant_Leaves_Fire"
    },
    {
      "x": 0,
      "y": 23,
      "z": -4,
      "name": "Plant_Leaves_Fire"
    },
    {
      "x": 0,
      "y": 28,
      "z": -4,
      "name": "Wood_Fire_Trunk_Full"
    },
    {
      "x": 0,
      "y": 29,
      "z": -4,
      "name": "Deco_Fire"
    },
    {
      "x": 0,
      "y": 30,
      "z": -4,
      "name": "Plant_Leaves_Fire"
    },
    {
      "x": 0,
      "y": 23,
      "z": -3,
      "name": "Wood_Fire_Trunk_Full"
    },
    {
      "x": 0,
      "y": 24,
      "z": -3,
      "name": "Deco_Fire"
    },
    {
      "x": 0,
      "y": 30,
      "z": -3,
      "name": "Plant_Leaves_Fire"
    },
    {
      "x": 0,
      "y": 31,
      "z": -3,
      "name": "Plant_Leaves_Fire"
    },
    {
      "x": 0,
      "y": 10,
      "z": -2,
      "name": "Wood_Fire_Trunk_Full"
    },
    {
      "x": 0,
      "y": 11,
      "z": -2,
      "name": "Wood_Fire_Trunk"
    },
    {
      "x": 0,
      "y": 12,
      "z": -2,
      "name": "Wood_Fire_Trunk_Full"
    },
    {
      "x": 0,
      "y": 23,
      "z": -2,
      "name": "Wood_Fire_Trunk_Full"
    },
    {
      "x": 0,
      "y": 30,
      "z": -2,
      "name": "Plant_Leaves_Fire"
    },
    {
      "x": 0,
      "y": 9,
      "z": -1,
      "name": "Wood_Fire_Trunk_Full"
    },
    {
      "x": 0,
      "y": 10,
      "z": -1,
      "name": "Wood_Fire_Trunk_Full"
    },
    {
      "x": 0,
      "y": 12,
      "z": -1,
      "name": "Wood_Fire_Trunk_Full"
    },
    {
      "x": 0,
      "y": 13,
      "z": -1,
      "name": "Wood_Fire_Trunk"
    },
    {
      "x": 0,
      "y": 14,
      "z": -1,
      "name": "Wood_Fire_Trunk"
    },
    {
      "x": 0,
      "y": 15,
      "z": -1,
      "name": "Wood_Fire_Trunk_Full"
    },
    {
      "x": 0,
      "y": 30,
      "z": -1,
      "name": "Plant_Leaves_Fire"
    },
    {
      "x": 0,
      "y": 9,
      "z": 0,
      "name": "Wood_Fire_Trunk_Full"
    },
    {
      "x": 0,
      "y": 13,
      "z": 0,
      "name": "Wood_Fire_Trunk"
    },
    {
      "x": 0,
      "y": 14,
      "z": 0,
      "name": "Wood_Fire_Trunk"
    },
    {
      "x": 0,
      "y": 15,
      "z": 0,
      "name": "Wood_Fire_Trunk"
    },
    {
      "x": 0,
      "y": 16,
      "z": 0,
      "name": "Wood_Fire_Trunk"
    },
    {
      "x": 0,
      "y": 17,
      "z": 0,
      "name": "Wood_Fire_Trunk_Full"
    },
    {
      "x": 0,
      "y": 31,
      "z": 0,
      "name": "Plant_Leaves_Fire"
    },
    {
      "x": 0,
      "y": 14,
      "z": 1,
      "name": "Wood_Fire_Trunk_Full"
    },
    {
      "x": 0,
      "y": 15,
      "z": 1,
      "name": "Wood_Fire_Trunk"
    },
    {
      "x": 0,
      "y": 16,
      "z": 1,
      "name": "Wood_Fire_Trunk"
    },
    {
      "x": 0,
      "y": 17,
      "z": 1,
      "name": "Wood_Fire_Trunk"
    },
    {
      "x": 0,
      "y": 18,
      "z": 1,
      "name": "Wood_Fire_Trunk"
    },
    {
      "x": 0,
      "y": 19,
      "z": 1,
      "name": "Wood_Fire_Trunk"
    },
    {
      "x": 0,
      "y": 20,
      "z": 1,
      "name": "Wood_Fire_Trunk"
    },
    {
      "x": 0,
      "y": 21,
      "z": 1,
      "name": "Wood_Fire_Trunk"
    },
    {
      "x": 0,
      "y": 22,
      "z": 1,
      "name": "Wood_Fire_Trunk"
    },
    {
      "x": 0,
      "y": 23,
      "z": 1,
      "name": "Wood_Fire_Trunk"
    },
    {
      "x": 0,
      "y": 24,
      "z": 1,
      "name": "Wood_Fire_Trunk"
    },
    {
      "x": 0,
      "y": 25,
      "z": 1,
      "name": "Wood_Fire_Trunk_Full"
    },
    {
      "x": 0,
      "y": 28,
      "z": 1,
      "name": "Plant_Leaves_Fire"
    },
    {
      "x": 0,
      "y": 29,
      "z": 1,
      "name": "Plant_Leaves_Fire"
    },
    {
      "x": 0,
      "y": 30,
      "z": 1,
      "name": "Plant_Leaves_Fire"
    },
    {
      "x": 0,
      "y": 31,
      "z": 1,
      "name": "Plant_Leaves_Fire"
    },
    {
      "x": 0,
      "y": 12,
      "z": 2,
      "name": "Wood_Fire_Trunk_Full"
    },
    {
      "x": 0,
      "y": 13,
      "z": 2,
      "name": "Wood_Fire_Trunk"
    },
    {
      "x": 0,
      "y": 14,
      "z": 2,
      "name": "Wood_Fire_Trunk"
    },
    {
      "x": 0,
      "y": 15,
      "z": 2,
      "name": "Wood_Fire_Trunk"
    },
    {
      "x": 0,
      "y": 16,
      "z": 2,
      "name": "Wood_Fire_Trunk_Full"
    },
    {
      "x": 0,
      "y": 27,
      "z": 2,
      "name": "Plant_Leaves_Fire"
    },
    {
      "x": 0,
      "y": 29,
      "z": 2,
      "name": "Plant_Leaves_Fire"
    },
    {
      "x": 0,
      "y": 30,
      "z": 2,
      "name": "Plant_Leaves_Fire"
    },
    {
      "x": 0,
      "y": 23,
      "z": 3,
      "name": "Wood_Fire_Trunk_Full"
    },
    {
      "x": 0,
      "y": 27,
      "z": 3,
      "name": "Plant_Leaves_Fire"
    },
    {
      "x": 0,
      "y": 29,
      "z": 3,
      "name": "Plant_Leaves_Fire"
    },
    {
      "x": 0,
      "y": 23,
      "z": 4,
      "name": "Wood_Fire_Trunk_Full"
    },
    {
      "x": 0,
      "y": 24,
      "z": 4,
      "name": "Deco_Fire"
    },
    {
      "x": 0,
      "y": 27,
      "z": 4,
      "name": "Plant_Leaves_Fire"
    },
    {
      "x": 0,
      "y": 23,
      "z": 5,
      "name": "Wood_Fire_Trunk_Full"
    },
    {
      "x": 0,
      "y": 24,
      "z": 5,
      "name": "Deco_Fire"
    },
    {
      "x": 0,
      "y": 25,
      "z": 5,
      "name": "Plant_Leaves_Fire"
    },
    {
      "x": 0,
      "y": 22,
      "z": 6,
      "name": "Plant_Leaves_Fire"
    },
    {
      "x": 0,
      "y": 23,
      "z": 6,
      "name": "Wood_Fire_Trunk_Full"
    },
    {
      "x": 0,
      "y": 24,
      "z": 6,
      "name": "Plant_Leaves_Fire"
    },
    {
      "x": 0,
      "y": 25,
      "z": 6,
      "name": "Plant_Leaves_Fire"
    },
    {
      "x": 0,
      "y": 21,
      "z": 7,
      "name": "Plant_Leaves_Fire"
    },
    {
      "x": 0,
      "y": 22,
      "z": 7,
      "name": "Plant_Leaves_Fire"
    },
    {
      "x": 0,
      "y": 23,
      "z": 7,
      "name": "Plant_Leaves_Fire"
    },
    {
      "x": 0,
      "y": 24,
      "z": 7,
      "name": "Plant_Leaves_Fire"
    },
    {
      "x": 1,
      "y": 28,
      "z": -7,
      "name": "Plant_Leaves_Fire"
    },
    {
      "x": 1,
      "y": 26,
      "z": -6,
      "name": "Plant_Leaves_Fire"
    },
    {
      "x": 1,
      "y": 27,
      "z": -6,
      "name": "Plant_Leaves_Fire"
    },
    {
      "x": 1,
      "y": 28,
      "z": -6,
      "name": "Plant_Leaves_Fire"
    },
    {
      "x": 1,
      "y": 22,
      "z": -5,
      "name": "Plant_Leaves_Fire"
    },
    {
      "x": 1,
      "y": 23,
      "z": -5,
      "name": "Plant_Leaves_Fire"
    },
    {
      "x": 1,
      "y": 24,
      "z": -5,
      "name": "Plant_Leaves_Fire"
    },
    {
      "x": 1,
      "y": 27,
      "z": -5,
      "name": "Plant_Leaves_Fire"
    },
    {
      "x": 1,
      "y": 28,
      "z": -5,
      "name": "Wood_Fire_Trunk_Full"
    },
    {
      "x": 1,
      "y": 29,
      "z": -5,
      "name": "Deco_Fire"
    },
    {
      "x": 1,
      "y": 23,
      "z": -4,
      "name": "Wood_Fire_Trunk_Full"
    },
    {
      "x": 1,
      "y": 24,
      "z": -4,
      "name": "Plant_Leaves_Fire"
    },
    {
      "x": 1,
      "y": 28,
      "z": -4,
      "name": "Wood_Fire_Trunk_Full"
    },
    {
      "x": 1,
      "y": 29,
      "z": -4,
      "name": "Deco_Fire"
    },
    {
      "x": 1,
      "y": 23,
      "z": -3,
      "name": "Wood_Fire_Trunk_Full"
    },
    {
      "x": 1,
      "y": 24,
      "z": -3,
      "name": "Deco_Fire"
    },
    {
      "x": 1,
      "y": 29,
      "z": -3,
      "name": "Plant_Leaves_Fire"
    },
    {
      "x": 1,
      "y": 30,
      "z": -3,
      "name": "Plant_Leaves_Fire"
    },
    {
      "x": 1,
      "y": 29,
      "z": -1,
      "name": "Plant_Leaves_Fire"
    },
    {
      "x": 1,
      "y": 11,
      "z": 0,
      "name": "Wood_Fire_Trunk_Full"
    },
    {
      "x": 1,
      "y": 14,
      "z": 0,
      "name": "Wood_Fire_Trunk_Full"
    },
    {
      "x": 1,
      "y": 15,
      "z": 0,
      "name": "Wood_Fire_Trunk_Full"
    },
    {
      "x": 1,
      "y": 25,
      "z": 0,
      "name": "Wood_Fire_Trunk_Full"
    },
    {
      "x": 1,
      "y": 29,
      "z": 0,
      "name": "Plant_Leaves_Fire"
    },
    {
      "x": 1,
      "y": 21,
      "z": 1,
      "name": "Wood_Fire_Trunk_Full"
    },
    {
      "x": 1,
      "y": 25,
      "z": 1,
      "name": "Wood_Fire_Trunk_Full"
    },
    {
      "x": 1,
      "y": 26,
      "z": 1,
      "name": "Wood_Fire_Trunk"
    },
    {
      "x": 1,
      "y": 27,
      "z": 1,
      "name": "Wood_Fire_Trunk_Full"
    },
    {
      "x": 1,
      "y": 28,
      "z": 1,
      "name": "Plant_Leaves_Fire"
    },
    {
      "x": 1,
      "y": 29,
      "z": 1,
      "name": "Plant_Leaves_Fire"
    },
    {
      "x": 1,
      "y": 26,
      "z": 2,
      "name": "Plant_Leaves_Fire"
    },
    {
      "x": 1,
      "y": 27,
      "z": 2,
      "name": "Plant_Leaves_Fire"
    },
    {
      "x": 1,
      "y": 28,
      "z": 2,
      "name": "Plant_Leaves_Fire"
    },
    {
      "x": 1,
      "y": 27,
      "z": 3,
      "name": "Plant_Leaves_Fire"
    },
    {
      "x": 1,
      "y": 28,
      "z": 3,
      "name": "Plant_Leaves_Fire"
    },
    {
      "x": 1,
      "y": 27,
      "z": 4,
      "name": "Plant_Leaves_Fire"
    },
    {
      "x": 1,
      "y": 28,
      "z": 4,
      "name": "Plant_Leaves_Fire"
    },
    {
      "x": 1,
      "y": 24,
      "z": 5,
      "name": "Plant_Leaves_Fire"
    },
    {
      "x": 1,
      "y": 25,
      "z": 5,
      "name": "Plant_Leaves_Fire"
    },
    {
      "x": 1,
      "y": 21,
      "z": 6,
      "name": "Plant_Leaves_Fire"
    },
    {
      "x": 1,
      "y": 22,
      "z": 6,
      "name": "Plant_Leaves_Fire"
    },
    {
      "x": 1,
      "y": 23,
      "z": 6,
      "name": "Plant_Leaves_Fire"
    },
    {
      "x": 1,
      "y": 24,
      "z": 6,
      "name": "Plant_Leaves_Fire"
    },
    {
      "x": 1,
      "y": 22,
      "z": 7,
      "name": "Plant_Leaves_Fire"
    },
    {
      "x": 1,
      "y": 23,
      "z": 7,
      "name": "Plant_Leaves_Fire"
    },
    {
      "x": 2,
      "y": 26,
      "z": -6,
      "name": "Plant_Leaves_Fire"
    },
    {
      "x": 2,
      "y": 27,
      "z": -6,
      "name": "Plant_Leaves_Fire"
    },
    {
      "x": 2,
      "y": 28,
      "z": -6,
      "name": "Plant_Leaves_Fire"
    },
    {
      "x": 2,
      "y": 20,
      "z": -5,
      "name": "Plant_Leaves_Fire"
    },
    {
      "x": 2,
      "y": 21,
      "z": -5,
      "name": "Plant_Leaves_Fire"
    },
    {
      "x": 2,
      "y": 22,
      "z": -5,
      "name": "Plant_Leaves_Fire"
    },
    {
      "x": 2,
      "y": 23,
      "z": -5,
      "name": "Plant_Leaves_Fire"
    },
    {
      "x": 2,
      "y": 27,
      "z": -5,
      "name": "Plant_Leaves_Fire"
    },
    {
      "x": 2,
      "y": 28,
      "z": -5,
      "name": "Plant_Leaves_Fire"
    },
    {
      "x": 2,
      "y": 29,
      "z": -5,
      "name": "Plant_Leaves_Fire"
    },
    {
      "x": 2,
      "y": 22,
      "z": -4,
      "name": "Plant_Leaves_Fire"
    },
    {
      "x": 2,
      "y": 23,
      "z": -4,
      "name": "Plant_Leaves_Fire"
    },
    {
      "x": 2,
      "y": 24,
      "z": -4,
      "name": "Plant_Leaves_Fire"
    },
    {
      "x": 2,
      "y": 26,
      "z": -4,
      "name": "Plant_Leaves_Fire"
    },
    {
      "x": 2,
      "y": 27,
      "z": -4,
      "name": "Plant_Leaves_Fire"
    },
    {
      "x": 2,
      "y": 28,
      "z": -4,
      "name": "Plant_Leaves_Fire"
    },
    {
      "x": 2,
      "y": 29,
      "z": -4,
      "name": "Plant_Leaves_Fire"
    },
    {
      "x": 2,
      "y": 29,
      "z": -1,
      "name": "Plant_Leaves_Fire"
    },
    {
      "x": 2,
      "y": 11,
      "z": 0,
      "name": "Wood_Fire_Trunk_Full"
    },
    {
      "x": 2,
      "y": 12,
      "z": 0,
      "name": "Wood_Fire_Trunk"
    },
    {
      "x": 2,
      "y": 13,
      "z": 0,
      "name": "Wood_Fire_Trunk"
    },
    {
      "x": 2,
      "y": 14,
      "z": 0,
      "name": "Wood_Fire_Trunk_Full"
    },
    {
      "x": 2,
      "y": 25,
      "z": 0,
      "name": "Wood_Fire_Trunk_Full"
    },
    {
      "x": 2,
      "y": 28,
      "z": 0,
      "name": "Plant_Leaves_Fire"
    },
    {
      "x": 2,
      "y": 29,
      "z": 0,
      "name": "Plant_Leaves_Fire"
    },
    {
      "x": 2,
      "y": 21,
      "z": 1,
      "name": "Wood_Fire_Trunk_Full"
    },
    {
      "x": 2,
      "y": 27,
      "z": 1,
      "name": "Wood_Fire_Trunk_Full"
    },
    {
      "x": 2,
      "y": 28,
      "z": 1,
      "name": "Wood_Fire_Trunk_Full"
    },
    {
      "x": 2,
      "y": 29,
      "z": 1,
      "name": "Deco_Fire"
    },
    {
      "x": 2,
      "y": 21,
      "z": 2,
      "name": "Plant_Leaves_Fire"
    },
    {
      "x": 2,
      "y": 26,
      "z": 2,
      "name": "Plant_Leaves_Fire"
    },
    {
      "x": 2,
      "y": 27,
      "z": 2,
      "name": "Plant_Leaves_Fire"
    },
    {
      "x": 2,
      "y": 28,
      "z": 2,
      "name": "Plant_Leaves_Fire"
    },
    {
      "x": 2,
      "y": 29,
      "z": 2,
      "name": "Plant_Leaves_Fire"
    },
    {
      "x": 2,
      "y": 20,
      "z": 3,
      "name": "Plant_Leaves_Fire"
    },
    {
      "x": 2,
      "y": 21,
      "z": 3,
      "name": "Plant_Leaves_Fire"
    },
    {
      "x": 2,
      "y": 27,
      "z": 3,
      "name": "Plant_Leaves_Fire"
    },
    {
      "x": 2,
      "y": 28,
      "z": 3,
      "name": "Plant_Leaves_Fire"
    },
    {
      "x": 2,
      "y": 29,
      "z": 3,
      "name": "Plant_Leaves_Fire"
    },
    {
      "x": 2,
      "y": 26,
      "z": 4,
      "name": "Plant_Leaves_Fire"
    },
    {
      "x": 2,
      "y": 27,
      "z": 4,
      "name": "Plant_Leaves_Fire"
    },
    {
      "x": 2,
      "y": 20,
      "z": 5,
      "name": "Plant_Leaves_Fire"
    },
    {
      "x": 2,
      "y": 21,
      "z": 5,
      "name": "Plant_Leaves_Fire"
    },
    {
      "x": 2,
      "y": 22,
      "z": 5,
      "name": "Plant_Leaves_Fire"
    },
    {
      "x": 2,
      "y": 23,
      "z": 5,
      "name": "Plant_Leaves_Fire"
    },
    {
      "x": 2,
      "y": 24,
      "z": 5,
      "name": "Plant_Leaves_Fire"
    },
    {
      "x": 2,
      "y": 22,
      "z": 6,
      "name": "Plant_Leaves_Fire"
    },
    {
      "x": 2,
      "y": 23,
      "z": 6,
      "name": "Plant_Leaves_Fire"
    },
    {
      "x": 2,
      "y": 24,
      "z": 6,
      "name": "Plant_Leaves_Fire"
    },
    {
      "x": 3,
      "y": 22,
      "z": -5,
      "name": "Plant_Leaves_Fire"
    },
    {
      "x": 3,
      "y": 22,
      "z": -4,
      "name": "Plant_Leaves_Fire"
    },
    {
      "x": 3,
      "y": 23,
      "z": -4,
      "name": "Plant_Leaves_Fire"
    },
    {
      "x": 3,
      "y": 28,
      "z": -4,
      "name": "Plant_Leaves_Fire"
    },
    {
      "x": 3,
      "y": 24,
      "z": -3,
      "name": "Plant_Leaves_Fire"
    },
    {
      "x": 3,
      "y": 25,
      "z": -3,
      "name": "Plant_Leaves_Fire"
    },
    {
      "x": 3,
      "y": 26,
      "z": -3,
      "name": "Plant_Leaves_Fire"
    },
    {
      "x": 3,
      "y": 24,
      "z": -2,
      "name": "Plant_Leaves_Fire"
    },
    {
      "x": 3,
      "y": 26,
      "z": -2,
      "name": "Wood_Fire_Trunk_Full"
    },
    {
      "x": 3,
      "y": 27,
      "z": -2,
      "name": "Deco_Fire"
    },
    {
      "x": 3,
      "y": 28,
      "z": -2,
      "name": "Plant_Leaves_Fire"
    },
    {
      "x": 3,
      "y": 19,
      "z": -1,
      "name": "Plant_Leaves_Fire"
    },
    {
      "x": 3,
      "y": 20,
      "z": -1,
      "name": "Plant_Leaves_Fire"
    },
    {
      "x": 3,
      "y": 21,
      "z": -1,
      "name": "Plant_Leaves_Fire"
    },
    {
      "x": 3,
      "y": 25,
      "z": -1,
      "name": "Wood_Fire_Trunk_Full"
    },
    {
      "x": 3,
      "y": 26,
      "z": -1,
      "name": "Wood_Fire_Trunk_Full"
    },
    {
      "x": 3,
      "y": 27,
      "z": -1,
      "name": "Deco_Fire"
    },
    {
      "x": 3,
      "y": 28,
      "z": -1,
      "name": "Plant_Leaves_Fire"
    },
    {
      "x": 3,
      "y": 20,
      "z": 0,
      "name": "Plant_Leaves_Fire"
    },
    {
      "x": 3,
      "y": 21,
      "z": 0,
      "name": "Plant_Leaves_Fire"
    },
    {
      "x": 3,
      "y": 22,
      "z": 0,
      "name": "Plant_Leaves_Fire"
    },
    {
      "x": 3,
      "y": 25,
      "z": 0,
      "name": "Wood_Fire_Trunk_Full"
    },
    {
      "x": 3,
      "y": 27,
      "z": 0,
      "name": "Plant_Leaves_Fire"
    },
    {
      "x": 3,
      "y": 28,
      "z": 0,
      "name": "Plant_Leaves_Fire"
    },
    {
      "x": 3,
      "y": 29,
      "z": 0,
      "name": "Plant_Leaves_Fire"
    },
    {
      "x": 3,
      "y": 20,
      "z": 1,
      "name": "Plant_Leaves_Fire"
    },
    {
      "x": 3,
      "y": 21,
      "z": 1,
      "name": "Wood_Fire_Trunk_Full"
    },
    {
      "x": 3,
      "y": 22,
      "z": 1,
      "name": "Deco_Fire"
    },
    {
      "x": 3,
      "y": 25,
      "z": 1,
      "name": "Plant_Leaves_Fire"
    },
    {
      "x": 3,
      "y": 27,
      "z": 1,
      "name": "Plant_Leaves_Fire"
    },
    {
      "x": 3,
      "y": 28,
      "z": 1,
      "name": "Plant_Leaves_Fire"
    },
    {
      "x": 3,
      "y": 29,
      "z": 1,
      "name": "Plant_Leaves_Fire"
    },
    {
      "x": 3,
      "y": 19,
      "z": 2,
      "name": "Plant_Leaves_Fire"
    },
    {
      "x": 3,
      "y": 20,
      "z": 2,
      "name": "Plant_Leaves_Fire"
    },
    {
      "x": 3,
      "y": 21,
      "z": 2,
      "name": "Plant_Leaves_Fire"
    },
    {
      "x": 3,
      "y": 22,
      "z": 2,
      "name": "Plant_Leaves_Fire"
    },
    {
      "x": 3,
      "y": 27,
      "z": 2,
      "name": "Plant_Leaves_Fire"
    },
    {
      "x": 3,
      "y": 28,
      "z": 2,
      "name": "Plant_Leaves_Fire"
    },
    {
      "x": 3,
      "y": 21,
      "z": 3,
      "name": "Plant_Leaves_Fire"
    },
    {
      "x": 3,
      "y": 22,
      "z": 3,
      "name": "Plant_Leaves_Fire"
    },
    {
      "x": 3,
      "y": 27,
      "z": 3,
      "name": "Plant_Leaves_Fire"
    },
    {
      "x": 3,
      "y": 23,
      "z": 5,
      "name": "Plant_Leaves_Fire"
    },
    {
      "x": 4,
      "y": 25,
      "z": -3,
      "name": "Plant_Leaves_Fire"
    },
    {
      "x": 4,
      "y": 24,
      "z": -2,
      "name": "Plant_Leaves_Fire"
    },
    {
      "x": 4,
      "y": 25,
      "z": -2,
      "name": "Plant_Leaves_Fire"
    },
    {
      "x": 4,
      "y": 26,
      "z": -2,
      "name": "Plant_Leaves_Fire"
    },
    {
      "x": 4,
      "y": 21,
      "z": -1,
      "name": "Plant_Leaves_Fire"
    },
    {
      "x": 4,
      "y": 27,
      "z": -1,
      "name": "Plant_Leaves_Fire"
    },
    {
      "x": 4,
      "y": 28,
      "z": -1,
      "name": "Plant_Leaves_Fire"
    },
    {
      "x": 4,
      "y": 19,
      "z": 0,
      "name": "Plant_Leaves_Fire"
    },
    {
      "x": 4,
      "y": 20,
      "z": 0,
      "name": "Plant_Leaves_Fire"
    },
    {
      "x": 4,
      "y": 21,
      "z": 0,
      "name": "Plant_Leaves_Fire"
    },
    {
      "x": 4,
      "y": 25,
      "z": 0,
      "name": "Wood_Fire_Trunk_Full"
    },
    {
      "x": 4,
      "y": 26,
      "z": 0,
      "name": "Deco_Fire"
    },
    {
      "x": 4,
      "y": 27,
      "z": 0,
      "name": "Plant_Leaves_Fire"
    },
    {
      "x": 4,
      "y": 20,
      "z": 1,
      "name": "Plant_Leaves_Fire"
    },
    {
      "x": 4,
      "y": 21,
      "z": 1,
      "name": "Plant_Leaves_Fire"
    },
    {
      "x": 4,
      "y": 23,
      "z": 1,
      "name": "Plant_Leaves_Fire"
    },
    {
      "x": 4,
      "y": 24,
      "z": 1,
      "name": "Plant_Leaves_Fire"
    },
    {
      "x": 4,
      "y": 25,
      "z": 1,
      "name": "Plant_Leaves_Fire"
    },
    {
      "x": 4,
      "y": 19,
      "z": 2,
      "name": "Plant_Leaves_Fire"
    },
    {
      "x": 4,
      "y": 20,
      "z": 2,
      "name": "Plant_Leaves_Fire"
    },
    {
      "x": 4,
      "y": 21,
      "z": 2,
      "name": "Plant_Leaves_Fire"
    },
    {
      "x": 4,
      "y": 25,
      "z": 2,
      "name": "Plant_Leaves_Fire"
    },
    {
      "x": 4,
      "y": 26,
      "z": 2,
      "name": "Plant_Leaves_Fire"
    },
    {
      "x": 5,
      "y": 23,
      "z": -2,
      "name": "Plant_Leaves_Fire"
    },
    {
      "x": 5,
      "y": 24,
      "z": -2,
      "name": "Plant_Leaves_Fire"
    },
    {
      "x": 5,
      "y": 25,
      "z": -2,
      "name": "Plant_Leaves_Fire"
    },
    {
      "x": 5,
      "y": 26,
      "z": -2,
      "name": "Plant_Leaves_Fire"
    },
    {
      "x": 5,
      "y": 24,
      "z": -1,
      "name": "Plant_Leaves_Fire"
    },
    {
      "x": 5,
      "y": 25,
      "z": -1,
      "name": "Plant_Leaves_Fire"
    },
    {
      "x": 5,
      "y": 26,
      "z": -1,
      "name": "Plant_Leaves_Fire"
    },
    {
      "x": 5,
      "y": 24,
      "z": 0,
      "name": "Plant_Leaves_Fire"
    },
    {
      "x": 5,
      "y": 25,
      "z": 0,
      "name": "Wood_Fire_Trunk_Full"
    },
    {
      "x": 5,
      "y": 26,
      "z": 0,
      "name": "Plant_Leaves_Fire"
    },
    {
      "x": 5,
      "y": 23,
      "z": 1,
      "name": "Plant_Leaves_Fire"
    },
    {
      "x": 5,
      "y": 24,
      "z": 1,
      "name": "Plant_Leaves_Fire"
    },
    {
      "x": 5,
      "y": 25,
      "z": 1,
      "name": "Plant_Leaves_Fire"
    },
    {
      "x": 5,
      "y": 26,
      "z": 1,
      "name": "Plant_Leaves_Fire"
    },
    {
      "x": 5,
      "y": 25,
      "z": 2,
      "name": "Plant_Leaves_Fire"
    },
    {
      "x": 6,
      "y": 23,
      "z": -1,
      "name": "Plant_Leaves_Fire"
    },
    {
      "x": 6,
      "y": 24,
      "z": -1,
      "name": "Plant_Leaves_Fire"
    },
    {
      "x": 6,
      "y": 25,
      "z": -1,
      "name": "Plant_Leaves_Fire"
    },
    {
      "x": 6,
      "y": 24,
      "z": 0,
      "name": "Plant_Leaves_Fire"
    },
    {
      "x": 6,
      "y": 25,
      "z": 0,
      "name": "Plant_Leaves_Fire"
    },
    {
      "x": 6,
      "y": 26,
      "z": 0,
      "name": "Plant_Leaves_Fire"
    },
    {
      "x": 6,
      "y": 25,
      "z": 1,
      "name": "Plant_Leaves_Fire"
    },
    {
      "x": 6,
      "y": 26,
      "z": 1,
      "name": "Plant_Leaves_Fire"
    }
  ]
}