{
  "version": 8,
  "blockIdVersion": 10,
  "anchorX": -1,
  "anchorY": 6,
  "anchorZ": 2,
  "blocks": [
    {
      "x": -6,
      "y": 14,
      "z": -2,
      "name": "Plant_Leaves_Fire"
    },
    {
      "x": -6,
      "y": 15,
      "z": -2,
      "name": "Plant_Leaves_Fire"
    },
    {
      "x": -6,
      "y": 15,
      "z": -1,
      "name": "Plant_Leaves_Fire"
    },
    {
      "x": -6,
      "y": 12,
      "z": 4,
      "name": "Plant_Leaves_Fire"
    },
    {
      "x": -6,
      "y": 13,
      "z": 4,
      "name": "Plant_Leaves_Fire"
    },
    {
      "x": -6,
      "y": 14,
      "z": 4,
      "name": "Plant_Leaves_Fire"
    },
    {
      "x": -6,
      "y": 14,
      "z": 5,
      "name": "Plant_Leaves_Fire"
    },
    {
      "x": -6,
      "y": 15,
      "z": 5,
      "name": "Plant_Leaves_Fire"
    },
    {
      "x": -5,
      "y": 14,
      "z": -3,
      "name": "Plant_Leaves_Fire"
    },
    {
      "x": -5,
      "y": 15,
      "z": -3,
      "name": "Plant_Leaves_Fire"
    },
    {
      "x": -5,
      "y": 13,
      "z": -2,
      "name": "Plant_Leaves_Fire"
    },
    {
      "x": -5,
      "y": 14,
      "z": -2,
      "name": "Plant_Leaves_Fire"
    },
    {
      "x": -5,
      "y": 15,
      "z": -2,
      "name": "Plant_Leaves_Fire"
    },
    {
      "x": -5,
      "y": 16,
      "z": -2,
      "name": "Plant_Leaves_Fire"
    },
    {
      "x": -5,
      "y": 12,
      "z": -1,
      "name": "Plant_Leaves_Fire"
    },
    {
      "x": -5,
      "y": 13,
      "z": -1,
      "name": "Plant_Leaves_Fire"
    },
    {
      "x": -5,
      "y": 14,
      "z": -1,
      "name": "Plant_Leaves_Fire"
    },
    {
      "x": -5,
      "y": 15,
      "z": -1,
      "name": "Plant_Leaves_Fire"
    },
    {
      "x": -5,
      "y": 16,
      "z": -1,
      "name": "Plant_Leaves_Fire"
    },
    {
      "x": -5,
      "y": 16,
      "z": 0,
      "name": "Plant_Leaves_Fire"
    },
    {
      "x": -5,
      "y": 14,
      "z": 4,
      "name": "Plant_Leaves_Fire"
    },
    {
      "x": -5,
      "y": 15,
      "z": 4,
      "name": "Plant_Leaves_Fire"
    },
    {
      "x": -5,
      "y": 13,
      "z": 5,
      "name": "Plant_Leaves_Fire"
    },
    {
      "x": -5,
      "y": 14,
      "z": 5,
      "name": "Plant_Leaves_Fire"
    },
    {
      "x": -5,
      "y": 15,
      "z": 5,
      "name": "Plant_Leaves_Fire"
    },
    {
      "x": -5,
      "y": 16,
      "z": 5,
      "name": "Plant_Leaves_Fire"
    },
    {
      "x": -5,
      "y": 12,
      "z": 6,
      "name": "Plant_Leaves_Fire"
    },
    {
      "x": -5,
      "y": 13,
      "z": 6,
      "name": "Plant_Leaves_Fire"
    },
    {
      "x": -5,
      "y": 14,
      "z": 6,
      "name": "Plant_Leaves_Fire"
    },
    {
      "x": -5,
      "y": 15,
      "z": 6,
      "name": "Plant_Leaves_Fire"
    },
    {
      "x": -5,
      "y": 16,
      "z": 6,
      "name": "Plant_Leaves_Fire"
    },
    {
      "x": -5,
      "y": 13,
      "z": 7,
      "name": "Plant_Leaves_Fire"
    },
    {
      "x": -5,
      "y": 14,
      "z": 7,
      "name": "Plant_Leaves_Fire"
    },
    {
      "x": -4,
      "y": 14,
      "z": -3,
      "name": "Plant_Leaves_Fire"
    },
    {
      "x": -4,
      "y": 15,
      "z": -3,
      "name": "Plant_Leaves_Fire"
    },
    {
      "x": -4,
      "y": 16,
      "z": -3,
      "name": "Plant_Leaves_Fire"
    },
    {
      "x": -4,
      "y": 14,
      "z": -2,
      "name": "Plant_Leaves_Fire"
    },
    {
      "x": -4,
      "y": 15,
      "z": -2,
      "name": "Wood_Fire_Trunk_Full"
    },
    {
      "x": -4,
      "y": 16,
      "z": -2,
      "name": "Deco_Fire"
    },
    {
      "x": -4,
      "y": 17,
      "z": -2,
      "name": "Plant_Leaves_Fire"
    },
    {
      "x": -4,
      "y": 14,
      "z": -1,
      "name": "Wood_Fire_Trunk_Full"
    },
    {
      "x": -4,
      "y": 15,
      "z": -1,
      "name": "Wood_Fire_Trunk_Full"
    },
    {
      "x": -4,
      "y": 16,
      "z": -1,
      "name": "Plant_Leaves_Fire"
    },
    {
      "x": -4,
      "y": 17,
      "z": -1,
      "name": "Plant_Leaves_Fire"
    },
    {
      "x": -4,
      "y": 13,
      "z": 0,
      "name": "Wood_Fire_Trunk_Full"
    },
    {
      "x": -4,
      "y": 14,
      "z": 0,
      "name": "Wood_Fire_Trunk_Full"
    },
    {
      "x": -4,
      "y": 19,
      "z": 0,
      "name": "Plant_Leaves_Fire"
    },
    {
      "x": -4,
      "y": 13,
      "z": 1,
      "name": "Wood_Fire_Trunk_Full"
    },
    {
      "x": -4,
      "y": 16,
      "z": 1,
      "name": "Plant_Leaves_Fire"
    },
    {
      "x": -4,
      "y": 17,
      "z": 1,
      "name": "Plant_Leaves_Fire"
    },
    {
      "x": -4,
      "y": 19,
      "z": 1,
      "name": "Plant_Leaves_Fire"
    },
    {
      "x": -4,
      "y": 6,
      "z": 2,
      "name": "Wood_Fire_Trunk_Full"
    },
    {
      "x": -4,
      "y": 7,
      "z": 2,
      "name": "Wood_Fire_Trunk"
    },
    {
      "x": -4,
      "y": 8,
      "z": 2,
      "name": "Wood_Fire_Trunk_Full"
    },
    {
      "x": -4,
      "y": 15,
      "z": 2,
      "name": "Plant_Leaves_Fire"
    },
    {
      "x": -4,
      "y": 16,
      "z": 2,
      "name": "Plant_Leaves_Fire"
    },
    {
      "x": -4,
      "y": 17,
      "z": 2,
      "name": "Plant_Leaves_Fire"
    },
    {
      "x": -4,
      "y": 18,
      "z": 2,
      "name": "Plant_Leaves_Fire"
    },
    {
      "x": -4,
      "y": 19,
      "z": 2,
      "name": "Plant_Leaves_Fire"
    },
    {
      "x": -4,
      "y": 16,
      "z": 3,
      "name": "Plant_Leaves_Fire"
    },
    {
      "x": -4,
      "y": 17,
      "z": 3,
      "name": "Plant_Leaves_Fire"
    },
    {
      "x": -4,
      "y": 18,
      "z": 3,
      "name": "Plant_Leaves_Fire"
    },
    {
      "x": -4,
      "y": 19,
      "z": 3,
      "name": "Plant_Leaves_Fire"
    },
    {
      "x": -4,
      "y": 20,
      "z": 3,
      "name": "Plant_Leaves_Fire"
    },
    {
      "x": -4,
      "y": 14,
      "z": 4,
      "name": "Wood_Fire_Trunk_Full"
    },
    {
      "x": -4,
      "y": 15,
      "z": 4,
      "name": "Deco_Fire"
    },
    {
      "x": -4,
      "y": 14,
      "z": 5,
      "name": "Wood_Fire_Trunk_Full"
    },
    {
      "x": -4,
      "y": 15,
      "z": 5,
      "name": "Wood_Fire_Trunk_Full"
    },
    {
      "x": -4,
      "y": 16,
      "z": 5,
      "name": "Deco_Fire"
    },
    {
      "x": -4,
      "y": 14,
      "z": 6,
      "name": "Plant_Leaves_Fire"
    },
    {
      "x": -4,
      "y": 15,
      "z": 6,
      "name": "Wood_Fire_Trunk_Full"
    },
    {
      "x": -4,
      "y": 16,
      "z": 6,
      "name": "Deco_Fire"
    },
    {
      "x": -4,
      "y": 13,
      "z": 7,
      "name": "Plant_Leaves_Fire"
    },
    {
      "x": -4,
      "y": 14,
      "z": 7,
      "name": "Plant_Leaves_Fire"
    },
    {
      "x": -4,
      "y": 15,
      "z": 7,
      "name": "Plant_Leaves_Fire"
    },
    {
      "x": -3,
      "y": 12,
      "z": -3,
      "name": "Plant_Leaves_Fire"
    },
    {
      "x": -3,
      "y": 13,
      "z": -3,
      "name": "Plant_Leaves_Fire"
    },
    {
      "x": -3,
      "y": 14,
      "z": -3,
      "name": "Plant_Leaves_Fire"
    },
    {
      "x": -3,
      "y": 15,
      "z": -3,
      "name": "Plant_Leaves_Fire"
    },
    {
      "x": -3,
      "y": 16,
      "z": -3,
      "name": "Plant_Leaves_Fire"
    },
    {
      "x": -3,
      "y": 15,
      "z": -2,
      "name": "Plant_Leaves_Fire"
    },
    {
      "x": -3,
      "y": 16,
      "z": -2,
      "name": "Plant_Leaves_Fire"
    },
    {
      "x": -3,
      "y": 17,
      "z": -2,
      "name": "Plant_Leaves_Fire"
    },
    {
      "x": -3,
      "y": 14,
      "z": -1,
      "name": "Plant_Leaves_Fire"
    },
    {
      "x": -3,
      "y": 15,
      "z": -1,
      "name": "Plant_Leaves_Fire"
    },
    {
      "x": -3,
      "y": 16,
      "z": -1,
      "name": "Plant_Leaves_Fire"
    },
    {
      "x": -3,
      "y": 17,
      "z": -1,
      "name": "Plant_Leaves_Fire"
    },
    {
      "x": -3,
      "y": 19,
      "z": -1,
      "name": "Plant_Leaves_Fire"
    },
    {
      "x": -3,
      "y": 18,
      "z": 0,
      "name": "Plant_Leaves_Fire"
    },
    {
      "x": -3,
      "y": 19,
      "z": 0,
      "name": "Plant_Leaves_Fire"
    },
    {
      "x": -3,
      "y": 20,
      "z": 0,
      "name": "Plant_Leaves_Fire"
    },
    {
      "x": -3,
      "y": 13,
      "z": 1,
      "name": "Wood_Fire_Trunk_Full"
    },
    {
      "x": -3,
      "y": 15,
      "z": 1,
      "name": "Plant_Leaves_Fire"
    },
    {
      "x": -3,
      "y": 16,
      "z": 1,
      "name": "Plant_Leaves_Fire"
    },
    {
      "x": -3,
      "y": 17,
      "z": 1,
      "name": "Plant_Leaves_Fire"
    },
    {
      "x": -3,
      "y": 19,
      "z": 1,
      "name": "Plant_Leaves_Fire"
    },
    {
      "x": -3,
      "y": 20,
      "z": 1,
      "name": "Plant_Leaves_Fire"
    },
    {
      "x": -3,
      "y": 5,
      "z": 2,
      "name": "Wood_Fire_Trunk_Full"
    },
    {
      "x": -3,
      "y": 6,
      "z": 2,
      "name": "Wood_Fire_Trunk_Full"
    },
    {
      "x": -3,
      "y": 8,
      "z": 2,
      "name": "Wood_Fire_Trunk_Full"
    },
    {
      "x": -3,
      "y": 9,
      "z": 2,
      "name": "Wood_Fire_Trunk_Full"
    },
    {
      "x": -3,
      "y": 12,
      "z": 2,
      "name": "Wood_Fire_Trunk_Full"
    },
    {
      "x": -3,
      "y": 13,
      "z": 2,
      "name": "Wood_Fire_Trunk"
    },
    {
      "x": -3,
      "y": 14,
      "z": 2,
      "name": "Wood_Fire_Trunk"
    },
    {
      "x": -3,
      "y": 15,
      "z": 2,
      "name": "Wood_Fire_Trunk_Full"
    },
    {
      "x": -3,
      "y": 16,
      "z": 2,
      "name": "Wood_Fire_Trunk_Full"
    },
    {
      "x": -3,
      "y": 17,
      "z": 2,
      "name": "Plant_Leaves_Fire"
    },
    {
      "x": -3,
      "y": 18,
      "z": 2,
      "name": "Plant_Leaves_Fire"
    },
    {
      "x": -3,
      "y": 19,
      "z": 2,
      "name": "Plant_Leaves_Fire"
    },
    {
      "x": -3,
      "y": 20,
      "z": 2,
      "name": "Plant_Leaves_Fire"
    },
    {
      "x": -3,
      "y": 21,
      "z": 2,
      "name": "Plant_Leaves_Fire"
    },
    {
      "x": -3,
      "y": 14,
      "z": 3,
      "name": "Wood_Fire_Trunk_Full"
    },
    {
      "x": -3,
      "y": 15,
      "z": 3,
      "name": "Plant_Leaves_Fire"
    },
    {
      "x": -3,
      "y": 16,
      "z": 3,
      "name": "Plant_Leaves_Fire"
    },
    {
      "x": -3,
      "y": 17,
      "z": 3,
      "name": "Plant_Leaves_Fire"
    },
    {
      "x": -3,
      "y": 18,
      "z": 3,
      "name": "Plant_Leaves_Fire"
    },
    {
      "x": -3,
      "y": 19,
      "z": 3,
      "name": "Plant_Leaves_Fire"
    },
    {
      "x": -3,
      "y": 20,
      "z": 3,
      "name": "Plant_Leaves_Fire"
    },
    {
      "x": -3,
      "y": 14,
      "z": 4,
      "name": "Wood_Fire_Trunk_Full"
    },
    {
      "x": -3,
      "y": 16,
      "z": 4,
      "name": "Plant_Leaves_Fire"
    },
    {
      "x": -3,
      "y": 17,
      "z": 4,
      "name": "Plant_Leaves_Fire"
    },
    {
      "x": -3,
      "y": 19,
      "z": 4,
      "name": "Plant_Leaves_Fire"
    },
    {
      "x": -3,
      "y": 15,
      "z": 6,
      "name": "Plant_Leaves_Fire"
    },
    {
      "x": -3,
      "y": 14,
      "z": 7,
      "name": "Plant_Leaves_Fire"
    },
    {
      "x": -3,
      "y": 15,
      "z": 7,
      "name": "Plant_Leaves_Fire"
    },
    {
      "x": -3,
      "y": 16,
      "z": 7,
      "name": "Plant_Leaves_Fire"
    },
    {
      "x": -2,
      "y": 15,
      "z": -3,
      "name": "Plant_Leaves_Fire"
    },
    {
      "x": -2,
      "y": 16,
      "z": -3,
      "name": "Plant_Leaves_Fire"
    },
    {
      "x": -2,
      "y": 13,
      "z": -2,
      "name": "Wood_Fire_Trunk_Full"
    },
    {
      "x": -2,
      "y": 16,
      "z": -2,
      "name": "Plant_Leaves_Fire"
    },
    {
      "x": -2,
      "y": 17,
      "z": -2,
      "name": "Plant_Leaves_Fire"
    },
    {
      "x": -2,
      "y": 19,
      "z": -2,
      "name": "Plant_Leaves_Fire"
    },
    {
      "x": -2,
      "y": 19,
      "z": -1,
      "name": "Plant_Leaves_Fire"
    },
    {
      "x": -2,
      "y": 17,
      "z": 0,
      "name": "Plant_Leaves_Fire"
    },
    {
      "x": -2,
      "y": 20,
      "z": 0,
      "name": "Plant_Leaves_Fire"
    },
    {
      "x": -2,
      "y": 17,
      "z": 1,
      "name": "Plant_Leaves_Fire"
    },
    {
      "x": -2,
      "y": 18,
      "z": 1,
      "name": "Plant_Leaves_Fire"
    },
    {
      "x": -2,
      "y": 19,
      "z": 1,
      "name": "Plant_Leaves_Fire"
    },
    {
      "x": -2,
      "y": 20,
      "z": 1,
      "name": "Plant_Leaves_Fire"
    },
    {
      "x": -2,
      "y": 21,
      "z": 1,
      "name": "Plant_Leaves_Fire"
    },
    {
      "x": -2,
      "y": 9,
      "z": 2,
      "name": "Wood_Fire_Trunk_Full"
    },
    {
      "x": -2,
      "y": 10,
      "z": 2,
      "name": "Wood_Fire_Trunk"
    },
    {
      "x": -2,
      "y": 11,
      "z": 2,
      "name": "Wood_Fire_Trunk"
    },
    {
      "x": -2,
      "y": 12,
      "z": 2,
      "name": "Wood_Fire_Trunk_Full"
    },
    {
      "x": -2,
      "y": 16,
      "z": 2,
      "name": "Wood_Fire_Trunk_Full"
    },
    {
      "x": -2,
      "y": 17,
      "z": 2,
      "name": "Wood_Fire_Trunk_Full"
    },
    {
      "x": -2,
      "y": 18,
      "z": 2,
      "name": "Wood_Fire_Trunk_Full"
    },
    {
      "x": -2,
      "y": 19,
      "z": 2,
      "name": "Deco_Fire"
    },
    {
      "x": -2,
      "y": 20,
      "z": 2,
      "name": "Wood_Fire_Trunk_Full"
    },
    {
      "x": -2,
      "y": 21,
      "z": 2,
      "name": "Deco_Fire"
    },
    {
      "x": -2,
      "y": 17,
      "z": 3,
      "name": "Plant_Leaves_Fire"
    },
    {
      "x": -2,
      "y": 18,
      "z": 3,
      "name": "Plant_Leaves_Fire"
    },
    {
      "x": -2,
      "y": 19,
      "z": 3,
      "name": "Plant_Leaves_Fire"
    },
    {
      "x": -2,
      "y": 20,
      "z": 3,
      "name": "Plant_Leaves_Fire"
    },
    {
      "x": -2,
      "y": 21,
      "z": 3,
      "name": "Plant_Leaves_Fire"
    },
    {
      "x": -2,
      "y": 17,
      "z": 4,
      "name": "Plant_Leaves_Fire"
    },
    {
      "x": -2,
      "y": 18,
      "z": 4,
      "name": "Plant_Leaves_Fire"
    },
    {
      "x": -2,
      "y": 19,
      "z": 4,
      "name": "Plant_Leaves_Fire"
    },
    {
      "x": -2,
      "y": 20,
      "z": 4,
      "name": "Plant_Leaves_Fire"
    },
    {
      "x": -2,
      "y": 18,
      "z": 5,
      "name": "Plant_Leaves_Fire"
    },
    {
      "x": -2,
      "y": 17,
      "z": 6,
      "name": "Plant_Leaves_Fire"
    },
    {
      "x": -1,
      "y": 13,
      "z": -2,
      "name": "Wood_Fire_Trunk_Full"
    },
    {
      "x": -1,
      "y": 19,
      "z": -2,
      "name": "Plant_Leaves_Fire"
    },
    {
      "x": -1,
      "y": 13,
      "z": -1,
      "name": "Wood_Fire_Trunk_Full"
    },
    {
      "x": -1,
      "y": 18,
      "z": -1,
      "name": "Plant_Leaves_Fire"
    },
    {
      "x": -1,
      "y": 19,
      "z": -1,
      "name": "Plant_Leaves_Fire"
    },
    {
      "x": -1,
      "y": 20,
      "z": -1,
      "name": "Plant_Leaves_Fire"
    },
    {
      "x": -1,
      "y": 5,
      "z": 0,
      "name": "Wood_Fire_Trunk_Full"
    },
    {
      "x": -1,
      "y": 6,
      "z": 0,
      "name": "Wood_Fire_Trunk_Full"
    },
    {
      "x": -1,
      "y": 13,
      "z": 0,
      "name": "Wood_Fire_Trunk_Full"
    },
    {
      "x": -1,
      "y": 15,
      "z": 0,
      "name": "Plant_Leaves_Fire"
    },
    {
      "x": -1,
      "y": 16,
      "z": 0,
      "name": "Plant_Leaves_Fire"
    },
    {
      "x": -1,
      "y": 17,
      "z": 0,
      "name": "Plant_Leaves_Fire"
    },
    {
      "x": -1,
      "y": 18,
      "z": 0,
      "name": "Plant_Leaves_Fire"
    },
    {
      "x": -1,
      "y": 19,
      "z": 0,
      "name": "Plant_Leaves_Fire"
    },
    {
      "x": -1,
      "y": 20,
      "z": 0,
      "name": "Plant_Leaves_Fire"
    },
    {
      "x": -1,
      "y": 6,
      "z": 1,
      "name": "Wood_Fire_Trunk_Full"
    },
    {
      "x": -1,
      "y": 7,
      "z": 1,
      "name": "Wood_Fire_Trunk"
    },
    {
      "x": -1,
      "y": 8,
      "z": 1,
      "name": "Wood_Fire_Trunk"
    },
    {
      "x": -1,
      "y": 9,
      "z": 1,
      "name": "Wood_Fire_Trunk_Full"
    },
    {
      "x": -1,
      "y": 11,
      "z": 1,
      "name": "Wood_Fire_Trunk_Full"
    },
    {
      "x": -1,
      "y": 12,
      "z": 1,
      "name": "Wood_Fire_Trunk_Full",
      "rotation": 4
    },
    {
      "x": -1,
      "y": 13,
      "z": 1,
      "name": "Wood_Fire_Trunk_Full"
    },
    {
      "x": -1,
      "y": 18,
      "z": 1,
      "name": "Plant_Leaves_Fire"
    },
    {
      "x": -1,
      "y": 19,
      "z": 1,
      "name": "Plant_Leaves_Fire"
    },
    {
      "x": -1,
      "y": 20,
      "z": 1,
      "name": "Plant_Leaves_Fire"
    },
    {
      "x": -1,
      "y": 21,
      "z": 1,
      "name": "Plant_Leaves_Fire"
    },
    {
      "x": -1,
      "y": 6,
      "z": 2,
      "name": "Wood_Fire_Trunk_Full"
    },
    {
      "x": -1,
      "y": 8,
      "z": 2,
      "name": "Wood_Fire_Trunk_Full"
    },
    {
      "x": -1,
      "y": 9,
      "z": 2,
      "name": "Wood_Fire_Trunk"
    },
    {
      "x": -1,
      "y": 10,
      "z": 2,
      "name": "Wood_Fire_Trunk"
    },
    {
      "x": -1,
      "y": 11,
      "z": 2,
      "name": "Wood_Fire_Trunk"
    },
    {
      "x": -1,
      "y": 12,
      "z": 2,
      "name": "Wood_Fire_Trunk"
    },
    {
      "x": -1,
      "y": 13,
      "z": 2,
      "name": "Wood_Fire_Trunk_Full"
    },
    {
      "x": -1,
      "y": 14,
      "z": 2,
      "name": "Wood_Fire_Trunk_Full"
    },
    {
      "x": -1,
      "y": 17,
      "z": 2,
      "name": "Plant_Leaves_Fire"
    },
    {
      "x": -1,
      "y": 18,
      "z": 2,
      "name": "Wood_Fire_Trunk_Full"
    },
    {
      "x": -1,
      "y": 19,
      "z": 2,
      "name": "Wood_Fire_Trunk_Full"
    },
    {
      "x": -1,
      "y": 20,
      "z": 2,
      "name": "Wood_Fire_Trunk_Full"
    },
    {
      "x": -1,
      "y": 21,
      "z": 2,
      "name": "Deco_Fire"
    },
    {
      "x": -1,
      "y": 8,
      "z": 3,
      "name": "Wood_Fire_Trunk_Full"
    },
    {
      "x": -1,
      "y": 9,
      "z": 3,
      "name": "Wood_Fire_Trunk_Full"
    },
    {
      "x": -1,
      "y": 17,
      "z": 3,
      "name": "Plant_Leaves_Fire"
    },
    {
      "x": -1,
      "y": 18,
      "z": 3,
      "name": "Plant_Leaves_Fire"
    },
    {
      "x": -1,
      "y": 19,
      "z": 3,
      "name": "Plant_Leaves_Fire"
    },
    {
      "x": -1,
      "y": 20,
      "z": 3,
      "name": "Plant_Leaves_Fire"
    },
    {
      "x": -1,
      "y": 21,
      "z": 3,
      "name": "Plant_Leaves_Fire"
    },
    {
      "x": -1,
      "y": 6,
      "z": 4,
      "name": "Wood_Fire_Trunk_Full"
    },
    {
      "x": -1,
      "y": 7,
      "z": 4,
      "name": "Wood_Fire_Trunk"
    },
    {
      "x": -1,
      "y": 8,
      "z": 4,
      "name": "Wood_Fire_Trunk_Full"
    },
    {
      "x": -1,
      "y": 18,
      "z": 4,
      "name": "Plant_Leaves_Fire"
    },
    {
      "x": -1,
      "y": 19,
      "z": 4,
      "name": "Plant_Leaves_Fire"
    },
    {
      "x": -1,
      "y": 17,
      "z": 5,
      "name": "Plant_Leaves_Fire"
    },
    {
      "x": -1,
      "y": 17,
      "z": 6,
      "name": "Plant_Leaves_Fire"
    },
    {
      "x": -1,
      "y": 18,
      "z": 6,
      "name": "Plant_Leaves_Fire"
    },
    {
      "x": -1,
      "y": 19,
      "z": 6,
      "name": "Plant_Leaves_Fire"
    },
    {
      "x": -1,
      "y": 17,
      "z": 7,
      "name": "Plant_Leaves_Fire"
    },
    {
      "x": -1,
      "y": 18,
      "z": 7,
      "name": "Plant_Leaves_Fire"
    },
    {
      "x": 0,
      "y": 16,
      "z": -3,
      "name": "Plant_Leaves_Fire"
    },
    {
      "x": 0,
      "y": 17,
      "z": -3,
      "name": "Plant_Leaves_Fire"
    },
    {
      "x": 0,
      "y": 18,
      "z": -3,
      "name": "Plant_Leaves_Fire"
    },
    {
      "x": 0,
      "y": 17,
      "z": -2,
      "name": "Plant_Leaves_Fire"
    },
    {
      "x": 0,
      "y": 16,
      "z": 0,
      "name": "Wood_Fire_Trunk_Full"
    },
    {
      "x": 0,
      "y": 17,
      "z": 0,
      "name": "Plant_Leaves_Fire"
    },
    {
      "x": 0,
      "y": 18,
      "z": 0,
      "name": "Plant_Leaves_Fire"
    },
    {
      "x": 0,
      "y": 19,
      "z": 0,
      "name": "Plant_Leaves_Fire"
    },
    {
      "x": 0,
      "y": 12,
      "z": 1,
      "name": "Wood_Fire_Trunk_Full"
    },
    {
      "x": 0,
      "y": 13,
      "z": 1,
      "name": "Wood_Fire_Trunk_Full"
    },
    {
      "x": 0,
      "y": 16,
      "z": 1,
      "name": "Wood_Fire_Trunk_Full"
    },
    {
      "x": 0,
      "y": 17,
      "z": 1,
      "name": "Plant_Leaves_Fire"
    },
    {
      "x": 0,
      "y": 18,
      "z": 1,
      "name": "Plant_Leaves_Fire"
    },
    {
      "x": 0,
      "y": 19,
      "z": 1,
      "name": "Plant_Leaves_Fire"
    },
    {
      "x": 0,
      "y": 20,
      "z": 1,
      "name": "Plant_Leaves_Fire"
    },
    {
      "x": 0,
      "y": 11,
      "z": 2,
      "name": "Wood_Fire_Trunk_Full"
    },
    {
      "x": 0,
      "y": 12,
      "z": 2,
      "name": "Wood_Fire_Trunk_Full"
    },
    {
      "x": 0,
      "y": 13,
      "z": 2,
      "name": "Wood_Fire_Trunk_Full"
    },
    {
      "x": 0,
      "y": 14,
      "z": 2,
      "name": "Wood_Fire_Trunk_Full"
    },
    {
      "x": 0,
      "y": 15,
      "z": 2,
      "name": "Wood_Fire_Trunk"
    },
    {
      "x": 0,
      "y": 16,
      "z": 2,
      "name": "Wood_Fire_Trunk"
    },
    {
      "x": 0,
      "y": 17,
      "z": 2,
      "name": "Wood_Fire_Trunk_Full"
    },
    {
      "x": 0,
      "y": 18,
      "z": 2,
      "name": "Wood_Fire_Trunk_Full"
    },
    {
      "x": 0,
      "y": 19,
      "z": 2,
      "name": "Deco_Fire"
    },
    {
      "x": 0,
      "y": 20,
      "z": 2,
      "name": "Plant_Leaves_Fire"
    },
    {
      "x": 0,
      "y": 13,
      "z": 3,
      "name": "Wood_Fire_Trunk_Full"
    },
    {
      "x": 0,
      "y": 15,
      "z": 3,
      "name": "Wood_Fire_Trunk_Full"
    },
    {
      "x": 0,
      "y": 17,
      "z": 3,
      "name": "Plant_Leaves_Fire"
    },
    {
      "x": 0,
      "y": 18,
      "z": 3,
      "name": "Plant_Leaves_Fire"
    },
    {
      "x": 0,
      "y": 19,
      "z": 3,
      "name": "Plant_Leaves_Fire"
    },
    {
      "x": 0,
      "y": 16,
      "z": 4,
      "name": "Plant_Leaves_Fire"
    },
    {
      "x": 0,
      "y": 17,
      "z": 4,
      "name": "Plant_Leaves_Fire"
    },
    {
      "x": 0,
      "y": 18,
      "z": 4,
      "name": "Plant_Leaves_Fire"
    },
    {
      "x": 0,
      "y": 16,
      "z": 5,
      "name": "Plant_Leaves_Fire"
    },
    {
      "x": 0,
      "y": 17,
      "z": 5,
      "name": "Plant_Leaves_Fire"
    },
    {
      "x": 0,
      "y": 18,
      "z": 5,
      "name": "Plant_Leaves_Fire"
    },
    {
      "x": 0,
      "y": 19,
      "z": 5,
      "name": "Plant_Leaves_Fire"
    },
    {
      "x": 0,
      "y": 17,
      "z": 6,
      "name": "Plant_Leaves_Fire"
    },
    {
      "x": 0,
      "y": 18,
      "z": 6,
      "name": "Plant_Leaves_Fire"
    },
    {
      "x": 0,
      "y": 19,
      "z": 6,
      "name": "Plant_Leaves_Fire"
    },
    {
      "x": 0,
      "y": 14,
      "z": 7,
      "name": "Plant_Leaves_Fire"
    },
    {
      "x": 0,
      "y": 15,
      "z": 7,
      "name": "Plant_Leaves_Fire"
    },
    {
      "x": 0,
      "y": 16,
      "z": 7,
      "name": "Plant_Leaves_Fire"
    },
    {
      "x": 0,
      "y": 17,
      "z": 7,
      "name": "Plant_Leaves_Fire"
    },
    {
      "x": 0,
      "y": 18,
      "z": 7,
      "name": "Plant_Leaves_Fire"
    },
    {
      "x": 1,
      "y": 16,
      "z": -3,
      "name": "Plant_Leaves_Fire"
    },
    {
      "x": 1,
      "y": 17,
      "z": -3,
      "name": "Plant_Leaves_Fire"
    },
    {
      "x": 1,
      "y": 15,
      "z": -2,
      "name": "Plant_Leaves_Fire"
    },
    {
      "x": 1,
      "y": 16,
      "z": -2,
      "name": "Plant_Leaves_Fire"
    },
    {
      "x": 1,
      "y": 17,
      "z": -2,
      "name": "Wood_Fire_Trunk_Full"
    },
    {
      "x": 1,
      "y": 18,
      "z": -2,
      "name": "Deco_Fire"
    },
    {
      "x": 1,
      "y": 16,
      "z": -1,
      "name": "Wood_Fire_Trunk_Full"
    },
    {
      "x": 1,
      "y": 17,
      "z": -1,
      "name": "Wood_Fire_Trunk_Full"
    },
    {
      "x": 1,
      "y": 18,
      "z": -1,
      "name": "Deco_Fire"
    },
    {
      "x": 1,
      "y": 13,
      "z": 0,
      "name": "Wood_Fire_Trunk_Full"
    },
    {
      "x": 1,
      "y": 16,
      "z": 0,
      "name": "Wood_Fire_Trunk_Full"
    },
    {
      "x": 1,
      "y": 13,
      "z": 1,
      "name": "Wood_Fire_Trunk_Full"
    },
    {
      "x": 1,
      "y": 15,
      "z": 1,
      "name": "Plant_Leaves_Fire"
    },
    {
      "x": 1,
      "y": 16,
      "z": 1,
      "name": "Plant_Leaves_Fire"
    },
    {
      "x": 1,
      "y": 17,
      "z": 1,
      "name": "Plant_Leaves_Fire"
    },
    {
      "x": 1,
      "y": 18,
      "z": 1,
      "name": "Plant_Leaves_Fire"
    },
    {
      "x": 1,
      "y": 19,
      "z": 1,
      "name": "Plant_Leaves_Fire"
    },
    {
      "x": 1,
      "y": 16,
      "z": 2,
      "name": "Plant_Leaves_Fire"
    },
    {
      "x": 1,
      "y": 17,
      "z": 2,
      "name": "Plant_Leaves_Fire"
    },
    {
      "x": 1,
      "y": 18,
      "z": 2,
      "name": "Plant_Leaves_Fire"
    },
    {
      "x": 1,
      "y": 19,
      "z": 2,
      "name": "Plant_Leaves_Fire"
    },
    {
      "x": 1,
      "y": 13,
      "z": 3,
      "name": "Wood_Fire_Trunk_Full"
    },
    {
      "x": 1,
      "y": 15,
      "z": 3,
      "name": "Wood_Fire_Trunk_Full"
    },
    {
      "x": 1,
      "y": 17,
      "z": 3,
      "name": "Plant_Leaves_Fire"
    },
    {
      "x": 1,
      "y": 18,
      "z": 3,
      "name": "Plant_Leaves_Fire"
    },
    {
      "x": 1,
      "y": 19,
      "z": 3,
      "name": "Plant_Leaves_Fire"
    },
    {
      "x": 1,
      "y": 15,
      "z": 4,
      "name": "Wood_Fire_Trunk_Full"
    },
    {
      "x": 1,
      "y": 16,
      "z": 4,
      "name": "Wood_Fire_Trunk_Full"
    },
    {
      "x": 1,
      "y": 17,
      "z": 4,
      "name": "Plant_Leaves_Fire"
    },
    {
      "x": 1,
      "y": 16,
      "z": 5,
      "name": "Wood_Fire_Trunk_Full"
    },
    {
      "x": 1,
      "y": 17,
      "z": 5,
      "name": "Wood_Fire_Trunk_Full"
    },
    {
      "x": 1,
      "y": 18,
      "z": 5,
      "name": "Plant_Leaves_Fire"
    },
    {
      "x": 1,
      "y": 19,
      "z": 5,
      "name": "Plant_Leaves_Fire"
    },
    {
      "x": 1,
      "y": 16,
      "z": 6,
      "name": "Plant_Leaves_Fire"
    },
    {
      "x": 1,
      "y": 17,
      "z": 6,
      "name": "Wood_Fire_Trunk_Full"
    },
    {
      "x": 1,
      "y": 18,
      "z": 6,
      "name": "Deco_Fire"
    },
    {
      "x": 1,
      "y": 19,
      "z": 6,
      "name": "Plant_Leaves_Fire"
    },
    {
      "x": 1,
      "y": 16,
      "z": 7,
      "name": "Plant_Leaves_Fire"
    },
    {
      "x": 1,
      "y": 17,
      "z": 7,
      "name": "Plant_Leaves_Fire"
    },
    {
      "x": 1,
      "y": 18,
      "z": 7,
      "name": "Plant_Leaves_Fire"
    },
    {
      "x": 2,
      "y": 15,
      "z": -3,
      "name": "Plant_Leaves_Fire"
    },
    {
      "x": 2,
      "y": 16,
      "z": -3,
      "name": "Plant_Leaves_Fire"
    },
    {
      "x": 2,
      "y": 14,
      "z": -2,
      "name": "Plant_Leaves_Fire"
    },
    {
      "x": 2,
      "y": 15,
      "z": -2,
      "name": "Plant_Leaves_Fire"
    },
    {
      "x": 2,
      "y": 16,
      "z": -2,
      "name": "Plant_Leaves_Fire"
    },
    {
      "x": 2,
      "y": 17,
      "z": -2,
      "name": "Plant_Leaves_Fire"
    },
    {
      "x": 2,
      "y": 18,
      "z": -2,
      "name": "Plant_Leaves_Fire"
    },
    {
      "x": 2,
      "y": 16,
      "z": -1,
      "name": "Plant_Leaves_Fire"
    },
    {
      "x": 2,
      "y": 17,
      "z": -1,
      "name": "Plant_Leaves_Fire"
    },
    {
      "x": 2,
      "y": 18,
      "z": -1,
      "name": "Plant_Leaves_Fire"
    },
    {
      "x": 2,
      "y": 13,
      "z": 0,
      "name": "Wood_Fire_Trunk_Full"
    },
    {
      "x": 2,
      "y": 16,
      "z": 0,
      "name": "Plant_Leaves_Fire"
    },
    {
      "x": 2,
      "y": 17,
      "z": 0,
      "name": "Plant_Leaves_Fire"
    },
    {
      "x": 2,
      "y": 13,
      "z": 3,
      "name": "Wood_Fire_Trunk_Full"
    },
    {
      "x": 2,
      "y": 14,
      "z": 3,
      "name": "Deco_Fire"
    },
    {
      "x": 2,
      "y": 13,
      "z": 4,
      "name": "Wood_Fire_Trunk_Full"
    },
    {
      "x": 2,
      "y": 14,
      "z": 4,
      "name": "Deco_Fire"
    },
    {
      "x": 2,
      "y": 18,
      "z": 4,
      "name": "Plant_Leaves_Fire"
    },
    {
      "x": 2,
      "y": 14,
      "z": 5,
      "name": "Plant_Leaves_Fire"
    },
    {
      "x": 2,
      "y": 15,
      "z": 5,
      "name": "Plant_Leaves_Fire"
    },
    {
      "x": 2,
      "y": 16,
      "z": 5,
      "name": "Plant_Leaves_Fire"
    },
    {
      "x": 2,
      "y": 17,
      "z": 5,
      "name": "Plant_Leaves_Fire"
    },
    {
      "x": 2,
      "y": 18,
      "z": 5,
      "name": "Plant_Leaves_Fire"
    },
    {
      "x": 2,
      "y": 14,
      "z": 6,
      "name": "Plant_Leaves_Fire"
    },
    {
      "x": 2,
      "y": 15,
      "z": 6,
      "name": "Plant_Leaves_Fire"
    },
    {
      "x": 2,
      "y": 16,
      "z": 6,
      "name": "Plant_Leaves_Fire"
    },
    {
      "x": 2,
      "y": 17,
      "z": 6,
      "name": "Plant_Leaves_Fire"
    },
    {
      "x": 2,
      "y": 18,
      "z": 6,
      "name": "Plant_Leaves_Fire"
    },
    {
      "x": 2,
      "y": 16,
      "z": 7,
      "name": "Plant_Leaves_Fire"
    },
    {
      "x": 2,
      "y": 17,
      "z": 7,
      "name": "Plant_Leaves_Fire"
    },
    {
      "x": 3,
      "y": 15,
      "z": -1,
      "name": "Plant_Leaves_Fire"
    },
    {
      "x": 3,
      "y": 16,
      "z": -1,
      "name": "Plant_Leaves_Fire"
    },
    {
      "x": 3,
      "y": 17,
      "z": -1,
      "name": "Plant_Leaves_Fire"
    },
    {
      "x": 3,
      "y": 13,
      "z": 0,
      "name": "Wood_Fire_Trunk_Full"
    },
    {
      "x": 3,
      "y": 14,
      "z": 0,
      "name": "Deco_Fire"
    },
    {
      "x": 3,
      "y": 15,
      "z": 0,
      "name": "Plant_Leaves_Fire"
    },
    {
      "x": 3,
      "y": 16,
      "z": 0,
      "name": "Plant_Leaves_Fire"
    },
    {
      "x": 3,
      "y": 13,
      "z": 4,
      "name": "Wood_Fire_Trunk_Full"
    },
    {
      "x": 3,
      "y": 14,
      "z": 4,
      "name": "Deco_Fire"
    },
    {
      "x": 3,
      "y": 13,
      "z": 5,
      "name": "Plant_Leaves_Fire"
    },
    {
      "x": 3,
      "y": 17,
      "z": 5,
      "name": "Plant_Leaves_Fire"
    },
    {
      "x": 3,
      "y": 13,
      "z": 6,
      "name": "Plant_Leaves_Fire"
    },
    {
      "x": 3,
      "y": 16,
      "z": 6,
      "name": "Plant_Leaves_Fire"
    },
    {
      "x": 3,
      "y": 17,
      "z": 6,
      "name": "Plant_Leaves_Fire"
    },
    {
      "x": 4,
      "y": 11,
      "z": -2,
      "name": "Plant_Leaves_Fire"
    },
    {
      "x": 4,
      "y": 12,
      "z": -2,
      "name": "Plant_Leaves_Fire"
    },
    {
      "x": 4,
      "y": 13,
      "z": -2,
      "name": "Plant_Leaves_Fire"
    },
    {
      "x": 4,
      "y": 14,
      "z": -2,
      "name": "Plant_Leaves_Fire"
    },
    {
      "x": 4,
      "y": 12,
      "z": -1,
      "name": "Plant_Leaves_Fire"
    },
    {
      "x": 4,
      "y": 13,
      "z": -1,
      "name": "Plant_Leaves_Fire"
    },
    {
      "x": 4,
      "y": 14,
      "z": -1,
      "name": "Plant_Leaves_Fire"
    },
    {
      "x": 4,
      "y": 13,
      "z": 0,
      "name": "Wood_Fire_Trunk_Full"
    },
    {
      "x": 4,
      "y": 14,
      "z": 0,
      "name": "Deco_Fire"
    },
    {
      "x": 4,
      "y": 13,
      "z": 1,
      "name": "Plant_Leaves_Fire"
    },
    {
      "x": 4,
      "y": 14,
      "z": 1,
      "name": "Plant_Leaves_Fire"
    },
    {
      "x": 4,
      "y": 12,
      "z": 2,
      "name": "Plant_Leaves_Fire"
    },
    {
      "x": 4,
      "y": 13,
      "z": 2,
      "name": "Plant_Leaves_Fire"
    },
    {
      "x": 4,
      "y": 14,
      "z": 2,
      "name": "Plant_Leaves_Fire"
    },
    {
      "x": 4,
      "y": 11,
      "z": 3,
      "name": "Plant_Leaves_Fire"
    },
    {
      "x": 4,
      "y": 12,
      "z": 3,
      "name": "Plant_Leaves_Fire"
    },
    {
      "x": 4,
      "y": 11,
      "z": 4,
      "name": "Plant_Leaves_Fire"
    },
    {
      "x": 4,
      "y": 12,
      "z": 4,
      "name": "Plant_Leaves_Fire"
    },
    {
      "x": 4,
      "y": 13,
      "z": 4,
      "name": "Wood_Fire_Trunk_Full"
    },
    {
      "x": 4,
      "y": 14,
      "z": 4,
      "name": "Deco_Fire"
    },
    {
      "x": 4,
      "y": 11,
      "z": 5,
      "name": "Plant_Leaves_Fire"
    },
    {
      "x": 4,
      "y": 12,
      "z": 5,
      "name": "Plant_Leaves_Fire"
    },
    {
      "x": 4,
      "y": 13,
      "z": 5,
      "name": "Plant_Leaves_Fire"
    },
    {
      "x": 4,
      "y": 14,
      "z": 5,
      "name": "Plant_Leaves_Fire"
    },
    {
      "x": 4,
      "y": 12,
      "z": 6,
      "name": "Plant_Leaves_Fire"
    },
    {
      "x": 5,
      "y": 12,
      "z": -2,
      "name": "Plant_Leaves_Fire"
    },
    {
      "x": 5,
      "y": 11,
      "z": -1,
      "name": "Plant_Leaves_Fire"
    },
    {
      "x": 5,
      "y": 12,
      "z": -1,
      "name": "Plant_Leaves_Fire"
    },
    {
      "x": 5,
      "y": 13,
      "z": -1,
      "name": "Plant_Leaves_Fire"
    },
    {
      "x": 5,
      "y": 14,
      "z": -1,
      "name": "Plant_Leaves_Fire"
    },
    {
      "x": 5,
      "y": 12,
      "z": 0,
      "name": "Plant_Leaves_Fire"
    },
    {
      "x": 5,
      "y": 13,
      "z": 0,
      "name": "Wood_Fire_Trunk_Full"
    },
    {
      "x": 5,
      "y": 14,
      "z": 0,
      "name": "Deco_Fire"
    },
    {
      "x": 5,
      "y": 12,
      "z": 1,
      "name": "Plant_Leaves_Fire"
    },
    {
      "x": 5,
      "y": 13,
      "z": 1,
      "name": "Plant_Leaves_Fire"
    },
    {
      "x": 5,
      "y": 14,
      "z": 1,
      "name": "Plant_Leaves_Fire"
    },
    {
      "x": 5,
      "y": 13,
      "z": 2,
      "name": "Plant_Leaves_Fire"
    },
    {
      "x": 5,
      "y": 13,
      "z": 3,
      "name": "Plant_Leaves_Fire"
    },
    {
      "x": 5,
      "y": 12,
      "z": 4,
      "name": "Plant_Leaves_Fire"
    },
    {
      "x": 5,
      "y": 13,
      "z": 4,
      "name": "Plant_Leaves_Fire"
    },
    {
      "x": 5,
      "y": 12,
      "z": 5,
      "name": "Plant_Leaves_Fire"
    },
    {
      "x": 6,
      "y": 13,
      "z": -1,
      "name": "Plant_Leaves_Fire"
    },
    {
      "x": 6,
      "y": 10,
      "z": 0,
      "name": "Plant_Leaves_Fire"
    },
    {
      "x": 6,
      "y": 11,
      "z": 0,
      "name": "Plant_Leaves_Fire"
    },
    {
      "x": 6,
      "y": 12,
      "z": 0,
      "name": "Plant_Leaves_Fire"
    },
    {
      "x": 6,
      "y": 13,
      "z": 0,
      "name": "Plant_Leaves_Fire"
    }
  ]
}