{
  "version": 8,
  "blockIdVersion": 8,
  "anchorX": -2,
  "anchorY": 13,
  "anchorZ": -12,
  "blocks": [
    {
      "x": -21,
      "y": 6,
      "z": -7,
      "name": "Rock_Volcanic_Brick"
    },
    {
      "x": -21,
      "y": 7,
      "z": -7,
      "name": "Rock_Volcanic_Brick"
    },
    {
      "x": -21,
      "y": 8,
      "z": -7,
      "name": "Rock_Volcanic_Brick"
    },
    {
      "x": -21,
      "y": 9,
      "z": -7,
      "name": "Rock_Volcanic_Brick"
    },
    {
      "x": -21,
      "y": 10,
      "z": -7,
      "name": "Rock_Volcanic_Brick"
    },
    {
      "x": -21,
      "y": 11,
      "z": -7,
      "name": "Rock_Volcanic_Brick"
    },
    {
      "x": -21,
      "y": 12,
      "z": -7,
      "name": "Rock_Volcanic_Brick"
    },
    {
      "x": -21,
      "y": 13,
      "z": -7,
      "name": "Rock_Volcanic_Brick"
    },
    {
      "x": -21,
      "y": 14,
      "z": -7,
      "name": "Rock_Volcanic_Brick"
    },
    {
      "x": -21,
      "y": 15,
      "z": -7,
      "name": "Rock_Volcanic_Brick"
    },
    {
      "x": -21,
      "y": 16,
      "z": -7,
      "name": "Rock_Volcanic_Brick"
    },
    {
      "x": -21,
      "y": 17,
      "z": -7,
      "name": "Rock_Volcanic_Brick"
    },
    {
      "x": -21,
      "y": 18,
      "z": -7,
      "name": "Rock_Volcanic_Brick"
    },
    {
      "x": -21,
      "y": 19,
      "z": -7,
      "name": "Rock_Volcanic_Brick"
    },
    {
      "x": -21,
      "y": 20,
      "z": -7,
      "name": "Rock_Volcanic_Brick"
    },
    {
      "x": -21,
      "y": 21,
      "z": -7,
      "name": "Rock_Volcanic_Brick"
    },
    {
      "x": -21,
      "y": 22,
      "z": -7,
      "name": "Rock_Volcanic_Brick"
    },
    {
      "x": -21,
      "y": 23,
      "z": -7,
      "name": "Rock_Volcanic_Brick"
    },
    {
      "x": -21,
      "y": 6,
      "z": -6,
      "name": "Rock_Volcanic_Brick"
    },
    {
      "x": -21,
      "y": 7,
      "z": -6,
      "name": "Rock_Volcanic_Brick"
    },
    {
      "x": -21,
      "y": 8,
      "z": -6,
      "name": "Rock_Volcanic_Brick"
    },
    {
      "x": -21,
      "y": 9,
      "z": -6,
      "name": "Rock_Volcanic_Brick"
    },
    {
      "x": -21,
      "y": 10,
      "z": -6,
      "name": "Rock_Volcanic_Brick"
    },
    {
      "x": -21,
      "y": 11,
      "z": -6,
      "name": "Rock_Volcanic_Brick"
    },
    {
      "x": -21,
      "y": 12,
      "z": -6,
      "name": "Rock_Volcanic_Brick"
    },
    {
      "x": -21,
      "y": 13,
      "z": -6,
      "name": "Rock_Volcanic_Brick"
    },
    {
      "x": -21,
      "y": 14,
      "z": -6,
      "name": "Rock_Volcanic_Brick"
    },
    {
      "x": -21,
      "y": 15,
      "z": -6,
      "name": "Rock_Volcanic_Brick"
    },
    {
      "x": -21,
      "y": 16,
      "z": -6,
      "name": "Rock_Volcanic_Brick"
    },
    {
      "x": -21,
      "y": 17,
      "z": -6,
      "name": "Rock_Volcanic_Brick"
    },
    {
      "x": -21,
      "y": 18,
      "z": -6,
      "name": "Rock_Volcanic_Brick"
    },
    {
      "x": -21,
      "y": 19,
      "z": -6,
      "name": "Rock_Volcanic_Brick"
    },
    {
      "x": -21,
      "y": 20,
      "z": -6,
      "name": "Rock_Volcanic_Brick"
    },
    {
      "x": -21,
      "y": 21,
      "z": -6,
      "name": "Rock_Volcanic_Brick"
    },
    {
      "x": -21,
      "y": 22,
      "z": -6,
      "name": "Rock_Volcanic_Brick"
    },
    {
      "x": -21,
      "y": 23,
      "z": -6,
      "name": "Rock_Volcanic_Brick"
    },
    {
      "x": -21,
      "y": 6,
      "z": -5,
      "name": "Rock_Volcanic_Brick"
    },
    {
      "x": -21,
      "y": 7,
      "z": -5,
      "name": "Rock_Volcanic_Brick"
    },
    {
      "x": -21,
      "y": 8,
      "z": -5,
      "name": "Rock_Volcanic_Brick"
    },
    {
      "x": -21,
      "y": 9,
      "z": -5,
      "name": "Rock_Volcanic_Brick"
    },
    {
      "x": -21,
      "y": 10,
      "z": -5,
      "name": "Rock_Volcanic_Brick"
    },
    {
      "x": -21,
      "y": 11,
      "z": -5,
      "name": "Rock_Volcanic_Brick"
    },
    {
      "x": -21,
      "y": 12,
      "z": -5,
      "name": "Rock_Volcanic_Brick"
    },
    {
      "x": -21,
      "y": 13,
      "z": -5,
      "name": "Rock_Volcanic_Brick"
    },
    {
      "x": -21,
      "y": 14,
      "z": -5,
      "name": "Rock_Volcanic_Brick"
    },
    {
      "x": -21,
      "y": 15,
      "z": -5,
      "name": "Rock_Volcanic_Brick"
    },
    {
      "x": -21,
      "y": 16,
      "z": -5,
      "name": "Rock_Volcanic_Brick"
    },
    {
      "x": -21,
      "y": 17,
      "z": -5,
      "name": "Rock_Volcanic_Brick"
    },
    {
      "x": -21,
      "y": 18,
      "z": -5,
      "name": "Rock_Volcanic_Brick"
    },
    {
      "x": -21,
      "y": 19,
      "z": -5,
      "name": "Rock_Volcanic_Brick"
    },
    {
      "x": -21,
      "y": 20,
      "z": -5,
      "name": "Rock_Volcanic_Brick"
    },
    {
      "x": -21,
      "y": 21,
      "z": -5,
      "name": "Rock_Volcanic_Brick"
    },
    {
      "x": -21,
      "y": 22,
      "z": -5,
      "name": "Rock_Volcanic_Brick"
    },
    {
      "x": -21,
      "y": 23,
      "z": -5,
      "name": "Rock_Volcanic_Brick"
    },
    {
      "x": -21,
      "y": 6,
      "z": -4,
      "name": "Rock_Volcanic_Brick"
    },
    {
      "x": -21,
      "y": 7,
      "z": -4,
      "name": "Rock_Volcanic_Brick"
    },
    {
      "x": -21,
      "y": 8,
      "z": -4,
      "name": "Rock_Volcanic_Brick"
    },
    {
      "x": -21,
      "y": 9,
      "z": -4,
      "name": "Rock_Volcanic_Brick"
    },
    {
      "x": -21,
      "y": 10,
      "z": -4,
      "name": "Rock_Volcanic_Brick"
    },
    {
      "x": -21,
      "y": 11,
      "z": -4,
      "name": "Rock_Volcanic_Brick"
    },
    {
      "x": -21,
      "y": 12,
      "z": -4,
      "name": "Rock_Volcanic_Brick"
    },
    {
      "x": -21,
      "y": 13,
      "z": -4,
      "name": "Rock_Volcanic_Brick"
    },
    {
      "x": -21,
      "y": 14,
      "z": -4,
      "name": "Rock_Volcanic_Brick"
    },
    {
      "x": -21,
      "y": 15,
      "z": -4,
      "name": "Rock_Volcanic_Brick"
    },
    {
      "x": -21,
      "y": 16,
      "z": -4,
      "name": "Rock_Volcanic_Brick"
    },
    {
      "x": -21,
      "y": 17,
      "z": -4,
      "name": "Rock_Volcanic_Brick"
    },
    {
      "x": -21,
      "y": 18,
      "z": -4,
      "name": "Soil_Clay_Black"
    },
    {
      "x": -21,
      "y": 19,
      "z": -4,
      "name": "Soil_Clay_Black"
    },
    {
      "x": -21,
      "y": 20,
      "z": -4,
      "name": "Soil_Clay_Black"
    },
    {
      "x": -21,
      "y": 21,
      "z": -4,
      "name": "Rock_Volcanic_Brick"
    },
    {
      "x": -21,
      "y": 22,
      "z": -4,
      "name": "Rock_Volcanic_Brick"
    },
    {
      "x": -21,
      "y": 23,
      "z": -4,
      "name": "Rock_Volcanic_Brick"
    },
    {
      "x": -21,
      "y": 6,
      "z": -3,
      "name": "Rock_Volcanic_Brick"
    },
    {
      "x": -21,
      "y": 7,
      "z": -3,
      "name": "Rock_Volcanic_Brick"
    },
    {
      "x": -21,
      "y": 8,
      "z": -3,
      "name": "Rock_Volcanic_Brick"
    },
    {
      "x": -21,
      "y": 9,
      "z": -3,
      "name": "Rock_Volcanic_Brick"
    },
    {
      "x": -21,
      "y": 10,
      "z": -3,
      "name": "Rock_Volcanic_Brick"
    },
    {
      "x": -21,
      "y": 11,
      "z": -3,
      "name": "Rock_Volcanic_Brick"
    },
    {
      "x": -21,
      "y": 12,
      "z": -3,
      "name": "Rock_Volcanic_Brick"
    },
    {
      "x": -21,
      "y": 13,
      "z": -3,
      "name": "Rock_Volcanic_Brick"
    },
    {
      "x": -21,
      "y": 14,
      "z": -3,
      "name": "Rock_Volcanic_Brick"
    },
    {
      "x": -21,
      "y": 15,
      "z": -3,
      "name": "Rock_Volcanic_Brick"
    },
    {
      "x": -21,
      "y": 16,
      "z": -3,
      "name": "Rock_Volcanic_Brick"
    },
    {
      "x": -21,
      "y": 17,
      "z": -3,
      "name": "Soil_Clay_Black"
    },
    {
      "x": -21,
      "y": 18,
      "z": -3,
      "name": "Soil_Clay_Black"
    },
    {
      "x": -21,
      "y": 19,
      "z": -3,
      "name": "Soil_Clay_Black"
    },
    {
      "x": -21,
      "y": 20,
      "z": -3,
      "name": "Soil_Clay_Black"
    },
    {
      "x": -21,
      "y": 21,
      "z": -3,
      "name": "Soil_Clay_Black"
    },
    {
      "x": -21,
      "y": 22,
      "z": -3,
      "name": "Rock_Volcanic_Brick"
    },
    {
      "x": -21,
      "y": 23,
      "z": -3,
      "name": "Rock_Volcanic_Brick"
    },
    {
      "x": -21,
      "y": 6,
      "z": -2,
      "name": "Rock_Volcanic_Brick"
    },
    {
      "x": -21,
      "y": 7,
      "z": -2,
      "name": "Rock_Volcanic_Brick"
    },
    {
      "x": -21,
      "y": 8,
      "z": -2,
      "name": "Rock_Volcanic_Brick"
    },
    {
      "x": -21,
      "y": 9,
      "z": -2,
      "name": "Empty"
    },
    {
      "x": -21,
      "y": 10,
      "z": -2,
      "name": "Empty"
    },
    {
      "x": -21,
      "y": 11,
      "z": -2,
      "name": "Empty"
    },
    {
      "x": -21,
      "y": 12,
      "z": -2,
      "name": "Rock_Volcanic_Brick"
    },
    {
      "x": -21,
      "y": 13,
      "z": -2,
      "name": "Rock_Volcanic_Brick"
    },
    {
      "x": -21,
      "y": 14,
      "z": -2,
      "name": "Rock_Volcanic_Brick"
    },
    {
      "x": -21,
      "y": 15,
      "z": -2,
      "name": "Empty"
    },
    {
      "x": -21,
      "y": 16,
      "z": -2,
      "name": "Empty"
    },
    {
      "x": -21,
      "y": 17,
      "z": -2,
      "name": "Empty"
    },
    {
      "x": -21,
      "y": 18,
      "z": -2,
      "name": "Soil_Clay_Black"
    },
    {
      "x": -21,
      "y": 19,
      "z": -2,
      "name": "Soil_Clay_Black"
    },
    {
      "x": -21,
      "y": 20,
      "z": -2,
      "name": "Soil_Clay_Black"
    },
    {
      "x": -21,
      "y": 21,
      "z": -2,
      "name": "Soil_Clay_Black"
    },
    {
      "x": -21,
      "y": 22,
      "z": -2,
      "name": "Soil_Clay_Black"
    },
    {
      "x": -21,
      "y": 23,
      "z": -2,
      "name": "Rock_Volcanic_Brick"
    },
    {
      "x": -21,
      "y": 6,
      "z": -1,
      "name": "Soil_Dirt_Poisoned"
    },
    {
      "x": -21,
      "y": 7,
      "z": -1,
      "name": "Soil_Dirt_Poisoned"
    },
    {
      "x": -21,
      "y": 8,
      "z": -1,
      "name": "Empty"
    },
    {
      "x": -21,
      "y": 9,
      "z": -1,
      "name": "Empty"
    },
    {
      "x": -21,
      "y": 10,
      "z": -1,
      "name": "Empty"
    },
    {
      "x": -21,
      "y": 11,
      "z": -1,
      "name": "Empty"
    },
    {
      "x": -21,
      "y": 12,
      "z": -1,
      "name": "Empty"
    },
    {
      "x": -21,
      "y": 13,
      "z": -1,
      "name": "Rock_Volcanic_Brick"
    },
    {
      "x": -21,
      "y": 14,
      "z": -1,
      "name": "Empty"
    },
    {
      "x": -21,
      "y": 15,
      "z": -1,
      "name": "Empty"
    },
    {
      "x": -21,
      "y": 16,
      "z": -1,
      "name": "Empty"
    },
    {
      "x": -21,
      "y": 17,
      "z": -1,
      "name": "Empty"
    },
    {
      "x": -21,
      "y": 18,
      "z": -1,
      "name": "Empty"
    },
    {
      "x": -21,
      "y": 19,
      "z": -1,
      "name": "Soil_Clay_Black"
    },
    {
      "x": -21,
      "y": 20,
      "z": -1,
      "name": "Soil_Clay_Black"
    },
    {
      "x": -21,
      "y": 21,
      "z": -1,
      "name": "Soil_Clay_Black"
    },
    {
      "x": -21,
      "y": 22,
      "z": -1,
      "name": "Soil_Clay_Black"
    },
    {
      "x": -21,
      "y": 23,
      "z": -1,
      "name": "Soil_Clay_Black"
    },
    {
      "x": -21,
      "y": 6,
      "z": 0,
      "name": "Soil_Dirt_Poisoned"
    },
    {
      "x": -21,
      "y": 7,
      "z": 0,
      "name": "Soil_Dirt_Poisoned"
    },
    {
      "x": -21,
      "y": 8,
      "z": 0,
      "name": "Empty"
    },
    {
      "x": -21,
      "y": 9,
      "z": 0,
      "name": "Empty"
    },
    {
      "x": -21,
      "y": 10,
      "z": 0,
      "name": "Empty"
    },
    {
      "x": -21,
      "y": 11,
      "z": 0,
      "name": "Empty"
    },
    {
      "x": -21,
      "y": 12,
      "z": 0,
      "name": "Empty"
    },
    {
      "x": -21,
      "y": 13,
      "z": 0,
      "name": "Rock_Volcanic_Brick"
    },
    {
      "x": -21,
      "y": 14,
      "z": 0,
      "name": "Empty"
    },
    {
      "x": -21,
      "y": 15,
      "z": 0,
      "name": "Empty"
    },
    {
      "x": -21,
      "y": 16,
      "z": 0,
      "name": "Empty"
    },
    {
      "x": -21,
      "y": 17,
      "z": 0,
      "name": "Empty"
    },
    {
      "x": -21,
      "y": 18,
      "z": 0,
      "name": "Empty"
    },
    {
      "x": -21,
      "y": 19,
      "z": 0,
      "name": "Rock_Volcanic_Brick"
    },
    {
      "x": -21,
      "y": 20,
      "z": 0,
      "name": "Soil_Clay_Black"
    },
    {
      "x": -21,
      "y": 21,
      "z": 0,
      "name": "Soil_Clay_Black"
    },
    {
      "x": -21,
      "y": 22,
      "z": 0,
      "name": "Soil_Clay_Black"
    },
    {
      "x": -21,
      "y": 23,
      "z": 0,
      "name": "Soil_Clay_Black"
    },
    {
      "x": -21,
      "y": 6,
      "z": 1,
      "name": "Soil_Dirt_Poisoned"
    },
    {
      "x": -21,
      "y": 7,
      "z": 1,
      "name": "Soil_Dirt_Poisoned"
    },
    {
      "x": -21,
      "y": 8,
      "z": 1,
      "name": "Plant_Seaweed_Dead_Stack"
    },
    {
      "x": -21,
      "y": 9,
      "z": 1,
      "name": "Plant_Seaweed_Dead_Stack"
    },
    {
      "x": -21,
      "y": 10,
      "z": 1,
      "name": "Empty"
    },
    {
      "x": -21,
      "y": 11,
      "z": 1,
      "name": "Empty"
    },
    {
      "x": -21,
      "y": 12,
      "z": 1,
      "name": "Empty"
    },
    {
      "x": -21,
      "y": 13,
      "z": 1,
      "name": "Rock_Volcanic_Brick"
    },
    {
      "x": -21,
      "y": 14,
      "z": 1,
      "name": "Empty"
    },
    {
      "x": -21,
      "y": 15,
      "z": 1,
      "name": "Empty"
    },
    {
      "x": -21,
      "y": 16,
      "z": 1,
      "name": "Empty"
    },
    {
      "x": -21,
      "y": 17,
      "z": 1,
      "name": "Empty"
    },
    {
      "x": -21,
      "y": 18,
      "z": 1,
      "name": "Empty"
    },
    {
      "x": -21,
      "y": 19,
      "z": 1,
      "name": "Rock_Volcanic_Brick"
    },
    {
      "x": -21,
      "y": 20,
      "z": 1,
      "name": "Rock_Volcanic_Brick"
    },
    {
      "x": -21,
      "y": 21,
      "z": 1,
      "name": "Soil_Clay_Black"
    },
    {
      "x": -21,
      "y": 22,
      "z": 1,
      "name": "Soil_Clay_Black"
    },
    {
      "x": -21,
      "y": 23,
      "z": 1,
      "name": "Soil_Clay_Black"
    },
    {
      "x": -21,
      "y": 6,
      "z": 2,
      "name": "Rock_Volcanic_Brick"
    },
    {
      "x": -21,
      "y": 7,
      "z": 2,
      "name": "Rock_Volcanic_Brick"
    },
    {
      "x": -21,
      "y": 8,
      "z": 2,
      "name": "Rock_Volcanic_Brick"
    },
    {
      "x": -21,
      "y": 9,
      "z": 2,
      "name": "Empty"
    },
    {
      "x": -21,
      "y": 10,
      "z": 2,
      "name": "Empty"
    },
    {
      "x": -21,
      "y": 11,
      "z": 2,
      "name": "Empty"
    },
    {
      "x": -21,
      "y": 12,
      "z": 2,
      "name": "Rock_Volcanic_Brick"
    },
    {
      "x": -21,
      "y": 13,
      "z": 2,
      "name": "Rock_Volcanic_Brick"
    },
    {
      "x": -21,
      "y": 14,
      "z": 2,
      "name": "Rock_Volcanic_Brick"
    },
    {
      "x": -21,
      "y": 15,
      "z": 2,
      "name": "Empty"
    },
    {
      "x": -21,
      "y": 16,
      "z": 2,
      "name": "Empty"
    },
    {
      "x": -21,
      "y": 17,
      "z": 2,
      "name": "Empty"
    },
    {
      "x": -21,
      "y": 18,
      "z": 2,
      "name": "Rock_Volcanic_Brick"
    },
    {
      "x": -21,
      "y": 19,
      "z": 2,
      "name": "Rock_Volcanic_Brick"
    },
    {
      "x": -21,
      "y": 20,
      "z": 2,
      "name": "Rock_Volcanic_Brick"
    },
    {
      "x": -21,
      "y": 21,
      "z": 2,
      "name": "Rock_Volcanic_Brick"
    },
    {
      "x": -21,
      "y": 22,
      "z": 2,
      "name": "Rock_Volcanic_Brick"
    },
    {
      "x": -21,
      "y": 23,
      "z": 2,
      "name": "Rock_Volcanic_Brick"
    },
    {
      "x": -21,
      "y": 6,
      "z": 3,
      "name": "Rock_Volcanic_Brick"
    },
    {
      "x": -21,
      "y": 7,
      "z": 3,
      "name": "Rock_Volcanic_Brick"
    },
    {
      "x": -21,
      "y": 8,
      "z": 3,
      "name": "Rock_Volcanic_Brick"
    },
    {
      "x": -21,
      "y": 9,
      "z": 3,
      "name": "Rock_Volcanic_Brick"
    },
    {
      "x": -21,
      "y": 10,
      "z": 3,
      "name": "Rock_Volcanic_Brick"
    },
    {
      "x": -21,
      "y": 11,
      "z": 3,
      "name": "Rock_Volcanic_Brick"
    },
    {
      "x": -21,
      "y": 12,
      "z": 3,
      "name": "Rock_Volcanic_Brick"
    },
    {
      "x": -21,
      "y": 13,
      "z": 3,
      "name": "Rock_Volcanic_Brick"
    },
    {
      "x": -21,
      "y": 14,
      "z": 3,
      "name": "Rock_Volcanic_Brick"
    },
    {
      "x": -21,
      "y": 15,
      "z": 3,
      "name": "Rock_Volcanic_Brick"
    },
    {
      "x": -21,
      "y": 16,
      "z": 3,
      "name": "Rock_Volcanic_Brick"
    },
    {
      "x": -21,
      "y": 17,
      "z": 3,
      "name": "Rock_Volcanic_Brick"
    },
    {
      "x": -21,
      "y": 18,
      "z": 3,
      "name": "Rock_Volcanic_Brick"
    },
    {
      "x": -21,
      "y": 19,
      "z": 3,
      "name": "Rock_Volcanic_Brick"
    },
    {
      "x": -21,
      "y": 20,
      "z": 3,
      "name": "Rock_Volcanic_Brick"
    },
    {
      "x": -21,
      "y": 21,
      "z": 3,
      "name": "Rock_Volcanic_Brick"
    },
    {
      "x": -21,
      "y": 22,
      "z": 3,
      "name": "Rock_Volcanic_Brick"
    },
    {
      "x": -21,
      "y": 23,
      "z": 3,
      "name": "Rock_Volcanic_Brick"
    },
    {
      "x": -21,
      "y": 6,
      "z": 4,
      "name": "Rock_Volcanic_Brick"
    },
    {
      "x": -21,
      "y": 7,
      "z": 4,
      "name": "Rock_Volcanic_Brick"
    },
    {
      "x": -21,
      "y": 8,
      "z": 4,
      "name": "Rock_Volcanic_Brick"
    },
    {
      "x": -21,
      "y": 9,
      "z": 4,
      "name": "Rock_Volcanic_Brick"
    },
    {
      "x": -21,
      "y": 10,
      "z": 4,
      "name": "Rock_Volcanic_Brick"
    },
    {
      "x": -21,
      "y": 11,
      "z": 4,
      "name": "Rock_Volcanic_Brick"
    },
    {
      "x": -21,
      "y": 12,
      "z": 4,
      "name": "Rock_Volcanic_Brick"
    },
    {
      "x": -21,
      "y": 13,
      "z": 4,
      "name": "Rock_Volcanic_Brick"
    },
    {
      "x": -21,
      "y": 14,
      "z": 4,
      "name": "Rock_Volcanic_Brick"
    },
    {
      "x": -21,
      "y": 15,
      "z": 4,
      "name": "Rock_Volcanic_Brick"
    },
    {
      "x": -21,
      "y": 16,
      "z": 4,
      "name": "Rock_Volcanic_Brick"
    },
    {
      "x": -21,
      "y": 17,
      "z": 4,
      "name": "Rock_Volcanic_Brick"
    },
    {
      "x": -21,
      "y": 18,
      "z": 4,
      "name": "Rock_Volcanic_Brick"
    },
    {
      "x": -21,
      "y": 19,
      "z": 4,
      "name": "Rock_Volcanic_Brick"
    },
    {
      "x": -21,
      "y": 20,
      "z": 4,
      "name": "Rock_Volcanic_Brick"
    },
    {
      "x": -21,
      "y": 21,
      "z": 4,
      "name": "Rock_Volcanic_Brick"
    },
    {
      "x": -21,
      "y": 22,
      "z": 4,
      "name": "Rock_Volcanic_Brick"
    },
    {
      "x": -21,
      "y": 23,
      "z": 4,
      "name": "Rock_Volcanic_Brick"
    },
    {
      "x": -21,
      "y": 6,
      "z": 5,
      "name": "Rock_Volcanic_Brick"
    },
    {
      "x": -21,
      "y": 7,
      "z": 5,
      "name": "Rock_Volcanic_Brick"
    },
    {
      "x": -21,
      "y": 8,
      "z": 5,
      "name": "Rock_Volcanic_Brick"
    },
    {
      "x": -21,
      "y": 9,
      "z": 5,
      "name": "Rock_Volcanic_Brick"
    },
    {
      "x": -21,
      "y": 10,
      "z": 5,
      "name": "Rock_Volcanic_Brick"
    },
    {
      "x": -21,
      "y": 11,
      "z": 5,
      "name": "Rock_Volcanic_Brick"
    },
    {
      "x": -21,
      "y": 12,
      "z": 5,
      "name": "Rock_Volcanic_Brick"
    },
    {
      "x": -21,
      "y": 13,
      "z": 5,
      "name": "Rock_Volcanic_Brick"
    },
    {
      "x": -21,
      "y": 14,
      "z": 5,
      "name": "Rock_Volcanic_Brick"
    },
    {
      "x": -21,
      "y": 15,
      "z": 5,
      "name": "Rock_Volcanic_Brick"
    },
    {
      "x": -21,
      "y": 16,
      "z": 5,
      "name": "Rock_Volcanic_Brick"
    },
    {
      "x": -21,
      "y": 17,
      "z": 5,
      "name": "Rock_Volcanic_Brick"
    },
    {
      "x": -21,
      "y": 18,
      "z": 5,
      "name": "Rock_Volcanic_Brick"
    },
    {
      "x": -21,
      "y": 19,
      "z": 5,
      "name": "Rock_Volcanic_Brick"
    },
    {
      "x": -21,
      "y": 20,
      "z": 5,
      "name": "Rock_Volcanic_Brick"
    },
    {
      "x": -21,
      "y": 21,
      "z": 5,
      "name": "Rock_Volcanic_Brick"
    },
    {
      "x": -21,
      "y": 22,
      "z": 5,
      "name": "Rock_Volcanic_Brick"
    },
    {
      "x": -21,
      "y": 23,
      "z": 5,
      "name": "Rock_Volcanic_Brick"
    },
    {
      "x": -21,
      "y": 6,
      "z": 6,
      "name": "Rock_Volcanic_Brick"
    },
    {
      "x": -21,
      "y": 7,
      "z": 6,
      "name": "Rock_Volcanic_Brick"
    },
    {
      "x": -21,
      "y": 8,
      "z": 6,
      "name": "Rock_Volcanic_Brick"
    },
    {
      "x": -21,
      "y": 9,
      "z": 6,
      "name": "Rock_Volcanic_Brick"
    },
    {
      "x": -21,
      "y": 10,
      "z": 6,
      "name": "Rock_Volcanic_Brick"
    },
    {
      "x": -21,
      "y": 11,
      "z": 6,
      "name": "Rock_Volcanic_Brick"
    },
    {
      "x": -21,
      "y": 12,
      "z": 6,
      "name": "Rock_Volcanic_Brick"
    },
    {
      "x": -21,
      "y": 13,
      "z": 6,
      "name": "Rock_Volcanic_Brick"
    },
    {
      "x": -21,
      "y": 14,
      "z": 6,
      "name": "Rock_Volcanic_Brick"
    },
    {
      "x": -21,
      "y": 15,
      "z": 6,
      "name": "Rock_Volcanic_Brick"
    },
    {
      "x": -21,
      "y": 16,
      "z": 6,
      "name": "Rock_Volcanic_Brick"
    },
    {
      "x": -21,
      "y": 17,
      "z": 6,
      "name": "Rock_Volcanic_Brick"
    },
    {
      "x": -21,
      "y": 18,
      "z": 6,
      "name": "Rock_Volcanic_Brick"
    },
    {
      "x": -21,
      "y": 19,
      "z": 6,
      "name": "Rock_Volcanic_Brick"
    },
    {
      "x": -21,
      "y": 20,
      "z": 6,
      "name": "Rock_Volcanic_Brick"
    },
    {
      "x": -21,
      "y": 21,
      "z": 6,
      "name": "Rock_Volcanic_Brick"
    },
    {
      "x": -21,
      "y": 22,
      "z": 6,
      "name": "Rock_Volcanic_Brick"
    },
    {
      "x": -21,
      "y": 23,
      "z": 6,
      "name": "Rock_Volcanic_Brick"
    },
    {
      "x": -21,
      "y": 6,
      "z": 7,
      "name": "Rock_Volcanic_Brick"
    },
    {
      "x": -21,
      "y": 7,
      "z": 7,
      "name": "Rock_Volcanic_Brick"
    },
    {
      "x": -21,
      "y": 8,
      "z": 7,
      "name": "Rock_Volcanic_Brick"
    },
    {
      "x": -21,
      "y": 9,
      "z": 7,
      "name": "Rock_Volcanic_Brick"
    },
    {
      "x": -21,
      "y": 10,
      "z": 7,
      "name": "Rock_Volcanic_Brick"
    },
    {
      "x": -21,
      "y": 11,
      "z": 7,
      "name": "Rock_Volcanic_Brick"
    },
    {
      "x": -21,
      "y": 12,
      "z": 7,
      "name": "Rock_Volcanic_Brick"
    },
    {
      "x": -21,
      "y": 13,
      "z": 7,
      "name": "Rock_Volcanic_Brick"
    },
    {
      "x": -21,
      "y": 14,
      "z": 7,
      "name": "Rock_Volcanic_Brick"
    },
    {
      "x": -21,
      "y": 15,
      "z": 7,
      "name": "Rock_Volcanic_Brick"
    },
    {
      "x": -21,
      "y": 16,
      "z": 7,
      "name": "Rock_Volcanic_Brick"
    },
    {
      "x": -21,
      "y": 17,
      "z": 7,
      "name": "Rock_Volcanic_Brick"
    },
    {
      "x": -21,
      "y": 18,
      "z": 7,
      "name": "Rock_Volcanic_Brick"
    },
    {
      "x": -21,
      "y": 19,
      "z": 7,
      "name": "Rock_Volcanic_Brick"
    },
    {
      "x": -21,
      "y": 20,
      "z": 7,
      "name": "Rock_Volcanic_Brick"
    },
    {
      "x": -21,
      "y": 21,
      "z": 7,
      "name": "Rock_Volcanic_Brick"
    },
    {
      "x": -21,
      "y": 22,
      "z": 7,
      "name": "Rock_Volcanic_Brick"
    },
    {
      "x": -21,
      "y": 23,
      "z": 7,
      "name": "Rock_Volcanic_Brick"
    },
    {
      "x": -20,
      "y": 6,
      "z": -7,
      "name": "Rock_Volcanic_Brick"
    },
    {
      "x": -20,
      "y": 7,
      "z": -7,
      "name": "Rock_Volcanic_Brick"
    },
    {
      "x": -20,
      "y": 8,
      "z": -7,
      "name": "Rock_Volcanic_Brick"
    },
    {
      "x": -20,
      "y": 9,
      "z": -7,
      "name": "Rock_Volcanic_Brick"
    },
    {
      "x": -20,
      "y": 10,
      "z": -7,
      "name": "Rock_Volcanic_Brick"
    },
    {
      "x": -20,
      "y": 11,
      "z": -7,
      "name": "Rock_Volcanic_Brick"
    },
    {
      "x": -20,
      "y": 12,
      "z": -7,
      "name": "Rock_Volcanic_Brick"
    },
    {
      "x": -20,
      "y": 13,
      "z": -7,
      "name": "Rock_Volcanic_Brick"
    },
    {
      "x": -20,
      "y": 14,
      "z": -7,
      "name": "Rock_Volcanic_Brick"
    },
    {
      "x": -20,
      "y": 15,
      "z": -7,
      "name": "Rock_Volcanic_Brick"
    },
    {
      "x": -20,
      "y": 16,
      "z": -7,
      "name": "Rock_Volcanic_Brick"
    },
    {
      "x": -20,
      "y": 17,
      "z": -7,
      "name": "Rock_Volcanic_Brick"
    },
    {
      "x": -20,
      "y": 18,
      "z": -7,
      "name": "Rock_Volcanic_Brick"
    },
    {
      "x": -20,
      "y": 19,
      "z": -7,
      "name": "Rock_Volcanic_Brick"
    },
    {
      "x": -20,
      "y": 20,
      "z": -7,
      "name": "Rock_Volcanic_Brick"
    },
    {
      "x": -20,
      "y": 21,
      "z": -7,
      "name": "Rock_Volcanic_Brick"
    },
    {
      "x": -20,
      "y": 22,
      "z": -7,
      "name": "Rock_Volcanic_Brick"
    },
    {
      "x": -20,
      "y": 23,
      "z": -7,
      "name": "Rock_Volcanic_Brick"
    },
    {
      "x": -20,
      "y": 6,
      "z": -6,
      "name": "Rock_Volcanic_Brick"
    },
    {
      "x": -20,
      "y": 7,
      "z": -6,
      "name": "Rock_Volcanic_Brick"
    },
    {
      "x": -20,
      "y": 8,
      "z": -6,
      "name": "Rock_Volcanic_Brick"
    },
    {
      "x": -20,
      "y": 9,
      "z": -6,
      "name": "Rock_Volcanic_Brick"
    },
    {
      "x": -20,
      "y": 10,
      "z": -6,
      "name": "Rock_Volcanic_Brick"
    },
    {
      "x": -20,
      "y": 11,
      "z": -6,
      "name": "Wood_Blackwood_Planks"
    },
    {
      "x": -20,
      "y": 12,
      "z": -6,
      "name": "Furniture_Ancient_Crate"
    },
    {
      "x": -20,
      "y": 13,
      "z": -6,
      "name": "Furniture_Ancient_Crate"
    },
    {
      "x": -20,
      "y": 14,
      "z": -6,
      "name": "Empty"
    },
    {
      "x": -20,
      "y": 15,
      "z": -6,
      "name": "Empty"
    },
    {
      "x": -20,
      "y": 16,
      "z": -6,
      "name": "Empty"
    },
    {
      "x": -20,
      "y": 17,
      "z": -6,
      "name": "Empty"
    },
    {
      "x": -20,
      "y": 18,
      "z": -6,
      "name": "Empty"
    },
    {
      "x": -20,
      "y": 19,
      "z": -6,
      "name": "Rock_Volcanic_Brick_Half",
      "rotation": 4
    },
    {
      "x": -20,
      "y": 20,
      "z": -6,
      "name": "Rock_Volcanic_Brick"
    },
    {
      "x": -20,
      "y": 21,
      "z": -6,
      "name": "Rock_Volcanic_Brick"
    },
    {
      "x": -20,
      "y": 22,
      "z": -6,
      "name": "Rock_Volcanic_Brick"
    },
    {
      "x": -20,
      "y": 23,
      "z": -6,
      "name": "Rock_Volcanic_Brick"
    },
    {
      "x": -20,
      "y": 6,
      "z": -5,
      "name": "Rock_Volcanic_Brick"
    },
    {
      "x": -20,
      "y": 7,
      "z": -5,
      "name": "Rock_Volcanic_Brick"
    },
    {
      "x": -20,
      "y": 8,
      "z": -5,
      "name": "Rock_Volcanic_Brick"
    },
    {
      "x": -20,
      "y": 9,
      "z": -5,
      "name": "Rock_Volcanic_Brick"
    },
    {
      "x": -20,
      "y": 10,
      "z": -5,
      "name": "Rock_Volcanic_Brick"
    },
    {
      "x": -20,
      "y": 11,
      "z": -5,
      "name": "Wood_Blackwood_Planks"
    },
    {
      "x": -20,
      "y": 12,
      "z": -5,
      "name": "Furniture_Ancient_Crate"
    },
    {
      "x": -20,
      "y": 13,
      "z": -5,
      "name": "Empty"
    },
    {
      "x": -20,
      "y": 14,
      "z": -5,
      "name": "Empty"
    },
    {
      "x": -20,
      "y": 15,
      "z": -5,
      "name": "Empty"
    },
    {
      "x": -20,
      "y": 16,
      "z": -5,
      "name": "Empty"
    },
    {
      "x": -20,
      "y": 17,
      "z": -5,
      "name": "Empty"
    },
    {
      "x": -20,
      "y": 18,
      "z": -5,
      "name": "Empty"
    },
    {
      "x": -20,
      "y": 19,
      "z": -5,
      "name": "Empty"
    },
    {
      "x": -20,
      "y": 20,
      "z": -5,
      "name": "Empty"
    },
    {
      "x": -20,
      "y": 21,
      "z": -5,
      "name": "Rock_Volcanic_Brick"
    },
    {
      "x": -20,
      "y": 22,
      "z": -5,
      "name": "Rock_Volcanic_Brick"
    },
    {
      "x": -20,
      "y": 23,
      "z": -5,
      "name": "Rock_Volcanic_Brick"
    },
    {
      "x": -20,
      "y": 6,
      "z": -4,
      "name": "Rock_Volcanic_Brick"
    },
    {
      "x": -20,
      "y": 7,
      "z": -4,
      "name": "Rock_Volcanic_Brick"
    },
    {
      "x": -20,
      "y": 8,
      "z": -4,
      "name": "Rock_Volcanic_Brick"
    },
    {
      "x": -20,
      "y": 9,
      "z": -4,
      "name": "Rock_Volcanic_Brick"
    },
    {
      "x": -20,
      "y": 10,
      "z": -4,
      "name": "Rock_Volcanic_Brick"
    },
    {
      "x": -20,
      "y": 11,
      "z": -4,
      "name": "Wood_Blackwood_Planks"
    },
    {
      "x": -20,
      "y": 12,
      "z": -4,
      "name": "Empty"
    },
    {
      "x": -20,
      "y": 13,
      "z": -4,
      "name": "Empty"
    },
    {
      "x": -20,
      "y": 14,
      "z": -4,
      "name": "Empty"
    },
    {
      "x": -20,
      "y": 15,
      "z": -4,
      "name": "Empty"
    },
    {
      "x": -20,
      "y": 16,
      "z": -4,
      "name": "Empty"
    },
    {
      "x": -20,
      "y": 17,
      "z": -4,
      "name": "Empty"
    },
    {
      "x": -20,
      "y": 18,
      "z": -4,
      "name": "Empty"
    },
    {
      "x": -20,
      "y": 19,
      "z": -4,
      "name": "Empty"
    },
    {
      "x": -20,
      "y": 20,
      "z": -4,
      "name": "Empty"
    },
    {
      "x": -20,
      "y": 21,
      "z": -4,
      "name": "Rock_Volcanic_Brick"
    },
    {
      "x": -20,
      "y": 22,
      "z": -4,
      "name": "Rock_Volcanic_Brick"
    },
    {
      "x": -20,
      "y": 23,
      "z": -4,
      "name": "Rock_Volcanic_Brick"
    },
    {
      "x": -20,
      "y": 6,
      "z": -3,
      "name": "Rock_Volcanic_Brick"
    },
    {
      "x": -20,
      "y": 7,
      "z": -3,
      "name": "Rock_Volcanic_Brick"
    },
    {
      "x": -20,
      "y": 8,
      "z": -3,
      "name": "Rock_Volcanic_Brick"
    },
    {
      "x": -20,
      "y": 9,
      "z": -3,
      "name": "Rock_Volcanic_Brick"
    },
    {
      "x": -20,
      "y": 10,
      "z": -3,
      "name": "Rock_Volcanic_Brick"
    },
    {
      "x": -20,
      "y": 11,
      "z": -3,
      "name": "Rock_Volcanic_Brick"
    },
    {
      "x": -20,
      "y": 12,
      "z": -3,
      "name": "Rock_Volcanic_Brick"
    },
    {
      "x": -20,
      "y": 13,
      "z": -3,
      "name": "Empty"
    },
    {
      "x": -20,
      "y": 14,
      "z": -3,
      "name": "Wood_Blackwood_Planks_Half",
      "rotation": 6
    },
    {
      "x": -20,
      "y": 15,
      "z": -3,
      "name": "Wood_Blackwood_Planks"
    },
    {
      "x": -20,
      "y": 16,
      "z": -3,
      "name": "Wood_Blackwood_Planks"
    },
    {
      "x": -20,
      "y": 17,
      "z": -3,
      "name": "Wood_Blackwood_Planks"
    },
    {
      "x": -20,
      "y": 18,
      "z": -3,
      "name": "Wood_Blackwood_Planks_Half",
      "rotation": 6
    },
    {
      "x": -20,
      "y": 19,
      "z": -3,
      "name": "Empty"
    },
    {
      "x": -20,
      "y": 20,
      "z": -3,
      "name": "Empty"
    },
    {
      "x": -20,
      "y": 21,
      "z": -3,
      "name": "Rock_Volcanic_Brick_Half",
      "rotation": 8
    },
    {
      "x": -20,
      "y": 22,
      "z": -3,
      "name": "Rock_Volcanic_Brick"
    },
    {
      "x": -20,
      "y": 23,
      "z": -3,
      "name": "Rock_Volcanic_Brick"
    },
    {
      "x": -20,
      "y": 6,
      "z": -2,
      "name": "Rock_Volcanic_Brick"
    },
    {
      "x": -20,
      "y": 7,
      "z": -2,
      "name": "Rock_Volcanic_Brick"
    },
    {
      "x": -20,
      "y": 8,
      "z": -2,
      "name": "Rock_Volcanic_Brick"
    },
    {
      "x": -20,
      "y": 9,
      "z": -2,
      "name": "Empty"
    },
    {
      "x": -20,
      "y": 10,
      "z": -2,
      "name": "Empty"
    },
    {
      "x": -20,
      "y": 11,
      "z": -2,
      "name": "Empty"
    },
    {
      "x": -20,
      "y": 12,
      "z": -2,
      "name": "Rock_Volcanic_Brick"
    },
    {
      "x": -20,
      "y": 13,
      "z": -2,
      "name": "Rock_Volcanic_Brick"
    },
    {
      "x": -20,
      "y": 14,
      "z": -2,
      "name": "Wood_Blackwood_Planks"
    },
    {
      "x": -20,
      "y": 15,
      "z": -2,
      "name": "Wood_Blackwood_Planks_Half",
      "rotation": 4
    },
    {
      "x": -20,
      "y": 16,
      "z": -2,
      "name": "Empty"
    },
    {
      "x": -20,
      "y": 17,
      "z": -2,
      "name": "Wood_Blackwood_Planks_Half",
      "rotation": 4
    },
    {
      "x": -20,
      "y": 18,
      "z": -2,
      "name": "Wood_Blackwood_Planks"
    },
    {
      "x": -20,
      "y": 19,
      "z": -2,
      "name": "Wood_Blackwood_Planks_Half"
    },
    {
      "x": -20,
      "y": 20,
      "z": -2,
      "name": "Plant_Vine_Wall_Poisoned",
      "rotation": 1
    },
    {
      "x": -20,
      "y": 21,
      "z": -2,
      "name": "Plant_Vine_Wall_Poisoned",
      "rotation": 1
    },
    {
      "x": -20,
      "y": 22,
      "z": -2,
      "name": "Soil_Clay_Black"
    },
    {
      "x": -20,
      "y": 23,
      "z": -2,
      "name": "Soil_Clay_Black"
    },
    {
      "x": -20,
      "y": 6,
      "z": -1,
      "name": "Soil_Dirt_Poisoned"
    },
    {
      "x": -20,
      "y": 7,
      "z": -1,
      "name": "Soil_Dirt_Poisoned"
    },
    {
      "x": -20,
      "y": 8,
      "z": -1,
      "name": "Empty"
    },
    {
      "x": -20,
      "y": 9,
      "z": -1,
      "name": "Empty"
    },
    {
      "x": -20,
      "y": 10,
      "z": -1,
      "name": "Empty"
    },
    {
      "x": -20,
      "y": 11,
      "z": -1,
      "name": "Empty"
    },
    {
      "x": -20,
      "y": 12,
      "z": -1,
      "name": "Empty"
    },
    {
      "x": -20,
      "y": 13,
      "z": -1,
      "name": "Rock_Volcanic_Brick"
    },
    {
      "x": -20,
      "y": 14,
      "z": -1,
      "name": "Wood_Blackwood_Planks_Half"
    },
    {
      "x": -20,
      "y": 15,
      "z": -1,
      "name": "Empty"
    },
    {
      "x": -20,
      "y": 16,
      "z": -1,
      "name": "Empty"
    },
    {
      "x": -20,
      "y": 17,
      "z": -1,
      "name": "Empty"
    },
    {
      "x": -20,
      "y": 18,
      "z": -1,
      "name": "Wood_Blackwood_Planks_Half",
      "rotation": 8
    },
    {
      "x": -20,
      "y": 19,
      "z": -1,
      "name": "Wood_Blackwood_Planks"
    },
    {
      "x": -20,
      "y": 20,
      "z": -1,
      "name": "Plant_Vine_Wall_Poisoned",
      "rotation": 1
    },
    {
      "x": -20,
      "y": 21,
      "z": -1,
      "name": "Plant_Vine_Wall_Poisoned",
      "rotation": 1
    },
    {
      "x": -20,
      "y": 22,
      "z": -1,
      "name": "Soil_Clay_Black"
    },
    {
      "x": -20,
      "y": 23,
      "z": -1,
      "name": "Soil_Clay_Black"
    },
    {
      "x": -20,
      "y": 6,
      "z": 0,
      "name": "Soil_Dirt_Poisoned"
    },
    {
      "x": -20,
      "y": 7,
      "z": 0,
      "name": "Soil_Dirt_Poisoned"
    },
    {
      "x": -20,
      "y": 8,
      "z": 0,
      "name": "Empty"
    },
    {
      "x": -20,
      "y": 9,
      "z": 0,
      "name": "Empty"
    },
    {
      "x": -20,
      "y": 10,
      "z": 0,
      "name": "Empty"
    },
    {
      "x": -20,
      "y": 11,
      "z": 0,
      "name": "Empty"
    },
    {
      "x": -20,
      "y": 12,
      "z": 0,
      "name": "Empty"
    },
    {
      "x": -20,
      "y": 13,
      "z": 0,
      "name": "Rock_Volcanic_Brick"
    },
    {
      "x": -20,
      "y": 14,
      "z": 0,
      "name": "Empty"
    },
    {
      "x": -20,
      "y": 15,
      "z": 0,
      "name": "Empty"
    },
    {
      "x": -20,
      "y": 16,
      "z": 0,
      "name": "Empty"
    },
    {
      "x": -20,
      "y": 17,
      "z": 0,
      "name": "Empty"
    },
    {
      "x": -20,
      "y": 18,
      "z": 0,
      "name": "Empty"
    },
    {
      "x": -20,
      "y": 19,
      "z": 0,
      "name": "Wood_Blackwood_Planks"
    },
    {
      "x": -20,
      "y": 20,
      "z": 0,
      "name": "Empty"
    },
    {
      "x": -20,
      "y": 21,
      "z": 0,
      "name": "Empty"
    },
    {
      "x": -20,
      "y": 22,
      "z": 0,
      "name": "Wood_Burnt_Roots"
    },
    {
      "x": -20,
      "y": 23,
      "z": 0,
      "name": "Soil_Clay_Black"
    },
    {
      "x": -20,
      "y": 6,
      "z": 1,
      "name": "Soil_Dirt_Poisoned"
    },
    {
      "x": -20,
      "y": 7,
      "z": 1,
      "name": "Soil_Dirt_Poisoned"
    },
    {
      "x": -20,
      "y": 8,
      "z": 1,
      "name": "Empty"
    },
    {
      "x": -20,
      "y": 9,
      "z": 1,
      "name": "Empty"
    },
    {
      "x": -20,
      "y": 10,
      "z": 1,
      "name": "Empty"
    },
    {
      "x": -20,
      "y": 11,
      "z": 1,
      "name": "Empty"
    },
    {
      "x": -20,
      "y": 12,
      "z": 1,
      "name": "Empty"
    },
    {
      "x": -20,
      "y": 13,
      "z": 1,
      "name": "Rock_Volcanic_Brick"
    },
    {
      "x": -20,
      "y": 14,
      "z": 1,
      "name": "Wood_Blackwood_Planks_Half"
    },
    {
      "x": -20,
      "y": 15,
      "z": 1,
      "name": "Empty"
    },
    {
      "x": -20,
      "y": 16,
      "z": 1,
      "name": "Empty"
    },
    {
      "x": -20,
      "y": 17,
      "z": 1,
      "name": "Empty"
    },
    {
      "x": -20,
      "y": 18,
      "z": 1,
      "name": "Wood_Blackwood_Planks_Half",
      "rotation": 8
    },
    {
      "x": -20,
      "y": 19,
      "z": 1,
      "name": "Wood_Blackwood_Planks"
    },
    {
      "x": -20,
      "y": 20,
      "z": 1,
      "name": "Empty"
    },
    {
      "x": -20,
      "y": 21,
      "z": 1,
      "name": "Empty"
    },
    {
      "x": -20,
      "y": 22,
      "z": 1,
      "name": "Plant_Vine_Wall_Poisoned",
      "rotation": 1
    },
    {
      "x": -20,
      "y": 23,
      "z": 1,
      "name": "Soil_Clay_Black"
    },
    {
      "x": -20,
      "y": 6,
      "z": 2,
      "name": "Rock_Volcanic_Brick"
    },
    {
      "x": -20,
      "y": 7,
      "z": 2,
      "name": "Rock_Volcanic_Brick"
    },
    {
      "x": -20,
      "y": 8,
      "z": 2,
      "name": "Rock_Volcanic_Brick"
    },
    {
      "x": -20,
      "y": 9,
      "z": 2,
      "name": "Empty"
    },
    {
      "x": -20,
      "y": 10,
      "z": 2,
      "name": "Empty"
    },
    {
      "x": -20,
      "y": 11,
      "z": 2,
      "name": "Empty"
    },
    {
      "x": -20,
      "y": 12,
      "z": 2,
      "name": "Rock_Volcanic_Brick"
    },
    {
      "x": -20,
      "y": 13,
      "z": 2,
      "name": "Rock_Volcanic_Brick"
    },
    {
      "x": -20,
      "y": 14,
      "z": 2,
      "name": "Wood_Blackwood_Planks"
    },
    {
      "x": -20,
      "y": 15,
      "z": 2,
      "name": "Wood_Blackwood_Planks_Half",
      "rotation": 6
    },
    {
      "x": -20,
      "y": 16,
      "z": 2,
      "name": "Empty"
    },
    {
      "x": -20,
      "y": 17,
      "z": 2,
      "name": "Wood_Blackwood_Planks_Half",
      "rotation": 6
    },
    {
      "x": -20,
      "y": 18,
      "z": 2,
      "name": "Wood_Blackwood_Planks"
    },
    {
      "x": -20,
      "y": 19,
      "z": 2,
      "name": "Wood_Blackwood_Planks_Half"
    },
    {
      "x": -20,
      "y": 20,
      "z": 2,
      "name": "Empty"
    },
    {
      "x": -20,
      "y": 21,
      "z": 2,
      "name": "Empty"
    },
    {
      "x": -20,
      "y": 22,
      "z": 2,
      "name": "Empty"
    },
    {
      "x": -20,
      "y": 23,
      "z": 2,
      "name": "Rock_Volcanic_Brick"
    },
    {
      "x": -20,
      "y": 6,
      "z": 3,
      "name": "Rock_Volcanic_Brick"
    },
    {
      "x": -20,
      "y": 7,
      "z": 3,
      "name": "Rock_Volcanic_Brick"
    },
    {
      "x": -20,
      "y": 8,
      "z": 3,
      "name": "Rock_Volcanic_Brick"
    },
    {
      "x": -20,
      "y": 9,
      "z": 3,
      "name": "Rock_Volcanic_Brick"
    },
    {
      "x": -20,
      "y": 10,
      "z": 3,
      "name": "Rock_Volcanic_Brick"
    },
    {
      "x": -20,
      "y": 11,
      "z": 3,
      "name": "Rock_Volcanic_Brick"
    },
    {
      "x": -20,
      "y": 12,
      "z": 3,
      "name": "Rock_Volcanic_Brick"
    },
    {
      "x": -20,
      "y": 13,
      "z": 3,
      "name": "Empty"
    },
    {
      "x": -20,
      "y": 14,
      "z": 3,
      "name": "Wood_Blackwood_Planks_Half",
      "rotation": 4
    },
    {
      "x": -20,
      "y": 15,
      "z": 3,
      "name": "Wood_Blackwood_Planks"
    },
    {
      "x": -20,
      "y": 16,
      "z": 3,
      "name": "Wood_Blackwood_Planks"
    },
    {
      "x": -20,
      "y": 17,
      "z": 3,
      "name": "Wood_Blackwood_Planks"
    },
    {
      "x": -20,
      "y": 18,
      "z": 3,
      "name": "Wood_Blackwood_Planks_Half",
      "rotation": 4
    },
    {
      "x": -20,
      "y": 19,
      "z": 3,
      "name": "Empty"
    },
    {
      "x": -20,
      "y": 20,
      "z": 3,
      "name": "Empty"
    },
    {
      "x": -20,
      "y": 21,
      "z": 3,
      "name": "Empty"
    },
    {
      "x": -20,
      "y": 22,
      "z": 3,
      "name": "Rock_Volcanic_Brick_Half",
      "rotation": 8
    },
    {
      "x": -20,
      "y": 23,
      "z": 3,
      "name": "Rock_Volcanic_Brick"
    },
    {
      "x": -20,
      "y": 6,
      "z": 4,
      "name": "Rock_Volcanic_Brick"
    },
    {
      "x": -20,
      "y": 7,
      "z": 4,
      "name": "Rock_Volcanic_Brick"
    },
    {
      "x": -20,
      "y": 8,
      "z": 4,
      "name": "Rock_Volcanic_Brick"
    },
    {
      "x": -20,
      "y": 9,
      "z": 4,
      "name": "Rock_Volcanic_Brick"
    },
    {
      "x": -20,
      "y": 10,
      "z": 4,
      "name": "Rock_Volcanic_Brick"
    },
    {
      "x": -20,
      "y": 11,
      "z": 4,
      "name": "Wood_Blackwood_Planks"
    },
    {
      "x": -20,
      "y": 12,
      "z": 4,
      "name": "Empty"
    },
    {
      "x": -20,
      "y": 13,
      "z": 4,
      "name": "Empty"
    },
    {
      "x": -20,
      "y": 14,
      "z": 4,
      "name": "Empty"
    },
    {
      "x": -20,
      "y": 15,
      "z": 4,
      "name": "Empty"
    },
    {
      "x": -20,
      "y": 16,
      "z": 4,
      "name": "Empty"
    },
    {
      "x": -20,
      "y": 17,
      "z": 4,
      "name": "Empty"
    },
    {
      "x": -20,
      "y": 18,
      "z": 4,
      "name": "Empty"
    },
    {
      "x": -20,
      "y": 19,
      "z": 4,
      "name": "Empty"
    },
    {
      "x": -20,
      "y": 20,
      "z": 4,
      "name": "Empty"
    },
    {
      "x": -20,
      "y": 21,
      "z": 4,
      "name": "Empty"
    },
    {
      "x": -20,
      "y": 22,
      "z": 4,
      "name": "Rock_Volcanic_Brick"
    },
    {
      "x": -20,
      "y": 23,
      "z": 4,
      "name": "Rock_Volcanic_Brick"
    },
    {
      "x": -20,
      "y": 6,
      "z": 5,
      "name": "Rock_Volcanic_Brick"
    },
    {
      "x": -20,
      "y": 7,
      "z": 5,
      "name": "Rock_Volcanic_Brick"
    },
    {
      "x": -20,
      "y": 8,
      "z": 5,
      "name": "Rock_Volcanic_Brick"
    },
    {
      "x": -20,
      "y": 9,
      "z": 5,
      "name": "Rock_Volcanic_Brick"
    },
    {
      "x": -20,
      "y": 10,
      "z": 5,
      "name": "Rock_Volcanic_Brick"
    },
    {
      "x": -20,
      "y": 11,
      "z": 5,
      "name": "Soil_Clay_Black"
    },
    {
      "x": -20,
      "y": 12,
      "z": 5,
      "name": "Empty"
    },
    {
      "x": -20,
      "y": 13,
      "z": 5,
      "name": "Empty"
    },
    {
      "x": -20,
      "y": 14,
      "z": 5,
      "name": "Empty"
    },
    {
      "x": -20,
      "y": 15,
      "z": 5,
      "name": "Empty"
    },
    {
      "x": -20,
      "y": 16,
      "z": 5,
      "name": "Empty"
    },
    {
      "x": -20,
      "y": 17,
      "z": 5,
      "name": "Empty"
    },
    {
      "x": -20,
      "y": 18,
      "z": 5,
      "name": "Empty"
    },
    {
      "x": -20,
      "y": 19,
      "z": 5,
      "name": "Empty"
    },
    {
      "x": -20,
      "y": 20,
      "z": 5,
      "name": "Empty"
    },
    {
      "x": -20,
      "y": 21,
      "z": 5,
      "name": "Empty"
    },
    {
      "x": -20,
      "y": 22,
      "z": 5,
      "name": "Rock_Volcanic_Brick"
    },
    {
      "x": -20,
      "y": 23,
      "z": 5,
      "name": "Rock_Volcanic_Brick"
    },
    {
      "x": -20,
      "y": 6,
      "z": 6,
      "name": "Rock_Volcanic_Brick"
    },
    {
      "x": -20,
      "y": 7,
      "z": 6,
      "name": "Rock_Volcanic_Brick"
    },
    {
      "x": -20,
      "y": 8,
      "z": 6,
      "name": "Rock_Volcanic_Brick"
    },
    {
      "x": -20,
      "y": 9,
      "z": 6,
      "name": "Rock_Volcanic_Brick"
    },
    {
      "x": -20,
      "y": 10,
      "z": 6,
      "name": "Rock_Volcanic_Brick"
    },
    {
      "x": -20,
      "y": 11,
      "z": 6,
      "name": "Wood_Blackwood_Planks"
    },
    {
      "x": -20,
      "y": 12,
      "z": 6,
      "name": "Wood_Burnt_Trunk"
    },
    {
      "x": -20,
      "y": 13,
      "z": 6,
      "name": "Wood_Burnt_Trunk"
    },
    {
      "x": -20,
      "y": 14,
      "z": 6,
      "name": "Wood_Burnt_Trunk"
    },
    {
      "x": -20,
      "y": 15,
      "z": 6,
      "name": "Wood_Burnt_Trunk"
    },
    {
      "x": -20,
      "y": 16,
      "z": 6,
      "name": "Wood_Burnt_Trunk"
    },
    {
      "x": -20,
      "y": 17,
      "z": 6,
      "name": "Wood_Burnt_Trunk"
    },
    {
      "x": -20,
      "y": 18,
      "z": 6,
      "name": "Wood_Burnt_Trunk"
    },
    {
      "x": -20,
      "y": 19,
      "z": 6,
      "name": "Wood_Burnt_Trunk"
    },
    {
      "x": -20,
      "y": 20,
      "z": 6,
      "name": "Wood_Burnt_Trunk"
    },
    {
      "x": -20,
      "y": 21,
      "z": 6,
      "name": "Wood_Burnt_Trunk"
    },
    {
      "x": -20,
      "y": 22,
      "z": 6,
      "name": "Rock_Volcanic_Brick"
    },
    {
      "x": -20,
      "y": 23,
      "z": 6,
      "name": "Rock_Volcanic_Brick"
    },
    {
      "x": -20,
      "y": 6,
      "z": 7,
      "name": "Rock_Volcanic_Brick"
    },
    {
      "x": -20,
      "y": 7,
      "z": 7,
      "name": "Rock_Volcanic_Brick"
    },
    {
      "x": -20,
      "y": 8,
      "z": 7,
      "name": "Rock_Volcanic_Brick"
    },
    {
      "x": -20,
      "y": 9,
      "z": 7,
      "name": "Rock_Volcanic_Brick"
    },
    {
      "x": -20,
      "y": 10,
      "z": 7,
      "name": "Rock_Volcanic_Brick"
    },
    {
      "x": -20,
      "y": 11,
      "z": 7,
      "name": "Rock_Volcanic_Brick"
    },
    {
      "x": -20,
      "y": 12,
      "z": 7,
      "name": "Rock_Volcanic_Brick"
    },
    {
      "x": -20,
      "y": 13,
      "z": 7,
      "name": "Rock_Volcanic_Brick"
    },
    {
      "x": -20,
      "y": 14,
      "z": 7,
      "name": "Rock_Volcanic_Brick"
    },
    {
      "x": -20,
      "y": 15,
      "z": 7,
      "name": "Rock_Volcanic_Brick"
    },
    {
      "x": -20,
      "y": 16,
      "z": 7,
      "name": "Rock_Volcanic_Brick"
    },
    {
      "x": -20,
      "y": 17,
      "z": 7,
      "name": "Rock_Volcanic_Brick"
    },
    {
      "x": -20,
      "y": 18,
      "z": 7,
      "name": "Rock_Volcanic_Brick"
    },
    {
      "x": -20,
      "y": 19,
      "z": 7,
      "name": "Rock_Volcanic_Brick"
    },
    {
      "x": -20,
      "y": 20,
      "z": 7,
      "name": "Rock_Volcanic_Brick"
    },
    {
      "x": -20,
      "y": 21,
      "z": 7,
      "name": "Rock_Volcanic_Brick"
    },
    {
      "x": -20,
      "y": 22,
      "z": 7,
      "name": "Rock_Volcanic_Brick"
    },
    {
      "x": -20,
      "y": 23,
      "z": 7,
      "name": "Rock_Volcanic_Brick"
    },
    {
      "x": -19,
      "y": 6,
      "z": -7,
      "name": "Rock_Volcanic_Brick"
    },
    {
      "x": -19,
      "y": 7,
      "z": -7,
      "name": "Rock_Volcanic_Brick"
    },
    {
      "x": -19,
      "y": 8,
      "z": -7,
      "name": "Rock_Volcanic_Brick"
    },
    {
      "x": -19,
      "y": 9,
      "z": -7,
      "name": "Rock_Volcanic_Brick"
    },
    {
      "x": -19,
      "y": 10,
      "z": -7,
      "name": "Rock_Volcanic_Brick"
    },
    {
      "x": -19,
      "y": 11,
      "z": -7,
      "name": "Rock_Volcanic_Brick"
    },
    {
      "x": -19,
      "y": 12,
      "z": -7,
      "name": "Rock_Volcanic_Brick"
    },
    {
      "x": -19,
      "y": 13,
      "z": -7,
      "name": "Rock_Volcanic_Brick"
    },
    {
      "x": -19,
      "y": 14,
      "z": -7,
      "name": "Rock_Volcanic_Brick"
    },
    {
      "x": -19,
      "y": 15,
      "z": -7,
      "name": "Rock_Volcanic_Brick"
    },
    {
      "x": -19,
      "y": 16,
      "z": -7,
      "name": "Rock_Volcanic_Brick"
    },
    {
      "x": -19,
      "y": 17,
      "z": -7,
      "name": "Rock_Volcanic_Brick"
    },
    {
      "x": -19,
      "y": 18,
      "z": -7,
      "name": "Rock_Volcanic_Brick_Stairs"
    },
    {
      "x": -19,
      "y": 19,
      "z": -7,
      "name": "Empty"
    },
    {
      "x": -19,
      "y": 20,
      "z": -7,
      "name": "Rock_Volcanic_Brick"
    },
    {
      "x": -19,
      "y": 21,
      "z": -7,
      "name": "Rock_Volcanic_Brick"
    },
    {
      "x": -19,
      "y": 22,
      "z": -7,
      "name": "Rock_Volcanic_Brick"
    },
    {
      "x": -19,
      "y": 23,
      "z": -7,
      "name": "Rock_Volcanic_Brick"
    },
    {
      "x": -19,
      "y": 6,
      "z": -6,
      "name": "Rock_Volcanic_Brick"
    },
    {
      "x": -19,
      "y": 7,
      "z": -6,
      "name": "Rock_Volcanic_Brick"
    },
    {
      "x": -19,
      "y": 8,
      "z": -6,
      "name": "Rock_Volcanic_Brick"
    },
    {
      "x": -19,
      "y": 9,
      "z": -6,
      "name": "Rock_Volcanic_Brick"
    },
    {
      "x": -19,
      "y": 10,
      "z": -6,
      "name": "Rock_Volcanic_Brick"
    },
    {
      "x": -19,
      "y": 11,
      "z": -6,
      "name": "Wood_Blackwood_Planks"
    },
    {
      "x": -19,
      "y": 12,
      "z": -6,
      "name": "Furniture_Ancient_Crate",
      "rotation": 1
    },
    {
      "x": -19,
      "y": 13,
      "z": -6,
      "name": "Furniture_Ancient_Crate",
      "rotation": 1
    },
    {
      "x": -19,
      "y": 14,
      "z": -6,
      "name": "Empty"
    },
    {
      "x": -19,
      "y": 15,
      "z": -6,
      "name": "Empty"
    },
    {
      "x": -19,
      "y": 16,
      "z": -6,
      "name": "Empty"
    },
    {
      "x": -19,
      "y": 17,
      "z": -6,
      "name": "Empty"
    },
    {
      "x": -19,
      "y": 18,
      "z": -6,
      "name": "Empty"
    },
    {
      "x": -19,
      "y": 19,
      "z": -6,
      "name": "Empty"
    },
    {
      "x": -19,
      "y": 20,
      "z": -6,
      "name": "Rock_Volcanic_Brick"
    },
    {
      "x": -19,
      "y": 21,
      "z": -6,
      "name": "Rock_Volcanic_Brick"
    },
    {
      "x": -19,
      "y": 22,
      "z": -6,
      "name": "Rock_Volcanic_Brick"
    },
    {
      "x": -19,
      "y": 23,
      "z": -6,
      "name": "Rock_Volcanic_Brick"
    },
    {
      "x": -19,
      "y": 6,
      "z": -5,
      "name": "Rock_Volcanic_Brick"
    },
    {
      "x": -19,
      "y": 7,
      "z": -5,
      "name": "Rock_Volcanic_Brick"
    },
    {
      "x": -19,
      "y": 8,
      "z": -5,
      "name": "Rock_Volcanic_Brick"
    },
    {
      "x": -19,
      "y": 9,
      "z": -5,
      "name": "Rock_Volcanic_Brick"
    },
    {
      "x": -19,
      "y": 10,
      "z": -5,
      "name": "Rock_Volcanic_Brick"
    },
    {
      "x": -19,
      "y": 11,
      "z": -5,
      "name": "Wood_Blackwood_Planks"
    },
    {
      "x": -19,
      "y": 12,
      "z": -5,
      "name": "Furniture_Ancient_Barrel"
    },
    {
      "x": -19,
      "y": 13,
      "z": -5,
      "name": "Empty"
    },
    {
      "x": -19,
      "y": 14,
      "z": -5,
      "name": "Empty"
    },
    {
      "x": -19,
      "y": 15,
      "z": -5,
      "name": "Empty"
    },
    {
      "x": -19,
      "y": 16,
      "z": -5,
      "name": "Empty"
    },
    {
      "x": -19,
      "y": 17,
      "z": -5,
      "name": "Empty"
    },
    {
      "x": -19,
      "y": 18,
      "z": -5,
      "name": "Empty"
    },
    {
      "x": -19,
      "y": 19,
      "z": -5,
      "name": "Empty"
    },
    {
      "x": -19,
      "y": 20,
      "z": -5,
      "name": "Empty"
    },
    {
      "x": -19,
      "y": 21,
      "z": -5,
      "name": "Rock_Volcanic_Brick"
    },
    {
      "x": -19,
      "y": 22,
      "z": -5,
      "name": "Rock_Volcanic_Brick"
    },
    {
      "x": -19,
      "y": 23,
      "z": -5,
      "name": "Rock_Volcanic_Brick"
    },
    {
      "x": -19,
      "y": 6,
      "z": -4,
      "name": "Rock_Volcanic_Brick"
    },
    {
      "x": -19,
      "y": 7,
      "z": -4,
      "name": "Wood_Blackwood_Planks"
    },
    {
      "x": -19,
      "y": 8,
      "z": -4,
      "name": "Wood_Blackwood_Planks"
    },
    {
      "x": -19,
      "y": 9,
      "z": -4,
      "name": "Wood_Blackwood_Planks"
    },
    {
      "x": -19,
      "y": 10,
      "z": -4,
      "name": "Wood_Blackwood_Planks"
    },
    {
      "x": -19,
      "y": 11,
      "z": -4,
      "name": "Wood_Blackwood_Planks"
    },
    {
      "x": -19,
      "y": 12,
      "z": -4,
      "name": "Empty"
    },
    {
      "x": -19,
      "y": 13,
      "z": -4,
      "name": "Empty"
    },
    {
      "x": -19,
      "y": 14,
      "z": -4,
      "name": "Empty"
    },
    {
      "x": -19,
      "y": 15,
      "z": -4,
      "name": "Empty"
    },
    {
      "x": -19,
      "y": 16,
      "z": -4,
      "name": "Empty"
    },
    {
      "x": -19,
      "y": 17,
      "z": -4,
      "name": "Empty"
    },
    {
      "x": -19,
      "y": 18,
      "z": -4,
      "name": "Empty"
    },
    {
      "x": -19,
      "y": 19,
      "z": -4,
      "name": "Empty"
    },
    {
      "x": -19,
      "y": 20,
      "z": -4,
      "name": "Empty"
    },
    {
      "x": -19,
      "y": 21,
      "z": -4,
      "name": "Rock_Volcanic_Brick"
    },
    {
      "x": -19,
      "y": 22,
      "z": -4,
      "name": "Rock_Volcanic_Brick"
    },
    {
      "x": -19,
      "y": 23,
      "z": -4,
      "name": "Rock_Volcanic_Brick"
    },
    {
      "x": -19,
      "y": 6,
      "z": -3,
      "name": "Soil_Dirt_Poisoned"
    },
    {
      "x": -19,
      "y": 7,
      "z": -3,
      "name": "Plant_Seaweed_Winter_Aurora"
    },
    {
      "x": -19,
      "y": 8,
      "z": -3,
      "name": "Plant_Seaweed_Winter_Aurora",
      "filler": 1024
    },
    {
      "x": -19,
      "y": 9,
      "z": -3,
      "name": "Empty"
    },
    {
      "x": -19,
      "y": 10,
      "z": -3,
      "name": "Empty"
    },
    {
      "x": -19,
      "y": 11,
      "z": -3,
      "name": "Empty"
    },
    {
      "x": -19,
      "y": 12,
      "z": -3,
      "name": "Empty"
    },
    {
      "x": -19,
      "y": 13,
      "z": -3,
      "name": "Empty"
    },
    {
      "x": -19,
      "y": 14,
      "z": -3,
      "name": "Empty"
    },
    {
      "x": -19,
      "y": 15,
      "z": -3,
      "name": "Empty"
    },
    {
      "x": -19,
      "y": 16,
      "z": -3,
      "name": "Empty"
    },
    {
      "x": -19,
      "y": 17,
      "z": -3,
      "name": "Empty"
    },
    {
      "x": -19,
      "y": 18,
      "z": -3,
      "name": "Empty"
    },
    {
      "x": -19,
      "y": 19,
      "z": -3,
      "name": "Empty"
    },
    {
      "x": -19,
      "y": 20,
      "z": -3,
      "name": "Empty"
    },
    {
      "x": -19,
      "y": 21,
      "z": -3,
      "name": "Empty"
    },
    {
      "x": -19,
      "y": 22,
      "z": -3,
      "name": "Soil_Clay_Black"
    },
    {
      "x": -19,
      "y": 23,
      "z": -3,
      "name": "Soil_Clay_Black"
    },
    {
      "x": -19,
      "y": 6,
      "z": -2,
      "name": "Soil_Dirt_Poisoned"
    },
    {
      "x": -19,
      "y": 7,
      "z": -2,
      "name": "Plant_Seaweed_Dead_Eerie"
    },
    {
      "x": -19,
      "y": 8,
      "z": -2,
      "name": "Plant_Seaweed_Dead_Eerie",
      "filler": 1024
    },
    {
      "x": -19,
      "y": 9,
      "z": -2,
      "name": "Empty"
    },
    {
      "x": -19,
      "y": 10,
      "z": -2,
      "name": "Empty"
    },
    {
      "x": -19,
      "y": 11,
      "z": -2,
      "name": "Empty"
    },
    {
      "x": -19,
      "y": 12,
      "z": -2,
      "name": "Empty"
    },
    {
      "x": -19,
      "y": 13,
      "z": -2,
      "name": "Empty"
    },
    {
      "x": -19,
      "y": 14,
      "z": -2,
      "name": "Empty"
    },
    {
      "x": -19,
      "y": 15,
      "z": -2,
      "name": "Empty"
    },
    {
      "x": -19,
      "y": 16,
      "z": -2,
      "name": "Empty"
    },
    {
      "x": -19,
      "y": 17,
      "z": -2,
      "name": "Empty"
    },
    {
      "x": -19,
      "y": 18,
      "z": -2,
      "name": "Empty"
    },
    {
      "x": -19,
      "y": 19,
      "z": -2,
      "name": "Empty"
    },
    {
      "x": -19,
      "y": 20,
      "z": -2,
      "name": "Empty"
    },
    {
      "x": -19,
      "y": 21,
      "z": -2,
      "name": "Empty"
    },
    {
      "x": -19,
      "y": 22,
      "z": -2,
      "name": "Soil_Clay_Black"
    },
    {
      "x": -19,
      "y": 23,
      "z": -2,
      "name": "Soil_Clay_Black"
    },
    {
      "x": -19,
      "y": 6,
      "z": -1,
      "name": "Soil_Dirt_Poisoned"
    },
    {
      "x": -19,
      "y": 7,
      "z": -1,
      "name": "Soil_Dirt_Poisoned"
    },
    {
      "x": -19,
      "y": 8,
      "z": -1,
      "name": "Plant_Seaweed_Dead_Stack"
    },
    {
      "x": -19,
      "y": 9,
      "z": -1,
      "name": "Plant_Seaweed_Dead_Stack"
    },
    {
      "x": -19,
      "y": 10,
      "z": -1,
      "name": "Plant_Seaweed_Dead_Stack"
    },
    {
      "x": -19,
      "y": 11,
      "z": -1,
      "name": "Plant_Seaweed_Dead_Stack"
    },
    {
      "x": -19,
      "y": 12,
      "z": -1,
      "name": "Empty"
    },
    {
      "x": -19,
      "y": 13,
      "z": -1,
      "name": "Empty"
    },
    {
      "x": -19,
      "y": 14,
      "z": -1,
      "name": "Empty"
    },
    {
      "x": -19,
      "y": 15,
      "z": -1,
      "name": "Empty"
    },
    {
      "x": -19,
      "y": 16,
      "z": -1,
      "name": "Empty"
    },
    {
      "x": -19,
      "y": 17,
      "z": -1,
      "name": "Empty"
    },
    {
      "x": -19,
      "y": 18,
      "z": -1,
      "name": "Plant_Vine_Wall_Poisoned",
      "rotation": 1
    },
    {
      "x": -19,
      "y": 19,
      "z": -1,
      "name": "Plant_Vine_Wall_Poisoned",
      "rotation": 1
    },
    {
      "x": -19,
      "y": 20,
      "z": -1,
      "name": "Empty"
    },
    {
      "x": -19,
      "y": 21,
      "z": -1,
      "name": "Empty"
    },
    {
      "x": -19,
      "y": 22,
      "z": -1,
      "name": "Soil_Clay_Black"
    },
    {
      "x": -19,
      "y": 23,
      "z": -1,
      "name": "Soil_Clay_Black"
    },
    {
      "x": -19,
      "y": 6,
      "z": 0,
      "name": "Soil_Dirt_Poisoned"
    },
    {
      "x": -19,
      "y": 7,
      "z": 0,
      "name": "Soil_Dirt_Poisoned"
    },
    {
      "x": -19,
      "y": 8,
      "z": 0,
      "name": "Empty"
    },
    {
      "x": -19,
      "y": 9,
      "z": 0,
      "name": "Empty"
    },
    {
      "x": -19,
      "y": 10,
      "z": 0,
      "name": "Empty"
    },
    {
      "x": -19,
      "y": 11,
      "z": 0,
      "name": "Empty"
    },
    {
      "x": -19,
      "y": 12,
      "z": 0,
      "name": "Empty"
    },
    {
      "x": -19,
      "y": 13,
      "z": 0,
      "name": "Empty"
    },
    {
      "x": -19,
      "y": 14,
      "z": 0,
      "name": "Empty"
    },
    {
      "x": -19,
      "y": 15,
      "z": 0,
      "name": "Empty"
    },
    {
      "x": -19,
      "y": 16,
      "z": 0,
      "name": "Empty"
    },
    {
      "x": -19,
      "y": 17,
      "z": 0,
      "name": "Rock_Crystal_Purple_Small",
      "rotation": 8
    },
    {
      "x": -19,
      "y": 18,
      "z": 0,
      "name": "Deco_Iron_Chain_Small"
    },
    {
      "x": -19,
      "y": 19,
      "z": 0,
      "name": "Deco_Iron_Chain_Small"
    },
    {
      "x": -19,
      "y": 20,
      "z": 0,
      "name": "Deco_Iron_Chain_Small"
    },
    {
      "x": -19,
      "y": 21,
      "z": 0,
      "name": "Deco_Iron_Chain_Small"
    },
    {
      "x": -19,
      "y": 22,
      "z": 0,
      "name": "Wood_Blackwood_Beam"
    },
    {
      "x": -19,
      "y": 23,
      "z": 0,
      "name": "Soil_Clay_Black"
    },
    {
      "x": -19,
      "y": 6,
      "z": 1,
      "name": "Soil_Dirt_Poisoned"
    },
    {
      "x": -19,
      "y": 7,
      "z": 1,
      "name": "Soil_Dirt_Poisoned"
    },
    {
      "x": -19,
      "y": 8,
      "z": 1,
      "name": "Empty"
    },
    {
      "x": -19,
      "y": 9,
      "z": 1,
      "name": "Empty"
    },
    {
      "x": -19,
      "y": 10,
      "z": 1,
      "name": "Empty"
    },
    {
      "x": -19,
      "y": 11,
      "z": 1,
      "name": "Empty"
    },
    {
      "x": -19,
      "y": 12,
      "z": 1,
      "name": "Empty"
    },
    {
      "x": -19,
      "y": 13,
      "z": 1,
      "name": "Empty"
    },
    {
      "x": -19,
      "y": 14,
      "z": 1,
      "name": "Empty"
    },
    {
      "x": -19,
      "y": 15,
      "z": 1,
      "name": "Empty"
    },
    {
      "x": -19,
      "y": 16,
      "z": 1,
      "name": "Empty"
    },
    {
      "x": -19,
      "y": 17,
      "z": 1,
      "name": "Empty"
    },
    {
      "x": -19,
      "y": 18,
      "z": 1,
      "name": "Empty"
    },
    {
      "x": -19,
      "y": 19,
      "z": 1,
      "name": "Empty"
    },
    {
      "x": -19,
      "y": 20,
      "z": 1,
      "name": "Empty"
    },
    {
      "x": -19,
      "y": 21,
      "z": 1,
      "name": "Empty"
    },
    {
      "x": -19,
      "y": 22,
      "z": 1,
      "name": "Empty"
    },
    {
      "x": -19,
      "y": 23,
      "z": 1,
      "name": "Soil_Clay_Black"
    },
    {
      "x": -19,
      "y": 6,
      "z": 2,
      "name": "Soil_Dirt_Poisoned"
    },
    {
      "x": -19,
      "y": 7,
      "z": 2,
      "name": "Soil_Dirt_Poisoned"
    },
    {
      "x": -19,
      "y": 8,
      "z": 2,
      "name": "Plant_Seaweed_Winter_Aurora"
    },
    {
      "x": -19,
      "y": 9,
      "z": 2,
      "name": "Plant_Seaweed_Winter_Aurora",
      "filler": 1024
    },
    {
      "x": -19,
      "y": 10,
      "z": 2,
      "name": "Empty"
    },
    {
      "x": -19,
      "y": 11,
      "z": 2,
      "name": "Empty"
    },
    {
      "x": -19,
      "y": 12,
      "z": 2,
      "name": "Empty"
    },
    {
      "x": -19,
      "y": 13,
      "z": 2,
      "name": "Empty"
    },
    {
      "x": -19,
      "y": 14,
      "z": 2,
      "name": "Empty"
    },
    {
      "x": -19,
      "y": 15,
      "z": 2,
      "name": "Empty"
    },
    {
      "x": -19,
      "y": 16,
      "z": 2,
      "name": "Empty"
    },
    {
      "x": -19,
      "y": 17,
      "z": 2,
      "name": "Empty"
    },
    {
      "x": -19,
      "y": 18,
      "z": 2,
      "name": "Empty"
    },
    {
      "x": -19,
      "y": 19,
      "z": 2,
      "name": "Empty"
    },
    {
      "x": -19,
      "y": 20,
      "z": 2,
      "name": "Empty"
    },
    {
      "x": -19,
      "y": 21,
      "z": 2,
      "name": "Empty"
    },
    {
      "x": -19,
      "y": 22,
      "z": 2,
      "name": "Empty"
    },
    {
      "x": -19,
      "y": 23,
      "z": 2,
      "name": "Rock_Volcanic_Brick"
    },
    {
      "x": -19,
      "y": 6,
      "z": 3,
      "name": "Soil_Dirt_Poisoned"
    },
    {
      "x": -19,
      "y": 7,
      "z": 3,
      "name": "Soil_Dirt_Poisoned"
    },
    {
      "x": -19,
      "y": 8,
      "z": 3,
      "name": "Plant_Seaweed_Winter_Aurora"
    },
    {
      "x": -19,
      "y": 9,
      "z": 3,
      "name": "Plant_Seaweed_Winter_Aurora",
      "filler": 1024
    },
    {
      "x": -19,
      "y": 10,
      "z": 3,
      "name": "Empty"
    },
    {
      "x": -19,
      "y": 11,
      "z": 3,
      "name": "Empty"
    },
    {
      "x": -19,
      "y": 12,
      "z": 3,
      "name": "Empty"
    },
    {
      "x": -19,
      "y": 13,
      "z": 3,
      "name": "Empty"
    },
    {
      "x": -19,
      "y": 14,
      "z": 3,
      "name": "Empty"
    },
    {
      "x": -19,
      "y": 15,
      "z": 3,
      "name": "Empty"
    },
    {
      "x": -19,
      "y": 16,
      "z": 3,
      "name": "Empty"
    },
    {
      "x": -19,
      "y": 17,
      "z": 3,
      "name": "Empty"
    },
    {
      "x": -19,
      "y": 18,
      "z": 3,
      "name": "Empty"
    },
    {
      "x": -19,
      "y": 19,
      "z": 3,
      "name": "Empty"
    },
    {
      "x": -19,
      "y": 20,
      "z": 3,
      "name": "Empty"
    },
    {
      "x": -19,
      "y": 21,
      "z": 3,
      "name": "Empty"
    },
    {
      "x": -19,
      "y": 22,
      "z": 3,
      "name": "Rock_Volcanic_Brick_Half",
      "rotation": 8
    },
    {
      "x": -19,
      "y": 23,
      "z": 3,
      "name": "Rock_Volcanic_Brick"
    },
    {
      "x": -19,
      "y": 6,
      "z": 4,
      "name": "Rock_Volcanic_Brick"
    },
    {
      "x": -19,
      "y": 7,
      "z": 4,
      "name": "Rock_Volcanic_Brick"
    },
    {
      "x": -19,
      "y": 8,
      "z": 4,
      "name": "Wood_Blackwood_Planks"
    },
    {
      "x": -19,
      "y": 9,
      "z": 4,
      "name": "Wood_Blackwood_Planks"
    },
    {
      "x": -19,
      "y": 10,
      "z": 4,
      "name": "Wood_Blackwood_Planks"
    },
    {
      "x": -19,
      "y": 11,
      "z": 4,
      "name": "Wood_Blackwood_Planks"
    },
    {
      "x": -19,
      "y": 12,
      "z": 4,
      "name": "Empty"
    },
    {
      "x": -19,
      "y": 13,
      "z": 4,
      "name": "Empty"
    },
    {
      "x": -19,
      "y": 14,
      "z": 4,
      "name": "Empty"
    },
    {
      "x": -19,
      "y": 15,
      "z": 4,
      "name": "Empty"
    },
    {
      "x": -19,
      "y": 16,
      "z": 4,
      "name": "Empty"
    },
    {
      "x": -19,
      "y": 17,
      "z": 4,
      "name": "Empty"
    },
    {
      "x": -19,
      "y": 18,
      "z": 4,
      "name": "Empty"
    },
    {
      "x": -19,
      "y": 19,
      "z": 4,
      "name": "Empty"
    },
    {
      "x": -19,
      "y": 20,
      "z": 4,
      "name": "Empty"
    },
    {
      "x": -19,
      "y": 21,
      "z": 4,
      "name": "Empty"
    },
    {
      "x": -19,
      "y": 22,
      "z": 4,
      "name": "Rock_Volcanic_Brick_Half",
      "rotation": 8
    },
    {
      "x": -19,
      "y": 23,
      "z": 4,
      "name": "Rock_Volcanic_Brick"
    },
    {
      "x": -19,
      "y": 6,
      "z": 5,
      "name": "Rock_Volcanic_Brick"
    },
    {
      "x": -19,
      "y": 7,
      "z": 5,
      "name": "Rock_Volcanic_Brick"
    },
    {
      "x": -19,
      "y": 8,
      "z": 5,
      "name": "Rock_Volcanic_Brick"
    },
    {
      "x": -19,
      "y": 9,
      "z": 5,
      "name": "Rock_Volcanic_Brick"
    },
    {
      "x": -19,
      "y": 10,
      "z": 5,
      "name": "Rock_Volcanic_Brick"
    },
    {
      "x": -19,
      "y": 11,
      "z": 5,
      "name": "Soil_Clay_Black"
    },
    {
      "x": -19,
      "y": 12,
      "z": 5,
      "name": "Empty"
    },
    {
      "x": -19,
      "y": 13,
      "z": 5,
      "name": "Empty"
    },
    {
      "x": -19,
      "y": 14,
      "z": 5,
      "name": "Empty"
    },
    {
      "x": -19,
      "y": 15,
      "z": 5,
      "name": "Empty"
    },
    {
      "x": -19,
      "y": 16,
      "z": 5,
      "name": "Empty"
    },
    {
      "x": -19,
      "y": 17,
      "z": 5,
      "name": "Empty"
    },
    {
      "x": -19,
      "y": 18,
      "z": 5,
      "name": "Empty"
    },
    {
      "x": -19,
      "y": 19,
      "z": 5,
      "name": "Empty"
    },
    {
      "x": -19,
      "y": 20,
      "z": 5,
      "name": "Empty"
    },
    {
      "x": -19,
      "y": 21,
      "z": 5,
      "name": "Empty"
    },
    {
      "x": -19,
      "y": 22,
      "z": 5,
      "name": "Rock_Volcanic_Brick"
    },
    {
      "x": -19,
      "y": 23,
      "z": 5,
      "name": "Rock_Volcanic_Brick"
    },
    {
      "x": -19,
      "y": 6,
      "z": 6,
      "name": "Rock_Volcanic_Brick"
    },
    {
      "x": -19,
      "y": 7,
      "z": 6,
      "name": "Rock_Volcanic_Brick"
    },
    {
      "x": -19,
      "y": 8,
      "z": 6,
      "name": "Rock_Volcanic_Brick"
    },
    {
      "x": -19,
      "y": 9,
      "z": 6,
      "name": "Rock_Volcanic_Brick"
    },
    {
      "x": -19,
      "y": 10,
      "z": 6,
      "name": "Rock_Volcanic_Brick"
    },
    {
      "x": -19,
      "y": 11,
      "z": 6,
      "name": "Soil_Clay_Black"
    },
    {
      "x": -19,
      "y": 12,
      "z": 6,
      "name": "Plant_Bush_Dead_Twisted"
    },
    {
      "x": -19,
      "y": 13,
      "z": 6,
      "name": "Empty"
    },
    {
      "x": -19,
      "y": 14,
      "z": 6,
      "name": "Empty"
    },
    {
      "x": -19,
      "y": 15,
      "z": 6,
      "name": "Empty"
    },
    {
      "x": -19,
      "y": 16,
      "z": 6,
      "name": "Empty"
    },
    {
      "x": -19,
      "y": 17,
      "z": 6,
      "name": "Empty"
    },
    {
      "x": -19,
      "y": 18,
      "z": 6,
      "name": "Empty"
    },
    {
      "x": -19,
      "y": 19,
      "z": 6,
      "name": "Empty"
    },
    {
      "x": -19,
      "y": 20,
      "z": 6,
      "name": "Empty"
    },
    {
      "x": -19,
      "y": 21,
      "z": 6,
      "name": "Empty"
    },
    {
      "x": -19,
      "y": 22,
      "z": 6,
      "name": "Rock_Volcanic_Brick"
    },
    {
      "x": -19,
      "y": 23,
      "z": 6,
      "name": "Rock_Volcanic_Brick"
    },
    {
      "x": -19,
      "y": 6,
      "z": 7,
      "name": "Rock_Volcanic_Brick"
    },
    {
      "x": -19,
      "y": 7,
      "z": 7,
      "name": "Rock_Volcanic_Brick"
    },
    {
      "x": -19,
      "y": 8,
      "z": 7,
      "name": "Rock_Volcanic_Brick"
    },
    {
      "x": -19,
      "y": 9,
      "z": 7,
      "name": "Rock_Volcanic_Brick"
    },
    {
      "x": -19,
      "y": 10,
      "z": 7,
      "name": "Rock_Volcanic_Brick"
    },
    {
      "x": -19,
      "y": 11,
      "z": 7,
      "name": "Rock_Volcanic_Brick"
    },
    {
      "x": -19,
      "y": 12,
      "z": 7,
      "name": "Wood_Blackwood_Planks"
    },
    {
      "x": -19,
      "y": 13,
      "z": 7,
      "name": "Wood_Blackwood_Planks"
    },
    {
      "x": -19,
      "y": 14,
      "z": 7,
      "name": "Wood_Blackwood_Planks"
    },
    {
      "x": -19,
      "y": 15,
      "z": 7,
      "name": "Wood_Blackwood_Planks"
    },
    {
      "x": -19,
      "y": 16,
      "z": 7,
      "name": "Wood_Blackwood_Planks"
    },
    {
      "x": -19,
      "y": 17,
      "z": 7,
      "name": "Wood_Blackwood_Planks"
    },
    {
      "x": -19,
      "y": 18,
      "z": 7,
      "name": "Wood_Blackwood_Planks"
    },
    {
      "x": -19,
      "y": 19,
      "z": 7,
      "name": "Wood_Blackwood_Planks"
    },
    {
      "x": -19,
      "y": 20,
      "z": 7,
      "name": "Wood_Blackwood_Planks"
    },
    {
      "x": -19,
      "y": 21,
      "z": 7,
      "name": "Wood_Blackwood_Planks"
    },
    {
      "x": -19,
      "y": 22,
      "z": 7,
      "name": "Rock_Volcanic_Brick"
    },
    {
      "x": -19,
      "y": 23,
      "z": 7,
      "name": "Rock_Volcanic_Brick"
    },
    {
      "x": -18,
      "y": 6,
      "z": -7,
      "name": "Rock_Volcanic_Brick"
    },
    {
      "x": -18,
      "y": 7,
      "z": -7,
      "name": "Rock_Volcanic_Brick"
    },
    {
      "x": -18,
      "y": 8,
      "z": -7,
      "name": "Rock_Volcanic_Brick"
    },
    {
      "x": -18,
      "y": 9,
      "z": -7,
      "name": "Rock_Volcanic_Brick"
    },
    {
      "x": -18,
      "y": 10,
      "z": -7,
      "name": "Rock_Volcanic_Brick"
    },
    {
      "x": -18,
      "y": 11,
      "z": -7,
      "name": "Rock_Volcanic_Brick"
    },
    {
      "x": -18,
      "y": 12,
      "z": -7,
      "name": "Rock_Volcanic_Brick"
    },
    {
      "x": -18,
      "y": 13,
      "z": -7,
      "name": "Rock_Volcanic_Brick"
    },
    {
      "x": -18,
      "y": 14,
      "z": -7,
      "name": "Rock_Volcanic_Brick"
    },
    {
      "x": -18,
      "y": 15,
      "z": -7,
      "name": "Rock_Volcanic_Brick"
    },
    {
      "x": -18,
      "y": 16,
      "z": -7,
      "name": "Rock_Volcanic_Brick"
    },
    {
      "x": -18,
      "y": 17,
      "z": -7,
      "name": "Rock_Volcanic_Brick"
    },
    {
      "x": -18,
      "y": 18,
      "z": -7,
      "name": "Rock_Volcanic_Brick_Stairs"
    },
    {
      "x": -18,
      "y": 19,
      "z": -7,
      "name": "Empty"
    },
    {
      "x": -18,
      "y": 20,
      "z": -7,
      "name": "Rock_Volcanic_Brick"
    },
    {
      "x": -18,
      "y": 21,
      "z": -7,
      "name": "Rock_Volcanic_Brick"
    },
    {
      "x": -18,
      "y": 22,
      "z": -7,
      "name": "Rock_Volcanic_Brick"
    },
    {
      "x": -18,
      "y": 23,
      "z": -7,
      "name": "Rock_Volcanic_Brick"
    },
    {
      "x": -18,
      "y": 6,
      "z": -6,
      "name": "Rock_Volcanic_Brick"
    },
    {
      "x": -18,
      "y": 7,
      "z": -6,
      "name": "Rock_Volcanic_Brick"
    },
    {
      "x": -18,
      "y": 8,
      "z": -6,
      "name": "Rock_Volcanic_Brick"
    },
    {
      "x": -18,
      "y": 9,
      "z": -6,
      "name": "Rock_Volcanic_Brick"
    },
    {
      "x": -18,
      "y": 10,
      "z": -6,
      "name": "Rock_Volcanic_Brick"
    },
    {
      "x": -18,
      "y": 11,
      "z": -6,
      "name": "Wood_Blackwood_Planks"
    },
    {
      "x": -18,
      "y": 12,
      "z": -6,
      "name": "Empty"
    },
    {
      "x": -18,
      "y": 13,
      "z": -6,
      "name": "Empty"
    },
    {
      "x": -18,
      "y": 14,
      "z": -6,
      "name": "Empty"
    },
    {
      "x": -18,
      "y": 15,
      "z": -6,
      "name": "Empty"
    },
    {
      "x": -18,
      "y": 16,
      "z": -6,
      "name": "Empty"
    },
    {
      "x": -18,
      "y": 17,
      "z": -6,
      "name": "Empty"
    },
    {
      "x": -18,
      "y": 18,
      "z": -6,
      "name": "Empty"
    },
    {
      "x": -18,
      "y": 19,
      "z": -6,
      "name": "Empty"
    },
    {
      "x": -18,
      "y": 20,
      "z": -6,
      "name": "Rock_Volcanic_Brick"
    },
    {
      "x": -18,
      "y": 21,
      "z": -6,
      "name": "Rock_Volcanic_Brick"
    },
    {
      "x": -18,
      "y": 22,
      "z": -6,
      "name": "Rock_Volcanic_Brick"
    },
    {
      "x": -18,
      "y": 23,
      "z": -6,
      "name": "Rock_Volcanic_Brick"
    },
    {
      "x": -18,
      "y": 6,
      "z": -5,
      "name": "Rock_Volcanic_Brick"
    },
    {
      "x": -18,
      "y": 7,
      "z": -5,
      "name": "Rock_Volcanic_Brick"
    },
    {
      "x": -18,
      "y": 8,
      "z": -5,
      "name": "Rock_Volcanic_Brick"
    },
    {
      "x": -18,
      "y": 9,
      "z": -5,
      "name": "Rock_Volcanic_Brick"
    },
    {
      "x": -18,
      "y": 10,
      "z": -5,
      "name": "Rock_Volcanic_Brick"
    },
    {
      "x": -18,
      "y": 11,
      "z": -5,
      "name": "Wood_Blackwood_Planks"
    },
    {
      "x": -18,
      "y": 12,
      "z": -5,
      "name": "Empty"
    },
    {
      "x": -18,
      "y": 13,
      "z": -5,
      "name": "Empty"
    },
    {
      "x": -18,
      "y": 14,
      "z": -5,
      "name": "Empty"
    },
    {
      "x": -18,
      "y": 15,
      "z": -5,
      "name": "Empty"
    },
    {
      "x": -18,
      "y": 16,
      "z": -5,
      "name": "Empty"
    },
    {
      "x": -18,
      "y": 17,
      "z": -5,
      "name": "Empty"
    },
    {
      "x": -18,
      "y": 18,
      "z": -5,
      "name": "Empty"
    },
    {
      "x": -18,
      "y": 19,
      "z": -5,
      "name": "Empty"
    },
    {
      "x": -18,
      "y": 20,
      "z": -5,
      "name": "Empty"
    },
    {
      "x": -18,
      "y": 21,
      "z": -5,
      "name": "Rock_Volcanic_Brick"
    },
    {
      "x": -18,
      "y": 22,
      "z": -5,
      "name": "Rock_Volcanic_Brick"
    },
    {
      "x": -18,
      "y": 23,
      "z": -5,
      "name": "Rock_Volcanic_Brick"
    },
    {
      "x": -18,
      "y": 6,
      "z": -4,
      "name": "Rock_Volcanic_Brick"
    },
    {
      "x": -18,
      "y": 7,
      "z": -4,
      "name": "Wood_Blackwood_Planks"
    },
    {
      "x": -18,
      "y": 8,
      "z": -4,
      "name": "Wood_Blackwood_Planks"
    },
    {
      "x": -18,
      "y": 9,
      "z": -4,
      "name": "Wood_Blackwood_Planks"
    },
    {
      "x": -18,
      "y": 10,
      "z": -4,
      "name": "Wood_Blackwood_Planks"
    },
    {
      "x": -18,
      "y": 11,
      "z": -4,
      "name": "Wood_Blackwood_Planks"
    },
    {
      "x": -18,
      "y": 12,
      "z": -4,
      "name": "Empty"
    },
    {
      "x": -18,
      "y": 13,
      "z": -4,
      "name": "Empty"
    },
    {
      "x": -18,
      "y": 14,
      "z": -4,
      "name": "Empty"
    },
    {
      "x": -18,
      "y": 15,
      "z": -4,
      "name": "Empty"
    },
    {
      "x": -18,
      "y": 16,
      "z": -4,
      "name": "Empty"
    },
    {
      "x": -18,
      "y": 17,
      "z": -4,
      "name": "Empty"
    },
    {
      "x": -18,
      "y": 18,
      "z": -4,
      "name": "Empty"
    },
    {
      "x": -18,
      "y": 19,
      "z": -4,
      "name": "Empty"
    },
    {
      "x": -18,
      "y": 20,
      "z": -4,
      "name": "Empty"
    },
    {
      "x": -18,
      "y": 21,
      "z": -4,
      "name": "Rock_Volcanic_Brick_Half",
      "rotation": 8
    },
    {
      "x": -18,
      "y": 22,
      "z": -4,
      "name": "Rock_Volcanic_Brick"
    },
    {
      "x": -18,
      "y": 23,
      "z": -4,
      "name": "Rock_Volcanic_Brick"
    },
    {
      "x": -18,
      "y": 6,
      "z": -3,
      "name": "Soil_Dirt_Poisoned"
    },
    {
      "x": -18,
      "y": 7,
      "z": -3,
      "name": "Empty"
    },
    {
      "x": -18,
      "y": 8,
      "z": -3,
      "name": "Empty"
    },
    {
      "x": -18,
      "y": 9,
      "z": -3,
      "name": "Empty"
    },
    {
      "x": -18,
      "y": 10,
      "z": -3,
      "name": "Empty"
    },
    {
      "x": -18,
      "y": 11,
      "z": -3,
      "name": "Empty"
    },
    {
      "x": -18,
      "y": 12,
      "z": -3,
      "name": "Empty"
    },
    {
      "x": -18,
      "y": 13,
      "z": -3,
      "name": "Empty"
    },
    {
      "x": -18,
      "y": 14,
      "z": -3,
      "name": "Empty"
    },
    {
      "x": -18,
      "y": 15,
      "z": -3,
      "name": "Empty"
    },
    {
      "x": -18,
      "y": 16,
      "z": -3,
      "name": "Empty"
    },
    {
      "x": -18,
      "y": 17,
      "z": -3,
      "name": "Empty"
    },
    {
      "x": -18,
      "y": 18,
      "z": -3,
      "name": "Empty"
    },
    {
      "x": -18,
      "y": 19,
      "z": -3,
      "name": "Empty"
    },
    {
      "x": -18,
      "y": 20,
      "z": -3,
      "name": "Empty"
    },
    {
      "x": -18,
      "y": 21,
      "z": -3,
      "name": "Empty"
    },
    {
      "x": -18,
      "y": 22,
      "z": -3,
      "name": "Soil_Clay_Black"
    },
    {
      "x": -18,
      "y": 23,
      "z": -3,
      "name": "Soil_Clay_Black"
    },
    {
      "x": -18,
      "y": 6,
      "z": -2,
      "name": "Soil_Dirt_Poisoned"
    },
    {
      "x": -18,
      "y": 7,
      "z": -2,
      "name": "Plant_Seaweed_Dead_Stack"
    },
    {
      "x": -18,
      "y": 8,
      "z": -2,
      "name": "Plant_Seaweed_Dead_Stack"
    },
    {
      "x": -18,
      "y": 9,
      "z": -2,
      "name": "Plant_Seaweed_Dead_Stack"
    },
    {
      "x": -18,
      "y": 10,
      "z": -2,
      "name": "Empty"
    },
    {
      "x": -18,
      "y": 11,
      "z": -2,
      "name": "Empty"
    },
    {
      "x": -18,
      "y": 12,
      "z": -2,
      "name": "Empty"
    },
    {
      "x": -18,
      "y": 13,
      "z": -2,
      "name": "Empty"
    },
    {
      "x": -18,
      "y": 14,
      "z": -2,
      "name": "Empty"
    },
    {
      "x": -18,
      "y": 15,
      "z": -2,
      "name": "Empty"
    },
    {
      "x": -18,
      "y": 16,
      "z": -2,
      "name": "Empty"
    },
    {
      "x": -18,
      "y": 17,
      "z": -2,
      "name": "Empty"
    },
    {
      "x": -18,
      "y": 18,
      "z": -2,
      "name": "Empty"
    },
    {
      "x": -18,
      "y": 19,
      "z": -2,
      "name": "Empty"
    },
    {
      "x": -18,
      "y": 20,
      "z": -2,
      "name": "Empty"
    },
    {
      "x": -18,
      "y": 21,
      "z": -2,
      "name": "Empty"
    },
    {
      "x": -18,
      "y": 22,
      "z": -2,
      "name": "Soil_Clay_Black"
    },
    {
      "x": -18,
      "y": 23,
      "z": -2,
      "name": "Soil_Clay_Black"
    },
    {
      "x": -18,
      "y": 6,
      "z": -1,
      "name": "Soil_Dirt_Poisoned"
    },
    {
      "x": -18,
      "y": 7,
      "z": -1,
      "name": "Soil_Dirt_Poisoned"
    },
    {
      "x": -18,
      "y": 8,
      "z": -1,
      "name": "Empty"
    },
    {
      "x": -18,
      "y": 9,
      "z": -1,
      "name": "Empty"
    },
    {
      "x": -18,
      "y": 10,
      "z": -1,
      "name": "Empty"
    },
    {
      "x": -18,
      "y": 11,
      "z": -1,
      "name": "Empty"
    },
    {
      "x": -18,
      "y": 12,
      "z": -1,
      "name": "Empty"
    },
    {
      "x": -18,
      "y": 13,
      "z": -1,
      "name": "Empty"
    },
    {
      "x": -18,
      "y": 14,
      "z": -1,
      "name": "Empty"
    },
    {
      "x": -18,
      "y": 15,
      "z": -1,
      "name": "Empty"
    },
    {
      "x": -18,
      "y": 16,
      "z": -1,
      "name": "Empty"
    },
    {
      "x": -18,
      "y": 17,
      "z": -1,
      "name": "Empty"
    },
    {
      "x": -18,
      "y": 18,
      "z": -1,
      "name": "Empty"
    },
    {
      "x": -18,
      "y": 19,
      "z": -1,
      "name": "Empty"
    },
    {
      "x": -18,
      "y": 20,
      "z": -1,
      "name": "Empty"
    },
    {
      "x": -18,
      "y": 21,
      "z": -1,
      "name": "Empty"
    },
    {
      "x": -18,
      "y": 22,
      "z": -1,
      "name": "Soil_Clay_Black"
    },
    {
      "x": -18,
      "y": 23,
      "z": -1,
      "name": "Soil_Clay_Black"
    },
    {
      "x": -18,
      "y": 6,
      "z": 0,
      "name": "Soil_Dirt_Poisoned"
    },
    {
      "x": -18,
      "y": 7,
      "z": 0,
      "name": "Soil_Dirt_Poisoned"
    },
    {
      "x": -18,
      "y": 8,
      "z": 0,
      "name": "Empty"
    },
    {
      "x": -18,
      "y": 9,
      "z": 0,
      "name": "Empty"
    },
    {
      "x": -18,
      "y": 10,
      "z": 0,
      "name": "Empty"
    },
    {
      "x": -18,
      "y": 11,
      "z": 0,
      "name": "Empty"
    },
    {
      "x": -18,
      "y": 12,
      "z": 0,
      "name": "Empty"
    },
    {
      "x": -18,
      "y": 13,
      "z": 0,
      "name": "Empty"
    },
    {
      "x": -18,
      "y": 14,
      "z": 0,
      "name": "Empty"
    },
    {
      "x": -18,
      "y": 15,
      "z": 0,
      "name": "Empty"
    },
    {
      "x": -18,
      "y": 16,
      "z": 0,
      "name": "Empty"
    },
    {
      "x": -18,
      "y": 17,
      "z": 0,
      "name": "Empty"
    },
    {
      "x": -18,
      "y": 18,
      "z": 0,
      "name": "Empty"
    },
    {
      "x": -18,
      "y": 19,
      "z": 0,
      "name": "Empty"
    },
    {
      "x": -18,
      "y": 20,
      "z": 0,
      "name": "Empty"
    },
    {
      "x": -18,
      "y": 21,
      "z": 0,
      "name": "Empty"
    },
    {
      "x": -18,
      "y": 22,
      "z": 0,
      "name": "Empty"
    },
    {
      "x": -18,
      "y": 23,
      "z": 0,
      "name": "Soil_Clay_Black"
    },
    {
      "x": -18,
      "y": 6,
      "z": 1,
      "name": "Soil_Dirt_Poisoned"
    },
    {
      "x": -18,
      "y": 7,
      "z": 1,
      "name": "Soil_Dirt_Poisoned"
    },
    {
      "x": -18,
      "y": 8,
      "z": 1,
      "name": "Empty"
    },
    {
      "x": -18,
      "y": 9,
      "z": 1,
      "name": "Empty"
    },
    {
      "x": -18,
      "y": 10,
      "z": 1,
      "name": "Empty"
    },
    {
      "x": -18,
      "y": 11,
      "z": 1,
      "name": "Empty"
    },
    {
      "x": -18,
      "y": 12,
      "z": 1,
      "name": "Empty"
    },
    {
      "x": -18,
      "y": 13,
      "z": 1,
      "name": "Empty"
    },
    {
      "x": -18,
      "y": 14,
      "z": 1,
      "name": "Empty"
    },
    {
      "x": -18,
      "y": 15,
      "z": 1,
      "name": "Empty"
    },
    {
      "x": -18,
      "y": 16,
      "z": 1,
      "name": "Empty"
    },
    {
      "x": -18,
      "y": 17,
      "z": 1,
      "name": "Empty"
    },
    {
      "x": -18,
      "y": 18,
      "z": 1,
      "name": "Empty"
    },
    {
      "x": -18,
      "y": 19,
      "z": 1,
      "name": "Empty"
    },
    {
      "x": -18,
      "y": 20,
      "z": 1,
      "name": "Empty"
    },
    {
      "x": -18,
      "y": 21,
      "z": 1,
      "name": "Empty"
    },
    {
      "x": -18,
      "y": 22,
      "z": 1,
      "name": "Empty"
    },
    {
      "x": -18,
      "y": 23,
      "z": 1,
      "name": "Soil_Clay_Black"
    },
    {
      "x": -18,
      "y": 6,
      "z": 2,
      "name": "Soil_Dirt_Poisoned"
    },
    {
      "x": -18,
      "y": 7,
      "z": 2,
      "name": "Soil_Dirt_Poisoned"
    },
    {
      "x": -18,
      "y": 8,
      "z": 2,
      "name": "Empty"
    },
    {
      "x": -18,
      "y": 9,
      "z": 2,
      "name": "Empty"
    },
    {
      "x": -18,
      "y": 10,
      "z": 2,
      "name": "Empty"
    },
    {
      "x": -18,
      "y": 11,
      "z": 2,
      "name": "Empty"
    },
    {
      "x": -18,
      "y": 12,
      "z": 2,
      "name": "Empty"
    },
    {
      "x": -18,
      "y": 13,
      "z": 2,
      "name": "Empty"
    },
    {
      "x": -18,
      "y": 14,
      "z": 2,
      "name": "Empty"
    },
    {
      "x": -18,
      "y": 15,
      "z": 2,
      "name": "Empty"
    },
    {
      "x": -18,
      "y": 16,
      "z": 2,
      "name": "Empty"
    },
    {
      "x": -18,
      "y": 17,
      "z": 2,
      "name": "Empty"
    },
    {
      "x": -18,
      "y": 18,
      "z": 2,
      "name": "Empty"
    },
    {
      "x": -18,
      "y": 19,
      "z": 2,
      "name": "Empty"
    },
    {
      "x": -18,
      "y": 20,
      "z": 2,
      "name": "Empty"
    },
    {
      "x": -18,
      "y": 21,
      "z": 2,
      "name": "Empty"
    },
    {
      "x": -18,
      "y": 22,
      "z": 2,
      "name": "Rock_Volcanic_Brick_Half",
      "rotation": 8
    },
    {
      "x": -18,
      "y": 23,
      "z": 2,
      "name": "Rock_Volcanic_Brick"
    },
    {
      "x": -18,
      "y": 6,
      "z": 3,
      "name": "Soil_Dirt_Poisoned"
    },
    {
      "x": -18,
      "y": 7,
      "z": 3,
      "name": "Plant_Crop_Mushroom_Block_Purple"
    },
    {
      "x": -18,
      "y": 8,
      "z": 3,
      "name": "Plant_Crop_Mushroom_Block_Purple"
    },
    {
      "x": -18,
      "y": 9,
      "z": 3,
      "name": "Plant_Crop_Mushroom_Block_Purple"
    },
    {
      "x": -18,
      "y": 10,
      "z": 3,
      "name": "Empty"
    },
    {
      "x": -18,
      "y": 11,
      "z": 3,
      "name": "Empty"
    },
    {
      "x": -18,
      "y": 12,
      "z": 3,
      "name": "Empty"
    },
    {
      "x": -18,
      "y": 13,
      "z": 3,
      "name": "Empty"
    },
    {
      "x": -18,
      "y": 14,
      "z": 3,
      "name": "Empty"
    },
    {
      "x": -18,
      "y": 15,
      "z": 3,
      "name": "Empty"
    },
    {
      "x": -18,
      "y": 16,
      "z": 3,
      "name": "Empty"
    },
    {
      "x": -18,
      "y": 17,
      "z": 3,
      "name": "Empty"
    },
    {
      "x": -18,
      "y": 18,
      "z": 3,
      "name": "Empty"
    },
    {
      "x": -18,
      "y": 19,
      "z": 3,
      "name": "Empty"
    },
    {
      "x": -18,
      "y": 20,
      "z": 3,
      "name": "Empty"
    },
    {
      "x": -18,
      "y": 21,
      "z": 3,
      "name": "Empty"
    },
    {
      "x": -18,
      "y": 22,
      "z": 3,
      "name": "Rock_Volcanic_Brick_Half",
      "rotation": 8
    },
    {
      "x": -18,
      "y": 23,
      "z": 3,
      "name": "Rock_Volcanic_Brick"
    },
    {
      "x": -18,
      "y": 6,
      "z": 4,
      "name": "Rock_Volcanic_Brick"
    },
    {
      "x": -18,
      "y": 7,
      "z": 4,
      "name": "Rock_Volcanic_Brick"
    },
    {
      "x": -18,
      "y": 8,
      "z": 4,
      "name": "Plant_Crop_Mushroom_Block_Purple"
    },
    {
      "x": -18,
      "y": 9,
      "z": 4,
      "name": "Plant_Crop_Mushroom_Block_Purple"
    },
    {
      "x": -18,
      "y": 10,
      "z": 4,
      "name": "Plant_Crop_Mushroom_Block_Purple"
    },
    {
      "x": -18,
      "y": 11,
      "z": 4,
      "name": "Plant_Crop_Mushroom_Block_Purple"
    },
    {
      "x": -18,
      "y": 12,
      "z": 4,
      "name": "Empty"
    },
    {
      "x": -18,
      "y": 13,
      "z": 4,
      "name": "Empty"
    },
    {
      "x": -18,
      "y": 14,
      "z": 4,
      "name": "Empty"
    },
    {
      "x": -18,
      "y": 15,
      "z": 4,
      "name": "Empty"
    },
    {
      "x": -18,
      "y": 16,
      "z": 4,
      "name": "Empty"
    },
    {
      "x": -18,
      "y": 17,
      "z": 4,
      "name": "Empty"
    },
    {
      "x": -18,
      "y": 18,
      "z": 4,
      "name": "Empty"
    },
    {
      "x": -18,
      "y": 19,
      "z": 4,
      "name": "Empty"
    },
    {
      "x": -18,
      "y": 20,
      "z": 4,
      "name": "Empty"
    },
    {
      "x": -18,
      "y": 21,
      "z": 4,
      "name": "Empty"
    },
    {
      "x": -18,
      "y": 22,
      "z": 4,
      "name": "Rock_Volcanic_Brick_Half",
      "rotation": 8
    },
    {
      "x": -18,
      "y": 23,
      "z": 4,
      "name": "Rock_Volcanic_Brick"
    },
    {
      "x": -18,
      "y": 6,
      "z": 5,
      "name": "Rock_Volcanic_Brick"
    },
    {
      "x": -18,
      "y": 7,
      "z": 5,
      "name": "Rock_Volcanic_Brick"
    },
    {
      "x": -18,
      "y": 8,
      "z": 5,
      "name": "Rock_Volcanic_Brick"
    },
    {
      "x": -18,
      "y": 9,
      "z": 5,
      "name": "Rock_Volcanic_Brick"
    },
    {
      "x": -18,
      "y": 10,
      "z": 5,
      "name": "Plant_Crop_Mushroom_Block_Purple"
    },
    {
      "x": -18,
      "y": 11,
      "z": 5,
      "name": "Soil_Clay_Black"
    },
    {
      "x": -18,
      "y": 12,
      "z": 5,
      "name": "Plant_Bramble_Dead_Twisted"
    },
    {
      "x": -18,
      "y": 13,
      "z": 5,
      "name": "Empty"
    },
    {
      "x": -18,
      "y": 14,
      "z": 5,
      "name": "Empty"
    },
    {
      "x": -18,
      "y": 15,
      "z": 5,
      "name": "Empty"
    },
    {
      "x": -18,
      "y": 16,
      "z": 5,
      "name": "Empty"
    },
    {
      "x": -18,
      "y": 17,
      "z": 5,
      "name": "Empty"
    },
    {
      "x": -18,
      "y": 18,
      "z": 5,
      "name": "Empty"
    },
    {
      "x": -18,
      "y": 19,
      "z": 5,
      "name": "Empty"
    },
    {
      "x": -18,
      "y": 20,
      "z": 5,
      "name": "Empty"
    },
    {
      "x": -18,
      "y": 21,
      "z": 5,
      "name": "Empty"
    },
    {
      "x": -18,
      "y": 22,
      "z": 5,
      "name": "Rock_Volcanic_Brick"
    },
    {
      "x": -18,
      "y": 23,
      "z": 5,
      "name": "Rock_Volcanic_Brick"
    },
    {
      "x": -18,
      "y": 6,
      "z": 6,
      "name": "Rock_Volcanic_Brick"
    },
    {
      "x": -18,
      "y": 7,
      "z": 6,
      "name": "Rock_Volcanic_Brick"
    },
    {
      "x": -18,
      "y": 8,
      "z": 6,
      "name": "Rock_Volcanic_Brick"
    },
    {
      "x": -18,
      "y": 9,
      "z": 6,
      "name": "Rock_Volcanic_Brick"
    },
    {
      "x": -18,
      "y": 10,
      "z": 6,
      "name": "Rock_Volcanic_Brick"
    },
    {
      "x": -18,
      "y": 11,
      "z": 6,
      "name": "Soil_Clay_Black"
    },
    {
      "x": -18,
      "y": 12,
      "z": 6,
      "name": "Plant_Bush_Dead_Twisted"
    },
    {
      "x": -18,
      "y": 13,
      "z": 6,
      "name": "Empty"
    },
    {
      "x": -18,
      "y": 14,
      "z": 6,
      "name": "Empty"
    },
    {
      "x": -18,
      "y": 15,
      "z": 6,
      "name": "Empty"
    },
    {
      "x": -18,
      "y": 16,
      "z": 6,
      "name": "Empty"
    },
    {
      "x": -18,
      "y": 17,
      "z": 6,
      "name": "Empty"
    },
    {
      "x": -18,
      "y": 18,
      "z": 6,
      "name": "Empty"
    },
    {
      "x": -18,
      "y": 19,
      "z": 6,
      "name": "Empty"
    },
    {
      "x": -18,
      "y": 20,
      "z": 6,
      "name": "Empty"
    },
    {
      "x": -18,
      "y": 21,
      "z": 6,
      "name": "Empty"
    },
    {
      "x": -18,
      "y": 22,
      "z": 6,
      "name": "Rock_Volcanic_Brick"
    },
    {
      "x": -18,
      "y": 23,
      "z": 6,
      "name": "Rock_Volcanic_Brick"
    },
    {
      "x": -18,
      "y": 6,
      "z": 7,
      "name": "Rock_Volcanic_Brick"
    },
    {
      "x": -18,
      "y": 7,
      "z": 7,
      "name": "Rock_Volcanic_Brick"
    },
    {
      "x": -18,
      "y": 8,
      "z": 7,
      "name": "Rock_Volcanic_Brick"
    },
    {
      "x": -18,
      "y": 9,
      "z": 7,
      "name": "Rock_Volcanic_Brick"
    },
    {
      "x": -18,
      "y": 10,
      "z": 7,
      "name": "Rock_Volcanic_Brick"
    },
    {
      "x": -18,
      "y": 11,
      "z": 7,
      "name": "Rock_Volcanic_Brick"
    },
    {
      "x": -18,
      "y": 12,
      "z": 7,
      "name": "Wood_Blackwood_Planks"
    },
    {
      "x": -18,
      "y": 13,
      "z": 7,
      "name": "Wood_Blackwood_Planks"
    },
    {
      "x": -18,
      "y": 14,
      "z": 7,
      "name": "Wood_Blackwood_Planks"
    },
    {
      "x": -18,
      "y": 15,
      "z": 7,
      "name": "Wood_Blackwood_Planks"
    },
    {
      "x": -18,
      "y": 16,
      "z": 7,
      "name": "Wood_Blackwood_Planks"
    },
    {
      "x": -18,
      "y": 17,
      "z": 7,
      "name": "Wood_Blackwood_Planks"
    },
    {
      "x": -18,
      "y": 18,
      "z": 7,
      "name": "Wood_Blackwood_Planks"
    },
    {
      "x": -18,
      "y": 19,
      "z": 7,
      "name": "Wood_Blackwood_Planks"
    },
    {
      "x": -18,
      "y": 20,
      "z": 7,
      "name": "Wood_Blackwood_Planks"
    },
    {
      "x": -18,
      "y": 21,
      "z": 7,
      "name": "Wood_Blackwood_Planks"
    },
    {
      "x": -18,
      "y": 22,
      "z": 7,
      "name": "Rock_Volcanic_Brick"
    },
    {
      "x": -18,
      "y": 23,
      "z": 7,
      "name": "Rock_Volcanic_Brick"
    },
    {
      "x": -17,
      "y": 6,
      "z": -7,
      "name": "Rock_Volcanic_Brick"
    },
    {
      "x": -17,
      "y": 7,
      "z": -7,
      "name": "Rock_Volcanic_Brick"
    },
    {
      "x": -17,
      "y": 8,
      "z": -7,
      "name": "Rock_Volcanic_Brick"
    },
    {
      "x": -17,
      "y": 9,
      "z": -7,
      "name": "Rock_Volcanic_Brick"
    },
    {
      "x": -17,
      "y": 10,
      "z": -7,
      "name": "Rock_Volcanic_Brick"
    },
    {
      "x": -17,
      "y": 11,
      "z": -7,
      "name": "Rock_Volcanic_Brick"
    },
    {
      "x": -17,
      "y": 12,
      "z": -7,
      "name": "Rock_Volcanic_Brick"
    },
    {
      "x": -17,
      "y": 13,
      "z": -7,
      "name": "Rock_Volcanic_Brick"
    },
    {
      "x": -17,
      "y": 14,
      "z": -7,
      "name": "Rock_Volcanic_Brick"
    },
    {
      "x": -17,
      "y": 15,
      "z": -7,
      "name": "Rock_Volcanic_Brick"
    },
    {
      "x": -17,
      "y": 16,
      "z": -7,
      "name": "Rock_Volcanic_Brick"
    },
    {
      "x": -17,
      "y": 17,
      "z": -7,
      "name": "Rock_Volcanic_Brick"
    },
    {
      "x": -17,
      "y": 18,
      "z": -7,
      "name": "Rock_Volcanic_Brick_Stairs"
    },
    {
      "x": -17,
      "y": 19,
      "z": -7,
      "name": "Empty"
    },
    {
      "x": -17,
      "y": 20,
      "z": -7,
      "name": "Rock_Volcanic_Brick"
    },
    {
      "x": -17,
      "y": 21,
      "z": -7,
      "name": "Rock_Volcanic_Brick"
    },
    {
      "x": -17,
      "y": 22,
      "z": -7,
      "name": "Rock_Volcanic_Brick"
    },
    {
      "x": -17,
      "y": 23,
      "z": -7,
      "name": "Rock_Volcanic_Brick"
    },
    {
      "x": -17,
      "y": 6,
      "z": -6,
      "name": "Rock_Volcanic_Brick"
    },
    {
      "x": -17,
      "y": 7,
      "z": -6,
      "name": "Rock_Volcanic_Brick"
    },
    {
      "x": -17,
      "y": 8,
      "z": -6,
      "name": "Rock_Volcanic_Brick"
    },
    {
      "x": -17,
      "y": 9,
      "z": -6,
      "name": "Rock_Volcanic_Brick"
    },
    {
      "x": -17,
      "y": 10,
      "z": -6,
      "name": "Rock_Volcanic_Brick"
    },
    {
      "x": -17,
      "y": 11,
      "z": -6,
      "name": "Wood_Blackwood_Planks"
    },
    {
      "x": -17,
      "y": 12,
      "z": -6,
      "name": "Empty"
    },
    {
      "x": -17,
      "y": 13,
      "z": -6,
      "name": "Empty"
    },
    {
      "x": -17,
      "y": 14,
      "z": -6,
      "name": "Empty"
    },
    {
      "x": -17,
      "y": 15,
      "z": -6,
      "name": "Empty"
    },
    {
      "x": -17,
      "y": 16,
      "z": -6,
      "name": "Empty"
    },
    {
      "x": -17,
      "y": 17,
      "z": -6,
      "name": "Empty"
    },
    {
      "x": -17,
      "y": 18,
      "z": -6,
      "name": "Empty"
    },
    {
      "x": -17,
      "y": 19,
      "z": -6,
      "name": "Empty"
    },
    {
      "x": -17,
      "y": 20,
      "z": -6,
