{
  "version": 8,
  "blockIdVersion": 10,
  "anchorX": -1,
  "anchorY": 2,
  "anchorZ": -6,
  "blocks": [
    {
      "x": -6,
      "y": 5,
      "z": -8,
      "name": "Wood_Dry_Branch_Corner",
      "rotation": 9
    },
    {
      "x": -6,
      "y": 3,
      "z": -7,
      "name": "Cloth_Roof_Hide_Vertical",
      "rotation": 3
    },
    {
      "x": -6,
      "y": 4,
      "z": -7,
      "name": "Cloth_Roof_Hide_Vertical",
      "rotation": 3
    },
    {
      "x": -6,
      "y": 5,
      "z": -7,
      "name": "Wood_Drywood_Planks_Half",
      "rotation": 7
    },
    {
      "x": -6,
      "y": 4,
      "z": -6,
      "name": "Cloth_Roof_Hide_Flap",
      "rotation": 3
    },
    {
      "x": -6,
      "y": 5,
      "z": -6,
      "name": "Wood_Drywood_Planks_Half",
      "rotation": 7
    },
    {
      "x": -6,
      "y": 3,
      "z": -5,
      "name": "Cloth_Roof_Hide_Vertical",
      "rotation": 3
    },
    {
      "x": -6,
      "y": 4,
      "z": -5,
      "name": "Cloth_Roof_Hide_Vertical",
      "rotation": 3
    },
    {
      "x": -6,
      "y": 5,
      "z": -5,
      "name": "Wood_Drywood_Planks_Half",
      "rotation": 7
    },
    {
      "x": -6,
      "y": 5,
      "z": -4,
      "name": "Wood_Dry_Branch_Corner",
      "rotation": 9
    },
    {
      "x": -5,
      "y": 3,
      "z": -9,
      "name": "Cloth_Roof_Hide_Vertical",
      "rotation": 3
    },
    {
      "x": -5,
      "y": 4,
      "z": -9,
      "name": "Cloth_Roof_Hide_Vertical",
      "rotation": 3
    },
    {
      "x": -5,
      "y": 5,
      "z": -9,
      "name": "Wood_Drywood_Planks_Half",
      "rotation": 7
    },
    {
      "x": -5,
      "y": 2,
      "z": -8,
      "name": "Rock_Sandstone_Cobble"
    },
    {
      "x": -5,
      "y": 3,
      "z": -8,
      "name": "Cloth_Roof_Hide_Vertical",
      "rotation": 3
    },
    {
      "x": -5,
      "y": 4,
      "z": -8,
      "name": "Cloth_Roof_Hide_Vertical",
      "rotation": 3
    },
    {
      "x": -5,
      "y": 5,
      "z": -8,
      "name": "Wood_Drywood_Planks",
      "rotation": 2
    },
    {
      "x": -5,
      "y": 2,
      "z": -7,
      "name": "Rock_Sandstone_Cobble"
    },
    {
      "x": -5,
      "y": 3,
      "z": -7,
      "name": "Cloth_Roof_Hide_Vertical"
    },
    {
      "x": -5,
      "y": 4,
      "z": -7,
      "name": "Cloth_Roof_Hide_Vertical"
    },
    {
      "x": -5,
      "y": 5,
      "z": -7,
      "name": "Wood_Drywood_Planks",
      "rotation": 2
    },
    {
      "x": -5,
      "y": 6,
      "z": -7,
      "name": "*Cloth_Roof_Hide_State_Definitions_Corner_Right",
      "rotation": 3
    },
    {
      "x": -5,
      "y": 2,
      "z": -6,
      "name": "Rock_Sandstone_Cobble"
    },
    {
      "x": -5,
      "y": 3,
      "z": -6,
      "name": "Empty"
    },
    {
      "x": -5,
      "y": 4,
      "z": -6,
      "name": "Empty"
    },
    {
      "x": -5,
      "y": 5,
      "z": -6,
      "name": "Wood_Drywood_Planks_Half",
      "rotation": 5
    },
    {
      "x": -5,
      "y": 6,
      "z": -6,
      "name": "Cloth_Roof_Hide",
      "rotation": 3
    },
    {
      "x": -5,
      "y": 2,
      "z": -5,
      "name": "Rock_Sandstone_Cobble"
    },
    {
      "x": -5,
      "y": 3,
      "z": -5,
      "name": "Cloth_Roof_Hide_Vertical",
      "rotation": 2
    },
    {
      "x": -5,
      "y": 4,
      "z": -5,
      "name": "Cloth_Roof_Hide_Vertical",
      "rotation": 2
    },
    {
      "x": -5,
      "y": 5,
      "z": -5,
      "name": "Wood_Drywood_Planks",
      "rotation": 3
    },
    {
      "x": -5,
      "y": 6,
      "z": -5,
      "name": "*Cloth_Roof_Hide_State_Definitions_Corner_Right"
    },
    {
      "x": -5,
      "y": 2,
      "z": -4,
      "name": "Rock_Sandstone_Cobble"
    },
    {
      "x": -5,
      "y": 3,
      "z": -4,
      "name": "Cloth_Roof_Hide_Vertical",
      "rotation": 3
    },
    {
      "x": -5,
      "y": 4,
      "z": -4,
      "name": "Cloth_Roof_Hide_Vertical",
      "rotation": 3
    },
    {
      "x": -5,
      "y": 5,
      "z": -4,
      "name": "Wood_Drywood_Planks",
      "rotation": 3
    },
    {
      "x": -5,
      "y": 3,
      "z": -3,
      "name": "Cloth_Roof_Hide_Vertical",
      "rotation": 3
    },
    {
      "x": -5,
      "y": 4,
      "z": -3,
      "name": "Cloth_Roof_Hide_Vertical",
      "rotation": 3
    },
    {
      "x": -5,
      "y": 5,
      "z": -3,
      "name": "Wood_Drywood_Planks_Half",
      "rotation": 7
    },
    {
      "x": -4,
      "y": 3,
      "z": -10,
      "name": "Cloth_Roof_Hide_Vertical",
      "rotation": 2
    },
    {
      "x": -4,
      "y": 4,
      "z": -10,
      "name": "Cloth_Roof_Hide_Vertical",
      "rotation": 2
    },
    {
      "x": -4,
      "y": 5,
      "z": -10,
      "name": "Wood_Drywood_Planks_Half",
      "rotation": 6
    },
    {
      "x": -4,
      "y": 2,
      "z": -9,
      "name": "Rock_Sandstone_Cobble"
    },
    {
      "x": -4,
      "y": 3,
      "z": -9,
      "name": "Furniture_Feran_Pot"
    },
    {
      "x": -4,
      "y": 4,
      "z": -9,
      "name": "Empty"
    },
    {
      "x": -4,
      "y": 5,
      "z": -9,
      "name": "Wood_Drywood_Planks",
      "rotation": 2
    },
    {
      "x": -4,
      "y": 6,
      "z": -9,
      "name": "*Cloth_Roof_Hide_State_Definitions_Corner_Right",
      "rotation": 3
    },
    {
      "x": -4,
      "y": 2,
      "z": -8,
      "name": "Rock_Sandstone_Cobble"
    },
    {
      "x": -4,
      "y": 3,
      "z": -8,
      "name": "Furniture_Feran_Pot_Secondary"
    },
    {
      "x": -4,
      "y": 4,
      "z": -8,
      "name": "Empty"
    },
    {
      "x": -4,
      "y": 5,
      "z": -8,
      "name": "Wood_Drywood_Planks_Half",
      "rotation": 5
    },
    {
      "x": -4,
      "y": 6,
      "z": -8,
      "name": "Cloth_Roof_Hide",
      "rotation": 3
    },
    {
      "x": -4,
      "y": 2,
      "z": -7,
      "name": "Rock_Sandstone_Cobble"
    },
    {
      "x": -4,
      "y": 3,
      "z": -7,
      "name": "Empty"
    },
    {
      "x": -4,
      "y": 4,
      "z": -7,
      "name": "Empty"
    },
    {
      "x": -4,
      "y": 6,
      "z": -7,
      "name": "*Cloth_Roof_Hide_State_Definitions_Corner_Right",
      "rotation": 10
    },
    {
      "x": -4,
      "y": 2,
      "z": -6,
      "name": "Rock_Sandstone_Cobble"
    },
    {
      "x": -4,
      "y": 3,
      "z": -6,
      "name": "Empty"
    },
    {
      "x": -4,
      "y": 4,
      "z": -6,
      "name": "Empty"
    },
    {
      "x": -4,
      "y": 7,
      "z": -6,
      "name": "Cloth_Roof_Hide_Flat"
    },
    {
      "x": -4,
      "y": 2,
      "z": -5,
      "name": "Rock_Sandstone_Cobble"
    },
    {
      "x": -4,
      "y": 3,
      "z": -5,
      "name": "Empty"
    },
    {
      "x": -4,
      "y": 4,
      "z": -5,
      "name": "Empty"
    },
    {
      "x": -4,
      "y": 5,
      "z": -5,
      "name": "Empty"
    },
    {
      "x": -4,
      "y": 6,
      "z": -5,
      "name": "*Cloth_Roof_Hide_State_Definitions_Corner_Right",
      "rotation": 11
    },
    {
      "x": -4,
      "y": 2,
      "z": -4,
      "name": "Rock_Sandstone_Cobble"
    },
    {
      "x": -4,
      "y": 3,
      "z": -4,
      "name": "Empty"
    },
    {
      "x": -4,
      "y": 4,
      "z": -4,
      "name": "Empty"
    },
    {
      "x": -4,
      "y": 5,
      "z": -4,
      "name": "Wood_Drywood_Planks_Half",
      "rotation": 5
    },
    {
      "x": -4,
      "y": 6,
      "z": -4,
      "name": "Cloth_Roof_Hide",
      "rotation": 3
    },
    {
      "x": -4,
      "y": 2,
      "z": -3,
      "name": "Rock_Sandstone_Cobble"
    },
    {
      "x": -4,
      "y": 3,
      "z": -3,
      "name": "Furniture_Feran_Wardrobe",
      "rotation": 2
    },
    {
      "x": -4,
      "y": 4,
      "z": -3,
      "name": "Furniture_Feran_Wardrobe",
      "filler": 1024,
      "rotation": 2
    },
    {
      "x": -4,
      "y": 5,
      "z": -3,
      "name": "Wood_Drywood_Planks",
      "rotation": 3
    },
    {
      "x": -4,
      "y": 6,
      "z": -3,
      "name": "*Cloth_Roof_Hide_State_Definitions_Corner_Right"
    },
    {
      "x": -4,
      "y": 3,
      "z": -2,
      "name": "Cloth_Roof_Hide_Vertical"
    },
    {
      "x": -4,
      "y": 4,
      "z": -2,
      "name": "Cloth_Roof_Hide_Vertical"
    },
    {
      "x": -4,
      "y": 5,
      "z": -2,
      "name": "Wood_Drywood_Planks_Half",
      "rotation": 4
    },
    {
      "x": -3,
      "y": 5,
      "z": -11,
      "name": "Wood_Dry_Branch_Corner",
      "rotation": 8
    },
    {
      "x": -3,
      "y": 2,
      "z": -10,
      "name": "Rock_Sandstone_Cobble"
    },
    {
      "x": -3,
      "y": 3,
      "z": -10,
      "name": "Cloth_Roof_Hide_Vertical",
      "rotation": 2
    },
    {
      "x": -3,
      "y": 4,
      "z": -10,
      "name": "Cloth_Roof_Hide_Vertical",
      "rotation": 2
    },
    {
      "x": -3,
      "y": 5,
      "z": -10,
      "name": "Wood_Drywood_Planks",
      "rotation": 2
    },
    {
      "x": -3,
      "y": 2,
      "z": -9,
      "name": "Rock_Sandstone_Cobble"
    },
    {
      "x": -3,
      "y": 3,
      "z": -9,
      "name": "Empty"
    },
    {
      "x": -3,
      "y": 4,
      "z": -9,
      "name": "Empty"
    },
    {
      "x": -3,
      "y": 5,
      "z": -9,
      "name": "Wood_Drywood_Planks_Half",
      "rotation": 4
    },
    {
      "x": -3,
      "y": 6,
      "z": -9,
      "name": "Cloth_Roof_Hide",
      "rotation": 2
    },
    {
      "x": -3,
      "y": 2,
      "z": -8,
      "name": "Rock_Sandstone_Cobble"
    },
    {
      "x": -3,
      "y": 3,
      "z": -8,
      "name": "Wood_Dry_Branch_Long"
    },
    {
      "x": -3,
      "y": 4,
      "z": -8,
      "name": "Wood_Dry_Branch_Long"
    },
    {
      "x": -3,
      "y": 5,
      "z": -8,
      "name": "Wood_Dry_Branch_Long",
      "rotation": 2
    },
    {
      "x": -3,
      "y": 6,
      "z": -8,
      "name": "Wood_Dry_Branch_Long"
    },
    {
      "x": -3,
      "y": 7,
      "z": -8,
      "name": "Cloth_Roof_Hide_Flat"
    },
    {
      "x": -3,
      "y": 2,
      "z": -7,
      "name": "Rock_Sandstone_Cobble"
    },
    {
      "x": -3,
      "y": 3,
      "z": -7,
      "name": "Empty"
    },
    {
      "x": -3,
      "y": 4,
      "z": -7,
      "name": "Empty"
    },
    {
      "x": -3,
      "y": 6,
      "z": -7,
      "name": "Cloth_Roof_Hide_Flat",
      "rotation": 8
    },
    {
      "x": -3,
      "y": 7,
      "z": -7,
      "name": "*Cloth_Roof_Hide_State_Definitions_Corner_Right",
      "rotation": 3
    },
    {
      "x": -3,
      "y": 2,
      "z": -6,
      "name": "Rock_Sandstone_Cobble"
    },
    {
      "x": -3,
      "y": 3,
      "z": -6,
      "name": "Empty"
    },
    {
      "x": -3,
      "y": 4,
      "z": -6,
      "name": "Empty"
    },
    {
      "x": -3,
      "y": 6,
      "z": -6,
      "name": "Cloth_Roof_Hide_Flat",
      "rotation": 8
    },
    {
      "x": -3,
      "y": 7,
      "z": -6,
      "name": "Wood_Drywood_Planks_Half",
      "rotation": 7
    },
    {
      "x": -3,
      "y": 2,
      "z": -5,
      "name": "Rock_Sandstone_Cobble"
    },
    {
      "x": -3,
      "y": 3,
      "z": -5,
      "name": "Empty"
    },
    {
      "x": -3,
      "y": 4,
      "z": -5,
      "name": "Empty"
    },
    {
      "x": -3,
      "y": 5,
      "z": -5,
      "name": "Empty"
    },
    {
      "x": -3,
      "y": 6,
      "z": -5,
      "name": "Cloth_Roof_Hide_Flat",
      "rotation": 9
    },
    {
      "x": -3,
      "y": 7,
      "z": -5,
      "name": "*Cloth_Roof_Hide_State_Definitions_Corner_Right"
    },
    {
      "x": -3,
      "y": 2,
      "z": -4,
      "name": "Rock_Sandstone_Cobble"
    },
    {
      "x": -3,
      "y": 3,
      "z": -4,
      "name": "Wood_Dry_Branch_Long"
    },
    {
      "x": -3,
      "y": 4,
      "z": -4,
      "name": "Wood_Dry_Branch_Long"
    },
    {
      "x": -3,
      "y": 5,
      "z": -4,
      "name": "Wood_Dry_Branch_Long",
      "rotation": 3
    },
    {
      "x": -3,
      "y": 6,
      "z": -4,
      "name": "Wood_Dry_Branch_Long",
      "rotation": 1
    },
    {
      "x": -3,
      "y": 7,
      "z": -4,
      "name": "Cloth_Roof_Hide_Flat",
      "rotation": 1
    },
    {
      "x": -3,
      "y": 2,
      "z": -3,
      "name": "Rock_Sandstone_Cobble"
    },
    {
      "x": -3,
      "y": 3,
      "z": -3,
      "name": "Furniture_Feran_Wardrobe",
      "filler": 1,
      "rotation": 2
    },
    {
      "x": -3,
      "y": 4,
      "z": -3,
      "name": "Furniture_Feran_Wardrobe",
      "filler": 1025,
      "rotation": 2
    },
    {
      "x": -3,
      "y": 5,
      "z": -3,
      "name": "Wood_Drywood_Planks_Half",
      "rotation": 6
    },
    {
      "x": -3,
      "y": 6,
      "z": -3,
      "name": "Cloth_Roof_Hide"
    },
    {
      "x": -3,
      "y": 2,
      "z": -2,
      "name": "Rock_Sandstone_Cobble"
    },
    {
      "x": -3,
      "y": 3,
      "z": -2,
      "name": "Cloth_Roof_Hide_Vertical"
    },
    {
      "x": -3,
      "y": 4,
      "z": -2,
      "name": "Cloth_Roof_Hide_Vertical"
    },
    {
      "x": -3,
      "y": 5,
      "z": -2,
      "name": "Wood_Drywood_Planks",
      "rotation": 3
    },
    {
      "x": -3,
      "y": 5,
      "z": -1,
      "name": "Wood_Dry_Branch_Corner",
      "rotation": 10
    },
    {
      "x": -2,
      "y": 3,
      "z": -11,
      "name": "Cloth_Roof_Hide_Vertical",
      "rotation": 2
    },
    {
      "x": -2,
      "y": 4,
      "z": -11,
      "name": "Cloth_Roof_Hide_Vertical",
      "rotation": 2
    },
    {
      "x": -2,
      "y": 5,
      "z": -11,
      "name": "Wood_Drywood_Planks_Half",
      "rotation": 6
    },
    {
      "x": -2,
      "y": 2,
      "z": -10,
      "name": "Rock_Sandstone_Cobble"
    },
    {
      "x": -2,
      "y": 3,
      "z": -10,
      "name": "Cloth_Roof_Hide_Vertical",
      "rotation": 1
    },
    {
      "x": -2,
      "y": 4,
      "z": -10,
      "name": "Cloth_Roof_Hide_Vertical",
      "rotation": 1
    },
    {
      "x": -2,
      "y": 5,
      "z": -10,
      "name": "Wood_Drywood_Planks",
      "rotation": 2
    },
    {
      "x": -2,
      "y": 6,
      "z": -10,
      "name": "*Cloth_Roof_Hide_State_Definitions_Corner_Right",
      "rotation": 3
    },
    {
      "x": -2,
      "y": 2,
      "z": -9,
      "name": "Rock_Sandstone_Cobble"
    },
    {
      "x": -2,
      "y": 3,
      "z": -9,
      "name": "Empty"
    },
    {
      "x": -2,
      "y": 4,
      "z": -9,
      "name": "Empty"
    },
    {
      "x": -2,
      "y": 6,
      "z": -9,
      "name": "*Cloth_Roof_Hide_State_Definitions_Corner_Right",
      "rotation": 10
    },
    {
      "x": -2,
      "y": 2,
      "z": -8,
      "name": "Rock_Sandstone_Cobble"
    },
    {
      "x": -2,
      "y": 3,
      "z": -8,
      "name": "Empty"
    },
    {
      "x": -2,
      "y": 4,
      "z": -8,
      "name": "Empty"
    },
    {
      "x": -2,
      "y": 6,
      "z": -8,
      "name": "Cloth_Roof_Hide_Flat",
      "rotation": 8
    },
    {
      "x": -2,
      "y": 7,
      "z": -8,
      "name": "*Cloth_Roof_Hide_State_Definitions_Corner_Right",
      "rotation": 3
    },
    {
      "x": -2,
      "y": 2,
      "z": -7,
      "name": "Rock_Sandstone_Cobble"
    },
    {
      "x": -2,
      "y": 3,
      "z": -7,
      "name": "Empty"
    },
    {
      "x": -2,
      "y": 4,
      "z": -7,
      "name": "Empty"
    },
    {
      "x": -2,
      "y": 7,
      "z": -7,
      "name": "Wood_Drywood_Planks"
    },
    {
      "x": -2,
      "y": 2,
      "z": -6,
      "name": "Rock_Sandstone_Cobble"
    },
    {
      "x": -2,
      "y": 3,
      "z": -6,
      "name": "Furniture_Feran_Stool",
      "rotation": 2
    },
    {
      "x": -2,
      "y": 4,
      "z": -6,
      "name": "Empty"
    },
    {
      "x": -2,
      "y": 7,
      "z": -6,
      "name": "Wood_Drywood_Planks_Half",
      "rotation": 5
    },
    {
      "x": -2,
      "y": 2,
      "z": -5,
      "name": "Rock_Sandstone_Cobble"
    },
    {
      "x": -2,
      "y": 3,
      "z": -5,
      "name": "Empty"
    },
    {
      "x": -2,
      "y": 4,
      "z": -5,
      "name": "Empty"
    },
    {
      "x": -2,
      "y": 5,
      "z": -5,
      "name": "Empty"
    },
    {
      "x": -2,
      "y": 6,
      "z": -5,
      "name": "Empty"
    },
    {
      "x": -2,
      "y": 7,
      "z": -5,
      "name": "Wood_Drywood_Planks",
      "rotation": 1
    },
    {
      "x": -2,
      "y": 2,
      "z": -4,
      "name": "Rock_Sandstone_Cobble"
    },
    {
      "x": -2,
      "y": 3,
      "z": -4,
      "name": "Empty"
    },
    {
      "x": -2,
      "y": 4,
      "z": -4,
      "name": "Empty"
    },
    {
      "x": -2,
      "y": 5,
      "z": -4,
      "name": "Empty"
    },
    {
      "x": -2,
      "y": 6,
      "z": -4,
      "name": "Cloth_Roof_Hide_Flat",
      "rotation": 9
    },
    {
      "x": -2,
      "y": 7,
      "z": -4,
      "name": "*Cloth_Roof_Hide_State_Definitions_Corner_Right"
    },
    {
      "x": -2,
      "y": 2,
      "z": -3,
      "name": "Rock_Sandstone_Cobble"
    },
    {
      "x": -2,
      "y": 3,
      "z": -3,
      "name": "Furniture_Village_Pot"
    },
    {
      "x": -2,
      "y": 4,
      "z": -3,
      "name": "Empty"
    },
    {
      "x": -2,
      "y": 5,
      "z": -3,
      "name": "Empty"
    },
    {
      "x": -2,
      "y": 6,
      "z": -3,
      "name": "*Cloth_Roof_Hide_State_Definitions_Corner_Right",
      "rotation": 11
    },
    {
      "x": -2,
      "y": 2,
      "z": -2,
      "name": "Rock_Sandstone_Cobble"
    },
    {
      "x": -2,
      "y": 3,
      "z": -2,
      "name": "Cloth_Roof_Hide_Vertical",
      "rotation": 1
    },
    {
      "x": -2,
      "y": 4,
      "z": -2,
      "name": "Cloth_Roof_Hide_Vertical",
      "rotation": 1
    },
    {
      "x": -2,
      "y": 5,
      "z": -2,
      "name": "Wood_Drywood_Planks",
      "rotation": 3
    },
    {
      "x": -2,
      "y": 6,
      "z": -2,
      "name": "*Cloth_Roof_Hide_State_Definitions_Corner_Right"
    },
    {
      "x": -2,
      "y": 3,
      "z": -1,
      "name": "Cloth_Roof_Hide_Vertical"
    },
    {
      "x": -2,
      "y": 4,
      "z": -1,
      "name": "Cloth_Roof_Hide_Vertical"
    },
    {
      "x": -2,
      "y": 5,
      "z": -1,
      "name": "Wood_Drywood_Planks_Half",
      "rotation": 4
    },
    {
      "x": -1,
      "y": 4,
      "z": -11,
      "name": "Cloth_Roof_Hide_Flap",
      "rotation": 2
    },
    {
      "x": -1,
      "y": 5,
      "z": -11,
      "name": "Wood_Drywood_Planks_Half",
      "rotation": 6
    },
    {
      "x": -1,
      "y": 2,
      "z": -10,
      "name": "Rock_Sandstone_Cobble"
    },
    {
      "x": -1,
      "y": 3,
      "z": -10,
      "name": "Empty"
    },
    {
      "x": -1,
      "y": 4,
      "z": -10,
      "name": "Empty"
    },
    {
      "x": -1,
      "y": 5,
      "z": -10,
      "name": "Wood_Drywood_Planks_Half",
      "rotation": 4
    },
    {
      "x": -1,
      "y": 6,
      "z": -10,
      "name": "Cloth_Roof_Hide",
      "rotation": 2
    },
    {
      "x": -1,
      "y": 2,
      "z": -9,
      "name": "Rock_Sandstone_Cobble"
    },
    {
      "x": -1,
      "y": 3,
      "z": -9,
      "name": "Empty"
    },
    {
      "x": -1,
      "y": 4,
      "z": -9,
      "name": "Empty"
    },
    {
      "x": -1,
      "y": 7,
      "z": -9,
      "name": "Cloth_Roof_Hide_Flat",
      "rotation": 3
    },
    {
      "x": -1,
      "y": 2,
      "z": -8,
      "name": "Rock_Sandstone_Cobble"
    },
    {
      "x": -1,
      "y": 3,
      "z": -8,
      "name": "Empty"
    },
    {
      "x": -1,
      "y": 4,
      "z": -8,
      "name": "Empty"
    },
    {
      "x": -1,
      "y": 6,
      "z": -8,
      "name": "Cloth_Roof_Hide_Flat",
      "rotation": 11
    },
    {
      "x": -1,
      "y": 7,
      "z": -8,
      "name": "Wood_Drywood_Planks_Half",
      "rotation": 6
    },
    {
      "x": -1,
      "y": 2,
      "z": -7,
      "name": "Rock_Sandstone_Cobble"
    },
    {
      "x": -1,
      "y": 3,
      "z": -7,
      "name": "Empty"
    },
    {
      "x": -1,
      "y": 4,
      "z": -7,
      "name": "Empty"
    },
    {
      "x": -1,
      "y": 7,
      "z": -7,
      "name": "Wood_Drywood_Planks_Half",
      "rotation": 4
    },
    {
      "x": -1,
      "y": 2,
      "z": -6,
      "name": "Rock_Sandstone_Cobble"
    },
    {
      "x": -1,
      "y": 3,
      "z": -6,
      "name": "Empty"
    },
    {
      "x": -1,
      "y": 4,
      "z": -6,
      "name": "Empty"
    },
    {
      "x": -1,
      "y": 2,
      "z": -5,
      "name": "Rock_Sandstone_Cobble"
    },
    {
      "x": -1,
      "y": 3,
      "z": -5,
      "name": "Empty"
    },
    {
      "x": -1,
      "y": 4,
      "z": -5,
      "name": "Empty"
    },
    {
      "x": -1,
      "y": 5,
      "z": -5,
      "name": "Empty"
    },
    {
      "x": -1,
      "y": 6,
      "z": -5,
      "name": "Empty"
    },
    {
      "x": -1,
      "y": 7,
      "z": -5,
      "name": "Wood_Drywood_Planks_Half",
      "rotation": 6
    },
    {
      "x": -1,
      "y": 2,
      "z": -4,
      "name": "Rock_Sandstone_Cobble"
    },
    {
      "x": -1,
      "y": 3,
      "z": -4,
      "name": "Empty"
    },
    {
      "x": -1,
      "y": 4,
      "z": -4,
      "name": "Empty"
    },
    {
      "x": -1,
      "y": 5,
      "z": -4,
      "name": "Empty"
    },
    {
      "x": -1,
      "y": 6,
      "z": -4,
      "name": "Cloth_Roof_Hide_Flat",
      "rotation": 9
    },
    {
      "x": -1,
      "y": 7,
      "z": -4,
      "name": "Wood_Drywood_Planks_Half",
      "rotation": 4
    },
    {
      "x": -1,
      "y": 2,
      "z": -3,
      "name": "Rock_Sandstone_Cobble"
    },
    {
      "x": -1,
      "y": 3,
      "z": -3,
      "name": "Empty"
    },
    {
      "x": -1,
      "y": 4,
      "z": -3,
      "name": "Empty"
    },
    {
      "x": -1,
      "y": 5,
      "z": -3,
      "name": "Empty"
    },
    {
      "x": -1,
      "y": 6,
      "z": -3,
      "name": "Empty"
    },
    {
      "x": -1,
      "y": 7,
      "z": -3,
      "name": "Cloth_Roof_Hide_Flat",
      "rotation": 1
    },
    {
      "x": -1,
      "y": 2,
      "z": -2,
      "name": "Rock_Sandstone_Cobble"
    },
    {
      "x": -1,
      "y": 3,
      "z": -2,
      "name": "Empty"
    },
    {
      "x": -1,
      "y": 4,
      "z": -2,
      "name": "Empty"
    },
    {
      "x": -1,
      "y": 5,
      "z": -2,
      "name": "Wood_Drywood_Planks_Half",
      "rotation": 6
    },
    {
      "x": -1,
      "y": 6,
      "z": -2,
      "name": "Cloth_Roof_Hide"
    },
    {
      "x": -1,
      "y": 4,
      "z": -1,
      "name": "Cloth_Roof_Hide_Flap"
    },
    {
      "x": -1,
      "y": 5,
      "z": -1,
      "name": "Wood_Drywood_Planks_Half",
      "rotation": 4
    },
    {
      "x": 0,
      "y": 3,
      "z": -11,
      "name": "Cloth_Roof_Hide_Vertical",
      "rotation": 2
    },
    {
      "x": 0,
      "y": 4,
      "z": -11,
      "name": "Cloth_Roof_Hide_Vertical",
      "rotation": 2
    },
    {
      "x": 0,
      "y": 5,
      "z": -11,
      "name": "Wood_Drywood_Planks_Half",
      "rotation": 6
    },
    {
      "x": 0,
      "y": 2,
      "z": -10,
      "name": "Rock_Sandstone_Cobble"
    },
    {
      "x": 0,
      "y": 3,
      "z": -10,
      "name": "Cloth_Roof_Hide_Vertical",
      "rotation": 3
    },
    {
      "x": 0,
      "y": 4,
      "z": -10,
      "name": "Cloth_Roof_Hide_Vertical",
      "rotation": 3
    },
    {
      "x": 0,
      "y": 5,
      "z": -10,
      "name": "Wood_Drywood_Planks",
      "rotation": 1
    },
    {
      "x": 0,
      "y": 6,
      "z": -10,
      "name": "*Cloth_Roof_Hide_State_Definitions_Corner_Right",
      "rotation": 2
    },
    {
      "x": 0,
      "y": 2,
      "z": -9,
      "name": "Rock_Sandstone_Cobble"
    },
    {
      "x": 0,
      "y": 3,
      "z": -9,
      "name": "Furniture_Feran_Bed",
      "filler": 30,
      "rotation": 3
    },
    {
      "x": 0,
      "y": 4,
      "z": -9,
      "name": "Furniture_Feran_Bed",
      "filler": 1054,
      "rotation": 3
    },
    {
      "x": 0,
      "y": 5,
      "z": -9,
      "name": "Empty"
    },
    {
      "x": 0,
      "y": 6,
      "z": -9,
      "name": "*Cloth_Roof_Hide_State_Definitions_Corner_Right",
      "rotation": 9
    },
    {
      "x": 0,
      "y": 2,
      "z": -8,
      "name": "Rock_Sandstone_Cobble"
    },
    {
      "x": 0,
      "y": 3,
      "z": -8,
      "name": "Furniture_Feran_Bed",
      "filler": 62,
      "rotation": 3
    },
    {
      "x": 0,
      "y": 4,
      "z": -8,
      "name": "Furniture_Feran_Bed",
      "filler": 1086,
      "rotation": 3
    },
    {
      "x": 0,
      "y": 5,
      "z": -8,
      "name": "Empty"
    },
    {
      "x": 0,
      "y": 6,
      "z": -8,
      "name": "Cloth_Roof_Hide_Flat",
      "rotation": 11
    },
    {
      "x": 0,
      "y": 7,
      "z": -8,
      "name": "*Cloth_Roof_Hide_State_Definitions_Corner_Right",
      "rotation": 2
    },
    {
      "x": 0,
      "y": 2,
      "z": -7,
      "name": "Rock_Sandstone_Cobble"
    },
    {
      "x": 0,
      "y": 3,
      "z": -7,
      "name": "Empty"
    },
    {
      "x": 0,
      "y": 4,
      "z": -7,
      "name": "Empty"
    },
    {
      "x": 0,
      "y": 5,
      "z": -7,
      "name": "Empty"
    },
    {
      "x": 0,
      "y": 6,
      "z": -7,
      "name": "Empty"
    },
    {
      "x": 0,
      "y": 7,
      "z": -7,
      "name": "Wood_Drywood_Planks",
      "rotation": 3
    },
    {
      "x": 0,
      "y": 2,
      "z": -6,
      "name": "Rock_Sandstone_Cobble"
    },
    {
      "x": 0,
      "y": 3,
      "z": -6,
      "name": "Empty"
    },
    {
      "x": 0,
      "y": 4,
      "z": -6,
      "name": "Empty"
    },
    {
      "x": 0,
      "y": 5,
      "z": -6,
      "name": "Empty"
    },
    {
      "x": 0,
      "y": 6,
      "z": -6,
      "name": "Empty"
    },
    {
      "x": 0,
      "y": 7,
      "z": -6,
      "name": "Wood_Drywood_Planks_Half",
      "rotation": 7
    },
    {
      "x": 0,
      "y": 2,
      "z": -5,
      "name": "Rock_Sandstone_Cobble"
    },
    {
      "x": 0,
      "y": 3,
      "z": -5,
      "name": "Furniture_Crude_Brazier"
    },
    {
      "x": 0,
      "y": 4,
      "z": -5,
      "name": "Empty"
    },
    {
      "x": 0,
      "y": 5,
      "z": -5,
      "name": "Empty"
    },
    {
      "x": 0,
      "y": 6,
      "z": -5,
      "name": "Empty"
    },
    {
      "x": 0,
      "y": 7,
      "z": -5,
      "name": "Wood_Drywood_Planks",
      "rotation": 2
    },
    {
      "x": 0,
      "y": 2,
      "z": -4,
      "name": "Rock_Sandstone_Cobble"
    },
    {
      "x": 0,
      "y": 3,
      "z": -4,
      "name": "Empty"
    },
    {
      "x": 0,
      "y": 4,
      "z": -4,
      "name": "Empty"
    },
    {
      "x": 0,
      "y": 5,
      "z": -4,
      "name": "Empty"
    },
    {
      "x": 0,
      "y": 6,
      "z": -4,
      "name": "Cloth_Roof_Hide_Flat",
      "rotation": 10
    },
    {
      "x": 0,
      "y": 7,
      "z": -4,
      "name": "*Cloth_Roof_Hide_State_Definitions_Corner_Right",
      "rotation": 1
    },
    {
      "x": 0,
      "y": 2,
      "z": -3,
      "name": "Rock_Sandstone_Cobble"
    },
    {
      "x": 0,
      "y": 3,
      "z": -3,
      "name": "Empty"
    },
    {
      "x": 0,
      "y": 4,
      "z": -3,
      "name": "Empty"
    },
    {
      "x": 0,
      "y": 5,
      "z": -3,
      "name": "Empty"
    },
    {
      "x": 0,
      "y": 6,
      "z": -3,
      "name": "*Cloth_Roof_Hide_State_Definitions_Corner_Right",
      "rotation": 8
    },
    {
      "x": 0,
      "y": 2,
      "z": -2,
      "name": "Rock_Sandstone_Cobble"
    },
    {
      "x": 0,
      "y": 3,
      "z": -2,
      "name": "Cloth_Roof_Hide_Vertical",
      "rotation": 3
    },
    {
      "x": 0,
      "y": 4,
      "z": -2,
      "name": "Cloth_Roof_Hide_Vertical",
      "rotation": 3
    },
    {
      "x": 0,
      "y": 5,
      "z": -2,
      "name": "Wood_Drywood_Planks"
    },
    {
      "x": 0,
      "y": 6,
      "z": -2,
      "name": "*Cloth_Roof_Hide_State_Definitions_Corner_Right",
      "rotation": 1
    },
    {
      "x": 0,
      "y": 3,
      "z": -1,
      "name": "Cloth_Roof_Hide_Vertical"
    },
    {
      "x": 0,
      "y": 4,
      "z": -1,
      "name": "Cloth_Roof_Hide_Vertical"
    },
    {
      "x": 0,
      "y": 5,
      "z": -1,
      "name": "Wood_Drywood_Planks_Half",
      "rotation": 4
    },
    {
      "x": 1,
      "y": 5,
      "z": -11,
      "name": "Wood_Dry_Branch_Corner",
      "rotation": 8
    },
    {
      "x": 1,
      "y": 2,
      "z": -10,
      "name": "Rock_Sandstone_Cobble"
    },
    {
      "x": 1,
      "y": 3,
      "z": -10,
      "name": "Cloth_Roof_Hide_Vertical",
      "rotation": 2
    },
    {
      "x": 1,
      "y": 4,
      "z": -10,
      "name": "Cloth_Roof_Hide_Vertical",
      "rotation": 2
    },
    {
      "x": 1,
      "y": 5,
      "z": -10,
      "name": "Wood_Drywood_Planks",
      "rotation": 1
    },
    {
      "x": 1,
      "y": 2,
      "z": -9,
      "name": "Rock_Sandstone_Cobble"
    },
    {
      "x": 1,
      "y": 3,
      "z": -9,
      "name": "Furniture_Feran_Bed",
      "filler": 31,
      "rotation": 3
    },
    {
      "x": 1,
      "y": 4,
      "z": -9,
      "name": "Furniture_Feran_Bed",
      "filler": 1055,
      "rotation": 3
    },
    {
      "x": 1,
      "y": 5,
      "z": -9,
      "name": "Wood_Drywood_Planks_Half",
      "rotation": 4
    },
    {
      "x": 1,
      "y": 6,
      "z": -9,
      "name": "Cloth_Roof_Hide",
      "rotation": 2
    },
    {
      "x": 1,
      "y": 2,
      "z": -8,
      "name": "Rock_Sandstone_Cobble"
    },
    {
      "x": 1,
      "y": 3,
      "z": -8,
      "name": "Furniture_Feran_Bed",
      "filler": 63,
      "rotation": 3
    },
    {
      "x": 1,
      "y": 4,
      "z": -8,
      "name": "Furniture_Feran_Bed",
      "filler": 1087,
      "rotation": 3
    },
    {
      "x": 1,
      "y": 5,
      "z": -8,
      "name": "Empty"
    },
    {
      "x": 1,
      "y": 6,
      "z": -8,
      "name": "Empty"
    },
    {
      "x": 1,
      "y": 7,
      "z": -8,
      "name": "Cloth_Roof_Hide_Flat",
      "rotation": 3
    },
    {
      "x": 1,
      "y": 2,
      "z": -7,
      "name": "Rock_Sandstone_Cobble"
    },
    {
      "x": 1,
      "y": 3,
      "z": -7,
      "name": "Empty"
    },
    {
      "x": 1,
      "y": 4,
      "z": -7,
      "name": "Empty"
    },
    {
      "x": 1,
      "y": 5,
      "z": -7,
      "name": "Empty"
    },
    {
      "x": 1,
      "y": 6,
      "z": -7,
      "name": "Cloth_Roof_Hide_Flat",
      "rotation": 11
    },
    {
      "x": 1,
      "y": 7,
      "z": -7,
      "name": "*Cloth_Roof_Hide_State_Definitions_Corner_Right",
      "rotation": 2
    },
    {
      "x": 1,
      "y": 2,
      "z": -6,
      "name": "Rock_Sandstone_Cobble"
    },
    {
      "x": 1,
      "y": 3,
      "z": -6,
      "name": "Empty"
    },
    {
      "x": 1,
      "y": 4,
      "z": -6,
      "name": "Empty"
    },
    {
      "x": 1,
      "y": 5,
      "z": -6,
      "name": "Empty"
    },
    {
      "x": 1,
      "y": 6,
      "z": -6,
      "name": "Cloth_Roof_Hide_Flat",
      "rotation": 11
    },
    {
      "x": 1,
      "y": 7,
      "z": -6,
      "name": "Wood_Drywood_Planks_Half",
      "rotation": 5
    },
    {
      "x": 1,
      "y": 2,
      "z": -5,
      "name": "Rock_Sandstone_Cobble"
    },
    {
      "x": 1,
      "y": 3,
      "z": -5,
      "name": "Empty"
    },
    {
      "x": 1,
      "y": 4,
      "z": -5,
      "name": "Empty"
    },
    {
      "x": 1,
      "y": 5,
      "z": -5,
      "name": "Empty"
    },
    {
      "x": 1,
      "y": 6,
      "z": -5,
      "name": "Cloth_Roof_Hide_Flat",
      "rotation": 10
    },
    {
      "x": 1,
      "y": 7,
      "z": -5,
      "name": "*Cloth_Roof_Hide_State_Definitions_Corner_Right",
      "rotation": 1
    },
    {
      "x": 1,
      "y": 2,
      "z": -4,
      "name": "Rock_Sandstone_Cobble"
    },
    {
      "x": 1,
      "y": 3,
      "z": -4,
      "name": "Wood_Dry_Branch_Long"
    },
    {
      "x": 1,
      "y": 4,
      "z": -4,
      "name": "Wood_Dry_Branch_Long"
    },
    {
      "x": 1,
      "y": 5,
      "z": -4,
      "name": "Wood_Dry_Branch_Long"
    },
    {
      "x": 1,
      "y": 6,
      "z": -4,
      "name": "Wood_Dry_Branch_Long",
      "rotation": 2
    },
    {
      "x": 1,
      "y": 7,
      "z": -4,
      "name": "Cloth_Roof_Hide_Flat",
      "rotation": 2
    },
    {
      "x": 1,
      "y": 2,
      "z": -3,
      "name": "Rock_Sandstone_Cobble"
    },
    {
      "x": 1,
      "y": 3,
      "z": -3,
      "name": "Empty"
    },
    {
      "x": 1,
      "y": 4,
      "z": -3,
      "name": "Empty"
    },
    {
      "x": 1,
      "y": 5,
      "z": -3,
      "name": "Wood_Drywood_Planks_Half",
      "rotation": 6
    },
    {
      "x": 1,
      "y": 6,
      "z": -3,
      "name": "Cloth_Roof_Hide"
    },
    {
      "x": 1,
      "y": 2,
      "z": -2,
      "name": "Rock_Sandstone_Cobble"
    },
    {
      "x": 1,
      "y": 3,
      "z": -2,
      "name": "Cloth_Roof_Hide_Vertical"
    },
    {
      "x": 1,
      "y": 4,
      "z": -2,
      "name": "Cloth_Roof_Hide_Vertical"
    },
    {
      "x": 1,
      "y": 5,
      "z": -2,
      "name": "Wood_Drywood_Planks"
    },
    {
      "x": 1,
      "y": 5,
      "z": -1,
      "name": "Wood_Dry_Branch_Corner",
      "rotation": 10
    },
    {
      "x": 2,
      "y": 3,
      "z": -10,
      "name": "Cloth_Roof_Hide_Vertical",
      "rotation": 2
    },
    {
      "x": 2,
      "y": 4,
      "z": -10,
      "name": "Cloth_Roof_Hide_Vertical",
      "rotation": 2
    },
    {
      "x": 2,
      "y": 5,
      "z": -10,
      "name": "Wood_Drywood_Planks_Half",
      "rotation": 6
    },
    {
      "x": 2,
      "y": 2,
      "z": -9,
      "name": "Rock_Sandstone_Cobble"
    },
    {
      "x": 2,
      "y": 3,
      "z": -9,
      "name": "Furniture_Feran_Bed",
      "components": {
        "Components": {
          "PlacedByInteraction": {
            "WhoPlacedUuid": {
              "$binary": "8ANiB9W8OW235Djd8ODgjA==",
              "$type": "04"
            }
          },
          "RespawnBlock": {}
        }
      },
      "rotation": 3
    },
    {
      "x": 2,
      "y": 4,
      "z": -9,
      "name": "Furniture_Feran_Bed",
      "filler": 1024,
      "rotation": 3
    },
    {
      "x": 2,
      "y": 5,
      "z": -9,
      "name": "Wood_Drywood_Planks",
      "rotation": 1
    },
    {
      "x": 2,
      "y": 6,
      "z": -9,
      "name": "*Cloth_Roof_Hide_State_Definitions_Corner_Right",
      "rotation": 2
    },
    {
      "x": 2,
      "y": 2,
      "z": -8,
      "name": "Rock_Sandstone_Cobble"
    },
    {
      "x": 2,
      "y": 3,
      "z": -8,
      "name": "Furniture_Feran_Bed",
      "filler": 32,
      "rotation": 3
    },
    {
      "x": 2,
      "y": 4,
      "z": -8,
      "name": "Furniture_Feran_Bed",
      "filler": 1056,
      "rotation": 3
    },
    {
      "x": 2,
      "y": 5,
      "z": -8,
      "name": "Wood_Drywood_Planks_Half",
      "rotation": 7
    },
    {
      "x": 2,
      "y": 6,
      "z": -8,
      "name": "Cloth_Roof_Hide",
      "rotation": 1
    },
    {
      "x": 2,
      "y": 2,
      "z": -7,
      "name": "Rock_Sandstone_Cobble"
    },
    {
      "x": 2,
      "y": 3,
      "z": -7,
      "name": "Empty"
    },
    {
      "x": 2,
      "y": 4,
      "z": -7,
      "name": "Empty"
    },
    {
      "x": 2,
      "y": 5,
      "z": -7,
      "name": "Empty"
    },
    {
      "x": 2,
      "y": 6,
      "z": -7,
      "name": "*Cloth_Roof_Hide_State_Definitions_Corner_Right",
      "rotation": 9
    },
    {
      "x": 2,
      "y": 2,
      "z": -6,
      "name": "Rock_Sandstone_Cobble"
    },
    {
      "x": 2,
      "y": 3,
      "z": -6,
      "name": "Empty"
    },
    {
      "x": 2,
      "y": 4,
      "z": -6,
      "name": "Empty"
    },
    {
      "x": 2,
      "y": 5,
      "z": -6,
      "name": "Empty"
    },
    {
      "x": 2,
      "y": 6,
      "z": -6,
      "name": "Empty"
    },
    {
      "x": 2,
      "y": 7,
      "z": -6,
      "name": "Cloth_Roof_Hide_Flat",
      "rotation": 3
    },
    {
      "x": 2,
      "y": 2,
      "z": -5,
      "name": "Rock_Sandstone_Cobble"
    },
    {
      "x": 2,
      "y": 3,
      "z": -5,
      "name": "Empty"
    },
    {
      "x": 2,
      "y": 4,
      "z": -5,
      "name": "Empty"
    },
    {
      "x": 2,
      "y": 5,
      "z": -5,
      "name": "Empty"
    },
    {
      "x": 2,
      "y": 6,
      "z": -5,
      "name": "*Cloth_Roof_Hide_State_Definitions_Corner_Right",
      "rotation": 8
    },
    {
      "x": 2,
      "y": 2,
      "z": -4,
      "name": "Rock_Sandstone_Cobble"
    },
    {
      "x": 2,
      "y": 3,
      "z": -4,
      "name": "Empty"
    },
    {
      "x": 2,
      "y": 4,
      "z": -4,
      "name": "Empty"
    },
    {
      "x": 2,
      "y": 5,
      "z": -4,
      "name": "Wood_Drywood_Planks_Half",
      "rotation": 7
    },
    {
      "x": 2,
      "y": 6,
      "z": -4,
      "name": "Cloth_Roof_Hide",
      "rotation": 1
    },
    {
      "x": 2,
      "y": 2,
      "z": -3,
      "name": "Rock_Sandstone_Cobble"
    },
    {
      "x": 2,
      "y": 3,
      "z": -3,
      "name": "Empty"
    },
    {
      "x": 2,
      "y": 4,
      "z": -3,
      "name": "Empty"
    },
    {
      "x": 2,
      "y": 5,
      "z": -3,
      "name": "Wood_Drywood_Planks"
    },
    {
      "x": 2,
      "y": 6,
      "z": -3,
      "name": "*Cloth_Roof_Hide_State_Definitions_Corner_Right",
      "rotation": 1
    },
    {
      "x": 2,
      "y": 3,
      "z": -2,
      "name": "Cloth_Roof_Hide_Vertical"
    },
    {
      "x": 2,
      "y": 4,
      "z": -2,
      "name": "Cloth_Roof_Hide_Vertical"
    },
    {
      "x": 2,
      "y": 5,
      "z": -2,
      "name": "Wood_Drywood_Planks_Half",
      "rotation": 4
    },
    {
      "x": 3,
      "y": 3,
      "z": -9,
      "name": "Cloth_Roof_Hide_Vertical",
      "rotation": 1
    },
    {
      "x": 3,
      "y": 4,
      "z": -9,
      "name": "Cloth_Roof_Hide_Vertical",
      "rotation": 1
    },
    {
      "x": 3,
      "y": 5,
      "z": -9,
      "name": "Wood_Drywood_Planks_Half",
      "rotation": 5
    },
    {
      "x": 3,
      "y": 2,
      "z": -8,
      "name": "Rock_Sandstone_Cobble"
    },
    {
      "x": 3,
      "y": 3,
      "z": -8,
      "name": "Cloth_Roof_Hide_Vertical",
      "rotation": 1
    },
    {
      "x": 3,
      "y": 4,
      "z": -8,
      "name": "Cloth_Roof_Hide_Vertical",
      "rotation": 1
    },
    {
      "x": 3,
      "y": 5,
      "z": -8,
      "name": "Wood_Drywood_Planks",
      "rotation": 1
    },
    {
      "x": 3,
      "y": 2,
      "z": -7,
      "name": "Rock_Sandstone_Cobble"
    },
    {
      "x": 3,
      "y": 3,
      "z": -7,
      "name": "Cloth_Roof_Hide_Vertical"
    },
    {
      "x": 3,
      "y": 4,
      "z": -7,
      "name": "Cloth_Roof_Hide_Vertical"
    },
    {
      "x": 3,
      "y": 5,
      "z": -7,
      "name": "Wood_Drywood_Planks",
      "rotation": 1
    },
    {
      "x": 3,
      "y": 6,
      "z": -7,
      "name": "*Cloth_Roof_Hide_State_Definitions_Corner_Right",
      "rotation": 2
    },
    {
      "x": 3,
      "y": 2,
      "z": -6,
      "name": "Rock_Sandstone_Cobble"
    },
    {
      "x": 3,
      "y": 3,
      "z": -6,
      "name": "Empty"
    },
    {
      "x": 3,
      "y": 4,
      "z": -6,
      "name": "Empty"
    },
    {
      "x": 3,
      "y": 5,
      "z": -6,
      "name": "Wood_Drywood_Planks_Half",
      "rotation": 7
    },
    {
      "x": 3,
      "y": 6,
      "z": -6,
      "name": "Cloth_Roof_Hide",
      "rotation": 1
    },
    {
      "x": 3,
      "y": 2,
      "z": -5,
      "name": "Rock_Sandstone_Cobble"
    },
    {
      "x": 3,
      "y": 3,
      "z": -5,
      "name": "Cloth_Roof_Hide_Vertical",
      "rotation": 2
    },
    {
      "x": 3,
      "y": 4,
      "z": -5,
      "name": "Cloth_Roof_Hide_Vertical",
      "rotation": 2
    },
    {
      "x": 3,
      "y": 5,
      "z": -5,
      "name": "Wood_Drywood_Planks"
    },
    {
      "x": 3,
      "y": 6,
      "z": -5,
      "name": "*Cloth_Roof_Hide_State_Definitions_Corner_Right",
      "rotation": 1
    },
    {
      "x": 3,
      "y": 2,
      "z": -4,
      "name": "Rock_Sandstone_Cobble"
    },
    {
      "x": 3,
      "y": 3,
      "z": -4,
      "name": "Cloth_Roof_Hide_Vertical",
      "rotation": 1
    },
    {
      "x": 3,
      "y": 4,
      "z": -4,
      "name": "Cloth_Roof_Hide_Vertical",
      "rotation": 1
    },
    {
      "x": 3,
      "y": 5,
      "z": -4,
      "name": "Wood_Drywood_Planks"
    },
    {
      "x": 3,
      "y": 3,
      "z": -3,
      "name": "Cloth_Roof_Hide_Vertical",
      "rotation": 1
    },
    {
      "x": 3,
      "y": 4,
      "z": -3,
      "name": "Cloth_Roof_Hide_Vertical",
      "rotation": 1
    },
    {
      "x": 3,
      "y": 5,
      "z": -3,
      "name": "Wood_Drywood_Planks_Half",
      "rotation": 5
    },
    {
      "x": 4,
      "y": 5,
      "z": -8,
      "name": "Wood_Dry_Branch_Corner",
      "rotation": 11
    },
    {
      "x": 4,
      "y": 3,
      "z": -7,
      "name": "Cloth_Roof_Hide_Vertical",
      "rotation": 1
    },
    {
      "x": 4,
      "y": 4,
      "z": -7,
      "name": "Cloth_Roof_Hide_Vertical",
      "rotation": 1
    },
    {
      "x": 4,
      "y": 5,
      "z": -7,
      "name": "Wood_Drywood_Planks_Half",
      "rotation": 5
    },
    {
      "x": 4,
      "y": 4,
      "z": -6,
      "name": "Cloth_Roof_Hide_Flap",
      "rotation": 1
    },
    {
      "x": 4,
      "y": 5,
      "z": -6,
      "name": "Wood_Drywood_Planks_Half",
      "rotation": 5
    },
    {
      "x": 4,
      "y": 3,
      "z": -5,
      "name": "Cloth_Roof_Hide_Vertical",
      "rotation": 1
    },
    {
      "x": 4,
      "y": 4,
      "z": -5,
      "name": "Cloth_Roof_Hide_Vertical",
      "rotation": 1
    },
    {
      "x": 4,
      "y": 5,
      "z": -5,
      "name": "Wood_Drywood_Planks_Half",
      "rotation": 5
    },
    {
      "x": 4,
      "y": 5,
      "z": -4,
      "name": "Wood_Dry_Branch_Corner",
      "rotation": 11
    }
  ],
  "entities": [
    {
      "Components": {
        "Nameplate": {
          "Text": "Feran_T3"
        },
        "HiddenFromAdventurePlayer": {},
        "SpawnMarkerComponent": {
          "SpawnMarker": "Feran_T3",
          "RespawnTime": 0.0,
          "SpawnCount": 0,
          "PersistedFlock": {},
          "SpawnPosition": {
            "X": 0.0,
            "Y": 0.0,
            "Z": 0.0
          }
        },
        "Transform": {
          "Position": {
            "X": -0.9418716430664062,
            "Y": 3.0128936767578125,
            "Z": -7.398262023925781
          },
          "Rotation": {
            "Pitch": 0.0,
            "Yaw": 0.9397692680358887,
            "Roll": 0.0
          }
        },
        "Intangible": {},
        "Model": {
          "Model": {
            "Id": "NPC_Spawn_Marker",
            "Scale": 1.0,
            "Static": false
          }
        },
        "UUID": {
          "UUID": {
            "$binary": "a/CMjH7nMYelcpHGWQAHWQ==",
            "$type": "04"
          }
        }
      }
    }
  ]
}