{
  "version": 8,
  "blockIdVersion": 10,
  "anchorX": -3,
  "anchorY": 11,
  "anchorZ": -1,
  "blocks": [
    {
      "x": -16,
      "y": 35,
      "z": -5,
      "name": "Plant_Leaves_Crystal"
    },
    {
      "x": -16,
      "y": 35,
      "z": -4,
      "name": "Plant_Leaves_Crystal"
    },
    {
      "x": -16,
      "y": 35,
      "z": -3,
      "name": "Plant_Leaves_Crystal"
    },
    {
      "x": -16,
      "y": 35,
      "z": -2,
      "name": "Plant_Leaves_Crystal"
    },
    {
      "x": -15,
      "y": 34,
      "z": -6,
      "name": "Plant_Leaves_Crystal"
    },
    {
      "x": -15,
      "y": 35,
      "z": -6,
      "name": "Plant_Leaves_Crystal"
    },
    {
      "x": -15,
      "y": 35,
      "z": -5,
      "name": "Plant_Leaves_Crystal"
    },
    {
      "x": -15,
      "y": 34,
      "z": -4,
      "name": "Plant_Leaves_Crystal"
    },
    {
      "x": -15,
      "y": 35,
      "z": -4,
      "name": "Plant_Leaves_Crystal"
    },
    {
      "x": -15,
      "y": 36,
      "z": -4,
      "name": "Plant_Leaves_Crystal"
    },
    {
      "x": -15,
      "y": 35,
      "z": -3,
      "name": "Plant_Leaves_Crystal"
    },
    {
      "x": -15,
      "y": 34,
      "z": -2,
      "name": "Plant_Leaves_Crystal"
    },
    {
      "x": -15,
      "y": 35,
      "z": -2,
      "name": "Plant_Leaves_Crystal"
    },
    {
      "x": -15,
      "y": 36,
      "z": -2,
      "name": "Plant_Leaves_Crystal"
    },
    {
      "x": -15,
      "y": 34,
      "z": -1,
      "name": "Plant_Leaves_Crystal"
    },
    {
      "x": -15,
      "y": 35,
      "z": -1,
      "name": "Plant_Leaves_Crystal"
    },
    {
      "x": -15,
      "y": 35,
      "z": 0,
      "name": "Plant_Leaves_Crystal"
    },
    {
      "x": -15,
      "y": 34,
      "z": 2,
      "name": "Plant_Leaves_Crystal"
    },
    {
      "x": -15,
      "y": 35,
      "z": 2,
      "name": "Plant_Leaves_Crystal"
    },
    {
      "x": -15,
      "y": 34,
      "z": 3,
      "name": "Plant_Leaves_Crystal"
    },
    {
      "x": -14,
      "y": 34,
      "z": -6,
      "name": "Plant_Leaves_Crystal"
    },
    {
      "x": -14,
      "y": 35,
      "z": -6,
      "name": "Plant_Leaves_Crystal"
    },
    {
      "x": -14,
      "y": 34,
      "z": -5,
      "name": "Plant_Leaves_Crystal"
    },
    {
      "x": -14,
      "y": 35,
      "z": -5,
      "name": "Plant_Leaves_Crystal"
    },
    {
      "x": -14,
      "y": 35,
      "z": -4,
      "name": "Plant_Leaves_Crystal"
    },
    {
      "x": -14,
      "y": 36,
      "z": -4,
      "name": "Plant_Leaves_Crystal"
    },
    {
      "x": -14,
      "y": 34,
      "z": -3,
      "name": "Plant_Fruit_Pinkberry",
      "rotation": 8
    },
    {
      "x": -14,
      "y": 35,
      "z": -3,
      "name": "Plant_Leaves_Crystal"
    },
    {
      "x": -14,
      "y": 36,
      "z": -3,
      "name": "Plant_Leaves_Crystal"
    },
    {
      "x": -14,
      "y": 37,
      "z": -3,
      "name": "Plant_Leaves_Crystal"
    },
    {
      "x": -14,
      "y": 33,
      "z": -2,
      "name": "Plant_Fruit_Pinkberry",
      "rotation": 8
    },
    {
      "x": -14,
      "y": 34,
      "z": -2,
      "name": "Plant_Leaves_Crystal"
    },
    {
      "x": -14,
      "y": 35,
      "z": -2,
      "name": "Plant_Leaves_Crystal"
    },
    {
      "x": -14,
      "y": 36,
      "z": -2,
      "name": "Plant_Leaves_Crystal"
    },
    {
      "x": -14,
      "y": 37,
      "z": -2,
      "name": "Plant_Leaves_Crystal"
    },
    {
      "x": -14,
      "y": 34,
      "z": -1,
      "name": "Plant_Leaves_Crystal"
    },
    {
      "x": -14,
      "y": 35,
      "z": -1,
      "name": "Plant_Leaves_Crystal"
    },
    {
      "x": -14,
      "y": 36,
      "z": -1,
      "name": "Plant_Leaves_Crystal"
    },
    {
      "x": -14,
      "y": 34,
      "z": 0,
      "name": "Plant_Leaves_Crystal"
    },
    {
      "x": -14,
      "y": 35,
      "z": 0,
      "name": "Plant_Leaves_Crystal"
    },
    {
      "x": -14,
      "y": 36,
      "z": 0,
      "name": "Plant_Leaves_Crystal"
    },
    {
      "x": -14,
      "y": 33,
      "z": 1,
      "name": "Plant_Leaves_Crystal"
    },
    {
      "x": -14,
      "y": 34,
      "z": 1,
      "name": "Plant_Leaves_Crystal"
    },
    {
      "x": -14,
      "y": 35,
      "z": 1,
      "name": "Plant_Leaves_Crystal"
    },
    {
      "x": -14,
      "y": 34,
      "z": 2,
      "name": "Plant_Leaves_Crystal"
    },
    {
      "x": -14,
      "y": 35,
      "z": 2,
      "name": "Plant_Leaves_Crystal"
    },
    {
      "x": -14,
      "y": 34,
      "z": 3,
      "name": "Plant_Leaves_Crystal"
    },
    {
      "x": -14,
      "y": 34,
      "z": 4,
      "name": "Plant_Leaves_Crystal"
    },
    {
      "x": -14,
      "y": 33,
      "z": 5,
      "name": "Plant_Leaves_Crystal"
    },
    {
      "x": -14,
      "y": 34,
      "z": 5,
      "name": "Plant_Leaves_Crystal"
    },
    {
      "x": -13,
      "y": 35,
      "z": -7,
      "name": "Plant_Leaves_Crystal"
    },
    {
      "x": -13,
      "y": 35,
      "z": -6,
      "name": "Plant_Leaves_Crystal"
    },
    {
      "x": -13,
      "y": 34,
      "z": -5,
      "name": "Plant_Leaves_Crystal"
    },
    {
      "x": -13,
      "y": 35,
      "z": -5,
      "name": "Plant_Leaves_Crystal"
    },
    {
      "x": -13,
      "y": 36,
      "z": -5,
      "name": "Plant_Leaves_Crystal"
    },
    {
      "x": -13,
      "y": 34,
      "z": -4,
      "name": "Plant_Leaves_Crystal"
    },
    {
      "x": -13,
      "y": 35,
      "z": -4,
      "name": "Plant_Leaves_Crystal"
    },
    {
      "x": -13,
      "y": 36,
      "z": -4,
      "name": "Plant_Leaves_Crystal"
    },
    {
      "x": -13,
      "y": 37,
      "z": -4,
      "name": "Plant_Leaves_Crystal"
    },
    {
      "x": -13,
      "y": 35,
      "z": -3,
      "name": "Plant_Leaves_Crystal"
    },
    {
      "x": -13,
      "y": 36,
      "z": -3,
      "name": "Plant_Leaves_Crystal"
    },
    {
      "x": -13,
      "y": 37,
      "z": -3,
      "name": "Plant_Leaves_Crystal"
    },
    {
      "x": -13,
      "y": 34,
      "z": -2,
      "name": "Plant_Leaves_Crystal"
    },
    {
      "x": -13,
      "y": 35,
      "z": -2,
      "name": "Plant_Leaves_Crystal"
    },
    {
      "x": -13,
      "y": 36,
      "z": -2,
      "name": "Plant_Leaves_Crystal"
    },
    {
      "x": -13,
      "y": 37,
      "z": -2,
      "name": "Plant_Leaves_Crystal"
    },
    {
      "x": -13,
      "y": 28,
      "z": -1,
      "name": "Plant_Leaves_Crystal"
    },
    {
      "x": -13,
      "y": 35,
      "z": -1,
      "name": "Plant_Leaves_Crystal"
    },
    {
      "x": -13,
      "y": 36,
      "z": -1,
      "name": "Plant_Leaves_Crystal"
    },
    {
      "x": -13,
      "y": 28,
      "z": 0,
      "name": "Plant_Leaves_Crystal"
    },
    {
      "x": -13,
      "y": 34,
      "z": 0,
      "name": "Plant_Leaves_Crystal"
    },
    {
      "x": -13,
      "y": 35,
      "z": 0,
      "name": "Plant_Leaves_Crystal"
    },
    {
      "x": -13,
      "y": 36,
      "z": 0,
      "name": "Plant_Leaves_Crystal"
    },
    {
      "x": -13,
      "y": 39,
      "z": 0,
      "name": "Plant_Leaves_Crystal"
    },
    {
      "x": -13,
      "y": 34,
      "z": 1,
      "name": "Plant_Leaves_Crystal"
    },
    {
      "x": -13,
      "y": 35,
      "z": 1,
      "name": "Plant_Leaves_Crystal"
    },
    {
      "x": -13,
      "y": 36,
      "z": 1,
      "name": "Plant_Leaves_Crystal"
    },
    {
      "x": -13,
      "y": 38,
      "z": 1,
      "name": "Plant_Leaves_Crystal"
    },
    {
      "x": -13,
      "y": 39,
      "z": 1,
      "name": "Plant_Leaves_Crystal"
    },
    {
      "x": -13,
      "y": 33,
      "z": 2,
      "name": "Plant_Leaves_Crystal"
    },
    {
      "x": -13,
      "y": 34,
      "z": 2,
      "name": "Plant_Leaves_Crystal"
    },
    {
      "x": -13,
      "y": 35,
      "z": 2,
      "name": "Plant_Leaves_Crystal"
    },
    {
      "x": -13,
      "y": 33,
      "z": 3,
      "name": "Plant_Leaves_Crystal"
    },
    {
      "x": -13,
      "y": 34,
      "z": 3,
      "name": "Plant_Leaves_Crystal"
    },
    {
      "x": -13,
      "y": 35,
      "z": 3,
      "name": "Plant_Leaves_Crystal"
    },
    {
      "x": -13,
      "y": 34,
      "z": 4,
      "name": "Plant_Leaves_Crystal"
    },
    {
      "x": -13,
      "y": 35,
      "z": 4,
      "name": "Plant_Leaves_Crystal"
    },
    {
      "x": -13,
      "y": 34,
      "z": 5,
      "name": "Plant_Leaves_Crystal"
    },
    {
      "x": -13,
      "y": 34,
      "z": 6,
      "name": "Plant_Leaves_Crystal"
    },
    {
      "x": -12,
      "y": 35,
      "z": -9,
      "name": "Plant_Leaves_Crystal"
    },
    {
      "x": -12,
      "y": 35,
      "z": -8,
      "name": "Plant_Leaves_Crystal"
    },
    {
      "x": -12,
      "y": 35,
      "z": -7,
      "name": "Plant_Leaves_Crystal"
    },
    {
      "x": -12,
      "y": 36,
      "z": -7,
      "name": "Plant_Leaves_Crystal"
    },
    {
      "x": -12,
      "y": 34,
      "z": -6,
      "name": "Wood_Crystal_Branch_Corner",
      "rotation": 2
    },
    {
      "x": -12,
      "y": 35,
      "z": -6,
      "name": "Plant_Leaves_Crystal"
    },
    {
      "x": -12,
      "y": 36,
      "z": -6,
      "name": "Plant_Leaves_Crystal"
    },
    {
      "x": -12,
      "y": 34,
      "z": -5,
      "name": "Wood_Crystal_Branch_Long",
      "rotation": 4
    },
    {
      "x": -12,
      "y": 36,
      "z": -5,
      "name": "Plant_Leaves_Crystal"
    },
    {
      "x": -12,
      "y": 37,
      "z": -5,
      "name": "Plant_Leaves_Crystal"
    },
    {
      "x": -12,
      "y": 34,
      "z": -4,
      "name": "Wood_Crystal_Branch_Long",
      "rotation": 4
    },
    {
      "x": -12,
      "y": 35,
      "z": -4,
      "name": "Plant_Leaves_Crystal"
    },
    {
      "x": -12,
      "y": 36,
      "z": -4,
      "name": "Plant_Leaves_Crystal"
    },
    {
      "x": -12,
      "y": 37,
      "z": -4,
      "name": "Plant_Leaves_Crystal"
    },
    {
      "x": -12,
      "y": 34,
      "z": -3,
      "name": "Wood_Crystal_Trunk_Full"
    },
    {
      "x": -12,
      "y": 35,
      "z": -3,
      "name": "Plant_Leaves_Crystal"
    },
    {
      "x": -12,
      "y": 36,
      "z": -3,
      "name": "Plant_Leaves_Crystal"
    },
    {
      "x": -12,
      "y": 37,
      "z": -3,
      "name": "Plant_Leaves_Crystal"
    },
    {
      "x": -12,
      "y": 28,
      "z": -2,
      "name": "Plant_Leaves_Crystal"
    },
    {
      "x": -12,
      "y": 34,
      "z": -2,
      "name": "Plant_Leaves_Crystal"
    },
    {
      "x": -12,
      "y": 35,
      "z": -2,
      "name": "Plant_Leaves_Crystal"
    },
    {
      "x": -12,
      "y": 37,
      "z": -2,
      "name": "Plant_Leaves_Crystal"
    },
    {
      "x": -12,
      "y": 39,
      "z": -2,
      "name": "Plant_Leaves_Crystal"
    },
    {
      "x": -12,
      "y": 28,
      "z": -1,
      "name": "Plant_Leaves_Crystal"
    },
    {
      "x": -12,
      "y": 35,
      "z": -1,
      "name": "Plant_Leaves_Crystal"
    },
    {
      "x": -12,
      "y": 36,
      "z": -1,
      "name": "Plant_Leaves_Crystal"
    },
    {
      "x": -12,
      "y": 37,
      "z": -1,
      "name": "Plant_Leaves_Crystal"
    },
    {
      "x": -12,
      "y": 39,
      "z": -1,
      "name": "Plant_Leaves_Crystal"
    },
    {
      "x": -12,
      "y": 28,
      "z": 0,
      "name": "Plant_Leaves_Crystal"
    },
    {
      "x": -12,
      "y": 34,
      "z": 0,
      "name": "Plant_Leaves_Crystal"
    },
    {
      "x": -12,
      "y": 35,
      "z": 0,
      "name": "Plant_Leaves_Crystal"
    },
    {
      "x": -12,
      "y": 39,
      "z": 0,
      "name": "Plant_Leaves_Crystal"
    },
    {
      "x": -12,
      "y": 24,
      "z": 1,
      "name": "Plant_Leaves_Crystal"
    },
    {
      "x": -12,
      "y": 25,
      "z": 1,
      "name": "Plant_Leaves_Crystal"
    },
    {
      "x": -12,
      "y": 26,
      "z": 1,
      "name": "Plant_Leaves_Crystal"
    },
    {
      "x": -12,
      "y": 27,
      "z": 1,
      "name": "Plant_Leaves_Crystal"
    },
    {
      "x": -12,
      "y": 28,
      "z": 1,
      "name": "Plant_Leaves_Crystal"
    },
    {
      "x": -12,
      "y": 34,
      "z": 1,
      "name": "Plant_Leaves_Crystal"
    },
    {
      "x": -12,
      "y": 35,
      "z": 1,
      "name": "Plant_Leaves_Crystal"
    },
    {
      "x": -12,
      "y": 39,
      "z": 1,
      "name": "Plant_Leaves_Crystal"
    },
    {
      "x": -12,
      "y": 32,
      "z": 2,
      "name": "Plant_Fruit_Pinkberry",
      "rotation": 8
    },
    {
      "x": -12,
      "y": 33,
      "z": 2,
      "name": "Plant_Leaves_Crystal"
    },
    {
      "x": -12,
      "y": 34,
      "z": 2,
      "name": "Plant_Leaves_Crystal"
    },
    {
      "x": -12,
      "y": 35,
      "z": 2,
      "name": "Plant_Leaves_Crystal"
    },
    {
      "x": -12,
      "y": 39,
      "z": 2,
      "name": "Plant_Leaves_Crystal"
    },
    {
      "x": -12,
      "y": 33,
      "z": 3,
      "name": "Wood_Crystal_Branch_Corner",
      "rotation": 3
    },
    {
      "x": -12,
      "y": 34,
      "z": 3,
      "name": "Plant_Leaves_Crystal"
    },
    {
      "x": -12,
      "y": 35,
      "z": 3,
      "name": "Plant_Leaves_Crystal"
    },
    {
      "x": -12,
      "y": 39,
      "z": 3,
      "name": "Plant_Leaves_Crystal"
    },
    {
      "x": -12,
      "y": 33,
      "z": 4,
      "name": "Plant_Leaves_Crystal"
    },
    {
      "x": -12,
      "y": 34,
      "z": 4,
      "name": "Plant_Leaves_Crystal"
    },
    {
      "x": -12,
      "y": 35,
      "z": 4,
      "name": "Plant_Leaves_Crystal"
    },
    {
      "x": -12,
      "y": 36,
      "z": 4,
      "name": "Plant_Leaves_Crystal"
    },
    {
      "x": -12,
      "y": 33,
      "z": 5,
      "name": "Plant_Leaves_Crystal"
    },
    {
      "x": -12,
      "y": 34,
      "z": 5,
      "name": "Plant_Leaves_Crystal"
    },
    {
      "x": -12,
      "y": 35,
      "z": 5,
      "name": "Plant_Leaves_Crystal"
    },
    {
      "x": -12,
      "y": 34,
      "z": 6,
      "name": "Plant_Leaves_Crystal"
    },
    {
      "x": -11,
      "y": 33,
      "z": -10,
      "name": "Plant_Leaves_Crystal"
    },
    {
      "x": -11,
      "y": 34,
      "z": -10,
      "name": "Plant_Leaves_Crystal"
    },
    {
      "x": -11,
      "y": 35,
      "z": -10,
      "name": "Plant_Leaves_Crystal"
    },
    {
      "x": -11,
      "y": 34,
      "z": -9,
      "name": "Plant_Fruit_Pinkberry",
      "rotation": 8
    },
    {
      "x": -11,
      "y": 35,
      "z": -9,
      "name": "Plant_Leaves_Crystal"
    },
    {
      "x": -11,
      "y": 34,
      "z": -8,
      "name": "Plant_Leaves_Crystal"
    },
    {
      "x": -11,
      "y": 35,
      "z": -8,
      "name": "Plant_Leaves_Crystal"
    },
    {
      "x": -11,
      "y": 36,
      "z": -8,
      "name": "Plant_Leaves_Crystal"
    },
    {
      "x": -11,
      "y": 34,
      "z": -7,
      "name": "Wood_Crystal_Branch_Corner",
      "rotation": 3
    },
    {
      "x": -11,
      "y": 35,
      "z": -7,
      "name": "Plant_Leaves_Crystal"
    },
    {
      "x": -11,
      "y": 36,
      "z": -7,
      "name": "Plant_Leaves_Crystal"
    },
    {
      "x": -11,
      "y": 37,
      "z": -7,
      "name": "Plant_Leaves_Crystal"
    },
    {
      "x": -11,
      "y": 35,
      "z": -6,
      "name": "Plant_Leaves_Crystal"
    },
    {
      "x": -11,
      "y": 36,
      "z": -6,
      "name": "Plant_Leaves_Crystal"
    },
    {
      "x": -11,
      "y": 35,
      "z": -5,
      "name": "Plant_Leaves_Crystal"
    },
    {
      "x": -11,
      "y": 35,
      "z": -4,
      "name": "Plant_Leaves_Crystal"
    },
    {
      "x": -11,
      "y": 37,
      "z": -4,
      "name": "Plant_Leaves_Crystal"
    },
    {
      "x": -11,
      "y": 26,
      "z": -3,
      "name": "Plant_Leaves_Crystal"
    },
    {
      "x": -11,
      "y": 27,
      "z": -3,
      "name": "Plant_Leaves_Crystal"
    },
    {
      "x": -11,
      "y": 28,
      "z": -3,
      "name": "Plant_Leaves_Crystal"
    },
    {
      "x": -11,
      "y": 34,
      "z": -3,
      "name": "Wood_Crystal_Trunk_Full"
    },
    {
      "x": -11,
      "y": 35,
      "z": -3,
      "name": "Plant_Leaves_Crystal"
    },
    {
      "x": -11,
      "y": 36,
      "z": -3,
      "name": "Plant_Leaves_Crystal"
    },
    {
      "x": -11,
      "y": 37,
      "z": -3,
      "name": "Plant_Leaves_Crystal"
    },
    {
      "x": -11,
      "y": 39,
      "z": -3,
      "name": "Plant_Leaves_Crystal"
    },
    {
      "x": -11,
      "y": 28,
      "z": -2,
      "name": "Plant_Leaves_Crystal"
    },
    {
      "x": -11,
      "y": 34,
      "z": -2,
      "name": "Wood_Crystal_Trunk_Full"
    },
    {
      "x": -11,
      "y": 35,
      "z": -2,
      "name": "Plant_Leaves_Crystal"
    },
    {
      "x": -11,
      "y": 36,
      "z": -2,
      "name": "Plant_Leaves_Crystal"
    },
    {
      "x": -11,
      "y": 37,
      "z": -2,
      "name": "Plant_Leaves_Crystal"
    },
    {
      "x": -11,
      "y": 39,
      "z": -2,
      "name": "Plant_Leaves_Crystal"
    },
    {
      "x": -11,
      "y": 27,
      "z": -1,
      "name": "Plant_Leaves_Crystal"
    },
    {
      "x": -11,
      "y": 28,
      "z": -1,
      "name": "Plant_Leaves_Crystal"
    },
    {
      "x": -11,
      "y": 34,
      "z": -1,
      "name": "Wood_Crystal_Branch_Corner"
    },
    {
      "x": -11,
      "y": 35,
      "z": -1,
      "name": "Plant_Leaves_Crystal"
    },
    {
      "x": -11,
      "y": 36,
      "z": -1,
      "name": "Plant_Leaves_Crystal"
    },
    {
      "x": -11,
      "y": 37,
      "z": -1,
      "name": "Plant_Leaves_Crystal"
    },
    {
      "x": -11,
      "y": 39,
      "z": -1,
      "name": "Plant_Leaves_Crystal"
    },
    {
      "x": -11,
      "y": 27,
      "z": 0,
      "name": "Wood_Crystal_Branch_Corner",
      "rotation": 3
    },
    {
      "x": -11,
      "y": 28,
      "z": 0,
      "name": "Plant_Leaves_Crystal"
    },
    {
      "x": -11,
      "y": 34,
      "z": 0,
      "name": "Plant_Leaves_Crystal"
    },
    {
      "x": -11,
      "y": 35,
      "z": 0,
      "name": "Plant_Leaves_Crystal"
    },
    {
      "x": -11,
      "y": 36,
      "z": 0,
      "name": "Plant_Leaves_Crystal"
    },
    {
      "x": -11,
      "y": 37,
      "z": 0,
      "name": "Plant_Leaves_Crystal"
    },
    {
      "x": -11,
      "y": 39,
      "z": 0,
      "name": "Plant_Leaves_Crystal"
    },
    {
      "x": -11,
      "y": 28,
      "z": 1,
      "name": "Plant_Leaves_Crystal"
    },
    {
      "x": -11,
      "y": 34,
      "z": 1,
      "name": "Plant_Leaves_Crystal"
    },
    {
      "x": -11,
      "y": 38,
      "z": 1,
      "name": "Plant_Leaves_Crystal"
    },
    {
      "x": -11,
      "y": 39,
      "z": 1,
      "name": "Plant_Leaves_Crystal"
    },
    {
      "x": -11,
      "y": 33,
      "z": 2,
      "name": "Plant_Leaves_Crystal"
    },
    {
      "x": -11,
      "y": 34,
      "z": 2,
      "name": "Plant_Leaves_Crystal"
    },
    {
      "x": -11,
      "y": 35,
      "z": 2,
      "name": "Plant_Leaves_Crystal"
    },
    {
      "x": -11,
      "y": 36,
      "z": 2,
      "name": "Plant_Leaves_Crystal"
    },
    {
      "x": -11,
      "y": 33,
      "z": 3,
      "name": "Wood_Crystal_Trunk_Full"
    },
    {
      "x": -11,
      "y": 34,
      "z": 3,
      "name": "Plant_Leaves_Crystal"
    },
    {
      "x": -11,
      "y": 36,
      "z": 3,
      "name": "Plant_Leaves_Crystal"
    },
    {
      "x": -11,
      "y": 39,
      "z": 3,
      "name": "Plant_Leaves_Crystal"
    },
    {
      "x": -11,
      "y": 33,
      "z": 4,
      "name": "Wood_Crystal_Trunk_Full"
    },
    {
      "x": -11,
      "y": 34,
      "z": 4,
      "name": "Plant_Leaves_Crystal"
    },
    {
      "x": -11,
      "y": 35,
      "z": 4,
      "name": "Plant_Leaves_Crystal"
    },
    {
      "x": -11,
      "y": 36,
      "z": 4,
      "name": "Plant_Leaves_Crystal"
    },
    {
      "x": -11,
      "y": 39,
      "z": 4,
      "name": "Plant_Leaves_Crystal"
    },
    {
      "x": -11,
      "y": 33,
      "z": 5,
      "name": "Plant_Leaves_Crystal"
    },
    {
      "x": -11,
      "y": 34,
      "z": 5,
      "name": "Plant_Leaves_Crystal"
    },
    {
      "x": -11,
      "y": 35,
      "z": 5,
      "name": "Plant_Leaves_Crystal"
    },
    {
      "x": -11,
      "y": 36,
      "z": 5,
      "name": "Plant_Leaves_Crystal"
    },
    {
      "x": -11,
      "y": 33,
      "z": 6,
      "name": "Wood_Crystal_Branch_Corner",
      "rotation": 3
    },
    {
      "x": -11,
      "y": 34,
      "z": 6,
      "name": "Plant_Leaves_Crystal"
    },
    {
      "x": -11,
      "y": 35,
      "z": 6,
      "name": "Plant_Leaves_Crystal"
    },
    {
      "x": -11,
      "y": 34,
      "z": 7,
      "name": "Plant_Leaves_Crystal"
    },
    {
      "x": -10,
      "y": 35,
      "z": -10,
      "name": "Plant_Leaves_Crystal"
    },
    {
      "x": -10,
      "y": 35,
      "z": -9,
      "name": "Plant_Leaves_Crystal"
    },
    {
      "x": -10,
      "y": 36,
      "z": -9,
      "name": "Plant_Leaves_Crystal"
    },
    {
      "x": -10,
      "y": 34,
      "z": -8,
      "name": "Plant_Leaves_Crystal"
    },
    {
      "x": -10,
      "y": 35,
      "z": -8,
      "name": "Plant_Leaves_Crystal"
    },
    {
      "x": -10,
      "y": 36,
      "z": -8,
      "name": "Plant_Leaves_Crystal"
    },
    {
      "x": -10,
      "y": 37,
      "z": -8,
      "name": "Plant_Leaves_Crystal"
    },
    {
      "x": -10,
      "y": 34,
      "z": -7,
      "name": "Wood_Crystal_Trunk_Full"
    },
    {
      "x": -10,
      "y": 35,
      "z": -7,
      "name": "Plant_Leaves_Crystal"
    },
    {
      "x": -10,
      "y": 36,
      "z": -7,
      "name": "Plant_Leaves_Crystal"
    },
    {
      "x": -10,
      "y": 37,
      "z": -7,
      "name": "Plant_Leaves_Crystal"
    },
    {
      "x": -10,
      "y": 34,
      "z": -6,
      "name": "Plant_Leaves_Crystal"
    },
    {
      "x": -10,
      "y": 35,
      "z": -6,
      "name": "Plant_Leaves_Crystal"
    },
    {
      "x": -10,
      "y": 36,
      "z": -6,
      "name": "Plant_Leaves_Crystal"
    },
    {
      "x": -10,
      "y": 28,
      "z": -4,
      "name": "Plant_Leaves_Crystal"
    },
    {
      "x": -10,
      "y": 35,
      "z": -4,
      "name": "Plant_Leaves_Crystal"
    },
    {
      "x": -10,
      "y": 28,
      "z": -3,
      "name": "Plant_Leaves_Crystal"
    },
    {
      "x": -10,
      "y": 34,
      "z": -3,
      "name": "Wood_Crystal_Trunk_Full"
    },
    {
      "x": -10,
      "y": 37,
      "z": -3,
      "name": "Plant_Leaves_Crystal"
    },
    {
      "x": -10,
      "y": 27,
      "z": -2,
      "name": "Plant_Leaves_Crystal"
    },
    {
      "x": -10,
      "y": 28,
      "z": -2,
      "name": "Plant_Leaves_Crystal"
    },
    {
      "x": -10,
      "y": 35,
      "z": -2,
      "name": "Plant_Leaves_Crystal"
    },
    {
      "x": -10,
      "y": 37,
      "z": -2,
      "name": "Plant_Leaves_Crystal"
    },
    {
      "x": -10,
      "y": 39,
      "z": -2,
      "name": "Plant_Leaves_Crystal"
    },
    {
      "x": -10,
      "y": 27,
      "z": -1,
      "name": "Wood_Crystal_Branch_Long",
      "rotation": 4
    },
    {
      "x": -10,
      "y": 28,
      "z": -1,
      "name": "Plant_Leaves_Crystal"
    },
    {
      "x": -10,
      "y": 29,
      "z": -1,
      "name": "Plant_Leaves_Crystal"
    },
    {
      "x": -10,
      "y": 33,
      "z": -1,
      "name": "Wood_Crystal_Branch_Corner",
      "rotation": 2
    },
    {
      "x": -10,
      "y": 34,
      "z": -1,
      "name": "Wood_Crystal_Branch_Long"
    },
    {
      "x": -10,
      "y": 35,
      "z": -1,
      "name": "Plant_Leaves_Crystal"
    },
    {
      "x": -10,
      "y": 37,
      "z": -1,
      "name": "Plant_Leaves_Crystal"
    },
    {
      "x": -10,
      "y": 39,
      "z": -1,
      "name": "Plant_Leaves_Crystal"
    },
    {
      "x": -10,
      "y": 26,
      "z": 0,
      "name": "Wood_Crystal_Roots"
    },
    {
      "x": -10,
      "y": 27,
      "z": 0,
      "name": "Wood_Crystal_Trunk_Full"
    },
    {
      "x": -10,
      "y": 28,
      "z": 0,
      "name": "Plant_Leaves_Crystal"
    },
    {
      "x": -10,
      "y": 29,
      "z": 0,
      "name": "Plant_Leaves_Crystal"
    },
    {
      "x": -10,
      "y": 33,
      "z": 0,
      "name": "Wood_Crystal_Branch_Long",
      "rotation": 4
    },
    {
      "x": -10,
      "y": 35,
      "z": 0,
      "name": "Plant_Leaves_Crystal"
    },
    {
      "x": -10,
      "y": 39,
      "z": 0,
      "name": "Plant_Leaves_Crystal"
    },
    {
      "x": -10,
      "y": 28,
      "z": 1,
      "name": "Plant_Leaves_Crystal"
    },
    {
      "x": -10,
      "y": 33,
      "z": 1,
      "name": "Wood_Crystal_Branch_Long",
      "rotation": 4
    },
    {
      "x": -10,
      "y": 34,
      "z": 1,
      "name": "Plant_Leaves_Crystal"
    },
    {
      "x": -10,
      "y": 35,
      "z": 1,
      "name": "Plant_Leaves_Crystal"
    },
    {
      "x": -10,
      "y": 38,
      "z": 1,
      "name": "Wood_Crystal_Trunk_Full"
    },
    {
      "x": -10,
      "y": 39,
      "z": 1,
      "name": "Plant_Leaves_Crystal"
    },
    {
      "x": -10,
      "y": 27,
      "z": 2,
      "name": "Plant_Leaves_Crystal"
    },
    {
      "x": -10,
      "y": 28,
      "z": 2,
      "name": "Plant_Leaves_Crystal"
    },
    {
      "x": -10,
      "y": 33,
      "z": 2,
      "name": "Wood_Crystal_Branch_Long",
      "rotation": 4
    },
    {
      "x": -10,
      "y": 34,
      "z": 2,
      "name": "Plant_Leaves_Crystal"
    },
    {
      "x": -10,
      "y": 35,
      "z": 2,
      "name": "Plant_Leaves_Crystal"
    },
    {
      "x": -10,
      "y": 36,
      "z": 2,
      "name": "Plant_Leaves_Crystal"
    },
    {
      "x": -10,
      "y": 38,
      "z": 2,
      "name": "Plant_Leaves_Crystal"
    },
    {
      "x": -10,
      "y": 39,
      "z": 2,
      "name": "Plant_Leaves_Crystal"
    },
    {
      "x": -10,
      "y": 33,
      "z": 3,
      "name": "Wood_Crystal_Trunk_Full"
    },
    {
      "x": -10,
      "y": 34,
      "z": 3,
      "name": "Plant_Leaves_Crystal"
    },
    {
      "x": -10,
      "y": 36,
      "z": 3,
      "name": "Plant_Leaves_Crystal"
    },
    {
      "x": -10,
      "y": 39,
      "z": 3,
      "name": "Plant_Leaves_Crystal"
    },
    {
      "x": -10,
      "y": 33,
      "z": 4,
      "name": "Plant_Leaves_Crystal"
    },
    {
      "x": -10,
      "y": 34,
      "z": 4,
      "name": "Plant_Leaves_Crystal"
    },
    {
      "x": -10,
      "y": 35,
      "z": 4,
      "name": "Plant_Leaves_Crystal"
    },
    {
      "x": -10,
      "y": 37,
      "z": 4,
      "name": "Plant_Leaves_Crystal"
    },
    {
      "x": -10,
      "y": 39,
      "z": 4,
      "name": "Plant_Leaves_Crystal"
    },
    {
      "x": -10,
      "y": 34,
      "z": 5,
      "name": "Plant_Leaves_Crystal"
    },
    {
      "x": -10,
      "y": 35,
      "z": 5,
      "name": "Plant_Leaves_Crystal"
    },
    {
      "x": -10,
      "y": 33,
      "z": 6,
      "name": "Wood_Crystal_Branch_Long",
      "rotation": 5
    },
    {
      "x": -10,
      "y": 34,
      "z": 6,
      "name": "Plant_Leaves_Crystal"
    },
    {
      "x": -10,
      "y": 35,
      "z": 6,
      "name": "Plant_Leaves_Crystal"
    },
    {
      "x": -10,
      "y": 34,
      "z": 7,
      "name": "Plant_Leaves_Crystal"
    },
    {
      "x": -10,
      "y": 33,
      "z": 8,
      "name": "Plant_Leaves_Crystal"
    },
    {
      "x": -10,
      "y": 34,
      "z": 8,
      "name": "Plant_Leaves_Crystal"
    },
    {
      "x": -10,
      "y": 33,
      "z": 9,
      "name": "Plant_Leaves_Crystal"
    },
    {
      "x": -10,
      "y": 34,
      "z": 9,
      "name": "Plant_Leaves_Crystal"
    },
    {
      "x": -9,
      "y": 35,
      "z": -11,
      "name": "Plant_Leaves_Crystal"
    },
    {
      "x": -9,
      "y": 34,
      "z": -10,
      "name": "Wood_Crystal_Branch_Corner",
      "rotation": 2
    },
    {
      "x": -9,
      "y": 35,
      "z": -10,
      "name": "Plant_Leaves_Crystal"
    },
    {
      "x": -9,
      "y": 34,
      "z": -9,
      "name": "Wood_Crystal_Branch_Long",
      "rotation": 4
    },
    {
      "x": -9,
      "y": 35,
      "z": -9,
      "name": "Plant_Leaves_Crystal"
    },
    {
      "x": -9,
      "y": 36,
      "z": -9,
      "name": "Plant_Leaves_Crystal"
    },
    {
      "x": -9,
      "y": 34,
      "z": -8,
      "name": "Wood_Crystal_Branch_Long",
      "rotation": 4
    },
    {
      "x": -9,
      "y": 35,
      "z": -8,
      "name": "Plant_Leaves_Crystal"
    },
    {
      "x": -9,
      "y": 36,
      "z": -8,
      "name": "Plant_Leaves_Crystal"
    },
    {
      "x": -9,
      "y": 34,
      "z": -7,
      "name": "Wood_Crystal_Trunk_Full"
    },
    {
      "x": -9,
      "y": 35,
      "z": -7,
      "name": "Plant_Leaves_Crystal"
    },
    {
      "x": -9,
      "y": 37,
      "z": -7,
      "name": "Plant_Leaves_Crystal"
    },
    {
      "x": -9,
      "y": 34,
      "z": -6,
      "name": "Wood_Crystal_Trunk_Full"
    },
    {
      "x": -9,
      "y": 35,
      "z": -6,
      "name": "Plant_Leaves_Crystal"
    },
    {
      "x": -9,
      "y": 37,
      "z": -6,
      "name": "Plant_Leaves_Crystal"
    },
    {
      "x": -9,
      "y": 34,
      "z": -5,
      "name": "Wood_Crystal_Trunk_Full"
    },
    {
      "x": -9,
      "y": 39,
      "z": -4,
      "name": "Plant_Leaves_Crystal"
    },
    {
      "x": -9,
      "y": 27,
      "z": -3,
      "name": "Plant_Fruit_Pinkberry",
      "rotation": 8
    },
    {
      "x": -9,
      "y": 28,
      "z": -3,
      "name": "Plant_Leaves_Crystal"
    },
    {
      "x": -9,
      "y": 29,
      "z": -3,
      "name": "Plant_Leaves_Crystal"
    },
    {
      "x": -9,
      "y": 34,
      "z": -3,
      "name": "Wood_Crystal_Trunk_Full"
    },
    {
      "x": -9,
      "y": 27,
      "z": -2,
      "name": "Wood_Crystal_Branch_Corner",
      "rotation": 2
    },
    {
      "x": -9,
      "y": 28,
      "z": -2,
      "name": "Plant_Leaves_Crystal"
    },
    {
      "x": -9,
      "y": 39,
      "z": -2,
      "name": "Plant_Leaves_Crystal"
    },
    {
      "x": -9,
      "y": 27,
      "z": -1,
      "name": "Wood_Crystal_Branch_Long",
      "rotation": 4
    },
    {
      "x": -9,
      "y": 28,
      "z": -1,
      "name": "Plant_Leaves_Crystal"
    },
    {
      "x": -9,
      "y": 29,
      "z": -1,
      "name": "Plant_Leaves_Crystal"
    },
    {
      "x": -9,
      "y": 39,
      "z": -1,
      "name": "Plant_Leaves_Crystal"
    },
    {
      "x": -9,
      "y": 26,
      "z": 0,
      "name": "Wood_Crystal_Roots"
    },
    {
      "x": -9,
      "y": 27,
      "z": 0,
      "name": "Wood_Crystal_Trunk_Full"
    },
    {
      "x": -9,
      "y": 28,
      "z": 0,
      "name": "Plant_Leaves_Crystal"
    },
    {
      "x": -9,
      "y": 29,
      "z": 0,
      "name": "Plant_Leaves_Crystal"
    },
    {
      "x": -9,
      "y": 39,
      "z": 0,
      "name": "Plant_Leaves_Crystal"
    },
    {
      "x": -9,
      "y": 27,
      "z": 1,
      "name": "Plant_Leaves_Crystal"
    },
    {
      "x": -9,
      "y": 28,
      "z": 1,
      "name": "Plant_Leaves_Crystal"
    },
    {
      "x": -9,
      "y": 34,
      "z": 1,
      "name": "Plant_Leaves_Crystal"
    },
    {
      "x": -9,
      "y": 38,
      "z": 1,
      "name": "Wood_Crystal_Trunk_Full"
    },
    {
      "x": -9,
      "y": 39,
      "z": 1,
      "name": "Plant_Leaves_Crystal"
    },
    {
      "x": -9,
      "y": 28,
      "z": 2,
      "name": "Plant_Leaves_Crystal"
    },
    {
      "x": -9,
      "y": 33,
      "z": 2,
      "name": "Wood_Crystal_Trunk_Full"
    },
    {
      "x": -9,
      "y": 34,
      "z": 2,
      "name": "Plant_Leaves_Crystal"
    },
    {
      "x": -9,
      "y": 38,
      "z": 2,
      "name": "Plant_Leaves_Crystal"
    },
    {
      "x": -9,
      "y": 39,
      "z": 2,
      "name": "Plant_Leaves_Crystal"
    },
    {
      "x": -9,
      "y": 28,
      "z": 3,
      "name": "Plant_Leaves_Crystal"
    },
    {
      "x": -9,
      "y": 33,
      "z": 3,
      "name": "Wood_Crystal_Trunk_Full"
    },
    {
      "x": -9,
      "y": 36,
      "z": 3,
      "name": "Plant_Leaves_Crystal"
    },
    {
      "x": -9,
      "y": 37,
      "z": 3,
      "name": "Plant_Leaves_Crystal"
    },
    {
      "x": -9,
      "y": 38,
      "z": 3,
      "name": "Plant_Leaves_Crystal"
    },
    {
      "x": -9,
      "y": 39,
      "z": 3,
      "name": "Plant_Leaves_Crystal"
    },
    {
      "x": -9,
      "y": 36,
      "z": 4,
      "name": "Plant_Leaves_Crystal"
    },
    {
      "x": -9,
      "y": 37,
      "z": 4,
      "name": "Plant_Leaves_Crystal"
    },
    {
      "x": -9,
      "y": 39,
      "z": 4,
      "name": "Plant_Leaves_Crystal"
    },
    {
      "x": -9,
      "y": 34,
      "z": 5,
      "name": "Plant_Leaves_Crystal"
    },
    {
      "x": -9,
      "y": 36,
      "z": 5,
      "name": "Plant_Leaves_Crystal"
    },
    {
      "x": -9,
      "y": 33,
      "z": 6,
      "name": "Wood_Crystal_Branch_Long",
      "rotation": 5
    },
    {
      "x": -9,
      "y": 35,
      "z": 6,
      "name": "Plant_Leaves_Crystal"
    },
    {
      "x": -9,
      "y": 36,
      "z": 6,
      "name": "Plant_Leaves_Crystal"
    },
    {
      "x": -9,
      "y": 33,
      "z": 7,
      "name": "Plant_Leaves_Crystal"
    },
    {
      "x": -9,
      "y": 34,
      "z": 7,
      "name": "Plant_Leaves_Crystal"
    },
    {
      "x": -9,
      "y": 35,
      "z": 7,
      "name": "Plant_Leaves_Crystal"
    },
    {
      "x": -9,
      "y": 33,
      "z": 8,
      "name": "Plant_Leaves_Crystal"
    },
    {
      "x": -9,
      "y": 34,
      "z": 8,
      "name": "Plant_Leaves_Crystal"
    },
    {
      "x": -9,
      "y": 33,
      "z": 9,
      "name": "Plant_Fruit_Pinkberry"
    },
    {
      "x": -9,
      "y": 34,
      "z": 9,
      "name": "Plant_Leaves_Crystal"
    },
    {
      "x": -9,
      "y": 34,
      "z": 10,
      "name": "Plant_Leaves_Crystal"
    },
    {
      "x": -8,
      "y": 35,
      "z": -11,
      "name": "Plant_Leaves_Crystal"
    },
    {
      "x": -8,
      "y": 36,
      "z": -11,
      "name": "Plant_Leaves_Crystal"
    },
    {
      "x": -8,
      "y": 35,
      "z": -10,
      "name": "Plant_Leaves_Crystal"
    },
    {
      "x": -8,
      "y": 36,
      "z": -10,
      "name": "Plant_Leaves_Crystal"
    },
    {
      "x": -8,
      "y": 34,
      "z": -9,
      "name": "Plant_Leaves_Crystal"
    },
    {
      "x": -8,
      "y": 35,
      "z": -9,
      "name": "Plant_Leaves_Crystal"
    },
    {
      "x": -8,
      "y": 36,
      "z": -9,
      "name": "Plant_Leaves_Crystal"
    },
    {
      "x": -8,
      "y": 6,
      "z": -8,
      "name": "Wood_Crystal_Trunk"
    },
    {
      "x": -8,
      "y": 7,
      "z": -8,
      "name": "Wood_Crystal_Trunk"
    },
    {
      "x": -8,
      "y": 8,
      "z": -8,
      "name": "Wood_Crystal_Trunk"
    },
    {
      "x": -8,
      "y": 9,
      "z": -8,
      "name": "Wood_Crystal_Trunk_Full"
    },
    {
      "x": -8,
      "y": 34,
      "z": -8,
      "name": "Plant_Leaves_Crystal"
    },
    {
      "x": -8,
      "y": 35,
      "z": -8,
      "name": "Plant_Leaves_Crystal"
    },
    {
      "x": -8,
      "y": 36,
      "z": -8,
      "name": "Plant_Leaves_Crystal"
    },
    {
      "x": -8,
      "y": 6,
      "z": -7,
      "name": "Wood_Crystal_Trunk"
    },
    {
      "x": -8,
      "y": 7,
      "z": -7,
      "name": "Wood_Crystal_Trunk"
    },
    {
      "x": -8,
      "y": 8,
      "z": -7,
      "name": "Wood_Crystal_Trunk_Full"
    },
    {
      "x": -8,
      "y": 34,
      "z": -7,
      "name": "Wood_Crystal_Branch_Corner",
      "rotation": 1
    },
    {
      "x": -8,
      "y": 35,
      "z": -7,
      "name": "Plant_Leaves_Crystal"
    },
    {
      "x": -8,
      "y": 36,
      "z": -7,
      "name": "Plant_Leaves_Crystal"
    },
    {
      "x": -8,
      "y": 37,
      "z": -7,
      "name": "Plant_Leaves_Crystal"
    },
    {
      "x": -8,
      "y": 35,
      "z": -6,
      "name": "Plant_Leaves_Crystal"
    },
    {
      "x": -8,
      "y": 36,
      "z": -6,
      "name": "Plant_Leaves_Crystal"
    },
    {
      "x": -8,
      "y": 37,
      "z": -6,
      "name": "Plant_Leaves_Crystal"
    },
    {
      "x": -8,
      "y": 33,
      "z": -5,
      "name": "Wood_Crystal_Roots"
    },
    {
      "x": -8,
      "y": 34,
      "z": -5,
      "name": "Wood_Crystal_Trunk_Full"
    },
    {
      "x": -8,
      "y": 35,
      "z": -5,
      "name": "Plant_Leaves_Crystal"
    },
    {
      "x": -8,
      "y": 39,
      "z": -5,
      "name": "Plant_Leaves_Crystal"
    },
    {
      "x": -8,
      "y": 33,
      "z": -4,
      "name": "Wood_Crystal_Roots"
    },
    {
      "x": -8,
      "y": 34,
      "z": -4,
      "name": "Wood_Crystal_Trunk_Full"
    },
    {
      "x": -8,
      "y": 35,
      "z": -4,
      "name": "Plant_Leaves_Crystal"
    },
    {
      "x": -8,
      "y": 39,
      "z": -4,
      "name": "Plant_Leaves_Crystal"
    },
    {
      "x": -8,
      "y": 28,
      "z": -3,
      "name": "Plant_Leaves_Crystal"
    },
    {
      "x": -8,
      "y": 33,
      "z": -3,
      "name": "Wood_Crystal_Trunk_Full"
    },
    {
      "x": -8,
      "y": 34,
      "z": -3,
      "name": "Wood_Crystal_Trunk_Full"
    },
    {
      "x": -8,
      "y": 39,
      "z": -3,
      "name": "Plant_Leaves_Crystal"
    },
    {
      "x": -8,
      "y": 28,
      "z": -2,
      "name": "Plant_Leaves_Crystal"
    },
    {
      "x": -8,
      "y": 39,
      "z": -2,
      "name": "Plant_Leaves_Crystal"
    },
    {
      "x": -8,
      "y": 28,
      "z": -1,
      "name": "Plant_Leaves_Crystal"
    },
    {
      "x": -8,
      "y": 29,
      "z": -1,
      "name": "Plant_Leaves_Crystal"
    },
    {
      "x": -8,
      "y": 38,
      "z": -1,
      "name": "Plant_Leaves_Crystal"
    },
    {
      "x": -8,
      "y": 27,
      "z": 0,
      "name": "Wood_Crystal_Trunk_Full"
    },
    {
      "x": -8,
      "y": 28,
      "z": 0,
      "name": "Plant_Leaves_Crystal"
    },
    {
      "x": -8,
      "y": 29,
      "z": 0,
      "name": "Plant_Leaves_Crystal"
    },
    {
      "x": -8,
      "y": 39,
      "z": 0,
      "name": "Plant_Leaves_Crystal"
    },
    {
      "x": -8,
      "y": 26,
      "z": 1,
      "name": "Wood_Crystal_Roots"
    },
    {
      "x": -8,
      "y": 27,
      "z": 1,
      "name": "Wood_Crystal_Trunk_Full"
    },
    {
      "x": -8,
      "y": 28,
      "z": 1,
      "name": "Plant_Leaves_Crystal"
    },
    {
      "x": -8,
      "y": 29,
      "z": 1,
      "name": "Plant_Leaves_Crystal"
    },
    {
      "x": -8,
      "y": 38,
      "z": 1,
      "name": "Wood_Crystal_Trunk_Full"
    },
    {
      "x": -8,
      "y": 27,
      "z": 2,
      "name": "Wood_Crystal_Branch_Corner"
    },
    {
      "x": -8,
      "y": 28,
      "z": 2,
      "name": "Plant_Leaves_Crystal"
    },
    {
      "x": -8,
      "y": 29,
      "z": 2,
      "name": "Plant_Leaves_Crystal"
    },
    {
      "x": -8,
      "y": 33,
      "z": 2,
      "name": "Wood_Crystal_Trunk_Full"
    },
    {
      "x": -8,
      "y": 34,
      "z": 2,
      "name": "Plant_Leaves_Crystal"
    },
    {
      "x": -8,
      "y": 36,
      "z": 2,
      "name": "Plant_Leaves_Crystal"
    },
    {
      "x": -8,
      "y": 38,
      "z": 2,
      "name": "Wood_Crystal_Trunk_Full"
    },
    {
      "x": -8,
      "y": 39,
      "z": 2,
      "name": "Plant_Leaves_Crystal"
    },
    {
      "x": -8,
      "y": 28,
      "z": 3,
      "name": "Plant_Leaves_Crystal"
    },
    {
      "x": -8,
      "y": 36,
      "z": 3,
      "name": "Plant_Leaves_Crystal"
    },
    {
      "x": -8,
      "y": 37,
      "z": 3,
      "name": "Plant_Leaves_Crystal"
    },
    {
      "x": -8,
      "y": 38,
      "z": 3,
      "name": "Plant_Leaves_Crystal"
    },
    {
      "x": -8,
      "y": 39,
      "z": 3,
      "name": "Plant_Leaves_Crystal"
    },
    {
      "x": -8,
      "y": 34,
      "z": 4,
      "name": "Plant_Leaves_Crystal"
    },
    {
      "x": -8,
      "y": 36,
      "z": 4,
      "name": "Plant_Leaves_Crystal"
    },
    {
      "x": -8,
      "y": 38,
      "z": 4,
      "name": "Plant_Leaves_Crystal"
    },
    {
      "x": -8,
      "y": 39,
      "z": 4,
      "name": "Plant_Leaves_Crystal"
    },
    {
      "x": -8,
      "y": 34,
      "z": 5,
      "name": "Plant_Leaves_Crystal"
    },
    {
      "x": -8,
      "y": 36,
      "z": 5,
      "name": "Plant_Leaves_Crystal"
    },
    {
      "x": -8,
      "y": 39,
      "z": 5,
      "name": "Plant_Leaves_Crystal"
    },
    {
      "x": -8,
      "y": 33,
      "z": 6,
      "name": "Wood_Crystal_Branch_Long",
      "rotation": 5
    },
    {
      "x": -8,
      "y": 34,
      "z": 6,
      "name": "Plant_Leaves_Crystal"
    },
    {
      "x": -8,
      "y": 35,
      "z": 6,
      "name": "Plant_Leaves_Crystal"
    },
    {
      "x": -8,
      "y": 36,
      "z": 6,
      "name": "Plant_Leaves_Crystal"
    },
    {
      "x": -8,
      "y": 33,
      "z": 7,
      "name": "Plant_Leaves_Crystal"
    },
    {
      "x": -8,
      "y": 34,
      "z": 7,
      "name": "Plant_Leaves_Crystal"
    },
    {
      "x": -8,
      "y": 35,
      "z": 7,
      "name": "Plant_Leaves_Crystal"
    },
    {
      "x": -8,
      "y": 36,
      "z": 7,
      "name": "Plant_Leaves_Crystal"
    },
    {
      "x": -8,
      "y": 34,
      "z": 8,
      "name": "Plant_Leaves_Crystal"
    },
    {
      "x": -8,
      "y": 35,
      "z": 8,
      "name": "Plant_Leaves_Crystal"
    },
    {
      "x": -8,
      "y": 33,
      "z": 9,
      "name": "Plant_Leaves_Crystal"
    },
    {
      "x": -8,
      "y": 34,
      "z": 9,
      "name": "Plant_Leaves_Crystal"
    },
    {
      "x": -8,
      "y": 35,
      "z": 9,
      "name": "Plant_Leaves_Crystal"
    },
    {
      "x": -8,
      "y": 34,
      "z": 10,
      "name": "Plant_Leaves_Crystal"
    },
    {
      "x": -7,
      "y": 36,
      "z": -11,
      "name": "Plant_Leaves_Crystal"
    },
    {
      "x": -7,
      "y": 33,
      "z": -10,
      "name": "Plant_Leaves_Crystal"
    },
    {
      "x": -7,
      "y": 34,
      "z": -10,
      "name": "Plant_Leaves_Crystal"
    },
    {
      "x": -7,
      "y": 35,
      "z": -10,
      "name": "Plant_Leaves_Crystal"
    },
    {
      "x": -7,
      "y": 36,
      "z": -10,
      "name": "Plant_Leaves_Crystal"
    },
    {
      "x": -7,
      "y": 35,
      "z": -9,
      "name": "Plant_Leaves_Crystal"
    },
    {
      "x": -7,
      "y": 36,
      "z": -9,
      "name": "Plant_Leaves_Crystal"
    },
    {
      "x": -7,
      "y": 37,
      "z": -9,
      "name": "Plant_Leaves_Crystal"
    },
    {
      "x": -7,
      "y": 5,
      "z": -8,
      "name": "Wood_Crystal_Roots"
    },
    {
      "x": -7,
      "y": 6,
      "z": -8,
      "name": "Wood_Crystal_Trunk"
    },
    {
      "x": -7,
      "y": 7,
      "z": -8,
      "name": "Wood_Crystal_Trunk"
    },
    {
      "x": -7,
      "y": 8,
      "z": -8,
      "name": "Wood_Crystal_Trunk"
    },
    {
      "x": -7,
      "y": 9,
      "z": -8,
      "name": "Wood_Crystal_Trunk"
    },
    {
      "x": -7,
      "y": 10,
      "z": -8,
      "name": "Wood_Crystal_Trunk_Full"
    },
    {
      "x": -7,
      "y": 35,
      "z": -8,
      "name": "Plant_Leaves_Crystal"
    },
    {
      "x": -7,
      "y": 36,
      "z": -8,
      "name": "Plant_Leaves_Crystal"
    },
    {
      "x": -7,
      "y": 6,
      "z": -7,
      "name": "Wood_Crystal_Roots"
    },
    {
      "x": -7,
      "y": 7,
      "z": -7,
      "name": "Wood_Crystal_Trunk"
    },
    {
      "x": -7,
      "y": 8,
      "z": -7,
      "name": "Wood_Crystal_Trunk"
    },
    {
      "x": -7,
      "y": 9,
      "z": -7,
      "name": "Wood_Crystal_Trunk"
    },
    {
      "x": -7,
      "y": 10,
      "z": -7,
      "name": "Wood_Crystal_Trunk"
    },
    {
      "x": -7,
      "y": 11,
      "z": -7,
      "name": "Wood_Crystal_Trunk_Full"
    },
    {
      "x": -7,
      "y": 35,
      "z": -7,
      "name": "Plant_Leaves_Crystal"
    },
    {
      "x": -7,
      "y": 8,
      "z": -6,
      "name": "Wood_Crystal_Trunk"
    },
    {
      "x": -7,
      "y": 9,
      "z": -6,
      "name": "Wood_Crystal_Trunk"
    },
    {
      "x": -7,
      "y": 10,
      "z": -6,
      "name": "Wood_Crystal_Trunk"
    },
    {
      "x": -7,
      "y": 11,
      "z": -6,
      "name": "Wood_Crystal_Trunk"
    },
    {
      "x": -7,
      "y": 12,
      "z": -6,
      "name": "Wood_Crystal_Trunk_Full"
    },
    {
      "x": -7,
      "y": 35,
      "z": -6,
      "name": "Plant_Leaves_Crystal"
    },
    {
      "x": -7,
      "y": 36,
      "z": -6,
      "name": "Plant_Leaves_Crystal"
    },
    {
      "x": -7,
      "y": 8,
      "z": -5,
      "name": "Wood_Crystal_Roots"
    },
    {
      "x": -7,
      "y": 9,
      "z": -5,
      "name": "Wood_Crystal_Trunk"
    },
    {
      "x": -7,
      "y": 10,
      "z": -5,
      "name": "Wood_Crystal_Trunk"
    },
    {
      "x": -7,
      "y": 11,
      "z": -5,
      "name": "Wood_Crystal_Trunk"
    },
    {
      "x": -7,
      "y": 12,
      "z": -5,
      "name": "Wood_Crystal_Trunk"
    },
    {
      "x": -7,
      "y": 13,
      "z": -5,
      "name": "Wood_Crystal_Trunk_Full"
    },
    {
      "x": -7,
      "y": 35,
      "z": -5,
      "name": "Plant_Leaves_Crystal"
    },
    {
      "x": -7,
      "y": 39,
      "z": -5,
      "name": "Plant_Leaves_Crystal"
    },
    {
      "x": -7,
      "y": 10,
      "z": -4,
      "name": "Wood_Crystal_Trunk"
    },
    {
      "x": -7,
      "y": 11,
      "z": -4,
      "name": "Wood_Crystal_Trunk"
    },
    {
      "x": -7,
      "y": 12,
      "z": -4,
      "name": "Wood_Crystal_Trunk"
    },
    {
      "x": -7,
      "y": 13,
      "z": -4,
      "name": "Wood_Crystal_Trunk"
    },
    {
      "x": -7,
      "y": 14,
      "z": -4,
      "name": "Wood_Crystal_Trunk_Full"
    },
    {
      "x": -7,
      "y": 39,
      "z": -4,
      "name": "Plant_Leaves_Crystal"
    },
    {
      "x": -7,
      "y": 11,
      "z": -3,
      "name": "Wood_Crystal_Trunk"
    },
    {
      "x": -7,
      "y": 12,
      "z": -3,
      "name": "Wood_Crystal_Trunk"
    },
    {
      "x": -7,
      "y": 13,
      "z": -3,
      "name": "Wood_Crystal_Trunk_Full"
    },
    {
      "x": -7,
      "y": 28,
      "z": -3,
      "name": "Plant_Leaves_Crystal"
    },
    {
      "x": -7,
      "y": 32,
      "z": -3,
      "name": "Wood_Crystal_Roots"
    },
    {
      "x": -7,
      "y": 33,
      "z": -3,
      "name": "Wood_Crystal_Trunk_Full"
    },
    {
      "x": -7,
      "y": 34,
      "z": -3,
      "name": "Wood_Crystal_Trunk_Full"
    },
    {
      "x": -7,
      "y": 38,
      "z": -3,
      "name": "Plant_Leaves_Crystal"
    },
    {
      "x": -7,
      "y": 39,
      "z": -3,
      "name": "Plant_Leaves_Crystal"
    },
    {
      "x": -7,
      "y": 28,
      "z": -2,
      "name": "Plant_Leaves_Crystal"
    },
    {
      "x": -7,
      "y": 33,
      "z": -2,
      "name": "Wood_Crystal_Trunk_Full"
    },
    {
      "x": -7,
      "y": 38,
      "z": -2,
      "name": "Plant_Leaves_Crystal"
    },
    {
      "x": -7,
      "y": 39,
      "z": -2,
      "name": "Plant_Leaves_Crystal"
    },
    {
      "x": -7,
      "y": 26,
      "z": -1,
      "name": "Wood_Crystal_Trunk_Full"
    },
    {
      "x": -7,
      "y": 27,
      "z": -1,
      "name": "Wood_Crystal_Trunk_Full"
    },
    {
      "x": -7,
      "y": 38,
      "z": -1,
      "name": "Plant_Leaves_Crystal"
    },
    {
      "x": -7,
      "y": 27,
      "z": 0,
      "name": "Wood_Crystal_Trunk_Full"
    },
    {
      "x": -7,
      "y": 36,
      "z": 0,
      "name": "Wood_Crystal_Trunk_Full"
    },
    {
      "x": -7,
      "y": 37,
      "z": 0,
      "name": "Wood_Crystal_Trunk_Full"
    },
    {
      "x": -7,
      "y": 28,
      "z": 1,
      "name": "Plant_Leaves_Crystal"
    },
    {
      "x": -7,
      "y": 32,
      "z": 1,
      "name": "Wood_Crystal_Trunk_Full"
    },
    {
      "x": -7,
      "y": 33,
      "z": 1,
      "name": "Wood_Crystal_Trunk_Full"
    },
    {
      "x": -7,
      "y": 37,
      "z": 1,
      "name": "Wood_Crystal_Trunk_Full"
    },
    {
      "x": -7,
      "y": 38,
      "z": 1,
      "name": "Wood_Crystal_Trunk"
    },
    {
      "x": -7,
      "y": 39,
      "z": 1,
      "name": "Wood_Crystal_Trunk_Full"
    },
    {
      "x": -7,
      "y": 27,
      "z": 2,
      "name": "Plant_Fruit_Pinkberry",
      "rotation": 8
    },
    {
      "x": -7,
      "y": 28,
      "z": 2,
      "name": "Plant_Leaves_Crystal"
    },
    {
      "x": -7,
      "y": 32,
      "z": 2,
      "name": "Wood_Crystal_Trunk_Full"
    },
    {
      "x": -7,
      "y": 33,
      "z": 2,
      "name": "Wood_Crystal_Trunk_Full"
    },
    {
      "x": -7,
      "y": 38,
      "z": 2,
      "name": "Plant_Leaves_Crystal"
    },
    {
      "x": -7,
      "y": 39,
      "z": 2,
      "name": "Plant_Leaves_Crystal"
    },
    {
      "x": -7,
      "y": 10,
      "z": 3,
      "name": "Wood_Crystal_Trunk"
    },
    {
      "x": -7,
      "y": 11,
      "z": 3,
      "name": "Wood_Crystal_Trunk_Full"
    },
    {
      "x": -7,
      "y": 33,
      "z": 3,
      "name": "Wood_Crystal_Trunk_Full"
    },
    {
      "x": -7,
      "y": 38,
      "z": 3,
      "name": "Plant_Leaves_Crystal"
    },
    {
      "x": -7,
      "y": 39,
      "z": 3,
      "name": "Plant_Leaves_Crystal"
    },
    {
      "x": -7,
      "y": 8,
      "z": 4,
      "name": "Wood_Crystal_Trunk"
    },
    {
      "x": -7,
      "y": 9,
      "z": 4,
      "name": "Wood_Crystal_Trunk"
    },
    {
      "x": -7,
      "y": 10,
      "z": 4,
      "name": "Wood_Crystal_Trunk"
    },
    {
      "x": -7,
      "y": 11,
      "z": 4,
      "name": "Wood_Crystal_Trunk"
    },
    {
      "x": -7,
      "y": 12,
      "z": 4,
      "name": "Wood_Crystal_Trunk_Full"
    },
    {
      "x": -7,
      "y": 33,
      "z": 4,
      "name": "Wood_Crystal_Trunk_Full"
    },
    {
      "x": -7,
      "y": 36,
      "z": 4,
      "name": "Plant_Leaves_Crystal"
    },
    {
      "x": -7,
      "y": 39,
      "z": 4,
      "name": "Plant_Leaves_Crystal"
    },
    {
      "x": -7,
      "y": 6,
      "z": 5,
      "name": "Wood_Crystal_Roots"
    },
    {
      "x": -7,
      "y": 7,
      "z": 5,
      "name": "Wood_Crystal_Trunk"
    },
    {
      "x": -7,
      "y": 8,
      "z": 5,
      "name": "Wood_Crystal_Trunk"
    },
    {
      "x": -7,
      "y": 9,
      "z": 5,
      "name": "Wood_Crystal_Trunk"
    },
    {
      "x": -7,
      "y": 10,
      "z": 5,
      "name": "Wood_Crystal_Trunk"
    },
    {
      "x": -7,
      "y": 11,
      "z": 5,
      "name": "Wood_Crystal_Trunk_Full"
    },
    {
      "x": -7,
      "y": 33,
      "z": 5,
      "name": "Wood_Crystal_Trunk_Full"
    },
    {
      "x": -7,
      "y": 34,
      "z": 5,
      "name": "Plant_Leaves_Crystal"
    },
    {
      "x": -7,
      "y": 35,
      "z": 5,
      "name": "Plant_Leaves_Crystal"
    },
    {
      "x": -7,
      "y": 36,
      "z": 5,
      "name": "Plant_Leaves_Crystal"
    },
    {
      "x": -7,
      "y": 37,
      "z": 5,
      "name": "Plant_Leaves_Crystal"
    },
    {
      "x": -7,
      "y": 39,
      "z": 5,
      "name": "Plant_Leaves_Crystal"
    },
    {
      "x": -7,
      "y": 7,
      "z": 6,
      "name": "Wood_Crystal_Trunk"
    },
    {
      "x": -7,
      "y": 8,
      "z": 6,
      "name": "Wood_Crystal_Trunk"
    },
    {
      "x": -7,
      "y": 9,
      "z": 6,
      "name": "Wood_Crystal_Trunk_Full"
    },
    {
      "x": -7,
      "y": 28,
      "z": 6,
      "name": "Plant_Leaves_Crystal"
    },
    {
      "x": -7,
      "y": 33,
      "z": 6,
      "name": "Wood_Crystal_Trunk_Full"
    },
    {
      "x": -7,
      "y": 34,
      "z": 6,
      "name": "Plant_Leaves_Crystal"
    },
    {
      "x": -7,
      "y": 35,
      "z": 6,
      "name": "Plant_Leaves_Crystal"
    },
    {
      "x": -7,
      "y": 36,
      "z": 6,
      "name": "Plant_Leaves_Crystal"
    },
    {
      "x": -7,
      "y": 37,
      "z": 6,
      "name": "Plant_Leaves_Crystal"
    },
    {
      "x": -7,
      "y": 33,
      "z": 7,
      "name": "Plant_Fruit_Pinkberry"
    },
    {
      "x": -7,
      "y": 34,
      "z": 7,
      "name": "Plant_Leaves_Crystal"
    },
    {
      "x": -7,
      "y": 35,
      "z": 7,
      "name": "Plant_Leaves_Crystal"
    },
    {
      "x": -7,
      "y": 36,
      "z": 7,
      "name": "Plant_Leaves_Crystal"
    },
    {
      "x": -7,
      "y": 34,
      "z": 8,
      "name": "Plant_Leaves_Crystal"
    },
    {
      "x": -7,
      "y": 35,
      "z": 8,
      "name": "Plant_Leaves_Crystal"
    },
    {
      "x": -7,
      "y": 36,
      "z": 8,
      "name": "Plant_Leaves_Crystal"
    },
    {
      "x": -7,
      "y": 34,
      "z": 9,
      "name": "Plant_Leaves_Crystal"
    },
    {
      "x": -7,
      "y": 34,
      "z": 10,
      "name": "Plant_Leaves_Crystal"
    },
    {
      "x": -6,
      "y": 36,
      "z": -11,
      "name": "Plant_Leaves_Crystal"
    },
    {
      "x": -6,
      "y": 35,
      "z": -10,
      "name": "Plant_Leaves_Crystal"
    },
    {
      "x": -6,
      "y": 36,
      "z": -10,
      "name": "Plant_Leaves_Crystal"
    },
    {
      "x": -6,
      "y": 37,
      "z": -10,
      "name": "Plant_Leaves_Crystal"
    },
    {
      "x": -6,
      "y": 35,
      "z": -9,
      "name": "Plant_Leaves_Crystal"
    },
    {
      "x": -6,
      "y": 36,
      "z": -9,
      "name": "Plant_Leaves_Crystal"
    },
    {
      "x": -6,
      "y": 37,
      "z": -9,
      "name": "Plant_Leaves_Crystal"
    },
    {
      "x": -6,
      "y": 7,
      "z": -8,
      "name": "Wood_Crystal_Trunk"
    },
    {
      "x": -6,
      "y": 8,
      "z": -8,
      "name": "Wood_Crystal_Trunk"
    },
    {
      "x": -6,
      "y": 9,
      "z": -8,
      "name": "Wood_Crystal_Trunk"
    },
    {
      "x": -6,
      "y": 10,
      "z": -8,
      "name": "Wood_Crystal_Trunk_Full"
    },
    {
      "x": -6,
      "y": 35,
      "z": -8,
      "name": "Plant_Leaves_Crystal"
    },
    {
      "x": -6,
      "y": 36,
      "z": -8,
      "name": "Plant_Leaves_Crystal"
    },
    {
      "x": -6,
      "y": 7,
      "z": -7,
      "name": "Wood_Crystal_Trunk"
    },
    {
      "x": -6,
      "y": 8,
      "z": -7,
      "name": "Wood_Crystal_Trunk"
    },
    {
      "x": -6,
      "y": 9,
      "z": -7,
      "name": "Wood_Crystal_Trunk"
    },
    {
      "x": -6,
      "y": 10,
      "z": -7,
      "name": "Wood_Crystal_Trunk"
    },
    {
      "x": -6,
      "y": 11,
      "z": -7,
      "name": "Wood_Crystal_Trunk"
    },
    {
      "x": -6,
      "y": 12,
      "z": -7,
      "name": "Wood_Crystal_Trunk_Full"
    },
    {
      "x": -6,
      "y": 35,
      "z": -7,
      "name": "Plant_Leaves_Crystal"
    },
    {
      "x": -6,
      "y": 36,
      "z": -7,
      "name": "Plant_Leaves_Crystal"
    },
    {
      "x": -6,
      "y": 37,
      "z": -7,
      "name": "Plant_Leaves_Crystal"
    },
    {
      "x": -6,
      "y": 38,
      "z": -7,
      "name": "Plant_Leaves_Crystal"
    },
    {
      "x": -6,
      "y": 7,
      "z": -6,
      "name": "Wood_Crystal_Roots"
    },
    {
      "x": -6,
      "y": 8,
      "z": -6,
      "name": "Wood_Crystal_Trunk"
    },
    {
      "x": -6,
      "y": 9,
      "z": -6,
      "name": "Wood_Crystal_Trunk"
    },
    {
      "x": -6,
      "y": 10,
      "z": -6,
      "name": "Wood_Crystal_Trunk"
    },
    {
      "x": -6,
      "y": 11,
      "z": -6,
      "name": "Wood_Crystal_Trunk"
    },
    {
      "x": -6,
      "y": 12,
      "z": -6,
      "name": "Wood_Crystal_Trunk_Full"
    },
    {
      "x": -6,
      "y": 36,
      "z": -6,
      "name": "Plant_Leaves_Crystal"
    },
    {
      "x": -6,
      "y": 8,
      "z": -5,
      "name": "Wood_Crystal_Trunk"
    },
    {
      "x": -6,
      "y": 9,
      "z": -5,
      "name": "Wood_Crystal_Trunk"
    },
    {
      "x": -6,
      "y": 10,
      "z": -5,
      "name": "Wood_Crystal_Trunk"
    },
    {
      "x": -6,
      "y": 11,
      "z": -5,
      "name": "Wood_Crystal_Trunk"
    },
    {
      "x": -6,
      "y": 12,
      "z": -5,
      "name": "Wood_Crystal_Trunk"
    },
    {
      "x": -6,
      "y": 13,
      "z": -5,
      "name": "Wood_Crystal_Trunk_Full"
    },
    {
      "x": -6,
      "y": 39,
      "z": -5,
      "name": "Plant_Leaves_Crystal"
    },
    {
      "x": -6,
      "y": 9,
      "z": -4,
      "name": "Wood_Crystal_Roots"
    },
    {
      "x": -6,
      "y": 10,
      "z": -4,
      "name": "Wood_Crystal_Trunk"
    },
    {
      "x": -6,
      "y": 11,
      "z": -4,
      "name": "Wood_Crystal_Trunk"
    },
    {
      "x": -6,
      "y": 12,
      "z": -4,
      "name": "Wood_Crystal_Trunk"
    },
    {
      "x": -6,
      "y": 13,
      "z": -4,
      "name": "Wood_Crystal_Trunk"
    },
    {
      "x": -6,
      "y": 14,
      "z": -4,
      "name": "Wood_Crystal_Trunk"
    },
    {
      "x": -6,
      "y": 15,
      "z": -4,
      "name": "Wood_Crystal_Trunk_Full"
    },
    {
      "x": -6,
      "y": 38,
      "z": -4,
      "name": "Plant_Fruit_Pinkberry"
    },
    {
      "x": -6,
      "y": 39,
      "z": -4,
      "name": "Plant_Leaves_Crystal"
    },
    {
      "x": -6,
      "y": 10,
      "z": -3,
      "name": "Wood_Crystal_Trunk"
    },
    {
      "x": -6,
      "y": 11,
      "z": -3,
      "name": "Wood_Crystal_Trunk"
    },
    {
      "x": -6,
      "y": 12,
      "z": -3,
      "name": "Wood_Crystal_Trunk"
    },
    {
      "x": -6,
      "y": 13,
      "z": -3,
      "name": "Wood_Crystal_Trunk"
    },
    {
      "x": -6,
      "y": 14,
      "z": -3,
      "name": "Wood_Crystal_Trunk"
    },
    {
      "x": -6,
      "y": 15,
      "z": -3,
      "name": "Wood_Crystal_Trunk"
    },
    {
      "x": -6,
      "y": 16,
      "z": -3,
      "name": "Wood_Crystal_Trunk"
    },
    {
      "x": -6,
      "y": 38,
      "z": -3,
      "name": "Plant_Leaves_Crystal"
    },
    {
      "x": -6,
      "y": 39,
      "z": -3,
      "name": "Plant_Leaves_Crystal"
    },
    {
      "x": -6,
      "y": 11,
      "z": -2,
      "name": "Wood_Crystal_Trunk"
    },
    {
      "x": -6,
      "y": 12,
      "z": -2,
      "name": "Wood_Crystal_Trunk"
    },
    {
      "x": -6,
      "y": 13,
      "z": -2,
      "name": "Wood_Crystal_Trunk"
    },
    {
      "x": -6,
      "y": 14,
      "z": -2,
      "name": "Wood_Crystal_Trunk"
    },
    {
      "x": -6,
      "y": 15,
      "z": -2,
      "name": "Wood_Crystal_Trunk"
    },
    {
      "x": -6,
      "y": 16,
      "z": -2,
      "name": "Wood_Crystal_Trunk"
    },
    {
      "x": -6,
      "y": 30,
      "z": -2,
      "name": "Wood_Crystal_Trunk_Full"
    },
    {
      "x": -6,
      "y": 31,
      "z": -2,
      "name": "Wood_Crystal_Trunk"
    },
    {
      "x": -6,
      "y": 32,
      "z": -2,
      "name": "Wood_Crystal_Trunk"
    },
    {
      "x": -6,
      "y": 33,
      "z": -2,
      "name": "Wood_Crystal_Trunk_Full"
    },
    {
      "x": -6,
      "y": 37,
      "z": -2,
      "name": "Plant_Fruit_Pinkberry",
      "rotation": 8
    },
    {
      "x": -6,
      "y": 38,
      "z": -2,
      "name": "Plant_Leaves_Crystal"
    },
    {
      "x": -6,
      "y": 39,
      "z": -2,
      "name": "Plant_Leaves_Crystal"
    },
    {
      "x": -6,
      "y": 12,
      "z": -1,
      "name": "Wood_Crystal_Trunk"
    },
    {
      "x": -6,
      "y": 13,
      "z": -1,
      "name": "Wood_Crystal_Trunk"
    },
    {
      "x": -6,
      "y": 14,
      "z": -1,
      "name": "Wood_Crystal_Trunk"
    },
    {
      "x": -6,
      "y": 15,
      "z": -1,
      "name": "Wood_Crystal_Trunk"
    },
    {
      "x": -6,
      "y": 16,
      "z": -1,
      "name": "Wood_Crystal_Trunk"
    },
    {
      "x": -6,
      "y": 25,
      "z": -1,
      "name": "Wood_Crystal_Trunk_Full"
    },
    {
      "x": -6,
      "y": 26,
      "z": -1,
      "name": "Wood_Crystal_Trunk"
    },
    {
      "x": -6,
      "y": 27,
      "z": -1,
      "name": "Wood_Crystal_Trunk"
    },
    {
      "x": -6,
      "y": 28,
      "z": -1,
      "name": "Wood_Crystal_Trunk"
    },
    {
      "x": -6,
      "y": 29,
      "z": -1,
      "name": "Wood_Crystal_Trunk"
    },
    {
      "x": -6,
      "y": 30,
      "z": -1,
      "name": "Wood_Crystal_Trunk"
    },
    {
      "x": -6,
      "y": 31,
      "z": -1,
      "name": "Wood_Crystal_Trunk"
    },
    {
      "x": -6,
      "y": 32,
      "z": -1,
      "name": "Wood_Crystal_Trunk"
    },
    {
      "x": -6,
      "y": 33,
      "z": -1,
      "name": "Wood_Crystal_Trunk_Full"
    },
    {
      "x": -6,
      "y": 36,
      "z": -1,
      "name": "Wood_Crystal_Trunk_Full"
    },
    {
      "x": -6,
      "y": 38,
      "z": -1,
      "name": "Plant_Leaves_Crystal"
    },
    {
      "x": -6,
      "y": 39,
      "z": -1,
      "name": "Plant_Leaves_Crystal"
    },
    {
      "x": -6,
      "y": 13,
      "z": 0,
      "name": "Wood_Crystal_Trunk"
    },
    {
      "x": -6,
      "y": 14,
      "z": 0,
      "name": "Wood_Crystal_Trunk"
    },
    {
      "x": -6,
      "y": 15,
      "z": 0,
      "name": "Wood_Crystal_Trunk"
    },
    {
      "x": -6,
      "y": 23,
      "z": 0,
      "name": "Wood_Crystal_Trunk"
    },
    {
      "x": -6,
      "y": 24,
      "z": 0,
      "name": "Wood_Crystal_Trunk"
    },
    {
      "x": -6,
      "y": 25,
      "z": 0,
      "name": "Wood_Crystal_Trunk"
    },
    {
      "x": -6,
      "y": 26,
      "z": 0,
      "name": "Wood_Crystal_Trunk"
    },
    {
      "x": -6,
      "y": 27,
      "z": 0,
      "name": "Wood_Crystal_Trunk"
    },
    {
      "x": -6,
      "y": 28,
      "z": 0,
      "name": "Wood_Crystal_Trunk"
    },
    {
      "x": -6,
      "y": 29,
      "z": 0,
      "name": "Wood_Crystal_Trunk"
    },
    {
      "x": -6,
      "y": 30,
      "z": 0,
      "name": "Wood_Crystal_Trunk"
    },
    {
      "x": -6,
      "y": 31,
      "z": 0,
      "name": "Wood_Crystal_Trunk"
    },
    {
      "x": -6,
      "y": 32,
      "z": 0,
      "name": "Wood_Crystal_Trunk"
    },
    {
      "x": -6,
      "y": 33,
      "z": 0,
      "name": "Wood_Crystal_Trunk_Full"
    },
    {
      "x": -6,
      "y": 36,
      "z": 0,
      "name": "Wood_Crystal_Trunk_Full"
    },
    {
      "x": -6,
      "y": 39,
      "z": 0,
      "name": "Plant_Leaves_Crystal"
    },
    {
      "x": -6,
      "y": 13,
      "z": 1,
      "name": "Wood_Crystal_Trunk"
    },
    {
      "x": -6,
      "y": 14,
      "z": 1,
      "name": "Wood_Crystal_Trunk"
    },
    {
      "x": -6,
      "y": 15,
      "z": 1,
      "name": "Wood_Crystal_Trunk"
    },
    {
      "x": -6,
      "y": 16,
      "z": 1,
      "name": "Wood_Crystal_Trunk"
    },
    {
      "x": -6,
      "y": 17,
      "z": 1,
      "name": "Wood_Crystal_Trunk"
    },
    {
      "x": -6,
      "y": 32,
      "z": 1,
      "name": "Wood_Crystal_Trunk_Full"
    },
    {
      "x": -6,
      "y": 38,
      "z": 1,
      "name": "Plant_Leaves_Crystal"
    },
    {
      "x": -6,
      "y": 12,
      "z": 2,
      "name": "Wood_Crystal_Trunk"
    },
    {
      "x": -6,
      "y": 13,
      "z": 2,
      "name": "Wood_Crystal_Trunk"
    },
    {
      "x": -6,
      "y": 14,
      "z": 2,
      "name": "Wood_Crystal_Trunk"
    },
    {
      "x": -6,
      "y": 15,
      "z": 2,
      "name": "Wood_Crystal_Trunk"
    },
    {
      "x": -6,
      "y": 16,
      "z": 2,
      "name": "Wood_Crystal_Trunk"
    },
    {
      "x": -6,
      "y": 17,
      "z": 2,
      "name": "Wood_Crystal_Trunk"
    },
    {
      "x": -6,
      "y": 18,
      "z": 2,
      "name": "Wood_Crystal_Trunk"
    },
    {
      "x": -6,
      "y": 19,
      "z": 2,
      "name": "Wood_Crystal_Trunk_Full"
    },
    {
      "x": -6,
      "y": 38,
      "z": 2,
      "name": "Plant_Leaves_Crystal"
    },
    {
      "x": -6,
      "y": 39,
      "z": 2,
      "name": "Plant_Leaves_Crystal"
    },
    {
      "x": -6,
      "y": 9,
      "z": 3,
      "name": "Wood_Crystal_Trunk"
    },
    {
      "x": -6,
      "y": 10,
      "z": 3,
      "name": "Wood_Crystal_Trunk"
    },
    {
      "x": -6,
      "y": 11,
      "z": 3,
      "name": "Wood_Crystal_Trunk"
    },
    {
      "x": -6,
      "y": 12,
      "z": 3,
      "name": "Wood_Crystal_Trunk"
    },
    {
      "x": -6,
      "y": 13,
      "z": 3,
      "name": "Wood_Crystal_Trunk"
    },
    {
      "x": -6,
      "y": 14,
      "z": 3,
      "name": "Wood_Crystal_Trunk"
    },
    {
      "x": -6,
      "y": 15,
      "z": 3,
      "name": "Wood_Crystal_Trunk"
    },
    {
      "x": -6,
      "y": 16,
      "z": 3,
      "name": "Wood_Crystal_Trunk"
    },
    {
      "x": -6,
      "y": 17,
      "z": 3,
      "name": "Wood_Crystal_Trunk"
    },
    {
      "x": -6,
      "y": 18,
      "z": 3,
      "name": "Wood_Crystal_Trunk"
    },
    {
      "x": -6,
      "y": 19,
      "z": 3,
      "name": "Wood_Crystal_Trunk"
    },
    {
      "x": -6,
      "y": 20,
      "z": 3,
      "name": "Wood_Crystal_Trunk_Full"
    },
    {
      "x": -6,
      "y": 28,
      "z": 3,
      "name": "Plant_Leaves_Crystal"
    },
    {
      "x": -6,
      "y": 38,
      "z": 3,
      "name": "Plant_Leaves_Crystal"
    },
    {
      "x": -6,
      "y": 7,
      "z": 4,
      "name": "Wood_Crystal_Roots"
    },
    {
      "x": -6,
      "y": 8,
      "z": 4,
      "name": "Wood_Crystal_Trunk"
    },
    {
      "x": -6,
      "y": 9,
      "z": 4,
      "name": "Wood_Crystal_Trunk"
    },
    {
      "x": -6,
      "y": 10,
      "z": 4,
      "name": "Wood_Crystal_Trunk"
    },
    {
      "x": -6,
      "y": 11,
      "z": 4,
      "name": "Wood_Crystal_Trunk"
    },
    {
      "x": -6,
      "y": 12,
      "z": 4,
      "name": "Wood_Crystal_Trunk"
    },
    {
      "x": -6,
      "y": 13,
      "z": 4,
      "name": "Wood_Crystal_Trunk"
    },
    {
      "x": -6,
      "y": 14,
      "z": 4,
      "name": "Wood_Crystal_Trunk"
    },
    {
      "x": -6,
      "y": 15,
      "z": 4,
      "name": "Wood_Crystal_Trunk_Full"
    },
    {
      "x": -6,
      "y": 28,
      "z": 4,
      "name": "Plant_Leaves_Crystal"
    },
    {
      "x": -6,
      "y": 34,
      "z": 4,
      "name": "Plant_Leaves_Crystal"
    },
    {
      "x": -6,
      "y": 36,
      "z": 4,
      "name": "Plant_Leaves_Crystal"
    },
    {
      "x": -6,
      "y": 39,
      "z": 4,
      "name": "Plant_Leaves_Crystal"
    },
    {
      "x": -6,
      "y": 7,
      "z": 5,
      "name": "Wood_Crystal_Roots"
    },
    {
      "x": -6,
      "y": 8,
      "z": 5,
      "name": "Wood_Crystal_Trunk"
    },
    {
      "x": -6,
      "y": 9,
      "z": 5,
      "name": "Wood_Crystal_Trunk"
    },
    {
      "x": -6,
      "y": 10,
      "z": 5,
      "name": "Wood_Crystal_Trunk"
    },
    {
      "x": -6,
      "y": 11,
      "z": 5,
      "name": "Wood_Crystal_Trunk"
    },
    {
      "x": -6,
      "y": 12,
      "z": 5,
      "name": "Wood_Crystal_Trunk"
    },
    {
      "x": -6,
      "y": 13,
      "z": 5,
      "name": "Wood_Crystal_Trunk"
    },
    {
      "x": -6,
      "y": 14,
      "z": 5,
      "name": "Wood_Crystal_Trunk_Full"
    },
    {
      "x": -6,
      "y": 28,
      "z": 5,
      "name": "Plant_Leaves_Crystal"
    },
    {
      "x": -6,
      "y": 29,
      "z": 5,
      "name": "Plant_Leaves_Crystal"
    },
    {
      "x": -6,
      "y": 33,
      "z": 5,
      "name": "Wood_Crystal_Trunk_Full"
    },
    {
      "x": -6,
      "y": 34,
      "z": 5,
      "name": "Plant_Leaves_Crystal"
    },
    {
      "x": -6,
      "y": 35,
      "z": 5,
      "name": "Plant_Leaves_Crystal"
    },
    {
      "x": -6,
      "y": 36,
      "z": 5,
      "name": "Plant_Leaves_Crystal"
    },
    {
      "x": -6,
      "y": 37,
      "z": 5,
      "name": "Plant_Leaves_Crystal"
    },
    {
      "x": -6,
      "y": 39,
      "z": 5,
      "name": "Plant_Leaves_Crystal"
    },
    {
      "x": -6,
      "y": 7,
      "z": 6,
      "name": "Wood_Crystal_Trunk"
    },
    {
      "x": -6,
      "y": 8,
      "z": 6,
      "name": "Wood_Crystal_Trunk"
    },
    {
      "x": -6,
      "y": 9,
      "z": 6,
      "name": "Wood_Crystal_Trunk"
    },
    {
      "x": -6,
      "y": 10,
      "z": 6,
      "name": "Wood_Crystal_Trunk_Full"
    },
    {
      "x": -6,
      "y": 28,
      "z": 6,
      "name": "Plant_Leaves_Crystal"
    },
    {
      "x": -6,
      "y": 33,
      "z": 6,
      "name": "Wood_Crystal_Branch_Long",
      "rotation": 5
    },
    {
      "x": -6,
      "y": 34,
      "z": 6,
      "name": "Plant_Leaves_Crystal"
    },
    {
      "x": -6,
      "y": 36,
      "z": 6,
      "name": "Plant_Leaves_Crystal"
    },
    {
      "x": -6,
      "y": 27,
      "z": 7,
      "name": "Plant_Leaves_Crystal"
    },
    {
      "x": -6,
      "y": 28,
      "z": 7,
      "name": "Plant_Leaves_Crystal"
    },
    {
      "x": -6,
      "y": 33,
      "z": 7,
      "name": "Plant_Leaves_Crystal"
    },
    {
      "x": -6,
      "y": 34,
      "z": 7,
      "name": "Plant_Leaves_Crystal"
    },
    {
      "x": -6,
      "y": 35,
      "z": 7,
      "name": "Plant_Leaves_Crystal"
    },
    {
      "x": -6,
      "y": 36,
      "z": 7,
      "name": "Plant_Leaves_Crystal"
    },
    {
      "x": -6,
      "y": 32,
      "z": 8,
      "name": "Plant_Fruit_Pinkberry",
      "rotation": 8
    },
    {
      "x": -6,
      "y": 33,
      "z": 8,
      "name": "Plant_Leaves_Crystal"
    },
    {
      "x": -6,
      "y": 34,
      "z": 8,
      "name": "Plant_Leaves_Crystal"
    },
    {
      "x": -6,
      "y": 35,
      "z": 8,
      "name": "Plant_Leaves_Crystal"
    },
    {
      "x": -6,
      "y": 36,
      "z": 8,
      "name": "Plant_Leaves_Crystal"
    },
    {
      "x": -6,
      "y": 33,
      "z": 9,
      "name": "Plant_Leaves_Crystal"
    },
    {
      "x": -6,
      "y": 34,
      "z": 9,
      "name": "Plant_Leaves_Crystal"
    },
    {
      "x": -6,
      "y": 35,
      "z": 9,
      "name": "Plant_Leaves_Crystal"
    },
    {
      "x": -6,
      "y": 34,
      "z": 10,
      "name": "Plant_Leaves_Crystal"
    },
    {
      "x": -5,
      "y": 35,
      "z": -11,
      "name": "Plant_Leaves_Crystal"
    },
    {
      "x": -5,
      "y": 36,
      "z": -11,
      "name": "Plant_Leaves_Crystal"
    },
    {
      "x": -5,
      "y": 35,
      "z": -10,
      "name": "Plant_Leaves_Crystal"
    },
    {
      "x": -5,
      "y": 36,
      "z": -10,
      "name": "Plant_Leaves_Crystal"
    },
    {
      "x": -5,
      "y": 37,
      "z": -10,
      "name": "Plant_Leaves_Crystal"
    },
    {
      "x": -5,
      "y": 36,
      "z": -9,
      "name": "Plant_Leaves_Crystal"
    },
    {
      "x": -5,
      "y": 37,
      "z": -9,
      "name": "Plant_Leaves_Crystal"
    },
    {
      "x": -5,
      "y": 35,
      "z": -8,
      "name": "Plant_Fruit_Pinkberry",
      "rotation": 8
    },
    {
      "x": -5,
      "y": 36,
      "z": -8,
      "name": "Plant_Leaves_Crystal"
    },
    {
      "x": -5,
      "y": 37,
      "z": -8,
      "name": "Plant_Leaves_Crystal"
    },
    {
      "x": -5,
      "y": 38,
      "z": -8,
      "name": "Plant_Leaves_Crystal"
    },
    {
      "x": -5,
      "y": 8,
      "z": -7,
      "name": "Wood_Crystal_Trunk"
    },
    {
      "x": -5,
      "y": 9,
      "z": -7,
      "name": "Wood_Crystal_Trunk"
    },
    {
      "x": -5,
      "y": 10,
      "z": -7,
      "name": "Wood_Crystal_Trunk"
    },
    {
      "x": -5,
      "y": 11,
      "z": -7,
      "name": "Wood_Crystal_Trunk"
    },
    {
      "x": -5,
      "y": 12,
      "z": -7,
      "name": "Wood_Crystal_Trunk_Full"
    },
    {
      "x": -5,
      "y": 35,
      "z": -7,
      "name": "Wood_Crystal_Branch_Corner",
      "rotation": 3
    },
    {
      "x": -5,
      "y": 36,
      "z": -7,
      "name": "Plant_Leaves_Crystal"
    },
    {
      "x": -5,
      "y": 37,
      "z": -7,
      "name": "Plant_Leaves_Crystal"
    },
    {
      "x": -5,
      "y": 38,
      "z": -7,
      "name": "Plant_Leaves_Crystal"
    },
    {
      "x": -5,
      "y": 8,
      "z": -6,
      "name": "Wood_Crystal_Trunk"
    },
    {
      "x": -5,
      "y": 9,
      "z": -6,
      "name": "Wood_Crystal_Trunk"
    },
    {
      "x": -5,
      "y": 10,
      "z": -6,
      "name": "Wood_Crystal_Trunk"
    },
    {
      "x": -5,
      "y": 11,
      "z": -6,
      "name": "Wood_Crystal_Trunk"
    },
    {
      "x": -5,
      "y": 12,
      "z": -6,
      "name": "Wood_Crystal_Trunk"
    },
    {
      "x": -5,
      "y": 13,
      "z": -6,
      "name": "Wood_Crystal_Trunk_Full"
    },
    {
      "x": -5,
      "y": 36,
      "z": -6,
      "name": "Plant_Leaves_Crystal"
    },
    {
      "x": -5,
      "y": 38,
      "z": -6,
      "name": "Plant_Leaves_Crystal"
    },
    {
      "x": -5,
      "y": 8,
      "z": -5,
      "name": "Wood_Crystal_Trunk"
    },
    {
      "x": -5,
      "y": 9,
      "z": -5,
      "name": "Wood_Crystal_Trunk"
    },
    {
      "x": -5,
      "y": 10,
      "z": -5,
      "name": "Wood_Crystal_Trunk"
    },
    {
      "x": -5,
      "y": 11,
      "z": -5,
      "name": "Wood_Crystal_Trunk"
    },
    {
      "x": -5,
      "y": 12,
      "z": -5,
      "name": "Wood_Crystal_Trunk"
    },
    {
      "x": -5,
      "y": 13,
      "z": -5,
      "name": "Wood_Crystal_Trunk"
    },
    {
      "x": -5,
      "y": 14,
      "z": -5,
      "name": "Wood_Crystal_Trunk_Full"
    },
    {
      "x": -5,
      "y": 39,
      "z": -5,
      "name": "Plant_Leaves_Crystal"
    },
    {
      "x": -5,
      "y": 9,
      "z": -4,
      "name": "Wood_Crystal_Roots"
    },
    {
      "x": -5,
      "y": 10,
      "z": -4,
      "name": "Wood_Crystal_Trunk"
    },
    {
      "x": -5,
      "y": 11,
      "z": -4,
      "name": "Wood_Crystal_Trunk"
    },
    {
      "x": -5,
      "y": 12,
      "z": -4,
      "name": "Wood_Crystal_Trunk"
    },
    {
      "x": -5,
      "y": 13,
      "z": -4,
      "name": "Wood_Crystal_Trunk"
    },
    {
      "x": -5,
      "y": 14,
      "z": -4,
      "name": "Wood_Crystal_Trunk"
    },
    {
      "x": -5,
      "y": 15,
      "z": -4,
      "name": "Wood_Crystal_Trunk_Full"
    },
    {
      "x": -5,
      "y": 38,
      "z": -4,
      "name": "Plant_Fruit_Pinkberry",
      "rotation": 8
    },
    {
      "x": -5,
      "y": 39,
      "z": -4,
      "name": "Plant_Leaves_Crystal"
    },
    {
      "x": -5,
      "y": 11,
      "z": -3,
      "name": "Wood_Crystal_Trunk"
    },
    {
      "x": -5,
      "y": 12,
      "z": -3,
      "name": "Wood_Crystal_Trunk"
    },
    {
      "x": -5,
      "y": 13,
      "z": -3,
      "name": "Wood_Crystal_Trunk"
    },
    {
      "x": -5,
      "y": 14,
      "z": -3,
      "name": "Wood_Crystal_Trunk"
    },
    {
      "x": -5,
      "y": 15,
      "z": -3,
      "name": "Wood_Crystal_Trunk"
    },
    {
      "x": -5,
      "y": 16,
      "z": -3,
      "name": "Wood_Crystal_Trunk"
    },
    {
      "x": -5,
      "y": 38,
      "z": -3,
      "name": "Wood_Crystal_Trunk_Full"
    },
    {
      "x": -5,
      "y": 39,
      "z": -3,
      "name": "Plant_Leaves_Crystal"
    },
    {
      "x": -5,
      "y": 11,
      "z": -2,
      "name": "Wood_Crystal_Trunk"
    },
    {
      "x": -5,
      "y": 12,
      "z": -2,
      "name": "Wood_Crystal_Trunk"
    },
    {
      "x": -5,
      "y": 13,
      "z": -2,
      "name": "Wood_Crystal_Trunk"
    },
    {
      "x": -5,
      "y": 14,
      "z": -2,
      "name": "Wood_Crystal_Trunk"
    },
    {
      "x": -5,
      "y": 15,
      "z": -2,
      "name": "Wood_Crystal_Trunk"
    },
    {
      "x": -5,
      "y": 16,
      "z": -2,
      "name": "Rock_Crystal_Pink_Block"
    },
    {
      "x": -5,
      "y": 17,
      "z": -2,
      "name": "Rock_Crystal_Pink_Small"
    },
    {
      "x": -5,
      "y": 28,
      "z": -2,
      "name": "Wood_Crystal_Trunk_Full"
    },
    {
      "x": -5,
      "y": 29,
      "z": -2,
      "name": "Wood_Crystal_Trunk"
    },
    {
      "x": -5,
      "y": 30,
      "z": -2,
      "name": "Wood_Crystal_Trunk"
    },
    {
      "x": -5,
      "y": 31,
      "z": -2,
      "name": "Wood_Crystal_Trunk"
    },
    {
      "x": -5,
      "y": 32,
      "z": -2,
      "name": "Wood_Crystal_Trunk"
    },
    {
      "x": -5,
      "y": 33,
      "z": -2,
      "name": "Wood_Crystal_Trunk"
    },
    {
      "x": -5,
      "y": 34,
      "z": -2,
      "name": "Wood_Crystal_Trunk_Full"
    },
    {
      "x": -5,
      "y": 38,
      "z": -2,
      "name": "Wood_Crystal_Trunk_Full"
    },
    {
      "x": -5,
      "y": 39,
      "z": -2,
      "name": "Plant_Leaves_Crystal"
    },
    {
      "x": -5,
      "y": 12,
      "z": -1,
      "name": "Wood_Crystal_Trunk"
    },
    {
      "x": -5,
      "y": 13,
      "z": -1,
      "name": "Wood_Crystal_Trunk"
    },
    {
      "x": -5,
      "y": 14,
      "z": -1,
      "name": "Rock_Crystal_Pink_Block"
    },
    {
      "x": -5,
      "y": 15,
      "z": -1,
      "name": "Rock_Crystal_Pink_Block"
    },
    {
      "x": -5,
      "y": 16,
      "z": -1,
      "name": "Rock_Crystal_Pink_Block"
    },
    {
      "x": -5,
      "y": 17,
      "z": -1,
      "name": "Rock_Crystal_Pink_Block"
    },
    {
      "x": -5,
      "y": 18,
      "z": -1,
      "name": "Rock_Crystal_Pink_Block"
    },
    {
      "x": -5,
      "y": 24,
      "z": -1,
      "name": "Wood_Crystal_Trunk"
    },
    {
      "x": -5,
      "y": 25,
      "z": -1,
      "name": "Wood_Crystal_Trunk"
    },
    {
      "x": -5,
      "y": 26,
      "z": -1,
      "name": "Wood_Crystal_Trunk"
    },
    {
      "x": -5,
      "y": 27,
      "z": -1,
      "name": "Wood_Crystal_Trunk"
    },
    {
      "x": -5,
      "y": 28,
      "z": -1,
      "name": "Wood_Crystal_Trunk"
    },
    {
      "x": -5,
      "y": 29,
      "z": -1,
      "name": "Wood_Crystal_Trunk"
    },
    {
      "x": -5,
      "y": 30,
      "z": -1,
      "name": "Wood_Crystal_Trunk"
    },
    {
      "x": -5,
      "y": 31,
      "z": -1,
      "name": "Wood_Crystal_Trunk"
    },
    {
      "x": -5,
      "y": 32,
      "z": -1,
      "name": "Wood_Crystal_Trunk"
    },
    {
      "x": -5,
      "y": 33,
      "z": -1,
      "name": "Wood_Crystal_Trunk"
    },
    {
      "x": -5,
      "y": 34,
      "z": -1,
      "name": "Wood_Crystal_Trunk"
    },
    {
      "x": -5,
      "y": 35,
      "z": -1,
      "name": "Wood_Crystal_Trunk"
    },
    {
      "x": -5,
      "y": 36,
      "z": -1,
      "name": "Wood_Crystal_Trunk"
    },
    {
      "x": -5,
      "y": 37,
      "z": -1,
      "name": "Wood_Crystal_Trunk"
    },
    {
      "x": -5,
      "y": 38,
      "z": -1,
      "name": "Wood_Crystal_Trunk_Full"
    },
    {
      "x": -5,
      "y": 39,
      "z": -1,
      "name": "Plant_Leaves_Crystal"
    },
    {
      "x": -5,
      "y": 11,
      "z": 0,
      "name": "Wood_Crystal_Roots"
    },
    {
      "x": -5,
      "y": 12,
      "z": 0,
      "name": "Wood_Crystal_Trunk"
    },
    {
      "x": -5,
      "y": 13,
      "z": 0,
      "name": "Rock_Crystal_Pink_Block"
    },
    {
      "x": -5,
      "y": 14,
      "z": 0,
      "name": "Rock_Crystal_Pink_Block"
    },
    {
      "x": -5,
      "y": 15,
      "z": 0,
      "name": "Rock_Crystal_Pink_Block"
    },
    {
      "x": -5,
      "y": 16,
      "z": 0,
      "name": "Rock_Crystal_Pink_Block"
    },
    {
      "x": -5,
      "y": 17,
      "z": 0,
      "name": "Rock_Crystal_Pink_Block"
    },
    {
      "x": -5,
      "y": 18,
      "z": 0,
      "name": "Rock_Crystal_Pink_Block"
    },
    {
      "x": -5,
      "y": 19,
      "z": 0,
      "name": "Rock_Crystal_Pink_Block"
    },
    {
      "x": -5,
      "y": 20,
      "z": 0,
      "name": "Rock_Crystal_Pink_Medium"
    },
    {
      "x": -5,
      "y": 22,
      "z": 0,
      "name": "Rock_Crystal_Pink_Large",
      "rotation": 8
    },
    {
      "x": -5,
      "y": 23,
      "z": 0,
      "name": "Rock_Crystal_Pink_Block"
    },
    {
      "x": -5,
      "y": 24,
      "z": 0,
      "name": "Wood_Crystal_Trunk"
    },
    {
      "x": -5,
      "y": 25,
      "z": 0,
      "name": "Wood_Crystal_Trunk"
    },
    {
      "x": -5,
      "y": 26,
      "z": 0,
      "name": "Wood_Crystal_Trunk"
    },
    {
      "x": -5,
      "y": 27,
      "z": 0,
      "name": "Wood_Crystal_Trunk"
    },
    {
      "x": -5,
      "y": 28,
      "z": 0,
      "name": "Wood_Crystal_Trunk"
    },
    {
      "x": -5,
      "y": 29,
      "z": 0,
      "name": "Wood_Crystal_Trunk"
    },
    {
      "x": -5,
      "y": 30,
      "z": 0,
      "name": "Wood_Crystal_Trunk"
    },
    {
      "x": -5,
      "y": 31,
      "z": 0,
      "name": "Wood_Crystal_Trunk"
    },
    {
      "x": -5,
      "y": 32,
      "z": 0,
      "name": "Wood_Crystal_Trunk_Full"
    },
    {
      "x": -5,
      "y": 39,
      "z": 0,
      "name": "Plant_Leaves_Crystal"
    },
    {
      "x": -5,
      "y": 11,
      "z": 1,
      "name": "Wood_Crystal_Trunk"
    },
    {
      "x": -5,
      "y": 12,
      "z": 1,
      "name": "Wood_Crystal_Trunk"
    },
    {
      "x": -5,
      "y": 13,
      "z": 1,
      "name": "Wood_Crystal_Trunk"
    },
    {
      "x": -5,
      "y": 14,
      "z": 1,
      "name": "Rock_Crystal_Pink_Block"
    },
    {
      "x": -5,
      "y": 15,
      "z": 1,
      "name": "Rock_Crystal_Pink_Block"
    },
    {
      "x": -5,
      "y": 16,
      "z": 1,
      "name": "Rock_Crystal_Pink_Block"
    },
    {
      "x": -5,
      "y": 17,
      "z": 1,
      "name": "Rock_Crystal_Pink_Block"
    },
    {
      "x": -5,
      "y": 18,
      "z": 1,
      "name": "Rock_Crystal_Pink_Block"
    },
    {
      "x": -5,
      "y": 19,
      "z": 1,
      "name": "Rock_Crystal_Pink_Block"
    },
    {
      "x": -5,
      "y": 20,
      "z": 1,
      "name": "Rock_Crystal_Pink_Block"
    },
    {
      "x": -5,
      "y": 21,
      "z": 1,
      "name": "Rock_Crystal_Pink_Block"
    },
    {
      "x": -5,
      "y": 22,
      "z": 1,
      "name": "Rock_Crystal_Pink_Block"
    },
    {
      "x": -5,
      "y": 23,
      "z": 1,
      "name": "Wood_Crystal_Trunk"
    },
    {
      "x": -5,
      "y": 24,
      "z": 1,
      "name": "Wood_Crystal_Trunk"
    },
    {
      "x": -5,
      "y": 25,
      "z": 1,
      "name": "Wood_Crystal_Trunk"
    },
    {
      "x": -5,
      "y": 26,
      "z": 1,
      "name": "Wood_Crystal_Trunk"
    },
    {
      "x": -5,
      "y": 27,
      "z": 1,
      "name": "Wood_Crystal_Trunk"
    },
    {
      "x": -5,
      "y": 28,
      "z": 1,
      "name": "Wood_Crystal_Trunk_Full"
    },
    {
      "x": -5,
      "y": 39,
      "z": 1,
      "name": "Plant_Leaves_Crystal"
    },
    {
      "x": -5,
      "y": 10,
      "z": 2,
      "name": "Wood_Crystal_Trunk"
    },
    {
      "x": -5,
      "y": 11,
      "z": 2,
      "name": "Wood_Crystal_Trunk"
    },
    {
      "x": -5,
      "y": 12,
      "z": 2,
      "name": "Wood_Crystal_Trunk"
    },
    {
      "x": -5,
      "y": 13,
      "z": 2,
      "name": "Wood_Crystal_Trunk"
    },
    {
      "x": -5,
      "y": 14,
      "z": 2,
      "name": "Wood_Crystal_Trunk"
    },
    {
      "x": -5,
      "y": 15,
      "z": 2,
      "name": "Wood_Crystal_Trunk"
    },
    {
      "x": -5,
      "y": 16,
      "z": 2,
      "name": "Rock_Crystal_Pink_Block"
    },
    {
      "x": -5,
      "y": 17,
      "z": 2,
      "name": "Rock_Crystal_Pink_Block"
    },
    {
      "x": -5,
      "y": 18,
      "z": 2,
      "name": "Rock_Crystal_Pink_Block"
    },
    {
      "x": -5,
      "y": 19,
      "z": 2,
      "name": "Wood_Crystal_Trunk"
    },
    {
      "x": -5,
      "y": 20,
      "z": 2,
      "name": "Wood_Crystal_Trunk"
    },
    {
      "x": -5,
      "y": 21,
      "z": 2,
      "name": "Wood_Crystal_Trunk"
    },
    {
      "x": -5,
      "y": 22,
      "z": 2,
      "name": "Wood_Crystal_Trunk"
    },
    {
      "x": -5,
      "y": 23,
      "z": 2,
      "name": "Wood_Crystal_Trunk"
    },
    {
      "x": -5,
      "y": 24,
      "z": 2,
      "name": "Wood_Crystal_Trunk"
    },
    {
      "x": -5,
      "y": 25,
      "z": 2,
      "name": "Wood_Crystal_Trunk_Full"
    },
    {
      "x": -5,
      "y": 38,
      "z": 2,
      "name": "Plant_Leaves_Crystal"
    },
    {
      "x": -5,
      "y": 39,
      "z": 2,
      "name": "Plant_Leaves_Crystal"
    },
    {
      "x": -5,
      "y": 9,
      "z": 3,
      "name": "Wood_Crystal_Trunk"
    },
    {
      "x": -5,
      "y": 10,
      "z": 3,
      "name": "Wood_Crystal_Trunk"
    },
    {
      "x": -5,
      "y": 11,
      "z": 3,
      "name": "Wood_Crystal_Trunk"
    },
    {
      "x": -5,
      "y": 12,
      "z": 3,
      "name": "Wood_Crystal_Trunk"
    },
    {
      "x": -5,
      "y": 13,
      "z": 3,
      "name": "Wood_Crystal_Trunk"
    },
    {
      "x": -5,
      "y": 14,
      "z": 3,
      "name": "Wood_Crystal_Trunk"
    },
    {
      "x": -5,
      "y": 15,
      "z": 3,
      "name": "Wood_Crystal_Trunk"
    },
    {
      "x": -5,
      "y": 16,
      "z": 3,
      "name": "Wood_Crystal_Trunk"
    },
    {
      "x": -5,
      "y": 17,
      "z": 3,
      "name": "Wood_Crystal_Trunk"
    },
    {
      "x": -5,
      "y": 18,
      "z": 3,
      "name": "Wood_Crystal_Trunk"
    },
    {
      "x": -5,
      "y": 19,
      "z": 3,
      "name": "Wood_Crystal_Trunk"
    },
    {
      "x": -5,
      "y": 20,
      "z": 3,
      "name": "Wood_Crystal_Trunk"
    },
    {
      "x": -5,
      "y": 21,
      "z": 3,
      "name": "Wood_Crystal_Trunk"
    },
    {
      "x": -5,
      "y": 22,
      "z": 3,
      "name": "Wood_Crystal_Trunk_Full"
    },
    {
      "x": -5,
      "y": 28,
      "z": 3,
      "name": "Plant_Leaves_Crystal"
    },
    {
      "x": -5,
      "y": 39,
      "z": 3,
      "name": "Plant_Leaves_Crystal"
    },
    {
      "x": -5,
      "y": 8,
      "z": 4,
      "name": "Wood_Crystal_Roots"
    },
    {
      "x": -5,
      "y": 9,
      "z": 4,
      "name": "Wood_Crystal_Trunk"
    },
    {
      "x": -5,
      "y": 10,
      "z": 4,
      "name": "Wood_Crystal_Trunk"
    },
    {
      "x": -5,
      "y": 11,
      "z": 4,
      "name": "Wood_Crystal_Trunk"
    },
    {
      "x": -5,
      "y": 12,
      "z": 4,
      "name": "Wood_Crystal_Trunk"
    },
    {
      "x": -5,
      "y": 13,
      "z": 4,
      "name": "Wood_Crystal_Trunk"
    },
    {
      "x": -5,
      "y": 14,
      "z": 4,
      "name": "Wood_Crystal_Trunk"
    },
    {
      "x": -5,
      "y": 15,
      "z": 4,
      "name": "Wood_Crystal_Trunk"
    },
    {
      "x": -5,
      "y": 16,
      "z": 4,
      "name": "Wood_Crystal_Trunk"
    },
    {
      "x": -5,
      "y": 17,
      "z": 4,
      "name": "Wood_Crystal_Trunk_Full"
    },
    {
      "x": -5,
      "y": 18,
      "z": 4,
      "name": "Plant_Flower_Common_Poisoned2",
      "rotation": 7
    },
    {
      "x": -5,
      "y": 28,
      "z": 4,
      "name": "Plant_Leaves_Crystal"
    },
    {
      "x": -5,
      "y": 34,
      "z": 4,
      "name": "Plant_Leaves_Crystal"
    },
    {
      "x": -5,
      "y": 36,
      "z": 4,
      "name": "Plant_Leaves_Crystal"
    },
    {
      "x": -5,
      "y": 39,
      "z": 4,
      "name": "Plant_Leaves_Crystal"
    },
    {
      "x": -5,
      "y": 8,
      "z": 5,
      "name": "Wood_Crystal_Trunk"
    },
    {
      "x": -5,
      "y": 9,
      "z": 5,
      "name": "Wood_Crystal_Trunk"
    },
    {
      "x": -5,
      "y": 10,
      "z": 5,
      "name": "Wood_Crystal_Trunk"
    },
    {
      "x": -5,
      "y": 11,
      "z": 5,
      "name": "Wood_Crystal_Trunk"
    },
    {
      "x": -5,
      "y": 12,
      "z": 5,
      "name": "Wood_Crystal_Trunk"
    },
    {
      "x": -5,
      "y": 13,
      "z": 5,
      "name": "Wood_Crystal_Trunk"
    },
    {
      "x": -5,
      "y": 14,
      "z": 5,
      "name": "Wood_Crystal_Trunk_Full"
    },
    {
      "x": -5,
      "y": 28,
      "z": 5,
      "name": "Plant_Leaves_Crystal"
    },
    {
      "x": -5,
      "y": 33,
      "z": 5,
      "name": "Plant_Leaves_Crystal"
    },
    {
      "x": -5,
      "y": 34,
      "z": 5,
      "name": "Plant_Leaves_Crystal"
    },
    {
      "x": -5,
      "y": 35,
      "z": 5,
      "name": "Plant_Leaves_Crystal"
    },
    {
      "x": -5,
      "y": 36,
      "z": 5,
      "name": "Plant_Leaves_Crystal"
    },
    {
      "x": -5,
      "y": 37,
      "z": 5,
      "name": "Plant_Leaves_Crystal"
    },
    {
      "x": -5,
      "y": 8,
      "z": 6,
      "name": "Wood_Crystal_Trunk"
    },
    {
      "x": -5,
      "y": 9,
      "z": 6,
      "name": "Wood_Crystal_Trunk"
    },
    {
      "x": -5,
      "y": 10,
      "z": 6,
      "name": "Wood_Crystal_Trunk_Full"
    },
    {
      "x": -5,
      "y": 26,
      "z": 6,
      "name": "Plant_Fruit_Pinkberry",
      "rotation": 8
    },
    {
      "x": -5,
      "y": 27,
      "z": 6,
      "name": "Plant_Leaves_Crystal"
    },
    {
      "x": -5,
      "y": 28,
      "z": 6,
      "name": "Plant_Leaves_Crystal"
    },
    {
      "x": -5,
      "y": 33,
      "z": 6,
      "name": "Wood_Crystal_Branch_Long",
      "rotation": 5
    },
    {
      "x": -5,
      "y": 34,
      "z": 6,
      "name": "Plant_Leaves_Crystal"
    },
    {
      "x": -5,
      "y": 35,
      "z": 6,
      "name": "Plant_Leaves_Crystal"
    },
    {
      "x": -5,
      "y": 36,
      "z": 6,
      "name": "Plant_Leaves_Crystal"
    },
    {
      "x": -5,
      "y": 27,
      "z": 7,
      "name": "Plant_Fruit_Pinkberry"
    },
    {
      "x": -5,
      "y": 28,
      "z": 7,
      "name": "Plant_Leaves_Crystal"
    },
    {
      "x": -5,
      "y": 34,
      "z": 7,
      "name": "Plant_Leaves_Crystal"
    },
    {
      "x": -5,
      "y": 35,
      "z": 7,
      "name": "Plant_Leaves_Crystal"
    },
    {
      "x": -5,
      "y": 36,
      "z": 7,
      "name": "Plant_Leaves_Crystal"
    },
    {
      "x": -5,
      "y": 28,
      "z": 8,
      "name": "Plant_Leaves_Crystal"
    },
    {
      "x": -5,
      "y": 33,
      "z": 8,
      "name": "Plant_Leaves_Crystal"
    },
    {
      "x": -5,
      "y": 34,
      "z": 8,
      "name": "Plant_Leaves_Crystal"
    },
    {
      "x": -5,
      "y": 35,
      "z": 8,
      "name": "Plant_Leaves_Crystal"
    },
    {
      "x": -5,
      "y": 33,
      "z": 9,
      "name": "Plant_Leaves_Crystal"
    },
    {
      "x": -5,
      "y": 34,
      "z": 9,
      "name": "Plant_Leaves_Crystal"
    },
    {
      "x": -5,
      "y": 34,
      "z": 10,
      "name": "Plant_Leaves_Crystal"
    },
    {
      "x": -4,
      "y": 36,
      "z": -12,
      "name": "Plant_Leaves_Crystal"
    },
    {
      "x": -4,
      "y": 35,
      "z": -11,
      "name": "Plant_Leaves_Crystal"
    },
    {
      "x": -4,
      "y": 36,
      "z": -11,
      "name": "Plant_Leaves_Crystal"
    },
    {
      "x": -4,
      "y": 37,
      "z": -11,
      "name": "Plant_Leaves_Crystal"
    },
    {
      "x": -4,
      "y": 35,
      "z": -10,
      "name": "Plant_Leaves_Crystal"
    },
    {
      "x": -4,
      "y": 36,
      "z": -10,
      "name": "Plant_Leaves_Crystal"
    },
    {
      "x": -4,
      "y": 37,
      "z": -10,
      "name": "Plant_Leaves_Crystal"
    },
    {
      "x": -4,
      "y": 38,
      "z": -10,
      "name": "Plant_Leaves_Crystal"
    },
    {
      "x": -4,
      "y": 35,
      "z": -9,
      "name": "Plant_Leaves_Crystal"
    },
    {
      "x": -4,
      "y": 36,
      "z": -9,
      "name": "Plant_Leaves_Crystal"
    },
    {
      "x": -4,
      "y": 37,
      "z": -9,
      "name": "Plant_Leaves_Crystal"
    },
    {
      "x": -4,
      "y": 38,
      "z": -9,
      "name": "Plant_Leaves_Crystal"
    },
    {
      "x": -4,
      "y": 35,
      "z": -8,
      "name": "Plant_Leaves_Crystal"
    },
    {
      "x": -4,
      "y": 36,
      "z": -8,
      "name": "Plant_Leaves_Crystal"
    },
    {
      "x": -4,
      "y": 38,
      "z": -8,
      "name": "Plant_Leaves_Crystal"
    },
    {
      "x": -4,
      "y": 35,
      "z": -7,
      "name": "Wood_Crystal_Trunk_Full"
    },
    {
      "x": -4,
      "y": 36,
      "z": -7,
      "name": "Plant_Leaves_Crystal"
    },
    {
      "x": -4,
      "y": 37,
      "z": -7,
      "name": "Plant_Leaves_Crystal"
    },
    {
      "x": -4,
      "y": 38,
      "z": -7,
      "name": "Plant_Leaves_Crystal"
    },
    {
      "x": -4,
      "y": 9,
      "z": -6,
      "name": "Wood_Crystal_Trunk"
    },
    {
      "x": -4,
      "y": 10,
      "z": -6,
      "name": "Wood_Crystal_Trunk"
    },
    {
      "x": -4,
      "y": 11,
      "z": -6,
      "name": "Wood_Crystal_Trunk"
    },
    {
      "x": -4,
      "y": 12,
      "z": -6,
      "name": "Wood_Crystal_Trunk_Full"
    },
    {
      "x": -4,
      "y": 36,
      "z": -6,
      "name": "Plant_Leaves_Crystal"
    },
    {
      "x": -4,
      "y": 38,
      "z": -6,
      "name": "Plant_Leaves_Crystal"
    },
    {
      "x": -4,
      "y": 39,
      "z": -6,
      "name": "Plant_Leaves_Crystal"
    },
    {
      "x": -4,
      "y": 9,
      "z": -5,
      "name": "Wood_Crystal_Trunk"
    },
    {
      "x": -4,
      "y": 10,
      "z": -5,
      "name": "Wood_Crystal_Trunk"
    },
    {
      "x": -4,
      "y": 11,
      "z": -5,
      "name": "Wood_Crystal_Trunk"
    },
    {
      "x": -4,
      "y": 12,
      "z": -5,
      "name": "Wood_Crystal_Trunk"
    },
    {
      "x": -4,
      "y": 13,
      "z": -5,
      "name": "Wood_Crystal_Trunk"
    },
    {
      "x": -4,
      "y": 14,
      "z": -5,
      "name": "Wood_Crystal_Trunk_Full"
    },
    {
      "x": -4,
      "y": 39,
      "z": -5,
      "name": "Plant_Leaves_Crystal"
    },
    {
      "x": -4,
      "y": 10,
      "z": -4,
      "name": "Wood_Crystal_Roots"
    },
    {
      "x": -4,
      "y": 11,
      "z": -4,
      "name": "Wood_Crystal_Trunk"
    },
    {
      "x": -4,
      "y": 12,
      "z": -4,
      "name": "Wood_Crystal_Trunk"
    },
    {
      "x": -4,
      "y": 13,
      "z": -4,
      "name": "Wood_Crystal_Trunk"
    },
    {
      "x": -4,
      "y": 14,
      "z": -4,
      "name": "Wood_Crystal_Trunk"
    },
    {
      "x": -4,
      "y": 15,
      "z": -4,
      "name": "Wood_Crystal_Trunk_Full"
    },
    {
      "x": -4,
      "y": 39,
      "z": -4,
      "name": "Plant_Leaves_Crystal"
    },
    {
      "x": -4,
      "y": 11,
      "z": -3,
      "name": "Wood_Crystal_Trunk"
    },
    {
      "x": -4,
      "y": 12,
      "z": -3,
      "name": "Wood_Crystal_Trunk"
    },
    {
      "x": -4,
      "y": 13,
      "z": -3,
      "name": "Wood_Crystal_Trunk"
    },
    {
      "x": -4,
      "y": 14,
      "z": -3,
      "name": "Wood_Crystal_Trunk"
    },
    {
      "x": -4,
      "y": 15,
      "z": -3,
      "name": "Wood_Crystal_Trunk"
    },
    {
      "x": -4,
      "y": 16,
      "z": -3,
      "name": "Wood_Crystal_Trunk"
    },
    {
      "x": -4,
      "y": 17,
      "z": -3,
      "name": "Wood_Crystal_Trunk"
    },
    {
      "x": -4,
      "y": 33,
      "z": -3,
      "name": "Wood_Crystal_Trunk_Full"
    },
    {
      "x": -4,
      "y": 34,
      "z": -3,
      "name": "Wood_Crystal_Trunk_Full"
    },
    {
      "x": -4,
      "y": 12,
      "z": -2,
      "name": "Wood_Crystal_Trunk"
    },
    {
      "x": -4,
      "y": 13,
      "z": -2,
      "name": "Wood_Crystal_Trunk"
    },
    {
      "x": -4,
      "y": 14,
      "z": -2,
      "name": "Wood_Crystal_Trunk"
    },
    {
      "x": -4,
      "y": 15,
      "z": -2,
      "name": "Rock_Crystal_Pink_Block"
    },
    {
      "x": -4,
      "y": 16,
      "z": -2,
      "name": "Rock_Crystal_Pink_Block"
    },
    {
      "x": -4,
      "y": 17,
      "z": -2,
      "name": "Rock_Crystal_Pink_Block"
    },
    {
      "x": -4,
      "y": 18,
      "z": -2,
      "name": "Rock_Crystal_Pink_Medium"
    },
    {
      "x": -4,
      "y": 32,
      "z": -2,
      "name": "Wood_Crystal_Trunk_Full"
    },
    {
      "x": -4,
      "y": 33,
      "z": -2,
      "name": "Wood_Crystal_Trunk_Full"
    },
    {
      "x": -4,
      "y": 34,
      "z": -2,
      "name": "Wood_Crystal_Trunk_Full"
    },
    {
      "x": -4,
      "y": 38,
      "z": -2,
      "name": "Plant_Leaves_Crystal"
    },
    {
      "x": -4,
      "y": 39,
      "z": -2,
      "name": "Plant_Leaves_Crystal"
    },
    {
      "x": -4,
      "y": 12,
      "z": -1,
      "name": "Wood_Crystal_Trunk"
    },
    {
      "x": -4,
      "y": 13,
      "z": -1,
      "name": "Rock_Crystal_Pink_Block"
    },
    {
      "x": -4,
      "y": 14,
      "z": -1,
      "name": "Rock_Crystal_Pink_Block"
    },
    {
      "x": -4,
      "y": 15,
      "z": -1,
      "name": "Rock_Crystal_Pink_Block"
    },
    {
      "x": -4,
      "y": 16,
      "z": -1,
      "name": "Rock_Crystal_Pink_Block"
    },
    {
      "x": -4,
      "y": 17,
      "z": -1,
      "name": "Rock_Crystal_Pink_Block"
    },
    {
      "x": -4,
      "y": 18,
      "z": -1,
      "name": "Rock_Crystal_Pink_Block"
    },
    {
      "x": -4,
      "y": 19,
      "z": -1,
      "name": "Rock_Crystal_Pink_Block"
    },
    {
      "x": -4,
      "y": 20,
      "z": -1,
      "name": "Rock_Crystal_Pink_Block"
    },
    {
      "x": -4,
      "y": 22,
      "z": -1,
      "name": "Wood_Crystal_Trunk"
    },
    {
      "x": -4,
      "y": 23,
      "z": -1,
      "name": "Wood_Crystal_Trunk"
    },
    {
      "x": -4,
      "y": 24,
      "z": -1,
      "name": "Wood_Crystal_Trunk"
    },
    {
      "x": -4,
      "y": 25,
      "z": -1,
      "name": "Wood_Crystal_Trunk"
    },
    {
      "x": -4,
      "y": 26,
      "z": -1,
      "name": "Wood_Crystal_Trunk"
    },
    {
      "x": -4,
      "y": 27,
      "z": -1,
      "name": "Wood_Crystal_Trunk"
    },
    {
      "x": -4,
      "y": 28,
      "z": -1,
      "name": "Wood_Crystal_Trunk"
    },
    {
      "x": -4,
      "y": 29,
      "z": -1,
      "name": "Wood_Crystal_Trunk"
    },
    {
      "x": -4,
      "y": 30,
      "z": -1,
      "name": "Wood_Crystal_Trunk"
    },
    {
      "x": -4,
      "y": 31,
      "z": -1,
      "name": "Wood_Crystal_Trunk"
    },
    {
      "x": -4,
      "y": 32,
      "z": -1,
      "name": "Wood_Crystal_Trunk_Full"
    },
    {
      "x": -4,
      "y": 38,
      "z": -1,
      "name": "Plant_Leaves_Crystal"
    },
    {
      "x": -4,
      "y": 39,
      "z": -1,
      "name": "Plant_Leaves_Crystal"
    },
    {
      "x": -4,
      "y": 11,
      "z": 0,
      "name": "Wood_Crystal_Trunk"
    },
    {
      "x": -4,
      "y": 12,
      "z": 0,
      "name": "Wood_Crystal_Trunk"
    },
    {
      "x": -4,
      "y": 13,
      "z": 0,
      "name": "Rock_Crystal_Pink_Block"
    },
    {
      "x": -4,
      "y": 14,
      "z": 0,
      "name": "Rock_Crystal_Pink_Block"
    },
    {
      "x": -4,
      "y": 15,
      "z": 0,
      "name": "Rock_Crystal_Pink_Block"
    },
    {
      "x": -4,
      "y": 16,
      "z": 0,
      "name": "Rock_Crystal_Pink_Block"
    },
    {
      "x": -4,
      "y": 17,
      "z": 0,
      "name": "Rock_Crystal_Pink_Block"
