{
  "version": 8,
  "blockIdVersion": 10,
  "anchorX": -1,
  "anchorY": 8,
  "anchorZ": -1,
  "blocks": [
    {
      "x": -5,
      "y": 8,
      "z": -2,
      "name": "Soil_Leaves"
    },
    {
      "x": -5,
      "y": 9,
      "z": -2,
      "name": "Plant_Grass_Sharp"
    },
    {
      "x": -5,
      "y": 8,
      "z": -1,
      "name": "Soil_Leaves"
    },
    {
      "x": -4,
      "y": 8,
      "z": -4,
      "name": "Soil_Grass"
    },
    {
      "x": -4,
      "y": 9,
      "z": -4,
      "name": "Plant_Bush_Arid_Red"
    },
    {
      "x": -4,
      "y": 10,
      "z": -4,
      "name": "Wood_Oak_Branch_Corner",
      "rotation": 3
    },
    {
      "x": -4,
      "y": 6,
      "z": -3,
      "name": "Soil_Dirt"
    },
    {
      "x": -4,
      "y": 7,
      "z": -3,
      "name": "Soil_Dirt"
    },
    {
      "x": -4,
      "y": 8,
      "z": -3,
      "name": "Soil_Leaves"
    },
    {
      "x": -4,
      "y": 9,
      "z": -3,
      "name": "Furniture_Kweebec_Shelf",
      "rotation": 3
    },
    {
      "x": -4,
      "y": 7,
      "z": -2,
      "name": "Soil_Dirt"
    },
    {
      "x": -4,
      "y": 8,
      "z": -2,
      "name": "Soil_Leaves"
    },
    {
      "x": -4,
      "y": 9,
      "z": -2,
      "name": "Plant_Grass_Sharp_Tall"
    },
    {
      "x": -4,
      "y": 10,
      "z": -2,
      "name": "Plant_Grass_Sharp_Tall",
      "filler": 1024
    },
    {
      "x": -4,
      "y": 8,
      "z": -1,
      "name": "Soil_Leaves"
    },
    {
      "x": -4,
      "y": 9,
      "z": -1,
      "name": "Plant_Grass_Sharp_Tall"
    },
    {
      "x": -4,
      "y": 10,
      "z": -1,
      "name": "Plant_Grass_Sharp_Tall",
      "filler": 1024
    },
    {
      "x": -4,
      "y": 7,
      "z": 0,
      "name": "Soil_Dirt"
    },
    {
      "x": -4,
      "y": 8,
      "z": 0,
      "name": "Soil_Grass"
    },
    {
      "x": -4,
      "y": 9,
      "z": 0,
      "name": "Wood_Oak_Branch_Short",
      "support": 15,
      "rotation": 3
    },
    {
      "x": -4,
      "y": 8,
      "z": 1,
      "name": "Soil_Grass"
    },
    {
      "x": -4,
      "y": 9,
      "z": 1,
      "name": "Plant_Grass_Sharp"
    },
    {
      "x": -3,
      "y": 7,
      "z": -4,
      "name": "Wood_Oak_Trunk_Full",
      "support": 15
    },
    {
      "x": -3,
      "y": 8,
      "z": -4,
      "name": "Wood_Oak_Trunk",
      "support": 15
    },
    {
      "x": -3,
      "y": 9,
      "z": -4,
      "name": "Wood_Oak_Trunk",
      "support": 15
    },
    {
      "x": -3,
      "y": 10,
      "z": -4,
      "name": "Wood_Oak_Trunk_Full",
      "support": 15
    },
    {
      "x": -3,
      "y": 6,
      "z": -3,
      "name": "Soil_Dirt"
    },
    {
      "x": -3,
      "y": 7,
      "z": -3,
      "name": "Soil_Dirt"
    },
    {
      "x": -3,
      "y": 8,
      "z": -3,
      "name": "Soil_Dirt"
    },
    {
      "x": -3,
      "y": 9,
      "z": -3,
      "name": "Wood_Oak_Trunk",
      "rotation": 4
    },
    {
      "x": -3,
      "y": 10,
      "z": -3,
      "name": "Plant_Moss_Rug_Green"
    },
    {
      "x": -3,
      "y": 6,
      "z": -2,
      "name": "Soil_Dirt"
    },
    {
      "x": -3,
      "y": 7,
      "z": -2,
      "name": "Soil_Dirt"
    },
    {
      "x": -3,
      "y": 8,
      "z": -2,
      "name": "Soil_Dirt"
    },
    {
      "x": -3,
      "y": 9,
      "z": -2,
      "name": "Wood_Oak_Trunk",
      "support": 15,
      "rotation": 4
    },
    {
      "x": -3,
      "y": 5,
      "z": -1,
      "name": "Soil_Dirt"
    },
    {
      "x": -3,
      "y": 6,
      "z": -1,
      "name": "Soil_Dirt"
    },
    {
      "x": -3,
      "y": 7,
      "z": -1,
      "name": "Soil_Dirt"
    },
    {
      "x": -3,
      "y": 8,
      "z": -1,
      "name": "Soil_Dirt"
    },
    {
      "x": -3,
      "y": 9,
      "z": -1,
      "name": "Wood_Oak_Trunk",
      "support": 15,
      "rotation": 4
    },
    {
      "x": -3,
      "y": 13,
      "z": -1,
      "name": "Plant_Leaves_Autumn"
    },
    {
      "x": -3,
      "y": 5,
      "z": 0,
      "name": "Soil_Dirt"
    },
    {
      "x": -3,
      "y": 6,
      "z": 0,
      "name": "Soil_Dirt"
    },
    {
      "x": -3,
      "y": 7,
      "z": 0,
      "name": "Soil_Dirt"
    },
    {
      "x": -3,
      "y": 8,
      "z": 0,
      "name": "Soil_Dirt"
    },
    {
      "x": -3,
      "y": 9,
      "z": 0,
      "name": "Wood_Oak_Trunk",
      "support": 15,
      "rotation": 4
    },
    {
      "x": -3,
      "y": 5,
      "z": 1,
      "name": "Soil_Dirt"
    },
    {
      "x": -3,
      "y": 6,
      "z": 1,
      "name": "Soil_Dirt"
    },
    {
      "x": -3,
      "y": 7,
      "z": 1,
      "name": "Wood_Oak_Trunk",
      "support": 15
    },
    {
      "x": -3,
      "y": 8,
      "z": 1,
      "name": "Wood_Oak_Trunk",
      "support": 15
    },
    {
      "x": -3,
      "y": 9,
      "z": 1,
      "name": "Wood_Oak_Trunk",
      "support": 15
    },
    {
      "x": -3,
      "y": 10,
      "z": 1,
      "name": "Wood_Oak_Trunk",
      "support": 15
    },
    {
      "x": -3,
      "y": 11,
      "z": 1,
      "name": "Wood_Oak_Trunk",
      "support": 15
    },
    {
      "x": -3,
      "y": 12,
      "z": 1,
      "name": "Wood_Oak_Trunk_Full",
      "support": 15
    },
    {
      "x": -3,
      "y": 8,
      "z": 2,
      "name": "Soil_Grass"
    },
    {
      "x": -2,
      "y": 6,
      "z": -4,
      "name": "Soil_Dirt"
    },
    {
      "x": -2,
      "y": 7,
      "z": -4,
      "name": "Soil_Dirt"
    },
    {
      "x": -2,
      "y": 8,
      "z": -4,
      "name": "Soil_Dirt"
    },
    {
      "x": -2,
      "y": 9,
      "z": -4,
      "name": "Wood_Oak_Trunk_Full",
      "support": 15
    },
    {
      "x": -2,
      "y": 5,
      "z": -3,
      "name": "Soil_Dirt"
    },
    {
      "x": -2,
      "y": 6,
      "z": -3,
      "name": "Soil_Dirt"
    },
    {
      "x": -2,
      "y": 7,
      "z": -3,
      "name": "Soil_Dirt"
    },
    {
      "x": -2,
      "y": 8,
      "z": -3,
      "name": "Soil_Dirt"
    },
    {
      "x": -2,
      "y": 9,
      "z": -3,
      "name": "Wood_Hardwood_Planks_Half"
    },
    {
      "x": -2,
      "y": 5,
      "z": -2,
      "name": "Soil_Dirt"
    },
    {
      "x": -2,
      "y": 6,
      "z": -2,
      "name": "Soil_Dirt"
    },
    {
      "x": -2,
      "y": 7,
      "z": -2,
      "name": "Soil_Dirt"
    },
    {
      "x": -2,
      "y": 8,
      "z": -2,
      "name": "Soil_Dirt"
    },
    {
      "x": -2,
      "y": 9,
      "z": -2,
      "name": "Wood_Hardwood_Planks_Half"
    },
    {
      "x": -2,
      "y": 14,
      "z": -2,
      "name": "Plant_Leaves_Autumn"
    },
    {
      "x": -2,
      "y": 5,
      "z": -1,
      "name": "Soil_Dirt"
    },
    {
      "x": -2,
      "y": 6,
      "z": -1,
      "name": "Soil_Dirt"
    },
    {
      "x": -2,
      "y": 7,
      "z": -1,
      "name": "Soil_Dirt"
    },
    {
      "x": -2,
      "y": 8,
      "z": -1,
      "name": "Soil_Dirt"
    },
    {
      "x": -2,
      "y": 9,
      "z": -1,
      "name": "Wood_Hardwood_Planks_Half"
    },
    {
      "x": -2,
      "y": 12,
      "z": -1,
      "name": "Wood_Oak_Branch_Corner",
      "support": 15,
      "rotation": 2
    },
    {
      "x": -2,
      "y": 13,
      "z": -1,
      "name": "Wood_Oak_Branch_Long",
      "support": 15
    },
    {
      "x": -2,
      "y": 14,
      "z": -1,
      "name": "Plant_Leaves_Autumn"
    },
    {
      "x": -2,
      "y": 5,
      "z": 0,
      "name": "Soil_Dirt"
    },
    {
      "x": -2,
      "y": 6,
      "z": 0,
      "name": "Soil_Dirt"
    },
    {
      "x": -2,
      "y": 7,
      "z": 0,
      "name": "Soil_Dirt"
    },
    {
      "x": -2,
      "y": 8,
      "z": 0,
      "name": "Soil_Dirt"
    },
    {
      "x": -2,
      "y": 9,
      "z": 0,
      "name": "Wood_Hardwood_Planks_Half"
    },
    {
      "x": -2,
      "y": 12,
      "z": 0,
      "name": "Wood_Oak_Branch_Long",
      "support": 15,
      "rotation": 4
    },
    {
      "x": -2,
      "y": 13,
      "z": 0,
      "name": "Plant_Leaves_Autumn"
    },
    {
      "x": -2,
      "y": 5,
      "z": 1,
      "name": "Soil_Dirt"
    },
    {
      "x": -2,
      "y": 6,
      "z": 1,
      "name": "Soil_Dirt"
    },
    {
      "x": -2,
      "y": 7,
      "z": 1,
      "name": "Soil_Dirt"
    },
    {
      "x": -2,
      "y": 8,
      "z": 1,
      "name": "Soil_Dirt"
    },
    {
      "x": -2,
      "y": 9,
      "z": 1,
      "name": "Wood_Hardwood_Planks_Half"
    },
    {
      "x": -2,
      "y": 12,
      "z": 1,
      "name": "Wood_Oak_Trunk_Full",
      "support": 15
    },
    {
      "x": -2,
      "y": 13,
      "z": 1,
      "name": "Wood_Oak_Trunk_Full",
      "support": 15
    },
    {
      "x": -2,
      "y": 7,
      "z": 2,
      "name": "Soil_Dirt"
    },
    {
      "x": -2,
      "y": 8,
      "z": 2,
      "name": "Soil_Grass"
    },
    {
      "x": -2,
      "y": 9,
      "z": 2,
      "name": "Plant_Grass_Sharp"
    },
    {
      "x": -1,
      "y": 6,
      "z": -4,
      "name": "Soil_Dirt"
    },
    {
      "x": -1,
      "y": 7,
      "z": -4,
      "name": "Soil_Dirt"
    },
    {
      "x": -1,
      "y": 8,
      "z": -4,
      "name": "Soil_Dirt"
    },
    {
      "x": -1,
      "y": 9,
      "z": -4,
      "name": "Wood_Hardwood_Planks_Half"
    },
    {
      "x": -1,
      "y": 5,
      "z": -3,
      "name": "Soil_Dirt"
    },
    {
      "x": -1,
      "y": 6,
      "z": -3,
      "name": "Soil_Dirt"
    },
    {
      "x": -1,
      "y": 7,
      "z": -3,
      "name": "Soil_Dirt"
    },
    {
      "x": -1,
      "y": 8,
      "z": -3,
      "name": "Soil_Dirt"
    },
    {
      "x": -1,
      "y": 9,
      "z": -3,
      "name": "Wood_Hardwood_Planks_Half"
    },
    {
      "x": -1,
      "y": 5,
      "z": -2,
      "name": "Soil_Dirt"
    },
    {
      "x": -1,
      "y": 6,
      "z": -2,
      "name": "Soil_Dirt"
    },
    {
      "x": -1,
      "y": 7,
      "z": -2,
      "name": "Soil_Dirt"
    },
    {
      "x": -1,
      "y": 8,
      "z": -2,
      "name": "Soil_Dirt"
    },
    {
      "x": -1,
      "y": 9,
      "z": -2,
      "name": "Wood_Hardwood_Planks_Half"
    },
    {
      "x": -1,
      "y": 5,
      "z": -1,
      "name": "Soil_Dirt"
    },
    {
      "x": -1,
      "y": 6,
      "z": -1,
      "name": "Soil_Dirt"
    },
    {
      "x": -1,
      "y": 7,
      "z": -1,
      "name": "Soil_Dirt"
    },
    {
      "x": -1,
      "y": 8,
      "z": -1,
      "name": "Soil_Dirt"
    },
    {
      "x": -1,
      "y": 9,
      "z": -1,
      "name": "Wood_Hardwood_Planks_Half"
    },
    {
      "x": -1,
      "y": 13,
      "z": -1,
      "name": "Plant_Leaves_Autumn"
    },
    {
      "x": -1,
      "y": 5,
      "z": 0,
      "name": "Soil_Dirt"
    },
    {
      "x": -1,
      "y": 6,
      "z": 0,
      "name": "Soil_Dirt"
    },
    {
      "x": -1,
      "y": 7,
      "z": 0,
      "name": "Soil_Dirt"
    },
    {
      "x": -1,
      "y": 8,
      "z": 0,
      "name": "Soil_Dirt"
    },
    {
      "x": -1,
      "y": 9,
      "z": 0,
      "name": "Wood_Hardwood_Planks_Half"
    },
    {
      "x": -1,
      "y": 5,
      "z": 1,
      "name": "Soil_Dirt"
    },
    {
      "x": -1,
      "y": 6,
      "z": 1,
      "name": "Soil_Dirt"
    },
    {
      "x": -1,
      "y": 7,
      "z": 1,
      "name": "Soil_Dirt"
    },
    {
      "x": -1,
      "y": 8,
      "z": 1,
      "name": "Soil_Dirt"
    },
    {
      "x": -1,
      "y": 9,
      "z": 1,
      "name": "Wood_Oak_Trunk",
      "rotation": 5
    },
    {
      "x": -1,
      "y": 10,
      "z": 1,
      "name": "*Plant_Crop_Cotton_Block_State_Definitions_StageFinal"
    },
    {
      "x": -1,
      "y": 11,
      "z": 1,
      "name": "*Plant_Crop_Cotton_Block_State_Definitions_StageFinal",
      "filler": 1024
    },
    {
      "x": -1,
      "y": 6,
      "z": 2,
      "name": "Soil_Dirt"
    },
    {
      "x": -1,
      "y": 7,
      "z": 2,
      "name": "Soil_Dirt"
    },
    {
      "x": -1,
      "y": 8,
      "z": 2,
      "name": "Soil_Grass"
    },
    {
      "x": -1,
      "y": 9,
      "z": 2,
      "name": "Furniture_Kweebec_Shelf"
    },
    {
      "x": 0,
      "y": 6,
      "z": -4,
      "name": "Soil_Dirt"
    },
    {
      "x": 0,
      "y": 7,
      "z": -4,
      "name": "Soil_Dirt"
    },
    {
      "x": 0,
      "y": 8,
      "z": -4,
      "name": "Soil_Dirt"
    },
    {
      "x": 0,
      "y": 9,
      "z": -4,
      "name": "Wood_Hardwood_Planks_Half"
    },
    {
      "x": 0,
      "y": 6,
      "z": -3,
      "name": "Soil_Dirt"
    },
    {
      "x": 0,
      "y": 7,
      "z": -3,
      "name": "Soil_Dirt"
    },
    {
      "x": 0,
      "y": 8,
      "z": -3,
      "name": "Soil_Dirt"
    },
    {
      "x": 0,
      "y": 9,
      "z": -3,
      "name": "Wood_Oak_Trunk",
      "support": 15,
      "rotation": 4
    },
    {
      "x": 0,
      "y": 10,
      "z": -3,
      "name": "*Plant_Crop_Cotton_Block_State_Definitions_Stage2",
      "components": {
        "Components": {
          "FarmingBlock": {
            "GrowthProgress": 2.0,
            "LastTickGameTime": "0001-01-01T12:00:00Z"
          }
        }
      }
    },
    {
      "x": 0,
      "y": 11,
      "z": -3,
      "name": "*Plant_Crop_Cotton_Block_State_Definitions_Stage2",
      "filler": 1024
    },
    {
      "x": 0,
      "y": 5,
      "z": -2,
      "name": "Soil_Dirt"
    },
    {
      "x": 0,
      "y": 6,
      "z": -2,
      "name": "Soil_Dirt"
    },
    {
      "x": 0,
      "y": 7,
      "z": -2,
      "name": "Soil_Dirt"
    },
    {
      "x": 0,
      "y": 8,
      "z": -2,
      "name": "Soil_Dirt"
    },
    {
      "x": 0,
      "y": 9,
      "z": -2,
      "name": "Wood_Oak_Trunk",
      "support": 15,
      "rotation": 4
    },
    {
      "x": 0,
      "y": 10,
      "z": -2,
      "name": "*Plant_Crop_Cotton_Block_State_Definitions_Stage2",
      "components": {
        "Components": {
          "FarmingBlock": {
            "GrowthProgress": 2.0,
            "LastTickGameTime": "0001-01-01T12:00:00Z"
          }
        }
      }
    },
    {
      "x": 0,
      "y": 11,
      "z": -2,
      "name": "*Plant_Crop_Cotton_Block_State_Definitions_Stage2",
      "filler": 1024
    },
    {
      "x": 0,
      "y": 5,
      "z": -1,
      "name": "Soil_Dirt"
    },
    {
      "x": 0,
      "y": 6,
      "z": -1,
      "name": "Soil_Dirt"
    },
    {
      "x": 0,
      "y": 7,
      "z": -1,
      "name": "Soil_Dirt"
    },
    {
      "x": 0,
      "y": 8,
      "z": -1,
      "name": "Soil_Dirt"
    },
    {
      "x": 0,
      "y": 9,
      "z": -1,
      "name": "Wood_Oak_Trunk",
      "support": 15,
      "rotation": 4
    },
    {
      "x": 0,
      "y": 10,
      "z": -1,
      "name": "*Plant_Crop_Cotton_Block_State_Definitions_StageFinal"
    },
    {
      "x": 0,
      "y": 11,
      "z": -1,
      "name": "*Plant_Crop_Cotton_Block_State_Definitions_StageFinal",
      "filler": 1024
    },
    {
      "x": 0,
      "y": 6,
      "z": 0,
      "name": "Soil_Dirt"
    },
    {
      "x": 0,
      "y": 7,
      "z": 0,
      "name": "Soil_Dirt"
    },
    {
      "x": 0,
      "y": 8,
      "z": 0,
      "name": "Soil_Dirt"
    },
    {
      "x": 0,
      "y": 9,
      "z": 0,
      "name": "Wood_Oak_Trunk",
      "support": 15,
      "rotation": 4
    },
    {
      "x": 0,
      "y": 10,
      "z": 0,
      "name": "Wood_Oak_Branch_Corner",
      "support": 15,
      "rotation": 9
    },
    {
      "x": 0,
      "y": 11,
      "z": 0,
      "name": "Furniture_Kweebec_Lantern"
    },
    {
      "x": 0,
      "y": 12,
      "z": 0,
      "name": "Wood_Oak_Branch_Corner",
      "support": 15,
      "rotation": 9
    },
    {
      "x": 0,
      "y": 6,
      "z": 1,
      "name": "Soil_Dirt"
    },
    {
      "x": 0,
      "y": 7,
      "z": 1,
      "name": "Soil_Dirt"
    },
    {
      "x": 0,
      "y": 8,
      "z": 1,
      "name": "Soil_Dirt"
    },
    {
      "x": 0,
      "y": 9,
      "z": 1,
      "name": "Wood_Oak_Trunk",
      "support": 15,
      "rotation": 4
    },
    {
      "x": 0,
      "y": 7,
      "z": 2,
      "name": "Soil_Dirt"
    },
    {
      "x": 0,
      "y": 8,
      "z": 2,
      "name": "Soil_Dirt"
    },
    {
      "x": 0,
      "y": 9,
      "z": 2,
      "name": "Wood_Oak_Trunk",
      "support": 15,
      "rotation": 4
    },
    {
      "x": 1,
      "y": 8,
      "z": -4,
      "name": "Soil_Grass"
    },
    {
      "x": 1,
      "y": 9,
      "z": -4,
      "name": "Plant_Grass_Sharp"
    },
    {
      "x": 1,
      "y": 7,
      "z": -3,
      "name": "Soil_Dirt"
    },
    {
      "x": 1,
      "y": 8,
      "z": -3,
      "name": "Soil_Grass"
    },
    {
      "x": 1,
      "y": 9,
      "z": -3,
      "name": "Plant_Grass_Sharp"
    },
    {
      "x": 1,
      "y": 7,
      "z": -2,
      "name": "Soil_Dirt"
    },
    {
      "x": 1,
      "y": 8,
      "z": -2,
      "name": "Soil_Leaves"
    },
    {
      "x": 1,
      "y": 9,
      "z": -2,
      "name": "Furniture_Kweebec_Shelf",
      "rotation": 1
    },
    {
      "x": 1,
      "y": 6,
      "z": -1,
      "name": "Soil_Dirt"
    },
    {
      "x": 1,
      "y": 7,
      "z": -1,
      "name": "Soil_Dirt"
    },
    {
      "x": 1,
      "y": 8,
      "z": -1,
      "name": "Soil_Leaves"
    },
    {
      "x": 1,
      "y": 9,
      "z": -1,
      "name": "Furniture_Kweebec_Shelf",
      "rotation": 1
    },
    {
      "x": 1,
      "y": 6,
      "z": 0,
      "name": "Soil_Dirt"
    },
    {
      "x": 1,
      "y": 7,
      "z": 0,
      "name": "Soil_Dirt"
    },
    {
      "x": 1,
      "y": 8,
      "z": 0,
      "name": "Soil_Grass"
    },
    {
      "x": 1,
      "y": 9,
      "z": 0,
      "name": "Plant_Bush_Arid_Red"
    },
    {
      "x": 1,
      "y": 10,
      "z": 0,
      "name": "Wood_Oak_Branch_Corner",
      "support": 15,
      "rotation": 1
    },
    {
      "x": 1,
      "y": 11,
      "z": 0,
      "name": "Wood_Oak_Branch_Long",
      "support": 15
    },
    {
      "x": 1,
      "y": 12,
      "z": 0,
      "name": "Wood_Oak_Branch_Corner",
      "support": 15,
      "rotation": 11
    },
    {
      "x": 1,
      "y": 6,
      "z": 1,
      "name": "Soil_Dirt"
    },
    {
      "x": 1,
      "y": 7,
      "z": 1,
      "name": "Soil_Dirt"
    },
    {
      "x": 1,
      "y": 8,
      "z": 1,
      "name": "Soil_Grass"
    },
    {
      "x": 1,
      "y": 9,
      "z": 1,
      "name": "Block_Spawner_Block",
      "components": {
        "Components": {
          "BlockSpawner": {
            "BlockSpawnerId": "Zone1_Kweebec_Tier3"
          }
        }
      },
      "rotation": 1
    },
    {
      "x": 1,
      "y": 8,
      "z": 2,
      "name": "Soil_Grass"
    },
    {
      "x": 1,
      "y": 9,
      "z": 2,
      "name": "Wood_Oak_Branch_Short",
      "support": 15,
      "rotation": 1
    },
    {
      "x": 2,
      "y": 8,
      "z": -3,
      "name": "Soil_Leaves"
    },
    {
      "x": 2,
      "y": 8,
      "z": -2,
      "name": "Soil_Leaves"
    },
    {
      "x": 2,
      "y": 9,
      "z": -2,
      "name": "Plant_Grass_Sharp"
    },
    {
      "x": 2,
      "y": 8,
      "z": 0,
      "name": "Soil_Grass"
    },
    {
      "x": 2,
      "y": 8,
      "z": 1,
      "name": "Soil_Grass"
    }
  ],
  "entities": [
    {
      "Components": {
        "Nameplate": {
          "Text": "Kweebec_Merchant"
        },
        "HiddenFromAdventurePlayer": {},
        "SpawnMarkerComponent": {
          "SpawnMarker": "Kweebec_Merchant",
          "RespawnTime": 0.0,
          "SpawnCount": 0,
          "PersistedFlock": {},
          "SpawnPosition": {
            "X": 0.0,
            "Y": 0.0,
            "Z": 0.0
          }
        },
        "Transform": {
          "Position": {
            "X": -0.90264892578125,
            "Y": 10.127189636230469,
            "Z": -2.242340087890625
          },
          "Rotation": {
            "Pitch": 0.0,
            "Yaw": 0.8252253532409668,
            "Roll": 0.0
          }
        },
        "Intangible": {},
        "Model": {
          "Model": {
            "Id": "NPC_Spawn_Marker",
            "Scale": 1.0,
            "Static": false
          }
        },
        "UUID": {
          "UUID": {
            "$binary": "lPakmmMUOtSj9gC0uASZVg==",
            "$type": "04"
          }
        }
      }
    }
  ]
}