{
  "version": 8,
  "blockIdVersion": 10,
  "anchorX": -1,
  "anchorY": 10,
  "anchorZ": 2,
  "blocks": [
    {
      "x": -16,
      "y": 24,
      "z": 0,
      "name": "Plant_Leaves_Jungle"
    },
    {
      "x": -16,
      "y": 25,
      "z": 0,
      "name": "Plant_Leaves_Jungle"
    },
    {
      "x": -16,
      "y": 24,
      "z": 1,
      "name": "Plant_Leaves_Jungle"
    },
    {
      "x": -16,
      "y": 25,
      "z": 1,
      "name": "Plant_Leaves_Jungle"
    },
    {
      "x": -16,
      "y": 26,
      "z": 1,
      "name": "Plant_Leaves_Jungle"
    },
    {
      "x": -16,
      "y": 23,
      "z": 2,
      "name": "Plant_Leaves_Jungle"
    },
    {
      "x": -16,
      "y": 24,
      "z": 2,
      "name": "Plant_Leaves_Jungle"
    },
    {
      "x": -16,
      "y": 25,
      "z": 2,
      "name": "Plant_Leaves_Jungle"
    },
    {
      "x": -16,
      "y": 26,
      "z": 2,
      "name": "Plant_Leaves_Jungle"
    },
    {
      "x": -16,
      "y": 24,
      "z": 3,
      "name": "Plant_Leaves_Jungle"
    },
    {
      "x": -16,
      "y": 25,
      "z": 3,
      "name": "Plant_Leaves_Jungle"
    },
    {
      "x": -15,
      "y": 33,
      "z": -3,
      "name": "Plant_Leaves_Jungle"
    },
    {
      "x": -15,
      "y": 24,
      "z": -2,
      "name": "Plant_Leaves_Jungle"
    },
    {
      "x": -15,
      "y": 26,
      "z": -2,
      "name": "Plant_Leaves_Jungle"
    },
    {
      "x": -15,
      "y": 32,
      "z": -2,
      "name": "Plant_Leaves_Jungle"
    },
    {
      "x": -15,
      "y": 33,
      "z": -2,
      "name": "Plant_Leaves_Jungle"
    },
    {
      "x": -15,
      "y": 34,
      "z": -2,
      "name": "Plant_Leaves_Jungle"
    },
    {
      "x": -15,
      "y": 23,
      "z": -1,
      "name": "Plant_Leaves_Jungle"
    },
    {
      "x": -15,
      "y": 24,
      "z": -1,
      "name": "Plant_Leaves_Jungle"
    },
    {
      "x": -15,
      "y": 25,
      "z": -1,
      "name": "Plant_Leaves_Jungle"
    },
    {
      "x": -15,
      "y": 26,
      "z": -1,
      "name": "Plant_Leaves_Jungle"
    },
    {
      "x": -15,
      "y": 31,
      "z": -1,
      "name": "Plant_Leaves_Jungle"
    },
    {
      "x": -15,
      "y": 32,
      "z": -1,
      "name": "Plant_Leaves_Jungle"
    },
    {
      "x": -15,
      "y": 33,
      "z": -1,
      "name": "Plant_Leaves_Jungle"
    },
    {
      "x": -15,
      "y": 34,
      "z": -1,
      "name": "Plant_Leaves_Jungle"
    },
    {
      "x": -15,
      "y": 35,
      "z": -1,
      "name": "Plant_Leaves_Jungle"
    },
    {
      "x": -15,
      "y": 23,
      "z": 0,
      "name": "Plant_Leaves_Jungle"
    },
    {
      "x": -15,
      "y": 24,
      "z": 0,
      "name": "Plant_Leaves_Jungle"
    },
    {
      "x": -15,
      "y": 25,
      "z": 0,
      "name": "Plant_Leaves_Jungle"
    },
    {
      "x": -15,
      "y": 26,
      "z": 0,
      "name": "Plant_Leaves_Jungle"
    },
    {
      "x": -15,
      "y": 27,
      "z": 0,
      "name": "Plant_Leaves_Jungle"
    },
    {
      "x": -15,
      "y": 32,
      "z": 0,
      "name": "Plant_Leaves_Jungle"
    },
    {
      "x": -15,
      "y": 33,
      "z": 0,
      "name": "Plant_Leaves_Jungle"
    },
    {
      "x": -15,
      "y": 34,
      "z": 0,
      "name": "Plant_Leaves_Jungle"
    },
    {
      "x": -15,
      "y": 35,
      "z": 0,
      "name": "Plant_Leaves_Jungle"
    },
    {
      "x": -15,
      "y": 33,
      "z": 1,
      "name": "Plant_Leaves_Jungle"
    },
    {
      "x": -15,
      "y": 27,
      "z": 2,
      "name": "Plant_Leaves_Jungle"
    },
    {
      "x": -15,
      "y": 25,
      "z": 3,
      "name": "Plant_Leaves_Jungle"
    },
    {
      "x": -15,
      "y": 26,
      "z": 3,
      "name": "Plant_Leaves_Jungle"
    },
    {
      "x": -15,
      "y": 24,
      "z": 4,
      "name": "Plant_Leaves_Jungle"
    },
    {
      "x": -15,
      "y": 25,
      "z": 4,
      "name": "Plant_Leaves_Jungle"
    },
    {
      "x": -14,
      "y": 32,
      "z": -4,
      "name": "Plant_Leaves_Jungle"
    },
    {
      "x": -14,
      "y": 33,
      "z": -4,
      "name": "Plant_Leaves_Jungle"
    },
    {
      "x": -14,
      "y": 34,
      "z": -4,
      "name": "Plant_Leaves_Jungle"
    },
    {
      "x": -14,
      "y": 23,
      "z": -3,
      "name": "Plant_Leaves_Jungle"
    },
    {
      "x": -14,
      "y": 24,
      "z": -3,
      "name": "Plant_Leaves_Jungle"
    },
    {
      "x": -14,
      "y": 25,
      "z": -3,
      "name": "Plant_Leaves_Jungle"
    },
    {
      "x": -14,
      "y": 26,
      "z": -3,
      "name": "Plant_Leaves_Jungle"
    },
    {
      "x": -14,
      "y": 30,
      "z": -3,
      "name": "Plant_Leaves_Jungle"
    },
    {
      "x": -14,
      "y": 31,
      "z": -3,
      "name": "Plant_Leaves_Jungle"
    },
    {
      "x": -14,
      "y": 32,
      "z": -3,
      "name": "Plant_Leaves_Jungle"
    },
    {
      "x": -14,
      "y": 33,
      "z": -3,
      "name": "Plant_Leaves_Jungle"
    },
    {
      "x": -14,
      "y": 34,
      "z": -3,
      "name": "Plant_Leaves_Jungle"
    },
    {
      "x": -14,
      "y": 35,
      "z": -3,
      "name": "Plant_Leaves_Jungle"
    },
    {
      "x": -14,
      "y": 24,
      "z": -2,
      "name": "Plant_Leaves_Jungle"
    },
    {
      "x": -14,
      "y": 25,
      "z": -2,
      "name": "Plant_Leaves_Jungle"
    },
    {
      "x": -14,
      "y": 26,
      "z": -2,
      "name": "Plant_Leaves_Jungle"
    },
    {
      "x": -14,
      "y": 27,
      "z": -2,
      "name": "Plant_Leaves_Jungle"
    },
    {
      "x": -14,
      "y": 33,
      "z": -2,
      "name": "Plant_Leaves_Jungle"
    },
    {
      "x": -14,
      "y": 34,
      "z": -2,
      "name": "Plant_Leaves_Jungle"
    },
    {
      "x": -14,
      "y": 35,
      "z": -2,
      "name": "Plant_Leaves_Jungle"
    },
    {
      "x": -14,
      "y": 27,
      "z": -1,
      "name": "Plant_Leaves_Jungle"
    },
    {
      "x": -14,
      "y": 33,
      "z": -1,
      "name": "Wood_Jungle_Branch_Long",
      "rotation": 5
    },
    {
      "x": -14,
      "y": 35,
      "z": -1,
      "name": "Plant_Leaves_Jungle"
    },
    {
      "x": -14,
      "y": 26,
      "z": 0,
      "name": "Wood_Jungle_Branch_Long",
      "rotation": 5
    },
    {
      "x": -14,
      "y": 27,
      "z": 0,
      "name": "Plant_Leaves_Jungle"
    },
    {
      "x": -14,
      "y": 28,
      "z": 0,
      "name": "Plant_Leaves_Jungle"
    },
    {
      "x": -14,
      "y": 31,
      "z": 0,
      "name": "Plant_Leaves_Jungle"
    },
    {
      "x": -14,
      "y": 33,
      "z": 0,
      "name": "Plant_Leaves_Jungle"
    },
    {
      "x": -14,
      "y": 35,
      "z": 0,
      "name": "Plant_Leaves_Jungle"
    },
    {
      "x": -14,
      "y": 27,
      "z": 1,
      "name": "Plant_Leaves_Jungle"
    },
    {
      "x": -14,
      "y": 30,
      "z": 1,
      "name": "Plant_Leaves_Jungle"
    },
    {
      "x": -14,
      "y": 31,
      "z": 1,
      "name": "Plant_Leaves_Jungle"
    },
    {
      "x": -14,
      "y": 32,
      "z": 1,
      "name": "Plant_Leaves_Jungle"
    },
    {
      "x": -14,
      "y": 33,
      "z": 1,
      "name": "Plant_Leaves_Jungle"
    },
    {
      "x": -14,
      "y": 27,
      "z": 2,
      "name": "Plant_Leaves_Jungle"
    },
    {
      "x": -14,
      "y": 32,
      "z": 2,
      "name": "Plant_Leaves_Jungle"
    },
    {
      "x": -14,
      "y": 33,
      "z": 2,
      "name": "Plant_Leaves_Jungle"
    },
    {
      "x": -14,
      "y": 34,
      "z": 2,
      "name": "Plant_Leaves_Jungle"
    },
    {
      "x": -14,
      "y": 26,
      "z": 3,
      "name": "Wood_Jungle_Branch_Long",
      "rotation": 5
    },
    {
      "x": -14,
      "y": 27,
      "z": 3,
      "name": "Plant_Leaves_Jungle"
    },
    {
      "x": -14,
      "y": 32,
      "z": 3,
      "name": "Plant_Leaves_Jungle"
    },
    {
      "x": -14,
      "y": 33,
      "z": 3,
      "name": "Plant_Leaves_Jungle"
    },
    {
      "x": -14,
      "y": 34,
      "z": 3,
      "name": "Plant_Leaves_Jungle"
    },
    {
      "x": -14,
      "y": 35,
      "z": 3,
      "name": "Plant_Leaves_Jungle"
    },
    {
      "x": -14,
      "y": 25,
      "z": 4,
      "name": "Plant_Leaves_Jungle"
    },
    {
      "x": -14,
      "y": 26,
      "z": 4,
      "name": "Plant_Leaves_Jungle"
    },
    {
      "x": -14,
      "y": 31,
      "z": 4,
      "name": "Plant_Leaves_Jungle"
    },
    {
      "x": -14,
      "y": 32,
      "z": 4,
      "name": "Plant_Leaves_Jungle"
    },
    {
      "x": -14,
      "y": 33,
      "z": 4,
      "name": "Plant_Leaves_Jungle"
    },
    {
      "x": -14,
      "y": 34,
      "z": 4,
      "name": "Plant_Leaves_Jungle"
    },
    {
      "x": -14,
      "y": 35,
      "z": 4,
      "name": "Plant_Leaves_Jungle"
    },
    {
      "x": -14,
      "y": 25,
      "z": 5,
      "name": "Plant_Leaves_Jungle"
    },
    {
      "x": -14,
      "y": 32,
      "z": 5,
      "name": "Plant_Leaves_Jungle"
    },
    {
      "x": -14,
      "y": 33,
      "z": 5,
      "name": "Plant_Leaves_Jungle"
    },
    {
      "x": -14,
      "y": 34,
      "z": 5,
      "name": "Plant_Leaves_Jungle"
    },
    {
      "x": -14,
      "y": 33,
      "z": 6,
      "name": "Plant_Leaves_Jungle"
    },
    {
      "x": -13,
      "y": 0,
      "z": -6,
      "name": "Wood_Jungle_Trunk"
    },
    {
      "x": -13,
      "y": 1,
      "z": -6,
      "name": "Wood_Jungle_Trunk"
    },
    {
      "x": -13,
      "y": 2,
      "z": -6,
      "name": "Wood_Jungle_Trunk"
    },
    {
      "x": -13,
      "y": 3,
      "z": -6,
      "name": "Wood_Jungle_Trunk"
    },
    {
      "x": -13,
      "y": 4,
      "z": -6,
      "name": "Wood_Jungle_Trunk_Full"
    },
    {
      "x": -13,
      "y": 0,
      "z": -5,
      "name": "Wood_Jungle_Trunk"
    },
    {
      "x": -13,
      "y": 1,
      "z": -5,
      "name": "Wood_Jungle_Trunk"
    },
    {
      "x": -13,
      "y": 2,
      "z": -5,
      "name": "Wood_Jungle_Trunk"
    },
    {
      "x": -13,
      "y": 3,
      "z": -5,
      "name": "Wood_Jungle_Trunk"
    },
    {
      "x": -13,
      "y": 4,
      "z": -5,
      "name": "Wood_Jungle_Trunk_Full"
    },
    {
      "x": -13,
      "y": 31,
      "z": -5,
      "name": "Plant_Leaves_Jungle"
    },
    {
      "x": -13,
      "y": 32,
      "z": -5,
      "name": "Plant_Leaves_Jungle"
    },
    {
      "x": -13,
      "y": 33,
      "z": -5,
      "name": "Plant_Leaves_Jungle"
    },
    {
      "x": -13,
      "y": 1,
      "z": -4,
      "name": "Wood_Jungle_Trunk"
    },
    {
      "x": -13,
      "y": 2,
      "z": -4,
      "name": "Wood_Jungle_Trunk_Full"
    },
    {
      "x": -13,
      "y": 24,
      "z": -4,
      "name": "Plant_Leaves_Jungle"
    },
    {
      "x": -13,
      "y": 25,
      "z": -4,
      "name": "Plant_Leaves_Jungle"
    },
    {
      "x": -13,
      "y": 26,
      "z": -4,
      "name": "Plant_Leaves_Jungle"
    },
    {
      "x": -13,
      "y": 31,
      "z": -4,
      "name": "Plant_Leaves_Jungle"
    },
    {
      "x": -13,
      "y": 32,
      "z": -4,
      "name": "Plant_Leaves_Jungle"
    },
    {
      "x": -13,
      "y": 35,
      "z": -4,
      "name": "Plant_Leaves_Jungle"
    },
    {
      "x": -13,
      "y": 23,
      "z": -3,
      "name": "Plant_Leaves_Jungle"
    },
    {
      "x": -13,
      "y": 26,
      "z": -3,
      "name": "Plant_Leaves_Jungle"
    },
    {
      "x": -13,
      "y": 27,
      "z": -3,
      "name": "Plant_Leaves_Jungle"
    },
    {
      "x": -13,
      "y": 35,
      "z": -3,
      "name": "Plant_Leaves_Jungle"
    },
    {
      "x": -13,
      "y": 27,
      "z": -2,
      "name": "Plant_Leaves_Jungle"
    },
    {
      "x": -13,
      "y": 36,
      "z": -2,
      "name": "Plant_Leaves_Jungle"
    },
    {
      "x": -13,
      "y": 28,
      "z": -1,
      "name": "Plant_Leaves_Jungle"
    },
    {
      "x": -13,
      "y": 33,
      "z": -1,
      "name": "Wood_Jungle_Branch_Long",
      "rotation": 5
    },
    {
      "x": -13,
      "y": 36,
      "z": -1,
      "name": "Plant_Leaves_Jungle"
    },
    {
      "x": -13,
      "y": 26,
      "z": 0,
      "name": "Wood_Jungle_Branch_Long",
      "rotation": 5
    },
    {
      "x": -13,
      "y": 28,
      "z": 0,
      "name": "Plant_Leaves_Jungle"
    },
    {
      "x": -13,
      "y": 28,
      "z": 1,
      "name": "Plant_Leaves_Jungle"
    },
    {
      "x": -13,
      "y": 32,
      "z": 1,
      "name": "Plant_Leaves_Jungle"
    },
    {
      "x": -13,
      "y": 34,
      "z": 1,
      "name": "Plant_Leaves_Jungle"
    },
    {
      "x": -13,
      "y": 27,
      "z": 2,
      "name": "Plant_Leaves_Jungle"
    },
    {
      "x": -13,
      "y": 30,
      "z": 2,
      "name": "Plant_Leaves_Jungle"
    },
    {
      "x": -13,
      "y": 31,
      "z": 2,
      "name": "Plant_Leaves_Jungle"
    },
    {
      "x": -13,
      "y": 32,
      "z": 2,
      "name": "Plant_Leaves_Jungle"
    },
    {
      "x": -13,
      "y": 33,
      "z": 2,
      "name": "Plant_Leaves_Jungle"
    },
    {
      "x": -13,
      "y": 34,
      "z": 2,
      "name": "Plant_Leaves_Jungle"
    },
    {
      "x": -13,
      "y": 35,
      "z": 2,
      "name": "Plant_Leaves_Jungle"
    },
    {
      "x": -13,
      "y": 26,
      "z": 3,
      "name": "Wood_Jungle_Branch_Long",
      "rotation": 5
    },
    {
      "x": -13,
      "y": 27,
      "z": 3,
      "name": "Plant_Leaves_Jungle"
    },
    {
      "x": -13,
      "y": 31,
      "z": 3,
      "name": "Plant_Leaves_Jungle"
    },
    {
      "x": -13,
      "y": 33,
      "z": 3,
      "name": "Plant_Leaves_Jungle"
    },
    {
      "x": -13,
      "y": 35,
      "z": 3,
      "name": "Plant_Leaves_Jungle"
    },
    {
      "x": -13,
      "y": 26,
      "z": 4,
      "name": "Plant_Leaves_Jungle"
    },
    {
      "x": -13,
      "y": 27,
      "z": 4,
      "name": "Plant_Leaves_Jungle"
    },
    {
      "x": -13,
      "y": 33,
      "z": 4,
      "name": "Wood_Jungle_Branch_Long",
      "rotation": 5
    },
    {
      "x": -13,
      "y": 35,
      "z": 4,
      "name": "Plant_Leaves_Jungle"
    },
    {
      "x": -13,
      "y": 26,
      "z": 5,
      "name": "Plant_Leaves_Jungle"
    },
    {
      "x": -13,
      "y": 33,
      "z": 5,
      "name": "Plant_Leaves_Jungle"
    },
    {
      "x": -13,
      "y": 34,
      "z": 5,
      "name": "Plant_Leaves_Jungle"
    },
    {
      "x": -13,
      "y": 35,
      "z": 5,
      "name": "Plant_Leaves_Jungle"
    },
    {
      "x": -13,
      "y": 24,
      "z": 6,
      "name": "Plant_Leaves_Jungle"
    },
    {
      "x": -13,
      "y": 25,
      "z": 6,
      "name": "Plant_Leaves_Jungle"
    },
    {
      "x": -13,
      "y": 30,
      "z": 6,
      "name": "Plant_Leaves_Jungle"
    },
    {
      "x": -13,
      "y": 31,
      "z": 6,
      "name": "Plant_Leaves_Jungle"
    },
    {
      "x": -13,
      "y": 32,
      "z": 6,
      "name": "Plant_Leaves_Jungle"
    },
    {
      "x": -13,
      "y": 33,
      "z": 6,
      "name": "Plant_Leaves_Jungle"
    },
    {
      "x": -13,
      "y": 34,
      "z": 6,
      "name": "Plant_Leaves_Jungle"
    },
    {
      "x": -13,
      "y": 35,
      "z": 6,
      "name": "Plant_Leaves_Jungle"
    },
    {
      "x": -13,
      "y": 32,
      "z": 7,
      "name": "Plant_Leaves_Jungle"
    },
    {
      "x": -13,
      "y": 33,
      "z": 7,
      "name": "Plant_Leaves_Jungle"
    },
    {
      "x": -13,
      "y": 34,
      "z": 7,
      "name": "Plant_Leaves_Jungle"
    },
    {
      "x": -12,
      "y": 33,
      "z": -7,
      "name": "Plant_Leaves_Jungle"
    },
    {
      "x": -12,
      "y": 0,
      "z": -6,
      "name": "Wood_Jungle_Trunk"
    },
    {
      "x": -12,
      "y": 1,
      "z": -6,
      "name": "Wood_Jungle_Trunk"
    },
    {
      "x": -12,
      "y": 2,
      "z": -6,
      "name": "Wood_Jungle_Trunk"
    },
    {
      "x": -12,
      "y": 3,
      "z": -6,
      "name": "Wood_Jungle_Trunk"
    },
    {
      "x": -12,
      "y": 4,
      "z": -6,
      "name": "Wood_Jungle_Trunk_Full"
    },
    {
      "x": -12,
      "y": 32,
      "z": -6,
      "name": "Plant_Leaves_Jungle"
    },
    {
      "x": -12,
      "y": 33,
      "z": -6,
      "name": "Plant_Leaves_Jungle"
    },
    {
      "x": -12,
      "y": 34,
      "z": -6,
      "name": "Plant_Leaves_Jungle"
    },
    {
      "x": -12,
      "y": 35,
      "z": -6,
      "name": "Plant_Leaves_Jungle"
    },
    {
      "x": -12,
      "y": 0,
      "z": -5,
      "name": "Wood_Jungle_Trunk"
    },
    {
      "x": -12,
      "y": 1,
      "z": -5,
      "name": "Wood_Jungle_Trunk"
    },
    {
      "x": -12,
      "y": 2,
      "z": -5,
      "name": "Wood_Jungle_Trunk"
    },
    {
      "x": -12,
      "y": 3,
      "z": -5,
      "name": "Wood_Jungle_Trunk"
    },
    {
      "x": -12,
      "y": 4,
      "z": -5,
      "name": "Wood_Jungle_Trunk"
    },
    {
      "x": -12,
      "y": 5,
      "z": -5,
      "name": "Wood_Jungle_Trunk"
    },
    {
      "x": -12,
      "y": 6,
      "z": -5,
      "name": "Wood_Jungle_Trunk"
    },
    {
      "x": -12,
      "y": 7,
      "z": -5,
      "name": "Wood_Jungle_Trunk"
    },
    {
      "x": -12,
      "y": 8,
      "z": -5,
      "name": "Wood_Jungle_Trunk_Full"
    },
    {
      "x": -12,
      "y": 33,
      "z": -5,
      "name": "Plant_Leaves_Jungle"
    },
    {
      "x": -12,
      "y": 34,
      "z": -5,
      "name": "Plant_Leaves_Jungle"
    },
    {
      "x": -12,
      "y": 35,
      "z": -5,
      "name": "Plant_Leaves_Jungle"
    },
    {
      "x": -12,
      "y": 1,
      "z": -4,
      "name": "Wood_Jungle_Trunk"
    },
    {
      "x": -12,
      "y": 2,
      "z": -4,
      "name": "Wood_Jungle_Trunk"
    },
    {
      "x": -12,
      "y": 3,
      "z": -4,
      "name": "Wood_Jungle_Trunk"
    },
    {
      "x": -12,
      "y": 4,
      "z": -4,
      "name": "Wood_Jungle_Trunk"
    },
    {
      "x": -12,
      "y": 5,
      "z": -4,
      "name": "Wood_Jungle_Trunk"
    },
    {
      "x": -12,
      "y": 6,
      "z": -4,
      "name": "Wood_Jungle_Trunk"
    },
    {
      "x": -12,
      "y": 7,
      "z": -4,
      "name": "Wood_Jungle_Trunk_Full"
    },
    {
      "x": -12,
      "y": 23,
      "z": -4,
      "name": "Plant_Leaves_Jungle"
    },
    {
      "x": -12,
      "y": 24,
      "z": -4,
      "name": "Plant_Leaves_Jungle"
    },
    {
      "x": -12,
      "y": 25,
      "z": -4,
      "name": "Plant_Leaves_Jungle"
    },
    {
      "x": -12,
      "y": 26,
      "z": -4,
      "name": "Plant_Leaves_Jungle"
    },
    {
      "x": -12,
      "y": 35,
      "z": -4,
      "name": "Plant_Leaves_Jungle"
    },
    {
      "x": -12,
      "y": 2,
      "z": -3,
      "name": "Wood_Jungle_Trunk"
    },
    {
      "x": -12,
      "y": 3,
      "z": -3,
      "name": "Wood_Jungle_Trunk_Full"
    },
    {
      "x": -12,
      "y": 22,
      "z": -3,
      "name": "Plant_Leaves_Jungle"
    },
    {
      "x": -12,
      "y": 23,
      "z": -3,
      "name": "Plant_Leaves_Jungle"
    },
    {
      "x": -12,
      "y": 26,
      "z": -3,
      "name": "Plant_Leaves_Jungle"
    },
    {
      "x": -12,
      "y": 27,
      "z": -3,
      "name": "Plant_Leaves_Jungle"
    },
    {
      "x": -12,
      "y": 36,
      "z": -3,
      "name": "Plant_Leaves_Jungle"
    },
    {
      "x": -12,
      "y": 28,
      "z": -2,
      "name": "Plant_Leaves_Jungle"
    },
    {
      "x": -12,
      "y": 28,
      "z": -1,
      "name": "Plant_Leaves_Jungle"
    },
    {
      "x": -12,
      "y": 33,
      "z": -1,
      "name": "Wood_Jungle_Trunk_Full"
    },
    {
      "x": -12,
      "y": 36,
      "z": -1,
      "name": "Plant_Leaves_Jungle"
    },
    {
      "x": -12,
      "y": 26,
      "z": 0,
      "name": "Wood_Jungle_Branch_Long",
      "rotation": 5
    },
    {
      "x": -12,
      "y": 28,
      "z": 0,
      "name": "Plant_Leaves_Jungle"
    },
    {
      "x": -12,
      "y": 36,
      "z": 0,
      "name": "Plant_Leaves_Jungle"
    },
    {
      "x": -12,
      "y": 28,
      "z": 1,
      "name": "Plant_Leaves_Jungle"
    },
    {
      "x": -12,
      "y": 31,
      "z": 1,
      "name": "Plant_Leaves_Jungle"
    },
    {
      "x": -12,
      "y": 32,
      "z": 1,
      "name": "Plant_Leaves_Jungle"
    },
    {
      "x": -12,
      "y": 33,
      "z": 1,
      "name": "Plant_Leaves_Jungle"
    },
    {
      "x": -12,
      "y": 34,
      "z": 1,
      "name": "Plant_Leaves_Jungle"
    },
    {
      "x": -12,
      "y": 35,
      "z": 1,
      "name": "Plant_Leaves_Jungle"
    },
    {
      "x": -12,
      "y": 36,
      "z": 1,
      "name": "Plant_Leaves_Jungle"
    },
    {
      "x": -12,
      "y": 33,
      "z": 2,
      "name": "Plant_Leaves_Jungle"
    },
    {
      "x": -12,
      "y": 34,
      "z": 2,
      "name": "Plant_Leaves_Jungle"
    },
    {
      "x": -12,
      "y": 35,
      "z": 2,
      "name": "Plant_Leaves_Jungle"
    },
    {
      "x": -12,
      "y": 26,
      "z": 3,
      "name": "Wood_Jungle_Branch_Long",
      "rotation": 5
    },
    {
      "x": -12,
      "y": 27,
      "z": 3,
      "name": "Plant_Leaves_Jungle"
    },
    {
      "x": -12,
      "y": 28,
      "z": 3,
      "name": "Plant_Leaves_Jungle"
    },
    {
      "x": -12,
      "y": 34,
      "z": 3,
      "name": "Plant_Leaves_Jungle"
    },
    {
      "x": -12,
      "y": 35,
      "z": 3,
      "name": "Plant_Leaves_Jungle"
    },
    {
      "x": -12,
      "y": 26,
      "z": 4,
      "name": "Plant_Leaves_Jungle"
    },
    {
      "x": -12,
      "y": 27,
      "z": 4,
      "name": "Plant_Leaves_Jungle"
    },
    {
      "x": -12,
      "y": 33,
      "z": 4,
      "name": "Wood_Jungle_Branch_Long",
      "rotation": 5
    },
    {
      "x": -12,
      "y": 36,
      "z": 4,
      "name": "Plant_Leaves_Jungle"
    },
    {
      "x": -12,
      "y": 26,
      "z": 5,
      "name": "Plant_Leaves_Jungle"
    },
    {
      "x": -12,
      "y": 36,
      "z": 5,
      "name": "Plant_Leaves_Jungle"
    },
    {
      "x": -12,
      "y": 24,
      "z": 6,
      "name": "Plant_Leaves_Jungle"
    },
    {
      "x": -12,
      "y": 25,
      "z": 6,
      "name": "Plant_Leaves_Jungle"
    },
    {
      "x": -12,
      "y": 26,
      "z": 6,
      "name": "Plant_Leaves_Jungle"
    },
    {
      "x": -12,
      "y": 35,
      "z": 6,
      "name": "Plant_Leaves_Jungle"
    },
    {
      "x": -12,
      "y": 1,
      "z": 7,
      "name": "Wood_Jungle_Trunk"
    },
    {
      "x": -12,
      "y": 2,
      "z": 7,
      "name": "Wood_Jungle_Trunk_Full"
    },
    {
      "x": -12,
      "y": 31,
      "z": 7,
      "name": "Plant_Leaves_Jungle"
    },
    {
      "x": -12,
      "y": 32,
      "z": 7,
      "name": "Plant_Leaves_Jungle"
    },
    {
      "x": -12,
      "y": 35,
      "z": 7,
      "name": "Plant_Leaves_Jungle"
    },
    {
      "x": -12,
      "y": 0,
      "z": 8,
      "name": "Wood_Jungle_Trunk"
    },
    {
      "x": -12,
      "y": 1,
      "z": 8,
      "name": "Wood_Jungle_Trunk"
    },
    {
      "x": -12,
      "y": 2,
      "z": 8,
      "name": "Wood_Jungle_Trunk"
    },
    {
      "x": -12,
      "y": 3,
      "z": 8,
      "name": "Wood_Jungle_Trunk"
    },
    {
      "x": -12,
      "y": 4,
      "z": 8,
      "name": "Wood_Jungle_Trunk_Full"
    },
    {
      "x": -12,
      "y": 31,
      "z": 8,
      "name": "Plant_Leaves_Jungle"
    },
    {
      "x": -12,
      "y": 32,
      "z": 8,
      "name": "Plant_Leaves_Jungle"
    },
    {
      "x": -12,
      "y": 33,
      "z": 8,
      "name": "Plant_Leaves_Jungle"
    },
    {
      "x": -12,
      "y": 0,
      "z": 9,
      "name": "Wood_Jungle_Trunk"
    },
    {
      "x": -12,
      "y": 1,
      "z": 9,
      "name": "Wood_Jungle_Trunk"
    },
    {
      "x": -12,
      "y": 2,
      "z": 9,
      "name": "Wood_Jungle_Trunk"
    },
    {
      "x": -12,
      "y": 3,
      "z": 9,
      "name": "Wood_Jungle_Trunk"
    },
    {
      "x": -12,
      "y": 4,
      "z": 9,
      "name": "Wood_Jungle_Trunk_Full"
    },
    {
      "x": -11,
      "y": 32,
      "z": -7,
      "name": "Plant_Leaves_Jungle"
    },
    {
      "x": -11,
      "y": 34,
      "z": -7,
      "name": "Plant_Leaves_Jungle"
    },
    {
      "x": -11,
      "y": 1,
      "z": -6,
      "name": "Wood_Jungle_Trunk"
    },
    {
      "x": -11,
      "y": 2,
      "z": -6,
      "name": "Wood_Jungle_Trunk_Full"
    },
    {
      "x": -11,
      "y": 32,
      "z": -6,
      "name": "Plant_Leaves_Jungle"
    },
    {
      "x": -11,
      "y": 33,
      "z": -6,
      "name": "Plant_Leaves_Jungle"
    },
    {
      "x": -11,
      "y": 34,
      "z": -6,
      "name": "Plant_Leaves_Jungle"
    },
    {
      "x": -11,
      "y": 35,
      "z": -6,
      "name": "Plant_Leaves_Jungle"
    },
    {
      "x": -11,
      "y": 1,
      "z": -5,
      "name": "Wood_Jungle_Trunk"
    },
    {
      "x": -11,
      "y": 2,
      "z": -5,
      "name": "Wood_Jungle_Trunk"
    },
    {
      "x": -11,
      "y": 3,
      "z": -5,
      "name": "Wood_Jungle_Trunk"
    },
    {
      "x": -11,
      "y": 4,
      "z": -5,
      "name": "Wood_Jungle_Trunk"
    },
    {
      "x": -11,
      "y": 5,
      "z": -5,
      "name": "Wood_Jungle_Trunk"
    },
    {
      "x": -11,
      "y": 6,
      "z": -5,
      "name": "Wood_Jungle_Trunk"
    },
    {
      "x": -11,
      "y": 7,
      "z": -5,
      "name": "Wood_Jungle_Trunk_Full"
    },
    {
      "x": -11,
      "y": 33,
      "z": -5,
      "name": "Wood_Jungle_Branch_Corner",
      "rotation": 2
    },
    {
      "x": -11,
      "y": 36,
      "z": -5,
      "name": "Plant_Leaves_Jungle"
    },
    {
      "x": -11,
      "y": 1,
      "z": -4,
      "name": "Wood_Jungle_Trunk"
    },
    {
      "x": -11,
      "y": 2,
      "z": -4,
      "name": "Wood_Jungle_Trunk"
    },
    {
      "x": -11,
      "y": 3,
      "z": -4,
      "name": "Wood_Jungle_Trunk"
    },
    {
      "x": -11,
      "y": 4,
      "z": -4,
      "name": "Wood_Jungle_Trunk"
    },
    {
      "x": -11,
      "y": 5,
      "z": -4,
      "name": "Wood_Jungle_Trunk"
    },
    {
      "x": -11,
      "y": 6,
      "z": -4,
      "name": "Wood_Jungle_Trunk"
    },
    {
      "x": -11,
      "y": 7,
      "z": -4,
      "name": "Wood_Jungle_Trunk"
    },
    {
      "x": -11,
      "y": 8,
      "z": -4,
      "name": "Wood_Jungle_Trunk"
    },
    {
      "x": -11,
      "y": 9,
      "z": -4,
      "name": "Wood_Jungle_Trunk"
    },
    {
      "x": -11,
      "y": 10,
      "z": -4,
      "name": "Wood_Jungle_Trunk_Full"
    },
    {
      "x": -11,
      "y": 24,
      "z": -4,
      "name": "Plant_Leaves_Jungle"
    },
    {
      "x": -11,
      "y": 25,
      "z": -4,
      "name": "Plant_Leaves_Jungle"
    },
    {
      "x": -11,
      "y": 26,
      "z": -4,
      "name": "Plant_Leaves_Jungle"
    },
    {
      "x": -11,
      "y": 33,
      "z": -4,
      "name": "Wood_Jungle_Branch_Long",
      "rotation": 4
    },
    {
      "x": -11,
      "y": 2,
      "z": -3,
      "name": "Wood_Jungle_Trunk"
    },
    {
      "x": -11,
      "y": 3,
      "z": -3,
      "name": "Wood_Jungle_Trunk"
    },
    {
      "x": -11,
      "y": 4,
      "z": -3,
      "name": "Wood_Jungle_Trunk"
    },
    {
      "x": -11,
      "y": 5,
      "z": -3,
      "name": "Wood_Jungle_Trunk"
    },
    {
      "x": -11,
      "y": 6,
      "z": -3,
      "name": "Wood_Jungle_Trunk"
    },
    {
      "x": -11,
      "y": 7,
      "z": -3,
      "name": "Wood_Jungle_Trunk"
    },
    {
      "x": -11,
      "y": 8,
      "z": -3,
      "name": "Wood_Jungle_Trunk"
    },
    {
      "x": -11,
      "y": 9,
      "z": -3,
      "name": "Wood_Jungle_Trunk_Full"
    },
    {
      "x": -11,
      "y": 26,
      "z": -3,
      "name": "Plant_Leaves_Jungle"
    },
    {
      "x": -11,
      "y": 27,
      "z": -3,
      "name": "Plant_Leaves_Jungle"
    },
    {
      "x": -11,
      "y": 28,
      "z": -3,
      "name": "Plant_Leaves_Jungle"
    },
    {
      "x": -11,
      "y": 33,
      "z": -3,
      "name": "Wood_Jungle_Branch_Long",
      "rotation": 4
    },
    {
      "x": -11,
      "y": 36,
      "z": -3,
      "name": "Plant_Leaves_Jungle"
    },
    {
      "x": -11,
      "y": 3,
      "z": -2,
      "name": "Wood_Jungle_Trunk"
    },
    {
      "x": -11,
      "y": 4,
      "z": -2,
      "name": "Wood_Jungle_Trunk"
    },
    {
      "x": -11,
      "y": 5,
      "z": -2,
      "name": "Wood_Jungle_Trunk"
    },
    {
      "x": -11,
      "y": 6,
      "z": -2,
      "name": "Wood_Jungle_Trunk_Full"
    },
    {
      "x": -11,
      "y": 26,
      "z": -2,
      "name": "Wood_Jungle_Branch_Long",
      "rotation": 4
    },
    {
      "x": -11,
      "y": 28,
      "z": -2,
      "name": "Plant_Leaves_Jungle"
    },
    {
      "x": -11,
      "y": 33,
      "z": -2,
      "name": "Wood_Jungle_Trunk_Full"
    },
    {
      "x": -11,
      "y": 34,
      "z": -2,
      "name": "Wood_Jungle_Branch_Long"
    },
    {
      "x": -11,
      "y": 36,
      "z": -2,
      "name": "Plant_Leaves_Jungle"
    },
    {
      "x": -11,
      "y": 4,
      "z": -1,
      "name": "Wood_Jungle_Trunk"
    },
    {
      "x": -11,
      "y": 5,
      "z": -1,
      "name": "Wood_Jungle_Trunk_Full"
    },
    {
      "x": -11,
      "y": 26,
      "z": -1,
      "name": "Wood_Jungle_Branch_Long",
      "rotation": 4
    },
    {
      "x": -11,
      "y": 28,
      "z": -1,
      "name": "Plant_Leaves_Jungle"
    },
    {
      "x": -11,
      "y": 33,
      "z": -1,
      "name": "Wood_Jungle_Trunk_Full"
    },
    {
      "x": -11,
      "y": 36,
      "z": -1,
      "name": "Plant_Leaves_Jungle"
    },
    {
      "x": -11,
      "y": 26,
      "z": 0,
      "name": "Wood_Jungle_Trunk_Full"
    },
    {
      "x": -11,
      "y": 27,
      "z": 0,
      "name": "Wood_Jungle_Branch_Long"
    },
    {
      "x": -11,
      "y": 28,
      "z": 0,
      "name": "Plant_Leaves_Jungle"
    },
    {
      "x": -11,
      "y": 33,
      "z": 0,
      "name": "Wood_Jungle_Branch_Corner"
    },
    {
      "x": -11,
      "y": 34,
      "z": 0,
      "name": "Plant_Leaves_Jungle"
    },
    {
      "x": -11,
      "y": 35,
      "z": 0,
      "name": "Plant_Leaves_Jungle"
    },
    {
      "x": -11,
      "y": 36,
      "z": 0,
      "name": "Plant_Leaves_Jungle"
    },
    {
      "x": -11,
      "y": 25,
      "z": 1,
      "name": "Wood_Jungle_Trunk_Full"
    },
    {
      "x": -11,
      "y": 26,
      "z": 1,
      "name": "Wood_Jungle_Trunk_Full"
    },
    {
      "x": -11,
      "y": 28,
      "z": 1,
      "name": "Plant_Leaves_Jungle"
    },
    {
      "x": -11,
      "y": 33,
      "z": 1,
      "name": "Plant_Leaves_Jungle"
    },
    {
      "x": -11,
      "y": 34,
      "z": 1,
      "name": "Plant_Leaves_Jungle"
    },
    {
      "x": -11,
      "y": 35,
      "z": 1,
      "name": "Plant_Leaves_Jungle"
    },
    {
      "x": -11,
      "y": 36,
      "z": 1,
      "name": "Plant_Leaves_Jungle"
    },
    {
      "x": -11,
      "y": 26,
      "z": 2,
      "name": "Wood_Jungle_Trunk_Full"
    },
    {
      "x": -11,
      "y": 28,
      "z": 2,
      "name": "Plant_Leaves_Jungle"
    },
    {
      "x": -11,
      "y": 33,
      "z": 2,
      "name": "Plant_Leaves_Jungle"
    },
    {
      "x": -11,
      "y": 34,
      "z": 2,
      "name": "Plant_Leaves_Jungle"
    },
    {
      "x": -11,
      "y": 35,
      "z": 2,
      "name": "Plant_Leaves_Jungle"
    },
    {
      "x": -11,
      "y": 36,
      "z": 2,
      "name": "Plant_Leaves_Jungle"
    },
    {
      "x": -11,
      "y": 26,
      "z": 3,
      "name": "Wood_Jungle_Trunk_Full"
    },
    {
      "x": -11,
      "y": 27,
      "z": 3,
      "name": "Plant_Leaves_Jungle"
    },
    {
      "x": -11,
      "y": 28,
      "z": 3,
      "name": "Plant_Leaves_Jungle"
    },
    {
      "x": -11,
      "y": 34,
      "z": 3,
      "name": "Plant_Leaves_Jungle"
    },
    {
      "x": -11,
      "y": 35,
      "z": 3,
      "name": "Plant_Leaves_Jungle"
    },
    {
      "x": -11,
      "y": 36,
      "z": 3,
      "name": "Plant_Leaves_Jungle"
    },
    {
      "x": -11,
      "y": 27,
      "z": 4,
      "name": "Plant_Leaves_Jungle"
    },
    {
      "x": -11,
      "y": 33,
      "z": 4,
      "name": "Wood_Jungle_Trunk_Full"
    },
    {
      "x": -11,
      "y": 36,
      "z": 4,
      "name": "Plant_Leaves_Jungle"
    },
    {
      "x": -11,
      "y": 26,
      "z": 5,
      "name": "Plant_Leaves_Jungle"
    },
    {
      "x": -11,
      "y": 27,
      "z": 5,
      "name": "Plant_Leaves_Jungle"
    },
    {
      "x": -11,
      "y": 2,
      "z": 6,
      "name": "Wood_Jungle_Trunk"
    },
    {
      "x": -11,
      "y": 3,
      "z": 6,
      "name": "Wood_Jungle_Trunk"
    },
    {
      "x": -11,
      "y": 4,
      "z": 6,
      "name": "Wood_Jungle_Trunk"
    },
    {
      "x": -11,
      "y": 5,
      "z": 6,
      "name": "Wood_Jungle_Trunk_Full"
    },
    {
      "x": -11,
      "y": 36,
      "z": 6,
      "name": "Plant_Leaves_Jungle"
    },
    {
      "x": -11,
      "y": 1,
      "z": 7,
      "name": "Wood_Jungle_Trunk"
    },
    {
      "x": -11,
      "y": 2,
      "z": 7,
      "name": "Wood_Jungle_Trunk"
    },
    {
      "x": -11,
      "y": 3,
      "z": 7,
      "name": "Wood_Jungle_Trunk"
    },
    {
      "x": -11,
      "y": 4,
      "z": 7,
      "name": "Wood_Jungle_Trunk"
    },
    {
      "x": -11,
      "y": 5,
      "z": 7,
      "name": "Wood_Jungle_Trunk"
    },
    {
      "x": -11,
      "y": 6,
      "z": 7,
      "name": "Wood_Jungle_Trunk"
    },
    {
      "x": -11,
      "y": 7,
      "z": 7,
      "name": "Wood_Jungle_Trunk_Full"
    },
    {
      "x": -11,
      "y": 35,
      "z": 7,
      "name": "Plant_Leaves_Jungle"
    },
    {
      "x": -11,
      "y": 0,
      "z": 8,
      "name": "Wood_Jungle_Trunk"
    },
    {
      "x": -11,
      "y": 1,
      "z": 8,
      "name": "Wood_Jungle_Trunk"
    },
    {
      "x": -11,
      "y": 2,
      "z": 8,
      "name": "Wood_Jungle_Trunk"
    },
    {
      "x": -11,
      "y": 3,
      "z": 8,
      "name": "Wood_Jungle_Trunk"
    },
    {
      "x": -11,
      "y": 4,
      "z": 8,
      "name": "Wood_Jungle_Trunk"
    },
    {
      "x": -11,
      "y": 5,
      "z": 8,
      "name": "Wood_Jungle_Trunk"
    },
    {
      "x": -11,
      "y": 6,
      "z": 8,
      "name": "Wood_Jungle_Trunk"
    },
    {
      "x": -11,
      "y": 7,
      "z": 8,
      "name": "Wood_Jungle_Trunk"
    },
    {
      "x": -11,
      "y": 8,
      "z": 8,
      "name": "Wood_Jungle_Trunk_Full"
    },
    {
      "x": -11,
      "y": 33,
      "z": 8,
      "name": "Plant_Leaves_Jungle"
    },
    {
      "x": -11,
      "y": 34,
      "z": 8,
      "name": "Plant_Leaves_Jungle"
    },
    {
      "x": -11,
      "y": 35,
      "z": 8,
      "name": "Plant_Leaves_Jungle"
    },
    {
      "x": -11,
      "y": 0,
      "z": 9,
      "name": "Wood_Jungle_Trunk"
    },
    {
      "x": -11,
      "y": 1,
      "z": 9,
      "name": "Wood_Jungle_Trunk"
    },
    {
      "x": -11,
      "y": 2,
      "z": 9,
      "name": "Wood_Jungle_Trunk"
    },
    {
      "x": -11,
      "y": 3,
      "z": 9,
      "name": "Wood_Jungle_Trunk"
    },
    {
      "x": -11,
      "y": 4,
      "z": 9,
      "name": "Wood_Jungle_Trunk_Full"
    },
    {
      "x": -11,
      "y": 32,
      "z": 9,
      "name": "Plant_Leaves_Jungle"
    },
    {
      "x": -11,
      "y": 33,
      "z": 9,
      "name": "Plant_Leaves_Jungle"
    },
    {
      "x": -11,
      "y": 34,
      "z": 9,
      "name": "Plant_Leaves_Jungle"
    },
    {
      "x": -11,
      "y": 35,
      "z": 9,
      "name": "Plant_Leaves_Jungle"
    },
    {
      "x": -11,
      "y": 33,
      "z": 10,
      "name": "Plant_Leaves_Jungle"
    },
    {
      "x": -10,
      "y": 34,
      "z": -8,
      "name": "Plant_Leaves_Jungle"
    },
    {
      "x": -10,
      "y": 33,
      "z": -7,
      "name": "Plant_Leaves_Jungle"
    },
    {
      "x": -10,
      "y": 34,
      "z": -7,
      "name": "Plant_Leaves_Jungle"
    },
    {
      "x": -10,
      "y": 35,
      "z": -7,
      "name": "Plant_Leaves_Jungle"
    },
    {
      "x": -10,
      "y": 35,
      "z": -6,
      "name": "Plant_Leaves_Jungle"
    },
    {
      "x": -10,
      "y": 36,
      "z": -6,
      "name": "Plant_Leaves_Jungle"
    },
    {
      "x": -10,
      "y": 2,
      "z": -5,
      "name": "Wood_Jungle_Trunk"
    },
    {
      "x": -10,
      "y": 3,
      "z": -5,
      "name": "Wood_Jungle_Trunk_Full"
    },
    {
      "x": -10,
      "y": 36,
      "z": -5,
      "name": "Plant_Leaves_Jungle"
    },
    {
      "x": -10,
      "y": 1,
      "z": -4,
      "name": "Wood_Jungle_Trunk"
    },
    {
      "x": -10,
      "y": 2,
      "z": -4,
      "name": "Wood_Jungle_Trunk"
    },
    {
      "x": -10,
      "y": 3,
      "z": -4,
      "name": "Wood_Jungle_Trunk"
    },
    {
      "x": -10,
      "y": 4,
      "z": -4,
      "name": "Wood_Jungle_Trunk"
    },
    {
      "x": -10,
      "y": 5,
      "z": -4,
      "name": "Wood_Jungle_Trunk"
    },
    {
      "x": -10,
      "y": 6,
      "z": -4,
      "name": "Wood_Jungle_Trunk"
    },
    {
      "x": -10,
      "y": 7,
      "z": -4,
      "name": "Wood_Jungle_Trunk"
    },
    {
      "x": -10,
      "y": 8,
      "z": -4,
      "name": "Wood_Jungle_Trunk"
    },
    {
      "x": -10,
      "y": 9,
      "z": -4,
      "name": "Wood_Jungle_Trunk_Full"
    },
    {
      "x": -10,
      "y": 24,
      "z": -4,
      "name": "Plant_Leaves_Jungle"
    },
    {
      "x": -10,
      "y": 25,
      "z": -4,
      "name": "Plant_Leaves_Jungle"
    },
    {
      "x": -10,
      "y": 36,
      "z": -4,
      "name": "Plant_Leaves_Jungle"
    },
    {
      "x": -10,
      "y": 2,
      "z": -3,
      "name": "Wood_Jungle_Trunk"
    },
    {
      "x": -10,
      "y": 3,
      "z": -3,
      "name": "Wood_Jungle_Trunk"
    },
    {
      "x": -10,
      "y": 4,
      "z": -3,
      "name": "Wood_Jungle_Trunk"
    },
    {
      "x": -10,
      "y": 5,
      "z": -3,
      "name": "Wood_Jungle_Trunk"
    },
    {
      "x": -10,
      "y": 6,
      "z": -3,
      "name": "Wood_Jungle_Trunk"
    },
    {
      "x": -10,
      "y": 7,
      "z": -3,
      "name": "Wood_Jungle_Trunk"
    },
    {
      "x": -10,
      "y": 8,
      "z": -3,
      "name": "Wood_Jungle_Trunk"
    },
    {
      "x": -10,
      "y": 9,
      "z": -3,
      "name": "Wood_Jungle_Trunk"
    },
    {
      "x": -10,
      "y": 10,
      "z": -3,
      "name": "Wood_Jungle_Trunk"
    },
    {
      "x": -10,
      "y": 11,
      "z": -3,
      "name": "Wood_Jungle_Trunk"
    },
    {
      "x": -10,
      "y": 12,
      "z": -3,
      "name": "Wood_Jungle_Trunk_Full"
    },
    {
      "x": -10,
      "y": 26,
      "z": -3,
      "name": "Plant_Leaves_Jungle"
    },
    {
      "x": -10,
      "y": 28,
      "z": -3,
      "name": "Plant_Leaves_Jungle"
    },
    {
      "x": -10,
      "y": 36,
      "z": -3,
      "name": "Plant_Leaves_Jungle"
    },
    {
      "x": -10,
      "y": 3,
      "z": -2,
      "name": "Wood_Jungle_Trunk"
    },
    {
      "x": -10,
      "y": 4,
      "z": -2,
      "name": "Wood_Jungle_Trunk"
    },
    {
      "x": -10,
      "y": 5,
      "z": -2,
      "name": "Wood_Jungle_Trunk"
    },
    {
      "x": -10,
      "y": 6,
      "z": -2,
      "name": "Wood_Jungle_Trunk"
    },
    {
      "x": -10,
      "y": 7,
      "z": -2,
      "name": "Wood_Jungle_Trunk"
    },
    {
      "x": -10,
      "y": 8,
      "z": -2,
      "name": "Wood_Jungle_Trunk"
    },
    {
      "x": -10,
      "y": 9,
      "z": -2,
      "name": "Wood_Jungle_Trunk"
    },
    {
      "x": -10,
      "y": 10,
      "z": -2,
      "name": "Wood_Jungle_Trunk"
    },
    {
      "x": -10,
      "y": 11,
      "z": -2,
      "name": "Wood_Jungle_Trunk_Full"
    },
    {
      "x": -10,
      "y": 28,
      "z": -2,
      "name": "Plant_Leaves_Jungle"
    },
    {
      "x": -10,
      "y": 33,
      "z": -2,
      "name": "Wood_Jungle_Trunk_Full"
    },
    {
      "x": -10,
      "y": 36,
      "z": -2,
      "name": "Plant_Leaves_Jungle"
    },
    {
      "x": -10,
      "y": 4,
      "z": -1,
      "name": "Wood_Jungle_Trunk"
    },
    {
      "x": -10,
      "y": 5,
      "z": -1,
      "name": "Wood_Jungle_Trunk"
    },
    {
      "x": -10,
      "y": 6,
      "z": -1,
      "name": "Wood_Jungle_Trunk"
    },
    {
      "x": -10,
      "y": 7,
      "z": -1,
      "name": "Wood_Jungle_Trunk"
    },
    {
      "x": -10,
      "y": 8,
      "z": -1,
      "name": "Wood_Jungle_Trunk"
    },
    {
      "x": -10,
      "y": 9,
      "z": -1,
      "name": "Wood_Jungle_Trunk_Full"
    },
    {
      "x": -10,
      "y": 28,
      "z": -1,
      "name": "Plant_Leaves_Jungle"
    },
    {
      "x": -10,
      "y": 36,
      "z": -1,
      "name": "Plant_Leaves_Jungle"
    },
    {
      "x": -10,
      "y": 6,
      "z": 0,
      "name": "Wood_Jungle_Trunk"
    },
    {
      "x": -10,
      "y": 7,
      "z": 0,
      "name": "Wood_Jungle_Trunk_Full"
    },
    {
      "x": -10,
      "y": 28,
      "z": 0,
      "name": "Plant_Leaves_Jungle"
    },
    {
      "x": -10,
      "y": 34,
      "z": 0,
      "name": "Plant_Leaves_Jungle"
    },
    {
      "x": -10,
      "y": 35,
      "z": 0,
      "name": "Plant_Leaves_Jungle"
    },
    {
      "x": -10,
      "y": 25,
      "z": 1,
      "name": "Wood_Jungle_Trunk_Full"
    },
    {
      "x": -10,
      "y": 33,
      "z": 1,
      "name": "Plant_Leaves_Jungle"
    },
    {
      "x": -10,
      "y": 36,
      "z": 1,
      "name": "Plant_Leaves_Jungle"
    },
    {
      "x": -10,
      "y": 28,
      "z": 2,
      "name": "Plant_Leaves_Jungle"
    },
    {
      "x": -10,
      "y": 34,
      "z": 2,
      "name": "Plant_Leaves_Jungle"
    },
    {
      "x": -10,
      "y": 35,
      "z": 2,
      "name": "Plant_Leaves_Jungle"
    },
    {
      "x": -10,
      "y": 36,
      "z": 2,
      "name": "Plant_Leaves_Jungle"
    },
    {
      "x": -10,
      "y": 28,
      "z": 3,
      "name": "Plant_Leaves_Jungle"
    },
    {
      "x": -10,
      "y": 33,
      "z": 3,
      "name": "Wood_Jungle_Branch_Corner",
      "rotation": 2
    },
    {
      "x": -10,
      "y": 35,
      "z": 3,
      "name": "Plant_Leaves_Jungle"
    },
    {
      "x": -10,
      "y": 36,
      "z": 3,
      "name": "Plant_Leaves_Jungle"
    },
    {
      "x": -10,
      "y": 6,
      "z": 4,
      "name": "Wood_Jungle_Trunk"
    },
    {
      "x": -10,
      "y": 7,
      "z": 4,
      "name": "Wood_Jungle_Trunk_Full"
    },
    {
      "x": -10,
      "y": 27,
      "z": 4,
      "name": "Plant_Leaves_Jungle"
    },
    {
      "x": -10,
      "y": 33,
      "z": 4,
      "name": "Wood_Jungle_Trunk_Full"
    },
    {
      "x": -10,
      "y": 36,
      "z": 4,
      "name": "Plant_Leaves_Jungle"
    },
    {
      "x": -10,
      "y": 3,
      "z": 5,
      "name": "Wood_Jungle_Trunk"
    },
    {
      "x": -10,
      "y": 4,
      "z": 5,
      "name": "Wood_Jungle_Trunk"
    },
    {
      "x": -10,
      "y": 5,
      "z": 5,
      "name": "Wood_Jungle_Trunk"
    },
    {
      "x": -10,
      "y": 6,
      "z": 5,
      "name": "Wood_Jungle_Trunk"
    },
    {
      "x": -10,
      "y": 7,
      "z": 5,
      "name": "Wood_Jungle_Trunk_Full"
    },
    {
      "x": -10,
      "y": 27,
      "z": 5,
      "name": "Plant_Leaves_Jungle"
    },
    {
      "x": -10,
      "y": 33,
      "z": 5,
      "name": "Wood_Jungle_Trunk_Full"
    },
    {
      "x": -10,
      "y": 34,
      "z": 5,
      "name": "Wood_Jungle_Branch_Long"
    },
    {
      "x": -10,
      "y": 36,
      "z": 5,
      "name": "Plant_Leaves_Jungle"
    },
    {
      "x": -10,
      "y": 2,
      "z": 6,
      "name": "Wood_Jungle_Trunk"
    },
    {
      "x": -10,
      "y": 3,
      "z": 6,
      "name": "Wood_Jungle_Trunk"
    },
    {
      "x": -10,
      "y": 4,
      "z": 6,
      "name": "Wood_Jungle_Trunk"
    },
    {
      "x": -10,
      "y": 5,
      "z": 6,
      "name": "Wood_Jungle_Trunk"
    },
    {
      "x": -10,
      "y": 6,
      "z": 6,
      "name": "Wood_Jungle_Trunk"
    },
    {
      "x": -10,
      "y": 7,
      "z": 6,
      "name": "Wood_Jungle_Trunk"
    },
    {
      "x": -10,
      "y": 8,
      "z": 6,
      "name": "Wood_Jungle_Trunk"
    },
    {
      "x": -10,
      "y": 9,
      "z": 6,
      "name": "Wood_Jungle_Trunk_Full"
    },
    {
      "x": -10,
      "y": 33,
      "z": 6,
      "name": "Wood_Jungle_Branch_Long",
      "rotation": 4
    },
    {
      "x": -10,
      "y": 36,
      "z": 6,
      "name": "Plant_Leaves_Jungle"
    },
    {
      "x": -10,
      "y": 1,
      "z": 7,
      "name": "Wood_Jungle_Trunk"
    },
    {
      "x": -10,
      "y": 2,
      "z": 7,
      "name": "Wood_Jungle_Trunk"
    },
    {
      "x": -10,
      "y": 3,
      "z": 7,
      "name": "Wood_Jungle_Trunk"
    },
    {
      "x": -10,
      "y": 4,
      "z": 7,
      "name": "Wood_Jungle_Trunk"
    },
    {
      "x": -10,
      "y": 5,
      "z": 7,
      "name": "Wood_Jungle_Trunk"
    },
    {
      "x": -10,
      "y": 6,
      "z": 7,
      "name": "Wood_Jungle_Trunk"
    },
    {
      "x": -10,
      "y": 7,
      "z": 7,
      "name": "Wood_Jungle_Trunk"
    },
    {
      "x": -10,
      "y": 8,
      "z": 7,
      "name": "Wood_Jungle_Trunk"
    },
    {
      "x": -10,
      "y": 9,
      "z": 7,
      "name": "Wood_Jungle_Trunk"
    },
    {
      "x": -10,
      "y": 10,
      "z": 7,
      "name": "Wood_Jungle_Trunk_Full"
    },
    {
      "x": -10,
      "y": 33,
      "z": 7,
      "name": "Wood_Jungle_Branch_Long",
      "rotation": 4
    },
    {
      "x": -10,
      "y": 1,
      "z": 8,
      "name": "Wood_Jungle_Trunk"
    },
    {
      "x": -10,
      "y": 2,
      "z": 8,
      "name": "Wood_Jungle_Trunk"
    },
    {
      "x": -10,
      "y": 3,
      "z": 8,
      "name": "Wood_Jungle_Trunk"
    },
    {
      "x": -10,
      "y": 4,
      "z": 8,
      "name": "Wood_Jungle_Trunk"
    },
    {
      "x": -10,
      "y": 5,
      "z": 8,
      "name": "Wood_Jungle_Trunk"
    },
    {
      "x": -10,
      "y": 6,
      "z": 8,
      "name": "Wood_Jungle_Trunk"
    },
    {
      "x": -10,
      "y": 7,
      "z": 8,
      "name": "Wood_Jungle_Trunk_Full"
    },
    {
      "x": -10,
      "y": 33,
      "z": 8,
      "name": "Wood_Jungle_Branch_Corner"
    },
    {
      "x": -10,
      "y": 36,
      "z": 8,
      "name": "Plant_Leaves_Jungle"
    },
    {
      "x": -10,
      "y": 1,
      "z": 9,
      "name": "Wood_Jungle_Trunk"
    },
    {
      "x": -10,
      "y": 2,
      "z": 9,
      "name": "Wood_Jungle_Trunk_Full"
    },
    {
      "x": -10,
      "y": 32,
      "z": 9,
      "name": "Plant_Leaves_Jungle"
    },
    {
      "x": -10,
      "y": 33,
      "z": 9,
      "name": "Plant_Leaves_Jungle"
    },
    {
      "x": -10,
      "y": 34,
      "z": 9,
      "name": "Plant_Leaves_Jungle"
    },
    {
      "x": -10,
      "y": 35,
      "z": 9,
      "name": "Plant_Leaves_Jungle"
    },
    {
      "x": -10,
      "y": 32,
      "z": 10,
      "name": "Plant_Leaves_Jungle"
    },
    {
      "x": -10,
      "y": 34,
      "z": 10,
      "name": "Plant_Leaves_Jungle"
    },
    {
      "x": -9,
      "y": 31,
      "z": -8,
      "name": "Plant_Leaves_Jungle"
    },
    {
      "x": -9,
      "y": 32,
      "z": -8,
      "name": "Plant_Leaves_Jungle"
    },
    {
      "x": -9,
      "y": 33,
      "z": -8,
      "name": "Plant_Leaves_Jungle"
    },
    {
      "x": -9,
      "y": 34,
      "z": -8,
      "name": "Plant_Leaves_Jungle"
    },
    {
      "x": -9,
      "y": 34,
      "z": -7,
      "name": "Wood_Jungle_Branch_Long",
      "rotation": 4
    },
    {
      "x": -9,
      "y": 34,
      "z": -6,
      "name": "Wood_Jungle_Branch_Long",
      "rotation": 4
    },
    {
      "x": -9,
      "y": 35,
      "z": -6,
      "name": "Plant_Leaves_Jungle"
    },
    {
      "x": -9,
      "y": 36,
      "z": -6,
      "name": "Plant_Leaves_Jungle"
    },
    {
      "x": -9,
      "y": 34,
      "z": -5,
      "name": "Wood_Jungle_Branch_Long",
      "rotation": 4
    },
    {
      "x": -9,
      "y": 35,
      "z": -5,
      "name": "Plant_Leaves_Jungle"
    },
    {
      "x": -9,
      "y": 36,
      "z": -5,
      "name": "Plant_Leaves_Jungle"
    },
    {
      "x": -9,
      "y": 2,
      "z": -4,
      "name": "Wood_Jungle_Trunk"
    },
    {
      "x": -9,
      "y": 3,
      "z": -4,
      "name": "Wood_Jungle_Trunk"
    },
    {
      "x": -9,
      "y": 4,
      "z": -4,
      "name": "Wood_Jungle_Trunk"
    },
    {
      "x": -9,
      "y": 5,
      "z": -4,
      "name": "Wood_Jungle_Trunk"
    },
    {
      "x": -9,
      "y": 6,
      "z": -4,
      "name": "Wood_Jungle_Trunk_Full"
    },
    {
      "x": -9,
      "y": 33,
      "z": -4,
      "name": "Wood_Jungle_Trunk_Full"
    },
    {
      "x": -9,
      "y": 34,
      "z": -4,
      "name": "Wood_Jungle_Trunk_Full"
    },
    {
      "x": -9,
      "y": 35,
      "z": -4,
      "name": "Wood_Jungle_Branch_Long"
    },
    {
      "x": -9,
      "y": 36,
      "z": -4,
      "name": "Plant_Leaves_Jungle"
    },
    {
      "x": -9,
      "y": 2,
      "z": -3,
      "name": "Wood_Jungle_Trunk"
    },
    {
      "x": -9,
      "y": 3,
      "z": -3,
      "name": "Wood_Jungle_Trunk"
    },
    {
      "x": -9,
      "y": 4,
      "z": -3,
      "name": "Wood_Jungle_Trunk"
    },
    {
      "x": -9,
      "y": 5,
      "z": -3,
      "name": "Wood_Jungle_Trunk"
    },
    {
      "x": -9,
      "y": 6,
      "z": -3,
      "name": "Wood_Jungle_Trunk"
    },
    {
      "x": -9,
      "y": 7,
      "z": -3,
      "name": "Wood_Jungle_Trunk"
    },
    {
      "x": -9,
      "y": 8,
      "z": -3,
      "name": "Wood_Jungle_Trunk"
    },
    {
      "x": -9,
      "y": 9,
      "z": -3,
      "name": "Wood_Jungle_Trunk"
    },
    {
      "x": -9,
      "y": 10,
      "z": -3,
      "name": "Wood_Jungle_Trunk"
    },
    {
      "x": -9,
      "y": 11,
      "z": -3,
      "name": "Wood_Jungle_Trunk_Full"
    },
    {
      "x": -9,
      "y": 33,
      "z": -3,
      "name": "Wood_Jungle_Trunk_Full"
    },
    {
      "x": -9,
      "y": 36,
      "z": -3,
      "name": "Plant_Leaves_Jungle"
    },
    {
      "x": -9,
      "y": 3,
      "z": -2,
      "name": "Wood_Jungle_Trunk"
    },
    {
      "x": -9,
      "y": 4,
      "z": -2,
      "name": "Wood_Jungle_Trunk"
    },
    {
      "x": -9,
      "y": 5,
      "z": -2,
      "name": "Wood_Jungle_Trunk"
    },
    {
      "x": -9,
      "y": 6,
      "z": -2,
      "name": "Wood_Jungle_Trunk"
    },
    {
      "x": -9,
      "y": 7,
      "z": -2,
      "name": "Wood_Jungle_Trunk"
    },
    {
      "x": -9,
      "y": 8,
      "z": -2,
      "name": "Wood_Jungle_Trunk"
    },
    {
      "x": -9,
      "y": 9,
      "z": -2,
      "name": "Wood_Jungle_Trunk"
    },
    {
      "x": -9,
      "y": 10,
      "z": -2,
      "name": "Wood_Jungle_Trunk"
    },
    {
      "x": -9,
      "y": 11,
      "z": -2,
      "name": "Wood_Jungle_Trunk"
    },
    {
      "x": -9,
      "y": 12,
      "z": -2,
      "name": "Wood_Jungle_Trunk"
    },
    {
      "x": -9,
      "y": 13,
      "z": -2,
      "name": "Wood_Jungle_Trunk_Full"
    },
    {
      "x": -9,
      "y": 28,
      "z": -2,
      "name": "Plant_Leaves_Jungle"
    },
    {
      "x": -9,
      "y": 32,
      "z": -2,
      "name": "Wood_Jungle_Trunk_Full"
    },
    {
      "x": -9,
      "y": 33,
      "z": -2,
      "name": "Wood_Jungle_Trunk_Full"
    },
    {
      "x": -9,
      "y": 4,
      "z": -1,
      "name": "Wood_Jungle_Trunk"
    },
    {
      "x": -9,
      "y": 5,
      "z": -1,
      "name": "Wood_Jungle_Trunk"
    },
    {
      "x": -9,
      "y": 6,
      "z": -1,
      "name": "Wood_Jungle_Trunk"
    },
    {
      "x": -9,
      "y": 7,
      "z": -1,
      "name": "Wood_Jungle_Trunk"
    },
    {
      "x": -9,
      "y": 8,
      "z": -1,
      "name": "Wood_Jungle_Trunk"
    },
    {
      "x": -9,
      "y": 9,
      "z": -1,
      "name": "Wood_Jungle_Trunk"
    },
    {
      "x": -9,
      "y": 10,
      "z": -1,
      "name": "Wood_Jungle_Trunk"
    },
    {
      "x": -9,
      "y": 11,
      "z": -1,
      "name": "Wood_Jungle_Trunk"
    },
    {
      "x": -9,
      "y": 12,
      "z": -1,
      "name": "Wood_Jungle_Trunk_Full"
    },
    {
      "x": -9,
      "y": 28,
      "z": -1,
      "name": "Plant_Leaves_Jungle"
    },
    {
      "x": -9,
      "y": 32,
      "z": -1,
      "name": "Wood_Jungle_Trunk_Full"
    },
    {
      "x": -9,
      "y": 35,
      "z": -1,
      "name": "Wood_Jungle_Branch_Corner",
      "rotation": 3
    },
    {
      "x": -9,
      "y": 36,
      "z": -1,
      "name": "Plant_Leaves_Jungle"
    },
    {
      "x": -9,
      "y": 37,
      "z": -1,
      "name": "Plant_Leaves_Jungle"
    },
    {
      "x": -9,
      "y": 5,
      "z": 0,
      "name": "Wood_Jungle_Trunk"
    },
    {
      "x": -9,
      "y": 6,
      "z": 0,
      "name": "Wood_Jungle_Trunk"
    },
    {
      "x": -9,
      "y": 7,
      "z": 0,
      "name": "Wood_Jungle_Trunk"
    },
    {
      "x": -9,
      "y": 8,
      "z": 0,
      "name": "Wood_Jungle_Trunk"
    },
    {
      "x": -9,
      "y": 9,
      "z": 0,
      "name": "Wood_Jungle_Trunk"
    },
    {
      "x": -9,
      "y": 10,
      "z": 0,
      "name": "Wood_Jungle_Trunk"
    },
    {
      "x": -9,
      "y": 11,
      "z": 0,
      "name": "Wood_Jungle_Trunk_Full"
    },
    {
      "x": -9,
      "y": 25,
      "z": 0,
      "name": "Wood_Jungle_Trunk_Full"
    },
    {
      "x": -9,
      "y": 28,
      "z": 0,
      "name": "Plant_Leaves_Jungle"
    },
    {
      "x": -9,
      "y": 37,
      "z": 0,
      "name": "Plant_Leaves_Jungle"
    },
    {
      "x": -9,
      "y": 6,
      "z": 1,
      "name": "Wood_Jungle_Trunk"
    },
    {
      "x": -9,
      "y": 7,
      "z": 1,
      "name": "Wood_Jungle_Trunk"
    },
    {
      "x": -9,
      "y": 8,
      "z": 1,
      "name": "Wood_Jungle_Trunk_Full"
    },
    {
      "x": -9,
      "y": 25,
      "z": 1,
      "name": "Wood_Jungle_Trunk_Full"
    },
    {
      "x": -9,
      "y": 28,
      "z": 1,
      "name": "Plant_Leaves_Jungle"
    },
    {
      "x": -9,
      "y": 36,
      "z": 1,
      "name": "Plant_Leaves_Jungle"
    },
    {
      "x": -9,
      "y": 28,
      "z": 2,
      "name": "Plant_Leaves_Jungle"
    },
    {
      "x": -9,
      "y": 36,
      "z": 2,
      "name": "Plant_Leaves_Jungle"
    },
    {
      "x": -9,
      "y": 6,
      "z": 3,
      "name": "Wood_Jungle_Trunk"
    },
    {
      "x": -9,
      "y": 7,
      "z": 3,
      "name": "Wood_Jungle_Trunk"
    },
    {
      "x": -9,
      "y": 8,
      "z": 3,
      "name": "Wood_Jungle_Trunk"
    },
    {
      "x": -9,
      "y": 9,
      "z": 3,
      "name": "Wood_Jungle_Trunk_Full"
    },
    {
      "x": -9,
      "y": 28,
      "z": 3,
      "name": "Plant_Leaves_Jungle"
    },
    {
      "x": -9,
      "y": 5,
      "z": 4,
      "name": "Wood_Jungle_Trunk"
    },
    {
      "x": -9,
      "y": 6,
      "z": 4,
      "name": "Wood_Jungle_Trunk"
    },
    {
      "x": -9,
      "y": 7,
      "z": 4,
      "name": "Wood_Jungle_Trunk"
    },
    {
      "x": -9,
      "y": 8,
      "z": 4,
      "name": "Wood_Jungle_Trunk"
    },
    {
      "x": -9,
      "y": 9,
      "z": 4,
      "name": "Wood_Jungle_Trunk_Full"
    },
    {
      "x": -9,
      "y": 36,
      "z": 4,
      "name": "Plant_Leaves_Jungle"
    },
    {
      "x": -9,
      "y": 3,
      "z": 5,
      "name": "Wood_Jungle_Trunk"
    },
    {
      "x": -9,
      "y": 4,
      "z": 5,
      "name": "Wood_Jungle_Trunk"
    },
    {
      "x": -9,
      "y": 5,
      "z": 5,
      "name": "Wood_Jungle_Trunk"
    },
    {
      "x": -9,
      "y": 6,
      "z": 5,
      "name": "Wood_Jungle_Trunk"
    },
    {
      "x": -9,
      "y": 7,
      "z": 5,
      "name": "Wood_Jungle_Trunk"
    },
    {
      "x": -9,
      "y": 8,
      "z": 5,
      "name": "Wood_Jungle_Trunk"
    },
    {
      "x": -9,
      "y": 9,
      "z": 5,
      "name": "Wood_Jungle_Trunk"
    },
    {
      "x": -9,
      "y": 10,
      "z": 5,
      "name": "Wood_Jungle_Trunk"
    },
    {
      "x": -9,
      "y": 11,
      "z": 5,
      "name": "Wood_Jungle_Trunk_Full"
    },
    {
      "x": -9,
      "y": 33,
      "z": 5,
      "name": "Wood_Jungle_Trunk_Full"
    },
    {
      "x": -9,
      "y": 36,
      "z": 5,
      "name": "Plant_Leaves_Jungle"
    },
    {
      "x": -9,
      "y": 2,
      "z": 6,
      "name": "Wood_Jungle_Trunk"
    },
    {
      "x": -9,
      "y": 3,
      "z": 6,
      "name": "Wood_Jungle_Trunk"
    },
    {
      "x": -9,
      "y": 4,
      "z": 6,
      "name": "Wood_Jungle_Trunk"
    },
    {
      "x": -9,
      "y": 5,
      "z": 6,
      "name": "Wood_Jungle_Trunk"
    },
    {
      "x": -9,
      "y": 6,
      "z": 6,
      "name": "Wood_Jungle_Trunk"
    },
    {
      "x": -9,
      "y": 7,
      "z": 6,
      "name": "Wood_Jungle_Trunk"
    },
    {
      "x": -9,
      "y": 8,
      "z": 6,
      "name": "Wood_Jungle_Trunk"
    },
    {
      "x": -9,
      "y": 9,
      "z": 6,
      "name": "Wood_Jungle_Trunk"
    },
    {
      "x": -9,
      "y": 10,
      "z": 6,
      "name": "Wood_Jungle_Trunk"
    },
    {
      "x": -9,
      "y": 11,
      "z": 6,
      "name": "Wood_Jungle_Trunk"
    },
    {
      "x": -9,
      "y": 12,
      "z": 6,
      "name": "Wood_Jungle_Trunk_Full"
    },
    {
      "x": -9,
      "y": 36,
      "z": 6,
      "name": "Plant_Leaves_Jungle"
    },
    {
      "x": -9,
      "y": 2,
      "z": 7,
      "name": "Wood_Jungle_Trunk"
    },
    {
      "x": -9,
      "y": 3,
      "z": 7,
      "name": "Wood_Jungle_Trunk"
    },
    {
      "x": -9,
      "y": 4,
      "z": 7,
      "name": "Wood_Jungle_Trunk"
    },
    {
      "x": -9,
      "y": 5,
      "z": 7,
      "name": "Wood_Jungle_Trunk"
    },
    {
      "x": -9,
      "y": 6,
      "z": 7,
      "name": "Wood_Jungle_Trunk"
    },
    {
      "x": -9,
      "y": 7,
      "z": 7,
      "name": "Wood_Jungle_Trunk"
    },
    {
      "x": -9,
      "y": 8,
      "z": 7,
      "name": "Wood_Jungle_Trunk"
    },
    {
      "x": -9,
      "y": 9,
      "z": 7,
      "name": "Wood_Jungle_Trunk_Full"
    },
    {
      "x": -9,
      "y": 36,
      "z": 7,
      "name": "Plant_Leaves_Jungle"
    },
    {
      "x": -9,
      "y": 2,
      "z": 8,
      "name": "Wood_Jungle_Trunk"
    },
    {
      "x": -9,
      "y": 3,
      "z": 8,
      "name": "Wood_Jungle_Trunk"
    },
    {
      "x": -9,
      "y": 4,
      "z": 8,
      "name": "Wood_Jungle_Trunk"
    },
    {
      "x": -9,
      "y": 5,
      "z": 8,
      "name": "Wood_Jungle_Trunk_Full"
    },
    {
      "x": -9,
      "y": 36,
      "z": 8,
      "name": "Plant_Leaves_Jungle"
    },
    {
      "x": -9,
      "y": 35,
      "z": 9,
      "name": "Plant_Leaves_Jungle"
    },
    {
      "x": -9,
      "y": 36,
      "z": 9,
      "name": "Plant_Leaves_Jungle"
    },
    {
      "x": -9,
      "y": 33,
      "z": 10,
      "name": "Plant_Leaves_Jungle"
    },
    {
      "x": -9,
      "y": 34,
      "z": 10,
      "name": "Plant_Leaves_Jungle"
    },
    {
      "x": -9,
      "y": 35,
      "z": 10,
      "name": "Plant_Leaves_Jungle"
    },
    {
      "x": -9,
      "y": 34,
      "z": 11,
      "name": "Plant_Leaves_Jungle"
    },
    {
      "x": -8,
      "y": 30,
      "z": -8,
      "name": "Plant_Leaves_Jungle"
    },
    {
      "x": -8,
      "y": 31,
      "z": -8,
      "name": "Plant_Leaves_Jungle"
    },
    {
      "x": -8,
      "y": 32,
      "z": -8,
      "name": "Plant_Leaves_Jungle"
    },
    {
      "x": -8,
      "y": 33,
      "z": -8,
      "name": "Plant_Leaves_Jungle"
    },
    {
      "x": -8,
      "y": 34,
      "z": -8,
      "name": "Plant_Leaves_Jungle"
    },
    {
      "x": -8,
      "y": 35,
      "z": -8,
      "name": "Plant_Leaves_Jungle"
    },
    {
      "x": -8,
      "y": 35,
      "z": -7,
      "name": "Plant_Leaves_Jungle"
    },
    {
      "x": -8,
      "y": 36,
      "z": -6,
      "name": "Plant_Leaves_Jungle"
    },
    {
      "x": -8,
      "y": 35,
      "z": -5,
      "name": "Plant_Leaves_Jungle"
    },
    {
      "x": -8,
      "y": 36,
      "z": -5,
      "name": "Plant_Leaves_Jungle"
    },
    {
      "x": -8,
      "y": 3,
      "z": -4,
      "name": "Wood_Jungle_Trunk"
    },
    {
      "x": -8,
      "y": 4,
      "z": -4,
      "name": "Wood_Jungle_Trunk"
    },
    {
      "x": -8,
      "y": 5,
      "z": -4,
      "name": "Wood_Jungle_Trunk_Full"
    },
    {
      "x": -8,
      "y": 34,
      "z": -4,
      "name": "Wood_Jungle_Branch_Corner",
      "rotation": 1
    },
    {
      "x": -8,
      "y": 35,
      "z": -4,
      "name": "Plant_Leaves_Jungle"
    },
    {
      "x": -8,
      "y": 36,
      "z": -4,
      "name": "Plant_Leaves_Jungle"
    },
    {
      "x": -8,
      "y": 3,
      "z": -3,
      "name": "Wood_Jungle_Trunk"
    },
    {
      "x": -8,
      "y": 4,
      "z": -3,
      "name": "Wood_Jungle_Trunk"
    },
    {
      "x": -8,
      "y": 5,
      "z": -3,
      "name": "Wood_Jungle_Trunk"
    },
    {
      "x": -8,
      "y": 6,
      "z": -3,
      "name": "Wood_Jungle_Trunk"
    },
    {
      "x": -8,
      "y": 7,
      "z": -3,
      "name": "Wood_Jungle_Trunk"
    },
    {
      "x": -8,
      "y": 8,
      "z": -3,
      "name": "Wood_Jungle_Trunk"
    },
    {
      "x": -8,
      "y": 9,
      "z": -3,
      "name": "Wood_Jungle_Trunk_Full"
    },
    {
      "x": -8,
      "y": 37,
      "z": -3,
      "name": "Plant_Leaves_Jungle"
    },
    {
      "x": -8,
      "y": 4,
      "z": -2,
      "name": "Wood_Jungle_Trunk"
    },
    {
      "x": -8,
      "y": 5,
      "z": -2,
      "name": "Wood_Jungle_Trunk"
    },
    {
      "x": -8,
      "y": 6,
      "z": -2,
      "name": "Wood_Jungle_Trunk"
    },
    {
      "x": -8,
      "y": 7,
      "z": -2,
      "name": "Wood_Jungle_Trunk"
    },
    {
      "x": -8,
      "y": 8,
      "z": -2,
      "name": "Wood_Jungle_Trunk"
    },
    {
      "x": -8,
      "y": 9,
      "z": -2,
      "name": "Wood_Jungle_Trunk"
    },
    {
      "x": -8,
      "y": 10,
      "z": -2,
      "name": "Wood_Jungle_Trunk"
    },
    {
      "x": -8,
      "y": 11,
      "z": -2,
      "name": "Wood_Jungle_Trunk"
    },
    {
      "x": -8,
      "y": 12,
      "z": -2,
      "name": "Wood_Jungle_Trunk_Full"
    },
    {
      "x": -8,
      "y": 37,
      "z": -2,
      "name": "Plant_Leaves_Jungle"
    },
    {
      "x": -8,
      "y": 5,
      "z": -1,
      "name": "Wood_Jungle_Trunk"
    },
    {
      "x": -8,
      "y": 6,
      "z": -1,
      "name": "Wood_Jungle_Trunk"
    },
    {
      "x": -8,
      "y": 7,
      "z": -1,
      "name": "Wood_Jungle_Trunk"
    },
    {
      "x": -8,
      "y": 8,
      "z": -1,
      "name": "Wood_Jungle_Trunk"
    },
    {
      "x": -8,
      "y": 9,
      "z": -1,
      "name": "Wood_Jungle_Trunk"
    },
    {
      "x": -8,
      "y": 10,
      "z": -1,
      "name": "Wood_Jungle_Trunk"
    },
    {
      "x": -8,
      "y": 11,
      "z": -1,
      "name": "Wood_Jungle_Trunk"
    },
    {
      "x": -8,
      "y": 12,
      "z": -1,
      "name": "Wood_Jungle_Trunk"
    },
    {
      "x": -8,
      "y": 13,
      "z": -1,
      "name": "Wood_Jungle_Trunk"
    },
    {
      "x": -8,
      "y": 14,
      "z": -1,
      "name": "Wood_Jungle_Trunk"
    },
    {
      "x": -8,
      "y": 15,
      "z": -1,
      "name": "Wood_Jungle_Trunk_Full"
    },
    {
      "x": -8,
      "y": 32,
      "z": -1,
      "name": "Wood_Jungle_Trunk_Full"
    },
    {
      "x": -8,
      "y": 35,
      "z": -1,
      "name": "Wood_Jungle_Branch_Long",
      "rotation": 5
    },
    {
      "x": -8,
      "y": 37,
      "z": -1,
      "name": "Plant_Leaves_Jungle"
    },
    {
      "x": -8,
      "y": 5,
      "z": 0,
      "name": "Wood_Jungle_Trunk"
    },
    {
      "x": -8,
      "y": 6,
      "z": 0,
      "name": "Wood_Jungle_Trunk"
    },
    {
      "x": -8,
      "y": 7,
      "z": 0,
      "name": "Wood_Jungle_Trunk"
    },
    {
      "x": -8,
      "y": 8,
      "z": 0,
      "name": "Wood_Jungle_Trunk"
    },
    {
      "x": -8,
      "y": 9,
      "z": 0,
      "name": "Wood_Jungle_Trunk"
    },
    {
      "x": -8,
      "y": 10,
      "z": 0,
      "name": "Wood_Jungle_Trunk"
    },
    {
      "x": -8,
      "y": 11,
      "z": 0,
      "name": "Wood_Jungle_Trunk"
    },
    {
      "x": -8,
      "y": 12,
      "z": 0,
      "name": "Wood_Jungle_Trunk"
    },
    {
      "x": -8,
      "y": 13,
      "z": 0,
      "name": "Wood_Jungle_Trunk"
    },
    {
      "x": -8,
      "y": 14,
      "z": 0,
      "name": "Wood_Jungle_Trunk_Full"
    },
    {
      "x": -8,
      "y": 25,
      "z": 0,
      "name": "Wood_Jungle_Trunk_Full"
    },
    {
      "x": -8,
      "y": 28,
      "z": 0,
      "name": "Plant_Leaves_Jungle"
    },
    {
      "x": -8,
      "y": 37,
      "z": 0,
      "name": "Plant_Leaves_Jungle"
    },
    {
      "x": -8,
      "y": 5,
      "z": 1,
      "name": "Wood_Jungle_Trunk"
    },
    {
      "x": -8,
      "y": 6,
      "z": 1,
      "name": "Wood_Jungle_Trunk"
    },
    {
      "x": -8,
      "y": 7,
      "z": 1,
      "name": "Wood_Jungle_Trunk"
    },
    {
      "x": -8,
      "y": 8,
      "z": 1,
      "name": "Wood_Jungle_Trunk"
    },
    {
      "x": -8,
      "y": 9,
      "z": 1,
      "name": "Wood_Jungle_Trunk"
    },
    {
      "x": -8,
      "y": 10,
      "z": 1,
      "name": "Wood_Jungle_Trunk"
    },
    {
      "x": -8,
      "y": 11,
      "z": 1,
      "name": "Wood_Jungle_Trunk"
    },
    {
      "x": -8,
      "y": 12,
      "z": 1,
      "name": "Wood_Jungle_Trunk_Full"
    },
    {
      "x": -8,
      "y": 28,
      "z": 1,
      "name": "Plant_Leaves_Jungle"
    },
    {
      "x": -8,
      "y": 36,
      "z": 1,
      "name": "Plant_Leaves_Jungle"
    },
    {
      "x": -8,
      "y": 6,
      "z": 2,
      "name": "Wood_Jungle_Trunk"
    },
    {
      "x": -8,
      "y": 7,
      "z": 2,
      "name": "Wood_Jungle_Trunk"
    },
    {
      "x": -8,
      "y": 8,
      "z": 2,
      "name": "Wood_Jungle_Trunk"
    },
    {
      "x": -8,
      "y": 9,
      "z": 2,
      "name": "Wood_Jungle_Trunk"
    },
    {
      "x": -8,
      "y": 10,
      "z": 2,
      "name": "Wood_Jungle_Trunk"
    },
    {
      "x": -8,
      "y": 11,
      "z": 2,
      "name": "Wood_Jungle_Trunk_Full"
    },
    {
      "x": -8,
      "y": 36,
      "z": 2,
      "name": "Plant_Leaves_Jungle"
    },
    {
      "x": -8,
      "y": 6,
      "z": 3,
      "name": "Wood_Jungle_Trunk"
    },
    {
      "x": -8,
      "y": 7,
      "z": 3,
      "name": "Wood_Jungle_Trunk"
    },
    {
      "x": -8,
      "y": 8,
      "z": 3,
      "name": "Wood_Jungle_Trunk"
    },
    {
      "x": -8,
      "y": 9,
      "z": 3,
      "name": "Wood_Jungle_Trunk"
    },
    {
      "x": -8,
      "y": 10,
      "z": 3,
      "name": "Wood_Jungle_Trunk"
    },
    {
      "x": -8,
      "y": 11,
      "z": 3,
      "name": "Wood_Jungle_Trunk_Full"
    },
    {
      "x": -8,
      "y": 37,
      "z": 3,
      "name": "Plant_Leaves_Jungle"
    },
    {
      "x": -8,
      "y": 5,
      "z": 4,
      "name": "Wood_Jungle_Trunk"
    },
    {
      "x": -8,
      "y": 6,
      "z": 4,
      "name": "Wood_Jungle_Trunk"
    },
    {
      "x": -8,
      "y": 7,
      "z": 4,
      "name": "Wood_Jungle_Trunk"
    },
    {
      "x": -8,
      "y": 8,
      "z": 4,
      "name": "Wood_Jungle_Trunk"
    },
    {
      "x": -8,
      "y": 9,
      "z": 4,
      "name": "Wood_Jungle_Trunk"
    },
    {
      "x": -8,
      "y": 10,
      "z": 4,
      "name": "Wood_Jungle_Trunk"
    },
    {
      "x": -8,
      "y": 11,
      "z": 4,
      "name": "Wood_Jungle_Trunk"
    },
    {
      "x": -8,
      "y": 12,
      "z": 4,
      "name": "Wood_Jungle_Trunk"
    },
    {
      "x": -8,
      "y": 13,
      "z": 4,
      "name": "Wood_Jungle_Trunk_Full"
    },
    {
      "x": -8,
      "y": 32,
      "z": 4,
      "name": "Wood_Jungle_Trunk_Full"
    },
    {
      "x": -8,
      "y": 35,
      "z": 4,
      "name": "Wood_Jungle_Branch_Corner",
      "rotation": 3
    },
    {
      "x": -8,
      "y": 36,
      "z": 4,
      "name": "Plant_Leaves_Jungle"
    },
    {
      "x": -8,
      "y": 37,
      "z": 4,
      "name": "Plant_Leaves_Jungle"
    },
    {
      "x": -8,
      "y": 4,
      "z": 5,
      "name": "Wood_Jungle_Trunk"
    },
    {
      "x": -8,
      "y": 5,
      "z": 5,
      "name": "Wood_Jungle_Trunk"
    },
    {
      "x": -8,
      "y": 6,
      "z": 5,
      "name": "Wood_Jungle_Trunk"
    },
    {
      "x": -8,
      "y": 7,
      "z": 5,
      "name": "Wood_Jungle_Trunk"
    },
    {
      "x": -8,
      "y": 8,
      "z": 5,
      "name": "Wood_Jungle_Trunk"
    },
    {
      "x": -8,
      "y": 9,
      "z": 5,
      "name": "Wood_Jungle_Trunk"
    },
    {
      "x": -8,
      "y": 10,
      "z": 5,
      "name": "Wood_Jungle_Trunk"
    },
    {
      "x": -8,
      "y": 11,
      "z": 5,
      "name": "Wood_Jungle_Trunk"
    },
    {
      "x": -8,
      "y": 12,
      "z": 5,
      "name": "Wood_Jungle_Trunk"
    },
    {
      "x": -8,
      "y": 13,
      "z": 5,
      "name": "Wood_Jungle_Trunk"
    },
    {
      "x": -8,
      "y": 14,
      "z": 5,
      "name": "Wood_Jungle_Trunk_Full"
    },
    {
      "x": -8,
      "y": 32,
      "z": 5,
      "name": "Wood_Jungle_Trunk_Full"
    },
    {
      "x": -8,
      "y": 33,
      "z": 5,
      "name": "Wood_Jungle_Trunk_Full"
    },
    {
      "x": -8,
      "y": 3,
      "z": 6,
      "name": "Wood_Jungle_Trunk"
    },
    {
      "x": -8,
      "y": 4,
      "z": 6,
      "name": "Wood_Jungle_Trunk"
    },
    {
      "x": -8,
      "y": 5,
      "z": 6,
      "name": "Wood_Jungle_Trunk"
    },
    {
      "x": -8,
      "y": 6,
      "z": 6,
      "name": "Wood_Jungle_Trunk"
    },
    {
      "x": -8,
      "y": 7,
      "z": 6,
      "name": "Wood_Jungle_Trunk"
    },
    {
      "x": -8,
      "y": 8,
      "z": 6,
      "name": "Wood_Jungle_Trunk"
    },
    {
      "x": -8,
      "y": 9,
      "z": 6,
      "name": "Wood_Jungle_Trunk"
    },
    {
      "x": -8,
      "y": 10,
      "z": 6,
      "name": "Wood_Jungle_Trunk"
    },
    {
      "x": -8,
      "y": 11,
      "z": 6,
      "name": "Wood_Jungle_Trunk_Full"
    },
    {
      "x": -8,
      "y": 33,
      "z": 6,
      "name": "Wood_Jungle_Trunk_Full"
    },
    {
      "x": -8,
      "y": 36,
      "z": 6,
      "name": "Plant_Leaves_Jungle"
    },
    {
      "x": -8,
      "y": 3,
      "z": 7,
      "name": "Wood_Jungle_Trunk"
    },
    {
      "x": -8,
      "y": 4,
      "z": 7,
      "name": "Wood_Jungle_Trunk"
    },
    {
      "x": -8,
      "y": 5,
      "z": 7,
      "name": "Wood_Jungle_Trunk"
    },
    {
      "x": -8,
      "y": 6,
      "z": 7,
      "name": "Wood_Jungle_Trunk"
    },
    {
      "x": -8,
      "y": 7,
      "z": 7,
      "name": "Wood_Jungle_Trunk_Full"
    },
    {
      "x": -8,
      "y": 33,
      "z": 7,
      "name": "Wood_Jungle_Trunk_Full"
    },
    {
      "x": -8,
      "y": 34,
      "z": 7,
      "name": "Wood_Jungle_Trunk_Full"
    },
    {
      "x": -8,
      "y": 35,
      "z": 7,
      "name": "Wood_Jungle_Branch_Long"
    },
    {
      "x": -8,
      "y": 36,
      "z": 7,
      "name": "Plant_Leaves_Jungle"
    },
    {
      "x": -8,
      "y": 34,
      "z": 8,
      "name": "Wood_Jungle_Branch_Long",
      "rotation": 4
    },
    {
      "x": -8,
      "y": 35,
      "z": 8,
      "name": "Plant_Leaves_Jungle"
    },
    {
      "x": -8,
      "y": 36,
      "z": 8,
      "name": "Plant_Leaves_Jungle"
    },
    {
      "x": -8,
      "y": 34,
      "z": 9,
      "name": "Wood_Jungle_Branch_Long",
      "rotation": 4
    },
    {
      "x": -8,
      "y": 35,
      "z": 9,
      "name": "Plant_Leaves_Jungle"
    },
    {
      "x": -8,
      "y": 36,
      "z": 9,
      "name": "Plant_Leaves_Jungle"
    },
    {
      "x": -8,
      "y": 34,
      "z": 10,
      "name": "Wood_Jungle_Branch_Long",
      "rotation": 4
    },
    {
      "x": -8,
      "y": 31,
      "z": 11,
      "name": "Plant_Leaves_Jungle"
    },
    {
      "x": -8,
      "y": 32,
      "z": 11,
      "name": "Plant_Leaves_Jungle"
    },
    {
      "x": -8,
      "y": 33,
      "z": 11,
      "name": "Plant_Leaves_Jungle"
    },
    {
      "x": -8,
      "y": 34,
      "z": 11,
      "name": "Plant_Leaves_Jungle"
    },
    {
      "x": -7,
      "y": 34,
      "z": -8,
      "name": "Plant_Leaves_Jungle"
    },
    {
      "x": -7,
      "y": 35,
      "z": -8,
      "name": "Plant_Leaves_Jungle"
    },
    {
      "x": -7,
      "y": 33,
      "z": -7,
      "name": "Plant_Leaves_Jungle"
    },
    {
      "x": -7,
      "y": 34,
      "z": -7,
      "name": "Plant_Leaves_Jungle"
    },
    {
      "x": -7,
      "y": 35,
      "z": -7,
      "name": "Plant_Leaves_Jungle"
    },
    {
      "x": -7,
      "y": 36,
      "z": -6,
      "name": "Plant_Leaves_Jungle"
    },
    {
      "x": -7,
      "y": 36,
      "z": -5,
      "name": "Plant_Leaves_Jungle"
    },
    {
      "x": -7,
      "y": 35,
      "z": -4,
      "name": "Plant_Leaves_Jungle"
    },
    {
      "x": -7,
      "y": 36,
      "z": -4,
      "name": "Plant_Leaves_Jungle"
    },
    {
      "x": -7,
      "y": 5,
      "z": -3,
      "name": "Wood_Jungle_Trunk"
    },
    {
      "x": -7,
      "y": 6,
      "z": -3,
      "name": "Wood_Jungle_Trunk"
    },
    {
      "x": -7,
      "y": 7,
      "z": -3,
      "name": "Wood_Jungle_Trunk_Full"
    },
    {
      "x": -7,
      "y": 37,
      "z": -3,
      "name": "Plant_Leaves_Jungle"
    },
    {
      "x": -7,
      "y": 5,
      "z": -2,
      "name": "Wood_Jungle_Trunk"
    },
    {
      "x": -7,
      "y": 6,
      "z": -2,
      "name": "Wood_Jungle_Trunk"
    },
    {
      "x": -7,
      "y": 7,
      "z": -2,
      "name": "Wood_Jungle_Trunk"
    },
    {
      "x": -7,
      "y": 8,
      "z": -2,
      "name": "Wood_Jungle_Trunk"
    },
    {
      "x": -7,
      "y": 9,
      "z": -2,
      "name": "Wood_Jungle_Trunk"
    },
    {
      "x": -7,
      "y": 10,
      "z": -2,
      "name": "Wood_Jungle_Trunk_Full"
    },
    {
      "x": -7,
      "y": 35,
      "z": -2,
      "name": "Wood_Jungle_Trunk_Full"
    },
    {
      "x": -7,
      "y": 36,
      "z": -2,
      "name": "Wood_Jungle_Branch_Long"
    },
    {
      "x": -7,
      "y": 37,
      "z": -2,
      "name": "Plant_Leaves_Jungle"
    },
    {
      "x": -7,
      "y": 40,
      "z": -2,
      "name": "Plant_Leaves_Jungle"
    },
    {
      "x": -7,
      "y": 5,
      "z": -1,
      "name": "Wood_Jungle_Trunk"
    },
    {
      "x": -7,
      "y": 6,
      "z": -1,
      "name": "Wood_Jungle_Trunk"
    },
    {
      "x": -7,
      "y": 7,
      "z": -1,
      "name": "Wood_Jungle_Trunk"
    },
    {
      "x": -7,
      "y": 8,
      "z": -1,
      "name": "Wood_Jungle_Trunk"
    },
    {
      "x": -7,
      "y": 9,
      "z": -1,
      "name": "Wood_Jungle_Trunk"
    },
    {
      "x": -7,
      "y": 10,
      "z": -1,
      "name": "Wood_Jungle_Trunk"
    },
    {
      "x": -7,
      "y": 11,
      "z": -1,
      "name": "Wood_Jungle_Trunk"
    },
    {
      "x": -7,
      "y": 12,
      "z": -1,
      "name": "Wood_Jungle_Trunk"
    },
    {
      "x": -7,
      "y": 13,
      "z": -1,
      "name": "Wood_Jungle_Trunk"
    },
    {
      "x": -7,
      "y": 14,
      "z": -1,
      "name": "Wood_Jungle_Trunk_Full"
    },
    {
      "x": -7,
      "y": 31,
      "z": -1,
      "name": "Wood_Jungle_Trunk_Full"
    },
    {
      "x": -7,
      "y": 32,
      "z": -1,
      "name": "Wood_Jungle_Trunk"
    },
    {
      "x": -7,
      "y": 33,
      "z": -1,
      "name": "Wood_Jungle_Trunk"
    },
    {
      "x": -7,
      "y": 34,
      "z": -1,
      "name": "Wood_Jungle_Trunk"
    },
    {
      "x": -7,
      "y": 35,
      "z": -1,
      "name": "Wood_Jungle_Trunk_Full"
    },
    {
      "x": -7,
      "y": 37,
      "z": -1,
      "name": "Plant_Leaves_Jungle"
    },
    {
      "x": -7,
      "y": 39,
      "z": -1,
      "name": "Plant_Leaves_Jungle"
    },
    {
      "x": -7,
      "y": 40,
      "z": -1,
      "name": "Plant_Leaves_Jungle"
    },
    {
      "x": -7,
      "y": 5,
      "z": 0,
      "name": "Wood_Jungle_Trunk"
    },
    {
      "x": -7,
      "y": 6,
      "z": 0,
      "name": "Wood_Jungle_Trunk"
    },
    {
      "x": -7,
      "y": 7,
      "z": 0,
      "name": "Wood_Jungle_Trunk"
    },
    {
      "x": -7,
      "y": 8,
      "z": 0,
      "name": "Wood_Jungle_Trunk"
    },
    {
      "x": -7,
      "y": 9,
      "z": 0,
      "name": "Wood_Jungle_Trunk"
    },
    {
      "x": -7,
      "y": 10,
      "z": 0,
      "name": "Wood_Jungle_Trunk"
    },
    {
      "x": -7,
      "y": 11,
      "z": 0,
      "name": "Wood_Jungle_Trunk"
    },
    {
      "x": -7,
      "y": 12,
      "z": 0,
      "name": "Wood_Jungle_Trunk"
    },
    {
      "x": -7,
      "y": 13,
      "z": 0,
      "name": "Wood_Jungle_Trunk"
    },
    {
      "x": -7,
      "y": 14,
      "z": 0,
      "name": "Wood_Jungle_Trunk"
    },
    {
      "x": -7,
      "y": 15,
      "z": 0,
      "name": "Wood_Jungle_Trunk"
    },
    {
      "x": -7,
      "y": 16,
      "z": 0,
      "name": "Wood_Jungle_Trunk_Full"
    },
    {
      "x": -7,
      "y": 24,
      "z": 0,
      "name": "Wood_Jungle_Trunk_Full"
    },
    {
      "x": -7,
      "y": 25,
      "z": 0,
      "name": "Wood_Jungle_Trunk_Full"
    },
    {
      "x": -7,
      "y": 37,
      "z": 0,
      "name": "Plant_Leaves_Jungle"
    },
    {
      "x": -7,
      "y": 5,
      "z": 1,
      "name": "Wood_Jungle_Trunk"
    },
    {
      "x": -7,
      "y": 6,
      "z": 1,
      "name": "Wood_Jungle_Trunk"
    },
    {
      "x": -7,
      "y": 7,
      "z": 1,
      "name": "Wood_Jungle_Trunk"
    },
    {
      "x": -7,
      "y": 8,
      "z": 1,
      "name": "Wood_Jungle_Trunk"
    },
    {
      "x": -7,
      "y": 9,
      "z": 1,
      "name": "Wood_Jungle_Trunk"
    },
    {
      "x": -7,
      "y": 10,
      "z": 1,
      "name": "Wood_Jungle_Trunk"
    },
    {
      "x": -7,
      "y": 11,
      "z": 1,
      "name": "Wood_Jungle_Trunk"
    },
    {
      "x": -7,
      "y": 12,
      "z": 1,
      "name": "Wood_Jungle_Trunk"
    },
    {
      "x": -7,
      "y": 13,
      "z": 1,
      "name": "Wood_Jungle_Trunk"
    },
    {
      "x": -7,
      "y": 14,
      "z": 1,
      "name": "Wood_Jungle_Trunk"
    },
    {
      "x": -7,
      "y": 15,
      "z": 1,
      "name": "Wood_Jungle_Trunk"
    },
    {
      "x": -7,
      "y": 16,
      "z": 1,
      "name": "Wood_Jungle_Trunk_Full"
    },
    {
      "x": -7,
      "y": 6,
      "z": 2,
      "name": "Wood_Jungle_Trunk"
    },
    {
      "x": -7,
      "y": 7,
      "z": 2,
      "name": "Wood_Jungle_Trunk"
    },
    {
      "x": -7,
      "y": 8,
      "z": 2,
      "name": "Wood_Jungle_Trunk"
    },
    {
      "x": -7,
      "y": 9,
      "z": 2,
      "name": "Wood_Jungle_Trunk"
    },
    {
      "x": -7,
      "y": 10,
      "z": 2,
      "name": "Wood_Jungle_Trunk"
    },
    {
      "x": -7,
      "y": 11,
      "z": 2,
      "name": "Wood_Jungle_Trunk"
    },
    {
      "x": -7,
      "y": 12,
      "z": 2,
      "name": "Wood_Jungle_Trunk"
    },
    {
      "x": -7,
      "y": 13,
      "z": 2,
      "name": "Wood_Jungle_Trunk"
    },
    {
      "x": -7,
      "y": 14,
      "z": 2,
      "name": "Wood_Jungle_Trunk"
    },
    {
      "x": -7,
      "y": 15,
      "z": 2,
      "name": "Wood_Jungle_Trunk_Full"
    },
    {
      "x": -7,
      "y": 16,
      "z": 2,
      "name": "Plant_Vine_Liana",
      "rotation": 3
    },
    {
      "x": -7,
      "y": 17,
      "z": 2,
      "name": "Plant_Vine_Liana",
      "rotation": 3
    },
    {
      "x": -7,
      "y": 18,
      "z": 2,
      "name": "Plant_Vine_Liana",
      "rotation": 3
    },
    {
      "x": -7,
      "y": 19,
      "z": 2,
      "name": "Plant_Vine_Liana",
      "rotation": 3
    },
    {
      "x": -7,
      "y": 36,
      "z": 2,
      "name": "Plant_Leaves_Jungle"
    },
    {
      "x": -7,
      "y": 6,
      "z": 3,
      "name": "Wood_Jungle_Trunk"
    },
    {
      "x": -7,
      "y": 7,
      "z": 3,
      "name": "Wood_Jungle_Trunk"
    },
    {
      "x": -7,
      "y": 8,
      "z": 3,
      "name": "Wood_Jungle_Trunk"
    },
    {
      "x": -7,
      "y": 9,
      "z": 3,
      "name": "Wood_Jungle_Trunk"
    },
    {
      "x": -7,
      "y": 10,
      "z": 3,
      "name": "Wood_Jungle_Trunk"
    },
    {
      "x": -7,
      "y": 11,
      "z": 3,
      "name": "Wood_Jungle_Trunk"
    },
    {
      "x": -7,
      "y": 12,
      "z": 3,
      "name": "Wood_Jungle_Trunk"
    },
    {
      "x": -7,
      "y": 13,
      "z": 3,
      "name": "Wood_Jungle_Trunk_Full"
    },
    {
      "x": -7,
      "y": 15,
      "z": 3,
      "name": "Plant_Vine_Liana",
      "rotation": 3
    },
    {
      "x": -7,
      "y": 16,
      "z": 3,
      "name": "Plant_Vine_Liana",
      "rotation": 3
    },
    {
      "x": -7,
      "y": 17,
      "z": 3,
      "name": "Plant_Vine_Liana",
      "rotation": 3
    },
    {
      "x": -7,
      "y": 37,
      "z": 3,
      "name": "Plant_Leaves_Jungle"
    },
    {
      "x": -7,
      "y": 5,
      "z": 4,
      "name": "Wood_Jungle_Trunk"
    },
    {
      "x": -7,
      "y": 6,
      "z": 4,
      "name": "Wood_Jungle_Trunk"
    },
    {
      "x": -7,
      "y": 7,
      "z": 4,
      "name": "Wood_Jungle_Trunk"
    },
    {
      "x": -7,
      "y": 8,
      "z": 4,
      "name": "Wood_Jungle_Trunk"
    },
    {
      "x": -7,
      "y": 9,
      "z": 4,
      "name": "Wood_Jungle_Trunk"
    },
    {
      "x": -7,
      "y": 10,
      "z": 4,
      "name": "Wood_Jungle_Trunk"
    },
    {
      "x": -7,
      "y": 11,
      "z": 4,
      "name": "Wood_Jungle_Trunk"
    },
    {
      "x": -7,
      "y": 12,
      "z": 4,
      "name": "Wood_Jungle_Trunk"
    },
    {
      "x": -7,
      "y": 13,
      "z": 4,
      "name": "Wood_Jungle_Trunk"
    },
    {
      "x": -7,
      "y": 14,
      "z": 4,
      "name": "Wood_Jungle_Trunk"
    },
    {
      "x": -7,
      "y": 15,
      "z": 4,
      "name": "Wood_Jungle_Trunk_Full"
    },
    {
      "x": -7,
      "y": 32,
      "z": 4,
      "name": "Wood_Jungle_Trunk_Full"
    },
    {
      "x": -7,
      "y": 35,
      "z": 4,
      "name": "Wood_Jungle_Branch_Long",
      "rotation": 5
    },
    {
      "x": -7,
      "y": 37,
      "z": 4,
      "name": "Plant_Leaves_Jungle"
    },
    {
      "x": -7,
      "y": 5,
      "z": 5,
      "name": "Wood_Jungle_Trunk"
    },
    {
      "x": -7,
      "y": 6,
      "z": 5,
      "name": "Wood_Jungle_Trunk"
    },
    {
      "x": -7,
      "y": 7,
      "z": 5,
      "name": "Wood_Jungle_Trunk"
    },
    {
      "x": -7,
      "y": 8,
      "z": 5,
      "name": "Wood_Jungle_Trunk"
    },
    {
      "x": -7,
      "y": 9,
      "z": 5,
      "name": "Wood_Jungle_Trunk"
    },
    {
      "x": -7,
      "y": 10,
      "z": 5,
      "name": "Wood_Jungle_Trunk"
    },
    {
      "x": -7,
      "y": 11,
      "z": 5,
      "name": "Wood_Jungle_Trunk"
    },
    {
      "x": -7,
      "y": 12,
      "z": 5,
      "name": "Wood_Jungle_Trunk"
    },
    {
      "x": -7,
      "y": 13,
      "z": 5,
      "name": "Wood_Jungle_Trunk_Full"
    },
    {
      "x": -7,
      "y": 37,
      "z": 5,
      "name": "Plant_Leaves_Jungle"
    },
    {
      "x": -7,
      "y": 4,
      "z": 6,
      "name": "Wood_Jungle_Trunk"
    },
    {
      "x": -7,
      "y": 5,
      "z": 6,
      "name": "Wood_Jungle_Trunk"
    },
    {
      "x": -7,
      "y": 6,
      "z": 6,
      "name": "Wood_Jungle_Trunk"
    },
    {
      "x": -7,
      "y": 7,
      "z": 6,
      "name": "Wood_Jungle_Trunk"
    },
    {
      "x": -7,
      "y": 8,
      "z": 6,
      "name": "Wood_Jungle_Trunk"
    },
    {
      "x": -7,
      "y": 9,
      "z": 6,
      "name": "Wood_Jungle_Trunk_Full"
    },
    {
      "x": -7,
      "y": 37,
      "z": 6,
      "name": "Plant_Leaves_Jungle"
    },
    {
      "x": -7,
      "y": 4,
      "z": 7,
      "name": "Wood_Jungle_Trunk"
    },
    {
      "x": -7,
      "y": 5,
      "z": 7,
      "name": "Wood_Jungle_Trunk_Full"
    },
    {
      "x": -7,
      "y": 34,
      "z": 7,
      "name": "Wood_Jungle_Branch_Corner",
      "rotation": 1
    },
    {
      "x": -7,
      "y": 35,
      "z": 7,
      "name": "Plant_Leaves_Jungle"
    },
    {
      "x": -7,
      "y": 36,
      "z": 7,
      "name": "Plant_Leaves_Jungle"
    },
    {
      "x": -7,
      "y": 35,
      "z": 8,
      "name": "Plant_Leaves_Jungle"
    },
    {
      "x": -7,
      "y": 36,
      "z": 8,
      "name": "Plant_Leaves_Jungle"
    },
    {
      "x": -7,
      "y": 36,
      "z": 9,
      "name": "Plant_Leaves_Jungle"
    },
    {
      "x": -7,
      "y": 35,
      "z": 10,
      "name": "Plant_Leaves_Jungle"
    },
    {
      "x": -7,
      "y": 30,
      "z": 11,
      "name": "Plant_Leaves_Jungle"
    },
    {
      "x": -7,
      "y": 31,
      "z": 11,
      "name": "Plant_Leaves_Jungle"
    },
    {
      "x": -7,
      "y": 32,
      "z": 11,
      "name": "Plant_Leaves_Jungle"
    },
    {
      "x": -7,
      "y": 33,
      "z": 11,
      "name": "Plant_Leaves_Jungle"
    },
    {
      "x": -7,
      "y": 34,
      "z": 11,
      "name": "Plant_Leaves_Jungle"
    },
    {
      "x": -7,
      "y": 35,
      "z": 11,
      "name": "Plant_Leaves_Jungle"
    },
    {
      "x": -6,
      "y": 32,
      "z": -9,
      "name": "Plant_Leaves_Jungle"
    },
    {
      "x": -6,
      "y": 33,
      "z": -9,
      "name": "Plant_Leaves_Jungle"
    },
    {
      "x": -6,
      "y": 31,
      "z": -8,
      "name": "Plant_Leaves_Jungle"
    },
    {
      "x": -6,
      "y": 32,
      "z": -8,
      "name": "Plant_Leaves_Jungle"
    },
    {
      "x": -6,
      "y": 33,
      "z": -8,
      "name": "Plant_Leaves_Jungle"
    },
    {
      "x": -6,
      "y": 34,
      "z": -8,
      "name": "Plant_Leaves_Jungle"
    },
    {
      "x": -6,
      "y": 26,
      "z": -7,
      "name": "Plant_Leaves_Jungle"
    },
    {
      "x": -6,
      "y": 27,
      "z": -7,
      "name": "Plant_Leaves_Jungle"
    },
    {
      "x": -6,
      "y": 34,
      "z": -7,
      "name": "Plant_Leaves_Jungle"
    },
    {
      "x": -6,
      "y": 35,
      "z": -7,
      "name": "Plant_Leaves_Jungle"
    },
    {
      "x": -6,
      "y": 25,
      "z": -6,
      "name": "Plant_Leaves_Jungle"
    },
    {
      "x": -6,
      "y": 26,
      "z": -6,
      "name": "Plant_Leaves_Jungle"
    },
    {
      "x": -6,
      "y": 27,
      "z": -6,
      "name": "Plant_Leaves_Jungle"
    },
    {
      "x": -6,
      "y": 28,
      "z": -6,
      "name": "Plant_Leaves_Jungle"
    },
    {
      "x": -6,
      "y": 36,
      "z": -6,
      "name": "Plant_Leaves_Jungle"
    },
    {
      "x": -6,
      "y": 35,
      "z": -4,
      "name": "Plant_Leaves_Jungle"
    },
    {
      "x": -6,
      "y": 36,
      "z": -4,
      "name": "Plant_Leaves_Jungle"
    },
    {
      "x": -6,
      "y": 36,
      "z": -3,
      "name": "Plant_Leaves_Jungle"
    },
    {
      "x": -6,
      "y": 39,
      "z": -3,
      "name": "Plant_Leaves_Jungle"
    },
    {
      "x": -6,
      "y": 40,
      "z": -3,
      "name": "Plant_Leaves_Jungle"
    },
    {
      "x": -6,
      "y": 6,
      "z": -2,
      "name": "Wood_Jungle_Trunk"
    },
    {
      "x": -6,
      "y": 7,
      "z": -2,
      "name": "Wood_Jungle_Trunk"
    },
    {
      "x": -6,
      "y": 8,
      "z": -2,
      "name": "Wood_Jungle_Trunk"
    },
    {
      "x": -6,
      "y": 9,
      "z": -2,
      "name": "Wood_Jungle_Trunk_Full"
    },
    {
      "x": -6,
      "y": 13,
      "z": -2,
      "name": "Plant_Vine_Liana",
      "rotation": 2
    },
    {
      "x": -6,
      "y": 14,
      "z": -2,
      "name": "Plant_Vine_Liana",
      "rotation": 2
    },
    {
      "x": -6,
      "y": 37,
      "z": -2,
      "name": "Plant_Leaves_Jungle"
    },
    {
      "x": -6,
      "y": 40,
      "z": -2,
      "name": "Plant_Leaves_Jungle"
    },
    {
      "x": -6,
      "y": 41,
      "z": -2,
      "name": "Plant_Leaves_Jungle"
    },
    {
      "x": -6,
      "y": 5,
      "z": -1,
      "name": "Wood_Jungle_Trunk"
    },
    {
      "x": -6,
      "y": 6,
      "z": -1,
      "name": "Wood_Jungle_Trunk"
    },
    {
      "x": -6,
      "y": 7,
      "z": -1,
      "name": "Wood_Jungle_Trunk"
    },
    {
      "x": -6,
      "y": 8,
      "z": -1,
      "name": "Wood_Jungle_Trunk"
    },
    {
      "x": -6,
      "y": 9,
      "z": -1,
      "name": "Wood_Jungle_Trunk"
    },
    {
      "x": -6,
      "y": 10,
      "z": -1,
      "name": "Wood_Jungle_Trunk"
    },
    {
      "x": -6,
      "y": 11,
      "z": -1,
      "name": "Wood_Jungle_Trunk"
    },
    {
      "x": -6,
      "y": 12,
      "z": -1,
      "name": "Wood_Jungle_Trunk"
    },
    {
      "x": -6,
      "y": 13,
      "z": -1,
      "name": "Wood_Jungle_Trunk"
    },
    {
      "x": -6,
      "y": 14,
      "z": -1,
      "name": "Wood_Jungle_Trunk_Full"
    },
    {
      "x": -6,
      "y": 31,
      "z": -1,
      "name": "Wood_Jungle_Trunk_Full"
    },
    {
      "x": -6,
      "y": 40,
      "z": -1,
      "name": "Wood_Jungle_Branch_Long",
      "rotation": 5
    },
    {
      "x": -6,
      "y": 41,
      "z": -1,
      "name": "Plant_Leaves_Jungle"
    },
    {
      "x": -6,
      "y": 6,
      "z": 0,
      "name": "Wood_Jungle_Trunk"
    },
    {
      "x": -6,
      "y": 7,
      "z": 0,
      "name": "Wood_Jungle_Trunk"
    },
    {
      "x": -6,
      "y": 8,
      "z": 0,
      "name": "Wood_Jungle_Trunk"
    },
    {
      "x": -6,
      "y": 9,
      "z": 0,
      "name": "Wood_Jungle_Trunk"
    },
    {
      "x": -6,
      "y": 10,
      "z": 0,
      "name": "Wood_Jungle_Trunk"
    },
    {
      "x": -6,
      "y": 11,
      "z": 0,
      "name": "Wood_Jungle_Trunk"
    },
    {
      "x": -6,
      "y": 12,
      "z": 0,
      "name": "Wood_Jungle_Trunk"
    },
    {
      "x": -6,
      "y": 13,
      "z": 0,
      "name": "Wood_Jungle_Trunk"
    },
    {
      "x": -6,
      "y": 14,
      "z": 0,
      "name": "Wood_Jungle_Trunk"
    },
    {
      "x": -6,
      "y": 15,
      "z": 0,
      "name": "Wood_Jungle_Trunk"
    },
    {
      "x": -6,
      "y": 16,
      "z": 0,
      "name": "Wood_Jungle_Trunk"
    },
    {
      "x": -6,
      "y": 17,
      "z": 0,
      "name": "Wood_Jungle_Trunk_Full"
    },
    {
      "x": -6,
      "y": 24,
      "z": 0,
      "name": "Wood_Jungle_Trunk_Full"
    },
    {
      "x": -6,
      "y": 31,
      "z": 0,
      "name": "Wood_Jungle_Trunk_Full"
    },
    {
      "x": -6,
      "y": 32,
      "z": 0,
      "name": "Rock_Crystal_Red_Medium"
    },
    {
      "x": -6,
      "y": 39,
      "z": 0,
      "name": "Plant_Leaves_Jungle"
    },
    {
      "x": -6,
      "y": 40,
      "z": 0,
      "name": "Plant_Leaves_Jungle"
    },
    {
      "x": -6,
      "y": 6,
      "z": 1,
      "name": "Wood_Jungle_Trunk"
    },
    {
      "x": -6,
      "y": 7,
      "z": 1,
      "name": "Wood_Jungle_Trunk"
    },
    {
      "x": -6,
      "y": 8,
      "z": 1,
      "name": "Wood_Jungle_Trunk"
    },
    {
      "x": -6,
      "y": 9,
      "z": 1,
      "name": "Wood_Jungle_Trunk"
    },
    {
      "x": -6,
      "y": 10,
      "z": 1,
      "name": "Wood_Jungle_Trunk"
    },
    {
      "x": -6,
      "y": 11,
      "z": 1,
      "name": "Wood_Jungle_Trunk"
    },
    {
      "x": -6,
      "y": 12,
      "z": 1,
      "name": "Wood_Jungle_Trunk"
    },
    {
      "x": -6,
      "y": 13,
      "z": 1,
      "name": "Wood_Jungle_Trunk"
    },
    {
      "x": -6,
      "y": 14,
      "z": 1,
      "name": "Wood_Jungle_Trunk"
    },
    {
      "x": -6,
      "y": 15,
      "z": 1,
      "name": "Wood_Jungle_Trunk"
    },
    {
      "x": -6,
      "y": 16,
      "z": 1,
      "name": "Wood_Jungle_Trunk"
    },
    {
      "x": -6,
      "y": 17,
      "z": 1,
      "name": "Wood_Jungle_Trunk"
    },
    {
      "x": -6,
      "y": 18,
      "z": 1,
      "name": "Wood_Jungle_Trunk"
    },
    {
      "x": -6,
      "y": 19,
      "z": 1,
      "name": "Wood_Jungle_Trunk_Full"
    },
    {
      "x": -6,
      "y": 6,
      "z": 2,
      "name": "Wood_Jungle_Trunk"
    },
    {
      "x": -6,
      "y": 7,
      "z": 2,
      "name": "Wood_Jungle_Trunk"
    },
    {
      "x": -6,
      "y": 8,
      "z": 2,
      "name": "Wood_Jungle_Trunk"
    },
    {
      "x": -6,
      "y": 9,
      "z": 2,
      "name": "Wood_Jungle_Trunk"
    },
    {
      "x": -6,
      "y": 10,
      "z": 2,
      "name": "Wood_Jungle_Trunk"
    },
    {
      "x": -6,
      "y": 11,
      "z": 2,
      "name": "Wood_Jungle_Trunk"
    },
    {
      "x": -6,
      "y": 12,
      "z": 2,
      "name": "Wood_Jungle_Trunk"
    },
    {
      "x": -6,
      "y": 13,
      "z": 2,
      "name": "Wood_Jungle_Trunk"
    },
    {
      "x": -6,
      "y": 14,
      "z": 2,
      "name": "Wood_Jungle_Trunk"
    },
    {
      "x": -6,
      "y": 15,
      "z": 2,
      "name": "Wood_Jungle_Trunk"
    },
    {
      "x": -6,
      "y": 16,
      "z": 2,
      "name": "Wood_Jungle_Trunk"
    },
    {
      "x": -6,
      "y": 17,
      "z": 2,
      "name": "Wood_Jungle_Trunk"
    },
    {
      "x": -6,
      "y": 18,
      "z": 2,
      "name": "Wood_Jungle_Trunk"
    },
    {
      "x": -6,
      "y": 19,
      "z": 2,
      "name": "Wood_Jungle_Trunk_Full"
    },
    {
      "x": -6,
      "y": 20,
      "z": 2,
      "name": "Plant_Vine_Liana",
      "rotation": 3
    },
    {
      "x": -6,
      "y": 21,
      "z": 2,
      "name": "Plant_Vine_Liana",
      "rotation": 3
    },
    {
      "x": -6,
      "y": 6,
      "z": 3,
      "name": "Wood_Jungle_Trunk"
    },
    {
      "x": -6,
      "y": 7,
      "z": 3,
      "name": "Wood_Jungle_Trunk"
    },
    {
      "x": -6,
      "y": 8,
      "z": 3,
      "name": "Wood_Jungle_Trunk"
    },
    {
      "x": -6,
      "y": 9,
      "z": 3,
      "name": "Wood_Jungle_Trunk"
    },
    {
      "x": -6,
      "y": 10,
      "z": 3,
      "name": "Wood_Jungle_Trunk"
    },
    {
      "x": -6,
      "y": 11,
      "z": 3,
      "name": "Wood_Jungle_Trunk"
    },
    {
      "x": -6,
      "y": 12,
      "z": 3,
      "name": "Wood_Jungle_Trunk"
    },
    {
      "x": -6,
      "y": 13,
      "z": 3,
      "name": "Wood_Jungle_Trunk"
    },
    {
      "x": -6,
      "y": 14,
      "z": 3,
      "name": "Wood_Jungle_Trunk"
    },
    {
      "x": -6,
      "y": 15,
      "z": 3,
      "name": "Wood_Jungle_Trunk"
    },
    {
      "x": -6,
      "y": 16,
      "z": 3,
      "name": "Wood_Jungle_Trunk"
    },
    {
      "x": -6,
      "y": 17,
      "z": 3,
      "name": "Wood_Jungle_Trunk"
    },
    {
      "x": -6,
      "y": 18,
      "z": 3,
      "name": "Wood_Jungle_Trunk_Full"
    },
    {
      "x": -6,
      "y": 37,
      "z": 3,
      "name": "Plant_Leaves_Jungle"
    },
    {
      "x": -6,
      "y": 5,
      "z": 4,
      "name": "Wood_Jungle_Trunk"
    },
    {
      "x": -6,
      "y": 6,
      "z": 4,
      "name": "Wood_Jungle_Trunk"
    },
    {
      "x": -6,
      "y": 7,
      "z": 4,
      "name": "Wood_Jungle_Trunk"
    },
    {
      "x": -6,
      "y": 8,
      "z": 4,
      "name": "Wood_Jungle_Trunk"
    },
    {
      "x": -6,
      "y": 9,
      "z": 4,
      "name": "Wood_Jungle_Trunk"
    },
    {
      "x": -6,
      "y": 10,
      "z": 4,
      "name": "Wood_Jungle_Trunk"
    },
    {
      "x": -6,
      "y": 11,
      "z": 4,
      "name": "Wood_Jungle_Trunk"
    },
    {
      "x": -6,
      "y": 12,
      "z": 4,
      "name": "Wood_Jungle_Trunk"
    },
    {
      "x": -6,
      "y": 13,
      "z": 4,
      "name": "Wood_Jungle_Trunk"
    },
    {
      "x": -6,
      "y": 14,
      "z": 4,
      "name": "Wood_Jungle_Trunk"
    },
    {
      "x": -6,
      "y": 15,
      "z": 4,
      "name": "Wood_Jungle_Trunk"
    },
    {
      "x": -6,
      "y": 16,
      "z": 4,
      "name": "Wood_Jungle_Trunk_Full"
    },
    {
      "x": -6,
      "y": 31,
      "z": 4,
      "name": "Wood_Jungle_Trunk_Full"
    },
    {
      "x": -6,
      "y": 32,
      "z": 4,
      "name": "Wood_Jungle_Trunk"
    },
    {
      "x": -6,
      "y": 33,
      "z": 4,
      "name": "Wood_Jungle_Trunk"
    },
    {
      "x": -6,
      "y": 34,
      "z": 4,
      "name": "Wood_Jungle_Trunk"
    },
    {
      "x": -6,
      "y": 35,
      "z": 4,
      "name": "Wood_Jungle_Trunk_Full"
    },
    {
      "x": -6,
      "y": 37,
      "z": 4,
      "name": "Plant_Leaves_Jungle"
    },
    {
      "x": -6,
      "y": 5,
      "z": 5,
      "name": "Wood_Jungle_Trunk"
    },
    {
      "x": -6,
      "y": 6,
      "z": 5,
      "name": "Wood_Jungle_Trunk"
    },
    {
      "x": -6,
      "y": 7,
      "z": 5,
      "name": "Wood_Jungle_Trunk"
    },
    {
      "x": -6,
      "y": 8,
      "z": 5,
      "name": "Wood_Jungle_Trunk"
    },
    {
      "x": -6,
      "y": 9,
      "z": 5,
      "name": "Wood_Jungle_Trunk"
    },
    {
      "x": -6,
      "y": 10,
      "z": 5,
      "name": "Wood_Jungle_Trunk"
    },
    {
      "x": -6,
      "y": 11,
      "z": 5,
      "name": "Wood_Jungle_Trunk"
    },
    {
      "x": -6,
      "y": 12,
      "z": 5,
      "name": "Wood_Jungle_Trunk_Full"
    },
    {
      "x": -6,
      "y": 35,
      "z": 5,
      "name": "Wood_Jungle_Trunk_Full"
    },
    {
      "x": -6,
      "y": 36,
      "z": 5,
      "name": "Wood_Jungle_Branch_Long"
    },
    {
      "x": -6,
      "y": 37,
      "z": 5,
      "name": "Plant_Leaves_Jungle"
    },
    {
      "x": -6,
      "y": 5,
      "z": 6,
      "name": "Wood_Jungle_Trunk"
    },
    {
      "x": -6,
      "y": 6,
      "z": 6,
      "name": "Wood_Jungle_Trunk"
    },
    {
      "x": -6,
      "y": 7,
      "z": 6,
      "name": "Wood_Jungle_Trunk_Full"
    },
    {
      "x": -6,
      "y": 37,
      "z": 6,
      "name": "Plant_Leaves_Jungle"
    },
    {
      "x": -6,
      "y": 35,
      "z": 7,
      "name": "Plant_Leaves_Jungle"
    },
    {
      "x": -6,
      "y": 36,
      "z": 7,
      "name": "Plant_Leaves_Jungle"
    },
    {
      "x": -6,
      "y": 36,
      "z": 8,
      "name": "Plant_Leaves_Jungle"
    },
    {
      "x": -6,
      "y": 36,
      "z": 9,
      "name": "Plant_Leaves_Jungle"
    },
    {
      "x": -6,
      "y": 33,
      "z": 10,
      "name": "Plant_Leaves_Jungle"
    },
    {
      "x": -6,
      "y": 34,
      "z": 10,
      "name": "Plant_Leaves_Jungle"
    },
    {
      "x": -6,
      "y": 35,
      "z": 10,
      "name": "Plant_Leaves_Jungle"
    },
    {
      "x": -6,
      "y": 34,
      "z": 11,
      "name": "Plant_Leaves_Jungle"
    },
    {
      "x": -6,
      "y": 35,
      "z": 11,
      "name": "Plant_Leaves_Jungle"
    },
    {
      "x": -5,
      "y": 33,
      "z": -11,
      "name": "Plant_Leaves_Jungle"
    },
    {
      "x": -5,
