{
  "version": 8,
  "blockIdVersion": 8,
  "anchorX": 0,
  "anchorY": 1,
  "anchorZ": 8,
  "blocks": [
    {
      "x": -4,
      "y": 1,
      "z": -8,
      "name": "Rock_Stone"
    },
    {
      "x": -4,
      "y": 2,
      "z": -8,
      "name": "Rock_Quartzite_Brick"
    },
    {
      "x": -4,
      "y": 3,
      "z": -8,
      "name": "Rock_Quartzite_Brick"
    },
    {
      "x": -4,
      "y": 4,
      "z": -8,
      "name": "Rock_Quartzite"
    },
    {
      "x": -4,
      "y": 5,
      "z": -8,
      "name": "Rock_Quartzite"
    },
    {
      "x": -4,
      "y": 6,
      "z": -8,
      "name": "Rock_Quartzite"
    },
    {
      "x": -4,
      "y": 7,
      "z": -8,
      "name": "Rock_Quartzite"
    },
    {
      "x": -4,
      "y": 1,
      "z": -7,
      "name": "Rock_Stone"
    },
    {
      "x": -4,
      "y": 2,
      "z": -7,
      "name": "Rock_Quartzite_Brick"
    },
    {
      "x": -4,
      "y": 3,
      "z": -7,
      "name": "Rock_Quartzite_Brick"
    },
    {
      "x": -4,
      "y": 4,
      "z": -7,
      "name": "Rock_Quartzite"
    },
    {
      "x": -4,
      "y": 5,
      "z": -7,
      "name": "Rock_Quartzite"
    },
    {
      "x": -4,
      "y": 6,
      "z": -7,
      "name": "Rock_Quartzite"
    },
    {
      "x": -4,
      "y": 7,
      "z": -7,
      "name": "Rock_Quartzite"
    },
    {
      "x": -4,
      "y": 1,
      "z": -6,
      "name": "Rock_Stone"
    },
    {
      "x": -4,
      "y": 2,
      "z": -6,
      "name": "Rock_Quartzite_Brick"
    },
    {
      "x": -4,
      "y": 3,
      "z": -6,
      "name": "Rock_Quartzite_Brick"
    },
    {
      "x": -4,
      "y": 4,
      "z": -6,
      "name": "Rock_Quartzite"
    },
    {
      "x": -4,
      "y": 5,
      "z": -6,
      "name": "Rock_Quartzite"
    },
    {
      "x": -4,
      "y": 6,
      "z": -6,
      "name": "Rock_Quartzite"
    },
    {
      "x": -4,
      "y": 7,
      "z": -6,
      "name": "Rock_Quartzite"
    },
    {
      "x": -4,
      "y": 1,
      "z": -5,
      "name": "Rock_Stone"
    },
    {
      "x": -4,
      "y": 2,
      "z": -5,
      "name": "Rock_Quartzite_Brick"
    },
    {
      "x": -4,
      "y": 3,
      "z": -5,
      "name": "Rock_Quartzite_Brick"
    },
    {
      "x": -4,
      "y": 4,
      "z": -5,
      "name": "Rock_Quartzite"
    },
    {
      "x": -4,
      "y": 5,
      "z": -5,
      "name": "Rock_Quartzite_Cobble"
    },
    {
      "x": -4,
      "y": 6,
      "z": -5,
      "name": "Rock_Quartzite"
    },
    {
      "x": -4,
      "y": 7,
      "z": -5,
      "name": "Rock_Quartzite"
    },
    {
      "x": -4,
      "y": 1,
      "z": -4,
      "name": "Rock_Stone"
    },
    {
      "x": -4,
      "y": 2,
      "z": -4,
      "name": "Rock_Quartzite_Brick"
    },
    {
      "x": -4,
      "y": 3,
      "z": -4,
      "name": "Rock_Quartzite_Cobble"
    },
    {
      "x": -4,
      "y": 4,
      "z": -4,
      "name": "Rock_Quartzite_Cobble"
    },
    {
      "x": -4,
      "y": 5,
      "z": -4,
      "name": "Rock_Quartzite_Cobble"
    },
    {
      "x": -4,
      "y": 6,
      "z": -4,
      "name": "Rock_Quartzite"
    },
    {
      "x": -4,
      "y": 7,
      "z": -4,
      "name": "Rock_Quartzite"
    },
    {
      "x": -4,
      "y": 1,
      "z": -3,
      "name": "Rock_Stone"
    },
    {
      "x": -4,
      "y": 2,
      "z": -3,
      "name": "Rock_Quartzite_Brick"
    },
    {
      "x": -4,
      "y": 3,
      "z": -3,
      "name": "Rock_Quartzite_Brick"
    },
    {
      "x": -4,
      "y": 4,
      "z": -3,
      "name": "Rock_Quartzite"
    },
    {
      "x": -4,
      "y": 5,
      "z": -3,
      "name": "Rock_Quartzite"
    },
    {
      "x": -4,
      "y": 6,
      "z": -3,
      "name": "Rock_Quartzite"
    },
    {
      "x": -4,
      "y": 7,
      "z": -3,
      "name": "Rock_Quartzite"
    },
    {
      "x": -4,
      "y": 1,
      "z": -2,
      "name": "Rock_Stone"
    },
    {
      "x": -4,
      "y": 2,
      "z": -2,
      "name": "Rock_Quartzite_Brick"
    },
    {
      "x": -4,
      "y": 3,
      "z": -2,
      "name": "Rock_Quartzite_Brick"
    },
    {
      "x": -4,
      "y": 4,
      "z": -2,
      "name": "Rock_Quartzite"
    },
    {
      "x": -4,
      "y": 5,
      "z": -2,
      "name": "Rock_Quartzite"
    },
    {
      "x": -4,
      "y": 6,
      "z": -2,
      "name": "Rock_Quartzite"
    },
    {
      "x": -4,
      "y": 7,
      "z": -2,
      "name": "Rock_Quartzite"
    },
    {
      "x": -4,
      "y": 1,
      "z": -1,
      "name": "Rock_Stone"
    },
    {
      "x": -4,
      "y": 2,
      "z": -1,
      "name": "Rock_Quartzite_Brick"
    },
    {
      "x": -4,
      "y": 3,
      "z": -1,
      "name": "Rock_Quartzite_Brick"
    },
    {
      "x": -4,
      "y": 4,
      "z": -1,
      "name": "Rock_Quartzite"
    },
    {
      "x": -4,
      "y": 5,
      "z": -1,
      "name": "Rock_Quartzite"
    },
    {
      "x": -4,
      "y": 6,
      "z": -1,
      "name": "Rock_Quartzite"
    },
    {
      "x": -4,
      "y": 7,
      "z": -1,
      "name": "Rock_Quartzite"
    },
    {
      "x": -4,
      "y": 1,
      "z": 0,
      "name": "Rock_Stone"
    },
    {
      "x": -4,
      "y": 2,
      "z": 0,
      "name": "Rock_Quartzite_Brick"
    },
    {
      "x": -4,
      "y": 3,
      "z": 0,
      "name": "Rock_Quartzite_Brick"
    },
    {
      "x": -4,
      "y": 4,
      "z": 0,
      "name": "Rock_Quartzite"
    },
    {
      "x": -4,
      "y": 5,
      "z": 0,
      "name": "Rock_Quartzite"
    },
    {
      "x": -4,
      "y": 6,
      "z": 0,
      "name": "Rock_Quartzite"
    },
    {
      "x": -4,
      "y": 7,
      "z": 0,
      "name": "Rock_Quartzite"
    },
    {
      "x": -4,
      "y": 1,
      "z": 1,
      "name": "Rock_Stone"
    },
    {
      "x": -4,
      "y": 2,
      "z": 1,
      "name": "Rock_Quartzite_Brick"
    },
    {
      "x": -4,
      "y": 3,
      "z": 1,
      "name": "Rock_Quartzite_Brick"
    },
    {
      "x": -4,
      "y": 4,
      "z": 1,
      "name": "Rock_Quartzite"
    },
    {
      "x": -4,
      "y": 5,
      "z": 1,
      "name": "Rock_Quartzite"
    },
    {
      "x": -4,
      "y": 6,
      "z": 1,
      "name": "Rock_Quartzite"
    },
    {
      "x": -4,
      "y": 7,
      "z": 1,
      "name": "Rock_Quartzite"
    },
    {
      "x": -4,
      "y": 1,
      "z": 2,
      "name": "Rock_Stone"
    },
    {
      "x": -4,
      "y": 2,
      "z": 2,
      "name": "Rock_Quartzite_Brick"
    },
    {
      "x": -4,
      "y": 3,
      "z": 2,
      "name": "Rock_Quartzite_Brick"
    },
    {
      "x": -4,
      "y": 4,
      "z": 2,
      "name": "Rock_Quartzite"
    },
    {
      "x": -4,
      "y": 5,
      "z": 2,
      "name": "Rock_Quartzite"
    },
    {
      "x": -4,
      "y": 6,
      "z": 2,
      "name": "Rock_Quartzite"
    },
    {
      "x": -4,
      "y": 7,
      "z": 2,
      "name": "Rock_Quartzite"
    },
    {
      "x": -4,
      "y": 1,
      "z": 3,
      "name": "Rock_Stone"
    },
    {
      "x": -4,
      "y": 2,
      "z": 3,
      "name": "Rock_Quartzite_Brick"
    },
    {
      "x": -4,
      "y": 3,
      "z": 3,
      "name": "Rock_Quartzite_Brick"
    },
    {
      "x": -4,
      "y": 4,
      "z": 3,
      "name": "Rock_Quartzite"
    },
    {
      "x": -4,
      "y": 5,
      "z": 3,
      "name": "Rock_Quartzite"
    },
    {
      "x": -4,
      "y": 6,
      "z": 3,
      "name": "Rock_Quartzite"
    },
    {
      "x": -4,
      "y": 7,
      "z": 3,
      "name": "Rock_Quartzite"
    },
    {
      "x": -4,
      "y": 1,
      "z": 4,
      "name": "Rock_Stone"
    },
    {
      "x": -4,
      "y": 2,
      "z": 4,
      "name": "Rock_Quartzite_Brick"
    },
    {
      "x": -4,
      "y": 3,
      "z": 4,
      "name": "Rock_Quartzite_Brick"
    },
    {
      "x": -4,
      "y": 4,
      "z": 4,
      "name": "Rock_Quartzite"
    },
    {
      "x": -4,
      "y": 5,
      "z": 4,
      "name": "Rock_Quartzite"
    },
    {
      "x": -4,
      "y": 6,
      "z": 4,
      "name": "Rock_Quartzite"
    },
    {
      "x": -4,
      "y": 7,
      "z": 4,
      "name": "Rock_Quartzite"
    },
    {
      "x": -4,
      "y": 1,
      "z": 5,
      "name": "Rock_Stone"
    },
    {
      "x": -4,
      "y": 2,
      "z": 5,
      "name": "Rock_Quartzite_Brick"
    },
    {
      "x": -4,
      "y": 3,
      "z": 5,
      "name": "Rock_Quartzite_Brick"
    },
    {
      "x": -4,
      "y": 4,
      "z": 5,
      "name": "Rock_Quartzite"
    },
    {
      "x": -4,
      "y": 5,
      "z": 5,
      "name": "Rock_Quartzite"
    },
    {
      "x": -4,
      "y": 6,
      "z": 5,
      "name": "Rock_Quartzite"
    },
    {
      "x": -4,
      "y": 7,
      "z": 5,
      "name": "Rock_Quartzite"
    },
    {
      "x": -4,
      "y": 1,
      "z": 6,
      "name": "Rock_Stone"
    },
    {
      "x": -4,
      "y": 2,
      "z": 6,
      "name": "Rock_Quartzite_Brick"
    },
    {
      "x": -4,
      "y": 3,
      "z": 6,
      "name": "Rock_Quartzite_Brick"
    },
    {
      "x": -4,
      "y": 4,
      "z": 6,
      "name": "Rock_Quartzite"
    },
    {
      "x": -4,
      "y": 5,
      "z": 6,
      "name": "Rock_Quartzite"
    },
    {
      "x": -4,
      "y": 6,
      "z": 6,
      "name": "Rock_Quartzite"
    },
    {
      "x": -4,
      "y": 7,
      "z": 6,
      "name": "Rock_Quartzite"
    },
    {
      "x": -4,
      "y": 1,
      "z": 7,
      "name": "Rock_Stone"
    },
    {
      "x": -4,
      "y": 2,
      "z": 7,
      "name": "Rock_Quartzite_Brick"
    },
    {
      "x": -4,
      "y": 3,
      "z": 7,
      "name": "Rock_Quartzite_Brick"
    },
    {
      "x": -4,
      "y": 4,
      "z": 7,
      "name": "Rock_Quartzite"
    },
    {
      "x": -4,
      "y": 5,
      "z": 7,
      "name": "Rock_Quartzite"
    },
    {
      "x": -4,
      "y": 6,
      "z": 7,
      "name": "Rock_Quartzite"
    },
    {
      "x": -4,
      "y": 7,
      "z": 7,
      "name": "Rock_Quartzite"
    },
    {
      "x": -4,
      "y": 1,
      "z": 8,
      "name": "Rock_Stone"
    },
    {
      "x": -4,
      "y": 2,
      "z": 8,
      "name": "Rock_Quartzite_Brick"
    },
    {
      "x": -4,
      "y": 3,
      "z": 8,
      "name": "Rock_Quartzite_Brick"
    },
    {
      "x": -4,
      "y": 4,
      "z": 8,
      "name": "Rock_Quartzite"
    },
    {
      "x": -4,
      "y": 5,
      "z": 8,
      "name": "Rock_Quartzite"
    },
    {
      "x": -4,
      "y": 6,
      "z": 8,
      "name": "Rock_Quartzite"
    },
    {
      "x": -4,
      "y": 7,
      "z": 8,
      "name": "Rock_Quartzite"
    },
    {
      "x": -3,
      "y": 0,
      "z": -8,
      "name": "Rock_Stone"
    },
    {
      "x": -3,
      "y": 1,
      "z": -8,
      "name": "Rock_Stone_Cobble"
    },
    {
      "x": -3,
      "y": 2,
      "z": -8,
      "name": "Rock_Stone_Brick_Pillar_Base"
    },
    {
      "x": -3,
      "y": 3,
      "z": -8,
      "name": "Rock_Stone_Brick_Pillar_Middle"
    },
    {
      "x": -3,
      "y": 4,
      "z": -8,
      "name": "Rock_Stone_Brick_Pillar_Base",
      "rotation": 8
    },
    {
      "x": -3,
      "y": 5,
      "z": -8,
      "name": "Rock_Stone_Brick"
    },
    {
      "x": -3,
      "y": 6,
      "z": -8,
      "name": "Rock_Stone_Brick"
    },
    {
      "x": -3,
      "y": 7,
      "z": -8,
      "name": "Rock_Quartzite"
    },
    {
      "x": -3,
      "y": 8,
      "z": -8,
      "name": "Rock_Quartzite"
    },
    {
      "x": -3,
      "y": 0,
      "z": -7,
      "name": "Rock_Stone"
    },
    {
      "x": -3,
      "y": 1,
      "z": -7,
      "name": "Rock_Stone"
    },
    {
      "x": -3,
      "y": 2,
      "z": -7,
      "name": "Rock_Stone"
    },
    {
      "x": -3,
      "y": 3,
      "z": -7,
      "name": "Rock_Stone"
    },
    {
      "x": -3,
      "y": 4,
      "z": -7,
      "name": "Rock_Stone"
    },
    {
      "x": -3,
      "y": 5,
      "z": -7,
      "name": "Rock_Stone"
    },
    {
      "x": -3,
      "y": 6,
      "z": -7,
      "name": "Rock_Quartzite"
    },
    {
      "x": -3,
      "y": 7,
      "z": -7,
      "name": "Rock_Quartzite"
    },
    {
      "x": -3,
      "y": 8,
      "z": -7,
      "name": "Rock_Quartzite"
    },
    {
      "x": -3,
      "y": 0,
      "z": -6,
      "name": "Rock_Stone"
    },
    {
      "x": -3,
      "y": 1,
      "z": -6,
      "name": "Rock_Stone"
    },
    {
      "x": -3,
      "y": 2,
      "z": -6,
      "name": "Rock_Stone"
    },
    {
      "x": -3,
      "y": 3,
      "z": -6,
      "name": "Rock_Stone"
    },
    {
      "x": -3,
      "y": 4,
      "z": -6,
      "name": "Rock_Stone"
    },
    {
      "x": -3,
      "y": 5,
      "z": -6,
      "name": "Rock_Stone"
    },
    {
      "x": -3,
      "y": 6,
      "z": -6,
      "name": "Rock_Quartzite"
    },
    {
      "x": -3,
      "y": 7,
      "z": -6,
      "name": "Rock_Quartzite"
    },
    {
      "x": -3,
      "y": 8,
      "z": -6,
      "name": "Rock_Quartzite"
    },
    {
      "x": -3,
      "y": 0,
      "z": -5,
      "name": "Rock_Stone"
    },
    {
      "x": -3,
      "y": 1,
      "z": -5,
      "name": "Rock_Stone_Cobble"
    },
    {
      "x": -3,
      "y": 2,
      "z": -5,
      "name": "Empty"
    },
    {
      "x": -3,
      "y": 3,
      "z": -5,
      "name": "Empty"
    },
    {
      "x": -3,
      "y": 4,
      "z": -5,
      "name": "Empty"
    },
    {
      "x": -3,
      "y": 5,
      "z": -5,
      "name": "Empty"
    },
    {
      "x": -3,
      "y": 6,
      "z": -5,
      "name": "Rock_Quartzite"
    },
    {
      "x": -3,
      "y": 7,
      "z": -5,
      "name": "Rock_Quartzite"
    },
    {
      "x": -3,
      "y": 8,
      "z": -5,
      "name": "Rock_Quartzite"
    },
    {
      "x": -3,
      "y": 0,
      "z": -4,
      "name": "Rock_Stone"
    },
    {
      "x": -3,
      "y": 1,
      "z": -4,
      "name": "Rock_Stone_Cobble"
    },
    {
      "x": -3,
      "y": 2,
      "z": -4,
      "name": "Empty"
    },
    {
      "x": -3,
      "y": 3,
      "z": -4,
      "name": "Empty"
    },
    {
      "x": -3,
      "y": 4,
      "z": -4,
      "name": "Empty"
    },
    {
      "x": -3,
      "y": 5,
      "z": -4,
      "name": "Empty"
    },
    {
      "x": -3,
      "y": 6,
      "z": -4,
      "name": "Rock_Quartzite"
    },
    {
      "x": -3,
      "y": 7,
      "z": -4,
      "name": "Rock_Quartzite"
    },
    {
      "x": -3,
      "y": 8,
      "z": -4,
      "name": "Rock_Quartzite"
    },
    {
      "x": -3,
      "y": 0,
      "z": -3,
      "name": "Rock_Stone"
    },
    {
      "x": -3,
      "y": 1,
      "z": -3,
      "name": "Rock_Stone"
    },
    {
      "x": -3,
      "y": 2,
      "z": -3,
      "name": "Rock_Stone"
    },
    {
      "x": -3,
      "y": 3,
      "z": -3,
      "name": "Rock_Stone"
    },
    {
      "x": -3,
      "y": 4,
      "z": -3,
      "name": "Rock_Stone"
    },
    {
      "x": -3,
      "y": 5,
      "z": -3,
      "name": "Rock_Stone"
    },
    {
      "x": -3,
      "y": 6,
      "z": -3,
      "name": "Rock_Stone"
    },
    {
      "x": -3,
      "y": 7,
      "z": -3,
      "name": "Rock_Quartzite"
    },
    {
      "x": -3,
      "y": 8,
      "z": -3,
      "name": "Rock_Quartzite"
    },
    {
      "x": -3,
      "y": 0,
      "z": -2,
      "name": "Rock_Stone"
    },
    {
      "x": -3,
      "y": 1,
      "z": -2,
      "name": "Rock_Stone"
    },
    {
      "x": -3,
      "y": 2,
      "z": -2,
      "name": "Rock_Stone"
    },
    {
      "x": -3,
      "y": 3,
      "z": -2,
      "name": "Rock_Stone"
    },
    {
      "x": -3,
      "y": 4,
      "z": -2,
      "name": "Rock_Stone"
    },
    {
      "x": -3,
      "y": 5,
      "z": -2,
      "name": "Rock_Stone"
    },
    {
      "x": -3,
      "y": 6,
      "z": -2,
      "name": "Rock_Stone"
    },
    {
      "x": -3,
      "y": 7,
      "z": -2,
      "name": "Rock_Quartzite"
    },
    {
      "x": -3,
      "y": 8,
      "z": -2,
      "name": "Rock_Quartzite"
    },
    {
      "x": -3,
      "y": 0,
      "z": -1,
      "name": "Rock_Stone"
    },
    {
      "x": -3,
      "y": 1,
      "z": -1,
      "name": "Rock_Stone"
    },
    {
      "x": -3,
      "y": 2,
      "z": -1,
      "name": "Rock_Stone"
    },
    {
      "x": -3,
      "y": 3,
      "z": -1,
      "name": "Rock_Stone"
    },
    {
      "x": -3,
      "y": 4,
      "z": -1,
      "name": "Rock_Stone"
    },
    {
      "x": -3,
      "y": 5,
      "z": -1,
      "name": "Rock_Stone"
    },
    {
      "x": -3,
      "y": 6,
      "z": -1,
      "name": "Rock_Stone"
    },
    {
      "x": -3,
      "y": 7,
      "z": -1,
      "name": "Rock_Quartzite"
    },
    {
      "x": -3,
      "y": 8,
      "z": -1,
      "name": "Rock_Quartzite"
    },
    {
      "x": -3,
      "y": 0,
      "z": 0,
      "name": "Rock_Stone"
    },
    {
      "x": -3,
      "y": 1,
      "z": 0,
      "name": "Rock_Stone"
    },
    {
      "x": -3,
      "y": 2,
      "z": 0,
      "name": "Rock_Stone"
    },
    {
      "x": -3,
      "y": 3,
      "z": 0,
      "name": "Rock_Stone"
    },
    {
      "x": -3,
      "y": 4,
      "z": 0,
      "name": "Rock_Stone"
    },
    {
      "x": -3,
      "y": 5,
      "z": 0,
      "name": "Rock_Stone"
    },
    {
      "x": -3,
      "y": 6,
      "z": 0,
      "name": "Rock_Stone"
    },
    {
      "x": -3,
      "y": 7,
      "z": 0,
      "name": "Rock_Quartzite"
    },
    {
      "x": -3,
      "y": 8,
      "z": 0,
      "name": "Rock_Quartzite"
    },
    {
      "x": -3,
      "y": 0,
      "z": 1,
      "name": "Rock_Stone"
    },
    {
      "x": -3,
      "y": 1,
      "z": 1,
      "name": "Rock_Stone_Cobble"
    },
    {
      "x": -3,
      "y": 2,
      "z": 1,
      "name": "Furniture_Ancient_Barrel"
    },
    {
      "x": -3,
      "y": 3,
      "z": 1,
      "name": "Rock_Stone_Stalactite_Large",
      "filler": 31744,
      "rotation": 8
    },
    {
      "x": -3,
      "y": 4,
      "z": 1,
      "name": "Rock_Stone_Stalactite_Large",
      "rotation": 8
    },
    {
      "x": -3,
      "y": 5,
      "z": 1,
      "name": "Rock_Stone"
    },
    {
      "x": -3,
      "y": 6,
      "z": 1,
      "name": "Rock_Stone"
    },
    {
      "x": -3,
      "y": 7,
      "z": 1,
      "name": "Rock_Quartzite"
    },
    {
      "x": -3,
      "y": 8,
      "z": 1,
      "name": "Rock_Quartzite"
    },
    {
      "x": -3,
      "y": 0,
      "z": 2,
      "name": "Rock_Stone"
    },
    {
      "x": -3,
      "y": 1,
      "z": 2,
      "name": "Rock_Stone_Cobble"
    },
    {
      "x": -3,
      "y": 2,
      "z": 2,
      "name": "Furniture_Ancient_Shelf",
      "rotation": 1
    },
    {
      "x": -3,
      "y": 3,
      "z": 2,
      "name": "Furniture_Tavern_Shelf",
      "rotation": 1
    },
    {
      "x": -3,
      "y": 4,
      "z": 2,
      "name": "Empty"
    },
    {
      "x": -3,
      "y": 5,
      "z": 2,
      "name": "Rock_Stone"
    },
    {
      "x": -3,
      "y": 6,
      "z": 2,
      "name": "Rock_Stone"
    },
    {
      "x": -3,
      "y": 7,
      "z": 2,
      "name": "Rock_Quartzite"
    },
    {
      "x": -3,
      "y": 8,
      "z": 2,
      "name": "Rock_Quartzite"
    },
    {
      "x": -3,
      "y": 0,
      "z": 3,
      "name": "Rock_Stone"
    },
    {
      "x": -3,
      "y": 1,
      "z": 3,
      "name": "Rock_Stone_Cobble_Mossy"
    },
    {
      "x": -3,
      "y": 2,
      "z": 3,
      "name": "Furniture_Ancient_Shelf",
      "rotation": 1
    },
    {
      "x": -3,
      "y": 3,
      "z": 3,
      "name": "Empty"
    },
    {
      "x": -3,
      "y": 4,
      "z": 3,
      "name": "Empty"
    },
    {
      "x": -3,
      "y": 5,
      "z": 3,
      "name": "Rock_Stone"
    },
    {
      "x": -3,
      "y": 6,
      "z": 3,
      "name": "Rock_Stone"
    },
    {
      "x": -3,
      "y": 7,
      "z": 3,
      "name": "Rock_Quartzite"
    },
    {
      "x": -3,
      "y": 8,
      "z": 3,
      "name": "Rock_Quartzite"
    },
    {
      "x": -3,
      "y": 0,
      "z": 4,
      "name": "Rock_Stone"
    },
    {
      "x": -3,
      "y": 1,
      "z": 4,
      "name": "Rock_Stone_Cobble"
    },
    {
      "x": -3,
      "y": 2,
      "z": 4,
      "name": "Furniture_Ancient_Barrel"
    },
    {
      "x": -3,
      "y": 3,
      "z": 4,
      "name": "Empty"
    },
    {
      "x": -3,
      "y": 4,
      "z": 4,
      "name": "Rock_Quartzite"
    },
    {
      "x": -3,
      "y": 5,
      "z": 4,
      "name": "Rock_Stone"
    },
    {
      "x": -3,
      "y": 6,
      "z": 4,
      "name": "Rock_Stone"
    },
    {
      "x": -3,
      "y": 7,
      "z": 4,
      "name": "Rock_Quartzite"
    },
    {
      "x": -3,
      "y": 8,
      "z": 4,
      "name": "Rock_Quartzite"
    },
    {
      "x": -3,
      "y": 0,
      "z": 5,
      "name": "Rock_Stone"
    },
    {
      "x": -3,
      "y": 1,
      "z": 5,
      "name": "Rock_Stone_Cobble"
    },
    {
      "x": -3,
      "y": 2,
      "z": 5,
      "name": "Rock_Quartzite"
    },
    {
      "x": -3,
      "y": 3,
      "z": 5,
      "name": "Rock_Quartzite"
    },
    {
      "x": -3,
      "y": 4,
      "z": 5,
      "name": "Rock_Quartzite"
    },
    {
      "x": -3,
      "y": 5,
      "z": 5,
      "name": "Rock_Stone"
    },
    {
      "x": -3,
      "y": 6,
      "z": 5,
      "name": "Rock_Stone"
    },
    {
      "x": -3,
      "y": 7,
      "z": 5,
      "name": "Rock_Quartzite"
    },
    {
      "x": -3,
      "y": 8,
      "z": 5,
      "name": "Rock_Quartzite"
    },
    {
      "x": -3,
      "y": 0,
      "z": 6,
      "name": "Rock_Stone"
    },
    {
      "x": -3,
      "y": 1,
      "z": 6,
      "name": "Rock_Stone_Cobble"
    },
    {
      "x": -3,
      "y": 2,
      "z": 6,
      "name": "Rock_Quartzite"
    },
    {
      "x": -3,
      "y": 3,
      "z": 6,
      "name": "Rock_Quartzite"
    },
    {
      "x": -3,
      "y": 4,
      "z": 6,
      "name": "Rock_Quartzite"
    },
    {
      "x": -3,
      "y": 5,
      "z": 6,
      "name": "Rock_Stone"
    },
    {
      "x": -3,
      "y": 6,
      "z": 6,
      "name": "Rock_Stone"
    },
    {
      "x": -3,
      "y": 7,
      "z": 6,
      "name": "Rock_Quartzite"
    },
    {
      "x": -3,
      "y": 8,
      "z": 6,
      "name": "Rock_Quartzite"
    },
    {
      "x": -3,
      "y": 0,
      "z": 7,
      "name": "Rock_Stone"
    },
    {
      "x": -3,
      "y": 1,
      "z": 7,
      "name": "Rock_Stone"
    },
    {
      "x": -3,
      "y": 2,
      "z": 7,
      "name": "Rock_Stone"
    },
    {
      "x": -3,
      "y": 3,
      "z": 7,
      "name": "Rock_Stone"
    },
    {
      "x": -3,
      "y": 4,
      "z": 7,
      "name": "Rock_Stone"
    },
    {
      "x": -3,
      "y": 5,
      "z": 7,
      "name": "Rock_Stone"
    },
    {
      "x": -3,
      "y": 6,
      "z": 7,
      "name": "Rock_Stone"
    },
    {
      "x": -3,
      "y": 7,
      "z": 7,
      "name": "Rock_Quartzite"
    },
    {
      "x": -3,
      "y": 8,
      "z": 7,
      "name": "Rock_Quartzite"
    },
    {
      "x": -3,
      "y": 0,
      "z": 8,
      "name": "Rock_Stone"
    },
    {
      "x": -3,
      "y": 1,
      "z": 8,
      "name": "Rock_Stone"
    },
    {
      "x": -3,
      "y": 2,
      "z": 8,
      "name": "Rock_Stone"
    },
    {
      "x": -3,
      "y": 3,
      "z": 8,
      "name": "Rock_Stone"
    },
    {
      "x": -3,
      "y": 4,
      "z": 8,
      "name": "Rock_Stone"
    },
    {
      "x": -3,
      "y": 5,
      "z": 8,
      "name": "Rock_Stone"
    },
    {
      "x": -3,
      "y": 6,
      "z": 8,
      "name": "Rock_Stone"
    },
    {
      "x": -3,
      "y": 7,
      "z": 8,
      "name": "Rock_Quartzite"
    },
    {
      "x": -3,
      "y": 8,
      "z": 8,
      "name": "Rock_Quartzite"
    },
    {
      "x": -2,
      "y": 0,
      "z": -8,
      "name": "Rock_Stone"
    },
    {
      "x": -2,
      "y": 1,
      "z": -8,
      "name": "Soil_Gravel"
    },
    {
      "x": -2,
      "y": 2,
      "z": -8,
      "name": "Empty"
    },
    {
      "x": -2,
      "y": 3,
      "z": -8,
      "name": "Empty"
    },
    {
      "x": -2,
      "y": 4,
      "z": -8,
      "name": "Plant_Vine_Wall",
      "rotation": 1
    },
    {
      "x": -2,
      "y": 5,
      "z": -8,
      "name": "Rock_Stone_Brick_Half",
      "rotation": 5
    },
    {
      "x": -2,
      "y": 6,
      "z": -8,
      "name": "Rock_Stone_Brick"
    },
    {
      "x": -2,
      "y": 7,
      "z": -8,
      "name": "Rock_Quartzite"
    },
    {
      "x": -2,
      "y": 8,
      "z": -8,
      "name": "Rock_Quartzite"
    },
    {
      "x": -2,
      "y": 0,
      "z": -7,
      "name": "Rock_Stone"
    },
    {
      "x": -2,
      "y": 1,
      "z": -7,
      "name": "Rock_Stone"
    },
    {
      "x": -2,
      "y": 2,
      "z": -7,
      "name": "Rock_Stone"
    },
    {
      "x": -2,
      "y": 3,
      "z": -7,
      "name": "Rock_Stone"
    },
    {
      "x": -2,
      "y": 4,
      "z": -7,
      "name": "Rock_Stone"
    },
    {
      "x": -2,
      "y": 5,
      "z": -7,
      "name": "Rock_Stone"
    },
    {
      "x": -2,
      "y": 6,
      "z": -7,
      "name": "Rock_Stone"
    },
    {
      "x": -2,
      "y": 7,
      "z": -7,
      "name": "Rock_Quartzite"
    },
    {
      "x": -2,
      "y": 8,
      "z": -7,
      "name": "Rock_Quartzite"
    },
    {
      "x": -2,
      "y": 0,
      "z": -6,
      "name": "Rock_Stone"
    },
    {
      "x": -2,
      "y": 1,
      "z": -6,
      "name": "Rock_Stone"
    },
    {
      "x": -2,
      "y": 2,
      "z": -6,
      "name": "Rock_Stone"
    },
    {
      "x": -2,
      "y": 3,
      "z": -6,
      "name": "Empty"
    },
    {
      "x": -2,
      "y": 4,
      "z": -6,
      "name": "Empty"
    },
    {
      "x": -2,
      "y": 5,
      "z": -6,
      "name": "Rock_Stone"
    },
    {
      "x": -2,
      "y": 6,
      "z": -6,
      "name": "Rock_Stone"
    },
    {
      "x": -2,
      "y": 7,
      "z": -6,
      "name": "Rock_Quartzite"
    },
    {
      "x": -2,
      "y": 8,
      "z": -6,
      "name": "Rock_Quartzite"
    },
    {
      "x": -2,
      "y": 0,
      "z": -5,
      "name": "Rock_Stone"
    },
    {
      "x": -2,
      "y": 1,
      "z": -5,
      "name": "Rock_Stone_Cobble"
    },
    {
      "x": -2,
      "y": 2,
      "z": -5,
      "name": "Empty"
    },
    {
      "x": -2,
      "y": 3,
      "z": -5,
      "name": "Empty"
    },
    {
      "x": -2,
      "y": 4,
      "z": -5,
      "name": "Empty"
    },
    {
      "x": -2,
      "y": 5,
      "z": -5,
      "name": "Empty"
    },
    {
      "x": -2,
      "y": 6,
      "z": -5,
      "name": "Empty"
    },
    {
      "x": -2,
      "y": 7,
      "z": -5,
      "name": "Rock_Quartzite"
    },
    {
      "x": -2,
      "y": 8,
      "z": -5,
      "name": "Rock_Quartzite"
    },
    {
      "x": -2,
      "y": 0,
      "z": -4,
      "name": "Rock_Stone"
    },
    {
      "x": -2,
      "y": 1,
      "z": -4,
      "name": "Rock_Stone_Cobble"
    },
    {
      "x": -2,
      "y": 2,
      "z": -4,
      "name": "Empty"
    },
    {
      "x": -2,
      "y": 3,
      "z": -4,
      "name": "Empty"
    },
    {
      "x": -2,
      "y": 4,
      "z": -4,
      "name": "Empty"
    },
    {
      "x": -2,
      "y": 5,
      "z": -4,
      "name": "Empty"
    },
    {
      "x": -2,
      "y": 6,
      "z": -4,
      "name": "Empty"
    },
    {
      "x": -2,
      "y": 7,
      "z": -4,
      "name": "Rock_Quartzite"
    },
    {
      "x": -2,
      "y": 8,
      "z": -4,
      "name": "Rock_Quartzite"
    },
    {
      "x": -2,
      "y": 0,
      "z": -3,
      "name": "Rock_Stone"
    },
    {
      "x": -2,
      "y": 1,
      "z": -3,
      "name": "Rock_Stone"
    },
    {
      "x": -2,
      "y": 2,
      "z": -3,
      "name": "Rock_Stone"
    },
    {
      "x": -2,
      "y": 3,
      "z": -3,
      "name": "Plant_Moss_Rug_Green"
    },
    {
      "x": -2,
      "y": 4,
      "z": -3,
      "name": "Plant_Vine_Wall",
      "rotation": 1
    },
    {
      "x": -2,
      "y": 5,
      "z": -3,
      "name": "Plant_Vine",
      "rotation": 1
    },
    {
      "x": -2,
      "y": 6,
      "z": -3,
      "name": "Rock_Stone"
    },
    {
      "x": -2,
      "y": 7,
      "z": -3,
      "name": "Rock_Quartzite"
    },
    {
      "x": -2,
      "y": 8,
      "z": -3,
      "name": "Rock_Quartzite"
    },
    {
      "x": -2,
      "y": 0,
      "z": -2,
      "name": "Rock_Stone"
    },
    {
      "x": -2,
      "y": 1,
      "z": -2,
      "name": "Rock_Stone"
    },
    {
      "x": -2,
      "y": 2,
      "z": -2,
      "name": "Rock_Stone"
    },
    {
      "x": -2,
      "y": 3,
      "z": -2,
      "name": "Rock_Stone"
    },
    {
      "x": -2,
      "y": 4,
      "z": -2,
      "name": "Empty"
    },
    {
      "x": -2,
      "y": 5,
      "z": -2,
      "name": "Rock_Stone"
    },
    {
      "x": -2,
      "y": 6,
      "z": -2,
      "name": "Rock_Stone"
    },
    {
      "x": -2,
      "y": 7,
      "z": -2,
      "name": "Rock_Quartzite"
    },
    {
      "x": -2,
      "y": 8,
      "z": -2,
      "name": "Rock_Quartzite"
    },
    {
      "x": -2,
      "y": 0,
      "z": -1,
      "name": "Rock_Stone"
    },
    {
      "x": -2,
      "y": 1,
      "z": -1,
      "name": "Rock_Stone"
    },
    {
      "x": -2,
      "y": 2,
      "z": -1,
      "name": "Rock_Stone"
    },
    {
      "x": -2,
      "y": 3,
      "z": -1,
      "name": "Rock_Stone"
    },
    {
      "x": -2,
      "y": 4,
      "z": -1,
      "name": "Plant_Moss_Rug_Green"
    },
    {
      "x": -2,
      "y": 5,
      "z": -1,
      "name": "Rock_Stone"
    },
    {
      "x": -2,
      "y": 6,
      "z": -1,
      "name": "Rock_Stone"
    },
    {
      "x": -2,
      "y": 7,
      "z": -1,
      "name": "Rock_Quartzite"
    },
    {
      "x": -2,
      "y": 8,
      "z": -1,
      "name": "Rock_Quartzite"
    },
    {
      "x": -2,
      "y": 0,
      "z": 0,
      "name": "Rock_Stone"
    },
    {
      "x": -2,
      "y": 1,
      "z": 0,
      "name": "Rock_Stone"
    },
    {
      "x": -2,
      "y": 2,
      "z": 0,
      "name": "Rock_Stone"
    },
    {
      "x": -2,
      "y": 3,
      "z": 0,
      "name": "Plant_Moss_Rug_Green"
    },
    {
      "x": -2,
      "y": 4,
      "z": 0,
      "name": "Empty"
    },
    {
      "x": -2,
      "y": 5,
      "z": 0,
      "name": "Rock_Stone"
    },
    {
      "x": -2,
      "y": 6,
      "z": 0,
      "name": "Rock_Stone"
    },
    {
      "x": -2,
      "y": 7,
      "z": 0,
      "name": "Rock_Quartzite"
    },
    {
      "x": -2,
      "y": 8,
      "z": 0,
      "name": "Rock_Quartzite"
    },
    {
      "x": -2,
      "y": 0,
      "z": 1,
      "name": "Rock_Stone"
    },
    {
      "x": -2,
      "y": 1,
      "z": 1,
      "name": "Rock_Stone_Cobble"
    },
    {
      "x": -2,
      "y": 2,
      "z": 1,
      "name": "Furniture_Ancient_Barrel"
    },
    {
      "x": -2,
      "y": 3,
      "z": 1,
      "name": "Empty"
    },
    {
      "x": -2,
      "y": 4,
      "z": 1,
      "name": "Empty"
    },
    {
      "x": -2,
      "y": 5,
      "z": 1,
      "name": "Rock_Stone"
    },
    {
      "x": -2,
      "y": 6,
      "z": 1,
      "name": "Rock_Stone"
    },
    {
      "x": -2,
      "y": 7,
      "z": 1,
      "name": "Rock_Quartzite"
    },
    {
      "x": -2,
      "y": 8,
      "z": 1,
      "name": "Rock_Quartzite"
    },
    {
      "x": -2,
      "y": 0,
      "z": 2,
      "name": "Rock_Stone"
    },
    {
      "x": -2,
      "y": 1,
      "z": 2,
      "name": "Rock_Stone_Cobble"
    },
    {
      "x": -2,
      "y": 2,
      "z": 2,
      "name": "Plant_Crop_Mushroom_Cap_Brown",
      "components": {
        "Components": {
          "FarmingBlock": {}
        }
      }
    },
    {
      "x": -2,
      "y": 3,
      "z": 2,
      "name": "Empty"
    },
    {
      "x": -2,
      "y": 4,
      "z": 2,
      "name": "Empty"
    },
    {
      "x": -2,
      "y": 5,
      "z": 2,
      "name": "Rock_Stone"
    },
    {
      "x": -2,
      "y": 6,
      "z": 2,
      "name": "Rock_Stone"
    },
    {
      "x": -2,
      "y": 7,
      "z": 2,
      "name": "Rock_Quartzite"
    },
    {
      "x": -2,
      "y": 8,
      "z": 2,
      "name": "Rock_Quartzite"
    },
    {
      "x": -2,
      "y": 0,
      "z": 3,
      "name": "Rock_Stone"
    },
    {
      "x": -2,
      "y": 1,
      "z": 3,
      "name": "Soil_Pathway"
    },
    {
      "x": -2,
      "y": 2,
      "z": 3,
      "name": "Empty"
    },
    {
      "x": -2,
      "y": 3,
      "z": 3,
      "name": "Empty"
    },
    {
      "x": -2,
      "y": 4,
      "z": 3,
      "name": "Empty"
    },
    {
      "x": -2,
      "y": 5,
      "z": 3,
      "name": "Rock_Stone"
    },
    {
      "x": -2,
      "y": 6,
      "z": 3,
      "name": "Rock_Stone"
    },
    {
      "x": -2,
      "y": 7,
      "z": 3,
      "name": "Rock_Quartzite"
    },
    {
      "x": -2,
      "y": 8,
      "z": 3,
      "name": "Rock_Quartzite"
    },
    {
      "x": -2,
      "y": 0,
      "z": 4,
      "name": "Rock_Stone"
    },
    {
      "x": -2,
      "y": 1,
      "z": 4,
      "name": "Soil_Pathway"
    },
    {
      "x": -2,
      "y": 2,
      "z": 4,
      "name": "Empty"
    },
    {
      "x": -2,
      "y": 3,
      "z": 4,
      "name": "Empty"
    },
    {
      "x": -2,
      "y": 4,
      "z": 4,
      "name": "Rock_Stone_Stalactite_Small",
      "rotation": 8
    },
    {
      "x": -2,
      "y": 5,
      "z": 4,
      "name": "Rock_Stone"
    },
    {
      "x": -2,
      "y": 6,
      "z": 4,
      "name": "Rock_Stone"
    },
    {
      "x": -2,
      "y": 7,
      "z": 4,
      "name": "Rock_Quartzite"
    },
    {
      "x": -2,
      "y": 8,
      "z": 4,
      "name": "Rock_Quartzite"
    },
    {
      "x": -2,
      "y": 0,
      "z": 5,
      "name": "Rock_Stone"
    },
    {
      "x": -2,
      "y": 1,
      "z": 5,
      "name": "Soil_Pathway"
    },
    {
      "x": -2,
      "y": 2,
      "z": 5,
      "name": "Plant_Grass_Rocky_Short"
    },
    {
      "x": -2,
      "y": 3,
      "z": 5,
      "name": "Empty"
    },
    {
      "x": -2,
      "y": 4,
      "z": 5,
      "name": "Plant_Vine",
      "rotation": 1
    },
    {
      "x": -2,
      "y": 5,
      "z": 5,
      "name": "Rock_Stone"
    },
    {
      "x": -2,
      "y": 6,
      "z": 5,
      "name": "Rock_Stone"
    },
    {
      "x": -2,
      "y": 7,
      "z": 5,
      "name": "Rock_Quartzite"
    },
    {
      "x": -2,
      "y": 8,
      "z": 5,
      "name": "Rock_Quartzite"
    },
    {
      "x": -2,
      "y": 0,
      "z": 6,
      "name": "Rock_Stone"
    },
    {
      "x": -2,
      "y": 1,
      "z": 6,
      "name": "Soil_Gravel_Mossy"
    },
    {
      "x": -2,
      "y": 2,
      "z": 6,
      "name": "Empty"
    },
    {
      "x": -2,
      "y": 3,
      "z": 6,
      "name": "Plant_Vine_Wall",
      "rotation": 1
    },
    {
      "x": -2,
      "y": 4,
      "z": 6,
      "name": "Plant_Vine",
      "rotation": 1
    },
    {
      "x": -2,
      "y": 5,
      "z": 6,
      "name": "Rock_Stone"
    },
    {
      "x": -2,
      "y": 6,
      "z": 6,
      "name": "Rock_Stone"
    },
    {
      "x": -2,
      "y": 7,
      "z": 6,
      "name": "Rock_Quartzite"
    },
    {
      "x": -2,
      "y": 8,
      "z": 6,
      "name": "Rock_Quartzite"
    },
    {
      "x": -2,
      "y": 0,
      "z": 7,
      "name": "Rock_Stone"
    },
    {
      "x": -2,
      "y": 1,
      "z": 7,
      "name": "Rock_Stone"
    },
    {
      "x": -2,
      "y": 2,
      "z": 7,
      "name": "Rock_Stone"
    },
    {
      "x": -2,
      "y": 3,
      "z": 7,
      "name": "Rock_Stone"
    },
    {
      "x": -2,
      "y": 4,
      "z": 7,
      "name": "Rock_Stone_Stalactite_Small",
      "rotation": 8
    },
    {
      "x": -2,
      "y": 5,
      "z": 7,
      "name": "Rock_Stone"
    },
    {
      "x": -2,
      "y": 6,
      "z": 7,
      "name": "Rock_Stone"
    },
    {
      "x": -2,
      "y": 7,
      "z": 7,
      "name": "Rock_Quartzite"
    },
    {
      "x": -2,
      "y": 8,
      "z": 7,
      "name": "Rock_Quartzite"
    },
    {
      "x": -2,
      "y": 0,
      "z": 8,
      "name": "Rock_Stone"
    },
    {
      "x": -2,
      "y": 1,
      "z": 8,
      "name": "Rock_Stone"
    },
    {
      "x": -2,
      "y": 2,
      "z": 8,
      "name": "Rock_Stone"
    },
    {
      "x": -2,
      "y": 3,
      "z": 8,
      "name": "Rock_Stone"
    },
    {
      "x": -2,
      "y": 4,
      "z": 8,
      "name": "Rock_Stone"
    },
    {
      "x": -2,
      "y": 5,
      "z": 8,
      "name": "Rock_Stone"
    },
    {
      "x": -2,
      "y": 6,
      "z": 8,
      "name": "Rock_Stone"
    },
    {
      "x": -2,
      "y": 7,
      "z": 8,
      "name": "Rock_Quartzite"
    },
    {
      "x": -2,
      "y": 8,
      "z": 8,
      "name": "Rock_Quartzite"
    },
    {
      "x": -1,
      "y": 0,
      "z": -8,
      "name": "Rock_Stone"
    },
    {
      "x": -1,
      "y": 1,
      "z": -8,
      "name": "Soil_Pathway"
    },
    {
      "x": -1,
      "y": 2,
      "z": -8,
      "name": "Plant_Grass_Rocky_Short"
    },
    {
      "x": -1,
      "y": 3,
      "z": -8,
      "name": "Empty"
    },
    {
      "x": -1,
      "y": 4,
      "z": -8,
      "name": "Empty"
    },
    {
      "x": -1,
      "y": 5,
      "z": -8,
      "name": "Empty"
    },
    {
      "x": -1,
      "y": 6,
      "z": -8,
      "name": "Rock_Stone_Brick_Half",
      "rotation": 8
    },
    {
      "x": -1,
      "y": 7,
      "z": -8,
      "name": "Rock_Quartzite"
    },
    {
      "x": -1,
      "y": 8,
      "z": -8,
      "name": "Rock_Quartzite"
    },
    {
      "x": -1,
      "y": 0,
      "z": -7,
      "name": "Rock_Stone"
    },
    {
      "x": -1,
      "y": 1,
      "z": -7,
      "name": "Soil_Pathway"
    },
    {
      "x": -1,
      "y": 2,
      "z": -7,
      "name": "Empty"
    },
    {
      "x": -1,
      "y": 3,
      "z": -7,
      "name": "Empty"
    },
    {
      "x": -1,
      "y": 4,
      "z": -7,
      "name": "Plant_Vine_Wall",
      "rotation": 1
    },
    {
      "x": -1,
      "y": 5,
      "z": -7,
      "name": "Plant_Vine",
      "rotation": 1
    },
    {
      "x": -1,
      "y": 6,
      "z": -7,
      "name": "Rock_Stone"
    },
    {
      "x": -1,
      "y": 7,
      "z": -7,
      "name": "Rock_Quartzite"
    },
    {
      "x": -1,
      "y": 8,
      "z": -7,
      "name": "Rock_Quartzite"
    },
    {
      "x": -1,
      "y": 0,
      "z": -6,
      "name": "Rock_Stone"
    },
    {
      "x": -1,
      "y": 1,
      "z": -6,
      "name": "Soil_Pathway"
    },
    {
      "x": -1,
      "y": 2,
      "z": -6,
      "name": "Empty"
    },
    {
      "x": -1,
      "y": 3,
      "z": -6,
      "name": "Empty"
    },
    {
      "x": -1,
      "y": 4,
      "z": -6,
      "name": "Empty"
    },
    {
      "x": -1,
      "y": 5,
      "z": -6,
      "name": "Plant_Vine_Wall",
      "rotation": 1
    },
    {
      "x": -1,
      "y": 6,
      "z": -6,
      "name": "Plant_Vine",
      "rotation": 1
    },
    {
      "x": -1,
      "y": 7,
      "z": -6,
      "name": "Rock_Quartzite"
    },
    {
      "x": -1,
      "y": 8,
      "z": -6,
      "name": "Rock_Quartzite"
    },
    {
      "x": -1,
      "y": 0,
      "z": -5,
      "name": "Rock_Stone"
    },
    {
      "x": -1,
      "y": 1,
      "z": -5,
      "name": "Rock_Stone_Cobble"
    },
    {
      "x": -1,
      "y": 2,
      "z": -5,
      "name": "Empty"
    },
    {
      "x": -1,
      "y": 3,
      "z": -5,
      "name": "Empty"
    },
    {
      "x": -1,
      "y": 4,
      "z": -5,
      "name": "Empty"
    },
    {
      "x": -1,
      "y": 5,
      "z": -5,
      "name": "Empty"
    },
    {
      "x": -1,
      "y": 6,
      "z": -5,
      "name": "Empty"
    },
    {
      "x": -1,
      "y": 7,
      "z": -5,
      "name": "Rock_Quartzite"
    },
    {
      "x": -1,
      "y": 8,
      "z": -5,
      "name": "Rock_Quartzite"
    },
    {
      "x": -1,
      "y": 0,
      "z": -4,
      "name": "Rock_Stone"
    },
    {
      "x": -1,
      "y": 1,
      "z": -4,
      "name": "Soil_Pathway"
    },
    {
      "x": -1,
      "y": 2,
      "z": -4,
      "name": "Empty"
    },
    {
      "x": -1,
      "y": 3,
      "z": -4,
      "name": "Empty"
    },
    {
      "x": -1,
      "y": 4,
      "z": -4,
      "name": "Empty"
    },
    {
      "x": -1,
      "y": 5,
      "z": -4,
      "name": "Empty"
    },
    {
      "x": -1,
      "y": 6,
      "z": -4,
      "name": "Wood_Gnarled_Roots"
    },
    {
      "x": -1,
      "y": 7,
      "z": -4,
      "name": "Rock_Quartzite"
    },
    {
      "x": -1,
      "y": 8,
      "z": -4,
      "name": "Rock_Quartzite"
    },
    {
      "x": -1,
      "y": 0,
      "z": -3,
      "name": "Rock_Stone"
    },
    {
      "x": -1,
      "y": 1,
      "z": -3,
      "name": "Soil_Pathway"
    },
    {
      "x": -1,
      "y": 2,
      "z": -3,
      "name": "Empty"
    },
    {
      "x": -1,
      "y": 3,
      "z": -3,
      "name": "Empty"
    },
    {
      "x": -1,
      "y": 4,
      "z": -3,
      "name": "Empty"
    },
    {
      "x": -1,
      "y": 5,
      "z": -3,
      "name": "Empty"
    },
    {
      "x": -1,
      "y": 6,
      "z": -3,
      "name": "Empty"
    },
    {
      "x": -1,
      "y": 7,
      "z": -3,
      "name": "Rock_Quartzite"
    },
    {
      "x": -1,
      "y": 8,
      "z": -3,
      "name": "Rock_Quartzite"
    },
    {
      "x": -1,
      "y": 0,
      "z": -2,
      "name": "Rock_Stone"
    },
    {
      "x": -1,
      "y": 1,
      "z": -2,
      "name": "Soil_Pathway"
    },
    {
      "x": -1,
      "y": 2,
      "z": -2,
      "name": "Plant_Grass_Gnarled_Short"
    },
    {
      "x": -1,
      "y": 3,
      "z": -2,
      "name": "Plant_Vine",
      "rotation": 1
    },
    {
      "x": -1,
      "y": 4,
      "z": -2,
      "name": "Empty"
    },
    {
      "x": -1,
      "y": 5,
      "z": -2,
      "name": "Empty"
    },
    {
      "x": -1,
      "y": 6,
      "z": -2,
      "name": "Empty"
    },
    {
      "x": -1,
      "y": 7,
      "z": -2,
      "name": "Rock_Quartzite"
    },
    {
      "x": -1,
      "y": 8,
      "z": -2,
      "name": "Rock_Quartzite"
    },
    {
      "x": -1,
      "y": 0,
      "z": -1,
      "name": "Rock_Stone"
    },
    {
      "x": -1,
      "y": 1,
      "z": -1,
      "name": "Soil_Pathway"
    },
    {
      "x": -1,
      "y": 2,
      "z": -1,
      "name": "Plant_Vine_Wall",
      "rotation": 1
    },
    {
      "x": -1,
      "y": 3,
      "z": -1,
      "name": "Plant_Vine",
      "rotation": 1
    },
    {
      "x": -1,
      "y": 4,
      "z": -1,
      "name": "Empty"
    },
    {
      "x": -1,
      "y": 5,
      "z": -1,
      "name": "Rock_Stone_Brick_Half",
      "rotation": 8
    },
    {
      "x": -1,
      "y": 6,
      "z": -1,
      "name": "Rock_Stone_Brick"
    },
    {
      "x": -1,
      "y": 7,
      "z": -1,
      "name": "Rock_Quartzite"
    },
    {
      "x": -1,
      "y": 8,
      "z": -1,
      "name": "Rock_Quartzite"
    },
    {
      "x": -1,
      "y": 0,
      "z": 0,
      "name": "Rock_Stone"
    },
    {
      "x": -1,
      "y": 1,
      "z": 0,
      "name": "Soil_Pathway"
    },
    {
      "x": -1,
      "y": 2,
      "z": 0,
      "name": "Empty"
    },
    {
      "x": -1,
      "y": 3,
      "z": 0,
      "name": "Empty"
    },
    {
      "x": -1,
      "y": 4,
      "z": 0,
      "name": "Empty"
    },
    {
      "x": -1,
      "y": 5,
      "z": 0,
      "name": "Empty"
    },
    {
      "x": -1,
      "y": 6,
      "z": 0,
      "name": "Empty"
    },
    {
      "x": -1,
      "y": 7,
      "z": 0,
      "name": "Rock_Quartzite_Cobble"
    },
    {
      "x": -1,
      "y": 8,
      "z": 0,
      "name": "Rock_Quartzite"
    },
    {
      "x": -1,
      "y": 0,
      "z": 1,
      "name": "Rock_Stone"
    },
    {
      "x": -1,
      "y": 1,
      "z": 1,
      "name": "Soil_Pathway"
    },
    {
      "x": -1,
      "y": 2,
      "z": 1,
      "name": "Rubble_Stone"
    },
    {
      "x": -1,
      "y": 3,
      "z": 1,
      "name": "Empty"
    },
    {
      "x": -1,
      "y": 4,
      "z": 1,
      "name": "Empty"
    },
    {
      "x": -1,
      "y": 5,
      "z": 1,
      "name": "Empty"
    },
    {
      "x": -1,
      "y": 6,
      "z": 1,
      "name": "Empty"
    },
    {
      "x": -1,
      "y": 7,
      "z": 1,
      "name": "Rock_Quartzite_Cobble"
    },
    {
      "x": -1,
      "y": 8,
      "z": 1,
      "name": "Rock_Quartzite"
    },
    {
      "x": -1,
      "y": 0,
      "z": 2,
      "name": "Rock_Stone"
    },
    {
      "x": -1,
      "y": 1,
      "z": 2,
      "name": "Soil_Pathway"
    },
    {
      "x": -1,
      "y": 2,
      "z": 2,
      "name": "Empty"
    },
    {
      "x": -1,
      "y": 3,
      "z": 2,
      "name": "Empty"
    },
    {
      "x": -1,
      "y": 4,
      "z": 2,
      "name": "Empty"
    },
    {
      "x": -1,
      "y": 5,
      "z": 2,
      "name": "Empty"
    },
    {
      "x": -1,
      "y": 6,
      "z": 2,
      "name": "Wood_Dry_Roots"
    },
    {
      "x": -1,
      "y": 7,
      "z": 2,
      "name": "Rock_Quartzite"
    },
    {
      "x": -1,
      "y": 8,
      "z": 2,
      "name": "Rock_Quartzite"
    },
    {
      "x": -1,
      "y": 0,
      "z": 3,
      "name": "Rock_Stone"
    },
    {
      "x": -1,
      "y": 1,
      "z": 3,
      "name": "Soil_Pathway"
    },
    {
      "x": -1,
      "y": 2,
      "z": 3,
      "name": "Empty"
    },
    {
      "x": -1,
      "y": 3,
      "z": 3,
      "name": "Empty"
    },
    {
      "x": -1,
      "y": 4,
      "z": 3,
      "name": "Empty"
    },
    {
      "x": -1,
      "y": 5,
      "z": 3,
      "name": "Plant_Vine_Wall",
      "rotation": 1
    },
    {
      "x": -1,
      "y": 6,
      "z": 3,
      "name": "Rock_Stone"
    },
    {
      "x": -1,
      "y": 7,
      "z": 3,
      "name": "Rock_Quartzite"
    },
    {
      "x": -1,
      "y": 8,
      "z": 3,
      "name": "Rock_Quartzite"
    },
    {
      "x": -1,
      "y": 0,
      "z": 4,
      "name": "Rock_Stone"
    },
    {
      "x": -1,
      "y": 1,
      "z": 4,
      "name": "Soil_Pathway"
    },
    {
      "x": -1,
      "y": 2,
      "z": 4,
      "name": "Empty"
    },
    {
      "x": -1,
      "y": 3,
      "z": 4,
      "name": "Empty"
    },
    {
      "x": -1,
      "y": 4,
      "z": 4,
      "name": "Empty"
    },
    {
      "x": -1,
      "y": 5,
      "z": 4,
      "name": "Empty"
    },
    {
      "x": -1,
      "y": 6,
      "z": 4,
      "name": "Rock_Stone"
    },
    {
      "x": -1,
      "y": 7,
      "z": 4,
      "name": "Rock_Quartzite"
    },
    {
      "x": -1,
      "y": 8,
      "z": 4,
      "name": "Rock_Quartzite"
    },
    {
      "x": -1,
      "y": 0,
      "z": 5,
      "name": "Rock_Stone"
    },
    {
      "x": -1,
      "y": 1,
      "z": 5,
      "name": "Soil_Pathway"
    },
    {
      "x": -1,
      "y": 2,
      "z": 5,
      "name": "Empty"
    },
    {
      "x": -1,
      "y": 3,
      "z": 5,
      "name": "Empty"
    },
    {
      "x": -1,
      "y": 4,
      "z": 5,
      "name": "Empty"
    },
    {
      "x": -1,
      "y": 5,
      "z": 5,
      "name": "Rock_Stone"
    },
    {
      "x": -1,
      "y": 6,
      "z": 5,
      "name": "Rock_Stone"
    },
    {
      "x": -1,
      "y": 7,
      "z": 5,
      "name": "Rock_Quartzite"
    },
    {
      "x": -1,
      "y": 8,
      "z": 5,
      "name": "Rock_Quartzite"
    },
    {
      "x": -1,
      "y": 0,
      "z": 6,
      "name": "Rock_Stone"
    },
    {
      "x": -1,
      "y": 1,
      "z": 6,
      "name": "Soil_Pathway"
    },
    {
      "x": -1,
      "y": 2,
      "z": 6,
      "name": "Empty"
    },
    {
      "x": -1,
      "y": 3,
      "z": 6,
      "name": "Empty"
    },
    {
      "x": -1,
      "y": 4,
      "z": 6,
      "name": "Empty"
    },
    {
      "x": -1,
      "y": 5,
      "z": 6,
      "name": "Rock_Stone"
    },
    {
      "x": -1,
      "y": 6,
      "z": 6,
      "name": "Rock_Stone"
    },
    {
      "x": -1,
      "y": 7,
      "z": 6,
      "name": "Rock_Quartzite"
    },
    {
      "x": -1,
      "y": 8,
      "z": 6,
      "name": "Rock_Quartzite"
    },
    {
      "x": -1,
      "y": 0,
      "z": 7,
      "name": "Rock_Stone"
    },
    {
      "x": -1,
      "y": 1,
      "z": 7,
      "name": "Soil_Pathway"
    },
    {
      "x": -1,
      "y": 2,
      "z": 7,
      "name": "Empty"
    },
    {
      "x": -1,
      "y": 3,
      "z": 7,
      "name": "Empty"
    },
    {
      "x": -1,
      "y": 4,
      "z": 7,
      "name": "Empty"
    },
    {
      "x": -1,
      "y": 5,
      "z": 7,
      "name": "Rock_Stone"
    },
    {
      "x": -1,
      "y": 6,
      "z": 7,
      "name": "Rock_Stone"
    },
    {
      "x": -1,
      "y": 7,
      "z": 7,
      "name": "Rock_Quartzite"
    },
    {
      "x": -1,
      "y": 8,
      "z": 7,
      "name": "Rock_Quartzite"
    },
    {
      "x": -1,
      "y": 0,
      "z": 8,
      "name": "Rock_Stone"
    },
    {
      "x": -1,
      "y": 1,
      "z": 8,
      "name": "Soil_Gravel"
    },
    {
      "x": -1,
      "y": 2,
      "z": 8,
      "name": "Empty"
    },
    {
      "x": -1,
      "y": 3,
      "z": 8,
      "name": "Empty"
    },
    {
      "x": -1,
      "y": 4,
      "z": 8,
      "name": "Empty"
    },
    {
      "x": -1,
      "y": 5,
      "z": 8,
      "name": "Empty"
    },
    {
      "x": -1,
      "y": 6,
      "z": 8,
      "name": "Rock_Stone"
    },
    {
      "x": -1,
      "y": 7,
      "z": 8,
      "name": "Rock_Quartzite"
    },
    {
      "x": -1,
      "y": 8,
      "z": 8,
      "name": "Rock_Quartzite"
    },
    {
      "x": 0,
      "y": 0,
      "z": -8,
      "name": "Rock_Stone"
    },
    {
      "x": 0,
      "y": 1,
      "z": -8,
      "name": "Soil_Pathway"
    },
    {
      "x": 0,
      "y": 2,
      "z": -8,
      "name": "Empty"
    },
    {
      "x": 0,
      "y": 3,
      "z": -8,
      "name": "Empty"
    },
    {
      "x": 0,
      "y": 4,
      "z": -8,
      "name": "Empty"
    },
    {
      "x": 0,
      "y": 5,
      "z": -8,
      "name": "Empty"
    },
    {
      "x": 0,
      "y": 6,
      "z": -8,
      "name": "Empty"
    },
    {
      "x": 0,
      "y": 7,
      "z": -8,
      "name": "Rock_Quartzite_Cobble"
    },
    {
      "x": 0,
      "y": 8,
      "z": -8,
      "name": "Rock_Quartzite"
    },
    {
      "x": 0,
      "y": 0,
      "z": -7,
      "name": "Rock_Stone"
    },
    {
      "x": 0,
      "y": 1,
      "z": -7,
      "name": "Soil_Pathway"
    },
    {
      "x": 0,
      "y": 2,
      "z": -7,
      "name": "Empty"
    },
    {
      "x": 0,
      "y": 3,
      "z": -7,
      "name": "Empty"
    },
    {
      "x": 0,
      "y": 4,
      "z": -7,
      "name": "Empty"
    },
    {
      "x": 0,
      "y": 5,
      "z": -7,
      "name": "Empty"
    },
    {
      "x": 0,
      "y": 6,
      "z": -7,
      "name": "Empty"
    },
    {
      "x": 0,
      "y": 7,
      "z": -7,
      "name": "Rock_Quartzite_Cobble"
    },
    {
      "x": 0,
      "y": 8,
      "z": -7,
      "name": "Rock_Quartzite"
    },
    {
      "x": 0,
      "y": 0,
      "z": -6,
      "name": "Rock_Stone"
    },
    {
      "x": 0,
      "y": 1,
      "z": -6,
      "name": "Soil_Pathway"
    },
    {
      "x": 0,
      "y": 2,
      "z": -6,
      "name": "Empty"
    },
    {
      "x": 0,
      "y": 3,
      "z": -6,
      "name": "Empty"
    },
    {
      "x": 0,
      "y": 4,
      "z": -6,
      "name": "Empty"
    },
    {
      "x": 0,
      "y": 5,
      "z": -6,
      "name": "Empty"
    },
    {
      "x": 0,
      "y": 6,
      "z": -6,
      "name": "Empty"
    },
    {
      "x": 0,
      "y": 7,
      "z": -6,
      "name": "Rock_Quartzite"
    },
    {
      "x": 0,
      "y": 8,
      "z": -6,
      "name": "Rock_Quartzite"
    },
    {
      "x": 0,
      "y": 0,
      "z": -5,
      "name": "Rock_Stone"
    },
    {
      "x": 0,
      "y": 1,
      "z": -5,
      "name": "Soil_Pathway"
    },
    {
      "x": 0,
      "y": 2,
      "z": -5,
      "name": "Empty"
    },
    {
      "x": 0,
      "y": 3,
      "z": -5,
      "name": "Empty"
    },
    {
      "x": 0,
      "y": 4,
      "z": -5,
      "name": "Empty"
    },
    {
      "x": 0,
      "y": 5,
      "z": -5,
      "name": "Empty"
    },
    {
      "x": 0,
      "y": 6,
      "z": -5,
      "name": "Empty"
    },
    {
      "x": 0,
      "y": 7,
      "z": -5,
      "name": "Rock_Quartzite_Cobble"
    },
    {
      "x": 0,
      "y": 8,
      "z": -5,
      "name": "Rock_Quartzite"
    },
    {
      "x": 0,
      "y": 0,
      "z": -4,
      "name": "Rock_Stone"
    },
    {
      "x": 0,
      "y": 1,
      "z": -4,
      "name": "Soil_Pathway"
    },
    {
      "x": 0,
      "y": 2,
      "z": -4,
      "name": "Empty"
    },
    {
      "x": 0,
      "y": 3,
      "z": -4,
      "name": "Empty"
    },
    {
      "x": 0,
      "y": 4,
      "z": -4,
      "name": "Empty"
    },
    {
      "x": 0,
      "y": 5,
      "z": -4,
      "name": "Empty"
    },
    {
      "x": 0,
      "y": 6,
      "z": -4,
      "name": "Empty"
    },
    {
      "x": 0,
      "y": 7,
      "z": -4,
      "name": "Rock_Quartzite"
    },
    {
      "x": 0,
      "y": 8,
      "z": -4,
      "name": "Rock_Quartzite"
    },
    {
      "x": 0,
      "y": 0,
      "z": -3,
      "name": "Rock_Stone"
    },
    {
      "x": 0,
      "y": 1,
      "z": -3,
      "name": "Soil_Pathway"
    },
    {
      "x": 0,
      "y": 2,
      "z": -3,
      "name": "Empty"
    },
    {
      "x": 0,
      "y": 3,
      "z": -3,
      "name": "Empty"
    },
    {
      "x": 0,
      "y": 4,
      "z": -3,
      "name": "Empty"
    },
    {
      "x": 0,
      "y": 5,
      "z": -3,
      "name": "Empty"
    },
    {
      "x": 0,
      "y": 6,
      "z": -3,
      "name": "Empty"
    },
    {
      "x": 0,
      "y": 7,
      "z": -3,
      "name": "Rock_Quartzite"
    },
    {
      "x": 0,
      "y": 8,
      "z": -3,
      "name": "Rock_Quartzite"
    },
    {
      "x": 0,
      "y": 0,
      "z": -2,
      "name": "Rock_Stone"
    },
    {
      "x": 0,
      "y": 1,
      "z": -2,
      "name": "Soil_Pathway"
    },
    {
      "x": 0,
      "y": 2,
      "z": -2,
      "name": "Empty"
    },
    {
      "x": 0,
      "y": 3,
      "z": -2,
      "name": "Empty"
    },
    {
      "x": 0,
      "y": 4,
      "z": -2,
      "name": "Empty"
    },
    {
      "x": 0,
      "y": 5,
      "z": -2,
      "name": "Empty"
    },
    {
      "x": 0,
      "y": 6,
      "z": -2,
      "name": "Empty"
    },
    {
      "x": 0,
      "y": 7,
      "z": -2,
      "name": "Rock_Quartzite"
    },
    {
      "x": 0,
      "y": 8,
      "z": -2,
      "name": "Rock_Quartzite"
    },
    {
      "x": 0,
      "y": 0,
      "z": -1,
      "name": "Rock_Stone"
    },
    {
      "x": 0,
      "y": 1,
      "z": -1,
      "name": "Soil_Pathway"
    },
    {
      "x": 0,
      "y": 2,
      "z": -1,
      "name": "Empty"
    },
    {
      "x": 0,
      "y": 3,
      "z": -1,
      "name": "Empty"
    },
    {
      "x": 0,
      "y": 4,
      "z": -1,
      "name": "Empty"
    },
    {
      "x": 0,
      "y": 5,
      "z": -1,
      "name": "Empty"
    },
    {
      "x": 0,
      "y": 6,
      "z": -1,
      "name": "Rock_Stone_Brick"
    },
    {
      "x": 0,
      "y": 7,
      "z": -1,
      "name": "Rock_Quartzite"
    },
    {
      "x": 0,
      "y": 8,
      "z": -1,
      "name": "Rock_Quartzite"
    },
    {
      "x": 0,
      "y": 0,
      "z": 0,
      "name": "Rock_Stone"
    },
    {
      "x": 0,
      "y": 1,
      "z": 0,
      "name": "Soil_Pathway"
    },
    {
      "x": 0,
      "y": 2,
      "z": 0,
      "name": "Empty"
    },
    {
      "x": 0,
      "y": 3,
      "z": 0,
      "name": "Empty"
    },
    {
      "x": 0,
      "y": 4,
      "z": 0,
      "name": "Empty"
    },
    {
      "x": 0,
      "y": 5,
      "z": 0,
      "name": "Empty"
    },
    {
      "x": 0,
      "y": 6,
      "z": 0,
      "name": "Empty"
    },
    {
      "x": 0,
      "y": 7,
      "z": 0,
      "name": "Rock_Quartzite"
    },
    {
      "x": 0,
      "y": 8,
      "z": 0,
      "name": "Rock_Quartzite"
    },
    {
      "x": 0,
      "y": 0,
      "z": 1,
      "name": "Rock_Stone"
    },
    {
      "x": 0,
      "y": 1,
      "z": 1,
      "name": "Soil_Pathway"
    },
    {
      "x": 0,
      "y": 2,
      "z": 1,
      "name": "Empty"
    },
    {
      "x": 0,
      "y": 3,
      "z": 1,
      "name": "Empty"
    },
    {
      "x": 0,
      "y": 4,
      "z": 1,
      "name": "Empty"
    },
    {
      "x": 0,
      "y": 5,
      "z": 1,
      "name": "Empty"
    },
    {
      "x": 0,
      "y": 6,
      "z": 1,
      "name": "Empty"
    },
    {
      "x": 0,
      "y": 7,
      "z": 1,
      "name": "Rock_Quartzite"
    },
    {
      "x": 0,
      "y": 8,
      "z": 1,
      "name": "Rock_Quartzite"
    },
    {
      "x": 0,
      "y": 0,
      "z": 2,
      "name": "Rock_Stone"
    },
    {
      "x": 0,
      "y": 1,
      "z": 2,
      "name": "Soil_Pathway"
    },
    {
      "x": 0,
      "y": 2,
      "z": 2,
      "name": "Empty"
    },
    {
      "x": 0,
      "y": 3,
      "z": 2,
      "name": "Empty"
    },
    {
      "x": 0,
      "y": 4,
      "z": 2,
      "name": "Empty"
    },
    {
      "x": 0,
      "y": 5,
      "z": 2,
      "name": "Empty"
    },
    {
      "x": 0,
      "y": 6,
      "z": 2,
      "name": "Empty"
    },
    {
      "x": 0,
      "y": 7,
      "z": 2,
      "name": "Rock_Quartzite"
    },
    {
      "x": 0,
      "y": 8,
      "z": 2,
      "name": "Rock_Quartzite"
    },
    {
      "x": 0,
      "y": 0,
      "z": 3,
      "name": "Rock_Stone"
    },
    {
      "x": 0,
      "y": 1,
      "z": 3,
      "name": "Soil_Pathway"
    },
    {
      "x": 0,
      "y": 2,
      "z": 3,
      "name": "Empty"
    },
    {
      "x": 0,
      "y": 3,
      "z": 3,
      "name": "Empty"
    },
    {
      "x": 0,
      "y": 4,
      "z": 3,
      "name": "Empty"
    },
    {
      "x": 0,
      "y": 5,
      "z": 3,
      "name": "Empty"
    },
    {
      "x": 0,
      "y": 6,
      "z": 3,
      "name": "Empty"
    },
    {
      "x": 0,
      "y": 7,
      "z": 3,
      "name": "Rock_Quartzite"
    },
    {
      "x": 0,
      "y": 8,
      "z": 3,
      "name": "Rock_Quartzite"
    },
    {
      "x": 0,
      "y": 0,
      "z": 4,
      "name": "Rock_Stone"
    },
    {
      "x": 0,
      "y": 1,
      "z": 4,
      "name": "Soil_Pathway"
    },
    {
      "x": 0,
      "y": 2,
      "z": 4,
      "name": "Empty"
    },
    {
      "x": 0,
      "y": 3,
      "z": 4,
      "name": "Empty"
    },
    {
      "x": 0,
      "y": 4,
      "z": 4,
      "name": "Empty"
    },
    {
      "x": 0,
      "y": 5,
      "z": 4,
      "name": "Empty"
    },
    {
      "x": 0,
      "y": 6,
      "z": 4,
      "name": "Empty"
    },
    {
      "x": 0,
      "y": 7,
      "z": 4,
      "name": "Rock_Quartzite_Cobble"
    },
    {
      "x": 0,
      "y": 8,
      "z": 4,
      "name": "Rock_Quartzite"
    },
    {
      "x": 0,
      "y": 0,
      "z": 5,
      "name": "Rock_Stone"
    },
    {
      "x": 0,
      "y": 1,
      "z": 5,
      "name": "Soil_Pathway"
    },
    {
      "x": 0,
      "y": 2,
      "z": 5,
      "name": "Empty"
    },
    {
      "x": 0,
      "y": 3,
      "z": 5,
      "name": "Empty"
    },
    {
      "x": 0,
      "y": 4,
      "z": 5,
      "name": "Empty"
    },
    {
      "x": 0,
      "y": 5,
      "z": 5,
      "name": "Empty"
    },
    {
      "x": 0,
      "y": 6,
      "z": 5,
      "name": "Empty"
    },
    {
      "x": 0,
      "y": 7,
      "z": 5,
      "name": "Rock_Quartzite_Cobble"
    },
    {
      "x": 0,
      "y": 8,
      "z": 5,
      "name": "Rock_Quartzite"
    },
    {
      "x": 0,
      "y": 0,
      "z": 6,
      "name": "Rock_Stone"
    },
    {
      "x": 0,
      "y": 1,
      "z": 6,
      "name": "Soil_Pathway"
    },
    {
      "x": 0,
      "y": 2,
      "z": 6,
      "name": "Empty"
    },
    {
      "x": 0,
      "y": 3,
      "z": 6,
      "name": "Empty"
    },
    {
      "x": 0,
      "y": 4,
      "z": 6,
      "name": "Empty"
    },
    {
      "x": 0,
      "y": 5,
      "z": 6,
      "name": "Wood_Gnarled_Roots"
    },
    {
      "x": 0,
      "y": 6,
      "z": 6,
      "name": "Rock_Stone"
    },
    {
      "x": 0,
      "y": 7,
      "z": 6,
      "name": "Rock_Quartzite"
    },
    {
      "x": 0,
      "y": 8,
      "z": 6,
      "name": "Rock_Quartzite"
    },
    {
      "x": 0,
      "y": 0,
      "z": 7,
      "name": "Rock_Stone"
    },
    {
      "x": 0,
      "y": 1,
      "z": 7,
      "name": "Soil_Pathway"
    },
    {
      "x": 0,
      "y": 2,
      "z": 7,
      "name": "Empty"
    },
    {
      "x": 0,
      "y": 3,
      "z": 7,
      "name": "Empty"
    },
    {
      "x": 0,
      "y": 4,
      "z": 7,
      "name": "Empty"
    },
    {
      "x": 0,
      "y": 5,
      "z": 7,
      "name": "Rock_Stone"
    },
    {
      "x": 0,
      "y": 6,
      "z": 7,
      "name": "Rock_Stone"
    },
    {
      "x": 0,
      "y": 7,
      "z": 7,
      "name": "Rock_Quartzite"
    },
    {
      "x": 0,
      "y": 8,
      "z": 7,
      "name": "Rock_Quartzite"
    },
    {
      "x": 0,
      "y": 0,
      "z": 8,
      "name": "Rock_Stone"
    },
    {
      "x": 0,
      "y": 1,
      "z": 8,
      "name": "Soil_Pathway"
    },
    {
      "x": 0,
      "y": 2,
      "z": 8,
      "name": "Empty"
    },
    {
      "x": 0,
      "y": 3,
      "z": 8,
      "name": "Empty"
    },
    {
      "x": 0,
      "y": 4,
      "z": 8,
      "name": "Empty"
    },
    {
      "x": 0,
      "y": 5,
      "z": 8,
      "name": "Empty"
    },
    {
      "x": 0,
      "y": 6,
      "z": 8,
      "name": "Empty"
    },
    {
      "x": 0,
      "y": 7,
      "z": 8,
      "name": "Rock_Quartzite"
    },
    {
      "x": 0,
      "y": 8,
      "z": 8,
      "name": "Rock_Quartzite"
    },
    {
      "x": 1,
      "y": 0,
      "z": -8,
      "name": "Rock_Stone"
    },
    {
      "x": 1,
      "y": 1,
      "z": -8,
      "name": "Soil_Pathway"
    },
    {
      "x": 1,
      "y": 2,
      "z": -8,
      "name": "Empty"
    },
    {
      "x": 1,
      "y": 3,
      "z": -8,
      "name": "Empty"
    },
    {
      "x": 1,
      "y": 4,
      "z": -8,
      "name": "Empty"
    },
    {
      "x": 1,
      "y": 5,
      "z": -8,
      "name": "Empty"
    },
    {
      "x": 1,
      "y": 6,
      "z": -8,
      "name": "Rock_Stone_Brick_Half",
      "rotation": 8
    },
    {
      "x": 1,
      "y": 7,
      "z": -8,
      "name": "Rock_Quartzite"
    },
    {
      "x": 1,
      "y": 8,
      "z": -8,
      "name": "Rock_Quartzite"
    },
    {
      "x": 1,
      "y": 0,
      "z": -7,
      "name": "Rock_Stone"
    },
    {
      "x": 1,
      "y": 1,
      "z": -7,
      "name": "Soil_Pathway"
    },
    {
      "x": 1,
      "y": 2,
      "z": -7,
      "name": "Empty"
    },
    {
      "x": 1,
      "y": 3,
      "z": -7,
      "name": "Empty"
    },
    {
      "x": 1,
      "y": 4,
      "z": -7,
      "name": "Empty"
    },
    {
      "x": 1,
      "y": 5,
      "z": -7,
      "name": "Empty"
    },
    {
      "x": 1,
      "y": 6,
      "z": -7,
      "name": "Empty"
    },
    {
      "x": 1,
      "y": 7,
      "z": -7,
      "name": "Rock_Quartzite_Cobble"
    },
    {
      "x": 1,
      "y": 8,
      "z": -7,
      "name": "Rock_Quartzite"
    },
    {
      "x": 1,
      "y": 0,
      "z": -6,
      "name": "Rock_Stone"
    },
    {
      "x": 1,
      "y": 1,
      "z": -6,
      "name": "Soil_Gravel"
    },
    {
      "x": 1,
      "y": 2,
      "z": -6,
      "name": "Rubble_Stone"
    },
    {
      "x": 1,
      "y": 3,
      "z": -6,
      "name": "Empty"
    },
    {
      "x": 1,
      "y": 4,
      "z": -6,
      "name": "Empty"
    },
    {
      "x": 1,
      "y": 5,
      "z": -6,
      "name": "Empty"
    },
    {
      "x": 1,
      "y": 6,
      "z": -6,
      "name": "Empty"
    },
    {
      "x": 1,
      "y": 7,
      "z": -6,
      "name": "Rock_Quartzite"
    },
    {
      "x": 1,
      "y": 8,
      "z": -6,
      "name": "Rock_Quartzite"
    },
    {
      "x": 1,
      "y": 0,
      "z": -5,
      "name": "Rock_Stone"
    },
    {
      "x": 1,
      "y": 1,
      "z": -5,
      "name": "Soil_Pathway"
    },
    {
      "x": 1,
      "y": 2,
      "z": -5,
      "name": "Empty"
    },
    {
      "x": 1,
      "y": 3,
      "z": -5,
      "name": "Empty"
    },
    {
      "x": 1,
      "y": 4,
      "z": -5,
      "name": "Empty"
    },
    {
      "x": 1,
      "y": 5,
      "z": -5,
      "name": "Empty"
    },
    {
      "x": 1,
      "y": 6,
      "z": -5,
      "name": "Empty"
    },
    {
      "x": 1,
      "y": 7,
      "z": -5,
      "name": "Rock_Quartzite_Cobble"
    },
    {
      "x": 1,
      "y": 8,
      "z": -5,
      "name": "Rock_Quartzite"
    },
    {
      "x": 1,
      "y": 0,
      "z": -4,
      "name": "Rock_Stone"
    },
    {
      "x": 1,
      "y": 1,
      "z": -4,
      "name": "Soil_Pathway"
    },
    {
      "x": 1,
      "y": 2,
      "z": -4,
      "name": "Empty"
    },
    {
      "x": 1,
      "y": 3,
      "z": -4,
      "name": "Empty"
    },
    {
      "x": 1,
      "y": 4,
      "z": -4,
      "name": "Empty"
    },
    {
      "x": 1,
      "y": 5,
      "z": -4,
      "name": "Empty"
    },
    {
      "x": 1,
      "y": 6,
      "z": -4,
      "name": "Empty"
    },
    {
      "x": 1,
      "y": 7,
      "z": -4,
      "name": "Rock_Quartzite"
    },
    {
      "x": 1,
      "y": 8,
      "z": -4,
      "name": "Rock_Quartzite"
    },
    {
      "x": 1,
      "y": 0,
      "z": -3,
      "name": "Rock_Stone"
    },
    {
      "x": 1,
      "y": 1,
      "z": -3,
      "name": "Soil_Pathway"
    },
    {
      "x": 1,
      "y": 2,
      "z": -3,
      "name": "Empty"
    },
    {
      "x": 1,
      "y": 3,
      "z": -3,
      "name": "Plant_Vine_Wall",
      "rotation": 3
    },
    {
      "x": 1,
      "y": 4,
      "z": -3,
      "name": "Empty"
    },
    {
      "x": 1,
      "y": 5,
      "z": -3,
      "name": "Empty"
    },
    {
      "x": 1,
      "y": 6,
      "z": -3,
      "name": "Plant_Vine_Wall",
      "rotation": 3
    },
    {
      "x": 1,
      "y": 7,
      "z": -3,
      "name": "Rock_Quartzite"
    },
    {
      "x": 1,
      "y": 8,
      "z": -3,
      "name": "Rock_Quartzite"
    },
    {
      "x": 1,
      "y": 0,
      "z": -2,
      "name": "Rock_Stone"
    },
    {
      "x": 1,
      "y": 1,
      "z": -2,
      "name": "Soil_Pathway"
    },
    {
      "x": 1,
      "y": 2,
      "z": -2,
      "name": "Empty"
    },
    {
      "x": 1,
      "y": 3,
      "z": -2,
      "name": "Empty"
    },
    {
      "x": 1,
      "y": 4,
      "z": -2,
      "name": "Plant_Vine_Wall",
      "rotation": 3
    },
    {
      "x": 1,
      "y": 5,
      "z": -2,
      "name": "Plant_Vine",
      "rotation": 3
    },
    {
      "x": 1,
      "y": 6,
      "z": -2,
      "name": "Plant_Vine",
      "rotation": 3
    },
    {
      "x": 1,
      "y": 7,
      "z": -2,
      "name": "Rock_Quartzite"
    },
    {
      "x": 1,
      "y": 8,
      "z": -2,
      "name": "Rock_Quartzite"
    },
    {
      "x": 1,
      "y": 0,
      "z": -1,
      "name": "Rock_Stone"
    },
    {
      "x": 1,
      "y": 1,
      "z": -1,
      "name": "Soil_Gravel_Mossy"
    },
    {
      "x": 1,
      "y": 2,
      "z": -1,
      "name": "Empty"
    },
    {
      "x": 1,
      "y": 3,
      "z": -1,
      "name": "Empty"
    },
    {
      "x": 1,
      "y": 4,
      "z": -1,
      "name": "Empty"
    },
    {
      "x": 1,
      "y": 5,
      "z": -1,
      "name": "Rock_Stone_Brick_Half",
      "rotation": 8
    },
    {
      "x": 1,
      "y": 6,
      "z": -1,
      "name": "Rock_Stone_Brick"
    },
    {
      "x": 1,
      "y": 7,
      "z": -1,
      "name": "Rock_Quartzite"
    },
    {
      "x": 1,
      "y": 8,
      "z": -1,
      "name": "Rock_Quartzite"
    },
    {
      "x": 1,
      "y": 0,
      "z": 0,
      "name": "Rock_Stone"
    },
    {
      "x": 1,
      "y": 1,
      "z": 0,
      "name": "Soil_Pathway"
    },
    {
      "x": 1,
      "y": 2,
      "z": 0,
      "name": "Deco_Bone_Pile"
    },
    {
      "x": 1,
      "y": 3,
      "z": 0,
      "name": "Plant_Vine_Wall",
      "rotation": 3
    },
    {
      "x": 1,
      "y": 4,
      "z": 0,
      "name": "Empty"
    },
    {
      "x": 1,
      "y": 5,
      "z": 0,
      "name": "Empty"
    },
    {
      "x": 1,
      "y": 6,
      "z": 0,
      "name": "Wood_Gnarled_Roots"
    },
    {
      "x": 1,
      "y": 7,
      "z": 0,
      "name": "Rock_Quartzite"
    },
    {
      "x": 1,
      "y": 8,
      "z": 0,
      "name": "Rock_Quartzite"
    },
    {
      "x": 1,
      "y": 0,
      "z": 1,
      "name": "Rock_Stone"
    },
    {
      "x": 1,
      "y": 1,
      "z": 1,
      "name": "Soil_Pathway"
    },
    {
      "x": 1,
      "y": 2,
      "z": 1,
      "name": "Plant_Grass_Rocky_Short"
    },
    {
      "x": 1,
      "y": 3,
      "z": 1,
      "name": "Empty"
    },
    {
      "x": 1,
      "y": 4,
      "z": 1,
      "name": "Empty"
    },
    {
      "x": 1,
      "y": 5,
      "z": 1,
      "name": "Empty"
    },
    {
      "x": 1,
      "y": 6,
      "z": 1,
      "name": "Empty"
    },
    {
      "x": 1,
      "y": 7,
      "z": 1,
      "name": "Rock_Quartzite"
    },
    {
      "x": 1,
      "y": 8,
      "z": 1,
      "name": "Rock_Quartzite"
    },
    {
      "x": 1,
      "y": 0,
      "z": 2,
      "name": "Rock_Stone"
    },
    {
      "x": 1,
      "y": 1,
      "z": 2,
      "name": "Soil_Pathway"
    },
    {
      "x": 1,
      "y": 2,
      "z": 2,
      "name": "Empty"
    },
    {
      "x": 1,
      "y": 3,
      "z": 2,
      "name": "Empty"
    },
    {
      "x": 1,
      "y": 4,
      "z": 2,
      "name": "Empty"
    },
    {
      "x": 1,
      "y": 5,
      "z": 2,
      "name": "Empty"
    },
    {
      "x": 1,
      "y": 6,
      "z": 2,
      "name": "Empty"
    },
    {
      "x": 1,
      "y": 7,
      "z": 2,
      "name": "Empty"
    },
    {
      "x": 1,
      "y": 8,
      "z": 2,
      "name": "Rock_Quartzite"
    },
    {
      "x": 1,
      "y": 0,
      "z": 3,
      "name": "Rock_Stone"
    },
    {
      "x": 1,
      "y": 1,
      "z": 3,
      "name": "Soil_Pathway"
    },
    {
      "x": 1,
      "y": 2,
      "z": 3,
      "name": "Empty"
    },
    {
      "x": 1,
      "y": 3,
      "z": 3,
      "name": "Empty"
    },
    {
      "x": 1,
      "y": 4,
      "z": 3,
      "name": "Empty"
    },
    {
      "x": 1,
      "y": 5,
      "z": 3,
      "name": "Empty"
    },
    {
      "x": 1,
      "y": 6,
      "z": 3,
      "name": "Empty"
    },
    {
      "x": 1,
      "y": 7,
      "z": 3,
      "name": "Empty"
    },
    {
      "x": 1,
      "y": 8,
      "z": 3,
      "name": "Rock_Quartzite"
    },
    {
      "x": 1,
      "y": 0,
      "z": 4,
      "name": "Rock_Stone"
    },
    {
      "x": 1,
      "y": 1,
      "z": 4,
      "name": "Soil_Pathway"
    },
    {
      "x": 1,
      "y": 2,
      "z": 4,
      "name": "Empty"
    },
    {
      "x": 1,
      "y": 3,
      "z": 4,
      "name": "Empty"
    },
    {
      "x": 1,
      "y": 4,
      "z": 4,
      "name": "Empty"
    },
    {
      "x": 1,
      "y": 5,
      "z": 4,
      "name": "Empty"
    },
    {
      "x": 1,
      "y": 6,
      "z": 4,
      "name": "Empty"
    },
    {
      "x": 1,
      "y": 7,
      "z": 4,
      "name": "Rock_Quartzite"
    },
    {
      "x": 1,
      "y": 8,
      "z": 4,
      "name": "Rock_Quartzite"
    },
    {
      "x": 1,
      "y": 0,
      "z": 5,
      "name": "Rock_Stone"
    },
    {
      "x": 1,
      "y": 1,
      "z": 5,
      "name": "Soil_Pathway"
    },
    {
      "x": 1,
      "y": 2,
      "z": 5,
      "name": "Empty"
    },
    {
      "x": 1,
      "y": 3,
      "z": 5,
      "name": "Empty"
    },
    {
      "x": 1,
      "y": 4,
      "z": 5,
      "name": "Empty"
    },
    {
      "x": 1,
      "y": 5,
      "z": 5,
      "name": "Empty"
    },
    {
      "x": 1,
      "y": 6,
      "z": 5,
      "name": "Empty"
    },
    {
      "x": 1,
      "y": 7,
      "z": 5,
      "name": "Rock_Quartzite_Cobble"
    },
    {
      "x": 1,
      "y": 8,
      "z": 5,
      "name": "Rock_Quartzite"
    },
    {
      "x": 1,
      "y": 0,
      "z": 6,
      "name": "Rock_Stone"
    },
    {
      "x": 1,
      "y": 1,
      "z": 6,
      "name": "Soil_Pathway"
    },
    {
      "x": 1,
      "y": 2,
      "z": 6,
      "name": "Empty"
    },
    {
      "x": 1,
      "y": 3,
      "z": 6,
      "name": "Empty"
    },
    {
      "x": 1,
      "y": 4,
      "z": 6,
      "name": "Empty"
    },
    {
      "x": 1,
      "y": 5,
      "z": 6,
      "name": "Plant_Vine_Wall",
      "rotation": 2
    },
    {
      "x": 1,
      "y": 6,
      "z": 6,
      "name": "Rock_Quartzite_Cobble"
    },
    {
      "x": 1,
      "y": 7,
      "z": 6,
      "name": "Rock_Quartzite"
    },
    {
      "x": 1,
      "y": 8,
      "z": 6,
      "name": "Rock_Quartzite"
    },
    {
      "x": 1,
      "y": 0,
      "z": 7,
      "name": "Rock_Stone"
    },
    {
      "x": 1,
      "y": 1,
      "z": 7,
      "name": "Soil_Pathway"
    },
    {
      "x": 1,
      "y": 2,
      "z": 7,
      "name": "Plant_Grass_Rocky_Short"
    },
    {
      "x": 1,
      "y": 3,
      "z": 7,
      "name": "Empty"
    },
    {
      "x": 1,
      "y": 4,
      "z": 7,
      "name": "Empty"
    },
    {
      "x": 1,
      "y": 5,
      "z": 7,
      "name": "Rock_Stone"
    },
    {
      "x": 1,
      "y": 6,
      "z": 7,
      "name": "Rock_Stone"
    },
    {
      "x": 1,
      "y": 7,
      "z": 7,
      "name": "Rock_Quartzite"
    },
    {
      "x": 1,
      "y": 8,
      "z": 7,
      "name": "Rock_Quartzite"
    },
    {
      "x": 1,
      "y": 0,
      "z": 8,
      "name": "Rock_Stone"
    },
    {
      "x": 1,
      "y": 1,
      "z": 8,
      "name": "Soil_Pathway"
    },
    {
      "x": 1,
      "y": 2,
      "z": 8,
      "name": "Empty"
    },
    {
      "x": 1,
      "y": 3,
      "z": 8,
      "name": "Empty"
    },
    {
      "x": 1,
      "y": 4,
      "z": 8,
      "name": "Empty"
    },
    {
      "x": 1,
      "y": 5,
      "z": 8,
      "name": "Rock_Stone"
    },
    {
      "x": 1,
      "y": 6,
      "z": 8,
      "name": "Rock_Stone"
    },
    {
      "x": 1,
      "y": 7,
      "z": 8,
      "name": "Rock_Quartzite"
    },
    {
      "x": 1,
      "y": 8,
      "z": 8,
      "name": "Rock_Quartzite"
    },
    {
      "x": 2,
      "y": 0,
      "z": -8,
      "name": "Rock_Stone"
    },
    {
      "x": 2,
      "y": 1,
      "z": -8,
      "name": "Rock_Stone_Cobble"
    },
    {
      "x": 2,
      "y": 2,
      "z": -8,
      "name": "Plant_Moss_Rug_Green"
    },
    {
      "x": 2,
      "y": 3,
      "z": -8,
      "name": "Empty"
    },
    {
      "x": 2,
      "y": 4,
      "z": -8,
      "name": "Empty"
    },
    {
      "x": 2,
      "y": 5,
      "z": -8,
      "name": "Rock_Stone_Brick_Half",
      "rotation": 7
    },
    {
      "x": 2,
      "y": 6,
      "z": -8,
      "name": "Rock_Stone_Brick"
    },
    {
      "x": 2,
      "y": 7,
      "z": -8,
      "name": "Rock_Quartzite"
    },
    {
      "x": 2,
      "y": 8,
      "z": -8,
      "name": "Rock_Quartzite"
    },
    {
      "x": 2,
      "y": 0,
      "z": -7,
      "name": "Rock_Stone"
    },
    {
      "x": 2,
      "y": 1,
      "z": -7,
      "name": "Rock_Stone_Cobble"
    },
    {
      "x": 2,
      "y": 2,
      "z": -7,
      "name": "Plant_Moss_Rug_Green"
    },
    {
      "x": 2,
      "y": 3,
      "z": -7,
      "name": "Empty"
    },
    {
      "x": 2,
      "y": 4,
      "z": -7,
      "name": "Empty"
    },
    {
      "x": 2,
      "y": 5,
      "z": -7,
      "name": "Empty"
    },
    {
      "x": 2,
      "y": 6,
      "z": -7,
      "name": "Wood_Dry_Roots"
    },
    {
      "x": 2,
      "y": 7,
      "z": -7,
      "name": "Rock_Quartzite_Cobble"
    },
    {
      "x": 2,
      "y": 8,
      "z": -7,
      "name": "Rock_Quartzite"
    },
    {
      "x": 2,
      "y": 0,
      "z": -6,
      "name": "Rock_Stone"
    },
    {
      "x": 2,
      "y": 1,
      "z": -6,
      "name": "Soil_Gravel"
    },
    {
      "x": 2,
      "y": 2,
      "z": -6,
      "name": "Plant_Crop_Mushroom_Flatcap_Green",
      "components": {
        "Components": {
          "FarmingBlock": {}
        }
      }
    },
    {
      "x": 2,
      "y": 3,
      "z": -6,
      "name": "Empty"
    },
    {
      "x": 2,
      "y": 4,
      "z": -6,
      "name": "Empty"
    },
    {
      "x": 2,
      "y": 5,
      "z": -6,
      "name": "Empty"
    },
    {
      "x": 2,
      "y": 6,
      "z": -6,
      "name": "Empty"
    },
    {
      "x": 2,
      "y": 7,
      "z": -6,
      "name": "Rock_Quartzite"
    },
    {
      "x": 2,
      "y": 8,
      "z": -6,
      "name": "Rock_Quartzite"
    },
    {
      "x": 2,
      "y": 0,
      "z": -5,
      "name": "Rock_Stone"
    },
    {
      "x": 2,
      "y": 1,
      "z": -5,
      "name": "Soil_Gravel_Mossy"
    },
    {
      "x": 2,
      "y": 2,
      "z": -5,
      "name": "Plant_Grass_Gnarled_Short"
    },
    {
      "x": 2,
      "y": 3,
      "z": -5,
      "name": "Empty"
    },
    {
      "x": 2,
      "y": 4,
      "z": -5,
      "name": "Empty"
    },
    {
      "x": 2,
      "y": 5,
      "z": -5,
      "name": "Empty"
    },
    {
      "x": 2,
      "y": 6,
      "z": -5,
      "name": "Empty"
    },
    {
      "x": 2,
      "y": 7,
      "z": -5,
      "name": "Rock_Quartzite_Cobble"
    },
    {
      "x": 2,
      "y": 8,
      "z": -5,
      "name": "Rock_Quartzite"
    },
    {
      "x": 2,
      "y": 0,
      "z": -4,
      "name": "Rock_Stone"
    },
    {
      "x": 2,
      "y": 1,
      "z": -4,
      "name": "Soil_Pathway"
    },
    {
      "x": 2,
      "y": 2,
      "z": -4,
      "name": "Furniture_Ancient_Barrel"
    },
    {
      "x": 2,
      "y": 3,
      "z": -4,
      "name": "Empty"
    },
    {
      "x": 2,
      "y": 4,
      "z": -4,
      "name": "Empty"
    },
    {
      "x": 2,
      "y": 5,
      "z": -4,
      "name": "Empty"
    },
    {
      "x": 2,
      "y": 6,
      "z": -4,
      "name": "Empty"
    },
    {
      "x": 2,
      "y": 7,
      "z": -4,
      "name": "Rock_Quartzite"
    },
    {
      "x": 2,
      "y": 8,
      "z": -4,
      "name": "Rock_Quartzite"
    },
    {
      "x": 2,
      "y": 0,
      "z": -3,
      "name": "Rock_Stone"
    },
    {
      "x": 2,
      "y": 1,
      "z": -3,
      "name": "Rock_Stone"
    },
    {
      "x": 2,
      "y": 2,
      "z": -3,
      "name": "Rock_Stone"
    },
    {
      "x": 2,
      "y": 3,
      "z": -3,
      "name": "Rock_Stone"
    },
    {
      "x": 2,
      "y": 4,
      "z": -3,
      "name": "Plant_Moss_Rug_Green"
    },
    {
      "x": 2,
      "y": 5,
      "z": -3,
      "name": "Plant_Vine_Wall",
      "rotation": 2
    },
    {
      "x": 2,
      "y": 6,
      "z": -3,
      "name": "Rock_Stone"
    },
    {
      "x": 2,
      "y": 7,
      "z": -3,
      "name": "Rock_Quartzite"
    },
    {
      "x": 2,
      "y": 8,
      "z": -3,
      "name": "Rock_Quartzite"
    },
    {
      "x": 2,
      "y": 0,
      "z": -2,
      "name": "Rock_Stone"
    },
    {
      "x": 2,
      "y": 1,
      "z": -2,
      "name": "Rock_Stone"
    },
    {
      "x": 2,
      "y": 2,
      "z": -2,
      "name": "Rock_Stone"
    },
    {
      "x": 2,
      "y": 3,
      "z": -2,
      "name": "Rock_Stone"
    },
    {
      "x": 2,
      "y": 4,
      "z": -2,
      "name": "Rock_Stone"
    },
    {
      "x": 2,
      "y": 5,
      "z": -2,
      "name": "Rock_Stone"
    },
    {
      "x": 2,
      "y": 6,
      "z": -2,
      "name": "Rock_Stone"
    },
    {
      "x": 2,
      "y": 7,
      "z": -2,
      "name": "Rock_Quartzite"
    },
    {
      "x": 2,
      "y": 8,
      "z": -2,
      "name": "Rock_Quartzite"
    },
    {
      "x": 2,
      "y": 0,
      "z": -1,
      "name": "Rock_Stone"
    },
    {
      "x": 2,
      "y": 1,
      "z": -1,
      "name": "Rock_Stone"
    },
    {
      "x": 2,
      "y": 2,
      "z": -1,
      "name": "Rock_Stone"
    },
    {
      "x": 2,
      "y": 3,
      "z": -1,
      "name": "Rock_Stone"
    },
    {
      "x": 2,
      "y": 4,
      "z": -1,
      "name": "Rock_Stone"
    },
    {
      "x": 2,
      "y": 5,
      "z": -1,
      "name": "Rock_Stone"
    },
    {
      "x": 2,
      "y": 6,
      "z": -1,
      "name": "Rock_Stone"
    },
    {
      "x": 2,
      "y": 7,
      "z": -1,
      "name": "Rock_Stone"
    },
    {
      "x": 2,
      "y": 8,
      "z": -1,
      "name": "Rock_Quartzite"
    },
    {
      "x": 2,
      "y": 0,
      "z": 0,
      "name": "Rock_Stone"
    },
    {
      "x": 2,
      "y": 1,
      "z": 0,
      "name": "Rock_Stone"
    },
    {
      "x": 2,
      "y": 2,
      "z": 0,
      "name": "Rock_Stone"
    },
    {
      "x": 2,
      "y": 3,
      "z": 0,
      "name": "Rock_Stone"
    },
    {
      "x": 2,
      "y": 4,
      "z": 0,
      "name": "Plant_Moss_Rug_Green"
    },
    {
      "x": 2,
      "y": 5,
      "z": 0,
      "name": "Empty"
    },
    {
      "x": 2,
      "y": 6,
      "z": 0,
      "name": "Rock_Stone"
    },
    {
      "x": 2,
      "y": 7,
      "z": 0,
      "name": "Rock_Stone"
    },
    {
      "x": 2,
      "y": 8,
      "z": 0,
      "name": "Rock_Quartzite"
    },
    {
      "x": 2,
      "y": 0,
      "z": 1,
      "name": "Rock_Stone"
    },
    {
      "x": 2,
      "y": 1,
      "z": 1,
      "name": "Soil_Gravel"
    },
    {
      "x": 2,
      "y": 2,
      "z": 1,
      "name": "Plant_Vine_Wall"
    },
    {
      "x": 2,
      "y": 3,
      "z": 1,
      "name": "Plant_Vine"
    },
    {
      "x": 2,
      "y": 4,
      "z": 1,
      "name": "Empty"
    },
    {
      "x": 2,
      "y": 5,
      "z": 1,
      "name": "Empty"
    },
    {
      "x": 2,
      "y": 6,
      "z": 1,
      "name": "Plant_Vine",
      "rotation": 3
    },
    {
      "x": 2,
      "y": 7,
      "z": 1,
      "name": "Rock_Quartzite"
    },
    {
      "x": 2,
      "y": 8,
      "z": 1,
      "name": "Rock_Quartzite"
    },
    {
      "x": 2,
      "y": 0,
      "z": 2,
      "name": "Rock_Stone"
    },
    {
      "x": 2,
      "y": 1,
      "z": 2,
      "name": "Soil_Gravel"
    },
    {
      "x": 2,
      "y": 2,
      "z": 2,
      "name": "Empty"
    },
    {
      "x": 2,
      "y": 3,
      "z": 2,
      "name": "Empty"
    },
    {
      "x": 2,
      "y": 4,
      "z": 2,
      "name": "Empty"
    },
    {
      "x": 2,
      "y": 5,
      "z": 2,
      "name": "Empty"
    },
    {
      "x": 2,
      "y": 6,
      "z": 2,
      "name": "Plant_Vine_Wall",
      "rotation": 3
    },
    {
      "x": 2,
      "y": 7,
      "z": 2,
      "name": "Plant_Vine",
      "rotation": 3
    },
    {
      "x": 2,
      "y": 8,
      "z": 2,
      "name": "Rock_Quartzite"
    },
    {
      "x": 2,
      "y": 0,
      "z": 3,
      "name": "Rock_Stone"
    },
    {
      "x": 2,
      "y": 1,
      "z": 3,
      "name": "Soil_Gravel_Mossy"
    },
    {
      "x": 2,
      "y": 2,
      "z": 3,
      "name": "Wood_Deadwood_Beam"
    },
    {
      "x": 2,
      "y": 3,
      "z": 3,
      "name": "Furniture_Ancient_Torch",
      "rotation": 3
    },
    {
      "x": 2,
      "y": 4,
      "z": 3,
      "name": "Empty"
    },
    {
      "x": 2,
      "y": 5,
      "z": 3,
      "name": "Empty"
    },
    {
      "x": 2,
      "y": 6,
      "z": 3,
      "name": "Empty"
    },
    {
      "x": 2,
      "y": 7,
      "z": 3,
      "name": "Empty"
    },
    {
      "x": 2,
      "y": 8,
      "z": 3,
      "name": "Rock_Quartzite"
    },
    {
      "x": 2,
      "y": 0,
      "z": 4,
      "name": "Rock_Stone"
    },
    {
      "x": 2,
      "y": 1,
      "z": 4,
      "name": "Soil_Pathway"
    },
    {
      "x": 2,
      "y": 2,
      "z": 4,
      "name": "Deco_Bone_Skulls"
    },
    {
      "x": 2,
      "y": 3,
      "z": 4,
      "name": "Empty"
    },
    {
      "x": 2,
      "y": 4,
      "z": 4,
      "name": "Empty"
    },
    {
      "x": 2,
      "y": 5,
      "z": 4,
      "name": "Empty"
    },
    {
      "x": 2,
      "y": 6,
      "z": 4,
      "name": "Plant_Vine_Wall",
      "rotation": 3
    },
    {
      "x": 2,
      "y": 7,
      "z": 4,
      "name": "Rock_Quartzite"
    },
    {
      "x": 2,
      "y": 8,
      "z": 4,
      "name": "Rock_Quartzite"
    },
    {
      "x": 2,
      "y": 0,
      "z": 5,
      "name": "Rock_Stone"
    },
    {
      "x": 2,
      "y": 1,
      "z": 5,
      "name": "Soil_Pathway"
    },
    {
      "x": 2,
      "y": 2,
      "z": 5,
      "name": "Empty"
    },
    {
      "x": 2,
      "y": 3,
      "z": 5,
      "name": "Empty"
    },
    {
      "x": 2,
      "y": 4,
      "z": 5,
      "name": "Empty"
    },
    {
      "x": 2,
      "y": 5,
      "z": 5,
      "name": "Plant_Vine_Wall",
      "rotation": 3
    },
    {
      "x": 2,
      "y": 6,
      "z": 5,
      "name": "Plant_Vine",
      "rotation": 3
    },
    {
      "x": 2,
      "y": 7,
      "z": 5,
      "name": "Rock_Quartzite"
    },
    {
      "x": 2,
      "y": 8,
      "z": 5,
      "name": "Rock_Quartzite"
    },
    {
      "x": 2,
      "y": 0,
      "z": 6,
      "name": "Rock_Stone"
    },
    {
      "x": 2,
      "y": 1,
      "z": 6,
      "name": "Soil_Pathway"
    },
    {
      "x": 2,
      "y": 2,
      "z": 6,
      "name": "Furniture_Ancient_Barrel"
    },
    {
      "x": 2,
      "y": 3,
      "z": 6,
      "name": "Empty"
    },
    {
      "x": 2,
      "y": 4,
      "z": 6,
      "name": "Empty"
    },
    {
      "x": 2,
      "y": 5,
      "z": 6,
      "name": "Rock_Quartzite"
    },
    {
      "x": 2,
      "y": 6,
      "z": 6,
      "name": "Rock_Quartzite"
    },
    {
      "x": 2,
      "y": 7,
      "z": 6,
      "name": "Rock_Quartzite"
    },
    {
      "x": 2,
      "y": 8,
      "z": 6,
      "name": "Rock_Quartzite"
    },
    {
      "x": 2,
      "y": 0,
      "z": 7,
      "name": "Rock_Stone"
    },
    {
      "x": 2,
      "y": 1,
      "z": 7,
      "name": "Rock_Stone_Cobble"
    },
    {
      "x": 2,
      "y": 2,
      "z": 7,
      "name": "Furniture_Ancient_Barrel"
    },
    {
      "x": 2,
      "y": 3,
      "z": 7,
      "name": "Rock_Stone_Stalactite_Large",
      "filler": 31744,
      "rotation": 8
    },
    {
      "x": 2,
      "y": 4,
      "z": 7,
      "name": "Rock_Stone_Stalactite_Large",
      "rotation": 8
    },
    {
      "x": 2,
      "y": 5,
      "z": 7,
      "name": "Rock_Stone"
    },
    {
      "x": 2,
      "y": 6,
      "z": 7,
      "name": "Rock_Stone"
    },
    {
      "x": 2,
      "y": 7,
      "z": 7,
      "name": "Rock_Quartzite"
    },
    {
      "x": 2,
      "y": 8,
      "z": 7,
      "name": "Rock_Quartzite"
    },
    {
      "x": 2,
      "y": 0,
      "z": 8,
      "name": "Rock_Stone"
    },
    {
      "x": 2,
      "y": 1,
      "z": 8,
      "name": "Rock_Stone_Cobble"
    },
    {
      "x": 2,
      "y": 2,
      "z": 8,
      "name": "Rubble_Stone"
    },
    {
      "x": 2,
      "y": 3,
      "z": 8,
      "name": "Empty"
    },
    {
      "x": 2,
      "y": 4,
      "z": 8,
      "name": "Empty"
    },
    {
      "x": 2,
      "y": 5,
      "z": 8,
      "name": "Rock_Stone"
    },
    {
      "x": 2,
      "y": 6,
      "z": 8,
      "name": "Rock_Stone"
    },
    {
      "x": 2,
      "y": 7,
      "z": 8,
      "name": "Rock_Quartzite"
    },
    {
      "x": 2,
      "y": 8,
      "z": 8,
      "name": "Rock_Quartzite"
    },
    {
      "x": 3,
      "y": 0,
      "z": -8,
      "name": "Rock_Stone"
    },
    {
      "x": 3,
      "y": 1,
      "z": -8,
      "name": "Rock_Stone_Cobble"
    },
    {
      "x": 3,
      "y": 2,
      "z": -8,
      "name": "Rock_Stone_Brick_Pillar_Base"
    },
    {
      "x": 3,
      "y": 3,
      "z": -8,
      "name": "Rock_Stone_Brick_Pillar_Middle"
    },
    {
      "x": 3,
      "y": 4,
      "z": -8,
      "name": "Rock_Stone_Brick_Pillar_Base",
      "rotation": 8
    },
    {
      "x": 3,
      "y": 5,
      "z": -8,
      "name": "Rock_Stone_Brick"
    },
    {
      "x": 3,
      "y": 6,
      "z": -8,
      "name": "Rock_Stone_Brick"
    },
    {
      "x": 3,
      "y": 7,
      "z": -8,
      "name": "Rock_Quartzite"
    },
    {
      "x": 3,
      "y": 8,
      "z": -8,
      "name": "Rock_Quartzite"
    },
    {
      "x": 3,
      "y": 0,
      "z": -7,
      "name": "Rock_Stone"
    },
    {
      "x": 3,
      "y": 1,
      "z": -7,
      "name": "Rock_Stone_Cobble"
    },
    {
      "x": 3,
      "y": 2,
      "z": -7,
      "name": "Furniture_Ancient_Wardrobe",
      "filler": 992,
      "rotation": 3
    },
    {
      "x": 3,
      "y": 3,
      "z": -7,
      "name": "Furniture_Ancient_Wardrobe",
      "filler": 2016,
      "rotation": 3
    },
    {
      "x": 3,
      "y": 4,
      "z": -7,
      "name": "Empty"
    },
    {
      "x": 3,
      "y": 5,
      "z": -7,
      "name": "Rock_Quartzite"
    },
    {
      "x": 3,
      "y": 6,
      "z": -7,
      "name": "Rock_Quartzite"
    },
    {
      "x": 3,
      "y": 7,
      "z": -7,
      "name": "Rock_Quartzite"
    },
    {
      "x": 3,
      "y": 8,
      "z": -7,
      "name": "Rock_Quartzite"
    },
    {
      "x": 3,
      "y": 0,
      "z": -6,
      "name": "Rock_Stone"
    },
    {
      "x": 3,
      "y": 1,
      "z": -6,
      "name": "Rock_Stone_Cobble"
    },
    {
      "x": 3,
      "y": 2,
      "z": -6,
      "name": "Furniture_Ancient_Wardrobe",
      "rotation": 3
    },
    {
      "x": 3,
      "y": 3,
      "z": -6,
      "name": "Furniture_Ancient_Wardrobe",
      "filler": 1024,
      "rotation": 3
    },
    {
      "x": 3,
      "y": 4,
      "z": -6,
      "name": "Empty"
    },
    {
      "x": 3,
      "y": 5,
      "z": -6,
      "name": "Rock_Quartzite"
    },
    {
      "x": 3,
      "y": 6,
      "z": -6,
      "name": "Rock_Quartzite"
    },
    {
      "x": 3,
      "y": 7,
      "z": -6,
      "name": "Rock_Quartzite"
    },
    {
      "x": 3,
      "y": 8,
      "z": -6,
      "name": "Rock_Quartzite"
    },
    {
      "x": 3,
      "y": 0,
      "z": -5,
      "name": "Rock_Stone"
    },
    {
      "x": 3,
      "y": 1,
      "z": -5,
      "name": "Rock_Stone_Cobble"
    },
    {
      "x": 3,
      "y": 2,
      "z": -5,
      "name": "Furniture_Ancient_Crate",
      "rotation": 3
    },
    {
      "x": 3,
      "y": 3,
      "z": -5,
      "name": "Furniture_Tavern_Shelf",
      "rotation": 3
    },
    {
      "x": 3,
      "y": 4,
      "z": -5,
      "name": "Empty"
    },
    {
      "x": 3,
      "y": 5,
      "z": -5,
      "name": "Empty"
    },
    {
      "x": 3,
      "y": 6,
      "z": -5,
      "name": "Rock_Quartzite_Cobble"
    },
    {
      "x": 3,
      "y": 7,
      "z": -5,
      "name": "Rock_Quartzite"
    },
    {
      "x": 3,
      "y": 8,
      "z": -5,
      "name": "Rock_Quartzite"
    },
    {
      "x": 3,
      "y": 0,
      "z": -4,
      "name": "Rock_Stone"
    },
    {
      "x": 3,
      "y": 1,
      "z": -4,
      "name": "Rock_Stone_Cobble"
    },
    {
      "x": 3,
      "y": 2,
      "z": -4,
      "name": "Furniture_Ancient_Crate",
      "rotation": 3
    },
    {
      "x": 3,
      "y": 3,
      "z": -4,
      "name": "Furniture_Tavern_Shelf",
      "rotation": 3
    },
    {
      "x": 3,
      "y": 4,
      "z": -4,
      "name": "Empty"
    },
    {
      "x": 3,
      "y": 5,
      "z": -4,
      "name": "Empty"
    },
    {
      "x": 3,
      "y": 6,
      "z": -4,
      "name": "Rock_Quartzite"
    },
    {
      "x": 3,
      "y": 7,
      "z": -4,
      "name": "Rock_Quartzite"
    },
    {
      "x": 3,
      "y": 8,
      "z": -4,
      "name": "Rock_Quartzite"
    },
    {
      "x": 3,
      "y": 0,
      "z": -3,
      "name": "Rock_Stone"
    },
    {
      "x": 3,
      "y": 1,
      "z": -3,
      "name": "Rock_Stone"
    },
    {
      "x": 3,
      "y": 2,
      "z": -3,
      "name": "Rock_Stone"
    },
    {
      "x": 3,
      "y": 3,
      "z": -3,
      "name": "Rock_Stone"
    },
    {
      "x": 3,
      "y": 4,
      "z": -3,
      "name": "Rock_Stone"
    },
    {
      "x": 3,
      "y": 5,
      "z": -3,
      "name": "Rock_Stone"
    },
    {
      "x": 3,
      "y": 6,
      "z": -3,
      "name": "Rock_Stone"
    },
    {
      "x": 3,
      "y": 7,
      "z": -3,
      "name": "Rock_Quartzite"
    },
    {
      "x": 3,
      "y": 8,
      "z": -3,
      "name": "Rock_Quartzite"
    },
    {
      "x": 3,
      "y": 0,
      "z": -2,
      "name": "Rock_Stone"
    },
    {
      "x": 3,
      "y": 1,
      "z": -2,
      "name": "Rock_Stone"
    },
    {
      "x": 3,
      "y": 2,
      "z": -2,
      "name": "Rock_Stone"
    },
    {
      "x": 3,
      "y": 3,
      "z": -2,
      "name": "Rock_Stone"
    },
    {
      "x": 3,
      "y": 4,
      "z": -2,
      "name": "Rock_Stone"
    },
    {
      "x": 3,
      "y": 5,
      "z": -2,
      "name": "Rock_Stone"
    },
    {
      "x": 3,
      "y": 6,
      "z": -2,
      "name": "Rock_Stone"
    },
    {
      "x": 3,
      "y": 7,
      "z": -2,
      "name": "Rock_Quartzite"
    },
    {
      "x": 3,
      "y": 8,
      "z": -2,
      "name": "Rock_Quartzite"
    },
    {
      "x": 3,
      "y": 0,
      "z": -1,
      "name": "Rock_Stone"
    },
    {
      "x": 3,
      "y": 1,
      "z": -1,
      "name": "Rock_Stone"
    },
    {
      "x": 3,
      "y": 2,
      "z": -1,
      "name": "Rock_Stone"
    },
    {
      "x": 3,
      "y": 3,
      "z": -1,
      "name": "Rock_Stone"
    },
    {
      "x": 3,
      "y": 4,
      "z": -1,
      "name": "Rock_Stone"
    },
    {
      "x": 3,
      "y": 5,
      "z": -1,
      "name": "Rock_Stone"
    },
    {
      "x": 3,
      "y": 6,
      "z": -1,
      "name": "Rock_Stone"
    },
    {
      "x": 3,
      "y": 7,
      "z": -1,
      "name": "Rock_Stone"
    },
    {
      "x": 3,
      "y": 8,
      "z": -1,
      "name": "Rock_Quartzite"
    },
    {
      "x": 3,
      "y": 0,
      "z": 0,
      "name": "Rock_Stone"
    },
    {
      "x": 3,
      "y": 1,
      "z": 0,
      "name": "Rock_Stone"
    },
    {
      "x": 3,
      "y": 2,
      "z": 0,
      "name": "Rock_Stone"
    },
    {
      "x": 3,
      "y": 3,
      "z": 0,
      "name": "Rock_Stone"
    },
    {
      "x": 3,
      "y": 4,
      "z": 0,
      "name": "Rock_Stone"
    },
    {
      "x": 3,
      "y": 5,
      "z": 0,
      "name": "Rock_Stone"
    },
    {
      "x": 3,
      "y": 6,
      "z": 0,
      "name": "Rock_Stone"
    },
    {
      "x": 3,
      "y": 7,
      "z": 0,
      "name": "Rock_Stone"
    },
    {
      "x": 3,
      "y": 8,
      "z": 0,
      "name": "Rock_Quartzite"
    },
    {
      "x": 3,
      "y": 0,
      "z": 1,
      "name": "Rock_Stone"
    },
    {
      "x": 3,
      "y": 1,
      "z": 1,
      "name": "Soil_Gravel"
    },
    {
      "x": 3,
      "y": 2,
      "z": 1,
      "name": "Furniture_Ancient_Bookshelf",
      "rotation": 3
    },
    {
      "x": 3,
      "y": 3,
      "z": 1,
      "name": "Furniture_Ancient_Bookshelf",
      "rotation": 3
    },
    {
      "x": 3,
      "y": 4,
      "z": 1,
      "name": "Empty"
    },
    {
      "x": 3,
      "y": 5,
      "z": 1,
      "name": "Empty"
    },
    {
      "x": 3,
      "y": 6,
      "z": 1,
      "name": "Rock_Quartzite"
    },
    {
      "x": 3,
      "y": 7,
      "z": 1,
      "name": "Rock_Quartzite"
    },
    {
      "x": 3,
      "y": 8,
      "z": 1,
      "name": "Rock_Quartzite"
    },
    {
      "x": 3,
      "y": 0,
      "z": 2,
      "name": "Rock_Stone"
    },
    {
      "x": 3,
      "y": 1,
      "z": 2,
      "name": "Soil_Gravel"
    },
    {
      "x": 3,
      "y": 2,
      "z": 2,
      "name": "Furniture_Ancient_Bookshelf",
      "rotation": 3
    },
    {
      "x": 3,
      "y": 3,
      "z": 2,
      "name": "Furniture_Ancient_Bookshelf",
      "rotation": 3
    },
    {
      "x": 3,
      "y": 4,
      "z": 2,
      "name": "Empty"
    },
    {
      "x": 3,
      "y": 5,
      "z": 2,
      "name": "Empty"
    },
    {
      "x": 3,
      "y": 6,
      "z": 2,
      "name": "Rock_Quartzite_Cobble"
    },
    {
      "x": 3,
      "y": 7,
      "z": 2,
      "name": "Rock_Quartzite"
    },
    {
      "x": 3,
      "y": 8,
      "z": 2,
      "name": "Rock_Quartzite"
    },
    {
      "x": 3,
      "y": 0,
      "z": 3,
      "name": "Rock_Stone"
    },
    {
      "x": 3,
      "y": 1,
      "z": 3,
      "name": "Rock_Stone_Cobble_Mossy"
    },
    {
      "x": 3,
      "y": 2,
      "z": 3,
      "name": "Plant_Grass_Gnarled_Short"
    },
    {
      "x": 3,
      "y": 3,
      "z": 3,
      "name": "Empty"
    },
    {
      "x": 3,
      "y": 4,
      "z": 3,
      "name": "Empty"
    },
    {
      "x": 3,
      "y": 5,
      "z": 3,
      "name": "Empty"
    },
    {
      "x": 3,
      "y": 6,
      "z": 3,
      "name": "Empty"
    },
    {
      "x": 3,
      "y": 7,
      "z": 3,
      "name": "Empty"
    },
    {
      "x": 3,
      "y": 8,
      "z": 3,
      "name": "Rock_Quartzite"
    },
    {
      "x": 3,
      "y": 0,
      "z": 4,
      "name": "Rock_Stone"
    },
    {
      "x": 3,
      "y": 1,
      "z": 4,
      "name": "Rock_Stone_Cobble_Mossy"
    },
    {
      "x": 3,
      "y": 2,
      "z": 4,
      "name": "Furniture_Ancient_Wardrobe",
      "filler": 992,
      "rotation": 3
    },
    {
      "x": 3,
      "y": 3,
      "z": 4,
      "name": "Furniture_Ancient_Wardrobe",
      "filler": 2016,
      "rotation": 3
    },
    {
      "x": 3,
      "y": 4,
      "z": 4,
      "name": "Empty"
    },
    {
      "x": 3,
      "y": 5,
      "z": 4,
      "name": "Wood_Gnarled_Roots"
    },
    {
      "x": 3,
      "y": 6,
      "z": 4,
      "name": "Rock_Quartzite"
    },
    {
      "x": 3,
      "y": 7,
      "z": 4,
      "name": "Rock_Quartzite"
    },
    {
      "x": 3,
      "y": 8,
      "z": 4,
      "name": "Rock_Quartzite"
    },
    {
      "x": 3,
      "y": 0,
      "z": 5,
      "name": "Rock_Stone"
    },
    {
      "x": 3,
      "y": 1,
      "z": 5,
      "name": "Rock_Stone_Cobble"
    },
    {
      "x": 3,
      "y": 2,
      "z": 5,
      "name": "Furniture_Ancient_Wardrobe",
      "rotation": 3
    },
    {
      "x": 3,
      "y": 3,
      "z": 5,
      "name": "Furniture_Ancient_Wardrobe",
      "filler": 1024,
      "rotation": 3
    },
    {
      "x": 3,
      "y": 4,
      "z": 5,
      "name": "Empty"
    },
    {
      "x": 3,
      "y": 5,
      "z": 5,
      "name": "Rock_Quartzite"
    },
    {
      "x": 3,
      "y": 6,
      "z": 5,
      "name": "Rock_Quartzite"
    },
    {
      "x": 3,
      "y": 7,
      "z": 5,
      "name": "Rock_Quartzite"
    },
    {
      "x": 3,
      "y": 8,
      "z": 5,
      "name": "Rock_Quartzite"
    },
    {
      "x": 3,
      "y": 0,
      "z": 6,
      "name": "Rock_Stone"
