{
  "version": 8,
  "blockIdVersion": 8,
  "anchorX": 0,
  "anchorY": 18,
  "anchorZ": 35,
  "blocks": [
    {
      "x": -13,
      "y": 21,
      "z": 25,
      "name": "Rock_Sandstone"
    },
    {
      "x": -13,
      "y": 20,
      "z": 26,
      "name": "Rock_Sandstone"
    },
    {
      "x": -13,
      "y": 21,
      "z": 26,
      "name": "Rock_Sandstone"
    },
    {
      "x": -13,
      "y": 18,
      "z": 27,
      "name": "Rock_Sandstone"
    },
    {
      "x": -13,
      "y": 19,
      "z": 27,
      "name": "Rock_Sandstone"
    },
    {
      "x": -13,
      "y": 20,
      "z": 27,
      "name": "Rock_Sandstone"
    },
    {
      "x": -13,
      "y": 21,
      "z": 27,
      "name": "Rock_Sandstone"
    },
    {
      "x": -13,
      "y": 18,
      "z": 28,
      "name": "Rock_Sandstone"
    },
    {
      "x": -13,
      "y": 19,
      "z": 28,
      "name": "Rock_Sandstone"
    },
    {
      "x": -13,
      "y": 20,
      "z": 28,
      "name": "Rock_Sandstone"
    },
    {
      "x": -13,
      "y": 21,
      "z": 28,
      "name": "Rock_Sandstone"
    },
    {
      "x": -13,
      "y": 18,
      "z": 29,
      "name": "Rock_Sandstone"
    },
    {
      "x": -13,
      "y": 19,
      "z": 29,
      "name": "Rock_Sandstone"
    },
    {
      "x": -13,
      "y": 20,
      "z": 29,
      "name": "Rock_Sandstone"
    },
    {
      "x": -13,
      "y": 21,
      "z": 29,
      "name": "Rock_Sandstone"
    },
    {
      "x": -13,
      "y": 18,
      "z": 30,
      "name": "Rock_Sandstone"
    },
    {
      "x": -13,
      "y": 19,
      "z": 30,
      "name": "Rock_Sandstone"
    },
    {
      "x": -13,
      "y": 20,
      "z": 30,
      "name": "Rock_Sandstone"
    },
    {
      "x": -13,
      "y": 21,
      "z": 30,
      "name": "Rock_Sandstone"
    },
    {
      "x": -13,
      "y": 18,
      "z": 31,
      "name": "Rock_Sandstone"
    },
    {
      "x": -13,
      "y": 19,
      "z": 31,
      "name": "Rock_Sandstone"
    },
    {
      "x": -13,
      "y": 20,
      "z": 31,
      "name": "Rock_Sandstone"
    },
    {
      "x": -13,
      "y": 21,
      "z": 31,
      "name": "Rock_Sandstone"
    },
    {
      "x": -13,
      "y": 18,
      "z": 32,
      "name": "Rock_Sandstone"
    },
    {
      "x": -13,
      "y": 19,
      "z": 32,
      "name": "Rock_Sandstone"
    },
    {
      "x": -13,
      "y": 20,
      "z": 32,
      "name": "Rock_Sandstone"
    },
    {
      "x": -13,
      "y": 21,
      "z": 32,
      "name": "Rock_Sandstone"
    },
    {
      "x": -13,
      "y": 19,
      "z": 33,
      "name": "Rock_Sandstone"
    },
    {
      "x": -13,
      "y": 20,
      "z": 33,
      "name": "Rock_Sandstone"
    },
    {
      "x": -13,
      "y": 21,
      "z": 33,
      "name": "Rock_Sandstone"
    },
    {
      "x": -13,
      "y": 19,
      "z": 34,
      "name": "Rock_Sandstone"
    },
    {
      "x": -13,
      "y": 20,
      "z": 34,
      "name": "Rock_Sandstone"
    },
    {
      "x": -13,
      "y": 21,
      "z": 34,
      "name": "Rock_Sandstone"
    },
    {
      "x": -12,
      "y": 18,
      "z": 25,
      "name": "Rock_Sandstone"
    },
    {
      "x": -12,
      "y": 19,
      "z": 25,
      "name": "Rock_Sandstone"
    },
    {
      "x": -12,
      "y": 20,
      "z": 25,
      "name": "Rock_Sandstone"
    },
    {
      "x": -12,
      "y": 21,
      "z": 25,
      "name": "Rock_Sandstone"
    },
    {
      "x": -12,
      "y": 22,
      "z": 25,
      "name": "Rock_Sandstone"
    },
    {
      "x": -12,
      "y": 18,
      "z": 26,
      "name": "Rock_Sandstone"
    },
    {
      "x": -12,
      "y": 19,
      "z": 26,
      "name": "Rock_Sandstone"
    },
    {
      "x": -12,
      "y": 20,
      "z": 26,
      "name": "Rock_Sandstone"
    },
    {
      "x": -12,
      "y": 21,
      "z": 26,
      "name": "Empty"
    },
    {
      "x": -12,
      "y": 22,
      "z": 26,
      "name": "Rock_Sandstone"
    },
    {
      "x": -12,
      "y": 23,
      "z": 26,
      "name": "Rock_Sandstone"
    },
    {
      "x": -12,
      "y": 18,
      "z": 27,
      "name": "Rock_Sandstone"
    },
    {
      "x": -12,
      "y": 19,
      "z": 27,
      "name": "Deco_Bone_Skulls"
    },
    {
      "x": -12,
      "y": 20,
      "z": 27,
      "name": "Empty"
    },
    {
      "x": -12,
      "y": 21,
      "z": 27,
      "name": "Empty"
    },
    {
      "x": -12,
      "y": 22,
      "z": 27,
      "name": "Rock_Sandstone"
    },
    {
      "x": -12,
      "y": 23,
      "z": 27,
      "name": "Rock_Sandstone"
    },
    {
      "x": -12,
      "y": 18,
      "z": 28,
      "name": "Rock_Sandstone"
    },
    {
      "x": -12,
      "y": 19,
      "z": 28,
      "name": "Deco_Bone_Pile"
    },
    {
      "x": -12,
      "y": 20,
      "z": 28,
      "name": "Empty"
    },
    {
      "x": -12,
      "y": 21,
      "z": 28,
      "name": "Empty"
    },
    {
      "x": -12,
      "y": 22,
      "z": 28,
      "name": "Rock_Sandstone"
    },
    {
      "x": -12,
      "y": 18,
      "z": 29,
      "name": "Rock_Sandstone"
    },
    {
      "x": -12,
      "y": 19,
      "z": 29,
      "name": "Container_Bucket"
    },
    {
      "x": -12,
      "y": 20,
      "z": 29,
      "name": "Empty"
    },
    {
      "x": -12,
      "y": 21,
      "z": 29,
      "name": "Empty"
    },
    {
      "x": -12,
      "y": 22,
      "z": 29,
      "name": "Rock_Sandstone"
    },
    {
      "x": -12,
      "y": 18,
      "z": 30,
      "name": "Rock_Sandstone"
    },
    {
      "x": -12,
      "y": 19,
      "z": 30,
      "name": "Empty"
    },
    {
      "x": -12,
      "y": 20,
      "z": 30,
      "name": "Empty"
    },
    {
      "x": -12,
      "y": 21,
      "z": 30,
      "name": "Empty"
    },
    {
      "x": -12,
      "y": 22,
      "z": 30,
      "name": "Rock_Sandstone"
    },
    {
      "x": -12,
      "y": 18,
      "z": 31,
      "name": "Rock_Sandstone"
    },
    {
      "x": -12,
      "y": 19,
      "z": 31,
      "name": "Empty"
    },
    {
      "x": -12,
      "y": 20,
      "z": 31,
      "name": "Empty"
    },
    {
      "x": -12,
      "y": 21,
      "z": 31,
      "name": "Empty"
    },
    {
      "x": -12,
      "y": 22,
      "z": 31,
      "name": "Rock_Sandstone"
    },
    {
      "x": -12,
      "y": 18,
      "z": 32,
      "name": "Rock_Sandstone"
    },
    {
      "x": -12,
      "y": 19,
      "z": 32,
      "name": "Empty"
    },
    {
      "x": -12,
      "y": 20,
      "z": 32,
      "name": "Empty"
    },
    {
      "x": -12,
      "y": 21,
      "z": 32,
      "name": "Plant_Roots_Cave",
      "rotation": 11
    },
    {
      "x": -12,
      "y": 22,
      "z": 32,
      "name": "Rock_Sandstone"
    },
    {
      "x": -12,
      "y": 18,
      "z": 33,
      "name": "Rock_Sandstone"
    },
    {
      "x": -12,
      "y": 19,
      "z": 33,
      "name": "Rock_Sandstone"
    },
    {
      "x": -12,
      "y": 20,
      "z": 33,
      "name": "Empty"
    },
    {
      "x": -12,
      "y": 21,
      "z": 33,
      "name": "Empty"
    },
    {
      "x": -12,
      "y": 22,
      "z": 33,
      "name": "Rock_Sandstone"
    },
    {
      "x": -12,
      "y": 18,
      "z": 34,
      "name": "Rock_Sandstone"
    },
    {
      "x": -12,
      "y": 19,
      "z": 34,
      "name": "Rock_Sandstone"
    },
    {
      "x": -12,
      "y": 20,
      "z": 34,
      "name": "Rock_Sandstone"
    },
    {
      "x": -12,
      "y": 21,
      "z": 34,
      "name": "Rock_Sandstone"
    },
    {
      "x": -12,
      "y": 22,
      "z": 34,
      "name": "Rock_Sandstone"
    },
    {
      "x": -11,
      "y": 19,
      "z": 24,
      "name": "Rock_Sandstone"
    },
    {
      "x": -11,
      "y": 20,
      "z": 24,
      "name": "Rock_Sandstone"
    },
    {
      "x": -11,
      "y": 21,
      "z": 24,
      "name": "Rock_Sandstone"
    },
    {
      "x": -11,
      "y": 22,
      "z": 24,
      "name": "Rock_Sandstone"
    },
    {
      "x": -11,
      "y": 23,
      "z": 24,
      "name": "Rock_Sandstone"
    },
    {
      "x": -11,
      "y": 18,
      "z": 25,
      "name": "Rock_Sandstone"
    },
    {
      "x": -11,
      "y": 19,
      "z": 25,
      "name": "Rock_Sandstone"
    },
    {
      "x": -11,
      "y": 20,
      "z": 25,
      "name": "Empty"
    },
    {
      "x": -11,
      "y": 21,
      "z": 25,
      "name": "Empty"
    },
    {
      "x": -11,
      "y": 22,
      "z": 25,
      "name": "Empty"
    },
    {
      "x": -11,
      "y": 23,
      "z": 25,
      "name": "Rock_Sandstone"
    },
    {
      "x": -11,
      "y": 24,
      "z": 25,
      "name": "Rock_Sandstone"
    },
    {
      "x": -11,
      "y": 18,
      "z": 26,
      "name": "Rock_Sandstone"
    },
    {
      "x": -11,
      "y": 19,
      "z": 26,
      "name": "Block_Spawner_Block",
      "components": {
        "Components": {
          "BlockSpawner": {
            "BlockSpawnerId": "Zone2_Encounters_Tier3"
          }
        }
      },
      "rotation": 2
    },
    {
      "x": -11,
      "y": 20,
      "z": 26,
      "name": "Empty"
    },
    {
      "x": -11,
      "y": 21,
      "z": 26,
      "name": "Empty"
    },
    {
      "x": -11,
      "y": 22,
      "z": 26,
      "name": "Empty"
    },
    {
      "x": -11,
      "y": 23,
      "z": 26,
      "name": "Empty"
    },
    {
      "x": -11,
      "y": 24,
      "z": 26,
      "name": "Rock_Sandstone"
    },
    {
      "x": -11,
      "y": 18,
      "z": 27,
      "name": "Rock_Sandstone"
    },
    {
      "x": -11,
      "y": 19,
      "z": 27,
      "name": "Empty"
    },
    {
      "x": -11,
      "y": 20,
      "z": 27,
      "name": "Empty"
    },
    {
      "x": -11,
      "y": 21,
      "z": 27,
      "name": "Empty"
    },
    {
      "x": -11,
      "y": 22,
      "z": 27,
      "name": "Empty"
    },
    {
      "x": -11,
      "y": 23,
      "z": 27,
      "name": "Rock_Sandstone"
    },
    {
      "x": -11,
      "y": 24,
      "z": 27,
      "name": "Rock_Sandstone"
    },
    {
      "x": -11,
      "y": 18,
      "z": 28,
      "name": "Rock_Sandstone"
    },
    {
      "x": -11,
      "y": 19,
      "z": 28,
      "name": "Empty"
    },
    {
      "x": -11,
      "y": 20,
      "z": 28,
      "name": "Empty"
    },
    {
      "x": -11,
      "y": 21,
      "z": 28,
      "name": "Empty"
    },
    {
      "x": -11,
      "y": 22,
      "z": 28,
      "name": "Plant_Roots_Cave_Small",
      "rotation": 8
    },
    {
      "x": -11,
      "y": 23,
      "z": 28,
      "name": "Rock_Sandstone"
    },
    {
      "x": -11,
      "y": 18,
      "z": 29,
      "name": "Rock_Sandstone"
    },
    {
      "x": -11,
      "y": 19,
      "z": 29,
      "name": "Empty"
    },
    {
      "x": -11,
      "y": 20,
      "z": 29,
      "name": "Empty"
    },
    {
      "x": -11,
      "y": 21,
      "z": 29,
      "name": "Empty"
    },
    {
      "x": -11,
      "y": 22,
      "z": 29,
      "name": "Rock_Sandstone"
    },
    {
      "x": -11,
      "y": 23,
      "z": 29,
      "name": "Rock_Sandstone"
    },
    {
      "x": -11,
      "y": 18,
      "z": 30,
      "name": "Rock_Sandstone"
    },
    {
      "x": -11,
      "y": 19,
      "z": 30,
      "name": "Empty"
    },
    {
      "x": -11,
      "y": 20,
      "z": 30,
      "name": "Empty"
    },
    {
      "x": -11,
      "y": 21,
      "z": 30,
      "name": "Empty"
    },
    {
      "x": -11,
      "y": 22,
      "z": 30,
      "name": "Rock_Sandstone"
    },
    {
      "x": -11,
      "y": 18,
      "z": 31,
      "name": "Rock_Sandstone"
    },
    {
      "x": -11,
      "y": 19,
      "z": 31,
      "name": "Empty"
    },
    {
      "x": -11,
      "y": 20,
      "z": 31,
      "name": "Empty"
    },
    {
      "x": -11,
      "y": 21,
      "z": 31,
      "name": "Plant_Roots_Cave_Small",
      "rotation": 8
    },
    {
      "x": -11,
      "y": 22,
      "z": 31,
      "name": "Rock_Sandstone"
    },
    {
      "x": -11,
      "y": 18,
      "z": 32,
      "name": "Rock_Sandstone"
    },
    {
      "x": -11,
      "y": 19,
      "z": 32,
      "name": "Empty"
    },
    {
      "x": -11,
      "y": 20,
      "z": 32,
      "name": "Empty"
    },
    {
      "x": -11,
      "y": 21,
      "z": 32,
      "name": "Empty"
    },
    {
      "x": -11,
      "y": 22,
      "z": 32,
      "name": "Rock_Sandstone"
    },
    {
      "x": -11,
      "y": 18,
      "z": 33,
      "name": "Rock_Sandstone"
    },
    {
      "x": -11,
      "y": 19,
      "z": 33,
      "name": "Empty"
    },
    {
      "x": -11,
      "y": 20,
      "z": 33,
      "name": "Empty"
    },
    {
      "x": -11,
      "y": 21,
      "z": 33,
      "name": "Empty"
    },
    {
      "x": -11,
      "y": 22,
      "z": 33,
      "name": "Rock_Sandstone"
    },
    {
      "x": -11,
      "y": 18,
      "z": 34,
      "name": "Rock_Sandstone"
    },
    {
      "x": -11,
      "y": 19,
      "z": 34,
      "name": "Rock_Sandstone"
    },
    {
      "x": -11,
      "y": 20,
      "z": 34,
      "name": "Rock_Sandstone"
    },
    {
      "x": -11,
      "y": 21,
      "z": 34,
      "name": "Rock_Sandstone"
    },
    {
      "x": -11,
      "y": 22,
      "z": 34,
      "name": "Rock_Sandstone"
    },
    {
      "x": -10,
      "y": 18,
      "z": 22,
      "name": "Rock_Sandstone"
    },
    {
      "x": -10,
      "y": 19,
      "z": 22,
      "name": "Rock_Sandstone"
    },
    {
      "x": -10,
      "y": 20,
      "z": 22,
      "name": "Rock_Sandstone"
    },
    {
      "x": -10,
      "y": 21,
      "z": 22,
      "name": "Rock_Sandstone"
    },
    {
      "x": -10,
      "y": 22,
      "z": 22,
      "name": "Rock_Sandstone"
    },
    {
      "x": -10,
      "y": 23,
      "z": 22,
      "name": "Rock_Sandstone"
    },
    {
      "x": -10,
      "y": 24,
      "z": 22,
      "name": "Rock_Sandstone"
    },
    {
      "x": -10,
      "y": 25,
      "z": 22,
      "name": "Rock_Sandstone"
    },
    {
      "x": -10,
      "y": 18,
      "z": 23,
      "name": "Rock_Sandstone"
    },
    {
      "x": -10,
      "y": 19,
      "z": 23,
      "name": "Rock_Sandstone"
    },
    {
      "x": -10,
      "y": 20,
      "z": 23,
      "name": "Rock_Sandstone"
    },
    {
      "x": -10,
      "y": 21,
      "z": 23,
      "name": "Rock_Sandstone"
    },
    {
      "x": -10,
      "y": 22,
      "z": 23,
      "name": "Rock_Sandstone"
    },
    {
      "x": -10,
      "y": 23,
      "z": 23,
      "name": "Rock_Sandstone"
    },
    {
      "x": -10,
      "y": 24,
      "z": 23,
      "name": "Rock_Sandstone"
    },
    {
      "x": -10,
      "y": 25,
      "z": 23,
      "name": "Rock_Sandstone"
    },
    {
      "x": -10,
      "y": 26,
      "z": 23,
      "name": "Rock_Sandstone"
    },
    {
      "x": -10,
      "y": 27,
      "z": 23,
      "name": "Rock_Sandstone"
    },
    {
      "x": -10,
      "y": 18,
      "z": 24,
      "name": "Rock_Sandstone"
    },
    {
      "x": -10,
      "y": 19,
      "z": 24,
      "name": "Rock_Sandstone"
    },
    {
      "x": -10,
      "y": 20,
      "z": 24,
      "name": "Rock_Sandstone"
    },
    {
      "x": -10,
      "y": 21,
      "z": 24,
      "name": "Rock_Sandstone"
    },
    {
      "x": -10,
      "y": 22,
      "z": 24,
      "name": "Rock_Sandstone"
    },
    {
      "x": -10,
      "y": 23,
      "z": 24,
      "name": "Rock_Sandstone"
    },
    {
      "x": -10,
      "y": 24,
      "z": 24,
      "name": "Rock_Sandstone"
    },
    {
      "x": -10,
      "y": 25,
      "z": 24,
      "name": "Rock_Sandstone"
    },
    {
      "x": -10,
      "y": 26,
      "z": 24,
      "name": "Rock_Sandstone"
    },
    {
      "x": -10,
      "y": 27,
      "z": 24,
      "name": "Rock_Sandstone"
    },
    {
      "x": -10,
      "y": 18,
      "z": 25,
      "name": "Rock_Sandstone"
    },
    {
      "x": -10,
      "y": 19,
      "z": 25,
      "name": "Rock_Sandstone"
    },
    {
      "x": -10,
      "y": 20,
      "z": 25,
      "name": "Empty"
    },
    {
      "x": -10,
      "y": 21,
      "z": 25,
      "name": "Empty"
    },
    {
      "x": -10,
      "y": 22,
      "z": 25,
      "name": "Rock_Sandstone"
    },
    {
      "x": -10,
      "y": 23,
      "z": 25,
      "name": "Rock_Sandstone"
    },
    {
      "x": -10,
      "y": 24,
      "z": 25,
      "name": "Rock_Sandstone"
    },
    {
      "x": -10,
      "y": 25,
      "z": 25,
      "name": "Rock_Sandstone"
    },
    {
      "x": -10,
      "y": 26,
      "z": 25,
      "name": "Rock_Sandstone"
    },
    {
      "x": -10,
      "y": 27,
      "z": 25,
      "name": "Rock_Sandstone"
    },
    {
      "x": -10,
      "y": 28,
      "z": 25,
      "name": "Rock_Sandstone"
    },
    {
      "x": -10,
      "y": 18,
      "z": 26,
      "name": "Rock_Sandstone"
    },
    {
      "x": -10,
      "y": 19,
      "z": 26,
      "name": "Furniture_Village_Planter"
    },
    {
      "x": -10,
      "y": 20,
      "z": 26,
      "name": "Furniture_Crude_Brazier"
    },
    {
      "x": -10,
      "y": 21,
      "z": 26,
      "name": "Empty"
    },
    {
      "x": -10,
      "y": 22,
      "z": 26,
      "name": "Empty"
    },
    {
      "x": -10,
      "y": 23,
      "z": 26,
      "name": "Plant_Roots_Cave",
      "rotation": 10
    },
    {
      "x": -10,
      "y": 24,
      "z": 26,
      "name": "Rock_Sandstone"
    },
    {
      "x": -10,
      "y": 25,
      "z": 26,
      "name": "Rock_Sandstone"
    },
    {
      "x": -10,
      "y": 26,
      "z": 26,
      "name": "Rock_Sandstone"
    },
    {
      "x": -10,
      "y": 27,
      "z": 26,
      "name": "Rock_Sandstone"
    },
    {
      "x": -10,
      "y": 28,
      "z": 26,
      "name": "Rock_Sandstone"
    },
    {
      "x": -10,
      "y": 18,
      "z": 27,
      "name": "Rock_Sandstone"
    },
    {
      "x": -10,
      "y": 19,
      "z": 27,
      "name": "Empty"
    },
    {
      "x": -10,
      "y": 20,
      "z": 27,
      "name": "Empty"
    },
    {
      "x": -10,
      "y": 21,
      "z": 27,
      "name": "Empty"
    },
    {
      "x": -10,
      "y": 22,
      "z": 27,
      "name": "Empty"
    },
    {
      "x": -10,
      "y": 23,
      "z": 27,
      "name": "Plant_Roots_Cave_Small",
      "rotation": 8
    },
    {
      "x": -10,
      "y": 24,
      "z": 27,
      "name": "Rock_Sandstone"
    },
    {
      "x": -10,
      "y": 25,
      "z": 27,
      "name": "Rock_Sandstone"
    },
    {
      "x": -10,
      "y": 26,
      "z": 27,
      "name": "Rock_Sandstone"
    },
    {
      "x": -10,
      "y": 27,
      "z": 27,
      "name": "Rock_Sandstone"
    },
    {
      "x": -10,
      "y": 28,
      "z": 27,
      "name": "Rock_Sandstone"
    },
    {
      "x": -10,
      "y": 18,
      "z": 28,
      "name": "Rock_Sandstone"
    },
    {
      "x": -10,
      "y": 19,
      "z": 28,
      "name": "Empty"
    },
    {
      "x": -10,
      "y": 20,
      "z": 28,
      "name": "Empty"
    },
    {
      "x": -10,
      "y": 21,
      "z": 28,
      "name": "Empty"
    },
    {
      "x": -10,
      "y": 22,
      "z": 28,
      "name": "Empty"
    },
    {
      "x": -10,
      "y": 23,
      "z": 28,
      "name": "Rock_Sandstone"
    },
    {
      "x": -10,
      "y": 24,
      "z": 28,
      "name": "Rock_Sandstone"
    },
    {
      "x": -10,
      "y": 25,
      "z": 28,
      "name": "Rock_Sandstone"
    },
    {
      "x": -10,
      "y": 26,
      "z": 28,
      "name": "Rock_Sandstone"
    },
    {
      "x": -10,
      "y": 27,
      "z": 28,
      "name": "Rock_Sandstone"
    },
    {
      "x": -10,
      "y": 28,
      "z": 28,
      "name": "Rock_Sandstone"
    },
    {
      "x": -10,
      "y": 18,
      "z": 29,
      "name": "Rock_Sandstone"
    },
    {
      "x": -10,
      "y": 19,
      "z": 29,
      "name": "Deco_Bone_Pile"
    },
    {
      "x": -10,
      "y": 20,
      "z": 29,
      "name": "Empty"
    },
    {
      "x": -10,
      "y": 21,
      "z": 29,
      "name": "Empty"
    },
    {
      "x": -10,
      "y": 22,
      "z": 29,
      "name": "Rock_Sandstone"
    },
    {
      "x": -10,
      "y": 23,
      "z": 29,
      "name": "Rock_Sandstone"
    },
    {
      "x": -10,
      "y": 24,
      "z": 29,
      "name": "Rock_Sandstone"
    },
    {
      "x": -10,
      "y": 25,
      "z": 29,
      "name": "Rock_Sandstone"
    },
    {
      "x": -10,
      "y": 26,
      "z": 29,
      "name": "Rock_Sandstone"
    },
    {
      "x": -10,
      "y": 27,
      "z": 29,
      "name": "Rock_Sandstone"
    },
    {
      "x": -10,
      "y": 28,
      "z": 29,
      "name": "Rock_Sandstone"
    },
    {
      "x": -10,
      "y": 18,
      "z": 30,
      "name": "Rock_Sandstone"
    },
    {
      "x": -10,
      "y": 19,
      "z": 30,
      "name": "Deco_Bone_Skulls"
    },
    {
      "x": -10,
      "y": 20,
      "z": 30,
      "name": "Empty"
    },
    {
      "x": -10,
      "y": 21,
      "z": 30,
      "name": "Empty"
    },
    {
      "x": -10,
      "y": 22,
      "z": 30,
      "name": "Rock_Sandstone"
    },
    {
      "x": -10,
      "y": 23,
      "z": 30,
      "name": "Rock_Sandstone"
    },
    {
      "x": -10,
      "y": 24,
      "z": 30,
      "name": "Rock_Sandstone"
    },
    {
      "x": -10,
      "y": 25,
      "z": 30,
      "name": "Rock_Sandstone"
    },
    {
      "x": -10,
      "y": 26,
      "z": 30,
      "name": "Rock_Sandstone"
    },
    {
      "x": -10,
      "y": 27,
      "z": 30,
      "name": "Rock_Sandstone"
    },
    {
      "x": -10,
      "y": 28,
      "z": 30,
      "name": "Rock_Sandstone"
    },
    {
      "x": -10,
      "y": 18,
      "z": 31,
      "name": "Rock_Sandstone"
    },
    {
      "x": -10,
      "y": 19,
      "z": 31,
      "name": "Empty"
    },
    {
      "x": -10,
      "y": 20,
      "z": 31,
      "name": "Empty"
    },
    {
      "x": -10,
      "y": 21,
      "z": 31,
      "name": "Empty"
    },
    {
      "x": -10,
      "y": 22,
      "z": 31,
      "name": "Rock_Sandstone"
    },
    {
      "x": -10,
      "y": 23,
      "z": 31,
      "name": "Rock_Sandstone"
    },
    {
      "x": -10,
      "y": 24,
      "z": 31,
      "name": "Rock_Sandstone"
    },
    {
      "x": -10,
      "y": 25,
      "z": 31,
      "name": "Rock_Sandstone"
    },
    {
      "x": -10,
      "y": 26,
      "z": 31,
      "name": "Rock_Sandstone"
    },
    {
      "x": -10,
      "y": 27,
      "z": 31,
      "name": "Rock_Sandstone"
    },
    {
      "x": -10,
      "y": 28,
      "z": 31,
      "name": "Rock_Sandstone"
    },
    {
      "x": -10,
      "y": 18,
      "z": 32,
      "name": "Rock_Sandstone"
    },
    {
      "x": -10,
      "y": 19,
      "z": 32,
      "name": "Deco_Bone_Skulls"
    },
    {
      "x": -10,
      "y": 20,
      "z": 32,
      "name": "Empty"
    },
    {
      "x": -10,
      "y": 21,
      "z": 32,
      "name": "Empty"
    },
    {
      "x": -10,
      "y": 22,
      "z": 32,
      "name": "Rock_Sandstone"
    },
    {
      "x": -10,
      "y": 23,
      "z": 32,
      "name": "Rock_Sandstone"
    },
    {
      "x": -10,
      "y": 24,
      "z": 32,
      "name": "Rock_Sandstone"
    },
    {
      "x": -10,
      "y": 25,
      "z": 32,
      "name": "Rock_Sandstone"
    },
    {
      "x": -10,
      "y": 26,
      "z": 32,
      "name": "Rock_Sandstone"
    },
    {
      "x": -10,
      "y": 27,
      "z": 32,
      "name": "Rock_Sandstone"
    },
    {
      "x": -10,
      "y": 18,
      "z": 33,
      "name": "Rock_Sandstone"
    },
    {
      "x": -10,
      "y": 19,
      "z": 33,
      "name": "Empty"
    },
    {
      "x": -10,
      "y": 20,
      "z": 33,
      "name": "Empty"
    },
    {
      "x": -10,
      "y": 21,
      "z": 33,
      "name": "Rock_Sandstone"
    },
    {
      "x": -10,
      "y": 22,
      "z": 33,
      "name": "Rock_Sandstone"
    },
    {
      "x": -10,
      "y": 23,
      "z": 33,
      "name": "Rock_Sandstone"
    },
    {
      "x": -10,
      "y": 24,
      "z": 33,
      "name": "Rock_Sandstone"
    },
    {
      "x": -10,
      "y": 25,
      "z": 33,
      "name": "Rock_Sandstone"
    },
    {
      "x": -10,
      "y": 26,
      "z": 33,
      "name": "Rock_Sandstone"
    },
    {
      "x": -10,
      "y": 27,
      "z": 33,
      "name": "Rock_Sandstone"
    },
    {
      "x": -10,
      "y": 18,
      "z": 34,
      "name": "Rock_Sandstone"
    },
    {
      "x": -10,
      "y": 19,
      "z": 34,
      "name": "Empty"
    },
    {
      "x": -10,
      "y": 20,
      "z": 34,
      "name": "Empty"
    },
    {
      "x": -10,
      "y": 21,
      "z": 34,
      "name": "Rock_Sandstone"
    },
    {
      "x": -10,
      "y": 22,
      "z": 34,
      "name": "Rock_Sandstone"
    },
    {
      "x": -10,
      "y": 23,
      "z": 34,
      "name": "Rock_Sandstone"
    },
    {
      "x": -10,
      "y": 24,
      "z": 34,
      "name": "Rock_Sandstone"
    },
    {
      "x": -10,
      "y": 25,
      "z": 34,
      "name": "Rock_Sandstone"
    },
    {
      "x": -10,
      "y": 26,
      "z": 34,
      "name": "Rock_Sandstone"
    },
    {
      "x": -10,
      "y": 18,
      "z": 35,
      "name": "Rock_Sandstone"
    },
    {
      "x": -10,
      "y": 19,
      "z": 35,
      "name": "Rock_Sandstone"
    },
    {
      "x": -10,
      "y": 20,
      "z": 35,
      "name": "Rock_Sandstone"
    },
    {
      "x": -9,
      "y": 20,
      "z": 21,
      "name": "Rock_Sandstone"
    },
    {
      "x": -9,
      "y": 21,
      "z": 21,
      "name": "Rock_Sandstone"
    },
    {
      "x": -9,
      "y": 22,
      "z": 21,
      "name": "Rock_Sandstone"
    },
    {
      "x": -9,
      "y": 23,
      "z": 21,
      "name": "Rock_Sandstone"
    },
    {
      "x": -9,
      "y": 24,
      "z": 21,
      "name": "Rock_Sandstone"
    },
    {
      "x": -9,
      "y": 25,
      "z": 21,
      "name": "Rock_Sandstone"
    },
    {
      "x": -9,
      "y": 26,
      "z": 21,
      "name": "Rock_Sandstone"
    },
    {
      "x": -9,
      "y": 27,
      "z": 21,
      "name": "Rock_Sandstone"
    },
    {
      "x": -9,
      "y": 17,
      "z": 22,
      "name": "Rock_Sandstone"
    },
    {
      "x": -9,
      "y": 18,
      "z": 22,
      "name": "Rock_Sandstone"
    },
    {
      "x": -9,
      "y": 19,
      "z": 22,
      "name": "Rock_Sandstone"
    },
    {
      "x": -9,
      "y": 20,
      "z": 22,
      "name": "Rock_Sandstone"
    },
    {
      "x": -9,
      "y": 21,
      "z": 22,
      "name": "Rock_Sandstone"
    },
    {
      "x": -9,
      "y": 22,
      "z": 22,
      "name": "Rock_Sandstone"
    },
    {
      "x": -9,
      "y": 23,
      "z": 22,
      "name": "Rock_Sandstone"
    },
    {
      "x": -9,
      "y": 24,
      "z": 22,
      "name": "Rock_Sandstone"
    },
    {
      "x": -9,
      "y": 25,
      "z": 22,
      "name": "Rock_Sandstone"
    },
    {
      "x": -9,
      "y": 26,
      "z": 22,
      "name": "Rock_Sandstone"
    },
    {
      "x": -9,
      "y": 27,
      "z": 22,
      "name": "Rock_Sandstone"
    },
    {
      "x": -9,
      "y": 17,
      "z": 23,
      "name": "Rock_Sandstone"
    },
    {
      "x": -9,
      "y": 18,
      "z": 23,
      "name": "Rock_Sandstone_Brick"
    },
    {
      "x": -9,
      "y": 19,
      "z": 23,
      "name": "Rock_Sandstone"
    },
    {
      "x": -9,
      "y": 20,
      "z": 23,
      "name": "Rock_Sandstone"
    },
    {
      "x": -9,
      "y": 21,
      "z": 23,
      "name": "Rock_Sandstone"
    },
    {
      "x": -9,
      "y": 22,
      "z": 23,
      "name": "Rock_Sandstone"
    },
    {
      "x": -9,
      "y": 23,
      "z": 23,
      "name": "Rock_Sandstone"
    },
    {
      "x": -9,
      "y": 24,
      "z": 23,
      "name": "Rock_Sandstone"
    },
    {
      "x": -9,
      "y": 25,
      "z": 23,
      "name": "Rock_Sandstone"
    },
    {
      "x": -9,
      "y": 26,
      "z": 23,
      "name": "Rock_Sandstone"
    },
    {
      "x": -9,
      "y": 27,
      "z": 23,
      "name": "Rock_Sandstone"
    },
    {
      "x": -9,
      "y": 28,
      "z": 23,
      "name": "Rock_Sandstone"
    },
    {
      "x": -9,
      "y": 17,
      "z": 24,
      "name": "Rock_Sandstone"
    },
    {
      "x": -9,
      "y": 18,
      "z": 24,
      "name": "Rock_Sandstone_Brick"
    },
    {
      "x": -9,
      "y": 19,
      "z": 24,
      "name": "Rock_Sandstone"
    },
    {
      "x": -9,
      "y": 20,
      "z": 24,
      "name": "Rock_Sandstone"
    },
    {
      "x": -9,
      "y": 21,
      "z": 24,
      "name": "Rock_Sandstone"
    },
    {
      "x": -9,
      "y": 22,
      "z": 24,
      "name": "Rock_Sandstone"
    },
    {
      "x": -9,
      "y": 23,
      "z": 24,
      "name": "Rock_Sandstone"
    },
    {
      "x": -9,
      "y": 24,
      "z": 24,
      "name": "Rock_Sandstone"
    },
    {
      "x": -9,
      "y": 25,
      "z": 24,
      "name": "Rock_Sandstone"
    },
    {
      "x": -9,
      "y": 26,
      "z": 24,
      "name": "Rock_Sandstone"
    },
    {
      "x": -9,
      "y": 27,
      "z": 24,
      "name": "Rock_Sandstone"
    },
    {
      "x": -9,
      "y": 28,
      "z": 24,
      "name": "Rock_Sandstone"
    },
    {
      "x": -9,
      "y": 17,
      "z": 25,
      "name": "Rock_Sandstone"
    },
    {
      "x": -9,
      "y": 18,
      "z": 25,
      "name": "Rock_Sandstone_Brick"
    },
    {
      "x": -9,
      "y": 19,
      "z": 25,
      "name": "Rock_Sandstone"
    },
    {
      "x": -9,
      "y": 20,
      "z": 25,
      "name": "Rock_Sandstone"
    },
    {
      "x": -9,
      "y": 21,
      "z": 25,
      "name": "Rock_Sandstone"
    },
    {
      "x": -9,
      "y": 22,
      "z": 25,
      "name": "Rock_Sandstone"
    },
    {
      "x": -9,
      "y": 23,
      "z": 25,
      "name": "Furniture_Village_Bookcase",
      "rotation": 1
    },
    {
      "x": -9,
      "y": 24,
      "z": 25,
      "name": "Furniture_Village_Bookcase",
      "rotation": 1
    },
    {
      "x": -9,
      "y": 25,
      "z": 25,
      "name": "Rock_Sandstone"
    },
    {
      "x": -9,
      "y": 26,
      "z": 25,
      "name": "Rock_Sandstone"
    },
    {
      "x": -9,
      "y": 27,
      "z": 25,
      "name": "Rock_Sandstone"
    },
    {
      "x": -9,
      "y": 28,
      "z": 25,
      "name": "Rock_Sandstone"
    },
    {
      "x": -9,
      "y": 17,
      "z": 26,
      "name": "Rock_Sandstone"
    },
    {
      "x": -9,
      "y": 18,
      "z": 26,
      "name": "Rock_Sandstone"
    },
    {
      "x": -9,
      "y": 19,
      "z": 26,
      "name": "Rock_Sandstone"
    },
    {
      "x": -9,
      "y": 20,
      "z": 26,
      "name": "Furniture_Village_Bookcase",
      "rotation": 1
    },
    {
      "x": -9,
      "y": 21,
      "z": 26,
      "name": "Furniture_Village_Bookcase",
      "rotation": 1
    },
    {
      "x": -9,
      "y": 22,
      "z": 26,
      "name": "Furniture_Village_Bookcase",
      "rotation": 1
    },
    {
      "x": -9,
      "y": 23,
      "z": 26,
      "name": "Furniture_Village_Bookcase",
      "rotation": 1
    },
    {
      "x": -9,
      "y": 24,
      "z": 26,
      "name": "Furniture_Village_Bookcase",
      "rotation": 1
    },
    {
      "x": -9,
      "y": 25,
      "z": 26,
      "name": "Rock_Sandstone"
    },
    {
      "x": -9,
      "y": 26,
      "z": 26,
      "name": "Rock_Sandstone"
    },
    {
      "x": -9,
      "y": 27,
      "z": 26,
      "name": "Rock_Sandstone"
    },
    {
      "x": -9,
      "y": 28,
      "z": 26,
      "name": "Rock_Sandstone"
    },
    {
      "x": -9,
      "y": 17,
      "z": 27,
      "name": "Rock_Sandstone"
    },
    {
      "x": -9,
      "y": 18,
      "z": 27,
      "name": "Rock_Sandstone"
    },
    {
      "x": -9,
      "y": 19,
      "z": 27,
      "name": "Rock_Sandstone"
    },
    {
      "x": -9,
      "y": 20,
      "z": 27,
      "name": "Furniture_Village_Bookcase",
      "rotation": 1
    },
    {
      "x": -9,
      "y": 21,
      "z": 27,
      "name": "Furniture_Village_Bookcase",
      "rotation": 1
    },
    {
      "x": -9,
      "y": 22,
      "z": 27,
      "name": "Furniture_Village_Bookcase",
      "rotation": 1
    },
    {
      "x": -9,
      "y": 23,
      "z": 27,
      "name": "Furniture_Village_Bookcase",
      "rotation": 1
    },
    {
      "x": -9,
      "y": 24,
      "z": 27,
      "name": "Furniture_Village_Bookcase",
      "rotation": 1
    },
    {
      "x": -9,
      "y": 25,
      "z": 27,
      "name": "Furniture_Village_Bookcase",
      "rotation": 1
    },
    {
      "x": -9,
      "y": 26,
      "z": 27,
      "name": "Rock_Sandstone"
    },
    {
      "x": -9,
      "y": 27,
      "z": 27,
      "name": "Rock_Sandstone"
    },
    {
      "x": -9,
      "y": 28,
      "z": 27,
      "name": "Rock_Sandstone"
    },
    {
      "x": -9,
      "y": 17,
      "z": 28,
      "name": "Rock_Sandstone"
    },
    {
      "x": -9,
      "y": 18,
      "z": 28,
      "name": "Soil_Gravel_Sand_White"
    },
    {
      "x": -9,
      "y": 19,
      "z": 28,
      "name": "Furniture_Village_Bookcase",
      "rotation": 1
    },
    {
      "x": -9,
      "y": 20,
      "z": 28,
      "name": "Furniture_Village_Bookcase",
      "rotation": 1
    },
    {
      "x": -9,
      "y": 21,
      "z": 28,
      "name": "Furniture_Village_Bookcase",
      "rotation": 1
    },
    {
      "x": -9,
      "y": 22,
      "z": 28,
      "name": "Furniture_Village_Bookcase",
      "rotation": 1
    },
    {
      "x": -9,
      "y": 23,
      "z": 28,
      "name": "Furniture_Village_Bookcase",
      "rotation": 1
    },
    {
      "x": -9,
      "y": 24,
      "z": 28,
      "name": "Furniture_Village_Bookcase",
      "rotation": 1
    },
    {
      "x": -9,
      "y": 25,
      "z": 28,
      "name": "Furniture_Village_Bookcase",
      "rotation": 1
    },
    {
      "x": -9,
      "y": 26,
      "z": 28,
      "name": "Furniture_Village_Bookcase",
      "rotation": 1
    },
    {
      "x": -9,
      "y": 27,
      "z": 28,
      "name": "Rock_Sandstone"
    },
    {
      "x": -9,
      "y": 28,
      "z": 28,
      "name": "Rock_Sandstone"
    },
    {
      "x": -9,
      "y": 17,
      "z": 29,
      "name": "Rock_Sandstone"
    },
    {
      "x": -9,
      "y": 18,
      "z": 29,
      "name": "Rock_Sandstone"
    },
    {
      "x": -9,
      "y": 19,
      "z": 29,
      "name": "Rock_Sandstone"
    },
    {
      "x": -9,
      "y": 20,
      "z": 29,
      "name": "Rock_Sandstone"
    },
    {
      "x": -9,
      "y": 21,
      "z": 29,
      "name": "Furniture_Village_Bookcase",
      "rotation": 1
    },
    {
      "x": -9,
      "y": 22,
      "z": 29,
      "name": "Furniture_Village_Bookcase",
      "rotation": 1
    },
    {
      "x": -9,
      "y": 23,
      "z": 29,
      "name": "Furniture_Village_Bookcase",
      "rotation": 1
    },
    {
      "x": -9,
      "y": 24,
      "z": 29,
      "name": "Furniture_Village_Bookcase",
      "rotation": 1
    },
    {
      "x": -9,
      "y": 25,
      "z": 29,
      "name": "Furniture_Village_Bookcase",
      "rotation": 1
    },
    {
      "x": -9,
      "y": 26,
      "z": 29,
      "name": "Rock_Sandstone"
    },
    {
      "x": -9,
      "y": 27,
      "z": 29,
      "name": "Rock_Sandstone"
    },
    {
      "x": -9,
      "y": 28,
      "z": 29,
      "name": "Rock_Sandstone"
    },
    {
      "x": -9,
      "y": 17,
      "z": 30,
      "name": "Rock_Sandstone"
    },
    {
      "x": -9,
      "y": 18,
      "z": 30,
      "name": "Rock_Sandstone"
    },
    {
      "x": -9,
      "y": 19,
      "z": 30,
      "name": "Rock_Sandstone"
    },
    {
      "x": -9,
      "y": 20,
      "z": 30,
      "name": "Rock_Sandstone"
    },
    {
      "x": -9,
      "y": 21,
      "z": 30,
      "name": "Furniture_Village_Bookcase",
      "rotation": 1
    },
    {
      "x": -9,
      "y": 22,
      "z": 30,
      "name": "Furniture_Village_Bookcase",
      "rotation": 1
    },
    {
      "x": -9,
      "y": 23,
      "z": 30,
      "name": "Furniture_Village_Bookcase",
      "rotation": 1
    },
    {
      "x": -9,
      "y": 24,
      "z": 30,
      "name": "Furniture_Village_Bookcase",
      "rotation": 1
    },
    {
      "x": -9,
      "y": 25,
      "z": 30,
      "name": "Furniture_Village_Bookcase",
      "rotation": 1
    },
    {
      "x": -9,
      "y": 26,
      "z": 30,
      "name": "Rock_Sandstone"
    },
    {
      "x": -9,
      "y": 27,
      "z": 30,
      "name": "Rock_Sandstone"
    },
    {
      "x": -9,
      "y": 28,
      "z": 30,
      "name": "Rock_Sandstone"
    },
    {
      "x": -9,
      "y": 17,
      "z": 31,
      "name": "Rock_Sandstone"
    },
    {
      "x": -9,
      "y": 18,
      "z": 31,
      "name": "Rock_Sandstone"
    },
    {
      "x": -9,
      "y": 19,
      "z": 31,
      "name": "Rock_Sandstone"
    },
    {
      "x": -9,
      "y": 20,
      "z": 31,
      "name": "Rock_Sandstone"
    },
    {
      "x": -9,
      "y": 21,
      "z": 31,
      "name": "Rock_Sandstone"
    },
    {
      "x": -9,
      "y": 22,
      "z": 31,
      "name": "Rock_Sandstone"
    },
    {
      "x": -9,
      "y": 23,
      "z": 31,
      "name": "Rock_Sandstone"
    },
    {
      "x": -9,
      "y": 24,
      "z": 31,
      "name": "Furniture_Village_Bookcase",
      "rotation": 1
    },
    {
      "x": -9,
      "y": 25,
      "z": 31,
      "name": "Rock_Sandstone"
    },
    {
      "x": -9,
      "y": 26,
      "z": 31,
      "name": "Rock_Sandstone"
    },
    {
      "x": -9,
      "y": 27,
      "z": 31,
      "name": "Rock_Sandstone"
    },
    {
      "x": -9,
      "y": 28,
      "z": 31,
      "name": "Rock_Sandstone"
    },
    {
      "x": -9,
      "y": 17,
      "z": 32,
      "name": "Rock_Sandstone"
    },
    {
      "x": -9,
      "y": 18,
      "z": 32,
      "name": "Rock_Sandstone"
    },
    {
      "x": -9,
      "y": 19,
      "z": 32,
      "name": "Deco_Bone_Pile"
    },
    {
      "x": -9,
      "y": 20,
      "z": 32,
      "name": "Empty"
    },
    {
      "x": -9,
      "y": 21,
      "z": 32,
      "name": "Empty"
    },
    {
      "x": -9,
      "y": 22,
      "z": 32,
      "name": "Rock_Sandstone"
    },
    {
      "x": -9,
      "y": 23,
      "z": 32,
      "name": "Rock_Sandstone"
    },
    {
      "x": -9,
      "y": 24,
      "z": 32,
      "name": "Rock_Sandstone"
    },
    {
      "x": -9,
      "y": 25,
      "z": 32,
      "name": "Rock_Sandstone"
    },
    {
      "x": -9,
      "y": 26,
      "z": 32,
      "name": "Rock_Sandstone"
    },
    {
      "x": -9,
      "y": 27,
      "z": 32,
      "name": "Rock_Sandstone"
    },
    {
      "x": -9,
      "y": 28,
      "z": 32,
      "name": "Rock_Sandstone"
    },
    {
      "x": -9,
      "y": 17,
      "z": 33,
      "name": "Rock_Sandstone"
    },
    {
      "x": -9,
      "y": 18,
      "z": 33,
      "name": "Rock_Sandstone"
    },
    {
      "x": -9,
      "y": 19,
      "z": 33,
      "name": "Empty"
    },
    {
      "x": -9,
      "y": 20,
      "z": 33,
      "name": "Empty"
    },
    {
      "x": -9,
      "y": 21,
      "z": 33,
      "name": "Rock_Sandstone"
    },
    {
      "x": -9,
      "y": 22,
      "z": 33,
      "name": "Rock_Sandstone"
    },
    {
      "x": -9,
      "y": 23,
      "z": 33,
      "name": "Rock_Sandstone"
    },
    {
      "x": -9,
      "y": 24,
      "z": 33,
      "name": "Rock_Sandstone"
    },
    {
      "x": -9,
      "y": 25,
      "z": 33,
      "name": "Rock_Sandstone"
    },
    {
      "x": -9,
      "y": 26,
      "z": 33,
      "name": "Rock_Sandstone"
    },
    {
      "x": -9,
      "y": 27,
      "z": 33,
      "name": "Rock_Sandstone"
    },
    {
      "x": -9,
      "y": 28,
      "z": 33,
      "name": "Rock_Sandstone"
    },
    {
      "x": -9,
      "y": 17,
      "z": 34,
      "name": "Rock_Sandstone"
    },
    {
      "x": -9,
      "y": 18,
      "z": 34,
      "name": "Rock_Sandstone"
    },
    {
      "x": -9,
      "y": 19,
      "z": 34,
      "name": "Empty"
    },
    {
      "x": -9,
      "y": 20,
      "z": 34,
      "name": "Empty"
    },
    {
      "x": -9,
      "y": 21,
      "z": 34,
      "name": "Rock_Sandstone"
    },
    {
      "x": -9,
      "y": 22,
      "z": 34,
      "name": "Rock_Sandstone"
    },
    {
      "x": -9,
      "y": 23,
      "z": 34,
      "name": "Rock_Sandstone"
    },
    {
      "x": -9,
      "y": 24,
      "z": 34,
      "name": "Rock_Sandstone"
    },
    {
      "x": -9,
      "y": 25,
      "z": 34,
      "name": "Rock_Sandstone"
    },
    {
      "x": -9,
      "y": 26,
      "z": 34,
      "name": "Rock_Sandstone"
    },
    {
      "x": -9,
      "y": 27,
      "z": 34,
      "name": "Rock_Sandstone"
    },
    {
      "x": -9,
      "y": 18,
      "z": 35,
      "name": "Rock_Sandstone"
    },
    {
      "x": -9,
      "y": 19,
      "z": 35,
      "name": "Rock_Sandstone"
    },
    {
      "x": -9,
      "y": 20,
      "z": 35,
      "name": "Rock_Sandstone"
    },
    {
      "x": -9,
      "y": 21,
      "z": 35,
      "name": "Rock_Sandstone"
    },
    {
      "x": -9,
      "y": 22,
      "z": 35,
      "name": "Rock_Sandstone"
    },
    {
      "x": -9,
      "y": 23,
      "z": 35,
      "name": "Rock_Sandstone"
    },
    {
      "x": -9,
      "y": 24,
      "z": 35,
      "name": "Rock_Sandstone"
    },
    {
      "x": -9,
      "y": 25,
      "z": 35,
      "name": "Rock_Sandstone"
    },
    {
      "x": -9,
      "y": 26,
      "z": 35,
      "name": "Rock_Sandstone"
    },
    {
      "x": -8,
      "y": 18,
      "z": 21,
      "name": "Rock_Sandstone"
    },
    {
      "x": -8,
      "y": 19,
      "z": 21,
      "name": "Rock_Sandstone"
    },
    {
      "x": -8,
      "y": 20,
      "z": 21,
      "name": "Rock_Sandstone"
    },
    {
      "x": -8,
      "y": 21,
      "z": 21,
      "name": "Rock_Sandstone"
    },
    {
      "x": -8,
      "y": 22,
      "z": 21,
      "name": "Rock_Sandstone"
    },
    {
      "x": -8,
      "y": 23,
      "z": 21,
      "name": "Rock_Sandstone"
    },
    {
      "x": -8,
      "y": 24,
      "z": 21,
      "name": "Rock_Sandstone"
    },
    {
      "x": -8,
      "y": 25,
      "z": 21,
      "name": "Rock_Sandstone"
    },
    {
      "x": -8,
      "y": 26,
      "z": 21,
      "name": "Rock_Sandstone"
    },
    {
      "x": -8,
      "y": 27,
      "z": 21,
      "name": "Rock_Sandstone"
    },
    {
      "x": -8,
      "y": 17,
      "z": 22,
      "name": "Rock_Sandstone"
    },
    {
      "x": -8,
      "y": 18,
      "z": 22,
      "name": "Rock_Sandstone"
    },
    {
      "x": -8,
      "y": 19,
      "z": 22,
      "name": "Rock_Sandstone"
    },
    {
      "x": -8,
      "y": 20,
      "z": 22,
      "name": "Rock_Sandstone"
    },
    {
      "x": -8,
      "y": 21,
      "z": 22,
      "name": "Rock_Sandstone"
    },
    {
      "x": -8,
      "y": 22,
      "z": 22,
      "name": "Rock_Sandstone"
    },
    {
      "x": -8,
      "y": 23,
      "z": 22,
      "name": "Rock_Sandstone"
    },
    {
      "x": -8,
      "y": 24,
      "z": 22,
      "name": "Rock_Sandstone"
    },
    {
      "x": -8,
      "y": 25,
      "z": 22,
      "name": "Rock_Sandstone"
    },
    {
      "x": -8,
      "y": 26,
      "z": 22,
      "name": "Rock_Sandstone"
    },
    {
      "x": -8,
      "y": 27,
      "z": 22,
      "name": "Rock_Sandstone"
    },
    {
      "x": -8,
      "y": 28,
      "z": 22,
      "name": "Rock_Sandstone"
    },
    {
      "x": -8,
      "y": 17,
      "z": 23,
      "name": "Rock_Sandstone"
    },
    {
      "x": -8,
      "y": 18,
      "z": 23,
      "name": "Rock_Sandstone"
    },
    {
      "x": -8,
      "y": 19,
      "z": 23,
      "name": "Furniture_Village_Crate"
    },
    {
      "x": -8,
      "y": 20,
      "z": 23,
      "name": "Furniture_Tavern_Barrel"
    },
    {
      "x": -8,
      "y": 21,
      "z": 23,
      "name": "Empty"
    },
    {
      "x": -8,
      "y": 22,
      "z": 23,
      "name": "Empty"
    },
    {
      "x": -8,
      "y": 23,
      "z": 23,
      "name": "Empty"
    },
    {
      "x": -8,
      "y": 24,
      "z": 23,
      "name": "Empty"
    },
    {
      "x": -8,
      "y": 25,
      "z": 23,
      "name": "Empty"
    },
    {
      "x": -8,
      "y": 26,
      "z": 23,
      "name": "Empty"
    },
    {
      "x": -8,
      "y": 27,
      "z": 23,
      "name": "Rock_Sandstone"
    },
    {
      "x": -8,
      "y": 28,
      "z": 23,
      "name": "Rock_Sandstone"
    },
    {
      "x": -8,
      "y": 17,
      "z": 24,
      "name": "Rock_Sandstone"
    },
    {
      "x": -8,
      "y": 18,
      "z": 24,
      "name": "Rock_Sandstone"
    },
    {
      "x": -8,
      "y": 19,
      "z": 24,
      "name": "Furniture_Village_Crate"
    },
    {
      "x": -8,
      "y": 20,
      "z": 24,
      "name": "Empty"
    },
    {
      "x": -8,
      "y": 21,
      "z": 24,
      "name": "Empty"
    },
    {
      "x": -8,
      "y": 22,
      "z": 24,
      "name": "Empty"
    },
    {
      "x": -8,
      "y": 23,
      "z": 24,
      "name": "Empty"
    },
    {
      "x": -8,
      "y": 24,
      "z": 24,
      "name": "Empty"
    },
    {
      "x": -8,
      "y": 25,
      "z": 24,
      "name": "Empty"
    },
    {
      "x": -8,
      "y": 26,
      "z": 24,
      "name": "Empty"
    },
    {
      "x": -8,
      "y": 27,
      "z": 24,
      "name": "Rock_Sandstone"
    },
    {
      "x": -8,
      "y": 28,
      "z": 24,
      "name": "Rock_Sandstone"
    },
    {
      "x": -8,
      "y": 29,
      "z": 24,
      "name": "Rock_Sandstone"
    },
    {
      "x": -8,
      "y": 17,
      "z": 25,
      "name": "Rock_Sandstone"
    },
    {
      "x": -8,
      "y": 18,
      "z": 25,
      "name": "Rock_Sandstone"
    },
    {
      "x": -8,
      "y": 19,
      "z": 25,
      "name": "Empty"
    },
    {
      "x": -8,
      "y": 20,
      "z": 25,
      "name": "Empty"
    },
    {
      "x": -8,
      "y": 21,
      "z": 25,
      "name": "Wood_Torch_Wall",
      "rotation": 1
    },
    {
      "x": -8,
      "y": 22,
      "z": 25,
      "name": "Empty"
    },
    {
      "x": -8,
      "y": 23,
      "z": 25,
      "name": "Empty"
    },
    {
      "x": -8,
      "y": 24,
      "z": 25,
      "name": "Empty"
    },
    {
      "x": -8,
      "y": 25,
      "z": 25,
      "name": "Empty"
    },
    {
      "x": -8,
      "y": 26,
      "z": 25,
      "name": "Rock_Sandstone"
    },
    {
      "x": -8,
      "y": 27,
      "z": 25,
      "name": "Rock_Sandstone"
    },
    {
      "x": -8,
      "y": 28,
      "z": 25,
      "name": "Rock_Sandstone"
    },
    {
      "x": -8,
      "y": 29,
      "z": 25,
      "name": "Rock_Sandstone"
    },
    {
      "x": -8,
      "y": 17,
      "z": 26,
      "name": "Rock_Sandstone"
    },
    {
      "x": -8,
      "y": 18,
      "z": 26,
      "name": "Rock_Sandstone"
    },
    {
      "x": -8,
      "y": 19,
      "z": 26,
      "name": "Furniture_Village_Bench",
      "rotation": 1
    },
    {
      "x": -8,
      "y": 20,
      "z": 26,
      "name": "Furniture_Village_Bench",
      "filler": 1024,
      "rotation": 1
    },
    {
      "x": -8,
      "y": 21,
      "z": 26,
      "name": "Empty"
    },
    {
      "x": -8,
      "y": 22,
      "z": 26,
      "name": "Empty"
    },
    {
      "x": -8,
      "y": 23,
      "z": 26,
      "name": "Empty"
    },
    {
      "x": -8,
      "y": 24,
      "z": 26,
      "name": "Empty"
    },
    {
      "x": -8,
      "y": 25,
      "z": 26,
      "name": "Empty"
    },
    {
      "x": -8,
      "y": 26,
      "z": 26,
      "name": "Rock_Sandstone"
    },
    {
      "x": -8,
      "y": 27,
      "z": 26,
      "name": "Rock_Sandstone"
    },
    {
      "x": -8,
      "y": 28,
      "z": 26,
      "name": "Rock_Sandstone"
    },
    {
      "x": -8,
      "y": 29,
      "z": 26,
      "name": "Rock_Sandstone"
    },
    {
      "x": -8,
      "y": 17,
      "z": 27,
      "name": "Rock_Sandstone"
    },
    {
      "x": -8,
      "y": 18,
      "z": 27,
      "name": "Soil_Gravel_Sand_White"
    },
    {
      "x": -8,
      "y": 19,
      "z": 27,
      "name": "Furniture_Village_Bench",
      "filler": 32,
      "rotation": 1
    },
    {
      "x": -8,
      "y": 20,
      "z": 27,
      "name": "Furniture_Village_Bench",
      "filler": 1056,
      "rotation": 1
    },
    {
      "x": -8,
      "y": 21,
      "z": 27,
      "name": "Empty"
    },
    {
      "x": -8,
      "y": 22,
      "z": 27,
      "name": "Empty"
    },
    {
      "x": -8,
      "y": 23,
      "z": 27,
      "name": "Empty"
    },
    {
      "x": -8,
      "y": 24,
      "z": 27,
      "name": "Empty"
    },
    {
      "x": -8,
      "y": 25,
      "z": 27,
      "name": "Empty"
    },
    {
      "x": -8,
      "y": 26,
      "z": 27,
      "name": "Rock_Sandstone"
    },
    {
      "x": -8,
      "y": 27,
      "z": 27,
      "name": "Rock_Sandstone"
    },
    {
      "x": -8,
      "y": 28,
      "z": 27,
      "name": "Rock_Sandstone"
    },
    {
      "x": -8,
      "y": 29,
      "z": 27,
      "name": "Rock_Sandstone"
    },
    {
      "x": -8,
      "y": 17,
      "z": 28,
      "name": "Rock_Sandstone"
    },
    {
      "x": -8,
      "y": 18,
      "z": 28,
      "name": "Soil_Gravel_Sand_White"
    },
    {
      "x": -8,
      "y": 19,
      "z": 28,
      "name": "Empty"
    },
    {
      "x": -8,
      "y": 20,
      "z": 28,
      "name": "Empty"
    },
    {
      "x": -8,
      "y": 21,
      "z": 28,
      "name": "Empty"
    },
    {
      "x": -8,
      "y": 22,
      "z": 28,
      "name": "Empty"
    },
    {
      "x": -8,
      "y": 23,
      "z": 28,
      "name": "Empty"
    },
    {
      "x": -8,
      "y": 24,
      "z": 28,
      "name": "Empty"
    },
    {
      "x": -8,
      "y": 25,
      "z": 28,
      "name": "Empty"
    },
    {
      "x": -8,
      "y": 26,
      "z": 28,
      "name": "Empty"
    },
    {
      "x": -8,
      "y": 27,
      "z": 28,
      "name": "Rock_Sandstone"
    },
    {
      "x": -8,
      "y": 28,
      "z": 28,
      "name": "Rock_Sandstone"
    },
    {
      "x": -8,
      "y": 29,
      "z": 28,
      "name": "Rock_Sandstone"
    },
    {
      "x": -8,
      "y": 17,
      "z": 29,
      "name": "Rock_Sandstone"
    },
    {
      "x": -8,
      "y": 18,
      "z": 29,
      "name": "Soil_Sand_White"
    },
    {
      "x": -8,
      "y": 19,
      "z": 29,
      "name": "Empty"
    },
    {
      "x": -8,
      "y": 20,
      "z": 29,
      "name": "Empty"
    },
    {
      "x": -8,
      "y": 21,
      "z": 29,
      "name": "Empty"
    },
    {
      "x": -8,
      "y": 22,
      "z": 29,
      "name": "Empty"
    },
    {
      "x": -8,
      "y": 23,
      "z": 29,
      "name": "Empty"
    },
    {
      "x": -8,
      "y": 24,
      "z": 29,
      "name": "Empty"
    },
    {
      "x": -8,
      "y": 25,
      "z": 29,
      "name": "Empty"
    },
    {
      "x": -8,
      "y": 26,
      "z": 29,
      "name": "Empty"
    },
    {
      "x": -8,
      "y": 27,
      "z": 29,
      "name": "Rock_Sandstone"
    },
    {
      "x": -8,
      "y": 28,
      "z": 29,
      "name": "Rock_Sandstone"
    },
    {
      "x": -8,
      "y": 29,
      "z": 29,
      "name": "Rock_Sandstone"
    },
    {
      "x": -8,
      "y": 17,
      "z": 30,
      "name": "Rock_Sandstone"
    },
    {
      "x": -8,
      "y": 18,
      "z": 30,
      "name": "Soil_Gravel_Sand_White"
    },
    {
      "x": -8,
      "y": 19,
      "z": 30,
      "name": "Empty"
    },
    {
      "x": -8,
      "y": 20,
      "z": 30,
      "name": "Empty"
    },
    {
      "x": -8,
      "y": 21,
      "z": 30,
      "name": "Empty"
    },
    {
      "x": -8,
      "y": 22,
      "z": 30,
      "name": "Empty"
    },
    {
      "x": -8,
      "y": 23,
      "z": 30,
      "name": "Empty"
    },
    {
      "x": -8,
      "y": 24,
      "z": 30,
      "name": "Empty"
    },
    {
      "x": -8,
      "y": 25,
      "z": 30,
      "name": "Empty"
    },
    {
      "x": -8,
      "y": 26,
      "z": 30,
      "name": "Empty"
    },
    {
      "x": -8,
      "y": 27,
      "z": 30,
      "name": "Rock_Sandstone"
    },
    {
      "x": -8,
      "y": 28,
      "z": 30,
      "name": "Rock_Sandstone"
    },
    {
      "x": -8,
      "y": 29,
      "z": 30,
      "name": "Rock_Sandstone"
    },
    {
      "x": -8,
      "y": 17,
      "z": 31,
      "name": "Rock_Sandstone"
    },
    {
      "x": -8,
      "y": 18,
      "z": 31,
      "name": "Soil_Gravel_Sand_White"
    },
    {
      "x": -8,
      "y": 19,
      "z": 31,
      "name": "Empty"
    },
    {
      "x": -8,
      "y": 20,
      "z": 31,
      "name": "Empty"
    },
    {
      "x": -8,
      "y": 21,
      "z": 31,
      "name": "Empty"
    },
    {
      "x": -8,
      "y": 22,
      "z": 31,
      "name": "Empty"
    },
    {
      "x": -8,
      "y": 23,
      "z": 31,
      "name": "Empty"
    },
    {
      "x": -8,
      "y": 24,
      "z": 31,
      "name": "Empty"
    },
    {
      "x": -8,
      "y": 25,
      "z": 31,
      "name": "Empty"
    },
    {
      "x": -8,
      "y": 26,
      "z": 31,
      "name": "Empty"
    },
    {
      "x": -8,
      "y": 27,
      "z": 31,
      "name": "Rock_Sandstone"
    },
    {
      "x": -8,
      "y": 28,
      "z": 31,
      "name": "Rock_Sandstone"
    },
    {
      "x": -8,
      "y": 29,
      "z": 31,
      "name": "Rock_Sandstone"
    },
    {
      "x": -8,
      "y": 17,
      "z": 32,
      "name": "Rock_Sandstone"
    },
    {
      "x": -8,
      "y": 18,
      "z": 32,
      "name": "Rock_Sandstone"
    },
    {
      "x": -8,
      "y": 19,
      "z": 32,
      "name": "Rock_Sandstone_Brick_Ornate"
    },
    {
      "x": -8,
      "y": 20,
      "z": 32,
      "name": "Rock_Sandstone_Brick_Decorative"
    },
    {
      "x": -8,
      "y": 21,
      "z": 32,
      "name": "Rock_Sandstone_Brick_Decorative"
    },
    {
      "x": -8,
      "y": 22,
      "z": 32,
      "name": "Rock_Sandstone_Brick"
    },
    {
      "x": -8,
      "y": 23,
      "z": 32,
      "name": "Rock_Sandstone_Brick"
    },
    {
      "x": -8,
      "y": 24,
      "z": 32,
      "name": "Rock_Sandstone_Brick"
    },
    {
      "x": -8,
      "y": 25,
      "z": 32,
      "name": "Rock_Sandstone_Brick"
    },
    {
      "x": -8,
      "y": 26,
      "z": 32,
      "name": "Rock_Sandstone"
    },
    {
      "x": -8,
      "y": 27,
      "z": 32,
      "name": "Rock_Sandstone"
    },
    {
      "x": -8,
      "y": 28,
      "z": 32,
      "name": "Rock_Sandstone"
    },
    {
      "x": -8,
      "y": 29,
      "z": 32,
      "name": "Rock_Sandstone"
    },
    {
      "x": -8,
      "y": 17,
      "z": 33,
      "name": "Rock_Sandstone"
    },
    {
      "x": -8,
      "y": 18,
      "z": 33,
      "name": "Rock_Sandstone"
    },
    {
      "x": -8,
      "y": 19,
      "z": 33,
      "name": "Rock_Sandstone_Brick_Ornate"
    },
    {
      "x": -8,
      "y": 20,
      "z": 33,
      "name": "Rock_Sandstone_Brick_Decorative"
    },
    {
      "x": -8,
      "y": 21,
      "z": 33,
      "name": "Rock_Sandstone_Brick_Decorative"
    },
    {
      "x": -8,
      "y": 22,
      "z": 33,
      "name": "Rock_Sandstone_Brick"
    },
    {
      "x": -8,
      "y": 23,
      "z": 33,
      "name": "Rock_Sandstone_Brick"
    },
    {
      "x": -8,
      "y": 24,
      "z": 33,
      "name": "Rock_Sandstone_Brick"
    },
    {
      "x": -8,
      "y": 25,
      "z": 33,
      "name": "Rock_Sandstone"
    },
    {
      "x": -8,
      "y": 26,
      "z": 33,
      "name": "Rock_Sandstone"
    },
    {
      "x": -8,
      "y": 27,
      "z": 33,
      "name": "Rock_Sandstone"
    },
    {
      "x": -8,
      "y": 28,
      "z": 33,
      "name": "Rock_Sandstone"
    },
    {
      "x": -8,
      "y": 17,
      "z": 34,
      "name": "Rock_Sandstone"
    },
    {
      "x": -8,
      "y": 18,
      "z": 34,
      "name": "Rock_Sandstone"
    },
    {
      "x": -8,
      "y": 19,
      "z": 34,
      "name": "Empty"
    },
    {
      "x": -8,
      "y": 20,
      "z": 34,
      "name": "Empty"
    },
    {
      "x": -8,
      "y": 21,
      "z": 34,
      "name": "Rock_Sandstone"
    },
    {
      "x": -8,
      "y": 22,
      "z": 34,
      "name": "Rock_Sandstone"
    },
    {
      "x": -8,
      "y": 23,
      "z": 34,
      "name": "Rock_Sandstone"
    },
    {
      "x": -8,
      "y": 24,
      "z": 34,
      "name": "Rock_Sandstone"
    },
    {
      "x": -8,
      "y": 25,
      "z": 34,
      "name": "Rock_Sandstone"
    },
    {
      "x": -8,
      "y": 26,
      "z": 34,
      "name": "Rock_Sandstone"
    },
    {
      "x": -8,
      "y": 27,
      "z": 34,
      "name": "Rock_Sandstone"
    },
    {
      "x": -8,
      "y": 28,
      "z": 34,
      "name": "Rock_Sandstone"
    },
    {
      "x": -8,
      "y": 18,
      "z": 35,
      "name": "Rock_Sandstone"
    },
    {
      "x": -8,
      "y": 19,
      "z": 35,
      "name": "Rock_Sandstone"
    },
    {
      "x": -8,
      "y": 20,
      "z": 35,
      "name": "Rock_Sandstone"
    },
    {
      "x": -8,
      "y": 21,
      "z": 35,
      "name": "Rock_Sandstone"
    },
    {
      "x": -8,
      "y": 22,
      "z": 35,
      "name": "Rock_Sandstone"
    },
    {
      "x": -8,
      "y": 23,
      "z": 35,
      "name": "Rock_Sandstone"
    },
    {
      "x": -8,
      "y": 24,
      "z": 35,
      "name": "Rock_Sandstone"
    },
    {
      "x": -8,
      "y": 25,
      "z": 35,
      "name": "Rock_Sandstone"
    },
    {
      "x": -8,
      "y": 26,
      "z": 35,
      "name": "Rock_Sandstone"
    },
    {
      "x": -8,
      "y": 27,
      "z": 35,
      "name": "Rock_Sandstone"
    },
    {
      "x": -8,
      "y": 28,
      "z": 35,
      "name": "Rock_Sandstone"
    },
    {
      "x": -7,
      "y": 18,
      "z": 21,
      "name": "Rock_Sandstone"
    },
    {
      "x": -7,
      "y": 19,
      "z": 21,
      "name": "Rock_Sandstone"
    },
    {
      "x": -7,
      "y": 20,
      "z": 21,
      "name": "Rock_Sandstone"
    },
    {
      "x": -7,
      "y": 21,
      "z": 21,
      "name": "Rock_Sandstone"
    },
    {
      "x": -7,
      "y": 22,
      "z": 21,
      "name": "Rock_Sandstone"
    },
    {
      "x": -7,
      "y": 23,
      "z": 21,
      "name": "Rock_Sandstone"
    },
    {
      "x": -7,
      "y": 24,
      "z": 21,
      "name": "Rock_Sandstone"
    },
    {
      "x": -7,
      "y": 25,
      "z": 21,
      "name": "Rock_Sandstone"
    },
    {
      "x": -7,
      "y": 26,
      "z": 21,
      "name": "Rock_Sandstone"
    },
    {
      "x": -7,
      "y": 27,
      "z": 21,
      "name": "Rock_Sandstone"
    },
    {
      "x": -7,
      "y": 28,
      "z": 21,
      "name": "Rock_Sandstone"
    },
    {
      "x": -7,
      "y": 17,
      "z": 22,
      "name": "Rock_Sandstone"
    },
    {
      "x": -7,
      "y": 18,
      "z": 22,
      "name": "Rock_Sandstone"
    },
    {
      "x": -7,
      "y": 19,
      "z": 22,
      "name": "Rock_Sandstone"
    },
    {
      "x": -7,
      "y": 20,
      "z": 22,
      "name": "Rock_Sandstone"
    },
    {
      "x": -7,
      "y": 21,
      "z": 22,
      "name": "Rock_Sandstone"
    },
    {
      "x": -7,
      "y": 22,
      "z": 22,
      "name": "Empty"
    },
    {
      "x": -7,
      "y": 23,
      "z": 22,
      "name": "Empty"
    },
    {
      "x": -7,
      "y": 24,
      "z": 22,
      "name": "Rock_Sandstone"
    },
    {
      "x": -7,
      "y": 25,
      "z": 22,
      "name": "Rock_Sandstone"
    },
    {
      "x": -7,
      "y": 26,
      "z": 22,
      "name": "Rock_Sandstone"
    },
    {
      "x": -7,
      "y": 27,
      "z": 22,
      "name": "Rock_Sandstone"
    },
    {
      "x": -7,
      "y": 28,
      "z": 22,
      "name": "Rock_Sandstone"
    },
    {
      "x": -7,
      "y": 17,
      "z": 23,
      "name": "Rock_Sandstone"
    },
    {
      "x": -7,
      "y": 18,
      "z": 23,
      "name": "Soil_Sand_White"
    },
    {
      "x": -7,
      "y": 19,
      "z": 23,
      "name": "Furniture_Village_Crate"
    },
    {
      "x": -7,
      "y": 20,
      "z": 23,
      "name": "Empty"
    },
    {
      "x": -7,
      "y": 21,
      "z": 23,
      "name": "Empty"
    },
    {
      "x": -7,
      "y": 22,
      "z": 23,
      "name": "Empty"
    },
    {
      "x": -7,
      "y": 23,
      "z": 23,
      "name": "Empty"
    },
    {
      "x": -7,
      "y": 24,
      "z": 23,
      "name": "Empty"
    },
    {
      "x": -7,
      "y": 25,
      "z": 23,
      "name": "Empty"
    },
    {
      "x": -7,
      "y": 26,
      "z": 23,
      "name": "Empty"
    },
    {
      "x": -7,
      "y": 27,
      "z": 23,
      "name": "Rock_Sandstone"
    },
    {
      "x": -7,
      "y": 28,
      "z": 23,
      "name": "Rock_Sandstone"
    },
    {
      "x": -7,
      "y": 29,
      "z": 23,
      "name": "Rock_Sandstone"
    },
    {
      "x": -7,
      "y": 17,
      "z": 24,
      "name": "Rock_Sandstone"
    },
    {
      "x": -7,
      "y": 18,
      "z": 24,
      "name": "Soil_Sand_White"
    },
    {
      "x": -7,
      "y": 19,
      "z": 24,
      "name": "Container_Bucket"
    },
    {
      "x": -7,
      "y": 20,
      "z": 24,
      "name": "Empty"
    },
    {
      "x": -7,
      "y": 21,
      "z": 24,
      "name": "Empty"
    },
    {
      "x": -7,
      "y": 22,
      "z": 24,
      "name": "Empty"
    },
    {
      "x": -7,
      "y": 23,
      "z": 24,
      "name": "Empty"
    },
    {
      "x": -7,
      "y": 24,
      "z": 24,
      "name": "Empty"
    },
    {
      "x": -7,
      "y": 25,
      "z": 24,
      "name": "Empty"
    },
    {
      "x": -7,
      "y": 26,
      "z": 24,
      "name": "Empty"
    },
    {
      "x": -7,
      "y": 27,
      "z": 24,
      "name": "Rock_Sandstone"
    },
    {
      "x": -7,
      "y": 28,
      "z": 24,
      "name": "Rock_Sandstone"
    },
    {
      "x": -7,
      "y": 29,
      "z": 24,
      "name": "Rock_Sandstone"
    },
    {
      "x": -7,
      "y": 17,
      "z": 25,
      "name": "Rock_Sandstone"
    },
    {
      "x": -7,
      "y": 18,
      "z": 25,
      "name": "Soil_Gravel_Sand_White"
    },
    {
      "x": -7,
      "y": 19,
      "z": 25,
      "name": "Empty"
    },
    {
      "x": -7,
      "y": 20,
      "z": 25,
      "name": "Empty"
    },
    {
      "x": -7,
      "y": 21,
      "z": 25,
      "name": "Empty"
    },
    {
      "x": -7,
      "y": 22,
      "z": 25,
      "name": "Empty"
    },
    {
      "x": -7,
      "y": 23,
      "z": 25,
      "name": "Empty"
    },
    {
      "x": -7,
      "y": 24,
      "z": 25,
      "name": "Empty"
    },
    {
      "x": -7,
      "y": 25,
      "z": 25,
      "name": "Empty"
    },
    {
      "x": -7,
      "y": 26,
      "z": 25,
      "name": "Empty"
    },
    {
      "x": -7,
      "y": 27,
      "z": 25,
      "name": "Rock_Sandstone"
    },
    {
      "x": -7,
      "y": 28,
      "z": 25,
      "name": "Rock_Sandstone"
    },
    {
      "x": -7,
      "y": 29,
      "z": 25,
      "name": "Rock_Sandstone"
    },
    {
      "x": -7,
      "y": 17,
      "z": 26,
      "name": "Rock_Sandstone"
    },
    {
      "x": -7,
      "y": 18,
      "z": 26,
      "name": "Soil_Gravel_Sand_White"
    },
    {
      "x": -7,
      "y": 19,
      "z": 26,
      "name": "Empty"
    },
    {
      "x": -7,
      "y": 20,
      "z": 26,
      "name": "Empty"
    },
    {
      "x": -7,
      "y": 21,
      "z": 26,
      "name": "Empty"
    },
    {
      "x": -7,
      "y": 22,
      "z": 26,
      "name": "Empty"
    },
    {
      "x": -7,
      "y": 23,
      "z": 26,
      "name": "Empty"
    },
    {
      "x": -7,
      "y": 24,
      "z": 26,
      "name": "Empty"
    },
    {
      "x": -7,
      "y": 25,
      "z": 26,
      "name": "Empty"
    },
    {
      "x": -7,
      "y": 26,
      "z": 26,
      "name": "Empty"
    },
    {
      "x": -7,
      "y": 27,
      "z": 26,
      "name": "Rock_Sandstone"
    },
    {
      "x": -7,
      "y": 28,
      "z": 26,
      "name": "Rock_Sandstone"
    },
    {
      "x": -7,
      "y": 29,
      "z": 26,
      "name": "Rock_Sandstone"
    },
    {
      "x": -7,
      "y": 17,
      "z": 27,
      "name": "Rock_Sandstone"
    },
    {
      "x": -7,
      "y": 18,
      "z": 27,
      "name": "Soil_Sand_White"
    },
    {
      "x": -7,
      "y": 19,
      "z": 27,
      "name": "Empty"
    },
    {
      "x": -7,
      "y": 20,
      "z": 27,
      "name": "Empty"
    },
    {
      "x": -7,
      "y": 21,
      "z": 27,
      "name": "Empty"
    },
    {
      "x": -7,
      "y": 22,
      "z": 27,
      "name": "Empty"
    },
    {
      "x": -7,
      "y": 23,
      "z": 27,
      "name": "Empty"
    },
    {
      "x": -7,
      "y": 24,
      "z": 27,
      "name": "Empty"
    },
    {
      "x": -7,
      "y": 25,
      "z": 27,
      "name": "Empty"
    },
    {
      "x": -7,
      "y": 26,
      "z": 27,
      "name": "Empty"
    },
    {
      "x": -7,
      "y": 27,
      "z": 27,
      "name": "Empty"
    },
    {
      "x": -7,
      "y": 28,
      "z": 27,
      "name": "Rock_Sandstone"
    },
    {
      "x": -7,
      "y": 29,
      "z": 27,
      "name": "Rock_Sandstone"
    },
    {
      "x": -7,
      "y": 17,
      "z": 28,
      "name": "Rock_Sandstone"
    },
    {
      "x": -7,
      "y": 18,
      "z": 28,
      "name": "Soil_Gravel_Sand_White"
    },
    {
      "x": -7,
      "y": 19,
      "z": 28,
      "name": "Furniture_Crude_Stool"
    },
    {
      "x": -7,
      "y": 20,
      "z": 28,
      "name": "Empty"
    },
    {
      "x": -7,
      "y": 21,
      "z": 28,
      "name": "Empty"
    },
    {
      "x": -7,
      "y": 22,
      "z": 28,
      "name": "Empty"
    },
    {
      "x": -7,
      "y": 23,
      "z": 28,
      "name": "Empty"
    },
    {
      "x": -7,
      "y": 24,
      "z": 28,
      "name": "Empty"
    },
    {
      "x": -7,
      "y": 25,
      "z": 28,
      "name": "Empty"
    },
    {
      "x": -7,
      "y": 26,
      "z": 28,
      "name": "Empty"
    },
    {
      "x": -7,
      "y": 27,
      "z": 28,
      "name": "Empty"
    },
    {
      "x": -7,
      "y": 28,
      "z": 28,
      "name": "Rock_Sandstone"
    },
    {
      "x": -7,
      "y": 29,
      "z": 28,
      "name": "Rock_Sandstone"
    },
    {
      "x": -7,
      "y": 17,
      "z": 29,
      "name": "Rock_Sandstone"
    },
    {
      "x": -7,
      "y": 18,
      "z": 29,
      "name": "Soil_Sand_White"
    },
    {
      "x": -7,
      "y": 19,
      "z": 29,
      "name": "Empty"
    },
    {
      "x": -7,
      "y": 20,
      "z": 29,
      "name": "Empty"
    },
    {
      "x": -7,
      "y": 21,
      "z": 29,
      "name": "Empty"
    },
    {
      "x": -7,
      "y": 22,
      "z": 29,
      "name": "Empty"
    },
    {
      "x": -7,
      "y": 23,
      "z": 29,
      "name": "Empty"
    },
    {
      "x": -7,
      "y": 24,
      "z": 29,
      "name": "Empty"
    },
    {
      "x": -7,
      "y": 25,
      "z": 29,
      "name": "Empty"
    },
    {
      "x": -7,
      "y": 26,
      "z": 29,
      "name": "Empty"
    },
    {
      "x": -7,
      "y": 27,
      "z": 29,
      "name": "Empty"
    },
    {
      "x": -7,
      "y": 28,
      "z": 29,
      "name": "Rock_Sandstone"
    },
    {
      "x": -7,
      "y": 29,
      "z": 29,
      "name": "Rock_Sandstone"
    },
    {
      "x": -7,
      "y": 17,
      "z": 30,
      "name": "Rock_Sandstone"
    },
    {
      "x": -7,
      "y": 18,
      "z": 30,
      "name": "Soil_Sand_White"
    },
    {
      "x": -7,
      "y": 19,
      "z": 30,
      "name": "Empty"
    },
    {
      "x": -7,
      "y": 20,
      "z": 30,
      "name": "Empty"
    },
    {
      "x": -7,
      "y": 21,
      "z": 30,
      "name": "Empty"
    },
    {
      "x": -7,
      "y": 22,
      "z": 30,
      "name": "Empty"
    },
    {
      "x": -7,
      "y": 23,
      "z": 30,
      "name": "Empty"
    },
    {
      "x": -7,
      "y": 24,
      "z": 30,
      "name": "Empty"
    },
    {
      "x": -7,
      "y": 25,
      "z": 30,
      "name": "Empty"
    },
    {
      "x": -7,
      "y": 26,
      "z": 30,
      "name": "Empty"
    },
    {
      "x": -7,
      "y": 27,
      "z": 30,
      "name": "Rock_Sandstone"
    },
    {
      "x": -7,
      "y": 28,
      "z": 30,
      "name": "Rock_Sandstone"
    },
    {
      "x": -7,
      "y": 29,
      "z": 30,
      "name": "Rock_Sandstone"
    },
    {
      "x": -7,
      "y": 17,
      "z": 31,
      "name": "Rock_Sandstone"
    },
    {
      "x": -7,
      "y": 18,
      "z": 31,
      "name": "Soil_Sand_White"
    },
    {
      "x": -7,
      "y": 19,
      "z": 31,
      "name": "Empty"
    },
    {
      "x": -7,
      "y": 20,
      "z": 31,
      "name": "Empty"
    },
    {
      "x": -7,
      "y": 21,
      "z": 31,
      "name": "Empty"
    },
    {
      "x": -7,
      "y": 22,
      "z": 31,
      "name": "Empty"
    },
    {
      "x": -7,
      "y": 23,
      "z": 31,
      "name": "Empty"
    },
    {
      "x": -7,
      "y": 24,
      "z": 31,
      "name": "Empty"
    },
    {
      "x": -7,
      "y": 25,
      "z": 31,
      "name": "Empty"
    },
    {
      "x": -7,
      "y": 26,
      "z": 31,
      "name": "Empty"
    },
    {
      "x": -7,
      "y": 27,
      "z": 31,
      "name": "Rock_Sandstone"
    },
    {
      "x": -7,
      "y": 28,
      "z": 31,
      "name": "Rock_Sandstone"
    },
    {
      "x": -7,
      "y": 29,
      "z": 31,
      "name": "Rock_Sandstone"
    },
    {
      "x": -7,
      "y": 17,
      "z": 32,
      "name": "Rock_Sandstone"
    },
    {
      "x": -7,
      "y": 18,
      "z": 32,
      "name": "Soil_Sand_White"
    },
    {
      "x": -7,
      "y": 19,
      "z": 32,
      "name": "Rock_Sandstone_Brick_Ornate"
    },
    {
      "x": -7,
      "y": 20,
      "z": 32,
      "name": "Rock_Sandstone_Brick_Decorative"
    },
    {
      "x": -7,
      "y": 21,
      "z": 32,
      "name": "Rock_Sandstone_Brick_Decorative"
    },
    {
      "x": -7,
      "y": 22,
      "z": 32,
      "name": "Rock_Sandstone_Brick"
    },
    {
      "x": -7,
      "y": 23,
      "z": 32,
      "name": "Rock_Sandstone_Brick"
    },
    {
      "x": -7,
      "y": 24,
      "z": 32,
      "name": "Rock_Sandstone_Brick"
    },
    {
      "x": -7,
      "y": 25,
      "z": 32,
      "name": "Rock_Sandstone_Brick"
    },
    {
      "x": -7,
      "y": 26,
      "z": 32,
      "name": "Rock_Sandstone_Brick"
    },
    {
      "x": -7,
      "y": 27,
      "z": 32,
      "name": "Rock_Sandstone"
    },
    {
      "x": -7,
      "y": 28,
      "z": 32,
      "name": "Rock_Sandstone"
    },
    {
      "x": -7,
      "y": 29,
      "z": 32,
      "name": "Rock_Sandstone"
    },
    {
      "x": -7,
      "y": 17,
      "z": 33,
      "name": "Rock_Sandstone"
    },
    {
      "x": -7,
      "y": 18,
      "z": 33,
      "name": "Soil_Sand_White"
    },
    {
      "x": -7,
      "y": 19,
      "z": 33,
      "name": "Rock_Sandstone_Brick_Ornate"
    },
    {
      "x": -7,
      "y": 20,
      "z": 33,
      "name": "Rock_Sandstone_Brick_Decorative"
    },
    {
      "x": -7,
      "y": 21,
      "z": 33,
      "name": "Rock_Sandstone_Brick_Decorative"
    },
    {
      "x": -7,
      "y": 22,
      "z": 33,
      "name": "Rock_Sandstone_Brick"
    },
    {
      "x": -7,
      "y": 23,
      "z": 33,
      "name": "Rock_Sandstone_Brick"
    },
    {
      "x": -7,
      "y": 24,
      "z": 33,
      "name": "Rock_Sandstone_Brick"
    },
    {
      "x": -7,
      "y": 25,
      "z": 33,
      "name": "Rock_Sandstone_Brick"
    },
    {
      "x": -7,
      "y": 26,
      "z": 33,
      "name": "Rock_Sandstone_Brick"
    },
    {
      "x": -7,
      "y": 27,
      "z": 33,
      "name": "Rock_Sandstone"
    },
    {
      "x": -7,
      "y": 28,
      "z": 33,
      "name": "Rock_Sandstone"
    },
    {
      "x": -7,
      "y": 29,
      "z": 33,
      "name": "Rock_Sandstone"
    },
    {
      "x": -7,
      "y": 17,
      "z": 34,
      "name": "Rock_Sandstone"
    },
    {
      "x": -7,
      "y": 18,
      "z": 34,
      "name": "Rock_Sandstone"
    },
    {
      "x": -7,
      "y": 19,
      "z": 34,
      "name": "Empty"
    },
    {
      "x": -7,
      "y": 20,
      "z": 34,
      "name": "Empty"
    },
    {
      "x": -7,
      "y": 21,
      "z": 34,
      "name": "Rock_Sandstone"
    },
    {
      "x": -7,
      "y": 22,
      "z": 34,
      "name": "Rock_Sandstone"
    },
    {
      "x": -7,
      "y": 23,
      "z": 34,
      "name": "Rock_Sandstone"
    },
    {
      "x": -7,
      "y": 24,
      "z": 34,
      "name": "Rock_Sandstone"
    },
    {
      "x": -7,
      "y": 25,
      "z": 34,
      "name": "Rock_Sandstone"
    },
    {
      "x": -7,
      "y": 26,
      "z": 34,
      "name": "Rock_Sandstone"
    },
    {
      "x": -7,
      "y": 27,
      "z": 34,
      "name": "Rock_Sandstone"
    },
    {
      "x": -7,
      "y": 28,
      "z": 34,
      "name": "Rock_Sandstone"
    },
    {
      "x": -7,
      "y": 18,
      "z": 35,
      "name": "Rock_Sandstone"
    },
    {
      "x": -7,
      "y": 19,
      "z": 35,
      "name": "Rock_Sandstone"
    },
    {
      "x": -7,
      "y": 20,
      "z": 35,
      "name": "Rock_Sandstone"
    },
    {
      "x": -7,
      "y": 21,
      "z": 35,
      "name": "Rock_Sandstone"
    },
    {
      "x": -7,
      "y": 22,
      "z": 35,
      "name": "Rock_Sandstone"
    },
    {
      "x": -7,
      "y": 23,
      "z": 35,
      "name": "Rock_Sandstone"
    },
    {
      "x": -7,
      "y": 24,
      "z": 35,
      "name": "Rock_Sandstone"
    },
    {
      "x": -7,
      "y": 25,
      "z": 35,
      "name": "Rock_Sandstone"
    },
    {
      "x": -7,
      "y": 26,
      "z": 35,
      "name": "Rock_Sandstone"
    },
    {
      "x": -7,
      "y": 27,
      "z": 35,
      "name": "Rock_Sandstone"
    },
    {
      "x": -7,
      "y": 28,
      "z": 35,
      "name": "Rock_Sandstone"
    },
    {
      "x": -6,
      "y": 18,
      "z": 21,
      "name": "Rock_Sandstone"
    },
    {
      "x": -6,
      "y": 19,
      "z": 21,
      "name": "Rock_Sandstone"
    },
    {
      "x": -6,
      "y": 20,
      "z": 21,
      "name": "Rock_Sandstone"
    },
    {
      "x": -6,
      "y": 21,
      "z": 21,
      "name": "Rock_Sandstone"
    },
    {
      "x": -6,
      "y": 22,
      "z": 21,
      "name": "Rock_Sandstone"
    },
    {
      "x": -6,
      "y": 23,
      "z": 21,
      "name": "Rock_Sandstone"
    },
    {
      "x": -6,
      "y": 24,
      "z": 21,
      "name": "Rock_Sandstone"
    },
    {
      "x": -6,
      "y": 25,
      "z": 21,
      "name": "Rock_Sandstone"
    },
    {
      "x": -6,
      "y": 26,
      "z": 21,
      "name": "Rock_Sandstone"
    },
    {
      "x": -6,
      "y": 27,
      "z": 21,
      "name": "Rock_Sandstone"
    },
    {
      "x": -6,
      "y": 28,
      "z": 21,
      "name": "Rock_Sandstone"
    },
    {
      "x": -6,
      "y": 17,
      "z": 22,
      "name": "Rock_Sandstone"
    },
    {
      "x": -6,
      "y": 18,
      "z": 22,
      "name": "Soil_Gravel_Sand_White"
    },
    {
      "x": -6,
      "y": 19,
      "z": 22,
      "name": "Empty"
    },
    {
      "x": -6,
      "y": 20,
      "z": 22,
      "name": "Empty"
    },
    {
      "x": -6,
      "y": 21,
      "z": 22,
      "name": "Empty"
    },
    {
      "x": -6,
      "y": 22,
      "z": 22,
      "name": "Empty"
    },
    {
      "x": -6,
      "y": 23,
      "z": 22,
      "name": "Empty"
    },
    {
      "x": -6,
      "y": 24,
      "z": 22,
      "name": "Empty"
    },
    {
      "x": -6,
      "y": 25,
      "z": 22,
      "name": "Rock_Sandstone"
    },
    {
      "x": -6,
      "y": 26,
      "z": 22,
      "name": "Rock_Sandstone"
    },
    {
      "x": -6,
      "y": 27,
      "z": 22,
      "name": "Rock_Sandstone"
    },
    {
      "x": -6,
      "y": 28,
      "z": 22,
      "name": "Rock_Sandstone"
    },
    {
      "x": -6,
      "y": 17,
      "z": 23,
      "name": "Rock_Sandstone"
    },
    {
      "x": -6,
      "y": 18,
      "z": 23,
      "name": "Soil_Sand_White"
    },
    {
      "x": -6,
      "y": 19,
      "z": 23,
      "name": "Empty"
    },
    {
      "x": -6,
      "y": 20,
      "z": 23,
      "name": "Empty"
    },
    {
      "x": -6,
      "y": 21,
      "z": 23,
      "name": "Empty"
    },
    {
      "x": -6,
      "y": 22,
      "z": 23,
      "name": "Empty"
    },
    {
      "x": -6,
      "y": 23,
      "z": 23,
      "name": "Empty"
    },
    {
      "x": -6,
      "y": 24,
      "z": 23,
      "name": "Empty"
    },
    {
      "x": -6,
      "y": 25,
      "z": 23,
      "name": "Empty"
    },
    {
      "x": -6,
      "y": 26,
      "z": 23,
      "name": "Empty"
    },
    {
      "x": -6,
      "y": 27,
      "z": 23,
      "name": "Empty"
    },
    {
      "x": -6,
      "y": 28,
      "z": 23,
      "name": "Rock_Sandstone"
    },
    {
      "x": -6,
      "y": 29,
      "z": 23,
      "name": "Rock_Sandstone"
    },
    {
      "x": -6,
      "y": 17,
      "z": 24,
      "name": "Rock_Sandstone"
    },
    {
      "x": -6,
      "y": 18,
      "z": 24,
      "name": "Soil_Sand_White"
    },
    {
      "x": -6,
      "y": 19,
      "z": 24,
      "name": "Empty"
    },
    {
      "x": -6,
      "y": 20,
      "z": 24,
      "name": "Empty"
    },
    {
      "x": -6,
      "y": 21,
      "z": 24,
      "name": "Empty"
    },
    {
      "x": -6,
      "y": 22,
      "z": 24,
      "name": "Empty"
    },
    {
      "x": -6,
      "y": 23,
      "z": 24,
      "name": "Empty"
    },
    {
      "x": -6,
      "y": 24,
      "z": 24,
      "name": "Empty"
    },
    {
      "x": -6,
      "y": 25,
      "z": 24,
      "name": "Empty"
    },
    {
      "x": -6,
      "y": 26,
      "z": 24,
      "name": "Empty"
    },
    {
      "x": -6,
      "y": 27,
      "z": 24,
      "name": "Empty"
    },
    {
      "x": -6,
      "y": 28,
      "z": 24,
      "name": "Rock_Sandstone"
    },
    {
      "x": -6,
      "y": 29,
      "z": 24,
      "name": "Rock_Sandstone"
    },
    {
      "x": -6,
      "y": 17,
      "z": 25,
      "name": "Rock_Sandstone"
    },
    {
      "x": -6,
      "y": 18,
      "z": 25,
      "name": "Soil_Gravel_Sand_White"
    },
    {
      "x": -6,
      "y": 19,
      "z": 25,
      "name": "Empty"
    },
    {
      "x": -6,
      "y": 20,
      "z": 25,
      "name": "Empty"
    },
    {
      "x": -6,
      "y": 21,
      "z": 25,
      "name": "Empty"
    },
    {
      "x": -6,
      "y": 22,
      "z": 25,
      "name": "Empty"
    },
    {
      "x": -6,
      "y": 23,
      "z": 25,
      "name": "Empty"
    },
    {
      "x": -6,
      "y": 24,
      "z": 25,
      "name": "Empty"
    },
    {
      "x": -6,
      "y": 25,
      "z": 25,
      "name": "Empty"
    },
    {
      "x": -6,
      "y": 26,
      "z": 25,
      "name": "Empty"
    },
    {
      "x": -6,
      "y": 27,
      "z": 25,
      "name": "Empty"
    },
    {
      "x": -6,
      "y": 28,
      "z": 25,
      "name": "Rock_Sandstone"
    },
    {
      "x": -6,
      "y": 29,
      "z": 25,
      "name": "Rock_Sandstone"
    },
    {
      "x": -6,
      "y": 17,
      "z": 26,
      "name": "Rock_Sandstone"
    },
    {
      "x": -6,
      "y": 18,
      "z": 26,
      "name": "Soil_Sand_White"
    },
    {
      "x": -6,
      "y": 19,
      "z": 26,
      "name": "Furniture_Crude_Brazier"
    },
    {
      "x": -6,
      "y": 20,
      "z": 26,
      "name": "Empty"
    },
    {
      "x": -6,
      "y": 21,
      "z": 26,
      "name": "Empty"
    },
    {
      "x": -6,
      "y": 22,
      "z": 26,
      "name": "Empty"
    },
    {
      "x": -6,
      "y": 23,
      "z": 26,
      "name": "Empty"
    },
    {
      "x": -6,
      "y": 24,
      "z": 26,
      "name": "Empty"
    },
    {
      "x": -6,
      "y": 25,
      "z": 26,
      "name": "Empty"
    },
    {
      "x": -6,
      "y": 26,
      "z": 26,
      "name": "Empty"
    },
    {
      "x": -6,
      "y": 27,
      "z": 26,
      "name": "Empty"
    },
    {
      "x": -6,
      "y": 28,
      "z": 26,
      "name": "Rock_Sandstone"
    },
    {
      "x": -6,
      "y": 29,
      "z": 26,
      "name": "Rock_Sandstone"
    },
    {
      "x": -6,
      "y": 17,
      "z": 27,
      "name": "Rock_Sandstone"
    },
    {
      "x": -6,
      "y": 18,
      "z": 27,
      "name": "Soil_Gravel_Sand_White"
    },
    {
      "x": -6,
      "y": 19,
      "z": 27,
      "name": "Empty"
    },
    {
      "x": -6,
      "y": 20,
      "z": 27,
      "name": "Empty"
    },
    {
      "x": -6,
      "y": 21,
      "z": 27,
      "name": "Empty"
    },
    {
      "x": -6,
      "y": 22,
      "z": 27,
      "name": "Empty"
    },
    {
      "x": -6,
      "y": 23,
      "z": 27,
      "name": "Empty"
    },
    {
      "x": -6,
      "y": 24,
      "z": 27,
      "name": "Empty"
    },
    {
      "x": -6,
      "y": 25,
      "z": 27,
      "name": "Empty"
    },
    {
      "x": -6,
      "y": 26,
      "z": 27,
      "name": "Empty"
    },
    {
      "x": -6,
      "y": 27,
      "z": 27,
      "name": "Empty"
    },
    {
      "x": -6,
      "y": 28,
      "z": 27,
      "name": "Rock_Sandstone"
    },
    {
      "x": -6,
      "y": 29,
      "z": 27,
      "name": "Rock_Sandstone"
    },
    {
      "x": -6,
      "y": 17,
      "z": 28,
      "name": "Rock_Sandstone"
    },
    {
      "x": -6,
      "y": 18,
      "z": 28,
      "name": "Soil_Gravel_Sand_White"
    },
    {
      "x": -6,
      "y": 19,
      "z": 28,
      "name": "Furniture_Crude_Stool"
    },
    {
      "x": -6,
      "y": 20,
      "z": 28,
      "name": "Empty"
    },
    {
      "x": -6,
      "y": 21,
      "z": 28,
      "name": "Empty"
    },
    {
      "x": -6,
      "y": 22,
      "z": 28,
      "name": "Empty"
    },
    {
      "x": -6,
      "y": 23,
      "z": 28,
      "name": "Empty"
    },
    {
      "x": -6,
      "y": 24,
      "z": 28,
      "name": "Empty"
    },
    {
      "x": -6,
      "y": 25,
      "z": 28,
      "name": "Empty"
    },
    {
      "x": -6,
      "y": 26,
      "z": 28,
      "name": "Empty"
    },
    {
      "x": -6,
      "y": 27,
      "z": 28,
      "name": "Empty"
    },
    {
      "x": -6,
      "y": 28,
      "z": 28,
      "name": "Rock_Sandstone"
    },
    {
      "x": -6,
      "y": 29,
      "z": 28,
      "name": "Rock_Sandstone"
    },
    {
      "x": -6,
      "y": 17,
      "z": 29,
      "name": "Rock_Sandstone"
    },
    {
      "x": -6,
      "y": 18,
      "z": 29,
      "name": "Soil_Gravel_Sand_White"
    },
    {
      "x": -6,
      "y": 19,
      "z": 29,
      "name": "Empty"
    },
    {
      "x": -6,
      "y": 20,
      "z": 29,
      "name": "Empty"
    },
    {
      "x": -6,
      "y": 21,
      "z": 29,
      "name": "Empty"
    },
    {
      "x": -6,
      "y": 22,
      "z": 29,
      "name": "Empty"
    },
    {
      "x": -6,
      "y": 23,
      "z": 29,
      "name": "Empty"
    },
    {
      "x": -6,
      "y": 24,
      "z": 29,
      "name": "Empty"
    },
    {
      "x": -6,
      "y": 25,
      "z": 29,
      "name": "Empty"
    },
    {
      "x": -6,
      "y": 26,
      "z": 29,
      "name": "Empty"
    },
    {
      "x": -6,
      "y": 27,
      "z": 29,
      "name": "Empty"
    },
    {
      "x": -6,
      "y": 28,
      "z": 29,
      "name": "Rock_Sandstone"
    },
    {
      "x": -6,
      "y": 29,
      "z": 29,
      "name": "Rock_Sandstone"
    },
    {
      "x": -6,
      "y": 17,
      "z": 30,
      "name": "Rock_Sandstone"
    },
    {
      "x": -6,
      "y": 18,
      "z": 30,
      "name": "Soil_Sand_White"
    },
    {
      "x": -6,
      "y": 19,
      "z": 30,
      "name": "Empty"
    },
    {
      "x": -6,
      "y": 20,
      "z": 30,
      "name": "Empty"
    },
    {
      "x": -6,
      "y": 21,
      "z": 30,
      "name": "Empty"
    },
    {
      "x": -6,
      "y": 22,
      "z": 30,
      "name": "Empty"
    },
    {
      "x": -6,
      "y": 23,
      "z": 30,
      "name": "Empty"
    },
    {
      "x": -6,
      "y": 24,
      "z": 30,
      "name": "Empty"
    },
    {
      "x": -6,
      "y": 25,
      "z": 30,
      "name": "Empty"
    },
    {
      "x": -6,
      "y": 26,
      "z": 30,
      "name": "Empty"
    },
    {
      "x": -6,
      "y": 27,
      "z": 30,
      "name": "Empty"
    },
    {
      "x": -6,
      "y": 28,
      "z": 30,
      "name": "Rock_Sandstone"
    },
    {
      "x": -6,
      "y": 29,
      "z": 30,
      "name": "Rock_Sandstone"
    },
    {
      "x": -6,
      "y": 17,
      "z": 31,
      "name": "Rock_Sandstone"
    },
    {
      "x": -6,
      "y": 18,
      "z": 31,
      "name": "Soil_Sand_White"
    },
    {
      "x": -6,
      "y": 19,
      "z": 31,
      "name": "Empty"
    },
    {
      "x": -6,
      "y": 20,
      "z": 31,
      "name": "Empty"
    },
    {
      "x": -6,
      "y": 21,
      "z": 31,
      "name": "Empty"
    },
    {
      "x": -6,
      "y": 22,
      "z": 31,
      "name": "Empty"
    },
    {
      "x": -6,
      "y": 23,
      "z": 31,
      "name": "Empty"
    },
    {
      "x": -6,
      "y": 24,
      "z": 31,
      "name": "Empty"
    },
    {
      "x": -6,
      "y": 25,
      "z": 31,
      "name": "Empty"
    },
    {
      "x": -6,
      "y": 26,
      "z": 31,
      "name": "Empty"
    },
    {
      "x": -6,
      "y": 27,
      "z": 31,
      "name": "Empty"
    },
    {
      "x": -6,
      "y": 28,
      "z": 31,
      "name": "Rock_Sandstone"
    },
    {
      "x": -6,
      "y": 29,
      "z": 31,
      "name": "Rock_Sandstone"
    },
    {
      "x": -6,
      "y": 17,
      "z": 32,
      "name": "Rock_Sandstone"
    },
    {
      "x": -6,
      "y": 18,
      "z": 32,
      "name": "Soil_Sand_White"
    },
    {
      "x": -6,
      "y": 19,
      "z": 32,
      "name": "Rock_Sandstone_Brick_Half"
    },
    {
      "x": -6,
      "y": 20,
      "z": 32,
      "name": "Empty"
    },
    {
      "x": -6,
      "y": 21,
      "z": 32,
      "name": "Empty"
    },
    {
      "x": -6,
      "y": 22,
      "z": 32,
      "name": "Empty"
    },
    {
      "x": -6,
      "y": 23,
      "z": 32,
      "name": "Rock_Sandstone_Brick_Beam",
      "rotation": 5
    },
    {
      "x": -6,
      "y": 24,
      "z": 32,
      "name": "Rock_Sandstone_Brick_Beam",
      "rotation": 5
    },
    {
      "x": -6,
      "y": 25,
      "z": 32,
      "name": "Empty"
    },
    {
      "x": -6,
      "y": 26,
      "z": 32,
      "name": "Empty"
    },
    {
      "x": -6,
      "y": 27,
      "z": 32,
      "name": "Rock_Sandstone_Brick_Beam",
      "rotation": 5
    },
    {
      "x": -6,
      "y": 28,
      "z": 32,
      "name": "Rock_Sandstone"
    },
    {
      "x": -6,
      "y": 29,
      "z": 32,
      "name": "Rock_Sandstone"
    },
    {
      "x": -6,
      "y": 17,
      "z": 33,
      "name": "Rock_Sandstone"
    },
    {
      "x": -6,
      "y": 18,
      "z": 33,
      "name": "Rock_Sandstone"
    },
    {
      "x": -6,
      "y": 19,
      "z": 33,
      "name": "Rock_Crystal_Yellow_Small"
    },
    {
      "x": -6,
      "y": 20,
      "z": 33,
      "name": "Empty"
    },
    {
      "x": -6,
      "y": 21,
      "z": 33,
      "name": "Empty"
    },
    {
      "x": -6,
      "y": 22,
      "z": 33,
      "name": "Empty"
    },
    {
      "x": -6,
      "y": 23,
      "z": 33,
      "name": "Empty"
    },
    {
      "x": -6,
      "y": 24,
      "z": 33,
      "name": "Empty"
    },
    {
      "x": -6,
      "y": 25,
      "z": 33,
      "name": "Empty"
    },
    {
      "x": -6,
      "y": 26,
      "z": 33,
      "name": "Empty"
    },
    {
      "x": -6,
      "y": 27,
      "z": 33,
      "name": "Empty"
    },
    {
      "x": -6,
      "y": 28,
      "z": 33,
      "name": "Rock_Sandstone"
    },
    {
      "x": -6,
      "y": 17,
      "z": 34,
      "name": "Rock_Sandstone"
    },
    {
      "x": -6,
      "y": 18,
      "z": 34,
      "name": "Rock_Sandstone"
    },
    {
      "x": -6,
      "y": 19,
      "z": 34,
      "name": "Empty"
    },
    {
      "x": -6,
      "y": 20,
      "z": 34,
      "name": "Empty"
    },
    {
      "x": -6,
      "y": 21,
      "z": 34,
      "name": "Empty"
    },
    {
      "x": -6,
      "y": 22,
      "z": 34,
      "name": "Empty"
    },
    {
      "x": -6,
      "y": 23,
      "z": 34,
      "name": "Rock_Sandstone"
    },
    {
      "x": -6,
      "y": 24,
      "z": 34,
      "name": "Rock_Sandstone"
    },
    {
      "x": -6,
      "y": 25,
      "z": 34,
      "name": "Rock_Sandstone"
    },
    {
      "x": -6,
      "y": 26,
      "z": 34,
      "name": "Rock_Sandstone"
    },
    {
      "x": -6,
      "y": 27,
      "z": 34,
      "name": "Rock_Sandstone"
    },
    {
      "x": -6,
      "y": 28,
      "z": 34,
      "name": "Rock_Sandstone"
    },
    {
      "x": -6,
      "y": 18,
      "z": 35,
      "name": "Rock_Sandstone"
    },
    {
      "x": -6,
      "y": 19,
      "z": 35,
      "name": "Rock_Sandstone"
    },
    {
      "x": -6,
      "y": 20,
      "z": 35,
      "name": "Rock_Sandstone"
    },
    {
      "x": -6,
      "y": 21,
      "z": 35,
      "name": "Rock_Sandstone"
    },
    {
      "x": -6,
      "y": 22,
      "z": 35,
      "name": "Rock_Sandstone"
    },
    {
      "x": -6,
      "y": 23,
      "z": 35,
      "name": "Rock_Sandstone"
    },
    {
      "x": -6,
      "y": 24,
      "z": 35,
      "name": "Rock_Sandstone"
    },
    {
      "x": -6,
      "y": 25,
      "z": 35,
      "name": "Rock_Sandstone"
    },
    {
      "x": -6,
      "y": 26,
      "z": 35,
      "name": "Rock_Sandstone"
    },
    {
      "x": -6,
      "y": 27,
      "z": 35,
      "name": "Rock_Sandstone"
    },
    {
      "x": -6,
      "y": 28,
      "z": 35,
      "name": "Rock_Sandstone"
    },
    {
      "x": -5,
      "y": 18,
      "z": 21,
      "name": "Rock_Sandstone"
    },
    {
      "x": -5,
      "y": 19,
      "z": 21,
      "name": "Rock_Sandstone"
    },
    {
      "x": -5,
      "y": 20,
      "z": 21,
      "name": "Rock_Sandstone"
    },
    {
      "x": -5,
      "y": 21,
      "z": 21,
      "name": "Rock_Sandstone"
    },
    {
      "x": -5,
      "y": 22,
      "z": 21,
      "name": "Rock_Sandstone"
    },
    {
      "x": -5,
      "y": 23,
      "z": 21,
      "name": "Rock_Sandstone"
    },
    {
      "x": -5,
      "y": 24,
      "z": 21,
      "name": "Rock_Sandstone"
    },
    {
      "x": -5,
      "y": 25,
      "z": 21,
      "name": "Rock_Sandstone"
    },
    {
      "x": -5,
      "y": 26,
      "z": 21,
      "name": "Rock_Sandstone"
    },
    {
      "x": -5,
      "y": 27,
      "z": 21,
      "name": "Rock_Sandstone"
    },
    {
      "x": -5,
      "y": 28,
      "z": 21,
      "name": "Rock_Sandstone"
    },
    {
      "x": -5,
      "y": 17,
      "z": 22,
      "name": "Rock_Sandstone"
    },
    {
      "x": -5,
      "y": 18,
      "z": 22,
      "name": "Soil_Gravel_Sand_White"
    },
    {
      "x": -5,
      "y": 19,
      "z": 22,
      "name": "Empty"
    },
    {
      "x": -5,
      "y": 20,
      "z": 22,
      "name": "Empty"
    },
    {
      "x": -5,
      "y": 21,
      "z": 22,
      "name": "Empty"
    },
    {
      "x": -5,
      "y": 22,
      "z": 22,
      "name": "Empty"
    },
    {
      "x": -5,
      "y": 23,
      "z": 22,
      "name": "Empty"
    },
    {
      "x": -5,
      "y": 24,
      "z": 22,
      "name": "Empty"
    },
    {
      "x": -5,
      "y": 25,
      "z": 22,
      "name": "Empty"
    },
    {
      "x": -5,
      "y": 26,
      "z": 22,
      "name": "Rock_Sandstone"
    },
    {
      "x": -5,
      "y": 27,
      "z": 22,
      "name": "Rock_Sandstone"
    },
    {
      "x": -5,
      "y": 28,
      "z": 22,
      "name": "Rock_Sandstone"
    },
    {
      "x": -5,
      "y": 17,
      "z": 23,
      "name": "Rock_Sandstone"
    },
    {
      "x": -5,
      "y": 18,
      "z": 23,
      "name": "Soil_Sand_White"
    },
    {
      "x": -5,
      "y": 19,
      "z": 23,
      "name": "Deco_Bone_Pile"
    },
    {
      "x": -5,
      "y": 20,
      "z": 23,
      "name": "Empty"
    },
    {
      "x": -5,
      "y": 21,
      "z": 23,
      "name": "Empty"
    },
    {
      "x": -5,
      "y": 22,
      "z": 23,
      "name": "Empty"
    },
    {
      "x": -5,
      "y": 23,
      "z": 23,
      "name": "Empty"
    },
    {
      "x": -5,
      "y": 24,
      "z": 23,
      "name": "Empty"
    },
    {
      "x": -5,
      "y": 25,
      "z": 23,
      "name": "Empty"
    },
    {
      "x": -5,
      "y": 26,
      "z": 23,
      "name": "Empty"
    },
    {
      "x": -5,
      "y": 27,
      "z": 23,
      "name": "Empty"
    },
    {
      "x": -5,
      "y": 28,
      "z": 23,
      "name": "Rock_Sandstone"
    },
    {
      "x": -5,
      "y": 29,
      "z": 23,
      "name": "Rock_Sandstone"
    },
    {
      "x": -5,
      "y": 17,
      "z": 24,
      "name": "Rock_Sandstone"
    },
    {
      "x": -5,
      "y": 18,
      "z": 24,
      "name": "Soil_Sand_White"
    },
    {
      "x": -5,
      "y": 19,
      "z": 24,
      "name": "Empty"
    },
    {
      "x": -5,
      "y": 20,
      "z": 24,
      "name": "Empty"
    },
    {
      "x": -5,
      "y": 21,
      "z": 24,
      "name": "Empty"
    },
    {
      "x": -5,
      "y": 22,
      "z": 24,
      "name": "Empty"
    },
    {
      "x": -5,
      "y": 23,
      "z": 24,
      "name": "Empty"
    },
    {
      "x": -5,
      "y": 24,
      "z": 24,
      "name": "Empty"
    },
    {
      "x": -5,
      "y": 25,
      "z": 24,
      "name": "Empty"
    },
    {
      "x": -5,
      "y": 26,
      "z": 24,
      "name": "Empty"
    },
    {
      "x": -5,
      "y": 27,
      "z": 24,
      "name": "Empty"
    },
    {
      "x": -5,
      "y": 28,
      "z": 24,
      "name": "Rock_Sandstone"
    },
    {
      "x": -5,
      "y": 29,
      "z": 24,
      "name": "Rock_Sandstone"
    },
    {
      "x": -5,
      "y": 17,
      "z": 25,
      "name": "Rock_Sandstone"
    },
    {
      "x": -5,
      "y": 18,
      "z": 25,
      "name": "Soil_Gravel_Sand_White"
    },
    {
      "x": -5,
      "y": 19,
      "z": 25,
      "name": "Empty"
    },
    {
      "x": -5,
      "y": 20,
      "z": 25,
      "name": "Empty"
    },
    {
      "x": -5,
      "y": 21,
      "z": 25,
      "name": "Empty"
    },
    {
      "x": -5,
      "y": 22,
      "z": 25,
      "name": "Empty"
    },
    {
      "x": -5,
      "y": 23,
      "z": 25,
      "name": "Empty"
    },
    {
      "x": -5,
      "y": 24,
      "z": 25,
      "name": "Empty"
    },
    {
      "x": -5,
      "y": 25,
      "z": 25,
      "name": "Empty"
    },
    {
      "x": -5,
      "y": 26,
      "z": 25,
      "name": "Empty"
    },
    {
      "x": -5,
      "y": 27,
      "z": 25,
      "name": "Empty"
    },
    {
      "x": -5,
      "y": 28,
      "z": 25,
      "name": "Rock_Sandstone"
    },
    {
      "x": -5,
      "y": 29,
      "z": 25,
      "name": "Rock_Sandstone"
    },
    {
      "x": -5,
      "y": 17,
      "z": 26,
      "name": "Rock_Sandstone"
    },
    {
      "x": -5,
      "y": 18,
      "z": 26,
      "name": "Soil_Sand_White"
    },
    {
      "x": -5,
      "y": 19,
      "z": 26,
      "name": "Empty"
    },
    {
      "x": -5,
      "y": 20,
      "z": 26,
      "name": "Empty"
    },
    {
      "x": -5,
      "y": 21,
      "z": 26,
      "name": "Empty"
    },
    {
      "x": -5,
      "y": 22,
      "z": 26,
      "name": "Empty"
    },
    {
      "x": -5,
      "y": 23,
      "z": 26,
      "name": "Empty"
    },
    {
      "x": -5,
      "y": 24,
      "z": 26,
      "name": "Empty"
    },
    {
      "x": -5,
      "y": 25,
      "z": 26,
      "name": "Empty"
    },
    {
      "x": -5,
      "y": 26,
      "z": 26,
      "name": "Empty"
    },
    {
      "x": -5,
      "y": 27,
      "z": 26,
      "name": "Empty"
    },
    {
      "x": -5,
      "y": 28,
      "z": 26,
      "name": "Plant_Roots_Cave",
      "rotation": 11
    },
    {
      "x": -5,
      "y": 29,
      "z": 26,
      "name": "Rock_Sandstone"
    },
    {
      "x": -5,
      "y": 17,
      "z": 27,
      "name": "Rock_Sandstone"
    },
    {
      "x": -5,
      "y": 18,
      "z": 27,
      "name": "Soil_Sand_White"
    },
    {
      "x": -5,
      "y": 19,
      "z": 27,
      "name": "Empty"
    },
    {
      "x": -5,
      "y": 20,
      "z": 27,
      "name": "Empty"
    },
    {
      "x": -5,
      "y": 21,
      "z": 27,
      "name": "Empty"
    },
    {
      "x": -5,
      "y": 22,
      "z": 27,
      "name": "Empty"
    },
    {
      "x": -5,
      "y": 23,
      "z": 27,
      "name": "Empty"
    },
    {
      "x": -5,
      "y": 24,
      "z": 27,
      "name": "Empty"
    },
    {
      "x": -5,
      "y": 25,
      "z": 27,
      "name": "Empty"
    },
    {
      "x": -5,
      "y": 26,
      "z": 27,
      "name": "Empty"
    },
    {
      "x": -5,
      "y": 27,
      "z": 27,
      "name": "Empty"
    },
    {
      "x": -5,
      "y": 28,
      "z": 27,
      "name": "Empty"
    },
    {
      "x": -5,
      "y": 29,
      "z": 27,
      "name": "Rock_Sandstone"
    },
    {
      "x": -5,
      "y": 17,
      "z": 28,
      "name": "Rock_Sandstone"
    },
    {
      "x": -5,
      "y": 18,
      "z": 28,
      "name": "Soil_Gravel_Sand_White"
    },
    {
      "x": -5,
      "y": 19,
      "z": 28,
      "name": "Empty"
    },
    {
      "x": -5,
      "y": 20,
      "z": 28,
      "name": "Empty"
    },
    {
      "x": -5,
      "y": 21,
      "z": 28,
      "name": "Empty"
    },
    {
      "x": -5,
      "y": 22,
      "z": 28,
      "name": "Empty"
    },
    {
      "x": -5,
      "y": 23,
      "z": 28,
      "name": "Empty"
    },
    {
      "x": -5,
      "y": 24,
      "z": 28,
      "name": "Empty"
    },
    {
      "x": -5,
      "y": 25,
      "z": 28,
      "name": "Empty"
    },
    {
      "x": -5,
      "y": 26,
      "z": 28,
      "name": "Empty"
    },
    {
      "x": -5,
      "y": 27,
      "z": 28,
      "name": "Empty"
    },
    {
      "x": -5,
      "y": 28,
      "z": 28,
      "name": "Empty"
    },
    {
      "x": -5,
      "y": 29,
      "z": 28,
      "name": "Rock_Sandstone"
    },
    {
      "x": -5,
      "y": 17,
      "z": 29,
      "name": "Rock_Sandstone"
    },
    {
      "x": -5,
      "y": 18,
      "z": 29,
      "name": "Soil_Sand_White"
    },
    {
      "x": -5,
      "y": 19,
      "z": 29,
      "name": "Empty"
    },
    {
      "x": -5,
      "y": 20,
      "z": 29,
      "name": "Empty"
    },
    {
      "x": -5,
      "y": 21,
      "z": 29,
      "name": "Empty"
    },
    {
      "x": -5,
      "y": 22,
      "z": 29,
      "name": "Empty"
    },
    {
      "x": -5,
      "y": 23,
      "z": 29,
      "name": "Empty"
    },
    {
      "x": -5,
      "y": 24,
      "z": 29,
      "name": "Empty"
    },
    {
      "x": -5,
      "y": 25,
      "z": 29,
      "name": "Empty"
    },
    {
      "x": -5,
      "y": 26,
      "z": 29,
      "name": "Empty"
    },
    {
      "x": -5,
      "y": 27,
      "z": 29,
      "name": "Empty"
    },
    {
      "x": -5,
      "y": 28,
      "z": 29,
      "name": "Rock_Sandstone"
    },
    {
      "x": -5,
      "y": 29,
      "z": 29,
      "name": "Rock_Sandstone"
