{
  "version": 8,
  "blockIdVersion": 8,
  "anchorX": -1,
  "anchorY": 8,
  "anchorZ": 0,
  "blocks": [
    {
      "x": -5,
      "y": 7,
      "z": -2,
      "name": "Rock_Basalt"
    },
    {
      "x": -5,
      "y": 8,
      "z": -2,
      "name": "Rock_Basalt"
    },
    {
      "x": -5,
      "y": 7,
      "z": -1,
      "name": "Rock_Basalt"
    },
    {
      "x": -5,
      "y": 8,
      "z": -1,
      "name": "Rock_Basalt"
    },
    {
      "x": -5,
      "y": 9,
      "z": -1,
      "name": "Rock_Basalt"
    },
    {
      "x": -5,
      "y": 7,
      "z": 0,
      "name": "Rock_Basalt"
    },
    {
      "x": -5,
      "y": 8,
      "z": 0,
      "name": "Rock_Basalt"
    },
    {
      "x": -5,
      "y": 9,
      "z": 0,
      "name": "Rock_Basalt"
    },
    {
      "x": -5,
      "y": 7,
      "z": 1,
      "name": "Rock_Basalt"
    },
    {
      "x": -5,
      "y": 8,
      "z": 1,
      "name": "Rock_Basalt"
    },
    {
      "x": -5,
      "y": 9,
      "z": 1,
      "name": "Rock_Basalt"
    },
    {
      "x": -5,
      "y": 16,
      "z": 1,
      "name": "Plant_Crop_Mushroom_Block_Purple"
    },
    {
      "x": -5,
      "y": 17,
      "z": 1,
      "name": "Plant_Crop_Mushroom_Glowing_Purple"
    },
    {
      "x": -5,
      "y": 8,
      "z": 2,
      "name": "Rock_Basalt"
    },
    {
      "x": -5,
      "y": 16,
      "z": 2,
      "name": "Plant_Crop_Mushroom_Block_Purple"
    },
    {
      "x": -5,
      "y": 17,
      "z": 2,
      "name": "Plant_Crop_Mushroom_Glowing_Purple"
    },
    {
      "x": -5,
      "y": 16,
      "z": 3,
      "name": "Plant_Crop_Mushroom_Block_Purple"
    },
    {
      "x": -5,
      "y": 16,
      "z": 4,
      "name": "Plant_Crop_Mushroom_Block_Purple"
    },
    {
      "x": -4,
      "y": 30,
      "z": -4,
      "name": "Plant_Crop_Mushroom_Block_Purple"
    },
    {
      "x": -4,
      "y": 31,
      "z": -4,
      "name": "Plant_Crop_Mushroom_Glowing_Purple"
    },
    {
      "x": -4,
      "y": 7,
      "z": -3,
      "name": "Rock_Basalt"
    },
    {
      "x": -4,
      "y": 8,
      "z": -3,
      "name": "Rock_Basalt"
    },
    {
      "x": -4,
      "y": 9,
      "z": -3,
      "name": "Rock_Basalt"
    },
    {
      "x": -4,
      "y": 30,
      "z": -3,
      "name": "Plant_Crop_Mushroom_Block_Purple"
    },
    {
      "x": -4,
      "y": 31,
      "z": -3,
      "name": "Plant_Crop_Mushroom_Glowing_Purple"
    },
    {
      "x": -4,
      "y": 6,
      "z": -2,
      "name": "Rock_Basalt"
    },
    {
      "x": -4,
      "y": 7,
      "z": -2,
      "name": "Rock_Basalt"
    },
    {
      "x": -4,
      "y": 8,
      "z": -2,
      "name": "Rock_Basalt"
    },
    {
      "x": -4,
      "y": 9,
      "z": -2,
      "name": "Rock_Basalt"
    },
    {
      "x": -4,
      "y": 30,
      "z": -2,
      "name": "Plant_Crop_Mushroom_Block_Purple"
    },
    {
      "x": -4,
      "y": 6,
      "z": -1,
      "name": "Rock_Basalt"
    },
    {
      "x": -4,
      "y": 7,
      "z": -1,
      "name": "Rock_Basalt"
    },
    {
      "x": -4,
      "y": 8,
      "z": -1,
      "name": "Rock_Basalt"
    },
    {
      "x": -4,
      "y": 9,
      "z": -1,
      "name": "Rock_Basalt"
    },
    {
      "x": -4,
      "y": 10,
      "z": -1,
      "name": "Rock_Basalt"
    },
    {
      "x": -4,
      "y": 6,
      "z": 0,
      "name": "Rock_Basalt"
    },
    {
      "x": -4,
      "y": 7,
      "z": 0,
      "name": "Rock_Basalt"
    },
    {
      "x": -4,
      "y": 8,
      "z": 0,
      "name": "Rock_Basalt"
    },
    {
      "x": -4,
      "y": 9,
      "z": 0,
      "name": "Rock_Basalt"
    },
    {
      "x": -4,
      "y": 10,
      "z": 0,
      "name": "Rock_Basalt"
    },
    {
      "x": -4,
      "y": 6,
      "z": 1,
      "name": "Rock_Basalt"
    },
    {
      "x": -4,
      "y": 7,
      "z": 1,
      "name": "Rock_Basalt"
    },
    {
      "x": -4,
      "y": 8,
      "z": 1,
      "name": "Rock_Basalt"
    },
    {
      "x": -4,
      "y": 9,
      "z": 1,
      "name": "Rock_Basalt"
    },
    {
      "x": -4,
      "y": 10,
      "z": 1,
      "name": "Rock_Basalt_Cobble"
    },
    {
      "x": -4,
      "y": 16,
      "z": 1,
      "name": "Plant_Crop_Mushroom_Block_Purple"
    },
    {
      "x": -4,
      "y": 17,
      "z": 1,
      "name": "Plant_Crop_Mushroom_Glowing_Purple"
    },
    {
      "x": -4,
      "y": 7,
      "z": 2,
      "name": "Rock_Basalt"
    },
    {
      "x": -4,
      "y": 8,
      "z": 2,
      "name": "Rock_Basalt"
    },
    {
      "x": -4,
      "y": 9,
      "z": 2,
      "name": "Rock_Basalt_Cobble"
    },
    {
      "x": -4,
      "y": 17,
      "z": 2,
      "name": "Plant_Crop_Mushroom_Block_Purple"
    },
    {
      "x": -4,
      "y": 7,
      "z": 3,
      "name": "Rock_Basalt"
    },
    {
      "x": -4,
      "y": 8,
      "z": 3,
      "name": "Rock_Basalt_Cobble"
    },
    {
      "x": -4,
      "y": 9,
      "z": 3,
      "name": "Rock_Basalt_Cobble"
    },
    {
      "x": -4,
      "y": 16,
      "z": 3,
      "name": "Plant_Crop_Mushroom_Block_Purple_Mycelium"
    },
    {
      "x": -4,
      "y": 17,
      "z": 3,
      "name": "Plant_Crop_Mushroom_Block_Purple"
    },
    {
      "x": -4,
      "y": 16,
      "z": 4,
      "name": "Plant_Crop_Mushroom_Block_Purple"
    },
    {
      "x": -4,
      "y": 16,
      "z": 5,
      "name": "Plant_Crop_Mushroom_Block_Purple"
    },
    {
      "x": -3,
      "y": 30,
      "z": -5,
      "name": "Plant_Crop_Mushroom_Block_Purple"
    },
    {
      "x": -3,
      "y": 31,
      "z": -5,
      "name": "Plant_Crop_Mushroom_Glowing_Purple"
    },
    {
      "x": -3,
      "y": 7,
      "z": -4,
      "name": "Rock_Basalt"
    },
    {
      "x": -3,
      "y": 8,
      "z": -4,
      "name": "Rock_Basalt"
    },
    {
      "x": -3,
      "y": 9,
      "z": -4,
      "name": "Rock_Basalt"
    },
    {
      "x": -3,
      "y": 31,
      "z": -4,
      "name": "Plant_Crop_Mushroom_Block_Purple"
    },
    {
      "x": -3,
      "y": 32,
      "z": -4,
      "name": "Plant_Crop_Mushroom_Glowing_Purple"
    },
    {
      "x": -3,
      "y": 35,
      "z": -4,
      "name": "Soil_Gravel"
    },
    {
      "x": -3,
      "y": 36,
      "z": -4,
      "name": "Soil_Gravel"
    },
    {
      "x": -3,
      "y": 37,
      "z": -4,
      "name": "Soil_Gravel"
    },
    {
      "x": -3,
      "y": 38,
      "z": -4,
      "name": "Soil_Gravel"
    },
    {
      "x": -3,
      "y": 6,
      "z": -3,
      "name": "Rock_Basalt"
    },
    {
      "x": -3,
      "y": 7,
      "z": -3,
      "name": "Rock_Basalt"
    },
    {
      "x": -3,
      "y": 8,
      "z": -3,
      "name": "Rock_Basalt"
    },
    {
      "x": -3,
      "y": 9,
      "z": -3,
      "name": "Rock_Basalt"
    },
    {
      "x": -3,
      "y": 10,
      "z": -3,
      "name": "Rock_Basalt"
    },
    {
      "x": -3,
      "y": 30,
      "z": -3,
      "name": "Plant_Crop_Mushroom_Block_Purple_Mycelium"
    },
    {
      "x": -3,
      "y": 31,
      "z": -3,
      "name": "Plant_Crop_Mushroom_Block_Purple"
    },
    {
      "x": -3,
      "y": 34,
      "z": -3,
      "name": "Soil_Gravel"
    },
    {
      "x": -3,
      "y": 35,
      "z": -3,
      "name": "Soil_Gravel"
    },
    {
      "x": -3,
      "y": 36,
      "z": -3,
      "name": "Soil_Gravel"
    },
    {
      "x": -3,
      "y": 37,
      "z": -3,
      "name": "Soil_Gravel"
    },
    {
      "x": -3,
      "y": 38,
      "z": -3,
      "name": "Rock_Basalt_Cobble"
    },
    {
      "x": -3,
      "y": 6,
      "z": -2,
      "name": "Rock_Basalt"
    },
    {
      "x": -3,
      "y": 7,
      "z": -2,
      "name": "Rock_Basalt"
    },
    {
      "x": -3,
      "y": 8,
      "z": -2,
      "name": "Rock_Basalt"
    },
    {
      "x": -3,
      "y": 9,
      "z": -2,
      "name": "Rock_Basalt"
    },
    {
      "x": -3,
      "y": 10,
      "z": -2,
      "name": "Rock_Basalt"
    },
    {
      "x": -3,
      "y": 21,
      "z": -2,
      "name": "Rock_Basalt"
    },
    {
      "x": -3,
      "y": 22,
      "z": -2,
      "name": "Rock_Basalt"
    },
    {
      "x": -3,
      "y": 23,
      "z": -2,
      "name": "Rock_Basalt"
    },
    {
      "x": -3,
      "y": 24,
      "z": -2,
      "name": "Rock_Basalt"
    },
    {
      "x": -3,
      "y": 31,
      "z": -2,
      "name": "Plant_Crop_Mushroom_Block_Purple"
    },
    {
      "x": -3,
      "y": 34,
      "z": -2,
      "name": "Soil_Gravel"
    },
    {
      "x": -3,
      "y": 35,
      "z": -2,
      "name": "Soil_Gravel"
    },
    {
      "x": -3,
      "y": 36,
      "z": -2,
      "name": "Rock_Basalt_Cobble"
    },
    {
      "x": -3,
      "y": 37,
      "z": -2,
      "name": "Rock_Basalt_Cobble"
    },
    {
      "x": -3,
      "y": 38,
      "z": -2,
      "name": "Rock_Basalt_Cobble"
    },
    {
      "x": -3,
      "y": 6,
      "z": -1,
      "name": "Rock_Basalt"
    },
    {
      "x": -3,
      "y": 7,
      "z": -1,
      "name": "Rock_Basalt"
    },
    {
      "x": -3,
      "y": 8,
      "z": -1,
      "name": "Rock_Basalt"
    },
    {
      "x": -3,
      "y": 9,
      "z": -1,
      "name": "Rock_Basalt"
    },
    {
      "x": -3,
      "y": 10,
      "z": -1,
      "name": "Rock_Basalt"
    },
    {
      "x": -3,
      "y": 11,
      "z": -1,
      "name": "Rock_Basalt_Cobble"
    },
    {
      "x": -3,
      "y": 12,
      "z": -1,
      "name": "Rock_Basalt_Cobble"
    },
    {
      "x": -3,
      "y": 16,
      "z": -1,
      "name": "Rock_Basalt_Cobble"
    },
    {
      "x": -3,
      "y": 17,
      "z": -1,
      "name": "Rock_Basalt"
    },
    {
      "x": -3,
      "y": 18,
      "z": -1,
      "name": "Rock_Basalt"
    },
    {
      "x": -3,
      "y": 19,
      "z": -1,
      "name": "Rock_Basalt"
    },
    {
      "x": -3,
      "y": 20,
      "z": -1,
      "name": "Rock_Basalt"
    },
    {
      "x": -3,
      "y": 21,
      "z": -1,
      "name": "Rock_Basalt"
    },
    {
      "x": -3,
      "y": 22,
      "z": -1,
      "name": "Rock_Basalt"
    },
    {
      "x": -3,
      "y": 23,
      "z": -1,
      "name": "Rock_Basalt"
    },
    {
      "x": -3,
      "y": 24,
      "z": -1,
      "name": "Rock_Basalt"
    },
    {
      "x": -3,
      "y": 25,
      "z": -1,
      "name": "Rock_Basalt"
    },
    {
      "x": -3,
      "y": 29,
      "z": -1,
      "name": "Plant_Crop_Mushroom_Block_Purple_Mycelium"
    },
    {
      "x": -3,
      "y": 30,
      "z": -1,
      "name": "Plant_Crop_Mushroom_Block_Purple"
    },
    {
      "x": -3,
      "y": 34,
      "z": -1,
      "name": "Rock_Basalt_Cobble"
    },
    {
      "x": -3,
      "y": 35,
      "z": -1,
      "name": "Rock_Basalt_Cobble"
    },
    {
      "x": -3,
      "y": 36,
      "z": -1,
      "name": "Rock_Basalt"
    },
    {
      "x": -3,
      "y": 37,
      "z": -1,
      "name": "Rock_Basalt"
    },
    {
      "x": -3,
      "y": 38,
      "z": -1,
      "name": "Rock_Basalt"
    },
    {
      "x": -3,
      "y": 39,
      "z": -1,
      "name": "Rock_Basalt"
    },
    {
      "x": -3,
      "y": 6,
      "z": 0,
      "name": "Rock_Basalt"
    },
    {
      "x": -3,
      "y": 7,
      "z": 0,
      "name": "Rock_Basalt"
    },
    {
      "x": -3,
      "y": 8,
      "z": 0,
      "name": "Rock_Basalt"
    },
    {
      "x": -3,
      "y": 9,
      "z": 0,
      "name": "Rock_Basalt"
    },
    {
      "x": -3,
      "y": 10,
      "z": 0,
      "name": "Rock_Basalt_Cobble"
    },
    {
      "x": -3,
      "y": 11,
      "z": 0,
      "name": "Rock_Basalt_Cobble"
    },
    {
      "x": -3,
      "y": 12,
      "z": 0,
      "name": "Rock_Basalt_Cobble"
    },
    {
      "x": -3,
      "y": 13,
      "z": 0,
      "name": "Rock_Basalt_Cobble"
    },
    {
      "x": -3,
      "y": 14,
      "z": 0,
      "name": "Rock_Basalt_Cobble"
    },
    {
      "x": -3,
      "y": 15,
      "z": 0,
      "name": "Rock_Basalt_Cobble"
    },
    {
      "x": -3,
      "y": 16,
      "z": 0,
      "name": "Rock_Basalt_Cobble"
    },
    {
      "x": -3,
      "y": 17,
      "z": 0,
      "name": "Rock_Basalt_Cobble"
    },
    {
      "x": -3,
      "y": 18,
      "z": 0,
      "name": "Rock_Basalt"
    },
    {
      "x": -3,
      "y": 19,
      "z": 0,
      "name": "Rock_Basalt"
    },
    {
      "x": -3,
      "y": 20,
      "z": 0,
      "name": "Rock_Basalt"
    },
    {
      "x": -3,
      "y": 21,
      "z": 0,
      "name": "Rock_Basalt"
    },
    {
      "x": -3,
      "y": 22,
      "z": 0,
      "name": "Rock_Basalt"
    },
    {
      "x": -3,
      "y": 23,
      "z": 0,
      "name": "Rock_Basalt"
    },
    {
      "x": -3,
      "y": 34,
      "z": 0,
      "name": "Rock_Basalt"
    },
    {
      "x": -3,
      "y": 35,
      "z": 0,
      "name": "Rock_Basalt"
    },
    {
      "x": -3,
      "y": 36,
      "z": 0,
      "name": "Rock_Basalt"
    },
    {
      "x": -3,
      "y": 37,
      "z": 0,
      "name": "Rock_Basalt"
    },
    {
      "x": -3,
      "y": 38,
      "z": 0,
      "name": "Rock_Basalt"
    },
    {
      "x": -3,
      "y": 39,
      "z": 0,
      "name": "Rock_Basalt"
    },
    {
      "x": -3,
      "y": 6,
      "z": 1,
      "name": "Rock_Basalt"
    },
    {
      "x": -3,
      "y": 7,
      "z": 1,
      "name": "Rock_Basalt"
    },
    {
      "x": -3,
      "y": 8,
      "z": 1,
      "name": "Rock_Basalt"
    },
    {
      "x": -3,
      "y": 9,
      "z": 1,
      "name": "Rock_Basalt"
    },
    {
      "x": -3,
      "y": 10,
      "z": 1,
      "name": "Rock_Basalt_Cobble"
    },
    {
      "x": -3,
      "y": 11,
      "z": 1,
      "name": "Rock_Basalt_Cobble"
    },
    {
      "x": -3,
      "y": 12,
      "z": 1,
      "name": "Rock_Basalt_Cobble"
    },
    {
      "x": -3,
      "y": 13,
      "z": 1,
      "name": "Rock_Basalt_Cobble"
    },
    {
      "x": -3,
      "y": 14,
      "z": 1,
      "name": "Rock_Basalt_Cobble"
    },
    {
      "x": -3,
      "y": 15,
      "z": 1,
      "name": "Rock_Basalt_Cobble"
    },
    {
      "x": -3,
      "y": 16,
      "z": 1,
      "name": "Rock_Basalt_Cobble"
    },
    {
      "x": -3,
      "y": 17,
      "z": 1,
      "name": "Rock_Basalt_Cobble"
    },
    {
      "x": -3,
      "y": 18,
      "z": 1,
      "name": "Rock_Basalt"
    },
    {
      "x": -3,
      "y": 19,
      "z": 1,
      "name": "Rock_Basalt"
    },
    {
      "x": -3,
      "y": 34,
      "z": 1,
      "name": "Rock_Basalt"
    },
    {
      "x": -3,
      "y": 35,
      "z": 1,
      "name": "Rock_Basalt"
    },
    {
      "x": -3,
      "y": 36,
      "z": 1,
      "name": "Rock_Basalt"
    },
    {
      "x": -3,
      "y": 37,
      "z": 1,
      "name": "Rock_Basalt"
    },
    {
      "x": -3,
      "y": 38,
      "z": 1,
      "name": "Rock_Basalt_Cobble"
    },
    {
      "x": -3,
      "y": 39,
      "z": 1,
      "name": "Rock_Basalt_Cobble"
    },
    {
      "x": -3,
      "y": 6,
      "z": 2,
      "name": "Rock_Basalt"
    },
    {
      "x": -3,
      "y": 7,
      "z": 2,
      "name": "Rock_Basalt"
    },
    {
      "x": -3,
      "y": 8,
      "z": 2,
      "name": "Rock_Basalt_Cobble"
    },
    {
      "x": -3,
      "y": 9,
      "z": 2,
      "name": "Rock_Basalt_Cobble"
    },
    {
      "x": -3,
      "y": 10,
      "z": 2,
      "name": "Rock_Basalt_Cobble"
    },
    {
      "x": -3,
      "y": 11,
      "z": 2,
      "name": "Rock_Basalt_Cobble"
    },
    {
      "x": -3,
      "y": 12,
      "z": 2,
      "name": "Rock_Basalt_Cobble"
    },
    {
      "x": -3,
      "y": 13,
      "z": 2,
      "name": "Rock_Basalt_Cobble"
    },
    {
      "x": -3,
      "y": 14,
      "z": 2,
      "name": "Plant_Crop_Mushroom_Block_Purple_Trunk"
    },
    {
      "x": -3,
      "y": 15,
      "z": 2,
      "name": "Plant_Crop_Mushroom_Block_Purple_Trunk"
    },
    {
      "x": -3,
      "y": 16,
      "z": 2,
      "name": "Plant_Crop_Mushroom_Block_Purple"
    },
    {
      "x": -3,
      "y": 17,
      "z": 2,
      "name": "Plant_Crop_Mushroom_Block_Purple"
    },
    {
      "x": -3,
      "y": 37,
      "z": 2,
      "name": "Rock_Basalt_Cobble"
    },
    {
      "x": -3,
      "y": 38,
      "z": 2,
      "name": "Rock_Basalt_Cobble"
    },
    {
      "x": -3,
      "y": 39,
      "z": 2,
      "name": "Rock_Basalt_Cobble"
    },
    {
      "x": -3,
      "y": 6,
      "z": 3,
      "name": "Rock_Basalt"
    },
    {
      "x": -3,
      "y": 7,
      "z": 3,
      "name": "Rock_Basalt_Cobble"
    },
    {
      "x": -3,
      "y": 8,
      "z": 3,
      "name": "Rock_Basalt_Cobble"
    },
    {
      "x": -3,
      "y": 9,
      "z": 3,
      "name": "Rock_Basalt_Cobble"
    },
    {
      "x": -3,
      "y": 10,
      "z": 3,
      "name": "Rock_Basalt_Cobble"
    },
    {
      "x": -3,
      "y": 11,
      "z": 3,
      "name": "Rock_Basalt_Cobble"
    },
    {
      "x": -3,
      "y": 12,
      "z": 3,
      "name": "Rock_Basalt_Cobble"
    },
    {
      "x": -3,
      "y": 13,
      "z": 3,
      "name": "Plant_Crop_Mushroom_Block_Purple_Trunk"
    },
    {
      "x": -3,
      "y": 14,
      "z": 3,
      "name": "Plant_Crop_Mushroom_Block_Purple_Trunk"
    },
    {
      "x": -3,
      "y": 17,
      "z": 3,
      "name": "Rock_Crystal_Purple_Block",
      "rotation": 4
    },
    {
      "x": -3,
      "y": 18,
      "z": 3,
      "name": "Plant_Crop_Mushroom_Glowing_Purple"
    },
    {
      "x": -3,
      "y": 39,
      "z": 3,
      "name": "Rock_Basalt_Cobble"
    },
    {
      "x": -3,
      "y": 7,
      "z": 4,
      "name": "Rock_Basalt_Cobble"
    },
    {
      "x": -3,
      "y": 8,
      "z": 4,
      "name": "Rock_Basalt_Cobble"
    },
    {
      "x": -3,
      "y": 9,
      "z": 4,
      "name": "Rock_Basalt_Cobble"
    },
    {
      "x": -3,
      "y": 16,
      "z": 4,
      "name": "Plant_Crop_Mushroom_Block_Purple_Mycelium"
    },
    {
      "x": -3,
      "y": 17,
      "z": 4,
      "name": "Plant_Crop_Mushroom_Block_Purple"
    },
    {
      "x": -3,
      "y": 16,
      "z": 5,
      "name": "Plant_Crop_Mushroom_Block_Purple"
    },
    {
      "x": -2,
      "y": 8,
      "z": -5,
      "name": "Rock_Basalt"
    },
    {
      "x": -2,
      "y": 30,
      "z": -5,
      "name": "Plant_Crop_Mushroom_Block_Purple"
    },
    {
      "x": -2,
      "y": 31,
      "z": -5,
      "name": "Plant_Crop_Mushroom_Block_Purple"
    },
    {
      "x": -2,
      "y": 36,
      "z": -5,
      "name": "Rock_Basalt_Cobble"
    },
    {
      "x": -2,
      "y": 37,
      "z": -5,
      "name": "Rock_Basalt_Cobble"
    },
    {
      "x": -2,
      "y": 38,
      "z": -5,
      "name": "Rock_Basalt_Cobble"
    },
    {
      "x": -2,
      "y": 7,
      "z": -4,
      "name": "Rock_Basalt"
    },
    {
      "x": -2,
      "y": 8,
      "z": -4,
      "name": "Rock_Basalt"
    },
    {
      "x": -2,
      "y": 9,
      "z": -4,
      "name": "Rock_Basalt"
    },
    {
      "x": -2,
      "y": 29,
      "z": -4,
      "name": "Plant_Crop_Mushroom_Block_Purple_Mycelium"
    },
    {
      "x": -2,
      "y": 30,
      "z": -4,
      "name": "Plant_Crop_Mushroom_Block_Purple_Mycelium"
    },
    {
      "x": -2,
      "y": 31,
      "z": -4,
      "name": "Rock_Crystal_Purple_Block",
      "rotation": 5
    },
    {
      "x": -2,
      "y": 34,
      "z": -4,
      "name": "Rock_Basalt_Cobble"
    },
    {
      "x": -2,
      "y": 35,
      "z": -4,
      "name": "Soil_Gravel"
    },
    {
      "x": -2,
      "y": 36,
      "z": -4,
      "name": "Rock_Basalt_Cobble"
    },
    {
      "x": -2,
      "y": 37,
      "z": -4,
      "name": "Soil_Gravel"
    },
    {
      "x": -2,
      "y": 38,
      "z": -4,
      "name": "Rock_Basalt_Cobble"
    },
    {
      "x": -2,
      "y": 39,
      "z": -4,
      "name": "Rock_Basalt_Cobble"
    },
    {
      "x": -2,
      "y": 6,
      "z": -3,
      "name": "Rock_Basalt"
    },
    {
      "x": -2,
      "y": 7,
      "z": -3,
      "name": "Rock_Basalt"
    },
    {
      "x": -2,
      "y": 8,
      "z": -3,
      "name": "Rock_Basalt"
    },
    {
      "x": -2,
      "y": 9,
      "z": -3,
      "name": "Rock_Basalt"
    },
    {
      "x": -2,
      "y": 10,
      "z": -3,
      "name": "Rock_Basalt"
    },
    {
      "x": -2,
      "y": 18,
      "z": -3,
      "name": "Rock_Basalt_Cobble"
    },
    {
      "x": -2,
      "y": 19,
      "z": -3,
      "name": "Rock_Basalt_Cobble"
    },
    {
      "x": -2,
      "y": 20,
      "z": -3,
      "name": "Rock_Basalt_Cobble"
    },
    {
      "x": -2,
      "y": 21,
      "z": -3,
      "name": "Rock_Basalt_Cobble"
    },
    {
      "x": -2,
      "y": 22,
      "z": -3,
      "name": "Rock_Basalt_Cobble"
    },
    {
      "x": -2,
      "y": 23,
      "z": -3,
      "name": "Rock_Basalt_Cobble"
    },
    {
      "x": -2,
      "y": 24,
      "z": -3,
      "name": "Rock_Basalt_Cobble"
    },
    {
      "x": -2,
      "y": 25,
      "z": -3,
      "name": "Rock_Basalt_Cobble"
    },
    {
      "x": -2,
      "y": 28,
      "z": -3,
      "name": "Plant_Crop_Mushroom_Block_Purple_Trunk"
    },
    {
      "x": -2,
      "y": 29,
      "z": -3,
      "name": "Plant_Crop_Mushroom_Block_Purple_Trunk"
    },
    {
      "x": -2,
      "y": 30,
      "z": -3,
      "name": "Plant_Crop_Mushroom_Block_Purple_Trunk"
    },
    {
      "x": -2,
      "y": 31,
      "z": -3,
      "name": "Plant_Crop_Mushroom_Block_Purple"
    },
    {
      "x": -2,
      "y": 34,
      "z": -3,
      "name": "Soil_Gravel"
    },
    {
      "x": -2,
      "y": 35,
      "z": -3,
      "name": "Soil_Gravel"
    },
    {
      "x": -2,
      "y": 36,
      "z": -3,
      "name": "Rock_Basalt_Cobble"
    },
    {
      "x": -2,
      "y": 37,
      "z": -3,
      "name": "Rock_Basalt_Cobble"
    },
    {
      "x": -2,
      "y": 38,
      "z": -3,
      "name": "Rock_Basalt_Cobble"
    },
    {
      "x": -2,
      "y": 39,
      "z": -3,
      "name": "Rock_Basalt"
    },
    {
      "x": -2,
      "y": 40,
      "z": -3,
      "name": "Rock_Basalt"
    },
    {
      "x": -2,
      "y": 6,
      "z": -2,
      "name": "Rock_Basalt"
    },
    {
      "x": -2,
      "y": 7,
      "z": -2,
      "name": "Rock_Basalt"
    },
    {
      "x": -2,
      "y": 8,
      "z": -2,
      "name": "Rock_Basalt"
    },
    {
      "x": -2,
      "y": 9,
      "z": -2,
      "name": "Rock_Basalt"
    },
    {
      "x": -2,
      "y": 10,
      "z": -2,
      "name": "Rock_Basalt"
    },
    {
      "x": -2,
      "y": 11,
      "z": -2,
      "name": "Rock_Basalt"
    },
    {
      "x": -2,
      "y": 12,
      "z": -2,
      "name": "Rock_Basalt"
    },
    {
      "x": -2,
      "y": 13,
      "z": -2,
      "name": "Rock_Basalt"
    },
    {
      "x": -2,
      "y": 14,
      "z": -2,
      "name": "Rock_Basalt"
    },
    {
      "x": -2,
      "y": 15,
      "z": -2,
      "name": "Rock_Basalt"
    },
    {
      "x": -2,
      "y": 17,
      "z": -2,
      "name": "Rock_Basalt"
    },
    {
      "x": -2,
      "y": 18,
      "z": -2,
      "name": "Rock_Basalt"
    },
    {
      "x": -2,
      "y": 19,
      "z": -2,
      "name": "Rock_Basalt_Cobble"
    },
    {
      "x": -2,
      "y": 20,
      "z": -2,
      "name": "Rock_Basalt_Cobble"
    },
    {
      "x": -2,
      "y": 21,
      "z": -2,
      "name": "Rock_Basalt_Cobble"
    },
    {
      "x": -2,
      "y": 22,
      "z": -2,
      "name": "Rock_Basalt"
    },
    {
      "x": -2,
      "y": 23,
      "z": -2,
      "name": "Rock_Basalt_Cobble"
    },
    {
      "x": -2,
      "y": 24,
      "z": -2,
      "name": "Rock_Basalt"
    },
    {
      "x": -2,
      "y": 25,
      "z": -2,
      "name": "Rock_Basalt_Cobble"
    },
    {
      "x": -2,
      "y": 26,
      "z": -2,
      "name": "Plant_Crop_Mushroom_Block_Purple_Trunk"
    },
    {
      "x": -2,
      "y": 27,
      "z": -2,
      "name": "Plant_Crop_Mushroom_Block_Purple_Trunk"
    },
    {
      "x": -2,
      "y": 28,
      "z": -2,
      "name": "Plant_Crop_Mushroom_Block_Purple_Trunk"
    },
    {
      "x": -2,
      "y": 29,
      "z": -2,
      "name": "Plant_Crop_Mushroom_Block_Purple_Trunk"
    },
    {
      "x": -2,
      "y": 30,
      "z": -2,
      "name": "Plant_Crop_Mushroom_Block_Purple"
    },
    {
      "x": -2,
      "y": 31,
      "z": -2,
      "name": "Plant_Crop_Mushroom_Block_Purple"
    },
    {
      "x": -2,
      "y": 33,
      "z": -2,
      "name": "Soil_Gravel"
    },
    {
      "x": -2,
      "y": 34,
      "z": -2,
      "name": "Rock_Basalt_Cobble"
    },
    {
      "x": -2,
      "y": 35,
      "z": -2,
      "name": "Rock_Basalt_Cobble"
    },
    {
      "x": -2,
      "y": 36,
      "z": -2,
      "name": "Rock_Basalt"
    },
    {
      "x": -2,
      "y": 37,
      "z": -2,
      "name": "Rock_Basalt_Cobble"
    },
    {
      "x": -2,
      "y": 38,
      "z": -2,
      "name": "Rock_Basalt"
    },
    {
      "x": -2,
      "y": 39,
      "z": -2,
      "name": "Rock_Basalt"
    },
    {
      "x": -2,
      "y": 40,
      "z": -2,
      "name": "Rock_Basalt"
    },
    {
      "x": -2,
      "y": 5,
      "z": -1,
      "name": "Rock_Basalt"
    },
    {
      "x": -2,
      "y": 6,
      "z": -1,
      "name": "Rock_Basalt"
    },
    {
      "x": -2,
      "y": 7,
      "z": -1,
      "name": "Rock_Basalt"
    },
    {
      "x": -2,
      "y": 8,
      "z": -1,
      "name": "Rock_Basalt"
    },
    {
      "x": -2,
      "y": 9,
      "z": -1,
      "name": "Rock_Basalt"
    },
    {
      "x": -2,
      "y": 10,
      "z": -1,
      "name": "Rock_Basalt"
    },
    {
      "x": -2,
      "y": 11,
      "z": -1,
      "name": "Rock_Basalt"
    },
    {
      "x": -2,
      "y": 12,
      "z": -1,
      "name": "Rock_Basalt_Cobble"
    },
    {
      "x": -2,
      "y": 13,
      "z": -1,
      "name": "Rock_Basalt"
    },
    {
      "x": -2,
      "y": 14,
      "z": -1,
      "name": "Rock_Basalt"
    },
    {
      "x": -2,
      "y": 15,
      "z": -1,
      "name": "Rock_Basalt_Cobble"
    },
    {
      "x": -2,
      "y": 16,
      "z": -1,
      "name": "Rock_Basalt"
    },
    {
      "x": -2,
      "y": 17,
      "z": -1,
      "name": "Rock_Basalt"
    },
    {
      "x": -2,
      "y": 18,
      "z": -1,
      "name": "Rock_Basalt"
    },
    {
      "x": -2,
      "y": 19,
      "z": -1,
      "name": "Rock_Basalt"
    },
    {
      "x": -2,
      "y": 20,
      "z": -1,
      "name": "Rock_Basalt_Cobble"
    },
    {
      "x": -2,
      "y": 21,
      "z": -1,
      "name": "Rock_Basalt"
    },
    {
      "x": -2,
      "y": 22,
      "z": -1,
      "name": "Rock_Basalt"
    },
    {
      "x": -2,
      "y": 23,
      "z": -1,
      "name": "Rock_Basalt"
    },
    {
      "x": -2,
      "y": 24,
      "z": -1,
      "name": "Rock_Basalt"
    },
    {
      "x": -2,
      "y": 25,
      "z": -1,
      "name": "Rock_Basalt_Cobble"
    },
    {
      "x": -2,
      "y": 26,
      "z": -1,
      "name": "Rock_Basalt_Cobble"
    },
    {
      "x": -2,
      "y": 27,
      "z": -1,
      "name": "Rock_Basalt_Cobble"
    },
    {
      "x": -2,
      "y": 28,
      "z": -1,
      "name": "Rock_Basalt_Cobble"
    },
    {
      "x": -2,
      "y": 29,
      "z": -1,
      "name": "Rock_Basalt_Cobble"
    },
    {
      "x": -2,
      "y": 30,
      "z": -1,
      "name": "Rock_Basalt_Cobble"
    },
    {
      "x": -2,
      "y": 31,
      "z": -1,
      "name": "Rock_Basalt_Cobble"
    },
    {
      "x": -2,
      "y": 32,
      "z": -1,
      "name": "Soil_Gravel"
    },
    {
      "x": -2,
      "y": 33,
      "z": -1,
      "name": "Soil_Gravel"
    },
    {
      "x": -2,
      "y": 34,
      "z": -1,
      "name": "Soil_Gravel"
    },
    {
      "x": -2,
      "y": 35,
      "z": -1,
      "name": "Rock_Basalt_Cobble"
    },
    {
      "x": -2,
      "y": 36,
      "z": -1,
      "name": "Rock_Basalt"
    },
    {
      "x": -2,
      "y": 37,
      "z": -1,
      "name": "Rock_Basalt"
    },
    {
      "x": -2,
      "y": 38,
      "z": -1,
      "name": "Rock_Basalt"
    },
    {
      "x": -2,
      "y": 39,
      "z": -1,
      "name": "Rock_Basalt"
    },
    {
      "x": -2,
      "y": 40,
      "z": -1,
      "name": "Rock_Basalt"
    },
    {
      "x": -2,
      "y": 5,
      "z": 0,
      "name": "Rock_Basalt"
    },
    {
      "x": -2,
      "y": 6,
      "z": 0,
      "name": "Rock_Basalt"
    },
    {
      "x": -2,
      "y": 7,
      "z": 0,
      "name": "Rock_Basalt"
    },
    {
      "x": -2,
      "y": 8,
      "z": 0,
      "name": "Rock_Basalt"
    },
    {
      "x": -2,
      "y": 9,
      "z": 0,
      "name": "Rock_Basalt"
    },
    {
      "x": -2,
      "y": 10,
      "z": 0,
      "name": "Rock_Basalt"
    },
    {
      "x": -2,
      "y": 11,
      "z": 0,
      "name": "Rock_Basalt_Cobble"
    },
    {
      "x": -2,
      "y": 12,
      "z": 0,
      "name": "Rock_Basalt_Cobble"
    },
    {
      "x": -2,
      "y": 13,
      "z": 0,
      "name": "Rock_Basalt_Cobble"
    },
    {
      "x": -2,
      "y": 14,
      "z": 0,
      "name": "Rock_Basalt_Cobble"
    },
    {
      "x": -2,
      "y": 15,
      "z": 0,
      "name": "Rock_Basalt_Cobble"
    },
    {
      "x": -2,
      "y": 16,
      "z": 0,
      "name": "Rock_Basalt_Cobble"
    },
    {
      "x": -2,
      "y": 17,
      "z": 0,
      "name": "Rock_Basalt"
    },
    {
      "x": -2,
      "y": 18,
      "z": 0,
      "name": "Rock_Basalt"
    },
    {
      "x": -2,
      "y": 19,
      "z": 0,
      "name": "Rock_Basalt"
    },
    {
      "x": -2,
      "y": 20,
      "z": 0,
      "name": "Rock_Basalt"
    },
    {
      "x": -2,
      "y": 21,
      "z": 0,
      "name": "Rock_Basalt"
    },
    {
      "x": -2,
      "y": 22,
      "z": 0,
      "name": "Rock_Basalt"
    },
    {
      "x": -2,
      "y": 23,
      "z": 0,
      "name": "Rock_Basalt"
    },
    {
      "x": -2,
      "y": 24,
      "z": 0,
      "name": "Rock_Basalt"
    },
    {
      "x": -2,
      "y": 25,
      "z": 0,
      "name": "Rock_Basalt"
    },
    {
      "x": -2,
      "y": 26,
      "z": 0,
      "name": "Rock_Basalt_Cobble"
    },
    {
      "x": -2,
      "y": 27,
      "z": 0,
      "name": "Rock_Basalt_Cobble"
    },
    {
      "x": -2,
      "y": 28,
      "z": 0,
      "name": "Rock_Basalt_Cobble"
    },
    {
      "x": -2,
      "y": 29,
      "z": 0,
      "name": "Rock_Basalt_Cobble"
    },
    {
      "x": -2,
      "y": 30,
      "z": 0,
      "name": "Rock_Basalt_Cobble"
    },
    {
      "x": -2,
      "y": 31,
      "z": 0,
      "name": "Rock_Basalt"
    },
    {
      "x": -2,
      "y": 32,
      "z": 0,
      "name": "Rock_Basalt_Cobble"
    },
    {
      "x": -2,
      "y": 33,
      "z": 0,
      "name": "Soil_Gravel"
    },
    {
      "x": -2,
      "y": 34,
      "z": 0,
      "name": "Rock_Basalt_Cobble"
    },
    {
      "x": -2,
      "y": 35,
      "z": 0,
      "name": "Rock_Basalt"
    },
    {
      "x": -2,
      "y": 36,
      "z": 0,
      "name": "Rock_Basalt"
    },
    {
      "x": -2,
      "y": 37,
      "z": 0,
      "name": "Rock_Basalt"
    },
    {
      "x": -2,
      "y": 38,
      "z": 0,
      "name": "Rock_Basalt"
    },
    {
      "x": -2,
      "y": 39,
      "z": 0,
      "name": "Rock_Basalt"
    },
    {
      "x": -2,
      "y": 40,
      "z": 0,
      "name": "Rock_Basalt"
    },
    {
      "x": -2,
      "y": 5,
      "z": 1,
      "name": "Rock_Basalt"
    },
    {
      "x": -2,
      "y": 6,
      "z": 1,
      "name": "Rock_Basalt"
    },
    {
      "x": -2,
      "y": 7,
      "z": 1,
      "name": "Rock_Basalt"
    },
    {
      "x": -2,
      "y": 8,
      "z": 1,
      "name": "Rock_Basalt"
    },
    {
      "x": -2,
      "y": 9,
      "z": 1,
      "name": "Rock_Basalt"
    },
    {
      "x": -2,
      "y": 10,
      "z": 1,
      "name": "Rock_Basalt_Cobble"
    },
    {
      "x": -2,
      "y": 11,
      "z": 1,
      "name": "Rock_Basalt_Cobble"
    },
    {
      "x": -2,
      "y": 12,
      "z": 1,
      "name": "Rock_Basalt_Cobble"
    },
    {
      "x": -2,
      "y": 13,
      "z": 1,
      "name": "Rock_Basalt_Cobble"
    },
    {
      "x": -2,
      "y": 14,
      "z": 1,
      "name": "Rock_Basalt_Cobble"
    },
    {
      "x": -2,
      "y": 15,
      "z": 1,
      "name": "Rock_Basalt_Cobble"
    },
    {
      "x": -2,
      "y": 16,
      "z": 1,
      "name": "Rock_Basalt_Cobble"
    },
    {
      "x": -2,
      "y": 17,
      "z": 1,
      "name": "Rock_Basalt_Cobble"
    },
    {
      "x": -2,
      "y": 18,
      "z": 1,
      "name": "Rock_Basalt"
    },
    {
      "x": -2,
      "y": 19,
      "z": 1,
      "name": "Rock_Basalt"
    },
    {
      "x": -2,
      "y": 20,
      "z": 1,
      "name": "Rock_Basalt"
    },
    {
      "x": -2,
      "y": 21,
      "z": 1,
      "name": "Rock_Basalt"
    },
    {
      "x": -2,
      "y": 22,
      "z": 1,
      "name": "Rock_Basalt"
    },
    {
      "x": -2,
      "y": 23,
      "z": 1,
      "name": "Rock_Basalt"
    },
    {
      "x": -2,
      "y": 24,
      "z": 1,
      "name": "Rock_Basalt"
    },
    {
      "x": -2,
      "y": 25,
      "z": 1,
      "name": "Rock_Basalt"
    },
    {
      "x": -2,
      "y": 26,
      "z": 1,
      "name": "Rock_Basalt"
    },
    {
      "x": -2,
      "y": 27,
      "z": 1,
      "name": "Rock_Basalt"
    },
    {
      "x": -2,
      "y": 31,
      "z": 1,
      "name": "Rock_Basalt"
    },
    {
      "x": -2,
      "y": 32,
      "z": 1,
      "name": "Rock_Basalt"
    },
    {
      "x": -2,
      "y": 33,
      "z": 1,
      "name": "Rock_Basalt"
    },
    {
      "x": -2,
      "y": 34,
      "z": 1,
      "name": "Rock_Basalt"
    },
    {
      "x": -2,
      "y": 35,
      "z": 1,
      "name": "Rock_Basalt"
    },
    {
      "x": -2,
      "y": 36,
      "z": 1,
      "name": "Rock_Basalt"
    },
    {
      "x": -2,
      "y": 37,
      "z": 1,
      "name": "Rock_Basalt"
    },
    {
      "x": -2,
      "y": 38,
      "z": 1,
      "name": "Rock_Basalt"
    },
    {
      "x": -2,
      "y": 39,
      "z": 1,
      "name": "Rock_Basalt_Cobble"
    },
    {
      "x": -2,
      "y": 40,
      "z": 1,
      "name": "Rock_Basalt"
    },
    {
      "x": -2,
      "y": 6,
      "z": 2,
      "name": "Rock_Basalt"
    },
    {
      "x": -2,
      "y": 7,
      "z": 2,
      "name": "Rock_Basalt"
    },
    {
      "x": -2,
      "y": 8,
      "z": 2,
      "name": "Rock_Basalt"
    },
    {
      "x": -2,
      "y": 9,
      "z": 2,
      "name": "Rock_Basalt_Cobble"
    },
    {
      "x": -2,
      "y": 10,
      "z": 2,
      "name": "Rock_Basalt_Cobble"
    },
    {
      "x": -2,
      "y": 11,
      "z": 2,
      "name": "Rock_Basalt_Cobble"
    },
    {
      "x": -2,
      "y": 12,
      "z": 2,
      "name": "Rock_Basalt_Cobble"
    },
    {
      "x": -2,
      "y": 13,
      "z": 2,
      "name": "Rock_Basalt_Cobble"
    },
    {
      "x": -2,
      "y": 14,
      "z": 2,
      "name": "Rock_Basalt_Cobble"
    },
    {
      "x": -2,
      "y": 15,
      "z": 2,
      "name": "Rock_Basalt_Cobble"
    },
    {
      "x": -2,
      "y": 16,
      "z": 2,
      "name": "Rock_Basalt_Cobble"
    },
    {
      "x": -2,
      "y": 17,
      "z": 2,
      "name": "Rock_Basalt"
    },
    {
      "x": -2,
      "y": 18,
      "z": 2,
      "name": "Rock_Basalt"
    },
    {
      "x": -2,
      "y": 19,
      "z": 2,
      "name": "Rock_Basalt"
    },
    {
      "x": -2,
      "y": 20,
      "z": 2,
      "name": "Rock_Basalt"
    },
    {
      "x": -2,
      "y": 21,
      "z": 2,
      "name": "Rock_Basalt"
    },
    {
      "x": -2,
      "y": 22,
      "z": 2,
      "name": "Rock_Basalt"
    },
    {
      "x": -2,
      "y": 33,
      "z": 2,
      "name": "Rock_Basalt"
    },
    {
      "x": -2,
      "y": 34,
      "z": 2,
      "name": "Rock_Basalt"
    },
    {
      "x": -2,
      "y": 35,
      "z": 2,
      "name": "Rock_Basalt"
    },
    {
      "x": -2,
      "y": 36,
      "z": 2,
      "name": "Rock_Basalt"
    },
    {
      "x": -2,
      "y": 37,
      "z": 2,
      "name": "Soil_Gravel"
    },
    {
      "x": -2,
      "y": 38,
      "z": 2,
      "name": "Soil_Gravel"
    },
    {
      "x": -2,
      "y": 39,
      "z": 2,
      "name": "Rock_Basalt_Cobble"
    },
    {
      "x": -2,
      "y": 40,
      "z": 2,
      "name": "Rock_Basalt_Cobble"
    },
    {
      "x": -2,
      "y": 6,
      "z": 3,
      "name": "Rock_Basalt"
    },
    {
      "x": -2,
      "y": 7,
      "z": 3,
      "name": "Rock_Basalt"
    },
    {
      "x": -2,
      "y": 8,
      "z": 3,
      "name": "Rock_Basalt_Cobble"
    },
    {
      "x": -2,
      "y": 9,
      "z": 3,
      "name": "Rock_Basalt_Cobble"
    },
    {
      "x": -2,
      "y": 10,
      "z": 3,
      "name": "Plant_Crop_Mushroom_Block_Purple_Trunk"
    },
    {
      "x": -2,
      "y": 11,
      "z": 3,
      "name": "Plant_Crop_Mushroom_Block_Purple_Trunk"
    },
    {
      "x": -2,
      "y": 12,
      "z": 3,
      "name": "Plant_Crop_Mushroom_Block_Purple_Trunk"
    },
    {
      "x": -2,
      "y": 13,
      "z": 3,
      "name": "Plant_Crop_Mushroom_Block_Purple_Trunk"
    },
    {
      "x": -2,
      "y": 14,
      "z": 3,
      "name": "Plant_Crop_Mushroom_Block_Purple_Trunk"
    },
    {
      "x": -2,
      "y": 15,
      "z": 3,
      "name": "Plant_Crop_Mushroom_Block_Purple_Trunk"
    },
    {
      "x": -2,
      "y": 16,
      "z": 3,
      "name": "Plant_Crop_Mushroom_Block_Purple_Trunk"
    },
    {
      "x": -2,
      "y": 17,
      "z": 3,
      "name": "Rock_Basalt_Cobble"
    },
    {
      "x": -2,
      "y": 18,
      "z": 3,
      "name": "Rock_Basalt"
    },
    {
      "x": -2,
      "y": 19,
      "z": 3,
      "name": "Rock_Basalt"
    },
    {
      "x": -2,
      "y": 20,
      "z": 3,
      "name": "Rock_Basalt"
    },
    {
      "x": -2,
      "y": 35,
      "z": 3,
      "name": "Rock_Basalt"
    },
    {
      "x": -2,
      "y": 36,
      "z": 3,
      "name": "Soil_Gravel"
    },
    {
      "x": -2,
      "y": 37,
      "z": 3,
      "name": "Soil_Gravel"
    },
    {
      "x": -2,
      "y": 38,
      "z": 3,
      "name": "Soil_Gravel"
    },
    {
      "x": -2,
      "y": 39,
      "z": 3,
      "name": "Soil_Gravel"
    },
    {
      "x": -2,
      "y": 40,
      "z": 3,
      "name": "Rock_Basalt_Cobble"
    },
    {
      "x": -2,
      "y": 7,
      "z": 4,
      "name": "Rock_Basalt_Cobble"
    },
    {
      "x": -2,
      "y": 8,
      "z": 4,
      "name": "Rock_Basalt_Cobble"
    },
    {
      "x": -2,
      "y": 9,
      "z": 4,
      "name": "Rock_Basalt_Cobble"
    },
    {
      "x": -2,
      "y": 15,
      "z": 4,
      "name": "Plant_Crop_Mushroom_Block_Purple_Mycelium"
    },
    {
      "x": -2,
      "y": 16,
      "z": 4,
      "name": "Plant_Crop_Mushroom_Block_Purple"
    },
    {
      "x": -2,
      "y": 37,
      "z": 4,
      "name": "Soil_Gravel"
    },
    {
      "x": -2,
      "y": 38,
      "z": 4,
      "name": "Soil_Gravel"
    },
    {
      "x": -2,
      "y": 39,
      "z": 4,
      "name": "Soil_Gravel"
    },
    {
      "x": -2,
      "y": 40,
      "z": 4,
      "name": "Soil_Gravel"
    },
    {
      "x": -2,
      "y": 8,
      "z": 5,
      "name": "Rock_Basalt_Cobble"
    },
    {
      "x": -2,
      "y": 16,
      "z": 5,
      "name": "Plant_Crop_Mushroom_Block_Purple"
    },
    {
      "x": -2,
      "y": 39,
      "z": 5,
      "name": "Soil_Gravel"
    },
    {
      "x": -2,
      "y": 40,
      "z": 5,
      "name": "Soil_Gravel"
    },
    {
      "x": -2,
      "y": 41,
      "z": 5,
      "name": "Rock_Basalt_Cobble"
    },
    {
      "x": -2,
      "y": 39,
      "z": 6,
      "name": "Soil_Gravel"
    },
    {
      "x": -2,
      "y": 40,
      "z": 6,
      "name": "Rock_Basalt_Cobble"
    },
    {
      "x": -2,
      "y": 41,
      "z": 6,
      "name": "Rock_Basalt_Cobble"
    },
    {
      "x": -2,
      "y": 39,
      "z": 7,
      "name": "Rock_Basalt_Cobble"
    },
    {
      "x": -2,
      "y": 40,
      "z": 7,
      "name": "Rock_Basalt_Cobble"
    },
    {
      "x": -2,
      "y": 41,
      "z": 7,
      "name": "Rock_Basalt"
    },
    {
      "x": -1,
      "y": 7,
      "z": -5,
      "name": "Rock_Basalt"
    },
    {
      "x": -1,
      "y": 8,
      "z": -5,
      "name": "Rock_Basalt"
    },
    {
      "x": -1,
      "y": 9,
      "z": -5,
      "name": "Rock_Basalt"
    },
    {
      "x": -1,
      "y": 10,
      "z": -5,
      "name": "Rock_Basalt"
    },
    {
      "x": -1,
      "y": 30,
      "z": -5,
      "name": "Plant_Crop_Mushroom_Block_Purple"
    },
    {
      "x": -1,
      "y": 31,
      "z": -5,
      "name": "Plant_Crop_Mushroom_Block_Purple"
    },
    {
      "x": -1,
      "y": 35,
      "z": -5,
      "name": "Rock_Basalt"
    },
    {
      "x": -1,
      "y": 36,
      "z": -5,
      "name": "Rock_Basalt"
    },
    {
      "x": -1,
      "y": 37,
      "z": -5,
      "name": "Rock_Basalt_Cobble"
    },
    {
      "x": -1,
      "y": 38,
      "z": -5,
      "name": "Rock_Basalt"
    },
    {
      "x": -1,
      "y": 6,
      "z": -4,
      "name": "Rock_Basalt"
    },
    {
      "x": -1,
      "y": 7,
      "z": -4,
      "name": "Rock_Basalt"
    },
    {
      "x": -1,
      "y": 8,
      "z": -4,
      "name": "Rock_Basalt"
    },
    {
      "x": -1,
      "y": 9,
      "z": -4,
      "name": "Rock_Basalt"
    },
    {
      "x": -1,
      "y": 10,
      "z": -4,
      "name": "Rock_Basalt"
    },
    {
      "x": -1,
      "y": 11,
      "z": -4,
      "name": "Rock_Basalt"
    },
    {
      "x": -1,
      "y": 22,
      "z": -4,
      "name": "Soil_Gravel"
    },
    {
      "x": -1,
      "y": 23,
      "z": -4,
      "name": "Soil_Gravel"
    },
    {
      "x": -1,
      "y": 24,
      "z": -4,
      "name": "Soil_Gravel"
    },
    {
      "x": -1,
      "y": 25,
      "z": -4,
      "name": "Soil_Gravel"
    },
    {
      "x": -1,
      "y": 26,
      "z": -4,
      "name": "Rock_Basalt"
    },
    {
      "x": -1,
      "y": 27,
      "z": -4,
      "name": "Rock_Basalt_Cobble"
    },
    {
      "x": -1,
      "y": 28,
      "z": -4,
      "name": "Rock_Basalt"
    },
    {
      "x": -1,
      "y": 31,
      "z": -4,
      "name": "Plant_Crop_Mushroom_Block_Purple"
    },
    {
      "x": -1,
      "y": 32,
      "z": -4,
      "name": "Rock_Basalt"
    },
    {
      "x": -1,
      "y": 33,
      "z": -4,
      "name": "Rock_Basalt_Cobble"
    },
    {
      "x": -1,
      "y": 34,
      "z": -4,
      "name": "Rock_Basalt_Cobble"
    },
    {
      "x": -1,
      "y": 35,
      "z": -4,
      "name": "Rock_Basalt"
    },
    {
      "x": -1,
      "y": 36,
      "z": -4,
      "name": "Rock_Basalt_Cobble"
    },
    {
      "x": -1,
      "y": 37,
      "z": -4,
      "name": "Rock_Basalt_Cobble"
    },
    {
      "x": -1,
      "y": 38,
      "z": -4,
      "name": "Rock_Basalt_Cobble"
    },
    {
      "x": -1,
      "y": 39,
      "z": -4,
      "name": "Rock_Basalt"
    },
    {
      "x": -1,
      "y": 40,
      "z": -4,
      "name": "Rock_Basalt"
    },
    {
      "x": -1,
      "y": 6,
      "z": -3,
      "name": "Rock_Basalt"
    },
    {
      "x": -1,
      "y": 7,
      "z": -3,
      "name": "Rock_Basalt"
    },
    {
      "x": -1,
      "y": 8,
      "z": -3,
      "name": "Rock_Basalt"
    },
    {
      "x": -1,
      "y": 9,
      "z": -3,
      "name": "Rock_Basalt"
    },
    {
      "x": -1,
      "y": 10,
      "z": -3,
      "name": "Rock_Basalt"
    },
    {
      "x": -1,
      "y": 11,
      "z": -3,
      "name": "Rock_Basalt"
    },
    {
      "x": -1,
      "y": 12,
      "z": -3,
      "name": "Rock_Basalt"
    },
    {
      "x": -1,
      "y": 13,
      "z": -3,
      "name": "Rock_Basalt"
    },
    {
      "x": -1,
      "y": 14,
      "z": -3,
      "name": "Rock_Basalt"
    },
    {
      "x": -1,
      "y": 17,
      "z": -3,
      "name": "Rock_Basalt"
    },
    {
      "x": -1,
      "y": 18,
      "z": -3,
      "name": "Rock_Basalt_Cobble"
    },
    {
      "x": -1,
      "y": 19,
      "z": -3,
      "name": "Rock_Basalt_Cobble"
    },
    {
      "x": -1,
      "y": 20,
      "z": -3,
      "name": "Rock_Basalt_Cobble"
    },
    {
      "x": -1,
      "y": 21,
      "z": -3,
      "name": "Rock_Basalt_Cobble"
    },
    {
      "x": -1,
      "y": 22,
      "z": -3,
      "name": "Soil_Gravel"
    },
    {
      "x": -1,
      "y": 23,
      "z": -3,
      "name": "Rock_Basalt_Cobble"
    },
    {
      "x": -1,
      "y": 24,
      "z": -3,
      "name": "Soil_Gravel"
    },
    {
      "x": -1,
      "y": 25,
      "z": -3,
      "name": "Rock_Basalt_Cobble"
    },
    {
      "x": -1,
      "y": 26,
      "z": -3,
      "name": "Rock_Basalt_Cobble"
    },
    {
      "x": -1,
      "y": 27,
      "z": -3,
      "name": "Rock_Basalt_Cobble"
    },
    {
      "x": -1,
      "y": 28,
      "z": -3,
      "name": "Rock_Basalt_Cobble"
    },
    {
      "x": -1,
      "y": 29,
      "z": -3,
      "name": "Rock_Basalt"
    },
    {
      "x": -1,
      "y": 30,
      "z": -3,
      "name": "Rock_Basalt"
    },
    {
      "x": -1,
      "y": 31,
      "z": -3,
      "name": "Rock_Basalt"
    },
    {
      "x": -1,
      "y": 32,
      "z": -3,
      "name": "Rock_Basalt_Cobble"
    },
    {
      "x": -1,
      "y": 33,
      "z": -3,
      "name": "Rock_Basalt_Cobble"
    },
    {
      "x": -1,
      "y": 34,
      "z": -3,
      "name": "Rock_Basalt_Cobble"
    },
    {
      "x": -1,
      "y": 35,
      "z": -3,
      "name": "Rock_Basalt_Cobble"
    },
    {
      "x": -1,
      "y": 36,
      "z": -3,
      "name": "Rock_Basalt"
    },
    {
      "x": -1,
      "y": 37,
      "z": -3,
      "name": "Rock_Basalt_Cobble"
    },
    {
      "x": -1,
      "y": 38,
      "z": -3,
      "name": "Rock_Basalt"
    },
    {
      "x": -1,
      "y": 39,
      "z": -3,
      "name": "Rock_Basalt"
    },
    {
      "x": -1,
      "y": 40,
      "z": -3,
      "name": "Rock_Basalt"
    },
    {
      "x": -1,
      "y": 5,
      "z": -2,
      "name": "Rock_Basalt"
    },
    {
      "x": -1,
      "y": 6,
      "z": -2,
      "name": "Rock_Basalt"
    },
    {
      "x": -1,
      "y": 7,
      "z": -2,
      "name": "Rock_Basalt"
    },
    {
      "x": -1,
      "y": 8,
      "z": -2,
      "name": "Rock_Basalt"
    },
    {
      "x": -1,
      "y": 9,
      "z": -2,
      "name": "Rock_Basalt"
    },
    {
      "x": -1,
      "y": 10,
      "z": -2,
      "name": "Rock_Basalt"
    },
    {
      "x": -1,
      "y": 11,
      "z": -2,
      "name": "Rock_Basalt"
    },
    {
      "x": -1,
      "y": 12,
      "z": -2,
      "name": "Rock_Basalt"
    },
    {
      "x": -1,
      "y": 13,
      "z": -2,
      "name": "Rock_Basalt"
    },
    {
      "x": -1,
      "y": 14,
      "z": -2,
      "name": "Rock_Basalt"
    },
    {
      "x": -1,
      "y": 15,
      "z": -2,
      "name": "Rock_Basalt"
    },
    {
      "x": -1,
      "y": 16,
      "z": -2,
      "name": "Rock_Basalt"
    },
    {
      "x": -1,
      "y": 17,
      "z": -2,
      "name": "Rock_Basalt"
    },
    {
      "x": -1,
      "y": 18,
      "z": -2,
      "name": "Rock_Basalt_Cobble"
    },
    {
      "x": -1,
      "y": 19,
      "z": -2,
      "name": "Rock_Basalt_Cobble"
    },
    {
      "x": -1,
      "y": 20,
      "z": -2,
      "name": "Rock_Basalt_Cobble"
    },
    {
      "x": -1,
      "y": 21,
      "z": -2,
      "name": "Rock_Basalt_Cobble"
    },
    {
      "x": -1,
      "y": 22,
      "z": -2,
      "name": "Rock_Basalt_Cobble"
    },
    {
      "x": -1,
      "y": 23,
      "z": -2,
      "name": "Rock_Basalt_Cobble"
    },
    {
      "x": -1,
      "y": 24,
      "z": -2,
      "name": "Rock_Basalt_Cobble"
    },
    {
      "x": -1,
      "y": 25,
      "z": -2,
      "name": "Rock_Basalt_Cobble"
    },
    {
      "x": -1,
      "y": 26,
      "z": -2,
      "name": "Rock_Basalt_Cobble"
    },
    {
      "x": -1,
      "y": 27,
      "z": -2,
      "name": "Rock_Basalt_Cobble"
    },
    {
      "x": -1,
      "y": 28,
      "z": -2,
      "name": "Rock_Basalt_Cobble"
    },
    {
      "x": -1,
      "y": 29,
      "z": -2,
      "name": "Rock_Basalt_Cobble"
    },
    {
      "x": -1,
      "y": 30,
      "z": -2,
      "name": "Rock_Basalt"
    },
    {
      "x": -1,
      "y": 31,
      "z": -2,
      "name": "Rock_Basalt_Cobble"
    },
    {
      "x": -1,
      "y": 32,
      "z": -2,
      "name": "Rock_Basalt_Cobble"
    },
    {
      "x": -1,
      "y": 33,
      "z": -2,
      "name": "Rock_Basalt_Cobble"
    },
    {
      "x": -1,
      "y": 34,
      "z": -2,
      "name": "Rock_Basalt_Cobble"
    },
    {
      "x": -1,
      "y": 35,
      "z": -2,
      "name": "Rock_Basalt_Cobble"
    },
    {
      "x": -1,
      "y": 36,
      "z": -2,
      "name": "Rock_Basalt"
    },
    {
      "x": -1,
      "y": 37,
      "z": -2,
      "name": "Rock_Basalt"
    },
    {
      "x": -1,
      "y": 38,
      "z": -2,
      "name": "Rock_Basalt"
    },
    {
      "x": -1,
      "y": 39,
      "z": -2,
      "name": "Rock_Basalt"
    },
    {
      "x": -1,
      "y": 40,
      "z": -2,
      "name": "Rock_Basalt"
    },
    {
      "x": -1,
      "y": 5,
      "z": -1,
      "name": "Rock_Basalt"
    },
    {
      "x": -1,
      "y": 6,
      "z": -1,
      "name": "Rock_Basalt"
    },
    {
      "x": -1,
      "y": 7,
      "z": -1,
      "name": "Rock_Basalt"
    },
    {
      "x": -1,
      "y": 8,
      "z": -1,
      "name": "Rock_Basalt"
    },
    {
      "x": -1,
      "y": 9,
      "z": -1,
      "name": "Rock_Basalt"
    },
    {
      "x": -1,
      "y": 10,
      "z": -1,
      "name": "Rock_Basalt"
    },
    {
      "x": -1,
      "y": 11,
      "z": -1,
      "name": "Rock_Basalt"
    },
    {
      "x": -1,
      "y": 12,
      "z": -1,
      "name": "Rock_Basalt"
    },
    {
      "x": -1,
      "y": 13,
      "z": -1,
      "name": "Rock_Basalt"
    },
    {
      "x": -1,
      "y": 14,
      "z": -1,
      "name": "Rock_Basalt"
    },
    {
      "x": -1,
      "y": 15,
      "z": -1,
      "name": "Rock_Basalt"
    },
    {
      "x": -1,
      "y": 16,
      "z": -1,
      "name": "Rock_Basalt"
    },
    {
      "x": -1,
      "y": 17,
      "z": -1,
      "name": "Rock_Basalt"
    },
    {
      "x": -1,
      "y": 18,
      "z": -1,
      "name": "Rock_Basalt"
    },
    {
      "x": -1,
      "y": 19,
      "z": -1,
      "name": "Rock_Basalt_Cobble"
    },
    {
      "x": -1,
      "y": 20,
      "z": -1,
      "name": "Rock_Basalt_Cobble"
    },
    {
      "x": -1,
      "y": 21,
      "z": -1,
      "name": "Rock_Basalt_Cobble"
    },
    {
      "x": -1,
      "y": 22,
      "z": -1,
      "name": "Rock_Basalt"
    },
    {
      "x": -1,
      "y": 23,
      "z": -1,
      "name": "Rock_Basalt"
    },
    {
      "x": -1,
      "y": 24,
      "z": -1,
      "name": "Rock_Basalt"
    },
    {
      "x": -1,
      "y": 25,
      "z": -1,
      "name": "Rock_Basalt"
    },
    {
      "x": -1,
      "y": 26,
      "z": -1,
      "name": "Rock_Basalt_Cobble"
    },
    {
      "x": -1,
      "y": 27,
      "z": -1,
      "name": "Rock_Basalt_Cobble"
    },
    {
      "x": -1,
      "y": 28,
      "z": -1,
      "name": "Rock_Basalt_Cobble"
    },
    {
      "x": -1,
      "y": 29,
      "z": -1,
      "name": "Rock_Basalt_Cobble"
    },
    {
      "x": -1,
      "y": 30,
      "z": -1,
      "name": "Rock_Basalt_Cobble"
    },
    {
      "x": -1,
      "y": 31,
      "z": -1,
      "name": "Rock_Basalt"
    },
    {
      "x": -1,
      "y": 32,
      "z": -1,
      "name": "Rock_Basalt_Cobble"
    },
    {
      "x": -1,
      "y": 33,
      "z": -1,
      "name": "Soil_Gravel"
    },
    {
      "x": -1,
      "y": 34,
      "z": -1,
      "name": "Rock_Basalt_Cobble"
    },
    {
      "x": -1,
      "y": 35,
      "z": -1,
      "name": "Rock_Basalt"
    },
    {
      "x": -1,
      "y": 36,
      "z": -1,
      "name": "Rock_Basalt"
    },
    {
      "x": -1,
      "y": 37,
      "z": -1,
      "name": "Rock_Basalt"
    },
    {
      "x": -1,
      "y": 38,
      "z": -1,
      "name": "Rock_Basalt"
    },
    {
      "x": -1,
      "y": 39,
      "z": -1,
      "name": "Rock_Basalt"
    },
    {
      "x": -1,
      "y": 40,
      "z": -1,
      "name": "Rock_Basalt"
    },
    {
      "x": -1,
      "y": 5,
      "z": 0,
      "name": "Rock_Basalt"
    },
    {
      "x": -1,
      "y": 6,
      "z": 0,
      "name": "Rock_Basalt"
    },
    {
      "x": -1,
      "y": 7,
      "z": 0,
      "name": "Rock_Basalt"
    },
    {
      "x": -1,
      "y": 8,
      "z": 0,
      "name": "Rock_Basalt"
    },
    {
      "x": -1,
      "y": 9,
      "z": 0,
      "name": "Rock_Basalt"
    },
    {
      "x": -1,
      "y": 10,
      "z": 0,
      "name": "Rock_Basalt"
    },
    {
      "x": -1,
      "y": 11,
      "z": 0,
      "name": "Rock_Basalt"
    },
    {
      "x": -1,
      "y": 12,
      "z": 0,
      "name": "Rock_Basalt_Cobble"
    },
    {
      "x": -1,
      "y": 13,
      "z": 0,
      "name": "Rock_Basalt"
    },
    {
      "x": -1,
      "y": 14,
      "z": 0,
      "name": "Rock_Basalt"
    },
    {
      "x": -1,
      "y": 15,
      "z": 0,
      "name": "Rock_Basalt_Cobble"
    },
    {
      "x": -1,
      "y": 16,
      "z": 0,
      "name": "Rock_Basalt"
    },
    {
      "x": -1,
      "y": 17,
      "z": 0,
      "name": "Rock_Basalt"
    },
    {
      "x": -1,
      "y": 18,
      "z": 0,
      "name": "Rock_Basalt"
    },
    {
      "x": -1,
      "y": 19,
      "z": 0,
      "name": "Rock_Basalt"
    },
    {
      "x": -1,
      "y": 20,
      "z": 0,
      "name": "Rock_Basalt"
    },
    {
      "x": -1,
      "y": 21,
      "z": 0,
      "name": "Rock_Basalt"
    },
    {
      "x": -1,
      "y": 22,
      "z": 0,
      "name": "Rock_Basalt"
    },
    {
      "x": -1,
      "y": 23,
      "z": 0,
      "name": "Rock_Basalt"
    },
    {
      "x": -1,
      "y": 24,
      "z": 0,
      "name": "Rock_Basalt"
    },
    {
      "x": -1,
      "y": 25,
      "z": 0,
      "name": "Rock_Basalt"
    },
    {
      "x": -1,
      "y": 26,
      "z": 0,
      "name": "Rock_Basalt"
    },
    {
      "x": -1,
      "y": 27,
      "z": 0,
      "name": "Rock_Basalt_Cobble"
    },
    {
      "x": -1,
      "y": 28,
      "z": 0,
      "name": "Rock_Basalt"
    },
    {
      "x": -1,
      "y": 29,
      "z": 0,
      "name": "Rock_Basalt_Cobble"
    },
    {
      "x": -1,
      "y": 30,
      "z": 0,
      "name": "Rock_Basalt"
    },
    {
      "x": -1,
      "y": 31,
      "z": 0,
      "name": "Rock_Basalt"
    },
    {
      "x": -1,
      "y": 32,
      "z": 0,
      "name": "Rock_Basalt"
    },
    {
      "x": -1,
      "y": 33,
      "z": 0,
      "name": "Rock_Basalt_Cobble"
    },
    {
      "x": -1,
      "y": 34,
      "z": 0,
      "name": "Rock_Basalt"
    },
    {
      "x": -1,
      "y": 35,
      "z": 0,
      "name": "Rock_Basalt"
    },
    {
      "x": -1,
      "y": 36,
      "z": 0,
      "name": "Rock_Basalt"
    },
    {
      "x": -1,
      "y": 37,
      "z": 0,
      "name": "Rock_Basalt"
    },
    {
      "x": -1,
      "y": 38,
      "z": 0,
      "name": "Rock_Basalt"
    },
    {
      "x": -1,
      "y": 39,
      "z": 0,
      "name": "Rock_Basalt"
    },
    {
      "x": -1,
      "y": 40,
      "z": 0,
      "name": "Rock_Basalt"
    },
    {
      "x": -1,
      "y": 5,
      "z": 1,
      "name": "Rock_Basalt"
    },
    {
      "x": -1,
      "y": 6,
      "z": 1,
      "name": "Rock_Basalt"
    },
    {
      "x": -1,
      "y": 7,
      "z": 1,
      "name": "Rock_Basalt"
    },
    {
      "x": -1,
      "y": 8,
      "z": 1,
      "name": "Rock_Basalt"
    },
    {
      "x": -1,
      "y": 9,
      "z": 1,
      "name": "Rock_Basalt"
    },
    {
      "x": -1,
      "y": 10,
      "z": 1,
      "name": "Rock_Basalt"
    },
    {
      "x": -1,
      "y": 11,
      "z": 1,
      "name": "Rock_Basalt_Cobble"
    },
    {
      "x": -1,
      "y": 12,
      "z": 1,
      "name": "Rock_Basalt_Cobble"
    },
    {
      "x": -1,
      "y": 13,
      "z": 1,
      "name": "Rock_Basalt_Cobble"
    },
    {
      "x": -1,
      "y": 14,
      "z": 1,
      "name": "Rock_Basalt_Cobble"
    },
    {
      "x": -1,
      "y": 15,
      "z": 1,
      "name": "Rock_Basalt_Cobble"
    },
    {
      "x": -1,
      "y": 16,
      "z": 1,
      "name": "Rock_Basalt_Cobble"
    },
    {
      "x": -1,
      "y": 17,
      "z": 1,
      "name": "Rock_Basalt"
    },
    {
      "x": -1,
      "y": 18,
      "z": 1,
      "name": "Rock_Basalt"
    },
    {
      "x": -1,
      "y": 19,
      "z": 1,
      "name": "Rock_Basalt"
    },
    {
      "x": -1,
      "y": 20,
      "z": 1,
      "name": "Rock_Basalt"
    },
    {
      "x": -1,
      "y": 21,
      "z": 1,
      "name": "Rock_Basalt"
    },
    {
      "x": -1,
      "y": 22,
      "z": 1,
      "name": "Rock_Basalt"
    },
    {
      "x": -1,
      "y": 23,
      "z": 1,
      "name": "Rock_Basalt"
    },
    {
      "x": -1,
      "y": 24,
      "z": 1,
      "name": "Rock_Basalt"
    },
    {
      "x": -1,
      "y": 25,
      "z": 1,
      "name": "Rock_Basalt"
    },
    {
      "x": -1,
      "y": 26,
      "z": 1,
      "name": "Rock_Basalt"
    },
    {
      "x": -1,
      "y": 27,
      "z": 1,
      "name": "Rock_Basalt"
    },
    {
      "x": -1,
      "y": 28,
      "z": 1,
      "name": "Rock_Basalt"
    },
    {
      "x": -1,
      "y": 29,
      "z": 1,
      "name": "Rock_Basalt"
    },
    {
      "x": -1,
      "y": 30,
      "z": 1,
      "name": "Rock_Basalt"
    },
    {
      "x": -1,
      "y": 31,
      "z": 1,
      "name": "Rock_Basalt"
    },
    {
      "x": -1,
      "y": 32,
      "z": 1,
      "name": "Rock_Basalt_Cobble"
    },
    {
      "x": -1,
      "y": 33,
      "z": 1,
      "name": "Rock_Basalt_Cobble"
    },
    {
      "x": -1,
      "y": 34,
      "z": 1,
      "name": "Rock_Basalt_Cobble"
    },
    {
      "x": -1,
      "y": 35,
      "z": 1,
      "name": "Rock_Basalt"
    },
    {
      "x": -1,
      "y": 36,
      "z": 1,
      "name": "Rock_Basalt"
    },
    {
      "x": -1,
      "y": 37,
      "z": 1,
      "name": "Rock_Basalt"
    },
    {
      "x": -1,
      "y": 38,
      "z": 1,
      "name": "Rock_Basalt"
    },
    {
      "x": -1,
      "y": 39,
      "z": 1,
      "name": "Rock_Basalt"
    },
    {
      "x": -1,
      "y": 40,
      "z": 1,
      "name": "Rock_Basalt"
    },
    {
      "x": -1,
      "y": 5,
      "z": 2,
      "name": "Rock_Basalt"
    },
    {
      "x": -1,
      "y": 6,
      "z": 2,
      "name": "Rock_Basalt"
    },
    {
      "x": -1,
      "y": 7,
      "z": 2,
      "name": "Rock_Basalt"
    },
    {
      "x": -1,
      "y": 8,
      "z": 2,
      "name": "Rock_Basalt"
    },
    {
      "x": -1,
      "y": 9,
      "z": 2,
      "name": "Rock_Basalt"
    },
    {
      "x": -1,
      "y": 10,
      "z": 2,
      "name": "Rock_Basalt"
    },
    {
      "x": -1,
      "y": 11,
      "z": 2,
      "name": "Rock_Basalt_Cobble"
    },
    {
      "x": -1,
      "y": 12,
      "z": 2,
      "name": "Rock_Basalt_Cobble"
    },
    {
      "x": -1,
      "y": 13,
      "z": 2,
      "name": "Rock_Basalt"
    },
    {
      "x": -1,
      "y": 14,
      "z": 2,
      "name": "Rock_Basalt"
    },
    {
      "x": -1,
      "y": 15,
      "z": 2,
      "name": "Rock_Basalt_Cobble"
    },
    {
      "x": -1,
      "y": 16,
      "z": 2,
      "name": "Rock_Basalt"
    },
    {
      "x": -1,
      "y": 17,
      "z": 2,
      "name": "Rock_Basalt"
    },
    {
      "x": -1,
      "y": 18,
      "z": 2,
      "name": "Rock_Basalt_Cobble"
    },
    {
      "x": -1,
      "y": 19,
      "z": 2,
      "name": "Rock_Basalt"
    },
    {
      "x": -1,
      "y": 20,
      "z": 2,
      "name": "Rock_Basalt"
    },
    {
      "x": -1,
      "y": 21,
      "z": 2,
      "name": "Rock_Basalt"
    },
    {
      "x": -1,
      "y": 22,
      "z": 2,
      "name": "Rock_Basalt"
    },
    {
      "x": -1,
      "y": 23,
      "z": 2,
      "name": "Rock_Basalt"
    },
    {
      "x": -1,
      "y": 29,
      "z": 2,
      "name": "Rock_Basalt"
    },
    {
      "x": -1,
      "y": 30,
      "z": 2,
      "name": "Rock_Basalt"
    },
    {
      "x": -1,
      "y": 31,
      "z": 2,
      "name": "Rock_Basalt"
    },
    {
      "x": -1,
      "y": 32,
      "z": 2,
      "name": "Rock_Basalt"
    },
    {
      "x": -1,
      "y": 33,
      "z": 2,
      "name": "Rock_Basalt_Cobble"
    },
    {
      "x": -1,
      "y": 34,
      "z": 2,
      "name": "Rock_Basalt"
    },
    {
      "x": -1,
      "y": 35,
      "z": 2,
      "name": "Rock_Basalt"
    },
    {
      "x": -1,
      "y": 36,
      "z": 2,
      "name": "Rock_Basalt_Cobble"
    },
    {
      "x": -1,
      "y": 37,
      "z": 2,
      "name": "Rock_Basalt_Cobble"
    },
    {
      "x": -1,
      "y": 38,
      "z": 2,
      "name": "Rock_Basalt_Cobble"
    },
    {
      "x": -1,
      "y": 39,
      "z": 2,
      "name": "Rock_Basalt_Cobble"
    },
    {
      "x": -1,
      "y": 40,
      "z": 2,
      "name": "Rock_Basalt"
    },
    {
      "x": -1,
      "y": 6,
      "z": 3,
      "name": "Rock_Basalt"
    },
    {
      "x": -1,
      "y": 7,
      "z": 3,
      "name": "Rock_Basalt"
    },
    {
      "x": -1,
      "y": 8,
      "z": 3,
      "name": "Rock_Basalt"
    },
    {
      "x": -1,
      "y": 9,
      "z": 3,
      "name": "Rock_Basalt_Cobble"
    },
    {
      "x": -1,
      "y": 10,
      "z": 3,
      "name": "Rock_Basalt_Cobble"
    },
    {
      "x": -1,
      "y": 11,
      "z": 3,
      "name": "Plant_Crop_Mushroom_Block_Purple_Trunk"
    },
    {
      "x": -1,
      "y": 12,
      "z": 3,
      "name": "Plant_Crop_Mushroom_Block_Purple_Trunk"
    },
    {
      "x": -1,
      "y": 13,
      "z": 3,
      "name": "Plant_Crop_Mushroom_Block_Purple_Trunk"
    },
    {
      "x": -1,
      "y": 14,
      "z": 3,
      "name": "Rock_Basalt_Cobble"
    },
    {
      "x": -1,
      "y": 15,
      "z": 3,
      "name": "Rock_Basalt_Cobble"
    },
    {
      "x": -1,
      "y": 16,
      "z": 3,
      "name": "Soil_Gravel"
    },
    {
      "x": -1,
      "y": 17,
      "z": 3,
      "name": "Rock_Basalt_Cobble"
    },
    {
      "x": -1,
      "y": 18,
      "z": 3,
      "name": "Soil_Gravel"
    },
    {
      "x": -1,
      "y": 19,
      "z": 3,
      "name": "Rock_Basalt_Cobble"
    },
    {
      "x": -1,
      "y": 20,
      "z": 3,
      "name": "Rock_Basalt_Cobble"
    },
    {
      "x": -1,
      "y": 21,
      "z": 3,
      "name": "Rock_Basalt"
    },
    {
      "x": -1,
      "y": 32,
      "z": 3,
      "name": "Rock_Basalt"
    },
    {
      "x": -1,
      "y": 33,
      "z": 3,
      "name": "Rock_Basalt"
    },
    {
      "x": -1,
      "y": 34,
      "z": 3,
      "name": "Rock_Basalt"
    },
    {
      "x": -1,
      "y": 35,
      "z": 3,
      "name": "Rock_Basalt_Cobble"
    },
    {
      "x": -1,
      "y": 36,
      "z": 3,
      "name": "Rock_Basalt_Cobble"
    },
    {
      "x": -1,
      "y": 37,
      "z": 3,
      "name": "Soil_Gravel"
    },
    {
      "x": -1,
      "y": 38,
      "z": 3,
      "name": "Soil_Gravel"
    },
    {
      "x": -1,
      "y": 39,
      "z": 3,
      "name": "Rock_Basalt_Cobble"
    },
    {
      "x": -1,
      "y": 40,
      "z": 3,
      "name": "Rock_Basalt_Cobble"
    },
    {
      "x": -1,
      "y": 6,
      "z": 4,
      "name": "Rock_Basalt"
    },
    {
      "x": -1,
      "y": 7,
      "z": 4,
      "name": "Rock_Basalt"
    },
    {
      "x": -1,
      "y": 8,
      "z": 4,
      "name": "Rock_Basalt_Cobble"
    },
    {
      "x": -1,
      "y": 9,
      "z": 4,
      "name": "Rock_Basalt_Cobble"
    },
    {
      "x": -1,
      "y": 10,
      "z": 4,
      "name": "Rock_Basalt_Cobble"
    },
    {
      "x": -1,
      "y": 14,
      "z": 4,
      "name": "Rock_Basalt_Cobble"
    },
    {
      "x": -1,
      "y": 15,
      "z": 4,
      "name": "Soil_Gravel"
    },
    {
      "x": -1,
      "y": 16,
      "z": 4,
      "name": "Soil_Gravel"
    },
    {
      "x": -1,
      "y": 36,
      "z": 4,
      "name": "Rock_Basalt_Cobble"
    },
    {
      "x": -1,
      "y": 37,
      "z": 4,
      "name": "Rock_Basalt_Cobble"
    },
    {
      "x": -1,
      "y": 38,
      "z": 4,
      "name": "Rock_Basalt_Cobble"
    },
    {
      "x": -1,
      "y": 39,
      "z": 4,
      "name": "Soil_Gravel"
    },
    {
      "x": -1,
      "y": 40,
      "z": 4,
      "name": "Rock_Basalt_Cobble"
    },
    {
      "x": -1,
      "y": 41,
      "z": 4,
      "name": "Rock_Basalt"
    },
    {
      "x": -1,
      "y": 7,
      "z": 5,
      "name": "Rock_Basalt"
    },
    {
      "x": -1,
      "y": 8,
      "z": 5,
      "name": "Rock_Basalt"
    },
    {
      "x": -1,
      "y": 9,
      "z": 5,
      "name": "Rock_Basalt_Cobble"
    },
    {
      "x": -1,
      "y": 38,
      "z": 5,
      "name": "Rock_Basalt_Cobble"
    },
    {
      "x": -1,
      "y": 39,
      "z": 5,
      "name": "Soil_Gravel"
    },
    {
      "x": -1,
      "y": 40,
      "z": 5,
      "name": "Rock_Basalt_Cobble"
    },
    {
      "x": -1,
      "y": 41,
      "z": 5,
      "name": "Rock_Basalt_Cobble"
    },
    {
      "x": -1,
      "y": 37,
      "z": 6,
      "name": "Rock_Basalt_Cobble"
    },
    {
      "x": -1,
      "y": 38,
      "z": 6,
      "name": "Rock_Basalt_Cobble"
    },
    {
      "x": -1,
      "y": 39,
      "z": 6,
      "name": "Rock_Basalt_Cobble"
    },
    {
      "x": -1,
      "y": 40,
      "z": 6,
      "name": "Rock_Basalt_Cobble"
    },
    {
      "x": -1,
      "y": 41,
      "z": 6,
      "name": "Rock_Basalt"
    },
    {
      "x": -1,
      "y": 38,
      "z": 7,
      "name": "Rock_Basalt"
    },
    {
      "x": -1,
      "y": 39,
      "z": 7,
      "name": "Rock_Basalt_Cobble"
    },
    {
      "x": -1,
      "y": 40,
      "z": 7,
      "name": "Rock_Basalt"
    },
    {
      "x": -1,
      "y": 41,
      "z": 7,
      "name": "Rock_Basalt"
    },
    {
      "x": -1,
      "y": 39,
      "z": 8,
      "name": "Rock_Basalt"
    },
    {
      "x": -1,
      "y": 40,
      "z": 8,
      "name": "Rock_Basalt"
    },
    {
      "x": -1,
      "y": 41,
      "z": 8,
      "name": "Rock_Basalt"
    },
    {
      "x": 0,
      "y": 7,
      "z": -5,
      "name": "Rock_Basalt"
    },
    {
      "x": 0,
      "y": 8,
      "z": -5,
      "name": "Rock_Basalt"
    },
    {
      "x": 0,
      "y": 9,
      "z": -5,
      "name": "Rock_Basalt"
    },
    {
      "x": 0,
      "y": 10,
      "z": -5,
      "name": "Rock_Basalt"
    },
    {
      "x": 0,
      "y": 30,
      "z": -5,
      "name": "Plant_Crop_Mushroom_Block_Purple"
    },
    {
      "x": 0,
      "y": 35,
      "z": -5,
      "name": "Rock_Basalt"
    },
    {
      "x": 0,
      "y": 36,
      "z": -5,
      "name": "Rock_Basalt"
    },
    {
      "x": 0,
      "y": 37,
      "z": -5,
      "name": "Rock_Basalt"
    },
    {
      "x": 0,
      "y": 38,
      "z": -5,
      "name": "Rock_Basalt"
    },
    {
      "x": 0,
      "y": 6,
      "z": -4,
      "name": "Rock_Basalt"
    },
    {
      "x": 0,
      "y": 7,
      "z": -4,
      "name": "Rock_Basalt"
    },
    {
      "x": 0,
      "y": 8,
      "z": -4,
      "name": "Rock_Basalt"
    },
    {
      "x": 0,
      "y": 9,
      "z": -4,
      "name": "Rock_Basalt"
    },
    {
      "x": 0,
      "y": 10,
      "z": -4,
      "name": "Rock_Basalt"
    },
    {
      "x": 0,
      "y": 11,
      "z": -4,
      "name": "Rock_Basalt"
    },
    {
      "x": 0,
      "y": 21,
      "z": -4,
      "name": "Soil_Gravel"
    },
    {
      "x": 0,
      "y": 22,
      "z": -4,
      "name": "Soil_Gravel"
    },
    {
      "x": 0,
      "y": 23,
      "z": -4,
      "name": "Soil_Gravel"
    },
    {
      "x": 0,
      "y": 24,
      "z": -4,
      "name": "Soil_Gravel"
    },
    {
      "x": 0,
      "y": 25,
      "z": -4,
      "name": "Rock_Basalt_Cobble"
    },
    {
      "x": 0,
      "y": 26,
      "z": -4,
      "name": "Rock_Basalt"
    },
    {
      "x": 0,
      "y": 27,
      "z": -4,
      "name": "Rock_Basalt"
    },
    {
      "x": 0,
      "y": 28,
      "z": -4,
      "name": "Rock_Basalt"
    },
    {
      "x": 0,
      "y": 29,
      "z": -4,
      "name": "Rock_Basalt"
    },
    {
      "x": 0,
      "y": 30,
      "z": -4,
      "name": "Plant_Crop_Mushroom_Block_Purple"
    },
    {
      "x": 0,
      "y": 33,
      "z": -4,
      "name": "Rock_Basalt"
    },
    {
      "x": 0,
      "y": 34,
      "z": -4,
      "name": "Rock_Basalt"
    },
    {
      "x": 0,
      "y": 35,
      "z": -4,
      "name": "Rock_Basalt"
    },
    {
      "x": 0,
      "y": 36,
      "z": -4,
      "name": "Rock_Basalt"
    },
    {
      "x": 0,
      "y": 37,
      "z": -4,
      "name": "Rock_Basalt"
    },
    {
      "x": 0,
      "y": 38,
      "z": -4,
      "name": "Rock_Basalt"
    },
    {
      "x": 0,
      "y": 39,
      "z": -4,
      "name": "Rock_Basalt"
    },
    {
      "x": 0,
      "y": 40,
      "z": -4,
      "name": "Rock_Basalt"
    },
    {
      "x": 0,
      "y": 6,
      "z": -3,
      "name": "Rock_Basalt"
    },
    {
      "x": 0,
      "y": 7,
      "z": -3,
      "name": "Rock_Basalt"
    },
    {
      "x": 0,
      "y": 8,
      "z": -3,
      "name": "Rock_Basalt"
    },
    {
      "x": 0,
      "y": 9,
      "z": -3,
      "name": "Rock_Basalt"
    },
    {
      "x": 0,
      "y": 10,
      "z": -3,
      "name": "Rock_Basalt"
    },
    {
      "x": 0,
      "y": 11,
      "z": -3,
      "name": "Rock_Basalt"
    },
    {
      "x": 0,
      "y": 12,
      "z": -3,
      "name": "Rock_Basalt_Cobble"
    },
    {
      "x": 0,
      "y": 13,
      "z": -3,
      "name": "Rock_Basalt"
    },
    {
      "x": 0,
      "y": 14,
      "z": -3,
      "name": "Rock_Basalt"
    },
    {
      "x": 0,
      "y": 15,
      "z": -3,
      "name": "Rock_Basalt_Cobble"
    },
    {
      "x": 0,
      "y": 18,
      "z": -3,
      "name": "Rock_Basalt_Cobble"
    },
    {
      "x": 0,
      "y": 19,
      "z": -3,
      "name": "Rock_Basalt_Cobble"
    },
    {
      "x": 0,
      "y": 20,
      "z": -3,
      "name": "Soil_Gravel"
    },
    {
      "x": 0,
      "y": 21,
      "z": -3,
      "name": "Soil_Gravel"
    },
    {
      "x": 0,
      "y": 22,
      "z": -3,
      "name": "Soil_Gravel"
    },
    {
      "x": 0,
      "y": 23,
      "z": -3,
      "name": "Rock_Basalt_Cobble"
    },
    {
      "x": 0,
      "y": 24,
      "z": -3,
      "name": "Rock_Basalt_Cobble"
    },
    {
      "x": 0,
      "y": 25,
      "z": -3,
      "name": "Rock_Basalt_Cobble"
    },
    {
      "x": 0,
      "y": 26,
      "z": -3,
      "name": "Rock_Basalt_Cobble"
    },
    {
      "x": 0,
      "y": 27,
      "z": -3,
      "name": "Rock_Basalt_Cobble"
    },
    {
      "x": 0,
      "y": 28,
      "z": -3,
      "name": "Rock_Basalt"
    },
    {
      "x": 0,
      "y": 29,
      "z": -3,
      "name": "Rock_Basalt"
    },
    {
      "x": 0,
      "y": 30,
      "z": -3,
      "name": "Rock_Basalt"
    },
    {
      "x": 0,
      "y": 31,
      "z": -3,
      "name": "Rock_Basalt"
    },
    {
      "x": 0,
      "y": 32,
      "z": -3,
      "name": "Rock_Basalt"
    },
    {
      "x": 0,
      "y": 33,
      "z": -3,
      "name": "Rock_Basalt_Cobble"
    },
    {
      "x": 0,
      "y": 34,
      "z": -3,
      "name": "Rock_Basalt"
    },
    {
      "x": 0,
      "y": 35,
      "z": -3,
      "name": "Rock_Basalt"
    },
    {
      "x": 0,
      "y": 36,
      "z": -3,
      "name": "Rock_Basalt"
    },
    {
      "x": 0,
      "y": 37,
      "z": -3,
      "name": "Rock_Basalt"
    },
    {
      "x": 0,
      "y": 38,
      "z": -3,
      "name": "Rock_Basalt"
    },
    {
      "x": 0,
      "y": 39,
      "z": -3,
      "name": "Rock_Basalt"
    },
    {
      "x": 0,
      "y": 40,
      "z": -3,
      "name": "Rock_Basalt"
    },
    {
      "x": 0,
      "y": 5,
      "z": -2,
      "name": "Rock_Basalt"
    },
    {
      "x": 0,
      "y": 6,
      "z": -2,
      "name": "Rock_Basalt"
    },
    {
      "x": 0,
      "y": 7,
      "z": -2,
      "name": "Rock_Basalt"
    },
    {
      "x": 0,
      "y": 8,
      "z": -2,
      "name": "Rock_Basalt"
    },
    {
      "x": 0,
      "y": 9,
      "z": -2,
      "name": "Rock_Basalt"
    },
    {
      "x": 0,
      "y": 10,
      "z": -2,
      "name": "Rock_Basalt"
    },
    {
      "x": 0,
      "y": 11,
      "z": -2,
      "name": "Rock_Basalt_Cobble"
    },
    {
      "x": 0,
      "y": 12,
      "z": -2,
      "name": "Rock_Basalt_Cobble"
    },
    {
      "x": 0,
      "y": 13,
      "z": -2,
      "name": "Rock_Basalt_Cobble"
    },
    {
      "x": 0,
      "y": 14,
      "z": -2,
      "name": "Rock_Basalt_Cobble"
    },
    {
      "x": 0,
      "y": 15,
      "z": -2,
      "name": "Rock_Basalt_Cobble"
    },
    {
      "x": 0,
      "y": 16,
      "z": -2,
      "name": "Rock_Basalt_Cobble"
    },
    {
      "x": 0,
      "y": 17,
      "z": -2,
      "name": "Rock_Basalt_Cobble"
    },
    {
      "x": 0,
      "y": 18,
      "z": -2,
      "name": "Rock_Basalt"
    },
    {
      "x": 0,
      "y": 19,
      "z": -2,
      "name": "Rock_Basalt_Cobble"
    },
    {
      "x": 0,
      "y": 20,
      "z": -2,
      "name": "Rock_Basalt_Cobble"
    },
    {
      "x": 0,
      "y": 21,
      "z": -2,
      "name": "Rock_Basalt_Cobble"
    },
    {
      "x": 0,
      "y": 22,
      "z": -2,
      "name": "Rock_Basalt_Cobble"
    },
    {
      "x": 0,
      "y": 23,
      "z": -2,
      "name": "Rock_Basalt_Cobble"
    },
    {
      "x": 0,
      "y": 24,
      "z": -2,
      "name": "Rock_Basalt"
    },
    {
      "x": 0,
      "y": 25,
      "z": -2,
      "name": "Rock_Basalt_Cobble"
    },
    {
      "x": 0,
      "y": 26,
      "z": -2,
      "name": "Rock_Basalt_Cobble"
    },
    {
      "x": 0,
      "y": 27,
      "z": -2,
      "name": "Rock_Basalt_Cobble"
    },
    {
      "x": 0,
      "y": 28,
      "z": -2,
      "name": "Rock_Basalt_Cobble"
    },
    {
      "x": 0,
      "y": 29,
      "z": -2,
      "name": "Rock_Basalt"
    },
    {
      "x": 0,
      "y": 30,
      "z": -2,
      "name": "Rock_Basalt"
    },
    {
      "x": 0,
      "y": 31,
      "z": -2,
      "name": "Rock_Basalt"
    },
    {
      "x": 0,
      "y": 32,
      "z": -2,
      "name": "Rock_Basalt_Cobble"
    },
    {
      "x": 0,
      "y": 33,
      "z": -2,
      "name": "Rock_Basalt_Cobble"
    },
    {
      "x": 0,
      "y": 34,
      "z": -2,
      "name": "Rock_Basalt_Cobble"
    },
    {
      "x": 0,
      "y": 35,
      "z": -2,
      "name": "Rock_Basalt"
    },
    {
      "x": 0,
      "y": 36,
      "z": -2,
      "name": "Rock_Basalt"
    },
    {
      "x": 0,
      "y": 37,
      "z": -2,
      "name": "Rock_Basalt"
    },
    {
      "x": 0,
      "y": 38,
      "z": -2,
      "name": "Rock_Basalt"
    },
    {
      "x": 0,
      "y": 39,
      "z": -2,
      "name": "Rock_Basalt"
    },
    {
      "x": 0,
      "y": 40,
      "z": -2,
      "name": "Rock_Basalt"
    },
    {
      "x": 0,
      "y": 5,
      "z": -1,
      "name": "Rock_Basalt"
    },
    {
      "x": 0,
      "y": 6,
      "z": -1,
      "name": "Rock_Basalt"
    },
    {
      "x": 0,
      "y": 7,
      "z": -1,
      "name": "Rock_Basalt"
    },
    {
      "x": 0,
      "y": 8,
      "z": -1,
      "name": "Rock_Basalt"
    },
    {
      "x": 0,
      "y": 9,
      "z": -1,
      "name": "Rock_Basalt"
    },
    {
      "x": 0,
      "y": 10,
      "z": -1,
      "name": "Rock_Basalt"
    },
    {
      "x": 0,
      "y": 11,
      "z": -1,
      "name": "Rock_Basalt"
    },
    {
      "x": 0,
      "y": 12,
      "z": -1,
      "name": "Rock_Basalt_Cobble"
    },
    {
      "x": 0,
      "y": 13,
      "z": -1,
      "name": "Rock_Basalt"
    },
    {
      "x": 0,
      "y": 14,
      "z": -1,
      "name": "Rock_Basalt"
    },
    {
      "x": 0,
      "y": 15,
      "z": -1,
      "name": "Rock_Basalt_Cobble"
    },
    {
      "x": 0,
      "y": 16,
      "z": -1,
      "name": "Rock_Basalt_Cobble"
    },
    {
      "x": 0,
      "y": 17,
      "z": -1,
      "name": "Rock_Basalt"
    },
    {
      "x": 0,
      "y": 18,
      "z": -1,
      "name": "Rock_Basalt"
    },
    {
      "x": 0,
      "y": 19,
      "z": -1,
      "name": "Rock_Basalt"
    },
    {
      "x": 0,
      "y": 20,
      "z": -1,
      "name": "Rock_Basalt_Cobble"
    },
    {
      "x": 0,
      "y": 21,
      "z": -1,
      "name": "Rock_Basalt"
    },
    {
      "x": 0,
      "y": 22,
      "z": -1,
      "name": "Rock_Basalt"
    },
    {
      "x": 0,
      "y": 23,
      "z": -1,
      "name": "Rock_Basalt"
    },
    {
      "x": 0,
      "y": 24,
      "z": -1,
      "name": "Rock_Basalt"
    },
    {
      "x": 0,
      "y": 25,
      "z": -1,
      "name": "Rock_Basalt_Cobble"
    },
    {
      "x": 0,
      "y": 26,
      "z": -1,
      "name": "Rock_Basalt_Cobble"
    },
    {
      "x": 0,
      "y": 27,
      "z": -1,
      "name": "Rock_Basalt_Cobble"
    },
    {
      "x": 0,
      "y": 28,
      "z": -1,
      "name": "Rock_Basalt"
    },
    {
      "x": 0,
      "y": 29,
      "z": -1,
      "name": "Rock_Basalt"
    },
    {
      "x": 0,
      "y": 30,
      "z": -1,
      "name": "Rock_Basalt"
    },
    {
      "x": 0,
      "y": 31,
      "z": -1,
      "name": "Rock_Basalt"
    },
    {
      "x": 0,
      "y": 32,
      "z": -1,
      "name": "Rock_Basalt"
    },
    {
      "x": 0,
      "y": 33,
      "z": -1,
      "name": "Rock_Basalt_Cobble"
    },
    {
      "x": 0,
      "y": 34,
      "z": -1,
      "name": "Rock_Basalt"
    },
    {
      "x": 0,
      "y": 35,
      "z": -1,
      "name": "Rock_Basalt"
    },
    {
      "x": 0,
      "y": 36,
      "z": -1,
      "name": "Rock_Basalt"
    },
    {
      "x": 0,
      "y": 37,
      "z": -1,
      "name": "Rock_Basalt"
    },
    {
      "x": 0,
      "y": 38,
      "z": -1,
      "name": "Rock_Basalt"
    },
    {
      "x": 0,
      "y": 39,
      "z": -1,
      "name": "Rock_Basalt"
    },
    {
      "x": 0,
      "y": 40,
      "z": -1,
      "name": "Rock_Basalt"
    },
    {
      "x": 0,
      "y": 5,
      "z": 0,
      "name": "Rock_Basalt"
    },
    {
      "x": 0,
      "y": 6,
      "z": 0,
      "name": "Rock_Basalt"
    },
    {
      "x": 0,
      "y": 7,
      "z": 0,
      "name": "Rock_Basalt"
    },
    {
      "x": 0,
      "y": 8,
      "z": 0,
      "name": "Rock_Basalt"
    },
    {
      "x": 0,
      "y": 9,
      "z": 0,
      "name": "Rock_Basalt"
    },
    {
      "x": 0,
      "y": 10,
      "z": 0,
      "name": "Rock_Basalt"
    },
    {
      "x": 0,
      "y": 11,
      "z": 0,
      "name": "Rock_Basalt"
    },
    {
      "x": 0,
      "y": 12,
      "z": 0,
      "name": "Rock_Basalt"
    },
    {
      "x": 0,
      "y": 13,
      "z": 0,
      "name": "Rock_Basalt"
    },
    {
      "x": 0,
      "y": 14,
      "z": 0,
      "name": "Rock_Basalt"
    },
    {
      "x": 0,
      "y": 15,
      "z": 0,
      "name": "Rock_Basalt"
    },
    {
      "x": 0,
      "y": 16,
      "z": 0,
      "name": "Rock_Basalt"
    },
    {
      "x": 0,
      "y": 17,
      "z": 0,
      "name": "Rock_Basalt"
    },
    {
      "x": 0,
      "y": 18,
      "z": 0,
      "name": "Rock_Basalt"
    },
    {
      "x": 0,
      "y": 19,
      "z": 0,
      "name": "Rock_Basalt"
    },
    {
      "x": 0,
      "y": 20,
      "z": 0,
      "name": "Rock_Basalt"
    },
    {
      "x": 0,
      "y": 21,
      "z": 0,
      "name": "Rock_Basalt"
    },
    {
      "x": 0,
      "y": 22,
      "z": 0,
      "name": "Rock_Basalt"
    },
    {
      "x": 0,
      "y": 23,
      "z": 0,
      "name": "Rock_Basalt_Cobble"
    },
    {
      "x": 0,
      "y": 24,
      "z": 0,
      "name": "Rock_Basalt"
    },
    {
      "x": 0,
      "y": 25,
      "z": 0,
      "name": "Rock_Basalt"
    },
    {
      "x": 0,
      "y": 26,
      "z": 0,
      "name": "Rock_Basalt_Cobble"
    },
    {
      "x": 0,
      "y": 27,
      "z": 0,
      "name": "Rock_Basalt"
    },
    {
      "x": 0,
      "y": 28,
      "z": 0,
      "name": "Rock_Basalt"
    },
    {
      "x": 0,
      "y": 29,
      "z": 0,
      "name": "Rock_Basalt"
    },
    {
      "x": 0,
      "y": 30,
      "z": 0,
      "name": "Rock_Basalt"
    },
    {
      "x": 0,
      "y": 31,
      "z": 0,
      "name": "Rock_Basalt"
    },
    {
      "x": 0,
      "y": 32,
      "z": 0,
      "name": "Rock_Basalt_Cobble"
    },
    {
      "x": 0,
      "y": 33,
      "z": 0,
      "name": "Rock_Basalt_Cobble"
    },
    {
      "x": 0,
      "y": 34,
      "z": 0,
      "name": "Rock_Basalt_Cobble"
    },
    {
      "x": 0,
      "y": 35,
      "z": 0,
      "name": "Rock_Basalt"
    },
    {
      "x": 0,
      "y": 36,
      "z": 0,
      "name": "Rock_Basalt"
    },
    {
      "x": 0,
      "y": 37,
      "z": 0,
      "name": "Rock_Basalt"
    },
    {
      "x": 0,
      "y": 38,
      "z": 0,
      "name": "Rock_Basalt"
    },
    {
      "x": 0,
      "y": 39,
      "z": 0,
      "name": "Rock_Basalt"
    },
    {
      "x": 0,
      "y": 40,
      "z": 0,
      "name": "Rock_Basalt"
    },
    {
      "x": 0,
      "y": 41,
      "z": 0,
      "name": "Rock_Basalt"
    },
    {
      "x": 0,
      "y": 5,
      "z": 1,
      "name": "Rock_Basalt"
    },
    {
      "x": 0,
      "y": 6,
      "z": 1,
      "name": "Rock_Basalt"
    },
    {
      "x": 0,
      "y": 7,
      "z": 1,
      "name": "Rock_Basalt"
    },
    {
      "x": 0,
      "y": 8,
      "z": 1,
      "name": "Rock_Basalt"
    },
    {
      "x": 0,
      "y": 9,
      "z": 1,
      "name": "Rock_Basalt"
    },
    {
      "x": 0,
      "y": 10,
      "z": 1,
      "name": "Rock_Basalt"
    },
    {
      "x": 0,
      "y": 11,
      "z": 1,
      "name": "Rock_Basalt"
    },
    {
      "x": 0,
      "y": 12,
      "z": 1,
      "name": "Rock_Basalt"
    },
    {
      "x": 0,
      "y": 13,
      "z": 1,
      "name": "Rock_Basalt"
    },
    {
      "x": 0,
      "y": 14,
      "z": 1,
      "name": "Rock_Basalt"
    },
    {
      "x": 0,
      "y": 15,
      "z": 1,
      "name": "Rock_Basalt"
    },
    {
      "x": 0,
      "y": 16,
      "z": 1,
      "name": "Rock_Basalt"
    },
    {
      "x": 0,
      "y": 17,
      "z": 1,
      "name": "Rock_Basalt"
    },
    {
      "x": 0,
      "y": 18,
      "z": 1,
      "name": "Rock_Basalt_Cobble"
    },
    {
      "x": 0,
      "y": 19,
      "z": 1,
      "name": "Rock_Basalt"
    },
    {
      "x": 0,
      "y": 20,
      "z": 1,
      "name": "Rock_Basalt"
    },
    {
      "x": 0,
      "y": 21,
      "z": 1,
      "name": "Rock_Basalt"
    },
    {
      "x": 0,
      "y": 22,
      "z": 1,
      "name": "Rock_Basalt_Cobble"
    },
    {
      "x": 0,
      "y": 23,
      "z": 1,
      "name": "Rock_Basalt_Cobble"
    },
    {
      "x": 0,
      "y": 24,
      "z": 1,
      "name": "Rock_Basalt_Cobble"
    },
    {
      "x": 0,
      "y": 25,
      "z": 1,
      "name": "Rock_Basalt"
    },
    {
      "x": 0,
      "y": 26,
      "z": 1,
      "name": "Rock_Basalt"
    },
    {
      "x": 0,
      "y": 27,
      "z": 1,
      "name": "Rock_Basalt"
    },
    {
      "x": 0,
      "y": 28,
      "z": 1,
      "name": "Rock_Basalt"
    },
    {
      "x": 0,
      "y": 29,
      "z": 1,
      "name": "Rock_Basalt"
    },
    {
      "x": 0,
      "y": 30,
      "z": 1,
      "name": "Rock_Basalt"
    },
    {
      "x": 0,
      "y": 31,
      "z": 1,
      "name": "Rock_Basalt_Cobble"
    },
    {
      "x": 0,
      "y": 32,
      "z": 1,
      "name": "Rock_Basalt_Cobble"
    },
    {
      "x": 0,
      "y": 33,
      "z": 1,
      "name": "Rock_Basalt_Cobble"
    },
    {
      "x": 0,
      "y": 34,
      "z": 1,
      "name": "Rock_Basalt_Cobble"
    },
    {
      "x": 0,
      "y": 35,
      "z": 1,
      "name": "Rock_Basalt_Cobble"
    },
    {
      "x": 0,
      "y": 36,
      "z": 1,
      "name": "Rock_Basalt"
    },
    {
      "x": 0,
      "y": 37,
      "z": 1,
      "name": "Rock_Basalt"
    },
    {
      "x": 0,
      "y": 38,
      "z": 1,
      "name": "Rock_Basalt"
    },
    {
      "x": 0,
      "y": 39,
      "z": 1,
      "name": "Rock_Basalt"
    },
    {
      "x": 0,
      "y": 40,
      "z": 1,
      "name": "Rock_Basalt"
    },
    {
      "x": 0,
      "y": 41,
      "z": 1,
      "name": "Rock_Basalt"
    },
    {
      "x": 0,
      "y": 5,
      "z": 2,
      "name": "Rock_Basalt"
    },
    {
      "x": 0,
      "y": 6,
      "z": 2,
      "name": "Rock_Basalt"
    },
    {
      "x": 0,
      "y": 7,
      "z": 2,
      "name": "Rock_Basalt"
    },
    {
      "x": 0,
      "y": 8,
      "z": 2,
      "name": "Rock_Basalt"
    },
    {
      "x": 0,
      "y": 9,
      "z": 2,
      "name": "Rock_Basalt"
    },
    {
      "x": 0,
      "y": 10,
      "z": 2,
      "name": "Rock_Basalt"
    },
    {
      "x": 0,
      "y": 11,
      "z": 2,
      "name": "Rock_Basalt"
    },
    {
      "x": 0,
      "y": 12,
      "z": 2,
      "name": "Rock_Basalt"
    },
    {
      "x": 0,
      "y": 13,
      "z": 2,
      "name": "Rock_Basalt"
    },
    {
      "x": 0,
      "y": 14,
      "z": 2,
      "name": "Rock_Basalt"
    },
    {
      "x": 0,
      "y": 15,
      "z": 2,
      "name": "Rock_Basalt"
    },
    {
      "x": 0,
      "y": 16,
      "z": 2,
      "name": "Rock_Basalt"
    },
    {
      "x": 0,
      "y": 17,
      "z": 2,
      "name": "Rock_Basalt_Cobble"
    },
    {
      "x": 0,
      "y": 18,
      "z": 2,
      "name": "Soil_Gravel"
    },
    {
      "x": 0,
      "y": 19,
      "z": 2,
      "name": "Soil_Gravel"
    },
    {
      "x": 0,
      "y": 20,
      "z": 2,
      "name": "Rock_Basalt_Cobble"
    },
    {
      "x": 0,
      "y": 21,
      "z": 2,
      "name": "Rock_Basalt"
    },
    {
      "x": 0,
      "y": 22,
      "z": 2,
      "name": "Rock_Basalt"
    },
    {
      "x": 0,
      "y": 23,
      "z": 2,
      "name": "Rock_Basalt_Cobble"
    },
    {
      "x": 0,
      "y": 27,
      "z": 2,
      "name": "Rock_Basalt"
    },
    {
      "x": 0,
      "y": 28,
      "z": 2,
      "name": "Rock_Basalt"
    },
    {
      "x": 0,
      "y": 29,
      "z": 2,
      "name": "Rock_Basalt"
    },
    {
      "x": 0,
      "y": 30,
      "z": 2,
      "name": "Rock_Basalt"
    },
    {
      "x": 0,
      "y": 31,
      "z": 2,
      "name": "Rock_Basalt"
    },
    {
      "x": 0,
      "y": 32,
      "z": 2,
      "name": "Rock_Basalt_Cobble"
    },
    {
      "x": 0,
      "y": 33,
      "z": 2,
      "name": "Rock_Basalt_Cobble"
    },
    {
      "x": 0,
      "y": 34,
      "z": 2,
      "name": "Rock_Basalt_Cobble"
    },
    {
      "x": 0,
      "y": 35,
      "z": 2,
      "name": "Rock_Basalt"
    },
    {
      "x": 0,
      "y": 36,
      "z": 2,
      "name": "Rock_Basalt_Cobble"
    },
    {
      "x": 0,
      "y": 37,
      "z": 2,
      "name": "Rock_Basalt_Cobble"
    },
    {
      "x": 0,
      "y": 38,
      "z": 2,
      "name": "Rock_Basalt"
    },
    {
      "x": 0,
      "y": 39,
      "z": 2,
      "name": "Rock_Basalt"
    },
    {
      "x": 0,
      "y": 40,
      "z": 2,
      "name": "Rock_Basalt"
    },
    {
      "x": 0,
      "y": 41,
      "z": 2,
      "name": "Rock_Basalt"
    },
    {
      "x": 0,
      "y": 6,
      "z": 3,
      "name": "Rock_Basalt"
    },
    {
      "x": 0,
      "y": 7,
      "z": 3,
      "name": "Rock_Basalt"
    },
    {
      "x": 0,
      "y": 8,
      "z": 3,
      "name": "Rock_Basalt"
    },
    {
      "x": 0,
      "y": 9,
      "z": 3,
      "name": "Rock_Basalt"
    },
    {
      "x": 0,
      "y": 10,
      "z": 3,
      "name": "Rock_Basalt"
    },
    {
      "x": 0,
      "y": 11,
      "z": 3,
      "name": "Rock_Basalt"
    },
    {
      "x": 0,
      "y": 12,
      "z": 3,
      "name": "Rock_Basalt"
    },
    {
      "x": 0,
      "y": 13,
      "z": 3,
      "name": "Rock_Basalt"
    },
    {
      "x": 0,
      "y": 14,
      "z": 3,
      "name": "Rock_Basalt"
    },
    {
      "x": 0,
      "y": 15,
      "z": 3,
      "name": "Rock_Basalt_Cobble"
    },
    {
      "x": 0,
      "y": 16,
      "z": 3,
      "name": "Rock_Basalt_Cobble"
    },
    {
      "x": 0,
      "y": 17,
      "z": 3,
      "name": "Soil_Gravel"
    },
    {
      "x": 0,
      "y": 18,
      "z": 3,
      "name": "Soil_Gravel"
    },
    {
      "x": 0,
      "y": 19,
      "z": 3,
      "name": "Soil_Gravel"
    },
    {
      "x": 0,
      "y": 20,
      "z": 3,
      "name": "Rock_Basalt_Cobble"
    },
    {
      "x": 0,
      "y": 31,
      "z": 3,
      "name": "Rock_Basalt"
    },
    {
      "x": 0,
      "y": 32,
      "z": 3,
      "name": "Rock_Basalt"
    },
    {
      "x": 0,
      "y": 33,
      "z": 3,
      "name": "Rock_Basalt_Cobble"
    },
    {
      "x": 0,
      "y": 34,
      "z": 3,
      "name": "Rock_Basalt"
    },
    {
      "x": 0,
      "y": 35,
      "z": 3,
      "name": "Rock_Basalt_Cobble"
    },
    {
      "x": 0,
      "y": 36,
      "z": 3,
      "name": "Rock_Basalt_Cobble"
    },
    {
      "x": 0,
      "y": 37,
      "z": 3,
      "name": "Rock_Basalt_Cobble"
    },
    {
      "x": 0,
      "y": 38,
      "z": 3,
      "name": "Rock_Basalt_Cobble"
    },
    {
      "x": 0,
      "y": 39,
      "z": 3,
      "name": "Rock_Basalt"
    },
    {
      "x": 0,
      "y": 40,
      "z": 3,
      "name": "Rock_Basalt"
    },
    {
      "x": 0,
      "y": 6,
      "z": 4,
      "name": "Rock_Basalt"
    },
    {
      "x": 0,
      "y": 7,
      "z": 4,
      "name": "Rock_Basalt"
    },
    {
      "x": 0,
      "y": 8,
      "z": 4,
      "name": "Rock_Basalt"
    },
    {
      "x": 0,
      "y": 9,
      "z": 4,
      "name": "Rock_Basalt"
    },
    {
      "x": 0,
      "y": 10,
      "z": 4,
      "name": "Rock_Basalt"
    },
    {
      "x": 0,
      "y": 13,
      "z": 4,
      "name": "Rock_Basalt"
    },
    {
      "x": 0,
      "y": 14,
      "z": 4,
      "name": "Rock_Basalt_Cobble"
    },
    {
      "x": 0,
      "y": 15,
      "z": 4,
      "name": "Rock_Basalt_Cobble"
    },
    {
      "x": 0,
      "y": 16,
      "z": 4,
      "name": "Soil_Gravel"
    },
    {
      "x": 0,
      "y": 17,
      "z": 4,
      "name": "Soil_Gravel"
    },
    {
      "x": 0,
      "y": 36,
      "z": 4,
      "name": "Rock_Basalt_Cobble"
    },
    {
      "x": 0,
      "y": 37,
      "z": 4,
      "name": "Rock_Basalt_Cobble"
    },
    {
      "x": 0,
      "y": 38,
      "z": 4,
      "name": "Rock_Basalt_Cobble"
    },
    {
      "x": 0,
      "y": 39,
      "z": 4,
      "name": "Rock_Basalt_Cobble"
    },
    {
      "x": 0,
      "y": 40,
      "z": 4,
      "name": "Rock_Basalt"
    },
    {
      "x": 0,
      "y": 41,
      "z": 4,
      "name": "Rock_Basalt"
    },
    {
      "x": 0,
      "y": 7,
      "z": 5,
      "name": "Rock_Basalt"
    },
    {
      "x": 0,
      "y": 8,
      "z": 5,
      "name": "Rock_Basalt"
    },
    {
      "x": 0,
      "y": 9,
      "z": 5,
      "name": "Rock_Basalt"
    },
    {
      "x": 0,
      "y": 37,
      "z": 5,
      "name": "Rock_Basalt_Cobble"
    },
    {
      "x": 0,
      "y": 38,
      "z": 5,
      "name": "Rock_Basalt_Cobble"
    },
    {
      "x": 0,
      "y": 39,
      "z": 5,
      "name": "Rock_Basalt_Cobble"
    },
    {
      "x": 0,
      "y": 40,
      "z": 5,
      "name": "Rock_Basalt_Cobble"
    },
    {
      "x": 0,
      "y": 41,
      "z": 5,
      "name": "Rock_Basalt"
    },
    {
      "x": 0,
      "y": 37,
      "z": 6,
      "name": "Rock_Basalt_Cobble"
    },
    {
      "x": 0,
      "y": 38,
      "z": 6,
      "name": "Rock_Basalt"
    },
    {
      "x": 0,
      "y": 39,
      "z": 6,
      "name": "Rock_Basalt_Cobble"
    },
    {
      "x": 0,
      "y": 40,
      "z": 6,
      "name": "Rock_Basalt"
    },
    {
      "x": 0,
      "y": 41,
      "z": 6,
      "name": "Rock_Basalt"
    },
    {
      "x": 0,
      "y": 37,
      "z": 7,
      "name": "Rock_Basalt"
    },
    {
      "x": 0,
      "y": 38,
      "z": 7,
      "name": "Rock_Basalt"
    },
    {
      "x": 0,
      "y": 39,
      "z": 7,
      "name": "Rock_Basalt"
    },
    {
      "x": 0,
      "y": 40,
      "z": 7,
      "name": "Rock_Basalt"
    },
    {
      "x": 0,
      "y": 41,
      "z": 7,
      "name": "Rock_Basalt"
    },
    {
      "x": 0,
      "y": 39,
      "z": 8,
      "name": "Rock_Basalt"
    },
    {
      "x": 0,
      "y": 40,
      "z": 8,
      "name": "Rock_Basalt"
    },
    {
      "x": 0,
      "y": 41,
      "z": 8,
      "name": "Rock_Basalt"
    },
    {
      "x": 1,
      "y": 7,
      "z": -5,
      "name": "Rock_Basalt"
    },
    {
      "x": 1,
      "y": 8,
      "z": -5,
      "name": "Rock_Basalt"
    },
    {
      "x": 1,
      "y": 9,
      "z": -5,
      "name": "Rock_Basalt"
    },
    {
      "x": 1,
      "y": 23,
      "z": -5,
      "name": "Plant_Crop_Mushroom_Block_Red"
    },
    {
      "x": 1,
      "y": 36,
      "z": -5,
      "name": "Rock_Basalt"
    },
    {
      "x": 1,
      "y": 37,
      "z": -5,
      "name": "Rock_Basalt"
    },
    {
      "x": 1,
      "y": 38,
      "z": -5,
      "name": "Rock_Basalt"
    },
    {
      "x": 1,
      "y": 39,
      "z": -5,
      "name": "Rock_Basalt"
    },
    {
      "x": 1,
      "y": 6,
      "z": -4,
      "name": "Rock_Basalt"
    },
    {
      "x": 1,
      "y": 7,
      "z": -4,
      "name": "Rock_Basalt"
    },
    {
      "x": 1,
      "y": 8,
      "z": -4,
      "name": "Rock_Basalt"
    },
    {
      "x": 1,
      "y": 9,
      "z": -4,
      "name": "Rock_Basalt"
    },
    {
      "x": 1,
      "y": 10,
      "z": -4,
      "name": "Rock_Basalt"
    },
    {
      "x": 1,
      "y": 22,
      "z": -4,
      "name": "Soil_Gravel"
    },
    {
      "x": 1,
      "y": 23,
      "z": -4,
      "name": "Rock_Basalt_Cobble"
    },
    {
      "x": 1,
      "y": 24,
      "z": -4,
      "name": "Rock_Basalt_Cobble"
    },
    {
      "x": 1,
      "y": 25,
      "z": -4,
      "name": "Rock_Basalt_Cobble"
    },
    {
      "x": 1,
      "y": 26,
      "z": -4,
      "name": "Rock_Basalt_Cobble"
    },
    {
      "x": 1,
      "y": 27,
      "z": -4,
      "name": "Rock_Basalt_Cobble"
    },
    {
      "x": 1,
      "y": 34,
      "z": -4,
      "name": "Rock_Basalt"
    },
    {
      "x": 1,
      "y": 35,
      "z": -4,
      "name": "Rock_Basalt"
    },
    {
      "x": 1,
      "y": 36,
      "z": -4,
      "name": "Rock_Basalt"
    },
    {
      "x": 1,
      "y": 37,
      "z": -4,
      "name": "Rock_Basalt"
    },
    {
      "x": 1,
      "y": 38,
      "z": -4,
      "name": "Rock_Basalt"
    },
    {
      "x": 1,
      "y": 39,
      "z": -4,
      "name": "Rock_Basalt"
    },
    {
      "x": 1,
      "y": 40,
      "z": -4,
      "name": "Rock_Basalt"
    },
    {
      "x": 1,
      "y": 6,
      "z": -3,
      "name": "Rock_Basalt"
    },
    {
      "x": 1,
      "y": 7,
      "z": -3,
      "name": "Rock_Basalt"
    },
    {
      "x": 1,
      "y": 8,
      "z": -3,
      "name": "Rock_Basalt"
    },
    {
      "x": 1,
      "y": 9,
      "z": -3,
      "name": "Rock_Basalt"
    },
    {
      "x": 1,
      "y": 10,
      "z": -3,
      "name": "Rock_Basalt_Cobble"
    },
    {
      "x": 1,
      "y": 11,
      "z": -3,
      "name": "Rock_Basalt_Cobble"
    },
    {
      "x": 1,
      "y": 12,
      "z": -3,
      "name": "Rock_Basalt_Cobble"
    },
    {
      "x": 1,
      "y": 13,
      "z": -3,
      "name": "Rock_Basalt_Cobble"
    },
    {
      "x": 1,
      "y": 14,
      "z": -3,
      "name": "Rock_Basalt_Cobble"
    },
    {
      "x": 1,
      "y": 15,
      "z": -3,
      "name": "Rock_Basalt_Cobble"
    },
    {
      "x": 1,
      "y": 20,
      "z": -3,
      "name": "Soil_Gravel"
    },
    {
      "x": 1,
      "y": 21,
      "z": -3,
      "name": "Soil_Gravel"
    },
    {
      "x": 1,
      "y": 22,
      "z": -3,
      "name": "Soil_Gravel"
    },
    {
      "x": 1,
      "y": 23,
      "z": -3,
      "name": "Rock_Basalt_Cobble"
    },
    {
      "x": 1,
      "y": 24,
      "z": -3,
      "name": "Rock_Basalt_Cobble"
    },
    {
      "x": 1,
      "y": 25,
      "z": -3,
      "name": "Rock_Basalt_Cobble"
    },
    {
      "x": 1,
      "y": 26,
      "z": -3,
      "name": "Rock_Basalt_Cobble"
    },
    {
      "x": 1,
      "y": 27,
      "z": -3,
      "name": "Rock_Basalt_Cobble"
    },
    {
      "x": 1,
      "y": 29,
      "z": -3,
      "name": "Rock_Basalt"
    },
    {
      "x": 1,
      "y": 30,
      "z": -3,
      "name": "Rock_Basalt"
    },
    {
      "x": 1,
      "y": 31,
      "z": -3,
      "name": "Rock_Basalt"
    },
    {
      "x": 1,
      "y": 32,
      "z": -3,
      "name": "Rock_Basalt"
    },
    {
      "x": 1,
      "y": 33,
      "z": -3,
      "name": "Rock_Basalt"
    },
    {
      "x": 1,
      "y": 34,
      "z": -3,
      "name": "Rock_Basalt"
    },
    {
      "x": 1,
      "y": 35,
      "z": -3,
      "name": "Rock_Basalt"
    },
    {
      "x": 1,
      "y": 36,
      "z": -3,
      "name": "Rock_Basalt"
    },
    {
      "x": 1,
      "y": 37,
      "z": -3,
      "name": "Rock_Basalt"
    },
    {
      "x": 1,
      "y": 38,
      "z": -3,
      "name": "Rock_Basalt"
    },
    {
      "x": 1,
      "y": 39,
      "z": -3,
      "name": "Rock_Basalt"
    },
    {
      "x": 1,
      "y": 40,
      "z": -3,
      "name": "Rock_Basalt"
    },
    {
      "x": 1,
      "y": 5,
      "z": -2,
      "name": "Rock_Basalt"
    },
    {
      "x": 1,
      "y": 6,
      "z": -2,
      "name": "Rock_Basalt"
    },
    {
      "x": 1,
      "y": 7,
      "z": -2,
      "name": "Rock_Basalt"
    },
    {
      "x": 1,
      "y": 8,
      "z": -2,
      "name": "Rock_Basalt"
    },
    {
      "x": 1,
      "y": 9,
      "z": -2,
      "name": "Rock_Basalt_Cobble"
    },
    {
      "x": 1,
      "y": 10,
      "z": -2,
      "name": "Rock_Basalt_Cobble"
    },
    {
      "x": 1,
      "y": 11,
      "z": -2,
      "name": "Soil_Gravel"
    },
    {
      "x": 1,
      "y": 12,
      "z": -2,
      "name": "Rock_Basalt_Cobble"
    },
    {
      "x": 1,
      "y": 13,
      "z": -2,
      "name": "Rock_Basalt_Cobble"
    },
    {
      "x": 1,
      "y": 14,
      "z": -2,
      "name": "Rock_Basalt_Cobble"
    },
    {
      "x": 1,
      "y": 15,
      "z": -2,
      "name": "Soil_Gravel"
    },
    {
      "x": 1,
      "y": 16,
      "z": -2,
      "name": "Soil_Gravel"
    },
    {
      "x": 1,
      "y": 17,
      "z": -2,
      "name": "Soil_Gravel"
    },
    {
      "x": 1,
      "y": 18,
      "z": -2,
      "name": "Soil_Gravel"
    },
    {
      "x": 1,
      "y": 19,
      "z": -2,
      "name": "Soil_Gravel"
    },
    {
      "x": 1,
      "y": 20,
      "z": -2,
      "name": "Soil_Gravel"
    },
    {
      "x": 1,
      "y": 21,
      "z": -2,
      "name": "Soil_Gravel"
    },
    {
      "x": 1,
      "y": 22,
      "z": -2,
      "name": "Rock_Basalt"
    },
    {
      "x": 1,
      "y": 23,
      "z": -2,
      "name": "Rock_Basalt"
    },
    {
      "x": 1,
      "y": 24,
      "z": -2,
      "name": "Rock_Basalt_Cobble"
    },
    {
      "x": 1,
      "y": 25,
      "z": -2,
      "name": "Soil_Gravel"
