{
  "version": 8,
  "blockIdVersion": 8,
  "anchorX": -3,
  "anchorY": 5,
  "anchorZ": 0,
  "blocks": [
    {
      "x": -9,
      "y": 15,
      "z": -1,
      "name": "Plant_Crop_Mushroom_Block_Red"
    },
    {
      "x": -9,
      "y": 15,
      "z": 0,
      "name": "Plant_Crop_Mushroom_Block_Red"
    },
    {
      "x": -9,
      "y": 16,
      "z": 0,
      "name": "Plant_Crop_Mushroom_Block_Red"
    },
    {
      "x": -9,
      "y": 17,
      "z": 0,
      "name": "Plant_Crop_Mushroom_Block_Red"
    },
    {
      "x": -9,
      "y": 15,
      "z": 1,
      "name": "Plant_Crop_Mushroom_Block_Red"
    },
    {
      "x": -9,
      "y": 16,
      "z": 1,
      "name": "Plant_Crop_Mushroom_Block_Red"
    },
    {
      "x": -9,
      "y": 17,
      "z": 1,
      "name": "Plant_Crop_Mushroom_Block_Red"
    },
    {
      "x": -9,
      "y": 18,
      "z": 1,
      "name": "Plant_Crop_Mushroom_Block_Red"
    },
    {
      "x": -9,
      "y": 19,
      "z": 1,
      "name": "Plant_Crop_Mushroom_Block_Red"
    },
    {
      "x": -9,
      "y": 16,
      "z": 2,
      "name": "Plant_Crop_Mushroom_Block_Red"
    },
    {
      "x": -9,
      "y": 17,
      "z": 2,
      "name": "Plant_Crop_Mushroom_Block_Red"
    },
    {
      "x": -9,
      "y": 18,
      "z": 2,
      "name": "Plant_Crop_Mushroom_Block_Red"
    },
    {
      "x": -9,
      "y": 19,
      "z": 2,
      "name": "Plant_Crop_Mushroom_Block_Red"
    },
    {
      "x": -9,
      "y": 16,
      "z": 3,
      "name": "Plant_Crop_Mushroom_Block_Red"
    },
    {
      "x": -9,
      "y": 17,
      "z": 3,
      "name": "Plant_Crop_Mushroom_Block_Red"
    },
    {
      "x": -9,
      "y": 18,
      "z": 3,
      "name": "Plant_Crop_Mushroom_Block_Red"
    },
    {
      "x": -9,
      "y": 19,
      "z": 3,
      "name": "Plant_Crop_Mushroom_Block_Red"
    },
    {
      "x": -9,
      "y": 16,
      "z": 4,
      "name": "Plant_Crop_Mushroom_Block_Red"
    },
    {
      "x": -9,
      "y": 17,
      "z": 4,
      "name": "Plant_Crop_Mushroom_Block_Red"
    },
    {
      "x": -9,
      "y": 18,
      "z": 4,
      "name": "Plant_Crop_Mushroom_Block_Red"
    },
    {
      "x": -9,
      "y": 19,
      "z": 4,
      "name": "Plant_Crop_Mushroom_Block_Red"
    },
    {
      "x": -9,
      "y": 16,
      "z": 5,
      "name": "Plant_Crop_Mushroom_Block_Red"
    },
    {
      "x": -9,
      "y": 17,
      "z": 5,
      "name": "Plant_Crop_Mushroom_Block_Red"
    },
    {
      "x": -9,
      "y": 18,
      "z": 5,
      "name": "Plant_Crop_Mushroom_Block_Red"
    },
    {
      "x": -8,
      "y": 15,
      "z": -2,
      "name": "Plant_Crop_Mushroom_Block_Red"
    },
    {
      "x": -8,
      "y": 16,
      "z": -2,
      "name": "Plant_Crop_Mushroom_Block_Red"
    },
    {
      "x": -8,
      "y": 17,
      "z": -2,
      "name": "Plant_Crop_Mushroom_Cap_Red",
      "components": {
        "Components": {
          "FarmingBlock": {}
        }
      }
    },
    {
      "x": -8,
      "y": 15,
      "z": -1,
      "name": "Plant_Crop_Mushroom_Block_Red"
    },
    {
      "x": -8,
      "y": 16,
      "z": -1,
      "name": "Plant_Crop_Mushroom_Block_Red"
    },
    {
      "x": -8,
      "y": 17,
      "z": -1,
      "name": "Plant_Crop_Mushroom_Block_Red"
    },
    {
      "x": -8,
      "y": 18,
      "z": -1,
      "name": "Plant_Crop_Mushroom_Block_Red"
    },
    {
      "x": -8,
      "y": 19,
      "z": -1,
      "name": "Plant_Crop_Mushroom_Block_Red"
    },
    {
      "x": -8,
      "y": 18,
      "z": 0,
      "name": "Plant_Crop_Mushroom_Block_Red"
    },
    {
      "x": -8,
      "y": 19,
      "z": 0,
      "name": "Plant_Crop_Mushroom_Block_Red"
    },
    {
      "x": -8,
      "y": 20,
      "z": 0,
      "name": "Plant_Crop_Mushroom_Block_Red"
    },
    {
      "x": -8,
      "y": 19,
      "z": 1,
      "name": "Rock_Crystal_Red_Small",
      "components": {
        "Components": {
          "FarmingBlock": {}
        }
      },
      "rotation": 5
    },
    {
      "x": -8,
      "y": 20,
      "z": 1,
      "name": "Plant_Crop_Mushroom_Block_Red"
    },
    {
      "x": -8,
      "y": 19,
      "z": 2,
      "name": "Rock_Crystal_Red_Small",
      "components": {
        "Components": {
          "FarmingBlock": {}
        }
      },
      "rotation": 5
    },
    {
      "x": -8,
      "y": 20,
      "z": 2,
      "name": "Plant_Crop_Mushroom_Block_Red"
    },
    {
      "x": -8,
      "y": 21,
      "z": 2,
      "name": "Plant_Crop_Mushroom_Block_Red"
    },
    {
      "x": -8,
      "y": 20,
      "z": 3,
      "name": "Plant_Crop_Mushroom_Block_Red"
    },
    {
      "x": -8,
      "y": 21,
      "z": 3,
      "name": "Plant_Crop_Mushroom_Block_Red"
    },
    {
      "x": -8,
      "y": 20,
      "z": 4,
      "name": "Plant_Crop_Mushroom_Block_Red"
    },
    {
      "x": -8,
      "y": 21,
      "z": 4,
      "name": "Plant_Crop_Mushroom_Block_Red"
    },
    {
      "x": -8,
      "y": 16,
      "z": 5,
      "name": "Plant_Crop_Mushroom_Block_Red"
    },
    {
      "x": -8,
      "y": 17,
      "z": 5,
      "name": "Plant_Crop_Mushroom_Block_Red"
    },
    {
      "x": -8,
      "y": 18,
      "z": 5,
      "name": "Plant_Crop_Mushroom_Block_Red"
    },
    {
      "x": -8,
      "y": 19,
      "z": 5,
      "name": "Plant_Crop_Mushroom_Block_Red"
    },
    {
      "x": -8,
      "y": 20,
      "z": 5,
      "name": "Plant_Crop_Mushroom_Block_Red"
    },
    {
      "x": -8,
      "y": 16,
      "z": 6,
      "name": "Plant_Crop_Mushroom_Block_Red"
    },
    {
      "x": -8,
      "y": 17,
      "z": 6,
      "name": "Plant_Crop_Mushroom_Block_Red"
    },
    {
      "x": -8,
      "y": 18,
      "z": 6,
      "name": "Plant_Crop_Mushroom_Block_Red"
    },
    {
      "x": -7,
      "y": 14,
      "z": -5,
      "name": "Plant_Crop_Mushroom_Block_Red"
    },
    {
      "x": -7,
      "y": 15,
      "z": -5,
      "name": "Plant_Crop_Mushroom_Block_Red"
    },
    {
      "x": -7,
      "y": 15,
      "z": -4,
      "name": "Plant_Crop_Mushroom_Block_Red"
    },
    {
      "x": -7,
      "y": 16,
      "z": -4,
      "name": "Plant_Crop_Mushroom_Block_Red"
    },
    {
      "x": -7,
      "y": 17,
      "z": -4,
      "name": "Plant_Crop_Mushroom_Block_Red"
    },
    {
      "x": -7,
      "y": 15,
      "z": -3,
      "name": "Plant_Crop_Mushroom_Block_Red"
    },
    {
      "x": -7,
      "y": 16,
      "z": -3,
      "name": "Plant_Crop_Mushroom_Block_Red"
    },
    {
      "x": -7,
      "y": 17,
      "z": -3,
      "name": "Plant_Crop_Mushroom_Block_Red"
    },
    {
      "x": -7,
      "y": 18,
      "z": -3,
      "name": "Plant_Crop_Mushroom_Cap_Red",
      "components": {
        "Components": {
          "FarmingBlock": {}
        }
      }
    },
    {
      "x": -7,
      "y": 15,
      "z": -2,
      "name": "Plant_Crop_Mushroom_Block_Red"
    },
    {
      "x": -7,
      "y": 16,
      "z": -2,
      "name": "Plant_Crop_Mushroom_Block_Red"
    },
    {
      "x": -7,
      "y": 17,
      "z": -2,
      "name": "Plant_Crop_Mushroom_Block_Red"
    },
    {
      "x": -7,
      "y": 18,
      "z": -2,
      "name": "Plant_Crop_Mushroom_Block_Red"
    },
    {
      "x": -7,
      "y": 19,
      "z": -2,
      "name": "Plant_Crop_Mushroom_Block_Red"
    },
    {
      "x": -7,
      "y": 20,
      "z": -2,
      "name": "Plant_Crop_Mushroom_Block_Red"
    },
    {
      "x": -7,
      "y": 19,
      "z": -1,
      "name": "Plant_Crop_Mushroom_Block_Red"
    },
    {
      "x": -7,
      "y": 20,
      "z": -1,
      "name": "Plant_Crop_Mushroom_Block_Red"
    },
    {
      "x": -7,
      "y": 21,
      "z": -1,
      "name": "Plant_Crop_Mushroom_Block_Red"
    },
    {
      "x": -7,
      "y": 22,
      "z": -1,
      "name": "Plant_Crop_Mushroom_Block_Red"
    },
    {
      "x": -7,
      "y": 21,
      "z": 0,
      "name": "Plant_Crop_Mushroom_Block_Red"
    },
    {
      "x": -7,
      "y": 22,
      "z": 0,
      "name": "Plant_Crop_Mushroom_Block_Red"
    },
    {
      "x": -7,
      "y": 21,
      "z": 1,
      "name": "Plant_Crop_Mushroom_Block_Red"
    },
    {
      "x": -7,
      "y": 22,
      "z": 1,
      "name": "Plant_Crop_Mushroom_Block_Red"
    },
    {
      "x": -7,
      "y": 23,
      "z": 1,
      "name": "Plant_Crop_Mushroom_Block_Red"
    },
    {
      "x": -7,
      "y": 21,
      "z": 2,
      "name": "Plant_Crop_Mushroom_Block_Red"
    },
    {
      "x": -7,
      "y": 22,
      "z": 2,
      "name": "Plant_Crop_Mushroom_Block_Red"
    },
    {
      "x": -7,
      "y": 23,
      "z": 2,
      "name": "Plant_Crop_Mushroom_Block_Red"
    },
    {
      "x": -7,
      "y": 21,
      "z": 3,
      "name": "Plant_Crop_Mushroom_Block_Red"
    },
    {
      "x": -7,
      "y": 22,
      "z": 3,
      "name": "Plant_Crop_Mushroom_Block_Red"
    },
    {
      "x": -7,
      "y": 23,
      "z": 3,
      "name": "Plant_Crop_Mushroom_Block_Red"
    },
    {
      "x": -7,
      "y": 20,
      "z": 4,
      "name": "Plant_Crop_Mushroom_Block_Red"
    },
    {
      "x": -7,
      "y": 21,
      "z": 4,
      "name": "Plant_Crop_Mushroom_Block_Red"
    },
    {
      "x": -7,
      "y": 22,
      "z": 4,
      "name": "Plant_Crop_Mushroom_Cap_Red",
      "components": {
        "Components": {
          "FarmingBlock": {}
        }
      }
    },
    {
      "x": -7,
      "y": 20,
      "z": 5,
      "name": "Plant_Crop_Mushroom_Block_Red"
    },
    {
      "x": -7,
      "y": 21,
      "z": 5,
      "name": "Plant_Crop_Mushroom_Block_Red"
    },
    {
      "x": -7,
      "y": 16,
      "z": 6,
      "name": "Plant_Crop_Mushroom_Block_Red"
    },
    {
      "x": -7,
      "y": 17,
      "z": 6,
      "name": "Plant_Crop_Mushroom_Block_Red"
    },
    {
      "x": -7,
      "y": 18,
      "z": 6,
      "name": "Plant_Crop_Mushroom_Block_Red"
    },
    {
      "x": -7,
      "y": 19,
      "z": 6,
      "name": "Plant_Crop_Mushroom_Block_Red"
    },
    {
      "x": -7,
      "y": 16,
      "z": 7,
      "name": "Plant_Crop_Mushroom_Block_Red"
    },
    {
      "x": -7,
      "y": 17,
      "z": 7,
      "name": "Plant_Crop_Mushroom_Block_Red"
    },
    {
      "x": -6,
      "y": 14,
      "z": -6,
      "name": "Plant_Crop_Mushroom_Block_Red"
    },
    {
      "x": -6,
      "y": 14,
      "z": -5,
      "name": "Plant_Crop_Mushroom_Block_Red"
    },
    {
      "x": -6,
      "y": 15,
      "z": -5,
      "name": "Plant_Crop_Mushroom_Block_Red"
    },
    {
      "x": -6,
      "y": 16,
      "z": -5,
      "name": "Plant_Crop_Mushroom_Block_Red"
    },
    {
      "x": -6,
      "y": 15,
      "z": -4,
      "name": "Plant_Crop_Mushroom_Block_Red_Mycelium"
    },
    {
      "x": -6,
      "y": 16,
      "z": -4,
      "name": "Plant_Crop_Mushroom_Block_Red_Mycelium"
    },
    {
      "x": -6,
      "y": 17,
      "z": -4,
      "name": "Plant_Crop_Mushroom_Block_Red"
    },
    {
      "x": -6,
      "y": 18,
      "z": -4,
      "name": "Plant_Crop_Mushroom_Block_Red"
    },
    {
      "x": -6,
      "y": 19,
      "z": -4,
      "name": "Plant_Crop_Mushroom_Block_Red"
    },
    {
      "x": -6,
      "y": 17,
      "z": -3,
      "name": "Plant_Crop_Mushroom_Block_Red_Mycelium"
    },
    {
      "x": -6,
      "y": 18,
      "z": -3,
      "name": "Plant_Crop_Mushroom_Block_Red"
    },
    {
      "x": -6,
      "y": 19,
      "z": -3,
      "name": "Plant_Crop_Mushroom_Block_Red"
    },
    {
      "x": -6,
      "y": 20,
      "z": -3,
      "name": "Plant_Crop_Mushroom_Block_Red"
    },
    {
      "x": -6,
      "y": 21,
      "z": -3,
      "name": "Plant_Crop_Mushroom_Block_Red"
    },
    {
      "x": -6,
      "y": 22,
      "z": -3,
      "name": "Plant_Crop_Mushroom_Block_Red"
    },
    {
      "x": -6,
      "y": 4,
      "z": -2,
      "name": "Plant_Crop_Mushroom_Block_Red_Trunk"
    },
    {
      "x": -6,
      "y": 5,
      "z": -2,
      "name": "Plant_Crop_Mushroom_Block_Red_Trunk"
    },
    {
      "x": -6,
      "y": 18,
      "z": -2,
      "name": "Plant_Crop_Mushroom_Block_Red"
    },
    {
      "x": -6,
      "y": 19,
      "z": -2,
      "name": "Plant_Crop_Mushroom_Block_Red"
    },
    {
      "x": -6,
      "y": 20,
      "z": -2,
      "name": "Plant_Crop_Mushroom_Block_Red"
    },
    {
      "x": -6,
      "y": 21,
      "z": -2,
      "name": "Plant_Crop_Mushroom_Block_Red"
    },
    {
      "x": -6,
      "y": 22,
      "z": -2,
      "name": "Plant_Crop_Mushroom_Block_Red"
    },
    {
      "x": -6,
      "y": 3,
      "z": -1,
      "name": "Plant_Crop_Mushroom_Block_Red_Trunk"
    },
    {
      "x": -6,
      "y": 4,
      "z": -1,
      "name": "Plant_Crop_Mushroom_Block_Red_Trunk"
    },
    {
      "x": -6,
      "y": 5,
      "z": -1,
      "name": "Plant_Crop_Mushroom_Block_Red_Trunk"
    },
    {
      "x": -6,
      "y": 22,
      "z": -1,
      "name": "Plant_Crop_Mushroom_Block_Red"
    },
    {
      "x": -6,
      "y": 23,
      "z": -1,
      "name": "Plant_Crop_Mushroom_Block_Red"
    },
    {
      "x": -6,
      "y": 3,
      "z": 0,
      "name": "Plant_Crop_Mushroom_Block_Red_Trunk"
    },
    {
      "x": -6,
      "y": 4,
      "z": 0,
      "name": "Plant_Crop_Mushroom_Block_Red_Trunk"
    },
    {
      "x": -6,
      "y": 5,
      "z": 0,
      "name": "Plant_Crop_Mushroom_Block_Red_Trunk"
    },
    {
      "x": -6,
      "y": 6,
      "z": 0,
      "name": "Plant_Crop_Mushroom_Block_Red_Trunk"
    },
    {
      "x": -6,
      "y": 23,
      "z": 0,
      "name": "Plant_Crop_Mushroom_Block_Red"
    },
    {
      "x": -6,
      "y": 24,
      "z": 0,
      "name": "Plant_Crop_Mushroom_Block_Red"
    },
    {
      "x": -6,
      "y": 25,
      "z": 0,
      "name": "Plant_Crop_Mushroom_Cap_Red",
      "components": {
        "Components": {
          "FarmingBlock": {}
        }
      }
    },
    {
      "x": -6,
      "y": 4,
      "z": 1,
      "name": "Plant_Crop_Mushroom_Block_Red_Trunk"
    },
    {
      "x": -6,
      "y": 5,
      "z": 1,
      "name": "Plant_Crop_Mushroom_Block_Red_Trunk"
    },
    {
      "x": -6,
      "y": 6,
      "z": 1,
      "name": "Plant_Crop_Mushroom_Block_Red_Trunk"
    },
    {
      "x": -6,
      "y": 23,
      "z": 1,
      "name": "Plant_Crop_Mushroom_Block_Red_Mycelium"
    },
    {
      "x": -6,
      "y": 24,
      "z": 1,
      "name": "Plant_Crop_Mushroom_Block_Red"
    },
    {
      "x": -6,
      "y": 25,
      "z": 1,
      "name": "Plant_Crop_Mushroom_Cap_Red",
      "components": {
        "Components": {
          "FarmingBlock": {}
        }
      }
    },
    {
      "x": -6,
      "y": 23,
      "z": 2,
      "name": "Plant_Crop_Mushroom_Block_Red_Mycelium"
    },
    {
      "x": -6,
      "y": 24,
      "z": 2,
      "name": "Plant_Crop_Mushroom_Block_Red"
    },
    {
      "x": -6,
      "y": 25,
      "z": 2,
      "name": "Plant_Crop_Mushroom_Block_Red"
    },
    {
      "x": -6,
      "y": 24,
      "z": 3,
      "name": "Plant_Crop_Mushroom_Block_Red"
    },
    {
      "x": -6,
      "y": 25,
      "z": 3,
      "name": "Plant_Crop_Mushroom_Block_Red"
    },
    {
      "x": -6,
      "y": 22,
      "z": 4,
      "name": "Plant_Crop_Mushroom_Block_Red"
    },
    {
      "x": -6,
      "y": 23,
      "z": 4,
      "name": "Plant_Crop_Mushroom_Block_Red"
    },
    {
      "x": -6,
      "y": 24,
      "z": 4,
      "name": "Plant_Crop_Mushroom_Block_Red"
    },
    {
      "x": -6,
      "y": 20,
      "z": 5,
      "name": "Rock_Crystal_Red_Small",
      "components": {
        "Components": {
          "FarmingBlock": {}
        }
      },
      "rotation": 6
    },
    {
      "x": -6,
      "y": 22,
      "z": 5,
      "name": "Plant_Crop_Mushroom_Block_Red"
    },
    {
      "x": -6,
      "y": 23,
      "z": 5,
      "name": "Plant_Crop_Mushroom_Block_Red"
    },
    {
      "x": -6,
      "y": 18,
      "z": 6,
      "name": "Rock_Crystal_Red_Small",
      "components": {
        "Components": {
          "FarmingBlock": {}
        }
      },
      "rotation": 6
    },
    {
      "x": -6,
      "y": 20,
      "z": 6,
      "name": "Plant_Crop_Mushroom_Block_Red"
    },
    {
      "x": -6,
      "y": 21,
      "z": 6,
      "name": "Plant_Crop_Mushroom_Block_Red"
    },
    {
      "x": -6,
      "y": 22,
      "z": 6,
      "name": "Plant_Crop_Mushroom_Block_Red"
    },
    {
      "x": -6,
      "y": 15,
      "z": 7,
      "name": "Plant_Crop_Mushroom_Block_Red"
    },
    {
      "x": -6,
      "y": 16,
      "z": 7,
      "name": "Plant_Crop_Mushroom_Block_Red"
    },
    {
      "x": -6,
      "y": 17,
      "z": 7,
      "name": "Plant_Crop_Mushroom_Block_Red"
    },
    {
      "x": -6,
      "y": 18,
      "z": 7,
      "name": "Plant_Crop_Mushroom_Block_Red"
    },
    {
      "x": -6,
      "y": 19,
      "z": 7,
      "name": "Plant_Crop_Mushroom_Block_Red"
    },
    {
      "x": -6,
      "y": 20,
      "z": 7,
      "name": "Plant_Crop_Mushroom_Block_Red"
    },
    {
      "x": -6,
      "y": 15,
      "z": 8,
      "name": "Plant_Crop_Mushroom_Block_Red"
    },
    {
      "x": -5,
      "y": 13,
      "z": -7,
      "name": "Plant_Crop_Mushroom_Block_Red"
    },
    {
      "x": -5,
      "y": 14,
      "z": -7,
      "name": "Plant_Crop_Mushroom_Block_Red"
    },
    {
      "x": -5,
      "y": 14,
      "z": -6,
      "name": "Plant_Crop_Mushroom_Block_Red"
    },
    {
      "x": -5,
      "y": 15,
      "z": -6,
      "name": "Plant_Crop_Mushroom_Block_Red"
    },
    {
      "x": -5,
      "y": 16,
      "z": -6,
      "name": "Plant_Crop_Mushroom_Block_Red"
    },
    {
      "x": -5,
      "y": 17,
      "z": -6,
      "name": "Plant_Crop_Mushroom_Block_Red"
    },
    {
      "x": -5,
      "y": 16,
      "z": -5,
      "name": "Plant_Crop_Mushroom_Block_Red_Mycelium"
    },
    {
      "x": -5,
      "y": 17,
      "z": -5,
      "name": "Plant_Crop_Mushroom_Block_Red"
    },
    {
      "x": -5,
      "y": 18,
      "z": -5,
      "name": "Plant_Crop_Mushroom_Block_Red"
    },
    {
      "x": -5,
      "y": 19,
      "z": -5,
      "name": "Plant_Crop_Mushroom_Block_Red"
    },
    {
      "x": -5,
      "y": 20,
      "z": -5,
      "name": "Plant_Crop_Mushroom_Cap_Red",
      "components": {
        "Components": {
          "FarmingBlock": {}
        }
      }
    },
    {
      "x": -5,
      "y": 17,
      "z": -4,
      "name": "Plant_Crop_Mushroom_Block_Red_Mycelium"
    },
    {
      "x": -5,
      "y": 19,
      "z": -4,
      "name": "Plant_Crop_Mushroom_Block_Red"
    },
    {
      "x": -5,
      "y": 20,
      "z": -4,
      "name": "Plant_Crop_Mushroom_Block_Red"
    },
    {
      "x": -5,
      "y": 21,
      "z": -4,
      "name": "Plant_Crop_Mushroom_Cap_Red",
      "components": {
        "Components": {
          "FarmingBlock": {}
        }
      }
    },
    {
      "x": -5,
      "y": 5,
      "z": -3,
      "name": "Plant_Crop_Mushroom_Block_Red_Trunk"
    },
    {
      "x": -5,
      "y": 6,
      "z": -3,
      "name": "Plant_Crop_Mushroom_Block_Red_Trunk"
    },
    {
      "x": -5,
      "y": 19,
      "z": -3,
      "name": "Plant_Crop_Mushroom_Block_Red_Mycelium"
    },
    {
      "x": -5,
      "y": 20,
      "z": -3,
      "name": "Plant_Crop_Mushroom_Block_Red"
    },
    {
      "x": -5,
      "y": 21,
      "z": -3,
      "name": "Plant_Crop_Mushroom_Block_Red"
    },
    {
      "x": -5,
      "y": 22,
      "z": -3,
      "name": "Plant_Crop_Mushroom_Block_Red"
    },
    {
      "x": -5,
      "y": 23,
      "z": -3,
      "name": "Plant_Crop_Mushroom_Block_Red"
    },
    {
      "x": -5,
      "y": 4,
      "z": -2,
      "name": "Plant_Crop_Mushroom_Block_Red_Trunk"
    },
    {
      "x": -5,
      "y": 5,
      "z": -2,
      "name": "Plant_Crop_Mushroom_Block_Red_Trunk"
    },
    {
      "x": -5,
      "y": 6,
      "z": -2,
      "name": "Plant_Crop_Mushroom_Block_Red_Trunk"
    },
    {
      "x": -5,
      "y": 7,
      "z": -2,
      "name": "Plant_Crop_Mushroom_Block_Red_Trunk"
    },
    {
      "x": -5,
      "y": 23,
      "z": -2,
      "name": "Plant_Crop_Mushroom_Block_Red"
    },
    {
      "x": -5,
      "y": 2,
      "z": -1,
      "name": "Plant_Crop_Mushroom_Block_Red_Trunk"
    },
    {
      "x": -5,
      "y": 3,
      "z": -1,
      "name": "Plant_Crop_Mushroom_Block_Red_Trunk"
    },
    {
      "x": -5,
      "y": 4,
      "z": -1,
      "name": "Plant_Crop_Mushroom_Block_Red_Trunk"
    },
    {
      "x": -5,
      "y": 5,
      "z": -1,
      "name": "Plant_Crop_Mushroom_Block_Red_Trunk"
    },
    {
      "x": -5,
      "y": 6,
      "z": -1,
      "name": "Plant_Crop_Mushroom_Block_Red_Trunk"
    },
    {
      "x": -5,
      "y": 7,
      "z": -1,
      "name": "Plant_Crop_Mushroom_Block_Red_Trunk"
    },
    {
      "x": -5,
      "y": 23,
      "z": -1,
      "name": "Plant_Crop_Mushroom_Block_Red"
    },
    {
      "x": -5,
      "y": 24,
      "z": -1,
      "name": "Plant_Crop_Mushroom_Block_Red"
    },
    {
      "x": -5,
      "y": 25,
      "z": -1,
      "name": "Plant_Crop_Mushroom_Block_Red"
    },
    {
      "x": -5,
      "y": 3,
      "z": 0,
      "name": "Plant_Crop_Mushroom_Block_Red_Trunk"
    },
    {
      "x": -5,
      "y": 4,
      "z": 0,
      "name": "Plant_Crop_Mushroom_Block_Red_Trunk"
    },
    {
      "x": -5,
      "y": 5,
      "z": 0,
      "name": "Plant_Crop_Mushroom_Block_Red_Trunk"
    },
    {
      "x": -5,
      "y": 6,
      "z": 0,
      "name": "Plant_Crop_Mushroom_Block_Red_Trunk"
    },
    {
      "x": -5,
      "y": 7,
      "z": 0,
      "name": "Plant_Crop_Mushroom_Block_Red_Trunk"
    },
    {
      "x": -5,
      "y": 8,
      "z": 0,
      "name": "Plant_Crop_Mushroom_Block_Red_Trunk"
    },
    {
      "x": -5,
      "y": 24,
      "z": 0,
      "name": "Plant_Crop_Mushroom_Block_Red_Mycelium"
    },
    {
      "x": -5,
      "y": 25,
      "z": 0,
      "name": "Plant_Crop_Mushroom_Block_Red"
    },
    {
      "x": -5,
      "y": 26,
      "z": 0,
      "name": "Plant_Crop_Mushroom_Cap_Red",
      "components": {
        "Components": {
          "FarmingBlock": {}
        }
      }
    },
    {
      "x": -5,
      "y": 3,
      "z": 1,
      "name": "Plant_Crop_Mushroom_Block_Red_Trunk"
    },
    {
      "x": -5,
      "y": 4,
      "z": 1,
      "name": "Plant_Crop_Mushroom_Block_Red_Trunk"
    },
    {
      "x": -5,
      "y": 5,
      "z": 1,
      "name": "Plant_Crop_Mushroom_Block_Red_Trunk"
    },
    {
      "x": -5,
      "y": 6,
      "z": 1,
      "name": "Plant_Crop_Mushroom_Block_Red_Trunk"
    },
    {
      "x": -5,
      "y": 24,
      "z": 1,
      "name": "Plant_Crop_Mushroom_Block_Red_Mycelium"
    },
    {
      "x": -5,
      "y": 25,
      "z": 1,
      "name": "Plant_Crop_Mushroom_Block_Red"
    },
    {
      "x": -5,
      "y": 26,
      "z": 1,
      "name": "Plant_Crop_Mushroom_Block_Red"
    },
    {
      "x": -5,
      "y": 26,
      "z": 2,
      "name": "Plant_Crop_Mushroom_Block_Red"
    },
    {
      "x": -5,
      "y": 25,
      "z": 3,
      "name": "Plant_Crop_Mushroom_Block_Red"
    },
    {
      "x": -5,
      "y": 26,
      "z": 3,
      "name": "Plant_Crop_Mushroom_Cap_Red",
      "components": {
        "Components": {
          "FarmingBlock": {}
        }
      }
    },
    {
      "x": -5,
      "y": 24,
      "z": 4,
      "name": "Plant_Crop_Mushroom_Block_Red"
    },
    {
      "x": -5,
      "y": 25,
      "z": 4,
      "name": "Plant_Crop_Mushroom_Block_Red"
    },
    {
      "x": -5,
      "y": 24,
      "z": 5,
      "name": "Plant_Crop_Mushroom_Block_Red"
    },
    {
      "x": -5,
      "y": 23,
      "z": 6,
      "name": "Plant_Crop_Mushroom_Block_Red"
    },
    {
      "x": -5,
      "y": 24,
      "z": 6,
      "name": "Plant_Crop_Mushroom_Block_Red"
    },
    {
      "x": -5,
      "y": 17,
      "z": 7,
      "name": "Rock_Crystal_Red_Small",
      "components": {
        "Components": {
          "FarmingBlock": {}
        }
      },
      "rotation": 6
    },
    {
      "x": -5,
      "y": 18,
      "z": 7,
      "name": "Rock_Crystal_Red_Small",
      "components": {
        "Components": {
          "FarmingBlock": {}
        }
      },
      "rotation": 6
    },
    {
      "x": -5,
      "y": 19,
      "z": 7,
      "name": "Plant_Crop_Mushroom_Block_Red"
    },
    {
      "x": -5,
      "y": 20,
      "z": 7,
      "name": "Plant_Crop_Mushroom_Block_Red"
    },
    {
      "x": -5,
      "y": 21,
      "z": 7,
      "name": "Plant_Crop_Mushroom_Block_Red"
    },
    {
      "x": -5,
      "y": 22,
      "z": 7,
      "name": "Plant_Crop_Mushroom_Block_Red"
    },
    {
      "x": -5,
      "y": 15,
      "z": 8,
      "name": "Plant_Crop_Mushroom_Block_Red"
    },
    {
      "x": -5,
      "y": 16,
      "z": 8,
      "name": "Plant_Crop_Mushroom_Block_Red"
    },
    {
      "x": -5,
      "y": 17,
      "z": 8,
      "name": "Plant_Crop_Mushroom_Block_Red"
    },
    {
      "x": -5,
      "y": 18,
      "z": 8,
      "name": "Plant_Crop_Mushroom_Block_Red"
    },
    {
      "x": -5,
      "y": 19,
      "z": 8,
      "name": "Plant_Crop_Mushroom_Block_Red"
    },
    {
      "x": -5,
      "y": 15,
      "z": 9,
      "name": "Plant_Crop_Mushroom_Block_Red"
    },
    {
      "x": -5,
      "y": 16,
      "z": 9,
      "name": "Plant_Crop_Mushroom_Block_Red"
    },
    {
      "x": -5,
      "y": 17,
      "z": 9,
      "name": "Plant_Crop_Mushroom_Block_Red"
    },
    {
      "x": -4,
      "y": 13,
      "z": -7,
      "name": "Plant_Crop_Mushroom_Block_Red"
    },
    {
      "x": -4,
      "y": 14,
      "z": -7,
      "name": "Plant_Crop_Mushroom_Block_Red"
    },
    {
      "x": -4,
      "y": 15,
      "z": -7,
      "name": "Plant_Crop_Mushroom_Block_Red"
    },
    {
      "x": -4,
      "y": 16,
      "z": -7,
      "name": "Plant_Crop_Mushroom_Block_Red"
    },
    {
      "x": -4,
      "y": 17,
      "z": -7,
      "name": "Plant_Crop_Mushroom_Cap_Red",
      "components": {
        "Components": {
          "FarmingBlock": {}
        }
      }
    },
    {
      "x": -4,
      "y": 17,
      "z": -6,
      "name": "Plant_Crop_Mushroom_Block_Red"
    },
    {
      "x": -4,
      "y": 18,
      "z": -6,
      "name": "Plant_Crop_Mushroom_Block_Red"
    },
    {
      "x": -4,
      "y": 17,
      "z": -5,
      "name": "Rock_Crystal_Red_Small",
      "components": {
        "Components": {
          "FarmingBlock": {}
        }
      },
      "rotation": 4
    },
    {
      "x": -4,
      "y": 18,
      "z": -5,
      "name": "Rock_Crystal_Red_Small",
      "components": {
        "Components": {
          "FarmingBlock": {}
        }
      },
      "rotation": 4
    },
    {
      "x": -4,
      "y": 19,
      "z": -5,
      "name": "Plant_Crop_Mushroom_Block_Red"
    },
    {
      "x": -4,
      "y": 20,
      "z": -5,
      "name": "Plant_Crop_Mushroom_Cap_Red",
      "components": {
        "Components": {
          "FarmingBlock": {}
        }
      }
    },
    {
      "x": -4,
      "y": 19,
      "z": -4,
      "name": "Plant_Crop_Mushroom_Block_Red_Mycelium"
    },
    {
      "x": -4,
      "y": 20,
      "z": -4,
      "name": "Plant_Crop_Mushroom_Block_Red"
    },
    {
      "x": -4,
      "y": 21,
      "z": -4,
      "name": "Plant_Crop_Mushroom_Block_Red"
    },
    {
      "x": -4,
      "y": 4,
      "z": -3,
      "name": "Plant_Crop_Mushroom_Block_Red_Trunk"
    },
    {
      "x": -4,
      "y": 5,
      "z": -3,
      "name": "Plant_Crop_Mushroom_Block_Red_Trunk"
    },
    {
      "x": -4,
      "y": 6,
      "z": -3,
      "name": "Plant_Crop_Mushroom_Block_Red_Trunk"
    },
    {
      "x": -4,
      "y": 22,
      "z": -3,
      "name": "Plant_Crop_Mushroom_Block_Red"
    },
    {
      "x": -4,
      "y": 23,
      "z": -3,
      "name": "Plant_Crop_Mushroom_Block_Red"
    },
    {
      "x": -4,
      "y": 4,
      "z": -2,
      "name": "Plant_Crop_Mushroom_Block_Red_Trunk"
    },
    {
      "x": -4,
      "y": 5,
      "z": -2,
      "name": "Plant_Crop_Mushroom_Block_Red_Trunk"
    },
    {
      "x": -4,
      "y": 6,
      "z": -2,
      "name": "Plant_Crop_Mushroom_Block_Red_Trunk"
    },
    {
      "x": -4,
      "y": 7,
      "z": -2,
      "name": "Plant_Crop_Mushroom_Block_Red_Trunk"
    },
    {
      "x": -4,
      "y": 8,
      "z": -2,
      "name": "Plant_Crop_Mushroom_Block_Red_Trunk"
    },
    {
      "x": -4,
      "y": 9,
      "z": -2,
      "name": "Plant_Crop_Mushroom_Block_Red_Trunk"
    },
    {
      "x": -4,
      "y": 23,
      "z": -2,
      "name": "Plant_Crop_Mushroom_Block_Red"
    },
    {
      "x": -4,
      "y": 24,
      "z": -2,
      "name": "Plant_Crop_Mushroom_Block_Red"
    },
    {
      "x": -4,
      "y": 25,
      "z": -2,
      "name": "Plant_Crop_Mushroom_Block_Red"
    },
    {
      "x": -4,
      "y": 2,
      "z": -1,
      "name": "Plant_Crop_Mushroom_Block_Red_Trunk"
    },
    {
      "x": -4,
      "y": 3,
      "z": -1,
      "name": "Plant_Crop_Mushroom_Block_Red_Trunk"
    },
    {
      "x": -4,
      "y": 4,
      "z": -1,
      "name": "Plant_Crop_Mushroom_Block_Red_Trunk"
    },
    {
      "x": -4,
      "y": 5,
      "z": -1,
      "name": "Plant_Crop_Mushroom_Block_Red_Trunk"
    },
    {
      "x": -4,
      "y": 6,
      "z": -1,
      "name": "Plant_Crop_Mushroom_Block_Red_Trunk"
    },
    {
      "x": -4,
      "y": 7,
      "z": -1,
      "name": "Plant_Crop_Mushroom_Block_Red_Trunk"
    },
    {
      "x": -4,
      "y": 8,
      "z": -1,
      "name": "Plant_Crop_Mushroom_Block_Red_Trunk"
    },
    {
      "x": -4,
      "y": 9,
      "z": -1,
      "name": "Plant_Crop_Mushroom_Block_Red_Trunk"
    },
    {
      "x": -4,
      "y": 10,
      "z": -1,
      "name": "Plant_Crop_Mushroom_Block_Red_Trunk"
    },
    {
      "x": -4,
      "y": 11,
      "z": -1,
      "name": "Plant_Crop_Mushroom_Block_Red_Trunk"
    },
    {
      "x": -4,
      "y": 25,
      "z": -1,
      "name": "Plant_Crop_Mushroom_Block_Red"
    },
    {
      "x": -4,
      "y": 26,
      "z": -1,
      "name": "Plant_Crop_Mushroom_Block_Red"
    },
    {
      "x": -4,
      "y": 2,
      "z": 0,
      "name": "Plant_Crop_Mushroom_Block_Red_Trunk"
    },
    {
      "x": -4,
      "y": 3,
      "z": 0,
      "name": "Plant_Crop_Mushroom_Block_Red_Trunk"
    },
    {
      "x": -4,
      "y": 4,
      "z": 0,
      "name": "Plant_Crop_Mushroom_Block_Red_Trunk"
    },
    {
      "x": -4,
      "y": 5,
      "z": 0,
      "name": "Plant_Crop_Mushroom_Block_Red_Trunk"
    },
    {
      "x": -4,
      "y": 6,
      "z": 0,
      "name": "Plant_Crop_Mushroom_Block_Red_Trunk"
    },
    {
      "x": -4,
      "y": 7,
      "z": 0,
      "name": "Plant_Crop_Mushroom_Block_Red_Trunk"
    },
    {
      "x": -4,
      "y": 8,
      "z": 0,
      "name": "Plant_Crop_Mushroom_Block_Red_Trunk"
    },
    {
      "x": -4,
      "y": 9,
      "z": 0,
      "name": "Plant_Crop_Mushroom_Block_Red_Trunk"
    },
    {
      "x": -4,
      "y": 10,
      "z": 0,
      "name": "Plant_Crop_Mushroom_Block_Red_Trunk"
    },
    {
      "x": -4,
      "y": 11,
      "z": 0,
      "name": "Plant_Crop_Mushroom_Block_Red_Trunk"
    },
    {
      "x": -4,
      "y": 12,
      "z": 0,
      "name": "Plant_Crop_Mushroom_Block_Red_Trunk"
    },
    {
      "x": -4,
      "y": 25,
      "z": 0,
      "name": "Plant_Crop_Mushroom_Block_Red_Mycelium"
    },
    {
      "x": -4,
      "y": 26,
      "z": 0,
      "name": "Plant_Crop_Mushroom_Block_Red"
    },
    {
      "x": -4,
      "y": 3,
      "z": 1,
      "name": "Plant_Crop_Mushroom_Block_Red_Trunk"
    },
    {
      "x": -4,
      "y": 5,
      "z": 1,
      "name": "Plant_Crop_Mushroom_Block_Red_Trunk"
    },
    {
      "x": -4,
      "y": 6,
      "z": 1,
      "name": "Plant_Crop_Mushroom_Block_Red_Trunk"
    },
    {
      "x": -4,
      "y": 7,
      "z": 1,
      "name": "Plant_Crop_Mushroom_Block_Red_Trunk"
    },
    {
      "x": -4,
      "y": 8,
      "z": 1,
      "name": "Plant_Crop_Mushroom_Block_Red_Trunk"
    },
    {
      "x": -4,
      "y": 11,
      "z": 1,
      "name": "Plant_Crop_Mushroom_Block_Red_Trunk"
    },
    {
      "x": -4,
      "y": 26,
      "z": 1,
      "name": "Plant_Crop_Mushroom_Block_Red"
    },
    {
      "x": -4,
      "y": 27,
      "z": 1,
      "name": "Plant_Crop_Mushroom_Cap_Red",
      "components": {
        "Components": {
          "FarmingBlock": {}
        }
      }
    },
    {
      "x": -4,
      "y": 26,
      "z": 2,
      "name": "Plant_Crop_Mushroom_Block_Red"
    },
    {
      "x": -4,
      "y": 27,
      "z": 2,
      "name": "Plant_Crop_Mushroom_Cap_Red",
      "components": {
        "Components": {
          "FarmingBlock": {}
        }
      }
    },
    {
      "x": -4,
      "y": 25,
      "z": 3,
      "name": "Plant_Crop_Mushroom_Block_Red"
    },
    {
      "x": -4,
      "y": 26,
      "z": 3,
      "name": "Plant_Crop_Mushroom_Block_Red"
    },
    {
      "x": -4,
      "y": 27,
      "z": 3,
      "name": "Plant_Crop_Mushroom_Cap_Red",
      "components": {
        "Components": {
          "FarmingBlock": {}
        }
      }
    },
    {
      "x": -4,
      "y": 24,
      "z": 4,
      "name": "Plant_Crop_Mushroom_Block_Red_Mycelium"
    },
    {
      "x": -4,
      "y": 25,
      "z": 4,
      "name": "Plant_Crop_Mushroom_Block_Red"
    },
    {
      "x": -4,
      "y": 26,
      "z": 4,
      "name": "Plant_Crop_Mushroom_Block_Red"
    },
    {
      "x": -4,
      "y": 24,
      "z": 5,
      "name": "Plant_Crop_Mushroom_Block_Red"
    },
    {
      "x": -4,
      "y": 25,
      "z": 5,
      "name": "Plant_Crop_Mushroom_Block_Red"
    },
    {
      "x": -4,
      "y": 24,
      "z": 6,
      "name": "Plant_Crop_Mushroom_Block_Red"
    },
    {
      "x": -4,
      "y": 25,
      "z": 6,
      "name": "Plant_Crop_Mushroom_Block_Red"
    },
    {
      "x": -4,
      "y": 22,
      "z": 7,
      "name": "Plant_Crop_Mushroom_Block_Red"
    },
    {
      "x": -4,
      "y": 23,
      "z": 7,
      "name": "Plant_Crop_Mushroom_Block_Red"
    },
    {
      "x": -4,
      "y": 18,
      "z": 8,
      "name": "Rock_Crystal_Red_Small",
      "components": {
        "Components": {
          "FarmingBlock": {}
        }
      },
      "rotation": 6
    },
    {
      "x": -4,
      "y": 19,
      "z": 8,
      "name": "Plant_Crop_Mushroom_Block_Red"
    },
    {
      "x": -4,
      "y": 20,
      "z": 8,
      "name": "Plant_Crop_Mushroom_Block_Red"
    },
    {
      "x": -4,
      "y": 21,
      "z": 8,
      "name": "Plant_Crop_Mushroom_Block_Red"
    },
    {
      "x": -4,
      "y": 15,
      "z": 9,
      "name": "Plant_Crop_Mushroom_Block_Red"
    },
    {
      "x": -4,
      "y": 16,
      "z": 9,
      "name": "Plant_Crop_Mushroom_Block_Red"
    },
    {
      "x": -4,
      "y": 17,
      "z": 9,
      "name": "Plant_Crop_Mushroom_Block_Red"
    },
    {
      "x": -4,
      "y": 18,
      "z": 9,
      "name": "Plant_Crop_Mushroom_Block_Red"
    },
    {
      "x": -4,
      "y": 19,
      "z": 9,
      "name": "Plant_Crop_Mushroom_Block_Red"
    },
    {
      "x": -4,
      "y": 20,
      "z": 9,
      "name": "Plant_Crop_Mushroom_Cap_Red",
      "components": {
        "Components": {
          "FarmingBlock": {}
        }
      }
    },
    {
      "x": -3,
      "y": 12,
      "z": -7,
      "name": "Plant_Crop_Mushroom_Block_Red"
    },
    {
      "x": -3,
      "y": 13,
      "z": -7,
      "name": "Plant_Crop_Mushroom_Block_Red"
    },
    {
      "x": -3,
      "y": 14,
      "z": -7,
      "name": "Plant_Crop_Mushroom_Block_Red"
    },
    {
      "x": -3,
      "y": 15,
      "z": -7,
      "name": "Plant_Crop_Mushroom_Block_Red"
    },
    {
      "x": -3,
      "y": 16,
      "z": -7,
      "name": "Plant_Crop_Mushroom_Block_Red"
    },
    {
      "x": -3,
      "y": 17,
      "z": -7,
      "name": "Plant_Crop_Mushroom_Cap_Red",
      "components": {
        "Components": {
          "FarmingBlock": {}
        }
      }
    },
    {
      "x": -3,
      "y": 17,
      "z": -6,
      "name": "Plant_Crop_Mushroom_Block_Red"
    },
    {
      "x": -3,
      "y": 18,
      "z": -6,
      "name": "Plant_Crop_Mushroom_Block_Red"
    },
    {
      "x": -3,
      "y": 18,
      "z": -5,
      "name": "Rock_Crystal_Red_Small",
      "components": {
        "Components": {
          "FarmingBlock": {}
        }
      },
      "rotation": 4
    },
    {
      "x": -3,
      "y": 19,
      "z": -5,
      "name": "Plant_Crop_Mushroom_Block_Red"
    },
    {
      "x": -3,
      "y": 20,
      "z": -5,
      "name": "Plant_Crop_Mushroom_Block_Red"
    },
    {
      "x": -3,
      "y": 20,
      "z": -4,
      "name": "Plant_Crop_Mushroom_Block_Red"
    },
    {
      "x": -3,
      "y": 21,
      "z": -4,
      "name": "Plant_Crop_Mushroom_Block_Red"
    },
    {
      "x": -3,
      "y": 4,
      "z": -3,
      "name": "Plant_Crop_Mushroom_Block_Red_Trunk"
    },
    {
      "x": -3,
      "y": 5,
      "z": -3,
      "name": "Plant_Crop_Mushroom_Block_Red_Trunk"
    },
    {
      "x": -3,
      "y": 6,
      "z": -3,
      "name": "Plant_Crop_Mushroom_Block_Red_Trunk"
    },
    {
      "x": -3,
      "y": 7,
      "z": -3,
      "name": "Plant_Crop_Mushroom_Block_Red_Trunk"
    },
    {
      "x": -3,
      "y": 8,
      "z": -3,
      "name": "Plant_Crop_Mushroom_Block_Red_Trunk"
    },
    {
      "x": -3,
      "y": 22,
      "z": -3,
      "name": "Plant_Crop_Mushroom_Block_Red"
    },
    {
      "x": -3,
      "y": 23,
      "z": -3,
      "name": "Plant_Crop_Mushroom_Block_Red"
    },
    {
      "x": -3,
      "y": 24,
      "z": -3,
      "name": "Plant_Crop_Mushroom_Block_Red"
    },
    {
      "x": -3,
      "y": 2,
      "z": -2,
      "name": "Plant_Crop_Mushroom_Block_Red_Trunk"
    },
    {
      "x": -3,
      "y": 3,
      "z": -2,
      "name": "Plant_Crop_Mushroom_Block_Red_Trunk"
    },
    {
      "x": -3,
      "y": 4,
      "z": -2,
      "name": "Plant_Crop_Mushroom_Block_Red_Trunk"
    },
    {
      "x": -3,
      "y": 5,
      "z": -2,
      "name": "Plant_Crop_Mushroom_Block_Red_Trunk"
    },
    {
      "x": -3,
      "y": 6,
      "z": -2,
      "name": "Plant_Crop_Mushroom_Block_Red_Trunk"
    },
    {
      "x": -3,
      "y": 7,
      "z": -2,
      "name": "Plant_Crop_Mushroom_Block_Red_Trunk"
    },
    {
      "x": -3,
      "y": 8,
      "z": -2,
      "name": "Plant_Crop_Mushroom_Block_Red_Trunk"
    },
    {
      "x": -3,
      "y": 9,
      "z": -2,
      "name": "Plant_Crop_Mushroom_Block_Red_Trunk"
    },
    {
      "x": -3,
      "y": 10,
      "z": -2,
      "name": "Plant_Crop_Mushroom_Block_Red_Trunk"
    },
    {
      "x": -3,
      "y": 11,
      "z": -2,
      "name": "Plant_Crop_Mushroom_Block_Red_Trunk"
    },
    {
      "x": -3,
      "y": 12,
      "z": -2,
      "name": "Plant_Crop_Mushroom_Block_Red_Trunk"
    },
    {
      "x": -3,
      "y": 25,
      "z": -2,
      "name": "Plant_Crop_Mushroom_Block_Red"
    },
    {
      "x": -3,
      "y": 2,
      "z": -1,
      "name": "Plant_Crop_Mushroom_Block_Red_Trunk"
    },
    {
      "x": -3,
      "y": 3,
      "z": -1,
      "name": "Plant_Crop_Mushroom_Block_Red_Trunk"
    },
    {
      "x": -3,
      "y": 4,
      "z": -1,
      "name": "Plant_Crop_Mushroom_Block_Red_Trunk"
    },
    {
      "x": -3,
      "y": 5,
      "z": -1,
      "name": "Plant_Crop_Mushroom_Block_Red_Trunk"
    },
    {
      "x": -3,
      "y": 6,
      "z": -1,
      "name": "Plant_Crop_Mushroom_Block_Red_Trunk"
    },
    {
      "x": -3,
      "y": 7,
      "z": -1,
      "name": "Plant_Crop_Mushroom_Block_Red_Trunk"
    },
    {
      "x": -3,
      "y": 8,
      "z": -1,
      "name": "Plant_Crop_Mushroom_Block_Red_Trunk"
    },
    {
      "x": -3,
      "y": 9,
      "z": -1,
      "name": "Plant_Crop_Mushroom_Block_Red_Trunk"
    },
    {
      "x": -3,
      "y": 10,
      "z": -1,
      "name": "Plant_Crop_Mushroom_Block_Red_Trunk"
    },
    {
      "x": -3,
      "y": 11,
      "z": -1,
      "name": "Plant_Crop_Mushroom_Block_Red_Trunk"
    },
    {
      "x": -3,
      "y": 12,
      "z": -1,
      "name": "Plant_Crop_Mushroom_Block_Red_Trunk"
    },
    {
      "x": -3,
      "y": 13,
      "z": -1,
      "name": "Plant_Crop_Mushroom_Block_Red_Trunk"
    },
    {
      "x": -3,
      "y": 14,
      "z": -1,
      "name": "Plant_Crop_Mushroom_Block_Red_Trunk"
    },
    {
      "x": -3,
      "y": 15,
      "z": -1,
      "name": "Plant_Crop_Mushroom_Block_Red_Trunk"
    },
    {
      "x": -3,
      "y": 16,
      "z": -1,
      "name": "Plant_Crop_Mushroom_Block_Red_Trunk"
    },
    {
      "x": -3,
      "y": 25,
      "z": -1,
      "name": "Plant_Crop_Mushroom_Block_Red"
    },
    {
      "x": -3,
      "y": 26,
      "z": -1,
      "name": "Plant_Crop_Mushroom_Block_Red"
    },
    {
      "x": -3,
      "y": 2,
      "z": 0,
      "name": "Plant_Crop_Mushroom_Block_Red_Trunk"
    },
    {
      "x": -3,
      "y": 3,
      "z": 0,
      "name": "Plant_Crop_Mushroom_Block_Red_Trunk"
    },
    {
      "x": -3,
      "y": 4,
      "z": 0,
      "name": "Plant_Crop_Mushroom_Block_Red_Trunk"
    },
    {
      "x": -3,
      "y": 5,
      "z": 0,
      "name": "Plant_Crop_Mushroom_Block_Red_Trunk"
    },
    {
      "x": -3,
      "y": 6,
      "z": 0,
      "name": "Plant_Crop_Mushroom_Block_Red_Trunk"
    },
    {
      "x": -3,
      "y": 7,
      "z": 0,
      "name": "Plant_Crop_Mushroom_Block_Red_Trunk"
    },
    {
      "x": -3,
      "y": 8,
      "z": 0,
      "name": "Plant_Crop_Mushroom_Block_Red_Trunk"
    },
    {
      "x": -3,
      "y": 9,
      "z": 0,
      "name": "Plant_Crop_Mushroom_Block_Red_Trunk"
    },
    {
      "x": -3,
      "y": 10,
      "z": 0,
      "name": "Plant_Crop_Mushroom_Block_Red_Trunk"
    },
    {
      "x": -3,
      "y": 11,
      "z": 0,
      "name": "Plant_Crop_Mushroom_Block_Red_Trunk"
    },
    {
      "x": -3,
      "y": 12,
      "z": 0,
      "name": "Plant_Crop_Mushroom_Block_Red_Trunk"
    },
    {
      "x": -3,
      "y": 13,
      "z": 0,
      "name": "Plant_Crop_Mushroom_Block_Red_Trunk"
    },
    {
      "x": -3,
      "y": 14,
      "z": 0,
      "name": "Plant_Crop_Mushroom_Block_Red_Trunk"
    },
    {
      "x": -3,
      "y": 15,
      "z": 0,
      "name": "Plant_Crop_Mushroom_Block_Red_Trunk"
    },
    {
      "x": -3,
      "y": 16,
      "z": 0,
      "name": "Plant_Crop_Mushroom_Block_Red_Trunk"
    },
    {
      "x": -3,
      "y": 17,
      "z": 0,
      "name": "Plant_Crop_Mushroom_Block_Red_Trunk"
    },
    {
      "x": -3,
      "y": 18,
      "z": 0,
      "name": "Plant_Crop_Mushroom_Block_Red_Trunk"
    },
    {
      "x": -3,
      "y": 26,
      "z": 0,
      "name": "Plant_Crop_Mushroom_Block_Red"
    },
    {
      "x": -3,
      "y": 27,
      "z": 0,
      "name": "Plant_Crop_Mushroom_Block_Red"
    },
    {
      "x": -3,
      "y": 5,
      "z": 1,
      "name": "Plant_Crop_Mushroom_Block_Red_Trunk"
    },
    {
      "x": -3,
      "y": 6,
      "z": 1,
      "name": "Plant_Crop_Mushroom_Block_Red_Trunk"
    },
    {
      "x": -3,
      "y": 7,
      "z": 1,
      "name": "Plant_Crop_Mushroom_Block_Red_Trunk"
    },
    {
      "x": -3,
      "y": 8,
      "z": 1,
      "name": "Plant_Crop_Mushroom_Block_Red_Trunk"
    },
    {
      "x": -3,
      "y": 9,
      "z": 1,
      "name": "Plant_Crop_Mushroom_Block_Red_Trunk"
    },
    {
      "x": -3,
      "y": 10,
      "z": 1,
      "name": "Plant_Crop_Mushroom_Block_Red_Trunk"
    },
    {
      "x": -3,
      "y": 11,
      "z": 1,
      "name": "Plant_Crop_Mushroom_Block_Red_Trunk"
    },
    {
      "x": -3,
      "y": 12,
      "z": 1,
      "name": "Plant_Crop_Mushroom_Block_Red_Trunk"
    },
    {
      "x": -3,
      "y": 13,
      "z": 1,
      "name": "Plant_Crop_Mushroom_Block_Red_Trunk"
    },
    {
      "x": -3,
      "y": 14,
      "z": 1,
      "name": "Plant_Crop_Mushroom_Block_Red_Trunk"
    },
    {
      "x": -3,
      "y": 15,
      "z": 1,
      "name": "Plant_Crop_Mushroom_Block_Red_Trunk"
    },
    {
      "x": -3,
      "y": 16,
      "z": 1,
      "name": "Plant_Crop_Mushroom_Block_Red_Trunk"
    },
    {
      "x": -3,
      "y": 17,
      "z": 1,
      "name": "Plant_Crop_Mushroom_Block_Red_Trunk"
    },
    {
      "x": -3,
      "y": 18,
      "z": 1,
      "name": "Plant_Crop_Mushroom_Block_Red_Trunk"
    },
    {
      "x": -3,
      "y": 19,
      "z": 1,
      "name": "Plant_Crop_Mushroom_Block_Red_Trunk"
    },
    {
      "x": -3,
      "y": 20,
      "z": 1,
      "name": "Plant_Crop_Mushroom_Block_Red_Trunk"
    },
    {
      "x": -3,
      "y": 27,
      "z": 1,
      "name": "Plant_Crop_Mushroom_Block_Red"
    },
    {
      "x": -3,
      "y": 12,
      "z": 2,
      "name": "Plant_Crop_Mushroom_Block_Red_Trunk"
    },
    {
      "x": -3,
      "y": 13,
      "z": 2,
      "name": "Plant_Crop_Mushroom_Block_Red_Trunk"
    },
    {
      "x": -3,
      "y": 14,
      "z": 2,
      "name": "Plant_Crop_Mushroom_Block_Red_Trunk"
    },
    {
      "x": -3,
      "y": 15,
      "z": 2,
      "name": "Plant_Crop_Mushroom_Block_Red_Trunk"
    },
    {
      "x": -3,
      "y": 16,
      "z": 2,
      "name": "Plant_Crop_Mushroom_Block_Red_Trunk"
    },
    {
      "x": -3,
      "y": 17,
      "z": 2,
      "name": "Plant_Crop_Mushroom_Block_Red_Trunk"
    },
    {
      "x": -3,
      "y": 18,
      "z": 2,
      "name": "Plant_Crop_Mushroom_Block_Red_Trunk"
    },
    {
      "x": -3,
      "y": 19,
      "z": 2,
      "name": "Plant_Crop_Mushroom_Block_Red_Trunk"
    },
    {
      "x": -3,
      "y": 20,
      "z": 2,
      "name": "Plant_Crop_Mushroom_Block_Red_Trunk"
    },
    {
      "x": -3,
      "y": 27,
      "z": 2,
      "name": "Plant_Crop_Mushroom_Block_Red"
    },
    {
      "x": -3,
      "y": 28,
      "z": 2,
      "name": "Plant_Crop_Mushroom_Cap_Red",
      "components": {
        "Components": {
          "FarmingBlock": {}
        }
      }
    },
    {
      "x": -3,
      "y": 16,
      "z": 3,
      "name": "Plant_Crop_Mushroom_Block_Red_Trunk"
    },
    {
      "x": -3,
      "y": 17,
      "z": 3,
      "name": "Plant_Crop_Mushroom_Block_Red_Trunk"
    },
    {
      "x": -3,
      "y": 25,
      "z": 3,
      "name": "Plant_Crop_Mushroom_Block_Red_Mycelium"
    },
    {
      "x": -3,
      "y": 26,
      "z": 3,
      "name": "Plant_Crop_Mushroom_Block_Red"
    },
    {
      "x": -3,
      "y": 27,
      "z": 3,
      "name": "Plant_Crop_Mushroom_Block_Red"
    },
    {
      "x": -3,
      "y": 28,
      "z": 3,
      "name": "Plant_Crop_Mushroom_Cap_Red",
      "components": {
        "Components": {
          "FarmingBlock": {}
        }
      }
    },
    {
      "x": -3,
      "y": 24,
      "z": 4,
      "name": "Plant_Crop_Mushroom_Block_Red_Mycelium"
    },
    {
      "x": -3,
      "y": 25,
      "z": 4,
      "name": "Plant_Crop_Mushroom_Block_Red_Mycelium"
    },
    {
      "x": -3,
      "y": 26,
      "z": 4,
      "name": "Plant_Crop_Mushroom_Block_Red_Mycelium"
    },
    {
      "x": -3,
      "y": 27,
      "z": 4,
      "name": "Plant_Crop_Mushroom_Block_Red"
    },
    {
      "x": -3,
      "y": 25,
      "z": 5,
      "name": "Plant_Crop_Mushroom_Block_Red"
    },
    {
      "x": -3,
      "y": 26,
      "z": 5,
      "name": "Plant_Crop_Mushroom_Block_Red"
    },
    {
      "x": -3,
      "y": 23,
      "z": 6,
      "name": "Plant_Crop_Mushroom_Block_Red_Mycelium"
    },
    {
      "x": -3,
      "y": 24,
      "z": 6,
      "name": "Plant_Crop_Mushroom_Block_Red"
    },
    {
      "x": -3,
      "y": 25,
      "z": 6,
      "name": "Plant_Crop_Mushroom_Block_Red"
    },
    {
      "x": -3,
      "y": 22,
      "z": 7,
      "name": "Plant_Crop_Mushroom_Block_Red"
    },
    {
      "x": -3,
      "y": 23,
      "z": 7,
      "name": "Plant_Crop_Mushroom_Block_Red"
    },
    {
      "x": -3,
      "y": 24,
      "z": 7,
      "name": "Plant_Crop_Mushroom_Block_Red"
    },
    {
      "x": -3,
      "y": 19,
      "z": 8,
      "name": "Plant_Crop_Mushroom_Block_Red"
    },
    {
      "x": -3,
      "y": 20,
      "z": 8,
      "name": "Plant_Crop_Mushroom_Block_Red"
    },
    {
      "x": -3,
      "y": 21,
      "z": 8,
      "name": "Plant_Crop_Mushroom_Block_Red"
    },
    {
      "x": -3,
      "y": 22,
      "z": 8,
      "name": "Plant_Crop_Mushroom_Block_Red"
    },
    {
      "x": -3,
      "y": 23,
      "z": 8,
      "name": "Plant_Crop_Mushroom_Cap_Red",
      "components": {
        "Components": {
          "FarmingBlock": {}
        }
      }
    },
    {
      "x": -3,
      "y": 15,
      "z": 9,
      "name": "Plant_Crop_Mushroom_Block_Red"
    },
    {
      "x": -3,
      "y": 16,
      "z": 9,
      "name": "Plant_Crop_Mushroom_Block_Red"
    },
    {
      "x": -3,
      "y": 17,
      "z": 9,
      "name": "Plant_Crop_Mushroom_Block_Red"
    },
    {
      "x": -3,
      "y": 18,
      "z": 9,
      "name": "Plant_Crop_Mushroom_Block_Red"
    },
    {
      "x": -3,
      "y": 19,
      "z": 9,
      "name": "Plant_Crop_Mushroom_Block_Red"
    },
    {
      "x": -3,
      "y": 20,
      "z": 9,
      "name": "Plant_Crop_Mushroom_Cap_Red",
      "components": {
        "Components": {
          "FarmingBlock": {}
        }
      }
    },
    {
      "x": -2,
      "y": 12,
      "z": -7,
      "name": "Plant_Crop_Mushroom_Block_Red"
    },
    {
      "x": -2,
      "y": 13,
      "z": -7,
      "name": "Plant_Crop_Mushroom_Block_Red"
    },
    {
      "x": -2,
      "y": 14,
      "z": -7,
      "name": "Plant_Crop_Mushroom_Block_Red"
    },
    {
      "x": -2,
      "y": 15,
      "z": -7,
      "name": "Plant_Crop_Mushroom_Block_Red"
    },
    {
      "x": -2,
      "y": 16,
      "z": -7,
      "name": "Plant_Crop_Mushroom_Block_Red"
    },
    {
      "x": -2,
      "y": 16,
      "z": -6,
      "name": "Plant_Crop_Mushroom_Block_Red"
    },
    {
      "x": -2,
      "y": 17,
      "z": -6,
      "name": "Plant_Crop_Mushroom_Block_Red"
    },
    {
      "x": -2,
      "y": 18,
      "z": -6,
      "name": "Plant_Crop_Mushroom_Block_Red"
    },
    {
      "x": -2,
      "y": 19,
      "z": -5,
      "name": "Plant_Crop_Mushroom_Block_Red"
    },
    {
      "x": -2,
      "y": 20,
      "z": -5,
      "name": "Plant_Crop_Mushroom_Block_Red"
    },
    {
      "x": -2,
      "y": 6,
      "z": -4,
      "name": "Plant_Crop_Mushroom_Block_Red_Trunk"
    },
    {
      "x": -2,
      "y": 7,
      "z": -4,
      "name": "Plant_Crop_Mushroom_Block_Red_Trunk"
    },
    {
      "x": -2,
      "y": 8,
      "z": -4,
      "name": "Plant_Crop_Mushroom_Block_Red_Trunk"
    },
    {
      "x": -2,
      "y": 9,
      "z": -4,
      "name": "Plant_Crop_Mushroom_Block_Red_Trunk"
    },
    {
      "x": -2,
      "y": 20,
      "z": -4,
      "name": "Plant_Crop_Mushroom_Block_Red"
    },
    {
      "x": -2,
      "y": 21,
      "z": -4,
      "name": "Plant_Crop_Mushroom_Block_Red"
    },
    {
      "x": -2,
      "y": 3,
      "z": -3,
      "name": "Plant_Crop_Mushroom_Block_Red_Trunk"
    },
    {
      "x": -2,
      "y": 4,
      "z": -3,
      "name": "Plant_Crop_Mushroom_Block_Red_Trunk"
    },
    {
      "x": -2,
      "y": 5,
      "z": -3,
      "name": "Plant_Crop_Mushroom_Block_Red_Trunk"
    },
    {
      "x": -2,
      "y": 6,
      "z": -3,
      "name": "Plant_Crop_Mushroom_Block_Red_Trunk"
    },
    {
      "x": -2,
      "y": 7,
      "z": -3,
      "name": "Plant_Crop_Mushroom_Block_Red_Trunk"
    },
    {
      "x": -2,
      "y": 8,
      "z": -3,
      "name": "Plant_Crop_Mushroom_Block_Red_Trunk"
    },
    {
      "x": -2,
      "y": 9,
      "z": -3,
      "name": "Plant_Crop_Mushroom_Block_Red_Trunk"
    },
    {
      "x": -2,
      "y": 10,
      "z": -3,
      "name": "Plant_Crop_Mushroom_Block_Red_Trunk"
    },
    {
      "x": -2,
      "y": 11,
      "z": -3,
      "name": "Plant_Crop_Mushroom_Block_Red_Trunk"
    },
    {
      "x": -2,
      "y": 22,
      "z": -3,
      "name": "Plant_Crop_Mushroom_Block_Red"
    },
    {
      "x": -2,
      "y": 23,
      "z": -3,
      "name": "Plant_Crop_Mushroom_Block_Red"
    },
    {
      "x": -2,
      "y": 24,
      "z": -3,
      "name": "Plant_Crop_Mushroom_Block_Red"
    },
    {
      "x": -2,
      "y": 2,
      "z": -2,
      "name": "Plant_Crop_Mushroom_Block_Red_Trunk"
    },
    {
      "x": -2,
      "y": 3,
      "z": -2,
      "name": "Plant_Crop_Mushroom_Block_Red_Trunk"
    },
    {
      "x": -2,
      "y": 4,
      "z": -2,
      "name": "Plant_Crop_Mushroom_Block_Red_Trunk"
    },
    {
      "x": -2,
      "y": 5,
      "z": -2,
      "name": "Plant_Crop_Mushroom_Block_Red_Trunk"
    },
    {
      "x": -2,
      "y": 6,
      "z": -2,
      "name": "Plant_Crop_Mushroom_Block_Red_Trunk"
    },
    {
      "x": -2,
      "y": 7,
      "z": -2,
      "name": "Plant_Crop_Mushroom_Block_Red_Trunk"
    },
    {
      "x": -2,
      "y": 8,
      "z": -2,
      "name": "Plant_Crop_Mushroom_Block_Red_Trunk"
    },
    {
      "x": -2,
      "y": 9,
      "z": -2,
      "name": "Plant_Crop_Mushroom_Block_Red_Trunk"
    },
    {
      "x": -2,
      "y": 10,
      "z": -2,
      "name": "Plant_Crop_Mushroom_Block_Red_Trunk"
    },
    {
      "x": -2,
      "y": 11,
      "z": -2,
      "name": "Plant_Crop_Mushroom_Block_Red_Trunk"
    },
    {
      "x": -2,
      "y": 12,
      "z": -2,
      "name": "Plant_Crop_Mushroom_Block_Red_Trunk"
    },
    {
      "x": -2,
      "y": 13,
      "z": -2,
      "name": "Plant_Crop_Mushroom_Block_Red_Trunk"
    },
    {
      "x": -2,
      "y": 25,
      "z": -2,
      "name": "Plant_Crop_Mushroom_Block_Red"
    },
    {
      "x": -2,
      "y": 26,
      "z": -2,
      "name": "Plant_Crop_Mushroom_Block_Red"
    },
    {
      "x": -2,
      "y": 4,
      "z": -1,
      "name": "Plant_Crop_Mushroom_Block_Red_Trunk"
    },
    {
      "x": -2,
      "y": 5,
      "z": -1,
      "name": "Plant_Crop_Mushroom_Block_Red_Trunk"
    },
    {
      "x": -2,
      "y": 6,
      "z": -1,
      "name": "Plant_Crop_Mushroom_Block_Red_Trunk"
    },
    {
      "x": -2,
      "y": 7,
      "z": -1,
      "name": "Plant_Crop_Mushroom_Block_Red_Trunk"
    },
    {
      "x": -2,
      "y": 8,
      "z": -1,
      "name": "Plant_Crop_Mushroom_Block_Red_Trunk"
    },
    {
      "x": -2,
      "y": 9,
      "z": -1,
      "name": "Plant_Crop_Mushroom_Block_Red_Trunk"
    },
    {
      "x": -2,
      "y": 10,
      "z": -1,
      "name": "Plant_Crop_Mushroom_Block_Red_Trunk"
    },
    {
      "x": -2,
      "y": 11,
      "z": -1,
      "name": "Plant_Crop_Mushroom_Block_Red_Trunk"
    },
    {
      "x": -2,
      "y": 12,
      "z": -1,
      "name": "Plant_Crop_Mushroom_Block_Red_Trunk"
    },
    {
      "x": -2,
      "y": 13,
      "z": -1,
      "name": "Plant_Crop_Mushroom_Block_Red_Trunk"
    },
    {
      "x": -2,
      "y": 14,
      "z": -1,
      "name": "Plant_Crop_Mushroom_Block_Red_Trunk"
    },
    {
      "x": -2,
      "y": 15,
      "z": -1,
      "name": "Plant_Crop_Mushroom_Block_Red_Trunk"
    },
    {
      "x": -2,
      "y": 16,
      "z": -1,
      "name": "Plant_Crop_Mushroom_Block_Red_Trunk"
    },
    {
      "x": -2,
      "y": 17,
      "z": -1,
      "name": "Plant_Crop_Mushroom_Block_Red_Trunk"
    },
    {
      "x": -2,
      "y": 18,
      "z": -1,
      "name": "Plant_Crop_Mushroom_Block_Red_Trunk"
    },
    {
      "x": -2,
      "y": 19,
      "z": -1,
      "name": "Plant_Crop_Mushroom_Block_Red_Trunk"
    },
    {
      "x": -2,
      "y": 26,
      "z": -1,
      "name": "Plant_Crop_Mushroom_Block_Red"
    },
    {
      "x": -2,
      "y": 4,
      "z": 0,
      "name": "Plant_Crop_Mushroom_Block_Red_Trunk"
    },
    {
      "x": -2,
      "y": 5,
      "z": 0,
      "name": "Plant_Crop_Mushroom_Block_Red_Trunk"
    },
    {
      "x": -2,
      "y": 6,
      "z": 0,
      "name": "Plant_Crop_Mushroom_Block_Red_Trunk"
    },
    {
      "x": -2,
      "y": 7,
      "z": 0,
      "name": "Plant_Crop_Mushroom_Block_Red_Trunk"
    },
    {
      "x": -2,
      "y": 8,
      "z": 0,
      "name": "Plant_Crop_Mushroom_Block_Red_Trunk"
    },
    {
      "x": -2,
      "y": 9,
      "z": 0,
      "name": "Plant_Crop_Mushroom_Block_Red_Trunk"
    },
    {
      "x": -2,
      "y": 10,
      "z": 0,
      "name": "Plant_Crop_Mushroom_Block_Red_Trunk"
    },
    {
      "x": -2,
      "y": 11,
      "z": 0,
      "name": "Plant_Crop_Mushroom_Block_Red_Trunk"
    },
    {
      "x": -2,
      "y": 12,
      "z": 0,
      "name": "Plant_Crop_Mushroom_Block_Red_Trunk"
    },
    {
      "x": -2,
      "y": 13,
      "z": 0,
      "name": "Plant_Crop_Mushroom_Block_Red_Trunk"
    },
    {
      "x": -2,
      "y": 14,
      "z": 0,
      "name": "Plant_Crop_Mushroom_Block_Red_Trunk"
    },
    {
      "x": -2,
      "y": 15,
      "z": 0,
      "name": "Plant_Crop_Mushroom_Block_Red_Trunk"
    },
    {
      "x": -2,
      "y": 16,
      "z": 0,
      "name": "Plant_Crop_Mushroom_Block_Red_Trunk"
    },
    {
      "x": -2,
      "y": 17,
      "z": 0,
      "name": "Plant_Crop_Mushroom_Block_Red_Trunk"
    },
    {
      "x": -2,
      "y": 18,
      "z": 0,
      "name": "Plant_Crop_Mushroom_Block_Red_Trunk"
    },
    {
      "x": -2,
      "y": 19,
      "z": 0,
      "name": "Plant_Crop_Mushroom_Block_Red_Trunk"
    },
    {
      "x": -2,
      "y": 20,
      "z": 0,
      "name": "Plant_Crop_Mushroom_Block_Red_Trunk"
    },
    {
      "x": -2,
      "y": 27,
      "z": 0,
      "name": "Plant_Crop_Mushroom_Block_Red"
    },
    {
      "x": -2,
      "y": 5,
      "z": 1,
      "name": "Plant_Crop_Mushroom_Block_Red_Trunk"
    },
    {
      "x": -2,
      "y": 6,
      "z": 1,
      "name": "Plant_Crop_Mushroom_Block_Red_Trunk"
    },
    {
      "x": -2,
      "y": 7,
      "z": 1,
      "name": "Plant_Crop_Mushroom_Block_Red_Trunk"
    },
    {
      "x": -2,
      "y": 8,
      "z": 1,
      "name": "Plant_Crop_Mushroom_Block_Red_Trunk"
    },
    {
      "x": -2,
      "y": 9,
      "z": 1,
      "name": "Plant_Crop_Mushroom_Block_Red_Trunk"
    },
    {
      "x": -2,
      "y": 10,
      "z": 1,
      "name": "Plant_Crop_Mushroom_Block_Red_Trunk"
    },
    {
      "x": -2,
      "y": 11,
      "z": 1,
      "name": "Plant_Crop_Mushroom_Block_Red_Trunk"
    },
    {
      "x": -2,
      "y": 12,
      "z": 1,
      "name": "Plant_Crop_Mushroom_Block_Red_Trunk"
    },
    {
      "x": -2,
      "y": 13,
      "z": 1,
      "name": "Plant_Crop_Mushroom_Block_Red_Trunk"
    },
    {
      "x": -2,
      "y": 14,
      "z": 1,
      "name": "Plant_Crop_Mushroom_Block_Red_Trunk"
    },
    {
      "x": -2,
      "y": 15,
      "z": 1,
      "name": "Plant_Crop_Mushroom_Block_Red_Trunk"
    },
    {
      "x": -2,
      "y": 16,
      "z": 1,
      "name": "Plant_Crop_Mushroom_Block_Red_Trunk"
    },
    {
      "x": -2,
      "y": 17,
      "z": 1,
      "name": "Plant_Crop_Mushroom_Block_Red_Trunk"
    },
    {
      "x": -2,
      "y": 18,
      "z": 1,
      "name": "Plant_Crop_Mushroom_Block_Red_Trunk"
    },
    {
      "x": -2,
      "y": 19,
      "z": 1,
      "name": "Plant_Crop_Mushroom_Block_Red_Trunk"
    },
    {
      "x": -2,
      "y": 20,
      "z": 1,
      "name": "Plant_Crop_Mushroom_Block_Red_Trunk"
    },
    {
      "x": -2,
      "y": 21,
      "z": 1,
      "name": "Plant_Crop_Mushroom_Block_Red_Trunk"
    },
    {
      "x": -2,
      "y": 22,
      "z": 1,
      "name": "Plant_Crop_Mushroom_Block_Red_Trunk"
    },
    {
      "x": -2,
      "y": 27,
      "z": 1,
      "name": "Plant_Crop_Mushroom_Block_Red"
    },
    {
      "x": -2,
      "y": 8,
      "z": 2,
      "name": "Plant_Crop_Mushroom_Block_Red_Trunk"
    },
    {
      "x": -2,
      "y": 9,
      "z": 2,
      "name": "Plant_Crop_Mushroom_Block_Red_Trunk"
    },
    {
      "x": -2,
      "y": 10,
      "z": 2,
      "name": "Plant_Crop_Mushroom_Block_Red_Trunk"
    },
    {
      "x": -2,
      "y": 11,
      "z": 2,
      "name": "Plant_Crop_Mushroom_Block_Red_Trunk"
    },
    {
      "x": -2,
      "y": 12,
      "z": 2,
      "name": "Plant_Crop_Mushroom_Block_Red_Trunk"
    },
    {
      "x": -2,
      "y": 13,
      "z": 2,
      "name": "Plant_Crop_Mushroom_Block_Red_Trunk"
    },
    {
      "x": -2,
      "y": 14,
      "z": 2,
      "name": "Plant_Crop_Mushroom_Block_Red_Trunk"
    },
    {
      "x": -2,
      "y": 15,
      "z": 2,
      "name": "Plant_Crop_Mushroom_Block_Red_Trunk"
    },
    {
      "x": -2,
      "y": 16,
      "z": 2,
      "name": "Plant_Crop_Mushroom_Block_Red_Trunk"
    },
    {
      "x": -2,
      "y": 17,
      "z": 2,
      "name": "Plant_Crop_Mushroom_Block_Red_Trunk"
    },
    {
      "x": -2,
      "y": 18,
      "z": 2,
      "name": "Plant_Crop_Mushroom_Block_Red_Trunk"
    },
    {
      "x": -2,
      "y": 19,
      "z": 2,
      "name": "Plant_Crop_Mushroom_Block_Red_Trunk"
    },
    {
      "x": -2,
      "y": 20,
      "z": 2,
      "name": "Plant_Crop_Mushroom_Block_Red_Trunk"
    },
    {
      "x": -2,
      "y": 21,
      "z": 2,
      "name": "Plant_Crop_Mushroom_Block_Red_Trunk"
    },
    {
      "x": -2,
      "y": 22,
      "z": 2,
      "name": "Plant_Crop_Mushroom_Block_Red_Trunk"
    },
    {
      "x": -2,
      "y": 27,
      "z": 2,
      "name": "Plant_Crop_Mushroom_Block_Red"
    },
    {
      "x": -2,
      "y": 28,
      "z": 2,
      "name": "Plant_Crop_Mushroom_Cap_Red",
      "components": {
        "Components": {
          "FarmingBlock": {}
        }
      }
    },
    {
      "x": -2,
      "y": 15,
      "z": 3,
      "name": "Plant_Crop_Mushroom_Block_Red_Trunk"
    },
    {
      "x": -2,
      "y": 16,
      "z": 3,
      "name": "Plant_Crop_Mushroom_Block_Red_Trunk"
    },
    {
      "x": -2,
      "y": 17,
      "z": 3,
      "name": "Plant_Crop_Mushroom_Block_Red_Trunk"
    },
    {
      "x": -2,
      "y": 18,
      "z": 3,
      "name": "Plant_Crop_Mushroom_Block_Red_Trunk"
    },
    {
      "x": -2,
      "y": 27,
      "z": 3,
      "name": "Plant_Crop_Mushroom_Block_Red"
    },
    {
      "x": -2,
      "y": 26,
      "z": 4,
      "name": "Plant_Crop_Mushroom_Block_Red_Mycelium"
    },
    {
      "x": -2,
      "y": 27,
      "z": 4,
      "name": "Plant_Crop_Mushroom_Block_Red"
    },
    {
      "x": -2,
      "y": 25,
      "z": 5,
      "name": "Plant_Crop_Mushroom_Block_Red_Mycelium"
    },
    {
      "x": -2,
      "y": 26,
      "z": 5,
      "name": "Plant_Crop_Mushroom_Block_Red"
    },
    {
      "x": -2,
      "y": 23,
      "z": 6,
      "name": "Plant_Crop_Mushroom_Block_Red_Mycelium"
    },
    {
      "x": -2,
      "y": 24,
      "z": 6,
      "name": "Plant_Crop_Mushroom_Block_Red"
    },
    {
      "x": -2,
      "y": 25,
      "z": 6,
      "name": "Plant_Crop_Mushroom_Block_Red"
    },
    {
      "x": -2,
      "y": 21,
      "z": 7,
      "name": "Rock_Crystal_Red_Small",
      "components": {
        "Components": {
          "FarmingBlock": {}
        }
      },
      "rotation": 6
    },
    {
      "x": -2,
      "y": 22,
      "z": 7,
      "name": "Rock_Crystal_Red_Small",
      "components": {
        "Components": {
          "FarmingBlock": {}
        }
      },
      "rotation": 6
    },
    {
      "x": -2,
      "y": 23,
      "z": 7,
      "name": "Plant_Crop_Mushroom_Block_Red"
    },
    {
      "x": -2,
      "y": 24,
      "z": 7,
      "name": "Plant_Crop_Mushroom_Cap_Red",
      "components": {
        "Components": {
          "FarmingBlock": {}
        }
      }
    },
    {
      "x": -2,
      "y": 19,
      "z": 8,
      "name": "Plant_Crop_Mushroom_Block_Red"
    },
    {
      "x": -2,
      "y": 20,
      "z": 8,
      "name": "Plant_Crop_Mushroom_Block_Red"
    },
    {
      "x": -2,
      "y": 21,
      "z": 8,
      "name": "Plant_Crop_Mushroom_Block_Red"
    },
    {
      "x": -2,
      "y": 22,
      "z": 8,
      "name": "Plant_Crop_Mushroom_Block_Red"
    },
    {
      "x": -2,
      "y": 23,
      "z": 8,
      "name": "Plant_Crop_Mushroom_Cap_Red",
      "components": {
        "Components": {
          "FarmingBlock": {}
        }
      }
    },
    {
      "x": -2,
      "y": 14,
      "z": 9,
      "name": "Plant_Crop_Mushroom_Block_Red"
    },
    {
      "x": -2,
      "y": 15,
      "z": 9,
      "name": "Plant_Crop_Mushroom_Block_Red"
    },
    {
      "x": -2,
      "y": 16,
      "z": 9,
      "name": "Plant_Crop_Mushroom_Block_Red"
    },
    {
      "x": -2,
      "y": 17,
      "z": 9,
      "name": "Plant_Crop_Mushroom_Block_Red"
    },
    {
      "x": -2,
      "y": 18,
      "z": 9,
      "name": "Plant_Crop_Mushroom_Block_Red"
    },
    {
      "x": -1,
      "y": 11,
      "z": -7,
      "name": "Plant_Crop_Mushroom_Block_Red"
    },
    {
      "x": -1,
      "y": 12,
      "z": -7,
      "name": "Plant_Crop_Mushroom_Block_Red"
    },
    {
      "x": -1,
      "y": 13,
      "z": -7,
      "name": "Plant_Crop_Mushroom_Block_Red"
    },
    {
      "x": -1,
      "y": 14,
      "z": -7,
      "name": "Plant_Crop_Mushroom_Block_Red"
    },
    {
      "x": -1,
      "y": 15,
      "z": -7,
      "name": "Plant_Crop_Mushroom_Block_Red"
    },
    {
      "x": -1,
      "y": 16,
      "z": -6,
      "name": "Plant_Crop_Mushroom_Block_Red"
    },
    {
      "x": -1,
      "y": 17,
      "z": -6,
      "name": "Plant_Crop_Mushroom_Block_Red"
    },
    {
      "x": -1,
      "y": 18,
      "z": -6,
      "name": "Plant_Crop_Mushroom_Block_Red"
    },
    {
      "x": -1,
      "y": 19,
      "z": -5,
      "name": "Plant_Crop_Mushroom_Block_Red"
    },
    {
      "x": -1,
      "y": 8,
      "z": -4,
      "name": "Plant_Crop_Mushroom_Block_Red_Trunk"
    },
    {
      "x": -1,
      "y": 9,
      "z": -4,
      "name": "Plant_Crop_Mushroom_Block_Red_Trunk"
    },
    {
      "x": -1,
      "y": 10,
      "z": -4,
      "name": "Plant_Crop_Mushroom_Block_Red_Trunk"
    },
    {
      "x": -1,
      "y": 19,
      "z": -4,
      "name": "Plant_Crop_Mushroom_Block_Red_Mycelium"
    },
    {
      "x": -1,
      "y": 20,
      "z": -4,
      "name": "Plant_Crop_Mushroom_Block_Red"
    },
    {
      "x": -1,
      "y": 21,
      "z": -4,
      "name": "Plant_Crop_Mushroom_Block_Red"
    },
    {
      "x": -1,
      "y": 4,
      "z": -3,
      "name": "Plant_Crop_Mushroom_Block_Red_Trunk"
    },
    {
      "x": -1,
      "y": 5,
      "z": -3,
      "name": "Plant_Crop_Mushroom_Block_Red_Trunk"
    },
    {
      "x": -1,
      "y": 6,
      "z": -3,
      "name": "Plant_Crop_Mushroom_Block_Red_Trunk"
    },
    {
      "x": -1,
      "y": 7,
      "z": -3,
      "name": "Plant_Crop_Mushroom_Block_Red_Trunk"
    },
    {
      "x": -1,
      "y": 8,
      "z": -3,
      "name": "Plant_Crop_Mushroom_Block_Red_Trunk"
    },
    {
      "x": -1,
      "y": 9,
      "z": -3,
      "name": "Plant_Crop_Mushroom_Block_Red_Trunk"
    },
    {
      "x": -1,
      "y": 10,
      "z": -3,
      "name": "Plant_Crop_Mushroom_Block_Red_Trunk"
    },
    {
      "x": -1,
      "y": 11,
      "z": -3,
      "name": "Plant_Crop_Mushroom_Block_Red_Trunk"
    },
    {
      "x": -1,
      "y": 21,
      "z": -3,
      "name": "Plant_Crop_Mushroom_Block_Red_Mycelium"
    },
    {
      "x": -1,
      "y": 22,
      "z": -3,
      "name": "Plant_Crop_Mushroom_Block_Red"
    },
    {
      "x": -1,
      "y": 23,
      "z": -3,
      "name": "Plant_Crop_Mushroom_Block_Red"
    },
    {
      "x": -1,
      "y": 24,
      "z": -3,
      "name": "Plant_Crop_Mushroom_Block_Red"
    },
    {
      "x": -1,
      "y": 25,
      "z": -3,
      "name": "Plant_Crop_Mushroom_Block_Red"
    },
    {
      "x": -1,
      "y": 3,
      "z": -2,
      "name": "Plant_Crop_Mushroom_Block_Red_Trunk"
    },
    {
      "x": -1,
      "y": 4,
      "z": -2,
      "name": "Plant_Crop_Mushroom_Block_Red_Trunk"
    },
    {
      "x": -1,
      "y": 5,
      "z": -2,
      "name": "Plant_Crop_Mushroom_Block_Red_Trunk"
    },
    {
      "x": -1,
      "y": 6,
      "z": -2,
      "name": "Plant_Crop_Mushroom_Block_Red_Trunk"
    },
    {
      "x": -1,
      "y": 7,
      "z": -2,
      "name": "Plant_Crop_Mushroom_Block_Red_Trunk"
    },
    {
      "x": -1,
      "y": 8,
      "z": -2,
      "name": "Plant_Crop_Mushroom_Block_Red_Trunk"
    },
    {
      "x": -1,
      "y": 9,
      "z": -2,
      "name": "Plant_Crop_Mushroom_Block_Red_Trunk"
    },
    {
      "x": -1,
      "y": 10,
      "z": -2,
      "name": "Plant_Crop_Mushroom_Block_Red_Trunk"
    },
    {
      "x": -1,
      "y": 11,
      "z": -2,
      "name": "Plant_Crop_Mushroom_Block_Red_Trunk"
    },
    {
      "x": -1,
      "y": 12,
      "z": -2,
      "name": "Plant_Crop_Mushroom_Block_Red_Trunk"
    },
    {
      "x": -1,
      "y": 13,
      "z": -2,
      "name": "Plant_Crop_Mushroom_Block_Red_Trunk"
    },
    {
      "x": -1,
      "y": 14,
      "z": -2,
      "name": "Plant_Crop_Mushroom_Block_Red_Trunk"
    },
    {
      "x": -1,
      "y": 25,
      "z": -2,
      "name": "Plant_Crop_Mushroom_Block_Red"
    },
    {
      "x": -1,
      "y": 26,
      "z": -2,
      "name": "Plant_Crop_Mushroom_Block_Red"
    },
    {
      "x": -1,
      "y": 5,
      "z": -1,
      "name": "Plant_Crop_Mushroom_Block_Red_Trunk"
    },
    {
      "x": -1,
      "y": 6,
      "z": -1,
      "name": "Plant_Crop_Mushroom_Block_Red_Trunk"
    },
    {
      "x": -1,
      "y": 7,
      "z": -1,
      "name": "Plant_Crop_Mushroom_Block_Red_Trunk"
    },
    {
      "x": -1,
      "y": 8,
      "z": -1,
      "name": "Plant_Crop_Mushroom_Block_Red_Trunk"
    },
    {
      "x": -1,
      "y": 9,
      "z": -1,
      "name": "Plant_Crop_Mushroom_Block_Red_Trunk"
    },
    {
      "x": -1,
      "y": 10,
      "z": -1,
      "name": "Plant_Crop_Mushroom_Block_Red_Trunk"
    },
    {
      "x": -1,
      "y": 11,
      "z": -1,
      "name": "Plant_Crop_Mushroom_Block_Red_Trunk"
    },
    {
      "x": -1,
      "y": 12,
      "z": -1,
      "name": "Plant_Crop_Mushroom_Block_Red_Trunk"
    },
    {
      "x": -1,
      "y": 13,
      "z": -1,
      "name": "Plant_Crop_Mushroom_Block_Red_Trunk"
    },
    {
      "x": -1,
      "y": 14,
      "z": -1,
      "name": "Plant_Crop_Mushroom_Block_Red_Trunk"
    },
    {
      "x": -1,
      "y": 15,
      "z": -1,
      "name": "Plant_Crop_Mushroom_Block_Red_Trunk"
    },
    {
      "x": -1,
      "y": 16,
      "z": -1,
      "name": "Plant_Crop_Mushroom_Block_Red_Trunk"
    },
    {
      "x": -1,
      "y": 17,
      "z": -1,
      "name": "Plant_Crop_Mushroom_Block_Red_Trunk"
    },
    {
      "x": -1,
      "y": 18,
      "z": -1,
      "name": "Plant_Crop_Mushroom_Block_Red_Trunk"
    },
    {
      "x": -1,
      "y": 19,
      "z": -1,
      "name": "Plant_Crop_Mushroom_Block_Red_Trunk"
    },
    {
      "x": -1,
      "y": 20,
      "z": -1,
      "name": "Plant_Crop_Mushroom_Block_Red_Trunk"
    },
    {
      "x": -1,
      "y": 26,
      "z": -1,
      "name": "Plant_Crop_Mushroom_Block_Red"
    },
    {
      "x": -1,
      "y": 27,
      "z": -1,
      "name": "Plant_Crop_Mushroom_Block_Red"
    },
    {
      "x": -1,
      "y": 5,
      "z": 0,
      "name": "Plant_Crop_Mushroom_Block_Red_Trunk"
    },
    {
      "x": -1,
      "y": 6,
      "z": 0,
      "name": "Plant_Crop_Mushroom_Block_Red_Trunk"
    },
    {
      "x": -1,
      "y": 7,
      "z": 0,
      "name": "Plant_Crop_Mushroom_Block_Red_Trunk"
    },
    {
      "x": -1,
      "y": 8,
      "z": 0,
      "name": "Plant_Crop_Mushroom_Block_Red_Trunk"
    },
    {
      "x": -1,
      "y": 9,
      "z": 0,
      "name": "Plant_Crop_Mushroom_Block_Red_Trunk"
    },
    {
      "x": -1,
      "y": 10,
      "z": 0,
      "name": "Plant_Crop_Mushroom_Block_Red_Trunk"
    },
    {
      "x": -1,
      "y": 11,
      "z": 0,
      "name": "Plant_Crop_Mushroom_Block_Red_Trunk"
    },
    {
      "x": -1,
      "y": 12,
      "z": 0,
      "name": "Plant_Crop_Mushroom_Block_Red_Trunk"
    },
    {
      "x": -1,
      "y": 13,
      "z": 0,
      "name": "Plant_Crop_Mushroom_Block_Red_Trunk"
    },
    {
      "x": -1,
      "y": 14,
      "z": 0,
      "name": "Plant_Crop_Mushroom_Block_Red_Trunk"
    },
    {
      "x": -1,
      "y": 15,
      "z": 0,
      "name": "Plant_Crop_Mushroom_Block_Red_Trunk"
    },
    {
      "x": -1,
      "y": 16,
      "z": 0,
      "name": "Plant_Crop_Mushroom_Block_Red_Trunk"
    },
    {
      "x": -1,
      "y": 17,
      "z": 0,
      "name": "Plant_Crop_Mushroom_Block_Red_Trunk"
    },
    {
      "x": -1,
      "y": 18,
      "z": 0,
      "name": "Plant_Crop_Mushroom_Block_Red_Trunk"
    },
    {
      "x": -1,
      "y": 19,
      "z": 0,
      "name": "Plant_Crop_Mushroom_Block_Red_Trunk"
    },
    {
      "x": -1,
      "y": 20,
      "z": 0,
      "name": "Plant_Crop_Mushroom_Block_Red_Trunk"
    },
    {
      "x": -1,
      "y": 21,
      "z": 0,
      "name": "Plant_Crop_Mushroom_Block_Red_Trunk"
    },
    {
      "x": -1,
      "y": 22,
      "z": 0,
      "name": "Plant_Crop_Mushroom_Block_Red_Trunk"
    },
    {
      "x": -1,
      "y": 23,
      "z": 0,
      "name": "Plant_Crop_Mushroom_Block_Red_Trunk"
    },
    {
      "x": -1,
      "y": 24,
      "z": 0,
      "name": "Plant_Crop_Mushroom_Block_Red_Trunk"
    },
    {
      "x": -1,
      "y": 27,
      "z": 0,
      "name": "Plant_Crop_Mushroom_Block_Red"
    },
    {
      "x": -1,
      "y": 6,
      "z": 1,
      "name": "Plant_Crop_Mushroom_Block_Red_Trunk"
    },
    {
      "x": -1,
      "y": 7,
      "z": 1,
      "name": "Plant_Crop_Mushroom_Block_Red_Trunk"
    },
    {
      "x": -1,
      "y": 8,
      "z": 1,
      "name": "Plant_Crop_Mushroom_Block_Red_Trunk"
    },
    {
      "x": -1,
      "y": 9,
      "z": 1,
      "name": "Plant_Crop_Mushroom_Block_Red_Trunk"
    },
    {
      "x": -1,
      "y": 10,
      "z": 1,
      "name": "Plant_Crop_Mushroom_Block_Red_Trunk"
    },
    {
      "x": -1,
      "y": 11,
      "z": 1,
      "name": "Plant_Crop_Mushroom_Block_Red_Trunk"
    },
    {
      "x": -1,
      "y": 12,
      "z": 1,
      "name": "Plant_Crop_Mushroom_Block_Red_Trunk"
    },
    {
      "x": -1,
      "y": 13,
      "z": 1,
      "name": "Plant_Crop_Mushroom_Block_Red_Trunk"
    },
    {
      "x": -1,
      "y": 14,
      "z": 1,
      "name": "Plant_Crop_Mushroom_Block_Red_Trunk"
    },
    {
      "x": -1,
      "y": 15,
      "z": 1,
      "name": "Plant_Crop_Mushroom_Block_Red_Trunk"
    },
    {
      "x": -1,
      "y": 16,
      "z": 1,
      "name": "Plant_Crop_Mushroom_Block_Red_Trunk"
    },
    {
      "x": -1,
      "y": 17,
      "z": 1,
      "name": "Plant_Crop_Mushroom_Block_Red_Trunk"
    },
    {
      "x": -1,
      "y": 18,
      "z": 1,
      "name": "Plant_Crop_Mushroom_Block_Red_Trunk"
    },
    {
      "x": -1,
      "y": 19,
      "z": 1,
      "name": "Plant_Crop_Mushroom_Block_Red_Trunk"
    },
    {
      "x": -1,
      "y": 20,
      "z": 1,
      "name": "Plant_Crop_Mushroom_Block_Red_Trunk"
    },
    {
      "x": -1,
      "y": 21,
      "z": 1,
      "name": "Plant_Crop_Mushroom_Block_Red_Trunk"
    },
    {
      "x": -1,
      "y": 22,
      "z": 1,
      "name": "Plant_Crop_Mushroom_Block_Red_Trunk"
    },
    {
      "x": -1,
      "y": 23,
      "z": 1,
      "name": "Plant_Crop_Mushroom_Block_Red_Trunk"
    },
    {
      "x": -1,
      "y": 24,
      "z": 1,
      "name": "Plant_Crop_Mushroom_Block_Red_Trunk"
    },
    {
      "x": -1,
      "y": 25,
      "z": 1,
      "name": "Plant_Crop_Mushroom_Block_Red_Trunk"
    },
    {
      "x": -1,
      "y": 26,
      "z": 1,
      "name": "Plant_Crop_Mushroom_Block_Red_Trunk"
    },
    {
      "x": -1,
      "y": 27,
      "z": 1,
      "name": "Plant_Crop_Mushroom_Block_Red"
    },
    {
      "x": -1,
      "y": 10,
      "z": 2,
      "name": "Plant_Crop_Mushroom_Block_Red_Trunk"
    },
    {
      "x": -1,
      "y": 11,
      "z": 2,
      "name": "Plant_Crop_Mushroom_Block_Red_Trunk"
    },
    {
      "x": -1,
      "y": 12,
      "z": 2,
      "name": "Plant_Crop_Mushroom_Block_Red_Trunk"
    },
    {
      "x": -1,
      "y": 13,
      "z": 2,
      "name": "Plant_Crop_Mushroom_Block_Red_Trunk"
    },
    {
      "x": -1,
      "y": 14,
      "z": 2,
      "name": "Plant_Crop_Mushroom_Block_Red_Trunk"
    },
    {
      "x": -1,
      "y": 15,
      "z": 2,
      "name": "Plant_Crop_Mushroom_Block_Red_Trunk"
    },
    {
      "x": -1,
      "y": 16,
      "z": 2,
      "name": "Plant_Crop_Mushroom_Block_Red_Trunk"
    },
    {
      "x": -1,
      "y": 17,
      "z": 2,
      "name": "Plant_Crop_Mushroom_Block_Red_Trunk"
    },
    {
      "x": -1,
      "y": 18,
      "z": 2,
      "name": "Plant_Crop_Mushroom_Block_Red_Trunk"
    },
    {
      "x": -1,
      "y": 19,
      "z": 2,
      "name": "Plant_Crop_Mushroom_Block_Red_Trunk"
    },
    {
      "x": -1,
      "y": 20,
      "z": 2,
      "name": "Plant_Crop_Mushroom_Block_Red_Trunk"
    },
    {
      "x": -1,
      "y": 21,
      "z": 2,
      "name": "Plant_Crop_Mushroom_Block_Red_Trunk"
    },
    {
      "x": -1,
      "y": 22,
      "z": 2,
      "name": "Plant_Crop_Mushroom_Block_Red_Trunk"
    },
    {
      "x": -1,
      "y": 23,
      "z": 2,
      "name": "Plant_Crop_Mushroom_Block_Red_Trunk"
    },
    {
      "x": -1,
      "y": 24,
      "z": 2,
      "name": "Plant_Crop_Mushroom_Block_Red_Trunk"
    },
    {
      "x": -1,
      "y": 25,
      "z": 2,
      "name": "Plant_Crop_Mushroom_Block_Red_Trunk"
    },
    {
      "x": -1,
      "y": 26,
      "z": 2,
      "name": "Plant_Crop_Mushroom_Block_Red_Trunk"
    },
    {
      "x": -1,
      "y": 27,
      "z": 2,
      "name": "Plant_Crop_Mushroom_Block_Red"
    },
    {
      "x": -1,
      "y": 13,
      "z": 3,
      "name": "Plant_Crop_Mushroom_Block_Red_Trunk"
    },
    {
      "x": -1,
      "y": 14,
      "z": 3,
      "name": "Plant_Crop_Mushroom_Block_Red_Trunk"
    },
    {
      "x": -1,
      "y": 15,
      "z": 3,
      "name": "Plant_Crop_Mushroom_Block_Red_Trunk"
    },
    {
      "x": -1,
      "y": 16,
      "z": 3,
      "name": "Plant_Crop_Mushroom_Block_Red_Trunk"
    },
    {
      "x": -1,
      "y": 17,
      "z": 3,
      "name": "Plant_Crop_Mushroom_Block_Red_Trunk"
    },
    {
      "x": -1,
      "y": 18,
      "z": 3,
      "name": "Plant_Crop_Mushroom_Block_Red_Trunk"
    },
    {
      "x": -1,
      "y": 19,
      "z": 3,
      "name": "Plant_Crop_Mushroom_Block_Red_Trunk"
    },
    {
      "x": -1,
      "y": 20,
      "z": 3,
      "name": "Plant_Crop_Mushroom_Block_Red_Trunk"
    },
    {
      "x": -1,
      "y": 21,
      "z": 3,
      "name": "Plant_Crop_Mushroom_Block_Red_Trunk"
    },
    {
      "x": -1,
      "y": 22,
      "z": 3,
      "name": "Plant_Crop_Mushroom_Block_Red_Trunk"
    },
    {
      "x": -1,
      "y": 23,
      "z": 3,
      "name": "Plant_Crop_Mushroom_Block_Red_Trunk"
    },
    {
      "x": -1,
      "y": 27,
      "z": 3,
      "name": "Plant_Crop_Mushroom_Block_Red"
    },
    {
      "x": -1,
      "y": 17,
      "z": 4,
      "name": "Plant_Crop_Mushroom_Block_Red_Trunk"
    },
    {
      "x": -1,
      "y": 18,
      "z": 4,
      "name": "Plant_Crop_Mushroom_Block_Red_Trunk"
    },
    {
      "x": -1,
      "y": 27,
      "z": 4,
      "name": "Plant_Crop_Mushroom_Block_Red"
    },
    {
      "x": -1,
      "y": 25,
      "z": 5,
      "name": "Plant_Crop_Mushroom_Block_Red_Mycelium"
    },
    {
      "x": -1,
      "y": 26,
      "z": 5,
      "name": "Plant_Crop_Mushroom_Block_Red"
    },
    {
      "x": -1,
      "y": 24,
      "z": 6,
      "name": "Plant_Crop_Mushroom_Block_Red"
    },
    {
      "x": -1,
      "y": 25,
      "z": 6,
      "name": "Plant_Crop_Mushroom_Block_Red"
    },
    {
      "x": -1,
      "y": 22,
      "z": 7,
      "name": "Plant_Crop_Mushroom_Block_Red"
    },
    {
      "x": -1,
      "y": 23,
      "z": 7,
      "name": "Plant_Crop_Mushroom_Block_Red"
    },
    {
      "x": -1,
      "y": 18,
      "z": 8,
      "name": "Plant_Crop_Mushroom_Block_Red"
    },
    {
      "x": -1,
      "y": 19,
      "z": 8,
      "name": "Plant_Crop_Mushroom_Block_Red"
    },
    {
      "x": -1,
      "y": 20,
      "z": 8,
      "name": "Plant_Crop_Mushroom_Block_Red"
    },
    {
      "x": -1,
      "y": 21,
      "z": 8,
      "name": "Plant_Crop_Mushroom_Block_Red"
    },
    {
      "x": -1,
      "y": 14,
      "z": 9,
      "name": "Plant_Crop_Mushroom_Block_Red"
    },
    {
      "x": -1,
      "y": 15,
      "z": 9,
      "name": "Plant_Crop_Mushroom_Block_Red"
    },
    {
      "x": -1,
      "y": 16,
      "z": 9,
      "name": "Plant_Crop_Mushroom_Block_Red"
    },
    {
      "x": -1,
      "y": 17,
      "z": 9,
      "name": "Plant_Crop_Mushroom_Block_Red"
    },
    {
      "x": 0,
      "y": 11,
      "z": -7,
      "name": "Plant_Crop_Mushroom_Block_Red"
    },
    {
      "x": 0,
      "y": 11,
      "z": -6,
      "name": "Plant_Crop_Mushroom_Block_Red"
    },
    {
      "x": 0,
      "y": 12,
      "z": -6,
      "name": "Plant_Crop_Mushroom_Block_Red"
    },
    {
      "x": 0,
      "y": 13,
      "z": -6,
      "name": "Plant_Crop_Mushroom_Block_Red"
    },
    {
      "x": 0,
      "y": 14,
      "z": -6,
      "name": "Plant_Crop_Mushroom_Block_Red"
    },
    {
      "x": 0,
      "y": 15,
      "z": -6,
      "name": "Plant_Crop_Mushroom_Block_Red"
    },
    {
      "x": 0,
      "y": 16,
      "z": -6,
      "name": "Plant_Crop_Mushroom_Block_Red"
    },
    {
      "x": 0,
      "y": 17,
      "z": -5,
      "name": "Plant_Crop_Mushroom_Block_Red"
    },
    {
      "x": 0,
      "y": 18,
      "z": -5,
      "name": "Plant_Crop_Mushroom_Block_Red"
    },
    {
      "x": 0,
      "y": 19,
      "z": -5,
      "name": "Plant_Crop_Mushroom_Block_Red"
    },
    {
      "x": 0,
      "y": 20,
      "z": -4,
      "name": "Plant_Crop_Mushroom_Block_Red"
    },
    {
      "x": 0,
      "y": 7,
      "z": -3,
      "name": "Plant_Crop_Mushroom_Block_Red_Trunk"
    },
    {
      "x": 0,
      "y": 8,
      "z": -3,
      "name": "Plant_Crop_Mushroom_Block_Red_Trunk"
    },
    {
      "x": 0,
      "y": 9,
      "z": -3,
      "name": "Plant_Crop_Mushroom_Block_Red_Trunk"
    },
    {
      "x": 0,
      "y": 10,
      "z": -3,
      "name": "Plant_Crop_Mushroom_Block_Red_Trunk"
    },
    {
      "x": 0,
      "y": 20,
      "z": -3,
      "name": "Plant_Crop_Mushroom_Block_Red_Mycelium"
    },
    {
      "x": 0,
      "y": 21,
      "z": -3,
      "name": "Plant_Crop_Mushroom_Block_Red"
    },
    {
      "x": 0,
      "y": 22,
      "z": -3,
      "name": "Plant_Crop_Mushroom_Block_Red"
    },
    {
      "x": 0,
      "y": 23,
      "z": -3,
      "name": "Plant_Crop_Mushroom_Block_Red"
    },
    {
      "x": 0,
      "y": 24,
      "z": -3,
      "name": "Plant_Crop_Mushroom_Block_Red"
    },
    {
      "x": 0,
      "y": 25,
      "z": -3,
      "name": "Plant_Crop_Mushroom_Block_Red"
    },
    {
      "x": 0,
      "y": 6,
      "z": -2,
      "name": "Plant_Crop_Mushroom_Block_Red_Trunk"
    },
    {
      "x": 0,
      "y": 7,
      "z": -2,
      "name": "Plant_Crop_Mushroom_Block_Red_Trunk"
    },
    {
      "x": 0,
      "y": 8,
      "z": -2,
      "name": "Plant_Crop_Mushroom_Block_Red_Trunk"
    },
    {
      "x": 0,
      "y": 9,
      "z": -2,
      "name": "Plant_Crop_Mushroom_Block_Red_Trunk"
    },
    {
      "x": 0,
      "y": 10,
      "z": -2,
      "name": "Plant_Crop_Mushroom_Block_Red_Trunk"
    },
    {
      "x": 0,
      "y": 11,
      "z": -2,
      "name": "Plant_Crop_Mushroom_Block_Red_Trunk"
    },
    {
      "x": 0,
      "y": 12,
      "z": -2,
      "name": "Plant_Crop_Mushroom_Block_Red_Trunk"
    },
    {
      "x": 0,
      "y": 13,
      "z": -2,
      "name": "Plant_Crop_Mushroom_Block_Red_Trunk"
    },
    {
      "x": 0,
      "y": 24,
      "z": -2,
      "name": "Rock_Crystal_Red_Small",
      "components": {
        "Components": {
          "FarmingBlock": {}
        }
      },
      "rotation": 8
    },
    {
      "x": 0,
      "y": 25,
      "z": -2,
      "name": "Plant_Crop_Mushroom_Block_Red"
    },
    {
      "x": 0,
      "y": 6,
      "z": -1,
      "name": "Plant_Crop_Mushroom_Block_Red_Trunk"
    },
    {
      "x": 0,
      "y": 7,
      "z": -1,
      "name": "Plant_Crop_Mushroom_Block_Red_Trunk"
    },
    {
      "x": 0,
      "y": 8,
      "z": -1,
      "name": "Plant_Crop_Mushroom_Block_Red_Trunk"
    },
    {
      "x": 0,
      "y": 9,
      "z": -1,
      "name": "Plant_Crop_Mushroom_Block_Red_Trunk"
    },
    {
      "x": 0,
      "y": 10,
      "z": -1,
      "name": "Plant_Crop_Mushroom_Block_Red_Trunk"
    },
    {
      "x": 0,
      "y": 11,
      "z": -1,
      "name": "Plant_Crop_Mushroom_Block_Red_Trunk"
    },
    {
      "x": 0,
      "y": 12,
      "z": -1,
      "name": "Plant_Crop_Mushroom_Block_Red_Trunk"
    },
    {
      "x": 0,
      "y": 13,
      "z": -1,
      "name": "Plant_Crop_Mushroom_Block_Red_Trunk"
    },
    {
      "x": 0,
      "y": 14,
      "z": -1,
      "name": "Plant_Crop_Mushroom_Block_Red_Trunk"
    },
    {
      "x": 0,
      "y": 15,
      "z": -1,
      "name": "Plant_Crop_Mushroom_Block_Red_Trunk"
    },
    {
      "x": 0,
      "y": 16,
      "z": -1,
      "name": "Plant_Crop_Mushroom_Block_Red_Trunk"
    },
    {
      "x": 0,
      "y": 17,
      "z": -1,
      "name": "Plant_Crop_Mushroom_Block_Red_Trunk"
    },
    {
      "x": 0,
      "y": 18,
      "z": -1,
      "name": "Plant_Crop_Mushroom_Block_Red_Trunk"
    },
    {
      "x": 0,
      "y": 19,
      "z": -1,
      "name": "Plant_Crop_Mushroom_Block_Red_Trunk"
    },
    {
      "x": 0,
      "y": 20,
      "z": -1,
      "name": "Plant_Crop_Mushroom_Block_Red_Trunk"
    },
    {
      "x": 0,
      "y": 25,
      "z": -1,
      "name": "Rock_Crystal_Red_Small",
      "components": {
        "Components": {
          "FarmingBlock": {}
        }
      },
      "rotation": 8
    },
    {
      "x": 0,
      "y": 26,
      "z": -1,
      "name": "Plant_Crop_Mushroom_Block_Red"
    },
    {
      "x": 0,
      "y": 27,
      "z": -1,
      "name": "Plant_Crop_Mushroom_Block_Red"
    },
    {
      "x": 0,
      "y": 7,
      "z": 0,
      "name": "Plant_Crop_Mushroom_Block_Red_Trunk"
    },
    {
      "x": 0,
      "y": 8,
      "z": 0,
      "name": "Plant_Crop_Mushroom_Block_Red_Trunk"
    },
    {
      "x": 0,
      "y": 9,
      "z": 0,
      "name": "Plant_Crop_Mushroom_Block_Red_Trunk"
    },
    {
      "x": 0,
      "y": 10,
      "z": 0,
      "name": "Plant_Crop_Mushroom_Block_Red_Trunk"
    },
    {
      "x": 0,
      "y": 11,
      "z": 0,
      "name": "Plant_Crop_Mushroom_Block_Red_Trunk"
    },
    {
      "x": 0,
      "y": 12,
      "z": 0,
      "name": "Plant_Crop_Mushroom_Block_Red_Trunk"
    },
    {
      "x": 0,
      "y": 13,
      "z": 0,
      "name": "Plant_Crop_Mushroom_Block_Red_Trunk"
    },
    {
      "x": 0,
      "y": 14,
      "z": 0,
      "name": "Plant_Crop_Mushroom_Block_Red_Trunk"
    },
    {
      "x": 0,
      "y": 15,
      "z": 0,
      "name": "Plant_Crop_Mushroom_Block_Red_Trunk"
    },
    {
      "x": 0,
      "y": 16,
      "z": 0,
      "name": "Plant_Crop_Mushroom_Block_Red_Trunk"
    },
    {
      "x": 0,
      "y": 17,
      "z": 0,
      "name": "Plant_Crop_Mushroom_Block_Red_Trunk"
    },
    {
      "x": 0,
      "y": 18,
      "z": 0,
      "name": "Plant_Crop_Mushroom_Block_Red_Trunk"
    },
    {
      "x": 0,
      "y": 19,
      "z": 0,
      "name": "Plant_Crop_Mushroom_Block_Red_Trunk"
    },
    {
      "x": 0,
      "y": 20,
      "z": 0,
      "name": "Plant_Crop_Mushroom_Block_Red_Trunk"
    },
    {
      "x": 0,
      "y": 21,
      "z": 0,
      "name": "Plant_Crop_Mushroom_Block_Red_Trunk"
    },
    {
      "x": 0,
      "y": 22,
      "z": 0,
      "name": "Plant_Crop_Mushroom_Block_Red_Trunk"
    },
    {
      "x": 0,
      "y": 23,
      "z": 0,
      "name": "Plant_Crop_Mushroom_Block_Red_Trunk"
    },
    {
      "x": 0,
      "y": 24,
      "z": 0,
      "name": "Plant_Crop_Mushroom_Block_Red_Trunk"
    },
    {
      "x": 0,
      "y": 25,
      "z": 0,
      "name": "Plant_Crop_Mushroom_Block_Red_Trunk"
    },
    {
      "x": 0,
      "y": 27,
      "z": 0,
      "name": "Plant_Crop_Mushroom_Block_Red"
    },
    {
      "x": 0,
      "y": 8,
      "z": 1,
      "name": "Plant_Crop_Mushroom_Block_Red_Trunk"
    },
    {
      "x": 0,
      "y": 9,
      "z": 1,
      "name": "Plant_Crop_Mushroom_Block_Red_Trunk"
    },
    {
      "x": 0,
      "y": 10,
      "z": 1,
      "name": "Plant_Crop_Mushroom_Block_Red_Trunk"
    },
    {
      "x": 0,
      "y": 11,
      "z": 1,
      "name": "Plant_Crop_Mushroom_Block_Red_Trunk"
    },
    {
      "x": 0,
      "y": 12,
      "z": 1,
      "name": "Plant_Crop_Mushroom_Block_Red_Trunk"
    },
    {
      "x": 0,
      "y": 13,
      "z": 1,
      "name": "Plant_Crop_Mushroom_Block_Red_Trunk"
    },
    {
      "x": 0,
      "y": 14,
      "z": 1,
      "name": "Plant_Crop_Mushroom_Block_Red_Trunk"
    },
    {
      "x": 0,
      "y": 15,
      "z": 1,
      "name": "Plant_Crop_Mushroom_Block_Red_Trunk"
    },
    {
      "x": 0,
      "y": 16,
      "z": 1,
      "name": "Plant_Crop_Mushroom_Block_Red_Trunk"
    },
    {
      "x": 0,
      "y": 17,
      "z": 1,
      "name": "Plant_Crop_Mushroom_Block_Red_Trunk"
    },
    {
      "x": 0,
      "y": 18,
      "z": 1,
      "name": "Plant_Crop_Mushroom_Block_Red_Trunk"
    },
    {
      "x": 0,
      "y": 19,
      "z": 1,
      "name": "Plant_Crop_Mushroom_Block_Red_Trunk"
    },
    {
      "x": 0,
      "y": 20,
      "z": 1,
      "name": "Plant_Crop_Mushroom_Block_Red_Trunk"
    },
    {
      "x": 0,
      "y": 21,
      "z": 1,
      "name": "Plant_Crop_Mushroom_Block_Red_Trunk"
    },
    {
      "x": 0,
      "y": 22,
      "z": 1,
      "name": "Plant_Crop_Mushroom_Block_Red_Trunk"
    },
    {
      "x": 0,
      "y": 23,
      "z": 1,
      "name": "Plant_Crop_Mushroom_Block_Red_Trunk"
    },
    {
      "x": 0,
      "y": 24,
      "z": 1,
      "name": "Plant_Crop_Mushroom_Block_Red_Trunk"
    },
    {
      "x": 0,
      "y": 25,
      "z": 1,
      "name": "Plant_Crop_Mushroom_Block_Red_Trunk"
    },
    {
      "x": 0,
      "y": 26,
      "z": 1,
      "name": "Plant_Crop_Mushroom_Block_Red_Trunk"
    },
    {
      "x": 0,
      "y": 27,
      "z": 1,
      "name": "Plant_Crop_Mushroom_Block_Red"
    },
    {
      "x": 0,
      "y": 12,
      "z": 2,
      "name": "Plant_Crop_Mushroom_Block_Red_Trunk"
    },
    {
      "x": 0,
      "y": 13,
      "z": 2,
      "name": "Plant_Crop_Mushroom_Block_Red_Trunk"
    },
    {
      "x": 0,
      "y": 14,
      "z": 2,
      "name": "Plant_Crop_Mushroom_Block_Red_Trunk"
    },
    {
      "x": 0,
      "y": 15,
      "z": 2,
      "name": "Plant_Crop_Mushroom_Block_Red_Trunk"
    },
    {
      "x": 0,
      "y": 16,
      "z": 2,
      "name": "Plant_Crop_Mushroom_Block_Red_Trunk"
    },
    {
      "x": 0,
      "y": 17,
      "z": 2,
      "name": "Plant_Crop_Mushroom_Block_Red_Trunk"
    },
    {
      "x": 0,
      "y": 18,
      "z": 2,
      "name": "Plant_Crop_Mushroom_Block_Red_Trunk"
    },
    {
      "x": 0,
      "y": 19,
      "z": 2,
      "name": "Plant_Crop_Mushroom_Block_Red_Trunk"
    },
    {
      "x": 0,
      "y": 20,
      "z": 2,
      "name": "Plant_Crop_Mushroom_Block_Red_Trunk"
    },
    {
      "x": 0,
      "y": 21,
      "z": 2,
      "name": "Plant_Crop_Mushroom_Block_Red_Trunk"
    },
    {
      "x": 0,
      "y": 22,
      "z": 2,
      "name": "Plant_Crop_Mushroom_Block_Red_Trunk"
    },
    {
      "x": 0,
      "y": 23,
      "z": 2,
      "name": "Plant_Crop_Mushroom_Block_Red_Trunk"
    },
    {
      "x": 0,
      "y": 24,
      "z": 2,
      "name": "Plant_Crop_Mushroom_Block_Red_Trunk"
    },
    {
      "x": 0,
      "y": 25,
      "z": 2,
      "name": "Plant_Crop_Mushroom_Block_Red_Trunk"
    },
    {
      "x": 0,
      "y": 26,
      "z": 2,
      "name": "Plant_Crop_Mushroom_Block_Red_Trunk"
    },
    {
      "x": 0,
      "y": 27,
      "z": 2,
      "name": "Plant_Crop_Mushroom_Block_Red"
    },
    {
      "x": 0,
      "y": 14,
      "z": 3,
      "name": "Plant_Crop_Mushroom_Block_Red_Trunk"
    },
    {
      "x": 0,
      "y": 15,
      "z": 3,
      "name": "Plant_Crop_Mushroom_Block_Red_Trunk"
    },
    {
      "x": 0,
      "y": 16,
      "z": 3,
      "name": "Plant_Crop_Mushroom_Block_Red_Trunk"
    },
    {
      "x": 0,
      "y": 17,
      "z": 3,
      "name": "Plant_Crop_Mushroom_Block_Red_Trunk"
    },
    {
      "x": 0,
      "y": 18,
      "z": 3,
      "name": "Plant_Crop_Mushroom_Block_Red_Trunk"
    },
    {
      "x": 0,
      "y": 19,
      "z": 3,
      "name": "Plant_Crop_Mushroom_Block_Red_Trunk"
    },
    {
      "x": 0,
      "y": 20,
      "z": 3,
      "name": "Plant_Crop_Mushroom_Block_Red_Trunk"
    },
    {
      "x": 0,
      "y": 21,
      "z": 3,
      "name": "Plant_Crop_Mushroom_Block_Red_Trunk"
    },
    {
      "x": 0,
      "y": 27,
      "z": 3,
      "name": "Plant_Crop_Mushroom_Block_Red"
    },
    {
      "x": 0,
      "y": 19,
      "z": 4,
      "name": "Plant_Crop_Mushroom_Block_Red_Trunk"
    },
    {
      "x": 0,
      "y": 26,
      "z": 4,
      "name": "Plant_Crop_Mushroom_Block_Red"
    },
    {
      "x": 0,
      "y": 24,
      "z": 5,
      "name": "Plant_Crop_Mushroom_Block_Red_Mycelium"
    },
    {
      "x": 0,
      "y": 25,
      "z": 5,
      "name": "Plant_Crop_Mushroom_Block_Red"
    },
    {
      "x": 0,
      "y": 26,
      "z": 5,
      "name": "Plant_Crop_Mushroom_Block_Red"
    },
    {
      "x": 0,
      "y": 24,
      "z": 6,
      "name": "Plant_Crop_Mushroom_Block_Red"
    },
    {
      "x": 0,
      "y": 19,
      "z": 7,
      "name": "Plant_Crop_Mushroom_Block_Red_Mycelium"
    },
    {
      "x": 0,
      "y": 20,
      "z": 7,
      "name": "Plant_Crop_Mushroom_Block_Red"
    },
    {
      "x": 0,
      "y": 21,
      "z": 7,
      "name": "Plant_Crop_Mushroom_Block_Red"
    },
    {
      "x": 0,
      "y": 22,
      "z": 7,
      "name": "Plant_Crop_Mushroom_Block_Red"
    },
    {
      "x": 0,
      "y": 23,
      "z": 7,
      "name": "Plant_Crop_Mushroom_Block_Red"
    },
    {
      "x": 0,
      "y": 18,
      "z": 8,
      "name": "Plant_Crop_Mushroom_Block_Red"
    },
    {
      "x": 0,
      "y": 19,
      "z": 8,
      "name": "Plant_Crop_Mushroom_Block_Red"
    },
    {
      "x": 0,
      "y": 14,
      "z": 9,
      "name": "Plant_Crop_Mushroom_Block_Red"
    },
    {
      "x": 0,
      "y": 15,
      "z": 9,
      "name": "Plant_Crop_Mushroom_Block_Red"
    },
    {
      "x": 0,
      "y": 16,
      "z": 9,
      "name": "Plant_Crop_Mushroom_Block_Red"
    },
    {
      "x": 0,
      "y": 17,
      "z": 9,
      "name": "Plant_Crop_Mushroom_Block_Red"
    },
    {
      "x": 1,
      "y": 11,
      "z": -6,
      "name": "Plant_Crop_Mushroom_Block_Red"
    },
    {
      "x": 1,
      "y": 12,
      "z": -6,
      "name": "Plant_Crop_Mushroom_Block_Red"
    },
    {
      "x": 1,
      "y": 13,
      "z": -6,
      "name": "Plant_Crop_Mushroom_Block_Red"
    },
    {
      "x": 1,
      "y": 14,
      "z": -6,
      "name": "Plant_Crop_Mushroom_Block_Red"
    },
    {
      "x": 1,
      "y": 15,
      "z": -6,
      "name": "Plant_Crop_Mushroom_Block_Red"
    },
    {
      "x": 1,
      "y": 16,
      "z": -6,
      "name": "Plant_Crop_Mushroom_Block_Red"
    },
    {
      "x": 1,
      "y": 17,
      "z": -5,
      "name": "Plant_Crop_Mushroom_Block_Red"
    },
    {
      "x": 1,
      "y": 18,
      "z": -5,
      "name": "Plant_Crop_Mushroom_Block_Red"
    },
    {
      "x": 1,
      "y": 19,
      "z": -4,
      "name": "Plant_Crop_Mushroom_Block_Red"
    },
    {
      "x": 1,
      "y": 20,
      "z": -4,
      "name": "Plant_Crop_Mushroom_Block_Red"
    },
    {
      "x": 1,
      "y": 20,
      "z": -3,
      "name": "Plant_Crop_Mushroom_Block_Red_Mycelium"
    },
    {
      "x": 1,
      "y": 21,
      "z": -3,
      "name": "Plant_Crop_Mushroom_Block_Red"
    },
    {
      "x": 1,
      "y": 22,
      "z": -3,
      "name": "Plant_Crop_Mushroom_Block_Red"
    },
    {
      "x": 1,
      "y": 23,
      "z": -3,
      "name": "Plant_Crop_Mushroom_Block_Red"
    },
    {
      "x": 1,
      "y": 24,
      "z": -3,
      "name": "Plant_Crop_Mushroom_Block_Red"
    },
    {
      "x": 1,
      "y": 25,
      "z": -3,
      "name": "Plant_Crop_Mushroom_Block_Red"
    },
    {
      "x": 1,
      "y": 9,
      "z": -2,
      "name": "Plant_Crop_Mushroom_Block_Red_Trunk"
    },
    {
      "x": 1,
      "y": 10,
      "z": -2,
      "name": "Plant_Crop_Mushroom_Block_Red_Trunk"
    },
    {
      "x": 1,
      "y": 25,
      "z": -2,
      "name": "Plant_Crop_Mushroom_Block_Red"
    },
    {
      "x": 1,
      "y": 8,
      "z": -1,
      "name": "Plant_Crop_Mushroom_Block_Red_Trunk"
    },
    {
      "x": 1,
      "y": 9,
      "z": -1,
      "name": "Plant_Crop_Mushroom_Block_Red_Trunk"
    },
    {
      "x": 1,
      "y": 10,
      "z": -1,
      "name": "Plant_Crop_Mushroom_Block_Red_Trunk"
    },
    {
      "x": 1,
      "y": 11,
      "z": -1,
      "name": "Plant_Crop_Mushroom_Block_Red_Trunk"
    },
    {
      "x": 1,
      "y": 12,
      "z": -1,
      "name": "Plant_Crop_Mushroom_Block_Red_Trunk"
    },
    {
      "x": 1,
      "y": 13,
      "z": -1,
      "name": "Plant_Crop_Mushroom_Block_Red_Trunk"
    },
    {
      "x": 1,
      "y": 14,
      "z": -1,
      "name": "Plant_Crop_Mushroom_Block_Red_Trunk"
    },
    {
      "x": 1,
      "y": 18,
      "z": -1,
      "name": "Plant_Crop_Mushroom_Block_Red_Trunk"
    },
    {
      "x": 1,
      "y": 19,
      "z": -1,
      "name": "Plant_Crop_Mushroom_Block_Red_Trunk"
    },
    {
      "x": 1,
      "y": 25,
      "z": -1,
      "name": "Rock_Crystal_Red_Small",
      "components": {
        "Components": {
          "FarmingBlock": {}
        }
      },
      "rotation": 8
    },
    {
      "x": 1,
      "y": 26,
      "z": -1,
      "name": "Plant_Crop_Mushroom_Block_Red"
    },
    {
      "x": 1,
      "y": 10,
      "z": 0,
      "name": "Plant_Crop_Mushroom_Block_Red_Trunk"
    },
    {
      "x": 1,
      "y": 11,
      "z": 0,
      "name": "Plant_Crop_Mushroom_Block_Red_Trunk"
    },
    {
      "x": 1,
      "y": 12,
      "z": 0,
      "name": "Plant_Crop_Mushroom_Block_Red_Trunk"
    },
    {
      "x": 1,
      "y": 13,
      "z": 0,
      "name": "Plant_Crop_Mushroom_Block_Red_Trunk"
    },
    {
      "x": 1,
      "y": 14,
      "z": 0,
      "name": "Plant_Crop_Mushroom_Block_Red_Trunk"
    },
    {
      "x": 1,
      "y": 15,
      "z": 0,
      "name": "Plant_Crop_Mushroom_Block_Red_Trunk"
    },
    {
      "x": 1,
      "y": 16,
      "z": 0,
      "name": "Plant_Crop_Mushroom_Block_Red_Trunk"
    },
    {
      "x": 1,
      "y": 17,
      "z": 0,
      "name": "Plant_Crop_Mushroom_Block_Red_Trunk"
    },
    {
      "x": 1,
      "y": 18,
      "z": 0,
      "name": "Plant_Crop_Mushroom_Block_Red_Trunk"
    },
    {
      "x": 1,
      "y": 19,
      "z": 0,
      "name": "Plant_Crop_Mushroom_Block_Red_Trunk"
    },
    {
      "x": 1,
      "y": 20,
      "z": 0,
      "name": "Plant_Crop_Mushroom_Block_Red_Trunk"
    },
    {
      "x": 1,
      "y": 21,
      "z": 0,
      "name": "Plant_Crop_Mushroom_Block_Red_Trunk"
    },
    {
      "x": 1,
      "y": 22,
      "z": 0,
      "name": "Plant_Crop_Mushroom_Block_Red_Trunk"
    },
    {
      "x": 1,
      "y": 23,
      "z": 0,
