{
  "version": 8,
  "blockIdVersion": 8,
  "anchorX": 4,
  "anchorY": 14,
  "anchorZ": 1,
  "blocks": [
    {
      "x": 2,
      "y": 10,
      "z": -1,
      "name": "Rock_Sandstone_White"
    },
    {
      "x": 2,
      "y": 11,
      "z": -1,
      "name": "Rock_Sandstone_White"
    },
    {
      "x": 2,
      "y": 12,
      "z": -1,
      "name": "Rock_Sandstone_White"
    },
    {
      "x": 2,
      "y": 13,
      "z": -1,
      "name": "Rock_Sandstone_White"
    },
    {
      "x": 2,
      "y": 14,
      "z": -1,
      "name": "Soil_Sand_White"
    },
    {
      "x": 2,
      "y": 10,
      "z": 0,
      "name": "Rock_Sandstone_White"
    },
    {
      "x": 2,
      "y": 11,
      "z": 0,
      "name": "Rock_Sandstone_White"
    },
    {
      "x": 2,
      "y": 12,
      "z": 0,
      "name": "Rock_Sandstone_White"
    },
    {
      "x": 2,
      "y": 13,
      "z": 0,
      "name": "Rock_Sandstone_White"
    },
    {
      "x": 2,
      "y": 14,
      "z": 0,
      "name": "Rock_Sandstone"
    },
    {
      "x": 2,
      "y": 15,
      "z": 0,
      "name": "Rock_Sandstone_White"
    },
    {
      "x": 2,
      "y": 10,
      "z": 1,
      "name": "Rock_Sandstone_White"
    },
    {
      "x": 2,
      "y": 11,
      "z": 1,
      "name": "Rock_Sandstone_White"
    },
    {
      "x": 2,
      "y": 12,
      "z": 1,
      "name": "Rock_Sandstone_White"
    },
    {
      "x": 2,
      "y": 13,
      "z": 1,
      "name": "Rock_Sandstone_White"
    },
    {
      "x": 2,
      "y": 14,
      "z": 1,
      "name": "Rock_Sandstone"
    },
    {
      "x": 2,
      "y": 15,
      "z": 1,
      "name": "Rock_Sandstone_White"
    },
    {
      "x": 2,
      "y": 11,
      "z": 2,
      "name": "Rock_Sandstone_White"
    },
    {
      "x": 2,
      "y": 12,
      "z": 2,
      "name": "Rock_Sandstone_White"
    },
    {
      "x": 2,
      "y": 13,
      "z": 2,
      "name": "Rock_Sandstone"
    },
    {
      "x": 2,
      "y": 14,
      "z": 2,
      "name": "Rock_Sandstone_White"
    },
    {
      "x": 2,
      "y": 15,
      "z": 2,
      "name": "Rock_Sandstone_White"
    },
    {
      "x": 2,
      "y": 13,
      "z": 3,
      "name": "Rock_Sandstone"
    },
    {
      "x": 2,
      "y": 14,
      "z": 3,
      "name": "Rock_Sandstone_White"
    },
    {
      "x": 2,
      "y": 15,
      "z": 3,
      "name": "Rock_Sandstone_White"
    },
    {
      "x": 3,
      "y": 11,
      "z": -2,
      "name": "Rock_Sandstone_White"
    },
    {
      "x": 3,
      "y": 12,
      "z": -2,
      "name": "Rock_Sandstone_White"
    },
    {
      "x": 3,
      "y": 13,
      "z": -2,
      "name": "Rock_Sandstone_White"
    },
    {
      "x": 3,
      "y": 14,
      "z": -2,
      "name": "Soil_Sand_White"
    },
    {
      "x": 3,
      "y": 10,
      "z": -1,
      "name": "Rock_Sandstone_White"
    },
    {
      "x": 3,
      "y": 11,
      "z": -1,
      "name": "Rock_Sandstone_White"
    },
    {
      "x": 3,
      "y": 12,
      "z": -1,
      "name": "Rock_Sandstone_White"
    },
    {
      "x": 3,
      "y": 13,
      "z": -1,
      "name": "Rock_Sandstone_White"
    },
    {
      "x": 3,
      "y": 14,
      "z": -1,
      "name": "Soil_Sand_White"
    },
    {
      "x": 3,
      "y": 15,
      "z": -1,
      "name": "Soil_Sand_White"
    },
    {
      "x": 3,
      "y": 9,
      "z": 0,
      "name": "Rock_Sandstone_White"
    },
    {
      "x": 3,
      "y": 10,
      "z": 0,
      "name": "Rock_Sandstone_White"
    },
    {
      "x": 3,
      "y": 11,
      "z": 0,
      "name": "Rock_Sandstone_White"
    },
    {
      "x": 3,
      "y": 12,
      "z": 0,
      "name": "Rock_Sandstone_White"
    },
    {
      "x": 3,
      "y": 13,
      "z": 0,
      "name": "Rock_Sandstone_White"
    },
    {
      "x": 3,
      "y": 14,
      "z": 0,
      "name": "Rock_Sandstone"
    },
    {
      "x": 3,
      "y": 15,
      "z": 0,
      "name": "Rock_Sandstone_White"
    },
    {
      "x": 3,
      "y": 9,
      "z": 1,
      "name": "Rock_Sandstone_White"
    },
    {
      "x": 3,
      "y": 10,
      "z": 1,
      "name": "Rock_Sandstone_White"
    },
    {
      "x": 3,
      "y": 11,
      "z": 1,
      "name": "Rock_Sandstone_White"
    },
    {
      "x": 3,
      "y": 12,
      "z": 1,
      "name": "Rock_Sandstone_White"
    },
    {
      "x": 3,
      "y": 13,
      "z": 1,
      "name": "Rock_Sandstone_White"
    },
    {
      "x": 3,
      "y": 14,
      "z": 1,
      "name": "Rock_Sandstone_White"
    },
    {
      "x": 3,
      "y": 15,
      "z": 1,
      "name": "Rock_Sandstone_White"
    },
    {
      "x": 3,
      "y": 9,
      "z": 2,
      "name": "Rock_Sandstone_White"
    },
    {
      "x": 3,
      "y": 10,
      "z": 2,
      "name": "Rock_Sandstone_White"
    },
    {
      "x": 3,
      "y": 11,
      "z": 2,
      "name": "Rock_Sandstone_White"
    },
    {
      "x": 3,
      "y": 12,
      "z": 2,
      "name": "Rock_Sandstone_White"
    },
    {
      "x": 3,
      "y": 13,
      "z": 2,
      "name": "Rock_Sandstone_White"
    },
    {
      "x": 3,
      "y": 14,
      "z": 2,
      "name": "Rock_Sandstone"
    },
    {
      "x": 3,
      "y": 15,
      "z": 2,
      "name": "Rock_Sandstone_White"
    },
    {
      "x": 3,
      "y": 9,
      "z": 3,
      "name": "Rock_Sandstone_White"
    },
    {
      "x": 3,
      "y": 10,
      "z": 3,
      "name": "Rock_Sandstone_White"
    },
    {
      "x": 3,
      "y": 11,
      "z": 3,
      "name": "Rock_Sandstone_White"
    },
    {
      "x": 3,
      "y": 12,
      "z": 3,
      "name": "Rock_Sandstone_White"
    },
    {
      "x": 3,
      "y": 13,
      "z": 3,
      "name": "Rock_Sandstone"
    },
    {
      "x": 3,
      "y": 14,
      "z": 3,
      "name": "Rock_Sandstone_White"
    },
    {
      "x": 3,
      "y": 15,
      "z": 3,
      "name": "Rock_Sandstone_White"
    },
    {
      "x": 3,
      "y": 10,
      "z": 4,
      "name": "Rock_Sandstone_White"
    },
    {
      "x": 3,
      "y": 11,
      "z": 4,
      "name": "Rock_Sandstone_White"
    },
    {
      "x": 3,
      "y": 12,
      "z": 4,
      "name": "Rock_Sandstone_White"
    },
    {
      "x": 3,
      "y": 13,
      "z": 4,
      "name": "Rock_Sandstone"
    },
    {
      "x": 3,
      "y": 14,
      "z": 4,
      "name": "Rock_Sandstone_White"
    },
    {
      "x": 3,
      "y": 15,
      "z": 4,
      "name": "Rock_Sandstone_White"
    },
    {
      "x": 3,
      "y": 11,
      "z": 5,
      "name": "Rock_Sandstone_White"
    },
    {
      "x": 3,
      "y": 12,
      "z": 5,
      "name": "Rock_Sandstone_White"
    },
    {
      "x": 3,
      "y": 13,
      "z": 5,
      "name": "Soil_Sand_White"
    },
    {
      "x": 4,
      "y": 12,
      "z": -3,
      "name": "Rock_Sandstone_White"
    },
    {
      "x": 4,
      "y": 13,
      "z": -3,
      "name": "Rock_Sandstone_White"
    },
    {
      "x": 4,
      "y": 14,
      "z": -3,
      "name": "Soil_Sand_White"
    },
    {
      "x": 4,
      "y": 10,
      "z": -2,
      "name": "Rock_Sandstone_White"
    },
    {
      "x": 4,
      "y": 11,
      "z": -2,
      "name": "Rock_Sandstone_White"
    },
    {
      "x": 4,
      "y": 12,
      "z": -2,
      "name": "Rock_Sandstone_White"
    },
    {
      "x": 4,
      "y": 13,
      "z": -2,
      "name": "Rock_Sandstone_White"
    },
    {
      "x": 4,
      "y": 14,
      "z": -2,
      "name": "Rock_Sandstone"
    },
    {
      "x": 4,
      "y": 15,
      "z": -2,
      "name": "Soil_Sand_White"
    },
    {
      "x": 4,
      "y": 9,
      "z": -1,
      "name": "Rock_Sandstone_White"
    },
    {
      "x": 4,
      "y": 10,
      "z": -1,
      "name": "Rock_Sandstone_White"
    },
    {
      "x": 4,
      "y": 11,
      "z": -1,
      "name": "Rock_Sandstone_White"
    },
    {
      "x": 4,
      "y": 12,
      "z": -1,
      "name": "Rock_Sandstone_White"
    },
    {
      "x": 4,
      "y": 13,
      "z": -1,
      "name": "Rock_Sandstone_White"
    },
    {
      "x": 4,
      "y": 14,
      "z": -1,
      "name": "Rock_Sandstone"
    },
    {
      "x": 4,
      "y": 15,
      "z": -1,
      "name": "Rock_Sandstone_White"
    },
    {
      "x": 4,
      "y": 9,
      "z": 0,
      "name": "Rock_Sandstone_White"
    },
    {
      "x": 4,
      "y": 10,
      "z": 0,
      "name": "Rock_Sandstone_White"
    },
    {
      "x": 4,
      "y": 11,
      "z": 0,
      "name": "Rock_Sandstone_White"
    },
    {
      "x": 4,
      "y": 12,
      "z": 0,
      "name": "Rock_Sandstone_White"
    },
    {
      "x": 4,
      "y": 13,
      "z": 0,
      "name": "Rock_Sandstone_White"
    },
    {
      "x": 4,
      "y": 14,
      "z": 0,
      "name": "Rock_Sandstone"
    },
    {
      "x": 4,
      "y": 15,
      "z": 0,
      "name": "Rock_Sandstone_White"
    },
    {
      "x": 4,
      "y": 9,
      "z": 1,
      "name": "Rock_Sandstone_White"
    },
    {
      "x": 4,
      "y": 10,
      "z": 1,
      "name": "Rock_Sandstone_White"
    },
    {
      "x": 4,
      "y": 11,
      "z": 1,
      "name": "Rock_Sandstone_White"
    },
    {
      "x": 4,
      "y": 12,
      "z": 1,
      "name": "Rock_Sandstone_White"
    },
    {
      "x": 4,
      "y": 13,
      "z": 1,
      "name": "Rock_Sandstone_White"
    },
    {
      "x": 4,
      "y": 14,
      "z": 1,
      "name": "Rock_Sandstone"
    },
    {
      "x": 4,
      "y": 15,
      "z": 1,
      "name": "Rock_Sandstone_White"
    },
    {
      "x": 4,
      "y": 9,
      "z": 2,
      "name": "Rock_Sandstone_White"
    },
    {
      "x": 4,
      "y": 10,
      "z": 2,
      "name": "Rock_Sandstone_White"
    },
    {
      "x": 4,
      "y": 11,
      "z": 2,
      "name": "Rock_Sandstone_White"
    },
    {
      "x": 4,
      "y": 12,
      "z": 2,
      "name": "Rock_Sandstone_White"
    },
    {
      "x": 4,
      "y": 13,
      "z": 2,
      "name": "Rock_Sandstone_White"
    },
    {
      "x": 4,
      "y": 14,
      "z": 2,
      "name": "Rock_Sandstone"
    },
    {
      "x": 4,
      "y": 15,
      "z": 2,
      "name": "Rock_Sandstone_White"
    },
    {
      "x": 4,
      "y": 9,
      "z": 3,
      "name": "Rock_Sandstone_White"
    },
    {
      "x": 4,
      "y": 10,
      "z": 3,
      "name": "Rock_Sandstone_White"
    },
    {
      "x": 4,
      "y": 11,
      "z": 3,
      "name": "Rock_Sandstone_White"
    },
    {
      "x": 4,
      "y": 12,
      "z": 3,
      "name": "Rock_Sandstone_White"
    },
    {
      "x": 4,
      "y": 13,
      "z": 3,
      "name": "Rock_Sandstone_White"
    },
    {
      "x": 4,
      "y": 14,
      "z": 3,
      "name": "Rock_Sandstone"
    },
    {
      "x": 4,
      "y": 15,
      "z": 3,
      "name": "Rock_Sandstone_White"
    },
    {
      "x": 4,
      "y": 9,
      "z": 4,
      "name": "Rock_Sandstone_White"
    },
    {
      "x": 4,
      "y": 10,
      "z": 4,
      "name": "Rock_Sandstone_White"
    },
    {
      "x": 4,
      "y": 11,
      "z": 4,
      "name": "Rock_Sandstone_White"
    },
    {
      "x": 4,
      "y": 12,
      "z": 4,
      "name": "Rock_Sandstone_White"
    },
    {
      "x": 4,
      "y": 13,
      "z": 4,
      "name": "Rock_Sandstone"
    },
    {
      "x": 4,
      "y": 14,
      "z": 4,
      "name": "Rock_Sandstone_White"
    },
    {
      "x": 4,
      "y": 15,
      "z": 4,
      "name": "Rock_Sandstone_White"
    },
    {
      "x": 4,
      "y": 10,
      "z": 5,
      "name": "Rock_Sandstone_White"
    },
    {
      "x": 4,
      "y": 11,
      "z": 5,
      "name": "Rock_Sandstone_White"
    },
    {
      "x": 4,
      "y": 12,
      "z": 5,
      "name": "Rock_Sandstone_White"
    },
    {
      "x": 4,
      "y": 13,
      "z": 5,
      "name": "Soil_Sand_White"
    },
    {
      "x": 5,
      "y": 11,
      "z": -3,
      "name": "Rock_Sandstone_White"
    },
    {
      "x": 5,
      "y": 12,
      "z": -3,
      "name": "Rock_Sandstone_White"
    },
    {
      "x": 5,
      "y": 13,
      "z": -3,
      "name": "Soil_Sand_White"
    },
    {
      "x": 5,
      "y": 14,
      "z": -3,
      "name": "Soil_Sand_White"
    },
    {
      "x": 5,
      "y": 10,
      "z": -2,
      "name": "Rock_Sandstone_White"
    },
    {
      "x": 5,
      "y": 11,
      "z": -2,
      "name": "Rock_Sandstone_White"
    },
    {
      "x": 5,
      "y": 12,
      "z": -2,
      "name": "Rock_Sandstone_White"
    },
    {
      "x": 5,
      "y": 13,
      "z": -2,
      "name": "Rock_Sandstone_White"
    },
    {
      "x": 5,
      "y": 14,
      "z": -2,
      "name": "Rock_Sandstone"
    },
    {
      "x": 5,
      "y": 15,
      "z": -2,
      "name": "Soil_Sand_White"
    },
    {
      "x": 5,
      "y": 9,
      "z": -1,
      "name": "Rock_Sandstone_White"
    },
    {
      "x": 5,
      "y": 10,
      "z": -1,
      "name": "Rock_Sandstone_White"
    },
    {
      "x": 5,
      "y": 11,
      "z": -1,
      "name": "Rock_Sandstone_White"
    },
    {
      "x": 5,
      "y": 12,
      "z": -1,
      "name": "Rock_Sandstone_White"
    },
    {
      "x": 5,
      "y": 13,
      "z": -1,
      "name": "Rock_Sandstone_White"
    },
    {
      "x": 5,
      "y": 14,
      "z": -1,
      "name": "Rock_Sandstone"
    },
    {
      "x": 5,
      "y": 15,
      "z": -1,
      "name": "Rock_Sandstone_White"
    },
    {
      "x": 5,
      "y": 9,
      "z": 0,
      "name": "Rock_Sandstone_White"
    },
    {
      "x": 5,
      "y": 10,
      "z": 0,
      "name": "Rock_Sandstone_White"
    },
    {
      "x": 5,
      "y": 11,
      "z": 0,
      "name": "Rock_Sandstone_White"
    },
    {
      "x": 5,
      "y": 12,
      "z": 0,
      "name": "Rock_Sandstone_White"
    },
    {
      "x": 5,
      "y": 13,
      "z": 0,
      "name": "Rock_Sandstone_White"
    },
    {
      "x": 5,
      "y": 14,
      "z": 0,
      "name": "Rock_Sandstone"
    },
    {
      "x": 5,
      "y": 15,
      "z": 0,
      "name": "Rock_Sandstone_White"
    },
    {
      "x": 5,
      "y": 9,
      "z": 1,
      "name": "Rock_Sandstone_White"
    },
    {
      "x": 5,
      "y": 10,
      "z": 1,
      "name": "Rock_Sandstone_White"
    },
    {
      "x": 5,
      "y": 11,
      "z": 1,
      "name": "Rock_Sandstone_White"
    },
    {
      "x": 5,
      "y": 12,
      "z": 1,
      "name": "Rock_Sandstone_White"
    },
    {
      "x": 5,
      "y": 13,
      "z": 1,
      "name": "Rock_Sandstone_White"
    },
    {
      "x": 5,
      "y": 14,
      "z": 1,
      "name": "Rock_Sandstone"
    },
    {
      "x": 5,
      "y": 15,
      "z": 1,
      "name": "Rock_Sandstone_White"
    },
    {
      "x": 5,
      "y": 9,
      "z": 2,
      "name": "Rock_Sandstone_White"
    },
    {
      "x": 5,
      "y": 10,
      "z": 2,
      "name": "Rock_Sandstone_White"
    },
    {
      "x": 5,
      "y": 11,
      "z": 2,
      "name": "Rock_Sandstone_White"
    },
    {
      "x": 5,
      "y": 12,
      "z": 2,
      "name": "Rock_Sandstone_White"
    },
    {
      "x": 5,
      "y": 13,
      "z": 2,
      "name": "Rock_Sandstone_White"
    },
    {
      "x": 5,
      "y": 14,
      "z": 2,
      "name": "Rock_Sandstone"
    },
    {
      "x": 5,
      "y": 15,
      "z": 2,
      "name": "Rock_Sandstone_White"
    },
    {
      "x": 5,
      "y": 9,
      "z": 3,
      "name": "Rock_Sandstone_White"
    },
    {
      "x": 5,
      "y": 10,
      "z": 3,
      "name": "Rock_Sandstone_White"
    },
    {
      "x": 5,
      "y": 11,
      "z": 3,
      "name": "Rock_Sandstone_White"
    },
    {
      "x": 5,
      "y": 12,
      "z": 3,
      "name": "Rock_Sandstone_White"
    },
    {
      "x": 5,
      "y": 13,
      "z": 3,
      "name": "Rock_Sandstone_White"
    },
    {
      "x": 5,
      "y": 14,
      "z": 3,
      "name": "Rock_Sandstone"
    },
    {
      "x": 5,
      "y": 15,
      "z": 3,
      "name": "Rock_Sandstone_White"
    },
    {
      "x": 5,
      "y": 9,
      "z": 4,
      "name": "Rock_Sandstone_White"
    },
    {
      "x": 5,
      "y": 10,
      "z": 4,
      "name": "Rock_Sandstone_White"
    },
    {
      "x": 5,
      "y": 11,
      "z": 4,
      "name": "Rock_Sandstone_White"
    },
    {
      "x": 5,
      "y": 12,
      "z": 4,
      "name": "Rock_Sandstone_White"
    },
    {
      "x": 5,
      "y": 13,
      "z": 4,
      "name": "Rock_Sandstone_White"
    },
    {
      "x": 5,
      "y": 14,
      "z": 4,
      "name": "Rock_Sandstone"
    },
    {
      "x": 5,
      "y": 15,
      "z": 4,
      "name": "Rock_Sandstone_White"
    },
    {
      "x": 5,
      "y": 10,
      "z": 5,
      "name": "Rock_Sandstone_White"
    },
    {
      "x": 5,
      "y": 11,
      "z": 5,
      "name": "Rock_Sandstone_White"
    },
    {
      "x": 5,
      "y": 12,
      "z": 5,
      "name": "Rock_Sandstone_White"
    },
    {
      "x": 5,
      "y": 13,
      "z": 5,
      "name": "Soil_Sand_White"
    },
    {
      "x": 6,
      "y": 11,
      "z": -3,
      "name": "Rock_Sandstone_White"
    },
    {
      "x": 6,
      "y": 12,
      "z": -3,
      "name": "Rock_Sandstone_White"
    },
    {
      "x": 6,
      "y": 13,
      "z": -3,
      "name": "Soil_Sand_White"
    },
    {
      "x": 6,
      "y": 11,
      "z": -2,
      "name": "Rock_Sandstone_White"
    },
    {
      "x": 6,
      "y": 12,
      "z": -2,
      "name": "Rock_Sandstone_White"
    },
    {
      "x": 6,
      "y": 13,
      "z": -2,
      "name": "Rock_Sandstone_White"
    },
    {
      "x": 6,
      "y": 14,
      "z": -2,
      "name": "Soil_Sand_White"
    },
    {
      "x": 6,
      "y": 10,
      "z": -1,
      "name": "Rock_Sandstone_White"
    },
    {
      "x": 6,
      "y": 11,
      "z": -1,
      "name": "Rock_Sandstone_White"
    },
    {
      "x": 6,
      "y": 12,
      "z": -1,
      "name": "Rock_Sandstone_White"
    },
    {
      "x": 6,
      "y": 13,
      "z": -1,
      "name": "Rock_Sandstone_White"
    },
    {
      "x": 6,
      "y": 14,
      "z": -1,
      "name": "Rock_Sandstone"
    },
    {
      "x": 6,
      "y": 15,
      "z": -1,
      "name": "Soil_Sand_White"
    },
    {
      "x": 6,
      "y": 9,
      "z": 0,
      "name": "Rock_Sandstone_White"
    },
    {
      "x": 6,
      "y": 10,
      "z": 0,
      "name": "Rock_Sandstone_White"
    },
    {
      "x": 6,
      "y": 11,
      "z": 0,
      "name": "Rock_Sandstone_White"
    },
    {
      "x": 6,
      "y": 12,
      "z": 0,
      "name": "Rock_Sandstone_White"
    },
    {
      "x": 6,
      "y": 13,
      "z": 0,
      "name": "Rock_Sandstone_White"
    },
    {
      "x": 6,
      "y": 14,
      "z": 0,
      "name": "Rock_Sandstone"
    },
    {
      "x": 6,
      "y": 15,
      "z": 0,
      "name": "Rock_Sandstone_White"
    },
    {
      "x": 6,
      "y": 9,
      "z": 1,
      "name": "Rock_Sandstone_White"
    },
    {
      "x": 6,
      "y": 10,
      "z": 1,
      "name": "Rock_Sandstone_White"
    },
    {
      "x": 6,
      "y": 11,
      "z": 1,
      "name": "Rock_Sandstone_White"
    },
    {
      "x": 6,
      "y": 12,
      "z": 1,
      "name": "Rock_Sandstone_White"
    },
    {
      "x": 6,
      "y": 13,
      "z": 1,
      "name": "Rock_Sandstone_White"
    },
    {
      "x": 6,
      "y": 14,
      "z": 1,
      "name": "Rock_Sandstone"
    },
    {
      "x": 6,
      "y": 15,
      "z": 1,
      "name": "Rock_Sandstone_White"
    },
    {
      "x": 6,
      "y": 9,
      "z": 2,
      "name": "Rock_Sandstone_White"
    },
    {
      "x": 6,
      "y": 10,
      "z": 2,
      "name": "Rock_Sandstone_White"
    },
    {
      "x": 6,
      "y": 11,
      "z": 2,
      "name": "Rock_Sandstone_White"
    },
    {
      "x": 6,
      "y": 12,
      "z": 2,
      "name": "Rock_Sandstone_White"
    },
    {
      "x": 6,
      "y": 13,
      "z": 2,
      "name": "Rock_Sandstone_White"
    },
    {
      "x": 6,
      "y": 14,
      "z": 2,
      "name": "Rock_Sandstone"
    },
    {
      "x": 6,
      "y": 15,
      "z": 2,
      "name": "Rock_Sandstone_White"
    },
    {
      "x": 6,
      "y": 9,
      "z": 3,
      "name": "Rock_Sandstone_White"
    },
    {
      "x": 6,
      "y": 10,
      "z": 3,
      "name": "Rock_Sandstone_White"
    },
    {
      "x": 6,
      "y": 11,
      "z": 3,
      "name": "Rock_Sandstone_White"
    },
    {
      "x": 6,
      "y": 12,
      "z": 3,
      "name": "Rock_Sandstone_White"
    },
    {
      "x": 6,
      "y": 13,
      "z": 3,
      "name": "Rock_Sandstone_White"
    },
    {
      "x": 6,
      "y": 14,
      "z": 3,
      "name": "Rock_Sandstone"
    },
    {
      "x": 6,
      "y": 15,
      "z": 3,
      "name": "Rock_Sandstone_White"
    },
    {
      "x": 6,
      "y": 9,
      "z": 4,
      "name": "Rock_Sandstone_White"
    },
    {
      "x": 6,
      "y": 10,
      "z": 4,
      "name": "Rock_Sandstone_White"
    },
    {
      "x": 6,
      "y": 11,
      "z": 4,
      "name": "Rock_Sandstone_White"
    },
    {
      "x": 6,
      "y": 12,
      "z": 4,
      "name": "Rock_Sandstone_White"
    },
    {
      "x": 6,
      "y": 13,
      "z": 4,
      "name": "Soil_Sand_White"
    },
    {
      "x": 6,
      "y": 11,
      "z": 5,
      "name": "Rock_Sandstone_White"
    },
    {
      "x": 6,
      "y": 12,
      "z": 5,
      "name": "Soil_Sand_White"
    },
    {
      "x": 7,
      "y": 11,
      "z": -2,
      "name": "Rock_Sandstone_White"
    },
    {
      "x": 7,
      "y": 12,
      "z": -2,
      "name": "Rock_Sandstone_White"
    },
    {
      "x": 7,
      "y": 13,
      "z": -2,
      "name": "Soil_Sand_White"
    },
    {
      "x": 7,
      "y": 11,
      "z": -1,
      "name": "Rock_Sandstone_White"
    },
    {
      "x": 7,
      "y": 12,
      "z": -1,
      "name": "Rock_Sandstone_White"
    },
    {
      "x": 7,
      "y": 13,
      "z": -1,
      "name": "Soil_Sand_White"
    },
    {
      "x": 7,
      "y": 14,
      "z": -1,
      "name": "Soil_Sand_White"
    },
    {
      "x": 7,
      "y": 10,
      "z": 0,
      "name": "Rock_Sandstone_White"
    },
    {
      "x": 7,
      "y": 11,
      "z": 0,
      "name": "Rock_Sandstone_White"
    },
    {
      "x": 7,
      "y": 12,
      "z": 0,
      "name": "Rock_Sandstone_White"
    },
    {
      "x": 7,
      "y": 13,
      "z": 0,
      "name": "Rock_Sandstone_White"
    },
    {
      "x": 7,
      "y": 14,
      "z": 0,
      "name": "Soil_Sand_White"
    },
    {
      "x": 7,
      "y": 10,
      "z": 1,
      "name": "Rock_Sandstone_White"
    },
    {
      "x": 7,
      "y": 11,
      "z": 1,
      "name": "Rock_Sandstone_White"
    },
    {
      "x": 7,
      "y": 12,
      "z": 1,
      "name": "Rock_Sandstone_White"
    },
    {
      "x": 7,
      "y": 13,
      "z": 1,
      "name": "Rock_Sandstone_White"
    },
    {
      "x": 7,
      "y": 14,
      "z": 1,
      "name": "Soil_Sand_White"
    },
    {
      "x": 7,
      "y": 9,
      "z": 2,
      "name": "Rock_Sandstone_White"
    },
    {
      "x": 7,
      "y": 10,
      "z": 2,
      "name": "Rock_Sandstone_White"
    },
    {
      "x": 7,
      "y": 11,
      "z": 2,
      "name": "Rock_Sandstone_White"
    },
    {
      "x": 7,
      "y": 12,
      "z": 2,
      "name": "Rock_Sandstone_White"
    },
    {
      "x": 7,
      "y": 13,
      "z": 2,
      "name": "Soil_Sand_White"
    },
    {
      "x": 7,
      "y": 14,
      "z": 2,
      "name": "Soil_Sand_White"
    },
    {
      "x": 7,
      "y": 9,
      "z": 3,
      "name": "Rock_Sandstone_White"
    },
    {
      "x": 7,
      "y": 10,
      "z": 3,
      "name": "Rock_Sandstone_White"
    },
    {
      "x": 7,
      "y": 11,
      "z": 3,
      "name": "Rock_Sandstone_White"
    },
    {
      "x": 7,
      "y": 12,
      "z": 3,
      "name": "Rock_Sandstone_White"
    },
    {
      "x": 7,
      "y": 13,
      "z": 3,
      "name": "Soil_Sand_White"
    },
    {
      "x": 7,
      "y": 11,
      "z": 4,
      "name": "Rock_Sandstone_White"
    },
    {
      "x": 7,
      "y": 12,
      "z": 4,
      "name": "Soil_Sand_White"
    }
  ]
}