{
  "version": 8,
  "blockIdVersion": 8,
  "anchorX": 0,
  "anchorY": 0,
  "anchorZ": 0,
  "blocks": [
    {
      "x": -10,
      "y": -1,
      "z": -10,
      "name": "Rock_Stone"
    },
    {
      "x": -10,
      "y": 0,
      "z": -10,
      "name": "Rock_Stone"
    },
    {
      "x": -10,
      "y": 1,
      "z": -10,
      "name": "Rock_Stone"
    },
    {
      "x": -10,
      "y": 2,
      "z": -10,
      "name": "Rock_Stone"
    },
    {
      "x": -10,
      "y": 3,
      "z": -10,
      "name": "Rock_Stone"
    },
    {
      "x": -10,
      "y": 4,
      "z": -10,
      "name": "Rock_Stone"
    },
    {
      "x": -10,
      "y": 5,
      "z": -10,
      "name": "Rock_Stone"
    },
    {
      "x": -10,
      "y": 6,
      "z": -10,
      "name": "Rock_Stone"
    },
    {
      "x": -10,
      "y": 7,
      "z": -10,
      "name": "Rock_Stone"
    },
    {
      "x": -10,
      "y": 8,
      "z": -10,
      "name": "Rock_Stone"
    },
    {
      "x": -10,
      "y": 9,
      "z": -10,
      "name": "Rock_Stone"
    },
    {
      "x": -10,
      "y": 10,
      "z": -10,
      "name": "Rock_Stone"
    },
    {
      "x": -10,
      "y": 11,
      "z": -10,
      "name": "Rock_Stone"
    },
    {
      "x": -10,
      "y": 12,
      "z": -10,
      "name": "Rock_Stone"
    },
    {
      "x": -10,
      "y": 13,
      "z": -10,
      "name": "Rock_Stone"
    },
    {
      "x": -10,
      "y": -1,
      "z": -9,
      "name": "Rock_Stone"
    },
    {
      "x": -10,
      "y": 0,
      "z": -9,
      "name": "Rock_Stone"
    },
    {
      "x": -10,
      "y": 1,
      "z": -9,
      "name": "Rock_Stone"
    },
    {
      "x": -10,
      "y": 2,
      "z": -9,
      "name": "Rock_Stone"
    },
    {
      "x": -10,
      "y": 3,
      "z": -9,
      "name": "Rock_Stone"
    },
    {
      "x": -10,
      "y": 4,
      "z": -9,
      "name": "Rock_Stone"
    },
    {
      "x": -10,
      "y": 5,
      "z": -9,
      "name": "Rock_Stone"
    },
    {
      "x": -10,
      "y": 6,
      "z": -9,
      "name": "Rock_Stone"
    },
    {
      "x": -10,
      "y": 7,
      "z": -9,
      "name": "Rock_Stone"
    },
    {
      "x": -10,
      "y": 8,
      "z": -9,
      "name": "Rock_Stone"
    },
    {
      "x": -10,
      "y": 9,
      "z": -9,
      "name": "Rock_Stone"
    },
    {
      "x": -10,
      "y": 10,
      "z": -9,
      "name": "Rock_Stone"
    },
    {
      "x": -10,
      "y": 11,
      "z": -9,
      "name": "Rock_Stone"
    },
    {
      "x": -10,
      "y": 12,
      "z": -9,
      "name": "Rock_Stone"
    },
    {
      "x": -10,
      "y": 13,
      "z": -9,
      "name": "Rock_Stone"
    },
    {
      "x": -10,
      "y": -1,
      "z": -8,
      "name": "Rock_Stone"
    },
    {
      "x": -10,
      "y": 0,
      "z": -8,
      "name": "Rock_Stone"
    },
    {
      "x": -10,
      "y": 1,
      "z": -8,
      "name": "Rock_Stone"
    },
    {
      "x": -10,
      "y": 2,
      "z": -8,
      "name": "Rock_Stone"
    },
    {
      "x": -10,
      "y": 3,
      "z": -8,
      "name": "Rock_Stone"
    },
    {
      "x": -10,
      "y": 4,
      "z": -8,
      "name": "Rock_Stone"
    },
    {
      "x": -10,
      "y": 5,
      "z": -8,
      "name": "Rock_Stone"
    },
    {
      "x": -10,
      "y": 6,
      "z": -8,
      "name": "Rock_Stone"
    },
    {
      "x": -10,
      "y": 7,
      "z": -8,
      "name": "Rock_Stone"
    },
    {
      "x": -10,
      "y": 8,
      "z": -8,
      "name": "Rock_Stone"
    },
    {
      "x": -10,
      "y": 9,
      "z": -8,
      "name": "Rock_Stone"
    },
    {
      "x": -10,
      "y": 10,
      "z": -8,
      "name": "Rock_Stone"
    },
    {
      "x": -10,
      "y": 11,
      "z": -8,
      "name": "Rock_Stone"
    },
    {
      "x": -10,
      "y": 12,
      "z": -8,
      "name": "Rock_Stone"
    },
    {
      "x": -10,
      "y": 13,
      "z": -8,
      "name": "Rock_Stone"
    },
    {
      "x": -10,
      "y": -1,
      "z": -7,
      "name": "Rock_Stone"
    },
    {
      "x": -10,
      "y": 0,
      "z": -7,
      "name": "Rock_Stone"
    },
    {
      "x": -10,
      "y": 1,
      "z": -7,
      "name": "Rock_Stone"
    },
    {
      "x": -10,
      "y": 2,
      "z": -7,
      "name": "Rock_Stone"
    },
    {
      "x": -10,
      "y": 3,
      "z": -7,
      "name": "Rock_Stone"
    },
    {
      "x": -10,
      "y": 4,
      "z": -7,
      "name": "Rock_Stone"
    },
    {
      "x": -10,
      "y": 5,
      "z": -7,
      "name": "Rock_Stone"
    },
    {
      "x": -10,
      "y": 6,
      "z": -7,
      "name": "Rock_Stone"
    },
    {
      "x": -10,
      "y": 7,
      "z": -7,
      "name": "Rock_Stone"
    },
    {
      "x": -10,
      "y": 8,
      "z": -7,
      "name": "Rock_Stone"
    },
    {
      "x": -10,
      "y": 9,
      "z": -7,
      "name": "Rock_Stone"
    },
    {
      "x": -10,
      "y": 10,
      "z": -7,
      "name": "Rock_Stone"
    },
    {
      "x": -10,
      "y": 11,
      "z": -7,
      "name": "Rock_Stone"
    },
    {
      "x": -10,
      "y": 12,
      "z": -7,
      "name": "Rock_Stone"
    },
    {
      "x": -10,
      "y": 13,
      "z": -7,
      "name": "Rock_Stone"
    },
    {
      "x": -10,
      "y": -1,
      "z": -6,
      "name": "Rock_Stone"
    },
    {
      "x": -10,
      "y": 0,
      "z": -6,
      "name": "Rock_Stone"
    },
    {
      "x": -10,
      "y": 1,
      "z": -6,
      "name": "Rock_Stone"
    },
    {
      "x": -10,
      "y": 2,
      "z": -6,
      "name": "Rock_Stone"
    },
    {
      "x": -10,
      "y": 3,
      "z": -6,
      "name": "Rock_Stone"
    },
    {
      "x": -10,
      "y": 4,
      "z": -6,
      "name": "Rock_Stone"
    },
    {
      "x": -10,
      "y": 5,
      "z": -6,
      "name": "Rock_Stone"
    },
    {
      "x": -10,
      "y": 6,
      "z": -6,
      "name": "Rock_Stone"
    },
    {
      "x": -10,
      "y": 7,
      "z": -6,
      "name": "Rock_Stone"
    },
    {
      "x": -10,
      "y": 8,
      "z": -6,
      "name": "Rock_Stone"
    },
    {
      "x": -10,
      "y": 9,
      "z": -6,
      "name": "Rock_Stone"
    },
    {
      "x": -10,
      "y": 10,
      "z": -6,
      "name": "Rock_Stone"
    },
    {
      "x": -10,
      "y": 11,
      "z": -6,
      "name": "Rock_Stone"
    },
    {
      "x": -10,
      "y": 12,
      "z": -6,
      "name": "Rock_Stone"
    },
    {
      "x": -10,
      "y": 13,
      "z": -6,
      "name": "Rock_Stone"
    },
    {
      "x": -10,
      "y": -1,
      "z": -5,
      "name": "Rock_Stone"
    },
    {
      "x": -10,
      "y": 0,
      "z": -5,
      "name": "Rock_Stone"
    },
    {
      "x": -10,
      "y": 1,
      "z": -5,
      "name": "Rock_Stone"
    },
    {
      "x": -10,
      "y": 2,
      "z": -5,
      "name": "Rock_Stone"
    },
    {
      "x": -10,
      "y": 3,
      "z": -5,
      "name": "Rock_Stone"
    },
    {
      "x": -10,
      "y": 4,
      "z": -5,
      "name": "Rock_Stone"
    },
    {
      "x": -10,
      "y": 5,
      "z": -5,
      "name": "Rock_Stone"
    },
    {
      "x": -10,
      "y": 6,
      "z": -5,
      "name": "Rock_Stone"
    },
    {
      "x": -10,
      "y": 7,
      "z": -5,
      "name": "Rock_Stone"
    },
    {
      "x": -10,
      "y": 8,
      "z": -5,
      "name": "Rock_Stone"
    },
    {
      "x": -10,
      "y": 9,
      "z": -5,
      "name": "Rock_Stone"
    },
    {
      "x": -10,
      "y": 10,
      "z": -5,
      "name": "Rock_Stone"
    },
    {
      "x": -10,
      "y": 11,
      "z": -5,
      "name": "Rock_Stone"
    },
    {
      "x": -10,
      "y": 12,
      "z": -5,
      "name": "Rock_Stone"
    },
    {
      "x": -10,
      "y": 13,
      "z": -5,
      "name": "Rock_Stone"
    },
    {
      "x": -10,
      "y": -1,
      "z": -4,
      "name": "Rock_Stone"
    },
    {
      "x": -10,
      "y": 0,
      "z": -4,
      "name": "Rock_Stone"
    },
    {
      "x": -10,
      "y": 1,
      "z": -4,
      "name": "Rock_Stone"
    },
    {
      "x": -10,
      "y": 2,
      "z": -4,
      "name": "Rock_Stone"
    },
    {
      "x": -10,
      "y": 3,
      "z": -4,
      "name": "Rock_Stone"
    },
    {
      "x": -10,
      "y": 4,
      "z": -4,
      "name": "Rock_Stone"
    },
    {
      "x": -10,
      "y": 5,
      "z": -4,
      "name": "Rock_Stone"
    },
    {
      "x": -10,
      "y": 6,
      "z": -4,
      "name": "Rock_Stone"
    },
    {
      "x": -10,
      "y": 7,
      "z": -4,
      "name": "Rock_Stone"
    },
    {
      "x": -10,
      "y": 8,
      "z": -4,
      "name": "Rock_Stone"
    },
    {
      "x": -10,
      "y": 9,
      "z": -4,
      "name": "Rock_Stone"
    },
    {
      "x": -10,
      "y": 10,
      "z": -4,
      "name": "Rock_Stone"
    },
    {
      "x": -10,
      "y": 11,
      "z": -4,
      "name": "Rock_Stone"
    },
    {
      "x": -10,
      "y": 12,
      "z": -4,
      "name": "Rock_Stone"
    },
    {
      "x": -10,
      "y": 13,
      "z": -4,
      "name": "Rock_Stone"
    },
    {
      "x": -10,
      "y": -1,
      "z": -3,
      "name": "Rock_Stone"
    },
    {
      "x": -10,
      "y": 0,
      "z": -3,
      "name": "Rock_Stone"
    },
    {
      "x": -10,
      "y": 1,
      "z": -3,
      "name": "Rock_Stone"
    },
    {
      "x": -10,
      "y": 2,
      "z": -3,
      "name": "Rock_Stone"
    },
    {
      "x": -10,
      "y": 3,
      "z": -3,
      "name": "Rock_Stone"
    },
    {
      "x": -10,
      "y": 4,
      "z": -3,
      "name": "Rock_Stone"
    },
    {
      "x": -10,
      "y": 5,
      "z": -3,
      "name": "Rock_Stone"
    },
    {
      "x": -10,
      "y": 6,
      "z": -3,
      "name": "Rock_Stone"
    },
    {
      "x": -10,
      "y": 7,
      "z": -3,
      "name": "Rock_Stone"
    },
    {
      "x": -10,
      "y": 8,
      "z": -3,
      "name": "Rock_Stone"
    },
    {
      "x": -10,
      "y": 9,
      "z": -3,
      "name": "Rock_Stone"
    },
    {
      "x": -10,
      "y": 10,
      "z": -3,
      "name": "Rock_Stone"
    },
    {
      "x": -10,
      "y": 11,
      "z": -3,
      "name": "Rock_Stone"
    },
    {
      "x": -10,
      "y": 12,
      "z": -3,
      "name": "Rock_Stone"
    },
    {
      "x": -10,
      "y": 13,
      "z": -3,
      "name": "Rock_Stone"
    },
    {
      "x": -10,
      "y": -1,
      "z": -2,
      "name": "Rock_Stone"
    },
    {
      "x": -10,
      "y": 0,
      "z": -2,
      "name": "Rock_Stone"
    },
    {
      "x": -10,
      "y": 1,
      "z": -2,
      "name": "Empty"
    },
    {
      "x": -10,
      "y": 2,
      "z": -2,
      "name": "Empty"
    },
    {
      "x": -10,
      "y": 3,
      "z": -2,
      "name": "Empty"
    },
    {
      "x": -10,
      "y": 4,
      "z": -2,
      "name": "Rock_Stone"
    },
    {
      "x": -10,
      "y": 5,
      "z": -2,
      "name": "Rock_Stone"
    },
    {
      "x": -10,
      "y": 6,
      "z": -2,
      "name": "Rock_Stone"
    },
    {
      "x": -10,
      "y": 7,
      "z": -2,
      "name": "Rock_Stone"
    },
    {
      "x": -10,
      "y": 8,
      "z": -2,
      "name": "Rock_Stone"
    },
    {
      "x": -10,
      "y": 9,
      "z": -2,
      "name": "Rock_Stone"
    },
    {
      "x": -10,
      "y": 10,
      "z": -2,
      "name": "Rock_Stone"
    },
    {
      "x": -10,
      "y": 11,
      "z": -2,
      "name": "Rock_Stone"
    },
    {
      "x": -10,
      "y": 12,
      "z": -2,
      "name": "Rock_Stone"
    },
    {
      "x": -10,
      "y": 13,
      "z": -2,
      "name": "Rock_Stone"
    },
    {
      "x": -10,
      "y": -1,
      "z": -1,
      "name": "Rock_Stone"
    },
    {
      "x": -10,
      "y": 0,
      "z": -1,
      "name": "Soil_Gravel"
    },
    {
      "x": -10,
      "y": 1,
      "z": -1,
      "name": "Empty"
    },
    {
      "x": -10,
      "y": 2,
      "z": -1,
      "name": "Empty"
    },
    {
      "x": -10,
      "y": 3,
      "z": -1,
      "name": "Empty"
    },
    {
      "x": -10,
      "y": 4,
      "z": -1,
      "name": "Empty"
    },
    {
      "x": -10,
      "y": 5,
      "z": -1,
      "name": "Empty"
    },
    {
      "x": -10,
      "y": 6,
      "z": -1,
      "name": "Rock_Stone"
    },
    {
      "x": -10,
      "y": 7,
      "z": -1,
      "name": "Rock_Stone"
    },
    {
      "x": -10,
      "y": 8,
      "z": -1,
      "name": "Rock_Stone"
    },
    {
      "x": -10,
      "y": 9,
      "z": -1,
      "name": "Rock_Stone"
    },
    {
      "x": -10,
      "y": 10,
      "z": -1,
      "name": "Rock_Stone"
    },
    {
      "x": -10,
      "y": 11,
      "z": -1,
      "name": "Rock_Stone"
    },
    {
      "x": -10,
      "y": 12,
      "z": -1,
      "name": "Rock_Stone"
    },
    {
      "x": -10,
      "y": 13,
      "z": -1,
      "name": "Rock_Stone"
    },
    {
      "x": -10,
      "y": -1,
      "z": 0,
      "name": "Rock_Stone"
    },
    {
      "x": -10,
      "y": 0,
      "z": 0,
      "name": "Soil_Gravel"
    },
    {
      "x": -10,
      "y": 1,
      "z": 0,
      "name": "Rail",
      "rotation": 1
    },
    {
      "x": -10,
      "y": 2,
      "z": 0,
      "name": "Empty"
    },
    {
      "x": -10,
      "y": 3,
      "z": 0,
      "name": "Empty"
    },
    {
      "x": -10,
      "y": 4,
      "z": 0,
      "name": "Empty"
    },
    {
      "x": -10,
      "y": 5,
      "z": 0,
      "name": "Empty"
    },
    {
      "x": -10,
      "y": 6,
      "z": 0,
      "name": "Rock_Stone"
    },
    {
      "x": -10,
      "y": 7,
      "z": 0,
      "name": "Rock_Stone"
    },
    {
      "x": -10,
      "y": 8,
      "z": 0,
      "name": "Rock_Stone"
    },
    {
      "x": -10,
      "y": 9,
      "z": 0,
      "name": "Rock_Stone"
    },
    {
      "x": -10,
      "y": 10,
      "z": 0,
      "name": "Rock_Stone"
    },
    {
      "x": -10,
      "y": 11,
      "z": 0,
      "name": "Rock_Stone"
    },
    {
      "x": -10,
      "y": 12,
      "z": 0,
      "name": "Rock_Stone"
    },
    {
      "x": -10,
      "y": 13,
      "z": 0,
      "name": "Rock_Stone"
    },
    {
      "x": -10,
      "y": -1,
      "z": 1,
      "name": "Rock_Stone"
    },
    {
      "x": -10,
      "y": 0,
      "z": 1,
      "name": "Rock_Stone"
    },
    {
      "x": -10,
      "y": 1,
      "z": 1,
      "name": "Empty"
    },
    {
      "x": -10,
      "y": 2,
      "z": 1,
      "name": "Empty"
    },
    {
      "x": -10,
      "y": 3,
      "z": 1,
      "name": "Empty"
    },
    {
      "x": -10,
      "y": 4,
      "z": 1,
      "name": "Empty"
    },
    {
      "x": -10,
      "y": 5,
      "z": 1,
      "name": "Empty"
    },
    {
      "x": -10,
      "y": 6,
      "z": 1,
      "name": "Rock_Stone"
    },
    {
      "x": -10,
      "y": 7,
      "z": 1,
      "name": "Rock_Stone"
    },
    {
      "x": -10,
      "y": 8,
      "z": 1,
      "name": "Rock_Stone"
    },
    {
      "x": -10,
      "y": 9,
      "z": 1,
      "name": "Rock_Stone"
    },
    {
      "x": -10,
      "y": 10,
      "z": 1,
      "name": "Rock_Stone"
    },
    {
      "x": -10,
      "y": 11,
      "z": 1,
      "name": "Rock_Stone"
    },
    {
      "x": -10,
      "y": 12,
      "z": 1,
      "name": "Rock_Stone"
    },
    {
      "x": -10,
      "y": 13,
      "z": 1,
      "name": "Rock_Stone"
    },
    {
      "x": -10,
      "y": -1,
      "z": 2,
      "name": "Rock_Stone"
    },
    {
      "x": -10,
      "y": 0,
      "z": 2,
      "name": "Rock_Stone"
    },
    {
      "x": -10,
      "y": 1,
      "z": 2,
      "name": "Empty"
    },
    {
      "x": -10,
      "y": 2,
      "z": 2,
      "name": "Empty"
    },
    {
      "x": -10,
      "y": 3,
      "z": 2,
      "name": "Empty"
    },
    {
      "x": -10,
      "y": 4,
      "z": 2,
      "name": "Empty"
    },
    {
      "x": -10,
      "y": 5,
      "z": 2,
      "name": "Empty"
    },
    {
      "x": -10,
      "y": 6,
      "z": 2,
      "name": "Rock_Stone"
    },
    {
      "x": -10,
      "y": 7,
      "z": 2,
      "name": "Rock_Stone"
    },
    {
      "x": -10,
      "y": 8,
      "z": 2,
      "name": "Rock_Stone"
    },
    {
      "x": -10,
      "y": 9,
      "z": 2,
      "name": "Rock_Stone"
    },
    {
      "x": -10,
      "y": 10,
      "z": 2,
      "name": "Rock_Stone"
    },
    {
      "x": -10,
      "y": 11,
      "z": 2,
      "name": "Rock_Stone"
    },
    {
      "x": -10,
      "y": 12,
      "z": 2,
      "name": "Rock_Stone"
    },
    {
      "x": -10,
      "y": 13,
      "z": 2,
      "name": "Rock_Stone"
    },
    {
      "x": -10,
      "y": -1,
      "z": 3,
      "name": "Rock_Stone"
    },
    {
      "x": -10,
      "y": 0,
      "z": 3,
      "name": "Rock_Stone"
    },
    {
      "x": -10,
      "y": 1,
      "z": 3,
      "name": "Rock_Stone"
    },
    {
      "x": -10,
      "y": 2,
      "z": 3,
      "name": "Rock_Stone"
    },
    {
      "x": -10,
      "y": 3,
      "z": 3,
      "name": "Rock_Stone"
    },
    {
      "x": -10,
      "y": 4,
      "z": 3,
      "name": "Rock_Stone"
    },
    {
      "x": -10,
      "y": 5,
      "z": 3,
      "name": "Rock_Stone"
    },
    {
      "x": -10,
      "y": 6,
      "z": 3,
      "name": "Rock_Stone"
    },
    {
      "x": -10,
      "y": 7,
      "z": 3,
      "name": "Rock_Stone"
    },
    {
      "x": -10,
      "y": 8,
      "z": 3,
      "name": "Rock_Stone"
    },
    {
      "x": -10,
      "y": 9,
      "z": 3,
      "name": "Rock_Stone"
    },
    {
      "x": -10,
      "y": 10,
      "z": 3,
      "name": "Rock_Stone"
    },
    {
      "x": -10,
      "y": 11,
      "z": 3,
      "name": "Rock_Stone"
    },
    {
      "x": -10,
      "y": 12,
      "z": 3,
      "name": "Rock_Stone"
    },
    {
      "x": -10,
      "y": 13,
      "z": 3,
      "name": "Rock_Stone"
    },
    {
      "x": -10,
      "y": -1,
      "z": 4,
      "name": "Rock_Stone"
    },
    {
      "x": -10,
      "y": 0,
      "z": 4,
      "name": "Rock_Stone"
    },
    {
      "x": -10,
      "y": 1,
      "z": 4,
      "name": "Rock_Stone"
    },
    {
      "x": -10,
      "y": 2,
      "z": 4,
      "name": "Rock_Stone"
    },
    {
      "x": -10,
      "y": 3,
      "z": 4,
      "name": "Rock_Stone"
    },
    {
      "x": -10,
      "y": 4,
      "z": 4,
      "name": "Rock_Stone"
    },
    {
      "x": -10,
      "y": 5,
      "z": 4,
      "name": "Rock_Stone"
    },
    {
      "x": -10,
      "y": 6,
      "z": 4,
      "name": "Rock_Stone"
    },
    {
      "x": -10,
      "y": 7,
      "z": 4,
      "name": "Rock_Stone"
    },
    {
      "x": -10,
      "y": 8,
      "z": 4,
      "name": "Rock_Stone"
    },
    {
      "x": -10,
      "y": 9,
      "z": 4,
      "name": "Rock_Stone"
    },
    {
      "x": -10,
      "y": 10,
      "z": 4,
      "name": "Rock_Stone"
    },
    {
      "x": -10,
      "y": 11,
      "z": 4,
      "name": "Rock_Stone"
    },
    {
      "x": -10,
      "y": 12,
      "z": 4,
      "name": "Rock_Stone"
    },
    {
      "x": -10,
      "y": 13,
      "z": 4,
      "name": "Rock_Stone"
    },
    {
      "x": -10,
      "y": -1,
      "z": 5,
      "name": "Rock_Stone"
    },
    {
      "x": -10,
      "y": 0,
      "z": 5,
      "name": "Rock_Stone"
    },
    {
      "x": -10,
      "y": 1,
      "z": 5,
      "name": "Rock_Stone"
    },
    {
      "x": -10,
      "y": 2,
      "z": 5,
      "name": "Rock_Stone"
    },
    {
      "x": -10,
      "y": 3,
      "z": 5,
      "name": "Rock_Stone"
    },
    {
      "x": -10,
      "y": 4,
      "z": 5,
      "name": "Rock_Stone"
    },
    {
      "x": -10,
      "y": 5,
      "z": 5,
      "name": "Rock_Stone"
    },
    {
      "x": -10,
      "y": 6,
      "z": 5,
      "name": "Rock_Stone"
    },
    {
      "x": -10,
      "y": 7,
      "z": 5,
      "name": "Rock_Stone"
    },
    {
      "x": -10,
      "y": 8,
      "z": 5,
      "name": "Rock_Stone"
    },
    {
      "x": -10,
      "y": 9,
      "z": 5,
      "name": "Rock_Stone"
    },
    {
      "x": -10,
      "y": 10,
      "z": 5,
      "name": "Rock_Stone"
    },
    {
      "x": -10,
      "y": 11,
      "z": 5,
      "name": "Rock_Stone"
    },
    {
      "x": -10,
      "y": 12,
      "z": 5,
      "name": "Rock_Stone"
    },
    {
      "x": -10,
      "y": 13,
      "z": 5,
      "name": "Rock_Stone"
    },
    {
      "x": -10,
      "y": -1,
      "z": 6,
      "name": "Rock_Stone"
    },
    {
      "x": -10,
      "y": 0,
      "z": 6,
      "name": "Rock_Stone"
    },
    {
      "x": -10,
      "y": 1,
      "z": 6,
      "name": "Rock_Stone"
    },
    {
      "x": -10,
      "y": 2,
      "z": 6,
      "name": "Rock_Stone"
    },
    {
      "x": -10,
      "y": 3,
      "z": 6,
      "name": "Rock_Stone"
    },
    {
      "x": -10,
      "y": 4,
      "z": 6,
      "name": "Rock_Stone"
    },
    {
      "x": -10,
      "y": 5,
      "z": 6,
      "name": "Rock_Stone"
    },
    {
      "x": -10,
      "y": 6,
      "z": 6,
      "name": "Rock_Stone"
    },
    {
      "x": -10,
      "y": 7,
      "z": 6,
      "name": "Rock_Stone"
    },
    {
      "x": -10,
      "y": 8,
      "z": 6,
      "name": "Rock_Stone"
    },
    {
      "x": -10,
      "y": 9,
      "z": 6,
      "name": "Rock_Stone"
    },
    {
      "x": -10,
      "y": 10,
      "z": 6,
      "name": "Rock_Stone"
    },
    {
      "x": -10,
      "y": 11,
      "z": 6,
      "name": "Rock_Stone"
    },
    {
      "x": -10,
      "y": 12,
      "z": 6,
      "name": "Rock_Stone"
    },
    {
      "x": -10,
      "y": 13,
      "z": 6,
      "name": "Rock_Stone"
    },
    {
      "x": -10,
      "y": -1,
      "z": 7,
      "name": "Rock_Stone"
    },
    {
      "x": -10,
      "y": 0,
      "z": 7,
      "name": "Rock_Stone"
    },
    {
      "x": -10,
      "y": 1,
      "z": 7,
      "name": "Rock_Stone"
    },
    {
      "x": -10,
      "y": 2,
      "z": 7,
      "name": "Rock_Stone"
    },
    {
      "x": -10,
      "y": 3,
      "z": 7,
      "name": "Rock_Stone"
    },
    {
      "x": -10,
      "y": 4,
      "z": 7,
      "name": "Rock_Stone"
    },
    {
      "x": -10,
      "y": 5,
      "z": 7,
      "name": "Rock_Stone"
    },
    {
      "x": -10,
      "y": 6,
      "z": 7,
      "name": "Rock_Stone"
    },
    {
      "x": -10,
      "y": 7,
      "z": 7,
      "name": "Rock_Stone"
    },
    {
      "x": -10,
      "y": 8,
      "z": 7,
      "name": "Rock_Stone"
    },
    {
      "x": -10,
      "y": 9,
      "z": 7,
      "name": "Rock_Stone"
    },
    {
      "x": -10,
      "y": 10,
      "z": 7,
      "name": "Rock_Stone"
    },
    {
      "x": -10,
      "y": 11,
      "z": 7,
      "name": "Rock_Stone"
    },
    {
      "x": -10,
      "y": 12,
      "z": 7,
      "name": "Rock_Stone"
    },
    {
      "x": -10,
      "y": 13,
      "z": 7,
      "name": "Rock_Stone"
    },
    {
      "x": -10,
      "y": -1,
      "z": 8,
      "name": "Rock_Stone"
    },
    {
      "x": -10,
      "y": 0,
      "z": 8,
      "name": "Rock_Stone"
    },
    {
      "x": -10,
      "y": 1,
      "z": 8,
      "name": "Rock_Stone"
    },
    {
      "x": -10,
      "y": 2,
      "z": 8,
      "name": "Rock_Stone"
    },
    {
      "x": -10,
      "y": 3,
      "z": 8,
      "name": "Rock_Stone"
    },
    {
      "x": -10,
      "y": 4,
      "z": 8,
      "name": "Rock_Stone"
    },
    {
      "x": -10,
      "y": 5,
      "z": 8,
      "name": "Rock_Stone"
    },
    {
      "x": -10,
      "y": 6,
      "z": 8,
      "name": "Rock_Stone"
    },
    {
      "x": -10,
      "y": 7,
      "z": 8,
      "name": "Rock_Stone"
    },
    {
      "x": -10,
      "y": 8,
      "z": 8,
      "name": "Rock_Stone"
    },
    {
      "x": -10,
      "y": 9,
      "z": 8,
      "name": "Rock_Stone"
    },
    {
      "x": -10,
      "y": 10,
      "z": 8,
      "name": "Rock_Stone"
    },
    {
      "x": -10,
      "y": 11,
      "z": 8,
      "name": "Rock_Stone"
    },
    {
      "x": -10,
      "y": 12,
      "z": 8,
      "name": "Rock_Stone"
    },
    {
      "x": -10,
      "y": 13,
      "z": 8,
      "name": "Rock_Stone"
    },
    {
      "x": -10,
      "y": -1,
      "z": 9,
      "name": "Rock_Stone"
    },
    {
      "x": -10,
      "y": 0,
      "z": 9,
      "name": "Rock_Stone"
    },
    {
      "x": -10,
      "y": 1,
      "z": 9,
      "name": "Rock_Stone"
    },
    {
      "x": -10,
      "y": 2,
      "z": 9,
      "name": "Rock_Stone"
    },
    {
      "x": -10,
      "y": 3,
      "z": 9,
      "name": "Rock_Stone"
    },
    {
      "x": -10,
      "y": 4,
      "z": 9,
      "name": "Rock_Stone"
    },
    {
      "x": -10,
      "y": 5,
      "z": 9,
      "name": "Rock_Stone"
    },
    {
      "x": -10,
      "y": 6,
      "z": 9,
      "name": "Rock_Stone"
    },
    {
      "x": -10,
      "y": 7,
      "z": 9,
      "name": "Rock_Stone"
    },
    {
      "x": -10,
      "y": 8,
      "z": 9,
      "name": "Rock_Stone"
    },
    {
      "x": -10,
      "y": 9,
      "z": 9,
      "name": "Rock_Stone"
    },
    {
      "x": -10,
      "y": 10,
      "z": 9,
      "name": "Rock_Stone"
    },
    {
      "x": -10,
      "y": 11,
      "z": 9,
      "name": "Rock_Stone"
    },
    {
      "x": -10,
      "y": 12,
      "z": 9,
      "name": "Rock_Stone"
    },
    {
      "x": -10,
      "y": 13,
      "z": 9,
      "name": "Rock_Stone"
    },
    {
      "x": -10,
      "y": -1,
      "z": 10,
      "name": "Rock_Stone"
    },
    {
      "x": -10,
      "y": 0,
      "z": 10,
      "name": "Rock_Stone"
    },
    {
      "x": -10,
      "y": 1,
      "z": 10,
      "name": "Rock_Stone"
    },
    {
      "x": -10,
      "y": 2,
      "z": 10,
      "name": "Rock_Stone"
    },
    {
      "x": -10,
      "y": 3,
      "z": 10,
      "name": "Rock_Stone"
    },
    {
      "x": -10,
      "y": 4,
      "z": 10,
      "name": "Rock_Stone"
    },
    {
      "x": -10,
      "y": 5,
      "z": 10,
      "name": "Rock_Stone"
    },
    {
      "x": -10,
      "y": 6,
      "z": 10,
      "name": "Rock_Stone"
    },
    {
      "x": -10,
      "y": 7,
      "z": 10,
      "name": "Rock_Stone"
    },
    {
      "x": -10,
      "y": 8,
      "z": 10,
      "name": "Rock_Stone"
    },
    {
      "x": -10,
      "y": 9,
      "z": 10,
      "name": "Rock_Stone"
    },
    {
      "x": -10,
      "y": 10,
      "z": 10,
      "name": "Rock_Stone"
    },
    {
      "x": -10,
      "y": 11,
      "z": 10,
      "name": "Rock_Stone"
    },
    {
      "x": -10,
      "y": 12,
      "z": 10,
      "name": "Rock_Stone"
    },
    {
      "x": -10,
      "y": 13,
      "z": 10,
      "name": "Rock_Stone"
    },
    {
      "x": -9,
      "y": -1,
      "z": -10,
      "name": "Rock_Stone"
    },
    {
      "x": -9,
      "y": 0,
      "z": -10,
      "name": "Rock_Stone"
    },
    {
      "x": -9,
      "y": 1,
      "z": -10,
      "name": "Rock_Stone"
    },
    {
      "x": -9,
      "y": 2,
      "z": -10,
      "name": "Rock_Stone"
    },
    {
      "x": -9,
      "y": 3,
      "z": -10,
      "name": "Rock_Stone"
    },
    {
      "x": -9,
      "y": 4,
      "z": -10,
      "name": "Rock_Stone"
    },
    {
      "x": -9,
      "y": 5,
      "z": -10,
      "name": "Rock_Stone"
    },
    {
      "x": -9,
      "y": 6,
      "z": -10,
      "name": "Rock_Stone"
    },
    {
      "x": -9,
      "y": 7,
      "z": -10,
      "name": "Rock_Stone"
    },
    {
      "x": -9,
      "y": 8,
      "z": -10,
      "name": "Rock_Stone"
    },
    {
      "x": -9,
      "y": 9,
      "z": -10,
      "name": "Rock_Stone"
    },
    {
      "x": -9,
      "y": 10,
      "z": -10,
      "name": "Rock_Stone"
    },
    {
      "x": -9,
      "y": 11,
      "z": -10,
      "name": "Rock_Stone"
    },
    {
      "x": -9,
      "y": 12,
      "z": -10,
      "name": "Rock_Stone"
    },
    {
      "x": -9,
      "y": 13,
      "z": -10,
      "name": "Rock_Stone"
    },
    {
      "x": -9,
      "y": -1,
      "z": -9,
      "name": "Rock_Stone"
    },
    {
      "x": -9,
      "y": 0,
      "z": -9,
      "name": "Rock_Stone"
    },
    {
      "x": -9,
      "y": 1,
      "z": -9,
      "name": "Rock_Stone"
    },
    {
      "x": -9,
      "y": 2,
      "z": -9,
      "name": "Rock_Stone"
    },
    {
      "x": -9,
      "y": 3,
      "z": -9,
      "name": "Rock_Stone"
    },
    {
      "x": -9,
      "y": 4,
      "z": -9,
      "name": "Rock_Stone"
    },
    {
      "x": -9,
      "y": 5,
      "z": -9,
      "name": "Rock_Stone"
    },
    {
      "x": -9,
      "y": 6,
      "z": -9,
      "name": "Rock_Stone"
    },
    {
      "x": -9,
      "y": 7,
      "z": -9,
      "name": "Rock_Stone"
    },
    {
      "x": -9,
      "y": 8,
      "z": -9,
      "name": "Rock_Stone"
    },
    {
      "x": -9,
      "y": 9,
      "z": -9,
      "name": "Rock_Stone"
    },
    {
      "x": -9,
      "y": 10,
      "z": -9,
      "name": "Rock_Stone"
    },
    {
      "x": -9,
      "y": 11,
      "z": -9,
      "name": "Rock_Stone"
    },
    {
      "x": -9,
      "y": 12,
      "z": -9,
      "name": "Rock_Stone"
    },
    {
      "x": -9,
      "y": 13,
      "z": -9,
      "name": "Rock_Stone"
    },
    {
      "x": -9,
      "y": -1,
      "z": -8,
      "name": "Rock_Stone"
    },
    {
      "x": -9,
      "y": 0,
      "z": -8,
      "name": "Rock_Stone"
    },
    {
      "x": -9,
      "y": 1,
      "z": -8,
      "name": "Rock_Stone"
    },
    {
      "x": -9,
      "y": 2,
      "z": -8,
      "name": "Rock_Stone"
    },
    {
      "x": -9,
      "y": 3,
      "z": -8,
      "name": "Rock_Stone"
    },
    {
      "x": -9,
      "y": 4,
      "z": -8,
      "name": "Rock_Stone"
    },
    {
      "x": -9,
      "y": 5,
      "z": -8,
      "name": "Rock_Stone"
    },
    {
      "x": -9,
      "y": 6,
      "z": -8,
      "name": "Rock_Stone"
    },
    {
      "x": -9,
      "y": 7,
      "z": -8,
      "name": "Rock_Stone"
    },
    {
      "x": -9,
      "y": 8,
      "z": -8,
      "name": "Rock_Stone"
    },
    {
      "x": -9,
      "y": 9,
      "z": -8,
      "name": "Rock_Stone"
    },
    {
      "x": -9,
      "y": 10,
      "z": -8,
      "name": "Rock_Stone"
    },
    {
      "x": -9,
      "y": 11,
      "z": -8,
      "name": "Rock_Stone"
    },
    {
      "x": -9,
      "y": 12,
      "z": -8,
      "name": "Rock_Stone"
    },
    {
      "x": -9,
      "y": 13,
      "z": -8,
      "name": "Rock_Stone"
    },
    {
      "x": -9,
      "y": -1,
      "z": -7,
      "name": "Rock_Stone"
    },
    {
      "x": -9,
      "y": 0,
      "z": -7,
      "name": "Rock_Stone"
    },
    {
      "x": -9,
      "y": 1,
      "z": -7,
      "name": "Rock_Stone"
    },
    {
      "x": -9,
      "y": 2,
      "z": -7,
      "name": "Rock_Stone"
    },
    {
      "x": -9,
      "y": 3,
      "z": -7,
      "name": "Rock_Stone"
    },
    {
      "x": -9,
      "y": 4,
      "z": -7,
      "name": "Rock_Stone"
    },
    {
      "x": -9,
      "y": 5,
      "z": -7,
      "name": "Rock_Stone"
    },
    {
      "x": -9,
      "y": 6,
      "z": -7,
      "name": "Rock_Stone"
    },
    {
      "x": -9,
      "y": 7,
      "z": -7,
      "name": "Rock_Stone"
    },
    {
      "x": -9,
      "y": 8,
      "z": -7,
      "name": "Rock_Stone"
    },
    {
      "x": -9,
      "y": 9,
      "z": -7,
      "name": "Rock_Stone"
    },
    {
      "x": -9,
      "y": 10,
      "z": -7,
      "name": "Rock_Stone"
    },
    {
      "x": -9,
      "y": 11,
      "z": -7,
      "name": "Rock_Stone"
    },
    {
      "x": -9,
      "y": 12,
      "z": -7,
      "name": "Rock_Stone"
    },
    {
      "x": -9,
      "y": 13,
      "z": -7,
      "name": "Rock_Stone"
    },
    {
      "x": -9,
      "y": -1,
      "z": -6,
      "name": "Rock_Stone"
    },
    {
      "x": -9,
      "y": 0,
      "z": -6,
      "name": "Rock_Stone"
    },
    {
      "x": -9,
      "y": 1,
      "z": -6,
      "name": "Rock_Stone"
    },
    {
      "x": -9,
      "y": 2,
      "z": -6,
      "name": "Rock_Stone"
    },
    {
      "x": -9,
      "y": 3,
      "z": -6,
      "name": "Rock_Stone"
    },
    {
      "x": -9,
      "y": 4,
      "z": -6,
      "name": "Rock_Stone"
    },
    {
      "x": -9,
      "y": 5,
      "z": -6,
      "name": "Rock_Stone"
    },
    {
      "x": -9,
      "y": 6,
      "z": -6,
      "name": "Rock_Stone"
    },
    {
      "x": -9,
      "y": 7,
      "z": -6,
      "name": "Rock_Stone"
    },
    {
      "x": -9,
      "y": 8,
      "z": -6,
      "name": "Rock_Stone"
    },
    {
      "x": -9,
      "y": 9,
      "z": -6,
      "name": "Rock_Stone"
    },
    {
      "x": -9,
      "y": 10,
      "z": -6,
      "name": "Rock_Stone"
    },
    {
      "x": -9,
      "y": 11,
      "z": -6,
      "name": "Rock_Stone"
    },
    {
      "x": -9,
      "y": 12,
      "z": -6,
      "name": "Rock_Stone"
    },
    {
      "x": -9,
      "y": 13,
      "z": -6,
      "name": "Rock_Stone"
    },
    {
      "x": -9,
      "y": -1,
      "z": -5,
      "name": "Rock_Stone"
    },
    {
      "x": -9,
      "y": 0,
      "z": -5,
      "name": "Rock_Stone"
    },
    {
      "x": -9,
      "y": 1,
      "z": -5,
      "name": "Rock_Stone"
    },
    {
      "x": -9,
      "y": 2,
      "z": -5,
      "name": "Rock_Stone"
    },
    {
      "x": -9,
      "y": 3,
      "z": -5,
      "name": "Rock_Stone"
    },
    {
      "x": -9,
      "y": 4,
      "z": -5,
      "name": "Rock_Stone"
    },
    {
      "x": -9,
      "y": 5,
      "z": -5,
      "name": "Rock_Stone"
    },
    {
      "x": -9,
      "y": 6,
      "z": -5,
      "name": "Rock_Stone"
    },
    {
      "x": -9,
      "y": 7,
      "z": -5,
      "name": "Rock_Stone"
    },
    {
      "x": -9,
      "y": 8,
      "z": -5,
      "name": "Rock_Stone"
    },
    {
      "x": -9,
      "y": 9,
      "z": -5,
      "name": "Rock_Stone"
    },
    {
      "x": -9,
      "y": 10,
      "z": -5,
      "name": "Rock_Stone"
    },
    {
      "x": -9,
      "y": 11,
      "z": -5,
      "name": "Rock_Stone"
    },
    {
      "x": -9,
      "y": 12,
      "z": -5,
      "name": "Rock_Stone"
    },
    {
      "x": -9,
      "y": 13,
      "z": -5,
      "name": "Rock_Stone"
    },
    {
      "x": -9,
      "y": -1,
      "z": -4,
      "name": "Rock_Stone"
    },
    {
      "x": -9,
      "y": 0,
      "z": -4,
      "name": "Rock_Stone"
    },
    {
      "x": -9,
      "y": 1,
      "z": -4,
      "name": "Rock_Stone"
    },
    {
      "x": -9,
      "y": 2,
      "z": -4,
      "name": "Rock_Stone"
    },
    {
      "x": -9,
      "y": 3,
      "z": -4,
      "name": "Rock_Stone"
    },
    {
      "x": -9,
      "y": 4,
      "z": -4,
      "name": "Rock_Stone"
    },
    {
      "x": -9,
      "y": 5,
      "z": -4,
      "name": "Rock_Stone"
    },
    {
      "x": -9,
      "y": 6,
      "z": -4,
      "name": "Rock_Stone"
    },
    {
      "x": -9,
      "y": 7,
      "z": -4,
      "name": "Rock_Stone"
    },
    {
      "x": -9,
      "y": 8,
      "z": -4,
      "name": "Rock_Stone"
    },
    {
      "x": -9,
      "y": 9,
      "z": -4,
      "name": "Rock_Stone"
    },
    {
      "x": -9,
      "y": 10,
      "z": -4,
      "name": "Rock_Stone"
    },
    {
      "x": -9,
      "y": 11,
      "z": -4,
      "name": "Rock_Stone"
    },
    {
      "x": -9,
      "y": 12,
      "z": -4,
      "name": "Rock_Stone"
    },
    {
      "x": -9,
      "y": 13,
      "z": -4,
      "name": "Rock_Stone"
    },
    {
      "x": -9,
      "y": -1,
      "z": -3,
      "name": "Rock_Stone"
    },
    {
      "x": -9,
      "y": 0,
      "z": -3,
      "name": "Rock_Stone"
    },
    {
      "x": -9,
      "y": 1,
      "z": -3,
      "name": "Rock_Stone"
    },
    {
      "x": -9,
      "y": 2,
      "z": -3,
      "name": "Rock_Stone"
    },
    {
      "x": -9,
      "y": 3,
      "z": -3,
      "name": "Rock_Stone"
    },
    {
      "x": -9,
      "y": 4,
      "z": -3,
      "name": "Rock_Stone"
    },
    {
      "x": -9,
      "y": 5,
      "z": -3,
      "name": "Rock_Stone"
    },
    {
      "x": -9,
      "y": 6,
      "z": -3,
      "name": "Rock_Stone"
    },
    {
      "x": -9,
      "y": 7,
      "z": -3,
      "name": "Rock_Stone"
    },
    {
      "x": -9,
      "y": 8,
      "z": -3,
      "name": "Rock_Stone"
    },
    {
      "x": -9,
      "y": 9,
      "z": -3,
      "name": "Rock_Stone"
    },
    {
      "x": -9,
      "y": 10,
      "z": -3,
      "name": "Rock_Stone"
    },
    {
      "x": -9,
      "y": 11,
      "z": -3,
      "name": "Rock_Stone"
    },
    {
      "x": -9,
      "y": 12,
      "z": -3,
      "name": "Rock_Stone"
    },
    {
      "x": -9,
      "y": 13,
      "z": -3,
      "name": "Rock_Stone"
    },
    {
      "x": -9,
      "y": -1,
      "z": -2,
      "name": "Rock_Stone"
    },
    {
      "x": -9,
      "y": 0,
      "z": -2,
      "name": "Rock_Stone"
    },
    {
      "x": -9,
      "y": 1,
      "z": -2,
      "name": "Empty"
    },
    {
      "x": -9,
      "y": 2,
      "z": -2,
      "name": "Empty"
    },
    {
      "x": -9,
      "y": 3,
      "z": -2,
      "name": "Empty"
    },
    {
      "x": -9,
      "y": 4,
      "z": -2,
      "name": "Empty"
    },
    {
      "x": -9,
      "y": 5,
      "z": -2,
      "name": "Rock_Stone"
    },
    {
      "x": -9,
      "y": 6,
      "z": -2,
      "name": "Rock_Stone"
    },
    {
      "x": -9,
      "y": 7,
      "z": -2,
      "name": "Rock_Stone"
    },
    {
      "x": -9,
      "y": 8,
      "z": -2,
      "name": "Rock_Stone"
    },
    {
      "x": -9,
      "y": 9,
      "z": -2,
      "name": "Rock_Stone"
    },
    {
      "x": -9,
      "y": 10,
      "z": -2,
      "name": "Rock_Stone"
    },
    {
      "x": -9,
      "y": 11,
      "z": -2,
      "name": "Rock_Stone"
    },
    {
      "x": -9,
      "y": 12,
      "z": -2,
      "name": "Rock_Stone"
    },
    {
      "x": -9,
      "y": 13,
      "z": -2,
      "name": "Rock_Stone"
    },
    {
      "x": -9,
      "y": -1,
      "z": -1,
      "name": "Rock_Stone"
    },
    {
      "x": -9,
      "y": 0,
      "z": -1,
      "name": "Soil_Gravel"
    },
    {
      "x": -9,
      "y": 1,
      "z": -1,
      "name": "Empty"
    },
    {
      "x": -9,
      "y": 2,
      "z": -1,
      "name": "Empty"
    },
    {
      "x": -9,
      "y": 3,
      "z": -1,
      "name": "Empty"
    },
    {
      "x": -9,
      "y": 4,
      "z": -1,
      "name": "Empty"
    },
    {
      "x": -9,
      "y": 5,
      "z": -1,
      "name": "Empty"
    },
    {
      "x": -9,
      "y": 6,
      "z": -1,
      "name": "Empty"
    },
    {
      "x": -9,
      "y": 7,
      "z": -1,
      "name": "Rock_Stone"
    },
    {
      "x": -9,
      "y": 8,
      "z": -1,
      "name": "Rock_Stone"
    },
    {
      "x": -9,
      "y": 9,
      "z": -1,
      "name": "Rock_Stone"
    },
    {
      "x": -9,
      "y": 10,
      "z": -1,
      "name": "Rock_Stone"
    },
    {
      "x": -9,
      "y": 11,
      "z": -1,
      "name": "Rock_Stone"
    },
    {
      "x": -9,
      "y": 12,
      "z": -1,
      "name": "Rock_Stone"
    },
    {
      "x": -9,
      "y": 13,
      "z": -1,
      "name": "Rock_Stone"
    },
    {
      "x": -9,
      "y": -1,
      "z": 0,
      "name": "Rock_Stone"
    },
    {
      "x": -9,
      "y": 0,
      "z": 0,
      "name": "Soil_Gravel"
    },
    {
      "x": -9,
      "y": 1,
      "z": 0,
      "name": "Rail",
      "rotation": 1
    },
    {
      "x": -9,
      "y": 2,
      "z": 0,
      "name": "Empty"
    },
    {
      "x": -9,
      "y": 3,
      "z": 0,
      "name": "Empty"
    },
    {
      "x": -9,
      "y": 4,
      "z": 0,
      "name": "Empty"
    },
    {
      "x": -9,
      "y": 5,
      "z": 0,
      "name": "Empty"
    },
    {
      "x": -9,
      "y": 6,
      "z": 0,
      "name": "Empty"
    },
    {
      "x": -9,
      "y": 7,
      "z": 0,
      "name": "Rock_Stone"
    },
    {
      "x": -9,
      "y": 8,
      "z": 0,
      "name": "Rock_Stone"
    },
    {
      "x": -9,
      "y": 9,
      "z": 0,
      "name": "Rock_Stone"
    },
    {
      "x": -9,
      "y": 10,
      "z": 0,
      "name": "Rock_Stone"
    },
    {
      "x": -9,
      "y": 11,
      "z": 0,
      "name": "Rock_Stone"
    },
    {
      "x": -9,
      "y": 12,
      "z": 0,
      "name": "Rock_Stone"
    },
    {
      "x": -9,
      "y": 13,
      "z": 0,
      "name": "Rock_Stone"
    },
    {
      "x": -9,
      "y": -1,
      "z": 1,
      "name": "Rock_Stone"
    },
    {
      "x": -9,
      "y": 0,
      "z": 1,
      "name": "Rock_Stone"
    },
    {
      "x": -9,
      "y": 1,
      "z": 1,
      "name": "Empty"
    },
    {
      "x": -9,
      "y": 2,
      "z": 1,
      "name": "Empty"
    },
    {
      "x": -9,
      "y": 3,
      "z": 1,
      "name": "Empty"
    },
    {
      "x": -9,
      "y": 4,
      "z": 1,
      "name": "Empty"
    },
    {
      "x": -9,
      "y": 5,
      "z": 1,
      "name": "Empty"
    },
    {
      "x": -9,
      "y": 6,
      "z": 1,
      "name": "Empty"
    },
    {
      "x": -9,
      "y": 7,
      "z": 1,
      "name": "Rock_Stone"
    },
    {
      "x": -9,
      "y": 8,
      "z": 1,
      "name": "Rock_Stone"
    },
    {
      "x": -9,
      "y": 9,
      "z": 1,
      "name": "Rock_Stone"
    },
    {
      "x": -9,
      "y": 10,
      "z": 1,
      "name": "Rock_Stone"
    },
    {
      "x": -9,
      "y": 11,
      "z": 1,
      "name": "Rock_Stone"
    },
    {
      "x": -9,
      "y": 12,
      "z": 1,
      "name": "Rock_Stone"
    },
    {
      "x": -9,
      "y": 13,
      "z": 1,
      "name": "Rock_Stone"
    },
    {
      "x": -9,
      "y": -1,
      "z": 2,
      "name": "Rock_Stone"
    },
    {
      "x": -9,
      "y": 0,
      "z": 2,
      "name": "Rock_Stone"
    },
    {
      "x": -9,
      "y": 1,
      "z": 2,
      "name": "Rock_Stone"
    },
    {
      "x": -9,
      "y": 2,
      "z": 2,
      "name": "Rock_Stone"
    },
    {
      "x": -9,
      "y": 3,
      "z": 2,
      "name": "Empty"
    },
    {
      "x": -9,
      "y": 4,
      "z": 2,
      "name": "Empty"
    },
    {
      "x": -9,
      "y": 5,
      "z": 2,
      "name": "Empty"
    },
    {
      "x": -9,
      "y": 6,
      "z": 2,
      "name": "Rock_Stone"
    },
    {
      "x": -9,
      "y": 7,
      "z": 2,
      "name": "Rock_Stone"
    },
    {
      "x": -9,
      "y": 8,
      "z": 2,
      "name": "Rock_Stone"
    },
    {
      "x": -9,
      "y": 9,
      "z": 2,
      "name": "Rock_Stone"
    },
    {
      "x": -9,
      "y": 10,
      "z": 2,
      "name": "Rock_Stone"
    },
    {
      "x": -9,
      "y": 11,
      "z": 2,
      "name": "Rock_Stone"
    },
    {
      "x": -9,
      "y": 12,
      "z": 2,
      "name": "Rock_Stone"
    },
    {
      "x": -9,
      "y": 13,
      "z": 2,
      "name": "Rock_Stone"
    },
    {
      "x": -9,
      "y": -1,
      "z": 3,
      "name": "Rock_Stone"
    },
    {
      "x": -9,
      "y": 0,
      "z": 3,
      "name": "Rock_Stone"
    },
    {
      "x": -9,
      "y": 1,
      "z": 3,
      "name": "Rock_Stone"
    },
    {
      "x": -9,
      "y": 2,
      "z": 3,
      "name": "Rock_Stone"
    },
    {
      "x": -9,
      "y": 3,
      "z": 3,
      "name": "Rock_Stone"
    },
    {
      "x": -9,
      "y": 4,
      "z": 3,
      "name": "Empty"
    },
    {
      "x": -9,
      "y": 5,
      "z": 3,
      "name": "Empty"
    },
    {
      "x": -9,
      "y": 6,
      "z": 3,
      "name": "Rock_Stone"
    },
    {
      "x": -9,
      "y": 7,
      "z": 3,
      "name": "Rock_Stone"
    },
    {
      "x": -9,
      "y": 8,
      "z": 3,
      "name": "Rock_Stone"
    },
    {
      "x": -9,
      "y": 9,
      "z": 3,
      "name": "Rock_Stone"
    },
    {
      "x": -9,
      "y": 10,
      "z": 3,
      "name": "Rock_Stone"
    },
    {
      "x": -9,
      "y": 11,
      "z": 3,
      "name": "Rock_Stone"
    },
    {
      "x": -9,
      "y": 12,
      "z": 3,
      "name": "Rock_Stone"
    },
    {
      "x": -9,
      "y": 13,
      "z": 3,
      "name": "Rock_Stone"
    },
    {
      "x": -9,
      "y": -1,
      "z": 4,
      "name": "Rock_Stone"
    },
    {
      "x": -9,
      "y": 0,
      "z": 4,
      "name": "Rock_Stone"
    },
    {
      "x": -9,
      "y": 1,
      "z": 4,
      "name": "Rock_Stone"
    },
    {
      "x": -9,
      "y": 2,
      "z": 4,
      "name": "Rock_Stone"
    },
    {
      "x": -9,
      "y": 3,
      "z": 4,
      "name": "Rock_Stone"
    },
    {
      "x": -9,
      "y": 4,
      "z": 4,
      "name": "Rock_Stone"
    },
    {
      "x": -9,
      "y": 5,
      "z": 4,
      "name": "Rock_Stone"
    },
    {
      "x": -9,
      "y": 6,
      "z": 4,
      "name": "Rock_Stone"
    },
    {
      "x": -9,
      "y": 7,
      "z": 4,
      "name": "Rock_Stone"
    },
    {
      "x": -9,
      "y": 8,
      "z": 4,
      "name": "Rock_Stone"
    },
    {
      "x": -9,
      "y": 9,
      "z": 4,
      "name": "Rock_Stone"
    },
    {
      "x": -9,
      "y": 10,
      "z": 4,
      "name": "Rock_Stone"
    },
    {
      "x": -9,
      "y": 11,
      "z": 4,
      "name": "Rock_Stone"
    },
    {
      "x": -9,
      "y": 12,
      "z": 4,
      "name": "Rock_Stone"
    },
    {
      "x": -9,
      "y": 13,
      "z": 4,
      "name": "Rock_Stone"
    },
    {
      "x": -9,
      "y": -1,
      "z": 5,
      "name": "Rock_Stone"
    },
    {
      "x": -9,
      "y": 0,
      "z": 5,
      "name": "Rock_Stone"
    },
    {
      "x": -9,
      "y": 1,
      "z": 5,
      "name": "Rock_Stone"
    },
    {
      "x": -9,
      "y": 2,
      "z": 5,
      "name": "Rock_Stone"
    },
    {
      "x": -9,
      "y": 3,
      "z": 5,
      "name": "Rock_Stone"
    },
    {
      "x": -9,
      "y": 4,
      "z": 5,
      "name": "Rock_Stone"
    },
    {
      "x": -9,
      "y": 5,
      "z": 5,
      "name": "Rock_Stone"
    },
    {
      "x": -9,
      "y": 6,
      "z": 5,
      "name": "Rock_Stone"
    },
    {
      "x": -9,
      "y": 7,
      "z": 5,
      "name": "Rock_Stone"
    },
    {
      "x": -9,
      "y": 8,
      "z": 5,
      "name": "Rock_Stone"
    },
    {
      "x": -9,
      "y": 9,
      "z": 5,
      "name": "Rock_Stone"
    },
    {
      "x": -9,
      "y": 10,
      "z": 5,
      "name": "Rock_Stone"
    },
    {
      "x": -9,
      "y": 11,
      "z": 5,
      "name": "Rock_Stone"
    },
    {
      "x": -9,
      "y": 12,
      "z": 5,
      "name": "Rock_Stone"
    },
    {
      "x": -9,
      "y": 13,
      "z": 5,
      "name": "Rock_Stone"
    },
    {
      "x": -9,
      "y": -1,
      "z": 6,
      "name": "Rock_Stone"
    },
    {
      "x": -9,
      "y": 0,
      "z": 6,
      "name": "Rock_Stone"
    },
    {
      "x": -9,
      "y": 1,
      "z": 6,
      "name": "Rock_Stone"
    },
    {
      "x": -9,
      "y": 2,
      "z": 6,
      "name": "Rock_Stone"
    },
    {
      "x": -9,
      "y": 3,
      "z": 6,
      "name": "Rock_Stone"
    },
    {
      "x": -9,
      "y": 4,
      "z": 6,
      "name": "Rock_Stone"
    },
    {
      "x": -9,
      "y": 5,
      "z": 6,
      "name": "Rock_Stone"
    },
    {
      "x": -9,
      "y": 6,
      "z": 6,
      "name": "Rock_Stone"
    },
    {
      "x": -9,
      "y": 7,
      "z": 6,
      "name": "Rock_Stone"
    },
    {
      "x": -9,
      "y": 8,
      "z": 6,
      "name": "Rock_Stone"
    },
    {
      "x": -9,
      "y": 9,
      "z": 6,
      "name": "Rock_Stone"
    },
    {
      "x": -9,
      "y": 10,
      "z": 6,
      "name": "Rock_Stone"
    },
    {
      "x": -9,
      "y": 11,
      "z": 6,
      "name": "Rock_Stone"
    },
    {
      "x": -9,
      "y": 12,
      "z": 6,
      "name": "Rock_Stone"
    },
    {
      "x": -9,
      "y": 13,
      "z": 6,
      "name": "Rock_Stone"
    },
    {
      "x": -9,
      "y": -1,
      "z": 7,
      "name": "Rock_Stone"
    },
    {
      "x": -9,
      "y": 0,
      "z": 7,
      "name": "Rock_Stone"
    },
    {
      "x": -9,
      "y": 1,
      "z": 7,
      "name": "Rock_Stone"
    },
    {
      "x": -9,
      "y": 2,
      "z": 7,
      "name": "Rock_Stone"
    },
    {
      "x": -9,
      "y": 3,
      "z": 7,
      "name": "Rock_Stone"
    },
    {
      "x": -9,
      "y": 4,
      "z": 7,
      "name": "Rock_Stone"
    },
    {
      "x": -9,
      "y": 5,
      "z": 7,
      "name": "Rock_Stone"
    },
    {
      "x": -9,
      "y": 6,
      "z": 7,
      "name": "Rock_Stone"
    },
    {
      "x": -9,
      "y": 7,
      "z": 7,
      "name": "Rock_Stone"
    },
    {
      "x": -9,
      "y": 8,
      "z": 7,
      "name": "Rock_Stone"
    },
    {
      "x": -9,
      "y": 9,
      "z": 7,
      "name": "Rock_Stone"
    },
    {
      "x": -9,
      "y": 10,
      "z": 7,
      "name": "Rock_Stone"
    },
    {
      "x": -9,
      "y": 11,
      "z": 7,
      "name": "Rock_Stone"
    },
    {
      "x": -9,
      "y": 12,
      "z": 7,
      "name": "Rock_Stone"
    },
    {
      "x": -9,
      "y": 13,
      "z": 7,
      "name": "Rock_Stone"
    },
    {
      "x": -9,
      "y": -1,
      "z": 8,
      "name": "Rock_Stone"
    },
    {
      "x": -9,
      "y": 0,
      "z": 8,
      "name": "Rock_Stone"
    },
    {
      "x": -9,
      "y": 1,
      "z": 8,
      "name": "Rock_Stone"
    },
    {
      "x": -9,
      "y": 2,
      "z": 8,
      "name": "Rock_Stone"
    },
    {
      "x": -9,
      "y": 3,
      "z": 8,
      "name": "Rock_Stone"
    },
    {
      "x": -9,
      "y": 4,
      "z": 8,
      "name": "Rock_Stone"
    },
    {
      "x": -9,
      "y": 5,
      "z": 8,
      "name": "Rock_Stone"
    },
    {
      "x": -9,
      "y": 6,
      "z": 8,
      "name": "Rock_Stone"
    },
    {
      "x": -9,
      "y": 7,
      "z": 8,
      "name": "Rock_Stone"
    },
    {
      "x": -9,
      "y": 8,
      "z": 8,
      "name": "Rock_Stone"
    },
    {
      "x": -9,
      "y": 9,
      "z": 8,
      "name": "Rock_Stone"
    },
    {
      "x": -9,
      "y": 10,
      "z": 8,
      "name": "Rock_Stone"
    },
    {
      "x": -9,
      "y": 11,
      "z": 8,
      "name": "Rock_Stone"
    },
    {
      "x": -9,
      "y": 12,
      "z": 8,
      "name": "Rock_Stone"
    },
    {
      "x": -9,
      "y": 13,
      "z": 8,
      "name": "Rock_Stone"
    },
    {
      "x": -9,
      "y": -1,
      "z": 9,
      "name": "Rock_Stone"
    },
    {
      "x": -9,
      "y": 0,
      "z": 9,
      "name": "Rock_Stone"
    },
    {
      "x": -9,
      "y": 1,
      "z": 9,
      "name": "Rock_Stone"
    },
    {
      "x": -9,
      "y": 2,
      "z": 9,
      "name": "Rock_Stone"
    },
    {
      "x": -9,
      "y": 3,
      "z": 9,
      "name": "Rock_Stone"
    },
    {
      "x": -9,
      "y": 4,
      "z": 9,
      "name": "Rock_Stone"
    },
    {
      "x": -9,
      "y": 5,
      "z": 9,
      "name": "Rock_Stone"
    },
    {
      "x": -9,
      "y": 6,
      "z": 9,
      "name": "Rock_Stone"
    },
    {
      "x": -9,
      "y": 7,
      "z": 9,
      "name": "Rock_Stone"
    },
    {
      "x": -9,
      "y": 8,
      "z": 9,
      "name": "Rock_Stone"
    },
    {
      "x": -9,
      "y": 9,
      "z": 9,
      "name": "Rock_Stone"
    },
    {
      "x": -9,
      "y": 10,
      "z": 9,
      "name": "Rock_Stone"
    },
    {
      "x": -9,
      "y": 11,
      "z": 9,
      "name": "Rock_Stone"
    },
    {
      "x": -9,
      "y": 12,
      "z": 9,
      "name": "Rock_Stone"
    },
    {
      "x": -9,
      "y": 13,
      "z": 9,
      "name": "Rock_Stone"
    },
    {
      "x": -9,
      "y": -1,
      "z": 10,
      "name": "Rock_Stone"
    },
    {
      "x": -9,
      "y": 0,
      "z": 10,
      "name": "Rock_Stone"
    },
    {
      "x": -9,
      "y": 1,
      "z": 10,
      "name": "Rock_Stone"
    },
    {
      "x": -9,
      "y": 2,
      "z": 10,
      "name": "Rock_Stone"
    },
    {
      "x": -9,
      "y": 3,
      "z": 10,
      "name": "Rock_Stone"
    },
    {
      "x": -9,
      "y": 4,
      "z": 10,
      "name": "Rock_Stone"
    },
    {
      "x": -9,
      "y": 5,
      "z": 10,
      "name": "Rock_Stone"
    },
    {
      "x": -9,
      "y": 6,
      "z": 10,
      "name": "Rock_Stone"
    },
    {
      "x": -9,
      "y": 7,
      "z": 10,
      "name": "Rock_Stone"
    },
    {
      "x": -9,
      "y": 8,
      "z": 10,
      "name": "Rock_Stone"
    },
    {
      "x": -9,
      "y": 9,
      "z": 10,
      "name": "Rock_Stone"
    },
    {
      "x": -9,
      "y": 10,
      "z": 10,
      "name": "Rock_Stone"
    },
    {
      "x": -9,
      "y": 11,
      "z": 10,
      "name": "Rock_Stone"
    },
    {
      "x": -9,
      "y": 12,
      "z": 10,
      "name": "Rock_Stone"
    },
    {
      "x": -9,
      "y": 13,
      "z": 10,
      "name": "Rock_Stone"
    },
    {
      "x": -8,
      "y": -1,
      "z": -10,
      "name": "Rock_Stone"
    },
    {
      "x": -8,
      "y": 0,
      "z": -10,
      "name": "Rock_Stone"
    },
    {
      "x": -8,
      "y": 1,
      "z": -10,
      "name": "Rock_Stone"
    },
    {
      "x": -8,
      "y": 2,
      "z": -10,
      "name": "Rock_Stone"
    },
    {
      "x": -8,
      "y": 3,
      "z": -10,
      "name": "Rock_Stone"
    },
    {
      "x": -8,
      "y": 4,
      "z": -10,
      "name": "Rock_Stone"
    },
    {
      "x": -8,
      "y": 5,
      "z": -10,
      "name": "Rock_Stone"
    },
    {
      "x": -8,
      "y": 6,
      "z": -10,
      "name": "Rock_Stone"
    },
    {
      "x": -8,
      "y": 7,
      "z": -10,
      "name": "Rock_Stone"
    },
    {
      "x": -8,
      "y": 8,
      "z": -10,
      "name": "Rock_Stone"
    },
    {
      "x": -8,
      "y": 9,
      "z": -10,
      "name": "Rock_Stone"
    },
    {
      "x": -8,
      "y": 10,
      "z": -10,
      "name": "Rock_Stone"
    },
    {
      "x": -8,
      "y": 11,
      "z": -10,
      "name": "Rock_Stone"
    },
    {
      "x": -8,
      "y": 12,
      "z": -10,
      "name": "Rock_Stone"
    },
    {
      "x": -8,
      "y": 13,
      "z": -10,
      "name": "Rock_Stone"
    },
    {
      "x": -8,
      "y": -1,
      "z": -9,
      "name": "Rock_Stone"
    },
    {
      "x": -8,
      "y": 0,
      "z": -9,
      "name": "Rock_Stone"
    },
    {
      "x": -8,
      "y": 1,
      "z": -9,
      "name": "Rock_Stone"
    },
    {
      "x": -8,
      "y": 2,
      "z": -9,
      "name": "Rock_Stone"
    },
    {
      "x": -8,
      "y": 3,
      "z": -9,
      "name": "Rock_Stone"
    },
    {
      "x": -8,
      "y": 4,
      "z": -9,
      "name": "Rock_Stone"
    },
    {
      "x": -8,
      "y": 5,
      "z": -9,
      "name": "Rock_Stone"
    },
    {
      "x": -8,
      "y": 6,
      "z": -9,
      "name": "Rock_Stone"
    },
    {
      "x": -8,
      "y": 7,
      "z": -9,
      "name": "Rock_Stone"
    },
    {
      "x": -8,
      "y": 8,
      "z": -9,
      "name": "Rock_Stone"
    },
    {
      "x": -8,
      "y": 9,
      "z": -9,
      "name": "Rock_Stone"
    },
    {
      "x": -8,
      "y": 10,
      "z": -9,
      "name": "Rock_Stone"
    },
    {
      "x": -8,
      "y": 11,
      "z": -9,
      "name": "Rock_Stone"
    },
    {
      "x": -8,
      "y": 12,
      "z": -9,
      "name": "Rock_Stone"
    },
    {
      "x": -8,
      "y": 13,
      "z": -9,
      "name": "Rock_Stone"
    },
    {
      "x": -8,
      "y": -1,
      "z": -8,
      "name": "Rock_Stone"
    },
    {
      "x": -8,
      "y": 0,
      "z": -8,
      "name": "Rock_Stone"
    },
    {
      "x": -8,
      "y": 1,
      "z": -8,
      "name": "Rock_Stone"
    },
    {
      "x": -8,
      "y": 2,
      "z": -8,
      "name": "Rock_Stone"
    },
    {
      "x": -8,
      "y": 3,
      "z": -8,
      "name": "Rock_Stone"
    },
    {
      "x": -8,
      "y": 4,
      "z": -8,
      "name": "Rock_Stone"
    },
    {
      "x": -8,
      "y": 5,
      "z": -8,
      "name": "Rock_Stone"
    },
    {
      "x": -8,
      "y": 6,
      "z": -8,
      "name": "Rock_Stone"
    },
    {
      "x": -8,
      "y": 7,
      "z": -8,
      "name": "Rock_Stone"
    },
    {
      "x": -8,
      "y": 8,
      "z": -8,
      "name": "Rock_Stone"
    },
    {
      "x": -8,
      "y": 9,
      "z": -8,
      "name": "Rock_Stone"
    },
    {
      "x": -8,
      "y": 10,
      "z": -8,
      "name": "Rock_Stone"
    },
    {
      "x": -8,
      "y": 11,
      "z": -8,
      "name": "Rock_Stone"
    },
    {
      "x": -8,
      "y": 12,
      "z": -8,
      "name": "Rock_Stone"
    },
    {
      "x": -8,
      "y": 13,
      "z": -8,
      "name": "Rock_Stone"
    },
    {
      "x": -8,
      "y": -1,
      "z": -7,
      "name": "Rock_Stone"
    },
    {
      "x": -8,
      "y": 0,
      "z": -7,
      "name": "Rock_Stone"
    },
    {
      "x": -8,
      "y": 1,
      "z": -7,
      "name": "Rock_Stone"
    },
    {
      "x": -8,
      "y": 2,
      "z": -7,
      "name": "Rock_Stone"
    },
    {
      "x": -8,
      "y": 3,
      "z": -7,
      "name": "Rock_Stone"
    },
    {
      "x": -8,
      "y": 4,
      "z": -7,
      "name": "Rock_Stone"
    },
    {
      "x": -8,
      "y": 5,
      "z": -7,
      "name": "Rock_Stone"
    },
    {
      "x": -8,
      "y": 6,
      "z": -7,
      "name": "Rock_Stone"
    },
    {
      "x": -8,
      "y": 7,
      "z": -7,
      "name": "Rock_Stone"
    },
    {
      "x": -8,
      "y": 8,
      "z": -7,
      "name": "Rock_Stone"
    },
    {
      "x": -8,
      "y": 9,
      "z": -7,
      "name": "Rock_Stone"
    },
    {
      "x": -8,
      "y": 10,
      "z": -7,
      "name": "Rock_Stone"
    },
    {
      "x": -8,
      "y": 11,
      "z": -7,
      "name": "Rock_Stone"
    },
    {
      "x": -8,
      "y": 12,
      "z": -7,
      "name": "Rock_Stone"
    },
    {
      "x": -8,
      "y": 13,
      "z": -7,
      "name": "Rock_Stone"
    },
    {
      "x": -8,
      "y": -1,
      "z": -6,
      "name": "Rock_Stone"
    },
    {
      "x": -8,
      "y": 0,
      "z": -6,
      "name": "Rock_Stone"
    },
    {
      "x": -8,
      "y": 1,
      "z": -6,
      "name": "Rock_Stone"
    },
    {
      "x": -8,
      "y": 2,
      "z": -6,
      "name": "Rock_Stone"
    },
    {
      "x": -8,
      "y": 3,
      "z": -6,
      "name": "Rock_Stone"
    },
    {
      "x": -8,
      "y": 4,
      "z": -6,
      "name": "Rock_Stone"
    },
    {
      "x": -8,
      "y": 5,
      "z": -6,
      "name": "Rock_Stone"
    },
    {
      "x": -8,
      "y": 6,
      "z": -6,
      "name": "Rock_Stone"
    },
    {
      "x": -8,
      "y": 7,
      "z": -6,
      "name": "Rock_Stone"
    },
    {
      "x": -8,
      "y": 8,
      "z": -6,
      "name": "Rock_Stone"
    },
    {
      "x": -8,
      "y": 9,
      "z": -6,
      "name": "Rock_Stone"
    },
    {
      "x": -8,
      "y": 10,
      "z": -6,
      "name": "Rock_Stone"
    },
    {
      "x": -8,
      "y": 11,
      "z": -6,
      "name": "Rock_Stone"
    },
    {
      "x": -8,
      "y": 12,
      "z": -6,
      "name": "Rock_Stone"
    },
    {
      "x": -8,
      "y": 13,
      "z": -6,
      "name": "Rock_Stone"
    },
    {
      "x": -8,
      "y": -1,
      "z": -5,
      "name": "Rock_Stone"
    },
    {
      "x": -8,
      "y": 0,
      "z": -5,
      "name": "Rock_Stone"
    },
    {
      "x": -8,
      "y": 1,
      "z": -5,
      "name": "Rock_Stone"
    },
    {
      "x": -8,
      "y": 2,
      "z": -5,
      "name": "Rock_Stone"
    },
    {
      "x": -8,
      "y": 3,
      "z": -5,
      "name": "Rock_Stone"
    },
    {
      "x": -8,
      "y": 4,
      "z": -5,
      "name": "Rock_Stone"
    },
    {
      "x": -8,
      "y": 5,
      "z": -5,
      "name": "Rock_Stone"
    },
    {
      "x": -8,
      "y": 6,
      "z": -5,
      "name": "Rock_Stone"
    },
    {
      "x": -8,
      "y": 7,
      "z": -5,
      "name": "Rock_Stone"
    },
    {
      "x": -8,
      "y": 8,
      "z": -5,
      "name": "Rock_Stone"
    },
    {
      "x": -8,
      "y": 9,
      "z": -5,
      "name": "Rock_Stone"
    },
    {
      "x": -8,
      "y": 10,
      "z": -5,
      "name": "Rock_Stone"
    },
    {
      "x": -8,
      "y": 11,
      "z": -5,
      "name": "Rock_Stone"
    },
    {
      "x": -8,
      "y": 12,
      "z": -5,
      "name": "Rock_Stone"
    },
    {
      "x": -8,
      "y": 13,
      "z": -5,
      "name": "Rock_Stone"
    },
    {
      "x": -8,
      "y": -1,
      "z": -4,
      "name": "Rock_Stone"
    },
    {
      "x": -8,
      "y": 0,
      "z": -4,
      "name": "Rock_Stone"
    },
    {
      "x": -8,
      "y": 1,
      "z": -4,
      "name": "Rock_Stone"
    },
    {
      "x": -8,
      "y": 2,
      "z": -4,
      "name": "Rock_Stone"
    },
    {
      "x": -8,
      "y": 3,
      "z": -4,
      "name": "Rock_Stone"
    },
    {
      "x": -8,
      "y": 4,
      "z": -4,
      "name": "Rock_Stone"
    },
    {
      "x": -8,
      "y": 5,
      "z": -4,
      "name": "Rock_Stone"
    },
    {
      "x": -8,
      "y": 6,
      "z": -4,
      "name": "Rock_Stone"
    },
    {
      "x": -8,
      "y": 7,
      "z": -4,
      "name": "Rock_Stone"
    },
    {
      "x": -8,
      "y": 8,
      "z": -4,
      "name": "Rock_Stone"
    },
    {
      "x": -8,
      "y": 9,
      "z": -4,
      "name": "Rock_Stone"
    },
    {
      "x": -8,
      "y": 10,
      "z": -4,
      "name": "Rock_Stone"
    },
    {
      "x": -8,
      "y": 11,
      "z": -4,
      "name": "Rock_Stone"
    },
    {
      "x": -8,
      "y": 12,
      "z": -4,
      "name": "Rock_Stone"
    },
    {
      "x": -8,
      "y": 13,
      "z": -4,
      "name": "Rock_Stone"
    },
    {
      "x": -8,
      "y": -1,
      "z": -3,
      "name": "Rock_Stone"
    },
    {
      "x": -8,
      "y": 0,
      "z": -3,
      "name": "Rock_Stone"
    },
    {
      "x": -8,
      "y": 1,
      "z": -3,
      "name": "Rock_Stone_Cobble"
    },
    {
      "x": -8,
      "y": 2,
      "z": -3,
      "name": "Rock_Stone_Cobble"
    },
    {
      "x": -8,
      "y": 3,
      "z": -3,
      "name": "Empty"
    },
    {
      "x": -8,
      "y": 4,
      "z": -3,
      "name": "Empty"
    },
    {
      "x": -8,
      "y": 5,
      "z": -3,
      "name": "Empty"
    },
    {
      "x": -8,
      "y": 6,
      "z": -3,
      "name": "Wood_Beech_Trunk",
      "rotation": 4
    },
    {
      "x": -8,
      "y": 7,
      "z": -3,
      "name": "Rock_Stone"
    },
    {
      "x": -8,
      "y": 8,
      "z": -3,
      "name": "Rock_Stone"
    },
    {
      "x": -8,
      "y": 9,
      "z": -3,
      "name": "Rock_Stone"
    },
    {
      "x": -8,
      "y": 10,
      "z": -3,
      "name": "Rock_Stone"
    },
    {
      "x": -8,
      "y": 11,
      "z": -3,
      "name": "Rock_Stone"
    },
    {
      "x": -8,
      "y": 12,
      "z": -3,
      "name": "Rock_Stone"
    },
    {
      "x": -8,
      "y": 13,
      "z": -3,
      "name": "Rock_Stone"
    },
    {
      "x": -8,
      "y": -1,
      "z": -2,
      "name": "Rock_Stone"
    },
    {
      "x": -8,
      "y": 0,
      "z": -2,
      "name": "Rock_Stone"
    },
    {
      "x": -8,
      "y": 1,
      "z": -2,
      "name": "Wood_Beech_Trunk"
    },
    {
      "x": -8,
      "y": 2,
      "z": -2,
      "name": "Wood_Beech_Trunk"
    },
    {
      "x": -8,
      "y": 3,
      "z": -2,
      "name": "Wood_Beech_Trunk"
    },
    {
      "x": -8,
      "y": 4,
      "z": -2,
      "name": "Wood_Beech_Trunk"
    },
    {
      "x": -8,
      "y": 5,
      "z": -2,
      "name": "Wood_Beech_Trunk"
    },
    {
      "x": -8,
      "y": 6,
      "z": -2,
      "name": "Wood_Beech_Trunk",
      "rotation": 4
    },
    {
      "x": -8,
      "y": 7,
      "z": -2,
      "name": "Empty"
    },
    {
      "x": -8,
      "y": 8,
      "z": -2,
      "name": "Rock_Stone"
    },
    {
      "x": -8,
      "y": 9,
      "z": -2,
      "name": "Rock_Stone"
    },
    {
      "x": -8,
      "y": 10,
      "z": -2,
      "name": "Rock_Stone"
    },
    {
      "x": -8,
      "y": 11,
      "z": -2,
      "name": "Rock_Stone"
    },
    {
      "x": -8,
      "y": 12,
      "z": -2,
      "name": "Rock_Stone"
    },
    {
      "x": -8,
      "y": 13,
      "z": -2,
      "name": "Rock_Stone"
    },
    {
      "x": -8,
      "y": -1,
      "z": -1,
      "name": "Rock_Stone"
    },
    {
      "x": -8,
      "y": 0,
      "z": -1,
      "name": "Rock_Stone"
    },
    {
      "x": -8,
      "y": 1,
      "z": -1,
      "name": "Empty"
    },
    {
      "x": -8,
      "y": 2,
      "z": -1,
      "name": "Empty"
    },
    {
      "x": -8,
      "y": 3,
      "z": -1,
      "name": "Empty"
    },
    {
      "x": -8,
      "y": 4,
      "z": -1,
      "name": "Empty"
    },
    {
      "x": -8,
      "y": 5,
      "z": -1,
      "name": "Empty"
    },
    {
      "x": -8,
      "y": 6,
      "z": -1,
      "name": "Wood_Beech_Trunk",
      "rotation": 4
    },
    {
      "x": -8,
      "y": 7,
      "z": -1,
      "name": "Empty"
    },
    {
      "x": -8,
      "y": 8,
      "z": -1,
      "name": "Rock_Stone"
    },
    {
      "x": -8,
      "y": 9,
      "z": -1,
      "name": "Rock_Stone"
    },
    {
      "x": -8,
      "y": 10,
      "z": -1,
      "name": "Rock_Stone"
    },
    {
      "x": -8,
      "y": 11,
      "z": -1,
      "name": "Rock_Stone"
    },
    {
      "x": -8,
      "y": 12,
      "z": -1,
      "name": "Rock_Stone"
    },
    {
      "x": -8,
      "y": 13,
      "z": -1,
      "name": "Rock_Stone"
    },
    {
      "x": -8,
      "y": -1,
      "z": 0,
      "name": "Rock_Stone"
    },
    {
      "x": -8,
      "y": 0,
      "z": 0,
      "name": "Soil_Gravel"
    },
    {
      "x": -8,
      "y": 1,
      "z": 0,
      "name": "Empty"
    },
    {
      "x": -8,
      "y": 2,
      "z": 0,
      "name": "Empty"
    },
    {
      "x": -8,
      "y": 3,
      "z": 0,
      "name": "Empty"
    },
    {
      "x": -8,
      "y": 4,
      "z": 0,
      "name": "Empty"
    },
    {
      "x": -8,
      "y": 5,
      "z": 0,
      "name": "Wood_Softwood_Planks_Half",
      "rotation": 8
    },
    {
      "x": -8,
      "y": 6,
      "z": 0,
      "name": "Wood_Beech_Trunk",
      "rotation": 4
    },
    {
      "x": -8,
      "y": 7,
      "z": 0,
      "name": "Empty"
    },
    {
      "x": -8,
      "y": 8,
      "z": 0,
      "name": "Rock_Stone"
    },
    {
      "x": -8,
      "y": 9,
      "z": 0,
      "name": "Rock_Stone"
    },
    {
      "x": -8,
      "y": 10,
      "z": 0,
      "name": "Rock_Stone"
    },
    {
      "x": -8,
      "y": 11,
      "z": 0,
      "name": "Rock_Stone"
    },
    {
      "x": -8,
      "y": 12,
      "z": 0,
      "name": "Rock_Stone"
    },
    {
      "x": -8,
      "y": 13,
      "z": 0,
      "name": "Rock_Stone"
    },
    {
      "x": -8,
      "y": -1,
      "z": 1,
      "name": "Rock_Stone"
    },
    {
      "x": -8,
      "y": 0,
      "z": 1,
      "name": "Soil_Gravel"
    },
    {
      "x": -8,
      "y": 1,
      "z": 1,
      "name": "Empty"
    },
    {
      "x": -8,
      "y": 2,
      "z": 1,
      "name": "Empty"
    },
    {
      "x": -8,
      "y": 3,
      "z": 1,
      "name": "Empty"
    },
    {
      "x": -8,
      "y": 4,
      "z": 1,
      "name": "Empty"
    },
    {
      "x": -8,
      "y": 5,
      "z": 1,
      "name": "Wood_Softwood_Planks_Half",
      "rotation": 8
    },
    {
      "x": -8,
      "y": 6,
      "z": 1,
      "name": "Wood_Beech_Trunk",
      "rotation": 4
    },
    {
      "x": -8,
      "y": 7,
      "z": 1,
      "name": "Empty"
    },
    {
      "x": -8,
      "y": 8,
      "z": 1,
      "name": "Rock_Stone"
    },
    {
      "x": -8,
      "y": 9,
      "z": 1,
      "name": "Rock_Stone"
    },
    {
      "x": -8,
      "y": 10,
      "z": 1,
      "name": "Rock_Stone"
    },
    {
      "x": -8,
      "y": 11,
      "z": 1,
      "name": "Rock_Stone"
    },
    {
      "x": -8,
      "y": 12,
      "z": 1,
      "name": "Rock_Stone"
    },
    {
      "x": -8,
      "y": 13,
      "z": 1,
      "name": "Rock_Stone"
    },
    {
      "x": -8,
      "y": -1,
      "z": 2,
      "name": "Rock_Stone"
    },
    {
      "x": -8,
      "y": 0,
      "z": 2,
      "name": "Rock_Stone"
    },
    {
      "x": -8,
      "y": 1,
      "z": 2,
      "name": "Wood_Beech_Trunk"
    },
    {
      "x": -8,
      "y": 2,
      "z": 2,
      "name": "Wood_Beech_Trunk"
    },
    {
      "x": -8,
      "y": 3,
      "z": 2,
      "name": "Wood_Beech_Trunk"
    },
    {
      "x": -8,
      "y": 4,
      "z": 2,
      "name": "Wood_Beech_Trunk"
    },
    {
      "x": -8,
      "y": 5,
      "z": 2,
      "name": "Wood_Beech_Trunk"
    },
    {
      "x": -8,
      "y": 6,
      "z": 2,
      "name": "Wood_Beech_Trunk",
      "rotation": 4
    },
    {
      "x": -8,
      "y": 7,
      "z": 2,
      "name": "Rock_Stone"
    },
    {
      "x": -8,
      "y": 8,
      "z": 2,
      "name": "Rock_Stone"
    },
    {
      "x": -8,
      "y": 9,
      "z": 2,
      "name": "Rock_Stone"
    },
    {
      "x": -8,
      "y": 10,
      "z": 2,
      "name": "Rock_Stone"
    },
    {
      "x": -8,
      "y": 11,
      "z": 2,
      "name": "Rock_Stone"
    },
    {
      "x": -8,
      "y": 12,
      "z": 2,
      "name": "Rock_Stone"
    },
    {
      "x": -8,
      "y": 13,
      "z": 2,
      "name": "Rock_Stone"
    },
    {
      "x": -8,
      "y": -1,
      "z": 3,
      "name": "Rock_Stone"
    },
    {
      "x": -8,
      "y": 0,
      "z": 3,
      "name": "Rock_Stone"
    },
    {
      "x": -8,
      "y": 1,
      "z": 3,
      "name": "Rock_Stone"
    },
    {
      "x": -8,
      "y": 2,
      "z": 3,
      "name": "Rock_Stone"
    },
    {
      "x": -8,
      "y": 3,
      "z": 3,
      "name": "Rock_Stone"
    },
    {
      "x": -8,
      "y": 4,
      "z": 3,
      "name": "Empty"
    },
    {
      "x": -8,
      "y": 5,
      "z": 3,
      "name": "Wood_Softwood_Planks_Half",
      "rotation": 8
    },
    {
      "x": -8,
      "y": 6,
      "z": 3,
      "name": "Wood_Beech_Trunk",
      "rotation": 4
    },
    {
      "x": -8,
      "y": 7,
      "z": 3,
      "name": "Rock_Stone"
    },
    {
      "x": -8,
      "y": 8,
      "z": 3,
      "name": "Rock_Stone"
    },
    {
      "x": -8,
      "y": 9,
      "z": 3,
      "name": "Rock_Stone"
    },
    {
      "x": -8,
      "y": 10,
      "z": 3,
      "name": "Rock_Stone"
    },
    {
      "x": -8,
      "y": 11,
      "z": 3,
      "name": "Rock_Stone"
    },
    {
      "x": -8,
      "y": 12,
      "z": 3,
      "name": "Rock_Stone"
    },
    {
      "x": -8,
      "y": 13,
      "z": 3,
      "name": "Rock_Stone"
    },
    {
      "x": -8,
      "y": -1,
      "z": 4,
      "name": "Rock_Stone"
    },
    {
      "x": -8,
      "y": 0,
      "z": 4,
      "name": "Rock_Stone"
    },
    {
      "x": -8,
      "y": 1,
      "z": 4,
      "name": "Rock_Stone"
    },
    {
      "x": -8,
      "y": 2,
      "z": 4,
      "name": "Rock_Stone"
    },
    {
      "x": -8,
      "y": 3,
      "z": 4,
      "name": "Rock_Stone"
    },
    {
      "x": -8,
      "y": 4,
      "z": 4,
      "name": "Rock_Stone"
    },
    {
      "x": -8,
      "y": 5,
      "z": 4,
      "name": "Rock_Stone"
    },
    {
      "x": -8,
      "y": 6,
      "z": 4,
      "name": "Rock_Stone"
    },
    {
      "x": -8,
      "y": 7,
      "z": 4,
      "name": "Rock_Stone"
    },
    {
      "x": -8,
      "y": 8,
      "z": 4,
      "name": "Rock_Stone"
    },
    {
      "x": -8,
      "y": 9,
      "z": 4,
      "name": "Rock_Stone"
    },
    {
      "x": -8,
      "y": 10,
      "z": 4,
      "name": "Rock_Stone"
    },
    {
      "x": -8,
      "y": 11,
      "z": 4,
      "name": "Rock_Stone"
    },
    {
      "x": -8,
      "y": 12,
      "z": 4,
      "name": "Rock_Stone"
    },
    {
      "x": -8,
      "y": 13,
      "z": 4,
      "name": "Rock_Stone"
    },
    {
      "x": -8,
      "y": -1,
      "z": 5,
      "name": "Rock_Stone"
    },
    {
      "x": -8,
      "y": 0,
      "z": 5,
      "name": "Rock_Stone"
    },
    {
      "x": -8,
      "y": 1,
      "z": 5,
      "name": "Rock_Stone"
    },
    {
      "x": -8,
      "y": 2,
      "z": 5,
      "name": "Rock_Stone"
    },
    {
      "x": -8,
      "y": 3,
      "z": 5,
      "name": "Rock_Stone"
    },
    {
      "x": -8,
      "y": 4,
      "z": 5,
      "name": "Rock_Stone"
    },
    {
      "x": -8,
      "y": 5,
      "z": 5,
      "name": "Rock_Stone"
    },
    {
      "x": -8,
      "y": 6,
      "z": 5,
      "name": "Rock_Stone"
    },
    {
      "x": -8,
      "y": 7,
      "z": 5,
      "name": "Rock_Stone"
    },
    {
      "x": -8,
      "y": 8,
      "z": 5,
      "name": "Rock_Stone"
    },
    {
      "x": -8,
      "y": 9,
      "z": 5,
      "name": "Rock_Stone"
    },
    {
      "x": -8,
      "y": 10,
      "z": 5,
      "name": "Rock_Stone"
    },
    {
      "x": -8,
      "y": 11,
      "z": 5,
      "name": "Rock_Stone"
    },
    {
      "x": -8,
      "y": 12,
      "z": 5,
      "name": "Rock_Stone"
    },
    {
      "x": -8,
      "y": 13,
      "z": 5,
      "name": "Rock_Stone"
    },
    {
      "x": -8,
      "y": -1,
      "z": 6,
      "name": "Rock_Stone"
    },
    {
      "x": -8,
      "y": 0,
      "z": 6,
      "name": "Rock_Stone"
    },
    {
      "x": -8,
      "y": 1,
      "z": 6,
      "name": "Rock_Stone"
    },
    {
      "x": -8,
      "y": 2,
      "z": 6,
      "name": "Rock_Stone"
    },
    {
      "x": -8,
      "y": 3,
      "z": 6,
      "name": "Rock_Stone"
    },
    {
      "x": -8,
      "y": 4,
      "z": 6,
      "name": "Rock_Stone"
    },
    {
      "x": -8,
      "y": 5,
      "z": 6,
      "name": "Rock_Stone"
    },
    {
      "x": -8,
      "y": 6,
      "z": 6,
      "name": "Rock_Stone"
    },
    {
      "x": -8,
      "y": 7,
      "z": 6,
      "name": "Rock_Stone"
    },
    {
      "x": -8,
      "y": 8,
      "z": 6,
      "name": "Rock_Stone"
    },
    {
      "x": -8,
      "y": 9,
      "z": 6,
      "name": "Rock_Stone"
    },
    {
      "x": -8,
      "y": 10,
      "z": 6,
      "name": "Rock_Stone"
    },
    {
      "x": -8,
      "y": 11,
      "z": 6,
      "name": "Rock_Stone"
    },
    {
      "x": -8,
      "y": 12,
      "z": 6,
      "name": "Rock_Stone"
    },
    {
      "x": -8,
      "y": 13,
      "z": 6,
      "name": "Rock_Stone"
    },
    {
      "x": -8,
      "y": -1,
      "z": 7,
      "name": "Rock_Stone"
    },
    {
      "x": -8,
      "y": 0,
      "z": 7,
      "name": "Rock_Stone"
    },
    {
      "x": -8,
      "y": 1,
      "z": 7,
      "name": "Rock_Stone"
    },
    {
      "x": -8,
      "y": 2,
      "z": 7,
      "name": "Rock_Stone"
    },
    {
      "x": -8,
      "y": 3,
      "z": 7,
      "name": "Rock_Stone"
    },
    {
      "x": -8,
      "y": 4,
      "z": 7,
      "name": "Rock_Stone"
    },
    {
      "x": -8,
      "y": 5,
      "z": 7,
      "name": "Rock_Stone"
    },
    {
      "x": -8,
      "y": 6,
      "z": 7,
      "name": "Rock_Stone"
    },
    {
      "x": -8,
      "y": 7,
      "z": 7,
      "name": "Rock_Stone"
    },
    {
      "x": -8,
      "y": 8,
      "z": 7,
      "name": "Rock_Stone"
    },
    {
      "x": -8,
      "y": 9,
      "z": 7,
      "name": "Rock_Stone"
    },
    {
      "x": -8,
      "y": 10,
      "z": 7,
      "name": "Rock_Stone"
    },
    {
      "x": -8,
      "y": 11,
      "z": 7,
      "name": "Rock_Stone"
    },
    {
      "x": -8,
      "y": 12,
      "z": 7,
      "name": "Rock_Stone"
    },
    {
      "x": -8,
      "y": 13,
      "z": 7,
      "name": "Rock_Stone"
    },
    {
      "x": -8,
      "y": -1,
      "z": 8,
      "name": "Rock_Stone"
    },
    {
      "x": -8,
      "y": 0,
      "z": 8,
      "name": "Rock_Stone"
    },
    {
      "x": -8,
      "y": 1,
      "z": 8,
      "name": "Rock_Stone"
    },
    {
      "x": -8,
      "y": 2,
      "z": 8,
      "name": "Rock_Stone"
    },
    {
      "x": -8,
      "y": 3,
      "z": 8,
      "name": "Rock_Stone"
    },
    {
      "x": -8,
      "y": 4,
      "z": 8,
      "name": "Rock_Stone"
    },
    {
      "x": -8,
      "y": 5,
      "z": 8,
      "name": "Rock_Stone"
    },
    {
      "x": -8,
      "y": 6,
      "z": 8,
      "name": "Rock_Stone"
    },
    {
      "x": -8,
      "y": 7,
      "z": 8,
      "name": "Rock_Stone"
    },
    {
      "x": -8,
      "y": 8,
      "z": 8,
      "name": "Rock_Stone"
    },
    {
      "x": -8,
      "y": 9,
      "z": 8,
      "name": "Rock_Stone"
    },
    {
      "x": -8,
      "y": 10,
      "z": 8,
      "name": "Rock_Stone"
    },
    {
      "x": -8,
      "y": 11,
      "z": 8,
      "name": "Rock_Stone"
    },
    {
      "x": -8,
      "y": 12,
      "z": 8,
      "name": "Rock_Stone"
    },
    {
      "x": -8,
      "y": 13,
      "z": 8,
      "name": "Rock_Stone"
    },
    {
      "x": -8,
      "y": -1,
      "z": 9,
      "name": "Rock_Stone"
    },
    {
      "x": -8,
      "y": 0,
      "z": 9,
      "name": "Rock_Stone"
    },
    {
      "x": -8,
      "y": 1,
      "z": 9,
      "name": "Rock_Stone"
    },
    {
      "x": -8,
      "y": 2,
      "z": 9,
      "name": "Rock_Stone"
    },
    {
      "x": -8,
      "y": 3,
      "z": 9,
      "name": "Rock_Stone"
    },
    {
      "x": -8,
      "y": 4,
      "z": 9,
      "name": "Rock_Stone"
    },
    {
      "x": -8,
      "y": 5,
      "z": 9,
      "name": "Rock_Stone"
    },
    {
      "x": -8,
      "y": 6,
      "z": 9,
      "name": "Rock_Stone"
    },
    {
      "x": -8,
      "y": 7,
      "z": 9,
      "name": "Rock_Stone"
    },
    {
      "x": -8,
      "y": 8,
      "z": 9,
      "name": "Rock_Stone"
    },
    {
      "x": -8,
      "y": 9,
      "z": 9,
      "name": "Rock_Stone"
    },
    {
      "x": -8,
      "y": 10,
      "z": 9,
      "name": "Rock_Stone"
    },
    {
      "x": -8,
      "y": 11,
      "z": 9,
      "name": "Rock_Stone"
    },
    {
      "x": -8,
      "y": 12,
      "z": 9,
      "name": "Rock_Stone"
    },
    {
      "x": -8,
      "y": 13,
      "z": 9,
      "name": "Rock_Stone"
    },
    {
      "x": -8,
      "y": -1,
      "z": 10,
      "name": "Rock_Stone"
    },
    {
      "x": -8,
      "y": 0,
      "z": 10,
      "name": "Rock_Stone"
    },
    {
      "x": -8,
      "y": 1,
      "z": 10,
      "name": "Rock_Stone"
    },
    {
      "x": -8,
      "y": 2,
      "z": 10,
      "name": "Rock_Stone"
    },
    {
      "x": -8,
      "y": 3,
      "z": 10,
      "name": "Rock_Stone"
    },
    {
      "x": -8,
      "y": 4,
      "z": 10,
      "name": "Rock_Stone"
    },
    {
      "x": -8,
      "y": 5,
      "z": 10,
      "name": "Rock_Stone"
    },
    {
      "x": -8,
      "y": 6,
      "z": 10,
      "name": "Rock_Stone"
    },
    {
      "x": -8,
      "y": 7,
      "z": 10,
      "name": "Rock_Stone"
    },
    {
      "x": -8,
      "y": 8,
      "z": 10,
      "name": "Rock_Stone"
    },
    {
      "x": -8,
      "y": 9,
      "z": 10,
      "name": "Rock_Stone"
    },
    {
      "x": -8,
      "y": 10,
      "z": 10,
      "name": "Rock_Stone"
    },
    {
      "x": -8,
      "y": 11,
      "z": 10,
      "name": "Rock_Stone"
    },
    {
      "x": -8,
      "y": 12,
      "z": 10,
      "name": "Rock_Stone"
    },
    {
      "x": -8,
      "y": 13,
      "z": 10,
      "name": "Rock_Stone"
    },
    {
      "x": -7,
      "y": -1,
      "z": -10,
      "name": "Rock_Stone"
    },
    {
      "x": -7,
      "y": 0,
      "z": -10,
      "name": "Rock_Stone"
    },
    {
      "x": -7,
      "y": 1,
      "z": -10,
      "name": "Rock_Stone"
    },
    {
      "x": -7,
      "y": 2,
      "z": -10,
      "name": "Rock_Stone"
    },
    {
      "x": -7,
      "y": 3,
      "z": -10,
      "name": "Rock_Stone"
    },
    {
      "x": -7,
      "y": 4,
      "z": -10,
      "name": "Rock_Stone"
    },
    {
      "x": -7,
      "y": 5,
      "z": -10,
      "name": "Rock_Stone"
    },
    {
      "x": -7,
      "y": 6,
      "z": -10,
      "name": "Rock_Stone"
    },
    {
      "x": -7,
      "y": 7,
      "z": -10,
      "name": "Rock_Stone"
    },
    {
      "x": -7,
      "y": 8,
      "z": -10,
      "name": "Rock_Stone"
    },
    {
      "x": -7,
      "y": 9,
      "z": -10,
      "name": "Rock_Stone"
    },
    {
      "x": -7,
      "y": 10,
      "z": -10,
      "name": "Rock_Stone"
    },
    {
      "x": -7,
      "y": 11,
      "z": -10,
      "name": "Rock_Stone"
    },
    {
      "x": -7,
      "y": 12,
      "z": -10,
      "name": "Rock_Stone"
    },
    {
      "x": -7,
      "y": 13,
      "z": -10,
      "name": "Rock_Stone"
    },
    {
      "x": -7,
      "y": -1,
      "z": -9,
      "name": "Rock_Stone"
    },
    {
      "x": -7,
      "y": 0,
      "z": -9,
      "name": "Rock_Stone"
    },
    {
      "x": -7,
      "y": 1,
      "z": -9,
      "name": "Rock_Stone"
    },
    {
      "x": -7,
      "y": 2,
      "z": -9,
      "name": "Rock_Stone"
    },
    {
      "x": -7,
      "y": 3,
      "z": -9,
      "name": "Rock_Stone"
    },
    {
      "x": -7,
      "y": 4,
      "z": -9,
      "name": "Rock_Stone"
    },
    {
      "x": -7,
      "y": 5,
      "z": -9,
      "name": "Rock_Stone"
    },
    {
      "x": -7,
      "y": 6,
      "z": -9,
      "name": "Rock_Stone"
    },
    {
      "x": -7,
      "y": 7,
      "z": -9,
      "name": "Rock_Stone"
    },
    {
      "x": -7,
      "y": 8,
      "z": -9,
      "name": "Rock_Stone"
    },
    {
      "x": -7,
      "y": 9,
      "z": -9,
      "name": "Rock_Stone"
    },
    {
      "x": -7,
      "y": 10,
      "z": -9,
      "name": "Rock_Stone"
    },
    {
      "x": -7,
      "y": 11,
      "z": -9,
      "name": "Rock_Stone"
    },
    {
      "x": -7,
      "y": 12,
      "z": -9,
      "name": "Rock_Stone"
    },
    {
      "x": -7,
      "y": 13,
      "z": -9,
      "name": "Rock_Stone"
    },
    {
      "x": -7,
      "y": -1,
      "z": -8,
      "name": "Rock_Stone"
    },
    {
      "x": -7,
      "y": 0,
      "z": -8,
      "name": "Rock_Stone"
    },
    {
      "x": -7,
      "y": 1,
      "z": -8,
      "name": "Rock_Stone"
    },
    {
      "x": -7,
      "y": 2,
      "z": -8,
      "name": "Rock_Stone"
    },
    {
      "x": -7,
      "y": 3,
      "z": -8,
      "name": "Rock_Stone"
    },
    {
      "x": -7,
      "y": 4,
      "z": -8,
      "name": "Rock_Stone"
    },
    {
      "x": -7,
      "y": 5,
      "z": -8,
      "name": "Rock_Stone"
    },
    {
      "x": -7,
      "y": 6,
      "z": -8,
      "name": "Rock_Stone"
    },
    {
      "x": -7,
      "y": 7,
      "z": -8,
      "name": "Rock_Stone"
    },
    {
      "x": -7,
      "y": 8,
      "z": -8,
      "name": "Rock_Stone"
    },
    {
      "x": -7,
      "y": 9,
      "z": -8,
      "name": "Rock_Stone"
    },
    {
      "x": -7,
      "y": 10,
      "z": -8,
      "name": "Rock_Stone"
    },
    {
      "x": -7,
      "y": 11,
      "z": -8,
      "name": "Rock_Stone"
    },
    {
      "x": -7,
      "y": 12,
      "z": -8,
      "name": "Rock_Stone"
    },
    {
      "x": -7,
      "y": 13,
      "z": -8,
      "name": "Rock_Stone"
    },
    {
      "x": -7,
      "y": -1,
      "z": -7,
      "name": "Rock_Stone"
    },
    {
      "x": -7,
      "y": 0,
      "z": -7,
      "name": "Rock_Stone"
    },
    {
      "x": -7,
      "y": 1,
      "z": -7,
      "name": "Rock_Stone"
    },
    {
      "x": -7,
      "y": 2,
      "z": -7,
      "name": "Rock_Stone"
    },
    {
      "x": -7,
      "y": 3,
      "z": -7,
      "name": "Rock_Stone"
    },
    {
      "x": -7,
      "y": 4,
      "z": -7,
      "name": "Rock_Stone"
    },
    {
      "x": -7,
      "y": 5,
      "z": -7,
      "name": "Rock_Stone"
    },
    {
      "x": -7,
      "y": 6,
      "z": -7,
      "name": "Rock_Stone"
    },
    {
      "x": -7,
      "y": 7,
      "z": -7,
      "name": "Rock_Stone"
    },
    {
      "x": -7,
      "y": 8,
      "z": -7,
      "name": "Rock_Stone"
    },
    {
      "x": -7,
      "y": 9,
      "z": -7,
      "name": "Rock_Stone"
    },
    {
      "x": -7,
      "y": 10,
      "z": -7,
      "name": "Rock_Stone"
    },
    {
      "x": -7,
      "y": 11,
      "z": -7,
      "name": "Rock_Stone"
    },
    {
      "x": -7,
      "y": 12,
      "z": -7,
      "name": "Rock_Stone"
    },
    {
      "x": -7,
      "y": 13,
      "z": -7,
      "name": "Rock_Stone"
    },
    {
      "x": -7,
      "y": -1,
      "z": -6,
      "name": "Rock_Stone"
    },
    {
      "x": -7,
      "y": 0,
      "z": -6,
      "name": "Rock_Stone"
    },
    {
      "x": -7,
      "y": 1,
      "z": -6,
      "name": "Rock_Stone"
    },
    {
      "x": -7,
      "y": 2,
      "z": -6,
      "name": "Rock_Stone"
    },
    {
      "x": -7,
      "y": 3,
      "z": -6,
      "name": "Rock_Stone"
    },
    {
      "x": -7,
      "y": 4,
      "z": -6,
      "name": "Rock_Stone"
    },
    {
      "x": -7,
      "y": 5,
      "z": -6,
      "name": "Rock_Stone"
    },
    {
      "x": -7,
      "y": 6,
      "z": -6,
      "name": "Rock_Stone"
    },
    {
      "x": -7,
      "y": 7,
      "z": -6,
      "name": "Rock_Stone"
    },
    {
      "x": -7,
      "y": 8,
      "z": -6,
      "name": "Rock_Stone"
    },
    {
      "x": -7,
      "y": 9,
      "z": -6,
      "name": "Rock_Stone"
    },
    {
      "x": -7,
      "y": 10,
      "z": -6,
      "name": "Rock_Stone"
    },
    {
      "x": -7,
      "y": 11,
      "z": -6,
      "name": "Rock_Stone"
    },
    {
      "x": -7,
      "y": 12,
      "z": -6,
      "name": "Rock_Stone"
    },
    {
      "x": -7,
      "y": 13,
      "z": -6,
      "name": "Rock_Stone"
    },
    {
      "x": -7,
      "y": -1,
      "z": -5,
      "name": "Rock_Stone"
    },
    {
      "x": -7,
      "y": 0,
      "z": -5,
      "name": "Rock_Stone"
    },
    {
      "x": -7,
      "y": 1,
      "z": -5,
      "name": "Rock_Stone"
    },
    {
      "x": -7,
      "y": 2,
      "z": -5,
      "name": "Rock_Stone"
    },
    {
      "x": -7,
      "y": 3,
      "z": -5,
      "name": "Empty"
    },
    {
      "x": -7,
      "y": 4,
      "z": -5,
      "name": "Rock_Stone"
    },
    {
      "x": -7,
      "y": 5,
      "z": -5,
      "name": "Rock_Stone"
    },
    {
      "x": -7,
      "y": 6,
      "z": -5,
      "name": "Rock_Stone"
    },
    {
      "x": -7,
      "y": 7,
      "z": -5,
      "name": "Rock_Stone"
    },
    {
      "x": -7,
      "y": 8,
      "z": -5,
      "name": "Rock_Stone"
    },
    {
      "x": -7,
      "y": 9,
      "z": -5,
      "name": "Rock_Stone"
    },
    {
      "x": -7,
      "y": 10,
      "z": -5,
      "name": "Rock_Stone"
    },
    {
      "x": -7,
      "y": 11,
      "z": -5,
      "name": "Rock_Stone"
    },
    {
      "x": -7,
      "y": 12,
      "z": -5,
      "name": "Rock_Stone"
    },
    {
      "x": -7,
      "y": 13,
      "z": -5,
      "name": "Rock_Stone"
    },
    {
      "x": -7,
      "y": -1,
      "z": -4,
      "name": "Rock_Stone"
    },
    {
      "x": -7,
      "y": 0,
      "z": -4,
      "name": "Rock_Stone"
    },
    {
      "x": -7,
      "y": 1,
      "z": -4,
      "name": "Rock_Stone"
    },
    {
      "x": -7,
      "y": 2,
      "z": -4,
      "name": "Rock_Stone"
    },
    {
      "x": -7,
      "y": 3,
      "z": -4,
      "name": "Empty"
    },
    {
      "x": -7,
      "y": 4,
      "z": -4,
      "name": "Empty"
    },
    {
      "x": -7,
      "y": 5,
      "z": -4,
      "name": "Rock_Stone"
    },
    {
      "x": -7,
      "y": 6,
      "z": -4,
      "name": "Rock_Stone"
    },
    {
      "x": -7,
      "y": 7,
      "z": -4,
      "name": "Rock_Stone"
    },
    {
      "x": -7,
      "y": 8,
      "z": -4,
      "name": "Rock_Stone"
    },
    {
      "x": -7,
      "y": 9,
      "z": -4,
      "name": "Rock_Stone"
    },
    {
      "x": -7,
      "y": 10,
      "z": -4,
      "name": "Rock_Stone"
    },
    {
      "x": -7,
      "y": 11,
      "z": -4,
      "name": "Rock_Stone"
    },
    {
      "x": -7,
      "y": 12,
      "z": -4,
      "name": "Rock_Stone"
    },
    {
      "x": -7,
      "y": 13,
      "z": -4,
      "name": "Rock_Stone"
    },
    {
      "x": -7,
      "y": -1,
      "z": -3,
      "name": "Rock_Stone"
    },
    {
      "x": -7,
      "y": 0,
      "z": -3,
      "name": "Rock_Stone"
    },
    {
      "x": -7,
      "y": 1,
      "z": -3,
      "name": "Rock_Stone_Cobble"
    },
    {
      "x": -7,
      "y": 2,
      "z": -3,
      "name": "Rock_Stone_Cobble"
    },
    {
      "x": -7,
      "y": 3,
      "z": -3,
      "name": "Empty"
    },
    {
      "x": -7,
      "y": 4,
      "z": -3,
      "name": "Empty"
    },
    {
      "x": -7,
      "y": 5,
      "z": -3,
      "name": "Empty"
    },
    {
      "x": -7,
      "y": 6,
      "z": -3,
      "name": "Empty"
    },
    {
      "x": -7,
      "y": 7,
      "z": -3,
      "name": "Empty"
    },
    {
      "x": -7,
      "y": 8,
      "z": -3,
      "name": "Rock_Stone"
    },
    {
      "x": -7,
      "y": 9,
      "z": -3,
      "name": "Rock_Stone"
    },
    {
      "x": -7,
      "y": 10,
      "z": -3,
      "name": "Rock_Stone"
    },
    {
      "x": -7,
      "y": 11,
      "z": -3,
      "name": "Rock_Stone"
    },
    {
      "x": -7,
      "y": 12,
      "z": -3,
      "name": "Rock_Stone"
    },
    {
      "x": -7,
      "y": 13,
      "z": -3,
      "name": "Rock_Stone"
    },
    {
      "x": -7,
      "y": -1,
      "z": -2,
      "name": "Rock_Stone"
    },
    {
      "x": -7,
      "y": 0,
      "z": -2,
      "name": "Rock_Stone_Cobble"
    },
    {
      "x": -7,
      "y": 1,
      "z": -2,
      "name": "Rock_Stone_Cobble"
    },
    {
      "x": -7,
      "y": 2,
      "z": -2,
      "name": "Empty"
    },
    {
      "x": -7,
      "y": 3,
      "z": -2,
      "name": "Empty"
    },
    {
      "x": -7,
      "y": 4,
      "z": -2,
      "name": "Empty"
    },
    {
      "x": -7,
      "y": 5,
      "z": -2,
      "name": "Empty"
    },
    {
      "x": -7,
      "y": 6,
      "z": -2,
      "name": "Wood_Softwood_Planks_Half",
      "rotation": 5
    },
    {
      "x": -7,
      "y": 7,
      "z": -2,
      "name": "Empty"
    },
    {
      "x": -7,
      "y": 8,
      "z": -2,
      "name": "Rock_Stone"
    },
    {
      "x": -7,
      "y": 9,
      "z": -2,
      "name": "Rock_Stone"
    },
    {
      "x": -7,
      "y": 10,
      "z": -2,
      "name": "Rock_Stone"
    },
    {
      "x": -7,
      "y": 11,
      "z": -2,
      "name": "Rock_Stone"
    },
    {
      "x": -7,
      "y": 12,
      "z": -2,
      "name": "Rock_Stone"
    },
    {
      "x": -7,
      "y": 13,
      "z": -2,
      "name": "Rock_Stone"
    },
    {
      "x": -7,
      "y": -1,
      "z": -1,
      "name": "Rock_Stone"
    },
    {
      "x": -7,
      "y": 0,
      "z": -1,
      "name": "Rock_Stone"
    },
    {
      "x": -7,
      "y": 1,
      "z": -1,
      "name": "Empty"
    },
    {
      "x": -7,
      "y": 2,
      "z": -1,
      "name": "Empty"
    },
    {
      "x": -7,
      "y": 3,
      "z": -1,
      "name": "Empty"
    },
    {
      "x": -7,
      "y": 4,
      "z": -1,
      "name": "Empty"
    },
    {
      "x": -7,
      "y": 5,
      "z": -1,
      "name": "Empty"
    },
    {
      "x": -7,
      "y": 6,
      "z": -1,
      "name": "Empty"
    },
    {
      "x": -7,
      "y": 7,
      "z": -1,
      "name": "Empty"
    },
    {
      "x": -7,
      "y": 8,
      "z": -1,
      "name": "Rock_Stone"
    },
    {
      "x": -7,
      "y": 9,
      "z": -1,
      "name": "Rock_Stone"
    },
    {
      "x": -7,
      "y": 10,
      "z": -1,
      "name": "Rock_Stone"
    },
    {
      "x": -7,
      "y": 11,
      "z": -1,
      "name": "Rock_Stone"
    },
    {
      "x": -7,
      "y": 12,
      "z": -1,
      "name": "Rock_Stone"
    },
    {
      "x": -7,
      "y": 13,
      "z": -1,
      "name": "Rock_Stone"
    },
    {
      "x": -7,
      "y": -1,
      "z": 0,
      "name": "Rock_Stone"
    },
    {
      "x": -7,
      "y": 0,
      "z": 0,
      "name": "Soil_Gravel"
    },
    {
      "x": -7,
      "y": 1,
      "z": 0,
      "name": "Empty"
    },
    {
      "x": -7,
      "y": 2,
      "z": 0,
      "name": "Empty"
    },
    {
      "x": -7,
      "y": 3,
      "z": 0,
      "name": "Empty"
    },
    {
      "x": -7,
      "y": 4,
      "z": 0,
      "name": "Empty"
    },
    {
      "x": -7,
      "y": 5,
      "z": 0,
      "name": "Empty"
    },
    {
      "x": -7,
      "y": 6,
      "z": 0,
      "name": "Empty"
    },
    {
      "x": -7,
      "y": 7,
      "z": 0,
      "name": "Empty"
    },
    {
      "x": -7,
      "y": 8,
      "z": 0,
      "name": "Empty"
    },
    {
      "x": -7,
      "y": 9,
      "z": 0,
      "name": "Rock_Stone"
    },
    {
      "x": -7,
      "y": 10,
      "z": 0,
      "name": "Rock_Stone"
    },
    {
      "x": -7,
      "y": 11,
      "z": 0,
      "name": "Rock_Stone"
    },
    {
      "x": -7,
      "y": 12,
      "z": 0,
      "name": "Rock_Stone"
    },
    {
      "x": -7,
      "y": 13,
      "z": 0,
      "name": "Rock_Stone"
    },
    {
      "x": -7,
      "y": -1,
      "z": 1,
      "name": "Rock_Stone"
    },
    {
      "x": -7,
      "y": 0,
      "z": 1,
      "name": "Soil_Gravel"
    },
    {
      "x": -7,
      "y": 1,
      "z": 1,
      "name": "Empty"
    },
    {
      "x": -7,
      "y": 2,
      "z": 1,
      "name": "Empty"
    },
    {
      "x": -7,
      "y": 3,
      "z": 1,
      "name": "Empty"
    },
    {
      "x": -7,
      "y": 4,
      "z": 1,
      "name": "Empty"
    },
    {
      "x": -7,
      "y": 5,
      "z": 1,
      "name": "Empty"
    },
    {
      "x": -7,
      "y": 6,
      "z": 1,
      "name": "Empty"
    },
    {
      "x": -7,
      "y": 7,
      "z": 1,
      "name": "Empty"
    },
    {
      "x": -7,
      "y": 8,
      "z": 1,
      "name": "Empty"
    },
    {
      "x": -7,
      "y": 9,
      "z": 1,
      "name": "Empty"
    },
    {
      "x": -7,
      "y": 10,
      "z": 1,
      "name": "Rock_Stone"
    },
    {
      "x": -7,
      "y": 11,
      "z": 1,
      "name": "Rock_Stone"
    },
    {
      "x": -7,
      "y": 12,
      "z": 1,
      "name": "Rock_Stone"
    },
    {
      "x": -7,
      "y": 13,
      "z": 1,
      "name": "Rock_Stone"
    },
    {
      "x": -7,
      "y": -1,
      "z": 2,
      "name": "Rock_Stone"
    },
    {
      "x": -7,
      "y": 0,
      "z": 2,
      "name": "Rock_Stone"
    },
    {
      "x": -7,
      "y": 1,
      "z": 2,
      "name": "Rock_Stone"
    },
    {
      "x": -7,
      "y": 2,
      "z": 2,
      "name": "Empty"
    },
    {
      "x": -7,
      "y": 3,
      "z": 2,
      "name": "Empty"
    },
    {
      "x": -7,
      "y": 4,
      "z": 2,
      "name": "Empty"
    },
    {
      "x": -7,
      "y": 5,
      "z": 2,
      "name": "Empty"
    },
    {
      "x": -7,
      "y": 6,
      "z": 2,
      "name": "Wood_Softwood_Planks_Half",
      "rotation": 5
    },
    {
      "x": -7,
      "y": 7,
      "z": 2,
      "name": "Empty"
    },
    {
      "x": -7,
      "y": 8,
      "z": 2,
      "name": "Empty"
    },
    {
      "x": -7,
      "y": 9,
      "z": 2,
      "name": "Rock_Stone"
    },
    {
      "x": -7,
      "y": 10,
      "z": 2,
      "name": "Rock_Stone"
    },
    {
      "x": -7,
      "y": 11,
      "z": 2,
      "name": "Rock_Stone"
    },
    {
      "x": -7,
      "y": 12,
      "z": 2,
      "name": "Rock_Stone"
    },
    {
      "x": -7,
      "y": 13,
      "z": 2,
      "name": "Rock_Stone"
    },
    {
      "x": -7,
      "y": -1,
      "z": 3,
      "name": "Rock_Stone"
    },
    {
      "x": -7,
      "y": 0,
      "z": 3,
      "name": "Rock_Stone"
    },
    {
      "x": -7,
      "y": 1,
      "z": 3,
      "name": "Rock_Stone"
    },
    {
      "x": -7,
      "y": 2,
      "z": 3,
      "name": "Rock_Stone"
    },
    {
      "x": -7,
      "y": 3,
      "z": 3,
      "name": "Rock_Stone"
    },
    {
      "x": -7,
      "y": 4,
      "z": 3,
      "name": "Empty"
    },
    {
      "x": -7,
      "y": 5,
      "z": 3,
      "name": "Empty"
    },
    {
      "x": -7,
      "y": 6,
      "z": 3,
      "name": "Rock_Stone"
    },
    {
      "x": -7,
      "y": 7,
      "z": 3,
      "name": "Rock_Stone"
    },
    {
      "x": -7,
      "y": 8,
      "z": 3,
      "name": "Rock_Stone"
    },
    {
      "x": -7,
      "y": 9,
      "z": 3,
      "name": "Rock_Stone"
    },
    {
      "x": -7,
      "y": 10,
      "z": 3,
      "name": "Rock_Stone"
    },
    {
      "x": -7,
      "y": 11,
      "z": 3,
      "name": "Rock_Stone"
    },
    {
      "x": -7,
      "y": 12,
      "z": 3,
      "name": "Rock_Stone"
    },
    {
      "x": -7,
      "y": 13,
      "z": 3,
      "name": "Rock_Stone"
    },
    {
      "x": -7,
      "y": -1,
      "z": 4,
      "name": "Rock_Stone"
    },
    {
      "x": -7,
      "y": 0,
      "z": 4,
      "name": "Rock_Stone"
    },
    {
      "x": -7,
      "y": 1,
      "z": 4,
      "name": "Rock_Stone"
    },
    {
      "x": -7,
      "y": 2,
      "z": 4,
      "name": "Rock_Stone"
    },
    {
      "x": -7,
      "y": 3,
      "z": 4,
      "name": "Rock_Stone"
    },
    {
      "x": -7,
      "y": 4,
      "z": 4,
      "name": "Empty"
    },
    {
      "x": -7,
      "y": 5,
      "z": 4,
      "name": "Rock_Stone"
    },
    {
      "x": -7,
      "y": 6,
      "z": 4,
      "name": "Rock_Stone"
    },
    {
      "x": -7,
      "y": 7,
      "z": 4,
      "name": "Rock_Stone"
    },
    {
      "x": -7,
      "y": 8,
      "z": 4,
      "name": "Rock_Stone"
    },
    {
      "x": -7,
      "y": 9,
      "z": 4,
      "name": "Rock_Stone"
    },
    {
      "x": -7,
      "y": 10,
      "z": 4,
      "name": "Rock_Stone"
    },
    {
      "x": -7,
      "y": 11,
      "z": 4,
      "name": "Rock_Stone"
    },
    {
      "x": -7,
      "y": 12,
      "z": 4,
      "name": "Rock_Stone"
    },
    {
      "x": -7,
      "y": 13,
      "z": 4,
      "name": "Rock_Stone"
    },
    {
      "x": -7,
      "y": -1,
      "z": 5,
      "name": "Rock_Stone"
    },
    {
      "x": -7,
      "y": 0,
      "z": 5,
      "name": "Rock_Stone"
    },
    {
      "x": -7,
      "y": 1,
      "z": 5,
      "name": "Rock_Stone"
    },
    {
      "x": -7,
      "y": 2,
      "z": 5,
      "name": "Rock_Stone"
    },
    {
      "x": -7,
      "y": 3,
      "z": 5,
      "name": "Rock_Stone"
    },
    {
      "x": -7,
      "y": 4,
      "z": 5,
      "name": "Rock_Stone"
    },
    {
      "x": -7,
      "y": 5,
      "z": 5,
      "name": "Rock_Stone"
    },
    {
      "x": -7,
      "y": 6,
      "z": 5,
      "name": "Rock_Stone"
    },
    {
      "x": -7,
      "y": 7,
      "z": 5,
      "name": "Rock_Stone"
    },
    {
      "x": -7,
      "y": 8,
      "z": 5,
      "name": "Rock_Stone"
    },
    {
      "x": -7,
      "y": 9,
      "z": 5,
      "name": "Rock_Stone"
    },
    {
      "x": -7,
      "y": 10,
      "z": 5,
      "name": "Rock_Stone"
    },
    {
      "x": -7,
      "y": 11,
      "z": 5,
      "name": "Rock_Stone"
    },
    {
      "x": -7,
      "y": 12,
      "z": 5,
      "name": "Rock_Stone"
    },
    {
      "x": -7,
      "y": 13,
      "z": 5,
      "name": "Rock_Stone"
    },
    {
      "x": -7,
      "y": -1,
      "z": 6,
      "name": "Rock_Stone"
    },
    {
      "x": -7,
      "y": 0,
      "z": 6,
      "name": "Rock_Stone"
    },
    {
      "x": -7,
