{
  "version": 8,
  "blockIdVersion": 8,
  "anchorX": 8,
  "anchorY": 5,
  "anchorZ": 7,
  "blocks": [
    {
      "x": 7,
      "y": 7,
      "z": 7,
      "name": "Wood_Crystal_Trunk_Full"
    },
    {
      "x": 7,
      "y": 8,
      "z": 8,
      "name": "Wood_Crystal_Trunk_Full"
    },
    {
      "x": 7,
      "y": 9,
      "z": 8,
      "name": "Wood_Crystal_Trunk_Full"
    },
    {
      "x": 8,
      "y": 4,
      "z": 7,
      "name": "Wood_Crystal_Roots"
    },
    {
      "x": 8,
      "y": 5,
      "z": 7,
      "name": "Wood_Crystal_Trunk_Full"
    },
    {
      "x": 8,
      "y": 6,
      "z": 7,
      "name": "Wood_Crystal_Trunk_Full"
    },
    {
      "x": 8,
      "y": 7,
      "z": 7,
      "name": "Wood_Crystal_Trunk_Full"
    },
    {
      "x": 8,
      "y": 8,
      "z": 7,
      "name": "Wood_Crystal_Trunk_Full"
    },
    {
      "x": 8,
      "y": 9,
      "z": 9,
      "name": "Wood_Crystal_Trunk_Full"
    },
    {
      "x": 8,
      "y": 10,
      "z": 9,
      "name": "Wood_Crystal_Trunk_Full"
    },
    {
      "x": 8,
      "y": 10,
      "z": 10,
      "name": "Plant_Leaves_Crystal"
    },
    {
      "x": 8,
      "y": 10,
      "z": 11,
      "name": "Plant_Leaves_Crystal"
    },
    {
      "x": 9,
      "y": 9,
      "z": 6,
      "name": "Plant_Leaves_Crystal"
    },
    {
      "x": 9,
      "y": 10,
      "z": 6,
      "name": "Plant_Fruit_Pinkberry"
    },
    {
      "x": 9,
      "y": 8,
      "z": 7,
      "name": "Wood_Crystal_Trunk_Full"
    },
    {
      "x": 9,
      "y": 9,
      "z": 7,
      "name": "Wood_Crystal_Trunk_Full"
    },
    {
      "x": 9,
      "y": 10,
      "z": 9,
      "name": "Wood_Crystal_Trunk_Full"
    },
    {
      "x": 9,
      "y": 10,
      "z": 10,
      "name": "Wood_Crystal_Trunk_Full"
    },
    {
      "x": 9,
      "y": 11,
      "z": 10,
      "name": "Plant_Leaves_Crystal"
    },
    {
      "x": 9,
      "y": 11,
      "z": 11,
      "name": "Plant_Leaves_Crystal"
    },
    {
      "x": 9,
      "y": 10,
      "z": 12,
      "name": "Plant_Leaves_Crystal"
    },
    {
      "x": 9,
      "y": 11,
      "z": 12,
      "name": "Plant_Leaves_Crystal"
    },
    {
      "x": 10,
      "y": 10,
      "z": 4,
      "name": "Plant_Leaves_Crystal"
    },
    {
      "x": 10,
      "y": 9,
      "z": 5,
      "name": "Plant_Leaves_Crystal"
    },
    {
      "x": 10,
      "y": 10,
      "z": 5,
      "name": "Plant_Leaves_Crystal"
    },
    {
      "x": 10,
      "y": 9,
      "z": 6,
      "name": "Wood_Crystal_Trunk_Full"
    },
    {
      "x": 10,
      "y": 10,
      "z": 6,
      "name": "Plant_Leaves_Crystal"
    },
    {
      "x": 10,
      "y": 9,
      "z": 7,
      "name": "Wood_Crystal_Trunk_Full"
    },
    {
      "x": 10,
      "y": 10,
      "z": 9,
      "name": "Plant_Leaves_Crystal"
    },
    {
      "x": 10,
      "y": 10,
      "z": 10,
      "name": "Wood_Crystal_Trunk_Full"
    },
    {
      "x": 10,
      "y": 11,
      "z": 10,
      "name": "Plant_Leaves_Crystal"
    },
    {
      "x": 10,
      "y": 10,
      "z": 11,
      "name": "Plant_Leaves_Crystal"
    },
    {
      "x": 10,
      "y": 11,
      "z": 11,
      "name": "Plant_Leaves_Crystal"
    },
    {
      "x": 10,
      "y": 10,
      "z": 12,
      "name": "Plant_Leaves_Crystal"
    },
    {
      "x": 10,
      "y": 10,
      "z": 13,
      "name": "Plant_Leaves_Crystal"
    },
    {
      "x": 11,
      "y": 9,
      "z": 4,
      "name": "Plant_Leaves_Crystal"
    },
    {
      "x": 11,
      "y": 9,
      "z": 5,
      "name": "Plant_Leaves_Crystal"
    },
    {
      "x": 11,
      "y": 10,
      "z": 5,
      "name": "Plant_Leaves_Crystal"
    },
    {
      "x": 11,
      "y": 9,
      "z": 6,
      "name": "Wood_Crystal_Trunk_Full"
    },
    {
      "x": 11,
      "y": 10,
      "z": 6,
      "name": "Plant_Leaves_Crystal"
    },
    {
      "x": 11,
      "y": 9,
      "z": 7,
      "name": "Plant_Leaves_Crystal"
    },
    {
      "x": 11,
      "y": 10,
      "z": 7,
      "name": "Plant_Leaves_Crystal"
    },
    {
      "x": 11,
      "y": 10,
      "z": 9,
      "name": "Plant_Leaves_Crystal"
    },
    {
      "x": 11,
      "y": 10,
      "z": 10,
      "name": "Wood_Crystal_Trunk_Full"
    },
    {
      "x": 11,
      "y": 11,
      "z": 10,
      "name": "Plant_Leaves_Crystal"
    },
    {
      "x": 11,
      "y": 10,
      "z": 11,
      "name": "Plant_Leaves_Crystal"
    },
    {
      "x": 11,
      "y": 11,
      "z": 11,
      "name": "Plant_Leaves_Crystal"
    },
    {
      "x": 11,
      "y": 9,
      "z": 12,
      "name": "Plant_Leaves_Crystal"
    },
    {
      "x": 11,
      "y": 10,
      "z": 12,
      "name": "Plant_Fruit_Pinkberry"
    },
    {
      "x": 11,
      "y": 11,
      "z": 12,
      "name": "Plant_Leaves_Crystal"
    },
    {
      "x": 11,
      "y": 10,
      "z": 13,
      "name": "Plant_Leaves_Crystal"
    },
    {
      "x": 12,
      "y": 9,
      "z": 3,
      "name": "Plant_Leaves_Crystal"
    },
    {
      "x": 12,
      "y": 9,
      "z": 4,
      "name": "Plant_Leaves_Crystal"
    },
    {
      "x": 12,
      "y": 10,
      "z": 4,
      "name": "Plant_Fruit_Pinkberry"
    },
    {
      "x": 12,
      "y": 9,
      "z": 5,
      "name": "Plant_Leaves_Crystal"
    },
    {
      "x": 12,
      "y": 10,
      "z": 5,
      "name": "Plant_Leaves_Crystal"
    },
    {
      "x": 12,
      "y": 9,
      "z": 6,
      "name": "Plant_Leaves_Crystal"
    },
    {
      "x": 12,
      "y": 10,
      "z": 6,
      "name": "Plant_Leaves_Crystal"
    },
    {
      "x": 12,
      "y": 11,
      "z": 6,
      "name": "Plant_Leaves_Crystal"
    },
    {
      "x": 12,
      "y": 9,
      "z": 7,
      "name": "Plant_Leaves_Crystal"
    },
    {
      "x": 12,
      "y": 10,
      "z": 7,
      "name": "Plant_Leaves_Crystal"
    },
    {
      "x": 12,
      "y": 11,
      "z": 7,
      "name": "Plant_Fruit_Pinkberry"
    },
    {
      "x": 12,
      "y": 10,
      "z": 8,
      "name": "Plant_Leaves_Crystal"
    },
    {
      "x": 12,
      "y": 10,
      "z": 9,
      "name": "Plant_Leaves_Crystal"
    },
    {
      "x": 12,
      "y": 10,
      "z": 10,
      "name": "Plant_Leaves_Crystal"
    },
    {
      "x": 12,
      "y": 11,
      "z": 10,
      "name": "Plant_Leaves_Crystal"
    },
    {
      "x": 12,
      "y": 10,
      "z": 11,
      "name": "Plant_Leaves_Crystal"
    },
    {
      "x": 12,
      "y": 11,
      "z": 11,
      "name": "Plant_Leaves_Crystal"
    },
    {
      "x": 12,
      "y": 9,
      "z": 12,
      "name": "Plant_Leaves_Crystal"
    },
    {
      "x": 12,
      "y": 10,
      "z": 12,
      "name": "Plant_Leaves_Crystal"
    },
    {
      "x": 12,
      "y": 9,
      "z": 13,
      "name": "Plant_Leaves_Crystal"
    },
    {
      "x": 13,
      "y": 9,
      "z": 3,
      "name": "Plant_Leaves_Crystal"
    },
    {
      "x": 13,
      "y": 9,
      "z": 4,
      "name": "Plant_Leaves_Crystal"
    },
    {
      "x": 13,
      "y": 10,
      "z": 5,
      "name": "Plant_Leaves_Crystal"
    },
    {
      "x": 13,
      "y": 10,
      "z": 6,
      "name": "Plant_Leaves_Crystal"
    },
    {
      "x": 13,
      "y": 11,
      "z": 6,
      "name": "Plant_Leaves_Crystal"
    },
    {
      "x": 13,
      "y": 9,
      "z": 10,
      "name": "Plant_Leaves_Crystal"
    },
    {
      "x": 13,
      "y": 10,
      "z": 10,
      "name": "Plant_Fruit_Pinkberry"
    },
    {
      "x": 13,
      "y": 9,
      "z": 11,
      "name": "Plant_Leaves_Crystal"
    },
    {
      "x": 13,
      "y": 10,
      "z": 11,
      "name": "Plant_Leaves_Crystal"
    },
    {
      "x": 13,
      "y": 8,
      "z": 12,
      "name": "Plant_Leaves_Crystal"
    },
    {
      "x": 13,
      "y": 9,
      "z": 12,
      "name": "Plant_Leaves_Crystal"
    },
    {
      "x": 13,
      "y": 10,
      "z": 12,
      "name": "Plant_Leaves_Crystal"
    },
    {
      "x": 13,
      "y": 8,
      "z": 13,
      "name": "Plant_Leaves_Crystal"
    },
    {
      "x": 13,
      "y": 9,
      "z": 13,
      "name": "Plant_Leaves_Crystal"
    },
    {
      "x": 14,
      "y": 10,
      "z": 5,
      "name": "Plant_Leaves_Crystal"
    },
    {
      "x": 14,
      "y": 10,
      "z": 6,
      "name": "Plant_Leaves_Crystal"
    }
  ]
}