{
  "version": 8,
  "blockIdVersion": 8,
  "anchorX": 0,
  "anchorY": -1,
  "anchorZ": 0,
  "blocks": [
    {
      "x": -4,
      "y": 0,
      "z": 0,
      "name": "Plant_Leaves_Fir_Snow",
      "rotation": 3
    },
    {
      "x": -3,
      "y": 0,
      "z": 0,
      "name": "Plant_Leaves_Fir_Snow",
      "rotation": 3
    },
    {
      "x": -3,
      "y": 1,
      "z": 0,
      "name": "Plant_Leaves_Fir_Snow",
      "rotation": 3
    },
    {
      "x": -2,
      "y": 1,
      "z": -1,
      "name": "Plant_Leaves_Fir_Snow",
      "rotation": 3
    },
    {
      "x": -2,
      "y": 2,
      "z": -1,
      "name": "Plant_Leaves_Fir_Snow",
      "rotation": 3
    },
    {
      "x": -2,
      "y": 5,
      "z": -1,
      "name": "Plant_Leaves_Fir_Snow",
      "rotation": 3
    },
    {
      "x": -2,
      "y": 1,
      "z": 0,
      "name": "Plant_Leaves_Fir_Snow",
      "rotation": 3
    },
    {
      "x": -2,
      "y": 2,
      "z": 0,
      "name": "Plant_Leaves_Fir_Snow",
      "rotation": 3
    },
    {
      "x": -2,
      "y": 5,
      "z": 0,
      "name": "Plant_Leaves_Fir_Snow",
      "rotation": 3
    },
    {
      "x": -2,
      "y": 8,
      "z": 0,
      "name": "Plant_Leaves_Fir_Snow",
      "rotation": 3
    },
    {
      "x": -2,
      "y": 11,
      "z": 0,
      "name": "Plant_Leaves_Fir_Snow",
      "rotation": 3
    },
    {
      "x": -2,
      "y": 2,
      "z": 1,
      "name": "Plant_Leaves_Fir_Snow",
      "rotation": 3
    },
    {
      "x": -2,
      "y": 6,
      "z": 1,
      "name": "Plant_Leaves_Fir_Snow",
      "rotation": 3
    },
    {
      "x": -2,
      "y": 6,
      "z": 2,
      "name": "Plant_Leaves_Fir_Snow",
      "rotation": 3
    },
    {
      "x": -1,
      "y": 1,
      "z": -2,
      "name": "Plant_Leaves_Fir_Snow",
      "rotation": 3
    },
    {
      "x": -1,
      "y": 5,
      "z": -2,
      "name": "Plant_Leaves_Fir_Snow",
      "rotation": 2
    },
    {
      "x": -1,
      "y": -5,
      "z": -1,
      "name": "Wood_Fir_Roots"
    },
    {
      "x": -1,
      "y": -4,
      "z": -1,
      "name": "Wood_Fir_Trunk"
    },
    {
      "x": -1,
      "y": -3,
      "z": -1,
      "name": "Wood_Fir_Trunk_Full"
    },
    {
      "x": -1,
      "y": 1,
      "z": -1,
      "name": "Plant_Leaves_Fir_Snow",
      "rotation": 3
    },
    {
      "x": -1,
      "y": 2,
      "z": -1,
      "name": "Plant_Leaves_Fir_Snow",
      "rotation": 3
    },
    {
      "x": -1,
      "y": 5,
      "z": -1,
      "name": "Plant_Leaves_Fir_Snow",
      "rotation": 3
    },
    {
      "x": -1,
      "y": 8,
      "z": -1,
      "name": "Plant_Leaves_Fir_Snow",
      "rotation": 3
    },
    {
      "x": -1,
      "y": 11,
      "z": -1,
      "name": "Plant_Leaves_Fir_Snow",
      "rotation": 3
    },
    {
      "x": -1,
      "y": 1,
      "z": 0,
      "name": "Plant_Leaves_Fir_Snow",
      "rotation": 3
    },
    {
      "x": -1,
      "y": 2,
      "z": 0,
      "name": "Plant_Leaves_Fir_Snow",
      "rotation": 3
    },
    {
      "x": -1,
      "y": 3,
      "z": 0,
      "name": "Plant_Leaves_Fir_Snow",
      "rotation": 3
    },
    {
      "x": -1,
      "y": 5,
      "z": 0,
      "name": "Plant_Leaves_Fir_Snow",
      "rotation": 3
    },
    {
      "x": -1,
      "y": 6,
      "z": 0,
      "name": "Plant_Leaves_Fir_Snow",
      "rotation": 3
    },
    {
      "x": -1,
      "y": 8,
      "z": 0,
      "name": "Wood_Fir_Branch_Long",
      "rotation": 5
    },
    {
      "x": -1,
      "y": 9,
      "z": 0,
      "name": "Plant_Leaves_Fir_Snow",
      "rotation": 3
    },
    {
      "x": -1,
      "y": 11,
      "z": 0,
      "name": "Plant_Leaves_Fir_Snow",
      "rotation": 3
    },
    {
      "x": -1,
      "y": 14,
      "z": 0,
      "name": "Plant_Leaves_Fir_Snow",
      "rotation": 3
    },
    {
      "x": -1,
      "y": 15,
      "z": 0,
      "name": "Plant_Leaves_Fir_Snow",
      "rotation": 3
    },
    {
      "x": -1,
      "y": 17,
      "z": 0,
      "name": "Plant_Leaves_Fir_Snow",
      "rotation": 3
    },
    {
      "x": -1,
      "y": 18,
      "z": 0,
      "name": "Plant_Leaves_Fir_Snow",
      "rotation": 3
    },
    {
      "x": -1,
      "y": 20,
      "z": 0,
      "name": "Plant_Leaves_Fir_Snow",
      "rotation": 3
    },
    {
      "x": -1,
      "y": 2,
      "z": 1,
      "name": "Plant_Leaves_Fir_Snow",
      "rotation": 3
    },
    {
      "x": -1,
      "y": 5,
      "z": 1,
      "name": "Plant_Leaves_Fir_Snow",
      "rotation": 3
    },
    {
      "x": -1,
      "y": 6,
      "z": 1,
      "name": "Plant_Leaves_Fir_Snow"
    },
    {
      "x": -1,
      "y": 9,
      "z": 1,
      "name": "Plant_Leaves_Fir_Snow",
      "rotation": 3
    },
    {
      "x": -1,
      "y": 12,
      "z": 1,
      "name": "Plant_Leaves_Fir_Snow",
      "rotation": 3
    },
    {
      "x": -1,
      "y": 6,
      "z": 2,
      "name": "Plant_Leaves_Fir_Snow"
    },
    {
      "x": -1,
      "y": 8,
      "z": 2,
      "name": "Plant_Leaves_Fir_Snow",
      "rotation": 3
    },
    {
      "x": 0,
      "y": 1,
      "z": -4,
      "name": "Plant_Leaves_Fir_Snow",
      "rotation": 2
    },
    {
      "x": 0,
      "y": 1,
      "z": -3,
      "name": "Plant_Leaves_Fir_Snow",
      "rotation": 2
    },
    {
      "x": 0,
      "y": 2,
      "z": -3,
      "name": "Plant_Leaves_Fir_Snow",
      "rotation": 2
    },
    {
      "x": 0,
      "y": 5,
      "z": -3,
      "name": "Plant_Leaves_Fir_Snow",
      "rotation": 2
    },
    {
      "x": 0,
      "y": 1,
      "z": -2,
      "name": "Plant_Leaves_Fir_Snow",
      "rotation": 2
    },
    {
      "x": 0,
      "y": 2,
      "z": -2,
      "name": "Plant_Leaves_Fir_Snow",
      "rotation": 2
    },
    {
      "x": 0,
      "y": 3,
      "z": -2,
      "name": "Plant_Leaves_Fir_Snow",
      "rotation": 2
    },
    {
      "x": 0,
      "y": 5,
      "z": -2,
      "name": "Plant_Leaves_Fir_Snow",
      "rotation": 2
    },
    {
      "x": 0,
      "y": 8,
      "z": -2,
      "name": "Plant_Leaves_Fir_Snow",
      "rotation": 2
    },
    {
      "x": 0,
      "y": 10,
      "z": -2,
      "name": "Plant_Leaves_Fir_Snow",
      "rotation": 2
    },
    {
      "x": 0,
      "y": -4,
      "z": -1,
      "name": "Wood_Fir_Roots"
    },
    {
      "x": 0,
      "y": -3,
      "z": -1,
      "name": "Wood_Fir_Trunk"
    },
    {
      "x": 0,
      "y": -2,
      "z": -1,
      "name": "Wood_Fir_Trunk_Full"
    },
    {
      "x": 0,
      "y": 2,
      "z": -1,
      "name": "Plant_Leaves_Fir_Snow",
      "rotation": 2
    },
    {
      "x": 0,
      "y": 3,
      "z": -1,
      "name": "Wood_Fir_Branch_Short",
      "rotation": 2
    },
    {
      "x": 0,
      "y": 5,
      "z": -1,
      "name": "Wood_Fir_Branch_Long",
      "rotation": 4
    },
    {
      "x": 0,
      "y": 6,
      "z": -1,
      "name": "Plant_Leaves_Fir_Snow",
      "rotation": 2
    },
    {
      "x": 0,
      "y": 8,
      "z": -1,
      "name": "Plant_Leaves_Fir_Snow",
      "rotation": 2
    },
    {
      "x": 0,
      "y": 9,
      "z": -1,
      "name": "Plant_Leaves_Fir_Snow",
      "rotation": 2
    },
    {
      "x": 0,
      "y": 10,
      "z": -1,
      "name": "Wood_Fir_Branch_Long",
      "rotation": 4
    },
    {
      "x": 0,
      "y": 11,
      "z": -1,
      "name": "Plant_Leaves_Fir_Snow",
      "rotation": 2
    },
    {
      "x": 0,
      "y": 12,
      "z": -1,
      "name": "Plant_Leaves_Fir_Snow",
      "rotation": 2
    },
    {
      "x": 0,
      "y": 14,
      "z": -1,
      "name": "Plant_Leaves_Fir_Snow",
      "rotation": 2
    },
    {
      "x": 0,
      "y": 15,
      "z": -1,
      "name": "Wood_Fir_Branch_Short",
      "rotation": 2
    },
    {
      "x": 0,
      "y": 17,
      "z": -1,
      "name": "Plant_Leaves_Fir_Snow",
      "rotation": 2
    },
    {
      "x": 0,
      "y": 18,
      "z": -1,
      "name": "Plant_Leaves_Fir_Snow",
      "rotation": 2
    },
    {
      "x": 0,
      "y": 20,
      "z": -1,
      "name": "Plant_Leaves_Fir_Snow",
      "rotation": 2
    },
    {
      "x": 0,
      "y": -3,
      "z": 0,
      "name": "Wood_Fir_Roots"
    },
    {
      "x": 0,
      "y": -2,
      "z": 0,
      "name": "Wood_Fir_Trunk"
    },
    {
      "x": 0,
      "y": -1,
      "z": 0,
      "name": "Wood_Fir_Trunk"
    },
    {
      "x": 0,
      "y": 0,
      "z": 0,
      "name": "Wood_Fir_Trunk"
    },
    {
      "x": 0,
      "y": 1,
      "z": 0,
      "name": "Wood_Fir_Trunk"
    },
    {
      "x": 0,
      "y": 2,
      "z": 0,
      "name": "Wood_Fir_Trunk"
    },
    {
      "x": 0,
      "y": 3,
      "z": 0,
      "name": "Wood_Fir_Trunk"
    },
    {
      "x": 0,
      "y": 4,
      "z": 0,
      "name": "Wood_Fir_Trunk"
    },
    {
      "x": 0,
      "y": 5,
      "z": 0,
      "name": "Wood_Fir_Trunk"
    },
    {
      "x": 0,
      "y": 6,
      "z": 0,
      "name": "Wood_Fir_Trunk"
    },
    {
      "x": 0,
      "y": 7,
      "z": 0,
      "name": "Wood_Fir_Trunk"
    },
    {
      "x": 0,
      "y": 8,
      "z": 0,
      "name": "Wood_Fir_Trunk"
    },
    {
      "x": 0,
      "y": 9,
      "z": 0,
      "name": "Wood_Fir_Trunk"
    },
    {
      "x": 0,
      "y": 10,
      "z": 0,
      "name": "Wood_Fir_Trunk"
    },
    {
      "x": 0,
      "y": 11,
      "z": 0,
      "name": "Wood_Fir_Trunk"
    },
    {
      "x": 0,
      "y": 12,
      "z": 0,
      "name": "Wood_Fir_Trunk"
    },
    {
      "x": 0,
      "y": 13,
      "z": 0,
      "name": "Wood_Fir_Trunk"
    },
    {
      "x": 0,
      "y": 14,
      "z": 0,
      "name": "Wood_Fir_Trunk"
    },
    {
      "x": 0,
      "y": 15,
      "z": 0,
      "name": "Wood_Fir_Trunk_Full"
    },
    {
      "x": 0,
      "y": 16,
      "z": 0,
      "name": "Wood_Fir_Branch_Long"
    },
    {
      "x": 0,
      "y": 17,
      "z": 0,
      "name": "Wood_Fir_Branch_Long"
    },
    {
      "x": 0,
      "y": 18,
      "z": 0,
      "name": "Wood_Fir_Branch_Long"
    },
    {
      "x": 0,
      "y": 19,
      "z": 0,
      "name": "Wood_Fir_Branch_Long"
    },
    {
      "x": 0,
      "y": 20,
      "z": 0,
      "name": "Wood_Fir_Branch_Long"
    },
    {
      "x": 0,
      "y": 21,
      "z": 0,
      "name": "Plant_Leaves_Fir_Tip_Snow"
    },
    {
      "x": 0,
      "y": 22,
      "z": 0,
      "name": "Plant_Leaves_Fir_Tip_Snow"
    },
    {
      "x": 0,
      "y": 23,
      "z": 0,
      "name": "Plant_Leaves_Fir_Tip_Snow"
    },
    {
      "x": 0,
      "y": 24,
      "z": 0,
      "name": "Plant_Leaves_Fir_Tip_Snow"
    },
    {
      "x": 0,
      "y": 25,
      "z": 0,
      "name": "Plant_Leaves_Fir_Tip_Snow"
    },
    {
      "x": 0,
      "y": 26,
      "z": 0,
      "name": "Plant_Leaves_Fir_Tip_Snow"
    },
    {
      "x": 0,
      "y": -6,
      "z": 1,
      "name": "Wood_Fir_Roots"
    },
    {
      "x": 0,
      "y": -5,
      "z": 1,
      "name": "Wood_Fir_Trunk"
    },
    {
      "x": 0,
      "y": -4,
      "z": 1,
      "name": "Wood_Fir_Trunk"
    },
    {
      "x": 0,
      "y": -3,
      "z": 1,
      "name": "Wood_Fir_Trunk"
    },
    {
      "x": 0,
      "y": -2,
      "z": 1,
      "name": "Wood_Fir_Trunk"
    },
    {
      "x": 0,
      "y": -1,
      "z": 1,
      "name": "Wood_Fir_Trunk_Full"
    },
    {
      "x": 0,
      "y": 2,
      "z": 1,
      "name": "Plant_Leaves_Fir_Snow"
    },
    {
      "x": 0,
      "y": 3,
      "z": 1,
      "name": "Plant_Leaves_Fir_Snow"
    },
    {
      "x": 0,
      "y": 5,
      "z": 1,
      "name": "Plant_Leaves_Fir_Snow"
    },
    {
      "x": 0,
      "y": 6,
      "z": 1,
      "name": "Plant_Leaves_Fir_Snow"
    },
    {
      "x": 0,
      "y": 8,
      "z": 1,
      "name": "Plant_Leaves_Fir_Snow"
    },
    {
      "x": 0,
      "y": 9,
      "z": 1,
      "name": "Plant_Leaves_Fir_Snow"
    },
    {
      "x": 0,
      "y": 11,
      "z": 1,
      "name": "Plant_Leaves_Fir_Snow"
    },
    {
      "x": 0,
      "y": 12,
      "z": 1,
      "name": "Plant_Leaves_Fir_Snow"
    },
    {
      "x": 0,
      "y": 13,
      "z": 1,
      "name": "Plant_Leaves_Fir_Snow"
    },
    {
      "x": 0,
      "y": 15,
      "z": 1,
      "name": "Plant_Leaves_Fir_Snow"
    },
    {
      "x": 0,
      "y": 17,
      "z": 1,
      "name": "Plant_Leaves_Fir_Snow"
    },
    {
      "x": 0,
      "y": 18,
      "z": 1,
      "name": "Plant_Leaves_Fir_Snow"
    },
    {
      "x": 0,
      "y": 21,
      "z": 1,
      "name": "Plant_Leaves_Fir_Snow"
    },
    {
      "x": 0,
      "y": 22,
      "z": 1,
      "name": "Plant_Leaves_Fir_Snow"
    },
    {
      "x": 0,
      "y": 2,
      "z": 2,
      "name": "Plant_Leaves_Fir_Snow"
    },
    {
      "x": 0,
      "y": 3,
      "z": 2,
      "name": "Plant_Leaves_Fir_Snow"
    },
    {
      "x": 0,
      "y": 5,
      "z": 2,
      "name": "Plant_Leaves_Fir_Snow"
    },
    {
      "x": 0,
      "y": 6,
      "z": 2,
      "name": "Plant_Leaves_Fir_Snow"
    },
    {
      "x": 0,
      "y": 8,
      "z": 2,
      "name": "Plant_Leaves_Fir_Snow"
    },
    {
      "x": 0,
      "y": 10,
      "z": 2,
      "name": "Plant_Leaves_Fir_Snow"
    },
    {
      "x": 0,
      "y": 1,
      "z": 3,
      "name": "Plant_Leaves_Fir_Snow"
    },
    {
      "x": 0,
      "y": 2,
      "z": 3,
      "name": "Plant_Leaves_Fir_Snow"
    },
    {
      "x": 0,
      "y": 5,
      "z": 3,
      "name": "Plant_Leaves_Fir_Snow"
    },
    {
      "x": 0,
      "y": 1,
      "z": 4,
      "name": "Plant_Leaves_Fir_Snow"
    },
    {
      "x": 1,
      "y": 1,
      "z": -4,
      "name": "Plant_Leaves_Fir_Snow",
      "rotation": 2
    },
    {
      "x": 1,
      "y": 1,
      "z": -3,
      "name": "Plant_Leaves_Fir_Snow",
      "rotation": 2
    },
    {
      "x": 1,
      "y": 2,
      "z": -3,
      "name": "Plant_Leaves_Fir_Snow",
      "rotation": 1
    },
    {
      "x": 1,
      "y": 1,
      "z": -2,
      "name": "Plant_Leaves_Fir_Snow",
      "rotation": 1
    },
    {
      "x": 1,
      "y": 2,
      "z": -2,
      "name": "Plant_Leaves_Fir_Snow",
      "rotation": 2
    },
    {
      "x": 1,
      "y": 5,
      "z": -2,
      "name": "Plant_Leaves_Fir_Snow",
      "rotation": 1
    },
    {
      "x": 1,
      "y": -8,
      "z": -1,
      "name": "Wood_Fir_Roots"
    },
    {
      "x": 1,
      "y": -7,
      "z": -1,
      "name": "Wood_Fir_Trunk"
    },
    {
      "x": 1,
      "y": -6,
      "z": -1,
      "name": "Wood_Fir_Trunk"
    },
    {
      "x": 1,
      "y": -5,
      "z": -1,
      "name": "Wood_Fir_Trunk"
    },
    {
      "x": 1,
      "y": -4,
      "z": -1,
      "name": "Wood_Fir_Trunk"
    },
    {
      "x": 1,
      "y": -3,
      "z": -1,
      "name": "Wood_Fir_Trunk"
    },
    {
      "x": 1,
      "y": -2,
      "z": -1,
      "name": "Wood_Fir_Trunk_Full"
    },
    {
      "x": 1,
      "y": 2,
      "z": -1,
      "name": "Plant_Leaves_Fir_Snow",
      "rotation": 2
    },
    {
      "x": 1,
      "y": 3,
      "z": -1,
      "name": "Plant_Leaves_Fir_Snow",
      "rotation": 1
    },
    {
      "x": 1,
      "y": 5,
      "z": -1,
      "name": "Plant_Leaves_Fir_Snow",
      "rotation": 1
    },
    {
      "x": 1,
      "y": 11,
      "z": -1,
      "name": "Plant_Leaves_Fir_Snow",
      "rotation": 1
    },
    {
      "x": 1,
      "y": 2,
      "z": 0,
      "name": "Plant_Leaves_Fir_Snow",
      "rotation": 1
    },
    {
      "x": 1,
      "y": 3,
      "z": 0,
      "name": "Plant_Leaves_Fir_Snow",
      "rotation": 1
    },
    {
      "x": 1,
      "y": 5,
      "z": 0,
      "name": "Wood_Fir_Branch_Corner",
      "rotation": 1
    },
    {
      "x": 1,
      "y": 6,
      "z": 0,
      "name": "Plant_Leaves_Fir_Snow",
      "rotation": 1
    },
    {
      "x": 1,
      "y": 8,
      "z": 0,
      "name": "Wood_Fir_Branch_Long",
      "rotation": 5
    },
    {
      "x": 1,
      "y": 9,
      "z": 0,
      "name": "Plant_Leaves_Fir_Snow",
      "rotation": 1
    },
    {
      "x": 1,
      "y": 11,
      "z": 0,
      "name": "Wood_Fir_Branch_Corner",
      "rotation": 1
    },
    {
      "x": 1,
      "y": 12,
      "z": 0,
      "name": "Plant_Leaves_Fir_Snow",
      "rotation": 1
    },
    {
      "x": 1,
      "y": 14,
      "z": 0,
      "name": "Plant_Leaves_Fir_Snow",
      "rotation": 1
    },
    {
      "x": 1,
      "y": 15,
      "z": 0,
      "name": "Plant_Leaves_Fir_Snow",
      "rotation": 1
    },
    {
      "x": 1,
      "y": 17,
      "z": 0,
      "name": "Plant_Leaves_Fir_Snow",
      "rotation": 1
    },
    {
      "x": 1,
      "y": 18,
      "z": 0,
      "name": "Plant_Leaves_Fir_Snow",
      "rotation": 1
    },
    {
      "x": 1,
      "y": 20,
      "z": 0,
      "name": "Plant_Leaves_Fir_Snow",
      "rotation": 1
    },
    {
      "x": 1,
      "y": 21,
      "z": 0,
      "name": "Plant_Leaves_Fir_Snow",
      "rotation": 1
    },
    {
      "x": 1,
      "y": -4,
      "z": 1,
      "name": "Wood_Fir_Roots"
    },
    {
      "x": 1,
      "y": -3,
      "z": 1,
      "name": "Wood_Fir_Trunk_Full"
    },
    {
      "x": 1,
      "y": 2,
      "z": 1,
      "name": "Plant_Leaves_Fir_Snow"
    },
    {
      "x": 1,
      "y": 5,
      "z": 1,
      "name": "Plant_Leaves_Fir_Snow",
      "rotation": 1
    },
    {
      "x": 1,
      "y": 6,
      "z": 1,
      "name": "Plant_Leaves_Fir_Snow",
      "rotation": 1
    },
    {
      "x": 1,
      "y": 8,
      "z": 1,
      "name": "Plant_Leaves_Fir_Snow",
      "rotation": 1
    },
    {
      "x": 1,
      "y": 9,
      "z": 1,
      "name": "Plant_Leaves_Fir_Snow",
      "rotation": 1
    },
    {
      "x": 1,
      "y": 11,
      "z": 1,
      "name": "Plant_Leaves_Fir_Snow",
      "rotation": 1
    },
    {
      "x": 1,
      "y": 17,
      "z": 1,
      "name": "Plant_Leaves_Fir_Snow",
      "rotation": 1
    },
    {
      "x": 1,
      "y": 2,
      "z": 2,
      "name": "Plant_Leaves_Fir_Snow"
    },
    {
      "x": 1,
      "y": 5,
      "z": 2,
      "name": "Plant_Leaves_Fir_Snow"
    },
    {
      "x": 2,
      "y": 1,
      "z": -2,
      "name": "Plant_Leaves_Fir_Snow",
      "rotation": 1
    },
    {
      "x": 2,
      "y": 2,
      "z": -1,
      "name": "Plant_Leaves_Fir_Snow",
      "rotation": 2
    },
    {
      "x": 2,
      "y": 2,
      "z": 0,
      "name": "Plant_Leaves_Fir_Snow",
      "rotation": 1
    },
    {
      "x": 2,
      "y": 3,
      "z": 0,
      "name": "Plant_Leaves_Fir_Snow",
      "rotation": 1
    },
    {
      "x": 2,
      "y": 5,
      "z": 0,
      "name": "Plant_Leaves_Fir_Snow",
      "rotation": 1
    },
    {
      "x": 2,
      "y": 6,
      "z": 0,
      "name": "Plant_Leaves_Fir_Snow",
      "rotation": 1
    },
    {
      "x": 2,
      "y": 8,
      "z": 0,
      "name": "Plant_Leaves_Fir_Snow",
      "rotation": 1
    },
    {
      "x": 2,
      "y": 1,
      "z": 1,
      "name": "Plant_Leaves_Fir_Snow",
      "rotation": 1
    },
    {
      "x": 2,
      "y": 2,
      "z": 1,
      "name": "Plant_Leaves_Fir_Snow",
      "rotation": 1
    },
    {
      "x": 2,
      "y": 5,
      "z": 1,
      "name": "Plant_Leaves_Fir_Snow",
      "rotation": 1
    },
    {
      "x": 2,
      "y": 5,
      "z": 2,
      "name": "Plant_Leaves_Fir_Snow",
      "rotation": 1
    },
    {
      "x": 3,
      "y": 2,
      "z": 0,
      "name": "Plant_Leaves_Fir_Snow",
      "rotation": 1
    },
    {
      "x": 3,
      "y": 5,
      "z": 0,
      "name": "Plant_Leaves_Fir_Snow",
      "rotation": 1
    },
    {
      "x": 3,
      "y": 1,
      "z": 1,
      "name": "Plant_Leaves_Fir_Snow",
      "rotation": 1
    },
    {
      "x": 4,
      "y": 1,
      "z": 0,
      "name": "Plant_Leaves_Fir_Snow",
      "rotation": 1
    },
    {
      "x": 4,
      "y": 2,
      "z": 0,
      "name": "Plant_Leaves_Fir_Snow",
      "rotation": 1
    },
    {
      "x": 5,
      "y": 1,
      "z": 0,
      "name": "Plant_Leaves_Fir_Snow",
      "rotation": 1
    }
  ]
}