{
  "version": 8,
  "blockIdVersion": 8,
  "anchorX": 0,
  "anchorY": 5,
  "anchorZ": -3,
  "blocks": [
    {
      "x": -10,
      "y": 22,
      "z": 0,
      "name": "Plant_Leaves_Dry"
    },
    {
      "x": -9,
      "y": 22,
      "z": -2,
      "name": "Plant_Leaves_Dry"
    },
    {
      "x": -9,
      "y": 22,
      "z": -1,
      "name": "Plant_Leaves_Dry"
    },
    {
      "x": -9,
      "y": 22,
      "z": 0,
      "name": "Plant_Leaves_Dry"
    },
    {
      "x": -9,
      "y": 22,
      "z": 1,
      "name": "Plant_Leaves_Dry"
    },
    {
      "x": -9,
      "y": 22,
      "z": 2,
      "name": "Plant_Leaves_Dry"
    },
    {
      "x": -8,
      "y": 22,
      "z": -4,
      "name": "Plant_Leaves_Dry"
    },
    {
      "x": -8,
      "y": 22,
      "z": -3,
      "name": "Plant_Leaves_Dry"
    },
    {
      "x": -8,
      "y": 22,
      "z": -2,
      "name": "Plant_Leaves_Dry"
    },
    {
      "x": -8,
      "y": 22,
      "z": -1,
      "name": "Plant_Leaves_Dry"
    },
    {
      "x": -8,
      "y": 23,
      "z": -1,
      "name": "Plant_Leaves_Dry"
    },
    {
      "x": -8,
      "y": 22,
      "z": 0,
      "name": "Plant_Leaves_Dry"
    },
    {
      "x": -8,
      "y": 22,
      "z": 1,
      "name": "Plant_Leaves_Dry"
    },
    {
      "x": -8,
      "y": 22,
      "z": 2,
      "name": "Plant_Leaves_Dry"
    },
    {
      "x": -8,
      "y": 22,
      "z": 3,
      "name": "Plant_Leaves_Dry"
    },
    {
      "x": -8,
      "y": 22,
      "z": 4,
      "name": "Plant_Leaves_Dry"
    },
    {
      "x": -7,
      "y": 22,
      "z": -5,
      "name": "Plant_Leaves_Dry"
    },
    {
      "x": -7,
      "y": 22,
      "z": -4,
      "name": "Plant_Leaves_Dry"
    },
    {
      "x": -7,
      "y": 22,
      "z": -3,
      "name": "Plant_Leaves_Dry"
    },
    {
      "x": -7,
      "y": 22,
      "z": -2,
      "name": "Plant_Leaves_Dry"
    },
    {
      "x": -7,
      "y": 23,
      "z": -1,
      "name": "Plant_Leaves_Dry"
    },
    {
      "x": -7,
      "y": 22,
      "z": 0,
      "name": "Wood_Dry_Branch_Long",
      "rotation": 5
    },
    {
      "x": -7,
      "y": 23,
      "z": 0,
      "name": "Plant_Leaves_Dry"
    },
    {
      "x": -7,
      "y": 22,
      "z": 1,
      "name": "Plant_Leaves_Dry"
    },
    {
      "x": -7,
      "y": 22,
      "z": 2,
      "name": "Plant_Leaves_Dry"
    },
    {
      "x": -7,
      "y": 22,
      "z": 3,
      "name": "Plant_Leaves_Dry"
    },
    {
      "x": -7,
      "y": 22,
      "z": 4,
      "name": "Plant_Leaves_Dry"
    },
    {
      "x": -6,
      "y": 22,
      "z": -5,
      "name": "Plant_Leaves_Dry"
    },
    {
      "x": -6,
      "y": 22,
      "z": -4,
      "name": "Plant_Leaves_Dry"
    },
    {
      "x": -6,
      "y": 22,
      "z": -3,
      "name": "Plant_Leaves_Dry"
    },
    {
      "x": -6,
      "y": 23,
      "z": -2,
      "name": "Plant_Leaves_Dry"
    },
    {
      "x": -6,
      "y": 23,
      "z": -1,
      "name": "Plant_Leaves_Dry"
    },
    {
      "x": -6,
      "y": 22,
      "z": 0,
      "name": "Wood_Dry_Branch_Long",
      "rotation": 5
    },
    {
      "x": -6,
      "y": 23,
      "z": 0,
      "name": "Plant_Leaves_Dry"
    },
    {
      "x": -6,
      "y": 23,
      "z": 1,
      "name": "Plant_Leaves_Dry"
    },
    {
      "x": -6,
      "y": 23,
      "z": 2,
      "name": "Plant_Leaves_Dry"
    },
    {
      "x": -6,
      "y": 22,
      "z": 3,
      "name": "Plant_Leaves_Dry"
    },
    {
      "x": -6,
      "y": 22,
      "z": 4,
      "name": "Plant_Leaves_Dry"
    },
    {
      "x": -6,
      "y": 22,
      "z": 5,
      "name": "Plant_Leaves_Dry"
    },
    {
      "x": -5,
      "y": 22,
      "z": -5,
      "name": "Plant_Leaves_Dry"
    },
    {
      "x": -5,
      "y": 22,
      "z": -4,
      "name": "Plant_Leaves_Dry"
    },
    {
      "x": -5,
      "y": 22,
      "z": -3,
      "name": "Plant_Leaves_Dry"
    },
    {
      "x": -5,
      "y": 23,
      "z": -3,
      "name": "Plant_Leaves_Dry"
    },
    {
      "x": -5,
      "y": 22,
      "z": -2,
      "name": "Wood_Dry_Branch_Long",
      "rotation": 4
    },
    {
      "x": -5,
      "y": 23,
      "z": -2,
      "name": "Plant_Leaves_Dry"
    },
    {
      "x": -5,
      "y": 22,
      "z": -1,
      "name": "Wood_Dry_Branch_Long",
      "rotation": 4
    },
    {
      "x": -5,
      "y": 23,
      "z": -1,
      "name": "Plant_Leaves_Dry"
    },
    {
      "x": -5,
      "y": 22,
      "z": 0,
      "name": "Wood_Dry_Trunk_Full"
    },
    {
      "x": -5,
      "y": 22,
      "z": 1,
      "name": "Wood_Dry_Branch_Long",
      "rotation": 4
    },
    {
      "x": -5,
      "y": 22,
      "z": 2,
      "name": "Wood_Dry_Branch_Long",
      "rotation": 4
    },
    {
      "x": -5,
      "y": 23,
      "z": 2,
      "name": "Plant_Leaves_Dry"
    },
    {
      "x": -5,
      "y": 22,
      "z": 3,
      "name": "Plant_Leaves_Dry"
    },
    {
      "x": -5,
      "y": 22,
      "z": 4,
      "name": "Plant_Leaves_Dry"
    },
    {
      "x": -4,
      "y": 20,
      "z": -6,
      "name": "Plant_Leaves_Dry"
    },
    {
      "x": -4,
      "y": 20,
      "z": -5,
      "name": "Plant_Leaves_Dry"
    },
    {
      "x": -4,
      "y": 22,
      "z": -5,
      "name": "Plant_Leaves_Dry"
    },
    {
      "x": -4,
      "y": 20,
      "z": -4,
      "name": "Plant_Leaves_Dry"
    },
    {
      "x": -4,
      "y": 22,
      "z": -4,
      "name": "Plant_Leaves_Dry"
    },
    {
      "x": -4,
      "y": 22,
      "z": -3,
      "name": "Plant_Leaves_Dry"
    },
    {
      "x": -4,
      "y": 19,
      "z": -1,
      "name": "Wood_Dry_Trunk_Full"
    },
    {
      "x": -4,
      "y": 20,
      "z": -1,
      "name": "Wood_Dry_Trunk"
    },
    {
      "x": -4,
      "y": 21,
      "z": -1,
      "name": "Wood_Dry_Trunk_Full"
    },
    {
      "x": -4,
      "y": 23,
      "z": -1,
      "name": "Plant_Leaves_Dry"
    },
    {
      "x": -4,
      "y": 21,
      "z": 0,
      "name": "Wood_Dry_Trunk_Full"
    },
    {
      "x": -4,
      "y": 22,
      "z": 0,
      "name": "Wood_Dry_Trunk_Full"
    },
    {
      "x": -4,
      "y": 23,
      "z": 0,
      "name": "Plant_Leaves_Dry"
    },
    {
      "x": -4,
      "y": 23,
      "z": 1,
      "name": "Plant_Leaves_Dry"
    },
    {
      "x": -4,
      "y": 22,
      "z": 2,
      "name": "Plant_Leaves_Dry"
    },
    {
      "x": -4,
      "y": 22,
      "z": 4,
      "name": "Plant_Leaves_Dry"
    },
    {
      "x": -4,
      "y": 22,
      "z": 5,
      "name": "Plant_Leaves_Dry"
    },
    {
      "x": -3,
      "y": 20,
      "z": -6,
      "name": "Plant_Leaves_Dry"
    },
    {
      "x": -3,
      "y": 20,
      "z": -5,
      "name": "Plant_Leaves_Dry"
    },
    {
      "x": -3,
      "y": 22,
      "z": -4,
      "name": "Plant_Leaves_Dry"
    },
    {
      "x": -3,
      "y": 21,
      "z": -3,
      "name": "Plant_Leaves_Dry"
    },
    {
      "x": -3,
      "y": 22,
      "z": -3,
      "name": "Plant_Leaves_Dry"
    },
    {
      "x": -3,
      "y": 12,
      "z": -2,
      "name": "Plant_Vine_Wall_Dry",
      "rotation": 3
    },
    {
      "x": -3,
      "y": 13,
      "z": -2,
      "name": "Plant_Vine_Wall_Dry",
      "rotation": 3
    },
    {
      "x": -3,
      "y": 14,
      "z": -2,
      "name": "Plant_Vine_Wall_Dry",
      "rotation": 3
    },
    {
      "x": -3,
      "y": 21,
      "z": -2,
      "name": "Plant_Leaves_Dry"
    },
    {
      "x": -3,
      "y": 14,
      "z": -1,
      "name": "Wood_Dry_Trunk_Full"
    },
    {
      "x": -3,
      "y": 15,
      "z": -1,
      "name": "Wood_Dry_Trunk"
    },
    {
      "x": -3,
      "y": 16,
      "z": -1,
      "name": "Wood_Dry_Trunk"
    },
    {
      "x": -3,
      "y": 17,
      "z": -1,
      "name": "Wood_Dry_Trunk"
    },
    {
      "x": -3,
      "y": 18,
      "z": -1,
      "name": "Wood_Dry_Trunk"
    },
    {
      "x": -3,
      "y": 19,
      "z": -1,
      "name": "Wood_Dry_Trunk_Full"
    },
    {
      "x": -3,
      "y": 23,
      "z": 0,
      "name": "Plant_Leaves_Dry"
    },
    {
      "x": -3,
      "y": 20,
      "z": 1,
      "name": "Plant_Leaves_Dry"
    },
    {
      "x": -3,
      "y": 23,
      "z": 1,
      "name": "Plant_Leaves_Dry"
    },
    {
      "x": -3,
      "y": 20,
      "z": 2,
      "name": "Plant_Leaves_Dry"
    },
    {
      "x": -3,
      "y": 22,
      "z": 3,
      "name": "Plant_Leaves_Dry"
    },
    {
      "x": -3,
      "y": 22,
      "z": 4,
      "name": "Plant_Leaves_Dry"
    },
    {
      "x": -2,
      "y": 20,
      "z": -7,
      "name": "Plant_Leaves_Dry"
    },
    {
      "x": -2,
      "y": 20,
      "z": -6,
      "name": "Plant_Leaves_Dry"
    },
    {
      "x": -2,
      "y": 20,
      "z": -4,
      "name": "Plant_Leaves_Dry"
    },
    {
      "x": -2,
      "y": 11,
      "z": -3,
      "name": "Plant_Vine_Wall_Dry",
      "rotation": 2
    },
    {
      "x": -2,
      "y": 12,
      "z": -3,
      "name": "Plant_Vine_Wall_Dry",
      "rotation": 2
    },
    {
      "x": -2,
      "y": 13,
      "z": -3,
      "name": "Plant_Vine_Wall_Dry",
      "rotation": 2
    },
    {
      "x": -2,
      "y": 21,
      "z": -3,
      "name": "Plant_Leaves_Dry"
    },
    {
      "x": -2,
      "y": 11,
      "z": -2,
      "name": "Wood_Dry_Trunk_Full"
    },
    {
      "x": -2,
      "y": 12,
      "z": -2,
      "name": "Wood_Dry_Trunk"
    },
    {
      "x": -2,
      "y": 13,
      "z": -2,
      "name": "Wood_Dry_Trunk"
    },
    {
      "x": -2,
      "y": 14,
      "z": -2,
      "name": "Wood_Dry_Trunk_Full"
    },
    {
      "x": -2,
      "y": 20,
      "z": -2,
      "name": "Wood_Dry_Trunk_Full"
    },
    {
      "x": -2,
      "y": 21,
      "z": -2,
      "name": "Plant_Leaves_Dry"
    },
    {
      "x": -2,
      "y": 14,
      "z": -1,
      "name": "Wood_Dry_Trunk_Full"
    },
    {
      "x": -2,
      "y": 15,
      "z": -1,
      "name": "Wood_Dry_Trunk_Full"
    },
    {
      "x": -2,
      "y": 18,
      "z": -1,
      "name": "Wood_Dry_Trunk_Full"
    },
    {
      "x": -2,
      "y": 19,
      "z": -1,
      "name": "Wood_Dry_Trunk"
    },
    {
      "x": -2,
      "y": 20,
      "z": -1,
      "name": "Wood_Dry_Trunk_Full"
    },
    {
      "x": -2,
      "y": 21,
      "z": -1,
      "name": "Plant_Leaves_Dry"
    },
    {
      "x": -2,
      "y": 20,
      "z": 1,
      "name": "Plant_Leaves_Dry"
    },
    {
      "x": -2,
      "y": 20,
      "z": 2,
      "name": "Plant_Leaves_Dry"
    },
    {
      "x": -2,
      "y": 22,
      "z": 2,
      "name": "Plant_Leaves_Dry"
    },
    {
      "x": -2,
      "y": 20,
      "z": 3,
      "name": "Plant_Leaves_Dry"
    },
    {
      "x": -2,
      "y": 22,
      "z": 3,
      "name": "Plant_Leaves_Dry"
    },
    {
      "x": -2,
      "y": 22,
      "z": 4,
      "name": "Plant_Leaves_Dry"
    },
    {
      "x": -1,
      "y": 20,
      "z": -6,
      "name": "Plant_Leaves_Dry"
    },
    {
      "x": -1,
      "y": 20,
      "z": -5,
      "name": "Plant_Leaves_Dry"
    },
    {
      "x": -1,
      "y": 7,
      "z": -4,
      "name": "Plant_Vine_Wall_Dry",
      "rotation": 2
    },
    {
      "x": -1,
      "y": 8,
      "z": -4,
      "name": "Plant_Vine_Wall_Dry",
      "rotation": 2
    },
    {
      "x": -1,
      "y": 9,
      "z": -4,
      "name": "Plant_Vine_Wall_Dry",
      "rotation": 2
    },
    {
      "x": -1,
      "y": 10,
      "z": -4,
      "name": "Plant_Vine_Wall_Dry",
      "rotation": 2
    },
    {
      "x": -1,
      "y": 20,
      "z": -4,
      "name": "Wood_Dry_Branch_Long",
      "rotation": 4
    },
    {
      "x": -1,
      "y": 21,
      "z": -4,
      "name": "Plant_Leaves_Dry"
    },
    {
      "x": -1,
      "y": 5,
      "z": -3,
      "name": "Wood_Dry_Trunk"
    },
    {
      "x": -1,
      "y": 6,
      "z": -3,
      "name": "Wood_Dry_Trunk"
    },
    {
      "x": -1,
      "y": 7,
      "z": -3,
      "name": "Wood_Dry_Trunk"
    },
    {
      "x": -1,
      "y": 8,
      "z": -3,
      "name": "Wood_Dry_Trunk"
    },
    {
      "x": -1,
      "y": 9,
      "z": -3,
      "name": "Wood_Dry_Trunk"
    },
    {
      "x": -1,
      "y": 10,
      "z": -3,
      "name": "Wood_Dry_Trunk"
    },
    {
      "x": -1,
      "y": 11,
      "z": -3,
      "name": "Wood_Dry_Trunk_Full"
    },
    {
      "x": -1,
      "y": 20,
      "z": -3,
      "name": "Wood_Dry_Branch_Long",
      "rotation": 4
    },
    {
      "x": -1,
      "y": 11,
      "z": -2,
      "name": "Wood_Dry_Trunk_Full"
    },
    {
      "x": -1,
      "y": 20,
      "z": -2,
      "name": "Wood_Dry_Trunk_Full"
    },
    {
      "x": -1,
      "y": 20,
      "z": -1,
      "name": "Wood_Dry_Branch_Long",
      "rotation": 4
    },
    {
      "x": -1,
      "y": 21,
      "z": -1,
      "name": "Plant_Leaves_Dry"
    },
    {
      "x": -1,
      "y": 13,
      "z": 0,
      "name": "Plant_Leaves_Dry"
    },
    {
      "x": -1,
      "y": 20,
      "z": 0,
      "name": "Wood_Dry_Branch_Long",
      "rotation": 4
    },
    {
      "x": -1,
      "y": 21,
      "z": 0,
      "name": "Plant_Leaves_Dry"
    },
    {
      "x": -1,
      "y": 13,
      "z": 1,
      "name": "Plant_Leaves_Dry"
    },
    {
      "x": -1,
      "y": 20,
      "z": 1,
      "name": "Plant_Leaves_Dry"
    },
    {
      "x": -1,
      "y": 21,
      "z": 1,
      "name": "Plant_Leaves_Dry"
    },
    {
      "x": -1,
      "y": 13,
      "z": 2,
      "name": "Plant_Leaves_Dry"
    },
    {
      "x": -1,
      "y": 20,
      "z": 2,
      "name": "Plant_Leaves_Dry"
    },
    {
      "x": -1,
      "y": 13,
      "z": 3,
      "name": "Plant_Leaves_Dry"
    },
    {
      "x": -1,
      "y": 20,
      "z": 3,
      "name": "Plant_Leaves_Dry"
    },
    {
      "x": 0,
      "y": 20,
      "z": -7,
      "name": "Plant_Leaves_Dry"
    },
    {
      "x": 0,
      "y": 20,
      "z": -6,
      "name": "Plant_Leaves_Dry"
    },
    {
      "x": 0,
      "y": 20,
      "z": -5,
      "name": "Plant_Leaves_Dry"
    },
    {
      "x": 0,
      "y": 5,
      "z": -4,
      "name": "Wood_Dry_Trunk"
    },
    {
      "x": 0,
      "y": 6,
      "z": -4,
      "name": "Wood_Dry_Trunk_Full"
    },
    {
      "x": 0,
      "y": 7,
      "z": -4,
      "name": "Plant_Vine_Wall_Dry",
      "rotation": 2
    },
    {
      "x": 0,
      "y": 8,
      "z": -4,
      "name": "Plant_Vine_Wall_Dry",
      "rotation": 2
    },
    {
      "x": 0,
      "y": 21,
      "z": -4,
      "name": "Plant_Leaves_Dry"
    },
    {
      "x": 0,
      "y": 5,
      "z": -3,
      "name": "Wood_Dry_Trunk"
    },
    {
      "x": 0,
      "y": 6,
      "z": -3,
      "name": "Wood_Dry_Trunk"
    },
    {
      "x": 0,
      "y": 7,
      "z": -3,
      "name": "Wood_Dry_Trunk"
    },
    {
      "x": 0,
      "y": 8,
      "z": -3,
      "name": "Wood_Dry_Trunk"
    },
    {
      "x": 0,
      "y": 9,
      "z": -3,
      "name": "Wood_Dry_Trunk_Full"
    },
    {
      "x": 0,
      "y": 21,
      "z": -3,
      "name": "Plant_Leaves_Dry"
    },
    {
      "x": 0,
      "y": 20,
      "z": -2,
      "name": "Wood_Dry_Branch_Long",
      "rotation": 5
    },
    {
      "x": 0,
      "y": 21,
      "z": -2,
      "name": "Plant_Leaves_Dry"
    },
    {
      "x": 0,
      "y": 13,
      "z": -1,
      "name": "Plant_Leaves_Dry"
    },
    {
      "x": 0,
      "y": 21,
      "z": -1,
      "name": "Plant_Leaves_Dry"
    },
    {
      "x": 0,
      "y": 13,
      "z": 0,
      "name": "Plant_Leaves_Dry"
    },
    {
      "x": 0,
      "y": 21,
      "z": 0,
      "name": "Plant_Leaves_Dry"
    },
    {
      "x": 0,
      "y": 13,
      "z": 1,
      "name": "Plant_Leaves_Dry"
    },
    {
      "x": 0,
      "y": 20,
      "z": 1,
      "name": "Plant_Leaves_Dry"
    },
    {
      "x": 0,
      "y": 13,
      "z": 2,
      "name": "Plant_Leaves_Dry"
    },
    {
      "x": 0,
      "y": 20,
      "z": 2,
      "name": "Plant_Leaves_Dry"
    },
    {
      "x": 0,
      "y": 13,
      "z": 3,
      "name": "Plant_Leaves_Dry"
    },
    {
      "x": 0,
      "y": 20,
      "z": 3,
      "name": "Plant_Leaves_Dry"
    },
    {
      "x": 0,
      "y": 13,
      "z": 4,
      "name": "Plant_Leaves_Dry"
    },
    {
      "x": 0,
      "y": 13,
      "z": 5,
      "name": "Plant_Leaves_Dry"
    },
    {
      "x": 1,
      "y": 20,
      "z": -6,
      "name": "Plant_Leaves_Dry"
    },
    {
      "x": 1,
      "y": 20,
      "z": -5,
      "name": "Plant_Leaves_Dry"
    },
    {
      "x": 1,
      "y": 20,
      "z": -4,
      "name": "Plant_Leaves_Dry"
    },
    {
      "x": 1,
      "y": 9,
      "z": -3,
      "name": "Wood_Dry_Trunk_Full"
    },
    {
      "x": 1,
      "y": 10,
      "z": -3,
      "name": "Wood_Dry_Trunk_Full"
    },
    {
      "x": 1,
      "y": 20,
      "z": -3,
      "name": "Plant_Leaves_Dry"
    },
    {
      "x": 1,
      "y": 13,
      "z": -2,
      "name": "Plant_Leaves_Dry"
    },
    {
      "x": 1,
      "y": 20,
      "z": -2,
      "name": "Wood_Dry_Branch_Long",
      "rotation": 5
    },
    {
      "x": 1,
      "y": 21,
      "z": -2,
      "name": "Plant_Leaves_Dry"
    },
    {
      "x": 1,
      "y": 13,
      "z": -1,
      "name": "Plant_Leaves_Dry"
    },
    {
      "x": 1,
      "y": 21,
      "z": -1,
      "name": "Plant_Leaves_Dry"
    },
    {
      "x": 1,
      "y": 13,
      "z": 0,
      "name": "Plant_Leaves_Dry"
    },
    {
      "x": 1,
      "y": 20,
      "z": 0,
      "name": "Plant_Leaves_Dry"
    },
    {
      "x": 1,
      "y": 13,
      "z": 1,
      "name": "Wood_Dry_Branch_Long",
      "rotation": 5
    },
    {
      "x": 1,
      "y": 20,
      "z": 1,
      "name": "Plant_Leaves_Dry"
    },
    {
      "x": 1,
      "y": 13,
      "z": 2,
      "name": "Plant_Leaves_Dry"
    },
    {
      "x": 1,
      "y": 14,
      "z": 2,
      "name": "Plant_Leaves_Dry"
    },
    {
      "x": 1,
      "y": 20,
      "z": 2,
      "name": "Plant_Leaves_Dry"
    },
    {
      "x": 1,
      "y": 13,
      "z": 3,
      "name": "Plant_Leaves_Dry"
    },
    {
      "x": 1,
      "y": 20,
      "z": 3,
      "name": "Plant_Leaves_Dry"
    },
    {
      "x": 1,
      "y": 13,
      "z": 4,
      "name": "Plant_Leaves_Dry"
    },
    {
      "x": 1,
      "y": 13,
      "z": 5,
      "name": "Plant_Leaves_Dry"
    },
    {
      "x": 2,
      "y": 20,
      "z": -6,
      "name": "Plant_Leaves_Dry"
    },
    {
      "x": 2,
      "y": 20,
      "z": -5,
      "name": "Plant_Leaves_Dry"
    },
    {
      "x": 2,
      "y": 20,
      "z": -4,
      "name": "Plant_Leaves_Dry"
    },
    {
      "x": 2,
      "y": 10,
      "z": -3,
      "name": "Wood_Dry_Trunk_Full"
    },
    {
      "x": 2,
      "y": 20,
      "z": -3,
      "name": "Plant_Leaves_Dry"
    },
    {
      "x": 2,
      "y": 10,
      "z": -2,
      "name": "Wood_Dry_Trunk_Full"
    },
    {
      "x": 2,
      "y": 11,
      "z": -2,
      "name": "Wood_Dry_Trunk_Full"
    },
    {
      "x": 2,
      "y": 20,
      "z": -2,
      "name": "Plant_Leaves_Dry"
    },
    {
      "x": 2,
      "y": 11,
      "z": -1,
      "name": "Wood_Dry_Trunk_Full"
    },
    {
      "x": 2,
      "y": 20,
      "z": -1,
      "name": "Plant_Leaves_Dry"
    },
    {
      "x": 2,
      "y": 21,
      "z": -1,
      "name": "Plant_Leaves_Dry"
    },
    {
      "x": 2,
      "y": 14,
      "z": 0,
      "name": "Plant_Leaves_Dry"
    },
    {
      "x": 2,
      "y": 20,
      "z": 0,
      "name": "Plant_Leaves_Dry"
    },
    {
      "x": 2,
      "y": 13,
      "z": 1,
      "name": "Wood_Dry_Branch_Long",
      "rotation": 5
    },
    {
      "x": 2,
      "y": 14,
      "z": 1,
      "name": "Plant_Leaves_Dry"
    },
    {
      "x": 2,
      "y": 20,
      "z": 1,
      "name": "Plant_Leaves_Dry"
    },
    {
      "x": 2,
      "y": 14,
      "z": 2,
      "name": "Plant_Leaves_Dry"
    },
    {
      "x": 2,
      "y": 20,
      "z": 2,
      "name": "Plant_Leaves_Dry"
    },
    {
      "x": 2,
      "y": 13,
      "z": 4,
      "name": "Plant_Leaves_Dry"
    },
    {
      "x": 2,
      "y": 13,
      "z": 5,
      "name": "Plant_Leaves_Dry"
    },
    {
      "x": 2,
      "y": 13,
      "z": 6,
      "name": "Plant_Leaves_Dry"
    },
    {
      "x": 3,
      "y": 20,
      "z": -4,
      "name": "Plant_Leaves_Dry"
    },
    {
      "x": 3,
      "y": 20,
      "z": -3,
      "name": "Plant_Leaves_Dry"
    },
    {
      "x": 3,
      "y": 20,
      "z": -2,
      "name": "Plant_Leaves_Dry"
    },
    {
      "x": 3,
      "y": 11,
      "z": -1,
      "name": "Wood_Dry_Trunk_Full"
    },
    {
      "x": 3,
      "y": 12,
      "z": -1,
      "name": "Wood_Dry_Trunk_Full"
    },
    {
      "x": 3,
      "y": 20,
      "z": -1,
      "name": "Plant_Leaves_Dry"
    },
    {
      "x": 3,
      "y": 12,
      "z": 0,
      "name": "Wood_Dry_Trunk_Full"
    },
    {
      "x": 3,
      "y": 14,
      "z": 0,
      "name": "Plant_Leaves_Dry"
    },
    {
      "x": 3,
      "y": 20,
      "z": 0,
      "name": "Plant_Leaves_Dry"
    },
    {
      "x": 3,
      "y": 12,
      "z": 1,
      "name": "Wood_Dry_Trunk_Full"
    },
    {
      "x": 3,
      "y": 13,
      "z": 1,
      "name": "Wood_Dry_Trunk_Full"
    },
    {
      "x": 3,
      "y": 14,
      "z": 1,
      "name": "Plant_Leaves_Dry"
    },
    {
      "x": 3,
      "y": 13,
      "z": 2,
      "name": "Wood_Dry_Branch_Long",
      "rotation": 4
    },
    {
      "x": 3,
      "y": 14,
      "z": 2,
      "name": "Plant_Leaves_Dry"
    },
    {
      "x": 3,
      "y": 13,
      "z": 3,
      "name": "Wood_Dry_Branch_Long",
      "rotation": 4
    },
    {
      "x": 3,
      "y": 14,
      "z": 3,
      "name": "Plant_Leaves_Dry"
    },
    {
      "x": 3,
      "y": 13,
      "z": 4,
      "name": "Plant_Leaves_Dry"
    },
    {
      "x": 3,
      "y": 13,
      "z": 5,
      "name": "Plant_Leaves_Dry"
    },
    {
      "x": 3,
      "y": 13,
      "z": 6,
      "name": "Plant_Leaves_Dry"
    },
    {
      "x": 4,
      "y": 20,
      "z": -2,
      "name": "Plant_Leaves_Dry"
    },
    {
      "x": 4,
      "y": 13,
      "z": 1,
      "name": "Wood_Dry_Branch_Long",
      "rotation": 5
    },
    {
      "x": 4,
      "y": 14,
      "z": 1,
      "name": "Plant_Leaves_Dry"
    },
    {
      "x": 4,
      "y": 14,
      "z": 2,
      "name": "Plant_Leaves_Dry"
    },
    {
      "x": 4,
      "y": 14,
      "z": 3,
      "name": "Plant_Leaves_Dry"
    },
    {
      "x": 4,
      "y": 13,
      "z": 4,
      "name": "Plant_Leaves_Dry"
    },
    {
      "x": 4,
      "y": 14,
      "z": 4,
      "name": "Plant_Leaves_Dry"
    },
    {
      "x": 4,
      "y": 13,
      "z": 5,
      "name": "Plant_Leaves_Dry"
    },
    {
      "x": 4,
      "y": 13,
      "z": 6,
      "name": "Plant_Leaves_Dry"
    },
    {
      "x": 5,
      "y": 13,
      "z": -2,
      "name": "Plant_Leaves_Dry"
    },
    {
      "x": 5,
      "y": 14,
      "z": 0,
      "name": "Plant_Leaves_Dry"
    },
    {
      "x": 5,
      "y": 13,
      "z": 1,
      "name": "Wood_Dry_Branch_Long",
      "rotation": 5
    },
    {
      "x": 5,
      "y": 14,
      "z": 1,
      "name": "Plant_Leaves_Dry"
    },
    {
      "x": 5,
      "y": 14,
      "z": 2,
      "name": "Plant_Leaves_Dry"
    },
    {
      "x": 5,
      "y": 14,
      "z": 3,
      "name": "Plant_Leaves_Dry"
    },
    {
      "x": 5,
      "y": 13,
      "z": 4,
      "name": "Plant_Leaves_Dry"
    },
    {
      "x": 5,
      "y": 13,
      "z": 5,
      "name": "Plant_Leaves_Dry"
    },
    {
      "x": 6,
      "y": 13,
      "z": -2,
      "name": "Plant_Leaves_Dry"
    },
    {
      "x": 6,
      "y": 13,
      "z": -1,
      "name": "Plant_Leaves_Dry"
    },
    {
      "x": 6,
      "y": 13,
      "z": 0,
      "name": "Plant_Leaves_Dry"
    },
    {
      "x": 6,
      "y": 13,
      "z": 1,
      "name": "Plant_Leaves_Dry"
    },
    {
      "x": 6,
      "y": 13,
      "z": 2,
      "name": "Plant_Leaves_Dry"
    },
    {
      "x": 6,
      "y": 13,
      "z": 3,
      "name": "Plant_Leaves_Dry"
    },
    {
      "x": 6,
      "y": 13,
      "z": 4,
      "name": "Plant_Leaves_Dry"
    },
    {
      "x": 6,
      "y": 13,
      "z": 5,
      "name": "Plant_Leaves_Dry"
    },
    {
      "x": 7,
      "y": 13,
      "z": -1,
      "name": "Plant_Leaves_Dry"
    },
    {
      "x": 7,
      "y": 13,
      "z": 0,
      "name": "Plant_Leaves_Dry"
    },
    {
      "x": 7,
      "y": 13,
      "z": 1,
      "name": "Plant_Leaves_Dry"
    },
    {
      "x": 7,
      "y": 13,
      "z": 2,
      "name": "Plant_Leaves_Dry"
    },
    {
      "x": 7,
      "y": 13,
      "z": 3,
      "name": "Plant_Leaves_Dry"
    },
    {
      "x": 7,
      "y": 13,
      "z": 4,
      "name": "Plant_Leaves_Dry"
    },
    {
      "x": 8,
      "y": 13,
      "z": 1,
      "name": "Plant_Leaves_Dry"
    },
    {
      "x": 8,
      "y": 13,
      "z": 2,
      "name": "Plant_Leaves_Dry"
    }
  ]
}