{
  "version": 8,
  "blockIdVersion": 8,
  "anchorX": 2,
  "anchorY": 10,
  "anchorZ": 4,
  "blocks": [
    {
      "x": -12,
      "y": 11,
      "z": -9,
      "name": "Plant_Roots_Cave_Small",
      "rotation": 8
    },
    {
      "x": -12,
      "y": 12,
      "z": -9,
      "name": "Soil_Dirt"
    },
    {
      "x": -12,
      "y": 13,
      "z": -9,
      "name": "Soil_Grass"
    },
    {
      "x": -12,
      "y": 10,
      "z": -8,
      "name": "Rock_Stone"
    },
    {
      "x": -12,
      "y": 11,
      "z": -8,
      "name": "Rock_Stone_Mossy"
    },
    {
      "x": -12,
      "y": 12,
      "z": -8,
      "name": "Rock_Stone_Mossy"
    },
    {
      "x": -12,
      "y": 13,
      "z": -8,
      "name": "Soil_Dirt"
    },
    {
      "x": -12,
      "y": 14,
      "z": -8,
      "name": "Soil_Grass"
    },
    {
      "x": -12,
      "y": 9,
      "z": -7,
      "name": "Rock_Stone"
    },
    {
      "x": -12,
      "y": 10,
      "z": -7,
      "name": "Rock_Stone_Mossy"
    },
    {
      "x": -12,
      "y": 11,
      "z": -7,
      "name": "Rock_Stone_Mossy"
    },
    {
      "x": -12,
      "y": 12,
      "z": -7,
      "name": "Rock_Stone_Mossy"
    },
    {
      "x": -12,
      "y": 13,
      "z": -7,
      "name": "Soil_Dirt"
    },
    {
      "x": -12,
      "y": 14,
      "z": -7,
      "name": "Soil_Grass"
    },
    {
      "x": -12,
      "y": 8,
      "z": -6,
      "name": "Rock_Stone"
    },
    {
      "x": -12,
      "y": 9,
      "z": -6,
      "name": "Rock_Stone"
    },
    {
      "x": -12,
      "y": 10,
      "z": -6,
      "name": "Rock_Stone"
    },
    {
      "x": -12,
      "y": 11,
      "z": -6,
      "name": "Rock_Stone_Mossy"
    },
    {
      "x": -12,
      "y": 12,
      "z": -6,
      "name": "Rock_Stone"
    },
    {
      "x": -12,
      "y": 13,
      "z": -6,
      "name": "Soil_Dirt"
    },
    {
      "x": -12,
      "y": 14,
      "z": -6,
      "name": "Soil_Grass"
    },
    {
      "x": -12,
      "y": 9,
      "z": -5,
      "name": "Rock_Stone"
    },
    {
      "x": -12,
      "y": 10,
      "z": -5,
      "name": "Rock_Stone"
    },
    {
      "x": -12,
      "y": 11,
      "z": -5,
      "name": "Rock_Stone"
    },
    {
      "x": -12,
      "y": 12,
      "z": -5,
      "name": "Rock_Stone"
    },
    {
      "x": -12,
      "y": 13,
      "z": -5,
      "name": "Soil_Dirt"
    },
    {
      "x": -12,
      "y": 14,
      "z": -5,
      "name": "Soil_Grass"
    },
    {
      "x": -12,
      "y": 11,
      "z": -4,
      "name": "Rock_Stone"
    },
    {
      "x": -12,
      "y": 12,
      "z": -4,
      "name": "Rock_Stone"
    },
    {
      "x": -12,
      "y": 13,
      "z": -4,
      "name": "Soil_Dirt"
    },
    {
      "x": -12,
      "y": 14,
      "z": -4,
      "name": "Soil_Grass"
    },
    {
      "x": -12,
      "y": 11,
      "z": -3,
      "name": "Plant_Roots_Cave_Small",
      "rotation": 8
    },
    {
      "x": -12,
      "y": 12,
      "z": -3,
      "name": "Soil_Dirt"
    },
    {
      "x": -12,
      "y": 13,
      "z": -3,
      "name": "Soil_Grass"
    },
    {
      "x": -12,
      "y": 14,
      "z": -3,
      "name": "Plant_Moss_Rug_Green"
    },
    {
      "x": -11,
      "y": 28,
      "z": -16,
      "name": "Plant_Leaves_Oak"
    },
    {
      "x": -11,
      "y": 27,
      "z": -15,
      "name": "Plant_Leaves_Oak"
    },
    {
      "x": -11,
      "y": 28,
      "z": -15,
      "name": "Plant_Leaves_Oak"
    },
    {
      "x": -11,
      "y": 29,
      "z": -15,
      "name": "Plant_Leaves_Oak"
    },
    {
      "x": -11,
      "y": 27,
      "z": -14,
      "name": "Plant_Leaves_Oak"
    },
    {
      "x": -11,
      "y": 28,
      "z": -14,
      "name": "Plant_Leaves_Oak"
    },
    {
      "x": -11,
      "y": 29,
      "z": -14,
      "name": "Plant_Leaves_Oak"
    },
    {
      "x": -11,
      "y": 30,
      "z": -14,
      "name": "Plant_Leaves_Oak"
    },
    {
      "x": -11,
      "y": 28,
      "z": -13,
      "name": "Plant_Leaves_Oak"
    },
    {
      "x": -11,
      "y": 29,
      "z": -13,
      "name": "Plant_Leaves_Oak"
    },
    {
      "x": -11,
      "y": 10,
      "z": -11,
      "name": "Rock_Stone"
    },
    {
      "x": -11,
      "y": 11,
      "z": -11,
      "name": "Rock_Stone"
    },
    {
      "x": -11,
      "y": 9,
      "z": -10,
      "name": "Rock_Stone"
    },
    {
      "x": -11,
      "y": 10,
      "z": -10,
      "name": "Rock_Stone"
    },
    {
      "x": -11,
      "y": 11,
      "z": -10,
      "name": "Rock_Stone"
    },
    {
      "x": -11,
      "y": 12,
      "z": -10,
      "name": "Rock_Stone"
    },
    {
      "x": -11,
      "y": 13,
      "z": -10,
      "name": "Soil_Dirt"
    },
    {
      "x": -11,
      "y": 14,
      "z": -10,
      "name": "Soil_Grass"
    },
    {
      "x": -11,
      "y": 8,
      "z": -9,
      "name": "Rock_Stone"
    },
    {
      "x": -11,
      "y": 9,
      "z": -9,
      "name": "Rock_Stone"
    },
    {
      "x": -11,
      "y": 10,
      "z": -9,
      "name": "Rock_Stone"
    },
    {
      "x": -11,
      "y": 11,
      "z": -9,
      "name": "Rock_Stone"
    },
    {
      "x": -11,
      "y": 12,
      "z": -9,
      "name": "Rock_Stone"
    },
    {
      "x": -11,
      "y": 13,
      "z": -9,
      "name": "Soil_Dirt"
    },
    {
      "x": -11,
      "y": 14,
      "z": -9,
      "name": "Soil_Grass"
    },
    {
      "x": -11,
      "y": 8,
      "z": -8,
      "name": "Rock_Stone"
    },
    {
      "x": -11,
      "y": 9,
      "z": -8,
      "name": "Rock_Stone"
    },
    {
      "x": -11,
      "y": 10,
      "z": -8,
      "name": "Rock_Stone"
    },
    {
      "x": -11,
      "y": 11,
      "z": -8,
      "name": "Rock_Stone"
    },
    {
      "x": -11,
      "y": 12,
      "z": -8,
      "name": "Rock_Stone_Mossy"
    },
    {
      "x": -11,
      "y": 13,
      "z": -8,
      "name": "Soil_Dirt"
    },
    {
      "x": -11,
      "y": 14,
      "z": -8,
      "name": "Soil_Grass"
    },
    {
      "x": -11,
      "y": 8,
      "z": -7,
      "name": "Rock_Stone"
    },
    {
      "x": -11,
      "y": 9,
      "z": -7,
      "name": "Rock_Stone"
    },
    {
      "x": -11,
      "y": 10,
      "z": -7,
      "name": "Rock_Stone"
    },
    {
      "x": -11,
      "y": 11,
      "z": -7,
      "name": "Rock_Stone_Mossy"
    },
    {
      "x": -11,
      "y": 12,
      "z": -7,
      "name": "Rock_Stone"
    },
    {
      "x": -11,
      "y": 13,
      "z": -7,
      "name": "Rock_Stone"
    },
    {
      "x": -11,
      "y": 14,
      "z": -7,
      "name": "Soil_Dirt"
    },
    {
      "x": -11,
      "y": 15,
      "z": -7,
      "name": "Soil_Grass"
    },
    {
      "x": -11,
      "y": 8,
      "z": -6,
      "name": "Rock_Stone"
    },
    {
      "x": -11,
      "y": 9,
      "z": -6,
      "name": "Rock_Stone"
    },
    {
      "x": -11,
      "y": 10,
      "z": -6,
      "name": "Rock_Stone"
    },
    {
      "x": -11,
      "y": 11,
      "z": -6,
      "name": "Rock_Stone"
    },
    {
      "x": -11,
      "y": 12,
      "z": -6,
      "name": "Rock_Stone"
    },
    {
      "x": -11,
      "y": 13,
      "z": -6,
      "name": "Rock_Stone"
    },
    {
      "x": -11,
      "y": 14,
      "z": -6,
      "name": "Soil_Dirt"
    },
    {
      "x": -11,
      "y": 15,
      "z": -6,
      "name": "Soil_Grass"
    },
    {
      "x": -11,
      "y": 8,
      "z": -5,
      "name": "Rock_Stone"
    },
    {
      "x": -11,
      "y": 9,
      "z": -5,
      "name": "Rock_Stone"
    },
    {
      "x": -11,
      "y": 10,
      "z": -5,
      "name": "Rock_Stone"
    },
    {
      "x": -11,
      "y": 11,
      "z": -5,
      "name": "Rock_Stone"
    },
    {
      "x": -11,
      "y": 12,
      "z": -5,
      "name": "Rock_Stone"
    },
    {
      "x": -11,
      "y": 13,
      "z": -5,
      "name": "Rock_Stone"
    },
    {
      "x": -11,
      "y": 14,
      "z": -5,
      "name": "Soil_Dirt"
    },
    {
      "x": -11,
      "y": 15,
      "z": -5,
      "name": "Soil_Grass"
    },
    {
      "x": -11,
      "y": 7,
      "z": -4,
      "name": "Rock_Stone"
    },
    {
      "x": -11,
      "y": 8,
      "z": -4,
      "name": "Rock_Stone"
    },
    {
      "x": -11,
      "y": 9,
      "z": -4,
      "name": "Rock_Stone"
    },
    {
      "x": -11,
      "y": 10,
      "z": -4,
      "name": "Rock_Stone"
    },
    {
      "x": -11,
      "y": 11,
      "z": -4,
      "name": "Rock_Stone"
    },
    {
      "x": -11,
      "y": 12,
      "z": -4,
      "name": "Rock_Stone"
    },
    {
      "x": -11,
      "y": 13,
      "z": -4,
      "name": "Soil_Dirt"
    },
    {
      "x": -11,
      "y": 14,
      "z": -4,
      "name": "Soil_Grass"
    },
    {
      "x": -11,
      "y": 10,
      "z": -3,
      "name": "Rock_Stone"
    },
    {
      "x": -11,
      "y": 11,
      "z": -3,
      "name": "Rock_Stone"
    },
    {
      "x": -11,
      "y": 12,
      "z": -3,
      "name": "Rock_Stone"
    },
    {
      "x": -11,
      "y": 13,
      "z": -3,
      "name": "Soil_Dirt"
    },
    {
      "x": -11,
      "y": 14,
      "z": -3,
      "name": "Soil_Grass"
    },
    {
      "x": -11,
      "y": 15,
      "z": -3,
      "name": "Plant_Moss_Rug_Green"
    },
    {
      "x": -11,
      "y": 11,
      "z": -2,
      "name": "Plant_Roots_Cave_Small",
      "rotation": 8
    },
    {
      "x": -11,
      "y": 12,
      "z": -2,
      "name": "Soil_Dirt"
    },
    {
      "x": -11,
      "y": 13,
      "z": -2,
      "name": "Soil_Grass"
    },
    {
      "x": -11,
      "y": 14,
      "z": -2,
      "name": "Plant_Moss_Rug_Green"
    },
    {
      "x": -11,
      "y": 13,
      "z": -1,
      "name": "Plant_Moss_Wall_Green"
    },
    {
      "x": -11,
      "y": 12,
      "z": 8,
      "name": "Plant_Moss_Wall_Green",
      "rotation": 3
    },
    {
      "x": -10,
      "y": 28,
      "z": -17,
      "name": "Plant_Leaves_Oak"
    },
    {
      "x": -10,
      "y": 29,
      "z": -17,
      "name": "Plant_Leaves_Oak"
    },
    {
      "x": -10,
      "y": 30,
      "z": -17,
      "name": "Plant_Leaves_Oak"
    },
    {
      "x": -10,
      "y": 27,
      "z": -16,
      "name": "Plant_Leaves_Oak"
    },
    {
      "x": -10,
      "y": 28,
      "z": -16,
      "name": "Plant_Leaves_Oak"
    },
    {
      "x": -10,
      "y": 29,
      "z": -16,
      "name": "Plant_Leaves_Oak"
    },
    {
      "x": -10,
      "y": 30,
      "z": -16,
      "name": "Plant_Leaves_Oak"
    },
    {
      "x": -10,
      "y": 27,
      "z": -15,
      "name": "Plant_Leaves_Oak"
    },
    {
      "x": -10,
      "y": 28,
      "z": -15,
      "name": "Plant_Leaves_Oak"
    },
    {
      "x": -10,
      "y": 29,
      "z": -15,
      "name": "Plant_Leaves_Oak"
    },
    {
      "x": -10,
      "y": 30,
      "z": -15,
      "name": "Plant_Leaves_Oak"
    },
    {
      "x": -10,
      "y": 30,
      "z": -14,
      "name": "Plant_Leaves_Oak"
    },
    {
      "x": -10,
      "y": 27,
      "z": -13,
      "name": "Plant_Leaves_Oak"
    },
    {
      "x": -10,
      "y": 28,
      "z": -13,
      "name": "Wood_Oak_Branch_Long",
      "rotation": 5
    },
    {
      "x": -10,
      "y": 29,
      "z": -13,
      "name": "Plant_Leaves_Oak"
    },
    {
      "x": -10,
      "y": 30,
      "z": -13,
      "name": "Plant_Leaves_Oak"
    },
    {
      "x": -10,
      "y": 28,
      "z": -12,
      "name": "Plant_Leaves_Oak"
    },
    {
      "x": -10,
      "y": 9,
      "z": -11,
      "name": "Rock_Stone"
    },
    {
      "x": -10,
      "y": 10,
      "z": -11,
      "name": "Rock_Stone"
    },
    {
      "x": -10,
      "y": 11,
      "z": -11,
      "name": "Rock_Stone"
    },
    {
      "x": -10,
      "y": 12,
      "z": -11,
      "name": "Soil_Dirt"
    },
    {
      "x": -10,
      "y": 13,
      "z": -11,
      "name": "Soil_Grass"
    },
    {
      "x": -10,
      "y": 14,
      "z": -11,
      "name": "Plant_Grass_Sharp"
    },
    {
      "x": -10,
      "y": 30,
      "z": -11,
      "name": "Plant_Leaves_Oak"
    },
    {
      "x": -10,
      "y": 8,
      "z": -10,
      "name": "Rock_Stone"
    },
    {
      "x": -10,
      "y": 9,
      "z": -10,
      "name": "Rock_Stone"
    },
    {
      "x": -10,
      "y": 10,
      "z": -10,
      "name": "Rock_Stone"
    },
    {
      "x": -10,
      "y": 11,
      "z": -10,
      "name": "Rock_Stone"
    },
    {
      "x": -10,
      "y": 12,
      "z": -10,
      "name": "Rock_Stone"
    },
    {
      "x": -10,
      "y": 13,
      "z": -10,
      "name": "Soil_Dirt"
    },
    {
      "x": -10,
      "y": 14,
      "z": -10,
      "name": "Soil_Grass"
    },
    {
      "x": -10,
      "y": 29,
      "z": -10,
      "name": "Plant_Leaves_Oak"
    },
    {
      "x": -10,
      "y": 33,
      "z": -10,
      "name": "Plant_Leaves_Oak"
    },
    {
      "x": -10,
      "y": 8,
      "z": -9,
      "name": "Rock_Stone"
    },
    {
      "x": -10,
      "y": 9,
      "z": -9,
      "name": "Rock_Stone"
    },
    {
      "x": -10,
      "y": 10,
      "z": -9,
      "name": "Rock_Stone"
    },
    {
      "x": -10,
      "y": 11,
      "z": -9,
      "name": "Rock_Stone"
    },
    {
      "x": -10,
      "y": 12,
      "z": -9,
      "name": "Rock_Stone"
    },
    {
      "x": -10,
      "y": 13,
      "z": -9,
      "name": "Rock_Stone"
    },
    {
      "x": -10,
      "y": 14,
      "z": -9,
      "name": "Soil_Dirt"
    },
    {
      "x": -10,
      "y": 15,
      "z": -9,
      "name": "Soil_Grass"
    },
    {
      "x": -10,
      "y": 32,
      "z": -9,
      "name": "Plant_Leaves_Oak"
    },
    {
      "x": -10,
      "y": 33,
      "z": -9,
      "name": "Plant_Leaves_Oak"
    },
    {
      "x": -10,
      "y": 8,
      "z": -8,
      "name": "Rock_Stone"
    },
    {
      "x": -10,
      "y": 9,
      "z": -8,
      "name": "Rock_Stone"
    },
    {
      "x": -10,
      "y": 10,
      "z": -8,
      "name": "Rock_Stone"
    },
    {
      "x": -10,
      "y": 11,
      "z": -8,
      "name": "Rock_Stone"
    },
    {
      "x": -10,
      "y": 12,
      "z": -8,
      "name": "Rock_Stone"
    },
    {
      "x": -10,
      "y": 13,
      "z": -8,
      "name": "Rock_Stone"
    },
    {
      "x": -10,
      "y": 14,
      "z": -8,
      "name": "Soil_Dirt"
    },
    {
      "x": -10,
      "y": 15,
      "z": -8,
      "name": "Soil_Grass"
    },
    {
      "x": -10,
      "y": 16,
      "z": -8,
      "name": "Plant_Grass_Sharp"
    },
    {
      "x": -10,
      "y": 7,
      "z": -7,
      "name": "Rock_Stone"
    },
    {
      "x": -10,
      "y": 8,
      "z": -7,
      "name": "Rock_Stone"
    },
    {
      "x": -10,
      "y": 9,
      "z": -7,
      "name": "Rock_Stone"
    },
    {
      "x": -10,
      "y": 10,
      "z": -7,
      "name": "Rock_Stone"
    },
    {
      "x": -10,
      "y": 11,
      "z": -7,
      "name": "Rock_Stone"
    },
    {
      "x": -10,
      "y": 12,
      "z": -7,
      "name": "Rock_Stone"
    },
    {
      "x": -10,
      "y": 13,
      "z": -7,
      "name": "Rock_Stone"
    },
    {
      "x": -10,
      "y": 14,
      "z": -7,
      "name": "Soil_Dirt"
    },
    {
      "x": -10,
      "y": 15,
      "z": -7,
      "name": "Soil_Grass"
    },
    {
      "x": -10,
      "y": 7,
      "z": -6,
      "name": "Rock_Stone"
    },
    {
      "x": -10,
      "y": 8,
      "z": -6,
      "name": "Rock_Stone"
    },
    {
      "x": -10,
      "y": 9,
      "z": -6,
      "name": "Rock_Stone"
    },
    {
      "x": -10,
      "y": 10,
      "z": -6,
      "name": "Rock_Stone"
    },
    {
      "x": -10,
      "y": 11,
      "z": -6,
      "name": "Rock_Stone"
    },
    {
      "x": -10,
      "y": 12,
      "z": -6,
      "name": "Rock_Stone"
    },
    {
      "x": -10,
      "y": 13,
      "z": -6,
      "name": "Rock_Stone"
    },
    {
      "x": -10,
      "y": 14,
      "z": -6,
      "name": "Soil_Dirt"
    },
    {
      "x": -10,
      "y": 15,
      "z": -6,
      "name": "Soil_Grass"
    },
    {
      "x": -10,
      "y": 7,
      "z": -5,
      "name": "Rock_Stone"
    },
    {
      "x": -10,
      "y": 8,
      "z": -5,
      "name": "Rock_Stone"
    },
    {
      "x": -10,
      "y": 9,
      "z": -5,
      "name": "Rock_Stone"
    },
    {
      "x": -10,
      "y": 10,
      "z": -5,
      "name": "Rock_Stone"
    },
    {
      "x": -10,
      "y": 11,
      "z": -5,
      "name": "Rock_Stone"
    },
    {
      "x": -10,
      "y": 12,
      "z": -5,
      "name": "Rock_Stone"
    },
    {
      "x": -10,
      "y": 13,
      "z": -5,
      "name": "Rock_Stone"
    },
    {
      "x": -10,
      "y": 14,
      "z": -5,
      "name": "Soil_Dirt"
    },
    {
      "x": -10,
      "y": 15,
      "z": -5,
      "name": "Soil_Grass"
    },
    {
      "x": -10,
      "y": 7,
      "z": -4,
      "name": "Rock_Stone"
    },
    {
      "x": -10,
      "y": 8,
      "z": -4,
      "name": "Rock_Stone"
    },
    {
      "x": -10,
      "y": 9,
      "z": -4,
      "name": "Rock_Stone"
    },
    {
      "x": -10,
      "y": 10,
      "z": -4,
      "name": "Rock_Stone"
    },
    {
      "x": -10,
      "y": 11,
      "z": -4,
      "name": "Rock_Stone"
    },
    {
      "x": -10,
      "y": 12,
      "z": -4,
      "name": "Rock_Stone"
    },
    {
      "x": -10,
      "y": 13,
      "z": -4,
      "name": "Rock_Stone"
    },
    {
      "x": -10,
      "y": 14,
      "z": -4,
      "name": "Soil_Dirt"
    },
    {
      "x": -10,
      "y": 15,
      "z": -4,
      "name": "Soil_Grass"
    },
    {
      "x": -10,
      "y": 18,
      "z": -4,
      "name": "Plant_Moss_Wall_Green",
      "rotation": 3
    },
    {
      "x": -10,
      "y": 7,
      "z": -3,
      "name": "Rock_Stone"
    },
    {
      "x": -10,
      "y": 8,
      "z": -3,
      "name": "Rock_Stone"
    },
    {
      "x": -10,
      "y": 9,
      "z": -3,
      "name": "Rock_Stone"
    },
    {
      "x": -10,
      "y": 10,
      "z": -3,
      "name": "Rock_Stone"
    },
    {
      "x": -10,
      "y": 11,
      "z": -3,
      "name": "Rock_Stone"
    },
    {
      "x": -10,
      "y": 12,
      "z": -3,
      "name": "Rock_Stone"
    },
    {
      "x": -10,
      "y": 13,
      "z": -3,
      "name": "Rock_Stone"
    },
    {
      "x": -10,
      "y": 14,
      "z": -3,
      "name": "Soil_Dirt"
    },
    {
      "x": -10,
      "y": 15,
      "z": -3,
      "name": "Soil_Grass"
    },
    {
      "x": -10,
      "y": 17,
      "z": -3,
      "name": "Plant_Moss_Wall_Green",
      "rotation": 3
    },
    {
      "x": -10,
      "y": 18,
      "z": -3,
      "name": "Plant_Moss_Wall_Green",
      "rotation": 3
    },
    {
      "x": -10,
      "y": 19,
      "z": -3,
      "name": "Plant_Moss_Wall_Green",
      "rotation": 3
    },
    {
      "x": -10,
      "y": 9,
      "z": -2,
      "name": "Rock_Stone"
    },
    {
      "x": -10,
      "y": 10,
      "z": -2,
      "name": "Rock_Stone"
    },
    {
      "x": -10,
      "y": 11,
      "z": -2,
      "name": "Rock_Stone"
    },
    {
      "x": -10,
      "y": 12,
      "z": -2,
      "name": "Rock_Stone"
    },
    {
      "x": -10,
      "y": 13,
      "z": -2,
      "name": "Soil_Dirt"
    },
    {
      "x": -10,
      "y": 14,
      "z": -2,
      "name": "Soil_Grass"
    },
    {
      "x": -10,
      "y": 15,
      "z": -2,
      "name": "Plant_Moss_Rug_Green"
    },
    {
      "x": -10,
      "y": 18,
      "z": -2,
      "name": "Rock_Stone"
    },
    {
      "x": -10,
      "y": 19,
      "z": -2,
      "name": "Rock_Stone"
    },
    {
      "x": -10,
      "y": 20,
      "z": -2,
      "name": "Rock_Stone"
    },
    {
      "x": -10,
      "y": 21,
      "z": -2,
      "name": "Rock_Stone"
    },
    {
      "x": -10,
      "y": 11,
      "z": -1,
      "name": "Plant_Moss_Wall_Green"
    },
    {
      "x": -10,
      "y": 12,
      "z": -1,
      "name": "Plant_Moss_Wall_Green"
    },
    {
      "x": -10,
      "y": 13,
      "z": -1,
      "name": "Plant_Moss_Wall_Green"
    },
    {
      "x": -10,
      "y": 17,
      "z": -1,
      "name": "Rock_Stone"
    },
    {
      "x": -10,
      "y": 18,
      "z": -1,
      "name": "Rock_Stone"
    },
    {
      "x": -10,
      "y": 19,
      "z": -1,
      "name": "Rock_Stone"
    },
    {
      "x": -10,
      "y": 20,
      "z": -1,
      "name": "Rock_Stone"
    },
    {
      "x": -10,
      "y": 21,
      "z": -1,
      "name": "Rock_Stone"
    },
    {
      "x": -10,
      "y": 18,
      "z": 0,
      "name": "Rock_Stone"
    },
    {
      "x": -10,
      "y": 19,
      "z": 0,
      "name": "Rock_Stone"
    },
    {
      "x": -10,
      "y": 20,
      "z": 0,
      "name": "Rock_Stone"
    },
    {
      "x": -10,
      "y": 21,
      "z": 0,
      "name": "Rock_Stone"
    },
    {
      "x": -10,
      "y": 20,
      "z": 1,
      "name": "Rock_Stone"
    },
    {
      "x": -10,
      "y": 21,
      "z": 1,
      "name": "Rock_Stone"
    },
    {
      "x": -10,
      "y": 12,
      "z": 7,
      "name": "Plant_Moss_Wall_Green",
      "rotation": 2
    },
    {
      "x": -10,
      "y": 13,
      "z": 7,
      "name": "Plant_Moss_Wall_Green",
      "rotation": 3
    },
    {
      "x": -10,
      "y": 9,
      "z": 8,
      "name": "Rock_Stone"
    },
    {
      "x": -10,
      "y": 10,
      "z": 8,
      "name": "Rock_Stone"
    },
    {
      "x": -10,
      "y": 11,
      "z": 8,
      "name": "Rock_Stone"
    },
    {
      "x": -10,
      "y": 12,
      "z": 8,
      "name": "Rock_Stone"
    },
    {
      "x": -10,
      "y": 13,
      "z": 8,
      "name": "Plant_Moss_Rug_Green"
    },
    {
      "x": -10,
      "y": 7,
      "z": 9,
      "name": "Rock_Stone"
    },
    {
      "x": -10,
      "y": 8,
      "z": 9,
      "name": "Rock_Stone"
    },
    {
      "x": -10,
      "y": 9,
      "z": 9,
      "name": "Rock_Stone"
    },
    {
      "x": -10,
      "y": 10,
      "z": 9,
      "name": "Rock_Stone"
    },
    {
      "x": -10,
      "y": 11,
      "z": 9,
      "name": "Rock_Stone"
    },
    {
      "x": -10,
      "y": 12,
      "z": 9,
      "name": "Plant_Moss_Wall_Green"
    },
    {
      "x": -10,
      "y": 9,
      "z": 10,
      "name": "Rock_Stone"
    },
    {
      "x": -10,
      "y": 10,
      "z": 10,
      "name": "Rock_Stone"
    },
    {
      "x": -9,
      "y": 28,
      "z": -18,
      "name": "Plant_Leaves_Oak"
    },
    {
      "x": -9,
      "y": 29,
      "z": -18,
      "name": "Plant_Leaves_Oak"
    },
    {
      "x": -9,
      "y": 27,
      "z": -17,
      "name": "Plant_Leaves_Oak"
    },
    {
      "x": -9,
      "y": 28,
      "z": -17,
      "name": "Plant_Leaves_Oak"
    },
    {
      "x": -9,
      "y": 29,
      "z": -17,
      "name": "Plant_Leaves_Oak"
    },
    {
      "x": -9,
      "y": 30,
      "z": -17,
      "name": "Plant_Leaves_Oak"
    },
    {
      "x": -9,
      "y": 27,
      "z": -16,
      "name": "Plant_Leaves_Oak"
    },
    {
      "x": -9,
      "y": 28,
      "z": -16,
      "name": "Plant_Leaves_Oak"
    },
    {
      "x": -9,
      "y": 29,
      "z": -16,
      "name": "Plant_Leaves_Oak"
    },
    {
      "x": -9,
      "y": 30,
      "z": -16,
      "name": "Plant_Leaves_Oak"
    },
    {
      "x": -9,
      "y": 31,
      "z": -16,
      "name": "Plant_Leaves_Oak"
    },
    {
      "x": -9,
      "y": 32,
      "z": -16,
      "name": "Plant_Leaves_Oak"
    },
    {
      "x": -9,
      "y": 30,
      "z": -15,
      "name": "Plant_Leaves_Oak"
    },
    {
      "x": -9,
      "y": 31,
      "z": -15,
      "name": "Plant_Leaves_Oak"
    },
    {
      "x": -9,
      "y": 32,
      "z": -15,
      "name": "Plant_Leaves_Oak"
    },
    {
      "x": -9,
      "y": 31,
      "z": -14,
      "name": "Plant_Leaves_Oak"
    },
    {
      "x": -9,
      "y": 28,
      "z": -13,
      "name": "Wood_Oak_Trunk_Full"
    },
    {
      "x": -9,
      "y": 32,
      "z": -13,
      "name": "Plant_Leaves_Oak"
    },
    {
      "x": -9,
      "y": 30,
      "z": -12,
      "name": "Plant_Leaves_Oak"
    },
    {
      "x": -9,
      "y": 11,
      "z": -11,
      "name": "Empty"
    },
    {
      "x": -9,
      "y": 12,
      "z": -11,
      "name": "Rock_Stone_Mossy"
    },
    {
      "x": -9,
      "y": 13,
      "z": -11,
      "name": "Soil_Dirt"
    },
    {
      "x": -9,
      "y": 14,
      "z": -11,
      "name": "Soil_Grass"
    },
    {
      "x": -9,
      "y": 29,
      "z": -11,
      "name": "Plant_Leaves_Oak"
    },
    {
      "x": -9,
      "y": 30,
      "z": -11,
      "name": "Plant_Leaves_Oak"
    },
    {
      "x": -9,
      "y": 31,
      "z": -11,
      "name": "Plant_Leaves_Oak"
    },
    {
      "x": -9,
      "y": 33,
      "z": -11,
      "name": "Plant_Leaves_Oak"
    },
    {
      "x": -9,
      "y": 34,
      "z": -11,
      "name": "Plant_Leaves_Oak"
    },
    {
      "x": -9,
      "y": 10,
      "z": -10,
      "name": "Rock_Stone"
    },
    {
      "x": -9,
      "y": 11,
      "z": -10,
      "name": "Rock_Stone"
    },
    {
      "x": -9,
      "y": 12,
      "z": -10,
      "name": "Rock_Stone_Mossy"
    },
    {
      "x": -9,
      "y": 13,
      "z": -10,
      "name": "Soil_Dirt"
    },
    {
      "x": -9,
      "y": 14,
      "z": -10,
      "name": "Soil_Grass"
    },
    {
      "x": -9,
      "y": 29,
      "z": -10,
      "name": "Plant_Leaves_Oak"
    },
    {
      "x": -9,
      "y": 30,
      "z": -10,
      "name": "Wood_Oak_Branch_Long",
      "rotation": 5
    },
    {
      "x": -9,
      "y": 31,
      "z": -10,
      "name": "Plant_Leaves_Oak"
    },
    {
      "x": -9,
      "y": 33,
      "z": -10,
      "name": "Plant_Leaves_Oak"
    },
    {
      "x": -9,
      "y": 34,
      "z": -10,
      "name": "Plant_Leaves_Oak"
    },
    {
      "x": -9,
      "y": 7,
      "z": -9,
      "name": "Rock_Stone"
    },
    {
      "x": -9,
      "y": 9,
      "z": -9,
      "name": "Rock_Stone"
    },
    {
      "x": -9,
      "y": 10,
      "z": -9,
      "name": "Rock_Stone"
    },
    {
      "x": -9,
      "y": 11,
      "z": -9,
      "name": "Rock_Stone"
    },
    {
      "x": -9,
      "y": 12,
      "z": -9,
      "name": "Rock_Stone"
    },
    {
      "x": -9,
      "y": 13,
      "z": -9,
      "name": "Rock_Stone"
    },
    {
      "x": -9,
      "y": 14,
      "z": -9,
      "name": "Soil_Dirt"
    },
    {
      "x": -9,
      "y": 15,
      "z": -9,
      "name": "Soil_Grass"
    },
    {
      "x": -9,
      "y": 16,
      "z": -9,
      "name": "Plant_Grass_Sharp"
    },
    {
      "x": -9,
      "y": 29,
      "z": -9,
      "name": "Plant_Leaves_Oak"
    },
    {
      "x": -9,
      "y": 30,
      "z": -9,
      "name": "Plant_Leaves_Oak"
    },
    {
      "x": -9,
      "y": 31,
      "z": -9,
      "name": "Plant_Leaves_Oak"
    },
    {
      "x": -9,
      "y": 32,
      "z": -9,
      "name": "Plant_Leaves_Oak"
    },
    {
      "x": -9,
      "y": 33,
      "z": -9,
      "name": "Plant_Leaves_Oak"
    },
    {
      "x": -9,
      "y": 7,
      "z": -8,
      "name": "Rock_Stone"
    },
    {
      "x": -9,
      "y": 8,
      "z": -8,
      "name": "Rock_Stone"
    },
    {
      "x": -9,
      "y": 9,
      "z": -8,
      "name": "Rock_Stone"
    },
    {
      "x": -9,
      "y": 10,
      "z": -8,
      "name": "Rock_Stone"
    },
    {
      "x": -9,
      "y": 11,
      "z": -8,
      "name": "Rock_Stone"
    },
    {
      "x": -9,
      "y": 12,
      "z": -8,
      "name": "Rock_Stone"
    },
    {
      "x": -9,
      "y": 13,
      "z": -8,
      "name": "Rock_Stone"
    },
    {
      "x": -9,
      "y": 14,
      "z": -8,
      "name": "Soil_Dirt"
    },
    {
      "x": -9,
      "y": 15,
      "z": -8,
      "name": "Soil_Grass"
    },
    {
      "x": -9,
      "y": 16,
      "z": -8,
      "name": "Plant_Grass_Sharp_Tall"
    },
    {
      "x": -9,
      "y": 17,
      "z": -8,
      "name": "Plant_Grass_Sharp_Tall",
      "filler": 1024
    },
    {
      "x": -9,
      "y": 29,
      "z": -8,
      "name": "Plant_Leaves_Oak"
    },
    {
      "x": -9,
      "y": 31,
      "z": -8,
      "name": "Plant_Leaves_Oak"
    },
    {
      "x": -9,
      "y": 32,
      "z": -8,
      "name": "Plant_Leaves_Oak"
    },
    {
      "x": -9,
      "y": 33,
      "z": -8,
      "name": "Plant_Leaves_Oak"
    },
    {
      "x": -9,
      "y": 34,
      "z": -8,
      "name": "Plant_Leaves_Oak"
    },
    {
      "x": -9,
      "y": 7,
      "z": -7,
      "name": "Rock_Stone"
    },
    {
      "x": -9,
      "y": 8,
      "z": -7,
      "name": "Rock_Stone"
    },
    {
      "x": -9,
      "y": 9,
      "z": -7,
      "name": "Rock_Stone"
    },
    {
      "x": -9,
      "y": 10,
      "z": -7,
      "name": "Rock_Stone"
    },
    {
      "x": -9,
      "y": 11,
      "z": -7,
      "name": "Rock_Stone"
    },
    {
      "x": -9,
      "y": 12,
      "z": -7,
      "name": "Rock_Stone"
    },
    {
      "x": -9,
      "y": 13,
      "z": -7,
      "name": "Rock_Stone"
    },
    {
      "x": -9,
      "y": 14,
      "z": -7,
      "name": "Soil_Dirt"
    },
    {
      "x": -9,
      "y": 15,
      "z": -7,
      "name": "Soil_Grass"
    },
    {
      "x": -9,
      "y": 16,
      "z": -7,
      "name": "Plant_Grass_Sharp"
    },
    {
      "x": -9,
      "y": 30,
      "z": -7,
      "name": "Plant_Leaves_Oak"
    },
    {
      "x": -9,
      "y": 31,
      "z": -7,
      "name": "Plant_Leaves_Oak"
    },
    {
      "x": -9,
      "y": 32,
      "z": -7,
      "name": "Plant_Leaves_Oak"
    },
    {
      "x": -9,
      "y": 33,
      "z": -7,
      "name": "Plant_Leaves_Oak"
    },
    {
      "x": -9,
      "y": 34,
      "z": -7,
      "name": "Plant_Leaves_Oak"
    },
    {
      "x": -9,
      "y": 6,
      "z": -6,
      "name": "Rock_Stone"
    },
    {
      "x": -9,
      "y": 7,
      "z": -6,
      "name": "Rock_Stone"
    },
    {
      "x": -9,
      "y": 8,
      "z": -6,
      "name": "Rock_Stone"
    },
    {
      "x": -9,
      "y": 9,
      "z": -6,
      "name": "Rock_Stone"
    },
    {
      "x": -9,
      "y": 10,
      "z": -6,
      "name": "Rock_Stone"
    },
    {
      "x": -9,
      "y": 11,
      "z": -6,
      "name": "Rock_Stone"
    },
    {
      "x": -9,
      "y": 12,
      "z": -6,
      "name": "Rock_Stone"
    },
    {
      "x": -9,
      "y": 13,
      "z": -6,
      "name": "Rock_Stone"
    },
    {
      "x": -9,
      "y": 14,
      "z": -6,
      "name": "Soil_Dirt"
    },
    {
      "x": -9,
      "y": 15,
      "z": -6,
      "name": "Soil_Grass"
    },
    {
      "x": -9,
      "y": 16,
      "z": -6,
      "name": "*Plant_Crop_Berry_Block_State_Definitions_StageFinal",
      "components": {
        "Components": {
          "FarmingBlock": {}
        }
      }
    },
    {
      "x": -9,
      "y": 33,
      "z": -6,
      "name": "Plant_Leaves_Oak"
    },
    {
      "x": -9,
      "y": 6,
      "z": -5,
      "name": "Rock_Stone"
    },
    {
      "x": -9,
      "y": 7,
      "z": -5,
      "name": "Rock_Stone"
    },
    {
      "x": -9,
      "y": 8,
      "z": -5,
      "name": "Rock_Stone"
    },
    {
      "x": -9,
      "y": 9,
      "z": -5,
      "name": "Rock_Stone"
    },
    {
      "x": -9,
      "y": 10,
      "z": -5,
      "name": "Rock_Stone"
    },
    {
      "x": -9,
      "y": 11,
      "z": -5,
      "name": "Rock_Stone"
    },
    {
      "x": -9,
      "y": 12,
      "z": -5,
      "name": "Rock_Stone"
    },
    {
      "x": -9,
      "y": 13,
      "z": -5,
      "name": "Rock_Stone"
    },
    {
      "x": -9,
      "y": 14,
      "z": -5,
      "name": "Soil_Dirt"
    },
    {
      "x": -9,
      "y": 15,
      "z": -5,
      "name": "Soil_Grass"
    },
    {
      "x": -9,
      "y": 16,
      "z": -5,
      "name": "Plant_Bush"
    },
    {
      "x": -9,
      "y": 20,
      "z": -5,
      "name": "Plant_Moss_Wall_Green",
      "rotation": 3
    },
    {
      "x": -9,
      "y": 21,
      "z": -5,
      "name": "Plant_Moss_Wall_Green",
      "rotation": 3
    },
    {
      "x": -9,
      "y": 27,
      "z": -5,
      "name": "Plant_Leaves_Oak"
    },
    {
      "x": -9,
      "y": 28,
      "z": -5,
      "name": "Plant_Leaves_Oak"
    },
    {
      "x": -9,
      "y": 6,
      "z": -4,
      "name": "Rock_Stone"
    },
    {
      "x": -9,
      "y": 7,
      "z": -4,
      "name": "Rock_Stone"
    },
    {
      "x": -9,
      "y": 8,
      "z": -4,
      "name": "Rock_Stone"
    },
    {
      "x": -9,
      "y": 9,
      "z": -4,
      "name": "Rock_Stone"
    },
    {
      "x": -9,
      "y": 10,
      "z": -4,
      "name": "Rock_Stone"
    },
    {
      "x": -9,
      "y": 11,
      "z": -4,
      "name": "Rock_Stone"
    },
    {
      "x": -9,
      "y": 12,
      "z": -4,
      "name": "Rock_Stone"
    },
    {
      "x": -9,
      "y": 13,
      "z": -4,
      "name": "Rock_Stone"
    },
    {
      "x": -9,
      "y": 14,
      "z": -4,
      "name": "Soil_Dirt"
    },
    {
      "x": -9,
      "y": 15,
      "z": -4,
      "name": "Soil_Grass"
    },
    {
      "x": -9,
      "y": 17,
      "z": -4,
      "name": "Rock_Stone_Mossy"
    },
    {
      "x": -9,
      "y": 18,
      "z": -4,
      "name": "Rock_Stone_Mossy"
    },
    {
      "x": -9,
      "y": 19,
      "z": -4,
      "name": "Plant_Moss_Wall_Green",
      "rotation": 2
    },
    {
      "x": -9,
      "y": 20,
      "z": -4,
      "name": "Plant_Moss_Wall_Green",
      "rotation": 2
    },
    {
      "x": -9,
      "y": 21,
      "z": -4,
      "name": "Plant_Moss_Wall_Green",
      "rotation": 3
    },
    {
      "x": -9,
      "y": 26,
      "z": -4,
      "name": "Plant_Leaves_Oak"
    },
    {
      "x": -9,
      "y": 27,
      "z": -4,
      "name": "Plant_Leaves_Oak"
    },
    {
      "x": -9,
      "y": 28,
      "z": -4,
      "name": "Plant_Leaves_Oak"
    },
    {
      "x": -9,
      "y": 7,
      "z": -3,
      "name": "Rock_Stone"
    },
    {
      "x": -9,
      "y": 8,
      "z": -3,
      "name": "Rock_Stone"
    },
    {
      "x": -9,
      "y": 9,
      "z": -3,
      "name": "Rock_Stone"
    },
    {
      "x": -9,
      "y": 10,
      "z": -3,
      "name": "Rock_Stone"
    },
    {
      "x": -9,
      "y": 11,
      "z": -3,
      "name": "Rock_Stone"
    },
    {
      "x": -9,
      "y": 12,
      "z": -3,
      "name": "Rock_Stone"
    },
    {
      "x": -9,
      "y": 13,
      "z": -3,
      "name": "Rock_Stone"
    },
    {
      "x": -9,
      "y": 14,
      "z": -3,
      "name": "Soil_Dirt"
    },
    {
      "x": -9,
      "y": 15,
      "z": -3,
      "name": "Soil_Grass"
    },
    {
      "x": -9,
      "y": 16,
      "z": -3,
      "name": "Rock_Stone"
    },
    {
      "x": -9,
      "y": 17,
      "z": -3,
      "name": "Rock_Stone_Mossy"
    },
    {
      "x": -9,
      "y": 18,
      "z": -3,
      "name": "Rock_Stone"
    },
    {
      "x": -9,
      "y": 19,
      "z": -3,
      "name": "Rock_Stone"
    },
    {
      "x": -9,
      "y": 20,
      "z": -3,
      "name": "Rock_Stone"
    },
    {
      "x": -9,
      "y": 21,
      "z": -3,
      "name": "Plant_Moss_Rug_Green"
    },
    {
      "x": -9,
      "y": 7,
      "z": -2,
      "name": "Rock_Stone"
    },
    {
      "x": -9,
      "y": 8,
      "z": -2,
      "name": "Rock_Stone"
    },
    {
      "x": -9,
      "y": 9,
      "z": -2,
      "name": "Rock_Stone"
    },
    {
      "x": -9,
      "y": 10,
      "z": -2,
      "name": "Rock_Stone"
    },
    {
      "x": -9,
      "y": 11,
      "z": -2,
      "name": "Rock_Stone"
    },
    {
      "x": -9,
      "y": 12,
      "z": -2,
      "name": "Rock_Stone"
    },
    {
      "x": -9,
      "y": 13,
      "z": -2,
      "name": "Rock_Stone"
    },
    {
      "x": -9,
      "y": 14,
      "z": -2,
      "name": "Rock_Stone"
    },
    {
      "x": -9,
      "y": 15,
      "z": -2,
      "name": "Rock_Stone"
    },
    {
      "x": -9,
      "y": 16,
      "z": -2,
      "name": "Rock_Stone"
    },
    {
      "x": -9,
      "y": 17,
      "z": -2,
      "name": "Rock_Stone"
    },
    {
      "x": -9,
      "y": 18,
      "z": -2,
      "name": "Rock_Stone"
    },
    {
      "x": -9,
      "y": 19,
      "z": -2,
      "name": "Rock_Stone"
    },
    {
      "x": -9,
      "y": 20,
      "z": -2,
      "name": "Rock_Stone"
    },
    {
      "x": -9,
      "y": 21,
      "z": -2,
      "name": "Rock_Stone"
    },
    {
      "x": -9,
      "y": 22,
      "z": -2,
      "name": "Rock_Stone"
    },
    {
      "x": -9,
      "y": 11,
      "z": -1,
      "name": "Plant_Moss_Wall_Green"
    },
    {
      "x": -9,
      "y": 12,
      "z": -1,
      "name": "Plant_Moss_Wall_Green"
    },
    {
      "x": -9,
      "y": 13,
      "z": -1,
      "name": "Rock_Stone"
    },
    {
      "x": -9,
      "y": 14,
      "z": -1,
      "name": "Rock_Stone"
    },
    {
      "x": -9,
      "y": 15,
      "z": -1,
      "name": "Rock_Stone"
    },
    {
      "x": -9,
      "y": 16,
      "z": -1,
      "name": "Rock_Stone"
    },
    {
      "x": -9,
      "y": 17,
      "z": -1,
      "name": "Rock_Stone"
    },
    {
      "x": -9,
      "y": 18,
      "z": -1,
      "name": "Rock_Stone"
    },
    {
      "x": -9,
      "y": 19,
      "z": -1,
      "name": "Rock_Stone"
    },
    {
      "x": -9,
      "y": 20,
      "z": -1,
      "name": "Rock_Stone"
    },
    {
      "x": -9,
      "y": 21,
      "z": -1,
      "name": "Rock_Stone"
    },
    {
      "x": -9,
      "y": 22,
      "z": -1,
      "name": "Rock_Stone"
    },
    {
      "x": -9,
      "y": 16,
      "z": 0,
      "name": "Rock_Stone"
    },
    {
      "x": -9,
      "y": 17,
      "z": 0,
      "name": "Rock_Stone"
    },
    {
      "x": -9,
      "y": 18,
      "z": 0,
      "name": "Rock_Stone"
    },
    {
      "x": -9,
      "y": 19,
      "z": 0,
      "name": "Rock_Stone"
    },
    {
      "x": -9,
      "y": 20,
      "z": 0,
      "name": "Rock_Stone"
    },
    {
      "x": -9,
      "y": 21,
      "z": 0,
      "name": "Rock_Stone"
    },
    {
      "x": -9,
      "y": 22,
      "z": 0,
      "name": "Rock_Stone"
    },
    {
      "x": -9,
      "y": 19,
      "z": 1,
      "name": "Rock_Stone"
    },
    {
      "x": -9,
      "y": 20,
      "z": 1,
      "name": "Rock_Stone"
    },
    {
      "x": -9,
      "y": 21,
      "z": 1,
      "name": "Rock_Stone"
    },
    {
      "x": -9,
      "y": 8,
      "z": 4,
      "name": "Rock_Stone"
    },
    {
      "x": -9,
      "y": 9,
      "z": 4,
      "name": "Soil_Dirt"
    },
    {
      "x": -9,
      "y": 10,
      "z": 4,
      "name": "Soil_Grass"
    },
    {
      "x": -9,
      "y": 8,
      "z": 5,
      "name": "Rock_Stone"
    },
    {
      "x": -9,
      "y": 9,
      "z": 5,
      "name": "Soil_Dirt"
    },
    {
      "x": -9,
      "y": 10,
      "z": 5,
      "name": "Soil_Grass"
    },
    {
      "x": -9,
      "y": 11,
      "z": 5,
      "name": "Plant_Grass_Sharp"
    },
    {
      "x": -9,
      "y": 13,
      "z": 6,
      "name": "Plant_Moss_Wall_Green",
      "rotation": 2
    },
    {
      "x": -9,
      "y": 9,
      "z": 7,
      "name": "Rock_Stone"
    },
    {
      "x": -9,
      "y": 10,
      "z": 7,
      "name": "Rock_Stone_Mossy"
    },
    {
      "x": -9,
      "y": 11,
      "z": 7,
      "name": "Rock_Stone_Mossy"
    },
    {
      "x": -9,
      "y": 12,
      "z": 7,
      "name": "Rock_Stone_Mossy"
    },
    {
      "x": -9,
      "y": 13,
      "z": 7,
      "name": "Rock_Stone"
    },
    {
      "x": -9,
      "y": 14,
      "z": 7,
      "name": "Plant_Moss_Rug_Green"
    },
    {
      "x": -9,
      "y": 7,
      "z": 8,
      "name": "Rock_Stone"
    },
    {
      "x": -9,
      "y": 8,
      "z": 8,
      "name": "Rock_Stone"
    },
    {
      "x": -9,
      "y": 9,
      "z": 8,
      "name": "Rock_Stone"
    },
    {
      "x": -9,
      "y": 10,
      "z": 8,
      "name": "Rock_Stone"
    },
    {
      "x": -9,
      "y": 11,
      "z": 8,
      "name": "Rock_Stone_Mossy"
    },
    {
      "x": -9,
      "y": 12,
      "z": 8,
      "name": "Rock_Stone"
    },
    {
      "x": -9,
      "y": 13,
      "z": 8,
      "name": "Rock_Stone"
    },
    {
      "x": -9,
      "y": 14,
      "z": 8,
      "name": "Rock_Stone"
    },
    {
      "x": -9,
      "y": 15,
      "z": 8,
      "name": "Rock_Stone"
    },
    {
      "x": -9,
      "y": 16,
      "z": 8,
      "name": "Rock_Stone"
    },
    {
      "x": -9,
      "y": 7,
      "z": 9,
      "name": "Rock_Stone"
    },
    {
      "x": -9,
      "y": 8,
      "z": 9,
      "name": "Rock_Stone"
    },
    {
      "x": -9,
      "y": 9,
      "z": 9,
      "name": "Rock_Stone"
    },
    {
      "x": -9,
      "y": 10,
      "z": 9,
      "name": "Rock_Stone"
    },
    {
      "x": -9,
      "y": 11,
      "z": 9,
      "name": "Rock_Stone"
    },
    {
      "x": -9,
      "y": 12,
      "z": 9,
      "name": "Rock_Stone"
    },
    {
      "x": -9,
      "y": 13,
      "z": 9,
      "name": "Rock_Stone"
    },
    {
      "x": -9,
      "y": 14,
      "z": 9,
      "name": "Rock_Stone"
    },
    {
      "x": -9,
      "y": 15,
      "z": 9,
      "name": "Rock_Stone"
    },
    {
      "x": -9,
      "y": 16,
      "z": 9,
      "name": "Rock_Stone"
    },
    {
      "x": -9,
      "y": 17,
      "z": 9,
      "name": "Rock_Stone"
    },
    {
      "x": -9,
      "y": 18,
      "z": 9,
      "name": "Rock_Stone"
    },
    {
      "x": -9,
      "y": 8,
      "z": 10,
      "name": "Rock_Stone"
    },
    {
      "x": -9,
      "y": 9,
      "z": 10,
      "name": "Rock_Stone"
    },
    {
      "x": -9,
      "y": 10,
      "z": 10,
      "name": "Rock_Stone"
    },
    {
      "x": -9,
      "y": 11,
      "z": 10,
      "name": "Rock_Stone"
    },
    {
      "x": -9,
      "y": 12,
      "z": 10,
      "name": "Rock_Stone"
    },
    {
      "x": -9,
      "y": 13,
      "z": 10,
      "name": "Rock_Stone"
    },
    {
      "x": -9,
      "y": 14,
      "z": 10,
      "name": "Rock_Stone"
    },
    {
      "x": -9,
      "y": 15,
      "z": 10,
      "name": "Rock_Stone"
    },
    {
      "x": -9,
      "y": 9,
      "z": 11,
      "name": "Rock_Stone"
    },
    {
      "x": -9,
      "y": 10,
      "z": 11,
      "name": "Rock_Stone"
    },
    {
      "x": -9,
      "y": 11,
      "z": 11,
      "name": "Rock_Stone"
    },
    {
      "x": -9,
      "y": 12,
      "z": 11,
      "name": "Rock_Stone"
    },
    {
      "x": -8,
      "y": 28,
      "z": -19,
      "name": "Plant_Leaves_Oak"
    },
    {
      "x": -8,
      "y": 29,
      "z": -19,
      "name": "Plant_Leaves_Oak"
    },
    {
      "x": -8,
      "y": 27,
      "z": -18,
      "name": "Plant_Leaves_Oak"
    },
    {
      "x": -8,
      "y": 28,
      "z": -18,
      "name": "Plant_Leaves_Oak"
    },
    {
      "x": -8,
      "y": 29,
      "z": -18,
      "name": "Plant_Leaves_Oak"
    },
    {
      "x": -8,
      "y": 30,
      "z": -18,
      "name": "Plant_Leaves_Oak"
    },
    {
      "x": -8,
      "y": 29,
      "z": -17,
      "name": "Plant_Leaves_Oak"
    },
    {
      "x": -8,
      "y": 30,
      "z": -17,
      "name": "Plant_Leaves_Oak"
    },
    {
      "x": -8,
      "y": 31,
      "z": -17,
      "name": "Plant_Leaves_Oak"
    },
    {
      "x": -8,
      "y": 32,
      "z": -17,
      "name": "Plant_Leaves_Oak"
    },
    {
      "x": -8,
      "y": 28,
      "z": -16,
      "name": "Wood_Oak_Branch_Long",
      "rotation": 5
    },
    {
      "x": -8,
      "y": 31,
      "z": -16,
      "name": "Plant_Leaves_Oak"
    },
    {
      "x": -8,
      "y": 32,
      "z": -16,
      "name": "Plant_Leaves_Oak"
    },
    {
      "x": -8,
      "y": 33,
      "z": -16,
      "name": "Plant_Leaves_Oak"
    },
    {
      "x": -8,
      "y": 31,
      "z": -15,
      "name": "Wood_Oak_Branch_Long",
      "rotation": 5
    },
    {
      "x": -8,
      "y": 32,
      "z": -15,
      "name": "Plant_Leaves_Oak"
    },
    {
      "x": -8,
      "y": 33,
      "z": -15,
      "name": "Plant_Leaves_Oak"
    },
    {
      "x": -8,
      "y": 11,
      "z": -14,
      "name": "Empty"
    },
    {
      "x": -8,
      "y": 12,
      "z": -14,
      "name": "Rock_Stone_Mossy"
    },
    {
      "x": -8,
      "y": 13,
      "z": -14,
      "name": "Rock_Stone_Mossy"
    },
    {
      "x": -8,
      "y": 14,
      "z": -14,
      "name": "Soil_Dirt"
    },
    {
      "x": -8,
      "y": 15,
      "z": -14,
      "name": "Soil_Grass"
    },
    {
      "x": -8,
      "y": 27,
      "z": -14,
      "name": "Wood_Oak_Trunk_Full"
    },
    {
      "x": -8,
      "y": 31,
      "z": -14,
      "name": "Plant_Leaves_Oak"
    },
    {
      "x": -8,
      "y": 32,
      "z": -14,
      "name": "Plant_Leaves_Oak"
    },
    {
      "x": -8,
      "y": 33,
      "z": -14,
      "name": "Plant_Leaves_Oak"
    },
    {
      "x": -8,
      "y": 11,
      "z": -13,
      "name": "Empty"
    },
    {
      "x": -8,
      "y": 12,
      "z": -13,
      "name": "Empty"
    },
    {
      "x": -8,
      "y": 13,
      "z": -13,
      "name": "Rock_Stone"
    },
    {
      "x": -8,
      "y": 14,
      "z": -13,
      "name": "Rock_Stone"
    },
    {
      "x": -8,
      "y": 15,
      "z": -13,
      "name": "Soil_Dirt"
    },
    {
      "x": -8,
      "y": 16,
      "z": -13,
      "name": "Soil_Grass"
    },
    {
      "x": -8,
      "y": 27,
      "z": -13,
      "name": "Wood_Oak_Trunk_Full"
    },
    {
      "x": -8,
      "y": 28,
      "z": -13,
      "name": "Wood_Oak_Trunk_Full"
    },
    {
      "x": -8,
      "y": 31,
      "z": -13,
      "name": "Plant_Leaves_Oak"
    },
    {
      "x": -8,
      "y": 32,
      "z": -13,
      "name": "Plant_Leaves_Oak"
    },
    {
      "x": -8,
      "y": 33,
      "z": -13,
      "name": "Plant_Leaves_Oak"
    },
    {
      "x": -8,
      "y": 11,
      "z": -12,
      "name": "Empty"
    },
    {
      "x": -8,
      "y": 12,
      "z": -12,
      "name": "Empty"
    },
    {
      "x": -8,
      "y": 13,
      "z": -12,
      "name": "Empty"
    },
    {
      "x": -8,
      "y": 14,
      "z": -12,
      "name": "Rock_Stone"
    },
    {
      "x": -8,
      "y": 15,
      "z": -12,
      "name": "Soil_Dirt"
    },
    {
      "x": -8,
      "y": 16,
      "z": -12,
      "name": "Soil_Grass"
    },
    {
      "x": -8,
      "y": 32,
      "z": -12,
      "name": "Plant_Leaves_Oak"
    },
    {
      "x": -8,
      "y": 33,
      "z": -12,
      "name": "Plant_Leaves_Oak"
    },
    {
      "x": -8,
      "y": 11,
      "z": -11,
      "name": "Empty"
    },
    {
      "x": -8,
      "y": 12,
      "z": -11,
      "name": "Empty"
    },
    {
      "x": -8,
      "y": 13,
      "z": -11,
      "name": "Rock_Stone"
    },
    {
      "x": -8,
      "y": 14,
      "z": -11,
      "name": "Rock_Stone"
    },
    {
      "x": -8,
      "y": 15,
      "z": -11,
      "name": "Soil_Dirt"
    },
    {
      "x": -8,
      "y": 16,
      "z": -11,
      "name": "Soil_Grass"
    },
    {
      "x": -8,
      "y": 34,
      "z": -11,
      "name": "Plant_Leaves_Oak"
    },
    {
      "x": -8,
      "y": 11,
      "z": -10,
      "name": "Empty"
    },
    {
      "x": -8,
      "y": 12,
      "z": -10,
      "name": "Rock_Stone"
    },
    {
      "x": -8,
      "y": 13,
      "z": -10,
      "name": "Rock_Stone"
    },
    {
      "x": -8,
      "y": 14,
      "z": -10,
      "name": "Rock_Stone"
    },
    {
      "x": -8,
      "y": 15,
      "z": -10,
      "name": "Soil_Dirt"
    },
    {
      "x": -8,
      "y": 16,
      "z": -10,
      "name": "Soil_Grass"
    },
    {
      "x": -8,
      "y": 30,
      "z": -10,
      "name": "Wood_Oak_Branch_Long",
      "rotation": 5
    },
    {
      "x": -8,
      "y": 33,
      "z": -10,
      "name": "Plant_Leaves_Oak"
    },
    {
      "x": -8,
      "y": 34,
      "z": -10,
      "name": "Plant_Leaves_Oak"
    },
    {
      "x": -8,
      "y": 9,
      "z": -9,
      "name": "Rock_Stone"
    },
    {
      "x": -8,
      "y": 10,
      "z": -9,
      "name": "Rock_Stone"
    },
    {
      "x": -8,
      "y": 11,
      "z": -9,
      "name": "Rock_Stone_Mossy"
    },
    {
      "x": -8,
      "y": 12,
      "z": -9,
      "name": "Rock_Stone"
    },
    {
      "x": -8,
      "y": 13,
      "z": -9,
      "name": "Rock_Stone"
    },
    {
      "x": -8,
      "y": 14,
      "z": -9,
      "name": "Soil_Dirt"
    },
    {
      "x": -8,
      "y": 15,
      "z": -9,
      "name": "Soil_Grass"
    },
    {
      "x": -8,
      "y": 16,
      "z": -9,
      "name": "Plant_Grass_Sharp"
    },
    {
      "x": -8,
      "y": 33,
      "z": -9,
      "name": "Plant_Leaves_Oak"
    },
    {
      "x": -8,
      "y": 34,
      "z": -9,
      "name": "Plant_Leaves_Oak"
    },
    {
      "x": -8,
      "y": 7,
      "z": -8,
      "name": "Rock_Stone"
    },
    {
      "x": -8,
      "y": 8,
      "z": -8,
      "name": "Rock_Stone"
    },
    {
      "x": -8,
      "y": 9,
      "z": -8,
      "name": "Rock_Stone"
    },
    {
      "x": -8,
      "y": 10,
      "z": -8,
      "name": "Rock_Stone"
    },
    {
      "x": -8,
      "y": 11,
      "z": -8,
      "name": "Rock_Stone"
    },
    {
      "x": -8,
      "y": 12,
      "z": -8,
      "name": "Rock_Stone"
    },
    {
      "x": -8,
      "y": 13,
      "z": -8,
      "name": "Rock_Stone"
    },
    {
      "x": -8,
      "y": 14,
      "z": -8,
      "name": "Soil_Dirt"
    },
    {
      "x": -8,
      "y": 15,
      "z": -8,
      "name": "Soil_Grass"
    },
    {
      "x": -8,
      "y": 16,
      "z": -8,
      "name": "Plant_Grass_Sharp"
    },
    {
      "x": -8,
      "y": 31,
      "z": -8,
      "name": "Wood_Oak_Branch_Long",
      "rotation": 5
    },
    {
      "x": -8,
      "y": 32,
      "z": -8,
      "name": "Plant_Leaves_Oak"
    },
    {
      "x": -8,
      "y": 33,
      "z": -8,
      "name": "Plant_Leaves_Oak"
    },
    {
      "x": -8,
      "y": 35,
      "z": -8,
      "name": "Plant_Leaves_Oak"
    },
    {
      "x": -8,
      "y": 6,
      "z": -7,
      "name": "Rock_Stone"
    },
    {
      "x": -8,
      "y": 7,
      "z": -7,
      "name": "Rock_Stone"
    },
    {
      "x": -8,
      "y": 8,
      "z": -7,
      "name": "Rock_Stone"
    },
    {
      "x": -8,
      "y": 9,
      "z": -7,
      "name": "Rock_Stone"
    },
    {
      "x": -8,
      "y": 10,
      "z": -7,
      "name": "Rock_Stone"
    },
    {
      "x": -8,
      "y": 11,
      "z": -7,
      "name": "Rock_Stone"
    },
    {
      "x": -8,
      "y": 12,
      "z": -7,
      "name": "Rock_Stone"
    },
    {
      "x": -8,
      "y": 13,
      "z": -7,
      "name": "Rock_Stone"
    },
    {
      "x": -8,
      "y": 14,
      "z": -7,
      "name": "Soil_Dirt"
    },
    {
      "x": -8,
      "y": 15,
      "z": -7,
      "name": "Soil_Grass"
    },
    {
      "x": -8,
      "y": 16,
      "z": -7,
      "name": "Plant_Grass_Sharp"
    },
    {
      "x": -8,
      "y": 31,
      "z": -7,
      "name": "Plant_Leaves_Oak"
    },
    {
      "x": -8,
      "y": 32,
      "z": -7,
      "name": "Plant_Leaves_Oak"
    },
    {
      "x": -8,
      "y": 33,
      "z": -7,
      "name": "Plant_Leaves_Oak"
    },
    {
      "x": -8,
      "y": 34,
      "z": -7,
      "name": "Wood_Oak_Branch_Long",
      "rotation": 5
    },
    {
      "x": -8,
      "y": 35,
      "z": -7,
      "name": "Plant_Leaves_Oak"
    },
    {
      "x": -8,
      "y": 6,
      "z": -6,
      "name": "Rock_Stone"
    },
    {
      "x": -8,
      "y": 7,
      "z": -6,
      "name": "Rock_Stone"
    },
    {
      "x": -8,
      "y": 8,
      "z": -6,
      "name": "Rock_Stone"
    },
    {
      "x": -8,
      "y": 9,
      "z": -6,
      "name": "Rock_Stone"
    },
    {
      "x": -8,
      "y": 10,
      "z": -6,
      "name": "Rock_Stone"
    },
    {
      "x": -8,
      "y": 11,
      "z": -6,
      "name": "Rock_Stone"
    },
    {
      "x": -8,
      "y": 12,
      "z": -6,
      "name": "Rock_Stone"
    },
    {
      "x": -8,
      "y": 13,
      "z": -6,
      "name": "Rock_Stone"
    },
    {
      "x": -8,
      "y": 14,
      "z": -6,
      "name": "Soil_Dirt"
    },
    {
      "x": -8,
      "y": 15,
      "z": -6,
      "name": "Soil_Grass"
    },
    {
      "x": -8,
      "y": 18,
      "z": -6,
      "name": "Rock_Stone_Mossy"
    },
    {
      "x": -8,
      "y": 19,
      "z": -6,
      "name": "Rock_Stone_Mossy"
    },
    {
      "x": -8,
      "y": 31,
      "z": -6,
      "name": "Plant_Leaves_Oak"
    },
    {
      "x": -8,
      "y": 32,
      "z": -6,
      "name": "Plant_Leaves_Oak"
    },
    {
      "x": -8,
      "y": 33,
      "z": -6,
      "name": "Plant_Leaves_Oak"
    },
    {
      "x": -8,
      "y": 34,
      "z": -6,
      "name": "Plant_Leaves_Oak"
    },
    {
      "x": -8,
      "y": 6,
      "z": -5,
      "name": "Rock_Stone"
    },
    {
      "x": -8,
      "y": 7,
      "z": -5,
      "name": "Rock_Stone"
    },
    {
      "x": -8,
      "y": 8,
      "z": -5,
      "name": "Rock_Stone"
    },
    {
      "x": -8,
      "y": 9,
      "z": -5,
      "name": "Rock_Stone"
    },
    {
      "x": -8,
      "y": 10,
      "z": -5,
      "name": "Rock_Stone"
    },
    {
      "x": -8,
      "y": 11,
      "z": -5,
      "name": "Rock_Stone"
    },
    {
      "x": -8,
      "y": 12,
      "z": -5,
      "name": "Rock_Stone"
    },
    {
      "x": -8,
      "y": 13,
      "z": -5,
      "name": "Rock_Stone"
    },
    {
      "x": -8,
      "y": 14,
      "z": -5,
      "name": "Soil_Dirt"
    },
    {
      "x": -8,
      "y": 15,
      "z": -5,
      "name": "Soil_Grass"
    },
    {
      "x": -8,
      "y": 17,
      "z": -5,
      "name": "Rock_Stone"
    },
    {
      "x": -8,
      "y": 18,
      "z": -5,
      "name": "Rock_Stone_Mossy"
    },
    {
      "x": -8,
      "y": 19,
      "z": -5,
      "name": "Rock_Stone"
    },
    {
      "x": -8,
      "y": 20,
      "z": -5,
      "name": "Rock_Stone"
    },
    {
      "x": -8,
      "y": 21,
      "z": -5,
      "name": "Rock_Stone"
    },
    {
      "x": -8,
      "y": 22,
      "z": -5,
      "name": "Plant_Moss_Rug_Green"
    },
    {
      "x": -8,
      "y": 32,
      "z": -5,
      "name": "Plant_Leaves_Oak"
    },
    {
      "x": -8,
      "y": 33,
      "z": -5,
      "name": "Plant_Leaves_Oak"
    },
    {
      "x": -8,
      "y": 34,
      "z": -5,
      "name": "Plant_Leaves_Oak"
    },
    {
      "x": -8,
      "y": 6,
      "z": -4,
      "name": "Rock_Stone"
    },
    {
      "x": -8,
      "y": 7,
      "z": -4,
      "name": "Rock_Stone"
    },
    {
      "x": -8,
      "y": 8,
      "z": -4,
      "name": "Rock_Stone"
    },
    {
      "x": -8,
      "y": 9,
      "z": -4,
      "name": "Rock_Stone"
    },
    {
      "x": -8,
      "y": 10,
      "z": -4,
      "name": "Rock_Stone"
    },
    {
      "x": -8,
      "y": 11,
      "z": -4,
      "name": "Rock_Stone"
    },
    {
      "x": -8,
      "y": 12,
      "z": -4,
      "name": "Rock_Stone"
    },
    {
      "x": -8,
      "y": 13,
      "z": -4,
      "name": "Rock_Stone"
    },
    {
      "x": -8,
      "y": 14,
      "z": -4,
      "name": "Rock_Stone"
    },
    {
      "x": -8,
      "y": 15,
      "z": -4,
      "name": "Soil_Dirt"
    },
    {
      "x": -8,
      "y": 16,
      "z": -4,
      "name": "Rock_Stone"
    },
    {
      "x": -8,
      "y": 17,
      "z": -4,
      "name": "Rock_Stone_Mossy"
    },
    {
      "x": -8,
      "y": 18,
      "z": -4,
      "name": "Rock_Stone"
    },
    {
      "x": -8,
      "y": 19,
      "z": -4,
      "name": "Rock_Stone"
    },
    {
      "x": -8,
      "y": 20,
      "z": -4,
      "name": "Rock_Stone"
    },
    {
      "x": -8,
      "y": 21,
      "z": -4,
      "name": "Rock_Stone"
    },
    {
      "x": -8,
      "y": 22,
      "z": -4,
      "name": "Plant_Moss_Rug_Green"
    },
    {
      "x": -8,
      "y": 26,
      "z": -4,
      "name": "Plant_Leaves_Oak"
    },
    {
      "x": -8,
      "y": 28,
      "z": -4,
      "name": "Plant_Leaves_Oak"
    },
    {
      "x": -8,
      "y": 29,
      "z": -4,
      "name": "Plant_Leaves_Oak"
    },
    {
      "x": -8,
      "y": 6,
      "z": -3,
      "name": "Rock_Stone"
    },
    {
      "x": -8,
      "y": 7,
      "z": -3,
      "name": "Rock_Stone"
    },
    {
      "x": -8,
      "y": 8,
      "z": -3,
      "name": "Rock_Stone"
    },
    {
      "x": -8,
      "y": 9,
      "z": -3,
      "name": "Rock_Stone"
    },
    {
      "x": -8,
      "y": 10,
      "z": -3,
      "name": "Rock_Stone"
    },
    {
      "x": -8,
      "y": 11,
      "z": -3,
      "name": "Rock_Stone"
    },
    {
      "x": -8,
      "y": 12,
      "z": -3,
      "name": "Rock_Stone"
    },
    {
      "x": -8,
      "y": 13,
      "z": -3,
      "name": "Rock_Stone"
    },
    {
      "x": -8,
      "y": 14,
      "z": -3,
      "name": "Rock_Stone"
    },
    {
      "x": -8,
      "y": 15,
      "z": -3,
      "name": "Rock_Stone"
    },
    {
      "x": -8,
      "y": 16,
      "z": -3,
      "name": "Rock_Stone"
    },
    {
      "x": -8,
      "y": 17,
      "z": -3,
      "name": "Rock_Stone"
    },
    {
      "x": -8,
      "y": 18,
      "z": -3,
      "name": "Rock_Stone"
    },
    {
      "x": -8,
      "y": 19,
      "z": -3,
      "name": "Rock_Stone"
    },
    {
      "x": -8,
      "y": 20,
      "z": -3,
      "name": "Rock_Stone"
    },
    {
      "x": -8,
      "y": 21,
      "z": -3,
      "name": "Rock_Stone"
    },
    {
      "x": -8,
      "y": 22,
      "z": -3,
      "name": "Rock_Stone"
    },
    {
      "x": -8,
      "y": 26,
      "z": -3,
      "name": "Plant_Leaves_Oak"
    },
    {
      "x": -8,
      "y": 27,
      "z": -3,
      "name": "Plant_Leaves_Oak"
    },
    {
      "x": -8,
      "y": 28,
      "z": -3,
      "name": "Plant_Leaves_Oak"
    },
    {
      "x": -8,
      "y": 29,
      "z": -3,
      "name": "Plant_Leaves_Oak"
    },
    {
      "x": -8,
      "y": 6,
      "z": -2,
      "name": "Rock_Stone"
    },
    {
      "x": -8,
      "y": 7,
      "z": -2,
      "name": "Rock_Stone"
    },
    {
      "x": -8,
      "y": 8,
      "z": -2,
      "name": "Rock_Stone"
    },
    {
      "x": -8,
      "y": 9,
      "z": -2,
      "name": "Rock_Stone"
    },
    {
      "x": -8,
      "y": 10,
      "z": -2,
      "name": "Rock_Stone"
    },
    {
      "x": -8,
      "y": 11,
      "z": -2,
      "name": "Rock_Stone"
    },
    {
      "x": -8,
      "y": 12,
      "z": -2,
      "name": "Rock_Stone"
    },
    {
      "x": -8,
      "y": 13,
      "z": -2,
      "name": "Rock_Stone"
    },
    {
      "x": -8,
      "y": 14,
      "z": -2,
      "name": "Rock_Stone"
    },
    {
      "x": -8,
      "y": 15,
      "z": -2,
      "name": "Rock_Stone"
    },
    {
      "x": -8,
      "y": 16,
      "z": -2,
      "name": "Rock_Stone"
    },
    {
      "x": -8,
      "y": 17,
      "z": -2,
      "name": "Rock_Stone"
    },
    {
      "x": -8,
      "y": 18,
      "z": -2,
      "name": "Rock_Stone"
    },
    {
      "x": -8,
      "y": 19,
      "z": -2,
      "name": "Rock_Stone"
    },
    {
      "x": -8,
      "y": 20,
      "z": -2,
      "name": "Rock_Stone"
    },
    {
      "x": -8,
      "y": 21,
      "z": -2,
      "name": "Rock_Stone"
    },
    {
      "x": -8,
      "y": 22,
      "z": -2,
      "name": "Rock_Stone"
    },
    {
      "x": -8,
      "y": 6,
      "z": -1,
      "name": "Rock_Stone"
    },
    {
      "x": -8,
      "y": 7,
      "z": -1,
      "name": "Rock_Stone"
    },
    {
      "x": -8,
      "y": 8,
      "z": -1,
      "name": "Rock_Stone"
    },
    {
      "x": -8,
      "y": 9,
      "z": -1,
      "name": "Rock_Stone"
    },
    {
      "x": -8,
      "y": 10,
      "z": -1,
      "name": "Rock_Stone"
    },
    {
      "x": -8,
      "y": 11,
      "z": -1,
      "name": "Rock_Stone"
    },
    {
      "x": -8,
      "y": 12,
      "z": -1,
      "name": "Rock_Stone"
    },
    {
      "x": -8,
      "y": 13,
      "z": -1,
      "name": "Rock_Stone"
    },
    {
      "x": -8,
      "y": 14,
      "z": -1,
      "name": "Rock_Stone"
    },
    {
      "x": -8,
      "y": 15,
      "z": -1,
      "name": "Rock_Stone"
    },
    {
      "x": -8,
      "y": 16,
      "z": -1,
      "name": "Rock_Stone"
    },
    {
      "x": -8,
      "y": 17,
      "z": -1,
      "name": "Rock_Stone"
    },
    {
      "x": -8,
      "y": 18,
      "z": -1,
      "name": "Rock_Stone"
    },
    {
      "x": -8,
      "y": 19,
      "z": -1,
      "name": "Rock_Stone"
    },
    {
      "x": -8,
      "y": 20,
      "z": -1,
      "name": "Rock_Stone"
    },
    {
      "x": -8,
      "y": 21,
      "z": -1,
      "name": "Rock_Stone"
    },
    {
      "x": -8,
      "y": 22,
      "z": -1,
      "name": "Rock_Stone"
    },
    {
      "x": -8,
      "y": 7,
      "z": 0,
      "name": "Rock_Stone"
    },
    {
      "x": -8,
      "y": 8,
      "z": 0,
      "name": "Rock_Stone"
    },
    {
      "x": -8,
      "y": 10,
      "z": 0,
      "name": "Rock_Stone"
    },
    {
      "x": -8,
      "y": 11,
      "z": 0,
      "name": "Rock_Stone"
    },
    {
      "x": -8,
      "y": 12,
      "z": 0,
      "name": "Rock_Stone"
    },
    {
      "x": -8,
      "y": 13,
      "z": 0,
      "name": "Rock_Stone"
    },
    {
      "x": -8,
      "y": 14,
      "z": 0,
      "name": "Rock_Stone"
    },
    {
      "x": -8,
      "y": 15,
      "z": 0,
      "name": "Rock_Stone"
    },
    {
      "x": -8,
      "y": 16,
      "z": 0,
      "name": "Rock_Stone"
    },
    {
      "x": -8,
      "y": 17,
      "z": 0,
      "name": "Rock_Stone"
    },
    {
      "x": -8,
      "y": 18,
      "z": 0,
      "name": "Rock_Stone"
    },
    {
      "x": -8,
      "y": 19,
      "z": 0,
      "name": "Rock_Stone"
    },
    {
      "x": -8,
      "y": 20,
      "z": 0,
      "name": "Rock_Stone"
    },
    {
      "x": -8,
      "y": 21,
      "z": 0,
      "name": "Rock_Stone"
    },
    {
      "x": -8,
      "y": 22,
      "z": 0,
      "name": "Rock_Stone"
    },
    {
      "x": -8,
      "y": 11,
      "z": 1,
      "name": "Empty"
    },
    {
      "x": -8,
      "y": 12,
      "z": 1,
      "name": "Empty"
    },
    {
      "x": -8,
      "y": 13,
      "z": 1,
      "name": "Rock_Stone"
    },
    {
      "x": -8,
      "y": 14,
      "z": 1,
      "name": "Rock_Stone"
    },
    {
      "x": -8,
      "y": 15,
      "z": 1,
      "name": "Rock_Stone"
    },
    {
      "x": -8,
      "y": 16,
      "z": 1,
      "name": "Rock_Stone"
    },
    {
      "x": -8,
      "y": 17,
      "z": 1,
      "name": "Rock_Stone"
    },
    {
      "x": -8,
      "y": 18,
      "z": 1,
      "name": "Rock_Stone"
    },
    {
      "x": -8,
      "y": 19,
      "z": 1,
      "name": "Rock_Stone"
    },
    {
      "x": -8,
      "y": 20,
      "z": 1,
      "name": "Rock_Stone"
    },
    {
      "x": -8,
      "y": 21,
      "z": 1,
      "name": "Rock_Stone"
    },
    {
      "x": -8,
      "y": 22,
      "z": 1,
      "name": "Rock_Stone"
    },
    {
      "x": -8,
      "y": 8,
      "z": 2,
      "name": "Rock_Stone"
    },
    {
      "x": -8,
      "y": 9,
      "z": 2,
      "name": "Soil_Dirt"
    },
    {
      "x": -8,
      "y": 10,
      "z": 2,
      "name": "Soil_Grass"
    },
    {
      "x": -8,
      "y": 11,
      "z": 2,
      "name": "Empty"
    },
    {
      "x": -8,
      "y": 12,
      "z": 2,
      "name": "Empty"
    },
    {
      "x": -8,
      "y": 13,
      "z": 2,
      "name": "Empty"
    },
    {
      "x": -8,
      "y": 14,
      "z": 2,
      "name": "Empty"
    },
    {
      "x": -8,
      "y": 15,
      "z": 2,
      "name": "Empty"
    },
    {
      "x": -8,
      "y": 16,
      "z": 2,
      "name": "Rock_Stone"
    },
    {
      "x": -8,
      "y": 17,
      "z": 2,
      "name": "Rock_Stone"
    },
    {
      "x": -8,
      "y": 18,
      "z": 2,
      "name": "Rock_Stone"
    },
    {
      "x": -8,
      "y": 19,
      "z": 2,
      "name": "Soil_Dirt"
    },
    {
      "x": -8,
      "y": 20,
      "z": 2,
      "name": "Soil_Grass"
    },
    {
      "x": -8,
      "y": 8,
      "z": 3,
      "name": "Rock_Stone"
    },
    {
      "x": -8,
      "y": 9,
      "z": 3,
      "name": "Soil_Dirt"
    },
    {
      "x": -8,
      "y": 10,
      "z": 3,
      "name": "Soil_Grass"
    },
    {
      "x": -8,
      "y": 11,
      "z": 3,
      "name": "Empty"
    },
    {
      "x": -8,
      "y": 12,
      "z": 3,
      "name": "Empty"
    },
    {
      "x": -8,
      "y": 13,
      "z": 3,
      "name": "Empty"
    },
    {
      "x": -8,
      "y": 14,
      "z": 3,
      "name": "Empty"
    },
    {
      "x": -8,
      "y": 15,
      "z": 3,
      "name": "Empty"
    },
    {
      "x": -8,
      "y": 16,
      "z": 3,
      "name": "Empty"
    },
    {
      "x": -8,
      "y": 17,
      "z": 3,
      "name": "Empty"
    },
    {
      "x": -8,
      "y": 18,
      "z": 3,
      "name": "Rock_Stone"
    },
    {
      "x": -8,
      "y": 19,
      "z": 3,
      "name": "Rock_Stone"
    },
    {
      "x": -8,
      "y": 20,
      "z": 3,
      "name": "Soil_Dirt"
    },
    {
      "x": -8,
      "y": 21,
      "z": 3,
      "name": "Soil_Grass"
    },
    {
      "x": -8,
      "y": 8,
      "z": 4,
      "name": "Rock_Stone"
    },
    {
      "x": -8,
      "y": 9,
      "z": 4,
      "name": "Soil_Dirt"
    },
    {
      "x": -8,
      "y": 10,
      "z": 4,
      "name": "Soil_Grass"
    },
    {
      "x": -8,
      "y": 11,
      "z": 4,
      "name": "Empty"
    },
    {
      "x": -8,
      "y": 12,
      "z": 4,
      "name": "Empty"
    },
    {
      "x": -8,
      "y": 13,
      "z": 4,
      "name": "Empty"
    },
    {
      "x": -8,
      "y": 14,
      "z": 4,
      "name": "Empty"
    },
    {
      "x": -8,
      "y": 15,
      "z": 4,
      "name": "Empty"
    },
    {
      "x": -8,
      "y": 16,
      "z": 4,
      "name": "Empty"
    },
    {
      "x": -8,
      "y": 17,
      "z": 4,
      "name": "Empty"
    },
    {
      "x": -8,
      "y": 19,
      "z": 4,
      "name": "Rock_Stone_Mossy"
    },
    {
      "x": -8,
      "y": 20,
      "z": 4,
      "name": "Soil_Dirt"
    },
    {
      "x": -8,
      "y": 21,
      "z": 4,
      "name": "Soil_Grass"
    },
    {
      "x": -8,
      "y": 8,
      "z": 5,
      "name": "Rock_Stone"
    },
    {
      "x": -8,
      "y": 9,
      "z": 5,
      "name": "Soil_Dirt"
    },
    {
      "x": -8,
      "y": 10,
      "z": 5,
      "name": "Soil_Grass"
    },
    {
      "x": -8,
      "y": 11,
      "z": 5,
      "name": "Plant_Grass_Sharp"
    },
    {
      "x": -8,
      "y": 12,
      "z": 5,
      "name": "Empty"
    },
    {
      "x": -8,
      "y": 13,
      "z": 5,
      "name": "Empty"
    },
    {
      "x": -8,
      "y": 14,
      "z": 5,
      "name": "Empty"
    },
    {
      "x": -8,
      "y": 15,
      "z": 5,
      "name": "Empty"
    },
    {
      "x": -8,
      "y": 16,
      "z": 5,
      "name": "Empty"
    },
    {
      "x": -8,
      "y": 17,
      "z": 5,
      "name": "Empty"
    },
    {
      "x": -8,
      "y": 19,
      "z": 5,
      "name": "Rock_Stone_Mossy"
    },
    {
      "x": -8,
      "y": 20,
      "z": 5,
      "name": "Soil_Dirt"
    },
    {
      "x": -8,
      "y": 21,
      "z": 5,
      "name": "Soil_Grass"
    },
    {
      "x": -8,
      "y": 8,
      "z": 6,
      "name": "Rock_Stone"
    },
    {
      "x": -8,
      "y": 9,
      "z": 6,
      "name": "Soil_Dirt"
    },
    {
      "x": -8,
      "y": 10,
      "z": 6,
      "name": "Soil_Grass"
    },
    {
      "x": -8,
      "y": 11,
      "z": 6,
      "name": "Plant_Grass_Sharp"
    },
    {
      "x": -8,
      "y": 12,
      "z": 6,
      "name": "Empty"
    },
    {
      "x": -8,
      "y": 13,
      "z": 6,
      "name": "Empty"
    },
    {
      "x": -8,
      "y": 14,
      "z": 6,
      "name": "Empty"
    },
    {
      "x": -8,
      "y": 15,
      "z": 6,
      "name": "Empty"
    },
    {
      "x": -8,
      "y": 16,
      "z": 6,
      "name": "Empty"
    },
    {
      "x": -8,
      "y": 17,
      "z": 6,
      "name": "Empty"
    },
    {
      "x": -8,
      "y": 18,
      "z": 6,
      "name": "Rock_Stone"
    },
    {
      "x": -8,
      "y": 19,
      "z": 6,
      "name": "Rock_Stone_Mossy"
    },
    {
      "x": -8,
      "y": 20,
      "z": 6,
      "name": "Soil_Dirt"
    },
    {
      "x": -8,
      "y": 21,
      "z": 6,
      "name": "Soil_Grass"
    },
    {
      "x": -8,
      "y": 7,
      "z": 7,
      "name": "Rock_Stone"
    },
    {
      "x": -8,
      "y": 8,
      "z": 7,
      "name": "Rock_Stone"
    },
    {
      "x": -8,
      "y": 9,
      "z": 7,
      "name": "Rock_Stone"
    },
    {
      "x": -8,
      "y": 10,
      "z": 7,
      "name": "Rock_Stone"
    },
    {
      "x": -8,
      "y": 11,
      "z": 7,
      "name": "Rock_Stone_Mossy"
    },
    {
      "x": -8,
      "y": 12,
      "z": 7,
      "name": "Plant_Moss_Rug_Green"
    },
    {
      "x": -8,
      "y": 13,
      "z": 7,
      "name": "Empty"
    },
    {
      "x": -8,
      "y": 14,
      "z": 7,
      "name": "Empty"
    },
    {
      "x": -8,
      "y": 15,
      "z": 7,
      "name": "Empty"
    },
    {
      "x": -8,
      "y": 16,
      "z": 7,
      "name": "Rock_Stone"
    },
    {
      "x": -8,
      "y": 17,
      "z": 7,
      "name": "Rock_Stone"
    },
    {
      "x": -8,
      "y": 18,
      "z": 7,
      "name": "Rock_Stone"
    },
    {
      "x": -8,
      "y": 19,
      "z": 7,
      "name": "Rock_Stone"
    },
    {
      "x": -8,
      "y": 20,
      "z": 7,
      "name": "Soil_Dirt"
    },
    {
      "x": -8,
      "y": 21,
      "z": 7,
      "name": "Soil_Grass"
    },
    {
      "x": -8,
      "y": 7,
      "z": 8,
      "name": "Rock_Stone"
    },
    {
      "x": -8,
      "y": 8,
      "z": 8,
      "name": "Rock_Stone"
    },
    {
      "x": -8,
      "y": 9,
      "z": 8,
      "name": "Rock_Stone"
    },
    {
      "x": -8,
      "y": 10,
      "z": 8,
      "name": "Rock_Stone"
    },
    {
      "x": -8,
      "y": 11,
      "z": 8,
      "name": "Rock_Stone"
    },
    {
      "x": -8,
      "y": 12,
      "z": 8,
      "name": "Rock_Stone"
    },
    {
      "x": -8,
      "y": 13,
      "z": 8,
      "name": "Rock_Stone"
    },
    {
      "x": -8,
      "y": 14,
      "z": 8,
      "name": "Rock_Stone"
    },
    {
      "x": -8,
      "y": 15,
      "z": 8,
      "name": "Rock_Stone"
    },
    {
      "x": -8,
      "y": 16,
      "z": 8,
      "name": "Rock_Stone"
    },
    {
      "x": -8,
      "y": 17,
      "z": 8,
      "name": "Rock_Stone"
    },
    {
      "x": -8,
      "y": 18,
      "z": 8,
      "name": "Rock_Stone"
    },
    {
      "x": -8,
      "y": 19,
      "z": 8,
      "name": "Rock_Stone"
    },
    {
      "x": -8,
      "y": 20,
      "z": 8,
      "name": "Soil_Dirt"
    },
    {
      "x": -8,
      "y": 21,
      "z": 8,
      "name": "Soil_Grass"
    },
    {
      "x": -8,
      "y": 7,
      "z": 9,
      "name": "Rock_Stone"
    },
    {
      "x": -8,
      "y": 8,
      "z": 9,
      "name": "Rock_Stone"
    },
    {
      "x": -8,
      "y": 9,
      "z": 9,
      "name": "Rock_Stone"
    },
    {
      "x": -8,
      "y": 10,
      "z": 9,
      "name": "Rock_Stone"
    },
    {
      "x": -8,
      "y": 11,
      "z": 9,
      "name": "Rock_Stone"
    },
    {
      "x": -8,
      "y": 12,
      "z": 9,
      "name": "Rock_Stone"
    },
    {
      "x": -8,
      "y": 13,
      "z": 9,
      "name": "Rock_Stone"
    },
    {
      "x": -8,
      "y": 14,
      "z": 9,
      "name": "Rock_Stone"
    },
    {
      "x": -8,
      "y": 15,
      "z": 9,
      "name": "Rock_Stone"
    },
    {
      "x": -8,
      "y": 16,
      "z": 9,
      "name": "Rock_Stone"
    },
    {
      "x": -8,
      "y": 17,
      "z": 9,
      "name": "Rock_Stone_Mossy"
    },
    {
      "x": -8,
      "y": 18,
      "z": 9,
      "name": "Rock_Stone"
    },
    {
      "x": -8,
      "y": 19,
      "z": 9,
      "name": "Soil_Dirt"
    },
    {
      "x": -8,
      "y": 20,
      "z": 9,
      "name": "Soil_Grass"
    },
    {
      "x": -8,
      "y": 7,
      "z": 10,
      "name": "Rock_Stone"
    },
    {
      "x": -8,
      "y": 8,
      "z": 10,
      "name": "Rock_Stone"
    },
    {
      "x": -8,
      "y": 9,
      "z": 10,
      "name": "Rock_Stone"
    },
    {
      "x": -8,
      "y": 10,
      "z": 10,
      "name": "Rock_Stone"
    },
    {
      "x": -8,
      "y": 11,
      "z": 10,
      "name": "Rock_Stone"
    },
    {
      "x": -8,
      "y": 12,
      "z": 10,
      "name": "Rock_Stone"
    },
    {
      "x": -8,
      "y": 13,
      "z": 10,
      "name": "Rock_Stone"
    },
    {
      "x": -8,
      "y": 14,
      "z": 10,
      "name": "Rock_Stone"
    },
    {
      "x": -8,
      "y": 15,
      "z": 10,
      "name": "Rock_Stone"
    },
    {
      "x": -8,
      "y": 16,
      "z": 10,
      "name": "Rock_Stone_Mossy"
    },
    {
      "x": -8,
      "y": 17,
      "z": 10,
      "name": "Rock_Stone_Mossy"
    },
    {
      "x": -8,
      "y": 18,
      "z": 10,
      "name": "Rock_Stone_Mossy"
    },
    {
      "x": -8,
      "y": 19,
      "z": 10,
      "name": "Soil_Dirt"
    },
    {
      "x": -8,
      "y": 20,
      "z": 10,
      "name": "Soil_Grass"
    },
    {
      "x": -8,
      "y": 10,
      "z": 11,
      "name": "Rock_Stone"
    },
    {
      "x": -8,
      "y": 11,
      "z": 11,
      "name": "Rock_Stone"
    },
    {
      "x": -8,
      "y": 12,
      "z": 11,
      "name": "Empty"
    },
    {
      "x": -8,
      "y": 13,
      "z": 11,
      "name": "Empty"
    },
    {
      "x": -8,
      "y": 14,
      "z": 11,
      "name": "Empty"
    },
    {
      "x": -8,
      "y": 15,
      "z": 11,
      "name": "Empty"
    },
    {
      "x": -8,
      "y": 16,
      "z": 11,
      "name": "Empty"
    },
    {
      "x": -8,
      "y": 17,
      "z": 11,
      "name": "Rock_Stone_Mossy"
    },
    {
      "x": -8,
      "y": 18,
      "z": 11,
      "name": "Rock_Stone"
    },
    {
      "x": -8,
      "y": 19,
      "z": 11,
      "name": "Soil_Dirt"
    },
    {
      "x": -8,
      "y": 20,
      "z": 11,
      "name": "Soil_Grass"
    },
    {
      "x": -8,
      "y": 11,
      "z": 12,
      "name": "Empty"
    },
    {
      "x": -8,
      "y": 12,
      "z": 12,
      "name": "Empty"
    },
    {
      "x": -8,
      "y": 13,
      "z": 12,
      "name": "Empty"
    },
    {
      "x": -8,
      "y": 14,
      "z": 12,
      "name": "Empty"
    },
    {
      "x": -8,
      "y": 15,
      "z": 12,
      "name": "Empty"
    },
    {
      "x": -8,
      "y": 16,
      "z": 12,
      "name": "Empty"
    },
    {
      "x": -8,
      "y": 17,
      "z": 12,
      "name": "Empty"
    },
    {
      "x": -8,
      "y": 18,
      "z": 12,
      "name": "Soil_Dirt"
    },
    {
      "x": -8,
      "y": 19,
      "z": 12,
      "name": "Soil_Grass"
    },
    {
      "x": -7,
      "y": 27,
      "z": -19,
      "name": "Plant_Leaves_Oak"
    },
    {
      "x": -7,
      "y": 28,
      "z": -19,
      "name": "Plant_Leaves_Oak"
    },
    {
      "x": -7,
      "y": 29,
      "z": -19,
      "name": "Plant_Leaves_Oak"
    },
    {
      "x": -7,
      "y": 27,
      "z": -18,
      "name": "Plant_Leaves_Oak"
    },
    {
      "x": -7,
      "y": 28,
      "z": -18,
      "name": "Wood_Oak_Branch_Long",
      "rotation": 4
    },
    {
      "x": -7,
      "y": 29,
      "z": -18,
      "name": "Plant_Leaves_Oak"
    },
    {
      "x": -7,
      "y": 28,
      "z": -17,
      "name": "Wood_Oak_Branch_Long",
      "rotation": 4
    },
    {
      "x": -7,
      "y": 30,
      "z": -17,
      "name": "Plant_Leaves_Oak"
    },
    {
      "x": -7,
      "y": 31,
      "z": -17,
      "name": "Plant_Leaves_Oak"
    },
    {
      "x": -7,
      "y": 32,
      "z": -17,
      "name": "Plant_Leaves_Oak"
    },
    {
      "x": -7,
      "y": 33,
      "z": -17,
      "name": "Plant_Leaves_Oak"
    },
    {
      "x": -7,
      "y": 12,
      "z": -16,
      "name": "Rock_Stone"
    },
    {
      "x": -7,
      "y": 13,
      "z": -16,
      "name": "Soil_Dirt"
    },
    {
      "x": -7,
      "y": 14,
      "z": -16,
      "name": "Soil_Grass"
    },
    {
      "x": -7,
      "y": 27,
      "z": -16,
      "name": "Wood_Oak_Trunk_Full"
    },
    {
      "x": -7,
      "y": 28,
      "z": -16,
      "name": "Wood_Oak_Trunk_Full"
    },
    {
      "x": -7,
      "y": 31,
      "z": -16,
      "name": "Wood_Oak_Branch_Long",
      "rotation": 4
    },
    {
      "x": -7,
      "y": 32,
      "z": -16,
      "name": "Plant_Leaves_Oak"
    },
    {
      "x": -7,
      "y": 33,
      "z": -16,
      "name": "Plant_Leaves_Oak"
    },
    {
      "x": -7,
      "y": 10,
      "z": -15,
      "name": "Rock_Stone"
    },
    {
      "x": -7,
      "y": 11,
      "z": -15,
      "name": "Rock_Stone"
    },
    {
      "x": -7,
      "y": 12,
      "z": -15,
      "name": "Rock_Stone"
    },
    {
      "x": -7,
      "y": 13,
      "z": -15,
      "name": "Rock_Stone"
    },
    {
      "x": -7,
      "y": 14,
      "z": -15,
      "name": "Rock_Stone"
    },
    {
      "x": -7,
      "y": 15,
      "z": -15,
      "name": "Soil_Dirt"
    },
    {
      "x": -7,
      "y": 16,
      "z": -15,
      "name": "Soil_Grass"
    },
    {
      "x": -7,
      "y": 31,
      "z": -15,
      "name": "Wood_Oak_Trunk_Full"
    },
    {
      "x": -7,
      "y": 32,
      "z": -15,
      "name": "Plant_Leaves_Oak"
    },
    {
      "x": -7,
      "y": 33,
      "z": -15,
      "name": "Plant_Leaves_Oak"
    },
    {
      "x": -7,
      "y": 10,
      "z": -14,
      "name": "Rock_Stone"
    },
    {
      "x": -7,
      "y": 11,
      "z": -14,
      "name": "Rock_Stone"
    },
    {
      "x": -7,
      "y": 12,
      "z": -14,
      "name": "Rock_Stone_Mossy"
    },
    {
      "x": -7,
      "y": 13,
      "z": -14,
      "name": "Rock_Stone"
    },
    {
      "x": -7,
      "y": 14,
      "z": -14,
      "name": "Rock_Stone"
    },
    {
      "x": -7,
      "y": 15,
      "z": -14,
      "name": "Soil_Dirt"
    },
    {
      "x": -7,
      "y": 16,
      "z": -14,
      "name": "Soil_Grass"
    },
    {
      "x": -7,
      "y": 27,
      "z": -14,
      "name": "Wood_Oak_Trunk_Full"
    },
    {
      "x": -7,
      "y": 30,
      "z": -14,
      "name": "Wood_Oak_Trunk_Full"
    },
    {
      "x": -7,
      "y": 31,
      "z": -14,
      "name": "Wood_Oak_Trunk_Full"
    },
    {
      "x": -7,
      "y": 34,
      "z": -14,
      "name": "Plant_Leaves_Oak"
    },
    {
      "x": -7,
      "y": 11,
      "z": -13,
      "name": "Empty"
    },
    {
      "x": -7,
      "y": 12,
      "z": -13,
      "name": "Rock_Stone_Mossy"
    },
    {
      "x": -7,
      "y": 13,
      "z": -13,
      "name": "Rock_Stone_Mossy"
    },
    {
      "x": -7,
      "y": 14,
      "z": -13,
      "name": "Rock_Stone"
    },
    {
      "x": -7,
      "y": 15,
      "z": -13,
      "name": "Soil_Dirt"
    },
    {
      "x": -7,
      "y": 16,
      "z": -13,
      "name": "Soil_Grass"
    },
    {
      "x": -7,
      "y": 33,
      "z": -13,
      "name": "Plant_Leaves_Oak"
    },
    {
      "x": -7,
      "y": 34,
      "z": -13,
      "name": "Plant_Leaves_Oak"
    },
    {
      "x": -7,
      "y": 11,
      "z": -12,
      "name": "Empty"
    },
    {
      "x": -7,
      "y": 12,
      "z": -12,
      "name": "Plant_Roots_Cave_Small",
      "rotation": 8
    },
    {
      "x": -7,
      "y": 13,
      "z": -12,
      "name": "Rock_Stone_Mossy"
    },
    {
      "x": -7,
      "y": 14,
      "z": -12,
      "name": "Rock_Stone_Mossy"
    },
    {
      "x": -7,
      "y": 15,
      "z": -12,
      "name": "Rock_Stone"
    },
    {
      "x": -7,
      "y": 16,
      "z": -12,
      "name": "Soil_Dirt"
    },
    {
      "x": -7,
      "y": 17,
      "z": -12,
      "name": "Soil_Grass"
    },
    {
      "x": -7,
      "y": 11,
      "z": -11,
      "name": "Empty"
    },
    {
      "x": -7,
      "y": 12,
      "z": -11,
      "name": "Empty"
    },
    {
      "x": -7,
      "y": 13,
      "z": -11,
      "name": "Rock_Stone_Mossy"
    },
    {
      "x": -7,
      "y": 14,
      "z": -11,
      "name": "Rock_Stone"
    },
    {
      "x": -7,
      "y": 15,
      "z": -11,
      "name": "Rock_Stone"
    },
    {
      "x": -7,
      "y": 16,
      "z": -11,
      "name": "Soil_Dirt"
    },
    {
      "x": -7,
      "y": 17,
      "z": -11,
      "name": "Soil_Grass"
    },
    {
      "x": -7,
      "y": 34,
      "z": -11,
      "name": "Plant_Leaves_Oak"
    },
    {
      "x": -7,
      "y": 11,
      "z": -10,
      "name": "Empty"
    },
    {
      "x": -7,
      "y": 12,
      "z": -10,
      "name": "Empty"
    },
    {
      "x": -7,
      "y": 13,
      "z": -10,
      "name": "Rock_Stone"
    },
    {
      "x": -7,
      "y": 14,
      "z": -10,
      "name": "Rock_Stone"
    },
    {
      "x": -7,
      "y": 15,
      "z": -10,
      "name": "Rock_Stone"
    },
    {
      "x": -7,
      "y": 16,
      "z": -10,
      "name": "Soil_Dirt"
    },
    {
      "x": -7,
      "y": 17,
      "z": -10,
      "name": "Soil_Grass"
    },
    {
      "x": -7,
      "y": 30,
      "z": -10,
      "name": "Wood_Oak_Trunk_Full"
    },
    {
      "x": -7,
      "y": 34,
      "z": -10,
      "name": "Plant_Leaves_Oak"
    },
    {
      "x": -7,
      "y": 10,
      "z": -9,
      "name": "Rock_Stone_Mossy"
    },
    {
      "x": -7,
      "y": 11,
      "z": -9,
      "name": "Rock_Stone_Mossy"
    },
    {
      "x": -7,
      "y": 12,
      "z": -9,
      "name": "Rock_Stone_Mossy"
    },
    {
      "x": -7,
      "y": 13,
      "z": -9,
      "name": "Rock_Stone"
    },
    {
      "x": -7,
      "y": 14,
      "z": -9,
      "name": "Rock_Stone"
    },
    {
      "x": -7,
      "y": 15,
      "z": -9,
      "name": "Rock_Stone"
    },
    {
      "x": -7,
      "y": 16,
      "z": -9,
      "name": "Soil_Dirt"
    },
    {
      "x": -7,
      "y": 17,
      "z": -9,
      "name": "Soil_Grass"
    },
    {
      "x": -7,
      "y": 34,
      "z": -9,
      "name": "Plant_Leaves_Oak"
    },
    {
      "x": -7,
      "y": 35,
      "z": -9,
      "name": "Plant_Leaves_Oak"
    },
    {
      "x": -7,
      "y": 6,
      "z": -8,
      "name": "Rock_Stone"
    },
    {
      "x": -7,
      "y": 7,
      "z": -8,
      "name": "Rock_Stone"
    },
    {
      "x": -7,
      "y": 8,
      "z": -8,
      "name": "Rock_Stone"
    },
    {
      "x": -7,
      "y": 9,
      "z": -8,
      "name": "Rock_Stone"
    },
    {
      "x": -7,
      "y": 10,
      "z": -8,
      "name": "Rock_Stone"
    },
    {
      "x": -7,
      "y": 11,
      "z": -8,
      "name": "Rock_Stone_Mossy"
    },
    {
      "x": -7,
      "y": 12,
      "z": -8,
      "name": "Rock_Stone"
    },
    {
      "x": -7,
      "y": 13,
      "z": -8,
      "name": "Rock_Stone"
    },
    {
      "x": -7,
      "y": 14,
      "z": -8,
      "name": "Rock_Stone"
    },
    {
      "x": -7,
      "y": 15,
      "z": -8,
      "name": "Soil_Grass"
    },
    {
      "x": -7,
      "y": 16,
      "z": -8,
      "name": "Plant_Grass_Sharp"
    },
    {
      "x": -7,
      "y": 31,
      "z": -8,
      "name": "Wood_Oak_Trunk_Full"
    },
    {
      "x": -7,
      "y": 32,
      "z": -8,
      "name": "Plant_Leaves_Oak"
    },
    {
      "x": -7,
      "y": 36,
      "z": -8,
      "name": "Plant_Leaves_Oak"
    },
    {
      "x": -7,
      "y": 5,
      "z": -7,
      "name": "Rock_Stone"
    },
    {
      "x": -7,
      "y": 6,
      "z": -7,
      "name": "Rock_Stone"
    },
    {
      "x": -7,
      "y": 7,
      "z": -7,
      "name": "Rock_Stone"
    },
    {
      "x": -7,
      "y": 8,
      "z": -7,
      "name": "Rock_Stone"
    },
    {
      "x": -7,
      "y": 9,
      "z": -7,
      "name": "Rock_Stone"
    },
    {
      "x": -7,
      "y": 10,
      "z": -7,
      "name": "Rock_Stone"
    },
    {
      "x": -7,
      "y": 11,
      "z": -7,
      "name": "Rock_Stone"
    },
    {
      "x": -7,
      "y": 12,
      "z": -7,
      "name": "Rock_Stone"
    },
    {
      "x": -7,
      "y": 13,
      "z": -7,
      "name": "Rock_Stone"
    },
    {
      "x": -7,
      "y": 14,
      "z": -7,
      "name": "Rock_Stone"
    },
    {
      "x": -7,
      "y": 15,
      "z": -7,
      "name": "Soil_Grass"
    },
    {
      "x": -7,
      "y": 18,
      "z": -7,
      "name": "Rock_Stone_Mossy"
    },
    {
      "x": -7,
      "y": 19,
      "z": -7,
      "name": "Rock_Stone_Mossy"
    },
    {
      "x": -7,
      "y": 20,
      "z": -7,
      "name": "Rock_Stone_Mossy"
    },
    {
      "x": -7,
      "y": 21,
      "z": -7,
      "name": "Rock_Stone"
    },
    {
      "x": -7,
      "y": 31,
      "z": -7,
      "name": "Wood_Oak_Branch_Long",
      "rotation": 4
    },
    {
      "x": -7,
      "y": 33,
      "z": -7,
      "name": "Plant_Leaves_Oak"
    },
    {
      "x": -7,
      "y": 34,
      "z": -7,
      "name": "Wood_Oak_Trunk_Full"
    },
    {
      "x": -7,
      "y": 35,
      "z": -7,
      "name": "Plant_Leaves_Oak"
    },
    {
      "x": -7,
      "y": 36,
      "z": -7,
      "name": "Plant_Leaves_Oak"
    },
    {
      "x": -7,
      "y": 5,
      "z": -6,
      "name": "Rock_Stone"
    },
    {
      "x": -7,
      "y": 6,
      "z": -6,
      "name": "Rock_Stone"
    },
    {
      "x": -7,
      "y": 7,
      "z": -6,
      "name": "Rock_Stone"
    },
    {
      "x": -7,
      "y": 8,
      "z": -6,
      "name": "Rock_Stone"
    },
    {
      "x": -7,
      "y": 9,
      "z": -6,
      "name": "Rock_Stone"
    },
    {
      "x": -7,
      "y": 10,
      "z": -6,
      "name": "Rock_Stone"
    },
    {
      "x": -7,
      "y": 11,
      "z": -6,
      "name": "Rock_Stone"
    },
    {
      "x": -7,
      "y": 12,
      "z": -6,
      "name": "Rock_Stone"
    },
    {
      "x": -7,
      "y": 13,
      "z": -6,
      "name": "Rock_Stone"
    },
    {
      "x": -7,
      "y": 14,
      "z": -6,
      "name": "Rock_Stone"
    },
    {
      "x": -7,
      "y": 15,
      "z": -6,
      "name": "Soil_Grass"
    },
    {
      "x": -7,
      "y": 18,
      "z": -6,
      "name": "Rock_Stone_Mossy"
    },
    {
      "x": -7,
      "y": 19,
      "z": -6,
      "name": "Rock_Stone_Mossy"
    },
    {
      "x": -7,
      "y": 20,
      "z": -6,
      "name": "Rock_Stone"
    },
    {
      "x": -7,
      "y": 21,
      "z": -6,
      "name": "Rock_Stone"
    },
    {
      "x": -7,
      "y": 22,
      "z": -6,
      "name": "Rock_Stone"
    },
    {
      "x": -7,
      "y": 30,
      "z": -6,
      "name": "Plant_Leaves_Oak"
    },
    {
      "x": -7,
      "y": 31,
      "z": -6,
      "name": "Plant_Leaves_Oak"
    },
    {
      "x": -7,
      "y": 32,
      "z": -6,
      "name": "Plant_Leaves_Oak"
    },
    {
      "x": -7,
      "y": 35,
      "z": -6,
      "name": "Plant_Leaves_Oak"
    },
    {
      "x": -7,
      "y": 5,
      "z": -5,
      "name": "Rock_Stone"
    },
    {
      "x": -7,
      "y": 6,
      "z": -5,
      "name": "Rock_Stone"
    },
    {
      "x": -7,
      "y": 7,
      "z": -5,
      "name": "Rock_Stone"
    },
    {
      "x": -7,
      "y": 8,
      "z": -5,
      "name": "Rock_Stone"
    },
    {
      "x": -7,
      "y": 9,
      "z": -5,
      "name": "Rock_Stone"
    },
    {
      "x": -7,
      "y": 10,
      "z": -5,
      "name": "Rock_Stone"
    },
    {
      "x": -7,
      "y": 11,
      "z": -5,
      "name": "Rock_Stone"
    },
    {
      "x": -7,
      "y": 12,
      "z": -5,
      "name": "Rock_Stone"
    },
    {
      "x": -7,
      "y": 13,
      "z": -5,
      "name": "Rock_Stone"
    },
    {
      "x": -7,
      "y": 14,
      "z": -5,
      "name": "Rock_Stone"
    },
    {
      "x": -7,
      "y": 15,
      "z": -5,
      "name": "Rock_Stone"
    },
    {
      "x": -7,
      "y": 16,
      "z": -5,
      "name": "Rock_Stone"
    },
    {
      "x": -7,
      "y": 17,
      "z": -5,
      "name": "Rock_Stone"
    },
    {
      "x": -7,
      "y": 18,
      "z": -5,
      "name": "Rock_Stone"
    },
    {
      "x": -7,
      "y": 19,
      "z": -5,
      "name": "Rock_Stone"
    },
    {
      "x": -7,
      "y": 20,
      "z": -5,
      "name": "Rock_Stone"
    },
    {
      "x": -7,
      "y": 21,
      "z": -5,
      "name": "Rock_Stone"
    },
    {
      "x": -7,
      "y": 22,
      "z": -5,
      "name": "Rock_Stone"
    },
    {
      "x": -7,
      "y": 34,
      "z": -5,
      "name": "Plant_Leaves_Oak"
    },
    {
      "x": -7,
      "y": 35,
      "z": -5,
      "name": "Plant_Leaves_Oak"
    },
    {
      "x": -7,
      "y": 5,
      "z": -4,
      "name": "Rock_Stone"
    },
    {
      "x": -7,
      "y": 6,
      "z": -4,
      "name": "Rock_Stone"
    },
    {
      "x": -7,
      "y": 7,
      "z": -4,
      "name": "Rock_Stone"
    },
    {
      "x": -7,
      "y": 8,
      "z": -4,
      "name": "Rock_Stone"
    },
    {
      "x": -7,
      "y": 9,
      "z": -4,
      "name": "Rock_Stone"
    },
    {
      "x": -7,
      "y": 10,
      "z": -4,
      "name": "Rock_Stone"
    },
    {
      "x": -7,
      "y": 11,
      "z": -4,
      "name": "Rock_Stone"
    },
    {
      "x": -7,
      "y": 12,
      "z": -4,
      "name": "Rock_Stone"
    },
    {
      "x": -7,
      "y": 13,
      "z": -4,
      "name": "Soil_Dirt"
    },
    {
      "x": -7,
      "y": 14,
      "z": -4,
      "name": "Soil_Grass"
    },
    {
      "x": -7,
      "y": 16,
      "z": -4,
      "name": "Rock_Stone"
    },
    {
      "x": -7,
      "y": 17,
      "z": -4,
      "name": "Rock_Stone"
    },
    {
      "x": -7,
      "y": 18,
      "z": -4,
      "name": "Rock_Stone"
    },
    {
      "x": -7,
      "y": 19,
      "z": -4,
      "name": "Rock_Stone"
    },
    {
      "x": -7,
      "y": 20,
      "z": -4,
      "name": "Rock_Stone"
    },
    {
      "x": -7,
      "y": 21,
      "z": -4,
      "name": "Rock_Stone"
    },
    {
      "x": -7,
      "y": 22,
      "z": -4,
      "name": "Rock_Stone"
    },
    {
      "x": -7,
      "y": 30,
      "z": -4,
      "name": "Plant_Leaves_Oak"
    },
    {
      "x": -7,
      "y": 32,
      "z": -4,
      "name": "Plant_Leaves_Oak"
    },
    {
      "x": -7,
      "y": 33,
      "z": -4,
      "name": "Plant_Leaves_Oak"
    },
    {
      "x": -7,
      "y": 34,
      "z": -4,
      "name": "Plant_Leaves_Oak"
    },
    {
      "x": -7,
      "y": 5,
      "z": -3,
      "name": "Rock_Stone"
    },
    {
      "x": -7,
      "y": 6,
      "z": -3,
      "name": "Rock_Stone"
    },
    {
      "x": -7,
      "y": 7,
      "z": -3,
      "name": "Rock_Stone"
    },
    {
      "x": -7,
      "y": 8,
      "z": -3,
      "name": "Rock_Stone"
    },
    {
      "x": -7,
      "y": 9,
      "z": -3,
      "name": "Rock_Stone"
    },
    {
      "x": -7,
      "y": 10,
      "z": -3,
      "name": "Rock_Stone"
    },
    {
      "x": -7,
      "y": 11,
      "z": -3,
      "name": "Rock_Stone"
    },
    {
      "x": -7,
      "y": 12,
      "z": -3,
      "name": "Rock_Stone"
    },
    {
      "x": -7,
      "y": 13,
      "z": -3,
      "name": "Rock_Stone"
    },
    {
      "x": -7,
      "y": 14,
      "z": -3,
      "name": "Rock_Stone"
    },
    {
      "x": -7,
      "y": 15,
      "z": -3,
      "name": "Rock_Stone"
    },
    {
      "x": -7,
      "y": 16,
      "z": -3,
      "name": "Rock_Stone"
    },
    {
      "x": -7,
      "y": 17,
      "z": -3,
      "name": "Rock_Stone"
    },
    {
      "x": -7,
      "y": 18,
      "z": -3,
      "name": "Rock_Stone"
    },
    {
      "x": -7,
      "y": 19,
      "z": -3,
      "name": "Rock_Stone"
    },
    {
      "x": -7,
      "y": 20,
      "z": -3,
      "name": "Rock_Stone"
    },
    {
      "x": -7,
      "y": 21,
      "z": -3,
      "name": "Rock_Stone"
    },
    {
      "x": -7,
      "y": 22,
      "z": -3,
      "name": "Rock_Stone"
    },
    {
      "x": -7,
      "y": 26,
      "z": -3,
      "name": "Plant_Leaves_Oak"
    },
    {
      "x": -7,
      "y": 27,
      "z": -3,
      "name": "Plant_Leaves_Oak"
    },
    {
      "x": -7,
      "y": 29,
      "z": -3,
      "name": "Plant_Leaves_Oak"
    },
    {
      "x": -7,
      "y": 5,
      "z": -2,
      "name": "Rock_Stone"
    },
    {
      "x": -7,
      "y": 6,
      "z": -2,
      "name": "Rock_Stone"
    },
    {
      "x": -7,
      "y": 7,
      "z": -2,
      "name": "Rock_Stone"
    },
    {
      "x": -7,
      "y": 8,
      "z": -2,
      "name": "Rock_Stone"
    },
    {
      "x": -7,
      "y": 9,
      "z": -2,
      "name": "Rock_Stone"
    },
    {
      "x": -7,
      "y": 10,
      "z": -2,
      "name": "Rock_Stone"
    },
    {
      "x": -7,
      "y": 11,
      "z": -2,
      "name": "Rock_Stone"
    },
    {
      "x": -7,
      "y": 12,
      "z": -2,
      "name": "Rock_Stone"
    },
    {
      "x": -7,
      "y": 13,
      "z": -2,
      "name": "Rock_Stone"
    },
    {
      "x": -7,
      "y": 14,
      "z": -2,
      "name": "Rock_Stone"
    },
    {
      "x": -7,
      "y": 15,
      "z": -2,
      "name": "Rock_Stone"
    },
    {
      "x": -7,
      "y": 16,
      "z": -2,
      "name": "Rock_Stone"
    },
    {
      "x": -7,
      "y": 17,
      "z": -2,
      "name": "Rock_Stone"
    },
    {
      "x": -7,
      "y": 18,
      "z": -2,
      "name": "Rock_Stone"
    },
    {
      "x": -7,
      "y": 19,
      "z": -2,
      "name": "Rock_Stone"
    },
    {
      "x": -7,
      "y": 20,
      "z": -2,
      "name": "Rock_Stone"
    },
    {
      "x": -7,
      "y": 21,
      "z": -2,
      "name": "Rock_Stone"
    },
    {
      "x": -7,
      "y": 22,
      "z": -2,
      "name": "Rock_Stone"
    },
    {
      "x": -7,
      "y": 27,
      "z": -2,
      "name": "Plant_Leaves_Oak"
    },
    {
      "x": -7,
      "y": 28,
      "z": -2,
      "name": "Plant_Leaves_Oak"
    },
    {
      "x": -7,
      "y": 4,
      "z": -1,
      "name": "Rock_Stone"
    },
    {
      "x": -7,
      "y": 5,
      "z": -1,
      "name": "Rock_Stone"
    },
    {
      "x": -7,
      "y": 6,
      "z": -1,
      "name": "Rock_Stone"
    },
    {
      "x": -7,
      "y": 7,
      "z": -1,
      "name": "Rock_Stone"
    },
    {
      "x": -7,
      "y": 8,
      "z": -1,
      "name": "Rock_Stone"
    },
    {
      "x": -7,
      "y": 9,
      "z": -1,
      "name": "Rock_Stone"
    },
    {
      "x": -7,
      "y": 10,
      "z": -1,
      "name": "Rock_Stone"
    },
    {
      "x": -7,
      "y": 11,
      "z": -1,
      "name": "Rock_Stone"
    },
    {
      "x": -7,
      "y": 12,
      "z": -1,
      "name": "Rock_Stone"
    },
    {
      "x": -7,
      "y": 13,
      "z": -1,
      "name": "Rock_Stone"
    },
    {
      "x": -7,
      "y": 14,
      "z": -1,
      "name": "Rock_Stone"
    },
    {
      "x": -7,
      "y": 15,
      "z": -1,
      "name": "Rock_Stone"
    },
    {
      "x": -7,
      "y": 16,
      "z": -1,
      "name": "Rock_Stone"
    },
    {
      "x": -7,
      "y": 17,
      "z": -1,
      "name": "Rock_Stone"
    },
    {
      "x": -7,
      "y": 18,
      "z": -1,
      "name": "Rock_Stone"
    },
    {
      "x": -7,
      "y": 19,
      "z": -1,
      "name": "Rock_Stone"
    },
    {
      "x": -7,
      "y": 20,
      "z": -1,
      "name": "Rock_Stone"
    },
    {
      "x": -7,
      "y": 21,
      "z": -1,
      "name": "Rock_Stone"
    },
    {
      "x": -7,
      "y": 22,
      "z": -1,
      "name": "Rock_Stone"
    },
    {
      "x": -7,
      "y": 4,
      "z": 0,
      "name": "Rock_Stone"
    },
    {
      "x": -7,
      "y": 5,
      "z": 0,
      "name": "Rock_Stone"
    },
    {
      "x": -7,
      "y": 6,
      "z": 0,
      "name": "Rock_Stone"
    },
    {
      "x": -7,
      "y": 7,
      "z": 0,
      "name": "Rock_Stone"
    },
    {
      "x": -7,
      "y": 8,
      "z": 0,
      "name": "Rock_Stone"
    },
    {
      "x": -7,
      "y": 9,
      "z": 0,
      "name": "Rock_Stone"
    },
    {
      "x": -7,
      "y": 10,
      "z": 0,
      "name": "Rock_Stone"
    },
    {
      "x": -7,
      "y": 11,
      "z": 0,
      "name": "Rock_Stone"
    },
    {
      "x": -7,
      "y": 12,
      "z": 0,
      "name": "Rock_Stone"
    },
    {
      "x": -7,
      "y": 13,
      "z": 0,
      "name": "Rock_Stone"
    },
    {
      "x": -7,
      "y": 14,
      "z": 0,
      "name": "Rock_Stone"
    },
    {
      "x": -7,
      "y": 15,
      "z": 0,
      "name": "Rock_Stone"
    },
    {
      "x": -7,
      "y": 16,
      "z": 0,
      "name": "Rock_Stone"
    },
    {
      "x": -7,
      "y": 17,
      "z": 0,
      "name": "Rock_Stone"
    },
    {
      "x": -7,
      "y": 18,
      "z": 0,
      "name": "Rock_Stone"
    },
    {
      "x": -7,
      "y": 19,
      "z": 0,
      "name": "Rock_Stone"
    },
    {
      "x": -7,
      "y": 20,
      "z": 0,
      "name": "Rock_Stone"
    },
    {
      "x": -7,
      "y": 21,
      "z": 0,
      "name": "Rock_Stone"
    },
    {
      "x": -7,
      "y": 22,
      "z": 0,
      "name": "Rock_Stone"
    },
    {
      "x": -7,
      "y": 4,
      "z": 1,
      "name": "Rock_Stone"
    },
    {
      "x": -7,
      "y": 5,
      "z": 1,
      "name": "Rock_Stone"
    },
    {
      "x": -7,
      "y": 6,
      "z": 1,
      "name": "Rock_Stone"
    },
    {
      "x": -7,
      "y": 7,
      "z": 1,
      "name": "Rock_Stone"
    },
    {
      "x": -7,
      "y": 8,
      "z": 1,
      "name": "Rock_Stone"
    },
    {
      "x": -7,
      "y": 9,
      "z": 1,
      "name": "Rock_Stone"
    },
    {
      "x": -7,
      "y": 10,
      "z": 1,
      "name": "Rock_Stone"
    },
    {
      "x": -7,
      "y": 11,
      "z": 1,
      "name": "Rock_Stone"
    },
    {
      "x": -7,
      "y": 12,
      "z": 1,
      "name": "Rock_Stone_Mossy"
    },
    {
      "x": -7,
      "y": 13,
      "z": 1,
      "name": "Rock_Stone"
    },
    {
      "x": -7,
      "y": 14,
      "z": 1,
      "name": "Rock_Stone"
    },
    {
      "x": -7,
      "y": 15,
      "z": 1,
      "name": "Rock_Stone"
    },
    {
      "x": -7,
      "y": 16,
      "z": 1,
      "name": "Rock_Stone"
    },
    {
      "x": -7,
      "y": 17,
      "z": 1,
      "name": "Rock_Stone"
    },
    {
      "x": -7,
      "y": 18,
      "z": 1,
      "name": "Rock_Stone"
    },
    {
      "x": -7,
      "y": 19,
      "z": 1,
      "name": "Rock_Stone"
    },
    {
      "x": -7,
      "y": 20,
      "z": 1,
      "name": "Rock_Stone"
    },
    {
      "x": -7,
      "y": 21,
      "z": 1,
      "name": "Rock_Stone"
    },
    {
      "x": -7,
      "y": 22,
      "z": 1,
      "name": "Rock_Stone"
    },
    {
      "x": -7,
      "y": 4,
      "z": 2,
      "name": "Rock_Stone"
    },
    {
      "x": -7,
      "y": 5,
      "z": 2,
      "name": "Rock_Stone"
    },
    {
      "x": -7,
      "y": 6,
      "z": 2,
      "name": "Rock_Stone"
    },
    {
      "x": -7,
      "y": 7,
      "z": 2,
      "name": "Rock_Stone"
    },
    {
      "x": -7,
      "y": 8,
      "z": 2,
      "name": "Rock_Stone"
    },
    {
      "x": -7,
      "y": 9,
      "z": 2,
      "name": "Rock_Stone"
    },
    {
      "x": -7,
      "y": 10,
      "z": 2,
      "name": "Rock_Stone"
    },
    {
      "x": -7,
      "y": 11,
      "z": 2,
      "name": "Rock_Stone_Mossy"
    },
    {
