{
  "version": 8,
  "blockIdVersion": 8,
  "anchorX": 1,
  "anchorY": 10,
  "anchorZ": 0,
  "blocks": [
    {
      "x": -17,
      "y": 14,
      "z": -3,
      "name": "Soil_Gravel_Sand"
    },
    {
      "x": -17,
      "y": 14,
      "z": -2,
      "name": "Soil_Gravel_Sand"
    },
    {
      "x": -17,
      "y": 15,
      "z": -2,
      "name": "Rock_Sandstone_White"
    },
    {
      "x": -17,
      "y": 3,
      "z": -1,
      "name": "Rock_Sandstone_White"
    },
    {
      "x": -17,
      "y": 4,
      "z": -1,
      "name": "Rock_Sandstone_White"
    },
    {
      "x": -17,
      "y": 5,
      "z": -1,
      "name": "Rock_Sandstone_White"
    },
    {
      "x": -17,
      "y": 7,
      "z": -1,
      "name": "Rock_Sandstone_White"
    },
    {
      "x": -17,
      "y": 8,
      "z": -1,
      "name": "Rock_Sandstone_White"
    },
    {
      "x": -17,
      "y": 9,
      "z": -1,
      "name": "Rock_Sandstone_White"
    },
    {
      "x": -17,
      "y": 11,
      "z": -1,
      "name": "Rock_Sandstone_White"
    },
    {
      "x": -17,
      "y": 12,
      "z": -1,
      "name": "Rock_Sandstone_White"
    },
    {
      "x": -17,
      "y": 14,
      "z": -1,
      "name": "Soil_Gravel_Sand"
    },
    {
      "x": -17,
      "y": 15,
      "z": -1,
      "name": "Soil_Gravel_Sand"
    },
    {
      "x": -17,
      "y": 3,
      "z": 0,
      "name": "Rock_Sandstone_White"
    },
    {
      "x": -17,
      "y": 4,
      "z": 0,
      "name": "Rock_Sandstone_White"
    },
    {
      "x": -17,
      "y": 5,
      "z": 0,
      "name": "Rock_Sandstone_White"
    },
    {
      "x": -17,
      "y": 7,
      "z": 0,
      "name": "Rock_Sandstone_White"
    },
    {
      "x": -17,
      "y": 8,
      "z": 0,
      "name": "Rock_Sandstone_White"
    },
    {
      "x": -17,
      "y": 9,
      "z": 0,
      "name": "Rock_Sandstone_White"
    },
    {
      "x": -17,
      "y": 11,
      "z": 0,
      "name": "Rock_Sandstone_White"
    },
    {
      "x": -17,
      "y": 12,
      "z": 0,
      "name": "Rock_Sandstone_White"
    },
    {
      "x": -17,
      "y": 14,
      "z": 0,
      "name": "Soil_Gravel_Sand"
    },
    {
      "x": -17,
      "y": 15,
      "z": 0,
      "name": "Soil_Gravel_Sand"
    },
    {
      "x": -17,
      "y": 3,
      "z": 1,
      "name": "Rock_Sandstone_White"
    },
    {
      "x": -17,
      "y": 4,
      "z": 1,
      "name": "Rock_Sandstone_White"
    },
    {
      "x": -17,
      "y": 5,
      "z": 1,
      "name": "Rock_Sandstone_White"
    },
    {
      "x": -17,
      "y": 7,
      "z": 1,
      "name": "Rock_Sandstone_White"
    },
    {
      "x": -17,
      "y": 8,
      "z": 1,
      "name": "Rock_Sandstone_White"
    },
    {
      "x": -17,
      "y": 9,
      "z": 1,
      "name": "Rock_Sandstone_White"
    },
    {
      "x": -17,
      "y": 11,
      "z": 1,
      "name": "Rock_Sandstone_White"
    },
    {
      "x": -17,
      "y": 12,
      "z": 1,
      "name": "Rock_Sandstone_White"
    },
    {
      "x": -17,
      "y": 14,
      "z": 1,
      "name": "Soil_Gravel_Sand"
    },
    {
      "x": -17,
      "y": 15,
      "z": 1,
      "name": "Soil_Gravel_Sand"
    },
    {
      "x": -17,
      "y": 7,
      "z": 2,
      "name": "Rock_Sandstone_White"
    },
    {
      "x": -17,
      "y": 8,
      "z": 2,
      "name": "Rock_Sandstone_White"
    },
    {
      "x": -17,
      "y": 11,
      "z": 2,
      "name": "Rock_Sandstone_White"
    },
    {
      "x": -17,
      "y": 12,
      "z": 2,
      "name": "Rock_Sandstone_White"
    },
    {
      "x": -17,
      "y": 14,
      "z": 2,
      "name": "Soil_Gravel_Sand"
    },
    {
      "x": -17,
      "y": 15,
      "z": 2,
      "name": "Soil_Gravel_Sand"
    },
    {
      "x": -17,
      "y": 14,
      "z": 3,
      "name": "Soil_Gravel_Sand"
    },
    {
      "x": -16,
      "y": 14,
      "z": -5,
      "name": "Soil_Gravel_Sand"
    },
    {
      "x": -16,
      "y": 14,
      "z": -4,
      "name": "Soil_Gravel_Sand"
    },
    {
      "x": -16,
      "y": 15,
      "z": -4,
      "name": "Rock_Sandstone_White"
    },
    {
      "x": -16,
      "y": 7,
      "z": -3,
      "name": "Rock_Sandstone_White"
    },
    {
      "x": -16,
      "y": 8,
      "z": -3,
      "name": "Rock_Sandstone_White"
    },
    {
      "x": -16,
      "y": 11,
      "z": -3,
      "name": "Rock_Sandstone_White"
    },
    {
      "x": -16,
      "y": 12,
      "z": -3,
      "name": "Soil_Gravel_Sand"
    },
    {
      "x": -16,
      "y": 14,
      "z": -3,
      "name": "Soil_Gravel_Sand"
    },
    {
      "x": -16,
      "y": 15,
      "z": -3,
      "name": "Rock_Sandstone_White"
    },
    {
      "x": -16,
      "y": 3,
      "z": -2,
      "name": "Rock_Sandstone_White"
    },
    {
      "x": -16,
      "y": 4,
      "z": -2,
      "name": "Rock_Sandstone_White"
    },
    {
      "x": -16,
      "y": 5,
      "z": -2,
      "name": "Rock_Sandstone_White"
    },
    {
      "x": -16,
      "y": 7,
      "z": -2,
      "name": "Rock_Sandstone_White"
    },
    {
      "x": -16,
      "y": 8,
      "z": -2,
      "name": "Rock_Sandstone_White"
    },
    {
      "x": -16,
      "y": 9,
      "z": -2,
      "name": "Rock_Sandstone_White"
    },
    {
      "x": -16,
      "y": 11,
      "z": -2,
      "name": "Rock_Sandstone_White"
    },
    {
      "x": -16,
      "y": 12,
      "z": -2,
      "name": "Soil_Gravel_Sand"
    },
    {
      "x": -16,
      "y": 14,
      "z": -2,
      "name": "Soil_Gravel_Sand"
    },
    {
      "x": -16,
      "y": 15,
      "z": -2,
      "name": "Rock_Sandstone_White"
    },
    {
      "x": -16,
      "y": 3,
      "z": -1,
      "name": "Rock_Sandstone_White"
    },
    {
      "x": -16,
      "y": 4,
      "z": -1,
      "name": "Rock_Sandstone_White"
    },
    {
      "x": -16,
      "y": 5,
      "z": -1,
      "name": "Rock_Sandstone_White"
    },
    {
      "x": -16,
      "y": 6,
      "z": -1,
      "name": "Rock_Sandstone_White"
    },
    {
      "x": -16,
      "y": 7,
      "z": -1,
      "name": "Rock_Sandstone_White"
    },
    {
      "x": -16,
      "y": 8,
      "z": -1,
      "name": "Rock_Sandstone_White"
    },
    {
      "x": -16,
      "y": 9,
      "z": -1,
      "name": "Rock_Sandstone_White"
    },
    {
      "x": -16,
      "y": 11,
      "z": -1,
      "name": "Rock_Sandstone_White"
    },
    {
      "x": -16,
      "y": 12,
      "z": -1,
      "name": "Rock_Sandstone_White"
    },
    {
      "x": -16,
      "y": 13,
      "z": -1,
      "name": "Soil_Gravel_Sand"
    },
    {
      "x": -16,
      "y": 14,
      "z": -1,
      "name": "Soil_Gravel_Sand"
    },
    {
      "x": -16,
      "y": 15,
      "z": -1,
      "name": "Soil_Gravel_Sand"
    },
    {
      "x": -16,
      "y": 1,
      "z": 0,
      "name": "Rock_Sandstone_White"
    },
    {
      "x": -16,
      "y": 2,
      "z": 0,
      "name": "Rock_Sandstone_White"
    },
    {
      "x": -16,
      "y": 3,
      "z": 0,
      "name": "Rock_Sandstone_White"
    },
    {
      "x": -16,
      "y": 4,
      "z": 0,
      "name": "Rock_Sandstone_White"
    },
    {
      "x": -16,
      "y": 5,
      "z": 0,
      "name": "Rock_Sandstone_White"
    },
    {
      "x": -16,
      "y": 6,
      "z": 0,
      "name": "Rock_Sandstone_White"
    },
    {
      "x": -16,
      "y": 7,
      "z": 0,
      "name": "Rock_Sandstone_White"
    },
    {
      "x": -16,
      "y": 8,
      "z": 0,
      "name": "Rock_Sandstone_White"
    },
    {
      "x": -16,
      "y": 9,
      "z": 0,
      "name": "Rock_Sandstone_White"
    },
    {
      "x": -16,
      "y": 11,
      "z": 0,
      "name": "Rock_Sandstone_White"
    },
    {
      "x": -16,
      "y": 12,
      "z": 0,
      "name": "Rock_Sandstone_White"
    },
    {
      "x": -16,
      "y": 13,
      "z": 0,
      "name": "Rock_Sandstone"
    },
    {
      "x": -16,
      "y": 14,
      "z": 0,
      "name": "Soil_Gravel_Sand"
    },
    {
      "x": -16,
      "y": 15,
      "z": 0,
      "name": "Soil_Gravel_Sand"
    },
    {
      "x": -16,
      "y": 1,
      "z": 1,
      "name": "Rock_Sandstone_White"
    },
    {
      "x": -16,
      "y": 2,
      "z": 1,
      "name": "Rock_Sandstone_White"
    },
    {
      "x": -16,
      "y": 3,
      "z": 1,
      "name": "Rock_Sandstone_White"
    },
    {
      "x": -16,
      "y": 4,
      "z": 1,
      "name": "Rock_Sandstone_White"
    },
    {
      "x": -16,
      "y": 5,
      "z": 1,
      "name": "Rock_Sandstone_White"
    },
    {
      "x": -16,
      "y": 6,
      "z": 1,
      "name": "Rock_Sandstone_White"
    },
    {
      "x": -16,
      "y": 7,
      "z": 1,
      "name": "Rock_Sandstone_White"
    },
    {
      "x": -16,
      "y": 8,
      "z": 1,
      "name": "Rock_Sandstone_White"
    },
    {
      "x": -16,
      "y": 9,
      "z": 1,
      "name": "Rock_Sandstone_White"
    },
    {
      "x": -16,
      "y": 11,
      "z": 1,
      "name": "Rock_Sandstone_White"
    },
    {
      "x": -16,
      "y": 12,
      "z": 1,
      "name": "Rock_Sandstone_White"
    },
    {
      "x": -16,
      "y": 13,
      "z": 1,
      "name": "Rock_Sandstone"
    },
    {
      "x": -16,
      "y": 14,
      "z": 1,
      "name": "Soil_Gravel_Sand"
    },
    {
      "x": -16,
      "y": 15,
      "z": 1,
      "name": "Soil_Gravel_Sand"
    },
    {
      "x": -16,
      "y": 1,
      "z": 2,
      "name": "Rock_Sandstone_White"
    },
    {
      "x": -16,
      "y": 2,
      "z": 2,
      "name": "Rock_Sandstone_White"
    },
    {
      "x": -16,
      "y": 3,
      "z": 2,
      "name": "Rock_Sandstone_White"
    },
    {
      "x": -16,
      "y": 4,
      "z": 2,
      "name": "Rock_Sandstone_White"
    },
    {
      "x": -16,
      "y": 5,
      "z": 2,
      "name": "Rock_Sandstone_White"
    },
    {
      "x": -16,
      "y": 7,
      "z": 2,
      "name": "Rock_Sandstone_White"
    },
    {
      "x": -16,
      "y": 8,
      "z": 2,
      "name": "Rock_Sandstone_White"
    },
    {
      "x": -16,
      "y": 9,
      "z": 2,
      "name": "Rock_Sandstone_White"
    },
    {
      "x": -16,
      "y": 11,
      "z": 2,
      "name": "Rock_Sandstone_White"
    },
    {
      "x": -16,
      "y": 12,
      "z": 2,
      "name": "Rock_Sandstone_White"
    },
    {
      "x": -16,
      "y": 13,
      "z": 2,
      "name": "Rock_Sandstone"
    },
    {
      "x": -16,
      "y": 14,
      "z": 2,
      "name": "Soil_Gravel_Sand"
    },
    {
      "x": -16,
      "y": 15,
      "z": 2,
      "name": "Soil_Gravel_Sand"
    },
    {
      "x": -16,
      "y": 3,
      "z": 3,
      "name": "Rock_Sandstone_White"
    },
    {
      "x": -16,
      "y": 4,
      "z": 3,
      "name": "Rock_Sandstone_White"
    },
    {
      "x": -16,
      "y": 5,
      "z": 3,
      "name": "Rock_Sandstone_White"
    },
    {
      "x": -16,
      "y": 7,
      "z": 3,
      "name": "Rock_Sandstone_White"
    },
    {
      "x": -16,
      "y": 8,
      "z": 3,
      "name": "Rock_Sandstone_White"
    },
    {
      "x": -16,
      "y": 9,
      "z": 3,
      "name": "Rock_Sandstone_White"
    },
    {
      "x": -16,
      "y": 11,
      "z": 3,
      "name": "Rock_Sandstone_White"
    },
    {
      "x": -16,
      "y": 12,
      "z": 3,
      "name": "Rock_Sandstone_White"
    },
    {
      "x": -16,
      "y": 14,
      "z": 3,
      "name": "Soil_Gravel_Sand"
    },
    {
      "x": -16,
      "y": 15,
      "z": 3,
      "name": "Soil_Gravel_Sand"
    },
    {
      "x": -16,
      "y": 3,
      "z": 4,
      "name": "Rock_Sandstone_White"
    },
    {
      "x": -16,
      "y": 4,
      "z": 4,
      "name": "Rock_Sandstone_White"
    },
    {
      "x": -16,
      "y": 5,
      "z": 4,
      "name": "Rock_Sandstone_White"
    },
    {
      "x": -16,
      "y": 7,
      "z": 4,
      "name": "Rock_Sandstone_White"
    },
    {
      "x": -16,
      "y": 8,
      "z": 4,
      "name": "Rock_Sandstone_White"
    },
    {
      "x": -16,
      "y": 9,
      "z": 4,
      "name": "Rock_Sandstone_White"
    },
    {
      "x": -16,
      "y": 14,
      "z": 4,
      "name": "Soil_Gravel_Sand"
    },
    {
      "x": -15,
      "y": 14,
      "z": -6,
      "name": "Soil_Gravel_Sand"
    },
    {
      "x": -15,
      "y": 15,
      "z": -6,
      "name": "Rock_Sandstone_White"
    },
    {
      "x": -15,
      "y": 7,
      "z": -5,
      "name": "Rock_Sandstone_White"
    },
    {
      "x": -15,
      "y": 8,
      "z": -5,
      "name": "Rock_Sandstone_White"
    },
    {
      "x": -15,
      "y": 9,
      "z": -5,
      "name": "Rock_Sandstone_White"
    },
    {
      "x": -15,
      "y": 11,
      "z": -5,
      "name": "Rock_Sandstone_White"
    },
    {
      "x": -15,
      "y": 12,
      "z": -5,
      "name": "Soil_Gravel_Sand"
    },
    {
      "x": -15,
      "y": 14,
      "z": -5,
      "name": "Soil_Gravel_Sand"
    },
    {
      "x": -15,
      "y": 15,
      "z": -5,
      "name": "Rock_Sandstone_White"
    },
    {
      "x": -15,
      "y": 16,
      "z": -5,
      "name": "Rock_Sandstone_White"
    },
    {
      "x": -15,
      "y": 7,
      "z": -4,
      "name": "Rock_Sandstone_White"
    },
    {
      "x": -15,
      "y": 8,
      "z": -4,
      "name": "Rock_Sandstone_White"
    },
    {
      "x": -15,
      "y": 9,
      "z": -4,
      "name": "Rock_Sandstone_White"
    },
    {
      "x": -15,
      "y": 11,
      "z": -4,
      "name": "Rock_Sandstone_White"
    },
    {
      "x": -15,
      "y": 12,
      "z": -4,
      "name": "Soil_Gravel_Sand"
    },
    {
      "x": -15,
      "y": 14,
      "z": -4,
      "name": "Soil_Gravel_Sand"
    },
    {
      "x": -15,
      "y": 15,
      "z": -4,
      "name": "Rock_Sandstone_White"
    },
    {
      "x": -15,
      "y": 16,
      "z": -4,
      "name": "Rock_Sandstone_White"
    },
    {
      "x": -15,
      "y": 3,
      "z": -3,
      "name": "Rock_Sandstone_White"
    },
    {
      "x": -15,
      "y": 4,
      "z": -3,
      "name": "Rock_Sandstone_White"
    },
    {
      "x": -15,
      "y": 5,
      "z": -3,
      "name": "Rock_Sandstone_White"
    },
    {
      "x": -15,
      "y": 7,
      "z": -3,
      "name": "Rock_Sandstone_White"
    },
    {
      "x": -15,
      "y": 8,
      "z": -3,
      "name": "Rock_Sandstone_White"
    },
    {
      "x": -15,
      "y": 9,
      "z": -3,
      "name": "Rock_Sandstone_White"
    },
    {
      "x": -15,
      "y": 11,
      "z": -3,
      "name": "Rock_Sandstone_White"
    },
    {
      "x": -15,
      "y": 12,
      "z": -3,
      "name": "Soil_Gravel_Sand"
    },
    {
      "x": -15,
      "y": 13,
      "z": -3,
      "name": "Soil_Gravel_Sand"
    },
    {
      "x": -15,
      "y": 14,
      "z": -3,
      "name": "Soil_Gravel_Sand"
    },
    {
      "x": -15,
      "y": 15,
      "z": -3,
      "name": "Rock_Sandstone_White"
    },
    {
      "x": -15,
      "y": 16,
      "z": -3,
      "name": "Rock_Sandstone_White"
    },
    {
      "x": -15,
      "y": 3,
      "z": -2,
      "name": "Rock_Sandstone_White"
    },
    {
      "x": -15,
      "y": 4,
      "z": -2,
      "name": "Rock_Sandstone_White"
    },
    {
      "x": -15,
      "y": 5,
      "z": -2,
      "name": "Rock_Sandstone_White"
    },
    {
      "x": -15,
      "y": 6,
      "z": -2,
      "name": "Rock_Sandstone_White"
    },
    {
      "x": -15,
      "y": 7,
      "z": -2,
      "name": "Rock_Sandstone_White"
    },
    {
      "x": -15,
      "y": 8,
      "z": -2,
      "name": "Rock_Sandstone_White"
    },
    {
      "x": -15,
      "y": 9,
      "z": -2,
      "name": "Rock_Sandstone_White"
    },
    {
      "x": -15,
      "y": 11,
      "z": -2,
      "name": "Rock_Sandstone_White"
    },
    {
      "x": -15,
      "y": 12,
      "z": -2,
      "name": "Soil_Gravel_Sand"
    },
    {
      "x": -15,
      "y": 13,
      "z": -2,
      "name": "Soil_Gravel_Sand"
    },
    {
      "x": -15,
      "y": 14,
      "z": -2,
      "name": "Soil_Gravel_Sand"
    },
    {
      "x": -15,
      "y": 15,
      "z": -2,
      "name": "Rock_Sandstone_White"
    },
    {
      "x": -15,
      "y": 16,
      "z": -2,
      "name": "Rock_Sandstone_White"
    },
    {
      "x": -15,
      "y": 1,
      "z": -1,
      "name": "Rock_Sandstone_White"
    },
    {
      "x": -15,
      "y": 2,
      "z": -1,
      "name": "Rock_Sandstone_White"
    },
    {
      "x": -15,
      "y": 3,
      "z": -1,
      "name": "Rock_Sandstone_White"
    },
    {
      "x": -15,
      "y": 4,
      "z": -1,
      "name": "Rock_Sandstone_White"
    },
    {
      "x": -15,
      "y": 5,
      "z": -1,
      "name": "Rock_Sandstone_White"
    },
    {
      "x": -15,
      "y": 6,
      "z": -1,
      "name": "Rock_Sandstone_White"
    },
    {
      "x": -15,
      "y": 7,
      "z": -1,
      "name": "Rock_Sandstone_White"
    },
    {
      "x": -15,
      "y": 8,
      "z": -1,
      "name": "Rock_Sandstone_White"
    },
    {
      "x": -15,
      "y": 9,
      "z": -1,
      "name": "Rock_Sandstone_White"
    },
    {
      "x": -15,
      "y": 10,
      "z": -1,
      "name": "Rock_Sandstone_White"
    },
    {
      "x": -15,
      "y": 11,
      "z": -1,
      "name": "Rock_Sandstone_White"
    },
    {
      "x": -15,
      "y": 12,
      "z": -1,
      "name": "Rock_Sandstone_White"
    },
    {
      "x": -15,
      "y": 13,
      "z": -1,
      "name": "Soil_Gravel_Sand"
    },
    {
      "x": -15,
      "y": 14,
      "z": -1,
      "name": "Soil_Gravel_Sand"
    },
    {
      "x": -15,
      "y": 15,
      "z": -1,
      "name": "Soil_Gravel_Sand"
    },
    {
      "x": -15,
      "y": 16,
      "z": -1,
      "name": "Rock_Sandstone_White"
    },
    {
      "x": -15,
      "y": 1,
      "z": 0,
      "name": "Rock_Sandstone_White"
    },
    {
      "x": -15,
      "y": 2,
      "z": 0,
      "name": "Rock_Sandstone_White"
    },
    {
      "x": -15,
      "y": 3,
      "z": 0,
      "name": "Rock_Sandstone_White"
    },
    {
      "x": -15,
      "y": 4,
      "z": 0,
      "name": "Rock_Sandstone_White"
    },
    {
      "x": -15,
      "y": 5,
      "z": 0,
      "name": "Rock_Sandstone_White"
    },
    {
      "x": -15,
      "y": 6,
      "z": 0,
      "name": "Rock_Sandstone_White"
    },
    {
      "x": -15,
      "y": 7,
      "z": 0,
      "name": "Rock_Sandstone_White"
    },
    {
      "x": -15,
      "y": 8,
      "z": 0,
      "name": "Rock_Sandstone_White"
    },
    {
      "x": -15,
      "y": 9,
      "z": 0,
      "name": "Rock_Sandstone_White"
    },
    {
      "x": -15,
      "y": 10,
      "z": 0,
      "name": "Rock_Sandstone_White"
    },
    {
      "x": -15,
      "y": 11,
      "z": 0,
      "name": "Rock_Sandstone_White"
    },
    {
      "x": -15,
      "y": 12,
      "z": 0,
      "name": "Rock_Sandstone_White"
    },
    {
      "x": -15,
      "y": 13,
      "z": 0,
      "name": "Rock_Sandstone"
    },
    {
      "x": -15,
      "y": 14,
      "z": 0,
      "name": "Soil_Gravel_Sand"
    },
    {
      "x": -15,
      "y": 15,
      "z": 0,
      "name": "Soil_Gravel_Sand"
    },
    {
      "x": -15,
      "y": 16,
      "z": 0,
      "name": "Soil_Gravel_Sand"
    },
    {
      "x": -15,
      "y": 1,
      "z": 1,
      "name": "Rock_Sandstone_White"
    },
    {
      "x": -15,
      "y": 2,
      "z": 1,
      "name": "Rock_Sandstone_White"
    },
    {
      "x": -15,
      "y": 3,
      "z": 1,
      "name": "Rock_Sandstone_White"
    },
    {
      "x": -15,
      "y": 4,
      "z": 1,
      "name": "Rock_Sandstone_White"
    },
    {
      "x": -15,
      "y": 5,
      "z": 1,
      "name": "Rock_Sandstone_White"
    },
    {
      "x": -15,
      "y": 6,
      "z": 1,
      "name": "Rock_Sandstone_White"
    },
    {
      "x": -15,
      "y": 7,
      "z": 1,
      "name": "Rock_Sandstone_White"
    },
    {
      "x": -15,
      "y": 8,
      "z": 1,
      "name": "Rock_Sandstone_White"
    },
    {
      "x": -15,
      "y": 9,
      "z": 1,
      "name": "Rock_Sandstone_White"
    },
    {
      "x": -15,
      "y": 10,
      "z": 1,
      "name": "Rock_Sandstone_White"
    },
    {
      "x": -15,
      "y": 11,
      "z": 1,
      "name": "Rock_Sandstone_White"
    },
    {
      "x": -15,
      "y": 12,
      "z": 1,
      "name": "Rock_Sandstone_White"
    },
    {
      "x": -15,
      "y": 13,
      "z": 1,
      "name": "Rock_Sandstone"
    },
    {
      "x": -15,
      "y": 14,
      "z": 1,
      "name": "Soil_Gravel_Sand"
    },
    {
      "x": -15,
      "y": 15,
      "z": 1,
      "name": "Soil_Gravel_Sand"
    },
    {
      "x": -15,
      "y": 16,
      "z": 1,
      "name": "Soil_Gravel_Sand"
    },
    {
      "x": -15,
      "y": 1,
      "z": 2,
      "name": "Rock_Sandstone_White"
    },
    {
      "x": -15,
      "y": 2,
      "z": 2,
      "name": "Rock_Sandstone_White"
    },
    {
      "x": -15,
      "y": 3,
      "z": 2,
      "name": "Rock_Sandstone_White"
    },
    {
      "x": -15,
      "y": 4,
      "z": 2,
      "name": "Rock_Sandstone_White"
    },
    {
      "x": -15,
      "y": 5,
      "z": 2,
      "name": "Rock_Sandstone_White"
    },
    {
      "x": -15,
      "y": 6,
      "z": 2,
      "name": "Rock_Sandstone_White"
    },
    {
      "x": -15,
      "y": 7,
      "z": 2,
      "name": "Rock_Sandstone_White"
    },
    {
      "x": -15,
      "y": 8,
      "z": 2,
      "name": "Rock_Sandstone_White"
    },
    {
      "x": -15,
      "y": 9,
      "z": 2,
      "name": "Rock_Sandstone_White"
    },
    {
      "x": -15,
      "y": 10,
      "z": 2,
      "name": "Rock_Sandstone_White"
    },
    {
      "x": -15,
      "y": 11,
      "z": 2,
      "name": "Rock_Sandstone_White"
    },
    {
      "x": -15,
      "y": 12,
      "z": 2,
      "name": "Rock_Sandstone_White"
    },
    {
      "x": -15,
      "y": 13,
      "z": 2,
      "name": "Rock_Sandstone"
    },
    {
      "x": -15,
      "y": 14,
      "z": 2,
      "name": "Soil_Gravel_Sand"
    },
    {
      "x": -15,
      "y": 15,
      "z": 2,
      "name": "Soil_Gravel_Sand"
    },
    {
      "x": -15,
      "y": 16,
      "z": 2,
      "name": "Soil_Gravel_Sand"
    },
    {
      "x": -15,
      "y": 1,
      "z": 3,
      "name": "Rock_Sandstone_White"
    },
    {
      "x": -15,
      "y": 2,
      "z": 3,
      "name": "Rock_Sandstone_White"
    },
    {
      "x": -15,
      "y": 3,
      "z": 3,
      "name": "Rock_Sandstone_White"
    },
    {
      "x": -15,
      "y": 4,
      "z": 3,
      "name": "Rock_Sandstone_White"
    },
    {
      "x": -15,
      "y": 5,
      "z": 3,
      "name": "Rock_Sandstone_White"
    },
    {
      "x": -15,
      "y": 7,
      "z": 3,
      "name": "Rock_Sandstone_White"
    },
    {
      "x": -15,
      "y": 8,
      "z": 3,
      "name": "Rock_Sandstone_White"
    },
    {
      "x": -15,
      "y": 9,
      "z": 3,
      "name": "Rock_Sandstone_White"
    },
    {
      "x": -15,
      "y": 10,
      "z": 3,
      "name": "Rock_Sandstone_White"
    },
    {
      "x": -15,
      "y": 11,
      "z": 3,
      "name": "Rock_Sandstone_White"
    },
    {
      "x": -15,
      "y": 12,
      "z": 3,
      "name": "Rock_Sandstone_White"
    },
    {
      "x": -15,
      "y": 13,
      "z": 3,
      "name": "Rock_Sandstone"
    },
    {
      "x": -15,
      "y": 14,
      "z": 3,
      "name": "Soil_Gravel_Sand"
    },
    {
      "x": -15,
      "y": 15,
      "z": 3,
      "name": "Soil_Gravel_Sand"
    },
    {
      "x": -15,
      "y": 3,
      "z": 4,
      "name": "Rock_Sandstone_White"
    },
    {
      "x": -15,
      "y": 4,
      "z": 4,
      "name": "Rock_Sandstone_White"
    },
    {
      "x": -15,
      "y": 5,
      "z": 4,
      "name": "Rock_Sandstone_White"
    },
    {
      "x": -15,
      "y": 7,
      "z": 4,
      "name": "Rock_Sandstone_White"
    },
    {
      "x": -15,
      "y": 8,
      "z": 4,
      "name": "Rock_Sandstone_White"
    },
    {
      "x": -15,
      "y": 9,
      "z": 4,
      "name": "Rock_Sandstone_White"
    },
    {
      "x": -15,
      "y": 11,
      "z": 4,
      "name": "Rock_Sandstone_White"
    },
    {
      "x": -15,
      "y": 12,
      "z": 4,
      "name": "Rock_Sandstone_White"
    },
    {
      "x": -15,
      "y": 14,
      "z": 4,
      "name": "Soil_Gravel_Sand"
    },
    {
      "x": -15,
      "y": 15,
      "z": 4,
      "name": "Soil_Gravel_Sand"
    },
    {
      "x": -15,
      "y": 3,
      "z": 5,
      "name": "Rock_Sandstone_White"
    },
    {
      "x": -15,
      "y": 4,
      "z": 5,
      "name": "Rock_Sandstone_White"
    },
    {
      "x": -15,
      "y": 5,
      "z": 5,
      "name": "Rock_Sandstone_White"
    },
    {
      "x": -15,
      "y": 7,
      "z": 5,
      "name": "Rock_Sandstone_White"
    },
    {
      "x": -15,
      "y": 8,
      "z": 5,
      "name": "Rock_Sandstone_White"
    },
    {
      "x": -15,
      "y": 9,
      "z": 5,
      "name": "Rock_Sandstone_White"
    },
    {
      "x": -15,
      "y": 14,
      "z": 5,
      "name": "Soil_Gravel_Sand"
    },
    {
      "x": -15,
      "y": 15,
      "z": 5,
      "name": "Soil_Gravel_Sand"
    },
    {
      "x": -14,
      "y": 7,
      "z": -6,
      "name": "Rock_Sandstone_White"
    },
    {
      "x": -14,
      "y": 8,
      "z": -6,
      "name": "Rock_Sandstone_White"
    },
    {
      "x": -14,
      "y": 12,
      "z": -6,
      "name": "Soil_Gravel_Sand"
    },
    {
      "x": -14,
      "y": 14,
      "z": -6,
      "name": "Soil_Gravel_Sand"
    },
    {
      "x": -14,
      "y": 15,
      "z": -6,
      "name": "Rock_Sandstone_White"
    },
    {
      "x": -14,
      "y": 16,
      "z": -6,
      "name": "Rock_Sandstone_White"
    },
    {
      "x": -14,
      "y": 7,
      "z": -5,
      "name": "Rock_Sandstone_White"
    },
    {
      "x": -14,
      "y": 8,
      "z": -5,
      "name": "Rock_Sandstone_White"
    },
    {
      "x": -14,
      "y": 9,
      "z": -5,
      "name": "Rock_Sandstone_White"
    },
    {
      "x": -14,
      "y": 11,
      "z": -5,
      "name": "Rock_Sandstone_White"
    },
    {
      "x": -14,
      "y": 12,
      "z": -5,
      "name": "Soil_Gravel_Sand"
    },
    {
      "x": -14,
      "y": 14,
      "z": -5,
      "name": "Soil_Gravel_Sand"
    },
    {
      "x": -14,
      "y": 15,
      "z": -5,
      "name": "Rock_Sandstone_White"
    },
    {
      "x": -14,
      "y": 16,
      "z": -5,
      "name": "Rock_Sandstone_White"
    },
    {
      "x": -14,
      "y": 3,
      "z": -4,
      "name": "Rock_Sandstone_White"
    },
    {
      "x": -14,
      "y": 4,
      "z": -4,
      "name": "Rock_Sandstone_White"
    },
    {
      "x": -14,
      "y": 5,
      "z": -4,
      "name": "Rock_Sandstone_White"
    },
    {
      "x": -14,
      "y": 6,
      "z": -4,
      "name": "Rock_Sandstone_White"
    },
    {
      "x": -14,
      "y": 7,
      "z": -4,
      "name": "Rock_Sandstone_White"
    },
    {
      "x": -14,
      "y": 8,
      "z": -4,
      "name": "Rock_Sandstone_White"
    },
    {
      "x": -14,
      "y": 9,
      "z": -4,
      "name": "Rock_Sandstone_White"
    },
    {
      "x": -14,
      "y": 10,
      "z": -4,
      "name": "Rock_Sandstone_White"
    },
    {
      "x": -14,
      "y": 11,
      "z": -4,
      "name": "Rock_Sandstone_White"
    },
    {
      "x": -14,
      "y": 12,
      "z": -4,
      "name": "Soil_Gravel_Sand"
    },
    {
      "x": -14,
      "y": 14,
      "z": -4,
      "name": "Soil_Gravel_Sand"
    },
    {
      "x": -14,
      "y": 15,
      "z": -4,
      "name": "Rock_Sandstone_White"
    },
    {
      "x": -14,
      "y": 16,
      "z": -4,
      "name": "Rock_Sandstone_White"
    },
    {
      "x": -14,
      "y": 3,
      "z": -3,
      "name": "Rock_Sandstone_White"
    },
    {
      "x": -14,
      "y": 4,
      "z": -3,
      "name": "Rock_Sandstone_White"
    },
    {
      "x": -14,
      "y": 5,
      "z": -3,
      "name": "Rock_Sandstone_White"
    },
    {
      "x": -14,
      "y": 6,
      "z": -3,
      "name": "Rock_Sandstone_White"
    },
    {
      "x": -14,
      "y": 7,
      "z": -3,
      "name": "Rock_Sandstone_White"
    },
    {
      "x": -14,
      "y": 8,
      "z": -3,
      "name": "Rock_Sandstone_White"
    },
    {
      "x": -14,
      "y": 9,
      "z": -3,
      "name": "Rock_Sandstone_White"
    },
    {
      "x": -14,
      "y": 10,
      "z": -3,
      "name": "Rock_Sandstone_White"
    },
    {
      "x": -14,
      "y": 11,
      "z": -3,
      "name": "Rock_Sandstone_White"
    },
    {
      "x": -14,
      "y": 12,
      "z": -3,
      "name": "Soil_Gravel_Sand"
    },
    {
      "x": -14,
      "y": 13,
      "z": -3,
      "name": "Soil_Gravel_Sand"
    },
    {
      "x": -14,
      "y": 14,
      "z": -3,
      "name": "Soil_Gravel_Sand"
    },
    {
      "x": -14,
      "y": 15,
      "z": -3,
      "name": "Rock_Sandstone_White"
    },
    {
      "x": -14,
      "y": 16,
      "z": -3,
      "name": "Rock_Sandstone_White"
    },
    {
      "x": -14,
      "y": 1,
      "z": -2,
      "name": "Rock_Sandstone_White"
    },
    {
      "x": -14,
      "y": 2,
      "z": -2,
      "name": "Rock_Sandstone_White"
    },
    {
      "x": -14,
      "y": 3,
      "z": -2,
      "name": "Rock_Sandstone_White"
    },
    {
      "x": -14,
      "y": 4,
      "z": -2,
      "name": "Rock_Sandstone_White"
    },
    {
      "x": -14,
      "y": 5,
      "z": -2,
      "name": "Rock_Sandstone_White"
    },
    {
      "x": -14,
      "y": 6,
      "z": -2,
      "name": "Rock_Sandstone_White"
    },
    {
      "x": -14,
      "y": 7,
      "z": -2,
      "name": "Rock_Sandstone_White"
    },
    {
      "x": -14,
      "y": 8,
      "z": -2,
      "name": "Rock_Sandstone_White"
    },
    {
      "x": -14,
      "y": 9,
      "z": -2,
      "name": "Rock_Sandstone_White"
    },
    {
      "x": -14,
      "y": 10,
      "z": -2,
      "name": "Rock_Sandstone_White"
    },
    {
      "x": -14,
      "y": 11,
      "z": -2,
      "name": "Rock_Sandstone_White"
    },
    {
      "x": -14,
      "y": 12,
      "z": -2,
      "name": "Soil_Gravel_Sand"
    },
    {
      "x": -14,
      "y": 13,
      "z": -2,
      "name": "Soil_Gravel_Sand"
    },
    {
      "x": -14,
      "y": 14,
      "z": -2,
      "name": "Soil_Gravel_Sand"
    },
    {
      "x": -14,
      "y": 15,
      "z": -2,
      "name": "Rock_Sandstone_White"
    },
    {
      "x": -14,
      "y": 16,
      "z": -2,
      "name": "Rock_Sandstone_White"
    },
    {
      "x": -14,
      "y": 1,
      "z": -1,
      "name": "Rock_Sandstone_White"
    },
    {
      "x": -14,
      "y": 2,
      "z": -1,
      "name": "Rock_Sandstone_White"
    },
    {
      "x": -14,
      "y": 3,
      "z": -1,
      "name": "Rock_Sandstone_White"
    },
    {
      "x": -14,
      "y": 4,
      "z": -1,
      "name": "Rock_Sandstone_White"
    },
    {
      "x": -14,
      "y": 5,
      "z": -1,
      "name": "Rock_Sandstone_White"
    },
    {
      "x": -14,
      "y": 6,
      "z": -1,
      "name": "Rock_Sandstone_White"
    },
    {
      "x": -14,
      "y": 7,
      "z": -1,
      "name": "Rock_Sandstone_White"
    },
    {
      "x": -14,
      "y": 8,
      "z": -1,
      "name": "Rock_Sandstone_White"
    },
    {
      "x": -14,
      "y": 9,
      "z": -1,
      "name": "Rock_Sandstone_White"
    },
    {
      "x": -14,
      "y": 10,
      "z": -1,
      "name": "Rock_Sandstone_White"
    },
    {
      "x": -14,
      "y": 11,
      "z": -1,
      "name": "Rock_Sandstone_White"
    },
    {
      "x": -14,
      "y": 12,
      "z": -1,
      "name": "Rock_Sandstone_White"
    },
    {
      "x": -14,
      "y": 13,
      "z": -1,
      "name": "Soil_Gravel_Sand"
    },
    {
      "x": -14,
      "y": 14,
      "z": -1,
      "name": "Soil_Gravel_Sand"
    },
    {
      "x": -14,
      "y": 15,
      "z": -1,
      "name": "Soil_Gravel_Sand"
    },
    {
      "x": -14,
      "y": 16,
      "z": -1,
      "name": "Rock_Sandstone_White"
    },
    {
      "x": -14,
      "y": 1,
      "z": 0,
      "name": "Rock_Sandstone_White"
    },
    {
      "x": -14,
      "y": 2,
      "z": 0,
      "name": "Rock_Sandstone_White"
    },
    {
      "x": -14,
      "y": 3,
      "z": 0,
      "name": "Rock_Sandstone_White"
    },
    {
      "x": -14,
      "y": 4,
      "z": 0,
      "name": "Rock_Sandstone_White"
    },
    {
      "x": -14,
      "y": 5,
      "z": 0,
      "name": "Rock_Sandstone_White"
    },
    {
      "x": -14,
      "y": 6,
      "z": 0,
      "name": "Rock_Sandstone_White"
    },
    {
      "x": -14,
      "y": 7,
      "z": 0,
      "name": "Rock_Sandstone_White"
    },
    {
      "x": -14,
      "y": 8,
      "z": 0,
      "name": "Rock_Sandstone_White"
    },
    {
      "x": -14,
      "y": 9,
      "z": 0,
      "name": "Rock_Sandstone_White"
    },
    {
      "x": -14,
      "y": 10,
      "z": 0,
      "name": "Rock_Sandstone_White"
    },
    {
      "x": -14,
      "y": 11,
      "z": 0,
      "name": "Rock_Sandstone_White"
    },
    {
      "x": -14,
      "y": 12,
      "z": 0,
      "name": "Rock_Sandstone_White"
    },
    {
      "x": -14,
      "y": 13,
      "z": 0,
      "name": "Rock_Sandstone"
    },
    {
      "x": -14,
      "y": 14,
      "z": 0,
      "name": "Soil_Gravel_Sand"
    },
    {
      "x": -14,
      "y": 15,
      "z": 0,
      "name": "Soil_Gravel_Sand"
    },
    {
      "x": -14,
      "y": 16,
      "z": 0,
      "name": "Soil_Gravel_Sand"
    },
    {
      "x": -14,
      "y": 1,
      "z": 1,
      "name": "Rock_Sandstone_White"
    },
    {
      "x": -14,
      "y": 2,
      "z": 1,
      "name": "Rock_Sandstone_White"
    },
    {
      "x": -14,
      "y": 3,
      "z": 1,
      "name": "Rock_Sandstone_White"
    },
    {
      "x": -14,
      "y": 4,
      "z": 1,
      "name": "Rock_Sandstone_White"
    },
    {
      "x": -14,
      "y": 5,
      "z": 1,
      "name": "Rock_Sandstone_White"
    },
    {
      "x": -14,
      "y": 6,
      "z": 1,
      "name": "Rock_Sandstone_White"
    },
    {
      "x": -14,
      "y": 7,
      "z": 1,
      "name": "Rock_Sandstone_White"
    },
    {
      "x": -14,
      "y": 8,
      "z": 1,
      "name": "Rock_Sandstone_White"
    },
    {
      "x": -14,
      "y": 9,
      "z": 1,
      "name": "Rock_Sandstone_White"
    },
    {
      "x": -14,
      "y": 10,
      "z": 1,
      "name": "Rock_Sandstone_White"
    },
    {
      "x": -14,
      "y": 11,
      "z": 1,
      "name": "Rock_Sandstone_White"
    },
    {
      "x": -14,
      "y": 12,
      "z": 1,
      "name": "Rock_Sandstone_White"
    },
    {
      "x": -14,
      "y": 13,
      "z": 1,
      "name": "Rock_Sandstone"
    },
    {
      "x": -14,
      "y": 14,
      "z": 1,
      "name": "Soil_Gravel_Sand"
    },
    {
      "x": -14,
      "y": 15,
      "z": 1,
      "name": "Soil_Gravel_Sand"
    },
    {
      "x": -14,
      "y": 16,
      "z": 1,
      "name": "Soil_Gravel_Sand"
    },
    {
      "x": -14,
      "y": 1,
      "z": 2,
      "name": "Rock_Sandstone_White"
    },
    {
      "x": -14,
      "y": 2,
      "z": 2,
      "name": "Rock_Sandstone_White"
    },
    {
      "x": -14,
      "y": 3,
      "z": 2,
      "name": "Rock_Sandstone_White"
    },
    {
      "x": -14,
      "y": 4,
      "z": 2,
      "name": "Rock_Sandstone_White"
    },
    {
      "x": -14,
      "y": 5,
      "z": 2,
      "name": "Rock_Sandstone_White"
    },
    {
      "x": -14,
      "y": 6,
      "z": 2,
      "name": "Rock_Sandstone_White"
    },
    {
      "x": -14,
      "y": 7,
      "z": 2,
      "name": "Rock_Sandstone_White"
    },
    {
      "x": -14,
      "y": 8,
      "z": 2,
      "name": "Rock_Sandstone_White"
    },
    {
      "x": -14,
      "y": 9,
      "z": 2,
      "name": "Rock_Sandstone_White"
    },
    {
      "x": -14,
      "y": 10,
      "z": 2,
      "name": "Rock_Sandstone_White"
    },
    {
      "x": -14,
      "y": 11,
      "z": 2,
      "name": "Rock_Sandstone_White"
    },
    {
      "x": -14,
      "y": 12,
      "z": 2,
      "name": "Rock_Sandstone_White"
    },
    {
      "x": -14,
      "y": 13,
      "z": 2,
      "name": "Rock_Sandstone"
    },
    {
      "x": -14,
      "y": 14,
      "z": 2,
      "name": "Soil_Gravel_Sand"
    },
    {
      "x": -14,
      "y": 15,
      "z": 2,
      "name": "Soil_Gravel_Sand"
    },
    {
      "x": -14,
      "y": 16,
      "z": 2,
      "name": "Soil_Gravel_Sand"
    },
    {
      "x": -14,
      "y": 1,
      "z": 3,
      "name": "Rock_Sandstone_White"
    },
    {
      "x": -14,
      "y": 2,
      "z": 3,
      "name": "Rock_Sandstone_White"
    },
    {
      "x": -14,
      "y": 3,
      "z": 3,
      "name": "Rock_Sandstone_White"
    },
    {
      "x": -14,
      "y": 4,
      "z": 3,
      "name": "Rock_Sandstone_White"
    },
    {
      "x": -14,
      "y": 5,
      "z": 3,
      "name": "Rock_Sandstone_White"
    },
    {
      "x": -14,
      "y": 6,
      "z": 3,
      "name": "Rock_Sandstone_White"
    },
    {
      "x": -14,
      "y": 7,
      "z": 3,
      "name": "Rock_Sandstone_White"
    },
    {
      "x": -14,
      "y": 8,
      "z": 3,
      "name": "Rock_Sandstone_White"
    },
    {
      "x": -14,
      "y": 9,
      "z": 3,
      "name": "Rock_Sandstone_White"
    },
    {
      "x": -14,
      "y": 10,
      "z": 3,
      "name": "Rock_Sandstone_White"
    },
    {
      "x": -14,
      "y": 11,
      "z": 3,
      "name": "Rock_Sandstone_White"
    },
    {
      "x": -14,
      "y": 12,
      "z": 3,
      "name": "Rock_Sandstone_White"
    },
    {
      "x": -14,
      "y": 13,
      "z": 3,
      "name": "Rock_Sandstone"
    },
    {
      "x": -14,
      "y": 14,
      "z": 3,
      "name": "Soil_Gravel_Sand"
    },
    {
      "x": -14,
      "y": 15,
      "z": 3,
      "name": "Soil_Gravel_Sand"
    },
    {
      "x": -14,
      "y": 16,
      "z": 3,
      "name": "Soil_Gravel_Sand"
    },
    {
      "x": -14,
      "y": 1,
      "z": 4,
      "name": "Rock_Sandstone_White"
    },
    {
      "x": -14,
      "y": 2,
      "z": 4,
      "name": "Rock_Sandstone_White"
    },
    {
      "x": -14,
      "y": 3,
      "z": 4,
      "name": "Rock_Sandstone_White"
    },
    {
      "x": -14,
      "y": 4,
      "z": 4,
      "name": "Rock_Sandstone_White"
    },
    {
      "x": -14,
      "y": 5,
      "z": 4,
      "name": "Rock_Sandstone_White"
    },
    {
      "x": -14,
      "y": 7,
      "z": 4,
      "name": "Rock_Sandstone_White"
    },
    {
      "x": -14,
      "y": 8,
      "z": 4,
      "name": "Rock_Sandstone_White"
    },
    {
      "x": -14,
      "y": 9,
      "z": 4,
      "name": "Rock_Sandstone_White"
    },
    {
      "x": -14,
      "y": 10,
      "z": 4,
      "name": "Rock_Sandstone_White"
    },
    {
      "x": -14,
      "y": 11,
      "z": 4,
      "name": "Rock_Sandstone_White"
    },
    {
      "x": -14,
      "y": 12,
      "z": 4,
      "name": "Rock_Sandstone_White"
    },
    {
      "x": -14,
      "y": 14,
      "z": 4,
      "name": "Soil_Gravel_Sand"
    },
    {
      "x": -14,
      "y": 15,
      "z": 4,
      "name": "Soil_Gravel_Sand"
    },
    {
      "x": -14,
      "y": 16,
      "z": 4,
      "name": "Rock_Sandstone"
    },
    {
      "x": -14,
      "y": 3,
      "z": 5,
      "name": "Rock_Sandstone_White"
    },
    {
      "x": -14,
      "y": 4,
      "z": 5,
      "name": "Rock_Sandstone_White"
    },
    {
      "x": -14,
      "y": 5,
      "z": 5,
      "name": "Rock_Sandstone_White"
    },
    {
      "x": -14,
      "y": 7,
      "z": 5,
      "name": "Rock_Sandstone_White"
    },
    {
      "x": -14,
      "y": 8,
      "z": 5,
      "name": "Rock_Sandstone_White"
    },
    {
      "x": -14,
      "y": 9,
      "z": 5,
      "name": "Rock_Sandstone_White"
    },
    {
      "x": -14,
      "y": 14,
      "z": 5,
      "name": "Soil_Gravel_Sand"
    },
    {
      "x": -14,
      "y": 15,
      "z": 5,
      "name": "Soil_Gravel_Sand"
    },
    {
      "x": -14,
      "y": 3,
      "z": 6,
      "name": "Rock_Sandstone_White"
    },
    {
      "x": -14,
      "y": 4,
      "z": 6,
      "name": "Rock_Sandstone_White"
    },
    {
      "x": -14,
      "y": 5,
      "z": 6,
      "name": "Rock_Sandstone_White"
    },
    {
      "x": -14,
      "y": 7,
      "z": 6,
      "name": "Rock_Sandstone_White"
    },
    {
      "x": -14,
      "y": 8,
      "z": 6,
      "name": "Rock_Sandstone_White"
    },
    {
      "x": -13,
      "y": 7,
      "z": -7,
      "name": "Rock_Sandstone_White"
    },
    {
      "x": -13,
      "y": 8,
      "z": -7,
      "name": "Rock_Sandstone_White"
    },
    {
      "x": -13,
      "y": 15,
      "z": -7,
      "name": "Rock_Sandstone_White"
    },
    {
      "x": -13,
      "y": 16,
      "z": -7,
      "name": "Rock_Sandstone_White"
    },
    {
      "x": -13,
      "y": 7,
      "z": -6,
      "name": "Rock_Sandstone_White"
    },
    {
      "x": -13,
      "y": 8,
      "z": -6,
      "name": "Rock_Sandstone_White"
    },
    {
      "x": -13,
      "y": 9,
      "z": -6,
      "name": "Rock_Sandstone_White"
    },
    {
      "x": -13,
      "y": 11,
      "z": -6,
      "name": "Rock_Sandstone_White"
    },
    {
      "x": -13,
      "y": 12,
      "z": -6,
      "name": "Soil_Gravel_Sand"
    },
    {
      "x": -13,
      "y": 14,
      "z": -6,
      "name": "Soil_Gravel_Sand"
    },
    {
      "x": -13,
      "y": 15,
      "z": -6,
      "name": "Rock_Sandstone_White"
    },
    {
      "x": -13,
      "y": 16,
      "z": -6,
      "name": "Rock_Sandstone_White"
    },
    {
      "x": -13,
      "y": 3,
      "z": -5,
      "name": "Rock_Sandstone_White"
    },
    {
      "x": -13,
      "y": 4,
      "z": -5,
      "name": "Rock_Sandstone_White"
    },
    {
      "x": -13,
      "y": 5,
      "z": -5,
      "name": "Rock_Sandstone_White"
    },
    {
      "x": -13,
      "y": 6,
      "z": -5,
      "name": "Rock_Sandstone_White"
    },
    {
      "x": -13,
      "y": 7,
      "z": -5,
      "name": "Rock_Sandstone_White"
    },
    {
      "x": -13,
      "y": 8,
      "z": -5,
      "name": "Rock_Sandstone_White"
    },
    {
      "x": -13,
      "y": 9,
      "z": -5,
      "name": "Rock_Sandstone_White"
    },
    {
      "x": -13,
      "y": 10,
      "z": -5,
      "name": "Rock_Sandstone_White"
    },
    {
      "x": -13,
      "y": 11,
      "z": -5,
      "name": "Rock_Sandstone_White"
    },
    {
      "x": -13,
      "y": 12,
      "z": -5,
      "name": "Soil_Gravel_Sand"
    },
    {
      "x": -13,
      "y": 14,
      "z": -5,
      "name": "Soil_Gravel_Sand"
    },
    {
      "x": -13,
      "y": 15,
      "z": -5,
      "name": "Rock_Sandstone_White"
    },
    {
      "x": -13,
      "y": 16,
      "z": -5,
      "name": "Rock_Sandstone_White"
    },
    {
      "x": -13,
      "y": 3,
      "z": -4,
      "name": "Rock_Sandstone_White"
    },
    {
      "x": -13,
      "y": 4,
      "z": -4,
      "name": "Rock_Sandstone_White"
    },
    {
      "x": -13,
      "y": 5,
      "z": -4,
      "name": "Rock_Sandstone_White"
    },
    {
      "x": -13,
      "y": 6,
      "z": -4,
      "name": "Rock_Sandstone_White"
    },
    {
      "x": -13,
      "y": 7,
      "z": -4,
      "name": "Rock_Sandstone_White"
    },
    {
      "x": -13,
      "y": 8,
      "z": -4,
      "name": "Rock_Sandstone_White"
    },
    {
      "x": -13,
      "y": 9,
      "z": -4,
      "name": "Rock_Sandstone_White"
    },
    {
      "x": -13,
      "y": 10,
      "z": -4,
      "name": "Rock_Sandstone_White"
    },
    {
      "x": -13,
      "y": 11,
      "z": -4,
      "name": "Rock_Sandstone_White"
    },
    {
      "x": -13,
      "y": 12,
      "z": -4,
      "name": "Soil_Gravel_Sand"
    },
    {
      "x": -13,
      "y": 13,
      "z": -4,
      "name": "Soil_Gravel_Sand"
    },
    {
      "x": -13,
      "y": 14,
      "z": -4,
      "name": "Soil_Gravel_Sand"
    },
    {
      "x": -13,
      "y": 15,
      "z": -4,
      "name": "Rock_Sandstone_White"
    },
    {
      "x": -13,
      "y": 16,
      "z": -4,
      "name": "Rock_Sandstone_White"
    },
    {
      "x": -13,
      "y": 3,
      "z": -3,
      "name": "Rock_Sandstone_White"
    },
    {
      "x": -13,
      "y": 4,
      "z": -3,
      "name": "Rock_Sandstone_White"
    },
    {
      "x": -13,
      "y": 5,
      "z": -3,
      "name": "Rock_Sandstone_White"
    },
    {
      "x": -13,
      "y": 6,
      "z": -3,
      "name": "Rock_Sandstone_White"
    },
    {
      "x": -13,
      "y": 7,
      "z": -3,
      "name": "Rock_Sandstone_White"
    },
    {
      "x": -13,
      "y": 8,
      "z": -3,
      "name": "Rock_Sandstone_White"
    },
    {
      "x": -13,
      "y": 9,
      "z": -3,
      "name": "Rock_Sandstone_White"
    },
    {
      "x": -13,
      "y": 10,
      "z": -3,
      "name": "Rock_Sandstone_White"
    },
    {
      "x": -13,
      "y": 11,
      "z": -3,
      "name": "Rock_Sandstone_White"
    },
    {
      "x": -13,
      "y": 12,
      "z": -3,
      "name": "Soil_Gravel_Sand"
    },
    {
      "x": -13,
      "y": 13,
      "z": -3,
      "name": "Soil_Gravel_Sand"
    },
    {
      "x": -13,
      "y": 14,
      "z": -3,
      "name": "Soil_Gravel_Sand"
    },
    {
      "x": -13,
      "y": 15,
      "z": -3,
      "name": "Rock_Sandstone_White"
    },
    {
      "x": -13,
      "y": 16,
      "z": -3,
      "name": "Rock_Sandstone_White"
    },
    {
      "x": -13,
      "y": 1,
      "z": -2,
      "name": "Rock_Sandstone_White"
    },
    {
      "x": -13,
      "y": 2,
      "z": -2,
      "name": "Rock_Sandstone_White"
    },
    {
      "x": -13,
      "y": 3,
      "z": -2,
      "name": "Rock_Sandstone_White"
    },
    {
      "x": -13,
      "y": 4,
      "z": -2,
      "name": "Rock_Sandstone_White"
    },
    {
      "x": -13,
      "y": 5,
      "z": -2,
      "name": "Rock_Sandstone_White"
    },
    {
      "x": -13,
      "y": 6,
      "z": -2,
      "name": "Rock_Sandstone_White"
    },
    {
      "x": -13,
      "y": 7,
      "z": -2,
      "name": "Rock_Sandstone_White"
    },
    {
      "x": -13,
      "y": 8,
      "z": -2,
      "name": "Rock_Sandstone_White"
    },
    {
      "x": -13,
      "y": 9,
      "z": -2,
      "name": "Rock_Sandstone_White"
    },
    {
      "x": -13,
      "y": 10,
      "z": -2,
      "name": "Rock_Sandstone_White"
    },
    {
      "x": -13,
      "y": 11,
      "z": -2,
      "name": "Rock_Sandstone_White"
    },
    {
      "x": -13,
      "y": 12,
      "z": -2,
      "name": "Soil_Gravel_Sand"
    },
    {
      "x": -13,
      "y": 13,
      "z": -2,
      "name": "Soil_Gravel_Sand"
    },
    {
      "x": -13,
      "y": 14,
      "z": -2,
      "name": "Soil_Gravel_Sand"
    },
    {
      "x": -13,
      "y": 15,
      "z": -2,
      "name": "Rock_Sandstone_White"
    },
    {
      "x": -13,
      "y": 16,
      "z": -2,
      "name": "Rock_Sandstone_White"
    },
    {
      "x": -13,
      "y": 1,
      "z": -1,
      "name": "Rock_Sandstone_White"
    },
    {
      "x": -13,
      "y": 2,
      "z": -1,
      "name": "Rock_Sandstone_White"
    },
    {
      "x": -13,
      "y": 3,
      "z": -1,
      "name": "Rock_Sandstone_White"
    },
    {
      "x": -13,
      "y": 4,
      "z": -1,
      "name": "Rock_Sandstone_White"
    },
    {
      "x": -13,
      "y": 5,
      "z": -1,
      "name": "Rock_Sandstone_White"
    },
    {
      "x": -13,
      "y": 6,
      "z": -1,
      "name": "Rock_Sandstone_White"
    },
    {
      "x": -13,
      "y": 7,
      "z": -1,
      "name": "Rock_Sandstone_White"
    },
    {
      "x": -13,
      "y": 8,
      "z": -1,
      "name": "Rock_Sandstone_White"
    },
    {
      "x": -13,
      "y": 9,
      "z": -1,
      "name": "Rock_Sandstone_White"
    },
    {
      "x": -13,
      "y": 10,
      "z": -1,
      "name": "Rock_Sandstone_White"
    },
    {
      "x": -13,
      "y": 11,
      "z": -1,
      "name": "Rock_Sandstone_White"
    },
    {
      "x": -13,
      "y": 12,
      "z": -1,
      "name": "Rock_Sandstone_White"
    },
    {
      "x": -13,
      "y": 13,
      "z": -1,
      "name": "Soil_Gravel_Sand"
    },
    {
      "x": -13,
      "y": 14,
      "z": -1,
      "name": "Soil_Gravel_Sand"
    },
    {
      "x": -13,
      "y": 15,
      "z": -1,
      "name": "Soil_Gravel_Sand"
    },
    {
      "x": -13,
      "y": 16,
      "z": -1,
      "name": "Rock_Sandstone_White"
    },
    {
      "x": -13,
      "y": 0,
      "z": 0,
      "name": "Rock_Sandstone_White"
    },
    {
      "x": -13,
      "y": 1,
      "z": 0,
      "name": "Rock_Sandstone_White"
    },
    {
      "x": -13,
      "y": 2,
      "z": 0,
      "name": "Rock_Sandstone_White"
    },
    {
      "x": -13,
      "y": 3,
      "z": 0,
      "name": "Rock_Sandstone_White"
    },
    {
      "x": -13,
      "y": 4,
      "z": 0,
      "name": "Rock_Sandstone_White"
    },
    {
      "x": -13,
      "y": 5,
      "z": 0,
      "name": "Rock_Sandstone_White"
    },
    {
      "x": -13,
      "y": 6,
      "z": 0,
      "name": "Rock_Sandstone_White"
    },
    {
      "x": -13,
      "y": 7,
      "z": 0,
      "name": "Rock_Sandstone_White"
    },
    {
      "x": -13,
      "y": 8,
      "z": 0,
      "name": "Rock_Sandstone_White"
    },
    {
      "x": -13,
      "y": 9,
      "z": 0,
      "name": "Rock_Sandstone_White"
    },
    {
      "x": -13,
      "y": 10,
      "z": 0,
      "name": "Rock_Sandstone_White"
    },
    {
      "x": -13,
      "y": 11,
      "z": 0,
      "name": "Rock_Sandstone_White"
    },
    {
      "x": -13,
      "y": 12,
      "z": 0,
      "name": "Rock_Sandstone_White"
    },
    {
      "x": -13,
      "y": 13,
      "z": 0,
      "name": "Rock_Sandstone"
    },
    {
      "x": -13,
      "y": 14,
      "z": 0,
      "name": "Soil_Gravel_Sand"
    },
    {
      "x": -13,
      "y": 15,
      "z": 0,
      "name": "Soil_Gravel_Sand"
    },
    {
      "x": -13,
      "y": 16,
      "z": 0,
      "name": "Soil_Gravel_Sand"
    },
    {
      "x": -13,
      "y": 0,
      "z": 1,
      "name": "Rock_Sandstone_White"
    },
    {
      "x": -13,
      "y": 1,
      "z": 1,
      "name": "Rock_Sandstone_White"
    },
    {
      "x": -13,
      "y": 2,
      "z": 1,
      "name": "Rock_Sandstone_White"
    },
    {
      "x": -13,
      "y": 3,
      "z": 1,
      "name": "Rock_Sandstone_White"
    },
    {
      "x": -13,
      "y": 4,
      "z": 1,
      "name": "Rock_Sandstone_White"
    },
    {
      "x": -13,
      "y": 5,
      "z": 1,
      "name": "Rock_Sandstone_White"
    },
    {
      "x": -13,
      "y": 6,
      "z": 1,
      "name": "Rock_Sandstone_White"
    },
    {
      "x": -13,
      "y": 7,
      "z": 1,
      "name": "Rock_Sandstone_White"
    },
    {
      "x": -13,
      "y": 8,
      "z": 1,
      "name": "Rock_Sandstone_White"
    },
    {
      "x": -13,
      "y": 9,
      "z": 1,
      "name": "Rock_Sandstone_White"
    },
    {
      "x": -13,
      "y": 10,
      "z": 1,
      "name": "Rock_Sandstone"
    },
    {
      "x": -13,
      "y": 11,
      "z": 1,
      "name": "Rock_Sandstone_White"
    },
    {
      "x": -13,
      "y": 12,
      "z": 1,
      "name": "Rock_Sandstone_White"
    },
    {
      "x": -13,
      "y": 13,
      "z": 1,
      "name": "Rock_Sandstone"
    },
    {
      "x": -13,
      "y": 14,
      "z": 1,
      "name": "Soil_Gravel_Sand"
    },
    {
      "x": -13,
      "y": 15,
      "z": 1,
      "name": "Soil_Gravel_Sand"
    },
    {
      "x": -13,
      "y": 16,
      "z": 1,
      "name": "Soil_Gravel_Sand"
    },
    {
      "x": -13,
      "y": 0,
      "z": 2,
      "name": "Rock_Sandstone_White"
    },
    {
      "x": -13,
      "y": 1,
      "z": 2,
      "name": "Rock_Sandstone_White"
    },
    {
      "x": -13,
      "y": 2,
      "z": 2,
      "name": "Rock_Sandstone_White"
    },
    {
      "x": -13,
      "y": 3,
      "z": 2,
      "name": "Rock_Sandstone_White"
    },
    {
      "x": -13,
      "y": 4,
      "z": 2,
      "name": "Rock_Sandstone_White"
    },
    {
      "x": -13,
      "y": 5,
      "z": 2,
      "name": "Rock_Sandstone_White"
    },
    {
      "x": -13,
      "y": 6,
      "z": 2,
      "name": "Rock_Sandstone_White"
    },
    {
      "x": -13,
      "y": 7,
      "z": 2,
      "name": "Rock_Sandstone_White"
    },
    {
      "x": -13,
      "y": 8,
      "z": 2,
      "name": "Rock_Sandstone_White"
    },
    {
      "x": -13,
      "y": 9,
      "z": 2,
      "name": "Rock_Sandstone_White"
    },
    {
      "x": -13,
      "y": 10,
      "z": 2,
      "name": "Rock_Sandstone"
    },
    {
      "x": -13,
      "y": 11,
      "z": 2,
      "name": "Rock_Sandstone_White"
    },
    {
      "x": -13,
      "y": 12,
      "z": 2,
      "name": "Rock_Sandstone_White"
    },
    {
      "x": -13,
      "y": 13,
      "z": 2,
      "name": "Rock_Sandstone"
    },
    {
      "x": -13,
      "y": 14,
      "z": 2,
      "name": "Soil_Gravel_Sand"
    },
    {
      "x": -13,
      "y": 15,
      "z": 2,
      "name": "Soil_Gravel_Sand"
    },
    {
      "x": -13,
      "y": 16,
      "z": 2,
      "name": "Soil_Gravel_Sand"
    },
    {
      "x": -13,
      "y": 1,
      "z": 3,
      "name": "Rock_Sandstone_White"
    },
    {
      "x": -13,
      "y": 2,
      "z": 3,
      "name": "Rock_Sandstone_White"
    },
    {
      "x": -13,
      "y": 3,
      "z": 3,
      "name": "Rock_Sandstone_White"
    },
    {
      "x": -13,
      "y": 4,
      "z": 3,
      "name": "Rock_Sandstone_White"
    },
    {
      "x": -13,
      "y": 5,
      "z": 3,
      "name": "Rock_Sandstone_White"
    },
    {
      "x": -13,
      "y": 6,
      "z": 3,
      "name": "Rock_Sandstone_White"
    },
    {
      "x": -13,
      "y": 7,
      "z": 3,
      "name": "Rock_Sandstone_White"
    },
    {
      "x": -13,
      "y": 8,
      "z": 3,
      "name": "Rock_Sandstone_White"
    },
    {
      "x": -13,
      "y": 9,
      "z": 3,
      "name": "Rock_Sandstone_White"
    },
    {
      "x": -13,
      "y": 10,
      "z": 3,
      "name": "Rock_Sandstone_White"
    },
    {
      "x": -13,
      "y": 11,
      "z": 3,
      "name": "Rock_Sandstone_White"
    },
    {
      "x": -13,
      "y": 12,
      "z": 3,
      "name": "Rock_Sandstone_White"
    },
    {
      "x": -13,
      "y": 13,
      "z": 3,
      "name": "Rock_Sandstone"
    },
    {
      "x": -13,
      "y": 14,
      "z": 3,
      "name": "Soil_Gravel_Sand"
    },
    {
      "x": -13,
      "y": 15,
      "z": 3,
      "name": "Soil_Gravel_Sand"
    },
    {
      "x": -13,
      "y": 16,
      "z": 3,
      "name": "Soil_Gravel_Sand"
    },
    {
      "x": -13,
      "y": 1,
      "z": 4,
      "name": "Rock_Sandstone_White"
    },
    {
      "x": -13,
      "y": 2,
      "z": 4,
      "name": "Rock_Sandstone_White"
    },
    {
      "x": -13,
      "y": 3,
      "z": 4,
      "name": "Rock_Sandstone_White"
    },
    {
      "x": -13,
      "y": 4,
      "z": 4,
      "name": "Rock_Sandstone_White"
    },
    {
      "x": -13,
      "y": 5,
      "z": 4,
      "name": "Rock_Sandstone_White"
    },
    {
      "x": -13,
      "y": 7,
      "z": 4,
      "name": "Rock_Sandstone_White"
    },
    {
      "x": -13,
      "y": 8,
      "z": 4,
      "name": "Rock_Sandstone_White"
    },
    {
      "x": -13,
      "y": 9,
      "z": 4,
      "name": "Rock_Sandstone_White"
    },
    {
      "x": -13,
      "y": 10,
      "z": 4,
      "name": "Rock_Sandstone_White"
    },
    {
      "x": -13,
      "y": 11,
      "z": 4,
      "name": "Rock_Sandstone_White"
    },
    {
      "x": -13,
      "y": 12,
      "z": 4,
      "name": "Rock_Sandstone_White"
    },
    {
      "x": -13,
      "y": 13,
      "z": 4,
      "name": "Soil_Gravel_Sand"
    },
    {
      "x": -13,
      "y": 14,
      "z": 4,
      "name": "Soil_Gravel_Sand"
    },
    {
      "x": -13,
      "y": 15,
      "z": 4,
      "name": "Soil_Gravel_Sand"
    },
    {
      "x": -13,
      "y": 16,
      "z": 4,
      "name": "Rock_Sandstone"
    },
    {
      "x": -13,
      "y": 3,
      "z": 5,
      "name": "Rock_Sandstone_White"
    },
    {
      "x": -13,
      "y": 4,
      "z": 5,
      "name": "Rock_Sandstone_White"
    },
    {
      "x": -13,
      "y": 5,
      "z": 5,
      "name": "Rock_Sandstone_White"
    },
    {
      "x": -13,
      "y": 7,
      "z": 5,
      "name": "Rock_Sandstone_White"
    },
    {
      "x": -13,
      "y": 8,
      "z": 5,
      "name": "Rock_Sandstone_White"
    },
    {
      "x": -13,
      "y": 9,
      "z": 5,
      "name": "Rock_Sandstone_White"
    },
    {
      "x": -13,
      "y": 11,
      "z": 5,
      "name": "Rock_Sandstone_White"
    },
    {
      "x": -13,
      "y": 12,
      "z": 5,
      "name": "Rock_Sandstone_White"
    },
    {
      "x": -13,
      "y": 14,
      "z": 5,
      "name": "Soil_Gravel_Sand"
    },
    {
      "x": -13,
      "y": 15,
      "z": 5,
      "name": "Soil_Gravel_Sand"
    },
    {
      "x": -13,
      "y": 3,
      "z": 6,
      "name": "Rock_Sandstone_White"
    },
    {
      "x": -13,
      "y": 4,
      "z": 6,
      "name": "Rock_Sandstone_White"
    },
    {
      "x": -13,
      "y": 5,
      "z": 6,
      "name": "Rock_Sandstone_White"
    },
    {
      "x": -13,
      "y": 7,
      "z": 6,
      "name": "Rock_Sandstone_White"
    },
    {
      "x": -13,
      "y": 8,
      "z": 6,
      "name": "Rock_Sandstone_White"
    },
    {
      "x": -13,
      "y": 9,
      "z": 6,
      "name": "Rock_Sandstone_White"
    },
    {
      "x": -13,
      "y": 14,
      "z": 6,
      "name": "Soil_Gravel_Sand"
    },
    {
      "x": -13,
      "y": 15,
      "z": 6,
      "name": "Soil_Gravel_Sand"
    },
    {
      "x": -12,
      "y": 16,
      "z": -8,
      "name": "Rock_Sandstone_White"
    },
    {
      "x": -12,
      "y": 17,
      "z": -8,
      "name": "Rock_Sandstone_Brick_Decorative"
    },
    {
      "x": -12,
      "y": 18,
      "z": -8,
      "name": "Rock_Sandstone_Brick_Decorative"
    },
    {
      "x": -12,
      "y": 19,
      "z": -8,
      "name": "Rock_Sandstone_Brick_Decorative"
    },
    {
      "x": -12,
      "y": 20,
      "z": -8,
      "name": "Rock_Sandstone_Brick_Decorative"
    },
    {
      "x": -12,
      "y": 7,
      "z": -7,
      "name": "Rock_Sandstone_White"
    },
    {
      "x": -12,
      "y": 8,
      "z": -7,
      "name": "Rock_Sandstone_White"
    },
    {
      "x": -12,
      "y": 11,
      "z": -7,
      "name": "Rock_Sandstone_White"
    },
    {
      "x": -12,
      "y": 15,
      "z": -7,
      "name": "Rock_Sandstone_White"
    },
    {
      "x": -12,
      "y": 16,
      "z": -7,
      "name": "Rock_Sandstone_White"
    },
    {
      "x": -12,
      "y": 17,
      "z": -7,
      "name": "Rock_Sandstone_Brick_Decorative"
    },
    {
      "x": -12,
      "y": 18,
      "z": -7,
      "name": "Rock_Sandstone_Brick_Decorative"
    },
    {
      "x": -12,
      "y": 19,
      "z": -7,
      "name": "Rock_Sandstone_Brick_Decorative"
    },
    {
      "x": -12,
      "y": 20,
      "z": -7,
      "name": "Rock_Sandstone_Brick_Decorative"
    },
    {
      "x": -12,
      "y": 3,
      "z": -6,
      "name": "Rock_Sandstone_White"
    },
    {
      "x": -12,
      "y": 4,
      "z": -6,
      "name": "Rock_Sandstone_White"
    },
    {
      "x": -12,
      "y": 5,
      "z": -6,
      "name": "Rock_Sandstone_White"
    },
    {
      "x": -12,
      "y": 6,
      "z": -6,
      "name": "Rock_Sandstone_White"
    },
    {
      "x": -12,
      "y": 7,
      "z": -6,
      "name": "Rock_Sandstone_White"
    },
    {
      "x": -12,
      "y": 8,
      "z": -6,
      "name": "Rock_Sandstone_White"
    },
    {
      "x": -12,
      "y": 9,
      "z": -6,
      "name": "Rock_Sandstone_White"
    },
    {
      "x": -12,
      "y": 10,
      "z": -6,
      "name": "Rock_Sandstone_White"
    },
    {
      "x": -12,
      "y": 11,
      "z": -6,
      "name": "Rock_Sandstone_White"
    },
    {
      "x": -12,
      "y": 12,
      "z": -6,
      "name": "Soil_Gravel_Sand"
    },
    {
      "x": -12,
      "y": 14,
      "z": -6,
      "name": "Soil_Gravel_Sand"
    },
    {
      "x": -12,
      "y": 15,
      "z": -6,
      "name": "Rock_Sandstone_White"
    },
    {
      "x": -12,
      "y": 16,
      "z": -6,
      "name": "Rock_Sandstone_White"
    },
    {
      "x": -12,
      "y": 17,
      "z": -6,
      "name": "Rock_Sandstone_Brick_Decorative"
    },
    {
      "x": -12,
      "y": 18,
      "z": -6,
      "name": "Rock_Sandstone_Brick_Decorative"
    },
    {
      "x": -12,
      "y": 19,
      "z": -6,
      "name": "Rock_Sandstone_Brick_Decorative"
    },
    {
      "x": -12,
      "y": 20,
      "z": -6,
      "name": "Rock_Sandstone_Brick_Decorative"
    },
    {
      "x": -12,
      "y": 3,
      "z": -5,
      "name": "Rock_Sandstone_White"
    },
    {
      "x": -12,
      "y": 4,
      "z": -5,
      "name": "Rock_Sandstone_White"
    },
    {
      "x": -12,
      "y": 5,
      "z": -5,
      "name": "Rock_Sandstone_White"
    },
    {
      "x": -12,
      "y": 6,
      "z": -5,
      "name": "Rock_Sandstone_White"
    },
    {
      "x": -12,
      "y": 7,
      "z": -5,
      "name": "Rock_Sandstone_White"
    },
    {
      "x": -12,
      "y": 8,
      "z": -5,
      "name": "Rock_Sandstone_White"
    },
    {
      "x": -12,
      "y": 9,
      "z": -5,
      "name": "Rock_Sandstone_White"
    },
    {
      "x": -12,
      "y": 10,
      "z": -5,
      "name": "Rock_Sandstone_White"
    },
    {
      "x": -12,
      "y": 11,
      "z": -5,
      "name": "Rock_Sandstone_White"
    },
    {
      "x": -12,
      "y": 12,
      "z": -5,
      "name": "Soil_Gravel_Sand"
    },
    {
      "x": -12,
      "y": 13,
      "z": -5,
      "name": "Soil_Gravel_Sand"
    },
    {
      "x": -12,
      "y": 14,
      "z": -5,
      "name": "Soil_Gravel_Sand"
    },
    {
      "x": -12,
      "y": 15,
      "z": -5,
      "name": "Rock_Sandstone_White"
    },
    {
      "x": -12,
      "y": 16,
      "z": -5,
      "name": "Rock_Sandstone_White"
    },
    {
      "x": -12,
      "y": 3,
      "z": -4,
      "name": "Rock_Sandstone_White"
    },
    {
      "x": -12,
      "y": 4,
      "z": -4,
      "name": "Rock_Sandstone_White"
    },
    {
      "x": -12,
      "y": 5,
      "z": -4,
      "name": "Rock_Sandstone_White"
    },
    {
      "x": -12,
      "y": 6,
      "z": -4,
      "name": "Rock_Sandstone_White"
    },
    {
      "x": -12,
      "y": 7,
      "z": -4,
      "name": "Rock_Sandstone_White"
    },
    {
      "x": -12,
      "y": 8,
      "z": -4,
      "name": "Rock_Sandstone_White"
    },
    {
      "x": -12,
      "y": 9,
      "z": -4,
      "name": "Rock_Sandstone_White"
    },
    {
      "x": -12,
      "y": 10,
      "z": -4,
      "name": "Rock_Sandstone_White"
    },
    {
      "x": -12,
      "y": 11,
      "z": -4,
      "name": "Rock_Sandstone_White"
    },
    {
      "x": -12,
      "y": 12,
      "z": -4,
      "name": "Soil_Gravel_Sand"
    },
    {
      "x": -12,
      "y": 13,
      "z": -4,
      "name": "Soil_Gravel_Sand"
    },
    {
      "x": -12,
      "y": 14,
      "z": -4,
      "name": "Soil_Gravel_Sand"
    },
    {
      "x": -12,
      "y": 15,
      "z": -4,
      "name": "Rock_Sandstone_White"
    },
    {
      "x": -12,
      "y": 16,
      "z": -4,
      "name": "Rock_Sandstone_White"
    },
    {
      "x": -12,
      "y": 1,
      "z": -3,
      "name": "Rock_Sandstone_White"
    },
    {
      "x": -12,
      "y": 2,
      "z": -3,
      "name": "Rock_Sandstone_White"
    },
    {
      "x": -12,
      "y": 3,
      "z": -3,
      "name": "Rock_Sandstone_White"
    },
    {
      "x": -12,
      "y": 4,
      "z": -3,
      "name": "Rock_Sandstone_White"
    },
    {
      "x": -12,
      "y": 5,
      "z": -3,
      "name": "Rock_Sandstone_White"
    },
    {
      "x": -12,
      "y": 6,
      "z": -3,
      "name": "Rock_Sandstone_White"
    },
    {
      "x": -12,
      "y": 7,
      "z": -3,
      "name": "Rock_Sandstone_White"
    },
    {
      "x": -12,
      "y": 8,
      "z": -3,
      "name": "Rock_Sandstone_White"
    },
    {
      "x": -12,
      "y": 9,
      "z": -3,
      "name": "Rock_Sandstone_White"
    },
    {
      "x": -12,
      "y": 10,
      "z": -3,
      "name": "Rock_Sandstone_White"
    },
    {
      "x": -12,
      "y": 11,
      "z": -3,
      "name": "Rock_Sandstone_White"
    },
    {
      "x": -12,
      "y": 12,
      "z": -3,
      "name": "Soil_Gravel_Sand"
    },
    {
      "x": -12,
      "y": 13,
      "z": -3,
      "name": "Soil_Gravel_Sand"
    },
    {
      "x": -12,
      "y": 14,
      "z": -3,
      "name": "Soil_Gravel_Sand"
    },
    {
      "x": -12,
      "y": 15,
      "z": -3,
      "name": "Rock_Sandstone_White"
    },
    {
      "x": -12,
      "y": 16,
      "z": -3,
      "name": "Rock_Sandstone_White"
    },
    {
      "x": -12,
      "y": 19,
      "z": -3,
      "name": "Soil_Gravel_Sand"
    },
    {
      "x": -12,
      "y": 20,
      "z": -3,
      "name": "Rock_Sandstone"
    },
    {
      "x": -12,
      "y": 1,
      "z": -2,
      "name": "Rock_Sandstone_White"
    },
    {
      "x": -12,
      "y": 2,
      "z": -2,
      "name": "Rock_Sandstone_White"
    },
    {
      "x": -12,
      "y": 3,
      "z": -2,
      "name": "Rock_Sandstone_White"
    },
    {
      "x": -12,
      "y": 4,
      "z": -2,
      "name": "Rock_Sandstone_White"
    },
    {
      "x": -12,
      "y": 5,
      "z": -2,
      "name": "Rock_Sandstone_White"
    },
    {
      "x": -12,
      "y": 6,
      "z": -2,
      "name": "Rock_Sandstone_White"
    },
    {
      "x": -12,
      "y": 7,
      "z": -2,
      "name": "Rock_Sandstone_White"
    },
    {
      "x": -12,
      "y": 8,
      "z": -2,
      "name": "Rock_Sandstone_White"
    },
    {
      "x": -12,
      "y": 9,
      "z": -2,
      "name": "Rock_Sandstone_White"
    },
    {
      "x": -12,
      "y": 10,
      "z": -2,
      "name": "Rock_Sandstone_White"
    },
    {
      "x": -12,
      "y": 11,
      "z": -2,
      "name": "Rock_Sandstone_White"
    },
    {
      "x": -12,
      "y": 12,
      "z": -2,
      "name": "Soil_Gravel_Sand"
    },
    {
      "x": -12,
      "y": 13,
      "z": -2,
      "name": "Soil_Gravel_Sand"
    },
    {
      "x": -12,
      "y": 14,
      "z": -2,
      "name": "Soil_Gravel_Sand"
    },
    {
      "x": -12,
      "y": 15,
      "z": -2,
      "name": "Rock_Sandstone_White"
    },
    {
      "x": -12,
      "y": 16,
      "z": -2,
      "name": "Rock_Sandstone_White"
    },
    {
      "x": -12,
      "y": 17,
      "z": -2,
      "name": "Soil_Gravel_Sand"
    },
    {
      "x": -12,
      "y": 19,
      "z": -2,
      "name": "Soil_Gravel_Sand"
    },
    {
      "x": -12,
      "y": 20,
      "z": -2,
      "name": "Rock_Sandstone"
    },
    {
      "x": -12,
      "y": 0,
      "z": -1,
      "name": "Rock_Sandstone_White"
    },
    {
      "x": -12,
      "y": 1,
      "z": -1,
      "name": "Rock_Sandstone_White"
    },
    {
      "x": -12,
      "y": 2,
      "z": -1,
      "name": "Rock_Sandstone_White"
    },
    {
      "x": -12,
      "y": 3,
      "z": -1,
      "name": "Rock_Sandstone_White"
    },
    {
      "x": -12,
      "y": 4,
      "z": -1,
      "name": "Rock_Sandstone_White"
    },
    {
      "x": -12,
      "y": 5,
      "z": -1,
      "name": "Rock_Sandstone_White"
    },
    {
      "x": -12,
      "y": 6,
      "z": -1,
      "name": "Rock_Sandstone_White"
    },
    {
      "x": -12,
      "y": 7,
      "z": -1,
      "name": "Rock_Sandstone_White"
    },
    {
      "x": -12,
      "y": 8,
      "z": -1,
      "name": "Rock_Sandstone_White"
    },
    {
      "x": -12,
      "y": 9,
      "z": -1,
      "name": "Rock_Sandstone_White"
    },
    {
      "x": -12,
      "y": 10,
      "z": -1,
      "name": "Rock_Sandstone_White"
    },
    {
      "x": -12,
      "y": 11,
      "z": -1,
      "name": "Rock_Sandstone_White"
    },
    {
      "x": -12,
      "y": 12,
      "z": -1,
      "name": "Rock_Sandstone_White"
    },
    {
      "x": -12,
      "y": 13,
      "z": -1,
      "name": "Soil_Gravel_Sand"
    },
    {
      "x": -12,
      "y": 14,
      "z": -1,
      "name": "Soil_Gravel_Sand"
    },
    {
      "x": -12,
      "y": 15,
      "z": -1,
      "name": "Soil_Gravel_Sand"
    },
    {
      "x": -12,
      "y": 16,
      "z": -1,
      "name": "Rock_Sandstone_White"
    },
    {
      "x": -12,
      "y": 17,
      "z": -1,
      "name": "Rock_Sandstone_White"
    },
    {
      "x": -12,
      "y": 19,
      "z": -1,
      "name": "Soil_Gravel_Sand"
    },
    {
      "x": -12,
      "y": 20,
      "z": -1,
      "name": "Soil_Gravel_Sand"
    },
    {
      "x": -12,
      "y": 0,
      "z": 0,
      "name": "Rock_Sandstone_White"
    },
    {
      "x": -12,
      "y": 1,
      "z": 0,
      "name": "Rock_Sandstone_White"
    },
    {
      "x": -12,
      "y": 2,
      "z": 0,
      "name": "Rock_Sandstone_White"
    },
    {
      "x": -12,
      "y": 3,
      "z": 0,
      "name": "Rock_Sandstone_White"
    },
    {
      "x": -12,
      "y": 4,
      "z": 0,
      "name": "Rock_Sandstone_White"
    },
    {
      "x": -12,
      "y": 5,
      "z": 0,
      "name": "Rock_Sandstone_White"
    },
    {
      "x": -12,
      "y": 6,
      "z": 0,
      "name": "Rock_Sandstone_White"
    },
    {
      "x": -12,
      "y": 7,
      "z": 0,
      "name": "Rock_Sandstone_White"
    },
    {
      "x": -12,
      "y": 8,
      "z": 0,
      "name": "Rock_Sandstone_White"
    },
    {
      "x": -12,
      "y": 9,
      "z": 0,
      "name": "Rock_Sandstone_White"
    },
    {
      "x": -12,
      "y": 10,
      "z": 0,
      "name": "Rock_Sandstone_White"
    },
    {
      "x": -12,
      "y": 11,
      "z": 0,
      "name": "Rock_Sandstone_White"
    },
    {
      "x": -12,
      "y": 12,
      "z": 0,
      "name": "Rock_Sandstone_White"
    },
    {
      "x": -12,
      "y": 13,
      "z": 0,
      "name": "Rock_Sandstone"
    },
    {
      "x": -12,
      "y": 14,
      "z": 0,
      "name": "Soil_Gravel_Sand"
    },
    {
      "x": -12,
      "y": 15,
      "z": 0,
      "name": "Soil_Gravel_Sand"
    },
    {
      "x": -12,
      "y": 16,
      "z": 0,
      "name": "Soil_Gravel_Sand"
    },
    {
      "x": -12,
      "y": 17,
      "z": 0,
      "name": "Rock_Sandstone_White"
    },
    {
      "x": -12,
      "y": 0,
      "z": 1,
      "name": "Rock_Sandstone_White"
    },
    {
      "x": -12,
      "y": 1,
      "z": 1,
      "name": "Rock_Sandstone_White"
    },
    {
      "x": -12,
      "y": 2,
      "z": 1,
      "name": "Rock_Sandstone_White"
    },
    {
      "x": -12,
      "y": 3,
      "z": 1,
      "name": "Rock_Sandstone_White"
    },
    {
      "x": -12,
      "y": 4,
      "z": 1,
      "name": "Rock_Sandstone_White"
    },
    {
      "x": -12,
      "y": 5,
      "z": 1,
      "name": "Rock_Sandstone_White"
    },
    {
      "x": -12,
      "y": 6,
      "z": 1,
      "name": "Rock_Sandstone_White"
    },
    {
      "x": -12,
      "y": 7,
      "z": 1,
      "name": "Rock_Sandstone_White"
    },
    {
      "x": -12,
      "y": 8,
      "z": 1,
      "name": "Rock_Sandstone_White"
    },
    {
      "x": -12,
      "y": 9,
      "z": 1,
      "name": "Rock_Sandstone_White"
    },
    {
      "x": -12,
      "y": 10,
      "z": 1,
      "name": "Rock_Sandstone"
    },
    {
      "x": -12,
      "y": 11,
      "z": 1,
      "name": "Rock_Sandstone_White"
    },
    {
      "x": -12,
      "y": 12,
      "z": 1,
      "name": "Rock_Sandstone_White"
    },
    {
      "x": -12,
      "y": 13,
      "z": 1,
      "name": "Rock_Sandstone"
    },
    {
      "x": -12,
      "y": 14,
      "z": 1,
      "name": "Soil_Gravel_Sand"
    },
    {
      "x": -12,
      "y": 15,
      "z": 1,
      "name": "Soil_Gravel_Sand"
    },
    {
      "x": -12,
      "y": 16,
      "z": 1,
      "name": "Soil_Gravel_Sand"
    },
    {
      "x": -12,
      "y": 17,
      "z": 1,
      "name": "Rock_Sandstone_White"
    },
    {
      "x": -12,
      "y": 0,
      "z": 2,
      "name": "Rock_Sandstone_White"
    },
    {
      "x": -12,
      "y": 1,
      "z": 2,
      "name": "Rock_Sandstone_White"
    },
    {
      "x": -12,
      "y": 2,
      "z": 2,
      "name": "Rock_Sandstone_White"
    },
    {
      "x": -12,
      "y": 3,
      "z": 2,
      "name": "Rock_Sandstone_White"
    },
    {
      "x": -12,
      "y": 4,
      "z": 2,
      "name": "Rock_Sandstone_White"
    },
    {
      "x": -12,
      "y": 5,
      "z": 2,
      "name": "Rock_Sandstone_White"
    },
    {
      "x": -12,
      "y": 6,
      "z": 2,
      "name": "Rock_Sandstone_White"
    },
    {
      "x": -12,
      "y": 7,
      "z": 2,
      "name": "Rock_Sandstone_White"
    },
    {
      "x": -12,
      "y": 8,
      "z": 2,
      "name": "Rock_Sandstone_White"
    },
    {
      "x": -12,
      "y": 9,
      "z": 2,
      "name": "Rock_Sandstone_White"
    },
    {
      "x": -12,
      "y": 10,
      "z": 2,
      "name": "Rock_Sandstone_White"
    },
    {
      "x": -12,
      "y": 11,
      "z": 2,
      "name": "Rock_Sandstone_White"
    },
    {
      "x": -12,
      "y": 12,
      "z": 2,
      "name": "Rock_Sandstone_White"
    },
    {
      "x": -12,
      "y": 13,
      "z": 2,
      "name": "Rock_Sandstone"
    },
    {
      "x": -12,
      "y": 14,
      "z": 2,
      "name": "Soil_Gravel_Sand"
    },
    {
      "x": -12,
      "y": 15,
      "z": 2,
      "name": "Soil_Gravel_Sand"
    },
    {
      "x": -12,
      "y": 16,
      "z": 2,
      "name": "Soil_Gravel_Sand"
    },
    {
      "x": -12,
      "y": 17,
      "z": 2,
      "name": "Rock_Sandstone_White"
    },
    {
      "x": -12,
      "y": 0,
      "z": 3,
      "name": "Rock_Sandstone_White"
    },
    {
      "x": -12,
      "y": 1,
      "z": 3,
      "name": "Rock_Sandstone_White"
    },
    {
      "x": -12,
      "y": 2,
      "z": 3,
      "name": "Rock_Sandstone_White"
    },
    {
      "x": -12,
      "y": 3,
      "z": 3,
      "name": "Rock_Sandstone_White"
    },
    {
      "x": -12,
      "y": 4,
      "z": 3,
      "name": "Rock_Sandstone_White"
    },
    {
      "x": -12,
      "y": 5,
      "z": 3,
      "name": "Rock_Sandstone_White"
    },
    {
      "x": -12,
      "y": 6,
      "z": 3,
      "name": "Rock_Sandstone_White"
    },
    {
      "x": -12,
      "y": 7,
      "z": 3,
      "name": "Rock_Sandstone_White"
    },
    {
      "x": -12,
      "y": 8,
      "z": 3,
      "name": "Rock_Sandstone_White"
    },
    {
      "x": -12,
      "y": 9,
      "z": 3,
      "name": "Rock_Sandstone_White"
    },
    {
      "x": -12,
      "y": 10,
      "z": 3,
      "name": "Rock_Sandstone_White"
    },
    {
      "x": -12,
      "y": 11,
      "z": 3,
      "name": "Rock_Sandstone_White"
    },
    {
      "x": -12,
      "y": 12,
      "z": 3,
      "name": "Rock_Sandstone_White"
    },
    {
      "x": -12,
      "y": 13,
      "z": 3,
      "name": "Soil_Gravel_Sand"
    },
    {
      "x": -12,
      "y": 14,
      "z": 3,
      "name": "Soil_Gravel_Sand"
    },
    {
      "x": -12,
      "y": 15,
      "z": 3,
      "name": "Soil_Gravel_Sand"
    },
    {
      "x": -12,
      "y": 16,
      "z": 3,
      "name": "Rock_Sandstone"
    },
    {
      "x": -12,
      "y": 17,
      "z": 3,
      "name": "Rock_Sandstone_White"
    },
    {
      "x": -12,
      "y": 1,
      "z": 4,
      "name": "Rock_Sandstone_White"
    },
    {
      "x": -12,
      "y": 2,
      "z": 4,
      "name": "Rock_Sandstone_White"
    },
    {
      "x": -12,
      "y": 3,
      "z": 4,
      "name": "Rock_Sandstone_White"
    },
    {
      "x": -12,
      "y": 4,
      "z": 4,
      "name": "Rock_Sandstone_White"
    },
    {
      "x": -12,
      "y": 5,
      "z": 4,
      "name": "Rock_Sandstone_White"
    },
    {
      "x": -12,
      "y": 6,
      "z": 4,
      "name": "Rock_Sandstone_White"
    },
    {
      "x": -12,
      "y": 7,
      "z": 4,
      "name": "Rock_Sandstone_White"
    },
    {
      "x": -12,
      "y": 8,
      "z": 4,
      "name": "Rock_Sandstone_White"
    },
    {
      "x": -12,
      "y": 9,
      "z": 4,
      "name": "Rock_Sandstone_White"
    },
    {
      "x": -12,
      "y": 10,
      "z": 4,
      "name": "Rock_Sandstone_White"
    },
    {
      "x": -12,
      "y": 11,
      "z": 4,
      "name": "Rock_Sandstone_White"
    },
    {
      "x": -12,
      "y": 12,
      "z": 4,
      "name": "Rock_Sandstone_White"
    },
    {
      "x": -12,
      "y": 13,
      "z": 4,
      "name": "Soil_Gravel_Sand"
    },
    {
      "x": -12,
      "y": 14,
      "z": 4,
      "name": "Soil_Gravel_Sand"
    },
    {
      "x": -12,
      "y": 15,
      "z": 4,
      "name": "Soil_Gravel_Sand"
    },
    {
      "x": -12,
      "y": 16,
      "z": 4,
      "name": "Rock_Sandstone"
    },
    {
      "x": -12,
      "y": 3,
      "z": 5,
      "name": "Rock_Sandstone_White"
    },
    {
      "x": -12,
      "y": 4,
      "z": 5,
      "name": "Rock_Sandstone_White"
    },
    {
      "x": -12,
      "y": 5,
      "z": 5,
      "name": "Rock_Sandstone_White"
    },
    {
      "x": -12,
      "y": 6,
      "z": 5,
      "name": "Rock_Sandstone_White"
    },
    {
      "x": -12,
      "y": 7,
      "z": 5,
      "name": "Rock_Sandstone_White"
    },
    {
      "x": -12,
      "y": 8,
      "z": 5,
      "name": "Rock_Sandstone_White"
    },
    {
      "x": -12,
      "y": 9,
      "z": 5,
      "name": "Rock_Sandstone_White"
    },
    {
      "x": -12,
      "y": 10,
      "z": 5,
      "name": "Rock_Sandstone_White"
    },
    {
      "x": -12,
      "y": 11,
      "z": 5,
      "name": "Rock_Sandstone_White"
    },
    {
      "x": -12,
      "y": 12,
      "z": 5,
      "name": "Rock_Sandstone_White"
    },
    {
      "x": -12,
      "y": 13,
      "z": 5,
      "name": "Soil_Gravel_Sand"
    },
    {
      "x": -12,
      "y": 14,
      "z": 5,
      "name": "Soil_Gravel_Sand"
    },
    {
      "x": -12,
      "y": 15,
      "z": 5,
      "name": "Soil_Gravel_Sand"
    },
    {
      "x": -12,
      "y": 16,
      "z": 5,
      "name": "Rock_Sandstone"
    },
    {
      "x": -12,
      "y": 3,
      "z": 6,
      "name": "Rock_Sandstone_White"
    },
    {
      "x": -12,
      "y": 4,
      "z": 6,
      "name": "Rock_Sandstone_White"
    },
    {
      "x": -12,
      "y": 5,
      "z": 6,
      "name": "Rock_Sandstone_White"
    },
    {
      "x": -12,
      "y": 7,
      "z": 6,
      "name": "Rock_Sandstone_White"
    },
    {
      "x": -12,
      "y": 8,
      "z": 6,
      "name": "Rock_Sandstone_White"
    },
    {
      "x": -12,
      "y": 9,
      "z": 6,
      "name": "Rock_Sandstone_White"
    },
    {
      "x": -12,
      "y": 11,
      "z": 6,
      "name": "Rock_Sandstone_White"
    },
    {
      "x": -12,
      "y": 12,
      "z": 6,
      "name": "Rock_Sandstone_White"
    },
    {
      "x": -12,
      "y": 14,
      "z": 6,
      "name": "Soil_Gravel_Sand"
    },
    {
      "x": -12,
      "y": 15,
      "z": 6,
      "name": "Soil_Gravel_Sand"
    },
    {
      "x": -12,
      "y": 7,
      "z": 7,
      "name": "Rock_Sandstone_White"
    },
    {
      "x": -12,
      "y": 8,
      "z": 7,
      "name": "Rock_Sandstone_White"
    },
    {
      "x": -12,
      "y": 9,
      "z": 7,
      "name": "Rock_Sandstone_White"
    },
    {
      "x": -12,
      "y": 11,
      "z": 7,
      "name": "Rock_Sandstone_White"
    },
    {
      "x": -12,
      "y": 12,
      "z": 7,
      "name": "Rock_Sandstone_White"
    },
    {
      "x": -11,
      "y": 17,
      "z": -9,
      "name": "Rock_Sandstone_Brick_Smooth_Half",
      "rotation": 6
    },
    {
      "x": -11,
      "y": 18,
      "z": -9,
      "name": "Rock_Sandstone_Brick_Smooth_Half",
      "rotation": 6
    },
    {
      "x": -11,
      "y": 19,
      "z": -9,
      "name": "Rock_Sandstone_Brick_Smooth_Half",
      "rotation": 6
    },
    {
      "x": -11,
      "y": 20,
      "z": -9,
      "name": "Rock_Sandstone_Brick_Smooth_Half",
      "rotation": 6
    },
    {
      "x": -11,
      "y": 15,
      "z": -8,
      "name": "Rock_Sandstone_White"
    },
    {
      "x": -11,
      "y": 16,
      "z": -8,
      "name": "Rock_Sandstone_White"
    },
    {
      "x": -11,
      "y": 17,
      "z": -8,
      "name": "Rock_Sandstone_Brick_Decorative"
    },
    {
      "x": -11,
      "y": 18,
      "z": -8,
      "name": "Rock_Sandstone_Brick_Decorative"
    },
    {
      "x": -11,
      "y": 19,
      "z": -8,
      "name": "Rock_Sandstone_Brick_Decorative"
    },
    {
      "x": -11,
      "y": 20,
      "z": -8,
      "name": "Rock_Sandstone_Brick_Decorative"
    },
    {
      "x": -11,
      "y": 21,
      "z": -8,
      "name": "Rock_Sandstone_Brick_Decorative"
    },
    {
      "x": -11,
      "y": 22,
      "z": -8,
      "name": "Rock_Sandstone_Brick_Decorative"
    },
    {
      "x": -11,
      "y": 23,
      "z": -8,
      "name": "Rock_Sandstone_Brick_Decorative"
    },
    {
      "x": -11,
      "y": 24,
      "z": -8,
      "name": "Rock_Sandstone_Brick_Decorative"
    },
    {
      "x": -11,
      "y": 25,
      "z": -8,
      "name": "Rock_Sandstone_Brick_Decorative"
    },
    {
      "x": -11,
      "y": 26,
      "z": -8,
      "name": "Rock_Sandstone_Brick_Decorative"
    },
    {
      "x": -11,
      "y": 27,
      "z": -8,
      "name": "Rock_Sandstone_Brick_Decorative"
    },
    {
      "x": -11,
      "y": 28,
      "z": -8,
      "name": "Rock_Sandstone_Brick_Decorative"
    },
    {
      "x": -11,
      "y": 3,
      "z": -7,
      "name": "Rock_Sandstone_White"
    },
    {
      "x": -11,
      "y": 4,
      "z": -7,
      "name": "Rock_Sandstone_White"
    },
    {
      "x": -11,
      "y": 5,
      "z": -7,
      "name": "Rock_Sandstone_White"
    },
    {
      "x": -11,
      "y": 7,
      "z": -7,
      "name": "Rock_Sandstone_White"
    },
    {
      "x": -11,
      "y": 8,
      "z": -7,
      "name": "Rock_Sandstone_White"
    },
    {
      "x": -11,
      "y": 9,
      "z": -7,
      "name": "Rock_Sandstone_White"
    },
    {
      "x": -11,
      "y": 11,
      "z": -7,
      "name": "Rock_Sandstone_White"
    },
    {
      "x": -11,
      "y": 12,
      "z": -7,
      "name": "Soil_Gravel_Sand"
    },
    {
      "x": -11,
      "y": 15,
      "z": -7,
      "name": "Rock_Sandstone_White"
    },
    {
      "x": -11,
      "y": 16,
      "z": -7,
      "name": "Rock_Sandstone_White"
    },
    {
      "x": -11,
      "y": 17,
      "z": -7,
      "name": "Rock_Sandstone_Brick_Decorative"
    },
    {
      "x": -11,
      "y": 18,
      "z": -7,
      "name": "Rock_Sandstone_Brick_Decorative"
    },
    {
      "x": -11,
      "y": 19,
      "z": -7,
      "name": "Rock_Sandstone_Brick_Decorative"
    },
    {
      "x": -11,
      "y": 20,
      "z": -7,
      "name": "Rock_Sandstone_Brick_Decorative"
    },
    {
      "x": -11,
      "y": 21,
      "z": -7,
      "name": "Rock_Sandstone_Brick_Decorative"
    },
    {
      "x": -11,
      "y": 22,
      "z": -7,
      "name": "Rock_Sandstone_Brick_Decorative"
    },
    {
      "x": -11,
      "y": 23,
      "z": -7,
      "name": "Rock_Sandstone_Brick_Decorative"
    },
    {
      "x": -11,
      "y": 24,
      "z": -7,
      "name": "Rock_Sandstone_Brick_Decorative"
    },
    {
      "x": -11,
      "y": 25,
      "z": -7,
      "name": "Rock_Sandstone_Brick_Decorative"
    },
    {
      "x": -11,
      "y": 26,
      "z": -7,
      "name": "Rock_Sandstone_Brick_Decorative"
    },
    {
      "x": -11,
      "y": 27,
      "z": -7,
      "name": "Rock_Sandstone_Brick_Decorative"
    },
    {
      "x": -11,
      "y": 28,
      "z": -7,
      "name": "Rock_Sandstone_Brick_Decorative"
    },
    {
      "x": -11,
      "y": 3,
      "z": -6,
      "name": "Rock_Sandstone_White"
    },
    {
      "x": -11,
      "y": 4,
      "z": -6,
      "name": "Rock_Sandstone_White"
    },
    {
      "x": -11,
      "y": 5,
      "z": -6,
      "name": "Rock_Sandstone_White"
    },
    {
      "x": -11,
      "y": 6,
      "z": -6,
      "name": "Rock_Sandstone_White"
    },
    {
      "x": -11,
      "y": 7,
      "z": -6,
      "name": "Rock_Sandstone_White"
    },
    {
      "x": -11,
      "y": 8,
      "z": -6,
      "name": "Rock_Sandstone_White"
    },
    {
      "x": -11,
      "y": 9,
      "z": -6,
      "name": "Rock_Sandstone_White"
    },
    {
      "x": -11,
      "y": 10,
      "z": -6,
      "name": "Rock_Sandstone_White"
    },
    {
      "x": -11,
      "y": 11,
      "z": -6,
      "name": "Rock_Sandstone_White"
    },
    {
      "x": -11,
      "y": 12,
      "z": -6,
      "name": "Soil_Gravel_Sand"
    },
    {
      "x": -11,
      "y": 13,
      "z": -6,
      "name": "Soil_Gravel_Sand"
    },
    {
      "x": -11,
      "y": 14,
      "z": -6,
      "name": "Soil_Gravel_Sand"
    },
    {
      "x": -11,
      "y": 15,
      "z": -6,
      "name": "Rock_Sandstone_White"
    },
    {
      "x": -11,
      "y": 16,
      "z": -6,
      "name": "Rock_Sandstone_White"
    },
    {
      "x": -11,
      "y": 17,
      "z": -6,
      "name": "Rock_Sandstone_Brick_Decorative"
    },
    {
      "x": -11,
      "y": 18,
      "z": -6,
      "name": "Rock_Sandstone_Brick_Decorative"
    },
    {
      "x": -11,
      "y": 19,
      "z": -6,
      "name": "Rock_Sandstone_Brick_Decorative"
    },
    {
      "x": -11,
      "y": 20,
      "z": -6,
      "name": "Rock_Sandstone_Brick_Decorative"
    },
    {
      "x": -11,
      "y": 21,
      "z": -6,
      "name": "Rock_Sandstone_Brick_Decorative"
    },
    {
      "x": -11,
      "y": 22,
      "z": -6,
      "name": "Rock_Sandstone_Brick_Decorative"
    },
    {
      "x": -11,
      "y": 23,
      "z": -6,
      "name": "Rock_Sandstone_Brick_Decorative"
    },
    {
      "x": -11,
      "y": 24,
      "z": -6,
      "name": "Rock_Sandstone_Brick_Decorative"
    },
    {
      "x": -11,
      "y": 25,
      "z": -6,
      "name": "Rock_Sandstone_Brick_Decorative"
    },
    {
      "x": -11,
      "y": 26,
      "z": -6,
      "name": "Rock_Sandstone_Brick_Decorative"
    },
    {
      "x": -11,
      "y": 27,
      "z": -6,
      "name": "Rock_Sandstone_Brick_Decorative"
    },
    {
      "x": -11,
      "y": 28,
      "z": -6,
      "name": "Rock_Sandstone_Brick_Decorative"
    },
    {
      "x": -11,
      "y": 3,
      "z": -5,
      "name": "Rock_Sandstone_White"
    },
    {
      "x": -11,
      "y": 4,
      "z": -5,
      "name": "Rock_Sandstone_White"
    },
    {
      "x": -11,
      "y": 5,
      "z": -5,
      "name": "Rock_Sandstone_White"
    },
    {
      "x": -11,
      "y": 6,
      "z": -5,
      "name": "Rock_Sandstone_White"
    },
    {
      "x": -11,
      "y": 7,
      "z": -5,
      "name": "Rock_Sandstone_White"
    },
    {
      "x": -11,
      "y": 8,
      "z": -5,
      "name": "Rock_Sandstone_White"
    },
    {
      "x": -11,
      "y": 9,
      "z": -5,
      "name": "Rock_Sandstone_White"
    },
    {
      "x": -11,
      "y": 10,
      "z": -5,
      "name": "Rock_Sandstone_White"
    },
    {
      "x": -11,
      "y": 11,
      "z": -5,
      "name": "Rock_Sandstone_White"
    },
    {
      "x": -11,
      "y": 12,
      "z": -5,
      "name": "Soil_Gravel_Sand"
    },
    {
      "x": -11,
      "y": 13,
      "z": -5,
      "name": "Soil_Gravel_Sand"
    },
    {
      "x": -11,
      "y": 14,
      "z": -5,
      "name": "Soil_Gravel_Sand"
    },
    {
      "x": -11,
      "y": 15,
      "z": -5,
      "name": "Rock_Sandstone_White"
    },
    {
      "x": -11,
      "y": 16,
      "z": -5,
      "name": "Rock_Sandstone_White"
    },
    {
      "x": -11,
      "y": 17,
      "z": -5,
      "name": "Soil_Gravel_Sand"
    },
    {
      "x": -11,
      "y": 20,
      "z": -5,
      "name": "Rock_Sandstone"
    },
    {
      "x": -11,
      "y": 1,
      "z": -4,
      "name": "Rock_Sandstone_White"
    },
    {
      "x": -11,
      "y": 2,
      "z": -4,
      "name": "Rock_Sandstone_White"
    },
    {
      "x": -11,
      "y": 3,
      "z": -4,
      "name": "Rock_Sandstone_White"
    },
    {
      "x": -11,
      "y": 4,
      "z": -4,
      "name": "Rock_Sandstone_White"
    },
    {
      "x": -11,
      "y": 5,
      "z": -4,
      "name": "Rock_Sandstone_White"
    },
    {
      "x": -11,
      "y": 6,
      "z": -4,
      "name": "Rock_Sandstone_White"
    },
    {
      "x": -11,
      "y": 7,
      "z": -4,
      "name": "Rock_Sandstone_White"
    },
    {
      "x": -11,
      "y": 8,
      "z": -4,
      "name": "Rock_Sandstone_White"
    },
    {
      "x": -11,
      "y": 9,
      "z": -4,
      "name": "Rock_Sandstone_White"
    },
    {
      "x": -11,
      "y": 10,
      "z": -4,
      "name": "Rock_Sandstone_White"
    },
    {
      "x": -11,
      "y": 11,
      "z": -4,
      "name": "Rock_Sandstone_White"
    },
    {
      "x": -11,
      "y": 12,
      "z": -4,
      "name": "Soil_Gravel_Sand"
    },
    {
      "x": -11,
      "y": 13,
      "z": -4,
      "name": "Soil_Gravel_Sand"
    },
    {
      "x": -11,
      "y": 14,
      "z": -4,
      "name": "Soil_Gravel_Sand"
    },
    {
      "x": -11,
      "y": 15,
      "z": -4,
      "name": "Rock_Sandstone_White"
    },
    {
      "x": -11,
      "y": 16,
      "z": -4,
      "name": "Rock_Sandstone_White"
    },
    {
      "x": -11,
      "y": 17,
      "z": -4,
      "name": "Soil_Gravel_Sand"
    },
    {
      "x": -11,
      "y": 19,
      "z": -4,
      "name": "Soil_Gravel_Sand"
    },
    {
      "x": -11,
      "y": 20,
      "z": -4,
      "name": "Rock_Sandstone"
    },
    {
      "x": -11,
      "y": 1,
      "z": -3,
      "name": "Rock_Sandstone_White"
    },
    {
      "x": -11,
      "y": 2,
      "z": -3,
      "name": "Rock_Sandstone_White"
    },
    {
      "x": -11,
      "y": 3,
      "z": -3,
      "name": "Rock_Sandstone_White"
    },
    {
      "x": -11,
      "y": 4,
      "z": -3,
      "name": "Rock_Sandstone_White"
    },
    {
      "x": -11,
      "y": 5,
      "z": -3,
      "name": "Rock_Sandstone_White"
    },
    {
      "x": -11,
      "y": 6,
      "z": -3,
      "name": "Rock_Sandstone_White"
    },
    {
      "x": -11,
      "y": 7,
      "z": -3,
      "name": "Rock_Sandstone_White"
    },
    {
      "x": -11,
      "y": 8,
      "z": -3,
      "name": "Rock_Sandstone_White"
    },
    {
      "x": -11,
      "y": 9,
      "z": -3,
      "name": "Rock_Sandstone_White"
    },
    {
      "x": -11,
      "y": 10,
      "z": -3,
      "name": "Rock_Sandstone_White"
    },
    {
      "x": -11,
      "y": 11,
      "z": -3,
      "name": "Rock_Sandstone_White"
    },
    {
      "x": -11,
      "y": 12,
      "z": -3,
      "name": "Soil_Gravel_Sand"
    },
    {
      "x": -11,
      "y": 13,
      "z": -3,
      "name": "Soil_Gravel_Sand"
    },
    {
      "x": -11,
      "y": 14,
      "z": -3,
      "name": "Soil_Gravel_Sand"
    },
    {
      "x": -11,
      "y": 15,
      "z": -3,
      "name": "Rock_Sandstone_White"
    },
    {
      "x": -11,
      "y": 16,
      "z": -3,
      "name": "Rock_Sandstone_White"
    },
    {
      "x": -11,
      "y": 17,
      "z": -3,
      "name": "Soil_Gravel_Sand"
    },
    {
      "x": -11,
      "y": 19,
      "z": -3,
      "name": "Soil_Gravel_Sand"
    },
    {
      "x": -11,
      "y": 20,
      "z": -3,
      "name": "Soil_Sand_White"
    },
    {
      "x": -11,
      "y": 0,
      "z": -2,
      "name": "Rock_Sandstone_White"
    },
    {
      "x": -11,
      "y": 1,
      "z": -2,
      "name": "Rock_Sandstone_White"
    },
    {
      "x": -11,
      "y": 2,
      "z": -2,
      "name": "Rock_Sandstone_White"
    },
    {
      "x": -11,
      "y": 3,
      "z": -2,
      "name": "Rock_Sandstone_White"
    },
    {
      "x": -11,
      "y": 4,
      "z": -2,
      "name": "Rock_Sandstone_White"
    },
    {
      "x": -11,
      "y": 5,
      "z": -2,
      "name": "Rock_Sandstone_White"
    },
    {
      "x": -11,
      "y": 6,
      "z": -2,
      "name": "Rock_Sandstone_White"
    },
    {
      "x": -11,
      "y": 7,
      "z": -2,
      "name": "Rock_Sandstone_White"
    },
    {
      "x": -11,
      "y": 8,
      "z": -2,
      "name": "Rock_Sandstone_White"
    },
    {
      "x": -11,
      "y": 9,
      "z": -2,
      "name": "Rock_Sandstone_White"
    },
    {
      "x": -11,
      "y": 10,
      "z": -2,
      "name": "Rock_Sandstone_White"
    },
    {
      "x": -11,
      "y": 11,
      "z": -2,
      "name": "Rock_Sandstone_White"
    },
    {
      "x": -11,
      "y": 12,
      "z": -2,
      "name": "Soil_Gravel_Sand"
    },
    {
      "x": -11,
      "y": 13,
      "z": -2,
      "name": "Soil_Gravel_Sand"
    },
    {
      "x": -11,
      "y": 14,
      "z": -2,
      "name": "Soil_Gravel_Sand"
    },
    {
      "x": -11,
      "y": 15,
      "z": -2,
      "name": "Rock_Sandstone_White"
    },
    {
      "x": -11,
      "y": 16,
      "z": -2,
      "name": "Rock_Sandstone_White"
    },
    {
      "x": -11,
      "y": 17,
      "z": -2,
      "name": "Soil_Gravel_Sand"
    },
    {
      "x": -11,
      "y": 19,
      "z": -2,
      "name": "Soil_Gravel_Sand"
    },
    {
      "x": -11,
      "y": 20,
      "z": -2,
      "name": "Soil_Sand_White"
    },
    {
      "x": -11,
      "y": 0,
      "z": -1,
      "name": "Rock_Sandstone_White"
    },
    {
      "x": -11,
      "y": 1,
      "z": -1,
      "name": "Rock_Sandstone_White"
    },
    {
      "x": -11,
      "y": 2,
      "z": -1,
      "name": "Rock_Sandstone_White"
    },
    {
      "x": -11,
      "y": 3,
      "z": -1,
      "name": "Rock_Sandstone_White"
    },
    {
      "x": -11,
      "y": 4,
      "z": -1,
      "name": "Rock_Sandstone_White"
    },
    {
      "x": -11,
      "y": 5,
      "z": -1,
      "name": "Rock_Sandstone_White"
    },
    {
      "x": -11,
      "y": 6,
      "z": -1,
      "name": "Rock_Sandstone_White"
    },
    {
      "x": -11,
      "y": 7,
      "z": -1,
      "name": "Rock_Sandstone_White"
    },
    {
      "x": -11,
      "y": 8,
      "z": -1,
      "name": "Rock_Sandstone_White"
    },
    {
      "x": -11,
      "y": 9,
      "z": -1,
      "name": "Rock_Sandstone_White"
    },
    {
      "x": -11,
      "y": 10,
      "z": -1,
      "name": "Rock_Sandstone_White"
    },
    {
      "x": -11,
      "y": 11,
      "z": -1,
      "name": "Rock_Sandstone_White"
    },
    {
      "x": -11,
      "y": 12,
      "z": -1,
      "name": "Soil_Gravel_Sand"
    },
    {
      "x": -11,
      "y": 13,
      "z": -1,
      "name": "Soil_Gravel_Sand"
    },
    {
      "x": -11,
      "y": 14,
      "z": -1,
      "name": "Soil_Gravel_Sand"
    },
    {
      "x": -11,
      "y": 15,
      "z": -1,
      "name": "Rock_Sandstone_White"
    },
    {
      "x": -11,
      "y": 16,
      "z": -1,
      "name": "Rock_Sandstone_White"
    },
    {
      "x": -11,
      "y": 17,
      "z": -1,
      "name": "Soil_Gravel_Sand"
    },
    {
      "x": -11,
      "y": 19,
      "z": -1,
      "name": "Soil_Gravel_Sand"
    },
    {
      "x": -11,
      "y": 20,
      "z": -1,
      "name": "Soil_Sand_White"
    },
    {
      "x": -11,
      "y": 0,
      "z": 0,
      "name": "Rock_Sandstone_White"
    },
    {
      "x": -11,
      "y": 1,
      "z": 0,
      "name": "Rock_Sandstone_White"
    },
    {
      "x": -11,
      "y": 2,
      "z": 0,
      "name": "Rock_Sandstone_White"
    },
    {
      "x": -11,
      "y": 3,
      "z": 0,
      "name": "Rock_Sandstone_White"
    },
    {
      "x": -11,
      "y": 4,
      "z": 0,
      "name": "Rock_Sandstone_White"
    },
    {
      "x": -11,
      "y": 5,
      "z": 0,
      "name": "Rock_Sandstone_White"
    },
    {
      "x": -11,
      "y": 6,
      "z": 0,
      "name": "Rock_Sandstone_White"
    },
    {
      "x": -11,
      "y": 7,
      "z": 0,
      "name": "Rock_Sandstone_White"
    },
    {
      "x": -11,
      "y": 8,
      "z": 0,
      "name": "Rock_Sandstone_White"
    },
    {
      "x": -11,
      "y": 9,
      "z": 0,
      "name": "Rock_Sandstone_White"
    },
    {
      "x": -11,
      "y": 10,
      "z": 0,
      "name": "Rock_Sandstone_White"
    },
    {
      "x": -11,
      "y": 11,
      "z": 0,
      "name": "Rock_Sandstone_White"
    },
    {
      "x": -11,
      "y": 12,
      "z": 0,
      "name": "Rock_Sandstone_White"
    },
    {
      "x": -11,
      "y": 13,
      "z": 0,
      "name": "Rock_Sandstone"
    },
    {
      "x": -11,
      "y": 14,
      "z": 0,
      "name": "Soil_Gravel_Sand"
    },
    {
      "x": -11,
      "y": 15,
      "z": 0,
      "name": "Soil_Gravel_Sand"
    },
    {
      "x": -11,
      "y": 16,
      "z": 0,
      "name": "Soil_Gravel_Sand"
    },
    {
      "x": -11,
      "y": 17,
      "z": 0,
      "name": "Rock_Sandstone_White"
    },
    {
      "x": -11,
      "y": 19,
      "z": 0,
      "name": "Soil_Gravel_Sand"
    },
    {
      "x": -11,
      "y": 20,
      "z": 0,
      "name": "Soil_Sand_White"
    },
    {
      "x": -11,
      "y": 0,
      "z": 1,
      "name": "Rock_Sandstone_White"
    },
    {
      "x": -11,
      "y": 1,
      "z": 1,
      "name": "Rock_Sandstone_White"
    },
    {
      "x": -11,
      "y": 2,
      "z": 1,
      "name": "Rock_Sandstone_White"
    },
    {
      "x": -11,
      "y": 3,
      "z": 1,
      "name": "Rock_Sandstone_White"
    },
    {
      "x": -11,
      "y": 4,
      "z": 1,
      "name": "Rock_Sandstone_White"
    },
    {
      "x": -11,
      "y": 5,
      "z": 1,
      "name": "Rock_Sandstone_White"
    },
    {
      "x": -11,
      "y": 6,
      "z": 1,
      "name": "Rock_Sandstone_White"
    },
    {
      "x": -11,
      "y": 7,
      "z": 1,
      "name": "Rock_Sandstone_White"
    },
    {
      "x": -11,
      "y": 8,
      "z": 1,
      "name": "Rock_Sandstone_White"
    },
    {
      "x": -11,
      "y": 9,
      "z": 1,
      "name": "Rock_Sandstone"
    },
    {
      "x": -11,
      "y": 10,
      "z": 1,
      "name": "Rock_Sandstone"
    },
    {
      "x": -11,
      "y": 11,
      "z": 1,
      "name": "Rock_Sandstone_White"
    },
    {
      "x": -11,
      "y": 12,
      "z": 1,
      "name": "Rock_Sandstone_White"
    },
    {
      "x": -11,
      "y": 13,
      "z": 1,
      "name": "Rock_Sandstone"
    },
    {
      "x": -11,
      "y": 14,
      "z": 1,
      "name": "Soil_Gravel_Sand"
    },
    {
      "x": -11,
      "y": 15,
      "z": 1,
      "name": "Soil_Gravel_Sand"
    },
    {
      "x": -11,
      "y": 16,
      "z": 1,
      "name": "Soil_Gravel_Sand"
    },
    {
      "x": -11,
      "y": 17,
      "z": 1,
      "name": "Rock_Sandstone_White"
    },
    {
      "x": -11,
      "y": 19,
      "z": 1,
      "name": "Soil_Gravel_Sand"
    },
    {
      "x": -11,
      "y": 20,
      "z": 1,
      "name": "Soil_Sand_White"
    },
    {
      "x": -11,
      "y": 0,
      "z": 2,
      "name": "Rock_Sandstone_White"
    },
    {
      "x": -11,
      "y": 1,
      "z": 2,
      "name": "Rock_Sandstone_White"
    },
    {
      "x": -11,
      "y": 2,
      "z": 2,
      "name": "Rock_Sandstone_White"
    },
    {
      "x": -11,
      "y": 3,
      "z": 2,
      "name": "Rock_Sandstone_White"
    },
    {
      "x": -11,
      "y": 4,
      "z": 2,
      "name": "Rock_Sandstone_White"
    },
    {
      "x": -11,
      "y": 5,
      "z": 2,
