{
  "version": 8,
  "blockIdVersion": 10,
  "anchorX": -2,
  "anchorY": 13,
  "anchorZ": 0,
  "blocks": [
    {
      "x": -10,
      "y": 16,
      "z": 3,
      "name": "Plant_Leaves_Palo"
    },
    {
      "x": -10,
      "y": 16,
      "z": 4,
      "name": "Plant_Leaves_Palo"
    },
    {
      "x": -10,
      "y": 16,
      "z": 5,
      "name": "Plant_Leaves_Palo"
    },
    {
      "x": -9,
      "y": 17,
      "z": -4,
      "name": "Plant_Leaves_Palo"
    },
    {
      "x": -9,
      "y": 17,
      "z": -3,
      "name": "Plant_Leaves_Palo"
    },
    {
      "x": -9,
      "y": 17,
      "z": -2,
      "name": "Plant_Leaves_Palo"
    },
    {
      "x": -9,
      "y": 16,
      "z": 2,
      "name": "Plant_Leaves_Palo"
    },
    {
      "x": -9,
      "y": 16,
      "z": 3,
      "name": "Plant_Leaves_Palo"
    },
    {
      "x": -9,
      "y": 16,
      "z": 4,
      "name": "Plant_Leaves_Palo"
    },
    {
      "x": -9,
      "y": 17,
      "z": 4,
      "name": "Plant_Leaves_Palo"
    },
    {
      "x": -9,
      "y": 16,
      "z": 5,
      "name": "Plant_Leaves_Palo"
    },
    {
      "x": -9,
      "y": 17,
      "z": 5,
      "name": "Plant_Leaves_Palo"
    },
    {
      "x": -9,
      "y": 16,
      "z": 6,
      "name": "Plant_Leaves_Palo"
    },
    {
      "x": -9,
      "y": 16,
      "z": 7,
      "name": "Plant_Leaves_Palo"
    },
    {
      "x": -8,
      "y": 17,
      "z": -6,
      "name": "Plant_Leaves_Palo"
    },
    {
      "x": -8,
      "y": 17,
      "z": -5,
      "name": "Plant_Leaves_Palo"
    },
    {
      "x": -8,
      "y": 17,
      "z": -4,
      "name": "Plant_Leaves_Palo"
    },
    {
      "x": -8,
      "y": 17,
      "z": -3,
      "name": "Plant_Leaves_Palo"
    },
    {
      "x": -8,
      "y": 18,
      "z": -3,
      "name": "Plant_Leaves_Palo"
    },
    {
      "x": -8,
      "y": 17,
      "z": -2,
      "name": "Plant_Leaves_Palo"
    },
    {
      "x": -8,
      "y": 17,
      "z": -1,
      "name": "Plant_Leaves_Palo"
    },
    {
      "x": -8,
      "y": 19,
      "z": 1,
      "name": "Plant_Leaves_Palo"
    },
    {
      "x": -8,
      "y": 16,
      "z": 2,
      "name": "Plant_Leaves_Palo"
    },
    {
      "x": -8,
      "y": 19,
      "z": 2,
      "name": "Plant_Leaves_Palo"
    },
    {
      "x": -8,
      "y": 17,
      "z": 3,
      "name": "Plant_Leaves_Palo"
    },
    {
      "x": -8,
      "y": 19,
      "z": 3,
      "name": "Plant_Leaves_Palo"
    },
    {
      "x": -8,
      "y": 17,
      "z": 4,
      "name": "Wood_Palo_Branch_Long",
      "rotation": 5
    },
    {
      "x": -8,
      "y": 19,
      "z": 4,
      "name": "Plant_Leaves_Palo"
    },
    {
      "x": -8,
      "y": 17,
      "z": 5,
      "name": "Plant_Leaves_Palo"
    },
    {
      "x": -8,
      "y": 19,
      "z": 5,
      "name": "Plant_Leaves_Palo"
    },
    {
      "x": -8,
      "y": 16,
      "z": 6,
      "name": "Plant_Leaves_Palo"
    },
    {
      "x": -8,
      "y": 17,
      "z": 6,
      "name": "Plant_Leaves_Palo"
    },
    {
      "x": -8,
      "y": 16,
      "z": 7,
      "name": "Plant_Leaves_Palo"
    },
    {
      "x": -7,
      "y": 17,
      "z": -6,
      "name": "Plant_Leaves_Palo"
    },
    {
      "x": -7,
      "y": 17,
      "z": -5,
      "name": "Plant_Leaves_Palo"
    },
    {
      "x": -7,
      "y": 18,
      "z": -5,
      "name": "Plant_Leaves_Palo"
    },
    {
      "x": -7,
      "y": 18,
      "z": -4,
      "name": "Plant_Leaves_Palo"
    },
    {
      "x": -7,
      "y": 17,
      "z": -3,
      "name": "Wood_Palo_Branch_Long",
      "rotation": 5
    },
    {
      "x": -7,
      "y": 18,
      "z": -3,
      "name": "Plant_Leaves_Palo"
    },
    {
      "x": -7,
      "y": 18,
      "z": -2,
      "name": "Plant_Leaves_Palo"
    },
    {
      "x": -7,
      "y": 17,
      "z": -1,
      "name": "Plant_Leaves_Palo"
    },
    {
      "x": -7,
      "y": 19,
      "z": 1,
      "name": "Plant_Leaves_Palo"
    },
    {
      "x": -7,
      "y": 19,
      "z": 2,
      "name": "Plant_Leaves_Palo"
    },
    {
      "x": -7,
      "y": 20,
      "z": 2,
      "name": "Plant_Leaves_Palo"
    },
    {
      "x": -7,
      "y": 19,
      "z": 3,
      "name": "Plant_Leaves_Palo"
    },
    {
      "x": -7,
      "y": 17,
      "z": 4,
      "name": "Wood_Palo_Branch_Long",
      "rotation": 5
    },
    {
      "x": -7,
      "y": 18,
      "z": 4,
      "name": "Plant_Leaves_Palo"
    },
    {
      "x": -7,
      "y": 19,
      "z": 4,
      "name": "Plant_Leaves_Palo"
    },
    {
      "x": -7,
      "y": 20,
      "z": 4,
      "name": "Plant_Leaves_Palo"
    },
    {
      "x": -7,
      "y": 17,
      "z": 5,
      "name": "Plant_Leaves_Palo"
    },
    {
      "x": -7,
      "y": 19,
      "z": 5,
      "name": "Plant_Leaves_Palo"
    },
    {
      "x": -7,
      "y": 17,
      "z": 6,
      "name": "Plant_Leaves_Palo"
    },
    {
      "x": -7,
      "y": 19,
      "z": 6,
      "name": "Plant_Leaves_Palo"
    },
    {
      "x": -7,
      "y": 16,
      "z": 7,
      "name": "Plant_Leaves_Palo"
    },
    {
      "x": -7,
      "y": 16,
      "z": 8,
      "name": "Plant_Leaves_Palo"
    },
    {
      "x": -6,
      "y": 17,
      "z": -7,
      "name": "Plant_Leaves_Palo"
    },
    {
      "x": -6,
      "y": 17,
      "z": -6,
      "name": "Plant_Leaves_Palo"
    },
    {
      "x": -6,
      "y": 18,
      "z": -6,
      "name": "Plant_Leaves_Palo"
    },
    {
      "x": -6,
      "y": 18,
      "z": -5,
      "name": "Plant_Leaves_Palo"
    },
    {
      "x": -6,
      "y": 18,
      "z": -4,
      "name": "Plant_Leaves_Palo"
    },
    {
      "x": -6,
      "y": 17,
      "z": -3,
      "name": "Wood_Palo_Branch_Long",
      "rotation": 5
    },
    {
      "x": -6,
      "y": 18,
      "z": -3,
      "name": "Plant_Leaves_Palo"
    },
    {
      "x": -6,
      "y": 18,
      "z": -2,
      "name": "Plant_Leaves_Palo"
    },
    {
      "x": -6,
      "y": 20,
      "z": 0,
      "name": "Plant_Leaves_Palo"
    },
    {
      "x": -6,
      "y": 23,
      "z": 0,
      "name": "Plant_Leaves_Palo"
    },
    {
      "x": -6,
      "y": 20,
      "z": 1,
      "name": "Plant_Leaves_Palo"
    },
    {
      "x": -6,
      "y": 23,
      "z": 1,
      "name": "Plant_Leaves_Palo"
    },
    {
      "x": -6,
      "y": 19,
      "z": 2,
      "name": "Plant_Leaves_Palo"
    },
    {
      "x": -6,
      "y": 20,
      "z": 2,
      "name": "Plant_Leaves_Palo"
    },
    {
      "x": -6,
      "y": 21,
      "z": 2,
      "name": "Plant_Leaves_Palo"
    },
    {
      "x": -6,
      "y": 23,
      "z": 2,
      "name": "Plant_Leaves_Palo"
    },
    {
      "x": -6,
      "y": 16,
      "z": 3,
      "name": "Wood_Palo_Trunk_Full"
    },
    {
      "x": -6,
      "y": 17,
      "z": 3,
      "name": "Wood_Palo_Trunk_Full"
    },
    {
      "x": -6,
      "y": 19,
      "z": 3,
      "name": "Wood_Palo_Branch_Long",
      "rotation": 5
    },
    {
      "x": -6,
      "y": 20,
      "z": 3,
      "name": "Plant_Leaves_Palo"
    },
    {
      "x": -6,
      "y": 21,
      "z": 3,
      "name": "Plant_Leaves_Palo"
    },
    {
      "x": -6,
      "y": 17,
      "z": 4,
      "name": "Wood_Palo_Trunk_Full"
    },
    {
      "x": -6,
      "y": 18,
      "z": 4,
      "name": "Plant_Leaves_Palo"
    },
    {
      "x": -6,
      "y": 19,
      "z": 4,
      "name": "Plant_Leaves_Palo"
    },
    {
      "x": -6,
      "y": 20,
      "z": 4,
      "name": "Plant_Leaves_Palo"
    },
    {
      "x": -6,
      "y": 17,
      "z": 5,
      "name": "Wood_Palo_Branch_Long",
      "rotation": 4
    },
    {
      "x": -6,
      "y": 18,
      "z": 5,
      "name": "Plant_Leaves_Palo"
    },
    {
      "x": -6,
      "y": 19,
      "z": 5,
      "name": "Plant_Leaves_Palo"
    },
    {
      "x": -6,
      "y": 20,
      "z": 5,
      "name": "Plant_Leaves_Palo"
    },
    {
      "x": -6,
      "y": 21,
      "z": 5,
      "name": "Plant_Leaves_Palo"
    },
    {
      "x": -6,
      "y": 17,
      "z": 6,
      "name": "Wood_Palo_Branch_Long",
      "rotation": 4
    },
    {
      "x": -6,
      "y": 19,
      "z": 6,
      "name": "Plant_Leaves_Palo"
    },
    {
      "x": -6,
      "y": 16,
      "z": 7,
      "name": "Plant_Leaves_Palo"
    },
    {
      "x": -6,
      "y": 17,
      "z": 7,
      "name": "Plant_Leaves_Palo"
    },
    {
      "x": -6,
      "y": 16,
      "z": 8,
      "name": "Plant_Leaves_Palo"
    },
    {
      "x": -5,
      "y": 17,
      "z": -7,
      "name": "Plant_Leaves_Palo"
    },
    {
      "x": -5,
      "y": 17,
      "z": -6,
      "name": "Plant_Leaves_Palo"
    },
    {
      "x": -5,
      "y": 18,
      "z": -6,
      "name": "Plant_Leaves_Palo"
    },
    {
      "x": -5,
      "y": 19,
      "z": -6,
      "name": "Plant_Leaves_Palo"
    },
    {
      "x": -5,
      "y": 17,
      "z": -5,
      "name": "Wood_Palo_Branch_Long",
      "rotation": 4
    },
    {
      "x": -5,
      "y": 18,
      "z": -5,
      "name": "Plant_Leaves_Palo"
    },
    {
      "x": -5,
      "y": 19,
      "z": -5,
      "name": "Plant_Leaves_Palo"
    },
    {
      "x": -5,
      "y": 21,
      "z": -5,
      "name": "Plant_Leaves_Palo"
    },
    {
      "x": -5,
      "y": 17,
      "z": -4,
      "name": "Wood_Palo_Branch_Long",
      "rotation": 4
    },
    {
      "x": -5,
      "y": 18,
      "z": -4,
      "name": "Plant_Leaves_Palo"
    },
    {
      "x": -5,
      "y": 19,
      "z": -4,
      "name": "Plant_Leaves_Palo"
    },
    {
      "x": -5,
      "y": 21,
      "z": -4,
      "name": "Plant_Leaves_Palo"
    },
    {
      "x": -5,
      "y": 17,
      "z": -3,
      "name": "Wood_Palo_Trunk_Full"
    },
    {
      "x": -5,
      "y": 21,
      "z": -3,
      "name": "Plant_Leaves_Palo"
    },
    {
      "x": -5,
      "y": 23,
      "z": -1,
      "name": "Plant_Leaves_Palo"
    },
    {
      "x": -5,
      "y": 9,
      "z": 0,
      "name": "Wood_Palo_Roots"
    },
    {
      "x": -5,
      "y": 10,
      "z": 0,
      "name": "Wood_Palo_Trunk_Full"
    },
    {
      "x": -5,
      "y": 11,
      "z": 0,
      "name": "Wood_Palo_Trunk_Full"
    },
    {
      "x": -5,
      "y": 23,
      "z": 0,
      "name": "Plant_Leaves_Palo"
    },
    {
      "x": -5,
      "y": 20,
      "z": 1,
      "name": "Plant_Leaves_Palo"
    },
    {
      "x": -5,
      "y": 23,
      "z": 1,
      "name": "Plant_Leaves_Palo"
    },
    {
      "x": -5,
      "y": 24,
      "z": 1,
      "name": "Plant_Leaves_Palo"
    },
    {
      "x": -5,
      "y": 16,
      "z": 2,
      "name": "Wood_Palo_Trunk_Full"
    },
    {
      "x": -5,
      "y": 20,
      "z": 2,
      "name": "Plant_Leaves_Palo"
    },
    {
      "x": -5,
      "y": 21,
      "z": 2,
      "name": "Plant_Leaves_Palo"
    },
    {
      "x": -5,
      "y": 23,
      "z": 2,
      "name": "Plant_Leaves_Palo"
    },
    {
      "x": -5,
      "y": 16,
      "z": 3,
      "name": "Wood_Palo_Trunk_Full"
    },
    {
      "x": -5,
      "y": 19,
      "z": 3,
      "name": "Wood_Palo_Branch_Long",
      "rotation": 5
    },
    {
      "x": -5,
      "y": 20,
      "z": 3,
      "name": "Plant_Leaves_Palo"
    },
    {
      "x": -5,
      "y": 23,
      "z": 3,
      "name": "Plant_Leaves_Palo"
    },
    {
      "x": -5,
      "y": 17,
      "z": 4,
      "name": "Plant_Leaves_Palo"
    },
    {
      "x": -5,
      "y": 20,
      "z": 4,
      "name": "Plant_Leaves_Palo"
    },
    {
      "x": -5,
      "y": 21,
      "z": 4,
      "name": "Plant_Leaves_Palo"
    },
    {
      "x": -5,
      "y": 17,
      "z": 5,
      "name": "Plant_Leaves_Palo"
    },
    {
      "x": -5,
      "y": 19,
      "z": 5,
      "name": "Plant_Leaves_Palo"
    },
    {
      "x": -5,
      "y": 20,
      "z": 5,
      "name": "Plant_Leaves_Palo"
    },
    {
      "x": -5,
      "y": 17,
      "z": 6,
      "name": "Plant_Leaves_Palo"
    },
    {
      "x": -5,
      "y": 19,
      "z": 6,
      "name": "Plant_Leaves_Palo"
    },
    {
      "x": -5,
      "y": 20,
      "z": 6,
      "name": "Plant_Leaves_Palo"
    },
    {
      "x": -5,
      "y": 16,
      "z": 7,
      "name": "Plant_Leaves_Palo"
    },
    {
      "x": -5,
      "y": 19,
      "z": 7,
      "name": "Plant_Leaves_Palo"
    },
    {
      "x": -5,
      "y": 16,
      "z": 8,
      "name": "Plant_Leaves_Palo"
    },
    {
      "x": -4,
      "y": 17,
      "z": -7,
      "name": "Plant_Leaves_Palo"
    },
    {
      "x": -4,
      "y": 17,
      "z": -6,
      "name": "Plant_Leaves_Palo"
    },
    {
      "x": -4,
      "y": 19,
      "z": -6,
      "name": "Plant_Leaves_Palo"
    },
    {
      "x": -4,
      "y": 21,
      "z": -6,
      "name": "Plant_Leaves_Palo"
    },
    {
      "x": -4,
      "y": 18,
      "z": -5,
      "name": "Plant_Leaves_Palo"
    },
    {
      "x": -4,
      "y": 21,
      "z": -5,
      "name": "Plant_Leaves_Palo"
    },
    {
      "x": -4,
      "y": 19,
      "z": -4,
      "name": "Plant_Leaves_Palo"
    },
    {
      "x": -4,
      "y": 21,
      "z": -4,
      "name": "Wood_Palo_Branch_Long",
      "rotation": 5
    },
    {
      "x": -4,
      "y": 22,
      "z": -4,
      "name": "Plant_Leaves_Palo"
    },
    {
      "x": -4,
      "y": 17,
      "z": -3,
      "name": "Wood_Palo_Trunk_Full"
    },
    {
      "x": -4,
      "y": 19,
      "z": -3,
      "name": "Plant_Leaves_Palo"
    },
    {
      "x": -4,
      "y": 21,
      "z": -3,
      "name": "Plant_Leaves_Palo"
    },
    {
      "x": -4,
      "y": 17,
      "z": -2,
      "name": "Wood_Palo_Trunk_Full"
    },
    {
      "x": -4,
      "y": 19,
      "z": -2,
      "name": "Plant_Leaves_Palo"
    },
    {
      "x": -4,
      "y": 21,
      "z": -2,
      "name": "Plant_Leaves_Palo"
    },
    {
      "x": -4,
      "y": 10,
      "z": -1,
      "name": "Wood_Palo_Branch_Long"
    },
    {
      "x": -4,
      "y": 11,
      "z": -1,
      "name": "Wood_Palo_Branch_Corner",
      "rotation": 8
    },
    {
      "x": -4,
      "y": 24,
      "z": -1,
      "name": "Plant_Leaves_Palo"
    },
    {
      "x": -4,
      "y": 11,
      "z": 0,
      "name": "Wood_Palo_Trunk_Full"
    },
    {
      "x": -4,
      "y": 12,
      "z": 0,
      "name": "Wood_Palo_Trunk_Full"
    },
    {
      "x": -4,
      "y": 17,
      "z": 0,
      "name": "Wood_Palo_Trunk_Full"
    },
    {
      "x": -4,
      "y": 23,
      "z": 0,
      "name": "Wood_Palo_Branch_Long",
      "rotation": 5
    },
    {
      "x": -4,
      "y": 24,
      "z": 0,
      "name": "Plant_Leaves_Palo"
    },
    {
      "x": -4,
      "y": 11,
      "z": 1,
      "name": "Wood_Palo_Branch_Long",
      "rotation": 4
    },
    {
      "x": -4,
      "y": 16,
      "z": 1,
      "name": "Wood_Palo_Trunk_Full"
    },
    {
      "x": -4,
      "y": 24,
      "z": 1,
      "name": "Plant_Leaves_Palo"
    },
    {
      "x": -4,
      "y": 10,
      "z": 2,
      "name": "Wood_Palo_Branch_Long"
    },
    {
      "x": -4,
      "y": 11,
      "z": 2,
      "name": "Wood_Palo_Branch_Corner",
      "rotation": 10
    },
    {
      "x": -4,
      "y": 16,
      "z": 2,
      "name": "Wood_Palo_Trunk_Full"
    },
    {
      "x": -4,
      "y": 19,
      "z": 2,
      "name": "Wood_Palo_Trunk_Full"
    },
    {
      "x": -4,
      "y": 20,
      "z": 2,
      "name": "Plant_Leaves_Palo"
    },
    {
      "x": -4,
      "y": 24,
      "z": 2,
      "name": "Plant_Leaves_Palo"
    },
    {
      "x": -4,
      "y": 19,
      "z": 3,
      "name": "Wood_Palo_Trunk_Full"
    },
    {
      "x": -4,
      "y": 20,
      "z": 3,
      "name": "Plant_Leaves_Palo"
    },
    {
      "x": -4,
      "y": 23,
      "z": 3,
      "name": "Plant_Leaves_Palo"
    },
    {
      "x": -4,
      "y": 17,
      "z": 4,
      "name": "Plant_Leaves_Palo"
    },
    {
      "x": -4,
      "y": 19,
      "z": 4,
      "name": "Wood_Palo_Branch_Long",
      "rotation": 4
    },
    {
      "x": -4,
      "y": 20,
      "z": 4,
      "name": "Plant_Leaves_Palo"
    },
    {
      "x": -4,
      "y": 17,
      "z": 5,
      "name": "Plant_Leaves_Palo"
    },
    {
      "x": -4,
      "y": 19,
      "z": 5,
      "name": "Wood_Palo_Branch_Long",
      "rotation": 4
    },
    {
      "x": -4,
      "y": 20,
      "z": 5,
      "name": "Plant_Leaves_Palo"
    },
    {
      "x": -4,
      "y": 21,
      "z": 5,
      "name": "Plant_Leaves_Palo"
    },
    {
      "x": -4,
      "y": 16,
      "z": 6,
      "name": "Plant_Leaves_Palo"
    },
    {
      "x": -4,
      "y": 19,
      "z": 6,
      "name": "Plant_Leaves_Palo"
    },
    {
      "x": -4,
      "y": 20,
      "z": 6,
      "name": "Plant_Leaves_Palo"
    },
    {
      "x": -4,
      "y": 21,
      "z": 6,
      "name": "Plant_Leaves_Palo"
    },
    {
      "x": -4,
      "y": 16,
      "z": 7,
      "name": "Plant_Leaves_Palo"
    },
    {
      "x": -4,
      "y": 19,
      "z": 7,
      "name": "Plant_Leaves_Palo"
    },
    {
      "x": -3,
      "y": 21,
      "z": -7,
      "name": "Plant_Leaves_Palo"
    },
    {
      "x": -3,
      "y": 17,
      "z": -6,
      "name": "Plant_Leaves_Palo"
    },
    {
      "x": -3,
      "y": 19,
      "z": -6,
      "name": "Plant_Leaves_Palo"
    },
    {
      "x": -3,
      "y": 21,
      "z": -6,
      "name": "Plant_Leaves_Palo"
    },
    {
      "x": -3,
      "y": 17,
      "z": -5,
      "name": "Plant_Leaves_Palo"
    },
    {
      "x": -3,
      "y": 19,
      "z": -5,
      "name": "Plant_Leaves_Palo"
    },
    {
      "x": -3,
      "y": 22,
      "z": -5,
      "name": "Plant_Leaves_Palo"
    },
    {
      "x": -3,
      "y": 19,
      "z": -4,
      "name": "Plant_Leaves_Palo"
    },
    {
      "x": -3,
      "y": 21,
      "z": -4,
      "name": "Wood_Palo_Branch_Long",
      "rotation": 5
    },
    {
      "x": -3,
      "y": 22,
      "z": -4,
      "name": "Plant_Leaves_Palo"
    },
    {
      "x": -3,
      "y": 19,
      "z": -3,
      "name": "Wood_Palo_Branch_Long",
      "rotation": 5
    },
    {
      "x": -3,
      "y": 20,
      "z": -3,
      "name": "Plant_Leaves_Palo"
    },
    {
      "x": -3,
      "y": 22,
      "z": -3,
      "name": "Plant_Leaves_Palo"
    },
    {
      "x": -3,
      "y": 24,
      "z": -3,
      "name": "Plant_Leaves_Palo"
    },
    {
      "x": -3,
      "y": 17,
      "z": -2,
      "name": "Wood_Palo_Trunk_Full"
    },
    {
      "x": -3,
      "y": 19,
      "z": -2,
      "name": "Plant_Leaves_Palo"
    },
    {
      "x": -3,
      "y": 23,
      "z": -2,
      "name": "Plant_Leaves_Palo"
    },
    {
      "x": -3,
      "y": 24,
      "z": -2,
      "name": "Plant_Leaves_Palo"
    },
    {
      "x": -3,
      "y": 13,
      "z": -1,
      "name": "Wood_Palo_Trunk_Full"
    },
    {
      "x": -3,
      "y": 14,
      "z": -1,
      "name": "Wood_Palo_Trunk"
    },
    {
      "x": -3,
      "y": 15,
      "z": -1,
      "name": "Wood_Palo_Trunk_Full"
    },
    {
      "x": -3,
      "y": 17,
      "z": -1,
      "name": "Wood_Palo_Trunk_Full"
    },
    {
      "x": -3,
      "y": 19,
      "z": -1,
      "name": "Plant_Leaves_Palo"
    },
    {
      "x": -3,
      "y": 23,
      "z": -1,
      "name": "Plant_Leaves_Palo"
    },
    {
      "x": -3,
      "y": 24,
      "z": -1,
      "name": "Plant_Leaves_Palo"
    },
    {
      "x": -3,
      "y": 9,
      "z": 0,
      "name": "Wood_Palo_Roots"
    },
    {
      "x": -3,
      "y": 10,
      "z": 0,
      "name": "Wood_Palo_Trunk_Full"
    },
    {
      "x": -3,
      "y": 11,
      "z": 0,
      "name": "Wood_Palo_Trunk"
    },
    {
      "x": -3,
      "y": 12,
      "z": 0,
      "name": "Wood_Palo_Trunk"
    },
    {
      "x": -3,
      "y": 13,
      "z": 0,
      "name": "Wood_Palo_Trunk"
    },
    {
      "x": -3,
      "y": 14,
      "z": 0,
      "name": "Wood_Palo_Trunk"
    },
    {
      "x": -3,
      "y": 15,
      "z": 0,
      "name": "Wood_Palo_Trunk"
    },
    {
      "x": -3,
      "y": 16,
      "z": 0,
      "name": "Wood_Palo_Trunk_Full"
    },
    {
      "x": -3,
      "y": 17,
      "z": 0,
      "name": "Wood_Palo_Trunk"
    },
    {
      "x": -3,
      "y": 18,
      "z": 0,
      "name": "Wood_Palo_Trunk"
    },
    {
      "x": -3,
      "y": 19,
      "z": 0,
      "name": "Wood_Palo_Trunk_Full"
    },
    {
      "x": -3,
      "y": 22,
      "z": 0,
      "name": "Wood_Palo_Trunk_Full"
    },
    {
      "x": -3,
      "y": 23,
      "z": 0,
      "name": "Wood_Palo_Trunk_Full"
    },
    {
      "x": -3,
      "y": 24,
      "z": 0,
      "name": "Plant_Leaves_Palo"
    },
    {
      "x": -3,
      "y": 13,
      "z": 1,
      "name": "Wood_Palo_Trunk_Full"
    },
    {
      "x": -3,
      "y": 14,
      "z": 1,
      "name": "Wood_Palo_Trunk"
    },
    {
      "x": -3,
      "y": 15,
      "z": 1,
      "name": "Wood_Palo_Trunk"
    },
    {
      "x": -3,
      "y": 16,
      "z": 1,
      "name": "Wood_Palo_Trunk_Full"
    },
    {
      "x": -3,
      "y": 18,
      "z": 1,
      "name": "Wood_Palo_Trunk_Full"
    },
    {
      "x": -3,
      "y": 19,
      "z": 1,
      "name": "Wood_Palo_Trunk_Full"
    },
    {
      "x": -3,
      "y": 23,
      "z": 1,
      "name": "Wood_Palo_Branch_Long",
      "rotation": 4
    },
    {
      "x": -3,
      "y": 24,
      "z": 1,
      "name": "Plant_Leaves_Palo"
    },
    {
      "x": -3,
      "y": 25,
      "z": 1,
      "name": "Plant_Leaves_Palo"
    },
    {
      "x": -3,
      "y": 19,
      "z": 2,
      "name": "Wood_Palo_Trunk_Full"
    },
    {
      "x": -3,
      "y": 23,
      "z": 2,
      "name": "Plant_Leaves_Palo"
    },
    {
      "x": -3,
      "y": 24,
      "z": 2,
      "name": "Plant_Leaves_Palo"
    },
    {
      "x": -3,
      "y": 20,
      "z": 3,
      "name": "Plant_Leaves_Palo"
    },
    {
      "x": -3,
      "y": 23,
      "z": 3,
      "name": "Plant_Leaves_Palo"
    },
    {
      "x": -3,
      "y": 24,
      "z": 3,
      "name": "Plant_Leaves_Palo"
    },
    {
      "x": -3,
      "y": 19,
      "z": 4,
      "name": "Plant_Leaves_Palo"
    },
    {
      "x": -3,
      "y": 23,
      "z": 4,
      "name": "Plant_Leaves_Palo"
    },
    {
      "x": -3,
      "y": 19,
      "z": 5,
      "name": "Plant_Leaves_Palo"
    },
    {
      "x": -3,
      "y": 20,
      "z": 5,
      "name": "Plant_Leaves_Palo"
    },
    {
      "x": -3,
      "y": 19,
      "z": 6,
      "name": "Plant_Leaves_Palo"
    },
    {
      "x": -3,
      "y": 19,
      "z": 7,
      "name": "Plant_Leaves_Palo"
    },
    {
      "x": -2,
      "y": 19,
      "z": -7,
      "name": "Plant_Leaves_Palo"
    },
    {
      "x": -2,
      "y": 21,
      "z": -7,
      "name": "Plant_Leaves_Palo"
    },
    {
      "x": -2,
      "y": 19,
      "z": -6,
      "name": "Plant_Leaves_Palo"
    },
    {
      "x": -2,
      "y": 21,
      "z": -6,
      "name": "Wood_Palo_Branch_Long",
      "rotation": 4
    },
    {
      "x": -2,
      "y": 22,
      "z": -6,
      "name": "Plant_Leaves_Palo"
    },
    {
      "x": -2,
      "y": 19,
      "z": -5,
      "name": "Plant_Leaves_Palo"
    },
    {
      "x": -2,
      "y": 21,
      "z": -5,
      "name": "Wood_Palo_Branch_Long",
      "rotation": 4
    },
    {
      "x": -2,
      "y": 22,
      "z": -5,
      "name": "Plant_Leaves_Palo"
    },
    {
      "x": -2,
      "y": 19,
      "z": -4,
      "name": "Plant_Leaves_Palo"
    },
    {
      "x": -2,
      "y": 20,
      "z": -4,
      "name": "Plant_Leaves_Palo"
    },
    {
      "x": -2,
      "y": 21,
      "z": -4,
      "name": "Wood_Palo_Trunk_Full"
    },
    {
      "x": -2,
      "y": 22,
      "z": -4,
      "name": "Plant_Leaves_Palo"
    },
    {
      "x": -2,
      "y": 9,
      "z": -3,
      "name": "Wood_Palo_Roots"
    },
    {
      "x": -2,
      "y": 10,
      "z": -3,
      "name": "Wood_Palo_Trunk_Full"
    },
    {
      "x": -2,
      "y": 11,
      "z": -3,
      "name": "Wood_Palo_Trunk_Full"
    },
    {
      "x": -2,
      "y": 19,
      "z": -3,
      "name": "Wood_Palo_Branch_Long",
      "rotation": 5
    },
    {
      "x": -2,
      "y": 20,
      "z": -3,
      "name": "Plant_Leaves_Palo"
    },
    {
      "x": -2,
      "y": 21,
      "z": -3,
      "name": "Wood_Palo_Trunk_Full"
    },
    {
      "x": -2,
      "y": 22,
      "z": -3,
      "name": "Plant_Leaves_Palo"
    },
    {
      "x": -2,
      "y": 11,
      "z": -2,
      "name": "Wood_Palo_Trunk_Full"
    },
    {
      "x": -2,
      "y": 12,
      "z": -2,
      "name": "Wood_Palo_Trunk_Full"
    },
    {
      "x": -2,
      "y": 17,
      "z": -2,
      "name": "Wood_Palo_Trunk_Full"
    },
    {
      "x": -2,
      "y": 20,
      "z": -2,
      "name": "Plant_Leaves_Palo"
    },
    {
      "x": -2,
      "y": 21,
      "z": -2,
      "name": "Wood_Palo_Trunk_Full"
    },
    {
      "x": -2,
      "y": 23,
      "z": -2,
      "name": "Plant_Leaves_Palo"
    },
    {
      "x": -2,
      "y": 24,
      "z": -2,
      "name": "Plant_Leaves_Palo"
    },
    {
      "x": -2,
      "y": 9,
      "z": -1,
      "name": "Wood_Palo_Roots"
    },
    {
      "x": -2,
      "y": 10,
      "z": -1,
      "name": "Wood_Palo_Trunk_Full"
    },
    {
      "x": -2,
      "y": 11,
      "z": -1,
      "name": "Wood_Palo_Trunk"
    },
    {
      "x": -2,
      "y": 12,
      "z": -1,
      "name": "Wood_Palo_Trunk"
    },
    {
      "x": -2,
      "y": 13,
      "z": -1,
      "name": "Wood_Palo_Trunk"
    },
    {
      "x": -2,
      "y": 14,
      "z": -1,
      "name": "Wood_Palo_Trunk"
    },
    {
      "x": -2,
      "y": 15,
      "z": -1,
      "name": "Wood_Palo_Trunk"
    },
    {
      "x": -2,
      "y": 16,
      "z": -1,
      "name": "Wood_Palo_Trunk_Full"
    },
    {
      "x": -2,
      "y": 17,
      "z": -1,
      "name": "Wood_Palo_Trunk_Full"
    },
    {
      "x": -2,
      "y": 18,
      "z": -1,
      "name": "Wood_Palo_Trunk"
    },
    {
      "x": -2,
      "y": 19,
      "z": -1,
      "name": "Wood_Palo_Trunk_Full"
    },
    {
      "x": -2,
      "y": 20,
      "z": -1,
      "name": "Wood_Palo_Trunk_Full"
    },
    {
      "x": -2,
      "y": 21,
      "z": -1,
      "name": "Wood_Palo_Trunk_Full"
    },
    {
      "x": -2,
      "y": 23,
      "z": -1,
      "name": "Plant_Leaves_Palo"
    },
    {
      "x": -2,
      "y": 24,
      "z": -1,
      "name": "Plant_Leaves_Palo"
    },
    {
      "x": -2,
      "y": 25,
      "z": -1,
      "name": "Plant_Leaves_Palo"
    },
    {
      "x": -2,
      "y": 5,
      "z": 0,
      "name": "Wood_Palo_Roots"
    },
    {
      "x": -2,
      "y": 6,
      "z": 0,
      "name": "Wood_Palo_Trunk"
    },
    {
      "x": -2,
      "y": 7,
      "z": 0,
      "name": "Wood_Palo_Trunk"
    },
    {
      "x": -2,
      "y": 8,
      "z": 0,
      "name": "Wood_Palo_Trunk"
    },
    {
      "x": -2,
      "y": 9,
      "z": 0,
      "name": "Wood_Palo_Trunk"
    },
    {
      "x": -2,
      "y": 10,
      "z": 0,
      "name": "Wood_Palo_Trunk"
    },
    {
      "x": -2,
      "y": 11,
      "z": 0,
      "name": "Wood_Palo_Trunk"
    },
    {
      "x": -2,
      "y": 12,
      "z": 0,
      "name": "Wood_Palo_Trunk"
    },
    {
      "x": -2,
      "y": 13,
      "z": 0,
      "name": "Wood_Palo_Trunk"
    },
    {
      "x": -2,
      "y": 14,
      "z": 0,
      "name": "Wood_Palo_Trunk"
    },
    {
      "x": -2,
      "y": 15,
      "z": 0,
      "name": "Wood_Palo_Trunk"
    },
    {
      "x": -2,
      "y": 16,
      "z": 0,
      "name": "Wood_Palo_Trunk"
    },
    {
      "x": -2,
      "y": 17,
      "z": 0,
      "name": "Wood_Palo_Trunk_Full"
    },
    {
      "x": -2,
      "y": 18,
      "z": 0,
      "name": "Wood_Palo_Trunk"
    },
    {
      "x": -2,
      "y": 19,
      "z": 0,
      "name": "Wood_Palo_Trunk"
    },
    {
      "x": -2,
      "y": 20,
      "z": 0,
      "name": "Wood_Palo_Trunk"
    },
    {
      "x": -2,
      "y": 21,
      "z": 0,
      "name": "Wood_Palo_Trunk"
    },
    {
      "x": -2,
      "y": 22,
      "z": 0,
      "name": "Wood_Palo_Trunk_Full"
    },
    {
      "x": -2,
      "y": 23,
      "z": 0,
      "name": "Wood_Palo_Trunk"
    },
    {
      "x": -2,
      "y": 24,
      "z": 0,
      "name": "Plant_Leaves_Palo"
    },
    {
      "x": -2,
      "y": 25,
      "z": 0,
      "name": "Plant_Leaves_Palo"
    },
    {
      "x": -2,
      "y": 8,
      "z": 1,
      "name": "Wood_Palo_Trunk_Full"
    },
    {
      "x": -2,
      "y": 9,
      "z": 1,
      "name": "Wood_Palo_Trunk_Full"
    },
    {
      "x": -2,
      "y": 10,
      "z": 1,
      "name": "Wood_Palo_Trunk_Full"
    },
    {
      "x": -2,
      "y": 11,
      "z": 1,
      "name": "Wood_Palo_Trunk_Full"
    },
    {
      "x": -2,
      "y": 12,
      "z": 1,
      "name": "Wood_Palo_Trunk"
    },
    {
      "x": -2,
      "y": 13,
      "z": 1,
      "name": "Wood_Palo_Trunk"
    },
    {
      "x": -2,
      "y": 14,
      "z": 1,
      "name": "Wood_Palo_Trunk"
    },
    {
      "x": -2,
      "y": 15,
      "z": 1,
      "name": "Wood_Palo_Trunk"
    },
    {
      "x": -2,
      "y": 16,
      "z": 1,
      "name": "Wood_Palo_Trunk"
    },
    {
      "x": -2,
      "y": 17,
      "z": 1,
      "name": "Wood_Palo_Trunk"
    },
    {
      "x": -2,
      "y": 18,
      "z": 1,
      "name": "Wood_Palo_Trunk"
    },
    {
      "x": -2,
      "y": 19,
      "z": 1,
      "name": "Wood_Palo_Trunk"
    },
    {
      "x": -2,
      "y": 20,
      "z": 1,
      "name": "Wood_Palo_Trunk"
    },
    {
      "x": -2,
      "y": 21,
      "z": 1,
      "name": "Wood_Palo_Trunk"
    },
    {
      "x": -2,
      "y": 22,
      "z": 1,
      "name": "Wood_Palo_Trunk_Full"
    },
    {
      "x": -2,
      "y": 24,
      "z": 1,
      "name": "Plant_Leaves_Palo"
    },
    {
      "x": -2,
      "y": 25,
      "z": 1,
      "name": "Plant_Leaves_Palo"
    },
    {
      "x": -2,
      "y": 9,
      "z": 2,
      "name": "Wood_Palo_Roots"
    },
    {
      "x": -2,
      "y": 10,
      "z": 2,
      "name": "Wood_Palo_Trunk_Full"
    },
    {
      "x": -2,
      "y": 11,
      "z": 2,
      "name": "Wood_Palo_Trunk_Full"
    },
    {
      "x": -2,
      "y": 20,
      "z": 2,
      "name": "Wood_Palo_Trunk_Full"
    },
    {
      "x": -2,
      "y": 21,
      "z": 2,
      "name": "Wood_Palo_Trunk"
    },
    {
      "x": -2,
      "y": 22,
      "z": 2,
      "name": "Wood_Palo_Trunk_Full"
    },
    {
      "x": -2,
      "y": 23,
      "z": 2,
      "name": "Wood_Palo_Trunk_Full"
    },
    {
      "x": -2,
      "y": 9,
      "z": 3,
      "name": "Wood_Palo_Branch_Long"
    },
    {
      "x": -2,
      "y": 10,
      "z": 3,
      "name": "Wood_Palo_Branch_Corner",
      "rotation": 10
    },
    {
      "x": -2,
      "y": 19,
      "z": 3,
      "name": "Plant_Leaves_Palo"
    },
    {
      "x": -2,
      "y": 23,
      "z": 3,
      "name": "Wood_Palo_Branch_Long",
      "rotation": 4
    },
    {
      "x": -2,
      "y": 24,
      "z": 3,
      "name": "Plant_Leaves_Palo"
    },
    {
      "x": -2,
      "y": 19,
      "z": 4,
      "name": "Plant_Leaves_Palo"
    },
    {
      "x": -2,
      "y": 20,
      "z": 4,
      "name": "Plant_Leaves_Palo"
    },
    {
      "x": -2,
      "y": 23,
      "z": 4,
      "name": "Plant_Leaves_Palo"
    },
    {
      "x": -2,
      "y": 19,
      "z": 5,
      "name": "Plant_Leaves_Palo"
    },
    {
      "x": -2,
      "y": 20,
      "z": 5,
      "name": "Plant_Leaves_Palo"
    },
    {
      "x": -2,
      "y": 23,
      "z": 5,
      "name": "Plant_Leaves_Palo"
    },
    {
      "x": -2,
      "y": 19,
      "z": 6,
      "name": "Plant_Leaves_Palo"
    },
    {
      "x": -1,
      "y": 19,
      "z": -7,
      "name": "Plant_Leaves_Palo"
    },
    {
      "x": -1,
      "y": 21,
      "z": -7,
      "name": "Plant_Leaves_Palo"
    },
    {
      "x": -1,
      "y": 19,
      "z": -6,
      "name": "Plant_Leaves_Palo"
    },
    {
      "x": -1,
      "y": 20,
      "z": -6,
      "name": "Plant_Leaves_Palo"
    },
    {
      "x": -1,
      "y": 21,
      "z": -6,
      "name": "Plant_Leaves_Palo"
    },
    {
      "x": -1,
      "y": 19,
      "z": -5,
      "name": "Wood_Palo_Branch_Long",
      "rotation": 4
    },
    {
      "x": -1,
      "y": 20,
      "z": -5,
      "name": "Plant_Leaves_Palo"
    },
    {
      "x": -1,
      "y": 22,
      "z": -5,
      "name": "Plant_Leaves_Palo"
    },
    {
      "x": -1,
      "y": 19,
      "z": -4,
      "name": "Wood_Palo_Branch_Long",
      "rotation": 4
    },
    {
      "x": -1,
      "y": 20,
      "z": -4,
      "name": "Plant_Leaves_Palo"
    },
    {
      "x": -1,
      "y": 21,
      "z": -4,
      "name": "Wood_Palo_Branch_Long",
      "rotation": 5
    },
    {
      "x": -1,
      "y": 22,
      "z": -4,
      "name": "Plant_Leaves_Palo"
    },
    {
      "x": -1,
      "y": 19,
      "z": -3,
      "name": "Wood_Palo_Trunk_Full"
    },
    {
      "x": -1,
      "y": 20,
      "z": -3,
      "name": "Plant_Leaves_Palo"
    },
    {
      "x": -1,
      "y": 22,
      "z": -3,
      "name": "Plant_Leaves_Palo"
    },
    {
      "x": -1,
      "y": 24,
      "z": -3,
      "name": "Plant_Leaves_Palo"
    },
    {
      "x": -1,
      "y": 10,
      "z": -2,
      "name": "Wood_Palo_Branch_Long"
    },
    {
      "x": -1,
      "y": 11,
      "z": -2,
      "name": "Wood_Palo_Branch_Corner",
      "rotation": 11
    },
    {
      "x": -1,
      "y": 19,
      "z": -2,
      "name": "Wood_Palo_Trunk_Full"
    },
    {
      "x": -1,
      "y": 20,
      "z": -2,
      "name": "Plant_Leaves_Palo"
    },
    {
      "x": -1,
      "y": 22,
      "z": -2,
      "name": "Plant_Leaves_Palo"
    },
    {
      "x": -1,
      "y": 24,
      "z": -2,
      "name": "Plant_Leaves_Palo"
    },
    {
      "x": -1,
      "y": 12,
      "z": -1,
      "name": "Wood_Palo_Trunk_Full"
    },
    {
      "x": -1,
      "y": 13,
      "z": -1,
      "name": "Wood_Palo_Trunk_Full"
    },
    {
      "x": -1,
      "y": 14,
      "z": -1,
      "name": "Wood_Palo_Trunk_Full"
    },
    {
      "x": -1,
      "y": 18,
      "z": -1,
      "name": "Wood_Palo_Trunk_Full"
    },
    {
      "x": -1,
      "y": 19,
      "z": -1,
      "name": "Wood_Palo_Trunk_Full"
    },
    {
      "x": -1,
      "y": 21,
      "z": -1,
      "name": "Wood_Palo_Trunk_Full"
    },
    {
      "x": -1,
      "y": 22,
      "z": -1,
      "name": "Wood_Palo_Trunk_Full"
    },
    {
      "x": -1,
      "y": 23,
      "z": -1,
      "name": "Plant_Leaves_Palo"
    },
    {
      "x": -1,
      "y": 24,
      "z": -1,
      "name": "Plant_Leaves_Palo"
    },
    {
      "x": -1,
      "y": 8,
      "z": 0,
      "name": "Wood_Palo_Roots"
    },
    {
      "x": -1,
      "y": 9,
      "z": 0,
      "name": "Wood_Palo_Trunk_Full"
    },
    {
      "x": -1,
      "y": 10,
      "z": 0,
      "name": "Wood_Palo_Trunk"
    },
    {
      "x": -1,
      "y": 11,
      "z": 0,
      "name": "Wood_Palo_Trunk"
    },
    {
      "x": -1,
      "y": 12,
      "z": 0,
      "name": "Wood_Palo_Trunk"
    },
    {
      "x": -1,
      "y": 13,
      "z": 0,
      "name": "Wood_Palo_Trunk"
    },
    {
      "x": -1,
      "y": 14,
      "z": 0,
      "name": "Wood_Palo_Trunk"
    },
    {
      "x": -1,
      "y": 15,
      "z": 0,
      "name": "Wood_Palo_Trunk"
    },
    {
      "x": -1,
      "y": 16,
      "z": 0,
      "name": "Wood_Palo_Trunk_Full"
    },
    {
      "x": -1,
      "y": 17,
      "z": 0,
      "name": "Wood_Palo_Trunk_Full"
    },
    {
      "x": -1,
      "y": 18,
      "z": 0,
      "name": "Wood_Palo_Trunk_Full"
    },
    {
      "x": -1,
      "y": 19,
      "z": 0,
      "name": "Wood_Palo_Trunk"
    },
    {
      "x": -1,
      "y": 23,
      "z": 0,
      "name": "Plant_Leaves_Palo"
    },
    {
      "x": -1,
      "y": 24,
      "z": 0,
      "name": "Plant_Leaves_Palo"
    },
    {
      "x": -1,
      "y": 25,
      "z": 0,
      "name": "Plant_Leaves_Palo"
    },
    {
      "x": -1,
      "y": 13,
      "z": 1,
      "name": "Wood_Palo_Trunk_Full"
    },
    {
      "x": -1,
      "y": 14,
      "z": 1,
      "name": "Wood_Palo_Trunk"
    },
    {
      "x": -1,
      "y": 15,
      "z": 1,
      "name": "Wood_Palo_Trunk_Full"
    },
    {
      "x": -1,
      "y": 16,
      "z": 1,
      "name": "Wood_Palo_Trunk_Full"
    },
    {
      "x": -1,
      "y": 17,
      "z": 1,
      "name": "Wood_Palo_Trunk_Full"
    },
    {
      "x": -1,
      "y": 19,
      "z": 1,
      "name": "Wood_Palo_Trunk_Full"
    },
    {
      "x": -1,
      "y": 23,
      "z": 1,
      "name": "Plant_Leaves_Palo"
    },
    {
      "x": -1,
      "y": 24,
      "z": 1,
      "name": "Plant_Leaves_Palo"
    },
    {
      "x": -1,
      "y": 25,
      "z": 1,
      "name": "Plant_Leaves_Palo"
    },
    {
      "x": -1,
      "y": 23,
      "z": 2,
      "name": "Wood_Palo_Branch_Long",
      "rotation": 5
    },
    {
      "x": -1,
      "y": 24,
      "z": 2,
      "name": "Plant_Leaves_Palo"
    },
    {
      "x": -1,
      "y": 20,
      "z": 3,
      "name": "Plant_Leaves_Palo"
    },
    {
      "x": -1,
      "y": 24,
      "z": 3,
      "name": "Plant_Leaves_Palo"
    },
    {
      "x": -1,
      "y": 19,
      "z": 4,
      "name": "Plant_Leaves_Palo"
    },
    {
      "x": -1,
      "y": 23,
      "z": 4,
      "name": "Plant_Leaves_Palo"
    },
    {
      "x": -1,
      "y": 24,
      "z": 4,
      "name": "Plant_Leaves_Palo"
    },
    {
      "x": -1,
      "y": 19,
      "z": 5,
      "name": "Plant_Leaves_Palo"
    },
    {
      "x": -1,
      "y": 23,
      "z": 5,
      "name": "Plant_Leaves_Palo"
    },
    {
      "x": 0,
      "y": 19,
      "z": -6,
      "name": "Plant_Leaves_Palo"
    },
    {
      "x": 0,
      "y": 19,
      "z": -5,
      "name": "Plant_Leaves_Palo"
    },
    {
      "x": 0,
      "y": 19,
      "z": -4,
      "name": "Plant_Leaves_Palo"
    },
    {
      "x": 0,
      "y": 20,
      "z": -4,
      "name": "Plant_Leaves_Palo"
    },
    {
      "x": 0,
      "y": 22,
      "z": -4,
      "name": "Plant_Leaves_Palo"
    },
    {
      "x": 0,
      "y": 19,
      "z": -3,
      "name": "Wood_Palo_Branch_Long",
      "rotation": 5
    },
    {
      "x": 0,
      "y": 20,
      "z": -3,
      "name": "Plant_Leaves_Palo"
    },
    {
      "x": 0,
      "y": 22,
      "z": -3,
      "name": "Plant_Leaves_Palo"
    },
    {
      "x": 0,
      "y": 20,
      "z": -2,
      "name": "Plant_Leaves_Palo"
    },
    {
      "x": 0,
      "y": 23,
      "z": -2,
      "name": "Plant_Leaves_Palo"
    },
    {
      "x": 0,
      "y": 24,
      "z": -2,
      "name": "Plant_Leaves_Palo"
    },
    {
      "x": 0,
      "y": 20,
      "z": -1,
      "name": "Plant_Leaves_Palo"
    },
    {
      "x": 0,
      "y": 22,
      "z": -1,
      "name": "Wood_Palo_Trunk_Full"
    },
    {
      "x": 0,
      "y": 23,
      "z": -1,
      "name": "Plant_Leaves_Palo"
    },
    {
      "x": 0,
      "y": 24,
      "z": -1,
      "name": "Plant_Leaves_Palo"
    },
    {
      "x": 0,
      "y": 10,
      "z": 0,
      "name": "Wood_Palo_Trunk_Full"
    },
    {
      "x": 0,
      "y": 11,
      "z": 0,
      "name": "Wood_Palo_Trunk_Full"
    },
    {
      "x": 0,
      "y": 16,
      "z": 0,
      "name": "Wood_Palo_Trunk_Full"
    },
    {
      "x": 0,
      "y": 23,
      "z": 0,
      "name": "Plant_Leaves_Palo"
    },
    {
      "x": 0,
      "y": 24,
      "z": 0,
      "name": "Plant_Leaves_Palo"
    },
    {
      "x": 0,
      "y": 16,
      "z": 1,
      "name": "Wood_Palo_Trunk_Full"
    },
    {
      "x": 0,
      "y": 19,
      "z": 1,
      "name": "Wood_Palo_Trunk_Full"
    },
    {
      "x": 0,
      "y": 21,
      "z": 1,
      "name": "Plant_Leaves_Palo"
    },
    {
      "x": 0,
      "y": 22,
      "z": 1,
      "name": "Plant_Leaves_Palo"
    },
    {
      "x": 0,
      "y": 24,
      "z": 1,
      "name": "Plant_Leaves_Palo"
    },
    {
      "x": 0,
      "y": 19,
      "z": 2,
      "name": "Wood_Palo_Trunk_Full"
    },
    {
      "x": 0,
      "y": 20,
      "z": 2,
      "name": "Plant_Leaves_Palo"
    },
    {
      "x": 0,
      "y": 21,
      "z": 2,
      "name": "Plant_Leaves_Palo"
    },
    {
      "x": 0,
      "y": 23,
      "z": 2,
      "name": "Plant_Leaves_Palo"
    },
    {
      "x": 0,
      "y": 24,
      "z": 2,
      "name": "Plant_Leaves_Palo"
    },
    {
      "x": 0,
      "y": 20,
      "z": 3,
      "name": "Plant_Leaves_Palo"
    },
    {
      "x": 0,
      "y": 21,
      "z": 3,
      "name": "Plant_Leaves_Palo"
    },
    {
      "x": 0,
      "y": 24,
      "z": 3,
      "name": "Plant_Leaves_Palo"
    },
    {
      "x": 0,
      "y": 16,
      "z": 4,
      "name": "Plant_Leaves_Palo"
    },
    {
      "x": 0,
      "y": 19,
      "z": 4,
      "name": "Plant_Leaves_Palo"
    },
    {
      "x": 0,
      "y": 23,
      "z": 4,
      "name": "Plant_Leaves_Palo"
    },
    {
      "x": 0,
      "y": 16,
      "z": 5,
      "name": "Plant_Leaves_Palo"
    },
    {
      "x": 0,
      "y": 19,
      "z": 5,
      "name": "Plant_Leaves_Palo"
    },
    {
      "x": 0,
      "y": 23,
      "z": 5,
      "name": "Plant_Leaves_Palo"
    },
    {
      "x": 1,
      "y": 19,
      "z": -4,
      "name": "Plant_Leaves_Palo"
    },
    {
      "x": 1,
      "y": 20,
      "z": -4,
      "name": "Plant_Leaves_Palo"
    },
    {
      "x": 1,
      "y": 22,
      "z": -4,
      "name": "Plant_Leaves_Palo"
    },
    {
      "x": 1,
      "y": 22,
      "z": -3,
      "name": "Wood_Palo_Branch_Long",
      "rotation": 4
    },
    {
      "x": 1,
      "y": 23,
      "z": -3,
      "name": "Plant_Leaves_Palo"
    },
    {
      "x": 1,
      "y": 22,
      "z": -2,
      "name": "Wood_Palo_Branch_Long",
      "rotation": 4
    },
    {
      "x": 1,
      "y": 23,
      "z": -2,
      "name": "Plant_Leaves_Palo"
    },
    {
      "x": 1,
      "y": 22,
      "z": -1,
      "name": "Wood_Palo_Trunk_Full"
    },
    {
      "x": 1,
      "y": 23,
      "z": -1,
      "name": "Plant_Leaves_Palo"
    },
    {
      "x": 1,
      "y": 8,
      "z": 0,
      "name": "Wood_Palo_Roots"
    },
    {
      "x": 1,
      "y": 9,
      "z": 0,
      "name": "Wood_Palo_Trunk_Full"
    },
    {
      "x": 1,
      "y": 10,
      "z": 0,
      "name": "Wood_Palo_Trunk_Full"
    },
    {
      "x": 1,
      "y": 19,
      "z": 0,
      "name": "Plant_Leaves_Palo"
    },
    {
      "x": 1,
      "y": 22,
      "z": 0,
      "name": "Wood_Palo_Branch_Long",
      "rotation": 4
    },
    {
      "x": 1,
      "y": 23,
      "z": 0,
      "name": "Plant_Leaves_Palo"
    },
    {
      "x": 1,
      "y": 16,
      "z": 1,
      "name": "Wood_Palo_Trunk_Full"
    },
    {
      "x": 1,
      "y": 20,
      "z": 1,
      "name": "Plant_Leaves_Palo"
    },
    {
      "x": 1,
      "y": 16,
      "z": 2,
      "name": "Wood_Palo_Trunk_Full"
    },
    {
      "x": 1,
      "y": 17,
      "z": 2,
      "name": "Wood_Palo_Trunk_Full"
    },
    {
      "x": 1,
      "y": 19,
      "z": 2,
      "name": "Wood_Palo_Trunk_Full"
    },
    {
      "x": 1,
      "y": 20,
      "z": 2,
      "name": "Plant_Leaves_Palo"
    },
    {
      "x": 1,
      "y": 21,
      "z": 2,
      "name": "Plant_Leaves_Palo"
    },
    {
      "x": 1,
      "y": 23,
      "z": 2,
      "name": "Plant_Leaves_Palo"
    },
    {
      "x": 1,
      "y": 19,
      "z": 3,
      "name": "Wood_Palo_Branch_Long",
      "rotation": 4
    },
    {
      "x": 1,
      "y": 20,
      "z": 3,
      "name": "Plant_Leaves_Palo"
    },
    {
      "x": 1,
      "y": 21,
      "z": 3,
      "name": "Plant_Leaves_Palo"
    },
    {
      "x": 1,
      "y": 22,
      "z": 3,
      "name": "Plant_Leaves_Palo"
    },
    {
      "x": 1,
      "y": 23,
      "z": 3,
      "name": "Plant_Leaves_Palo"
    },
    {
      "x": 1,
      "y": 17,
      "z": 4,
      "name": "Plant_Leaves_Palo"
    },
    {
      "x": 1,
      "y": 19,
      "z": 4,
      "name": "Wood_Palo_Branch_Long",
      "rotation": 4
    },
    {
      "x": 1,
      "y": 20,
      "z": 4,
      "name": "Plant_Leaves_Palo"
    },
    {
      "x": 1,
      "y": 23,
      "z": 4,
      "name": "Plant_Leaves_Palo"
    },
    {
      "x": 1,
      "y": 16,
      "z": 5,
      "name": "Plant_Leaves_Palo"
    },
    {
      "x": 1,
      "y": 19,
      "z": 5,
      "name": "Plant_Leaves_Palo"
    },
    {
      "x": 1,
      "y": 16,
      "z": 6,
      "name": "Plant_Leaves_Palo"
    },
    {
      "x": 1,
      "y": 19,
      "z": 6,
      "name": "Plant_Leaves_Palo"
    },
    {
      "x": 2,
      "y": 22,
      "z": -4,
      "name": "Plant_Leaves_Palo"
    },
    {
      "x": 2,
      "y": 22,
      "z": -3,
      "name": "Plant_Leaves_Palo"
    },
    {
      "x": 2,
      "y": 23,
      "z": -2,
      "name": "Plant_Leaves_Palo"
    },
    {
      "x": 2,
      "y": 19,
      "z": -1,
      "name": "Plant_Leaves_Palo"
    },
    {
      "x": 2,
      "y": 22,
      "z": -1,
      "name": "Wood_Palo_Branch_Long",
      "rotation": 5
    },
    {
      "x": 2,
      "y": 23,
      "z": -1,
      "name": "Plant_Leaves_Palo"
    },
    {
      "x": 2,
      "y": 19,
      "z": 0,
      "name": "Plant_Leaves_Palo"
    },
    {
      "x": 2,
      "y": 20,
      "z": 0,
      "name": "Plant_Leaves_Palo"
    },
    {
      "x": 2,
      "y": 23,
      "z": 0,
      "name": "Plant_Leaves_Palo"
    },
    {
      "x": 2,
      "y": 19,
      "z": 1,
      "name": "Plant_Leaves_Palo"
    },
    {
      "x": 2,
      "y": 17,
      "z": 2,
      "name": "Wood_Palo_Trunk_Full"
    },
    {
      "x": 2,
      "y": 19,
      "z": 2,
      "name": "Wood_Palo_Branch_Long",
      "rotation": 5
    },
    {
      "x": 2,
      "y": 20,
      "z": 2,
      "name": "Plant_Leaves_Palo"
    },
    {
      "x": 2,
      "y": 21,
      "z": 2,
      "name": "Plant_Leaves_Palo"
    },
    {
      "x": 2,
      "y": 17,
      "z": 3,
      "name": "Wood_Palo_Branch_Long",
      "rotation": 4
    },
    {
      "x": 2,
      "y": 18,
      "z": 3,
      "name": "Plant_Leaves_Palo"
    },
    {
      "x": 2,
      "y": 20,
      "z": 3,
      "name": "Plant_Leaves_Palo"
    },
    {
      "x": 2,
      "y": 17,
      "z": 4,
      "name": "Wood_Palo_Branch_Long",
      "rotation": 4
    },
    {
      "x": 2,
      "y": 18,
      "z": 4,
      "name": "Plant_Leaves_Palo"
    },
    {
      "x": 2,
      "y": 19,
      "z": 4,
      "name": "Plant_Leaves_Palo"
    },
    {
      "x": 2,
      "y": 20,
      "z": 4,
      "name": "Plant_Leaves_Palo"
    },
    {
      "x": 2,
      "y": 16,
      "z": 5,
      "name": "Plant_Leaves_Palo"
    },
    {
      "x": 2,
      "y": 17,
      "z": 5,
      "name": "Plant_Leaves_Palo"
    },
    {
      "x": 2,
      "y": 19,
      "z": 5,
      "name": "Plant_Leaves_Palo"
    },
    {
      "x": 2,
      "y": 16,
      "z": 6,
      "name": "Plant_Leaves_Palo"
    },
    {
      "x": 2,
      "y": 19,
      "z": 6,
      "name": "Plant_Leaves_Palo"
    },
    {
      "x": 3,
      "y": 22,
      "z": -3,
      "name": "Plant_Leaves_Palo"
    },
    {
      "x": 3,
      "y": 22,
      "z": -2,
      "name": "Plant_Leaves_Palo"
    },
    {
      "x": 3,
      "y": 19,
      "z": -1,
      "name": "Plant_Leaves_Palo"
    },
    {
      "x": 3,
      "y": 22,
      "z": -1,
      "name": "Wood_Palo_Branch_Long",
      "rotation": 5
    },
    {
      "x": 3,
      "y": 23,
      "z": -1,
      "name": "Plant_Leaves_Palo"
    },
    {
      "x": 3,
      "y": 19,
      "z": 0,
      "name": "Plant_Leaves_Palo"
    },
    {
      "x": 3,
      "y": 20,
      "z": 0,
      "name": "Plant_Leaves_Palo"
    },
    {
      "x": 3,
      "y": 22,
      "z": 0,
      "name": "Plant_Leaves_Palo"
    },
    {
      "x": 3,
      "y": 17,
      "z": 1,
      "name": "Plant_Leaves_Palo"
    },
    {
      "x": 3,
      "y": 19,
      "z": 1,
      "name": "Plant_Leaves_Palo"
    },
    {
      "x": 3,
      "y": 20,
      "z": 1,
      "name": "Plant_Leaves_Palo"
    },
    {
      "x": 3,
      "y": 17,
      "z": 2,
      "name": "Wood_Palo_Branch_Long",
      "rotation": 5
    },
    {
      "x": 3,
      "y": 18,
      "z": 2,
      "name": "Plant_Leaves_Palo"
    },
    {
      "x": 3,
      "y": 19,
      "z": 2,
      "name": "Wood_Palo_Branch_Long",
      "rotation": 5
    },
    {
      "x": 3,
      "y": 20,
      "z": 2,
      "name": "Plant_Leaves_Palo"
    },
    {
      "x": 3,
      "y": 17,
      "z": 3,
      "name": "Plant_Leaves_Palo"
    },
    {
      "x": 3,
      "y": 18,
      "z": 3,
      "name": "Plant_Leaves_Palo"
    },
    {
      "x": 3,
      "y": 19,
      "z": 3,
      "name": "Plant_Leaves_Palo"
    },
    {
      "x": 3,
      "y": 20,
      "z": 3,
      "name": "Plant_Leaves_Palo"
    },
    {
      "x": 3,
      "y": 17,
      "z": 4,
      "name": "Plant_Leaves_Palo"
    },
    {
      "x": 3,
      "y": 19,
      "z": 4,
      "name": "Plant_Leaves_Palo"
    },
    {
      "x": 3,
      "y": 20,
      "z": 4,
      "name": "Plant_Leaves_Palo"
    },
    {
      "x": 3,
      "y": 16,
      "z": 5,
      "name": "Plant_Leaves_Palo"
    },
    {
      "x": 3,
      "y": 17,
      "z": 5,
      "name": "Plant_Leaves_Palo"
    },
    {
      "x": 3,
      "y": 19,
      "z": 5,
      "name": "Plant_Leaves_Palo"
    },
    {
      "x": 3,
      "y": 16,
      "z": 6,
      "name": "Plant_Leaves_Palo"
    },
    {
      "x": 3,
      "y": 19,
      "z": 6,
      "name": "Plant_Leaves_Palo"
    },
    {
      "x": 4,
      "y": 22,
      "z": -2,
      "name": "Plant_Leaves_Palo"
    },
    {
      "x": 4,
      "y": 22,
      "z": -1,
      "name": "Plant_Leaves_Palo"
    },
    {
      "x": 4,
      "y": 16,
      "z": 0,
      "name": "Plant_Leaves_Palo"
    },
    {
      "x": 4,
      "y": 19,
      "z": 0,
      "name": "Plant_Leaves_Palo"
    },
    {
      "x": 4,
      "y": 22,
      "z": 0,
      "name": "Plant_Leaves_Palo"
    },
    {
      "x": 4,
      "y": 17,
      "z": 1,
      "name": "Plant_Leaves_Palo"
    },
    {
      "x": 4,
      "y": 19,
      "z": 1,
      "name": "Plant_Leaves_Palo"
    },
    {
      "x": 4,
      "y": 17,
      "z": 2,
      "name": "Wood_Palo_Branch_Long",
      "rotation": 5
    },
    {
      "x": 4,
      "y": 18,
      "z": 2,
      "name": "Plant_Leaves_Palo"
    },
    {
      "x": 4,
      "y": 19,
      "z": 2,
      "name": "Plant_Leaves_Palo"
    },
    {
      "x": 4,
      "y": 20,
      "z": 2,
      "name": "Plant_Leaves_Palo"
    },
    {
      "x": 4,
      "y": 17,
      "z": 3,
      "name": "Plant_Leaves_Palo"
    },
    {
      "x": 4,
      "y": 19,
      "z": 3,
      "name": "Plant_Leaves_Palo"
    },
    {
      "x": 4,
      "y": 16,
      "z": 4,
      "name": "Plant_Leaves_Palo"
    },
    {
      "x": 4,
      "y": 17,
      "z": 4,
      "name": "Plant_Leaves_Palo"
    },
    {
      "x": 4,
      "y": 19,
      "z": 4,
      "name": "Plant_Leaves_Palo"
    },
    {
      "x": 4,
      "y": 16,
      "z": 5,
      "name": "Plant_Leaves_Palo"
    },
    {
      "x": 4,
      "y": 19,
      "z": 5,
      "name": "Plant_Leaves_Palo"
    },
    {
      "x": 5,
      "y": 16,
      "z": 0,
      "name": "Plant_Leaves_Palo"
    },
    {
      "x": 5,
      "y": 16,
      "z": 1,
      "name": "Plant_Leaves_Palo"
    },
    {
      "x": 5,
      "y": 19,
      "z": 1,
      "name": "Plant_Leaves_Palo"
    },
    {
      "x": 5,
      "y": 16,
      "z": 2,
      "name": "Plant_Leaves_Palo"
    },
    {
      "x": 5,
      "y": 17,
      "z": 2,
      "name": "Plant_Leaves_Palo"
    },
    {
      "x": 5,
      "y": 19,
      "z": 2,
      "name": "Plant_Leaves_Palo"
    },
    {
      "x": 5,
      "y": 16,
      "z": 3,
      "name": "Plant_Leaves_Palo"
    },
    {
      "x": 5,
      "y": 19,
      "z": 3,
      "name": "Plant_Leaves_Palo"
    },
    {
      "x": 5,
      "y": 16,
      "z": 4,
      "name": "Plant_Leaves_Palo"
    },
    {
      "x": 5,
      "y": 16,
      "z": 5,
      "name": "Plant_Leaves_Palo"
    },
    {
      "x": 6,
      "y": 16,
      "z": 1,
      "name": "Plant_Leaves_Palo"
    },
    {
      "x": 6,
      "y": 16,
      "z": 2,
      "name": "Plant_Leaves_Palo"
    },
    {
      "x": 6,
      "y": 16,
      "z": 3,
      "name": "Plant_Leaves_Palo"
    }
  ]
}