{
  "version": 8,
  "blockIdVersion": 8,
  "anchorX": 0,
  "anchorY": 0,
  "anchorZ": 0,
  "blocks": [
    {
      "x": -20,
      "y": 3,
      "z": -12,
      "name": "Soil_Mud_Dry"
    },
    {
      "x": -20,
      "y": 4,
      "z": -12,
      "name": "Soil_Mud_Dry"
    },
    {
      "x": -20,
      "y": 10,
      "z": -12,
      "name": "Rock_Stone"
    },
    {
      "x": -20,
      "y": 11,
      "z": -12,
      "name": "Rock_Stone"
    },
    {
      "x": -20,
      "y": 3,
      "z": -11,
      "name": "Soil_Mud_Dry"
    },
    {
      "x": -20,
      "y": 4,
      "z": -11,
      "name": "Soil_Mud_Dry"
    },
    {
      "x": -20,
      "y": 5,
      "z": -11,
      "name": "Soil_Mud_Dry"
    },
    {
      "x": -20,
      "y": 8,
      "z": -11,
      "name": "Rock_Stone"
    },
    {
      "x": -20,
      "y": 9,
      "z": -11,
      "name": "Rock_Stone"
    },
    {
      "x": -20,
      "y": 10,
      "z": -11,
      "name": "Rock_Stone"
    },
    {
      "x": -20,
      "y": 11,
      "z": -11,
      "name": "Rock_Stone"
    },
    {
      "x": -20,
      "y": 3,
      "z": -10,
      "name": "Soil_Mud_Dry"
    },
    {
      "x": -20,
      "y": 4,
      "z": -10,
      "name": "Soil_Mud_Dry"
    },
    {
      "x": -20,
      "y": 5,
      "z": -10,
      "name": "Soil_Mud_Dry"
    },
    {
      "x": -20,
      "y": 6,
      "z": -10,
      "name": "Soil_Mud_Dry"
    },
    {
      "x": -20,
      "y": 7,
      "z": -10,
      "name": "Rock_Stone"
    },
    {
      "x": -20,
      "y": 8,
      "z": -10,
      "name": "Rock_Stone"
    },
    {
      "x": -20,
      "y": 9,
      "z": -10,
      "name": "Rock_Stone"
    },
    {
      "x": -20,
      "y": 10,
      "z": -10,
      "name": "Rock_Stone"
    },
    {
      "x": -20,
      "y": 11,
      "z": -10,
      "name": "Rock_Stone"
    },
    {
      "x": -20,
      "y": 5,
      "z": -9,
      "name": "Soil_Mud_Dry"
    },
    {
      "x": -20,
      "y": 6,
      "z": -9,
      "name": "Rock_Stone"
    },
    {
      "x": -20,
      "y": 7,
      "z": -9,
      "name": "Rock_Stone"
    },
    {
      "x": -20,
      "y": 8,
      "z": -9,
      "name": "Rock_Stone"
    },
    {
      "x": -20,
      "y": 9,
      "z": -9,
      "name": "Rock_Stone"
    },
    {
      "x": -20,
      "y": 10,
      "z": -9,
      "name": "Rock_Stone"
    },
    {
      "x": -20,
      "y": 11,
      "z": -9,
      "name": "Rock_Stone"
    },
    {
      "x": -20,
      "y": 6,
      "z": -8,
      "name": "Rock_Stone"
    },
    {
      "x": -20,
      "y": 7,
      "z": -8,
      "name": "Rock_Stone"
    },
    {
      "x": -20,
      "y": 8,
      "z": -8,
      "name": "Rock_Stone"
    },
    {
      "x": -20,
      "y": 9,
      "z": -8,
      "name": "Rock_Stone"
    },
    {
      "x": -20,
      "y": 10,
      "z": -8,
      "name": "Rock_Stone"
    },
    {
      "x": -20,
      "y": 8,
      "z": -7,
      "name": "Rock_Stone"
    },
    {
      "x": -20,
      "y": 9,
      "z": -7,
      "name": "Rock_Stone"
    },
    {
      "x": -20,
      "y": 10,
      "z": -7,
      "name": "Rock_Stone"
    },
    {
      "x": -20,
      "y": 6,
      "z": -1,
      "name": "Rock_Stone"
    },
    {
      "x": -20,
      "y": 7,
      "z": -1,
      "name": "Rock_Stone"
    },
    {
      "x": -20,
      "y": 5,
      "z": 0,
      "name": "Rock_Stone"
    },
    {
      "x": -20,
      "y": 6,
      "z": 0,
      "name": "Rock_Stone"
    },
    {
      "x": -20,
      "y": 7,
      "z": 0,
      "name": "Rock_Stone"
    },
    {
      "x": -20,
      "y": 8,
      "z": 0,
      "name": "Rock_Stone"
    },
    {
      "x": -20,
      "y": 4,
      "z": 1,
      "name": "Rock_Stone"
    },
    {
      "x": -20,
      "y": 5,
      "z": 1,
      "name": "Rock_Stone"
    },
    {
      "x": -20,
      "y": 6,
      "z": 1,
      "name": "Rock_Stone"
    },
    {
      "x": -20,
      "y": 7,
      "z": 1,
      "name": "Rock_Stone"
    },
    {
      "x": -20,
      "y": 8,
      "z": 1,
      "name": "Rock_Stone"
    },
    {
      "x": -20,
      "y": 4,
      "z": 2,
      "name": "Rock_Stone"
    },
    {
      "x": -20,
      "y": 5,
      "z": 2,
      "name": "Rock_Stone"
    },
    {
      "x": -20,
      "y": 6,
      "z": 2,
      "name": "Rock_Stone"
    },
    {
      "x": -20,
      "y": 7,
      "z": 2,
      "name": "Rock_Stone"
    },
    {
      "x": -19,
      "y": 0,
      "z": -14,
      "name": "Soil_Mud_Dry"
    },
    {
      "x": -19,
      "y": 1,
      "z": -14,
      "name": "Soil_Mud_Dry"
    },
    {
      "x": -19,
      "y": 0,
      "z": -13,
      "name": "Soil_Mud_Dry"
    },
    {
      "x": -19,
      "y": 1,
      "z": -13,
      "name": "Soil_Mud_Dry"
    },
    {
      "x": -19,
      "y": 2,
      "z": -13,
      "name": "Soil_Mud_Dry"
    },
    {
      "x": -19,
      "y": 3,
      "z": -13,
      "name": "Soil_Mud_Dry"
    },
    {
      "x": -19,
      "y": 4,
      "z": -13,
      "name": "Soil_Mud_Dry"
    },
    {
      "x": -19,
      "y": 9,
      "z": -13,
      "name": "Rock_Stone"
    },
    {
      "x": -19,
      "y": 10,
      "z": -13,
      "name": "Rock_Stone"
    },
    {
      "x": -19,
      "y": 11,
      "z": -13,
      "name": "Rock_Stone"
    },
    {
      "x": -19,
      "y": 12,
      "z": -13,
      "name": "Rock_Stone"
    },
    {
      "x": -19,
      "y": 0,
      "z": -12,
      "name": "Soil_Mud_Dry"
    },
    {
      "x": -19,
      "y": 1,
      "z": -12,
      "name": "Soil_Mud_Dry"
    },
    {
      "x": -19,
      "y": 2,
      "z": -12,
      "name": "Soil_Mud_Dry"
    },
    {
      "x": -19,
      "y": 3,
      "z": -12,
      "name": "Soil_Mud_Dry"
    },
    {
      "x": -19,
      "y": 4,
      "z": -12,
      "name": "Soil_Mud_Dry"
    },
    {
      "x": -19,
      "y": 5,
      "z": -12,
      "name": "Empty"
    },
    {
      "x": -19,
      "y": 6,
      "z": -12,
      "name": "Empty"
    },
    {
      "x": -19,
      "y": 7,
      "z": -12,
      "name": "Empty"
    },
    {
      "x": -19,
      "y": 8,
      "z": -12,
      "name": "Rock_Stone"
    },
    {
      "x": -19,
      "y": 9,
      "z": -12,
      "name": "Rock_Stone"
    },
    {
      "x": -19,
      "y": 10,
      "z": -12,
      "name": "Rock_Stone"
    },
    {
      "x": -19,
      "y": 11,
      "z": -12,
      "name": "Rock_Stone"
    },
    {
      "x": -19,
      "y": 12,
      "z": -12,
      "name": "Rock_Stone"
    },
    {
      "x": -19,
      "y": 0,
      "z": -11,
      "name": "Soil_Mud_Dry"
    },
    {
      "x": -19,
      "y": 1,
      "z": -11,
      "name": "Soil_Mud_Dry"
    },
    {
      "x": -19,
      "y": 2,
      "z": -11,
      "name": "Soil_Mud_Dry"
    },
    {
      "x": -19,
      "y": 3,
      "z": -11,
      "name": "Soil_Mud_Dry"
    },
    {
      "x": -19,
      "y": 4,
      "z": -11,
      "name": "Empty"
    },
    {
      "x": -19,
      "y": 5,
      "z": -11,
      "name": "Empty"
    },
    {
      "x": -19,
      "y": 6,
      "z": -11,
      "name": "Empty"
    },
    {
      "x": -19,
      "y": 7,
      "z": -11,
      "name": "Empty"
    },
    {
      "x": -19,
      "y": 8,
      "z": -11,
      "name": "Empty"
    },
    {
      "x": -19,
      "y": 9,
      "z": -11,
      "name": "Empty"
    },
    {
      "x": -19,
      "y": 10,
      "z": -11,
      "name": "Rock_Stone"
    },
    {
      "x": -19,
      "y": 11,
      "z": -11,
      "name": "Rock_Stone"
    },
    {
      "x": -19,
      "y": 1,
      "z": -10,
      "name": "Soil_Mud_Dry"
    },
    {
      "x": -19,
      "y": 2,
      "z": -10,
      "name": "Soil_Mud_Dry"
    },
    {
      "x": -19,
      "y": 3,
      "z": -10,
      "name": "Soil_Mud_Dry"
    },
    {
      "x": -19,
      "y": 4,
      "z": -10,
      "name": "Soil_Mud_Dry"
    },
    {
      "x": -19,
      "y": 5,
      "z": -10,
      "name": "Soil_Mud_Dry"
    },
    {
      "x": -19,
      "y": 6,
      "z": -10,
      "name": "Empty"
    },
    {
      "x": -19,
      "y": 7,
      "z": -10,
      "name": "Empty"
    },
    {
      "x": -19,
      "y": 8,
      "z": -10,
      "name": "Rock_Stone"
    },
    {
      "x": -19,
      "y": 9,
      "z": -10,
      "name": "Rock_Stone"
    },
    {
      "x": -19,
      "y": 10,
      "z": -10,
      "name": "Rock_Stone"
    },
    {
      "x": -19,
      "y": 11,
      "z": -10,
      "name": "Rock_Stone"
    },
    {
      "x": -19,
      "y": 2,
      "z": -9,
      "name": "Soil_Mud_Dry"
    },
    {
      "x": -19,
      "y": 3,
      "z": -9,
      "name": "Soil_Mud_Dry"
    },
    {
      "x": -19,
      "y": 4,
      "z": -9,
      "name": "Soil_Mud_Dry"
    },
    {
      "x": -19,
      "y": 5,
      "z": -9,
      "name": "Soil_Mud_Dry"
    },
    {
      "x": -19,
      "y": 6,
      "z": -9,
      "name": "Soil_Mud_Dry"
    },
    {
      "x": -19,
      "y": 7,
      "z": -9,
      "name": "Rock_Stone"
    },
    {
      "x": -19,
      "y": 8,
      "z": -9,
      "name": "Rock_Stone"
    },
    {
      "x": -19,
      "y": 9,
      "z": -9,
      "name": "Rock_Stone"
    },
    {
      "x": -19,
      "y": 10,
      "z": -9,
      "name": "Rock_Stone"
    },
    {
      "x": -19,
      "y": 11,
      "z": -9,
      "name": "Rock_Stone"
    },
    {
      "x": -19,
      "y": 3,
      "z": -8,
      "name": "Soil_Mud_Dry"
    },
    {
      "x": -19,
      "y": 4,
      "z": -8,
      "name": "Soil_Mud_Dry"
    },
    {
      "x": -19,
      "y": 5,
      "z": -8,
      "name": "Soil_Mud_Dry"
    },
    {
      "x": -19,
      "y": 6,
      "z": -8,
      "name": "Rock_Stone"
    },
    {
      "x": -19,
      "y": 7,
      "z": -8,
      "name": "Rock_Stone"
    },
    {
      "x": -19,
      "y": 8,
      "z": -8,
      "name": "Rock_Stone"
    },
    {
      "x": -19,
      "y": 9,
      "z": -8,
      "name": "Rock_Stone"
    },
    {
      "x": -19,
      "y": 10,
      "z": -8,
      "name": "Rock_Stone"
    },
    {
      "x": -19,
      "y": 11,
      "z": -8,
      "name": "Rock_Stone"
    },
    {
      "x": -19,
      "y": 4,
      "z": -7,
      "name": "Rock_Stone"
    },
    {
      "x": -19,
      "y": 5,
      "z": -7,
      "name": "Rock_Stone"
    },
    {
      "x": -19,
      "y": 6,
      "z": -7,
      "name": "Rock_Stone"
    },
    {
      "x": -19,
      "y": 7,
      "z": -7,
      "name": "Rock_Stone"
    },
    {
      "x": -19,
      "y": 8,
      "z": -7,
      "name": "Rock_Stone"
    },
    {
      "x": -19,
      "y": 9,
      "z": -7,
      "name": "Rock_Stone"
    },
    {
      "x": -19,
      "y": 10,
      "z": -7,
      "name": "Rock_Stone"
    },
    {
      "x": -19,
      "y": 5,
      "z": -6,
      "name": "Rock_Stone"
    },
    {
      "x": -19,
      "y": 6,
      "z": -6,
      "name": "Rock_Stone"
    },
    {
      "x": -19,
      "y": 7,
      "z": -6,
      "name": "Rock_Stone"
    },
    {
      "x": -19,
      "y": 8,
      "z": -6,
      "name": "Rock_Stone"
    },
    {
      "x": -19,
      "y": 9,
      "z": -6,
      "name": "Rock_Stone"
    },
    {
      "x": -19,
      "y": 6,
      "z": -5,
      "name": "Rock_Stone"
    },
    {
      "x": -19,
      "y": 6,
      "z": -2,
      "name": "Rock_Stone"
    },
    {
      "x": -19,
      "y": 7,
      "z": -2,
      "name": "Rock_Stone"
    },
    {
      "x": -19,
      "y": 8,
      "z": -2,
      "name": "Rock_Stone"
    },
    {
      "x": -19,
      "y": 4,
      "z": -1,
      "name": "Rock_Stone"
    },
    {
      "x": -19,
      "y": 5,
      "z": -1,
      "name": "Rock_Stone"
    },
    {
      "x": -19,
      "y": 6,
      "z": -1,
      "name": "Rock_Stone"
    },
    {
      "x": -19,
      "y": 7,
      "z": -1,
      "name": "Rock_Stone"
    },
    {
      "x": -19,
      "y": 8,
      "z": -1,
      "name": "Rock_Stone"
    },
    {
      "x": -19,
      "y": 9,
      "z": -1,
      "name": "Rock_Stone"
    },
    {
      "x": -19,
      "y": 10,
      "z": -1,
      "name": "Rock_Stone"
    },
    {
      "x": -19,
      "y": 3,
      "z": 0,
      "name": "Rock_Stone"
    },
    {
      "x": -19,
      "y": 4,
      "z": 0,
      "name": "Rock_Stone"
    },
    {
      "x": -19,
      "y": 5,
      "z": 0,
      "name": "Rock_Stone"
    },
    {
      "x": -19,
      "y": 6,
      "z": 0,
      "name": "Rock_Stone"
    },
    {
      "x": -19,
      "y": 7,
      "z": 0,
      "name": "Rock_Stone"
    },
    {
      "x": -19,
      "y": 8,
      "z": 0,
      "name": "Rock_Stone"
    },
    {
      "x": -19,
      "y": 9,
      "z": 0,
      "name": "Rock_Stone"
    },
    {
      "x": -19,
      "y": 10,
      "z": 0,
      "name": "Rock_Stone"
    },
    {
      "x": -19,
      "y": 11,
      "z": 0,
      "name": "Rock_Stone"
    },
    {
      "x": -19,
      "y": 12,
      "z": 0,
      "name": "Rock_Stone"
    },
    {
      "x": -19,
      "y": 3,
      "z": 1,
      "name": "Rock_Stone"
    },
    {
      "x": -19,
      "y": 4,
      "z": 1,
      "name": "Rock_Stone"
    },
    {
      "x": -19,
      "y": 5,
      "z": 1,
      "name": "Rock_Stone"
    },
    {
      "x": -19,
      "y": 6,
      "z": 1,
      "name": "Rock_Stone"
    },
    {
      "x": -19,
      "y": 7,
      "z": 1,
      "name": "Rock_Stone"
    },
    {
      "x": -19,
      "y": 8,
      "z": 1,
      "name": "Rock_Stone"
    },
    {
      "x": -19,
      "y": 9,
      "z": 1,
      "name": "Rock_Stone"
    },
    {
      "x": -19,
      "y": 10,
      "z": 1,
      "name": "Rock_Stone"
    },
    {
      "x": -19,
      "y": 11,
      "z": 1,
      "name": "Rock_Stone"
    },
    {
      "x": -19,
      "y": 12,
      "z": 1,
      "name": "Rock_Stone"
    },
    {
      "x": -19,
      "y": 3,
      "z": 2,
      "name": "Rock_Stone"
    },
    {
      "x": -19,
      "y": 4,
      "z": 2,
      "name": "Rock_Stone"
    },
    {
      "x": -19,
      "y": 5,
      "z": 2,
      "name": "Rock_Stone"
    },
    {
      "x": -19,
      "y": 6,
      "z": 2,
      "name": "Rock_Stone"
    },
    {
      "x": -19,
      "y": 7,
      "z": 2,
      "name": "Rock_Stone"
    },
    {
      "x": -19,
      "y": 8,
      "z": 2,
      "name": "Rock_Stone"
    },
    {
      "x": -19,
      "y": 9,
      "z": 2,
      "name": "Rock_Stone"
    },
    {
      "x": -19,
      "y": 10,
      "z": 2,
      "name": "Rock_Stone"
    },
    {
      "x": -19,
      "y": 11,
      "z": 2,
      "name": "Rock_Stone"
    },
    {
      "x": -19,
      "y": 5,
      "z": 3,
      "name": "Rock_Stone"
    },
    {
      "x": -19,
      "y": 6,
      "z": 3,
      "name": "Rock_Stone"
    },
    {
      "x": -19,
      "y": 7,
      "z": 3,
      "name": "Rock_Stone"
    },
    {
      "x": -19,
      "y": 8,
      "z": 3,
      "name": "Rock_Stone"
    },
    {
      "x": -19,
      "y": 6,
      "z": 5,
      "name": "Empty"
    },
    {
      "x": -19,
      "y": 7,
      "z": 5,
      "name": "Empty"
    },
    {
      "x": -19,
      "y": -1,
      "z": 6,
      "name": "Rock_Stone"
    },
    {
      "x": -19,
      "y": 0,
      "z": 6,
      "name": "Rock_Stone"
    },
    {
      "x": -19,
      "y": 1,
      "z": 6,
      "name": "Rock_Stone"
    },
    {
      "x": -19,
      "y": 2,
      "z": 6,
      "name": "Soil_Mud_Dry"
    },
    {
      "x": -19,
      "y": 4,
      "z": 6,
      "name": "Empty"
    },
    {
      "x": -19,
      "y": 5,
      "z": 6,
      "name": "Empty"
    },
    {
      "x": -19,
      "y": 6,
      "z": 6,
      "name": "Empty"
    },
    {
      "x": -19,
      "y": 7,
      "z": 6,
      "name": "Empty"
    },
    {
      "x": -19,
      "y": -1,
      "z": 7,
      "name": "Rock_Stone"
    },
    {
      "x": -19,
      "y": 0,
      "z": 7,
      "name": "Rock_Stone"
    },
    {
      "x": -19,
      "y": 1,
      "z": 7,
      "name": "Rock_Stone"
    },
    {
      "x": -19,
      "y": 2,
      "z": 7,
      "name": "Soil_Mud_Dry"
    },
    {
      "x": -19,
      "y": 3,
      "z": 7,
      "name": "Empty"
    },
    {
      "x": -19,
      "y": 4,
      "z": 7,
      "name": "Empty"
    },
    {
      "x": -19,
      "y": 5,
      "z": 7,
      "name": "Empty"
    },
    {
      "x": -19,
      "y": 6,
      "z": 7,
      "name": "Empty"
    },
    {
      "x": -19,
      "y": 7,
      "z": 7,
      "name": "Empty"
    },
    {
      "x": -19,
      "y": -1,
      "z": 8,
      "name": "Rock_Stone"
    },
    {
      "x": -19,
      "y": 0,
      "z": 8,
      "name": "Rock_Stone"
    },
    {
      "x": -19,
      "y": 1,
      "z": 8,
      "name": "Soil_Mud_Dry"
    },
    {
      "x": -19,
      "y": 2,
      "z": 8,
      "name": "Soil_Mud_Dry"
    },
    {
      "x": -19,
      "y": 3,
      "z": 8,
      "name": "Plant_Moss_Rug_Green"
    },
    {
      "x": -19,
      "y": 4,
      "z": 8,
      "name": "Empty"
    },
    {
      "x": -19,
      "y": 5,
      "z": 8,
      "name": "Empty"
    },
    {
      "x": -19,
      "y": 6,
      "z": 8,
      "name": "Empty"
    },
    {
      "x": -19,
      "y": -2,
      "z": 9,
      "name": "Rock_Stone"
    },
    {
      "x": -19,
      "y": -1,
      "z": 9,
      "name": "Rock_Stone"
    },
    {
      "x": -19,
      "y": 0,
      "z": 9,
      "name": "Rock_Stone"
    },
    {
      "x": -19,
      "y": 1,
      "z": 9,
      "name": "Soil_Mud_Dry"
    },
    {
      "x": -19,
      "y": 2,
      "z": 9,
      "name": "Soil_Mud_Dry"
    },
    {
      "x": -19,
      "y": 3,
      "z": 9,
      "name": "Plant_Moss_Rug_Green"
    },
    {
      "x": -19,
      "y": 4,
      "z": 9,
      "name": "Empty"
    },
    {
      "x": -19,
      "y": 5,
      "z": 9,
      "name": "Empty"
    },
    {
      "x": -19,
      "y": 6,
      "z": 9,
      "name": "Empty"
    },
    {
      "x": -19,
      "y": -2,
      "z": 10,
      "name": "Rock_Stone"
    },
    {
      "x": -19,
      "y": -1,
      "z": 10,
      "name": "Rock_Stone"
    },
    {
      "x": -19,
      "y": 0,
      "z": 10,
      "name": "Rock_Stone"
    },
    {
      "x": -19,
      "y": 1,
      "z": 10,
      "name": "Soil_Mud_Dry"
    },
    {
      "x": -19,
      "y": 2,
      "z": 10,
      "name": "Soil_Mud_Dry"
    },
    {
      "x": -19,
      "y": 3,
      "z": 10,
      "name": "Empty"
    },
    {
      "x": -19,
      "y": 4,
      "z": 10,
      "name": "Empty"
    },
    {
      "x": -19,
      "y": 5,
      "z": 10,
      "name": "Empty"
    },
    {
      "x": -19,
      "y": -2,
      "z": 11,
      "name": "Rock_Stone"
    },
    {
      "x": -19,
      "y": -1,
      "z": 11,
      "name": "Rock_Stone"
    },
    {
      "x": -19,
      "y": 0,
      "z": 11,
      "name": "Rock_Stone"
    },
    {
      "x": -19,
      "y": 1,
      "z": 11,
      "name": "Soil_Mud_Dry"
    },
    {
      "x": -19,
      "y": 2,
      "z": 11,
      "name": "Empty"
    },
    {
      "x": -19,
      "y": 3,
      "z": 11,
      "name": "Empty"
    },
    {
      "x": -19,
      "y": 4,
      "z": 11,
      "name": "Empty"
    },
    {
      "x": -19,
      "y": -2,
      "z": 12,
      "name": "Rock_Stone"
    },
    {
      "x": -19,
      "y": -1,
      "z": 12,
      "name": "Rock_Stone"
    },
    {
      "x": -19,
      "y": 0,
      "z": 12,
      "name": "Rock_Stone"
    },
    {
      "x": -19,
      "y": 1,
      "z": 12,
      "name": "Soil_Mud_Dry"
    },
    {
      "x": -19,
      "y": 2,
      "z": 12,
      "name": "Empty"
    },
    {
      "x": -19,
      "y": 3,
      "z": 12,
      "name": "Empty"
    },
    {
      "x": -19,
      "y": -1,
      "z": 13,
      "name": "Rock_Stone"
    },
    {
      "x": -19,
      "y": 0,
      "z": 13,
      "name": "Rock_Stone"
    },
    {
      "x": -19,
      "y": 1,
      "z": 13,
      "name": "Soil_Mud_Dry"
    },
    {
      "x": -19,
      "y": 2,
      "z": 13,
      "name": "Soil_Mud_Dry"
    },
    {
      "x": -18,
      "y": 0,
      "z": -14,
      "name": "Soil_Mud_Dry"
    },
    {
      "x": -18,
      "y": 1,
      "z": -14,
      "name": "Soil_Mud_Dry"
    },
    {
      "x": -18,
      "y": 2,
      "z": -14,
      "name": "Soil_Mud_Dry"
    },
    {
      "x": -18,
      "y": 3,
      "z": -14,
      "name": "Soil_Mud_Dry"
    },
    {
      "x": -18,
      "y": 0,
      "z": -13,
      "name": "Soil_Mud_Dry"
    },
    {
      "x": -18,
      "y": 1,
      "z": -13,
      "name": "Soil_Mud_Dry"
    },
    {
      "x": -18,
      "y": 2,
      "z": -13,
      "name": "Soil_Mud_Dry"
    },
    {
      "x": -18,
      "y": 3,
      "z": -13,
      "name": "Empty"
    },
    {
      "x": -18,
      "y": 4,
      "z": -13,
      "name": "Empty"
    },
    {
      "x": -18,
      "y": 5,
      "z": -13,
      "name": "Empty"
    },
    {
      "x": -18,
      "y": 6,
      "z": -13,
      "name": "Rock_Stone_Stalactite_Large",
      "filler": 31744,
      "rotation": 8
    },
    {
      "x": -18,
      "y": 7,
      "z": -13,
      "name": "Rock_Stone_Stalactite_Large",
      "rotation": 8
    },
    {
      "x": -18,
      "y": 8,
      "z": -13,
      "name": "Rock_Stone"
    },
    {
      "x": -18,
      "y": 9,
      "z": -13,
      "name": "Rock_Stone"
    },
    {
      "x": -18,
      "y": 10,
      "z": -13,
      "name": "Rock_Stone"
    },
    {
      "x": -18,
      "y": 11,
      "z": -13,
      "name": "Rock_Stone"
    },
    {
      "x": -18,
      "y": 12,
      "z": -13,
      "name": "Rock_Stone"
    },
    {
      "x": -18,
      "y": 0,
      "z": -12,
      "name": "Soil_Mud_Dry"
    },
    {
      "x": -18,
      "y": 1,
      "z": -12,
      "name": "Plant_Crop_Mushroom_Cap_Brown",
      "components": {
        "Components": {
          "FarmingBlock": {}
        }
      }
    },
    {
      "x": -18,
      "y": 2,
      "z": -12,
      "name": "Empty"
    },
    {
      "x": -18,
      "y": 3,
      "z": -12,
      "name": "Empty"
    },
    {
      "x": -18,
      "y": 4,
      "z": -12,
      "name": "Empty"
    },
    {
      "x": -18,
      "y": 5,
      "z": -12,
      "name": "Empty"
    },
    {
      "x": -18,
      "y": 6,
      "z": -12,
      "name": "Empty"
    },
    {
      "x": -18,
      "y": 7,
      "z": -12,
      "name": "Empty"
    },
    {
      "x": -18,
      "y": 8,
      "z": -12,
      "name": "Empty"
    },
    {
      "x": -18,
      "y": 9,
      "z": -12,
      "name": "Empty"
    },
    {
      "x": -18,
      "y": 10,
      "z": -12,
      "name": "Empty"
    },
    {
      "x": -18,
      "y": 11,
      "z": -12,
      "name": "Rock_Stone"
    },
    {
      "x": -18,
      "y": 12,
      "z": -12,
      "name": "Rock_Stone"
    },
    {
      "x": -18,
      "y": 0,
      "z": -11,
      "name": "Soil_Mud_Dry"
    },
    {
      "x": -18,
      "y": 1,
      "z": -11,
      "name": "Soil_Mud_Dry"
    },
    {
      "x": -18,
      "y": 2,
      "z": -11,
      "name": "Empty"
    },
    {
      "x": -18,
      "y": 3,
      "z": -11,
      "name": "Empty"
    },
    {
      "x": -18,
      "y": 4,
      "z": -11,
      "name": "Empty"
    },
    {
      "x": -18,
      "y": 5,
      "z": -11,
      "name": "Empty"
    },
    {
      "x": -18,
      "y": 6,
      "z": -11,
      "name": "Empty"
    },
    {
      "x": -18,
      "y": 7,
      "z": -11,
      "name": "Empty"
    },
    {
      "x": -18,
      "y": 8,
      "z": -11,
      "name": "Empty"
    },
    {
      "x": -18,
      "y": 9,
      "z": -11,
      "name": "Empty"
    },
    {
      "x": -18,
      "y": 10,
      "z": -11,
      "name": "Empty"
    },
    {
      "x": -18,
      "y": 11,
      "z": -11,
      "name": "Rock_Stone"
    },
    {
      "x": -18,
      "y": 0,
      "z": -10,
      "name": "Soil_Mud_Dry"
    },
    {
      "x": -18,
      "y": 1,
      "z": -10,
      "name": "Soil_Mud_Dry"
    },
    {
      "x": -18,
      "y": 2,
      "z": -10,
      "name": "Soil_Mud_Dry"
    },
    {
      "x": -18,
      "y": 3,
      "z": -10,
      "name": "Plant_Moss_Rug_Green"
    },
    {
      "x": -18,
      "y": 4,
      "z": -10,
      "name": "Empty"
    },
    {
      "x": -18,
      "y": 5,
      "z": -10,
      "name": "Empty"
    },
    {
      "x": -18,
      "y": 6,
      "z": -10,
      "name": "Empty"
    },
    {
      "x": -18,
      "y": 7,
      "z": -10,
      "name": "Empty"
    },
    {
      "x": -18,
      "y": 8,
      "z": -10,
      "name": "Empty"
    },
    {
      "x": -18,
      "y": 9,
      "z": -10,
      "name": "Empty"
    },
    {
      "x": -18,
      "y": 10,
      "z": -10,
      "name": "Empty"
    },
    {
      "x": -18,
      "y": 11,
      "z": -10,
      "name": "Rock_Stone"
    },
    {
      "x": -18,
      "y": 1,
      "z": -9,
      "name": "Soil_Mud_Dry"
    },
    {
      "x": -18,
      "y": 2,
      "z": -9,
      "name": "Soil_Mud_Dry"
    },
    {
      "x": -18,
      "y": 3,
      "z": -9,
      "name": "Soil_Mud_Dry"
    },
    {
      "x": -18,
      "y": 4,
      "z": -9,
      "name": "Empty"
    },
    {
      "x": -18,
      "y": 5,
      "z": -9,
      "name": "Empty"
    },
    {
      "x": -18,
      "y": 6,
      "z": -9,
      "name": "Empty"
    },
    {
      "x": -18,
      "y": 7,
      "z": -9,
      "name": "Empty"
    },
    {
      "x": -18,
      "y": 8,
      "z": -9,
      "name": "Rock_Stone_Stalactite_Large",
      "filler": 31744,
      "rotation": 8
    },
    {
      "x": -18,
      "y": 9,
      "z": -9,
      "name": "Rock_Stone_Stalactite_Large",
      "rotation": 8
    },
    {
      "x": -18,
      "y": 10,
      "z": -9,
      "name": "Rock_Stone"
    },
    {
      "x": -18,
      "y": 11,
      "z": -9,
      "name": "Rock_Stone"
    },
    {
      "x": -18,
      "y": 2,
      "z": -8,
      "name": "Soil_Mud_Dry"
    },
    {
      "x": -18,
      "y": 3,
      "z": -8,
      "name": "Soil_Mud_Dry"
    },
    {
      "x": -18,
      "y": 4,
      "z": -8,
      "name": "Soil_Mud_Dry"
    },
    {
      "x": -18,
      "y": 5,
      "z": -8,
      "name": "Soil_Mud_Dry"
    },
    {
      "x": -18,
      "y": 6,
      "z": -8,
      "name": "Empty"
    },
    {
      "x": -18,
      "y": 7,
      "z": -8,
      "name": "Empty"
    },
    {
      "x": -18,
      "y": 8,
      "z": -8,
      "name": "Empty"
    },
    {
      "x": -18,
      "y": 9,
      "z": -8,
      "name": "Empty"
    },
    {
      "x": -18,
      "y": 10,
      "z": -8,
      "name": "Rock_Stone"
    },
    {
      "x": -18,
      "y": 11,
      "z": -8,
      "name": "Rock_Stone"
    },
    {
      "x": -18,
      "y": 3,
      "z": -7,
      "name": "Soil_Mud_Dry"
    },
    {
      "x": -18,
      "y": 4,
      "z": -7,
      "name": "Soil_Mud_Dry"
    },
    {
      "x": -18,
      "y": 5,
      "z": -7,
      "name": "Rock_Stone"
    },
    {
      "x": -18,
      "y": 6,
      "z": -7,
      "name": "Rock_Stone"
    },
    {
      "x": -18,
      "y": 7,
      "z": -7,
      "name": "Empty"
    },
    {
      "x": -18,
      "y": 8,
      "z": -7,
      "name": "Empty"
    },
    {
      "x": -18,
      "y": 9,
      "z": -7,
      "name": "Rock_Stone"
    },
    {
      "x": -18,
      "y": 10,
      "z": -7,
      "name": "Rock_Stone"
    },
    {
      "x": -18,
      "y": 11,
      "z": -7,
      "name": "Rock_Stone"
    },
    {
      "x": -18,
      "y": 3,
      "z": -6,
      "name": "Soil_Mud_Dry"
    },
    {
      "x": -18,
      "y": 5,
      "z": -6,
      "name": "Rock_Stone"
    },
    {
      "x": -18,
      "y": 6,
      "z": -6,
      "name": "Rock_Stone"
    },
    {
      "x": -18,
      "y": 7,
      "z": -6,
      "name": "Rock_Stone"
    },
    {
      "x": -18,
      "y": 8,
      "z": -6,
      "name": "Rock_Stone"
    },
    {
      "x": -18,
      "y": 9,
      "z": -6,
      "name": "Rock_Stone"
    },
    {
      "x": -18,
      "y": 10,
      "z": -6,
      "name": "Rock_Stone"
    },
    {
      "x": -18,
      "y": 4,
      "z": -5,
      "name": "Soil_Mud_Dry"
    },
    {
      "x": -18,
      "y": 5,
      "z": -5,
      "name": "Rock_Stone"
    },
    {
      "x": -18,
      "y": 6,
      "z": -5,
      "name": "Rock_Stone"
    },
    {
      "x": -18,
      "y": 7,
      "z": -5,
      "name": "Rock_Stone"
    },
    {
      "x": -18,
      "y": 4,
      "z": -2,
      "name": "Rock_Stone"
    },
    {
      "x": -18,
      "y": 5,
      "z": -2,
      "name": "Rock_Stone"
    },
    {
      "x": -18,
      "y": 6,
      "z": -2,
      "name": "Rock_Stone"
    },
    {
      "x": -18,
      "y": 7,
      "z": -2,
      "name": "Rock_Stone"
    },
    {
      "x": -18,
      "y": 8,
      "z": -2,
      "name": "Rock_Stone"
    },
    {
      "x": -18,
      "y": 9,
      "z": -2,
      "name": "Rock_Stone"
    },
    {
      "x": -18,
      "y": 10,
      "z": -2,
      "name": "Rock_Stone"
    },
    {
      "x": -18,
      "y": 11,
      "z": -2,
      "name": "Rock_Stone"
    },
    {
      "x": -18,
      "y": 12,
      "z": -2,
      "name": "Rock_Stone"
    },
    {
      "x": -18,
      "y": 2,
      "z": -1,
      "name": "Rock_Stone"
    },
    {
      "x": -18,
      "y": 3,
      "z": -1,
      "name": "Rock_Stone"
    },
    {
      "x": -18,
      "y": 4,
      "z": -1,
      "name": "Rock_Stone"
    },
    {
      "x": -18,
      "y": 5,
      "z": -1,
      "name": "Rock_Stone"
    },
    {
      "x": -18,
      "y": 6,
      "z": -1,
      "name": "Rock_Stone"
    },
    {
      "x": -18,
      "y": 7,
      "z": -1,
      "name": "Rock_Stone"
    },
    {
      "x": -18,
      "y": 8,
      "z": -1,
      "name": "Rock_Stone"
    },
    {
      "x": -18,
      "y": 9,
      "z": -1,
      "name": "Rock_Stone"
    },
    {
      "x": -18,
      "y": 10,
      "z": -1,
      "name": "Rock_Stone"
    },
    {
      "x": -18,
      "y": 11,
      "z": -1,
      "name": "Rock_Stone"
    },
    {
      "x": -18,
      "y": 12,
      "z": -1,
      "name": "Rock_Stone"
    },
    {
      "x": -18,
      "y": 13,
      "z": -1,
      "name": "Rock_Stone"
    },
    {
      "x": -18,
      "y": 2,
      "z": 0,
      "name": "Rock_Stone"
    },
    {
      "x": -18,
      "y": 3,
      "z": 0,
      "name": "Rock_Stone"
    },
    {
      "x": -18,
      "y": 4,
      "z": 0,
      "name": "Soil_Mud_Dry"
    },
    {
      "x": -18,
      "y": 5,
      "z": 0,
      "name": "Rock_Stone"
    },
    {
      "x": -18,
      "y": 6,
      "z": 0,
      "name": "Rock_Stone"
    },
    {
      "x": -18,
      "y": 7,
      "z": 0,
      "name": "Rock_Stone"
    },
    {
      "x": -18,
      "y": 8,
      "z": 0,
      "name": "Rock_Stone"
    },
    {
      "x": -18,
      "y": 9,
      "z": 0,
      "name": "Rock_Stone"
    },
    {
      "x": -18,
      "y": 10,
      "z": 0,
      "name": "Rock_Stone"
    },
    {
      "x": -18,
      "y": 11,
      "z": 0,
      "name": "Rock_Stone"
    },
    {
      "x": -18,
      "y": 12,
      "z": 0,
      "name": "Rock_Stone"
    },
    {
      "x": -18,
      "y": 13,
      "z": 0,
      "name": "Rock_Stone"
    },
    {
      "x": -18,
      "y": 2,
      "z": 1,
      "name": "Rock_Stone"
    },
    {
      "x": -18,
      "y": 3,
      "z": 1,
      "name": "Rock_Stone"
    },
    {
      "x": -18,
      "y": 4,
      "z": 1,
      "name": "Rock_Stone"
    },
    {
      "x": -18,
      "y": 5,
      "z": 1,
      "name": "Rock_Stone"
    },
    {
      "x": -18,
      "y": 6,
      "z": 1,
      "name": "Rock_Stone"
    },
    {
      "x": -18,
      "y": 7,
      "z": 1,
      "name": "Rock_Stone"
    },
    {
      "x": -18,
      "y": 8,
      "z": 1,
      "name": "Rock_Stone"
    },
    {
      "x": -18,
      "y": 9,
      "z": 1,
      "name": "Rock_Stone"
    },
    {
      "x": -18,
      "y": 10,
      "z": 1,
      "name": "Rock_Stone"
    },
    {
      "x": -18,
      "y": 11,
      "z": 1,
      "name": "Rock_Stone"
    },
    {
      "x": -18,
      "y": 12,
      "z": 1,
      "name": "Rock_Stone"
    },
    {
      "x": -18,
      "y": 13,
      "z": 1,
      "name": "Rock_Stone"
    },
    {
      "x": -18,
      "y": 2,
      "z": 2,
      "name": "Soil_Mud_Dry"
    },
    {
      "x": -18,
      "y": 3,
      "z": 2,
      "name": "Soil_Mud_Dry"
    },
    {
      "x": -18,
      "y": 4,
      "z": 2,
      "name": "Rock_Stone"
    },
    {
      "x": -18,
      "y": 5,
      "z": 2,
      "name": "Rock_Stone"
    },
    {
      "x": -18,
      "y": 6,
      "z": 2,
      "name": "Rock_Stone"
    },
    {
      "x": -18,
      "y": 7,
      "z": 2,
      "name": "Rock_Stone"
    },
    {
      "x": -18,
      "y": 8,
      "z": 2,
      "name": "Rock_Stone"
    },
    {
      "x": -18,
      "y": 9,
      "z": 2,
      "name": "Rock_Stone"
    },
    {
      "x": -18,
      "y": 10,
      "z": 2,
      "name": "Rock_Stone"
    },
    {
      "x": -18,
      "y": 11,
      "z": 2,
      "name": "Rock_Stone"
    },
    {
      "x": -18,
      "y": 12,
      "z": 2,
      "name": "Rock_Stone"
    },
    {
      "x": -18,
      "y": 13,
      "z": 2,
      "name": "Rock_Stone"
    },
    {
      "x": -18,
      "y": 1,
      "z": 3,
      "name": "Rock_Stone"
    },
    {
      "x": -18,
      "y": 2,
      "z": 3,
      "name": "Soil_Mud_Dry"
    },
    {
      "x": -18,
      "y": 3,
      "z": 3,
      "name": "Soil_Mud_Dry"
    },
    {
      "x": -18,
      "y": 4,
      "z": 3,
      "name": "Rock_Stone"
    },
    {
      "x": -18,
      "y": 5,
      "z": 3,
      "name": "Rock_Stone"
    },
    {
      "x": -18,
      "y": 6,
      "z": 3,
      "name": "Empty"
    },
    {
      "x": -18,
      "y": 7,
      "z": 3,
      "name": "Empty"
    },
    {
      "x": -18,
      "y": 8,
      "z": 3,
      "name": "Empty"
    },
    {
      "x": -18,
      "y": 9,
      "z": 3,
      "name": "Rock_Stone"
    },
    {
      "x": -18,
      "y": 10,
      "z": 3,
      "name": "Rock_Stone"
    },
    {
      "x": -18,
      "y": 11,
      "z": 3,
      "name": "Rock_Stone"
    },
    {
      "x": -18,
      "y": 12,
      "z": 3,
      "name": "Rock_Stone"
    },
    {
      "x": -18,
      "y": 0,
      "z": 4,
      "name": "Rock_Stone"
    },
    {
      "x": -18,
      "y": 1,
      "z": 4,
      "name": "Soil_Mud_Dry"
    },
    {
      "x": -18,
      "y": 2,
      "z": 4,
      "name": "Soil_Mud_Dry"
    },
    {
      "x": -18,
      "y": 3,
      "z": 4,
      "name": "Soil_Mud_Dry"
    },
    {
      "x": -18,
      "y": 4,
      "z": 4,
      "name": "Empty"
    },
    {
      "x": -18,
      "y": 5,
      "z": 4,
      "name": "Empty"
    },
    {
      "x": -18,
      "y": 6,
      "z": 4,
      "name": "Empty"
    },
    {
      "x": -18,
      "y": 7,
      "z": 4,
      "name": "Empty"
    },
    {
      "x": -18,
      "y": 8,
      "z": 4,
      "name": "Empty"
    },
    {
      "x": -18,
      "y": 9,
      "z": 4,
      "name": "Empty"
    },
    {
      "x": -18,
      "y": 0,
      "z": 5,
      "name": "Rock_Stone"
    },
    {
      "x": -18,
      "y": 1,
      "z": 5,
      "name": "Soil_Mud_Dry"
    },
    {
      "x": -18,
      "y": 2,
      "z": 5,
      "name": "Soil_Mud_Dry"
    },
    {
      "x": -18,
      "y": 3,
      "z": 5,
      "name": "Empty"
    },
    {
      "x": -18,
      "y": 4,
      "z": 5,
      "name": "Empty"
    },
    {
      "x": -18,
      "y": 5,
      "z": 5,
      "name": "Empty"
    },
    {
      "x": -18,
      "y": 6,
      "z": 5,
      "name": "Empty"
    },
    {
      "x": -18,
      "y": 7,
      "z": 5,
      "name": "Empty"
    },
    {
      "x": -18,
      "y": 8,
      "z": 5,
      "name": "Empty"
    },
    {
      "x": -18,
      "y": 9,
      "z": 5,
      "name": "Empty"
    },
    {
      "x": -18,
      "y": -1,
      "z": 6,
      "name": "Rock_Stone"
    },
    {
      "x": -18,
      "y": 0,
      "z": 6,
      "name": "Rock_Stone"
    },
    {
      "x": -18,
      "y": 1,
      "z": 6,
      "name": "Soil_Mud_Dry"
    },
    {
      "x": -18,
      "y": 2,
      "z": 6,
      "name": "Soil_Mud_Dry"
    },
    {
      "x": -18,
      "y": 3,
      "z": 6,
      "name": "Empty"
    },
    {
      "x": -18,
      "y": 4,
      "z": 6,
      "name": "Empty"
    },
    {
      "x": -18,
      "y": 5,
      "z": 6,
      "name": "Empty"
    },
    {
      "x": -18,
      "y": 6,
      "z": 6,
      "name": "Empty"
    },
    {
      "x": -18,
      "y": 7,
      "z": 6,
      "name": "Empty"
    },
    {
      "x": -18,
      "y": 8,
      "z": 6,
      "name": "Empty"
    },
    {
      "x": -18,
      "y": 9,
      "z": 6,
      "name": "Empty"
    },
    {
      "x": -18,
      "y": 10,
      "z": 6,
      "name": "Empty"
    },
    {
      "x": -18,
      "y": -2,
      "z": 7,
      "name": "Rock_Stone"
    },
    {
      "x": -18,
      "y": -1,
      "z": 7,
      "name": "Rock_Stone"
    },
    {
      "x": -18,
      "y": 0,
      "z": 7,
      "name": "Rock_Stone"
    },
    {
      "x": -18,
      "y": 1,
      "z": 7,
      "name": "Soil_Mud_Dry"
    },
    {
      "x": -18,
      "y": 2,
      "z": 7,
      "name": "Soil_Mud_Dry"
    },
    {
      "x": -18,
      "y": 3,
      "z": 7,
      "name": "Empty"
    },
    {
      "x": -18,
      "y": 4,
      "z": 7,
      "name": "Empty"
    },
    {
      "x": -18,
      "y": 5,
      "z": 7,
      "name": "Empty"
    },
    {
      "x": -18,
      "y": 6,
      "z": 7,
      "name": "Empty"
    },
    {
      "x": -18,
      "y": 7,
      "z": 7,
      "name": "Empty"
    },
    {
      "x": -18,
      "y": 8,
      "z": 7,
      "name": "Empty"
    },
    {
      "x": -18,
      "y": 9,
      "z": 7,
      "name": "Empty"
    },
    {
      "x": -18,
      "y": -2,
      "z": 8,
      "name": "Rock_Stone"
    },
    {
      "x": -18,
      "y": -1,
      "z": 8,
      "name": "Rock_Stone"
    },
    {
      "x": -18,
      "y": 0,
      "z": 8,
      "name": "Rock_Stone"
    },
    {
      "x": -18,
      "y": 1,
      "z": 8,
      "name": "Soil_Mud_Dry"
    },
    {
      "x": -18,
      "y": 2,
      "z": 8,
      "name": "Soil_Mud_Dry"
    },
    {
      "x": -18,
      "y": 3,
      "z": 8,
      "name": "Plant_Moss_Rug_Green"
    },
    {
      "x": -18,
      "y": 4,
      "z": 8,
      "name": "Empty"
    },
    {
      "x": -18,
      "y": 5,
      "z": 8,
      "name": "Empty"
    },
    {
      "x": -18,
      "y": 6,
      "z": 8,
      "name": "Empty"
    },
    {
      "x": -18,
      "y": 7,
      "z": 8,
      "name": "Empty"
    },
    {
      "x": -18,
      "y": 8,
      "z": 8,
      "name": "Empty"
    },
    {
      "x": -18,
      "y": 9,
      "z": 8,
      "name": "Empty"
    },
    {
      "x": -18,
      "y": -2,
      "z": 9,
      "name": "Rock_Stone"
    },
    {
      "x": -18,
      "y": -1,
      "z": 9,
      "name": "Rock_Stone"
    },
    {
      "x": -18,
      "y": 0,
      "z": 9,
      "name": "Rock_Stone"
    },
    {
      "x": -18,
      "y": 1,
      "z": 9,
      "name": "Soil_Mud_Dry"
    },
    {
      "x": -18,
      "y": 2,
      "z": 9,
      "name": "Empty"
    },
    {
      "x": -18,
      "y": 3,
      "z": 9,
      "name": "Empty"
    },
    {
      "x": -18,
      "y": 4,
      "z": 9,
      "name": "Empty"
    },
    {
      "x": -18,
      "y": 5,
      "z": 9,
      "name": "Empty"
    },
    {
      "x": -18,
      "y": 6,
      "z": 9,
      "name": "Empty"
    },
    {
      "x": -18,
      "y": 7,
      "z": 9,
      "name": "Empty"
    },
    {
      "x": -18,
      "y": 8,
      "z": 9,
      "name": "Empty"
    },
    {
      "x": -18,
      "y": 9,
      "z": 9,
      "name": "Empty"
    },
    {
      "x": -18,
      "y": -3,
      "z": 10,
      "name": "Rock_Stone"
    },
    {
      "x": -18,
      "y": -2,
      "z": 10,
      "name": "Rock_Stone"
    },
    {
      "x": -18,
      "y": -1,
      "z": 10,
      "name": "Rock_Stone"
    },
    {
      "x": -18,
      "y": 0,
      "z": 10,
      "name": "Rock_Stone"
    },
    {
      "x": -18,
      "y": 1,
      "z": 10,
      "name": "Soil_Mud_Dry"
    },
    {
      "x": -18,
      "y": 2,
      "z": 10,
      "name": "Plant_Crop_Mushroom_Cap_Brown",
      "components": {
        "Components": {
          "FarmingBlock": {}
        }
      }
    },
    {
      "x": -18,
      "y": 3,
      "z": 10,
      "name": "Empty"
    },
    {
      "x": -18,
      "y": 4,
      "z": 10,
      "name": "Empty"
    },
    {
      "x": -18,
      "y": 5,
      "z": 10,
      "name": "Empty"
    },
    {
      "x": -18,
      "y": 6,
      "z": 10,
      "name": "Empty"
    },
    {
      "x": -18,
      "y": 7,
      "z": 10,
      "name": "Empty"
    },
    {
      "x": -18,
      "y": 8,
      "z": 10,
      "name": "Empty"
    },
    {
      "x": -18,
      "y": -3,
      "z": 11,
      "name": "Rock_Stone"
    },
    {
      "x": -18,
      "y": -2,
      "z": 11,
      "name": "Rock_Stone"
    },
    {
      "x": -18,
      "y": -1,
      "z": 11,
      "name": "Rock_Stone"
    },
    {
      "x": -18,
      "y": 0,
      "z": 11,
      "name": "Rock_Stone"
    },
    {
      "x": -18,
      "y": 1,
      "z": 11,
      "name": "Soil_Mud_Dry"
    },
    {
      "x": -18,
      "y": 2,
      "z": 11,
      "name": "Empty"
    },
    {
      "x": -18,
      "y": 3,
      "z": 11,
      "name": "Empty"
    },
    {
      "x": -18,
      "y": 4,
      "z": 11,
      "name": "Empty"
    },
    {
      "x": -18,
      "y": 5,
      "z": 11,
      "name": "Empty"
    },
    {
      "x": -18,
      "y": 6,
      "z": 11,
      "name": "Empty"
    },
    {
      "x": -18,
      "y": 7,
      "z": 11,
      "name": "Empty"
    },
    {
      "x": -18,
      "y": 8,
      "z": 11,
      "name": "Empty"
    },
    {
      "x": -18,
      "y": -3,
      "z": 12,
      "name": "Rock_Stone"
    },
    {
      "x": -18,
      "y": -2,
      "z": 12,
      "name": "Rock_Stone"
    },
    {
      "x": -18,
      "y": -1,
      "z": 12,
      "name": "Rock_Stone"
    },
    {
      "x": -18,
      "y": 0,
      "z": 12,
      "name": "Soil_Mud_Dry"
    },
    {
      "x": -18,
      "y": 1,
      "z": 12,
      "name": "Soil_Mud_Dry"
    },
    {
      "x": -18,
      "y": 2,
      "z": 12,
      "name": "Empty"
    },
    {
      "x": -18,
      "y": 3,
      "z": 12,
      "name": "Empty"
    },
    {
      "x": -18,
      "y": 4,
      "z": 12,
      "name": "Empty"
    },
    {
      "x": -18,
      "y": 5,
      "z": 12,
      "name": "Empty"
    },
    {
      "x": -18,
      "y": 6,
      "z": 12,
      "name": "Empty"
    },
    {
      "x": -18,
      "y": 7,
      "z": 12,
      "name": "Empty"
    },
    {
      "x": -18,
      "y": -2,
      "z": 13,
      "name": "Rock_Stone"
    },
    {
      "x": -18,
      "y": -1,
      "z": 13,
      "name": "Rock_Stone"
    },
    {
      "x": -18,
      "y": 0,
      "z": 13,
      "name": "Soil_Mud_Dry"
    },
    {
      "x": -18,
      "y": 1,
      "z": 13,
      "name": "Soil_Mud_Dry"
    },
    {
      "x": -18,
      "y": 2,
      "z": 13,
      "name": "Empty"
    },
    {
      "x": -18,
      "y": 3,
      "z": 13,
      "name": "Empty"
    },
    {
      "x": -18,
      "y": 4,
      "z": 13,
      "name": "Empty"
    },
    {
      "x": -18,
      "y": -1,
      "z": 14,
      "name": "Rock_Stone"
    },
    {
      "x": -18,
      "y": 0,
      "z": 14,
      "name": "Soil_Mud_Dry"
    },
    {
      "x": -18,
      "y": 1,
      "z": 14,
      "name": "Soil_Mud_Dry"
    },
    {
      "x": -17,
      "y": 0,
      "z": -14,
      "name": "Soil_Dirt"
    },
    {
      "x": -17,
      "y": 1,
      "z": -14,
      "name": "Empty"
    },
    {
      "x": -17,
      "y": 2,
      "z": -14,
      "name": "Empty"
    },
    {
      "x": -17,
      "y": 3,
      "z": -14,
      "name": "Empty"
    },
    {
      "x": -17,
      "y": 4,
      "z": -14,
      "name": "Empty"
    },
    {
      "x": -17,
      "y": 5,
      "z": -14,
      "name": "Empty"
    },
    {
      "x": -17,
      "y": 6,
      "z": -14,
      "name": "Empty"
    },
    {
      "x": -17,
      "y": 7,
      "z": -14,
      "name": "Empty"
    },
    {
      "x": -17,
      "y": 8,
      "z": -14,
      "name": "Empty"
    },
    {
      "x": -17,
      "y": 0,
      "z": -13,
      "name": "Soil_Dirt"
    },
    {
      "x": -17,
      "y": 1,
      "z": -13,
      "name": "Wood_Deadwood_Beam"
    },
    {
      "x": -17,
      "y": 2,
      "z": -13,
      "name": "*Furniture_Ancient_Torch_State_Definitions_Off",
      "rotation": 2
    },
    {
      "x": -17,
      "y": 3,
      "z": -13,
      "name": "Empty"
    },
    {
      "x": -17,
      "y": 4,
      "z": -13,
      "name": "Empty"
    },
    {
      "x": -17,
      "y": 5,
      "z": -13,
      "name": "Empty"
    },
    {
      "x": -17,
      "y": 6,
      "z": -13,
      "name": "Empty"
    },
    {
      "x": -17,
      "y": 7,
      "z": -13,
      "name": "Empty"
    },
    {
      "x": -17,
      "y": 8,
      "z": -13,
      "name": "Empty"
    },
    {
      "x": -17,
      "y": 9,
      "z": -13,
      "name": "Empty"
    },
    {
      "x": -17,
      "y": 10,
      "z": -13,
      "name": "Empty"
    },
    {
      "x": -17,
      "y": 11,
      "z": -13,
      "name": "Empty"
    },
    {
      "x": -17,
      "y": 0,
      "z": -12,
      "name": "Soil_Dirt"
    },
    {
      "x": -17,
      "y": 1,
      "z": -12,
      "name": "Empty"
    },
    {
      "x": -17,
      "y": 2,
      "z": -12,
      "name": "Empty"
    },
    {
      "x": -17,
      "y": 3,
      "z": -12,
      "name": "Empty"
    },
    {
      "x": -17,
      "y": 4,
      "z": -12,
      "name": "Empty"
    },
    {
      "x": -17,
      "y": 5,
      "z": -12,
      "name": "Empty"
    },
    {
      "x": -17,
      "y": 6,
      "z": -12,
      "name": "Empty"
    },
    {
      "x": -17,
      "y": 7,
      "z": -12,
      "name": "Empty"
    },
    {
      "x": -17,
      "y": 8,
      "z": -12,
      "name": "Empty"
    },
    {
      "x": -17,
      "y": 9,
      "z": -12,
      "name": "Empty"
    },
    {
      "x": -17,
      "y": 10,
      "z": -12,
      "name": "Empty"
    },
    {
      "x": -17,
      "y": 0,
      "z": -11,
      "name": "Soil_Dirt"
    },
    {
      "x": -17,
      "y": 1,
      "z": -11,
      "name": "Empty"
    },
    {
      "x": -17,
      "y": 2,
      "z": -11,
      "name": "Empty"
    },
    {
      "x": -17,
      "y": 3,
      "z": -11,
      "name": "Empty"
    },
    {
      "x": -17,
      "y": 4,
      "z": -11,
      "name": "Empty"
    },
    {
      "x": -17,
      "y": 5,
      "z": -11,
      "name": "Empty"
    },
    {
      "x": -17,
      "y": 6,
      "z": -11,
      "name": "Empty"
    },
    {
      "x": -17,
      "y": 7,
      "z": -11,
      "name": "Empty"
    },
    {
      "x": -17,
      "y": 8,
      "z": -11,
      "name": "Empty"
    },
    {
      "x": -17,
      "y": 9,
      "z": -11,
      "name": "Empty"
    },
    {
      "x": -17,
      "y": 10,
      "z": -11,
      "name": "Empty"
    },
    {
      "x": -17,
      "y": 11,
      "z": -11,
      "name": "Empty"
    },
    {
      "x": -17,
      "y": 0,
      "z": -10,
      "name": "Soil_Mud_Dry"
    },
    {
      "x": -17,
      "y": 1,
      "z": -10,
      "name": "Soil_Mud_Dry"
    },
    {
      "x": -17,
      "y": 2,
      "z": -10,
      "name": "Plant_Moss_Rug_Green"
    },
    {
      "x": -17,
      "y": 3,
      "z": -10,
      "name": "Empty"
    },
    {
      "x": -17,
      "y": 4,
      "z": -10,
      "name": "Empty"
    },
    {
      "x": -17,
      "y": 5,
      "z": -10,
      "name": "Empty"
    },
    {
      "x": -17,
      "y": 6,
      "z": -10,
      "name": "Empty"
    },
    {
      "x": -17,
      "y": 7,
      "z": -10,
      "name": "Empty"
    },
    {
      "x": -17,
      "y": 8,
      "z": -10,
      "name": "Empty"
    },
    {
      "x": -17,
      "y": 9,
      "z": -10,
      "name": "Empty"
    },
    {
      "x": -17,
      "y": 10,
      "z": -10,
      "name": "Empty"
    },
    {
      "x": -17,
      "y": 11,
      "z": -10,
      "name": "Empty"
    },
    {
      "x": -17,
      "y": 0,
      "z": -9,
      "name": "Soil_Mud_Dry"
    },
    {
      "x": -17,
      "y": 1,
      "z": -9,
      "name": "Soil_Mud_Dry"
    },
    {
      "x": -17,
      "y": 2,
      "z": -9,
      "name": "Soil_Mud_Dry"
    },
    {
      "x": -17,
      "y": 3,
      "z": -9,
      "name": "Empty"
    },
    {
      "x": -17,
      "y": 4,
      "z": -9,
      "name": "Empty"
    },
    {
      "x": -17,
      "y": 5,
      "z": -9,
      "name": "Empty"
    },
    {
      "x": -17,
      "y": 6,
      "z": -9,
      "name": "Empty"
    },
    {
      "x": -17,
      "y": 7,
      "z": -9,
      "name": "Empty"
    },
    {
      "x": -17,
      "y": 8,
      "z": -9,
      "name": "Empty"
    },
    {
      "x": -17,
      "y": 9,
      "z": -9,
      "name": "Empty"
    },
    {
      "x": -17,
      "y": 10,
      "z": -9,
      "name": "Empty"
    },
    {
      "x": -17,
      "y": 11,
      "z": -9,
      "name": "Empty"
    },
    {
      "x": -17,
      "y": 1,
      "z": -8,
      "name": "Soil_Mud_Dry"
    },
    {
      "x": -17,
      "y": 2,
      "z": -8,
      "name": "Soil_Mud_Dry"
    },
    {
      "x": -17,
      "y": 3,
      "z": -8,
      "name": "Soil_Mud_Dry"
    },
    {
      "x": -17,
      "y": 4,
      "z": -8,
      "name": "Empty"
    },
    {
      "x": -17,
      "y": 5,
      "z": -8,
      "name": "Empty"
    },
    {
      "x": -17,
      "y": 6,
      "z": -8,
      "name": "Empty"
    },
    {
      "x": -17,
      "y": 7,
      "z": -8,
      "name": "Empty"
    },
    {
      "x": -17,
      "y": 8,
      "z": -8,
      "name": "Empty"
    },
    {
      "x": -17,
      "y": 9,
      "z": -8,
      "name": "Empty"
    },
    {
      "x": -17,
      "y": 10,
      "z": -8,
      "name": "Plant_Roots_Cave",
      "rotation": 8
    },
    {
      "x": -17,
      "y": 11,
      "z": -8,
      "name": "Rock_Stone"
    },
    {
      "x": -17,
      "y": 2,
      "z": -7,
      "name": "Soil_Mud_Dry"
    },
    {
      "x": -17,
      "y": 3,
      "z": -7,
      "name": "Soil_Mud_Dry"
    },
    {
      "x": -17,
      "y": 4,
      "z": -7,
      "name": "Empty"
    },
    {
      "x": -17,
      "y": 5,
      "z": -7,
      "name": "Empty"
    },
    {
      "x": -17,
      "y": 6,
      "z": -7,
      "name": "Empty"
    },
    {
      "x": -17,
      "y": 7,
      "z": -7,
      "name": "Empty"
    },
    {
      "x": -17,
      "y": 8,
      "z": -7,
      "name": "Empty"
    },
    {
      "x": -17,
      "y": 9,
      "z": -7,
      "name": "Empty"
    },
    {
      "x": -17,
      "y": 10,
      "z": -7,
      "name": "Empty"
    },
    {
      "x": -17,
      "y": 11,
      "z": -7,
      "name": "Rock_Stone"
    },
    {
      "x": -17,
      "y": 2,
      "z": -6,
      "name": "Soil_Mud_Dry"
    },
    {
      "x": -17,
      "y": 3,
      "z": -6,
      "name": "Soil_Mud_Dry"
    },
    {
      "x": -17,
      "y": 4,
      "z": -6,
      "name": "Soil_Mud_Dry"
    },
    {
      "x": -17,
      "y": 5,
      "z": -6,
      "name": "Empty"
    },
    {
      "x": -17,
      "y": 6,
      "z": -6,
      "name": "Empty"
    },
    {
      "x": -17,
      "y": 7,
      "z": -6,
      "name": "Empty"
    },
    {
      "x": -17,
      "y": 8,
      "z": -6,
      "name": "Empty"
    },
    {
      "x": -17,
      "y": 9,
      "z": -6,
      "name": "Empty"
    },
    {
      "x": -17,
      "y": 3,
      "z": -5,
      "name": "Soil_Mud_Dry"
    },
    {
      "x": -17,
      "y": 4,
      "z": -5,
      "name": "Soil_Mud_Dry"
    },
    {
      "x": -17,
      "y": 5,
      "z": -5,
      "name": "Soil_Mud_Dry"
    },
    {
      "x": -17,
      "y": 6,
      "z": -5,
      "name": "Empty"
    },
    {
      "x": -17,
      "y": 7,
      "z": -5,
      "name": "Empty"
    },
    {
      "x": -17,
      "y": 8,
      "z": -5,
      "name": "Empty"
    },
    {
      "x": -17,
      "y": 2,
      "z": -4,
      "name": "Soil_Mud_Dry"
    },
    {
      "x": -17,
      "y": 3,
      "z": -4,
      "name": "Soil_Mud_Dry"
    },
    {
      "x": -17,
      "y": 4,
      "z": -4,
      "name": "Soil_Mud_Dry"
    },
    {
      "x": -17,
      "y": 2,
      "z": -3,
      "name": "Soil_Mud_Dry"
    },
    {
      "x": -17,
      "y": 3,
      "z": -3,
      "name": "Soil_Mud_Dry"
    },
    {
      "x": -17,
      "y": 4,
      "z": -3,
      "name": "Soil_Mud_Dry"
    },
    {
      "x": -17,
      "y": 7,
      "z": -3,
      "name": "Empty"
    },
    {
      "x": -17,
      "y": 8,
      "z": -3,
      "name": "Empty"
    },
    {
      "x": -17,
      "y": 12,
      "z": -3,
      "name": "Rock_Stone"
    },
    {
      "x": -17,
      "y": 2,
      "z": -2,
      "name": "Soil_Mud_Dry"
    },
    {
      "x": -17,
      "y": 3,
      "z": -2,
      "name": "Soil_Mud_Dry"
    },
    {
      "x": -17,
      "y": 4,
      "z": -2,
      "name": "Soil_Mud_Dry"
    },
    {
      "x": -17,
      "y": 5,
      "z": -2,
      "name": "Soil_Mud_Dry"
    },
    {
      "x": -17,
      "y": 6,
      "z": -2,
      "name": "Rock_Stone"
    },
    {
      "x": -17,
      "y": 7,
      "z": -2,
      "name": "Rock_Stone"
    },
    {
      "x": -17,
      "y": 8,
      "z": -2,
      "name": "Rock_Stone"
    },
    {
      "x": -17,
      "y": 9,
      "z": -2,
      "name": "Rock_Stone"
    },
    {
      "x": -17,
      "y": 11,
      "z": -2,
      "name": "Rock_Stone"
    },
    {
      "x": -17,
      "y": 12,
      "z": -2,
      "name": "Rock_Stone"
    },
    {
      "x": -17,
      "y": 13,
      "z": -2,
      "name": "Rock_Stone"
    },
    {
      "x": -17,
      "y": 1,
      "z": -1,
      "name": "Rock_Stone"
    },
    {
      "x": -17,
      "y": 2,
      "z": -1,
      "name": "Soil_Mud_Dry"
    },
    {
      "x": -17,
      "y": 3,
      "z": -1,
      "name": "Soil_Mud_Dry"
    },
    {
      "x": -17,
      "y": 4,
      "z": -1,
      "name": "Soil_Mud_Dry"
    },
    {
      "x": -17,
      "y": 5,
      "z": -1,
      "name": "Soil_Mud_Dry"
    },
    {
      "x": -17,
      "y": 6,
      "z": -1,
      "name": "Rock_Stone"
    },
    {
      "x": -17,
      "y": 7,
      "z": -1,
      "name": "Rock_Stone"
    },
    {
      "x": -17,
      "y": 8,
      "z": -1,
      "name": "Rock_Stone"
    },
    {
      "x": -17,
      "y": 9,
      "z": -1,
      "name": "Rock_Stone"
    },
    {
      "x": -17,
      "y": 10,
      "z": -1,
      "name": "Rock_Stone"
    },
    {
      "x": -17,
      "y": 11,
      "z": -1,
      "name": "Rock_Stone"
    },
    {
      "x": -17,
      "y": 12,
      "z": -1,
      "name": "Rock_Stone"
    },
    {
      "x": -17,
      "y": 13,
      "z": -1,
      "name": "Rock_Stone"
    },
    {
      "x": -17,
      "y": 14,
      "z": -1,
      "name": "Rock_Stone"
    },
    {
      "x": -17,
      "y": 1,
      "z": 0,
      "name": "Rock_Stone"
    },
    {
      "x": -17,
      "y": 2,
      "z": 0,
      "name": "Soil_Dirt"
    },
    {
      "x": -17,
      "y": 3,
      "z": 0,
      "name": "Soil_Mud_Dry"
    },
    {
      "x": -17,
      "y": 4,
      "z": 0,
      "name": "Soil_Mud_Dry"
    },
    {
      "x": -17,
      "y": 5,
      "z": 0,
      "name": "Soil_Mud_Dry"
    },
    {
      "x": -17,
      "y": 6,
      "z": 0,
      "name": "Rock_Stone"
    },
    {
      "x": -17,
      "y": 7,
      "z": 0,
      "name": "Rock_Stone"
    },
    {
      "x": -17,
      "y": 8,
      "z": 0,
      "name": "Rock_Stone"
    },
    {
      "x": -17,
      "y": 9,
      "z": 0,
      "name": "Rock_Stone"
    },
    {
      "x": -17,
      "y": 10,
      "z": 0,
      "name": "Rock_Stone"
    },
    {
      "x": -17,
      "y": 11,
      "z": 0,
      "name": "Rock_Stone"
    },
    {
      "x": -17,
      "y": 12,
      "z": 0,
      "name": "Rock_Stone"
    },
    {
      "x": -17,
      "y": 13,
      "z": 0,
      "name": "Rock_Stone"
    },
    {
      "x": -17,
      "y": 14,
      "z": 0,
      "name": "Rock_Stone"
    },
    {
      "x": -17,
      "y": 15,
      "z": 0,
      "name": "Rock_Stone"
    },
    {
      "x": -17,
      "y": 1,
      "z": 1,
      "name": "Rock_Stone"
    },
    {
      "x": -17,
      "y": 2,
      "z": 1,
      "name": "Soil_Mud_Dry"
    },
    {
      "x": -17,
      "y": 3,
      "z": 1,
      "name": "Soil_Mud_Dry"
    },
    {
      "x": -17,
      "y": 4,
      "z": 1,
      "name": "Soil_Mud_Dry"
    },
    {
      "x": -17,
      "y": 5,
      "z": 1,
      "name": "Empty"
    },
    {
      "x": -17,
      "y": 6,
      "z": 1,
      "name": "Empty"
    },
    {
      "x": -17,
      "y": 7,
      "z": 1,
      "name": "Empty"
    },
    {
      "x": -17,
      "y": 8,
      "z": 1,
      "name": "Empty"
    },
    {
      "x": -17,
      "y": 9,
      "z": 1,
      "name": "Rock_Stone"
    },
    {
      "x": -17,
      "y": 10,
      "z": 1,
      "name": "Rock_Stone"
    },
    {
      "x": -17,
      "y": 11,
      "z": 1,
      "name": "Rock_Stone"
    },
    {
      "x": -17,
      "y": 12,
      "z": 1,
      "name": "Rock_Stone"
    },
    {
      "x": -17,
      "y": 13,
      "z": 1,
      "name": "Rock_Stone"
    },
    {
      "x": -17,
      "y": 14,
      "z": 1,
      "name": "Rock_Stone"
    },
    {
      "x": -17,
      "y": 0,
      "z": 2,
      "name": "Rock_Stone"
    },
    {
      "x": -17,
      "y": 1,
      "z": 2,
      "name": "Rock_Stone"
    },
    {
      "x": -17,
      "y": 2,
      "z": 2,
      "name": "Soil_Mud_Dry"
    },
    {
      "x": -17,
      "y": 3,
      "z": 2,
      "name": "Soil_Mud_Dry"
    },
    {
      "x": -17,
      "y": 4,
      "z": 2,
      "name": "Soil_Mud_Dry"
    },
    {
      "x": -17,
      "y": 5,
      "z": 2,
      "name": "Empty"
    },
    {
      "x": -17,
      "y": 6,
      "z": 2,
      "name": "Empty"
    },
    {
      "x": -17,
      "y": 7,
      "z": 2,
      "name": "Empty"
    },
    {
      "x": -17,
      "y": 8,
      "z": 2,
      "name": "Empty"
    },
    {
      "x": -17,
      "y": 9,
      "z": 2,
      "name": "Empty"
    },
    {
      "x": -17,
      "y": 10,
      "z": 2,
      "name": "Rock_Stone"
    },
    {
      "x": -17,
      "y": 11,
      "z": 2,
      "name": "Rock_Stone"
    },
    {
      "x": -17,
      "y": 12,
      "z": 2,
      "name": "Rock_Stone"
    },
    {
      "x": -17,
      "y": 13,
      "z": 2,
      "name": "Rock_Stone"
    },
    {
      "x": -17,
      "y": 0,
      "z": 3,
      "name": "Rock_Stone"
    },
    {
      "x": -17,
      "y": 1,
      "z": 3,
      "name": "Soil_Mud_Dry"
    },
    {
      "x": -17,
      "y": 2,
      "z": 3,
      "name": "Soil_Mud_Dry"
    },
    {
      "x": -17,
      "y": 3,
      "z": 3,
      "name": "Empty"
    },
    {
      "x": -17,
      "y": 4,
      "z": 3,
      "name": "Empty"
    },
    {
      "x": -17,
      "y": 5,
      "z": 3,
      "name": "Empty"
    },
    {
      "x": -17,
      "y": 6,
      "z": 3,
      "name": "Empty"
    },
    {
      "x": -17,
      "y": 7,
      "z": 3,
      "name": "Empty"
    },
    {
      "x": -17,
      "y": 8,
      "z": 3,
      "name": "Empty"
    },
    {
      "x": -17,
      "y": 9,
      "z": 3,
      "name": "Empty"
    },
    {
      "x": -17,
      "y": 10,
      "z": 3,
      "name": "Empty"
    },
    {
      "x": -17,
      "y": 11,
      "z": 3,
      "name": "Rock_Stone"
    },
    {
      "x": -17,
      "y": 12,
      "z": 3,
      "name": "Rock_Stone"
    },
    {
      "x": -17,
      "y": 13,
      "z": 3,
      "name": "Rock_Stone"
    },
    {
      "x": -17,
      "y": 0,
      "z": 4,
      "name": "Rock_Stone"
    },
    {
      "x": -17,
      "y": 1,
      "z": 4,
      "name": "Soil_Mud_Dry"
    },
    {
      "x": -17,
      "y": 2,
      "z": 4,
      "name": "Soil_Mud_Dry"
    },
    {
      "x": -17,
      "y": 3,
      "z": 4,
      "name": "Empty"
    },
    {
      "x": -17,
      "y": 4,
      "z": 4,
      "name": "Empty"
    },
    {
      "x": -17,
      "y": 5,
      "z": 4,
      "name": "Empty"
    },
    {
      "x": -17,
      "y": 6,
      "z": 4,
      "name": "Empty"
    },
    {
      "x": -17,
      "y": 7,
      "z": 4,
      "name": "Empty"
    },
    {
      "x": -17,
      "y": 8,
      "z": 4,
      "name": "Empty"
    },
    {
      "x": -17,
      "y": 9,
      "z": 4,
      "name": "Empty"
    },
    {
      "x": -17,
      "y": 10,
      "z": 4,
      "name": "Empty"
    },
    {
      "x": -17,
      "y": -1,
      "z": 5,
      "name": "Rock_Stone"
    },
    {
      "x": -17,
      "y": 0,
      "z": 5,
      "name": "Rock_Stone"
    },
    {
      "x": -17,
      "y": 1,
      "z": 5,
      "name": "Soil_Mud_Dry"
    },
    {
      "x": -17,
      "y": 2,
      "z": 5,
      "name": "Empty"
    },
    {
      "x": -17,
      "y": 3,
      "z": 5,
      "name": "Empty"
    },
    {
      "x": -17,
      "y": 4,
      "z": 5,
      "name": "Empty"
    },
    {
      "x": -17,
      "y": 5,
      "z": 5,
      "name": "Empty"
    },
    {
      "x": -17,
      "y": 6,
      "z": 5,
      "name": "Empty"
    },
    {
      "x": -17,
      "y": 7,
      "z": 5,
      "name": "Empty"
    },
    {
      "x": -17,
      "y": 8,
      "z": 5,
      "name": "Empty"
    },
    {
      "x": -17,
      "y": 9,
      "z": 5,
      "name": "Empty"
    },
    {
      "x": -17,
      "y": 10,
      "z": 5,
      "name": "Empty"
    },
    {
      "x": -17,
      "y": 11,
      "z": 5,
      "name": "Empty"
    },
    {
      "x": -17,
      "y": -1,
      "z": 6,
      "name": "Rock_Stone"
    },
    {
      "x": -17,
      "y": 0,
      "z": 6,
      "name": "Soil_Mud_Dry"
    },
    {
      "x": -17,
      "y": 1,
      "z": 6,
      "name": "Soil_Mud_Dry"
    },
    {
      "x": -17,
      "y": 2,
      "z": 6,
      "name": "Empty"
    },
    {
      "x": -17,
      "y": 3,
      "z": 6,
      "name": "Empty"
    },
    {
      "x": -17,
      "y": 4,
      "z": 6,
      "name": "Empty"
    },
    {
      "x": -17,
      "y": 5,
      "z": 6,
      "name": "Empty"
    },
    {
      "x": -17,
      "y": 6,
      "z": 6,
      "name": "Empty"
    },
    {
      "x": -17,
      "y": 7,
      "z": 6,
      "name": "Empty"
    },
    {
      "x": -17,
      "y": 8,
      "z": 6,
      "name": "Empty"
    },
    {
      "x": -17,
      "y": 9,
      "z": 6,
      "name": "Empty"
    },
    {
      "x": -17,
      "y": 10,
      "z": 6,
      "name": "Empty"
    },
    {
      "x": -17,
      "y": 11,
      "z": 6,
      "name": "Empty"
    },
    {
      "x": -17,
      "y": -2,
      "z": 7,
      "name": "Rock_Stone"
    },
    {
      "x": -17,
      "y": -1,
      "z": 7,
      "name": "Rock_Stone"
    },
    {
      "x": -17,
      "y": 0,
      "z": 7,
      "name": "Soil_Mud_Dry"
    },
    {
      "x": -17,
      "y": 1,
      "z": 7,
      "name": "Soil_Mud_Dry"
    },
    {
      "x": -17,
      "y": 2,
      "z": 7,
      "name": "Empty"
    },
    {
      "x": -17,
      "y": 3,
      "z": 7,
      "name": "Empty"
    },
    {
      "x": -17,
      "y": 4,
      "z": 7,
      "name": "Empty"
    },
    {
      "x": -17,
      "y": 5,
      "z": 7,
      "name": "Empty"
    },
    {
      "x": -17,
      "y": 6,
      "z": 7,
      "name": "Empty"
    },
    {
      "x": -17,
      "y": 7,
      "z": 7,
      "name": "Empty"
    },
    {
      "x": -17,
      "y": 8,
      "z": 7,
      "name": "Empty"
    },
    {
      "x": -17,
      "y": 9,
      "z": 7,
      "name": "Empty"
    },
    {
      "x": -17,
      "y": 10,
      "z": 7,
      "name": "Empty"
    },
    {
      "x": -17,
      "y": -2,
      "z": 8,
      "name": "Rock_Stone"
    },
    {
      "x": -17,
      "y": -1,
      "z": 8,
      "name": "Rock_Stone"
    },
    {
      "x": -17,
      "y": 0,
      "z": 8,
      "name": "Soil_Mud_Dry"
    },
    {
      "x": -17,
      "y": 1,
      "z": 8,
      "name": "Soil_Mud_Dry"
    },
    {
      "x": -17,
      "y": 2,
      "z": 8,
      "name": "Empty"
    },
    {
      "x": -17,
      "y": 3,
      "z": 8,
      "name": "Empty"
    },
    {
      "x": -17,
      "y": 4,
      "z": 8,
      "name": "Empty"
    },
    {
      "x": -17,
      "y": 5,
      "z": 8,
      "name": "Empty"
    },
    {
      "x": -17,
      "y": 6,
      "z": 8,
      "name": "Empty"
    },
    {
      "x": -17,
      "y": 7,
      "z": 8,
      "name": "Empty"
    },
    {
      "x": -17,
      "y": 8,
      "z": 8,
      "name": "Empty"
    },
    {
      "x": -17,
      "y": 9,
      "z": 8,
      "name": "Empty"
    },
    {
      "x": -17,
      "y": 10,
      "z": 8,
      "name": "Empty"
    },
    {
      "x": -17,
      "y": -2,
      "z": 9,
      "name": "Rock_Stone"
    },
    {
      "x": -17,
      "y": -1,
      "z": 9,
      "name": "Rock_Stone"
    },
    {
      "x": -17,
      "y": 0,
      "z": 9,
      "name": "Soil_Mud_Dry"
    },
    {
      "x": -17,
      "y": 1,
      "z": 9,
      "name": "Soil_Mud_Dry"
    },
    {
      "x": -17,
      "y": 2,
      "z": 9,
      "name": "Empty"
    },
    {
      "x": -17,
      "y": 3,
      "z": 9,
      "name": "Empty"
    },
    {
      "x": -17,
      "y": 4,
      "z": 9,
      "name": "Empty"
    },
    {
      "x": -17,
      "y": 5,
      "z": 9,
      "name": "Empty"
    },
    {
      "x": -17,
      "y": 6,
      "z": 9,
      "name": "Empty"
    },
    {
      "x": -17,
      "y": 7,
      "z": 9,
      "name": "Empty"
    },
    {
      "x": -17,
      "y": 8,
      "z": 9,
      "name": "Empty"
    },
    {
      "x": -17,
      "y": 9,
      "z": 9,
      "name": "Empty"
    },
    {
      "x": -17,
      "y": 10,
      "z": 9,
      "name": "Empty"
    },
    {
      "x": -17,
      "y": -3,
      "z": 10,
      "name": "Rock_Stone"
    },
    {
      "x": -17,
      "y": -2,
      "z": 10,
      "name": "Rock_Stone"
    },
    {
      "x": -17,
      "y": -1,
      "z": 10,
      "name": "Rock_Stone"
    },
    {
      "x": -17,
      "y": 0,
      "z": 10,
      "name": "Soil_Mud_Dry"
    },
    {
      "x": -17,
      "y": 1,
      "z": 10,
      "name": "Soil_Mud_Dry"
    },
    {
      "x": -17,
      "y": 2,
      "z": 10,
      "name": "Empty"
    },
    {
      "x": -17,
      "y": 3,
      "z": 10,
      "name": "Empty"
    },
    {
      "x": -17,
      "y": 4,
      "z": 10,
      "name": "Empty"
    },
    {
      "x": -17,
      "y": 5,
      "z": 10,
      "name": "Empty"
    },
    {
      "x": -17,
      "y": 6,
      "z": 10,
      "name": "Empty"
    },
    {
      "x": -17,
      "y": 7,
      "z": 10,
      "name": "Empty"
    },
    {
      "x": -17,
      "y": 8,
      "z": 10,
      "name": "Empty"
    },
    {
      "x": -17,
      "y": 9,
      "z": 10,
      "name": "Empty"
    },
    {
      "x": -17,
      "y": 10,
      "z": 10,
      "name": "Empty"
    },
    {
      "x": -17,
      "y": -3,
      "z": 11,
      "name": "Rock_Stone"
    },
    {
      "x": -17,
      "y": -2,
      "z": 11,
      "name": "Rock_Stone"
    },
    {
      "x": -17,
      "y": -1,
      "z": 11,
      "name": "Rock_Stone"
    },
    {
      "x": -17,
      "y": 0,
      "z": 11,
      "name": "Soil_Mud_Dry"
    },
    {
      "x": -17,
      "y": 1,
      "z": 11,
      "name": "Soil_Mud_Dry"
    },
    {
      "x": -17,
      "y": 2,
      "z": 11,
      "name": "Empty"
    },
    {
      "x": -17,
      "y": 3,
      "z": 11,
      "name": "Empty"
    },
    {
      "x": -17,
      "y": 4,
      "z": 11,
      "name": "Empty"
    },
    {
      "x": -17,
      "y": 5,
      "z": 11,
      "name": "Empty"
    },
    {
      "x": -17,
      "y": 6,
      "z": 11,
      "name": "Empty"
    },
    {
      "x": -17,
      "y": 7,
      "z": 11,
      "name": "Empty"
    },
    {
      "x": -17,
      "y": 8,
      "z": 11,
      "name": "Empty"
    },
    {
      "x": -17,
      "y": 9,
      "z": 11,
      "name": "Empty"
    },
    {
      "x": -17,
      "y": 10,
      "z": 11,
      "name": "Empty"
    },
    {
      "x": -17,
      "y": -3,
      "z": 12,
      "name": "Rock_Stone"
    },
    {
      "x": -17,
      "y": -2,
      "z": 12,
      "name": "Rock_Stone"
    },
    {
      "x": -17,
      "y": -1,
      "z": 12,
      "name": "Rock_Stone"
    },
    {
      "x": -17,
      "y": 0,
      "z": 12,
      "name": "Soil_Mud_Dry"
    },
    {
      "x": -17,
      "y": 1,
      "z": 12,
      "name": "Soil_Mud_Dry"
    },
    {
      "x": -17,
      "y": 2,
      "z": 12,
      "name": "Empty"
    },
    {
      "x": -17,
      "y": 3,
      "z": 12,
      "name": "Empty"
    },
    {
      "x": -17,
      "y": 4,
      "z": 12,
      "name": "Empty"
    },
    {
      "x": -17,
      "y": 5,
      "z": 12,
      "name": "Empty"
    },
    {
      "x": -17,
      "y": 6,
      "z": 12,
      "name": "Empty"
    },
    {
      "x": -17,
      "y": 7,
      "z": 12,
      "name": "Empty"
    },
    {
      "x": -17,
      "y": 8,
      "z": 12,
      "name": "Empty"
    },
    {
      "x": -17,
      "y": 9,
      "z": 12,
      "name": "Empty"
    },
    {
      "x": -17,
      "y": 10,
      "z": 12,
      "name": "Empty"
    },
    {
      "x": -17,
      "y": -2,
      "z": 13,
      "name": "Rock_Stone"
    },
    {
      "x": -17,
      "y": -1,
      "z": 13,
      "name": "Rock_Stone"
    },
    {
      "x": -17,
      "y": 0,
      "z": 13,
      "name": "Soil_Dirt"
    },
    {
      "x": -17,
      "y": 1,
      "z": 13,
      "name": "Empty"
    },
    {
      "x": -17,
      "y": 2,
      "z": 13,
      "name": "Empty"
    },
    {
      "x": -17,
      "y": 3,
      "z": 13,
      "name": "Empty"
    },
    {
      "x": -17,
      "y": 4,
      "z": 13,
      "name": "Empty"
    },
    {
      "x": -17,
      "y": 5,
      "z": 13,
      "name": "Empty"
    },
    {
      "x": -17,
      "y": 6,
      "z": 13,
      "name": "Empty"
    },
    {
      "x": -17,
      "y": 7,
      "z": 13,
      "name": "Empty"
    },
    {
      "x": -17,
      "y": -2,
      "z": 14,
      "name": "Rock_Stone"
    },
    {
      "x": -17,
      "y": -1,
      "z": 14,
      "name": "Rock_Stone"
    },
    {
      "x": -17,
      "y": 0,
      "z": 14,
      "name": "Soil_Dirt"
    },
    {
      "x": -17,
      "y": 1,
      "z": 14,
      "name": "Empty"
    },
    {
      "x": -17,
      "y": 2,
      "z": 14,
      "name": "Empty"
    },
    {
      "x": -17,
      "y": 3,
      "z": 14,
      "name": "Empty"
    },
    {
      "x": -17,
      "y": 4,
      "z": 14,
      "name": "Empty"
    },
    {
      "x": -17,
      "y": 5,
      "z": 14,
      "name": "Empty"
    },
    {
      "x": -17,
      "y": 6,
      "z": 14,
      "name": "Empty"
    },
    {
      "x": -17,
      "y": 7,
      "z": 14,
      "name": "Empty"
    },
    {
      "x": -17,
      "y": 8,
      "z": 14,
      "name": "Empty"
    },
    {
      "x": -16,
      "y": 0,
      "z": -14,
      "name": "Soil_Dirt"
    },
    {
      "x": -16,
      "y": 1,
      "z": -14,
      "name": "Empty"
    },
    {
      "x": -16,
      "y": 2,
      "z": -14,
      "name": "Empty"
    },
    {
      "x": -16,
      "y": 3,
      "z": -14,
      "name": "Empty"
    },
    {
      "x": -16,
      "y": 4,
      "z": -14,
      "name": "Empty"
    },
    {
      "x": -16,
      "y": 5,
      "z": -14,
      "name": "Empty"
    },
    {
      "x": -16,
      "y": 6,
      "z": -14,
      "name": "Empty"
    },
    {
      "x": -16,
      "y": 7,
      "z": -14,
      "name": "Empty"
    },
    {
      "x": -16,
      "y": 8,
      "z": -14,
      "name": "Empty"
    },
    {
      "x": -16,
      "y": 9,
      "z": -14,
      "name": "Empty"
    },
    {
      "x": -16,
      "y": 0,
      "z": -13,
      "name": "Soil_Dirt"
    },
    {
      "x": -16,
      "y": 1,
      "z": -13,
      "name": "Empty"
    },
    {
      "x": -16,
      "y": 2,
      "z": -13,
      "name": "Empty"
    },
    {
      "x": -16,
      "y": 3,
      "z": -13,
      "name": "Empty"
    },
    {
      "x": -16,
      "y": 4,
      "z": -13,
      "name": "Empty"
    },
    {
      "x": -16,
      "y": 5,
      "z": -13,
      "name": "Empty"
    },
    {
      "x": -16,
      "y": 6,
      "z": -13,
      "name": "Empty"
    },
    {
      "x": -16,
      "y": 7,
      "z": -13,
      "name": "Empty"
    },
    {
      "x": -16,
      "y": 8,
      "z": -13,
      "name": "Empty"
    },
    {
      "x": -16,
      "y": 9,
      "z": -13,
      "name": "Empty"
    },
    {
      "x": -16,
      "y": 10,
      "z": -13,
      "name": "Empty"
    },
    {
      "x": -16,
      "y": 11,
      "z": -13,
      "name": "Empty"
    },
    {
      "x": -16,
      "y": 0,
      "z": -12,
      "name": "Soil_Dirt"
    },
    {
      "x": -16,
      "y": 1,
      "z": -12,
      "name": "Empty"
    },
    {
      "x": -16,
      "y": 2,
      "z": -12,
      "name": "Empty"
    },
    {
      "x": -16,
      "y": 3,
      "z": -12,
      "name": "Empty"
    },
    {
      "x": -16,
      "y": 4,
      "z": -12,
      "name": "Empty"
    },
    {
      "x": -16,
      "y": 5,
      "z": -12,
      "name": "Empty"
    },
    {
      "x": -16,
      "y": 6,
      "z": -12,
      "name": "Empty"
    },
    {
      "x": -16,
      "y": 7,
      "z": -12,
      "name": "Empty"
    },
    {
      "x": -16,
      "y": 8,
      "z": -12,
      "name": "Empty"
    },
    {
      "x": -16,
      "y": 9,
      "z": -12,
      "name": "Empty"
    },
    {
      "x": -16,
      "y": 10,
      "z": -12,
      "name": "Empty"
    },
    {
      "x": -16,
      "y": 11,
      "z": -12,
      "name": "Empty"
    },
    {
      "x": -16,
      "y": 0,
      "z": -11,
      "name": "Soil_Dirt"
    },
    {
      "x": -16,
      "y": 1,
      "z": -11,
      "name": "Empty"
    },
    {
      "x": -16,
      "y": 2,
      "z": -11,
      "name": "Empty"
    },
    {
      "x": -16,
      "y": 3,
      "z": -11,
      "name": "Empty"
    },
    {
      "x": -16,
      "y": 4,
      "z": -11,
      "name": "Empty"
    },
    {
      "x": -16,
      "y": 5,
      "z": -11,
      "name": "Empty"
    },
    {
      "x": -16,
      "y": 6,
      "z": -11,
      "name": "Empty"
    },
    {
      "x": -16,
      "y": 7,
      "z": -11,
      "name": "Empty"
    },
    {
      "x": -16,
      "y": 8,
      "z": -11,
      "name": "Empty"
    },
    {
      "x": -16,
      "y": 9,
      "z": -11,
      "name": "Empty"
    },
    {
      "x": -16,
      "y": 10,
      "z": -11,
      "name": "Empty"
    },
    {
      "x": -16,
      "y": 11,
      "z": -11,
      "name": "Empty"
    },
    {
      "x": -16,
      "y": 0,
      "z": -10,
      "name": "Soil_Dirt"
    },
    {
      "x": -16,
      "y": 1,
      "z": -10,
      "name": "Empty"
    },
    {
      "x": -16,
      "y": 2,
      "z": -10,
      "name": "Empty"
    },
    {
      "x": -16,
      "y": 3,
      "z": -10,
      "name": "Empty"
    },
    {
      "x": -16,
      "y": 4,
      "z": -10,
      "name": "Empty"
    },
    {
      "x": -16,
      "y": 5,
      "z": -10,
      "name": "Empty"
    },
    {
      "x": -16,
      "y": 6,
      "z": -10,
      "name": "Empty"
    },
    {
      "x": -16,
      "y": 7,
      "z": -10,
      "name": "Empty"
    },
    {
      "x": -16,
      "y": 8,
      "z": -10,
      "name": "Empty"
    },
    {
      "x": -16,
      "y": 9,
      "z": -10,
      "name": "Empty"
    },
    {
      "x": -16,
      "y": 10,
      "z": -10,
      "name": "Empty"
    },
    {
      "x": -16,
      "y": 11,
      "z": -10,
      "name": "Empty"
    },
    {
      "x": -16,
      "y": 0,
      "z": -9,
      "name": "Soil_Mud_Dry"
    },
    {
      "x": -16,
      "y": 1,
      "z": -9,
      "name": "Soil_Mud_Dry"
    },
    {
      "x": -16,
      "y": 2,
      "z": -9,
      "name": "Empty"
    },
    {
      "x": -16,
      "y": 3,
      "z": -9,
      "name": "Empty"
    },
    {
      "x": -16,
      "y": 4,
      "z": -9,
      "name": "Empty"
    },
    {
      "x": -16,
      "y": 5,
      "z": -9,
      "name": "Empty"
    },
    {
      "x": -16,
      "y": 6,
      "z": -9,
      "name": "Empty"
    },
    {
      "x": -16,
      "y": 7,
      "z": -9,
      "name": "Empty"
    },
    {
      "x": -16,
      "y": 8,
      "z": -9,
      "name": "Empty"
    },
    {
      "x": -16,
      "y": 9,
      "z": -9,
      "name": "Empty"
    },
    {
      "x": -16,
      "y": 10,
      "z": -9,
      "name": "Empty"
    },
    {
      "x": -16,
      "y": 11,
      "z": -9,
      "name": "Empty"
    },
    {
      "x": -16,
      "y": 12,
      "z": -9,
      "name": "Empty"
    },
    {
      "x": -16,
      "y": 1,
      "z": -8,
      "name": "Soil_Mud_Dry"
    },
    {
      "x": -16,
      "y": 2,
      "z": -8,
      "name": "Soil_Mud_Dry"
    },
    {
      "x": -16,
      "y": 3,
      "z": -8,
      "name": "Empty"
    },
    {
      "x": -16,
      "y": 4,
      "z": -8,
      "name": "Empty"
    },
    {
      "x": -16,
      "y": 5,
      "z": -8,
      "name": "Empty"
    },
    {
      "x": -16,
      "y": 6,
      "z": -8,
      "name": "Empty"
    },
    {
      "x": -16,
      "y": 7,
      "z": -8,
      "name": "Empty"
    },
    {
      "x": -16,
      "y": 8,
      "z": -8,
      "name": "Empty"
    },
    {
      "x": -16,
      "y": 9,
      "z": -8,
      "name": "Empty"
    },
    {
      "x": -16,
      "y": 10,
      "z": -8,
      "name": "Empty"
    },
    {
      "x": -16,
      "y": 11,
      "z": -8,
      "name": "Empty"
    },
    {
      "x": -16,
      "y": 12,
      "z": -8,
      "name": "Empty"
    },
    {
      "x": -16,
      "y": 1,
      "z": -7,
      "name": "Soil_Dirt"
    },
    {
      "x": -16,
      "y": 2,
      "z": -7,
      "name": "Soil_Mud_Dry"
    },
    {
      "x": -16,
      "y": 3,
      "z": -7,
      "name": "Empty"
    },
    {
      "x": -16,
      "y": 4,
      "z": -7,
      "name": "Empty"
    },
    {
      "x": -16,
      "y": 5,
      "z": -7,
      "name": "Empty"
    },
    {
      "x": -16,
      "y": 6,
      "z": -7,
      "name": "Empty"
    },
    {
      "x": -16,
      "y": 7,
      "z": -7,
      "name": "Empty"
    },
    {
      "x": -16,
      "y": 8,
      "z": -7,
      "name": "Empty"
    },
    {
      "x": -16,
      "y": 9,
      "z": -7,
      "name": "Empty"
    },
    {
      "x": -16,
      "y": 10,
      "z": -7,
      "name": "Empty"
    },
    {
      "x": -16,
      "y": 11,
      "z": -7,
      "name": "Empty"
    },
    {
      "x": -16,
      "y": 12,
      "z": -7,
      "name": "Empty"
    },
    {
      "x": -16,
      "y": 2,
      "z": -6,
      "name": "Soil_Mud_Dry"
    },
    {
      "x": -16,
      "y": 3,
      "z": -6,
      "name": "Soil_Mud_Dry"
    },
    {
      "x": -16,
      "y": 4,
      "z": -6,
      "name": "Empty"
    },
    {
      "x": -16,
      "y": 5,
      "z": -6,
      "name": "Empty"
    },
    {
      "x": -16,
      "y": 6,
      "z": -6,
      "name": "Empty"
    },
    {
      "x": -16,
      "y": 7,
      "z": -6,
      "name": "Empty"
    },
    {
      "x": -16,
      "y": 8,
      "z": -6,
      "name": "Empty"
    },
    {
      "x": -16,
      "y": 9,
      "z": -6,
      "name": "Empty"
    },
    {
      "x": -16,
      "y": 10,
      "z": -6,
      "name": "Empty"
    },
    {
      "x": -16,
      "y": 11,
      "z": -6,
      "name": "Empty"
    },
    {
      "x": -16,
      "y": 2,
      "z": -5,
      "name": "Soil_Mud_Dry"
    },
    {
      "x": -16,
      "y": 3,
      "z": -5,
      "name": "Soil_Mud_Dry"
    },
    {
      "x": -16,
      "y": 4,
      "z": -5,
      "name": "Plant_Moss_Rug_Green"
    },
    {
      "x": -16,
      "y": 5,
      "z": -5,
      "name": "Empty"
    },
    {
      "x": -16,
      "y": 6,
      "z": -5,
      "name": "Empty"
    },
    {
      "x": -16,
      "y": 7,
      "z": -5,
      "name": "Empty"
    },
    {
      "x": -16,
      "y": 8,
      "z": -5,
      "name": "Empty"
    },
    {
      "x": -16,
      "y": 9,
      "z": -5,
      "name": "Empty"
    },
    {
      "x": -16,
      "y": 10,
      "z": -5,
      "name": "Empty"
    },
    {
      "x": -16,
      "y": 2,
      "z": -4,
      "name": "Soil_Dirt"
    },
    {
      "x": -16,
      "y": 3,
      "z": -4,
      "name": "Soil_Mud_Dry"
    },
    {
      "x": -16,
      "y": 4,
      "z": -4,
      "name": "Plant_Moss_Rug_Green"
    },
    {
      "x": -16,
      "y": 5,
      "z": -4,
      "name": "Empty"
    },
    {
      "x": -16,
      "y": 6,
      "z": -4,
      "name": "Empty"
    },
    {
      "x": -16,
      "y": 7,
      "z": -4,
      "name": "Empty"
    },
    {
      "x": -16,
      "y": 8,
      "z": -4,
      "name": "Empty"
    },
    {
      "x": -16,
      "y": 9,
      "z": -4,
      "name": "Empty"
    },
    {
      "x": -16,
      "y": 10,
      "z": -4,
      "name": "Empty"
    },
    {
      "x": -16,
      "y": 0,
      "z": -3,
      "name": "Rock_Stone"
    },
    {
      "x": -16,
      "y": 1,
      "z": -3,
      "name": "Rock_Stone"
    },
    {
      "x": -16,
      "y": 2,
      "z": -3,
      "name": "Soil_Dirt"
    },
    {
      "x": -16,
      "y": 3,
      "z": -3,
      "name": "Empty"
    },
    {
      "x": -16,
      "y": 4,
      "z": -3,
      "name": "Empty"
    },
    {
      "x": -16,
      "y": 5,
      "z": -3,
      "name": "Empty"
    },
    {
      "x": -16,
      "y": 6,
      "z": -3,
      "name": "Empty"
    },
    {
      "x": -16,
      "y": 7,
      "z": -3,
      "name": "Empty"
    },
    {
      "x": -16,
      "y": 8,
      "z": -3,
      "name": "Empty"
    },
    {
      "x": -16,
      "y": 9,
      "z": -3,
      "name": "Empty"
    },
    {
      "x": -16,
      "y": 11,
      "z": -3,
      "name": "Rock_Stone"
    },
    {
      "x": -16,
      "y": 12,
      "z": -3,
      "name": "Rock_Stone"
    },
    {
      "x": -16,
      "y": 13,
      "z": -3,
      "name": "Rock_Stone"
    },
    {
      "x": -16,
      "y": 0,
      "z": -2,
      "name": "Rock_Stone"
    },
    {
      "x": -16,
      "y": 1,
      "z": -2,
      "name": "Rock_Stone"
    },
    {
      "x": -16,
      "y": 2,
      "z": -2,
      "name": "Soil_Mud_Dry"
    },
    {
      "x": -16,
      "y": 3,
      "z": -2,
      "name": "Empty"
    },
    {
      "x": -16,
      "y": 4,
      "z": -2,
      "name": "Empty"
    },
    {
      "x": -16,
      "y": 5,
      "z": -2,
      "name": "Empty"
    },
    {
      "x": -16,
      "y": 6,
      "z": -2,
      "name": "Empty"
    },
    {
      "x": -16,
      "y": 7,
      "z": -2,
      "name": "Empty"
    },
    {
      "x": -16,
      "y": 8,
      "z": -2,
      "name": "Empty"
    },
    {
      "x": -16,
      "y": 9,
      "z": -2,
      "name": "Empty"
    },
    {
      "x": -16,
      "y": 10,
      "z": -2,
      "name": "Rock_Stone"
    },
    {
      "x": -16,
      "y": 11,
      "z": -2,
      "name": "Rock_Stone"
    },
    {
      "x": -16,
      "y": 12,
      "z": -2,
      "name": "Rock_Stone"
    },
    {
      "x": -16,
      "y": 13,
      "z": -2,
      "name": "Rock_Stone"
    },
    {
      "x": -16,
      "y": 14,
      "z": -2,
      "name": "Rock_Stone"
    },
    {
      "x": -16,
      "y": 15,
      "z": -2,
      "name": "Rock_Stone"
    },
    {
      "x": -16,
      "y": 1,
      "z": -1,
      "name": "Rock_Stone"
    },
    {
      "x": -16,
      "y": 2,
      "z": -1,
      "name": "Soil_Dirt"
    },
    {
      "x": -16,
      "y": 3,
      "z": -1,
      "name": "Rubble_Stone"
    },
    {
      "x": -16,
      "y": 4,
      "z": -1,
      "name": "Empty"
    },
    {
      "x": -16,
      "y": 5,
      "z": -1,
      "name": "Empty"
    },
    {
      "x": -16,
      "y": 6,
      "z": -1,
      "name": "Empty"
    },
    {
      "x": -16,
      "y": 7,
      "z": -1,
      "name": "Empty"
    },
    {
      "x": -16,
      "y": 8,
      "z": -1,
      "name": "Empty"
    },
    {
      "x": -16,
      "y": 9,
      "z": -1,
      "name": "Empty"
    },
    {
      "x": -16,
      "y": 10,
      "z": -1,
      "name": "Rock_Stone"
    },
    {
      "x": -16,
      "y": 11,
      "z": -1,
      "name": "Rock_Stone"
    },
    {
      "x": -16,
      "y": 12,
      "z": -1,
      "name": "Rock_Stone"
    },
    {
      "x": -16,
      "y": 13,
      "z": -1,
      "name": "Rock_Stone"
    },
    {
      "x": -16,
      "y": 14,
      "z": -1,
      "name": "Rock_Stone"
    },
    {
      "x": -16,
      "y": 15,
      "z": -1,
      "name": "Rock_Stone"
    },
    {
      "x": -16,
      "y": 1,
      "z": 0,
      "name": "Rock_Stone"
    },
    {
      "x": -16,
      "y": 2,
      "z": 0,
      "name": "Soil_Dirt"
    },
    {
      "x": -16,
      "y": 3,
      "z": 0,
      "name": "Empty"
    },
    {
      "x": -16,
      "y": 4,
      "z": 0,
      "name": "Empty"
    },
    {
      "x": -16,
      "y": 5,
      "z": 0,
      "name": "Rock_Stone_Stalactite_Large",
      "filler": 31744,
      "rotation": 8
    },
    {
      "x": -16,
      "y": 6,
      "z": 0,
      "name": "Rock_Stone_Stalactite_Large",
      "rotation": 8
    },
    {
      "x": -16,
      "y": 7,
      "z": 0,
      "name": "Rock_Stone"
    },
    {
      "x": -16,
      "y": 8,
      "z": 0,
      "name": "Rock_Stone"
    },
    {
      "x": -16,
      "y": 9,
      "z": 0,
      "name": "Rock_Stone"
    },
    {
      "x": -16,
      "y": 10,
      "z": 0,
      "name": "Rock_Stone"
    },
    {
      "x": -16,
      "y": 11,
      "z": 0,
      "name": "Rock_Stone"
    },
    {
      "x": -16,
      "y": 12,
      "z": 0,
      "name": "Rock_Stone"
    },
    {
      "x": -16,
      "y": 13,
      "z": 0,
      "name": "Rock_Stone"
    },
    {
      "x": -16,
      "y": 14,
      "z": 0,
      "name": "Rock_Stone"
    },
    {
      "x": -16,
      "y": 15,
      "z": 0,
      "name": "Rock_Stone"
    },
    {
      "x": -16,
      "y": 1,
      "z": 1,
      "name": "Rock_Stone"
    },
    {
      "x": -16,
      "y": 2,
      "z": 1,
      "name": "Soil_Dirt"
    },
    {
      "x": -16,
      "y": 3,
      "z": 1,
      "name": "Empty"
    },
    {
      "x": -16,
      "y": 4,
      "z": 1,
      "name": "Empty"
    },
    {
      "x": -16,
      "y": 5,
      "z": 1,
      "name": "Empty"
    },
    {
      "x": -16,
      "y": 6,
      "z": 1,
      "name": "Empty"
    },
    {
      "x": -16,
      "y": 7,
      "z": 1,
      "name": "Empty"
    },
    {
      "x": -16,
      "y": 8,
      "z": 1,
      "name": "Empty"
    },
    {
      "x": -16,
      "y": 9,
      "z": 1,
      "name": "Empty"
    },
    {
      "x": -16,
      "y": 10,
      "z": 1,
      "name": "Rock_Stone"
    },
    {
      "x": -16,
      "y": 11,
      "z": 1,
      "name": "Rock_Stone"
    },
    {
      "x": -16,
      "y": 12,
      "z": 1,
      "name": "Rock_Stone"
    },
    {
      "x": -16,
      "y": 13,
      "z": 1,
      "name": "Rock_Stone"
    },
    {
      "x": -16,
      "y": 14,
      "z": 1,
      "name": "Rock_Stone"
    },
    {
      "x": -16,
      "y": 15,
      "z": 1,
      "name": "Rock_Stone"
    },
    {
      "x": -16,
      "y": 0,
      "z": 2,
      "name": "Rock_Stone"
    },
    {
      "x": -16,
      "y": 1,
      "z": 2,
      "name": "Soil_Dirt"
    },
    {
      "x": -16,
      "y": 2,
      "z": 2,
      "name": "Soil_Mud_Dry"
    },
    {
      "x": -16,
      "y": 3,
      "z": 2,
      "name": "Empty"
    },
    {
      "x": -16,
      "y": 4,
      "z": 2,
      "name": "Empty"
    },
    {
      "x": -16,
      "y": 5,
      "z": 2,
      "name": "Empty"
    },
    {
      "x": -16,
      "y": 6,
      "z": 2,
      "name": "Empty"
    },
    {
      "x": -16,
      "y": 7,
      "z": 2,
      "name": "Empty"
    },
    {
      "x": -16,
      "y": 8,
      "z": 2,
      "name": "Empty"
    },
    {
      "x": -16,
      "y": 9,
      "z": 2,
      "name": "Empty"
    },
    {
      "x": -16,
      "y": 10,
      "z": 2,
      "name": "Empty"
    },
    {
      "x": -16,
      "y": 11,
      "z": 2,
      "name": "Rock_Stone"
    },
    {
      "x": -16,
      "y": 12,
      "z": 2,
      "name": "Rock_Stone"
    },
    {
      "x": -16,
      "y": 13,
      "z": 2,
      "name": "Rock_Stone"
    },
    {
      "x": -16,
      "y": 14,
      "z": 2,
      "name": "Rock_Stone"
    },
    {
      "x": -16,
      "y": 15,
      "z": 2,
      "name": "Rock_Stone"
    },
    {
      "x": -16,
      "y": -1,
      "z": 3,
      "name": "Rock_Stone"
    },
    {
      "x": -16,
      "y": 0,
      "z": 3,
      "name": "Rock_Stone"
    },
    {
      "x": -16,
      "y": 1,
      "z": 3,
      "name": "Soil_Dirt"
    },
    {
      "x": -16,
      "y": 2,
      "z": 3,
      "name": "Soil_Dirt"
    },
    {
      "x": -16,
      "y": 3,
      "z": 3,
      "name": "Empty"
    },
    {
      "x": -16,
      "y": 4,
      "z": 3,
      "name": "Empty"
    },
    {
      "x": -16,
      "y": 5,
      "z": 3,
      "name": "Empty"
    },
    {
      "x": -16,
      "y": 6,
      "z": 3,
      "name": "Empty"
    },
    {
      "x": -16,
      "y": 7,
      "z": 3,
      "name": "Empty"
    },
    {
      "x": -16,
      "y": 8,
      "z": 3,
      "name": "Empty"
    },
    {
      "x": -16,
      "y": 9,
      "z": 3,
      "name": "Empty"
    },
    {
      "x": -16,
      "y": 10,
      "z": 3,
      "name": "Empty"
    },
    {
      "x": -16,
      "y": 11,
      "z": 3,
      "name": "Empty"
    },
    {
      "x": -16,
      "y": 12,
      "z": 3,
      "name": "Rock_Stone"
    },
    {
      "x": -16,
      "y": 13,
      "z": 3,
      "name": "Rock_Stone"
    },
    {
      "x": -16,
      "y": 14,
      "z": 3,
      "name": "Rock_Stone"
    },
    {
      "x": -16,
      "y": -1,
      "z": 4,
      "name": "Rock_Stone"
    },
    {
      "x": -16,
      "y": 0,
      "z": 4,
      "name": "Rock_Stone"
    },
    {
      "x": -16,
      "y": 1,
      "z": 4,
      "name": "Soil_Dirt"
    },
    {
      "x": -16,
      "y": 2,
      "z": 4,
      "name": "Empty"
    },
    {
      "x": -16,
      "y": 3,
      "z": 4,
      "name": "Empty"
    },
    {
      "x": -16,
      "y": 4,
      "z": 4,
      "name": "Empty"
    },
    {
      "x": -16,
      "y": 5,
      "z": 4,
      "name": "Empty"
    },
    {
      "x": -16,
      "y": 6,
      "z": 4,
      "name": "Empty"
    },
    {
      "x": -16,
      "y": 7,
      "z": 4,
      "name": "Empty"
    },
    {
      "x": -16,
      "y": 8,
      "z": 4,
      "name": "Empty"
    },
    {
      "x": -16,
      "y": 9,
      "z": 4,
      "name": "Empty"
    },
    {
      "x": -16,
      "y": 10,
      "z": 4,
      "name": "Empty"
    },
    {
      "x": -16,
      "y": 11,
      "z": 4,
      "name": "Empty"
    },
    {
      "x": -16,
      "y": 12,
      "z": 4,
      "name": "Empty"
    },
    {
      "x": -16,
      "y": -1,
      "z": 5,
      "name": "Rock_Stone"
    },
    {
      "x": -16,
      "y": 0,
      "z": 5,
      "name": "Soil_Dirt"
    },
    {
      "x": -16,
      "y": 1,
      "z": 5,
      "name": "Soil_Mud_Dry"
    },
    {
      "x": -16,
      "y": 2,
      "z": 5,
      "name": "Empty"
    },
    {
      "x": -16,
      "y": 3,
      "z": 5,
      "name": "Empty"
    },
    {
      "x": -16,
      "y": 4,
      "z": 5,
      "name": "Empty"
    },
    {
      "x": -16,
      "y": 5,
      "z": 5,
      "name": "Empty"
    },
    {
      "x": -16,
      "y": 6,
      "z": 5,
      "name": "Empty"
    },
    {
      "x": -16,
      "y": 7,
      "z": 5,
      "name": "Empty"
    },
    {
      "x": -16,
      "y": 8,
      "z": 5,
      "name": "Empty"
    },
    {
      "x": -16,
      "y": 9,
      "z": 5,
      "name": "Empty"
    },
    {
      "x": -16,
      "y": 10,
      "z": 5,
      "name": "Empty"
    },
    {
      "x": -16,
      "y": 11,
      "z": 5,
      "name": "Empty"
    },
    {
      "x": -16,
      "y": 12,
      "z": 5,
      "name": "Empty"
    },
    {
      "x": -16,
      "y": -1,
      "z": 6,
      "name": "Rock_Stone"
    },
    {
      "x": -16,
      "y": 0,
      "z": 6,
      "name": "Soil_Mud_Dry"
    },
    {
      "x": -16,
      "y": 1,
      "z": 6,
      "name": "Soil_Mud_Dry"
    },
    {
      "x": -16,
      "y": 2,
      "z": 6,
      "name": "Empty"
    },
    {
      "x": -16,
      "y": 3,
      "z": 6,
      "name": "Empty"
    },
    {
      "x": -16,
      "y": 4,
      "z": 6,
      "name": "Empty"
    },
    {
      "x": -16,
      "y": 5,
      "z": 6,
      "name": "Empty"
    },
    {
      "x": -16,
      "y": 6,
      "z": 6,
      "name": "Empty"
    },
    {
      "x": -16,
      "y": 7,
      "z": 6,
      "name": "Empty"
    },
    {
      "x": -16,
      "y": 8,
      "z": 6,
      "name": "Empty"
    },
    {
      "x": -16,
      "y": 9,
      "z": 6,
      "name": "Empty"
    },
    {
      "x": -16,
      "y": 10,
      "z": 6,
      "name": "Empty"
    },
    {
      "x": -16,
      "y": 11,
      "z": 6,
      "name": "Empty"
    },
    {
      "x": -16,
      "y": 12,
      "z": 6,
      "name": "Empty"
    },
    {
      "x": -16,
      "y": -2,
      "z": 7,
      "name": "Rock_Stone"
    },
    {
      "x": -16,
      "y": -1,
      "z": 7,
      "name": "Rock_Stone"
    },
    {
      "x": -16,
      "y": 0,
      "z": 7,
      "name": "Soil_Mud_Dry"
    },
    {
      "x": -16,
      "y": 1,
      "z": 7,
      "name": "Empty"
    },
    {
      "x": -16,
      "y": 2,
      "z": 7,
      "name": "Empty"
    },
    {
      "x": -16,
      "y": 3,
      "z": 7,
      "name": "Empty"
    },
    {
      "x": -16,
      "y": 4,
      "z": 7,
      "name": "Empty"
    },
    {
      "x": -16,
      "y": 5,
      "z": 7,
      "name": "Empty"
    },
    {
      "x": -16,
      "y": 6,
      "z": 7,
      "name": "Empty"
    },
    {
      "x": -16,
      "y": 7,
      "z": 7,
      "name": "Empty"
    },
    {
      "x": -16,
      "y": 8,
      "z": 7,
      "name": "Empty"
    },
    {
      "x": -16,
      "y": 9,
      "z": 7,
      "name": "Empty"
    },
    {
      "x": -16,
      "y": 10,
      "z": 7,
      "name": "Empty"
    },
    {
      "x": -16,
      "y": 11,
      "z": 7,
      "name": "Empty"
    },
    {
      "x": -16,
      "y": 12,
      "z": 7,
      "name": "Empty"
    },
    {
      "x": -16,
      "y": -2,
      "z": 8,
      "name": "Rock_Stone"
    },
    {
      "x": -16,
      "y": -1,
      "z": 8,
      "name": "Rock_Stone"
    },
    {
      "x": -16,
      "y": 0,
      "z": 8,
      "name": "Soil_Mud_Dry"
    },
    {
      "x": -16,
      "y": 1,
      "z": 8,
      "name": "Empty"
    },
    {
      "x": -16,
      "y": 2,
      "z": 8,
      "name": "Empty"
    },
    {
      "x": -16,
      "y": 3,
      "z": 8,
      "name": "Empty"
    },
    {
      "x": -16,
      "y": 4,
      "z": 8,
      "name": "Empty"
    },
    {
      "x": -16,
      "y": 5,
      "z": 8,
      "name": "Empty"
    },
    {
      "x": -16,
      "y": 6,
      "z": 8,
      "name": "Empty"
    },
    {
      "x": -16,
      "y": 7,
      "z": 8,
      "name": "Empty"
    },
    {
      "x": -16,
      "y": 8,
      "z": 8,
      "name": "Empty"
    },
    {
      "x": -16,
      "y": 9,
      "z": 8,
      "name": "Empty"
    },
    {
      "x": -16,
      "y": 10,
      "z": 8,
      "name": "Empty"
    },
    {
      "x": -16,
      "y": 11,
      "z": 8,
      "name": "Empty"
    },
    {
      "x": -16,
      "y": 12,
      "z": 8,
      "name": "Empty"
    },
    {
      "x": -16,
      "y": -2,
      "z": 9,
      "name": "Rock_Stone"
    },
    {
      "x": -16,
      "y": -1,
      "z": 9,
      "name": "Rock_Stone"
    },
    {
      "x": -16,
      "y": 0,
      "z": 9,
      "name": "Soil_Mud_Dry"
    },
    {
      "x": -16,
      "y": 1,
      "z": 9,
      "name": "Empty"
    },
    {
      "x": -16,
      "y": 2,
      "z": 9,
      "name": "Empty"
    },
    {
      "x": -16,
      "y": 3,
      "z": 9,
      "name": "Empty"
    },
    {
      "x": -16,
      "y": 4,
      "z": 9,
      "name": "Empty"
    },
    {
      "x": -16,
      "y": 5,
      "z": 9,
      "name": "Empty"
    },
    {
      "x": -16,
      "y": 6,
      "z": 9,
      "name": "Empty"
    },
    {
      "x": -16,
      "y": 7,
      "z": 9,
      "name": "Empty"
    },
    {
      "x": -16,
      "y": 8,
      "z": 9,
      "name": "Empty"
    },
    {
      "x": -16,
      "y": 9,
      "z": 9,
      "name": "Empty"
    },
    {
      "x": -16,
      "y": 10,
      "z": 9,
      "name": "Empty"
    },
    {
      "x": -16,
      "y": 11,
      "z": 9,
      "name": "Empty"
    },
    {
      "x": -16,
      "y": -3,
      "z": 10,
      "name": "Rock_Stone"
    },
    {
      "x": -16,
      "y": -2,
      "z": 10,
      "name": "Rock_Stone"
    },
    {
      "x": -16,
      "y": -1,
      "z": 10,
      "name": "Rock_Stone"
    },
    {
      "x": -16,
      "y": 0,
      "z": 10,
      "name": "Soil_Mud_Dry"
    },
    {
      "x": -16,
      "y": 1,
      "z": 10,
      "name": "Empty"
    },
    {
      "x": -16,
      "y": 2,
      "z": 10,
      "name": "Empty"
    },
    {
      "x": -16,
      "y": 3,
      "z": 10,
      "name": "Empty"
    },
    {
      "x": -16,
      "y": 4,
      "z": 10,
      "name": "Empty"
    },
    {
      "x": -16,
      "y": 5,
      "z": 10,
      "name": "Empty"
    },
    {
      "x": -16,
      "y": 6,
      "z": 10,
      "name": "Empty"
    },
    {
      "x": -16,
      "y": 7,
      "z": 10,
      "name": "Empty"
    },
    {
      "x": -16,
      "y": 8,
      "z": 10,
      "name": "Empty"
    },
    {
      "x": -16,
      "y": 9,
      "z": 10,
      "name": "Empty"
    },
    {
      "x": -16,
      "y": 10,
      "z": 10,
      "name": "Empty"
    },
    {
      "x": -16,
      "y": 11,
      "z": 10,
      "name": "Empty"
    },
    {
      "x": -16,
      "y": -3,
      "z": 11,
      "name": "Rock_Stone"
    },
    {
      "x": -16,
      "y": -2,
      "z": 11,
      "name": "Rock_Stone"
    },
    {
      "x": -16,
      "y": -1,
      "z": 11,
      "name": "Rock_Stone"
    },
    {
      "x": -16,
      "y": 0,
      "z": 11,
      "name": "Soil_Mud_Dry"
    },
    {
      "x": -16,
      "y": 1,
      "z": 11,
      "name": "Soil_Mud_Dry"
    },
    {
      "x": -16,
      "y": 2,
      "z": 11,
      "name": "Empty"
    },
    {
      "x": -16,
      "y": 3,
      "z": 11,
      "name": "Empty"
    },
    {
      "x": -16,
      "y": 4,
      "z": 11,
      "name": "Empty"
    },
    {
      "x": -16,
      "y": 5,
      "z": 11,
      "name": "Empty"
    },
    {
      "x": -16,
      "y": 6,
      "z": 11,
      "name": "Empty"
    },
    {
      "x": -16,
      "y": 7,
      "z": 11,
      "name": "Empty"
    },
    {
      "x": -16,
      "y": 8,
      "z": 11,
      "name": "Empty"
    },
    {
      "x": -16,
      "y": 9,
      "z": 11,
      "name": "Empty"
    },
    {
      "x": -16,
      "y": 10,
      "z": 11,
      "name": "Empty"
    },
    {
      "x": -16,
      "y": -3,
      "z": 12,
      "name": "Rock_Stone"
    },
    {
      "x": -16,
      "y": -2,
      "z": 12,
      "name": "Rock_Stone"
    },
    {
      "x": -16,
      "y": -1,
      "z": 12,
      "name": "Rock_Stone"
    },
    {
      "x": -16,
      "y": 0,
      "z": 12,
      "name": "Soil_Mud_Dry"
    },
    {
      "x": -16,
      "y": 1,
      "z": 12,
      "name": "Soil_Mud_Dry"
    },
    {
      "x": -16,
      "y": 2,
      "z": 12,
      "name": "Empty"
    },
    {
      "x": -16,
      "y": 3,
      "z": 12,
      "name": "Empty"
    },
    {
      "x": -16,
      "y": 4,
      "z": 12,
      "name": "Empty"
    },
    {
      "x": -16,
      "y": 5,
      "z": 12,
      "name": "Empty"
    },
    {
      "x": -16,
      "y": 6,
      "z": 12,
