{
  "version": 8,
  "blockIdVersion": 8,
  "anchorX": 0,
  "anchorY": 0,
  "anchorZ": 0,
  "blocks": [
    {
      "x": -23,
      "y": 10,
      "z": -7,
      "name": "Rock_Stone"
    },
    {
      "x": -23,
      "y": 11,
      "z": -7,
      "name": "Rock_Stone"
    },
    {
      "x": -23,
      "y": 6,
      "z": -6,
      "name": "Rock_Stone"
    },
    {
      "x": -23,
      "y": 7,
      "z": -6,
      "name": "Rock_Stone"
    },
    {
      "x": -23,
      "y": 8,
      "z": -6,
      "name": "Rock_Stone"
    },
    {
      "x": -23,
      "y": 10,
      "z": -6,
      "name": "Rock_Stone"
    },
    {
      "x": -23,
      "y": 5,
      "z": -5,
      "name": "Rock_Stone"
    },
    {
      "x": -23,
      "y": 6,
      "z": -5,
      "name": "Rock_Stone"
    },
    {
      "x": -23,
      "y": 7,
      "z": -5,
      "name": "Rock_Stone"
    },
    {
      "x": -23,
      "y": 8,
      "z": -5,
      "name": "Rock_Stone"
    },
    {
      "x": -23,
      "y": 9,
      "z": -5,
      "name": "Rock_Stone"
    },
    {
      "x": -23,
      "y": 4,
      "z": -4,
      "name": "Rock_Stone"
    },
    {
      "x": -23,
      "y": 5,
      "z": -4,
      "name": "Rock_Stone"
    },
    {
      "x": -23,
      "y": 6,
      "z": -4,
      "name": "Rock_Stone"
    },
    {
      "x": -23,
      "y": 7,
      "z": -4,
      "name": "Rock_Stone"
    },
    {
      "x": -23,
      "y": 4,
      "z": -3,
      "name": "Rock_Stone"
    },
    {
      "x": -23,
      "y": 5,
      "z": -3,
      "name": "Rock_Stone"
    },
    {
      "x": -23,
      "y": 6,
      "z": -3,
      "name": "Rock_Stone"
    },
    {
      "x": -22,
      "y": 11,
      "z": -8,
      "name": "Rock_Stone"
    },
    {
      "x": -22,
      "y": 12,
      "z": -8,
      "name": "Rock_Stone"
    },
    {
      "x": -22,
      "y": 4,
      "z": -7,
      "name": "Rock_Stone"
    },
    {
      "x": -22,
      "y": 5,
      "z": -7,
      "name": "Rock_Stone"
    },
    {
      "x": -22,
      "y": 6,
      "z": -7,
      "name": "Rock_Stone"
    },
    {
      "x": -22,
      "y": 7,
      "z": -7,
      "name": "Rock_Stone"
    },
    {
      "x": -22,
      "y": 8,
      "z": -7,
      "name": "Rock_Stone"
    },
    {
      "x": -22,
      "y": 9,
      "z": -7,
      "name": "Rock_Stone"
    },
    {
      "x": -22,
      "y": 10,
      "z": -7,
      "name": "Rock_Stone"
    },
    {
      "x": -22,
      "y": 11,
      "z": -7,
      "name": "Rock_Stone"
    },
    {
      "x": -22,
      "y": 12,
      "z": -7,
      "name": "Rock_Stone"
    },
    {
      "x": -22,
      "y": 4,
      "z": -6,
      "name": "Rock_Stone"
    },
    {
      "x": -22,
      "y": 5,
      "z": -6,
      "name": "Rock_Stone"
    },
    {
      "x": -22,
      "y": 6,
      "z": -6,
      "name": "Rock_Stone"
    },
    {
      "x": -22,
      "y": 7,
      "z": -6,
      "name": "Rock_Stone"
    },
    {
      "x": -22,
      "y": 8,
      "z": -6,
      "name": "Rock_Stone"
    },
    {
      "x": -22,
      "y": 9,
      "z": -6,
      "name": "Rock_Stone"
    },
    {
      "x": -22,
      "y": 10,
      "z": -6,
      "name": "Rock_Stone"
    },
    {
      "x": -22,
      "y": 11,
      "z": -6,
      "name": "Rock_Stone"
    },
    {
      "x": -22,
      "y": 12,
      "z": -6,
      "name": "Rock_Stone"
    },
    {
      "x": -22,
      "y": 4,
      "z": -5,
      "name": "Rock_Stone"
    },
    {
      "x": -22,
      "y": 5,
      "z": -5,
      "name": "Rock_Stone"
    },
    {
      "x": -22,
      "y": 6,
      "z": -5,
      "name": "Rock_Stone"
    },
    {
      "x": -22,
      "y": 7,
      "z": -5,
      "name": "Soil_Mud_Dry"
    },
    {
      "x": -22,
      "y": 8,
      "z": -5,
      "name": "Rock_Stone"
    },
    {
      "x": -22,
      "y": 9,
      "z": -5,
      "name": "Rock_Stone"
    },
    {
      "x": -22,
      "y": 10,
      "z": -5,
      "name": "Rock_Stone"
    },
    {
      "x": -22,
      "y": 11,
      "z": -5,
      "name": "Rock_Stone"
    },
    {
      "x": -22,
      "y": 4,
      "z": -4,
      "name": "Rock_Stone"
    },
    {
      "x": -22,
      "y": 5,
      "z": -4,
      "name": "Rock_Stone"
    },
    {
      "x": -22,
      "y": 6,
      "z": -4,
      "name": "Soil_Mud_Dry"
    },
    {
      "x": -22,
      "y": 7,
      "z": -4,
      "name": "Soil_Mud_Dry"
    },
    {
      "x": -22,
      "y": 8,
      "z": -4,
      "name": "Soil_Mud_Dry"
    },
    {
      "x": -22,
      "y": 9,
      "z": -4,
      "name": "Rock_Stone"
    },
    {
      "x": -22,
      "y": 10,
      "z": -4,
      "name": "Rock_Stone"
    },
    {
      "x": -22,
      "y": 4,
      "z": -3,
      "name": "Rock_Stone"
    },
    {
      "x": -22,
      "y": 5,
      "z": -3,
      "name": "Soil_Mud_Dry"
    },
    {
      "x": -22,
      "y": 6,
      "z": -3,
      "name": "Soil_Mud_Dry"
    },
    {
      "x": -22,
      "y": 7,
      "z": -3,
      "name": "Soil_Mud_Dry"
    },
    {
      "x": -22,
      "y": 8,
      "z": -3,
      "name": "Soil_Mud_Dry"
    },
    {
      "x": -22,
      "y": 9,
      "z": -3,
      "name": "Soil_Mud_Dry"
    },
    {
      "x": -22,
      "y": 6,
      "z": -2,
      "name": "Soil_Mud_Dry"
    },
    {
      "x": -22,
      "y": 8,
      "z": -2,
      "name": "Soil_Mud_Dry"
    },
    {
      "x": -21,
      "y": 11,
      "z": -9,
      "name": "Rock_Stone"
    },
    {
      "x": -21,
      "y": 12,
      "z": -9,
      "name": "Rock_Stone"
    },
    {
      "x": -21,
      "y": 5,
      "z": -8,
      "name": "Rock_Stone"
    },
    {
      "x": -21,
      "y": 6,
      "z": -8,
      "name": "Rock_Stone"
    },
    {
      "x": -21,
      "y": 7,
      "z": -8,
      "name": "Rock_Stone"
    },
    {
      "x": -21,
      "y": 8,
      "z": -8,
      "name": "Rock_Stone"
    },
    {
      "x": -21,
      "y": 9,
      "z": -8,
      "name": "Rock_Stone"
    },
    {
      "x": -21,
      "y": 10,
      "z": -8,
      "name": "Rock_Stone"
    },
    {
      "x": -21,
      "y": 11,
      "z": -8,
      "name": "Rock_Stone"
    },
    {
      "x": -21,
      "y": 12,
      "z": -8,
      "name": "Rock_Stone"
    },
    {
      "x": -21,
      "y": 13,
      "z": -8,
      "name": "Rock_Stone"
    },
    {
      "x": -21,
      "y": 4,
      "z": -7,
      "name": "Rock_Stone"
    },
    {
      "x": -21,
      "y": 5,
      "z": -7,
      "name": "Rock_Stone"
    },
    {
      "x": -21,
      "y": 6,
      "z": -7,
      "name": "Rock_Stone"
    },
    {
      "x": -21,
      "y": 7,
      "z": -7,
      "name": "Soil_Mud_Dry"
    },
    {
      "x": -21,
      "y": 8,
      "z": -7,
      "name": "Rock_Stone"
    },
    {
      "x": -21,
      "y": 9,
      "z": -7,
      "name": "Rock_Stone"
    },
    {
      "x": -21,
      "y": 10,
      "z": -7,
      "name": "Rock_Stone"
    },
    {
      "x": -21,
      "y": 11,
      "z": -7,
      "name": "Rock_Stone"
    },
    {
      "x": -21,
      "y": 12,
      "z": -7,
      "name": "Rock_Stone"
    },
    {
      "x": -21,
      "y": 13,
      "z": -7,
      "name": "Rock_Stone"
    },
    {
      "x": -21,
      "y": 3,
      "z": -6,
      "name": "Rock_Stone"
    },
    {
      "x": -21,
      "y": 4,
      "z": -6,
      "name": "Rock_Stone"
    },
    {
      "x": -21,
      "y": 5,
      "z": -6,
      "name": "Rock_Stone"
    },
    {
      "x": -21,
      "y": 6,
      "z": -6,
      "name": "Soil_Mud_Dry"
    },
    {
      "x": -21,
      "y": 7,
      "z": -6,
      "name": "Soil_Mud_Dry"
    },
    {
      "x": -21,
      "y": 8,
      "z": -6,
      "name": "Soil_Mud_Dry"
    },
    {
      "x": -21,
      "y": 9,
      "z": -6,
      "name": "Rock_Stone"
    },
    {
      "x": -21,
      "y": 10,
      "z": -6,
      "name": "Rock_Stone"
    },
    {
      "x": -21,
      "y": 11,
      "z": -6,
      "name": "Rock_Stone"
    },
    {
      "x": -21,
      "y": 12,
      "z": -6,
      "name": "Rock_Stone"
    },
    {
      "x": -21,
      "y": 3,
      "z": -5,
      "name": "Rock_Stone"
    },
    {
      "x": -21,
      "y": 4,
      "z": -5,
      "name": "Rock_Stone"
    },
    {
      "x": -21,
      "y": 5,
      "z": -5,
      "name": "Rock_Stone"
    },
    {
      "x": -21,
      "y": 6,
      "z": -5,
      "name": "Soil_Mud_Dry"
    },
    {
      "x": -21,
      "y": 7,
      "z": -5,
      "name": "Soil_Mud_Dry"
    },
    {
      "x": -21,
      "y": 8,
      "z": -5,
      "name": "Soil_Mud_Dry"
    },
    {
      "x": -21,
      "y": 9,
      "z": -5,
      "name": "Rock_Stone"
    },
    {
      "x": -21,
      "y": 10,
      "z": -5,
      "name": "Rock_Stone"
    },
    {
      "x": -21,
      "y": 11,
      "z": -5,
      "name": "Rock_Stone"
    },
    {
      "x": -21,
      "y": 12,
      "z": -5,
      "name": "Rock_Stone"
    },
    {
      "x": -21,
      "y": 3,
      "z": -4,
      "name": "Rock_Stone"
    },
    {
      "x": -21,
      "y": 4,
      "z": -4,
      "name": "Rock_Stone"
    },
    {
      "x": -21,
      "y": 5,
      "z": -4,
      "name": "Soil_Mud_Dry"
    },
    {
      "x": -21,
      "y": 6,
      "z": -4,
      "name": "Soil_Mud_Dry"
    },
    {
      "x": -21,
      "y": 7,
      "z": -4,
      "name": "Soil_Mud_Dry"
    },
    {
      "x": -21,
      "y": 8,
      "z": -4,
      "name": "Soil_Mud_Dry"
    },
    {
      "x": -21,
      "y": 9,
      "z": -4,
      "name": "Soil_Mud_Dry"
    },
    {
      "x": -21,
      "y": 10,
      "z": -4,
      "name": "Rock_Stone"
    },
    {
      "x": -21,
      "y": 11,
      "z": -4,
      "name": "Rock_Stone"
    },
    {
      "x": -21,
      "y": 3,
      "z": -3,
      "name": "Rock_Stone"
    },
    {
      "x": -21,
      "y": 4,
      "z": -3,
      "name": "Soil_Mud_Dry"
    },
    {
      "x": -21,
      "y": 5,
      "z": -3,
      "name": "Soil_Mud_Dry"
    },
    {
      "x": -21,
      "y": 6,
      "z": -3,
      "name": "Soil_Mud_Dry"
    },
    {
      "x": -21,
      "y": 7,
      "z": -3,
      "name": "Soil_Mud_Dry"
    },
    {
      "x": -21,
      "y": 8,
      "z": -3,
      "name": "Soil_Mud_Dry"
    },
    {
      "x": -21,
      "y": 9,
      "z": -3,
      "name": "Soil_Mud_Dry"
    },
    {
      "x": -21,
      "y": 10,
      "z": -3,
      "name": "Soil_Mud_Dry"
    },
    {
      "x": -21,
      "y": 11,
      "z": -3,
      "name": "Rock_Stone"
    },
    {
      "x": -21,
      "y": 12,
      "z": -3,
      "name": "Rock_Stone"
    },
    {
      "x": -21,
      "y": 4,
      "z": -2,
      "name": "Rock_Stone"
    },
    {
      "x": -21,
      "y": 5,
      "z": -2,
      "name": "Soil_Mud_Dry"
    },
    {
      "x": -21,
      "y": 6,
      "z": -2,
      "name": "Soil_Mud_Dry"
    },
    {
      "x": -21,
      "y": 7,
      "z": -2,
      "name": "Soil_Mud_Dry"
    },
    {
      "x": -21,
      "y": 8,
      "z": -2,
      "name": "Soil_Mud_Dry"
    },
    {
      "x": -21,
      "y": 9,
      "z": -2,
      "name": "Soil_Mud_Dry"
    },
    {
      "x": -21,
      "y": 10,
      "z": -2,
      "name": "Rock_Stone"
    },
    {
      "x": -21,
      "y": 11,
      "z": -2,
      "name": "Rock_Stone"
    },
    {
      "x": -21,
      "y": 6,
      "z": -1,
      "name": "Soil_Mud_Dry"
    },
    {
      "x": -21,
      "y": 8,
      "z": -1,
      "name": "Soil_Mud_Dry"
    },
    {
      "x": -20,
      "y": 4,
      "z": -9,
      "name": "Rock_Stone"
    },
    {
      "x": -20,
      "y": 5,
      "z": -9,
      "name": "Rock_Stone"
    },
    {
      "x": -20,
      "y": 6,
      "z": -9,
      "name": "Rock_Stone"
    },
    {
      "x": -20,
      "y": 10,
      "z": -9,
      "name": "Rock_Stone"
    },
    {
      "x": -20,
      "y": 11,
      "z": -9,
      "name": "Rock_Stone"
    },
    {
      "x": -20,
      "y": 2,
      "z": -8,
      "name": "Rock_Stone"
    },
    {
      "x": -20,
      "y": 3,
      "z": -8,
      "name": "Rock_Stone"
    },
    {
      "x": -20,
      "y": 4,
      "z": -8,
      "name": "Rock_Stone"
    },
    {
      "x": -20,
      "y": 5,
      "z": -8,
      "name": "Rock_Stone"
    },
    {
      "x": -20,
      "y": 6,
      "z": -8,
      "name": "Rock_Stone"
    },
    {
      "x": -20,
      "y": 7,
      "z": -8,
      "name": "Soil_Mud_Dry"
    },
    {
      "x": -20,
      "y": 8,
      "z": -8,
      "name": "Rock_Stone"
    },
    {
      "x": -20,
      "y": 9,
      "z": -8,
      "name": "Rock_Stone"
    },
    {
      "x": -20,
      "y": 10,
      "z": -8,
      "name": "Rock_Stone"
    },
    {
      "x": -20,
      "y": 11,
      "z": -8,
      "name": "Rock_Stone"
    },
    {
      "x": -20,
      "y": 12,
      "z": -8,
      "name": "Rock_Stone"
    },
    {
      "x": -20,
      "y": 13,
      "z": -8,
      "name": "Rock_Stone"
    },
    {
      "x": -20,
      "y": 2,
      "z": -7,
      "name": "Rock_Stone"
    },
    {
      "x": -20,
      "y": 3,
      "z": -7,
      "name": "Rock_Stone"
    },
    {
      "x": -20,
      "y": 4,
      "z": -7,
      "name": "Rock_Stone"
    },
    {
      "x": -20,
      "y": 5,
      "z": -7,
      "name": "Rock_Stone"
    },
    {
      "x": -20,
      "y": 6,
      "z": -7,
      "name": "Soil_Mud_Dry"
    },
    {
      "x": -20,
      "y": 7,
      "z": -7,
      "name": "Soil_Mud_Dry"
    },
    {
      "x": -20,
      "y": 8,
      "z": -7,
      "name": "Soil_Mud_Dry"
    },
    {
      "x": -20,
      "y": 9,
      "z": -7,
      "name": "Soil_Mud_Dry"
    },
    {
      "x": -20,
      "y": 10,
      "z": -7,
      "name": "Rock_Stone"
    },
    {
      "x": -20,
      "y": 11,
      "z": -7,
      "name": "Rock_Stone"
    },
    {
      "x": -20,
      "y": 12,
      "z": -7,
      "name": "Rock_Stone"
    },
    {
      "x": -20,
      "y": 13,
      "z": -7,
      "name": "Rock_Stone"
    },
    {
      "x": -20,
      "y": 2,
      "z": -6,
      "name": "Rock_Stone"
    },
    {
      "x": -20,
      "y": 3,
      "z": -6,
      "name": "Rock_Stone"
    },
    {
      "x": -20,
      "y": 4,
      "z": -6,
      "name": "Rock_Stone"
    },
    {
      "x": -20,
      "y": 5,
      "z": -6,
      "name": "Soil_Mud_Dry"
    },
    {
      "x": -20,
      "y": 6,
      "z": -6,
      "name": "Soil_Mud_Dry"
    },
    {
      "x": -20,
      "y": 7,
      "z": -6,
      "name": "Soil_Mud_Dry"
    },
    {
      "x": -20,
      "y": 8,
      "z": -6,
      "name": "Soil_Mud_Dry"
    },
    {
      "x": -20,
      "y": 9,
      "z": -6,
      "name": "Soil_Mud_Dry"
    },
    {
      "x": -20,
      "y": 10,
      "z": -6,
      "name": "Soil_Mud_Dry"
    },
    {
      "x": -20,
      "y": 11,
      "z": -6,
      "name": "Rock_Stone"
    },
    {
      "x": -20,
      "y": 12,
      "z": -6,
      "name": "Rock_Stone"
    },
    {
      "x": -20,
      "y": 13,
      "z": -6,
      "name": "Rock_Stone"
    },
    {
      "x": -20,
      "y": 2,
      "z": -5,
      "name": "Rock_Stone"
    },
    {
      "x": -20,
      "y": 3,
      "z": -5,
      "name": "Rock_Stone"
    },
    {
      "x": -20,
      "y": 4,
      "z": -5,
      "name": "Rock_Stone"
    },
    {
      "x": -20,
      "y": 5,
      "z": -5,
      "name": "Soil_Mud_Dry"
    },
    {
      "x": -20,
      "y": 6,
      "z": -5,
      "name": "Soil_Mud_Dry"
    },
    {
      "x": -20,
      "y": 7,
      "z": -5,
      "name": "Soil_Mud_Dry"
    },
    {
      "x": -20,
      "y": 8,
      "z": -5,
      "name": "Soil_Mud_Dry"
    },
    {
      "x": -20,
      "y": 9,
      "z": -5,
      "name": "Soil_Mud_Dry"
    },
    {
      "x": -20,
      "y": 10,
      "z": -5,
      "name": "Rock_Stone"
    },
    {
      "x": -20,
      "y": 11,
      "z": -5,
      "name": "Rock_Stone"
    },
    {
      "x": -20,
      "y": 12,
      "z": -5,
      "name": "Rock_Stone"
    },
    {
      "x": -20,
      "y": 13,
      "z": -5,
      "name": "Rock_Stone"
    },
    {
      "x": -20,
      "y": 3,
      "z": -4,
      "name": "Rock_Stone"
    },
    {
      "x": -20,
      "y": 4,
      "z": -4,
      "name": "Soil_Mud_Dry"
    },
    {
      "x": -20,
      "y": 5,
      "z": -4,
      "name": "Soil_Mud_Dry"
    },
    {
      "x": -20,
      "y": 6,
      "z": -4,
      "name": "Soil_Mud_Dry"
    },
    {
      "x": -20,
      "y": 7,
      "z": -4,
      "name": "Soil_Mud_Dry"
    },
    {
      "x": -20,
      "y": 8,
      "z": -4,
      "name": "Soil_Mud_Dry"
    },
    {
      "x": -20,
      "y": 9,
      "z": -4,
      "name": "Soil_Mud_Dry"
    },
    {
      "x": -20,
      "y": 10,
      "z": -4,
      "name": "Soil_Mud_Dry"
    },
    {
      "x": -20,
      "y": 11,
      "z": -4,
      "name": "Rock_Stone"
    },
    {
      "x": -20,
      "y": 12,
      "z": -4,
      "name": "Rock_Stone"
    },
    {
      "x": -20,
      "y": 13,
      "z": -4,
      "name": "Rock_Stone"
    },
    {
      "x": -20,
      "y": 3,
      "z": -3,
      "name": "Rock_Stone"
    },
    {
      "x": -20,
      "y": 4,
      "z": -3,
      "name": "Soil_Mud_Dry"
    },
    {
      "x": -20,
      "y": 5,
      "z": -3,
      "name": "Soil_Mud_Dry"
    },
    {
      "x": -20,
      "y": 6,
      "z": -3,
      "name": "Soil_Mud_Dry"
    },
    {
      "x": -20,
      "y": 7,
      "z": -3,
      "name": "Soil_Mud_Dry"
    },
    {
      "x": -20,
      "y": 8,
      "z": -3,
      "name": "Soil_Mud_Dry"
    },
    {
      "x": -20,
      "y": 9,
      "z": -3,
      "name": "Soil_Mud_Dry"
    },
    {
      "x": -20,
      "y": 10,
      "z": -3,
      "name": "Soil_Mud_Dry"
    },
    {
      "x": -20,
      "y": 11,
      "z": -3,
      "name": "Rock_Stone"
    },
    {
      "x": -20,
      "y": 12,
      "z": -3,
      "name": "Rock_Stone"
    },
    {
      "x": -20,
      "y": 3,
      "z": -2,
      "name": "Rock_Stone"
    },
    {
      "x": -20,
      "y": 4,
      "z": -2,
      "name": "Soil_Mud_Dry"
    },
    {
      "x": -20,
      "y": 5,
      "z": -2,
      "name": "Soil_Mud_Dry"
    },
    {
      "x": -20,
      "y": 6,
      "z": -2,
      "name": "Soil_Mud_Dry"
    },
    {
      "x": -20,
      "y": 7,
      "z": -2,
      "name": "Soil_Mud_Dry"
    },
    {
      "x": -20,
      "y": 8,
      "z": -2,
      "name": "Soil_Mud_Dry"
    },
    {
      "x": -20,
      "y": 9,
      "z": -2,
      "name": "Soil_Mud_Dry"
    },
    {
      "x": -20,
      "y": 10,
      "z": -2,
      "name": "Soil_Mud_Dry"
    },
    {
      "x": -20,
      "y": 11,
      "z": -2,
      "name": "Rock_Stone"
    },
    {
      "x": -20,
      "y": 4,
      "z": -1,
      "name": "Rock_Stone"
    },
    {
      "x": -20,
      "y": 5,
      "z": -1,
      "name": "Soil_Mud_Dry"
    },
    {
      "x": -20,
      "y": 6,
      "z": -1,
      "name": "Soil_Mud_Dry"
    },
    {
      "x": -20,
      "y": 7,
      "z": -1,
      "name": "Soil_Mud_Dry"
    },
    {
      "x": -20,
      "y": 8,
      "z": -1,
      "name": "Soil_Mud_Dry"
    },
    {
      "x": -20,
      "y": 9,
      "z": -1,
      "name": "Soil_Mud_Dry"
    },
    {
      "x": -20,
      "y": 10,
      "z": -1,
      "name": "Rock_Stone"
    },
    {
      "x": -19,
      "y": 2,
      "z": -10,
      "name": "Rock_Stone"
    },
    {
      "x": -19,
      "y": 3,
      "z": -10,
      "name": "Rock_Stone"
    },
    {
      "x": -19,
      "y": 4,
      "z": -10,
      "name": "Rock_Stone"
    },
    {
      "x": -19,
      "y": 5,
      "z": -10,
      "name": "Rock_Stone"
    },
    {
      "x": -19,
      "y": 11,
      "z": -10,
      "name": "Rock_Stone"
    },
    {
      "x": -19,
      "y": 1,
      "z": -9,
      "name": "Rock_Stone"
    },
    {
      "x": -19,
      "y": 2,
      "z": -9,
      "name": "Rock_Stone"
    },
    {
      "x": -19,
      "y": 3,
      "z": -9,
      "name": "Rock_Stone"
    },
    {
      "x": -19,
      "y": 4,
      "z": -9,
      "name": "Rock_Stone"
    },
    {
      "x": -19,
      "y": 5,
      "z": -9,
      "name": "Rock_Stone"
    },
    {
      "x": -19,
      "y": 6,
      "z": -9,
      "name": "Rock_Stone"
    },
    {
      "x": -19,
      "y": 7,
      "z": -9,
      "name": "Rock_Stone"
    },
    {
      "x": -19,
      "y": 8,
      "z": -9,
      "name": "Rock_Stone"
    },
    {
      "x": -19,
      "y": 9,
      "z": -9,
      "name": "Rock_Stone"
    },
    {
      "x": -19,
      "y": 10,
      "z": -9,
      "name": "Rock_Stone"
    },
    {
      "x": -19,
      "y": 11,
      "z": -9,
      "name": "Rock_Stone"
    },
    {
      "x": -19,
      "y": 12,
      "z": -9,
      "name": "Rock_Stone"
    },
    {
      "x": -19,
      "y": 1,
      "z": -8,
      "name": "Rock_Stone"
    },
    {
      "x": -19,
      "y": 2,
      "z": -8,
      "name": "Rock_Stone"
    },
    {
      "x": -19,
      "y": 3,
      "z": -8,
      "name": "Rock_Stone"
    },
    {
      "x": -19,
      "y": 4,
      "z": -8,
      "name": "Rock_Stone"
    },
    {
      "x": -19,
      "y": 5,
      "z": -8,
      "name": "Rock_Stone"
    },
    {
      "x": -19,
      "y": 6,
      "z": -8,
      "name": "Soil_Mud_Dry"
    },
    {
      "x": -19,
      "y": 7,
      "z": -8,
      "name": "Soil_Mud_Dry"
    },
    {
      "x": -19,
      "y": 8,
      "z": -8,
      "name": "Soil_Mud_Dry"
    },
    {
      "x": -19,
      "y": 9,
      "z": -8,
      "name": "Soil_Mud_Dry"
    },
    {
      "x": -19,
      "y": 10,
      "z": -8,
      "name": "Rock_Stone"
    },
    {
      "x": -19,
      "y": 11,
      "z": -8,
      "name": "Rock_Stone"
    },
    {
      "x": -19,
      "y": 12,
      "z": -8,
      "name": "Rock_Stone"
    },
    {
      "x": -19,
      "y": 13,
      "z": -8,
      "name": "Rock_Stone"
    },
    {
      "x": -19,
      "y": 1,
      "z": -7,
      "name": "Rock_Stone"
    },
    {
      "x": -19,
      "y": 2,
      "z": -7,
      "name": "Rock_Stone"
    },
    {
      "x": -19,
      "y": 3,
      "z": -7,
      "name": "Rock_Stone"
    },
    {
      "x": -19,
      "y": 4,
      "z": -7,
      "name": "Rock_Stone"
    },
    {
      "x": -19,
      "y": 5,
      "z": -7,
      "name": "Soil_Mud_Dry"
    },
    {
      "x": -19,
      "y": 6,
      "z": -7,
      "name": "Soil_Mud_Dry"
    },
    {
      "x": -19,
      "y": 7,
      "z": -7,
      "name": "Soil_Mud_Dry"
    },
    {
      "x": -19,
      "y": 8,
      "z": -7,
      "name": "Soil_Mud_Dry"
    },
    {
      "x": -19,
      "y": 9,
      "z": -7,
      "name": "Soil_Mud_Dry"
    },
    {
      "x": -19,
      "y": 10,
      "z": -7,
      "name": "Soil_Mud_Dry"
    },
    {
      "x": -19,
      "y": 11,
      "z": -7,
      "name": "Rock_Stone"
    },
    {
      "x": -19,
      "y": 12,
      "z": -7,
      "name": "Rock_Stone"
    },
    {
      "x": -19,
      "y": 13,
      "z": -7,
      "name": "Rock_Stone"
    },
    {
      "x": -19,
      "y": 0,
      "z": -6,
      "name": "Rock_Stone"
    },
    {
      "x": -19,
      "y": 1,
      "z": -6,
      "name": "Rock_Stone"
    },
    {
      "x": -19,
      "y": 2,
      "z": -6,
      "name": "Rock_Stone"
    },
    {
      "x": -19,
      "y": 3,
      "z": -6,
      "name": "Rock_Stone"
    },
    {
      "x": -19,
      "y": 4,
      "z": -6,
      "name": "Rock_Stone"
    },
    {
      "x": -19,
      "y": 5,
      "z": -6,
      "name": "Soil_Mud_Dry"
    },
    {
      "x": -19,
      "y": 6,
      "z": -6,
      "name": "Soil_Mud_Dry"
    },
    {
      "x": -19,
      "y": 7,
      "z": -6,
      "name": "Soil_Mud_Dry"
    },
    {
      "x": -19,
      "y": 8,
      "z": -6,
      "name": "Soil_Mud_Dry"
    },
    {
      "x": -19,
      "y": 9,
      "z": -6,
      "name": "Soil_Mud_Dry"
    },
    {
      "x": -19,
      "y": 10,
      "z": -6,
      "name": "Soil_Mud_Dry"
    },
    {
      "x": -19,
      "y": 11,
      "z": -6,
      "name": "Soil_Mud_Dry"
    },
    {
      "x": -19,
      "y": 12,
      "z": -6,
      "name": "Rock_Stone"
    },
    {
      "x": -19,
      "y": 13,
      "z": -6,
      "name": "Rock_Stone"
    },
    {
      "x": -19,
      "y": -1,
      "z": -5,
      "name": "Rock_Stone"
    },
    {
      "x": -19,
      "y": 0,
      "z": -5,
      "name": "Rock_Stone"
    },
    {
      "x": -19,
      "y": 1,
      "z": -5,
      "name": "Rock_Stone"
    },
    {
      "x": -19,
      "y": 2,
      "z": -5,
      "name": "Rock_Stone"
    },
    {
      "x": -19,
      "y": 3,
      "z": -5,
      "name": "Rock_Stone"
    },
    {
      "x": -19,
      "y": 4,
      "z": -5,
      "name": "Soil_Mud_Dry"
    },
    {
      "x": -19,
      "y": 5,
      "z": -5,
      "name": "Soil_Mud_Dry"
    },
    {
      "x": -19,
      "y": 6,
      "z": -5,
      "name": "Furniture_Village_Crate"
    },
    {
      "x": -19,
      "y": 7,
      "z": -5,
      "name": "Empty"
    },
    {
      "x": -19,
      "y": 8,
      "z": -5,
      "name": "Empty"
    },
    {
      "x": -19,
      "y": 9,
      "z": -5,
      "name": "Empty"
    },
    {
      "x": -19,
      "y": 10,
      "z": -5,
      "name": "Soil_Mud_Dry"
    },
    {
      "x": -19,
      "y": 11,
      "z": -5,
      "name": "Rock_Stone"
    },
    {
      "x": -19,
      "y": 12,
      "z": -5,
      "name": "Rock_Stone"
    },
    {
      "x": -19,
      "y": 13,
      "z": -5,
      "name": "Rock_Stone"
    },
    {
      "x": -19,
      "y": 1,
      "z": -4,
      "name": "Rock_Stone"
    },
    {
      "x": -19,
      "y": 2,
      "z": -4,
      "name": "Rock_Stone"
    },
    {
      "x": -19,
      "y": 3,
      "z": -4,
      "name": "Rock_Stone"
    },
    {
      "x": -19,
      "y": 4,
      "z": -4,
      "name": "Soil_Mud_Dry"
    },
    {
      "x": -19,
      "y": 5,
      "z": -4,
      "name": "Rock_Stone_Mossy"
    },
    {
      "x": -19,
      "y": 6,
      "z": -4,
      "name": "Furniture_Village_Crate"
    },
    {
      "x": -19,
      "y": 7,
      "z": -4,
      "name": "Empty"
    },
    {
      "x": -19,
      "y": 8,
      "z": -4,
      "name": "Empty"
    },
    {
      "x": -19,
      "y": 9,
      "z": -4,
      "name": "Empty"
    },
    {
      "x": -19,
      "y": 10,
      "z": -4,
      "name": "Empty"
    },
    {
      "x": -19,
      "y": 11,
      "z": -4,
      "name": "Empty"
    },
    {
      "x": -19,
      "y": 12,
      "z": -4,
      "name": "Rock_Stone"
    },
    {
      "x": -19,
      "y": 13,
      "z": -4,
      "name": "Rock_Stone"
    },
    {
      "x": -19,
      "y": 1,
      "z": -3,
      "name": "Soil_Mud_Dry"
    },
    {
      "x": -19,
      "y": 2,
      "z": -3,
      "name": "Soil_Mud_Dry"
    },
    {
      "x": -19,
      "y": 3,
      "z": -3,
      "name": "Rock_Stone"
    },
    {
      "x": -19,
      "y": 4,
      "z": -3,
      "name": "Soil_Mud_Dry"
    },
    {
      "x": -19,
      "y": 5,
      "z": -3,
      "name": "Plant_Moss_Block_Green"
    },
    {
      "x": -19,
      "y": 6,
      "z": -3,
      "name": "Plant_Moss_Rug_Green"
    },
    {
      "x": -19,
      "y": 7,
      "z": -3,
      "name": "Empty"
    },
    {
      "x": -19,
      "y": 8,
      "z": -3,
      "name": "Empty"
    },
    {
      "x": -19,
      "y": 9,
      "z": -3,
      "name": "Empty"
    },
    {
      "x": -19,
      "y": 10,
      "z": -3,
      "name": "Empty"
    },
    {
      "x": -19,
      "y": 11,
      "z": -3,
      "name": "Empty"
    },
    {
      "x": -19,
      "y": 12,
      "z": -3,
      "name": "Rock_Stone"
    },
    {
      "x": -19,
      "y": 1,
      "z": -2,
      "name": "Soil_Mud_Dry"
    },
    {
      "x": -19,
      "y": 2,
      "z": -2,
      "name": "Rock_Stone"
    },
    {
      "x": -19,
      "y": 3,
      "z": -2,
      "name": "Rock_Stone"
    },
    {
      "x": -19,
      "y": 4,
      "z": -2,
      "name": "Rock_Stone"
    },
    {
      "x": -19,
      "y": 5,
      "z": -2,
      "name": "Soil_Mud_Dry"
    },
    {
      "x": -19,
      "y": 6,
      "z": -2,
      "name": "Rock_Stone_Mossy"
    },
    {
      "x": -19,
      "y": 7,
      "z": -2,
      "name": "Soil_Mud_Dry"
    },
    {
      "x": -19,
      "y": 8,
      "z": -2,
      "name": "Soil_Mud_Dry"
    },
    {
      "x": -19,
      "y": 9,
      "z": -2,
      "name": "Soil_Mud_Dry"
    },
    {
      "x": -19,
      "y": 10,
      "z": -2,
      "name": "Rock_Stone"
    },
    {
      "x": -19,
      "y": 11,
      "z": -2,
      "name": "Rock_Stone"
    },
    {
      "x": -19,
      "y": 12,
      "z": -2,
      "name": "Rock_Stone"
    },
    {
      "x": -19,
      "y": 1,
      "z": -1,
      "name": "Rock_Stone"
    },
    {
      "x": -19,
      "y": 2,
      "z": -1,
      "name": "Rock_Stone"
    },
    {
      "x": -19,
      "y": 3,
      "z": -1,
      "name": "Rock_Stone"
    },
    {
      "x": -19,
      "y": 4,
      "z": -1,
      "name": "Rock_Stone"
    },
    {
      "x": -19,
      "y": 5,
      "z": -1,
      "name": "Rock_Stone"
    },
    {
      "x": -19,
      "y": 6,
      "z": -1,
      "name": "Rock_Stone_Mossy"
    },
    {
      "x": -19,
      "y": 7,
      "z": -1,
      "name": "Rock_Stone"
    },
    {
      "x": -19,
      "y": 8,
      "z": -1,
      "name": "Soil_Mud_Dry"
    },
    {
      "x": -19,
      "y": 9,
      "z": -1,
      "name": "Rock_Stone"
    },
    {
      "x": -19,
      "y": 10,
      "z": -1,
      "name": "Rock_Stone"
    },
    {
      "x": -19,
      "y": 11,
      "z": -1,
      "name": "Rock_Stone"
    },
    {
      "x": -19,
      "y": 3,
      "z": 0,
      "name": "Rock_Stone"
    },
    {
      "x": -19,
      "y": 4,
      "z": 0,
      "name": "Rock_Stone"
    },
    {
      "x": -19,
      "y": 5,
      "z": 0,
      "name": "Rock_Stone"
    },
    {
      "x": -19,
      "y": 6,
      "z": 0,
      "name": "Rock_Stone"
    },
    {
      "x": -19,
      "y": 7,
      "z": 0,
      "name": "Rock_Stone"
    },
    {
      "x": -19,
      "y": 8,
      "z": 0,
      "name": "Rock_Stone"
    },
    {
      "x": -19,
      "y": 9,
      "z": 0,
      "name": "Rock_Stone"
    },
    {
      "x": -19,
      "y": 3,
      "z": 1,
      "name": "Rock_Stone"
    },
    {
      "x": -19,
      "y": 4,
      "z": 1,
      "name": "Rock_Stone"
    },
    {
      "x": -19,
      "y": 8,
      "z": 1,
      "name": "Rock_Stone"
    },
    {
      "x": -18,
      "y": 1,
      "z": -11,
      "name": "Rock_Stone"
    },
    {
      "x": -18,
      "y": 2,
      "z": -11,
      "name": "Rock_Stone"
    },
    {
      "x": -18,
      "y": 3,
      "z": -11,
      "name": "Rock_Stone"
    },
    {
      "x": -18,
      "y": 4,
      "z": -11,
      "name": "Rock_Stone"
    },
    {
      "x": -18,
      "y": 5,
      "z": -11,
      "name": "Rock_Stone"
    },
    {
      "x": -18,
      "y": 0,
      "z": -10,
      "name": "Rock_Stone"
    },
    {
      "x": -18,
      "y": 1,
      "z": -10,
      "name": "Rock_Stone"
    },
    {
      "x": -18,
      "y": 2,
      "z": -10,
      "name": "Rock_Stone"
    },
    {
      "x": -18,
      "y": 3,
      "z": -10,
      "name": "Rock_Stone"
    },
    {
      "x": -18,
      "y": 4,
      "z": -10,
      "name": "Rock_Stone"
    },
    {
      "x": -18,
      "y": 5,
      "z": -10,
      "name": "Rock_Stone"
    },
    {
      "x": -18,
      "y": 6,
      "z": -10,
      "name": "Rock_Stone"
    },
    {
      "x": -18,
      "y": 7,
      "z": -10,
      "name": "Soil_Clay"
    },
    {
      "x": -18,
      "y": 8,
      "z": -10,
      "name": "Soil_Clay"
    },
    {
      "x": -18,
      "y": 10,
      "z": -10,
      "name": "Rock_Stone"
    },
    {
      "x": -18,
      "y": 11,
      "z": -10,
      "name": "Rock_Stone"
    },
    {
      "x": -18,
      "y": 12,
      "z": -10,
      "name": "Rock_Stone"
    },
    {
      "x": -18,
      "y": 0,
      "z": -9,
      "name": "Rock_Stone"
    },
    {
      "x": -18,
      "y": 1,
      "z": -9,
      "name": "Rock_Stone"
    },
    {
      "x": -18,
      "y": 2,
      "z": -9,
      "name": "Rock_Stone"
    },
    {
      "x": -18,
      "y": 3,
      "z": -9,
      "name": "Rock_Stone"
    },
    {
      "x": -18,
      "y": 4,
      "z": -9,
      "name": "Rock_Stone"
    },
    {
      "x": -18,
      "y": 5,
      "z": -9,
      "name": "Rock_Stone"
    },
    {
      "x": -18,
      "y": 6,
      "z": -9,
      "name": "Soil_Clay"
    },
    {
      "x": -18,
      "y": 7,
      "z": -9,
      "name": "Soil_Clay"
    },
    {
      "x": -18,
      "y": 8,
      "z": -9,
      "name": "Soil_Clay"
    },
    {
      "x": -18,
      "y": 9,
      "z": -9,
      "name": "Soil_Clay"
    },
    {
      "x": -18,
      "y": 10,
      "z": -9,
      "name": "Soil_Clay"
    },
    {
      "x": -18,
      "y": 11,
      "z": -9,
      "name": "Rock_Stone"
    },
    {
      "x": -18,
      "y": 12,
      "z": -9,
      "name": "Rock_Stone"
    },
    {
      "x": -18,
      "y": 0,
      "z": -8,
      "name": "Rock_Stone"
    },
    {
      "x": -18,
      "y": 1,
      "z": -8,
      "name": "Rock_Stone"
    },
    {
      "x": -18,
      "y": 2,
      "z": -8,
      "name": "Rock_Stone"
    },
    {
      "x": -18,
      "y": 3,
      "z": -8,
      "name": "Rock_Stone"
    },
    {
      "x": -18,
      "y": 4,
      "z": -8,
      "name": "Rock_Stone"
    },
    {
      "x": -18,
      "y": 5,
      "z": -8,
      "name": "Rock_Stone"
    },
    {
      "x": -18,
      "y": 6,
      "z": -8,
      "name": "Rock_Stone"
    },
    {
      "x": -18,
      "y": 7,
      "z": -8,
      "name": "Soil_Clay"
    },
    {
      "x": -18,
      "y": 8,
      "z": -8,
      "name": "Soil_Clay"
    },
    {
      "x": -18,
      "y": 9,
      "z": -8,
      "name": "Soil_Mud_Dry"
    },
    {
      "x": -18,
      "y": 10,
      "z": -8,
      "name": "Soil_Mud_Dry"
    },
    {
      "x": -18,
      "y": 11,
      "z": -8,
      "name": "Soil_Clay"
    },
    {
      "x": -18,
      "y": 12,
      "z": -8,
      "name": "Rock_Stone"
    },
    {
      "x": -18,
      "y": 13,
      "z": -8,
      "name": "Rock_Stone"
    },
    {
      "x": -18,
      "y": -1,
      "z": -7,
      "name": "Rock_Stone"
    },
    {
      "x": -18,
      "y": 0,
      "z": -7,
      "name": "Rock_Stone"
    },
    {
      "x": -18,
      "y": 1,
      "z": -7,
      "name": "Rock_Stone"
    },
    {
      "x": -18,
      "y": 2,
      "z": -7,
      "name": "Rock_Stone"
    },
    {
      "x": -18,
      "y": 3,
      "z": -7,
      "name": "Rock_Stone"
    },
    {
      "x": -18,
      "y": 4,
      "z": -7,
      "name": "Rock_Stone"
    },
    {
      "x": -18,
      "y": 5,
      "z": -7,
      "name": "Soil_Gravel"
    },
    {
      "x": -18,
      "y": 6,
      "z": -7,
      "name": "Empty"
    },
    {
      "x": -18,
      "y": 7,
      "z": -7,
      "name": "Empty"
    },
    {
      "x": -18,
      "y": 8,
      "z": -7,
      "name": "Empty"
    },
    {
      "x": -18,
      "y": 9,
      "z": -7,
      "name": "Soil_Mud_Dry"
    },
    {
      "x": -18,
      "y": 10,
      "z": -7,
      "name": "Soil_Mud_Dry"
    },
    {
      "x": -18,
      "y": 11,
      "z": -7,
      "name": "Soil_Mud_Dry"
    },
    {
      "x": -18,
      "y": 12,
      "z": -7,
      "name": "Rock_Stone"
    },
    {
      "x": -18,
      "y": 13,
      "z": -7,
      "name": "Rock_Stone"
    },
    {
      "x": -18,
      "y": -1,
      "z": -6,
      "name": "Rock_Stone"
    },
    {
      "x": -18,
      "y": 0,
      "z": -6,
      "name": "Rock_Stone"
    },
    {
      "x": -18,
      "y": 1,
      "z": -6,
      "name": "Soil_Mud_Dry"
    },
    {
      "x": -18,
      "y": 2,
      "z": -6,
      "name": "Soil_Mud_Dry"
    },
    {
      "x": -18,
      "y": 3,
      "z": -6,
      "name": "Rock_Stone"
    },
    {
      "x": -18,
      "y": 4,
      "z": -6,
      "name": "Rock_Stone"
    },
    {
      "x": -18,
      "y": 5,
      "z": -6,
      "name": "Rock_Stone_Mossy"
    },
    {
      "x": -18,
      "y": 6,
      "z": -6,
      "name": "Furniture_Temple_Wind_Pot"
    },
    {
      "x": -18,
      "y": 7,
      "z": -6,
      "name": "Furniture_Temple_Wind_Pot",
      "filler": 1024
    },
    {
      "x": -18,
      "y": 8,
      "z": -6,
      "name": "Empty"
    },
    {
      "x": -18,
      "y": 9,
      "z": -6,
      "name": "Soil_Mud_Dry"
    },
    {
      "x": -18,
      "y": 10,
      "z": -6,
      "name": "Soil_Mud_Dry"
    },
    {
      "x": -18,
      "y": 11,
      "z": -6,
      "name": "Soil_Mud_Dry"
    },
    {
      "x": -18,
      "y": 12,
      "z": -6,
      "name": "Rock_Stone"
    },
    {
      "x": -18,
      "y": 13,
      "z": -6,
      "name": "Rock_Stone"
    },
    {
      "x": -18,
      "y": -2,
      "z": -5,
      "name": "Rock_Stone"
    },
    {
      "x": -18,
      "y": -1,
      "z": -5,
      "name": "Rock_Stone"
    },
    {
      "x": -18,
      "y": 0,
      "z": -5,
      "name": "Rock_Stone"
    },
    {
      "x": -18,
      "y": 1,
      "z": -5,
      "name": "Soil_Mud_Dry"
    },
    {
      "x": -18,
      "y": 2,
      "z": -5,
      "name": "Soil_Mud_Dry"
    },
    {
      "x": -18,
      "y": 3,
      "z": -5,
      "name": "Soil_Mud_Dry"
    },
    {
      "x": -18,
      "y": 4,
      "z": -5,
      "name": "Rock_Stone"
    },
    {
      "x": -18,
      "y": 5,
      "z": -5,
      "name": "Rock_Stone_Mossy"
    },
    {
      "x": -18,
      "y": 6,
      "z": -5,
      "name": "Furniture_Village_Pot"
    },
    {
      "x": -18,
      "y": 7,
      "z": -5,
      "name": "Empty"
    },
    {
      "x": -18,
      "y": 8,
      "z": -5,
      "name": "Empty"
    },
    {
      "x": -18,
      "y": 9,
      "z": -5,
      "name": "Plant_Roots_Cave_Small",
      "rotation": 8
    },
    {
      "x": -18,
      "y": 10,
      "z": -5,
      "name": "Soil_Mud_Dry"
    },
    {
      "x": -18,
      "y": 11,
      "z": -5,
      "name": "Soil_Mud_Dry"
    },
    {
      "x": -18,
      "y": 12,
      "z": -5,
      "name": "Rock_Stone"
    },
    {
      "x": -18,
      "y": 13,
      "z": -5,
      "name": "Rock_Stone"
    },
    {
      "x": -18,
      "y": -2,
      "z": -4,
      "name": "Rock_Stone"
    },
    {
      "x": -18,
      "y": -1,
      "z": -4,
      "name": "Rock_Stone"
    },
    {
      "x": -18,
      "y": 0,
      "z": -4,
      "name": "Rock_Stone"
    },
    {
      "x": -18,
      "y": 1,
      "z": -4,
      "name": "Soil_Mud_Dry"
    },
    {
      "x": -18,
      "y": 2,
      "z": -4,
      "name": "Soil_Mud_Dry"
    },
    {
      "x": -18,
      "y": 3,
      "z": -4,
      "name": "Soil_Mud_Dry"
    },
    {
      "x": -18,
      "y": 4,
      "z": -4,
      "name": "Soil_Mud_Dry"
    },
    {
      "x": -18,
      "y": 5,
      "z": -4,
      "name": "Plant_Moss_Block_Green"
    },
    {
      "x": -18,
      "y": 6,
      "z": -4,
      "name": "Plant_Moss_Short_Green"
    },
    {
      "x": -18,
      "y": 7,
      "z": -4,
      "name": "Empty"
    },
    {
      "x": -18,
      "y": 8,
      "z": -4,
      "name": "Empty"
    },
    {
      "x": -18,
      "y": 9,
      "z": -4,
      "name": "Empty"
    },
    {
      "x": -18,
      "y": 10,
      "z": -4,
      "name": "Empty"
    },
    {
      "x": -18,
      "y": 11,
      "z": -4,
      "name": "Empty"
    },
    {
      "x": -18,
      "y": 12,
      "z": -4,
      "name": "Rock_Stone"
    },
    {
      "x": -18,
      "y": 13,
      "z": -4,
      "name": "Rock_Stone"
    },
    {
      "x": -18,
      "y": 0,
      "z": -3,
      "name": "Soil_Mud_Dry"
    },
    {
      "x": -18,
      "y": 1,
      "z": -3,
      "name": "Empty"
    },
    {
      "x": -18,
      "y": 2,
      "z": -3,
      "name": "Empty"
    },
    {
      "x": -18,
      "y": 3,
      "z": -3,
      "name": "Rock_Stone_Mossy"
    },
    {
      "x": -18,
      "y": 4,
      "z": -3,
      "name": "Rock_Stone"
    },
    {
      "x": -18,
      "y": 5,
      "z": -3,
      "name": "Plant_Moss_Block_Green"
    },
    {
      "x": -18,
      "y": 6,
      "z": -3,
      "name": "Plant_Moss_Green"
    },
    {
      "x": -18,
      "y": 7,
      "z": -3,
      "name": "Empty"
    },
    {
      "x": -18,
      "y": 8,
      "z": -3,
      "name": "Empty"
    },
    {
      "x": -18,
      "y": 9,
      "z": -3,
      "name": "Empty"
    },
    {
      "x": -18,
      "y": 10,
      "z": -3,
      "name": "Empty"
    },
    {
      "x": -18,
      "y": 11,
      "z": -3,
      "name": "Empty"
    },
    {
      "x": -18,
      "y": 12,
      "z": -3,
      "name": "Rock_Stone"
    },
    {
      "x": -18,
      "y": 13,
      "z": -3,
      "name": "Rock_Stone"
    },
    {
      "x": -18,
      "y": 0,
      "z": -2,
      "name": "Soil_Mud_Dry"
    },
    {
      "x": -18,
      "y": 1,
      "z": -2,
      "name": "Empty"
    },
    {
      "x": -18,
      "y": 2,
      "z": -2,
      "name": "Empty"
    },
    {
      "x": -18,
      "y": 3,
      "z": -2,
      "name": "Empty"
    },
    {
      "x": -18,
      "y": 4,
      "z": -2,
      "name": "Rock_Stone_Mossy"
    },
    {
      "x": -18,
      "y": 5,
      "z": -2,
      "name": "Plant_Moss_Block_Green"
    },
    {
      "x": -18,
      "y": 6,
      "z": -2,
      "name": "Plant_Moss_Rug_Green"
    },
    {
      "x": -18,
      "y": 7,
      "z": -2,
      "name": "Empty"
    },
    {
      "x": -18,
      "y": 8,
      "z": -2,
      "name": "Empty"
    },
    {
      "x": -18,
      "y": 9,
      "z": -2,
      "name": "Empty"
    },
    {
      "x": -18,
      "y": 10,
      "z": -2,
      "name": "Empty"
    },
    {
      "x": -18,
      "y": 11,
      "z": -2,
      "name": "Rock_Stone"
    },
    {
      "x": -18,
      "y": 12,
      "z": -2,
      "name": "Rock_Stone"
    },
    {
      "x": -18,
      "y": 13,
      "z": -2,
      "name": "Rock_Stone"
    },
    {
      "x": -18,
      "y": 0,
      "z": -1,
      "name": "Soil_Dirt"
    },
    {
      "x": -18,
      "y": 1,
      "z": -1,
      "name": "Empty"
    },
    {
      "x": -18,
      "y": 2,
      "z": -1,
      "name": "Empty"
    },
    {
      "x": -18,
      "y": 3,
      "z": -1,
      "name": "Empty"
    },
    {
      "x": -18,
      "y": 4,
      "z": -1,
      "name": "Plant_Moss_Cave_Green",
      "rotation": 8
    },
    {
      "x": -18,
      "y": 5,
      "z": -1,
      "name": "Plant_Moss_Block_Green"
    },
    {
      "x": -18,
      "y": 6,
      "z": -1,
      "name": "Plant_Moss_Rug_Green"
    },
    {
      "x": -18,
      "y": 7,
      "z": -1,
      "name": "Empty"
    },
    {
      "x": -18,
      "y": 8,
      "z": -1,
      "name": "Empty"
    },
    {
      "x": -18,
      "y": 9,
      "z": -1,
      "name": "Rock_Stone"
    },
    {
      "x": -18,
      "y": 10,
      "z": -1,
      "name": "Rock_Stone"
    },
    {
      "x": -18,
      "y": 11,
      "z": -1,
      "name": "Rock_Stone"
    },
    {
      "x": -18,
      "y": 0,
      "z": 0,
      "name": "Soil_Dirt"
    },
    {
      "x": -18,
      "y": 1,
      "z": 0,
      "name": "Empty"
    },
    {
      "x": -18,
      "y": 2,
      "z": 0,
      "name": "Empty"
    },
    {
      "x": -18,
      "y": 3,
      "z": 0,
      "name": "Empty"
    },
    {
      "x": -18,
      "y": 4,
      "z": 0,
      "name": "Empty"
    },
    {
      "x": -18,
      "y": 5,
      "z": 0,
      "name": "Plant_Moss_Wall_Green"
    },
    {
      "x": -18,
      "y": 6,
      "z": 0,
      "name": "Empty"
    },
    {
      "x": -18,
      "y": 7,
      "z": 0,
      "name": "Empty"
    },
    {
      "x": -18,
      "y": 8,
      "z": 0,
      "name": "Empty"
    },
    {
      "x": -18,
      "y": 9,
      "z": 0,
      "name": "Rock_Stone"
    },
    {
      "x": -18,
      "y": 0,
      "z": 1,
      "name": "Soil_Dirt"
    },
    {
      "x": -18,
      "y": 1,
      "z": 1,
      "name": "Empty"
    },
    {
      "x": -18,
      "y": 2,
      "z": 1,
      "name": "Empty"
    },
    {
      "x": -18,
      "y": 3,
      "z": 1,
      "name": "Empty"
    },
    {
      "x": -18,
      "y": 4,
      "z": 1,
      "name": "Empty"
    },
    {
      "x": -18,
      "y": 5,
      "z": 1,
      "name": "Empty"
    },
    {
      "x": -18,
      "y": 6,
      "z": 1,
      "name": "Empty"
    },
    {
      "x": -18,
      "y": 7,
      "z": 1,
      "name": "Rock_Stone"
    },
    {
      "x": -18,
      "y": 8,
      "z": 1,
      "name": "Rock_Stone"
    },
    {
      "x": -18,
      "y": 9,
      "z": 1,
      "name": "Rock_Stone"
    },
    {
      "x": -18,
      "y": 0,
      "z": 2,
      "name": "Soil_Dirt"
    },
    {
      "x": -18,
      "y": 1,
      "z": 2,
      "name": "Empty"
    },
    {
      "x": -18,
      "y": 2,
      "z": 2,
      "name": "Empty"
    },
    {
      "x": -18,
      "y": 3,
      "z": 2,
      "name": "Rock_Stone_Stalactite_Large",
      "filler": 31744,
      "rotation": 8
    },
    {
      "x": -18,
      "y": 4,
      "z": 2,
      "name": "Rock_Stone_Stalactite_Large",
      "rotation": 8
    },
    {
      "x": -18,
      "y": 5,
      "z": 2,
      "name": "Rock_Stone"
    },
    {
      "x": -18,
      "y": 6,
      "z": 2,
      "name": "Rock_Stone"
    },
    {
      "x": -18,
      "y": 7,
      "z": 2,
      "name": "Rock_Stone"
    },
    {
      "x": -18,
      "y": 6,
      "z": 3,
      "name": "Rock_Stone"
    },
    {
      "x": -17,
      "y": 0,
      "z": -12,
      "name": "Rock_Stone"
    },
    {
      "x": -17,
      "y": 1,
      "z": -12,
      "name": "Rock_Stone"
    },
    {
      "x": -17,
      "y": 2,
      "z": -12,
      "name": "Rock_Stone"
    },
    {
      "x": -17,
      "y": 3,
      "z": -12,
      "name": "Rock_Stone"
    },
    {
      "x": -17,
      "y": 4,
      "z": -12,
      "name": "Rock_Stone"
    },
    {
      "x": -17,
      "y": 5,
      "z": -12,
      "name": "Rock_Stone"
    },
    {
      "x": -17,
      "y": 6,
      "z": -12,
      "name": "Rock_Stone"
    },
    {
      "x": -17,
      "y": 10,
      "z": -12,
      "name": "Rock_Stone"
    },
    {
      "x": -17,
      "y": 0,
      "z": -11,
      "name": "Rock_Stone"
    },
    {
      "x": -17,
      "y": 1,
      "z": -11,
      "name": "Rock_Stone"
    },
    {
      "x": -17,
      "y": 2,
      "z": -11,
      "name": "Rock_Stone"
    },
    {
      "x": -17,
      "y": 3,
      "z": -11,
      "name": "Rock_Stone"
    },
    {
      "x": -17,
      "y": 4,
      "z": -11,
      "name": "Rock_Stone"
    },
    {
      "x": -17,
      "y": 5,
      "z": -11,
      "name": "Rock_Stone"
    },
    {
      "x": -17,
      "y": 6,
      "z": -11,
      "name": "Rock_Stone"
    },
    {
      "x": -17,
      "y": 7,
      "z": -11,
      "name": "Soil_Clay"
    },
    {
      "x": -17,
      "y": 8,
      "z": -11,
      "name": "Soil_Clay"
    },
    {
      "x": -17,
      "y": 9,
      "z": -11,
      "name": "Rock_Stone"
    },
    {
      "x": -17,
      "y": 10,
      "z": -11,
      "name": "Rock_Stone"
    },
    {
      "x": -17,
      "y": 11,
      "z": -11,
      "name": "Rock_Stone"
    },
    {
      "x": -17,
      "y": -1,
      "z": -10,
      "name": "Rock_Stone"
    },
    {
      "x": -17,
      "y": 0,
      "z": -10,
      "name": "Rock_Stone"
    },
    {
      "x": -17,
      "y": 1,
      "z": -10,
      "name": "Rock_Stone"
    },
    {
      "x": -17,
      "y": 2,
      "z": -10,
      "name": "Rock_Stone"
    },
    {
      "x": -17,
      "y": 3,
      "z": -10,
      "name": "Rock_Stone"
    },
    {
      "x": -17,
      "y": 4,
      "z": -10,
      "name": "Rock_Stone"
    },
    {
      "x": -17,
      "y": 5,
      "z": -10,
      "name": "Rock_Stone"
    },
    {
      "x": -17,
      "y": 6,
      "z": -10,
      "name": "Soil_Clay"
    },
    {
      "x": -17,
      "y": 7,
      "z": -10,
      "name": "Soil_Clay"
    },
    {
      "x": -17,
      "y": 8,
      "z": -10,
      "name": "Soil_Clay"
    },
    {
      "x": -17,
      "y": 9,
      "z": -10,
      "name": "Soil_Clay"
    },
    {
      "x": -17,
      "y": 10,
      "z": -10,
      "name": "Soil_Clay"
    },
    {
      "x": -17,
      "y": 11,
      "z": -10,
      "name": "Rock_Stone"
    },
    {
      "x": -17,
      "y": 12,
      "z": -10,
      "name": "Rock_Stone"
    },
    {
      "x": -17,
      "y": -1,
      "z": -9,
      "name": "Rock_Stone"
    },
    {
      "x": -17,
      "y": 0,
      "z": -9,
      "name": "Rock_Stone"
    },
    {
      "x": -17,
      "y": 1,
      "z": -9,
      "name": "Rock_Stone"
    },
    {
      "x": -17,
      "y": 2,
      "z": -9,
      "name": "Rock_Stone"
    },
    {
      "x": -17,
      "y": 3,
      "z": -9,
      "name": "Rock_Stone"
    },
    {
      "x": -17,
      "y": 4,
      "z": -9,
      "name": "Rock_Stone"
    },
    {
      "x": -17,
      "y": 5,
      "z": -9,
      "name": "Soil_Clay"
    },
    {
      "x": -17,
      "y": 6,
      "z": -9,
      "name": "Soil_Clay"
    },
    {
      "x": -17,
      "y": 7,
      "z": -9,
      "name": "Soil_Clay"
    },
    {
      "x": -17,
      "y": 8,
      "z": -9,
      "name": "Soil_Clay"
    },
    {
      "x": -17,
      "y": 9,
      "z": -9,
      "name": "Soil_Clay"
    },
    {
      "x": -17,
      "y": 10,
      "z": -9,
      "name": "Soil_Clay"
    },
    {
      "x": -17,
      "y": 11,
      "z": -9,
      "name": "Soil_Clay"
    },
    {
      "x": -17,
      "y": 12,
      "z": -9,
      "name": "Rock_Stone"
    },
    {
      "x": -17,
      "y": 13,
      "z": -9,
      "name": "Rock_Stone"
    },
    {
      "x": -17,
      "y": -1,
      "z": -8,
      "name": "Rock_Stone"
    },
    {
      "x": -17,
      "y": 0,
      "z": -8,
      "name": "Rock_Stone"
    },
    {
      "x": -17,
      "y": 1,
      "z": -8,
      "name": "Rock_Stone"
    },
    {
      "x": -17,
      "y": 2,
      "z": -8,
      "name": "Rock_Stone"
    },
    {
      "x": -17,
      "y": 3,
      "z": -8,
      "name": "Rock_Stone"
    },
    {
      "x": -17,
      "y": 4,
      "z": -8,
      "name": "Rock_Stone"
    },
    {
      "x": -17,
      "y": 5,
      "z": -8,
      "name": "Soil_Gravel"
    },
    {
      "x": -17,
      "y": 6,
      "z": -8,
      "name": "Empty"
    },
    {
      "x": -17,
      "y": 7,
      "z": -8,
      "name": "Empty"
    },
    {
      "x": -17,
      "y": 8,
      "z": -8,
      "name": "Soil_Clay"
    },
    {
      "x": -17,
      "y": 9,
      "z": -8,
      "name": "Soil_Clay"
    },
    {
      "x": -17,
      "y": 10,
      "z": -8,
      "name": "Soil_Clay"
    },
    {
      "x": -17,
      "y": 11,
      "z": -8,
      "name": "Soil_Clay"
    },
    {
      "x": -17,
      "y": 12,
      "z": -8,
      "name": "Soil_Clay"
    },
    {
      "x": -17,
      "y": 13,
      "z": -8,
      "name": "Rock_Stone"
    },
    {
      "x": -17,
      "y": -2,
      "z": -7,
      "name": "Rock_Stone"
    },
    {
      "x": -17,
      "y": -1,
      "z": -7,
      "name": "Rock_Stone"
    },
    {
      "x": -17,
      "y": 0,
      "z": -7,
      "name": "Rock_Stone"
    },
    {
      "x": -17,
      "y": 1,
      "z": -7,
      "name": "Rock_Stone"
    },
    {
      "x": -17,
      "y": 2,
      "z": -7,
      "name": "Rock_Stone"
    },
    {
      "x": -17,
      "y": 3,
      "z": -7,
      "name": "Rock_Stone"
    },
    {
      "x": -17,
      "y": 4,
      "z": -7,
      "name": "Rock_Stone"
    },
    {
      "x": -17,
      "y": 5,
      "z": -7,
      "name": "Soil_Gravel"
    },
    {
      "x": -17,
      "y": 6,
      "z": -7,
      "name": "Furniture_Tavern_Barrel"
    },
    {
      "x": -17,
      "y": 7,
      "z": -7,
      "name": "Empty"
    },
    {
      "x": -17,
      "y": 8,
      "z": -7,
      "name": "Empty"
    },
    {
      "x": -17,
      "y": 9,
      "z": -7,
      "name": "Soil_Mud_Dry"
    },
    {
      "x": -17,
      "y": 10,
      "z": -7,
      "name": "Soil_Mud_Dry"
    },
    {
      "x": -17,
      "y": 11,
      "z": -7,
      "name": "Soil_Clay"
    },
    {
      "x": -17,
      "y": 12,
      "z": -7,
      "name": "Rock_Stone"
    },
    {
      "x": -17,
      "y": 13,
      "z": -7,
      "name": "Rock_Stone"
    },
    {
      "x": -17,
      "y": -2,
      "z": -6,
      "name": "Rock_Stone"
    },
    {
      "x": -17,
      "y": -1,
      "z": -6,
      "name": "Rock_Stone"
    },
    {
      "x": -17,
      "y": 0,
      "z": -6,
      "name": "Soil_Mud_Dry"
    },
    {
      "x": -17,
      "y": 1,
      "z": -6,
      "name": "Plant_Crop_Mushroom_Block_Brown"
    },
    {
      "x": -17,
      "y": 2,
      "z": -6,
      "name": "Empty"
    },
    {
      "x": -17,
      "y": 3,
      "z": -6,
      "name": "Rock_Stone"
    },
    {
      "x": -17,
      "y": 4,
      "z": -6,
      "name": "Rock_Stone"
    },
    {
      "x": -17,
      "y": 5,
      "z": -6,
      "name": "Soil_Gravel"
    },
    {
      "x": -17,
      "y": 6,
      "z": -6,
      "name": "Furniture_Temple_Dark_Pot"
    },
    {
      "x": -17,
      "y": 7,
      "z": -6,
      "name": "Empty"
    },
    {
      "x": -17,
      "y": 8,
      "z": -6,
      "name": "Empty"
    },
    {
      "x": -17,
      "y": 9,
      "z": -6,
      "name": "Empty"
    },
    {
      "x": -17,
      "y": 10,
      "z": -6,
      "name": "Empty"
    },
    {
      "x": -17,
      "y": 11,
      "z": -6,
      "name": "Soil_Mud_Dry"
    },
    {
      "x": -17,
      "y": 12,
      "z": -6,
      "name": "Rock_Stone"
    },
    {
      "x": -17,
      "y": 13,
      "z": -6,
      "name": "Rock_Stone"
    },
    {
      "x": -17,
      "y": -2,
      "z": -5,
      "name": "Rock_Stone"
    },
    {
      "x": -17,
      "y": -1,
      "z": -5,
      "name": "Rock_Stone"
    },
    {
      "x": -17,
      "y": 0,
      "z": -5,
      "name": "Soil_Mud_Dry"
    },
    {
      "x": -17,
      "y": 1,
      "z": -5,
      "name": "Empty"
    },
    {
      "x": -17,
      "y": 2,
      "z": -5,
      "name": "Empty"
    },
    {
      "x": -17,
      "y": 3,
      "z": -5,
      "name": "Empty"
    },
    {
      "x": -17,
      "y": 4,
      "z": -5,
      "name": "Rock_Stone"
    },
    {
      "x": -17,
      "y": 5,
      "z": -5,
      "name": "Rock_Stone_Mossy"
    },
    {
      "x": -17,
      "y": 6,
      "z": -5,
      "name": "Furniture_Human_Ruins_Pot_Small"
    },
    {
      "x": -17,
      "y": 7,
      "z": -5,
      "name": "Empty"
    },
    {
      "x": -17,
      "y": 8,
      "z": -5,
      "name": "Empty"
    },
    {
      "x": -17,
      "y": 9,
      "z": -5,
      "name": "Empty"
    },
    {
      "x": -17,
      "y": 10,
      "z": -5,
      "name": "Empty"
    },
    {
      "x": -17,
      "y": 11,
      "z": -5,
      "name": "Empty"
    },
    {
      "x": -17,
      "y": 12,
      "z": -5,
      "name": "Rock_Stone"
    },
    {
      "x": -17,
      "y": 13,
      "z": -5,
      "name": "Rock_Stone"
    },
    {
      "x": -17,
      "y": -2,
      "z": -4,
      "name": "Rock_Stone"
    },
    {
      "x": -17,
      "y": -1,
      "z": -4,
      "name": "Rock_Stone"
    },
    {
      "x": -17,
      "y": 0,
      "z": -4,
      "name": "Soil_Mud_Dry"
    },
    {
      "x": -17,
      "y": 1,
      "z": -4,
      "name": "Plant_Crop_Mushroom_Cap_Brown",
      "components": {
        "Components": {
          "FarmingBlock": {}
        }
      }
    },
    {
      "x": -17,
      "y": 2,
      "z": -4,
      "name": "Empty"
    },
    {
      "x": -17,
      "y": 3,
      "z": -4,
      "name": "Empty"
    },
    {
      "x": -17,
      "y": 4,
      "z": -4,
      "name": "Rock_Stone"
    },
    {
      "x": -17,
      "y": 5,
      "z": -4,
      "name": "Plant_Moss_Block_Green"
    },
    {
      "x": -17,
      "y": 6,
      "z": -4,
      "name": "Plant_Moss_Rug_Green"
    },
    {
      "x": -17,
      "y": 7,
      "z": -4,
      "name": "Empty"
    },
    {
      "x": -17,
      "y": 8,
      "z": -4,
      "name": "Empty"
    },
    {
      "x": -17,
      "y": 9,
      "z": -4,
      "name": "Empty"
    },
    {
      "x": -17,
      "y": 10,
      "z": -4,
      "name": "Rock_Stone_Stalactite_Large",
      "filler": 31744,
      "rotation": 8
    },
    {
      "x": -17,
      "y": 11,
      "z": -4,
      "name": "Rock_Stone_Stalactite_Large",
      "rotation": 8
    },
    {
      "x": -17,
      "y": 12,
      "z": -4,
      "name": "Rock_Stone"
    },
    {
      "x": -17,
      "y": 13,
      "z": -4,
      "name": "Rock_Stone"
    },
    {
      "x": -17,
      "y": -1,
      "z": -3,
      "name": "Rock_Stone"
    },
    {
      "x": -17,
      "y": 0,
      "z": -3,
      "name": "Soil_Pathway"
    },
    {
      "x": -17,
      "y": 1,
      "z": -3,
      "name": "Empty"
    },
    {
      "x": -17,
      "y": 2,
      "z": -3,
      "name": "Empty"
    },
    {
      "x": -17,
      "y": 3,
      "z": -3,
      "name": "Empty"
    },
    {
      "x": -17,
      "y": 4,
      "z": -3,
      "name": "Rock_Stone_Mossy"
    },
    {
      "x": -17,
      "y": 5,
      "z": -3,
      "name": "Plant_Moss_Block_Green"
    },
    {
      "x": -17,
      "y": 6,
      "z": -3,
      "name": "Empty"
    },
    {
      "x": -17,
      "y": 7,
      "z": -3,
      "name": "Empty"
    },
    {
      "x": -17,
      "y": 8,
      "z": -3,
      "name": "Empty"
    },
    {
      "x": -17,
      "y": 9,
      "z": -3,
      "name": "Empty"
    },
    {
      "x": -17,
      "y": 10,
      "z": -3,
      "name": "Empty"
    },
    {
      "x": -17,
      "y": 11,
      "z": -3,
      "name": "Empty"
    },
    {
      "x": -17,
      "y": 12,
      "z": -3,
      "name": "Rock_Stone"
    },
    {
      "x": -17,
      "y": 13,
      "z": -3,
      "name": "Rock_Stone"
    },
    {
      "x": -17,
      "y": -1,
      "z": -2,
      "name": "Rock_Stone"
    },
    {
      "x": -17,
      "y": 0,
      "z": -2,
      "name": "Soil_Pathway"
    },
    {
      "x": -17,
      "y": 1,
      "z": -2,
      "name": "Empty"
    },
    {
      "x": -17,
      "y": 2,
      "z": -2,
      "name": "Empty"
    },
    {
      "x": -17,
      "y": 3,
      "z": -2,
      "name": "Empty"
    },
    {
      "x": -17,
      "y": 4,
      "z": -2,
      "name": "Empty"
    },
    {
      "x": -17,
      "y": 5,
      "z": -2,
      "name": "Plant_Moss_Block_Green"
    },
    {
      "x": -17,
      "y": 6,
      "z": -2,
      "name": "Plant_Moss_Rug_Green"
    },
    {
      "x": -17,
      "y": 7,
      "z": -2,
      "name": "Empty"
    },
    {
      "x": -17,
      "y": 8,
      "z": -2,
      "name": "Empty"
    },
    {
      "x": -17,
      "y": 9,
      "z": -2,
      "name": "Empty"
    },
    {
      "x": -17,
      "y": 10,
      "z": -2,
      "name": "Empty"
    },
    {
      "x": -17,
      "y": 11,
      "z": -2,
      "name": "Empty"
    },
    {
      "x": -17,
      "y": 12,
      "z": -2,
      "name": "Rock_Stone"
    },
    {
      "x": -17,
      "y": 13,
      "z": -2,
      "name": "Rock_Stone"
    },
    {
      "x": -17,
      "y": -1,
      "z": -1,
      "name": "Rock_Stone"
    },
    {
      "x": -17,
      "y": 0,
      "z": -1,
      "name": "Soil_Pathway"
    },
    {
      "x": -17,
      "y": 1,
      "z": -1,
      "name": "Empty"
    },
    {
      "x": -17,
      "y": 2,
      "z": -1,
      "name": "Empty"
    },
    {
      "x": -17,
      "y": 3,
      "z": -1,
      "name": "Empty"
    },
    {
      "x": -17,
      "y": 4,
      "z": -1,
      "name": "Empty"
    },
    {
      "x": -17,
      "y": 5,
      "z": -1,
      "name": "Plant_Moss_Wall_Green",
      "rotation": 1
    },
    {
      "x": -17,
      "y": 6,
      "z": -1,
      "name": "Empty"
    },
    {
      "x": -17,
      "y": 7,
      "z": -1,
      "name": "Empty"
    },
    {
      "x": -17,
      "y": 8,
      "z": -1,
      "name": "Empty"
    },
    {
      "x": -17,
      "y": 9,
      "z": -1,
      "name": "Empty"
    },
    {
      "x": -17,
      "y": 10,
      "z": -1,
      "name": "Empty"
    },
    {
      "x": -17,
      "y": 11,
      "z": -1,
      "name": "Empty"
    },
    {
      "x": -17,
      "y": -1,
      "z": 0,
      "name": "Rock_Stone"
    },
    {
      "x": -17,
      "y": 0,
      "z": 0,
      "name": "Soil_Dirt"
    },
    {
      "x": -17,
      "y": 1,
      "z": 0,
      "name": "Empty"
    },
    {
      "x": -17,
      "y": 2,
      "z": 0,
      "name": "Empty"
    },
    {
      "x": -17,
      "y": 3,
      "z": 0,
      "name": "Empty"
    },
    {
      "x": -17,
      "y": 4,
      "z": 0,
      "name": "Empty"
    },
    {
      "x": -17,
      "y": 5,
      "z": 0,
      "name": "Empty"
    },
    {
      "x": -17,
      "y": 6,
      "z": 0,
      "name": "Empty"
    },
    {
      "x": -17,
      "y": 7,
      "z": 0,
      "name": "Empty"
    },
    {
      "x": -17,
      "y": 8,
      "z": 0,
      "name": "Empty"
    },
    {
      "x": -17,
      "y": 9,
      "z": 0,
      "name": "Empty"
    },
    {
      "x": -17,
      "y": -1,
      "z": 1,
      "name": "Rock_Stone"
    },
    {
      "x": -17,
      "y": 0,
      "z": 1,
      "name": "Soil_Dirt"
    },
    {
      "x": -17,
      "y": 1,
      "z": 1,
      "name": "Empty"
    },
    {
      "x": -17,
      "y": 2,
      "z": 1,
      "name": "Empty"
    },
    {
      "x": -17,
      "y": 3,
      "z": 1,
      "name": "Empty"
    },
    {
      "x": -17,
      "y": 4,
      "z": 1,
      "name": "Empty"
    },
    {
      "x": -17,
      "y": 5,
      "z": 1,
      "name": "Empty"
    },
    {
      "x": -17,
      "y": 6,
      "z": 1,
      "name": "Empty"
    },
    {
      "x": -17,
      "y": 7,
      "z": 1,
      "name": "Rock_Stone"
    },
    {
      "x": -17,
      "y": 8,
      "z": 1,
      "name": "Rock_Stone"
    },
    {
      "x": -17,
      "y": 9,
      "z": 1,
      "name": "Rock_Stone"
    },
    {
      "x": -17,
      "y": 0,
      "z": 2,
      "name": "Soil_Dirt"
    },
    {
      "x": -17,
      "y": 1,
      "z": 2,
      "name": "Empty"
    },
    {
      "x": -17,
      "y": 2,
      "z": 2,
      "name": "Empty"
    },
    {
      "x": -17,
      "y": 3,
      "z": 2,
      "name": "Empty"
    },
    {
      "x": -17,
      "y": 4,
      "z": 2,
      "name": "Empty"
    },
    {
      "x": -17,
      "y": 5,
      "z": 2,
      "name": "Empty"
    },
    {
      "x": -17,
      "y": 6,
      "z": 2,
      "name": "Empty"
    },
    {
      "x": -17,
      "y": 7,
      "z": 2,
      "name": "Rock_Stone"
    },
    {
      "x": -17,
      "y": 8,
      "z": 2,
      "name": "Rock_Stone"
    },
    {
      "x": -17,
      "y": 0,
      "z": 3,
      "name": "Soil_Dirt"
    },
    {
      "x": -17,
      "y": 1,
      "z": 3,
      "name": "Empty"
    },
    {
      "x": -17,
      "y": 2,
      "z": 3,
      "name": "Empty"
    },
    {
      "x": -17,
      "y": 3,
      "z": 3,
      "name": "Rock_Stone_Stalactite_Small",
      "rotation": 8
    },
    {
      "x": -17,
      "y": 4,
      "z": 3,
      "name": "Rock_Stone"
    },
    {
      "x": -17,
      "y": 5,
      "z": 3,
      "name": "Rock_Stone"
    },
    {
      "x": -17,
      "y": 6,
      "z": 3,
      "name": "Rock_Stone"
    },
    {
      "x": -17,
      "y": 7,
      "z": 3,
      "name": "Rock_Stone"
    },
    {
      "x": -17,
      "y": 0,
      "z": 4,
      "name": "Soil_Dirt"
    },
    {
      "x": -17,
      "y": 1,
      "z": 4,
      "name": "Rubble_Stone"
    },
    {
      "x": -17,
      "y": 2,
      "z": 4,
      "name": "Empty"
    },
    {
      "x": -17,
      "y": 3,
      "z": 4,
      "name": "Empty"
    },
    {
      "x": -17,
      "y": 7,
      "z": 8,
      "name": "Rock_Stone"
    },
    {
      "x": -17,
      "y": 2,
      "z": 9,
      "name": "Soil_Mud_Dry"
    },
    {
      "x": -17,
      "y": 3,
      "z": 9,
      "name": "Soil_Mud_Dry"
    },
    {
      "x": -17,
      "y": 4,
      "z": 9,
      "name": "Rock_Stone"
    },
    {
      "x": -17,
      "y": 5,
      "z": 9,
      "name": "Rock_Stone"
    },
    {
      "x": -17,
      "y": 6,
      "z": 9,
      "name": "Rock_Stone"
    },
    {
      "x": -17,
      "y": 7,
      "z": 9,
      "name": "Rock_Stone"
    },
    {
      "x": -17,
      "y": 2,
      "z": 10,
      "name": "Soil_Mud_Dry"
    },
    {
      "x": -17,
      "y": 3,
      "z": 10,
      "name": "Soil_Mud_Dry"
    },
    {
      "x": -17,
      "y": 4,
      "z": 10,
      "name": "Soil_Mud_Dry"
    },
    {
      "x": -17,
      "y": 5,
      "z": 10,
      "name": "Rock_Stone"
    },
    {
      "x": -17,
      "y": 6,
      "z": 10,
      "name": "Rock_Stone"
    },
    {
      "x": -17,
      "y": 7,
      "z": 10,
      "name": "Rock_Stone"
    },
    {
      "x": -17,
      "y": 8,
      "z": 10,
      "name": "Rock_Stone"
    },
    {
      "x": -17,
      "y": 2,
      "z": 11,
      "name": "Soil_Mud_Dry"
    },
    {
      "x": -17,
      "y": 3,
      "z": 11,
      "name": "Soil_Mud_Dry"
    },
    {
      "x": -17,
      "y": 4,
      "z": 11,
      "name": "Soil_Mud_Dry"
    },
    {
      "x": -17,
      "y": 5,
      "z": 11,
      "name": "Rock_Stone"
    },
    {
      "x": -17,
      "y": 6,
      "z": 11,
      "name": "Rock_Stone"
    },
    {
      "x": -17,
      "y": 7,
      "z": 11,
      "name": "Rock_Stone"
    },
    {
      "x": -17,
      "y": 8,
      "z": 11,
      "name": "Rock_Stone"
    },
    {
      "x": -17,
      "y": 2,
      "z": 12,
      "name": "Soil_Mud_Dry"
    },
    {
      "x": -17,
      "y": 3,
      "z": 12,
      "name": "Soil_Mud_Dry"
    },
    {
      "x": -17,
      "y": 4,
      "z": 12,
      "name": "Rock_Stone"
    },
    {
      "x": -17,
      "y": 5,
      "z": 12,
      "name": "Rock_Stone"
    },
    {
      "x": -17,
      "y": 6,
      "z": 12,
      "name": "Rock_Stone"
    },
    {
      "x": -17,
      "y": 7,
      "z": 12,
      "name": "Rock_Stone"
    },
    {
      "x": -17,
      "y": 5,
      "z": 13,
      "name": "Rock_Stone"
    },
    {
      "x": -17,
      "y": 6,
      "z": 13,
      "name": "Rock_Stone"
    },
    {
      "x": -17,
      "y": 7,
      "z": 13,
      "name": "Rock_Stone"
    },
    {
      "x": -16,
      "y": -1,
      "z": -14,
      "name": "Rock_Stone"
    },
    {
      "x": -16,
      "y": 0,
      "z": -14,
      "name": "Rock_Stone"
    },
    {
      "x": -16,
      "y": 1,
      "z": -14,
      "name": "Empty"
    },
    {
      "x": -16,
      "y": 2,
      "z": -14,
      "name": "Empty"
    },
    {
      "x": -16,
      "y": 3,
      "z": -14,
      "name": "Empty"
    },
    {
      "x": -16,
      "y": 4,
      "z": -14,
      "name": "Empty"
    },
    {
      "x": -16,
      "y": 5,
      "z": -14,
      "name": "Empty"
    },
    {
      "x": -16,
      "y": 6,
      "z": -14,
      "name": "Empty"
    },
    {
      "x": -16,
      "y": 0,
      "z": -13,
      "name": "Rock_Stone"
    },
    {
      "x": -16,
      "y": 1,
      "z": -13,
      "name": "Plant_Moss_Rug_Green"
    },
    {
      "x": -16,
      "y": 2,
      "z": -13,
      "name": "Empty"
    },
    {
      "x": -16,
      "y": 3,
      "z": -13,
      "name": "Empty"
    },
    {
      "x": -16,
      "y": 4,
      "z": -13,
      "name": "Empty"
    },
    {
      "x": -16,
      "y": 5,
      "z": -13,
      "name": "Empty"
    },
    {
      "x": -16,
      "y": 6,
      "z": -13,
      "name": "Rock_Stone"
    },
    {
      "x": -16,
      "y": -1,
      "z": -12,
      "name": "Rock_Stone"
    },
    {
      "x": -16,
      "y": 0,
      "z": -12,
      "name": "Rock_Stone"
    },
    {
      "x": -16,
      "y": 1,
      "z": -12,
      "name": "Rock_Stone"
    },
    {
      "x": -16,
      "y": 2,
      "z": -12,
      "name": "Rock_Stone"
    },
    {
      "x": -16,
      "y": 3,
      "z": -12,
      "name": "Rock_Stone"
    },
    {
      "x": -16,
      "y": 4,
      "z": -12,
      "name": "Rock_Stone"
    },
    {
      "x": -16,
      "y": 5,
      "z": -12,
      "name": "Rock_Stone"
    },
    {
      "x": -16,
      "y": 6,
      "z": -12,
      "name": "Rock_Stone"
    },
    {
      "x": -16,
      "y": 7,
      "z": -12,
      "name": "Rock_Stone"
    },
    {
      "x": -16,
      "y": 8,
      "z": -12,
      "name": "Rock_Stone"
    },
    {
      "x": -16,
      "y": 9,
      "z": -12,
      "name": "Rock_Stone"
    },
    {
      "x": -16,
      "y": 10,
      "z": -12,
      "name": "Rock_Stone"
    },
    {
      "x": -16,
      "y": 11,
      "z": -12,
      "name": "Rock_Stone"
    },
    {
      "x": -16,
      "y": -2,
      "z": -11,
      "name": "Rock_Stone"
    },
    {
      "x": -16,
      "y": -1,
      "z": -11,
      "name": "Rock_Stone"
    },
    {
      "x": -16,
      "y": 0,
      "z": -11,
      "name": "Rock_Stone"
    },
    {
      "x": -16,
      "y": 1,
      "z": -11,
      "name": "Rock_Stone"
    },
    {
      "x": -16,
      "y": 2,
      "z": -11,
      "name": "Rock_Stone"
    },
    {
      "x": -16,
      "y": 3,
      "z": -11,
      "name": "Rock_Stone"
    },
    {
      "x": -16,
      "y": 4,
      "z": -11,
      "name": "Rock_Stone"
    },
    {
      "x": -16,
      "y": 5,
      "z": -11,
      "name": "Rock_Stone"
    },
    {
      "x": -16,
      "y": 6,
      "z": -11,
      "name": "Soil_Clay"
    },
    {
      "x": -16,
      "y": 7,
      "z": -11,
      "name": "Soil_Clay"
    },
    {
      "x": -16,
      "y": 8,
      "z": -11,
      "name": "Soil_Clay"
    },
    {
      "x": -16,
      "y": 9,
      "z": -11,
      "name": "Soil_Clay"
    },
    {
      "x": -16,
      "y": 10,
      "z": -11,
      "name": "Soil_Clay"
    },
    {
      "x": -16,
      "y": 11,
      "z": -11,
      "name": "Rock_Stone"
    },
    {
      "x": -16,
      "y": 12,
      "z": -11,
      "name": "Rock_Stone"
    },
    {
      "x": -16,
      "y": -2,
      "z": -10,
      "name": "Rock_Stone"
    },
    {
      "x": -16,
      "y": -1,
      "z": -10,
      "name": "Rock_Stone"
    },
    {
      "x": -16,
      "y": 0,
      "z": -10,
      "name": "Rock_Stone"
    },
    {
      "x": -16,
      "y": 1,
      "z": -10,
      "name": "Rock_Stone"
    },
    {
      "x": -16,
      "y": 2,
      "z": -10,
      "name": "Rock_Stone"
    },
    {
      "x": -16,
      "y": 3,
      "z": -10,
      "name": "Rock_Stone"
    },
    {
      "x": -16,
      "y": 4,
      "z": -10,
      "name": "Rock_Stone"
    },
    {
      "x": -16,
      "y": 5,
      "z": -10,
      "name": "Soil_Clay"
    },
    {
      "x": -16,
      "y": 6,
      "z": -10,
      "name": "Soil_Mud_Dry"
    },
    {
      "x": -16,
      "y": 7,
      "z": -10,
      "name": "Soil_Clay"
    },
    {
      "x": -16,
      "y": 8,
      "z": -10,
      "name": "Soil_Clay"
    },
    {
      "x": -16,
      "y": 9,
      "z": -10,
      "name": "Soil_Clay"
    },
    {
      "x": -16,
      "y": 10,
      "z": -10,
      "name": "Soil_Clay"
    },
    {
      "x": -16,
      "y": 11,
      "z": -10,
      "name": "Soil_Clay"
    },
    {
      "x": -16,
      "y": 12,
      "z": -10,
      "name": "Rock_Stone"
    },
    {
      "x": -16,
      "y": -2,
      "z": -9,
      "name": "Rock_Stone"
    },
    {
      "x": -16,
      "y": -1,
      "z": -9,
      "name": "Rock_Stone"
    },
    {
      "x": -16,
      "y": 0,
      "z": -9,
      "name": "Rock_Stone"
    },
    {
      "x": -16,
      "y": 1,
      "z": -9,
      "name": "Rock_Stone"
    },
    {
      "x": -16,
      "y": 2,
      "z": -9,
      "name": "Rock_Stone"
    },
    {
      "x": -16,
      "y": 3,
      "z": -9,
      "name": "Rock_Stone"
    },
    {
      "x": -16,
      "y": 4,
      "z": -9,
      "name": "Rock_Stone"
    },
    {
      "x": -16,
      "y": 5,
      "z": -9,
      "name": "Soil_Mud_Dry"
    },
    {
      "x": -16,
      "y": 6,
      "z": -9,
      "name": "Empty"
    },
    {
      "x": -16,
      "y": 7,
      "z": -9,
      "name": "Soil_Clay"
    },
    {
      "x": -16,
      "y": 8,
      "z": -9,
      "name": "Soil_Clay"
    },
    {
      "x": -16,
      "y": 9,
      "z": -9,
      "name": "Soil_Clay"
    },
    {
      "x": -16,
      "y": 10,
      "z": -9,
      "name": "Soil_Clay"
    },
    {
      "x": -16,
      "y": 11,
      "z": -9,
      "name": "Soil_Clay"
    },
    {
      "x": -16,
      "y": 12,
      "z": -9,
      "name": "Soil_Clay"
    },
    {
      "x": -16,
      "y": 13,
      "z": -9,
      "name": "Rock_Stone"
    },
    {
      "x": -16,
      "y": -2,
      "z": -8,
      "name": "Rock_Stone"
    },
    {
      "x": -16,
      "y": -1,
      "z": -8,
      "name": "Rock_Stone"
    },
    {
      "x": -16,
      "y": 0,
      "z": -8,
      "name": "Rock_Stone"
    },
    {
      "x": -16,
      "y": 1,
      "z": -8,
      "name": "Rock_Stone"
    },
    {
      "x": -16,
      "y": 2,
      "z": -8,
      "name": "Rock_Stone"
    },
    {
      "x": -16,
      "y": 3,
      "z": -8,
      "name": "Rock_Stone"
    },
    {
      "x": -16,
      "y": 4,
      "z": -8,
      "name": "Rock_Stone"
    },
    {
      "x": -16,
      "y": 5,
      "z": -8,
      "name": "Soil_Pathway"
    },
    {
      "x": -16,
      "y": 6,
      "z": -8,
      "name": "Furniture_Crude_Bed",
      "components": {
        "Components": {
          "RespawnBlock": {}
        }
      }
    },
    {
      "x": -16,
      "y": 7,
      "z": -8,
      "name": "Empty"
    },
    {
      "x": -16,
      "y": 8,
      "z": -8,
      "name": "Empty"
    },
    {
      "x": -16,
      "y": 9,
      "z": -8,
      "name": "Plant_Roots_Cave",
      "rotation": 10
    },
    {
      "x": -16,
      "y": 10,
      "z": -8,
      "name": "Soil_Clay"
    },
    {
      "x": -16,
      "y": 11,
      "z": -8,
      "name": "Soil_Clay"
    },
    {
      "x": -16,
      "y": 12,
      "z": -8,
      "name": "Soil_Clay"
    },
    {
      "x": -16,
      "y": 13,
      "z": -8,
      "name": "Rock_Stone"
    },
    {
      "x": -16,
      "y": -2,
      "z": -7,
      "name": "Rock_Stone"
    },
    {
      "x": -16,
      "y": -1,
      "z": -7,
      "name": "Rock_Stone"
    },
    {
      "x": -16,
      "y": 0,
      "z": -7,
      "name": "Soil_Mud_Dry"
    },
    {
      "x": -16,
      "y": 1,
      "z": -7,
      "name": "Plant_Crop_Mushroom_Block_Brown"
    },
    {
      "x": -16,
      "y": 2,
      "z": -7,
      "name": "Rock_Stone"
    },
    {
      "x": -16,
      "y": 3,
      "z": -7,
      "name": "Rock_Stone"
    },
    {
      "x": -16,
      "y": 4,
      "z": -7,
      "name": "Rock_Stone"
    },
    {
      "x": -16,
      "y": 5,
      "z": -7,
      "name": "Soil_Gravel"
    },
    {
      "x": -16,
      "y": 6,
      "z": -7,
      "name": "Furniture_Crude_Bed",
      "components": {
        "Components": {
          "RespawnBlock": {}
        }
      },
      "filler": 32
    },
    {
      "x": -16,
      "y": 7,
      "z": -7,
      "name": "Empty"
    },
    {
      "x": -16,
      "y": 8,
      "z": -7,
      "name": "Empty"
    },
    {
      "x": -16,
      "y": 9,
      "z": -7,
      "name": "Empty"
    },
    {
      "x": -16,
      "y": 10,
      "z": -7,
      "name": "Empty"
    },
    {
      "x": -16,
      "y": 11,
      "z": -7,
      "name": "Empty"
    },
    {
      "x": -16,
      "y": 12,
      "z": -7,
      "name": "Soil_Clay"
    },
    {
      "x": -16,
      "y": 13,
      "z": -7,
      "name": "Rock_Stone"
    },
    {
      "x": -16,
      "y": -2,
      "z": -6,
      "name": "Rock_Stone"
    },
    {
      "x": -16,
      "y": -1,
      "z": -6,
      "name": "Rock_Stone"
    },
    {
      "x": -16,
      "y": 0,
      "z": -6,
      "name": "Soil_Mud_Dry"
    },
    {
      "x": -16,
      "y": 1,
      "z": -6,
      "name": "Plant_Crop_Mushroom_Shelve_Brown"
    },
    {
      "x": -16,
      "y": 2,
      "z": -6,
      "name": "Empty"
    },
    {
      "x": -16,
      "y": 3,
      "z": -6,
      "name": "Empty"
    },
    {
      "x": -16,
      "y": 4,
      "z": -6,
      "name": "Rock_Stone"
    },
    {
      "x": -16,
      "y": 5,
      "z": -6,
      "name": "Rock_Stone"
    },
    {
      "x": -16,
      "y": 6,
      "z": -6,
      "name": "Furniture_Ancient_Pot",
      "rotation": 1
    },
    {
      "x": -16,
      "y": 7,
      "z": -6,
      "name": "Empty"
    },
    {
      "x": -16,
      "y": 8,
      "z": -6,
      "name": "Empty"
    },
    {
      "x": -16,
      "y": 9,
      "z": -6,
      "name": "Empty"
    },
    {
      "x": -16,
      "y": 10,
      "z": -6,
      "name": "Empty"
    },
    {
      "x": -16,
      "y": 11,
      "z": -6,
      "name": "Empty"
    },
    {
      "x": -16,
      "y": 12,
      "z": -6,
      "name": "Empty"
    },
    {
      "x": -16,
      "y": 13,
      "z": -6,
      "name": "Rock_Stone"
    },
    {
      "x": -16,
      "y": -2,
      "z": -5,
      "name": "Rock_Stone"
    },
    {
      "x": -16,
      "y": -1,
      "z": -5,
      "name": "Rock_Stone"
    },
    {
      "x": -16,
      "y": 0,
      "z": -5,
      "name": "Soil_Mud_Dry"
    },
    {
      "x": -16,
      "y": 1,
      "z": -5,
      "name": "Empty"
    },
    {
      "x": -16,
      "y": 2,
      "z": -5,
      "name": "Empty"
    },
    {
      "x": -16,
      "y": 3,
      "z": -5,
      "name": "Empty"
    },
    {
      "x": -16,
      "y": 4,
      "z": -5,
      "name": "Empty"
    },
    {
      "x": -16,
      "y": 5,
      "z": -5,
      "name": "Soil_Gravel"
    },
    {
      "x": -16,
      "y": 6,
      "z": -5,
      "name": "Empty"
    },
    {
      "x": -16,
      "y": 7,
      "z": -5,
      "name": "Empty"
    },
    {
      "x": -16,
      "y": 8,
      "z": -5,
      "name": "Empty"
    },
    {
      "x": -16,
      "y": 9,
      "z": -5,
      "name": "Empty"
    },
    {
      "x": -16,
      "y": 10,
      "z": -5,
      "name": "Empty"
    },
    {
      "x": -16,
      "y": 11,
      "z": -5,
      "name": "Empty"
    },
    {
      "x": -16,
      "y": 12,
      "z": -5,
      "name": "Empty"
    },
    {
      "x": -16,
      "y": 13,
      "z": -5,
      "name": "Rock_Stone"
    },
    {
      "x": -16,
      "y": -2,
      "z": -4,
      "name": "Rock_Stone"
    },
    {
      "x": -16,
      "y": -1,
      "z": -4,
      "name": "Rock_Stone"
    },
    {
      "x": -16,
      "y": 0,
      "z": -4,
      "name": "Soil_Pathway"
    },
    {
      "x": -16,
      "y": 1,
      "z": -4,
      "name": "Empty"
    },
    {
      "x": -16,
      "y": 2,
      "z": -4,
      "name": "Empty"
    },
    {
      "x": -16,
      "y": 3,
      "z": -4,
      "name": "Empty"
    },
    {
      "x": -16,
      "y": 4,
      "z": -4,
      "name": "Empty"
    },
    {
      "x": -16,
      "y": 5,
      "z": -4,
      "name": "Soil_Gravel"
    },
    {
      "x": -16,
      "y": 6,
      "z": -4,
      "name": "Deco_Pot_Clay_Broken"
    },
    {
      "x": -16,
      "y": 7,
      "z": -4,
      "name": "Empty"
    },
    {
      "x": -16,
      "y": 8,
      "z": -4,
      "name": "Empty"
    },
    {
      "x": -16,
      "y": 9,
      "z": -4,
      "name": "Empty"
    },
    {
      "x": -16,
      "y": 10,
      "z": -4,
      "name": "Empty"
    },
    {
      "x": -16,
      "y": 11,
      "z": -4,
      "name": "Empty"
    },
    {
      "x": -16,
      "y": 12,
      "z": -4,
      "name": "Empty"
    },
    {
      "x": -16,
      "y": 13,
      "z": -4,
      "name": "Rock_Stone"
    },
    {
      "x": -16,
      "y": -1,
      "z": -3,
      "name": "Rock_Stone"
    },
    {
      "x": -16,
      "y": 0,
      "z": -3,
      "name": "Soil_Pathway"
    },
    {
      "x": -16,
      "y": 1,
      "z": -3,
      "name": "Empty"
    },
    {
      "x": -16,
      "y": 2,
      "z": -3,
      "name": "Empty"
    },
    {
      "x": -16,
      "y": 3,
      "z": -3,
      "name": "Empty"
    },
    {
      "x": -16,
      "y": 4,
      "z": -3,
      "name": "Empty"
    },
    {
      "x": -16,
      "y": 5,
      "z": -3,
      "name": "Plant_Moss_Block_Green"
    },
    {
      "x": -16,
      "y": 6,
      "z": -3,
      "name": "Empty"
    },
    {
      "x": -16,
      "y": 7,
      "z": -3,
      "name": "Empty"
    },
    {
      "x": -16,
      "y": 8,
      "z": -3,
      "name": "Empty"
    },
    {
      "x": -16,
      "y": 9,
      "z": -3,
      "name": "Empty"
    },
    {
      "x": -16,
      "y": 10,
      "z": -3,
      "name": "Empty"
    },
    {
      "x": -16,
      "y": 11,
      "z": -3,
      "name": "Rock_Stone_Stalactite_Small",
      "rotation": 8
    },
    {
      "x": -16,
      "y": 12,
      "z": -3,
      "name": "Rock_Stone"
    },
    {
      "x": -16,
      "y": 13,
      "z": -3,
      "name": "Rock_Stone"
    },
    {
      "x": -16,
      "y": -1,
      "z": -2,
      "name": "Rock_Stone"
    },
    {
      "x": -16,
      "y": 0,
      "z": -2,
      "name": "Soil_Pathway"
    },
    {
      "x": -16,
      "y": 1,
      "z": -2,
      "name": "Empty"
    },
    {
      "x": -16,
      "y": 2,
      "z": -2,
      "name": "Empty"
    },
    {
      "x": -16,
      "y": 3,
      "z": -2,
      "name": "Empty"
    },
    {
      "x": -16,
      "y": 4,
      "z": -2,
      "name": "Empty"
    },
    {
      "x": -16,
      "y": 5,
      "z": -2,
      "name": "Plant_Moss_Block_Green"
    },
    {
      "x": -16,
      "y": 6,
      "z": -2,
      "name": "Empty"
    },
    {
      "x": -16,
      "y": 7,
      "z": -2,
      "name": "Empty"
    },
    {
      "x": -16,
      "y": 8,
      "z": -2,
      "name": "Empty"
    },
    {
      "x": -16,
      "y": 9,
      "z": -2,
      "name": "Empty"
    },
    {
      "x": -16,
      "y": 10,
      "z": -2,
      "name": "Empty"
    },
    {
      "x": -16,
      "y": 11,
      "z": -2,
      "name": "Empty"
    },
    {
      "x": -16,
      "y": 12,
      "z": -2,
      "name": "Rock_Stone"
    },
    {
      "x": -16,
      "y": 13,
      "z": -2,
      "name": "Rock_Stone"
    },
    {
      "x": -16,
      "y": -1,
      "z": -1,
      "name": "Rock_Stone"
    },
    {
      "x": -16,
      "y": 0,
      "z": -1,
      "name": "Soil_Pathway"
    },
    {
      "x": -16,
      "y": 1,
      "z": -1,
      "name": "Empty"
    },
    {
      "x": -16,
      "y": 2,
      "z": -1,
      "name": "Empty"
    },
    {
      "x": -16,
      "y": 3,
      "z": -1,
      "name": "Empty"
    },
    {
      "x": -16,
      "y": 4,
      "z": -1,
      "name": "Empty"
    },
    {
      "x": -16,
      "y": 5,
      "z": -1,
      "name": "Empty"
    },
    {
      "x": -16,
      "y": 6,
      "z": -1,
      "name": "Empty"
    },
    {
      "x": -16,
      "y": 7,
      "z": -1,
      "name": "Empty"
    },
    {
      "x": -16,
      "y": 8,
      "z": -1,
      "name": "Empty"
    },
    {
      "x": -16,
      "y": 9,
      "z": -1,
      "name": "Empty"
    },
    {
      "x": -16,
      "y": 10,
      "z": -1,
      "name": "Empty"
    },
    {
      "x": -16,
      "y": 11,
      "z": -1,
      "name": "Empty"
    },
    {
      "x": -16,
      "y": -1,
      "z": 0,
      "name": "Rock_Stone"
    },
    {
      "x": -16,
      "y": 0,
      "z": 0,
      "name": "Soil_Pathway"
    },
    {
      "x": -16,
      "y": 1,
      "z": 0,
      "name": "Empty"
    },
    {
      "x": -16,
      "y": 2,
      "z": 0,
      "name": "Empty"
    },
    {
      "x": -16,
      "y": 3,
      "z": 0,
      "name": "Empty"
    },
    {
      "x": -16,
      "y": 4,
      "z": 0,
      "name": "Empty"
    },
    {
      "x": -16,
      "y": 5,
      "z": 0,
      "name": "Empty"
    },
    {
      "x": -16,
      "y": 6,
      "z": 0,
      "name": "Empty"
    },
    {
      "x": -16,
      "y": 7,
      "z": 0,
      "name": "Empty"
    },
    {
      "x": -16,
      "y": 8,
      "z": 0,
      "name": "Empty"
    },
    {
      "x": -16,
      "y": 9,
      "z": 0,
      "name": "Empty"
    },
    {
      "x": -16,
      "y": 10,
      "z": 0,
      "name": "Empty"
    },
    {
      "x": -16,
      "y": 11,
      "z": 0,
      "name": "Empty"
    },
    {
      "x": -16,
      "y": -1,
      "z": 1,
      "name": "Rock_Stone"
    },
    {
      "x": -16,
      "y": 0,
      "z": 1,
      "name": "Soil_Dirt"
    },
    {
      "x": -16,
      "y": 1,
      "z": 1,
      "name": "Empty"
    },
    {
      "x": -16,
      "y": 2,
      "z": 1,
      "name": "Empty"
    },
    {
      "x": -16,
      "y": 3,
      "z": 1,
      "name": "Empty"
    },
    {
      "x": -16,
      "y": 4,
      "z": 1,
      "name": "Empty"
    },
    {
      "x": -16,
      "y": 5,
      "z": 1,
      "name": "Plant_Moss_Wall_Green",
      "rotation": 3
    },
    {
      "x": -16,
      "y": 6,
      "z": 1,
      "name": "Empty"
    },
    {
      "x": -16,
      "y": 7,
      "z": 1,
      "name": "Empty"
    },
    {
      "x": -16,
      "y": 8,
      "z": 1,
      "name": "Rock_Stone"
    },
    {
      "x": -16,
      "y": 9,
      "z": 1,
      "name": "Rock_Stone"
    },
    {
      "x": -16,
      "y": -1,
      "z": 2,
      "name": "Rock_Stone"
    },
    {
      "x": -16,
      "y": 0,
      "z": 2,
      "name": "Soil_Dirt"
    },
    {
      "x": -16,
      "y": 1,
      "z": 2,
      "name": "Empty"
    },
    {
      "x": -16,
      "y": 2,
      "z": 2,
      "name": "Empty"
    },
    {
      "x": -16,
      "y": 3,
      "z": 2,
      "name": "Empty"
    },
    {
      "x": -16,
      "y": 4,
      "z": 2,
      "name": "Empty"
    },
    {
      "x": -16,
      "y": 5,
      "z": 2,
      "name": "Empty"
    },
    {
      "x": -16,
      "y": 6,
      "z": 2,
      "name": "Empty"
    },
    {
      "x": -16,
      "y": 7,
      "z": 2,
      "name": "Soil_Clay"
    },
    {
      "x": -16,
      "y": 8,
      "z": 2,
      "name": "Soil_Clay"
    },
    {
      "x": -16,
      "y": 0,
      "z": 3,
      "name": "Soil_Dirt"
    },
    {
      "x": -16,
      "y": 1,
      "z": 3,
      "name": "Empty"
    },
    {
      "x": -16,
      "y": 2,
      "z": 3,
      "name": "Empty"
    },
    {
      "x": -16,
      "y": 3,
      "z": 3,
      "name": "Empty"
    },
    {
      "x": -16,
      "y": 4,
      "z": 3,
      "name": "Empty"
    },
    {
      "x": -16,
      "y": 5,
      "z": 3,
      "name": "Rock_Stone"
    },
    {
      "x": -16,
      "y": 6,
      "z": 3,
      "name": "Rock_Stone"
    },
    {
      "x": -16,
      "y": 7,
      "z": 3,
      "name": "Soil_Clay"
    },
    {
      "x": -16,
      "y": 8,
      "z": 3,
      "name": "Rock_Stone"
    },
    {
      "x": -16,
      "y": 0,
      "z": 4,
      "name": "Soil_Dirt"
    },
    {
      "x": -16,
      "y": 1,
      "z": 4,
      "name": "Empty"
    },
    {
      "x": -16,
      "y": 2,
      "z": 4,
      "name": "Empty"
    },
    {
      "x": -16,
      "y": 3,
      "z": 4,
      "name": "Empty"
    },
    {
      "x": -16,
      "y": 4,
      "z": 4,
      "name": "Empty"
    },
    {
      "x": -16,
      "y": 6,
      "z": 4,
      "name": "Rock_Stone"
    },
    {
      "x": -16,
      "y": 7,
      "z": 4,
      "name": "Rock_Stone"
    },
    {
      "x": -16,
      "y": 8,
      "z": 4,
      "name": "Rock_Stone"
    },
    {
      "x": -16,
      "y": 0,
      "z": 5,
      "name": "Soil_Dirt"
    },
    {
      "x": -16,
      "y": 1,
      "z": 5,
      "name": "Rubble_Stone_Medium"
    },
    {
      "x": -16,
      "y": 2,
      "z": 5,
      "name": "Empty"
    },
    {
      "x": -16,
      "y": 6,
      "z": 5,
      "name": "Rock_Stone"
    },
    {
      "x": -16,
      "y": 7,
      "z": 5,
      "name": "Rock_Stone"
    },
    {
      "x": -16,
      "y": 8,
      "z": 5,
      "name": "Rock_Stone"
    },
    {
      "x": -16,
      "y": 0,
      "z": 6,
      "name": "Rock_Stone"
    },
    {
      "x": -16,
      "y": 6,
      "z": 6,
      "name": "Rock_Stone"
    },
    {
      "x": -16,
      "y": 7,
      "z": 6,
      "name": "Rock_Stone"
    },
    {
      "x": -16,
      "y": 8,
      "z": 6,
      "name": "Rock_Stone"
    },
    {
      "x": -16,
      "y": 9,
      "z": 6,
      "name": "Rock_Stone"
    },
    {
      "x": -16,
      "y": 5,
      "z": 7,
      "name": "Rock_Stone"
    },
    {
      "x": -16,
      "y": 6,
      "z": 7,
      "name": "Rock_Stone"
    },
    {
      "x": -16,
      "y": 7,
      "z": 7,
      "name": "Rock_Stone"
    },
    {
      "x": -16,
      "y": 8,
      "z": 7,
      "name": "Rock_Stone"
    },
    {
      "x": -16,
      "y": 9,
      "z": 7,
      "name": "Rock_Stone"
    },
    {
      "x": -16,
      "y": 2,
      "z": 8,
      "name": "Soil_Mud_Dry"
    },
    {
      "x": -16,
      "y": 3,
      "z": 8,
      "name": "Soil_Mud_Dry"
    },
    {
      "x": -16,
      "y": 4,
      "z": 8,
      "name": "Rock_Stone"
    },
    {
      "x": -16,
      "y": 5,
      "z": 8,
      "name": "Rock_Stone"
    },
    {
      "x": -16,
      "y": 6,
      "z": 8,
      "name": "Rock_Stone"
    },
    {
      "x": -16,
      "y": 7,
      "z": 8,
      "name": "Rock_Stone"
    },
    {
      "x": -16,
      "y": 8,
      "z": 8,
      "name": "Rock_Stone"
    },
    {
      "x": -16,
      "y": 1,
      "z": 9,
      "name": "Soil_Dirt"
    },
    {
      "x": -16,
      "y": 2,
      "z": 9,
      "name": "Plant_Crop_Mushroom_Cap_Brown",
      "components": {
        "Components": {
          "FarmingBlock": {}
        }
      }
    },
    {
      "x": -16,
      "y": 3,
      "z": 9,
      "name": "Empty"
    },
    {
      "x": -16,
      "y": 4,
      "z": 9,
      "name": "Rock_Stone"
    },
    {
      "x": -16,
      "y": 5,
      "z": 9,
      "name": "Rock_Stone"
    },
    {
      "x": -16,
      "y": 6,
      "z": 9,
      "name": "Rock_Stone"
    },
    {
      "x": -16,
      "y": 7,
      "z": 9,
      "name": "Rock_Stone"
    },
    {
      "x": -16,
      "y": 8,
      "z": 9,
      "name": "Rock_Stone"
    },
    {
      "x": -16,
      "y": 9,
      "z": 9,
      "name": "Rock_Stone"
    },
    {
      "x": -16,
      "y": 1,
      "z": 10,
      "name": "Soil_Pathway"
    },
    {
      "x": -16,
      "y": 2,
      "z": 10,
      "name": "Empty"
    },
    {
      "x": -16,
      "y": 3,
      "z": 10,
      "name": "Empty"
    },
    {
      "x": -16,
      "y": 4,
      "z": 10,
      "name": "Empty"
    },
    {
      "x": -16,
      "y": 5,
      "z": 10,
      "name": "Rock_Stone"
    },
    {
      "x": -16,
      "y": 6,
      "z": 10,
      "name": "Rock_Stone"
    },
    {
      "x": -16,
      "y": 7,
      "z": 10,
      "name": "Rock_Stone"
    },
    {
      "x": -16,
      "y": 8,
      "z": 10,
      "name": "Rock_Stone"
    },
    {
      "x": -16,
      "y": 9,
      "z": 10,
      "name": "Rock_Stone"
    },
    {
      "x": -16,
      "y": 1,
      "z": 11,
      "name": "Soil_Pathway"
    },
    {
      "x": -16,
      "y": 2,
      "z": 11,
      "name": "Empty"
    },
    {
      "x": -16,
      "y": 3,
      "z": 11,
      "name": "Empty"
    },
    {
      "x": -16,
      "y": 4,
      "z": 11,
      "name": "Empty"
    },
    {
      "x": -16,
      "y": 5,
      "z": 11,
      "name": "Rock_Stone"
    },
    {
      "x": -16,
      "y": 6,
      "z": 11,
      "name": "Rock_Stone"
    },
    {
      "x": -16,
      "y": 7,
      "z": 11,
      "name": "Rock_Stone"
    },
    {
      "x": -16,
      "y": 8,
      "z": 11,
      "name": "Rock_Stone"
    },
    {
      "x": -16,
      "y": 9,
      "z": 11,
      "name": "Rock_Stone"
    },
    {
      "x": -16,
      "y": 1,
      "z": 12,
      "name": "Soil_Pathway"
    },
    {
      "x": -16,
      "y": 2,
      "z": 12,
      "name": "Empty"
    },
    {
      "x": -16,
      "y": 3,
      "z": 12,
      "name": "Empty"
    },
    {
      "x": -16,
      "y": 4,
      "z": 12,
      "name": "Deco_SpiderWeb",
      "rotation": 11
    },
    {
      "x": -16,
      "y": 5,
      "z": 12,
      "name": "Rock_Stone"
    },
    {
      "x": -16,
      "y": 6,
      "z": 12,
      "name": "Rock_Stone"
    },
    {
      "x": -16,
      "y": 7,
      "z": 12,
      "name": "Rock_Stone"
    },
    {
      "x": -16,
      "y": 8,
      "z": 12,
      "name": "Rock_Stone"
    },
    {
      "x": -16,
      "y": 9,
      "z": 12,
      "name": "Rock_Stone"
    },
    {
      "x": -16,
      "y": 0,
      "z": 13,
      "name": "Soil_Pathway"
    },
    {
      "x": -16,
      "y": 1,
      "z": 13,
      "name": "Soil_Pathway_Half"
    },
    {
      "x": -16,
      "y": 2,
      "z": 13,
      "name": "Empty"
    },
    {
      "x": -16,
      "y": 3,
      "z": 13,
      "name": "Empty"
    },
    {
      "x": -16,
      "y": 4,
      "z": 13,
      "name": "Empty"
    },
    {
      "x": -16,
      "y": 5,
      "z": 13,
      "name": "Empty"
    },
    {
      "x": -16,
      "y": 6,
      "z": 13,
      "name": "Rock_Stone"
    },
    {
      "x": -16,
      "y": 7,
      "z": 13,
      "name": "Rock_Stone"
    },
    {
      "x": -16,
      "y": 0,
      "z": 14,
      "name": "Soil_Pathway"
    },
    {
      "x": -16,
      "y": 1,
      "z": 14,
      "name": "Empty"
    },
    {
      "x": -16,
      "y": 2,
      "z": 14,
      "name": "Empty"
    },
    {
      "x": -16,
      "y": 3,
      "z": 14,
      "name": "Empty"
    },
    {
      "x": -16,
      "y": 4,
      "z": 14,
      "name": "Empty"
    },
    {
      "x": -16,
      "y": 5,
      "z": 14,
      "name": "Empty"
    },
    {
      "x": -16,
      "y": 6,
      "z": 14,
      "name": "Empty"
    },
    {
      "x": -15,
      "y": -1,
      "z": -14,
      "name": "Rock_Stone"
    },
    {
      "x": -15,
      "y": 0,
      "z": -14,
      "name": "Rock_Stone"
    },
    {
      "x": -15,
      "y": 1,
      "z": -14,
      "name": "Empty"
    },
    {
      "x": -15,
      "y": 2,
      "z": -14,
      "name": "Empty"
    },
    {
      "x": -15,
      "y": 3,
      "z": -14,
      "name": "Empty"
    },
    {
      "x": -15,
      "y": 4,
      "z": -14,
      "name": "Empty"
    },
    {
      "x": -15,
      "y": 5,
      "z": -14,
      "name": "Empty"
    },
    {
      "x": -15,
      "y": 6,
      "z": -14,
      "name": "Empty"
    },
    {
      "x": -15,
      "y": 7,
      "z": -14,
      "name": "Empty"
    },
    {
      "x": -15,
      "y": -1,
      "z": -13,
      "name": "Rock_Stone"
    },
    {
      "x": -15,
      "y": 0,
      "z": -13,
      "name": "Rock_Stone_Mossy"
    },
    {
      "x": -15,
      "y": 1,
      "z": -13,
      "name": "Plant_Moss_Rug_Green"
    },
    {
      "x": -15,
      "y": 2,
      "z": -13,
      "name": "Empty"
    },
    {
      "x": -15,
      "y": 3,
      "z": -13,
      "name": "Empty"
    },
    {
      "x": -15,
      "y": 4,
      "z": -13,
      "name": "Empty"
    },
    {
      "x": -15,
      "y": 5,
      "z": -13,
      "name": "Empty"
    },
    {
      "x": -15,
      "y": 6,
      "z": -13,
      "name": "Empty"
    },
    {
      "x": -15,
      "y": 7,
      "z": -13,
      "name": "Empty"
    },
    {
      "x": -15,
      "y": 8,
      "z": -13,
      "name": "Rock_Stone"
    },
    {
      "x": -15,
      "y": 9,
      "z": -13,
      "name": "Rock_Stone"
    },
    {
      "x": -15,
      "y": 10,
      "z": -13,
      "name": "Rock_Stone"
    },
    {
      "x": -15,
      "y": -2,
      "z": -12,
      "name": "Rock_Stone"
    },
    {
      "x": -15,
      "y": -1,
      "z": -12,
      "name": "Plant_Moss_Block_Green"
    },
    {
      "x": -15,
      "y": 0,
      "z": -12,
      "name": "Plant_Moss_Block_Green"
    },
    {
      "x": -15,
      "y": 1,
      "z": -12,
      "name": "Plant_Moss_Rug_Green"
    },
    {
      "x": -15,
      "y": 2,
      "z": -12,
      "name": "Empty"
    },
    {
      "x": -15,
      "y": 3,
      "z": -12,
      "name": "Empty"
    },
    {
      "x": -15,
      "y": 4,
      "z": -12,
      "name": "Empty"
    },
    {
      "x": -15,
      "y": 5,
      "z": -12,
      "name": "Empty"
    },
    {
      "x": -15,
      "y": 6,
      "z": -12,
      "name": "Empty"
    },
    {
      "x": -15,
      "y": 7,
      "z": -12,
      "name": "Rock_Stone"
    },
    {
      "x": -15,
      "y": 8,
      "z": -12,
      "name": "Rock_Stone"
    },
    {
      "x": -15,
      "y": 9,
      "z": -12,
      "name": "Rock_Stone"
    },
    {
      "x": -15,
      "y": 10,
      "z": -12,
      "name": "Soil_Clay"
    },
    {
      "x": -15,
      "y": 11,
      "z": -12,
      "name": "Rock_Stone"
    },
    {
      "x": -15,
      "y": -2,
      "z": -11,
      "name": "Rock_Stone"
    },
    {
      "x": -15,
      "y": 1,
      "z": -11,
      "name": "Plant_Moss_Rug_Blue"
    },
    {
      "x": -15,
      "y": 2,
      "z": -11,
      "name": "Empty"
    },
    {
      "x": -15,
      "y": 3,
      "z": -11,
      "name": "Empty"
    },
    {
      "x": -15,
      "y": 4,
      "z": -11,
      "name": "Empty"
    },
    {
      "x": -15,
      "y": 5,
      "z": -11,
      "name": "Rock_Stone"
    },
    {
      "x": -15,
      "y": 6,
      "z": -11,
      "name": "Rock_Stone"
    },
    {
      "x": -15,
      "y": 7,
      "z": -11,
      "name": "Soil_Clay"
    },
    {
      "x": -15,
      "y": 8,
      "z": -11,
      "name": "Soil_Clay"
    },
    {
      "x": -15,
      "y": 9,
      "z": -11,
      "name": "Soil_Clay"
    },
    {
      "x": -15,
      "y": 10,
      "z": -11,
      "name": "Soil_Clay"
    },
    {
      "x": -15,
      "y": 11,
      "z": -11,
      "name": "Soil_Clay"
    },
    {
      "x": -15,
      "y": 12,
      "z": -11,
      "name": "Rock_Stone"
    },
    {
      "x": -15,
      "y": -2,
      "z": -10,
      "name": "Rock_Stone"
    },
    {
      "x": -15,
      "y": 1,
      "z": -10,
      "name": "Plant_Moss_Rug_Blue"
    },
    {
      "x": -15,
      "y": 2,
      "z": -10,
      "name": "Empty"
    },
    {
      "x": -15,
      "y": 3,
      "z": -10,
      "name": "Empty"
    },
    {
      "x": -15,
      "y": 4,
      "z": -10,
      "name": "Rock_Stone"
    },
    {
      "x": -15,
      "y": 5,
      "z": -10,
      "name": "Rock_Stone"
    },
    {
      "x": -15,
      "y": 6,
      "z": -10,
      "name": "Soil_Mud_Dry"
    },
    {
      "x": -15,
      "y": 7,
      "z": -10,
      "name": "Soil_Mud_Dry"
    },
    {
      "x": -15,
      "y": 8,
      "z": -10,
      "name": "Soil_Mud_Dry"
    },
    {
      "x": -15,
      "y": 9,
      "z": -10,
      "name": "Soil_Clay"
    },
    {
      "x": -15,
      "y": 10,
      "z": -10,
      "name": "Soil_Clay"
    },
    {
      "x": -15,
      "y": 11,
      "z": -10,
      "name": "Soil_Clay"
    },
    {
      "x": -15,
      "y": 12,
      "z": -10,
      "name": "Soil_Clay"
    },
    {
      "x": -15,
      "y": -2,
      "z": -9,
      "name": "Rock_Stone"
    },
    {
      "x": -15,
      "y": -1,
      "z": -9,
      "name": "Rock_Stone"
    },
    {
      "x": -15,
      "y": 0,
      "z": -9,
      "name": "Rock_Stone"
    },
    {
      "x": -15,
      "y": 1,
      "z": -9,
      "name": "Rock_Stone"
    },
    {
      "x": -15,
      "y": 2,
      "z": -9,
      "name": "Rock_Stone"
    },
    {
      "x": -15,
      "y": 3,
      "z": -9,
      "name": "Rock_Stone"
    },
    {
      "x": -15,
      "y": 4,
      "z": -9,
      "name": "Rock_Stone"
    },
    {
      "x": -15,
      "y": 5,
      "z": -9,
      "name": "Soil_Pathway"
    },
    {
      "x": -15,
      "y": 6,
      "z": -9,
      "name": "Empty"
    },
    {
      "x": -15,
      "y": 7,
      "z": -9,
      "name": "Empty"
    },
    {
      "x": -15,
      "y": 8,
      "z": -9,
      "name": "Empty"
    },
    {
      "x": -15,
      "y": 9,
      "z": -9,
      "name": "Empty"
    },
    {
      "x": -15,
      "y": 10,
      "z": -9,
      "name": "Empty"
    },
    {
      "x": -15,
      "y": 11,
      "z": -9,
      "name": "Empty"
    },
    {
      "x": -15,
      "y": 12,
      "z": -9,
      "name": "Rock_Stone"
    },
    {
